#######################################################################
# +-----------------------------------------------------------------+ #
# |                            BO3 object                           | #
# +-----------------------------------------------------------------+ #
#######################################################################

Author: Bo3 BulkEdit

Description: Converted Schematic - Modified by Bo3BulkEdit

Version: 3

SettingsMode: WriteDisable

#######################################################################
# +-----------------------------------------------------------------+ #
# |                          Main settings                          | #
# +-----------------------------------------------------------------+ #
#######################################################################

IsOTGPlus: true
Tree: false
Frequency: 1
Rarity: 100.0
RotateRandomly: false
SpawnHeight: randomY
MaxBranchDepth: 10
ExcludedBiomes: All

##############################
# Height Limits for the BO3. #
##############################

MinHeight: 0
MaxHeight: 255

#######################################################################
# +-----------------------------------------------------------------+ #
# |                      Source block settings                      | #
# +-----------------------------------------------------------------+ #
#######################################################################

CanOverride: true
MaxPercentageOutsideSourceBlock: 100
OutsideSourceBlock: placeAnyway

#######################################################################
# +-----------------------------------------------------------------+ #
# |                               OTG+                              | #
# +-----------------------------------------------------------------+ #
#######################################################################

BO3Group: CeilingCrystals:0

#######################################################################
# +-----------------------------------------------------------------+ #
# |                              Blocks                             | #
# +-----------------------------------------------------------------+ #
#######################################################################

B(0,750,0,AIR)
B(15,750,15,AIR)
B(5,-20,8,STAINED_GLASS:15)
B(4,-20,9,STAINED_GLASS:15)
B(5,-20,9,STAINED_GLASS:15)
B(4,-20,10,STAINED_GLASS:15)
B(4,-19,5,STAINED_GLASS:15)
B(3,-19,6,STAINED_GLASS:15)
B(4,-19,6,STAINED_GLASS:15)
B(3,-19,7,STAINED_GLASS:15)
B(4,-19,7,STAINED_GLASS:15)
B(3,-19,8,STAINED_GLASS:15)
B(4,-19,8,STAINED_GLASS:15)
B(5,-19,8,STAINED_GLASS:15)
B(3,-19,9,STAINED_GLASS:15)
B(4,-19,9,STAINED_GLASS:15)
B(5,-19,9,STAINED_GLASS:15)
B(4,-19,10,STAINED_GLASS:15)
B(5,-19,10,STAINED_GLASS:15)
B(2,-18,3,STAINED_GLASS:15)
B(3,-18,3,STAINED_GLASS:15)
B(0,-18,4,STAINED_GLASS:15)
B(1,-18,4,STAINED_GLASS:15)
B(2,-18,4,STAINED_GLASS:9)
B(3,-18,4,STAINED_GLASS:15)
B(0,-18,5,STAINED_GLASS:15)
B(1,-18,5,STAINED_GLASS:15)
B(2,-18,5,STAINED_GLASS:15)
B(3,-18,5,STAINED_GLASS:15)
B(4,-18,5,STAINED_GLASS:15)
B(2,-18,6,STAINED_GLASS:15)
B(3,-18,6,STAINED_GLASS:15)
B(4,-18,6,STAINED_GLASS:15)
B(2,-18,7,STAINED_GLASS:15)
B(3,-18,7,STAINED_GLASS:15)
B(4,-18,7,STAINED_GLASS:15)
B(5,-18,7,STAINED_GLASS:15)
B(2,-18,8,STAINED_GLASS:15)
B(3,-18,8,STAINED_GLASS:15)
B(4,-18,8,STAINED_GLASS:15)
B(5,-18,8,STAINED_GLASS:15)
B(3,-18,9,STAINED_GLASS:15)
B(4,-18,9,STAINED_GLASS:15)
B(5,-18,9,STAINED_GLASS:15)
B(1,-17,1,STAINED_GLASS:15)
B(2,-17,1,STAINED_GLASS:15)
B(0,-17,2,STAINED_GLASS:15)
B(1,-17,2,STAINED_GLASS:15)
B(2,-17,2,STAINED_GLASS:15)
B(0,-17,3,STAINED_GLASS:15)
B(1,-17,3,STAINED_GLASS:15)
B(2,-17,3,STAINED_GLASS:15)
B(3,-17,3,STAINED_GLASS:9)
B(0,-17,4,STAINED_GLASS:15)
B(1,-17,4,SEA_LANTERN)
B(2,-17,4,STAINED_GLASS:9)
B(3,-17,4,STAINED_GLASS:15)
B(0,-17,5,STAINED_GLASS:9)
B(1,-17,5,SEA_LANTERN)
B(2,-17,5,STAINED_GLASS:9)
B(3,-17,5,STAINED_GLASS:15)
B(4,-17,5,STAINED_GLASS:15)
B(0,-17,6,STAINED_GLASS:15)
B(1,-17,6,STAINED_GLASS:15)
B(2,-17,6,SEA_LANTERN)
B(3,-17,6,STAINED_GLASS:15)
B(4,-17,6,STAINED_GLASS:15)
B(1,-17,7,STAINED_GLASS:15)
B(2,-17,7,STAINED_GLASS:15)
B(3,-17,7,STAINED_GLASS:15)
B(4,-17,7,STAINED_GLASS:15)
B(5,-17,7,STAINED_GLASS:15)
B(2,-17,8,STAINED_GLASS:15)
B(3,-17,8,STAINED_GLASS:15)
B(4,-17,8,STAINED_GLASS:15)
B(5,-17,8,STAINED_GLASS:15)
B(0,-16,0,STAINED_GLASS:15)
B(1,-16,0,STAINED_GLASS:15)
B(2,-16,0,STAINED_GLASS:15)
B(0,-16,1,STAINED_GLASS:15)
B(1,-16,1,STAINED_GLASS:15)
B(2,-16,1,STAINED_GLASS:15)
B(0,-16,2,STAINED_GLASS:15)
B(1,-16,2,STAINED_GLASS:9)
B(2,-16,2,STAINED_GLASS:15)
B(0,-16,3,STAINED_GLASS:15)
B(1,-16,3,SEA_LANTERN)
B(2,-16,3,STAINED_GLASS:9)
B(3,-16,3,STAINED_GLASS:11)
B(0,-16,4,SEA_LANTERN)
B(1,-16,4,SEA_LANTERN)
B(2,-16,4,SEA_LANTERN)
B(3,-16,4,STAINED_GLASS:11)
B(4,-16,4,STAINED_GLASS:15)
B(0,-16,5,STAINED_GLASS:15)
B(1,-16,5,SEA_LANTERN)
B(2,-16,5,SEA_LANTERN)
B(3,-16,5,STAINED_GLASS:15)
B(4,-16,5,STAINED_GLASS:15)
B(0,-16,6,STAINED_GLASS:15)
B(1,-16,6,STAINED_GLASS:15)
B(2,-16,6,STAINED_GLASS:15)
B(3,-16,6,STAINED_GLASS:15)
B(4,-16,6,STAINED_GLASS:15)
B(1,-16,7,STAINED_GLASS:15)
B(2,-16,7,STAINED_GLASS:15)
B(3,-16,7,STAINED_GLASS:15)
B(4,-16,7,STAINED_GLASS:15)
B(2,-16,8,STAINED_GLASS:15)
B(3,-16,8,STAINED_GLASS:15)
B(4,-16,8,STAINED_GLASS:15)
B(0,-15,0,STAINED_GLASS:15)
B(1,-15,0,STAINED_GLASS:15)
B(2,-15,0,STAINED_GLASS:15)
B(0,-15,1,STAINED_GLASS:9)
B(1,-15,1,STAINED_GLASS:15)
B(2,-15,1,STAINED_GLASS:15)
B(0,-15,2,SEA_LANTERN)
B(1,-15,2,SEA_LANTERN)
B(2,-15,2,STAINED_GLASS:11)
B(0,-15,3,SEA_LANTERN)
B(1,-15,3,SEA_LANTERN)
B(2,-15,3,SEA_LANTERN)
B(3,-15,3,STAINED_GLASS:11)
B(0,-15,4,STAINED_GLASS:15)
B(1,-15,4,SEA_LANTERN)
B(2,-15,4,STAINED_GLASS:11)
B(3,-15,4,STAINED_GLASS:11)
B(4,-15,4,STAINED_GLASS:9)
B(0,-15,5,STAINED_GLASS:10)
B(1,-15,5,SEA_LANTERN)
B(2,-15,5,STAINED_GLASS:15)
B(3,-15,5,STAINED_GLASS:15)
B(4,-15,5,STAINED_GLASS:15)
B(0,-15,6,STAINED_GLASS:15)
B(1,-15,6,STAINED_GLASS:15)
B(2,-15,6,STAINED_GLASS:15)
B(3,-15,6,STAINED_GLASS:15)
B(4,-15,6,STAINED_GLASS:15)
B(0,-15,7,STAINED_GLASS:15)
B(1,-15,7,STAINED_GLASS:15)
B(2,-15,7,STAINED_GLASS:15)
B(3,-15,7,STAINED_GLASS:15)
B(4,-15,7,STAINED_GLASS:15)
B(0,-14,0,STAINED_GLASS:9)
B(1,-14,0,STAINED_GLASS:15)
B(2,-14,0,STAINED_GLASS:15)
B(0,-14,1,SEA_LANTERN)
B(1,-14,1,STAINED_GLASS:11)
B(2,-14,1,STAINED_GLASS:11)
B(0,-14,2,SEA_LANTERN)
B(1,-14,2,STAINED_GLASS:10)
B(2,-14,2,STAINED_GLASS:11)
B(0,-14,3,SEA_LANTERN)
B(1,-14,3,SEA_LANTERN)
B(2,-14,3,STAINED_GLASS:10)
B(3,-14,3,STAINED_GLASS:11)
B(0,-14,4,STAINED_GLASS:10)
B(1,-14,4,STAINED_GLASS:15)
B(2,-14,4,STAINED_GLASS:11)
B(3,-14,4,STAINED_GLASS:11)
B(0,-14,5,STAINED_GLASS:10)
B(1,-14,5,STAINED_GLASS:15)
B(2,-14,5,STAINED_GLASS:11)
B(3,-14,5,STAINED_GLASS:11)
B(0,-14,6,STAINED_GLASS:15)
B(1,-14,6,STAINED_GLASS:15)
B(2,-14,6,STAINED_GLASS:15)
B(3,-14,6,STAINED_GLASS:15)
B(0,-13,0,SEA_LANTERN)
B(1,-13,0,STAINED_GLASS:15)
B(2,-13,0,STAINED_GLASS:15)
B(0,-13,1,STAINED_GLASS:10)
B(1,-13,1,STAINED_GLASS:11)
B(2,-13,1,STAINED_GLASS:11)
B(0,-13,2,SEA_LANTERN)
B(1,-13,2,STAINED_GLASS:10)
B(2,-13,2,STAINED_GLASS:11)
B(0,-13,3,SEA_LANTERN)
B(1,-13,3,STAINED_GLASS:11)
B(2,-13,3,STAINED_GLASS:11)
B(3,-13,3,STAINED_GLASS:11)
B(0,-13,4,STAINED_GLASS:10)
B(1,-13,4,STAINED_GLASS:11)
B(0,-13,5,STAINED_GLASS:15)
B(0,-12,0,STAINED_GLASS:10)
B(1,-12,0,STAINED_GLASS:15)
B(2,-12,0,STAINED_GLASS:11)
B(0,-12,1,STAINED_GLASS:11)
B(1,-12,1,STAINED_GLASS:11)
B(2,-12,1,STAINED_GLASS:11)
B(0,-12,2,STAINED_GLASS:11)
B(1,-12,2,STAINED_GLASS:11)
B(0,-12,3,STAINED_GLASS:11)
B(0,-11,0,STAINED_GLASS:10)
B(1,-11,0,STAINED_GLASS:10)

