
#######################################################################
# +-----------------------------------------------------------------+ #
# |                            BO4 object                           | #
# +-----------------------------------------------------------------+ #
#######################################################################

Author: NLBlackEagle

Description: No description given

SettingsMode: WriteWithoutComments


#######################################################################
# +-----------------------------------------------------------------+ #
# |                          Main settings                          | #
# +-----------------------------------------------------------------+ #
#######################################################################

FixedRotation: 

Frequency: 0

SpawnHeight: highestBlock

UseCenterForHighestBlock: true

##############################
# Height Limits for the BO4. #
##############################

MinHeight: 0

MaxHeight: 255

InheritBO3: 

InheritBO3Rotation: NORTH

OverrideChildSettings: true

OverrideParentHeight: false

CanOverride: false

BranchFrequency: 0

BranchFrequencyGroup: 

MustBeBelowOther: false

MustBeInside: 

CannotBeInside: 

ReplacesBO3: 

MustBeInsideWorldBorders: false

CanSpawnOnWater: true

SpawnOnWaterOnly: false

SpawnUnderWater: false

SpawnAtWaterLevel: false

HeightOffset: 0

RemoveAir: true

ReplaceAbove: 

ReplaceBelow: 

ReplaceWithBiomeBlocks: true

ReplaceWithSurfaceBlock: GRASS

ReplaceWithGroundBlock: DIRT

ReplaceWithStoneBlock: STONE

SmoothRadius: 0

SmoothHeightOffset: 0

SmoothStartTop: false

SmoothStartWood: false

SmoothingSurfaceBlock: 

SmoothingGroundBlock: 

BO3Group: 

IsSpawnPoint: false

DoReplaceBlocks: true


#######################################################################
# +-----------------------------------------------------------------+ #
# |                              Blocks                             | #
# +-----------------------------------------------------------------+ #
#######################################################################

B(-1,24,-4,minecraft:andesite)
B(-1,25,-4,minecraft:andesite)
B(-1,26,-4,minecraft:andesite)
B(-1,23,-3,minecraft:andesite)
B(-1,24,-3,minecraft:andesite)
B(-1,25,-3,minecraft:andesite)
B(-1,26,-3,minecraft:andesite)
B(-1,27,-3,minecraft:andesite)
B(-1,23,-2,minecraft:andesite)
B(-1,24,-2,minecraft:andesite)
B(-1,25,-2,minecraft:andesite)
B(-1,26,-2,minecraft:andesite)
B(-1,27,-2,minecraft:andesite)
B(-1,23,-1,minecraft:andesite)
B(-1,24,-1,minecraft:andesite)
B(-1,25,-1,minecraft:andesite)
B(-1,26,-1,minecraft:andesite)
B(-1,27,-1,minecraft:andesite)
B(-1,24,0,minecraft:andesite)
B(-1,25,0,minecraft:andesite)
B(-1,26,0,minecraft:andesite)
B(0,23,-5,minecraft:andesite)
B(0,24,-5,minecraft:andesite)
B(0,25,-5,minecraft:andesite)
B(0,26,-5,minecraft:andesite)
B(0,27,-5,minecraft:andesite)
B(0,22,-4,minecraft:andesite)
B(0,23,-4,minecraft:andesite)
B(0,24,-4,minecraft:andesite)
B(0,25,-4,minecraft:andesite)
B(0,26,-4,minecraft:andesite)
B(0,27,-4,minecraft:andesite)
B(0,28,-4,minecraft:andesite)
B(0,22,-3,minecraft:andesite)
B(0,23,-3,minecraft:andesite)
B(0,24,-3,minecraft:andesite)
B(0,25,-3,minecraft:andesite)
B(0,26,-3,minecraft:andesite)
B(0,27,-3,minecraft:andesite)
B(0,28,-3,minecraft:andesite)
B(0,22,-2,minecraft:andesite)
B(0,23,-2,minecraft:andesite)
B(0,24,-2,minecraft:andesite)
B(0,25,-2,minecraft:andesite)
B(0,26,-2,minecraft:andesite)
B(0,27,-2,minecraft:andesite)
B(0,28,-2,minecraft:andesite)
B(0,22,-1,minecraft:andesite)
B(0,23,-1,minecraft:andesite)
B(0,24,-1,minecraft:andesite)
B(0,25,-1,minecraft:andesite)
B(0,26,-1,minecraft:andesite)
B(0,27,-1,minecraft:andesite)
B(0,28,-1,minecraft:andesite)
B(0,22,0,minecraft:andesite)
B(0,23,0,minecraft:andesite)
B(0,24,0,minecraft:andesite)
B(0,25,0,minecraft:andesite)
B(0,26,0,minecraft:andesite)
B(0,27,0,minecraft:andesite)
B(0,28,0,minecraft:andesite)
B(0,23,1,minecraft:andesite)
B(0,24,1,minecraft:andesite)
B(0,25,1,minecraft:andesite)
B(0,26,1,minecraft:andesite)
B(0,27,1,minecraft:andesite)
B(0,24,2,minecraft:andesite)
B(0,25,2,minecraft:andesite)
B(0,26,2,minecraft:andesite)
B(0,27,2,minecraft:andesite)
B(0,28,2,minecraft:andesite)
B(0,24,3,minecraft:andesite)
B(0,25,3,minecraft:andesite)
B(0,26,3,minecraft:andesite)
B(0,27,3,minecraft:andesite)
B(0,28,3,minecraft:andesite)
B(0,24,4,minecraft:andesite)
B(0,25,4,minecraft:andesite)
B(0,26,4,minecraft:andesite)
B(0,27,4,minecraft:andesite)
B(0,28,4,minecraft:andesite)
B(0,25,5,minecraft:andesite)
B(0,26,5,minecraft:andesite)
B(0,27,5,minecraft:andesite)
B(1,23,-6,minecraft:andesite)
B(1,24,-6,minecraft:andesite)
B(1,25,-6,minecraft:andesite)
B(1,26,-6,minecraft:andesite)
B(1,27,-6,minecraft:andesite)
B(1,22,-5,minecraft:andesite)
B(1,23,-5,minecraft:andesite)
B(1,24,-5,minecraft:andesite)
B(1,25,-5,minecraft:andesite)
B(1,26,-5,minecraft:andesite)
B(1,27,-5,minecraft:andesite)
B(1,28,-5,minecraft:andesite)
B(1,21,-4,minecraft:andesite)
B(1,22,-4,minecraft:andesite)
B(1,23,-4,minecraft:andesite)
B(1,24,-4,minecraft:andesite)
B(1,25,-4,minecraft:andesite)
B(1,26,-4,minecraft:andesite)
B(1,27,-4,minecraft:andesite)
B(1,28,-4,minecraft:andesite)
B(1,29,-4,minecraft:andesite)
B(1,21,-3,minecraft:andesite)
B(1,22,-3,minecraft:andesite)
B(1,23,-3,minecraft:andesite)
B(1,24,-3,minecraft:andesite)
B(1,25,-3,minecraft:andesite)
B(1,26,-3,minecraft:andesite)
B(1,27,-3,minecraft:andesite)
B(1,28,-3,minecraft:andesite)
B(1,29,-3,minecraft:andesite)
B(1,30,-3,minecraft:andesite)
B(1,31,-3,minecraft:andesite)
B(1,21,-2,minecraft:andesite)
B(1,22,-2,minecraft:andesite)
B(1,23,-2,minecraft:andesite)
B(1,24,-2,minecraft:andesite)
B(1,25,-2,minecraft:andesite)
B(1,26,-2,minecraft:andesite)
B(1,27,-2,minecraft:andesite)
B(1,28,-2,minecraft:andesite)
B(1,29,-2,minecraft:andesite)
B(1,30,-2,minecraft:andesite)
B(1,31,-2,minecraft:andesite)
B(1,32,-2,minecraft:andesite)
B(1,21,-1,minecraft:andesite)
B(1,22,-1,minecraft:andesite)
B(1,23,-1,minecraft:andesite)
B(1,24,-1,minecraft:andesite)
B(1,25,-1,minecraft:andesite)
B(1,26,-1,minecraft:andesite)
B(1,27,-1,minecraft:andesite)
B(1,28,-1,minecraft:andesite)
B(1,29,-1,minecraft:andesite)
B(1,30,-1,minecraft:andesite)
B(1,31,-1,minecraft:andesite)
B(1,32,-1,minecraft:andesite)
B(1,21,0,minecraft:andesite)
B(1,22,0,minecraft:andesite)
B(1,23,0,minecraft:andesite)
B(1,24,0,minecraft:andesite)
B(1,25,0,minecraft:andesite)
B(1,26,0,minecraft:andesite)
B(1,27,0,minecraft:andesite)
B(1,28,0,minecraft:andesite)
B(1,29,0,minecraft:andesite)
B(1,30,0,minecraft:andesite)
B(1,31,0,minecraft:andesite)
B(1,32,0,minecraft:andesite)
B(1,22,1,minecraft:andesite)
B(1,23,1,minecraft:andesite)
B(1,24,1,minecraft:andesite)
B(1,25,1,minecraft:andesite)
B(1,26,1,minecraft:andesite)
B(1,27,1,minecraft:andesite)
B(1,28,1,minecraft:andesite)
B(1,29,1,minecraft:andesite)
B(1,30,1,minecraft:andesite)
B(1,31,1,minecraft:andesite)
B(1,23,2,minecraft:andesite)
B(1,24,2,minecraft:andesite)
B(1,25,2,minecraft:andesite)
B(1,26,2,minecraft:andesite)
B(1,27,2,minecraft:andesite)
B(1,28,2,minecraft:andesite)
B(1,29,2,minecraft:andesite)
B(1,23,3,minecraft:andesite)
B(1,24,3,minecraft:andesite)
B(1,25,3,minecraft:andesite)
B(1,26,3,minecraft:andesite)
B(1,27,3,minecraft:andesite)
B(1,28,3,minecraft:andesite)
B(1,29,3,minecraft:andesite)
B(1,23,4,minecraft:andesite)
B(1,24,4,minecraft:andesite)
B(1,25,4,minecraft:andesite)
B(1,26,4,minecraft:andesite)
B(1,27,4,minecraft:andesite)
B(1,28,4,minecraft:andesite)
B(1,29,4,minecraft:andesite)
B(1,23,5,minecraft:andesite)
B(1,24,5,minecraft:andesite)
B(1,25,5,minecraft:andesite)
B(1,26,5,minecraft:andesite)
B(1,27,5,minecraft:andesite)
B(1,28,5,minecraft:andesite)
B(1,29,5,minecraft:andesite)
B(1,24,6,minecraft:andesite)
B(1,25,6,minecraft:andesite)
B(1,26,6,minecraft:andesite)
B(1,27,6,minecraft:andesite)
B(1,28,6,minecraft:andesite)
B(2,24,-7,minecraft:andesite)
B(2,25,-7,minecraft:andesite)
B(2,26,-7,minecraft:andesite)
B(2,27,-7,minecraft:andesite)
B(2,28,-7,minecraft:andesite)
B(2,22,-6,minecraft:andesite)
B(2,23,-6,minecraft:andesite)
B(2,24,-6,minecraft:andesite)
B(2,25,-6,minecraft:andesite)
B(2,26,-6,minecraft:andesite)
B(2,27,-6,minecraft:andesite)
B(2,28,-6,minecraft:andesite)
B(2,21,-5,minecraft:andesite)
B(2,22,-5,minecraft:andesite)
B(2,23,-5,minecraft:andesite)
B(2,24,-5,minecraft:andesite)
B(2,25,-5,minecraft:andesite)
B(2,26,-5,minecraft:andesite)
B(2,27,-5,minecraft:andesite)
B(2,28,-5,minecraft:andesite)
B(2,29,-5,minecraft:andesite)
B(2,21,-4,minecraft:andesite)
B(2,22,-4,minecraft:andesite)
B(2,23,-4,minecraft:andesite)
B(2,24,-4,minecraft:andesite)
B(2,25,-4,minecraft:andesite)
B(2,26,-4,minecraft:andesite)
B(2,27,-4,minecraft:andesite)
B(2,28,-4,minecraft:andesite)
B(2,29,-4,minecraft:andesite)
B(2,30,-4,minecraft:andesite)
B(2,31,-4,minecraft:andesite)
B(2,32,-4,minecraft:andesite)
B(2,20,-3,minecraft:andesite)
B(2,21,-3,minecraft:andesite)
B(2,22,-3,minecraft:andesite)
B(2,23,-3,minecraft:andesite)
B(2,24,-3,minecraft:andesite)
B(2,25,-3,minecraft:andesite)
B(2,26,-3,minecraft:andesite)
B(2,27,-3,minecraft:andesite)
B(2,28,-3,minecraft:andesite)
B(2,29,-3,minecraft:andesite)
B(2,30,-3,minecraft:andesite)
B(2,31,-3,minecraft:andesite)
B(2,32,-3,minecraft:andesite)
B(2,33,-3,minecraft:andesite)
B(2,20,-2,minecraft:andesite)
B(2,21,-2,minecraft:andesite)
B(2,22,-2,minecraft:andesite)
B(2,23,-2,minecraft:andesite)
B(2,24,-2,minecraft:andesite)
B(2,25,-2,minecraft:andesite)
B(2,26,-2,minecraft:andesite)
B(2,27,-2,minecraft:andesite)
B(2,28,-2,minecraft:andesite)
B(2,29,-2,minecraft:andesite)
B(2,30,-2,minecraft:andesite)
B(2,31,-2,minecraft:andesite)
B(2,32,-2,minecraft:andesite)
B(2,33,-2,minecraft:andesite)
B(2,20,-1,minecraft:andesite)
B(2,21,-1,minecraft:andesite)
B(2,22,-1,minecraft:andesite)
B(2,23,-1,minecraft:andesite)
B(2,24,-1,minecraft:andesite)
B(2,25,-1,minecraft:andesite)
B(2,26,-1,minecraft:andesite)
B(2,27,-1,minecraft:andesite)
B(2,28,-1,minecraft:andesite)
B(2,29,-1,minecraft:andesite)
B(2,30,-1,minecraft:andesite)
B(2,31,-1,minecraft:andesite)
B(2,32,-1,minecraft:andesite)
B(2,33,-1,minecraft:andesite)
B(2,21,0,minecraft:andesite)
B(2,22,0,minecraft:andesite)
B(2,23,0,minecraft:andesite)
B(2,24,0,minecraft:andesite)
B(2,25,0,minecraft:andesite)
B(2,26,0,minecraft:andesite)
B(2,27,0,minecraft:andesite)
B(2,28,0,minecraft:andesite)
B(2,29,0,minecraft:andesite)
B(2,30,0,minecraft:andesite)
B(2,31,0,minecraft:andesite)
B(2,32,0,minecraft:andesite)
B(2,33,0,minecraft:andesite)
B(2,21,1,minecraft:andesite)
B(2,22,1,minecraft:andesite)
B(2,23,1,minecraft:andesite)
B(2,24,1,minecraft:andesite)
B(2,25,1,minecraft:andesite)
B(2,26,1,minecraft:andesite)
B(2,27,1,minecraft:andesite)
B(2,28,1,minecraft:andesite)
B(2,29,1,minecraft:andesite)
B(2,30,1,minecraft:andesite)
B(2,31,1,minecraft:andesite)
B(2,32,1,minecraft:andesite)
B(2,33,1,minecraft:andesite)
B(2,21,2,minecraft:andesite)
B(2,22,2,minecraft:andesite)
B(2,23,2,minecraft:andesite)
B(2,24,2,minecraft:andesite)
B(2,25,2,minecraft:andesite)
B(2,26,2,minecraft:andesite)
B(2,27,2,minecraft:andesite)
B(2,28,2,minecraft:andesite)
B(2,29,2,minecraft:andesite)
B(2,30,2,minecraft:andesite)
B(2,31,2,minecraft:andesite)
B(2,32,2,minecraft:andesite)
B(2,22,3,minecraft:andesite)
B(2,23,3,minecraft:andesite)
B(2,24,3,minecraft:andesite)
B(2,25,3,minecraft:andesite)
B(2,26,3,minecraft:andesite)
B(2,27,3,minecraft:andesite)
B(2,28,3,minecraft:andesite)
B(2,29,3,minecraft:andesite)
B(2,30,3,minecraft:andesite)
B(2,22,4,minecraft:andesite)
B(2,23,4,minecraft:andesite)
B(2,24,4,minecraft:andesite)
B(2,25,4,minecraft:andesite)
B(2,26,4,minecraft:andesite)
B(2,27,4,minecraft:andesite)
B(2,28,4,minecraft:andesite)
B(2,29,4,minecraft:andesite)
B(2,30,4,minecraft:andesite)
B(2,22,5,minecraft:andesite)
B(2,23,5,minecraft:andesite)
B(2,24,5,minecraft:andesite)
B(2,25,5,minecraft:andesite)
B(2,26,5,minecraft:andesite)
B(2,27,5,minecraft:andesite)
B(2,28,5,minecraft:andesite)
B(2,29,5,minecraft:andesite)
B(2,30,5,minecraft:andesite)
B(2,23,6,minecraft:andesite)
B(2,24,6,minecraft:andesite)
B(2,25,6,minecraft:andesite)
B(2,26,6,minecraft:andesite)
B(2,27,6,minecraft:andesite)
B(2,28,6,minecraft:andesite)
B(2,29,6,minecraft:andesite)
B(2,24,7,minecraft:andesite)
B(2,25,7,minecraft:andesite)
B(2,26,7,minecraft:andesite)
B(2,27,7,minecraft:andesite)
B(2,28,7,minecraft:andesite)
B(3,22,-7,minecraft:andesite)
B(3,23,-7,minecraft:andesite)
B(3,24,-7,minecraft:andesite)
B(3,25,-7,minecraft:andesite)
B(3,26,-7,minecraft:andesite)
B(3,27,-7,minecraft:andesite)
B(3,28,-7,minecraft:andesite)
B(3,29,-7,minecraft:andesite)
B(3,22,-6,minecraft:andesite)
B(3,23,-6,minecraft:andesite)
B(3,24,-6,minecraft:andesite)
B(3,25,-6,minecraft:andesite)
B(3,26,-6,minecraft:andesite)
B(3,27,-6,minecraft:andesite)
B(3,28,-6,minecraft:andesite)
B(3,29,-6,minecraft:andesite)
B(3,21,-5,minecraft:andesite)
B(3,22,-5,minecraft:andesite)
B(3,23,-5,minecraft:andesite)
B(3,24,-5,minecraft:andesite)
B(3,25,-5,minecraft:andesite)
B(3,26,-5,minecraft:andesite)
B(3,27,-5,minecraft:andesite)
B(3,28,-5,minecraft:andesite)
B(3,29,-5,minecraft:andesite)
B(3,30,-5,minecraft:andesite)
B(3,31,-5,minecraft:andesite)
B(3,32,-5,minecraft:andesite)
B(3,20,-4,minecraft:andesite)
B(3,21,-4,minecraft:andesite)
B(3,22,-4,minecraft:andesite)
B(3,23,-4,minecraft:andesite)
B(3,24,-4,minecraft:andesite)
B(3,25,-4,minecraft:andesite)
B(3,26,-4,minecraft:andesite)
B(3,27,-4,minecraft:andesite)
B(3,28,-4,minecraft:andesite)
B(3,29,-4,minecraft:andesite)
B(3,30,-4,minecraft:andesite)
B(3,31,-4,minecraft:andesite)
B(3,32,-4,minecraft:andesite)
B(3,33,-4,minecraft:andesite)
B(3,20,-3,minecraft:andesite)
B(3,21,-3,minecraft:andesite)
B(3,22,-3,minecraft:andesite)
B(3,23,-3,minecraft:andesite)
B(3,24,-3,minecraft:andesite)
B(3,25,-3,minecraft:andesite)
B(3,26,-3,minecraft:andesite)
B(3,27,-3,minecraft:andesite)
B(3,28,-3,minecraft:andesite)
B(3,29,-3,minecraft:andesite)
B(3,30,-3,minecraft:andesite)
B(3,31,-3,minecraft:andesite)
B(3,32,-3,minecraft:andesite)
B(3,33,-3,minecraft:andesite)
B(3,34,-3,minecraft:andesite)
B(3,20,-2,minecraft:andesite)
B(3,21,-2,minecraft:andesite)
B(3,22,-2,minecraft:andesite)
B(3,23,-2,minecraft:andesite)
B(3,24,-2,minecraft:andesite)
B(3,25,-2,minecraft:andesite)
B(3,26,-2,minecraft:andesite)
B(3,27,-2,minecraft:andesite)
B(3,28,-2,minecraft:andesite)
B(3,29,-2,minecraft:andesite)
B(3,30,-2,minecraft:andesite)
B(3,31,-2,minecraft:andesite)
B(3,32,-2,minecraft:andesite)
B(3,33,-2,minecraft:andesite)
B(3,34,-2,minecraft:andesite)
B(3,20,-1,minecraft:andesite)
B(3,21,-1,minecraft:andesite)
B(3,22,-1,minecraft:andesite)
B(3,23,-1,minecraft:andesite)
B(3,24,-1,minecraft:andesite)
B(3,25,-1,minecraft:andesite)
B(3,26,-1,minecraft:andesite)
B(3,27,-1,minecraft:andesite)
B(3,28,-1,minecraft:andesite)
B(3,29,-1,minecraft:andesite)
B(3,30,-1,minecraft:andesite)
B(3,31,-1,minecraft:andesite)
B(3,32,-1,minecraft:andesite)
B(3,33,-1,minecraft:andesite)
B(3,34,-1,minecraft:andesite)
B(3,20,0,minecraft:andesite)
B(3,21,0,minecraft:andesite)
B(3,22,0,minecraft:andesite)
B(3,23,0,minecraft:andesite)
B(3,24,0,minecraft:andesite)
B(3,25,0,minecraft:andesite)
B(3,26,0,minecraft:andesite)
B(3,27,0,minecraft:andesite)
B(3,28,0,minecraft:andesite)
B(3,29,0,minecraft:andesite)
B(3,30,0,minecraft:andesite)
B(3,31,0,minecraft:andesite)
B(3,32,0,minecraft:andesite)
B(3,33,0,minecraft:andesite)
B(3,34,0,minecraft:andesite)
B(3,21,1,minecraft:andesite)
B(3,22,1,minecraft:andesite)
B(3,23,1,minecraft:andesite)
B(3,24,1,minecraft:andesite)
B(3,25,1,minecraft:andesite)
B(3,26,1,minecraft:andesite)
B(3,27,1,minecraft:andesite)
B(3,28,1,minecraft:andesite)
B(3,29,1,minecraft:andesite)
B(3,30,1,minecraft:andesite)
B(3,31,1,minecraft:andesite)
B(3,32,1,minecraft:andesite)
B(3,33,1,minecraft:andesite)
B(3,34,1,minecraft:andesite)
B(3,21,2,minecraft:andesite)
B(3,22,2,minecraft:andesite)
B(3,23,2,minecraft:andesite)
B(3,24,2,minecraft:andesite)
B(3,25,2,minecraft:andesite)
B(3,26,2,minecraft:andesite)
B(3,27,2,minecraft:andesite)
B(3,28,2,minecraft:andesite)
B(3,29,2,minecraft:andesite)
B(3,30,2,minecraft:andesite)
B(3,31,2,minecraft:andesite)
B(3,32,2,minecraft:andesite)
B(3,33,2,minecraft:andesite)
B(3,21,3,minecraft:andesite)
B(3,22,3,minecraft:andesite)
B(3,23,3,minecraft:andesite)
B(3,24,3,minecraft:andesite)
B(3,25,3,minecraft:andesite)
B(3,26,3,minecraft:andesite)
B(3,27,3,minecraft:andesite)
B(3,28,3,minecraft:andesite)
B(3,29,3,minecraft:andesite)
B(3,30,3,minecraft:andesite)
B(3,31,3,minecraft:andesite)
B(3,32,3,minecraft:andesite)
B(3,21,4,minecraft:andesite)
B(3,22,4,minecraft:andesite)
B(3,23,4,minecraft:andesite)
B(3,24,4,minecraft:andesite)
B(3,25,4,minecraft:andesite)
B(3,26,4,minecraft:andesite)
B(3,27,4,minecraft:andesite)
B(3,28,4,minecraft:andesite)
B(3,29,4,minecraft:andesite)
B(3,30,4,minecraft:andesite)
B(3,31,4,minecraft:andesite)
B(3,22,5,minecraft:andesite)
B(3,23,5,minecraft:andesite)
B(3,24,5,minecraft:andesite)
B(3,25,5,minecraft:andesite)
B(3,26,5,minecraft:andesite)
B(3,27,5,minecraft:andesite)
B(3,28,5,minecraft:andesite)
B(3,29,5,minecraft:andesite)
B(3,30,5,minecraft:andesite)
B(3,22,6,minecraft:andesite)
B(3,23,6,minecraft:andesite)
B(3,24,6,minecraft:andesite)
B(3,25,6,minecraft:andesite)
B(3,26,6,minecraft:andesite)
B(3,27,6,minecraft:andesite)
B(3,28,6,minecraft:andesite)
B(3,29,6,minecraft:andesite)
B(3,30,6,minecraft:andesite)
B(3,23,7,minecraft:andesite)
B(3,24,7,minecraft:andesite)
B(3,25,7,minecraft:andesite)
B(3,26,7,minecraft:andesite)
B(3,27,7,minecraft:andesite)
B(3,28,7,minecraft:andesite)
B(3,29,7,minecraft:andesite)
B(3,25,8,minecraft:andesite)
B(3,26,8,minecraft:andesite)
B(3,27,8,minecraft:andesite)
B(3,28,8,minecraft:andesite)
B(3,29,8,minecraft:andesite)
B(4,20,-7,minecraft:andesite)
B(4,21,-7,minecraft:andesite)
B(4,22,-7,minecraft:andesite)
B(4,23,-7,minecraft:andesite)
B(4,24,-7,minecraft:andesite)
B(4,25,-7,minecraft:andesite)
B(4,26,-7,minecraft:andesite)
B(4,27,-7,minecraft:andesite)
B(4,28,-7,minecraft:andesite)
B(4,29,-7,minecraft:andesite)
B(4,30,-7,minecraft:andesite)
B(4,31,-7,minecraft:andesite)
B(4,32,-7,minecraft:andesite)
B(4,19,-6,minecraft:andesite)
B(4,20,-6,minecraft:andesite)
B(4,21,-6,minecraft:andesite)
B(4,22,-6,minecraft:andesite)
B(4,23,-6,minecraft:andesite)
B(4,24,-6,minecraft:andesite)
B(4,25,-6,minecraft:andesite)
B(4,26,-6,minecraft:andesite)
B(4,27,-6,minecraft:andesite)
B(4,28,-6,minecraft:andesite)
B(4,29,-6,minecraft:andesite)
B(4,30,-6,minecraft:andesite)
B(4,31,-6,minecraft:andesite)
B(4,32,-6,minecraft:andesite)
B(4,33,-6,minecraft:andesite)
B(4,19,-5,minecraft:andesite)
B(4,20,-5,minecraft:andesite)
B(4,21,-5,minecraft:andesite)
B(4,22,-5,minecraft:andesite)
B(4,23,-5,minecraft:andesite)
B(4,24,-5,minecraft:andesite)
B(4,25,-5,minecraft:andesite)
B(4,26,-5,minecraft:andesite)
B(4,27,-5,minecraft:andesite)
B(4,28,-5,minecraft:andesite)
B(4,29,-5,minecraft:andesite)
B(4,30,-5,minecraft:andesite)
B(4,31,-5,minecraft:andesite)
B(4,32,-5,minecraft:andesite)
B(4,33,-5,minecraft:andesite)
B(4,19,-4,minecraft:andesite)
B(4,20,-4,minecraft:andesite)
B(4,21,-4,minecraft:andesite)
B(4,22,-4,minecraft:andesite)
B(4,23,-4,minecraft:andesite)
B(4,24,-4,minecraft:andesite)
B(4,25,-4,minecraft:andesite)
B(4,26,-4,minecraft:andesite)
B(4,27,-4,minecraft:andesite)
B(4,28,-4,minecraft:andesite)
B(4,29,-4,minecraft:andesite)
B(4,30,-4,minecraft:andesite)
B(4,31,-4,minecraft:andesite)
B(4,32,-4,minecraft:andesite)
B(4,33,-4,minecraft:andesite)
B(4,34,-4,minecraft:andesite)
B(4,19,-3,minecraft:andesite)
B(4,20,-3,minecraft:andesite)
B(4,21,-3,minecraft:andesite)
B(4,22,-3,minecraft:andesite)
B(4,23,-3,minecraft:andesite)
B(4,24,-3,minecraft:andesite)
B(4,25,-3,minecraft:andesite)
B(4,26,-3,minecraft:andesite)
B(4,27,-3,minecraft:andesite)
B(4,28,-3,minecraft:andesite)
B(4,29,-3,minecraft:andesite)
B(4,30,-3,minecraft:andesite)
B(4,31,-3,minecraft:andesite)
B(4,32,-3,minecraft:andesite)
B(4,33,-3,minecraft:andesite)
B(4,34,-3,minecraft:andesite)
B(4,20,-2,minecraft:andesite)
B(4,21,-2,minecraft:andesite)
B(4,22,-2,minecraft:andesite)
B(4,23,-2,minecraft:andesite)
B(4,24,-2,minecraft:andesite)
B(4,25,-2,minecraft:andesite)
B(4,26,-2,minecraft:andesite)
B(4,27,-2,minecraft:andesite)
B(4,28,-2,minecraft:andesite)
B(4,29,-2,minecraft:andesite)
B(4,30,-2,minecraft:andesite)
B(4,31,-2,minecraft:andesite)
B(4,32,-2,minecraft:andesite)
B(4,33,-2,minecraft:andesite)
B(4,34,-2,minecraft:andesite)
B(4,35,-2,minecraft:andesite)
B(4,20,-1,minecraft:andesite)
B(4,21,-1,minecraft:andesite)
B(4,22,-1,minecraft:andesite)
B(4,23,-1,minecraft:andesite)
B(4,24,-1,minecraft:andesite)
B(4,25,-1,minecraft:andesite)
B(4,26,-1,minecraft:andesite)
B(4,27,-1,minecraft:andesite)
B(4,28,-1,minecraft:andesite)
B(4,29,-1,minecraft:andesite)
B(4,30,-1,minecraft:andesite)
B(4,31,-1,minecraft:andesite)
B(4,32,-1,minecraft:andesite)
B(4,33,-1,minecraft:andesite)
B(4,34,-1,minecraft:andesite)
B(4,35,-1,minecraft:andesite)
B(4,20,0,minecraft:andesite)
B(4,21,0,minecraft:andesite)
B(4,22,0,minecraft:andesite)
B(4,23,0,minecraft:andesite)
B(4,24,0,minecraft:andesite)
B(4,25,0,minecraft:andesite)
B(4,26,0,minecraft:andesite)
B(4,27,0,minecraft:andesite)
B(4,28,0,minecraft:andesite)
B(4,29,0,minecraft:andesite)
B(4,30,0,minecraft:andesite)
B(4,31,0,minecraft:andesite)
B(4,32,0,minecraft:andesite)
B(4,33,0,minecraft:andesite)
B(4,34,0,minecraft:andesite)
B(4,35,0,minecraft:andesite)
B(4,21,1,minecraft:andesite)
B(4,22,1,minecraft:andesite)
B(4,23,1,minecraft:andesite)
B(4,24,1,minecraft:andesite)
B(4,25,1,minecraft:andesite)
B(4,26,1,minecraft:andesite)
B(4,27,1,minecraft:andesite)
B(4,28,1,minecraft:andesite)
B(4,29,1,minecraft:andesite)
B(4,30,1,minecraft:andesite)
B(4,31,1,minecraft:andesite)
B(4,32,1,minecraft:andesite)
B(4,33,1,minecraft:andesite)
B(4,34,1,minecraft:andesite)
B(4,21,2,minecraft:andesite)
B(4,22,2,minecraft:andesite)
B(4,23,2,minecraft:andesite)
B(4,24,2,minecraft:andesite)
B(4,25,2,minecraft:andesite)
B(4,26,2,minecraft:andesite)
B(4,27,2,minecraft:andesite)
B(4,28,2,minecraft:andesite)
B(4,29,2,minecraft:andesite)
B(4,30,2,minecraft:andesite)
B(4,31,2,minecraft:andesite)
B(4,32,2,minecraft:andesite)
B(4,33,2,minecraft:andesite)
B(4,34,2,minecraft:andesite)
B(4,21,3,minecraft:andesite)
B(4,22,3,minecraft:andesite)
B(4,23,3,minecraft:andesite)
B(4,24,3,minecraft:andesite)
B(4,25,3,minecraft:andesite)
B(4,26,3,minecraft:andesite)
B(4,27,3,minecraft:andesite)
B(4,28,3,minecraft:andesite)
B(4,29,3,minecraft:andesite)
B(4,30,3,minecraft:andesite)
B(4,31,3,minecraft:andesite)
B(4,32,3,minecraft:andesite)
B(4,33,3,minecraft:andesite)
B(4,21,4,minecraft:andesite)
B(4,22,4,minecraft:andesite)
B(4,23,4,minecraft:andesite)
B(4,24,4,minecraft:andesite)
B(4,25,4,minecraft:andesite)
B(4,26,4,minecraft:andesite)
B(4,27,4,minecraft:andesite)
B(4,28,4,minecraft:andesite)
B(4,29,4,minecraft:andesite)
B(4,30,4,minecraft:andesite)
B(4,31,4,minecraft:andesite)
B(4,21,5,minecraft:andesite)
B(4,22,5,minecraft:andesite)
B(4,23,5,minecraft:andesite)
B(4,24,5,minecraft:andesite)
B(4,25,5,minecraft:andesite)
B(4,26,5,minecraft:andesite)
B(4,27,5,minecraft:andesite)
B(4,28,5,minecraft:andesite)
B(4,29,5,minecraft:andesite)
B(4,30,5,minecraft:andesite)
B(4,31,5,minecraft:andesite)
B(4,22,6,minecraft:andesite)
B(4,23,6,minecraft:andesite)
B(4,24,6,minecraft:andesite)
B(4,25,6,minecraft:andesite)
B(4,26,6,minecraft:andesite)
B(4,27,6,minecraft:andesite)
B(4,28,6,minecraft:andesite)
B(4,29,6,minecraft:andesite)
B(4,30,6,minecraft:andesite)
B(4,23,7,minecraft:andesite)
B(4,24,7,minecraft:andesite)
B(4,25,7,minecraft:andesite)
B(4,26,7,minecraft:andesite)
B(4,27,7,minecraft:andesite)
B(4,28,7,minecraft:andesite)
B(4,29,7,minecraft:andesite)
B(4,30,7,minecraft:andesite)
B(4,24,8,minecraft:andesite)
B(4,25,8,minecraft:andesite)
B(4,26,8,minecraft:andesite)
B(4,27,8,minecraft:andesite)
B(4,28,8,minecraft:andesite)
B(4,29,8,minecraft:andesite)
B(4,30,8,minecraft:andesite)
B(5,18,-7,minecraft:andesite)
B(5,19,-7,minecraft:andesite)
B(5,20,-7,minecraft:andesite)
B(5,21,-7,minecraft:andesite)
B(5,22,-7,minecraft:andesite)
B(5,23,-7,minecraft:andesite)
B(5,24,-7,minecraft:andesite)
B(5,25,-7,minecraft:andesite)
B(5,26,-7,minecraft:andesite)
B(5,27,-7,minecraft:andesite)
B(5,28,-7,minecraft:andesite)
B(5,29,-7,minecraft:andesite)
B(5,30,-7,minecraft:andesite)
B(5,31,-7,minecraft:andesite)
B(5,32,-7,minecraft:andesite)
B(5,33,-7,minecraft:andesite)
B(5,34,-7,minecraft:andesite)
B(5,18,-6,minecraft:andesite)
B(5,19,-6,minecraft:andesite)
B(5,20,-6,minecraft:andesite)
B(5,21,-6,minecraft:andesite)
B(5,22,-6,minecraft:andesite)
B(5,23,-6,minecraft:andesite)
B(5,24,-6,minecraft:andesite)
B(5,25,-6,minecraft:andesite)
B(5,26,-6,minecraft:andesite)
B(5,27,-6,minecraft:andesite)
B(5,28,-6,minecraft:andesite)
B(5,29,-6,minecraft:andesite)
B(5,30,-6,minecraft:andesite)
B(5,31,-6,minecraft:andesite)
B(5,32,-6,minecraft:andesite)
B(5,33,-6,minecraft:andesite)
B(5,34,-6,minecraft:andesite)
B(5,18,-5,minecraft:andesite)
B(5,19,-5,minecraft:andesite)
B(5,20,-5,minecraft:andesite)
B(5,21,-5,minecraft:andesite)
B(5,22,-5,minecraft:andesite)
B(5,23,-5,minecraft:andesite)
B(5,24,-5,minecraft:andesite)
B(5,25,-5,minecraft:andesite)
B(5,26,-5,minecraft:andesite)
B(5,27,-5,minecraft:andesite)
B(5,28,-5,minecraft:andesite)
B(5,29,-5,minecraft:andesite)
B(5,30,-5,minecraft:andesite)
B(5,31,-5,minecraft:andesite)
B(5,32,-5,minecraft:andesite)
B(5,33,-5,minecraft:andesite)
B(5,34,-5,minecraft:andesite)
B(5,18,-4,minecraft:andesite)
B(5,19,-4,minecraft:andesite)
B(5,20,-4,minecraft:andesite)
B(5,21,-4,minecraft:andesite)
B(5,22,-4,minecraft:andesite)
B(5,23,-4,minecraft:andesite)
B(5,24,-4,minecraft:andesite)
B(5,25,-4,minecraft:andesite)
B(5,26,-4,minecraft:andesite)
B(5,27,-4,minecraft:andesite)
B(5,28,-4,minecraft:andesite)
B(5,29,-4,minecraft:andesite)
B(5,30,-4,minecraft:andesite)
B(5,31,-4,minecraft:andesite)
B(5,32,-4,minecraft:andesite)
B(5,33,-4,minecraft:andesite)
B(5,34,-4,minecraft:andesite)
B(5,18,-3,minecraft:andesite)
B(5,19,-3,minecraft:andesite)
B(5,20,-3,minecraft:andesite)
B(5,21,-3,minecraft:andesite)
B(5,22,-3,minecraft:andesite)
B(5,23,-3,minecraft:andesite)
B(5,24,-3,minecraft:andesite)
B(5,25,-3,minecraft:andesite)
B(5,26,-3,minecraft:andesite)
B(5,27,-3,minecraft:andesite)
B(5,28,-3,minecraft:andesite)
B(5,29,-3,minecraft:andesite)
B(5,30,-3,minecraft:andesite)
B(5,31,-3,minecraft:andesite)
B(5,32,-3,minecraft:andesite)
B(5,33,-3,minecraft:andesite)
B(5,34,-3,minecraft:andesite)
B(5,35,-3,minecraft:andesite)
B(5,19,-2,minecraft:andesite)
B(5,20,-2,minecraft:andesite)
B(5,21,-2,minecraft:andesite)
B(5,22,-2,minecraft:andesite)
B(5,23,-2,minecraft:andesite)
B(5,24,-2,minecraft:andesite)
B(5,25,-2,minecraft:andesite)
B(5,26,-2,minecraft:andesite)
B(5,27,-2,minecraft:andesite)
B(5,28,-2,minecraft:andesite)
B(5,29,-2,minecraft:andesite)
B(5,30,-2,minecraft:andesite)
B(5,31,-2,minecraft:andesite)
B(5,32,-2,minecraft:andesite)
B(5,33,-2,minecraft:andesite)
B(5,34,-2,minecraft:andesite)
B(5,35,-2,minecraft:andesite)
B(5,20,-1,minecraft:andesite)
B(5,21,-1,minecraft:andesite)
B(5,22,-1,minecraft:andesite)
B(5,23,-1,minecraft:andesite)
B(5,24,-1,minecraft:andesite)
B(5,25,-1,minecraft:andesite)
B(5,26,-1,minecraft:andesite)
B(5,27,-1,minecraft:andesite)
B(5,28,-1,minecraft:andesite)
B(5,29,-1,minecraft:andesite)
B(5,30,-1,minecraft:andesite)
B(5,31,-1,minecraft:andesite)
B(5,32,-1,minecraft:andesite)
B(5,33,-1,minecraft:andesite)
B(5,34,-1,minecraft:andesite)
B(5,35,-1,minecraft:andesite)
B(5,20,0,minecraft:andesite)
B(5,21,0,minecraft:andesite)
B(5,22,0,minecraft:andesite)
B(5,23,0,minecraft:andesite)
B(5,24,0,minecraft:andesite)
B(5,25,0,minecraft:andesite)
B(5,26,0,minecraft:stone)
B(5,27,0,minecraft:andesite)
B(5,28,0,minecraft:andesite)
B(5,29,0,minecraft:andesite)
B(5,30,0,minecraft:andesite)
B(5,31,0,minecraft:andesite)
B(5,32,0,minecraft:andesite)
B(5,33,0,minecraft:andesite)
B(5,34,0,minecraft:andesite)
B(5,35,0,minecraft:andesite)
B(5,21,1,minecraft:andesite)
B(5,22,1,minecraft:andesite)
B(5,23,1,minecraft:andesite)
B(5,24,1,minecraft:andesite)
B(5,25,1,minecraft:andesite)
B(5,26,1,minecraft:andesite)
B(5,27,1,minecraft:andesite)
B(5,28,1,minecraft:andesite)
B(5,29,1,minecraft:andesite)
B(5,30,1,minecraft:andesite)
B(5,31,1,minecraft:andesite)
B(5,32,1,minecraft:andesite)
B(5,33,1,minecraft:andesite)
B(5,34,1,minecraft:andesite)
B(5,35,1,minecraft:andesite)
B(5,21,2,minecraft:andesite)
B(5,22,2,minecraft:andesite)
B(5,23,2,minecraft:andesite)
B(5,24,2,minecraft:andesite)
B(5,25,2,minecraft:andesite)
B(5,26,2,minecraft:andesite)
B(5,27,2,minecraft:andesite)
B(5,28,2,minecraft:andesite)
B(5,29,2,minecraft:andesite)
B(5,30,2,minecraft:andesite)
B(5,31,2,minecraft:andesite)
B(5,32,2,minecraft:andesite)
B(5,33,2,minecraft:andesite)
B(5,34,2,minecraft:andesite)
B(5,35,2,minecraft:andesite)
B(5,36,2,minecraft:andesite)
B(5,21,3,minecraft:andesite)
B(5,22,3,minecraft:andesite)
B(5,23,3,minecraft:andesite)
B(5,24,3,minecraft:andesite)
B(5,25,3,minecraft:andesite)
B(5,26,3,minecraft:andesite)
B(5,27,3,minecraft:andesite)
B(5,28,3,minecraft:andesite)
B(5,29,3,minecraft:andesite)
B(5,30,3,minecraft:andesite)
B(5,31,3,minecraft:andesite)
B(5,32,3,minecraft:andesite)
B(5,33,3,minecraft:andesite)
B(5,34,3,minecraft:andesite)
B(5,35,3,minecraft:andesite)
B(5,36,3,minecraft:andesite)
B(5,21,4,minecraft:andesite)
B(5,22,4,minecraft:andesite)
B(5,23,4,minecraft:andesite)
B(5,24,4,minecraft:andesite)
B(5,25,4,minecraft:andesite)
B(5,26,4,minecraft:andesite)
B(5,27,4,minecraft:andesite)
B(5,28,4,minecraft:andesite)
B(5,29,4,minecraft:andesite)
B(5,30,4,minecraft:andesite)
B(5,31,4,minecraft:andesite)
B(5,32,4,minecraft:andesite)
B(5,33,4,minecraft:andesite)
B(5,34,4,minecraft:andesite)
B(5,35,4,minecraft:andesite)
B(5,36,4,minecraft:andesite)
B(5,21,5,minecraft:andesite)
B(5,22,5,minecraft:andesite)
B(5,23,5,minecraft:andesite)
B(5,24,5,minecraft:andesite)
B(5,25,5,minecraft:andesite)
B(5,26,5,minecraft:andesite)
B(5,27,5,minecraft:andesite)
B(5,28,5,minecraft:andesite)
B(5,29,5,minecraft:andesite)
B(5,30,5,minecraft:andesite)
B(5,31,5,minecraft:andesite)
B(5,33,5,minecraft:andesite)
B(5,34,5,minecraft:andesite)
B(5,35,5,minecraft:andesite)
B(5,22,6,minecraft:andesite)
B(5,23,6,minecraft:andesite)
B(5,24,6,minecraft:andesite)
B(5,25,6,minecraft:andesite)
B(5,26,6,minecraft:andesite)
B(5,27,6,minecraft:andesite)
B(5,28,6,minecraft:andesite)
B(5,29,6,minecraft:andesite)
B(5,30,6,minecraft:andesite)
B(5,31,6,minecraft:andesite)
B(5,22,7,minecraft:andesite)
B(5,23,7,minecraft:andesite)
B(5,24,7,minecraft:andesite)
B(5,25,7,minecraft:andesite)
B(5,26,7,minecraft:andesite)
B(5,27,7,minecraft:andesite)
B(5,28,7,minecraft:andesite)
B(5,29,7,minecraft:andesite)
B(5,30,7,minecraft:andesite)
B(5,31,7,minecraft:andesite)
B(5,23,8,minecraft:andesite)
B(5,24,8,minecraft:andesite)
B(5,25,8,minecraft:andesite)
B(5,26,8,minecraft:andesite)
B(5,27,8,minecraft:andesite)
B(5,28,8,minecraft:andesite)
B(5,29,8,minecraft:andesite)
B(5,30,8,minecraft:andesite)
B(5,31,8,minecraft:andesite)
B(6,17,-7,minecraft:andesite)
B(6,18,-7,minecraft:andesite)
B(6,19,-7,minecraft:andesite)
B(6,20,-7,minecraft:andesite)
B(6,21,-7,minecraft:andesite)
B(6,22,-7,minecraft:andesite)
B(6,23,-7,minecraft:andesite)
B(6,24,-7,minecraft:andesite)
B(6,25,-7,minecraft:andesite)
B(6,26,-7,minecraft:andesite)
B(6,27,-7,minecraft:andesite)
B(6,28,-7,minecraft:andesite)
B(6,29,-7,minecraft:andesite)
B(6,30,-7,minecraft:andesite)
B(6,31,-7,minecraft:andesite)
B(6,32,-7,minecraft:andesite)
B(6,33,-7,minecraft:andesite)
B(6,34,-7,minecraft:andesite)
B(6,35,-7,minecraft:andesite)
B(6,17,-6,minecraft:andesite)
B(6,18,-6,minecraft:andesite)
B(6,19,-6,minecraft:andesite)
B(6,20,-6,minecraft:andesite)
B(6,21,-6,minecraft:andesite)
B(6,22,-6,minecraft:andesite)
B(6,23,-6,minecraft:andesite)
B(6,24,-6,minecraft:andesite)
B(6,25,-6,minecraft:andesite)
B(6,26,-6,minecraft:andesite)
B(6,27,-6,minecraft:andesite)
B(6,28,-6,minecraft:andesite)
B(6,29,-6,minecraft:andesite)
B(6,30,-6,minecraft:andesite)
B(6,31,-6,minecraft:andesite)
B(6,32,-6,minecraft:andesite)
B(6,33,-6,minecraft:andesite)
B(6,34,-6,minecraft:andesite)
B(6,35,-6,minecraft:andesite)
B(6,17,-5,minecraft:andesite)
B(6,18,-5,minecraft:andesite)
B(6,19,-5,minecraft:andesite)
B(6,20,-5,minecraft:andesite)
B(6,21,-5,minecraft:andesite)
B(6,22,-5,minecraft:andesite)
B(6,23,-5,minecraft:andesite)
B(6,24,-5,minecraft:andesite)
B(6,25,-5,minecraft:andesite)
B(6,26,-5,minecraft:andesite)
B(6,27,-5,minecraft:andesite)
B(6,28,-5,minecraft:andesite)
B(6,29,-5,minecraft:andesite)
B(6,30,-5,minecraft:andesite)
B(6,31,-5,minecraft:andesite)
B(6,32,-5,minecraft:andesite)
B(6,33,-5,minecraft:andesite)
B(6,34,-5,minecraft:andesite)
B(6,35,-5,minecraft:andesite)
B(6,17,-4,minecraft:andesite)
B(6,18,-4,minecraft:andesite)
B(6,19,-4,minecraft:andesite)
B(6,20,-4,minecraft:andesite)
B(6,21,-4,minecraft:andesite)
B(6,22,-4,minecraft:andesite)
B(6,23,-4,minecraft:andesite)
B(6,24,-4,minecraft:andesite)
B(6,25,-4,minecraft:andesite)
B(6,26,-4,minecraft:andesite)
B(6,27,-4,minecraft:andesite)
B(6,28,-4,minecraft:andesite)
B(6,29,-4,minecraft:andesite)
B(6,30,-4,minecraft:andesite)
B(6,31,-4,minecraft:andesite)
B(6,32,-4,minecraft:andesite)
B(6,33,-4,minecraft:andesite)
B(6,34,-4,minecraft:andesite)
B(6,35,-4,minecraft:andesite)
B(6,17,-3,minecraft:andesite)
B(6,18,-3,minecraft:andesite)
B(6,19,-3,minecraft:andesite)
B(6,20,-3,minecraft:andesite)
B(6,21,-3,minecraft:andesite)
B(6,22,-3,minecraft:andesite)
B(6,23,-3,minecraft:andesite)
B(6,24,-3,minecraft:andesite)
B(6,25,-3,minecraft:andesite)
B(6,26,-3,minecraft:stone)
B(6,27,-3,minecraft:stone)
B(6,28,-3,minecraft:andesite)
B(6,29,-3,minecraft:andesite)
B(6,30,-3,minecraft:andesite)
B(6,31,-3,minecraft:andesite)
B(6,32,-3,minecraft:andesite)
B(6,33,-3,minecraft:andesite)
B(6,34,-3,minecraft:andesite)
B(6,35,-3,minecraft:andesite)
B(6,18,-2,minecraft:andesite)
B(6,19,-2,minecraft:andesite)
B(6,20,-2,minecraft:andesite)
B(6,21,-2,minecraft:andesite)
B(6,22,-2,minecraft:andesite)
B(6,23,-2,minecraft:andesite)
B(6,24,-2,minecraft:andesite)
B(6,25,-2,minecraft:stone)
B(6,26,-2,minecraft:stone)
B(6,27,-2,minecraft:stone)
B(6,28,-2,minecraft:andesite)
B(6,29,-2,minecraft:andesite)
B(6,30,-2,minecraft:andesite)
B(6,31,-2,minecraft:andesite)
B(6,32,-2,minecraft:andesite)
B(6,33,-2,minecraft:andesite)
B(6,34,-2,minecraft:andesite)
B(6,35,-2,minecraft:andesite)
B(6,19,-1,minecraft:andesite)
B(6,20,-1,minecraft:andesite)
B(6,21,-1,minecraft:andesite)
B(6,22,-1,minecraft:andesite)
B(6,23,-1,minecraft:andesite)
B(6,24,-1,minecraft:andesite)
B(6,25,-1,minecraft:stone)
B(6,26,-1,minecraft:stone)
B(6,27,-1,minecraft:stone)
B(6,28,-1,minecraft:stone)
B(6,29,-1,minecraft:andesite)
B(6,30,-1,minecraft:andesite)
B(6,31,-1,minecraft:andesite)
B(6,32,-1,minecraft:andesite)
B(6,33,-1,minecraft:andesite)
B(6,34,-1,minecraft:andesite)
B(6,35,-1,minecraft:andesite)
B(6,20,0,minecraft:andesite)
B(6,21,0,minecraft:andesite)
B(6,22,0,minecraft:andesite)
B(6,23,0,minecraft:andesite)
B(6,24,0,minecraft:andesite)
B(6,25,0,minecraft:stone)
B(6,26,0,minecraft:stone)
B(6,27,0,minecraft:stone)
B(6,28,0,minecraft:andesite)
B(6,29,0,minecraft:andesite)
B(6,30,0,minecraft:andesite)
B(6,31,0,minecraft:andesite)
B(6,32,0,minecraft:andesite)
B(6,33,0,minecraft:andesite)
B(6,34,0,minecraft:andesite)
B(6,35,0,minecraft:andesite)
B(6,36,0,minecraft:andesite)
B(6,20,1,minecraft:andesite)
B(6,21,1,minecraft:andesite)
B(6,22,1,minecraft:andesite)
B(6,23,1,minecraft:andesite)
B(6,24,1,minecraft:andesite)
B(6,25,1,minecraft:stone)
B(6,26,1,minecraft:stone)
B(6,27,1,minecraft:andesite)
B(6,28,1,minecraft:andesite)
B(6,29,1,minecraft:andesite)
B(6,30,1,minecraft:andesite)
B(6,31,1,minecraft:andesite)
B(6,32,1,minecraft:andesite)
B(6,33,1,minecraft:andesite)
B(6,34,1,minecraft:andesite)
B(6,35,1,minecraft:andesite)
B(6,36,1,minecraft:andesite)
B(6,37,1,minecraft:andesite)
B(6,21,2,minecraft:andesite)
B(6,22,2,minecraft:andesite)
B(6,23,2,minecraft:andesite)
B(6,24,2,minecraft:andesite)
B(6,25,2,minecraft:andesite)
B(6,26,2,minecraft:stone)
B(6,27,2,minecraft:andesite)
B(6,28,2,minecraft:andesite)
B(6,29,2,minecraft:andesite)
B(6,30,2,minecraft:andesite)
B(6,31,2,minecraft:andesite)
B(6,32,2,minecraft:andesite)
B(6,33,2,minecraft:andesite)
B(6,34,2,minecraft:andesite)
B(6,35,2,minecraft:andesite)
B(6,36,2,minecraft:andesite)
B(6,37,2,minecraft:andesite)
B(6,21,3,minecraft:andesite)
B(6,22,3,minecraft:andesite)
B(6,23,3,minecraft:andesite)
B(6,24,3,minecraft:andesite)
B(6,25,3,minecraft:andesite)
B(6,26,3,minecraft:andesite)
B(6,27,3,minecraft:andesite)
B(6,28,3,minecraft:andesite)
B(6,29,3,minecraft:andesite)
B(6,30,3,minecraft:andesite)
B(6,31,3,minecraft:andesite)
B(6,32,3,minecraft:andesite)
B(6,33,3,minecraft:andesite)
B(6,34,3,minecraft:andesite)
B(6,35,3,minecraft:andesite)
B(6,36,3,minecraft:andesite)
B(6,37,3,minecraft:andesite)
B(6,21,4,minecraft:andesite)
B(6,22,4,minecraft:andesite)
B(6,23,4,minecraft:andesite)
B(6,24,4,minecraft:andesite)
B(6,25,4,minecraft:andesite)
B(6,26,4,minecraft:andesite)
B(6,27,4,minecraft:andesite)
B(6,28,4,minecraft:andesite)
B(6,29,4,minecraft:andesite)
B(6,30,4,minecraft:andesite)
B(6,31,4,minecraft:andesite)
B(6,32,4,minecraft:andesite)
B(6,33,4,minecraft:andesite)
B(6,34,4,minecraft:andesite)
B(6,35,4,minecraft:andesite)
B(6,36,4,minecraft:andesite)
B(6,37,4,minecraft:andesite)
B(6,21,5,minecraft:andesite)
B(6,22,5,minecraft:andesite)
B(6,23,5,minecraft:andesite)
B(6,24,5,minecraft:andesite)
B(6,25,5,minecraft:andesite)
B(6,26,5,minecraft:andesite)
B(6,27,5,minecraft:andesite)
B(6,28,5,minecraft:andesite)
B(6,29,5,minecraft:andesite)
B(6,30,5,minecraft:andesite)
B(6,31,5,minecraft:andesite)
B(6,32,5,minecraft:andesite)
B(6,33,5,minecraft:andesite)
B(6,34,5,minecraft:andesite)
B(6,35,5,minecraft:andesite)
B(6,36,5,minecraft:andesite)
B(6,37,5,minecraft:andesite)
B(6,22,6,minecraft:andesite)
B(6,23,6,minecraft:andesite)
B(6,24,6,minecraft:andesite)
B(6,25,6,minecraft:andesite)
B(6,26,6,minecraft:andesite)
B(6,27,6,minecraft:andesite)
B(6,28,6,minecraft:andesite)
B(6,29,6,minecraft:andesite)
B(6,30,6,minecraft:andesite)
B(6,31,6,minecraft:andesite)
B(6,32,6,minecraft:andesite)
B(6,33,6,minecraft:andesite)
B(6,34,6,minecraft:andesite)
B(6,35,6,minecraft:andesite)
B(6,36,6,minecraft:andesite)
B(6,22,7,minecraft:andesite)
B(6,23,7,minecraft:andesite)
B(6,24,7,minecraft:andesite)
B(6,25,7,minecraft:andesite)
B(6,26,7,minecraft:andesite)
B(6,27,7,minecraft:andesite)
B(6,28,7,minecraft:andesite)
B(6,29,7,minecraft:andesite)
B(6,30,7,minecraft:andesite)
B(6,31,7,minecraft:andesite)
B(6,32,7,minecraft:andesite)
B(6,22,8,minecraft:andesite)
B(6,23,8,minecraft:andesite)
B(6,24,8,minecraft:andesite)
B(6,25,8,minecraft:andesite)
B(6,26,8,minecraft:andesite)
B(6,27,8,minecraft:andesite)
B(6,28,8,minecraft:andesite)
B(6,29,8,minecraft:andesite)
B(6,30,8,minecraft:andesite)
B(6,31,8,minecraft:andesite)
B(6,32,8,minecraft:andesite)
B(7,17,-7,minecraft:andesite)
B(7,18,-7,minecraft:andesite)
B(7,19,-7,minecraft:andesite)
B(7,20,-7,minecraft:andesite)
B(7,21,-7,minecraft:andesite)
B(7,22,-7,minecraft:andesite)
B(7,23,-7,minecraft:andesite)
B(7,24,-7,minecraft:andesite)
B(7,25,-7,minecraft:andesite)
B(7,26,-7,minecraft:andesite)
B(7,27,-7,minecraft:andesite)
B(7,28,-7,minecraft:andesite)
B(7,29,-7,minecraft:andesite)
B(7,30,-7,minecraft:andesite)
B(7,31,-7,minecraft:andesite)
B(7,32,-7,minecraft:andesite)
B(7,33,-7,minecraft:andesite)
B(7,34,-7,minecraft:andesite)
B(7,35,-7,minecraft:andesite)
B(7,16,-6,minecraft:andesite)
B(7,17,-6,minecraft:andesite)
B(7,18,-6,minecraft:andesite)
B(7,19,-6,minecraft:andesite)
B(7,20,-6,minecraft:andesite)
B(7,21,-6,minecraft:andesite)
B(7,22,-6,minecraft:andesite)
B(7,23,-6,minecraft:andesite)
B(7,24,-6,minecraft:andesite)
B(7,25,-6,minecraft:andesite)
B(7,26,-6,minecraft:andesite)
B(7,27,-6,minecraft:andesite)
B(7,28,-6,minecraft:andesite)
B(7,29,-6,minecraft:andesite)
B(7,30,-6,minecraft:andesite)
B(7,31,-6,minecraft:andesite)
B(7,32,-6,minecraft:andesite)
B(7,33,-6,minecraft:andesite)
B(7,34,-6,minecraft:andesite)
B(7,35,-6,minecraft:andesite)
B(7,36,-6,minecraft:andesite)
B(7,16,-5,minecraft:andesite)
B(7,17,-5,minecraft:andesite)
B(7,18,-5,minecraft:andesite)
B(7,19,-5,minecraft:andesite)
B(7,20,-5,minecraft:andesite)
B(7,21,-5,minecraft:andesite)
B(7,22,-5,minecraft:andesite)
B(7,23,-5,minecraft:andesite)
B(7,24,-5,minecraft:andesite)
B(7,25,-5,minecraft:andesite)
B(7,26,-5,minecraft:andesite)
B(7,27,-5,minecraft:stone)
B(7,28,-5,minecraft:stone)
B(7,29,-5,minecraft:andesite)
B(7,30,-5,minecraft:andesite)
B(7,31,-5,minecraft:andesite)
B(7,32,-5,minecraft:andesite)
B(7,33,-5,minecraft:andesite)
B(7,34,-5,minecraft:andesite)
B(7,35,-5,minecraft:andesite)
B(7,36,-5,minecraft:andesite)
B(7,16,-4,minecraft:andesite)
B(7,17,-4,minecraft:andesite)
B(7,18,-4,minecraft:andesite)
B(7,19,-4,minecraft:andesite)
B(7,20,-4,minecraft:andesite)
B(7,21,-4,minecraft:andesite)
B(7,22,-4,minecraft:andesite)
B(7,23,-4,minecraft:andesite)
B(7,24,-4,minecraft:andesite)
B(7,25,-4,minecraft:stone)
B(7,26,-4,minecraft:stone)
B(7,27,-4,minecraft:stone)
B(7,28,-4,minecraft:stone)
B(7,29,-4,minecraft:andesite)
B(7,30,-4,minecraft:andesite)
B(7,31,-4,minecraft:andesite)
B(7,32,-4,minecraft:andesite)
B(7,33,-4,minecraft:andesite)
B(7,34,-4,minecraft:andesite)
B(7,35,-4,minecraft:andesite)
B(7,36,-4,minecraft:andesite)
B(7,17,-3,minecraft:andesite)
B(7,18,-3,minecraft:andesite)
B(7,19,-3,minecraft:andesite)
B(7,20,-3,minecraft:andesite)
B(7,21,-3,minecraft:andesite)
B(7,22,-3,minecraft:andesite)
B(7,23,-3,minecraft:andesite)
B(7,24,-3,minecraft:andesite)
B(7,25,-3,minecraft:stone)
B(7,26,-3,minecraft:stone)
B(7,27,-3,minecraft:stone)
B(7,28,-3,minecraft:stone)
B(7,29,-3,minecraft:andesite)
B(7,30,-3,minecraft:andesite)
B(7,31,-3,minecraft:andesite)
B(7,32,-3,minecraft:andesite)
B(7,33,-3,minecraft:andesite)
B(7,34,-3,minecraft:andesite)
B(7,35,-3,minecraft:andesite)
B(7,36,-3,minecraft:andesite)
B(7,37,-3,minecraft:andesite)
B(7,17,-2,minecraft:andesite)
B(7,18,-2,minecraft:andesite)
B(7,19,-2,minecraft:andesite)
B(7,20,-2,minecraft:andesite)
B(7,21,-2,minecraft:andesite)
B(7,22,-2,minecraft:andesite)
B(7,23,-2,minecraft:andesite)
B(7,24,-2,minecraft:stone)
B(7,25,-2,minecraft:stone)
B(7,26,-2,minecraft:stone)
B(7,27,-2,minecraft:stone)
B(7,28,-2,minecraft:stone)
B(7,29,-2,minecraft:stone)
B(7,30,-2,minecraft:andesite)
B(7,31,-2,minecraft:andesite)
B(7,32,-2,minecraft:andesite)
B(7,33,-2,minecraft:andesite)
B(7,34,-2,minecraft:andesite)
B(7,35,-2,minecraft:andesite)
B(7,36,-2,minecraft:andesite)
B(7,37,-2,minecraft:andesite)
B(7,18,-1,minecraft:andesite)
B(7,19,-1,minecraft:andesite)
B(7,20,-1,minecraft:andesite)
B(7,21,-1,minecraft:andesite)
B(7,22,-1,minecraft:andesite)
B(7,23,-1,minecraft:andesite)
B(7,24,-1,minecraft:stone)
B(7,25,-1,minecraft:stone)
B(7,26,-1,minecraft:stone)
B(7,27,-1,minecraft:stone)
B(7,28,-1,minecraft:stone)
B(7,29,-1,minecraft:stone)
B(7,30,-1,minecraft:stone)
B(7,31,-1,minecraft:andesite)
B(7,32,-1,minecraft:andesite)
B(7,33,-1,minecraft:andesite)
B(7,34,-1,minecraft:andesite)
B(7,35,-1,minecraft:andesite)
B(7,36,-1,minecraft:andesite)
B(7,37,-1,minecraft:andesite)
B(7,19,0,minecraft:andesite)
B(7,20,0,minecraft:andesite)
B(7,21,0,minecraft:andesite)
B(7,22,0,minecraft:andesite)
B(7,23,0,minecraft:andesite)
B(7,24,0,minecraft:stone)
B(7,25,0,minecraft:stone)
B(7,26,0,minecraft:stone)
B(7,27,0,minecraft:stone)
B(7,28,0,minecraft:stone)
B(7,29,0,minecraft:stone)
B(7,30,0,minecraft:stone)
B(7,31,0,minecraft:stone)
B(7,32,0,minecraft:andesite)
B(7,33,0,minecraft:andesite)
B(7,34,0,minecraft:andesite)
B(7,35,0,minecraft:andesite)
B(7,36,0,minecraft:andesite)
B(7,37,0,minecraft:andesite)
B(7,20,1,minecraft:andesite)
B(7,21,1,minecraft:andesite)
B(7,22,1,minecraft:andesite)
B(7,23,1,minecraft:andesite)
B(7,24,1,minecraft:stone)
B(7,25,1,minecraft:stone)
B(7,26,1,minecraft:stone)
B(7,27,1,minecraft:stone)
B(7,28,1,minecraft:stone)
B(7,29,1,minecraft:andesite)
B(7,30,1,minecraft:andesite)
B(7,31,1,minecraft:andesite)
B(7,32,1,minecraft:andesite)
B(7,33,1,minecraft:andesite)
B(7,34,1,minecraft:andesite)
B(7,35,1,minecraft:andesite)
B(7,36,1,minecraft:andesite)
B(7,37,1,minecraft:andesite)
B(7,38,1,minecraft:andesite)
B(7,20,2,minecraft:andesite)
B(7,21,2,minecraft:andesite)
B(7,22,2,minecraft:andesite)
B(7,23,2,minecraft:andesite)
B(7,24,2,minecraft:andesite)
B(7,25,2,minecraft:stone)
B(7,26,2,minecraft:stone)
B(7,27,2,minecraft:stone)
B(7,28,2,minecraft:andesite)
B(7,29,2,minecraft:andesite)
B(7,30,2,minecraft:andesite)
B(7,31,2,minecraft:andesite)
B(7,32,2,minecraft:andesite)
B(7,33,2,minecraft:andesite)
B(7,34,2,minecraft:andesite)
B(7,35,2,minecraft:andesite)
B(7,36,2,minecraft:andesite)
B(7,37,2,minecraft:andesite)
B(7,38,2,minecraft:andesite)
B(7,20,3,minecraft:andesite)
B(7,21,3,minecraft:andesite)
B(7,22,3,minecraft:andesite)
B(7,23,3,minecraft:andesite)
B(7,24,3,minecraft:andesite)
B(7,25,3,minecraft:andesite)
B(7,26,3,minecraft:stone)
B(7,27,3,minecraft:stone)
B(7,28,3,minecraft:andesite)
B(7,29,3,minecraft:andesite)
B(7,30,3,minecraft:andesite)
B(7,31,3,minecraft:andesite)
B(7,32,3,minecraft:andesite)
B(7,33,3,minecraft:andesite)
B(7,34,3,minecraft:andesite)
B(7,35,3,minecraft:andesite)
B(7,36,3,minecraft:andesite)
B(7,37,3,minecraft:andesite)
B(7,38,3,minecraft:andesite)
B(7,20,4,minecraft:andesite)
B(7,21,4,minecraft:andesite)
B(7,22,4,minecraft:andesite)
B(7,23,4,minecraft:andesite)
B(7,24,4,minecraft:andesite)
B(7,25,4,minecraft:andesite)
B(7,26,4,minecraft:andesite)
B(7,27,4,minecraft:stone)
B(7,28,4,minecraft:andesite)
B(7,29,4,minecraft:andesite)
B(7,30,4,minecraft:andesite)
B(7,31,4,minecraft:andesite)
B(7,32,4,minecraft:andesite)
B(7,33,4,minecraft:andesite)
B(7,34,4,minecraft:andesite)
B(7,35,4,minecraft:andesite)
B(7,36,4,minecraft:andesite)
B(7,37,4,minecraft:andesite)
B(7,38,4,minecraft:andesite)
B(7,20,5,minecraft:andesite)
B(7,21,5,minecraft:andesite)
B(7,22,5,minecraft:andesite)
B(7,23,5,minecraft:andesite)
B(7,24,5,minecraft:andesite)
B(7,25,5,minecraft:andesite)
B(7,26,5,minecraft:andesite)
B(7,27,5,minecraft:andesite)
B(7,28,5,minecraft:andesite)
B(7,29,5,minecraft:andesite)
B(7,30,5,minecraft:andesite)
B(7,31,5,minecraft:andesite)
B(7,32,5,minecraft:andesite)
B(7,33,5,minecraft:andesite)
B(7,34,5,minecraft:andesite)
B(7,35,5,minecraft:andesite)
B(7,36,5,minecraft:andesite)
B(7,37,5,minecraft:andesite)
B(7,38,5,minecraft:andesite)
B(7,21,6,minecraft:andesite)
B(7,22,6,minecraft:andesite)
B(7,23,6,minecraft:andesite)
B(7,24,6,minecraft:andesite)
B(7,25,6,minecraft:andesite)
B(7,26,6,minecraft:andesite)
B(7,27,6,minecraft:andesite)
B(7,28,6,minecraft:stone)
B(7,29,6,minecraft:andesite)
B(7,30,6,minecraft:andesite)
B(7,31,6,minecraft:andesite)
B(7,32,6,minecraft:andesite)
B(7,33,6,minecraft:andesite)
B(7,34,6,minecraft:andesite)
B(7,35,6,minecraft:andesite)
B(7,36,6,minecraft:andesite)
B(7,37,6,minecraft:andesite)
B(7,22,7,minecraft:andesite)
B(7,23,7,minecraft:andesite)
B(7,24,7,minecraft:andesite)
B(7,25,7,minecraft:andesite)
B(7,26,7,minecraft:andesite)
B(7,27,7,minecraft:andesite)
B(7,28,7,minecraft:stone)
B(7,29,7,minecraft:andesite)
B(7,30,7,minecraft:andesite)
B(7,31,7,minecraft:andesite)
B(7,32,7,minecraft:andesite)
B(7,33,7,minecraft:andesite)
B(7,34,7,minecraft:andesite)
B(7,35,7,minecraft:andesite)
B(7,36,7,minecraft:andesite)
B(7,22,8,minecraft:andesite)
B(7,23,8,minecraft:andesite)
B(7,24,8,minecraft:andesite)
B(7,25,8,minecraft:andesite)
B(7,26,8,minecraft:andesite)
B(7,27,8,minecraft:andesite)
B(7,28,8,minecraft:andesite)
B(7,29,8,minecraft:andesite)
B(7,30,8,minecraft:andesite)
B(7,31,8,minecraft:andesite)
B(7,32,8,minecraft:andesite)
B(7,33,8,minecraft:andesite)
B(7,34,8,minecraft:andesite)

#######################################################################
# +-----------------------------------------------------------------+ #
# |                             Branches                            | #
# +-----------------------------------------------------------------+ #
#######################################################################

Branch(0,0,16,true,Amethyst_MediumC0R7,NORTH,100.0,0)

#######################################################################
# +-----------------------------------------------------------------+ #
# |                             Entities                            | #
# +-----------------------------------------------------------------+ #
#######################################################################

