
#######################################################################
# +-----------------------------------------------------------------+ #
# |                            BO4 object                           | #
# +-----------------------------------------------------------------+ #
#######################################################################

Author: NLBlackEagle

Description: No description given

SettingsMode: WriteWithoutComments


#######################################################################
# +-----------------------------------------------------------------+ #
# |                          Main settings                          | #
# +-----------------------------------------------------------------+ #
#######################################################################

FixedRotation: 

Frequency: 0

SpawnHeight: highestBlock

UseCenterForHighestBlock: true

##############################
# Height Limits for the BO4. #
##############################

MinHeight: 0

MaxHeight: 255

InheritBO3: 

InheritBO3Rotation: NORTH

OverrideChildSettings: true

OverrideParentHeight: false

CanOverride: false

BranchFrequency: 0

BranchFrequencyGroup: 

MustBeBelowOther: false

MustBeInside: 

CannotBeInside: 

ReplacesBO3: 

MustBeInsideWorldBorders: false

CanSpawnOnWater: true

SpawnOnWaterOnly: false

SpawnUnderWater: false

SpawnAtWaterLevel: false

HeightOffset: 0

RemoveAir: true

ReplaceAbove: 

ReplaceBelow: 

ReplaceWithBiomeBlocks: true

ReplaceWithSurfaceBlock: GRASS

ReplaceWithGroundBlock: DIRT

ReplaceWithStoneBlock: STONE

SmoothRadius: 0

SmoothHeightOffset: 0

SmoothStartTop: false

SmoothStartWood: false

SmoothingSurfaceBlock: 

SmoothingGroundBlock: 

BO3Group: 

IsSpawnPoint: false

DoReplaceBlocks: true


#######################################################################
# +-----------------------------------------------------------------+ #
# |                              Blocks                             | #
# +-----------------------------------------------------------------+ #
#######################################################################

B(-5,53,-7,minecraft:andesite)
B(-5,54,-7,minecraft:andesite)
B(-5,55,-7,minecraft:andesite)
B(-5,56,-7,minecraft:andesite)
B(-5,57,-7,minecraft:andesite)
B(-5,53,-6,minecraft:andesite)
B(-5,54,-6,minecraft:andesite)
B(-5,55,-6,minecraft:andesite)
B(-5,56,-6,minecraft:andesite)
B(-5,57,-6,minecraft:andesite)
B(-5,53,-5,minecraft:andesite)
B(-5,54,-5,minecraft:andesite)
B(-5,55,-5,minecraft:andesite)
B(-5,56,-5,minecraft:andesite)
B(-5,57,-5,minecraft:andesite)
B(-5,54,-4,minecraft:andesite)
B(-5,55,-4,minecraft:andesite)
B(-5,56,-4,minecraft:andesite)
B(-4,52,-7,minecraft:andesite)
B(-4,53,-7,minecraft:andesite)
B(-4,54,-7,minecraft:andesite)
B(-4,55,-7,minecraft:andesite)
B(-4,56,-7,minecraft:andesite)
B(-4,57,-7,minecraft:andesite)
B(-4,58,-7,minecraft:andesite)
B(-4,52,-6,minecraft:andesite)
B(-4,53,-6,minecraft:andesite)
B(-4,54,-6,minecraft:andesite)
B(-4,55,-6,minecraft:andesite)
B(-4,56,-6,minecraft:andesite)
B(-4,57,-6,minecraft:andesite)
B(-4,58,-6,minecraft:andesite)
B(-4,52,-5,minecraft:andesite)
B(-4,53,-5,minecraft:andesite)
B(-4,54,-5,minecraft:andesite)
B(-4,55,-5,minecraft:andesite)
B(-4,56,-5,minecraft:andesite)
B(-4,57,-5,minecraft:andesite)
B(-4,58,-5,minecraft:andesite)
B(-4,52,-4,minecraft:andesite)
B(-4,53,-4,minecraft:andesite)
B(-4,54,-4,minecraft:andesite)
B(-4,55,-4,minecraft:andesite)
B(-4,56,-4,minecraft:andesite)
B(-4,57,-4,minecraft:andesite)
B(-4,58,-4,minecraft:andesite)
B(-4,52,-3,minecraft:andesite)
B(-4,53,-3,minecraft:andesite)
B(-4,54,-3,minecraft:andesite)
B(-4,55,-3,minecraft:andesite)
B(-4,56,-3,minecraft:andesite)
B(-4,57,-3,minecraft:andesite)
B(-4,52,-2,minecraft:andesite)
B(-4,53,-2,minecraft:andesite)
B(-4,54,-2,minecraft:andesite)
B(-4,55,-2,minecraft:andesite)
B(-4,56,-2,minecraft:andesite)
B(-4,57,-2,minecraft:andesite)
B(-4,52,-1,minecraft:andesite)
B(-4,53,-1,minecraft:andesite)
B(-4,54,-1,minecraft:andesite)
B(-4,55,-1,minecraft:andesite)
B(-4,56,-1,minecraft:andesite)
B(-4,57,-1,minecraft:diorite)
B(-4,52,0,minecraft:andesite)
B(-4,53,0,minecraft:andesite)
B(-4,54,0,minecraft:andesite)
B(-4,55,0,minecraft:andesite)
B(-4,56,0,minecraft:andesite)
B(-4,57,0,minecraft:diorite)
B(-4,53,1,minecraft:andesite)
B(-4,54,1,minecraft:andesite)
B(-4,55,1,minecraft:andesite)
B(-4,56,1,minecraft:diorite)
B(-3,51,-7,minecraft:andesite)
B(-3,52,-7,minecraft:andesite)
B(-3,53,-7,minecraft:andesite)
B(-3,54,-7,minecraft:andesite)
B(-3,55,-7,minecraft:andesite)
B(-3,56,-7,minecraft:andesite)
B(-3,57,-7,minecraft:andesite)
B(-3,58,-7,minecraft:andesite)
B(-3,59,-7,minecraft:andesite)
B(-3,51,-6,minecraft:andesite)
B(-3,52,-6,minecraft:andesite)
B(-3,53,-6,minecraft:andesite)
B(-3,54,-6,minecraft:andesite)
B(-3,55,-6,minecraft:andesite)
B(-3,56,-6,minecraft:andesite)
B(-3,57,-6,minecraft:andesite)
B(-3,58,-6,minecraft:andesite)
B(-3,59,-6,minecraft:andesite)
B(-3,51,-5,minecraft:andesite)
B(-3,52,-5,minecraft:andesite)
B(-3,53,-5,minecraft:andesite)
B(-3,54,-5,minecraft:andesite)
B(-3,55,-5,minecraft:andesite)
B(-3,56,-5,minecraft:andesite)
B(-3,57,-5,minecraft:andesite)
B(-3,58,-5,minecraft:andesite)
B(-3,59,-5,minecraft:andesite)
B(-3,50,-4,minecraft:andesite)
B(-3,51,-4,minecraft:andesite)
B(-3,52,-4,minecraft:andesite)
B(-3,53,-4,minecraft:andesite)
B(-3,54,-4,minecraft:andesite)
B(-3,55,-4,minecraft:andesite)
B(-3,56,-4,minecraft:andesite)
B(-3,57,-4,minecraft:andesite)
B(-3,58,-4,minecraft:andesite)
B(-3,59,-4,minecraft:andesite)
B(-3,51,-3,minecraft:andesite)
B(-3,52,-3,minecraft:andesite)
B(-3,53,-3,minecraft:andesite)
B(-3,54,-3,minecraft:andesite)
B(-3,55,-3,minecraft:andesite)
B(-3,56,-3,minecraft:andesite)
B(-3,57,-3,minecraft:andesite)
B(-3,58,-3,minecraft:diorite)
B(-3,59,-3,minecraft:diorite)
B(-3,51,-2,minecraft:andesite)
B(-3,52,-2,minecraft:andesite)
B(-3,53,-2,minecraft:andesite)
B(-3,54,-2,minecraft:andesite)
B(-3,55,-2,minecraft:andesite)
B(-3,56,-2,minecraft:andesite)
B(-3,57,-2,minecraft:diorite)
B(-3,58,-2,minecraft:diorite)
B(-3,51,-1,minecraft:andesite)
B(-3,52,-1,minecraft:andesite)
B(-3,53,-1,minecraft:andesite)
B(-3,54,-1,minecraft:andesite)
B(-3,55,-1,minecraft:andesite)
B(-3,56,-1,minecraft:diorite)
B(-3,57,-1,minecraft:diorite)
B(-3,58,-1,minecraft:diorite)
B(-3,51,0,minecraft:andesite)
B(-3,52,0,minecraft:andesite)
B(-3,53,0,minecraft:andesite)
B(-3,54,0,minecraft:andesite)
B(-3,55,0,minecraft:andesite)
B(-3,56,0,minecraft:diorite)
B(-3,57,0,minecraft:diorite)
B(-3,58,0,minecraft:diorite)
B(-3,51,1,minecraft:andesite)
B(-3,52,1,minecraft:andesite)
B(-3,53,1,minecraft:andesite)
B(-3,54,1,minecraft:andesite)
B(-3,55,1,minecraft:diorite)
B(-3,56,1,minecraft:diorite)
B(-3,57,1,minecraft:diorite)
B(-3,58,1,minecraft:diorite)
B(-3,52,2,minecraft:andesite)
B(-3,53,2,minecraft:andesite)
B(-3,54,2,minecraft:andesite)
B(-3,55,2,minecraft:diorite)
B(-3,56,2,minecraft:diorite)
B(-3,57,2,minecraft:diorite)
B(-3,53,3,minecraft:andesite)
B(-2,51,-7,minecraft:andesite)
B(-2,52,-7,minecraft:andesite)
B(-2,53,-7,minecraft:andesite)
B(-2,54,-7,minecraft:andesite)
B(-2,55,-7,minecraft:andesite)
B(-2,56,-7,minecraft:andesite)
B(-2,57,-7,minecraft:andesite)
B(-2,58,-7,minecraft:andesite)
B(-2,59,-7,minecraft:andesite)
B(-2,60,-7,minecraft:andesite)
B(-2,50,-6,minecraft:andesite)
B(-2,51,-6,minecraft:andesite)
B(-2,52,-6,minecraft:andesite)
B(-2,53,-6,minecraft:andesite)
B(-2,54,-6,minecraft:andesite)
B(-2,55,-6,minecraft:andesite)
B(-2,56,-6,minecraft:andesite)
B(-2,57,-6,minecraft:andesite)
B(-2,58,-6,minecraft:andesite)
B(-2,59,-6,minecraft:andesite)
B(-2,60,-6,minecraft:andesite)
B(-2,50,-5,minecraft:andesite)
B(-2,51,-5,minecraft:andesite)
B(-2,52,-5,minecraft:andesite)
B(-2,53,-5,minecraft:andesite)
B(-2,54,-5,minecraft:andesite)
B(-2,55,-5,minecraft:andesite)
B(-2,56,-5,minecraft:andesite)
B(-2,57,-5,minecraft:andesite)
B(-2,58,-5,minecraft:andesite)
B(-2,59,-5,minecraft:andesite)
B(-2,60,-5,minecraft:andesite)
B(-2,49,-4,minecraft:andesite)
B(-2,50,-4,minecraft:andesite)
B(-2,51,-4,minecraft:andesite)
B(-2,52,-4,minecraft:andesite)
B(-2,53,-4,minecraft:andesite)
B(-2,54,-4,minecraft:andesite)
B(-2,55,-4,minecraft:andesite)
B(-2,56,-4,minecraft:andesite)
B(-2,57,-4,minecraft:andesite)
B(-2,58,-4,minecraft:andesite)
B(-2,59,-4,minecraft:diorite)
B(-2,50,-3,minecraft:andesite)
B(-2,51,-3,minecraft:andesite)
B(-2,52,-3,minecraft:andesite)
B(-2,53,-3,minecraft:andesite)
B(-2,54,-3,minecraft:andesite)
B(-2,55,-3,minecraft:andesite)
B(-2,56,-3,minecraft:andesite)
B(-2,57,-3,minecraft:diorite)
B(-2,58,-3,minecraft:diorite)
B(-2,59,-3,minecraft:diorite)
B(-2,50,-2,minecraft:andesite)
B(-2,51,-2,minecraft:andesite)
B(-2,52,-2,minecraft:andesite)
B(-2,53,-2,minecraft:andesite)
B(-2,54,-2,minecraft:andesite)
B(-2,55,-2,minecraft:andesite)
B(-2,56,-2,minecraft:diorite)
B(-2,57,-2,minecraft:diorite)
B(-2,58,-2,minecraft:diorite)
B(-2,59,-2,minecraft:diorite)
B(-2,49,-1,minecraft:andesite)
B(-2,50,-1,minecraft:andesite)
B(-2,51,-1,minecraft:andesite)
B(-2,52,-1,minecraft:andesite)
B(-2,53,-1,minecraft:andesite)
B(-2,54,-1,minecraft:andesite)
B(-2,55,-1,minecraft:andesite)
B(-2,56,-1,minecraft:diorite)
B(-2,57,-1,minecraft:diorite)
B(-2,58,-1,minecraft:diorite)
B(-2,59,-1,minecraft:diorite)
B(-2,50,0,minecraft:andesite)
B(-2,51,0,minecraft:andesite)
B(-2,52,0,minecraft:andesite)
B(-2,53,0,minecraft:andesite)
B(-2,54,0,minecraft:andesite)
B(-2,55,0,minecraft:diorite)
B(-2,56,0,minecraft:diorite)
B(-2,57,0,minecraft:diorite)
B(-2,58,0,minecraft:diorite)
B(-2,50,1,minecraft:andesite)
B(-2,51,1,minecraft:andesite)
B(-2,52,1,minecraft:andesite)
B(-2,53,1,minecraft:andesite)
B(-2,54,1,minecraft:andesite)
B(-2,55,1,minecraft:diorite)
B(-2,56,1,minecraft:diorite)
B(-2,57,1,minecraft:diorite)
B(-2,58,1,minecraft:diorite)
B(-2,59,1,minecraft:diorite)
B(-2,51,2,minecraft:andesite)
B(-2,52,2,minecraft:andesite)
B(-2,53,2,minecraft:andesite)
B(-2,54,2,minecraft:diorite)
B(-2,55,2,minecraft:diorite)
B(-2,56,2,minecraft:diorite)
B(-2,57,2,minecraft:diorite)
B(-2,58,2,minecraft:diorite)
B(-2,52,3,minecraft:andesite)
B(-2,53,3,minecraft:andesite)
B(-2,54,3,minecraft:diorite)
B(-2,55,3,minecraft:diorite)
B(-2,56,3,minecraft:diorite)
B(-2,57,3,minecraft:diorite)
B(-2,52,4,minecraft:andesite)
B(-2,53,4,minecraft:andesite)
B(-2,54,4,minecraft:diorite)
B(-2,55,4,minecraft:diorite)
B(-2,56,4,minecraft:diorite)
B(-2,57,4,minecraft:diorite)
B(-2,53,5,minecraft:andesite)
B(-2,54,5,minecraft:andesite)
B(-2,55,5,minecraft:diorite)
B(-2,56,5,minecraft:diorite)
B(-2,57,5,minecraft:diorite)
B(-2,54,6,minecraft:andesite)
B(-2,55,6,minecraft:diorite)
B(-2,56,6,minecraft:diorite)
B(-1,50,-7,minecraft:andesite)
B(-1,51,-7,minecraft:andesite)
B(-1,52,-7,minecraft:andesite)
B(-1,53,-7,minecraft:andesite)
B(-1,54,-7,minecraft:andesite)
B(-1,55,-7,minecraft:andesite)
B(-1,56,-7,minecraft:andesite)
B(-1,57,-7,minecraft:andesite)
B(-1,58,-7,minecraft:andesite)
B(-1,59,-7,minecraft:andesite)
B(-1,60,-7,minecraft:andesite)
B(-1,50,-6,minecraft:andesite)
B(-1,51,-6,minecraft:andesite)
B(-1,52,-6,minecraft:andesite)
B(-1,53,-6,minecraft:andesite)
B(-1,54,-6,minecraft:andesite)
B(-1,55,-6,minecraft:andesite)
B(-1,56,-6,minecraft:andesite)
B(-1,57,-6,minecraft:andesite)
B(-1,58,-6,minecraft:andesite)
B(-1,59,-6,minecraft:andesite)
B(-1,60,-6,minecraft:andesite)
B(-1,61,-6,minecraft:andesite)
B(-1,62,-6,minecraft:andesite)
B(-1,50,-5,minecraft:andesite)
B(-1,51,-5,minecraft:andesite)
B(-1,52,-5,minecraft:andesite)
B(-1,53,-5,minecraft:andesite)
B(-1,54,-5,minecraft:andesite)
B(-1,55,-5,minecraft:andesite)
B(-1,56,-5,minecraft:andesite)
B(-1,57,-5,minecraft:andesite)
B(-1,58,-5,minecraft:andesite)
B(-1,59,-5,minecraft:andesite)
B(-1,60,-5,minecraft:andesite)
B(-1,61,-5,minecraft:andesite)
B(-1,62,-5,minecraft:andesite)
B(-1,49,-4,minecraft:andesite)
B(-1,50,-4,minecraft:andesite)
B(-1,51,-4,minecraft:andesite)
B(-1,52,-4,minecraft:andesite)
B(-1,53,-4,minecraft:andesite)
B(-1,54,-4,minecraft:andesite)
B(-1,55,-4,minecraft:andesite)
B(-1,56,-4,minecraft:andesite)
B(-1,57,-4,minecraft:andesite)
B(-1,58,-4,minecraft:diorite)
B(-1,59,-4,minecraft:diorite)
B(-1,60,-4,minecraft:diorite)
B(-1,61,-4,minecraft:diorite)
B(-1,62,-4,minecraft:diorite)
B(-1,49,-3,minecraft:andesite)
B(-1,50,-3,minecraft:andesite)
B(-1,51,-3,minecraft:andesite)
B(-1,52,-3,minecraft:andesite)
B(-1,53,-3,minecraft:andesite)
B(-1,54,-3,minecraft:andesite)
B(-1,55,-3,minecraft:andesite)
B(-1,56,-3,minecraft:andesite)
B(-1,57,-3,minecraft:diorite)
B(-1,58,-3,minecraft:diorite)
B(-1,59,-3,minecraft:diorite)
B(-1,60,-3,minecraft:diorite)
B(-1,61,-3,minecraft:diorite)
B(-1,62,-3,minecraft:diorite)
B(-1,48,-2,minecraft:andesite)
B(-1,49,-2,minecraft:andesite)
B(-1,50,-2,minecraft:andesite)
B(-1,51,-2,minecraft:andesite)
B(-1,52,-2,minecraft:andesite)
B(-1,53,-2,minecraft:andesite)
B(-1,54,-2,minecraft:andesite)
B(-1,55,-2,minecraft:andesite)
B(-1,56,-2,minecraft:diorite)
B(-1,57,-2,minecraft:diorite)
B(-1,58,-2,minecraft:diorite)
B(-1,59,-2,minecraft:diorite)
B(-1,60,-2,minecraft:diorite)
B(-1,61,-2,minecraft:diorite)
B(-1,49,-1,minecraft:andesite)
B(-1,50,-1,minecraft:andesite)
B(-1,51,-1,minecraft:andesite)
B(-1,52,-1,minecraft:andesite)
B(-1,53,-1,minecraft:andesite)
B(-1,54,-1,minecraft:andesite)
B(-1,55,-1,minecraft:diorite)
B(-1,56,-1,minecraft:diorite)
B(-1,57,-1,minecraft:diorite)
B(-1,58,-1,minecraft:diorite)
B(-1,59,-1,minecraft:diorite)
B(-1,60,-1,minecraft:diorite)
B(-1,50,0,minecraft:andesite)
B(-1,51,0,minecraft:andesite)
B(-1,52,0,minecraft:andesite)
B(-1,53,0,minecraft:andesite)
B(-1,54,0,minecraft:andesite)
B(-1,55,0,minecraft:diorite)
B(-1,56,0,minecraft:diorite)
B(-1,57,0,minecraft:diorite)
B(-1,58,0,minecraft:diorite)
B(-1,59,0,minecraft:diorite)
B(-1,50,1,minecraft:andesite)
B(-1,51,1,minecraft:andesite)
B(-1,52,1,minecraft:andesite)
B(-1,53,1,minecraft:andesite)
B(-1,54,1,minecraft:diorite)
B(-1,55,1,minecraft:diorite)
B(-1,56,1,minecraft:diorite)
B(-1,57,1,minecraft:diorite)
B(-1,58,1,minecraft:diorite)
B(-1,59,1,minecraft:diorite)
B(-1,51,2,minecraft:andesite)
B(-1,52,2,minecraft:andesite)
B(-1,53,2,minecraft:andesite)
B(-1,54,2,minecraft:diorite)
B(-1,55,2,minecraft:diorite)
B(-1,56,2,minecraft:diorite)
B(-1,57,2,minecraft:diorite)
B(-1,58,2,minecraft:diorite)
B(-1,51,3,minecraft:andesite)
B(-1,52,3,minecraft:andesite)
B(-1,53,3,minecraft:andesite)
B(-1,54,3,minecraft:diorite)
B(-1,55,3,minecraft:diorite)
B(-1,56,3,minecraft:diorite)
B(-1,57,3,minecraft:diorite)
B(-1,58,3,minecraft:diorite)
B(-1,51,4,minecraft:andesite)
B(-1,52,4,minecraft:andesite)
B(-1,53,4,minecraft:andesite)
B(-1,54,4,minecraft:diorite)
B(-1,55,4,minecraft:diorite)
B(-1,56,4,minecraft:diorite)
B(-1,57,4,minecraft:diorite)
B(-1,58,4,minecraft:diorite)
B(-1,52,5,minecraft:andesite)
B(-1,53,5,minecraft:andesite)
B(-1,54,5,minecraft:diorite)
B(-1,55,5,minecraft:diorite)
B(-1,56,5,minecraft:diorite)
B(-1,57,5,minecraft:diorite)
B(-1,58,5,minecraft:diorite)
B(-1,52,6,minecraft:andesite)
B(-1,53,6,minecraft:andesite)
B(-1,54,6,minecraft:andesite)
B(-1,55,6,minecraft:diorite)
B(-1,56,6,minecraft:diorite)
B(-1,57,6,minecraft:diorite)
B(-1,58,6,minecraft:diorite)
B(-1,53,7,minecraft:andesite)
B(-1,54,7,minecraft:diorite)
B(-1,55,7,minecraft:diorite)
B(-1,56,7,minecraft:diorite)
B(-1,57,7,minecraft:diorite)
B(0,50,-7,minecraft:andesite)
B(0,51,-7,minecraft:andesite)
B(0,52,-7,minecraft:andesite)
B(0,53,-7,minecraft:andesite)
B(0,54,-7,minecraft:andesite)
B(0,55,-7,minecraft:andesite)
B(0,56,-7,minecraft:andesite)
B(0,57,-7,minecraft:andesite)
B(0,58,-7,minecraft:andesite)
B(0,59,-7,minecraft:andesite)
B(0,60,-7,minecraft:andesite)
B(0,50,-6,minecraft:andesite)
B(0,51,-6,minecraft:andesite)
B(0,52,-6,minecraft:andesite)
B(0,53,-6,minecraft:andesite)
B(0,54,-6,minecraft:andesite)
B(0,55,-6,minecraft:andesite)
B(0,56,-6,minecraft:andesite)
B(0,57,-6,minecraft:andesite)
B(0,58,-6,minecraft:andesite)
B(0,59,-6,minecraft:andesite)
B(0,60,-6,minecraft:andesite)
B(0,61,-6,minecraft:andesite)
B(0,62,-6,minecraft:andesite)
B(0,49,-5,minecraft:andesite)
B(0,50,-5,minecraft:andesite)
B(0,51,-5,minecraft:andesite)
B(0,52,-5,minecraft:andesite)
B(0,53,-5,minecraft:andesite)
B(0,54,-5,minecraft:andesite)
B(0,55,-5,minecraft:andesite)
B(0,56,-5,minecraft:andesite)
B(0,57,-5,minecraft:andesite)
B(0,58,-5,minecraft:andesite)
B(0,59,-5,minecraft:andesite)
B(0,60,-5,minecraft:andesite)
B(0,61,-5,minecraft:andesite)
B(0,62,-5,minecraft:andesite)
B(0,63,-5,minecraft:andesite)
B(0,49,-4,minecraft:andesite)
B(0,50,-4,minecraft:andesite)
B(0,51,-4,minecraft:andesite)
B(0,52,-4,minecraft:andesite)
B(0,53,-4,minecraft:andesite)
B(0,54,-4,minecraft:andesite)
B(0,55,-4,minecraft:andesite)
B(0,56,-4,minecraft:andesite)
B(0,57,-4,minecraft:andesite)
B(0,58,-4,minecraft:diorite)
B(0,59,-4,minecraft:diorite)
B(0,60,-4,minecraft:diorite)
B(0,61,-4,minecraft:diorite)
B(0,62,-4,minecraft:diorite)
B(0,63,-4,minecraft:andesite)
B(0,48,-3,minecraft:andesite)
B(0,49,-3,minecraft:andesite)
B(0,50,-3,minecraft:andesite)
B(0,51,-3,minecraft:andesite)
B(0,52,-3,minecraft:andesite)
B(0,53,-3,minecraft:andesite)
B(0,54,-3,minecraft:andesite)
B(0,55,-3,minecraft:andesite)
B(0,56,-3,minecraft:andesite)
B(0,57,-3,minecraft:diorite)
B(0,58,-3,minecraft:diorite)
B(0,59,-3,minecraft:diorite)
B(0,60,-3,minecraft:diorite)
B(0,61,-3,minecraft:diorite)
B(0,62,-3,minecraft:diorite)
B(0,63,-3,minecraft:diorite)
B(0,48,-2,minecraft:andesite)
B(0,49,-2,minecraft:andesite)
B(0,50,-2,minecraft:andesite)
B(0,51,-2,minecraft:andesite)
B(0,52,-2,minecraft:andesite)
B(0,53,-2,minecraft:andesite)
B(0,54,-2,minecraft:andesite)
B(0,55,-2,minecraft:andesite)
B(0,56,-2,minecraft:diorite)
B(0,57,-2,minecraft:diorite)
B(0,58,-2,minecraft:diorite)
B(0,59,-2,minecraft:diorite)
B(0,60,-2,minecraft:diorite)
B(0,61,-2,minecraft:diorite)
B(0,62,-2,minecraft:diorite)
B(0,49,-1,minecraft:andesite)
B(0,50,-1,minecraft:andesite)
B(0,51,-1,minecraft:andesite)
B(0,52,-1,minecraft:andesite)
B(0,53,-1,minecraft:andesite)
B(0,54,-1,minecraft:andesite)
B(0,55,-1,minecraft:diorite)
B(0,56,-1,minecraft:diorite)
B(0,57,-1,minecraft:diorite)
B(0,58,-1,minecraft:diorite)
B(0,59,-1,minecraft:diorite)
B(0,60,-1,minecraft:diorite)
B(0,61,-1,minecraft:diorite)
B(0,62,-1,minecraft:diorite)
B(0,50,0,minecraft:andesite)
B(0,51,0,minecraft:andesite)
B(0,52,0,minecraft:andesite)
B(0,53,0,minecraft:andesite)
B(0,54,0,minecraft:andesite)
B(0,55,0,minecraft:diorite)
B(0,56,0,minecraft:diorite)
B(0,57,0,minecraft:diorite)
B(0,58,0,minecraft:diorite)
B(0,59,0,minecraft:diorite)
B(0,60,0,minecraft:diorite)
B(0,61,0,minecraft:diorite)
B(0,50,1,minecraft:andesite)
B(0,51,1,minecraft:andesite)
B(0,52,1,minecraft:andesite)
B(0,53,1,minecraft:andesite)
B(0,54,1,minecraft:diorite)
B(0,55,1,minecraft:diorite)
B(0,56,1,minecraft:diorite)
B(0,57,1,minecraft:diorite)
B(0,58,1,minecraft:diorite)
B(0,59,1,minecraft:diorite)
B(0,60,1,minecraft:diorite)
B(0,50,2,minecraft:andesite)
B(0,51,2,minecraft:andesite)
B(0,52,2,minecraft:andesite)
B(0,53,2,minecraft:andesite)
B(0,54,2,minecraft:diorite)
B(0,55,2,minecraft:diorite)
B(0,56,2,minecraft:diorite)
B(0,57,2,minecraft:diorite)
B(0,58,2,minecraft:diorite)
B(0,59,2,minecraft:diorite)
B(0,50,3,minecraft:andesite)
B(0,51,3,minecraft:andesite)
B(0,52,3,minecraft:andesite)
B(0,53,3,minecraft:andesite)
B(0,54,3,minecraft:diorite)
B(0,55,3,minecraft:diorite)
B(0,56,3,minecraft:diorite)
B(0,57,3,minecraft:diorite)
B(0,58,3,minecraft:diorite)
B(0,59,3,minecraft:diorite)
B(0,50,4,minecraft:andesite)
B(0,51,4,minecraft:andesite)
B(0,52,4,minecraft:andesite)
B(0,53,4,minecraft:andesite)
B(0,54,4,minecraft:diorite)
B(0,55,4,minecraft:diorite)
B(0,56,4,minecraft:diorite)
B(0,57,4,minecraft:diorite)
B(0,58,4,minecraft:diorite)
B(0,59,4,minecraft:diorite)
B(0,60,4,minecraft:diorite)
B(0,51,5,minecraft:andesite)
B(0,52,5,minecraft:andesite)
B(0,53,5,minecraft:andesite)
B(0,54,5,minecraft:diorite)
B(0,55,5,minecraft:diorite)
B(0,56,5,minecraft:diorite)
B(0,57,5,minecraft:diorite)
B(0,58,5,minecraft:diorite)
B(0,59,5,minecraft:diorite)
B(0,60,5,minecraft:diorite)
B(0,51,6,minecraft:andesite)
B(0,52,6,minecraft:andesite)
B(0,53,6,minecraft:andesite)
B(0,54,6,minecraft:diorite)
B(0,55,6,minecraft:diorite)
B(0,56,6,minecraft:diorite)
B(0,57,6,minecraft:diorite)
B(0,58,6,minecraft:diorite)
B(0,59,6,minecraft:diorite)
B(0,52,7,minecraft:andesite)
B(0,53,7,minecraft:andesite)
B(0,54,7,minecraft:diorite)
B(0,55,7,minecraft:diorite)
B(0,56,7,minecraft:diorite)
B(0,57,7,minecraft:diorite)
B(0,58,7,minecraft:diorite)
B(0,53,8,minecraft:diorite)
B(0,54,8,minecraft:diorite)
B(0,55,8,minecraft:diorite)
B(0,56,8,minecraft:diorite)
B(0,57,8,minecraft:diorite)
B(1,49,-7,minecraft:andesite)
B(1,50,-7,minecraft:andesite)
B(1,51,-7,minecraft:andesite)
B(1,52,-7,minecraft:andesite)
B(1,53,-7,minecraft:andesite)
B(1,54,-7,minecraft:andesite)
B(1,55,-7,minecraft:andesite)
B(1,56,-7,minecraft:andesite)
B(1,57,-7,minecraft:andesite)
B(1,58,-7,minecraft:andesite)
B(1,59,-7,minecraft:andesite)
B(1,60,-7,minecraft:andesite)
B(1,61,-7,minecraft:andesite)
B(1,49,-6,minecraft:andesite)
B(1,50,-6,minecraft:andesite)
B(1,51,-6,minecraft:andesite)
B(1,52,-6,minecraft:andesite)
B(1,53,-6,minecraft:andesite)
B(1,54,-6,minecraft:andesite)
B(1,55,-6,minecraft:andesite)
B(1,56,-6,minecraft:andesite)
B(1,57,-6,minecraft:andesite)
B(1,58,-6,minecraft:andesite)
B(1,59,-6,minecraft:andesite)
B(1,60,-6,minecraft:andesite)
B(1,61,-6,minecraft:andesite)
B(1,62,-6,minecraft:andesite)
B(1,63,-6,minecraft:andesite)
B(1,48,-5,minecraft:andesite)
B(1,49,-5,minecraft:andesite)
B(1,50,-5,minecraft:andesite)
B(1,51,-5,minecraft:andesite)
B(1,52,-5,minecraft:andesite)
B(1,53,-5,minecraft:andesite)
B(1,54,-5,minecraft:andesite)
B(1,55,-5,minecraft:andesite)
B(1,56,-5,minecraft:andesite)
B(1,57,-5,minecraft:andesite)
B(1,58,-5,minecraft:andesite)
B(1,59,-5,minecraft:andesite)
B(1,60,-5,minecraft:andesite)
B(1,61,-5,minecraft:andesite)
B(1,62,-5,minecraft:andesite)
B(1,63,-5,minecraft:andesite)
B(1,48,-4,minecraft:andesite)
B(1,49,-4,minecraft:andesite)
B(1,50,-4,minecraft:andesite)
B(1,51,-4,minecraft:andesite)
B(1,52,-4,minecraft:andesite)
B(1,53,-4,minecraft:andesite)
B(1,54,-4,minecraft:andesite)
B(1,55,-4,minecraft:andesite)
B(1,56,-4,minecraft:andesite)
B(1,57,-4,minecraft:andesite)
B(1,58,-4,minecraft:diorite)
B(1,59,-4,minecraft:diorite)
B(1,60,-4,minecraft:diorite)
B(1,61,-4,minecraft:diorite)
B(1,62,-4,minecraft:diorite)
B(1,63,-4,minecraft:diorite)
B(1,47,-3,minecraft:andesite)
B(1,48,-3,minecraft:andesite)
B(1,49,-3,minecraft:andesite)
B(1,50,-3,minecraft:andesite)
B(1,51,-3,minecraft:andesite)
B(1,52,-3,minecraft:andesite)
B(1,53,-3,minecraft:andesite)
B(1,54,-3,minecraft:andesite)
B(1,55,-3,minecraft:andesite)
B(1,56,-3,minecraft:andesite)
B(1,57,-3,minecraft:diorite)
B(1,58,-3,minecraft:diorite)
B(1,59,-3,minecraft:diorite)
B(1,60,-3,minecraft:diorite)
B(1,61,-3,minecraft:diorite)
B(1,62,-3,minecraft:diorite)
B(1,63,-3,minecraft:diorite)
B(1,48,-2,minecraft:andesite)
B(1,49,-2,minecraft:andesite)
B(1,50,-2,minecraft:andesite)
B(1,51,-2,minecraft:andesite)
B(1,52,-2,minecraft:andesite)
B(1,53,-2,minecraft:andesite)
B(1,54,-2,minecraft:andesite)
B(1,55,-2,minecraft:andesite)
B(1,56,-2,minecraft:diorite)
B(1,57,-2,minecraft:diorite)
B(1,58,-2,minecraft:diorite)
B(1,59,-2,minecraft:diorite)
B(1,60,-2,minecraft:diorite)
B(1,61,-2,minecraft:diorite)
B(1,62,-2,minecraft:diorite)
B(1,63,-2,minecraft:diorite)
B(1,49,-1,minecraft:andesite)
B(1,50,-1,minecraft:andesite)
B(1,51,-1,minecraft:andesite)
B(1,52,-1,minecraft:andesite)
B(1,53,-1,minecraft:andesite)
B(1,54,-1,minecraft:andesite)
B(1,55,-1,minecraft:diorite)
B(1,56,-1,minecraft:diorite)
B(1,57,-1,minecraft:diorite)
B(1,58,-1,minecraft:diorite)
B(1,59,-1,minecraft:diorite)
B(1,60,-1,minecraft:diorite)
B(1,61,-1,minecraft:diorite)
B(1,62,-1,minecraft:diorite)
B(1,63,-1,minecraft:diorite)
B(1,49,0,minecraft:andesite)
B(1,50,0,minecraft:andesite)
B(1,51,0,minecraft:andesite)
B(1,52,0,minecraft:andesite)
B(1,53,0,minecraft:andesite)
B(1,54,0,minecraft:andesite)
B(1,55,0,minecraft:diorite)
B(1,56,0,minecraft:diorite)
B(1,57,0,minecraft:diorite)
B(1,58,0,minecraft:diorite)
B(1,59,0,minecraft:diorite)
B(1,60,0,minecraft:diorite)
B(1,61,0,minecraft:diorite)
B(1,62,0,minecraft:diorite)
B(1,49,1,minecraft:andesite)
B(1,50,1,minecraft:andesite)
B(1,51,1,minecraft:andesite)
B(1,52,1,minecraft:andesite)
B(1,53,1,minecraft:andesite)
B(1,54,1,minecraft:diorite)
B(1,55,1,minecraft:diorite)
B(1,56,1,minecraft:diorite)
B(1,57,1,minecraft:diorite)
B(1,58,1,minecraft:diorite)
B(1,59,1,minecraft:diorite)
B(1,60,1,minecraft:diorite)
B(1,61,1,minecraft:diorite)
B(1,49,2,minecraft:andesite)
B(1,50,2,minecraft:andesite)
B(1,51,2,minecraft:andesite)
B(1,52,2,minecraft:andesite)
B(1,53,2,minecraft:andesite)
B(1,54,2,minecraft:diorite)
B(1,55,2,minecraft:diorite)
B(1,56,2,minecraft:diorite)
B(1,57,2,minecraft:diorite)
B(1,58,2,minecraft:diorite)
B(1,59,2,minecraft:diorite)
B(1,60,2,minecraft:diorite)
B(1,49,3,minecraft:andesite)
B(1,50,3,minecraft:andesite)
B(1,51,3,minecraft:andesite)
B(1,52,3,minecraft:andesite)
B(1,53,3,minecraft:andesite)
B(1,54,3,minecraft:diorite)
B(1,55,3,minecraft:diorite)
B(1,56,3,minecraft:diorite)
B(1,57,3,minecraft:diorite)
B(1,58,3,minecraft:diorite)
B(1,59,3,minecraft:diorite)
B(1,60,3,minecraft:diorite)
B(1,49,4,minecraft:andesite)
B(1,50,4,minecraft:andesite)
B(1,51,4,minecraft:andesite)
B(1,52,4,minecraft:andesite)
B(1,53,4,minecraft:andesite)
B(1,54,4,minecraft:diorite)
B(1,55,4,minecraft:diorite)
B(1,56,4,minecraft:diorite)
B(1,57,4,minecraft:diorite)
B(1,58,4,minecraft:diorite)
B(1,59,4,minecraft:diorite)
B(1,60,4,minecraft:diorite)
B(1,50,5,minecraft:andesite)
B(1,51,5,minecraft:andesite)
B(1,52,5,minecraft:andesite)
B(1,53,5,minecraft:andesite)
B(1,54,5,minecraft:diorite)
B(1,55,5,minecraft:diorite)
B(1,56,5,minecraft:diorite)
B(1,57,5,minecraft:diorite)
B(1,58,5,minecraft:diorite)
B(1,59,5,minecraft:diorite)
B(1,60,5,minecraft:diorite)
B(1,51,6,minecraft:andesite)
B(1,52,6,minecraft:andesite)
B(1,53,6,minecraft:andesite)
B(1,54,6,minecraft:diorite)
B(1,55,6,minecraft:diorite)
B(1,56,6,minecraft:diorite)
B(1,57,6,minecraft:diorite)
B(1,58,6,minecraft:diorite)
B(1,59,6,minecraft:diorite)
B(1,60,6,minecraft:diorite)
B(1,51,7,minecraft:andesite)
B(1,52,7,minecraft:andesite)
B(1,53,7,minecraft:diorite)
B(1,54,7,minecraft:diorite)
B(1,55,7,minecraft:diorite)
B(1,56,7,minecraft:diorite)
B(1,57,7,minecraft:diorite)
B(1,58,7,minecraft:diorite)
B(1,59,7,minecraft:diorite)
B(1,51,8,minecraft:andesite)
B(1,52,8,minecraft:andesite)
B(1,53,8,minecraft:diorite)
B(1,54,8,minecraft:diorite)
B(1,55,8,minecraft:diorite)
B(1,56,8,minecraft:diorite)
B(1,57,8,minecraft:diorite)
B(1,58,8,minecraft:diorite)
B(2,49,-7,minecraft:andesite)
B(2,50,-7,minecraft:andesite)
B(2,51,-7,minecraft:andesite)
B(2,52,-7,minecraft:andesite)
B(2,53,-7,minecraft:andesite)
B(2,54,-7,minecraft:andesite)
B(2,55,-7,minecraft:andesite)
B(2,56,-7,minecraft:andesite)
B(2,57,-7,minecraft:andesite)
B(2,58,-7,minecraft:andesite)
B(2,59,-7,minecraft:andesite)
B(2,60,-7,minecraft:andesite)
B(2,61,-7,minecraft:andesite)
B(2,62,-7,minecraft:andesite)
B(2,63,-7,minecraft:andesite)
B(2,48,-6,minecraft:andesite)
B(2,49,-6,minecraft:andesite)
B(2,50,-6,minecraft:andesite)
B(2,51,-6,minecraft:andesite)
B(2,52,-6,minecraft:andesite)
B(2,53,-6,minecraft:andesite)
B(2,54,-6,minecraft:andesite)
B(2,55,-6,minecraft:andesite)
B(2,56,-6,minecraft:andesite)
B(2,57,-6,minecraft:andesite)
B(2,58,-6,minecraft:andesite)
B(2,59,-6,minecraft:andesite)
B(2,60,-6,minecraft:andesite)
B(2,61,-6,minecraft:andesite)
B(2,62,-6,minecraft:andesite)
B(2,63,-6,minecraft:andesite)
B(2,64,-6,minecraft:andesite)
B(2,47,-5,minecraft:andesite)
B(2,48,-5,minecraft:andesite)
B(2,49,-5,minecraft:andesite)
B(2,50,-5,minecraft:andesite)
B(2,51,-5,minecraft:andesite)
B(2,52,-5,minecraft:andesite)
B(2,53,-5,minecraft:andesite)
B(2,54,-5,minecraft:andesite)
B(2,55,-5,minecraft:andesite)
B(2,56,-5,minecraft:andesite)
B(2,57,-5,minecraft:andesite)
B(2,58,-5,minecraft:andesite)
B(2,59,-5,minecraft:andesite)
B(2,60,-5,minecraft:andesite)
B(2,61,-5,minecraft:andesite)
B(2,62,-5,minecraft:andesite)
B(2,63,-5,minecraft:andesite)
B(2,64,-5,minecraft:andesite)
B(2,47,-4,minecraft:andesite)
B(2,48,-4,minecraft:andesite)
B(2,49,-4,minecraft:andesite)
B(2,50,-4,minecraft:andesite)
B(2,51,-4,minecraft:andesite)
B(2,52,-4,minecraft:andesite)
B(2,53,-4,minecraft:andesite)
B(2,54,-4,minecraft:stone)
B(2,55,-4,minecraft:stone)
B(2,56,-4,minecraft:andesite)
B(2,57,-4,minecraft:andesite)
B(2,58,-4,minecraft:andesite)
B(2,59,-4,minecraft:diorite)
B(2,60,-4,minecraft:diorite)
B(2,61,-4,minecraft:diorite)
B(2,62,-4,minecraft:diorite)
B(2,63,-4,minecraft:diorite)
B(2,47,-3,minecraft:andesite)
B(2,48,-3,minecraft:andesite)
B(2,49,-3,minecraft:andesite)
B(2,50,-3,minecraft:andesite)
B(2,51,-3,minecraft:andesite)
B(2,52,-3,minecraft:andesite)
B(2,53,-3,minecraft:stone)
B(2,54,-3,minecraft:stone)
B(2,55,-3,minecraft:stone)
B(2,56,-3,minecraft:andesite)
B(2,57,-3,minecraft:diorite)
B(2,58,-3,minecraft:diorite)
B(2,59,-3,minecraft:diorite)
B(2,60,-3,minecraft:diorite)
B(2,61,-3,minecraft:diorite)
B(2,62,-3,minecraft:diorite)
B(2,63,-3,minecraft:diorite)
B(2,64,-3,minecraft:diorite)
B(2,48,-2,minecraft:andesite)
B(2,49,-2,minecraft:andesite)
B(2,50,-2,minecraft:andesite)
B(2,51,-2,minecraft:andesite)
B(2,52,-2,minecraft:andesite)
B(2,53,-2,minecraft:andesite)
B(2,54,-2,minecraft:stone)
B(2,55,-2,minecraft:stone)
B(2,56,-2,minecraft:diorite)
B(2,57,-2,minecraft:diorite)
B(2,58,-2,minecraft:diorite)
B(2,59,-2,minecraft:diorite)
B(2,60,-2,minecraft:diorite)
B(2,61,-2,minecraft:diorite)
B(2,62,-2,minecraft:diorite)
B(2,63,-2,minecraft:diorite)
B(2,64,-2,minecraft:diorite)
B(2,48,-1,minecraft:andesite)
B(2,49,-1,minecraft:andesite)
B(2,50,-1,minecraft:andesite)
B(2,51,-1,minecraft:andesite)
B(2,52,-1,minecraft:andesite)
B(2,53,-1,minecraft:andesite)
B(2,54,-1,minecraft:stone)
B(2,55,-1,minecraft:stone)
B(2,56,-1,minecraft:diorite)
B(2,57,-1,minecraft:diorite)
B(2,58,-1,minecraft:diorite)
B(2,59,-1,minecraft:diorite)
B(2,60,-1,minecraft:diorite)
B(2,61,-1,minecraft:diorite)
B(2,62,-1,minecraft:diorite)
B(2,63,-1,minecraft:diorite)
B(2,64,-1,minecraft:diorite)
B(2,49,0,minecraft:andesite)
B(2,50,0,minecraft:andesite)
B(2,51,0,minecraft:andesite)
B(2,52,0,minecraft:andesite)
B(2,53,0,minecraft:andesite)
B(2,54,0,minecraft:andesite)
B(2,55,0,minecraft:diorite)
B(2,56,0,minecraft:diorite)
B(2,57,0,minecraft:diorite)
B(2,58,0,minecraft:diorite)
B(2,59,0,minecraft:diorite)
B(2,60,0,minecraft:diorite)
B(2,61,0,minecraft:diorite)
B(2,62,0,minecraft:diorite)
B(2,63,0,minecraft:diorite)
B(2,49,1,minecraft:andesite)
B(2,50,1,minecraft:andesite)
B(2,51,1,minecraft:andesite)
B(2,52,1,minecraft:andesite)
B(2,53,1,minecraft:andesite)
B(2,54,1,minecraft:andesite)
B(2,55,1,minecraft:diorite)
B(2,56,1,minecraft:diorite)
B(2,57,1,minecraft:diorite)
B(2,58,1,minecraft:diorite)
B(2,59,1,minecraft:diorite)
B(2,60,1,minecraft:diorite)
B(2,61,1,minecraft:diorite)
B(2,62,1,minecraft:diorite)
B(2,48,2,minecraft:andesite)
B(2,49,2,minecraft:andesite)
B(2,50,2,minecraft:andesite)
B(2,51,2,minecraft:andesite)
B(2,52,2,minecraft:andesite)
B(2,53,2,minecraft:andesite)
B(2,54,2,minecraft:diorite)
B(2,55,2,minecraft:diorite)
B(2,56,2,minecraft:diorite)
B(2,57,2,minecraft:diorite)
B(2,58,2,minecraft:diorite)
B(2,59,2,minecraft:diorite)
B(2,60,2,minecraft:diorite)
B(2,61,2,minecraft:diorite)
B(2,49,3,minecraft:andesite)
B(2,50,3,minecraft:andesite)
B(2,51,3,minecraft:andesite)
B(2,52,3,minecraft:andesite)
B(2,53,3,minecraft:andesite)
B(2,54,3,minecraft:diorite)
B(2,55,3,minecraft:diorite)
B(2,56,3,minecraft:diorite)
B(2,57,3,minecraft:diorite)
B(2,58,3,minecraft:diorite)
B(2,59,3,minecraft:diorite)
B(2,60,3,minecraft:diorite)
B(2,49,4,minecraft:andesite)
B(2,50,4,minecraft:andesite)
B(2,51,4,minecraft:andesite)
B(2,52,4,minecraft:andesite)
B(2,53,4,minecraft:andesite)
B(2,54,4,minecraft:diorite)
B(2,55,4,minecraft:diorite)
B(2,56,4,minecraft:diorite)
B(2,57,4,minecraft:diorite)
B(2,58,4,minecraft:diorite)
B(2,59,4,minecraft:diorite)
B(2,60,4,minecraft:diorite)
B(2,50,5,minecraft:andesite)
B(2,51,5,minecraft:andesite)
B(2,52,5,minecraft:andesite)
B(2,53,5,minecraft:andesite)
B(2,54,5,minecraft:andesite)
B(2,55,5,minecraft:diorite)
B(2,56,5,minecraft:diorite)
B(2,57,5,minecraft:diorite)
B(2,58,5,minecraft:diorite)
B(2,59,5,minecraft:diorite)
B(2,60,5,minecraft:diorite)
B(2,49,6,minecraft:andesite)
B(2,50,6,minecraft:andesite)
B(2,51,6,minecraft:andesite)
B(2,52,6,minecraft:andesite)
B(2,53,6,minecraft:andesite)
B(2,54,6,minecraft:diorite)
B(2,55,6,minecraft:diorite)
B(2,56,6,minecraft:diorite)
B(2,57,6,minecraft:diorite)
B(2,58,6,minecraft:diorite)
B(2,59,6,minecraft:diorite)
B(2,60,6,minecraft:diorite)
B(2,49,7,minecraft:andesite)
B(2,50,7,minecraft:andesite)
B(2,51,7,minecraft:andesite)
B(2,52,7,minecraft:andesite)
B(2,53,7,minecraft:diorite)
B(2,54,7,minecraft:diorite)
B(2,55,7,minecraft:diorite)
B(2,56,7,minecraft:diorite)
B(2,57,7,minecraft:diorite)
B(2,58,7,minecraft:diorite)
B(2,59,7,minecraft:diorite)
B(2,60,7,minecraft:diorite)
B(2,48,8,minecraft:andesite)
B(2,49,8,minecraft:andesite)
B(2,50,8,minecraft:andesite)
B(2,51,8,minecraft:andesite)
B(2,52,8,minecraft:andesite)
B(2,53,8,minecraft:diorite)
B(2,54,8,minecraft:diorite)
B(2,55,8,minecraft:diorite)
B(2,56,8,minecraft:diorite)
B(2,57,8,minecraft:diorite)
B(2,58,8,minecraft:diorite)
B(2,59,8,minecraft:diorite)
B(3,49,-7,minecraft:andesite)
B(3,50,-7,minecraft:andesite)
B(3,51,-7,minecraft:andesite)
B(3,52,-7,minecraft:andesite)
B(3,53,-7,minecraft:andesite)
B(3,54,-7,minecraft:andesite)
B(3,55,-7,minecraft:andesite)
B(3,56,-7,minecraft:andesite)
B(3,57,-7,minecraft:andesite)
B(3,58,-7,minecraft:andesite)
B(3,59,-7,minecraft:andesite)
B(3,60,-7,minecraft:andesite)
B(3,61,-7,minecraft:andesite)
B(3,62,-7,minecraft:andesite)
B(3,63,-7,minecraft:andesite)
B(3,48,-6,minecraft:andesite)
B(3,49,-6,minecraft:andesite)
B(3,50,-6,minecraft:andesite)
B(3,51,-6,minecraft:andesite)
B(3,52,-6,minecraft:andesite)
B(3,53,-6,minecraft:andesite)
B(3,54,-6,minecraft:andesite)
B(3,55,-6,minecraft:andesite)
B(3,56,-6,minecraft:andesite)
B(3,57,-6,minecraft:andesite)
B(3,58,-6,minecraft:andesite)
B(3,59,-6,minecraft:andesite)
B(3,60,-6,minecraft:andesite)
B(3,61,-6,minecraft:andesite)
B(3,62,-6,minecraft:andesite)
B(3,63,-6,minecraft:andesite)
B(3,64,-6,minecraft:andesite)
B(3,47,-5,minecraft:andesite)
B(3,48,-5,minecraft:andesite)
B(3,49,-5,minecraft:andesite)
B(3,50,-5,minecraft:andesite)
B(3,51,-5,minecraft:andesite)
B(3,52,-5,minecraft:andesite)
B(3,53,-5,minecraft:andesite)
B(3,54,-5,minecraft:andesite)
B(3,55,-5,minecraft:stone)
B(3,56,-5,minecraft:stone)
B(3,57,-5,minecraft:andesite)
B(3,58,-5,minecraft:andesite)
B(3,59,-5,minecraft:andesite)
B(3,60,-5,minecraft:andesite)
B(3,61,-5,minecraft:andesite)
B(3,62,-5,minecraft:andesite)
B(3,63,-5,minecraft:andesite)
B(3,64,-5,minecraft:andesite)
B(3,65,-5,minecraft:andesite)
B(3,47,-4,minecraft:andesite)
B(3,48,-4,minecraft:andesite)
B(3,49,-4,minecraft:andesite)
B(3,50,-4,minecraft:andesite)
B(3,51,-4,minecraft:andesite)
B(3,52,-4,minecraft:andesite)
B(3,53,-4,minecraft:andesite)
B(3,54,-4,minecraft:stone)
B(3,55,-4,minecraft:stone)
B(3,56,-4,minecraft:stone)
B(3,57,-4,minecraft:andesite)
B(3,58,-4,minecraft:andesite)
B(3,59,-4,minecraft:andesite)
B(3,60,-4,minecraft:andesite)
B(3,61,-4,minecraft:diorite)
B(3,62,-4,minecraft:diorite)
B(3,63,-4,minecraft:diorite)
B(3,64,-4,minecraft:diorite)
B(3,46,-3,minecraft:andesite)
B(3,47,-3,minecraft:andesite)
B(3,48,-3,minecraft:andesite)
B(3,49,-3,minecraft:andesite)
B(3,50,-3,minecraft:andesite)
B(3,51,-3,minecraft:andesite)
B(3,52,-3,minecraft:andesite)
B(3,53,-3,minecraft:stone)
B(3,54,-3,minecraft:stone)
B(3,55,-3,minecraft:stone)
B(3,56,-3,minecraft:stone)
B(3,57,-3,minecraft:andesite)
B(3,58,-3,minecraft:diorite)
B(3,59,-3,minecraft:diorite)
B(3,60,-3,minecraft:diorite)
B(3,61,-3,minecraft:diorite)
B(3,62,-3,minecraft:diorite)
B(3,63,-3,minecraft:diorite)
B(3,64,-3,minecraft:diorite)
B(3,47,-2,minecraft:andesite)
B(3,48,-2,minecraft:andesite)
B(3,49,-2,minecraft:andesite)
B(3,50,-2,minecraft:andesite)
B(3,51,-2,minecraft:andesite)
B(3,52,-2,minecraft:andesite)
B(3,53,-2,minecraft:stone)
B(3,54,-2,minecraft:stone)
B(3,55,-2,minecraft:stone)
B(3,56,-2,minecraft:stone)
B(3,57,-2,minecraft:diorite)
B(3,58,-2,minecraft:diorite)
B(3,59,-2,minecraft:diorite)
B(3,60,-2,minecraft:diorite)
B(3,61,-2,minecraft:diorite)
B(3,62,-2,minecraft:diorite)
B(3,63,-2,minecraft:diorite)
B(3,64,-2,minecraft:diorite)
B(3,48,-1,minecraft:andesite)
B(3,49,-1,minecraft:andesite)
B(3,50,-1,minecraft:andesite)
B(3,51,-1,minecraft:andesite)
B(3,52,-1,minecraft:andesite)
B(3,53,-1,minecraft:stone)
B(3,54,-1,minecraft:stone)
B(3,55,-1,minecraft:stone)
B(3,56,-1,minecraft:diorite)
B(3,57,-1,minecraft:diorite)
B(3,58,-1,minecraft:diorite)
B(3,59,-1,minecraft:diorite)
B(3,60,-1,minecraft:diorite)
B(3,61,-1,minecraft:diorite)
B(3,62,-1,minecraft:diorite)
B(3,63,-1,minecraft:diorite)
B(3,64,-1,minecraft:diorite)
B(3,48,0,minecraft:andesite)
B(3,49,0,minecraft:andesite)
B(3,50,0,minecraft:andesite)
B(3,51,0,minecraft:andesite)
B(3,52,0,minecraft:andesite)
B(3,53,0,minecraft:andesite)
B(3,54,0,minecraft:stone)
B(3,55,0,minecraft:stone)
B(3,56,0,minecraft:diorite)
B(3,57,0,minecraft:diorite)
B(3,58,0,minecraft:diorite)
B(3,59,0,minecraft:diorite)
B(3,60,0,minecraft:diorite)
B(3,61,0,minecraft:diorite)
B(3,62,0,minecraft:diorite)
B(3,63,0,minecraft:diorite)
B(3,64,0,minecraft:diorite)
B(3,48,1,minecraft:andesite)
B(3,49,1,minecraft:andesite)
B(3,50,1,minecraft:andesite)
B(3,51,1,minecraft:andesite)
B(3,52,1,minecraft:andesite)
B(3,53,1,minecraft:andesite)
B(3,54,1,minecraft:andesite)
B(3,55,1,minecraft:diorite)
B(3,56,1,minecraft:diorite)
B(3,57,1,minecraft:diorite)
B(3,58,1,minecraft:diorite)
B(3,59,1,minecraft:diorite)
B(3,60,1,minecraft:diorite)
B(3,61,1,minecraft:diorite)
B(3,62,1,minecraft:diorite)
B(3,63,1,minecraft:diorite)
B(3,48,2,minecraft:andesite)
B(3,49,2,minecraft:andesite)
B(3,50,2,minecraft:andesite)
B(3,51,2,minecraft:andesite)
B(3,52,2,minecraft:andesite)
B(3,53,2,minecraft:andesite)
B(3,54,2,minecraft:andesite)
B(3,55,2,minecraft:diorite)
B(3,56,2,minecraft:diorite)
B(3,57,2,minecraft:diorite)
B(3,58,2,minecraft:diorite)
B(3,59,2,minecraft:diorite)
B(3,60,2,minecraft:diorite)
B(3,61,2,minecraft:diorite)
B(3,62,2,minecraft:diorite)
B(3,48,3,minecraft:andesite)
B(3,49,3,minecraft:andesite)
B(3,50,3,minecraft:andesite)
B(3,51,3,minecraft:andesite)
B(3,52,3,minecraft:andesite)
B(3,53,3,minecraft:andesite)
B(3,54,3,minecraft:andesite)
B(3,55,3,minecraft:diorite)
B(3,56,3,minecraft:diorite)
B(3,57,3,minecraft:diorite)
B(3,58,3,minecraft:diorite)
B(3,59,3,minecraft:diorite)
B(3,60,3,minecraft:diorite)
B(3,61,3,minecraft:diorite)
B(3,48,4,minecraft:andesite)
B(3,49,4,minecraft:andesite)
B(3,50,4,minecraft:andesite)
B(3,51,4,minecraft:andesite)
B(3,52,4,minecraft:andesite)
B(3,53,4,minecraft:andesite)
B(3,54,4,minecraft:andesite)
B(3,55,4,minecraft:diorite)
B(3,56,4,minecraft:diorite)
B(3,57,4,minecraft:diorite)
B(3,58,4,minecraft:diorite)
B(3,59,4,minecraft:diorite)
B(3,60,4,minecraft:diorite)
B(3,61,4,minecraft:diorite)
B(3,49,5,minecraft:andesite)
B(3,50,5,minecraft:andesite)
B(3,51,5,minecraft:andesite)
B(3,52,5,minecraft:andesite)
B(3,53,5,minecraft:andesite)
B(3,54,5,minecraft:andesite)
B(3,55,5,minecraft:diorite)
B(3,56,5,minecraft:diorite)
B(3,57,5,minecraft:diorite)
B(3,58,5,minecraft:diorite)
B(3,59,5,minecraft:diorite)
B(3,60,5,minecraft:diorite)
B(3,49,6,minecraft:andesite)
B(3,50,6,minecraft:andesite)
B(3,51,6,minecraft:andesite)
B(3,52,6,minecraft:andesite)
B(3,53,6,minecraft:andesite)
B(3,54,6,minecraft:diorite)
B(3,55,6,minecraft:diorite)
B(3,56,6,minecraft:diorite)
B(3,57,6,minecraft:diorite)
B(3,58,6,minecraft:diorite)
B(3,59,6,minecraft:diorite)
B(3,60,6,minecraft:diorite)
B(3,49,7,minecraft:andesite)
B(3,50,7,minecraft:andesite)
B(3,51,7,minecraft:andesite)
B(3,52,7,minecraft:andesite)
B(3,53,7,minecraft:diorite)
B(3,54,7,minecraft:diorite)
B(3,55,7,minecraft:diorite)
B(3,56,7,minecraft:diorite)
B(3,57,7,minecraft:diorite)
B(3,58,7,minecraft:diorite)
B(3,59,7,minecraft:diorite)
B(3,48,8,minecraft:andesite)
B(3,49,8,minecraft:andesite)
B(3,50,8,minecraft:andesite)
B(3,51,8,minecraft:andesite)
B(3,52,8,minecraft:andesite)
B(3,53,8,minecraft:diorite)
B(3,54,8,minecraft:diorite)
B(3,55,8,minecraft:diorite)
B(3,56,8,minecraft:diorite)
B(3,57,8,minecraft:diorite)
B(3,58,8,minecraft:diorite)
B(3,59,8,minecraft:diorite)
B(4,49,-7,minecraft:andesite)
B(4,50,-7,minecraft:andesite)
B(4,51,-7,minecraft:andesite)
B(4,52,-7,minecraft:andesite)
B(4,53,-7,minecraft:andesite)
B(4,54,-7,minecraft:andesite)
B(4,55,-7,minecraft:andesite)
B(4,56,-7,minecraft:andesite)
B(4,57,-7,minecraft:andesite)
B(4,58,-7,minecraft:andesite)
B(4,59,-7,minecraft:andesite)
B(4,60,-7,minecraft:andesite)
B(4,61,-7,minecraft:andesite)
B(4,62,-7,minecraft:andesite)
B(4,63,-7,minecraft:andesite)
B(4,48,-6,minecraft:andesite)
B(4,49,-6,minecraft:andesite)
B(4,50,-6,minecraft:andesite)
B(4,51,-6,minecraft:andesite)
B(4,52,-6,minecraft:andesite)
B(4,53,-6,minecraft:andesite)
B(4,54,-6,minecraft:andesite)
B(4,55,-6,minecraft:stone)
B(4,56,-6,minecraft:andesite)
B(4,57,-6,minecraft:andesite)
B(4,58,-6,minecraft:andesite)
B(4,59,-6,minecraft:andesite)
B(4,60,-6,minecraft:andesite)
B(4,61,-6,minecraft:andesite)
B(4,62,-6,minecraft:andesite)
B(4,63,-6,minecraft:andesite)
B(4,64,-6,minecraft:andesite)
B(4,48,-5,minecraft:andesite)
B(4,49,-5,minecraft:andesite)
B(4,50,-5,minecraft:andesite)
B(4,51,-5,minecraft:andesite)
B(4,52,-5,minecraft:andesite)
B(4,53,-5,minecraft:andesite)
B(4,54,-5,minecraft:andesite)
B(4,55,-5,minecraft:stone)
B(4,56,-5,minecraft:stone)
B(4,57,-5,minecraft:andesite)
B(4,58,-5,minecraft:andesite)
B(4,59,-5,minecraft:andesite)
B(4,60,-5,minecraft:andesite)
B(4,61,-5,minecraft:andesite)
B(4,62,-5,minecraft:andesite)
B(4,63,-5,minecraft:andesite)
B(4,64,-5,minecraft:andesite)
B(4,65,-5,minecraft:andesite)
B(4,47,-4,minecraft:andesite)
B(4,48,-4,minecraft:andesite)
B(4,49,-4,minecraft:andesite)
B(4,50,-4,minecraft:andesite)
B(4,51,-4,minecraft:andesite)
B(4,52,-4,minecraft:andesite)
B(4,53,-4,minecraft:andesite)
B(4,54,-4,minecraft:stone)
B(4,55,-4,minecraft:stone)
B(4,56,-4,minecraft:stone)
B(4,57,-4,minecraft:stone)
B(4,58,-4,minecraft:andesite)
B(4,59,-4,minecraft:andesite)
B(4,60,-4,minecraft:andesite)
B(4,61,-4,minecraft:diorite)
B(4,62,-4,minecraft:diorite)
B(4,63,-4,minecraft:diorite)
B(4,64,-4,minecraft:diorite)
B(4,65,-4,minecraft:diorite)
B(4,66,-4,minecraft:andesite)
B(4,47,-3,minecraft:andesite)
B(4,48,-3,minecraft:andesite)
B(4,49,-3,minecraft:andesite)
B(4,50,-3,minecraft:andesite)
B(4,51,-3,minecraft:andesite)
B(4,52,-3,minecraft:andesite)
B(4,53,-3,minecraft:andesite)
B(4,54,-3,minecraft:stone)
B(4,55,-3,minecraft:stone)
B(4,56,-3,minecraft:stone)
B(4,57,-3,minecraft:stone)
B(4,58,-3,minecraft:stone)
B(4,59,-3,minecraft:andesite)
B(4,60,-3,minecraft:diorite)
B(4,61,-3,minecraft:diorite)
B(4,62,-3,minecraft:diorite)
B(4,63,-3,minecraft:diorite)
B(4,64,-3,minecraft:diorite)
B(4,65,-3,minecraft:diorite)
B(4,47,-2,minecraft:andesite)
B(4,48,-2,minecraft:andesite)
B(4,49,-2,minecraft:andesite)
B(4,50,-2,minecraft:andesite)
B(4,51,-2,minecraft:andesite)
B(4,52,-2,minecraft:andesite)
B(4,53,-2,minecraft:andesite)
B(4,54,-2,minecraft:stone)
B(4,55,-2,minecraft:stone)
B(4,56,-2,minecraft:stone)
B(4,57,-2,minecraft:stone)
B(4,58,-2,minecraft:diorite)
B(4,59,-2,minecraft:diorite)
B(4,60,-2,minecraft:diorite)
B(4,61,-2,minecraft:diorite)
B(4,62,-2,minecraft:diorite)
B(4,63,-2,minecraft:diorite)
B(4,64,-2,minecraft:diorite)
B(4,65,-2,minecraft:diorite)
B(4,47,-1,minecraft:andesite)
B(4,48,-1,minecraft:andesite)
B(4,49,-1,minecraft:andesite)
B(4,50,-1,minecraft:andesite)
B(4,51,-1,minecraft:andesite)
B(4,52,-1,minecraft:andesite)
B(4,53,-1,minecraft:stone)
B(4,54,-1,minecraft:stone)
B(4,55,-1,minecraft:stone)
B(4,56,-1,minecraft:stone)
B(4,57,-1,minecraft:diorite)
B(4,58,-1,minecraft:diorite)
B(4,59,-1,minecraft:diorite)
B(4,60,-1,minecraft:diorite)
B(4,61,-1,minecraft:diorite)
B(4,62,-1,minecraft:diorite)
B(4,63,-1,minecraft:diorite)
B(4,64,-1,minecraft:diorite)
B(4,65,-1,minecraft:diorite)
B(4,47,0,minecraft:andesite)
B(4,48,0,minecraft:andesite)
B(4,49,0,minecraft:andesite)
B(4,50,0,minecraft:andesite)
B(4,51,0,minecraft:andesite)
B(4,52,0,minecraft:andesite)
B(4,53,0,minecraft:stone)
B(4,54,0,minecraft:stone)
B(4,55,0,minecraft:stone)
B(4,56,0,minecraft:stone)
B(4,57,0,minecraft:diorite)
B(4,58,0,minecraft:diorite)
B(4,59,0,minecraft:diorite)
B(4,60,0,minecraft:diorite)
B(4,61,0,minecraft:diorite)
B(4,62,0,minecraft:diorite)
B(4,63,0,minecraft:diorite)
B(4,64,0,minecraft:diorite)
B(4,48,1,minecraft:andesite)
B(4,49,1,minecraft:andesite)
B(4,50,1,minecraft:andesite)
B(4,51,1,minecraft:andesite)
B(4,52,1,minecraft:andesite)
B(4,53,1,minecraft:andesite)
B(4,54,1,minecraft:stone)
B(4,55,1,minecraft:stone)
B(4,56,1,minecraft:diorite)
B(4,57,1,minecraft:diorite)
B(4,58,1,minecraft:diorite)
B(4,59,1,minecraft:diorite)
B(4,60,1,minecraft:diorite)
B(4,61,1,minecraft:diorite)
B(4,62,1,minecraft:diorite)
B(4,63,1,minecraft:diorite)
B(4,47,2,minecraft:andesite)
B(4,48,2,minecraft:andesite)
B(4,49,2,minecraft:andesite)
B(4,50,2,minecraft:andesite)
B(4,51,2,minecraft:andesite)
B(4,52,2,minecraft:andesite)
B(4,53,2,minecraft:andesite)
B(4,54,2,minecraft:stone)
B(4,55,2,minecraft:stone)
B(4,56,2,minecraft:diorite)
B(4,57,2,minecraft:diorite)
B(4,58,2,minecraft:diorite)
B(4,59,2,minecraft:diorite)
B(4,60,2,minecraft:diorite)
B(4,61,2,minecraft:diorite)
B(4,62,2,minecraft:diorite)
B(4,63,2,minecraft:diorite)
B(4,47,3,minecraft:andesite)
B(4,48,3,minecraft:andesite)
B(4,49,3,minecraft:andesite)
B(4,50,3,minecraft:andesite)
B(4,51,3,minecraft:andesite)
B(4,52,3,minecraft:andesite)
B(4,53,3,minecraft:andesite)
B(4,54,3,minecraft:stone)
B(4,55,3,minecraft:stone)
B(4,56,3,minecraft:diorite)
B(4,57,3,minecraft:diorite)
B(4,58,3,minecraft:diorite)
B(4,59,3,minecraft:diorite)
B(4,60,3,minecraft:diorite)
B(4,61,3,minecraft:diorite)
B(4,62,3,minecraft:diorite)
B(4,47,4,minecraft:andesite)
B(4,48,4,minecraft:andesite)
B(4,49,4,minecraft:andesite)
B(4,50,4,minecraft:andesite)
B(4,51,4,minecraft:andesite)
B(4,52,4,minecraft:andesite)
B(4,53,4,minecraft:andesite)
B(4,54,4,minecraft:stone)
B(4,55,4,minecraft:stone)
B(4,56,4,minecraft:diorite)
B(4,57,4,minecraft:diorite)
B(4,58,4,minecraft:diorite)
B(4,59,4,minecraft:diorite)
B(4,60,4,minecraft:diorite)
B(4,61,4,minecraft:diorite)
B(4,62,4,minecraft:diorite)
B(4,63,4,minecraft:diorite)
B(4,48,5,minecraft:andesite)
B(4,49,5,minecraft:andesite)
B(4,50,5,minecraft:andesite)
B(4,51,5,minecraft:andesite)
B(4,52,5,minecraft:andesite)
B(4,53,5,minecraft:andesite)
B(4,54,5,minecraft:andesite)
B(4,55,5,minecraft:diorite)
B(4,56,5,minecraft:diorite)
B(4,57,5,minecraft:diorite)
B(4,58,5,minecraft:diorite)
B(4,59,5,minecraft:diorite)
B(4,60,5,minecraft:diorite)
B(4,61,5,minecraft:diorite)
B(4,62,5,minecraft:diorite)
B(4,49,6,minecraft:andesite)
B(4,50,6,minecraft:andesite)
B(4,51,6,minecraft:andesite)
B(4,52,6,minecraft:andesite)
B(4,53,6,minecraft:andesite)
B(4,54,6,minecraft:diorite)
B(4,55,6,minecraft:diorite)
B(4,56,6,minecraft:diorite)
B(4,57,6,minecraft:diorite)
B(4,58,6,minecraft:diorite)
B(4,59,6,minecraft:diorite)
B(4,60,6,minecraft:diorite)
B(4,48,7,minecraft:andesite)
B(4,49,7,minecraft:andesite)
B(4,50,7,minecraft:andesite)
B(4,51,7,minecraft:andesite)
B(4,52,7,minecraft:andesite)
B(4,53,7,minecraft:andesite)
B(4,54,7,minecraft:diorite)
B(4,55,7,minecraft:diorite)
B(4,56,7,minecraft:diorite)
B(4,57,7,minecraft:diorite)
B(4,58,7,minecraft:diorite)
B(4,59,7,minecraft:diorite)
B(4,48,8,minecraft:andesite)
B(4,49,8,minecraft:andesite)
B(4,50,8,minecraft:andesite)
B(4,51,8,minecraft:andesite)
B(4,52,8,minecraft:andesite)
B(4,53,8,minecraft:diorite)
B(4,54,8,minecraft:diorite)
B(4,55,8,minecraft:diorite)
B(4,56,8,minecraft:diorite)
B(4,57,8,minecraft:diorite)
B(4,58,8,minecraft:diorite)
B(4,59,8,minecraft:diorite)
B(5,48,-7,minecraft:andesite)
B(5,49,-7,minecraft:andesite)
B(5,50,-7,minecraft:andesite)
B(5,51,-7,minecraft:andesite)
B(5,52,-7,minecraft:andesite)
B(5,53,-7,minecraft:andesite)
B(5,54,-7,minecraft:andesite)
B(5,55,-7,minecraft:andesite)
B(5,56,-7,minecraft:andesite)
B(5,57,-7,minecraft:andesite)
B(5,58,-7,minecraft:andesite)
B(5,59,-7,minecraft:andesite)
B(5,60,-7,minecraft:andesite)
B(5,61,-7,minecraft:andesite)
B(5,62,-7,minecraft:andesite)
B(5,48,-6,minecraft:andesite)
B(5,49,-6,minecraft:andesite)
B(5,50,-6,minecraft:andesite)
B(5,51,-6,minecraft:andesite)
B(5,52,-6,minecraft:andesite)
B(5,53,-6,minecraft:andesite)
B(5,54,-6,minecraft:andesite)
B(5,55,-6,minecraft:andesite)
B(5,56,-6,minecraft:andesite)
B(5,57,-6,minecraft:andesite)
B(5,58,-6,minecraft:andesite)
B(5,59,-6,minecraft:andesite)
B(5,60,-6,minecraft:andesite)
B(5,61,-6,minecraft:andesite)
B(5,62,-6,minecraft:andesite)
B(5,63,-6,minecraft:andesite)
B(5,64,-6,minecraft:andesite)
B(5,48,-5,minecraft:andesite)
B(5,49,-5,minecraft:andesite)
B(5,50,-5,minecraft:andesite)
B(5,51,-5,minecraft:andesite)
B(5,52,-5,minecraft:andesite)
B(5,53,-5,minecraft:andesite)
B(5,54,-5,minecraft:andesite)
B(5,55,-5,minecraft:stone)
B(5,56,-5,minecraft:stone)
B(5,57,-5,minecraft:andesite)
B(5,58,-5,minecraft:andesite)
B(5,59,-5,minecraft:andesite)
B(5,60,-5,minecraft:andesite)
B(5,61,-5,minecraft:andesite)
B(5,62,-5,minecraft:andesite)
B(5,63,-5,minecraft:andesite)
B(5,64,-5,minecraft:andesite)
B(5,65,-5,minecraft:andesite)
B(5,48,-4,minecraft:andesite)
B(5,49,-4,minecraft:andesite)
B(5,50,-4,minecraft:andesite)
B(5,51,-4,minecraft:andesite)
B(5,52,-4,minecraft:andesite)
B(5,53,-4,minecraft:andesite)
B(5,54,-4,minecraft:andesite)
B(5,55,-4,minecraft:stone)
B(5,56,-4,minecraft:stone)
B(5,57,-4,minecraft:stone)
B(5,58,-4,minecraft:andesite)
B(5,59,-4,minecraft:andesite)
B(5,60,-4,minecraft:andesite)
B(5,61,-4,minecraft:andesite)
B(5,62,-4,minecraft:diorite)
B(5,63,-4,minecraft:diorite)
B(5,64,-4,minecraft:diorite)
B(5,65,-4,minecraft:andesite)
B(5,47,-3,minecraft:andesite)
B(5,48,-3,minecraft:andesite)
B(5,49,-3,minecraft:andesite)
B(5,50,-3,minecraft:andesite)
B(5,51,-3,minecraft:andesite)
B(5,52,-3,minecraft:andesite)
B(5,53,-3,minecraft:andesite)
B(5,54,-3,minecraft:stone)
B(5,55,-3,minecraft:stone)
B(5,56,-3,minecraft:stone)
B(5,57,-3,minecraft:stone)
B(5,58,-3,minecraft:andesite)
B(5,59,-3,minecraft:andesite)
B(5,60,-3,minecraft:diorite)
B(5,61,-3,minecraft:diorite)
B(5,62,-3,minecraft:diorite)
B(5,63,-3,minecraft:diorite)
B(5,64,-3,minecraft:diorite)
B(5,65,-3,minecraft:diorite)
B(5,47,-2,minecraft:andesite)
B(5,48,-2,minecraft:andesite)
B(5,49,-2,minecraft:andesite)
B(5,50,-2,minecraft:andesite)
B(5,51,-2,minecraft:andesite)
B(5,52,-2,minecraft:andesite)
B(5,53,-2,minecraft:andesite)
B(5,54,-2,minecraft:stone)
B(5,55,-2,minecraft:stone)
B(5,56,-2,minecraft:stone)
B(5,57,-2,minecraft:stone)
B(5,58,-2,minecraft:stone)
B(5,59,-2,minecraft:diorite)
B(5,60,-2,minecraft:diorite)
B(5,61,-2,minecraft:diorite)
B(5,62,-2,minecraft:diorite)
B(5,63,-2,minecraft:diorite)
B(5,64,-2,minecraft:diorite)
B(5,65,-2,minecraft:diorite)
B(5,47,-1,minecraft:andesite)
B(5,48,-1,minecraft:andesite)
B(5,49,-1,minecraft:andesite)
B(5,50,-1,minecraft:andesite)
B(5,51,-1,minecraft:andesite)
B(5,52,-1,minecraft:andesite)
B(5,53,-1,minecraft:andesite)
B(5,54,-1,minecraft:stone)
B(5,55,-1,minecraft:stone)
B(5,56,-1,minecraft:stone)
B(5,57,-1,minecraft:stone)
B(5,58,-1,minecraft:stone)
B(5,59,-1,minecraft:diorite)
B(5,60,-1,minecraft:diorite)
B(5,61,-1,minecraft:diorite)
B(5,62,-1,minecraft:diorite)
B(5,63,-1,minecraft:diorite)
B(5,64,-1,minecraft:diorite)
B(5,65,-1,minecraft:diorite)
B(5,47,0,minecraft:andesite)
B(5,48,0,minecraft:andesite)
B(5,49,0,minecraft:andesite)
B(5,50,0,minecraft:andesite)
B(5,51,0,minecraft:andesite)
B(5,52,0,minecraft:andesite)
B(5,53,0,minecraft:stone)
B(5,54,0,minecraft:stone)
B(5,55,0,minecraft:stone)
B(5,56,0,minecraft:stone)
B(5,57,0,minecraft:stone)
B(5,58,0,minecraft:diorite)
B(5,59,0,minecraft:diorite)
B(5,60,0,minecraft:diorite)
B(5,61,0,minecraft:diorite)
B(5,62,0,minecraft:diorite)
B(5,63,0,minecraft:diorite)
B(5,64,0,minecraft:diorite)
B(5,65,0,minecraft:diorite)
B(5,48,1,minecraft:andesite)
B(5,49,1,minecraft:andesite)
B(5,50,1,minecraft:andesite)
B(5,51,1,minecraft:andesite)
B(5,52,1,minecraft:stone)
B(5,53,1,minecraft:stone)
B(5,54,1,minecraft:stone)
B(5,55,1,minecraft:stone)
B(5,56,1,minecraft:stone)
B(5,57,1,minecraft:stone)
B(5,58,1,minecraft:diorite)
B(5,59,1,minecraft:diorite)
B(5,60,1,minecraft:diorite)
B(5,61,1,minecraft:diorite)
B(5,62,1,minecraft:diorite)
B(5,63,1,minecraft:diorite)
B(5,64,1,minecraft:diorite)
B(5,47,2,minecraft:obsidian)
B(5,48,2,minecraft:andesite)
B(5,49,2,minecraft:andesite)
B(5,50,2,minecraft:andesite)
B(5,51,2,minecraft:andesite)
B(5,52,2,minecraft:andesite)
B(5,53,2,minecraft:stone)
B(5,54,2,minecraft:stone)
B(5,55,2,minecraft:stone)
B(5,56,2,minecraft:stone)
B(5,57,2,minecraft:diorite)
B(5,58,2,minecraft:diorite)
B(5,59,2,minecraft:diorite)
B(5,60,2,minecraft:diorite)
B(5,61,2,minecraft:diorite)
B(5,62,2,minecraft:diorite)
B(5,63,2,minecraft:diorite)
B(5,64,2,minecraft:diorite)
B(5,46,3,minecraft:obsidian)
B(5,47,3,minecraft:obsidian)
B(5,48,3,minecraft:andesite)
B(5,49,3,minecraft:andesite)
B(5,50,3,minecraft:andesite)
B(5,51,3,minecraft:andesite)
B(5,52,3,minecraft:andesite)
B(5,53,3,minecraft:stone)
B(5,54,3,minecraft:stone)
B(5,55,3,minecraft:stone)
B(5,56,3,minecraft:stone)
B(5,57,3,minecraft:diorite)
B(5,58,3,minecraft:diorite)
B(5,59,3,minecraft:diorite)
B(5,60,3,minecraft:diorite)
B(5,61,3,minecraft:diorite)
B(5,62,3,minecraft:diorite)
B(5,63,3,minecraft:diorite)
B(5,64,3,minecraft:diorite)
B(5,47,4,minecraft:obsidian)
B(5,48,4,minecraft:andesite)
B(5,49,4,minecraft:andesite)
B(5,50,4,minecraft:andesite)
B(5,51,4,minecraft:andesite)
B(5,52,4,minecraft:andesite)
B(5,53,4,minecraft:andesite)
B(5,54,4,minecraft:stone)
B(5,55,4,minecraft:stone)
B(5,56,4,minecraft:stone)
B(5,57,4,minecraft:diorite)
B(5,58,4,minecraft:diorite)
B(5,59,4,minecraft:diorite)
B(5,60,4,minecraft:diorite)
B(5,61,4,minecraft:diorite)
B(5,62,4,minecraft:diorite)
B(5,63,4,minecraft:diorite)
B(5,64,4,minecraft:diorite)
B(5,65,4,minecraft:diorite)
B(5,47,5,minecraft:obsidian)
B(5,48,5,minecraft:andesite)
B(5,49,5,minecraft:andesite)
B(5,50,5,minecraft:andesite)
B(5,51,5,minecraft:andesite)
B(5,52,5,minecraft:andesite)
B(5,53,5,minecraft:andesite)
B(5,54,5,minecraft:stone)
B(5,55,5,minecraft:stone)
B(5,56,5,minecraft:diorite)
B(5,57,5,minecraft:diorite)
B(5,58,5,minecraft:diorite)
B(5,59,5,minecraft:diorite)
B(5,60,5,minecraft:diorite)
B(5,61,5,minecraft:diorite)
B(5,62,5,minecraft:diorite)
B(5,63,5,minecraft:diorite)
B(5,64,5,minecraft:diorite)
B(5,48,6,minecraft:andesite)
B(5,49,6,minecraft:andesite)
B(5,50,6,minecraft:andesite)
B(5,51,6,minecraft:andesite)
B(5,52,6,minecraft:andesite)
B(5,53,6,minecraft:andesite)
B(5,54,6,minecraft:stone)
B(5,55,6,minecraft:diorite)
B(5,56,6,minecraft:diorite)
B(5,57,6,minecraft:diorite)
B(5,58,6,minecraft:diorite)
B(5,59,6,minecraft:diorite)
B(5,60,6,minecraft:diorite)
B(5,61,6,minecraft:diorite)
B(5,62,6,minecraft:diorite)
B(5,63,6,minecraft:diorite)
B(5,64,6,minecraft:diorite)
B(5,48,7,minecraft:andesite)
B(5,49,7,minecraft:andesite)
B(5,50,7,minecraft:andesite)
B(5,51,7,minecraft:andesite)
B(5,52,7,minecraft:andesite)
B(5,53,7,minecraft:andesite)
B(5,54,7,minecraft:diorite)
B(5,55,7,minecraft:diorite)
B(5,56,7,minecraft:diorite)
B(5,57,7,minecraft:diorite)
B(5,58,7,minecraft:diorite)
B(5,59,7,minecraft:diorite)
B(5,60,7,minecraft:diorite)
B(5,61,7,minecraft:diorite)
B(5,48,8,minecraft:andesite)
B(5,49,8,minecraft:andesite)
B(5,50,8,minecraft:andesite)
B(5,51,8,minecraft:andesite)
B(5,52,8,minecraft:andesite)
B(5,53,8,minecraft:andesite)
B(5,54,8,minecraft:diorite)
B(5,55,8,minecraft:diorite)
B(5,56,8,minecraft:diorite)
B(5,57,8,minecraft:diorite)
B(5,58,8,minecraft:diorite)
B(5,59,8,minecraft:diorite)
B(5,60,8,minecraft:diorite)
B(5,61,8,minecraft:diorite)
B(6,49,-7,minecraft:andesite)
B(6,50,-7,minecraft:andesite)
B(6,51,-7,minecraft:andesite)
B(6,52,-7,minecraft:andesite)
B(6,53,-7,minecraft:andesite)
B(6,54,-7,minecraft:andesite)
B(6,55,-7,minecraft:andesite)
B(6,56,-7,minecraft:andesite)
B(6,57,-7,minecraft:andesite)
B(6,58,-7,minecraft:andesite)
B(6,59,-7,minecraft:andesite)
B(6,60,-7,minecraft:andesite)
B(6,61,-7,minecraft:andesite)
B(6,62,-7,minecraft:andesite)
B(6,48,-6,minecraft:andesite)
B(6,49,-6,minecraft:andesite)
B(6,50,-6,minecraft:andesite)
B(6,51,-6,minecraft:andesite)
B(6,52,-6,minecraft:andesite)
B(6,53,-6,minecraft:andesite)
B(6,54,-6,minecraft:andesite)
B(6,55,-6,minecraft:andesite)
B(6,56,-6,minecraft:andesite)
B(6,57,-6,minecraft:andesite)
B(6,58,-6,minecraft:andesite)
B(6,59,-6,minecraft:andesite)
B(6,60,-6,minecraft:andesite)
B(6,61,-6,minecraft:andesite)
B(6,62,-6,minecraft:andesite)
B(6,49,-5,minecraft:andesite)
B(6,50,-5,minecraft:andesite)
B(6,51,-5,minecraft:andesite)
B(6,52,-5,minecraft:andesite)
B(6,53,-5,minecraft:andesite)
B(6,54,-5,minecraft:andesite)
B(6,55,-5,minecraft:andesite)
B(6,56,-5,minecraft:andesite)
B(6,57,-5,minecraft:andesite)
B(6,58,-5,minecraft:andesite)
B(6,59,-5,minecraft:andesite)
B(6,60,-5,minecraft:andesite)
B(6,61,-5,minecraft:andesite)
B(6,62,-5,minecraft:andesite)
B(6,63,-5,minecraft:andesite)
B(6,64,-5,minecraft:andesite)
B(6,49,-4,minecraft:andesite)
B(6,50,-4,minecraft:andesite)
B(6,51,-4,minecraft:andesite)
B(6,52,-4,minecraft:andesite)
B(6,53,-4,minecraft:andesite)
B(6,54,-4,minecraft:andesite)
B(6,55,-4,minecraft:stone)
B(6,56,-4,minecraft:stone)
B(6,57,-4,minecraft:andesite)
B(6,58,-4,minecraft:andesite)
B(6,59,-4,minecraft:andesite)
B(6,60,-4,minecraft:andesite)
B(6,61,-4,minecraft:andesite)
B(6,62,-4,minecraft:andesite)
B(6,63,-4,minecraft:andesite)
B(6,64,-4,minecraft:andesite)
B(6,48,-3,minecraft:andesite)
B(6,49,-3,minecraft:andesite)
B(6,50,-3,minecraft:andesite)
B(6,51,-3,minecraft:andesite)
B(6,52,-3,minecraft:andesite)
B(6,53,-3,minecraft:andesite)
B(6,54,-3,minecraft:stone)
B(6,55,-3,minecraft:stone)
B(6,56,-3,minecraft:stone)
B(6,57,-3,minecraft:stone)
B(6,58,-3,minecraft:andesite)
B(6,59,-3,minecraft:andesite)
B(6,60,-3,minecraft:andesite)
B(6,61,-3,minecraft:diorite)
B(6,62,-3,minecraft:diorite)
B(6,63,-3,minecraft:diorite)
B(6,64,-3,minecraft:diorite)
B(6,48,-2,minecraft:andesite)
B(6,49,-2,minecraft:andesite)
B(6,50,-2,minecraft:andesite)
B(6,51,-2,minecraft:andesite)
B(6,52,-2,minecraft:andesite)
B(6,53,-2,minecraft:andesite)
B(6,54,-2,minecraft:stone)
B(6,55,-2,minecraft:stone)
B(6,56,-2,minecraft:stone)
B(6,57,-2,minecraft:stone)
B(6,58,-2,minecraft:stone)
B(6,59,-2,minecraft:andesite)
B(6,60,-2,minecraft:diorite)
B(6,61,-2,minecraft:diorite)
B(6,62,-2,minecraft:diorite)
B(6,63,-2,minecraft:diorite)
B(6,64,-2,minecraft:diorite)
B(6,65,-2,minecraft:diorite)
B(6,47,-1,minecraft:andesite)
B(6,48,-1,minecraft:andesite)
B(6,49,-1,minecraft:andesite)
B(6,50,-1,minecraft:andesite)
B(6,51,-1,minecraft:andesite)
B(6,52,-1,minecraft:andesite)
B(6,53,-1,minecraft:andesite)
B(6,54,-1,minecraft:stone)
B(6,55,-1,minecraft:stone)
B(6,56,-1,minecraft:stone)
B(6,57,-1,minecraft:stone)
B(6,58,-1,minecraft:stone)
B(6,59,-1,minecraft:diorite)
B(6,60,-1,minecraft:diorite)
B(6,61,-1,minecraft:diorite)
B(6,62,-1,minecraft:diorite)
B(6,63,-1,minecraft:diorite)
B(6,64,-1,minecraft:diorite)
B(6,65,-1,minecraft:diorite)
B(6,47,0,minecraft:andesite)
B(6,48,0,minecraft:andesite)
B(6,49,0,minecraft:andesite)
B(6,50,0,minecraft:andesite)
B(6,51,0,minecraft:andesite)
B(6,52,0,minecraft:andesite)
B(6,53,0,minecraft:stone)
B(6,54,0,minecraft:stone)
B(6,55,0,minecraft:stone)
B(6,56,0,minecraft:stone)
B(6,57,0,minecraft:stone)
B(6,58,0,minecraft:stone)
B(6,59,0,minecraft:diorite)
B(6,60,0,minecraft:diorite)
B(6,61,0,minecraft:diorite)
B(6,62,0,minecraft:diorite)
B(6,63,0,minecraft:diorite)
B(6,64,0,minecraft:diorite)
B(6,65,0,minecraft:diorite)
B(6,47,1,minecraft:obsidian)
B(6,48,1,minecraft:andesite)
B(6,49,1,minecraft:andesite)
B(6,50,1,minecraft:andesite)
B(6,51,1,minecraft:andesite)
B(6,52,1,minecraft:stone)
B(6,53,1,minecraft:stone)
B(6,54,1,minecraft:stone)
B(6,55,1,minecraft:stone)
B(6,56,1,minecraft:stone)
B(6,57,1,minecraft:stone)
B(6,58,1,minecraft:stone)
B(6,59,1,minecraft:diorite)
B(6,60,1,minecraft:diorite)
B(6,61,1,minecraft:diorite)
B(6,62,1,minecraft:diorite)
B(6,63,1,minecraft:diorite)
B(6,64,1,minecraft:diorite)
B(6,65,1,minecraft:diorite)
B(6,46,2,minecraft:obsidian)
B(6,47,2,minecraft:obsidian)
B(6,48,2,minecraft:obsidian)
B(6,49,2,minecraft:andesite)
B(6,50,2,minecraft:andesite)
B(6,51,2,minecraft:stone)
B(6,52,2,minecraft:stone)
B(6,53,2,minecraft:stone)
B(6,54,2,minecraft:stone)
B(6,55,2,minecraft:stone)
B(6,56,2,minecraft:stone)
B(6,57,2,minecraft:stone)
B(6,58,2,minecraft:stone)
B(6,59,2,minecraft:diorite)
B(6,60,2,minecraft:diorite)
B(6,61,2,minecraft:diorite)
B(6,62,2,minecraft:diorite)
B(6,63,2,minecraft:diorite)
B(6,64,2,minecraft:diorite)
B(6,46,3,minecraft:obsidian)
B(6,47,3,minecraft:obsidian)
B(6,48,3,minecraft:obsidian)
B(6,49,3,minecraft:andesite)
B(6,50,3,minecraft:andesite)
B(6,51,3,minecraft:andesite)
B(6,52,3,minecraft:stone)
B(6,53,3,minecraft:stone)
B(6,54,3,minecraft:stone)
B(6,55,3,minecraft:stone)
B(6,56,3,minecraft:stone)
B(6,57,3,minecraft:stone)
B(6,58,3,minecraft:stone)
B(6,59,3,minecraft:diorite)
B(6,60,3,minecraft:diorite)
B(6,61,3,minecraft:diorite)
B(6,62,3,minecraft:diorite)
B(6,63,3,minecraft:diorite)
B(6,64,3,minecraft:diorite)
B(6,65,3,minecraft:diorite)
B(6,46,4,minecraft:obsidian)
B(6,47,4,minecraft:obsidian)
B(6,48,4,minecraft:obsidian)
B(6,49,4,minecraft:andesite)
B(6,50,4,minecraft:andesite)
B(6,51,4,minecraft:andesite)
B(6,52,4,minecraft:andesite)
B(6,53,4,minecraft:stone)
B(6,54,4,minecraft:stone)
B(6,55,4,minecraft:stone)
B(6,56,4,minecraft:stone)
B(6,57,4,minecraft:stone)
B(6,58,4,minecraft:stone)
B(6,59,4,minecraft:stone)
B(6,60,4,minecraft:diorite)
B(6,61,4,minecraft:diorite)
B(6,62,4,minecraft:diorite)
B(6,63,4,minecraft:diorite)
B(6,64,4,minecraft:diorite)
B(6,65,4,minecraft:diorite)
B(6,47,5,minecraft:obsidian)
B(6,48,5,minecraft:obsidian)
B(6,49,5,minecraft:andesite)
B(6,50,5,minecraft:andesite)
B(6,51,5,minecraft:andesite)
B(6,52,5,minecraft:andesite)
B(6,53,5,minecraft:stone)
B(6,54,5,minecraft:stone)
B(6,55,5,minecraft:stone)
B(6,56,5,minecraft:stone)
B(6,57,5,minecraft:stone)
B(6,58,5,minecraft:stone)
B(6,59,5,minecraft:stone)
B(6,60,5,minecraft:diorite)
B(6,61,5,minecraft:diorite)
B(6,62,5,minecraft:diorite)
B(6,63,5,minecraft:diorite)
B(6,64,5,minecraft:diorite)
B(6,65,5,minecraft:diorite)
B(6,47,6,minecraft:obsidian)
B(6,48,6,minecraft:obsidian)
B(6,49,6,minecraft:andesite)
B(6,50,6,minecraft:andesite)
B(6,51,6,minecraft:andesite)
B(6,52,6,minecraft:andesite)
B(6,53,6,minecraft:stone)
B(6,54,6,minecraft:stone)
B(6,55,6,minecraft:stone)
B(6,56,6,minecraft:diorite)
B(6,57,6,minecraft:diorite)
B(6,58,6,minecraft:diorite)
B(6,59,6,minecraft:diorite)
B(6,60,6,minecraft:diorite)
B(6,61,6,minecraft:diorite)
B(6,62,6,minecraft:diorite)
B(6,63,6,minecraft:diorite)
B(6,64,6,minecraft:diorite)
B(6,65,6,minecraft:diorite)
B(6,47,7,minecraft:obsidian)
B(6,48,7,minecraft:obsidian)
B(6,49,7,minecraft:andesite)
B(6,50,7,minecraft:andesite)
B(6,51,7,minecraft:andesite)
B(6,52,7,minecraft:andesite)
B(6,53,7,minecraft:andesite)
B(6,54,7,minecraft:stone)
B(6,55,7,minecraft:diorite)
B(6,56,7,minecraft:diorite)
B(6,57,7,minecraft:diorite)
B(6,58,7,minecraft:diorite)
B(6,59,7,minecraft:diorite)
B(6,60,7,minecraft:diorite)
B(6,61,7,minecraft:diorite)
B(6,62,7,minecraft:diorite)
B(6,63,7,minecraft:diorite)
B(6,64,7,minecraft:diorite)
B(6,47,8,minecraft:obsidian)
B(6,48,8,minecraft:obsidian)
B(6,49,8,minecraft:andesite)
B(6,50,8,minecraft:andesite)
B(6,51,8,minecraft:andesite)
B(6,52,8,minecraft:andesite)
B(6,53,8,minecraft:andesite)
B(6,54,8,minecraft:stone)
B(6,55,8,minecraft:diorite)
B(6,56,8,minecraft:diorite)
B(6,57,8,minecraft:diorite)
B(6,58,8,minecraft:diorite)
B(6,59,8,minecraft:diorite)
B(6,60,8,minecraft:diorite)
B(6,61,8,minecraft:diorite)
B(6,62,8,minecraft:diorite)
B(7,50,-7,minecraft:andesite)
B(7,51,-7,minecraft:andesite)
B(7,52,-7,minecraft:andesite)
B(7,53,-7,minecraft:andesite)
B(7,54,-7,minecraft:andesite)
B(7,55,-7,minecraft:andesite)
B(7,56,-7,minecraft:andesite)
B(7,57,-7,minecraft:andesite)
B(7,58,-7,minecraft:andesite)
B(7,59,-7,minecraft:andesite)
B(7,60,-7,minecraft:andesite)
B(7,61,-7,minecraft:andesite)
B(7,62,-7,minecraft:andesite)
B(7,50,-6,minecraft:andesite)
B(7,51,-6,minecraft:andesite)
B(7,52,-6,minecraft:andesite)
B(7,53,-6,minecraft:andesite)
B(7,54,-6,minecraft:andesite)
B(7,55,-6,minecraft:andesite)
B(7,56,-6,minecraft:andesite)
B(7,57,-6,minecraft:andesite)
B(7,58,-6,minecraft:andesite)
B(7,59,-6,minecraft:andesite)
B(7,60,-6,minecraft:andesite)
B(7,61,-6,minecraft:andesite)
B(7,62,-6,minecraft:andesite)
B(7,49,-5,minecraft:andesite)
B(7,50,-5,minecraft:andesite)
B(7,51,-5,minecraft:andesite)
B(7,52,-5,minecraft:andesite)
B(7,53,-5,minecraft:andesite)
B(7,54,-5,minecraft:andesite)
B(7,55,-5,minecraft:andesite)
B(7,56,-5,minecraft:andesite)
B(7,57,-5,minecraft:andesite)
B(7,58,-5,minecraft:andesite)
B(7,59,-5,minecraft:andesite)
B(7,60,-5,minecraft:andesite)
B(7,61,-5,minecraft:andesite)
B(7,62,-5,minecraft:andesite)
B(7,63,-5,minecraft:andesite)
B(7,49,-4,minecraft:andesite)
B(7,50,-4,minecraft:andesite)
B(7,51,-4,minecraft:andesite)
B(7,52,-4,minecraft:andesite)
B(7,53,-4,minecraft:andesite)
B(7,54,-4,minecraft:andesite)
B(7,55,-4,minecraft:stone)
B(7,56,-4,minecraft:andesite)
B(7,57,-4,minecraft:andesite)
B(7,58,-4,minecraft:andesite)
B(7,59,-4,minecraft:andesite)
B(7,60,-4,minecraft:andesite)
B(7,61,-4,minecraft:andesite)
B(7,62,-4,minecraft:andesite)
B(7,63,-4,minecraft:andesite)
B(7,48,-3,minecraft:andesite)
B(7,49,-3,minecraft:andesite)
B(7,50,-3,minecraft:andesite)
B(7,51,-3,minecraft:andesite)
B(7,52,-3,minecraft:andesite)
B(7,53,-3,minecraft:andesite)
B(7,54,-3,minecraft:stone)
B(7,55,-3,minecraft:stone)
B(7,56,-3,minecraft:stone)
B(7,57,-3,minecraft:stone)
B(7,58,-3,minecraft:andesite)
B(7,59,-3,minecraft:andesite)
B(7,60,-3,minecraft:andesite)
B(7,61,-3,minecraft:andesite)
B(7,62,-3,minecraft:andesite)
B(7,63,-3,minecraft:andesite)
B(7,64,-3,minecraft:andesite)
B(7,47,-2,minecraft:andesite)
B(7,48,-2,minecraft:andesite)
B(7,49,-2,minecraft:andesite)
B(7,50,-2,minecraft:andesite)
B(7,51,-2,minecraft:andesite)
B(7,52,-2,minecraft:andesite)
B(7,53,-2,minecraft:andesite)
B(7,54,-2,minecraft:stone)
B(7,55,-2,minecraft:stone)
B(7,56,-2,minecraft:stone)
B(7,57,-2,minecraft:stone)
B(7,58,-2,minecraft:stone)
B(7,59,-2,minecraft:andesite)
B(7,60,-2,minecraft:andesite)
B(7,61,-2,minecraft:diorite)
B(7,62,-2,minecraft:diorite)
B(7,63,-2,minecraft:diorite)
B(7,64,-2,minecraft:diorite)
B(7,65,-2,minecraft:diorite)
B(7,47,-1,minecraft:andesite)
B(7,48,-1,minecraft:andesite)
B(7,49,-1,minecraft:andesite)
B(7,50,-1,minecraft:andesite)
B(7,51,-1,minecraft:andesite)
B(7,52,-1,minecraft:andesite)
B(7,53,-1,minecraft:andesite)
B(7,54,-1,minecraft:stone)
B(7,55,-1,minecraft:stone)
B(7,56,-1,minecraft:stone)
B(7,57,-1,minecraft:stone)
B(7,58,-1,minecraft:stone)
B(7,59,-1,minecraft:andesite)
B(7,60,-1,minecraft:diorite)
B(7,61,-1,minecraft:diorite)
B(7,62,-1,minecraft:diorite)
B(7,63,-1,minecraft:diorite)
B(7,64,-1,minecraft:diorite)
B(7,65,-1,minecraft:diorite)
B(7,47,0,minecraft:andesite)
B(7,48,0,minecraft:andesite)
B(7,49,0,minecraft:andesite)
B(7,50,0,minecraft:andesite)
B(7,51,0,minecraft:andesite)
B(7,52,0,minecraft:andesite)
B(7,53,0,minecraft:stone)
B(7,54,0,minecraft:stone)
B(7,55,0,minecraft:stone)
B(7,56,0,minecraft:stone)
B(7,57,0,minecraft:stone)
B(7,58,0,minecraft:stone)
B(7,59,0,minecraft:stone)
B(7,60,0,minecraft:diorite)
B(7,61,0,minecraft:diorite)
B(7,62,0,minecraft:diorite)
B(7,63,0,minecraft:diorite)
B(7,64,0,minecraft:diorite)
B(7,65,0,minecraft:diorite)
B(7,46,1,minecraft:obsidian)
B(7,47,1,minecraft:obsidian)
B(7,48,1,minecraft:andesite)
B(7,49,1,minecraft:andesite)
B(7,50,1,minecraft:andesite)
B(7,51,1,minecraft:andesite)
B(7,52,1,minecraft:stone)
B(7,53,1,minecraft:stone)
B(7,54,1,minecraft:stone)
B(7,55,1,minecraft:stone)
B(7,56,1,minecraft:stone)
B(7,57,1,minecraft:stone)
B(7,58,1,minecraft:stone)
B(7,59,1,minecraft:stone)
B(7,60,1,minecraft:diorite)
B(7,61,1,minecraft:diorite)
B(7,62,1,minecraft:diorite)
B(7,63,1,minecraft:diorite)
B(7,64,1,minecraft:diorite)
B(7,65,1,minecraft:diorite)
B(7,46,2,minecraft:obsidian)
B(7,47,2,minecraft:obsidian)
B(7,48,2,minecraft:obsidian)
B(7,49,2,minecraft:andesite)
B(7,50,2,minecraft:andesite)
B(7,51,2,minecraft:stone)
B(7,52,2,minecraft:stone)
B(7,53,2,minecraft:stone)
B(7,54,2,minecraft:stone)
B(7,55,2,minecraft:stone)
B(7,56,2,minecraft:stone)
B(7,57,2,minecraft:stone)
B(7,58,2,minecraft:stone)
B(7,59,2,minecraft:stone)
B(7,60,2,minecraft:diorite)
B(7,61,2,minecraft:diorite)
B(7,62,2,minecraft:diorite)
B(7,63,2,minecraft:diorite)
B(7,64,2,minecraft:diorite)
B(7,65,2,minecraft:diorite)
B(7,46,3,minecraft:obsidian)
B(7,47,3,minecraft:obsidian)
B(7,48,3,minecraft:obsidian)
B(7,49,3,minecraft:stone)
B(7,50,3,minecraft:stone)
B(7,51,3,minecraft:stone)
B(7,52,3,minecraft:stone)
B(7,53,3,minecraft:stone)
B(7,54,3,minecraft:stone)
B(7,55,3,minecraft:stone)
B(7,56,3,minecraft:stone)
B(7,57,3,minecraft:stone)
B(7,58,3,minecraft:stone)
B(7,59,3,minecraft:stone)
B(7,60,3,minecraft:diorite)
B(7,61,3,minecraft:diorite)
B(7,62,3,minecraft:diorite)
B(7,63,3,minecraft:diorite)
B(7,64,3,minecraft:diorite)
B(7,65,3,minecraft:diorite)
B(7,46,4,minecraft:obsidian)
B(7,47,4,minecraft:obsidian)
B(7,48,4,minecraft:obsidian)
B(7,49,4,minecraft:andesite)
B(7,50,4,minecraft:andesite)
B(7,51,4,minecraft:stone)
B(7,52,4,minecraft:stone)
B(7,53,4,minecraft:stone)
B(7,54,4,minecraft:stone)
B(7,55,4,minecraft:stone)
B(7,56,4,minecraft:stone)
B(7,57,4,minecraft:stone)
B(7,58,4,minecraft:stone)
B(7,59,4,minecraft:stone)
B(7,60,4,minecraft:stone)
B(7,61,4,minecraft:diorite)
B(7,62,4,minecraft:diorite)
B(7,63,4,minecraft:diorite)
B(7,64,4,minecraft:diorite)
B(7,65,4,minecraft:diorite)
B(7,46,5,minecraft:obsidian)
B(7,47,5,minecraft:obsidian)
B(7,48,5,minecraft:obsidian)
B(7,49,5,minecraft:andesite)
B(7,50,5,minecraft:andesite)
B(7,51,5,minecraft:andesite)
B(7,52,5,minecraft:stone)
B(7,53,5,minecraft:stone)
B(7,54,5,minecraft:stone)
B(7,55,5,minecraft:stone)
B(7,56,5,minecraft:stone)
B(7,57,5,minecraft:stone)
B(7,58,5,minecraft:stone)
B(7,59,5,minecraft:stone)
B(7,60,5,minecraft:diorite)
B(7,61,5,minecraft:diorite)
B(7,62,5,minecraft:diorite)
B(7,63,5,minecraft:diorite)
B(7,64,5,minecraft:diorite)
B(7,65,5,minecraft:diorite)
B(7,46,6,minecraft:obsidian)
B(7,47,6,minecraft:obsidian)
B(7,48,6,minecraft:obsidian)
B(7,49,6,minecraft:andesite)
B(7,50,6,minecraft:andesite)
B(7,51,6,minecraft:andesite)
B(7,52,6,minecraft:andesite)
B(7,53,6,minecraft:stone)
B(7,54,6,minecraft:stone)
B(7,55,6,minecraft:stone)
B(7,56,6,minecraft:stone)
B(7,57,6,minecraft:stone)
B(7,58,6,minecraft:stone)
B(7,59,6,minecraft:stone)
B(7,60,6,minecraft:diorite)
B(7,61,6,minecraft:diorite)
B(7,62,6,minecraft:diorite)
B(7,63,6,minecraft:diorite)
B(7,64,6,minecraft:diorite)
B(7,65,6,minecraft:diorite)
B(7,46,7,minecraft:obsidian)
B(7,47,7,minecraft:obsidian)
B(7,48,7,minecraft:obsidian)
B(7,49,7,minecraft:andesite)
B(7,50,7,minecraft:andesite)
B(7,51,7,minecraft:andesite)
B(7,52,7,minecraft:andesite)
B(7,53,7,minecraft:stone)
B(7,54,7,minecraft:stone)
B(7,55,7,minecraft:stone)
B(7,56,7,minecraft:stone)
B(7,57,7,minecraft:diorite)
B(7,58,7,minecraft:diorite)
B(7,59,7,minecraft:diorite)
B(7,60,7,minecraft:diorite)
B(7,61,7,minecraft:diorite)
B(7,62,7,minecraft:diorite)
B(7,63,7,minecraft:diorite)
B(7,64,7,minecraft:diorite)
B(7,65,7,minecraft:diorite)
B(7,46,8,minecraft:obsidian)
B(7,47,8,minecraft:obsidian)
B(7,48,8,minecraft:obsidian)
B(7,49,8,minecraft:obsidian)
B(7,50,8,minecraft:andesite)
B(7,51,8,minecraft:andesite)
B(7,52,8,minecraft:andesite)
B(7,53,8,minecraft:stone)
B(7,54,8,minecraft:stone)
B(7,55,8,minecraft:stone)
B(7,56,8,minecraft:diorite)
B(7,57,8,minecraft:diorite)
B(7,58,8,minecraft:diorite)
B(7,59,8,minecraft:diorite)
B(7,60,8,minecraft:diorite)
B(7,61,8,minecraft:diorite)
B(7,62,8,minecraft:diorite)
B(7,63,8,minecraft:diorite)
B(7,64,8,minecraft:diorite)

#######################################################################
# +-----------------------------------------------------------------+ #
# |                             Branches                            | #
# +-----------------------------------------------------------------+ #
#######################################################################

Branch(0,0,-16,true,Amethyst_MediumC1R0,NORTH,100.0,0)

#######################################################################
# +-----------------------------------------------------------------+ #
# |                             Entities                            | #
# +-----------------------------------------------------------------+ #
#######################################################################

