
#######################################################################
# +-----------------------------------------------------------------+ #
# |                            BO4 object                           | #
# +-----------------------------------------------------------------+ #
#######################################################################

Author: NLBlackEagle

Description: No description given

SettingsMode: WriteWithoutComments


#######################################################################
# +-----------------------------------------------------------------+ #
# |                          Main settings                          | #
# +-----------------------------------------------------------------+ #
#######################################################################

FixedRotation: 

Frequency: 0

SpawnHeight: highestBlock

UseCenterForHighestBlock: true

##############################
# Height Limits for the BO4. #
##############################

MinHeight: 0

MaxHeight: 255

InheritBO3: 

InheritBO3Rotation: NORTH

OverrideChildSettings: true

OverrideParentHeight: false

CanOverride: false

BranchFrequency: 0

BranchFrequencyGroup: 

MustBeBelowOther: false

MustBeInside: 

CannotBeInside: 

ReplacesBO3: 

MustBeInsideWorldBorders: false

CanSpawnOnWater: true

SpawnOnWaterOnly: false

SpawnUnderWater: false

SpawnAtWaterLevel: false

HeightOffset: 0

RemoveAir: true

ReplaceAbove: 

ReplaceBelow: 

ReplaceWithBiomeBlocks: true

ReplaceWithSurfaceBlock: GRASS

ReplaceWithGroundBlock: DIRT

ReplaceWithStoneBlock: STONE

SmoothRadius: 0

SmoothHeightOffset: 0

SmoothStartTop: false

SmoothStartWood: false

SmoothingSurfaceBlock: 

SmoothingGroundBlock: 

BO3Group: 

IsSpawnPoint: false

DoReplaceBlocks: true


#######################################################################
# +-----------------------------------------------------------------+ #
# |                              Blocks                             | #
# +-----------------------------------------------------------------+ #
#######################################################################

B(2,25,8,minecraft:andesite)
B(2,26,8,minecraft:andesite)
B(2,27,8,minecraft:andesite)
B(3,24,7,minecraft:andesite)
B(3,25,7,minecraft:andesite)
B(3,26,7,minecraft:andesite)
B(3,27,7,minecraft:andesite)
B(3,28,7,minecraft:andesite)
B(3,23,8,minecraft:andesite)
B(3,24,8,minecraft:andesite)
B(3,25,8,minecraft:andesite)
B(3,26,8,minecraft:andesite)
B(3,27,8,minecraft:andesite)
B(3,28,8,minecraft:andesite)
B(3,29,8,minecraft:andesite)
B(4,27,4,minecraft:andesite)
B(4,28,4,minecraft:andesite)
B(4,29,4,minecraft:andesite)
B(4,26,5,minecraft:andesite)
B(4,27,5,minecraft:andesite)
B(4,28,5,minecraft:andesite)
B(4,29,5,minecraft:andesite)
B(4,30,5,minecraft:andesite)
B(4,24,6,minecraft:andesite)
B(4,25,6,minecraft:andesite)
B(4,26,6,minecraft:andesite)
B(4,27,6,minecraft:andesite)
B(4,28,6,minecraft:andesite)
B(4,29,6,minecraft:andesite)
B(4,30,6,minecraft:andesite)
B(4,23,7,minecraft:andesite)
B(4,24,7,minecraft:andesite)
B(4,25,7,minecraft:andesite)
B(4,26,7,minecraft:andesite)
B(4,27,7,minecraft:andesite)
B(4,28,7,minecraft:andesite)
B(4,29,7,minecraft:andesite)
B(4,30,7,minecraft:andesite)
B(4,21,8,minecraft:andesite)
B(4,22,8,minecraft:andesite)
B(4,23,8,minecraft:andesite)
B(4,24,8,minecraft:andesite)
B(4,25,8,minecraft:andesite)
B(4,26,8,minecraft:andesite)
B(4,27,8,minecraft:andesite)
B(4,28,8,minecraft:andesite)
B(4,29,8,minecraft:andesite)
B(4,30,8,minecraft:andesite)
B(5,26,3,minecraft:andesite)
B(5,27,3,minecraft:andesite)
B(5,28,3,minecraft:andesite)
B(5,29,3,minecraft:andesite)
B(5,30,3,minecraft:andesite)
B(5,25,4,minecraft:andesite)
B(5,26,4,minecraft:andesite)
B(5,27,4,minecraft:andesite)
B(5,28,4,minecraft:andesite)
B(5,29,4,minecraft:andesite)
B(5,30,4,minecraft:andesite)
B(5,31,4,minecraft:andesite)
B(5,24,5,minecraft:andesite)
B(5,25,5,minecraft:andesite)
B(5,26,5,minecraft:andesite)
B(5,27,5,minecraft:andesite)
B(5,28,5,minecraft:andesite)
B(5,29,5,minecraft:andesite)
B(5,30,5,minecraft:andesite)
B(5,31,5,minecraft:andesite)
B(5,23,6,minecraft:andesite)
B(5,24,6,minecraft:andesite)
B(5,25,6,minecraft:andesite)
B(5,26,6,minecraft:andesite)
B(5,27,6,minecraft:andesite)
B(5,28,6,minecraft:andesite)
B(5,29,6,minecraft:andesite)
B(5,30,6,minecraft:andesite)
B(5,31,6,minecraft:andesite)
B(5,21,7,minecraft:andesite)
B(5,22,7,minecraft:andesite)
B(5,23,7,minecraft:andesite)
B(5,24,7,minecraft:andesite)
B(5,25,7,minecraft:andesite)
B(5,26,7,minecraft:andesite)
B(5,27,7,minecraft:andesite)
B(5,28,7,minecraft:andesite)
B(5,29,7,minecraft:andesite)
B(5,30,7,minecraft:andesite)
B(5,31,7,minecraft:andesite)
B(5,19,8,minecraft:andesite)
B(5,20,8,minecraft:andesite)
B(5,21,8,minecraft:andesite)
B(5,22,8,minecraft:andesite)
B(5,23,8,minecraft:andesite)
B(5,24,8,minecraft:andesite)
B(5,25,8,minecraft:andesite)
B(5,26,8,minecraft:andesite)
B(5,27,8,minecraft:andesite)
B(5,28,8,minecraft:andesite)
B(5,29,8,minecraft:andesite)
B(5,30,8,minecraft:andesite)
B(5,31,8,minecraft:andesite)
B(5,32,8,minecraft:andesite)
B(5,33,8,minecraft:andesite)
B(6,29,0,minecraft:andesite)
B(6,30,0,minecraft:andesite)
B(6,31,0,minecraft:andesite)
B(6,28,1,minecraft:andesite)
B(6,29,1,minecraft:andesite)
B(6,30,1,minecraft:andesite)
B(6,31,1,minecraft:andesite)
B(6,32,1,minecraft:andesite)
B(6,26,2,minecraft:andesite)
B(6,27,2,minecraft:andesite)
B(6,28,2,minecraft:andesite)
B(6,29,2,minecraft:andesite)
B(6,30,2,minecraft:andesite)
B(6,31,2,minecraft:andesite)
B(6,32,2,minecraft:andesite)
B(6,25,3,minecraft:andesite)
B(6,26,3,minecraft:andesite)
B(6,27,3,minecraft:andesite)
B(6,28,3,minecraft:andesite)
B(6,29,3,minecraft:andesite)
B(6,30,3,minecraft:andesite)
B(6,31,3,minecraft:andesite)
B(6,32,3,minecraft:andesite)
B(6,24,4,minecraft:andesite)
B(6,25,4,minecraft:andesite)
B(6,26,4,minecraft:andesite)
B(6,27,4,minecraft:andesite)
B(6,28,4,minecraft:andesite)
B(6,29,4,minecraft:andesite)
B(6,30,4,minecraft:andesite)
B(6,31,4,minecraft:andesite)
B(6,32,4,minecraft:andesite)
B(6,23,5,minecraft:andesite)
B(6,24,5,minecraft:andesite)
B(6,25,5,minecraft:andesite)
B(6,26,5,minecraft:andesite)
B(6,27,5,minecraft:andesite)
B(6,28,5,minecraft:andesite)
B(6,29,5,minecraft:andesite)
B(6,30,5,minecraft:andesite)
B(6,31,5,minecraft:andesite)
B(6,32,5,minecraft:andesite)
B(6,21,6,minecraft:andesite)
B(6,22,6,minecraft:andesite)
B(6,23,6,minecraft:andesite)
B(6,24,6,minecraft:andesite)
B(6,25,6,minecraft:andesite)
B(6,26,6,minecraft:andesite)
B(6,27,6,minecraft:andesite)
B(6,28,6,minecraft:andesite)
B(6,29,6,minecraft:andesite)
B(6,30,6,minecraft:andesite)
B(6,31,6,minecraft:andesite)
B(6,32,6,minecraft:andesite)
B(6,19,7,minecraft:andesite)
B(6,20,7,minecraft:andesite)
B(6,21,7,minecraft:andesite)
B(6,22,7,minecraft:andesite)
B(6,23,7,minecraft:andesite)
B(6,24,7,minecraft:andesite)
B(6,25,7,minecraft:andesite)
B(6,26,7,minecraft:andesite)
B(6,27,7,minecraft:andesite)
B(6,28,7,minecraft:andesite)
B(6,29,7,minecraft:andesite)
B(6,30,7,minecraft:andesite)
B(6,31,7,minecraft:andesite)
B(6,32,7,minecraft:andesite)
B(6,33,7,minecraft:andesite)
B(6,18,8,minecraft:andesite)
B(6,19,8,minecraft:andesite)
B(6,20,8,minecraft:andesite)
B(6,21,8,minecraft:andesite)
B(6,22,8,minecraft:andesite)
B(6,23,8,minecraft:andesite)
B(6,24,8,minecraft:andesite)
B(6,25,8,minecraft:andesite)
B(6,26,8,minecraft:andesite)
B(6,27,8,minecraft:andesite)
B(6,28,8,minecraft:andesite)
B(6,29,8,minecraft:andesite)
B(6,30,8,minecraft:andesite)
B(6,31,8,minecraft:andesite)
B(6,32,8,minecraft:andesite)
B(6,33,8,minecraft:andesite)
B(6,34,8,minecraft:andesite)
B(7,28,-1,minecraft:andesite)
B(7,29,-1,minecraft:andesite)
B(7,30,-1,minecraft:andesite)
B(7,31,-1,minecraft:andesite)
B(7,32,-1,minecraft:andesite)
B(7,27,0,minecraft:andesite)
B(7,28,0,minecraft:andesite)
B(7,29,0,minecraft:andesite)
B(7,30,0,minecraft:andesite)
B(7,31,0,minecraft:andesite)
B(7,32,0,minecraft:andesite)
B(7,33,0,minecraft:andesite)
B(7,26,1,minecraft:andesite)
B(7,27,1,minecraft:andesite)
B(7,28,1,minecraft:andesite)
B(7,29,1,minecraft:andesite)
B(7,30,1,minecraft:andesite)
B(7,31,1,minecraft:andesite)
B(7,32,1,minecraft:andesite)
B(7,33,1,minecraft:andesite)
B(7,25,2,minecraft:andesite)
B(7,26,2,minecraft:andesite)
B(7,27,2,minecraft:andesite)
B(7,28,2,minecraft:andesite)
B(7,29,2,minecraft:andesite)
B(7,30,2,minecraft:andesite)
B(7,31,2,minecraft:andesite)
B(7,32,2,minecraft:andesite)
B(7,33,2,minecraft:andesite)
B(7,24,3,minecraft:andesite)
B(7,25,3,minecraft:andesite)
B(7,26,3,minecraft:andesite)
B(7,27,3,minecraft:andesite)
B(7,28,3,minecraft:andesite)
B(7,29,3,minecraft:andesite)
B(7,30,3,minecraft:andesite)
B(7,31,3,minecraft:andesite)
B(7,32,3,minecraft:andesite)
B(7,33,3,minecraft:andesite)
B(7,23,4,minecraft:andesite)
B(7,24,4,minecraft:andesite)
B(7,25,4,minecraft:andesite)
B(7,26,4,minecraft:andesite)
B(7,27,4,minecraft:andesite)
B(7,28,4,minecraft:andesite)
B(7,29,4,minecraft:andesite)
B(7,30,4,minecraft:andesite)
B(7,31,4,minecraft:andesite)
B(7,32,4,minecraft:andesite)
B(7,33,4,minecraft:andesite)
B(7,20,5,minecraft:andesite)
B(7,21,5,minecraft:andesite)
B(7,22,5,minecraft:andesite)
B(7,23,5,minecraft:andesite)
B(7,24,5,minecraft:andesite)
B(7,25,5,minecraft:andesite)
B(7,26,5,minecraft:andesite)
B(7,27,5,minecraft:andesite)
B(7,28,5,minecraft:andesite)
B(7,29,5,minecraft:andesite)
B(7,30,5,minecraft:andesite)
B(7,31,5,minecraft:andesite)
B(7,32,5,minecraft:andesite)
B(7,33,5,minecraft:andesite)
B(7,19,6,minecraft:andesite)
B(7,20,6,minecraft:andesite)
B(7,21,6,minecraft:andesite)
B(7,22,6,minecraft:andesite)
B(7,23,6,minecraft:andesite)
B(7,24,6,minecraft:andesite)
B(7,25,6,minecraft:andesite)
B(7,26,6,minecraft:andesite)
B(7,27,6,minecraft:andesite)
B(7,28,6,minecraft:andesite)
B(7,29,6,minecraft:andesite)
B(7,30,6,minecraft:andesite)
B(7,31,6,minecraft:andesite)
B(7,32,6,minecraft:andesite)
B(7,33,6,minecraft:andesite)
B(7,18,7,minecraft:andesite)
B(7,19,7,minecraft:andesite)
B(7,20,7,minecraft:andesite)
B(7,21,7,minecraft:andesite)
B(7,22,7,minecraft:andesite)
B(7,23,7,minecraft:andesite)
B(7,24,7,minecraft:andesite)
B(7,25,7,minecraft:andesite)
B(7,26,7,minecraft:andesite)
B(7,27,7,minecraft:andesite)
B(7,28,7,minecraft:andesite)
B(7,29,7,minecraft:andesite)
B(7,30,7,minecraft:andesite)
B(7,31,7,minecraft:andesite)
B(7,32,7,minecraft:andesite)
B(7,33,7,minecraft:andesite)
B(7,34,7,minecraft:andesite)
B(7,17,8,minecraft:andesite)
B(7,18,8,minecraft:andesite)
B(7,19,8,minecraft:andesite)
B(7,20,8,minecraft:andesite)
B(7,21,8,minecraft:andesite)
B(7,22,8,minecraft:andesite)
B(7,23,8,minecraft:andesite)
B(7,24,8,minecraft:andesite)
B(7,25,8,minecraft:andesite)
B(7,26,8,minecraft:andesite)
B(7,27,8,minecraft:andesite)
B(7,28,8,minecraft:andesite)
B(7,29,8,minecraft:andesite)
B(7,30,8,minecraft:andesite)
B(7,31,8,minecraft:andesite)
B(7,32,8,minecraft:andesite)
B(7,33,8,minecraft:andesite)
B(7,34,8,minecraft:andesite)
B(7,35,8,minecraft:andesite)

#######################################################################
# +-----------------------------------------------------------------+ #
# |                             Branches                            | #
# +-----------------------------------------------------------------+ #
#######################################################################

Branch(16,0,0,true,Amethyst_MediumC1R5,NORTH,100.0,0)

#######################################################################
# +-----------------------------------------------------------------+ #
# |                             Entities                            | #
# +-----------------------------------------------------------------+ #
#######################################################################

