#######################################################################
# +-----------------------------------------------------------------+ #
# |                            BO3 object                           | #
# +-----------------------------------------------------------------+ #
#######################################################################

# This is the config file of a custom object.
# If you add this object correctly to your BiomeConfigs, it will spawn in the world.

# This is the creator of this BO3 object
Author: BO3 BulkEdit (by LanToaster)

# A short description of this BO3 object
Description: This Object was Created with BO3_BulkEdit

# The BO3 version, don't change this! It can be used by external applications to do a version check.
Version: 3

# The settings mode, WriteAll, WriteWithoutComments or WriteDisable. See WorldConfig.
SettingsMode: WriteDisable


#######################################################################
# +-----------------------------------------------------------------+ #
# |                          Main settings                          | #
# +-----------------------------------------------------------------+ #
#######################################################################

# This needs to be set to true to spawn the object in the Tree and Sapling resources.
Tree: false

# The frequency of the BO3 from 1 to 200. Tries this many times to spawn this BO3 when using the CustomObject(...) resource.

Frequency: 1

# The rarity of the BO3 from 0 to 100. Each spawn attempt has rarity% chance to succeed when using the CustomObject(...) resource.

Rarity: 100.0

# If you set this to true, the BO3 will be placed with a random rotation.
RotateRandomly: false

# The spawn height of the BO3 - randomY, highestBlock or highestSolidBlock.
SpawnHeight: randomY

# The height limits for the BO3.
MinHeight: 82

MaxHeight: 82

# Objects can have other objects attacthed to it: branches. Branches can also
# have branches attached to it, which can also have branches, etc. This is the
# maximum branch depth for this objects.
MaxBranchDepth: 10

# When spawned with the UseWorld keyword, this BO3 should NOT spawn in the following biomes.
# If you writer.write the BO3 name directly in the BiomeConfigs, this will be ignored.
ExcludedBiomes: All


#######################################################################
# +-----------------------------------------------------------------+ #
# |                      Source block settings                      | #
# +-----------------------------------------------------------------+ #
#######################################################################

# The block(s) the BO3 should spawn in.
SourceBlocks: AIR

# The maximum percentage of the BO3 that can be outside the SourceBlock.
# The BO3 won't be placed on a location with more blocks outside the SourceBlock than this percentage.
MaxPercentageOutsideSourceBlock: 100

# What to do when a block is about to be placed outside the SourceBlock? (dontPlace, placeAnyway)
OutsideSourceBlock: placeAnyway


#######################################################################
# +-----------------------------------------------------------------+ #
# |                              Blocks                             | #
# +-----------------------------------------------------------------+ #
#######################################################################

# All the blocks used in the BO3 are listed here. Possible blocks:
# Block(x,y,z,id[.data][,nbtfile.nbt)
# RandomBlock(x,y,z,id[:data][,nbtfile.nbt],chance[,id[:data][,nbtfile.nbt],chance[,...]])
# So RandomBlock(0,0,0,CHEST:0,chest.nbt,50,CHEST:0,anotherchest.nbt,100) will spawn a chest at
# the BO3 origin, and give it a 50% chance to have the contents of chest.nbt, or, if that
# fails, a 100% percent chance to have the contents of anotherchest.nbt.
RandomBlock(-7,-1,-7,STONEBRICK:1,10,STONEBRICK:2,10,COBBLESTONE,10,MOSSY_COBBLESTONE,10,SMOOTH_BRICK,100)
RandomBlock(-6,-1,-7,STONEBRICK:1,10,STONEBRICK:2,10,COBBLESTONE,10,MOSSY_COBBLESTONE,10,SMOOTH_BRICK,100)
RandomBlock(-5,-1,-7,STONEBRICK:1,10,STONEBRICK:2,10,COBBLESTONE,10,MOSSY_COBBLESTONE,10,SMOOTH_BRICK,100)
RandomBlock(-4,-1,-7,STONEBRICK:1,10,STONEBRICK:2,10,COBBLESTONE,10,MOSSY_COBBLESTONE,10,SMOOTH_BRICK,100)
RandomBlock(-3,-1,-7,STONEBRICK:1,10,STONEBRICK:2,10,COBBLESTONE,10,MOSSY_COBBLESTONE,10,SMOOTH_BRICK,100)
RandomBlock(-2,-1,-7,STONEBRICK:1,10,STONEBRICK:2,10,COBBLESTONE,10,MOSSY_COBBLESTONE,10,SMOOTH_BRICK,100)
RandomBlock(-7,-1,-6,STONEBRICK:1,10,STONEBRICK:2,10,COBBLESTONE,10,MOSSY_COBBLESTONE,10,SMOOTH_BRICK,100)
RandomBlock(-6,-1,-6,STONEBRICK:1,10,STONEBRICK:2,10,COBBLESTONE,10,MOSSY_COBBLESTONE,10,SMOOTH_BRICK,100)
RandomBlock(-5,-1,-6,STONEBRICK:1,10,STONEBRICK:2,10,COBBLESTONE,10,MOSSY_COBBLESTONE,10,SMOOTH_BRICK,100)
RandomBlock(-4,-1,-6,STONEBRICK:1,10,STONEBRICK:2,10,COBBLESTONE,10,MOSSY_COBBLESTONE,10,SMOOTH_BRICK,100)
RandomBlock(-3,-1,-6,STONEBRICK:1,10,STONEBRICK:2,10,COBBLESTONE,10,MOSSY_COBBLESTONE,10,SMOOTH_BRICK,100)
RandomBlock(-2,-1,-6,STONEBRICK:1,10,STONEBRICK:2,10,COBBLESTONE,10,MOSSY_COBBLESTONE,10,SMOOTH_BRICK,100)
RandomBlock(-7,-1,-5,STONEBRICK:1,10,STONEBRICK:2,10,COBBLESTONE,10,MOSSY_COBBLESTONE,10,SMOOTH_BRICK,100)
RandomBlock(-6,-1,-5,STONEBRICK:1,10,STONEBRICK:2,10,COBBLESTONE,10,MOSSY_COBBLESTONE,10,SMOOTH_BRICK,100)
RandomBlock(-5,-1,-5,STONEBRICK:1,10,STONEBRICK:2,10,COBBLESTONE,10,MOSSY_COBBLESTONE,10,SMOOTH_BRICK,100)
RandomBlock(-4,-1,-5,STONEBRICK:1,10,STONEBRICK:2,10,COBBLESTONE,10,MOSSY_COBBLESTONE,10,SMOOTH_BRICK,100)
RandomBlock(-3,-1,-5,STONEBRICK:1,10,STONEBRICK:2,10,COBBLESTONE,10,MOSSY_COBBLESTONE,10,SMOOTH_BRICK,100)
Block(-2,-1,-5,LEAVES:7)
RandomBlock(-7,-1,-4,STONEBRICK:1,10,STONEBRICK:2,10,COBBLESTONE,10,MOSSY_COBBLESTONE,10,SMOOTH_BRICK,100)
RandomBlock(-6,-1,-4,STONEBRICK:1,10,STONEBRICK:2,10,COBBLESTONE,10,MOSSY_COBBLESTONE,10,SMOOTH_BRICK,100)
RandomBlock(-5,-1,-4,STONEBRICK:1,10,STONEBRICK:2,10,COBBLESTONE,10,MOSSY_COBBLESTONE,10,SMOOTH_BRICK,100)
RandomBlock(-4,-1,-4,STONEBRICK:1,10,STONEBRICK:2,10,COBBLESTONE,10,MOSSY_COBBLESTONE,10,SMOOTH_BRICK,100)
RandomBlock(-3,-1,-4,STONEBRICK:1,10,STONEBRICK:2,10,COBBLESTONE,10,MOSSY_COBBLESTONE,10,SMOOTH_BRICK,100)
Block(-2,-1,-4,LEAVES:7)
RandomBlock(-7,-1,-3,STONEBRICK:1,10,STONEBRICK:2,10,COBBLESTONE,10,MOSSY_COBBLESTONE,10,SMOOTH_BRICK,100)
RandomBlock(-6,-1,-3,STONEBRICK:1,10,STONEBRICK:2,10,COBBLESTONE,10,MOSSY_COBBLESTONE,10,SMOOTH_BRICK,100)
RandomBlock(-5,-1,-3,STONEBRICK:1,10,STONEBRICK:2,10,COBBLESTONE,10,MOSSY_COBBLESTONE,10,SMOOTH_BRICK,100)
RandomBlock(-4,-1,-3,STONEBRICK:1,10,STONEBRICK:2,10,COBBLESTONE,10,MOSSY_COBBLESTONE,10,SMOOTH_BRICK,100)
RandomBlock(-3,-1,-3,STONEBRICK:1,10,STONEBRICK:2,10,COBBLESTONE,10,MOSSY_COBBLESTONE,10,SMOOTH_BRICK,100)
Block(-2,-1,-3,LEAVES:7)
RandomBlock(-7,-1,-2,STONEBRICK:1,10,STONEBRICK:2,10,COBBLESTONE,10,MOSSY_COBBLESTONE,10,SMOOTH_BRICK,100)
Block(-6,-1,-2,LEAVES:7)
Block(-5,-1,-2,LEAVES:7)
Block(-4,-1,-2,LEAVES:7)
RandomBlock(-3,-1,-2,STONEBRICK:1,10,STONEBRICK:2,10,COBBLESTONE,10,MOSSY_COBBLESTONE,10,SMOOTH_BRICK,100)
RandomBlock(-2,-1,-2,STONEBRICK:1,10,STONEBRICK:2,10,COBBLESTONE,10,MOSSY_COBBLESTONE,10,SMOOTH_BRICK,100)
RandomBlock(-7,0,-7,STONEBRICK:1,10,STONEBRICK:2,10,COBBLESTONE,10,MOSSY_COBBLESTONE,10,SMOOTH_BRICK,100)
RandomBlock(-6,0,-7,STONEBRICK:1,10,STONEBRICK:2,10,COBBLESTONE,10,MOSSY_COBBLESTONE,10,SMOOTH_BRICK,100)
RandomBlock(-5,0,-7,STONEBRICK:1,10,STONEBRICK:2,10,COBBLESTONE,10,MOSSY_COBBLESTONE,10,SMOOTH_BRICK,100)
RandomBlock(-4,0,-7,STONEBRICK:1,10,STONEBRICK:2,10,COBBLESTONE,10,MOSSY_COBBLESTONE,10,SMOOTH_BRICK,100)
RandomBlock(-3,0,-7,STONEBRICK:1,10,STONEBRICK:2,10,COBBLESTONE,10,MOSSY_COBBLESTONE,10,SMOOTH_BRICK,100)
Block(-2,0,-7,STONE_SLAB:0)
RandomBlock(-7,0,-6,STONEBRICK:1,10,STONEBRICK:2,10,COBBLESTONE,10,MOSSY_COBBLESTONE,10,SMOOTH_BRICK,100)
RandomBlock(-6,0,-6,STONEBRICK:1,10,STONEBRICK:2,10,COBBLESTONE,10,MOSSY_COBBLESTONE,10,SMOOTH_BRICK,100)
RandomBlock(-5,0,-6,STONEBRICK:1,10,STONEBRICK:2,10,COBBLESTONE,10,MOSSY_COBBLESTONE,10,SMOOTH_BRICK,100)
RandomBlock(-4,0,-6,STONEBRICK:1,10,STONEBRICK:2,10,COBBLESTONE,10,MOSSY_COBBLESTONE,10,SMOOTH_BRICK,100)
RandomBlock(-3,0,-6,STONEBRICK:1,10,STONEBRICK:2,10,COBBLESTONE,10,MOSSY_COBBLESTONE,10,SMOOTH_BRICK,100)
Block(-2,0,-6,STONE_SLAB:0)
RandomBlock(-7,0,-5,STONEBRICK:1,10,STONEBRICK:2,10,COBBLESTONE,10,MOSSY_COBBLESTONE,10,SMOOTH_BRICK,100)
RandomBlock(-6,0,-5,STONEBRICK:1,10,STONEBRICK:2,10,COBBLESTONE,10,MOSSY_COBBLESTONE,10,SMOOTH_BRICK,100)
RandomBlock(-5,0,-5,STONEBRICK:1,10,STONEBRICK:2,10,COBBLESTONE,10,MOSSY_COBBLESTONE,10,SMOOTH_BRICK,100)
RandomBlock(-4,0,-5,STONEBRICK:1,10,STONEBRICK:2,10,COBBLESTONE,10,MOSSY_COBBLESTONE,10,SMOOTH_BRICK,100)
RandomBlock(-3,0,-5,STONEBRICK:1,10,STONEBRICK:2,10,COBBLESTONE,10,MOSSY_COBBLESTONE,10,SMOOTH_BRICK,100)
Block(-2,0,-5,LEAVES:7)
RandomBlock(-7,0,-4,STONEBRICK:1,10,STONEBRICK:2,10,COBBLESTONE,10,MOSSY_COBBLESTONE,10,SMOOTH_BRICK,100)
RandomBlock(-6,0,-4,STONEBRICK:1,10,STONEBRICK:2,10,COBBLESTONE,10,MOSSY_COBBLESTONE,10,SMOOTH_BRICK,100)
RandomBlock(-5,0,-4,STONEBRICK:1,10,STONEBRICK:2,10,COBBLESTONE,10,MOSSY_COBBLESTONE,10,SMOOTH_BRICK,100)
RandomBlock(-4,0,-4,STONEBRICK:1,10,STONEBRICK:2,10,COBBLESTONE,10,MOSSY_COBBLESTONE,10,SMOOTH_BRICK,100)
RandomBlock(-3,0,-4,STONEBRICK:1,10,STONEBRICK:2,10,COBBLESTONE,10,MOSSY_COBBLESTONE,10,SMOOTH_BRICK,100)
Block(-2,0,-4,LEAVES:7)
RandomBlock(-7,0,-3,STONEBRICK:1,10,STONEBRICK:2,10,COBBLESTONE,10,MOSSY_COBBLESTONE,10,SMOOTH_BRICK,100)
RandomBlock(-6,0,-3,STONEBRICK:1,10,STONEBRICK:2,10,COBBLESTONE,10,MOSSY_COBBLESTONE,10,SMOOTH_BRICK,100)
RandomBlock(-5,0,-3,STONEBRICK:1,10,STONEBRICK:2,10,COBBLESTONE,10,MOSSY_COBBLESTONE,10,SMOOTH_BRICK,100)
RandomBlock(-4,0,-3,STONEBRICK:1,10,STONEBRICK:2,10,COBBLESTONE,10,MOSSY_COBBLESTONE,10,SMOOTH_BRICK,100)
RandomBlock(-3,0,-3,STONEBRICK:1,10,STONEBRICK:2,10,COBBLESTONE,10,MOSSY_COBBLESTONE,10,SMOOTH_BRICK,100)
Block(-2,0,-3,LEAVES:7)
Block(-7,0,-2,STONE_SLAB:0)
Block(-6,0,-2,LEAVES:7)
Block(-5,0,-2,LEAVES:7)
Block(-4,0,-2,LEAVES:7)
Block(-3,0,-2,STONE_SLAB:0)
Block(-2,0,-2,STONE_SLAB:0)
RandomBlock(-7,1,-7,STONEBRICK:1,10,STONEBRICK:2,10,COBBLESTONE,10,MOSSY_COBBLESTONE,10,SMOOTH_BRICK,100)
RandomBlock(-6,1,-7,STONEBRICK:1,10,STONEBRICK:2,10,COBBLESTONE,10,MOSSY_COBBLESTONE,10,SMOOTH_BRICK,100)
RandomBlock(-5,1,-7,STONEBRICK:1,10,STONEBRICK:2,10,COBBLESTONE,10,MOSSY_COBBLESTONE,10,SMOOTH_BRICK,100)
RandomBlock(-4,1,-7,STONEBRICK:1,10,STONEBRICK:2,10,COBBLESTONE,10,MOSSY_COBBLESTONE,10,SMOOTH_BRICK,100)
Block(-3,1,-7,STONE_SLAB:0)
RandomBlock(-7,1,-6,STONEBRICK:1,10,STONEBRICK:2,10,COBBLESTONE,10,MOSSY_COBBLESTONE,10,SMOOTH_BRICK,100)
RandomBlock(-6,1,-6,STONEBRICK:1,10,STONEBRICK:2,10,COBBLESTONE,10,MOSSY_COBBLESTONE,10,SMOOTH_BRICK,100)
RandomBlock(-5,1,-6,STONEBRICK:1,10,STONEBRICK:2,10,COBBLESTONE,10,MOSSY_COBBLESTONE,10,SMOOTH_BRICK,100)
RandomBlock(-4,1,-6,STONEBRICK:1,10,STONEBRICK:2,10,COBBLESTONE,10,MOSSY_COBBLESTONE,10,SMOOTH_BRICK,100)
Block(-3,1,-6,STONE_SLAB:0)
RandomBlock(-7,1,-5,STONEBRICK:1,10,STONEBRICK:2,10,COBBLESTONE,10,MOSSY_COBBLESTONE,10,SMOOTH_BRICK,100)
RandomBlock(-6,1,-5,STONEBRICK:1,10,STONEBRICK:2,10,COBBLESTONE,10,MOSSY_COBBLESTONE,10,SMOOTH_BRICK,100)
RandomBlock(-5,1,-5,STONEBRICK:1,10,STONEBRICK:2,10,COBBLESTONE,10,MOSSY_COBBLESTONE,10,SMOOTH_BRICK,100)
RandomBlock(-4,1,-5,STONEBRICK:1,10,STONEBRICK:2,10,COBBLESTONE,10,MOSSY_COBBLESTONE,10,SMOOTH_BRICK,100)
Block(-3,1,-5,LEAVES:7)
Block(-2,1,-5,VINE:2)
RandomBlock(-7,1,-4,STONEBRICK:1,10,STONEBRICK:2,10,COBBLESTONE,10,MOSSY_COBBLESTONE,10,SMOOTH_BRICK,100)
RandomBlock(-6,1,-4,STONEBRICK:1,10,STONEBRICK:2,10,COBBLESTONE,10,MOSSY_COBBLESTONE,10,SMOOTH_BRICK,100)
RandomBlock(-5,1,-4,STONEBRICK:1,10,STONEBRICK:2,10,COBBLESTONE,10,MOSSY_COBBLESTONE,10,SMOOTH_BRICK,100)
RandomBlock(-4,1,-4,STONEBRICK:1,10,STONEBRICK:2,10,COBBLESTONE,10,MOSSY_COBBLESTONE,10,SMOOTH_BRICK,100)
Block(-3,1,-4,LEAVES:7)
Block(-2,1,-4,VINE:2)
Block(-7,1,-3,STONE_SLAB:0)
Block(-6,1,-3,LEAVES:7)
Block(-5,1,-3,STONE_SLAB:0)
Block(-4,1,-3,STONE_SLAB:0)
Block(-3,1,-3,STONE_SLAB:0)
RandomBlock(-7,2,-7,STONEBRICK:1,10,STONEBRICK:2,10,COBBLESTONE,10,MOSSY_COBBLESTONE,10,SMOOTH_BRICK,100)
RandomBlock(-4,2,-7,STONEBRICK:1,10,STONEBRICK:2,10,COBBLESTONE,10,MOSSY_COBBLESTONE,10,SMOOTH_BRICK,100)
Block(-3,2,-7,VINE:2)
Block(-7,2,-6,LEAVES:7)
Block(-5,2,-6,LEAVES:7)
Block(-5,2,-5,LEAVES:7)
Block(-4,2,-5,LEAVES:7)
RandomBlock(-7,2,-4,STONEBRICK:1,10,STONEBRICK:2,10,COBBLESTONE,10,MOSSY_COBBLESTONE,10,SMOOTH_BRICK,100)
Block(-5,2,-4,LEAVES:7)
RandomBlock(-4,2,-4,STONEBRICK:1,10,STONEBRICK:2,10,COBBLESTONE,10,MOSSY_COBBLESTONE,10,SMOOTH_BRICK,100)
Block(-3,2,-4,VINE:2)
Block(-7,2,-3,VINE:4)
Block(-4,2,-3,VINE:4)
RandomBlock(-7,3,-7,STONEBRICK:1,10,STONEBRICK:2,10,COBBLESTONE,10,MOSSY_COBBLESTONE,10,SMOOTH_BRICK,100)
RandomBlock(-4,3,-7,STONEBRICK:1,10,STONEBRICK:2,10,COBBLESTONE,10,MOSSY_COBBLESTONE,10,SMOOTH_BRICK,100)
Block(-3,3,-7,VINE:2)
Block(-4,3,-6,STONE_BRICK_STAIRS:7)
Block(-4,3,-5,STONE_BRICK_STAIRS:6)
RandomBlock(-7,3,-4,STONEBRICK:1,10,STONEBRICK:2,10,COBBLESTONE,10,MOSSY_COBBLESTONE,10,SMOOTH_BRICK,100)
Block(-6,3,-4,STONE_BRICK_STAIRS:5)
Block(-5,3,-4,STONE_BRICK_STAIRS:4)
RandomBlock(-4,3,-4,STONEBRICK:1,10,STONEBRICK:2,10,COBBLESTONE,10,MOSSY_COBBLESTONE,10,SMOOTH_BRICK,100)
Block(-3,3,-4,VINE:2)
Block(-7,3,-3,VINE:4)
Block(-4,3,-3,VINE:4)
Block(-7,4,-7,STONE_SLAB:5)
Block(-6,4,-7,STONE_SLAB:5)
Block(-5,4,-7,STONE_SLAB:5)
Block(-4,4,-7,STONE_SLAB:5)
Block(-7,4,-6,STONE_SLAB:5)
Block(-4,4,-6,STONE_SLAB:0)
Block(-7,4,-5,STONE_SLAB:5)
Block(-4,4,-5,STONE_SLAB:0)
Block(-7,4,-4,STONE_SLAB:5)
Block(-6,4,-4,STONE_SLAB:0)
Block(-5,4,-4,STONE_SLAB:0)
Block(-4,4,-4,STONE_SLAB:5)
