
#######################################################################
# +-----------------------------------------------------------------+ #
# |                            BO3 object                           | #
# +-----------------------------------------------------------------+ #
#######################################################################

Author: NLBlackEagle

Description: No description given

Version: 3

SettingsMode: WriteDisable


#######################################################################
# +-----------------------------------------------------------------+ #
# |                          Main settings                          | #
# +-----------------------------------------------------------------+ #
#######################################################################

Tree: false

Frequency: 100

Rarity: 100.0

RotateRandomly: false

SpawnHeight: randomY

SpawnHeightOffset: 0

SpawnHeightVariance: 0

##############################
# Height Limits for the BO3. #
##############################

MinHeight: 18

MaxHeight: 18

######################
# Extrusion settings #
######################

ExtrudeMode: None

ExtrudeThroughBlocks: minecraft:air

MaxBranchDepth: 10

ExcludedBiomes: All


#######################################################################
# +-----------------------------------------------------------------+ #
# |                      Source block settings                      | #
# +-----------------------------------------------------------------+ #
#######################################################################

SourceBlocks: minecraft:air

MaxPercentageOutsideSourceBlock: 100

OutsideSourceBlock: placeAnyway


#######################################################################
# +-----------------------------------------------------------------+ #
# |                              Blocks                             | #
# +-----------------------------------------------------------------+ #
#######################################################################

Block(-6,24,3,minecraft:dispenser:5,StrongHoldDispenser/arrownbt/Trap.nbt)
Block(-6,24,4,minecraft:dispenser:5,StrongHoldDispenser/arrownbt/Trap.nbt)
Block(-6,24,5,minecraft:dispenser:5,StrongHoldDispenser/arrownbt/Trap.nbt)
Block(-6,24,6,minecraft:dispenser:5,StrongHoldDispenser/arrownbt/Trap.nbt)
Block(-3,24,3,minecraft:dispenser:12,StrongHoldDispenser/arrownbt/Trap.nbt)
Block(-3,24,4,minecraft:dispenser:12,StrongHoldDispenser/arrownbt/Trap.nbt)
Block(-3,24,5,minecraft:dispenser:12,StrongHoldDispenser/arrownbt/Trap.nbt)
Block(-3,24,6,minecraft:dispenser:4,StrongHoldDispenser/arrownbt/Trap.nbt)
Block(2,24,-5,minecraft:dispenser:3,StrongHoldDispenser/arrownbt/Trap.nbt)
Block(2,24,-2,minecraft:dispenser:10,StrongHoldDispenser/arrownbt/Trap.nbt)
Block(3,24,-5,minecraft:dispenser:3,StrongHoldDispenser/arrownbt/Trap.nbt)
Block(3,24,-2,minecraft:dispenser:10,StrongHoldDispenser/arrownbt/Trap.nbt)
Block(4,24,-5,minecraft:dispenser:3,StrongHoldDispenser/arrownbt/Trap.nbt)
Block(4,24,-2,minecraft:dispenser:10,StrongHoldDispenser/arrownbt/Trap.nbt)
Block(5,24,-5,minecraft:dispenser:3,StrongHoldDispenser/arrownbt/Trap.nbt)
Block(5,24,-2,minecraft:dispenser,StrongHoldDispenser/arrownbt/Trap.nbt)
Block(-7,3,-4,minecraft:skull:1,StrongHoldSkull/we-Stronghold01/1-Skull.nbt)
Block(-7,3,4,minecraft:skull:1,StrongHoldSkull/we-Stronghold01/2-Skull.nbt)
Block(-7,5,-4,minecraft:skull:1,StrongHoldSkull/we-Stronghold01/3-Skull.nbt)
Block(-7,5,0,minecraft:skull:1,StrongHoldSkull/we-Stronghold01/4-Skull.nbt)
Block(-7,5,4,minecraft:skull:1,StrongHoldSkull/we-Stronghold01/5-Skull.nbt)
Block(-7,5,8,minecraft:skull:1,StrongHoldSkull/we-Stronghold01/6-Skull.nbt)
Block(-7,6,-5,minecraft:skull:1,StrongHoldSkull/we-Stronghold01/7-Skull.nbt)
Block(-7,6,-3,minecraft:skull:1,StrongHoldSkull/we-Stronghold01/8-Skull.nbt)
Block(-7,6,-1,minecraft:skull:1,StrongHoldSkull/we-Stronghold01/9-Skull.nbt)
Block(-7,6,1,minecraft:skull:1,StrongHoldSkull/we-Stronghold01/10-Skull.nbt)
Block(-7,6,3,minecraft:skull:1,StrongHoldSkull/we-Stronghold01/11-Skull.nbt)
Block(-7,6,5,minecraft:skull:1,StrongHoldSkull/we-Stronghold01/12-Skull.nbt)
Block(-7,6,7,minecraft:skull:1,StrongHoldSkull/we-Stronghold01/13-Skull.nbt)
Block(-7,9,8,minecraft:skull:1,StrongHoldSkull/we-Stronghold01/14-Skull.nbt)
Block(-7,13,-5,minecraft:skull:1,StrongHoldSkull/we-Stronghold01/19-Skull.nbt)
Block(-7,14,-3,minecraft:skull:1,StrongHoldSkull/we-Stronghold01/20-Skull.nbt)
Block(-7,15,-5,minecraft:skull:1,StrongHoldSkull/we-Stronghold01/21-Skull.nbt)
Block(-7,15,5,minecraft:skull:1,StrongHoldSkull/we-Stronghold01/22-Skull.nbt)
Block(-7,15,7,minecraft:skull:1,StrongHoldSkull/we-Stronghold01/23-Skull.nbt)
Block(-7,15,8,minecraft:skull:1,StrongHoldSkull/we-Stronghold01/24-Skull.nbt)
Block(-7,16,1,minecraft:skull:1,StrongHoldSkull/we-Stronghold01/25-Skull.nbt)
Block(-7,16,4,minecraft:skull:1,StrongHoldSkull/we-Stronghold01/27-Skull.nbt)
Block(-7,17,-1,minecraft:skull:1,StrongHoldSkull/we-Stronghold01/29-Skull.nbt)
Block(-7,17,5,minecraft:skull:1,StrongHoldSkull/we-Stronghold01/31-Skull.nbt)
Block(-7,17,7,minecraft:skull:1,StrongHoldSkull/we-Stronghold01/32-Skull.nbt)
Block(-7,17,8,minecraft:skull:1,StrongHoldSkull/we-Stronghold01/33-Skull.nbt)
Block(-7,18,-6,minecraft:skull:1,StrongHoldSkull/we-Stronghold01/34-Skull.nbt)
Block(-7,18,-3,minecraft:skull:1,StrongHoldSkull/we-Stronghold01/35-Skull.nbt)
Block(-7,18,4,minecraft:skull:1,StrongHoldSkull/we-Stronghold01/36-Skull.nbt)
Block(-7,19,-5,minecraft:skull:1,StrongHoldSkull/we-Stronghold01/37-Skull.nbt)
Block(-7,19,-1,minecraft:skull:1,StrongHoldSkull/we-Stronghold01/38-Skull.nbt)
Block(-7,19,0,minecraft:skull:1,StrongHoldSkull/we-Stronghold01/39-Skull.nbt)
Block(-7,19,3,minecraft:skull:1,StrongHoldSkull/we-Stronghold01/40-Skull.nbt)
Block(-7,19,5,minecraft:skull:1,StrongHoldSkull/we-Stronghold01/41-Skull.nbt)
Block(-7,19,8,minecraft:skull:1,StrongHoldSkull/we-Stronghold01/42-Skull.nbt)
Block(-6,3,-5,minecraft:skull:1,StrongHoldSkull/we-Stronghold01/43-Skull.nbt)
Block(-6,3,-3,minecraft:skull:1,StrongHoldSkull/we-Stronghold01/44-Skull.nbt)
Block(-6,3,-1,minecraft:skull:1,StrongHoldSkull/we-Stronghold01/45-Skull.nbt)
Block(-6,3,1,minecraft:skull:1,StrongHoldSkull/we-Stronghold01/46-Skull.nbt)
Block(-6,3,3,minecraft:skull:1,StrongHoldSkull/we-Stronghold01/47-Skull.nbt)
Block(-6,3,5,minecraft:skull:1,StrongHoldSkull/we-Stronghold01/48-Skull.nbt)
Block(-6,3,7,minecraft:skull:1,StrongHoldSkull/we-Stronghold01/49-Skull.nbt)
Block(-6,4,-2,minecraft:skull:1,StrongHoldSkull/we-Stronghold01/50-Skull.nbt)
Block(-6,4,2,minecraft:skull:1,StrongHoldSkull/we-Stronghold01/51-Skull.nbt)
Block(-6,4,6,minecraft:skull:1,StrongHoldSkull/we-Stronghold01/52-Skull.nbt)
Block(-6,5,-5,minecraft:skull:1,StrongHoldSkull/we-Stronghold01/53-Skull.nbt)
Block(-6,6,-6,minecraft:skull:1,StrongHoldSkull/we-Stronghold01/54-Skull.nbt)
Block(-6,11,8,minecraft:skull:1,StrongHoldSkull/we-Stronghold01/55-Skull.nbt)
Block(-6,14,-6,minecraft:skull:1,StrongHoldSkull/we-Stronghold01/56-Skull.nbt)
Block(-6,15,8,minecraft:skull:1,StrongHoldSkull/we-Stronghold01/57-Skull.nbt)
Block(-6,17,-6,minecraft:skull:1,StrongHoldSkull/we-Stronghold01/58-Skull.nbt)
Block(-6,17,-4,minecraft:skull:1,StrongHoldSkull/we-Stronghold01/59-Skull.nbt)
Block(-6,18,-3,minecraft:skull:1,StrongHoldSkull/we-Stronghold01/60-Skull.nbt)
Block(-5,3,-6,minecraft:skull:1,StrongHoldSkull/we-Stronghold01/65-Skull.nbt)
Block(-5,5,-6,minecraft:skull:1,StrongHoldSkull/we-Stronghold01/66-Skull.nbt)
Block(-5,12,0,minecraft:skull:1,StrongHoldSkull/we-Stronghold01/70-Skull.nbt)
Block(-5,15,-6,minecraft:skull:1,StrongHoldSkull/we-Stronghold01/71-Skull.nbt)
Block(-5,17,-5,minecraft:skull:1,StrongHoldSkull/we-Stronghold01/73-Skull.nbt)
Block(-5,19,-6,minecraft:skull:1,StrongHoldSkull/we-Stronghold01/74-Skull.nbt)
Block(-4,3,-5,minecraft:skull:1,StrongHoldSkull/we-Stronghold01/76-Skull.nbt)
Block(-4,6,-6,minecraft:skull:1,StrongHoldSkull/we-Stronghold01/77-Skull.nbt)
Block(-4,12,-5,minecraft:skull:1,StrongHoldSkull/we-Stronghold01/80-Skull.nbt)
Block(-4,13,-6,minecraft:skull:1,StrongHoldSkull/we-Stronghold01/82-Skull.nbt)
Block(-4,14,8,minecraft:skull:1,StrongHoldSkull/we-Stronghold01/83-Skull.nbt)
Block(-4,15,-6,minecraft:skull:1,StrongHoldSkull/we-Stronghold01/84-Skull.nbt)
Block(-4,18,-5,minecraft:skull:1,StrongHoldSkull/we-Stronghold01/86-Skull.nbt)
Block(-4,19,-6,minecraft:skull:1,StrongHoldSkull/we-Stronghold01/87-Skull.nbt)
Block(-3,2,0,minecraft:skull:1,StrongHoldSkull/we-Stronghold01/88-Skull.nbt)
Block(-3,4,-5,minecraft:skull:1,StrongHoldSkull/we-Stronghold01/89-Skull.nbt)
Block(-2,3,-5,minecraft:skull:1,StrongHoldSkull/we-Stronghold01/96-Skull.nbt)
Block(-2,3,-1,minecraft:skull:1,StrongHoldSkull/we-Stronghold01/97-Skull.nbt)
Block(-2,3,1,minecraft:skull:1,StrongHoldSkull/we-Stronghold01/98-Skull.nbt)
Block(-2,6,-6,minecraft:skull:1,StrongHoldSkull/we-Stronghold01/99-Skull.nbt)
Block(-2,11,0,minecraft:skull:1,StrongHoldSkull/we-Stronghold01/101-Skull.nbt)
Block(-2,13,-6,minecraft:skull:1,StrongHoldSkull/we-Stronghold01/103-Skull.nbt)
Block(-2,14,8,minecraft:skull:1,StrongHoldSkull/we-Stronghold01/104-Skull.nbt)
Block(-2,17,-6,minecraft:skull:1,StrongHoldSkull/we-Stronghold01/105-Skull.nbt)
Block(-2,17,2,minecraft:skull:1,StrongHoldSkull/we-Stronghold01/106-Skull.nbt)
Block(-2,18,4,minecraft:skull:1,StrongHoldSkull/we-Stronghold01/107-Skull.nbt)
Block(-2,19,-6,minecraft:skull:1,StrongHoldSkull/we-Stronghold01/108-Skull.nbt)
Block(-1,2,-2,minecraft:skull:1,StrongHoldSkull/we-Stronghold01/109-Skull.nbt)
Block(-1,2,2,minecraft:skull:1,StrongHoldSkull/we-Stronghold01/110-Skull.nbt)
Block(-1,5,-6,minecraft:skull:1,StrongHoldSkull/we-Stronghold01/112-Skull.nbt)
Block(-1,14,8,minecraft:skull:1,StrongHoldSkull/we-Stronghold01/114-Skull.nbt)
Block(-1,16,6,minecraft:skull:1,StrongHoldSkull/we-Stronghold01/115-Skull.nbt)
Block(-1,17,3,minecraft:skull:1,StrongHoldSkull/we-Stronghold01/116-Skull.nbt)
Block(-1,19,-6,minecraft:skull:1,StrongHoldSkull/we-Stronghold01/117-Skull.nbt)
Block(-1,19,1,minecraft:skull:1,StrongHoldSkull/we-Stronghold01/118-Skull.nbt)
Block(-1,20,2,minecraft:skull:1,StrongHoldSkull/we-Stronghold01/119-Skull.nbt)
Block(0,3,-5,minecraft:skull:1,StrongHoldSkull/we-Stronghold01/120-Skull.nbt)
Block(0,3,-1,minecraft:skull:1,StrongHoldSkull/we-Stronghold01/121-Skull.nbt)
Block(0,3,1,minecraft:skull:1,StrongHoldSkull/we-Stronghold01/122-Skull.nbt)
Block(0,6,-6,minecraft:skull:1,StrongHoldSkull/we-Stronghold01/123-Skull.nbt)
Block(0,12,3,minecraft:skull:1,StrongHoldSkull/we-Stronghold01/125-Skull.nbt)
Block(0,14,8,minecraft:skull:1,StrongHoldSkull/we-Stronghold01/126-Skull.nbt)
Block(0,15,6,minecraft:skull:1,StrongHoldSkull/we-Stronghold01/127-Skull.nbt)
Block(0,15,7,minecraft:skull:1,StrongHoldSkull/we-Stronghold01/128-Skull.nbt)
Block(0,16,-6,minecraft:skull:1,StrongHoldSkull/we-Stronghold01/129-Skull.nbt)
Block(0,17,3,minecraft:skull:1,StrongHoldSkull/we-Stronghold01/130-Skull.nbt)
Block(0,18,-6,minecraft:skull:1,StrongHoldSkull/we-Stronghold01/131-Skull.nbt)
Block(0,18,2,minecraft:skull:1,StrongHoldSkull/we-Stronghold01/132-Skull.nbt)
Block(0,18,5,minecraft:skull:1,StrongHoldSkull/we-Stronghold01/133-Skull.nbt)
Block(0,19,1,minecraft:skull:1,StrongHoldSkull/we-Stronghold01/134-Skull.nbt)
Block(1,2,0,minecraft:skull:1,StrongHoldSkull/we-Stronghold01/135-Skull.nbt)
Block(1,4,-5,minecraft:skull:1,StrongHoldSkull/we-Stronghold01/136-Skull.nbt)
Block(1,14,7,minecraft:skull:1,StrongHoldSkull/we-Stronghold01/137-Skull.nbt)
Block(1,15,6,minecraft:skull:1,StrongHoldSkull/we-Stronghold01/138-Skull.nbt)
Block(1,15,8,minecraft:skull:1,StrongHoldSkull/we-Stronghold01/139-Skull.nbt)
Block(1,16,-5,minecraft:skull:1,StrongHoldSkull/we-Stronghold01/140-Skull.nbt)
Block(1,16,-3,minecraft:skull:1,StrongHoldSkull/we-Stronghold01/141-Skull.nbt)
Block(1,16,3,minecraft:skull:1,StrongHoldSkull/we-Stronghold01/142-Skull.nbt)
Block(1,17,0,minecraft:skull:1,StrongHoldSkull/we-Stronghold01/143-Skull.nbt)
Block(1,17,2,minecraft:skull:1,StrongHoldSkull/we-Stronghold01/144-Skull.nbt)
Block(1,17,5,minecraft:skull:1,StrongHoldSkull/we-Stronghold01/145-Skull.nbt)
Block(1,18,-1,minecraft:skull:1,StrongHoldSkull/we-Stronghold01/146-Skull.nbt)
Block(2,3,-5,minecraft:skull:1,StrongHoldSkull/we-Stronghold01/147-Skull.nbt)
Block(2,6,-6,minecraft:skull:1,StrongHoldSkull/we-Stronghold01/148-Skull.nbt)
Block(2,12,1,minecraft:skull:1,StrongHoldSkull/we-Stronghold01/149-Skull.nbt)
Block(2,16,-6,minecraft:skull:1,StrongHoldSkull/we-Stronghold01/150-Skull.nbt)
Block(2,16,-2,minecraft:skull:1,StrongHoldSkull/we-Stronghold01/151-Skull.nbt)
Block(2,16,1,minecraft:skull:1,StrongHoldSkull/we-Stronghold01/152-Skull.nbt)
Block(2,17,-1,minecraft:skull:1,StrongHoldSkull/we-Stronghold01/153-Skull.nbt)
Block(2,18,-6,minecraft:skull:1,StrongHoldSkull/we-Stronghold01/154-Skull.nbt)
Block(2,18,0,minecraft:skull:1,StrongHoldSkull/we-Stronghold01/155-Skull.nbt)
Block(3,3,-6,minecraft:skull:1,StrongHoldSkull/we-Stronghold01/158-Skull.nbt)
Block(3,5,-6,minecraft:skull:1,StrongHoldSkull/we-Stronghold01/159-Skull.nbt)
Block(3,16,-6,minecraft:skull:1,StrongHoldSkull/we-Stronghold01/160-Skull.nbt)
Block(3,17,5,minecraft:skull:1,StrongHoldSkull/we-Stronghold01/161-Skull.nbt)
Block(4,3,-5,minecraft:skull:1,StrongHoldSkull/we-Stronghold01/166-Skull.nbt)
Block(4,3,5,minecraft:skull:1,StrongHoldSkull/we-Stronghold01/167-Skull.nbt)
Block(4,3,7,minecraft:skull:1,StrongHoldSkull/we-Stronghold01/168-Skull.nbt)
Block(4,5,5,minecraft:skull:1,StrongHoldSkull/we-Stronghold01/169-Skull.nbt)
Block(4,5,7,minecraft:skull:1,StrongHoldSkull/we-Stronghold01/170-Skull.nbt)
Block(4,6,-6,minecraft:skull:1,StrongHoldSkull/we-Stronghold01/171-Skull.nbt)
Block(4,7,5,minecraft:skull:1,StrongHoldSkull/we-Stronghold01/172-Skull.nbt)
Block(4,7,7,minecraft:skull:1,StrongHoldSkull/we-Stronghold01/173-Skull.nbt)
Block(4,9,5,minecraft:skull:1,StrongHoldSkull/we-Stronghold01/174-Skull.nbt)
Block(4,9,7,minecraft:skull:1,StrongHoldSkull/we-Stronghold01/175-Skull.nbt)
Block(4,13,7,minecraft:skull:1,StrongHoldSkull/we-Stronghold01/176-Skull.nbt)
Block(4,15,-6,minecraft:skull:1,StrongHoldSkull/we-Stronghold01/177-Skull.nbt)
Block(4,16,-5,minecraft:skull:1,StrongHoldSkull/we-Stronghold01/178-Skull.nbt)
Block(4,16,-3,minecraft:skull:1,StrongHoldSkull/we-Stronghold01/179-Skull.nbt)
Block(4,16,-2,minecraft:skull:1,StrongHoldSkull/we-Stronghold01/180-Skull.nbt)
Block(4,17,-6,minecraft:skull:1,StrongHoldSkull/we-Stronghold01/181-Skull.nbt)
Block(4,17,0,minecraft:skull:1,StrongHoldSkull/we-Stronghold01/182-Skull.nbt)
Block(4,17,2,minecraft:skull:1,StrongHoldSkull/we-Stronghold01/183-Skull.nbt)
Block(4,17,4,minecraft:skull:1,StrongHoldSkull/we-Stronghold01/184-Skull.nbt)
Block(4,19,-6,minecraft:skull:1,StrongHoldSkull/we-Stronghold01/185-Skull.nbt)
Block(4,19,1,minecraft:skull:1,StrongHoldSkull/we-Stronghold01/186-Skull.nbt)
Block(5,4,-5,minecraft:skull:1,StrongHoldSkull/we-Stronghold01/189-Skull.nbt)
Block(5,14,2,minecraft:skull:1,StrongHoldSkull/we-Stronghold01/190-Skull.nbt)
Block(5,14,4,minecraft:skull:1,StrongHoldSkull/we-Stronghold01/191-Skull.nbt)
Block(5,16,1,minecraft:skull:1,StrongHoldSkull/we-Stronghold01/192-Skull.nbt)
Block(5,16,8,minecraft:skull:1,StrongHoldSkull/we-Stronghold01/193-Skull.nbt)
Block(5,17,0,minecraft:skull:1,StrongHoldSkull/we-Stronghold01/194-Skull.nbt)
Block(6,3,-5,minecraft:skull:1,StrongHoldSkull/we-Stronghold01/197-Skull.nbt)
Block(6,3,5,minecraft:skull:1,StrongHoldSkull/we-Stronghold01/198-Skull.nbt)
Block(6,3,7,minecraft:skull:1,StrongHoldSkull/we-Stronghold01/199-Skull.nbt)
Block(6,5,5,minecraft:skull:1,StrongHoldSkull/we-Stronghold01/200-Skull.nbt)
Block(6,5,7,minecraft:skull:1,StrongHoldSkull/we-Stronghold01/201-Skull.nbt)
Block(6,6,-6,minecraft:skull:1,StrongHoldSkull/we-Stronghold01/202-Skull.nbt)
Block(6,7,5,minecraft:skull:1,StrongHoldSkull/we-Stronghold01/203-Skull.nbt)
Block(6,7,7,minecraft:skull:1,StrongHoldSkull/we-Stronghold01/204-Skull.nbt)
Block(6,9,5,minecraft:skull:1,StrongHoldSkull/we-Stronghold01/205-Skull.nbt)
Block(6,9,7,minecraft:skull:1,StrongHoldSkull/we-Stronghold01/206-Skull.nbt)
Block(6,13,5,minecraft:skull:1,StrongHoldSkull/we-Stronghold01/207-Skull.nbt)
Block(6,15,1,minecraft:skull:1,StrongHoldSkull/we-Stronghold01/209-Skull.nbt)
Block(6,15,2,minecraft:skull:1,StrongHoldSkull/we-Stronghold01/210-Skull.nbt)
Block(6,17,-6,minecraft:skull:1,StrongHoldSkull/we-Stronghold01/211-Skull.nbt)
Block(6,17,8,minecraft:skull:1,StrongHoldSkull/we-Stronghold01/212-Skull.nbt)
Block(6,20,7,minecraft:skull:1,StrongHoldSkull/we-Stronghold01/213-Skull.nbt)
Block(7,5,-6,minecraft:skull:1,StrongHoldSkull/we-Stronghold01/215-Skull.nbt)
Block(7,9,-6,minecraft:skull:1,StrongHoldSkull/we-Stronghold01/216-Skull.nbt)
Block(7,11,-5,minecraft:skull:1,StrongHoldSkull/we-Stronghold01/217-Skull.nbt)
Block(7,14,-5,minecraft:skull:1,StrongHoldSkull/we-Stronghold01/219-Skull.nbt)
Block(7,14,-2,minecraft:skull:1,StrongHoldSkull/we-Stronghold01/220-Skull.nbt)
Block(7,14,-1,minecraft:skull:1,StrongHoldSkull/we-Stronghold01/221-Skull.nbt)
Block(7,14,2,minecraft:skull:1,StrongHoldSkull/we-Stronghold01/222-Skull.nbt)
Block(7,16,-6,minecraft:skull:1,StrongHoldSkull/we-Stronghold01/223-Skull.nbt)
Block(7,16,6,minecraft:skull:1,StrongHoldSkull/we-Stronghold01/224-Skull.nbt)
Block(7,17,7,minecraft:skull:1,StrongHoldSkull/we-Stronghold01/225-Skull.nbt)
Block(7,18,8,minecraft:skull:1,StrongHoldSkull/we-Stronghold01/227-Skull.nbt)
Block(-8,1,-7,minecraft:monster_egg:3)
Block(-8,1,-6,minecraft:monster_egg:4)
Block(-8,1,-5,minecraft:monster_egg:4)
Block(-8,1,-4,minecraft:monster_egg:4)
Block(-8,1,-3,minecraft:monster_egg:3)
Block(-8,1,-2,minecraft:stonebrick)
Block(-8,1,-1,minecraft:monster_egg:4)
Block(-8,1,0,minecraft:monster_egg:4)
Block(-8,1,1,minecraft:monster_egg:4)
Block(-8,1,2,minecraft:stonebrick)
Block(-8,1,3,minecraft:monster_egg:3)
Block(-8,1,4,minecraft:monster_egg:3)
Block(-8,1,5,minecraft:monster_egg:3)
Block(-8,1,6,minecraft:monster_egg:3)
Block(-8,1,7,minecraft:stonebrick)
Block(-8,1,8,minecraft:stonebrick)
Block(-8,2,-7,minecraft:monster_egg:4)
Block(-8,2,-6,minecraft:stonebrick)
Block(-8,2,-5,minecraft:monster_egg:4)
Block(-8,2,-4,minecraft:stone_brick_stairs:1)
Block(-8,2,-3,minecraft:monster_egg:4)
Block(-8,2,-2,minecraft:monster_egg:3)
Block(-8,2,-1,minecraft:monster_egg:3)
Block(-8,2,0,minecraft:stone_brick_stairs:1)
Block(-8,2,1,minecraft:monster_egg:4)
Block(-8,2,2,minecraft:monster_egg:4)
Block(-8,2,3,minecraft:monster_egg:3)
Block(-8,2,4,minecraft:stone_brick_stairs:1)
Block(-8,2,5,minecraft:monster_egg:4)
Block(-8,2,6,minecraft:monster_egg:3)
Block(-8,2,7,minecraft:monster_egg:3)
Block(-8,2,8,minecraft:stone_brick_stairs:1)
Block(-8,3,-7,minecraft:monster_egg:3)
Block(-8,3,-6,minecraft:monster_egg:4)
Block(-8,3,-5,minecraft:stone_brick_stairs:1)
Block(-8,3,-4,minecraft:stone_brick_stairs:5)
Block(-8,3,-3,minecraft:stone_brick_stairs:1)
Block(-8,3,-2,minecraft:monster_egg:4)
Block(-8,3,-1,minecraft:stone_brick_stairs:1)
Block(-8,3,0,minecraft:stone_brick_stairs:5)
Block(-8,3,1,minecraft:stone_brick_stairs:1)
Block(-8,3,2,minecraft:monster_egg:3)
Block(-8,3,3,minecraft:stone_brick_stairs:1)
Block(-8,3,4,minecraft:stone_brick_stairs:5)
Block(-8,3,5,minecraft:stone_brick_stairs:1)
Block(-8,3,6,minecraft:monster_egg:3)
Block(-8,3,7,minecraft:stone_brick_stairs:1)
Block(-8,3,8,minecraft:stone_brick_stairs:5)
Block(-8,4,-7,minecraft:monster_egg:3)
Block(-8,4,-6,minecraft:monster_egg:3)
Block(-8,4,-5,minecraft:obsidian)
Block(-8,4,-4,minecraft:obsidian)
Block(-8,4,-3,minecraft:obsidian)
Block(-8,4,-2,minecraft:monster_egg:4)
Block(-8,4,-1,minecraft:obsidian)
Block(-8,4,0,minecraft:obsidian)
Block(-8,4,1,minecraft:obsidian)
Block(-8,4,2,minecraft:monster_egg:3)
Block(-8,4,3,minecraft:obsidian)
Block(-8,4,4,minecraft:obsidian)
Block(-8,4,5,minecraft:obsidian)
Block(-8,4,6,minecraft:stonebrick)
Block(-8,4,7,minecraft:obsidian)
Block(-8,4,8,minecraft:obsidian)
Block(-8,5,-7,minecraft:stonebrick)
Block(-8,5,-6,minecraft:monster_egg:3)
Block(-8,5,-5,minecraft:stone_brick_stairs:5)
Block(-8,5,-4,minecraft:stone_brick_stairs:1)
Block(-8,5,-3,minecraft:stone_brick_stairs:5)
Block(-8,5,-2,minecraft:monster_egg:3)
Block(-8,5,-1,minecraft:stone_brick_stairs:5)
Block(-8,5,0,minecraft:stone_brick_stairs:1)
Block(-8,5,1,minecraft:stone_brick_stairs:5)
Block(-8,5,2,minecraft:stonebrick)
Block(-8,5,3,minecraft:stone_brick_stairs:5)
Block(-8,5,4,minecraft:stone_brick_stairs:1)
Block(-8,5,5,minecraft:stone_brick_stairs:5)
Block(-8,5,6,minecraft:monster_egg:4)
Block(-8,5,7,minecraft:stone_brick_stairs:5)
Block(-8,5,8,minecraft:stone_brick_stairs:1)
Block(-8,6,-7,minecraft:monster_egg:3)
Block(-8,6,-6,minecraft:stonebrick)
Block(-8,6,-5,minecraft:stone_brick_stairs:1)
Block(-8,6,-4,minecraft:stone_brick_stairs:5)
Block(-8,6,-3,minecraft:stone_brick_stairs:1)
Block(-8,6,-2,minecraft:stonebrick)
Block(-8,6,-1,minecraft:stone_brick_stairs:1)
Block(-8,6,0,minecraft:stone_brick_stairs:5)
Block(-8,6,1,minecraft:stone_brick_stairs:1)
Block(-8,6,2,minecraft:monster_egg:3)
Block(-8,6,3,minecraft:stone_brick_stairs:1)
Block(-8,6,4,minecraft:stone_brick_stairs:5)
Block(-8,6,5,minecraft:stone_brick_stairs:1)
Block(-8,6,6,minecraft:monster_egg:3)
Block(-8,6,7,minecraft:stone_brick_stairs:1)
Block(-8,6,8,minecraft:stone_brick_stairs:5)
Block(-8,7,-7,minecraft:monster_egg:3)
Block(-8,7,-6,minecraft:stonebrick)
Block(-8,7,-5,minecraft:monster_egg:3)
Block(-8,7,-4,minecraft:stonebrick)
Block(-8,7,-3,minecraft:stonebrick)
Block(-8,7,-2,minecraft:monster_egg:3)
Block(-8,7,-1,minecraft:monster_egg:3)
Block(-8,7,0,minecraft:monster_egg:4)
Block(-8,7,1,minecraft:monster_egg:3)
Block(-8,7,2,minecraft:monster_egg:3)
Block(-8,7,3,minecraft:monster_egg:3)
Block(-8,7,4,minecraft:stonebrick)
Block(-8,7,5,minecraft:monster_egg:3)
Block(-8,7,6,minecraft:stonebrick)
Block(-8,7,7,minecraft:monster_egg:4)
Block(-8,7,8,minecraft:monster_egg:3)
Block(-8,8,-7,minecraft:stonebrick)
Block(-8,8,-6,minecraft:monster_egg:4)
Block(-8,8,-5,minecraft:monster_egg:3)
Block(-8,8,-4,minecraft:monster_egg:3)
Block(-8,8,-3,minecraft:monster_egg:4)
Block(-8,8,-2,minecraft:monster_egg:3)
Block(-8,8,-1,minecraft:monster_egg:3)
Block(-8,8,0,minecraft:monster_egg:3)
Block(-8,8,1,minecraft:stonebrick)
Block(-8,8,2,minecraft:stonebrick)
Block(-8,8,3,minecraft:monster_egg:4)
Block(-8,8,4,minecraft:monster_egg:4)
Block(-8,8,5,minecraft:monster_egg:4)
Block(-8,8,6,minecraft:stonebrick)
Block(-8,8,7,minecraft:monster_egg:3)
Block(-8,8,8,minecraft:monster_egg:3)
Block(-8,9,-7,minecraft:stonebrick)
Block(-8,9,-6,minecraft:monster_egg:3)
Block(-8,9,-5,minecraft:stonebrick)
Block(-8,9,-4,minecraft:monster_egg:3)
Block(-8,9,-3,minecraft:monster_egg:3)
Block(-8,9,-2,minecraft:monster_egg:3)
Block(-8,9,-1,minecraft:stonebrick)
Block(-8,9,0,minecraft:stonebrick)
Block(-8,9,1,minecraft:monster_egg:3)
Block(-8,9,2,minecraft:stonebrick)
Block(-8,9,3,minecraft:monster_egg:3)
Block(-8,9,4,minecraft:monster_egg:3)
Block(-8,9,5,minecraft:monster_egg:4)
Block(-8,9,6,minecraft:monster_egg:3)
Block(-8,9,7,minecraft:monster_egg:3)
Block(-8,9,8,minecraft:monster_egg:3)
Block(-8,10,-7,minecraft:monster_egg:3)
Block(-8,10,-6,minecraft:stonebrick)
Block(-8,10,-5,minecraft:monster_egg:4)
Block(-8,10,-4,minecraft:monster_egg:3)
Block(-8,10,-3,minecraft:monster_egg:3)
Block(-8,10,-2,minecraft:monster_egg:4)
Block(-8,10,-1,minecraft:stonebrick)
Block(-8,10,0,minecraft:stonebrick)
Block(-8,10,1,minecraft:stonebrick)
Block(-8,10,2,minecraft:monster_egg:4)
Block(-8,10,3,minecraft:stonebrick)
Block(-8,10,4,minecraft:stonebrick)
Block(-8,10,5,minecraft:monster_egg:3)
Block(-8,10,6,minecraft:stonebrick)
Block(-8,10,7,minecraft:monster_egg:3)
Block(-8,10,8,minecraft:monster_egg:3)
Block(-8,11,-7,minecraft:monster_egg:3)
Block(-8,11,-6,minecraft:monster_egg:3)
Block(-8,11,-5,minecraft:monster_egg:3)
Block(-8,11,-4,minecraft:monster_egg:3)
Block(-8,11,-3,minecraft:monster_egg:4)
Block(-8,11,-2,minecraft:monster_egg:3)
Block(-8,11,-1,minecraft:monster_egg:3)
Block(-8,11,0,minecraft:monster_egg:3)
Block(-8,11,1,minecraft:monster_egg:3)
Block(-8,11,2,minecraft:stonebrick)
Block(-8,11,3,minecraft:monster_egg:4)
Block(-8,11,4,minecraft:monster_egg:4)
Block(-8,11,5,minecraft:stonebrick)
Block(-8,11,6,minecraft:monster_egg:3)
Block(-8,11,7,minecraft:stonebrick)
Block(-8,11,8,minecraft:stonebrick)
Block(-8,12,-7,minecraft:monster_egg:3)
Block(-8,12,-6,minecraft:monster_egg:3)
Block(-8,12,-5,minecraft:monster_egg:3)
Block(-8,12,-4,minecraft:monster_egg:4)
Block(-8,12,-3,minecraft:monster_egg:3)
Block(-8,12,-2,minecraft:monster_egg:3)
Block(-8,12,-1,minecraft:monster_egg:3)
Block(-8,12,0,minecraft:monster_egg:4)
Block(-8,12,1,minecraft:monster_egg:3)
Block(-8,12,2,minecraft:monster_egg:3)
Block(-8,12,3,minecraft:monster_egg:3)
Block(-8,12,4,minecraft:monster_egg:3)
Block(-8,12,5,minecraft:monster_egg:3)
Block(-8,12,6,minecraft:monster_egg:4)
Block(-8,12,7,minecraft:monster_egg:3)
Block(-8,12,8,minecraft:monster_egg:3)
Block(-8,13,-7,minecraft:monster_egg:4)
Block(-8,13,-6,minecraft:monster_egg:4)
Block(-8,13,-5,minecraft:monster_egg:3)
Block(-8,13,-4,minecraft:monster_egg:3)
Block(-8,13,-3,minecraft:monster_egg:3)
Block(-8,13,-2,minecraft:monster_egg:3)
Block(-8,13,-1,minecraft:monster_egg:4)
Block(-8,13,0,minecraft:monster_egg:4)
Block(-8,13,1,minecraft:monster_egg:3)
Block(-8,13,2,minecraft:monster_egg:3)
Block(-8,13,3,minecraft:stonebrick)
Block(-8,13,4,minecraft:monster_egg:3)
Block(-8,13,5,minecraft:monster_egg:3)
Block(-8,13,6,minecraft:stonebrick)
Block(-8,13,7,minecraft:monster_egg:3)
Block(-8,13,8,minecraft:stonebrick)
Block(-8,14,-7,minecraft:monster_egg:3)
Block(-8,14,-6,minecraft:stonebrick)
Block(-8,14,-5,minecraft:monster_egg:3)
Block(-8,14,-4,minecraft:stonebrick)
Block(-8,14,-3,minecraft:monster_egg:3)
Block(-8,14,-2,minecraft:stonebrick)
Block(-8,14,-1,minecraft:monster_egg:3)
Block(-8,14,0,minecraft:monster_egg:4)
Block(-8,14,1,minecraft:monster_egg:3)
Block(-8,14,2,minecraft:stonebrick)
Block(-8,14,3,minecraft:monster_egg:3)
Block(-8,14,4,minecraft:monster_egg:3)
Block(-8,14,5,minecraft:stonebrick)
Block(-8,14,6,minecraft:monster_egg:3)
Block(-8,14,7,minecraft:stonebrick)
Block(-8,14,8,minecraft:monster_egg:3)
Block(-8,15,-7,minecraft:monster_egg:3)
Block(-8,15,-6,minecraft:stonebrick)
Block(-8,15,-5,minecraft:monster_egg:4)
Block(-8,15,-4,minecraft:monster_egg:4)
Block(-8,15,-3,minecraft:monster_egg:3)
Block(-8,15,-2,minecraft:monster_egg:3)
Block(-8,15,-1,minecraft:monster_egg:3)
Block(-8,15,0,minecraft:stonebrick)
Block(-8,15,1,minecraft:monster_egg:3)
Block(-8,15,2,minecraft:monster_egg:4)
Block(-8,15,3,minecraft:monster_egg:3)
Block(-8,15,4,minecraft:stonebrick)
Block(-8,15,5,minecraft:monster_egg:3)
Block(-8,15,6,minecraft:monster_egg:3)
Block(-8,15,7,minecraft:monster_egg:3)
Block(-8,15,8,minecraft:monster_egg:4)
Block(-8,16,-7,minecraft:stonebrick)
Block(-8,16,-6,minecraft:stonebrick)
Block(-8,16,-5,minecraft:monster_egg:4)
Block(-8,16,-4,minecraft:monster_egg:4)
Block(-8,16,-3,minecraft:monster_egg:4)
Block(-8,16,-2,minecraft:monster_egg:3)
Block(-8,16,-1,minecraft:monster_egg:3)
Block(-8,16,0,minecraft:monster_egg:3)
Block(-8,16,1,minecraft:monster_egg:3)
Block(-8,16,2,minecraft:monster_egg:3)
Block(-8,16,3,minecraft:monster_egg:3)
Block(-8,16,4,minecraft:monster_egg:3)
Block(-8,16,5,minecraft:monster_egg:3)
Block(-8,16,6,minecraft:monster_egg:3)
Block(-8,16,7,minecraft:monster_egg:3)
Block(-8,16,8,minecraft:monster_egg:3)
Block(-8,17,-7,minecraft:monster_egg:3)
Block(-8,17,-6,minecraft:monster_egg:3)
Block(-8,17,-5,minecraft:monster_egg:4)
Block(-8,17,-4,minecraft:stonebrick)
Block(-8,17,-3,minecraft:stonebrick)
Block(-8,17,-2,minecraft:stonebrick)
Block(-8,17,-1,minecraft:monster_egg:3)
Block(-8,17,0,minecraft:monster_egg:3)
Block(-8,17,1,minecraft:monster_egg:4)
Block(-8,17,2,minecraft:monster_egg:4)
Block(-8,17,3,minecraft:monster_egg:3)
Block(-8,17,4,minecraft:stonebrick)
Block(-8,17,5,minecraft:monster_egg:4)
Block(-8,17,6,minecraft:monster_egg:4)
Block(-8,17,7,minecraft:monster_egg:4)
Block(-8,17,8,minecraft:monster_egg:3)
Block(-8,18,-7,minecraft:monster_egg:4)
Block(-8,18,-6,minecraft:monster_egg:3)
Block(-8,18,-5,minecraft:stonebrick)
Block(-8,18,-4,minecraft:monster_egg:4)
Block(-8,18,-3,minecraft:monster_egg:4)
Block(-8,18,-2,minecraft:monster_egg:3)
Block(-8,18,-1,minecraft:monster_egg:4)
Block(-8,18,0,minecraft:monster_egg:3)
Block(-8,18,1,minecraft:monster_egg:4)
Block(-8,18,2,minecraft:stonebrick)
Block(-8,18,3,minecraft:monster_egg:4)
Block(-8,18,4,minecraft:monster_egg:4)
Block(-8,18,5,minecraft:monster_egg:4)
Block(-8,18,6,minecraft:monster_egg:4)
Block(-8,18,7,minecraft:stonebrick)
Block(-8,18,8,minecraft:monster_egg:4)
Block(-8,19,-7,minecraft:monster_egg:4)
Block(-8,19,-6,minecraft:monster_egg:3)
Block(-8,19,-5,minecraft:monster_egg:3)
Block(-8,19,-4,minecraft:monster_egg:3)
Block(-8,19,-3,minecraft:monster_egg:3)
Block(-8,19,-2,minecraft:monster_egg:3)
Block(-8,19,-1,minecraft:monster_egg:3)
Block(-8,19,0,minecraft:stonebrick)
Block(-8,19,1,minecraft:monster_egg:4)
Block(-8,19,2,minecraft:stonebrick)
Block(-8,19,3,minecraft:monster_egg:3)
Block(-8,19,4,minecraft:monster_egg:3)
Block(-8,19,5,minecraft:monster_egg:4)
Block(-8,19,6,minecraft:monster_egg:3)
Block(-8,19,7,minecraft:stonebrick)
Block(-8,19,8,minecraft:monster_egg:3)
Block(-8,20,-7,minecraft:stonebrick)
Block(-8,20,-6,minecraft:monster_egg:3)
Block(-8,20,-5,minecraft:monster_egg:3)
Block(-8,20,-4,minecraft:monster_egg:3)
Block(-8,20,-3,minecraft:stonebrick)
Block(-8,20,-2,minecraft:monster_egg:3)
Block(-8,20,-1,minecraft:monster_egg:3)
Block(-8,20,0,minecraft:monster_egg:4)
Block(-8,20,1,minecraft:stonebrick)
Block(-8,20,2,minecraft:stonebrick)
Block(-8,20,3,minecraft:monster_egg:3)
Block(-8,20,4,minecraft:monster_egg:3)
Block(-8,20,5,minecraft:monster_egg:4)
Block(-8,20,6,minecraft:monster_egg:3)
Block(-8,20,7,minecraft:monster_egg:3)
Block(-8,20,8,minecraft:monster_egg:4)
Block(-8,21,-7,minecraft:monster_egg:3)
Block(-8,21,-6,minecraft:monster_egg:4)
Block(-8,21,-5,minecraft:monster_egg:3)
Block(-8,21,-4,minecraft:monster_egg:3)
Block(-8,21,-3,minecraft:stonebrick)
Block(-8,21,-2,minecraft:monster_egg:4)
Block(-8,21,-1,minecraft:monster_egg:3)
Block(-8,21,0,minecraft:monster_egg:4)
Block(-8,21,1,minecraft:monster_egg:4)
Block(-8,21,2,minecraft:monster_egg:4)
Block(-8,21,3,minecraft:monster_egg:3)
Block(-8,21,4,minecraft:monster_egg:3)
Block(-8,21,5,minecraft:monster_egg:4)
Block(-8,21,6,minecraft:monster_egg:3)
Block(-8,21,7,minecraft:monster_egg:3)
Block(-8,21,8,minecraft:monster_egg:4)
Block(-8,22,-7,minecraft:monster_egg:4)
Block(-8,22,-6,minecraft:stonebrick)
Block(-8,22,-5,minecraft:monster_egg:3)
Block(-8,22,-4,minecraft:monster_egg:4)
Block(-8,22,-3,minecraft:monster_egg:3)
Block(-8,22,-2,minecraft:monster_egg:3)
Block(-8,22,-1,minecraft:monster_egg:3)
Block(-8,22,0,minecraft:monster_egg:4)
Block(-8,22,1,minecraft:monster_egg:4)
Block(-8,22,2,minecraft:monster_egg:3)
Block(-8,22,3,minecraft:monster_egg:4)
Block(-8,22,4,minecraft:monster_egg:4)
Block(-8,22,5,minecraft:monster_egg:4)
Block(-8,22,6,minecraft:stonebrick)
Block(-8,22,7,minecraft:monster_egg:4)
Block(-8,22,8,minecraft:monster_egg:4)
Block(-8,23,-7,minecraft:monster_egg:3)
Block(-8,23,-6,minecraft:stonebrick)
Block(-8,23,-5,minecraft:monster_egg:3)
Block(-8,23,-4,minecraft:monster_egg:3)
Block(-8,23,-3,minecraft:stonebrick)
Block(-8,23,-2,minecraft:stonebrick)
Block(-8,23,-1,minecraft:monster_egg:3)
Block(-8,23,0,minecraft:stonebrick)
Block(-8,23,1,minecraft:monster_egg:3)
Block(-8,23,2,minecraft:stonebrick)
Block(-8,23,3,minecraft:monster_egg:4)
Block(-8,23,4,minecraft:monster_egg:3)
Block(-8,23,5,minecraft:stonebrick)
Block(-8,23,6,minecraft:stonebrick)
Block(-8,23,7,minecraft:monster_egg:3)
Block(-8,23,8,minecraft:monster_egg:4)
Block(-8,24,-7,minecraft:monster_egg:4)
Block(-8,24,-6,minecraft:stonebrick)
Block(-8,24,-5,minecraft:monster_egg:4)
Block(-8,24,-4,minecraft:monster_egg:4)
Block(-8,24,-3,minecraft:monster_egg:4)
Block(-8,24,-2,minecraft:monster_egg:3)
Block(-8,24,-1,minecraft:monster_egg:3)
Block(-8,24,0,minecraft:stonebrick)
Block(-8,24,1,minecraft:monster_egg:3)
Block(-8,24,2,minecraft:monster_egg:4)
Block(-8,24,3,minecraft:stonebrick)
Block(-8,24,4,minecraft:monster_egg:3)
Block(-8,24,5,minecraft:stonebrick)
Block(-8,24,6,minecraft:monster_egg:3)
Block(-8,24,7,minecraft:monster_egg:4)
Block(-8,24,8,minecraft:monster_egg:3)
Block(-8,25,-7,minecraft:stonebrick)
Block(-8,25,-6,minecraft:monster_egg:3)
Block(-8,25,-5,minecraft:stonebrick)
Block(-8,25,-4,minecraft:monster_egg:3)
Block(-8,25,-3,minecraft:stonebrick)
Block(-8,25,-2,minecraft:monster_egg:4)
Block(-8,25,-1,minecraft:monster_egg:4)
Block(-8,25,0,minecraft:monster_egg:3)
Block(-8,25,1,minecraft:monster_egg:4)
Block(-8,25,2,minecraft:stonebrick)
Block(-8,25,3,minecraft:monster_egg:3)
Block(-8,25,4,minecraft:stonebrick)
Block(-8,25,5,minecraft:monster_egg:3)
Block(-8,25,6,minecraft:monster_egg:3)
Block(-8,25,7,minecraft:monster_egg:3)
Block(-8,25,8,minecraft:monster_egg:3)
Block(-8,26,-7,minecraft:monster_egg:4)
Block(-8,26,-6,minecraft:stonebrick)
Block(-8,26,-5,minecraft:monster_egg:3)
Block(-8,26,-4,minecraft:stonebrick)
Block(-8,26,-3,minecraft:monster_egg:3)
Block(-8,26,-2,minecraft:monster_egg:3)
Block(-8,26,-1,minecraft:stonebrick)
Block(-8,26,0,minecraft:monster_egg:3)
Block(-8,26,1,minecraft:monster_egg:4)
Block(-8,26,2,minecraft:monster_egg:3)
Block(-8,26,3,minecraft:monster_egg:3)
Block(-8,26,4,minecraft:monster_egg:3)
Block(-8,26,5,minecraft:monster_egg:3)
Block(-8,26,6,minecraft:stonebrick)
Block(-8,26,7,minecraft:monster_egg:3)
Block(-8,26,8,minecraft:stonebrick)
Block(-8,27,-7,minecraft:monster_egg:4)
Block(-8,27,-6,minecraft:stonebrick)
Block(-8,27,-5,minecraft:monster_egg:3)
Block(-8,27,-4,minecraft:stonebrick)
Block(-8,27,-3,minecraft:stonebrick)
Block(-8,27,-2,minecraft:stonebrick)
Block(-8,27,-1,minecraft:monster_egg:4)
Block(-8,27,0,minecraft:monster_egg:4)
Block(-8,27,1,minecraft:monster_egg:4)
Block(-8,27,2,minecraft:monster_egg:3)
Block(-8,27,3,minecraft:monster_egg:4)
Block(-8,27,4,minecraft:monster_egg:3)
Block(-8,27,5,minecraft:stonebrick)
Block(-8,27,6,minecraft:monster_egg:3)
Block(-8,27,7,minecraft:monster_egg:4)
Block(-8,27,8,minecraft:monster_egg:3)
Block(-8,28,-7,minecraft:monster_egg:4)
Block(-8,28,-6,minecraft:monster_egg:3)
Block(-8,28,-5,minecraft:monster_egg:3)
Block(-8,28,-4,minecraft:monster_egg:4)
Block(-8,28,-3,minecraft:stonebrick)
Block(-8,28,-2,minecraft:monster_egg:3)
Block(-8,28,-1,minecraft:monster_egg:3)
Block(-8,28,0,minecraft:stonebrick)
Block(-8,28,1,minecraft:monster_egg:3)
Block(-8,28,2,minecraft:monster_egg:3)
Block(-8,28,3,minecraft:stonebrick)
Block(-8,28,4,minecraft:monster_egg:3)
Block(-8,28,5,minecraft:monster_egg:4)
Block(-8,28,6,minecraft:monster_egg:4)
Block(-8,28,7,minecraft:monster_egg:3)
Block(-8,28,8,minecraft:monster_egg:4)
Block(-8,29,-7,minecraft:monster_egg:4)
Block(-8,29,-6,minecraft:monster_egg:4)
Block(-8,29,-5,minecraft:monster_egg:4)
Block(-8,29,-4,minecraft:monster_egg:3)
Block(-8,29,-3,minecraft:monster_egg:3)
Block(-8,29,-2,minecraft:monster_egg:4)
Block(-8,29,-1,minecraft:monster_egg:3)
Block(-8,29,0,minecraft:monster_egg:3)
Block(-8,29,1,minecraft:monster_egg:4)
Block(-8,29,2,minecraft:monster_egg:4)
Block(-8,29,3,minecraft:monster_egg:4)
Block(-8,29,4,minecraft:monster_egg:3)
Block(-8,29,5,minecraft:monster_egg:3)
Block(-8,29,6,minecraft:monster_egg:3)
Block(-8,29,7,minecraft:monster_egg:3)
Block(-8,29,8,minecraft:monster_egg:3)
Block(-8,30,-7,minecraft:monster_egg:4)
Block(-8,30,-6,minecraft:monster_egg:4)
Block(-8,30,-5,minecraft:monster_egg:3)
Block(-8,30,-4,minecraft:monster_egg:4)
Block(-8,30,-3,minecraft:stonebrick)
Block(-8,30,-2,minecraft:stonebrick)
Block(-8,30,-1,minecraft:stonebrick)
Block(-8,30,0,minecraft:monster_egg:3)
Block(-8,30,1,minecraft:monster_egg:4)
Block(-8,30,2,minecraft:stonebrick)
Block(-8,30,3,minecraft:stonebrick)
Block(-8,30,4,minecraft:monster_egg:3)
Block(-8,30,5,minecraft:stonebrick)
Block(-8,30,6,minecraft:monster_egg:3)
Block(-8,30,7,minecraft:monster_egg:4)
Block(-8,30,8,minecraft:monster_egg:3)
Block(-8,31,-7,minecraft:monster_egg:3)
Block(-8,31,-6,minecraft:monster_egg:4)
Block(-8,31,-5,minecraft:monster_egg:4)
Block(-8,31,-4,minecraft:monster_egg:3)
Block(-8,31,-3,minecraft:stonebrick)
Block(-8,31,-2,minecraft:stonebrick)
Block(-8,31,-1,minecraft:monster_egg:3)
Block(-8,31,0,minecraft:monster_egg:4)
Block(-8,31,1,minecraft:monster_egg:3)
Block(-8,31,2,minecraft:monster_egg:3)
Block(-8,31,3,minecraft:monster_egg:3)
Block(-8,31,4,minecraft:monster_egg:3)
Block(-8,31,5,minecraft:monster_egg:4)
Block(-8,31,6,minecraft:monster_egg:3)
Block(-8,31,7,minecraft:monster_egg:3)
Block(-8,31,8,minecraft:monster_egg:4)
Block(-8,32,-7,minecraft:monster_egg:3)
Block(-8,32,-6,minecraft:monster_egg:3)
Block(-8,32,-5,minecraft:monster_egg:3)
Block(-8,32,-4,minecraft:monster_egg:3)
Block(-8,32,-3,minecraft:monster_egg:3)
Block(-8,32,-2,minecraft:stonebrick)
Block(-8,32,-1,minecraft:monster_egg:3)
Block(-8,32,0,minecraft:monster_egg:3)
Block(-8,32,1,minecraft:monster_egg:3)
Block(-8,32,2,minecraft:monster_egg:3)
Block(-8,32,3,minecraft:stonebrick)
Block(-8,32,4,minecraft:stonebrick)
Block(-8,32,5,minecraft:monster_egg:4)
Block(-8,32,6,minecraft:stonebrick)
Block(-8,32,7,minecraft:stonebrick)
Block(-8,32,8,minecraft:monster_egg:4)
Block(-8,33,-7,minecraft:monster_egg:3)
Block(-8,33,-6,minecraft:monster_egg:4)
Block(-8,33,-5,minecraft:monster_egg:3)
Block(-8,33,-4,minecraft:monster_egg:3)
Block(-8,33,-3,minecraft:stonebrick)
Block(-8,33,-2,minecraft:monster_egg:3)
Block(-8,33,-1,minecraft:monster_egg:4)
Block(-8,33,0,minecraft:monster_egg:3)
Block(-8,33,1,minecraft:monster_egg:4)
Block(-8,33,2,minecraft:stonebrick)
Block(-8,33,3,minecraft:monster_egg:4)
Block(-8,33,4,minecraft:stonebrick)
Block(-8,33,5,minecraft:monster_egg:3)
Block(-8,33,6,minecraft:stonebrick)
Block(-8,33,7,minecraft:monster_egg:3)
Block(-8,33,8,minecraft:stonebrick)
Block(-8,34,-7,minecraft:monster_egg:4)
Block(-8,34,-6,minecraft:monster_egg:3)
Block(-8,34,-5,minecraft:monster_egg:4)
Block(-8,34,-4,minecraft:monster_egg:4)
Block(-8,34,-3,minecraft:monster_egg:4)
Block(-8,34,-2,minecraft:monster_egg:4)
Block(-8,34,-1,minecraft:monster_egg:3)
Block(-8,34,0,minecraft:monster_egg:3)
Block(-8,34,1,minecraft:monster_egg:4)
Block(-8,34,2,minecraft:monster_egg:3)
Block(-8,34,3,minecraft:stonebrick)
Block(-8,34,4,minecraft:monster_egg:3)
Block(-8,34,5,minecraft:monster_egg:3)
Block(-8,34,6,minecraft:monster_egg:3)
Block(-8,34,7,minecraft:monster_egg:3)
Block(-8,34,8,minecraft:monster_egg:4)
Block(-8,35,-7,minecraft:stonebrick)
Block(-8,35,-6,minecraft:monster_egg:4)
Block(-8,35,-5,minecraft:stonebrick)
Block(-8,35,-4,minecraft:monster_egg:3)
Block(-8,35,-3,minecraft:monster_egg:3)
Block(-8,35,-2,minecraft:monster_egg:4)
Block(-8,35,-1,minecraft:monster_egg:3)
Block(-8,35,0,minecraft:monster_egg:4)
Block(-8,35,1,minecraft:monster_egg:3)
Block(-8,35,2,minecraft:stonebrick)
Block(-8,35,3,minecraft:monster_egg:3)
Block(-8,35,4,minecraft:monster_egg:3)
Block(-8,35,5,minecraft:stonebrick)
Block(-8,35,6,minecraft:monster_egg:3)
Block(-8,35,7,minecraft:stonebrick)
Block(-8,35,8,minecraft:stonebrick)
Block(-8,36,-7,minecraft:monster_egg:3)
Block(-8,36,-6,minecraft:monster_egg:3)
Block(-8,36,-5,minecraft:monster_egg:3)
Block(-8,36,-4,minecraft:monster_egg:3)
Block(-8,36,-3,minecraft:monster_egg:3)
Block(-8,36,-2,minecraft:stonebrick)
Block(-8,36,-1,minecraft:stonebrick)
Block(-8,36,0,minecraft:stonebrick)
Block(-8,36,1,minecraft:monster_egg:3)
Block(-8,36,2,minecraft:stonebrick)
Block(-8,36,3,minecraft:stonebrick)
Block(-8,36,4,minecraft:stonebrick)
Block(-8,36,5,minecraft:stonebrick)
Block(-8,36,6,minecraft:monster_egg:3)
Block(-8,36,7,minecraft:monster_egg:4)
Block(-8,36,8,minecraft:monster_egg:3)
Block(-8,37,-7,minecraft:monster_egg:4)
Block(-8,37,-6,minecraft:monster_egg:4)
Block(-8,37,-5,minecraft:monster_egg:3)
Block(-8,37,-4,minecraft:monster_egg:3)
Block(-8,37,-3,minecraft:stonebrick)
Block(-8,37,-2,minecraft:stonebrick)
Block(-8,37,-1,minecraft:monster_egg:4)
Block(-8,37,0,minecraft:monster_egg:4)
Block(-8,37,1,minecraft:monster_egg:3)
Block(-8,37,2,minecraft:stonebrick)
Block(-8,37,3,minecraft:monster_egg:3)
Block(-8,37,4,minecraft:monster_egg:3)
Block(-8,37,5,minecraft:stonebrick)
Block(-8,37,6,minecraft:stonebrick)
Block(-8,37,7,minecraft:monster_egg:4)
Block(-8,37,8,minecraft:stonebrick)
Block(-8,38,-7,minecraft:monster_egg:4)
Block(-8,38,-6,minecraft:monster_egg:3)
Block(-8,38,-5,minecraft:monster_egg:4)
Block(-8,38,-4,minecraft:stonebrick)
Block(-8,38,-3,minecraft:stonebrick)
Block(-8,38,-2,minecraft:monster_egg:3)
Block(-8,38,-1,minecraft:monster_egg:3)
Block(-8,38,0,minecraft:monster_egg:4)
Block(-8,38,1,minecraft:monster_egg:3)
Block(-8,38,2,minecraft:monster_egg:3)
Block(-8,38,3,minecraft:monster_egg:3)
Block(-8,38,4,minecraft:monster_egg:3)
Block(-8,38,5,minecraft:stonebrick)
Block(-8,38,6,minecraft:monster_egg:3)
Block(-8,38,7,minecraft:monster_egg:4)
Block(-8,38,8,minecraft:monster_egg:3)
Block(-8,39,-7,minecraft:monster_egg:3)
Block(-8,39,-6,minecraft:monster_egg:4)
Block(-8,39,-5,minecraft:monster_egg:3)
Block(-8,39,-4,minecraft:monster_egg:3)
Block(-8,39,-3,minecraft:monster_egg:4)
Block(-8,39,-2,minecraft:monster_egg:3)
Block(-8,39,-1,minecraft:monster_egg:3)
Block(-8,39,0,minecraft:monster_egg:4)
Block(-8,39,1,minecraft:monster_egg:4)
Block(-8,39,2,minecraft:monster_egg:3)
Block(-8,39,3,minecraft:stonebrick)
Block(-8,39,4,minecraft:stonebrick)
Block(-8,39,5,minecraft:monster_egg:4)
Block(-8,39,6,minecraft:stonebrick)
Block(-8,39,7,minecraft:monster_egg:3)
Block(-8,39,8,minecraft:stonebrick)
Block(-8,40,-7,minecraft:monster_egg:4)
Block(-8,40,-6,minecraft:monster_egg:3)
Block(-8,40,-5,minecraft:monster_egg:3)
Block(-8,40,-4,minecraft:stonebrick)
Block(-8,40,-3,minecraft:monster_egg:4)
Block(-8,40,-2,minecraft:monster_egg:3)
Block(-8,40,-1,minecraft:monster_egg:4)
Block(-8,40,0,minecraft:monster_egg:3)
Block(-8,40,1,minecraft:monster_egg:4)
Block(-8,40,2,minecraft:monster_egg:3)
Block(-8,40,3,minecraft:stonebrick)
Block(-8,40,4,minecraft:monster_egg:4)
Block(-8,40,5,minecraft:monster_egg:3)
Block(-8,40,6,minecraft:monster_egg:4)
Block(-8,40,7,minecraft:monster_egg:4)
Block(-8,40,8,minecraft:stonebrick)
Block(-8,41,-7,minecraft:monster_egg:4)
Block(-8,41,-6,minecraft:stonebrick)
Block(-8,41,-5,minecraft:monster_egg:4)
Block(-8,41,-4,minecraft:monster_egg:3)
Block(-8,41,-3,minecraft:monster_egg:3)
Block(-8,41,-2,minecraft:monster_egg:3)
Block(-8,41,-1,minecraft:monster_egg:4)
Block(-8,41,0,minecraft:monster_egg:3)
Block(-8,41,1,minecraft:monster_egg:4)
Block(-8,41,2,minecraft:monster_egg:4)
Block(-8,41,3,minecraft:stonebrick)
Block(-8,41,4,minecraft:monster_egg:3)
Block(-8,41,5,minecraft:monster_egg:4)
Block(-8,41,6,minecraft:monster_egg:3)
Block(-8,41,7,minecraft:monster_egg:3)
Block(-8,41,8,minecraft:monster_egg:3)
Block(-8,42,-7,minecraft:stonebrick)
Block(-8,42,-6,minecraft:stonebrick)
Block(-8,42,-5,minecraft:monster_egg:4)
Block(-8,42,-4,minecraft:monster_egg:3)
Block(-8,42,-3,minecraft:monster_egg:4)
Block(-8,42,-2,minecraft:monster_egg:4)
Block(-8,42,-1,minecraft:monster_egg:3)
Block(-8,42,0,minecraft:monster_egg:4)
Block(-8,42,1,minecraft:stonebrick)
Block(-8,42,2,minecraft:stonebrick)
Block(-8,42,3,minecraft:monster_egg:3)
Block(-8,42,4,minecraft:monster_egg:4)
Block(-8,42,5,minecraft:monster_egg:4)
Block(-8,42,6,minecraft:monster_egg:3)
Block(-8,42,7,minecraft:monster_egg:4)
Block(-8,42,8,minecraft:monster_egg:3)
Block(-8,43,-7,minecraft:monster_egg:4)
Block(-8,43,-6,minecraft:monster_egg:4)
Block(-8,43,-5,minecraft:monster_egg:3)
Block(-8,43,-4,minecraft:monster_egg:3)
Block(-8,43,-3,minecraft:monster_egg:3)
Block(-8,43,-2,minecraft:monster_egg:4)
Block(-8,43,-1,minecraft:monster_egg:3)
Block(-8,43,0,minecraft:monster_egg:3)
Block(-8,43,1,minecraft:monster_egg:3)
Block(-8,43,2,minecraft:stonebrick)
Block(-8,43,3,minecraft:monster_egg:3)
Block(-8,43,4,minecraft:monster_egg:3)
Block(-8,43,5,minecraft:monster_egg:3)
Block(-8,43,6,minecraft:monster_egg:3)
Block(-8,43,7,minecraft:monster_egg:3)
Block(-8,43,8,minecraft:monster_egg:3)
Block(-8,44,-7,minecraft:monster_egg:4)
Block(-8,44,-6,minecraft:monster_egg:3)
Block(-8,44,-5,minecraft:monster_egg:3)
Block(-8,44,-4,minecraft:monster_egg:3)
Block(-8,44,-3,minecraft:stonebrick)
Block(-8,44,-2,minecraft:monster_egg:3)
Block(-8,44,-1,minecraft:monster_egg:3)
Block(-8,44,0,minecraft:monster_egg:3)
Block(-8,44,1,minecraft:monster_egg:3)
Block(-8,44,2,minecraft:stonebrick)
Block(-8,44,3,minecraft:monster_egg:4)
Block(-8,44,4,minecraft:monster_egg:4)
Block(-8,44,5,minecraft:stonebrick)
Block(-8,44,6,minecraft:stonebrick)
Block(-8,44,7,minecraft:monster_egg:3)
Block(-8,44,8,minecraft:monster_egg:3)
Block(-7,1,-7,minecraft:stonebrick)
Block(-7,1,-6,minecraft:stonebrick)
Block(-7,1,-5,minecraft:monster_egg:3)
Block(-7,1,-4,minecraft:stonebrick)
Block(-7,1,-3,minecraft:monster_egg:3)
Block(-7,1,-2,minecraft:monster_egg:4)
Block(-7,1,-1,minecraft:stonebrick)
Block(-7,1,0,minecraft:netherrack)
Block(-7,1,1,minecraft:monster_egg:3)
Block(-7,1,2,minecraft:monster_egg:3)
Block(-7,1,3,minecraft:monster_egg:3)
Block(-7,1,4,minecraft:stonebrick)
Block(-7,1,5,minecraft:monster_egg:4)
Block(-7,1,6,minecraft:monster_egg:4)
Block(-7,1,7,minecraft:monster_egg:3)
Block(-7,1,8,minecraft:glowstone)
Block(-7,2,-7,minecraft:monster_egg:3)
Block(-7,2,-6,minecraft:monster_egg:4)
Block(-7,2,-5,minecraft:stone_brick_stairs)
Block(-7,2,-4,minecraft:anvil:11)
Block(-7,2,-3,minecraft:stone_brick_stairs:2)
Block(-7,2,-2,minecraft:monster_egg:3)
Block(-7,2,-1,minecraft:stone_brick_stairs)
Block(-7,2,0,minecraft:air)
Block(-7,2,1,minecraft:stone_brick_stairs:2)
Block(-7,2,2,minecraft:monster_egg:3)
Block(-7,2,3,minecraft:stone_brick_stairs)
Block(-7,2,4,minecraft:anvil:11)
Block(-7,2,5,minecraft:stone_brick_stairs:2)
Block(-7,2,6,minecraft:stonebrick)
Block(-7,2,7,minecraft:stone_brick_stairs)
Block(-7,2,8,minecraft:stone_slab)
Block(-7,3,-7,minecraft:monster_egg:3)
Block(-7,3,-6,minecraft:monster_egg:3)
Block(-7,3,-5,minecraft:cobblestone_wall)
Block(-7,3,-3,minecraft:cobblestone_wall)
Block(-7,3,-2,minecraft:stonebrick)
Block(-7,3,-1,minecraft:cobblestone_wall)
Block(-7,3,0,minecraft:air)
Block(-7,3,1,minecraft:cobblestone_wall)
Block(-7,3,2,minecraft:monster_egg:3)
Block(-7,3,3,minecraft:cobblestone_wall)
Block(-7,3,5,minecraft:cobblestone_wall)
Block(-7,3,6,minecraft:stonebrick)
Block(-7,3,7,minecraft:cobblestone_wall)
Block(-7,3,8,minecraft:air)
Block(-7,4,-7,minecraft:monster_egg:4)
Block(-7,4,-6,minecraft:monster_egg:3)
Block(-7,4,-5,minecraft:stone_brick_stairs:7)
Block(-7,4,-4,minecraft:cobblestone_wall)
Block(-7,4,-3,minecraft:stone_brick_stairs:6)
Block(-7,4,-2,minecraft:stonebrick)
Block(-7,4,-1,minecraft:stone_brick_stairs:7)
Block(-7,4,0,minecraft:cobblestone_wall)
Block(-7,4,1,minecraft:stone_brick_stairs:6)
Block(-7,4,2,minecraft:stonebrick)
Block(-7,4,3,minecraft:stone_brick_stairs:7)
Block(-7,4,4,minecraft:cobblestone_wall)
Block(-7,4,5,minecraft:stone_brick_stairs:6)
Block(-7,4,6,minecraft:monster_egg:3)
Block(-7,4,7,minecraft:stone_brick_stairs:7)
Block(-7,4,8,minecraft:cobblestone_wall)
Block(-7,5,-7,minecraft:monster_egg:3)
Block(-7,5,-6,minecraft:monster_egg:3)
Block(-7,5,-5,minecraft:cobblestone_wall)
Block(-7,5,-3,minecraft:cobblestone_wall)
Block(-7,5,-2,minecraft:monster_egg:4)
Block(-7,5,-1,minecraft:cobblestone_wall)
Block(-7,5,1,minecraft:cobblestone_wall)
Block(-7,5,2,minecraft:monster_egg:3)
Block(-7,5,3,minecraft:cobblestone_wall)
Block(-7,5,5,minecraft:cobblestone_wall)
Block(-7,5,6,minecraft:monster_egg:4)
Block(-7,5,7,minecraft:cobblestone_wall)
Block(-7,6,-7,minecraft:stonebrick)
Block(-7,6,-6,minecraft:stonebrick)
Block(-7,6,-4,minecraft:air)
Block(-7,6,-2,minecraft:monster_egg:3)
Block(-7,6,0,minecraft:iron_bars)
Block(-7,6,2,minecraft:stonebrick)
Block(-7,6,4,minecraft:cobblestone_wall)
Block(-7,6,6,minecraft:stonebrick)
Block(-7,6,8,minecraft:air)
Block(-7,7,-7,minecraft:monster_egg:3)
Block(-7,7,-6,minecraft:monster_egg:3)
Block(-7,7,-5,minecraft:stone_brick_stairs:7)
Block(-7,7,-4,minecraft:stone_slab:11)
Block(-7,7,-3,minecraft:air)
Block(-7,7,-2,minecraft:monster_egg:4)
Block(-7,7,-1,minecraft:stone_slab:11)
Block(-7,7,0,minecraft:stone_slab)
Block(-7,7,1,minecraft:stone_slab:11)
Block(-7,7,2,minecraft:stonebrick)
Block(-7,7,3,minecraft:stone_slab:11)
Block(-7,7,4,minecraft:stone_slab)
Block(-7,7,5,minecraft:stone_slab:11)
Block(-7,7,6,minecraft:monster_egg:4)
Block(-7,7,7,minecraft:stone_slab:11)
Block(-7,7,8,minecraft:stone_slab)
Block(-7,8,-7,minecraft:monster_egg:3)
Block(-7,8,-6,minecraft:cobblestone_wall)
Block(-7,8,-5,minecraft:stone_slab:5)
Block(-7,8,-4,minecraft:stone_slab:13)
Block(-7,8,-3,minecraft:stone_slab:3)
Block(-7,8,-2,minecraft:stone_slab:5)
Block(-7,8,-1,minecraft:stone_slab:11)
Block(-7,8,0,minecraft:stone_slab)
Block(-7,8,1,minecraft:stone_slab:11)
Block(-7,8,2,minecraft:stone_slab:5)
Block(-7,8,3,minecraft:stone_slab:11)
Block(-7,8,4,minecraft:stone_slab)
Block(-7,8,5,minecraft:stone_slab:11)
Block(-7,8,6,minecraft:stone_slab:5)
Block(-7,8,7,minecraft:stone_slab:11)
Block(-7,8,8,minecraft:stone_slab:8)
Block(-7,9,-7,minecraft:stonebrick)
Block(-7,9,-6,minecraft:cobblestone_wall)
Block(-7,9,-5,minecraft:double_stone_slab)
Block(-7,9,-4,minecraft:cobblestone_wall)
Block(-7,9,-3,minecraft:stone_slab)
Block(-7,9,-2,minecraft:monster_egg:3)
Block(-7,9,-1,minecraft:air)
Block(-7,9,0,minecraft:stone_slab)
Block(-7,9,1,minecraft:air)
Block(-7,9,2,minecraft:monster_egg:3)
Block(-7,9,3,minecraft:air)
Block(-7,9,4,minecraft:air)
Block(-7,9,5,minecraft:air)
Block(-7,9,6,minecraft:stonebrick)
Block(-7,9,7,minecraft:monster_egg:4)
Block(-7,10,-7,minecraft:stonebrick)
Block(-7,10,-6,minecraft:stone_slab:8)
Block(-7,10,-5,minecraft:stone_slab:8)
Block(-7,10,-4,minecraft:stone_slab:8)
Block(-7,10,-3,minecraft:stone_slab:8)
Block(-7,10,-2,minecraft:monster_egg:4)
Block(-7,10,-1,minecraft:stone_slab:8)
Block(-7,10,0,minecraft:stone_slab:8)
Block(-7,10,1,minecraft:stone_slab:8)
Block(-7,10,2,minecraft:monster_egg:4)
Block(-7,10,3,minecraft:air)
Block(-7,10,4,minecraft:air)
Block(-7,10,5,minecraft:air)
Block(-7,10,6,minecraft:monster_egg:4)
Block(-7,10,7,minecraft:monster_egg:3)
Block(-7,10,8,minecraft:stone_slab)
Block(-7,11,-7,minecraft:stonebrick)
Block(-7,11,-6,minecraft:stonebrick)
Block(-7,11,-5,minecraft:cauldron)
Block(-7,11,-4,minecraft:chest:5)
Block(-7,11,-3,minecraft:chest:5)
Block(-7,11,-2,minecraft:stonebrick)
Block(-7,11,-1,minecraft:cauldron)
Block(-7,11,0,minecraft:chest:5)
Block(-7,11,1,minecraft:chest:5)
Block(-7,11,2,minecraft:monster_egg:4)
Block(-7,11,3,minecraft:air)
Block(-7,11,4,minecraft:air)
Block(-7,11,5,minecraft:air)
Block(-7,11,6,minecraft:monster_egg:3)
Block(-7,11,7,minecraft:double_stone_slab)
Block(-7,11,8,minecraft:monster_egg:3)
Block(-7,12,-7,minecraft:stonebrick)
Block(-7,12,-6,minecraft:monster_egg:4)
Block(-7,12,-5,minecraft:stone_brick_stairs:7)
Block(-7,12,-4,minecraft:stone_slab:8)
Block(-7,12,-3,minecraft:stone_brick_stairs:5)
Block(-7,12,-2,minecraft:monster_egg:3)
Block(-7,12,-1,minecraft:stone_brick_stairs:5)
Block(-7,12,0,minecraft:stone_slab:8)
Block(-7,12,1,minecraft:stone_brick_stairs:5)
Block(-7,12,2,minecraft:monster_egg:3)
Block(-7,12,3,minecraft:stone_brick_stairs:5)
Block(-7,12,4,minecraft:stone_slab:8)
Block(-7,12,5,minecraft:stone_brick_stairs:5)
Block(-7,12,6,minecraft:stonebrick)
Block(-7,12,7,minecraft:double_stone_slab)
Block(-7,12,8,minecraft:double_stone_slab)
Block(-7,13,-7,minecraft:monster_egg:3)
Block(-7,13,-6,minecraft:monster_egg:4)
Block(-7,13,-4,minecraft:stone_brick_stairs:1)
Block(-7,13,-3,minecraft:cobblestone_wall)
Block(-7,13,-2,minecraft:monster_egg:4)
Block(-7,13,-1,minecraft:stone_slab:3)
Block(-7,13,0,minecraft:stone_brick_stairs:1)
Block(-7,13,1,minecraft:air)
Block(-7,13,2,minecraft:monster_egg:4)
Block(-7,13,3,minecraft:stone_brick_stairs:1)
Block(-7,13,4,minecraft:stone_brick_stairs:1)
Block(-7,13,5,minecraft:stone_brick_stairs:1)
Block(-7,13,6,minecraft:stonebrick)
Block(-7,13,7,minecraft:double_stone_slab)
Block(-7,13,8,minecraft:double_stone_slab)
Block(-7,14,-7,minecraft:monster_egg:3)
Block(-7,14,-6,minecraft:cobblestone_wall)
Block(-7,14,-5,minecraft:cobblestone_wall)
Block(-7,14,-4,minecraft:stone_slab:3)
Block(-7,14,-2,minecraft:stonebrick)
Block(-7,14,-1,minecraft:air)
Block(-7,14,0,minecraft:stone_slab:8)
Block(-7,14,1,minecraft:stone_slab)
Block(-7,14,2,minecraft:monster_egg:3)
Block(-7,14,3,minecraft:double_stone_slab)
Block(-7,14,4,minecraft:double_stone_slab)
Block(-7,14,5,minecraft:double_stone_slab)
Block(-7,14,6,minecraft:monster_egg:3)
Block(-7,14,7,minecraft:cobblestone_wall)
Block(-7,14,8,minecraft:stone_slab:8)
Block(-7,15,-7,minecraft:monster_egg:3)
Block(-7,15,-6,minecraft:stone_slab:3)
Block(-7,15,-4,minecraft:cobblestone_wall)
Block(-7,15,-3,minecraft:air)
Block(-7,15,-2,minecraft:monster_egg:3)
Block(-7,15,-1,minecraft:stone_slab)
Block(-7,15,0,minecraft:iron_bars)
Block(-7,15,1,minecraft:cobblestone_wall)
Block(-7,15,2,minecraft:stonebrick)
Block(-7,15,3,minecraft:stone_slab:13)
Block(-7,15,4,minecraft:cobblestone_wall)
Block(-7,15,6,minecraft:monster_egg:3)
Block(-7,16,-7,minecraft:stonebrick)
Block(-7,16,-6,minecraft:stone_slab:8)
Block(-7,16,-5,minecraft:monster_egg:3)
Block(-7,16,-4,minecraft:stone_slab:8)
Block(-7,16,-3,minecraft:stone_slab:8)
Block(-7,16,-2,minecraft:monster_egg:3)
Block(-7,16,-1,minecraft:cobblestone_wall)
Block(-7,16,0,minecraft:stone_brick_stairs:5)
Block(-7,16,2,minecraft:monster_egg:4)
Block(-7,16,3,minecraft:chest:5)
Block(-7,16,5,minecraft:iron_bars)
Block(-7,16,6,minecraft:monster_egg:4)
Block(-7,16,7,minecraft:iron_bars)
Block(-7,16,8,minecraft:cobblestone_wall)
Block(-7,17,-7,minecraft:monster_egg:3)
Block(-7,17,-6,minecraft:stone_brick_stairs:7)
Block(-7,17,-5,minecraft:cobblestone_wall)
Block(-7,17,-4,minecraft:chest:5)
Block(-7,17,-3,minecraft:iron_bars)
Block(-7,17,-2,minecraft:monster_egg:3)
Block(-7,17,0,minecraft:chest:5)
Block(-7,17,1,minecraft:iron_bars)
Block(-7,17,2,minecraft:monster_egg:3)
Block(-7,17,3,minecraft:cobblestone_wall)
Block(-7,17,4,minecraft:cobblestone_wall)
Block(-7,17,6,minecraft:stonebrick)
Block(-7,18,-7,minecraft:stonebrick)
Block(-7,18,-5,minecraft:cobblestone_wall)
Block(-7,18,-4,minecraft:stone_brick_stairs:5)
Block(-7,18,-2,minecraft:monster_egg:3)
Block(-7,18,-1,minecraft:iron_bars)
Block(-7,18,0,minecraft:stone_slab:8)
Block(-7,18,1,minecraft:stone_brick_stairs:5)
Block(-7,18,2,minecraft:monster_egg:4)
Block(-7,18,3,minecraft:cobblestone_wall)
Block(-7,18,5,minecraft:cobblestone_wall)
Block(-7,18,6,minecraft:monster_egg:3)
Block(-7,18,7,minecraft:cobblestone_wall)
Block(-7,18,8,minecraft:iron_bars)
Block(-7,19,-7,minecraft:monster_egg:3)
Block(-7,19,-6,minecraft:cobblestone_wall)
Block(-7,19,-4,minecraft:cobblestone_wall)
Block(-7,19,-3,minecraft:cobblestone_wall)
Block(-7,19,-2,minecraft:monster_egg:4)
Block(-7,19,1,minecraft:cobblestone_wall)
Block(-7,19,2,minecraft:stonebrick)
Block(-7,19,4,minecraft:stone_brick_stairs:5)
Block(-7,19,6,minecraft:monster_egg:3)
Block(-7,19,7,minecraft:stone_brick_stairs:7)
Block(-7,20,-7,minecraft:monster_egg:3)
Block(-7,20,-6,minecraft:stone_slab:8)
Block(-7,20,-5,minecraft:stone_brick_stairs:5)
Block(-7,20,-4,minecraft:stone_slab:8)
Block(-7,20,-3,minecraft:stone_brick_stairs:5)
Block(-7,20,-2,minecraft:stonebrick)
Block(-7,20,-1,minecraft:stone_brick_stairs:7)
Block(-7,20,0,minecraft:stone_slab:8)
Block(-7,20,1,minecraft:stone_brick_stairs:5)
Block(-7,20,2,minecraft:monster_egg:3)
Block(-7,20,3,minecraft:stone_brick_stairs:5)
Block(-7,20,4,minecraft:stone_slab:8)
Block(-7,20,5,minecraft:stone_brick_stairs:6)
Block(-7,20,6,minecraft:monster_egg:3)
Block(-7,20,7,minecraft:monster_egg:3)
Block(-7,20,8,minecraft:monster_egg:3)
Block(-7,21,-7,minecraft:monster_egg:4)
Block(-7,21,-6,minecraft:monster_egg:4)
Block(-7,21,-5,minecraft:monster_egg:3)
Block(-7,21,-4,minecraft:monster_egg:3)
Block(-7,21,-3,minecraft:monster_egg:4)
Block(-7,21,-2,minecraft:monster_egg:4)
Block(-7,21,-1,minecraft:monster_egg:3)
Block(-7,21,0,minecraft:monster_egg:3)
Block(-7,21,1,minecraft:stonebrick)
Block(-7,21,2,minecraft:monster_egg:4)
Block(-7,21,3,minecraft:stonebrick)
Block(-7,21,4,minecraft:monster_egg:3)
Block(-7,21,5,minecraft:monster_egg:3)
Block(-7,21,6,minecraft:monster_egg:4)
Block(-7,21,7,minecraft:monster_egg:3)
Block(-7,21,8,minecraft:monster_egg:3)
Block(-7,22,-7,minecraft:monster_egg:4)
Block(-7,22,-6,minecraft:monster_egg:4)
Block(-7,22,-5,minecraft:monster_egg:3)
Block(-7,22,-4,minecraft:stonebrick)
Block(-7,22,-3,minecraft:monster_egg:3)
Block(-7,22,-2,minecraft:monster_egg:3)
Block(-7,22,-1,minecraft:stonebrick)
Block(-7,22,0,minecraft:monster_egg:3)
Block(-7,22,1,minecraft:monster_egg:3)
Block(-7,22,2,minecraft:monster_egg:4)
Block(-7,22,3,minecraft:stonebrick)
Block(-7,22,4,minecraft:monster_egg:4)
Block(-7,22,5,minecraft:stonebrick)
Block(-7,22,6,minecraft:monster_egg:4)
Block(-7,22,7,minecraft:monster_egg:3)
Block(-7,22,8,minecraft:monster_egg:3)
Block(-7,23,-7,minecraft:monster_egg:4)
Block(-7,23,-6,minecraft:lava)
Block(-7,23,-5,minecraft:lava)
Block(-7,23,-4,minecraft:lava)
Block(-7,23,-3,minecraft:lava)
Block(-7,23,-2,minecraft:lava)
Block(-7,23,-1,minecraft:lava)
Block(-7,23,0,minecraft:lava)
Block(-7,23,1,minecraft:lava)
Block(-7,23,2,minecraft:lava)
Block(-7,23,3,minecraft:lava)
Block(-7,23,4,minecraft:lava)
Block(-7,23,5,minecraft:lava)
Block(-7,23,6,minecraft:lava)
Block(-7,23,7,minecraft:lava)
Block(-7,23,8,minecraft:lava)
Block(-7,24,-7,minecraft:monster_egg:3)
Block(-7,24,-6,minecraft:lava)
Block(-7,24,-5,minecraft:lava)
Block(-7,24,-4,minecraft:lava)
Block(-7,24,-3,minecraft:lava)
Block(-7,24,-2,minecraft:lava)
Block(-7,24,-1,minecraft:lava)
Block(-7,24,0,minecraft:lava)
Block(-7,24,1,minecraft:lava)
Block(-7,24,2,minecraft:lava)
Block(-7,24,3,minecraft:lava)
Block(-7,24,4,minecraft:lava)
Block(-7,24,5,minecraft:lava)
Block(-7,24,6,minecraft:lava)
Block(-7,24,7,minecraft:lava)
Block(-7,24,8,minecraft:lava)
Block(-7,25,-7,minecraft:stonebrick)
Block(-7,25,-6,minecraft:lava)
Block(-7,25,-5,minecraft:lava)
Block(-7,25,-4,minecraft:lava)
Block(-7,25,-3,minecraft:lava)
Block(-7,25,-2,minecraft:lava)
Block(-7,25,-1,minecraft:lava)
Block(-7,25,0,minecraft:lava)
Block(-7,25,1,minecraft:lava)
Block(-7,25,2,minecraft:lava)
Block(-7,25,3,minecraft:lava)
Block(-7,25,4,minecraft:lava)
Block(-7,25,5,minecraft:lava)
Block(-7,25,6,minecraft:lava)
Block(-7,25,7,minecraft:lava)
Block(-7,25,8,minecraft:lava)
Block(-7,26,-7,minecraft:monster_egg:4)
Block(-7,26,-6,minecraft:lava)
Block(-7,26,-5,minecraft:lava)
Block(-7,26,-4,minecraft:lava)
Block(-7,26,-3,minecraft:lava)
Block(-7,26,-2,minecraft:lava)
Block(-7,26,-1,minecraft:lava)
Block(-7,26,0,minecraft:lava)
Block(-7,26,1,minecraft:lava)
Block(-7,26,2,minecraft:lava)
Block(-7,26,3,minecraft:lava)
Block(-7,26,4,minecraft:lava)
Block(-7,26,5,minecraft:lava)
Block(-7,26,6,minecraft:lava)
Block(-7,26,7,minecraft:lava)
Block(-7,26,8,minecraft:lava)
Block(-7,27,-7,minecraft:monster_egg:3)
Block(-7,27,-6,minecraft:lava)
Block(-7,27,-5,minecraft:lava)
Block(-7,27,-4,minecraft:lava)
Block(-7,27,-3,minecraft:lava)
Block(-7,27,-2,minecraft:lava)
Block(-7,27,-1,minecraft:lava)
Block(-7,27,0,minecraft:lava)
Block(-7,27,1,minecraft:lava)
Block(-7,27,2,minecraft:lava)
Block(-7,27,3,minecraft:lava)
Block(-7,27,4,minecraft:lava)
Block(-7,27,5,minecraft:lava)
Block(-7,27,6,minecraft:lava)
Block(-7,27,7,minecraft:lava)
Block(-7,27,8,minecraft:lava)
Block(-7,28,-7,minecraft:stonebrick)
Block(-7,28,-6,minecraft:lava)
Block(-7,28,-5,minecraft:lava)
Block(-7,28,-4,minecraft:lava)
Block(-7,28,-3,minecraft:lava)
Block(-7,28,-2,minecraft:lava)
Block(-7,28,-1,minecraft:lava)
Block(-7,28,0,minecraft:lava)
Block(-7,28,1,minecraft:lava)
Block(-7,28,2,minecraft:lava)
Block(-7,28,3,minecraft:lava)
Block(-7,28,4,minecraft:lava)
Block(-7,28,5,minecraft:lava)
Block(-7,28,6,minecraft:lava)
Block(-7,28,7,minecraft:lava)
Block(-7,28,8,minecraft:lava)
Block(-7,29,-7,minecraft:stonebrick)
Block(-7,29,-6,minecraft:lava)
Block(-7,29,-5,minecraft:lava)
Block(-7,29,-4,minecraft:lava)
Block(-7,29,-3,minecraft:lava)
Block(-7,29,-2,minecraft:lava)
Block(-7,29,-1,minecraft:lava)
Block(-7,29,0,minecraft:lava)
Block(-7,29,1,minecraft:lava)
Block(-7,29,2,minecraft:lava)
Block(-7,29,3,minecraft:lava)
Block(-7,29,4,minecraft:lava)
Block(-7,29,5,minecraft:lava)
Block(-7,29,6,minecraft:lava)
Block(-7,29,7,minecraft:lava)
Block(-7,29,8,minecraft:lava)
Block(-7,30,-7,minecraft:monster_egg:3)
Block(-7,30,-6,minecraft:lava)
Block(-7,30,-5,minecraft:lava)
Block(-7,30,-4,minecraft:lava)
Block(-7,30,-3,minecraft:lava)
Block(-7,30,-2,minecraft:lava)
Block(-7,30,-1,minecraft:lava)
Block(-7,30,0,minecraft:lava)
Block(-7,30,1,minecraft:lava)
Block(-7,30,2,minecraft:lava)
Block(-7,30,3,minecraft:lava)
Block(-7,30,4,minecraft:lava)
Block(-7,30,5,minecraft:lava)
Block(-7,30,6,minecraft:lava)
Block(-7,30,7,minecraft:lava)
Block(-7,30,8,minecraft:lava)
Block(-7,31,-7,minecraft:stonebrick)
Block(-7,31,-6,minecraft:lava)
Block(-7,31,-5,minecraft:lava)
Block(-7,31,-4,minecraft:lava)
Block(-7,31,-3,minecraft:lava)
Block(-7,31,-2,minecraft:lava)
Block(-7,31,-1,minecraft:lava)
Block(-7,31,0,minecraft:lava)
Block(-7,31,1,minecraft:lava)
Block(-7,31,2,minecraft:lava)
Block(-7,31,3,minecraft:lava)
Block(-7,31,4,minecraft:lava)
Block(-7,31,5,minecraft:lava)
Block(-7,31,6,minecraft:lava)
Block(-7,31,7,minecraft:lava)
Block(-7,31,8,minecraft:lava)
Block(-7,32,-7,minecraft:monster_egg:3)
Block(-7,32,-6,minecraft:lava)
Block(-7,32,-5,minecraft:lava)
Block(-7,32,-4,minecraft:lava)
Block(-7,32,-3,minecraft:lava)
Block(-7,32,-2,minecraft:lava)
Block(-7,32,-1,minecraft:lava)
Block(-7,32,0,minecraft:lava)
Block(-7,32,1,minecraft:lava)
Block(-7,32,2,minecraft:lava)
Block(-7,32,3,minecraft:lava)
Block(-7,32,4,minecraft:lava)
Block(-7,32,5,minecraft:lava)
Block(-7,32,6,minecraft:lava)
Block(-7,32,7,minecraft:lava)
Block(-7,32,8,minecraft:lava)
Block(-7,33,-7,minecraft:stonebrick)
Block(-7,33,-6,minecraft:lava)
Block(-7,33,-5,minecraft:lava)
Block(-7,33,-4,minecraft:lava)
Block(-7,33,-3,minecraft:lava)
Block(-7,33,-2,minecraft:lava)
Block(-7,33,-1,minecraft:lava)
Block(-7,33,0,minecraft:lava)
Block(-7,33,1,minecraft:lava)
Block(-7,33,2,minecraft:lava)
Block(-7,33,3,minecraft:lava)
Block(-7,33,4,minecraft:lava)
Block(-7,33,5,minecraft:lava)
Block(-7,33,6,minecraft:lava)
Block(-7,33,7,minecraft:lava)
Block(-7,33,8,minecraft:lava)
Block(-7,34,-7,minecraft:monster_egg:4)
Block(-7,34,-6,minecraft:lava)
Block(-7,34,-5,minecraft:lava)
Block(-7,34,-4,minecraft:lava)
Block(-7,34,-3,minecraft:lava)
Block(-7,34,-2,minecraft:lava)
Block(-7,34,-1,minecraft:lava)
Block(-7,34,0,minecraft:lava)
Block(-7,34,1,minecraft:lava)
Block(-7,34,2,minecraft:lava)
Block(-7,34,3,minecraft:lava)
Block(-7,34,4,minecraft:lava)
Block(-7,34,5,minecraft:lava)
Block(-7,34,6,minecraft:lava)
Block(-7,34,7,minecraft:lava)
Block(-7,34,8,minecraft:lava)
Block(-7,35,-7,minecraft:stonebrick)
Block(-7,35,-6,minecraft:lava)
Block(-7,35,-5,minecraft:lava)
Block(-7,35,-4,minecraft:lava)
Block(-7,35,-3,minecraft:lava)
Block(-7,35,-2,minecraft:lava)
Block(-7,35,-1,minecraft:lava)
Block(-7,35,0,minecraft:lava)
Block(-7,35,1,minecraft:lava)
Block(-7,35,2,minecraft:lava)
Block(-7,35,3,minecraft:lava)
Block(-7,35,4,minecraft:lava)
Block(-7,35,5,minecraft:lava)
Block(-7,35,6,minecraft:lava)
Block(-7,35,7,minecraft:lava)
Block(-7,35,8,minecraft:lava)
Block(-7,36,-7,minecraft:monster_egg:4)
Block(-7,36,-6,minecraft:lava)
Block(-7,36,-5,minecraft:lava)
Block(-7,36,-4,minecraft:lava)
Block(-7,36,-3,minecraft:lava)
Block(-7,36,-2,minecraft:lava)
Block(-7,36,-1,minecraft:lava)
Block(-7,36,0,minecraft:lava)
Block(-7,36,1,minecraft:lava)
Block(-7,36,2,minecraft:lava)
Block(-7,36,3,minecraft:lava)
Block(-7,36,4,minecraft:lava)
Block(-7,36,5,minecraft:lava)
Block(-7,36,6,minecraft:lava)
Block(-7,36,7,minecraft:lava)
Block(-7,36,8,minecraft:lava)
Block(-7,37,-7,minecraft:monster_egg:3)
Block(-7,37,-6,minecraft:lava)
Block(-7,37,-5,minecraft:lava)
Block(-7,37,-4,minecraft:lava)
Block(-7,37,-3,minecraft:lava)
Block(-7,37,-2,minecraft:lava)
Block(-7,37,-1,minecraft:lava)
Block(-7,37,0,minecraft:lava)
Block(-7,37,1,minecraft:lava)
Block(-7,37,2,minecraft:lava)
Block(-7,37,3,minecraft:lava)
Block(-7,37,4,minecraft:lava)
Block(-7,37,5,minecraft:lava)
Block(-7,37,6,minecraft:lava)
Block(-7,37,7,minecraft:lava)
Block(-7,37,8,minecraft:lava)
Block(-7,38,-7,minecraft:monster_egg:4)
Block(-7,38,-6,minecraft:lava)
Block(-7,38,-5,minecraft:lava)
Block(-7,38,-4,minecraft:lava)
Block(-7,38,-3,minecraft:lava)
Block(-7,38,-2,minecraft:lava)
Block(-7,38,-1,minecraft:lava)
Block(-7,38,0,minecraft:lava)
Block(-7,38,1,minecraft:lava)
Block(-7,38,2,minecraft:lava)
Block(-7,38,3,minecraft:lava)
Block(-7,38,4,minecraft:lava)
Block(-7,38,5,minecraft:lava)
Block(-7,38,6,minecraft:lava)
Block(-7,38,7,minecraft:lava)
Block(-7,38,8,minecraft:lava)
Block(-7,39,-7,minecraft:stonebrick)
Block(-7,39,-6,minecraft:lava)
Block(-7,39,-5,minecraft:lava)
Block(-7,39,-4,minecraft:lava)
Block(-7,39,-3,minecraft:lava)
Block(-7,39,-2,minecraft:lava)
Block(-7,39,-1,minecraft:lava)
Block(-7,39,0,minecraft:lava)
Block(-7,39,1,minecraft:lava)
Block(-7,39,2,minecraft:lava)
Block(-7,39,3,minecraft:lava)
Block(-7,39,4,minecraft:lava)
Block(-7,39,5,minecraft:lava)
Block(-7,39,6,minecraft:lava)
Block(-7,39,7,minecraft:lava)
Block(-7,39,8,minecraft:lava)
Block(-7,40,-7,minecraft:monster_egg:4)
Block(-7,40,-6,minecraft:lava)
Block(-7,40,-5,minecraft:lava)
Block(-7,40,-4,minecraft:lava)
Block(-7,40,-3,minecraft:lava)
Block(-7,40,-2,minecraft:lava)
Block(-7,40,-1,minecraft:lava)
Block(-7,40,0,minecraft:lava)
Block(-7,40,1,minecraft:lava)
Block(-7,40,2,minecraft:lava)
Block(-7,40,3,minecraft:lava)
Block(-7,40,4,minecraft:lava)
Block(-7,40,5,minecraft:lava)
Block(-7,40,6,minecraft:lava)
Block(-7,40,7,minecraft:lava)
Block(-7,40,8,minecraft:lava)
Block(-7,41,-7,minecraft:stonebrick)
Block(-7,41,-6,minecraft:lava)
Block(-7,41,-5,minecraft:lava)
Block(-7,41,-4,minecraft:lava)
Block(-7,41,-3,minecraft:lava)
Block(-7,41,-2,minecraft:lava)
Block(-7,41,-1,minecraft:lava)
Block(-7,41,0,minecraft:lava)
Block(-7,41,1,minecraft:lava)
Block(-7,41,2,minecraft:lava)
Block(-7,41,3,minecraft:lava)
Block(-7,41,4,minecraft:lava)
Block(-7,41,5,minecraft:lava)
Block(-7,41,6,minecraft:lava)
Block(-7,41,7,minecraft:lava)
Block(-7,41,8,minecraft:lava)
Block(-7,42,-7,minecraft:monster_egg:4)
Block(-7,42,-6,minecraft:lava)
Block(-7,42,-5,minecraft:lava)
Block(-7,42,-4,minecraft:lava)
Block(-7,42,-3,minecraft:lava)
Block(-7,42,-2,minecraft:lava)
Block(-7,42,-1,minecraft:lava)
Block(-7,42,0,minecraft:lava)
Block(-7,42,1,minecraft:lava)
Block(-7,42,2,minecraft:lava)
Block(-7,42,3,minecraft:lava)
Block(-7,42,4,minecraft:lava)
Block(-7,42,5,minecraft:lava)
Block(-7,42,6,minecraft:lava)
Block(-7,42,7,minecraft:lava)
Block(-7,42,8,minecraft:lava)
Block(-7,43,-7,minecraft:monster_egg:3)
Block(-7,43,-6,minecraft:lava)
Block(-7,43,-5,minecraft:lava)
Block(-7,43,-4,minecraft:lava)
Block(-7,43,-3,minecraft:lava)
Block(-7,43,-2,minecraft:lava)
Block(-7,43,-1,minecraft:lava)
Block(-7,43,0,minecraft:lava)
Block(-7,43,1,minecraft:lava)
Block(-7,43,2,minecraft:lava)
Block(-7,43,3,minecraft:lava)
Block(-7,43,4,minecraft:lava)
Block(-7,43,5,minecraft:lava)
Block(-7,43,6,minecraft:lava)
Block(-7,43,7,minecraft:lava)
Block(-7,43,8,minecraft:lava)
Block(-7,44,-7,minecraft:monster_egg:3)
Block(-7,44,-6,minecraft:monster_egg:4)
Block(-7,44,-5,minecraft:monster_egg:3)
Block(-7,44,-4,minecraft:monster_egg:3)
Block(-7,44,-3,minecraft:monster_egg:4)
Block(-7,44,-2,minecraft:stonebrick)
Block(-7,44,-1,minecraft:monster_egg:4)
Block(-7,44,0,minecraft:monster_egg:3)
Block(-7,44,1,minecraft:monster_egg:4)
Block(-7,44,2,minecraft:monster_egg:4)
Block(-7,44,3,minecraft:stonebrick)
Block(-7,44,4,minecraft:monster_egg:4)
Block(-7,44,5,minecraft:monster_egg:3)
Block(-7,44,6,minecraft:stonebrick)
Block(-7,44,7,minecraft:monster_egg:3)
Block(-7,44,8,minecraft:monster_egg:4)
Block(-6,1,-7,minecraft:monster_egg:3)
Block(-6,1,-6,minecraft:stonebrick)
Block(-6,1,-5,minecraft:stonebrick)
Block(-6,1,-4,minecraft:monster_egg:3)
Block(-6,1,-3,minecraft:stonebrick)
Block(-6,1,-2,minecraft:monster_egg:4)
Block(-6,1,-1,minecraft:monster_egg:4)
Block(-6,1,0,minecraft:stone_brick_stairs:1)
Block(-6,1,1,minecraft:monster_egg:4)
Block(-6,1,2,minecraft:stonebrick)
Block(-6,1,3,minecraft:monster_egg:4)
Block(-6,1,4,minecraft:monster_egg:3)
Block(-6,1,5,minecraft:stonebrick)
Block(-6,1,6,minecraft:stonebrick)
Block(-6,1,7,minecraft:monster_egg:3)
Block(-6,1,8,minecraft:stone_brick_stairs:1)
Block(-6,2,-7,minecraft:monster_egg:3)
Block(-6,2,-6,minecraft:stone_brick_stairs:1)
Block(-6,2,-5,minecraft:cobblestone_wall)
Block(-6,2,-4,minecraft:stone_slab)
Block(-6,2,-3,minecraft:cobblestone_wall)
Block(-6,2,-2,minecraft:stone_brick_stairs:1)
Block(-6,2,-1,minecraft:cobblestone_wall)
Block(-6,2,0,minecraft:stone_brick_stairs:5)
Block(-6,2,1,minecraft:cobblestone_wall)
Block(-6,2,2,minecraft:stone_brick_stairs:1)
Block(-6,2,3,minecraft:cobblestone_wall)
Block(-6,2,4,minecraft:stone_brick_stairs:1)
Block(-6,2,5,minecraft:cobblestone_wall)
Block(-6,2,6,minecraft:stone_brick_stairs:1)
Block(-6,2,7,minecraft:cobblestone_wall)
Block(-6,2,8,minecraft:air)
Block(-6,3,-7,minecraft:stone_brick_stairs)
Block(-6,3,-6,minecraft:cobblestone_wall)
Block(-6,3,-4,minecraft:air)
Block(-6,3,-2,minecraft:cobblestone_wall)
Block(-6,3,0,minecraft:stone_slab)
Block(-6,3,2,minecraft:cobblestone_wall)
Block(-6,3,4,minecraft:cobblestone_wall)
Block(-6,3,6,minecraft:cobblestone_wall)
Block(-6,3,8,minecraft:air)
Block(-6,4,-7,minecraft:obsidian)
Block(-6,4,-6,minecraft:stone_brick_stairs:5)
Block(-6,4,-5,minecraft:cobblestone_wall)
Block(-6,4,-4,minecraft:air)
Block(-6,4,-3,minecraft:air)
Block(-6,4,-1,minecraft:air)
Block(-6,4,0,minecraft:air)
Block(-6,4,1,minecraft:air)
Block(-6,4,3,minecraft:air)
Block(-6,4,4,minecraft:iron_bars)
Block(-6,4,5,minecraft:air)
Block(-6,4,7,minecraft:air)
Block(-6,4,8,minecraft:air)
Block(-6,5,-7,minecraft:stone_brick_stairs:7)
Block(-6,5,-6,minecraft:cobblestone_wall)
Block(-6,5,-4,minecraft:air)
Block(-6,5,-3,minecraft:air)
Block(-6,5,-2,minecraft:air)
Block(-6,5,-1,minecraft:air)
Block(-6,5,0,minecraft:air)
Block(-6,5,1,minecraft:air)
Block(-6,5,2,minecraft:air)
Block(-6,5,3,minecraft:air)
Block(-6,5,4,minecraft:cobblestone_wall)
Block(-6,5,5,minecraft:air)
Block(-6,5,6,minecraft:air)
Block(-6,5,7,minecraft:air)
Block(-6,5,8,minecraft:air)
Block(-6,6,-7,minecraft:stone_brick_stairs)
Block(-6,6,-5,minecraft:cobblestone_wall)
Block(-6,6,-4,minecraft:air)
Block(-6,6,-3,minecraft:iron_bars)
Block(-6,6,-2,minecraft:air)
Block(-6,6,-1,minecraft:air)
Block(-6,6,0,minecraft:air)
Block(-6,6,1,minecraft:air)
Block(-6,6,2,minecraft:air)
Block(-6,6,3,minecraft:air)
Block(-6,6,4,minecraft:iron_bars)
Block(-6,6,5,minecraft:air)
Block(-6,6,6,minecraft:air)
Block(-6,6,7,minecraft:air)
Block(-6,6,8,minecraft:air)
Block(-6,7,-7,minecraft:monster_egg:4)
Block(-6,7,-6,minecraft:stone_brick_stairs:5)
Block(-6,7,-5,minecraft:cobblestone_wall)
Block(-6,7,-4,minecraft:air)
Block(-6,7,-3,minecraft:iron_bars)
Block(-6,7,-2,minecraft:stone_brick_stairs:5)
Block(-6,7,-1,minecraft:air)
Block(-6,7,0,minecraft:air)
Block(-6,7,1,minecraft:air)
Block(-6,7,2,minecraft:stone_brick_stairs:5)
Block(-6,7,3,minecraft:air)
Block(-6,7,4,minecraft:stone_slab)
Block(-6,7,5,minecraft:air)
Block(-6,7,6,minecraft:stone_brick_stairs:5)
Block(-6,7,7,minecraft:air)
Block(-6,7,8,minecraft:air)
Block(-6,8,-7,minecraft:monster_egg:4)
Block(-6,8,-6,minecraft:stone_slab:5)
Block(-6,8,-5,minecraft:stonebrick)
Block(-6,8,-4,minecraft:air)
Block(-6,8,-3,minecraft:iron_bars)
Block(-6,8,-2,minecraft:stone_slab:5)
Block(-6,8,-1,minecraft:air)
Block(-6,8,0,minecraft:air)
Block(-6,8,1,minecraft:air)
Block(-6,8,2,minecraft:stone_slab:5)
Block(-6,8,3,minecraft:stone_slab:8)
Block(-6,8,4,minecraft:air)
Block(-6,8,5,minecraft:stone_slab:8)
Block(-6,8,6,minecraft:stone_slab:5)
Block(-6,8,7,minecraft:air)
Block(-6,8,8,minecraft:air)
Block(-6,9,-7,minecraft:stonebrick)
Block(-6,9,-6,minecraft:stone_slab:8)
Block(-6,9,-5,minecraft:cobblestone_wall)
Block(-6,9,-4,minecraft:stone_slab)
Block(-6,9,-3,minecraft:stone_slab:5)
Block(-6,9,-2,minecraft:stone_slab:5)
Block(-6,9,-1,minecraft:stone_brick_stairs:5)
Block(-6,9,0,minecraft:stone_slab:8)
Block(-6,9,1,minecraft:stone_brick_stairs:5)
Block(-6,9,2,minecraft:double_stone_slab:5)
Block(-6,9,3,minecraft:stone_brick_stairs:0)
Block(-6,9,4,minecraft:air)
Block(-6,9,5,minecraft:stone_brick_stairs:0)
Block(-6,9,6,minecraft:double_stone_slab:5)
Block(-6,9,7,minecraft:air)
Block(-6,9,8,minecraft:air)
Block(-6,10,-7,minecraft:monster_egg:3)
Block(-6,10,-6,minecraft:stone_slab:8)
Block(-6,10,-5,minecraft:cauldron)
Block(-6,10,-4,minecraft:stone_slab:8)
Block(-6,10,-3,minecraft:stone_slab:8)
Block(-6,10,-2,minecraft:stone_slab:8)
Block(-6,10,-1,minecraft:stone_slab:8)
Block(-6,10,0,minecraft:stone_slab:8)
Block(-6,10,1,minecraft:stone_slab:8)
Block(-6,10,2,minecraft:double_stone_slab)
Block(-6,10,3,minecraft:air)
Block(-6,10,4,minecraft:air)
Block(-6,10,5,minecraft:air)
Block(-6,10,6,minecraft:double_stone_slab)
Block(-6,10,7,minecraft:stone_brick_stairs:5)
Block(-6,10,8,minecraft:stone_slab:8)
Block(-6,11,-7,minecraft:stonebrick)
Block(-6,11,-6,minecraft:cauldron)
Block(-6,11,-5,minecraft:air)
Block(-6,11,-4,minecraft:air)
Block(-6,11,-3,minecraft:air)
Block(-6,11,-2,minecraft:vine:2)
Block(-6,11,-1,minecraft:air)
Block(-6,11,0,minecraft:cauldron)
Block(-6,11,1,minecraft:monster_egg:3)
Block(-6,11,2,minecraft:double_stone_slab)
Block(-6,11,3,minecraft:air)
Block(-6,11,4,minecraft:air)
Block(-6,11,5,minecraft:air)
Block(-6,11,6,minecraft:double_stone_slab)
Block(-6,11,7,minecraft:stone_slab:8)
Block(-6,12,-7,minecraft:monster_egg:3)
Block(-6,12,-6,minecraft:stone_brick_stairs:5)
Block(-6,12,-5,minecraft:air)
Block(-6,12,-4,minecraft:air)
Block(-6,12,-3,minecraft:air)
Block(-6,12,-2,minecraft:ladder:5)
Block(-6,12,-1,minecraft:air)
Block(-6,12,0,minecraft:air)
Block(-6,12,1,minecraft:monster_egg:3)
Block(-6,12,2,minecraft:stone_brick_stairs)
Block(-6,12,3,minecraft:air)
Block(-6,12,4,minecraft:air)
Block(-6,12,5,minecraft:air)
Block(-6,12,6,minecraft:stone_brick_stairs:2)
Block(-6,12,7,minecraft:double_stone_slab)
Block(-6,12,8,minecraft:double_stone_slab)
Block(-6,13,-7,minecraft:monster_egg:3)
Block(-6,13,-6,minecraft:cobblestone_wall)
Block(-6,13,-5,minecraft:vine)
Block(-6,13,-4,minecraft:air)
Block(-6,13,-3,minecraft:air)
Block(-6,13,-2,minecraft:ladder:5)
Block(-6,13,-1,minecraft:air)
Block(-6,13,0,minecraft:stone_brick_stairs:6)
Block(-6,13,1,minecraft:stonebrick)
Block(-6,13,2,minecraft:stone_brick_stairs:7)
Block(-6,13,3,minecraft:stone_slab:8)
Block(-6,13,4,minecraft:stone_slab:8)
Block(-6,13,5,minecraft:stone_slab:8)
Block(-6,13,6,minecraft:stone_brick_stairs:6)
Block(-6,13,7,minecraft:monster_egg:3)
Block(-6,13,8,minecraft:double_stone_slab)
Block(-6,14,-7,minecraft:stonebrick)
Block(-6,14,-5,minecraft:air)
Block(-6,14,-4,minecraft:vine)
Block(-6,14,-3,minecraft:air)
Block(-6,14,-2,minecraft:ladder:5)
Block(-6,14,-1,minecraft:stone_brick_stairs:6)
Block(-6,14,0,minecraft:monster_egg:3)
Block(-6,14,1,minecraft:monster_egg:3)
Block(-6,14,2,minecraft:stone_slab)
Block(-6,14,3,minecraft:stone_slab)
Block(-6,14,4,minecraft:stone_slab)
Block(-6,14,5,minecraft:stone_slab)
Block(-6,14,6,minecraft:double_stone_slab)
Block(-6,14,7,minecraft:monster_egg:3)
Block(-6,14,8,minecraft:cobblestone_wall)
Block(-6,15,-7,minecraft:monster_egg:3)
Block(-6,15,-6,minecraft:cobblestone_wall)
Block(-6,15,-5,minecraft:air)
Block(-6,15,-4,minecraft:air)
Block(-6,15,-3,minecraft:stone_brick_stairs:6)
Block(-6,15,-2,minecraft:monster_egg:4)
Block(-6,15,-1,minecraft:stonebrick)
Block(-6,15,0,minecraft:monster_egg:3)
Block(-6,15,1,minecraft:monster_egg:3)
Block(-6,15,2,minecraft:air)
Block(-6,15,3,minecraft:air)
Block(-6,15,4,minecraft:air)
Block(-6,15,5,minecraft:air)
Block(-6,15,6,minecraft:monster_egg:3)
Block(-6,15,7,minecraft:monster_egg:3)
Block(-6,16,-7,minecraft:monster_egg:3)
Block(-6,16,-6,minecraft:stonebrick)
Block(-6,16,-5,minecraft:monster_egg:3)
Block(-6,16,-4,minecraft:stonebrick)
Block(-6,16,-3,minecraft:monster_egg:3)
Block(-6,16,-2,minecraft:stonebrick)
Block(-6,16,-1,minecraft:monster_egg:3)
Block(-6,16,0,minecraft:monster_egg:3)
Block(-6,16,1,minecraft:stone_brick_stairs)
Block(-6,16,2,minecraft:air)
Block(-6,16,3,minecraft:air)
Block(-6,16,4,minecraft:air)
Block(-6,16,5,minecraft:air)
Block(-6,16,6,minecraft:stone_brick_stairs:2)
Block(-6,16,7,minecraft:monster_egg:3)
Block(-6,16,8,minecraft:air)
Block(-6,17,-7,minecraft:monster_egg:4)
Block(-6,17,-5,minecraft:monster_egg:4)
Block(-6,17,-3,minecraft:cobblestone_wall)
Block(-6,17,-2,minecraft:monster_egg:4)
Block(-6,17,-1,minecraft:stonebrick)
Block(-6,17,0,minecraft:stone_brick_stairs)
Block(-6,17,1,minecraft:air)
Block(-6,17,2,minecraft:air)
Block(-6,17,3,minecraft:air)
Block(-6,17,4,minecraft:air)
Block(-6,17,5,minecraft:air)
Block(-6,17,6,minecraft:air)
Block(-6,17,7,minecraft:monster_egg:3)
Block(-6,17,8,minecraft:air)
Block(-6,18,-7,minecraft:monster_egg:3)
Block(-6,18,-6,minecraft:air)
Block(-6,18,-5,minecraft:monster_egg:3)
Block(-6,18,-4,minecraft:air)
Block(-6,18,-2,minecraft:monster_egg:4)
Block(-6,18,-1,minecraft:cobblestone_wall)
Block(-6,18,0,minecraft:air)
Block(-6,18,1,minecraft:air)
Block(-6,18,2,minecraft:air)
Block(-6,18,3,minecraft:air)
Block(-6,18,4,minecraft:air)
Block(-6,18,5,minecraft:air)
Block(-6,18,6,minecraft:air)
Block(-6,18,7,minecraft:monster_egg:3)
Block(-6,18,8,minecraft:air)
Block(-6,19,-7,minecraft:monster_egg:3)
Block(-6,19,-6,minecraft:cobblestone_wall)
Block(-6,19,-5,minecraft:monster_egg:3)
Block(-6,19,-4,minecraft:stone_brick_stairs:7)
Block(-6,19,-3,minecraft:stone_brick_stairs:6)
Block(-6,19,-2,minecraft:monster_egg:3)
Block(-6,19,-1,minecraft:cobblestone_wall)
Block(-6,19,0,minecraft:air)
Block(-6,19,1,minecraft:air)
Block(-6,19,2,minecraft:air)
Block(-6,19,3,minecraft:air)
Block(-6,19,4,minecraft:air)
Block(-6,19,5,minecraft:air)
Block(-6,19,6,minecraft:air)
Block(-6,19,7,minecraft:monster_egg:4)
Block(-6,19,8,minecraft:air)
Block(-6,20,-7,minecraft:stonebrick)
Block(-6,20,-6,minecraft:stone_brick_stairs:7)
Block(-6,20,-5,minecraft:double_stone_slab)
Block(-6,20,-4,minecraft:double_stone_slab)
Block(-6,20,-3,minecraft:double_stone_slab)
Block(-6,20,-2,minecraft:double_stone_slab)
Block(-6,20,-1,minecraft:double_stone_slab)
Block(-6,20,0,minecraft:air)
Block(-6,20,1,minecraft:air)
Block(-6,20,2,minecraft:air)
Block(-6,20,3,minecraft:air)
Block(-6,20,4,minecraft:air)
Block(-6,20,5,minecraft:air)
Block(-6,20,6,minecraft:stone_brick_stairs:6)
Block(-6,20,7,minecraft:monster_egg:3)
Block(-6,20,8,minecraft:stone_brick_stairs:7)
Block(-6,21,-7,minecraft:stonebrick)
Block(-6,21,-6,minecraft:monster_egg:4)
Block(-6,21,-5,minecraft:monster_egg:3)
Block(-6,21,-4,minecraft:monster_egg:3)
Block(-6,21,-3,minecraft:monster_egg:4)
Block(-6,21,-2,minecraft:monster_egg:4)
Block(-6,21,-1,minecraft:stonebrick)
Block(-6,21,0,minecraft:double_stone_slab)
Block(-6,21,1,minecraft:monster_egg:3)
Block(-6,21,2,minecraft:stone_slab:8)
Block(-6,21,3,minecraft:stonebrick)
Block(-6,21,4,minecraft:monster_egg:3)
Block(-6,21,5,minecraft:monster_egg:3)
Block(-6,21,6,minecraft:stonebrick)
Block(-6,21,7,minecraft:stonebrick)
Block(-6,21,8,minecraft:monster_egg:3)
Block(-6,22,-7,minecraft:monster_egg:4)
Block(-6,22,-6,minecraft:monster_egg:4)
Block(-6,22,-5,minecraft:monster_egg:3)
Block(-6,22,-4,minecraft:monster_egg:3)
Block(-6,22,-3,minecraft:monster_egg:4)
Block(-6,22,-2,minecraft:monster_egg:4)
Block(-6,22,-1,minecraft:monster_egg:3)
Block(-6,22,0,minecraft:monster_egg:3)
Block(-6,22,1,minecraft:monster_egg:3)
Block(-6,22,2,minecraft:monster_egg:3)
Block(-6,22,3,minecraft:stonebrick)
Block(-6,22,4,minecraft:monster_egg:3)
Block(-6,22,5,minecraft:monster_egg:3)
Block(-6,22,6,minecraft:stonebrick)
Block(-6,22,7,minecraft:monster_egg:3)
Block(-6,22,8,minecraft:monster_egg:3)
Block(-6,23,-7,minecraft:monster_egg:3)
Block(-6,23,-6,minecraft:lava)
Block(-6,23,-5,minecraft:monster_egg:3)
Block(-6,23,-4,minecraft:monster_egg:3)
Block(-6,23,-3,minecraft:monster_egg:3)
Block(-6,23,-2,minecraft:monster_egg:3)
Block(-6,23,-1,minecraft:monster_egg:3)
Block(-6,23,0,minecraft:stonebrick)
Block(-6,23,1,minecraft:stonebrick)
Block(-6,23,2,minecraft:monster_egg:3)
Block(-6,23,3,minecraft:monster_egg:4)
Block(-6,23,4,minecraft:monster_egg:3)
Block(-6,23,5,minecraft:monster_egg:3)
Block(-6,23,6,minecraft:stonebrick)
Block(-6,23,7,minecraft:monster_egg:3)
Block(-6,23,8,minecraft:monster_egg:3)
Block(-6,24,-7,minecraft:monster_egg:3)
Block(-6,24,-6,minecraft:lava)
Block(-6,24,-5,minecraft:monster_egg:3)
Block(-6,24,-4,minecraft:monster_egg:4)
Block(-6,24,-3,minecraft:stonebrick)
Block(-6,24,-2,minecraft:monster_egg:3)
Block(-6,24,-1,minecraft:monster_egg:3)
Block(-6,24,0,minecraft:monster_egg:3)
Block(-6,24,1,minecraft:iron_bars)
Block(-6,24,2,minecraft:monster_egg:3)
Block(-6,24,7,minecraft:stone_brick_stairs:1)
Block(-6,24,8,minecraft:stone_brick_stairs:1)
Block(-6,25,-7,minecraft:monster_egg:3)
Block(-6,25,-6,minecraft:lava)
Block(-6,25,-5,minecraft:monster_egg:4)
Block(-6,25,-4,minecraft:monster_egg:4)
Block(-6,25,-3,minecraft:monster_egg:4)
Block(-6,25,-2,minecraft:monster_egg:3)
Block(-6,25,-1,minecraft:stonebrick)
Block(-6,25,0,minecraft:monster_egg:3)
Block(-6,25,1,minecraft:iron_bars)
Block(-6,25,2,minecraft:monster_egg:3)
Block(-6,25,3,minecraft:monster_egg:3)
Block(-6,25,4,minecraft:monster_egg:3)
Block(-6,25,5,minecraft:monster_egg:3)
Block(-6,25,6,minecraft:monster_egg:4)
Block(-6,25,7,minecraft:stone_brick_stairs:5)
Block(-6,25,8,minecraft:stone_brick_stairs:5)
Block(-6,26,-7,minecraft:stonebrick)
Block(-6,26,-6,minecraft:lava)
Block(-6,26,-5,minecraft:monster_egg:3)
Block(-6,26,-4,minecraft:monster_egg:4)
Block(-6,26,-3,minecraft:stonebrick)
Block(-6,26,-2,minecraft:stonebrick)
Block(-6,26,-1,minecraft:monster_egg:3)
Block(-6,26,0,minecraft:stonebrick)
Block(-6,26,1,minecraft:monster_egg:3)
Block(-6,26,2,minecraft:stonebrick)
Block(-6,26,3,minecraft:monster_egg:3)
Block(-6,26,4,minecraft:monster_egg:3)
Block(-6,26,5,minecraft:monster_egg:3)
Block(-6,26,6,minecraft:monster_egg:3)
Block(-6,26,7,minecraft:stonebrick)
Block(-6,26,8,minecraft:monster_egg:3)
Block(-6,27,-7,minecraft:monster_egg:4)
Block(-6,27,-6,minecraft:lava)
Block(-6,27,-5,minecraft:monster_egg:3)
Block(-6,27,-4,minecraft:monster_egg:3)
Block(-6,27,-3,minecraft:monster_egg:3)
Block(-6,27,-2,minecraft:monster_egg:3)
Block(-6,27,-1,minecraft:stonebrick)
Block(-6,27,0,minecraft:monster_egg:4)
Block(-6,27,1,minecraft:monster_egg:4)
Block(-6,27,2,minecraft:monster_egg:4)
Block(-6,27,3,minecraft:monster_egg:4)
Block(-6,27,4,minecraft:monster_egg:4)
Block(-6,27,5,minecraft:monster_egg:3)
Block(-6,27,6,minecraft:stonebrick)
Block(-6,27,7,minecraft:stonebrick)
Block(-6,27,8,minecraft:iron_bars)
Block(-6,28,-7,minecraft:monster_egg:3)
Block(-6,28,-6,minecraft:lava)
Block(-6,28,-5,minecraft:monster_egg:3)
Block(-6,28,-4,minecraft:monster_egg:3)
Block(-6,28,-3,minecraft:monster_egg:3)
Block(-6,28,-2,minecraft:monster_egg:4)
Block(-6,28,-1,minecraft:monster_egg:3)
Block(-6,28,0,minecraft:monster_egg:4)
Block(-6,28,1,minecraft:monster_egg:3)
Block(-6,28,2,minecraft:monster_egg:3)
Block(-6,28,3,minecraft:monster_egg:4)
Block(-6,28,4,minecraft:monster_egg:4)
Block(-6,28,5,minecraft:monster_egg:4)
Block(-6,28,6,minecraft:monster_egg:3)
Block(-6,28,7,minecraft:monster_egg:3)
Block(-6,28,8,minecraft:iron_bars)
Block(-6,29,-7,minecraft:monster_egg:3)
Block(-6,29,-6,minecraft:lava)
Block(-6,29,-5,minecraft:monster_egg:3)
Block(-6,29,-4,minecraft:stonebrick)
Block(-6,29,-3,minecraft:monster_egg:4)
Block(-6,29,-2,minecraft:monster_egg:3)
Block(-6,29,-1,minecraft:stonebrick)
Block(-6,29,0,minecraft:stonebrick)
Block(-6,29,1,minecraft:stonebrick)
Block(-6,29,2,minecraft:monster_egg:3)
Block(-6,29,3,minecraft:stonebrick)
Block(-6,29,4,minecraft:monster_egg:4)
Block(-6,29,5,minecraft:stonebrick)
Block(-6,29,6,minecraft:stonebrick)
Block(-6,29,7,minecraft:monster_egg:4)
Block(-6,29,8,minecraft:monster_egg:3)
Block(-6,30,-7,minecraft:monster_egg:4)
Block(-6,30,-6,minecraft:lava)
Block(-6,30,-5,minecraft:monster_egg:3)
Block(-6,30,-4,minecraft:monster_egg:3)
Block(-6,30,-3,minecraft:monster_egg:3)
Block(-6,30,-2,minecraft:monster_egg:3)
Block(-6,30,-1,minecraft:monster_egg:3)
Block(-6,30,0,minecraft:monster_egg:3)
Block(-6,30,1,minecraft:monster_egg:4)
Block(-6,30,2,minecraft:stonebrick)
Block(-6,30,3,minecraft:monster_egg:3)
Block(-6,30,4,minecraft:monster_egg:4)
Block(-6,30,5,minecraft:monster_egg:3)
Block(-6,30,6,minecraft:monster_egg:3)
Block(-6,30,7,minecraft:monster_egg:4)
Block(-6,30,8,minecraft:monster_egg:3)
Block(-6,31,-7,minecraft:monster_egg:3)
Block(-6,31,-6,minecraft:lava)
Block(-6,31,-5,minecraft:monster_egg:3)
Block(-6,31,-4,minecraft:monster_egg:3)
Block(-6,31,-3,minecraft:monster_egg:3)
Block(-6,31,-2,minecraft:monster_egg:4)
Block(-6,31,-1,minecraft:monster_egg:3)
Block(-6,31,0,minecraft:stonebrick)
Block(-6,31,1,minecraft:monster_egg:3)
Block(-6,31,2,minecraft:monster_egg:3)
Block(-6,31,3,minecraft:monster_egg:3)
Block(-6,31,4,minecraft:monster_egg:3)
Block(-6,31,5,minecraft:monster_egg:3)
Block(-6,31,6,minecraft:monster_egg:3)
Block(-6,31,7,minecraft:stonebrick)
Block(-6,31,8,minecraft:monster_egg:3)
Block(-6,32,-7,minecraft:monster_egg:3)
Block(-6,32,-6,minecraft:lava)
Block(-6,32,-5,minecraft:monster_egg:4)
Block(-6,32,-4,minecraft:stonebrick)
Block(-6,32,-3,minecraft:stonebrick)
Block(-6,32,-2,minecraft:monster_egg:4)
Block(-6,32,-1,minecraft:monster_egg:4)
Block(-6,32,0,minecraft:monster_egg:3)
Block(-6,32,1,minecraft:stonebrick)
Block(-6,32,2,minecraft:stonebrick)
Block(-6,32,3,minecraft:monster_egg:3)
Block(-6,32,4,minecraft:stonebrick)
Block(-6,32,5,minecraft:stonebrick)
Block(-6,32,6,minecraft:monster_egg:3)
Block(-6,32,7,minecraft:monster_egg:4)
Block(-6,32,8,minecraft:stonebrick)
Block(-6,33,-7,minecraft:monster_egg:3)
Block(-6,33,-6,minecraft:lava)
Block(-6,33,-5,minecraft:monster_egg:3)
Block(-6,33,-4,minecraft:monster_egg:3)
Block(-6,33,-3,minecraft:monster_egg:4)
Block(-6,33,-2,minecraft:monster_egg:3)
Block(-6,33,-1,minecraft:monster_egg:4)
Block(-6,33,0,minecraft:monster_egg:4)
Block(-6,33,1,minecraft:monster_egg:4)
Block(-6,33,2,minecraft:monster_egg:3)
Block(-6,33,3,minecraft:monster_egg:3)
Block(-6,33,4,minecraft:monster_egg:3)
Block(-6,33,5,minecraft:monster_egg:4)
Block(-6,33,6,minecraft:monster_egg:4)
Block(-6,33,7,minecraft:stonebrick)
Block(-6,33,8,minecraft:stonebrick)
Block(-6,34,-7,minecraft:stonebrick)
Block(-6,34,-6,minecraft:lava)
Block(-6,34,-5,minecraft:monster_egg:3)
Block(-6,34,-4,minecraft:stonebrick)
Block(-6,34,-3,minecraft:stonebrick)
Block(-6,34,-2,minecraft:monster_egg:4)
Block(-6,34,-1,minecraft:stonebrick)
Block(-6,34,0,minecraft:monster_egg:3)
Block(-6,34,1,minecraft:stonebrick)
Block(-6,34,2,minecraft:monster_egg:3)
Block(-6,34,3,minecraft:monster_egg:4)
Block(-6,34,4,minecraft:stonebrick)
Block(-6,34,5,minecraft:monster_egg:3)
Block(-6,34,6,minecraft:monster_egg:4)
Block(-6,34,7,minecraft:monster_egg:3)
Block(-6,34,8,minecraft:monster_egg:4)
Block(-6,35,-7,minecraft:monster_egg:3)
Block(-6,35,-6,minecraft:lava)
Block(-6,35,-5,minecraft:monster_egg:3)
Block(-6,35,-4,minecraft:monster_egg:3)
Block(-6,35,-3,minecraft:monster_egg:3)
Block(-6,35,-2,minecraft:monster_egg:3)
Block(-6,35,-1,minecraft:monster_egg:3)
Block(-6,35,0,minecraft:monster_egg:4)
Block(-6,35,1,minecraft:monster_egg:4)
Block(-6,35,2,minecraft:monster_egg:3)
Block(-6,35,3,minecraft:monster_egg:4)
Block(-6,35,4,minecraft:stonebrick)
Block(-6,35,5,minecraft:monster_egg:3)
Block(-6,35,6,minecraft:monster_egg:3)
Block(-6,35,7,minecraft:monster_egg:4)
Block(-6,35,8,minecraft:monster_egg:4)
Block(-6,36,-7,minecraft:monster_egg:4)
Block(-6,36,-6,minecraft:lava)
Block(-6,36,-5,minecraft:monster_egg:4)
Block(-6,36,-4,minecraft:monster_egg:3)
Block(-6,36,-3,minecraft:monster_egg:3)
Block(-6,36,-2,minecraft:monster_egg:4)
Block(-6,36,-1,minecraft:monster_egg:4)
Block(-6,36,0,minecraft:stonebrick)
Block(-6,36,1,minecraft:monster_egg:4)
Block(-6,36,2,minecraft:stone_brick_stairs)
Block(-6,36,3,minecraft:stone_slab)
Block(-6,36,4,minecraft:stone_brick_stairs:2)
Block(-6,36,5,minecraft:stonebrick)
Block(-6,36,6,minecraft:monster_egg:3)
Block(-6,36,7,minecraft:stonebrick)
Block(-6,36,8,minecraft:monster_egg:3)
Block(-6,37,-7,minecraft:stonebrick)
Block(-6,37,-6,minecraft:lava)
Block(-6,37,-5,minecraft:monster_egg:3)
Block(-6,37,-4,minecraft:stonebrick)
Block(-6,37,-3,minecraft:monster_egg:3)
Block(-6,37,-2,minecraft:stonebrick)
Block(-6,37,-1,minecraft:monster_egg:4)
Block(-6,37,0,minecraft:stonebrick)
Block(-6,37,1,minecraft:monster_egg:3)
Block(-6,37,2,minecraft:stone_brick_stairs:7)
Block(-6,37,3,minecraft:stone_slab:8)
Block(-6,37,4,minecraft:stone_brick_stairs:6)
Block(-6,37,5,minecraft:monster_egg:3)
Block(-6,37,6,minecraft:monster_egg:3)
Block(-6,37,7,minecraft:monster_egg:3)
Block(-6,37,8,minecraft:monster_egg:3)
Block(-6,38,-7,minecraft:monster_egg:4)
Block(-6,38,-6,minecraft:lava)
Block(-6,38,-5,minecraft:stonebrick)
Block(-6,38,-4,minecraft:monster_egg:3)
Block(-6,38,-3,minecraft:monster_egg:3)
Block(-6,38,-2,minecraft:monster_egg:4)
Block(-6,38,-1,minecraft:monster_egg:3)
Block(-6,38,0,minecraft:monster_egg:3)
Block(-6,38,1,minecraft:monster_egg:3)
Block(-6,38,2,minecraft:monster_egg:3)
Block(-6,38,3,minecraft:monster_egg:3)
Block(-6,38,4,minecraft:stonebrick)
Block(-6,38,5,minecraft:monster_egg:3)
Block(-6,38,6,minecraft:monster_egg:4)
Block(-6,38,7,minecraft:monster_egg:3)
Block(-6,38,8,minecraft:monster_egg:4)
Block(-6,39,-7,minecraft:monster_egg:3)
Block(-6,39,-6,minecraft:lava)
Block(-6,39,-5,minecraft:monster_egg:4)
Block(-6,39,-4,minecraft:monster_egg:4)
Block(-6,39,-3,minecraft:monster_egg:3)
Block(-6,39,-2,minecraft:stonebrick)
Block(-6,39,-1,minecraft:stonebrick)
Block(-6,39,0,minecraft:monster_egg:4)
Block(-6,39,1,minecraft:monster_egg:3)
Block(-6,39,2,minecraft:monster_egg:3)
Block(-6,39,3,minecraft:monster_egg:3)
Block(-6,39,4,minecraft:monster_egg:4)
Block(-6,39,5,minecraft:monster_egg:4)
Block(-6,39,6,minecraft:monster_egg:3)
Block(-6,39,7,minecraft:monster_egg:3)
Block(-6,39,8,minecraft:monster_egg:4)
Block(-6,40,-7,minecraft:monster_egg:3)
Block(-6,40,-6,minecraft:lava)
Block(-6,40,-5,minecraft:monster_egg:4)
Block(-6,40,-4,minecraft:stonebrick)
Block(-6,40,-3,minecraft:monster_egg:3)
Block(-6,40,-2,minecraft:monster_egg:4)
Block(-6,40,-1,minecraft:monster_egg:3)
Block(-6,40,0,minecraft:monster_egg:3)
Block(-6,40,1,minecraft:stonebrick)
Block(-6,40,2,minecraft:monster_egg:3)
Block(-6,40,3,minecraft:monster_egg:4)
Block(-6,40,4,minecraft:monster_egg:4)
Block(-6,40,5,minecraft:monster_egg:3)
Block(-6,40,6,minecraft:stonebrick)
Block(-6,40,7,minecraft:monster_egg:3)
Block(-6,40,8,minecraft:monster_egg:3)
Block(-6,41,-7,minecraft:monster_egg:3)
Block(-6,41,-6,minecraft:lava)
Block(-6,41,-5,minecraft:monster_egg:4)
Block(-6,41,-4,minecraft:monster_egg:3)
Block(-6,41,-3,minecraft:stonebrick)
Block(-6,41,-2,minecraft:monster_egg:4)
Block(-6,41,-1,minecraft:stonebrick)
Block(-6,41,0,minecraft:monster_egg:4)
Block(-6,41,1,minecraft:monster_egg:4)
Block(-6,41,2,minecraft:monster_egg:3)
Block(-6,41,3,minecraft:monster_egg:3)
Block(-6,41,4,minecraft:monster_egg:3)
Block(-6,41,5,minecraft:stonebrick)
Block(-6,41,6,minecraft:monster_egg:3)
Block(-6,41,7,minecraft:stonebrick)
Block(-6,41,8,minecraft:stonebrick)
Block(-6,42,-7,minecraft:monster_egg:3)
Block(-6,42,-6,minecraft:lava)
Block(-6,42,-5,minecraft:monster_egg:4)
Block(-6,42,-4,minecraft:monster_egg:3)
Block(-6,42,-3,minecraft:stonebrick)
Block(-6,42,-2,minecraft:stonebrick)
Block(-6,42,-1,minecraft:monster_egg:3)
Block(-6,42,0,minecraft:monster_egg:4)
Block(-6,42,1,minecraft:monster_egg:3)
Block(-6,42,2,minecraft:monster_egg:3)
Block(-6,42,3,minecraft:monster_egg:3)
Block(-6,42,4,minecraft:monster_egg:3)
Block(-6,42,5,minecraft:monster_egg:3)
Block(-6,42,6,minecraft:monster_egg:4)
Block(-6,42,7,minecraft:monster_egg:4)
Block(-6,42,8,minecraft:monster_egg:3)
Block(-6,43,-7,minecraft:monster_egg:4)
Block(-6,43,-6,minecraft:lava)
Block(-6,43,-5,minecraft:lava)
Block(-6,43,-4,minecraft:lava)
Block(-6,43,-3,minecraft:lava)
Block(-6,43,-2,minecraft:lava)
Block(-6,43,-1,minecraft:lava)
Block(-6,43,0,minecraft:lava)
Block(-6,43,1,minecraft:lava)
Block(-6,43,2,minecraft:lava)
Block(-6,43,3,minecraft:lava)
Block(-6,43,4,minecraft:lava)
Block(-6,43,5,minecraft:lava)
Block(-6,43,6,minecraft:lava)
Block(-6,43,7,minecraft:lava)
Block(-6,43,8,minecraft:lava)
Block(-6,44,-7,minecraft:monster_egg:3)
Block(-6,44,-6,minecraft:monster_egg:3)
Block(-6,44,-5,minecraft:stonebrick)
Block(-6,44,-4,minecraft:monster_egg:3)
Block(-6,44,-3,minecraft:monster_egg:3)
Block(-6,44,-2,minecraft:monster_egg:3)
Block(-6,44,-1,minecraft:monster_egg:3)
Block(-6,44,0,minecraft:monster_egg:4)
Block(-6,44,1,minecraft:monster_egg:3)
Block(-6,44,2,minecraft:monster_egg:4)
Block(-6,44,3,minecraft:stonebrick)
Block(-6,44,4,minecraft:monster_egg:3)
Block(-6,44,5,minecraft:monster_egg:3)
Block(-6,44,6,minecraft:monster_egg:3)
Block(-6,44,7,minecraft:monster_egg:3)
Block(-6,44,8,minecraft:monster_egg:3)
Block(-6,57,-2,minecraft:air)
Block(-6,61,-2,minecraft:air)
Block(-6,61,-1,minecraft:air)
Block(-6,61,0,minecraft:air)
Block(-6,62,-1,minecraft:air)
Block(-6,62,0,minecraft:air)
Block(-6,63,-1,minecraft:air)
Block(-6,63,0,minecraft:air)
Block(-6,63,1,minecraft:air)
Block(-6,63,2,minecraft:air)
Block(-5,1,-7,minecraft:monster_egg:4)
Block(-5,1,-6,minecraft:stonebrick)
Block(-5,1,-5,minecraft:monster_egg:4)
Block(-5,1,-4,minecraft:monster_egg:3)
Block(-5,1,-3,minecraft:stone_slab:5)
Block(-5,1,-2,minecraft:stone_slab:5)
Block(-5,1,-1,minecraft:stone_slab:5)
Block(-5,1,0,minecraft:stone_slab)
Block(-5,1,1,minecraft:double_stone_slab)
Block(-5,1,2,minecraft:double_stone_slab)
Block(-5,1,3,minecraft:stonebrick)
Block(-5,1,4,minecraft:monster_egg:3)
Block(-5,1,5,minecraft:monster_egg:3)
Block(-5,1,6,minecraft:monster_egg:3)
Block(-5,1,7,minecraft:monster_egg:3)
Block(-5,1,8,minecraft:stone_slab)
Block(-5,2,-7,minecraft:stone_brick_stairs)
Block(-5,2,-6,minecraft:anvil:8)
Block(-5,2,-5,minecraft:stone_slab)
Block(-5,2,-4,minecraft:cobblestone_wall)
Block(-5,2,-3,minecraft:air)
Block(-5,2,-2,minecraft:air)
Block(-5,2,-1,minecraft:air)
Block(-5,2,0,minecraft:air)
Block(-5,2,1,minecraft:air)
Block(-5,2,2,minecraft:air)
Block(-5,2,3,minecraft:air)
Block(-5,2,4,minecraft:air)
Block(-5,2,5,minecraft:air)
Block(-5,2,6,minecraft:air)
Block(-5,2,7,minecraft:air)
Block(-5,2,8,minecraft:air)
Block(-5,3,-7,minecraft:stone_brick_stairs:7)
Block(-5,3,-5,minecraft:vine)
Block(-5,3,-4,minecraft:iron_bars)
Block(-5,3,-3,minecraft:air)
Block(-5,3,-2,minecraft:iron_bars)
Block(-5,3,-1,minecraft:air)
Block(-5,3,0,minecraft:air)
Block(-5,3,1,minecraft:air)
Block(-5,3,2,minecraft:air)
Block(-5,3,3,minecraft:air)
Block(-5,3,4,minecraft:air)
Block(-5,3,5,minecraft:air)
Block(-5,3,6,minecraft:air)
Block(-5,3,7,minecraft:air)
Block(-5,3,8,minecraft:air)
Block(-5,4,-7,minecraft:obsidian)
Block(-5,4,-6,minecraft:cobblestone_wall)
Block(-5,4,-5,minecraft:air)
Block(-5,4,-4,minecraft:iron_bars)
Block(-5,4,-3,minecraft:air)
Block(-5,4,-2,minecraft:iron_bars)
Block(-5,4,-1,minecraft:air)
Block(-5,4,0,minecraft:air)
Block(-5,4,1,minecraft:air)
Block(-5,4,2,minecraft:air)
Block(-5,4,3,minecraft:air)
Block(-5,4,4,minecraft:air)
Block(-5,4,5,minecraft:air)
Block(-5,4,6,minecraft:air)
Block(-5,4,7,minecraft:air)
Block(-5,4,8,minecraft:air)
Block(-5,5,-7,minecraft:stone_brick_stairs)
Block(-5,5,-5,minecraft:air)
Block(-5,5,-4,minecraft:air)
Block(-5,5,-3,minecraft:air)
Block(-5,5,-2,minecraft:iron_bars)
Block(-5,5,-1,minecraft:vine)
Block(-5,5,0,minecraft:air)
Block(-5,5,1,minecraft:air)
Block(-5,5,2,minecraft:air)
Block(-5,5,3,minecraft:air)
Block(-5,5,4,minecraft:air)
Block(-5,5,5,minecraft:air)
Block(-5,5,6,minecraft:air)
Block(-5,5,7,minecraft:air)
Block(-5,5,8,minecraft:air)
Block(-5,6,-7,minecraft:stone_brick_stairs:7)
Block(-5,6,-6,minecraft:air)
Block(-5,6,-5,minecraft:air)
Block(-5,6,-4,minecraft:air)
Block(-5,6,-3,minecraft:air)
Block(-5,6,-2,minecraft:iron_bars)
Block(-5,6,-1,minecraft:air)
Block(-5,6,0,minecraft:air)
Block(-5,6,1,minecraft:air)
Block(-5,6,2,minecraft:air)
Block(-5,6,3,minecraft:vine)
Block(-5,6,4,minecraft:air)
Block(-5,6,5,minecraft:air)
Block(-5,6,6,minecraft:air)
Block(-5,6,7,minecraft:air)
Block(-5,6,8,minecraft:air)
Block(-5,7,-7,minecraft:monster_egg:4)
Block(-5,7,-6,minecraft:stone_slab:11)
Block(-5,7,-5,minecraft:air)
Block(-5,7,-4,minecraft:iron_bars)
Block(-5,7,-3,minecraft:air)
Block(-5,7,-2,minecraft:iron_bars)
Block(-5,7,-1,minecraft:air)
Block(-5,7,0,minecraft:air)
Block(-5,7,1,minecraft:air)
Block(-5,7,2,minecraft:air)
Block(-5,7,3,minecraft:air)
Block(-5,7,4,minecraft:air)
Block(-5,7,5,minecraft:air)
Block(-5,7,6,minecraft:air)
Block(-5,7,7,minecraft:air)
Block(-5,7,8,minecraft:air)
Block(-5,8,-7,minecraft:monster_egg:3)
Block(-5,8,-6,minecraft:stone_slab:13)
Block(-5,8,-5,minecraft:air)
Block(-5,8,-4,minecraft:iron_bars)
Block(-5,8,-3,minecraft:stone_brick_stairs:4)
Block(-5,8,-2,minecraft:double_stone_slab:5)
Block(-5,8,-1,minecraft:air)
Block(-5,8,0,minecraft:air)
Block(-5,8,1,minecraft:air)
Block(-5,8,2,minecraft:double_stone_slab:5)
Block(-5,8,3,minecraft:air)
Block(-5,8,4,minecraft:air)
Block(-5,8,5,minecraft:air)
Block(-5,8,6,minecraft:double_stone_slab:5)
Block(-5,8,7,minecraft:air)
Block(-5,8,8,minecraft:air)
Block(-5,9,-7,minecraft:monster_egg:3)
Block(-5,9,-6,minecraft:cobblestone_wall)
Block(-5,9,-5,minecraft:stone_slab)
Block(-5,9,-4,minecraft:stone_slab:5)
Block(-5,9,-3,minecraft:cobblestone_wall)
Block(-5,9,-2,minecraft:stone_slab:13)
Block(-5,9,-1,minecraft:air)
Block(-5,9,0,minecraft:air)
Block(-5,9,1,minecraft:air)
Block(-5,9,2,minecraft:stone_slab:13)
Block(-5,9,3,minecraft:double_stone_slab)
Block(-5,9,4,minecraft:air)
Block(-5,9,5,minecraft:double_stone_slab)
Block(-5,9,6,minecraft:stone_slab:13)
Block(-5,9,7,minecraft:air)
Block(-5,9,8,minecraft:air)
Block(-5,10,-7,minecraft:monster_egg:3)
Block(-5,10,-6,minecraft:stone_slab:8)
Block(-5,10,-5,minecraft:stone_slab:8)
Block(-5,10,-4,minecraft:stone_slab:8)
Block(-5,10,-3,minecraft:stone_slab:8)
Block(-5,10,-2,minecraft:double_stone_slab)
Block(-5,10,-1,minecraft:double_stone_slab)
Block(-5,10,0,minecraft:double_stone_slab)
Block(-5,10,1,minecraft:double_stone_slab)
Block(-5,10,2,minecraft:double_stone_slab)
Block(-5,10,3,minecraft:stone_brick_stairs:0)
Block(-5,10,4,minecraft:air)
Block(-5,10,5,minecraft:stone_brick_stairs:0)
Block(-5,10,6,minecraft:cobblestone_wall)
Block(-5,10,7,minecraft:air)
Block(-5,10,8,minecraft:air)
Block(-5,11,-7,minecraft:stonebrick)
Block(-5,11,-6,minecraft:chest:3)
Block(-5,11,-5,minecraft:web)
Block(-5,11,-4,minecraft:air)
Block(-5,11,-3,minecraft:stone_brick_stairs:5)
Block(-5,11,-2,minecraft:stone_brick_stairs:5)
Block(-5,11,-1,minecraft:air)
Block(-5,11,0,minecraft:furnace)
Block(-5,11,1,minecraft:stone_brick_stairs:2)
Block(-5,11,2,minecraft:double_stone_slab)
Block(-5,11,3,minecraft:air)
Block(-5,11,4,minecraft:air)
Block(-5,11,5,minecraft:air)
Block(-5,11,6,minecraft:double_stone_slab)
Block(-5,11,7,minecraft:air)
Block(-5,11,8,minecraft:air)
Block(-5,12,-7,minecraft:monster_egg:3)
Block(-5,12,-6,minecraft:stone_slab:8)
Block(-5,12,-5,minecraft:air)
Block(-5,12,-4,minecraft:air)
Block(-5,12,-3,minecraft:flower_pot)
Block(-5,12,-2,minecraft:rail:1)
Block(-5,12,-1,minecraft:air)
Block(-5,12,1,minecraft:stone_brick_stairs:6)
Block(-5,12,2,minecraft:stone_brick_stairs)
Block(-5,12,3,minecraft:air)
Block(-5,12,4,minecraft:air)
Block(-5,12,5,minecraft:air)
