
#######################################################################
# +-----------------------------------------------------------------+ #
# |                            BO3 object                           | #
# +-----------------------------------------------------------------+ #
#######################################################################

Author: Bo3 BulkEdit

Description: Converted Schematic - Modified by Bo3BulkEdit

Version: 3

SettingsMode: WriteWithoutComments


#######################################################################
# +-----------------------------------------------------------------+ #
# |                          Main settings                          | #
# +-----------------------------------------------------------------+ #
#######################################################################

Tree: false

Frequency: 1

Rarity: 100.0

RotateRandomly: false

SpawnHeight: randomY

SpawnHeightOffset: 0

SpawnHeightVariance: 0

##############################
# Height Limits for the BO3. #
##############################

MinHeight: 0

MaxHeight: 255

######################
# Extrusion settings #
######################

ExtrudeMode: None

ExtrudeThroughBlocks: minecraft:air

MaxBranchDepth: 10


#######################################################################
# +-----------------------------------------------------------------+ #
# |                      Source block settings                      | #
# +-----------------------------------------------------------------+ #
#######################################################################

SourceBlocks: otg:air

MaxPercentageOutsideSourceBlock: 100

OutsideSourceBlock: placeAnyway

DoReplaceBlocks: true

IsOTGPlus: false


#######################################################################
# +-----------------------------------------------------------------+ #
# |                              Blocks                             | #
# +-----------------------------------------------------------------+ #
#######################################################################

B(-2,0,-5,minecraft:spruce_log)
B(-2,1,-5,minecraft:dark_oak_planks)
B(-2,2,-5,minecraft:spruce_planks)
B(-2,3,-5,minecraft:spruce_planks)
B(-2,4,-5,minecraft:spruce_planks)
B(-2,1,-4,minecraft:dark_oak_planks)
B(-2,2,-4,minecraft:spruce_fence[east=false,north=true,south=true,waterlogged=false,west=false])
B(-2,4,-4,minecraft:spruce_planks)
B(-2,1,-3,minecraft:dark_oak_planks)
B(-2,2,-3,minecraft:spruce_fence[east=false,north=true,south=true,waterlogged=false,west=false])
B(-2,3,-3,minecraft:spruce_fence[east=false,north=false,south=true,waterlogged=false,west=false])
B(-2,4,-3,minecraft:spruce_planks)
B(-2,1,-2,minecraft:dark_oak_planks)
B(-2,2,-2,minecraft:spruce_planks)
B(-2,3,-2,minecraft:spruce_planks)
B(-2,4,-2,minecraft:spruce_planks)
B(-2,1,-1,minecraft:dark_oak_planks)
B(-2,2,-1,minecraft:spruce_fence[east=false,north=true,south=true,waterlogged=false,west=false])
B(-2,3,-1,minecraft:spruce_fence[east=false,north=true,south=false,waterlogged=false,west=false])
B(-2,4,-1,minecraft:spruce_planks)
B(-2,1,0,minecraft:dark_oak_planks)
B(-2,2,0,minecraft:spruce_fence[east=false,north=true,south=true,waterlogged=false,west=false])
B(-2,4,0,minecraft:spruce_planks)
B(-2,1,1,minecraft:dark_oak_planks)
B(-2,2,1,minecraft:spruce_planks)
B(-2,3,1,minecraft:spruce_planks)
B(-2,4,1,minecraft:spruce_planks)
B(-2,1,2,minecraft:dark_oak_planks)
B(-2,4,2,minecraft:spruce_planks)
B(-2,1,3,minecraft:dark_oak_planks)
B(-2,2,3,minecraft:spruce_fence[east=false,north=false,south=true,waterlogged=false,west=false])
B(-2,4,3,minecraft:spruce_planks)
B(-2,0,4,minecraft:spruce_log)
B(-2,1,4,minecraft:dark_oak_planks)
B(-2,2,4,minecraft:spruce_planks)
B(-2,3,4,minecraft:spruce_planks)
B(-2,4,4,minecraft:spruce_planks)
B(-1,1,-5,minecraft:dark_oak_planks)
B(-1,4,-5,minecraft:spruce_planks)
B(-1,1,-4,minecraft:dark_oak_planks)
B(-1,2,-4,minecraft:cyan_bed)
B(-1,1,-3,minecraft:dark_oak_planks)
B(-1,1,-2,minecraft:dark_oak_planks)
B(-1,2,-2,minecraft:cyan_bed)
B(-1,1,-1,minecraft:dark_oak_planks)
B(-1,1,0,minecraft:dark_oak_planks)
B(-1,2,0,minecraft:cyan_bed)
B(-1,1,1,minecraft:dark_oak_planks)
B(-1,1,2,minecraft:dark_oak_planks)
B(-1,1,3,minecraft:dark_oak_planks)
B(-1,1,4,minecraft:dark_oak_planks)
B(-1,2,4,minecraft:crafting_table)
B(-1,4,4,minecraft:spruce_planks)
B(0,0,-5,minecraft:spruce_log)
B(0,1,-5,minecraft:dark_oak_planks)
B(0,2,-5,minecraft:spruce_fence[east=true,north=false,south=false,waterlogged=false,west=false])
B(0,3,-5,minecraft:spruce_fence[east=true,north=false,south=false,waterlogged=false,west=false])
B(0,4,-5,minecraft:spruce_planks)
B(0,1,-4,minecraft:dark_oak_planks)
B(0,2,-4,minecraft:orange_bed)
B(0,1,-3,minecraft:dark_oak_planks)
B(0,1,-2,minecraft:dark_oak_planks)
B(0,2,-2,minecraft:orange_bed)
B(0,1,-1,minecraft:dark_oak_planks)
B(0,1,0,minecraft:dark_oak_planks)
B(0,2,0,minecraft:orange_bed)
B(0,1,1,minecraft:dark_oak_planks)
B(0,1,2,minecraft:dark_oak_planks)
B(0,1,3,minecraft:dark_oak_planks)
B(0,1,4,minecraft:dark_oak_planks)
B(0,2,4,minecraft:furnace)
B(0,4,4,minecraft:spruce_planks)
B(1,1,-5,minecraft:dark_oak_planks)
B(1,2,-5,minecraft:spruce_planks)
B(1,3,-5,minecraft:spruce_planks)
B(1,4,-5,minecraft:spruce_planks)
B(1,1,-4,minecraft:dark_oak_planks)
B(1,1,-3,minecraft:dark_oak_planks)
B(1,1,-2,minecraft:dark_oak_planks)
B(1,1,-1,minecraft:dark_oak_planks)
B(1,1,0,minecraft:dark_oak_planks)
B(1,1,1,minecraft:dark_oak_planks)
B(1,1,2,minecraft:dark_oak_planks)
B(1,1,3,minecraft:dark_oak_planks)
B(1,2,3,minecraft:spruce_fence[east=false,north=false,south=true,waterlogged=false,west=false])
B(1,3,3,minecraft:spruce_fence[east=false,north=false,south=true,waterlogged=false,west=false])
B(1,4,3,minecraft:spruce_planks)
B(1,1,4,minecraft:dark_oak_planks)
B(1,2,4,minecraft:spruce_fence[east=false,north=true,south=false,waterlogged=false,west=true])
B(1,3,4,minecraft:spruce_fence[east=false,north=true,south=false,waterlogged=false,west=false])
B(1,4,4,minecraft:spruce_planks)
B(2,1,-5,minecraft:dark_oak_planks)
B(2,2,-5,minecraft:spruce_fence[east=true,north=false,south=false,waterlogged=false,west=true])
B(2,4,-5,minecraft:spruce_planks)
B(2,1,-4,minecraft:dark_oak_planks)
B(2,1,-3,minecraft:dark_oak_planks)
B(2,1,-2,minecraft:dark_oak_planks)
B(2,1,-1,minecraft:dark_oak_planks)
B(2,1,0,minecraft:dark_oak_planks)
B(2,1,1,minecraft:dark_oak_planks)
B(2,1,2,minecraft:dark_oak_planks)
B(2,1,3,minecraft:dark_oak_planks)
B(2,4,3,minecraft:spruce_planks)
B(2,1,4,minecraft:dark_oak_planks)
B(3,1,-5,minecraft:dark_oak_planks)
B(3,2,-5,minecraft:spruce_fence[east=true,north=false,south=false,waterlogged=false,west=true])
B(3,4,-5,minecraft:spruce_planks)
B(3,1,-4,minecraft:dark_oak_planks)
B(3,2,-4,minecraft:light_blue_bed)
B(3,1,-3,minecraft:dark_oak_planks)
B(3,1,-2,minecraft:dark_oak_planks)
B(3,2,-2,minecraft:light_blue_bed)
B(3,1,-1,minecraft:dark_oak_planks)
B(3,1,0,minecraft:dark_oak_planks)
B(3,2,0,minecraft:light_blue_bed)
B(3,1,1,minecraft:dark_oak_planks)
B(3,1,2,minecraft:dark_oak_planks)
B(3,1,3,minecraft:dark_oak_planks)
B(3,2,3,minecraft:spruce_fence[east=true,north=false,south=false,waterlogged=false,west=false])
B(3,3,3,minecraft:spruce_fence[east=true,north=false,south=false,waterlogged=false,west=false])
B(3,4,3,minecraft:spruce_planks)
B(3,1,4,minecraft:dark_oak_planks)
B(4,1,-5,minecraft:dark_oak_planks)
B(4,2,-5,minecraft:spruce_planks)
B(4,3,-5,minecraft:spruce_planks)
B(4,4,-5,minecraft:spruce_planks)
B(4,1,-4,minecraft:dark_oak_planks)
B(4,2,-4,minecraft:blue_bed)
B(4,1,-3,minecraft:dark_oak_planks)
B(4,1,-2,minecraft:dark_oak_planks)
B(4,2,-2,minecraft:blue_bed)
B(4,1,-1,minecraft:dark_oak_planks)
B(4,1,0,minecraft:dark_oak_planks)
B(4,2,0,minecraft:blue_bed)
B(4,1,1,minecraft:dark_oak_planks)
B(4,1,2,minecraft:dark_oak_planks)
B(4,1,3,minecraft:dark_oak_planks)
B(4,2,3,minecraft:spruce_fence[east=true,north=false,south=false,waterlogged=false,west=true])
B(4,3,3,minecraft:spruce_fence[east=true,north=false,south=false,waterlogged=false,west=true])
B(4,4,3,minecraft:spruce_planks)
B(4,1,4,minecraft:dark_oak_planks)
B(5,1,-5,minecraft:dark_oak_planks)
B(5,2,-5,minecraft:spruce_planks)
B(5,3,-5,minecraft:spruce_planks)
B(5,4,-5,minecraft:spruce_planks)
B(5,1,-4,minecraft:dark_oak_planks)
B(5,2,-4,minecraft:spruce_planks)
B(5,3,-4,minecraft:black_stained_glass_pane[east=false,north=true,south=true,waterlogged=false,west=false])
B(5,4,-4,minecraft:spruce_planks)
B(5,1,-3,minecraft:dark_oak_planks)
B(5,2,-3,minecraft:spruce_planks)
B(5,3,-3,minecraft:black_stained_glass_pane[east=false,north=true,south=true,waterlogged=false,west=false])
B(5,4,-3,minecraft:spruce_planks)
B(5,1,-2,minecraft:dark_oak_planks)
B(5,2,-2,minecraft:spruce_planks)
B(5,3,-2,minecraft:spruce_planks)
B(5,4,-2,minecraft:spruce_planks)
B(5,1,-1,minecraft:dark_oak_planks)
B(5,2,-1,minecraft:spruce_planks)
B(5,3,-1,minecraft:black_stained_glass_pane[east=false,north=true,south=true,waterlogged=false,west=false])
B(5,4,-1,minecraft:spruce_planks)
B(5,1,0,minecraft:dark_oak_planks)
B(5,2,0,minecraft:spruce_planks)
B(5,3,0,minecraft:black_stained_glass_pane[east=false,north=true,south=true,waterlogged=false,west=false])
B(5,4,0,minecraft:spruce_planks)
B(5,1,1,minecraft:dark_oak_planks)
B(5,2,1,minecraft:spruce_planks)
B(5,3,1,minecraft:spruce_planks)
B(5,4,1,minecraft:spruce_planks)
B(5,1,2,minecraft:dark_oak_planks)
B(5,2,2,minecraft:spruce_door[facing=north,half=lower,hinge=right,open=false,powered=false])
B(5,3,2,minecraft:spruce_door[facing=north,half=upper,hinge=right,open=false,powered=false])
B(5,4,2,minecraft:spruce_planks)
B(5,1,3,minecraft:dark_oak_planks)
B(5,2,3,minecraft:spruce_planks)
B(5,3,3,minecraft:spruce_planks)
B(5,4,3,minecraft:spruce_planks)
B(5,1,4,minecraft:dark_oak_planks)
B(5,2,4,minecraft:spruce_planks)
B(5,3,4,minecraft:spruce_planks)
B(5,4,4,minecraft:spruce_planks)
B(6,0,-8,minecraft:spruce_log)
B(6,1,-8,minecraft:dark_oak_planks)
B(6,2,-8,minecraft:spruce_fence)
B(6,3,-8,minecraft:spruce_fence)
B(6,4,-8,minecraft:spruce_planks)
B(6,1,-7,minecraft:dark_oak_planks)
B(6,1,-6,minecraft:dark_oak_planks)
B(6,0,-5,minecraft:spruce_log)
B(6,1,-5,minecraft:dark_oak_planks)
B(6,2,-5,minecraft:spruce_fence[east=false,north=false,south=false,waterlogged=false,west=true])
B(6,3,-5,minecraft:spruce_fence[east=false,north=false,south=false,waterlogged=false,west=true])
B(6,4,-5,minecraft:spruce_planks)
B(6,1,-4,minecraft:dark_oak_planks)
B(6,1,-3,minecraft:dark_oak_planks)
B(6,1,-2,minecraft:dark_oak_planks)
B(6,2,-2,minecraft:spruce_fence[east=false,north=false,south=false,waterlogged=false,west=true])
B(6,3,-2,minecraft:spruce_fence[east=false,north=false,south=false,waterlogged=false,west=true])
B(6,4,-2,minecraft:spruce_planks)
B(6,1,-1,minecraft:dark_oak_planks)
B(6,1,0,minecraft:dark_oak_planks)
B(6,1,1,minecraft:dark_oak_planks)
B(6,2,1,minecraft:spruce_fence[east=false,north=false,south=false,waterlogged=false,west=true])
B(6,3,1,minecraft:spruce_fence[east=false,north=false,south=false,waterlogged=false,west=true])
B(6,4,1,minecraft:spruce_planks)
B(6,1,2,minecraft:dark_oak_planks)
B(6,1,3,minecraft:dark_oak_planks)
B(6,0,4,minecraft:spruce_log)
B(6,1,4,minecraft:dark_oak_planks)
B(6,2,4,minecraft:spruce_fence[east=false,north=false,south=false,waterlogged=false,west=true])
B(6,3,4,minecraft:spruce_fence[east=false,north=false,south=false,waterlogged=false,west=true])
B(6,4,4,minecraft:spruce_planks)
B(6,1,5,minecraft:dark_oak_planks)
B(6,1,6,minecraft:dark_oak_planks)
B(6,0,7,minecraft:spruce_log)
B(6,1,7,minecraft:dark_oak_planks)
B(6,2,7,minecraft:spruce_fence)
B(6,3,7,minecraft:spruce_fence)
B(6,4,7,minecraft:spruce_planks)
B(7,1,-8,minecraft:dark_oak_planks)
B(7,2,-8,minecraft:rail)
B(7,4,-8,minecraft:spruce_planks)
B(7,1,-7,minecraft:dark_oak_planks)
B(7,2,-7,minecraft:rail)
B(7,1,-6,minecraft:dark_oak_planks)
B(7,2,-6,minecraft:rail)
B(7,1,-5,minecraft:dark_oak_planks)
B(7,2,-5,minecraft:rail)
B(7,4,-5,minecraft:spruce_planks)
B(7,1,-4,minecraft:dark_oak_planks)
B(7,2,-4,minecraft:rail)
B(7,1,-3,minecraft:dark_oak_planks)
B(7,2,-3,minecraft:rail)
B(7,1,-2,minecraft:dark_oak_planks)
B(7,2,-2,minecraft:rail)
B(7,4,-2,minecraft:spruce_planks)
B(7,1,-1,minecraft:dark_oak_planks)
B(7,2,-1,minecraft:rail)
B(7,1,0,minecraft:dark_oak_planks)
B(7,2,0,minecraft:rail)
B(7,1,1,minecraft:dark_oak_planks)
B(7,2,1,minecraft:rail)
B(7,4,1,minecraft:spruce_planks)
B(7,1,2,minecraft:dark_oak_planks)
B(7,2,2,minecraft:rail)
B(7,1,3,minecraft:dark_oak_planks)
B(7,2,3,minecraft:rail)
B(7,1,4,minecraft:dark_oak_planks)
B(7,2,4,minecraft:rail)
B(7,4,4,minecraft:spruce_planks)
B(7,1,5,minecraft:dark_oak_planks)
B(7,2,5,minecraft:rail)
B(7,1,6,minecraft:dark_oak_planks)
B(7,2,6,minecraft:rail)
B(7,1,7,minecraft:dark_oak_planks)
B(7,2,7,minecraft:rail)
B(7,4,7,minecraft:spruce_planks)
B(8,1,-8,minecraft:dark_oak_planks)
B(8,4,-8,minecraft:spruce_planks)
B(8,1,-7,minecraft:dark_oak_planks)
B(8,1,-6,minecraft:dark_oak_planks)
B(8,1,-5,minecraft:dark_oak_planks)
B(8,4,-5,minecraft:spruce_planks)
B(8,1,-4,minecraft:dark_oak_planks)
B(8,1,-3,minecraft:dark_oak_planks)
B(8,1,-2,minecraft:dark_oak_planks)
B(8,4,-2,minecraft:spruce_planks)
B(8,1,-1,minecraft:dark_oak_planks)
B(8,1,0,minecraft:dark_oak_planks)
B(8,4,0,minecraft:wall_torch)
B(8,1,1,minecraft:dark_oak_planks)
B(8,4,1,minecraft:spruce_planks)
B(8,1,2,minecraft:dark_oak_planks)
B(8,1,3,minecraft:dark_oak_planks)
B(8,1,4,minecraft:dark_oak_planks)
B(8,4,4,minecraft:spruce_planks)
B(8,1,5,minecraft:dark_oak_planks)
B(8,1,6,minecraft:dark_oak_planks)
B(8,1,7,minecraft:dark_oak_planks)
B(8,4,7,minecraft:spruce_planks)
B(9,0,-8,minecraft:spruce_log)
B(9,1,-8,minecraft:dark_oak_planks)
B(9,2,-8,minecraft:spruce_fence)
B(9,3,-8,minecraft:spruce_fence)
B(9,4,-8,minecraft:spruce_planks)
B(9,1,-7,minecraft:dark_oak_planks)
B(9,1,-6,minecraft:dark_oak_planks)
B(9,1,-5,minecraft:dark_oak_planks)
B(9,2,-5,minecraft:spruce_fence)
B(9,3,-5,minecraft:spruce_fence)
B(9,4,-5,minecraft:spruce_planks)
B(9,1,-4,minecraft:dark_oak_planks)
B(9,1,-3,minecraft:dark_oak_planks)
B(9,1,-2,minecraft:dark_oak_planks)
B(9,2,-2,minecraft:spruce_fence)
B(9,3,-2,minecraft:spruce_fence)
B(9,4,-2,minecraft:spruce_planks)
B(9,1,-1,minecraft:dark_oak_planks)
B(9,1,0,minecraft:dark_oak_planks)
B(9,1,1,minecraft:dark_oak_planks)
B(9,2,1,minecraft:spruce_fence)
B(9,3,1,minecraft:spruce_fence)
B(9,4,1,minecraft:spruce_planks)
B(9,1,2,minecraft:dark_oak_planks)
B(9,1,3,minecraft:dark_oak_planks)
B(9,1,4,minecraft:dark_oak_planks)
B(9,2,4,minecraft:spruce_fence)
B(9,3,4,minecraft:spruce_fence)
B(9,4,4,minecraft:spruce_planks)
B(9,1,5,minecraft:dark_oak_planks)
B(9,1,6,minecraft:dark_oak_planks)
B(9,0,7,minecraft:spruce_log)
B(9,1,7,minecraft:dark_oak_planks)
B(9,2,7,minecraft:spruce_fence)
B(9,3,7,minecraft:spruce_fence)
B(9,4,7,minecraft:spruce_planks)
RB(6,2,-7,minecraft:skeleton_skull,./NBT/Skulls/dungeon_skull_01.nbt,6,minecraft:air,9,minecraft:skeleton_skull,./NBT/Skulls/dungeon_skull_02.nbt,12,minecraft:air,15,minecraft:skeleton_skull,./NBT/Skulls/dungeon_skull_03.nbt,18,minecraft:air,21,minecraft:skeleton_skull,./NBT/Skulls/dungeon_skull_04.nbt,24,minecraft:air,27,minecraft:skeleton_skull,./NBT/Skulls/dungeon_skull_05.nbt,30,minecraft:air,33,minecraft:skeleton_skull,./NBT/Skulls/dungeon_skull_06.nbt,36,minecraft:air,39,minecraft:skeleton_skull,./NBT/Skulls/dungeon_skull_07.nbt,42,minecraft:air,45,minecraft:skeleton_skull,./NBT/Skulls/dungeon_skull_08.nbt,48,minecraft:air,51,minecraft:skeleton_skull,./NBT/Skulls/dungeon_skull_09.nbt,54,minecraft:air,57,minecraft:skeleton_skull,./NBT/Skulls/dungeon_skull_10.nbt,60,minecraft:air,63,minecraft:skeleton_skull,./NBT/Skulls/dungeon_skull_11.nbt,66,minecraft:air,69,minecraft:skeleton_skull,./NBT/Skulls/dungeon_skull_12.nbt,72,minecraft:air,75,minecraft:skeleton_skull,./NBT/Skulls/dungeon_skull_13.nbt,78,minecraft:air,81,minecraft:skeleton_skull,./NBT/Skulls/dungeon_skull_14.nbt,84,minecraft:air,87,minecraft:skeleton_skull,./NBT/Skulls/dungeon_skull_15.nbt,90,minecraft:air,93,minecraft:skeleton_skull,./NBT/Skulls/dungeon_skull_16.nbt,96,minecraft:air,100)
RB(9,2,-7,minecraft:skeleton_skull,./NBT/Skulls/dungeon_skull_01.nbt,6,minecraft:air,9,minecraft:skeleton_skull,./NBT/Skulls/dungeon_skull_02.nbt,12,minecraft:air,15,minecraft:skeleton_skull,./NBT/Skulls/dungeon_skull_03.nbt,18,minecraft:air,21,minecraft:skeleton_skull,./NBT/Skulls/dungeon_skull_04.nbt,24,minecraft:air,27,minecraft:skeleton_skull,./NBT/Skulls/dungeon_skull_05.nbt,30,minecraft:air,33,minecraft:skeleton_skull,./NBT/Skulls/dungeon_skull_06.nbt,36,minecraft:air,39,minecraft:skeleton_skull,./NBT/Skulls/dungeon_skull_07.nbt,42,minecraft:air,45,minecraft:skeleton_skull,./NBT/Skulls/dungeon_skull_08.nbt,48,minecraft:air,51,minecraft:skeleton_skull,./NBT/Skulls/dungeon_skull_09.nbt,54,minecraft:air,57,minecraft:skeleton_skull,./NBT/Skulls/dungeon_skull_10.nbt,60,minecraft:air,63,minecraft:skeleton_skull,./NBT/Skulls/dungeon_skull_11.nbt,66,minecraft:air,69,minecraft:skeleton_skull,./NBT/Skulls/dungeon_skull_12.nbt,72,minecraft:air,75,minecraft:skeleton_skull,./NBT/Skulls/dungeon_skull_13.nbt,78,minecraft:air,81,minecraft:skeleton_skull,./NBT/Skulls/dungeon_skull_14.nbt,84,minecraft:air,87,minecraft:skeleton_skull,./NBT/Skulls/dungeon_skull_15.nbt,90,minecraft:air,93,minecraft:skeleton_skull,./NBT/Skulls/dungeon_skull_16.nbt,96,minecraft:air,100)
RB(-1,2,-3,minecraft:cobweb,2,minecraft:air,30,minecraft:chest[facing=east,type=single,waterlogged=false],./NBT/VanillaLoot/abandoned_mineshaft.nbt,10,minecraft:chest[facing=east,type=single,waterlogged=false],./NBT/LoreStoryLine/LoreGeneric_5.nbt,2,minecraft:chest[facing=east,type=single,waterlogged=false],./NBT/LoreStoryLine/LoreGeneric_4.nbt,2,minecraft:chest[facing=east,type=single,waterlogged=false],./NBT/LoreStoryLine/LoreGeneric_3.nbt,2,minecraft:chest[facing=east,type=single,waterlogged=false],./NBT/LoreStoryLine/LoreGeneric_2.nbt,2,minecraft:chest[facing=east,type=single,waterlogged=false],./NBT/LoreStoryLine/LoreGeneric_1.nbt,2,minecraft:chest[facing=east,type=single,waterlogged=false],./NBT/LoreStoryLine/LoreMineshaft_5.nbt,10,minecraft:chest[facing=east,type=single,waterlogged=false],./NBT/LoreStoryLine/LoreMineshaft_4.nbt,10,minecraft:chest[facing=east,type=single,waterlogged=false],./NBT/LoreStoryLine/LoreMineshaft_3.nbt,10,minecraft:chest[facing=east,type=single,waterlogged=false],./NBT/LoreStoryLine/LoreMineshaft_2.nbt,10,minecraft:chest[facing=east,type=single,waterlogged=false],./NBT/LoreStoryLine/LoreMineshaft_1.nbt,10,minecraft:chest[facing=east,type=single,waterlogged=false],./NBT/VanillaLoot/abandoned_mineshaft.nbt,100)
RB(4,2,-3,minecraft:cobweb,2,minecraft:air,30,minecraft:chest[facing=west,type=single,waterlogged=false],./NBT/VanillaLoot/abandoned_mineshaft.nbt,10,minecraft:chest[facing=west,type=single,waterlogged=false],./NBT/LoreStoryLine/LoreGeneric_5.nbt,2,minecraft:chest[facing=west,type=single,waterlogged=false],./NBT/LoreStoryLine/LoreGeneric_4.nbt,2,minecraft:chest[facing=west,type=single,waterlogged=false],./NBT/LoreStoryLine/LoreGeneric_3.nbt,2,minecraft:chest[facing=west,type=single,waterlogged=false],./NBT/LoreStoryLine/LoreGeneric_2.nbt,2,minecraft:chest[facing=west,type=single,waterlogged=false],./NBT/LoreStoryLine/LoreGeneric_1.nbt,2,minecraft:chest[facing=west,type=single,waterlogged=false],./NBT/LoreStoryLine/LoreMineshaft_5.nbt,10,minecraft:chest[facing=west,type=single,waterlogged=false],./NBT/LoreStoryLine/LoreMineshaft_4.nbt,10,minecraft:chest[facing=west,type=single,waterlogged=false],./NBT/LoreStoryLine/LoreMineshaft_3.nbt,10,minecraft:chest[facing=west,type=single,waterlogged=false],./NBT/LoreStoryLine/LoreMineshaft_2.nbt,10,minecraft:chest[facing=west,type=single,waterlogged=false],./NBT/LoreStoryLine/LoreMineshaft_1.nbt,10,minecraft:chest[facing=west,type=single,waterlogged=false],./NBT/VanillaLoot/abandoned_mineshaft.nbt,100)
RB(9,2,-3,minecraft:skeleton_skull,./NBT/Skulls/dungeon_skull_01.nbt,6,minecraft:air,9,minecraft:skeleton_skull,./NBT/Skulls/dungeon_skull_02.nbt,12,minecraft:air,15,minecraft:skeleton_skull,./NBT/Skulls/dungeon_skull_03.nbt,18,minecraft:air,21,minecraft:skeleton_skull,./NBT/Skulls/dungeon_skull_04.nbt,24,minecraft:air,27,minecraft:skeleton_skull,./NBT/Skulls/dungeon_skull_05.nbt,30,minecraft:air,33,minecraft:skeleton_skull,./NBT/Skulls/dungeon_skull_06.nbt,36,minecraft:air,39,minecraft:skeleton_skull,./NBT/Skulls/dungeon_skull_07.nbt,42,minecraft:air,45,minecraft:skeleton_skull,./NBT/Skulls/dungeon_skull_08.nbt,48,minecraft:air,51,minecraft:skeleton_skull,./NBT/Skulls/dungeon_skull_09.nbt,54,minecraft:air,57,minecraft:skeleton_skull,./NBT/Skulls/dungeon_skull_10.nbt,60,minecraft:air,63,minecraft:skeleton_skull,./NBT/Skulls/dungeon_skull_11.nbt,66,minecraft:air,69,minecraft:skeleton_skull,./NBT/Skulls/dungeon_skull_12.nbt,72,minecraft:air,75,minecraft:skeleton_skull,./NBT/Skulls/dungeon_skull_13.nbt,78,minecraft:air,81,minecraft:skeleton_skull,./NBT/Skulls/dungeon_skull_14.nbt,84,minecraft:air,87,minecraft:skeleton_skull,./NBT/Skulls/dungeon_skull_15.nbt,90,minecraft:air,93,minecraft:skeleton_skull,./NBT/Skulls/dungeon_skull_16.nbt,96,minecraft:air,100)
RB(-1,2,-1,minecraft:cobweb,2,minecraft:air,30,minecraft:chest[facing=east,type=single,waterlogged=false],./NBT/VanillaLoot/abandoned_mineshaft.nbt,10,minecraft:chest[facing=east,type=single,waterlogged=false],./NBT/LoreStoryLine/LoreGeneric_5.nbt,2,minecraft:chest[facing=east,type=single,waterlogged=false],./NBT/LoreStoryLine/LoreGeneric_4.nbt,2,minecraft:chest[facing=east,type=single,waterlogged=false],./NBT/LoreStoryLine/LoreGeneric_3.nbt,2,minecraft:chest[facing=east,type=single,waterlogged=false],./NBT/LoreStoryLine/LoreGeneric_2.nbt,2,minecraft:chest[facing=east,type=single,waterlogged=false],./NBT/LoreStoryLine/LoreGeneric_1.nbt,2,minecraft:chest[facing=east,type=single,waterlogged=false],./NBT/LoreStoryLine/LoreMineshaft_5.nbt,10,minecraft:chest[facing=east,type=single,waterlogged=false],./NBT/LoreStoryLine/LoreMineshaft_4.nbt,10,minecraft:chest[facing=east,type=single,waterlogged=false],./NBT/LoreStoryLine/LoreMineshaft_3.nbt,10,minecraft:chest[facing=east,type=single,waterlogged=false],./NBT/LoreStoryLine/LoreMineshaft_2.nbt,10,minecraft:chest[facing=east,type=single,waterlogged=false],./NBT/LoreStoryLine/LoreMineshaft_1.nbt,10,minecraft:chest[facing=east,type=single,waterlogged=false],./NBT/VanillaLoot/abandoned_mineshaft.nbt,100)
RB(4,2,-1,minecraft:cobweb,2,minecraft:air,30,minecraft:chest[facing=west,type=single,waterlogged=false],./NBT/VanillaLoot/abandoned_mineshaft.nbt,10,minecraft:chest[facing=west,type=single,waterlogged=false],./NBT/LoreStoryLine/LoreGeneric_5.nbt,2,minecraft:chest[facing=west,type=single,waterlogged=false],./NBT/LoreStoryLine/LoreGeneric_4.nbt,2,minecraft:chest[facing=west,type=single,waterlogged=false],./NBT/LoreStoryLine/LoreGeneric_3.nbt,2,minecraft:chest[facing=west,type=single,waterlogged=false],./NBT/LoreStoryLine/LoreGeneric_2.nbt,2,minecraft:chest[facing=west,type=single,waterlogged=false],./NBT/LoreStoryLine/LoreGeneric_1.nbt,2,minecraft:chest[facing=west,type=single,waterlogged=false],./NBT/LoreStoryLine/LoreMineshaft_5.nbt,10,minecraft:chest[facing=west,type=single,waterlogged=false],./NBT/LoreStoryLine/LoreMineshaft_4.nbt,10,minecraft:chest[facing=west,type=single,waterlogged=false],./NBT/LoreStoryLine/LoreMineshaft_3.nbt,10,minecraft:chest[facing=west,type=single,waterlogged=false],./NBT/LoreStoryLine/LoreMineshaft_2.nbt,10,minecraft:chest[facing=west,type=single,waterlogged=false],./NBT/LoreStoryLine/LoreMineshaft_1.nbt,10,minecraft:chest[facing=west,type=single,waterlogged=false],./NBT/VanillaLoot/abandoned_mineshaft.nbt,100)
RB(6,2,0,minecraft:skeleton_skull,./NBT/Skulls/dungeon_skull_01.nbt,6,minecraft:air,9,minecraft:skeleton_skull,./NBT/Skulls/dungeon_skull_02.nbt,12,minecraft:air,15,minecraft:skeleton_skull,./NBT/Skulls/dungeon_skull_03.nbt,18,minecraft:air,21,minecraft:skeleton_skull,./NBT/Skulls/dungeon_skull_04.nbt,24,minecraft:air,27,minecraft:skeleton_skull,./NBT/Skulls/dungeon_skull_05.nbt,30,minecraft:air,33,minecraft:skeleton_skull,./NBT/Skulls/dungeon_skull_06.nbt,36,minecraft:air,39,minecraft:skeleton_skull,./NBT/Skulls/dungeon_skull_07.nbt,42,minecraft:air,45,minecraft:skeleton_skull,./NBT/Skulls/dungeon_skull_08.nbt,48,minecraft:air,51,minecraft:skeleton_skull,./NBT/Skulls/dungeon_skull_09.nbt,54,minecraft:air,57,minecraft:skeleton_skull,./NBT/Skulls/dungeon_skull_10.nbt,60,minecraft:air,63,minecraft:skeleton_skull,./NBT/Skulls/dungeon_skull_11.nbt,66,minecraft:air,69,minecraft:skeleton_skull,./NBT/Skulls/dungeon_skull_12.nbt,72,minecraft:air,75,minecraft:skeleton_skull,./NBT/Skulls/dungeon_skull_13.nbt,78,minecraft:air,81,minecraft:skeleton_skull,./NBT/Skulls/dungeon_skull_14.nbt,84,minecraft:air,87,minecraft:skeleton_skull,./NBT/Skulls/dungeon_skull_15.nbt,90,minecraft:air,93,minecraft:skeleton_skull,./NBT/Skulls/dungeon_skull_16.nbt,96,minecraft:air,100)
RB(-1,2,1,minecraft:cobweb,2,minecraft:air,30,minecraft:chest[facing=east,type=single,waterlogged=false],./NBT/VanillaLoot/abandoned_mineshaft.nbt,10,minecraft:chest[facing=east,type=single,waterlogged=false],./NBT/LoreStoryLine/LoreGeneric_5.nbt,2,minecraft:chest[facing=east,type=single,waterlogged=false],./NBT/LoreStoryLine/LoreGeneric_4.nbt,2,minecraft:chest[facing=east,type=single,waterlogged=false],./NBT/LoreStoryLine/LoreGeneric_3.nbt,2,minecraft:chest[facing=east,type=single,waterlogged=false],./NBT/LoreStoryLine/LoreGeneric_2.nbt,2,minecraft:chest[facing=east,type=single,waterlogged=false],./NBT/LoreStoryLine/LoreGeneric_1.nbt,2,minecraft:chest[facing=east,type=single,waterlogged=false],./NBT/LoreStoryLine/LoreMineshaft_5.nbt,10,minecraft:chest[facing=east,type=single,waterlogged=false],./NBT/LoreStoryLine/LoreMineshaft_4.nbt,10,minecraft:chest[facing=east,type=single,waterlogged=false],./NBT/LoreStoryLine/LoreMineshaft_3.nbt,10,minecraft:chest[facing=east,type=single,waterlogged=false],./NBT/LoreStoryLine/LoreMineshaft_2.nbt,10,minecraft:chest[facing=east,type=single,waterlogged=false],./NBT/LoreStoryLine/LoreMineshaft_1.nbt,10,minecraft:chest[facing=east,type=single,waterlogged=false],./NBT/VanillaLoot/abandoned_mineshaft.nbt,100)
RB(4,2,1,minecraft:cobweb,2,minecraft:air,30,minecraft:chest[facing=west,type=single,waterlogged=false],./NBT/VanillaLoot/abandoned_mineshaft.nbt,10,minecraft:chest[facing=west,type=single,waterlogged=false],./NBT/LoreStoryLine/LoreGeneric_5.nbt,2,minecraft:chest[facing=west,type=single,waterlogged=false],./NBT/LoreStoryLine/LoreGeneric_4.nbt,2,minecraft:chest[facing=west,type=single,waterlogged=false],./NBT/LoreStoryLine/LoreGeneric_3.nbt,2,minecraft:chest[facing=west,type=single,waterlogged=false],./NBT/LoreStoryLine/LoreGeneric_2.nbt,2,minecraft:chest[facing=west,type=single,waterlogged=false],./NBT/LoreStoryLine/LoreGeneric_1.nbt,2,minecraft:chest[facing=west,type=single,waterlogged=false],./NBT/LoreStoryLine/LoreMineshaft_5.nbt,10,minecraft:chest[facing=west,type=single,waterlogged=false],./NBT/LoreStoryLine/LoreMineshaft_4.nbt,10,minecraft:chest[facing=west,type=single,waterlogged=false],./NBT/LoreStoryLine/LoreMineshaft_3.nbt,10,minecraft:chest[facing=west,type=single,waterlogged=false],./NBT/LoreStoryLine/LoreMineshaft_2.nbt,10,minecraft:chest[facing=west,type=single,waterlogged=false],./NBT/LoreStoryLine/LoreMineshaft_1.nbt,10,minecraft:chest[facing=west,type=single,waterlogged=false],./NBT/VanillaLoot/abandoned_mineshaft.nbt,100)
RB(9,2,5,minecraft:skeleton_skull,./NBT/Skulls/dungeon_skull_01.nbt,6,minecraft:air,9,minecraft:skeleton_skull,./NBT/Skulls/dungeon_skull_02.nbt,12,minecraft:air,15,minecraft:skeleton_skull,./NBT/Skulls/dungeon_skull_03.nbt,18,minecraft:air,21,minecraft:skeleton_skull,./NBT/Skulls/dungeon_skull_04.nbt,24,minecraft:air,27,minecraft:skeleton_skull,./NBT/Skulls/dungeon_skull_05.nbt,30,minecraft:air,33,minecraft:skeleton_skull,./NBT/Skulls/dungeon_skull_06.nbt,36,minecraft:air,39,minecraft:skeleton_skull,./NBT/Skulls/dungeon_skull_07.nbt,42,minecraft:air,45,minecraft:skeleton_skull,./NBT/Skulls/dungeon_skull_08.nbt,48,minecraft:air,51,minecraft:skeleton_skull,./NBT/Skulls/dungeon_skull_09.nbt,54,minecraft:air,57,minecraft:skeleton_skull,./NBT/Skulls/dungeon_skull_10.nbt,60,minecraft:air,63,minecraft:skeleton_skull,./NBT/Skulls/dungeon_skull_11.nbt,66,minecraft:air,69,minecraft:skeleton_skull,./NBT/Skulls/dungeon_skull_12.nbt,72,minecraft:air,75,minecraft:skeleton_skull,./NBT/Skulls/dungeon_skull_13.nbt,78,minecraft:air,81,minecraft:skeleton_skull,./NBT/Skulls/dungeon_skull_14.nbt,84,minecraft:air,87,minecraft:skeleton_skull,./NBT/Skulls/dungeon_skull_15.nbt,90,minecraft:air,93,minecraft:skeleton_skull,./NBT/Skulls/dungeon_skull_16.nbt,96,minecraft:air,100)

#######################################################################
# +-----------------------------------------------------------------+ #
# |                            BO3 checks                           | #
# +-----------------------------------------------------------------+ #
#######################################################################


#######################################################################
# +-----------------------------------------------------------------+ #
# |                             Branches                            | #
# +-----------------------------------------------------------------+ #
#######################################################################

Branch(0,-10,0,MineshaftLargeSupport,NORTH,100.0)
WeightedBranch(8,0,16,MineShaftHallway-S,NORTH,100.0,MineShaftHallwayPopulated-02-S,NORTH,110.0,MineShaftHallwayPopulated-01-S,NORTH,120.0,MineShaftHallwaySpawner-S,NORTH,130.0,130.0)

#######################################################################
# +-----------------------------------------------------------------+ #
# |                             Entities                            | #
# +-----------------------------------------------------------------+ #
#######################################################################

Entity(1,3,-4,minecraft:zombie_villager,1)
Entity(2,3,-2,minecraft:zombie_villager,1)
Entity(2,3,0,minecraft:zombie_villager,1)
Entity(0,3,2,minecraft:zombie_villager,1)
Entity(3,3,2,minecraft:zombie_villager,1)
Entity(4,3,4,minecraft:parrot,1)
