
#######################################################################
# +-----------------------------------------------------------------+ #
# |                            BO3 object                           | #
# +-----------------------------------------------------------------+ #
#######################################################################

Author: Bo3 BulkEdit

Description: Converted Schematic - Modified by Bo3BulkEdit

Version: 3

SettingsMode: WriteWithoutComments


#######################################################################
# +-----------------------------------------------------------------+ #
# |                          Main settings                          | #
# +-----------------------------------------------------------------+ #
#######################################################################

Tree: false

Frequency: 1

Rarity: 100.0

RotateRandomly: false

SpawnHeight: randomY

SpawnHeightOffset: 0

SpawnHeightVariance: 0

##############################
# Height Limits for the BO3. #
##############################

MinHeight: 0

MaxHeight: 255

######################
# Extrusion settings #
######################

ExtrudeMode: None

ExtrudeThroughBlocks: minecraft:air

MaxBranchDepth: 10


#######################################################################
# +-----------------------------------------------------------------+ #
# |                      Source block settings                      | #
# +-----------------------------------------------------------------+ #
#######################################################################

SourceBlocks: otg:air

MaxPercentageOutsideSourceBlock: 100

OutsideSourceBlock: placeAnyway

DoReplaceBlocks: true

IsOTGPlus: false


#######################################################################
# +-----------------------------------------------------------------+ #
# |                              Blocks                             | #
# +-----------------------------------------------------------------+ #
#######################################################################

B(-8,0,-2,minecraft:spruce_log)
B(-8,1,-2,minecraft:dark_oak_planks)
B(-8,2,-2,minecraft:spruce_fence)
B(-8,3,-2,minecraft:spruce_fence)
B(-8,4,-2,minecraft:spruce_planks)
B(-8,1,-1,minecraft:dark_oak_planks)
B(-8,2,-1,minecraft:rail[shape=east_west])
B(-8,4,-1,minecraft:spruce_planks)
B(-8,1,0,minecraft:dark_oak_planks)
B(-8,4,0,minecraft:spruce_planks)
B(-8,0,1,minecraft:spruce_log)
B(-8,1,1,minecraft:dark_oak_planks)
B(-8,2,1,minecraft:spruce_fence)
B(-8,3,1,minecraft:spruce_fence)
B(-8,4,1,minecraft:spruce_planks)
B(-7,1,-2,minecraft:dark_oak_planks)
B(-7,1,-1,minecraft:dark_oak_planks)
B(-7,2,-1,minecraft:rail[shape=east_west])
B(-7,1,0,minecraft:dark_oak_planks)
B(-7,1,1,minecraft:dark_oak_planks)
B(-6,1,-2,minecraft:dark_oak_planks)
B(-6,1,-1,minecraft:dark_oak_planks)
B(-6,2,-1,minecraft:rail[shape=east_west])
B(-6,1,0,minecraft:dark_oak_planks)
B(-6,1,1,minecraft:dark_oak_planks)
B(-5,1,-2,minecraft:dark_oak_planks)
B(-5,2,-2,minecraft:spruce_fence)
B(-5,3,-2,minecraft:spruce_fence)
B(-5,4,-2,minecraft:spruce_planks)
B(-5,1,-1,minecraft:dark_oak_planks)
B(-5,2,-1,minecraft:rail[shape=east_west])
B(-5,4,-1,minecraft:spruce_planks)
B(-5,1,0,minecraft:dark_oak_planks)
B(-5,4,0,minecraft:spruce_planks)
B(-5,1,1,minecraft:dark_oak_planks)
B(-5,2,1,minecraft:spruce_fence)
B(-5,3,1,minecraft:spruce_fence)
B(-5,4,1,minecraft:spruce_planks)
B(-4,1,-2,minecraft:dark_oak_planks)
B(-4,1,-1,minecraft:dark_oak_planks)
B(-4,2,-1,minecraft:rail[shape=east_west])
B(-4,1,0,minecraft:dark_oak_planks)
B(-4,1,1,minecraft:dark_oak_planks)
B(-3,1,-2,minecraft:dark_oak_planks)
B(-3,1,-1,minecraft:dark_oak_planks)
B(-3,2,-1,minecraft:rail[shape=east_west])
B(-3,1,0,minecraft:dark_oak_planks)
B(-3,1,1,minecraft:dark_oak_planks)
B(-2,1,-2,minecraft:dark_oak_planks)
B(-2,2,-2,minecraft:spruce_fence)
B(-2,3,-2,minecraft:spruce_fence)
B(-2,4,-2,minecraft:spruce_planks)
B(-2,1,-1,minecraft:dark_oak_planks)
B(-2,2,-1,minecraft:rail[shape=east_west])
B(-2,4,-1,minecraft:spruce_planks)
B(-2,1,0,minecraft:dark_oak_planks)
B(-2,4,0,minecraft:spruce_planks)
B(-2,1,1,minecraft:dark_oak_planks)
B(-2,2,1,minecraft:spruce_fence)
B(-2,3,1,minecraft:spruce_fence)
B(-2,4,1,minecraft:spruce_planks)
B(-1,1,-2,minecraft:dark_oak_planks)
B(-1,1,-1,minecraft:dark_oak_planks)
B(-1,2,-1,minecraft:rail[shape=east_west])
B(-1,1,0,minecraft:dark_oak_planks)
B(-1,1,1,minecraft:dark_oak_planks)
B(0,1,-2,minecraft:dark_oak_planks)
B(0,1,-1,minecraft:dark_oak_planks)
B(0,2,-1,minecraft:rail[shape=east_west])
B(0,1,0,minecraft:dark_oak_planks)
B(0,1,1,minecraft:dark_oak_planks)
B(1,1,-2,minecraft:dark_oak_planks)
B(1,2,-2,minecraft:spruce_fence)
B(1,3,-2,minecraft:spruce_fence)
B(1,4,-2,minecraft:spruce_planks)
B(1,1,-1,minecraft:dark_oak_planks)
B(1,2,-1,minecraft:rail[shape=east_west])
B(1,4,-1,minecraft:spruce_planks)
B(1,1,0,minecraft:dark_oak_planks)
B(1,4,0,minecraft:spruce_planks)
B(1,1,1,minecraft:dark_oak_planks)
B(1,2,1,minecraft:spruce_fence)
B(1,3,1,minecraft:spruce_fence)
B(1,4,1,minecraft:spruce_planks)
B(2,1,-2,minecraft:dark_oak_planks)
B(2,1,-1,minecraft:dark_oak_planks)
B(2,2,-1,minecraft:rail[shape=east_west])
B(2,1,0,minecraft:dark_oak_planks)
B(2,1,1,minecraft:dark_oak_planks)
B(3,1,-2,minecraft:dark_oak_planks)
B(3,1,-1,minecraft:dark_oak_planks)
B(3,2,-1,minecraft:rail[shape=east_west])
B(3,1,0,minecraft:dark_oak_planks)
B(3,1,1,minecraft:dark_oak_planks)
B(4,1,-2,minecraft:dark_oak_planks)
B(4,2,-2,minecraft:spruce_fence)
B(4,3,-2,minecraft:spruce_fence)
B(4,4,-2,minecraft:spruce_planks)
B(4,1,-1,minecraft:dark_oak_planks)
B(4,2,-1,minecraft:rail[shape=east_west])
B(4,4,-1,minecraft:spruce_planks)
B(4,1,0,minecraft:dark_oak_planks)
B(4,4,0,minecraft:spruce_planks)
B(4,1,1,minecraft:dark_oak_planks)
B(4,2,1,minecraft:spruce_fence)
B(4,3,1,minecraft:spruce_fence)
B(4,4,1,minecraft:spruce_planks)
B(5,1,-2,minecraft:dark_oak_planks)
B(5,1,-1,minecraft:dark_oak_planks)
B(5,2,-1,minecraft:rail[shape=east_west])
B(5,1,0,minecraft:dark_oak_planks)
B(5,1,1,minecraft:dark_oak_planks)
B(6,1,-2,minecraft:dark_oak_planks)
B(6,1,-1,minecraft:dark_oak_planks)
B(6,2,-1,minecraft:rail[shape=east_west])
B(6,1,0,minecraft:dark_oak_planks)
B(6,1,1,minecraft:dark_oak_planks)
B(7,0,-2,minecraft:spruce_log)
B(7,1,-2,minecraft:dark_oak_planks)
B(7,2,-2,minecraft:spruce_fence)
B(7,3,-2,minecraft:spruce_fence)
B(7,4,-2,minecraft:spruce_planks)
B(7,1,-1,minecraft:dark_oak_planks)
B(7,2,-1,minecraft:rail[shape=east_west])
B(7,4,-1,minecraft:spruce_planks)
B(7,1,0,minecraft:dark_oak_planks)
B(7,4,0,minecraft:spruce_planks)
B(7,0,1,minecraft:spruce_log)
B(7,1,1,minecraft:dark_oak_planks)
B(7,2,1,minecraft:spruce_fence)
B(7,3,1,minecraft:spruce_fence)
B(7,4,1,minecraft:spruce_planks)
RB(-3,2,-2,minecraft:skeleton_skull,./NBT/Skulls/dungeon_skull_01.nbt,6,minecraft:air,9,minecraft:skeleton_skull,./NBT/Skulls/dungeon_skull_02.nbt,12,minecraft:air,15,minecraft:skeleton_skull,./NBT/Skulls/dungeon_skull_03.nbt,18,minecraft:air,21,minecraft:skeleton_skull,./NBT/Skulls/dungeon_skull_04.nbt,24,minecraft:air,27,minecraft:skeleton_skull,./NBT/Skulls/dungeon_skull_05.nbt,30,minecraft:air,33,minecraft:skeleton_skull,./NBT/Skulls/dungeon_skull_06.nbt,36,minecraft:air,39,minecraft:skeleton_skull,./NBT/Skulls/dungeon_skull_07.nbt,42,minecraft:air,45,minecraft:skeleton_skull,./NBT/Skulls/dungeon_skull_08.nbt,48,minecraft:air,51,minecraft:skeleton_skull,./NBT/Skulls/dungeon_skull_09.nbt,54,minecraft:air,57,minecraft:skeleton_skull,./NBT/Skulls/dungeon_skull_10.nbt,60,minecraft:air,63,minecraft:skeleton_skull,./NBT/Skulls/dungeon_skull_11.nbt,66,minecraft:air,69,minecraft:skeleton_skull,./NBT/Skulls/dungeon_skull_12.nbt,72,minecraft:air,75,minecraft:skeleton_skull,./NBT/Skulls/dungeon_skull_13.nbt,78,minecraft:air,81,minecraft:skeleton_skull,./NBT/Skulls/dungeon_skull_14.nbt,84,minecraft:air,87,minecraft:skeleton_skull,./NBT/Skulls/dungeon_skull_15.nbt,90,minecraft:air,93,minecraft:skeleton_skull,./NBT/Skulls/dungeon_skull_16.nbt,96,minecraft:air,100)
RB(5,2,-2,minecraft:skeleton_skull,./NBT/Skulls/dungeon_skull_01.nbt,6,minecraft:air,9,minecraft:skeleton_skull,./NBT/Skulls/dungeon_skull_02.nbt,12,minecraft:air,15,minecraft:skeleton_skull,./NBT/Skulls/dungeon_skull_03.nbt,18,minecraft:air,21,minecraft:skeleton_skull,./NBT/Skulls/dungeon_skull_04.nbt,24,minecraft:air,27,minecraft:skeleton_skull,./NBT/Skulls/dungeon_skull_05.nbt,30,minecraft:air,33,minecraft:skeleton_skull,./NBT/Skulls/dungeon_skull_06.nbt,36,minecraft:air,39,minecraft:skeleton_skull,./NBT/Skulls/dungeon_skull_07.nbt,42,minecraft:air,45,minecraft:skeleton_skull,./NBT/Skulls/dungeon_skull_08.nbt,48,minecraft:air,51,minecraft:skeleton_skull,./NBT/Skulls/dungeon_skull_09.nbt,54,minecraft:air,57,minecraft:skeleton_skull,./NBT/Skulls/dungeon_skull_10.nbt,60,minecraft:air,63,minecraft:skeleton_skull,./NBT/Skulls/dungeon_skull_11.nbt,66,minecraft:air,69,minecraft:skeleton_skull,./NBT/Skulls/dungeon_skull_12.nbt,72,minecraft:air,75,minecraft:skeleton_skull,./NBT/Skulls/dungeon_skull_13.nbt,78,minecraft:air,81,minecraft:skeleton_skull,./NBT/Skulls/dungeon_skull_14.nbt,84,minecraft:air,87,minecraft:skeleton_skull,./NBT/Skulls/dungeon_skull_15.nbt,90,minecraft:air,93,minecraft:skeleton_skull,./NBT/Skulls/dungeon_skull_16.nbt,96,minecraft:air,100)
RB(-3,2,1,minecraft:skeleton_skull,./NBT/Skulls/dungeon_skull_01.nbt,6,minecraft:air,9,minecraft:skeleton_skull,./NBT/Skulls/dungeon_skull_02.nbt,12,minecraft:air,15,minecraft:skeleton_skull,./NBT/Skulls/dungeon_skull_03.nbt,18,minecraft:air,21,minecraft:skeleton_skull,./NBT/Skulls/dungeon_skull_04.nbt,24,minecraft:air,27,minecraft:skeleton_skull,./NBT/Skulls/dungeon_skull_05.nbt,30,minecraft:air,33,minecraft:skeleton_skull,./NBT/Skulls/dungeon_skull_06.nbt,36,minecraft:air,39,minecraft:skeleton_skull,./NBT/Skulls/dungeon_skull_07.nbt,42,minecraft:air,45,minecraft:skeleton_skull,./NBT/Skulls/dungeon_skull_08.nbt,48,minecraft:air,51,minecraft:skeleton_skull,./NBT/Skulls/dungeon_skull_09.nbt,54,minecraft:air,57,minecraft:skeleton_skull,./NBT/Skulls/dungeon_skull_10.nbt,60,minecraft:air,63,minecraft:skeleton_skull,./NBT/Skulls/dungeon_skull_11.nbt,66,minecraft:air,69,minecraft:skeleton_skull,./NBT/Skulls/dungeon_skull_12.nbt,72,minecraft:air,75,minecraft:skeleton_skull,./NBT/Skulls/dungeon_skull_13.nbt,78,minecraft:air,81,minecraft:skeleton_skull,./NBT/Skulls/dungeon_skull_14.nbt,84,minecraft:air,87,minecraft:skeleton_skull,./NBT/Skulls/dungeon_skull_15.nbt,90,minecraft:air,93,minecraft:skeleton_skull,./NBT/Skulls/dungeon_skull_16.nbt,96,minecraft:air,100)
RB(6,2,1,minecraft:skeleton_skull,./NBT/Skulls/dungeon_skull_01.nbt,6,minecraft:air,9,minecraft:skeleton_skull,./NBT/Skulls/dungeon_skull_02.nbt,12,minecraft:air,15,minecraft:skeleton_skull,./NBT/Skulls/dungeon_skull_03.nbt,18,minecraft:air,21,minecraft:skeleton_skull,./NBT/Skulls/dungeon_skull_04.nbt,24,minecraft:air,27,minecraft:skeleton_skull,./NBT/Skulls/dungeon_skull_05.nbt,30,minecraft:air,33,minecraft:skeleton_skull,./NBT/Skulls/dungeon_skull_06.nbt,36,minecraft:air,39,minecraft:skeleton_skull,./NBT/Skulls/dungeon_skull_07.nbt,42,minecraft:air,45,minecraft:skeleton_skull,./NBT/Skulls/dungeon_skull_08.nbt,48,minecraft:air,51,minecraft:skeleton_skull,./NBT/Skulls/dungeon_skull_09.nbt,54,minecraft:air,57,minecraft:skeleton_skull,./NBT/Skulls/dungeon_skull_10.nbt,60,minecraft:air,63,minecraft:skeleton_skull,./NBT/Skulls/dungeon_skull_11.nbt,66,minecraft:air,69,minecraft:skeleton_skull,./NBT/Skulls/dungeon_skull_12.nbt,72,minecraft:air,75,minecraft:skeleton_skull,./NBT/Skulls/dungeon_skull_13.nbt,78,minecraft:air,81,minecraft:skeleton_skull,./NBT/Skulls/dungeon_skull_14.nbt,84,minecraft:air,87,minecraft:skeleton_skull,./NBT/Skulls/dungeon_skull_15.nbt,90,minecraft:air,93,minecraft:skeleton_skull,./NBT/Skulls/dungeon_skull_16.nbt,96,minecraft:air,100)
RB(-1,4,0,minecraft:wall_torch[facing=east],42,minecraft:air,50,minecraft:wall_torch[facing=east],50)

#######################################################################
# +-----------------------------------------------------------------+ #
# |                            BO3 checks                           | #
# +-----------------------------------------------------------------+ #
#######################################################################


#######################################################################
# +-----------------------------------------------------------------+ #
# |                             Branches                            | #
# +-----------------------------------------------------------------+ #
#######################################################################

Branch(16,0,6,MineshaftHallPart-01-E,NORTH,100.0)
Branch(-1,-11,-1,MineShaftHallwaySupport,EAST,100.0)

#######################################################################
# +-----------------------------------------------------------------+ #
# |                             Entities                            | #
# +-----------------------------------------------------------------+ #
#######################################################################

