
#######################################################################
# +-----------------------------------------------------------------+ #
# |                            BO3 object                           | #
# +-----------------------------------------------------------------+ #
#######################################################################

Author: BO3 BulkEdit (by LanToaster)

Description: This Object was Created with BO3_BulkEdit

Version: 3

SettingsMode: WriteWithoutComments


#######################################################################
# +-----------------------------------------------------------------+ #
# |                          Main settings                          | #
# +-----------------------------------------------------------------+ #
#######################################################################

Tree: false

Frequency: 100

Rarity: 100.0

RotateRandomly: true

SpawnHeight: randomY

SpawnHeightOffset: 0

SpawnHeightVariance: 0

##############################
# Height Limits for the BO3. #
##############################

MinHeight: 82

MaxHeight: 82

######################
# Extrusion settings #
######################

ExtrudeMode: None

ExtrudeThroughBlocks: otg:air

MaxBranchDepth: 50


#######################################################################
# +-----------------------------------------------------------------+ #
# |                      Source block settings                      | #
# +-----------------------------------------------------------------+ #
#######################################################################

SourceBlocks: otg:air

MaxPercentageOutsideSourceBlock: 100

OutsideSourceBlock: placeAnyway

DoReplaceBlocks: true

IsOTGPlus: false


#######################################################################
# +-----------------------------------------------------------------+ #
# |                              Blocks                             | #
# +-----------------------------------------------------------------+ #
#######################################################################

B(-7,-1,-1,minecraft:grass_block)
B(-7,3,-1,minecraft:jungle_slab)
B(-7,-1,0,minecraft:grass_block)
B(-7,3,0,minecraft:jungle_slab[type=double,waterlogged=false])
B(-7,3,1,minecraft:jungle_slab)
B(-7,3,2,minecraft:oak_slab[type=top,waterlogged=false])
B(-7,3,3,minecraft:oak_slab[type=top,waterlogged=false])
B(-7,3,4,minecraft:jungle_slab[type=double,waterlogged=false])
B(-7,3,5,minecraft:jungle_slab[type=double,waterlogged=false])
B(-7,3,6,minecraft:jungle_slab)
B(-6,-1,-6,minecraft:jungle_log)
B(-6,0,-6,minecraft:jungle_fence[east=true,north=false,south=true,waterlogged=false,west=false])
B(-6,-1,-5,minecraft:grass_block)
B(-6,0,-5,minecraft:jungle_fence[east=false,north=true,south=true,waterlogged=false,west=false])
B(-6,-1,-4,minecraft:grass_block)
B(-6,0,-4,minecraft:jungle_fence[east=false,north=true,south=true,waterlogged=false,west=false])
B(-6,-1,-3,minecraft:grass_block)
B(-6,0,-3,minecraft:jungle_fence[east=false,north=true,south=true,waterlogged=false,west=false])
B(-6,-1,-2,minecraft:grass_block)
B(-6,0,-2,minecraft:jungle_fence[east=false,north=true,south=true,waterlogged=false,west=false])
B(-6,-1,-1,minecraft:grass_block)
B(-6,0,-1,minecraft:jungle_fence[east=false,north=true,south=true,waterlogged=false,west=false])
B(-6,3,-1,minecraft:jungle_slab[type=double,waterlogged=false])
B(-6,-1,0,minecraft:jungle_log)
B(-6,0,0,minecraft:jungle_log)
B(-6,1,0,minecraft:jungle_log)
B(-6,2,0,minecraft:jungle_log)
B(-6,3,0,minecraft:jungle_log)
B(-6,4,0,minecraft:jungle_slab)
B(-6,-1,1,minecraft:grass_block)
B(-6,1,1,minecraft:jungle_log[axis=z])
B(-6,2,1,minecraft:jungle_fence[east=false,north=true,south=true,waterlogged=false,west=false])
B(-6,3,1,minecraft:jungle_slab[type=top,waterlogged=false])
B(-6,-1,2,minecraft:grass_block)
B(-6,1,2,minecraft:jungle_log[axis=z])
B(-6,2,2,minecraft:jungle_fence[east=false,north=true,south=true,waterlogged=false,west=false])
B(-6,3,2,minecraft:jungle_slab[type=top,waterlogged=false])
B(-6,4,2,minecraft:jungle_slab)
B(-6,1,3,minecraft:jungle_log[axis=z])
B(-6,2,3,minecraft:jungle_fence[east=true,north=true,south=true,waterlogged=false,west=false])
B(-6,3,3,minecraft:jungle_slab[type=top,waterlogged=false])
B(-6,4,3,minecraft:jungle_slab)
B(-6,1,4,minecraft:jungle_log[axis=z])
B(-6,2,4,minecraft:jungle_fence[east=false,north=true,south=true,waterlogged=false,west=false])
B(-6,3,4,minecraft:jungle_slab[type=top,waterlogged=false])
B(-6,-1,5,minecraft:jungle_log)
B(-6,0,5,minecraft:jungle_log)
B(-6,1,5,minecraft:jungle_log)
B(-6,2,5,minecraft:jungle_log)
B(-6,3,5,minecraft:jungle_log)
B(-6,4,5,minecraft:jungle_slab)
B(-6,3,6,minecraft:jungle_slab[type=double,waterlogged=false])
B(-5,-1,-7,minecraft:grass_block)
B(-5,-1,-6,minecraft:grass_block)
B(-5,0,-6,minecraft:jungle_fence[east=true,north=false,south=false,waterlogged=false,west=true])
B(-5,-1,-5,minecraft:grass_path)
B(-5,-1,-4,minecraft:dirt)
B(-5,-1,-3,minecraft:grass_path)
B(-5,-1,-2,minecraft:grass_path)
B(-5,-1,-1,minecraft:dirt)
B(-5,3,-1,minecraft:jungle_slab[type=top,waterlogged=false])
B(-5,4,-1,minecraft:jungle_slab)
B(-5,-1,0,minecraft:grass_block)
B(-5,0,0,minecraft:jungle_fence[east=true,north=false,south=false,waterlogged=false,west=true])
B(-5,1,0,minecraft:jungle_log[axis=x])
B(-5,2,0,minecraft:jungle_fence[east=true,north=false,south=false,waterlogged=false,west=true])
B(-5,3,0,minecraft:jungle_fence[east=true,north=false,south=false,waterlogged=false,west=true])
B(-5,4,0,minecraft:jungle_slab[type=double,waterlogged=false])
B(-5,-1,1,minecraft:grass_block)
B(-5,1,1,minecraft:jungle_slab[type=top,waterlogged=false])
B(-5,4,1,minecraft:jungle_slab)
B(-5,-1,2,minecraft:grass_block)
B(-5,1,2,minecraft:jungle_slab[type=top,waterlogged=false])
B(-5,4,2,minecraft:jungle_slab)
B(-5,-1,3,minecraft:grass_block)
B(-5,1,3,minecraft:jungle_slab[type=top,waterlogged=false])
B(-5,2,3,minecraft:hay_block)
B(-5,4,3,minecraft:jungle_slab)
B(-5,1,4,minecraft:jungle_slab[type=top,waterlogged=false])
B(-5,4,4,minecraft:jungle_slab)
B(-5,1,5,minecraft:jungle_log[axis=x])
B(-5,2,5,minecraft:jungle_fence[east=true,north=false,south=false,waterlogged=false,west=true])
B(-5,3,5,minecraft:jungle_fence[east=true,north=false,south=false,waterlogged=false,west=true])
B(-5,4,5,minecraft:jungle_slab[type=double,waterlogged=false])
B(-5,3,6,minecraft:jungle_slab[type=top,waterlogged=false])
B(-5,4,6,minecraft:jungle_slab)
B(-4,-1,-7,minecraft:grass_block)
B(-4,-1,-6,minecraft:grass_block)
B(-4,0,-6,minecraft:jungle_fence[east=true,north=false,south=false,waterlogged=false,west=true])
B(-4,-1,-5,minecraft:grass_path)
B(-4,-1,-4,minecraft:grass_path)
B(-4,-1,-3,minecraft:grass_path)
B(-4,-1,-2,minecraft:grass_path)
B(-4,-1,-1,minecraft:grass_path)
B(-4,4,-1,minecraft:jungle_slab[type=double,waterlogged=false])
B(-4,-1,0,minecraft:grass_block)
B(-4,0,0,minecraft:jungle_fence[east=true,north=false,south=false,waterlogged=false,west=true])
B(-4,1,0,minecraft:jungle_log[axis=x])
B(-4,2,0,minecraft:jungle_fence[east=true,north=false,south=false,waterlogged=false,west=true])
B(-4,3,0,minecraft:jungle_fence[east=false,north=false,south=false,waterlogged=false,west=true])
B(-4,4,0,minecraft:jungle_slab[type=top,waterlogged=false])
B(-4,-1,1,minecraft:grass_block)
B(-4,1,1,minecraft:jungle_slab[type=top,waterlogged=false])
B(-4,4,1,minecraft:jungle_slab[type=top,waterlogged=false])
B(-4,-1,2,minecraft:grass_block)
B(-4,1,2,minecraft:jungle_slab[type=top,waterlogged=false])
B(-4,2,2,minecraft:hay_block[axis=z])
B(-4,3,2,minecraft:hay_block)
B(-4,4,2,minecraft:jungle_slab[type=top,waterlogged=false])
B(-4,5,2,minecraft:jungle_slab)
B(-4,-1,3,minecraft:grass_block)
B(-4,1,3,minecraft:jungle_slab[type=top,waterlogged=false])
B(-4,2,3,minecraft:hay_block)
B(-4,4,3,minecraft:jungle_slab[type=top,waterlogged=false])
B(-4,1,4,minecraft:jungle_slab[type=top,waterlogged=false])
B(-4,2,4,minecraft:hay_block[axis=z])
B(-4,3,4,minecraft:hay_block)
B(-4,4,4,minecraft:jungle_slab[type=top,waterlogged=false])
B(-4,1,5,minecraft:jungle_log[axis=x])
B(-4,2,5,minecraft:jungle_fence[east=true,north=true,south=false,waterlogged=false,west=true])
B(-4,3,5,minecraft:jungle_fence[east=true,north=true,south=false,waterlogged=false,west=true])
B(-4,4,5,minecraft:jungle_slab[type=double,waterlogged=false])
B(-4,4,6,minecraft:jungle_slab[type=double,waterlogged=false])
B(-3,-1,-6,minecraft:grass_block)
B(-3,0,-6,minecraft:jungle_fence[east=true,north=false,south=false,waterlogged=false,west=true])
B(-3,-1,-5,minecraft:dirt)
B(-3,-1,-4,minecraft:grass_path)
B(-3,-1,-3,minecraft:grass_path)
B(-3,-1,-2,minecraft:grass_block)
B(-3,0,-2,minecraft:jungle_stairs[facing=south,half=bottom,shape=straight,waterlogged=false])
B(-3,-1,-1,minecraft:grass_block)
B(-3,0,-1,minecraft:jungle_stairs[facing=north,half=top,shape=straight,waterlogged=false])
B(-3,1,-1,minecraft:jungle_stairs[facing=south,half=bottom,shape=straight,waterlogged=false])
B(-3,4,-1,minecraft:jungle_slab[type=double,waterlogged=false])
B(-3,-1,0,minecraft:grass_block)
B(-3,0,0,minecraft:jungle_fence[east=true,north=false,south=false,waterlogged=false,west=true])
B(-3,1,0,minecraft:jungle_log[axis=x])
B(-3,2,0,minecraft:oak_fence_gate[facing=south,in_wall=false,open=true,powered=false])
B(-3,4,0,minecraft:jungle_slab[type=top,waterlogged=false])
B(-3,-1,1,minecraft:grass_block)
B(-3,1,1,minecraft:jungle_slab[type=top,waterlogged=false])
B(-3,4,1,minecraft:jungle_slab[type=top,waterlogged=false])
B(-3,-1,2,minecraft:grass_block)
B(-3,1,2,minecraft:jungle_slab[type=top,waterlogged=false])
B(-3,2,2,minecraft:hay_block[axis=x])
B(-3,3,2,minecraft:hay_block)
B(-3,4,2,minecraft:jungle_slab[type=top,waterlogged=false])
B(-3,-1,3,minecraft:grass_block)
B(-3,1,3,minecraft:jungle_slab[type=top,waterlogged=false])
B(-3,2,3,minecraft:hay_block[axis=z])
B(-3,4,3,minecraft:jungle_slab[type=top,waterlogged=false])
B(-3,5,3,minecraft:jungle_slab)
B(-3,1,4,minecraft:jungle_slab[type=top,waterlogged=false])
B(-3,2,4,minecraft:hay_block)
B(-3,3,4,minecraft:hay_block)
B(-3,4,4,minecraft:jungle_slab[type=top,waterlogged=false])
B(-3,1,5,minecraft:jungle_log[axis=x])
B(-3,2,5,minecraft:jungle_fence[east=true,north=true,south=false,waterlogged=false,west=true])
B(-3,3,5,minecraft:jungle_fence[east=true,north=true,south=false,waterlogged=false,west=true])
B(-3,4,5,minecraft:jungle_slab[type=double,waterlogged=false])
B(-3,4,6,minecraft:jungle_slab[type=double,waterlogged=false])
B(-2,-1,-7,minecraft:grass_block)
B(-2,-1,-6,minecraft:grass_block)
B(-2,0,-6,minecraft:jungle_fence[east=true,north=false,south=false,waterlogged=false,west=true])
B(-2,-1,-5,minecraft:dirt)
B(-2,-1,-4,minecraft:grass_path)
B(-2,-1,-3,minecraft:grass_path)
B(-2,-1,-2,minecraft:grass_path)
B(-2,-1,-1,minecraft:dirt)
B(-2,3,-1,minecraft:jungle_slab[type=top,waterlogged=false])
B(-2,4,-1,minecraft:jungle_slab)
B(-2,-1,0,minecraft:grass_block)
B(-2,0,0,minecraft:jungle_fence[east=true,north=false,south=false,waterlogged=false,west=true])
B(-2,1,0,minecraft:jungle_log[axis=x])
B(-2,2,0,minecraft:jungle_fence[east=true,north=false,south=false,waterlogged=false,west=true])
B(-2,3,0,minecraft:jungle_fence[east=true,north=false,south=false,waterlogged=false,west=false])
B(-2,4,0,minecraft:jungle_slab[type=double,waterlogged=false])
B(-2,-1,1,minecraft:grass_block)
B(-2,1,1,minecraft:jungle_slab[type=top,waterlogged=false])
B(-2,4,1,minecraft:jungle_slab)
B(-2,-1,2,minecraft:grass_block)
B(-2,1,2,minecraft:jungle_slab[type=top,waterlogged=false])
B(-2,4,2,minecraft:jungle_slab[type=double,waterlogged=false])
B(-2,-1,3,minecraft:grass_block)
B(-2,1,3,minecraft:jungle_slab[type=top,waterlogged=false])
B(-2,2,3,minecraft:hay_block[axis=z])
B(-2,4,3,minecraft:jungle_slab[type=double,waterlogged=false])
B(-2,1,4,minecraft:jungle_slab[type=top,waterlogged=false])
B(-2,2,4,minecraft:hay_block)
B(-2,4,4,minecraft:jungle_slab)
B(-2,1,5,minecraft:jungle_log[axis=x])
B(-2,2,5,minecraft:jungle_fence[east=true,north=true,south=false,waterlogged=false,west=true])
B(-2,3,5,minecraft:jungle_fence[east=true,north=false,south=false,waterlogged=false,west=true])
B(-2,4,5,minecraft:jungle_slab[type=double,waterlogged=false])
B(-2,3,6,minecraft:jungle_slab[type=top,waterlogged=false])
B(-2,4,6,minecraft:jungle_slab)
B(-1,-1,-7,minecraft:grass_block)
B(-1,-1,-6,minecraft:jungle_log)
B(-1,0,-6,minecraft:jungle_fence[east=true,north=false,south=false,waterlogged=false,west=true])
B(-1,-1,-5,minecraft:dirt)
B(-1,-1,-4,minecraft:grass_path)
B(-1,-1,-3,minecraft:grass_path)
B(-1,-1,-2,minecraft:grass_path)
B(-1,-1,-1,minecraft:dirt)
B(-1,3,-1,minecraft:jungle_slab[type=double,waterlogged=false])
B(-1,-1,0,minecraft:jungle_log)
B(-1,0,0,minecraft:jungle_log)
B(-1,1,0,minecraft:jungle_log)
B(-1,2,0,minecraft:jungle_log)
B(-1,3,0,minecraft:jungle_log)
B(-1,4,0,minecraft:jungle_slab)
B(-1,-1,1,minecraft:grass_block)
B(-1,1,1,minecraft:jungle_log[axis=z])
B(-1,2,1,minecraft:jungle_fence[east=false,north=true,south=true,waterlogged=false,west=false])
B(-1,3,1,minecraft:jungle_slab[type=top,waterlogged=false])
B(-1,-1,2,minecraft:grass_block)
B(-1,1,2,minecraft:jungle_log[axis=z])
B(-1,2,2,minecraft:jungle_fence[east=false,north=true,south=true,waterlogged=false,west=false])
B(-1,3,2,minecraft:jungle_slab[type=top,waterlogged=false])
B(-1,4,2,minecraft:oak_slab)
B(-1,-1,3,minecraft:grass_block)
B(-1,1,3,minecraft:jungle_log[axis=z])
B(-1,2,3,minecraft:jungle_fence[east=false,north=true,south=true,waterlogged=false,west=true])
B(-1,3,3,minecraft:jungle_slab[type=top,waterlogged=false])
B(-1,4,3,minecraft:oak_slab)
B(-1,-1,4,minecraft:grass_block)
B(-1,1,4,minecraft:jungle_log[axis=z])
B(-1,2,4,minecraft:jungle_fence[east=false,north=true,south=true,waterlogged=false,west=true])
B(-1,3,4,minecraft:jungle_slab[type=top,waterlogged=false])
B(-1,4,4,minecraft:oak_slab)
B(-1,-1,5,minecraft:jungle_log)
B(-1,0,5,minecraft:jungle_log)
B(-1,1,5,minecraft:jungle_log)
B(-1,2,5,minecraft:jungle_log)
B(-1,3,5,minecraft:jungle_log)
B(-1,4,5,minecraft:jungle_slab)
B(-1,3,6,minecraft:jungle_slab[type=double,waterlogged=false])
B(0,-1,-7,minecraft:grass_block)
B(0,-1,-6,minecraft:grass_block)
B(0,0,-6,minecraft:jungle_fence[east=true,north=false,south=false,waterlogged=false,west=true])
B(0,-1,-5,minecraft:dirt)
B(0,-1,-4,minecraft:grass_path)
B(0,-1,-3,minecraft:grass_path)
B(0,-1,-2,minecraft:grass_path)
B(0,-1,-1,minecraft:grass_path)
B(0,3,-1,minecraft:jungle_slab)
B(0,-1,0,minecraft:grass_block)
B(0,0,0,minecraft:jungle_fence[east=true,north=false,south=false,waterlogged=false,west=true])
B(0,3,0,minecraft:jungle_slab[type=double,waterlogged=false])
B(0,3,1,minecraft:jungle_slab[type=top,waterlogged=false])
B(0,-1,2,minecraft:grass_block)
B(0,3,2,minecraft:jungle_slab)
B(0,-1,3,minecraft:grass_block)
B(0,3,3,minecraft:jungle_slab[type=double,waterlogged=false])
B(0,3,4,minecraft:jungle_slab[type=top,waterlogged=false])
B(0,3,5,minecraft:jungle_slab[type=double,waterlogged=false])
B(0,3,6,minecraft:jungle_slab)
B(1,-1,-7,minecraft:grass_block)
B(1,-1,-6,minecraft:grass_block)
B(1,0,-6,minecraft:jungle_fence[east=true,north=false,south=false,waterlogged=false,west=true])
B(1,-1,-5,minecraft:dirt)
B(1,-1,-4,minecraft:dirt)
B(1,0,-4,minecraft:hay_block)
B(1,-1,-3,minecraft:grass_path)
B(1,-1,-2,minecraft:grass_path)
B(1,-1,-1,minecraft:grass_path)
B(1,-1,0,minecraft:grass_block)
B(1,0,0,minecraft:jungle_fence[east=true,north=false,south=false,waterlogged=false,west=true])
B(2,-1,-6,minecraft:grass_block)
B(2,0,-6,minecraft:jungle_fence[east=true,north=false,south=false,waterlogged=false,west=true])
B(2,-1,-5,minecraft:grass_path)
B(2,-1,-4,minecraft:grass_path)
B(2,-1,-3,minecraft:grass_path)
B(2,-1,-2,minecraft:grass_path)
B(2,-1,-1,minecraft:grass_path)
B(2,-1,0,minecraft:grass_block)
B(2,0,0,minecraft:jungle_fence[east=true,north=false,south=false,waterlogged=false,west=true])
B(2,-1,1,minecraft:grass_block)
B(3,-1,-6,minecraft:grass_block)
B(3,0,-6,minecraft:jungle_fence[east=true,north=false,south=false,waterlogged=false,west=true])
B(3,-1,-5,minecraft:grass_path)
B(3,-1,-4,minecraft:dirt)
B(3,-1,-3,minecraft:dirt)
B(3,-1,-2,minecraft:grass_path)
B(3,-1,-1,minecraft:dirt)
B(3,-1,0,minecraft:grass_block)
B(3,0,0,minecraft:oak_fence_gate[facing=south,in_wall=false,open=false,powered=false])
B(3,-1,1,minecraft:grass_block)
B(3,-1,2,minecraft:grass_block)
B(4,-1,-6,minecraft:grass_block)
B(4,0,-6,minecraft:jungle_fence[east=true,north=false,south=false,waterlogged=false,west=true])
B(4,-1,-5,minecraft:grass_path)
B(4,-1,-4,minecraft:cauldron[level=3])
B(4,-1,-3,minecraft:cauldron[level=3])
B(4,-1,-2,minecraft:grass_block)
B(4,-1,-1,minecraft:grass_block)
B(4,-1,0,minecraft:grass_block)
B(4,0,0,minecraft:jungle_fence[east=true,north=false,south=false,waterlogged=false,west=true])
B(4,-1,1,minecraft:grass_block)
B(4,-1,2,minecraft:grass_block)
B(5,-1,-6,minecraft:jungle_log)
B(5,0,-6,minecraft:jungle_fence[east=false,north=false,south=true,waterlogged=false,west=true])
B(5,-1,-5,minecraft:grass_block)
B(5,0,-5,minecraft:jungle_fence[east=false,north=true,south=true,waterlogged=false,west=false])
B(5,-1,-4,minecraft:grass_block)
B(5,0,-4,minecraft:jungle_fence[east=false,north=true,south=true,waterlogged=false,west=false])
B(5,-1,-3,minecraft:grass_block)
B(5,0,-3,minecraft:jungle_fence[east=false,north=true,south=true,waterlogged=false,west=false])
B(5,-1,-2,minecraft:grass_block)
B(5,0,-2,minecraft:jungle_fence[east=false,north=true,south=true,waterlogged=false,west=false])
B(5,-1,-1,minecraft:grass_block)
B(5,0,-1,minecraft:jungle_fence[east=false,north=true,south=true,waterlogged=false,west=false])
B(5,-1,0,minecraft:jungle_log)
B(5,0,0,minecraft:jungle_fence[east=false,north=true,south=false,waterlogged=false,west=true])
B(5,-1,1,minecraft:grass_block)
B(5,-1,2,minecraft:grass_block)
B(6,-1,0,minecraft:grass_block)
B(6,-1,1,minecraft:grass_block)
RB(-5,3,1,minecraft:white_wall_banner[facing=east],../JungleNBT/banners/JungleBanner01.nbt,8,minecraft:white_wall_banner[facing=east],../JungleNBT/banners/JungleBanner02.nbt,8,minecraft:white_wall_banner[facing=east],../JungleNBT/banners/JungleBanner03.nbt,8,minecraft:white_wall_banner[facing=east],../JungleNBT/banners/JungleBanner04.nbt,8,minecraft:white_wall_banner[facing=east],../JungleNBT/banners/JungleBanner05.nbt,8,minecraft:white_wall_banner[facing=east],../JungleNBT/banners/JungleBanner06.nbt,8,minecraft:white_wall_banner[facing=east],../JungleNBT/banners/JungleBanner07.nbt,8,minecraft:white_wall_banner[facing=east],../JungleNBT/banners/JungleBanner08.nbt,8,minecraft:white_wall_banner[facing=east],../JungleNBT/banners/JungleBanner09.nbt,8,minecraft:white_wall_banner[facing=east],../JungleNBT/banners/JungleBanner10.nbt,8,minecraft:white_wall_banner[facing=east],../JungleNBT/banners/JungleBanner11.nbt,8,minecraft:white_wall_banner[facing=east],../JungleNBT/banners/JungleBanner12.nbt,8,minecraft:white_wall_banner[facing=east],../JungleNBT/banners/JungleBanner13.nbt,8,minecraft:white_wall_banner[facing=east],../JungleNBT/banners/JungleBanner14.nbt,8,minecraft:white_wall_banner[facing=east],../JungleNBT/banners/JungleBanner15.nbt,8,minecraft:white_wall_banner[facing=east],../JungleNBT/banners/JungleBanner16.nbt,8,minecraft:white_wall_banner[facing=east],../JungleNBT/banners/JungleBanner17.nbt,8,minecraft:white_wall_banner[facing=east],../JungleNBT/banners/JungleBanner18.nbt,8,minecraft:white_wall_banner[facing=east],../JungleNBT/banners/JungleBanner19.nbt,8,minecraft:white_wall_banner[facing=east],../JungleNBT/banners/JungleBanner20.nbt,100)
RB(-2,3,1,minecraft:white_wall_banner[facing=west],../JungleNBT/banners/JungleBanner01.nbt,8,minecraft:white_wall_banner[facing=west],../JungleNBT/banners/JungleBanner02.nbt,8,minecraft:white_wall_banner[facing=west],../JungleNBT/banners/JungleBanner03.nbt,8,minecraft:white_wall_banner[facing=west],../JungleNBT/banners/JungleBanner04.nbt,8,minecraft:white_wall_banner[facing=west],../JungleNBT/banners/JungleBanner05.nbt,8,minecraft:white_wall_banner[facing=west],../JungleNBT/banners/JungleBanner06.nbt,8,minecraft:white_wall_banner[facing=west],../JungleNBT/banners/JungleBanner07.nbt,8,minecraft:white_wall_banner[facing=west],../JungleNBT/banners/JungleBanner08.nbt,8,minecraft:white_wall_banner[facing=west],../JungleNBT/banners/JungleBanner09.nbt,8,minecraft:white_wall_banner[facing=west],../JungleNBT/banners/JungleBanner10.nbt,8,minecraft:white_wall_banner[facing=west],../JungleNBT/banners/JungleBanner11.nbt,8,minecraft:white_wall_banner[facing=west],../JungleNBT/banners/JungleBanner12.nbt,8,minecraft:white_wall_banner[facing=west],../JungleNBT/banners/JungleBanner13.nbt,8,minecraft:white_wall_banner[facing=west],../JungleNBT/banners/JungleBanner14.nbt,8,minecraft:white_wall_banner[facing=west],../JungleNBT/banners/JungleBanner15.nbt,8,minecraft:white_wall_banner[facing=west],../JungleNBT/banners/JungleBanner16.nbt,8,minecraft:white_wall_banner[facing=west],../JungleNBT/banners/JungleBanner17.nbt,8,minecraft:white_wall_banner[facing=west],../JungleNBT/banners/JungleBanner18.nbt,8,minecraft:white_wall_banner[facing=west],../JungleNBT/banners/JungleBanner19.nbt,8,minecraft:white_wall_banner[facing=west],../JungleNBT/banners/JungleBanner20.nbt,100)
RB(-5,3,2,minecraft:white_wall_banner[facing=east],../JungleNBT/banners/JungleBanner01.nbt,8,minecraft:white_wall_banner[facing=east],../JungleNBT/banners/JungleBanner02.nbt,8,minecraft:white_wall_banner[facing=east],../JungleNBT/banners/JungleBanner03.nbt,8,minecraft:white_wall_banner[facing=east],../JungleNBT/banners/JungleBanner04.nbt,8,minecraft:white_wall_banner[facing=east],../JungleNBT/banners/JungleBanner05.nbt,8,minecraft:white_wall_banner[facing=east],../JungleNBT/banners/JungleBanner06.nbt,8,minecraft:white_wall_banner[facing=east],../JungleNBT/banners/JungleBanner07.nbt,8,minecraft:white_wall_banner[facing=east],../JungleNBT/banners/JungleBanner08.nbt,8,minecraft:white_wall_banner[facing=east],../JungleNBT/banners/JungleBanner09.nbt,8,minecraft:white_wall_banner[facing=east],../JungleNBT/banners/JungleBanner10.nbt,8,minecraft:white_wall_banner[facing=east],../JungleNBT/banners/JungleBanner11.nbt,8,minecraft:white_wall_banner[facing=east],../JungleNBT/banners/JungleBanner12.nbt,8,minecraft:white_wall_banner[facing=east],../JungleNBT/banners/JungleBanner13.nbt,8,minecraft:white_wall_banner[facing=east],../JungleNBT/banners/JungleBanner14.nbt,8,minecraft:white_wall_banner[facing=east],../JungleNBT/banners/JungleBanner15.nbt,8,minecraft:white_wall_banner[facing=east],../JungleNBT/banners/JungleBanner16.nbt,8,minecraft:white_wall_banner[facing=east],../JungleNBT/banners/JungleBanner17.nbt,8,minecraft:white_wall_banner[facing=east],../JungleNBT/banners/JungleBanner18.nbt,8,minecraft:white_wall_banner[facing=east],../JungleNBT/banners/JungleBanner19.nbt,8,minecraft:white_wall_banner[facing=east],../JungleNBT/banners/JungleBanner20.nbt,100)
RB(-2,3,2,minecraft:white_wall_banner[facing=west],../JungleNBT/banners/JungleBanner01.nbt,8,minecraft:white_wall_banner[facing=west],../JungleNBT/banners/JungleBanner02.nbt,8,minecraft:white_wall_banner[facing=west],../JungleNBT/banners/JungleBanner03.nbt,8,minecraft:white_wall_banner[facing=west],../JungleNBT/banners/JungleBanner04.nbt,8,minecraft:white_wall_banner[facing=west],../JungleNBT/banners/JungleBanner05.nbt,8,minecraft:white_wall_banner[facing=west],../JungleNBT/banners/JungleBanner06.nbt,8,minecraft:white_wall_banner[facing=west],../JungleNBT/banners/JungleBanner07.nbt,8,minecraft:white_wall_banner[facing=west],../JungleNBT/banners/JungleBanner08.nbt,8,minecraft:white_wall_banner[facing=west],../JungleNBT/banners/JungleBanner09.nbt,8,minecraft:white_wall_banner[facing=west],../JungleNBT/banners/JungleBanner10.nbt,8,minecraft:white_wall_banner[facing=west],../JungleNBT/banners/JungleBanner11.nbt,8,minecraft:white_wall_banner[facing=west],../JungleNBT/banners/JungleBanner12.nbt,8,minecraft:white_wall_banner[facing=west],../JungleNBT/banners/JungleBanner13.nbt,8,minecraft:white_wall_banner[facing=west],../JungleNBT/banners/JungleBanner14.nbt,8,minecraft:white_wall_banner[facing=west],../JungleNBT/banners/JungleBanner15.nbt,8,minecraft:white_wall_banner[facing=west],../JungleNBT/banners/JungleBanner16.nbt,8,minecraft:white_wall_banner[facing=west],../JungleNBT/banners/JungleBanner17.nbt,8,minecraft:white_wall_banner[facing=west],../JungleNBT/banners/JungleBanner18.nbt,8,minecraft:white_wall_banner[facing=west],../JungleNBT/banners/JungleBanner19.nbt,8,minecraft:white_wall_banner[facing=west],../JungleNBT/banners/JungleBanner20.nbt,100)
RB(-5,3,3,minecraft:white_wall_banner[facing=east],../JungleNBT/banners/JungleBanner01.nbt,8,minecraft:white_wall_banner[facing=east],../JungleNBT/banners/JungleBanner02.nbt,8,minecraft:white_wall_banner[facing=east],../JungleNBT/banners/JungleBanner03.nbt,8,minecraft:white_wall_banner[facing=east],../JungleNBT/banners/JungleBanner04.nbt,8,minecraft:white_wall_banner[facing=east],../JungleNBT/banners/JungleBanner05.nbt,8,minecraft:white_wall_banner[facing=east],../JungleNBT/banners/JungleBanner06.nbt,8,minecraft:white_wall_banner[facing=east],../JungleNBT/banners/JungleBanner07.nbt,8,minecraft:white_wall_banner[facing=east],../JungleNBT/banners/JungleBanner08.nbt,8,minecraft:white_wall_banner[facing=east],../JungleNBT/banners/JungleBanner09.nbt,8,minecraft:white_wall_banner[facing=east],../JungleNBT/banners/JungleBanner10.nbt,8,minecraft:white_wall_banner[facing=east],../JungleNBT/banners/JungleBanner11.nbt,8,minecraft:white_wall_banner[facing=east],../JungleNBT/banners/JungleBanner12.nbt,8,minecraft:white_wall_banner[facing=east],../JungleNBT/banners/JungleBanner13.nbt,8,minecraft:white_wall_banner[facing=east],../JungleNBT/banners/JungleBanner14.nbt,8,minecraft:white_wall_banner[facing=east],../JungleNBT/banners/JungleBanner15.nbt,8,minecraft:white_wall_banner[facing=east],../JungleNBT/banners/JungleBanner16.nbt,8,minecraft:white_wall_banner[facing=east],../JungleNBT/banners/JungleBanner17.nbt,8,minecraft:white_wall_banner[facing=east],../JungleNBT/banners/JungleBanner18.nbt,8,minecraft:white_wall_banner[facing=east],../JungleNBT/banners/JungleBanner19.nbt,8,minecraft:white_wall_banner[facing=east],../JungleNBT/banners/JungleBanner20.nbt,100)
RB(-2,3,3,minecraft:white_wall_banner[facing=west],../JungleNBT/banners/JungleBanner01.nbt,8,minecraft:white_wall_banner[facing=west],../JungleNBT/banners/JungleBanner02.nbt,8,minecraft:white_wall_banner[facing=west],../JungleNBT/banners/JungleBanner03.nbt,8,minecraft:white_wall_banner[facing=west],../JungleNBT/banners/JungleBanner04.nbt,8,minecraft:white_wall_banner[facing=west],../JungleNBT/banners/JungleBanner05.nbt,8,minecraft:white_wall_banner[facing=west],../JungleNBT/banners/JungleBanner06.nbt,8,minecraft:white_wall_banner[facing=west],../JungleNBT/banners/JungleBanner07.nbt,8,minecraft:white_wall_banner[facing=west],../JungleNBT/banners/JungleBanner08.nbt,8,minecraft:white_wall_banner[facing=west],../JungleNBT/banners/JungleBanner09.nbt,8,minecraft:white_wall_banner[facing=west],../JungleNBT/banners/JungleBanner10.nbt,8,minecraft:white_wall_banner[facing=west],../JungleNBT/banners/JungleBanner11.nbt,8,minecraft:white_wall_banner[facing=west],../JungleNBT/banners/JungleBanner12.nbt,8,minecraft:white_wall_banner[facing=west],../JungleNBT/banners/JungleBanner13.nbt,8,minecraft:white_wall_banner[facing=west],../JungleNBT/banners/JungleBanner14.nbt,8,minecraft:white_wall_banner[facing=west],../JungleNBT/banners/JungleBanner15.nbt,8,minecraft:white_wall_banner[facing=west],../JungleNBT/banners/JungleBanner16.nbt,8,minecraft:white_wall_banner[facing=west],../JungleNBT/banners/JungleBanner17.nbt,8,minecraft:white_wall_banner[facing=west],../JungleNBT/banners/JungleBanner18.nbt,8,minecraft:white_wall_banner[facing=west],../JungleNBT/banners/JungleBanner19.nbt,8,minecraft:white_wall_banner[facing=west],../JungleNBT/banners/JungleBanner20.nbt,100)
RB(-5,3,4,minecraft:white_wall_banner[facing=east],../JungleNBT/banners/JungleBanner01.nbt,8,minecraft:white_wall_banner[facing=east],../JungleNBT/banners/JungleBanner02.nbt,8,minecraft:white_wall_banner[facing=east],../JungleNBT/banners/JungleBanner03.nbt,8,minecraft:white_wall_banner[facing=east],../JungleNBT/banners/JungleBanner04.nbt,8,minecraft:white_wall_banner[facing=east],../JungleNBT/banners/JungleBanner05.nbt,8,minecraft:white_wall_banner[facing=east],../JungleNBT/banners/JungleBanner06.nbt,8,minecraft:white_wall_banner[facing=east],../JungleNBT/banners/JungleBanner07.nbt,8,minecraft:white_wall_banner[facing=east],../JungleNBT/banners/JungleBanner08.nbt,8,minecraft:white_wall_banner[facing=east],../JungleNBT/banners/JungleBanner09.nbt,8,minecraft:white_wall_banner[facing=east],../JungleNBT/banners/JungleBanner10.nbt,8,minecraft:white_wall_banner[facing=east],../JungleNBT/banners/JungleBanner11.nbt,8,minecraft:white_wall_banner[facing=east],../JungleNBT/banners/JungleBanner12.nbt,8,minecraft:white_wall_banner[facing=east],../JungleNBT/banners/JungleBanner13.nbt,8,minecraft:white_wall_banner[facing=east],../JungleNBT/banners/JungleBanner14.nbt,8,minecraft:white_wall_banner[facing=east],../JungleNBT/banners/JungleBanner15.nbt,8,minecraft:white_wall_banner[facing=east],../JungleNBT/banners/JungleBanner16.nbt,8,minecraft:white_wall_banner[facing=east],../JungleNBT/banners/JungleBanner17.nbt,8,minecraft:white_wall_banner[facing=east],../JungleNBT/banners/JungleBanner18.nbt,8,minecraft:white_wall_banner[facing=east],../JungleNBT/banners/JungleBanner19.nbt,8,minecraft:white_wall_banner[facing=east],../JungleNBT/banners/JungleBanner20.nbt,100)
RB(-2,3,4,minecraft:white_wall_banner[facing=west],../JungleNBT/banners/JungleBanner01.nbt,8,minecraft:white_wall_banner[facing=west],../JungleNBT/banners/JungleBanner02.nbt,8,minecraft:white_wall_banner[facing=west],../JungleNBT/banners/JungleBanner03.nbt,8,minecraft:white_wall_banner[facing=west],../JungleNBT/banners/JungleBanner04.nbt,8,minecraft:white_wall_banner[facing=west],../JungleNBT/banners/JungleBanner05.nbt,8,minecraft:white_wall_banner[facing=west],../JungleNBT/banners/JungleBanner06.nbt,8,minecraft:white_wall_banner[facing=west],../JungleNBT/banners/JungleBanner07.nbt,8,minecraft:white_wall_banner[facing=west],../JungleNBT/banners/JungleBanner08.nbt,8,minecraft:white_wall_banner[facing=west],../JungleNBT/banners/JungleBanner09.nbt,8,minecraft:white_wall_banner[facing=west],../JungleNBT/banners/JungleBanner10.nbt,8,minecraft:white_wall_banner[facing=west],../JungleNBT/banners/JungleBanner11.nbt,8,minecraft:white_wall_banner[facing=west],../JungleNBT/banners/JungleBanner12.nbt,8,minecraft:white_wall_banner[facing=west],../JungleNBT/banners/JungleBanner13.nbt,8,minecraft:white_wall_banner[facing=west],../JungleNBT/banners/JungleBanner14.nbt,8,minecraft:white_wall_banner[facing=west],../JungleNBT/banners/JungleBanner15.nbt,8,minecraft:white_wall_banner[facing=west],../JungleNBT/banners/JungleBanner16.nbt,8,minecraft:white_wall_banner[facing=west],../JungleNBT/banners/JungleBanner17.nbt,8,minecraft:white_wall_banner[facing=west],../JungleNBT/banners/JungleBanner18.nbt,8,minecraft:white_wall_banner[facing=west],../JungleNBT/banners/JungleBanner19.nbt,8,minecraft:white_wall_banner[facing=west],../JungleNBT/banners/JungleBanner20.nbt,100)

#######################################################################
# +-----------------------------------------------------------------+ #
# |                            BO3 checks                           | #
# +-----------------------------------------------------------------+ #
#######################################################################


#######################################################################
# +-----------------------------------------------------------------+ #
# |                             Branches                            | #
# +-----------------------------------------------------------------+ #
#######################################################################


#######################################################################
# +-----------------------------------------------------------------+ #
# |                             Entities                            | #
# +-----------------------------------------------------------------+ #
#######################################################################

Entity(-3,0,-5,minecraft:chicken,1,../JungleNBT/entities/chicken.txt)
Entity(-2,0,-5,minecraft:pig,1,../JungleNBT/entities/pig.txt)
Entity(-1,0,-5,minecraft:pig,1,../JungleNBT/entities/pig.txt)
Entity(0,0,-5,minecraft:chicken,1,../JungleNBT/entities/chicken.txt)
Entity(1,0,-5,minecraft:pig,1,../JungleNBT/entities/pig.txt)
Entity(-5,0,-4,minecraft:chicken,1,../JungleNBT/entities/chicken.txt)
Entity(3,0,-3,minecraft:villager,1,../JungleNBT/entities/tribalherder.txt)
