
#######################################################################
# +-----------------------------------------------------------------+ #
# |                            BO3 object                           | #
# +-----------------------------------------------------------------+ #
#######################################################################

Author: BO3 BulkEdit (by LanToaster)

Description: This Object was Created with BO3_BulkEdit

Version: 3

SettingsMode: WriteWithoutComments


#######################################################################
# +-----------------------------------------------------------------+ #
# |                          Main settings                          | #
# +-----------------------------------------------------------------+ #
#######################################################################

Tree: false

Frequency: 100

Rarity: 100.0

RotateRandomly: true

SpawnHeight: randomY

SpawnHeightOffset: 0

SpawnHeightVariance: 0

##############################
# Height Limits for the BO3. #
##############################

MinHeight: 82

MaxHeight: 82

######################
# Extrusion settings #
######################

ExtrudeMode: None

ExtrudeThroughBlocks: otg:air

MaxBranchDepth: 50


#######################################################################
# +-----------------------------------------------------------------+ #
# |                      Source block settings                      | #
# +-----------------------------------------------------------------+ #
#######################################################################

SourceBlocks: otg:air

MaxPercentageOutsideSourceBlock: 100

OutsideSourceBlock: placeAnyway

DoReplaceBlocks: true

IsOTGPlus: false


#######################################################################
# +-----------------------------------------------------------------+ #
# |                              Blocks                             | #
# +-----------------------------------------------------------------+ #
#######################################################################

B(-7,-1,1,minecraft:grass_path)
B(-6,2,-4,minecraft:jungle_slab[type=top,waterlogged=false])
B(-6,3,-3,minecraft:jungle_slab)
B(-6,3,-2,minecraft:jungle_slab)
B(-6,-1,-1,minecraft:grass_path)
B(-6,3,-1,minecraft:jungle_slab)
B(-6,-1,0,minecraft:grass_path)
B(-6,2,0,minecraft:jungle_slab[type=top,waterlogged=false])
B(-6,-1,1,minecraft:grass_path)
B(-6,2,1,minecraft:jungle_slab[type=top,waterlogged=false])
B(-6,2,2,minecraft:jungle_slab[type=top,waterlogged=false])
B(-5,-1,-4,minecraft:jungle_log)
B(-5,0,-4,minecraft:jungle_log)
B(-5,1,-4,minecraft:jungle_log)
B(-5,2,-4,minecraft:jungle_log)
B(-5,3,-4,minecraft:jungle_log)
B(-5,4,-4,minecraft:jungle_slab)
B(-5,-1,-3,minecraft:grass_block)
B(-5,0,-3,minecraft:jungle_fence[east=false,north=true,south=true,waterlogged=false,west=false])
B(-5,3,-3,minecraft:jungle_slab[type=top,waterlogged=false])
B(-5,-1,-2,minecraft:grass_block)
B(-5,0,-2,minecraft:jungle_fence[east=false,north=true,south=true,waterlogged=false,west=false])
B(-5,3,-2,minecraft:jungle_slab[type=top,waterlogged=false])
B(-5,-1,-1,minecraft:grass_block)
B(-5,0,-1,minecraft:jungle_fence[east=false,north=true,south=true,waterlogged=false,west=false])
B(-5,3,-1,minecraft:jungle_slab[type=double,waterlogged=false])
B(-5,-1,0,minecraft:grass_block)
B(-5,0,0,minecraft:jungle_fence[east=false,north=true,south=true,waterlogged=false,west=false])
B(-5,3,0,minecraft:jungle_slab[type=double,waterlogged=false])
B(-5,-1,1,minecraft:jungle_log)
B(-5,0,1,minecraft:jungle_log)
B(-5,1,1,minecraft:jungle_log)
B(-5,2,1,minecraft:jungle_log)
B(-5,3,1,minecraft:jungle_slab)
B(-5,-1,2,minecraft:grass_block)
B(-5,0,2,minecraft:jungle_fence[east=false,north=true,south=true,waterlogged=false,west=false])
B(-5,2,2,minecraft:jungle_slab[type=top,waterlogged=false])
B(-5,-1,3,minecraft:grass_block)
B(-5,0,3,minecraft:jungle_fence[east=false,north=true,south=true,waterlogged=false,west=false])
B(-5,-1,4,minecraft:jungle_log)
B(-5,0,4,minecraft:jungle_fence[east=true,north=true,south=false,waterlogged=false,west=false])
B(-4,-1,-5,minecraft:grass_block)
B(-4,-1,-4,minecraft:grass_block)
B(-4,0,-4,minecraft:jungle_fence[east=true,north=false,south=false,waterlogged=false,west=true])
B(-4,4,-4,minecraft:jungle_slab)
B(-4,-1,-3,minecraft:dirt)
B(-4,4,-3,minecraft:jungle_slab)
B(-4,-1,-2,minecraft:dirt)
B(-4,4,-2,minecraft:jungle_slab)
B(-4,-1,-1,minecraft:dirt)
B(-4,3,-1,minecraft:jungle_slab[type=top,waterlogged=false])
B(-4,4,-1,minecraft:jungle_slab)
B(-4,-1,0,minecraft:grass_path)
B(-4,3,0,minecraft:jungle_slab[type=double,waterlogged=false])
B(-4,-1,1,minecraft:grass_path)
B(-4,3,1,minecraft:jungle_slab)
B(-4,-1,2,minecraft:grass_path)
B(-4,3,2,minecraft:jungle_slab)
B(-4,-1,3,minecraft:grass_path)
B(-4,-1,4,minecraft:grass_block)
B(-4,0,4,minecraft:jungle_fence[east=true,north=false,south=false,waterlogged=false,west=true])
B(-3,-1,-5,minecraft:grass_block)
B(-3,-1,-4,minecraft:grass_block)
B(-3,0,-4,minecraft:jungle_fence[east=true,north=false,south=false,waterlogged=false,west=true])
B(-3,3,-4,minecraft:jungle_slab[type=top,waterlogged=false])
B(-3,-1,-3,minecraft:cauldron[level=3])
B(-3,4,-3,minecraft:jungle_slab)
B(-3,-1,-2,minecraft:grass_block)
B(-3,3,-2,minecraft:jungle_slab[type=top,waterlogged=false])
B(-3,-1,-1,minecraft:grass_path)
B(-3,3,-1,minecraft:jungle_slab[type=top,waterlogged=false])
B(-3,-1,0,minecraft:grass_path)
B(-3,3,0,minecraft:jungle_slab[type=double,waterlogged=false])
B(-3,-1,1,minecraft:grass_path)
B(-3,3,1,minecraft:jungle_slab)
B(-3,-1,2,minecraft:grass_path)
B(-3,3,2,minecraft:jungle_slab)
B(-3,-1,3,minecraft:grass_path)
B(-3,-1,4,minecraft:grass_block)
B(-3,0,4,minecraft:jungle_fence[east=true,north=false,south=false,waterlogged=false,west=true])
B(-3,-1,5,minecraft:grass_block)
B(-2,-1,-5,minecraft:grass_path)
B(-2,-1,-4,minecraft:jungle_log)
B(-2,0,-4,minecraft:jungle_log)
B(-2,1,-4,minecraft:jungle_log)
B(-2,2,-4,minecraft:jungle_log)
B(-2,3,-4,minecraft:jungle_log)
B(-2,4,-4,minecraft:jungle_slab)
B(-2,-1,-3,minecraft:cauldron[level=3])
B(-2,4,-3,minecraft:jungle_slab)
B(-2,-1,-2,minecraft:dirt)
B(-2,3,-2,minecraft:jungle_slab[type=top,waterlogged=false])
B(-2,-1,-1,minecraft:grass_path)
B(-2,3,-1,minecraft:jungle_slab[type=top,waterlogged=false])
B(-2,-1,0,minecraft:hay_block)
B(-2,3,0,minecraft:oak_slab[type=top,waterlogged=false])
B(-2,-1,1,minecraft:grass_path)
B(-2,3,1,minecraft:jungle_slab)
B(-2,-1,2,minecraft:grass_path)
B(-2,3,2,minecraft:jungle_slab)
B(-2,-1,3,minecraft:grass_path)
B(-2,-1,4,minecraft:jungle_log)
B(-2,0,4,minecraft:jungle_fence[east=true,north=false,south=false,waterlogged=false,west=true])
B(-2,-1,5,minecraft:grass_block)
B(-2,-1,6,minecraft:grass_block)
B(-1,-1,-5,minecraft:grass_path)
B(-1,-1,-4,minecraft:grass_block)
B(-1,0,-4,minecraft:jungle_fence[east=true,north=false,south=false,waterlogged=false,west=true])
B(-1,3,-4,minecraft:jungle_slab[type=top,waterlogged=false])
B(-1,-1,-3,minecraft:grass_path)
B(-1,4,-3,minecraft:jungle_slab)
B(-1,-1,-2,minecraft:grass_path)
B(-1,4,-2,minecraft:jungle_slab)
B(-1,-1,-1,minecraft:hay_block[axis=x])
B(-1,3,-1,minecraft:jungle_slab[type=top,waterlogged=false])
B(-1,-1,0,minecraft:hay_block)
B(-1,0,0,minecraft:hay_block)
B(-1,3,0,minecraft:jungle_slab)
B(-1,-1,1,minecraft:hay_block)
B(-1,3,1,minecraft:jungle_slab)
B(-1,-1,2,minecraft:grass_path)
B(-1,2,2,minecraft:jungle_slab[type=top,waterlogged=false])
B(-1,-1,3,minecraft:grass_path)
B(-1,-1,4,minecraft:grass_block)
B(-1,0,4,minecraft:spruce_fence_gate)
B(-1,-1,5,minecraft:grass_block)
B(-1,-1,6,minecraft:grass_block)
B(0,-1,-5,minecraft:grass_block)
B(0,-1,-4,minecraft:grass_block)
B(0,0,-4,minecraft:jungle_fence[east=true,north=false,south=false,waterlogged=false,west=true])
B(0,3,-4,minecraft:jungle_slab[type=top,waterlogged=false])
B(0,-1,-3,minecraft:grass_path)
B(0,3,-3,minecraft:jungle_slab[type=top,waterlogged=false])
B(0,-1,-2,minecraft:grass_path)
B(0,4,-2,minecraft:jungle_slab)
B(0,-1,-1,minecraft:grass_path)
B(0,3,-1,minecraft:jungle_slab[type=top,waterlogged=false])
B(0,-1,0,minecraft:hay_block[axis=x])
B(0,3,0,minecraft:jungle_slab)
B(0,-1,1,minecraft:hay_block[axis=x])
B(0,3,1,minecraft:jungle_slab)
B(0,-1,2,minecraft:grass_path)
B(0,2,2,minecraft:jungle_slab[type=top,waterlogged=false])
B(0,-1,3,minecraft:grass_block)
B(0,-1,4,minecraft:grass_block)
B(0,0,4,minecraft:spruce_fence_gate)
B(0,-1,5,minecraft:grass_block)
B(0,-1,6,minecraft:grass_block)
B(1,-1,-6,minecraft:grass_path)
B(1,-1,-5,minecraft:grass_path)
B(1,-1,-4,minecraft:jungle_log)
B(1,0,-4,minecraft:jungle_log)
B(1,1,-4,minecraft:jungle_log)
B(1,2,-4,minecraft:jungle_log)
B(1,3,-4,minecraft:jungle_log)
B(1,4,-4,minecraft:jungle_slab)
B(1,-1,-3,minecraft:dirt)
B(1,3,-3,minecraft:jungle_slab[type=top,waterlogged=false])
B(1,-1,-2,minecraft:grass_path)
B(1,4,-2,minecraft:jungle_slab)
B(1,-1,-1,minecraft:grass_path)
B(1,3,-1,minecraft:jungle_slab[type=top,waterlogged=false])
B(1,4,-1,minecraft:jungle_slab)
B(1,-1,0,minecraft:grass_path)
B(1,3,0,minecraft:oak_slab[type=top,waterlogged=false])
B(1,-1,1,minecraft:grass_path)
B(1,3,1,minecraft:jungle_slab)
B(1,-1,2,minecraft:grass_path)
B(1,2,2,minecraft:jungle_slab[type=top,waterlogged=false])
B(1,-1,3,minecraft:grass_block)
B(1,-1,4,minecraft:jungle_log)
B(1,0,4,minecraft:jungle_fence[east=true,north=false,south=false,waterlogged=false,west=true])
B(1,-1,5,minecraft:grass_block)
B(1,-1,6,minecraft:grass_block)
B(2,-1,-5,minecraft:grass_path)
B(2,-1,-4,minecraft:grass_block)
B(2,0,-4,minecraft:jungle_fence[east=true,north=false,south=false,waterlogged=false,west=true])
B(2,3,-4,minecraft:jungle_slab[type=top,waterlogged=false])
B(2,4,-4,minecraft:jungle_slab)
B(2,-1,-3,minecraft:grass_block)
B(2,4,-3,minecraft:jungle_slab)
B(2,-1,-2,minecraft:dirt)
B(2,4,-2,minecraft:jungle_slab)
B(2,-1,-1,minecraft:grass_path)
B(2,3,-1,minecraft:jungle_slab[type=top,waterlogged=false])
B(2,-1,0,minecraft:grass_path)
B(2,3,0,minecraft:oak_slab[type=top,waterlogged=false])
B(2,-1,1,minecraft:grass_path)
B(2,3,1,minecraft:jungle_slab)
B(2,-1,2,minecraft:grass_path)
B(2,3,2,minecraft:jungle_slab)
B(2,-1,3,minecraft:grass_path)
B(2,-1,4,minecraft:grass_block)
B(2,0,4,minecraft:jungle_fence[east=true,north=false,south=false,waterlogged=false,west=true])
B(2,-1,5,minecraft:grass_block)
B(3,-1,-5,minecraft:grass_block)
B(3,-1,-4,minecraft:grass_block)
B(3,0,-4,minecraft:jungle_fence[east=true,north=false,south=false,waterlogged=false,west=true])
B(3,3,-4,minecraft:jungle_slab[type=double,waterlogged=false])
B(3,-1,-3,minecraft:grass_path)
B(3,3,-3,minecraft:jungle_slab[type=top,waterlogged=false])
B(3,-1,-2,minecraft:dirt)
B(3,3,-2,minecraft:jungle_slab[type=top,waterlogged=false])
B(3,-1,-1,minecraft:grass_path)
B(3,3,-1,minecraft:jungle_slab[type=top,waterlogged=false])
B(3,-1,0,minecraft:dirt)
B(3,3,0,minecraft:jungle_slab)
B(3,-1,1,minecraft:grass_block)
B(3,3,1,minecraft:jungle_slab)
B(3,-1,2,minecraft:grass_path)
B(3,2,2,minecraft:jungle_slab[type=top,waterlogged=false])
B(3,-1,3,minecraft:grass_path)
B(3,-1,4,minecraft:grass_block)
B(3,0,4,minecraft:jungle_fence[east=true,north=false,south=false,waterlogged=false,west=true])
B(4,-1,-4,minecraft:jungle_log)
B(4,0,-4,minecraft:jungle_log)
B(4,1,-4,minecraft:jungle_log)
B(4,2,-4,minecraft:jungle_log)
B(4,3,-4,minecraft:jungle_slab)
B(4,-1,-3,minecraft:grass_block)
B(4,0,-3,minecraft:jungle_fence[east=false,north=true,south=true,waterlogged=false,west=false])
B(4,3,-3,minecraft:jungle_slab)
B(4,-1,-2,minecraft:grass_block)
B(4,0,-2,minecraft:jungle_fence[east=false,north=true,south=true,waterlogged=false,west=false])
B(4,3,-2,minecraft:jungle_slab)
B(4,-1,-1,minecraft:grass_block)
B(4,0,-1,minecraft:jungle_fence[east=false,north=true,south=true,waterlogged=false,west=false])
B(4,3,-1,minecraft:jungle_slab)
B(4,-1,0,minecraft:grass_block)
B(4,0,0,minecraft:jungle_fence[east=false,north=true,south=true,waterlogged=false,west=false])
B(4,3,0,minecraft:jungle_slab)
B(4,-1,1,minecraft:jungle_log)
B(4,0,1,minecraft:jungle_log)
B(4,1,1,minecraft:jungle_log)
B(4,2,1,minecraft:jungle_log)
B(4,3,1,minecraft:jungle_log)
B(4,4,1,minecraft:jungle_slab)
B(4,-1,2,minecraft:grass_block)
B(4,0,2,minecraft:jungle_fence[east=false,north=true,south=true,waterlogged=false,west=false])
B(4,2,2,minecraft:jungle_slab[type=top,waterlogged=false])
B(4,-1,3,minecraft:grass_block)
B(4,0,3,minecraft:jungle_fence[east=false,north=true,south=true,waterlogged=false,west=false])
B(4,-1,4,minecraft:jungle_log)
B(4,0,4,minecraft:jungle_fence[east=false,north=true,south=false,waterlogged=false,west=true])
B(5,2,-4,minecraft:jungle_slab[type=top,waterlogged=false])
B(5,2,-3,minecraft:jungle_slab[type=top,waterlogged=false])
B(5,3,-2,minecraft:jungle_slab)
B(5,-1,-1,minecraft:grass_path)
B(5,3,-1,minecraft:jungle_slab)
B(5,-1,0,minecraft:grass_path)
B(5,3,0,minecraft:jungle_slab)
B(5,-1,1,minecraft:grass_path)
B(5,2,1,minecraft:jungle_slab[type=top,waterlogged=false])
B(5,-1,2,minecraft:grass_path)

#######################################################################
# +-----------------------------------------------------------------+ #
# |                            BO3 checks                           | #
# +-----------------------------------------------------------------+ #
#######################################################################


#######################################################################
# +-----------------------------------------------------------------+ #
# |                             Branches                            | #
# +-----------------------------------------------------------------+ #
#######################################################################


#######################################################################
# +-----------------------------------------------------------------+ #
# |                             Entities                            | #
# +-----------------------------------------------------------------+ #
#######################################################################

Entity(1,0,-3,minecraft:mule,1,../JungleNBT/entities/donkey.txt)
Entity(-4,0,-2,minecraft:mule,1,../JungleNBT/entities/donkey.txt)
Entity(0,0,1,minecraft:villager,1,../JungleNBT/entities/tribalherder.txt)
