
#######################################################################
# +-----------------------------------------------------------------+ #
# |                            BO3 object                           | #
# +-----------------------------------------------------------------+ #
#######################################################################

Author: BO3 BulkEdit (by LanToaster)

Description: This Object was Created with BO3_BulkEdit

Version: 3

SettingsMode: WriteWithoutComments


#######################################################################
# +-----------------------------------------------------------------+ #
# |                          Main settings                          | #
# +-----------------------------------------------------------------+ #
#######################################################################

Tree: false

Frequency: 100

Rarity: 100.0

RotateRandomly: true

SpawnHeight: randomY

SpawnHeightOffset: 0

SpawnHeightVariance: 0

##############################
# Height Limits for the BO3. #
##############################

MinHeight: 82

MaxHeight: 82

######################
# Extrusion settings #
######################

ExtrudeMode: None

ExtrudeThroughBlocks: otg:air

MaxBranchDepth: 50


#######################################################################
# +-----------------------------------------------------------------+ #
# |                      Source block settings                      | #
# +-----------------------------------------------------------------+ #
#######################################################################

SourceBlocks: otg:air

MaxPercentageOutsideSourceBlock: 100

OutsideSourceBlock: placeAnyway

DoReplaceBlocks: true

IsOTGPlus: false


#######################################################################
# +-----------------------------------------------------------------+ #
# |                              Blocks                             | #
# +-----------------------------------------------------------------+ #
#######################################################################

B(-7,0,-1,minecraft:ladder[facing=west,waterlogged=false])
B(-7,1,-1,minecraft:ladder[facing=west,waterlogged=false])
B(-6,-1,-2,minecraft:dark_oak_planks)
B(-6,0,-2,minecraft:dark_oak_planks)
B(-6,1,-2,minecraft:dark_oak_stairs[facing=south,half=bottom,shape=straight,waterlogged=false])
B(-6,-1,-1,minecraft:dark_oak_planks)
B(-6,0,-1,minecraft:dark_oak_planks)
B(-6,1,-1,minecraft:dark_oak_planks)
B(-6,2,-1,minecraft:ladder[facing=west,waterlogged=false])
B(-6,3,-1,minecraft:ladder[facing=west,waterlogged=false])
B(-6,4,-1,minecraft:ladder[facing=west,waterlogged=false])
B(-6,5,-1,minecraft:ladder[facing=west,waterlogged=false])
B(-6,-1,0,minecraft:dark_oak_planks)
B(-6,0,0,minecraft:dark_oak_planks)
B(-6,1,0,minecraft:dark_oak_stairs[facing=east,half=bottom,shape=straight,waterlogged=false])
B(-5,-1,-3,minecraft:terracotta)
B(-5,0,-3,minecraft:coarse_dirt)
B(-5,1,-3,minecraft:coarse_dirt)
B(-5,2,-3,minecraft:terracotta)
B(-5,3,-3,minecraft:brick_slab)
B(-5,8,-3,minecraft:oak_trapdoor[facing=east,half=bottom,open=true,powered=false,waterlogged=false])
B(-5,-1,-2,minecraft:terracotta)
B(-5,0,-2,minecraft:terracotta)
B(-5,1,-2,minecraft:dirt)
B(-5,2,-2,minecraft:dirt)
B(-5,3,-2,minecraft:coarse_dirt)
B(-5,4,-2,minecraft:dark_oak_stairs[facing=east,half=bottom,shape=straight,waterlogged=false])
B(-5,-1,-1,minecraft:terracotta)
B(-5,0,-1,minecraft:terracotta)
B(-5,1,-1,minecraft:terracotta)
B(-5,2,-1,minecraft:dark_oak_planks)
B(-5,3,-1,minecraft:dark_oak_planks)
B(-5,4,-1,minecraft:dark_oak_planks)
B(-5,5,-1,minecraft:dark_oak_planks)
B(-5,6,-1,minecraft:ladder[facing=west,waterlogged=false])
B(-5,7,-1,minecraft:ladder[facing=west,waterlogged=false])
B(-5,8,-1,minecraft:ladder[facing=west,waterlogged=false])
B(-5,-1,0,minecraft:terracotta)
B(-5,0,0,minecraft:terracotta)
B(-5,1,0,minecraft:terracotta)
B(-5,2,0,minecraft:terracotta)
B(-5,3,0,minecraft:terracotta)
B(-5,4,0,minecraft:dark_oak_stairs[facing=east,half=bottom,shape=straight,waterlogged=false])
B(-5,-1,1,minecraft:terracotta)
B(-5,0,1,minecraft:terracotta)
B(-5,1,1,minecraft:terracotta)
B(-5,2,1,minecraft:dirt)
B(-5,3,1,minecraft:brick_slab)
B(-5,8,1,minecraft:oak_trapdoor[facing=east,half=bottom,open=true,powered=false,waterlogged=false])
B(-4,-1,-4,minecraft:dirt)
B(-4,0,-4,minecraft:terracotta)
B(-4,1,-4,minecraft:coarse_dirt)
B(-4,2,-4,minecraft:terracotta)
B(-4,3,-4,minecraft:brick_slab)
B(-4,8,-4,minecraft:oak_trapdoor[facing=south,half=bottom,open=true,powered=false,waterlogged=false])
B(-4,-1,-3,minecraft:dirt)
B(-4,0,-3,minecraft:dirt)
B(-4,1,-3,minecraft:dirt)
B(-4,2,-3,minecraft:terracotta)
B(-4,3,-3,minecraft:terracotta)
B(-4,4,-3,minecraft:terracotta)
B(-4,5,-3,minecraft:gray_terracotta)
B(-4,6,-3,minecraft:black_terracotta)
B(-4,7,-3,minecraft:terracotta)
B(-4,8,-3,minecraft:spruce_log)
B(-4,9,-3,minecraft:spruce_log)
B(-4,10,-3,minecraft:spruce_log)
B(-4,11,-3,minecraft:spruce_log)
B(-4,12,-3,minecraft:oak_fence)
B(-4,13,-3,minecraft:oak_fence)
B(-4,14,-3,minecraft:torch)
B(-4,-1,-2,minecraft:dirt)
B(-4,0,-2,minecraft:dirt)
B(-4,1,-2,minecraft:dirt)
B(-4,2,-2,minecraft:dirt)
B(-4,3,-2,minecraft:terracotta)
B(-4,4,-2,minecraft:terracotta)
B(-4,5,-2,minecraft:black_terracotta)
B(-4,6,-2,minecraft:gray_terracotta)
B(-4,7,-2,minecraft:dirt)
B(-4,8,-2,minecraft:terracotta)
B(-4,9,-2,minecraft:oak_trapdoor[facing=west,half=bottom,open=true,powered=false,waterlogged=false])
B(-4,11,-2,minecraft:spruce_slab[type=top,waterlogged=false])
B(-4,-1,-1,minecraft:dirt)
B(-4,0,-1,minecraft:dirt)
B(-4,1,-1,minecraft:dirt)
B(-4,2,-1,minecraft:dirt)
B(-4,3,-1,minecraft:terracotta)
B(-4,4,-1,minecraft:dark_oak_planks)
B(-4,5,-1,minecraft:dark_oak_planks)
B(-4,6,-1,minecraft:dark_oak_planks)
B(-4,7,-1,minecraft:dark_oak_planks)
B(-4,8,-1,minecraft:dark_oak_planks)
B(-4,11,-1,minecraft:spruce_slab[type=top,waterlogged=false])
B(-4,-1,0,minecraft:dirt)
B(-4,0,0,minecraft:dirt)
B(-4,1,0,minecraft:dirt)
B(-4,2,0,minecraft:dirt)
B(-4,3,0,minecraft:terracotta)
B(-4,4,0,minecraft:terracotta)
B(-4,5,0,minecraft:black_terracotta)
B(-4,6,0,minecraft:gray_terracotta)
B(-4,7,0,minecraft:terracotta)
B(-4,8,0,minecraft:terracotta)
B(-4,9,0,minecraft:oak_trapdoor[facing=west,half=bottom,open=true,powered=false,waterlogged=false])
B(-4,11,0,minecraft:spruce_slab[type=top,waterlogged=false])
B(-4,-1,1,minecraft:dirt)
B(-4,0,1,minecraft:dirt)
B(-4,1,1,minecraft:dirt)
B(-4,2,1,minecraft:terracotta)
B(-4,3,1,minecraft:terracotta)
B(-4,4,1,minecraft:terracotta)
B(-4,5,1,minecraft:gray_terracotta)
B(-4,6,1,minecraft:black_terracotta)
B(-4,7,1,minecraft:terracotta)
B(-4,8,1,minecraft:spruce_log)
B(-4,9,1,minecraft:spruce_log)
B(-4,10,1,minecraft:spruce_log)
B(-4,11,1,minecraft:spruce_log)
B(-4,12,1,minecraft:oak_fence)
B(-4,13,1,minecraft:oak_fence)
B(-4,14,1,minecraft:torch)
B(-4,-1,2,minecraft:dirt)
B(-4,0,2,minecraft:dirt)
B(-4,1,2,minecraft:dirt)
B(-4,2,2,minecraft:terracotta)
B(-4,3,2,minecraft:brick_slab)
B(-4,8,2,minecraft:oak_trapdoor[facing=north,half=bottom,open=true,powered=false,waterlogged=false])
B(-3,-1,-4,minecraft:dirt)
B(-3,0,-4,minecraft:terracotta)
B(-3,1,-4,minecraft:terracotta)
B(-3,2,-4,minecraft:coarse_dirt)
B(-3,3,-4,minecraft:terracotta)
B(-3,-1,-3,minecraft:dirt)
B(-3,0,-3,minecraft:dirt)
B(-3,1,-3,minecraft:dirt)
B(-3,2,-3,minecraft:dirt)
B(-3,3,-3,minecraft:terracotta)
B(-3,4,-3,minecraft:terracotta)
B(-3,5,-3,minecraft:black_terracotta)
B(-3,6,-3,minecraft:gray_terracotta)
B(-3,7,-3,minecraft:coarse_dirt)
B(-3,8,-3,minecraft:terracotta)
B(-3,9,-3,minecraft:oak_trapdoor[facing=north,half=bottom,open=true,powered=false,waterlogged=false])
B(-3,11,-3,minecraft:spruce_slab[type=top,waterlogged=false])
B(-3,-1,-2,minecraft:dirt)
B(-3,0,-2,minecraft:dirt)
B(-3,1,-2,minecraft:dirt)
B(-3,2,-2,minecraft:dirt)
B(-3,3,-2,minecraft:dirt)
B(-3,4,-2,minecraft:dirt)
B(-3,5,-2,minecraft:dirt)
B(-3,6,-2,minecraft:dirt)
B(-3,7,-2,minecraft:dirt)
B(-3,8,-2,minecraft:coarse_dirt)
B(-3,11,-2,minecraft:spruce_slab[type=top,waterlogged=false])
B(-3,-1,-1,minecraft:dirt)
B(-3,0,-1,minecraft:dirt)
B(-3,1,-1,minecraft:dirt)
B(-3,2,-1,minecraft:dirt)
B(-3,3,-1,minecraft:dirt)
B(-3,4,-1,minecraft:dirt)
B(-3,5,-1,minecraft:dirt)
B(-3,6,-1,minecraft:dirt)
B(-3,7,-1,minecraft:dirt)
B(-3,8,-1,minecraft:coarse_dirt)
B(-3,11,-1,minecraft:spruce_slab[type=top,waterlogged=false])
B(-3,-1,0,minecraft:dirt)
B(-3,0,0,minecraft:dirt)
B(-3,1,0,minecraft:dirt)
B(-3,2,0,minecraft:dirt)
B(-3,3,0,minecraft:dirt)
B(-3,4,0,minecraft:dirt)
B(-3,5,0,minecraft:dirt)
B(-3,6,0,minecraft:dirt)
B(-3,7,0,minecraft:dirt)
B(-3,8,0,minecraft:coarse_dirt)
B(-3,11,0,minecraft:spruce_slab[type=top,waterlogged=false])
B(-3,-1,1,minecraft:dirt)
B(-3,0,1,minecraft:dirt)
B(-3,1,1,minecraft:dirt)
B(-3,2,1,minecraft:dirt)
B(-3,3,1,minecraft:terracotta)
B(-3,4,1,minecraft:dirt)
B(-3,5,1,minecraft:black_terracotta)
B(-3,6,1,minecraft:gray_terracotta)
B(-3,7,1,minecraft:dirt)
B(-3,8,1,minecraft:coarse_dirt)
B(-3,11,1,minecraft:spruce_slab[type=top,waterlogged=false])
B(-3,-1,2,minecraft:terracotta)
B(-3,0,2,minecraft:terracotta)
B(-3,1,2,minecraft:terracotta)
B(-3,2,2,minecraft:terracotta)
B(-3,3,2,minecraft:terracotta)
B(-3,9,2,minecraft:oak_trapdoor[facing=north,half=bottom,open=true,powered=false,waterlogged=false])
B(-2,-1,-4,minecraft:dirt)
B(-2,0,-4,minecraft:terracotta)
B(-2,1,-4,minecraft:terracotta)
B(-2,2,-4,minecraft:coarse_dirt)
B(-2,3,-4,minecraft:coarse_dirt)
B(-2,9,-4,minecraft:oak_trapdoor[facing=south,half=bottom,open=true,powered=false,waterlogged=false])
B(-2,-1,-3,minecraft:dirt)
B(-2,0,-3,minecraft:dirt)
B(-2,1,-3,minecraft:dirt)
B(-2,2,-3,minecraft:dirt)
B(-2,3,-3,minecraft:terracotta)
B(-2,4,-3,minecraft:terracotta)
B(-2,5,-3,minecraft:gray_terracotta)
B(-2,6,-3,minecraft:black_terracotta)
B(-2,7,-3,minecraft:coarse_dirt)
B(-2,8,-3,minecraft:terracotta)
B(-2,12,-3,minecraft:spruce_slab)
B(-2,-1,-2,minecraft:dirt)
B(-2,0,-2,minecraft:dirt)
B(-2,1,-2,minecraft:dirt)
B(-2,2,-2,minecraft:dirt)
B(-2,3,-2,minecraft:dirt)
B(-2,4,-2,minecraft:dirt)
B(-2,5,-2,minecraft:dirt)
B(-2,6,-2,minecraft:dirt)
B(-2,7,-2,minecraft:dirt)
B(-2,8,-2,minecraft:coarse_dirt)
B(-2,12,-2,minecraft:spruce_slab)
B(-2,-1,-1,minecraft:dirt)
B(-2,0,-1,minecraft:dirt)
B(-2,1,-1,minecraft:dirt)
B(-2,2,-1,minecraft:dirt)
B(-2,3,-1,minecraft:dirt)
B(-2,4,-1,minecraft:dirt)
B(-2,5,-1,minecraft:dirt)
B(-2,6,-1,minecraft:dirt)
B(-2,7,-1,minecraft:dirt)
B(-2,8,-1,minecraft:coarse_dirt)
B(-2,12,-1,minecraft:spruce_slab)
B(-2,-1,0,minecraft:dirt)
B(-2,0,0,minecraft:dirt)
B(-2,1,0,minecraft:dirt)
B(-2,2,0,minecraft:dirt)
B(-2,3,0,minecraft:dirt)
B(-2,4,0,minecraft:dirt)
B(-2,5,0,minecraft:dirt)
B(-2,6,0,minecraft:dirt)
B(-2,7,0,minecraft:dirt)
B(-2,8,0,minecraft:coarse_dirt)
B(-2,12,0,minecraft:spruce_slab)
B(-2,-1,1,minecraft:dirt)
B(-2,0,1,minecraft:dirt)
B(-2,1,1,minecraft:dirt)
B(-2,2,1,minecraft:dirt)
B(-2,3,1,minecraft:terracotta)
B(-2,4,1,minecraft:terracotta)
B(-2,5,1,minecraft:gray_terracotta)
B(-2,6,1,minecraft:black_terracotta)
B(-2,7,1,minecraft:dirt)
B(-2,8,1,minecraft:terracotta)
B(-2,12,1,minecraft:spruce_slab)
B(-2,-1,2,minecraft:dirt)
B(-2,0,2,minecraft:dirt)
B(-2,1,2,minecraft:dirt)
B(-2,2,2,minecraft:terracotta)
B(-2,3,2,minecraft:terracotta)
B(-2,9,2,minecraft:oak_trapdoor[facing=north,half=bottom,open=true,powered=false,waterlogged=false])
B(-1,-1,-4,minecraft:terracotta)
B(-1,0,-4,minecraft:dirt)
B(-1,1,-4,minecraft:dirt)
B(-1,2,-4,minecraft:terracotta)
B(-1,3,-4,minecraft:terracotta)
B(-1,9,-4,minecraft:oak_trapdoor[facing=south,half=bottom,open=true,powered=false,waterlogged=false])
B(-1,-1,-3,minecraft:dirt)
B(-1,0,-3,minecraft:dirt)
B(-1,1,-3,minecraft:dirt)
B(-1,2,-3,minecraft:dirt)
B(-1,3,-3,minecraft:terracotta)
B(-1,4,-3,minecraft:coarse_dirt)
B(-1,5,-3,minecraft:black_terracotta)
B(-1,6,-3,minecraft:gray_terracotta)
B(-1,7,-3,minecraft:dirt)
B(-1,8,-3,minecraft:coarse_dirt)
B(-1,12,-3,minecraft:spruce_slab)
B(-1,-1,-2,minecraft:dirt)
B(-1,0,-2,minecraft:dirt)
B(-1,1,-2,minecraft:dirt)
B(-1,2,-2,minecraft:dirt)
B(-1,3,-2,minecraft:dirt)
B(-1,4,-2,minecraft:dirt)
B(-1,5,-2,minecraft:dirt)
B(-1,6,-2,minecraft:dirt)
B(-1,7,-2,minecraft:dirt)
B(-1,8,-2,minecraft:coarse_dirt)
B(-1,12,-2,minecraft:spruce_slab)
B(-1,-1,-1,minecraft:dirt)
B(-1,0,-1,minecraft:dirt)
B(-1,1,-1,minecraft:dirt)
B(-1,2,-1,minecraft:dirt)
B(-1,3,-1,minecraft:dirt)
B(-1,4,-1,minecraft:dirt)
B(-1,5,-1,minecraft:dirt)
B(-1,6,-1,minecraft:dirt)
B(-1,7,-1,minecraft:dirt)
B(-1,8,-1,minecraft:coarse_dirt)
B(-1,12,-1,minecraft:spruce_slab)
B(-1,-1,0,minecraft:dirt)
B(-1,0,0,minecraft:dirt)
B(-1,1,0,minecraft:dirt)
B(-1,2,0,minecraft:dirt)
B(-1,3,0,minecraft:dirt)
B(-1,4,0,minecraft:dirt)
B(-1,5,0,minecraft:dirt)
B(-1,6,0,minecraft:dirt)
B(-1,7,0,minecraft:dirt)
B(-1,8,0,minecraft:coarse_dirt)
B(-1,12,0,minecraft:spruce_slab)
B(-1,-1,1,minecraft:dirt)
B(-1,0,1,minecraft:dirt)
B(-1,1,1,minecraft:dirt)
B(-1,2,1,minecraft:dirt)
B(-1,3,1,minecraft:terracotta)
B(-1,4,1,minecraft:terracotta)
B(-1,5,1,minecraft:black_terracotta)
B(-1,6,1,minecraft:gray_terracotta)
B(-1,7,1,minecraft:terracotta)
B(-1,8,1,minecraft:coarse_dirt)
B(-1,12,1,minecraft:spruce_slab)
B(-1,-1,2,minecraft:terracotta)
B(-1,0,2,minecraft:dirt)
B(-1,1,2,minecraft:terracotta)
B(-1,2,2,minecraft:terracotta)
B(-1,3,2,minecraft:dirt)
B(-1,9,2,minecraft:oak_trapdoor[facing=north,half=bottom,open=true,powered=false,waterlogged=false])
B(0,-1,-4,minecraft:terracotta)
B(0,0,-4,minecraft:terracotta)
B(0,1,-4,minecraft:terracotta)
B(0,2,-4,minecraft:dirt)
B(0,3,-4,minecraft:brick_slab)
B(0,8,-4,minecraft:oak_trapdoor[facing=south,half=bottom,open=true,powered=false,waterlogged=false])
B(0,-1,-3,minecraft:dirt)
B(0,0,-3,minecraft:dirt)
B(0,1,-3,minecraft:dirt)
B(0,2,-3,minecraft:terracotta)
B(0,3,-3,minecraft:terracotta)
B(0,4,-3,minecraft:terracotta)
B(0,5,-3,minecraft:gray_terracotta)
B(0,6,-3,minecraft:black_terracotta)
B(0,7,-3,minecraft:terracotta)
B(0,8,-3,minecraft:spruce_log)
B(0,9,-3,minecraft:spruce_log)
B(0,10,-3,minecraft:spruce_log)
B(0,11,-3,minecraft:spruce_log)
B(0,12,-3,minecraft:spruce_log)
B(0,13,-3,minecraft:oak_fence)
B(0,14,-3,minecraft:torch)
B(0,-1,-2,minecraft:dirt)
B(0,0,-2,minecraft:dirt)
B(0,1,-2,minecraft:dirt)
B(0,2,-2,minecraft:dirt)
B(0,3,-2,minecraft:terracotta)
B(0,4,-2,minecraft:terracotta)
B(0,5,-2,minecraft:black_terracotta)
B(0,6,-2,minecraft:gray_terracotta)
B(0,7,-2,minecraft:terracotta)
B(0,8,-2,minecraft:terracotta)
B(0,9,-2,minecraft:oak_trapdoor[facing=east,half=bottom,open=true,powered=false,waterlogged=false])
B(0,12,-2,minecraft:spruce_slab)
B(0,-1,-1,minecraft:dirt)
B(0,0,-1,minecraft:dirt)
B(0,1,-1,minecraft:dirt)
B(0,2,-1,minecraft:dirt)
B(0,3,-1,minecraft:terracotta)
B(0,4,-1,minecraft:terracotta)
B(0,5,-1,minecraft:gray_terracotta)
B(0,6,-1,minecraft:black_terracotta)
B(0,7,-1,minecraft:dirt)
B(0,8,-1,minecraft:terracotta)
B(0,9,-1,minecraft:oak_trapdoor[facing=east,half=bottom,open=true,powered=false,waterlogged=false])
B(0,12,-1,minecraft:spruce_slab)
B(0,-1,0,minecraft:dirt)
B(0,0,0,minecraft:dirt)
B(0,1,0,minecraft:dirt)
B(0,2,0,minecraft:dirt)
B(0,3,0,minecraft:terracotta)
B(0,4,0,minecraft:terracotta)
B(0,5,0,minecraft:black_terracotta)
B(0,6,0,minecraft:gray_terracotta)
B(0,7,0,minecraft:dirt)
B(0,8,0,minecraft:coarse_dirt)
B(0,12,0,minecraft:spruce_slab)
B(0,-1,1,minecraft:dirt)
B(0,0,1,minecraft:dirt)
B(0,1,1,minecraft:dirt)
B(0,2,1,minecraft:terracotta)
B(0,3,1,minecraft:terracotta)
B(0,4,1,minecraft:terracotta)
B(0,5,1,minecraft:gray_terracotta)
B(0,6,1,minecraft:black_terracotta)
B(0,7,1,minecraft:terracotta)
B(0,8,1,minecraft:spruce_log)
B(0,9,1,minecraft:spruce_log)
B(0,10,1,minecraft:spruce_log)
B(0,11,1,minecraft:spruce_log)
B(0,12,1,minecraft:spruce_log)
B(0,13,1,minecraft:oak_fence)
B(0,14,1,minecraft:torch)
B(0,-1,2,minecraft:terracotta)
B(0,0,2,minecraft:terracotta)
B(0,1,2,minecraft:terracotta)
B(0,2,2,minecraft:terracotta)
B(0,3,2,minecraft:brick_slab)
B(0,8,2,minecraft:oak_trapdoor[facing=north,half=bottom,open=true,powered=false,waterlogged=false])
B(1,-1,-3,minecraft:terracotta)
B(1,0,-3,minecraft:dirt)
B(1,1,-3,minecraft:dirt)
B(1,2,-3,minecraft:terracotta)
B(1,3,-3,minecraft:brick_slab)
B(1,8,-3,minecraft:oak_trapdoor[facing=west,half=bottom,open=true,powered=false,waterlogged=false])
B(1,-1,-2,minecraft:dirt)
B(1,0,-2,minecraft:terracotta)
B(1,1,-2,minecraft:coarse_dirt)
B(1,2,-2,minecraft:terracotta)
B(1,3,-2,minecraft:dirt)
B(1,-1,-1,minecraft:dirt)
B(1,0,-1,minecraft:terracotta)
B(1,1,-1,minecraft:coarse_dirt)
B(1,2,-1,minecraft:terracotta)
B(1,3,-1,minecraft:dirt)
B(1,-1,0,minecraft:terracotta)
B(1,0,0,minecraft:terracotta)
B(1,1,0,minecraft:terracotta)
B(1,2,0,minecraft:coarse_dirt)
B(1,3,0,minecraft:terracotta)
B(1,9,0,minecraft:oak_trapdoor[facing=west,half=bottom,open=true,powered=false,waterlogged=false])
B(1,-1,1,minecraft:terracotta)
B(1,0,1,minecraft:terracotta)
B(1,1,1,minecraft:terracotta)
B(1,2,1,minecraft:terracotta)
B(1,3,1,minecraft:brick_slab)
B(1,8,1,minecraft:oak_trapdoor[facing=west,half=bottom,open=true,powered=false,waterlogged=false])

#######################################################################
# +-----------------------------------------------------------------+ #
# |                            BO3 checks                           | #
# +-----------------------------------------------------------------+ #
#######################################################################


#######################################################################
# +-----------------------------------------------------------------+ #
# |                             Branches                            | #
# +-----------------------------------------------------------------+ #
#######################################################################


#######################################################################
# +-----------------------------------------------------------------+ #
# |                             Entities                            | #
# +-----------------------------------------------------------------+ #
#######################################################################

Entity(-3,9,-2,minecraft:villager,1,../JungleNBT/entities/tribalbowman.txt)
