
#######################################################################
# +-----------------------------------------------------------------+ #
# |                            BO3 object                           | #
# +-----------------------------------------------------------------+ #
#######################################################################

Author: BO3 BulkEdit (by LanToaster)

Description: This Object was Created with BO3_BulkEdit

Version: 3

SettingsMode: WriteWithoutComments


#######################################################################
# +-----------------------------------------------------------------+ #
# |                          Main settings                          | #
# +-----------------------------------------------------------------+ #
#######################################################################

Tree: false

Frequency: 100

Rarity: 100.0

RotateRandomly: true

SpawnHeight: randomY

SpawnHeightOffset: 0

SpawnHeightVariance: 0

##############################
# Height Limits for the BO3. #
##############################

MinHeight: 82

MaxHeight: 82

######################
# Extrusion settings #
######################

ExtrudeMode: None

ExtrudeThroughBlocks: minecraft:air

MaxBranchDepth: 50


#######################################################################
# +-----------------------------------------------------------------+ #
# |                      Source block settings                      | #
# +-----------------------------------------------------------------+ #
#######################################################################

SourceBlocks: otg:air

MaxPercentageOutsideSourceBlock: 100

OutsideSourceBlock: placeAnyway

DoReplaceBlocks: true

IsOTGPlus: false


#######################################################################
# +-----------------------------------------------------------------+ #
# |                              Blocks                             | #
# +-----------------------------------------------------------------+ #
#######################################################################

B(-6,-1,-2,minecraft:grass_path)
B(-6,-1,-1,minecraft:grass_path)
B(-6,-1,0,minecraft:grass_path)
B(-6,-1,1,minecraft:grass_path)
B(-6,-1,2,minecraft:grass_path)
B(-5,-1,-3,minecraft:grass_path)
B(-5,-1,-2,minecraft:grass_path)
B(-5,-1,-1,minecraft:grass_path)
B(-5,-1,0,minecraft:grass_path)
B(-5,-1,1,minecraft:grass_path)
B(-5,-1,2,minecraft:grass_path)
B(-5,-1,3,minecraft:grass_path)
B(-5,-1,4,minecraft:grass_path)
B(-4,-1,-4,minecraft:grass_path)
B(-4,-1,-3,minecraft:cobblestone)
B(-4,0,-3,minecraft:jungle_log)
B(-4,1,-3,minecraft:jungle_log)
B(-4,2,-3,minecraft:jungle_log)
B(-4,3,-3,minecraft:jungle_log)
B(-4,4,-3,minecraft:jungle_log)
B(-4,5,-3,minecraft:cobblestone_wall)
B(-4,6,-3,minecraft:cobblestone_wall)
B(-4,7,-3,minecraft:cobblestone_wall[east=low,north=none,south=low,up=true,waterlogged=false,west=none])
B(-4,8,-3,minecraft:torch)
B(-4,-1,-2,minecraft:grass_path)
B(-4,6,-2,minecraft:spruce_slab[type=top,waterlogged=false])
B(-4,7,-2,minecraft:light_blue_terracotta)
B(-4,8,-2,minecraft:light_blue_terracotta)
B(-4,9,-2,minecraft:oak_stairs[facing=south,half=bottom,shape=outer_left,waterlogged=false])
B(-4,-1,-1,minecraft:grass_path)
B(-4,6,-1,minecraft:oak_stairs[facing=south,half=top,shape=straight,waterlogged=false])
B(-4,7,-1,minecraft:light_blue_terracotta)
B(-4,8,-1,minecraft:light_blue_terracotta)
B(-4,9,-1,minecraft:oak_stairs[facing=east,half=bottom,shape=straight,waterlogged=false])
B(-4,-1,0,minecraft:cobblestone)
B(-4,0,0,minecraft:spruce_fence)
B(-4,1,0,minecraft:spruce_fence)
B(-4,2,0,minecraft:spruce_fence)
B(-4,3,0,minecraft:spruce_fence)
B(-4,4,0,minecraft:spruce_fence[east=true,north=false,south=false,waterlogged=false,west=false])
B(-4,5,0,minecraft:hopper)
B(-4,6,0,minecraft:light_blue_terracotta)
B(-4,7,0,minecraft:light_blue_terracotta)
B(-4,8,0,minecraft:light_blue_terracotta)
B(-4,9,0,minecraft:oak_stairs[facing=east,half=bottom,shape=straight,waterlogged=false])
B(-4,-1,1,minecraft:grass_path)
B(-4,6,1,minecraft:oak_stairs[facing=north,half=top,shape=straight,waterlogged=false])
B(-4,7,1,minecraft:light_blue_terracotta)
B(-4,8,1,minecraft:light_blue_terracotta)
B(-4,9,1,minecraft:oak_stairs[facing=east,half=bottom,shape=straight,waterlogged=false])
B(-4,-1,2,minecraft:grass_path)
B(-4,6,2,minecraft:spruce_slab[type=top,waterlogged=false])
B(-4,7,2,minecraft:light_blue_terracotta)
B(-4,8,2,minecraft:light_blue_terracotta)
B(-4,9,2,minecraft:oak_stairs[facing=east,half=bottom,shape=outer_left,waterlogged=false])
B(-4,-1,3,minecraft:cobblestone)
B(-4,0,3,minecraft:jungle_log)
B(-4,1,3,minecraft:jungle_log)
B(-4,2,3,minecraft:jungle_log)
B(-4,3,3,minecraft:jungle_log)
B(-4,4,3,minecraft:jungle_log)
B(-4,5,3,minecraft:cobblestone_wall)
B(-4,6,3,minecraft:cobblestone_wall)
B(-4,7,3,minecraft:cobblestone_wall[east=low,north=low,south=none,up=true,waterlogged=false,west=none])
B(-4,8,3,minecraft:torch)
B(-4,-1,4,minecraft:grass_path)
B(-4,-1,5,minecraft:grass_path)
B(-3,-1,-5,minecraft:grass_path)
B(-3,-1,-4,minecraft:grass_path)
B(-3,-1,-3,minecraft:grass_path)
B(-3,6,-3,minecraft:spruce_slab[type=top,waterlogged=false])
B(-3,7,-3,minecraft:light_blue_terracotta)
B(-3,8,-3,minecraft:light_blue_terracotta)
B(-3,9,-3,minecraft:oak_stairs[facing=south,half=bottom,shape=outer_left,waterlogged=false])
B(-3,-1,-2,minecraft:cobblestone)
B(-3,6,-2,minecraft:spruce_slab[type=double,waterlogged=false])
B(-3,7,-2,minecraft:light_blue_terracotta)
B(-3,8,-2,minecraft:light_blue_terracotta)
B(-3,9,-2,minecraft:oak_stairs[facing=east,half=bottom,shape=inner_right,waterlogged=false])
B(-3,-1,-1,minecraft:cobblestone)
B(-3,5,-1,minecraft:oak_stairs[facing=south,half=top,shape=straight,waterlogged=false])
B(-3,6,-1,minecraft:oak_planks)
B(-3,7,-1,minecraft:water)
B(-3,8,-1,minecraft:water)
B(-3,9,-1,minecraft:water)
B(-3,10,-1,minecraft:spruce_slab)
B(-3,-1,0,minecraft:cobblestone)
B(-3,3,0,minecraft:oak_stairs[facing=east,half=top,shape=straight,waterlogged=false])
B(-3,4,0,minecraft:oak_planks)
B(-3,5,0,minecraft:oak_planks)
B(-3,6,0,minecraft:oak_planks)
B(-3,7,0,minecraft:water)
B(-3,8,0,minecraft:water)
B(-3,9,0,minecraft:water)
B(-3,10,0,minecraft:spruce_slab)
B(-3,-1,1,minecraft:cobblestone)
B(-3,5,1,minecraft:oak_stairs[facing=north,half=top,shape=straight,waterlogged=false])
B(-3,6,1,minecraft:oak_planks)
B(-3,7,1,minecraft:water)
B(-3,8,1,minecraft:water)
B(-3,9,1,minecraft:water)
B(-3,10,1,minecraft:spruce_slab)
B(-3,-1,2,minecraft:cobblestone)
B(-3,6,2,minecraft:spruce_slab[type=double,waterlogged=false])
B(-3,7,2,minecraft:light_blue_terracotta)
B(-3,8,2,minecraft:light_blue_terracotta)
B(-3,9,2,minecraft:oak_stairs[facing=north,half=bottom,shape=inner_right,waterlogged=false])
B(-3,-1,3,minecraft:grass_path)
B(-3,6,3,minecraft:spruce_slab[type=top,waterlogged=false])
B(-3,7,3,minecraft:light_blue_terracotta)
B(-3,8,3,minecraft:light_blue_terracotta)
B(-3,9,3,minecraft:oak_stairs[facing=east,half=bottom,shape=outer_left,waterlogged=false])
B(-3,-1,4,minecraft:grass_path)
B(-3,-1,5,minecraft:grass_path)
B(-2,-1,-6,minecraft:grass_path)
B(-2,-1,-5,minecraft:grass_path)
B(-2,-1,-4,minecraft:grass_path)
B(-2,-1,-3,minecraft:grass_path)
B(-2,6,-3,minecraft:oak_stairs[facing=east,half=top,shape=straight,waterlogged=false])
B(-2,7,-3,minecraft:light_blue_terracotta)
B(-2,8,-3,minecraft:light_blue_terracotta)
B(-2,9,-3,minecraft:oak_stairs[facing=south,half=bottom,shape=straight,waterlogged=false])
B(-2,-1,-2,minecraft:cobblestone)
B(-2,5,-2,minecraft:oak_stairs[facing=east,half=top,shape=straight,waterlogged=false])
B(-2,6,-2,minecraft:oak_planks)
B(-2,7,-2,minecraft:water)
B(-2,8,-2,minecraft:water)
B(-2,9,-2,minecraft:water)
B(-2,10,-2,minecraft:spruce_slab)
B(-2,-1,-1,minecraft:jungle_log)
B(-2,0,-1,minecraft:jungle_log)
B(-2,1,-1,minecraft:jungle_log)
B(-2,2,-1,minecraft:jungle_log)
B(-2,3,-1,minecraft:jungle_log)
B(-2,4,-1,minecraft:jungle_log)
B(-2,5,-1,minecraft:smooth_stone_slab)
B(-2,6,-1,minecraft:water)
B(-2,7,-1,minecraft:water)
B(-2,8,-1,minecraft:water)
B(-2,9,-1,minecraft:water)
B(-2,10,-1,minecraft:spruce_slab)
B(-2,-1,0,minecraft:cobblestone)
B(-2,0,0,minecraft:cauldron[level=3])
B(-2,3,0,minecraft:smooth_stone_slab)
B(-2,4,0,minecraft:smooth_stone_slab)
B(-2,5,0,minecraft:smooth_stone_slab)
B(-2,6,0,minecraft:water)
B(-2,7,0,minecraft:water)
B(-2,8,0,minecraft:water)
B(-2,9,0,minecraft:water)
B(-2,10,0,minecraft:spruce_slab)
B(-2,-1,1,minecraft:jungle_log)
B(-2,0,1,minecraft:jungle_log)
B(-2,1,1,minecraft:jungle_log)
B(-2,2,1,minecraft:jungle_log)
B(-2,3,1,minecraft:jungle_log)
B(-2,4,1,minecraft:oak_planks)
B(-2,5,1,minecraft:smooth_stone_slab)
B(-2,6,1,minecraft:water)
B(-2,7,1,minecraft:water)
B(-2,8,1,minecraft:water)
B(-2,9,1,minecraft:water)
B(-2,10,1,minecraft:spruce_slab)
B(-2,-1,2,minecraft:cobblestone)
B(-2,5,2,minecraft:oak_stairs[facing=east,half=top,shape=straight,waterlogged=false])
B(-2,6,2,minecraft:oak_planks)
B(-2,7,2,minecraft:water)
B(-2,8,2,minecraft:water)
B(-2,9,2,minecraft:water)
B(-2,10,2,minecraft:spruce_slab)
B(-2,-1,3,minecraft:grass_path)
B(-2,6,3,minecraft:oak_stairs[facing=east,half=top,shape=straight,waterlogged=false])
B(-2,7,3,minecraft:light_blue_terracotta)
B(-2,8,3,minecraft:light_blue_terracotta)
B(-2,9,3,minecraft:oak_stairs)
B(-2,-1,4,minecraft:grass_path)
B(-2,-1,5,minecraft:grass_path)
B(-2,-1,6,minecraft:grass_path)
B(-1,-1,-5,minecraft:grass_path)
B(-1,-1,-4,minecraft:grass_path)
B(-1,-1,-3,minecraft:cobblestone)
B(-1,0,-3,minecraft:spruce_fence)
B(-1,1,-3,minecraft:spruce_fence)
B(-1,2,-3,minecraft:spruce_fence)
B(-1,3,-3,minecraft:spruce_fence)
B(-1,4,-3,minecraft:spruce_fence[east=false,north=false,south=true,waterlogged=false,west=false])
B(-1,5,-3,minecraft:hopper)
B(-1,6,-3,minecraft:light_blue_terracotta)
B(-1,7,-3,minecraft:light_blue_terracotta)
B(-1,8,-3,minecraft:light_blue_terracotta)
B(-1,9,-3,minecraft:oak_stairs[facing=south,half=bottom,shape=straight,waterlogged=false])
B(-1,-1,-2,minecraft:cobblestone)
B(-1,3,-2,minecraft:oak_stairs[facing=south,half=top,shape=straight,waterlogged=false])
B(-1,4,-2,minecraft:oak_planks)
B(-1,5,-2,minecraft:oak_planks)
B(-1,6,-2,minecraft:oak_planks)
B(-1,7,-2,minecraft:water)
B(-1,8,-2,minecraft:water)
B(-1,9,-2,minecraft:water)
B(-1,10,-2,minecraft:spruce_slab)
B(-1,-1,-1,minecraft:cobblestone)
B(-1,0,-1,minecraft:cauldron[level=3])
B(-1,3,-1,minecraft:smooth_stone_slab)
B(-1,4,-1,minecraft:smooth_stone_slab)
B(-1,5,-1,minecraft:smooth_stone_slab)
B(-1,6,-1,minecraft:water)
B(-1,7,-1,minecraft:water)
B(-1,8,-1,minecraft:water)
B(-1,9,-1,minecraft:water)
B(-1,10,-1,minecraft:spruce_slab)
B(-1,-1,0,minecraft:cobblestone)
B(-1,0,0,minecraft:hopper)
B(-1,1,0,minecraft:cobblestone_wall)
B(-1,2,0,minecraft:cobblestone_wall)
B(-1,3,0,minecraft:cobblestone_wall)
B(-1,4,0,minecraft:cobblestone_wall)
B(-1,5,0,minecraft:cobblestone_wall)
B(-1,6,0,minecraft:hopper)
B(-1,7,0,minecraft:water)
B(-1,8,0,minecraft:water)
B(-1,9,0,minecraft:water)
B(-1,10,0,minecraft:oak_trapdoor[facing=east,half=bottom,open=false,powered=false,waterlogged=false])
B(-1,-1,1,minecraft:cobblestone)
B(-1,0,1,minecraft:cauldron[level=3])
B(-1,3,1,minecraft:smooth_stone_slab)
B(-1,4,1,minecraft:smooth_stone_slab)
B(-1,5,1,minecraft:smooth_stone_slab)
B(-1,6,1,minecraft:water)
B(-1,7,1,minecraft:water)
B(-1,8,1,minecraft:water)
B(-1,9,1,minecraft:water)
B(-1,10,1,minecraft:spruce_slab)
B(-1,-1,2,minecraft:cobblestone)
B(-1,3,2,minecraft:oak_stairs[facing=north,half=top,shape=straight,waterlogged=false])
B(-1,4,2,minecraft:oak_planks)
B(-1,5,2,minecraft:oak_planks)
B(-1,6,2,minecraft:oak_planks)
B(-1,7,2,minecraft:water)
B(-1,8,2,minecraft:water)
B(-1,9,2,minecraft:water)
B(-1,10,2,minecraft:spruce_slab)
B(-1,-1,3,minecraft:cobblestone)
B(-1,0,3,minecraft:spruce_fence)
B(-1,1,3,minecraft:spruce_fence)
B(-1,2,3,minecraft:spruce_fence)
B(-1,3,3,minecraft:spruce_fence)
B(-1,4,3,minecraft:spruce_fence[east=false,north=true,south=false,waterlogged=false,west=false])
B(-1,5,3,minecraft:hopper)
B(-1,6,3,minecraft:light_blue_terracotta)
B(-1,7,3,minecraft:light_blue_terracotta)
B(-1,8,3,minecraft:light_blue_terracotta)
B(-1,9,3,minecraft:oak_stairs)
B(-1,-1,4,minecraft:grass_path)
B(-1,-1,5,minecraft:grass_path)
B(-1,-1,6,minecraft:grass_path)
B(0,-1,-5,minecraft:grass_path)
B(0,-1,-4,minecraft:grass_path)
B(0,-1,-3,minecraft:grass_path)
B(0,6,-3,minecraft:oak_stairs[facing=west,half=top,shape=straight,waterlogged=false])
B(0,7,-3,minecraft:light_blue_terracotta)
B(0,8,-3,minecraft:light_blue_terracotta)
B(0,9,-3,minecraft:oak_stairs[facing=south,half=bottom,shape=straight,waterlogged=false])
B(0,-1,-2,minecraft:cobblestone)
B(0,5,-2,minecraft:oak_stairs[facing=west,half=top,shape=straight,waterlogged=false])
B(0,6,-2,minecraft:oak_planks)
B(0,7,-2,minecraft:water)
B(0,8,-2,minecraft:water)
B(0,9,-2,minecraft:water)
B(0,10,-2,minecraft:spruce_slab)
B(0,-1,-1,minecraft:jungle_log)
B(0,0,-1,minecraft:jungle_log)
B(0,1,-1,minecraft:jungle_log)
B(0,2,-1,minecraft:jungle_log)
B(0,3,-1,minecraft:jungle_log)
B(0,4,-1,minecraft:oak_planks)
B(0,5,-1,minecraft:smooth_stone_slab)
B(0,6,-1,minecraft:water)
B(0,7,-1,minecraft:water)
B(0,8,-1,minecraft:water)
B(0,9,-1,minecraft:water)
B(0,10,-1,minecraft:spruce_slab)
B(0,-1,0,minecraft:cobblestone)
B(0,0,0,minecraft:cauldron[level=3])
B(0,3,0,minecraft:smooth_stone_slab)
B(0,4,0,minecraft:smooth_stone_slab)
B(0,5,0,minecraft:smooth_stone_slab)
B(0,6,0,minecraft:water)
B(0,7,0,minecraft:water)
B(0,8,0,minecraft:water)
B(0,9,0,minecraft:water)
B(0,10,0,minecraft:spruce_slab)
B(0,-1,1,minecraft:jungle_log)
B(0,0,1,minecraft:jungle_log)
B(0,1,1,minecraft:jungle_log)
B(0,2,1,minecraft:jungle_log)
B(0,3,1,minecraft:jungle_log)
B(0,4,1,minecraft:oak_planks)
B(0,5,1,minecraft:smooth_stone_slab)
B(0,6,1,minecraft:water)
B(0,7,1,minecraft:water)
B(0,8,1,minecraft:water)
B(0,9,1,minecraft:water)
B(0,10,1,minecraft:spruce_slab)
B(0,-1,2,minecraft:cobblestone)
B(0,5,2,minecraft:oak_stairs[facing=west,half=top,shape=straight,waterlogged=false])
B(0,6,2,minecraft:oak_planks)
B(0,7,2,minecraft:water)
B(0,8,2,minecraft:water)
B(0,9,2,minecraft:water)
B(0,10,2,minecraft:spruce_slab)
B(0,-1,3,minecraft:grass_path)
B(0,6,3,minecraft:oak_stairs[facing=west,half=top,shape=straight,waterlogged=false])
B(0,7,3,minecraft:light_blue_terracotta)
B(0,8,3,minecraft:light_blue_terracotta)
B(0,9,3,minecraft:oak_stairs)
B(0,-1,4,minecraft:grass_path)
B(0,-1,5,minecraft:grass_path)
B(1,-1,-6,minecraft:grass_path)
B(1,-1,-5,minecraft:grass_path)
B(1,-1,-4,minecraft:grass_path)
B(1,-1,-3,minecraft:grass_path)
B(1,6,-3,minecraft:spruce_slab[type=top,waterlogged=false])
B(1,7,-3,minecraft:light_blue_terracotta)
B(1,8,-3,minecraft:light_blue_terracotta)
B(1,9,-3,minecraft:oak_stairs[facing=south,half=bottom,shape=outer_right,waterlogged=false])
B(1,-1,-2,minecraft:cobblestone)
B(1,6,-2,minecraft:spruce_slab[type=double,waterlogged=false])
B(1,7,-2,minecraft:light_blue_terracotta)
B(1,8,-2,minecraft:light_blue_terracotta)
B(1,9,-2,minecraft:oak_stairs[facing=west,half=bottom,shape=inner_left,waterlogged=false])
B(1,-1,-1,minecraft:cobblestone)
B(1,5,-1,minecraft:oak_stairs[facing=south,half=top,shape=straight,waterlogged=false])
B(1,6,-1,minecraft:oak_planks)
B(1,7,-1,minecraft:water)
B(1,8,-1,minecraft:water)
B(1,9,-1,minecraft:water)
B(1,10,-1,minecraft:spruce_slab)
B(1,-1,0,minecraft:cobblestone)
B(1,3,0,minecraft:oak_stairs[facing=west,half=top,shape=straight,waterlogged=false])
B(1,4,0,minecraft:oak_planks)
B(1,5,0,minecraft:oak_planks)
B(1,6,0,minecraft:oak_planks)
B(1,7,0,minecraft:water)
B(1,8,0,minecraft:water)
B(1,9,0,minecraft:water)
B(1,10,0,minecraft:spruce_slab)
B(1,-1,1,minecraft:cobblestone)
B(1,5,1,minecraft:oak_stairs[facing=north,half=top,shape=straight,waterlogged=false])
B(1,6,1,minecraft:oak_planks)
B(1,7,1,minecraft:water)
B(1,8,1,minecraft:water)
B(1,9,1,minecraft:water)
B(1,10,1,minecraft:spruce_slab)
B(1,-1,2,minecraft:cobblestone)
B(1,6,2,minecraft:spruce_slab[type=double,waterlogged=false])
B(1,7,2,minecraft:light_blue_terracotta)
B(1,8,2,minecraft:light_blue_terracotta)
B(1,9,2,minecraft:oak_stairs[facing=west,half=bottom,shape=inner_right,waterlogged=false])
B(1,-1,3,minecraft:grass_path)
B(1,6,3,minecraft:spruce_slab[type=top,waterlogged=false])
B(1,7,3,minecraft:light_blue_terracotta)
B(1,8,3,minecraft:light_blue_terracotta)
B(1,9,3,minecraft:oak_stairs[facing=north,half=bottom,shape=outer_left,waterlogged=false])
B(1,-1,4,minecraft:grass_path)
B(1,-1,5,minecraft:grass_path)
B(2,-1,-5,minecraft:grass_path)
B(2,-1,-4,minecraft:grass_path)
B(2,-1,-3,minecraft:cobblestone)
B(2,0,-3,minecraft:jungle_log)
B(2,1,-3,minecraft:jungle_log)
B(2,2,-3,minecraft:jungle_log)
B(2,3,-3,minecraft:jungle_log)
B(2,4,-3,minecraft:jungle_log)
B(2,5,-3,minecraft:cobblestone_wall)
B(2,6,-3,minecraft:cobblestone_wall)
B(2,7,-3,minecraft:cobblestone_wall[east=none,north=none,south=low,up=true,waterlogged=false,west=low])
B(2,8,-3,minecraft:torch)
B(2,-1,-2,minecraft:grass_path)
B(2,6,-2,minecraft:spruce_slab[type=top,waterlogged=false])
B(2,7,-2,minecraft:light_blue_terracotta)
B(2,8,-2,minecraft:light_blue_terracotta)
B(2,9,-2,minecraft:oak_stairs[facing=south,half=bottom,shape=outer_right,waterlogged=false])
B(2,-1,-1,minecraft:grass_path)
B(2,6,-1,minecraft:oak_stairs[facing=south,half=top,shape=straight,waterlogged=false])
B(2,7,-1,minecraft:light_blue_terracotta)
B(2,8,-1,minecraft:light_blue_terracotta)
B(2,9,-1,minecraft:oak_stairs[facing=west,half=bottom,shape=straight,waterlogged=false])
B(2,-1,0,minecraft:cobblestone)
B(2,0,0,minecraft:spruce_fence)
B(2,1,0,minecraft:spruce_fence)
B(2,2,0,minecraft:spruce_fence)
B(2,3,0,minecraft:spruce_fence)
B(2,4,0,minecraft:spruce_fence[east=false,north=false,south=false,waterlogged=false,west=true])
B(2,5,0,minecraft:hopper)
B(2,6,0,minecraft:light_blue_terracotta)
B(2,7,0,minecraft:light_blue_terracotta)
B(2,8,0,minecraft:light_blue_terracotta)
B(2,9,0,minecraft:oak_stairs[facing=west,half=bottom,shape=straight,waterlogged=false])
B(2,-1,1,minecraft:grass_path)
B(2,6,1,minecraft:oak_stairs[facing=north,half=top,shape=straight,waterlogged=false])
B(2,7,1,minecraft:light_blue_terracotta)
B(2,8,1,minecraft:light_blue_terracotta)
B(2,9,1,minecraft:oak_stairs[facing=west,half=bottom,shape=straight,waterlogged=false])
B(2,-1,2,minecraft:grass_path)
B(2,6,2,minecraft:spruce_slab[type=top,waterlogged=false])
B(2,7,2,minecraft:light_blue_terracotta)
B(2,8,2,minecraft:light_blue_terracotta)
B(2,9,2,minecraft:oak_stairs[facing=north,half=bottom,shape=outer_left,waterlogged=false])
B(2,-1,3,minecraft:cobblestone)
B(2,0,3,minecraft:jungle_log)
B(2,1,3,minecraft:jungle_log)
B(2,2,3,minecraft:jungle_log)
B(2,3,3,minecraft:jungle_log)
B(2,4,3,minecraft:jungle_log)
B(2,5,3,minecraft:cobblestone_wall)
B(2,6,3,minecraft:cobblestone_wall)
B(2,7,3,minecraft:cobblestone_wall[east=none,north=low,south=none,up=true,waterlogged=false,west=low])
B(2,8,3,minecraft:torch)
B(2,-1,4,minecraft:grass_path)
B(2,-1,5,minecraft:grass_path)
B(3,-1,-4,minecraft:grass_path)
B(3,-1,-3,minecraft:grass_path)
B(3,-1,-2,minecraft:grass_path)
B(3,-1,-1,minecraft:grass_path)
B(3,-1,0,minecraft:grass_path)
B(3,-1,1,minecraft:grass_path)
B(3,-1,2,minecraft:grass_path)
B(3,-1,3,minecraft:grass_path)
B(3,-1,4,minecraft:grass_path)
B(4,-1,-4,minecraft:grass_path)
B(4,-1,-3,minecraft:grass_path)
B(4,-1,-1,minecraft:grass_path)
B(4,-1,0,minecraft:grass_path)
B(4,-1,1,minecraft:grass_path)
B(4,-1,2,minecraft:grass_path)
B(4,-1,3,minecraft:grass_path)
B(5,-1,2,minecraft:grass_path)
RB(-1,7,-4,minecraft:white_wall_banner,../JungleNBT/banners/JungleBanner01.nbt,8,minecraft:white_wall_banner,../JungleNBT/banners/JungleBanner02.nbt,8,minecraft:white_wall_banner,../JungleNBT/banners/JungleBanner03.nbt,8,minecraft:white_wall_banner,../JungleNBT/banners/JungleBanner04.nbt,8,minecraft:white_wall_banner,../JungleNBT/banners/JungleBanner05.nbt,8,minecraft:white_wall_banner,../JungleNBT/banners/JungleBanner06.nbt,8,minecraft:white_wall_banner,../JungleNBT/banners/JungleBanner07.nbt,8,minecraft:white_wall_banner,../JungleNBT/banners/JungleBanner08.nbt,8,minecraft:white_wall_banner,../JungleNBT/banners/JungleBanner09.nbt,8,minecraft:white_wall_banner,../JungleNBT/banners/JungleBanner10.nbt,8,minecraft:white_wall_banner,../JungleNBT/banners/JungleBanner11.nbt,8,minecraft:white_wall_banner,../JungleNBT/banners/JungleBanner12.nbt,8,minecraft:white_wall_banner,../JungleNBT/banners/JungleBanner13.nbt,8,minecraft:white_wall_banner,../JungleNBT/banners/JungleBanner14.nbt,8,minecraft:white_wall_banner,../JungleNBT/banners/JungleBanner15.nbt,8,minecraft:white_wall_banner,../JungleNBT/banners/JungleBanner16.nbt,8,minecraft:white_wall_banner,../JungleNBT/banners/JungleBanner17.nbt,8,minecraft:white_wall_banner,../JungleNBT/banners/JungleBanner18.nbt,8,minecraft:white_wall_banner,../JungleNBT/banners/JungleBanner19.nbt,8,minecraft:white_wall_banner,../JungleNBT/banners/JungleBanner20.nbt,100)
RB(-5,7,0,minecraft:white_wall_banner[facing=west],../JungleNBT/banners/JungleBanner01.nbt,8,minecraft:white_wall_banner[facing=west],../JungleNBT/banners/JungleBanner02.nbt,8,minecraft:white_wall_banner[facing=west],../JungleNBT/banners/JungleBanner03.nbt,8,minecraft:white_wall_banner[facing=west],../JungleNBT/banners/JungleBanner04.nbt,8,minecraft:white_wall_banner[facing=west],../JungleNBT/banners/JungleBanner05.nbt,8,minecraft:white_wall_banner[facing=west],../JungleNBT/banners/JungleBanner06.nbt,8,minecraft:white_wall_banner[facing=west],../JungleNBT/banners/JungleBanner07.nbt,8,minecraft:white_wall_banner[facing=west],../JungleNBT/banners/JungleBanner08.nbt,8,minecraft:white_wall_banner[facing=west],../JungleNBT/banners/JungleBanner09.nbt,8,minecraft:white_wall_banner[facing=west],../JungleNBT/banners/JungleBanner10.nbt,8,minecraft:white_wall_banner[facing=west],../JungleNBT/banners/JungleBanner11.nbt,8,minecraft:white_wall_banner[facing=west],../JungleNBT/banners/JungleBanner12.nbt,8,minecraft:white_wall_banner[facing=west],../JungleNBT/banners/JungleBanner13.nbt,8,minecraft:white_wall_banner[facing=west],../JungleNBT/banners/JungleBanner14.nbt,8,minecraft:white_wall_banner[facing=west],../JungleNBT/banners/JungleBanner15.nbt,8,minecraft:white_wall_banner[facing=west],../JungleNBT/banners/JungleBanner16.nbt,8,minecraft:white_wall_banner[facing=west],../JungleNBT/banners/JungleBanner17.nbt,8,minecraft:white_wall_banner[facing=west],../JungleNBT/banners/JungleBanner18.nbt,8,minecraft:white_wall_banner[facing=west],../JungleNBT/banners/JungleBanner19.nbt,8,minecraft:white_wall_banner[facing=west],../JungleNBT/banners/JungleBanner20.nbt,100)
RB(3,7,0,minecraft:white_wall_banner[facing=east],../JungleNBT/banners/JungleBanner01.nbt,8,minecraft:white_wall_banner[facing=east],../JungleNBT/banners/JungleBanner02.nbt,8,minecraft:white_wall_banner[facing=east],../JungleNBT/banners/JungleBanner03.nbt,8,minecraft:white_wall_banner[facing=east],../JungleNBT/banners/JungleBanner04.nbt,8,minecraft:white_wall_banner[facing=east],../JungleNBT/banners/JungleBanner05.nbt,8,minecraft:white_wall_banner[facing=east],../JungleNBT/banners/JungleBanner06.nbt,8,minecraft:white_wall_banner[facing=east],../JungleNBT/banners/JungleBanner07.nbt,8,minecraft:white_wall_banner[facing=east],../JungleNBT/banners/JungleBanner08.nbt,8,minecraft:white_wall_banner[facing=east],../JungleNBT/banners/JungleBanner09.nbt,8,minecraft:white_wall_banner[facing=east],../JungleNBT/banners/JungleBanner10.nbt,8,minecraft:white_wall_banner[facing=east],../JungleNBT/banners/JungleBanner11.nbt,8,minecraft:white_wall_banner[facing=east],../JungleNBT/banners/JungleBanner12.nbt,8,minecraft:white_wall_banner[facing=east],../JungleNBT/banners/JungleBanner13.nbt,8,minecraft:white_wall_banner[facing=east],../JungleNBT/banners/JungleBanner14.nbt,8,minecraft:white_wall_banner[facing=east],../JungleNBT/banners/JungleBanner15.nbt,8,minecraft:white_wall_banner[facing=east],../JungleNBT/banners/JungleBanner16.nbt,8,minecraft:white_wall_banner[facing=east],../JungleNBT/banners/JungleBanner17.nbt,8,minecraft:white_wall_banner[facing=east],../JungleNBT/banners/JungleBanner18.nbt,8,minecraft:white_wall_banner[facing=east],../JungleNBT/banners/JungleBanner19.nbt,8,minecraft:white_wall_banner[facing=east],../JungleNBT/banners/JungleBanner20.nbt,100)
RB(-1,7,4,minecraft:white_wall_banner[facing=south],../JungleNBT/banners/JungleBanner01.nbt,8,minecraft:white_wall_banner[facing=south],../JungleNBT/banners/JungleBanner02.nbt,8,minecraft:white_wall_banner[facing=south],../JungleNBT/banners/JungleBanner03.nbt,8,minecraft:white_wall_banner[facing=south],../JungleNBT/banners/JungleBanner04.nbt,8,minecraft:white_wall_banner[facing=south],../JungleNBT/banners/JungleBanner05.nbt,8,minecraft:white_wall_banner[facing=south],../JungleNBT/banners/JungleBanner06.nbt,8,minecraft:white_wall_banner[facing=south],../JungleNBT/banners/JungleBanner07.nbt,8,minecraft:white_wall_banner[facing=south],../JungleNBT/banners/JungleBanner08.nbt,8,minecraft:white_wall_banner[facing=south],../JungleNBT/banners/JungleBanner09.nbt,8,minecraft:white_wall_banner[facing=south],../JungleNBT/banners/JungleBanner10.nbt,8,minecraft:white_wall_banner[facing=south],../JungleNBT/banners/JungleBanner11.nbt,8,minecraft:white_wall_banner[facing=south],../JungleNBT/banners/JungleBanner12.nbt,8,minecraft:white_wall_banner[facing=south],../JungleNBT/banners/JungleBanner13.nbt,8,minecraft:white_wall_banner[facing=south],../JungleNBT/banners/JungleBanner14.nbt,8,minecraft:white_wall_banner[facing=south],../JungleNBT/banners/JungleBanner15.nbt,8,minecraft:white_wall_banner[facing=south],../JungleNBT/banners/JungleBanner16.nbt,8,minecraft:white_wall_banner[facing=south],../JungleNBT/banners/JungleBanner17.nbt,8,minecraft:white_wall_banner[facing=south],../JungleNBT/banners/JungleBanner18.nbt,8,minecraft:white_wall_banner[facing=south],../JungleNBT/banners/JungleBanner19.nbt,8,minecraft:white_wall_banner[facing=south],../JungleNBT/banners/JungleBanner20.nbt,100)

#######################################################################
# +-----------------------------------------------------------------+ #
# |                            BO3 checks                           | #
# +-----------------------------------------------------------------+ #
#######################################################################


#######################################################################
# +-----------------------------------------------------------------+ #
# |                             Branches                            | #
# +-----------------------------------------------------------------+ #
#######################################################################


#######################################################################
# +-----------------------------------------------------------------+ #
# |                             Entities                            | #
# +-----------------------------------------------------------------+ #
#######################################################################

Entity(-3,0,-1,minecraft:villager,1,../JungleNBT/entities/tribalnative.txt)
Entity(1,0,-1,minecraft:villager,1,../JungleNBT/entities/tribalnative.txt)
Entity(0,0,2,minecraft:villager,1,../JungleNBT/entities/tribalnative.txt)
