
#######################################################################
# +-----------------------------------------------------------------+ #
# |                            BO3 object                           | #
# +-----------------------------------------------------------------+ #
#######################################################################

Author: BO3 BulkEdit (by LanToaster)

Description: This Object was Created with BO3_BulkEdit

Version: 3

SettingsMode: WriteWithoutComments


#######################################################################
# +-----------------------------------------------------------------+ #
# |                          Main settings                          | #
# +-----------------------------------------------------------------+ #
#######################################################################

Tree: false

Frequency: 100

Rarity: 100.0

RotateRandomly: true

SpawnHeight: randomY

SpawnHeightOffset: 0

SpawnHeightVariance: 0

##############################
# Height Limits for the BO3. #
##############################

MinHeight: 82

MaxHeight: 82

######################
# Extrusion settings #
######################

ExtrudeMode: None

ExtrudeThroughBlocks: minecraft:air

MaxBranchDepth: 50


#######################################################################
# +-----------------------------------------------------------------+ #
# |                      Source block settings                      | #
# +-----------------------------------------------------------------+ #
#######################################################################

SourceBlocks: otg:air

MaxPercentageOutsideSourceBlock: 100

OutsideSourceBlock: placeAnyway

DoReplaceBlocks: true

IsOTGPlus: false


#######################################################################
# +-----------------------------------------------------------------+ #
# |                              Blocks                             | #
# +-----------------------------------------------------------------+ #
#######################################################################

B(-6,-1,0,minecraft:grass_block)
B(-6,-1,2,minecraft:grass_block)
B(-5,-1,-4,minecraft:grass_block)
B(-5,-1,-3,minecraft:grass_block)
B(-5,-1,-1,minecraft:grass_block)
B(-5,-1,0,minecraft:grass_block)
B(-5,-1,1,minecraft:grass_block)
B(-5,-1,2,minecraft:grass_block)
B(-5,-1,3,minecraft:grass_block)
B(-5,-1,4,minecraft:grass_block)
B(-4,-1,-4,minecraft:grass_block)
B(-4,-1,-3,minecraft:grass_block)
B(-4,-1,-2,minecraft:grass_block)
B(-4,-1,-1,minecraft:grass_path)
B(-4,-1,0,minecraft:grass_path)
B(-4,-1,1,minecraft:grass_block)
B(-4,-1,2,minecraft:grass_block)
B(-4,-1,3,minecraft:grass_block)
B(-4,-1,4,minecraft:grass_block)
B(-3,-1,-4,minecraft:grass_block)
B(-3,-1,-3,minecraft:grass_path)
B(-3,-1,-2,minecraft:grass_path)
B(-3,-1,-1,minecraft:grass_path)
B(-3,-1,0,minecraft:grass_block)
B(-3,-1,1,minecraft:grass_path)
B(-3,-1,2,minecraft:grass_block)
B(-3,-1,3,minecraft:cobblestone_slab[type=double,waterlogged=false])
B(-3,0,3,minecraft:jungle_fence)
B(-3,1,3,minecraft:torch)
B(-3,-1,4,minecraft:grass_block)
B(-3,-1,5,minecraft:grass_block)
B(-2,-1,-6,minecraft:grass_block)
B(-2,-1,-5,minecraft:grass_block)
B(-2,-1,-4,minecraft:grass_path)
B(-2,-1,-3,minecraft:grass_block)
B(-2,-1,-2,minecraft:grass_block)
B(-2,-1,-1,minecraft:dirt)
B(-2,-1,0,minecraft:grass_block)
B(-2,-1,1,minecraft:grass_block)
B(-2,-1,2,minecraft:grass_block)
B(-2,-1,3,minecraft:grass_block)
B(-2,-1,4,minecraft:dirt)
B(-2,-1,5,minecraft:grass_block)
B(-1,-1,-6,minecraft:grass_block)
B(-1,-1,-5,minecraft:grass_block)
B(-1,-1,-4,minecraft:grass_block)
B(-1,-1,-3,minecraft:grass_path)
B(-1,-1,-2,minecraft:grass_path)
B(-1,-1,-1,minecraft:grass_block)
B(-1,0,-1,minecraft:cobblestone_slab)
B(-1,1,-1,minecraft:stone_button[face=wall,facing=west,powered=false])
B(-1,2,-1,minecraft:oak_trapdoor[facing=east,half=bottom,open=true,powered=false,waterlogged=false])
B(-1,3,-1,minecraft:stone_button[face=wall,facing=west,powered=false])
B(-1,4,-1,minecraft:oak_trapdoor[facing=east,half=bottom,open=true,powered=false,waterlogged=false])
B(-1,5,-1,minecraft:stone_button[face=wall,facing=west,powered=false])
B(-1,6,-1,minecraft:stone_button[face=wall,facing=west,powered=false])
B(-1,7,-1,minecraft:stone_button[face=wall,facing=west,powered=false])
B(-1,8,-1,minecraft:oak_trapdoor[facing=east,half=bottom,open=true,powered=false,waterlogged=false])
B(-1,-1,0,minecraft:grass_block)
B(-1,-1,1,minecraft:grass_block)
B(-1,-1,2,minecraft:grass_path)
B(-1,-1,3,minecraft:grass_block)
B(-1,-1,4,minecraft:grass_block)
B(-1,-1,5,minecraft:grass_block)
B(0,-1,-5,minecraft:grass_block)
B(0,7,-5,minecraft:oak_trapdoor[facing=south,half=bottom,open=false,powered=false,waterlogged=false])
B(0,-1,-4,minecraft:dirt)
B(0,4,-4,minecraft:oak_trapdoor[facing=south,half=bottom,open=true,powered=false,waterlogged=false])
B(0,6,-4,minecraft:jungle_fence)
B(0,7,-4,minecraft:dark_oak_slab)
B(0,-1,-3,minecraft:grass_path)
B(0,3,-3,minecraft:jungle_fence)
B(0,4,-3,minecraft:spruce_slab)
B(0,7,-3,minecraft:dark_oak_slab)
B(0,-1,-2,minecraft:grass_block)
B(0,0,-2,minecraft:cobblestone_slab)
B(0,1,-2,minecraft:stone_button)
B(0,2,-2,minecraft:jungle_fence_gate[facing=east,in_wall=false,open=false,powered=false])
B(0,3,-2,minecraft:jungle_stairs[facing=south,half=top,shape=straight,waterlogged=false])
B(0,4,-2,minecraft:spruce_slab)
B(0,6,-2,minecraft:jungle_stairs[facing=south,half=top,shape=straight,waterlogged=false])
B(0,7,-2,minecraft:dark_oak_slab[type=double,waterlogged=false])
B(0,-1,-1,minecraft:dirt)
B(0,0,-1,minecraft:cobblestone_slab[type=double,waterlogged=false])
B(0,1,-1,minecraft:jungle_log)
B(0,2,-1,minecraft:black_glazed_terracotta[facing=west])
B(0,3,-1,minecraft:black_glazed_terracotta[facing=west])
B(0,4,-1,minecraft:black_glazed_terracotta[facing=west])
B(0,5,-1,minecraft:gray_glazed_terracotta[facing=west])
B(0,6,-1,minecraft:gray_glazed_terracotta[facing=west])
B(0,7,-1,minecraft:red_glazed_terracotta[facing=west])
B(0,8,-1,minecraft:red_glazed_terracotta[facing=west])
B(0,9,-1,minecraft:spruce_slab)
B(0,-1,0,minecraft:grass_block)
B(0,0,0,minecraft:cobblestone_slab)
B(0,1,0,minecraft:stone_button[face=wall,facing=south,powered=false])
B(0,2,0,minecraft:jungle_fence_gate[facing=east,in_wall=false,open=false,powered=false])
B(0,3,0,minecraft:jungle_stairs[facing=north,half=top,shape=straight,waterlogged=false])
B(0,4,0,minecraft:spruce_slab)
B(0,6,0,minecraft:jungle_stairs[facing=north,half=top,shape=straight,waterlogged=false])
B(0,7,0,minecraft:dark_oak_slab[type=double,waterlogged=false])
B(0,-1,1,minecraft:grass_block)
B(0,3,1,minecraft:jungle_fence)
B(0,4,1,minecraft:spruce_slab)
B(0,7,1,minecraft:dark_oak_slab)
B(0,-1,2,minecraft:grass_path)
B(0,4,2,minecraft:oak_trapdoor[facing=north,half=bottom,open=true,powered=false,waterlogged=false])
B(0,6,2,minecraft:jungle_fence)
B(0,7,2,minecraft:dark_oak_slab)
B(0,-1,3,minecraft:grass_path)
B(0,7,3,minecraft:oak_trapdoor)
B(0,-1,4,minecraft:grass_block)
B(0,-1,5,minecraft:grass_block)
B(1,-1,-5,minecraft:grass_block)
B(1,-1,-4,minecraft:grass_path)
B(1,-1,-3,minecraft:grass_path)
B(1,-1,-2,minecraft:grass_path)
B(1,-1,-1,minecraft:grass_block)
B(1,0,-1,minecraft:cobblestone_slab)
B(1,1,-1,minecraft:stone_button[face=wall,facing=east,powered=false])
B(1,2,-1,minecraft:oak_trapdoor[facing=west,half=bottom,open=true,powered=false,waterlogged=false])
B(1,4,-1,minecraft:oak_trapdoor[facing=west,half=bottom,open=true,powered=false,waterlogged=false])
B(1,6,-1,minecraft:oak_trapdoor[facing=west,half=bottom,open=true,powered=false,waterlogged=false])
B(1,-1,0,minecraft:grass_block)
B(1,-1,1,minecraft:grass_path)
B(1,-1,2,minecraft:grass_path)
B(1,-1,3,minecraft:grass_block)
B(1,-1,4,minecraft:grass_block)
B(2,-1,-6,minecraft:grass_block)
B(2,-1,-5,minecraft:grass_block)
B(2,-1,-4,minecraft:grass_path)
B(2,-1,-3,minecraft:grass_block)
B(2,-1,-2,minecraft:grass_block)
B(2,-1,-1,minecraft:grass_block)
B(2,-1,0,minecraft:grass_block)
B(2,-1,1,minecraft:grass_path)
B(2,-1,2,minecraft:grass_block)
B(2,-1,3,minecraft:dirt)
B(3,-1,-6,minecraft:grass_block)
B(3,-1,-5,minecraft:grass_path)
B(3,-1,-4,minecraft:grass_path)
B(3,-1,-3,minecraft:grass_path)
B(3,-1,-2,minecraft:grass_block)
B(3,-1,-1,minecraft:dirt)
B(3,-1,0,minecraft:grass_path)
B(3,-1,1,minecraft:grass_path)
B(3,-1,2,minecraft:cobblestone_slab[type=double,waterlogged=false])
B(3,0,2,minecraft:jungle_fence)
B(3,1,2,minecraft:torch)
B(3,-1,3,minecraft:grass_block)
B(3,-1,4,minecraft:grass_block)
B(3,-1,5,minecraft:grass_block)
B(4,-1,-6,minecraft:grass_block)
B(4,-1,-5,minecraft:grass_block)
B(4,-1,-4,minecraft:grass_path)
B(4,-1,-3,minecraft:cobblestone_slab[type=double,waterlogged=false])
B(4,0,-3,minecraft:jungle_fence)
B(4,1,-3,minecraft:torch)
B(4,-1,-2,minecraft:grass_block)
B(4,-1,-1,minecraft:grass_block)
B(4,-1,0,minecraft:grass_path)
B(4,-1,1,minecraft:grass_block)
B(4,-1,2,minecraft:grass_block)
B(4,-1,3,minecraft:grass_block)
B(4,-1,5,minecraft:grass_block)
B(5,-1,-6,minecraft:grass_block)
B(5,-1,-5,minecraft:grass_block)
B(5,-1,-4,minecraft:grass_block)
B(5,-1,-3,minecraft:grass_block)
B(5,-1,-2,minecraft:grass_block)
B(5,-1,0,minecraft:grass_block)
B(5,-1,1,minecraft:grass_block)
B(5,-1,2,minecraft:grass_block)
B(6,-1,-4,minecraft:grass_block)
RB(-1,7,-2,minecraft:white_wall_banner[facing=west],../JungleNBT/banners/JungleBanner01.nbt,8,minecraft:white_wall_banner[facing=west],../JungleNBT/banners/JungleBanner02.nbt,8,minecraft:white_wall_banner[facing=west],../JungleNBT/banners/JungleBanner03.nbt,8,minecraft:white_wall_banner[facing=west],../JungleNBT/banners/JungleBanner04.nbt,8,minecraft:white_wall_banner[facing=west],../JungleNBT/banners/JungleBanner05.nbt,8,minecraft:white_wall_banner[facing=west],../JungleNBT/banners/JungleBanner06.nbt,8,minecraft:white_wall_banner[facing=west],../JungleNBT/banners/JungleBanner07.nbt,8,minecraft:white_wall_banner[facing=west],../JungleNBT/banners/JungleBanner08.nbt,8,minecraft:white_wall_banner[facing=west],../JungleNBT/banners/JungleBanner09.nbt,8,minecraft:white_wall_banner[facing=west],../JungleNBT/banners/JungleBanner10.nbt,8,minecraft:white_wall_banner[facing=west],../JungleNBT/banners/JungleBanner11.nbt,8,minecraft:white_wall_banner[facing=west],../JungleNBT/banners/JungleBanner12.nbt,8,minecraft:white_wall_banner[facing=west],../JungleNBT/banners/JungleBanner13.nbt,8,minecraft:white_wall_banner[facing=west],../JungleNBT/banners/JungleBanner14.nbt,8,minecraft:white_wall_banner[facing=west],../JungleNBT/banners/JungleBanner15.nbt,8,minecraft:white_wall_banner[facing=west],../JungleNBT/banners/JungleBanner16.nbt,8,minecraft:white_wall_banner[facing=west],../JungleNBT/banners/JungleBanner17.nbt,8,minecraft:white_wall_banner[facing=west],../JungleNBT/banners/JungleBanner18.nbt,8,minecraft:white_wall_banner[facing=west],../JungleNBT/banners/JungleBanner19.nbt,8,minecraft:white_wall_banner[facing=west],../JungleNBT/banners/JungleBanner20.nbt,100)
RB(1,7,-2,minecraft:white_wall_banner[facing=east],../JungleNBT/banners/JungleBanner01.nbt,8,minecraft:white_wall_banner[facing=east],../JungleNBT/banners/JungleBanner02.nbt,8,minecraft:white_wall_banner[facing=east],../JungleNBT/banners/JungleBanner03.nbt,8,minecraft:white_wall_banner[facing=east],../JungleNBT/banners/JungleBanner04.nbt,8,minecraft:white_wall_banner[facing=east],../JungleNBT/banners/JungleBanner05.nbt,8,minecraft:white_wall_banner[facing=east],../JungleNBT/banners/JungleBanner06.nbt,8,minecraft:white_wall_banner[facing=east],../JungleNBT/banners/JungleBanner07.nbt,8,minecraft:white_wall_banner[facing=east],../JungleNBT/banners/JungleBanner08.nbt,8,minecraft:white_wall_banner[facing=east],../JungleNBT/banners/JungleBanner09.nbt,8,minecraft:white_wall_banner[facing=east],../JungleNBT/banners/JungleBanner10.nbt,8,minecraft:white_wall_banner[facing=east],../JungleNBT/banners/JungleBanner11.nbt,8,minecraft:white_wall_banner[facing=east],../JungleNBT/banners/JungleBanner12.nbt,8,minecraft:white_wall_banner[facing=east],../JungleNBT/banners/JungleBanner13.nbt,8,minecraft:white_wall_banner[facing=east],../JungleNBT/banners/JungleBanner14.nbt,8,minecraft:white_wall_banner[facing=east],../JungleNBT/banners/JungleBanner15.nbt,8,minecraft:white_wall_banner[facing=east],../JungleNBT/banners/JungleBanner16.nbt,8,minecraft:white_wall_banner[facing=east],../JungleNBT/banners/JungleBanner17.nbt,8,minecraft:white_wall_banner[facing=east],../JungleNBT/banners/JungleBanner18.nbt,8,minecraft:white_wall_banner[facing=east],../JungleNBT/banners/JungleBanner19.nbt,8,minecraft:white_wall_banner[facing=east],../JungleNBT/banners/JungleBanner20.nbt,100)
RB(-1,7,0,minecraft:white_wall_banner[facing=west],../JungleNBT/banners/JungleBanner01.nbt,8,minecraft:white_wall_banner[facing=west],../JungleNBT/banners/JungleBanner02.nbt,8,minecraft:white_wall_banner[facing=west],../JungleNBT/banners/JungleBanner03.nbt,8,minecraft:white_wall_banner[facing=west],../JungleNBT/banners/JungleBanner04.nbt,8,minecraft:white_wall_banner[facing=west],../JungleNBT/banners/JungleBanner05.nbt,8,minecraft:white_wall_banner[facing=west],../JungleNBT/banners/JungleBanner06.nbt,8,minecraft:white_wall_banner[facing=west],../JungleNBT/banners/JungleBanner07.nbt,8,minecraft:white_wall_banner[facing=west],../JungleNBT/banners/JungleBanner08.nbt,8,minecraft:white_wall_banner[facing=west],../JungleNBT/banners/JungleBanner09.nbt,8,minecraft:white_wall_banner[facing=west],../JungleNBT/banners/JungleBanner10.nbt,8,minecraft:white_wall_banner[facing=west],../JungleNBT/banners/JungleBanner11.nbt,8,minecraft:white_wall_banner[facing=west],../JungleNBT/banners/JungleBanner12.nbt,8,minecraft:white_wall_banner[facing=west],../JungleNBT/banners/JungleBanner13.nbt,8,minecraft:white_wall_banner[facing=west],../JungleNBT/banners/JungleBanner14.nbt,8,minecraft:white_wall_banner[facing=west],../JungleNBT/banners/JungleBanner15.nbt,8,minecraft:white_wall_banner[facing=west],../JungleNBT/banners/JungleBanner16.nbt,8,minecraft:white_wall_banner[facing=west],../JungleNBT/banners/JungleBanner17.nbt,8,minecraft:white_wall_banner[facing=west],../JungleNBT/banners/JungleBanner18.nbt,8,minecraft:white_wall_banner[facing=west],../JungleNBT/banners/JungleBanner19.nbt,8,minecraft:white_wall_banner[facing=west],../JungleNBT/banners/JungleBanner20.nbt,100)
RB(1,7,0,minecraft:white_wall_banner[facing=east],../JungleNBT/banners/JungleBanner01.nbt,8,minecraft:white_wall_banner[facing=east],../JungleNBT/banners/JungleBanner02.nbt,8,minecraft:white_wall_banner[facing=east],../JungleNBT/banners/JungleBanner03.nbt,8,minecraft:white_wall_banner[facing=east],../JungleNBT/banners/JungleBanner04.nbt,8,minecraft:white_wall_banner[facing=east],../JungleNBT/banners/JungleBanner05.nbt,8,minecraft:white_wall_banner[facing=east],../JungleNBT/banners/JungleBanner06.nbt,8,minecraft:white_wall_banner[facing=east],../JungleNBT/banners/JungleBanner07.nbt,8,minecraft:white_wall_banner[facing=east],../JungleNBT/banners/JungleBanner08.nbt,8,minecraft:white_wall_banner[facing=east],../JungleNBT/banners/JungleBanner09.nbt,8,minecraft:white_wall_banner[facing=east],../JungleNBT/banners/JungleBanner10.nbt,8,minecraft:white_wall_banner[facing=east],../JungleNBT/banners/JungleBanner11.nbt,8,minecraft:white_wall_banner[facing=east],../JungleNBT/banners/JungleBanner12.nbt,8,minecraft:white_wall_banner[facing=east],../JungleNBT/banners/JungleBanner13.nbt,8,minecraft:white_wall_banner[facing=east],../JungleNBT/banners/JungleBanner14.nbt,8,minecraft:white_wall_banner[facing=east],../JungleNBT/banners/JungleBanner15.nbt,8,minecraft:white_wall_banner[facing=east],../JungleNBT/banners/JungleBanner16.nbt,8,minecraft:white_wall_banner[facing=east],../JungleNBT/banners/JungleBanner17.nbt,8,minecraft:white_wall_banner[facing=east],../JungleNBT/banners/JungleBanner18.nbt,8,minecraft:white_wall_banner[facing=east],../JungleNBT/banners/JungleBanner19.nbt,8,minecraft:white_wall_banner[facing=east],../JungleNBT/banners/JungleBanner20.nbt,100)

#######################################################################
# +-----------------------------------------------------------------+ #
# |                            BO3 checks                           | #
# +-----------------------------------------------------------------+ #
#######################################################################


#######################################################################
# +-----------------------------------------------------------------+ #
# |                             Branches                            | #
# +-----------------------------------------------------------------+ #
#######################################################################


#######################################################################
# +-----------------------------------------------------------------+ #
# |                             Entities                            | #
# +-----------------------------------------------------------------+ #
#######################################################################

Entity(0,0,-4,minecraft:villager,1,../JungleNBT/entities/tribalnative.txt)
