
#######################################################################
# +-----------------------------------------------------------------+ #
# |                            BO3 object                           | #
# +-----------------------------------------------------------------+ #
#######################################################################

Author: BO3 BulkEdit (by LanToaster)

Description: This Object was Created with BO3_BulkEdit

Version: 3

SettingsMode: WriteWithoutComments


#######################################################################
# +-----------------------------------------------------------------+ #
# |                          Main settings                          | #
# +-----------------------------------------------------------------+ #
#######################################################################

Tree: false

Frequency: 1

Rarity: 100.0

RotateRandomly: false

SpawnHeight: highestBlock

SpawnHeightOffset: 0

SpawnHeightVariance: 0

##############################
# Height Limits for the BO3. #
##############################

MinHeight: 0

MaxHeight: 255

######################
# Extrusion settings #
######################

ExtrudeMode: None

ExtrudeThroughBlocks: minecraft:air

MaxBranchDepth: 10


#######################################################################
# +-----------------------------------------------------------------+ #
# |                      Source block settings                      | #
# +-----------------------------------------------------------------+ #
#######################################################################

SourceBlocks: otg:air

MaxPercentageOutsideSourceBlock: 100

OutsideSourceBlock: placeAnyway

DoReplaceBlocks: true

IsOTGPlus: false


#######################################################################
# +-----------------------------------------------------------------+ #
# |                              Blocks                             | #
# +-----------------------------------------------------------------+ #
#######################################################################

B(-7,24,-7,minecraft:dark_oak_planks)
B(-7,25,-7,minecraft:dark_oak_planks)
B(-7,26,-7,minecraft:dark_oak_planks)
B(-7,27,-7,minecraft:dark_oak_planks)
B(-7,28,-7,minecraft:cyan_terracotta)
B(-7,29,-7,minecraft:cyan_terracotta)
B(-7,30,-7,minecraft:dark_oak_stairs[facing=south,half=bottom,shape=outer_left,waterlogged=false])
B(-7,24,-6,minecraft:oak_button[face=wall,facing=west,powered=false])
B(-7,26,-6,minecraft:dark_oak_planks)
B(-7,27,-6,minecraft:dark_oak_planks)
B(-7,28,-6,minecraft:black_stained_glass)
B(-7,29,-6,minecraft:black_stained_glass)
B(-7,30,-6,minecraft:dark_oak_stairs[facing=east,half=bottom,shape=straight,waterlogged=false])
B(-7,27,-5,minecraft:dark_oak_stairs[facing=east,half=top,shape=straight,waterlogged=false])
B(-7,28,-5,minecraft:black_stained_glass)
B(-7,29,-5,minecraft:black_stained_glass)
B(-7,30,-5,minecraft:dark_oak_stairs[facing=east,half=bottom,shape=straight,waterlogged=false])
B(-7,27,-4,minecraft:dark_oak_slab[type=top,waterlogged=false])
B(-7,28,-4,minecraft:cyan_terracotta)
B(-7,29,-4,minecraft:cyan_terracotta)
B(-7,30,-4,minecraft:dark_oak_stairs[facing=east,half=bottom,shape=straight,waterlogged=false])
B(-7,28,-3,minecraft:stone_button[face=wall,facing=south,powered=false])
B(-7,29,-3,minecraft:stone_button[face=wall,facing=south,powered=false])
B(-7,28,-1,minecraft:stone_button[face=wall,facing=west,powered=false])
B(-7,29,-1,minecraft:stone_button[face=wall,facing=west,powered=false])
B(-7,24,5,minecraft:dark_oak_slab[type=top,waterlogged=false])
B(-7,25,5,minecraft:iron_bars[east=false,north=false,south=true,waterlogged=false,west=false])
B(-7,26,5,minecraft:iron_bars[east=false,north=false,south=true,waterlogged=false,west=false])
B(-7,27,5,minecraft:dark_oak_slab)
B(-7,28,5,minecraft:dark_oak_fence[east=false,north=false,south=true,waterlogged=false,west=false])
B(-7,29,5,minecraft:dark_oak_fence[east=false,north=false,south=true,waterlogged=false,west=false])
B(-7,30,5,minecraft:dark_oak_fence[east=false,north=false,south=true,waterlogged=false,west=false])
B(-7,2,6,minecraft:mossy_stone_bricks)
B(-7,3,6,minecraft:cracked_stone_bricks)
B(-7,5,6,minecraft:mossy_stone_bricks)
B(-7,24,6,minecraft:oak_stairs[facing=west,half=top,shape=straight,waterlogged=false])
B(-7,25,6,minecraft:iron_bars[east=true,north=true,south=true,waterlogged=false,west=false])
B(-7,26,6,minecraft:iron_bars[east=true,north=true,south=true,waterlogged=false,west=false])
B(-7,27,6,minecraft:oak_stairs[facing=west,half=bottom,shape=straight,waterlogged=false])
B(-7,28,6,minecraft:dark_oak_fence[east=true,north=true,south=true,waterlogged=false,west=false])
B(-7,29,6,minecraft:jungle_log[axis=x])
B(-7,30,6,minecraft:dark_oak_fence[east=false,north=true,south=true,waterlogged=false,west=false])
B(-7,1,7,minecraft:cracked_stone_bricks)
B(-7,3,7,minecraft:infested_mossy_stone_bricks)
B(-7,6,7,minecraft:infested_mossy_stone_bricks)
B(-7,24,7,minecraft:dark_oak_slab[type=top,waterlogged=false])
B(-7,25,7,minecraft:iron_bars[east=false,north=true,south=false,waterlogged=false,west=false])
B(-7,26,7,minecraft:iron_bars[east=false,north=true,south=false,waterlogged=false,west=false])
B(-7,27,7,minecraft:dark_oak_slab)
B(-7,28,7,minecraft:dark_oak_fence[east=true,north=true,south=false,waterlogged=false,west=false])
B(-7,29,7,minecraft:dark_oak_fence[east=false,north=true,south=false,waterlogged=false,west=false])
B(-7,30,7,minecraft:dark_oak_fence[east=false,north=true,south=false,waterlogged=false,west=false])
B(-7,2,8,minecraft:infested_stone_bricks)
B(-7,6,8,minecraft:infested_mossy_stone_bricks)
B(-6,21,-7,minecraft:dark_oak_wood)
B(-6,22,-7,minecraft:dark_oak_planks)
B(-6,23,-7,minecraft:dark_oak_planks)
B(-6,24,-7,minecraft:spruce_planks)
B(-6,25,-7,minecraft:spruce_planks)
B(-6,26,-7,minecraft:cyan_terracotta)
B(-6,27,-7,minecraft:cyan_terracotta)
B(-6,28,-7,minecraft:cyan_terracotta)
B(-6,29,-7,minecraft:cyan_terracotta)
B(-6,30,-7,minecraft:cyan_terracotta)
B(-6,31,-7,minecraft:cyan_terracotta)
B(-6,32,-7,minecraft:dark_oak_stairs[facing=south,half=bottom,shape=straight,waterlogged=false])
B(-6,24,-6,minecraft:dark_oak_planks)
B(-6,25,-6,minecraft:dark_oak_planks)
B(-6,26,-6,minecraft:bookshelf)
B(-6,27,-6,minecraft:bookshelf)
B(-6,30,-6,minecraft:cyan_terracotta)
B(-6,31,-6,minecraft:cyan_terracotta)
B(-6,32,-6,minecraft:cyan_terracotta)
B(-6,33,-6,minecraft:dark_oak_slab)
B(-6,24,-5,minecraft:oak_button[face=wall,facing=west,powered=false])
B(-6,25,-5,minecraft:dark_oak_planks)
B(-6,26,-5,minecraft:dark_oak_planks)
B(-6,27,-5,minecraft:bookshelf)
B(-6,30,-5,minecraft:spruce_planks)
B(-6,26,-4,minecraft:dark_oak_planks)
B(-6,27,-4,minecraft:spruce_planks)
B(-6,30,-4,minecraft:dark_oak_stairs[facing=east,half=bottom,shape=straight,waterlogged=false])
B(-6,27,-3,minecraft:dark_oak_stairs[facing=north,half=top,shape=inner_right,waterlogged=false])
B(-6,28,-3,minecraft:black_stained_glass)
B(-6,29,-3,minecraft:black_stained_glass)
B(-6,30,-3,minecraft:dark_oak_stairs[facing=east,half=bottom,shape=straight,waterlogged=false])
B(-6,27,-2,minecraft:dark_oak_stairs[facing=east,half=top,shape=straight,waterlogged=false])
B(-6,28,-2,minecraft:black_stained_glass)
B(-6,29,-2,minecraft:black_stained_glass)
B(-6,30,-2,minecraft:dark_oak_stairs[facing=east,half=bottom,shape=straight,waterlogged=false])
B(-6,27,-1,minecraft:dark_oak_stairs[facing=east,half=top,shape=outer_left,waterlogged=false])
B(-6,28,-1,minecraft:cyan_terracotta)
B(-6,29,-1,minecraft:cyan_terracotta)
B(-6,30,-1,minecraft:dark_oak_stairs[facing=east,half=bottom,shape=straight,waterlogged=false])
B(-6,28,0,minecraft:stone_button[face=wall,facing=south,powered=false])
B(-6,29,0,minecraft:stone_button[face=wall,facing=south,powered=false])
B(-6,1,6,minecraft:cobblestone)
B(-6,2,6,minecraft:cobblestone)
B(-6,3,6,minecraft:cobblestone)
B(-6,4,6,minecraft:cobblestone)
B(-6,5,6,minecraft:cobblestone)
B(-6,6,6,minecraft:cobblestone)
B(-6,7,6,minecraft:cobblestone)
B(-6,8,6,minecraft:cobblestone)
B(-6,9,6,minecraft:jungle_log)
B(-6,10,6,minecraft:jungle_log)
B(-6,11,6,minecraft:jungle_log)
B(-6,12,6,minecraft:jungle_log)
B(-6,13,6,minecraft:jungle_log)
B(-6,14,6,minecraft:jungle_log)
B(-6,15,6,minecraft:jungle_log)
B(-6,16,6,minecraft:jungle_log)
B(-6,17,6,minecraft:jungle_log)
B(-6,18,6,minecraft:jungle_log)
B(-6,19,6,minecraft:jungle_log)
B(-6,20,6,minecraft:jungle_log)
B(-6,21,6,minecraft:jungle_log)
B(-6,22,6,minecraft:jungle_log)
B(-6,23,6,minecraft:jungle_log)
B(-6,24,6,minecraft:jungle_log)
B(-6,25,6,minecraft:jungle_log)
B(-6,26,6,minecraft:jungle_log)
B(-6,27,6,minecraft:jungle_log)
B(-6,28,6,minecraft:jungle_log)
B(-6,29,6,minecraft:oak_stairs[facing=west,half=bottom,shape=straight,waterlogged=false])
B(-6,1,7,minecraft:cracked_stone_bricks)
B(-6,2,7,minecraft:mossy_stone_bricks)
B(-6,3,7,minecraft:cracked_stone_bricks)
B(-6,6,7,minecraft:infested_mossy_stone_bricks)
B(-6,27,7,minecraft:oak_fence[east=false,north=true,south=true,waterlogged=false,west=false])
B(-6,28,7,minecraft:oak_fence[east=false,north=true,south=false,waterlogged=false,west=true])
B(-6,1,8,minecraft:infested_mossy_stone_bricks)
B(-6,2,8,minecraft:cracked_stone_bricks)
B(-6,6,8,minecraft:cracked_stone_bricks)
B(-6,26,8,minecraft:oak_fence)
B(-6,27,8,minecraft:oak_fence[east=false,north=true,south=false,waterlogged=false,west=false])
B(-5,20,-7,minecraft:dark_oak_wood)
B(-5,21,-7,minecraft:dark_oak_wood)
B(-5,22,-7,minecraft:dark_oak_planks)
B(-5,25,-7,minecraft:dark_oak_slab[type=top,waterlogged=false])
B(-5,26,-7,minecraft:cyan_terracotta)
B(-5,27,-7,minecraft:cyan_terracotta)
B(-5,28,-7,minecraft:cyan_terracotta)
B(-5,29,-7,minecraft:cyan_terracotta)
B(-5,23,-6,minecraft:dark_oak_planks)
B(-5,24,-6,minecraft:dark_oak_planks)
B(-5,25,-6,minecraft:spruce_planks)
B(-5,26,-6,minecraft:bookshelf)
B(-5,27,-6,minecraft:red_carpet)
B(-5,30,-6,minecraft:spruce_slab)
B(-5,24,-5,minecraft:dark_oak_planks)
B(-5,25,-5,minecraft:spruce_planks)
B(-5,26,-5,minecraft:bookshelf)
B(-5,27,-5,minecraft:red_carpet)
B(-5,30,-5,minecraft:cyan_terracotta)
B(-5,31,-5,minecraft:cyan_terracotta)
B(-5,32,-5,minecraft:cyan_terracotta)
B(-5,33,-5,minecraft:dark_oak_slab)
B(-5,24,-4,minecraft:oak_button[face=wall,facing=south,powered=false])
B(-5,25,-4,minecraft:cyan_terracotta)
B(-5,26,-4,minecraft:dark_oak_planks)
B(-5,27,-4,minecraft:red_carpet)
B(-5,30,-4,minecraft:cyan_terracotta)
B(-5,31,-4,minecraft:cyan_terracotta)
B(-5,32,-4,minecraft:cyan_terracotta)
B(-5,33,-4,minecraft:dark_oak_stairs[facing=south,half=bottom,shape=straight,waterlogged=false])
B(-5,26,-3,minecraft:dark_oak_slab[type=top,waterlogged=false])
B(-5,27,-3,minecraft:red_carpet)
B(-5,30,-3,minecraft:cyan_terracotta)
B(-5,31,-3,minecraft:cyan_terracotta)
B(-5,32,-3,minecraft:cyan_terracotta)
B(-5,33,-3,minecraft:cyan_terracotta)
B(-5,34,-3,minecraft:dark_oak_slab)
B(-5,26,-2,minecraft:dark_oak_slab[type=top,waterlogged=false])
B(-5,27,-2,minecraft:red_carpet)
B(-5,30,-2,minecraft:cyan_terracotta)
B(-5,31,-2,minecraft:cyan_terracotta)
B(-5,32,-2,minecraft:cyan_terracotta)
B(-5,33,-2,minecraft:cyan_terracotta)
B(-5,34,-2,minecraft:dark_oak_slab)
B(-5,27,-1,minecraft:dark_oak_stairs[facing=north,half=top,shape=straight,waterlogged=false])
B(-5,28,-1,minecraft:black_stained_glass)
B(-5,29,-1,minecraft:black_stained_glass)
B(-5,30,-1,minecraft:dark_oak_stairs[facing=east,half=bottom,shape=straight,waterlogged=false])
B(-5,34,-1,minecraft:oak_trapdoor[facing=east,half=top,open=true,powered=false,waterlogged=false])
B(-5,1,6,minecraft:cracked_stone_bricks)
B(-5,3,6,minecraft:infested_mossy_stone_bricks)
B(-5,4,6,minecraft:cracked_stone_bricks)
B(-5,6,6,minecraft:cracked_stone_bricks)
B(-5,25,6,minecraft:oak_fence[east=true,north=false,south=false,waterlogged=false,west=true])
B(-5,26,6,minecraft:oak_fence[east=false,north=false,south=false,waterlogged=false,west=true])
B(-5,1,7,minecraft:cracked_stone_bricks)
B(-5,2,7,minecraft:cracked_stone_bricks)
B(-5,3,7,minecraft:cracked_stone_bricks)
B(-5,6,7,minecraft:infested_cracked_stone_bricks)
B(-5,2,8,minecraft:mossy_stone_bricks)
B(-5,3,8,minecraft:mossy_stone_bricks)
B(-5,6,8,minecraft:infested_stone_bricks)
B(-4,20,-7,minecraft:dark_oak_wood)
B(-4,21,-7,minecraft:dark_oak_wood)
B(-4,22,-7,minecraft:dark_oak_planks)
B(-4,25,-7,minecraft:dark_oak_slab[type=top,waterlogged=false])
B(-4,26,-7,minecraft:dark_oak_planks)
B(-4,27,-7,minecraft:dark_oak_planks)
B(-4,28,-7,minecraft:dark_oak_planks)
B(-4,29,-7,minecraft:cyan_terracotta)
B(-4,23,-6,minecraft:dark_oak_planks)
B(-4,24,-6,minecraft:dark_oak_planks)
B(-4,25,-6,minecraft:spruce_planks)
B(-4,26,-6,minecraft:spruce_stairs[facing=west,half=bottom,shape=straight,waterlogged=false])
B(-4,30,-6,minecraft:spruce_slab)
B(-4,24,-5,minecraft:dark_oak_planks)
B(-4,25,-5,minecraft:spruce_planks)
B(-4,26,-5,minecraft:bookshelf)
B(-4,27,-5,minecraft:red_carpet)
B(-4,30,-5,minecraft:cyan_terracotta)
B(-4,24,-4,minecraft:oak_button[face=wall,facing=south,powered=false])
B(-4,25,-4,minecraft:cyan_terracotta)
B(-4,26,-4,minecraft:spruce_planks)
B(-4,27,-4,minecraft:red_carpet)
B(-4,30,-4,minecraft:cyan_terracotta)
B(-4,26,-3,minecraft:cyan_terracotta)
B(-4,27,-3,minecraft:red_carpet)
B(-4,30,-3,minecraft:cyan_terracotta)
B(-4,31,-3,minecraft:dark_oak_slab)
B(-4,26,-2,minecraft:dark_oak_slab[type=top,waterlogged=false])
B(-4,27,-2,minecraft:red_carpet)
B(-4,30,-2,minecraft:cyan_terracotta)
B(-4,31,-2,minecraft:cyan_terracotta)
B(-4,32,-2,minecraft:cyan_terracotta)
B(-4,33,-2,minecraft:cyan_terracotta)
B(-4,34,-2,minecraft:dark_oak_slab)
B(-4,27,-1,minecraft:dark_oak_stairs[facing=east,half=top,shape=inner_left,waterlogged=false])
B(-4,30,-1,minecraft:dark_oak_stairs[facing=east,half=bottom,shape=straight,waterlogged=false])
B(-4,33,-1,minecraft:cobblestone_wall[east=low,north=low,south=none,up=true,waterlogged=false,west=none])
B(-4,35,-1,minecraft:dark_oak_slab)
B(-4,27,0,minecraft:dark_oak_slab[type=top,waterlogged=false])
B(-4,28,0,minecraft:black_stained_glass)
B(-4,29,0,minecraft:black_stained_glass)
B(-4,30,0,minecraft:dark_oak_stairs[facing=east,half=bottom,shape=straight,waterlogged=false])
B(-4,34,0,minecraft:oak_trapdoor[facing=north,half=top,open=true,powered=false,waterlogged=false])
B(-4,1,3,minecraft:cobblestone)
B(-4,2,3,minecraft:cobblestone)
B(-4,3,3,minecraft:cobblestone)
B(-4,4,3,minecraft:cobblestone)
B(-4,5,3,minecraft:cobblestone)
B(-4,6,3,minecraft:cobblestone)
B(-4,7,3,minecraft:cobblestone)
B(-4,8,3,minecraft:cobblestone)
B(-4,9,3,minecraft:jungle_log)
B(-4,10,3,minecraft:jungle_log)
B(-4,11,3,minecraft:jungle_log)
B(-4,12,3,minecraft:jungle_log)
B(-4,13,3,minecraft:jungle_log)
B(-4,14,3,minecraft:jungle_log)
B(-4,15,3,minecraft:jungle_log)
B(-4,16,3,minecraft:jungle_log)
B(-4,17,3,minecraft:jungle_log)
B(-4,18,3,minecraft:jungle_log)
B(-4,19,3,minecraft:jungle_log)
B(-4,20,3,minecraft:jungle_log)
B(-4,21,3,minecraft:jungle_log)
B(-4,22,3,minecraft:jungle_log)
B(-4,23,3,minecraft:cobblestone_wall)
B(-4,1,4,minecraft:cracked_stone_bricks)
B(-4,2,4,minecraft:mossy_stone_bricks)
B(-4,3,4,minecraft:infested_stone_bricks)
B(-4,4,4,minecraft:cracked_stone_bricks)
B(-4,5,4,minecraft:infested_cracked_stone_bricks)
B(-4,6,4,minecraft:mossy_stone_bricks)
B(-4,22,4,minecraft:oak_stairs[facing=north,half=top,shape=straight,waterlogged=false])
B(-4,23,4,minecraft:cauldron[level=3])
B(-4,3,5,minecraft:cracked_stone_bricks)
B(-4,4,5,minecraft:infested_cracked_stone_bricks)
B(-4,22,5,minecraft:oak_stairs[facing=south,half=top,shape=straight,waterlogged=false])
B(-4,1,6,minecraft:cobblestone)
B(-4,2,6,minecraft:cobblestone)
B(-4,3,6,minecraft:cobblestone)
B(-4,4,6,minecraft:cobblestone)
B(-4,5,6,minecraft:cobblestone)
B(-4,6,6,minecraft:cobblestone)
B(-4,7,6,minecraft:cobblestone)
B(-4,8,6,minecraft:cobblestone)
B(-4,9,6,minecraft:jungle_log)
B(-4,10,6,minecraft:jungle_log)
B(-4,11,6,minecraft:jungle_log)
B(-4,12,6,minecraft:jungle_log)
B(-4,13,6,minecraft:jungle_log)
B(-4,14,6,minecraft:jungle_log)
B(-4,15,6,minecraft:jungle_log)
B(-4,16,6,minecraft:jungle_log)
B(-4,17,6,minecraft:jungle_log)
B(-4,18,6,minecraft:jungle_log)
B(-4,19,6,minecraft:jungle_log)
B(-4,20,6,minecraft:jungle_log)
B(-4,21,6,minecraft:jungle_log)
B(-4,22,6,minecraft:jungle_log)
B(-4,23,6,minecraft:jungle_log)
B(-4,24,6,minecraft:cobblestone_wall)
B(-4,25,6,minecraft:oak_fence[east=false,north=false,south=false,waterlogged=false,west=true])
B(-4,1,7,minecraft:mossy_stone_bricks)
B(-4,2,7,minecraft:infested_stone_bricks)
B(-4,6,7,minecraft:infested_cracked_stone_bricks)
B(-4,23,7,minecraft:oak_stairs[facing=north,half=top,shape=straight,waterlogged=false])
B(-4,24,7,minecraft:oak_fence[east=false,north=false,south=true,waterlogged=false,west=false])
B(-4,1,8,minecraft:mossy_stone_bricks)
B(-4,2,8,minecraft:infested_cracked_stone_bricks)
B(-4,3,8,minecraft:cracked_stone_bricks)
B(-4,6,8,minecraft:mossy_stone_bricks)
B(-4,23,8,minecraft:oak_stairs[facing=south,half=top,shape=straight,waterlogged=false])
B(-4,24,8,minecraft:oak_fence[east=false,north=true,south=false,waterlogged=false,west=false])
B(-3,19,-7,minecraft:dark_oak_wood)
B(-3,20,-7,minecraft:dark_oak_wood)
B(-3,21,-7,minecraft:dark_oak_wood)
B(-3,22,-7,minecraft:dark_oak_planks)
B(-3,23,-7,minecraft:spruce_log)
B(-3,24,-7,minecraft:spruce_log)
B(-3,25,-7,minecraft:spruce_planks)
B(-3,26,-7,minecraft:red_carpet)
B(-3,28,-7,minecraft:dark_oak_stairs[facing=west,half=top,shape=straight,waterlogged=false])
B(-3,29,-7,minecraft:cyan_terracotta)
B(-3,23,-6,minecraft:dark_oak_planks)
B(-3,24,-6,minecraft:redstone_block)
B(-3,25,-6,minecraft:spruce_planks)
B(-3,26,-6,minecraft:red_carpet)
B(-3,30,-6,minecraft:spruce_slab)
B(-3,24,-5,minecraft:dark_oak_planks)
B(-3,25,-5,minecraft:spruce_planks)
B(-3,26,-5,minecraft:bookshelf)
B(-3,27,-5,minecraft:red_carpet)
B(-3,30,-5,minecraft:cyan_terracotta)
B(-3,31,-5,minecraft:dark_oak_fence[east=true,north=false,south=false,waterlogged=false,west=false])
B(-3,24,-4,minecraft:oak_button[face=wall,facing=south,powered=false])
B(-3,25,-4,minecraft:cyan_terracotta)
B(-3,26,-4,minecraft:spruce_planks)
B(-3,27,-4,minecraft:red_carpet)
B(-3,30,-4,minecraft:cyan_terracotta)
B(-3,26,-3,minecraft:cyan_terracotta)
B(-3,27,-3,minecraft:dark_oak_stairs[facing=west,half=top,shape=straight,waterlogged=false])
B(-3,30,-3,minecraft:cyan_terracotta)
B(-3,26,-2,minecraft:dark_oak_stairs[facing=north,half=top,shape=straight,waterlogged=false])
B(-3,27,-2,minecraft:red_carpet)
B(-3,30,-2,minecraft:cyan_terracotta)
B(-3,31,-2,minecraft:spruce_planks)
B(-3,32,-2,minecraft:dark_oak_stairs[facing=south,half=bottom,shape=straight,waterlogged=false])
B(-3,34,-2,minecraft:lever[face=wall,facing=north,powered=true])
B(-3,26,-1,minecraft:dark_oak_slab[type=top,waterlogged=false])
B(-3,27,-1,minecraft:spruce_planks)
B(-3,28,-1,minecraft:dark_oak_stairs[facing=east,half=bottom,shape=straight,waterlogged=false])
B(-3,30,-1,minecraft:cyan_terracotta)
B(-3,31,-1,minecraft:cyan_terracotta)
B(-3,32,-1,minecraft:cyan_terracotta)
B(-3,33,-1,minecraft:cyan_terracotta)
B(-3,34,-1,minecraft:spruce_planks)
B(-3,27,0,minecraft:dark_oak_stairs[facing=north,half=top,shape=straight,waterlogged=false])
B(-3,28,0,minecraft:black_stained_glass)
B(-3,29,0,minecraft:black_stained_glass)
B(-3,30,0,minecraft:dark_oak_stairs[facing=east,half=bottom,shape=straight,waterlogged=false])
B(-3,35,0,minecraft:oak_trapdoor[facing=east,half=top,open=true,powered=false,waterlogged=false])
B(-3,1,3,minecraft:infested_mossy_stone_bricks)
B(-3,2,3,minecraft:infested_stone_bricks)
B(-3,3,3,minecraft:mossy_stone_bricks)
B(-3,6,3,minecraft:infested_mossy_stone_bricks)
B(-3,22,3,minecraft:oak_stairs[facing=west,half=top,shape=straight,waterlogged=false])
B(-3,1,4,minecraft:mossy_stone_bricks)
B(-3,2,4,minecraft:mossy_stone_bricks)
B(-3,3,4,minecraft:cracked_stone_bricks)
B(-3,4,4,minecraft:melon)
B(-3,5,4,minecraft:melon)
B(-3,6,4,minecraft:cracked_stone_bricks)
B(-3,22,4,minecraft:dark_oak_slab[type=top,waterlogged=false])
B(-3,1,5,minecraft:mossy_stone_bricks)
B(-3,2,5,minecraft:cracked_stone_bricks)
B(-3,3,5,minecraft:cracked_stone_bricks)
B(-3,4,5,minecraft:melon)
B(-3,5,5,minecraft:melon)
B(-3,6,5,minecraft:cracked_stone_bricks)
B(-3,22,5,minecraft:dark_oak_slab[type=top,waterlogged=false])
B(-3,23,5,minecraft:dark_oak_stairs[facing=south,half=bottom,shape=straight,waterlogged=false])
B(-3,1,6,minecraft:cracked_stone_bricks)
B(-3,3,6,minecraft:cracked_stone_bricks)
B(-3,4,6,minecraft:mossy_stone_bricks)
B(-3,6,6,minecraft:infested_cracked_stone_bricks)
B(-3,23,6,minecraft:oak_stairs[facing=west,half=top,shape=straight,waterlogged=false])
B(-3,24,6,minecraft:anvil)
B(-3,1,7,minecraft:cracked_stone_bricks)
B(-3,2,7,minecraft:infested_cracked_stone_bricks)
B(-3,3,7,minecraft:cracked_stone_bricks)
B(-3,6,7,minecraft:cracked_stone_bricks)
B(-3,23,7,minecraft:dark_oak_slab[type=top,waterlogged=false])
B(-3,1,8,minecraft:mossy_stone_bricks)
B(-3,23,8,minecraft:dark_oak_slab[type=top,waterlogged=false])
B(-2,18,-7,minecraft:dark_oak_planks)
B(-2,19,-7,minecraft:dark_oak_wood)
B(-2,20,-7,minecraft:dark_oak_wood)
B(-2,21,-7,minecraft:dark_oak_wood)
B(-2,22,-7,minecraft:dark_oak_planks)
B(-2,24,-7,minecraft:oak_trapdoor[facing=south,half=top,open=true,powered=false,waterlogged=false])
B(-2,25,-7,minecraft:dark_oak_slab[type=top,waterlogged=false])
B(-2,26,-7,minecraft:red_carpet)
B(-2,28,-7,minecraft:dark_oak_slab[type=top,waterlogged=false])
B(-2,29,-7,minecraft:cyan_terracotta)
B(-2,30,-7,minecraft:spruce_slab)
B(-2,41,-7,minecraft:spruce_fence[east=true,north=false,south=true,waterlogged=false,west=false])
B(-2,42,-7,minecraft:spruce_wood)
B(-2,52,-7,minecraft:black_wool)
B(-2,16,-6,minecraft:dark_oak_fence[east=false,north=false,south=true,waterlogged=false,west=false])
B(-2,17,-6,minecraft:dark_oak_fence[east=false,north=false,south=true,waterlogged=false,west=false])
B(-2,18,-6,minecraft:dark_oak_fence[east=false,north=true,south=true,waterlogged=false,west=false])
B(-2,19,-6,minecraft:dark_oak_fence[east=false,north=true,south=true,waterlogged=false,west=false])
B(-2,20,-6,minecraft:dark_oak_fence[east=false,north=true,south=true,waterlogged=false,west=false])
B(-2,21,-6,minecraft:dark_oak_fence[east=false,north=true,south=true,waterlogged=false,west=false])
B(-2,22,-6,minecraft:dark_oak_fence[east=false,north=true,south=true,waterlogged=false,west=false])
B(-2,23,-6,minecraft:dark_oak_planks)
B(-2,25,-6,minecraft:spruce_planks)
B(-2,26,-6,minecraft:red_carpet)
B(-2,30,-6,minecraft:spruce_slab)
B(-2,41,-6,minecraft:black_wool)
B(-2,52,-6,minecraft:black_wool)
B(-2,15,-5,minecraft:dark_oak_planks)
B(-2,16,-5,minecraft:dark_oak_wood)
B(-2,17,-5,minecraft:dark_oak_wood)
B(-2,18,-5,minecraft:dark_oak_wood)
B(-2,19,-5,minecraft:dark_oak_wood)
B(-2,20,-5,minecraft:dark_oak_wood)
B(-2,21,-5,minecraft:dark_oak_wood)
B(-2,22,-5,minecraft:dark_oak_planks)
B(-2,24,-5,minecraft:dark_oak_planks)
B(-2,25,-5,minecraft:spruce_planks)
B(-2,26,-5,minecraft:bookshelf)
B(-2,27,-5,minecraft:red_carpet)
B(-2,30,-5,minecraft:cyan_terracotta)
B(-2,31,-5,minecraft:dark_oak_fence[east=true,north=false,south=false,waterlogged=false,west=true])
B(-2,41,-5,minecraft:black_wool)
B(-2,42,-5,minecraft:black_wool)
B(-2,15,-4,minecraft:dark_oak_planks)
B(-2,16,-4,minecraft:dark_oak_wood)
B(-2,17,-4,minecraft:dark_oak_wood)
B(-2,18,-4,minecraft:dark_oak_wood)
B(-2,19,-4,minecraft:dark_oak_wood)
B(-2,20,-4,minecraft:dark_oak_wood)
B(-2,21,-4,minecraft:dark_oak_wood)
B(-2,22,-4,minecraft:dark_oak_wood)
B(-2,23,-4,minecraft:dark_oak_planks)
B(-2,24,-4,minecraft:oak_button[face=wall,facing=south,powered=false])
B(-2,25,-4,minecraft:cyan_terracotta)
B(-2,26,-4,minecraft:spruce_planks)
B(-2,27,-4,minecraft:red_carpet)
B(-2,30,-4,minecraft:cyan_terracotta)
B(-2,42,-4,minecraft:black_wool)
B(-2,43,-4,minecraft:black_wool)
B(-2,15,-3,minecraft:dark_oak_planks)
B(-2,16,-3,minecraft:dark_oak_wood)
B(-2,17,-3,minecraft:dark_oak_wood)
B(-2,18,-3,minecraft:dark_oak_wood)
B(-2,19,-3,minecraft:dark_oak_wood)
B(-2,20,-3,minecraft:dark_oak_wood)
B(-2,21,-3,minecraft:dark_oak_wood)
B(-2,22,-3,minecraft:dark_oak_wood)
B(-2,23,-3,minecraft:dark_oak_wood)
B(-2,24,-3,minecraft:dark_oak_planks)
B(-2,26,-3,minecraft:cyan_terracotta)
B(-2,27,-3,minecraft:dark_oak_slab[type=top,waterlogged=false])
B(-2,28,-3,minecraft:white_carpet)
B(-2,30,-3,minecraft:cyan_terracotta)
B(-2,15,-2,minecraft:dark_oak_planks)
B(-2,16,-2,minecraft:dark_oak_planks)
B(-2,17,-2,minecraft:dark_oak_planks)
B(-2,18,-2,minecraft:dark_oak_wood)
B(-2,19,-2,minecraft:dark_oak_wood)
B(-2,20,-2,minecraft:dark_oak_wood)
B(-2,21,-2,minecraft:dark_oak_planks)
B(-2,22,-2,minecraft:dark_oak_planks)
B(-2,23,-2,minecraft:dark_oak_planks)
B(-2,24,-2,minecraft:dark_oak_planks)
B(-2,26,-2,minecraft:dark_oak_slab[type=top,waterlogged=false])
B(-2,27,-2,minecraft:dark_oak_stairs[facing=south,half=bottom,shape=straight,waterlogged=false])
B(-2,30,-2,minecraft:cyan_terracotta)
B(-2,31,-2,minecraft:dark_oak_slab)
B(-2,17,-1,minecraft:dark_oak_planks)
B(-2,18,-1,minecraft:dark_oak_planks)
B(-2,19,-1,minecraft:dark_oak_planks)
B(-2,20,-1,minecraft:dark_oak_planks)
B(-2,21,-1,minecraft:dark_oak_planks)
B(-2,26,-1,minecraft:dark_oak_slab[type=top,waterlogged=false])
B(-2,27,-1,minecraft:spruce_planks)
B(-2,28,-1,minecraft:spruce_planks)
B(-2,30,-1,minecraft:cyan_terracotta)
B(-2,31,-1,minecraft:cyan_terracotta)
B(-2,32,-1,minecraft:cyan_terracotta)
B(-2,33,-1,minecraft:cyan_terracotta)
B(-2,34,-1,minecraft:spruce_planks)
B(-2,35,-1,minecraft:lever[face=wall,facing=north,powered=true])
B(-2,27,0,minecraft:dark_oak_slab[type=top,waterlogged=false])
B(-2,28,0,minecraft:cyan_terracotta)
B(-2,29,0,minecraft:cyan_terracotta)
B(-2,30,0,minecraft:dark_oak_stairs[facing=east,half=bottom,shape=straight,waterlogged=false])
B(-2,34,0,minecraft:cobblestone_wall[east=none,north=low,south=none,up=true,waterlogged=false,west=none])
B(-2,36,0,minecraft:dark_oak_slab)
B(-2,28,1,minecraft:stone_button[face=wall,facing=south,powered=false])
B(-2,29,1,minecraft:stone_button[face=wall,facing=south,powered=false])
B(-2,35,1,minecraft:oak_trapdoor[facing=north,half=top,open=true,powered=false,waterlogged=false])
B(-2,2,3,minecraft:mossy_stone_bricks)
B(-2,3,3,minecraft:mossy_stone_bricks)
B(-2,5,3,minecraft:infested_mossy_stone_bricks)
B(-2,6,3,minecraft:cracked_stone_bricks)
B(-2,22,3,minecraft:oak_stairs[facing=east,half=top,shape=straight,waterlogged=false])
B(-2,1,4,minecraft:mossy_stone_bricks)
B(-2,2,4,minecraft:mossy_stone_bricks)
B(-2,3,4,minecraft:cracked_stone_bricks)
B(-2,4,4,minecraft:melon)
B(-2,6,4,minecraft:mossy_stone_bricks)
B(-2,22,4,minecraft:dark_oak_slab[type=top,waterlogged=false])
B(-2,1,5,minecraft:cracked_stone_bricks)
B(-2,2,5,minecraft:infested_mossy_stone_bricks)
B(-2,3,5,minecraft:mossy_stone_bricks)
B(-2,4,5,minecraft:melon)
B(-2,22,5,minecraft:dark_oak_slab[type=top,waterlogged=false])
B(-2,23,5,minecraft:dark_oak_stairs[facing=south,half=bottom,shape=straight,waterlogged=false])
B(-2,1,6,minecraft:infested_cracked_stone_bricks)
B(-2,2,6,minecraft:cracked_stone_bricks)
B(-2,3,6,minecraft:mossy_stone_bricks)
B(-2,4,6,minecraft:mossy_stone_bricks)
B(-2,5,6,minecraft:cracked_stone_bricks)
B(-2,23,6,minecraft:oak_stairs[facing=east,half=top,shape=straight,waterlogged=false])
B(-2,1,7,minecraft:mossy_stone_bricks)
B(-2,2,7,minecraft:cracked_stone_bricks)
B(-2,3,7,minecraft:mossy_stone_bricks)
B(-2,6,7,minecraft:cracked_stone_bricks)
B(-2,23,7,minecraft:dark_oak_slab[type=top,waterlogged=false])
B(-2,2,8,minecraft:infested_cracked_stone_bricks)
B(-2,3,8,minecraft:infested_stone_bricks)
B(-2,6,8,minecraft:mossy_stone_bricks)
B(-2,23,8,minecraft:dark_oak_slab[type=top,waterlogged=false])
B(-1,19,-7,minecraft:dark_oak_wood)
B(-1,20,-7,minecraft:dark_oak_wood)
B(-1,21,-7,minecraft:dark_oak_wood)
B(-1,22,-7,minecraft:dark_oak_planks)
B(-1,23,-7,minecraft:spruce_log)
B(-1,24,-7,minecraft:spruce_log)
B(-1,25,-7,minecraft:spruce_planks)
B(-1,26,-7,minecraft:red_carpet)
B(-1,28,-7,minecraft:dark_oak_stairs[facing=east,half=top,shape=straight,waterlogged=false])
B(-1,29,-7,minecraft:cyan_terracotta)
B(-1,41,-7,minecraft:black_wool)
B(-1,23,-6,minecraft:dark_oak_planks)
B(-1,24,-6,minecraft:dark_oak_planks)
B(-1,25,-6,minecraft:spruce_planks)
B(-1,26,-6,minecraft:red_carpet)
B(-1,30,-6,minecraft:spruce_slab)
B(-1,39,-6,minecraft:black_wool)
B(-1,40,-6,minecraft:black_wool)
B(-1,24,-5,minecraft:dark_oak_planks)
B(-1,25,-5,minecraft:spruce_planks)
B(-1,26,-5,minecraft:bookshelf)
B(-1,27,-5,minecraft:red_carpet)
B(-1,30,-5,minecraft:cyan_terracotta)
B(-1,31,-5,minecraft:dark_oak_fence[east=false,north=false,south=false,waterlogged=false,west=true])
B(-1,24,-4,minecraft:oak_button[face=wall,facing=south,powered=false])
B(-1,25,-4,minecraft:cyan_terracotta)
B(-1,26,-4,minecraft:spruce_planks)
B(-1,27,-4,minecraft:red_carpet)
B(-1,30,-4,minecraft:cyan_terracotta)
B(-1,26,-3,minecraft:cyan_terracotta)
B(-1,27,-3,minecraft:dark_oak_stairs[facing=east,half=top,shape=straight,waterlogged=false])
B(-1,30,-3,minecraft:cyan_terracotta)
B(-1,26,-2,minecraft:dark_oak_stairs[facing=north,half=top,shape=straight,waterlogged=false])
B(-1,27,-2,minecraft:red_carpet)
B(-1,30,-2,minecraft:cyan_terracotta)
B(-1,31,-2,minecraft:spruce_planks)
B(-1,32,-2,minecraft:dark_oak_stairs[facing=south,half=bottom,shape=straight,waterlogged=false])
B(-1,34,-2,minecraft:lever[face=wall,facing=north,powered=true])
B(-1,26,-1,minecraft:dark_oak_slab[type=top,waterlogged=false])
B(-1,27,-1,minecraft:spruce_planks)
B(-1,28,-1,minecraft:dark_oak_stairs[facing=west,half=bottom,shape=straight,waterlogged=false])
B(-1,30,-1,minecraft:cyan_terracotta)
B(-1,31,-1,minecraft:cyan_terracotta)
B(-1,32,-1,minecraft:cyan_terracotta)
B(-1,33,-1,minecraft:cyan_terracotta)
B(-1,34,-1,minecraft:spruce_planks)
B(-1,27,0,minecraft:dark_oak_stairs[facing=north,half=top,shape=straight,waterlogged=false])
B(-1,28,0,minecraft:black_stained_glass)
B(-1,29,0,minecraft:black_stained_glass)
B(-1,30,0,minecraft:dark_oak_stairs[facing=east,half=bottom,shape=straight,waterlogged=false])
B(-1,35,0,minecraft:oak_trapdoor[facing=west,half=top,open=true,powered=false,waterlogged=false])
B(-1,1,3,minecraft:cobblestone)
B(-1,2,3,minecraft:cobblestone)
B(-1,3,3,minecraft:cobblestone)
B(-1,4,3,minecraft:cobblestone)
B(-1,5,3,minecraft:cobblestone)
B(-1,6,3,minecraft:cobblestone)
B(-1,7,3,minecraft:cobblestone)
B(-1,8,3,minecraft:cobblestone)
B(-1,9,3,minecraft:jungle_log)
B(-1,10,3,minecraft:jungle_log)
B(-1,11,3,minecraft:jungle_log)
B(-1,12,3,minecraft:jungle_log)
B(-1,13,3,minecraft:jungle_log)
B(-1,14,3,minecraft:jungle_log)
B(-1,15,3,minecraft:jungle_log)
B(-1,16,3,minecraft:jungle_log)
B(-1,17,3,minecraft:jungle_log)
B(-1,18,3,minecraft:jungle_log)
B(-1,19,3,minecraft:jungle_log)
B(-1,20,3,minecraft:jungle_log)
B(-1,21,3,minecraft:jungle_log)
B(-1,22,3,minecraft:jungle_log)
B(-1,23,3,minecraft:cobblestone_wall)
B(-1,2,4,minecraft:infested_mossy_stone_bricks)
B(-1,3,4,minecraft:mossy_stone_bricks)
B(-1,4,4,minecraft:hay_block[axis=z])
B(-1,5,4,minecraft:carved_pumpkin[facing=east])
B(-1,6,4,minecraft:mossy_stone_bricks)
B(-1,22,4,minecraft:dark_oak_slab[type=top,waterlogged=false])
B(-1,2,5,minecraft:mossy_stone_bricks)
B(-1,3,5,minecraft:infested_cracked_stone_bricks)
B(-1,4,5,minecraft:melon)
B(-1,6,5,minecraft:cracked_stone_bricks)
B(-1,22,5,minecraft:dark_oak_slab[type=top,waterlogged=false])
B(-1,23,5,minecraft:dark_oak_stairs[facing=south,half=bottom,shape=straight,waterlogged=false])
B(-1,1,6,minecraft:cobblestone)
B(-1,2,6,minecraft:cobblestone)
B(-1,3,6,minecraft:cobblestone)
B(-1,4,6,minecraft:cobblestone)
B(-1,5,6,minecraft:cobblestone)
B(-1,6,6,minecraft:cobblestone)
B(-1,7,6,minecraft:cobblestone)
B(-1,8,6,minecraft:cobblestone)
B(-1,9,6,minecraft:jungle_log)
B(-1,10,6,minecraft:jungle_log)
B(-1,11,6,minecraft:jungle_log)
B(-1,12,6,minecraft:jungle_log)
B(-1,13,6,minecraft:jungle_log)
B(-1,14,6,minecraft:jungle_log)
B(-1,15,6,minecraft:jungle_log)
B(-1,16,6,minecraft:jungle_log)
B(-1,17,6,minecraft:jungle_log)
B(-1,18,6,minecraft:jungle_log)
B(-1,19,6,minecraft:jungle_log)
B(-1,20,6,minecraft:jungle_log)
B(-1,21,6,minecraft:jungle_log)
B(-1,22,6,minecraft:jungle_log)
B(-1,23,6,minecraft:jungle_log)
B(-1,2,7,minecraft:cracked_stone_bricks)
B(-1,3,7,minecraft:infested_mossy_stone_bricks)
B(-1,6,7,minecraft:infested_mossy_stone_bricks)
B(-1,23,7,minecraft:jungle_log[axis=z])
B(-1,1,8,minecraft:infested_stone_bricks)
B(-1,2,8,minecraft:mossy_stone_bricks)
B(-1,6,8,minecraft:mossy_stone_bricks)
B(-1,23,8,minecraft:jungle_log[axis=z])
B(0,20,-7,minecraft:dark_oak_wood)
B(0,21,-7,minecraft:dark_oak_wood)
B(0,22,-7,minecraft:dark_oak_planks)
B(0,24,-7,minecraft:light_blue_bed)
B(0,25,-7,minecraft:dark_oak_slab[type=top,waterlogged=false])
B(0,26,-7,minecraft:spruce_planks)
B(0,27,-7,minecraft:spruce_planks)
B(0,28,-7,minecraft:spruce_planks)
B(0,29,-7,minecraft:cyan_terracotta)
B(0,39,-7,minecraft:black_wool)
B(0,40,-7,minecraft:black_wool)
B(0,23,-6,minecraft:dark_oak_planks)
B(0,24,-6,minecraft:dark_oak_planks)
B(0,25,-6,minecraft:spruce_planks)
B(0,26,-6,minecraft:spruce_stairs[facing=east,half=bottom,shape=straight,waterlogged=false])
B(0,30,-6,minecraft:spruce_slab)
B(0,38,-6,minecraft:black_wool)
B(0,24,-5,minecraft:dark_oak_planks)
B(0,25,-5,minecraft:spruce_planks)
B(0,26,-5,minecraft:bookshelf)
B(0,27,-5,minecraft:red_carpet)
B(0,30,-5,minecraft:cyan_terracotta)
B(0,24,-4,minecraft:oak_button[face=wall,facing=south,powered=false])
B(0,25,-4,minecraft:cyan_terracotta)
B(0,26,-4,minecraft:spruce_planks)
B(0,27,-4,minecraft:red_carpet)
B(0,30,-4,minecraft:cyan_terracotta)
B(0,26,-3,minecraft:cyan_terracotta)
B(0,27,-3,minecraft:red_carpet)
B(0,30,-3,minecraft:cyan_terracotta)
B(0,31,-3,minecraft:dark_oak_slab)
B(0,26,-2,minecraft:dark_oak_slab[type=top,waterlogged=false])
B(0,27,-2,minecraft:red_carpet)
B(0,30,-2,minecraft:cyan_terracotta)
B(0,31,-2,minecraft:cyan_terracotta)
B(0,32,-2,minecraft:cyan_terracotta)
B(0,33,-2,minecraft:cyan_terracotta)
B(0,34,-2,minecraft:dark_oak_slab)
B(0,27,-1,minecraft:dark_oak_stairs[facing=west,half=top,shape=inner_right,waterlogged=false])
B(0,30,-1,minecraft:dark_oak_stairs[facing=east,half=bottom,shape=straight,waterlogged=false])
B(0,33,-1,minecraft:cobblestone_wall[east=none,north=low,south=none,up=true,waterlogged=false,west=low])
B(0,35,-1,minecraft:dark_oak_slab)
B(0,27,0,minecraft:dark_oak_slab[type=top,waterlogged=false])
B(0,28,0,minecraft:black_stained_glass)
B(0,29,0,minecraft:black_stained_glass)
B(0,30,0,minecraft:dark_oak_stairs[facing=west,half=bottom,shape=straight,waterlogged=false])
B(0,34,0,minecraft:oak_trapdoor[facing=north,half=top,open=true,powered=false,waterlogged=false])
B(0,1,3,minecraft:cracked_stone_bricks)
B(0,2,3,minecraft:infested_mossy_stone_bricks)
B(0,3,3,minecraft:cracked_stone_bricks)
B(0,4,3,minecraft:mossy_stone_bricks)
B(0,5,3,minecraft:infested_cracked_stone_bricks)
B(0,6,3,minecraft:cracked_stone_bricks)
B(0,22,3,minecraft:oak_stairs[facing=west,half=top,shape=straight,waterlogged=false])
B(0,1,4,minecraft:mossy_stone_bricks)
B(0,3,4,minecraft:cracked_stone_bricks)
B(0,4,4,minecraft:hay_block[axis=z])
B(0,5,4,minecraft:hay_block[axis=z])
B(0,22,4,minecraft:dark_oak_slab[type=top,waterlogged=false])
B(0,1,5,minecraft:infested_cracked_stone_bricks)
B(0,3,5,minecraft:cracked_stone_bricks)
B(0,4,5,minecraft:melon)
B(0,6,5,minecraft:mossy_stone_bricks)
B(0,22,5,minecraft:dark_oak_slab[type=top,waterlogged=false])
B(0,23,5,minecraft:dark_oak_stairs[facing=south,half=bottom,shape=straight,waterlogged=false])
B(0,1,6,minecraft:cracked_stone_bricks)
B(0,2,6,minecraft:infested_stone_bricks)
B(0,4,6,minecraft:mossy_stone_bricks)
B(0,5,6,minecraft:mossy_stone_bricks)
B(0,23,6,minecraft:oak_stairs[facing=west,half=top,shape=straight,waterlogged=false])
B(0,1,7,minecraft:mossy_stone_bricks)
B(0,2,7,minecraft:infested_mossy_stone_bricks)
B(0,3,7,minecraft:cracked_stone_bricks)
B(0,6,7,minecraft:cracked_stone_bricks)
B(0,23,7,minecraft:dark_oak_slab[type=top,waterlogged=false])
B(0,2,8,minecraft:mossy_stone_bricks)
B(0,3,8,minecraft:infested_cracked_stone_bricks)
B(0,6,8,minecraft:infested_stone_bricks)
B(0,23,8,minecraft:dark_oak_slab[type=top,waterlogged=false])
B(1,20,-7,minecraft:dark_oak_wood)
B(1,21,-7,minecraft:dark_oak_wood)
B(1,22,-7,minecraft:dark_oak_planks)
B(1,24,-7,minecraft:blue_bed)
B(1,25,-7,minecraft:dark_oak_slab[type=top,waterlogged=false])
B(1,26,-7,minecraft:cyan_terracotta)
B(1,27,-7,minecraft:cyan_terracotta)
B(1,28,-7,minecraft:cyan_terracotta)
B(1,29,-7,minecraft:cyan_terracotta)
B(1,37,-7,minecraft:black_wool)
B(1,38,-7,minecraft:black_wool)
B(1,23,-6,minecraft:dark_oak_planks)
B(1,24,-6,minecraft:dark_oak_planks)
B(1,25,-6,minecraft:spruce_planks)
B(1,26,-6,minecraft:bookshelf)
B(1,27,-6,minecraft:red_carpet)
B(1,30,-6,minecraft:spruce_slab)
B(1,24,-5,minecraft:dark_oak_planks)
B(1,25,-5,minecraft:spruce_planks)
B(1,26,-5,minecraft:bookshelf)
B(1,27,-5,minecraft:red_carpet)
B(1,30,-5,minecraft:cyan_terracotta)
B(1,31,-5,minecraft:cyan_terracotta)
B(1,32,-5,minecraft:cyan_terracotta)
B(1,33,-5,minecraft:dark_oak_slab)
B(1,24,-4,minecraft:oak_button[face=wall,facing=south,powered=false])
B(1,25,-4,minecraft:cyan_terracotta)
B(1,26,-4,minecraft:dark_oak_planks)
B(1,27,-4,minecraft:red_carpet)
B(1,30,-4,minecraft:cyan_terracotta)
B(1,31,-4,minecraft:cyan_terracotta)
B(1,32,-4,minecraft:cyan_terracotta)
B(1,33,-4,minecraft:dark_oak_stairs[facing=south,half=bottom,shape=straight,waterlogged=false])
B(1,26,-3,minecraft:dark_oak_slab[type=top,waterlogged=false])
B(1,27,-3,minecraft:red_carpet)
B(1,30,-3,minecraft:cyan_terracotta)
B(1,31,-3,minecraft:cyan_terracotta)
B(1,32,-3,minecraft:cyan_terracotta)
B(1,33,-3,minecraft:cyan_terracotta)
B(1,34,-3,minecraft:dark_oak_slab)
B(1,26,-2,minecraft:dark_oak_slab[type=top,waterlogged=false])
B(1,27,-2,minecraft:red_carpet)
B(1,30,-2,minecraft:cyan_terracotta)
B(1,31,-2,minecraft:cyan_terracotta)
B(1,32,-2,minecraft:cyan_terracotta)
B(1,33,-2,minecraft:cyan_terracotta)
B(1,34,-2,minecraft:dark_oak_slab)
B(1,27,-1,minecraft:dark_oak_stairs[facing=north,half=top,shape=straight,waterlogged=false])
B(1,28,-1,minecraft:black_stained_glass)
B(1,29,-1,minecraft:black_stained_glass)
B(1,30,-1,minecraft:dark_oak_stairs[facing=east,half=bottom,shape=straight,waterlogged=false])
B(1,34,-1,minecraft:oak_trapdoor[facing=west,half=top,open=true,powered=false,waterlogged=false])
B(1,1,3,minecraft:mossy_stone_bricks)
B(1,2,3,minecraft:infested_mossy_stone_bricks)
B(1,3,3,minecraft:mossy_stone_bricks)
B(1,4,3,minecraft:mossy_stone_bricks)
B(1,22,3,minecraft:oak_stairs[facing=east,half=top,shape=straight,waterlogged=false])
B(1,2,4,minecraft:cracked_stone_bricks)
B(1,3,4,minecraft:cracked_stone_bricks)
B(1,4,4,minecraft:melon)
B(1,5,4,minecraft:carved_pumpkin[facing=west])
B(1,6,4,minecraft:mossy_stone_bricks)
B(1,22,4,minecraft:dark_oak_slab[type=top,waterlogged=false])
B(1,1,5,minecraft:cracked_stone_bricks)
B(1,2,5,minecraft:infested_stone_bricks)
B(1,3,5,minecraft:mossy_stone_bricks)
B(1,22,5,minecraft:dark_oak_slab[type=top,waterlogged=false])
B(1,23,5,minecraft:dark_oak_stairs[facing=south,half=bottom,shape=straight,waterlogged=false])
B(1,1,6,minecraft:infested_stone_bricks)
B(1,2,6,minecraft:mossy_stone_bricks)
B(1,4,6,minecraft:infested_cracked_stone_bricks)
B(1,5,6,minecraft:infested_stone_bricks)
B(1,6,6,minecraft:cracked_stone_bricks)
B(1,23,6,minecraft:oak_stairs[facing=east,half=top,shape=straight,waterlogged=false])
B(1,1,7,minecraft:cracked_stone_bricks)
B(1,2,7,minecraft:infested_cracked_stone_bricks)
B(1,3,7,minecraft:cracked_stone_bricks)
B(1,6,7,minecraft:cracked_stone_bricks)
B(1,23,7,minecraft:dark_oak_slab[type=top,waterlogged=false])
B(1,1,8,minecraft:cracked_stone_bricks)
B(1,2,8,minecraft:infested_cracked_stone_bricks)
B(1,6,8,minecraft:cracked_stone_bricks)
B(1,23,8,minecraft:dark_oak_slab[type=top,waterlogged=false])
B(2,21,-7,minecraft:dark_oak_wood)
B(2,22,-7,minecraft:dark_oak_planks)
B(2,23,-7,minecraft:dark_oak_planks)
B(2,24,-7,minecraft:spruce_planks)
B(2,25,-7,minecraft:spruce_planks)
B(2,26,-7,minecraft:cyan_terracotta)
B(2,27,-7,minecraft:cyan_terracotta)
B(2,28,-7,minecraft:cyan_terracotta)
B(2,29,-7,minecraft:cyan_terracotta)
B(2,30,-7,minecraft:dark_oak_planks)
B(2,31,-7,minecraft:cyan_terracotta)
B(2,32,-7,minecraft:dark_oak_stairs[facing=south,half=bottom,shape=straight,waterlogged=false])
B(2,36,-7,minecraft:black_wool)
B(2,24,-6,minecraft:dark_oak_planks)
B(2,25,-6,minecraft:dark_oak_planks)
B(2,26,-6,minecraft:bookshelf)
B(2,27,-6,minecraft:bookshelf)
B(2,30,-6,minecraft:cyan_terracotta)
B(2,31,-6,minecraft:cyan_terracotta)
B(2,32,-6,minecraft:cyan_terracotta)
B(2,33,-6,minecraft:dark_oak_slab)
B(2,24,-5,minecraft:oak_button[face=wall,facing=east,powered=false])
B(2,25,-5,minecraft:dark_oak_planks)
B(2,26,-5,minecraft:dark_oak_planks)
B(2,27,-5,minecraft:bookshelf)
B(2,30,-5,minecraft:spruce_planks)
B(2,26,-4,minecraft:dark_oak_planks)
B(2,27,-4,minecraft:spruce_planks)
B(2,30,-4,minecraft:dark_oak_stairs[facing=east,half=bottom,shape=straight,waterlogged=false])
B(2,27,-3,minecraft:dark_oak_stairs[facing=north,half=top,shape=inner_left,waterlogged=false])
B(2,28,-3,minecraft:black_stained_glass)
B(2,29,-3,minecraft:black_stained_glass)
B(2,30,-3,minecraft:dark_oak_stairs[facing=west,half=bottom,shape=straight,waterlogged=false])
B(2,27,-2,minecraft:dark_oak_stairs[facing=west,half=top,shape=straight,waterlogged=false])
B(2,28,-2,minecraft:black_stained_glass)
B(2,29,-2,minecraft:black_stained_glass)
B(2,30,-2,minecraft:dark_oak_stairs[facing=west,half=bottom,shape=straight,waterlogged=false])
B(2,27,-1,minecraft:dark_oak_stairs[facing=west,half=top,shape=outer_right,waterlogged=false])
B(2,28,-1,minecraft:cyan_terracotta)
B(2,29,-1,minecraft:cyan_terracotta)
B(2,30,-1,minecraft:dark_oak_stairs[facing=west,half=bottom,shape=straight,waterlogged=false])
B(2,28,0,minecraft:stone_button[face=wall,facing=south,powered=false])
B(2,29,0,minecraft:stone_button[face=wall,facing=south,powered=false])
B(2,1,3,minecraft:cobblestone)
B(2,2,3,minecraft:cobblestone)
B(2,3,3,minecraft:cobblestone)
B(2,4,3,minecraft:cobblestone)
B(2,5,3,minecraft:cobblestone)
B(2,6,3,minecraft:cobblestone)
B(2,7,3,minecraft:cobblestone)
B(2,8,3,minecraft:cobblestone)
B(2,9,3,minecraft:jungle_log)
B(2,10,3,minecraft:jungle_log)
B(2,11,3,minecraft:jungle_log)
B(2,12,3,minecraft:jungle_log)
B(2,13,3,minecraft:jungle_log)
B(2,14,3,minecraft:jungle_log)
B(2,15,3,minecraft:jungle_log)
B(2,16,3,minecraft:jungle_log)
B(2,17,3,minecraft:jungle_log)
B(2,18,3,minecraft:jungle_log)
B(2,19,3,minecraft:jungle_log)
B(2,20,3,minecraft:jungle_log)
B(2,21,3,minecraft:jungle_log)
B(2,22,3,minecraft:jungle_log)
B(2,23,3,minecraft:cobblestone_wall)
B(2,3,4,minecraft:infested_stone_bricks)
B(2,4,4,minecraft:hay_block[axis=z])
B(2,6,4,minecraft:mossy_stone_bricks)
B(2,22,4,minecraft:dark_oak_slab[type=top,waterlogged=false])
B(2,1,5,minecraft:mossy_stone_bricks)
B(2,3,5,minecraft:cracked_stone_bricks)
B(2,6,5,minecraft:infested_mossy_stone_bricks)
B(2,22,5,minecraft:dark_oak_slab[type=top,waterlogged=false])
B(2,23,5,minecraft:dark_oak_stairs[facing=south,half=bottom,shape=straight,waterlogged=false])
B(2,1,6,minecraft:cobblestone)
B(2,2,6,minecraft:cobblestone)
B(2,3,6,minecraft:cobblestone)
B(2,4,6,minecraft:cobblestone)
B(2,5,6,minecraft:cobblestone)
B(2,6,6,minecraft:cobblestone)
B(2,7,6,minecraft:cobblestone)
B(2,8,6,minecraft:cobblestone)
B(2,9,6,minecraft:jungle_log)
B(2,10,6,minecraft:jungle_log)
B(2,11,6,minecraft:jungle_log)
B(2,12,6,minecraft:jungle_log)
B(2,13,6,minecraft:jungle_log)
B(2,14,6,minecraft:jungle_log)
B(2,15,6,minecraft:jungle_log)
B(2,16,6,minecraft:jungle_log)
B(2,17,6,minecraft:jungle_log)
B(2,18,6,minecraft:jungle_log)
B(2,19,6,minecraft:jungle_log)
B(2,20,6,minecraft:jungle_log)
B(2,21,6,minecraft:jungle_log)
B(2,22,6,minecraft:jungle_log)
B(2,23,6,minecraft:jungle_log)
B(2,2,7,minecraft:cracked_stone_bricks)
B(2,3,7,minecraft:infested_mossy_stone_bricks)
B(2,23,7,minecraft:dark_oak_slab[type=top,waterlogged=false])
B(2,1,8,minecraft:infested_stone_bricks)
B(2,2,8,minecraft:mossy_stone_bricks)
B(2,3,8,minecraft:cracked_stone_bricks)
B(2,6,8,minecraft:infested_stone_bricks)
B(2,23,8,minecraft:dark_oak_slab[type=top,waterlogged=false])
B(3,24,-7,minecraft:dark_oak_planks)
B(3,25,-7,minecraft:spruce_planks)
B(3,26,-7,minecraft:spruce_planks)
B(3,27,-7,minecraft:spruce_planks)
B(3,28,-7,minecraft:cyan_terracotta)
B(3,29,-7,minecraft:cyan_terracotta)
B(3,30,-7,minecraft:dark_oak_stairs[facing=south,half=bottom,shape=outer_right,waterlogged=false])
B(3,35,-7,minecraft:black_wool)
B(3,24,-6,minecraft:oak_button[face=wall,facing=east,powered=false])
B(3,26,-6,minecraft:spruce_planks)
B(3,27,-6,minecraft:spruce_planks)
B(3,28,-6,minecraft:black_stained_glass)
B(3,29,-6,minecraft:black_stained_glass)
B(3,30,-6,minecraft:dark_oak_stairs[facing=west,half=bottom,shape=straight,waterlogged=false])
B(3,27,-5,minecraft:dark_oak_stairs[facing=west,half=top,shape=straight,waterlogged=false])
B(3,28,-5,minecraft:black_stained_glass)
B(3,29,-5,minecraft:black_stained_glass)
B(3,30,-5,minecraft:dark_oak_stairs[facing=west,half=bottom,shape=straight,waterlogged=false])
B(3,27,-4,minecraft:dark_oak_slab[type=top,waterlogged=false])
B(3,28,-4,minecraft:cyan_terracotta)
B(3,29,-4,minecraft:cyan_terracotta)
B(3,30,-4,minecraft:dark_oak_stairs[facing=west,half=bottom,shape=straight,waterlogged=false])
B(3,28,-3,minecraft:stone_button[face=wall,facing=south,powered=false])
B(3,29,-3,minecraft:stone_button[face=wall,facing=south,powered=false])
B(3,28,-1,minecraft:stone_button[face=wall,facing=east,powered=false])
B(3,29,-1,minecraft:stone_button[face=wall,facing=east,powered=false])
B(3,1,3,minecraft:mossy_stone_bricks)
B(3,4,3,minecraft:infested_stone_bricks)
B(3,22,3,minecraft:oak_stairs[facing=west,half=top,shape=straight,waterlogged=false])
B(3,2,4,minecraft:cracked_stone_bricks)
B(3,3,4,minecraft:infested_cracked_stone_bricks)
B(3,4,4,minecraft:hay_block[axis=x])
B(3,6,4,minecraft:cracked_stone_bricks)
B(3,22,4,minecraft:dark_oak_slab[type=top,waterlogged=false])
B(3,1,5,minecraft:cracked_stone_bricks)
B(3,3,5,minecraft:mossy_stone_bricks)
B(3,22,5,minecraft:dark_oak_slab[type=top,waterlogged=false])
B(3,23,5,minecraft:dark_oak_stairs[facing=south,half=bottom,shape=straight,waterlogged=false])
B(3,1,6,minecraft:infested_mossy_stone_bricks)
B(3,2,6,minecraft:infested_cracked_stone_bricks)
B(3,3,6,minecraft:mossy_stone_bricks)
B(3,4,6,minecraft:iron_door)
B(3,5,6,minecraft:iron_door[facing=north,half=upper,hinge=left,open=false,powered=false])
B(3,6,6,minecraft:cracked_stone_bricks)
B(3,23,6,minecraft:oak_stairs[facing=west,half=top,shape=straight,waterlogged=false])
B(3,3,7,minecraft:infested_mossy_stone_bricks)
B(3,6,7,minecraft:cracked_stone_bricks)
B(3,23,7,minecraft:dark_oak_slab[type=top,waterlogged=false])
B(3,1,8,minecraft:cracked_stone_bricks)
B(3,2,8,minecraft:mossy_stone_bricks)
B(3,6,8,minecraft:cracked_stone_bricks)
B(3,23,8,minecraft:dark_oak_slab[type=top,waterlogged=false])
B(4,24,-7,minecraft:oak_button[face=wall,facing=east,powered=false])
B(4,28,-7,minecraft:stone_button[face=wall,facing=east,powered=false])
B(4,29,-7,minecraft:stone_button[face=wall,facing=east,powered=false])
B(4,33,-7,minecraft:black_wool)
B(4,34,-7,minecraft:black_wool)
B(4,32,-6,minecraft:black_wool)
B(4,33,-6,minecraft:black_wool)
B(4,32,-5,minecraft:black_wool)
B(4,28,-4,minecraft:stone_button[face=wall,facing=east,powered=false])
B(4,29,-4,minecraft:stone_button[face=wall,facing=east,powered=false])
B(4,1,3,minecraft:infested_mossy_stone_bricks)
B(4,3,3,minecraft:cracked_stone_bricks)
B(4,5,3,minecraft:infested_stone_bricks)
B(4,6,3,minecraft:cracked_stone_bricks)
B(4,22,3,minecraft:oak_stairs[facing=east,half=top,shape=straight,waterlogged=false])
B(4,1,4,minecraft:mossy_stone_bricks)
B(4,2,4,minecraft:mossy_stone_bricks)
B(4,3,4,minecraft:cracked_stone_bricks)
B(4,4,4,minecraft:melon)
B(4,5,4,minecraft:hay_block[axis=x])
B(4,6,4,minecraft:infested_mossy_stone_bricks)
B(4,22,4,minecraft:dark_oak_slab[type=top,waterlogged=false])
B(4,2,5,minecraft:infested_stone_bricks)
B(4,3,5,minecraft:cracked_stone_bricks)
B(4,4,5,minecraft:melon)
B(4,6,5,minecraft:cracked_stone_bricks)
B(4,22,5,minecraft:dark_oak_slab[type=top,waterlogged=false])
B(4,23,5,minecraft:dark_oak_stairs[facing=south,half=bottom,shape=straight,waterlogged=false])
B(4,1,6,minecraft:mossy_stone_bricks)
B(4,2,6,minecraft:mossy_stone_bricks)
B(4,4,6,minecraft:cracked_stone_bricks)
B(4,5,6,minecraft:infested_mossy_stone_bricks)
B(4,6,6,minecraft:cracked_stone_bricks)
B(4,23,6,minecraft:oak_stairs[facing=east,half=top,shape=straight,waterlogged=false])
B(4,1,7,minecraft:mossy_stone_bricks)
B(4,3,7,minecraft:cracked_stone_bricks)
B(4,5,7,minecraft:lever[face=wall,facing=south,powered=false])
B(4,23,7,minecraft:dark_oak_slab[type=top,waterlogged=false])
B(4,1,8,minecraft:mossy_stone_bricks)
B(4,6,8,minecraft:cracked_stone_bricks)
B(4,23,8,minecraft:dark_oak_slab[type=top,waterlogged=false])
B(5,1,3,minecraft:cobblestone)
B(5,2,3,minecraft:cobblestone)
B(5,3,3,minecraft:cobblestone)
B(5,4,3,minecraft:cobblestone)
B(5,5,3,minecraft:cobblestone)
B(5,6,3,minecraft:cobblestone)
B(5,7,3,minecraft:cobblestone)
B(5,8,3,minecraft:cobblestone)
B(5,9,3,minecraft:jungle_log)
B(5,10,3,minecraft:jungle_log)
B(5,11,3,minecraft:jungle_log)
B(5,12,3,minecraft:jungle_log)
B(5,13,3,minecraft:jungle_log)
B(5,14,3,minecraft:jungle_log)
B(5,15,3,minecraft:jungle_log)
B(5,16,3,minecraft:jungle_log)
B(5,17,3,minecraft:jungle_log)
B(5,18,3,minecraft:jungle_log)
B(5,19,3,minecraft:jungle_log)
B(5,20,3,minecraft:jungle_log)
B(5,21,3,minecraft:jungle_log)
B(5,22,3,minecraft:jungle_log)
B(5,23,3,minecraft:cobblestone_wall)
B(5,1,4,minecraft:mossy_stone_bricks)
B(5,2,4,minecraft:mossy_stone_bricks)
B(5,3,4,minecraft:mossy_stone_bricks)
B(5,4,4,minecraft:mossy_stone_bricks)
B(5,6,4,minecraft:cracked_stone_bricks)
B(5,22,4,minecraft:oak_stairs[facing=north,half=top,shape=straight,waterlogged=false])
B(5,1,5,minecraft:mossy_stone_bricks)
B(5,2,5,minecraft:infested_stone_bricks)
B(5,3,5,minecraft:mossy_stone_bricks)
B(5,4,5,minecraft:mossy_stone_bricks)
B(5,5,5,minecraft:cracked_stone_bricks)
B(5,22,5,minecraft:oak_stairs[facing=south,half=top,shape=straight,waterlogged=false])
B(5,23,5,minecraft:cauldron[level=3])
B(5,1,6,minecraft:cobblestone)
B(5,2,6,minecraft:cobblestone)
B(5,3,6,minecraft:cobblestone)
B(5,4,6,minecraft:cobblestone)
B(5,5,6,minecraft:cobblestone)
B(5,6,6,minecraft:cobblestone)
B(5,7,6,minecraft:cobblestone)
B(5,8,6,minecraft:cobblestone)
B(5,9,6,minecraft:jungle_log)
B(5,10,6,minecraft:jungle_log)
B(5,11,6,minecraft:jungle_log)
B(5,12,6,minecraft:jungle_log)
B(5,13,6,minecraft:jungle_log)
B(5,14,6,minecraft:jungle_log)
B(5,15,6,minecraft:jungle_log)
B(5,16,6,minecraft:jungle_log)
B(5,17,6,minecraft:jungle_log)
B(5,18,6,minecraft:jungle_log)
B(5,19,6,minecraft:jungle_log)
B(5,20,6,minecraft:jungle_log)
B(5,21,6,minecraft:jungle_log)
B(5,22,6,minecraft:jungle_log)
B(5,23,6,minecraft:jungle_log)
B(5,24,6,minecraft:cobblestone_wall)
B(5,25,6,minecraft:torch)
B(5,1,7,minecraft:mossy_stone_bricks)
B(5,2,7,minecraft:cracked_stone_bricks)
B(5,3,7,minecraft:mossy_stone_bricks)
B(5,6,7,minecraft:mossy_stone_bricks)
B(5,23,7,minecraft:jungle_log[axis=z])
B(5,1,8,minecraft:cracked_stone_bricks)
B(5,2,8,minecraft:mossy_stone_bricks)
B(5,6,8,minecraft:infested_cracked_stone_bricks)
B(5,23,8,minecraft:jungle_log[axis=z])
B(6,1,6,minecraft:cracked_stone_bricks)
B(6,2,6,minecraft:infested_stone_bricks)
B(6,3,6,minecraft:cracked_stone_bricks)
B(6,4,6,minecraft:infested_stone_bricks)
B(6,5,6,minecraft:cracked_stone_bricks)
B(6,6,6,minecraft:mossy_stone_bricks)
B(6,23,6,minecraft:oak_stairs[facing=west,half=top,shape=straight,waterlogged=false])
B(6,1,7,minecraft:mossy_stone_bricks)
B(6,2,7,minecraft:mossy_stone_bricks)
B(6,4,7,minecraft:cobweb)
B(6,6,7,minecraft:mossy_stone_bricks)
B(6,23,7,minecraft:dark_oak_slab[type=top,waterlogged=false])
B(6,1,8,minecraft:infested_mossy_stone_bricks)
B(6,2,8,minecraft:infested_mossy_stone_bricks)
B(6,3,8,minecraft:infested_cracked_stone_bricks)
B(6,6,8,minecraft:cracked_stone_bricks)
B(6,23,8,minecraft:dark_oak_slab[type=top,waterlogged=false])
B(6,24,8,minecraft:hay_block)
B(7,1,6,minecraft:infested_mossy_stone_bricks)
B(7,3,6,minecraft:infested_cracked_stone_bricks)
B(7,4,6,minecraft:cracked_stone_bricks)
B(7,5,6,minecraft:infested_stone_bricks)
B(7,6,6,minecraft:cracked_stone_bricks)
B(7,23,6,minecraft:oak_stairs[facing=east,half=top,shape=straight,waterlogged=false])
B(7,4,7,minecraft:dark_oak_fence[east=false,north=true,south=false,waterlogged=false,west=false])
B(7,5,7,minecraft:torch)
B(7,6,7,minecraft:cracked_stone_bricks)
B(7,23,7,minecraft:dark_oak_slab[type=top,waterlogged=false])
B(7,3,8,minecraft:cracked_stone_bricks)
B(7,6,8,minecraft:infested_cracked_stone_bricks)
B(7,23,8,minecraft:dark_oak_slab[type=top,waterlogged=false])
B(-6,28,-6,minecraft:skeleton_skull,StructureNBT/PirateBo3/pir31/1-Skull.nbt)
B(-6,28,-5,minecraft:air,StructureNBT/PirateBo3/pir31/2-FlowerPot.nbt)
B(-4,28,-1,minecraft:air,StructureNBT/PirateBo3/pir31/3-FlowerPot.nbt)
RB(-3,24,7,minecraft:chest[facing=east,type=single,waterlogged=false],./StructureNBT/StructureLoot/JunkChest_1.nbt,20,minecraft:chest[facing=east,type=single,waterlogged=false],./StructureNBT/StructureLoot/JunkChest_2.nbt,15,minecraft:chest[facing=east,type=single,waterlogged=false],./StructureNBT/StructureLoot/JunkChest_3.nbt,15,minecraft:chest[facing=east,type=single,waterlogged=false],./StructureNBT/StructureLoot/JunkChest_4.nbt,15,minecraft:chest[facing=east,type=single,waterlogged=false],./StructureNBT/StructureLoot/JunkChest_5.nbt,15,minecraft:chest[facing=east,type=single,waterlogged=false],./StructureNBT/LoreStoryline/LoreGeneric_5.nbt,2,minecraft:chest[facing=east,type=single,waterlogged=false],./StructureNBT/LoreStoryline/LoreGeneric_4.nbt,2,minecraft:chest[facing=east,type=single,waterlogged=false],./StructureNBT/LoreStoryline/LoreGeneric_3.nbt,2,minecraft:chest[facing=east,type=single,waterlogged=false],./StructureNBT/LoreStoryline/LoreGeneric_2.nbt,2,minecraft:chest[facing=east,type=single,waterlogged=false],./StructureNBT/LoreStoryline/LoreGeneric_1.nbt,2,minecraft:chest[facing=east,type=single,waterlogged=false],./StructureNBT/LoreStoryline/LorePirate_5.nbt,3,minecraft:chest[facing=east,type=single,waterlogged=false],./StructureNBT/LoreStoryline/LorePirate_4.nbt,3,minecraft:chest[facing=east,type=single,waterlogged=false],./StructureNBT/LoreStoryline/LorePirate_3.nbt,3,minecraft:chest[facing=east,type=single,waterlogged=false],./StructureNBT/LoreStoryline/LorePirate_2.nbt,3,minecraft:chest[facing=east,type=single,waterlogged=false],./StructureNBT/LoreStoryline/LorePirate_1.nbt,3,minecraft:chest[facing=east,type=single,waterlogged=false],./StructureNBT/StructureLoot/Common1.nbt,3,minecraft:chest[facing=east,type=single,waterlogged=false],./StructureNBT/StructureLoot/Common2.nbt,3,minecraft:chest[facing=east,type=single,waterlogged=false],./StructureNBT/StructureLoot/Common3.nbt,3,minecraft:chest[facing=east,type=single,waterlogged=false],./StructureNBT/StructureLoot/Common4.nbt,3,minecraft:chest[facing=east,type=single,waterlogged=false],./StructureNBT/StructureLoot/Common5.nbt,3,minecraft:chest[facing=east,type=single,waterlogged=false],./StructureNBT/StructureLoot/Common5.nbt,3,minecraft:chest[facing=east,type=single,waterlogged=false],./StructureNBT/StructureLoot/Common6.nbt,3,minecraft:chest[facing=east,type=single,waterlogged=false],./StructureNBT/StructureLoot/Common7.nbt,3,minecraft:chest[facing=east,type=single,waterlogged=false],./StructureNBT/StructureLoot/Common8.nbt,3,minecraft:chest[facing=east,type=single,waterlogged=false],./StructureNBT/StructureLoot/Common9.nbt,3,minecraft:chest[facing=east,type=single,waterlogged=false],./StructureNBT/StructureLoot/Common10.nbt,3,minecraft:chest[facing=east,type=single,waterlogged=false],./StructureNBT/StructureLoot/Common11.nbt,3,minecraft:chest[facing=east,type=single,waterlogged=false],./StructureNBT/StructureLoot/Common12.nbt,3,minecraft:chest[facing=east,type=single,waterlogged=false],./StructureNBT/StructureLoot/Common13.nbt,3,minecraft:chest[facing=east,type=single,waterlogged=false],./StructureNBT/StructureLoot/Common14.nbt,3,minecraft:chest[facing=east,type=single,waterlogged=false],./StructureNBT/StructureLoot/Common15.nbt,3,minecraft:chest[facing=east,type=single,waterlogged=false],./StructureNBT/StructureLoot/Rare1.nbt,3,minecraft:chest[facing=east,type=single,waterlogged=false],./StructureNBT/StructureLoot/Rare2.nbt,3,minecraft:chest[facing=east,type=single,waterlogged=false],./StructureNBT/StructureLoot/Rare3.nbt,3,minecraft:chest[facing=east,type=single,waterlogged=false],./StructureNBT/StructureLoot/Rare4.nbt,3,minecraft:chest[facing=east,type=single,waterlogged=false],./StructureNBT/StructureLoot/Rare5.nbt,3,minecraft:chest[facing=east,type=single,waterlogged=false],./StructureNBT/StructureLoot/Rare6.nbt,3,minecraft:chest[facing=east,type=single,waterlogged=false],./StructureNBT/StructureLoot/Rare7.nbt,3,minecraft:chest[facing=east,type=single,waterlogged=false],./StructureNBT/StructureLoot/Rare8.nbt,3,minecraft:chest[facing=east,type=single,waterlogged=false],./StructureNBT/StructureLoot/Rare9.nbt,3,minecraft:chest[facing=east,type=single,waterlogged=false],./StructureNBT/StructureLoot/Rare10.nbt,3,minecraft:chest[facing=east,type=single,waterlogged=false],./StructureNBT/StructureLoot/Rare11.nbt,3,minecraft:chest[facing=east,type=single,waterlogged=false],./StructureNBT/StructureLoot/Rare12.nbt,3,minecraft:chest[facing=east,type=single,waterlogged=false],./StructureNBT/StructureLoot/Rare13.nbt,3,minecraft:chest[facing=east,type=single,waterlogged=false],./StructureNBT/StructureLoot/Rare14.nbt,3,minecraft:chest[facing=east,type=single,waterlogged=false],./StructureNBT/StructureLoot/Rare15.nbt,3,minecraft:chest[facing=east,type=single,waterlogged=false],./StructureNBT/StructureLoot/Epic1.nbt,3,minecraft:chest[facing=east,type=single,waterlogged=false],./StructureNBT/StructureLoot/Epic2.nbt,3,minecraft:chest[facing=east,type=single,waterlogged=false],./StructureNBT/StructureLoot/Epic3.nbt,3,minecraft:chest[facing=east,type=single,waterlogged=false],./StructureNBT/StructureLoot/Epic4.nbt,3,minecraft:chest[facing=east,type=single,waterlogged=false],./StructureNBT/StructureLoot/Epic5.nbt,3,minecraft:chest[facing=east,type=single,waterlogged=false],./StructureNBT/StructureLoot/Epic6.nbt,3,minecraft:chest[facing=east,type=single,waterlogged=false],./StructureNBT/StructureLoot/Epic7.nbt,3,minecraft:chest[facing=east,type=single,waterlogged=false],./StructureNBT/StructureLoot/Epic8.nbt,3,minecraft:chest[facing=east,type=single,waterlogged=false],./StructureNBT/StructureLoot/Epic9.nbt,3,minecraft:chest[facing=east,type=single,waterlogged=false],./StructureNBT/StructureLoot/Epic10.nbt,3,minecraft:chest[facing=east,type=single,waterlogged=false],./StructureNBT/StructureLoot/Epic11.nbt,3,minecraft:chest[facing=east,type=single,waterlogged=false],./StructureNBT/StructureLoot/Epic12.nbt,3,minecraft:chest[facing=east,type=single,waterlogged=false],./StructureNBT/StructureLoot/Epic13.nbt,3,minecraft:chest[facing=east,type=single,waterlogged=false],./StructureNBT/StructureLoot/Epic14.nbt,3,minecraft:chest[facing=east,type=single,waterlogged=false],./StructureNBT/StructureLoot/Epic15.nbt,1,minecraft:chest[facing=east,type=single,waterlogged=false],./StructureNBT/StructureLoot/Common15.nbt,100)
RB(-3,24,8,minecraft:chest[facing=east,type=single,waterlogged=false],./StructureNBT/StructureLoot/JunkChest_1.nbt,20,minecraft:chest[facing=east,type=single,waterlogged=false],./StructureNBT/StructureLoot/JunkChest_2.nbt,15,minecraft:chest[facing=east,type=single,waterlogged=false],./StructureNBT/StructureLoot/JunkChest_3.nbt,15,minecraft:chest[facing=east,type=single,waterlogged=false],./StructureNBT/StructureLoot/JunkChest_4.nbt,15,minecraft:chest[facing=east,type=single,waterlogged=false],./StructureNBT/StructureLoot/JunkChest_5.nbt,15,minecraft:chest[facing=east,type=single,waterlogged=false],./StructureNBT/LoreStoryline/LoreGeneric_5.nbt,2,minecraft:chest[facing=east,type=single,waterlogged=false],./StructureNBT/LoreStoryline/LoreGeneric_4.nbt,2,minecraft:chest[facing=east,type=single,waterlogged=false],./StructureNBT/LoreStoryline/LoreGeneric_3.nbt,2,minecraft:chest[facing=east,type=single,waterlogged=false],./StructureNBT/LoreStoryline/LoreGeneric_2.nbt,2,minecraft:chest[facing=east,type=single,waterlogged=false],./StructureNBT/LoreStoryline/LoreGeneric_1.nbt,2,minecraft:chest[facing=east,type=single,waterlogged=false],./StructureNBT/LoreStoryline/LorePirate_5.nbt,3,minecraft:chest[facing=east,type=single,waterlogged=false],./StructureNBT/LoreStoryline/LorePirate_4.nbt,3,minecraft:chest[facing=east,type=single,waterlogged=false],./StructureNBT/LoreStoryline/LorePirate_3.nbt,3,minecraft:chest[facing=east,type=single,waterlogged=false],./StructureNBT/LoreStoryline/LorePirate_2.nbt,3,minecraft:chest[facing=east,type=single,waterlogged=false],./StructureNBT/LoreStoryline/LorePirate_1.nbt,3,minecraft:chest[facing=east,type=single,waterlogged=false],./StructureNBT/StructureLoot/Common1.nbt,3,minecraft:chest[facing=east,type=single,waterlogged=false],./StructureNBT/StructureLoot/Common2.nbt,3,minecraft:chest[facing=east,type=single,waterlogged=false],./StructureNBT/StructureLoot/Common3.nbt,3,minecraft:chest[facing=east,type=single,waterlogged=false],./StructureNBT/StructureLoot/Common4.nbt,3,minecraft:chest[facing=east,type=single,waterlogged=false],./StructureNBT/StructureLoot/Common5.nbt,3,minecraft:chest[facing=east,type=single,waterlogged=false],./StructureNBT/StructureLoot/Common5.nbt,3,minecraft:chest[facing=east,type=single,waterlogged=false],./StructureNBT/StructureLoot/Common6.nbt,3,minecraft:chest[facing=east,type=single,waterlogged=false],./StructureNBT/StructureLoot/Common7.nbt,3,minecraft:chest[facing=east,type=single,waterlogged=false],./StructureNBT/StructureLoot/Common8.nbt,3,minecraft:chest[facing=east,type=single,waterlogged=false],./StructureNBT/StructureLoot/Common9.nbt,3,minecraft:chest[facing=east,type=single,waterlogged=false],./StructureNBT/StructureLoot/Common10.nbt,3,minecraft:chest[facing=east,type=single,waterlogged=false],./StructureNBT/StructureLoot/Common11.nbt,3,minecraft:chest[facing=east,type=single,waterlogged=false],./StructureNBT/StructureLoot/Common12.nbt,3,minecraft:chest[facing=east,type=single,waterlogged=false],./StructureNBT/StructureLoot/Common13.nbt,3,minecraft:chest[facing=east,type=single,waterlogged=false],./StructureNBT/StructureLoot/Common14.nbt,3,minecraft:chest[facing=east,type=single,waterlogged=false],./StructureNBT/StructureLoot/Common15.nbt,3,minecraft:chest[facing=east,type=single,waterlogged=false],./StructureNBT/StructureLoot/Rare1.nbt,3,minecraft:chest[facing=east,type=single,waterlogged=false],./StructureNBT/StructureLoot/Rare2.nbt,3,minecraft:chest[facing=east,type=single,waterlogged=false],./StructureNBT/StructureLoot/Rare3.nbt,3,minecraft:chest[facing=east,type=single,waterlogged=false],./StructureNBT/StructureLoot/Rare4.nbt,3,minecraft:chest[facing=east,type=single,waterlogged=false],./StructureNBT/StructureLoot/Rare5.nbt,3,minecraft:chest[facing=east,type=single,waterlogged=false],./StructureNBT/StructureLoot/Rare6.nbt,3,minecraft:chest[facing=east,type=single,waterlogged=false],./StructureNBT/StructureLoot/Rare7.nbt,3,minecraft:chest[facing=east,type=single,waterlogged=false],./StructureNBT/StructureLoot/Rare8.nbt,3,minecraft:chest[facing=east,type=single,waterlogged=false],./StructureNBT/StructureLoot/Rare9.nbt,3,minecraft:chest[facing=east,type=single,waterlogged=false],./StructureNBT/StructureLoot/Rare10.nbt,3,minecraft:chest[facing=east,type=single,waterlogged=false],./StructureNBT/StructureLoot/Rare11.nbt,3,minecraft:chest[facing=east,type=single,waterlogged=false],./StructureNBT/StructureLoot/Rare12.nbt,3,minecraft:chest[facing=east,type=single,waterlogged=false],./StructureNBT/StructureLoot/Rare13.nbt,3,minecraft:chest[facing=east,type=single,waterlogged=false],./StructureNBT/StructureLoot/Rare14.nbt,3,minecraft:chest[facing=east,type=single,waterlogged=false],./StructureNBT/StructureLoot/Rare15.nbt,3,minecraft:chest[facing=east,type=single,waterlogged=false],./StructureNBT/StructureLoot/Epic1.nbt,3,minecraft:chest[facing=east,type=single,waterlogged=false],./StructureNBT/StructureLoot/Epic2.nbt,3,minecraft:chest[facing=east,type=single,waterlogged=false],./StructureNBT/StructureLoot/Epic3.nbt,3,minecraft:chest[facing=east,type=single,waterlogged=false],./StructureNBT/StructureLoot/Epic4.nbt,3,minecraft:chest[facing=east,type=single,waterlogged=false],./StructureNBT/StructureLoot/Epic5.nbt,3,minecraft:chest[facing=east,type=single,waterlogged=false],./StructureNBT/StructureLoot/Epic6.nbt,3,minecraft:chest[facing=east,type=single,waterlogged=false],./StructureNBT/StructureLoot/Epic7.nbt,3,minecraft:chest[facing=east,type=single,waterlogged=false],./StructureNBT/StructureLoot/Epic8.nbt,3,minecraft:chest[facing=east,type=single,waterlogged=false],./StructureNBT/StructureLoot/Epic9.nbt,3,minecraft:chest[facing=east,type=single,waterlogged=false],./StructureNBT/StructureLoot/Epic10.nbt,3,minecraft:chest[facing=east,type=single,waterlogged=false],./StructureNBT/StructureLoot/Epic11.nbt,3,minecraft:chest[facing=east,type=single,waterlogged=false],./StructureNBT/StructureLoot/Epic12.nbt,3,minecraft:chest[facing=east,type=single,waterlogged=false],./StructureNBT/StructureLoot/Epic13.nbt,3,minecraft:chest[facing=east,type=single,waterlogged=false],./StructureNBT/StructureLoot/Epic14.nbt,3,minecraft:chest[facing=east,type=single,waterlogged=false],./StructureNBT/StructureLoot/Epic15.nbt,1,minecraft:chest[facing=east,type=single,waterlogged=false],./StructureNBT/StructureLoot/Common15.nbt,100)
B(-3,28,-3,minecraft:air,StructureNBT/PirateBo3/pir31/6-FlowerPot.nbt)
B(-3,33,0,minecraft:white_wall_banner[facing=south],StructureNBT/PirateBo3/pir31/7-Banner.nbt)
RB(-2,23,-7,minecraft:chest[facing=east,type=single,waterlogged=false],./StructureNBT/StructureLoot/JunkChest_1.nbt,20,minecraft:chest[facing=east,type=single,waterlogged=false],./StructureNBT/StructureLoot/JunkChest_2.nbt,15,minecraft:chest[facing=east,type=single,waterlogged=false],./StructureNBT/StructureLoot/JunkChest_3.nbt,15,minecraft:chest[facing=east,type=single,waterlogged=false],./StructureNBT/StructureLoot/JunkChest_4.nbt,15,minecraft:chest[facing=east,type=single,waterlogged=false],./StructureNBT/StructureLoot/JunkChest_5.nbt,15,minecraft:chest[facing=east,type=single,waterlogged=false],./StructureNBT/LoreStoryline/LoreGeneric_5.nbt,2,minecraft:chest[facing=east,type=single,waterlogged=false],./StructureNBT/LoreStoryline/LoreGeneric_4.nbt,2,minecraft:chest[facing=east,type=single,waterlogged=false],./StructureNBT/LoreStoryline/LoreGeneric_3.nbt,2,minecraft:chest[facing=east,type=single,waterlogged=false],./StructureNBT/LoreStoryline/LoreGeneric_2.nbt,2,minecraft:chest[facing=east,type=single,waterlogged=false],./StructureNBT/LoreStoryline/LoreGeneric_1.nbt,2,minecraft:chest[facing=east,type=single,waterlogged=false],./StructureNBT/LoreStoryline/LorePirate_5.nbt,3,minecraft:chest[facing=east,type=single,waterlogged=false],./StructureNBT/LoreStoryline/LorePirate_4.nbt,3,minecraft:chest[facing=east,type=single,waterlogged=false],./StructureNBT/LoreStoryline/LorePirate_3.nbt,3,minecraft:chest[facing=east,type=single,waterlogged=false],./StructureNBT/LoreStoryline/LorePirate_2.nbt,3,minecraft:chest[facing=east,type=single,waterlogged=false],./StructureNBT/LoreStoryline/LorePirate_1.nbt,3,minecraft:chest[facing=east,type=single,waterlogged=false],./StructureNBT/StructureLoot/Common1.nbt,3,minecraft:chest[facing=east,type=single,waterlogged=false],./StructureNBT/StructureLoot/Common2.nbt,3,minecraft:chest[facing=east,type=single,waterlogged=false],./StructureNBT/StructureLoot/Common3.nbt,3,minecraft:chest[facing=east,type=single,waterlogged=false],./StructureNBT/StructureLoot/Common4.nbt,3,minecraft:chest[facing=east,type=single,waterlogged=false],./StructureNBT/StructureLoot/Common5.nbt,3,minecraft:chest[facing=east,type=single,waterlogged=false],./StructureNBT/StructureLoot/Common5.nbt,3,minecraft:chest[facing=east,type=single,waterlogged=false],./StructureNBT/StructureLoot/Common6.nbt,3,minecraft:chest[facing=east,type=single,waterlogged=false],./StructureNBT/StructureLoot/Common7.nbt,3,minecraft:chest[facing=east,type=single,waterlogged=false],./StructureNBT/StructureLoot/Common8.nbt,3,minecraft:chest[facing=east,type=single,waterlogged=false],./StructureNBT/StructureLoot/Common9.nbt,3,minecraft:chest[facing=east,type=single,waterlogged=false],./StructureNBT/StructureLoot/Common10.nbt,3,minecraft:chest[facing=east,type=single,waterlogged=false],./StructureNBT/StructureLoot/Common11.nbt,3,minecraft:chest[facing=east,type=single,waterlogged=false],./StructureNBT/StructureLoot/Common12.nbt,3,minecraft:chest[facing=east,type=single,waterlogged=false],./StructureNBT/StructureLoot/Common13.nbt,3,minecraft:chest[facing=east,type=single,waterlogged=false],./StructureNBT/StructureLoot/Common14.nbt,3,minecraft:chest[facing=east,type=single,waterlogged=false],./StructureNBT/StructureLoot/Common15.nbt,3,minecraft:chest[facing=east,type=single,waterlogged=false],./StructureNBT/StructureLoot/Rare1.nbt,3,minecraft:chest[facing=east,type=single,waterlogged=false],./StructureNBT/StructureLoot/Rare2.nbt,3,minecraft:chest[facing=east,type=single,waterlogged=false],./StructureNBT/StructureLoot/Rare3.nbt,3,minecraft:chest[facing=east,type=single,waterlogged=false],./StructureNBT/StructureLoot/Rare4.nbt,3,minecraft:chest[facing=east,type=single,waterlogged=false],./StructureNBT/StructureLoot/Rare5.nbt,3,minecraft:chest[facing=east,type=single,waterlogged=false],./StructureNBT/StructureLoot/Rare6.nbt,3,minecraft:chest[facing=east,type=single,waterlogged=false],./StructureNBT/StructureLoot/Rare7.nbt,3,minecraft:chest[facing=east,type=single,waterlogged=false],./StructureNBT/StructureLoot/Rare8.nbt,3,minecraft:chest[facing=east,type=single,waterlogged=false],./StructureNBT/StructureLoot/Rare9.nbt,3,minecraft:chest[facing=east,type=single,waterlogged=false],./StructureNBT/StructureLoot/Rare10.nbt,3,minecraft:chest[facing=east,type=single,waterlogged=false],./StructureNBT/StructureLoot/Rare11.nbt,3,minecraft:chest[facing=east,type=single,waterlogged=false],./StructureNBT/StructureLoot/Rare12.nbt,3,minecraft:chest[facing=east,type=single,waterlogged=false],./StructureNBT/StructureLoot/Rare13.nbt,3,minecraft:chest[facing=east,type=single,waterlogged=false],./StructureNBT/StructureLoot/Rare14.nbt,3,minecraft:chest[facing=east,type=single,waterlogged=false],./StructureNBT/StructureLoot/Rare15.nbt,3,minecraft:chest[facing=east,type=single,waterlogged=false],./StructureNBT/StructureLoot/Epic1.nbt,3,minecraft:chest[facing=east,type=single,waterlogged=false],./StructureNBT/StructureLoot/Epic2.nbt,3,minecraft:chest[facing=east,type=single,waterlogged=false],./StructureNBT/StructureLoot/Epic3.nbt,3,minecraft:chest[facing=east,type=single,waterlogged=false],./StructureNBT/StructureLoot/Epic4.nbt,3,minecraft:chest[facing=east,type=single,waterlogged=false],./StructureNBT/StructureLoot/Epic5.nbt,3,minecraft:chest[facing=east,type=single,waterlogged=false],./StructureNBT/StructureLoot/Epic6.nbt,3,minecraft:chest[facing=east,type=single,waterlogged=false],./StructureNBT/StructureLoot/Epic7.nbt,3,minecraft:chest[facing=east,type=single,waterlogged=false],./StructureNBT/StructureLoot/Epic8.nbt,3,minecraft:chest[facing=east,type=single,waterlogged=false],./StructureNBT/StructureLoot/Epic9.nbt,3,minecraft:chest[facing=east,type=single,waterlogged=false],./StructureNBT/StructureLoot/Epic10.nbt,3,minecraft:chest[facing=east,type=single,waterlogged=false],./StructureNBT/StructureLoot/Epic11.nbt,3,minecraft:chest[facing=east,type=single,waterlogged=false],./StructureNBT/StructureLoot/Epic12.nbt,3,minecraft:chest[facing=east,type=single,waterlogged=false],./StructureNBT/StructureLoot/Epic13.nbt,3,minecraft:chest[facing=east,type=single,waterlogged=false],./StructureNBT/StructureLoot/Epic14.nbt,3,minecraft:chest[facing=east,type=single,waterlogged=false],./StructureNBT/StructureLoot/Epic15.nbt,1,minecraft:chest[facing=east,type=single,waterlogged=false],./StructureNBT/StructureLoot/Common15.nbt,100)
B(-2,29,-1,minecraft:skeleton_skull,StructureNBT/PirateBo3/pir31/9-Skull.nbt)
B(-1,33,0,minecraft:white_wall_banner[facing=south],StructureNBT/PirateBo3/pir31/10-Banner.nbt)
RB(0,23,3,minecraft:chest[facing=east,type=single,waterlogged=false],./StructureNBT/StructureLoot/JunkChest_1.nbt,20,minecraft:chest[facing=east,type=single,waterlogged=false],./StructureNBT/StructureLoot/JunkChest_2.nbt,15,minecraft:chest[facing=east,type=single,waterlogged=false],./StructureNBT/StructureLoot/JunkChest_3.nbt,15,minecraft:chest[facing=east,type=single,waterlogged=false],./StructureNBT/StructureLoot/JunkChest_4.nbt,15,minecraft:chest[facing=east,type=single,waterlogged=false],./StructureNBT/StructureLoot/JunkChest_5.nbt,15,minecraft:chest[facing=east,type=single,waterlogged=false],./StructureNBT/LoreStoryline/LoreGeneric_5.nbt,2,minecraft:chest[facing=east,type=single,waterlogged=false],./StructureNBT/LoreStoryline/LoreGeneric_4.nbt,2,minecraft:chest[facing=east,type=single,waterlogged=false],./StructureNBT/LoreStoryline/LoreGeneric_3.nbt,2,minecraft:chest[facing=east,type=single,waterlogged=false],./StructureNBT/LoreStoryline/LoreGeneric_2.nbt,2,minecraft:chest[facing=east,type=single,waterlogged=false],./StructureNBT/LoreStoryline/LoreGeneric_1.nbt,2,minecraft:chest[facing=east,type=single,waterlogged=false],./StructureNBT/LoreStoryline/LorePirate_5.nbt,3,minecraft:chest[facing=east,type=single,waterlogged=false],./StructureNBT/LoreStoryline/LorePirate_4.nbt,3,minecraft:chest[facing=east,type=single,waterlogged=false],./StructureNBT/LoreStoryline/LorePirate_3.nbt,3,minecraft:chest[facing=east,type=single,waterlogged=false],./StructureNBT/LoreStoryline/LorePirate_2.nbt,3,minecraft:chest[facing=east,type=single,waterlogged=false],./StructureNBT/LoreStoryline/LorePirate_1.nbt,3,minecraft:chest[facing=east,type=single,waterlogged=false],./StructureNBT/StructureLoot/Common1.nbt,3,minecraft:chest[facing=east,type=single,waterlogged=false],./StructureNBT/StructureLoot/Common2.nbt,3,minecraft:chest[facing=east,type=single,waterlogged=false],./StructureNBT/StructureLoot/Common3.nbt,3,minecraft:chest[facing=east,type=single,waterlogged=false],./StructureNBT/StructureLoot/Common4.nbt,3,minecraft:chest[facing=east,type=single,waterlogged=false],./StructureNBT/StructureLoot/Common5.nbt,3,minecraft:chest[facing=east,type=single,waterlogged=false],./StructureNBT/StructureLoot/Common5.nbt,3,minecraft:chest[facing=east,type=single,waterlogged=false],./StructureNBT/StructureLoot/Common6.nbt,3,minecraft:chest[facing=east,type=single,waterlogged=false],./StructureNBT/StructureLoot/Common7.nbt,3,minecraft:chest[facing=east,type=single,waterlogged=false],./StructureNBT/StructureLoot/Common8.nbt,3,minecraft:chest[facing=east,type=single,waterlogged=false],./StructureNBT/StructureLoot/Common9.nbt,3,minecraft:chest[facing=east,type=single,waterlogged=false],./StructureNBT/StructureLoot/Common10.nbt,3,minecraft:chest[facing=east,type=single,waterlogged=false],./StructureNBT/StructureLoot/Common11.nbt,3,minecraft:chest[facing=east,type=single,waterlogged=false],./StructureNBT/StructureLoot/Common12.nbt,3,minecraft:chest[facing=east,type=single,waterlogged=false],./StructureNBT/StructureLoot/Common13.nbt,3,minecraft:chest[facing=east,type=single,waterlogged=false],./StructureNBT/StructureLoot/Common14.nbt,3,minecraft:chest[facing=east,type=single,waterlogged=false],./StructureNBT/StructureLoot/Common15.nbt,3,minecraft:chest[facing=east,type=single,waterlogged=false],./StructureNBT/StructureLoot/Rare1.nbt,3,minecraft:chest[facing=east,type=single,waterlogged=false],./StructureNBT/StructureLoot/Rare2.nbt,3,minecraft:chest[facing=east,type=single,waterlogged=false],./StructureNBT/StructureLoot/Rare3.nbt,3,minecraft:chest[facing=east,type=single,waterlogged=false],./StructureNBT/StructureLoot/Rare4.nbt,3,minecraft:chest[facing=east,type=single,waterlogged=false],./StructureNBT/StructureLoot/Rare5.nbt,3,minecraft:chest[facing=east,type=single,waterlogged=false],./StructureNBT/StructureLoot/Rare6.nbt,3,minecraft:chest[facing=east,type=single,waterlogged=false],./StructureNBT/StructureLoot/Rare7.nbt,3,minecraft:chest[facing=east,type=single,waterlogged=false],./StructureNBT/StructureLoot/Rare8.nbt,3,minecraft:chest[facing=east,type=single,waterlogged=false],./StructureNBT/StructureLoot/Rare9.nbt,3,minecraft:chest[facing=east,type=single,waterlogged=false],./StructureNBT/StructureLoot/Rare10.nbt,3,minecraft:chest[facing=east,type=single,waterlogged=false],./StructureNBT/StructureLoot/Rare11.nbt,3,minecraft:chest[facing=east,type=single,waterlogged=false],./StructureNBT/StructureLoot/Rare12.nbt,3,minecraft:chest[facing=east,type=single,waterlogged=false],./StructureNBT/StructureLoot/Rare13.nbt,3,minecraft:chest[facing=east,type=single,waterlogged=false],./StructureNBT/StructureLoot/Rare14.nbt,3,minecraft:chest[facing=east,type=single,waterlogged=false],./StructureNBT/StructureLoot/Rare15.nbt,3,minecraft:chest[facing=east,type=single,waterlogged=false],./StructureNBT/StructureLoot/Epic1.nbt,3,minecraft:chest[facing=east,type=single,waterlogged=false],./StructureNBT/StructureLoot/Epic2.nbt,3,minecraft:chest[facing=east,type=single,waterlogged=false],./StructureNBT/StructureLoot/Epic3.nbt,3,minecraft:chest[facing=east,type=single,waterlogged=false],./StructureNBT/StructureLoot/Epic4.nbt,3,minecraft:chest[facing=east,type=single,waterlogged=false],./StructureNBT/StructureLoot/Epic5.nbt,3,minecraft:chest[facing=east,type=single,waterlogged=false],./StructureNBT/StructureLoot/Epic6.nbt,3,minecraft:chest[facing=east,type=single,waterlogged=false],./StructureNBT/StructureLoot/Epic7.nbt,3,minecraft:chest[facing=east,type=single,waterlogged=false],./StructureNBT/StructureLoot/Epic8.nbt,3,minecraft:chest[facing=east,type=single,waterlogged=false],./StructureNBT/StructureLoot/Epic9.nbt,3,minecraft:chest[facing=east,type=single,waterlogged=false],./StructureNBT/StructureLoot/Epic10.nbt,3,minecraft:chest[facing=east,type=single,waterlogged=false],./StructureNBT/StructureLoot/Epic11.nbt,3,minecraft:chest[facing=east,type=single,waterlogged=false],./StructureNBT/StructureLoot/Epic12.nbt,3,minecraft:chest[facing=east,type=single,waterlogged=false],./StructureNBT/StructureLoot/Epic13.nbt,3,minecraft:chest[facing=east,type=single,waterlogged=false],./StructureNBT/StructureLoot/Epic14.nbt,3,minecraft:chest[facing=east,type=single,waterlogged=false],./StructureNBT/StructureLoot/Epic15.nbt,1,minecraft:chest[facing=east,type=single,waterlogged=false],./StructureNBT/StructureLoot/Common15.nbt,100)
B(0,28,-1,minecraft:air,StructureNBT/PirateBo3/pir31/12-FlowerPot.nbt)
B(2,28,-6,minecraft:skeleton_skull,StructureNBT/PirateBo3/pir31/13-Skull.nbt)
B(2,28,-4,minecraft:air,StructureNBT/PirateBo3/pir31/14-FlowerPot.nbt)

#######################################################################
# +-----------------------------------------------------------------+ #
# |                            BO3 checks                           | #
# +-----------------------------------------------------------------+ #
#######################################################################


#######################################################################
# +-----------------------------------------------------------------+ #
# |                             Branches                            | #
# +-----------------------------------------------------------------+ #
#######################################################################

Branch(-16,0,0,Pir31_00-02,NORTH,100.0)
Branch(0,0,-16,Pir31_01-01,NORTH,100.0)
Branch(0,0,16,Pir31_01-03,NORTH,100.0)
Branch(16,0,0,Pir31_02-02,NORTH,100.0)

#######################################################################
# +-----------------------------------------------------------------+ #
# |                             Entities                            | #
# +-----------------------------------------------------------------+ #
#######################################################################

