
#######################################################################
# +-----------------------------------------------------------------+ #
# |                            BO3 object                           | #
# +-----------------------------------------------------------------+ #
#######################################################################

Author: NLBlackEagle

Description: No description given

Version: 3

SettingsMode: WriteWithoutComments


#######################################################################
# +-----------------------------------------------------------------+ #
# |                          Main settings                          | #
# +-----------------------------------------------------------------+ #
#######################################################################

Tree: false

Frequency: 1

Rarity: 5.0

RotateRandomly: true

SpawnHeight: highestBlock

SpawnHeightOffset: 0

SpawnHeightVariance: 0

##############################
# Height Limits for the BO3. #
##############################

MinHeight: 0

MaxHeight: 255

######################
# Extrusion settings #
######################

ExtrudeMode: None

ExtrudeThroughBlocks: otg:air

MaxBranchDepth: 10


#######################################################################
# +-----------------------------------------------------------------+ #
# |                      Source block settings                      | #
# +-----------------------------------------------------------------+ #
#######################################################################

SourceBlocks: otg:air

MaxPercentageOutsideSourceBlock: 2

OutsideSourceBlock: dontPlace

DoReplaceBlocks: true

IsOTGPlus: false


#######################################################################
# +-----------------------------------------------------------------+ #
# |                              Blocks                             | #
# +-----------------------------------------------------------------+ #
#######################################################################

B(-3,0,0,minecraft:grass)
B(-2,0,-3,minecraft:grass)
B(-2,0,-2,minecraft:vine[east=true,north=false,south=false,up=false,west=false])
B(-2,1,-2,minecraft:vine[east=true,north=false,south=false,up=false,west=false])
B(-2,0,-1,minecraft:vine[east=true,north=false,south=false,up=false,west=false])
B(-2,0,0,minecraft:cracked_stone_bricks)
B(-2,1,0,minecraft:mossy_stone_bricks)
B(-2,2,0,minecraft:mossy_stone_bricks)
B(-2,0,1,minecraft:vine[east=true,north=false,south=false,up=false,west=false])
B(-2,1,1,minecraft:vine[east=true,north=false,south=false,up=false,west=false])
B(-2,0,2,minecraft:oak_leaves[distance=7,persistent=true])
B(-1,0,-4,minecraft:grass)
B(-1,0,-3,minecraft:oak_leaves[distance=7,persistent=true])
B(-1,1,-3,minecraft:oak_leaves[distance=7,persistent=true])
B(-1,0,-2,minecraft:cracked_stone_bricks)
B(-1,1,-2,minecraft:mossy_stone_bricks)
B(-1,2,-2,minecraft:mossy_stone_bricks)
B(-1,3,-2,minecraft:cracked_stone_bricks)
B(-1,4,-2,minecraft:cracked_stone_bricks)
B(-1,5,-2,minecraft:cobblestone_wall[east=low,north=none,south=low,up=true,waterlogged=false,west=none])
B(-1,0,-1,minecraft:mossy_stone_bricks)
B(-1,1,-1,minecraft:mossy_stone_bricks)
B(-1,2,-1,minecraft:mossy_stone_bricks)
B(-1,3,-1,minecraft:vine[east=false,north=true,south=false,up=false,west=false])
B(-1,4,-1,minecraft:vine[east=false,north=true,south=false,up=false,west=false])
B(-1,5,-1,minecraft:mossy_stone_bricks)
B(-1,6,-1,minecraft:cobblestone_slab)
B(-1,0,0,minecraft:mossy_stone_bricks)
B(-1,1,0,minecraft:mossy_stone_bricks)
B(-1,2,0,minecraft:mossy_stone_bricks)
B(-1,3,0,minecraft:cracked_stone_bricks)
B(-1,4,0,minecraft:mossy_stone_bricks)
B(-1,5,0,minecraft:mossy_stone_bricks)
B(-1,6,0,minecraft:cobblestone_slab)
B(-1,0,1,minecraft:mossy_stone_bricks)
B(-1,1,1,minecraft:cracked_stone_bricks)
B(-1,2,1,minecraft:cracked_stone_bricks)
B(-1,3,1,minecraft:oak_leaves[distance=7,persistent=true])
B(-1,4,1,minecraft:oak_leaves[distance=7,persistent=true])
B(-1,5,1,minecraft:mossy_stone_bricks)
B(-1,6,1,minecraft:vine[east=true,north=false,south=false,up=false,west=false])
B(-1,0,2,minecraft:mossy_stone_bricks)
B(-1,1,2,minecraft:mossy_stone_bricks)
B(-1,2,2,minecraft:cracked_stone_bricks)
B(-1,3,2,minecraft:mossy_stone_bricks)
B(-1,4,2,minecraft:mossy_stone_bricks)
B(-1,5,2,minecraft:cobblestone_wall[east=low,north=low,south=none,up=true,waterlogged=false,west=none])
B(-1,0,3,minecraft:oak_leaves[distance=7,persistent=true])
B(-1,1,3,minecraft:vine[east=true,north=false,south=false,up=false,west=false])
B(-1,2,3,minecraft:vine[east=true,north=false,south=false,up=false,west=false])
B(-1,0,4,minecraft:fern)
B(0,0,-4,minecraft:vine[east=false,north=false,south=true,up=false,west=false])
B(0,0,-3,minecraft:mossy_stone_bricks)
B(0,1,-3,minecraft:mossy_stone_bricks)
B(0,2,-3,minecraft:mossy_stone_bricks)
B(0,3,-3,minecraft:mossy_stone_bricks)
B(0,4,-3,minecraft:mossy_stone_bricks)
B(0,5,-3,minecraft:vine[east=false,north=false,south=true,up=false,west=false])
B(0,0,-2,minecraft:mossy_stone_bricks)
B(0,5,-2,minecraft:mossy_stone_bricks)
B(0,6,-2,minecraft:vine[east=false,north=false,south=true,up=false,west=false])
B(0,0,-1,minecraft:mossy_stone_bricks)
B(0,3,-1,minecraft:chiseled_stone_bricks)
B(0,4,-1,minecraft:chiseled_stone_bricks)
B(0,5,-1,minecraft:chiseled_stone_bricks)
B(0,6,-1,minecraft:cracked_stone_bricks)
B(0,0,0,minecraft:mossy_stone_bricks)
B(0,1,0,minecraft:vine[east=false,north=false,south=false,up=false,west=true])
B(0,2,0,minecraft:vine[east=false,north=false,south=false,up=false,west=true])
B(0,3,0,minecraft:vine[east=false,north=true,south=false,up=false,west=true])
B(0,4,0,minecraft:vine[east=false,north=false,south=false,up=false,west=true])
B(0,5,0,minecraft:vine[east=false,north=false,south=false,up=false,west=true])
B(0,6,0,minecraft:mossy_stone_bricks)
B(0,0,1,minecraft:mossy_stone_bricks)
B(0,1,1,minecraft:vine[east=false,north=false,south=false,up=false,west=true])
B(0,2,1,minecraft:vine[east=false,north=false,south=false,up=false,west=true])
B(0,3,1,minecraft:chiseled_stone_bricks)
B(0,4,1,minecraft:chiseled_stone_bricks)
B(0,5,1,minecraft:chiseled_stone_bricks)
B(0,6,1,minecraft:cracked_stone_bricks)
B(0,0,2,minecraft:mossy_stone_bricks)
B(0,1,2,minecraft:vine[east=false,north=false,south=false,up=false,west=true])
B(0,5,2,minecraft:mossy_stone_bricks)
B(0,6,2,minecraft:cobblestone_slab)
B(0,0,3,minecraft:mossy_stone_bricks)
B(0,1,3,minecraft:cracked_stone_bricks)
B(0,2,3,minecraft:cracked_stone_bricks)
B(0,3,3,minecraft:mossy_stone_bricks)
B(0,4,3,minecraft:mossy_stone_bricks)
B(0,5,3,minecraft:vine[east=false,north=true,south=false,up=false,west=false])
B(0,0,4,minecraft:vine[east=false,north=true,south=false,up=false,west=false])
B(0,1,4,minecraft:vine[east=false,north=true,south=false,up=false,west=false])
B(1,0,-4,minecraft:vine[east=false,north=false,south=true,up=false,west=false])
B(1,1,-4,minecraft:vine[east=false,north=false,south=true,up=false,west=false])
B(1,0,-3,minecraft:mossy_stone_bricks)
B(1,1,-3,minecraft:mossy_stone_bricks)
B(1,2,-3,minecraft:mossy_stone_bricks)
B(1,3,-3,minecraft:mossy_stone_bricks)
B(1,4,-3,minecraft:mossy_stone_bricks)
B(1,5,-3,minecraft:cobblestone_wall[east=none,north=none,south=low,up=true,waterlogged=false,west=none])
B(1,0,-2,minecraft:mossy_stone_bricks)
B(1,5,-2,minecraft:cracked_stone_bricks)
B(1,6,-2,minecraft:cobblestone_slab)
B(1,0,-1,minecraft:mossy_stone_bricks)
B(1,6,-1,minecraft:grass_block)
B(1,7,-1,minecraft:grass)
B(1,0,0,minecraft:mossy_stone_bricks)
B(1,6,0,minecraft:mossy_stone_bricks)
B(1,0,1,minecraft:mossy_stone_bricks)
B(1,6,1,minecraft:cracked_stone_bricks)
B(1,0,2,minecraft:mossy_stone_bricks)
B(1,1,2,minecraft:mossy_stone_bricks)
B(1,5,2,minecraft:mossy_stone_bricks)
B(1,6,2,minecraft:oak_leaves[distance=7,persistent=true])
B(1,0,3,minecraft:mossy_stone_bricks)
B(1,1,3,minecraft:cracked_stone_bricks)
B(1,2,3,minecraft:cracked_stone_bricks)
B(1,3,3,minecraft:cracked_stone_bricks)
B(1,4,3,minecraft:mossy_stone_bricks)
B(1,5,3,minecraft:vine[east=false,north=true,south=false,up=false,west=false])
B(1,0,4,minecraft:vine[east=false,north=true,south=false,up=false,west=false])
B(2,0,-4,minecraft:vine[east=false,north=false,south=true,up=false,west=false])
B(2,1,-4,minecraft:vine[east=false,north=false,south=true,up=false,west=false])
B(2,2,-4,minecraft:vine[east=false,north=false,south=true,up=false,west=false])
B(2,3,-4,minecraft:vine[east=false,north=false,south=true,up=false,west=false])
B(2,4,-4,minecraft:vine[east=false,north=false,south=true,up=false,west=false])
B(2,0,-3,minecraft:mossy_stone_bricks)
B(2,1,-3,minecraft:mossy_stone_bricks)
B(2,2,-3,minecraft:mossy_stone_bricks)
B(2,3,-3,minecraft:mossy_stone_bricks)
B(2,4,-3,minecraft:cracked_stone_bricks)
B(2,0,-2,minecraft:mossy_stone_bricks)
B(2,1,-2,minecraft:mossy_stone_bricks)
B(2,2,-2,minecraft:vine[east=false,north=true,south=false,up=false,west=false])
B(2,3,-2,minecraft:vine[east=false,north=true,south=false,up=false,west=false])
B(2,4,-2,minecraft:vine[east=false,north=true,south=false,up=false,west=false])
B(2,5,-2,minecraft:cracked_stone_bricks)
B(2,6,-2,minecraft:cobblestone_slab)
B(2,0,-1,minecraft:mossy_stone_bricks)
B(2,1,-1,minecraft:mossy_stone_bricks)
B(2,2,-1,minecraft:vine[east=true,north=false,south=false,up=false,west=false])
B(2,3,-1,minecraft:vine[east=true,north=false,south=false,up=false,west=false])
B(2,4,-1,minecraft:vine[east=true,north=false,south=false,up=false,west=false])
B(2,5,-1,minecraft:vine[east=true,north=false,south=false,up=false,west=false])
B(2,6,-1,minecraft:grass_block)
B(2,7,-1,minecraft:grass)
B(2,0,0,minecraft:mossy_stone_bricks)
B(2,1,0,minecraft:mossy_stone_bricks)
B(2,5,0,minecraft:cobblestone_slab[type=top,waterlogged=false])
B(2,6,0,minecraft:grass_block)
B(2,7,0,minecraft:grass)
B(2,0,1,minecraft:mossy_stone_bricks)
B(2,1,1,minecraft:vine[east=true,north=false,south=false,up=false,west=false])
B(2,2,1,minecraft:vine[east=true,north=false,south=false,up=false,west=false])
B(2,3,1,minecraft:chiseled_stone_bricks)
B(2,4,1,minecraft:chiseled_stone_bricks)
B(2,5,1,minecraft:chiseled_stone_bricks)
B(2,6,1,minecraft:mossy_stone_bricks)
B(2,0,2,minecraft:mossy_stone_bricks)
B(2,1,2,minecraft:vine[east=false,north=false,south=true,up=false,west=false])
B(2,5,2,minecraft:mossy_stone_bricks)
B(2,6,2,minecraft:oak_leaves[distance=7,persistent=true])
B(2,0,3,minecraft:mossy_stone_bricks)
B(2,1,3,minecraft:mossy_stone_bricks)
B(2,2,3,minecraft:mossy_stone_bricks)
B(2,3,3,minecraft:cracked_stone_bricks)
B(2,4,3,minecraft:mossy_stone_bricks)
B(2,0,4,minecraft:oak_leaves[distance=7,persistent=true])
B(2,1,4,minecraft:vine[east=false,north=true,south=false,up=false,west=false])
B(3,0,-3,minecraft:grass)
B(3,1,-3,minecraft:vine[east=false,north=false,south=false,up=false,west=true])
B(3,2,-3,minecraft:vine[east=false,north=false,south=false,up=false,west=true])
B(3,3,-3,minecraft:vine[east=false,north=false,south=false,up=false,west=true])
B(3,0,-2,minecraft:mossy_stone_bricks)
B(3,1,-2,minecraft:mossy_stone_bricks)
B(3,2,-2,minecraft:cracked_stone_bricks)
B(3,3,-2,minecraft:mossy_stone_bricks)
B(3,4,-2,minecraft:mossy_stone_bricks)
B(3,5,-2,minecraft:cobblestone_wall[east=none,north=none,south=low,up=true,waterlogged=false,west=low])
B(3,0,-1,minecraft:mossy_stone_bricks)
B(3,1,-1,minecraft:mossy_stone_bricks)
B(3,2,-1,minecraft:mossy_stone_bricks)
B(3,5,-1,minecraft:mossy_stone_bricks)
B(3,6,-1,minecraft:cobblestone_slab)
B(3,0,0,minecraft:mossy_stone_bricks)
B(3,1,0,minecraft:mossy_stone_bricks)
B(3,2,0,minecraft:mossy_stone_bricks)
B(3,3,0,minecraft:mossy_stone_bricks)
B(3,4,0,minecraft:cracked_stone_bricks)
B(3,5,0,minecraft:cracked_stone_bricks)
B(3,6,0,minecraft:cobblestone_slab)
B(3,0,1,minecraft:mossy_stone_bricks)
B(3,1,1,minecraft:mossy_stone_bricks)
B(3,2,1,minecraft:mossy_stone_bricks)
B(3,3,1,minecraft:vine[east=false,north=false,south=false,up=false,west=true])
B(3,5,1,minecraft:mossy_stone_bricks)
B(3,6,1,minecraft:vine[east=false,north=false,south=false,up=false,west=true])
B(3,0,2,minecraft:cracked_stone_bricks)
B(3,1,2,minecraft:mossy_stone_bricks)
B(3,2,2,minecraft:cracked_stone_bricks)
B(3,3,2,minecraft:mossy_stone_bricks)
B(3,4,2,minecraft:mossy_stone_bricks)
B(3,5,2,minecraft:cobblestone_wall[east=none,north=low,south=none,up=true,waterlogged=false,west=low])
B(3,0,3,minecraft:oak_leaves[distance=7,persistent=true])
B(3,1,3,minecraft:oak_leaves[distance=7,persistent=true])
B(3,0,4,minecraft:oak_leaves[distance=7,persistent=true])
B(3,1,4,minecraft:oak_leaves[distance=7,persistent=true])
B(4,0,-2,minecraft:fern)
B(4,0,-1,minecraft:vine[east=false,north=false,south=false,up=false,west=true])
B(4,1,-1,minecraft:vine[east=false,north=false,south=false,up=false,west=true])
B(4,2,-1,minecraft:vine[east=false,north=false,south=false,up=false,west=true])
B(4,3,-1,minecraft:vine[east=false,north=false,south=false,up=false,west=true])
B(4,4,-1,minecraft:vine[east=false,north=false,south=false,up=false,west=true])
B(4,5,-1,minecraft:vine[east=false,north=false,south=false,up=false,west=true])
B(4,0,0,minecraft:mossy_stone_bricks)
B(4,1,0,minecraft:cracked_stone_bricks)
B(4,2,0,minecraft:mossy_stone_bricks)
B(4,0,1,minecraft:vine[east=false,north=false,south=false,up=false,west=true])
B(4,1,1,minecraft:vine[east=false,north=false,south=false,up=false,west=true])
B(4,0,2,minecraft:vine[east=false,north=false,south=false,up=false,west=true])
B(4,0,3,minecraft:fern)
RB(1,2,2,minecraft:chest,./StructureNBT/StructureLoot/JunkChest_1.nbt,20,minecraft:chest,./StructureNBT/StructureLoot/JunkChest_2.nbt,15,minecraft:chest,./StructureNBT/StructureLoot/JunkChest_3.nbt,15,minecraft:chest,./StructureNBT/StructureLoot/JunkChest_4.nbt,15,minecraft:chest,./StructureNBT/StructureLoot/JunkChest_5.nbt,15,minecraft:chest,./StructureNBT/LoreStoryline/LoreGeneric_5.nbt,2,minecraft:chest,./StructureNBT/LoreStoryline/LoreGeneric_4.nbt,2,minecraft:chest,./StructureNBT/LoreStoryline/LoreGeneric_3.nbt,2,minecraft:chest,./StructureNBT/LoreStoryline/LoreGeneric_2.nbt,2,minecraft:chest,./StructureNBT/LoreStoryline/LoreGeneric_1.nbt,2,minecraft:chest,./StructureNBT/LoreStoryline/LoreSmallRuin_5.nbt,3,minecraft:chest,./StructureNBT/LoreStoryline/LoreSmallRuin_4.nbt,3,minecraft:chest,./StructureNBT/LoreStoryline/LoreSmallRuin_3.nbt,3,minecraft:chest,./StructureNBT/LoreStoryline/LoreSmallRuin_2.nbt,3,minecraft:chest,./StructureNBT/LoreStoryline/LoreSmallRuin_1.nbt,3,minecraft:chest,./StructureNBT/StructureLoot/Common1.nbt,3,minecraft:chest,./StructureNBT/StructureLoot/Common2.nbt,3,minecraft:chest,./StructureNBT/StructureLoot/Common3.nbt,3,minecraft:chest,./StructureNBT/StructureLoot/Common4.nbt,3,minecraft:chest,./StructureNBT/StructureLoot/Common5.nbt,3,minecraft:chest,./StructureNBT/StructureLoot/Common5.nbt,3,minecraft:chest,./StructureNBT/StructureLoot/Common6.nbt,3,minecraft:chest,./StructureNBT/StructureLoot/Common7.nbt,3,minecraft:chest,./StructureNBT/StructureLoot/Common8.nbt,3,minecraft:chest,./StructureNBT/StructureLoot/Common9.nbt,3,minecraft:chest,./StructureNBT/StructureLoot/Common10.nbt,3,minecraft:chest,./StructureNBT/StructureLoot/Common11.nbt,3,minecraft:chest,./StructureNBT/StructureLoot/Common12.nbt,3,minecraft:chest,./StructureNBT/StructureLoot/Common13.nbt,3,minecraft:chest,./StructureNBT/StructureLoot/Common14.nbt,3,minecraft:chest,./StructureNBT/StructureLoot/Common15.nbt,3,minecraft:chest,./StructureNBT/StructureLoot/Rare1.nbt,3,minecraft:chest,./StructureNBT/StructureLoot/Rare2.nbt,3,minecraft:chest,./StructureNBT/StructureLoot/Rare3.nbt,3,minecraft:chest,./StructureNBT/StructureLoot/Rare4.nbt,3,minecraft:chest,./StructureNBT/StructureLoot/Rare5.nbt,3,minecraft:chest,./StructureNBT/StructureLoot/Rare6.nbt,3,minecraft:chest,./StructureNBT/StructureLoot/Rare7.nbt,3,minecraft:chest,./StructureNBT/StructureLoot/Rare8.nbt,3,minecraft:chest,./StructureNBT/StructureLoot/Rare9.nbt,3,minecraft:chest,./StructureNBT/StructureLoot/Rare10.nbt,3,minecraft:chest,./StructureNBT/StructureLoot/Rare11.nbt,3,minecraft:chest,./StructureNBT/StructureLoot/Rare12.nbt,3,minecraft:chest,./StructureNBT/StructureLoot/Rare13.nbt,3,minecraft:chest,./StructureNBT/StructureLoot/Rare14.nbt,3,minecraft:chest,./StructureNBT/StructureLoot/Rare15.nbt,3,minecraft:chest,./StructureNBT/StructureLoot/Epic1.nbt,3,minecraft:chest,./StructureNBT/StructureLoot/Epic2.nbt,3,minecraft:chest,./StructureNBT/StructureLoot/Epic3.nbt,3,minecraft:chest,./StructureNBT/StructureLoot/Epic4.nbt,3,minecraft:chest,./StructureNBT/StructureLoot/Epic5.nbt,3,minecraft:chest,./StructureNBT/StructureLoot/Epic6.nbt,3,minecraft:chest,./StructureNBT/StructureLoot/Epic7.nbt,3,minecraft:chest,./StructureNBT/StructureLoot/Epic8.nbt,3,minecraft:chest,./StructureNBT/StructureLoot/Epic9.nbt,3,minecraft:chest,./StructureNBT/StructureLoot/Epic10.nbt,3,minecraft:chest,./StructureNBT/StructureLoot/Epic11.nbt,3,minecraft:chest,./StructureNBT/StructureLoot/Epic12.nbt,3,minecraft:chest,./StructureNBT/StructureLoot/Epic13.nbt,3,minecraft:chest,./StructureNBT/StructureLoot/Epic14.nbt,3,minecraft:chest,./StructureNBT/StructureLoot/Epic15.nbt,1,minecraft:chest,./StructureNBT/StructureLoot/Common15.nbt,100)

#######################################################################
# +-----------------------------------------------------------------+ #
# |                            BO3 checks                           | #
# +-----------------------------------------------------------------+ #
#######################################################################

BlockCheck(-3,-1,-4,otg:dirt,minecraft:grass_block,minecraft:podzol)
BlockCheck(-3,-1,4,otg:dirt,minecraft:grass_block,minecraft:podzol)
BlockCheck(4,-1,4,otg:dirt,minecraft:grass_block,minecraft:podzol)
BlockCheck(4,-1,-4,otg:dirt,minecraft:grass_block,minecraft:podzol)

#######################################################################
# +-----------------------------------------------------------------+ #
# |                             Branches                            | #
# +-----------------------------------------------------------------+ #
#######################################################################


#######################################################################
# +-----------------------------------------------------------------+ #
# |                             Entities                            | #
# +-----------------------------------------------------------------+ #
#######################################################################

