
#######################################################################
# +-----------------------------------------------------------------+ #
# |                            BO3 object                           | #
# +-----------------------------------------------------------------+ #
#######################################################################

Author: NLBlackEagle

Description: No description given

Version: 3

SettingsMode: WriteWithoutComments


#######################################################################
# +-----------------------------------------------------------------+ #
# |                          Main settings                          | #
# +-----------------------------------------------------------------+ #
#######################################################################

Tree: false

Frequency: 1

Rarity: 5.0

RotateRandomly: true

SpawnHeight: highestBlock

SpawnHeightOffset: 0

SpawnHeightVariance: 0

##############################
# Height Limits for the BO3. #
##############################

MinHeight: 0

MaxHeight: 255

######################
# Extrusion settings #
######################

ExtrudeMode: None

ExtrudeThroughBlocks: otg:air

MaxBranchDepth: 10


#######################################################################
# +-----------------------------------------------------------------+ #
# |                      Source block settings                      | #
# +-----------------------------------------------------------------+ #
#######################################################################

SourceBlocks: otg:air

MaxPercentageOutsideSourceBlock: 2

OutsideSourceBlock: dontPlace

DoReplaceBlocks: true

IsOTGPlus: false


#######################################################################
# +-----------------------------------------------------------------+ #
# |                              Blocks                             | #
# +-----------------------------------------------------------------+ #
#######################################################################

B(-3,0,-3,minecraft:vine[east=true,north=false,south=false,up=false,west=false])
B(-3,1,-3,minecraft:vine[east=true,north=false,south=false,up=false,west=false])
B(-3,0,-2,minecraft:vine[east=true,north=false,south=false,up=false,west=false])
B(-3,0,-1,minecraft:cracked_stone_bricks)
B(-3,0,2,minecraft:vine[east=true,north=false,south=false,up=false,west=false])
B(-2,0,-4,minecraft:vine[east=false,north=false,south=true,up=false,west=false])
B(-2,0,-3,minecraft:cracked_stone_bricks)
B(-2,1,-3,minecraft:cracked_stone_bricks)
B(-2,2,-3,minecraft:flower_pot)
B(-2,0,-2,minecraft:cracked_stone_bricks)
B(-2,1,-2,minecraft:vine[east=false,north=true,south=false,up=false,west=false])
B(-2,0,-1,minecraft:grass)
B(-2,0,0,minecraft:oak_leaves[distance=7,persistent=true])
B(-2,0,1,minecraft:cobblestone_slab)
B(-2,0,2,minecraft:cracked_stone_bricks)
B(-2,0,3,minecraft:grass)
B(-1,0,-3,minecraft:spruce_slab)
B(-1,1,-3,minecraft:vine[east=false,north=false,south=false,up=false,west=true])
B(-1,0,-2,minecraft:cobblestone_slab)
B(-1,0,-1,minecraft:skeleton_skull[rotation=1])
B(-1,1,-1,minecraft:vine[east=true,north=false,south=false,up=false,west=false])
B(-1,2,-1,minecraft:vine[east=true,north=false,south=false,up=false,west=false])
B(-1,3,-1,minecraft:vine[east=true,north=false,south=false,up=false,west=false])
B(-1,0,0,minecraft:mossy_stone_bricks)
B(-1,1,0,minecraft:oak_leaves[distance=7,persistent=true])
B(-1,0,1,minecraft:oak_leaves[distance=7,persistent=true])
B(-1,1,1,minecraft:vine[east=true,north=false,south=false,up=false,west=false])
B(-1,2,1,minecraft:vine[east=true,north=false,south=false,up=false,west=false])
B(-1,0,2,minecraft:oak_leaves[distance=7,persistent=true])
B(-1,1,2,minecraft:oak_leaves[distance=7,persistent=true])
B(-1,0,3,minecraft:cracked_stone_bricks)
B(-1,1,3,minecraft:spruce_slab)
B(-1,0,4,minecraft:vine[east=false,north=true,south=false,up=false,west=false])
B(0,0,-3,minecraft:fern)
B(0,0,-2,minecraft:oak_leaves[distance=7,persistent=true])
B(0,1,-2,minecraft:oak_leaves[distance=7,persistent=true])
B(0,2,-2,minecraft:vine[east=false,north=false,south=true,up=false,west=false])
B(0,0,-1,minecraft:mossy_stone_bricks)
B(0,1,-1,minecraft:mossy_stone_bricks)
B(0,2,-1,minecraft:chiseled_stone_bricks)
B(0,3,-1,minecraft:mossy_stone_bricks)
B(0,4,-1,minecraft:cobblestone_wall[east=none,north=none,south=low,up=true,waterlogged=false,west=none])
B(0,0,0,minecraft:cobblestone_slab)
B(0,1,0,minecraft:vine[east=false,north=false,south=true,up=false,west=false])
B(0,2,0,minecraft:cobblestone_wall[east=none,north=low,south=low,up=true,waterlogged=false,west=none])
B(0,3,0,minecraft:cobblestone_wall[east=none,north=tall,south=tall,up=false,waterlogged=false,west=none])
B(0,4,0,minecraft:chiseled_stone_bricks)
B(0,0,1,minecraft:mossy_stone_bricks)
B(0,1,1,minecraft:cracked_stone_bricks)
B(0,2,1,minecraft:chiseled_stone_bricks)
B(0,3,1,minecraft:mossy_stone_bricks)
B(0,4,1,minecraft:cobblestone_wall[east=none,north=low,south=none,up=true,waterlogged=false,west=none])
B(0,0,2,minecraft:cobblestone_slab)
B(0,1,2,minecraft:vine[east=false,north=true,south=false,up=false,west=false])
B(1,0,-3,minecraft:oak_leaves[distance=7,persistent=true])
B(1,0,-2,minecraft:cobblestone_slab)
B(1,0,-1,minecraft:cobblestone_slab)
B(1,1,-1,minecraft:vine[east=false,north=false,south=false,up=false,west=true])
B(1,2,-1,minecraft:vine[east=false,north=false,south=false,up=false,west=true])
B(1,0,0,minecraft:mossy_stone_bricks)
B(1,0,1,minecraft:cobblestone_slab)
B(1,1,1,minecraft:vine[east=false,north=false,south=false,up=false,west=true])
B(1,2,1,minecraft:vine[east=false,north=false,south=false,up=false,west=true])
B(1,0,2,minecraft:oak_leaves[distance=7,persistent=true])
B(1,0,3,minecraft:grass)
B(2,0,-4,minecraft:vine[east=false,north=false,south=true,up=false,west=false])
B(2,0,-3,minecraft:mossy_stone_bricks)
B(2,0,-2,minecraft:cracked_stone_bricks)
B(2,1,-2,minecraft:spruce_slab)
B(2,0,-1,minecraft:mossy_stone_bricks)
B(2,1,-1,minecraft:spruce_slab)
B(2,0,0,minecraft:cobblestone_slab)
B(2,0,1,minecraft:grass)
B(2,0,2,minecraft:cracked_stone_bricks)
B(2,0,3,minecraft:vine[east=false,north=true,south=false,up=false,west=false])
B(3,0,-3,minecraft:vine[east=false,north=false,south=false,up=false,west=true])
B(3,0,-2,minecraft:vine[east=false,north=false,south=false,up=false,west=true])
B(3,0,-1,minecraft:vine[east=false,north=false,south=false,up=false,west=true])
B(3,0,2,minecraft:vine[east=false,north=false,south=false,up=false,west=true])

#######################################################################
# +-----------------------------------------------------------------+ #
# |                            BO3 checks                           | #
# +-----------------------------------------------------------------+ #
#######################################################################

BlockCheck(-3,-1,-3,otg:dirt,minecraft:grass_block,minecraft:podzol)
BlockCheck(-3,-1,3,otg:dirt,minecraft:grass_block,minecraft:podzol)
BlockCheck(3,-1,3,otg:dirt,minecraft:grass_block,minecraft:podzol)
BlockCheck(3,-1,-3,otg:dirt,minecraft:grass_block,minecraft:podzol)

#######################################################################
# +-----------------------------------------------------------------+ #
# |                             Branches                            | #
# +-----------------------------------------------------------------+ #
#######################################################################


#######################################################################
# +-----------------------------------------------------------------+ #
# |                             Entities                            | #
# +-----------------------------------------------------------------+ #
#######################################################################

