
#######################################################################
# +-----------------------------------------------------------------+ #
# |                            BO3 object                           | #
# +-----------------------------------------------------------------+ #
#######################################################################

Author: NLBlackEagle

Description: No description given

Version: 3

SettingsMode: WriteWithoutComments


#######################################################################
# +-----------------------------------------------------------------+ #
# |                          Main settings                          | #
# +-----------------------------------------------------------------+ #
#######################################################################

Tree: false

Frequency: 1

Rarity: 100.0

RotateRandomly: false

SpawnHeight: highestBlock

SpawnHeightOffset: 0

SpawnHeightVariance: 0

##############################
# Height Limits for the BO3. #
##############################

MinHeight: 80

MaxHeight: 200

######################
# Extrusion settings #
######################

ExtrudeMode: None

ExtrudeThroughBlocks: otg:air

MaxBranchDepth: 10


#######################################################################
# +-----------------------------------------------------------------+ #
# |                      Source block settings                      | #
# +-----------------------------------------------------------------+ #
#######################################################################

SourceBlocks: otg:stone,otg:dirt,minecraft:farmland,minecraft:grass_block

MaxPercentageOutsideSourceBlock: 100

OutsideSourceBlock: placeAnyway

DoReplaceBlocks: true

IsOTGPlus: false


#######################################################################
# +-----------------------------------------------------------------+ #
# |                              Blocks                             | #
# +-----------------------------------------------------------------+ #
#######################################################################

B(-11,-6,-13,minecraft:grass_block)
B(-11,-6,-12,minecraft:grass_block)
B(-11,-6,-11,minecraft:dirt)
B(-11,-5,-11,minecraft:grass_block)
B(-11,-6,-10,minecraft:dirt)
B(-11,-5,-10,minecraft:grass_block)
B(-11,-6,-9,minecraft:dirt)
B(-11,-5,-9,minecraft:dirt)
B(-11,-4,-9,minecraft:grass_block)
B(-11,-6,-8,minecraft:dirt)
B(-11,-5,-8,minecraft:dirt)
B(-11,-4,-8,minecraft:grass_block)
B(-11,-6,-7,minecraft:dirt)
B(-11,-5,-7,minecraft:dirt)
B(-11,-4,-7,minecraft:grass_block)
B(-11,-6,-6,minecraft:dirt)
B(-11,-5,-6,minecraft:dirt)
B(-11,-4,-6,minecraft:grass_block)
B(-11,-6,-5,minecraft:dirt)
B(-11,-5,-5,minecraft:dirt)
B(-11,-4,-5,minecraft:grass_block)
B(-11,-6,-4,minecraft:dirt)
B(-11,-5,-4,minecraft:dirt)
B(-11,-4,-4,minecraft:grass_block)
B(-11,-6,-3,minecraft:dirt)
B(-11,-5,-3,minecraft:dirt)
B(-11,-4,-3,minecraft:grass_block)
B(-11,-3,-3,minecraft:grass_block)
B(-11,-6,-2,minecraft:grass_block)
B(-11,-5,-2,minecraft:dirt)
B(-11,-4,-2,minecraft:grass_block)
B(-11,-3,-2,minecraft:grass_block)
B(-11,-6,-1,minecraft:dirt)
B(-11,-5,-1,minecraft:dirt)
B(-11,-4,-1,minecraft:dirt)
B(-11,-3,-1,minecraft:grass_block)
B(-11,-6,0,minecraft:dirt)
B(-11,-5,0,minecraft:dirt)
B(-11,-4,0,minecraft:grass_block)
B(-11,-3,0,minecraft:grass_block)
B(-11,-6,1,minecraft:dirt)
B(-11,-5,1,minecraft:grass_block)
B(-11,-4,1,minecraft:dirt)
B(-11,-3,1,minecraft:grass_block)
B(-11,-6,2,minecraft:dirt)
B(-11,-5,2,minecraft:dirt)
B(-11,-4,2,minecraft:dirt)
B(-11,-3,2,minecraft:grass_block)
B(-11,-6,3,minecraft:dirt)
B(-11,-5,3,minecraft:dirt)
B(-11,-4,3,minecraft:dirt)
B(-11,-3,3,minecraft:grass_block)
B(-11,-6,4,minecraft:dirt)
B(-11,-5,4,minecraft:dirt)
B(-11,-4,4,minecraft:grass_block)
B(-11,-6,5,minecraft:dirt)
B(-11,-5,5,minecraft:dirt)
B(-11,-4,5,minecraft:grass_block)
B(-11,-6,6,minecraft:dirt)
B(-11,-5,6,minecraft:dirt)
B(-11,-4,6,minecraft:grass_block)
B(-11,-6,7,minecraft:dirt)
B(-11,-5,7,minecraft:grass_block)
B(-11,-6,8,minecraft:dirt)
B(-11,-5,8,minecraft:grass_block)
B(-11,-6,9,minecraft:grass_block)
B(-11,-5,9,minecraft:grass_block)
B(-11,-6,10,minecraft:dirt)
B(-11,-5,10,minecraft:grass_block)
B(-11,-6,11,minecraft:grass_block)
B(-11,-6,12,minecraft:grass_block)
B(-10,-6,-14,minecraft:grass_block)
B(-10,-6,-13,minecraft:dirt)
B(-10,-5,-13,minecraft:grass_block)
B(-10,-6,-12,minecraft:dirt)
B(-10,-5,-12,minecraft:grass_block)
B(-10,-6,-11,minecraft:dirt)
B(-10,-5,-11,minecraft:grass_block)
B(-10,-6,-10,minecraft:dirt)
B(-10,-5,-10,minecraft:grass_block)
B(-10,-4,-10,minecraft:grass_block)
B(-10,-6,-9,minecraft:dirt)
B(-10,-5,-9,minecraft:grass_block)
B(-10,-4,-9,minecraft:grass_block)
B(-10,-6,-8,minecraft:dirt)
B(-10,-5,-8,minecraft:dirt)
B(-10,-4,-8,minecraft:grass_block)
B(-10,-6,-7,minecraft:dirt)
B(-10,-5,-7,minecraft:dirt)
B(-10,-4,-7,minecraft:grass_block)
B(-10,-6,-6,minecraft:dirt)
B(-10,-5,-6,minecraft:dirt)
B(-10,-4,-6,minecraft:dirt)
B(-10,-3,-6,minecraft:grass_block)
B(-10,-6,-5,minecraft:dirt)
B(-10,-5,-5,minecraft:dirt)
B(-10,-4,-5,minecraft:dirt)
B(-10,-3,-5,minecraft:grass_block)
B(-10,-6,-4,minecraft:dirt)
B(-10,-5,-4,minecraft:dirt)
B(-10,-4,-4,minecraft:dirt)
B(-10,-3,-4,minecraft:grass_block)
B(-10,-6,-3,minecraft:dirt)
B(-10,-5,-3,minecraft:grass_block)
B(-10,-4,-3,minecraft:dirt)
B(-10,-3,-3,minecraft:grass_block)
B(-10,-6,-2,minecraft:dirt)
B(-10,-5,-2,minecraft:dirt)
B(-10,-4,-2,minecraft:dirt)
B(-10,-3,-2,minecraft:dirt)
B(-10,-2,-2,minecraft:grass_block)
B(-10,-6,-1,minecraft:grass_block)
B(-10,-5,-1,minecraft:grass_block)
B(-10,-4,-1,minecraft:dirt)
B(-10,-3,-1,minecraft:dirt)
B(-10,-2,-1,minecraft:grass_block)
B(-10,-6,0,minecraft:dirt)
B(-10,-5,0,minecraft:dirt)
B(-10,-4,0,minecraft:dirt)
B(-10,-3,0,minecraft:grass_block)
B(-10,-2,0,minecraft:grass_block)
B(-10,-6,1,minecraft:dirt)
B(-10,-5,1,minecraft:dirt)
B(-10,-4,1,minecraft:dirt)
B(-10,-3,1,minecraft:grass_block)
B(-10,-6,2,minecraft:dirt)
B(-10,-5,2,minecraft:grass_block)
B(-10,-4,2,minecraft:dirt)
B(-10,-3,2,minecraft:dirt)
B(-10,-2,2,minecraft:grass_block)
B(-10,-6,3,minecraft:dirt)
B(-10,-5,3,minecraft:dirt)
B(-10,-4,3,minecraft:dirt)
B(-10,-3,3,minecraft:grass_block)
B(-10,-2,3,minecraft:grass_block)
B(-10,-6,4,minecraft:dirt)
B(-10,-5,4,minecraft:dirt)
B(-10,-4,4,minecraft:grass_block)
B(-10,-3,4,minecraft:grass_block)
B(-10,-6,5,minecraft:grass_block)
B(-10,-5,5,minecraft:dirt)
B(-10,-4,5,minecraft:dirt)
B(-10,-3,5,minecraft:grass_block)
B(-10,-6,6,minecraft:grass_block)
B(-10,-5,6,minecraft:dirt)
B(-10,-4,6,minecraft:dirt)
B(-10,-3,6,minecraft:grass_block)
B(-10,-6,7,minecraft:grass_block)
B(-10,-5,7,minecraft:dirt)
B(-10,-4,7,minecraft:grass_block)
B(-10,-6,8,minecraft:dirt)
B(-10,-5,8,minecraft:dirt)
B(-10,-4,8,minecraft:grass_block)
B(-10,-6,9,minecraft:dirt)
B(-10,-5,9,minecraft:dirt)
B(-10,-4,9,minecraft:grass_block)
B(-10,-6,10,minecraft:dirt)
B(-10,-5,10,minecraft:grass_block)
B(-10,-6,11,minecraft:dirt)
B(-10,-5,11,minecraft:grass_block)
B(-10,-6,12,minecraft:grass_block)
B(-10,-6,13,minecraft:grass_block)
B(-9,-6,-15,minecraft:grass_block)
B(-9,-6,-14,minecraft:dirt)
B(-9,-5,-14,minecraft:grass_block)
B(-9,-6,-13,minecraft:dirt)
B(-9,-5,-13,minecraft:grass_block)
B(-9,-6,-12,minecraft:dirt)
B(-9,-5,-12,minecraft:dirt)
B(-9,-4,-12,minecraft:grass_block)
B(-9,-6,-11,minecraft:dirt)
B(-9,-5,-11,minecraft:grass_block)
B(-9,-4,-11,minecraft:grass_block)
B(-9,-6,-10,minecraft:dirt)
B(-9,-5,-10,minecraft:dirt)
B(-9,-4,-10,minecraft:grass_block)
B(-9,-6,-9,minecraft:dirt)
B(-9,-5,-9,minecraft:dirt)
B(-9,-4,-9,minecraft:grass_block)
B(-9,-3,-9,minecraft:grass_block)
B(-9,-6,-8,minecraft:dirt)
B(-9,-5,-8,minecraft:dirt)
B(-9,-4,-8,minecraft:dirt)
B(-9,-3,-8,minecraft:grass_block)
B(-9,-6,-7,minecraft:dirt)
B(-9,-5,-7,minecraft:dirt)
B(-9,-4,-7,minecraft:dirt)
B(-9,-3,-7,minecraft:grass_block)
B(-9,-6,-6,minecraft:dirt)
B(-9,-5,-6,minecraft:dirt)
B(-9,-4,-6,minecraft:dirt)
B(-9,-3,-6,minecraft:grass_block)
B(-9,-6,-5,minecraft:dirt)
B(-9,-5,-5,minecraft:grass_block)
B(-9,-4,-5,minecraft:dirt)
B(-9,-3,-5,minecraft:dirt)
B(-9,-2,-5,minecraft:grass_block)
B(-9,-6,-4,minecraft:dirt)
B(-9,-5,-4,minecraft:dirt)
B(-9,-4,-4,minecraft:dirt)
B(-9,-3,-4,minecraft:dirt)
B(-9,-2,-4,minecraft:grass_block)
B(-9,-6,-3,minecraft:dirt)
B(-9,-5,-3,minecraft:dirt)
B(-9,-4,-3,minecraft:dirt)
B(-9,-3,-3,minecraft:dirt)
B(-9,-2,-3,minecraft:grass_block)
B(-9,-6,-2,minecraft:dirt)
B(-9,-5,-2,minecraft:dirt)
B(-9,-4,-2,minecraft:dirt)
B(-9,-3,-2,minecraft:grass_block)
B(-9,-2,-2,minecraft:grass_block)
B(-9,-6,-1,minecraft:dirt)
B(-9,-5,-1,minecraft:dirt)
B(-9,-4,-1,minecraft:dirt)
B(-9,-3,-1,minecraft:dirt)
B(-9,-2,-1,minecraft:grass_block)
B(-9,-6,0,minecraft:dirt)
B(-9,-5,0,minecraft:dirt)
B(-9,-4,0,minecraft:dirt)
B(-9,-3,0,minecraft:dirt)
B(-9,-2,0,minecraft:grass_block)
B(-9,-6,1,minecraft:dirt)
B(-9,-5,1,minecraft:dirt)
B(-9,-4,1,minecraft:grass_block)
B(-9,-3,1,minecraft:dirt)
B(-9,-2,1,minecraft:grass_block)
B(-9,-6,2,minecraft:grass_block)
B(-9,-5,2,minecraft:dirt)
B(-9,-4,2,minecraft:dirt)
B(-9,-3,2,minecraft:dirt)
B(-9,-2,2,minecraft:grass_block)
B(-9,-6,3,minecraft:grass_block)
B(-9,-5,3,minecraft:dirt)
B(-9,-4,3,minecraft:dirt)
B(-9,-3,3,minecraft:grass_block)
B(-9,-2,3,minecraft:grass_block)
B(-9,-6,4,minecraft:dirt)
B(-9,-5,4,minecraft:dirt)
B(-9,-4,4,minecraft:grass_block)
B(-9,-3,4,minecraft:dirt)
B(-9,-2,4,minecraft:grass_block)
B(-9,-6,5,minecraft:dirt)
B(-9,-5,5,minecraft:dirt)
B(-9,-4,5,minecraft:dirt)
B(-9,-3,5,minecraft:dirt)
B(-9,-2,5,minecraft:grass_block)
B(-9,-6,6,minecraft:dirt)
B(-9,-5,6,minecraft:dirt)
B(-9,-4,6,minecraft:grass_block)
B(-9,-3,6,minecraft:dirt)
B(-9,-2,6,minecraft:grass_block)
B(-9,-6,7,minecraft:grass_block)
B(-9,-5,7,minecraft:dirt)
B(-9,-4,7,minecraft:dirt)
B(-9,-3,7,minecraft:grass_block)
B(-9,-6,8,minecraft:dirt)
B(-9,-5,8,minecraft:dirt)
B(-9,-4,8,minecraft:dirt)
B(-9,-3,8,minecraft:grass_block)
B(-9,-6,9,minecraft:dirt)
B(-9,-5,9,minecraft:dirt)
B(-9,-4,9,minecraft:grass_block)
B(-9,-6,10,minecraft:dirt)
B(-9,-5,10,minecraft:dirt)
B(-9,-4,10,minecraft:grass_block)
B(-9,-6,11,minecraft:dirt)
B(-9,-5,11,minecraft:grass_block)
B(-9,-4,11,minecraft:grass_block)
B(-9,-6,12,minecraft:grass_block)
B(-9,-5,12,minecraft:grass_block)
B(-9,-6,13,minecraft:grass_block)
B(-9,-6,14,minecraft:grass_block)
B(-8,-6,-16,minecraft:grass_block)
B(-8,-6,-15,minecraft:grass_block)
B(-8,-6,-14,minecraft:dirt)
B(-8,-5,-14,minecraft:grass_block)
B(-8,-6,-13,minecraft:dirt)
B(-8,-5,-13,minecraft:grass_block)
B(-8,-4,-13,minecraft:grass_block)
B(-8,-6,-12,minecraft:dirt)
B(-8,-5,-12,minecraft:dirt)
B(-8,-4,-12,minecraft:grass_block)
B(-8,-6,-11,minecraft:dirt)
B(-8,-5,-11,minecraft:grass_block)
B(-8,-4,-11,minecraft:grass_block)
B(-8,-6,-10,minecraft:dirt)
B(-8,-5,-10,minecraft:grass_block)
B(-8,-4,-10,minecraft:dirt)
B(-8,-3,-10,minecraft:grass_block)
B(-8,-6,-9,minecraft:dirt)
B(-8,-5,-9,minecraft:dirt)
B(-8,-4,-9,minecraft:dirt)
B(-8,-3,-9,minecraft:grass_block)
B(-8,-6,-8,minecraft:dirt)
B(-8,-5,-8,minecraft:dirt)
B(-8,-4,-8,minecraft:dirt)
B(-8,-3,-8,minecraft:grass_block)
B(-8,-6,-7,minecraft:dirt)
B(-8,-5,-7,minecraft:dirt)
B(-8,-4,-7,minecraft:dirt)
B(-8,-3,-7,minecraft:dirt)
B(-8,-2,-7,minecraft:grass_block)
B(-8,-6,-6,minecraft:dirt)
B(-8,-5,-6,minecraft:dirt)
B(-8,-4,-6,minecraft:dirt)
B(-8,-3,-6,minecraft:dirt)
B(-8,-2,-6,minecraft:grass_block)
B(-8,-6,-5,minecraft:dirt)
B(-8,-5,-5,minecraft:dirt)
B(-8,-4,-5,minecraft:dirt)
B(-8,-3,-5,minecraft:dirt)
B(-8,-2,-5,minecraft:grass_block)
B(-8,-6,-4,minecraft:grass_block)
B(-8,-5,-4,minecraft:dirt)
B(-8,-4,-4,minecraft:dirt)
B(-8,-3,-4,minecraft:dirt)
B(-8,-2,-4,minecraft:grass_block)
B(-8,-6,-3,minecraft:dirt)
B(-8,-5,-3,minecraft:dirt)
B(-8,-4,-3,minecraft:dirt)
B(-8,-3,-3,minecraft:dirt)
B(-8,-2,-3,minecraft:grass_block)
B(-8,-6,-2,minecraft:dirt)
B(-8,-5,-2,minecraft:grass_block)
B(-8,-4,-2,minecraft:dirt)
B(-8,-3,-2,minecraft:grass_block)
B(-8,-2,-2,minecraft:grass_block)
B(-8,-6,-1,minecraft:dirt)
B(-8,-5,-1,minecraft:dirt)
B(-8,-4,-1,minecraft:dirt)
B(-8,-3,-1,minecraft:dirt)
B(-8,-2,-1,minecraft:grass_block)
B(-8,-1,-1,minecraft:farmland[moisture=6])
B(-8,0,-1,minecraft:wheat[age=7])
B(-8,-6,0,minecraft:dirt)
B(-8,-5,0,minecraft:dirt)
B(-8,-4,0,minecraft:dirt)
B(-8,-3,0,minecraft:dirt)
B(-8,-2,0,minecraft:grass_block)
B(-8,-1,0,minecraft:farmland[moisture=2])
B(-8,0,0,minecraft:wheat[age=7])
B(-8,-6,1,minecraft:dirt)
B(-8,-5,1,minecraft:dirt)
B(-8,-4,1,minecraft:dirt)
B(-8,-3,1,minecraft:grass_block)
B(-8,-2,1,minecraft:grass_block)
B(-8,-6,2,minecraft:grass_block)
B(-8,-5,2,minecraft:grass_block)
B(-8,-4,2,minecraft:dirt)
B(-8,-3,2,minecraft:grass_block)
B(-8,-2,2,minecraft:grass_block)
B(-8,-6,3,minecraft:grass_block)
B(-8,-5,3,minecraft:grass_block)
B(-8,-4,3,minecraft:dirt)
B(-8,-3,3,minecraft:dirt)
B(-8,-2,3,minecraft:grass_block)
B(-8,-6,4,minecraft:dirt)
B(-8,-5,4,minecraft:grass_block)
B(-8,-4,4,minecraft:dirt)
B(-8,-3,4,minecraft:grass_block)
B(-8,-2,4,minecraft:grass_block)
B(-8,-6,5,minecraft:grass_block)
B(-8,-5,5,minecraft:dirt)
B(-8,-4,5,minecraft:dirt)
B(-8,-3,5,minecraft:dirt)
B(-8,-2,5,minecraft:grass_block)
B(-8,-6,6,minecraft:dirt)
B(-8,-5,6,minecraft:dirt)
B(-8,-4,6,minecraft:dirt)
B(-8,-3,6,minecraft:dirt)
B(-8,-2,6,minecraft:grass_block)
B(-8,-6,7,minecraft:dirt)
B(-8,-5,7,minecraft:dirt)
B(-8,-4,7,minecraft:dirt)
B(-8,-3,7,minecraft:grass_block)
B(-8,-6,8,minecraft:dirt)
B(-8,-5,8,minecraft:dirt)
B(-8,-4,8,minecraft:dirt)
B(-8,-3,8,minecraft:grass_block)
B(-8,-6,9,minecraft:dirt)
B(-8,-5,9,minecraft:dirt)
B(-8,-4,9,minecraft:dirt)
B(-8,-3,9,minecraft:grass_block)
B(-8,-6,10,minecraft:dirt)
B(-8,-5,10,minecraft:dirt)
B(-8,-4,10,minecraft:dirt)
B(-8,-3,10,minecraft:grass_block)
B(-8,-6,11,minecraft:dirt)
B(-8,-5,11,minecraft:grass_block)
B(-8,-4,11,minecraft:grass_block)
B(-8,-6,12,minecraft:grass_block)
B(-8,-5,12,minecraft:dirt)
B(-8,-4,12,minecraft:grass_block)
B(-8,-6,13,minecraft:dirt)
B(-8,-5,13,minecraft:grass_block)
B(-8,-6,14,minecraft:grass_block)
B(-8,-6,15,minecraft:grass_block)
B(-7,-6,-16,minecraft:dirt)
B(-7,-5,-16,minecraft:grass_block)
B(-7,-6,-15,minecraft:dirt)
B(-7,-5,-15,minecraft:grass_block)
B(-7,-6,-14,minecraft:dirt)
B(-7,-5,-14,minecraft:dirt)
B(-7,-4,-14,minecraft:grass_block)
B(-7,-6,-13,minecraft:dirt)
B(-7,-5,-13,minecraft:grass_block)
B(-7,-4,-13,minecraft:grass_block)
B(-7,-6,-12,minecraft:grass_block)
B(-7,-5,-12,minecraft:grass_block)
B(-7,-4,-12,minecraft:grass_block)
B(-7,-3,-12,minecraft:grass_block)
B(-7,-6,-11,minecraft:dirt)
B(-7,-5,-11,minecraft:dirt)
B(-7,-4,-11,minecraft:dirt)
B(-7,-3,-11,minecraft:grass_block)
B(-7,-6,-10,minecraft:grass_block)
B(-7,-5,-10,minecraft:dirt)
B(-7,-4,-10,minecraft:dirt)
B(-7,-3,-10,minecraft:dirt)
B(-7,-2,-10,minecraft:grass_block)
B(-7,-6,-9,minecraft:dirt)
B(-7,-5,-9,minecraft:grass_block)
B(-7,-4,-9,minecraft:dirt)
B(-7,-3,-9,minecraft:dirt)
B(-7,-2,-9,minecraft:grass_block)
B(-7,-6,-8,minecraft:grass_block)
B(-7,-5,-8,minecraft:grass_block)
B(-7,-4,-8,minecraft:dirt)
B(-7,-3,-8,minecraft:dirt)
B(-7,-2,-8,minecraft:grass_block)
B(-7,-6,-7,minecraft:dirt)
B(-7,-5,-7,minecraft:dirt)
B(-7,-4,-7,minecraft:grass_block)
B(-7,-3,-7,minecraft:dirt)
B(-7,-2,-7,minecraft:grass_block)
B(-7,-6,-6,minecraft:dirt)
B(-7,-5,-6,minecraft:dirt)
B(-7,-4,-6,minecraft:grass_block)
B(-7,-3,-6,minecraft:dirt)
B(-7,-2,-6,minecraft:grass_block)
B(-7,-6,-5,minecraft:dirt)
B(-7,-5,-5,minecraft:dirt)
B(-7,-4,-5,minecraft:dirt)
B(-7,-3,-5,minecraft:dirt)
B(-7,-2,-5,minecraft:grass_block)
B(-7,-6,-4,minecraft:dirt)
B(-7,-5,-4,minecraft:dirt)
B(-7,-4,-4,minecraft:dirt)
B(-7,-3,-4,minecraft:dirt)
B(-7,-2,-4,minecraft:grass_block)
B(-7,-1,-4,minecraft:farmland[moisture=7])
B(-7,0,-4,minecraft:wheat[age=7])
B(-7,-6,-3,minecraft:dirt)
B(-7,-5,-3,minecraft:dirt)
B(-7,-4,-3,minecraft:dirt)
B(-7,-3,-3,minecraft:dirt)
B(-7,-2,-3,minecraft:grass_block)
B(-7,-1,-3,minecraft:farmland[moisture=6])
B(-7,0,-3,minecraft:wheat[age=7])
B(-7,-6,-2,minecraft:grass_block)
B(-7,-5,-2,minecraft:grass_block)
B(-7,-4,-2,minecraft:dirt)
B(-7,-3,-2,minecraft:dirt)
B(-7,-2,-2,minecraft:dirt)
B(-7,-1,-2,minecraft:grass_block)
B(-7,0,-2,minecraft:dark_oak_fence[east=false,north=false,south=true,waterlogged=false,west=false])
B(-7,-6,-1,minecraft:dirt)
B(-7,-5,-1,minecraft:dirt)
B(-7,-4,-1,minecraft:dirt)
B(-7,-3,-1,minecraft:dirt)
B(-7,-2,-1,minecraft:dirt)
B(-7,-1,-1,minecraft:grass_block)
B(-7,0,-1,minecraft:dark_oak_fence[east=false,north=true,south=true,waterlogged=false,west=false])
B(-7,-6,0,minecraft:grass_block)
B(-7,-5,0,minecraft:dirt)
B(-7,-4,0,minecraft:grass_block)
B(-7,-3,0,minecraft:dirt)
B(-7,-2,0,minecraft:dirt)
B(-7,-1,0,minecraft:grass_block)
B(-7,0,0,minecraft:dark_oak_fence[east=false,north=true,south=false,waterlogged=false,west=false])
B(-7,-6,1,minecraft:dirt)
B(-7,-5,1,minecraft:grass_block)
B(-7,-4,1,minecraft:dirt)
B(-7,-3,1,minecraft:dirt)
B(-7,-2,1,minecraft:grass_block)
B(-7,-1,1,minecraft:farmland[moisture=3])
B(-7,0,1,minecraft:wheat[age=7])
B(-7,-6,2,minecraft:dirt)
B(-7,-5,2,minecraft:dirt)
B(-7,-4,2,minecraft:dirt)
B(-7,-3,2,minecraft:dirt)
B(-7,-2,2,minecraft:grass_block)
B(-7,-1,2,minecraft:farmland[moisture=6])
B(-7,0,2,minecraft:wheat[age=7])
B(-7,-6,3,minecraft:grass_block)
B(-7,-5,3,minecraft:dirt)
B(-7,-4,3,minecraft:dirt)
B(-7,-3,3,minecraft:dirt)
B(-7,-2,3,minecraft:grass_block)
B(-7,-1,3,minecraft:farmland[moisture=6])
B(-7,0,3,minecraft:wheat[age=7])
B(-7,-6,4,minecraft:dirt)
B(-7,-5,4,minecraft:dirt)
B(-7,-4,4,minecraft:dirt)
B(-7,-3,4,minecraft:dirt)
B(-7,-2,4,minecraft:grass_block)
B(-7,-1,4,minecraft:farmland[moisture=6])
B(-7,0,4,minecraft:wheat[age=7])
B(-7,-6,5,minecraft:grass_block)
B(-7,-5,5,minecraft:grass_block)
B(-7,-4,5,minecraft:dirt)
B(-7,-3,5,minecraft:dirt)
B(-7,-2,5,minecraft:grass_block)
B(-7,-1,5,minecraft:farmland[moisture=7])
B(-7,0,5,minecraft:wheat[age=7])
B(-7,-6,6,minecraft:grass_block)
B(-7,-5,6,minecraft:dirt)
B(-7,-4,6,minecraft:dirt)
B(-7,-3,6,minecraft:dirt)
B(-7,-2,6,minecraft:grass_block)
B(-7,-6,7,minecraft:dirt)
B(-7,-5,7,minecraft:dirt)
B(-7,-4,7,minecraft:grass_block)
B(-7,-3,7,minecraft:dirt)
B(-7,-2,7,minecraft:grass_block)
B(-7,-6,8,minecraft:dirt)
B(-7,-5,8,minecraft:dirt)
B(-7,-4,8,minecraft:dirt)
B(-7,-3,8,minecraft:dirt)
B(-7,-2,8,minecraft:grass_block)
B(-7,-6,9,minecraft:dirt)
B(-7,-5,9,minecraft:dirt)
B(-7,-4,9,minecraft:dirt)
B(-7,-3,9,minecraft:dirt)
B(-7,-2,9,minecraft:grass_block)
B(-7,-6,10,minecraft:dirt)
B(-7,-5,10,minecraft:dirt)
B(-7,-4,10,minecraft:dirt)
B(-7,-3,10,minecraft:grass_block)
B(-7,-6,11,minecraft:dirt)
B(-7,-5,11,minecraft:dirt)
B(-7,-4,11,minecraft:grass_block)
B(-7,-3,11,minecraft:grass_block)
B(-7,-6,12,minecraft:dirt)
B(-7,-5,12,minecraft:dirt)
B(-7,-4,12,minecraft:grass_block)
B(-7,-6,13,minecraft:dirt)
B(-7,-5,13,minecraft:grass_block)
B(-7,-6,14,minecraft:dirt)
B(-7,-5,14,minecraft:grass_block)
B(-7,-6,15,minecraft:dirt)
B(-7,-5,15,minecraft:grass_block)
B(-6,-6,-16,minecraft:dirt)
B(-6,-5,-16,minecraft:grass_block)
B(-6,-6,-15,minecraft:dirt)
B(-6,-5,-15,minecraft:dirt)
B(-6,-4,-15,minecraft:grass_block)
B(-6,-6,-14,minecraft:dirt)
B(-6,-5,-14,minecraft:dirt)
B(-6,-4,-14,minecraft:grass_block)
B(-6,-6,-13,minecraft:dirt)
B(-6,-5,-13,minecraft:dirt)
B(-6,-4,-13,minecraft:dirt)
B(-6,-3,-13,minecraft:grass_block)
B(-6,-6,-12,minecraft:dirt)
B(-6,-5,-12,minecraft:grass_block)
B(-6,-4,-12,minecraft:dirt)
B(-6,-3,-12,minecraft:grass_block)
B(-6,-6,-11,minecraft:dirt)
B(-6,-5,-11,minecraft:grass_block)
B(-6,-4,-11,minecraft:dirt)
B(-6,-3,-11,minecraft:dirt)
B(-6,-2,-11,minecraft:grass_block)
B(-6,-6,-10,minecraft:grass_block)
B(-6,-5,-10,minecraft:dirt)
B(-6,-4,-10,minecraft:dirt)
B(-6,-3,-10,minecraft:dirt)
B(-6,-2,-10,minecraft:grass_block)
B(-6,-6,-9,minecraft:dirt)
B(-6,-5,-9,minecraft:dirt)
B(-6,-4,-9,minecraft:dirt)
B(-6,-3,-9,minecraft:dirt)
B(-6,-2,-9,minecraft:dirt)
B(-6,-1,-9,minecraft:grass_block)
B(-6,0,-9,minecraft:dark_oak_fence[east=true,north=false,south=true,waterlogged=false,west=false])
B(-6,-6,-8,minecraft:dirt)
B(-6,-5,-8,minecraft:dirt)
B(-6,-4,-8,minecraft:dirt)
B(-6,-3,-8,minecraft:dirt)
B(-6,-2,-8,minecraft:dirt)
B(-6,-1,-8,minecraft:grass_block)
B(-6,0,-8,minecraft:dark_oak_fence[east=true,north=true,south=false,waterlogged=false,west=false])
B(-6,-6,-7,minecraft:grass_block)
B(-6,-5,-7,minecraft:dirt)
B(-6,-4,-7,minecraft:dirt)
B(-6,-3,-7,minecraft:grass_block)
B(-6,-2,-7,minecraft:grass_block)
B(-6,-1,-7,minecraft:farmland[moisture=3])
B(-6,-6,-6,minecraft:dirt)
B(-6,-5,-6,minecraft:dirt)
B(-6,-4,-6,minecraft:dirt)
B(-6,-3,-6,minecraft:dirt)
B(-6,-2,-6,minecraft:dirt)
B(-6,-1,-6,minecraft:grass_block)
B(-6,0,-6,minecraft:dark_oak_fence[east=false,north=false,south=true,waterlogged=false,west=false])
B(-6,-6,-5,minecraft:dirt)
B(-6,-5,-5,minecraft:dirt)
B(-6,-4,-5,minecraft:dirt)
B(-6,-3,-5,minecraft:grass_block)
B(-6,-2,-5,minecraft:dirt)
B(-6,-1,-5,minecraft:grass_block)
B(-6,0,-5,minecraft:dark_oak_fence[east=false,north=true,south=false,waterlogged=false,west=false])
B(-6,-6,-4,minecraft:dirt)
B(-6,-5,-4,minecraft:grass_block)
B(-6,-4,-4,minecraft:dirt)
B(-6,-3,-4,minecraft:grass_block)
B(-6,-2,-4,minecraft:grass_block)
B(-6,-1,-4,minecraft:farmland[moisture=6])
B(-6,0,-4,minecraft:wheat[age=7])
B(-6,-6,-3,minecraft:dirt)
B(-6,-5,-3,minecraft:grass_block)
B(-6,-4,-3,minecraft:dirt)
B(-6,-3,-3,minecraft:dirt)
B(-6,-2,-3,minecraft:grass_block)
B(-6,-1,-3,minecraft:farmland[moisture=7])
B(-6,0,-3,minecraft:wheat[age=7])
B(-6,-6,-2,minecraft:grass_block)
B(-6,-5,-2,minecraft:dirt)
B(-6,-4,-2,minecraft:dirt)
B(-6,-3,-2,minecraft:grass_block)
B(-6,-2,-2,minecraft:grass_block)
B(-6,-1,-2,minecraft:farmland[moisture=2])
B(-6,0,-2,minecraft:wheat[age=7])
B(-6,-6,-1,minecraft:dirt)
B(-6,-5,-1,minecraft:dirt)
B(-6,-4,-1,minecraft:dirt)
B(-6,-3,-1,minecraft:dirt)
B(-6,-2,-1,minecraft:grass_block)
B(-6,-1,-1,minecraft:farmland[moisture=6])
B(-6,0,-1,minecraft:wheat[age=7])
B(-6,-6,0,minecraft:grass_block)
B(-6,-5,0,minecraft:dirt)
B(-6,-4,0,minecraft:grass_block)
B(-6,-3,0,minecraft:dirt)
B(-6,-2,0,minecraft:grass_block)
B(-6,-1,0,minecraft:farmland[moisture=1])
B(-6,0,0,minecraft:wheat[age=7])
B(-6,-6,1,minecraft:dirt)
B(-6,-5,1,minecraft:dirt)
B(-6,-4,1,minecraft:grass_block)
B(-6,-3,1,minecraft:dirt)
B(-6,-2,1,minecraft:grass_block)
B(-6,-1,1,minecraft:farmland[moisture=6])
B(-6,0,1,minecraft:wheat[age=7])
B(-6,-6,2,minecraft:dirt)
B(-6,-5,2,minecraft:dirt)
B(-6,-4,2,minecraft:dirt)
B(-6,-3,2,minecraft:grass_block)
B(-6,-2,2,minecraft:dirt)
B(-6,-1,2,minecraft:grass_block)
B(-6,0,2,minecraft:dark_oak_fence[east=false,north=false,south=true,waterlogged=false,west=false])
B(-6,-6,3,minecraft:dirt)
B(-6,-5,3,minecraft:dirt)
B(-6,-4,3,minecraft:dirt)
B(-6,-3,3,minecraft:dirt)
B(-6,-2,3,minecraft:dirt)
B(-6,-1,3,minecraft:grass_block)
B(-6,0,3,minecraft:dark_oak_fence[east=false,north=true,south=true,waterlogged=false,west=false])
B(-6,-6,4,minecraft:dirt)
B(-6,-5,4,minecraft:dirt)
B(-6,-4,4,minecraft:grass_block)
B(-6,-3,4,minecraft:grass_block)
B(-6,-2,4,minecraft:dirt)
B(-6,-1,4,minecraft:grass_block)
B(-6,0,4,minecraft:dark_oak_fence[east=false,north=true,south=true,waterlogged=false,west=false])
B(-6,-6,5,minecraft:dirt)
B(-6,-5,5,minecraft:dirt)
B(-6,-4,5,minecraft:dirt)
B(-6,-3,5,minecraft:dirt)
B(-6,-2,5,minecraft:dirt)
B(-6,-1,5,minecraft:grass_block)
B(-6,0,5,minecraft:dark_oak_fence[east=false,north=true,south=true,waterlogged=false,west=false])
B(-6,-6,6,minecraft:dirt)
B(-6,-5,6,minecraft:dirt)
B(-6,-4,6,minecraft:dirt)
B(-6,-3,6,minecraft:grass_block)
B(-6,-2,6,minecraft:dirt)
B(-6,-1,6,minecraft:grass_block)
B(-6,0,6,minecraft:dark_oak_fence[east=true,north=true,south=false,waterlogged=false,west=false])
B(-6,-6,7,minecraft:dirt)
B(-6,-5,7,minecraft:grass_block)
B(-6,-4,7,minecraft:dirt)
B(-6,-3,7,minecraft:dirt)
B(-6,-2,7,minecraft:grass_block)
B(-6,-1,7,minecraft:farmland[moisture=5])
B(-6,0,7,minecraft:wheat[age=7])
B(-6,-6,8,minecraft:dirt)
B(-6,-5,8,minecraft:dirt)
B(-6,-4,8,minecraft:dirt)
B(-6,-3,8,minecraft:dirt)
B(-6,-2,8,minecraft:grass_block)
B(-6,-6,9,minecraft:dirt)
B(-6,-5,9,minecraft:dirt)
B(-6,-4,9,minecraft:dirt)
B(-6,-3,9,minecraft:dirt)
B(-6,-2,9,minecraft:grass_block)
B(-6,-6,10,minecraft:dirt)
B(-6,-5,10,minecraft:dirt)
B(-6,-4,10,minecraft:dirt)
B(-6,-3,10,minecraft:dirt)
B(-6,-2,10,minecraft:grass_block)
B(-6,-6,11,minecraft:dirt)
B(-6,-5,11,minecraft:dirt)
B(-6,-4,11,minecraft:dirt)
B(-6,-3,11,minecraft:dirt)
B(-6,-2,11,minecraft:grass_block)
B(-6,-6,12,minecraft:dirt)
B(-6,-5,12,minecraft:dirt)
B(-6,-4,12,minecraft:dirt)
B(-6,-3,12,minecraft:grass_block)
B(-6,-6,13,minecraft:grass_block)
B(-6,-5,13,minecraft:dirt)
B(-6,-4,13,minecraft:grass_block)
B(-6,-6,14,minecraft:dirt)
B(-6,-5,14,minecraft:dirt)
B(-6,-4,14,minecraft:grass_block)
B(-6,-6,15,minecraft:dirt)
B(-6,-5,15,minecraft:grass_block)
B(-5,-6,-16,minecraft:dirt)
B(-5,-5,-16,minecraft:grass_block)
B(-5,-6,-15,minecraft:dirt)
B(-5,-5,-15,minecraft:dirt)
B(-5,-4,-15,minecraft:grass_block)
B(-5,-6,-14,minecraft:dirt)
B(-5,-5,-14,minecraft:grass_block)
B(-5,-4,-14,minecraft:grass_block)
B(-5,-6,-13,minecraft:dirt)
B(-5,-5,-13,minecraft:dirt)
B(-5,-4,-13,minecraft:dirt)
B(-5,-3,-13,minecraft:grass_block)
B(-5,-6,-12,minecraft:dirt)
B(-5,-5,-12,minecraft:dirt)
B(-5,-4,-12,minecraft:dirt)
B(-5,-3,-12,minecraft:dirt)
B(-5,-2,-12,minecraft:grass_block)
B(-5,-6,-11,minecraft:dirt)
B(-5,-5,-11,minecraft:dirt)
B(-5,-4,-11,minecraft:dirt)
B(-5,-3,-11,minecraft:dirt)
B(-5,-2,-11,minecraft:grass_block)
B(-5,-6,-10,minecraft:dirt)
B(-5,-5,-10,minecraft:grass_block)
B(-5,-4,-10,minecraft:dirt)
B(-5,-3,-10,minecraft:dirt)
B(-5,-2,-10,minecraft:grass_block)
B(-5,-6,-9,minecraft:dirt)
B(-5,-5,-9,minecraft:dirt)
B(-5,-4,-9,minecraft:dirt)
B(-5,-3,-9,minecraft:grass_block)
B(-5,-2,-9,minecraft:grass_block)
B(-5,-1,-9,minecraft:grass_block)
B(-5,0,-9,minecraft:dark_oak_fence[east=false,north=false,south=true,waterlogged=false,west=true])
B(-5,-6,-8,minecraft:dirt)
B(-5,-5,-8,minecraft:grass_block)
B(-5,-4,-8,minecraft:dirt)
B(-5,-3,-8,minecraft:dirt)
B(-5,-2,-8,minecraft:grass_block)
B(-5,-1,-8,minecraft:dirt)
B(-5,0,-8,minecraft:hay_block)
B(-5,-6,-7,minecraft:dirt)
B(-5,-5,-7,minecraft:dirt)
B(-5,-4,-7,minecraft:grass_block)
B(-5,-3,-7,minecraft:grass_block)
B(-5,-2,-7,minecraft:grass_block)
B(-5,-1,-7,minecraft:dirt)
B(-5,0,-7,minecraft:hay_block)
B(-5,-6,-6,minecraft:dirt)
B(-5,-5,-6,minecraft:dirt)
B(-5,-4,-6,minecraft:dirt)
B(-5,-3,-6,minecraft:dirt)
B(-5,-2,-6,minecraft:cobblestone)
B(-5,-1,-6,minecraft:farmland[moisture=6])
B(-5,0,-6,minecraft:wheat[age=7])
B(-5,-6,-5,minecraft:dirt)
B(-5,-5,-5,minecraft:dirt)
B(-5,-4,-5,minecraft:dirt)
B(-5,-3,-5,minecraft:dirt)
B(-5,-2,-5,minecraft:cobblestone)
B(-5,-1,-5,minecraft:farmland[moisture=5])
B(-5,0,-5,minecraft:wheat[age=7])
B(-5,-6,-4,minecraft:dirt)
B(-5,-5,-4,minecraft:dirt)
B(-5,-4,-4,minecraft:dirt)
B(-5,-3,-4,minecraft:grass_block)
B(-5,-2,-4,minecraft:grass_block)
B(-5,-1,-4,minecraft:farmland[moisture=3])
B(-5,0,-4,minecraft:wheat[age=7])
B(-5,-6,-3,minecraft:dirt)
B(-5,-5,-3,minecraft:dirt)
B(-5,-4,-3,minecraft:dirt)
B(-5,-3,-3,minecraft:dirt)
B(-5,-2,-3,minecraft:grass_block)
B(-5,-1,-3,minecraft:farmland[moisture=5])
B(-5,0,-3,minecraft:wheat[age=7])
B(-5,-6,-2,minecraft:dirt)
B(-5,-5,-2,minecraft:dirt)
B(-5,-4,-2,minecraft:dirt)
B(-5,-3,-2,minecraft:dirt)
B(-5,-2,-2,minecraft:grass_block)
B(-5,-1,-2,minecraft:farmland[moisture=6])
B(-5,0,-2,minecraft:wheat[age=7])
B(-5,-6,-1,minecraft:dirt)
B(-5,-5,-1,minecraft:dirt)
B(-5,-4,-1,minecraft:dirt)
B(-5,-3,-1,minecraft:dirt)
B(-5,-2,-1,minecraft:grass_block)
B(-5,-1,-1,minecraft:farmland[moisture=6])
B(-5,0,-1,minecraft:wheat[age=7])
B(-5,-6,0,minecraft:dirt)
B(-5,-5,0,minecraft:dirt)
B(-5,-4,0,minecraft:dirt)
B(-5,-3,0,minecraft:dirt)
B(-5,-2,0,minecraft:grass_block)
B(-5,-1,0,minecraft:farmland[moisture=6])
B(-5,0,0,minecraft:wheat[age=7])
B(-5,-6,1,minecraft:dirt)
B(-5,-5,1,minecraft:dirt)
B(-5,-4,1,minecraft:dirt)
B(-5,-3,1,minecraft:dirt)
B(-5,-2,1,minecraft:grass_block)
B(-5,-1,1,minecraft:farmland[moisture=7])
B(-5,0,1,minecraft:wheat[age=7])
B(-5,-6,2,minecraft:dirt)
B(-5,-5,2,minecraft:dirt)
B(-5,-4,2,minecraft:grass_block)
B(-5,-3,2,minecraft:grass_block)
B(-5,-2,2,minecraft:grass_block)
B(-5,-1,2,minecraft:farmland[moisture=4])
B(-5,0,2,minecraft:wheat[age=7])
B(-5,-6,3,minecraft:dirt)
B(-5,-5,3,minecraft:dirt)
B(-5,-4,3,minecraft:dirt)
B(-5,-3,3,minecraft:dirt)
B(-5,-2,3,minecraft:grass_block)
B(-5,-1,3,minecraft:farmland[moisture=5])
B(-5,0,3,minecraft:wheat[age=7])
B(-5,-6,4,minecraft:dirt)
B(-5,-5,4,minecraft:dirt)
B(-5,-4,4,minecraft:dirt)
B(-5,-3,4,minecraft:dirt)
B(-5,-2,4,minecraft:grass_block)
B(-5,-1,4,minecraft:farmland[moisture=3])
B(-5,0,4,minecraft:wheat[age=7])
B(-5,-6,5,minecraft:dirt)
B(-5,-5,5,minecraft:grass_block)
B(-5,-4,5,minecraft:dirt)
B(-5,-3,5,minecraft:grass_block)
B(-5,-2,5,minecraft:grass_block)
B(-5,-1,5,minecraft:farmland[moisture=4])
B(-5,0,5,minecraft:wheat[age=7])
B(-5,-6,6,minecraft:dirt)
B(-5,-5,6,minecraft:dirt)
B(-5,-4,6,minecraft:grass_block)
B(-5,-3,6,minecraft:dirt)
B(-5,-2,6,minecraft:cobblestone)
B(-5,-1,6,minecraft:grass_block)
B(-5,0,6,minecraft:hay_block)
B(-5,-6,7,minecraft:dirt)
B(-5,-5,7,minecraft:grass_block)
B(-5,-4,7,minecraft:dirt)
B(-5,-3,7,minecraft:dirt)
B(-5,-2,7,minecraft:dirt)
B(-5,-1,7,minecraft:farmland[moisture=6])
B(-5,0,7,minecraft:wheat[age=7])
B(-5,-6,8,minecraft:dirt)
B(-5,-5,8,minecraft:dirt)
B(-5,-4,8,minecraft:dirt)
B(-5,-3,8,minecraft:grass_block)
B(-5,-2,8,minecraft:grass_block)
B(-5,-1,8,minecraft:farmland[moisture=3])
B(-5,0,8,minecraft:wheat[age=7])
B(-5,-6,9,minecraft:grass_block)
B(-5,-5,9,minecraft:dirt)
B(-5,-4,9,minecraft:dirt)
B(-5,-3,9,minecraft:dirt)
B(-5,-2,9,minecraft:grass_block)
B(-5,-6,10,minecraft:dirt)
B(-5,-5,10,minecraft:dirt)
B(-5,-4,10,minecraft:grass_block)
B(-5,-3,10,minecraft:dirt)
B(-5,-2,10,minecraft:grass_block)
B(-5,-6,11,minecraft:dirt)
B(-5,-5,11,minecraft:dirt)
B(-5,-4,11,minecraft:grass_block)
B(-5,-3,11,minecraft:dirt)
B(-5,-2,11,minecraft:grass_block)
B(-5,-6,12,minecraft:grass_block)
B(-5,-5,12,minecraft:dirt)
B(-5,-4,12,minecraft:dirt)
B(-5,-3,12,minecraft:grass_block)
B(-5,-6,13,minecraft:dirt)
B(-5,-5,13,minecraft:dirt)
B(-5,-4,13,minecraft:grass_block)
B(-5,-3,13,minecraft:grass_block)
B(-5,-6,14,minecraft:dirt)
B(-5,-5,14,minecraft:dirt)
B(-5,-4,14,minecraft:grass_block)
B(-5,-6,15,minecraft:dirt)
B(-5,-5,15,minecraft:dirt)
B(-5,-4,15,minecraft:grass_block)
B(-4,-6,-16,minecraft:dirt)
B(-4,-5,-16,minecraft:dirt)
B(-4,-4,-16,minecraft:grass_block)
B(-4,-6,-15,minecraft:dirt)
B(-4,-5,-15,minecraft:dirt)
B(-4,-4,-15,minecraft:grass_block)
B(-4,-6,-14,minecraft:grass_block)
B(-4,-5,-14,minecraft:grass_block)
B(-4,-4,-14,minecraft:dirt)
B(-4,-3,-14,minecraft:grass_block)
B(-4,-6,-13,minecraft:dirt)
B(-4,-5,-13,minecraft:dirt)
B(-4,-4,-13,minecraft:dirt)
B(-4,-3,-13,minecraft:dirt)
B(-4,-2,-13,minecraft:grass_block)
B(-4,-6,-12,minecraft:dirt)
B(-4,-5,-12,minecraft:dirt)
B(-4,-4,-12,minecraft:dirt)
B(-4,-3,-12,minecraft:dirt)
B(-4,-2,-12,minecraft:grass_block)
B(-4,-6,-11,minecraft:dirt)
B(-4,-5,-11,minecraft:dirt)
B(-4,-4,-11,minecraft:grass_block)
B(-4,-3,-11,minecraft:dirt)
B(-4,-2,-11,minecraft:grass_block)
B(-4,-6,-10,minecraft:dirt)
B(-4,-5,-10,minecraft:dirt)
B(-4,-4,-10,minecraft:dirt)
B(-4,-3,-10,minecraft:dirt)
B(-4,-2,-10,minecraft:grass_block)
B(-4,-6,-9,minecraft:grass_block)
B(-4,-5,-9,minecraft:grass_block)
B(-4,-4,-9,minecraft:dirt)
B(-4,-3,-9,minecraft:dirt)
B(-4,-2,-9,minecraft:grass_block)
B(-4,-1,-9,minecraft:farmland[moisture=3])
B(-4,0,-9,minecraft:wheat[age=7])
B(-4,-6,-8,minecraft:dirt)
B(-4,-5,-8,minecraft:dirt)
B(-4,-4,-8,minecraft:dirt)
B(-4,-3,-8,minecraft:dirt)
B(-4,-2,-8,minecraft:dirt)
B(-4,-1,-8,minecraft:dirt)
B(-4,0,-8,minecraft:hay_block)
B(-4,-6,-7,minecraft:dirt)
B(-4,-5,-7,minecraft:dirt)
B(-4,-4,-7,minecraft:grass_block)
B(-4,-3,-7,minecraft:dirt)
B(-4,-2,-7,minecraft:dirt)
B(-4,-1,-7,minecraft:dirt)
B(-4,0,-7,minecraft:hay_block)
B(-4,-6,-6,minecraft:dirt)
B(-4,-5,-6,minecraft:dirt)
B(-4,-4,-6,minecraft:dirt)
B(-4,-3,-6,minecraft:dirt)
B(-4,-2,-6,minecraft:grass_block)
B(-4,-1,-6,minecraft:farmland[moisture=5])
B(-4,0,-6,minecraft:wheat[age=7])
B(-4,-6,-5,minecraft:dirt)
B(-4,-5,-5,minecraft:dirt)
B(-4,-4,-5,minecraft:dirt)
B(-4,-3,-5,minecraft:dirt)
B(-4,-2,-5,minecraft:grass_block)
B(-4,-1,-5,minecraft:farmland[moisture=4])
B(-4,0,-5,minecraft:wheat[age=7])
B(-4,-6,-4,minecraft:dirt)
B(-4,-5,-4,minecraft:dirt)
B(-4,-4,-4,minecraft:dirt)
B(-4,-3,-4,minecraft:dirt)
B(-4,-2,-4,minecraft:grass_block)
B(-4,-1,-4,minecraft:farmland[moisture=6])
B(-4,0,-4,minecraft:wheat[age=7])
B(-4,-6,-3,minecraft:dirt)
B(-4,-5,-3,minecraft:dirt)
B(-4,-4,-3,minecraft:dirt)
B(-4,-3,-3,minecraft:dirt)
B(-4,-2,-3,minecraft:dirt)
B(-4,-1,-3,minecraft:dirt)
B(-4,0,-3,minecraft:spruce_log)
B(-4,1,-3,minecraft:spruce_log)
B(-4,2,-3,minecraft:spruce_log)
B(-4,3,-3,minecraft:dark_oak_stairs[facing=south,half=bottom,shape=outer_left,waterlogged=false])
B(-4,-6,-2,minecraft:dirt)
B(-4,-5,-2,minecraft:dirt)
B(-4,-4,-2,minecraft:dirt)
B(-4,-3,-2,minecraft:dirt)
B(-4,-2,-2,minecraft:dirt)
B(-4,-1,-2,minecraft:grass_block)
B(-4,0,-2,minecraft:cobblestone)
B(-4,1,-2,minecraft:cobblestone)
B(-4,2,-2,minecraft:cobblestone)
B(-4,3,-2,minecraft:stone_brick_stairs[facing=east,half=bottom,shape=straight,waterlogged=false])
B(-4,6,-2,minecraft:spruce_log[axis=x])
B(-4,7,-2,minecraft:spruce_slab)
B(-4,-6,-1,minecraft:dirt)
B(-4,-5,-1,minecraft:dirt)
B(-4,-4,-1,minecraft:dirt)
B(-4,-3,-1,minecraft:dirt)
B(-4,-2,-1,minecraft:dirt)
B(-4,-1,-1,minecraft:grass_block)
B(-4,0,-1,minecraft:cobblestone_stairs[facing=east,half=bottom,shape=straight,waterlogged=false])
B(-4,1,-1,minecraft:cobblestone_stairs[facing=east,half=top,shape=straight,waterlogged=false])
B(-4,2,-1,minecraft:cobblestone_stairs[facing=east,half=bottom,shape=straight,waterlogged=false])
B(-4,7,-1,minecraft:spruce_slab)
B(-4,-6,0,minecraft:dirt)
B(-4,-5,0,minecraft:dirt)
B(-4,-4,0,minecraft:dirt)
B(-4,-3,0,minecraft:dirt)
B(-4,-2,0,minecraft:dirt)
B(-4,-1,0,minecraft:dirt)
B(-4,0,0,minecraft:cobblestone)
B(-4,1,0,minecraft:cobblestone)
B(-4,2,0,minecraft:cobblestone)
B(-4,3,0,minecraft:stone_brick_stairs[facing=east,half=bottom,shape=straight,waterlogged=false])
B(-4,7,0,minecraft:spruce_slab)
B(-4,-6,1,minecraft:dirt)
B(-4,-5,1,minecraft:dirt)
B(-4,-4,1,minecraft:dirt)
B(-4,-3,1,minecraft:dirt)
B(-4,-2,1,minecraft:grass_block)
B(-4,-1,1,minecraft:grass_block)
B(-4,0,1,minecraft:cobblestone_stairs[facing=east,half=bottom,shape=straight,waterlogged=false])
B(-4,1,1,minecraft:cobblestone_stairs[facing=east,half=top,shape=straight,waterlogged=false])
B(-4,2,1,minecraft:cobblestone_stairs[facing=east,half=bottom,shape=straight,waterlogged=false])
B(-4,7,1,minecraft:spruce_slab)
B(-4,-6,2,minecraft:dirt)
B(-4,-5,2,minecraft:dirt)
B(-4,-4,2,minecraft:dirt)
B(-4,-3,2,minecraft:grass_block)
B(-4,-2,2,minecraft:grass_block)
B(-4,-1,2,minecraft:dirt)
B(-4,0,2,minecraft:cobblestone)
B(-4,1,2,minecraft:cobblestone)
B(-4,2,2,minecraft:cobblestone)
B(-4,3,2,minecraft:stone_brick_stairs[facing=east,half=bottom,shape=straight,waterlogged=false])
B(-4,6,2,minecraft:spruce_log[axis=x])
B(-4,7,2,minecraft:spruce_slab)
B(-4,-6,3,minecraft:dirt)
B(-4,-5,3,minecraft:grass_block)
B(-4,-4,3,minecraft:dirt)
B(-4,-3,3,minecraft:dirt)
B(-4,-2,3,minecraft:dirt)
B(-4,-1,3,minecraft:dirt)
B(-4,0,3,minecraft:spruce_log)
B(-4,1,3,minecraft:spruce_log)
B(-4,2,3,minecraft:spruce_log)
B(-4,3,3,minecraft:dark_oak_stairs[facing=east,half=bottom,shape=straight,waterlogged=false])
B(-4,-6,4,minecraft:grass_block)
B(-4,-5,4,minecraft:dirt)
B(-4,-4,4,minecraft:grass_block)
B(-4,-3,4,minecraft:dirt)
B(-4,-2,4,minecraft:dirt)
B(-4,-1,4,minecraft:dirt)
B(-4,0,4,minecraft:hay_block)
B(-4,-6,5,minecraft:dirt)
B(-4,-5,5,minecraft:dirt)
B(-4,-4,5,minecraft:dirt)
B(-4,-3,5,minecraft:grass_block)
B(-4,-2,5,minecraft:grass_block)
B(-4,-1,5,minecraft:farmland[moisture=3])
B(-4,0,5,minecraft:wheat[age=7])
B(-4,-6,6,minecraft:dirt)
B(-4,-5,6,minecraft:dirt)
B(-4,-4,6,minecraft:dirt)
B(-4,-3,6,minecraft:dirt)
B(-4,-2,6,minecraft:grass_block)
B(-4,-1,6,minecraft:farmland[moisture=5])
B(-4,0,6,minecraft:wheat[age=7])
B(-4,-6,7,minecraft:dirt)
B(-4,-5,7,minecraft:dirt)
B(-4,-4,7,minecraft:dirt)
B(-4,-3,7,minecraft:grass_block)
B(-4,-2,7,minecraft:grass_block)
B(-4,-1,7,minecraft:farmland[moisture=7])
B(-4,0,7,minecraft:wheat[age=7])
B(-4,-6,8,minecraft:dirt)
B(-4,-5,8,minecraft:dirt)
B(-4,-4,8,minecraft:dirt)
B(-4,-3,8,minecraft:dirt)
B(-4,-2,8,minecraft:grass_block)
B(-4,-1,8,minecraft:farmland[moisture=6])
B(-4,0,8,minecraft:wheat[age=7])
B(-4,-6,9,minecraft:dirt)
B(-4,-5,9,minecraft:dirt)
B(-4,-4,9,minecraft:dirt)
B(-4,-3,9,minecraft:dirt)
B(-4,-2,9,minecraft:grass_block)
B(-4,-1,9,minecraft:farmland[moisture=6])
B(-4,0,9,minecraft:wheat[age=7])
B(-4,-6,10,minecraft:dirt)
B(-4,-5,10,minecraft:dirt)
B(-4,-4,10,minecraft:grass_block)
B(-4,-3,10,minecraft:dirt)
B(-4,-2,10,minecraft:grass_block)
B(-4,-1,10,minecraft:farmland[moisture=7])
B(-4,0,10,minecraft:wheat[age=7])
B(-4,-6,11,minecraft:dirt)
B(-4,-5,11,minecraft:dirt)
B(-4,-4,11,minecraft:dirt)
B(-4,-3,11,minecraft:dirt)
B(-4,-2,11,minecraft:grass_block)
B(-4,-6,12,minecraft:dirt)
B(-4,-5,12,minecraft:dirt)
B(-4,-4,12,minecraft:dirt)
B(-4,-3,12,minecraft:dirt)
B(-4,-2,12,minecraft:grass_block)
B(-4,-6,13,minecraft:grass_block)
B(-4,-5,13,minecraft:grass_block)
B(-4,-4,13,minecraft:dirt)
B(-4,-3,13,minecraft:grass_block)
B(-4,-2,13,minecraft:grass_block)
B(-4,-6,14,minecraft:dirt)
B(-4,-5,14,minecraft:dirt)
B(-4,-4,14,minecraft:dirt)
B(-4,-3,14,minecraft:grass_block)
B(-4,-6,15,minecraft:grass_block)
B(-4,-5,15,minecraft:dirt)
B(-4,-4,15,minecraft:grass_block)
B(-3,-6,-16,minecraft:dirt)
B(-3,-5,-16,minecraft:dirt)
B(-3,-4,-16,minecraft:grass_block)
B(-3,-6,-15,minecraft:dirt)
B(-3,-5,-15,minecraft:dirt)
B(-3,-4,-15,minecraft:dirt)
B(-3,-3,-15,minecraft:grass_block)
B(-3,-6,-14,minecraft:grass_block)
B(-3,-5,-14,minecraft:dirt)
B(-3,-4,-14,minecraft:dirt)
B(-3,-3,-14,minecraft:grass_block)
B(-3,-6,-13,minecraft:dirt)
B(-3,-5,-13,minecraft:dirt)
B(-3,-4,-13,minecraft:dirt)
B(-3,-3,-13,minecraft:grass_block)
B(-3,-2,-13,minecraft:grass_block)
B(-3,-6,-12,minecraft:dirt)
B(-3,-5,-12,minecraft:dirt)
B(-3,-4,-12,minecraft:dirt)
B(-3,-3,-12,minecraft:dirt)
B(-3,-2,-12,minecraft:grass_block)
B(-3,-6,-11,minecraft:grass_block)
B(-3,-5,-11,minecraft:grass_block)
B(-3,-4,-11,minecraft:dirt)
B(-3,-3,-11,minecraft:dirt)
B(-3,-2,-11,minecraft:dirt)
B(-3,-1,-11,minecraft:grass_block)
B(-3,0,-11,minecraft:dark_oak_fence[east=true,north=false,south=true,waterlogged=false,west=false])
B(-3,-6,-10,minecraft:grass_block)
B(-3,-5,-10,minecraft:dirt)
B(-3,-4,-10,minecraft:dirt)
B(-3,-3,-10,minecraft:dirt)
B(-3,-2,-10,minecraft:dirt)
B(-3,-1,-10,minecraft:grass_block)
B(-3,0,-10,minecraft:dark_oak_fence[east=false,north=true,south=true,waterlogged=false,west=false])
B(-3,-6,-9,minecraft:dirt)
B(-3,-5,-9,minecraft:dirt)
B(-3,-4,-9,minecraft:dirt)
B(-3,-3,-9,minecraft:dirt)
B(-3,-2,-9,minecraft:dirt)
B(-3,-1,-9,minecraft:grass_block)
B(-3,0,-9,minecraft:dark_oak_fence[east=false,north=true,south=false,waterlogged=false,west=false])
B(-3,-6,-8,minecraft:dirt)
B(-3,-5,-8,minecraft:dirt)
B(-3,-4,-8,minecraft:dirt)
B(-3,-3,-8,minecraft:dirt)
B(-3,-2,-8,minecraft:grass_block)
B(-3,-1,-8,minecraft:farmland[moisture=7])
B(-3,0,-8,minecraft:wheat[age=7])
B(-3,-6,-7,minecraft:dirt)
B(-3,-5,-7,minecraft:dirt)
B(-3,-4,-7,minecraft:dirt)
B(-3,-3,-7,minecraft:dirt)
B(-3,-2,-7,minecraft:grass_block)
B(-3,-1,-7,minecraft:farmland[moisture=6])
B(-3,0,-7,minecraft:wheat[age=7])
B(-3,-6,-6,minecraft:dirt)
B(-3,-5,-6,minecraft:dirt)
B(-3,-4,-6,minecraft:dirt)
B(-3,-3,-6,minecraft:dirt)
B(-3,-2,-6,minecraft:grass_block)
B(-3,-1,-6,minecraft:farmland[moisture=6])
B(-3,0,-6,minecraft:wheat[age=7])
B(-3,-6,-5,minecraft:dirt)
B(-3,-5,-5,minecraft:dirt)
B(-3,-4,-5,minecraft:dirt)
B(-3,-3,-5,minecraft:dirt)
B(-3,-2,-5,minecraft:grass_block)
B(-3,-1,-5,minecraft:farmland[moisture=6])
B(-3,0,-5,minecraft:wheat[age=7])
B(-3,-6,-4,minecraft:dirt)
B(-3,-5,-4,minecraft:dirt)
B(-3,-4,-4,minecraft:grass_block)
B(-3,-3,-4,minecraft:dirt)
B(-3,-2,-4,minecraft:dirt)
B(-3,-1,-4,minecraft:dirt)
B(-3,0,-4,minecraft:spruce_log)
B(-3,1,-4,minecraft:spruce_log)
B(-3,2,-4,minecraft:spruce_log)
B(-3,3,-4,minecraft:dark_oak_stairs[facing=south,half=bottom,shape=outer_left,waterlogged=false])
B(-3,-6,-3,minecraft:dirt)
B(-3,-5,-3,minecraft:dirt)
B(-3,-4,-3,minecraft:dirt)
B(-3,-3,-3,minecraft:dirt)
B(-3,-2,-3,minecraft:dirt)
B(-3,-1,-3,minecraft:dirt)
B(-3,0,-3,minecraft:dirt)
B(-3,1,-3,minecraft:cobblestone)
B(-3,2,-3,minecraft:cobblestone)
B(-3,3,-3,minecraft:stone_brick_stairs[facing=east,half=bottom,shape=inner_right,waterlogged=false])
B(-3,7,-3,minecraft:spruce_slab)
B(-3,-6,-2,minecraft:dirt)
B(-3,-5,-2,minecraft:dirt)
B(-3,-4,-2,minecraft:dirt)
B(-3,-3,-2,minecraft:dirt)
B(-3,-2,-2,minecraft:dirt)
B(-3,-1,-2,minecraft:spruce_log)
B(-3,0,-2,minecraft:spruce_log)
B(-3,1,-2,minecraft:spruce_log)
B(-3,2,-2,minecraft:spruce_log)
B(-3,3,-2,minecraft:spruce_log)
B(-3,4,-2,minecraft:spruce_log)
B(-3,5,-2,minecraft:spruce_log)
B(-3,6,-2,minecraft:spruce_log[axis=x])
B(-3,7,-2,minecraft:spruce_slab[type=double,waterlogged=false])
B(-3,-6,-1,minecraft:dirt)
B(-3,-5,-1,minecraft:grass_block)
B(-3,-4,-1,minecraft:grass_block)
B(-3,-3,-1,minecraft:dirt)
B(-3,-2,-1,minecraft:grass_block)
B(-3,-1,-1,minecraft:cobblestone)
B(-3,0,-1,minecraft:cobblestone)
B(-3,1,-1,minecraft:cobblestone)
B(-3,2,-1,minecraft:cobblestone)
B(-3,3,-1,minecraft:cobblestone)
B(-3,4,-1,minecraft:dark_oak_planks)
B(-3,5,-1,minecraft:dark_oak_planks)
B(-3,6,-1,minecraft:dark_oak_planks)
B(-3,7,-1,minecraft:spruce_slab[type=double,waterlogged=false])
B(-3,-6,0,minecraft:dirt)
B(-3,-5,0,minecraft:dirt)
B(-3,-4,0,minecraft:dirt)
B(-3,-3,0,minecraft:dirt)
B(-3,-2,0,minecraft:dirt)
B(-3,-1,0,minecraft:cobblestone)
B(-3,0,0,minecraft:stone)
B(-3,1,0,minecraft:cobblestone)
B(-3,2,0,minecraft:cobblestone)
B(-3,3,0,minecraft:cobblestone)
B(-3,4,0,minecraft:oak_log)
B(-3,5,0,minecraft:oak_log)
B(-3,6,0,minecraft:oak_log)
B(-3,7,0,minecraft:spruce_slab[type=double,waterlogged=false])
B(-3,-6,1,minecraft:dirt)
B(-3,-5,1,minecraft:dirt)
B(-3,-4,1,minecraft:dirt)
B(-3,-3,1,minecraft:dirt)
B(-3,-2,1,minecraft:dirt)
B(-3,-1,1,minecraft:cobblestone)
B(-3,0,1,minecraft:cobblestone)
B(-3,1,1,minecraft:cobblestone)
B(-3,2,1,minecraft:cobblestone)
B(-3,3,1,minecraft:cobblestone)
B(-3,4,1,minecraft:dark_oak_planks)
B(-3,5,1,minecraft:dark_oak_planks)
B(-3,6,1,minecraft:dark_oak_planks)
B(-3,7,1,minecraft:spruce_slab[type=double,waterlogged=false])
B(-3,-6,2,minecraft:grass_block)
B(-3,-5,2,minecraft:grass_block)
B(-3,-4,2,minecraft:dirt)
B(-3,-3,2,minecraft:dirt)
B(-3,-2,2,minecraft:dirt)
B(-3,-1,2,minecraft:spruce_log)
B(-3,0,2,minecraft:spruce_log)
B(-3,1,2,minecraft:spruce_log)
B(-3,2,2,minecraft:spruce_log)
B(-3,3,2,minecraft:spruce_log)
B(-3,4,2,minecraft:spruce_log)
B(-3,5,2,minecraft:spruce_log)
B(-3,6,2,minecraft:spruce_log[axis=x])
B(-3,7,2,minecraft:spruce_slab[type=double,waterlogged=false])
B(-3,-6,3,minecraft:dirt)
B(-3,-5,3,minecraft:dirt)
B(-3,-4,3,minecraft:dirt)
B(-3,-3,3,minecraft:dirt)
B(-3,-2,3,minecraft:dirt)
B(-3,-1,3,minecraft:dirt)
B(-3,0,3,minecraft:stone)
B(-3,1,3,minecraft:polished_andesite)
B(-3,2,3,minecraft:polished_andesite)
B(-3,3,3,minecraft:stone_brick_stairs[facing=east,half=bottom,shape=straight,waterlogged=false])
B(-3,7,3,minecraft:spruce_slab)
B(-3,-6,4,minecraft:dirt)
B(-3,-5,4,minecraft:dirt)
B(-3,-4,4,minecraft:dirt)
B(-3,-3,4,minecraft:dirt)
B(-3,-2,4,minecraft:dirt)
B(-3,-1,4,minecraft:dirt)
B(-3,0,4,minecraft:spruce_log)
B(-3,1,4,minecraft:spruce_log)
B(-3,2,4,minecraft:spruce_log)
B(-3,3,4,minecraft:dark_oak_stairs[facing=east,half=bottom,shape=straight,waterlogged=false])
B(-3,-6,5,minecraft:dirt)
B(-3,-5,5,minecraft:dirt)
B(-3,-4,5,minecraft:grass_block)
B(-3,-3,5,minecraft:dirt)
B(-3,-2,5,minecraft:dirt)
B(-3,-1,5,minecraft:dirt)
B(-3,0,5,minecraft:hay_block)
B(-3,-6,6,minecraft:grass_block)
B(-3,-5,6,minecraft:dirt)
B(-3,-4,6,minecraft:dirt)
B(-3,-3,6,minecraft:grass_block)
B(-3,-2,6,minecraft:grass_block)
B(-3,-1,6,minecraft:farmland[moisture=5])
B(-3,0,6,minecraft:wheat[age=7])
B(-3,-6,7,minecraft:dirt)
B(-3,-5,7,minecraft:grass_block)
B(-3,-4,7,minecraft:dirt)
B(-3,-3,7,minecraft:grass_block)
B(-3,-2,7,minecraft:grass_block)
B(-3,-1,7,minecraft:farmland[moisture=4])
B(-3,0,7,minecraft:wheat[age=7])
B(-3,-6,8,minecraft:dirt)
B(-3,-5,8,minecraft:dirt)
B(-3,-4,8,minecraft:grass_block)
B(-3,-3,8,minecraft:dirt)
B(-3,-2,8,minecraft:grass_block)
B(-3,-1,8,minecraft:farmland[moisture=4])
B(-3,0,8,minecraft:wheat[age=7])
B(-3,-6,9,minecraft:dirt)
B(-3,-5,9,minecraft:dirt)
B(-3,-4,9,minecraft:dirt)
B(-3,-3,9,minecraft:dirt)
B(-3,-2,9,minecraft:grass_block)
B(-3,-1,9,minecraft:farmland[moisture=3])
B(-3,0,9,minecraft:wheat[age=7])
B(-3,-6,10,minecraft:grass_block)
B(-3,-5,10,minecraft:grass_block)
B(-3,-4,10,minecraft:dirt)
B(-3,-3,10,minecraft:dirt)
B(-3,-2,10,minecraft:grass_block)
B(-3,-1,10,minecraft:farmland[moisture=3])
B(-3,0,10,minecraft:wheat[age=7])
B(-3,-6,11,minecraft:dirt)
B(-3,-5,11,minecraft:dirt)
B(-3,-4,11,minecraft:dirt)
B(-3,-3,11,minecraft:dirt)
B(-3,-2,11,minecraft:grass_block)
B(-3,-6,12,minecraft:dirt)
B(-3,-5,12,minecraft:dirt)
B(-3,-4,12,minecraft:dirt)
B(-3,-3,12,minecraft:dirt)
B(-3,-2,12,minecraft:grass_block)
B(-3,-6,13,minecraft:dirt)
B(-3,-5,13,minecraft:dirt)
B(-3,-4,13,minecraft:dirt)
B(-3,-3,13,minecraft:dirt)
B(-3,-2,13,minecraft:grass_block)
B(-3,-6,14,minecraft:dirt)
B(-3,-5,14,minecraft:dirt)
B(-3,-4,14,minecraft:dirt)
B(-3,-3,14,minecraft:grass_block)
B(-3,-6,15,minecraft:dirt)
B(-3,-5,15,minecraft:dirt)
B(-3,-4,15,minecraft:grass_block)
B(-2,-6,-16,minecraft:dirt)
B(-2,-5,-16,minecraft:dirt)
B(-2,-4,-16,minecraft:grass_block)
B(-2,-6,-15,minecraft:dirt)
B(-2,-5,-15,minecraft:dirt)
B(-2,-4,-15,minecraft:dirt)
B(-2,-3,-15,minecraft:grass_block)
B(-2,-6,-14,minecraft:dirt)
B(-2,-5,-14,minecraft:dirt)
B(-2,-4,-14,minecraft:dirt)
B(-2,-3,-14,minecraft:grass_block)
B(-2,-6,-13,minecraft:dirt)
B(-2,-5,-13,minecraft:dirt)
B(-2,-4,-13,minecraft:grass_block)
B(-2,-3,-13,minecraft:grass_block)
B(-2,-6,-12,minecraft:dirt)
B(-2,-5,-12,minecraft:dirt)
B(-2,-4,-12,minecraft:dirt)
B(-2,-3,-12,minecraft:dirt)
B(-2,-2,-12,minecraft:grass_block)
B(-2,-6,-11,minecraft:dirt)
B(-2,-5,-11,minecraft:grass_block)
B(-2,-4,-11,minecraft:dirt)
B(-2,-3,-11,minecraft:dirt)
B(-2,-2,-11,minecraft:dirt)
B(-2,-1,-11,minecraft:dirt)
B(-2,0,-11,minecraft:hay_block)
B(-2,1,-11,minecraft:hay_block)
B(-2,-6,-10,minecraft:dirt)
B(-2,-5,-10,minecraft:dirt)
B(-2,-4,-10,minecraft:dirt)
B(-2,-3,-10,minecraft:grass_block)
B(-2,-2,-10,minecraft:grass_block)
B(-2,-1,-10,minecraft:farmland[moisture=3])
B(-2,0,-10,minecraft:wheat[age=7])
B(-2,-6,-9,minecraft:grass_block)
B(-2,-5,-9,minecraft:dirt)
B(-2,-4,-9,minecraft:dirt)
B(-2,-3,-9,minecraft:grass_block)
B(-2,-2,-9,minecraft:grass_block)
B(-2,-1,-9,minecraft:farmland[moisture=5])
B(-2,0,-9,minecraft:wheat[age=7])
B(-2,-6,-8,minecraft:dirt)
B(-2,-5,-8,minecraft:grass_block)
B(-2,-4,-8,minecraft:dirt)
B(-2,-3,-8,minecraft:dirt)
B(-2,-2,-8,minecraft:grass_block)
B(-2,-1,-8,minecraft:farmland[moisture=5])
B(-2,0,-8,minecraft:wheat[age=7])
B(-2,-6,-7,minecraft:dirt)
B(-2,-5,-7,minecraft:dirt)
B(-2,-4,-7,minecraft:grass_block)
B(-2,-3,-7,minecraft:grass_block)
B(-2,-2,-7,minecraft:grass_block)
B(-2,-1,-7,minecraft:farmland[moisture=4])
B(-2,0,-7,minecraft:wheat[age=7])
B(-2,-6,-6,minecraft:dirt)
B(-2,-5,-6,minecraft:dirt)
B(-2,-4,-6,minecraft:dirt)
B(-2,-3,-6,minecraft:dirt)
B(-2,-2,-6,minecraft:grass_block)
B(-2,-1,-6,minecraft:farmland[moisture=6])
B(-2,0,-6,minecraft:wheat[age=7])
B(-2,-6,-5,minecraft:dirt)
B(-2,-5,-5,minecraft:dirt)
B(-2,-4,-5,minecraft:dirt)
B(-2,-3,-5,minecraft:dirt)
B(-2,-2,-5,minecraft:dirt)
B(-2,-1,-5,minecraft:dirt)
B(-2,0,-5,minecraft:spruce_log)
B(-2,1,-5,minecraft:spruce_log)
B(-2,2,-5,minecraft:spruce_log)
B(-2,3,-5,minecraft:dark_oak_stairs[facing=south,half=bottom,shape=outer_left,waterlogged=false])
B(-2,-6,-4,minecraft:grass_block)
B(-2,-5,-4,minecraft:dirt)
B(-2,-4,-4,minecraft:dirt)
B(-2,-3,-4,minecraft:dirt)
B(-2,-2,-4,minecraft:dirt)
B(-2,-1,-4,minecraft:dirt)
B(-2,0,-4,minecraft:cobblestone)
B(-2,1,-4,minecraft:cobblestone)
B(-2,2,-4,minecraft:cobblestone)
B(-2,3,-4,minecraft:stone_brick_stairs[facing=east,half=bottom,shape=inner_right,waterlogged=false])
B(-2,7,-4,minecraft:spruce_slab)
B(-2,-6,-3,minecraft:dirt)
B(-2,-5,-3,minecraft:dirt)
B(-2,-4,-3,minecraft:grass_block)
B(-2,-3,-3,minecraft:dirt)
B(-2,-2,-3,minecraft:dirt)
B(-2,-1,-3,minecraft:cobblestone)
B(-2,0,-3,minecraft:cobblestone)
B(-2,1,-3,minecraft:cobblestone)
B(-2,2,-3,minecraft:cobblestone)
B(-2,3,-3,minecraft:cobblestone)
B(-2,4,-3,minecraft:oak_log)
B(-2,5,-3,minecraft:oak_log)
B(-2,6,-3,minecraft:oak_log)
B(-2,7,-3,minecraft:spruce_slab[type=double,waterlogged=false])
B(-2,19,-3,minecraft:dark_oak_stairs[facing=south,half=top,shape=straight,waterlogged=false])
B(-2,20,-3,minecraft:dark_oak_stairs[facing=south,half=bottom,shape=straight,waterlogged=false])
B(-2,-6,-2,minecraft:dirt)
B(-2,-5,-2,minecraft:dirt)
B(-2,-4,-2,minecraft:dirt)
B(-2,-3,-2,minecraft:dirt)
B(-2,-2,-2,minecraft:cobblestone)
B(-2,-1,-2,minecraft:dark_oak_slab)
B(-2,0,-2,minecraft:ladder[facing=south,waterlogged=false])
B(-2,1,-2,minecraft:ladder[facing=south,waterlogged=false])
B(-2,2,-2,minecraft:ladder[facing=south,waterlogged=false])
B(-2,3,-2,minecraft:ladder[facing=south,waterlogged=false])
B(-2,4,-2,minecraft:ladder[facing=south,waterlogged=false])
B(-2,6,-2,minecraft:spruce_log[axis=x])
B(-2,7,-2,minecraft:oak_log)
B(-2,8,-2,minecraft:spruce_stairs[facing=south,half=bottom,shape=outer_left,waterlogged=false])
B(-2,12,-2,minecraft:spruce_log[axis=x])
B(-2,19,-2,minecraft:dark_oak_stairs[facing=north,half=top,shape=straight,waterlogged=false])
B(-2,20,-2,minecraft:spruce_log[axis=x])
B(-2,21,-2,minecraft:dark_oak_planks)
B(-2,22,-2,minecraft:dark_oak_stairs[facing=south,half=bottom,shape=straight,waterlogged=false])
B(-2,-6,-1,minecraft:dirt)
B(-2,-5,-1,minecraft:dirt)
B(-2,-4,-1,minecraft:dirt)
B(-2,-3,-1,minecraft:dirt)
B(-2,-2,-1,minecraft:cobblestone)
B(-2,-1,-1,minecraft:dark_oak_slab)
B(-2,7,-1,minecraft:dark_oak_planks)
B(-2,8,-1,minecraft:spruce_stairs[facing=east,half=bottom,shape=straight,waterlogged=false])
B(-2,22,-1,minecraft:spruce_stairs[facing=north,half=top,shape=straight,waterlogged=false])
B(-2,23,-1,minecraft:dark_oak_planks)
B(-2,24,-1,minecraft:dark_oak_stairs[facing=south,half=bottom,shape=straight,waterlogged=false])
B(-2,-6,0,minecraft:dirt)
B(-2,-5,0,minecraft:dirt)
B(-2,-4,0,minecraft:dirt)
B(-2,-3,0,minecraft:grass_block)
B(-2,-2,0,minecraft:glowstone)
B(-2,-1,0,minecraft:dark_oak_slab)
B(-2,0,0,minecraft:spruce_log[axis=x])
B(-2,7,0,minecraft:oak_log)
B(-2,8,0,minecraft:spruce_stairs[facing=east,half=bottom,shape=straight,waterlogged=false])
B(-2,23,0,minecraft:dark_oak_stairs[facing=east,half=top,shape=straight,waterlogged=false])
B(-2,24,0,minecraft:spruce_planks)
B(-2,25,0,minecraft:dark_oak_slab)
B(-2,-6,1,minecraft:dirt)
B(-2,-5,1,minecraft:dirt)
B(-2,-4,1,minecraft:grass_block)
B(-2,-3,1,minecraft:grass_block)
B(-2,-2,1,minecraft:cobblestone)
B(-2,-1,1,minecraft:dark_oak_slab)
B(-2,7,1,minecraft:dark_oak_planks)
B(-2,8,1,minecraft:spruce_stairs[facing=east,half=bottom,shape=straight,waterlogged=false])
B(-2,22,1,minecraft:spruce_stairs[facing=south,half=top,shape=straight,waterlogged=false])
B(-2,23,1,minecraft:dark_oak_planks)
B(-2,24,1,minecraft:dark_oak_stairs[facing=east,half=bottom,shape=straight,waterlogged=false])
B(-2,-6,2,minecraft:grass_block)
B(-2,-5,2,minecraft:dirt)
B(-2,-4,2,minecraft:grass_block)
B(-2,-3,2,minecraft:dirt)
B(-2,-2,2,minecraft:cobblestone)
B(-2,-1,2,minecraft:dark_oak_slab)
B(-2,0,2,minecraft:ladder)
B(-2,1,2,minecraft:ladder)
B(-2,2,2,minecraft:ladder)
B(-2,3,2,minecraft:ladder)
B(-2,4,2,minecraft:ladder)
B(-2,6,2,minecraft:spruce_log[axis=x])
B(-2,7,2,minecraft:oak_log)
B(-2,8,2,minecraft:spruce_stairs[facing=east,half=bottom,shape=straight,waterlogged=false])
B(-2,12,2,minecraft:spruce_log[axis=x])
B(-2,19,2,minecraft:dark_oak_stairs[facing=south,half=top,shape=straight,waterlogged=false])
B(-2,20,2,minecraft:spruce_log[axis=x])
B(-2,21,2,minecraft:dark_oak_planks)
B(-2,22,2,minecraft:dark_oak_stairs[facing=east,half=bottom,shape=straight,waterlogged=false])
B(-2,-6,3,minecraft:dirt)
B(-2,-5,3,minecraft:grass_block)
B(-2,-4,3,minecraft:dirt)
B(-2,-3,3,minecraft:dirt)
B(-2,-2,3,minecraft:dirt)
B(-2,-1,3,minecraft:cobblestone)
B(-2,0,3,minecraft:cobblestone)
B(-2,1,3,minecraft:cobblestone)
B(-2,2,3,minecraft:cobblestone)
B(-2,3,3,minecraft:cobblestone)
B(-2,4,3,minecraft:oak_log)
B(-2,5,3,minecraft:oak_log)
B(-2,6,3,minecraft:oak_log)
B(-2,7,3,minecraft:spruce_slab[type=double,waterlogged=false])
B(-2,19,3,minecraft:dark_oak_stairs[facing=north,half=top,shape=straight,waterlogged=false])
B(-2,20,3,minecraft:dark_oak_stairs[facing=east,half=bottom,shape=straight,waterlogged=false])
B(-2,-6,4,minecraft:dirt)
B(-2,-5,4,minecraft:dirt)
B(-2,-4,4,minecraft:dirt)
B(-2,-3,4,minecraft:dirt)
B(-2,-2,4,minecraft:dirt)
B(-2,-1,4,minecraft:grass_block)
B(-2,0,4,minecraft:stone)
B(-2,1,4,minecraft:polished_andesite)
B(-2,2,4,minecraft:polished_andesite)
B(-2,3,4,minecraft:stone_brick_stairs[facing=east,half=bottom,shape=straight,waterlogged=false])
B(-2,7,4,minecraft:spruce_slab)
B(-2,-6,5,minecraft:grass_block)
B(-2,-5,5,minecraft:dirt)
B(-2,-4,5,minecraft:dirt)
B(-2,-3,5,minecraft:dirt)
B(-2,-2,5,minecraft:dirt)
B(-2,-1,5,minecraft:dirt)
B(-2,0,5,minecraft:spruce_log)
B(-2,1,5,minecraft:spruce_log)
B(-2,2,5,minecraft:spruce_log)
B(-2,3,5,minecraft:dark_oak_stairs[facing=east,half=bottom,shape=straight,waterlogged=false])
B(-2,-6,6,minecraft:dirt)
B(-2,-5,6,minecraft:grass_block)
B(-2,-4,6,minecraft:dirt)
B(-2,-3,6,minecraft:grass_block)
B(-2,-2,6,minecraft:dirt)
B(-2,-1,6,minecraft:grass_block)
B(-2,3,6,minecraft:spruce_slab)
B(-2,-6,7,minecraft:dirt)
B(-2,-5,7,minecraft:dirt)
B(-2,-4,7,minecraft:dirt)
B(-2,-3,7,minecraft:dirt)
B(-2,-2,7,minecraft:dirt)
B(-2,-1,7,minecraft:grass_block)
B(-2,2,7,minecraft:spruce_slab[type=top,waterlogged=false])
B(-2,-6,8,minecraft:dirt)
B(-2,-5,8,minecraft:dirt)
B(-2,-4,8,minecraft:dirt)
B(-2,-3,8,minecraft:dirt)
B(-2,-2,8,minecraft:dirt)
B(-2,-1,8,minecraft:dirt)
B(-2,0,8,minecraft:spruce_log)
B(-2,1,8,minecraft:spruce_log)
B(-2,2,8,minecraft:spruce_slab)
B(-2,-6,9,minecraft:dirt)
B(-2,-5,9,minecraft:grass_block)
B(-2,-4,9,minecraft:dirt)
B(-2,-3,9,minecraft:dirt)
B(-2,-2,9,minecraft:grass_block)
B(-2,-1,9,minecraft:grass_block)
B(-2,1,9,minecraft:spruce_slab[type=top,waterlogged=false])
B(-2,-6,10,minecraft:dirt)
B(-2,-5,10,minecraft:dirt)
B(-2,-4,10,minecraft:dirt)
B(-2,-3,10,minecraft:dirt)
B(-2,-2,10,minecraft:grass_block)
B(-2,-1,10,minecraft:dirt)
B(-2,0,10,minecraft:spruce_log)
B(-2,1,10,minecraft:spruce_slab)
B(-2,-6,11,minecraft:grass_block)
B(-2,-5,11,minecraft:dirt)
B(-2,-4,11,minecraft:dirt)
B(-2,-3,11,minecraft:dirt)
B(-2,-2,11,minecraft:grass_block)
B(-2,-1,11,minecraft:farmland[moisture=4])
B(-2,0,11,minecraft:wheat[age=7])
B(-2,-6,12,minecraft:grass_block)
B(-2,-5,12,minecraft:dirt)
B(-2,-4,12,minecraft:grass_block)
B(-2,-3,12,minecraft:dirt)
B(-2,-2,12,minecraft:grass_block)
B(-2,-6,13,minecraft:dirt)
B(-2,-5,13,minecraft:dirt)
B(-2,-4,13,minecraft:dirt)
B(-2,-3,13,minecraft:grass_block)
B(-2,-6,14,minecraft:dirt)
B(-2,-5,14,minecraft:dirt)
B(-2,-4,14,minecraft:dirt)
B(-2,-3,14,minecraft:grass_block)
B(-2,-6,15,minecraft:dirt)
B(-2,-5,15,minecraft:grass_block)
B(-2,-4,15,minecraft:grass_block)
B(-1,-6,-16,minecraft:dirt)
B(-1,-5,-16,minecraft:dirt)
B(-1,-4,-16,minecraft:grass_block)
B(-1,-6,-15,minecraft:dirt)
B(-1,-5,-15,minecraft:grass_block)
B(-1,-4,-15,minecraft:grass_block)
B(-1,-3,-15,minecraft:grass_block)
B(-1,-6,-14,minecraft:grass_block)
B(-1,-5,-14,minecraft:dirt)
B(-1,-4,-14,minecraft:dirt)
B(-1,-3,-14,minecraft:grass_block)
B(-1,-6,-13,minecraft:dirt)
B(-1,-5,-13,minecraft:dirt)
B(-1,-4,-13,minecraft:dirt)
B(-1,-3,-13,minecraft:dirt)
B(-1,-2,-13,minecraft:grass_block)
B(-1,-1,-13,minecraft:grass_block)
B(-1,0,-13,minecraft:dark_oak_fence[east=true,north=false,south=true,waterlogged=false,west=false])
B(-1,-6,-12,minecraft:dirt)
B(-1,-5,-12,minecraft:dirt)
B(-1,-4,-12,minecraft:dirt)
B(-1,-3,-12,minecraft:dirt)
B(-1,-2,-12,minecraft:dirt)
B(-1,-1,-12,minecraft:grass_block)
B(-1,0,-12,minecraft:dark_oak_fence[east=true,north=true,south=true,waterlogged=false,west=false])
B(-1,-6,-11,minecraft:dirt)
B(-1,-5,-11,minecraft:dirt)
B(-1,-4,-11,minecraft:dirt)
B(-1,-3,-11,minecraft:dirt)
B(-1,-2,-11,minecraft:grass_block)
B(-1,-1,-11,minecraft:dirt)
B(-1,0,-11,minecraft:hay_block)
B(-1,-6,-10,minecraft:dirt)
B(-1,-5,-10,minecraft:grass_block)
B(-1,-4,-10,minecraft:dirt)
B(-1,-3,-10,minecraft:dirt)
B(-1,-2,-10,minecraft:grass_block)
B(-1,-1,-10,minecraft:farmland[moisture=6])
B(-1,0,-10,minecraft:wheat[age=7])
B(-1,-6,-9,minecraft:dirt)
B(-1,-5,-9,minecraft:dirt)
B(-1,-4,-9,minecraft:dirt)
B(-1,-3,-9,minecraft:dirt)
B(-1,-2,-9,minecraft:grass_block)
B(-1,-1,-9,minecraft:farmland[moisture=5])
B(-1,0,-9,minecraft:wheat[age=7])
B(-1,-6,-8,minecraft:dirt)
B(-1,-5,-8,minecraft:dirt)
B(-1,-4,-8,minecraft:grass_block)
B(-1,-3,-8,minecraft:dirt)
B(-1,-2,-8,minecraft:grass_block)
B(-1,-1,-8,minecraft:farmland[moisture=6])
B(-1,0,-8,minecraft:wheat[age=7])
B(-1,-6,-7,minecraft:dirt)
B(-1,-5,-7,minecraft:dirt)
B(-1,-4,-7,minecraft:grass_block)
B(-1,-3,-7,minecraft:dirt)
B(-1,-2,-7,minecraft:dirt)
B(-1,-1,-7,minecraft:dirt)
B(-1,0,-7,minecraft:stone_bricks)
B(-1,1,-7,minecraft:spruce_fence[east=true,north=false,south=false,waterlogged=false,west=false])
B(-1,-6,-6,minecraft:dirt)
B(-1,-5,-6,minecraft:dirt)
B(-1,-4,-6,minecraft:dirt)
B(-1,-3,-6,minecraft:dirt)
B(-1,-2,-6,minecraft:dirt)
B(-1,-1,-6,minecraft:grass_block)
B(-1,0,-6,minecraft:dark_oak_stairs[facing=east,half=bottom,shape=straight,waterlogged=false])
B(-1,-6,-5,minecraft:grass_block)
B(-1,-5,-5,minecraft:dirt)
B(-1,-4,-5,minecraft:dirt)
B(-1,-3,-5,minecraft:grass_block)
B(-1,-2,-5,minecraft:dirt)
B(-1,-1,-5,minecraft:dirt)
B(-1,0,-5,minecraft:cobblestone)
B(-1,1,-5,minecraft:cobblestone)
B(-1,2,-5,minecraft:cobblestone)
B(-1,3,-5,minecraft:stone_brick_stairs[facing=south,half=bottom,shape=straight,waterlogged=false])
B(-1,6,-5,minecraft:spruce_log[axis=z])
B(-1,7,-5,minecraft:spruce_slab)
B(-1,-6,-4,minecraft:grass_block)
B(-1,-5,-4,minecraft:dirt)
B(-1,-4,-4,minecraft:dirt)
B(-1,-3,-4,minecraft:dirt)
B(-1,-2,-4,minecraft:dirt)
B(-1,-1,-4,minecraft:grass_block)
B(-1,0,-4,minecraft:spruce_log)
B(-1,1,-4,minecraft:spruce_log)
B(-1,2,-4,minecraft:spruce_log)
B(-1,3,-4,minecraft:spruce_log)
B(-1,4,-4,minecraft:spruce_log)
B(-1,5,-4,minecraft:spruce_log)
B(-1,6,-4,minecraft:spruce_log[axis=z])
B(-1,7,-4,minecraft:spruce_slab[type=double,waterlogged=false])
B(-1,-6,-3,minecraft:dirt)
B(-1,-5,-3,minecraft:dirt)
B(-1,-4,-3,minecraft:grass_block)
B(-1,-3,-3,minecraft:dirt)
B(-1,-2,-3,minecraft:cobblestone)
B(-1,-1,-3,minecraft:cobblestone)
B(-1,0,-3,minecraft:cobblestone)
B(-1,1,-3,minecraft:dark_oak_slab)
B(-1,3,-3,minecraft:dark_oak_stairs[facing=north,half=top,shape=straight,waterlogged=false])
B(-1,4,-3,minecraft:hay_block)
B(-1,6,-3,minecraft:spruce_log[axis=z])
B(-1,7,-3,minecraft:oak_log)
B(-1,8,-3,minecraft:spruce_stairs[facing=east,half=bottom,shape=outer_right,waterlogged=false])
B(-1,12,-3,minecraft:spruce_log[axis=z])
B(-1,19,-3,minecraft:spruce_stairs[facing=south,half=top,shape=straight,waterlogged=false])
B(-1,20,-3,minecraft:spruce_log[axis=z])
B(-1,-6,-2,minecraft:dirt)
B(-1,-5,-2,minecraft:dirt)
B(-1,-4,-2,minecraft:dirt)
B(-1,-3,-2,minecraft:grass_block)
B(-1,-2,-2,minecraft:hopper[enabled=true,facing=south])
B(-1,0,-2,minecraft:cobblestone_stairs[facing=north,half=top,shape=straight,waterlogged=false])
B(-1,1,-2,minecraft:dark_oak_slab)
B(-1,6,-2,minecraft:spruce_log[axis=z])
B(-1,7,-2,minecraft:spruce_log)
B(-1,8,-2,minecraft:spruce_log)
B(-1,9,-2,minecraft:spruce_log)
B(-1,10,-2,minecraft:spruce_log)
B(-1,11,-2,minecraft:spruce_log)
B(-1,12,-2,minecraft:spruce_log)
B(-1,13,-2,minecraft:spruce_log)
B(-1,14,-2,minecraft:spruce_log)
B(-1,15,-2,minecraft:spruce_log)
B(-1,16,-2,minecraft:spruce_log)
B(-1,17,-2,minecraft:spruce_log)
B(-1,18,-2,minecraft:spruce_log)
B(-1,19,-2,minecraft:spruce_log)
B(-1,20,-2,minecraft:spruce_log)
B(-1,21,-2,minecraft:spruce_planks)
B(-1,22,-2,minecraft:spruce_stairs[facing=south,half=bottom,shape=straight,waterlogged=false])
B(-1,-6,-1,minecraft:dirt)
B(-1,-5,-1,minecraft:dirt)
B(-1,-4,-1,minecraft:dirt)
B(-1,-3,-1,minecraft:grass_block)
B(-1,-2,-1,minecraft:hopper[enabled=true,facing=south])
B(-1,1,-1,minecraft:dark_oak_slab)
B(-1,6,-1,minecraft:spruce_log[axis=z])
B(-1,7,-1,minecraft:dark_oak_planks)
B(-1,8,-1,minecraft:dark_oak_planks)
B(-1,9,-1,minecraft:dark_oak_planks)
B(-1,10,-1,minecraft:dark_oak_planks)
B(-1,11,-1,minecraft:dark_oak_planks)
B(-1,12,-1,minecraft:spruce_log[axis=z])
B(-1,13,-1,minecraft:dark_oak_planks)
B(-1,14,-1,minecraft:dark_oak_planks)
B(-1,15,-1,minecraft:dark_oak_planks)
B(-1,16,-1,minecraft:dark_oak_planks)
B(-1,17,-1,minecraft:dark_oak_planks)
B(-1,18,-1,minecraft:dark_oak_planks)
B(-1,19,-1,minecraft:dark_oak_planks)
B(-1,20,-1,minecraft:spruce_log[axis=z])
B(-1,21,-1,minecraft:dark_oak_planks)
B(-1,22,-1,minecraft:dark_oak_planks)
B(-1,23,-1,minecraft:spruce_planks)
B(-1,24,-1,minecraft:spruce_stairs[facing=south,half=bottom,shape=straight,waterlogged=false])
B(-1,-6,0,minecraft:dirt)
B(-1,-5,0,minecraft:dirt)
B(-1,-4,0,minecraft:grass_block)
B(-1,-3,0,minecraft:grass_block)
B(-1,-2,0,minecraft:hopper[enabled=true,facing=east])
B(-1,0,0,minecraft:spruce_log[axis=x])
B(-1,1,0,minecraft:dark_oak_slab)
B(-1,6,0,minecraft:spruce_log[axis=z])
B(-1,7,0,minecraft:oak_log)
B(-1,8,0,minecraft:oak_log)
B(-1,9,0,minecraft:spruce_slab)
B(-1,10,0,minecraft:spruce_stairs[facing=east,half=top,shape=straight,waterlogged=false])
B(-1,11,0,minecraft:oak_log)
B(-1,12,0,minecraft:spruce_log[axis=z])
B(-1,13,0,minecraft:oak_log)
B(-1,14,0,minecraft:spruce_slab)
B(-1,15,0,minecraft:spruce_stairs[facing=east,half=bottom,shape=straight,waterlogged=false])
B(-1,16,0,minecraft:oak_fence[east=false,north=true,south=true,waterlogged=false,west=false])
B(-1,17,0,minecraft:spruce_stairs[facing=east,half=top,shape=straight,waterlogged=false])
B(-1,18,0,minecraft:oak_log)
B(-1,19,0,minecraft:oak_log)
B(-1,20,0,minecraft:spruce_log[axis=z])
B(-1,21,0,minecraft:oak_log)
B(-1,22,0,minecraft:oak_log)
B(-1,23,0,minecraft:oak_log)
B(-1,24,0,minecraft:spruce_planks)
B(-1,25,0,minecraft:dark_oak_slab)
B(-1,-6,1,minecraft:dirt)
B(-1,-5,1,minecraft:dirt)
B(-1,-4,1,minecraft:dirt)
B(-1,-3,1,minecraft:grass_block)
B(-1,-2,1,minecraft:hopper[enabled=true,facing=north])
B(-1,1,1,minecraft:dark_oak_slab)
B(-1,6,1,minecraft:spruce_log[axis=z])
B(-1,7,1,minecraft:dark_oak_planks)
B(-1,8,1,minecraft:dark_oak_planks)
B(-1,9,1,minecraft:dark_oak_planks)
B(-1,10,1,minecraft:dark_oak_planks)
B(-1,11,1,minecraft:dark_oak_planks)
B(-1,12,1,minecraft:spruce_log[axis=z])
B(-1,13,1,minecraft:dark_oak_planks)
B(-1,14,1,minecraft:dark_oak_planks)
B(-1,15,1,minecraft:dark_oak_planks)
B(-1,16,1,minecraft:dark_oak_planks)
B(-1,17,1,minecraft:dark_oak_planks)
B(-1,18,1,minecraft:dark_oak_planks)
B(-1,19,1,minecraft:dark_oak_planks)
B(-1,20,1,minecraft:spruce_log[axis=z])
B(-1,21,1,minecraft:dark_oak_planks)
B(-1,22,1,minecraft:dark_oak_planks)
B(-1,23,1,minecraft:spruce_planks)
B(-1,24,1,minecraft:spruce_stairs[facing=east,half=bottom,shape=straight,waterlogged=false])
B(-1,-6,2,minecraft:dirt)
B(-1,-5,2,minecraft:dirt)
B(-1,-4,2,minecraft:dirt)
B(-1,-3,2,minecraft:grass_block)
B(-1,-2,2,minecraft:hopper[enabled=true,facing=north])
B(-1,0,2,minecraft:cobblestone_stairs[facing=south,half=top,shape=straight,waterlogged=false])
B(-1,1,2,minecraft:dark_oak_slab)
B(-1,6,2,minecraft:spruce_log[axis=z])
B(-1,7,2,minecraft:spruce_log)
B(-1,8,2,minecraft:spruce_log)
B(-1,9,2,minecraft:spruce_log)
B(-1,10,2,minecraft:spruce_log)
B(-1,11,2,minecraft:spruce_log)
B(-1,12,2,minecraft:spruce_log)
B(-1,13,2,minecraft:spruce_log)
B(-1,14,2,minecraft:spruce_log)
B(-1,15,2,minecraft:spruce_log)
B(-1,16,2,minecraft:spruce_log)
B(-1,17,2,minecraft:spruce_log)
B(-1,18,2,minecraft:spruce_log)
B(-1,19,2,minecraft:spruce_log)
B(-1,20,2,minecraft:spruce_log)
B(-1,21,2,minecraft:spruce_planks)
B(-1,22,2,minecraft:spruce_stairs[facing=east,half=bottom,shape=straight,waterlogged=false])
B(-1,-6,3,minecraft:grass_block)
B(-1,-5,3,minecraft:grass_block)
B(-1,-4,3,minecraft:dirt)
B(-1,-3,3,minecraft:dirt)
B(-1,-2,3,minecraft:dirt)
B(-1,-1,3,minecraft:cobblestone)
B(-1,0,3,minecraft:cobblestone)
B(-1,1,3,minecraft:dark_oak_slab)
B(-1,3,3,minecraft:dark_oak_stairs[facing=south,half=top,shape=straight,waterlogged=false])
B(-1,4,3,minecraft:hay_block[axis=z])
B(-1,6,3,minecraft:spruce_log[axis=z])
B(-1,7,3,minecraft:oak_log)
B(-1,8,3,minecraft:spruce_stairs[facing=east,half=bottom,shape=straight,waterlogged=false])
B(-1,12,3,minecraft:spruce_log[axis=z])
B(-1,19,3,minecraft:spruce_stairs[facing=north,half=top,shape=straight,waterlogged=false])
B(-1,20,3,minecraft:spruce_log[axis=z])
B(-1,-6,4,minecraft:grass_block)
B(-1,-5,4,minecraft:dirt)
B(-1,-4,4,minecraft:grass_block)
B(-1,-3,4,minecraft:dirt)
B(-1,-2,4,minecraft:dirt)
B(-1,-1,4,minecraft:dirt)
B(-1,0,4,minecraft:stone)
B(-1,1,4,minecraft:spruce_log)
B(-1,2,4,minecraft:spruce_log)
B(-1,3,4,minecraft:spruce_log)
B(-1,4,4,minecraft:spruce_log)
B(-1,5,4,minecraft:spruce_log)
B(-1,6,4,minecraft:spruce_log[axis=z])
B(-1,7,4,minecraft:spruce_slab[type=double,waterlogged=false])
B(-1,-6,5,minecraft:dirt)
B(-1,-5,5,minecraft:dirt)
B(-1,-4,5,minecraft:grass_block)
B(-1,-3,5,minecraft:dirt)
B(-1,-2,5,minecraft:dirt)
B(-1,-1,5,minecraft:dirt)
B(-1,0,5,minecraft:cobblestone)
B(-1,1,5,minecraft:cobblestone)
B(-1,2,5,minecraft:cobblestone)
B(-1,3,5,minecraft:stone_brick_stairs[facing=east,half=bottom,shape=straight,waterlogged=false])
B(-1,6,5,minecraft:spruce_log[axis=z])
B(-1,7,5,minecraft:spruce_slab)
B(-1,-6,6,minecraft:dirt)
B(-1,-5,6,minecraft:dirt)
B(-1,-4,6,minecraft:grass_block)
B(-1,-3,6,minecraft:dirt)
B(-1,-2,6,minecraft:dirt)
B(-1,-1,6,minecraft:dirt)
B(-1,0,6,minecraft:hay_block)
B(-1,3,6,minecraft:spruce_slab)
B(-1,-6,7,minecraft:dirt)
B(-1,-5,7,minecraft:dirt)
B(-1,-4,7,minecraft:grass_block)
B(-1,-3,7,minecraft:dirt)
B(-1,-2,7,minecraft:dirt)
B(-1,-1,7,minecraft:grass_block)
B(-1,0,7,minecraft:hay_block)
B(-1,2,7,minecraft:spruce_slab[type=top,waterlogged=false])
B(-1,-6,8,minecraft:dirt)
B(-1,-5,8,minecraft:grass_block)
B(-1,-4,8,minecraft:grass_block)
B(-1,-3,8,minecraft:dirt)
B(-1,-2,8,minecraft:dirt)
B(-1,-1,8,minecraft:grass_block)
B(-1,2,8,minecraft:spruce_slab)
B(-1,-6,9,minecraft:dirt)
B(-1,-5,9,minecraft:dirt)
B(-1,-4,9,minecraft:dirt)
B(-1,-3,9,minecraft:dirt)
B(-1,-2,9,minecraft:dirt)
B(-1,-1,9,minecraft:grass_block)
B(-1,0,9,minecraft:hay_block)
B(-1,1,9,minecraft:spruce_slab[type=top,waterlogged=false])
B(-1,-6,10,minecraft:dirt)
B(-1,-5,10,minecraft:dirt)
B(-1,-4,10,minecraft:dirt)
B(-1,-3,10,minecraft:dirt)
B(-1,-2,10,minecraft:dirt)
B(-1,-1,10,minecraft:grass_block)
B(-1,0,10,minecraft:dark_oak_fence[east=true,north=true,south=false,waterlogged=false,west=true])
B(-1,1,10,minecraft:spruce_slab)
B(-1,-6,11,minecraft:dirt)
B(-1,-5,11,minecraft:dirt)
B(-1,-4,11,minecraft:dirt)
B(-1,-3,11,minecraft:dirt)
B(-1,-2,11,minecraft:grass_block)
B(-1,-1,11,minecraft:farmland[moisture=4])
B(-1,0,11,minecraft:wheat[age=7])
B(-1,-6,12,minecraft:dirt)
B(-1,-5,12,minecraft:grass_block)
B(-1,-4,12,minecraft:grass_block)
B(-1,-3,12,minecraft:grass_block)
B(-1,-2,12,minecraft:grass_block)
B(-1,-6,13,minecraft:dirt)
B(-1,-5,13,minecraft:dirt)
B(-1,-4,13,minecraft:grass_block)
B(-1,-3,13,minecraft:dirt)
B(-1,-2,13,minecraft:grass_block)
B(-1,-6,14,minecraft:dirt)
B(-1,-5,14,minecraft:dirt)
B(-1,-4,14,minecraft:dirt)
B(-1,-3,14,minecraft:grass_block)
B(-1,-6,15,minecraft:dirt)
B(-1,-5,15,minecraft:dirt)
B(-1,-4,15,minecraft:grass_block)
B(0,-6,-16,minecraft:grass_block)
B(0,-5,-16,minecraft:dirt)
B(0,-4,-16,minecraft:dirt)
B(0,-3,-16,minecraft:grass_block)
B(0,-6,-15,minecraft:dirt)
B(0,-5,-15,minecraft:dirt)
B(0,-4,-15,minecraft:dirt)
B(0,-3,-15,minecraft:grass_block)
B(0,-6,-14,minecraft:dirt)
B(0,-5,-14,minecraft:dirt)
B(0,-4,-14,minecraft:dirt)
B(0,-3,-14,minecraft:grass_block)
B(0,-2,-14,minecraft:grass_block)
B(0,-6,-13,minecraft:dirt)
B(0,-5,-13,minecraft:dirt)
B(0,-4,-13,minecraft:dirt)
B(0,-3,-13,minecraft:dirt)
B(0,-2,-13,minecraft:dirt)
B(0,-1,-13,minecraft:grass_block)
B(0,0,-13,minecraft:dark_oak_fence[east=true,north=false,south=true,waterlogged=false,west=true])
B(0,-6,-12,minecraft:dirt)
B(0,-5,-12,minecraft:dirt)
B(0,-4,-12,minecraft:dirt)
B(0,-3,-12,minecraft:dirt)
B(0,-2,-12,minecraft:dirt)
B(0,-1,-12,minecraft:grass_block)
B(0,0,-12,minecraft:hay_block)
B(0,-6,-11,minecraft:dirt)
B(0,-5,-11,minecraft:dirt)
B(0,-4,-11,minecraft:dirt)
B(0,-3,-11,minecraft:dirt)
B(0,-2,-11,minecraft:grass_block)
B(0,-1,-11,minecraft:farmland[moisture=3])
B(0,0,-11,minecraft:wheat[age=7])
B(0,-6,-10,minecraft:dirt)
B(0,-5,-10,minecraft:dirt)
B(0,-4,-10,minecraft:dirt)
B(0,-3,-10,minecraft:dirt)
B(0,-2,-10,minecraft:grass_block)
B(0,-1,-10,minecraft:farmland[moisture=4])
B(0,0,-10,minecraft:wheat[age=7])
B(0,-6,-9,minecraft:dirt)
B(0,-5,-9,minecraft:dirt)
B(0,-4,-9,minecraft:dirt)
B(0,-3,-9,minecraft:dirt)
B(0,-2,-9,minecraft:grass_block)
B(0,-1,-9,minecraft:farmland[moisture=4])
B(0,0,-9,minecraft:wheat[age=7])
B(0,-6,-8,minecraft:dirt)
B(0,-5,-8,minecraft:dirt)
B(0,-4,-8,minecraft:dirt)
B(0,-3,-8,minecraft:dirt)
B(0,-2,-8,minecraft:grass_block)
B(0,-1,-8,minecraft:farmland[moisture=2])
B(0,0,-8,minecraft:wheat[age=7])
B(0,-6,-7,minecraft:grass_block)
B(0,-5,-7,minecraft:dirt)
B(0,-4,-7,minecraft:dirt)
B(0,-3,-7,minecraft:grass_block)
B(0,-2,-7,minecraft:dirt)
B(0,-1,-7,minecraft:grass_block)
B(0,0,-7,minecraft:stone_brick_stairs[facing=south,half=top,shape=straight,waterlogged=false])
B(0,1,-7,minecraft:spruce_fence[east=true,north=false,south=false,waterlogged=false,west=true])
B(0,-6,-6,minecraft:dirt)
B(0,-5,-6,minecraft:dirt)
B(0,-4,-6,minecraft:dirt)
B(0,-3,-6,minecraft:dirt)
B(0,-2,-6,minecraft:dirt)
B(0,-1,-6,minecraft:dirt)
B(0,0,-6,minecraft:dark_oak_planks)
B(0,-6,-5,minecraft:dirt)
B(0,-5,-5,minecraft:dirt)
B(0,-4,-5,minecraft:grass_block)
B(0,-3,-5,minecraft:dirt)
B(0,-2,-5,minecraft:dirt)
B(0,-1,-5,minecraft:grass_block)
B(0,0,-5,minecraft:dark_oak_planks)
B(0,1,-5,minecraft:cobblestone_stairs[facing=south,half=bottom,shape=straight,waterlogged=false])
B(0,2,-5,minecraft:cobblestone_stairs[facing=south,half=top,shape=straight,waterlogged=false])
B(0,3,-5,minecraft:dark_oak_slab)
B(0,7,-5,minecraft:spruce_slab)
B(0,-6,-4,minecraft:dirt)
B(0,-5,-4,minecraft:dirt)
B(0,-4,-4,minecraft:dirt)
B(0,-3,-4,minecraft:dirt)
B(0,-2,-4,minecraft:dirt)
B(0,-1,-4,minecraft:dirt)
B(0,0,-4,minecraft:cobblestone)
B(0,1,-4,minecraft:cobblestone)
B(0,2,-4,minecraft:cobblestone)
B(0,3,-4,minecraft:spruce_log[axis=x])
B(0,4,-4,minecraft:dark_oak_planks)
B(0,5,-4,minecraft:dark_oak_planks)
B(0,6,-4,minecraft:dark_oak_planks)
B(0,7,-4,minecraft:spruce_slab[type=double,waterlogged=false])
B(0,-6,-3,minecraft:dirt)
B(0,-5,-3,minecraft:dirt)
B(0,-4,-3,minecraft:dirt)
B(0,-3,-3,minecraft:dirt)
B(0,-2,-3,minecraft:dirt)
B(0,-1,-3,minecraft:cobblestone)
B(0,0,-3,minecraft:cobblestone)
B(0,3,-3,minecraft:dark_oak_stairs[facing=north,half=top,shape=straight,waterlogged=false])
B(0,4,-3,minecraft:hay_block[axis=x])
B(0,5,-3,minecraft:hay_block)
B(0,6,-3,minecraft:hay_block)
B(0,7,-3,minecraft:oak_log)
B(0,8,-3,minecraft:spruce_stairs[facing=south,half=bottom,shape=straight,waterlogged=false])
B(0,19,-3,minecraft:spruce_stairs[facing=south,half=top,shape=straight,waterlogged=false])
B(0,20,-3,minecraft:dark_oak_planks)
B(0,21,-3,minecraft:dark_oak_planks)
B(0,22,-3,minecraft:spruce_stairs[facing=east,half=bottom,shape=straight,waterlogged=false])
B(0,-6,-2,minecraft:dirt)
B(0,-5,-2,minecraft:dirt)
B(0,-4,-2,minecraft:grass_block)
B(0,-3,-2,minecraft:dirt)
B(0,-2,-2,minecraft:cobblestone)
B(0,-1,-2,minecraft:dark_oak_slab)
B(0,6,-2,minecraft:spruce_log[axis=x])
B(0,7,-2,minecraft:oak_log)
B(0,8,-2,minecraft:oak_log)
B(0,9,-2,minecraft:dark_oak_planks)
B(0,10,-2,minecraft:dark_oak_planks)
B(0,11,-2,minecraft:dark_oak_planks)
B(0,12,-2,minecraft:spruce_log[axis=x])
B(0,13,-2,minecraft:dark_oak_planks)
B(0,14,-2,minecraft:dark_oak_planks)
B(0,15,-2,minecraft:dark_oak_planks)
B(0,16,-2,minecraft:dark_oak_planks)
B(0,17,-2,minecraft:dark_oak_planks)
B(0,18,-2,minecraft:dark_oak_planks)
B(0,19,-2,minecraft:dark_oak_planks)
B(0,20,-2,minecraft:spruce_log[axis=x])
B(0,21,-2,minecraft:dark_oak_planks)
B(0,22,-2,minecraft:spruce_stairs[facing=east,half=bottom,shape=inner_right,waterlogged=false])
B(0,-6,-1,minecraft:grass_block)
B(0,-5,-1,minecraft:dirt)
B(0,-4,-1,minecraft:dirt)
B(0,-3,-1,minecraft:dirt)
B(0,-2,-1,minecraft:cobblestone)
B(0,-1,-1,minecraft:dark_oak_slab)
B(0,6,-1,minecraft:spruce_log[axis=z])
B(0,12,-1,minecraft:cobblestone_wall[east=none,north=low,south=low,up=true,waterlogged=false,west=low])
B(0,13,-1,minecraft:torch)
B(0,15,-1,minecraft:dark_oak_slab[type=top,waterlogged=false])
B(0,16,-1,minecraft:ladder[facing=south,waterlogged=false])
B(0,17,-1,minecraft:ladder[facing=south,waterlogged=false])
B(0,18,-1,minecraft:ladder[facing=south,waterlogged=false])
B(0,19,-1,minecraft:ladder[facing=south,waterlogged=false])
B(0,20,-1,minecraft:ladder[facing=south,waterlogged=false])
B(0,21,-1,minecraft:ladder[facing=south,waterlogged=false])
B(0,23,-1,minecraft:spruce_planks)
B(0,24,-1,minecraft:spruce_stairs[facing=south,half=bottom,shape=straight,waterlogged=false])
B(0,-6,0,minecraft:dirt)
B(0,-5,0,minecraft:dirt)
B(0,-4,0,minecraft:dirt)
B(0,-3,0,minecraft:grass_block)
B(0,-2,0,minecraft:hopper)
B(0,-1,0,minecraft:dark_oak_slab)
B(0,0,0,minecraft:spruce_log[axis=x])
B(0,1,0,minecraft:spruce_log)
B(0,2,0,minecraft:spruce_log)
B(0,3,0,minecraft:spruce_log)
B(0,4,0,minecraft:spruce_log)
B(0,5,0,minecraft:spruce_log)
B(0,6,0,minecraft:spruce_log[axis=z])
B(0,7,0,minecraft:spruce_log)
B(0,8,0,minecraft:spruce_log)
B(0,9,0,minecraft:spruce_log)
B(0,10,0,minecraft:spruce_log)
B(0,11,0,minecraft:spruce_log)
B(0,12,0,minecraft:spruce_log)
B(0,13,0,minecraft:spruce_log)
B(0,14,0,minecraft:spruce_log)
B(0,15,0,minecraft:spruce_log)
B(0,20,0,minecraft:spruce_log[axis=x])
B(0,23,0,minecraft:oak_trapdoor[facing=north,half=top,open=false,powered=false,waterlogged=false])
B(0,24,0,minecraft:spruce_planks)
B(0,25,0,minecraft:dark_oak_slab)
B(0,-6,1,minecraft:dirt)
B(0,-5,1,minecraft:dirt)
B(0,-4,1,minecraft:grass_block)
B(0,-3,1,minecraft:dirt)
B(0,-2,1,minecraft:cobblestone)
B(0,-1,1,minecraft:dark_oak_slab)
B(0,6,1,minecraft:spruce_log[axis=z])
B(0,12,1,minecraft:cobblestone_wall[east=none,north=low,south=low,up=true,waterlogged=false,west=low])
B(0,13,1,minecraft:torch)
B(0,15,1,minecraft:dark_oak_slab[type=top,waterlogged=false])
B(0,16,1,minecraft:ladder)
B(0,17,1,minecraft:ladder)
B(0,18,1,minecraft:ladder)
B(0,19,1,minecraft:ladder)
B(0,20,1,minecraft:ladder)
B(0,21,1,minecraft:ladder)
B(0,23,1,minecraft:spruce_planks)
B(0,24,1,minecraft:spruce_stairs[facing=east,half=bottom,shape=straight,waterlogged=false])
B(0,-6,2,minecraft:dirt)
B(0,-5,2,minecraft:dirt)
B(0,-4,2,minecraft:dirt)
B(0,-3,2,minecraft:dirt)
B(0,-2,2,minecraft:cobblestone)
B(0,-1,2,minecraft:dark_oak_slab)
B(0,6,2,minecraft:spruce_log[axis=x])
B(0,7,2,minecraft:oak_log)
B(0,8,2,minecraft:oak_log)
B(0,9,2,minecraft:dark_oak_planks)
B(0,10,2,minecraft:dark_oak_planks)
B(0,11,2,minecraft:dark_oak_planks)
B(0,12,2,minecraft:spruce_log[axis=x])
B(0,13,2,minecraft:dark_oak_planks)
B(0,14,2,minecraft:dark_oak_planks)
B(0,15,2,minecraft:dark_oak_planks)
B(0,16,2,minecraft:dark_oak_planks)
B(0,17,2,minecraft:dark_oak_planks)
B(0,18,2,minecraft:dark_oak_planks)
B(0,19,2,minecraft:dark_oak_planks)
B(0,20,2,minecraft:spruce_log[axis=x])
B(0,21,2,minecraft:dark_oak_planks)
B(0,22,2,minecraft:spruce_stairs[facing=east,half=bottom,shape=straight,waterlogged=false])
B(0,-6,3,minecraft:dirt)
B(0,-5,3,minecraft:dirt)
B(0,-4,3,minecraft:dirt)
B(0,-3,3,minecraft:dirt)
B(0,-2,3,minecraft:dirt)
B(0,-1,3,minecraft:cobblestone)
B(0,0,3,minecraft:cobblestone)
B(0,1,3,minecraft:hay_block[axis=z])
B(0,3,3,minecraft:dark_oak_stairs[facing=south,half=top,shape=straight,waterlogged=false])
B(0,4,3,minecraft:hay_block)
B(0,5,3,minecraft:hay_block[axis=x])
B(0,7,3,minecraft:oak_log)
B(0,8,3,minecraft:spruce_stairs[facing=east,half=bottom,shape=straight,waterlogged=false])
B(0,19,3,minecraft:spruce_stairs[facing=north,half=top,shape=straight,waterlogged=false])
B(0,20,3,minecraft:dark_oak_planks)
B(0,21,3,minecraft:dark_oak_planks)
B(0,22,3,minecraft:spruce_stairs[facing=east,half=bottom,shape=straight,waterlogged=false])
B(0,-6,4,minecraft:dirt)
B(0,-5,4,minecraft:dirt)
B(0,-4,4,minecraft:dirt)
B(0,-3,4,minecraft:dirt)
B(0,-2,4,minecraft:dirt)
B(0,-1,4,minecraft:dirt)
B(0,0,4,minecraft:stone)
B(0,1,4,minecraft:cobblestone)
B(0,2,4,minecraft:cobblestone)
B(0,3,4,minecraft:cobblestone)
B(0,4,4,minecraft:dark_oak_planks)
B(0,5,4,minecraft:dark_oak_planks)
B(0,6,4,minecraft:dark_oak_planks)
B(0,7,4,minecraft:spruce_slab[type=double,waterlogged=false])
B(0,-6,5,minecraft:dirt)
B(0,-5,5,minecraft:dirt)
B(0,-4,5,minecraft:dirt)
B(0,-3,5,minecraft:dirt)
B(0,-2,5,minecraft:dirt)
B(0,-1,5,minecraft:dirt)
B(0,0,5,minecraft:cobblestone_stairs[facing=east,half=bottom,shape=straight,waterlogged=false])
B(0,1,5,minecraft:cobblestone_stairs[facing=north,half=top,shape=straight,waterlogged=false])
B(0,2,5,minecraft:cobblestone_stairs[facing=east,half=bottom,shape=straight,waterlogged=false])
B(0,7,5,minecraft:spruce_slab)
B(0,-6,6,minecraft:dirt)
B(0,-5,6,minecraft:grass_block)
B(0,-4,6,minecraft:dirt)
B(0,-3,6,minecraft:dirt)
B(0,-2,6,minecraft:grass_block)
B(0,-1,6,minecraft:dirt)
B(0,0,6,minecraft:hay_block[axis=x])
B(0,1,6,minecraft:hay_block[axis=z])
B(0,2,6,minecraft:hay_block[axis=z])
B(0,3,6,minecraft:spruce_slab)
B(0,-6,7,minecraft:grass_block)
B(0,-5,7,minecraft:grass_block)
B(0,-4,7,minecraft:dirt)
B(0,-3,7,minecraft:dirt)
B(0,-2,7,minecraft:dirt)
B(0,-1,7,minecraft:dirt)
B(0,0,7,minecraft:hay_block[axis=x])
B(0,1,7,minecraft:hay_block)
B(0,2,7,minecraft:spruce_slab[type=top,waterlogged=false])
B(0,-6,8,minecraft:dirt)
B(0,-5,8,minecraft:dirt)
B(0,-4,8,minecraft:dirt)
B(0,-3,8,minecraft:grass_block)
B(0,-2,8,minecraft:dirt)
B(0,-1,8,minecraft:dirt)
B(0,0,8,minecraft:hay_block)
B(0,2,8,minecraft:spruce_slab)
B(0,-6,9,minecraft:dirt)
B(0,-5,9,minecraft:dirt)
B(0,-4,9,minecraft:dirt)
B(0,-3,9,minecraft:dirt)
B(0,-2,9,minecraft:dirt)
B(0,-1,9,minecraft:grass_block)
B(0,1,9,minecraft:spruce_slab[type=top,waterlogged=false])
B(0,-6,10,minecraft:dirt)
B(0,-5,10,minecraft:dirt)
B(0,-4,10,minecraft:dirt)
B(0,-3,10,minecraft:dirt)
B(0,-2,10,minecraft:dirt)
B(0,-1,10,minecraft:grass_block)
B(0,0,10,minecraft:dark_oak_fence[east=true,north=false,south=false,waterlogged=false,west=true])
B(0,1,10,minecraft:spruce_slab)
B(0,-6,11,minecraft:dirt)
B(0,-5,11,minecraft:grass_block)
B(0,-4,11,minecraft:grass_block)
B(0,-3,11,minecraft:dirt)
B(0,-2,11,minecraft:grass_block)
B(0,-1,11,minecraft:farmland[moisture=7])
B(0,0,11,minecraft:wheat[age=7])
B(0,-6,12,minecraft:dirt)
B(0,-5,12,minecraft:dirt)
B(0,-4,12,minecraft:grass_block)
B(0,-3,12,minecraft:dirt)
B(0,-2,12,minecraft:grass_block)
B(0,-1,12,minecraft:farmland[moisture=6])
B(0,0,12,minecraft:wheat[age=7])
B(0,-6,13,minecraft:dirt)
B(0,-5,13,minecraft:dirt)
B(0,-4,13,minecraft:dirt)
B(0,-3,13,minecraft:dirt)
B(0,-2,13,minecraft:grass_block)
B(0,-6,14,minecraft:dirt)
B(0,-5,14,minecraft:dirt)
B(0,-4,14,minecraft:dirt)
B(0,-3,14,minecraft:grass_block)
B(0,-6,15,minecraft:dirt)
B(0,-5,15,minecraft:grass_block)
B(0,-4,15,minecraft:grass_block)
B(1,-6,-16,minecraft:dirt)
B(1,-5,-16,minecraft:dirt)
B(1,-4,-16,minecraft:dirt)
B(1,-3,-16,minecraft:grass_block)
B(1,-6,-15,minecraft:grass_block)
B(1,-5,-15,minecraft:dirt)
B(1,-4,-15,minecraft:dirt)
B(1,-3,-15,minecraft:dirt)
B(1,-2,-15,minecraft:grass_block)
B(1,-6,-14,minecraft:dirt)
B(1,-5,-14,minecraft:grass_block)
B(1,-4,-14,minecraft:dirt)
B(1,-3,-14,minecraft:grass_block)
B(1,-2,-14,minecraft:grass_block)
B(1,-6,-13,minecraft:dirt)
B(1,-5,-13,minecraft:dirt)
B(1,-4,-13,minecraft:grass_block)
B(1,-3,-13,minecraft:dirt)
B(1,-2,-13,minecraft:grass_block)
B(1,-1,-13,minecraft:grass_block)
B(1,0,-13,minecraft:dark_oak_fence[east=false,north=false,south=false,waterlogged=false,west=true])
B(1,-6,-12,minecraft:dirt)
B(1,-5,-12,minecraft:grass_block)
B(1,-4,-12,minecraft:dirt)
B(1,-3,-12,minecraft:dirt)
B(1,-2,-12,minecraft:grass_block)
B(1,-1,-12,minecraft:farmland[moisture=6])
B(1,0,-12,minecraft:wheat[age=7])
B(1,-6,-11,minecraft:grass_block)
B(1,-5,-11,minecraft:dirt)
B(1,-4,-11,minecraft:dirt)
B(1,-3,-11,minecraft:grass_block)
B(1,-2,-11,minecraft:grass_block)
B(1,-1,-11,minecraft:farmland[moisture=5])
B(1,0,-11,minecraft:wheat[age=7])
B(1,-6,-10,minecraft:dirt)
B(1,-5,-10,minecraft:dirt)
B(1,-4,-10,minecraft:dirt)
B(1,-3,-10,minecraft:grass_block)
B(1,-2,-10,minecraft:grass_block)
B(1,-1,-10,minecraft:farmland[moisture=4])
B(1,0,-10,minecraft:wheat[age=7])
B(1,-6,-9,minecraft:dirt)
B(1,-5,-9,minecraft:dirt)
B(1,-4,-9,minecraft:dirt)
B(1,-3,-9,minecraft:dirt)
B(1,-2,-9,minecraft:grass_block)
B(1,-1,-9,minecraft:farmland[moisture=6])
B(1,0,-9,minecraft:wheat[age=7])
B(1,-6,-8,minecraft:dirt)
B(1,-5,-8,minecraft:dirt)
B(1,-4,-8,minecraft:dirt)
B(1,-3,-8,minecraft:dirt)
B(1,-2,-8,minecraft:grass_block)
B(1,-1,-8,minecraft:farmland[moisture=5])
B(1,0,-8,minecraft:wheat[age=7])
B(1,-6,-7,minecraft:dirt)
B(1,-5,-7,minecraft:dirt)
B(1,-4,-7,minecraft:dirt)
B(1,-3,-7,minecraft:dirt)
B(1,-2,-7,minecraft:dirt)
B(1,-1,-7,minecraft:grass_block)
B(1,0,-7,minecraft:stone_brick_stairs[facing=south,half=top,shape=straight,waterlogged=false])
B(1,1,-7,minecraft:spruce_fence[east=true,north=false,south=false,waterlogged=false,west=true])
B(1,-6,-6,minecraft:dirt)
B(1,-5,-6,minecraft:dirt)
B(1,-4,-6,minecraft:dirt)
B(1,-3,-6,minecraft:dirt)
B(1,-2,-6,minecraft:grass_block)
B(1,-1,-6,minecraft:dirt)
B(1,0,-6,minecraft:dark_oak_planks)
B(1,-6,-5,minecraft:dirt)
B(1,-5,-5,minecraft:dirt)
B(1,-4,-5,minecraft:dirt)
B(1,-3,-5,minecraft:dirt)
B(1,-2,-5,minecraft:dirt)
B(1,-1,-5,minecraft:dirt)
B(1,0,-5,minecraft:cobblestone)
B(1,3,-5,minecraft:stone_brick_stairs[facing=south,half=bottom,shape=straight,waterlogged=false])
B(1,7,-5,minecraft:spruce_slab)
B(1,-6,-4,minecraft:dirt)
B(1,-5,-4,minecraft:dirt)
B(1,-4,-4,minecraft:dirt)
B(1,-3,-4,minecraft:grass_block)
B(1,-2,-4,minecraft:grass_block)
B(1,-1,-4,minecraft:grass_block)
B(1,0,-4,minecraft:cobblestone)
B(1,3,-4,minecraft:spruce_log[axis=x])
B(1,4,-4,minecraft:oak_log)
B(1,5,-4,minecraft:oak_log)
B(1,6,-4,minecraft:oak_log)
B(1,7,-4,minecraft:spruce_slab[type=double,waterlogged=false])
B(1,-6,-3,minecraft:dirt)
B(1,-5,-3,minecraft:dirt)
B(1,-4,-3,minecraft:dirt)
B(1,-3,-3,minecraft:dirt)
B(1,-2,-3,minecraft:cobblestone)
B(1,-1,-3,minecraft:cobblestone)
B(1,0,-3,minecraft:cobblestone)
B(1,3,-3,minecraft:dark_oak_stairs[facing=north,half=top,shape=straight,waterlogged=false])
B(1,4,-3,minecraft:hay_block[axis=x])
B(1,5,-3,minecraft:hay_block[axis=z])
B(1,7,-3,minecraft:oak_log)
B(1,8,-3,minecraft:spruce_stairs[facing=south,half=bottom,shape=straight,waterlogged=false])
B(1,19,-3,minecraft:spruce_stairs[facing=south,half=top,shape=straight,waterlogged=false])
B(1,20,-3,minecraft:spruce_slab)
B(1,22,-3,minecraft:spruce_slab[type=top,waterlogged=false])
B(1,23,-3,minecraft:spruce_slab)
B(1,-6,-2,minecraft:dirt)
B(1,-5,-2,minecraft:dirt)
B(1,-4,-2,minecraft:grass_block)
B(1,-3,-2,minecraft:grass_block)
B(1,-2,-2,minecraft:stone_brick_stairs[facing=east,half=bottom,shape=straight,waterlogged=false])
B(1,6,-2,minecraft:spruce_log[axis=x])
B(1,7,-2,minecraft:oak_log)
B(1,8,-2,minecraft:oak_log)
B(1,9,-2,minecraft:spruce_slab)
B(1,10,-2,minecraft:spruce_stairs[facing=south,half=top,shape=straight,waterlogged=false])
B(1,11,-2,minecraft:oak_log)
B(1,12,-2,minecraft:spruce_log[axis=x])
B(1,13,-2,minecraft:oak_log)
B(1,14,-2,minecraft:spruce_slab)
B(1,15,-2,minecraft:spruce_stairs[facing=south,half=bottom,shape=straight,waterlogged=false])
B(1,16,-2,minecraft:oak_fence[east=true,north=false,south=false,waterlogged=false,west=true])
B(1,17,-2,minecraft:spruce_stairs[facing=south,half=top,shape=straight,waterlogged=false])
B(1,18,-2,minecraft:oak_log)
B(1,19,-2,minecraft:oak_log)
B(1,22,-2,minecraft:spruce_slab[type=top,waterlogged=false])
B(1,23,-2,minecraft:spruce_slab)
B(1,-6,-1,minecraft:dirt)
B(1,-5,-1,minecraft:grass_block)
B(1,-4,-1,minecraft:dirt)
B(1,-3,-1,minecraft:dirt)
B(1,-2,-1,minecraft:dark_oak_slab)
B(1,-1,-1,minecraft:stone_brick_stairs[facing=south,half=top,shape=straight,waterlogged=false])
B(1,0,-1,minecraft:dark_oak_slab[type=double,waterlogged=false])
B(1,1,-1,minecraft:stone_brick_stairs[facing=south,half=bottom,shape=straight,waterlogged=false])
B(1,19,-1,minecraft:cobblestone_stairs[facing=south,half=top,shape=straight,waterlogged=false])
B(1,20,-1,minecraft:dark_oak_planks)
B(1,21,-1,minecraft:cobblestone_stairs[facing=south,half=bottom,shape=straight,waterlogged=false])
B(1,23,-1,minecraft:spruce_planks)
B(1,24,-1,minecraft:spruce_stairs[facing=south,half=bottom,shape=straight,waterlogged=false])
B(1,-6,0,minecraft:dirt)
B(1,-5,0,minecraft:grass_block)
B(1,-4,0,minecraft:grass_block)
B(1,-3,0,minecraft:grass_block)
B(1,-2,0,minecraft:dark_oak_slab)
B(1,-1,0,minecraft:dark_oak_slab[type=double,waterlogged=false])
B(1,0,0,minecraft:spruce_log[axis=x])
B(1,1,0,minecraft:dark_oak_slab[type=double,waterlogged=false])
B(1,3,0,minecraft:dark_oak_stairs[facing=west,half=top,shape=straight,waterlogged=false])
B(1,4,0,minecraft:ladder[facing=east,waterlogged=false])
B(1,5,0,minecraft:ladder[facing=east,waterlogged=false])
B(1,6,0,minecraft:ladder[facing=east,waterlogged=false])
B(1,7,0,minecraft:ladder[facing=east,waterlogged=false])
B(1,8,0,minecraft:ladder[facing=east,waterlogged=false])
B(1,9,0,minecraft:ladder[facing=east,waterlogged=false])
B(1,10,0,minecraft:ladder[facing=east,waterlogged=false])
B(1,11,0,minecraft:ladder[facing=east,waterlogged=false])
B(1,12,0,minecraft:ladder[facing=east,waterlogged=false])
B(1,13,0,minecraft:ladder[facing=east,waterlogged=false])
B(1,14,0,minecraft:ladder[facing=east,waterlogged=false])
B(1,15,0,minecraft:ladder[facing=east,waterlogged=false])
B(1,19,0,minecraft:dark_oak_planks)
B(1,20,0,minecraft:spruce_log[axis=x])
B(1,21,0,minecraft:dark_oak_planks)
B(1,23,0,minecraft:oak_trapdoor[facing=north,half=top,open=false,powered=false,waterlogged=false])
B(1,24,0,minecraft:glowstone)
B(1,25,0,minecraft:dark_oak_slab)
B(1,-6,1,minecraft:dirt)
B(1,-5,1,minecraft:dirt)
B(1,-4,1,minecraft:dirt)
B(1,-3,1,minecraft:dirt)
B(1,-2,1,minecraft:dark_oak_slab)
B(1,-1,1,minecraft:stone_brick_stairs[facing=north,half=top,shape=straight,waterlogged=false])
B(1,0,1,minecraft:dark_oak_slab[type=double,waterlogged=false])
B(1,1,1,minecraft:stone_brick_stairs[facing=east,half=bottom,shape=straight,waterlogged=false])
B(1,19,1,minecraft:cobblestone_stairs[facing=north,half=top,shape=straight,waterlogged=false])
B(1,20,1,minecraft:dark_oak_planks)
B(1,21,1,minecraft:cobblestone_stairs[facing=east,half=bottom,shape=straight,waterlogged=false])
B(1,23,1,minecraft:spruce_planks)
B(1,24,1,minecraft:spruce_stairs[facing=east,half=bottom,shape=straight,waterlogged=false])
B(1,-6,2,minecraft:dirt)
B(1,-5,2,minecraft:dirt)
B(1,-4,2,minecraft:dirt)
B(1,-3,2,minecraft:grass_block)
B(1,-2,2,minecraft:stone_brick_stairs[facing=south,half=bottom,shape=straight,waterlogged=false])
B(1,6,2,minecraft:spruce_log[axis=x])
B(1,7,2,minecraft:oak_log)
B(1,8,2,minecraft:oak_log)
B(1,9,2,minecraft:spruce_slab)
B(1,10,2,minecraft:spruce_stairs[facing=north,half=top,shape=straight,waterlogged=false])
B(1,11,2,minecraft:oak_log)
B(1,12,2,minecraft:spruce_log[axis=x])
B(1,13,2,minecraft:oak_log)
B(1,14,2,minecraft:spruce_slab)
B(1,15,2,minecraft:spruce_stairs[facing=east,half=bottom,shape=straight,waterlogged=false])
B(1,16,2,minecraft:oak_fence[east=true,north=false,south=false,waterlogged=false,west=true])
B(1,17,2,minecraft:spruce_stairs[facing=north,half=top,shape=straight,waterlogged=false])
B(1,18,2,minecraft:oak_log)
B(1,19,2,minecraft:oak_log)
B(1,22,2,minecraft:spruce_slab[type=top,waterlogged=false])
B(1,23,2,minecraft:spruce_slab)
B(1,-6,3,minecraft:dirt)
B(1,-5,3,minecraft:grass_block)
B(1,-4,3,minecraft:dirt)
B(1,-3,3,minecraft:dirt)
B(1,-2,3,minecraft:cobblestone)
B(1,-1,3,minecraft:cobblestone)
B(1,0,3,minecraft:cobblestone)
B(1,1,3,minecraft:hay_block[axis=x])
B(1,2,3,minecraft:hay_block)
B(1,3,3,minecraft:dark_oak_stairs[facing=south,half=top,shape=straight,waterlogged=false])
B(1,4,3,minecraft:hay_block[axis=x])
B(1,5,3,minecraft:hay_block[axis=z])
B(1,6,3,minecraft:hay_block)
B(1,7,3,minecraft:oak_log)
B(1,8,3,minecraft:spruce_stairs[facing=east,half=bottom,shape=straight,waterlogged=false])
B(1,19,3,minecraft:spruce_stairs[facing=north,half=top,shape=straight,waterlogged=false])
B(1,20,3,minecraft:spruce_slab)
B(1,22,3,minecraft:spruce_slab[type=top,waterlogged=false])
B(1,23,3,minecraft:spruce_slab)
B(1,-6,4,minecraft:dirt)
B(1,-5,4,minecraft:dirt)
B(1,-4,4,minecraft:dirt)
B(1,-3,4,minecraft:dirt)
B(1,-2,4,minecraft:dirt)
B(1,-1,4,minecraft:dirt)
B(1,0,4,minecraft:stone)
B(1,1,4,minecraft:cobblestone)
B(1,2,4,minecraft:cobblestone)
B(1,3,4,minecraft:cobblestone)
B(1,4,4,minecraft:oak_log)
B(1,5,4,minecraft:oak_log)
B(1,6,4,minecraft:oak_log)
B(1,7,4,minecraft:spruce_slab[type=double,waterlogged=false])
B(1,-6,5,minecraft:grass_block)
B(1,-5,5,minecraft:dirt)
B(1,-4,5,minecraft:dirt)
B(1,-3,5,minecraft:grass_block)
B(1,-2,5,minecraft:dirt)
B(1,-1,5,minecraft:dirt)
B(1,0,5,minecraft:cobblestone)
B(1,1,5,minecraft:cobblestone)
B(1,2,5,minecraft:cobblestone)
B(1,3,5,minecraft:stone_brick_stairs[facing=east,half=bottom,shape=straight,waterlogged=false])
B(1,7,5,minecraft:spruce_slab)
B(1,-6,6,minecraft:dirt)
B(1,-5,6,minecraft:dirt)
B(1,-4,6,minecraft:dirt)
B(1,-3,6,minecraft:dirt)
B(1,-2,6,minecraft:dirt)
B(1,-1,6,minecraft:dirt)
B(1,0,6,minecraft:hay_block)
B(1,3,6,minecraft:spruce_slab)
B(1,-6,7,minecraft:dirt)
B(1,-5,7,minecraft:dirt)
B(1,-4,7,minecraft:dirt)
B(1,-3,7,minecraft:dirt)
B(1,-2,7,minecraft:dirt)
B(1,-1,7,minecraft:dirt)
B(1,0,7,minecraft:hay_block)
B(1,2,7,minecraft:spruce_slab[type=top,waterlogged=false])
B(1,-6,8,minecraft:dirt)
B(1,-5,8,minecraft:dirt)
B(1,-4,8,minecraft:dirt)
B(1,-3,8,minecraft:dirt)
B(1,-2,8,minecraft:dirt)
B(1,-1,8,minecraft:grass_block)
B(1,0,8,minecraft:hay_block)
B(1,2,8,minecraft:spruce_slab)
B(1,-6,9,minecraft:dirt)
B(1,-5,9,minecraft:grass_block)
B(1,-4,9,minecraft:dirt)
B(1,-3,9,minecraft:dirt)
B(1,-2,9,minecraft:dirt)
B(1,-1,9,minecraft:grass_block)
B(1,1,9,minecraft:spruce_slab[type=top,waterlogged=false])
B(1,-6,10,minecraft:dirt)
B(1,-5,10,minecraft:dirt)
B(1,-4,10,minecraft:dirt)
B(1,-3,10,minecraft:dirt)
B(1,-2,10,minecraft:grass_block)
B(1,-1,10,minecraft:dirt)
B(1,0,10,minecraft:spruce_log)
B(1,1,10,minecraft:spruce_slab)
B(1,-6,11,minecraft:dirt)
B(1,-5,11,minecraft:dirt)
B(1,-4,11,minecraft:dirt)
B(1,-3,11,minecraft:dirt)
B(1,-2,11,minecraft:grass_block)
B(1,-1,11,minecraft:farmland[moisture=4])
B(1,0,11,minecraft:wheat[age=7])
B(1,-6,12,minecraft:dirt)
B(1,-5,12,minecraft:dirt)
B(1,-4,12,minecraft:dirt)
B(1,-3,12,minecraft:dirt)
B(1,-2,12,minecraft:grass_block)
B(1,-1,12,minecraft:farmland[moisture=7])
B(1,0,12,minecraft:wheat[age=7])
B(1,-6,13,minecraft:grass_block)
B(1,-5,13,minecraft:dirt)
B(1,-4,13,minecraft:dirt)
B(1,-3,13,minecraft:dirt)
B(1,-2,13,minecraft:grass_block)
B(1,-6,14,minecraft:dirt)
B(1,-5,14,minecraft:dirt)
B(1,-4,14,minecraft:dirt)
B(1,-3,14,minecraft:grass_block)
B(1,-2,14,minecraft:grass_block)
B(1,-6,15,minecraft:dirt)
B(1,-5,15,minecraft:dirt)
B(1,-4,15,minecraft:dirt)
B(1,-3,15,minecraft:grass_block)
B(2,-6,-16,minecraft:dirt)
B(2,-5,-16,minecraft:dirt)
B(2,-4,-16,minecraft:dirt)
B(2,-3,-16,minecraft:grass_block)
B(2,-6,-15,minecraft:dirt)
B(2,-5,-15,minecraft:dirt)
B(2,-4,-15,minecraft:dirt)
B(2,-3,-15,minecraft:dirt)
B(2,-2,-15,minecraft:grass_block)
B(2,-6,-14,minecraft:grass_block)
B(2,-5,-14,minecraft:dirt)
B(2,-4,-14,minecraft:dirt)
B(2,-3,-14,minecraft:dirt)
B(2,-2,-14,minecraft:grass_block)
B(2,-1,-14,minecraft:farmland[moisture=6])
B(2,0,-14,minecraft:wheat[age=7])
B(2,-6,-13,minecraft:dirt)
B(2,-5,-13,minecraft:dirt)
B(2,-4,-13,minecraft:dirt)
B(2,-3,-13,minecraft:dirt)
B(2,-2,-13,minecraft:grass_block)
B(2,-1,-13,minecraft:farmland[moisture=2])
B(2,0,-13,minecraft:wheat[age=7])
B(2,-6,-12,minecraft:dirt)
B(2,-5,-12,minecraft:dirt)
B(2,-4,-12,minecraft:dirt)
B(2,-3,-12,minecraft:dirt)
B(2,-2,-12,minecraft:grass_block)
B(2,-1,-12,minecraft:farmland[moisture=6])
B(2,0,-12,minecraft:wheat[age=7])
B(2,-6,-11,minecraft:dirt)
B(2,-5,-11,minecraft:dirt)
B(2,-4,-11,minecraft:dirt)
B(2,-3,-11,minecraft:dirt)
B(2,-2,-11,minecraft:grass_block)
B(2,-1,-11,minecraft:farmland[moisture=5])
B(2,0,-11,minecraft:wheat[age=7])
B(2,-6,-10,minecraft:dirt)
B(2,-5,-10,minecraft:dirt)
B(2,-4,-10,minecraft:dirt)
B(2,-3,-10,minecraft:dirt)
B(2,-2,-10,minecraft:grass_block)
B(2,-1,-10,minecraft:farmland[moisture=7])
B(2,0,-10,minecraft:wheat[age=7])
B(2,-6,-9,minecraft:dirt)
B(2,-5,-9,minecraft:dirt)
B(2,-4,-9,minecraft:dirt)
B(2,-3,-9,minecraft:dirt)
B(2,-2,-9,minecraft:grass_block)
B(2,-1,-9,minecraft:farmland[moisture=7])
B(2,0,-9,minecraft:wheat[age=7])
B(2,-6,-8,minecraft:dirt)
B(2,-5,-8,minecraft:dirt)
B(2,-4,-8,minecraft:dirt)
B(2,-3,-8,minecraft:dirt)
B(2,-2,-8,minecraft:grass_block)
B(2,-1,-8,minecraft:farmland[moisture=4])
B(2,0,-8,minecraft:wheat[age=7])
B(2,-6,-7,minecraft:grass_block)
B(2,-5,-7,minecraft:dirt)
B(2,-4,-7,minecraft:dirt)
B(2,-3,-7,minecraft:dirt)
B(2,-2,-7,minecraft:dirt)
B(2,-1,-7,minecraft:grass_block)
B(2,0,-7,minecraft:stone_brick_stairs[facing=south,half=top,shape=straight,waterlogged=false])
B(2,1,-7,minecraft:spruce_fence[east=true,north=false,south=false,waterlogged=false,west=true])
B(2,-6,-6,minecraft:grass_block)
B(2,-5,-6,minecraft:dirt)
B(2,-4,-6,minecraft:dirt)
B(2,-3,-6,minecraft:dirt)
B(2,-2,-6,minecraft:grass_block)
B(2,-1,-6,minecraft:dirt)
B(2,0,-6,minecraft:dark_oak_planks)
B(2,-6,-5,minecraft:dirt)
B(2,-5,-5,minecraft:dirt)
B(2,-4,-5,minecraft:dirt)
B(2,-3,-5,minecraft:grass_block)
B(2,-2,-5,minecraft:dirt)
B(2,-1,-5,minecraft:dirt)
B(2,0,-5,minecraft:dark_oak_planks)
B(2,1,-5,minecraft:cobblestone_stairs[facing=south,half=bottom,shape=straight,waterlogged=false])
B(2,2,-5,minecraft:cobblestone_stairs[facing=south,half=top,shape=straight,waterlogged=false])
B(2,3,-5,minecraft:dark_oak_slab)
B(2,7,-5,minecraft:spruce_slab)
B(2,-6,-4,minecraft:dirt)
B(2,-5,-4,minecraft:dirt)
B(2,-4,-4,minecraft:dirt)
B(2,-3,-4,minecraft:dirt)
B(2,-2,-4,minecraft:dirt)
B(2,-1,-4,minecraft:dirt)
B(2,0,-4,minecraft:cobblestone)
B(2,1,-4,minecraft:cobblestone)
B(2,2,-4,minecraft:cobblestone)
B(2,3,-4,minecraft:spruce_log[axis=x])
B(2,4,-4,minecraft:dark_oak_planks)
B(2,5,-4,minecraft:dark_oak_planks)
B(2,6,-4,minecraft:dark_oak_planks)
B(2,7,-4,minecraft:spruce_slab[type=double,waterlogged=false])
B(2,-6,-3,minecraft:dirt)
B(2,-5,-3,minecraft:dirt)
B(2,-4,-3,minecraft:grass_block)
B(2,-3,-3,minecraft:dirt)
B(2,-2,-3,minecraft:dirt)
B(2,-1,-3,minecraft:cobblestone)
B(2,0,-3,minecraft:cobblestone)
B(2,3,-3,minecraft:dark_oak_stairs[facing=north,half=top,shape=straight,waterlogged=false])
B(2,4,-3,minecraft:hay_block[axis=z])
B(2,7,-3,minecraft:oak_log)
B(2,8,-3,minecraft:spruce_stairs[facing=south,half=bottom,shape=straight,waterlogged=false])
B(2,19,-3,minecraft:spruce_stairs[facing=south,half=top,shape=straight,waterlogged=false])
B(2,20,-3,minecraft:dark_oak_planks)
B(2,21,-3,minecraft:dark_oak_planks)
B(2,22,-3,minecraft:spruce_stairs[facing=west,half=bottom,shape=straight,waterlogged=false])
B(2,-6,-2,minecraft:grass_block)
B(2,-5,-2,minecraft:grass_block)
B(2,-4,-2,minecraft:dirt)
B(2,-3,-2,minecraft:dirt)
B(2,-2,-2,minecraft:cobblestone)
B(2,-1,-2,minecraft:stone_brick_stairs[facing=east,half=bottom,shape=straight,waterlogged=false])
B(2,6,-2,minecraft:spruce_log[axis=x])
B(2,7,-2,minecraft:oak_log)
B(2,8,-2,minecraft:oak_log)
B(2,9,-2,minecraft:dark_oak_planks)
B(2,10,-2,minecraft:dark_oak_planks)
B(2,11,-2,minecraft:dark_oak_planks)
B(2,12,-2,minecraft:spruce_log[axis=x])
B(2,13,-2,minecraft:dark_oak_planks)
B(2,14,-2,minecraft:dark_oak_planks)
B(2,15,-2,minecraft:dark_oak_planks)
B(2,16,-2,minecraft:dark_oak_planks)
B(2,17,-2,minecraft:dark_oak_planks)
B(2,18,-2,minecraft:dark_oak_planks)
B(2,19,-2,minecraft:dark_oak_planks)
B(2,20,-2,minecraft:spruce_log[axis=x])
B(2,21,-2,minecraft:dark_oak_planks)
B(2,22,-2,minecraft:spruce_stairs[facing=west,half=bottom,shape=inner_left,waterlogged=false])
B(2,-6,-1,minecraft:dirt)
B(2,-5,-1,minecraft:dirt)
B(2,-4,-1,minecraft:dirt)
B(2,-3,-1,minecraft:dirt)
B(2,-2,-1,minecraft:cobblestone)
B(2,-1,-1,minecraft:iron_bars[east=true,north=false,south=true,waterlogged=false,west=false])
B(2,0,-1,minecraft:iron_bars[east=true,north=false,south=true,waterlogged=false,west=true])
B(2,1,-1,minecraft:iron_bars)
B(2,2,-1,minecraft:iron_bars)
B(2,3,-1,minecraft:iron_bars)
B(2,4,-1,minecraft:iron_bars)
B(2,5,-1,minecraft:iron_bars)
B(2,6,-1,minecraft:iron_bars[east=true,north=true,south=false,waterlogged=false,west=false])
B(2,7,-1,minecraft:iron_bars[east=true,north=true,south=false,waterlogged=false,west=false])
B(2,8,-1,minecraft:iron_bars[east=true,north=true,south=false,waterlogged=false,west=false])
B(2,9,-1,minecraft:iron_bars[east=true,north=true,south=false,waterlogged=false,west=false])
B(2,10,-1,minecraft:iron_bars[east=true,north=true,south=false,waterlogged=false,west=false])
B(2,11,-1,minecraft:iron_bars[east=true,north=true,south=false,waterlogged=false,west=false])
B(2,12,-1,minecraft:iron_bars[east=true,north=true,south=false,waterlogged=false,west=false])
B(2,13,-1,minecraft:iron_bars[east=true,north=true,south=false,waterlogged=false,west=false])
B(2,14,-1,minecraft:iron_bars[east=true,north=true,south=false,waterlogged=false,west=false])
B(2,15,-1,minecraft:iron_bars[east=true,north=true,south=false,waterlogged=false,west=false])
B(2,16,-1,minecraft:iron_bars[east=true,north=true,south=false,waterlogged=false,west=false])
B(2,17,-1,minecraft:iron_bars[east=true,north=true,south=false,waterlogged=false,west=false])
B(2,18,-1,minecraft:iron_bars[east=true,north=true,south=false,waterlogged=false,west=false])
B(2,19,-1,minecraft:iron_bars[east=true,north=true,south=false,waterlogged=false,west=false])
B(2,20,-1,minecraft:iron_bars[east=true,north=true,south=true,waterlogged=false,west=true])
B(2,21,-1,minecraft:iron_bars[east=true,north=true,south=true,waterlogged=false,west=false])
B(2,23,-1,minecraft:spruce_planks)
B(2,24,-1,minecraft:spruce_stairs[facing=south,half=bottom,shape=straight,waterlogged=false])
B(2,-6,0,minecraft:dirt)
B(2,-5,0,minecraft:dirt)
B(2,-4,0,minecraft:dirt)
B(2,-3,0,minecraft:dirt)
B(2,-2,0,minecraft:cobblestone)
B(2,-1,0,minecraft:iron_bars[east=true,north=true,south=true,waterlogged=false,west=true])
B(2,0,0,minecraft:spruce_log[axis=x])
B(2,3,0,minecraft:dark_oak_slab[type=top,waterlogged=false])
B(2,20,0,minecraft:spruce_log[axis=x])
B(2,21,0,minecraft:iron_bars[east=true,north=true,south=true,waterlogged=false,west=true])
B(2,23,0,minecraft:oak_trapdoor[facing=east,half=top,open=false,powered=false,waterlogged=false])
B(2,24,0,minecraft:spruce_planks)
