#######################################################################
# +-----------------------------------------------------------------+ #
# |                            BO3 object                           | #
# +-----------------------------------------------------------------+ #
#######################################################################

Author: Bo3 BulkEdit

Description: Converted Schematic - Modified by Bo3BulkEdit

Version: 3

SettingsMode: WriteDisable

#######################################################################
# +-----------------------------------------------------------------+ #
# |                          Main settings                          | #
# +-----------------------------------------------------------------+ #
#######################################################################



Frequency: 0


SpawnHeight: randomY





##############################
# Height Limits for the BO3. #
##############################

MinHeight: 0
MaxHeight: 256

#######################################################################
# +-----------------------------------------------------------------+ #
# |                      Source block settings                      | #
# +-----------------------------------------------------------------+ #
#######################################################################

CanOverride: true
MaxPercentageOutsideSourceBlock: 100
OutsideSourceBlock: placeAnyway

#######################################################################
# +-----------------------------------------------------------------+ #
# |                               OTG+                              | #
# +-----------------------------------------------------------------+ #
#######################################################################

#######################################################################
# +-----------------------------------------------------------------+ #
# |                              Blocks                             | #
# +-----------------------------------------------------------------+ #
#######################################################################

B(0,750,0,AIR)
B(15,750,15,AIR)
B(5,9,15,STAINED_GLASS:6)
B(7,9,15,STAINED_GLASS:6)
B(5,10,13,STAINED_GLASS:6)
B(7,10,13,STAINED_GLASS:6)
B(3,10,14,STAINED_GLASS:6)
B(4,10,14,STAINED_GLASS:6)
B(5,10,14,STAINED_GLASS:6)
B(6,10,14,STAINED_GLASS:6)
B(7,10,14,STAINED_GLASS:6)
B(3,10,15,STAINED_GLASS:6)
B(4,10,15,STAINED_GLASS:6)
B(5,10,15,SEA_LANTERN)
B(6,10,15,STAINED_GLASS:6)
B(7,10,15,STAINED_GLASS:14)
B(4,11,11,STAINED_GLASS:6)
B(5,11,11,STAINED_GLASS:6)
B(6,11,11,STAINED_GLASS:6)
B(3,11,12,STAINED_GLASS:6)
B(4,11,12,STAINED_GLASS:6)
B(5,11,12,STAINED_GLASS:6)
B(6,11,12,STAINED_GLASS:15)
B(2,11,13,STAINED_GLASS:6)
B(3,11,13,STAINED_GLASS:6)
B(4,11,13,STAINED_GLASS:6)
B(5,11,13,STAINED_GLASS:14)
B(6,11,13,STAINED_GLASS:6)
B(7,11,13,STAINED_GLASS:15)
B(3,11,14,STAINED_GLASS:6)
B(4,11,14,STAINED_GLASS:14)
B(5,11,14,SEA_LANTERN)
B(6,11,14,STAINED_GLASS:14)
B(7,11,14,STAINED_GLASS:6)
B(3,11,15,STAINED_GLASS:6)
B(4,11,15,STAINED_GLASS:11)
B(5,11,15,SEA_LANTERN)
B(6,11,15,STAINED_GLASS:14)
B(7,11,15,STAINED_GLASS:14)
B(4,12,9,STAINED_GLASS:6)
B(5,12,9,STAINED_GLASS:6)
B(6,12,9,STAINED_GLASS:6)
B(1,12,10,STAINED_GLASS:6)
B(2,12,10,STAINED_GLASS:6)
B(3,12,10,STAINED_GLASS:6)
B(4,12,10,STAINED_GLASS:6)
B(5,12,10,STAINED_GLASS:6)
B(6,12,10,STAINED_GLASS:15)
B(2,12,11,STAINED_GLASS:6)
B(3,12,11,STAINED_GLASS:6)
B(4,12,11,STAINED_GLASS:6)
B(5,12,11,STAINED_GLASS:14)
B(6,12,11,STAINED_GLASS:14)
B(2,12,12,STAINED_GLASS:6)
B(3,12,12,STAINED_GLASS:6)
B(4,12,12,STAINED_GLASS:6)
B(5,12,12,SEA_LANTERN)
B(6,12,12,STAINED_GLASS:15)
B(2,12,13,STAINED_GLASS:6)
B(3,12,13,STAINED_GLASS:6)
B(4,12,13,SEA_LANTERN)
B(5,12,13,STAINED_GLASS:14)
B(6,12,13,STAINED_GLASS:14)
B(7,12,13,STAINED_GLASS:15)
B(3,12,14,STAINED_GLASS:15)
B(4,12,14,STAINED_GLASS:14)
B(5,12,14,SEA_LANTERN)
B(6,12,14,STAINED_GLASS:15)
B(7,12,14,STAINED_GLASS:15)
B(3,12,15,STAINED_GLASS:15)
B(4,12,15,STAINED_GLASS:15)
B(5,12,15,SEA_LANTERN)
B(6,12,15,SEA_LANTERN)
B(7,12,15,STAINED_GLASS:15)
B(3,13,7,STAINED_GLASS:6)
B(4,13,7,STAINED_GLASS:6)
B(5,13,7,STAINED_GLASS:15)
B(1,13,8,STAINED_GLASS:6)
B(2,13,8,STAINED_GLASS:6)
B(3,13,8,STAINED_GLASS:6)
B(4,13,8,STAINED_GLASS:6)
B(5,13,8,STAINED_GLASS:15)
B(1,13,9,STAINED_GLASS:6)
B(2,13,9,STAINED_GLASS:6)
B(3,13,9,STAINED_GLASS:6)
B(4,13,9,SEA_LANTERN)
B(5,13,9,STAINED_GLASS:15)
B(6,13,9,STAINED_GLASS:15)
B(1,13,10,STAINED_GLASS:6)
B(2,13,10,STAINED_GLASS:6)
B(3,13,10,STAINED_GLASS:11)
B(4,13,10,SEA_LANTERN)
B(5,13,10,STAINED_GLASS:14)
B(6,13,10,STAINED_GLASS:15)
B(2,13,11,STAINED_GLASS:6)
B(3,13,11,STAINED_GLASS:14)
B(4,13,11,SEA_LANTERN)
B(5,13,11,STAINED_GLASS:14)
B(6,13,11,STAINED_GLASS:14)
B(2,13,12,STAINED_GLASS:6)
B(3,13,12,STAINED_GLASS:6)
B(4,13,12,SEA_LANTERN)
B(5,13,12,SEA_LANTERN)
B(6,13,12,STAINED_GLASS:15)
B(2,13,13,STAINED_GLASS:6)
B(3,13,13,STAINED_GLASS:15)
B(4,13,13,SEA_LANTERN)
B(5,13,13,SEA_LANTERN)
B(6,13,13,STAINED_GLASS:15)
B(7,13,13,STAINED_GLASS:15)
B(3,13,14,STAINED_GLASS:15)
B(4,13,14,STAINED_GLASS:15)
B(5,13,14,STAINED_GLASS:15)
B(6,13,14,STAINED_GLASS:14)
B(7,13,14,STAINED_GLASS:15)
B(3,13,15,STAINED_GLASS:15)
B(4,13,15,STAINED_GLASS:11)
B(5,13,15,STAINED_GLASS:15)
B(6,13,15,STAINED_GLASS:11)
B(7,13,15,STAINED_GLASS:11)
B(3,14,5,STAINED_GLASS:6)
B(4,14,5,STAINED_GLASS:15)
B(0,14,6,STAINED_GLASS:6)
B(1,14,6,STAINED_GLASS:6)
B(2,14,6,STAINED_GLASS:6)
B(3,14,6,STAINED_GLASS:6)
B(4,14,6,STAINED_GLASS:15)
B(5,14,6,STAINED_GLASS:15)
B(1,14,7,STAINED_GLASS:6)
B(2,14,7,STAINED_GLASS:6)
B(3,14,7,SEA_LANTERN)
B(4,14,7,STAINED_GLASS:14)
B(5,14,7,STAINED_GLASS:15)
B(1,14,8,STAINED_GLASS:6)
B(2,14,8,STAINED_GLASS:6)
B(3,14,8,SEA_LANTERN)
B(4,14,8,SEA_LANTERN)
B(5,14,8,STAINED_GLASS:15)
B(1,14,9,STAINED_GLASS:6)
B(2,14,9,STAINED_GLASS:6)
B(3,14,9,SEA_LANTERN)
B(4,14,9,STAINED_GLASS:6)
B(5,14,9,STAINED_GLASS:15)
B(6,14,9,STAINED_GLASS:15)
B(1,14,10,STAINED_GLASS:15)
B(2,14,10,STAINED_GLASS:15)
B(3,14,10,STAINED_GLASS:11)
B(4,14,10,SEA_LANTERN)
B(5,14,10,STAINED_GLASS:15)
B(6,14,10,STAINED_GLASS:15)
B(2,14,11,STAINED_GLASS:15)
B(3,14,11,STAINED_GLASS:15)
B(4,14,11,SEA_LANTERN)
B(5,14,11,STAINED_GLASS:15)
B(6,14,11,STAINED_GLASS:15)
B(2,14,12,STAINED_GLASS:15)
B(3,14,12,STAINED_GLASS:15)
B(4,14,12,SEA_LANTERN)
B(5,14,12,SEA_LANTERN)
B(6,14,12,STAINED_GLASS:15)
B(2,14,13,STAINED_GLASS:15)
B(3,14,13,STAINED_GLASS:15)
B(4,14,13,STAINED_GLASS:15)
B(5,14,13,STAINED_GLASS:14)
B(6,14,13,STAINED_GLASS:14)
B(7,14,13,STAINED_GLASS:15)
B(3,14,14,STAINED_GLASS:15)
B(4,14,14,STAINED_GLASS:11)
B(5,14,14,STAINED_GLASS:15)
B(6,14,14,STAINED_GLASS:15)
B(7,14,14,STAINED_GLASS:15)
B(3,14,15,STAINED_GLASS:15)
B(4,14,15,STAINED_GLASS:15)
B(5,14,15,STAINED_GLASS:15)
B(6,14,15,STAINED_GLASS:15)
B(7,14,15,STAINED_GLASS:15)
B(4,15,3,STAINED_GLASS:6)
B(1,15,4,STAINED_GLASS:6)
B(3,15,4,STAINED_GLASS:6)
B(4,15,4,STAINED_GLASS:6)
B(0,15,5,STAINED_GLASS:6)
B(1,15,5,STAINED_GLASS:6)
B(2,15,5,STAINED_GLASS:6)
B(3,15,5,SEA_LANTERN)
B(4,15,5,STAINED_GLASS:15)
B(0,15,6,STAINED_GLASS:6)
B(1,15,6,STAINED_GLASS:6)
B(2,15,6,STAINED_GLASS:11)
B(3,15,6,SEA_LANTERN)
B(4,15,6,STAINED_GLASS:14)
B(5,15,6,STAINED_GLASS:15)
B(1,15,7,STAINED_GLASS:6)
B(2,15,7,STAINED_GLASS:11)
B(3,15,7,SEA_LANTERN)
B(4,15,7,STAINED_GLASS:14)
B(5,15,7,STAINED_GLASS:15)
B(1,15,8,STAINED_GLASS:6)
B(2,15,8,STAINED_GLASS:6)
B(3,15,8,SEA_LANTERN)
B(4,15,8,SEA_LANTERN)
B(5,15,8,STAINED_GLASS:15)
B(1,15,9,STAINED_GLASS:6)
B(2,15,9,STAINED_GLASS:15)
B(3,15,9,SEA_LANTERN)
B(4,15,9,SEA_LANTERN)
B(5,15,9,STAINED_GLASS:15)
B(6,15,9,STAINED_GLASS:15)
B(1,15,10,STAINED_GLASS:15)
B(2,15,10,STAINED_GLASS:15)
B(3,15,10,STAINED_GLASS:15)
B(4,15,10,SEA_LANTERN)
B(5,15,10,STAINED_GLASS:14)
B(6,15,10,STAINED_GLASS:15)
B(2,15,11,STAINED_GLASS:15)
B(3,15,11,STAINED_GLASS:11)
B(4,15,11,STAINED_GLASS:15)
B(5,15,11,STAINED_GLASS:14)
B(6,15,11,STAINED_GLASS:14)
B(2,15,12,STAINED_GLASS:15)
B(3,15,12,STAINED_GLASS:15)
B(4,15,12,STAINED_GLASS:15)
B(5,15,12,STAINED_GLASS:15)
B(6,15,12,STAINED_GLASS:15)
B(2,15,13,STAINED_GLASS:15)
B(3,15,13,STAINED_GLASS:15)
B(4,15,13,STAINED_GLASS:15)
B(5,15,13,STAINED_GLASS:15)
B(6,15,13,STAINED_GLASS:15)
B(7,15,13,STAINED_GLASS:15)
B(3,15,14,STAINED_GLASS:15)
B(4,15,14,STAINED_GLASS:15)
B(5,15,14,STAINED_GLASS:15)
B(6,15,14,STAINED_GLASS:15)
B(2,16,3,STAINED_GLASS:6)
B(3,16,3,STAINED_GLASS:6)
B(4,16,3,STAINED_GLASS:15)
B(0,16,4,STAINED_GLASS:6)
B(1,16,4,STAINED_GLASS:6)
B(2,16,4,STAINED_GLASS:6)
B(3,16,4,STAINED_GLASS:6)
B(4,16,4,STAINED_GLASS:15)
B(0,16,5,STAINED_GLASS:6)
B(1,16,5,STAINED_GLASS:6)
B(2,16,5,SEA_LANTERN)
B(3,16,5,STAINED_GLASS:15)
B(4,16,5,STAINED_GLASS:15)
B(0,16,6,STAINED_GLASS:6)
B(1,16,6,STAINED_GLASS:6)
B(2,16,6,SEA_LANTERN)
B(3,16,6,SEA_LANTERN)
B(4,16,6,STAINED_GLASS:15)
B(5,16,6,STAINED_GLASS:15)
B(1,16,7,STAINED_GLASS:15)
B(2,16,7,STAINED_GLASS:15)
B(3,16,7,STAINED_GLASS:15)
B(4,16,7,STAINED_GLASS:15)
B(5,16,7,STAINED_GLASS:15)
B(1,16,8,STAINED_GLASS:15)
B(2,16,8,STAINED_GLASS:15)
B(3,16,8,STAINED_GLASS:15)
B(4,16,8,SEA_LANTERN)
B(5,16,8,STAINED_GLASS:15)
B(1,16,9,STAINED_GLASS:15)
B(2,16,9,STAINED_GLASS:15)
B(3,16,9,STAINED_GLASS:15)
B(4,16,9,STAINED_GLASS:15)
B(5,16,9,STAINED_GLASS:15)
B(6,16,9,STAINED_GLASS:15)
B(1,16,10,STAINED_GLASS:15)
B(2,16,10,STAINED_GLASS:15)
B(3,16,10,STAINED_GLASS:11)
B(4,16,10,STAINED_GLASS:15)
B(5,16,10,STAINED_GLASS:15)
B(6,16,10,STAINED_GLASS:15)
B(2,16,11,STAINED_GLASS:15)
B(3,16,11,STAINED_GLASS:15)
B(4,16,11,STAINED_GLASS:15)
B(5,16,11,STAINED_GLASS:15)
B(6,16,11,STAINED_GLASS:15)
B(2,16,12,STAINED_GLASS:15)
B(3,16,12,STAINED_GLASS:15)
B(4,16,12,STAINED_GLASS:15)
B(5,16,12,STAINED_GLASS:15)
B(6,16,12,STAINED_GLASS:15)
B(2,16,13,STAINED_GLASS:15)
B(1,17,2,STAINED_GLASS:6)
B(2,17,2,STAINED_GLASS:6)
B(1,17,3,STAINED_GLASS:6)
B(2,17,3,SEA_LANTERN)
B(3,17,3,STAINED_GLASS:15)
B(0,17,4,STAINED_GLASS:6)
B(1,17,4,STAINED_GLASS:6)
B(2,17,4,SEA_LANTERN)
B(3,17,4,STAINED_GLASS:6)
B(1,17,5,STAINED_GLASS:15)
B(2,17,5,SEA_LANTERN)
B(3,17,5,STAINED_GLASS:15)
B(4,17,5,STAINED_GLASS:15)
B(0,17,6,STAINED_GLASS:15)
B(1,17,6,STAINED_GLASS:15)
B(2,17,6,SEA_LANTERN)
B(3,17,6,STAINED_GLASS:15)
B(4,17,6,STAINED_GLASS:14)
B(5,17,6,STAINED_GLASS:15)
B(1,17,7,STAINED_GLASS:15)
B(2,17,7,STAINED_GLASS:11)
B(3,17,7,STAINED_GLASS:15)
B(4,17,7,STAINED_GLASS:14)
B(5,17,7,STAINED_GLASS:15)
B(1,17,8,STAINED_GLASS:15)
B(2,17,8,STAINED_GLASS:15)
B(3,17,8,STAINED_GLASS:15)
B(4,17,8,STAINED_GLASS:15)
B(5,17,8,STAINED_GLASS:15)
B(1,17,9,STAINED_GLASS:15)
B(2,17,9,STAINED_GLASS:15)
B(3,17,9,STAINED_GLASS:15)
B(4,17,9,STAINED_GLASS:15)
B(5,17,9,STAINED_GLASS:15)
B(6,17,9,STAINED_GLASS:15)
B(1,17,10,STAINED_GLASS:15)
B(2,17,10,STAINED_GLASS:15)
B(3,17,10,STAINED_GLASS:15)
B(4,17,10,STAINED_GLASS:15)
B(5,17,10,STAINED_GLASS:15)
B(2,18,1,STAINED_GLASS:6)
B(0,18,2,STAINED_GLASS:6)
B(1,18,2,STAINED_GLASS:6)
B(2,18,2,STAINED_GLASS:6)
B(3,18,2,STAINED_GLASS:15)
B(1,18,3,STAINED_GLASS:6)
B(2,18,3,SEA_LANTERN)
B(3,18,3,STAINED_GLASS:15)
B(0,18,4,STAINED_GLASS:6)
B(1,18,4,STAINED_GLASS:15)
B(2,18,4,STAINED_GLASS:15)
B(3,18,4,STAINED_GLASS:15)
B(1,18,5,STAINED_GLASS:15)
B(2,18,5,STAINED_GLASS:15)
B(3,18,5,STAINED_GLASS:15)
B(4,18,5,STAINED_GLASS:15)
B(0,18,6,STAINED_GLASS:15)
B(1,18,6,STAINED_GLASS:15)
B(2,18,6,STAINED_GLASS:14)
B(3,18,6,STAINED_GLASS:15)
B(4,18,6,STAINED_GLASS:15)
B(5,18,6,STAINED_GLASS:15)
B(1,18,7,STAINED_GLASS:15)
B(2,18,7,STAINED_GLASS:15)
B(3,18,7,STAINED_GLASS:15)
B(4,18,7,STAINED_GLASS:15)
B(1,18,8,STAINED_GLASS:15)
B(2,18,8,STAINED_GLASS:15)
B(3,18,8,STAINED_GLASS:15)
B(1,19,0,STAINED_GLASS:6)
B(1,19,1,STAINED_GLASS:6)
B(2,19,1,STAINED_GLASS:6)
B(1,19,2,STAINED_GLASS:6)
B(2,19,2,STAINED_GLASS:6)
B(1,19,3,STAINED_GLASS:6)
B(2,19,3,STAINED_GLASS:15)
B(1,19,4,STAINED_GLASS:15)
B(2,19,4,STAINED_GLASS:15)
B(3,19,4,STAINED_GLASS:15)
B(2,19,5,STAINED_GLASS:15)
B(3,19,5,STAINED_GLASS:15)
B(2,19,6,STAINED_GLASS:15)
B(1,20,0,STAINED_GLASS:6)
B(1,20,1,STAINED_GLASS:6)
B(1,20,2,STAINED_GLASS:15)
B(2,20,2,STAINED_GLASS:15)

