
#######################################################################
# +-----------------------------------------------------------------+ #
# |                            BO4 object                           | #
# +-----------------------------------------------------------------+ #
#######################################################################

Author: NLBlackEagle

Description: No description given

SettingsMode: WriteWithoutComments


#######################################################################
# +-----------------------------------------------------------------+ #
# |                          Main settings                          | #
# +-----------------------------------------------------------------+ #
#######################################################################

Frequency: 0

SpawnHeight: highestBlock

UseCenterForHighestBlock: true

##############################
# Height Limits for the BO4. #
##############################

MinHeight: 0

MaxHeight: 255

InheritBO3: 

InheritBO3Rotation: NORTH

OverrideChildSettings: true

OverrideParentHeight: false

CanOverride: false

BranchFrequency: 0

BranchFrequencyGroup: 

MustBeBelowOther: false

MustBeInside: 

CannotBeInside: 

ReplacesBO3: 

MustBeInsideWorldBorders: false

CanSpawnOnWater: true

SpawnOnWaterOnly: false

SpawnUnderWater: false

SpawnAtWaterLevel: false

HeightOffset: 0

RemoveAir: true

ReplaceAbove: 

ReplaceBelow: 

ReplaceWithBiomeBlocks: true

ReplaceWithSurfaceBlock: GRASS

ReplaceWithGroundBlock: DIRT

ReplaceWithStoneBlock: STONE

SmoothRadius: 0

SmoothHeightOffset: 0

SmoothStartTop: false

SmoothStartWood: false

SmoothingSurfaceBlock: 

SmoothingGroundBlock: 

BO3Group: 

IsSpawnPoint: false

DoReplaceBlocks: true


#######################################################################
# +-----------------------------------------------------------------+ #
# |                              Blocks                             | #
# +-----------------------------------------------------------------+ #
#######################################################################

Block(-8,30,-7,STONE:5)
Block(-8,31,-7,STONE:5)
Block(-8,32,-7,STONE:5)
Block(-7,29,-7,STONE:5)
Block(-7,30,-7,STONE:5)
Block(-7,31,-7,STONE:5)
Block(-7,32,-7,STONE:5)
Block(-7,33,-7,STONE:5)
Block(-6,28,-7,STONE:5)
Block(-6,29,-7,STONE:5)
Block(-6,29,-6,STONE:5)
Block(-6,30,-7,STONE:5)
Block(-6,30,-6,STONE:5)
Block(-6,31,-7,STONE:5)
Block(-6,31,-6,STONE:5)
Block(-6,32,-7,STONE:5)
Block(-6,32,-6,STONE:5)
Block(-6,33,-7,STONE:5)
Block(-6,33,-6,STONE:5)
Block(-6,34,-7,STONE:5)
Block(-5,27,-7,STONE:5)
Block(-5,28,-7,STONE:5)
Block(-5,28,-6,STONE:5)
Block(-5,29,-7,STONE:5)
Block(-5,29,-6,STONE:5)
Block(-5,29,-5,STONE:5)
Block(-5,30,-7,STONE:5)
Block(-5,30,-6,STONE:5)
Block(-5,30,-5,STONE:5)
Block(-5,31,-7,STONE:5)
Block(-5,31,-6,STONE:5)
Block(-5,31,-5,STONE:5)
Block(-5,32,-7,STONE:5)
Block(-5,32,-6,STONE:5)
Block(-5,32,-5,STONE:5)
Block(-5,33,-7,STONE:5)
Block(-5,33,-6,STONE:5)
Block(-5,33,-5,STONE:5)
Block(-5,34,-7,STONE:5)
Block(-5,34,-6,STONE:5)
Block(-5,35,-7,STONE:5)
Block(-4,27,-7,STONE:5)
Block(-4,27,-6,STONE:5)
Block(-4,28,-7,STONE:5)
Block(-4,28,-6,STONE:5)
Block(-4,28,-5,STONE:5)
Block(-4,29,-7,STONE:5)
Block(-4,29,-6,STONE:5)
Block(-4,29,-5,STONE:5)
Block(-4,30,-7,STONE:5)
Block(-4,30,-6,STONE:5)
Block(-4,30,-5,STONE:5)
Block(-4,30,-4,STONE:5)
Block(-4,31,-7,STONE:5)
Block(-4,31,-6,STONE:5)
Block(-4,31,-5,STONE:5)
Block(-4,31,-4,STONE:5)
Block(-4,32,-7,STONE:5)
Block(-4,32,-6,STONE:5)
Block(-4,32,-5,STONE:5)
Block(-4,32,-4,STONE:5)
Block(-4,33,-7,STONE:5)
Block(-4,33,-6,STONE:5)
Block(-4,33,-5,STONE:5)
Block(-4,34,-7,STONE:5)
Block(-4,34,-6,STONE:5)
Block(-4,34,-5,STONE:5)
Block(-4,35,-7,STONE:5)
Block(-4,35,-6,STONE:5)
Block(-3,26,-7,STONE:5)
Block(-3,27,-7,STONE:5)
Block(-3,27,-6,STONE:5)
Block(-3,28,-7,STONE:5)
Block(-3,28,-6,STONE:5)
Block(-3,28,-5,STONE:5)
Block(-3,29,-7,STONE:5)
Block(-3,29,-6,STONE:5)
Block(-3,29,-5,STONE:5)
Block(-3,29,-4,STONE:5)
Block(-3,30,-7,STONE:5)
Block(-3,30,-6,STONE:5)
Block(-3,30,-5,STONE:5)
Block(-3,30,-4,STONE:5)
Block(-3,31,-7,STONE:5)
Block(-3,31,-6,STONE:5)
Block(-3,31,-5,STONE:5)
Block(-3,31,-4,STONE:5)
Block(-3,32,-7,STONE:5)
Block(-3,32,-6,STONE:5)
Block(-3,32,-5,STONE:5)
Block(-3,32,-4,STONE:5)
Block(-3,33,-7,STONE:5)
Block(-3,33,-6,STONE:5)
Block(-3,33,-5,STONE:5)
Block(-3,33,-4,STONE:5)
Block(-3,34,-7,STONE:5)
Block(-3,34,-6,STONE:5)
Block(-3,34,-5,STONE:5)
Block(-3,35,-7,STONE:5)
Block(-3,35,-6,STONE:5)
Block(-3,36,-7,STONE:5)
Block(-2,26,-7,OBSIDIAN:0)
Block(-2,27,-7,STONE:5)
Block(-2,27,-6,STONE:5)
Block(-2,28,-7,STONE:5)
Block(-2,28,-6,STONE:5)
Block(-2,28,-5,STONE:5)
Block(-2,29,-7,STONE:5)
Block(-2,29,-6,STONE:5)
Block(-2,29,-5,STONE:5)
Block(-2,29,-4,OBSIDIAN:0)
Block(-2,30,-7,STONE:5)
Block(-2,30,-6,STONE:5)
Block(-2,30,-5,STONE:5)
Block(-2,30,-4,OBSIDIAN:0)
Block(-2,31,-7,STONE:5)
Block(-2,31,-6,STONE:5)
Block(-2,31,-5,STONE:5)
Block(-2,31,-4,OBSIDIAN:0)
Block(-2,32,-7,STONE:5)
Block(-2,32,-6,STONE:5)
Block(-2,32,-5,STONE:5)
Block(-2,32,-4,STONE:5)
Block(-2,33,-7,STONE:5)
Block(-2,33,-6,STONE:5)
Block(-2,33,-5,STONE:5)
Block(-2,33,-4,STONE:5)
Block(-2,34,-7,STONE:5)
Block(-2,34,-6,STONE:5)
Block(-2,34,-5,STONE:5)
Block(-2,35,-7,STONE:5)
Block(-2,35,-6,STONE:5)
Block(-2,36,-7,STONE:5)
Block(-1,25,-7,OBSIDIAN:0)
Block(-1,26,-7,OBSIDIAN:0)
Block(-1,27,-7,OBSIDIAN:0)
Block(-1,27,-6,OBSIDIAN:0)
Block(-1,28,-7,STONE:0)
Block(-1,28,-6,STONE:0)
Block(-1,28,-5,OBSIDIAN:0)
Block(-1,29,-7,STONE:0)
Block(-1,29,-6,STONE:0)
Block(-1,29,-5,OBSIDIAN:0)
Block(-1,29,-4,OBSIDIAN:0)
Block(-1,30,-7,STONE:5)
Block(-1,30,-6,STONE:5)
Block(-1,30,-5,OBSIDIAN:0)
Block(-1,30,-4,OBSIDIAN:0)
Block(-1,31,-7,STONE:5)
Block(-1,31,-6,STONE:5)
Block(-1,31,-5,OBSIDIAN:0)
Block(-1,31,-4,OBSIDIAN:0)
Block(-1,32,-7,STONE:5)
Block(-1,32,-6,STONE:5)
Block(-1,32,-5,STONE:5)
Block(-1,32,-4,OBSIDIAN:0)
Block(-1,33,-7,STONE:5)
Block(-1,33,-6,STONE:5)
Block(-1,33,-5,STONE:5)
Block(-1,33,-4,STONE:5)
Block(-1,34,-7,STONE:5)
Block(-1,34,-6,STONE:5)
Block(-1,34,-5,STONE:5)
Block(-1,35,-7,STONE:5)
Block(-1,35,-6,STONE:5)
Block(-1,36,-7,STONE:5)
Block(0,24,-7,OBSIDIAN:0)
Block(0,25,-7,OBSIDIAN:0)
Block(0,25,-6,OBSIDIAN:0)
Block(0,26,-7,OBSIDIAN:0)
Block(0,26,-6,OBSIDIAN:0)
Block(0,27,-7,OBSIDIAN:0)
Block(0,27,-6,OBSIDIAN:0)
Block(0,27,-5,OBSIDIAN:0)
Block(0,28,-7,STONE:0)
Block(0,28,-6,STONE:0)
Block(0,28,-5,OBSIDIAN:0)
Block(0,28,-4,OBSIDIAN:0)
Block(0,29,-7,STONE:0)
Block(0,29,-6,STONE:0)
Block(0,29,-5,OBSIDIAN:0)
Block(0,29,-4,OBSIDIAN:0)
Block(0,29,-3,OBSIDIAN:0)
Block(0,30,-7,STONE:5)
Block(0,30,-6,STONE:5)
Block(0,30,-5,OBSIDIAN:0)
Block(0,30,-4,OBSIDIAN:0)
Block(0,30,-3,OBSIDIAN:0)
Block(0,31,-7,STONE:5)
Block(0,31,-6,STONE:5)
Block(0,31,-5,OBSIDIAN:0)
Block(0,31,-4,OBSIDIAN:0)
Block(0,31,-3,OBSIDIAN:0)
Block(0,32,-7,STONE:5)
Block(0,32,-6,STONE:5)
Block(0,32,-5,STONE:5)
Block(0,32,-4,OBSIDIAN:0)
Block(0,32,-3,OBSIDIAN:0)
Block(0,33,-7,STONE:5)
Block(0,33,-6,STONE:5)
Block(0,33,-5,STONE:5)
Block(0,33,-4,OBSIDIAN:0)
Block(0,33,-3,OBSIDIAN:0)
Block(0,34,-7,STONE:5)
Block(0,34,-6,STONE:5)
Block(0,34,-5,STONE:5)
Block(0,34,-4,OBSIDIAN:0)
Block(0,35,-7,STONE:5)
Block(0,35,-6,STONE:5)
Block(0,35,-5,STONE:5)
Block(1,23,-7,OBSIDIAN:0)
Block(1,24,-7,OBSIDIAN:0)
Block(1,24,-6,OBSIDIAN:0)
Block(1,25,-7,OBSIDIAN:0)
Block(1,25,-6,OBSIDIAN:0)
Block(1,26,-7,OBSIDIAN:0)
Block(1,26,-6,OBSIDIAN:0)
Block(1,26,-5,OBSIDIAN:0)
Block(1,27,-7,OBSIDIAN:0)
Block(1,27,-6,OBSIDIAN:0)
Block(1,27,-5,OBSIDIAN:0)
Block(1,27,-4,OBSIDIAN:0)
Block(1,28,-7,STONE:0)
Block(1,28,-6,STONE:0)
Block(1,28,-5,OBSIDIAN:0)
Block(1,28,-4,OBSIDIAN:0)
Block(1,28,-3,OBSIDIAN:0)
Block(1,29,-7,STONE:0)
Block(1,29,-6,STONE:0)
Block(1,29,-5,OBSIDIAN:0)
Block(1,29,-4,OBSIDIAN:0)
Block(1,29,-3,OBSIDIAN:0)
Block(1,30,-7,STONE:5)
Block(1,30,-6,STONE:5)
Block(1,30,-5,OBSIDIAN:0)
Block(1,30,-4,OBSIDIAN:0)
Block(1,30,-3,OBSIDIAN:0)
Block(1,30,-2,OBSIDIAN:0)
Block(1,31,-7,STONE:5)
Block(1,31,-6,STONE:5)
Block(1,31,-5,OBSIDIAN:0)
Block(1,31,-4,OBSIDIAN:0)
Block(1,31,-3,OBSIDIAN:0)
Block(1,31,-2,OBSIDIAN:0)
Block(1,32,-7,STONE:5)
Block(1,32,-6,STONE:5)
Block(1,32,-5,OBSIDIAN:0)
Block(1,32,-4,OBSIDIAN:0)
Block(1,32,-3,OBSIDIAN:0)
Block(1,32,-2,OBSIDIAN:0)
Block(1,33,-7,STONE:5)
Block(1,33,-6,STONE:5)
Block(1,33,-5,OBSIDIAN:0)
Block(1,33,-4,OBSIDIAN:0)
Block(1,33,-3,OBSIDIAN:0)
Block(1,34,-7,STONE:5)
Block(1,34,-6,STONE:5)
Block(1,34,-5,OBSIDIAN:0)
Block(1,34,-4,OBSIDIAN:0)
Block(1,34,-3,OBSIDIAN:0)
Block(1,35,-7,STONE:5)
Block(1,35,-6,STONE:5)
Block(1,35,-5,STONE:5)
Block(1,35,-4,OBSIDIAN:0)
Block(1,36,-7,STONE:5)
Block(1,36,-6,STONE:5)
Block(2,23,-7,OBSIDIAN:0)
Block(2,24,-7,OBSIDIAN:0)
Block(2,24,-6,OBSIDIAN:0)
Block(2,25,-7,OBSIDIAN:0)
Block(2,25,-6,OBSIDIAN:0)
Block(2,25,-5,OBSIDIAN:0)
Block(2,26,-7,OBSIDIAN:0)
Block(2,26,-6,OBSIDIAN:0)
Block(2,26,-5,OBSIDIAN:0)
Block(2,27,-7,STONE:3)
Block(2,27,-6,STONE:3)
Block(2,27,-5,STONE:3)
Block(2,27,-4,STONE:3)
Block(2,28,-7,STONE:3)
Block(2,28,-6,STONE:3)
Block(2,28,-5,STONE:3)
Block(2,28,-4,OBSIDIAN:0)
Block(2,28,-3,OBSIDIAN:0)
Block(2,29,-7,STONE:0)
Block(2,29,-6,STONE:3)
Block(2,29,-5,STONE:3)
Block(2,29,-4,OBSIDIAN:0)
Block(2,29,-3,OBSIDIAN:0)
Block(2,29,-2,OBSIDIAN:0)
Block(2,30,-7,STONE:0)
Block(2,30,-6,STONE:3)
Block(2,30,-5,STONE:3)
Block(2,30,-4,OBSIDIAN:0)
Block(2,30,-3,OBSIDIAN:0)
Block(2,30,-2,OBSIDIAN:0)
Block(2,31,-7,STONE:5)
Block(2,31,-6,STONE:3)
Block(2,31,-5,STONE:3)
Block(2,31,-4,OBSIDIAN:0)
Block(2,31,-3,OBSIDIAN:0)
Block(2,31,-2,OBSIDIAN:0)
Block(2,32,-7,STONE:5)
Block(2,32,-6,STONE:5)
Block(2,32,-5,OBSIDIAN:0)
Block(2,32,-4,OBSIDIAN:0)
Block(2,32,-3,OBSIDIAN:0)
Block(2,32,-2,OBSIDIAN:0)
Block(2,33,-7,STONE:5)
Block(2,33,-6,STONE:5)
Block(2,33,-5,OBSIDIAN:0)
Block(2,33,-4,OBSIDIAN:0)
Block(2,33,-3,OBSIDIAN:0)
Block(2,33,-2,OBSIDIAN:0)
Block(2,34,-7,STONE:5)
Block(2,34,-6,STONE:5)
Block(2,34,-5,OBSIDIAN:0)
Block(2,34,-4,OBSIDIAN:0)
Block(2,34,-3,OBSIDIAN:0)
Block(2,35,-7,STONE:5)
Block(2,35,-6,STONE:5)
Block(2,35,-5,STONE:5)
Block(2,35,-4,OBSIDIAN:0)
Block(2,36,-7,STONE:5)
Block(2,36,-6,STONE:5)
Block(2,36,-5,STONE:5)
Block(3,23,-7,OBSIDIAN:0)
Block(3,24,-7,OBSIDIAN:0)
Block(3,24,-6,OBSIDIAN:0)
Block(3,25,-7,OBSIDIAN:0)
Block(3,25,-6,OBSIDIAN:0)
Block(3,25,-5,OBSIDIAN:0)
Block(3,26,-7,STONE:3)
Block(3,26,-6,STONE:3)
Block(3,26,-5,STONE:3)
Block(3,27,-7,STONE:3)
Block(3,27,-6,STONE:3)
Block(3,27,-5,STONE:3)
Block(3,27,-4,STONE:3)
Block(3,28,-7,STONE:3)
Block(3,28,-6,STONE:3)
Block(3,28,-5,STONE:3)
Block(3,28,-4,STONE:3)
Block(3,28,-3,STONE:3)
Block(3,29,-7,STONE:3)
Block(3,29,-6,STONE:3)
Block(3,29,-5,STONE:3)
Block(3,29,-4,STONE:3)
Block(3,29,-3,STONE:3)
Block(3,29,-2,STONE:3)
Block(3,30,-7,STONE:3)
Block(3,30,-6,STONE:3)
Block(3,30,-5,STONE:3)
Block(3,30,-4,STONE:3)
Block(3,30,-3,STONE:3)
Block(3,30,-2,STONE:3)
Block(3,31,-7,STONE:3)
Block(3,31,-6,STONE:3)
Block(3,31,-5,STONE:3)
Block(3,31,-4,OBSIDIAN:0)
Block(3,31,-3,OBSIDIAN:0)
Block(3,31,-2,OBSIDIAN:0)
Block(3,32,-7,STONE:5)
Block(3,32,-6,STONE:3)
Block(3,32,-5,OBSIDIAN:0)
Block(3,32,-4,OBSIDIAN:0)
Block(3,32,-3,OBSIDIAN:0)
Block(3,32,-2,OBSIDIAN:0)
Block(3,33,-7,STONE:5)
Block(3,33,-6,STONE:5)
Block(3,33,-5,OBSIDIAN:0)
Block(3,33,-4,OBSIDIAN:0)
Block(3,33,-3,OBSIDIAN:0)
Block(3,33,-2,OBSIDIAN:0)
Block(3,34,-7,STONE:5)
Block(3,34,-6,STONE:5)
Block(3,34,-5,OBSIDIAN:0)
Block(3,34,-4,OBSIDIAN:0)
Block(3,34,-3,OBSIDIAN:0)
Block(3,35,-7,STONE:5)
Block(3,35,-6,STONE:5)
Block(3,35,-5,OBSIDIAN:0)
Block(3,35,-4,OBSIDIAN:0)
Block(3,36,-7,STONE:5)
Block(3,36,-6,STONE:5)
Block(3,36,-5,OBSIDIAN:0)
Block(4,23,-7,STONE:3)
Block(4,24,-7,STONE:3)
Block(4,24,-6,STONE:3)
Block(4,25,-7,STONE:3)
Block(4,25,-6,STONE:3)
Block(4,25,-5,STONE:3)
Block(4,26,-7,STONE:3)
Block(4,26,-6,STONE:3)
Block(4,26,-5,STONE:3)
Block(4,27,-7,STONE:3)
Block(4,27,-6,STONE:3)
Block(4,27,-5,STONE:3)
Block(4,27,-4,STONE:3)
Block(4,28,-7,STONE:3)
Block(4,28,-6,STONE:3)
Block(4,28,-5,STONE:3)
Block(4,28,-4,STONE:3)
Block(4,28,-3,STONE:3)
Block(4,29,-7,STONE:3)
Block(4,29,-6,STONE:3)
Block(4,29,-5,STONE:3)
Block(4,29,-4,STONE:3)
Block(4,29,-3,STONE:3)
Block(4,29,-2,STONE:3)
Block(4,30,-7,STONE:3)
Block(4,30,-6,STONE:3)
Block(4,30,-5,STONE:3)
Block(4,30,-4,STONE:3)
Block(4,30,-3,STONE:3)
Block(4,30,-2,STONE:3)
Block(4,31,-7,STONE:3)
Block(4,31,-6,STONE:3)
Block(4,31,-5,STONE:3)
Block(4,31,-4,STONE:3)
Block(4,31,-3,STONE:3)
Block(4,31,-2,STONE:3)
Block(4,32,-7,STONE:3)
Block(4,32,-6,STONE:3)
Block(4,32,-5,STONE:3)
Block(4,32,-4,OBSIDIAN:0)
Block(4,32,-3,OBSIDIAN:0)
Block(4,32,-2,OBSIDIAN:0)
Block(4,33,-7,STONE:5)
Block(4,33,-6,STONE:3)
Block(4,33,-5,OBSIDIAN:0)
Block(4,33,-4,OBSIDIAN:0)
Block(4,33,-3,OBSIDIAN:0)
Block(4,33,-2,OBSIDIAN:0)
Block(4,34,-7,STONE:5)
Block(4,34,-6,OBSIDIAN:0)
Block(4,34,-5,OBSIDIAN:0)
Block(4,34,-4,OBSIDIAN:0)
Block(4,34,-3,OBSIDIAN:0)
Block(4,35,-7,STONE:5)
Block(4,35,-6,OBSIDIAN:0)
Block(4,35,-5,OBSIDIAN:0)
Block(4,35,-4,OBSIDIAN:0)
Block(4,36,-7,STONE:5)
Block(4,36,-6,OBSIDIAN:0)
Block(4,36,-5,OBSIDIAN:0)
Block(5,23,-7,STONE:3)
Block(5,24,-7,STONE:3)
Block(5,24,-6,STONE:3)
Block(5,25,-7,STONE:3)
Block(5,25,-6,STONE:3)
Block(5,26,-7,STONE:3)
Block(5,26,-6,STONE:3)
Block(5,26,-5,STONE:3)
Block(5,27,-7,STONE:3)
Block(5,27,-6,STONE:3)
Block(5,27,-5,STONE:3)
Block(5,27,-4,STONE:3)
Block(5,28,-7,STONE:3)
Block(5,28,-6,STONE:3)
Block(5,28,-5,STONE:3)
Block(5,28,-4,STONE:3)
Block(5,28,-3,STONE:3)
Block(5,29,-7,STONE:3)
Block(5,29,-6,STONE:3)
Block(5,29,-5,STONE:3)
Block(5,29,-4,STONE:3)
Block(5,29,-3,STONE:3)
Block(5,30,-7,STONE:3)
Block(5,30,-6,STONE:3)
Block(5,30,-5,STONE:3)
Block(5,30,-4,STONE:3)
Block(5,30,-3,STONE:3)
Block(5,30,-2,STONE:3)
Block(5,31,-7,STONE:3)
Block(5,31,-6,STONE:3)
Block(5,31,-5,STONE:3)
Block(5,31,-4,STONE:3)
Block(5,31,-3,STONE:3)
Block(5,31,-2,STONE:3)
Block(5,32,-7,STONE:3)
Block(5,32,-6,STONE:3)
Block(5,32,-5,STONE:3)
Block(5,32,-4,OBSIDIAN:0)
Block(5,32,-3,OBSIDIAN:0)
Block(5,32,-2,OBSIDIAN:0)
Block(5,33,-7,STONE:5)
Block(5,33,-6,STONE:3)
Block(5,33,-5,OBSIDIAN:0)
Block(5,33,-4,OBSIDIAN:0)
Block(5,33,-3,OBSIDIAN:0)
Block(5,34,-7,STONE:5)
Block(5,34,-6,OBSIDIAN:0)
Block(5,34,-5,OBSIDIAN:0)
Block(5,34,-4,OBSIDIAN:0)
Block(5,34,-3,OBSIDIAN:0)
Block(5,35,-7,OBSIDIAN:0)
Block(5,35,-6,OBSIDIAN:0)
Block(5,35,-5,OBSIDIAN:0)
Block(5,35,-4,OBSIDIAN:0)
Block(5,36,-7,OBSIDIAN:0)
Block(5,36,-6,OBSIDIAN:0)
Block(6,24,-7,STONE:3)
Block(6,25,-7,STONE:3)
Block(6,25,-6,STONE:3)
Block(6,26,-7,STONE:3)
Block(6,26,-6,STONE:3)
Block(6,27,-7,STONE:3)
Block(6,27,-6,STONE:3)
Block(6,27,-5,STONE:3)
Block(6,28,-7,STONE:3)
Block(6,28,-6,STONE:3)
Block(6,28,-5,STONE:3)
Block(6,28,-4,STONE:3)
Block(6,29,-7,STONE:3)
Block(6,29,-6,STONE:3)
Block(6,29,-5,STONE:3)
Block(6,29,-4,STONE:3)
Block(6,29,-3,STONE:3)
Block(6,30,-7,STONE:3)
Block(6,30,-6,STONE:3)
Block(6,30,-5,STONE:3)
Block(6,30,-4,STONE:3)
Block(6,30,-3,STONE:3)
Block(6,31,-7,STONE:3)
Block(6,31,-6,STONE:3)
Block(6,31,-5,STONE:3)
Block(6,31,-4,STONE:3)
Block(6,31,-3,STONE:3)
Block(6,32,-7,STONE:3)
Block(6,32,-6,STONE:3)
Block(6,32,-5,STONE:3)
Block(6,32,-4,STONE:3)
Block(6,32,-3,STONE:3)
Block(6,33,-7,STONE:3)
Block(6,33,-6,OBSIDIAN:0)
Block(6,33,-5,OBSIDIAN:0)
Block(6,33,-4,OBSIDIAN:0)
Block(6,33,-3,OBSIDIAN:0)
Block(6,34,-7,OBSIDIAN:0)
Block(6,34,-6,OBSIDIAN:0)
Block(6,34,-5,OBSIDIAN:0)
Block(6,34,-4,OBSIDIAN:0)
Block(6,35,-7,OBSIDIAN:0)
Block(6,35,-6,OBSIDIAN:0)
Block(6,35,-5,OBSIDIAN:0)
Block(6,36,-7,OBSIDIAN:0)
Block(7,25,-7,STONE:3)
Block(7,26,-7,STONE:3)
Block(7,26,-6,STONE:3)
Block(7,27,-7,STONE:3)
Block(7,27,-6,STONE:3)
Block(7,27,-5,STONE:3)
Block(7,28,-7,STONE:3)
Block(7,28,-6,STONE:3)
Block(7,28,-5,STONE:3)
Block(7,28,-4,STONE:3)
Block(7,29,-7,STONE:3)
Block(7,29,-6,STONE:3)
Block(7,29,-5,STONE:3)
Block(7,29,-4,STONE:3)
Block(7,29,-3,STONE:3)
Block(7,30,-7,STONE:3)
Block(7,30,-6,STONE:3)
Block(7,30,-5,STONE:3)
Block(7,30,-4,STONE:3)
Block(7,30,-3,STONE:3)
Block(7,31,-7,STONE:3)
Block(7,31,-6,STONE:3)
Block(7,31,-5,STONE:3)
Block(7,31,-4,STONE:3)
Block(7,31,-3,STONE:3)
Block(7,32,-7,STONE:3)
Block(7,32,-6,STONE:3)
Block(7,32,-5,STONE:3)
Block(7,32,-4,STONE:3)
Block(7,32,-3,STONE:3)
Block(7,33,-7,STONE:3)
Block(7,33,-6,OBSIDIAN:0)
Block(7,33,-5,OBSIDIAN:0)
Block(7,33,-4,OBSIDIAN:0)
Block(7,33,-3,STONE:3)
Block(7,34,-7,OBSIDIAN:0)
Block(7,34,-6,OBSIDIAN:0)
Block(7,34,-5,OBSIDIAN:0)
Block(7,34,-4,OBSIDIAN:0)
Block(7,35,-7,OBSIDIAN:0)
Block(7,35,-6,OBSIDIAN:0)
Block(7,35,-5,OBSIDIAN:0)
Block(7,36,-7,OBSIDIAN:0)
Block(7,36,-6,OBSIDIAN:0)

#######################################################################
# +-----------------------------------------------------------------+ #
# |                             Branches                            | #
# +-----------------------------------------------------------------+ #
#######################################################################

Branch(0,0,-16,true,Amethyst_NormalC2R7,NORTH,100.0,0)

#######################################################################
# +-----------------------------------------------------------------+ #
# |                             Entities                            | #
# +-----------------------------------------------------------------+ #
#######################################################################


#######################################################################
# +-----------------------------------------------------------------+ #
# |                            Particles                            | #
# +-----------------------------------------------------------------+ #
#######################################################################


#######################################################################
# +-----------------------------------------------------------------+ #
# |                             Spawners                            | #
# +-----------------------------------------------------------------+ #
#######################################################################


#######################################################################
# +-----------------------------------------------------------------+ #
# |                             ModData                             | #
# +-----------------------------------------------------------------+ #
#######################################################################

