
#######################################################################
# +-----------------------------------------------------------------+ #
# |                            BO4 object                           | #
# +-----------------------------------------------------------------+ #
#######################################################################

Author: NLBlackEagle

Description: No description given

SettingsMode: WriteWithoutComments


#######################################################################
# +-----------------------------------------------------------------+ #
# |                          Main settings                          | #
# +-----------------------------------------------------------------+ #
#######################################################################

Frequency: 0

SpawnHeight: highestBlock

UseCenterForHighestBlock: true

##############################
# Height Limits for the BO4. #
##############################

MinHeight: 0

MaxHeight: 255

InheritBO3: 

InheritBO3Rotation: NORTH

OverrideChildSettings: true

OverrideParentHeight: false

CanOverride: false

BranchFrequency: 0

BranchFrequencyGroup: 

MustBeBelowOther: false

MustBeInside: 

CannotBeInside: 

ReplacesBO3: 

MustBeInsideWorldBorders: false

CanSpawnOnWater: true

SpawnOnWaterOnly: false

SpawnUnderWater: false

SpawnAtWaterLevel: false

HeightOffset: 0

RemoveAir: true

ReplaceAbove: 

ReplaceBelow: 

ReplaceWithBiomeBlocks: true

ReplaceWithSurfaceBlock: GRASS

ReplaceWithGroundBlock: DIRT

ReplaceWithStoneBlock: STONE

SmoothRadius: 0

SmoothHeightOffset: 0

SmoothStartTop: false

SmoothStartWood: false

SmoothingSurfaceBlock: 

SmoothingGroundBlock: 

BO3Group: 

IsSpawnPoint: false

DoReplaceBlocks: true


#######################################################################
# +-----------------------------------------------------------------+ #
# |                              Blocks                             | #
# +-----------------------------------------------------------------+ #
#######################################################################

Block(-8,11,5,OBSIDIAN:0)
Block(-8,11,6,OBSIDIAN:0)
Block(-8,11,7,STONE:5)
Block(-8,11,8,STONE:5)
Block(-8,12,1,OBSIDIAN:0)
Block(-8,12,2,OBSIDIAN:0)
Block(-8,12,3,OBSIDIAN:0)
Block(-8,12,4,OBSIDIAN:0)
Block(-8,12,5,OBSIDIAN:0)
Block(-8,12,6,OBSIDIAN:0)
Block(-8,12,7,STONE:5)
Block(-8,12,8,STONE:5)
Block(-8,13,-1,STONE:5)
Block(-8,13,0,OBSIDIAN:0)
Block(-8,13,1,OBSIDIAN:0)
Block(-8,13,2,OBSIDIAN:0)
Block(-8,13,3,OBSIDIAN:0)
Block(-8,13,4,OBSIDIAN:0)
Block(-8,13,5,OBSIDIAN:0)
Block(-8,13,6,OBSIDIAN:0)
Block(-8,13,7,STONE:5)
Block(-8,13,8,STONE:5)
Block(-8,14,-2,STONE:5)
Block(-8,14,-1,STONE:5)
Block(-8,14,0,STONE:5)
Block(-8,14,1,OBSIDIAN:0)
Block(-8,14,2,OBSIDIAN:0)
Block(-8,14,3,OBSIDIAN:0)
Block(-8,14,4,OBSIDIAN:0)
Block(-8,14,5,OBSIDIAN:0)
Block(-8,14,6,STONE:5)
Block(-8,14,7,STONE:5)
Block(-8,14,8,STONE:5)
Block(-8,15,-7,STONE:5)
Block(-8,15,-6,STONE:5)
Block(-8,15,-5,STONE:5)
Block(-8,15,-3,STONE:5)
Block(-8,15,-2,STONE:5)
Block(-8,15,-1,STONE:5)
Block(-8,15,0,STONE:5)
Block(-8,15,1,STONE:5)
Block(-8,15,2,STONE:5)
Block(-8,15,3,STONE:5)
Block(-8,15,4,STONE:5)
Block(-8,15,5,STONE:5)
Block(-8,15,6,STONE:5)
Block(-8,15,7,STONE:5)
Block(-8,15,8,STONE:5)
Block(-8,16,-7,STONE:5)
Block(-8,16,-6,STONE:5)
Block(-8,16,-5,STONE:5)
Block(-8,16,-4,STONE:5)
Block(-8,16,-3,STONE:5)
Block(-8,16,-2,STONE:5)
Block(-8,16,-1,STONE:5)
Block(-8,16,0,STONE:5)
Block(-8,16,1,STONE:5)
Block(-8,16,2,STONE:5)
Block(-8,16,3,STONE:5)
Block(-8,16,4,STONE:5)
Block(-8,16,5,STONE:5)
Block(-8,16,6,STONE:5)
Block(-8,16,7,STONE:5)
Block(-8,16,8,STONE:5)
Block(-8,17,-7,STONE:5)
Block(-8,17,-6,STONE:5)
Block(-8,17,-5,STONE:5)
Block(-8,17,-4,STONE:5)
Block(-8,17,-3,STONE:5)
Block(-8,17,-2,STONE:5)
Block(-8,17,-1,STONE:5)
Block(-8,17,0,STONE:5)
Block(-8,17,1,STONE:5)
Block(-8,17,2,STONE:5)
Block(-8,17,3,STONE:5)
Block(-8,17,4,STONE:5)
Block(-8,17,5,STONE:5)
Block(-8,17,6,STONE:5)
Block(-8,17,7,STONE:5)
Block(-8,17,8,STONE:5)
Block(-8,18,-7,STONE:5)
Block(-8,18,-6,STONE:5)
Block(-8,18,-5,STONE:5)
Block(-8,18,-4,STONE:5)
Block(-8,18,-3,STONE:5)
Block(-8,18,-2,STONE:5)
Block(-8,18,-1,STONE:5)
Block(-8,18,0,STONE:5)
Block(-8,18,1,STONE:5)
Block(-8,18,2,STONE:5)
Block(-8,18,3,STONE:5)
Block(-8,18,4,STONE:5)
Block(-8,18,5,STONE:0)
Block(-8,18,6,STONE:5)
Block(-8,18,7,STONE:5)
Block(-8,18,8,STONE:5)
Block(-8,19,-7,STONE:5)
Block(-8,19,-6,STONE:5)
Block(-8,19,-5,STONE:5)
Block(-8,19,-4,STONE:5)
Block(-8,19,-3,STONE:5)
Block(-8,19,-2,STONE:5)
Block(-8,19,-1,STONE:5)
Block(-8,19,0,STONE:5)
Block(-8,19,1,STONE:5)
Block(-8,19,2,STONE:0)
Block(-8,19,3,STONE:0)
Block(-8,19,4,STONE:0)
Block(-8,19,5,STONE:0)
Block(-8,19,6,STONE:0)
Block(-8,19,7,STONE:0)
Block(-8,19,8,STONE:0)
Block(-8,20,-7,STONE:5)
Block(-8,20,-6,STONE:5)
Block(-8,20,-5,STONE:5)
Block(-8,20,-4,STONE:5)
Block(-8,20,-3,STONE:5)
Block(-8,20,-2,STONE:5)
Block(-8,20,-1,STONE:5)
Block(-8,20,0,STONE:5)
Block(-8,20,1,STONE:0)
Block(-8,20,2,STONE:0)
Block(-8,20,3,STONE:0)
Block(-8,20,4,STONE:0)
Block(-8,20,5,STONE:0)
Block(-8,20,6,STONE:0)
Block(-8,20,7,STONE:0)
Block(-8,20,8,STONE:0)
Block(-8,21,-7,STONE:0)
Block(-8,21,-6,STONE:0)
Block(-8,21,-5,STONE:0)
Block(-8,21,-4,STONE:0)
Block(-8,21,-3,STONE:0)
Block(-8,21,-2,STONE:0)
Block(-8,21,-1,STONE:0)
Block(-8,21,0,STONE:0)
Block(-8,21,1,STONE:0)
Block(-8,21,2,STONE:0)
Block(-8,21,3,STONE:0)
Block(-8,21,4,STONE:0)
Block(-8,21,5,STONE:0)
Block(-8,21,6,STONE:0)
Block(-8,21,7,STONE:0)
Block(-8,21,8,STONE:0)
Block(-8,22,-7,STONE:0)
Block(-8,22,-6,STONE:0)
Block(-8,22,-5,STONE:0)
Block(-8,22,-4,STONE:0)
Block(-8,22,-3,STONE:0)
Block(-8,22,-2,STONE:0)
Block(-8,22,-1,STONE:0)
Block(-8,22,0,STONE:0)
Block(-8,22,1,STONE:0)
Block(-8,22,2,STONE:0)
Block(-8,22,3,STONE:0)
Block(-8,22,4,STONE:0)
Block(-8,22,5,STONE:0)
Block(-8,22,6,MAGMA:0)
Block(-8,22,7,MAGMA:0)
Block(-8,22,8,MAGMA:0)
Block(-8,23,-7,STONE:0)
Block(-8,23,-6,STONE:0)
Block(-8,23,-5,STONE:0)
Block(-8,23,-4,STONE:0)
Block(-8,23,-3,STONE:0)
Block(-8,23,-2,STONE:0)
Block(-8,23,-1,STONE:0)
Block(-8,23,0,STONE:0)
Block(-8,23,1,STONE:0)
Block(-8,23,2,STONE:0)
Block(-8,23,3,STONE:0)
Block(-8,23,4,STONE:0)
Block(-8,23,5,STONE:0)
Block(-8,23,6,MAGMA:0)
Block(-8,23,7,MAGMA:0)
Block(-8,23,8,MAGMA:0)
Block(-8,24,-7,STONE:0)
Block(-8,24,-6,STONE:0)
Block(-8,24,-5,STONE:0)
Block(-8,24,-4,STONE:0)
Block(-8,24,-3,STONE:0)
Block(-8,24,-2,STONE:0)
Block(-8,24,-1,STONE:0)
Block(-8,24,0,STONE:0)
Block(-8,24,1,STONE:0)
Block(-8,24,2,STONE:0)
Block(-8,24,3,STONE:0)
Block(-8,24,4,STONE:0)
Block(-8,24,5,STONE:0)
Block(-8,24,6,MAGMA:0)
Block(-8,24,7,MAGMA:0)
Block(-8,24,8,MAGMA:0)
Block(-8,25,-7,STONE:0)
Block(-8,25,-6,STONE:0)
Block(-8,25,-5,STONE:0)
Block(-8,25,-4,STONE:0)
Block(-8,25,-3,STONE:0)
Block(-8,25,-2,STONE:0)
Block(-8,25,-1,STONE:0)
Block(-8,25,0,STONE:0)
Block(-8,25,1,STONE:0)
Block(-8,25,2,STONE:0)
Block(-8,25,3,STONE:0)
Block(-8,25,4,STONE:0)
Block(-8,25,5,STONE:0)
Block(-8,25,6,MAGMA:0)
Block(-8,25,7,MAGMA:0)
Block(-8,25,8,MAGMA:0)
Block(-8,26,-7,STONE:0)
Block(-8,26,-6,STONE:0)
Block(-8,26,-5,STONE:0)
Block(-8,26,-4,STONE:0)
Block(-8,26,-3,STONE:0)
Block(-8,26,-2,STONE:0)
Block(-8,26,-1,STONE:0)
Block(-8,26,0,STONE:0)
Block(-8,26,1,STONE:0)
Block(-8,26,2,STONE:0)
Block(-8,26,3,STONE:0)
Block(-8,26,4,STONE:0)
Block(-8,26,5,STONE:0)
Block(-8,26,7,MAGMA:0)
Block(-8,26,8,MAGMA:0)
Block(-8,27,-7,STONE:0)
Block(-8,27,-6,STONE:0)
Block(-8,27,-5,STONE:0)
Block(-8,27,-4,STONE:0)
Block(-8,27,-3,STONE:0)
Block(-8,27,-2,GRASS:0)
Block(-8,27,-1,GRASS:0)
Block(-8,27,0,STONE:0)
Block(-8,27,1,STONE:0)
Block(-8,27,2,STONE:0)
Block(-8,27,3,STONE:0)
Block(-8,27,4,STONE:0)
Block(-8,27,5,GRASS:0)
Block(-8,28,-7,GRASS:0)
Block(-8,28,-6,STONE:0)
Block(-8,28,-5,GRASS:0)
Block(-8,28,-4,STONE:0)
Block(-8,28,-3,STONE:0)
Block(-8,28,0,GRASS:0)
Block(-8,28,1,GRASS:0)
Block(-8,28,2,GRASS:0)
Block(-8,28,3,GRASS:0)
Block(-8,28,4,GRASS:0)
Block(-8,29,-6,STONE:0)
Block(-8,29,-4,STONE:0)
Block(-8,29,-3,STONE:0)
Block(-8,34,7,STONE:0)
Block(-8,34,8,OBSIDIAN:0)
Block(-8,35,-7,OBSIDIAN:0)
Block(-8,35,-6,OBSIDIAN:0)
Block(-8,35,-4,OBSIDIAN:0)
Block(-8,35,-3,OBSIDIAN:0)
Block(-8,35,-2,OBSIDIAN:0)
Block(-8,35,-1,OBSIDIAN:0)
Block(-8,35,0,OBSIDIAN:0)
Block(-8,35,3,STONE:0)
Block(-8,35,4,STONE:0)
Block(-8,35,5,STONE:0)
Block(-8,35,6,STONE:0)
Block(-8,35,7,STONE:0)
Block(-8,35,8,STONE:0)
Block(-8,36,-7,OBSIDIAN:0)
Block(-8,36,-6,OBSIDIAN:0)
Block(-8,36,-5,OBSIDIAN:0)
Block(-8,36,-4,OBSIDIAN:0)
Block(-8,36,-3,OBSIDIAN:0)
Block(-8,36,-2,OBSIDIAN:0)
Block(-8,36,-1,OBSIDIAN:0)
Block(-8,36,0,OBSIDIAN:0)
Block(-8,36,1,STONE:0)
Block(-8,36,2,STONE:0)
Block(-8,36,3,STONE:0)
Block(-8,36,4,STONE:0)
Block(-8,36,5,STONE:0)
Block(-8,36,6,STONE:0)
Block(-8,36,7,STONE:0)
Block(-8,36,8,STONE:0)
Block(-8,37,-7,MAGMA:0)
Block(-8,37,-6,MAGMA:0)
Block(-8,37,-5,MAGMA:0)
Block(-8,37,-4,MAGMA:0)
Block(-8,37,-3,MAGMA:0)
Block(-8,37,-2,MAGMA:0)
Block(-8,37,-1,OBSIDIAN:0)
Block(-8,37,0,OBSIDIAN:0)
Block(-8,37,1,STONE:0)
Block(-8,37,2,STONE:0)
Block(-8,37,3,STONE:0)
Block(-8,37,4,STONE:0)
Block(-8,37,5,STONE:0)
Block(-8,37,6,STONE:0)
Block(-8,37,7,STONE:0)
Block(-8,37,8,STONE:0)
Block(-8,38,-7,STONE:0)
Block(-8,38,-6,STONE:0)
Block(-8,38,-5,STONE:0)
Block(-8,38,-4,MAGMA:0)
Block(-8,38,-3,MAGMA:0)
Block(-8,38,-2,MAGMA:0)
Block(-8,38,-1,MAGMA:0)
Block(-8,38,0,MAGMA:0)
Block(-8,38,1,STONE:0)
Block(-8,38,2,STONE:0)
Block(-8,38,3,STONE:0)
Block(-8,38,4,STONE:0)
Block(-8,38,5,STONE:0)
Block(-8,38,6,STONE:0)
Block(-8,38,7,STONE:0)
Block(-8,38,8,STONE:0)
Block(-8,39,-7,STONE:0)
Block(-8,39,-6,STONE:0)
Block(-8,39,-5,STONE:0)
Block(-8,39,-4,MAGMA:0)
Block(-8,39,-3,MAGMA:0)
Block(-8,39,-2,MAGMA:0)
Block(-8,39,-1,MAGMA:0)
Block(-8,39,0,MAGMA:0)
Block(-8,39,1,STONE:0)
Block(-8,39,2,STONE:0)
Block(-8,39,3,STONE:0)
Block(-8,39,4,STONE:0)
Block(-8,39,5,STONE:0)
Block(-8,39,6,STONE:0)
Block(-8,39,7,STONE:0)
Block(-8,39,8,STONE:0)
Block(-8,40,-7,STONE:0)
Block(-8,40,-6,STONE:0)
Block(-8,40,-5,STONE:0)
Block(-8,40,-4,STONE:0)
Block(-8,40,-3,STONE:0)
Block(-8,40,-2,STONE:0)
Block(-8,40,-1,STONE:0)
Block(-8,40,0,STONE:0)
Block(-8,40,1,STONE:0)
Block(-8,40,2,STONE:0)
Block(-8,40,3,STONE:0)
Block(-8,40,4,STONE:0)
Block(-8,40,5,STONE:0)
Block(-8,40,6,STONE:0)
Block(-8,40,7,STONE:0)
Block(-8,40,8,STONE:0)
Block(-8,41,-7,STONE:5)
Block(-8,41,-6,STONE:5)
Block(-8,41,-5,STONE:0)
Block(-8,41,-4,STONE:0)
Block(-8,41,-3,STONE:0)
Block(-8,41,-2,STONE:0)
Block(-8,41,-1,STONE:0)
Block(-8,41,0,STONE:0)
Block(-8,41,1,STONE:0)
Block(-8,41,2,STONE:0)
Block(-8,41,3,STONE:0)
Block(-8,41,4,STONE:0)
Block(-8,41,5,STONE:0)
Block(-8,41,6,STONE:0)
Block(-8,41,7,STONE:0)
Block(-8,41,8,STONE:0)
Block(-8,42,-7,STONE:5)
Block(-8,42,-6,STONE:5)
Block(-8,42,-5,STONE:5)
Block(-8,42,-4,STONE:5)
Block(-8,42,-3,STONE:5)
Block(-8,42,-2,STONE:0)
Block(-8,42,-1,STONE:0)
Block(-8,42,0,STONE:0)
Block(-8,42,1,STONE:0)
Block(-8,42,2,STONE:0)
Block(-8,42,3,STONE:0)
Block(-8,42,4,STONE:0)
Block(-8,42,5,STONE:5)
Block(-8,42,6,STONE:5)
Block(-8,42,7,STONE:5)
Block(-8,42,8,STONE:5)
Block(-8,43,-7,STONE:5)
Block(-8,43,-6,STONE:5)
Block(-8,43,-5,STONE:5)
Block(-8,43,-4,STONE:5)
Block(-8,43,-3,STONE:5)
Block(-8,43,-2,STONE:5)
Block(-8,43,-1,STONE:0)
Block(-8,43,0,STONE:0)
Block(-8,43,1,STONE:0)
Block(-8,43,2,STONE:0)
Block(-8,43,3,STONE:0)
Block(-8,43,4,STONE:5)
Block(-8,43,5,STONE:5)
Block(-8,43,6,STONE:5)
Block(-8,43,7,STONE:5)
Block(-8,43,8,STONE:5)
Block(-8,44,-7,STONE:5)
Block(-8,44,-6,STONE:5)
Block(-8,44,-5,STONE:5)
Block(-8,44,-4,STONE:5)
Block(-8,44,-3,STONE:5)
Block(-8,44,-2,STONE:5)
Block(-8,44,-1,STONE:5)
Block(-8,44,0,STONE:5)
Block(-8,44,1,STONE:5)
Block(-8,44,2,STONE:5)
Block(-8,44,3,STONE:5)
Block(-8,44,4,STONE:5)
Block(-8,44,5,STONE:5)
Block(-8,44,6,STONE:5)
Block(-8,44,7,STONE:5)
Block(-8,44,8,STONE:5)
Block(-8,45,-7,STONE:5)
Block(-8,45,-6,STONE:5)
Block(-8,45,-5,STONE:5)
Block(-8,45,-4,STONE:5)
Block(-8,45,-3,STONE:5)
Block(-8,45,-2,STONE:5)
Block(-8,45,-1,STONE:5)
Block(-8,45,0,STONE:5)
Block(-8,45,1,STONE:5)
Block(-8,45,2,STONE:5)
Block(-8,45,3,STONE:5)
Block(-8,45,4,STONE:5)
Block(-8,45,5,STONE:5)
Block(-8,45,6,STONE:5)
Block(-8,45,7,STONE:5)
Block(-8,45,8,STONE:5)
Block(-8,46,-7,STONE:5)
Block(-8,46,-6,STONE:5)
Block(-8,46,-5,STONE:5)
Block(-8,46,-4,STONE:5)
Block(-8,46,-3,STONE:5)
Block(-8,46,-2,STONE:5)
Block(-8,46,-1,STONE:5)
Block(-8,46,0,STONE:5)
Block(-8,46,1,STONE:5)
Block(-8,46,2,STONE:5)
Block(-8,46,3,STONE:5)
Block(-8,46,4,STONE:5)
Block(-8,46,5,STONE:5)
Block(-8,46,6,STONE:5)
Block(-8,46,7,STONE:5)
Block(-8,46,8,STONE:5)
Block(-8,47,-5,STONE:5)
Block(-8,47,-4,STONE:5)
Block(-8,47,-3,STONE:5)
Block(-8,47,-1,STONE:5)
Block(-8,47,0,STONE:5)
Block(-8,47,1,STONE:5)
Block(-8,47,2,STONE:5)
Block(-8,47,3,STONE:5)
Block(-8,47,4,STONE:5)
Block(-8,47,5,STONE:5)
Block(-8,47,6,STONE:5)
Block(-8,47,7,OBSIDIAN:0)
Block(-8,47,8,OBSIDIAN:0)
Block(-8,48,1,STONE:5)
Block(-8,48,2,STONE:5)
Block(-8,48,3,STONE:5)
Block(-8,48,4,STONE:5)
Block(-8,48,5,STONE:5)
Block(-8,48,6,STONE:5)
Block(-8,48,7,OBSIDIAN:0)
Block(-8,48,8,OBSIDIAN:0)
Block(-8,49,5,STONE:5)
Block(-8,49,6,STONE:5)
Block(-8,49,7,OBSIDIAN:0)
Block(-8,49,8,OBSIDIAN:0)
Block(-7,11,5,OBSIDIAN:0)
Block(-7,11,6,STONE:5)
Block(-7,11,7,STONE:5)
Block(-7,11,8,STONE:5)
Block(-7,12,0,OBSIDIAN:0)
Block(-7,12,1,OBSIDIAN:0)
Block(-7,12,2,OBSIDIAN:0)
Block(-7,12,3,OBSIDIAN:0)
Block(-7,12,4,OBSIDIAN:0)
Block(-7,12,5,OBSIDIAN:0)
Block(-7,12,6,STONE:5)
Block(-7,12,7,STONE:5)
Block(-7,12,8,STONE:5)
Block(-7,13,-1,STONE:5)
Block(-7,13,0,OBSIDIAN:0)
Block(-7,13,1,OBSIDIAN:0)
Block(-7,13,2,OBSIDIAN:0)
Block(-7,13,3,OBSIDIAN:0)
Block(-7,13,4,OBSIDIAN:0)
Block(-7,13,5,OBSIDIAN:0)
Block(-7,13,6,STONE:5)
Block(-7,13,7,STONE:5)
Block(-7,13,8,STONE:5)
Block(-7,14,-3,STONE:5)
Block(-7,14,-2,STONE:5)
Block(-7,14,-1,STONE:5)
Block(-7,14,0,STONE:5)
Block(-7,14,1,OBSIDIAN:0)
Block(-7,14,2,OBSIDIAN:0)
Block(-7,14,3,OBSIDIAN:0)
Block(-7,14,4,OBSIDIAN:0)
Block(-7,14,5,STONE:5)
Block(-7,14,6,STONE:5)
Block(-7,14,7,STONE:5)
Block(-7,14,8,STONE:5)
Block(-7,15,-7,STONE:5)
Block(-7,15,-6,STONE:5)
Block(-7,15,-5,STONE:5)
Block(-7,15,-4,STONE:5)
Block(-7,15,-3,STONE:5)
Block(-7,15,-2,STONE:5)
Block(-7,15,-1,STONE:5)
Block(-7,15,0,STONE:5)
Block(-7,15,1,STONE:5)
Block(-7,15,2,STONE:5)
Block(-7,15,3,STONE:5)
Block(-7,15,4,STONE:5)
Block(-7,15,5,STONE:5)
Block(-7,15,6,STONE:5)
Block(-7,15,7,STONE:5)
Block(-7,15,8,STONE:5)
Block(-7,16,-7,STONE:5)
Block(-7,16,-6,STONE:5)
Block(-7,16,-5,STONE:5)
Block(-7,16,-4,STONE:5)
Block(-7,16,-3,STONE:5)
Block(-7,16,-2,STONE:5)
Block(-7,16,-1,STONE:5)
Block(-7,16,0,STONE:5)
Block(-7,16,1,STONE:5)
Block(-7,16,2,STONE:5)
Block(-7,16,3,STONE:5)
Block(-7,16,4,STONE:5)
Block(-7,16,5,STONE:5)
Block(-7,16,6,STONE:5)
Block(-7,16,7,STONE:5)
Block(-7,16,8,STONE:5)
Block(-7,17,-7,STONE:5)
Block(-7,17,-6,STONE:5)
Block(-7,17,-5,STONE:5)
Block(-7,17,-4,STONE:5)
Block(-7,17,-3,STONE:5)
Block(-7,17,-2,STONE:5)
Block(-7,17,-1,STONE:5)
Block(-7,17,0,STONE:5)
Block(-7,17,1,STONE:5)
Block(-7,17,2,STONE:5)
Block(-7,17,3,STONE:5)
Block(-7,17,4,STONE:0)
Block(-7,17,5,STONE:5)
Block(-7,17,6,STONE:5)
Block(-7,17,7,STONE:5)
Block(-7,17,8,STONE:5)
Block(-7,18,-7,STONE:5)
Block(-7,18,-6,STONE:5)
Block(-7,18,-5,STONE:5)
Block(-7,18,-4,STONE:5)
Block(-7,18,-3,STONE:5)
Block(-7,18,-2,STONE:5)
Block(-7,18,-1,STONE:5)
Block(-7,18,0,STONE:5)
Block(-7,18,1,STONE:5)
Block(-7,18,2,STONE:5)
Block(-7,18,3,STONE:0)
Block(-7,18,4,STONE:0)
Block(-7,18,5,STONE:0)
Block(-7,18,6,STONE:5)
Block(-7,18,7,STONE:5)
Block(-7,18,8,STONE:5)
Block(-7,19,-7,STONE:5)
Block(-7,19,-6,STONE:5)
Block(-7,19,-5,STONE:5)
Block(-7,19,-4,STONE:5)
Block(-7,19,-3,STONE:5)
Block(-7,19,-2,STONE:5)
Block(-7,19,-1,STONE:5)
Block(-7,19,0,STONE:5)
Block(-7,19,1,STONE:5)
Block(-7,19,2,STONE:0)
Block(-7,19,3,STONE:0)
Block(-7,19,4,STONE:0)
Block(-7,19,5,STONE:0)
Block(-7,19,6,STONE:0)
Block(-7,19,7,STONE:0)
Block(-7,19,8,STONE:0)
Block(-7,20,-7,STONE:5)
Block(-7,20,-6,STONE:5)
Block(-7,20,-5,STONE:5)
Block(-7,20,-4,STONE:5)
Block(-7,20,-3,STONE:5)
Block(-7,20,-2,STONE:5)
Block(-7,20,-1,STONE:5)
Block(-7,20,0,STONE:0)
Block(-7,20,1,STONE:0)
Block(-7,20,2,STONE:0)
Block(-7,20,3,STONE:0)
Block(-7,20,4,STONE:0)
Block(-7,20,5,STONE:0)
Block(-7,20,6,STONE:0)
Block(-7,20,7,STONE:0)
Block(-7,20,8,STONE:0)
Block(-7,21,-7,STONE:0)
Block(-7,21,-6,STONE:0)
Block(-7,21,-5,STONE:0)
Block(-7,21,-4,STONE:0)
Block(-7,21,-3,STONE:0)
Block(-7,21,-2,STONE:0)
Block(-7,21,-1,STONE:0)
Block(-7,21,0,STONE:0)
Block(-7,21,1,STONE:0)
Block(-7,21,2,STONE:0)
Block(-7,21,3,STONE:0)
Block(-7,21,4,STONE:0)
Block(-7,21,5,STONE:0)
Block(-7,21,6,STONE:0)
Block(-7,21,7,MAGMA:0)
Block(-7,21,8,MAGMA:0)
Block(-7,22,-7,STONE:0)
Block(-7,22,-6,STONE:0)
Block(-7,22,-5,STONE:0)
Block(-7,22,-4,STONE:0)
Block(-7,22,-3,STONE:0)
Block(-7,22,-2,STONE:0)
Block(-7,22,-1,STONE:0)
Block(-7,22,0,STONE:0)
Block(-7,22,1,STONE:0)
Block(-7,22,2,STONE:0)
Block(-7,22,3,STONE:0)
Block(-7,22,4,STONE:0)
Block(-7,22,5,STONE:0)
Block(-7,22,6,MAGMA:0)
Block(-7,22,7,MAGMA:0)
Block(-7,22,8,MAGMA:0)
Block(-7,23,-7,STONE:0)
Block(-7,23,-6,STONE:0)
Block(-7,23,-5,STONE:0)
Block(-7,23,-4,STONE:0)
Block(-7,23,-3,STONE:0)
Block(-7,23,-2,STONE:0)
Block(-7,23,-1,STONE:0)
Block(-7,23,0,STONE:0)
Block(-7,23,1,STONE:0)
Block(-7,23,2,STONE:0)
Block(-7,23,3,STONE:0)
Block(-7,23,4,STONE:0)
Block(-7,23,5,MAGMA:0)
Block(-7,23,6,MAGMA:0)
Block(-7,23,7,MAGMA:0)
Block(-7,23,8,MAGMA:0)
Block(-7,24,-7,STONE:0)
Block(-7,24,-6,STONE:0)
Block(-7,24,-5,STONE:0)
Block(-7,24,-4,STONE:0)
Block(-7,24,-3,STONE:0)
Block(-7,24,-2,STONE:0)
Block(-7,24,-1,STONE:0)
Block(-7,24,0,STONE:0)
Block(-7,24,1,STONE:0)
Block(-7,24,2,STONE:0)
Block(-7,24,3,STONE:0)
Block(-7,24,4,STONE:0)
Block(-7,24,5,MAGMA:0)
Block(-7,24,6,MAGMA:0)
Block(-7,24,7,MAGMA:0)
Block(-7,24,8,MAGMA:0)
Block(-7,25,-7,STONE:0)
Block(-7,25,-6,STONE:0)
Block(-7,25,-5,STONE:0)
Block(-7,25,-4,STONE:0)
Block(-7,25,-3,STONE:0)
Block(-7,25,-2,STONE:0)
Block(-7,25,-1,GRASS:0)
Block(-7,25,0,STONE:0)
Block(-7,25,1,STONE:0)
Block(-7,25,2,STONE:0)
Block(-7,25,3,STONE:0)
Block(-7,25,4,STONE:0)
Block(-7,25,5,MAGMA:0)
Block(-7,25,6,MAGMA:0)
Block(-7,25,7,MAGMA:0)
Block(-7,25,8,MAGMA:0)
Block(-7,26,-7,STONE:0)
Block(-7,26,-6,STONE:0)
Block(-7,26,-5,STONE:0)
Block(-7,26,-4,STONE:0)
Block(-7,26,-3,GRASS:0)
Block(-7,26,-2,GRASS:0)
Block(-7,26,0,GRASS:0)
Block(-7,26,1,STONE:0)
Block(-7,26,2,STONE:0)
Block(-7,26,3,STONE:0)
Block(-7,26,4,GRASS:0)
Block(-7,27,-7,STONE:0)
Block(-7,27,-6,STONE:0)
Block(-7,27,-5,STONE:0)
Block(-7,27,-4,STONE:0)
Block(-7,27,1,GRASS:0)
Block(-7,27,2,GRASS:0)
Block(-7,27,3,GRASS:0)
Block(-7,28,-7,GRASS:0)
Block(-7,28,-6,GRASS:0)
Block(-7,28,-5,GRASS:0)
Block(-7,28,-4,GRASS:0)
Block(-7,34,8,STONE:0)
Block(-7,35,7,STONE:0)
Block(-7,35,8,STONE:0)
Block(-7,36,-7,MAGMA:0)
Block(-7,36,-6,OBSIDIAN:0)
Block(-7,36,-5,MAGMA:0)
Block(-7,36,-4,MAGMA:0)
Block(-7,36,-3,OBSIDIAN:0)
Block(-7,36,-2,OBSIDIAN:0)
Block(-7,36,-1,OBSIDIAN:0)
Block(-7,36,0,OBSIDIAN:0)
Block(-7,36,3,STONE:0)
Block(-7,36,4,STONE:0)
Block(-7,36,5,STONE:0)
Block(-7,36,6,STONE:0)
Block(-7,36,7,STONE:0)
Block(-7,36,8,STONE:0)
Block(-7,37,-7,STONE:0)
Block(-7,37,-6,STONE:0)
Block(-7,37,-5,MAGMA:0)
Block(-7,37,-4,MAGMA:0)
Block(-7,37,-3,MAGMA:0)
Block(-7,37,-2,OBSIDIAN:0)
Block(-7,37,-1,OBSIDIAN:0)
Block(-7,37,0,OBSIDIAN:0)
Block(-7,37,1,OBSIDIAN:0)
Block(-7,37,2,OBSIDIAN:0)
Block(-7,37,3,OBSIDIAN:0)
Block(-7,37,4,OBSIDIAN:0)
Block(-7,37,5,STONE:0)
Block(-7,37,6,STONE:0)
Block(-7,37,7,STONE:0)
Block(-7,37,8,STONE:0)
Block(-7,38,-7,STONE:0)
Block(-7,38,-6,STONE:0)
Block(-7,38,-5,MAGMA:0)
Block(-7,38,-4,MAGMA:0)
Block(-7,38,-3,MAGMA:0)
Block(-7,38,-2,MAGMA:0)
Block(-7,38,-1,MAGMA:0)
Block(-7,38,0,MAGMA:0)
Block(-7,38,1,OBSIDIAN:0)
Block(-7,38,2,OBSIDIAN:0)
Block(-7,38,3,OBSIDIAN:0)
Block(-7,38,4,OBSIDIAN:0)
Block(-7,38,5,OBSIDIAN:0)
Block(-7,38,6,OBSIDIAN:0)
Block(-7,38,7,STONE:0)
Block(-7,38,8,STONE:0)
Block(-7,39,-7,STONE:0)
Block(-7,39,-6,STONE:0)
Block(-7,39,-5,STONE:0)
Block(-7,39,-4,MAGMA:0)
Block(-7,39,-3,MAGMA:0)
Block(-7,39,-2,MAGMA:0)
Block(-7,39,-1,MAGMA:0)
Block(-7,39,0,MAGMA:0)
Block(-7,39,1,STONE:0)
Block(-7,39,2,MAGMA:0)
Block(-7,39,3,MAGMA:0)
Block(-7,39,4,MAGMA:0)
Block(-7,39,5,MAGMA:0)
Block(-7,39,6,MAGMA:0)
Block(-7,39,7,STONE:0)
Block(-7,39,8,STONE:0)
Block(-7,40,-7,STONE:0)
Block(-7,40,-6,STONE:0)
Block(-7,40,-5,STONE:0)
Block(-7,40,-4,STONE:0)
Block(-7,40,-3,MAGMA:0)
Block(-7,40,-2,MAGMA:0)
Block(-7,40,-1,MAGMA:0)
Block(-7,40,0,STONE:0)
Block(-7,40,1,STONE:0)
Block(-7,40,2,STONE:0)
Block(-7,40,3,STONE:0)
Block(-7,40,4,MAGMA:0)
Block(-7,40,5,MAGMA:0)
Block(-7,40,6,MAGMA:0)
Block(-7,40,7,STONE:0)
Block(-7,40,8,STONE:0)
Block(-7,41,-7,STONE:0)
Block(-7,41,-6,STONE:0)
Block(-7,41,-5,STONE:0)
Block(-7,41,-4,STONE:0)
Block(-7,41,-3,STONE:0)
Block(-7,41,-2,STONE:0)
Block(-7,41,-1,STONE:0)
Block(-7,41,0,STONE:0)
Block(-7,41,1,STONE:0)
Block(-7,41,2,STONE:0)
Block(-7,41,3,STONE:0)
Block(-7,41,4,STONE:0)
Block(-7,41,5,STONE:0)
Block(-7,41,6,STONE:0)
Block(-7,41,7,STONE:0)
Block(-7,41,8,STONE:0)
Block(-7,42,-7,STONE:5)
Block(-7,42,-6,STONE:5)
Block(-7,42,-5,STONE:5)
Block(-7,42,-4,STONE:5)
Block(-7,42,-3,STONE:5)
Block(-7,42,-2,STONE:0)
Block(-7,42,-1,STONE:0)
Block(-7,42,0,STONE:0)
Block(-7,42,1,STONE:0)
Block(-7,42,2,STONE:0)
Block(-7,42,3,STONE:0)
Block(-7,42,4,STONE:0)
Block(-7,42,5,STONE:0)
Block(-7,42,6,STONE:0)
Block(-7,42,7,STONE:0)
Block(-7,42,8,STONE:0)
Block(-7,43,-7,STONE:5)
Block(-7,43,-6,STONE:5)
Block(-7,43,-5,STONE:5)
Block(-7,43,-4,STONE:5)
Block(-7,43,-3,STONE:5)
Block(-7,43,-2,STONE:5)
Block(-7,43,-1,STONE:5)
Block(-7,43,0,STONE:5)
Block(-7,43,1,STONE:5)
Block(-7,43,2,STONE:0)
Block(-7,43,3,STONE:0)
Block(-7,43,4,STONE:0)
Block(-7,43,5,STONE:0)
Block(-7,43,6,STONE:5)
Block(-7,43,7,STONE:5)
Block(-7,43,8,STONE:5)
Block(-7,44,-7,STONE:5)
Block(-7,44,-6,STONE:5)
Block(-7,44,-5,STONE:5)
Block(-7,44,-4,STONE:5)
Block(-7,44,-3,STONE:5)
Block(-7,44,-2,STONE:5)
Block(-7,44,-1,STONE:5)
Block(-7,44,0,STONE:5)
Block(-7,44,1,STONE:5)
Block(-7,44,2,STONE:5)
Block(-7,44,3,STONE:5)
Block(-7,44,4,STONE:5)
Block(-7,44,5,STONE:5)
Block(-7,44,6,STONE:5)
Block(-7,44,7,STONE:5)
Block(-7,44,8,STONE:5)
Block(-7,45,-7,STONE:5)
Block(-7,45,-6,STONE:5)
Block(-7,45,-5,STONE:5)
Block(-7,45,-4,STONE:5)
Block(-7,45,-3,STONE:5)
Block(-7,45,-2,STONE:5)
Block(-7,45,-1,STONE:5)
Block(-7,45,0,STONE:5)
Block(-7,45,1,STONE:5)
Block(-7,45,2,STONE:5)
Block(-7,45,3,STONE:5)
Block(-7,45,4,STONE:5)
Block(-7,45,5,STONE:5)
Block(-7,45,6,STONE:5)
Block(-7,45,7,STONE:5)
Block(-7,45,8,STONE:5)
Block(-7,46,-7,STONE:5)
Block(-7,46,-6,STONE:5)
Block(-7,46,-5,STONE:5)
Block(-7,46,-4,STONE:5)
Block(-7,46,-3,STONE:5)
Block(-7,46,-2,STONE:5)
Block(-7,46,-1,STONE:5)
Block(-7,46,0,STONE:5)
Block(-7,46,1,STONE:5)
Block(-7,46,2,STONE:5)
Block(-7,46,3,STONE:5)
Block(-7,46,4,STONE:5)
Block(-7,46,5,STONE:5)
Block(-7,46,6,STONE:5)
Block(-7,46,7,STONE:5)
Block(-7,46,8,STONE:5)
Block(-7,47,-6,STONE:5)
Block(-7,47,-5,STONE:5)
Block(-7,47,-4,STONE:5)
Block(-7,47,-3,STONE:5)
Block(-7,47,-2,STONE:5)
Block(-7,47,-1,STONE:5)
Block(-7,47,0,STONE:5)
Block(-7,47,1,STONE:5)
Block(-7,47,2,STONE:5)
Block(-7,47,3,STONE:5)
Block(-7,47,4,STONE:5)
Block(-7,47,5,STONE:5)
Block(-7,47,6,STONE:5)
Block(-7,47,7,STONE:5)
Block(-7,47,8,STONE:5)
Block(-7,48,0,STONE:5)
Block(-7,48,1,STONE:5)
Block(-7,48,2,STONE:5)
Block(-7,48,3,STONE:5)
Block(-7,48,4,STONE:5)
Block(-7,48,5,STONE:5)
Block(-7,48,6,STONE:5)
Block(-7,48,7,STONE:5)
Block(-7,48,8,OBSIDIAN:0)
Block(-7,49,5,STONE:5)
Block(-7,49,6,STONE:5)
Block(-7,49,7,STONE:5)
Block(-7,49,8,OBSIDIAN:0)
Block(-7,50,6,STONE:5)
Block(-7,50,7,STONE:5)
Block(-7,50,8,OBSIDIAN:0)
Block(-6,11,5,OBSIDIAN:0)
Block(-6,11,6,OBSIDIAN:0)
Block(-6,11,7,OBSIDIAN:0)
Block(-6,11,8,STONE:5)
Block(-6,12,0,OBSIDIAN:0)
Block(-6,12,1,OBSIDIAN:0)
Block(-6,12,2,OBSIDIAN:0)
Block(-6,12,3,OBSIDIAN:0)
Block(-6,12,4,OBSIDIAN:0)
Block(-6,12,5,OBSIDIAN:0)
Block(-6,12,6,OBSIDIAN:0)
Block(-6,12,7,OBSIDIAN:0)
Block(-6,12,8,STONE:5)
Block(-6,13,-1,OBSIDIAN:0)
Block(-6,13,0,OBSIDIAN:0)
Block(-6,13,1,OBSIDIAN:0)
Block(-6,13,2,OBSIDIAN:0)
Block(-6,13,3,OBSIDIAN:0)
Block(-6,13,4,OBSIDIAN:0)
Block(-6,13,5,OBSIDIAN:0)
Block(-6,13,6,OBSIDIAN:0)
Block(-6,13,7,OBSIDIAN:0)
Block(-6,13,8,STONE:5)
Block(-6,14,-2,STONE:5)
Block(-6,14,-1,STONE:5)
Block(-6,14,0,OBSIDIAN:0)
Block(-6,14,1,OBSIDIAN:0)
Block(-6,14,2,OBSIDIAN:0)
Block(-6,14,3,OBSIDIAN:0)
Block(-6,14,4,STONE:5)
Block(-6,14,5,STONE:5)
Block(-6,14,6,STONE:5)
Block(-6,14,7,STONE:5)
Block(-6,14,8,STONE:5)
Block(-6,15,-7,STONE:5)
Block(-6,15,-6,STONE:5)
Block(-6,15,-5,STONE:5)
Block(-6,15,-4,STONE:5)
Block(-6,15,-3,STONE:5)
Block(-6,15,-2,STONE:5)
Block(-6,15,-1,STONE:5)
Block(-6,15,0,STONE:5)
Block(-6,15,1,STONE:5)
Block(-6,15,2,STONE:5)
Block(-6,15,3,STONE:5)
Block(-6,15,4,STONE:5)
Block(-6,15,5,STONE:5)
Block(-6,15,6,STONE:5)
Block(-6,15,7,STONE:5)
Block(-6,15,8,STONE:5)
Block(-6,16,-7,STONE:5)
Block(-6,16,-6,STONE:5)
Block(-6,16,-5,STONE:5)
Block(-6,16,-4,STONE:5)
Block(-6,16,-3,STONE:5)
Block(-6,16,-2,STONE:5)
Block(-6,16,-1,STONE:5)
Block(-6,16,0,STONE:5)
Block(-6,16,1,STONE:5)
Block(-6,16,2,STONE:5)
Block(-6,16,3,STONE:5)
Block(-6,16,4,STONE:5)
Block(-6,16,5,STONE:5)
Block(-6,16,6,STONE:5)
Block(-6,16,7,STONE:5)
Block(-6,16,8,STONE:5)
Block(-6,17,-7,STONE:5)
Block(-6,17,-6,STONE:5)
Block(-6,17,-5,STONE:5)
Block(-6,17,-4,STONE:5)
Block(-6,17,-3,STONE:5)
Block(-6,17,-2,STONE:5)
Block(-6,17,-1,STONE:5)
Block(-6,17,0,STONE:5)
Block(-6,17,1,STONE:5)
Block(-6,17,2,STONE:5)
Block(-6,17,3,STONE:5)
Block(-6,17,4,STONE:5)
Block(-6,17,5,STONE:5)
Block(-6,17,6,STONE:5)
Block(-6,17,7,STONE:5)
Block(-6,17,8,STONE:5)
Block(-6,18,-7,STONE:5)
Block(-6,18,-6,STONE:5)
Block(-6,18,-5,STONE:5)
Block(-6,18,-4,STONE:5)
Block(-6,18,-3,STONE:5)
Block(-6,18,-2,STONE:5)
Block(-6,18,-1,STONE:5)
Block(-6,18,0,STONE:5)
Block(-6,18,1,STONE:5)
Block(-6,18,2,STONE:0)
Block(-6,18,3,STONE:0)
Block(-6,18,4,STONE:5)
Block(-6,18,5,STONE:5)
Block(-6,18,6,STONE:5)
Block(-6,18,7,STONE:5)
Block(-6,18,8,STONE:5)
Block(-6,19,-7,STONE:5)
Block(-6,19,-6,STONE:5)
Block(-6,19,-5,STONE:5)
Block(-6,19,-4,STONE:5)
Block(-6,19,-3,STONE:5)
Block(-6,19,-2,STONE:5)
Block(-6,19,-1,STONE:5)
Block(-6,19,0,STONE:5)
Block(-6,19,1,STONE:0)
Block(-6,19,2,STONE:0)
Block(-6,19,3,STONE:0)
Block(-6,19,4,MAGMA:0)
Block(-6,19,5,MAGMA:0)
Block(-6,19,6,MAGMA:0)
Block(-6,19,7,STONE:5)
Block(-6,19,8,STONE:5)
Block(-6,20,-7,STONE:5)
Block(-6,20,-6,STONE:5)
Block(-6,20,-5,STONE:5)
Block(-6,20,-4,STONE:5)
Block(-6,20,-3,STONE:0)
Block(-6,20,-2,STONE:0)
Block(-6,20,-1,STONE:0)
Block(-6,20,0,STONE:0)
Block(-6,20,1,STONE:0)
Block(-6,20,2,STONE:0)
Block(-6,20,3,STONE:0)
Block(-6,20,4,MAGMA:0)
Block(-6,20,5,MAGMA:0)
Block(-6,20,6,MAGMA:0)
Block(-6,20,7,STONE:0)
Block(-6,20,8,STONE:0)
Block(-6,21,-7,STONE:0)
Block(-6,21,-6,STONE:0)
Block(-6,21,-5,STONE:0)
Block(-6,21,-4,STONE:0)
Block(-6,21,-3,STONE:0)
Block(-6,21,-2,STONE:0)
Block(-6,21,-1,STONE:0)
Block(-6,21,0,STONE:0)
Block(-6,21,1,STONE:0)
Block(-6,21,2,STONE:0)
Block(-6,21,3,STONE:0)
Block(-6,21,4,MAGMA:0)
Block(-6,21,5,MAGMA:0)
Block(-6,21,6,MAGMA:0)
Block(-6,21,7,OBSIDIAN:0)
Block(-6,21,8,OBSIDIAN:0)
Block(-6,22,-7,STONE:0)
Block(-6,22,-6,STONE:0)
Block(-6,22,-5,STONE:0)
Block(-6,22,-4,STONE:0)
Block(-6,22,-3,STONE:0)
Block(-6,22,-2,STONE:0)
Block(-6,22,-1,STONE:0)
Block(-6,22,0,STONE:0)
Block(-6,22,1,STONE:0)
Block(-6,22,2,STONE:0)
Block(-6,22,3,STONE:0)
Block(-6,22,4,STONE:0)
Block(-6,22,5,STONE:0)
Block(-6,22,6,MAGMA:0)
Block(-6,22,7,MAGMA:0)
Block(-6,22,8,OBSIDIAN:0)
Block(-6,23,-7,STONE:0)
Block(-6,23,-6,STONE:0)
Block(-6,23,-5,STONE:0)
Block(-6,23,-4,STONE:0)
Block(-6,23,-3,GRASS:0)
Block(-6,23,-2,GRASS:0)
Block(-6,23,-1,STONE:0)
Block(-6,23,0,STONE:0)
Block(-6,23,1,STONE:0)
Block(-6,23,2,STONE:0)
Block(-6,23,3,STONE:0)
Block(-6,23,4,STONE:0)
Block(-6,23,5,MAGMA:0)
Block(-6,23,6,MAGMA:0)
Block(-6,23,7,MAGMA:0)
Block(-6,23,8,MAGMA:0)
Block(-6,24,-7,STONE:0)
Block(-6,24,-6,STONE:0)
Block(-6,24,-5,STONE:0)
Block(-6,24,-4,GRASS:0)
Block(-6,24,-1,GRASS:0)
Block(-6,24,0,STONE:0)
Block(-6,24,1,STONE:0)
Block(-6,24,2,STONE:0)
Block(-6,24,3,STONE:0)
Block(-6,24,4,STONE:0)
Block(-6,24,5,MAGMA:0)
Block(-6,24,6,MAGMA:0)
Block(-6,24,7,MAGMA:0)
Block(-6,24,8,MAGMA:0)
Block(-6,25,-7,STONE:0)
Block(-6,25,-6,STONE:0)
Block(-6,25,-5,GRASS:0)
Block(-6,25,0,GRASS:0)
Block(-6,25,1,GRASS:0)
Block(-6,25,2,GRASS:0)
Block(-6,25,3,GRASS:0)
Block(-6,25,4,GRASS:0)
Block(-6,26,-7,GRASS:0)
Block(-6,26,-6,GRASS:0)
Block(-6,35,8,STONE:0)
Block(-6,36,7,STONE:0)
Block(-6,36,8,STONE:0)
Block(-6,37,-7,STONE:0)
Block(-6,37,-6,STONE:0)
Block(-6,37,-5,MAGMA:0)
Block(-6,37,-4,MAGMA:0)
Block(-6,37,-3,MAGMA:0)
Block(-6,37,-2,MAGMA:0)
Block(-6,37,-1,OBSIDIAN:0)
Block(-6,37,4,OBSIDIAN:0)
Block(-6,37,5,OBSIDIAN:0)
Block(-6,37,6,OBSIDIAN:0)
Block(-6,37,7,OBSIDIAN:0)
Block(-6,37,8,STONE:0)
Block(-6,38,-7,STONE:0)
Block(-6,38,-6,STONE:0)
Block(-6,38,-5,MAGMA:0)
Block(-6,38,-4,MAGMA:0)
Block(-6,38,-3,MAGMA:0)
Block(-6,38,-2,MAGMA:0)
Block(-6,38,-1,MAGMA:0)
Block(-6,38,0,MAGMA:0)
Block(-6,38,1,MAGMA:0)
Block(-6,38,2,OBSIDIAN:0)
Block(-6,38,3,OBSIDIAN:0)
Block(-6,38,4,OBSIDIAN:0)
Block(-6,38,5,OBSIDIAN:0)
Block(-6,38,6,OBSIDIAN:0)
Block(-6,38,7,OBSIDIAN:0)
Block(-6,38,8,STONE:0)
Block(-6,39,-7,STONE:0)
Block(-6,39,-6,STONE:0)
Block(-6,39,-5,STONE:0)
Block(-6,39,-4,MAGMA:0)
Block(-6,39,-3,MAGMA:0)
Block(-6,39,-2,MAGMA:0)
Block(-6,39,-1,MAGMA:0)
Block(-6,39,0,MAGMA:0)
Block(-6,39,1,MAGMA:0)
Block(-6,39,2,MAGMA:0)
Block(-6,39,3,MAGMA:0)
Block(-6,39,4,MAGMA:0)
Block(-6,39,5,MAGMA:0)
Block(-6,39,6,OBSIDIAN:0)
Block(-6,39,7,OBSIDIAN:0)
Block(-6,39,8,STONE:0)
Block(-6,40,-7,STONE:0)
Block(-6,40,-6,STONE:0)
Block(-6,40,-5,STONE:0)
Block(-6,40,-4,STONE:0)
Block(-6,40,-3,MAGMA:0)
Block(-6,40,-2,MAGMA:0)
Block(-6,40,-1,MAGMA:0)
Block(-6,40,0,STONE:0)
Block(-6,40,1,MAGMA:0)
Block(-6,40,2,MAGMA:0)
Block(-6,40,3,MAGMA:0)
Block(-6,40,4,MAGMA:0)
Block(-6,40,5,MAGMA:0)
Block(-6,40,6,MAGMA:0)
Block(-6,40,7,OBSIDIAN:0)
Block(-6,40,8,STONE:0)
Block(-6,41,-7,STONE:0)
Block(-6,41,-6,STONE:0)
Block(-6,41,-5,STONE:0)
Block(-6,41,-4,STONE:0)
Block(-6,41,-3,STONE:0)
Block(-6,41,-2,STONE:0)
Block(-6,41,-1,STONE:0)
Block(-6,41,0,STONE:0)
Block(-6,41,1,STONE:0)
Block(-6,41,2,STONE:0)
Block(-6,41,3,MAGMA:0)
Block(-6,41,4,MAGMA:0)
Block(-6,41,5,MAGMA:0)
Block(-6,41,6,MAGMA:0)
Block(-6,41,7,MAGMA:0)
Block(-6,41,8,STONE:0)
Block(-6,42,-7,STONE:0)
Block(-6,42,-6,STONE:5)
Block(-6,42,-5,STONE:5)
Block(-6,42,-4,STONE:5)
Block(-6,42,-3,STONE:0)
Block(-6,42,-2,STONE:0)
Block(-6,42,-1,STONE:0)
Block(-6,42,0,STONE:0)
Block(-6,42,1,STONE:0)
Block(-6,42,2,STONE:0)
Block(-6,42,3,STONE:0)
Block(-6,42,4,STONE:0)
Block(-6,42,5,STONE:0)
Block(-6,42,6,STONE:0)
Block(-6,42,7,STONE:0)
Block(-6,42,8,STONE:0)
Block(-6,43,-7,STONE:5)
Block(-6,43,-6,STONE:5)
Block(-6,43,-5,STONE:5)
Block(-6,43,-4,STONE:5)
Block(-6,43,-3,STONE:5)
Block(-6,43,-2,STONE:5)
Block(-6,43,-1,STONE:5)
Block(-6,43,0,STONE:5)
Block(-6,43,1,STONE:5)
Block(-6,43,2,STONE:5)
Block(-6,43,3,STONE:0)
Block(-6,43,4,STONE:0)
Block(-6,43,5,STONE:0)
Block(-6,43,6,STONE:0)
Block(-6,43,7,STONE:0)
Block(-6,43,8,STONE:0)
Block(-6,44,-7,STONE:5)
Block(-6,44,-6,STONE:5)
Block(-6,44,-5,STONE:5)
Block(-6,44,-4,STONE:5)
Block(-6,44,-3,STONE:5)
Block(-6,44,-2,STONE:5)
Block(-6,44,-1,STONE:5)
Block(-6,44,0,STONE:5)
Block(-6,44,1,STONE:5)
Block(-6,44,2,STONE:5)
Block(-6,44,3,STONE:5)
Block(-6,44,4,STONE:0)
Block(-6,44,5,STONE:0)
Block(-6,44,6,STONE:5)
Block(-6,44,7,STONE:5)
Block(-6,44,8,STONE:5)
Block(-6,45,-7,STONE:5)
Block(-6,45,-6,STONE:5)
Block(-6,45,-5,STONE:5)
Block(-6,45,-4,STONE:5)
Block(-6,45,-3,STONE:5)
Block(-6,45,-2,STONE:5)
Block(-6,45,-1,STONE:5)
Block(-6,45,0,STONE:5)
Block(-6,45,1,STONE:5)
Block(-6,45,2,STONE:5)
Block(-6,45,3,STONE:5)
Block(-6,45,4,STONE:5)
Block(-6,45,5,STONE:5)
Block(-6,45,6,STONE:5)
Block(-6,45,7,STONE:5)
Block(-6,45,8,STONE:5)
Block(-6,46,-7,STONE:5)
Block(-6,46,-6,STONE:5)
Block(-6,46,-5,STONE:5)
Block(-6,46,-4,STONE:5)
Block(-6,46,-3,STONE:5)
Block(-6,46,-2,STONE:5)
Block(-6,46,-1,STONE:5)
Block(-6,46,0,STONE:5)
Block(-6,46,1,STONE:5)
Block(-6,46,2,STONE:5)
Block(-6,46,3,STONE:5)
Block(-6,46,4,STONE:5)
Block(-6,46,5,STONE:5)
Block(-6,46,6,STONE:5)
Block(-6,46,7,STONE:5)
Block(-6,46,8,STONE:5)
Block(-6,47,-6,STONE:5)
Block(-6,47,-5,STONE:5)
Block(-6,47,-4,STONE:5)
Block(-6,47,-3,STONE:5)
Block(-6,47,-2,STONE:5)
Block(-6,47,-1,STONE:5)
Block(-6,47,0,STONE:5)
Block(-6,47,1,STONE:5)
Block(-6,47,2,STONE:5)
Block(-6,47,3,STONE:5)
Block(-6,47,4,STONE:5)
Block(-6,47,5,STONE:5)
Block(-6,47,6,STONE:5)
Block(-6,47,7,STONE:5)
Block(-6,47,8,STONE:5)
Block(-6,48,0,STONE:5)
Block(-6,48,1,STONE:5)
Block(-6,48,2,STONE:5)
Block(-6,48,3,STONE:5)
Block(-6,48,4,STONE:5)
Block(-6,48,5,STONE:5)
Block(-6,48,6,STONE:5)
Block(-6,48,7,STONE:5)
Block(-6,48,8,STONE:5)
Block(-6,49,4,STONE:5)
Block(-6,49,5,STONE:5)
Block(-6,49,6,STONE:5)
Block(-6,49,7,STONE:5)
Block(-6,49,8,STONE:5)
Block(-6,50,5,STONE:5)
Block(-6,50,6,STONE:5)
Block(-6,50,7,STONE:5)
Block(-6,50,8,STONE:5)
Block(-6,51,6,STONE:5)
Block(-6,51,7,STONE:5)
Block(-6,51,8,STONE:5)
Block(-5,11,6,OBSIDIAN:0)
Block(-5,11,7,OBSIDIAN:0)
Block(-5,11,8,OBSIDIAN:0)
Block(-5,12,0,OBSIDIAN:0)
Block(-5,12,1,OBSIDIAN:0)
Block(-5,12,2,OBSIDIAN:0)
Block(-5,12,3,OBSIDIAN:0)
Block(-5,12,4,OBSIDIAN:0)
Block(-5,12,5,OBSIDIAN:0)
Block(-5,12,6,OBSIDIAN:0)
Block(-5,12,7,OBSIDIAN:0)
Block(-5,12,8,OBSIDIAN:0)
Block(-5,13,-1,OBSIDIAN:0)
Block(-5,13,0,OBSIDIAN:0)
Block(-5,13,1,OBSIDIAN:0)
Block(-5,13,2,OBSIDIAN:0)
Block(-5,13,3,OBSIDIAN:0)
Block(-5,13,4,OBSIDIAN:0)
Block(-5,13,5,OBSIDIAN:0)
Block(-5,13,6,OBSIDIAN:0)
Block(-5,13,7,OBSIDIAN:0)
Block(-5,13,8,OBSIDIAN:0)
Block(-5,14,-2,STONE:5)
Block(-5,14,-1,STONE:5)
Block(-5,14,0,OBSIDIAN:0)
Block(-5,14,1,OBSIDIAN:0)
Block(-5,14,2,OBSIDIAN:0)
Block(-5,14,3,OBSIDIAN:0)
Block(-5,14,4,OBSIDIAN:0)
Block(-5,14,5,OBSIDIAN:0)
Block(-5,14,6,OBSIDIAN:0)
Block(-5,14,7,OBSIDIAN:0)
Block(-5,14,8,STONE:5)
Block(-5,15,-7,STONE:5)
Block(-5,15,-6,STONE:5)
Block(-5,15,-5,STONE:5)
Block(-5,15,-3,STONE:5)
Block(-5,15,-2,STONE:5)
Block(-5,15,-1,STONE:5)
Block(-5,15,0,STONE:5)
Block(-5,15,1,STONE:5)
Block(-5,15,2,STONE:5)
Block(-5,15,3,STONE:5)
Block(-5,15,4,STONE:5)
Block(-5,15,5,STONE:5)
Block(-5,15,6,STONE:5)
Block(-5,15,7,STONE:5)
Block(-5,15,8,STONE:5)
Block(-5,16,-7,STONE:5)
Block(-5,16,-6,STONE:5)
Block(-5,16,-5,STONE:5)
Block(-5,16,-4,STONE:5)
Block(-5,16,-3,STONE:5)
Block(-5,16,-2,STONE:5)
Block(-5,16,-1,STONE:5)
Block(-5,16,0,STONE:5)
Block(-5,16,1,STONE:5)
Block(-5,16,2,STONE:5)
Block(-5,16,3,STONE:5)
Block(-5,16,4,STONE:5)
Block(-5,16,5,STONE:5)
Block(-5,16,6,STONE:5)
Block(-5,16,7,STONE:5)
Block(-5,16,8,STONE:5)
Block(-5,17,-7,STONE:5)
Block(-5,17,-6,STONE:5)
Block(-5,17,-5,STONE:5)
Block(-5,17,-4,STONE:5)
Block(-5,17,-3,STONE:5)
Block(-5,17,-2,STONE:5)
Block(-5,17,-1,STONE:5)
Block(-5,17,0,STONE:5)
Block(-5,17,1,STONE:5)
Block(-5,17,2,STONE:5)
Block(-5,17,3,STONE:5)
Block(-5,17,4,STONE:5)
Block(-5,17,5,STONE:5)
Block(-5,17,6,STONE:5)
Block(-5,17,7,STONE:5)
Block(-5,17,8,STONE:5)
Block(-5,18,-7,STONE:5)
Block(-5,18,-6,STONE:5)
Block(-5,18,-5,STONE:5)
Block(-5,18,-4,STONE:5)
Block(-5,18,-3,STONE:5)
Block(-5,18,-2,STONE:5)
Block(-5,18,-1,STONE:5)
Block(-5,18,0,STONE:5)
Block(-5,18,1,STONE:0)
Block(-5,18,2,STONE:5)
Block(-5,18,3,MAGMA:0)
Block(-5,18,4,MAGMA:0)
Block(-5,18,5,MAGMA:0)
Block(-5,18,6,MAGMA:0)
Block(-5,18,7,MAGMA:0)
Block(-5,18,8,STONE:5)
Block(-5,19,-7,STONE:5)
Block(-5,19,-6,STONE:5)
Block(-5,19,-5,STONE:5)
Block(-5,19,-4,STONE:5)
Block(-5,19,-3,STONE:5)
Block(-5,19,-2,STONE:0)
Block(-5,19,-1,STONE:0)
Block(-5,19,0,STONE:0)
Block(-5,19,1,STONE:0)
Block(-5,19,2,STONE:0)
Block(-5,19,3,MAGMA:0)
Block(-5,19,4,MAGMA:0)
Block(-5,19,5,MAGMA:0)
Block(-5,19,6,MAGMA:0)
Block(-5,19,7,MAGMA:0)
Block(-5,19,8,STONE:5)
Block(-5,20,-7,STONE:5)
Block(-5,20,-6,STONE:5)
Block(-5,20,-5,STONE:5)
Block(-5,20,-4,STONE:0)
Block(-5,20,-3,STONE:0)
Block(-5,20,-2,STONE:0)
Block(-5,20,-1,STONE:0)
Block(-5,20,0,STONE:0)
Block(-5,20,1,STONE:0)
Block(-5,20,2,STONE:0)
Block(-5,20,3,MAGMA:0)
Block(-5,20,4,MAGMA:0)
Block(-5,20,5,MAGMA:0)
Block(-5,20,6,MAGMA:0)
Block(-5,20,7,OBSIDIAN:0)
Block(-5,20,8,STONE:5)
Block(-5,21,-7,STONE:0)
Block(-5,21,-6,STONE:0)
Block(-5,21,-5,STONE:0)
Block(-5,21,-4,STONE:0)
Block(-5,21,-3,STONE:0)
Block(-5,21,-2,STONE:0)
Block(-5,21,-1,STONE:0)
Block(-5,21,0,STONE:0)
Block(-5,21,1,STONE:0)
Block(-5,21,2,STONE:0)
Block(-5,21,3,MAGMA:0)
Block(-5,21,4,MAGMA:0)
Block(-5,21,5,MAGMA:0)
Block(-5,21,6,MAGMA:0)
Block(-5,21,7,OBSIDIAN:0)
Block(-5,21,8,OBSIDIAN:0)
Block(-5,22,-7,STONE:0)
Block(-5,22,-6,STONE:0)
Block(-5,22,-5,STONE:0)
Block(-5,22,-4,STONE:0)
Block(-5,22,-3,STONE:0)
Block(-5,22,-2,GRASS:0)
Block(-5,22,-1,STONE:0)
Block(-5,22,0,STONE:0)
Block(-5,22,1,STONE:0)
Block(-5,22,2,STONE:0)
Block(-5,22,3,MAGMA:0)
Block(-5,22,4,MAGMA:0)
Block(-5,22,5,MAGMA:0)
Block(-5,22,6,MAGMA:0)
Block(-5,22,7,OBSIDIAN:0)
Block(-5,22,8,OBSIDIAN:0)
Block(-5,23,-7,STONE:0)
Block(-5,23,-6,STONE:0)
Block(-5,23,-5,STONE:0)
Block(-5,23,-4,STONE:0)
Block(-5,23,-3,GRASS:0)
Block(-5,23,-1,GRASS:0)
Block(-5,23,0,STONE:0)
Block(-5,23,1,STONE:0)
Block(-5,23,2,STONE:0)
Block(-5,23,3,STONE:0)
Block(-5,23,4,STONE:0)
Block(-5,23,5,MAGMA:0)
Block(-5,23,7,MAGMA:0)
Block(-5,23,8,MAGMA:0)
Block(-5,24,-7,STONE:0)
Block(-5,24,-6,STONE:0)
Block(-5,24,-5,STONE:0)
Block(-5,24,-4,GRASS:0)
Block(-5,24,0,GRASS:0)
Block(-5,24,1,GRASS:0)
Block(-5,24,2,GRASS:0)
Block(-5,24,3,GRASS:0)
Block(-5,24,4,GRASS:0)
Block(-5,25,-7,GRASS:0)
Block(-5,25,-6,GRASS:0)
Block(-5,25,-5,GRASS:0)
Block(-5,37,-6,STONE:0)
Block(-5,37,-5,MAGMA:0)
Block(-5,37,-4,MAGMA:0)
Block(-5,37,-3,MAGMA:0)
Block(-5,37,-2,MAGMA:0)
Block(-5,37,8,STONE:0)
Block(-5,38,-7,STONE:0)
Block(-5,38,-6,STONE:0)
Block(-5,38,-5,MAGMA:0)
Block(-5,38,-4,MAGMA:0)
Block(-5,38,-3,MAGMA:0)
Block(-5,38,-2,MAGMA:0)
Block(-5,38,-1,MAGMA:0)
Block(-5,38,0,MAGMA:0)
Block(-5,38,1,OBSIDIAN:0)
Block(-5,38,2,OBSIDIAN:0)
Block(-5,38,3,OBSIDIAN:0)
Block(-5,38,4,OBSIDIAN:0)
Block(-5,38,8,OBSIDIAN:0)
Block(-5,39,-7,STONE:0)
Block(-5,39,-6,STONE:0)
Block(-5,39,-5,STONE:0)
Block(-5,39,-4,MAGMA:0)
Block(-5,39,-3,MAGMA:0)
Block(-5,39,-2,MAGMA:0)
Block(-5,39,-1,MAGMA:0)
Block(-5,39,0,MAGMA:0)
Block(-5,39,1,MAGMA:0)
Block(-5,39,2,OBSIDIAN:0)
Block(-5,39,3,MAGMA:0)
Block(-5,39,4,MAGMA:0)
Block(-5,39,5,MAGMA:0)
Block(-5,39,6,OBSIDIAN:0)
Block(-5,39,7,OBSIDIAN:0)
Block(-5,39,8,OBSIDIAN:0)
Block(-5,40,-7,STONE:0)
Block(-5,40,-6,STONE:0)
Block(-5,40,-5,STONE:0)
Block(-5,40,-4,STONE:0)
Block(-5,40,-3,MAGMA:0)
Block(-5,40,-2,MAGMA:0)
Block(-5,40,-1,MAGMA:0)
Block(-5,40,0,STONE:0)
Block(-5,40,1,MAGMA:0)
Block(-5,40,2,MAGMA:0)
Block(-5,40,3,MAGMA:0)
Block(-5,40,4,MAGMA:0)
Block(-5,40,5,MAGMA:0)
Block(-5,40,6,OBSIDIAN:0)
Block(-5,40,7,OBSIDIAN:0)
Block(-5,40,8,OBSIDIAN:0)
Block(-5,41,-7,STONE:0)
Block(-5,41,-6,STONE:0)
Block(-5,41,-5,STONE:0)
Block(-5,41,-4,STONE:0)
Block(-5,41,-3,STONE:0)
Block(-5,41,-2,STONE:0)
Block(-5,41,-1,STONE:0)
Block(-5,41,0,STONE:0)
Block(-5,41,1,STONE:0)
Block(-5,41,2,MAGMA:0)
Block(-5,41,3,MAGMA:0)
Block(-5,41,4,MAGMA:0)
Block(-5,41,5,MAGMA:0)
Block(-5,41,6,MAGMA:0)
Block(-5,41,7,OBSIDIAN:0)
Block(-5,41,8,STONE:0)
Block(-5,42,-7,STONE:0)
Block(-5,42,-6,STONE:0)
Block(-5,42,-5,STONE:0)
Block(-5,42,-4,STONE:0)
Block(-5,42,-3,STONE:0)
Block(-5,42,-2,STONE:0)
Block(-5,42,-1,STONE:0)
Block(-5,42,0,STONE:0)
Block(-5,42,1,STONE:0)
Block(-5,42,2,STONE:0)
Block(-5,42,3,MAGMA:0)
Block(-5,42,4,MAGMA:0)
Block(-5,42,5,MAGMA:0)
Block(-5,42,6,MAGMA:0)
Block(-5,42,7,MAGMA:0)
Block(-5,42,8,STONE:0)
Block(-5,43,-7,STONE:5)
Block(-5,43,-6,STONE:5)
Block(-5,43,-5,STONE:5)
Block(-5,43,-4,STONE:5)
Block(-5,43,-3,STONE:5)
Block(-5,43,-2,STONE:5)
Block(-5,43,-1,STONE:5)
Block(-5,43,0,STONE:5)
Block(-5,43,1,STONE:5)
Block(-5,43,2,STONE:5)
Block(-5,43,3,STONE:0)
Block(-5,43,4,STONE:0)
Block(-5,43,5,STONE:0)
Block(-5,43,6,STONE:0)
Block(-5,43,7,STONE:0)
Block(-5,43,8,STONE:0)
Block(-5,44,-7,STONE:5)
Block(-5,44,-6,STONE:5)
Block(-5,44,-5,STONE:5)
Block(-5,44,-4,STONE:5)
Block(-5,44,-3,STONE:5)
Block(-5,44,-2,STONE:5)
Block(-5,44,-1,STONE:5)
Block(-5,44,0,STONE:5)
Block(-5,44,1,STONE:5)
Block(-5,44,2,STONE:5)
Block(-5,44,3,STONE:5)
Block(-5,44,4,STONE:0)
Block(-5,44,5,STONE:0)
Block(-5,44,6,STONE:0)
Block(-5,44,7,STONE:0)
Block(-5,44,8,STONE:0)
Block(-5,45,-7,STONE:5)
Block(-5,45,-6,STONE:5)
Block(-5,45,-5,STONE:5)
Block(-5,45,-4,STONE:5)
Block(-5,45,-3,STONE:5)
Block(-5,45,-2,STONE:5)
Block(-5,45,-1,STONE:5)
Block(-5,45,0,STONE:5)
Block(-5,45,1,STONE:5)
Block(-5,45,2,STONE:5)
Block(-5,45,3,STONE:5)
Block(-5,45,4,STONE:5)
Block(-5,45,5,STONE:5)
Block(-5,45,6,STONE:5)
Block(-5,45,7,STONE:5)
Block(-5,45,8,STONE:5)
Block(-5,46,-7,STONE:5)
Block(-5,46,-6,STONE:5)
Block(-5,46,-5,STONE:5)
Block(-5,46,-4,STONE:5)
Block(-5,46,-3,STONE:5)
Block(-5,46,-2,STONE:5)
Block(-5,46,-1,STONE:5)
Block(-5,46,0,STONE:5)
Block(-5,46,1,STONE:5)
Block(-5,46,2,STONE:5)
Block(-5,46,3,STONE:5)
Block(-5,46,4,STONE:5)
Block(-5,46,5,STONE:5)
Block(-5,46,6,STONE:5)
Block(-5,46,7,STONE:5)
Block(-5,46,8,STONE:5)
Block(-5,47,-6,STONE:5)
Block(-5,47,-5,STONE:5)
Block(-5,47,-4,STONE:5)
Block(-5,47,-3,STONE:5)
Block(-5,47,-2,STONE:5)
Block(-5,47,-1,STONE:5)
Block(-5,47,0,STONE:5)
Block(-5,47,1,STONE:5)
Block(-5,47,2,STONE:5)
Block(-5,47,3,STONE:5)
Block(-5,47,4,STONE:5)
Block(-5,47,5,STONE:5)
Block(-5,47,6,STONE:5)
Block(-5,47,7,STONE:5)
Block(-5,47,8,STONE:5)
Block(-5,48,0,STONE:5)
Block(-5,48,1,STONE:5)
Block(-5,48,2,STONE:5)
Block(-5,48,3,STONE:5)
Block(-5,48,4,STONE:5)
Block(-5,48,5,STONE:5)
Block(-5,48,6,STONE:5)
Block(-5,48,7,STONE:5)
Block(-5,48,8,STONE:5)
Block(-5,49,4,STONE:5)
Block(-5,49,5,STONE:5)
Block(-5,49,6,STONE:5)
Block(-5,49,7,STONE:5)
Block(-5,49,8,STONE:5)
Block(-5,50,4,STONE:5)
Block(-5,50,5,STONE:5)
Block(-5,50,6,STONE:5)
Block(-5,50,7,STONE:5)
Block(-5,50,8,STONE:5)
Block(-5,51,5,STONE:5)
Block(-5,51,6,STONE:5)
Block(-5,51,7,STONE:5)
Block(-5,51,8,STONE:5)
Block(-5,52,7,STONE:5)
Block(-5,52,8,STONE:5)
Block(-4,12,1,OBSIDIAN:0)
Block(-4,12,2,OBSIDIAN:0)
Block(-4,12,3,OBSIDIAN:0)
Block(-4,12,5,OBSIDIAN:0)
Block(-4,12,6,OBSIDIAN:0)
Block(-4,12,7,OBSIDIAN:0)
Block(-4,12,8,OBSIDIAN:0)
Block(-4,13,-1,OBSIDIAN:0)
Block(-4,13,0,OBSIDIAN:0)
Block(-4,13,1,OBSIDIAN:0)
Block(-4,13,2,OBSIDIAN:0)
Block(-4,13,3,OBSIDIAN:0)
Block(-4,13,4,OBSIDIAN:0)
Block(-4,13,5,OBSIDIAN:0)
Block(-4,13,6,OBSIDIAN:0)
Block(-4,13,7,OBSIDIAN:0)
Block(-4,13,8,OBSIDIAN:0)
Block(-4,14,-2,OBSIDIAN:0)
Block(-4,14,-1,STONE:5)
Block(-4,14,0,OBSIDIAN:0)
Block(-4,14,1,OBSIDIAN:0)
Block(-4,14,2,OBSIDIAN:0)
Block(-4,14,3,OBSIDIAN:0)
Block(-4,14,4,OBSIDIAN:0)
Block(-4,14,5,OBSIDIAN:0)
Block(-4,14,6,OBSIDIAN:0)
Block(-4,14,7,OBSIDIAN:0)
Block(-4,14,8,OBSIDIAN:0)
Block(-4,15,-7,STONE:5)
Block(-4,15,-6,STONE:5)
Block(-4,15,-2,OBSIDIAN:0)
Block(-4,15,-1,STONE:5)
Block(-4,15,0,STONE:5)
Block(-4,15,1,STONE:5)
Block(-4,15,2,STONE:5)
Block(-4,15,3,STONE:5)
Block(-4,15,4,STONE:5)
Block(-4,15,5,STONE:5)
Block(-4,15,6,STONE:5)
Block(-4,15,7,STONE:5)
Block(-4,15,8,STONE:5)
Block(-4,16,-7,STONE:5)
Block(-4,16,-6,STONE:5)
Block(-4,16,-5,OBSIDIAN:0)
Block(-4,16,-4,OBSIDIAN:0)
Block(-4,16,-3,OBSIDIAN:0)
Block(-4,16,-2,OBSIDIAN:0)
Block(-4,16,-1,STONE:5)
Block(-4,16,0,STONE:5)
Block(-4,16,1,STONE:5)
Block(-4,16,2,STONE:5)
Block(-4,16,3,STONE:5)
Block(-4,16,4,STONE:5)
Block(-4,16,5,STONE:5)
Block(-4,16,6,STONE:5)
Block(-4,16,7,STONE:5)
Block(-4,16,8,STONE:5)
Block(-4,17,-7,STONE:5)
Block(-4,17,-6,STONE:5)
Block(-4,17,-5,STONE:5)
Block(-4,17,-4,STONE:5)
Block(-4,17,-3,STONE:5)
Block(-4,17,-2,STONE:5)
Block(-4,17,-1,STONE:5)
Block(-4,17,0,STONE:5)
Block(-4,17,1,STONE:5)
Block(-4,17,2,STONE:5)
Block(-4,17,3,STONE:5)
Block(-4,17,4,MAGMA:0)
Block(-4,17,5,MAGMA:0)
Block(-4,17,6,MAGMA:0)
Block(-4,17,7,STONE:5)
Block(-4,17,8,STONE:5)
Block(-4,18,-7,STONE:5)
Block(-4,18,-6,STONE:5)
Block(-4,18,-5,STONE:5)
Block(-4,18,-4,STONE:5)
Block(-4,18,-3,STONE:5)
Block(-4,18,-2,STONE:0)
Block(-4,18,-1,STONE:0)
Block(-4,18,0,STONE:0)
Block(-4,18,1,STONE:5)
Block(-4,18,2,STONE:5)
Block(-4,18,3,MAGMA:0)
Block(-4,18,4,MAGMA:0)
Block(-4,18,5,MAGMA:0)
Block(-4,18,6,MAGMA:0)
Block(-4,18,7,OBSIDIAN:0)
Block(-4,18,8,STONE:5)
Block(-4,19,-7,STONE:5)
Block(-4,19,-6,STONE:5)
Block(-4,19,-5,STONE:5)
Block(-4,19,-4,STONE:5)
Block(-4,19,-3,STONE:0)
Block(-4,19,-2,STONE:0)
Block(-4,19,-1,STONE:0)
Block(-4,19,0,STONE:0)
Block(-4,19,1,STONE:0)
Block(-4,19,2,MAGMA:0)
Block(-4,19,3,MAGMA:0)
Block(-4,19,4,MAGMA:0)
Block(-4,19,5,MAGMA:0)
Block(-4,19,6,OBSIDIAN:0)
Block(-4,19,7,OBSIDIAN:0)
Block(-4,19,8,OBSIDIAN:0)
Block(-4,20,-7,STONE:0)
Block(-4,20,-6,STONE:0)
Block(-4,20,-5,STONE:0)
Block(-4,20,-4,STONE:0)
Block(-4,20,-3,STONE:0)
Block(-4,20,-2,STONE:0)
Block(-4,20,-1,STONE:0)
Block(-4,20,0,STONE:0)
Block(-4,20,1,STONE:0)
Block(-4,20,2,MAGMA:0)
Block(-4,20,3,MAGMA:0)
Block(-4,20,4,MAGMA:0)
Block(-4,20,5,MAGMA:0)
Block(-4,20,6,MAGMA:0)
Block(-4,20,7,OBSIDIAN:0)
Block(-4,20,8,OBSIDIAN:0)
Block(-4,21,-7,STONE:0)
Block(-4,21,-6,STONE:0)
Block(-4,21,-5,STONE:0)
Block(-4,21,-4,STONE:0)
Block(-4,21,-3,STONE:0)
Block(-4,21,-2,GRASS:0)
Block(-4,21,-1,GRASS:0)
Block(-4,21,0,STONE:0)
Block(-4,21,1,STONE:0)
Block(-4,21,2,MAGMA:0)
Block(-4,21,3,MAGMA:0)
Block(-4,21,4,MAGMA:0)
Block(-4,21,5,MAGMA:0)
Block(-4,21,6,STATIONARY_WATER:0)
Block(-4,21,7,STATIONARY_WATER:0)
Block(-4,21,8,STATIONARY_WATER:0)
Block(-4,22,-7,STONE:0)
Block(-4,22,-6,STONE:0)
Block(-4,22,-5,STONE:0)
Block(-4,22,-4,STONE:0)
Block(-4,22,-3,STONE:0)
Block(-4,22,0,GRASS:0)
Block(-4,22,1,STONE:0)
Block(-4,22,2,STONE:0)
Block(-4,22,3,MAGMA:0)
Block(-4,22,4,MAGMA:0)
Block(-4,22,5,STATIONARY_WATER:0)
Block(-4,22,6,STATIONARY_WATER:0)
Block(-4,22,7,STATIONARY_WATER:0)
Block(-4,22,8,STATIONARY_WATER:0)
Block(-4,23,-7,STONE:0)
Block(-4,23,-6,STONE:0)
Block(-4,23,-5,STONE:0)
Block(-4,23,-4,STONE:0)
Block(-4,23,-3,GRASS:0)
Block(-4,23,1,GRASS:0)
Block(-4,23,2,GRASS:0)
Block(-4,23,3,GRASS:0)
Block(-4,24,-7,STONE:0)
Block(-4,24,-6,STONE:0)
Block(-4,24,-5,GRASS:0)
Block(-4,24,-4,GRASS:0)
Block(-4,25,-7,GRASS:0)
Block(-4,25,-6,GRASS:0)
Block(-4,37,-5,STONE:0)
Block(-4,37,-4,MAGMA:0)
Block(-4,37,-3,MAGMA:0)
Block(-4,38,-7,STONE:0)
Block(-4,38,-6,STONE:0)
Block(-4,38,-5,STONE:0)
Block(-4,38,-4,MAGMA:0)
Block(-4,38,-3,MAGMA:0)
Block(-4,38,-2,MAGMA:0)
Block(-4,38,-1,MAGMA:0)
Block(-4,38,1,OBSIDIAN:0)
Block(-4,38,2,OBSIDIAN:0)
Block(-4,38,3,OBSIDIAN:0)
Block(-4,39,-7,STONE:0)
Block(-4,39,-6,STONE:0)
Block(-4,39,-5,STONE:0)
Block(-4,39,-4,MAGMA:0)
Block(-4,39,-3,MAGMA:0)
Block(-4,39,-2,MAGMA:0)
Block(-4,39,-1,MAGMA:0)
Block(-4,39,0,OBSIDIAN:0)
Block(-4,39,1,OBSIDIAN:0)
Block(-4,39,2,OBSIDIAN:0)
Block(-4,39,3,OBSIDIAN:0)
Block(-4,39,4,MAGMA:0)
Block(-4,39,5,MAGMA:0)
Block(-4,40,-7,STONE:0)
Block(-4,40,-6,STONE:0)
Block(-4,40,-5,STONE:0)
Block(-4,40,-4,STONE:0)
Block(-4,40,-3,STONE:0)
Block(-4,40,-2,STONE:0)
Block(-4,40,-1,STONE:0)
Block(-4,40,0,STONE:0)
Block(-4,40,1,OBSIDIAN:0)
Block(-4,40,2,OBSIDIAN:0)
Block(-4,40,3,MAGMA:0)
Block(-4,40,4,MAGMA:0)
Block(-4,40,5,MAGMA:0)
Block(-4,40,6,OBSIDIAN:0)
Block(-4,40,7,OBSIDIAN:0)
Block(-4,40,8,OBSIDIAN:0)
Block(-4,41,-7,STONE:0)
Block(-4,41,-6,STONE:0)
Block(-4,41,-5,STONE:0)
Block(-4,41,-4,STONE:0)
Block(-4,41,-3,STONE:0)
Block(-4,41,-2,STONE:0)
Block(-4,41,-1,STONE:0)
Block(-4,41,0,STONE:0)
Block(-4,41,1,STONE:0)
Block(-4,41,2,MAGMA:0)
Block(-4,41,3,MAGMA:0)
Block(-4,41,4,MAGMA:0)
Block(-4,41,5,OBSIDIAN:0)
Block(-4,41,6,OBSIDIAN:0)
Block(-4,41,7,OBSIDIAN:0)
Block(-4,41,8,OBSIDIAN:0)
Block(-4,42,-7,STONE:0)
Block(-4,42,-6,STONE:0)
Block(-4,42,-5,STONE:0)
Block(-4,42,-4,STONE:0)
Block(-4,42,-3,STONE:0)
Block(-4,42,-2,STONE:0)
Block(-4,42,-1,STONE:0)
Block(-4,42,0,STONE:0)
Block(-4,42,1,STONE:0)
Block(-4,42,2,STONE:0)
Block(-4,42,3,MAGMA:0)
Block(-4,42,4,MAGMA:0)
Block(-4,42,5,MAGMA:0)
Block(-4,42,6,OBSIDIAN:0)
Block(-4,42,7,MAGMA:0)
Block(-4,42,8,STONE:0)
Block(-4,43,-7,STONE:0)
Block(-4,43,-6,STONE:0)
Block(-4,43,-5,STONE:0)
Block(-4,43,-4,STONE:0)
Block(-4,43,-3,STONE:0)
Block(-4,43,-2,STONE:5)
Block(-4,43,-1,STONE:5)
Block(-4,43,0,STONE:5)
Block(-4,43,1,STONE:5)
Block(-4,43,2,STONE:5)
Block(-4,43,3,STONE:0)
Block(-4,43,4,MAGMA:0)
Block(-4,43,5,MAGMA:0)
Block(-4,43,6,MAGMA:0)
Block(-4,43,7,STONE:0)
Block(-4,43,8,STONE:0)
Block(-4,44,-7,STONE:5)
Block(-4,44,-6,STONE:5)
Block(-4,44,-5,STONE:5)
Block(-4,44,-4,STONE:5)
Block(-4,44,-3,STONE:5)
Block(-4,44,-2,STONE:5)
Block(-4,44,-1,STONE:5)
Block(-4,44,0,STONE:5)
Block(-4,44,1,STONE:5)
Block(-4,44,2,STONE:5)
Block(-4,44,3,STONE:5)
Block(-4,44,4,STONE:0)
Block(-4,44,5,STONE:0)
Block(-4,44,6,STONE:0)
Block(-4,44,7,STONE:0)
Block(-4,44,8,STONE:0)
Block(-4,45,-7,STONE:5)
Block(-4,45,-6,STONE:5)
Block(-4,45,-5,STONE:5)
Block(-4,45,-4,STONE:5)
Block(-4,45,-3,STONE:5)
Block(-4,45,-2,STONE:5)
Block(-4,45,-1,STONE:5)
Block(-4,45,0,STONE:5)
Block(-4,45,1,STONE:5)
Block(-4,45,2,STONE:5)
Block(-4,45,3,STONE:5)
Block(-4,45,4,STONE:5)
Block(-4,45,5,STONE:0)
Block(-4,45,6,STONE:0)
Block(-4,45,7,STONE:0)
Block(-4,45,8,STONE:0)
Block(-4,46,-7,STONE:5)
Block(-4,46,-6,STONE:5)
Block(-4,46,-5,STONE:5)
Block(-4,46,-4,STONE:5)
Block(-4,46,-3,STONE:5)
Block(-4,46,-2,STONE:5)
Block(-4,46,-1,STONE:5)
Block(-4,46,0,STONE:5)
Block(-4,46,1,STONE:5)
Block(-4,46,2,STONE:5)
Block(-4,46,3,STONE:5)
Block(-4,46,4,STONE:5)
Block(-4,46,5,STONE:5)
Block(-4,46,6,STONE:5)
Block(-4,46,7,STONE:5)
Block(-4,46,8,STONE:5)
Block(-4,47,-7,STONE:5)
Block(-4,47,-5,STONE:5)
Block(-4,47,-4,STONE:5)
Block(-4,47,-3,STONE:5)
Block(-4,47,-1,STONE:5)
Block(-4,47,0,STONE:5)
Block(-4,47,1,STONE:5)
Block(-4,47,2,STONE:5)
Block(-4,47,3,STONE:5)
Block(-4,47,4,STONE:5)
Block(-4,47,5,STONE:5)
Block(-4,47,6,STONE:5)
Block(-4,47,7,STONE:5)
Block(-4,47,8,STONE:5)
Block(-4,48,1,STONE:5)
Block(-4,48,2,STONE:5)
Block(-4,48,3,STONE:5)
Block(-4,48,4,STONE:5)
Block(-4,48,5,STONE:5)
Block(-4,48,6,STONE:5)
Block(-4,48,7,STONE:5)
Block(-4,48,8,STONE:5)
Block(-4,49,3,STONE:5)
Block(-4,49,4,STONE:5)
Block(-4,49,5,STONE:5)
Block(-4,49,6,STONE:5)
Block(-4,49,7,STONE:5)
Block(-4,49,8,STONE:5)
Block(-4,50,4,STONE:5)
Block(-4,50,5,STONE:5)
Block(-4,50,6,STONE:5)
Block(-4,50,7,STONE:5)
Block(-4,50,8,STONE:5)
Block(-4,51,5,STONE:5)
Block(-4,51,6,STONE:5)
Block(-4,51,7,STONE:5)
Block(-4,51,8,STONE:5)
Block(-4,52,6,STONE:5)
Block(-4,52,7,STONE:5)
Block(-4,52,8,STONE:5)
Block(-3,13,0,OBSIDIAN:0)
Block(-3,13,1,OBSIDIAN:0)
Block(-3,13,2,OBSIDIAN:0)
Block(-3,13,3,OBSIDIAN:0)
Block(-3,13,4,OBSIDIAN:0)
Block(-3,13,5,OBSIDIAN:0)
Block(-3,13,6,OBSIDIAN:0)
Block(-3,13,7,OBSIDIAN:0)
Block(-3,13,8,OBSIDIAN:0)
Block(-3,14,-1,OBSIDIAN:0)
Block(-3,14,0,STONE:5)
Block(-3,14,1,OBSIDIAN:0)
Block(-3,14,2,OBSIDIAN:0)
Block(-3,14,3,OBSIDIAN:0)
Block(-3,14,4,OBSIDIAN:0)
Block(-3,14,5,OBSIDIAN:0)
Block(-3,14,6,OBSIDIAN:0)
Block(-3,14,7,OBSIDIAN:0)
Block(-3,14,8,OBSIDIAN:0)
Block(-3,15,-2,OBSIDIAN:0)
Block(-3,15,-1,OBSIDIAN:0)
Block(-3,15,0,STONE:5)
Block(-3,15,1,STONE:5)
Block(-3,15,2,STONE:5)
Block(-3,15,3,STONE:5)
Block(-3,15,4,STONE:5)
Block(-3,15,5,STONE:5)
Block(-3,15,6,STONE:5)
Block(-3,15,7,STONE:5)
Block(-3,15,8,STONE:5)
Block(-3,16,-7,OBSIDIAN:0)
Block(-3,16,-6,OBSIDIAN:0)
Block(-3,16,-5,OBSIDIAN:0)
Block(-3,16,-4,OBSIDIAN:0)
Block(-3,16,-3,OBSIDIAN:0)
Block(-3,16,-2,OBSIDIAN:0)
Block(-3,16,-1,OBSIDIAN:0)
Block(-3,16,0,STONE:5)
Block(-3,16,1,STONE:5)
Block(-3,16,2,STONE:5)
Block(-3,16,3,STONE:5)
Block(-3,16,4,STONE:5)
Block(-3,16,5,STONE:5)
Block(-3,16,6,STONE:5)
Block(-3,16,7,STONE:5)
Block(-3,16,8,STONE:5)
Block(-3,17,-7,STONE:5)
Block(-3,17,-6,STONE:5)
Block(-3,17,-5,OBSIDIAN:0)
Block(-3,17,-4,OBSIDIAN:0)
Block(-3,17,-3,OBSIDIAN:0)
Block(-3,17,-2,OBSIDIAN:0)
Block(-3,17,-1,STONE:0)
Block(-3,17,0,STONE:5)
Block(-3,17,1,STONE:5)
Block(-3,17,2,STONE:5)
Block(-3,17,3,STONE:5)
Block(-3,17,4,MAGMA:0)
Block(-3,17,5,MAGMA:0)
Block(-3,17,6,OBSIDIAN:0)
Block(-3,17,7,STONE:5)
Block(-3,17,8,STONE:5)
Block(-3,18,-7,STONE:5)
Block(-3,18,-6,STONE:5)
Block(-3,18,-5,STONE:5)
Block(-3,18,-4,STONE:5)
Block(-3,18,-3,STONE:0)
Block(-3,18,-2,STONE:0)
Block(-3,18,-1,STONE:0)
Block(-3,18,0,STONE:5)
Block(-3,18,1,STONE:5)
Block(-3,18,2,STONE:5)
Block(-3,18,3,MAGMA:0)
Block(-3,18,4,MAGMA:0)
Block(-3,18,5,OBSIDIAN:0)
Block(-3,18,6,OBSIDIAN:0)
Block(-3,18,7,OBSIDIAN:0)
Block(-3,18,8,STONE:5)
Block(-3,19,-7,STONE:0)
Block(-3,19,-6,STONE:0)
Block(-3,19,-5,STONE:0)
Block(-3,19,-4,STONE:0)
Block(-3,19,-3,STONE:0)
Block(-3,19,-2,STONE:0)
Block(-3,19,-1,STONE:0)
Block(-3,19,0,STONE:0)
Block(-3,19,1,STONE:5)
Block(-3,19,2,MAGMA:0)
Block(-3,19,3,MAGMA:0)
Block(-3,19,4,MAGMA:0)
Block(-3,19,5,MAGMA:0)
Block(-3,19,6,OBSIDIAN:0)
Block(-3,19,7,OBSIDIAN:0)
Block(-3,19,8,OBSIDIAN:0)
Block(-3,20,-7,STONE:0)
Block(-3,20,-6,STONE:0)
Block(-3,20,-5,STONE:0)
Block(-3,20,-4,STONE:0)
Block(-3,20,-3,STONE:0)
Block(-3,20,-2,STONE:0)
Block(-3,20,-1,STONE:0)
Block(-3,20,0,STONE:0)
Block(-3,20,1,STONE:0)
Block(-3,20,2,MAGMA:0)
Block(-3,20,3,MAGMA:0)
Block(-3,20,4,MAGMA:0)
Block(-3,20,5,MAGMA:0)
Block(-3,20,6,STATIONARY_WATER:0)
Block(-3,20,7,STATIONARY_WATER:0)
Block(-3,20,8,STATIONARY_WATER:0)
Block(-3,21,-7,STONE:0)
Block(-3,21,-6,STONE:0)
Block(-3,21,-5,STONE:0)
Block(-3,21,-4,STONE:0)
Block(-3,21,-3,STONE:0)
Block(-3,21,-2,STONE:0)
Block(-3,21,-1,STONE:0)
Block(-3,21,0,DIRT:0)
Block(-3,21,1,DIRT:0)
Block(-3,21,2,MAGMA:0)
Block(-3,21,3,MAGMA:0)
Block(-3,21,4,MAGMA:0)
Block(-3,21,5,STATIONARY_WATER:8)
Block(-3,21,6,STATIONARY_WATER:0)
Block(-3,21,7,STATIONARY_WATER:0)
Block(-3,21,8,STATIONARY_WATER:0)
Block(-3,22,-7,STONE:0)
Block(-3,22,-6,STONE:0)
Block(-3,22,-5,STONE:0)
Block(-3,22,-4,STONE:0)
Block(-3,22,-3,GRASS:0)
Block(-3,22,-2,GRASS:0)
Block(-3,22,-1,GRASS:0)
Block(-3,22,0,STATIONARY_WATER:0)
Block(-3,22,1,STATIONARY_WATER:0)
Block(-3,22,2,STATIONARY_WATER:1)
Block(-3,22,3,STATIONARY_WATER:2)
Block(-3,22,4,STATIONARY_WATER:1)
Block(-3,22,5,STATIONARY_WATER:0)
Block(-3,22,6,STATIONARY_WATER:0)
Block(-3,22,7,STATIONARY_WATER:0)
Block(-3,22,8,STATIONARY_WATER:0)
Block(-3,23,-7,STONE:0)
Block(-3,23,-6,STONE:0)
Block(-3,23,-5,STONE:0)
Block(-3,23,-4,GRASS:0)
Block(-3,24,-7,GRASS:0)
Block(-3,24,-6,GRASS:0)
Block(-3,24,-5,GRASS:0)
Block(-3,35,8,OBSIDIAN:0)
Block(-3,36,8,OBSIDIAN:0)
Block(-3,37,8,OBSIDIAN:0)
Block(-3,38,-6,STONE:0)
Block(-3,38,-5,STONE:0)
Block(-3,38,-4,STONE:0)
Block(-3,38,-3,MAGMA:0)
Block(-3,38,-2,MAGMA:0)
Block(-3,39,-7,STONE:0)
Block(-3,39,-6,STONE:0)
Block(-3,39,-5,STONE:0)
Block(-3,39,-4,STONE:0)
Block(-3,39,-3,STONE:0)
Block(-3,39,-2,STONE:0)
Block(-3,39,-1,STONE:0)
Block(-3,39,0,OBSIDIAN:0)
Block(-3,39,1,OBSIDIAN:0)
Block(-3,39,2,OBSIDIAN:0)
Block(-3,39,3,OBSIDIAN:0)
Block(-3,39,4,MAGMA:0)
Block(-3,40,-7,STONE:0)
Block(-3,40,-6,STONE:0)
Block(-3,40,-5,STONE:0)
Block(-3,40,-4,STONE:0)
Block(-3,40,-3,STONE:0)
Block(-3,40,-2,STONE:0)
Block(-3,40,-1,STONE:0)
Block(-3,40,0,STONE:0)
Block(-3,40,1,OBSIDIAN:0)
Block(-3,40,2,OBSIDIAN:0)
Block(-3,40,3,OBSIDIAN:0)
Block(-3,40,4,MAGMA:0)
Block(-3,40,5,OBSIDIAN:0)
Block(-3,41,-7,STONE:0)
Block(-3,41,-6,STONE:0)
Block(-3,41,-5,STONE:0)
Block(-3,41,-4,STONE:0)
Block(-3,41,-3,STONE:0)
Block(-3,41,-2,STONE:0)
Block(-3,41,-1,STONE:0)
Block(-3,41,0,STONE:0)
Block(-3,41,1,STONE:0)
Block(-3,41,2,OBSIDIAN:0)
Block(-3,41,3,MAGMA:0)
Block(-3,41,4,MAGMA:0)
Block(-3,41,5,OBSIDIAN:0)
Block(-3,41,6,OBSIDIAN:0)
Block(-3,41,7,OBSIDIAN:0)
Block(-3,41,8,OBSIDIAN:0)
Block(-3,42,-7,STONE:0)
Block(-3,42,-6,STONE:0)
Block(-3,42,-5,STONE:0)
Block(-3,42,-4,STONE:0)
Block(-3,42,-3,STONE:0)
Block(-3,42,-2,STONE:0)
Block(-3,42,-1,STONE:0)
Block(-3,42,0,STONE:0)
Block(-3,42,1,STONE:0)
Block(-3,42,2,STONE:0)
Block(-3,42,3,MAGMA:0)
Block(-3,42,4,MAGMA:0)
Block(-3,42,5,OBSIDIAN:0)
Block(-3,42,6,OBSIDIAN:0)
Block(-3,42,7,OBSIDIAN:0)
Block(-3,42,8,MAGMA:0)
Block(-3,43,-7,STONE:0)
Block(-3,43,-6,STONE:0)
Block(-3,43,-5,STONE:0)
Block(-3,43,-4,STONE:0)
Block(-3,43,-3,STONE:0)
Block(-3,43,-2,STONE:0)
Block(-3,43,-1,STONE:5)
Block(-3,43,0,STONE:5)
Block(-3,43,1,STONE:5)
Block(-3,43,2,STONE:0)
Block(-3,43,3,STONE:0)
Block(-3,43,4,MAGMA:0)
Block(-3,43,5,MAGMA:0)
Block(-3,43,6,MAGMA:0)
Block(-3,43,7,MAGMA:0)
Block(-3,43,8,MAGMA:0)
Block(-3,44,-7,STONE:0)
Block(-3,44,-6,STONE:0)
Block(-3,44,-5,STONE:0)
Block(-3,44,-4,STONE:5)
Block(-3,44,-3,STONE:5)
Block(-3,44,-2,STONE:5)
Block(-3,44,-1,STONE:5)
Block(-3,44,0,STONE:5)
Block(-3,44,1,STONE:5)
Block(-3,44,2,STONE:5)
Block(-3,44,3,STONE:5)
Block(-3,44,4,STONE:0)
Block(-3,44,5,STONE:0)
Block(-3,44,6,STONE:0)
Block(-3,44,7,STONE:0)
Block(-3,44,8,STONE:0)
Block(-3,45,-7,STONE:0)
Block(-3,45,-6,STONE:5)
Block(-3,45,-5,STONE:5)
Block(-3,45,-4,STONE:5)
Block(-3,45,-3,STONE:5)
Block(-3,45,-2,STONE:5)
Block(-3,45,-1,STONE:5)
Block(-3,45,0,STONE:5)
Block(-3,45,1,STONE:5)
Block(-3,45,2,STONE:5)
Block(-3,45,3,STONE:5)
Block(-3,45,4,STONE:5)
Block(-3,45,5,STONE:5)
Block(-3,45,6,STONE:5)
Block(-3,45,7,STONE:0)
Block(-3,45,8,STONE:0)
Block(-3,46,-7,STONE:5)
Block(-3,46,-6,STONE:5)
Block(-3,46,-5,STONE:5)
Block(-3,46,-4,STONE:5)
Block(-3,46,-3,STONE:5)
Block(-3,46,-2,STONE:5)
Block(-3,46,-1,STONE:5)
Block(-3,46,0,STONE:5)
Block(-3,46,1,STONE:5)
Block(-3,46,2,STONE:5)
Block(-3,46,3,STONE:5)
Block(-3,46,4,STONE:5)
Block(-3,46,5,STONE:5)
Block(-3,46,6,STONE:5)
Block(-3,46,7,STONE:5)
Block(-3,46,8,STONE:0)
Block(-3,47,-7,STONE:5)
Block(-3,47,-6,STONE:5)
Block(-3,47,0,STONE:5)
Block(-3,47,1,STONE:5)
Block(-3,47,2,STONE:5)
Block(-3,47,3,STONE:5)
Block(-3,47,4,STONE:5)
Block(-3,47,5,STONE:5)
Block(-3,47,6,STONE:5)
Block(-3,47,7,STONE:5)
Block(-3,47,8,STONE:5)
Block(-3,48,2,STONE:5)
Block(-3,48,3,STONE:5)
Block(-3,48,4,STONE:5)
Block(-3,48,5,STONE:5)
Block(-3,48,6,STONE:5)
Block(-3,48,7,STONE:5)
Block(-3,48,8,STONE:5)
Block(-3,49,3,STONE:5)
Block(-3,49,4,STONE:5)
Block(-3,49,5,STONE:5)
Block(-3,49,6,STONE:5)
Block(-3,49,7,STONE:5)
Block(-3,49,8,STONE:5)
Block(-3,50,4,STONE:5)
Block(-3,50,5,STONE:5)
Block(-3,50,6,STONE:5)
Block(-3,50,7,STONE:5)
Block(-3,50,8,STONE:5)
Block(-3,51,5,STONE:5)
Block(-3,51,6,STONE:5)
Block(-3,51,7,STONE:5)
Block(-3,51,8,STONE:5)
Block(-3,52,6,STONE:5)
Block(-3,52,7,STONE:5)
Block(-3,52,8,STONE:5)
Block(-2,14,0,STONE:5)
Block(-2,14,1,STONE:5)
Block(-2,14,2,STONE:5)
Block(-2,14,3,STONE:5)
Block(-2,14,4,STONE:5)
Block(-2,14,6,STONE:5)
Block(-2,14,7,STONE:5)
Block(-2,14,8,OBSIDIAN:0)
Block(-2,15,-5,OBSIDIAN:0)
Block(-2,15,-4,OBSIDIAN:0)
Block(-2,15,-3,OBSIDIAN:0)
Block(-2,15,-2,OBSIDIAN:0)
Block(-2,15,-1,OBSIDIAN:0)
Block(-2,15,0,STONE:5)
Block(-2,15,1,STONE:5)
Block(-2,15,2,STONE:5)
Block(-2,15,3,STONE:5)
Block(-2,15,4,STONE:5)
Block(-2,15,5,STONE:5)
Block(-2,15,6,STONE:5)
Block(-2,15,7,STONE:5)
Block(-2,15,8,STONE:5)
Block(-2,16,-7,OBSIDIAN:0)
Block(-2,16,-6,OBSIDIAN:0)
Block(-2,16,-5,OBSIDIAN:0)
Block(-2,16,-4,OBSIDIAN:0)
Block(-2,16,-3,OBSIDIAN:0)
Block(-2,16,-2,OBSIDIAN:0)
Block(-2,16,-1,OBSIDIAN:0)
Block(-2,16,0,STONE:5)
Block(-2,16,1,STONE:5)
Block(-2,16,2,STONE:5)
Block(-2,16,3,STONE:5)
Block(-2,16,4,STONE:5)
Block(-2,16,5,STONE:5)
Block(-2,16,6,STONE:5)
Block(-2,16,7,STONE:5)
Block(-2,16,8,STONE:5)
Block(-2,17,-7,OBSIDIAN:0)
Block(-2,17,-6,OBSIDIAN:0)
Block(-2,17,-5,OBSIDIAN:0)
Block(-2,17,-4,OBSIDIAN:0)
Block(-2,17,-3,OBSIDIAN:0)
Block(-2,17,-2,OBSIDIAN:0)
Block(-2,17,-1,STONE:5)
Block(-2,17,0,STONE:5)
Block(-2,17,1,STONE:5)
Block(-2,17,2,STONE:5)
Block(-2,17,3,STONE:5)
Block(-2,17,4,MAGMA:0)
Block(-2,17,5,OBSIDIAN:0)
Block(-2,17,6,OBSIDIAN:0)
Block(-2,17,7,STONE:5)
Block(-2,17,8,STONE:5)
Block(-2,18,-7,STONE:5)
Block(-2,18,-6,STONE:0)
Block(-2,18,-5,STONE:0)
Block(-2,18,-4,STONE:0)
Block(-2,18,-3,STONE:0)
Block(-2,18,-2,STONE:0)
Block(-2,18,-1,STONE:0)
Block(-2,18,0,STONE:5)
Block(-2,18,1,STONE:5)
Block(-2,18,2,STONE:5)
Block(-2,18,3,MAGMA:0)
Block(-2,18,4,MAGMA:0)
Block(-2,18,5,OBSIDIAN:0)
Block(-2,18,6,OBSIDIAN:0)
Block(-2,18,7,OBSIDIAN:0)
Block(-2,18,8,DIRT:0)
Block(-2,19,-7,STONE:0)
Block(-2,19,-6,STONE:0)
Block(-2,19,-5,STONE:0)
Block(-2,19,-4,STONE:0)
Block(-2,19,-3,STONE:0)
Block(-2,19,-2,STONE:0)
Block(-2,19,-1,STONE:0)
Block(-2,19,0,STONE:0)
Block(-2,19,1,STONE:5)
Block(-2,19,2,MAGMA:0)
Block(-2,19,3,MAGMA:0)
Block(-2,19,4,MAGMA:0)
Block(-2,19,5,OBSIDIAN:0)
Block(-2,19,6,STATIONARY_WATER:0)
Block(-2,19,7,STATIONARY_WATER:0)
Block(-2,19,8,STATIONARY_WATER:0)
Block(-2,20,-7,STONE:0)
Block(-2,20,-6,STONE:0)
Block(-2,20,-5,STONE:0)
Block(-2,20,-4,STONE:0)
Block(-2,20,-3,STONE:0)
Block(-2,20,-2,STONE:0)
Block(-2,20,-1,STONE:0)
Block(-2,20,0,STONE:0)
Block(-2,20,1,STONE:0)
Block(-2,20,2,MAGMA:0)
Block(-2,20,3,MAGMA:0)
Block(-2,20,4,MAGMA:0)
Block(-2,20,5,MAGMA:0)
Block(-2,20,6,STATIONARY_WATER:0)
Block(-2,20,7,STATIONARY_WATER:0)
Block(-2,20,8,STATIONARY_WATER:0)
Block(-2,21,-7,STONE:0)
Block(-2,21,-6,STONE:0)
Block(-2,21,-5,STONE:0)
Block(-2,21,-4,STONE:0)
Block(-2,21,-3,STONE:0)
Block(-2,21,-2,STONE:0)
Block(-2,21,-1,STONE:0)
Block(-2,21,0,STONE:0)
Block(-2,21,1,STONE:0)
Block(-2,21,2,MAGMA:0)
Block(-2,21,3,MAGMA:0)
Block(-2,21,4,MAGMA:0)
Block(-2,21,5,MAGMA:0)
Block(-2,21,6,STATIONARY_WATER:0)
Block(-2,21,7,STATIONARY_WATER:0)
Block(-2,21,8,STATIONARY_WATER:0)
Block(-2,22,-7,STONE:0)
Block(-2,22,-6,STONE:0)
Block(-2,22,-5,STONE:0)
Block(-2,22,-4,STONE:0)
Block(-2,22,-3,STONE:0)
Block(-2,22,-2,STONE:0)
Block(-2,22,-1,STONE:0)
Block(-2,22,0,GRASS:0)
Block(-2,22,1,GRASS:0)
Block(-2,22,2,GRASS:0)
Block(-2,22,3,MAGMA:0)
Block(-2,22,4,MAGMA:0)
Block(-2,22,5,STATIONARY_WATER:0)
Block(-2,22,6,STATIONARY_WATER:0)
Block(-2,22,7,STATIONARY_WATER:0)
Block(-2,22,8,STATIONARY_WATER:0)
Block(-2,23,-7,STONE:0)
Block(-2,23,-6,GRASS:0)
Block(-2,23,-5,GRASS:0)
Block(-2,23,-4,GRASS:0)
Block(-2,23,-3,GRASS:0)
Block(-2,23,-2,GRASS:0)
Block(-2,23,-1,GRASS:0)
Block(-2,24,-7,STONE:0)
Block(-2,25,-7,STONE:0)
Block(-2,26,-7,GRASS:0)
Block(-2,33,-7,OBSIDIAN:0)
Block(-2,33,-6,OBSIDIAN:0)
Block(-2,34,-7,OBSIDIAN:0)
Block(-2,35,7,OBSIDIAN:0)
Block(-2,35,8,OBSIDIAN:0)
Block(-2,36,7,OBSIDIAN:0)
Block(-2,36,8,OBSIDIAN:0)
Block(-2,37,8,OBSIDIAN:0)
Block(-2,38,-7,STONE:0)
Block(-2,39,-7,STONE:0)
Block(-2,39,-6,STONE:0)
Block(-2,39,-5,STONE:0)
Block(-2,39,-4,STONE:0)
Block(-2,39,-3,STONE:0)
Block(-2,39,-2,STONE:0)
Block(-2,40,-7,STONE:0)
Block(-2,40,-6,STONE:0)
Block(-2,40,-5,STONE:0)
Block(-2,40,-4,STONE:0)
Block(-2,40,-3,STONE:0)
Block(-2,40,-2,STONE:0)
Block(-2,40,-1,STONE:0)
Block(-2,40,0,MAGMA:0)
Block(-2,40,1,OBSIDIAN:0)
Block(-2,40,2,OBSIDIAN:0)
Block(-2,40,3,OBSIDIAN:0)
Block(-2,40,4,MAGMA:0)
Block(-2,41,-7,STONE:0)
Block(-2,41,-6,STONE:0)
Block(-2,41,-5,STONE:0)
Block(-2,41,-4,STONE:0)
Block(-2,41,-3,STONE:0)
Block(-2,41,-2,STONE:0)
Block(-2,41,-1,STONE:0)
Block(-2,41,0,STONE:0)
Block(-2,41,1,STONE:0)
Block(-2,41,2,OBSIDIAN:0)
Block(-2,41,3,OBSIDIAN:0)
Block(-2,41,4,MAGMA:0)
Block(-2,41,5,OBSIDIAN:0)
Block(-2,42,-7,STONE:0)
Block(-2,42,-6,STONE:0)
Block(-2,42,-5,STONE:0)
Block(-2,42,-4,STONE:0)
Block(-2,42,-3,STONE:0)
Block(-2,42,-2,STONE:0)
Block(-2,42,-1,STONE:0)
Block(-2,42,0,STONE:0)
Block(-2,42,1,STONE:0)
Block(-2,42,2,STONE:0)
Block(-2,42,3,MAGMA:0)
Block(-2,42,4,MAGMA:0)
Block(-2,42,5,MAGMA:0)
Block(-2,42,6,OBSIDIAN:0)
Block(-2,42,7,MAGMA:0)
Block(-2,42,8,OBSIDIAN:0)
Block(-2,43,-7,STONE:0)
Block(-2,43,-6,STONE:0)
Block(-2,43,-5,STONE:0)
Block(-2,43,-4,STONE:0)
Block(-2,43,-3,STONE:5)
Block(-2,43,-2,STONE:5)
Block(-2,43,-1,STONE:5)
Block(-2,43,0,STONE:0)
Block(-2,43,1,STONE:0)
Block(-2,43,2,STONE:0)
Block(-2,43,3,STONE:0)
Block(-2,43,4,MAGMA:0)
Block(-2,43,5,MAGMA:0)
Block(-2,43,6,MAGMA:0)
Block(-2,43,7,MAGMA:0)
Block(-2,43,8,MAGMA:0)
Block(-2,44,-7,STONE:0)
Block(-2,44,-6,STONE:0)
Block(-2,44,-5,STONE:5)
Block(-2,44,-4,STONE:5)
Block(-2,44,-3,STONE:5)
Block(-2,44,-2,STONE:5)
Block(-2,44,-1,STONE:5)
Block(-2,44,0,STONE:5)
Block(-2,44,1,STONE:5)
Block(-2,44,2,STONE:5)
Block(-2,44,3,STONE:5)
Block(-2,44,4,STONE:5)
Block(-2,44,5,MAGMA:0)
Block(-2,44,6,MAGMA:0)
Block(-2,44,7,MAGMA:0)
Block(-2,44,8,STONE:0)
Block(-2,45,-7,STONE:5)
Block(-2,45,-6,STONE:5)
Block(-2,45,-5,STONE:5)
Block(-2,45,-4,STONE:5)
Block(-2,45,-3,STONE:5)
Block(-2,45,-2,STONE:5)
Block(-2,45,-1,STONE:5)
Block(-2,45,0,STONE:5)
Block(-2,45,1,STONE:5)
Block(-2,45,2,STONE:5)
Block(-2,45,3,STONE:5)
Block(-2,45,4,STONE:5)
Block(-2,45,5,STONE:5)
Block(-2,45,6,STONE:5)
Block(-2,45,7,STONE:5)
Block(-2,45,8,STONE:0)
Block(-2,46,-7,STONE:5)
Block(-2,46,-6,STONE:5)
Block(-2,46,-5,STONE:5)
Block(-2,46,-4,STONE:5)
Block(-2,46,-3,STONE:5)
Block(-2,46,-2,STONE:5)
Block(-2,46,-1,STONE:5)
Block(-2,46,0,STONE:5)
Block(-2,46,1,STONE:5)
Block(-2,46,2,STONE:5)
Block(-2,46,3,STONE:5)
Block(-2,46,4,STONE:5)
Block(-2,46,5,STONE:5)
Block(-2,46,6,STONE:5)
Block(-2,46,7,STONE:5)
Block(-2,46,8,STONE:5)
Block(-2,47,-7,STONE:5)
Block(-2,47,-6,STONE:5)
Block(-2,47,-5,STONE:5)
Block(-2,47,-4,STONE:5)
Block(-2,47,-3,STONE:5)
Block(-2,47,-2,STONE:5)
Block(-2,47,2,STONE:5)
Block(-2,47,3,STONE:5)
Block(-2,47,4,STONE:5)
Block(-2,47,5,STONE:5)
Block(-2,47,6,STONE:5)
Block(-2,47,7,STONE:5)
Block(-2,47,8,STONE:5)
Block(-2,48,-7,STONE:5)
Block(-2,48,3,STONE:5)
Block(-2,48,4,STONE:5)
Block(-2,48,5,STONE:5)
Block(-2,48,6,STONE:5)
Block(-2,48,7,STONE:5)
Block(-2,48,8,STONE:5)
Block(-2,49,3,STONE:5)
Block(-2,49,4,STONE:5)
Block(-2,49,5,STONE:5)
Block(-2,49,6,STONE:5)
Block(-2,49,7,STONE:5)
Block(-2,49,8,STONE:5)
Block(-2,50,4,STONE:5)
Block(-2,50,5,STONE:5)
Block(-2,50,6,STONE:5)
Block(-2,50,7,STONE:5)
Block(-2,50,8,STONE:5)
Block(-2,51,5,STONE:5)
Block(-2,51,6,STONE:5)
Block(-2,51,7,STONE:5)
Block(-2,51,8,STONE:5)
Block(-2,52,6,STONE:5)
Block(-2,52,7,STONE:5)
Block(-2,52,8,STONE:5)
Block(-1,14,-4,OBSIDIAN:0)
Block(-1,14,-3,OBSIDIAN:0)
Block(-1,14,-2,OBSIDIAN:0)
Block(-1,15,-7,OBSIDIAN:0)
Block(-1,15,-6,OBSIDIAN:0)
Block(-1,15,-5,OBSIDIAN:0)
Block(-1,15,-4,OBSIDIAN:0)
Block(-1,15,-3,OBSIDIAN:0)
Block(-1,15,-2,OBSIDIAN:0)
Block(-1,15,-1,OBSIDIAN:0)
Block(-1,15,0,STONE:5)
Block(-1,15,1,STONE:5)
Block(-1,15,2,STONE:5)
Block(-1,15,3,STONE:5)
Block(-1,15,4,STONE:5)
Block(-1,16,-7,OBSIDIAN:0)
Block(-1,16,-6,OBSIDIAN:0)
Block(-1,16,-5,OBSIDIAN:0)
Block(-1,16,-4,OBSIDIAN:0)
Block(-1,16,-3,OBSIDIAN:0)
Block(-1,16,-2,OBSIDIAN:0)
Block(-1,16,-1,OBSIDIAN:0)
Block(-1,16,0,STONE:5)
Block(-1,16,1,STONE:5)
Block(-1,16,2,STONE:5)
Block(-1,16,3,STONE:5)
Block(-1,16,4,STONE:5)
Block(-1,16,5,STONE:5)
Block(-1,17,-7,OBSIDIAN:0)
Block(-1,17,-6,OBSIDIAN:0)
Block(-1,17,-5,OBSIDIAN:0)
Block(-1,17,-4,OBSIDIAN:0)
Block(-1,17,-3,OBSIDIAN:0)
Block(-1,17,-2,OBSIDIAN:0)
Block(-1,17,-1,STONE:5)
Block(-1,17,0,STONE:5)
Block(-1,17,1,STONE:5)
Block(-1,17,2,STONE:5)
Block(-1,17,3,STONE:5)
Block(-1,17,4,STONE:5)
Block(-1,17,5,STONE:5)
Block(-1,17,6,STONE:5)
Block(-1,17,7,STONE:5)
Block(-1,17,8,STONE:5)
Block(-1,18,-7,STONE:5)
Block(-1,18,-6,STONE:0)
Block(-1,18,-5,STONE:0)
Block(-1,18,-4,STONE:0)
Block(-1,18,-3,STONE:5)
Block(-1,18,-2,STONE:5)
Block(-1,18,-1,STONE:5)
Block(-1,18,0,STONE:5)
Block(-1,18,1,STONE:5)
Block(-1,18,2,STONE:5)
Block(-1,18,3,MAGMA:0)
Block(-1,18,4,MAGMA:0)
Block(-1,18,5,OBSIDIAN:0)
Block(-1,18,6,OBSIDIAN:0)
Block(-1,18,7,OBSIDIAN:0)
Block(-1,18,8,STONE:5)
Block(-1,19,-7,STONE:0)
Block(-1,19,-6,STONE:0)
Block(-1,19,-5,STONE:0)
Block(-1,19,-4,STONE:0)
Block(-1,19,-3,STONE:0)
Block(-1,19,-2,STONE:0)
Block(-1,19,-1,STONE:0)
Block(-1,19,0,STONE:0)
Block(-1,19,1,STONE:5)
Block(-1,19,2,STONE:5)
Block(-1,19,3,MAGMA:0)
Block(-1,19,4,MAGMA:0)
Block(-1,19,5,MAGMA:0)
Block(-1,19,6,OBSIDIAN:0)
Block(-1,19,7,OBSIDIAN:0)
Block(-1,19,8,STONE:5)
Block(-1,20,-7,STONE:0)
Block(-1,20,-6,STONE:0)
Block(-1,20,-5,STONE:0)
Block(-1,20,-4,STONE:0)
Block(-1,20,-3,STONE:0)
Block(-1,20,-2,STONE:0)
Block(-1,20,-1,STONE:0)
Block(-1,20,0,STONE:0)
Block(-1,20,1,STONE:0)
Block(-1,20,2,STONE:5)
Block(-1,20,3,MAGMA:0)
Block(-1,20,4,MAGMA:0)
Block(-1,20,5,MAGMA:0)
Block(-1,20,6,OBSIDIAN:0)
Block(-1,20,7,OBSIDIAN:0)
Block(-1,20,8,STONE:5)
Block(-1,21,-7,STONE:0)
Block(-1,21,-6,STONE:0)
Block(-1,21,-5,STONE:0)
Block(-1,21,-4,STONE:0)
Block(-1,21,-3,STONE:0)
Block(-1,21,-2,STONE:0)
Block(-1,21,-1,STONE:0)
Block(-1,21,0,STONE:0)
Block(-1,21,1,STONE:0)
Block(-1,21,2,STONE:0)
Block(-1,21,3,MAGMA:0)
Block(-1,21,4,MAGMA:0)
Block(-1,21,5,MAGMA:0)
Block(-1,21,6,OBSIDIAN:0)
Block(-1,21,7,OBSIDIAN:0)
Block(-1,21,8,STONE:5)
Block(-1,22,-7,STONE:0)
Block(-1,22,-6,STONE:0)
Block(-1,22,-5,STONE:0)
Block(-1,22,-4,STONE:0)
Block(-1,22,-3,STONE:0)
Block(-1,22,-2,STONE:0)
Block(-1,22,-1,STONE:0)
Block(-1,22,0,STONE:0)
Block(-1,22,1,STONE:0)
Block(-1,22,2,STONE:0)
Block(-1,22,3,MAGMA:0)
Block(-1,22,4,MAGMA:0)
Block(-1,22,5,MAGMA:0)
Block(-1,22,6,STATIONARY_WATER:0)
Block(-1,22,7,STATIONARY_WATER:0)
Block(-1,22,8,STATIONARY_WATER:0)
Block(-1,23,-7,STONE:0)
Block(-1,23,-6,STONE:0)
Block(-1,23,-5,GRASS:0)
Block(-1,23,-4,STONE:0)
Block(-1,23,-3,STONE:0)
Block(-1,23,-2,STONE:0)
Block(-1,23,-1,GRASS:0)
Block(-1,23,0,GRASS:0)
Block(-1,23,1,GRASS:0)
Block(-1,23,2,GRASS:0)
Block(-1,23,3,GRASS:0)
Block(-1,23,4,GRASS:0)
Block(-1,24,-7,STONE:0)
Block(-1,24,-6,STONE:0)
Block(-1,24,-4,GRASS:0)
Block(-1,24,-3,GRASS:0)
Block(-1,24,-2,GRASS:0)
Block(-1,25,-7,STONE:0)
Block(-1,25,-6,STONE:0)
Block(-1,26,-7,MAGMA:0)
Block(-1,26,-6,MAGMA:0)
Block(-1,26,2,OBSIDIAN:0)
Block(-1,26,3,OBSIDIAN:0)
Block(-1,27,-7,MAGMA:0)
Block(-1,27,-6,MAGMA:0)
Block(-1,27,1,OBSIDIAN:0)
Block(-1,27,2,OBSIDIAN:0)
Block(-1,28,-7,MAGMA:0)
Block(-1,28,0,OBSIDIAN:0)
Block(-1,28,1,OBSIDIAN:0)
Block(-1,29,-2,OBSIDIAN:0)
Block(-1,29,-1,OBSIDIAN:0)
Block(-1,29,0,OBSIDIAN:0)
Block(-1,30,-3,OBSIDIAN:0)
Block(-1,30,-2,OBSIDIAN:0)
Block(-1,30,-1,OBSIDIAN:0)
Block(-1,31,-4,OBSIDIAN:0)
Block(-1,31,-3,OBSIDIAN:0)
Block(-1,31,-2,OBSIDIAN:0)
Block(-1,32,-5,OBSIDIAN:0)
Block(-1,32,-4,OBSIDIAN:0)
Block(-1,32,-3,OBSIDIAN:0)
Block(-1,33,-6,OBSIDIAN:0)
Block(-1,33,-5,OBSIDIAN:0)
Block(-1,33,-4,OBSIDIAN:0)
Block(-1,34,-7,OBSIDIAN:0)
Block(-1,34,-6,OBSIDIAN:0)
Block(-1,34,6,OBSIDIAN:0)
Block(-1,34,7,OBSIDIAN:0)
Block(-1,34,8,OBSIDIAN:0)
Block(-1,35,-7,OBSIDIAN:0)
Block(-1,35,6,OBSIDIAN:0)
Block(-1,35,7,OBSIDIAN:0)
Block(-1,35,8,OBSIDIAN:0)
Block(-1,36,7,OBSIDIAN:0)
Block(-1,38,-7,STONE:0)
Block(-1,38,-5,STONE:0)
Block(-1,38,-4,STONE:0)
Block(-1,38,-3,OBSIDIAN:0)
Block(-1,39,-7,STONE:0)
Block(-1,39,-6,STONE:0)
Block(-1,39,-5,STONE:0)
Block(-1,39,-4,STONE:0)
Block(-1,39,-3,MAGMA:0)
Block(-1,39,-2,OBSIDIAN:0)
Block(-1,39,-1,OBSIDIAN:0)
Block(-1,39,0,OBSIDIAN:0)
Block(-1,39,1,MAGMA:0)
Block(-1,39,2,OBSIDIAN:0)
Block(-1,39,3,MAGMA:0)
Block(-1,40,-7,STONE:0)
Block(-1,40,-6,STONE:0)
Block(-1,40,-5,STONE:0)
Block(-1,40,-4,STONE:0)
Block(-1,40,-3,STONE:0)
Block(-1,40,-2,OBSIDIAN:0)
Block(-1,40,-1,OBSIDIAN:0)
Block(-1,40,0,OBSIDIAN:0)
Block(-1,40,1,OBSIDIAN:0)
Block(-1,40,2,OBSIDIAN:0)
Block(-1,40,3,OBSIDIAN:0)
Block(-1,40,4,MAGMA:0)
Block(-1,41,-7,STONE:0)
Block(-1,41,-6,STONE:0)
Block(-1,41,-5,STONE:0)
Block(-1,41,-4,STONE:0)
Block(-1,41,-3,STONE:0)
Block(-1,41,-2,STONE:0)
Block(-1,41,-1,STONE:0)
Block(-1,41,0,STONE:0)
Block(-1,41,1,MAGMA:0)
Block(-1,41,2,OBSIDIAN:0)
Block(-1,41,3,MAGMA:0)
Block(-1,41,4,MAGMA:0)
Block(-1,41,5,MAGMA:0)
Block(-1,41,6,MAGMA:0)
Block(-1,41,7,OBSIDIAN:0)
Block(-1,41,8,OBSIDIAN:0)
Block(-1,42,-7,STONE:0)
Block(-1,42,-6,STONE:0)
Block(-1,42,-5,STONE:0)
Block(-1,42,-4,STONE:0)
Block(-1,42,-3,STONE:0)
Block(-1,42,-2,STONE:0)
Block(-1,42,-1,STONE:0)
Block(-1,42,0,STONE:0)
Block(-1,42,1,STONE:0)
Block(-1,42,2,STONE:0)
Block(-1,42,3,MAGMA:0)
Block(-1,42,4,MAGMA:0)
Block(-1,42,5,MAGMA:0)
Block(-1,42,6,MAGMA:0)
Block(-1,42,7,OBSIDIAN:0)
Block(-1,42,8,OBSIDIAN:0)
Block(-1,43,-7,STONE:0)
Block(-1,43,-6,STONE:0)
Block(-1,43,-5,STONE:0)
Block(-1,43,-4,STONE:5)
Block(-1,43,-3,STONE:5)
Block(-1,43,-2,STONE:5)
Block(-1,43,-1,STONE:5)
Block(-1,43,0,STONE:5)
Block(-1,43,1,STONE:0)
Block(-1,43,2,STONE:0)
Block(-1,43,3,STONE:0)
Block(-1,43,4,MAGMA:0)
Block(-1,43,5,MAGMA:0)
Block(-1,43,6,MAGMA:0)
Block(-1,43,7,MAGMA:0)
Block(-1,43,8,OBSIDIAN:0)
Block(-1,44,-7,STONE:5)
Block(-1,44,-6,STONE:0)
Block(-1,44,-5,STONE:5)
Block(-1,44,-4,STONE:5)
Block(-1,44,-3,STONE:5)
Block(-1,44,-2,STONE:5)
Block(-1,44,-1,STONE:5)
Block(-1,44,0,STONE:5)
Block(-1,44,1,STONE:5)
Block(-1,44,2,STONE:5)
Block(-1,44,3,STONE:5)
Block(-1,44,4,STONE:5)
Block(-1,44,5,MAGMA:0)
Block(-1,44,6,MAGMA:0)
Block(-1,44,7,MAGMA:0)
Block(-1,44,8,STONE:0)
Block(-1,45,-7,STONE:5)
Block(-1,45,-6,STONE:5)
Block(-1,45,-5,STONE:5)
Block(-1,45,-4,STONE:5)
Block(-1,45,-3,STONE:5)
Block(-1,45,-2,STONE:5)
Block(-1,45,-1,STONE:5)
Block(-1,45,0,STONE:5)
Block(-1,45,1,STONE:5)
Block(-1,45,2,STONE:5)
Block(-1,45,3,STONE:5)
Block(-1,45,4,STONE:5)
Block(-1,45,5,STONE:5)
Block(-1,45,6,STONE:5)
Block(-1,45,7,STONE:5)
Block(-1,45,8,STONE:0)
Block(-1,46,-7,STONE:5)
Block(-1,46,-6,STONE:5)
Block(-1,46,-5,STONE:5)
Block(-1,46,-4,STONE:5)
Block(-1,46,-3,STONE:5)
Block(-1,46,-2,STONE:5)
Block(-1,46,-1,STONE:5)
Block(-1,46,0,STONE:5)
Block(-1,46,1,STONE:5)
Block(-1,46,2,STONE:5)
Block(-1,46,3,STONE:5)
Block(-1,46,4,STONE:5)
Block(-1,46,5,STONE:5)
Block(-1,46,6,STONE:5)
Block(-1,46,7,STONE:5)
Block(-1,46,8,STONE:5)
Block(-1,47,-7,STONE:5)
Block(-1,47,-6,STONE:5)
Block(-1,47,-5,STONE:5)
Block(-1,47,-4,STONE:5)
Block(-1,47,-3,STONE:5)
Block(-1,47,-2,STONE:5)
Block(-1,47,-1,STONE:5)
Block(-1,47,0,STONE:5)
Block(-1,47,1,STONE:5)
Block(-1,47,2,STONE:5)
Block(-1,47,3,STONE:5)
Block(-1,47,4,STONE:5)
Block(-1,47,5,STONE:5)
Block(-1,47,6,STONE:5)
Block(-1,47,7,STONE:5)
Block(-1,47,8,STONE:5)
Block(-1,48,-7,STONE:5)
Block(-1,48,-6,STONE:5)
Block(-1,48,-5,STONE:5)
Block(-1,48,-4,STONE:5)
Block(-1,48,-3,STONE:5)
Block(-1,48,3,STONE:5)
Block(-1,48,4,STONE:5)
Block(-1,48,5,STONE:5)
Block(-1,48,6,STONE:5)
Block(-1,48,7,STONE:5)
Block(-1,48,8,STONE:5)
Block(-1,49,4,STONE:5)
Block(-1,49,5,STONE:5)
Block(-1,49,6,STONE:5)
Block(-1,49,7,STONE:5)
Block(-1,49,8,STONE:5)
Block(-1,50,4,STONE:5)
Block(-1,50,5,STONE:5)
Block(-1,50,6,STONE:5)
Block(-1,50,7,STONE:5)
Block(-1,50,8,STONE:5)
Block(-1,51,5,STONE:5)
Block(-1,51,6,STONE:5)
Block(-1,51,7,STONE:5)
Block(-1,51,8,STONE:5)
Block(-1,52,7,STONE:5)
Block(-1,52,8,STONE:5)
Block(0,14,-7,OBSIDIAN:0)
Block(0,14,-5,OBSIDIAN:0)
Block(0,14,-4,OBSIDIAN:0)
Block(0,14,-3,OBSIDIAN:0)
Block(0,14,-2,OBSIDIAN:0)
Block(0,14,-1,STONE:5)
Block(0,14,1,STONE:5)
Block(0,14,2,STONE:5)
Block(0,14,3,STONE:5)
Block(0,15,-7,OBSIDIAN:0)
Block(0,15,-6,OBSIDIAN:0)
Block(0,15,-5,OBSIDIAN:0)
Block(0,15,-4,OBSIDIAN:0)
Block(0,15,-3,OBSIDIAN:0)
Block(0,15,-2,OBSIDIAN:0)
Block(0,15,-1,STONE:5)
Block(0,15,0,STONE:5)
Block(0,15,1,STONE:5)
Block(0,15,2,STONE:5)
Block(0,15,3,STONE:5)
Block(0,15,4,STONE:5)
Block(0,15,5,STONE:5)
Block(0,16,-7,OBSIDIAN:0)
Block(0,16,-6,OBSIDIAN:0)
Block(0,16,-5,OBSIDIAN:0)
Block(0,16,-4,OBSIDIAN:0)
Block(0,16,-3,OBSIDIAN:0)
Block(0,16,-2,OBSIDIAN:0)
Block(0,16,-1,STONE:5)
Block(0,16,0,STONE:5)
Block(0,16,1,STONE:5)
Block(0,16,2,STONE:5)
Block(0,16,3,STONE:5)
Block(0,16,4,STONE:5)
Block(0,16,5,STONE:5)
Block(0,16,6,STONE:5)
Block(0,16,7,STONE:5)
Block(0,16,8,STONE:5)
Block(0,17,-7,OBSIDIAN:0)
Block(0,17,-6,OBSIDIAN:0)
Block(0,17,-5,OBSIDIAN:0)
Block(0,17,-4,STONE:5)
Block(0,17,-3,STONE:5)
Block(0,17,-2,STONE:5)
Block(0,17,-1,STONE:5)
Block(0,17,0,STONE:5)
Block(0,17,1,STONE:5)
Block(0,17,2,STONE:5)
Block(0,17,3,STONE:5)
Block(0,17,4,STONE:5)
Block(0,17,5,STONE:5)
Block(0,17,6,STONE:5)
Block(0,17,7,STONE:5)
Block(0,17,8,STONE:5)
Block(0,18,-7,STONE:5)
Block(0,18,-6,STONE:5)
Block(0,18,-5,STONE:0)
Block(0,18,-4,STONE:5)
Block(0,18,-3,STONE:5)
Block(0,18,-2,STONE:5)
Block(0,18,-1,STONE:5)
Block(0,18,0,STONE:5)
Block(0,18,1,STONE:5)
Block(0,18,2,STONE:5)
Block(0,18,3,STONE:5)
Block(0,18,4,STONE:5)
Block(0,18,5,STONE:5)
Block(0,18,6,STONE:5)
Block(0,18,7,STONE:5)
Block(0,18,8,STONE:5)
Block(0,19,-7,STONE:0)
Block(0,19,-6,STONE:0)
Block(0,19,-5,STONE:0)
Block(0,19,-4,STONE:0)
Block(0,19,-3,STONE:0)
Block(0,19,-2,STONE:5)
Block(0,19,-1,STONE:5)
Block(0,19,0,STONE:5)
Block(0,19,1,STONE:5)
Block(0,19,2,STONE:5)
Block(0,19,3,STONE:5)
Block(0,19,4,MAGMA:0)
Block(0,19,5,MAGMA:0)
Block(0,19,6,MAGMA:0)
Block(0,19,7,STONE:5)
Block(0,19,8,STONE:5)
Block(0,20,-7,STONE:0)
Block(0,20,-6,STONE:0)
Block(0,20,-5,STONE:0)
Block(0,20,-4,STONE:0)
Block(0,20,-3,STONE:0)
Block(0,20,-2,STONE:0)
Block(0,20,-1,STONE:0)
Block(0,20,0,STONE:0)
Block(0,20,1,STONE:0)
Block(0,20,2,STONE:5)
Block(0,20,3,STONE:5)
Block(0,20,4,MAGMA:0)
Block(0,20,5,MAGMA:0)
Block(0,20,6,MAGMA:0)
Block(0,20,7,STONE:5)
Block(0,20,8,STONE:5)
Block(0,21,-7,STONE:0)
Block(0,21,-6,STONE:0)
Block(0,21,-5,STONE:0)
Block(0,21,-4,STONE:0)
Block(0,21,-3,STONE:0)
Block(0,21,-2,STONE:0)
Block(0,21,-1,STONE:0)
Block(0,21,0,STONE:0)
Block(0,21,1,STONE:0)
Block(0,21,2,STONE:0)
Block(0,21,3,STONE:0)
Block(0,21,4,MAGMA:0)
Block(0,21,5,MAGMA:0)
Block(0,21,6,OBSIDIAN:0)
Block(0,21,7,STONE:5)
Block(0,21,8,STONE:5)
Block(0,22,-7,STONE:0)
Block(0,22,-6,STONE:0)
Block(0,22,-5,STONE:0)
Block(0,22,-4,STONE:0)
Block(0,22,-3,STONE:0)
Block(0,22,-2,STONE:0)
Block(0,22,-1,STONE:0)
Block(0,22,0,STONE:0)
Block(0,22,1,STONE:0)
Block(0,22,2,STONE:0)
Block(0,22,3,STONE:0)
Block(0,22,4,STONE:0)
Block(0,22,5,MAGMA:0)
Block(0,22,6,MAGMA:0)
Block(0,22,7,OBSIDIAN:0)
Block(0,22,8,OBSIDIAN:0)
Block(0,23,-7,STONE:0)
Block(0,23,-6,STONE:0)
Block(0,23,-5,STONE:0)
Block(0,23,-4,STONE:0)
Block(0,23,-3,STONE:0)
Block(0,23,-2,STONE:0)
Block(0,23,-1,STONE:0)
Block(0,23,0,GRASS:0)
Block(0,23,1,STONE:0)
Block(0,23,2,STONE:0)
Block(0,23,3,MAGMA:0)
Block(0,23,4,MAGMA:0)
Block(0,23,5,MAGMA:0)
Block(0,23,6,OBSIDIAN:0)
Block(0,23,7,OBSIDIAN:0)
Block(0,24,-7,STONE:0)
Block(0,24,-6,STONE:0)
Block(0,24,-5,STONE:0)
Block(0,24,-4,STONE:0)
Block(0,24,-3,STONE:0)
Block(0,24,-2,STONE:0)
Block(0,24,-1,GRASS:0)
Block(0,24,1,GRASS:0)
Block(0,24,2,GRASS:0)
Block(0,24,3,MAGMA:0)
Block(0,24,5,OBSIDIAN:0)
Block(0,24,6,OBSIDIAN:0)
Block(0,25,-7,STONE:0)
Block(0,25,-6,STONE:0)
Block(0,25,-5,STONE:0)
Block(0,25,-4,STONE:0)
Block(0,25,-3,STONE:0)
Block(0,25,-2,GRASS:0)
Block(0,25,4,OBSIDIAN:0)
Block(0,25,5,OBSIDIAN:0)
Block(0,25,6,OBSIDIAN:0)
Block(0,26,-7,MAGMA:0)
Block(0,26,-6,MAGMA:0)
Block(0,26,-5,STONE:0)
Block(0,26,-4,GRASS:0)
Block(0,26,-3,GRASS:0)
Block(0,26,3,OBSIDIAN:0)
Block(0,26,4,OBSIDIAN:0)
Block(0,26,5,OBSIDIAN:0)
Block(0,27,-7,MAGMA:0)
Block(0,27,-6,MAGMA:0)
Block(0,27,-5,MAGMA:0)
Block(0,27,2,OBSIDIAN:0)
Block(0,27,3,OBSIDIAN:0)
Block(0,27,4,OBSIDIAN:0)
Block(0,28,-7,MAGMA:0)
Block(0,28,-6,MAGMA:0)
Block(0,28,1,OBSIDIAN:0)
Block(0,28,2,OBSIDIAN:0)
Block(0,28,3,OBSIDIAN:0)
Block(0,29,-7,MAGMA:0)
Block(0,29,-1,OBSIDIAN:0)
Block(0,29,0,OBSIDIAN:0)
Block(0,29,1,OBSIDIAN:0)
Block(0,30,-2,OBSIDIAN:0)
Block(0,30,-1,OBSIDIAN:0)
Block(0,30,0,OBSIDIAN:0)
Block(0,31,-3,OBSIDIAN:0)
Block(0,31,-2,OBSIDIAN:0)
Block(0,32,-4,OBSIDIAN:0)
Block(0,32,-3,OBSIDIAN:0)
Block(0,33,5,OBSIDIAN:0)
Block(0,33,6,OBSIDIAN:0)
Block(0,34,5,OBSIDIAN:0)
Block(0,34,6,OBSIDIAN:0)
Block(0,34,7,OBSIDIAN:0)
Block(0,35,6,OBSIDIAN:0)
Block(0,35,7,OBSIDIAN:0)
Block(0,38,-7,STONE:0)
Block(0,38,-6,STONE:0)
Block(0,38,-5,STONE:0)
Block(0,38,-4,OBSIDIAN:0)
Block(0,38,-3,OBSIDIAN:0)
Block(0,38,-2,OBSIDIAN:0)
Block(0,38,0,MAGMA:0)
Block(0,38,1,MAGMA:0)
Block(0,38,2,MAGMA:0)
Block(0,39,-7,STONE:0)
Block(0,39,-6,STONE:0)
Block(0,39,-5,STONE:0)
Block(0,39,-4,OBSIDIAN:0)
Block(0,39,-3,OBSIDIAN:0)
Block(0,39,-2,OBSIDIAN:0)
Block(0,39,-1,OBSIDIAN:0)
Block(0,39,0,OBSIDIAN:0)
Block(0,39,1,MAGMA:0)
Block(0,39,2,MAGMA:0)
Block(0,39,3,MAGMA:0)
Block(0,39,4,MAGMA:0)
Block(0,40,-7,STONE:0)
Block(0,40,-6,STONE:0)
Block(0,40,-5,STONE:0)
Block(0,40,-4,MAGMA:0)
Block(0,40,-3,MAGMA:0)
Block(0,40,-2,MAGMA:0)
Block(0,40,-1,OBSIDIAN:0)
Block(0,40,0,MAGMA:0)
Block(0,40,1,MAGMA:0)
Block(0,40,2,MAGMA:0)
Block(0,40,3,MAGMA:0)
Block(0,40,4,MAGMA:0)
Block(0,40,5,MAGMA:0)
Block(0,40,6,MAGMA:0)
Block(0,40,7,OBSIDIAN:0)
Block(0,40,8,OBSIDIAN:0)
Block(0,41,-7,STONE:0)
Block(0,41,-6,STONE:0)
Block(0,41,-5,STONE:0)
Block(0,41,-4,STONE:0)
Block(0,41,-3,STONE:0)
Block(0,41,-2,STONE:0)
Block(0,41,-1,MAGMA:0)
Block(0,41,0,MAGMA:0)
Block(0,41,1,MAGMA:0)
Block(0,41,2,MAGMA:0)
Block(0,41,3,MAGMA:0)
Block(0,41,4,MAGMA:0)
Block(0,41,5,MAGMA:0)
Block(0,41,6,MAGMA:0)
Block(0,41,7,OBSIDIAN:0)
Block(0,41,8,OBSIDIAN:0)
Block(0,42,-7,STONE:0)
Block(0,42,-6,STONE:0)
Block(0,42,-5,STONE:0)
Block(0,42,-4,STONE:0)
Block(0,42,-3,STONE:0)
Block(0,42,-2,STONE:0)
Block(0,42,-1,STONE:0)
Block(0,42,0,STONE:0)
Block(0,42,1,STONE:0)
Block(0,42,2,STONE:0)
Block(0,42,3,MAGMA:0)
Block(0,42,4,MAGMA:0)
Block(0,42,5,MAGMA:0)
Block(0,42,6,MAGMA:0)
Block(0,42,7,MAGMA:0)
Block(0,42,8,OBSIDIAN:0)
Block(0,43,-7,STONE:0)
Block(0,43,-6,STONE:0)
Block(0,43,-5,STONE:0)
Block(0,43,-4,STONE:5)
Block(0,43,-3,STONE:5)
Block(0,43,-2,STONE:5)
Block(0,43,-1,STONE:5)
Block(0,43,0,STONE:5)
Block(0,43,1,STONE:5)
Block(0,43,2,STONE:5)
Block(0,43,3,STONE:0)
Block(0,43,4,MAGMA:0)
Block(0,43,5,MAGMA:0)
Block(0,43,6,MAGMA:0)
Block(0,43,7,MAGMA:0)
Block(0,43,8,MAGMA:0)
Block(0,44,-7,STONE:5)
Block(0,44,-6,STONE:5)
Block(0,44,-5,STONE:5)
Block(0,44,-4,STONE:5)
Block(0,44,-3,STONE:5)
Block(0,44,-2,STONE:5)
Block(0,44,-1,STONE:5)
Block(0,44,0,STONE:5)
Block(0,44,1,STONE:5)
Block(0,44,2,STONE:5)
Block(0,44,3,STONE:5)
Block(0,44,4,STONE:5)
Block(0,44,5,MAGMA:0)
Block(0,44,6,MAGMA:0)
Block(0,44,7,MAGMA:0)
Block(0,44,8,STONE:0)
Block(0,45,-7,STONE:5)
Block(0,45,-6,STONE:5)
Block(0,45,-5,STONE:5)
Block(0,45,-4,STONE:5)
Block(0,45,-3,STONE:5)
Block(0,45,-2,STONE:5)
Block(0,45,-1,STONE:5)
Block(0,45,0,STONE:5)
Block(0,45,1,STONE:5)
Block(0,45,2,STONE:5)
Block(0,45,3,STONE:5)
Block(0,45,4,STONE:5)
Block(0,45,5,STONE:5)
Block(0,45,6,STONE:5)
Block(0,45,7,STONE:5)
Block(0,45,8,STONE:0)
Block(0,46,-7,STONE:5)
Block(0,46,-6,STONE:5)
Block(0,46,-5,STONE:5)
Block(0,46,-4,STONE:5)
Block(0,46,-3,STONE:5)
Block(0,46,-2,STONE:5)
Block(0,46,-1,STONE:5)
Block(0,46,0,STONE:5)
Block(0,46,1,STONE:5)
Block(0,46,2,STONE:5)
Block(0,46,3,STONE:5)
Block(0,46,4,STONE:5)
Block(0,46,5,STONE:5)
Block(0,46,6,STONE:5)
Block(0,46,7,STONE:5)
Block(0,46,8,STONE:5)
Block(0,47,-7,STONE:5)
Block(0,47,-6,STONE:5)
Block(0,47,-5,STONE:5)
Block(0,47,-4,STONE:5)
Block(0,47,-3,STONE:5)
Block(0,47,-2,STONE:5)
Block(0,47,-1,STONE:5)
Block(0,47,0,STONE:5)
Block(0,47,1,STONE:5)
Block(0,47,2,STONE:5)
Block(0,47,3,STONE:5)
Block(0,47,4,STONE:5)
Block(0,47,5,STONE:5)
Block(0,47,6,STONE:5)
Block(0,47,7,STONE:5)
Block(0,47,8,STONE:5)
Block(0,48,-7,STONE:5)
Block(0,48,-6,STONE:5)
Block(0,48,-5,STONE:5)
Block(0,48,-4,STONE:5)
Block(0,48,-3,STONE:5)
Block(0,48,-2,STONE:5)
Block(0,48,0,STONE:5)
Block(0,48,1,STONE:5)
Block(0,48,2,STONE:5)
Block(0,48,3,STONE:5)
Block(0,48,4,STONE:5)
Block(0,48,5,STONE:5)
Block(0,48,6,STONE:5)
Block(0,48,7,STONE:5)
Block(0,48,8,STONE:5)
Block(0,49,4,STONE:5)
Block(0,49,5,STONE:5)
Block(0,49,6,STONE:5)
Block(0,49,7,STONE:5)
Block(0,49,8,STONE:5)
Block(0,50,5,STONE:5)
Block(0,50,6,STONE:5)
Block(0,50,7,STONE:5)
Block(0,50,8,STONE:5)
Block(0,51,6,STONE:5)
Block(0,51,7,STONE:5)
Block(0,51,8,STONE:5)
Block(0,52,7,STONE:5)
Block(0,52,8,STONE:5)
Block(1,12,8,STONE:5)
Block(1,13,8,STONE:5)
Block(1,14,-7,OBSIDIAN:0)
Block(1,14,-6,OBSIDIAN:0)
Block(1,14,-5,OBSIDIAN:0)
Block(1,14,-4,OBSIDIAN:0)
Block(1,14,-3,OBSIDIAN:0)
Block(1,14,-2,STONE:5)
Block(1,14,-1,STONE:5)
Block(1,14,0,STONE:5)
Block(1,14,1,STONE:5)
Block(1,14,2,STONE:5)
Block(1,14,3,STONE:5)
Block(1,14,4,STONE:5)
Block(1,14,8,STONE:5)
Block(1,15,-7,OBSIDIAN:0)
Block(1,15,-6,OBSIDIAN:0)
Block(1,15,-5,OBSIDIAN:0)
Block(1,15,-4,OBSIDIAN:0)
Block(1,15,-3,OBSIDIAN:0)
Block(1,15,-2,STONE:5)
Block(1,15,-1,STONE:5)
Block(1,15,0,STONE:5)
Block(1,15,1,STONE:5)
Block(1,15,2,STONE:5)
Block(1,15,3,STONE:5)
Block(1,15,4,STONE:5)
Block(1,15,5,STONE:5)
Block(1,15,6,STONE:5)
Block(1,15,7,STONE:5)
Block(1,15,8,STONE:5)
Block(1,16,-7,OBSIDIAN:0)
Block(1,16,-6,OBSIDIAN:0)
Block(1,16,-5,OBSIDIAN:0)
Block(1,16,-4,STONE:5)
Block(1,16,-3,STONE:5)
Block(1,16,-2,STONE:5)
Block(1,16,-1,STONE:5)
Block(1,16,0,STONE:5)
Block(1,16,1,STONE:5)
Block(1,16,2,STONE:5)
Block(1,16,3,STONE:5)
Block(1,16,4,STONE:5)
Block(1,16,5,STONE:5)
Block(1,16,6,STONE:5)
Block(1,16,7,STONE:5)
Block(1,16,8,STONE:5)
Block(1,17,-7,STONE:5)
Block(1,17,-6,STONE:5)
Block(1,17,-5,STONE:5)
Block(1,17,-4,STONE:5)
Block(1,17,-3,STONE:5)
Block(1,17,-2,STONE:5)
Block(1,17,-1,STONE:5)
Block(1,17,0,STONE:5)
Block(1,17,1,STONE:5)
Block(1,17,2,STONE:5)
Block(1,17,3,STONE:5)
Block(1,17,4,STONE:5)
Block(1,17,5,STONE:5)
Block(1,17,6,STONE:5)
Block(1,17,7,STONE:5)
Block(1,17,8,STONE:5)
Block(1,18,-7,STONE:5)
Block(1,18,-6,STONE:5)
Block(1,18,-5,STONE:5)
Block(1,18,-4,STONE:5)
Block(1,18,-3,STONE:5)
Block(1,18,-2,STONE:5)
Block(1,18,-1,STONE:5)
Block(1,18,0,STONE:5)
Block(1,18,1,STONE:5)
Block(1,18,2,STONE:5)
Block(1,18,3,STONE:5)
Block(1,18,4,STONE:5)
Block(1,18,5,STONE:5)
Block(1,18,6,STONE:5)
Block(1,18,7,STONE:5)
Block(1,18,8,STONE:5)
Block(1,19,-7,STONE:5)
Block(1,19,-6,STONE:0)
Block(1,19,-5,STONE:0)
Block(1,19,-4,STONE:0)
Block(1,19,-3,STONE:5)
Block(1,19,-2,STONE:5)
Block(1,19,-1,STONE:5)
Block(1,19,0,STONE:5)
Block(1,19,1,STONE:5)
Block(1,19,2,STONE:5)
Block(1,19,3,STONE:5)
Block(1,19,4,STONE:5)
Block(1,19,5,STONE:5)
Block(1,19,6,STONE:5)
Block(1,19,7,STONE:5)
Block(1,19,8,STONE:5)
Block(1,20,-7,STONE:0)
Block(1,20,-6,STONE:0)
Block(1,20,-5,STONE:0)
Block(1,20,-4,STONE:0)
Block(1,20,-3,STONE:0)
Block(1,20,-2,STONE:0)
Block(1,20,-1,STONE:0)
Block(1,20,0,STONE:0)
Block(1,20,1,STONE:0)
Block(1,20,2,STONE:0)
Block(1,20,3,STONE:5)
Block(1,20,4,STONE:5)
Block(1,20,5,STONE:5)
Block(1,20,6,STONE:5)
Block(1,20,7,STONE:5)
Block(1,20,8,STONE:5)
Block(1,21,-7,STONE:0)
Block(1,21,-6,STONE:0)
Block(1,21,-5,STONE:0)
Block(1,21,-4,STONE:0)
Block(1,21,-3,STONE:0)
Block(1,21,-2,STONE:0)
Block(1,21,-1,STONE:0)
Block(1,21,0,STONE:0)
Block(1,21,1,STONE:0)
Block(1,21,2,STONE:0)
Block(1,21,3,STONE:0)
Block(1,21,4,STONE:0)
Block(1,21,5,STONE:0)
Block(1,21,6,MAGMA:0)
Block(1,21,7,MAGMA:0)
Block(1,21,8,OBSIDIAN:0)
Block(1,22,-7,STONE:0)
Block(1,22,-6,STONE:0)
Block(1,22,-5,STONE:0)
Block(1,22,-4,STONE:0)
Block(1,22,-3,STONE:0)
Block(1,22,-2,STONE:0)
Block(1,22,-1,STONE:0)
Block(1,22,0,STONE:0)
Block(1,22,1,STONE:0)
Block(1,22,2,MAGMA:0)
Block(1,22,3,MAGMA:0)
Block(1,22,4,MAGMA:0)
Block(1,22,5,MAGMA:0)
Block(1,22,6,MAGMA:0)
Block(1,22,7,OBSIDIAN:0)
Block(1,22,8,OBSIDIAN:0)
Block(1,23,-7,STONE:0)
Block(1,23,-6,STONE:0)
Block(1,23,-5,STONE:0)
Block(1,23,-4,STONE:0)
Block(1,23,-3,STONE:0)
Block(1,23,-2,STONE:0)
Block(1,23,-1,STONE:0)
Block(1,23,0,STONE:0)
Block(1,23,1,STONE:0)
Block(1,23,2,MAGMA:0)
Block(1,23,3,MAGMA:0)
Block(1,23,4,MAGMA:0)
Block(1,23,5,MAGMA:0)
Block(1,23,6,MAGMA:0)
Block(1,23,7,OBSIDIAN:0)
Block(1,23,8,OBSIDIAN:0)
Block(1,24,-7,STONE:0)
Block(1,24,-6,STONE:0)
Block(1,24,-5,STONE:0)
Block(1,24,-4,STONE:0)
Block(1,24,-3,STONE:0)
Block(1,24,-2,STONE:0)
Block(1,24,-1,STONE:0)
Block(1,24,0,GRASS:0)
Block(1,24,1,GRASS:0)
Block(1,24,2,MAGMA:0)
Block(1,24,3,MAGMA:0)
Block(1,24,4,MAGMA:0)
Block(1,24,6,OBSIDIAN:0)
Block(1,24,7,OBSIDIAN:0)
Block(1,24,8,OBSIDIAN:0)
Block(1,25,-7,STONE:0)
Block(1,25,-6,STONE:0)
Block(1,25,-5,STONE:0)
Block(1,25,-4,STONE:0)
Block(1,25,-3,STONE:0)
Block(1,25,-2,STONE:0)
Block(1,25,-1,STONE:0)
Block(1,25,5,OBSIDIAN:0)
Block(1,25,6,OBSIDIAN:0)
Block(1,25,7,OBSIDIAN:0)
Block(1,26,-7,MAGMA:0)
Block(1,26,-6,MAGMA:0)
Block(1,26,-5,STONE:0)
Block(1,26,-4,STONE:0)
Block(1,26,-3,STONE:0)
Block(1,26,-2,STONE:0)
Block(1,26,-1,GRASS:0)
Block(1,26,4,OBSIDIAN:0)
Block(1,26,5,OBSIDIAN:0)
Block(1,26,6,OBSIDIAN:0)
Block(1,27,-7,MAGMA:0)
Block(1,27,-6,MAGMA:0)
Block(1,27,-5,MAGMA:0)
Block(1,27,-4,GRASS:0)
Block(1,27,-3,GRASS:0)
Block(1,27,-2,GRASS:0)
Block(1,27,3,OBSIDIAN:0)
Block(1,27,4,OBSIDIAN:0)
Block(1,28,-7,MAGMA:0)
Block(1,28,-6,MAGMA:0)
Block(1,28,-5,MAGMA:0)
Block(1,28,1,OBSIDIAN:0)
Block(1,28,2,OBSIDIAN:0)
Block(1,28,3,OBSIDIAN:0)
Block(1,29,-7,MAGMA:0)
Block(1,29,-6,MAGMA:0)
Block(1,29,1,OBSIDIAN:0)
Block(1,33,4,OBSIDIAN:0)
Block(1,33,5,OBSIDIAN:0)
Block(1,33,6,OBSIDIAN:0)
Block(1,34,4,OBSIDIAN:0)
Block(1,34,5,OBSIDIAN:0)
Block(1,34,6,OBSIDIAN:0)
Block(1,38,-6,OBSIDIAN:0)
Block(1,38,-5,OBSIDIAN:0)
Block(1,38,-4,OBSIDIAN:0)
Block(1,38,-3,OBSIDIAN:0)
Block(1,38,-2,OBSIDIAN:0)
Block(1,38,-1,OBSIDIAN:0)
Block(1,38,0,MAGMA:0)
Block(1,38,1,MAGMA:0)
Block(1,38,2,MAGMA:0)
Block(1,38,3,MAGMA:0)
Block(1,39,-7,STONE:0)
Block(1,39,-6,STONE:0)
Block(1,39,-5,OBSIDIAN:0)
Block(1,39,-4,OBSIDIAN:0)
Block(1,39,-3,MAGMA:0)
Block(1,39,-2,OBSIDIAN:0)
Block(1,39,-1,MAGMA:0)
Block(1,39,0,MAGMA:0)
Block(1,39,1,MAGMA:0)
Block(1,39,2,MAGMA:0)
Block(1,39,3,MAGMA:0)
Block(1,39,4,MAGMA:0)
Block(1,39,5,MAGMA:0)
Block(1,39,6,MAGMA:0)
Block(1,39,7,MAGMA:0)
Block(1,40,-7,STONE:0)
Block(1,40,-6,STONE:0)
Block(1,40,-5,STONE:0)
Block(1,40,-4,MAGMA:0)
Block(1,40,-3,MAGMA:0)
Block(1,40,-2,MAGMA:0)
Block(1,40,-1,MAGMA:0)
Block(1,40,0,MAGMA:0)
Block(1,40,1,MAGMA:0)
Block(1,40,2,MAGMA:0)
Block(1,40,3,MAGMA:0)
Block(1,40,4,MAGMA:0)
Block(1,40,5,MAGMA:0)
Block(1,40,6,MAGMA:0)
Block(1,40,7,OBSIDIAN:0)
Block(1,40,8,OBSIDIAN:0)
Block(1,41,-7,STONE:0)
Block(1,41,-6,STONE:0)
Block(1,41,-5,STONE:0)
Block(1,41,-4,STONE:0)
Block(1,41,-3,MAGMA:0)
Block(1,41,-2,MAGMA:0)
Block(1,41,-1,MAGMA:0)
Block(1,41,0,MAGMA:0)
Block(1,41,1,MAGMA:0)
Block(1,41,2,MAGMA:0)
Block(1,41,3,MAGMA:0)
Block(1,41,4,MAGMA:0)
Block(1,41,5,MAGMA:0)
Block(1,41,6,MAGMA:0)
Block(1,41,7,MAGMA:0)
Block(1,41,8,OBSIDIAN:0)
Block(1,42,-7,STONE:0)
Block(1,42,-6,STONE:0)
Block(1,42,-5,STONE:0)
Block(1,42,-4,STONE:0)
Block(1,42,-3,STONE:0)
Block(1,42,-2,STONE:0)
Block(1,42,-1,STONE:0)
Block(1,42,0,STONE:0)
Block(1,42,1,STONE:0)
Block(1,42,2,STONE:0)
Block(1,42,3,STONE:0)
Block(1,42,4,MAGMA:0)
Block(1,42,5,MAGMA:0)
Block(1,42,6,MAGMA:0)
Block(1,42,7,MAGMA:0)
Block(1,42,8,MAGMA:0)
Block(1,43,-7,STONE:5)
Block(1,43,-6,STONE:5)
Block(1,43,-5,STONE:5)
Block(1,43,-4,STONE:5)
Block(1,43,-3,STONE:5)
Block(1,43,-2,STONE:5)
Block(1,43,-1,STONE:5)
Block(1,43,0,STONE:5)
Block(1,43,1,STONE:5)
Block(1,43,2,STONE:5)
Block(1,43,3,STONE:5)
Block(1,43,4,MAGMA:0)
Block(1,43,5,MAGMA:0)
Block(1,43,6,MAGMA:0)
Block(1,43,7,MAGMA:0)
Block(1,43,8,MAGMA:0)
Block(1,44,-7,STONE:5)
Block(1,44,-6,STONE:5)
Block(1,44,-5,STONE:5)
Block(1,44,-4,STONE:5)
Block(1,44,-3,STONE:5)
Block(1,44,-2,STONE:5)
Block(1,44,-1,STONE:5)
Block(1,44,0,STONE:5)
Block(1,44,1,STONE:5)
Block(1,44,2,STONE:5)
Block(1,44,3,STONE:5)
Block(1,44,4,STONE:5)
Block(1,44,5,STONE:5)
Block(1,44,6,STONE:5)
Block(1,44,7,STONE:0)
Block(1,44,8,STONE:0)
Block(1,45,-7,STONE:5)
Block(1,45,-6,STONE:5)
Block(1,45,-5,STONE:5)
Block(1,45,-4,STONE:5)
Block(1,45,-3,STONE:5)
Block(1,45,-2,STONE:5)
Block(1,45,-1,STONE:5)
Block(1,45,0,STONE:5)
Block(1,45,1,STONE:5)
Block(1,45,2,STONE:5)
Block(1,45,3,STONE:5)
Block(1,45,4,STONE:5)
Block(1,45,5,STONE:5)
Block(1,45,6,STONE:5)
Block(1,45,7,STONE:5)
Block(1,45,8,STONE:0)
Block(1,46,-7,STONE:5)
Block(1,46,-6,STONE:5)
Block(1,46,-5,STONE:5)
Block(1,46,-4,STONE:5)
Block(1,46,-3,STONE:5)
Block(1,46,-2,STONE:5)
Block(1,46,-1,STONE:5)
Block(1,46,0,STONE:5)
Block(1,46,1,STONE:5)
Block(1,46,2,STONE:5)
Block(1,46,3,STONE:5)
Block(1,46,4,STONE:5)
Block(1,46,5,STONE:5)
Block(1,46,6,STONE:5)
Block(1,46,7,STONE:5)
Block(1,46,8,STONE:5)
Block(1,47,-7,STONE:5)
Block(1,47,-6,STONE:5)
Block(1,47,-5,STONE:5)
Block(1,47,-4,STONE:5)
Block(1,47,-3,STONE:5)
Block(1,47,-2,STONE:5)
Block(1,47,-1,STONE:5)
Block(1,47,0,STONE:5)
Block(1,47,1,STONE:5)
Block(1,47,2,STONE:5)
Block(1,47,3,STONE:5)
Block(1,47,4,STONE:5)
Block(1,47,5,STONE:5)
Block(1,47,6,STONE:5)
Block(1,47,7,STONE:5)
Block(1,47,8,STONE:5)
Block(1,48,-7,STONE:5)
Block(1,48,-6,STONE:5)
Block(1,48,-5,STONE:5)
Block(1,48,-4,STONE:5)
Block(1,48,-3,STONE:5)
Block(1,48,-2,STONE:5)
Block(1,48,-1,STONE:5)
Block(1,48,0,STONE:5)
Block(1,48,1,STONE:5)
Block(1,48,2,STONE:5)
Block(1,48,3,STONE:5)
Block(1,48,4,STONE:5)
Block(1,48,5,STONE:5)
Block(1,48,6,STONE:5)
Block(1,48,7,STONE:5)
Block(1,48,8,STONE:5)
Block(1,49,5,STONE:5)
Block(1,49,6,STONE:5)
Block(1,49,7,STONE:5)
Block(1,49,8,STONE:5)
Block(1,50,6,STONE:5)
Block(1,50,7,STONE:5)
Block(1,50,8,STONE:5)
Block(1,51,6,STONE:5)
Block(1,51,7,STONE:5)
Block(1,51,8,STONE:5)
Block(1,52,8,STONE:5)
Block(2,11,8,STONE:5)
Block(2,12,8,STONE:5)
Block(2,13,7,STONE:5)
Block(2,13,8,STONE:5)
Block(2,14,-7,OBSIDIAN:0)
Block(2,14,-6,OBSIDIAN:0)
Block(2,14,-5,STONE:5)
Block(2,14,-4,STONE:5)
Block(2,14,-3,STONE:5)
Block(2,14,-2,STONE:5)
Block(2,14,-1,STONE:5)
Block(2,14,0,STONE:5)
Block(2,14,1,STONE:5)
Block(2,14,2,STONE:5)
Block(2,14,3,STONE:5)
Block(2,14,4,STONE:5)
Block(2,14,6,STONE:5)
Block(2,14,7,STONE:5)
Block(2,14,8,STONE:5)
Block(2,15,-7,OBSIDIAN:0)
Block(2,15,-6,OBSIDIAN:0)
Block(2,15,-5,STONE:5)
Block(2,15,-4,STONE:5)
Block(2,15,-3,STONE:5)
Block(2,15,-2,STONE:5)
Block(2,15,-1,STONE:5)
Block(2,15,0,STONE:5)
Block(2,15,1,STONE:5)
Block(2,15,2,STONE:5)
Block(2,15,3,STONE:5)
Block(2,15,4,STONE:5)
Block(2,15,5,STONE:5)
Block(2,15,6,STONE:5)
Block(2,15,7,STONE:5)
Block(2,15,8,STONE:5)
Block(2,16,-7,STONE:5)
Block(2,16,-6,STONE:5)
Block(2,16,-5,STONE:5)
Block(2,16,-4,STONE:5)
Block(2,16,-3,STONE:5)
Block(2,16,-2,STONE:5)
Block(2,16,-1,STONE:5)
Block(2,16,0,STONE:5)
Block(2,16,1,STONE:5)
Block(2,16,2,STONE:5)
Block(2,16,3,STONE:5)
Block(2,16,4,STONE:5)
Block(2,16,5,STONE:5)
Block(2,16,6,STONE:5)
Block(2,16,7,STONE:5)
Block(2,16,8,STONE:5)
Block(2,17,-7,STONE:5)
Block(2,17,-6,STONE:5)
Block(2,17,-5,STONE:5)
Block(2,17,-4,STONE:5)
Block(2,17,-3,STONE:5)
Block(2,17,-2,STONE:5)
Block(2,17,-1,STONE:5)
Block(2,17,0,STONE:5)
Block(2,17,1,STONE:5)
Block(2,17,2,STONE:5)
Block(2,17,3,STONE:5)
Block(2,17,4,STONE:5)
Block(2,17,5,STONE:5)
Block(2,17,6,STONE:5)
Block(2,17,7,STONE:5)
Block(2,17,8,STONE:5)
Block(2,18,-7,STONE:5)
Block(2,18,-6,STONE:5)
Block(2,18,-5,STONE:5)
Block(2,18,-4,STONE:5)
Block(2,18,-3,STONE:5)
Block(2,18,-2,STONE:5)
Block(2,18,-1,STONE:5)
Block(2,18,0,STONE:5)
Block(2,18,1,STONE:5)
Block(2,18,2,STONE:5)
Block(2,18,3,STONE:5)
Block(2,18,4,STONE:5)
Block(2,18,5,STONE:5)
Block(2,18,6,STONE:5)
Block(2,18,7,STONE:5)
Block(2,18,8,STONE:5)
Block(2,19,-7,STONE:5)
Block(2,19,-6,STONE:5)
Block(2,19,-5,STONE:5)
Block(2,19,-4,STONE:5)
Block(2,19,-3,STONE:5)
Block(2,19,-2,STONE:5)
Block(2,19,-1,STONE:5)
Block(2,19,0,STONE:5)
Block(2,19,1,STONE:5)
Block(2,19,2,STONE:5)
Block(2,19,3,STONE:5)
Block(2,19,4,STONE:5)
Block(2,19,5,STONE:5)
Block(2,19,6,STONE:5)
Block(2,19,7,STONE:5)
Block(2,19,8,STONE:5)
Block(2,20,-7,STONE:0)
Block(2,20,-6,STONE:0)
Block(2,20,-5,STONE:0)
Block(2,20,-4,STONE:0)
Block(2,20,-3,STONE:0)
Block(2,20,-2,STONE:0)
Block(2,20,-1,STONE:0)
Block(2,20,0,STONE:0)
Block(2,20,1,STONE:0)
Block(2,20,2,STONE:0)
Block(2,20,3,STONE:0)
Block(2,20,4,STONE:0)
Block(2,20,5,STONE:0)
Block(2,20,6,STONE:0)
Block(2,20,7,STONE:0)
Block(2,20,8,STONE:0)
Block(2,21,-7,STONE:0)
Block(2,21,-6,STONE:0)
Block(2,21,-5,STONE:0)
Block(2,21,-4,STONE:0)
Block(2,21,-3,STONE:0)
Block(2,21,-2,STONE:0)
Block(2,21,-1,STONE:0)
Block(2,21,0,STONE:0)
Block(2,21,1,STONE:0)
Block(2,21,2,STONE:0)
Block(2,21,3,MAGMA:0)
Block(2,21,4,MAGMA:0)
Block(2,21,5,MAGMA:0)
Block(2,21,6,MAGMA:0)
Block(2,21,7,MAGMA:0)
Block(2,21,8,MAGMA:0)
Block(2,22,-7,STONE:0)
Block(2,22,-6,STONE:0)
Block(2,22,-5,STONE:0)
Block(2,22,-4,STONE:0)
Block(2,22,-3,STONE:0)
Block(2,22,-2,STONE:0)
Block(2,22,-1,STONE:0)
Block(2,22,0,STONE:0)
Block(2,22,1,STONE:0)
Block(2,22,2,MAGMA:0)
Block(2,22,3,MAGMA:0)
Block(2,22,4,MAGMA:0)
Block(2,22,5,MAGMA:0)
Block(2,22,6,MAGMA:0)
Block(2,22,7,MAGMA:0)
Block(2,22,8,OBSIDIAN:0)
Block(2,23,-7,STONE:0)
Block(2,23,-6,STONE:0)
Block(2,23,-5,STONE:0)
Block(2,23,-4,STONE:0)
Block(2,23,-3,STONE:0)
Block(2,23,-2,STONE:0)
Block(2,23,-1,STONE:0)
Block(2,23,0,STONE:0)
Block(2,23,1,MAGMA:0)
Block(2,23,2,MAGMA:0)
Block(2,23,3,MAGMA:0)
Block(2,23,4,MAGMA:0)
Block(2,23,5,MAGMA:0)
Block(2,23,6,MAGMA:0)
Block(2,23,7,MAGMA:0)
Block(2,23,8,OBSIDIAN:0)
Block(2,24,-7,STONE:0)
Block(2,24,-6,STONE:0)
Block(2,24,-5,STONE:0)
Block(2,24,-4,STONE:0)
Block(2,24,-3,STONE:0)
Block(2,24,-2,STONE:0)
Block(2,24,-1,STONE:0)
Block(2,24,0,STONE:0)
Block(2,24,1,MAGMA:0)
Block(2,24,2,MAGMA:0)
Block(2,24,3,MAGMA:0)
Block(2,24,4,MAGMA:0)
Block(2,24,6,MAGMA:0)
Block(2,24,7,OBSIDIAN:0)
Block(2,24,8,OBSIDIAN:0)
Block(2,25,-7,STONE:0)
Block(2,25,-6,STONE:0)
Block(2,25,-5,STONE:0)
Block(2,25,-4,STONE:0)
Block(2,25,-3,STONE:0)
Block(2,25,-2,STONE:0)
Block(2,25,-1,STONE:0)
Block(2,25,0,STONE:0)
Block(2,25,6,OBSIDIAN:0)
Block(2,25,7,OBSIDIAN:0)
Block(2,26,-7,STONE:0)
Block(2,26,-6,STONE:0)
Block(2,26,-5,STONE:0)
Block(2,26,-4,STONE:0)
Block(2,26,-3,STONE:0)
Block(2,26,-2,STONE:0)
Block(2,26,-1,STONE:0)
Block(2,26,0,GRASS:0)
Block(2,26,6,OBSIDIAN:0)
Block(2,27,-7,MAGMA:0)
Block(2,27,-6,MAGMA:0)
Block(2,27,-5,MAGMA:0)
Block(2,27,-4,STONE:0)
Block(2,27,-3,STONE:0)
Block(2,27,-2,STONE:0)
Block(2,27,-1,GRASS:0)
Block(2,28,-7,MAGMA:0)
Block(2,28,-6,MAGMA:0)
Block(2,28,-5,MAGMA:0)
Block(2,28,-4,GRASS:0)
Block(2,28,-3,GRASS:0)
Block(2,28,-2,GRASS:0)
Block(2,29,-7,MAGMA:0)
Block(2,29,-6,MAGMA:0)
Block(2,30,-7,MAGMA:0)
Block(2,32,3,OBSIDIAN:0)
Block(2,32,4,OBSIDIAN:0)
Block(2,33,3,OBSIDIAN:0)
Block(2,33,4,OBSIDIAN:0)
Block(2,33,5,OBSIDIAN:0)
Block(2,34,4,OBSIDIAN:0)
Block(2,38,-6,OBSIDIAN:0)
Block(2,38,-5,OBSIDIAN:0)
Block(2,38,-4,OBSIDIAN:0)
Block(2,38,-3,MAGMA:0)
Block(2,38,-2,MAGMA:0)
Block(2,38,-1,MAGMA:0)
Block(2,38,0,MAGMA:0)
Block(2,38,1,MAGMA:0)
Block(2,38,2,MAGMA:0)
Block(2,38,3,MAGMA:0)
Block(2,39,-7,STONE:0)
Block(2,39,-6,STONE:0)
Block(2,39,-5,OBSIDIAN:0)
Block(2,39,-4,OBSIDIAN:0)
Block(2,39,-3,MAGMA:0)
Block(2,39,-2,MAGMA:0)
Block(2,39,-1,MAGMA:0)
Block(2,39,0,MAGMA:0)
Block(2,39,1,MAGMA:0)
Block(2,39,2,MAGMA:0)
Block(2,39,3,MAGMA:0)
Block(2,39,4,MAGMA:0)
Block(2,39,5,MAGMA:0)
Block(2,39,6,MAGMA:0)
Block(2,39,7,MAGMA:0)
Block(2,39,8,MAGMA:0)
Block(2,40,-7,STONE:0)
Block(2,40,-6,STONE:0)
Block(2,40,-5,STONE:0)
Block(2,40,-4,MAGMA:0)
Block(2,40,-3,MAGMA:0)
Block(2,40,-2,MAGMA:0)
Block(2,40,-1,MAGMA:0)
Block(2,40,0,MAGMA:0)
Block(2,40,1,MAGMA:0)
Block(2,40,2,MAGMA:0)
Block(2,40,3,MAGMA:0)
Block(2,40,4,MAGMA:0)
Block(2,40,5,MAGMA:0)
Block(2,40,6,MAGMA:0)
Block(2,40,7,MAGMA:0)
Block(2,40,8,MAGMA:0)
Block(2,41,-7,STONE:0)
Block(2,41,-6,STONE:0)
Block(2,41,-5,STONE:0)
Block(2,41,-4,STONE:0)
Block(2,41,-3,MAGMA:0)
Block(2,41,-2,MAGMA:0)
Block(2,41,-1,MAGMA:0)
Block(2,41,0,MAGMA:0)
Block(2,41,1,MAGMA:0)
Block(2,41,2,STONE:0)
Block(2,41,3,STONE:0)
Block(2,41,4,STONE:0)
Block(2,41,5,MAGMA:0)
Block(2,41,6,MAGMA:0)
Block(2,41,7,MAGMA:0)
Block(2,41,8,MAGMA:0)
Block(2,42,-7,STONE:5)
Block(2,42,-6,STONE:5)
Block(2,42,-5,STONE:5)
Block(2,42,-4,STONE:0)
Block(2,42,-3,STONE:5)
Block(2,42,-2,STONE:5)
Block(2,42,-1,STONE:5)
Block(2,42,0,STONE:0)
Block(2,42,1,STONE:0)
Block(2,42,2,STONE:0)
Block(2,42,3,STONE:0)
Block(2,42,4,STONE:0)
Block(2,42,5,MAGMA:0)
Block(2,42,6,MAGMA:0)
Block(2,42,7,MAGMA:0)
Block(2,42,8,MAGMA:0)
Block(2,43,-7,STONE:5)
Block(2,43,-6,STONE:5)
Block(2,43,-5,STONE:5)
Block(2,43,-4,STONE:5)
Block(2,43,-3,STONE:5)
Block(2,43,-2,STONE:5)
Block(2,43,-1,STONE:5)
Block(2,43,0,STONE:5)
Block(2,43,1,STONE:5)
Block(2,43,2,STONE:5)
Block(2,43,3,STONE:5)
Block(2,43,4,STONE:0)
Block(2,43,5,STONE:0)
Block(2,43,6,STONE:0)
Block(2,43,7,MAGMA:0)
Block(2,43,8,MAGMA:0)
Block(2,44,-7,STONE:5)
Block(2,44,-6,STONE:5)
Block(2,44,-5,STONE:5)
Block(2,44,-4,STONE:5)
Block(2,44,-3,STONE:5)
Block(2,44,-2,STONE:5)
Block(2,44,-1,STONE:5)
Block(2,44,0,STONE:5)
Block(2,44,1,STONE:5)
Block(2,44,2,STONE:5)
Block(2,44,3,STONE:5)
Block(2,44,4,STONE:5)
Block(2,44,5,STONE:5)
Block(2,44,6,STONE:0)
Block(2,44,7,STONE:0)
Block(2,44,8,STONE:0)
Block(2,45,-7,STONE:5)
Block(2,45,-6,STONE:5)
Block(2,45,-5,STONE:5)
Block(2,45,-4,STONE:5)
Block(2,45,-3,STONE:5)
Block(2,45,-2,STONE:5)
Block(2,45,-1,STONE:5)
Block(2,45,0,STONE:5)
Block(2,45,1,STONE:5)
Block(2,45,2,STONE:5)
Block(2,45,3,STONE:5)
Block(2,45,4,STONE:5)
Block(2,45,5,STONE:5)
Block(2,45,6,STONE:5)
Block(2,45,7,STONE:5)
Block(2,45,8,STONE:0)
Block(2,46,-7,STONE:5)
Block(2,46,-6,STONE:5)
Block(2,46,-5,STONE:5)
Block(2,46,-4,STONE:5)
Block(2,46,-3,STONE:5)
Block(2,46,-2,STONE:5)
Block(2,46,-1,STONE:5)
Block(2,46,0,STONE:5)
Block(2,46,1,STONE:5)
Block(2,46,2,STONE:5)
Block(2,46,3,STONE:5)
Block(2,46,4,STONE:5)
Block(2,46,5,STONE:5)
Block(2,46,6,STONE:5)
Block(2,46,7,STONE:5)
Block(2,46,8,STONE:5)
Block(2,47,-7,STONE:5)
Block(2,47,-6,STONE:5)
Block(2,47,-5,STONE:5)
Block(2,47,-4,STONE:5)
Block(2,47,-3,STONE:5)
Block(2,47,-2,STONE:5)
Block(2,47,-1,STONE:5)
Block(2,47,0,STONE:5)
Block(2,47,1,STONE:5)
Block(2,47,2,STONE:5)
Block(2,47,3,STONE:5)
Block(2,47,4,STONE:5)
Block(2,47,5,STONE:5)
Block(2,47,6,STONE:5)
Block(2,47,7,STONE:5)
Block(2,47,8,STONE:5)
Block(2,48,-7,STONE:5)
Block(2,48,-6,STONE:5)
Block(2,48,-5,STONE:5)
Block(2,48,-4,STONE:5)
