#######################################################################
# +-----------------------------------------------------------------+ #
# |                            BO3 object                           | #
# +-----------------------------------------------------------------+ #
#######################################################################

Author: Bo3 BulkEdit

Description: Converted Schematic - Modified by Bo3BulkEdit

Version: 3

SettingsMode: WriteDisable

#######################################################################
# +-----------------------------------------------------------------+ #
# |                          Main settings                          | #
# +-----------------------------------------------------------------+ #
#######################################################################

IsOTGPlus: false
Tree: false
Frequency: 1
Rarity: 100
RotateRandomly: false
SpawnHeight: randomY
SpawnHeightOffset: 0
SpawnHeightVariance: 0
MaxBranchDepth: 10
ExcludedBiomes: All

##############################
# Height Limits for the BO3. #
##############################

MinHeight: 0
MaxHeight: 256

#######################################################################
# +-----------------------------------------------------------------+ #
# |                      Source block settings                      | #
# +-----------------------------------------------------------------+ #
#######################################################################

SourceBlocks: AIR
MaxPercentageOutsideSourceBlock: 100
OutsideSourceBlock: placeAnyway

#######################################################################
# +-----------------------------------------------------------------+ #
# |                              Blocks                             | #
# +-----------------------------------------------------------------+ #
#######################################################################

B(-8,0,-8,LOG:1)
B(7,0,-8,LOG:1)
B(-8,0,-5,LOG:1)
B(1,0,-5,LOG:1)
B(4,0,-5,LOG:1)
B(7,0,-5,LOG:1)
B(-8,0,-2,LOG:1)
B(1,0,-2,LOG:1)
B(4,0,-2,LOG:1)
B(7,0,-2,LOG:1)
B(-8,0,7,LOG:1)
B(7,0,7,LOG:1)
B(-8,1,-8,PLANKS:5)
B(-7,1,-8,PLANKS:5)
B(-6,1,-8,PLANKS:5)
B(-5,1,-8,PLANKS:5)
B(-4,1,-8,PLANKS:5)
B(-3,1,-8,PLANKS:5)
B(-2,1,-8,PLANKS:5)
B(-1,1,-8,PLANKS:5)
B(0,1,-8,PLANKS:5)
B(1,1,-8,PLANKS:5)
B(2,1,-8,PLANKS:5)
B(3,1,-8,PLANKS:5)
B(4,1,-8,PLANKS:5)
B(5,1,-8,PLANKS:5)
B(6,1,-8,PLANKS:5)
B(7,1,-8,PLANKS:5)
B(-8,1,-7,PLANKS:5)
B(-7,1,-7,PLANKS:5)
B(-6,1,-7,PLANKS:5)
B(-5,1,-7,PLANKS:5)
B(-4,1,-7,PLANKS:5)
B(-3,1,-7,PLANKS:5)
B(-2,1,-7,PLANKS:5)
B(-1,1,-7,PLANKS:5)
B(0,1,-7,PLANKS:5)
B(1,1,-7,PLANKS:5)
B(2,1,-7,PLANKS:5)
B(3,1,-7,PLANKS:5)
B(4,1,-7,PLANKS:5)
B(5,1,-7,PLANKS:5)
B(6,1,-7,PLANKS:5)
B(7,1,-7,PLANKS:5)
B(-8,1,-6,PLANKS:5)
B(-7,1,-6,PLANKS:5)
B(-6,1,-6,PLANKS:5)
B(-5,1,-6,PLANKS:5)
B(-4,1,-6,PLANKS:5)
B(-3,1,-6,PLANKS:5)
B(-2,1,-6,PLANKS:5)
B(-1,1,-6,PLANKS:5)
B(0,1,-6,PLANKS:5)
B(1,1,-6,PLANKS:5)
B(2,1,-6,PLANKS:5)
B(3,1,-6,PLANKS:5)
B(4,1,-6,PLANKS:5)
B(5,1,-6,PLANKS:5)
B(6,1,-6,PLANKS:5)
B(7,1,-6,PLANKS:5)
B(-8,1,-5,PLANKS:5)
B(-7,1,-5,PLANKS:5)
B(-6,1,-5,PLANKS:5)
B(-5,1,-5,PLANKS:5)
B(-4,1,-5,PLANKS:5)
B(-3,1,-5,PLANKS:5)
B(-2,1,-5,PLANKS:5)
B(-1,1,-5,PLANKS:5)
B(0,1,-5,PLANKS:5)
B(1,1,-5,PLANKS:5)
B(2,1,-5,PLANKS:5)
B(3,1,-5,PLANKS:5)
B(4,1,-5,PLANKS:5)
B(5,1,-5,PLANKS:5)
B(6,1,-5,PLANKS:5)
B(7,1,-5,PLANKS:5)
B(1,1,-4,PLANKS:5)
B(2,1,-4,PLANKS:5)
B(3,1,-4,PLANKS:5)
B(4,1,-4,PLANKS:5)
B(1,1,-3,PLANKS:5)
B(2,1,-3,PLANKS:5)
B(3,1,-3,PLANKS:5)
B(4,1,-3,PLANKS:5)
B(-8,1,-2,PLANKS:5)
B(-7,1,-2,PLANKS:5)
B(-6,1,-2,PLANKS:5)
B(-5,1,-2,PLANKS:5)
B(-4,1,-2,PLANKS:5)
B(-3,1,-2,PLANKS:5)
B(-2,1,-2,PLANKS:5)
B(-1,1,-2,PLANKS:5)
B(0,1,-2,PLANKS:5)
B(1,1,-2,PLANKS:5)
B(2,1,-2,PLANKS:5)
B(3,1,-2,PLANKS:5)
B(4,1,-2,PLANKS:5)
B(5,1,-2,PLANKS:5)
B(6,1,-2,PLANKS:5)
B(7,1,-2,PLANKS:5)
B(-8,1,-1,PLANKS:5)
B(-7,1,-1,PLANKS:5)
B(-6,1,-1,PLANKS:5)
B(-5,1,-1,PLANKS:5)
B(-4,1,-1,PLANKS:5)
B(-3,1,-1,PLANKS:5)
B(-2,1,-1,PLANKS:5)
B(-1,1,-1,STONE)
B(0,1,-1,PLANKS:5)
B(1,1,-1,PLANKS:5)
B(2,1,-1,PLANKS:5)
B(3,1,-1,PLANKS:5)
B(4,1,-1,STONE)
B(5,1,-1,PLANKS:5)
B(6,1,-1,PLANKS:5)
B(7,1,-1,PLANKS:5)
B(-8,1,0,PLANKS:5)
B(-7,1,0,PLANKS:5)
B(-6,1,0,PLANKS:5)
B(-5,1,0,PLANKS:5)
B(-4,1,0,PLANKS:5)
B(-3,1,0,STONE)
B(-2,1,0,STONE)
B(-1,1,0,STONE)
B(0,1,0,PLANKS:5)
B(1,1,0,STONE)
B(2,1,0,STONE)
B(3,1,0,PLANKS:5)
B(4,1,0,STONE)
B(5,1,0,STONE)
B(6,1,0,PLANKS:5)
B(7,1,0,PLANKS:5)
B(-8,1,1,PLANKS:5)
B(-7,1,1,PLANKS:5)
B(-6,1,1,PLANKS:5)
B(-5,1,1,STONE)
B(-4,1,1,STONE)
B(-3,1,1,STONE)
B(-2,1,1,PLANKS:5)
B(-1,1,1,PLANKS:5)
B(0,1,1,PLANKS:5)
B(1,1,1,STONE)
B(2,1,1,PLANKS:5)
B(3,1,1,STONE)
B(4,1,1,STONE)
B(5,1,1,STONE)
B(6,1,1,PLANKS:5)
B(7,1,1,PLANKS:5)
B(-8,1,2,PLANKS:5)
B(-7,1,2,PLANKS:5)
B(-6,1,2,PLANKS:5)
B(-5,1,2,STONE)
B(-4,1,2,STONE)
B(-3,1,2,STONE)
B(-2,1,2,PLANKS:5)
B(-1,1,2,STONE)
B(0,1,2,STONE)
B(1,1,2,PLANKS:5)
B(2,1,2,PLANKS:5)
B(3,1,2,PLANKS:5)
B(4,1,2,PLANKS:5)
B(5,1,2,STONE)
B(6,1,2,STONE)
B(7,1,2,PLANKS:5)
B(-8,1,3,PLANKS:5)
B(-7,1,3,PLANKS:5)
B(-6,1,3,STONE)
B(-5,1,3,STONE)
B(-4,1,3,STONE)
B(-3,1,3,PLANKS:5)
B(-2,1,3,PLANKS:5)
B(-1,1,3,PLANKS:5)
B(0,1,3,STONE)
B(1,1,3,STONE)
B(2,1,3,PLANKS:5)
B(3,1,3,PLANKS:5)
B(4,1,3,STONE)
B(5,1,3,STONE)
B(6,1,3,STONE)
B(7,1,3,PLANKS:5)
B(-8,1,4,PLANKS:5)
B(-7,1,4,PLANKS:5)
B(-6,1,4,STONE)
B(-5,1,4,STONE)
B(-4,1,4,STONE)
B(-3,1,4,STONE)
B(-2,1,4,PLANKS:5)
B(-1,1,4,STONE)
B(0,1,4,STONE)
B(1,1,4,STONE)
B(2,1,4,STONE)
B(3,1,4,STONE)
B(4,1,4,STONE)
B(5,1,4,STONE)
B(6,1,4,PLANKS:5)
B(7,1,4,PLANKS:5)
B(-8,1,5,PLANKS:5)
B(-7,1,5,PLANKS:5)
B(-6,1,5,PLANKS:5)
B(-5,1,5,PLANKS:5)
B(-4,1,5,STONE)
B(-3,1,5,STONE)
B(-2,1,5,STONE)
B(-1,1,5,STONE)
B(0,1,5,STONE)
B(1,1,5,STONE)
B(2,1,5,STONE)
B(3,1,5,STONE)
B(4,1,5,STONE)
B(5,1,5,STONE)
B(6,1,5,PLANKS:5)
B(7,1,5,PLANKS:5)
B(-8,1,6,PLANKS:5)
B(-7,1,6,PLANKS:5)
B(-6,1,6,PLANKS:5)
B(-5,1,6,PLANKS:5)
B(-4,1,6,PLANKS:5)
B(-3,1,6,STONE)
B(-2,1,6,PLANKS:5)
B(-1,1,6,PLANKS:5)
B(0,1,6,PLANKS:5)
B(1,1,6,STONE)
B(2,1,6,STONE)
B(3,1,6,STONE)
B(4,1,6,PLANKS:5)
B(5,1,6,PLANKS:5)
B(6,1,6,PLANKS:5)
B(7,1,6,PLANKS:5)
B(-8,1,7,PLANKS:5)
B(-7,1,7,PLANKS:5)
B(-6,1,7,PLANKS:5)
B(-5,1,7,PLANKS:5)
B(-4,1,7,PLANKS:5)
B(-3,1,7,PLANKS:5)
B(-2,1,7,PLANKS:5)
B(-1,1,7,PLANKS:5)
B(0,1,7,PLANKS:5)
B(1,1,7,PLANKS:5)
B(2,1,7,PLANKS:5)
B(3,1,7,PLANKS:5)
B(4,1,7,PLANKS:5)
B(5,1,7,PLANKS:5)
B(6,1,7,PLANKS:5)
B(7,1,7,PLANKS:5)
B(-8,2,-8,SPRUCE_FENCE)
RB(-7,2,-8,SKULL:1,./NBT/Skulls/dungeon_skull_01.nbt,6,AIR,9,SKULL:1,./NBT/Skulls/dungeon_skull_02.nbt,12,AIR,15,SKULL:1,./NBT/Skulls/dungeon_skull_03.nbt,18,AIR,21,SKULL:1,./NBT/Skulls/dungeon_skull_04.nbt,24,AIR,27,SKULL:1,./NBT/Skulls/dungeon_skull_05.nbt,30,AIR,33,SKULL:1,./NBT/Skulls/dungeon_skull_06.nbt,36,AIR,39,SKULL:1,./NBT/Skulls/dungeon_skull_07.nbt,42,AIR,45,SKULL:1,./NBT/Skulls/dungeon_skull_08.nbt,48,AIR,51,SKULL:1,./NBT/Skulls/dungeon_skull_09.nbt,54,AIR,57,SKULL:1,./NBT/Skulls/dungeon_skull_10.nbt,60,AIR,63,SKULL:1,./NBT/Skulls/dungeon_skull_11.nbt,66,AIR,69,SKULL:1,./NBT/Skulls/dungeon_skull_12.nbt,72,AIR,75,SKULL:1,./NBT/Skulls/dungeon_skull_13.nbt,78,AIR,81,SKULL:1,./NBT/Skulls/dungeon_skull_14.nbt,84,AIR,87,SKULL:1,./NBT/Skulls/dungeon_skull_15.nbt,90,AIR,93,SKULL:1,./NBT/Skulls/dungeon_skull_16.nbt,96,AIR,100)
B(-6,2,-8,AIR)
B(-5,2,-8,SPRUCE_FENCE)
B(-4,2,-8,AIR)
RB(-3,2,-8,SKULL:1,./NBT/Skulls/dungeon_skull_01.nbt,6,AIR,9,SKULL:1,./NBT/Skulls/dungeon_skull_02.nbt,12,AIR,15,SKULL:1,./NBT/Skulls/dungeon_skull_03.nbt,18,AIR,21,SKULL:1,./NBT/Skulls/dungeon_skull_04.nbt,24,AIR,27,SKULL:1,./NBT/Skulls/dungeon_skull_05.nbt,30,AIR,33,SKULL:1,./NBT/Skulls/dungeon_skull_06.nbt,36,AIR,39,SKULL:1,./NBT/Skulls/dungeon_skull_07.nbt,42,AIR,45,SKULL:1,./NBT/Skulls/dungeon_skull_08.nbt,48,AIR,51,SKULL:1,./NBT/Skulls/dungeon_skull_09.nbt,54,AIR,57,SKULL:1,./NBT/Skulls/dungeon_skull_10.nbt,60,AIR,63,SKULL:1,./NBT/Skulls/dungeon_skull_11.nbt,66,AIR,69,SKULL:1,./NBT/Skulls/dungeon_skull_12.nbt,72,AIR,75,SKULL:1,./NBT/Skulls/dungeon_skull_13.nbt,78,AIR,81,SKULL:1,./NBT/Skulls/dungeon_skull_14.nbt,84,AIR,87,SKULL:1,./NBT/Skulls/dungeon_skull_15.nbt,90,AIR,93,SKULL:1,./NBT/Skulls/dungeon_skull_16.nbt,96,AIR,100)
B(-2,2,-8,SPRUCE_FENCE)
B(-1,2,-8,AIR)
B(0,2,-8,AIR)
B(1,2,-8,SPRUCE_FENCE)
B(2,2,-8,AIR)
B(3,2,-8,AIR)
B(4,2,-8,SPRUCE_FENCE)
RB(5,2,-8,SKULL:1,./NBT/Skulls/dungeon_skull_01.nbt,6,AIR,9,SKULL:1,./NBT/Skulls/dungeon_skull_02.nbt,12,AIR,15,SKULL:1,./NBT/Skulls/dungeon_skull_03.nbt,18,AIR,21,SKULL:1,./NBT/Skulls/dungeon_skull_04.nbt,24,AIR,27,SKULL:1,./NBT/Skulls/dungeon_skull_05.nbt,30,AIR,33,SKULL:1,./NBT/Skulls/dungeon_skull_06.nbt,36,AIR,39,SKULL:1,./NBT/Skulls/dungeon_skull_07.nbt,42,AIR,45,SKULL:1,./NBT/Skulls/dungeon_skull_08.nbt,48,AIR,51,SKULL:1,./NBT/Skulls/dungeon_skull_09.nbt,54,AIR,57,SKULL:1,./NBT/Skulls/dungeon_skull_10.nbt,60,AIR,63,SKULL:1,./NBT/Skulls/dungeon_skull_11.nbt,66,AIR,69,SKULL:1,./NBT/Skulls/dungeon_skull_12.nbt,72,AIR,75,SKULL:1,./NBT/Skulls/dungeon_skull_13.nbt,78,AIR,81,SKULL:1,./NBT/Skulls/dungeon_skull_14.nbt,84,AIR,87,SKULL:1,./NBT/Skulls/dungeon_skull_15.nbt,90,AIR,93,SKULL:1,./NBT/Skulls/dungeon_skull_16.nbt,96,AIR,100)
B(6,2,-8,AIR)
B(7,2,-8,SPRUCE_FENCE)
B(-8,2,-7,AIR)
B(-7,2,-7,AIR)
B(-6,2,-7,AIR)
B(-5,2,-7,AIR)
B(-4,2,-7,AIR)
B(-3,2,-7,AIR)
B(-2,2,-7,AIR)
B(-1,2,-7,AIR)
B(0,2,-7,AIR)
B(1,2,-7,AIR)
B(2,2,-7,AIR)
B(3,2,-7,AIR)
B(4,2,-7,AIR)
B(5,2,-7,AIR)
B(6,2,-7,AIR)
B(7,2,-7,AIR)
B(-8,2,-5,SPRUCE_FENCE)
RB(-7,2,-5,SKULL:1,./NBT/Skulls/dungeon_skull_01.nbt,6,AIR,9,SKULL:1,./NBT/Skulls/dungeon_skull_02.nbt,12,AIR,15,SKULL:1,./NBT/Skulls/dungeon_skull_03.nbt,18,AIR,21,SKULL:1,./NBT/Skulls/dungeon_skull_04.nbt,24,AIR,27,SKULL:1,./NBT/Skulls/dungeon_skull_05.nbt,30,AIR,33,SKULL:1,./NBT/Skulls/dungeon_skull_06.nbt,36,AIR,39,SKULL:1,./NBT/Skulls/dungeon_skull_07.nbt,42,AIR,45,SKULL:1,./NBT/Skulls/dungeon_skull_08.nbt,48,AIR,51,SKULL:1,./NBT/Skulls/dungeon_skull_09.nbt,54,AIR,57,SKULL:1,./NBT/Skulls/dungeon_skull_10.nbt,60,AIR,63,SKULL:1,./NBT/Skulls/dungeon_skull_11.nbt,66,AIR,69,SKULL:1,./NBT/Skulls/dungeon_skull_12.nbt,72,AIR,75,SKULL:1,./NBT/Skulls/dungeon_skull_13.nbt,78,AIR,81,SKULL:1,./NBT/Skulls/dungeon_skull_14.nbt,84,AIR,87,SKULL:1,./NBT/Skulls/dungeon_skull_15.nbt,90,AIR,93,SKULL:1,./NBT/Skulls/dungeon_skull_16.nbt,96,AIR,100)
B(-6,2,-5,AIR)
B(-5,2,-5,SPRUCE_FENCE)
B(-4,2,-5,AIR)
B(-3,2,-5,AIR)
B(-2,2,-5,SPRUCE_FENCE)
B(-1,2,-5,AIR)
RB(0,2,-5,SKULL:1,./NBT/Skulls/dungeon_skull_01.nbt,6,AIR,9,SKULL:1,./NBT/Skulls/dungeon_skull_02.nbt,12,AIR,15,SKULL:1,./NBT/Skulls/dungeon_skull_03.nbt,18,AIR,21,SKULL:1,./NBT/Skulls/dungeon_skull_04.nbt,24,AIR,27,SKULL:1,./NBT/Skulls/dungeon_skull_05.nbt,30,AIR,33,SKULL:1,./NBT/Skulls/dungeon_skull_06.nbt,36,AIR,39,SKULL:1,./NBT/Skulls/dungeon_skull_07.nbt,42,AIR,45,SKULL:1,./NBT/Skulls/dungeon_skull_08.nbt,48,AIR,51,SKULL:1,./NBT/Skulls/dungeon_skull_09.nbt,54,AIR,57,SKULL:1,./NBT/Skulls/dungeon_skull_10.nbt,60,AIR,63,SKULL:1,./NBT/Skulls/dungeon_skull_11.nbt,66,AIR,69,SKULL:1,./NBT/Skulls/dungeon_skull_12.nbt,72,AIR,75,SKULL:1,./NBT/Skulls/dungeon_skull_13.nbt,78,AIR,81,SKULL:1,./NBT/Skulls/dungeon_skull_14.nbt,84,AIR,87,SKULL:1,./NBT/Skulls/dungeon_skull_15.nbt,90,AIR,93,SKULL:1,./NBT/Skulls/dungeon_skull_16.nbt,96,AIR,100)
B(1,2,-5,SPRUCE_FENCE)
B(2,2,-5,AIR)
B(3,2,-5,AIR)
B(4,2,-5,SPRUCE_FENCE)
B(5,2,-5,AIR)
B(6,2,-5,AIR)
B(7,2,-5,SPRUCE_FENCE)
B(1,2,-4,AIR)
B(2,2,-4,AIR)
B(3,2,-4,AIR)
B(4,2,-4,AIR)
B(1,2,-3,AIR)
B(2,2,-3,AIR)
B(3,2,-3,AIR)
B(4,2,-3,AIR)
B(-8,2,-2,STONE)
B(-7,2,-2,STONE)
B(-6,2,-2,STONE)
B(-5,2,-2,STONE)
B(-4,2,-2,STONE)
B(-3,2,-2,STONE)
B(-2,2,-2,STONE)
B(-1,2,-2,STONE)
B(0,2,-2,STONE)
B(1,2,-2,SPRUCE_FENCE)
B(2,2,-2,AIR)
B(3,2,-2,AIR)
B(4,2,-2,SPRUCE_FENCE)
B(5,2,-2,STONE)
B(6,2,-2,STONE)
B(7,2,-2,STONE)
B(-8,2,-1,STONE)
B(-7,2,-1,STONE)
B(-6,2,-1,STONE)
B(-5,2,-1,STONE)
B(-4,2,-1,AIR)
B(-3,2,-1,SPRUCE_FENCE)
B(-2,2,-1,AIR)
B(-1,2,-1,STONE)
B(0,2,-1,AIR)
B(1,2,-1,AIR)
B(2,2,-1,AIR)
B(3,2,-1,AIR)
B(4,2,-1,AIR)
B(5,2,-1,STONE)
B(6,2,-1,STONE)
B(7,2,-1,STONE)
B(-8,2,0,STONE)
B(-7,2,0,STONE)
B(-6,2,0,SPRUCE_FENCE)
B(-5,2,0,AIR)
B(-4,2,0,AIR)
B(-3,2,0,AIR)
B(-2,2,0,STONE_BRICK_STAIRS)
B(-1,2,0,AIR)
B(0,2,0,STONE_BRICK_STAIRS)
B(1,2,0,AIR)
B(2,2,0,STONE_BRICK_STAIRS)
B(3,2,0,AIR)
B(4,2,0,STONE)
B(5,2,0,STONE)
B(6,2,0,STONE)
B(7,2,0,STONE)
B(-8,2,1,STONE)
B(-7,2,1,STONE)
B(-6,2,1,AIR)
B(-5,2,1,STONE_BRICK_STAIRS:6)
B(-3,2,1,AIR)
B(-2,2,1,STONE_BRICK_STAIRS)
B(-1,2,1,AIR)
B(0,2,1,STONE_BRICK_STAIRS)
B(1,2,1,AIR)
B(2,2,1,STONE_BRICK_STAIRS)
B(3,2,1,AIR)
B(4,2,1,AIR)
B(5,2,1,STONE)
B(6,2,1,STONE)
B(7,2,1,STONE)
B(-8,2,2,STONE)
B(-7,2,2,STONE)
B(-6,2,2,LEVER:10)
B(-5,2,2,GRASS)
B(-4,2,2,IRON_TRAPDOOR:15)
B(-3,2,2,AIR)
B(-2,2,2,AIR)
B(-1,2,2,AIR)
B(0,2,2,AIR)
B(1,2,2,AIR)
B(2,2,2,AIR)
B(3,2,2,AIR)
B(4,2,2,AIR)
B(5,2,2,SPRUCE_FENCE)
B(6,2,2,STONE)
B(7,2,2,STONE)
B(-8,2,3,STONE)
B(-7,2,3,STONE)
B(-6,2,3,AIR)
B(-5,2,3,STONE_BRICK_STAIRS:7)
B(-3,2,3,AIR)
B(-2,2,3,STONE_BRICK_STAIRS)
B(-1,2,3,AIR)
B(0,2,3,STONE_BRICK_STAIRS)
B(1,2,3,AIR)
B(2,2,3,STONE_BRICK_STAIRS)
B(3,2,3,AIR)
B(4,2,3,AIR)
B(5,2,3,AIR)
B(6,2,3,STONE)
B(7,2,3,STONE)
B(-8,2,4,STONE)
B(-7,2,4,STONE)
B(-6,2,4,SPRUCE_FENCE)
B(-5,2,4,AIR)
B(-4,2,4,AIR)
B(-3,2,4,AIR)
B(-2,2,4,STONE_BRICK_STAIRS)
B(-1,2,4,AIR)
B(0,2,4,STONE_BRICK_STAIRS)
B(1,2,4,AIR)
B(2,2,4,STONE_BRICK_STAIRS)
B(3,2,4,AIR)
B(4,2,4,AIR)
B(5,2,4,AIR)
B(6,2,4,STONE)
B(7,2,4,STONE)
B(-8,2,5,STONE)
B(-7,2,5,STONE)
B(-6,2,5,STONE)
B(-5,2,5,STONE)
B(-4,2,5,SPRUCE_FENCE)
B(-3,2,5,AIR)
B(-2,2,5,AIR)
B(-1,2,5,STONE)
B(0,2,5,STONE)
B(1,2,5,AIR)
B(2,2,5,SPRUCE_FENCE)
B(3,2,5,STONE)
B(4,2,5,STONE)
B(5,2,5,STONE)
B(6,2,5,STONE)
B(7,2,5,STONE)
B(-8,2,6,STONE)
B(-7,2,6,STONE)
B(-6,2,6,STONE)
B(-5,2,6,STONE)
B(-4,2,6,STONE)
B(-3,2,6,STONE)
B(-2,2,6,STONE)
B(-1,2,6,STONE)
B(0,2,6,STONE)
B(1,2,6,STONE)
B(2,2,6,STONE)
B(3,2,6,STONE)
B(4,2,6,STONE)
B(5,2,6,STONE)
B(6,2,6,STONE)
B(7,2,6,STONE)
B(-8,2,7,STONE)
B(-7,2,7,STONE)
B(-6,2,7,STONE)
B(-5,2,7,STONE)
B(-4,2,7,STONE)
B(-3,2,7,STONE)
B(-2,2,7,STONE)
B(-1,2,7,STONE)
B(0,2,7,STONE)
B(1,2,7,STONE)
B(2,2,7,STONE)
B(3,2,7,STONE)
B(4,2,7,STONE)
B(5,2,7,STONE)
B(6,2,7,STONE)
B(7,2,7,STONE)
B(-8,3,-8,SPRUCE_FENCE)
B(-7,3,-8,AIR)
B(-6,3,-8,AIR)
B(-5,3,-8,SPRUCE_FENCE)
B(-4,3,-8,AIR)
B(-3,3,-8,AIR)
B(-2,3,-8,SPRUCE_FENCE)
B(-1,3,-8,AIR)
B(0,3,-8,AIR)
B(1,3,-8,SPRUCE_FENCE)
B(2,3,-8,AIR)
B(3,3,-8,AIR)
B(4,3,-8,SPRUCE_FENCE)
B(5,3,-8,AIR)
B(6,3,-8,AIR)
B(7,3,-8,SPRUCE_FENCE)
B(-8,3,-7,AIR)
B(-7,3,-7,AIR)
B(-6,3,-7,AIR)
B(-5,3,-7,AIR)
B(-4,3,-7,AIR)
B(-3,3,-7,AIR)
B(-2,3,-7,AIR)
B(-1,3,-7,AIR)
B(0,3,-7,AIR)
B(1,3,-7,AIR)
B(2,3,-7,AIR)
B(3,3,-7,AIR)
B(4,3,-7,AIR)
B(5,3,-7,AIR)
B(6,3,-7,AIR)
B(7,3,-7,AIR)
B(-8,3,-6,AIR)
B(-7,3,-6,AIR)
B(-6,3,-6,AIR)
B(-5,3,-6,AIR)
B(-4,3,-6,AIR)
B(-3,3,-6,AIR)
B(-2,3,-6,AIR)
B(-1,3,-6,AIR)
B(0,3,-6,AIR)
B(1,3,-6,AIR)
B(2,3,-6,AIR)
B(3,3,-6,AIR)
B(4,3,-6,AIR)
B(5,3,-6,AIR)
B(6,3,-6,AIR)
B(7,3,-6,AIR)
B(-8,3,-5,SPRUCE_FENCE)
B(-7,3,-5,AIR)
B(-6,3,-5,AIR)
B(-5,3,-5,SPRUCE_FENCE)
B(-4,3,-5,AIR)
B(-3,3,-5,AIR)
B(-2,3,-5,SPRUCE_FENCE)
B(-1,3,-5,AIR)
B(0,3,-5,AIR)
B(1,3,-5,SPRUCE_FENCE)
B(2,3,-5,AIR)
B(3,3,-5,AIR)
B(4,3,-5,SPRUCE_FENCE)
B(5,3,-5,AIR)
B(6,3,-5,AIR)
B(7,3,-5,SPRUCE_FENCE)
B(1,3,-4,AIR)
B(2,3,-4,AIR)
B(3,3,-4,AIR)
B(4,3,-4,AIR)
B(1,3,-3,AIR)
B(2,3,-3,AIR)
B(3,3,-3,AIR)
B(4,3,-3,AIR)
B(-8,3,-2,STONE)
B(-7,3,-2,STONE)
B(-6,3,-2,STONE)
B(-5,3,-2,STONE)
B(-4,3,-2,STONE)
B(-3,3,-2,STONE)
B(-2,3,-2,STONE)
B(-1,3,-2,STONE)
B(0,3,-2,STONE)
B(1,3,-2,SPRUCE_FENCE)
B(2,3,-2,AIR)
B(3,3,-2,AIR)
B(4,3,-2,SPRUCE_FENCE)
B(5,3,-2,STONE)
B(6,3,-2,STONE)
B(7,3,-2,STONE)
B(-8,3,-1,STONE)
B(-7,3,-1,STONE)
B(-6,3,-1,STONE)
B(-5,3,-1,STONE)
B(-4,3,-1,AIR)
B(-3,3,-1,AIR)
B(-2,3,-1,AIR)
B(-1,3,-1,STONE)
B(0,3,-1,AIR)
B(1,3,-1,AIR)
B(2,3,-1,AIR)
B(3,3,-1,AIR)
B(4,3,-1,AIR)
B(5,3,-1,AIR)
B(6,3,-1,STONE)
B(7,3,-1,STONE)
B(-8,3,0,STONE)
B(-7,3,0,STONE)
B(-6,3,0,AIR)
B(-5,3,0,AIR)
B(-4,3,0,AIR)
B(-3,3,0,AIR)
B(-2,3,0,AIR)
B(-1,3,0,AIR)
B(0,3,0,AIR)
B(1,3,0,AIR)
B(2,3,0,AIR)
B(3,3,0,AIR)
B(4,3,0,AIR)
B(5,3,0,STONE)
B(6,3,0,STONE)
B(7,3,0,STONE)
B(-8,3,1,STONE)
B(-7,3,1,STONE)
B(-6,3,1,AIR)
B(-5,3,1,AIR)
B(-4,3,1,AIR)
B(-3,3,1,AIR)
B(-2,3,1,AIR)
B(-1,3,1,AIR)
B(0,3,1,AIR)
B(1,3,1,AIR)
B(2,3,1,AIR)
B(3,3,1,AIR)
B(4,3,1,AIR)
B(5,3,1,AIR)
B(6,3,1,STONE)
B(7,3,1,STONE)
B(-8,3,2,STONE)
B(-7,3,2,STONE)
B(-6,3,2,AIR)
B(-5,3,2,DOUBLE_PLANT)
B(-4,3,2,AIR)
B(-3,3,2,AIR)
B(-2,3,2,AIR)
B(-1,3,2,AIR)
B(0,3,2,AIR)
B(1,3,2,AIR)
B(2,3,2,AIR)
B(3,3,2,AIR)
B(4,3,2,AIR)
B(5,3,2,AIR)
B(6,3,2,AIR)
B(7,3,2,STONE)
B(-8,3,3,STONE)
B(-7,3,3,AIR)
B(-6,3,3,AIR)
B(-5,3,3,AIR)
B(-4,3,3,AIR)
B(-3,3,3,AIR)
B(-2,3,3,AIR)
B(-1,3,3,AIR)
B(0,3,3,AIR)
B(1,3,3,AIR)
B(2,3,3,AIR)
B(3,3,3,AIR)
B(4,3,3,AIR)
B(5,3,3,AIR)
B(6,3,3,AIR)
B(7,3,3,STONE)
B(-8,3,4,STONE)
B(-7,3,4,AIR)
B(-6,3,4,AIR)
B(-5,3,4,AIR)
B(-4,3,4,AIR)
B(-3,3,4,AIR)
B(-2,3,4,AIR)
B(-1,3,4,AIR)
B(0,3,4,AIR)
B(1,3,4,AIR)
B(2,3,4,AIR)
B(3,3,4,AIR)
B(4,3,4,AIR)
B(5,3,4,AIR)
B(6,3,4,STONE)
B(7,3,4,STONE)
B(-8,3,5,STONE)
B(-7,3,5,STONE)
B(-6,3,5,STONE)
B(-5,3,5,AIR)
B(-4,3,5,AIR)
B(-3,3,5,AIR)
B(-2,3,5,AIR)
B(-1,3,5,AIR)
B(0,3,5,AIR)
B(1,3,5,AIR)
B(2,3,5,AIR)
B(3,3,5,AIR)
B(4,3,5,STONE)
B(5,3,5,STONE)
B(6,3,5,STONE)
B(7,3,5,STONE)
B(-8,3,6,STONE)
B(-7,3,6,STONE)
B(-6,3,6,STONE)
B(-5,3,6,STONE)
B(-4,3,6,AIR)
B(-3,3,6,STONE)
B(-2,3,6,STONE)
B(-1,3,6,STONE)
B(0,3,6,STONE)
B(1,3,6,AIR)
B(2,3,6,AIR)
B(3,3,6,STONE)
B(4,3,6,STONE)
B(5,3,6,STONE)
B(6,3,6,STONE)
B(7,3,6,STONE)
B(-8,3,7,STONE)
B(-7,3,7,STONE)
B(-6,3,7,STONE)
B(-5,3,7,STONE)
B(-4,3,7,STONE)
B(-3,3,7,STONE)
B(-2,3,7,STONE)
B(-1,3,7,STONE)
B(0,3,7,STONE)
B(1,3,7,STONE)
B(2,3,7,STONE)
B(3,3,7,STONE)
B(4,3,7,STONE)
B(5,3,7,STONE)
B(6,3,7,STONE)
B(7,3,7,STONE)
B(-8,4,-8,PLANKS:1)
B(-7,4,-8,AIR)
B(-6,4,-8,AIR)
B(-5,4,-8,PLANKS:1)
B(-4,4,-8,AIR)
B(-3,4,-8,AIR)
B(-2,4,-8,PLANKS:1)
B(-1,4,-8,AIR)
B(0,4,-8,AIR)
B(1,4,-8,PLANKS:1)
B(2,4,-8,AIR)
B(3,4,-8,AIR)
B(4,4,-8,PLANKS:1)
B(5,4,-8,AIR)
B(6,4,-8,AIR)
B(7,4,-8,PLANKS:1)
B(-8,4,-7,PLANKS:1)
B(-7,4,-7,AIR)
B(-6,4,-7,AIR)
B(-5,4,-7,PLANKS:1)
B(-4,4,-7,AIR)
B(-3,4,-7,AIR)
B(-2,4,-7,PLANKS:1)
B(-1,4,-7,AIR)
RB(0,4,-7,TORCH:2,42,AIR,50,TORCH:2,50)
B(1,4,-7,PLANKS:1)
B(2,4,-7,AIR)
B(3,4,-7,AIR)
B(4,4,-7,PLANKS:1)
B(5,4,-7,AIR)
B(6,4,-7,AIR)
B(7,4,-7,PLANKS:1)
B(-8,4,-6,PLANKS:1)
B(-7,4,-6,AIR)
B(-6,4,-6,AIR)
B(-5,4,-6,PLANKS:1)
B(-4,4,-6,AIR)
B(-3,4,-6,AIR)
B(-2,4,-6,PLANKS:1)
B(-1,4,-6,AIR)
B(0,4,-6,AIR)
B(1,4,-6,PLANKS:1)
B(2,4,-6,AIR)
B(3,4,-6,AIR)
B(4,4,-6,PLANKS:1)
B(5,4,-6,AIR)
B(6,4,-6,AIR)
B(7,4,-6,PLANKS:1)
B(-8,4,-5,PLANKS:1)
B(-7,4,-5,AIR)
B(-6,4,-5,AIR)
B(-5,4,-5,PLANKS:1)
B(-4,4,-5,AIR)
B(-3,4,-5,AIR)
B(-2,4,-5,PLANKS:1)
B(-1,4,-5,AIR)
B(0,4,-5,AIR)
B(1,4,-5,PLANKS:1)
B(2,4,-5,AIR)
B(3,4,-5,AIR)
B(4,4,-5,PLANKS:1)
B(5,4,-5,AIR)
B(6,4,-5,AIR)
B(7,4,-5,PLANKS:1)
B(1,4,-4,AIR)
B(2,4,-4,AIR)
B(3,4,-4,AIR)
B(4,4,-4,AIR)
B(1,4,-3,AIR)
B(2,4,-3,AIR)
B(3,4,-3,AIR)
B(4,4,-3,AIR)
B(-8,4,-2,STONE)
B(-7,4,-2,STONE)
B(-6,4,-2,STONE)
B(-5,4,-2,STONE)
B(-4,4,-2,STONE)
B(-3,4,-2,STONE)
B(-2,4,-2,STONE)
B(-1,4,-2,STONE)
B(0,4,-2,STONE)
B(1,4,-2,PLANKS:1)
B(2,4,-2,PLANKS:1)
B(3,4,-2,PLANKS:1)
B(4,4,-2,PLANKS:1)
B(5,4,-2,STONE)
B(6,4,-2,STONE)
B(7,4,-2,STONE)
B(-8,4,-1,STONE)
B(-7,4,-1,STONE)
B(-6,4,-1,STONE)
B(-5,4,-1,AIR)
B(-3,4,-1,AIR)
B(-1,4,-1,AIR)
B(1,4,-1,AIR)
B(2,4,-1,AIR)
B(3,4,-1,AIR)
B(4,4,-1,AIR)
B(5,4,-1,AIR)
B(6,4,-1,STONE)
B(7,4,-1,STONE)
B(-8,4,0,STONE)
B(-7,4,0,STONE)
B(-5,4,0,AIR)
B(-4,4,0,AIR)
B(-3,4,0,AIR)
B(-2,4,0,AIR)
B(-1,4,0,AIR)
B(0,4,0,AIR)
B(1,4,0,AIR)
B(2,4,0,AIR)
B(3,4,0,AIR)
B(4,4,0,AIR)
B(5,4,0,AIR)
B(6,4,0,STONE)
B(7,4,0,STONE)
B(-8,4,1,STONE)
B(-7,4,1,STONE)
B(-6,4,1,AIR)
B(-5,4,1,AIR)
B(-4,4,1,AIR)
B(-3,4,1,AIR)
B(-2,4,1,AIR)
B(-1,4,1,AIR)
B(0,4,1,AIR)
B(1,4,1,AIR)
B(2,4,1,AIR)
B(3,4,1,AIR)
B(4,4,1,AIR)
B(6,4,1,STONE)
B(7,4,1,STONE)
B(-8,4,2,STONE)
B(-7,4,2,STONE)
B(-6,4,2,AIR)
B(-5,4,2,DOUBLE_PLANT:10)
B(-4,4,2,AIR)
B(-3,4,2,AIR)
B(-2,4,2,AIR)
B(-1,4,2,AIR)
B(0,4,2,AIR)
B(1,4,2,AIR)
B(2,4,2,AIR)
B(3,4,2,AIR)
B(4,4,2,AIR)
B(5,4,2,AIR)
B(6,4,2,AIR)
B(7,4,2,STONE)
B(-8,4,3,STONE)
B(-7,4,3,AIR)
B(-6,4,3,AIR)
B(-5,4,3,AIR)
B(-4,4,3,AIR)
B(-3,4,3,AIR)
B(-2,4,3,AIR)
B(-1,4,3,AIR)
B(0,4,3,AIR)
B(1,4,3,AIR)
B(2,4,3,AIR)
B(3,4,3,AIR)
B(4,4,3,AIR)
B(5,4,3,AIR)
B(6,4,3,AIR)
B(7,4,3,STONE)
B(-8,4,4,STONE)
B(-6,4,4,AIR)
B(-5,4,4,AIR)
B(-4,4,4,AIR)
B(-3,4,4,AIR)
B(-2,4,4,AIR)
B(-1,4,4,AIR)
B(0,4,4,AIR)
B(1,4,4,AIR)
B(2,4,4,AIR)
B(3,4,4,AIR)
B(4,4,4,AIR)
B(6,4,4,STONE)
B(7,4,4,STONE)
B(-8,4,5,STONE)
B(-7,4,5,STONE)
B(-6,4,5,STONE)
B(-5,4,5,AIR)
B(-4,4,5,AIR)
B(-3,4,5,AIR)
B(-1,4,5,AIR)
B(1,4,5,AIR)
B(2,4,5,AIR)
B(3,4,5,AIR)
B(4,4,5,AIR)
B(5,4,5,STONE)
B(6,4,5,STONE)
B(7,4,5,STONE)
B(-8,4,6,STONE)
B(-7,4,6,STONE)
B(-6,4,6,STONE)
B(-5,4,6,STONE)
B(-4,4,6,AIR)
B(-3,4,6,AIR)
B(-2,4,6,STONE)
B(-1,4,6,STONE)
B(0,4,6,STONE)
B(1,4,6,AIR)
B(2,4,6,AIR)
B(3,4,6,STONE)
B(4,4,6,STONE)
B(5,4,6,STONE)
B(6,4,6,STONE)
B(7,4,6,STONE)
B(-8,4,7,STONE)
B(-7,4,7,STONE)
B(-6,4,7,STONE)
B(-5,4,7,STONE)
B(-4,4,7,STONE)
B(-3,4,7,STONE)
B(-2,4,7,STONE)
B(-1,4,7,STONE)
B(0,4,7,STONE)
B(1,4,7,STONE)
B(2,4,7,STONE)
B(3,4,7,STONE)
B(4,4,7,STONE)
B(5,4,7,STONE)
B(6,4,7,STONE)
B(7,4,7,STONE)
B(-8,5,-2,STONE)
B(-7,5,-2,STONE)
B(-6,5,-2,STONE)
B(-5,5,-2,STONE)
B(-4,5,-2,STONE)
B(-3,5,-2,STONE)
B(-2,5,-2,STONE)
B(-1,5,-2,STONE)
B(0,5,-2,STONE)
B(1,5,-2,STONE)
B(2,5,-2,STONE)
B(3,5,-2,STONE)
B(4,5,-2,STONE)
B(5,5,-2,STONE)
B(6,5,-2,STONE)
B(7,5,-2,STONE)
B(-8,5,-1,STONE)
B(-7,5,-1,STONE)
B(-6,5,-1,STONE)
B(-5,5,-1,AIR)
B(-4,5,-1,AIR)
B(-3,5,-1,AIR)
B(-2,5,-1,STONE)
B(-1,5,-1,AIR)
B(0,5,-1,AIR)
B(1,5,-1,AIR)
B(2,5,-1,AIR)
B(3,5,-1,AIR)
B(4,5,-1,STONE)
B(5,5,-1,STONE)
B(6,5,-1,STONE)
B(7,5,-1,STONE)
B(-8,5,0,STONE)
B(-7,5,0,STONE)
B(-6,5,0,AIR)
B(-5,5,0,AIR)
B(-4,5,0,AIR)
B(-3,5,0,AIR)
B(-2,5,0,AIR)
B(-1,5,0,AIR)
B(0,5,0,AIR)
B(1,5,0,AIR)
B(2,5,0,AIR)
B(3,5,0,AIR)
B(4,5,0,AIR)
B(5,5,0,STONE)
B(6,5,0,STONE)
B(7,5,0,STONE)
B(-8,5,1,STONE)
B(-7,5,1,STONE)
B(-6,5,1,AIR)
B(-5,5,1,AIR)
B(-4,5,1,AIR)
B(-3,5,1,AIR)
B(-2,5,1,AIR)
B(-1,5,1,AIR)
B(0,5,1,AIR)
B(1,5,1,AIR)
B(2,5,1,AIR)
B(3,5,1,AIR)
B(4,5,1,AIR)
B(5,5,1,AIR)
B(6,5,1,STONE)
B(7,5,1,STONE)
B(-8,5,2,STONE)
B(-7,5,2,STONE)
B(-6,5,2,AIR)
B(-5,5,2,AIR)
B(-4,5,2,AIR)
B(-3,5,2,AIR)
B(-2,5,2,AIR)
B(-1,5,2,AIR)
B(0,5,2,AIR)
B(1,5,2,AIR)
B(2,5,2,AIR)
B(3,5,2,AIR)
B(4,5,2,AIR)
B(5,5,2,AIR)
B(6,5,2,AIR)
B(7,5,2,STONE)
B(-8,5,3,STONE)
B(-7,5,3,STONE)
B(-6,5,3,AIR)
B(-5,5,3,AIR)
B(-4,5,3,AIR)
B(-3,5,3,AIR)
B(-2,5,3,AIR)
B(-1,5,3,AIR)
B(0,5,3,AIR)
B(1,5,3,AIR)
B(2,5,3,AIR)
B(3,5,3,AIR)
B(4,5,3,AIR)
B(5,5,3,AIR)
B(6,5,3,AIR)
B(7,5,3,STONE)
B(-8,5,4,STONE)
B(-7,5,4,STONE)
B(-6,5,4,AIR)
B(-5,5,4,AIR)
B(-4,5,4,AIR)
B(-3,5,4,AIR)
B(-2,5,4,AIR)
B(-1,5,4,AIR)
B(0,5,4,AIR)
B(1,5,4,AIR)
B(2,5,4,AIR)
B(3,5,4,AIR)
B(4,5,4,AIR)
B(5,5,4,STONE)
B(6,5,4,STONE)
B(7,5,4,STONE)
B(-8,5,5,STONE)
B(-7,5,5,STONE)
B(-6,5,5,STONE)
B(-5,5,5,STONE)
B(-4,5,5,AIR)
B(-3,5,5,AIR)
B(-2,5,5,AIR)
B(-1,5,5,AIR)
B(0,5,5,AIR)
B(1,5,5,AIR)
B(2,5,5,AIR)
B(3,5,5,STONE)
B(4,5,5,STONE)
B(5,5,5,STONE)
B(6,5,5,STONE)
B(7,5,5,STONE)
B(-8,5,6,STONE)
B(-7,5,6,STONE)
B(-6,5,6,STONE)
B(-5,5,6,STONE)
B(-4,5,6,AIR)
B(-3,5,6,AIR)
B(-2,5,6,AIR)
B(-1,5,6,STONE)
B(0,5,6,STONE)
B(1,5,6,AIR)
B(2,5,6,STONE)
B(3,5,6,STONE)
B(4,5,6,STONE)
B(5,5,6,STONE)
B(6,5,6,STONE)
B(7,5,6,STONE)
B(-8,5,7,STONE)
B(-7,5,7,STONE)
B(-6,5,7,STONE)
B(-5,5,7,STONE)
B(-4,5,7,STONE)
B(-3,5,7,STONE)
B(-2,5,7,STONE)
B(-1,5,7,STONE)
B(0,5,7,STONE)
B(1,5,7,STONE)
B(2,5,7,STONE)
B(3,5,7,STONE)
B(4,5,7,STONE)
B(5,5,7,STONE)
B(6,5,7,STONE)
B(7,5,7,STONE)
B(-8,6,-2,STONE)
B(-7,6,-2,STONE)
B(-6,6,-2,STONE)
B(-5,6,-2,STONE)
B(-4,6,-2,STONE)
B(-3,6,-2,STONE)
B(-2,6,-2,STONE)
B(-1,6,-2,STONE)
B(0,6,-2,STONE)
B(1,6,-2,STONE)
B(2,6,-2,STONE)
B(3,6,-2,STONE)
B(4,6,-2,STONE)
B(5,6,-2,STONE)
B(6,6,-2,STONE)
B(7,6,-2,STONE)
B(-8,6,-1,STONE)
B(-7,6,-1,STONE)
B(-6,6,-1,STONE)
B(-5,6,-1,AIR)
B(-4,6,-1,AIR)
B(-3,6,-1,STONE)
B(-2,6,-1,STONE)
B(-1,6,-1,STONE)
B(0,6,-1,AIR)
B(1,6,-1,AIR)
B(2,6,-1,STONE)
B(3,6,-1,STONE)
B(4,6,-1,STONE)
B(5,6,-1,STONE)
B(6,6,-1,STONE)
B(7,6,-1,STONE)
B(-8,6,0,STONE)
B(-7,6,0,STONE)
B(-6,6,0,STONE)
B(-5,6,0,AIR)
B(-4,6,0,AIR)
B(-3,6,0,AIR)
B(-2,6,0,AIR)
B(-1,6,0,AIR)
B(0,6,0,AIR)
B(1,6,0,AIR)
B(2,6,0,AIR)
B(3,6,0,AIR)
B(4,6,0,AIR)
B(5,6,0,STONE)
B(6,6,0,STONE)
B(7,6,0,STONE)
B(-8,6,1,STONE)
B(-7,6,1,STONE)
B(-6,6,1,STONE)
B(-5,6,1,AIR)
B(-4,6,1,AIR)
B(-3,6,1,AIR)
B(-2,6,1,AIR)
B(-1,6,1,AIR)
B(0,6,1,AIR)
B(1,6,1,AIR)
B(2,6,1,AIR)
B(3,6,1,AIR)
B(4,6,1,AIR)
B(5,6,1,AIR)
B(6,6,1,STONE)
B(7,6,1,STONE)
B(-8,6,2,STONE)
B(-7,6,2,STONE)
B(-6,6,2,STONE)
B(-5,6,2,AIR)
B(-4,6,2,AIR)
B(-3,6,2,AIR)
B(-2,6,2,AIR)
B(-1,6,2,AIR)
B(0,6,2,AIR)
B(1,6,2,AIR)
B(2,6,2,AIR)
B(3,6,2,AIR)
B(4,6,2,AIR)
B(5,6,2,AIR)
B(6,6,2,STONE)
B(7,6,2,STONE)
B(-8,6,3,STONE)
B(-7,6,3,STONE)
B(-6,6,3,STONE)
B(-5,6,3,STONE)
B(-4,6,3,AIR)
B(-3,6,3,AIR)
B(-2,6,3,AIR)
B(-1,6,3,AIR)
B(0,6,3,AIR)
B(1,6,3,AIR)
B(2,6,3,AIR)
B(3,6,3,AIR)
B(4,6,3,AIR)
B(5,6,3,AIR)
B(6,6,3,AIR)
B(7,6,3,STONE)
B(-8,6,4,STONE)
B(-7,6,4,STONE)
B(-6,6,4,STONE)
B(-5,6,4,STONE)
B(-4,6,4,AIR)
B(-3,6,4,AIR)
B(-2,6,4,AIR)
B(-1,6,4,AIR)
B(0,6,4,AIR)
B(1,6,4,AIR)
B(2,6,4,AIR)
B(3,6,4,AIR)
B(4,6,4,STONE)
B(5,6,4,STONE)
B(6,6,4,STONE)
B(7,6,4,STONE)
B(-8,6,5,STONE)
B(-7,6,5,STONE)
B(-6,6,5,STONE)
B(-5,6,5,STONE)
B(-4,6,5,AIR)
B(-3,6,5,AIR)
B(-2,6,5,AIR)
B(-1,6,5,AIR)
B(0,6,5,AIR)
B(1,6,5,AIR)
B(2,6,5,STONE)
B(3,6,5,STONE)
B(4,6,5,STONE)
B(5,6,5,STONE)
B(6,6,5,STONE)
B(7,6,5,STONE)
B(-8,6,6,STONE)
B(-7,6,6,STONE)
B(-6,6,6,STONE)
B(-5,6,6,STONE)
B(-4,6,6,STONE)
B(-3,6,6,STONE)
B(-2,6,6,AIR)
B(-1,6,6,STONE)
B(0,6,6,STONE)
B(1,6,6,AIR)
B(2,6,6,STONE)
B(3,6,6,STONE)
B(4,6,6,STONE)
B(5,6,6,STONE)
B(6,6,6,STONE)
B(7,6,6,STONE)
B(-8,6,7,STONE)
B(-7,6,7,STONE)
B(-6,6,7,STONE)
B(-5,6,7,STONE)
B(-4,6,7,STONE)
B(-3,6,7,STONE)
B(-2,6,7,STONE)
B(-1,6,7,STONE)
B(0,6,7,STONE)
B(1,6,7,STONE)
B(2,6,7,STONE)
B(3,6,7,STONE)
B(4,6,7,STONE)
B(5,6,7,STONE)
B(6,6,7,STONE)
B(7,6,7,STONE)
B(-8,7,-2,STONE)
B(-7,7,-2,STONE)
B(-6,7,-2,STONE)
B(-5,7,-2,STONE)
B(-4,7,-2,STONE)
B(-3,7,-2,STONE)
B(-2,7,-2,STONE)
B(-1,7,-2,STONE)
B(0,7,-2,STONE)
B(1,7,-2,STONE)
B(2,7,-2,STONE)
B(3,7,-2,STONE)
B(4,7,-2,STONE)
B(5,7,-2,STONE)
B(6,7,-2,STONE)
B(7,7,-2,STONE)
B(-8,7,-1,STONE)
B(-7,7,-1,STONE)
B(-6,7,-1,STONE)
B(-5,7,-1,STONE)
B(-4,7,-1,STONE)
B(-3,7,-1,STONE)
B(-2,7,-1,STONE)
B(-1,7,-1,STONE)
B(0,7,-1,STONE)
B(1,7,-1,STONE)
B(2,7,-1,STONE)
B(3,7,-1,STONE)
B(4,7,-1,STONE)
B(5,7,-1,STONE)
B(6,7,-1,STONE)
B(7,7,-1,STONE)
B(-8,7,0,STONE)
B(-7,7,0,STONE)
B(-6,7,0,STONE)
B(-5,7,0,STONE)
B(-4,7,0,STONE)
B(-3,7,0,STONE)
B(-2,7,0,STONE)
B(-1,7,0,STONE)
B(0,7,0,AIR)
B(1,7,0,AIR)
B(2,7,0,STONE)
B(3,7,0,STONE)
B(4,7,0,STONE)
B(5,7,0,STONE)
B(6,7,0,STONE)
B(7,7,0,STONE)
B(-8,7,1,STONE)
B(-7,7,1,STONE)
B(-6,7,1,STONE)
B(-5,7,1,STONE)
B(-4,7,1,STONE)
B(-3,7,1,AIR)
B(-2,7,1,AIR)
B(-1,7,1,AIR)
B(0,7,1,AIR)
B(1,7,1,AIR)
B(2,7,1,AIR)
B(3,7,1,AIR)
B(4,7,1,STONE)
B(5,7,1,STONE)
B(6,7,1,STONE)
B(7,7,1,STONE)
B(-8,7,2,STONE)
B(-7,7,2,STONE)
B(-6,7,2,STONE)
B(-5,7,2,AIR)
B(-4,7,2,STONE)
B(-3,7,2,AIR)
B(-2,7,2,AIR)
B(-1,7,2,AIR)
B(0,7,2,AIR)
B(1,7,2,AIR)
B(2,7,2,AIR)
B(3,7,2,AIR)
B(4,7,2,STONE)
B(5,7,2,STONE)
B(6,7,2,STONE)
B(7,7,2,STONE)
B(-8,7,3,STONE)
B(-7,7,3,STONE)
B(-6,7,3,STONE)
B(-5,7,3,STONE)
B(-4,7,3,STONE)
B(-3,7,3,AIR)
B(-2,7,3,AIR)
B(-1,7,3,AIR)
B(0,7,3,AIR)
B(1,7,3,AIR)
B(2,7,3,AIR)
B(3,7,3,STONE)
B(4,7,3,STONE)
B(5,7,3,STONE)
B(6,7,3,STONE)
B(7,7,3,STONE)
B(-8,7,4,STONE)
B(-7,7,4,STONE)
B(-6,7,4,STONE)
B(-5,7,4,STONE)
B(-4,7,4,STONE)
B(-3,7,4,STONE)
B(-2,7,4,AIR)
B(-1,7,4,AIR)
B(0,7,4,AIR)
B(1,7,4,STONE)
B(2,7,4,STONE)
B(3,7,4,STONE)
B(4,7,4,STONE)
B(5,7,4,STONE)
B(6,7,4,STONE)
B(7,7,4,STONE)
B(-8,7,5,STONE)
B(-7,7,5,STONE)
B(-6,7,5,STONE)
B(-5,7,5,STONE)
B(-4,7,5,STONE)
B(-3,7,5,STONE)
B(-2,7,5,STONE)
B(-1,7,5,STONE)
B(0,7,5,STONE)
B(1,7,5,STONE)
B(2,7,5,STONE)
B(3,7,5,STONE)
B(4,7,5,STONE)
B(5,7,5,STONE)
B(6,7,5,STONE)
B(7,7,5,STONE)
B(-8,7,6,STONE)
B(-7,7,6,STONE)
B(-6,7,6,STONE)
B(-5,7,6,STONE)
B(-4,7,6,STONE)
B(-3,7,6,STONE)
B(-2,7,6,STONE)
B(-1,7,6,STONE)
B(0,7,6,STONE)
B(1,7,6,STONE)
B(2,7,6,STONE)
B(3,7,6,STONE)
B(4,7,6,STONE)
B(5,7,6,STONE)
B(6,7,6,STONE)
B(7,7,6,STONE)
B(-8,7,7,STONE)
B(-7,7,7,STONE)
B(-6,7,7,STONE)
B(-5,7,7,STONE)
B(-4,7,7,STONE)
B(-3,7,7,STONE)
B(-2,7,7,STONE)
B(-1,7,7,STONE)
B(0,7,7,STONE)
B(1,7,7,STONE)
B(2,7,7,STONE)
B(3,7,7,STONE)
B(4,7,7,STONE)
B(5,7,7,STONE)
B(6,7,7,STONE)
B(7,7,7,STONE)
B(-8,8,-2,STONE)
B(-7,8,-2,STONE)
B(-6,8,-2,STONE)
B(-5,8,-2,STONE)
B(-4,8,-2,STONE)
B(-3,8,-2,STONE)
B(-2,8,-2,STONE)
B(-1,8,-2,STONE)
B(0,8,-2,STONE)
B(1,8,-2,STONE)
B(2,8,-2,STONE)
B(3,8,-2,STONE)
B(4,8,-2,STONE)
B(5,8,-2,STONE)
B(6,8,-2,STONE)
B(7,8,-2,STONE)
B(-8,8,-1,STONE)
B(-7,8,-1,STONE)
B(-6,8,-1,STONE)
B(-5,8,-1,STONE)
B(-4,8,-1,STONE)
B(-3,8,-1,STONE)
B(-2,8,-1,STONE)
B(-1,8,-1,STONE)
B(0,8,-1,STONE)
B(1,8,-1,STONE)
B(2,8,-1,STONE)
B(3,8,-1,STONE)
B(4,8,-1,STONE)
B(5,8,-1,STONE)
B(6,8,-1,STONE)
B(7,8,-1,STONE)
B(-8,8,0,STONE)
B(-7,8,0,STONE)
B(-6,8,0,STONE)
B(-5,8,0,STONE)
B(-4,8,0,STONE)
B(-3,8,0,STONE)
B(-2,8,0,STONE)
B(-1,8,0,STONE)
B(0,8,0,STONE)
B(1,8,0,STONE)
B(2,8,0,STONE)
B(3,8,0,STONE)
B(4,8,0,STONE)
B(5,8,0,STONE)
B(6,8,0,STONE)
B(7,8,0,STONE)
B(-8,8,1,STONE)
B(-7,8,1,STONE)
B(-6,8,1,STONE)
B(-5,8,1,STONE)
B(-4,8,1,STONE)
B(-3,8,1,STONE)
B(-2,8,1,STONE)
B(-1,8,1,STONE)
B(0,8,1,STONE)
B(1,8,1,STONE)
B(2,8,1,STONE)
B(3,8,1,STONE)
B(4,8,1,STONE)
B(5,8,1,STONE)
B(6,8,1,STONE)
B(7,8,1,STONE)
B(-8,8,2,STONE)
B(-7,8,2,STONE)
B(-6,8,2,STONE)
B(-5,8,2,LIT_REDSTONE_LAMP)
B(-4,8,2,LEVER:14)
B(-3,8,2,STONE)
B(-2,8,2,STONE)
B(-1,8,2,STONE)
B(0,8,2,STONE)
B(1,8,2,STONE)
B(2,8,2,STONE)
B(3,8,2,STONE)
B(4,8,2,STONE)
B(5,8,2,STONE)
B(6,8,2,STONE)
B(7,8,2,STONE)
B(-8,8,3,STONE)
B(-7,8,3,STONE)
B(-6,8,3,STONE)
B(-5,8,3,STONE)
B(-4,8,3,STONE)
B(-3,8,3,STONE)
B(-2,8,3,STONE)
B(-1,8,3,STONE)
B(0,8,3,STONE)
B(1,8,3,STONE)
B(2,8,3,STONE)
B(3,8,3,STONE)
B(4,8,3,STONE)
B(5,8,3,STONE)
B(6,8,3,STONE)
B(7,8,3,STONE)
B(-8,8,4,STONE)
B(-7,8,4,STONE)
B(-6,8,4,STONE)
B(-5,8,4,STONE)
B(-4,8,4,STONE)
B(-3,8,4,STONE)
B(-2,8,4,STONE)
B(-1,8,4,STONE)
B(0,8,4,STONE)
B(1,8,4,STONE)
B(2,8,4,STONE)
B(3,8,4,STONE)
B(4,8,4,STONE)
B(5,8,4,STONE)
B(6,8,4,STONE)
B(7,8,4,STONE)
B(-8,8,5,STONE)
B(-7,8,5,STONE)
B(-6,8,5,STONE)
B(-5,8,5,STONE)
B(-4,8,5,STONE)
B(-3,8,5,STONE)
B(-2,8,5,STONE)
B(-1,8,5,STONE)
B(0,8,5,STONE)
B(1,8,5,STONE)
B(2,8,5,STONE)
B(3,8,5,STONE)
B(4,8,5,STONE)
B(5,8,5,STONE)
B(6,8,5,STONE)
B(7,8,5,STONE)
B(-8,8,6,STONE)
B(-7,8,6,STONE)
B(-6,8,6,STONE)
B(-5,8,6,STONE)
B(-4,8,6,STONE)
B(-3,8,6,STONE)
B(-2,8,6,STONE)
B(-1,8,6,STONE)
B(0,8,6,STONE)
B(1,8,6,STONE)
B(2,8,6,STONE)
B(3,8,6,STONE)
B(4,8,6,STONE)
B(5,8,6,STONE)
B(6,8,6,STONE)
B(7,8,6,STONE)
B(-8,8,7,STONE)
B(-7,8,7,STONE)
B(-6,8,7,STONE)
B(-5,8,7,STONE)
B(-4,8,7,STONE)
B(-3,8,7,STONE)
B(-2,8,7,STONE)
B(-1,8,7,STONE)
B(0,8,7,STONE)
B(1,8,7,STONE)
B(2,8,7,STONE)
B(3,8,7,STONE)
B(4,8,7,STONE)
B(5,8,7,STONE)
B(6,8,7,STONE)
B(7,8,7,STONE)

B(-8,2,-6,AIR)
B(-7,2,-6,AIR)
B(-6,2,-6,AIR)
B(-5,2,-6,AIR)
B(-4,2,-6,AIR)
B(-3,2,-6,AIR)
B(-2,2,-6,AIR)
B(-1,2,-6,AIR)
B(0,2,-6,AIR)
B(1,2,-6,AIR)
B(2,2,-6,AIR)
B(3,2,-6,AIR)
B(4,2,-6,AIR)
B(5,2,-6,AIR)
B(6,2,-6,AIR)
B(7,2,-6,AIR)

B(-8,2,-7,RAIL:1)
B(-7,2,-7,RAIL:1)
B(-6,2,-7,RAIL:1)
B(-5,2,-7,RAIL:1)
B(-4,2,-7,RAIL:1)
B(-3,2,-7,RAIL:1)
B(-2,2,-7,RAIL:1)
B(-1,2,-7,RAIL:1)
B(0,2,-7,RAIL:1)
B(1,2,-7,RAIL:1)
B(2,2,-7,RAIL:1)
B(3,2,-7,RAIL:1)
B(4,2,-7,RAIL:1)
B(5,2,-7,RAIL:1)
B(6,2,-7,RAIL:1)
B(7,2,-7,RAIL:1)




B(-4,4,-1,WALL_BANNER:3,./NBT/Banners/ChapelBanner.nbt)
B(-2,4,-1,WALL_BANNER:3,./NBT/Banners/ChapelBanner.nbt)
B(0,4,-1,WALL_BANNER:3,./NBT/Banners/ChapelBanner.nbt)
B(0,4,5,WALL_BANNER:2,./NBT/Banners/ChapelBanner.nbt)
B(-2,4,5,WALL_BANNER:2,./NBT/Banners/ChapelBanner.nbt)
B(5,4,4,WALL_BANNER:4,./NBT/Banners/ChapelBanner.nbt)
B(5,4,1,WALL_BANNER:4,./NBT/Banners/ChapelBanner.nbt)
B(-4,2,3,WALL_BANNER:5,./NBT/Banners/ChapelBanner.nbt)
B(-4,2,1,WALL_BANNER:5,./NBT/Banners/ChapelBanner.nbt)
B(-7,4,4,WALL_BANNER:5,./NBT/Banners/ChapelBanner.nbt)
B(-6,4,0,WALL_BANNER:5,./NBT/Banners/ChapelBanner.nbt)




Branch(0,-10,0,MineshaftLargeSupport,EAST,100)
WeightedBranch(16,0,-6,MineShaftHallway-E,NORTH,100,MineShaftHallwayPopulated-02-E,NORTH,10,MineShaftHallwayPopulated-01-E,NORTH,10,MineShaftHallwaySpawner-E,NORTH,10,130)