#######################################################################
# +-----------------------------------------------------------------+ #
# |                            BO3 object                           | #
# +-----------------------------------------------------------------+ #
#######################################################################

Author: Bo3 BulkEdit

Description: Converted Schematic - Modified by Bo3BulkEdit

Version: 3

SettingsMode: WriteDisable

#######################################################################
# +-----------------------------------------------------------------+ #
# |                          Main settings                          | #
# +-----------------------------------------------------------------+ #
#######################################################################

IsOTGPlus: false
Tree: false
Frequency: 1
Rarity: 100
RotateRandomly: false
SpawnHeight: randomY
SpawnHeightOffset: 0
SpawnHeightVariance: 0
MaxBranchDepth: 10
ExcludedBiomes: All

##############################
# Height Limits for the BO3. #
##############################

MinHeight: 0
MaxHeight: 256

#######################################################################
# +-----------------------------------------------------------------+ #
# |                      Source block settings                      | #
# +-----------------------------------------------------------------+ #
#######################################################################

SourceBlocks: AIR
MaxPercentageOutsideSourceBlock: 100
OutsideSourceBlock: placeAnyway

#######################################################################
# +-----------------------------------------------------------------+ #
# |                              Blocks                             | #
# +-----------------------------------------------------------------+ #
#######################################################################

B(-2,0,-8,LOG:1)
B(1,0,-8,LOG:1)
B(-2,0,7,LOG:1)
B(1,0,7,LOG:1)
B(-2,1,-8,PLANKS:5)
B(-1,1,-8,PLANKS:5)
B(0,1,-8,PLANKS:5)
B(1,1,-8,PLANKS:5)
B(-2,1,-7,PLANKS:5)
B(-1,1,-7,PLANKS:5)
B(0,1,-7,PLANKS:5)
B(1,1,-7,PLANKS:5)
B(-2,1,-6,PLANKS:5)
B(-1,1,-6,PLANKS:5)
B(0,1,-6,PLANKS:5)
B(1,1,-6,PLANKS:5)
B(-2,1,-5,PLANKS:5)
B(-1,1,-5,PLANKS:5)
B(0,1,-5,PLANKS:5)
B(1,1,-5,PLANKS:5)
B(-2,1,-4,PLANKS:5)
B(-1,1,-4,PLANKS:5)
B(0,1,-4,PLANKS:5)
B(1,1,-4,PLANKS:5)
B(-2,1,-3,PLANKS:5)
B(-1,1,-3,PLANKS:5)
B(0,1,-3,PLANKS:5)
B(1,1,-3,PLANKS:5)
B(-2,1,-2,PLANKS:5)
B(-1,1,-2,PLANKS:5)
B(0,1,-2,PLANKS:5)
B(1,1,-2,PLANKS:5)
B(-2,1,-1,PLANKS:5)
B(-1,1,-1,PLANKS:5)
B(0,1,-1,PLANKS:5)
B(1,1,-1,PLANKS:5)
B(-2,1,0,PLANKS:5)
B(-1,1,0,PLANKS:5)
B(0,1,0,PLANKS:5)
B(1,1,0,PLANKS:5)
B(-2,1,1,PLANKS:5)
B(-1,1,1,PLANKS:5)
B(0,1,1,PLANKS:5)
B(1,1,1,PLANKS:5)
B(-2,1,2,PLANKS:5)
B(-1,1,2,PLANKS:5)
B(0,1,2,PLANKS:5)
B(1,1,2,PLANKS:5)
B(-2,1,3,PLANKS:5)
B(-1,1,3,PLANKS:5)
B(0,1,3,PLANKS:5)
B(1,1,3,PLANKS:5)
B(-2,1,4,PLANKS:5)
B(-1,1,4,PLANKS:5)
B(0,1,4,PLANKS:5)
B(1,1,4,PLANKS:5)
B(-2,1,5,PLANKS:5)
B(-1,1,5,PLANKS:5)
B(0,1,5,PLANKS:5)
B(1,1,5,PLANKS:5)
B(-2,1,6,PLANKS:5)
B(-1,1,6,PLANKS:5)
B(0,1,6,PLANKS:5)
B(1,1,6,PLANKS:5)
B(-2,1,7,PLANKS:5)
B(-1,1,7,PLANKS:5)
B(0,1,7,PLANKS:5)
B(1,1,7,PLANKS:5)
B(-2,2,-8,SPRUCE_FENCE)
B(-1,2,-8,RAIL)
B(0,2,-8,AIR)
B(1,2,-8,SPRUCE_FENCE)
B(-2,2,-7,AIR)
B(-1,2,-7,RAIL)
B(0,2,-7,AIR)
RB(1,2,-7,AIR,20,SKULL:1,./NBT/Skulls/dungeon_skull_01.nbt,6,AIR,9,SKULL:1,./NBT/Skulls/dungeon_skull_02.nbt,12,AIR,15,SKULL:1,./NBT/Skulls/dungeon_skull_03.nbt,18,AIR,21,SKULL:1,./NBT/Skulls/dungeon_skull_04.nbt,24,AIR,27,SKULL:1,./NBT/Skulls/dungeon_skull_05.nbt,30,AIR,33,SKULL:1,./NBT/Skulls/dungeon_skull_06.nbt,36,AIR,39,SKULL:1,./NBT/Skulls/dungeon_skull_07.nbt,42,AIR,45,SKULL:1,./NBT/Skulls/dungeon_skull_08.nbt,48,AIR,51,SKULL:1,./NBT/Skulls/dungeon_skull_09.nbt,54,AIR,57,SKULL:1,./NBT/Skulls/dungeon_skull_10.nbt,60,AIR,63,SKULL:1,./NBT/Skulls/dungeon_skull_11.nbt,66,AIR,69,SKULL:1,./NBT/Skulls/dungeon_skull_12.nbt,72,AIR,75,SKULL:1,./NBT/Skulls/dungeon_skull_13.nbt,78,AIR,81,SKULL:1,./NBT/Skulls/dungeon_skull_14.nbt,84,AIR,87,SKULL:1,./NBT/Skulls/dungeon_skull_15.nbt,90,AIR,93,SKULL:1,./NBT/Skulls/dungeon_skull_16.nbt,96,AIR,100)
RB(-2,2,-6,AIR,20,SKULL:1,./NBT/Skulls/dungeon_skull_01.nbt,6,AIR,9,SKULL:1,./NBT/Skulls/dungeon_skull_02.nbt,12,AIR,15,SKULL:1,./NBT/Skulls/dungeon_skull_03.nbt,18,AIR,21,SKULL:1,./NBT/Skulls/dungeon_skull_04.nbt,24,AIR,27,SKULL:1,./NBT/Skulls/dungeon_skull_05.nbt,30,AIR,33,SKULL:1,./NBT/Skulls/dungeon_skull_06.nbt,36,AIR,39,SKULL:1,./NBT/Skulls/dungeon_skull_07.nbt,42,AIR,45,SKULL:1,./NBT/Skulls/dungeon_skull_08.nbt,48,AIR,51,SKULL:1,./NBT/Skulls/dungeon_skull_09.nbt,54,AIR,57,SKULL:1,./NBT/Skulls/dungeon_skull_10.nbt,60,AIR,63,SKULL:1,./NBT/Skulls/dungeon_skull_11.nbt,66,AIR,69,SKULL:1,./NBT/Skulls/dungeon_skull_12.nbt,72,AIR,75,SKULL:1,./NBT/Skulls/dungeon_skull_13.nbt,78,AIR,81,SKULL:1,./NBT/Skulls/dungeon_skull_14.nbt,84,AIR,87,SKULL:1,./NBT/Skulls/dungeon_skull_15.nbt,90,AIR,93,SKULL:1,./NBT/Skulls/dungeon_skull_16.nbt,96,WEB,100)
B(-1,2,-6,RAIL)
B(0,2,-6,AIR)
B(1,2,-6,AIR)
B(-2,2,-5,SPRUCE_FENCE)
B(-1,2,-5,RAIL)
B(0,2,-5,AIR)
B(1,2,-5,SPRUCE_FENCE)
B(-2,2,-4,AIR)
B(-1,2,-4,RAIL)
B(0,2,-4,AIR)
B(1,2,-4,AIR)
B(-2,2,-3,AIR)
B(-1,2,-3,RAIL)
B(0,2,-3,AIR)
B(1,2,-3,AIR)
B(-2,2,-2,SPRUCE_FENCE)
B(-1,2,-2,RAIL)
B(0,2,-2,AIR)
B(1,2,-2,SPRUCE_FENCE)
B(-2,2,-1,AIR)
B(-1,2,-1,RAIL)
B(0,2,-1,AIR)
B(1,2,-1,AIR)
B(-2,2,0,AIR)
B(-1,2,0,RAIL)
B(0,2,0,AIR)
B(1,2,0,AIR)
B(-2,2,1,SPRUCE_FENCE)
B(-1,2,1,RAIL)
B(0,2,1,AIR)
B(1,2,1,SPRUCE_FENCE)
RB(-2,2,2,AIR,20,SKULL:1,./NBT/Skulls/dungeon_skull_01.nbt,6,AIR,9,SKULL:1,./NBT/Skulls/dungeon_skull_02.nbt,12,AIR,15,SKULL:1,./NBT/Skulls/dungeon_skull_03.nbt,18,AIR,21,SKULL:1,./NBT/Skulls/dungeon_skull_04.nbt,24,AIR,27,SKULL:1,./NBT/Skulls/dungeon_skull_05.nbt,30,AIR,33,SKULL:1,./NBT/Skulls/dungeon_skull_06.nbt,36,AIR,39,SKULL:1,./NBT/Skulls/dungeon_skull_07.nbt,42,AIR,45,SKULL:1,./NBT/Skulls/dungeon_skull_08.nbt,48,AIR,51,SKULL:1,./NBT/Skulls/dungeon_skull_09.nbt,54,AIR,57,SKULL:1,./NBT/Skulls/dungeon_skull_10.nbt,60,AIR,63,SKULL:1,./NBT/Skulls/dungeon_skull_11.nbt,66,AIR,69,SKULL:1,./NBT/Skulls/dungeon_skull_12.nbt,72,AIR,75,SKULL:1,./NBT/Skulls/dungeon_skull_13.nbt,78,AIR,81,SKULL:1,./NBT/Skulls/dungeon_skull_14.nbt,84,AIR,87,SKULL:1,./NBT/Skulls/dungeon_skull_15.nbt,90,AIR,93,SKULL:1,./NBT/Skulls/dungeon_skull_16.nbt,96,WEB,100)
B(-1,2,2,RAIL)
B(0,2,2,AIR)
RB(1,2,2,AIR,20,SKULL:1,./NBT/Skulls/dungeon_skull_01.nbt,6,AIR,9,SKULL:1,./NBT/Skulls/dungeon_skull_02.nbt,12,AIR,15,SKULL:1,./NBT/Skulls/dungeon_skull_03.nbt,18,AIR,21,SKULL:1,./NBT/Skulls/dungeon_skull_04.nbt,24,AIR,27,SKULL:1,./NBT/Skulls/dungeon_skull_05.nbt,30,AIR,33,SKULL:1,./NBT/Skulls/dungeon_skull_06.nbt,36,AIR,39,SKULL:1,./NBT/Skulls/dungeon_skull_07.nbt,42,AIR,45,SKULL:1,./NBT/Skulls/dungeon_skull_08.nbt,48,AIR,51,SKULL:1,./NBT/Skulls/dungeon_skull_09.nbt,54,AIR,57,SKULL:1,./NBT/Skulls/dungeon_skull_10.nbt,60,AIR,63,SKULL:1,./NBT/Skulls/dungeon_skull_11.nbt,66,AIR,69,SKULL:1,./NBT/Skulls/dungeon_skull_12.nbt,72,AIR,75,SKULL:1,./NBT/Skulls/dungeon_skull_13.nbt,78,AIR,81,SKULL:1,./NBT/Skulls/dungeon_skull_14.nbt,84,AIR,87,SKULL:1,./NBT/Skulls/dungeon_skull_15.nbt,90,AIR,93,SKULL:1,./NBT/Skulls/dungeon_skull_16.nbt,96,WEB,100)
B(-2,2,3,AIR)
B(-1,2,3,RAIL)
B(0,2,3,AIR)
B(1,2,3,AIR)
B(-2,2,4,SPRUCE_FENCE)
B(-1,2,4,RAIL)
B(0,2,4,AIR)
B(1,2,4,SPRUCE_FENCE)
B(-2,2,5,AIR)
B(-1,2,5,RAIL)
B(0,2,5,AIR)
B(1,2,5,AIR)
B(-2,2,6,AIR)
B(-1,2,6,RAIL)
B(0,2,6,AIR)
B(1,2,6,AIR)
B(-2,2,7,SPRUCE_FENCE)
B(-1,2,7,RAIL)
B(0,2,7,AIR)
B(1,2,7,SPRUCE_FENCE)
B(-2,3,-8,SPRUCE_FENCE)
B(-1,3,-8,AIR)
B(0,3,-8,AIR)
B(1,3,-8,SPRUCE_FENCE)
B(-2,3,-7,AIR)
B(-1,3,-7,AIR)
B(0,3,-7,AIR)
B(1,3,-7,AIR)
B(-2,3,-6,AIR)
B(-1,3,-6,AIR)
B(0,3,-6,AIR)
B(1,3,-6,AIR)
B(-2,3,-5,SPRUCE_FENCE)
B(-1,3,-5,AIR)
B(0,3,-5,AIR)
B(1,3,-5,SPRUCE_FENCE)
B(-2,3,-4,AIR)
B(-1,3,-4,AIR)
B(0,3,-4,AIR)
B(1,3,-4,AIR)
B(-2,3,-3,AIR)
B(-1,3,-3,AIR)
B(0,3,-3,AIR)
B(1,3,-3,AIR)
B(-2,3,-2,SPRUCE_FENCE)
B(-1,3,-2,AIR)
B(0,3,-2,AIR)
B(1,3,-2,SPRUCE_FENCE)
B(-2,3,-1,AIR)
B(-1,3,-1,AIR)
B(0,3,-1,AIR)
B(1,3,-1,AIR)
B(-2,3,0,AIR)
B(-1,3,0,AIR)
B(0,3,0,AIR)
B(1,3,0,AIR)
B(-2,3,1,SPRUCE_FENCE)
B(-1,3,1,AIR)
B(0,3,1,AIR)
B(1,3,1,SPRUCE_FENCE)
B(-2,3,2,AIR)
B(-1,3,2,AIR)
B(0,3,2,AIR)
B(1,3,2,AIR)
B(-2,3,3,AIR)
B(-1,3,3,AIR)
B(0,3,3,AIR)
B(1,3,3,AIR)
B(-2,3,4,SPRUCE_FENCE)
B(-1,3,4,AIR)
B(0,3,4,AIR)
B(1,3,4,SPRUCE_FENCE)
B(-2,3,5,AIR)
B(-1,3,5,AIR)
B(0,3,5,AIR)
B(1,3,5,AIR)
B(-2,3,6,AIR)
B(-1,3,6,AIR)
B(0,3,6,AIR)
B(1,3,6,AIR)
B(-2,3,7,SPRUCE_FENCE)
B(-1,3,7,AIR)
B(0,3,7,AIR)
B(1,3,7,SPRUCE_FENCE)
B(-2,4,-8,PLANKS:1)
B(-1,4,-8,PLANKS:1)
B(0,4,-8,PLANKS:1)
B(1,4,-8,PLANKS:1)
B(-2,4,-7,AIR)
B(-1,4,-7,AIR)
B(0,4,-7,AIR)
B(1,4,-7,AIR)
B(-2,4,-6,AIR)
B(-1,4,-6,AIR)
B(0,4,-6,AIR)
B(1,4,-6,AIR)
B(-2,4,-5,PLANKS:1)
B(-1,4,-5,PLANKS:1)
B(0,4,-5,PLANKS:1)
B(1,4,-5,PLANKS:1)
B(-2,4,-4,AIR)
B(-1,4,-4,AIR)
B(0,4,-4,AIR)
B(1,4,-4,AIR)
B(-2,4,-3,AIR)
B(-1,4,-3,AIR)
B(0,4,-3,AIR)
B(1,4,-3,AIR)
B(-2,4,-2,PLANKS:1)
B(-1,4,-2,PLANKS:1)
B(0,4,-2,PLANKS:1)
B(1,4,-2,PLANKS:1)
B(-2,4,-1,AIR)
B(-1,4,-1,AIR)
B(0,4,-1,AIR)
B(1,4,-1,AIR)
B(-2,4,0,AIR)
B(-1,4,0,AIR)
B(1,4,0,AIR)
B(-2,4,1,PLANKS:1)
B(-1,4,1,PLANKS:1)
B(0,4,1,PLANKS:1)
B(1,4,1,PLANKS:1)
B(-2,4,2,AIR)
B(-1,4,2,AIR)
B(0,4,2,AIR)
B(1,4,2,AIR)
B(-2,4,3,AIR)
B(-1,4,3,AIR)
B(0,4,3,AIR)
B(1,4,3,AIR)
B(-2,4,4,PLANKS:1)
B(-1,4,4,PLANKS:1)
B(0,4,4,PLANKS:1)
B(1,4,4,PLANKS:1)
B(-2,4,5,AIR)
B(-1,4,5,AIR)
B(0,4,5,AIR)
B(1,4,5,AIR)
B(-2,4,6,AIR)
B(-1,4,6,AIR)
B(0,4,6,AIR)
B(1,4,6,AIR)
B(-2,4,7,PLANKS:1)
B(-1,4,7,PLANKS:1)
B(0,4,7,PLANKS:1)
B(1,4,7,PLANKS:1)

RB(0,4,0,TORCH:4,42,AIR,50,TORCH:4,50)

WeightedBranch(0,0,-16,MineShaftHallwayFloor-N,NORTH,100,MineShaftHallwayPopulatedFloor-02-N,NORTH,10,MineShaftHallwayPopulatedFloor-01-N,NORTH,10,MineShaftHallwaySpawnerFloor-N,NORTH,10,MineshaftTSectionFloor-N,NORTH,5,MineshaftCrossFloor-N,NORTH,5,MineshaftJunction-N,NORTH,5,145)
Branch(0,-11,0,MineShaftHallwaySupport,NORTH,100)