#######################################################################
# +-----------------------------------------------------------------+ #
# |                            BO3 object                           | #
# +-----------------------------------------------------------------+ #
#######################################################################

Author: Bo3 BulkEdit

Description: Converted Schematic - Modified by Bo3BulkEdit

Version: 3

SettingsMode: WriteDisable

#######################################################################
# +-----------------------------------------------------------------+ #
# |                          Main settings                          | #
# +-----------------------------------------------------------------+ #
#######################################################################

IsOTGPlus: false
Tree: false
Frequency: 1
Rarity: 100
RotateRandomly: false
SpawnHeight: randomY
SpawnHeightOffset: 0
SpawnHeightVariance: 0
MaxBranchDepth: 10
ExcludedBiomes: All

##############################
# Height Limits for the BO3. #
##############################

MinHeight: 0
MaxHeight: 256

#######################################################################
# +-----------------------------------------------------------------+ #
# |                      Source block settings                      | #
# +-----------------------------------------------------------------+ #
#######################################################################

SourceBlocks: HARDENED_CLAY,WATER,STATIONARY_WATER,SANDSTONE,AIR,LAVA,OBSIDIAN,SAND,STATIONARY_LAVA,DIRT,GRASS,GRAVEL,CLAY,DIRT:2,DIRT:1,STONE:5,STONE,STONE:3,STONE:1,STONE:1,REDSTONE_ORE,LAPIS_ORE,IRON_ORE,GOLD_ORE,EMERALD_ORE,DIAMOND_ORE,COAL_ORE
MaxPercentageOutsideSourceBlock: 100
OutsideSourceBlock: dontPlace

#######################################################################
# +-----------------------------------------------------------------+ #
# |                              Blocks                             | #
# +-----------------------------------------------------------------+ #
#######################################################################

B(-2,0,-8,COBBLESTONE)
B(1,0,-8,COBBLESTONE)
B(-8,0,-2,COBBLESTONE)
B(-2,0,-2,COBBLESTONE)
B(1,0,-2,COBBLESTONE)
B(7,0,-2,COBBLESTONE)
B(-8,0,1,COBBLESTONE)
B(-2,0,1,COBBLESTONE)
B(1,0,1,COBBLESTONE)
B(7,0,1,COBBLESTONE)
B(-2,0,7,COBBLESTONE)
B(1,0,7,COBBLESTONE)
B(-2,1,-8,COBBLESTONE)
B(1,1,-8,COBBLESTONE)
B(-8,1,-2,COBBLESTONE)
B(-2,1,-2,COBBLESTONE)
B(1,1,-2,COBBLESTONE)
B(7,1,-2,COBBLESTONE)
B(-8,1,1,COBBLESTONE)
B(-2,1,1,COBBLESTONE)
B(1,1,1,COBBLESTONE)
B(7,1,1,COBBLESTONE)
B(-2,1,7,COBBLESTONE)
B(1,1,7,COBBLESTONE)
B(-2,2,-8,COBBLESTONE)
B(1,2,-8,COBBLESTONE)
B(-8,2,-2,COBBLESTONE)
B(-2,2,-2,COBBLESTONE)
B(1,2,-2,COBBLESTONE)
B(7,2,-2,COBBLESTONE)
B(-8,2,1,COBBLESTONE)
B(-2,2,1,COBBLESTONE)
B(1,2,1,COBBLESTONE)
B(7,2,1,COBBLESTONE)
B(-2,2,7,COBBLESTONE)
B(1,2,7,COBBLESTONE)
B(-2,3,-8,COBBLESTONE)
B(1,3,-8,COBBLESTONE)
B(-8,3,-2,COBBLESTONE)
B(-2,3,-2,COBBLESTONE)
B(1,3,-2,COBBLESTONE)
B(7,3,-2,COBBLESTONE)
B(-8,3,1,COBBLESTONE)
B(-2,3,1,COBBLESTONE)
B(1,3,1,COBBLESTONE)
B(7,3,1,COBBLESTONE)
B(-2,3,7,COBBLESTONE)
B(1,3,7,COBBLESTONE)
B(-2,4,-8,COBBLESTONE)
B(1,4,-8,COBBLESTONE)
B(-8,4,-2,COBBLESTONE)
B(-2,4,-2,COBBLESTONE)
B(1,4,-2,COBBLESTONE)
B(7,4,-2,COBBLESTONE)
B(-8,4,1,COBBLESTONE)
B(-2,4,1,COBBLESTONE)
B(1,4,1,COBBLESTONE)
B(7,4,1,COBBLESTONE)
B(-2,4,7,COBBLESTONE)
B(1,4,7,COBBLESTONE)
B(-2,5,-8,COBBLESTONE)
B(1,5,-8,COBBLESTONE)
B(-8,5,-2,COBBLESTONE)
B(-2,5,-2,COBBLESTONE)
B(1,5,-2,COBBLESTONE)
B(7,5,-2,COBBLESTONE)
B(-8,5,1,COBBLESTONE)
B(-2,5,1,COBBLESTONE)
B(1,5,1,COBBLESTONE)
B(7,5,1,COBBLESTONE)
B(-2,5,7,COBBLESTONE)
B(1,5,7,COBBLESTONE)
B(-2,6,-8,COBBLESTONE)
B(1,6,-8,COBBLESTONE)
B(-8,6,-2,COBBLESTONE)
B(-2,6,-2,COBBLESTONE)
B(1,6,-2,COBBLESTONE)
B(7,6,-2,COBBLESTONE)
B(-8,6,1,COBBLESTONE)
B(-2,6,1,COBBLESTONE)
B(1,6,1,COBBLESTONE)
B(7,6,1,COBBLESTONE)
B(-2,6,7,COBBLESTONE)
B(1,6,7,COBBLESTONE)
B(-2,7,-8,COBBLESTONE)
B(1,7,-8,COBBLESTONE)
B(-2,7,-7,STONE_STAIRS:7)
B(1,7,-7,STONE_STAIRS:7)
B(-8,7,-2,COBBLESTONE)
B(-7,7,-2,STONE_STAIRS:5)
B(-2,7,-2,COBBLESTONE)
B(1,7,-2,COBBLESTONE)
B(6,7,-2,STONE_STAIRS:4)
B(7,7,-2,COBBLESTONE)
B(-8,7,1,COBBLESTONE)
B(-7,7,1,STONE_STAIRS:5)
B(-2,7,1,COBBLESTONE)
B(1,7,1,COBBLESTONE)
B(6,7,1,STONE_STAIRS:4)
B(7,7,1,COBBLESTONE)
B(-2,7,6,STONE_STAIRS:6)
B(1,7,6,STONE_STAIRS:6)
B(-2,7,7,COBBLESTONE)
B(1,7,7,COBBLESTONE)
B(-2,8,-8,COBBLESTONE)
B(1,8,-8,COBBLESTONE)
B(-2,8,-7,LOG:5)
B(-1,8,-7,LOG:5)
B(0,8,-7,LOG:5)
B(1,8,-7,LOG:5)
B(-2,8,-6,STONE_STAIRS:7)
B(1,8,-6,STONE_STAIRS:7)
B(-2,8,-5,STONE_SLAB:11)
B(1,8,-5,STONE_SLAB:11)
B(-8,8,-2,COBBLESTONE)
B(-7,8,-2,LOG:9)
B(-6,8,-2,STONE_STAIRS:5)
B(-5,8,-2,STONE_SLAB:11)
B(-2,8,-2,COBBLESTONE)
B(1,8,-2,COBBLESTONE)
B(4,8,-2,STONE_SLAB:11)
B(5,8,-2,STONE_STAIRS:4)
B(6,8,-2,LOG:9)
B(7,8,-2,COBBLESTONE)
B(-7,8,-1,LOG:9)
B(6,8,-1,LOG:9)
B(-7,8,0,LOG:9)
B(6,8,0,LOG:9)
B(-8,8,1,COBBLESTONE)
B(-7,8,1,LOG:9)
B(-6,8,1,STONE_STAIRS:5)
B(-5,8,1,STONE_SLAB:11)
B(-2,8,1,COBBLESTONE)
B(1,8,1,COBBLESTONE)
B(4,8,1,STONE_SLAB:11)
B(5,8,1,STONE_STAIRS:4)
B(6,8,1,LOG:9)
B(7,8,1,COBBLESTONE)
B(-2,8,4,STONE_SLAB:11)
B(1,8,4,STONE_SLAB:11)
B(-2,8,5,STONE_STAIRS:6)
B(1,8,5,STONE_STAIRS:6)
B(-2,8,6,LOG:5)
B(-1,8,6,LOG:5)
B(0,8,6,LOG:5)
B(1,8,6,LOG:5)
B(-2,8,7,COBBLESTONE)
B(1,8,7,COBBLESTONE)
B(-2,9,-8,COBBLESTONE)
B(1,9,-8,COBBLESTONE)
B(-2,9,-7,STONE_STAIRS)
B(1,9,-7,STONE_STAIRS)
B(-2,9,-5,STONE_STAIRS:2)
B(1,9,-5,STONE_STAIRS:2)
B(-2,9,-4,STONE_STAIRS:7)
B(1,9,-4,STONE_STAIRS:7)
B(-2,9,-3,STONE_SLAB:11)
B(1,9,-3,STONE_SLAB:11)
B(-8,9,-2,COBBLESTONE)
B(-7,9,-2,STONE_STAIRS:1)
B(-5,9,-2,STONE_STAIRS)
B(-4,9,-2,STONE_STAIRS:5)
B(-3,9,-2,STONE_SLAB:11)
B(-2,9,-2,COBBLESTONE)
B(-1,9,-2,STONE_SLAB:11)
B(0,9,-2,STONE_SLAB:11)
B(1,9,-2,COBBLESTONE)
B(2,9,-2,STONE_SLAB:11)
B(3,9,-2,STONE_STAIRS:4)
B(4,9,-2,STONE_STAIRS:1)
B(6,9,-2,STONE_STAIRS)
B(7,9,-2,COBBLESTONE)
B(-2,9,-1,STONE_SLAB:11)
B(1,9,-1,STONE_SLAB:11)
B(-2,9,0,STONE_SLAB:11)
B(1,9,0,STONE_SLAB:11)
B(-8,9,1,COBBLESTONE)
B(-7,9,1,STONE_STAIRS:1)
B(-5,9,1,STONE_STAIRS)
B(-4,9,1,STONE_STAIRS:5)
B(-3,9,1,STONE_SLAB:11)
B(-2,9,1,COBBLESTONE)
B(-1,9,1,STONE_SLAB:11)
B(0,9,1,STONE_SLAB:11)
B(1,9,1,COBBLESTONE)
B(2,9,1,STONE_SLAB:11)
B(3,9,1,STONE_STAIRS:4)
B(4,9,1,STONE_STAIRS:1)
B(6,9,1,STONE_STAIRS)
B(7,9,1,COBBLESTONE)
B(-2,9,2,STONE_SLAB:11)
B(1,9,2,STONE_SLAB:11)
B(-2,9,3,STONE_STAIRS:6)
B(1,9,3,STONE_STAIRS:6)
B(-2,9,4,STONE_STAIRS)
B(1,9,4,STONE_STAIRS)
B(-2,9,6,STONE_STAIRS:2)
B(1,9,6,STONE_STAIRS:2)
B(-2,9,7,COBBLESTONE)
B(1,9,7,COBBLESTONE)
B(-2,10,-8,LOG:1)
B(1,10,-8,LOG:1)
B(-2,10,-7,STONE_STAIRS:7)
B(1,10,-7,STONE_STAIRS:7)
B(-2,10,-5,STONE_STAIRS:6)
B(1,10,-5,STONE_STAIRS:6)
B(-2,10,-4,LOG:1)
B(1,10,-4,LOG:1)
B(-2,10,-3,STONE_SLAB:11)
B(1,10,-3,STONE_SLAB:11)
B(-8,10,-2,LOG:1)
B(-7,10,-2,STONE_STAIRS:5)
B(-5,10,-2,STONE_STAIRS:4)
B(-4,10,-2,LOG:1)
B(-3,10,-2,STONE_SLAB:11)
B(-2,10,-2,LOG:1)
B(-1,10,-2,STONE_SLAB:11)
B(0,10,-2,STONE_SLAB:11)
B(1,10,-2,LOG:1)
B(2,10,-2,STONE_SLAB:11)
B(3,10,-2,LOG:1)
B(4,10,-2,STONE_STAIRS:5)
B(6,10,-2,STONE_STAIRS:4)
B(7,10,-2,LOG:1)
B(-2,10,-1,STONE_SLAB:11)
B(1,10,-1,STONE_SLAB:11)
B(-2,10,0,STONE_SLAB:11)
B(1,10,0,STONE_SLAB:11)
B(-8,10,1,LOG:1)
B(-7,10,1,STONE_STAIRS:5)
B(-5,10,1,STONE_STAIRS:4)
B(-4,10,1,LOG:1)
B(-3,10,1,STONE_SLAB:11)
B(-2,10,1,LOG:1)
B(-1,10,1,STONE_SLAB:11)
B(0,10,1,STONE_SLAB:11)
B(1,10,1,LOG:1)
B(2,10,1,STONE_SLAB:11)
B(3,10,1,LOG:1)
B(4,10,1,STONE_STAIRS:5)
B(6,10,1,STONE_STAIRS:4)
B(7,10,1,LOG:1)
B(-2,10,2,STONE_SLAB:11)
B(1,10,2,STONE_SLAB:11)
B(-2,10,3,LOG:1)
B(1,10,3,LOG:1)
B(-2,10,4,STONE_STAIRS:7)
B(1,10,4,STONE_STAIRS:7)
B(-2,10,6,STONE_STAIRS:6)
B(1,10,6,STONE_STAIRS:6)
B(-2,10,7,LOG:1)
B(1,10,7,LOG:1)

Branch(0,-7,0,MineshaftCrossSupportExtension,NORTH,100)