Author: Bo3 BulkEdit

Description: Converted Schematic - Modified by Bo3BulkEdit

Version: 3

SettingsMode: WriteDisable

IsOTGPlus: false
Tree: false
Frequency: 1
Rarity: 100
RotateRandomly: false
SpawnHeight: randomY
MaxBranchDepth: 20
ExcludedBiomes: All

MinHeight: 0
MaxHeight: 256

SourceBlocks: AIR
MaxPercentageOutsideSourceBlock: 100
OutsideSourceBlock: placeAnyway

B(-1,0,-2,FENCE:0)
B(-1,1,-8,SPRUCE_FENCE:0)
B(-5,1,-4,WOOL:15)
B(-4,1,-4,WOOL:15)
B(-3,1,-4,FENCE:0)
B(-7,1,-3,WOOL:0)
B(-3,1,-3,FENCE:0)
B(-2,1,-3,FENCE:0)
B(-1,1,-3,FENCE:0)
B(-1,1,-2,FENCE:0)
B(-1,2,-8,TORCH:5)
B(-6,2,-4,WOOL:0)
B(-5,2,-4,WOOL:15)
B(-7,2,-3,WOOL:15)
B(-6,2,-3,WOOL:0)
B(-7,2,-2,WOOL:15)
B(-8,2,-1,WOOL:15)
B(-7,3,-3,WOOL:0)
B(-8,3,-2,WOOL:0)
B(-8,3,-1,WOOL:0)
B(-2,3,-1,FENCE:0)
B(-1,3,-1,TRAPDOOR:4)
B(-8,4,-3,WOOL:0)
B(-8,4,-2,WOOL:0)
B(-3,4,-2,FENCE:0)
B(-3,4,-1,FENCE:0)
B(-2,4,-1,FENCE:0)
B(-8,5,-3,WOOL:0)
B(-4,5,-3,FENCE:0)
B(-8,5,-2,WOOL:0)
B(-4,5,-2,FENCE:0)
B(-3,5,-2,FENCE:0)
B(-8,5,-1,WOOL:0)
B(-7,6,-4,WOOL:15)
B(-6,6,-4,WOOL:15)
B(-4,6,-4,FENCE:0)
B(-7,6,-3,WOOL:0)
B(-6,6,-3,FENCE:0)
B(-4,6,-3,FENCE:0)
B(-7,6,-2,WOOL:15)
B(-6,6,-2,FENCE:0)
B(-8,6,-1,WOOL:15)
B(-6,6,-1,FENCE:0)
B(-6,7,-4,WOOL:0)
B(-5,7,-4,WOOL:0)
B(-4,7,-4,FENCE:0)
B(-6,7,-3,WOODEN_SLAB:1)
B(-6,7,-2,WOODEN_SLAB:1)
B(-6,7,-1,WOODEN_SLAB:1)

BR(-8,0,0,WestPortShipFat_2x3,NORTH,100)
