Author: Bo3 BulkEdit

Description: Converted Schematic - Modified by Bo3BulkEdit

Version: 3

SettingsMode: WriteDisable

IsOTGPlus: false
Tree: false
Frequency: 1
Rarity: 100
RotateRandomly: false
SpawnHeight: randomY
MaxBranchDepth: 20
ExcludedBiomes: All

MinHeight: 0
MaxHeight: 256

SourceBlocks: AIR
MaxPercentageOutsideSourceBlock: 100
OutsideSourceBlock: placeAnyway

B(-8,-9,-1,LOG:12)
B(-7,-9,-1,LOG:12)
B(-6,-9,-1,LOG:12)
B(-5,-9,-1,LOG:12)
B(-4,-9,-1,LOG:12)
B(-3,-9,-1,LOG:12)
B(-2,-9,-1,LOG:12)
B(-8,-8,-3,LOG:12)
B(-7,-8,-3,LOG:12)
B(-6,-8,-3,LOG:12)
B(-5,-8,-3,LOG:12)
B(-4,-8,-3,LOG:12)
B(-3,-8,-3,LOG:12)
B(-8,-8,-2,LOG:12)
B(-7,-8,-2,LOG:12)
B(-6,-8,-2,LOG:12)
B(-5,-8,-2,LOG:12)
B(-4,-8,-2,LOG:12)
B(-3,-8,-2,LOG:12)
B(-2,-8,-2,LOG:12)
B(-1,-8,-2,LOG:12)
B(-8,-8,-1,LOG:12)
B(-7,-8,-1,LOG:12)
B(-6,-8,-1,LOG:12)
B(-5,-8,-1,HAY_BLOCK:0)
B(-4,-8,-1,MELON_BLOCK:0)
B(-3,-8,-1,MELON_BLOCK:0)
B(-2,-8,-1,HAY_BLOCK:4)
B(-1,-8,-1,LOG:12)
B(-8,-7,-4,LOG:12)
B(-7,-7,-4,LOG:12)
B(-6,-7,-4,LOG:12)
B(-5,-7,-4,LOG:12)
B(-4,-7,-4,LOG:12)
B(-3,-7,-4,LOG:12)
B(-2,-7,-4,LOG:12)
B(-8,-7,-3,TNT:0)
B(-7,-7,-3,TNT:0)
B(-6,-7,-3,LOG:12)
B(-5,-7,-3,MELON_BLOCK:0)
B(-4,-7,-3,MELON_BLOCK:0)
B(-3,-7,-3,HAY_BLOCK:8)
B(-2,-7,-3,LOG:12)
B(-1,-7,-3,LOG:12)
B(-8,-7,-2,TNT:0)
B(-7,-7,-2,TNT:0)
B(-6,-7,-2,LOG:12)
B(-5,-7,-2,MELON_BLOCK:0)
B(-4,-7,-2,PUMPKIN:1)
B(-3,-7,-2,PUMPKIN:1)
B(-2,-7,-2,HAY_BLOCK:4)
B(-1,-7,-2,HAY_BLOCK:0)
B(-8,-7,-1,LOG:12)
B(-7,-7,-1,LOG:12)
B(-6,-7,-1,LOG:12)
B(-5,-7,-1,HAY_BLOCK:0)
B(-4,-7,-1,PUMPKIN:1)
B(-3,-7,-1,PUMPKIN:1)
B(-2,-7,-1,AIR:0)
B(-1,-7,-1,HAY_BLOCK:0)
B(-8,-6,-5,LOG:12)
B(-7,-6,-5,LOG:12)
B(-6,-6,-5,LOG:12)
B(-5,-6,-5,LOG:12)
B(-4,-6,-5,LOG:12)
B(-3,-6,-5,LOG:12)
B(-8,-6,-4,TNT:0)
B(-7,-6,-4,TNT:0)
B(-6,-6,-4,LOG:12)
B(-5,-6,-4,LOG:12)
B(-4,-6,-4,LOG:12)
B(-3,-6,-4,LOG:12)
B(-2,-6,-4,LOG:12)
B(-1,-6,-4,LOG:12)
B(-8,-6,-3,TNT:0)
B(-7,-6,-3,TNT:0)
B(-6,-6,-3,LOG:12)
B(-5,-6,-3,HAY_BLOCK:8)
B(-4,-6,-3,AIR:0)
B(-3,-6,-3,HAY_BLOCK:8)
B(-2,-6,-3,MELON_BLOCK:0)
B(-1,-6,-3,PUMPKIN:1)
B(-8,-6,-2,TNT:0)
B(-7,-6,-2,TNT:0)
B(-6,-6,-2,LOG:12)
B(-5,-6,-2,AIR:0)
B(-4,-6,-2,AIR:0)
B(-3,-6,-2,AIR:0)
B(-2,-6,-2,AIR:0)
B(-1,-6,-2,AIR:0)
B(-8,-6,-1,LOG:12)
B(-7,-6,-1,LOG:12)
B(-6,-6,-1,LOG:12)
B(-5,-6,-1,HAY_BLOCK:0)
B(-4,-6,-1,AIR:0)
B(-3,-6,-1,AIR:0)
B(-2,-6,-1,AIR:0)
B(-1,-6,-1,AIR:0)
B(-8,-5,-5,LOG:12)
B(-7,-5,-5,LOG:12)
B(-6,-5,-5,LOG:12)
B(-5,-5,-5,LOG:12)
B(-4,-5,-5,LOG:12)
B(-3,-5,-5,LOG:12)
B(-2,-5,-5,LOG:12)
B(-1,-5,-5,LOG:12)
B(-8,-5,-4,TNT:0)
B(-7,-5,-4,TNT:0)
B(-6,-5,-4,LOG:12)
B(-5,-5,-4,LOG:12)
B(-4,-5,-4,LOG:12)
B(-3,-5,-4,LOG:12)
B(-2,-5,-4,LOG:12)
B(-1,-5,-4,LOG:12)
B(-8,-5,-3,AIR:0)
B(-7,-5,-3,TNT:0)
B(-6,-5,-3,LOG:12)
B(-5,-5,-3,AIR:0)
B(-4,-5,-3,AIR:0)
B(-3,-5,-3,HAY_BLOCK:4)
B(-2,-5,-3,HAY_BLOCK:8)
B(-1,-5,-3,AIR:0)
B(-8,-5,-2,AIR:0)
B(-7,-5,-2,TNT:0)
B(-6,-5,-2,LOG:12)
B(-5,-5,-2,AIR:0)
B(-4,-5,-2,AIR:0)
B(-3,-5,-2,AIR:0)
B(-2,-5,-2,AIR:0)
B(-1,-5,-2,AIR:0)
B(-8,-5,-1,LOG:12)
B(-7,-5,-1,LOG:12)
B(-6,-5,-1,LOG:12)
B(-5,-5,-1,HAY_BLOCK:4)
B(-4,-5,-1,AIR:0)
B(-3,-5,-1,AIR:0)
B(-2,-5,-1,AIR:0)
B(-1,-5,-1,AIR:0)
B(-8,-4,-6,PLANKS:0)
B(-7,-4,-6,PLANKS:0)
B(-6,-4,-6,PLANKS:0)
B(-5,-4,-6,PLANKS:0)
B(-4,-4,-6,PLANKS:0)
B(-8,-4,-5,DOUBLE_WOODEN_SLAB:1)
B(-7,-4,-5,DOUBLE_WOODEN_SLAB:1)
B(-6,-4,-5,DOUBLE_WOODEN_SLAB:1)
B(-5,-4,-5,DOUBLE_WOODEN_SLAB:1)
B(-4,-4,-5,DOUBLE_WOODEN_SLAB:1)
B(-3,-4,-5,PLANKS:0)
B(-2,-4,-5,PLANKS:0)
B(-1,-4,-5,PLANKS:0)
B(-8,-4,-4,DOUBLE_WOODEN_SLAB:1)
B(-7,-4,-4,DOUBLE_WOODEN_SLAB:1)
B(-6,-4,-4,DOUBLE_WOODEN_SLAB:1)
B(-5,-4,-4,DOUBLE_WOODEN_SLAB:1)
B(-4,-4,-4,DOUBLE_WOODEN_SLAB:1)
B(-3,-4,-4,DOUBLE_WOODEN_SLAB:1)
B(-2,-4,-4,DOUBLE_WOODEN_SLAB:1)
B(-1,-4,-4,DOUBLE_WOODEN_SLAB:1)
B(-8,-4,-3,DOUBLE_WOODEN_SLAB:1)
B(-7,-4,-3,DOUBLE_WOODEN_SLAB:1)
B(-6,-4,-3,DOUBLE_WOODEN_SLAB:1)
B(-5,-4,-3,WOODEN_SLAB:9)
B(-4,-4,-3,WOODEN_SLAB:9)
B(-3,-4,-3,WOODEN_SLAB:9)
B(-2,-4,-3,WOODEN_SLAB:9)
B(-1,-4,-3,WOODEN_SLAB:9)
B(-8,-4,-2,DOUBLE_WOODEN_SLAB:1)
B(-7,-4,-2,DOUBLE_WOODEN_SLAB:1)
B(-6,-4,-2,DOUBLE_WOODEN_SLAB:1)
B(-5,-4,-2,WOODEN_SLAB:9)
B(-4,-4,-2,WOODEN_SLAB:9)
B(-3,-4,-2,WOODEN_SLAB:9)
B(-2,-4,-2,WOODEN_SLAB:9)
B(-1,-4,-2,WOODEN_SLAB:9)
B(-8,-4,-1,DOUBLE_WOODEN_SLAB:1)
B(-7,-4,-1,DOUBLE_WOODEN_SLAB:1)
B(-6,-4,-1,DOUBLE_WOODEN_SLAB:1)
B(-5,-4,-1,WOODEN_SLAB:9)
B(-4,-4,-1,WOODEN_SLAB:9)
B(-3,-4,-1,WOODEN_SLAB:9)
B(-2,-4,-1,WOODEN_SLAB:9)
B(-1,-4,-1,WOODEN_SLAB:9)
B(-8,-3,-7,DISPENSER:2)
B(-3,-3,-7,DISPENSER:2)
B(-8,-3,-6,CONCRETE:15)
B(-7,-3,-6,PLANKS:0)
B(-6,-3,-6,PLANKS:0)
B(-5,-3,-6,PLANKS:0)
B(-4,-3,-6,PLANKS:0)
B(-3,-3,-6,CONCRETE:15)
B(-2,-3,-6,PLANKS:0)
B(-8,-3,-5,DISPENSER:9)
B(-7,-3,-5,WOODEN_BUTTON:1)
B(-4,-3,-5,WOODEN_BUTTON:2)
B(-3,-3,-5,DISPENSER:9)
B(-2,-3,-5,WOODEN_BUTTON:1)
B(-1,-3,-5,PLANKS:0)
B(-8,-3,-4,OAK_STAIRS:3)
B(-6,-3,-4,CARPET:12)
B(-3,-3,-4,OAK_STAIRS:3)
RB(-1,-3,-4,CHEST:3,../NBT/StructureLoot/JunkChest_1.nbt,15,CHEST:3,../NBT/StructureLoot/JunkChest_2.nbt,15,CHEST:3,../NBT/StructureLoot/JunkChest_3.nbt,15,CHEST:3,../NBT/StructureLoot/JunkChest_4.nbt,15,CHEST:3,../NBT/StructureLoot/JunkChest_5.nbt,15,CHEST:3,../NBT/StructureLoot/Common1.nbt,15,CHEST:3,../NBT/StructureLoot/Common2.nbt,15,CHEST:3,../NBT/StructureLoot/Common3.nbt,15,CHEST:3,../NBT/StructureLoot/Common4.nbt,15,CHEST:3,../NBT/StructureLoot/Common5.nbt,15,CHEST:3,../NBT/StructureLoot/Common6.nbt,15,CHEST:3,../NBT/StructureLoot/Common7.nbt,15,CHEST:3,../NBT/StructureLoot/Common8.nbt,15,CHEST:3,../NBT/StructureLoot/Common9.nbt,15,CHEST:3,../NBT/StructureLoot/Common10.nbt,15,CHEST:3,../NBT/StructureLoot/Common11.nbt,15,CHEST:3,../NBT/StructureLoot/Common12.nbt,15,CHEST:3,../NBT/StructureLoot/Common13.nbt,15,CHEST:3,../NBT/StructureLoot/Common14.nbt,15,CHEST:3,../NBT/StructureLoot/Common15.nbt,100)
B(-7,-3,-3,SPRUCE_FENCE:0)
B(-6,-3,-3,BED:9)
B(-5,-3,-3,BED:1)
B(-4,-3,-3,SPRUCE_FENCE:0)
B(-1,-3,-3,CARPET:12)
B(-7,-3,-2,CARPET:12)
B(-6,-3,-2,CARPET:13)
B(-4,-3,-2,CARPET:12)
B(-3,-3,-2,CARPET:12)
B(-2,-3,-2,CARPET:13)
B(-1,-3,-2,CARPET:12)
RB(-8,-3,-1,CHEST:5,../NBT/StructureLoot/JunkChest_1.nbt,15,CHEST:5,../NBT/StructureLoot/JunkChest_2.nbt,15,CHEST:5,../NBT/StructureLoot/JunkChest_3.nbt,15,CHEST:5,../NBT/StructureLoot/JunkChest_4.nbt,15,CHEST:5,../NBT/StructureLoot/JunkChest_5.nbt,15,CHEST:5,../NBT/StructureLoot/Common1.nbt,15,CHEST:5,../NBT/StructureLoot/Common2.nbt,15,CHEST:5,../NBT/StructureLoot/Common3.nbt,15,CHEST:5,../NBT/StructureLoot/Common4.nbt,15,CHEST:5,../NBT/StructureLoot/Common5.nbt,15,CHEST:5,../NBT/StructureLoot/Common6.nbt,15,CHEST:5,../NBT/StructureLoot/Common7.nbt,15,CHEST:5,../NBT/StructureLoot/Common8.nbt,15,CHEST:5,../NBT/StructureLoot/Common9.nbt,15,CHEST:5,../NBT/StructureLoot/Common10.nbt,15,CHEST:5,../NBT/StructureLoot/Common11.nbt,15,CHEST:5,../NBT/StructureLoot/Common12.nbt,15,CHEST:5,../NBT/StructureLoot/Common13.nbt,15,CHEST:5,../NBT/StructureLoot/Common14.nbt,15,CHEST:5,../NBT/StructureLoot/Common15.nbt,100)
B(-6,-3,-1,BED:3)
B(-5,-3,-1,BED:11)
B(-4,-3,-1,PLANKS:2)
B(-3,-3,-1,PLANKS:2)
B(-2,-3,-1,BED:9)
B(-1,-3,-1,BED:1)
B(-8,-2,-7,WOODEN_SLAB:13)
B(-3,-2,-7,WOODEN_SLAB:13)
B(-7,-2,-6,PLANKS:0)
B(-6,-2,-6,PLANKS:0)
B(-5,-2,-6,PLANKS:0)
B(-4,-2,-6,PLANKS:0)
B(-2,-2,-6,PLANKS:0)
B(-1,-2,-6,PLANKS:0)
B(-8,-2,-5,LEVER:13)
B(-7,-2,-5,BED:10)
B(-4,-2,-5,BED:10)
B(-3,-2,-5,LEVER:13)
RB(-1,-2,-5,CHEST:3,../NBT/StructureLoot/JunkChest_1.nbt,15,CHEST:3,../NBT/StructureLoot/JunkChest_2.nbt,15,CHEST:3,../NBT/StructureLoot/JunkChest_3.nbt,15,CHEST:3,../NBT/StructureLoot/JunkChest_4.nbt,15,CHEST:3,../NBT/StructureLoot/JunkChest_5.nbt,15,CHEST:3,../NBT/StructureLoot/Common1.nbt,15,CHEST:3,../NBT/StructureLoot/Common2.nbt,15,CHEST:3,../NBT/StructureLoot/Common3.nbt,15,CHEST:3,../NBT/StructureLoot/Common4.nbt,15,CHEST:3,../NBT/StructureLoot/Common5.nbt,15,CHEST:3,../NBT/StructureLoot/Common6.nbt,15,CHEST:3,../NBT/StructureLoot/Common7.nbt,15,CHEST:3,../NBT/StructureLoot/Common8.nbt,15,CHEST:3,../NBT/StructureLoot/Common9.nbt,15,CHEST:3,../NBT/StructureLoot/Common10.nbt,15,CHEST:3,../NBT/StructureLoot/Common11.nbt,15,CHEST:3,../NBT/StructureLoot/Common12.nbt,15,CHEST:3,../NBT/StructureLoot/Common13.nbt,15,CHEST:3,../NBT/StructureLoot/Common14.nbt,15,CHEST:3,../NBT/StructureLoot/Common15.nbt,100)
B(-7,-2,-4,BED:2)
B(-4,-2,-4,BED:2)
B(-7,-2,-3,SPRUCE_FENCE:0)
B(-4,-2,-3,SPRUCE_FENCE:0)
B(-6,-2,-2,AIR)
B(-4,-2,-1,WOODEN_BUTTON:5)
B(-3,-2,-1,WOODEN_BUTTON:5)
B(-8,-1,-6,PLANKS:0)
B(-7,-1,-6,PLANKS:0)
B(-6,-1,-6,PLANKS:0)
B(-5,-1,-6,PLANKS:0)
B(-4,-1,-6,PLANKS:0)
B(-3,-1,-6,PLANKS:0)
B(-2,-1,-6,PLANKS:0)
B(-1,-1,-6,PLANKS:0)
B(-8,-1,-5,WOODEN_SLAB:9)
B(-7,-1,-5,WOODEN_SLAB:9)
B(-6,-1,-5,WOODEN_SLAB:9)
B(-5,-1,-5,WOODEN_SLAB:9)
B(-4,-1,-5,WOODEN_SLAB:9)
B(-3,-1,-5,WOODEN_SLAB:9)
B(-2,-1,-5,WOODEN_SLAB:9)
B(-1,-1,-5,WOODEN_SLAB:9)
B(-8,-1,-4,WOODEN_SLAB:9)
B(-7,-1,-4,WOODEN_SLAB:9)
B(-6,-1,-4,WOODEN_SLAB:9)
B(-5,-1,-4,WOODEN_SLAB:9)
B(-4,-1,-4,WOODEN_SLAB:9)
B(-3,-1,-4,WOODEN_SLAB:9)
B(-2,-1,-4,WOODEN_SLAB:9)
B(-1,-1,-4,WOODEN_SLAB:9)
B(-8,-1,-3,WOODEN_SLAB:9)
B(-7,-1,-3,DOUBLE_WOODEN_SLAB:1)
B(-6,-1,-3,WOODEN_SLAB:9)
B(-5,-1,-3,WOODEN_SLAB:9)
B(-4,-1,-3,DOUBLE_WOODEN_SLAB:1)
B(-3,-1,-3,WOODEN_SLAB:9)
B(-2,-1,-3,WOODEN_SLAB:9)
B(-1,-1,-3,WOODEN_SLAB:9)
B(-8,-1,-2,WOODEN_SLAB:9)
B(-7,-1,-2,WOODEN_SLAB:9)
B(-6,-1,-2,WOODEN_SLAB:9)
B(-5,-1,-2,WOODEN_SLAB:9)
B(-4,-1,-2,WOODEN_SLAB:9)
B(-3,-1,-2,WOODEN_SLAB:9)
B(-2,-1,-2,WOODEN_SLAB:9)
B(-1,-1,-2,WOODEN_SLAB:9)
B(-8,-1,-1,WOODEN_SLAB:9)
B(-7,-1,-1,WOODEN_SLAB:9)
B(-6,-1,-1,WOODEN_SLAB:9)
B(-5,-1,-1,WOODEN_SLAB:9)
B(-4,-1,-1,WOODEN_SLAB:9)
B(-3,-1,-1,WOODEN_SLAB:9)
B(-2,-1,-1,WOODEN_SLAB:9)
B(-1,-1,-1,WOODEN_SLAB:9)
B(-7,0,-7,TRAPDOOR:4)
B(-8,0,-6,PLANKS:1)
B(-7,0,-6,PLANKS:5)
B(-6,0,-6,PLANKS:0)
B(-5,0,-6,PLANKS:0)
B(-4,0,-6,PLANKS:0)
B(-3,0,-6,PLANKS:0)
B(-2,0,-6,PLANKS:0)
B(-8,0,-5,WOODEN_BUTTON:1)
B(-7,0,-5,BED:10)
B(-6,0,-5,PLANKS:0)
B(-5,0,-5,PLANKS:0)
B(-4,0,-5,PLANKS:0)
B(-3,0,-5,PLANKS:0)
B(-2,0,-5,PLANKS:0)
B(-1,0,-5,PLANKS:0)
B(-7,0,-4,BED:2)
B(-6,0,-4,PLANKS:0)
B(-5,0,-4,BED:10)
B(-4,0,-4,CARPET:13)
B(-3,0,-4,BED:10)
B(-2,0,-4,CARPET:12)
B(-1,0,-4,BED:10)
B(-8,0,-3,CARPET:13)
B(-7,0,-3,CARPET:13)
B(-6,0,-3,PLANKS:0)
B(-5,0,-3,BED:2)
B(-4,0,-3,CARPET:13)
B(-3,0,-3,BED:2)
B(-2,0,-3,CARPET:12)
B(-1,0,-3,BED:2)
B(-6,0,-2,PLANKS:0)
B(-5,0,-2,PLANKS:0)
B(-3,0,-2,PLANKS:0)
B(-2,0,-2,CARPET:13)
B(-1,0,-2,PLANKS:0)
B(-8,0,-1,CARPET:15)
B(-6,0,-1,PLANKS:0)
B(-5,0,-1,PLANKS:0)
B(-4,0,-1,WOODEN_DOOR:1)
B(-3,0,-1,PLANKS:0)
B(-2,0,-1,WOODEN_DOOR:1)
B(-1,0,-1,PLANKS:0)
B(-7,1,-7,TRAPDOOR:4)
B(-8,1,-6,PLANKS:1)
B(-7,1,-6,PLANKS:5)
B(-6,1,-6,PLANKS:0)
B(-5,1,-6,PLANKS:0)
B(-4,1,-6,PLANKS:0)
B(-3,1,-6,PLANKS:0)
B(-6,1,-5,PLANKS:0)
B(-5,1,-5,PLANKS:0)
B(-4,1,-5,PLANKS:0)
B(-3,1,-5,PLANKS:0)
B(-2,1,-5,PLANKS:0)
B(-1,1,-5,PLANKS:0)
B(-6,1,-4,PLANKS:0)
B(-5,1,-4,BED:10)
B(-3,1,-4,BED:10)
B(-1,1,-4,BED:10)
B(-6,1,-3,PLANKS:0)
B(-5,1,-3,BED:2)
B(-3,1,-3,BED:2)
B(-1,1,-3,BED:2)
B(-6,1,-2,PLANKS:0)
B(-5,1,-2,PLANKS:0)
B(-3,1,-2,PLANKS:0)
B(-1,1,-2,PLANKS:0)
B(-6,1,-1,PLANKS:0)
B(-5,1,-1,PLANKS:0)
B(-4,1,-1,WOODEN_DOOR:8)
B(-3,1,-1,PLANKS:0)
B(-2,1,-1,WOODEN_DOOR:8)
B(-1,1,-1,PLANKS:0)
B(-8,2,-6,WOODEN_BUTTON:4)
B(-7,2,-6,TRAPDOOR:4)
B(-6,2,-6,PLANKS:0)
B(-5,2,-6,PLANKS:0)
B(-4,2,-6,PLANKS:0)
B(-8,2,-5,PLANKS:1)
B(-7,2,-5,PLANKS:5)
B(-6,2,-5,PLANKS:0)
B(-5,2,-5,DOUBLE_WOODEN_SLAB:1)
B(-4,2,-5,DOUBLE_WOODEN_SLAB:1)
B(-3,2,-5,PLANKS:0)
B(-2,2,-5,PLANKS:0)
B(-1,2,-5,PLANKS:0)
B(-8,2,-4,WOODEN_SLAB:1)
B(-7,2,-4,PLANKS:5)
B(-6,2,-4,PLANKS:0)
B(-5,2,-4,WOODEN_SLAB:9)
B(-4,2,-4,WOODEN_SLAB:9)
B(-3,2,-4,WOODEN_SLAB:9)
B(-2,2,-4,WOODEN_SLAB:9)
B(-1,2,-4,WOODEN_SLAB:9)
B(-8,2,-3,WOODEN_SLAB:1)
B(-7,2,-3,SPRUCE_STAIRS:2)
B(-6,2,-3,PLANKS:0)
B(-5,2,-3,WOODEN_SLAB:9)
B(-4,2,-3,WOODEN_SLAB:9)
B(-3,2,-3,WOODEN_SLAB:9)
B(-2,2,-3,WOODEN_SLAB:9)
B(-1,2,-3,WOODEN_SLAB:9)
B(-8,2,-2,WOODEN_SLAB:9)
B(-7,2,-2,TRAPDOOR:10)
B(-6,2,-2,PLANKS:0)
B(-5,2,-2,DOUBLE_WOODEN_SLAB:1)
B(-4,2,-2,WOODEN_SLAB:9)
B(-3,2,-2,DOUBLE_WOODEN_SLAB:1)
B(-2,2,-2,WOODEN_SLAB:9)
B(-1,2,-2,DOUBLE_WOODEN_SLAB:1)
B(-8,2,-1,WOODEN_SLAB:9)
B(-7,2,-1,TRAPDOOR:10)
B(-6,2,-1,PLANKS:0)
B(-5,2,-1,DOUBLE_WOODEN_SLAB:1)
B(-4,2,-1,DOUBLE_WOODEN_SLAB:1)
B(-3,2,-1,DOUBLE_WOODEN_SLAB:1)
B(-2,2,-1,DOUBLE_WOODEN_SLAB:1)
B(-1,2,-1,DOUBLE_WOODEN_SLAB:1)
B(-2,3,-7,FENCE:0)
B(-1,3,-7,FENCE:0)
B(-7,3,-6,WOODEN_SLAB:13)
B(-6,3,-6,DARK_OAK_STAIRS:6)
B(-5,3,-6,WOODEN_SLAB:13)
B(-4,3,-6,DARK_OAK_STAIRS:6)
B(-3,3,-6,WOODEN_SLAB:13)
B(-1,3,-6,FENCE:0)
B(-8,3,-5,WOODEN_SLAB:5)
B(-7,3,-5,WOODEN_SLAB:5)
B(-6,3,-5,PLANKS:5)
B(-5,3,-5,PLANKS:1)
B(-4,3,-5,PLANKS:1)
B(-3,3,-5,PLANKS:1)
B(-2,3,-5,PLANKS:1)
B(-1,3,-5,PLANKS:1)
B(-6,3,-4,PLANKS:1)
B(-5,3,-4,WOODEN_SLAB:1)
B(-4,3,-4,WOODEN_SLAB:1)
B(-3,3,-4,COAL_ORE:0)
B(-2,3,-4,COAL_ORE:0)
B(-1,3,-4,COAL_ORE:0)
B(-6,3,-3,PLANKS:1)
B(-5,3,-3,PLANKS:2)
B(-4,3,-3,PLANKS:2)
B(-3,3,-3,PLANKS:2)
B(-2,3,-3,PLANKS:2)
B(-1,3,-3,PLANKS:2)
B(-8,3,-2,SPRUCE_FENCE:0)
B(-6,3,-2,PLANKS:5)
B(-5,3,-2,PLANKS:2)
B(-4,3,-2,PLANKS:2)
B(-3,3,-2,PLANKS:2)
B(-2,3,-2,WOODEN_SLAB:1)
B(-1,3,-2,WOODEN_SLAB:1)
RB(-8,3,-1,CHEST:3,../NBT/StructureLoot/JunkChest_1.nbt,15,CHEST:3,../NBT/StructureLoot/JunkChest_2.nbt,15,CHEST:3,../NBT/StructureLoot/JunkChest_3.nbt,15,CHEST:3,../NBT/StructureLoot/JunkChest_4.nbt,15,CHEST:3,../NBT/StructureLoot/JunkChest_5.nbt,15,CHEST:3,../NBT/StructureLoot/Common1.nbt,15,CHEST:3,../NBT/StructureLoot/Common2.nbt,15,CHEST:3,../NBT/StructureLoot/Common3.nbt,15,CHEST:3,../NBT/StructureLoot/Common4.nbt,15,CHEST:3,../NBT/StructureLoot/Common5.nbt,15,CHEST:3,../NBT/StructureLoot/Common6.nbt,15,CHEST:3,../NBT/StructureLoot/Common7.nbt,15,CHEST:3,../NBT/StructureLoot/Common8.nbt,15,CHEST:3,../NBT/StructureLoot/Common9.nbt,15,CHEST:3,../NBT/StructureLoot/Common10.nbt,15,CHEST:3,../NBT/StructureLoot/Common11.nbt,15,CHEST:3,../NBT/StructureLoot/Common12.nbt,15,CHEST:3,../NBT/StructureLoot/Common13.nbt,15,CHEST:3,../NBT/StructureLoot/Common14.nbt,15,CHEST:3,../NBT/StructureLoot/Common15.nbt,100)
B(-6,3,-1,PLANKS:1)
B(-5,3,-1,STONE_BUTTON:3)
B(-4,3,-1,STONE_BUTTON:3)
B(-3,3,-1,STONE_BUTTON:3)
B(-2,4,-8,FENCE:0)
B(-2,4,-7,FENCE:0)
B(-7,4,-6,FENCE:0)
B(-6,4,-6,FENCE:0)
B(-5,4,-6,FENCE:0)
B(-4,4,-6,FENCE:0)
B(-3,4,-6,FENCE:0)
B(-6,4,-5,PLANKS:5)
B(-5,4,-5,WOODEN_SLAB:1)
B(-4,4,-5,PLANKS:1)
B(-3,4,-5,WOODEN_SLAB:1)
B(-2,4,-5,PLANKS:1)
B(-1,4,-5,WOODEN_SLAB:1)
B(-6,4,-4,PLANKS:1)
B(-4,4,-4,STONE_BUTTON:4)
B(-3,4,-4,STONE_BUTTON:4)
B(-2,4,-4,CONCRETE:15)
B(-6,4,-3,PLANKS:1)
B(-5,4,-3,STONE_BUTTON:5)
B(-4,4,-3,PLANKS:2)
B(-3,4,-3,PLANKS:2)
B(-2,4,-3,STONE_BUTTON:5)
B(-1,4,-3,STONE_BUTTON:5)
B(-6,4,-2,PLANKS:5)
B(-5,4,-2,STONE_BUTTON:5)
B(-4,4,-2,STONE_BUTTON:5)
B(-3,4,-2,STONE_BUTTON:5)
B(-6,4,-1,PLANKS:1)
B(-1,4,-1,STONE_BUTTON:4)
B(-7,5,-6,FENCE:0)
B(-6,5,-6,FENCE:0)
B(-5,5,-6,FENCE:0)
B(-4,5,-6,FENCE:0)
B(-3,5,-6,FENCE:0)
B(-6,5,-5,PLANKS:5)
B(-5,5,-5,PLANKS:1)
B(-4,5,-5,PLANKS:1)
B(-3,5,-5,PLANKS:1)
B(-2,5,-5,PLANKS:1)
B(-1,5,-5,PLANKS:1)
B(-6,5,-4,PLANKS:1)
RB(-2,5,-4,CHEST:3,../NBT/StructureLoot/JunkChest_1.nbt,15,CHEST:3,../NBT/StructureLoot/JunkChest_2.nbt,15,CHEST:3,../NBT/StructureLoot/JunkChest_3.nbt,15,CHEST:3,../NBT/StructureLoot/JunkChest_4.nbt,15,CHEST:3,../NBT/StructureLoot/JunkChest_5.nbt,15,CHEST:3,../NBT/StructureLoot/Common1.nbt,15,CHEST:3,../NBT/StructureLoot/Common2.nbt,15,CHEST:3,../NBT/StructureLoot/Common3.nbt,15,CHEST:3,../NBT/StructureLoot/Common4.nbt,15,CHEST:3,../NBT/StructureLoot/Common5.nbt,15,CHEST:3,../NBT/StructureLoot/Common6.nbt,15,CHEST:3,../NBT/StructureLoot/Common7.nbt,15,CHEST:3,../NBT/StructureLoot/Common8.nbt,15,CHEST:3,../NBT/StructureLoot/Common9.nbt,15,CHEST:3,../NBT/StructureLoot/Common10.nbt,15,CHEST:3,../NBT/StructureLoot/Common11.nbt,15,CHEST:3,../NBT/StructureLoot/Common12.nbt,15,CHEST:3,../NBT/StructureLoot/Common13.nbt,15,CHEST:3,../NBT/StructureLoot/Common14.nbt,15,CHEST:3,../NBT/StructureLoot/Common15.nbt,100)
B(-6,5,-3,PLANKS:1)
B(-4,5,-3,STONE_BUTTON:5)
B(-3,5,-3,STONE_BUTTON:5)
B(-6,5,-2,PLANKS:5)
B(-6,5,-1,PLANKS:1)
B(-1,5,-1,STONE_BUTTON:4)
B(-7,6,-8,WOOL:0)
B(-8,6,-7,WOOL:0)
B(-7,6,-7,WOOL:0)
B(-8,6,-6,WOOL:15)
B(-7,6,-6,WOOL:0)
B(-6,6,-6,FENCE:0)
B(-5,6,-6,FENCE:0)
B(-4,6,-6,FENCE:0)
B(-3,6,-6,FENCE:0)
B(-8,6,-5,WOOL:15)
B(-6,6,-5,WOODEN_SLAB:5)
B(-5,6,-5,WOODEN_SLAB:5)
B(-4,6,-5,WOODEN_SLAB:5)
B(-3,6,-5,WOODEN_SLAB:5)
B(-2,6,-5,WOODEN_SLAB:5)
B(-1,6,-5,WOODEN_SLAB:5)
B(-6,6,-4,WOODEN_SLAB:5)
B(-6,6,-3,WOODEN_SLAB:5)
B(-6,6,-2,WOODEN_SLAB:5)
B(-6,6,-1,WOODEN_SLAB:5)
B(-8,7,-8,WOOL:0)
B(-8,7,-7,WOOL:0)
B(-7,7,-6,FENCE:0)
B(-6,7,-6,FENCE:0)
B(-5,7,-6,FENCE:0)
B(-4,7,-6,FENCE:0)
B(-3,7,-6,FENCE:0)
B(-7,7,-5,FENCE:0)
B(-6,7,-5,FENCE:0)
B(-5,7,-5,FENCE:0)
B(-4,7,-5,FENCE:0)
B(-3,7,-5,FENCE:0)
B(-7,8,-5,FENCE:0)
B(-6,8,-5,FENCE:0)
B(-5,8,-5,FENCE:0)
B(-4,8,-5,FENCE:0)
B(-3,8,-5,FENCE:0)
B(-8,9,-5,FENCE:0)
B(-7,9,-5,FENCE:0)
B(-6,9,-5,FENCE:0)
B(-5,9,-5,FENCE:0)
B(-4,9,-5,FENCE:0)
B(-3,9,-5,FENCE:0)
B(-8,10,-5,FENCE:0)
B(-7,10,-5,FENCE:0)
B(-6,10,-5,FENCE:0)
B(-5,10,-5,FENCE:0)
B(-4,10,-5,FENCE:0)
B(-3,10,-5,FENCE:0)
B(-8,10,-4,FENCE:0)
B(-7,10,-4,FENCE:0)
B(-6,10,-4,FENCE:0)
B(-5,10,-4,FENCE:0)
B(-4,10,-4,FENCE:0)
B(-8,11,-4,FENCE:0)
B(-7,11,-4,FENCE:0)
B(-6,11,-4,FENCE:0)
B(-5,11,-4,FENCE:0)
B(-8,12,-4,FENCE:0)
B(-7,12,-4,FENCE:0)
B(-6,12,-4,FENCE:0)
B(-5,12,-4,FENCE:0)
B(-3,12,-2,WOOL:15)
B(-2,12,-2,WOOL:15)
B(-3,12,-1,PLANKS:1)
B(-2,12,-1,FENCE:0)
B(-1,12,-1,WOOL:15)
B(-8,13,-4,FENCE:0)
B(-7,13,-4,FENCE:0)
B(-6,13,-4,FENCE:0)
B(-5,13,-4,FENCE:0)
B(-8,13,-3,FENCE:0)
B(-7,13,-3,FENCE:0)
B(-6,13,-3,FENCE:0)
B(-5,13,-3,FENCE:0)
B(-2,13,-2,WOOL:0)
B(-3,13,-1,WOODEN_SLAB:1)
B(-2,13,-1,PLANKS:1)
B(-1,13,-1,WOOL:0)
B(-8,14,-3,FENCE:0)
B(-7,14,-3,FENCE:0)
B(-6,14,-3,FENCE:0)
B(-1,14,-2,WOOL:0)
B(-2,14,-1,WOODEN_SLAB:1)
B(-1,14,-1,PLANKS:1)
B(-8,15,-3,FENCE:0)
B(-7,15,-3,FENCE:0)
B(-6,15,-3,FENCE:0)
B(-1,15,-1,WOODEN_SLAB:1)
B(-8,16,-3,FENCE:0)
B(-7,16,-3,FENCE:0)
B(-6,16,-3,FENCE:0)
B(-8,16,-2,FENCE:0)
B(-7,16,-2,FENCE:0)
B(-6,16,-2,FENCE:0)
B(-8,17,-2,FENCE:0)
B(-7,17,-2,FENCE:0)
B(-6,17,-2,FENCE:0)
B(-8,18,-8,WOOL:0)
B(-8,18,-2,FENCE:0)
B(-7,18,-2,FENCE:0)
B(-8,18,-1,FENCE:0)
B(-7,18,-1,FENCE:0)
B(-8,19,-8,WOOL:0)
B(-8,19,-7,WOOL:0)
B(-8,19,-1,FENCE:0)
B(-7,19,-1,FENCE:0)
B(-7,20,-8,WOOL:15)
B(-6,20,-8,FENCE:0)
B(-7,20,-7,WOOL:0)
B(-6,20,-7,FENCE:0)
B(-8,20,-6,WOOL:15)
B(-7,20,-6,FENCE:0)
B(-8,20,-5,WOOL:0)
B(-7,20,-5,FENCE:0)
B(-8,20,-4,WOOL:15)
B(-7,20,-4,FENCE:0)
B(-7,21,-8,FENCE:0)
B(-6,21,-8,LOG:9)
B(-7,21,-7,FENCE:0)
B(-6,21,-7,LOG:9)
B(-8,21,-6,FENCE:0)
B(-7,21,-6,LOG:9)
B(-8,21,-5,FENCE:0)
B(-7,21,-5,LOG:9)
B(-8,21,-4,FENCE:0)
B(-7,21,-4,LOG:9)
B(-8,21,-3,LOG:9)
B(-8,21,-2,LOG:9)
B(-2,21,-2,WOOL:0)
B(-1,21,-2,WOOL:0)
B(-8,21,-1,LOG:9)
B(-2,21,-1,PLANKS:1)
B(-1,21,-1,FENCE:0)
B(-6,22,-8,WOOL:0)
B(-7,22,-7,WOOL:15)
B(-8,22,-6,WOOL:15)
B(-8,22,-5,WOOL:0)
B(-1,22,-2,WOOL:0)
B(-2,22,-1,WOODEN_SLAB:1)
B(-1,22,-1,PLANKS:1)
B(-6,23,-8,WOOL:0)
B(-7,23,-7,WOOL:0)
B(-8,23,-6,WOOL:0)
B(-1,23,-1,WOODEN_SLAB:1)
B(-7,24,-7,WOOL:15)
B(-8,24,-6,WOOL:0)
B(-8,29,-7,WOOL:15)
B(-7,30,-8,WOOL:15)
B(-7,30,-7,WOOL:15)
B(-8,30,-6,WOOL:15)
B(-7,30,-6,FENCE:0)
B(-8,30,-5,WOOL:0)
B(-7,30,-5,FENCE:0)
B(-8,30,-4,WOOL:0)
B(-7,30,-4,FENCE:0)
B(-8,30,-3,WOOL:0)
B(-8,30,-2,FENCE:0)
B(-8,30,-1,FENCE:0)
B(-6,31,-8,WOOL:15)
B(-7,31,-7,WOOL:15)
B(-8,31,-6,FENCE:0)
B(-7,31,-6,LOG:9)
B(-8,31,-5,FENCE:0)
B(-7,31,-5,LOG:9)
B(-8,31,-4,FENCE:0)
B(-7,31,-4,LOG:9)
B(-8,31,-3,LOG:9)
B(-8,31,-2,LOG:9)
B(-8,31,-1,LOG:9)
B(-6,32,-8,WOOL:15)
B(-5,32,-8,WOOL:0)

E(-6,-2,-2,VILLAGER,1,../NBT/MOBS/RandomVillager.txt)

BR(-8,0,0,WestPortShipFat_6x3,NORTH,100)
