Author: Bo3 BulkEdit

Description: Converted Schematic - Modified by Bo3BulkEdit

Version: 3

SettingsMode: WriteDisable

IsOTGPlus: false
Tree: false
Frequency: 1
Rarity: 100
RotateRandomly: false
SpawnHeight: randomY
MaxBranchDepth: 20
ExcludedBiomes: All

MinHeight: 0
MaxHeight: 256

SourceBlocks: AIR
MaxPercentageOutsideSourceBlock: 100
OutsideSourceBlock: placeAnyway

B(-8,-9,-7,LOG:12)
B(-7,-9,-7,LOG:12)
B(-6,-9,-7,LOG:12)
B(-5,-9,-7,LOG:12)
B(-4,-9,-7,DARK_OAK_FENCE:0)
B(-3,-9,-7,PLANKS:0)
B(-2,-9,-7,OAK_STAIRS:5)
B(-8,-8,-7,LOG:12)
B(-7,-8,-7,LOG:12)
B(-6,-8,-7,LOG:12)
B(-5,-8,-7,LOG:12)
B(-4,-8,-7,DARK_OAK_FENCE:0)
B(-3,-8,-7,DARK_OAK_FENCE:0)
B(-2,-8,-7,PLANKS:0)
B(-8,-7,-8,LOG:12)
B(-7,-7,-8,LOG:12)
B(-6,-7,-8,LOG:12)
B(-8,-7,-7,LOG:12)
B(-7,-7,-7,LOG:12)
B(-6,-7,-7,LOG:12)
B(-5,-7,-7,LOG:12)
B(-4,-7,-7,DARK_OAK_FENCE:0)
B(-3,-7,-7,PLANKS:0)
B(-2,-7,-7,PLANKS:0)
B(-8,-7,-6,LOG:12)
B(-7,-7,-6,LOG:12)
B(-6,-7,-6,LOG:12)
B(-8,-6,-8,OAK_STAIRS:3)
B(-7,-6,-8,OAK_STAIRS:3)
B(-6,-6,-8,LOG:12)
B(-5,-6,-8,LOG:12)
B(-4,-6,-8,LOG:12)
B(-8,-6,-7,CARPET:12)
B(-7,-6,-7,CARPET:12)
B(-6,-6,-7,OAK_STAIRS:0)
B(-5,-6,-7,LOG:12)
B(-4,-6,-7,LOG:12)
B(-3,-6,-7,DARK_OAK_FENCE:0)
B(-2,-6,-7,PLANKS:0)
B(-1,-6,-7,OAK_STAIRS:5)
B(-8,-6,-6,OAK_STAIRS:2)
B(-7,-6,-6,OAK_STAIRS:2)
B(-6,-6,-6,LOG:12)
B(-5,-6,-6,LOG:12)
B(-4,-6,-6,LOG:12)
B(-8,-6,-5,LOG:12)
B(-7,-6,-5,LOG:12)
B(-8,-5,-8,AIR:0)
B(-7,-5,-8,AIR:0)
B(-6,-5,-8,OAK_STAIRS:3)
B(-5,-5,-8,DARK_OAK_FENCE:0)
B(-4,-5,-8,LOG:12)
B(-8,-5,-7,AIR:0)
B(-7,-5,-7,AIR:0)
B(-6,-5,-7,AIR:0)
B(-5,-5,-7,LADDER:4)
B(-4,-5,-7,LOG:12)
B(-3,-5,-7,DARK_OAK_FENCE:0)
B(-2,-5,-7,PLANKS:0)
B(-1,-5,-7,PLANKS:0)
B(-8,-5,-6,AIR:0)
B(-7,-5,-6,AIR:0)
B(-6,-5,-6,OAK_STAIRS:2)
B(-5,-5,-6,DARK_OAK_FENCE:0)
B(-4,-5,-6,LOG:12)
B(-8,-5,-5,OAK_STAIRS:2)
B(-7,-5,-5,OAK_STAIRS:2)
B(-6,-5,-5,LOG:12)
B(-5,-5,-5,LOG:12)
B(-8,-5,-4,LOG:12)
B(-7,-5,-4,LOG:12)
B(-5,-4,-8,DARK_OAK_FENCE:0)
B(-4,-4,-8,PLANKS:0)
B(-5,-4,-7,LADDER:4)
B(-4,-4,-7,PLANKS:0)
B(-3,-4,-7,DARK_OAK_FENCE:0)
B(-2,-4,-7,PLANKS:0)
B(-1,-4,-7,PLANKS:0)
B(-5,-4,-6,DARK_OAK_FENCE:0)
B(-4,-4,-6,PLANKS:0)
B(-6,-4,-5,OAK_STAIRS:2)
B(-5,-4,-5,DARK_OAK_FENCE:0)
B(-4,-4,-5,PLANKS:0)
B(-8,-4,-4,OAK_STAIRS:2)
B(-7,-4,-4,LOG:12)
B(-6,-4,-4,LOG:12)
B(-5,-4,-4,LOG:12)
B(-8,-4,-3,LOG:12)
B(-8,-3,-8,WOODEN_SLAB:9)
B(-7,-3,-8,WOODEN_SLAB:9)
B(-6,-3,-8,WOODEN_SLAB:9)
B(-5,-3,-8,DARK_OAK_FENCE:0)
B(-4,-3,-8,DARK_OAK_FENCE:0)
B(-3,-3,-8,LOG:12)
B(-8,-3,-7,WOODEN_SLAB:9)
B(-7,-3,-7,WOODEN_SLAB:9)
B(-6,-3,-7,WOODEN_SLAB:9)
B(-5,-3,-7,LADDER:4)
B(-4,-3,-7,LOG:1)
B(-3,-3,-7,LOG:12)
B(-2,-3,-7,DARK_OAK_FENCE:0)
B(-1,-3,-7,OAK_STAIRS:1)
B(-8,-3,-6,WOODEN_SLAB:9)
B(-7,-3,-6,WOODEN_SLAB:9)
B(-6,-3,-6,WOODEN_SLAB:9)
B(-5,-3,-6,DARK_OAK_FENCE:0)
B(-4,-3,-6,DARK_OAK_FENCE:0)
B(-3,-3,-6,LOG:12)
B(-8,-3,-5,WOODEN_SLAB:9)
B(-7,-3,-5,WOODEN_SLAB:9)
B(-6,-3,-5,WOODEN_SLAB:9)
B(-5,-3,-5,DARK_OAK_FENCE:0)
B(-4,-3,-5,DARK_OAK_FENCE:0)
B(-3,-3,-5,LOG:12)
B(-8,-3,-4,WOODEN_SLAB:9)
B(-7,-3,-4,DOUBLE_WOODEN_SLAB:1)
B(-6,-3,-4,LOG:12)
B(-5,-3,-4,LOG:12)
B(-4,-3,-4,LOG:12)
B(-8,-3,-3,LOG:12)
B(-7,-3,-3,LOG:12)
B(-8,-2,-8,WOODEN_SLAB:1)
B(-7,-2,-8,WOODEN_SLAB:1)
B(-6,-2,-8,DOUBLE_WOODEN_SLAB:1)
B(-5,-2,-8,DOUBLE_WOODEN_SLAB:1)
B(-4,-2,-8,DOUBLE_WOODEN_SLAB:1)
B(-3,-2,-8,LOG:12)
B(-8,-2,-7,WOODEN_SLAB:1)
B(-7,-2,-7,WOODEN_SLAB:1)
B(-6,-2,-7,DOUBLE_WOODEN_SLAB:1)
B(-5,-2,-7,LADDER:4)
B(-4,-2,-7,LOG:1)
B(-3,-2,-7,LOG:12)
B(-8,-2,-6,WOODEN_SLAB:1)
B(-7,-2,-6,WOODEN_SLAB:1)
B(-6,-2,-6,DOUBLE_WOODEN_SLAB:1)
B(-5,-2,-6,DOUBLE_WOODEN_SLAB:1)
B(-4,-2,-6,DOUBLE_WOODEN_SLAB:1)
B(-3,-2,-6,LOG:12)
B(-8,-2,-5,WOODEN_SLAB:1)
B(-7,-2,-5,WOODEN_SLAB:1)
B(-6,-2,-5,DOUBLE_WOODEN_SLAB:1)
B(-5,-2,-5,DOUBLE_WOODEN_SLAB:1)
B(-4,-2,-5,DOUBLE_WOODEN_SLAB:1)
B(-3,-2,-5,LOG:12)
B(-8,-2,-4,DOUBLE_WOODEN_SLAB:1)
B(-7,-2,-4,DOUBLE_WOODEN_SLAB:1)
B(-6,-2,-4,DOUBLE_WOODEN_SLAB:1)
B(-5,-2,-4,LOG:12)
B(-4,-2,-4,LOG:12)
B(-3,-2,-4,LOG:12)
B(-8,-2,-3,LOG:12)
B(-7,-2,-3,LOG:12)
B(-6,-2,-3,LOG:12)
B(-5,-1,-8,OAK_STAIRS:0)
B(-4,-1,-8,DISPENSER:1)
B(-3,-1,-8,CONCRETE:15)
B(-2,-1,-8,DISPENSER:5)
B(-5,-1,-7,LADDER:4)
B(-4,-1,-7,LOG:1)
B(-3,-1,-7,LOG:12)
B(-5,-1,-6,OAK_STAIRS:0)
B(-4,-1,-6,DISPENSER:1)
B(-3,-1,-6,CONCRETE:15)
B(-2,-1,-6,DISPENSER:5)
B(-8,-1,-5,TRAPDOOR:12)
B(-4,-1,-5,WOODEN_BUTTON:3)
B(-3,-1,-5,LOG:12)
B(-8,-1,-4,LIT_REDSTONE_LAMP:0)
B(-7,-1,-4,PLANKS:0)
B(-6,-1,-4,PLANKS:0)
B(-5,-1,-4,LOG:12)
B(-4,-1,-4,LOG:12)
B(-3,-1,-4,LOG:12)
B(-8,-1,-3,REDSTONE_BLOCK:0)
B(-7,-1,-3,PLANKS:0)
B(-6,-1,-3,PLANKS:0)
B(-8,-1,-2,PLANKS:0)
B(-4,0,-8,LEVER:6)
B(-3,0,-8,WOODEN_SLAB:13)
B(-2,0,-8,WOODEN_SLAB:13)
B(-5,0,-7,LADDER:4)
B(-4,0,-7,LOG:1)
B(-3,0,-7,LOG:12)
B(-4,0,-6,LEVER:6)
B(-3,0,-6,WOODEN_SLAB:13)
B(-2,0,-6,WOODEN_SLAB:13)
B(-3,0,-5,LOG:12)
B(-8,0,-4,PLANKS:0)
B(-7,0,-4,PLANKS:0)
B(-6,0,-4,PLANKS:0)
B(-5,0,-4,PLANKS:0)
B(-4,0,-4,LOG:12)
B(-3,0,-4,LOG:12)
B(-8,0,-3,PLANKS:0)
B(-7,0,-3,PLANKS:0)
B(-6,0,-3,PLANKS:0)
B(-5,0,-3,PLANKS:0)
B(-8,1,-8,DOUBLE_WOODEN_SLAB:1)
B(-7,1,-8,DOUBLE_WOODEN_SLAB:1)
B(-6,1,-8,WOODEN_SLAB:9)
B(-5,1,-8,WOODEN_SLAB:9)
B(-4,1,-8,WOODEN_SLAB:9)
B(-3,1,-8,WOODEN_SLAB:9)
B(-2,1,-8,OAK_STAIRS:5)
B(-8,1,-7,DOUBLE_WOODEN_SLAB:1)
B(-7,1,-7,DOUBLE_WOODEN_SLAB:1)
B(-6,1,-7,WOODEN_SLAB:9)
B(-5,1,-7,LADDER:4)
B(-4,1,-7,LOG:1)
B(-3,1,-7,WOODEN_SLAB:9)
B(-2,1,-7,OAK_STAIRS:5)
B(-8,1,-6,DOUBLE_WOODEN_SLAB:1)
B(-7,1,-6,DOUBLE_WOODEN_SLAB:1)
B(-6,1,-6,WOODEN_SLAB:9)
B(-5,1,-6,WOODEN_SLAB:9)
B(-4,1,-6,WOODEN_SLAB:9)
B(-3,1,-6,WOODEN_SLAB:9)
B(-2,1,-6,OAK_STAIRS:5)
B(-8,1,-5,WOODEN_SLAB:1)
B(-7,1,-5,WOODEN_SLAB:1)
B(-6,1,-5,WOODEN_SLAB:9)
B(-5,1,-5,WOODEN_SLAB:9)
B(-4,1,-5,WOODEN_SLAB:9)
B(-3,1,-5,WOODEN_SLAB:9)
B(-2,1,-5,OAK_STAIRS:5)
B(-8,1,-4,WOODEN_SLAB:1)
B(-7,1,-4,WOODEN_SLAB:1)
B(-6,1,-4,DOUBLE_WOODEN_SLAB:1)
B(-5,1,-4,PLANKS:0)
B(-4,1,-4,PLANKS:0)
B(-3,1,-4,PLANKS:0)
B(-2,1,-4,OAK_STAIRS:5)
B(-8,1,-3,PLANKS:0)
B(-7,1,-3,PLANKS:0)
B(-6,1,-3,PLANKS:0)
B(-8,2,-8,PLANKS:0)
B(-7,2,-8,PLANKS:0)
B(-6,2,-8,CARPET:13)
B(-5,2,-8,CARPET:15)
B(-4,2,-8,OAK_STAIRS:0)
B(-3,2,-8,DISPENSER:1)
B(-2,2,-8,CONCRETE:15)
B(-1,2,-8,DISPENSER:5)
B(-8,2,-7,PLANKS:0)
B(-7,2,-7,PLANKS:0)
B(-6,2,-7,CARPET:13)
B(-5,2,-7,LADDER:4)
B(-4,2,-7,LOG:1)
B(-2,2,-7,PLANKS:0)
B(-8,2,-6,PLANKS:0)
B(-7,2,-6,PLANKS:0)
B(-5,2,-6,CARPET:15)
B(-4,2,-6,OAK_STAIRS:0)
B(-3,2,-6,DISPENSER:1)
B(-2,2,-6,CONCRETE:15)
B(-1,2,-6,DISPENSER:5)
B(-5,2,-5,CARPET:13)
B(-3,2,-5,WOODEN_BUTTON:3)
B(-2,2,-5,PLANKS:0)
B(-6,2,-4,PLANKS:0)
B(-5,2,-4,PLANKS:0)
B(-4,2,-4,PLANKS:0)
B(-3,2,-4,PLANKS:0)
B(-2,2,-4,PLANKS:0)
B(-8,2,-3,PLANKS:0)
B(-7,2,-3,PLANKS:0)
B(-6,2,-3,PLANKS:0)
B(-8,3,-8,PLANKS:0)
B(-7,3,-8,PLANKS:0)
B(-3,3,-8,LEVER:6)
B(-2,3,-8,WOODEN_SLAB:13)
B(-1,3,-8,WOODEN_SLAB:13)
B(-8,3,-7,PLANKS:0)
B(-7,3,-7,PLANKS:0)
B(-5,3,-7,LADDER:4)
B(-4,3,-7,LOG:1)
B(-2,3,-7,PLANKS:0)
B(-8,3,-6,PLANKS:0)
B(-7,3,-6,PLANKS:0)
B(-6,3,-6,AIR)
B(-3,3,-6,LEVER:6)
B(-2,3,-6,WOODEN_SLAB:13)
B(-1,3,-6,WOODEN_SLAB:13)
B(-2,3,-5,PLANKS:0)
B(-6,3,-4,PLANKS:0)
B(-5,3,-4,PLANKS:0)
B(-4,3,-4,PLANKS:0)
B(-3,3,-4,PLANKS:0)
B(-8,3,-3,PLANKS:0)
B(-7,3,-3,PLANKS:0)
B(-8,4,-8,DOUBLE_WOODEN_SLAB:1)
B(-7,4,-8,DOUBLE_WOODEN_SLAB:1)
B(-6,4,-8,WOODEN_SLAB:9)
B(-5,4,-8,WOODEN_SLAB:9)
B(-4,4,-8,WOODEN_SLAB:9)
B(-3,4,-8,WOODEN_SLAB:9)
B(-2,4,-8,WOODEN_SLAB:9)
B(-1,4,-8,OAK_STAIRS:5)
B(-8,4,-7,WOODEN_SLAB:1)
B(-7,4,-7,DOUBLE_WOODEN_SLAB:1)
B(-6,4,-7,WOODEN_SLAB:9)
B(-5,4,-7,WOODEN_SLAB:9)
B(-4,4,-7,LOG:1)
B(-3,4,-7,WOODEN_SLAB:9)
B(-2,4,-7,WOODEN_SLAB:9)
B(-1,4,-7,DOUBLE_WOODEN_SLAB:0)
B(-8,4,-6,DOUBLE_WOODEN_SLAB:1)
B(-7,4,-6,DOUBLE_WOODEN_SLAB:1)
B(-6,4,-6,WOODEN_SLAB:9)
B(-5,4,-6,WOODEN_SLAB:9)
B(-4,4,-6,WOODEN_SLAB:9)
B(-3,4,-6,WOODEN_SLAB:9)
B(-2,4,-6,WOODEN_SLAB:9)
B(-1,4,-6,OAK_STAIRS:5)
B(-8,4,-5,DOUBLE_WOODEN_SLAB:1)
B(-7,4,-5,DOUBLE_WOODEN_SLAB:1)
B(-6,4,-5,WOODEN_SLAB:9)
B(-5,4,-5,WOODEN_SLAB:9)
B(-4,4,-5,WOODEN_SLAB:9)
B(-3,4,-5,PLANKS:0)
B(-2,4,-5,PLANKS:0)
B(-1,4,-5,OAK_STAIRS:5)
B(-8,4,-4,DOUBLE_WOODEN_SLAB:1)
B(-7,4,-4,DOUBLE_WOODEN_SLAB:1)
B(-6,4,-4,PLANKS:0)
B(-5,4,-4,PLANKS:0)
B(-4,4,-4,PLANKS:0)
B(-8,4,-3,PLANKS:1)
B(-7,4,-3,PLANKS:5)
B(-7,4,-2,TRAPDOOR:5)
B(-8,5,-8,CARPET:14)
B(-7,5,-8,CARPET:14)
B(-6,5,-8,BIRCH_STAIRS:2)
B(-5,5,-8,CARPET:14)
B(-4,5,-8,CARPET:14)
B(-3,5,-8,CARPET:14)
B(-2,5,-8,PLANKS:0)
B(-1,5,-8,PLANKS:1)
B(-7,5,-7,CARPET:14)
B(-6,5,-7,CARPET:14)
B(-5,5,-7,CARPET:14)
B(-4,5,-7,LOG:1)
B(-3,5,-7,CARPET:14)
B(-2,5,-7,CARPET:14)
B(-1,5,-7,DARK_OAK_DOOR:2)
B(-8,5,-6,CARPET:14)
B(-7,5,-6,BED:0)
B(-6,5,-6,BED:0)
B(-5,5,-6,CARPET:14)
B(-4,5,-6,CRAFTING_TABLE:0)
B(-3,5,-6,CARPET:14)
B(-2,5,-6,CARPET:14)
B(-1,5,-6,PLANKS:1)
B(-8,5,-5,CARPET:14)
B(-7,5,-5,BED:8)
B(-6,5,-5,BED:8)
B(-5,5,-5,DOUBLE_WOODEN_SLAB:1)
B(-4,5,-5,PLANKS:1)
B(-3,5,-5,PLANKS:1)
B(-2,5,-5,PLANKS:1)
B(-1,5,-5,PLANKS:1)
B(-8,5,-4,CARPET:14)
B(-7,5,-4,PLANKS:1)
B(-6,5,-4,PLANKS:1)
B(-5,5,-4,PLANKS:1)
B(-4,5,-4,PLANKS:5)
B(-8,5,-3,PLANKS:5)
B(-4,5,-3,TRAPDOOR:5)
B(-8,5,-2,TRAPDOOR:5)
B(-2,6,-8,WOODEN_BUTTON:5)
B(-1,6,-8,PLANKS:1)
B(-7,6,-7,AIR)
B(-4,6,-7,LOG:1)
B(-1,6,-7,DARK_OAK_DOOR:9)
RB(-4,6,-6,FLOWER_POT:0,../NBT/Flowers/flower_pot_01.nbt,5,FLOWER_POT:0,../NBT/Flowers/flower_pot_02.nbt,5,FLOWER_POT:0,../NBT/Flowers/flower_pot_03.nbt,5,FLOWER_POT:0,../NBT/Flowers/flower_pot_04.nbt,5,FLOWER_POT:0,../NBT/Flowers/flower_pot_05.nbt,5,FLOWER_POT:0,../NBT/Flowers/flower_pot_06.nbt,5,FLOWER_POT:0,../NBT/Flowers/flower_pot_07.nbt,5,FLOWER_POT:0,../NBT/Flowers/flower_pot_08.nbt,5,FLOWER_POT:0,../NBT/Flowers/flower_pot_09.nbt,5,FLOWER_POT:0,../NBT/Flowers/flower_pot_10.nbt,5,FLOWER_POT:0,../NBT/Flowers/flower_pot_11.nbt,5,FLOWER_POT:0,../NBT/Flowers/flower_pot_12.nbt,5,FLOWER_POT:0,../NBT/Flowers/flower_pot_13.nbt,5,FLOWER_POT:0,../NBT/Flowers/flower_pot_14.nbt,5,FLOWER_POT:0,../NBT/Flowers/flower_pot_15.nbt,5,FLOWER_POT:0,../NBT/Flowers/flower_pot_16.nbt,5,FLOWER_POT:0,../NBT/Flowers/flower_pot_17.nbt,5,FLOWER_POT:0,../NBT/Flowers/flower_pot_18.nbt,5,FLOWER_POT:0,../NBT/Flowers/flower_pot_19.nbt,5,FLOWER_POT:0,../NBT/Flowers/flower_pot_20.nbt,100)
B(-1,6,-6,PLANKS:1)
B(-5,6,-5,DOUBLE_WOODEN_SLAB:1)
B(-4,6,-5,PLANKS:1)
B(-2,6,-5,PLANKS:1)
B(-1,6,-5,PLANKS:1)
B(-7,6,-4,PLANKS:1)
B(-6,6,-4,WOODEN_SLAB:9)
B(-5,6,-4,PLANKS:5)
B(-4,6,-4,DARK_OAK_STAIRS:7)
B(-3,6,-4,WOODEN_SLAB:13)
B(-2,6,-4,DARK_OAK_STAIRS:7)
B(-8,6,-3,PLANKS:5)
B(-5,6,-3,TRAPDOOR:5)
B(-8,6,-2,TRAPDOOR:5)
B(-8,7,-8,WOODEN_SLAB:1)
B(-7,7,-8,WOODEN_SLAB:1)
B(-6,7,-8,WOODEN_SLAB:1)
B(-5,7,-8,WOODEN_SLAB:1)
B(-4,7,-8,WOODEN_SLAB:1)
B(-3,7,-8,WOODEN_SLAB:1)
B(-2,7,-8,WOODEN_SLAB:1)
B(-1,7,-8,PLANKS:1)
B(-8,7,-7,WOODEN_SLAB:1)
B(-7,7,-7,WOODEN_SLAB:1)
B(-6,7,-7,WOODEN_SLAB:1)
B(-5,7,-7,WOODEN_SLAB:1)
B(-4,7,-7,LOG:1)
B(-3,7,-7,WOODEN_SLAB:1)
B(-2,7,-7,WOODEN_SLAB:1)
B(-1,7,-7,DOUBLE_WOODEN_SLAB:1)
B(-8,7,-6,WOODEN_SLAB:1)
B(-7,7,-6,WOODEN_SLAB:1)
B(-6,7,-6,WOODEN_SLAB:1)
B(-5,7,-6,WOODEN_SLAB:1)
B(-4,7,-6,WOODEN_SLAB:1)
B(-3,7,-6,WOODEN_SLAB:1)
B(-2,7,-6,WOODEN_SLAB:1)
B(-1,7,-6,PLANKS:1)
B(-8,7,-5,WOODEN_SLAB:1)
B(-7,7,-5,WOODEN_SLAB:1)
B(-6,7,-5,WOODEN_SLAB:1)
B(-5,7,-5,WOODEN_SLAB:1)
B(-4,7,-5,PLANKS:1)
B(-3,7,-5,PLANKS:1)
B(-2,7,-5,PLANKS:1)
B(-8,7,-4,WOODEN_SLAB:1)
B(-7,7,-4,WOODEN_SLAB:5)
B(-6,7,-4,DARK_OAK_STAIRS:0)
B(-5,7,-4,PLANKS:5)
B(-4,7,-4,FENCE:0)
B(-3,7,-4,FENCE:0)
B(-2,7,-4,FENCE:0)
B(-8,7,-3,WOODEN_SLAB:5)
B(-5,7,-3,TRAPDOOR:5)
B(-1,8,-8,WOODEN_SLAB:5)
B(-4,8,-7,LOG:1)
B(-1,8,-7,WOODEN_SLAB:5)
B(-1,8,-6,WOODEN_SLAB:5)
B(-4,8,-5,WOODEN_SLAB:5)
B(-3,8,-5,WOODEN_SLAB:5)
B(-2,8,-5,WOODEN_SLAB:5)
B(-5,8,-4,WOODEN_SLAB:5)
B(-4,8,-4,FENCE:0)
B(-3,8,-4,FENCE:0)
B(-2,8,-4,FENCE:0)
B(-1,9,-8,WOOL:0)
B(-7,9,-7,AIR)
B(-4,9,-7,LOG:12)
B(-8,9,-6,AIR)
B(-4,9,-5,FENCE:0)
B(-3,9,-5,FENCE:0)
B(-2,9,-5,FENCE:0)
B(-4,9,-4,FENCE:0)
B(-3,9,-4,FENCE:0)
B(-2,9,-4,FENCE:0)
B(-2,10,-8,WOOL:15)
B(-4,10,-7,LOG:1)
B(-4,10,-5,FENCE:0)
B(-3,10,-5,FENCE:0)
B(-2,10,-5,FENCE:0)
B(-4,11,-7,LOG:1)
B(-4,11,-5,FENCE:0)
B(-3,11,-5,FENCE:0)
B(-8,12,-8,FENCE:0)
B(-4,12,-8,FENCE:0)
B(-3,12,-8,FENCE:0)
B(-1,12,-8,WOOL:0)
B(-4,12,-7,LOG:1)
B(-4,12,-6,FENCE:0)
B(-3,12,-6,FENCE:0)
B(-4,12,-5,FENCE:0)
B(-3,12,-5,FENCE:0)
B(-5,13,-8,PLANKS:1)
B(-4,13,-8,FENCE:0)
B(-3,13,-8,FENCE:0)
B(-1,13,-8,WOOL:0)
B(-4,13,-7,LOG:1)
B(-4,13,-6,FENCE:0)
B(-3,13,-6,FENCE:0)
B(-5,14,-8,WOODEN_SLAB:1)
B(-4,14,-8,PLANKS:1)
B(-3,14,-8,FENCE:0)
B(-4,14,-7,LOG:12)
B(-4,14,-6,FENCE:0)
B(-4,15,-8,WOODEN_SLAB:1)
B(-3,15,-8,PLANKS:1)
B(-2,15,-8,FENCE:0)
B(-4,15,-7,LOG:1)
B(-3,16,-8,WOODEN_SLAB:1)
B(-2,16,-8,WOOL:15)
B(-8,16,-7,FENCE:0)
B(-7,16,-7,FENCE:0)
B(-4,16,-7,LOG:1)
B(-2,16,-7,PLANKS:1)
B(-1,16,-7,FENCE:0)
B(-1,17,-8,WOOL:0)
B(-7,17,-7,FENCE:0)
B(-6,17,-7,FENCE:0)
B(-5,17,-7,FENCE:0)
B(-4,17,-7,LOG:1)
B(-2,17,-7,WOODEN_SLAB:1)
B(-1,17,-7,PLANKS:1)
B(-8,18,-8,FENCE:0)
B(-4,18,-7,LOG:1)
B(-1,18,-7,WOODEN_SLAB:1)
B(-4,19,-7,LOG:12)
B(-4,20,-7,LOG:1)
B(-5,21,-8,DARK_OAK_STAIRS:6)
B(-4,21,-8,DARK_OAK_STAIRS:6)
B(-3,21,-8,DARK_OAK_STAIRS:6)
B(-5,21,-7,DARK_OAK_STAIRS:4)
B(-4,21,-7,LOG:1)
B(-3,21,-7,DARK_OAK_STAIRS:5)
B(-5,21,-6,DARK_OAK_STAIRS:7)
B(-4,21,-6,DARK_OAK_STAIRS:7)
B(-3,21,-6,DARK_OAK_STAIRS:5)
B(-8,22,-8,FENCE:0)
B(-5,22,-8,FENCE:0)
B(-4,22,-8,FENCE:0)
B(-3,22,-8,FENCE:0)
B(-5,22,-7,FENCE:0)
B(-4,22,-7,LOG:1)
B(-3,22,-7,FENCE:0)
B(-5,22,-6,FENCE:0)
B(-4,22,-6,FENCE:0)
B(-3,22,-6,FENCE:0)
B(-4,23,-7,LOG:1)
B(-4,24,-7,COBBLESTONE_WALL:0)
B(-4,25,-7,COBBLESTONE_WALL:0)
B(-4,26,-7,DARK_OAK_FENCE:0)
B(-2,27,-8,WOOL:0)
B(-1,27,-8,WOOL:0)
B(-4,27,-7,DARK_OAK_FENCE:0)
B(-3,27,-7,WOOL:14)
B(-4,28,-7,DARK_OAK_FENCE:0)
B(-4,29,-7,STANDING_BANNER:5,../NBT/Banners/dearoc_banner.nbt)

E(-6,3,-6,VILLAGER,1,../NBT/MOBS/RandomVillager.txt)
E(-7,6,-7,VILLAGER,1,../NBT/MOBS/RandomVillager.txt)
E(-7,9,-7,VILLAGER,1,../NBT/MOBS/RandomVillager.txt)
E(-8,9,-6,VILLAGER,1,../NBT/MOBS/CaptainVillager.txt)

BR(-8,0,0,WestPortShipFat_8x4,NORTH,100)
BR(0,0,8,WestPortShipFat_9x5,NORTH,100)
BR(8,0,0,WestPortShipFat_10x4,NORTH,100)
