Author: Bo3 BulkEdit

Description: Converted Schematic - Modified by Bo3BulkEdit

Version: 3

SettingsMode: WriteDisable

IsOTGPlus: false
Tree: false
Frequency: 1
Rarity: 100
RotateRandomly: false
SpawnHeight: randomY
MaxBranchDepth: 20
ExcludedBiomes: All

MinHeight: 0
MaxHeight: 256

SourceBlocks: AIR
MaxPercentageOutsideSourceBlock: 100
OutsideSourceBlock: placeAnyway

B(-8,-8,-2,LOG:12)
B(-7,-8,-2,LOG:12)
B(-8,-8,-1,LOG:12)
B(-7,-8,-1,LOG:12)
B(-6,-8,-1,LOG:12)
B(-5,-8,-1,LOG:12)
B(-8,-7,-3,LOG:12)
B(-7,-7,-3,LOG:12)
B(-8,-7,-2,MELON_BLOCK:0)
B(-7,-7,-2,MELON_BLOCK:0)
B(-6,-7,-2,LOG:12)
B(-5,-7,-2,LOG:12)
B(-4,-7,-2,LOG:12)
B(-8,-7,-1,MELON_BLOCK:0)
B(-7,-7,-1,HAY_BLOCK:4)
B(-6,-7,-1,LOG:12)
B(-5,-7,-1,LOG:12)
B(-4,-7,-1,LOG:12)
B(-3,-7,-1,LOG:12)
B(-2,-7,-1,LOG:12)
B(-8,-6,-4,LOG:12)
B(-7,-6,-4,LOG:12)
B(-8,-6,-3,PUMPKIN:0)
B(-7,-6,-3,MELON_BLOCK:0)
B(-6,-6,-3,LOG:12)
B(-5,-6,-3,LOG:12)
B(-4,-6,-3,LOG:12)
B(-8,-6,-2,PUMPKIN:2)
B(-7,-6,-2,PUMPKIN:1)
B(-6,-6,-2,LOG:12)
B(-5,-6,-2,LOG:12)
B(-4,-6,-2,LOG:12)
B(-3,-6,-2,LOG:12)
B(-2,-6,-2,LOG:12)
B(-1,-6,-2,LOG:12)
B(-8,-6,-1,MELON_BLOCK:0)
B(-7,-6,-1,AIR:0)
B(-6,-6,-1,LOG:12)
B(-5,-6,-1,CAULDRON:3)
B(-4,-6,-1,CAULDRON:3)
B(-3,-6,-1,CAULDRON:3)
B(-2,-6,-1,CAULDRON:3)
B(-1,-6,-1,LOG:12)
B(-8,-5,-4,LOG:12)
B(-7,-5,-4,LOG:12)
B(-6,-5,-4,LOG:12)
B(-5,-5,-4,LOG:12)
B(-8,-5,-3,HAY_BLOCK:8)
B(-7,-5,-3,HAY_BLOCK:4)
B(-6,-5,-3,LOG:12)
B(-5,-5,-3,LOG:12)
B(-4,-5,-3,LOG:12)
B(-3,-5,-3,LOG:12)
B(-2,-5,-3,LOG:12)
B(-8,-5,-2,AIR:0)
B(-7,-5,-2,AIR:0)
B(-6,-5,-2,LOG:12)
B(-5,-5,-2,CAULDRON:3)
B(-4,-5,-2,CAULDRON:3)
B(-3,-5,-2,CAULDRON:3)
B(-2,-5,-2,CAULDRON:3)
B(-1,-5,-2,LOG:12)
B(-8,-5,-1,AIR:0)
B(-7,-5,-1,AIR:0)
B(-6,-5,-1,LOG:12)
B(-5,-5,-1,CAULDRON:3)
B(-4,-5,-1,CAULDRON:3)
B(-3,-5,-1,CAULDRON:3)
B(-2,-5,-1,CAULDRON:3)
B(-1,-5,-1,LOG:12)
B(-8,-4,-5,PLANKS:0)
B(-7,-4,-5,PLANKS:0)
B(-6,-4,-5,PLANKS:0)
B(-8,-4,-4,DOUBLE_WOODEN_SLAB:1)
B(-7,-4,-4,DOUBLE_WOODEN_SLAB:1)
B(-6,-4,-4,PLANKS:0)
B(-5,-4,-4,PLANKS:0)
B(-4,-4,-4,PLANKS:0)
B(-3,-4,-4,PLANKS:0)
B(-8,-4,-3,WOODEN_SLAB:9)
B(-7,-4,-3,WOODEN_SLAB:9)
B(-6,-4,-3,PLANKS:0)
B(-5,-4,-3,PLANKS:0)
B(-4,-4,-3,PLANKS:0)
B(-3,-4,-3,PLANKS:0)
B(-2,-4,-3,PLANKS:0)
B(-1,-4,-3,LOG:12)
B(-8,-4,-2,WOODEN_SLAB:9)
B(-7,-4,-2,WOODEN_SLAB:9)
B(-6,-4,-2,PLANKS:0)
B(-1,-4,-2,PLANKS:0)
B(-8,-4,-1,WOODEN_SLAB:9)
B(-7,-4,-1,WOODEN_SLAB:9)
B(-6,-4,-1,PLANKS:0)
B(-1,-4,-1,PLANKS:0)
B(-6,-3,-6,DISPENSER:2)
B(-8,-3,-5,PLANKS:0)
B(-7,-3,-5,PLANKS:0)
B(-6,-3,-5,CONCRETE:15)
B(-5,-3,-5,PLANKS:0)
RB(-8,-3,-4,CHEST:3,../NBT/StructureLoot/JunkChest_1.nbt,15,CHEST:3,../NBT/StructureLoot/JunkChest_2.nbt,15,CHEST:3,../NBT/StructureLoot/JunkChest_3.nbt,15,CHEST:3,../NBT/StructureLoot/JunkChest_4.nbt,15,CHEST:3,../NBT/StructureLoot/JunkChest_5.nbt,15,CHEST:3,../NBT/StructureLoot/Common1.nbt,15,CHEST:3,../NBT/StructureLoot/Common2.nbt,15,CHEST:3,../NBT/StructureLoot/Common3.nbt,15,CHEST:3,../NBT/StructureLoot/Common4.nbt,15,CHEST:3,../NBT/StructureLoot/Common5.nbt,15,CHEST:3,../NBT/StructureLoot/Common6.nbt,15,CHEST:3,../NBT/StructureLoot/Common7.nbt,15,CHEST:3,../NBT/StructureLoot/Common8.nbt,15,CHEST:3,../NBT/StructureLoot/Common9.nbt,15,CHEST:3,../NBT/StructureLoot/Common10.nbt,15,CHEST:3,../NBT/StructureLoot/Common11.nbt,15,CHEST:3,../NBT/StructureLoot/Common12.nbt,15,CHEST:3,../NBT/StructureLoot/Common13.nbt,15,CHEST:3,../NBT/StructureLoot/Common14.nbt,15,CHEST:3,../NBT/StructureLoot/Common15.nbt,100)
B(-7,-3,-4,WOODEN_SLAB:1)
B(-6,-3,-4,DISPENSER:9)
B(-5,-3,-4,WOODEN_SLAB:1)
B(-4,-3,-4,PLANKS:0)
B(-3,-3,-4,PLANKS:0)
B(-2,-3,-4,PLANKS:0)
B(-7,-3,-3,WOODEN_SLAB:1)
B(-6,-3,-3,OAK_STAIRS:3)
B(-5,-3,-3,WOODEN_SLAB:1)
B(-4,-3,-3,DOUBLE_WOODEN_SLAB:1)
B(-3,-3,-3,DOUBLE_WOODEN_SLAB:1)
B(-2,-3,-3,DOUBLE_WOODEN_SLAB:1)
B(-1,-3,-3,PLANKS:0)
B(-8,-3,-2,CARPET:15)
B(-7,-3,-2,WOODEN_SLAB:1)
B(-6,-3,-2,WOODEN_SLAB:1)
B(-5,-3,-2,WOODEN_SLAB:1)
B(-4,-3,-2,DOUBLE_WOODEN_SLAB:1)
B(-3,-3,-2,DOUBLE_WOODEN_SLAB:1)
B(-2,-3,-2,DOUBLE_WOODEN_SLAB:1)
B(-1,-3,-2,DOUBLE_WOODEN_SLAB:1)
B(-7,-3,-1,WOODEN_SLAB:1)
B(-6,-3,-1,WOODEN_SLAB:1)
B(-5,-3,-1,WOODEN_SLAB:1)
B(-4,-3,-1,DOUBLE_WOODEN_SLAB:1)
B(-3,-3,-1,DOUBLE_WOODEN_SLAB:1)
B(-2,-3,-1,DOUBLE_WOODEN_SLAB:1)
B(-1,-3,-1,DOUBLE_WOODEN_SLAB:1)
B(-6,-2,-6,WOODEN_SLAB:13)
B(-8,-2,-5,PLANKS:0)
B(-7,-2,-5,PLANKS:0)
B(-5,-2,-5,PLANKS:0)
B(-3,-2,-5,DISPENSER:2)
B(-6,-2,-4,LEVER:13)
B(-4,-2,-4,PLANKS:0)
B(-3,-2,-4,CONCRETE:15)
B(-2,-2,-4,PLANKS:0)
B(-1,-2,-4,PLANKS:0)
B(-4,-2,-3,WOODEN_BUTTON:2)
B(-3,-2,-3,DISPENSER:9)
B(-2,-2,-3,WOODEN_BUTTON:1)
B(-1,-2,-3,DOUBLE_WOODEN_SLAB:1)
B(-3,-2,-2,OAK_STAIRS:3)
B(-1,-2,-2,DOUBLE_WOODEN_SLAB:1)
B(-4,-2,-1,CARPET:12)
B(-3,-2,-1,CARPET:12)
B(-2,-2,-1,CARPET:13)
B(-1,-2,-1,DOUBLE_WOODEN_SLAB:1)
B(-8,-1,-5,PLANKS:0)
B(-7,-1,-5,PLANKS:0)
B(-6,-1,-5,PLANKS:0)
B(-5,-1,-5,PLANKS:0)
B(-4,-1,-5,PLANKS:0)
B(-3,-1,-5,WOODEN_SLAB:13)
B(-8,-1,-4,WOODEN_SLAB:9)
B(-2,-1,-4,PLANKS:0)
B(-1,-1,-4,PLANKS:0)
B(-8,-1,-3,WOODEN_SLAB:9)
B(-3,-1,-3,LEVER:13)
B(-1,-1,-3,PLANKS:0)
B(-8,-1,-2,WOODEN_SLAB:9)
B(-7,-1,-2,AIR)
B(-1,-1,-2,PLANKS:0)
B(-8,-1,-1,WOODEN_SLAB:9)
B(-1,-1,-1,PLANKS:0)
B(-8,0,-5,PLANKS:0)
B(-7,0,-5,PLANKS:0)
B(-6,0,-5,PLANKS:0)
B(-5,0,-5,PLANKS:0)
B(-8,0,-4,PLANKS:0)
B(-7,0,-4,DOUBLE_WOODEN_SLAB:1)
B(-6,0,-4,DOUBLE_WOODEN_SLAB:1)
B(-5,0,-4,DOUBLE_WOODEN_SLAB:1)
B(-4,0,-4,PLANKS:0)
B(-3,0,-4,PLANKS:0)
B(-2,0,-4,PLANKS:0)
B(-1,0,-4,PLANKS:0)
B(-8,0,-3,PLANKS:0)
B(-7,0,-3,DOUBLE_WOODEN_SLAB:1)
B(-6,0,-3,DOUBLE_WOODEN_SLAB:1)
B(-5,0,-3,DOUBLE_WOODEN_SLAB:1)
B(-4,0,-3,WOODEN_SLAB:9)
B(-3,0,-3,WOODEN_SLAB:9)
B(-2,0,-3,WOODEN_SLAB:9)
B(-1,0,-3,PLANKS:0)
B(-8,0,-2,PLANKS:0)
B(-7,0,-2,DOUBLE_WOODEN_SLAB:1)
B(-6,0,-2,DOUBLE_WOODEN_SLAB:1)
B(-5,0,-2,DOUBLE_WOODEN_SLAB:1)
B(-4,0,-2,WOODEN_SLAB:9)
B(-3,0,-2,WOODEN_SLAB:9)
B(-2,0,-2,WOODEN_SLAB:9)
B(-1,0,-2,PLANKS:0)
B(-8,0,-1,PLANKS:0)
B(-7,0,-1,WOODEN_SLAB:1)
B(-6,0,-1,DOUBLE_WOODEN_SLAB:1)
B(-5,0,-1,DOUBLE_WOODEN_SLAB:1)
B(-4,0,-1,WOODEN_SLAB:9)
B(-3,0,-1,WOODEN_SLAB:9)
B(-2,0,-1,WOODEN_SLAB:9)
B(-1,0,-1,PLANKS:0)
B(-8,1,-5,PLANKS:0)
B(-7,1,-5,PLANKS:0)
B(-6,1,-5,PLANKS:0)
B(-5,1,-5,PLANKS:0)
B(-8,1,-4,PLANKS:0)
B(-7,1,-4,PLANKS:0)
B(-5,1,-4,PLANKS:0)
B(-4,1,-4,PLANKS:0)
B(-3,1,-4,PLANKS:0)
B(-2,1,-4,PLANKS:0)
B(-1,1,-4,PLANKS:0)
B(-8,1,-3,PLANKS:0)
B(-7,1,-3,DOUBLE_WOODEN_SLAB:1)
B(-6,1,-3,DOUBLE_WOODEN_SLAB:1)
B(-5,1,-3,SPRUCE_STAIRS:1)
B(-2,1,-3,DOUBLE_WOODEN_SLAB:1)
B(-1,1,-3,DOUBLE_WOODEN_SLAB:1)
B(-8,1,-2,PLANKS:0)
B(-7,1,-2,PLANKS:0)
B(-6,1,-2,PLANKS:0)
B(-2,1,-2,DARK_OAK_DOOR:0)
B(-1,1,-2,WOODEN_SLAB:1)
B(-8,1,-1,PLANKS:0)
B(-6,1,-1,CARPET:15)
B(-4,1,-1,PLANKS:0)
B(-3,1,-1,PLANKS:0)
B(-2,1,-1,PLANKS:0)
B(-1,1,-1,DOUBLE_WOODEN_SLAB:1)
B(-8,2,-5,PLANKS:0)
B(-7,2,-5,PLANKS:0)
B(-6,2,-5,PLANKS:0)
B(-8,2,-4,DOUBLE_WOODEN_SLAB:1)
B(-7,2,-4,PLANKS:0)
B(-6,2,-4,PLANKS:0)
B(-5,2,-4,PLANKS:0)
B(-4,2,-4,PLANKS:0)
B(-3,2,-4,PLANKS:0)
B(-2,2,-4,PLANKS:0)
B(-8,2,-3,DOUBLE_WOODEN_SLAB:1)
B(-7,2,-3,DOUBLE_WOODEN_SLAB:1)
B(-6,2,-3,SPRUCE_STAIRS:1)
B(-2,2,-3,DOUBLE_WOODEN_SLAB:1)
B(-1,2,-3,PLANKS:0)
B(-8,2,-2,DOUBLE_WOODEN_SLAB:1)
B(-7,2,-2,PLANKS:0)
B(-6,2,-2,PLANKS:0)
B(-2,2,-2,DARK_OAK_DOOR:9)
B(-8,2,-1,DOUBLE_WOODEN_SLAB:1)
B(-4,2,-1,PLANKS:0)
B(-3,2,-1,PLANKS:0)
B(-2,2,-1,PLANKS:0)
B(-1,2,-1,PLANKS:0)
B(-8,3,-6,FENCE:0)
B(-7,3,-6,TRAPDOOR:4)
B(-8,3,-5,PLANKS:1)
B(-7,3,-5,PLANKS:5)
B(-8,3,-4,COAL_ORE:0)
B(-7,3,-4,COAL_ORE:0)
B(-6,3,-4,PLANKS:1)
B(-5,3,-4,PLANKS:1)
B(-4,3,-4,PLANKS:0)
B(-3,3,-4,PLANKS:0)
B(-2,3,-4,PLANKS:0)
B(-8,3,-3,CONCRETE:15)
B(-7,3,-3,WOODEN_SLAB:1)
B(-3,3,-3,WOODEN_SLAB:9)
B(-2,3,-3,DOUBLE_WOODEN_SLAB:1)
B(-1,3,-3,PLANKS:0)
B(-8,3,-2,WOODEN_SLAB:1)
B(-7,3,-2,WOODEN_SLAB:1)
B(-6,3,-2,WOODEN_SLAB:1)
B(-5,3,-2,SPRUCE_STAIRS:0)
B(-4,3,-2,DOUBLE_WOODEN_SLAB:1)
B(-3,3,-2,DOUBLE_WOODEN_SLAB:1)
B(-2,3,-2,WOODEN_SLAB:9)
B(-1,3,-2,WOODEN_SLAB:9)
B(-7,3,-1,WOODEN_SLAB:1)
B(-6,3,-1,WOODEN_SLAB:1)
B(-5,3,-1,WOODEN_SLAB:1)
B(-4,3,-1,DOUBLE_WOODEN_SLAB:1)
B(-3,3,-1,DOUBLE_WOODEN_SLAB:1)
B(-2,3,-1,DOUBLE_WOODEN_SLAB:1)
B(-1,3,-1,PLANKS:0)
B(-7,4,-6,TRAPDOOR:12)
B(-8,4,-5,PLANKS:1)
B(-7,4,-5,PLANKS:5)
B(-6,4,-5,WOODEN_SLAB:13)
B(-5,4,-5,DARK_OAK_STAIRS:6)
B(-4,4,-5,WOODEN_SLAB:13)
B(-3,4,-5,DARK_OAK_STAIRS:6)
B(-8,4,-4,CONCRETE:15)
B(-6,4,-4,PLANKS:1)
B(-5,4,-4,PLANKS:1)
B(-4,4,-4,PLANKS:1)
B(-3,4,-4,PLANKS:1)
B(-2,4,-4,WOODEN_SLAB:13)
B(-3,4,-3,PLANKS:1)
B(-2,4,-3,PLANKS:1)
B(-1,4,-3,PLANKS:1)
B(-4,4,-2,SPRUCE_STAIRS:0)
B(-3,4,-2,PLANKS:1)
B(-2,4,-2,PLANKS:1)
B(-1,4,-2,DOUBLE_WOODEN_SLAB:1)
B(-8,4,-1,STONE_BUTTON:4)
B(-3,4,-1,PLANKS:1)
B(-2,4,-1,DOUBLE_WOODEN_SLAB:1)
B(-1,4,-1,DOUBLE_WOODEN_SLAB:1)
B(-8,5,-6,TRAPDOOR:4)
B(-8,5,-5,PLANKS:5)
B(-6,5,-5,FENCE:0)
B(-5,5,-5,FENCE:0)
B(-4,5,-5,FENCE:0)
B(-3,5,-5,FENCE:0)
B(-8,5,-4,CONCRETE:15)
B(-7,5,-4,PLANKS:1)
B(-6,5,-4,PLANKS:1)
B(-5,5,-4,PLANKS:1)
B(-4,5,-4,PLANKS:1)
B(-3,5,-4,PLANKS:1)
B(-2,5,-4,FENCE:0)
B(-3,5,-3,PLANKS:1)
B(-2,5,-3,PLANKS:1)
B(-1,5,-3,WOODEN_SLAB:1)
B(-3,5,-2,SPRUCE_STAIRS:0)
B(-2,5,-2,PLANKS:1)
RB(-1,5,-2,CHEST:5,../NBT/LoreStoryline/LoreGeneric_5.nbt,2,CHEST:5,../NBT/LoreStoryline/LoreGeneric_4.nbt,2,CHEST:5,../NBT/LoreStoryline/LoreGeneric_3.nbt,2,CHEST:5,../NBT/LoreStoryline/LoreGeneric_2.nbt,2,CHEST:5,../NBT/LoreStoryline/LoreGeneric_1.nbt,2,CHEST:5,../NBT/LoreStoryline/LoreHarbor_5.nbt,3,CHEST:5,../NBT/LoreStoryline/LoreHarbor_4.nbt,3,CHEST:5,../NBT/LoreStoryline/LoreHarbor_3.nbt,3,CHEST:5,../NBT/LoreStoryline/LoreHarbor_2.nbt,3,CHEST:5,../NBT/LoreStoryline/LoreHarbor_1.nbt,3,CHEST:5,../NBT/StructureLoot/Common1.nbt,3,CHEST:5,../NBT/StructureLoot/Common2.nbt,3,CHEST:5,../NBT/StructureLoot/Common3.nbt,3,CHEST:5,../NBT/StructureLoot/Common4.nbt,3,CHEST:5,../NBT/StructureLoot/Common5.nbt,3,CHEST:5,../NBT/StructureLoot/Common5.nbt,3,CHEST:5,../NBT/StructureLoot/Common6.nbt,3,CHEST:5,../NBT/StructureLoot/Common7.nbt,3,CHEST:5,../NBT/StructureLoot/Common8.nbt,3,CHEST:5,../NBT/StructureLoot/Common9.nbt,3,CHEST:5,../NBT/StructureLoot/Common10.nbt,3,CHEST:5,../NBT/StructureLoot/Common11.nbt,3,CHEST:5,../NBT/StructureLoot/Common12.nbt,3,CHEST:5,../NBT/StructureLoot/Common13.nbt,3,CHEST:5,../NBT/StructureLoot/Common14.nbt,3,CHEST:5,../NBT/StructureLoot/Common15.nbt,3,CHEST:5,../NBT/StructureLoot/Rare1.nbt,3,CHEST:5,../NBT/StructureLoot/Rare2.nbt,3,CHEST:5,../NBT/StructureLoot/Rare3.nbt,3,CHEST:5,../NBT/StructureLoot/Rare4.nbt,3,CHEST:5,../NBT/StructureLoot/Rare5.nbt,3,CHEST:5,../NBT/StructureLoot/Rare6.nbt,3,CHEST:5,../NBT/StructureLoot/Rare7.nbt,3,CHEST:5,../NBT/StructureLoot/Rare8.nbt,3,CHEST:5,../NBT/StructureLoot/Rare9.nbt,3,CHEST:5,../NBT/StructureLoot/Rare10.nbt,3,CHEST:5,../NBT/StructureLoot/Rare11.nbt,3,CHEST:5,../NBT/StructureLoot/Rare12.nbt,3,CHEST:5,../NBT/StructureLoot/Rare13.nbt,3,CHEST:5,../NBT/StructureLoot/Rare14.nbt,3,CHEST:5,../NBT/StructureLoot/Rare15.nbt,3,CHEST:5,../NBT/StructureLoot/Epic1.nbt,3,CHEST:5,../NBT/StructureLoot/Epic2.nbt,3,CHEST:5,../NBT/StructureLoot/Epic3.nbt,3,CHEST:5,../NBT/StructureLoot/Epic4.nbt,3,CHEST:5,../NBT/StructureLoot/Epic5.nbt,3,CHEST:5,../NBT/StructureLoot/Epic6.nbt,3,CHEST:5,../NBT/StructureLoot/Epic7.nbt,3,CHEST:5,../NBT/StructureLoot/Epic8.nbt,3,CHEST:5,../NBT/StructureLoot/Epic9.nbt,3,CHEST:5,../NBT/StructureLoot/Epic10.nbt,3,CHEST:5,../NBT/StructureLoot/Epic11.nbt,3,CHEST:5,../NBT/StructureLoot/Epic12.nbt,3,CHEST:5,../NBT/StructureLoot/Epic13.nbt,3,CHEST:5,../NBT/StructureLoot/Epic14.nbt,3,CHEST:5,../NBT/StructureLoot/Epic15.nbt,1,CHEST:5,../NBT/StructureLoot/Common15.nbt,100)
B(-8,5,-1,STONE_BUTTON:4)
B(-3,5,-1,PLANKS:1)
B(-2,5,-1,DOUBLE_WOODEN_SLAB:1)
B(-1,5,-1,DOUBLE_WOODEN_SLAB:1)
B(-8,6,-5,WOODEN_SLAB:5)
B(-6,6,-5,FENCE:0)
B(-5,6,-5,FENCE:0)
B(-4,6,-5,FENCE:0)
B(-3,6,-5,FENCE:0)
B(-7,6,-4,WOODEN_SLAB:5)
B(-6,6,-4,WOODEN_SLAB:5)
B(-5,6,-4,WOODEN_SLAB:5)
B(-4,6,-4,WOODEN_SLAB:5)
B(-3,6,-4,DARK_OAK_STAIRS:2)
B(-2,6,-4,FENCE:0)
B(-1,6,-4,TRAPDOOR:4)
B(-3,6,-3,DOUBLE_WOODEN_SLAB:5)
B(-2,6,-3,DOUBLE_WOODEN_SLAB:5)
B(-1,6,-3,DOUBLE_WOODEN_SLAB:5)
B(-2,6,-2,SPRUCE_STAIRS:0)
B(-1,6,-2,WOODEN_SLAB:9)
B(-3,6,-1,PLANKS:1)
B(-2,6,-1,DOUBLE_WOODEN_SLAB:1)
B(-1,6,-1,DOUBLE_WOODEN_SLAB:1)
B(-6,7,-5,FENCE:0)
B(-5,7,-5,FENCE:0)
B(-4,7,-5,FENCE:0)
B(-3,7,-5,FENCE:0)
B(-6,7,-4,FENCE:0)
B(-5,7,-4,FENCE:0)
B(-4,7,-4,FENCE:0)
B(-3,7,-4,FENCE:0)
B(-2,7,-4,FENCE:0)
B(-3,7,-3,DARK_OAK_FENCE:0)
B(-2,7,-3,DARK_OAK_FENCE:0)
B(-1,7,-3,DARK_OAK_FENCE:0)
B(-3,7,-1,DARK_OAK_FENCE:0)
B(-6,8,-4,FENCE:0)
B(-5,8,-4,FENCE:0)
B(-4,8,-4,FENCE:0)
B(-3,8,-4,FENCE:0)
B(-6,9,-4,FENCE:0)
B(-5,9,-4,FENCE:0)
B(-4,9,-4,FENCE:0)
B(-3,9,-4,FENCE:0)
B(-6,9,-3,FENCE:0)
B(-5,9,-3,FENCE:0)
B(-4,9,-3,FENCE:0)
B(-3,9,-3,FENCE:0)
B(-1,9,-2,WOOL:0)
B(-1,9,-1,PLANKS:1)
B(-6,10,-3,FENCE:0)
B(-5,10,-3,FENCE:0)
B(-4,10,-3,FENCE:0)
B(-3,10,-3,FENCE:0)
B(-1,10,-1,WOODEN_SLAB:1)
B(-6,11,-3,FENCE:0)
B(-5,11,-3,FENCE:0)
B(-4,11,-3,FENCE:0)
B(-6,11,-2,FENCE:0)
B(-5,11,-2,FENCE:0)
B(-4,11,-2,FENCE:0)
B(-6,12,-2,FENCE:0)
B(-5,12,-2,FENCE:0)
B(-4,12,-2,FENCE:0)
B(-6,12,-1,FENCE:0)
B(-5,12,-1,FENCE:0)
B(-3,12,-1,WOOL:15)
B(-2,12,-1,WOOL:0)
B(-8,13,-1,WOOL:0)
B(-6,13,-1,FENCE:0)
B(-5,13,-1,FENCE:0)
B(-4,13,-1,WOOL:0)
B(-3,13,-1,WOOL:0)
B(-8,14,-2,WOOL:0)
B(-8,14,-1,FENCE:0)
B(-7,14,-1,WOOL:0)
B(-6,14,-1,WOOL:0)
B(-5,14,-1,WOOL:0)
B(-4,14,-1,WOOL:0)
B(-8,15,-2,WOOL:0)
B(-7,15,-2,WOOL:0)
B(-6,15,-2,WOOL:0)
B(-8,15,-1,PLANKS:1)
B(-5,15,-1,WOOL:0)
B(-4,15,-1,WOOL:0)
B(-6,16,-2,WOOL:0)
B(-5,16,-2,WOOL:0)
B(-8,16,-1,WOODEN_SLAB:1)
B(-7,16,-1,WOOL:0)
B(-4,16,-1,WOOL:0)
B(-5,17,-2,WOOL:0)
B(-6,17,-1,WOOL:0)
B(-4,17,-1,WOOL:0)
B(-3,17,-1,WOOL:0)
B(-5,18,-1,WOOL:0)
B(-4,18,-1,WOOL:0)
B(-3,18,-1,WOOL:0)
B(-2,18,-1,WOOL:0)
B(-3,19,-1,WOOL:0)
B(-2,19,-1,WOOL:0)
B(-1,19,-1,WOOL:0)
B(-2,20,-1,WOOL:0)
B(-1,20,-1,WOOL:15)
B(-8,21,-1,WOOL:15)
B(-1,21,-1,WOOL:0)
B(-8,22,-2,WOOL:0)
B(-8,22,-1,FENCE:0)
B(-7,22,-1,WOOL:0)
B(-5,22,-1,WOOL:0)
B(-4,22,-1,WOOL:15)
B(-8,23,-2,WOOL:0)
B(-7,23,-2,WOOL:0)
B(-8,23,-1,PLANKS:1)
B(-6,23,-1,WOOL:0)
B(-5,23,-1,WOOL:0)
B(-8,24,-1,WOODEN_SLAB:1)
B(-7,24,-1,WOOL:15)
B(-6,24,-1,WOOL:0)
B(-5,24,-1,WOOL:0)
B(-6,25,-1,WOOL:15)
B(-5,25,-1,WOOL:0)
B(-4,25,-1,WOOL:0)
B(-5,26,-1,WOOL:15)
B(-4,26,-1,WOOL:0)
B(-3,26,-1,WOOL:15)
B(-3,27,-1,WOOL:0)

E(-7,-1,-2,VILLAGER,1,../NBT/MOBS/RandomVillager.txt)

BR(-8,0,0,WestPortShipFat_7x3,NORTH,100)
