Author: Bo3 BulkEdit

Description: Converted Schematic - Modified by Bo3BulkEdit

Version: 3

SettingsMode: WriteDisable

IsOTGPlus: false
Tree: false
Frequency: 1
Rarity: 100
RotateRandomly: false
SpawnHeight: randomY
MaxBranchDepth: 20
ExcludedBiomes: All

MinHeight: 0
MaxHeight: 256

SourceBlocks: AIR
MaxPercentageOutsideSourceBlock: 100
OutsideSourceBlock: placeAnyway

B(-1,5,-6,FENCE:0)
B(-1,5,-5,FENCE:0)
B(-4,6,-5,WOOL:0)
B(-3,6,-5,FENCE:0)
B(-2,6,-5,FENCE:0)
B(-1,6,-5,FENCE:0)
B(-7,7,-8,WOOL:0)
B(-7,7,-7,WOOL:0)
B(-6,7,-7,WOOL:15)
B(-6,7,-6,WOOL:15)
B(-5,7,-6,WOOL:15)
B(-4,7,-6,WOOL:0)
B(-4,7,-5,WOOL:0)
B(-8,8,-8,WOOL:0)
B(-7,8,-7,WOOL:0)
B(-7,8,-6,WOOL:0)
B(-8,9,-8,WOOL:0)
B(-8,9,-7,WOOL:0)
B(-8,14,-8,WOOL:0)
B(-8,14,-7,WOOL:0)
B(-8,14,-6,WOOL:0)
B(-7,15,-8,WOOL:0)
B(-6,15,-8,FENCE:0)
B(-7,15,-7,WOOL:0)
B(-7,15,-6,WOOL:15)
B(-6,15,-5,WOOL:0)
B(-7,16,-8,FENCE:0)
B(-6,16,-8,LOG:9)
B(-7,16,-7,FENCE:0)
B(-6,16,-7,WOOL:0)
B(-5,16,-6,WOOL:15)
B(-4,16,-6,WOOL:15)
B(-6,16,-5,WOOL:0)
B(-5,16,-4,WOOL:0)
B(-7,17,-8,WOOL:15)
B(-7,17,-7,WOOL:0)
B(-5,17,-4,WOOL:0)
B(-4,17,-4,WOOL:15)
B(-8,18,-8,WOOL:0)
B(-8,24,-8,WOOL:15)
B(-8,25,-8,WOOL:15)
B(-7,26,-8,WOOL:0)
B(-6,26,-7,WOOL:0)
B(-5,26,-6,WOOL:15)
B(-4,26,-6,WOOL:0)

BR(-8,0,0,WestPortShipFat_3x5,NORTH,100)
