
#######################################################################
# +-----------------------------------------------------------------+ #
# |                            BO3 object                           | #
# +-----------------------------------------------------------------+ #
#######################################################################

Author: BO3 BulkEdit (by LanToaster)

Description: This Object was Created with BO3_BulkEdit

Version: 3

SettingsMode: WriteWithoutComments


#######################################################################
# +-----------------------------------------------------------------+ #
# |                          Main settings                          | #
# +-----------------------------------------------------------------+ #
#######################################################################

Tree: false

Frequency: 1

Rarity: 100.0

RotateRandomly: false

SpawnHeight: randomY

SpawnHeightOffset: 0

SpawnHeightVariance: 0

##############################
# Height Limits for the BO3. #
##############################

MinHeight: 82

MaxHeight: 82

######################
# Extrusion settings #
######################

ExtrudeMode: None

ExtrudeThroughBlocks: minecraft:air

MaxBranchDepth: 10


#######################################################################
# +-----------------------------------------------------------------+ #
# |                      Source block settings                      | #
# +-----------------------------------------------------------------+ #
#######################################################################

SourceBlocks: otg:air

MaxPercentageOutsideSourceBlock: 100

OutsideSourceBlock: placeAnyway

DoReplaceBlocks: true

IsOTGPlus: false


#######################################################################
# +-----------------------------------------------------------------+ #
# |                              Blocks                             | #
# +-----------------------------------------------------------------+ #
#######################################################################

B(-7,4,-6,minecraft:jungle_leaves[distance=7,persistent=true])
B(-7,6,-6,minecraft:jungle_leaves[distance=7,persistent=true])
B(-7,11,-6,minecraft:jungle_leaves[distance=7,persistent=true])
B(-7,12,-6,minecraft:jungle_leaves[distance=7,persistent=true])
B(-7,12,-5,minecraft:stone_brick_slab)
B(-7,0,-4,minecraft:stone_brick_slab)
B(-7,0,-2,minecraft:water)
B(-7,7,-2,minecraft:vine[east=false,north=false,south=true,up=false,west=false])
B(-7,8,-2,minecraft:vine[east=false,north=false,south=true,up=false,west=false])
B(-7,9,-2,minecraft:vine[east=false,north=false,south=true,up=false,west=false])
B(-7,10,-2,minecraft:vine[east=false,north=false,south=true,up=false,west=false])
B(-7,12,-2,minecraft:stone_brick_slab)
B(-7,0,-1,minecraft:water)
B(-7,6,-1,minecraft:stone_brick_stairs[facing=east,half=bottom,shape=straight,waterlogged=false])
B(-7,10,-1,minecraft:jungle_leaves[distance=7,persistent=true])
B(-7,11,-1,minecraft:jungle_leaves[distance=7,persistent=true])
B(-7,12,-1,minecraft:jungle_leaves[distance=7,persistent=true])
B(-7,0,0,minecraft:water)
B(-7,6,0,minecraft:stone_brick_stairs[facing=east,half=bottom,shape=straight,waterlogged=false])
B(-7,10,0,minecraft:jungle_leaves[distance=7,persistent=true])
B(-7,12,0,minecraft:stone_brick_slab)
B(-7,0,1,minecraft:water)
B(-7,7,1,minecraft:vine[east=true,north=true,south=false,up=false,west=false])
B(-7,8,1,minecraft:vine[east=true,north=true,south=false,up=false,west=false])
B(-7,9,1,minecraft:vine[east=true,north=true,south=false,up=false,west=false])
B(-7,10,1,minecraft:vine[east=true,north=true,south=false,up=false,west=false])
B(-7,0,3,minecraft:stone_brick_slab)
B(-7,6,3,minecraft:jungle_leaves[distance=7,persistent=true])
B(-7,7,3,minecraft:jungle_leaves[distance=7,persistent=true])
B(-7,12,4,minecraft:stone_brick_slab)
B(-7,6,5,minecraft:jungle_leaves[distance=7,persistent=true])
B(-7,11,5,minecraft:stone_brick_stairs[facing=east,half=top,shape=straight,waterlogged=false])
B(-7,12,5,minecraft:stone_brick_slab)
B(-7,6,7,minecraft:stone_brick_slab)
B(-7,2,8,minecraft:stone_brick_slab[type=top,waterlogged=false])
B(-7,3,8,minecraft:grass_block)
B(-6,4,-7,minecraft:jungle_leaves[distance=7,persistent=true])
B(-6,11,-7,minecraft:stone_brick_stairs[facing=south,half=top,shape=straight,waterlogged=false])
B(-6,6,-6,minecraft:jungle_leaves[distance=7,persistent=true])
B(-6,7,-6,minecraft:jungle_leaves[distance=7,persistent=true])
B(-6,10,-6,minecraft:jungle_leaves[distance=7,persistent=true])
B(-6,12,-6,minecraft:jungle_leaves[distance=7,persistent=true])
B(-6,7,-5,minecraft:jungle_leaves[distance=7,persistent=true])
B(-6,8,-5,minecraft:jungle_leaves[distance=7,persistent=true])
B(-6,10,-5,minecraft:stone_brick_stairs[facing=east,half=top,shape=straight,waterlogged=false])
B(-6,0,-4,minecraft:stone_brick_slab)
B(-6,4,-4,minecraft:vine[east=true,north=true,south=false,up=false,west=false])
B(-6,5,-4,minecraft:vine[east=true,north=true,south=false,up=false,west=false])
B(-6,6,-4,minecraft:vine[east=true,north=true,south=false,up=false,west=false])
B(-6,7,-4,minecraft:vine[east=true,north=true,south=false,up=false,west=false])
B(-6,8,-4,minecraft:vine[east=true,north=true,south=false,up=false,west=false])
B(-6,10,-4,minecraft:stone_brick_stairs[facing=east,half=top,shape=straight,waterlogged=false])
B(-6,12,-4,minecraft:stone_brick_slab)
B(-6,4,-3,minecraft:vine[east=true,north=false,south=false,up=false,west=false])
B(-6,5,-3,minecraft:vine[east=true,north=false,south=false,up=false,west=false])
B(-6,6,-3,minecraft:vine[east=true,north=false,south=false,up=false,west=false])
B(-6,10,-3,minecraft:stone_brick_stairs[facing=east,half=top,shape=straight,waterlogged=false])
B(-6,0,-2,minecraft:water)
B(-6,7,-2,minecraft:stone_brick_stairs[facing=east,half=bottom,shape=straight,waterlogged=false])
B(-6,10,-2,minecraft:stone_brick_stairs[facing=east,half=top,shape=straight,waterlogged=false])
B(-6,12,-2,minecraft:stone_brick_slab)
B(-6,0,-1,minecraft:water)
B(-6,6,-1,minecraft:stone_brick_slab[type=top,waterlogged=false])
B(-6,10,-1,minecraft:stone_brick_stairs[facing=east,half=top,shape=straight,waterlogged=false])
B(-6,12,-1,minecraft:jungle_leaves[distance=7,persistent=true])
B(-6,0,0,minecraft:water)
B(-6,6,0,minecraft:stone_brick_slab[type=top,waterlogged=false])
B(-6,9,0,minecraft:jungle_leaves[distance=7,persistent=true])
B(-6,10,0,minecraft:stone_brick_stairs[facing=east,half=top,shape=straight,waterlogged=false])
B(-6,0,1,minecraft:water)
B(-6,7,1,minecraft:stone_brick_stairs[facing=east,half=bottom,shape=straight,waterlogged=false])
B(-6,9,1,minecraft:jungle_leaves[distance=7,persistent=true])
B(-6,10,1,minecraft:stone_brick_stairs[facing=east,half=top,shape=straight,waterlogged=false])
B(-6,12,1,minecraft:stone_brick_slab)
B(-6,7,2,minecraft:jungle_leaves[distance=7,persistent=true])
B(-6,8,2,minecraft:jungle_leaves[distance=7,persistent=true])
B(-6,9,2,minecraft:jungle_leaves[distance=7,persistent=true])
B(-6,10,2,minecraft:stone_brick_stairs[facing=east,half=top,shape=straight,waterlogged=false])
B(-6,0,3,minecraft:stone_brick_slab)
B(-6,7,3,minecraft:jungle_leaves[distance=7,persistent=true])
B(-6,8,3,minecraft:jungle_leaves[distance=7,persistent=true])
B(-6,10,3,minecraft:stone_brick_stairs[facing=east,half=top,shape=straight,waterlogged=false])
B(-6,12,3,minecraft:stone_brick_slab)
B(-6,7,4,minecraft:jungle_leaves[distance=7,persistent=true])
B(-6,10,4,minecraft:stone_brick_stairs[facing=east,half=top,shape=straight,waterlogged=false])
B(-6,6,5,minecraft:jungle_leaves[distance=7,persistent=true])
B(-6,7,5,minecraft:jungle_leaves[distance=7,persistent=true])
B(-6,10,5,minecraft:stone_brick_stairs[facing=east,half=top,shape=outer_left,waterlogged=false])
B(-6,12,5,minecraft:stone_brick_slab)
B(-6,6,6,minecraft:jungle_leaves[distance=7,persistent=true])
B(-6,11,6,minecraft:stone_brick_stairs[facing=north,half=top,shape=straight,waterlogged=false])
B(-6,12,6,minecraft:stone_brick_slab)
B(-6,6,7,minecraft:stone_brick_slab)
B(-6,2,8,minecraft:stone_brick_slab[type=top,waterlogged=false])
B(-6,3,8,minecraft:grass_block)
B(-5,7,-6,minecraft:stone_brick_stairs[facing=south,half=bottom,shape=straight,waterlogged=false])
B(-5,10,-6,minecraft:stone_brick_stairs[facing=south,half=top,shape=straight,waterlogged=false])
B(-5,12,-6,minecraft:jungle_leaves[distance=7,persistent=true])
B(-5,8,-5,minecraft:jungle_leaves[distance=7,persistent=true])
B(-5,9,-5,minecraft:jungle_leaves[distance=7,persistent=true])
B(-5,11,-5,minecraft:stone_brick_slab[type=top,waterlogged=false])
B(-5,12,-5,minecraft:jungle_leaves[distance=7,persistent=true])
B(-5,0,-4,minecraft:stone_brick_slab)
B(-5,8,-4,minecraft:stone_brick_stairs[facing=east,half=bottom,shape=straight,waterlogged=false])
B(-5,12,-4,minecraft:stone_brick_slab)
B(-5,8,-3,minecraft:stone_brick_stairs[facing=east,half=bottom,shape=straight,waterlogged=false])
B(-5,11,-3,minecraft:stone_brick_slab[type=top,waterlogged=false])
B(-5,12,-3,minecraft:jungle_leaves[distance=7,persistent=true])
B(-5,0,-2,minecraft:water)
B(-5,8,-2,minecraft:stone_brick_stairs[facing=east,half=bottom,shape=straight,waterlogged=false])
B(-5,12,-2,minecraft:stone_brick_slab)
B(-5,0,-1,minecraft:water)
B(-5,8,-1,minecraft:stone_brick_stairs[facing=east,half=bottom,shape=straight,waterlogged=false])
B(-5,11,-1,minecraft:stone_brick_slab[type=top,waterlogged=false])
B(-5,12,-1,minecraft:jungle_leaves[distance=7,persistent=true])
B(-5,13,-1,minecraft:jungle_leaves[distance=7,persistent=true])
B(-5,0,0,minecraft:water)
B(-5,8,0,minecraft:stone_brick_stairs[facing=east,half=bottom,shape=straight,waterlogged=false])
B(-5,11,0,minecraft:stone_brick_slab[type=top,waterlogged=false])
B(-5,12,0,minecraft:stone_brick_stairs[facing=east,half=bottom,shape=straight,waterlogged=false])
B(-5,0,1,minecraft:water)
B(-5,8,1,minecraft:stone_brick_stairs[facing=east,half=bottom,shape=straight,waterlogged=false])
B(-5,12,1,minecraft:stone_brick_slab)
B(-5,8,2,minecraft:stone_brick_stairs[facing=east,half=bottom,shape=straight,waterlogged=false])
B(-5,11,2,minecraft:stone_brick_slab[type=top,waterlogged=false])
B(-5,12,2,minecraft:jungle_leaves[distance=7,persistent=true])
B(-5,0,3,minecraft:stone_brick_slab)
B(-5,8,3,minecraft:stone_brick_stairs[facing=east,half=bottom,shape=straight,waterlogged=false])
B(-5,12,3,minecraft:stone_brick_slab)
B(-5,8,4,minecraft:stone_brick_stairs[facing=east,half=bottom,shape=outer_left,waterlogged=false])
B(-5,11,4,minecraft:stone_brick_slab[type=top,waterlogged=false])
B(-5,4,5,minecraft:vine[east=false,north=true,south=false,up=false,west=false])
B(-5,7,5,minecraft:stone_brick_stairs)
B(-5,10,5,minecraft:stone_brick_stairs[facing=north,half=top,shape=straight,waterlogged=false])
B(-5,12,6,minecraft:stone_brick_slab)
B(-5,6,7,minecraft:stone_brick_stairs)
B(-5,2,8,minecraft:stone_brick_slab[type=top,waterlogged=false])
B(-5,3,8,minecraft:grass_block)
B(-5,4,8,minecraft:jungle_leaves[distance=7,persistent=true])
B(-5,5,8,minecraft:jungle_leaves[distance=7,persistent=true])
B(-4,0,-7,minecraft:stone_brick_slab)
B(-4,0,-6,minecraft:stone_brick_slab)
B(-4,4,-6,minecraft:vine[east=false,north=false,south=true,up=false,west=false])
B(-4,5,-6,minecraft:vine[east=false,north=false,south=true,up=false,west=false])
B(-4,6,-6,minecraft:vine[east=false,north=false,south=true,up=false,west=false])
B(-4,7,-6,minecraft:vine[east=false,north=false,south=true,up=false,west=false])
B(-4,8,-6,minecraft:vine[east=false,north=false,south=true,up=false,west=false])
B(-4,10,-6,minecraft:stone_brick_stairs[facing=south,half=top,shape=straight,waterlogged=false])
B(-4,12,-6,minecraft:stone_brick_slab)
B(-4,0,-5,minecraft:stone_brick_slab)
B(-4,8,-5,minecraft:stone_brick_stairs[facing=south,half=bottom,shape=straight,waterlogged=false])
B(-4,12,-5,minecraft:stone_brick_slab)
B(-4,3,-4,minecraft:stone_brick_stairs[facing=north,half=bottom,shape=inner_left,waterlogged=false])
B(-4,8,-4,minecraft:stone_brick_stairs[facing=south,half=top,shape=outer_left,waterlogged=false])
B(-4,9,-4,minecraft:stone_brick_stairs[facing=north,half=bottom,shape=inner_left,waterlogged=false])
B(-4,12,-4,minecraft:stone_brick_slab)
B(-4,3,-3,minecraft:stone_brick_stairs[facing=west,half=bottom,shape=straight,waterlogged=false])
B(-4,8,-3,minecraft:stone_brick_stairs[facing=east,half=top,shape=straight,waterlogged=false])
B(-4,9,-3,minecraft:stone_brick_stairs[facing=west,half=bottom,shape=straight,waterlogged=false])
B(-4,11,-3,minecraft:stone_brick_slab[type=top,waterlogged=false])
B(-4,12,-3,minecraft:jungle_leaves[distance=7,persistent=true])
B(-4,3,-2,minecraft:stone_brick_stairs[facing=west,half=bottom,shape=straight,waterlogged=false])
B(-4,8,-2,minecraft:stone_brick_stairs[facing=east,half=top,shape=straight,waterlogged=false])
B(-4,9,-2,minecraft:stone_brick_stairs[facing=west,half=bottom,shape=straight,waterlogged=false])
B(-4,12,-2,minecraft:stone_brick_slab)
B(-4,0,-1,minecraft:water)
B(-4,3,-1,minecraft:stone_brick_stairs[facing=west,half=bottom,shape=straight,waterlogged=false])
B(-4,8,-1,minecraft:stone_brick_stairs[facing=east,half=top,shape=straight,waterlogged=false])
B(-4,9,-1,minecraft:stone_brick_stairs[facing=west,half=bottom,shape=straight,waterlogged=false])
B(-4,12,-1,minecraft:stone_brick_stairs[facing=west,half=top,shape=straight,waterlogged=false])
B(-4,13,-1,minecraft:jungle_leaves[distance=7,persistent=true])
B(-4,0,0,minecraft:water)
B(-4,3,0,minecraft:stone_brick_stairs[facing=west,half=bottom,shape=straight,waterlogged=false])
B(-4,8,0,minecraft:stone_brick_stairs[facing=east,half=top,shape=straight,waterlogged=false])
B(-4,9,0,minecraft:stone_brick_stairs[facing=west,half=bottom,shape=straight,waterlogged=false])
B(-4,12,0,minecraft:stone_brick_stairs[facing=west,half=top,shape=straight,waterlogged=false])
B(-4,3,1,minecraft:stone_brick_stairs[facing=west,half=bottom,shape=straight,waterlogged=false])
B(-4,8,1,minecraft:stone_brick_stairs[facing=east,half=top,shape=straight,waterlogged=false])
B(-4,9,1,minecraft:stone_brick_stairs[facing=west,half=bottom,shape=straight,waterlogged=false])
B(-4,12,1,minecraft:stone_brick_slab)
B(-4,3,2,minecraft:stone_brick_stairs[facing=west,half=bottom,shape=straight,waterlogged=false])
B(-4,8,2,minecraft:stone_brick_stairs[facing=east,half=top,shape=straight,waterlogged=false])
B(-4,9,2,minecraft:stone_brick_stairs[facing=west,half=bottom,shape=straight,waterlogged=false])
B(-4,11,2,minecraft:stone_brick_slab[type=top,waterlogged=false])
B(-4,12,2,minecraft:jungle_leaves[distance=7,persistent=true])
B(-4,3,3,minecraft:stone_brick_stairs[facing=south,half=bottom,shape=inner_right,waterlogged=false])
B(-4,8,3,minecraft:stone_brick_stairs[facing=north,half=top,shape=outer_right,waterlogged=false])
B(-4,9,3,minecraft:stone_brick_stairs[facing=south,half=bottom,shape=inner_right,waterlogged=false])
B(-4,12,3,minecraft:stone_brick_slab)
B(-4,0,4,minecraft:stone_brick_slab)
B(-4,8,4,minecraft:stone_brick_stairs)
B(-4,12,4,minecraft:stone_brick_slab)
B(-4,0,5,minecraft:stone_brick_slab)
B(-4,4,5,minecraft:vine[east=false,north=true,south=false,up=false,west=false])
B(-4,5,5,minecraft:vine[east=false,north=true,south=false,up=false,west=false])
B(-4,6,5,minecraft:vine[east=false,north=true,south=false,up=false,west=false])
B(-4,10,5,minecraft:stone_brick_stairs[facing=north,half=top,shape=straight,waterlogged=false])
B(-4,12,5,minecraft:stone_brick_slab)
B(-4,0,6,minecraft:stone_brick_slab)
B(-4,12,6,minecraft:stone_brick_slab)
B(-4,0,7,minecraft:stone_brick_slab)
B(-4,6,7,minecraft:stone_brick_slab)
B(-4,0,8,minecraft:stone_brick_slab)
B(-4,2,8,minecraft:stone_brick_slab[type=top,waterlogged=false])
B(-4,3,8,minecraft:grass_block)
B(-3,4,-6,minecraft:vine[east=false,north=false,south=true,up=false,west=false])
B(-3,5,-6,minecraft:vine[east=false,north=false,south=true,up=false,west=false])
B(-3,6,-6,minecraft:vine[east=false,north=false,south=true,up=false,west=false])
B(-3,7,-6,minecraft:vine[east=false,north=false,south=true,up=false,west=false])
B(-3,8,-6,minecraft:vine[east=false,north=false,south=true,up=false,west=false])
B(-3,10,-6,minecraft:stone_brick_stairs[facing=south,half=top,shape=straight,waterlogged=false])
B(-3,8,-5,minecraft:stone_brick_stairs[facing=south,half=bottom,shape=straight,waterlogged=false])
B(-3,11,-5,minecraft:stone_brick_slab[type=top,waterlogged=false])
B(-3,12,-5,minecraft:jungle_leaves[distance=7,persistent=true])
B(-3,3,-4,minecraft:stone_brick_stairs)
B(-3,8,-4,minecraft:stone_brick_stairs[facing=south,half=top,shape=straight,waterlogged=false])
B(-3,9,-4,minecraft:stone_brick_stairs)
B(-3,11,-4,minecraft:stone_brick_slab[type=top,waterlogged=false])
B(-3,12,-4,minecraft:jungle_leaves[distance=7,persistent=true])
B(-3,2,-3,minecraft:stone_brick_stairs[facing=west,half=bottom,shape=inner_right,waterlogged=false])
B(-3,7,-3,minecraft:stone_brick_stairs[facing=south,half=top,shape=outer_left,waterlogged=false])
B(-3,8,-3,minecraft:stone_brick_stairs[facing=west,half=bottom,shape=inner_right,waterlogged=false])
B(-3,11,-3,minecraft:stone_brick_slab[type=top,waterlogged=false])
B(-3,12,-3,minecraft:jungle_leaves[distance=7,persistent=true])
B(-3,13,-3,minecraft:jungle_leaves[distance=7,persistent=true])
B(-3,2,-2,minecraft:stone_brick_stairs[facing=west,half=bottom,shape=straight,waterlogged=false])
B(-3,7,-2,minecraft:stone_brick_stairs[facing=east,half=top,shape=straight,waterlogged=false])
B(-3,8,-2,minecraft:stone_brick_stairs[facing=west,half=bottom,shape=straight,waterlogged=false])
B(-3,12,-2,minecraft:stone_brick_slab)
B(-3,0,-1,minecraft:water)
B(-3,1,-1,minecraft:gold_block)
B(-3,7,-1,minecraft:stone_brick_stairs[facing=east,half=top,shape=straight,waterlogged=false])
B(-3,8,-1,minecraft:stone_brick_stairs[facing=west,half=bottom,shape=straight,waterlogged=false])
B(-3,12,-1,minecraft:jungle_leaves[distance=7,persistent=true])
B(-3,13,-1,minecraft:jungle_leaves[distance=7,persistent=true])
B(-3,0,0,minecraft:water)
B(-3,1,0,minecraft:gold_block)
B(-3,7,0,minecraft:stone_brick_stairs[facing=east,half=top,shape=straight,waterlogged=false])
B(-3,8,0,minecraft:stone_brick_stairs[facing=west,half=bottom,shape=straight,waterlogged=false])
B(-3,12,0,minecraft:jungle_leaves[distance=7,persistent=true])
B(-3,2,1,minecraft:stone_brick_stairs[facing=west,half=bottom,shape=straight,waterlogged=false])
B(-3,7,1,minecraft:stone_brick_stairs[facing=east,half=top,shape=straight,waterlogged=false])
B(-3,8,1,minecraft:stone_brick_stairs[facing=west,half=bottom,shape=straight,waterlogged=false])
B(-3,12,1,minecraft:stone_brick_slab)
B(-3,2,2,minecraft:stone_brick_stairs[facing=south,half=bottom,shape=inner_right,waterlogged=false])
B(-3,7,2,minecraft:stone_brick_stairs[facing=north,half=top,shape=outer_right,waterlogged=false])
B(-3,8,2,minecraft:stone_brick_stairs[facing=west,half=bottom,shape=inner_left,waterlogged=false])
B(-3,11,2,minecraft:stone_brick_slab[type=top,waterlogged=false])
B(-3,12,2,minecraft:jungle_leaves[distance=7,persistent=true])
B(-3,13,2,minecraft:jungle_leaves[distance=7,persistent=true])
B(-3,3,3,minecraft:stone_brick_stairs[facing=south,half=bottom,shape=straight,waterlogged=false])
B(-3,8,3,minecraft:stone_brick_stairs[facing=north,half=top,shape=straight,waterlogged=false])
B(-3,9,3,minecraft:stone_brick_stairs[facing=south,half=bottom,shape=straight,waterlogged=false])
B(-3,11,3,minecraft:stone_brick_slab[type=top,waterlogged=false])
B(-3,12,3,minecraft:jungle_leaves[distance=7,persistent=true])
B(-3,13,3,minecraft:jungle_leaves[distance=7,persistent=true])
B(-3,8,4,minecraft:stone_brick_stairs)
B(-3,11,4,minecraft:stone_brick_slab[type=top,waterlogged=false])
B(-3,12,4,minecraft:jungle_leaves[distance=7,persistent=true])
B(-3,4,5,minecraft:vine[east=true,north=true,south=false,up=false,west=false])
B(-3,5,5,minecraft:vine[east=true,north=true,south=false,up=false,west=false])
B(-3,6,5,minecraft:vine[east=true,north=true,south=false,up=false,west=false])
B(-3,7,5,minecraft:vine[east=true,north=true,south=false,up=false,west=false])
B(-3,8,5,minecraft:vine[east=true,north=true,south=false,up=false,west=false])
B(-3,9,5,minecraft:vine[east=true,north=false,south=false,up=false,west=false])
B(-3,10,5,minecraft:stone_brick_stairs[facing=north,half=top,shape=straight,waterlogged=false])
B(-3,4,6,minecraft:vine[east=true,north=false,south=false,up=false,west=false])
B(-3,5,6,minecraft:vine[east=true,north=false,south=false,up=false,west=false])
B(-3,6,6,minecraft:vine[east=true,north=false,south=false,up=false,west=false])
B(-3,7,6,minecraft:vine[east=true,north=false,south=false,up=false,west=false])
B(-3,8,6,minecraft:vine[east=true,north=false,south=false,up=false,west=false])
B(-3,9,6,minecraft:vine[east=true,north=false,south=false,up=false,west=false])
B(-3,10,6,minecraft:vine[east=true,north=false,south=false,up=false,west=false])
B(-3,11,6,minecraft:stone_brick_stairs[facing=north,half=top,shape=straight,waterlogged=false])
B(-3,12,6,minecraft:stone_brick_slab)
B(-3,6,7,minecraft:stone_brick_slab)
B(-3,2,8,minecraft:stone_brick_slab[type=top,waterlogged=false])
B(-3,3,8,minecraft:grass_block)
B(-2,0,-7,minecraft:water)
B(-2,6,-7,minecraft:stone_brick_slab)
B(-2,12,-7,minecraft:stone_brick_slab)
B(-2,0,-6,minecraft:water)
B(-2,7,-6,minecraft:stone_brick_stairs[facing=south,half=bottom,shape=straight,waterlogged=false])
B(-2,10,-6,minecraft:stone_brick_stairs[facing=south,half=top,shape=straight,waterlogged=false])
B(-2,12,-6,minecraft:jungle_leaves[distance=7,persistent=true])
B(-2,0,-5,minecraft:water)
B(-2,8,-5,minecraft:stone_brick_stairs[facing=south,half=bottom,shape=straight,waterlogged=false])
B(-2,12,-5,minecraft:stone_brick_slab)
B(-2,3,-4,minecraft:stone_brick_stairs)
B(-2,8,-4,minecraft:stone_brick_stairs[facing=south,half=top,shape=straight,waterlogged=false])
B(-2,9,-4,minecraft:stone_brick_stairs)
B(-2,12,-4,minecraft:stone_brick_slab)
B(-2,2,-3,minecraft:stone_brick_stairs)
B(-2,7,-3,minecraft:stone_brick_stairs[facing=south,half=top,shape=straight,waterlogged=false])
B(-2,8,-3,minecraft:stone_brick_stairs)
B(-2,12,-3,minecraft:stone_brick_slab)
B(-2,1,-2,minecraft:stone_brick_stairs[facing=west,half=bottom,shape=inner_right,waterlogged=false])
B(-2,6,-2,minecraft:stone_brick_stairs[facing=south,half=top,shape=outer_left,waterlogged=false])
B(-2,7,-2,minecraft:stone_brick_stairs[facing=west,half=bottom,shape=inner_right,waterlogged=false])
B(-2,12,-2,minecraft:stone_brick_slab)
B(-2,0,-1,minecraft:water)
B(-2,1,-1,minecraft:stone_brick_stairs[facing=west,half=bottom,shape=straight,waterlogged=false])
B(-2,6,-1,minecraft:stone_brick_stairs[facing=east,half=top,shape=straight,waterlogged=false])
B(-2,7,-1,minecraft:stone_brick_stairs[facing=west,half=bottom,shape=straight,waterlogged=false])
B(-2,0,0,minecraft:water)
B(-2,1,0,minecraft:stone_brick_stairs[facing=west,half=bottom,shape=straight,waterlogged=false])
B(-2,6,0,minecraft:stone_brick_stairs[facing=east,half=top,shape=straight,waterlogged=false])
B(-2,7,0,minecraft:stone_brick_stairs[facing=west,half=bottom,shape=straight,waterlogged=false])
B(-2,11,0,minecraft:jungle_leaves[distance=7,persistent=true])
B(-2,1,1,minecraft:stone_brick_stairs[facing=west,half=bottom,shape=inner_left,waterlogged=false])
B(-2,6,1,minecraft:stone_brick_stairs[facing=north,half=top,shape=outer_right,waterlogged=false])
B(-2,7,1,minecraft:stone_brick_stairs[facing=south,half=bottom,shape=inner_right,waterlogged=false])
B(-2,10,1,minecraft:jungle_leaves[distance=7,persistent=true])
B(-2,11,1,minecraft:jungle_leaves[distance=7,persistent=true])
B(-2,12,1,minecraft:stone_brick_slab)
B(-2,2,2,minecraft:stone_brick_stairs[facing=south,half=bottom,shape=straight,waterlogged=false])
B(-2,7,2,minecraft:stone_brick_stairs[facing=north,half=top,shape=straight,waterlogged=false])
B(-2,8,2,minecraft:stone_brick_stairs[facing=south,half=bottom,shape=straight,waterlogged=false])
B(-2,12,2,minecraft:stone_brick_slab)
B(-2,3,3,minecraft:stone_brick_stairs[facing=south,half=bottom,shape=straight,waterlogged=false])
B(-2,8,3,minecraft:stone_brick_stairs[facing=north,half=top,shape=straight,waterlogged=false])
B(-2,9,3,minecraft:stone_brick_stairs[facing=south,half=bottom,shape=straight,waterlogged=false])
B(-2,12,3,minecraft:stone_brick_slab)
B(-2,0,4,minecraft:water)
B(-2,8,4,minecraft:stone_brick_stairs)
B(-2,12,4,minecraft:stone_brick_slab)
B(-2,0,5,minecraft:water)
B(-2,7,5,minecraft:stone_brick_stairs)
B(-2,9,5,minecraft:jungle_leaves[distance=7,persistent=true])
B(-2,10,5,minecraft:stone_brick_stairs[facing=north,half=top,shape=straight,waterlogged=false])
B(-2,12,5,minecraft:stone_brick_slab)
B(-2,0,6,minecraft:water)
B(-2,9,6,minecraft:jungle_leaves[distance=7,persistent=true])
B(-2,10,6,minecraft:jungle_leaves[distance=7,persistent=true])
B(-2,11,6,minecraft:jungle_leaves[distance=7,persistent=true])
B(-2,12,6,minecraft:stone_brick_slab)
B(-2,0,7,minecraft:water)
B(-2,6,7,minecraft:stone_brick_stairs)
B(-2,7,7,minecraft:vine[east=false,north=true,south=false,up=false,west=false])
B(-2,8,7,minecraft:vine[east=false,north=true,south=false,up=false,west=false])
B(-2,9,7,minecraft:vine[east=false,north=true,south=false,up=false,west=false])
B(-2,10,7,minecraft:vine[east=false,north=true,south=false,up=false,west=false])
B(-2,11,7,minecraft:vine[east=false,north=true,south=false,up=false,west=false])
B(-2,1,8,minecraft:stone_brick_slab)
B(-2,2,8,minecraft:stone_brick_slab[type=top,waterlogged=false])
B(-2,3,8,minecraft:grass_block)
B(-2,4,8,minecraft:stone_brick_stairs)
B(-1,0,-7,minecraft:water)
B(-1,12,-7,minecraft:stone_brick_slab)
B(-1,0,-6,minecraft:water)
B(-1,10,-6,minecraft:stone_brick_stairs[facing=south,half=top,shape=straight,waterlogged=false])
B(-1,12,-6,minecraft:jungle_leaves[distance=7,persistent=true])
B(-1,0,-5,minecraft:water)
B(-1,8,-5,minecraft:stone_brick_stairs[facing=south,half=bottom,shape=straight,waterlogged=false])
B(-1,11,-5,minecraft:stone_brick_slab[type=top,waterlogged=false])
B(-1,12,-5,minecraft:stone_brick_stairs[facing=south,half=bottom,shape=straight,waterlogged=false])
B(-1,0,-4,minecraft:water)
B(-1,3,-4,minecraft:stone_brick_stairs)
B(-1,8,-4,minecraft:stone_brick_stairs[facing=south,half=top,shape=straight,waterlogged=false])
B(-1,9,-4,minecraft:stone_brick_stairs)
B(-1,12,-4,minecraft:stone_brick_stairs[facing=north,half=top,shape=straight,waterlogged=false])
B(-1,0,-3,minecraft:water)
B(-1,1,-3,minecraft:gold_block)
B(-1,7,-3,minecraft:stone_brick_stairs[facing=south,half=top,shape=straight,waterlogged=false])
B(-1,8,-3,minecraft:stone_brick_stairs)
B(-1,0,-2,minecraft:water)
B(-1,1,-2,minecraft:stone_brick_stairs)
B(-1,6,-2,minecraft:stone_brick_stairs[facing=south,half=top,shape=straight,waterlogged=false])
B(-1,7,-2,minecraft:stone_brick_stairs)
B(-1,0,-1,minecraft:water)
B(-1,0,0,minecraft:water)
B(-1,0,1,minecraft:water)
B(-1,1,1,minecraft:stone_brick_stairs[facing=south,half=bottom,shape=straight,waterlogged=false])
B(-1,6,1,minecraft:stone_brick_stairs[facing=north,half=top,shape=straight,waterlogged=false])
B(-1,7,1,minecraft:stone_brick_stairs[facing=south,half=bottom,shape=straight,waterlogged=false])
B(-1,0,2,minecraft:water)
B(-1,1,2,minecraft:gold_block)
B(-1,7,2,minecraft:stone_brick_stairs[facing=north,half=top,shape=straight,waterlogged=false])
B(-1,8,2,minecraft:stone_brick_stairs[facing=south,half=bottom,shape=straight,waterlogged=false])
B(-1,0,3,minecraft:water)
B(-1,3,3,minecraft:stone_brick_stairs[facing=south,half=bottom,shape=straight,waterlogged=false])
B(-1,8,3,minecraft:stone_brick_stairs[facing=north,half=top,shape=straight,waterlogged=false])
B(-1,9,3,minecraft:stone_brick_stairs[facing=south,half=bottom,shape=straight,waterlogged=false])
B(-1,12,3,minecraft:stone_brick_stairs[facing=south,half=top,shape=straight,waterlogged=false])
B(-1,0,4,minecraft:water)
B(-1,8,4,minecraft:jungle_leaves[distance=7,persistent=true])
B(-1,9,4,minecraft:jungle_leaves[distance=7,persistent=true])
B(-1,11,4,minecraft:stone_brick_slab[type=top,waterlogged=false])
B(-1,12,4,minecraft:stone_brick_stairs)
B(-1,0,5,minecraft:water)
B(-1,9,5,minecraft:jungle_leaves[distance=7,persistent=true])
B(-1,10,5,minecraft:stone_brick_stairs[facing=north,half=top,shape=straight,waterlogged=false])
B(-1,12,5,minecraft:jungle_leaves[distance=7,persistent=true])
B(-1,0,6,minecraft:water)
B(-1,11,6,minecraft:jungle_leaves[distance=7,persistent=true])
B(-1,0,7,minecraft:water)
B(-1,6,7,minecraft:stone_brick_slab)
B(-1,7,7,minecraft:vine[east=false,north=true,south=false,up=false,west=false])
B(-1,8,7,minecraft:vine[east=false,north=true,south=false,up=false,west=false])
B(-1,9,7,minecraft:vine[east=false,north=true,south=false,up=false,west=false])
B(-1,10,7,minecraft:vine[east=false,north=true,south=false,up=false,west=false])
B(-1,11,7,minecraft:vine[east=false,north=true,south=false,up=false,west=false])
B(-1,1,8,minecraft:stone_brick_slab)
B(-1,2,8,minecraft:stone_brick_slab[type=top,waterlogged=false])
B(-1,3,8,minecraft:grass_block)
B(0,0,-7,minecraft:water)
B(0,10,-7,minecraft:jungle_leaves[distance=7,persistent=true])
B(0,11,-7,minecraft:jungle_leaves[distance=7,persistent=true])
B(0,12,-7,minecraft:jungle_leaves[distance=7,persistent=true])
B(0,0,-6,minecraft:water)
B(0,9,-6,minecraft:jungle_leaves[distance=7,persistent=true])
B(0,10,-6,minecraft:stone_brick_stairs[facing=south,half=top,shape=straight,waterlogged=false])
B(0,12,-6,minecraft:jungle_leaves[distance=7,persistent=true])
B(0,0,-5,minecraft:water)
B(0,8,-5,minecraft:stone_brick_stairs[facing=south,half=bottom,shape=straight,waterlogged=false])
B(0,11,-5,minecraft:stone_brick_slab[type=top,waterlogged=false])
B(0,12,-5,minecraft:stone_brick_stairs[facing=south,half=bottom,shape=straight,waterlogged=false])
B(0,0,-4,minecraft:water)
B(0,3,-4,minecraft:stone_brick_stairs)
B(0,8,-4,minecraft:stone_brick_stairs[facing=south,half=top,shape=straight,waterlogged=false])
B(0,9,-4,minecraft:stone_brick_stairs)
B(0,12,-4,minecraft:stone_brick_stairs[facing=north,half=top,shape=straight,waterlogged=false])
B(0,0,-3,minecraft:water)
B(0,1,-3,minecraft:gold_block)
B(0,7,-3,minecraft:stone_brick_stairs[facing=south,half=top,shape=straight,waterlogged=false])
B(0,8,-3,minecraft:stone_brick_stairs)
B(0,0,-2,minecraft:water)
B(0,1,-2,minecraft:stone_brick_stairs)
B(0,6,-2,minecraft:stone_brick_stairs[facing=south,half=top,shape=straight,waterlogged=false])
B(0,7,-2,minecraft:stone_brick_stairs)
B(0,0,-1,minecraft:water)
B(0,0,0,minecraft:water)
B(0,0,1,minecraft:water)
B(0,1,1,minecraft:stone_brick_stairs[facing=south,half=bottom,shape=straight,waterlogged=false])
B(0,6,1,minecraft:stone_brick_stairs[facing=north,half=top,shape=straight,waterlogged=false])
B(0,7,1,minecraft:stone_brick_stairs[facing=south,half=bottom,shape=straight,waterlogged=false])
B(0,0,2,minecraft:water)
B(0,1,2,minecraft:gold_block)
B(0,7,2,minecraft:stone_brick_stairs[facing=north,half=top,shape=straight,waterlogged=false])
B(0,8,2,minecraft:stone_brick_stairs[facing=south,half=bottom,shape=straight,waterlogged=false])
B(0,10,2,minecraft:jungle_leaves[distance=7,persistent=true])
B(0,11,2,minecraft:jungle_leaves[distance=7,persistent=true])
B(0,12,2,minecraft:jungle_leaves[distance=7,persistent=true])
B(0,0,3,minecraft:water)
B(0,3,3,minecraft:stone_brick_stairs[facing=south,half=bottom,shape=straight,waterlogged=false])
B(0,8,3,minecraft:stone_brick_stairs[facing=north,half=top,shape=straight,waterlogged=false])
B(0,9,3,minecraft:stone_brick_stairs[facing=south,half=bottom,shape=straight,waterlogged=false])
B(0,12,3,minecraft:stone_brick_stairs[facing=south,half=top,shape=straight,waterlogged=false])
B(0,13,3,minecraft:jungle_leaves[distance=7,persistent=true])
B(0,0,4,minecraft:water)
B(0,8,4,minecraft:jungle_leaves[distance=7,persistent=true])
B(0,11,4,minecraft:stone_brick_slab[type=top,waterlogged=false])
B(0,12,4,minecraft:stone_brick_stairs)
B(0,0,5,minecraft:water)
B(0,8,5,minecraft:jungle_leaves[distance=7,persistent=true])
B(0,10,5,minecraft:stone_brick_stairs[facing=north,half=top,shape=straight,waterlogged=false])
B(0,12,5,minecraft:jungle_leaves[distance=7,persistent=true])
B(0,0,6,minecraft:water)
B(0,11,6,minecraft:jungle_leaves[distance=7,persistent=true])
B(0,12,6,minecraft:jungle_leaves[distance=7,persistent=true])
B(0,0,7,minecraft:water)
B(0,6,7,minecraft:stone_brick_slab)
B(0,1,8,minecraft:stone_brick_slab)
B(0,2,8,minecraft:stone_brick_slab[type=top,waterlogged=false])
B(0,3,8,minecraft:grass_block)
B(1,0,-7,minecraft:water)
B(1,7,-7,minecraft:vine[east=false,north=false,south=true,up=false,west=false])
B(1,8,-7,minecraft:vine[east=false,north=false,south=true,up=false,west=false])
B(1,9,-7,minecraft:vine[east=false,north=false,south=true,up=false,west=false])
B(1,10,-7,minecraft:vine[east=false,north=false,south=true,up=false,west=false])
B(1,12,-7,minecraft:jungle_leaves[distance=7,persistent=true])
B(1,0,-6,minecraft:water)
B(1,7,-6,minecraft:stone_brick_stairs[facing=south,half=bottom,shape=straight,waterlogged=false])
B(1,9,-6,minecraft:jungle_leaves[distance=7,persistent=true])
B(1,10,-6,minecraft:stone_brick_stairs[facing=south,half=top,shape=straight,waterlogged=false])
B(1,12,-6,minecraft:stone_brick_slab)
B(1,0,-5,minecraft:water)
B(1,8,-5,minecraft:stone_brick_stairs[facing=south,half=bottom,shape=straight,waterlogged=false])
B(1,12,-5,minecraft:stone_brick_slab)
B(1,3,-4,minecraft:stone_brick_stairs)
B(1,8,-4,minecraft:stone_brick_stairs[facing=south,half=top,shape=straight,waterlogged=false])
B(1,9,-4,minecraft:stone_brick_stairs)
B(1,12,-4,minecraft:stone_brick_slab)
B(1,2,-3,minecraft:stone_brick_stairs)
B(1,7,-3,minecraft:stone_brick_stairs[facing=south,half=top,shape=straight,waterlogged=false])
B(1,8,-3,minecraft:stone_brick_stairs)
B(1,12,-3,minecraft:stone_brick_slab)
B(1,1,-2,minecraft:stone_brick_stairs[facing=north,half=bottom,shape=inner_right,waterlogged=false])
B(1,6,-2,minecraft:stone_brick_stairs[facing=south,half=top,shape=outer_right,waterlogged=false])
B(1,7,-2,minecraft:stone_brick_stairs[facing=east,half=bottom,shape=inner_left,waterlogged=false])
B(1,12,-2,minecraft:stone_brick_slab)
B(1,0,-1,minecraft:water)
B(1,1,-1,minecraft:stone_brick_stairs[facing=east,half=bottom,shape=straight,waterlogged=false])
B(1,6,-1,minecraft:stone_brick_stairs[facing=west,half=top,shape=straight,waterlogged=false])
B(1,7,-1,minecraft:stone_brick_stairs[facing=east,half=bottom,shape=straight,waterlogged=false])
B(1,0,0,minecraft:water)
B(1,1,0,minecraft:stone_brick_stairs[facing=east,half=bottom,shape=straight,waterlogged=false])
B(1,6,0,minecraft:stone_brick_stairs[facing=west,half=top,shape=straight,waterlogged=false])
B(1,7,0,minecraft:stone_brick_stairs[facing=east,half=bottom,shape=straight,waterlogged=false])
B(1,1,1,minecraft:stone_brick_stairs[facing=south,half=bottom,shape=inner_left,waterlogged=false])
B(1,6,1,minecraft:stone_brick_stairs[facing=north,half=top,shape=outer_left,waterlogged=false])
B(1,7,1,minecraft:stone_brick_stairs[facing=east,half=bottom,shape=inner_right,waterlogged=false])
B(1,12,1,minecraft:stone_brick_slab)
B(1,2,2,minecraft:stone_brick_stairs[facing=south,half=bottom,shape=straight,waterlogged=false])
B(1,7,2,minecraft:stone_brick_stairs[facing=north,half=top,shape=straight,waterlogged=false])
B(1,8,2,minecraft:stone_brick_stairs[facing=south,half=bottom,shape=straight,waterlogged=false])
B(1,12,2,minecraft:stone_brick_slab)
B(1,3,3,minecraft:stone_brick_stairs[facing=south,half=bottom,shape=straight,waterlogged=false])
B(1,8,3,minecraft:stone_brick_stairs[facing=north,half=top,shape=straight,waterlogged=false])
B(1,9,3,minecraft:stone_brick_stairs[facing=south,half=bottom,shape=straight,waterlogged=false])
B(1,12,3,minecraft:stone_brick_slab)
B(1,0,4,minecraft:water)
B(1,8,4,minecraft:stone_brick_stairs)
B(1,12,4,minecraft:stone_brick_slab)
B(1,0,5,minecraft:water)
B(1,7,5,minecraft:stone_brick_stairs)
B(1,8,5,minecraft:jungle_leaves[distance=7,persistent=true])
B(1,10,5,minecraft:stone_brick_stairs[facing=north,half=top,shape=straight,waterlogged=false])
B(1,12,5,minecraft:stone_brick_slab)
B(1,0,6,minecraft:water)
B(1,12,6,minecraft:stone_brick_slab)
B(1,0,7,minecraft:water)
B(1,6,7,minecraft:stone_brick_stairs)
B(1,1,8,minecraft:stone_brick_slab)
B(1,2,8,minecraft:stone_brick_slab[type=top,waterlogged=false])
B(1,3,8,minecraft:grass_block)
B(1,4,8,minecraft:stone_brick_stairs)
B(2,6,-7,minecraft:jungle_leaves[distance=7,persistent=true])
B(2,11,-7,minecraft:stone_brick_stairs[facing=south,half=top,shape=straight,waterlogged=false])
B(2,12,-7,minecraft:stone_brick_slab)
B(2,6,-6,minecraft:jungle_leaves[distance=7,persistent=true])
B(2,7,-6,minecraft:jungle_leaves[distance=7,persistent=true])
B(2,8,-6,minecraft:jungle_leaves[distance=7,persistent=true])
B(2,9,-6,minecraft:vine[east=false,north=false,south=false,up=false,west=true])
B(2,10,-6,minecraft:stone_brick_stairs[facing=south,half=top,shape=straight,waterlogged=false])
B(2,12,-6,minecraft:jungle_leaves[distance=7,persistent=true])
B(2,8,-5,minecraft:stone_brick_stairs[facing=south,half=bottom,shape=straight,waterlogged=false])
B(2,11,-5,minecraft:stone_brick_slab[type=top,waterlogged=false])
B(2,12,-5,minecraft:jungle_leaves[distance=7,persistent=true])
B(2,3,-4,minecraft:stone_brick_stairs)
B(2,8,-4,minecraft:stone_brick_stairs[facing=south,half=top,shape=straight,waterlogged=false])
B(2,9,-4,minecraft:stone_brick_stairs)
B(2,11,-4,minecraft:stone_brick_slab[type=top,waterlogged=false])
B(2,2,-3,minecraft:stone_brick_stairs[facing=north,half=bottom,shape=inner_right,waterlogged=false])
B(2,7,-3,minecraft:stone_brick_stairs[facing=west,half=top,shape=outer_left,waterlogged=false])
B(2,8,-3,minecraft:stone_brick_stairs[facing=north,half=bottom,shape=inner_right,waterlogged=false])
B(2,11,-3,minecraft:stone_brick_slab[type=top,waterlogged=false])
B(2,12,-3,minecraft:jungle_leaves[distance=7,persistent=true])
B(2,13,-3,minecraft:jungle_leaves[distance=7,persistent=true])
B(2,2,-2,minecraft:stone_brick_stairs[facing=east,half=bottom,shape=straight,waterlogged=false])
B(2,7,-2,minecraft:stone_brick_stairs[facing=west,half=top,shape=straight,waterlogged=false])
B(2,8,-2,minecraft:stone_brick_stairs[facing=east,half=bottom,shape=straight,waterlogged=false])
B(2,12,-2,minecraft:stone_brick_slab)
B(2,0,-1,minecraft:water)
B(2,1,-1,minecraft:gold_block)
B(2,7,-1,minecraft:stone_brick_stairs[facing=west,half=top,shape=straight,waterlogged=false])
B(2,8,-1,minecraft:stone_brick_stairs[facing=east,half=bottom,shape=straight,waterlogged=false])
B(2,0,0,minecraft:water)
B(2,1,0,minecraft:gold_block)
B(2,7,0,minecraft:stone_brick_stairs[facing=west,half=top,shape=straight,waterlogged=false])
B(2,8,0,minecraft:stone_brick_stairs[facing=east,half=bottom,shape=straight,waterlogged=false])
B(2,10,0,minecraft:jungle_leaves[distance=7,persistent=true])
B(2,11,0,minecraft:jungle_leaves[distance=7,persistent=true])
B(2,12,0,minecraft:jungle_leaves[distance=7,persistent=true])
B(2,13,0,minecraft:jungle_leaves[distance=7,persistent=true])
B(2,2,1,minecraft:stone_brick_stairs[facing=east,half=bottom,shape=straight,waterlogged=false])
B(2,7,1,minecraft:stone_brick_stairs[facing=west,half=top,shape=straight,waterlogged=false])
B(2,8,1,minecraft:stone_brick_stairs[facing=east,half=bottom,shape=straight,waterlogged=false])
B(2,12,1,minecraft:stone_brick_slab)
B(2,13,1,minecraft:jungle_leaves[distance=7,persistent=true])
B(2,14,1,minecraft:jungle_leaves[distance=7,persistent=true])
B(2,2,2,minecraft:stone_brick_stairs[facing=east,half=bottom,shape=inner_right,waterlogged=false])
B(2,7,2,minecraft:stone_brick_stairs[facing=north,half=top,shape=outer_left,waterlogged=false])
B(2,8,2,minecraft:stone_brick_stairs[facing=east,half=bottom,shape=inner_right,waterlogged=false])
B(2,11,2,minecraft:stone_brick_slab[type=top,waterlogged=false])
B(2,12,2,minecraft:jungle_leaves[distance=7,persistent=true])
B(2,13,2,minecraft:jungle_leaves[distance=7,persistent=true])
B(2,3,3,minecraft:stone_brick_stairs[facing=south,half=bottom,shape=straight,waterlogged=false])
B(2,8,3,minecraft:stone_brick_stairs[facing=north,half=top,shape=straight,waterlogged=false])
B(2,9,3,minecraft:stone_brick_stairs[facing=south,half=bottom,shape=straight,waterlogged=false])
B(2,11,3,minecraft:stone_brick_slab[type=top,waterlogged=false])
B(2,12,3,minecraft:jungle_leaves[distance=7,persistent=true])
B(2,8,4,minecraft:stone_brick_stairs)
B(2,11,4,minecraft:stone_brick_slab[type=top,waterlogged=false])
B(2,12,4,minecraft:jungle_leaves[distance=7,persistent=true])
B(2,6,5,minecraft:jungle_leaves[distance=7,persistent=true])
B(2,7,5,minecraft:jungle_leaves[distance=7,persistent=true])
B(2,8,5,minecraft:vine[east=false,north=true,south=false,up=false,west=false])
B(2,10,5,minecraft:stone_brick_stairs[facing=north,half=top,shape=straight,waterlogged=false])
B(2,6,6,minecraft:jungle_leaves[distance=7,persistent=true])
B(2,11,6,minecraft:stone_brick_stairs[facing=north,half=top,shape=straight,waterlogged=false])
B(2,12,6,minecraft:stone_brick_slab)
B(2,5,7,minecraft:jungle_leaves[distance=7,persistent=true])
B(2,6,7,minecraft:jungle_leaves[distance=7,persistent=true])
B(2,2,8,minecraft:stone_brick_slab[type=top,waterlogged=false])
B(2,3,8,minecraft:grass_block)
B(2,4,8,minecraft:jungle_leaves[distance=7,persistent=true])
B(2,5,8,minecraft:jungle_leaves[distance=7,persistent=true])
B(3,0,-7,minecraft:stone_brick_slab)
B(3,12,-7,minecraft:stone_brick_slab)
B(3,0,-6,minecraft:stone_brick_slab)
B(3,7,-6,minecraft:jungle_leaves[distance=7,persistent=true])
B(3,10,-6,minecraft:stone_brick_stairs[facing=south,half=top,shape=straight,waterlogged=false])
B(3,12,-6,minecraft:stone_brick_slab)
B(3,0,-5,minecraft:stone_brick_slab)
B(3,8,-5,minecraft:stone_brick_stairs[facing=south,half=bottom,shape=straight,waterlogged=false])
B(3,12,-5,minecraft:stone_brick_slab)
B(3,3,-4,minecraft:stone_brick_stairs[facing=east,half=bottom,shape=inner_left,waterlogged=false])
B(3,8,-4,minecraft:stone_brick_stairs[facing=south,half=top,shape=outer_right,waterlogged=false])
B(3,9,-4,minecraft:stone_brick_stairs[facing=north,half=bottom,shape=inner_right,waterlogged=false])
B(3,12,-4,minecraft:stone_brick_slab)
B(3,3,-3,minecraft:stone_brick_stairs[facing=east,half=bottom,shape=straight,waterlogged=false])
B(3,8,-3,minecraft:stone_brick_stairs[facing=west,half=top,shape=straight,waterlogged=false])
B(3,9,-3,minecraft:stone_brick_stairs[facing=east,half=bottom,shape=straight,waterlogged=false])
B(3,11,-3,minecraft:stone_brick_slab[type=top,waterlogged=false])
B(3,12,-3,minecraft:jungle_leaves[distance=7,persistent=true])
B(3,3,-2,minecraft:stone_brick_stairs[facing=east,half=bottom,shape=straight,waterlogged=false])
B(3,8,-2,minecraft:stone_brick_stairs[facing=west,half=top,shape=straight,waterlogged=false])
B(3,9,-2,minecraft:stone_brick_stairs[facing=east,half=bottom,shape=straight,waterlogged=false])
B(3,12,-2,minecraft:stone_brick_slab)
B(3,0,-1,minecraft:water)
B(3,3,-1,minecraft:stone_brick_stairs[facing=east,half=bottom,shape=straight,waterlogged=false])
B(3,8,-1,minecraft:stone_brick_stairs[facing=west,half=top,shape=straight,waterlogged=false])
B(3,9,-1,minecraft:stone_brick_stairs[facing=east,half=bottom,shape=straight,waterlogged=false])
B(3,12,-1,minecraft:stone_brick_stairs[facing=east,half=top,shape=straight,waterlogged=false])
B(3,0,0,minecraft:water)
B(3,3,0,minecraft:stone_brick_stairs[facing=east,half=bottom,shape=straight,waterlogged=false])
B(3,8,0,minecraft:stone_brick_stairs[facing=west,half=top,shape=straight,waterlogged=false])
B(3,9,0,minecraft:stone_brick_stairs[facing=east,half=bottom,shape=straight,waterlogged=false])
B(3,12,0,minecraft:stone_brick_stairs[facing=east,half=top,shape=straight,waterlogged=false])
B(3,13,0,minecraft:jungle_leaves[distance=7,persistent=true])
B(3,3,1,minecraft:stone_brick_stairs[facing=east,half=bottom,shape=straight,waterlogged=false])
B(3,8,1,minecraft:stone_brick_stairs[facing=west,half=top,shape=straight,waterlogged=false])
B(3,9,1,minecraft:stone_brick_stairs[facing=east,half=bottom,shape=straight,waterlogged=false])
B(3,12,1,minecraft:stone_brick_slab)
B(3,13,1,minecraft:jungle_leaves[distance=7,persistent=true])
B(3,3,2,minecraft:stone_brick_stairs[facing=east,half=bottom,shape=straight,waterlogged=false])
B(3,8,2,minecraft:stone_brick_stairs[facing=west,half=top,shape=straight,waterlogged=false])
B(3,9,2,minecraft:stone_brick_stairs[facing=east,half=bottom,shape=straight,waterlogged=false])
B(3,11,2,minecraft:stone_brick_slab[type=top,waterlogged=false])
B(3,12,2,minecraft:jungle_leaves[distance=7,persistent=true])
B(3,13,2,minecraft:jungle_leaves[distance=7,persistent=true])
B(3,3,3,minecraft:stone_brick_stairs[facing=south,half=bottom,shape=inner_left,waterlogged=false])
B(3,8,3,minecraft:stone_brick_stairs[facing=north,half=top,shape=outer_left,waterlogged=false])
B(3,9,3,minecraft:stone_brick_stairs[facing=east,half=bottom,shape=inner_right,waterlogged=false])
B(3,12,3,minecraft:stone_brick_slab)
B(3,0,4,minecraft:stone_brick_slab)
B(3,8,4,minecraft:stone_brick_stairs)
B(3,12,4,minecraft:stone_brick_slab)
B(3,0,5,minecraft:stone_brick_slab)
B(3,6,5,minecraft:jungle_leaves[distance=7,persistent=true])
B(3,10,5,minecraft:stone_brick_stairs[facing=north,half=top,shape=straight,waterlogged=false])
B(3,12,5,minecraft:stone_brick_slab)
B(3,0,6,minecraft:stone_brick_slab)
B(3,6,6,minecraft:jungle_leaves[distance=7,persistent=true])
B(3,7,6,minecraft:jungle_leaves[distance=7,persistent=true])
B(3,8,6,minecraft:jungle_leaves[distance=7,persistent=true])
B(3,12,6,minecraft:stone_brick_slab)
B(3,0,7,minecraft:stone_brick_slab)
B(3,6,7,minecraft:jungle_leaves[distance=7,persistent=true])
B(3,0,8,minecraft:stone_brick_slab)
B(3,2,8,minecraft:stone_brick_slab[type=top,waterlogged=false])
B(3,3,8,minecraft:grass_block)
B(3,4,8,minecraft:jungle_leaves[distance=7,persistent=true])
B(4,7,-6,minecraft:vine[east=false,north=false,south=true,up=false,west=false])
B(4,8,-6,minecraft:vine[east=false,north=false,south=true,up=false,west=false])
B(4,10,-6,minecraft:stone_brick_stairs[facing=south,half=top,shape=straight,waterlogged=false])
B(4,8,-5,minecraft:stone_brick_stairs[facing=south,half=bottom,shape=outer_right,waterlogged=false])
B(4,11,-5,minecraft:stone_brick_slab[type=top,waterlogged=false])
B(4,0,-4,minecraft:stone_brick_slab)
B(4,8,-4,minecraft:stone_brick_stairs[facing=west,half=bottom,shape=straight,waterlogged=false])
B(4,12,-4,minecraft:stone_brick_slab)
B(4,8,-3,minecraft:stone_brick_stairs[facing=west,half=bottom,shape=straight,waterlogged=false])
B(4,11,-3,minecraft:stone_brick_slab[type=top,waterlogged=false])
B(4,12,-3,minecraft:jungle_leaves[distance=7,persistent=true])
B(4,0,-2,minecraft:water)
B(4,8,-2,minecraft:stone_brick_stairs[facing=west,half=bottom,shape=straight,waterlogged=false])
B(4,12,-2,minecraft:stone_brick_slab)
B(4,0,-1,minecraft:water)
B(4,8,-1,minecraft:stone_brick_stairs[facing=west,half=bottom,shape=straight,waterlogged=false])
B(4,11,-1,minecraft:stone_brick_slab[type=top,waterlogged=false])
B(4,12,-1,minecraft:stone_brick_stairs[facing=west,half=bottom,shape=straight,waterlogged=false])
B(4,0,0,minecraft:water)
B(4,8,0,minecraft:stone_brick_stairs[facing=west,half=bottom,shape=straight,waterlogged=false])
B(4,11,0,minecraft:stone_brick_slab[type=top,waterlogged=false])
B(4,12,0,minecraft:stone_brick_stairs[facing=west,half=bottom,shape=straight,waterlogged=false])
B(4,0,1,minecraft:water)
B(4,8,1,minecraft:stone_brick_stairs[facing=west,half=bottom,shape=straight,waterlogged=false])
B(4,12,1,minecraft:stone_brick_slab)
B(4,8,2,minecraft:stone_brick_stairs[facing=west,half=bottom,shape=straight,waterlogged=false])
B(4,11,2,minecraft:stone_brick_slab[type=top,waterlogged=false])
B(4,12,2,minecraft:jungle_leaves[distance=7,persistent=true])
B(4,0,3,minecraft:stone_brick_slab)
B(4,8,3,minecraft:stone_brick_stairs[facing=west,half=bottom,shape=straight,waterlogged=false])
B(4,12,3,minecraft:stone_brick_slab)
B(4,8,4,minecraft:stone_brick_stairs[facing=west,half=bottom,shape=outer_right,waterlogged=false])
B(4,11,4,minecraft:stone_brick_slab[type=top,waterlogged=false])
B(4,12,4,minecraft:jungle_leaves[distance=7,persistent=true])
B(4,7,5,minecraft:stone_brick_stairs)
B(4,10,5,minecraft:stone_brick_stairs[facing=north,half=top,shape=straight,waterlogged=false])
B(4,12,5,minecraft:jungle_leaves[distance=7,persistent=true])
B(4,12,6,minecraft:stone_brick_slab)
B(4,6,7,minecraft:stone_brick_stairs)
B(4,2,8,minecraft:stone_brick_slab[type=top,waterlogged=false])
B(4,3,8,minecraft:grass_block)
B(4,4,8,minecraft:stone_brick_stairs)
B(5,10,-6,minecraft:stone_brick_stairs[facing=south,half=top,shape=outer_right,waterlogged=false])
B(5,12,-6,minecraft:stone_brick_slab)
B(5,7,-5,minecraft:stone_brick_stairs[facing=west,half=bottom,shape=straight,waterlogged=false])
B(5,10,-5,minecraft:stone_brick_stairs[facing=west,half=top,shape=straight,waterlogged=false])
B(5,12,-5,minecraft:jungle_leaves[distance=7,persistent=true])
B(5,0,-4,minecraft:stone_brick_slab)
B(5,7,-4,minecraft:jungle_leaves[distance=7,persistent=true])
B(5,10,-4,minecraft:stone_brick_stairs[facing=west,half=top,shape=straight,waterlogged=false])
B(5,12,-4,minecraft:stone_brick_slab)
B(5,7,-3,minecraft:jungle_leaves[distance=7,persistent=true])
B(5,8,-3,minecraft:jungle_leaves[distance=7,persistent=true])
B(5,10,-3,minecraft:stone_brick_stairs[facing=west,half=top,shape=straight,waterlogged=false])
B(5,0,-2,minecraft:water)
B(5,7,-2,minecraft:jungle_leaves[distance=7,persistent=true])
B(5,8,-2,minecraft:jungle_leaves[distance=7,persistent=true])
B(5,10,-2,minecraft:stone_brick_stairs[facing=west,half=top,shape=straight,waterlogged=false])
B(5,12,-2,minecraft:stone_brick_slab)
B(5,0,-1,minecraft:water)
B(5,8,-1,minecraft:jungle_leaves[distance=7,persistent=true])
B(5,9,-1,minecraft:jungle_leaves[distance=7,persistent=true])
B(5,10,-1,minecraft:stone_brick_stairs[facing=west,half=top,shape=straight,waterlogged=false])
B(5,12,-1,minecraft:jungle_leaves[distance=7,persistent=true])
B(5,0,0,minecraft:water)
B(5,4,0,minecraft:vine[east=false,north=true,south=false,up=false,west=true])
B(5,5,0,minecraft:vine[east=false,north=true,south=false,up=false,west=true])
B(5,6,0,minecraft:vine[east=false,north=true,south=false,up=false,west=true])
B(5,7,0,minecraft:vine[east=false,north=true,south=false,up=false,west=false])
B(5,8,0,minecraft:vine[east=false,north=true,south=false,up=false,west=false])
B(5,9,0,minecraft:jungle_leaves[distance=7,persistent=true])
B(5,10,0,minecraft:stone_brick_stairs[facing=west,half=top,shape=straight,waterlogged=false])
B(5,0,1,minecraft:water)
B(5,10,1,minecraft:stone_brick_stairs[facing=west,half=top,shape=straight,waterlogged=false])
B(5,12,1,minecraft:stone_brick_slab)
B(5,4,2,minecraft:vine[east=false,north=false,south=false,up=false,west=true])
B(5,5,2,minecraft:vine[east=false,north=false,south=false,up=false,west=true])
B(5,6,2,minecraft:vine[east=false,north=false,south=false,up=false,west=true])
B(5,7,2,minecraft:vine[east=false,north=false,south=false,up=false,west=true])
B(5,8,2,minecraft:vine[east=false,north=false,south=false,up=false,west=true])
B(5,10,2,minecraft:stone_brick_stairs[facing=west,half=top,shape=straight,waterlogged=false])
B(5,0,3,minecraft:stone_brick_slab)
B(5,4,3,minecraft:vine[east=false,north=false,south=false,up=false,west=true])
B(5,5,3,minecraft:vine[east=false,north=false,south=false,up=false,west=true])
B(5,6,3,minecraft:vine[east=false,north=false,south=false,up=false,west=true])
B(5,7,3,minecraft:vine[east=false,north=false,south=false,up=false,west=true])
B(5,8,3,minecraft:vine[east=false,north=false,south=false,up=false,west=true])
B(5,10,3,minecraft:stone_brick_stairs[facing=west,half=top,shape=straight,waterlogged=false])
B(5,12,3,minecraft:stone_brick_slab)
B(5,7,4,minecraft:stone_brick_stairs[facing=west,half=bottom,shape=straight,waterlogged=false])
B(5,8,4,minecraft:vine[east=false,north=false,south=false,up=false,west=true])
B(5,10,4,minecraft:stone_brick_stairs[facing=west,half=top,shape=straight,waterlogged=false])
B(5,10,5,minecraft:stone_brick_stairs[facing=west,half=top,shape=outer_right,waterlogged=false])
B(5,12,5,minecraft:stone_brick_slab)
B(5,11,6,minecraft:stone_brick_stairs[facing=north,half=top,shape=straight,waterlogged=false])
B(5,12,6,minecraft:stone_brick_slab)
B(5,6,7,minecraft:stone_brick_slab)
B(5,2,8,minecraft:stone_brick_slab[type=top,waterlogged=false])
B(5,3,8,minecraft:grass_block)
B(6,11,-6,minecraft:stone_brick_stairs[facing=west,half=top,shape=straight,waterlogged=false])
B(6,12,-6,minecraft:stone_brick_slab)
B(6,10,-5,minecraft:jungle_leaves[distance=7,persistent=true])
B(6,11,-5,minecraft:jungle_leaves[distance=7,persistent=true])
B(6,12,-5,minecraft:jungle_leaves[distance=7,persistent=true])
B(6,0,-4,minecraft:stone_brick_slab)
B(6,6,-4,minecraft:jungle_leaves[distance=7,persistent=true])
B(6,12,-4,minecraft:stone_brick_slab)
B(6,6,-3,minecraft:jungle_leaves[distance=7,persistent=true])
B(6,0,-2,minecraft:water)
B(6,0,-1,minecraft:water)
B(6,12,-1,minecraft:jungle_leaves[distance=7,persistent=true])
B(6,0,0,minecraft:water)
B(6,9,0,minecraft:jungle_leaves[distance=7,persistent=true])
B(6,10,0,minecraft:jungle_leaves[distance=7,persistent=true])
B(6,11,0,minecraft:jungle_leaves[distance=7,persistent=true])
B(6,12,0,minecraft:jungle_leaves[distance=7,persistent=true])
B(6,0,1,minecraft:water)
B(6,11,1,minecraft:jungle_leaves[distance=7,persistent=true])
B(6,12,1,minecraft:jungle_leaves[distance=7,persistent=true])
B(6,0,3,minecraft:stone_brick_slab)
B(6,12,4,minecraft:stone_brick_slab)
B(6,11,5,minecraft:stone_brick_stairs[facing=west,half=top,shape=straight,waterlogged=false])
B(6,12,5,minecraft:stone_brick_slab)
B(6,12,6,minecraft:stone_brick_slab)
B(6,6,7,minecraft:stone_brick_slab)
B(6,2,8,minecraft:stone_brick_slab[type=top,waterlogged=false])
B(6,3,8,minecraft:grass_block)
B(7,4,-7,minecraft:vine[east=false,north=true,south=false,up=false,west=false])
B(7,6,-5,minecraft:stone_brick_stairs[facing=west,half=bottom,shape=straight,waterlogged=false])
B(7,0,-4,minecraft:stone_brick_slab)
B(7,6,-4,minecraft:jungle_leaves[distance=7,persistent=true])
B(7,6,-3,minecraft:stone_brick_slab)
B(7,0,-2,minecraft:water)
B(7,6,-2,minecraft:stone_brick_stairs[facing=west,half=bottom,shape=straight,waterlogged=false])
B(7,0,-1,minecraft:water)
B(7,0,0,minecraft:water)
B(7,0,1,minecraft:water)
B(7,0,3,minecraft:stone_brick_slab)
B(7,6,3,minecraft:stone_brick_slab)
B(7,6,4,minecraft:stone_brick_stairs[facing=west,half=bottom,shape=straight,waterlogged=false])
B(7,6,7,minecraft:stone_brick_slab)
B(7,2,8,minecraft:stone_brick_slab[type=top,waterlogged=false])
B(7,3,8,minecraft:grass_block)
B(7,4,8,minecraft:stone_brick_stairs)
B(8,2,-7,minecraft:stone_brick_slab[type=top,waterlogged=false])
B(8,3,-7,minecraft:grass_block)
B(8,2,-6,minecraft:stone_brick_slab[type=top,waterlogged=false])
B(8,3,-6,minecraft:grass_block)
B(8,2,-5,minecraft:stone_brick_slab[type=top,waterlogged=false])
B(8,3,-5,minecraft:grass_block)
B(8,4,-5,minecraft:stone_brick_stairs[facing=west,half=bottom,shape=straight,waterlogged=false])
B(8,0,-4,minecraft:stone_brick_slab)
B(8,2,-4,minecraft:stone_brick_slab[type=top,waterlogged=false])
B(8,3,-4,minecraft:grass_block)
B(8,4,-4,minecraft:jungle_leaves[distance=7,persistent=true])
B(8,5,-4,minecraft:jungle_leaves[distance=7,persistent=true])
B(8,6,-4,minecraft:jungle_leaves[distance=7,persistent=true])
B(8,2,-3,minecraft:stone_brick_slab[type=top,waterlogged=false])
B(8,3,-3,minecraft:grass_block)
B(8,1,-2,minecraft:stone_brick_slab)
B(8,2,-2,minecraft:stone_brick_slab[type=top,waterlogged=false])
B(8,3,-2,minecraft:grass_block)
B(8,4,-2,minecraft:stone_brick_stairs[facing=west,half=bottom,shape=straight,waterlogged=false])
B(8,1,-1,minecraft:stone_brick_slab)
B(8,2,-1,minecraft:stone_brick_slab[type=top,waterlogged=false])
B(8,3,-1,minecraft:grass_block)
B(8,1,0,minecraft:stone_brick_slab)
B(8,2,0,minecraft:stone_brick_slab[type=top,waterlogged=false])
B(8,3,0,minecraft:grass_block)
B(8,1,1,minecraft:stone_brick_slab)
B(8,2,1,minecraft:stone_brick_slab[type=top,waterlogged=false])
B(8,3,1,minecraft:grass_block)
B(8,4,1,minecraft:stone_brick_stairs[facing=west,half=bottom,shape=straight,waterlogged=false])
B(8,2,2,minecraft:stone_brick_slab[type=top,waterlogged=false])
B(8,3,2,minecraft:grass_block)
B(8,0,3,minecraft:stone_brick_slab)
B(8,2,3,minecraft:stone_brick_slab[type=top,waterlogged=false])
B(8,3,3,minecraft:grass_block)
B(8,2,4,minecraft:stone_brick_slab[type=top,waterlogged=false])
B(8,3,4,minecraft:grass_block)
B(8,4,4,minecraft:stone_brick_stairs[facing=west,half=bottom,shape=straight,waterlogged=false])
B(8,2,5,minecraft:stone_brick_slab[type=top,waterlogged=false])
B(8,3,5,minecraft:grass_block)
B(8,2,6,minecraft:stone_brick_slab[type=top,waterlogged=false])
B(8,3,6,minecraft:grass_block)
B(8,2,7,minecraft:stone_brick_slab[type=top,waterlogged=false])
B(8,3,7,minecraft:grass_block)
B(8,4,7,minecraft:stone_brick_stairs[facing=west,half=bottom,shape=straight,waterlogged=false])
B(8,5,7,minecraft:jungle_leaves[distance=7,persistent=true])
B(8,0,8,minecraft:cobblestone_wall)
B(8,1,8,minecraft:torch)
B(8,2,8,minecraft:stone_brick_slab[type=top,waterlogged=false])
B(8,3,8,minecraft:grass_block)
B(8,4,8,minecraft:jungle_leaves[distance=7,persistent=true])
RB(-7,-1,-7,minecraft:mossy_stone_bricks,10,minecraft:cracked_stone_bricks,10,minecraft:cobblestone,10,minecraft:mossy_cobblestone,10,minecraft:stone_bricks,100)
RB(-6,-1,-7,minecraft:mossy_stone_bricks,10,minecraft:cracked_stone_bricks,10,minecraft:cobblestone,10,minecraft:mossy_cobblestone,10,minecraft:stone_bricks,100)
RB(-5,-1,-7,minecraft:mossy_stone_bricks,10,minecraft:cracked_stone_bricks,10,minecraft:cobblestone,10,minecraft:mossy_cobblestone,10,minecraft:stone_bricks,100)
RB(-4,-1,-7,minecraft:mossy_stone_bricks,10,minecraft:cracked_stone_bricks,10,minecraft:cobblestone,10,minecraft:mossy_cobblestone,10,minecraft:stone_bricks,100)
RB(-3,-1,-7,minecraft:mossy_stone_bricks,10,minecraft:cracked_stone_bricks,10,minecraft:cobblestone,10,minecraft:mossy_cobblestone,10,minecraft:stone_bricks,100)
RB(-2,-1,-7,minecraft:mossy_stone_bricks,10,minecraft:cracked_stone_bricks,10,minecraft:cobblestone,10,minecraft:mossy_cobblestone,10,minecraft:stone_bricks,100)
RB(-1,-1,-7,minecraft:mossy_stone_bricks,10,minecraft:cracked_stone_bricks,10,minecraft:cobblestone,10,minecraft:mossy_cobblestone,10,minecraft:stone_bricks,100)
RB(0,-1,-7,minecraft:mossy_stone_bricks,10,minecraft:cracked_stone_bricks,10,minecraft:cobblestone,10,minecraft:mossy_cobblestone,10,minecraft:stone_bricks,100)
RB(1,-1,-7,minecraft:mossy_stone_bricks,10,minecraft:cracked_stone_bricks,10,minecraft:cobblestone,10,minecraft:mossy_cobblestone,10,minecraft:stone_bricks,100)
RB(2,-1,-7,minecraft:mossy_stone_bricks,10,minecraft:cracked_stone_bricks,10,minecraft:cobblestone,10,minecraft:mossy_cobblestone,10,minecraft:stone_bricks,100)
RB(3,-1,-7,minecraft:mossy_stone_bricks,10,minecraft:cracked_stone_bricks,10,minecraft:cobblestone,10,minecraft:mossy_cobblestone,10,minecraft:stone_bricks,100)
RB(4,-1,-7,minecraft:mossy_stone_bricks,10,minecraft:cracked_stone_bricks,10,minecraft:cobblestone,10,minecraft:mossy_cobblestone,10,minecraft:stone_bricks,100)
RB(5,-1,-7,minecraft:mossy_stone_bricks,10,minecraft:cracked_stone_bricks,10,minecraft:cobblestone,10,minecraft:mossy_cobblestone,10,minecraft:stone_bricks,100)
RB(6,-1,-7,minecraft:mossy_stone_bricks,10,minecraft:cracked_stone_bricks,10,minecraft:cobblestone,10,minecraft:mossy_cobblestone,10,minecraft:stone_bricks,100)
RB(7,-1,-7,minecraft:mossy_stone_bricks,10,minecraft:cracked_stone_bricks,10,minecraft:cobblestone,10,minecraft:mossy_cobblestone,10,minecraft:stone_bricks,100)
RB(8,-1,-7,minecraft:mossy_stone_bricks,10,minecraft:cracked_stone_bricks,10,minecraft:cobblestone,10,minecraft:mossy_cobblestone,10,minecraft:stone_bricks,100)
RB(-7,-1,-6,minecraft:mossy_stone_bricks,10,minecraft:cracked_stone_bricks,10,minecraft:cobblestone,10,minecraft:mossy_cobblestone,10,minecraft:stone_bricks,100)
RB(-6,-1,-6,minecraft:mossy_stone_bricks,10,minecraft:cracked_stone_bricks,10,minecraft:cobblestone,10,minecraft:mossy_cobblestone,10,minecraft:stone_bricks,100)
RB(-5,-1,-6,minecraft:mossy_stone_bricks,10,minecraft:cracked_stone_bricks,10,minecraft:cobblestone,10,minecraft:mossy_cobblestone,10,minecraft:stone_bricks,100)
RB(-4,-1,-6,minecraft:mossy_stone_bricks,10,minecraft:cracked_stone_bricks,10,minecraft:cobblestone,10,minecraft:mossy_cobblestone,10,minecraft:stone_bricks,100)
RB(-3,-1,-6,minecraft:mossy_stone_bricks,10,minecraft:cracked_stone_bricks,10,minecraft:cobblestone,10,minecraft:mossy_cobblestone,10,minecraft:stone_bricks,100)
RB(-2,-1,-6,minecraft:mossy_stone_bricks,10,minecraft:cracked_stone_bricks,10,minecraft:cobblestone,10,minecraft:mossy_cobblestone,10,minecraft:stone_bricks,100)
RB(-1,-1,-6,minecraft:mossy_stone_bricks,10,minecraft:cracked_stone_bricks,10,minecraft:cobblestone,10,minecraft:mossy_cobblestone,10,minecraft:stone_bricks,100)
RB(0,-1,-6,minecraft:mossy_stone_bricks,10,minecraft:cracked_stone_bricks,10,minecraft:cobblestone,10,minecraft:mossy_cobblestone,10,minecraft:stone_bricks,100)
RB(1,-1,-6,minecraft:mossy_stone_bricks,10,minecraft:cracked_stone_bricks,10,minecraft:cobblestone,10,minecraft:mossy_cobblestone,10,minecraft:stone_bricks,100)
RB(2,-1,-6,minecraft:mossy_stone_bricks,10,minecraft:cracked_stone_bricks,10,minecraft:cobblestone,10,minecraft:mossy_cobblestone,10,minecraft:stone_bricks,100)
RB(3,-1,-6,minecraft:mossy_stone_bricks,10,minecraft:cracked_stone_bricks,10,minecraft:cobblestone,10,minecraft:mossy_cobblestone,10,minecraft:stone_bricks,100)
RB(4,-1,-6,minecraft:mossy_stone_bricks,10,minecraft:cracked_stone_bricks,10,minecraft:cobblestone,10,minecraft:mossy_cobblestone,10,minecraft:stone_bricks,100)
RB(5,-1,-6,minecraft:mossy_stone_bricks,10,minecraft:cracked_stone_bricks,10,minecraft:cobblestone,10,minecraft:mossy_cobblestone,10,minecraft:stone_bricks,100)
RB(6,-1,-6,minecraft:mossy_stone_bricks,10,minecraft:cracked_stone_bricks,10,minecraft:cobblestone,10,minecraft:mossy_cobblestone,10,minecraft:stone_bricks,100)
RB(7,-1,-6,minecraft:mossy_stone_bricks,10,minecraft:cracked_stone_bricks,10,minecraft:cobblestone,10,minecraft:mossy_cobblestone,10,minecraft:stone_bricks,100)
RB(8,-1,-6,minecraft:mossy_stone_bricks,10,minecraft:cracked_stone_bricks,10,minecraft:cobblestone,10,minecraft:mossy_cobblestone,10,minecraft:stone_bricks,100)
RB(-7,-1,-5,minecraft:mossy_stone_bricks,10,minecraft:cracked_stone_bricks,10,minecraft:cobblestone,10,minecraft:mossy_cobblestone,10,minecraft:stone_bricks,100)
RB(-6,-1,-5,minecraft:mossy_stone_bricks,10,minecraft:cracked_stone_bricks,10,minecraft:cobblestone,10,minecraft:mossy_cobblestone,10,minecraft:stone_bricks,100)
RB(-5,-1,-5,minecraft:mossy_stone_bricks,10,minecraft:cracked_stone_bricks,10,minecraft:cobblestone,10,minecraft:mossy_cobblestone,10,minecraft:stone_bricks,100)
RB(-4,-1,-5,minecraft:mossy_stone_bricks,10,minecraft:cracked_stone_bricks,10,minecraft:cobblestone,10,minecraft:mossy_cobblestone,10,minecraft:stone_bricks,100)
RB(-3,-1,-5,minecraft:mossy_stone_bricks,10,minecraft:cracked_stone_bricks,10,minecraft:cobblestone,10,minecraft:mossy_cobblestone,10,minecraft:stone_bricks,100)
RB(-2,-1,-5,minecraft:mossy_stone_bricks,10,minecraft:cracked_stone_bricks,10,minecraft:cobblestone,10,minecraft:mossy_cobblestone,10,minecraft:stone_bricks,100)
RB(-1,-1,-5,minecraft:mossy_stone_bricks,10,minecraft:cracked_stone_bricks,10,minecraft:cobblestone,10,minecraft:mossy_cobblestone,10,minecraft:stone_bricks,100)
RB(0,-1,-5,minecraft:mossy_stone_bricks,10,minecraft:cracked_stone_bricks,10,minecraft:cobblestone,10,minecraft:mossy_cobblestone,10,minecraft:stone_bricks,100)
RB(1,-1,-5,minecraft:mossy_stone_bricks,10,minecraft:cracked_stone_bricks,10,minecraft:cobblestone,10,minecraft:mossy_cobblestone,10,minecraft:stone_bricks,100)
RB(2,-1,-5,minecraft:mossy_stone_bricks,10,minecraft:cracked_stone_bricks,10,minecraft:cobblestone,10,minecraft:mossy_cobblestone,10,minecraft:stone_bricks,100)
RB(3,-1,-5,minecraft:mossy_stone_bricks,10,minecraft:cracked_stone_bricks,10,minecraft:cobblestone,10,minecraft:mossy_cobblestone,10,minecraft:stone_bricks,100)
RB(4,-1,-5,minecraft:mossy_stone_bricks,10,minecraft:cracked_stone_bricks,10,minecraft:cobblestone,10,minecraft:mossy_cobblestone,10,minecraft:stone_bricks,100)
RB(5,-1,-5,minecraft:mossy_stone_bricks,10,minecraft:cracked_stone_bricks,10,minecraft:cobblestone,10,minecraft:mossy_cobblestone,10,minecraft:stone_bricks,100)
RB(6,-1,-5,minecraft:mossy_stone_bricks,10,minecraft:cracked_stone_bricks,10,minecraft:cobblestone,10,minecraft:mossy_cobblestone,10,minecraft:stone_bricks,100)
RB(7,-1,-5,minecraft:mossy_stone_bricks,10,minecraft:cracked_stone_bricks,10,minecraft:cobblestone,10,minecraft:mossy_cobblestone,10,minecraft:stone_bricks,100)
RB(8,-1,-5,minecraft:mossy_stone_bricks,10,minecraft:cracked_stone_bricks,10,minecraft:cobblestone,10,minecraft:mossy_cobblestone,10,minecraft:stone_bricks,100)
RB(-7,-1,-4,minecraft:mossy_stone_bricks,10,minecraft:cracked_stone_bricks,10,minecraft:cobblestone,10,minecraft:mossy_cobblestone,10,minecraft:stone_bricks,100)
RB(-6,-1,-4,minecraft:mossy_stone_bricks,10,minecraft:cracked_stone_bricks,10,minecraft:cobblestone,10,minecraft:mossy_cobblestone,10,minecraft:stone_bricks,100)
RB(-5,-1,-4,minecraft:mossy_stone_bricks,10,minecraft:cracked_stone_bricks,10,minecraft:cobblestone,10,minecraft:mossy_cobblestone,10,minecraft:stone_bricks,100)
RB(-4,-1,-4,minecraft:mossy_stone_bricks,10,minecraft:cracked_stone_bricks,10,minecraft:cobblestone,10,minecraft:mossy_cobblestone,10,minecraft:stone_bricks,100)
RB(-3,-1,-4,minecraft:mossy_stone_bricks,10,minecraft:cracked_stone_bricks,10,minecraft:cobblestone,10,minecraft:mossy_cobblestone,10,minecraft:stone_bricks,100)
RB(-2,-1,-4,minecraft:mossy_stone_bricks,10,minecraft:cracked_stone_bricks,10,minecraft:cobblestone,10,minecraft:mossy_cobblestone,10,minecraft:stone_bricks,100)
RB(-1,-1,-4,minecraft:mossy_stone_bricks,10,minecraft:cracked_stone_bricks,10,minecraft:cobblestone,10,minecraft:mossy_cobblestone,10,minecraft:stone_bricks,100)
RB(0,-1,-4,minecraft:mossy_stone_bricks,10,minecraft:cracked_stone_bricks,10,minecraft:cobblestone,10,minecraft:mossy_cobblestone,10,minecraft:stone_bricks,100)
RB(1,-1,-4,minecraft:mossy_stone_bricks,10,minecraft:cracked_stone_bricks,10,minecraft:cobblestone,10,minecraft:mossy_cobblestone,10,minecraft:stone_bricks,100)
RB(2,-1,-4,minecraft:mossy_stone_bricks,10,minecraft:cracked_stone_bricks,10,minecraft:cobblestone,10,minecraft:mossy_cobblestone,10,minecraft:stone_bricks,100)
RB(3,-1,-4,minecraft:mossy_stone_bricks,10,minecraft:cracked_stone_bricks,10,minecraft:cobblestone,10,minecraft:mossy_cobblestone,10,minecraft:stone_bricks,100)
RB(4,-1,-4,minecraft:mossy_stone_bricks,10,minecraft:cracked_stone_bricks,10,minecraft:cobblestone,10,minecraft:mossy_cobblestone,10,minecraft:stone_bricks,100)
RB(5,-1,-4,minecraft:mossy_stone_bricks,10,minecraft:cracked_stone_bricks,10,minecraft:cobblestone,10,minecraft:mossy_cobblestone,10,minecraft:stone_bricks,100)
RB(6,-1,-4,minecraft:mossy_stone_bricks,10,minecraft:cracked_stone_bricks,10,minecraft:cobblestone,10,minecraft:mossy_cobblestone,10,minecraft:stone_bricks,100)
RB(7,-1,-4,minecraft:mossy_stone_bricks,10,minecraft:cracked_stone_bricks,10,minecraft:cobblestone,10,minecraft:mossy_cobblestone,10,minecraft:stone_bricks,100)
RB(8,-1,-4,minecraft:mossy_stone_bricks,10,minecraft:cracked_stone_bricks,10,minecraft:cobblestone,10,minecraft:mossy_cobblestone,10,minecraft:stone_bricks,100)
RB(-7,-1,-3,minecraft:mossy_stone_bricks,10,minecraft:cracked_stone_bricks,10,minecraft:cobblestone,10,minecraft:mossy_cobblestone,10,minecraft:stone_bricks,100)
RB(-6,-1,-3,minecraft:mossy_stone_bricks,10,minecraft:cracked_stone_bricks,10,minecraft:cobblestone,10,minecraft:mossy_cobblestone,10,minecraft:stone_bricks,100)
RB(-5,-1,-3,minecraft:mossy_stone_bricks,10,minecraft:cracked_stone_bricks,10,minecraft:cobblestone,10,minecraft:mossy_cobblestone,10,minecraft:stone_bricks,100)
RB(-4,-1,-3,minecraft:mossy_stone_bricks,10,minecraft:cracked_stone_bricks,10,minecraft:cobblestone,10,minecraft:mossy_cobblestone,10,minecraft:stone_bricks,100)
RB(-3,-1,-3,minecraft:mossy_stone_bricks,10,minecraft:cracked_stone_bricks,10,minecraft:cobblestone,10,minecraft:mossy_cobblestone,10,minecraft:stone_bricks,100)
RB(-2,-1,-3,minecraft:mossy_stone_bricks,10,minecraft:cracked_stone_bricks,10,minecraft:cobblestone,10,minecraft:mossy_cobblestone,10,minecraft:stone_bricks,100)
RB(-1,-1,-3,minecraft:mossy_stone_bricks,10,minecraft:cracked_stone_bricks,10,minecraft:cobblestone,10,minecraft:mossy_cobblestone,10,minecraft:stone_bricks,100)
RB(0,-1,-3,minecraft:mossy_stone_bricks,10,minecraft:cracked_stone_bricks,10,minecraft:cobblestone,10,minecraft:mossy_cobblestone,10,minecraft:stone_bricks,100)
RB(1,-1,-3,minecraft:mossy_stone_bricks,10,minecraft:cracked_stone_bricks,10,minecraft:cobblestone,10,minecraft:mossy_cobblestone,10,minecraft:stone_bricks,100)
RB(2,-1,-3,minecraft:mossy_stone_bricks,10,minecraft:cracked_stone_bricks,10,minecraft:cobblestone,10,minecraft:mossy_cobblestone,10,minecraft:stone_bricks,100)
RB(3,-1,-3,minecraft:mossy_stone_bricks,10,minecraft:cracked_stone_bricks,10,minecraft:cobblestone,10,minecraft:mossy_cobblestone,10,minecraft:stone_bricks,100)
RB(4,-1,-3,minecraft:mossy_stone_bricks,10,minecraft:cracked_stone_bricks,10,minecraft:cobblestone,10,minecraft:mossy_cobblestone,10,minecraft:stone_bricks,100)
RB(5,-1,-3,minecraft:mossy_stone_bricks,10,minecraft:cracked_stone_bricks,10,minecraft:cobblestone,10,minecraft:mossy_cobblestone,10,minecraft:stone_bricks,100)
RB(6,-1,-3,minecraft:mossy_stone_bricks,10,minecraft:cracked_stone_bricks,10,minecraft:cobblestone,10,minecraft:mossy_cobblestone,10,minecraft:stone_bricks,100)
RB(7,-1,-3,minecraft:mossy_stone_bricks,10,minecraft:cracked_stone_bricks,10,minecraft:cobblestone,10,minecraft:mossy_cobblestone,10,minecraft:stone_bricks,100)
RB(8,-1,-3,minecraft:mossy_stone_bricks,10,minecraft:cracked_stone_bricks,10,minecraft:cobblestone,10,minecraft:mossy_cobblestone,10,minecraft:stone_bricks,100)
RB(-7,-1,-2,minecraft:mossy_stone_bricks,10,minecraft:cracked_stone_bricks,10,minecraft:cobblestone,10,minecraft:mossy_cobblestone,10,minecraft:stone_bricks,100)
RB(-6,-1,-2,minecraft:mossy_stone_bricks,10,minecraft:cracked_stone_bricks,10,minecraft:cobblestone,10,minecraft:mossy_cobblestone,10,minecraft:stone_bricks,100)
RB(-5,-1,-2,minecraft:mossy_stone_bricks,10,minecraft:cracked_stone_bricks,10,minecraft:cobblestone,10,minecraft:mossy_cobblestone,10,minecraft:stone_bricks,100)
RB(-4,-1,-2,minecraft:mossy_stone_bricks,10,minecraft:cracked_stone_bricks,10,minecraft:cobblestone,10,minecraft:mossy_cobblestone,10,minecraft:stone_bricks,100)
RB(-3,-1,-2,minecraft:mossy_stone_bricks,10,minecraft:cracked_stone_bricks,10,minecraft:cobblestone,10,minecraft:mossy_cobblestone,10,minecraft:stone_bricks,100)
RB(-2,-1,-2,minecraft:mossy_stone_bricks,10,minecraft:cracked_stone_bricks,10,minecraft:cobblestone,10,minecraft:mossy_cobblestone,10,minecraft:stone_bricks,100)
RB(-1,-1,-2,minecraft:mossy_stone_bricks,10,minecraft:cracked_stone_bricks,10,minecraft:cobblestone,10,minecraft:mossy_cobblestone,10,minecraft:stone_bricks,100)
RB(0,-1,-2,minecraft:mossy_stone_bricks,10,minecraft:cracked_stone_bricks,10,minecraft:cobblestone,10,minecraft:mossy_cobblestone,10,minecraft:stone_bricks,100)
RB(1,-1,-2,minecraft:mossy_stone_bricks,10,minecraft:cracked_stone_bricks,10,minecraft:cobblestone,10,minecraft:mossy_cobblestone,10,minecraft:stone_bricks,100)
RB(2,-1,-2,minecraft:mossy_stone_bricks,10,minecraft:cracked_stone_bricks,10,minecraft:cobblestone,10,minecraft:mossy_cobblestone,10,minecraft:stone_bricks,100)
RB(3,-1,-2,minecraft:mossy_stone_bricks,10,minecraft:cracked_stone_bricks,10,minecraft:cobblestone,10,minecraft:mossy_cobblestone,10,minecraft:stone_bricks,100)
RB(4,-1,-2,minecraft:mossy_stone_bricks,10,minecraft:cracked_stone_bricks,10,minecraft:cobblestone,10,minecraft:mossy_cobblestone,10,minecraft:stone_bricks,100)
RB(5,-1,-2,minecraft:mossy_stone_bricks,10,minecraft:cracked_stone_bricks,10,minecraft:cobblestone,10,minecraft:mossy_cobblestone,10,minecraft:stone_bricks,100)
RB(6,-1,-2,minecraft:mossy_stone_bricks,10,minecraft:cracked_stone_bricks,10,minecraft:cobblestone,10,minecraft:mossy_cobblestone,10,minecraft:stone_bricks,100)
RB(7,-1,-2,minecraft:mossy_stone_bricks,10,minecraft:cracked_stone_bricks,10,minecraft:cobblestone,10,minecraft:mossy_cobblestone,10,minecraft:stone_bricks,100)
RB(8,-1,-2,minecraft:mossy_stone_bricks,10,minecraft:cracked_stone_bricks,10,minecraft:cobblestone,10,minecraft:mossy_cobblestone,10,minecraft:stone_bricks,100)
RB(-7,-1,-1,minecraft:mossy_stone_bricks,10,minecraft:cracked_stone_bricks,10,minecraft:cobblestone,10,minecraft:mossy_cobblestone,10,minecraft:stone_bricks,100)
RB(-6,-1,-1,minecraft:mossy_stone_bricks,10,minecraft:cracked_stone_bricks,10,minecraft:cobblestone,10,minecraft:mossy_cobblestone,10,minecraft:stone_bricks,100)
RB(-5,-1,-1,minecraft:mossy_stone_bricks,10,minecraft:cracked_stone_bricks,10,minecraft:cobblestone,10,minecraft:mossy_cobblestone,10,minecraft:stone_bricks,100)
RB(-4,-1,-1,minecraft:mossy_stone_bricks,10,minecraft:cracked_stone_bricks,10,minecraft:cobblestone,10,minecraft:mossy_cobblestone,10,minecraft:stone_bricks,100)
RB(-3,-1,-1,minecraft:mossy_stone_bricks,10,minecraft:cracked_stone_bricks,10,minecraft:cobblestone,10,minecraft:mossy_cobblestone,10,minecraft:stone_bricks,100)
RB(-2,-1,-1,minecraft:mossy_stone_bricks,10,minecraft:cracked_stone_bricks,10,minecraft:cobblestone,10,minecraft:mossy_cobblestone,10,minecraft:stone_bricks,100)
RB(-1,-1,-1,minecraft:mossy_stone_bricks,10,minecraft:cracked_stone_bricks,10,minecraft:cobblestone,10,minecraft:mossy_cobblestone,10,minecraft:stone_bricks,100)
RB(0,-1,-1,minecraft:mossy_stone_bricks,10,minecraft:cracked_stone_bricks,10,minecraft:cobblestone,10,minecraft:mossy_cobblestone,10,minecraft:stone_bricks,100)
RB(1,-1,-1,minecraft:mossy_stone_bricks,10,minecraft:cracked_stone_bricks,10,minecraft:cobblestone,10,minecraft:mossy_cobblestone,10,minecraft:stone_bricks,100)
RB(2,-1,-1,minecraft:mossy_stone_bricks,10,minecraft:cracked_stone_bricks,10,minecraft:cobblestone,10,minecraft:mossy_cobblestone,10,minecraft:stone_bricks,100)
RB(3,-1,-1,minecraft:mossy_stone_bricks,10,minecraft:cracked_stone_bricks,10,minecraft:cobblestone,10,minecraft:mossy_cobblestone,10,minecraft:stone_bricks,100)
RB(4,-1,-1,minecraft:mossy_stone_bricks,10,minecraft:cracked_stone_bricks,10,minecraft:cobblestone,10,minecraft:mossy_cobblestone,10,minecraft:stone_bricks,100)
RB(5,-1,-1,minecraft:mossy_stone_bricks,10,minecraft:cracked_stone_bricks,10,minecraft:cobblestone,10,minecraft:mossy_cobblestone,10,minecraft:stone_bricks,100)
RB(6,-1,-1,minecraft:mossy_stone_bricks,10,minecraft:cracked_stone_bricks,10,minecraft:cobblestone,10,minecraft:mossy_cobblestone,10,minecraft:stone_bricks,100)
RB(7,-1,-1,minecraft:mossy_stone_bricks,10,minecraft:cracked_stone_bricks,10,minecraft:cobblestone,10,minecraft:mossy_cobblestone,10,minecraft:stone_bricks,100)
RB(8,-1,-1,minecraft:mossy_stone_bricks,10,minecraft:cracked_stone_bricks,10,minecraft:cobblestone,10,minecraft:mossy_cobblestone,10,minecraft:stone_bricks,100)
RB(-7,-1,0,minecraft:mossy_stone_bricks,10,minecraft:cracked_stone_bricks,10,minecraft:cobblestone,10,minecraft:mossy_cobblestone,10,minecraft:stone_bricks,100)
RB(-6,-1,0,minecraft:mossy_stone_bricks,10,minecraft:cracked_stone_bricks,10,minecraft:cobblestone,10,minecraft:mossy_cobblestone,10,minecraft:stone_bricks,100)
RB(-5,-1,0,minecraft:mossy_stone_bricks,10,minecraft:cracked_stone_bricks,10,minecraft:cobblestone,10,minecraft:mossy_cobblestone,10,minecraft:stone_bricks,100)
RB(-4,-1,0,minecraft:mossy_stone_bricks,10,minecraft:cracked_stone_bricks,10,minecraft:cobblestone,10,minecraft:mossy_cobblestone,10,minecraft:stone_bricks,100)
RB(-3,-1,0,minecraft:mossy_stone_bricks,10,minecraft:cracked_stone_bricks,10,minecraft:cobblestone,10,minecraft:mossy_cobblestone,10,minecraft:stone_bricks,100)
RB(-2,-1,0,minecraft:mossy_stone_bricks,10,minecraft:cracked_stone_bricks,10,minecraft:cobblestone,10,minecraft:mossy_cobblestone,10,minecraft:stone_bricks,100)
RB(-1,-1,0,minecraft:mossy_stone_bricks,10,minecraft:cracked_stone_bricks,10,minecraft:cobblestone,10,minecraft:mossy_cobblestone,10,minecraft:stone_bricks,100)
RB(0,-1,0,minecraft:mossy_stone_bricks,10,minecraft:cracked_stone_bricks,10,minecraft:cobblestone,10,minecraft:mossy_cobblestone,10,minecraft:stone_bricks,100)
RB(1,-1,0,minecraft:mossy_stone_bricks,10,minecraft:cracked_stone_bricks,10,minecraft:cobblestone,10,minecraft:mossy_cobblestone,10,minecraft:stone_bricks,100)
RB(2,-1,0,minecraft:mossy_stone_bricks,10,minecraft:cracked_stone_bricks,10,minecraft:cobblestone,10,minecraft:mossy_cobblestone,10,minecraft:stone_bricks,100)
RB(3,-1,0,minecraft:mossy_stone_bricks,10,minecraft:cracked_stone_bricks,10,minecraft:cobblestone,10,minecraft:mossy_cobblestone,10,minecraft:stone_bricks,100)
RB(4,-1,0,minecraft:mossy_stone_bricks,10,minecraft:cracked_stone_bricks,10,minecraft:cobblestone,10,minecraft:mossy_cobblestone,10,minecraft:stone_bricks,100)
RB(5,-1,0,minecraft:mossy_stone_bricks,10,minecraft:cracked_stone_bricks,10,minecraft:cobblestone,10,minecraft:mossy_cobblestone,10,minecraft:stone_bricks,100)
RB(6,-1,0,minecraft:mossy_stone_bricks,10,minecraft:cracked_stone_bricks,10,minecraft:cobblestone,10,minecraft:mossy_cobblestone,10,minecraft:stone_bricks,100)
RB(7,-1,0,minecraft:mossy_stone_bricks,10,minecraft:cracked_stone_bricks,10,minecraft:cobblestone,10,minecraft:mossy_cobblestone,10,minecraft:stone_bricks,100)
RB(8,-1,0,minecraft:mossy_stone_bricks,10,minecraft:cracked_stone_bricks,10,minecraft:cobblestone,10,minecraft:mossy_cobblestone,10,minecraft:stone_bricks,100)
RB(-7,-1,1,minecraft:mossy_stone_bricks,10,minecraft:cracked_stone_bricks,10,minecraft:cobblestone,10,minecraft:mossy_cobblestone,10,minecraft:stone_bricks,100)
RB(-6,-1,1,minecraft:mossy_stone_bricks,10,minecraft:cracked_stone_bricks,10,minecraft:cobblestone,10,minecraft:mossy_cobblestone,10,minecraft:stone_bricks,100)
RB(-5,-1,1,minecraft:mossy_stone_bricks,10,minecraft:cracked_stone_bricks,10,minecraft:cobblestone,10,minecraft:mossy_cobblestone,10,minecraft:stone_bricks,100)
RB(-4,-1,1,minecraft:mossy_stone_bricks,10,minecraft:cracked_stone_bricks,10,minecraft:cobblestone,10,minecraft:mossy_cobblestone,10,minecraft:stone_bricks,100)
RB(-3,-1,1,minecraft:mossy_stone_bricks,10,minecraft:cracked_stone_bricks,10,minecraft:cobblestone,10,minecraft:mossy_cobblestone,10,minecraft:stone_bricks,100)
RB(-2,-1,1,minecraft:mossy_stone_bricks,10,minecraft:cracked_stone_bricks,10,minecraft:cobblestone,10,minecraft:mossy_cobblestone,10,minecraft:stone_bricks,100)
RB(-1,-1,1,minecraft:mossy_stone_bricks,10,minecraft:cracked_stone_bricks,10,minecraft:cobblestone,10,minecraft:mossy_cobblestone,10,minecraft:stone_bricks,100)
RB(0,-1,1,minecraft:mossy_stone_bricks,10,minecraft:cracked_stone_bricks,10,minecraft:cobblestone,10,minecraft:mossy_cobblestone,10,minecraft:stone_bricks,100)
RB(1,-1,1,minecraft:mossy_stone_bricks,10,minecraft:cracked_stone_bricks,10,minecraft:cobblestone,10,minecraft:mossy_cobblestone,10,minecraft:stone_bricks,100)
RB(2,-1,1,minecraft:mossy_stone_bricks,10,minecraft:cracked_stone_bricks,10,minecraft:cobblestone,10,minecraft:mossy_cobblestone,10,minecraft:stone_bricks,100)
RB(3,-1,1,minecraft:mossy_stone_bricks,10,minecraft:cracked_stone_bricks,10,minecraft:cobblestone,10,minecraft:mossy_cobblestone,10,minecraft:stone_bricks,100)
RB(4,-1,1,minecraft:mossy_stone_bricks,10,minecraft:cracked_stone_bricks,10,minecraft:cobblestone,10,minecraft:mossy_cobblestone,10,minecraft:stone_bricks,100)
RB(5,-1,1,minecraft:mossy_stone_bricks,10,minecraft:cracked_stone_bricks,10,minecraft:cobblestone,10,minecraft:mossy_cobblestone,10,minecraft:stone_bricks,100)
RB(6,-1,1,minecraft:mossy_stone_bricks,10,minecraft:cracked_stone_bricks,10,minecraft:cobblestone,10,minecraft:mossy_cobblestone,10,minecraft:stone_bricks,100)
RB(7,-1,1,minecraft:mossy_stone_bricks,10,minecraft:cracked_stone_bricks,10,minecraft:cobblestone,10,minecraft:mossy_cobblestone,10,minecraft:stone_bricks,100)
RB(8,-1,1,minecraft:mossy_stone_bricks,10,minecraft:cracked_stone_bricks,10,minecraft:cobblestone,10,minecraft:mossy_cobblestone,10,minecraft:stone_bricks,100)
RB(-7,-1,2,minecraft:mossy_stone_bricks,10,minecraft:cracked_stone_bricks,10,minecraft:cobblestone,10,minecraft:mossy_cobblestone,10,minecraft:stone_bricks,100)
RB(-6,-1,2,minecraft:mossy_stone_bricks,10,minecraft:cracked_stone_bricks,10,minecraft:cobblestone,10,minecraft:mossy_cobblestone,10,minecraft:stone_bricks,100)
RB(-5,-1,2,minecraft:mossy_stone_bricks,10,minecraft:cracked_stone_bricks,10,minecraft:cobblestone,10,minecraft:mossy_cobblestone,10,minecraft:stone_bricks,100)
RB(-4,-1,2,minecraft:mossy_stone_bricks,10,minecraft:cracked_stone_bricks,10,minecraft:cobblestone,10,minecraft:mossy_cobblestone,10,minecraft:stone_bricks,100)
RB(-3,-1,2,minecraft:mossy_stone_bricks,10,minecraft:cracked_stone_bricks,10,minecraft:cobblestone,10,minecraft:mossy_cobblestone,10,minecraft:stone_bricks,100)
RB(-2,-1,2,minecraft:mossy_stone_bricks,10,minecraft:cracked_stone_bricks,10,minecraft:cobblestone,10,minecraft:mossy_cobblestone,10,minecraft:stone_bricks,100)
RB(-1,-1,2,minecraft:mossy_stone_bricks,10,minecraft:cracked_stone_bricks,10,minecraft:cobblestone,10,minecraft:mossy_cobblestone,10,minecraft:stone_bricks,100)
RB(0,-1,2,minecraft:mossy_stone_bricks,10,minecraft:cracked_stone_bricks,10,minecraft:cobblestone,10,minecraft:mossy_cobblestone,10,minecraft:stone_bricks,100)
RB(1,-1,2,minecraft:mossy_stone_bricks,10,minecraft:cracked_stone_bricks,10,minecraft:cobblestone,10,minecraft:mossy_cobblestone,10,minecraft:stone_bricks,100)
RB(2,-1,2,minecraft:mossy_stone_bricks,10,minecraft:cracked_stone_bricks,10,minecraft:cobblestone,10,minecraft:mossy_cobblestone,10,minecraft:stone_bricks,100)
RB(3,-1,2,minecraft:mossy_stone_bricks,10,minecraft:cracked_stone_bricks,10,minecraft:cobblestone,10,minecraft:mossy_cobblestone,10,minecraft:stone_bricks,100)
RB(4,-1,2,minecraft:mossy_stone_bricks,10,minecraft:cracked_stone_bricks,10,minecraft:cobblestone,10,minecraft:mossy_cobblestone,10,minecraft:stone_bricks,100)
RB(5,-1,2,minecraft:mossy_stone_bricks,10,minecraft:cracked_stone_bricks,10,minecraft:cobblestone,10,minecraft:mossy_cobblestone,10,minecraft:stone_bricks,100)
RB(6,-1,2,minecraft:mossy_stone_bricks,10,minecraft:cracked_stone_bricks,10,minecraft:cobblestone,10,minecraft:mossy_cobblestone,10,minecraft:stone_bricks,100)
RB(7,-1,2,minecraft:mossy_stone_bricks,10,minecraft:cracked_stone_bricks,10,minecraft:cobblestone,10,minecraft:mossy_cobblestone,10,minecraft:stone_bricks,100)
RB(8,-1,2,minecraft:mossy_stone_bricks,10,minecraft:cracked_stone_bricks,10,minecraft:cobblestone,10,minecraft:mossy_cobblestone,10,minecraft:stone_bricks,100)
RB(-7,-1,3,minecraft:mossy_stone_bricks,10,minecraft:cracked_stone_bricks,10,minecraft:cobblestone,10,minecraft:mossy_cobblestone,10,minecraft:stone_bricks,100)
RB(-6,-1,3,minecraft:mossy_stone_bricks,10,minecraft:cracked_stone_bricks,10,minecraft:cobblestone,10,minecraft:mossy_cobblestone,10,minecraft:stone_bricks,100)
RB(-5,-1,3,minecraft:mossy_stone_bricks,10,minecraft:cracked_stone_bricks,10,minecraft:cobblestone,10,minecraft:mossy_cobblestone,10,minecraft:stone_bricks,100)
RB(-4,-1,3,minecraft:mossy_stone_bricks,10,minecraft:cracked_stone_bricks,10,minecraft:cobblestone,10,minecraft:mossy_cobblestone,10,minecraft:stone_bricks,100)
RB(-3,-1,3,minecraft:mossy_stone_bricks,10,minecraft:cracked_stone_bricks,10,minecraft:cobblestone,10,minecraft:mossy_cobblestone,10,minecraft:stone_bricks,100)
RB(-2,-1,3,minecraft:mossy_stone_bricks,10,minecraft:cracked_stone_bricks,10,minecraft:cobblestone,10,minecraft:mossy_cobblestone,10,minecraft:stone_bricks,100)
RB(-1,-1,3,minecraft:mossy_stone_bricks,10,minecraft:cracked_stone_bricks,10,minecraft:cobblestone,10,minecraft:mossy_cobblestone,10,minecraft:stone_bricks,100)
RB(0,-1,3,minecraft:mossy_stone_bricks,10,minecraft:cracked_stone_bricks,10,minecraft:cobblestone,10,minecraft:mossy_cobblestone,10,minecraft:stone_bricks,100)
RB(1,-1,3,minecraft:mossy_stone_bricks,10,minecraft:cracked_stone_bricks,10,minecraft:cobblestone,10,minecraft:mossy_cobblestone,10,minecraft:stone_bricks,100)
RB(2,-1,3,minecraft:mossy_stone_bricks,10,minecraft:cracked_stone_bricks,10,minecraft:cobblestone,10,minecraft:mossy_cobblestone,10,minecraft:stone_bricks,100)
RB(3,-1,3,minecraft:mossy_stone_bricks,10,minecraft:cracked_stone_bricks,10,minecraft:cobblestone,10,minecraft:mossy_cobblestone,10,minecraft:stone_bricks,100)
RB(4,-1,3,minecraft:mossy_stone_bricks,10,minecraft:cracked_stone_bricks,10,minecraft:cobblestone,10,minecraft:mossy_cobblestone,10,minecraft:stone_bricks,100)
RB(5,-1,3,minecraft:mossy_stone_bricks,10,minecraft:cracked_stone_bricks,10,minecraft:cobblestone,10,minecraft:mossy_cobblestone,10,minecraft:stone_bricks,100)
RB(6,-1,3,minecraft:mossy_stone_bricks,10,minecraft:cracked_stone_bricks,10,minecraft:cobblestone,10,minecraft:mossy_cobblestone,10,minecraft:stone_bricks,100)
RB(7,-1,3,minecraft:mossy_stone_bricks,10,minecraft:cracked_stone_bricks,10,minecraft:cobblestone,10,minecraft:mossy_cobblestone,10,minecraft:stone_bricks,100)
RB(8,-1,3,minecraft:mossy_stone_bricks,10,minecraft:cracked_stone_bricks,10,minecraft:cobblestone,10,minecraft:mossy_cobblestone,10,minecraft:stone_bricks,100)
RB(-7,-1,4,minecraft:mossy_stone_bricks,10,minecraft:cracked_stone_bricks,10,minecraft:cobblestone,10,minecraft:mossy_cobblestone,10,minecraft:stone_bricks,100)
RB(-6,-1,4,minecraft:mossy_stone_bricks,10,minecraft:cracked_stone_bricks,10,minecraft:cobblestone,10,minecraft:mossy_cobblestone,10,minecraft:stone_bricks,100)
RB(-5,-1,4,minecraft:mossy_stone_bricks,10,minecraft:cracked_stone_bricks,10,minecraft:cobblestone,10,minecraft:mossy_cobblestone,10,minecraft:stone_bricks,100)
RB(-4,-1,4,minecraft:mossy_stone_bricks,10,minecraft:cracked_stone_bricks,10,minecraft:cobblestone,10,minecraft:mossy_cobblestone,10,minecraft:stone_bricks,100)
RB(-3,-1,4,minecraft:mossy_stone_bricks,10,minecraft:cracked_stone_bricks,10,minecraft:cobblestone,10,minecraft:mossy_cobblestone,10,minecraft:stone_bricks,100)
RB(-2,-1,4,minecraft:mossy_stone_bricks,10,minecraft:cracked_stone_bricks,10,minecraft:cobblestone,10,minecraft:mossy_cobblestone,10,minecraft:stone_bricks,100)
RB(-1,-1,4,minecraft:mossy_stone_bricks,10,minecraft:cracked_stone_bricks,10,minecraft:cobblestone,10,minecraft:mossy_cobblestone,10,minecraft:stone_bricks,100)
RB(0,-1,4,minecraft:mossy_stone_bricks,10,minecraft:cracked_stone_bricks,10,minecraft:cobblestone,10,minecraft:mossy_cobblestone,10,minecraft:stone_bricks,100)
RB(1,-1,4,minecraft:mossy_stone_bricks,10,minecraft:cracked_stone_bricks,10,minecraft:cobblestone,10,minecraft:mossy_cobblestone,10,minecraft:stone_bricks,100)
RB(2,-1,4,minecraft:mossy_stone_bricks,10,minecraft:cracked_stone_bricks,10,minecraft:cobblestone,10,minecraft:mossy_cobblestone,10,minecraft:stone_bricks,100)
RB(3,-1,4,minecraft:mossy_stone_bricks,10,minecraft:cracked_stone_bricks,10,minecraft:cobblestone,10,minecraft:mossy_cobblestone,10,minecraft:stone_bricks,100)
RB(4,-1,4,minecraft:mossy_stone_bricks,10,minecraft:cracked_stone_bricks,10,minecraft:cobblestone,10,minecraft:mossy_cobblestone,10,minecraft:stone_bricks,100)
RB(5,-1,4,minecraft:mossy_stone_bricks,10,minecraft:cracked_stone_bricks,10,minecraft:cobblestone,10,minecraft:mossy_cobblestone,10,minecraft:stone_bricks,100)
RB(6,-1,4,minecraft:mossy_stone_bricks,10,minecraft:cracked_stone_bricks,10,minecraft:cobblestone,10,minecraft:mossy_cobblestone,10,minecraft:stone_bricks,100)
RB(7,-1,4,minecraft:mossy_stone_bricks,10,minecraft:cracked_stone_bricks,10,minecraft:cobblestone,10,minecraft:mossy_cobblestone,10,minecraft:stone_bricks,100)
RB(8,-1,4,minecraft:mossy_stone_bricks,10,minecraft:cracked_stone_bricks,10,minecraft:cobblestone,10,minecraft:mossy_cobblestone,10,minecraft:stone_bricks,100)
RB(-7,-1,5,minecraft:mossy_stone_bricks,10,minecraft:cracked_stone_bricks,10,minecraft:cobblestone,10,minecraft:mossy_cobblestone,10,minecraft:stone_bricks,100)
RB(-6,-1,5,minecraft:mossy_stone_bricks,10,minecraft:cracked_stone_bricks,10,minecraft:cobblestone,10,minecraft:mossy_cobblestone,10,minecraft:stone_bricks,100)
RB(-5,-1,5,minecraft:mossy_stone_bricks,10,minecraft:cracked_stone_bricks,10,minecraft:cobblestone,10,minecraft:mossy_cobblestone,10,minecraft:stone_bricks,100)
RB(-4,-1,5,minecraft:mossy_stone_bricks,10,minecraft:cracked_stone_bricks,10,minecraft:cobblestone,10,minecraft:mossy_cobblestone,10,minecraft:stone_bricks,100)
RB(-3,-1,5,minecraft:mossy_stone_bricks,10,minecraft:cracked_stone_bricks,10,minecraft:cobblestone,10,minecraft:mossy_cobblestone,10,minecraft:stone_bricks,100)
RB(-2,-1,5,minecraft:mossy_stone_bricks,10,minecraft:cracked_stone_bricks,10,minecraft:cobblestone,10,minecraft:mossy_cobblestone,10,minecraft:stone_bricks,100)
RB(-1,-1,5,minecraft:mossy_stone_bricks,10,minecraft:cracked_stone_bricks,10,minecraft:cobblestone,10,minecraft:mossy_cobblestone,10,minecraft:stone_bricks,100)
RB(0,-1,5,minecraft:mossy_stone_bricks,10,minecraft:cracked_stone_bricks,10,minecraft:cobblestone,10,minecraft:mossy_cobblestone,10,minecraft:stone_bricks,100)
RB(1,-1,5,minecraft:mossy_stone_bricks,10,minecraft:cracked_stone_bricks,10,minecraft:cobblestone,10,minecraft:mossy_cobblestone,10,minecraft:stone_bricks,100)
RB(2,-1,5,minecraft:mossy_stone_bricks,10,minecraft:cracked_stone_bricks,10,minecraft:cobblestone,10,minecraft:mossy_cobblestone,10,minecraft:stone_bricks,100)
RB(3,-1,5,minecraft:mossy_stone_bricks,10,minecraft:cracked_stone_bricks,10,minecraft:cobblestone,10,minecraft:mossy_cobblestone,10,minecraft:stone_bricks,100)
RB(4,-1,5,minecraft:mossy_stone_bricks,10,minecraft:cracked_stone_bricks,10,minecraft:cobblestone,10,minecraft:mossy_cobblestone,10,minecraft:stone_bricks,100)
RB(5,-1,5,minecraft:mossy_stone_bricks,10,minecraft:cracked_stone_bricks,10,minecraft:cobblestone,10,minecraft:mossy_cobblestone,10,minecraft:stone_bricks,100)
RB(6,-1,5,minecraft:mossy_stone_bricks,10,minecraft:cracked_stone_bricks,10,minecraft:cobblestone,10,minecraft:mossy_cobblestone,10,minecraft:stone_bricks,100)
RB(7,-1,5,minecraft:mossy_stone_bricks,10,minecraft:cracked_stone_bricks,10,minecraft:cobblestone,10,minecraft:mossy_cobblestone,10,minecraft:stone_bricks,100)
RB(8,-1,5,minecraft:mossy_stone_bricks,10,minecraft:cracked_stone_bricks,10,minecraft:cobblestone,10,minecraft:mossy_cobblestone,10,minecraft:stone_bricks,100)
RB(-7,-1,6,minecraft:mossy_stone_bricks,10,minecraft:cracked_stone_bricks,10,minecraft:cobblestone,10,minecraft:mossy_cobblestone,10,minecraft:stone_bricks,100)
RB(-6,-1,6,minecraft:mossy_stone_bricks,10,minecraft:cracked_stone_bricks,10,minecraft:cobblestone,10,minecraft:mossy_cobblestone,10,minecraft:stone_bricks,100)
RB(-5,-1,6,minecraft:mossy_stone_bricks,10,minecraft:cracked_stone_bricks,10,minecraft:cobblestone,10,minecraft:mossy_cobblestone,10,minecraft:stone_bricks,100)
RB(-4,-1,6,minecraft:mossy_stone_bricks,10,minecraft:cracked_stone_bricks,10,minecraft:cobblestone,10,minecraft:mossy_cobblestone,10,minecraft:stone_bricks,100)
RB(-3,-1,6,minecraft:mossy_stone_bricks,10,minecraft:cracked_stone_bricks,10,minecraft:cobblestone,10,minecraft:mossy_cobblestone,10,minecraft:stone_bricks,100)
RB(-2,-1,6,minecraft:mossy_stone_bricks,10,minecraft:cracked_stone_bricks,10,minecraft:cobblestone,10,minecraft:mossy_cobblestone,10,minecraft:stone_bricks,100)
RB(-1,-1,6,minecraft:mossy_stone_bricks,10,minecraft:cracked_stone_bricks,10,minecraft:cobblestone,10,minecraft:mossy_cobblestone,10,minecraft:stone_bricks,100)
RB(0,-1,6,minecraft:mossy_stone_bricks,10,minecraft:cracked_stone_bricks,10,minecraft:cobblestone,10,minecraft:mossy_cobblestone,10,minecraft:stone_bricks,100)
RB(1,-1,6,minecraft:mossy_stone_bricks,10,minecraft:cracked_stone_bricks,10,minecraft:cobblestone,10,minecraft:mossy_cobblestone,10,minecraft:stone_bricks,100)
RB(2,-1,6,minecraft:mossy_stone_bricks,10,minecraft:cracked_stone_bricks,10,minecraft:cobblestone,10,minecraft:mossy_cobblestone,10,minecraft:stone_bricks,100)
RB(3,-1,6,minecraft:mossy_stone_bricks,10,minecraft:cracked_stone_bricks,10,minecraft:cobblestone,10,minecraft:mossy_cobblestone,10,minecraft:stone_bricks,100)
RB(4,-1,6,minecraft:mossy_stone_bricks,10,minecraft:cracked_stone_bricks,10,minecraft:cobblestone,10,minecraft:mossy_cobblestone,10,minecraft:stone_bricks,100)
RB(5,-1,6,minecraft:mossy_stone_bricks,10,minecraft:cracked_stone_bricks,10,minecraft:cobblestone,10,minecraft:mossy_cobblestone,10,minecraft:stone_bricks,100)
RB(6,-1,6,minecraft:mossy_stone_bricks,10,minecraft:cracked_stone_bricks,10,minecraft:cobblestone,10,minecraft:mossy_cobblestone,10,minecraft:stone_bricks,100)
RB(7,-1,6,minecraft:mossy_stone_bricks,10,minecraft:cracked_stone_bricks,10,minecraft:cobblestone,10,minecraft:mossy_cobblestone,10,minecraft:stone_bricks,100)
RB(8,-1,6,minecraft:mossy_stone_bricks,10,minecraft:cracked_stone_bricks,10,minecraft:cobblestone,10,minecraft:mossy_cobblestone,10,minecraft:stone_bricks,100)
RB(-7,-1,7,minecraft:mossy_stone_bricks,10,minecraft:cracked_stone_bricks,10,minecraft:cobblestone,10,minecraft:mossy_cobblestone,10,minecraft:stone_bricks,100)
RB(-6,-1,7,minecraft:mossy_stone_bricks,10,minecraft:cracked_stone_bricks,10,minecraft:cobblestone,10,minecraft:mossy_cobblestone,10,minecraft:stone_bricks,100)
RB(-5,-1,7,minecraft:mossy_stone_bricks,10,minecraft:cracked_stone_bricks,10,minecraft:cobblestone,10,minecraft:mossy_cobblestone,10,minecraft:stone_bricks,100)
RB(-4,-1,7,minecraft:mossy_stone_bricks,10,minecraft:cracked_stone_bricks,10,minecraft:cobblestone,10,minecraft:mossy_cobblestone,10,minecraft:stone_bricks,100)
RB(-3,-1,7,minecraft:mossy_stone_bricks,10,minecraft:cracked_stone_bricks,10,minecraft:cobblestone,10,minecraft:mossy_cobblestone,10,minecraft:stone_bricks,100)
RB(-2,-1,7,minecraft:mossy_stone_bricks,10,minecraft:cracked_stone_bricks,10,minecraft:cobblestone,10,minecraft:mossy_cobblestone,10,minecraft:stone_bricks,100)
RB(-1,-1,7,minecraft:mossy_stone_bricks,10,minecraft:cracked_stone_bricks,10,minecraft:cobblestone,10,minecraft:mossy_cobblestone,10,minecraft:stone_bricks,100)
RB(0,-1,7,minecraft:mossy_stone_bricks,10,minecraft:cracked_stone_bricks,10,minecraft:cobblestone,10,minecraft:mossy_cobblestone,10,minecraft:stone_bricks,100)
RB(1,-1,7,minecraft:mossy_stone_bricks,10,minecraft:cracked_stone_bricks,10,minecraft:cobblestone,10,minecraft:mossy_cobblestone,10,minecraft:stone_bricks,100)
RB(2,-1,7,minecraft:mossy_stone_bricks,10,minecraft:cracked_stone_bricks,10,minecraft:cobblestone,10,minecraft:mossy_cobblestone,10,minecraft:stone_bricks,100)
RB(3,-1,7,minecraft:mossy_stone_bricks,10,minecraft:cracked_stone_bricks,10,minecraft:cobblestone,10,minecraft:mossy_cobblestone,10,minecraft:stone_bricks,100)
RB(4,-1,7,minecraft:mossy_stone_bricks,10,minecraft:cracked_stone_bricks,10,minecraft:cobblestone,10,minecraft:mossy_cobblestone,10,minecraft:stone_bricks,100)
RB(5,-1,7,minecraft:mossy_stone_bricks,10,minecraft:cracked_stone_bricks,10,minecraft:cobblestone,10,minecraft:mossy_cobblestone,10,minecraft:stone_bricks,100)
RB(6,-1,7,minecraft:mossy_stone_bricks,10,minecraft:cracked_stone_bricks,10,minecraft:cobblestone,10,minecraft:mossy_cobblestone,10,minecraft:stone_bricks,100)
RB(7,-1,7,minecraft:mossy_stone_bricks,10,minecraft:cracked_stone_bricks,10,minecraft:cobblestone,10,minecraft:mossy_cobblestone,10,minecraft:stone_bricks,100)
RB(8,-1,7,minecraft:mossy_stone_bricks,10,minecraft:cracked_stone_bricks,10,minecraft:cobblestone,10,minecraft:mossy_cobblestone,10,minecraft:stone_bricks,100)
RB(-7,-1,8,minecraft:mossy_stone_bricks,10,minecraft:cracked_stone_bricks,10,minecraft:cobblestone,10,minecraft:mossy_cobblestone,10,minecraft:stone_bricks,100)
RB(-6,-1,8,minecraft:mossy_stone_bricks,10,minecraft:cracked_stone_bricks,10,minecraft:cobblestone,10,minecraft:mossy_cobblestone,10,minecraft:stone_bricks,100)
RB(-5,-1,8,minecraft:mossy_stone_bricks,10,minecraft:cracked_stone_bricks,10,minecraft:cobblestone,10,minecraft:mossy_cobblestone,10,minecraft:stone_bricks,100)
RB(-4,-1,8,minecraft:mossy_stone_bricks,10,minecraft:cracked_stone_bricks,10,minecraft:cobblestone,10,minecraft:mossy_cobblestone,10,minecraft:stone_bricks,100)
RB(-3,-1,8,minecraft:mossy_stone_bricks,10,minecraft:cracked_stone_bricks,10,minecraft:cobblestone,10,minecraft:mossy_cobblestone,10,minecraft:stone_bricks,100)
RB(-2,-1,8,minecraft:mossy_stone_bricks,10,minecraft:cracked_stone_bricks,10,minecraft:cobblestone,10,minecraft:mossy_cobblestone,10,minecraft:stone_bricks,100)
RB(-1,-1,8,minecraft:mossy_stone_bricks,10,minecraft:cracked_stone_bricks,10,minecraft:cobblestone,10,minecraft:mossy_cobblestone,10,minecraft:stone_bricks,100)
RB(0,-1,8,minecraft:mossy_stone_bricks,10,minecraft:cracked_stone_bricks,10,minecraft:cobblestone,10,minecraft:mossy_cobblestone,10,minecraft:stone_bricks,100)
RB(1,-1,8,minecraft:mossy_stone_bricks,10,minecraft:cracked_stone_bricks,10,minecraft:cobblestone,10,minecraft:mossy_cobblestone,10,minecraft:stone_bricks,100)
RB(2,-1,8,minecraft:mossy_stone_bricks,10,minecraft:cracked_stone_bricks,10,minecraft:cobblestone,10,minecraft:mossy_cobblestone,10,minecraft:stone_bricks,100)
RB(3,-1,8,minecraft:mossy_stone_bricks,10,minecraft:cracked_stone_bricks,10,minecraft:cobblestone,10,minecraft:mossy_cobblestone,10,minecraft:stone_bricks,100)
RB(4,-1,8,minecraft:mossy_stone_bricks,10,minecraft:cracked_stone_bricks,10,minecraft:cobblestone,10,minecraft:mossy_cobblestone,10,minecraft:stone_bricks,100)
RB(5,-1,8,minecraft:mossy_stone_bricks,10,minecraft:cracked_stone_bricks,10,minecraft:cobblestone,10,minecraft:mossy_cobblestone,10,minecraft:stone_bricks,100)
RB(6,-1,8,minecraft:mossy_stone_bricks,10,minecraft:cracked_stone_bricks,10,minecraft:cobblestone,10,minecraft:mossy_cobblestone,10,minecraft:stone_bricks,100)
RB(7,-1,8,minecraft:mossy_stone_bricks,10,minecraft:cracked_stone_bricks,10,minecraft:cobblestone,10,minecraft:mossy_cobblestone,10,minecraft:stone_bricks,100)
RB(8,-1,8,minecraft:mossy_stone_bricks,10,minecraft:cracked_stone_bricks,10,minecraft:cobblestone,10,minecraft:mossy_cobblestone,10,minecraft:stone_bricks,100)
RB(-3,0,-7,minecraft:mossy_stone_bricks,10,minecraft:cracked_stone_bricks,10,minecraft:cobblestone,10,minecraft:mossy_cobblestone,10,minecraft:stone_bricks,100)
RB(2,0,-7,minecraft:mossy_stone_bricks,10,minecraft:cracked_stone_bricks,10,minecraft:cobblestone,10,minecraft:mossy_cobblestone,10,minecraft:stone_bricks,100)
RB(8,0,-7,minecraft:mossy_stone_bricks,10,minecraft:cracked_stone_bricks,10,minecraft:cobblestone,10,minecraft:mossy_cobblestone,10,minecraft:stone_bricks,100)
RB(-3,0,-6,minecraft:mossy_stone_bricks,10,minecraft:cracked_stone_bricks,10,minecraft:cobblestone,10,minecraft:mossy_cobblestone,10,minecraft:stone_bricks,100)
RB(2,0,-6,minecraft:mossy_stone_bricks,10,minecraft:cracked_stone_bricks,10,minecraft:cobblestone,10,minecraft:mossy_cobblestone,10,minecraft:stone_bricks,100)
RB(8,0,-6,minecraft:mossy_stone_bricks,10,minecraft:cracked_stone_bricks,10,minecraft:cobblestone,10,minecraft:mossy_cobblestone,10,minecraft:stone_bricks,100)
RB(-3,0,-5,minecraft:mossy_stone_bricks,10,minecraft:cracked_stone_bricks,10,minecraft:cobblestone,10,minecraft:mossy_cobblestone,10,minecraft:stone_bricks,100)
RB(2,0,-5,minecraft:mossy_stone_bricks,10,minecraft:cracked_stone_bricks,10,minecraft:cobblestone,10,minecraft:mossy_cobblestone,10,minecraft:stone_bricks,100)
