#######################################################################
# +-----------------------------------------------------------------+ #
# |                            BO3 object                           | #
# +-----------------------------------------------------------------+ #
#######################################################################

Author: Bo3 BulkEdit

Description: Converted Schematic - Modified by Bo3BulkEdit

Version: 3

SettingsMode: WriteDisable

#######################################################################
# +-----------------------------------------------------------------+ #
# |                          Main settings                          | #
# +-----------------------------------------------------------------+ #
#######################################################################



Frequency: 0


SpawnHeight: randomY





##############################
# Height Limits for the BO3. #
##############################

MinHeight: 0
MaxHeight: 256

#######################################################################
# +-----------------------------------------------------------------+ #
# |                      Source block settings                      | #
# +-----------------------------------------------------------------+ #
#######################################################################

CanOverride: true
MaxPercentageOutsideSourceBlock: 100
OutsideSourceBlock: placeAnyway

#######################################################################
# +-----------------------------------------------------------------+ #
# |                               OTG+                              | #
# +-----------------------------------------------------------------+ #
#######################################################################

#######################################################################
# +-----------------------------------------------------------------+ #
# |                              Blocks                             | #
# +-----------------------------------------------------------------+ #
#######################################################################

B(0,750,0,AIR)
B(15,750,15,AIR)
B(2,-2,15,STAINED_GLASS:15)
B(1,-1,13,STAINED_GLASS:15)
B(2,-1,13,STAINED_GLASS:15)
B(0,-1,14,STAINED_GLASS:15)
B(2,-1,14,STAINED_GLASS:15)
B(3,-1,14,STAINED_GLASS:15)
B(0,-1,15,STAINED_GLASS:15)
B(1,-1,15,STAINED_GLASS:15)
B(2,-1,15,STAINED_GLASS:15)
B(3,-1,15,STAINED_GLASS:15)
B(0,0,12,STAINED_GLASS:15)
B(1,0,12,STAINED_GLASS:15)
B(0,0,13,STAINED_GLASS:10)
B(1,0,13,STAINED_GLASS:15)
B(2,0,13,STAINED_GLASS:15)
B(3,0,13,STAINED_GLASS:15)
B(0,0,14,STAINED_GLASS:15)
B(1,0,14,STAINED_GLASS:15)
B(2,0,14,STAINED_GLASS:15)
B(3,0,14,STAINED_GLASS:15)
B(4,0,14,STAINED_GLASS:15)
B(0,0,15,STAINED_GLASS:15)
B(1,0,15,STAINED_GLASS:15)
B(2,0,15,STAINED_GLASS:11)
B(3,0,15,STAINED_GLASS:15)
B(4,0,15,STAINED_GLASS:15)
B(5,0,15,STAINED_GLASS:15)
B(0,1,11,STAINED_GLASS:15)
B(0,1,12,STAINED_GLASS:10)
B(1,1,12,STAINED_GLASS:15)
B(0,1,13,STAINED_GLASS:15)
B(1,1,13,STAINED_GLASS:10)
B(2,1,13,STAINED_GLASS:15)
B(3,1,13,STAINED_GLASS:15)
B(0,1,14,STAINED_GLASS:10)
B(1,1,14,STAINED_GLASS:11)
B(2,1,14,STAINED_GLASS:10)
B(3,1,14,STAINED_GLASS:15)
B(4,1,14,STAINED_GLASS:15)
B(0,1,15,PURPLE_GLAZED_TERRACOTTA:3)
B(1,1,15,STAINED_GLASS:11)
B(2,1,15,STAINED_GLASS:11)
B(3,1,15,STAINED_GLASS:10)
B(4,1,15,STAINED_GLASS:10)
B(5,1,15,STAINED_GLASS:15)
B(0,2,11,STAINED_GLASS:15)
B(0,2,12,STAINED_GLASS:15)
B(1,2,12,STAINED_GLASS:15)
B(2,2,12,STAINED_GLASS:15)
B(0,2,13,STAINED_GLASS:10)
B(1,2,13,STAINED_GLASS:10)
B(2,2,13,STAINED_GLASS:15)
B(3,2,13,STAINED_GLASS:15)
B(0,2,14,STAINED_GLASS:11)
B(1,2,14,STAINED_GLASS:11)
B(2,2,14,STAINED_GLASS:10)
B(3,2,14,STAINED_GLASS:10)
B(4,2,14,STAINED_GLASS:15)
B(0,2,15,PURPLE_GLAZED_TERRACOTTA:3)
B(1,2,15,STAINED_GLASS:11)
B(2,2,15,STAINED_GLASS:11)
B(3,2,15,STAINED_GLASS:10)
B(4,2,15,STAINED_GLASS:10)
B(5,2,15,STAINED_GLASS:15)
B(0,3,11,STAINED_GLASS:15)
B(0,3,12,STAINED_GLASS:10)
B(1,3,12,STAINED_GLASS:15)
B(2,3,12,STAINED_GLASS:15)
B(0,3,13,STAINED_GLASS:11)
B(1,3,13,STAINED_GLASS:10)
B(2,3,13,STAINED_GLASS:15)
B(3,3,13,STAINED_GLASS:15)
B(0,3,14,STAINED_GLASS:11)
B(1,3,14,STAINED_GLASS:11)
B(2,3,14,STAINED_GLASS:10)
B(3,3,14,STAINED_GLASS:10)
B(4,3,14,STAINED_GLASS:15)
B(0,3,15,SEA_LANTERN)
B(1,3,15,STAINED_GLASS:11)
B(2,3,15,STAINED_GLASS:11)
B(3,3,15,STAINED_GLASS:10)
B(4,3,15,STAINED_GLASS:15)
B(0,4,11,STAINED_GLASS:15)
B(1,4,11,STAINED_GLASS:15)
B(0,4,12,STAINED_GLASS:10)
B(1,4,12,STAINED_GLASS:15)
B(2,4,12,STAINED_GLASS:15)
B(0,4,13,STAINED_GLASS:11)
B(1,4,13,STAINED_GLASS:10)
B(2,4,13,STAINED_GLASS:10)
B(3,4,13,STAINED_GLASS:15)
B(0,4,14,STAINED_GLASS:11)
B(1,4,14,STAINED_GLASS:11)
B(2,4,14,STAINED_GLASS:10)
B(3,4,14,STAINED_GLASS:10)
B(4,4,14,STAINED_GLASS:15)
B(0,4,15,SEA_LANTERN)
B(1,4,15,STAINED_GLASS:11)
B(2,4,15,STAINED_GLASS:11)
B(3,4,15,STAINED_GLASS:10)
B(4,4,15,STAINED_GLASS:15)
B(0,5,11,STAINED_GLASS:15)
B(1,5,11,STAINED_GLASS:15)
B(0,5,12,STAINED_GLASS:10)
B(1,5,12,STAINED_GLASS:15)
B(2,5,12,STAINED_GLASS:15)
B(0,5,13,STAINED_GLASS:11)
B(1,5,13,STAINED_GLASS:10)
B(2,5,13,STAINED_GLASS:10)
B(3,5,13,STAINED_GLASS:15)
B(0,5,14,STAINED_GLASS:11)
B(1,5,14,STAINED_GLASS:11)
B(2,5,14,STAINED_GLASS:10)
B(3,5,14,STAINED_GLASS:15)
B(0,5,15,SEA_LANTERN)
B(1,5,15,STAINED_GLASS:11)
B(2,5,15,STAINED_GLASS:11)
B(3,5,15,STAINED_GLASS:10)
B(4,5,15,STAINED_GLASS:15)
B(0,6,10,STAINED_GLASS:15)
B(0,6,11,STAINED_GLASS:15)
B(1,6,11,STAINED_GLASS:15)
B(0,6,12,STAINED_GLASS:10)
B(1,6,12,STAINED_GLASS:10)
B(2,6,12,STAINED_GLASS:15)
B(0,6,13,STAINED_GLASS:11)
B(1,6,13,STAINED_GLASS:10)
B(2,6,13,STAINED_GLASS:10)
B(3,6,13,STAINED_GLASS:15)
B(0,6,14,STAINED_GLASS:11)
B(1,6,14,STAINED_GLASS:11)
B(2,6,14,STAINED_GLASS:10)
B(3,6,14,STAINED_GLASS:3)
B(0,6,15,STAINED_GLASS:11)
B(1,6,15,STAINED_GLASS:11)
B(2,6,15,STAINED_GLASS:10)
B(3,6,15,STAINED_GLASS:3)
B(0,7,10,STAINED_GLASS:15)
B(0,7,11,STAINED_GLASS:3)
B(1,7,11,STAINED_GLASS:3)
B(0,7,12,STAINED_GLASS:10)
B(1,7,12,STAINED_GLASS:10)
B(2,7,12,STAINED_GLASS:3)
B(0,7,13,STAINED_GLASS:11)
B(1,7,13,STAINED_GLASS:10)
B(2,7,13,STAINED_GLASS:3)
B(0,7,14,STAINED_GLASS:11)
B(1,7,14,STAINED_GLASS:11)
B(2,7,14,STAINED_GLASS:10)
B(3,7,14,STAINED_GLASS:3)
B(0,7,15,STAINED_GLASS:11)
B(1,7,15,STAINED_GLASS:10)
B(2,7,15,STAINED_GLASS:3)
B(0,8,10,STAINED_GLASS:3)
B(0,8,11,STAINED_GLASS:10)
B(1,8,11,STAINED_GLASS:3)
B(0,8,12,STAINED_GLASS:10)
B(1,8,12,STAINED_GLASS:10)
B(2,8,12,STAINED_GLASS:3)
B(0,8,13,PURPLE_GLAZED_TERRACOTTA:3)
B(1,8,13,STAINED_GLASS:10)
B(2,8,13,STAINED_GLASS:3)
B(0,8,14,PURPLE_GLAZED_TERRACOTTA:3)
B(1,8,14,STAINED_GLASS:10)
B(2,8,14,STAINED_GLASS:3)
B(0,8,15,STAINED_GLASS:10)
B(1,8,15,STAINED_GLASS:3)
B(0,9,10,STAINED_GLASS:3)
B(0,9,11,STAINED_GLASS:10)
B(1,9,11,STAINED_GLASS:3)
B(0,9,12,STAINED_GLASS:10)
B(1,9,12,STAINED_GLASS:3)
B(0,9,13,PURPLE_GLAZED_TERRACOTTA:3)
B(1,9,13,STAINED_GLASS:10)
B(2,9,13,STAINED_GLASS:3)
B(0,9,14,STAINED_GLASS:10)
B(1,9,14,STAINED_GLASS:3)
B(0,9,15,STAINED_GLASS:10)
B(1,9,15,STAINED_GLASS:3)
B(0,10,10,STAINED_GLASS:3)
B(0,10,11,STAINED_GLASS:10)
B(1,10,11,STAINED_GLASS:15)
B(0,10,12,STAINED_GLASS:10)
B(1,10,12,STAINED_GLASS:15)
B(0,10,13,STAINED_GLASS:10)
B(1,10,13,STAINED_GLASS:3)
B(0,10,14,STAINED_GLASS:3)
B(0,10,15,STAINED_GLASS:15)
B(0,11,10,STAINED_GLASS:15)
B(0,11,11,STAINED_GLASS:15)
B(0,11,12,STAINED_GLASS:10)
B(1,11,12,STAINED_GLASS:3)
B(0,11,13,STAINED_GLASS:3)
B(0,11,14,STAINED_GLASS:3)
B(0,12,10,STAINED_GLASS:15)
B(0,12,11,STAINED_GLASS:15)
B(0,12,12,STAINED_GLASS:3)
B(0,13,11,STAINED_GLASS:15)

#######################################################################
# +-----------------------------------------------------------------+ #
# |                             Branches                            | #
# +-----------------------------------------------------------------+ #
#######################################################################

BR(-16,0,0,true,SPIKE-FAT-MED-04_0x0,NORTH,100,0)
