#######################################################################
# +-----------------------------------------------------------------+ #
# |                            BO3 object                           | #
# +-----------------------------------------------------------------+ #
#######################################################################

Author: Bo3 BulkEdit

Description: Converted Schematic - Modified by Bo3BulkEdit

Version: 3

SettingsMode: WriteDisable

#######################################################################
# +-----------------------------------------------------------------+ #
# |                          Main settings                          | #
# +-----------------------------------------------------------------+ #
#######################################################################

IsOTGPlus: true
Tree: false
Frequency: 1
Rarity: 100.0
RotateRandomly: false
SpawnHeight: randomY
MaxBranchDepth: 10
ExcludedBiomes: All

##############################
# Height Limits for the BO3. #
##############################

MinHeight: 0
MaxHeight: 255

#######################################################################
# +-----------------------------------------------------------------+ #
# |                      Source block settings                      | #
# +-----------------------------------------------------------------+ #
#######################################################################

CanOverride: true
MaxPercentageOutsideSourceBlock: 100
OutsideSourceBlock: placeAnyway

#######################################################################
# +-----------------------------------------------------------------+ #
# |                               OTG+                              | #
# +-----------------------------------------------------------------+ #
#######################################################################

BO3Group: CeilingCrystals:0

#######################################################################
# +-----------------------------------------------------------------+ #
# |                              Blocks                             | #
# +-----------------------------------------------------------------+ #
#######################################################################

B(0,750,0,AIR)
B(15,750,15,AIR)
B(15,-30,15,STAINED_GLASS:9)
B(15,-29,14,STAINED_GLASS:9)
B(14,-29,15,STAINED_GLASS:9)
B(15,-29,15,STAINED_GLASS:11)
B(15,-28,13,STAINED_GLASS:9)
B(14,-28,14,STAINED_GLASS:9)
B(15,-28,14,STAINED_GLASS:11)
B(13,-28,15,STAINED_GLASS:9)
B(14,-28,15,STAINED_GLASS:11)
B(15,-28,15,STAINED_GLASS:10)
B(15,-27,12,STAINED_GLASS:15)
B(14,-27,13,STAINED_GLASS:9)
B(15,-27,13,STAINED_GLASS:11)
B(13,-27,14,STAINED_GLASS:9)
B(14,-27,14,STAINED_GLASS:11)
B(15,-27,14,STAINED_GLASS:10)
B(12,-27,15,STAINED_GLASS:9)
B(13,-27,15,STAINED_GLASS:11)
B(14,-27,15,STAINED_GLASS:10)
B(15,-27,15,STAINED_GLASS:10)
B(15,-26,11,STAINED_GLASS:15)
B(14,-26,12,STAINED_GLASS:15)
B(15,-26,12,STAINED_GLASS:11)
B(13,-26,13,STAINED_GLASS:9)
B(14,-26,13,STAINED_GLASS:11)
B(15,-26,13,STAINED_GLASS:10)
B(12,-26,14,STAINED_GLASS:9)
B(13,-26,14,STAINED_GLASS:11)
B(14,-26,14,STAINED_GLASS:10)
B(15,-26,14,STAINED_GLASS:10)
B(11,-26,15,STAINED_GLASS:9)
B(12,-26,15,STAINED_GLASS:11)
B(13,-26,15,STAINED_GLASS:10)
B(14,-26,15,STAINED_GLASS:10)
B(15,-26,15,SEA_LANTERN)
B(15,-25,10,STAINED_GLASS:15)
B(14,-25,11,STAINED_GLASS:15)
B(15,-25,11,STAINED_GLASS:11)
B(13,-25,12,STAINED_GLASS:9)
B(14,-25,12,STAINED_GLASS:11)
B(15,-25,12,STAINED_GLASS:10)
B(12,-25,13,STAINED_GLASS:9)
B(13,-25,13,STAINED_GLASS:11)
B(14,-25,13,STAINED_GLASS:10)
B(15,-25,13,STAINED_GLASS:10)
B(11,-25,14,STAINED_GLASS:9)
B(12,-25,14,STAINED_GLASS:11)
B(13,-25,14,STAINED_GLASS:10)
B(14,-25,14,STAINED_GLASS:10)
B(15,-25,14,SEA_LANTERN)
B(10,-25,15,STAINED_GLASS:9)
B(11,-25,15,STAINED_GLASS:11)
B(12,-25,15,STAINED_GLASS:10)
B(13,-25,15,STAINED_GLASS:10)
B(14,-25,15,SEA_LANTERN)
B(15,-25,15,SEA_LANTERN)
B(14,-24,10,STAINED_GLASS:15)
B(15,-24,10,STAINED_GLASS:15)
B(13,-24,11,STAINED_GLASS:15)
B(14,-24,11,STAINED_GLASS:11)
B(15,-24,11,STAINED_GLASS:11)
B(12,-24,12,STAINED_GLASS:15)
B(13,-24,12,STAINED_GLASS:11)
B(14,-24,12,STAINED_GLASS:10)
B(15,-24,12,STAINED_GLASS:10)
B(11,-24,13,STAINED_GLASS:9)
B(12,-24,13,STAINED_GLASS:11)
B(13,-24,13,STAINED_GLASS:10)
B(14,-24,13,STAINED_GLASS:10)
B(15,-24,13,STAINED_GLASS:10)
B(10,-24,14,STAINED_GLASS:9)
B(11,-24,14,STAINED_GLASS:11)
B(12,-24,14,STAINED_GLASS:10)
B(13,-24,14,STAINED_GLASS:10)
B(14,-24,14,SEA_LANTERN)
B(15,-24,14,SEA_LANTERN)
B(10,-24,15,STAINED_GLASS:9)
B(11,-24,15,STAINED_GLASS:11)
B(12,-24,15,STAINED_GLASS:10)
B(13,-24,15,STAINED_GLASS:10)
B(14,-24,15,SEA_LANTERN)
B(15,-24,15,SEA_LANTERN)
B(14,-23,9,STAINED_GLASS:15)
B(13,-23,10,STAINED_GLASS:15)
B(14,-23,10,STAINED_GLASS:11)
B(15,-23,10,STAINED_GLASS:15)
B(12,-23,11,STAINED_GLASS:15)
B(13,-23,11,STAINED_GLASS:11)
B(14,-23,11,STAINED_GLASS:10)
B(15,-23,11,STAINED_GLASS:11)
B(11,-23,12,STAINED_GLASS:9)
B(12,-23,12,STAINED_GLASS:11)
B(13,-23,12,STAINED_GLASS:10)
B(14,-23,12,STAINED_GLASS:10)
B(15,-23,12,STAINED_GLASS:10)
B(10,-23,13,STAINED_GLASS:9)
B(11,-23,13,STAINED_GLASS:11)
B(12,-23,13,STAINED_GLASS:10)
B(13,-23,13,STAINED_GLASS:10)
B(14,-23,13,SEA_LANTERN)
B(15,-23,13,STAINED_GLASS:10)
B(9,-23,14,STAINED_GLASS:9)
B(10,-23,14,STAINED_GLASS:11)
B(11,-23,14,STAINED_GLASS:10)
B(12,-23,14,STAINED_GLASS:10)
B(13,-23,14,SEA_LANTERN)
B(14,-23,14,SEA_LANTERN)
B(15,-23,14,SEA_LANTERN)
B(10,-23,15,STAINED_GLASS:9)
B(11,-23,15,STAINED_GLASS:11)
B(12,-23,15,STAINED_GLASS:10)
B(13,-23,15,STAINED_GLASS:10)
B(14,-23,15,SEA_LANTERN)
B(15,-23,15,STAINED_GLASS:10)
B(13,-22,9,STAINED_GLASS:15)
B(14,-22,9,STAINED_GLASS:15)
B(12,-22,10,STAINED_GLASS:9)
B(13,-22,10,STAINED_GLASS:11)
B(14,-22,10,STAINED_GLASS:11)
B(15,-22,10,STAINED_GLASS:15)
B(11,-22,11,STAINED_GLASS:9)
B(12,-22,11,STAINED_GLASS:11)
B(13,-22,11,STAINED_GLASS:10)
B(14,-22,11,STAINED_GLASS:10)
B(15,-22,11,STAINED_GLASS:11)
B(10,-22,12,STAINED_GLASS:9)
B(11,-22,12,STAINED_GLASS:11)
B(12,-22,12,STAINED_GLASS:10)
B(13,-22,12,STAINED_GLASS:10)
B(14,-22,12,STAINED_GLASS:10)
B(15,-22,12,STAINED_GLASS:10)
B(9,-22,13,STAINED_GLASS:9)
B(10,-22,13,STAINED_GLASS:11)
B(11,-22,13,STAINED_GLASS:10)
B(12,-22,13,STAINED_GLASS:10)
B(13,-22,13,SEA_LANTERN)
B(14,-22,13,SEA_LANTERN)
B(15,-22,13,STAINED_GLASS:10)
B(9,-22,14,STAINED_GLASS:9)
B(10,-22,14,STAINED_GLASS:11)
B(11,-22,14,STAINED_GLASS:10)
B(12,-22,14,STAINED_GLASS:10)
B(13,-22,14,SEA_LANTERN)
B(14,-22,14,SEA_LANTERN)
B(15,-22,14,STAINED_GLASS:10)
B(10,-22,15,STAINED_GLASS:9)
B(11,-22,15,STAINED_GLASS:11)
B(12,-22,15,STAINED_GLASS:10)
B(13,-22,15,STAINED_GLASS:10)
B(14,-22,15,STAINED_GLASS:10)
B(15,-22,15,STAINED_GLASS:10)
B(13,-21,8,STAINED_GLASS:15)
B(12,-21,9,STAINED_GLASS:9)
B(13,-21,9,STAINED_GLASS:11)
B(14,-21,9,STAINED_GLASS:15)
B(11,-21,10,STAINED_GLASS:9)
B(12,-21,10,STAINED_GLASS:11)
B(13,-21,10,STAINED_GLASS:10)
B(14,-21,10,STAINED_GLASS:11)
B(15,-21,10,STAINED_GLASS:9)
B(10,-21,11,STAINED_GLASS:9)
B(11,-21,11,STAINED_GLASS:11)
B(12,-21,11,STAINED_GLASS:10)
B(13,-21,11,STAINED_GLASS:10)
B(14,-21,11,STAINED_GLASS:10)
B(15,-21,11,STAINED_GLASS:11)
B(9,-21,12,STAINED_GLASS:9)
B(10,-21,12,STAINED_GLASS:11)
B(11,-21,12,STAINED_GLASS:10)
B(12,-21,12,STAINED_GLASS:10)
B(13,-21,12,SEA_LANTERN)
B(14,-21,12,STAINED_GLASS:10)
B(15,-21,12,STAINED_GLASS:10)
B(8,-21,13,STAINED_GLASS:15)
B(9,-21,13,STAINED_GLASS:11)
B(10,-21,13,STAINED_GLASS:10)
B(11,-21,13,STAINED_GLASS:10)
B(12,-21,13,SEA_LANTERN)
B(13,-21,13,SEA_LANTERN)
B(14,-21,13,SEA_LANTERN)
B(15,-21,13,STAINED_GLASS:10)
B(9,-21,14,STAINED_GLASS:9)
B(10,-21,14,STAINED_GLASS:11)
B(11,-21,14,STAINED_GLASS:10)
B(12,-21,14,STAINED_GLASS:10)
B(13,-21,14,SEA_LANTERN)
B(14,-21,14,STAINED_GLASS:10)
B(15,-21,14,STAINED_GLASS:10)
B(10,-21,15,STAINED_GLASS:9)
B(11,-21,15,STAINED_GLASS:11)
B(12,-21,15,STAINED_GLASS:10)
B(13,-21,15,STAINED_GLASS:10)
B(14,-21,15,STAINED_GLASS:10)
B(15,-21,15,STAINED_GLASS:11)
B(12,-20,8,STAINED_GLASS:15)
B(13,-20,8,STAINED_GLASS:15)
B(11,-20,9,STAINED_GLASS:15)
B(12,-20,9,STAINED_GLASS:9)
B(13,-20,9,STAINED_GLASS:9)
B(14,-20,9,STAINED_GLASS:9)
B(15,-20,9,STAINED_GLASS:9)
B(10,-20,10,STAINED_GLASS:15)
B(11,-20,10,STAINED_GLASS:9)
B(12,-20,10,STAINED_GLASS:11)
B(13,-20,10,STAINED_GLASS:11)
B(14,-20,10,STAINED_GLASS:9)
B(15,-20,10,STAINED_GLASS:9)
B(9,-20,11,STAINED_GLASS:9)
B(10,-20,11,STAINED_GLASS:9)
B(11,-20,11,STAINED_GLASS:11)
B(12,-20,11,STAINED_GLASS:11)
B(13,-20,11,STAINED_GLASS:11)
B(14,-20,11,STAINED_GLASS:11)
B(15,-20,11,STAINED_GLASS:9)
B(8,-20,12,STAINED_GLASS:9)
B(9,-20,12,STAINED_GLASS:9)
B(10,-20,12,STAINED_GLASS:11)
B(11,-20,12,STAINED_GLASS:11)
B(12,-20,12,SEA_LANTERN)
B(13,-20,12,SEA_LANTERN)
B(14,-20,12,STAINED_GLASS:11)
B(15,-20,12,STAINED_GLASS:11)
B(8,-20,13,STAINED_GLASS:15)
B(9,-20,13,STAINED_GLASS:9)
B(10,-20,13,STAINED_GLASS:11)
B(11,-20,13,STAINED_GLASS:11)
B(12,-20,13,SEA_LANTERN)
B(13,-20,13,SEA_LANTERN)
B(14,-20,13,STAINED_GLASS:11)
B(15,-20,13,STAINED_GLASS:11)
B(9,-20,14,STAINED_GLASS:9)
B(10,-20,14,STAINED_GLASS:9)
B(11,-20,14,STAINED_GLASS:11)
B(12,-20,14,STAINED_GLASS:11)
B(13,-20,14,STAINED_GLASS:11)
B(14,-20,14,STAINED_GLASS:11)
B(15,-20,14,STAINED_GLASS:9)
B(9,-20,15,STAINED_GLASS:9)
B(10,-20,15,STAINED_GLASS:9)
B(11,-20,15,STAINED_GLASS:9)
B(12,-20,15,STAINED_GLASS:11)
B(13,-20,15,STAINED_GLASS:11)
B(14,-20,15,STAINED_GLASS:9)
B(15,-20,15,STAINED_GLASS:9)
B(12,-19,7,STAINED_GLASS:15)
B(11,-19,8,STAINED_GLASS:15)
B(12,-19,8,STAINED_GLASS:9)
B(13,-19,8,STAINED_GLASS:9)
B(10,-19,9,STAINED_GLASS:15)
B(11,-19,9,STAINED_GLASS:9)
B(12,-19,9,STAINED_GLASS:11)
B(13,-19,9,STAINED_GLASS:9)
B(14,-19,9,STAINED_GLASS:9)
B(15,-19,9,STAINED_GLASS:9)
B(9,-19,10,STAINED_GLASS:15)
B(10,-19,10,STAINED_GLASS:9)
B(11,-19,10,STAINED_GLASS:11)
B(12,-19,10,STAINED_GLASS:11)
B(13,-19,10,STAINED_GLASS:11)
B(14,-19,10,STAINED_GLASS:9)
B(15,-19,10,STAINED_GLASS:9)
B(8,-19,11,STAINED_GLASS:9)
B(9,-19,11,STAINED_GLASS:9)
B(10,-19,11,STAINED_GLASS:11)
B(11,-19,11,STAINED_GLASS:11)
B(12,-19,11,SEA_LANTERN)
B(13,-19,11,STAINED_GLASS:11)
B(14,-19,11,STAINED_GLASS:11)
B(15,-19,11,STAINED_GLASS:15)
B(7,-19,12,STAINED_GLASS:15)
B(8,-19,12,STAINED_GLASS:9)
B(9,-19,12,STAINED_GLASS:11)
B(10,-19,12,STAINED_GLASS:11)
B(11,-19,12,SEA_LANTERN)
B(12,-19,12,SEA_LANTERN)
B(13,-19,12,SEA_LANTERN)
B(14,-19,12,STAINED_GLASS:11)
B(15,-19,12,STAINED_GLASS:11)
B(8,-19,13,STAINED_GLASS:9)
B(9,-19,13,STAINED_GLASS:9)
B(10,-19,13,STAINED_GLASS:11)
B(11,-19,13,STAINED_GLASS:11)
B(12,-19,13,SEA_LANTERN)
B(13,-19,13,STAINED_GLASS:11)
B(14,-19,13,STAINED_GLASS:11)
B(15,-19,13,STAINED_GLASS:15)
B(9,-19,14,STAINED_GLASS:9)
B(10,-19,14,STAINED_GLASS:9)
B(11,-19,14,STAINED_GLASS:11)
B(12,-19,14,STAINED_GLASS:11)
B(13,-19,14,STAINED_GLASS:11)
B(14,-19,14,STAINED_GLASS:9)
B(15,-19,14,STAINED_GLASS:15)
B(9,-19,15,STAINED_GLASS:9)
B(10,-19,15,STAINED_GLASS:9)
B(11,-19,15,STAINED_GLASS:9)
B(12,-19,15,STAINED_GLASS:11)
B(13,-19,15,STAINED_GLASS:9)
B(14,-19,15,STAINED_GLASS:9)
B(15,-19,15,STAINED_GLASS:15)
B(11,-18,7,STAINED_GLASS:15)
B(12,-18,7,STAINED_GLASS:15)
B(10,-18,8,STAINED_GLASS:15)
B(11,-18,8,STAINED_GLASS:9)
B(12,-18,8,STAINED_GLASS:9)
B(13,-18,8,STAINED_GLASS:9)
B(14,-18,8,STAINED_GLASS:9)
B(9,-18,9,STAINED_GLASS:15)
B(10,-18,9,STAINED_GLASS:9)
B(11,-18,9,STAINED_GLASS:11)
B(12,-18,9,STAINED_GLASS:11)
B(13,-18,9,STAINED_GLASS:9)
B(14,-18,9,STAINED_GLASS:9)
B(15,-18,9,STAINED_GLASS:9)
B(8,-18,10,STAINED_GLASS:15)
B(9,-18,10,STAINED_GLASS:9)
B(10,-18,10,STAINED_GLASS:11)
B(11,-18,10,STAINED_GLASS:11)
B(12,-18,10,STAINED_GLASS:11)
B(13,-18,10,STAINED_GLASS:11)
B(14,-18,10,STAINED_GLASS:9)
B(15,-18,10,STAINED_GLASS:15)
B(7,-18,11,STAINED_GLASS:15)
B(8,-18,11,STAINED_GLASS:9)
B(9,-18,11,STAINED_GLASS:11)
B(10,-18,11,STAINED_GLASS:11)
B(11,-18,11,SEA_LANTERN)
B(12,-18,11,SEA_LANTERN)
B(13,-18,11,STAINED_GLASS:11)
B(14,-18,11,STAINED_GLASS:11)
B(15,-18,11,STAINED_GLASS:15)
B(7,-18,12,STAINED_GLASS:9)
B(8,-18,12,STAINED_GLASS:9)
B(9,-18,12,STAINED_GLASS:11)
B(10,-18,12,STAINED_GLASS:11)
B(11,-18,12,SEA_LANTERN)
B(12,-18,12,SEA_LANTERN)
B(13,-18,12,STAINED_GLASS:11)
B(14,-18,12,STAINED_GLASS:11)
B(15,-18,12,STAINED_GLASS:15)
B(8,-18,13,STAINED_GLASS:9)
B(9,-18,13,STAINED_GLASS:9)
B(10,-18,13,STAINED_GLASS:11)
B(11,-18,13,STAINED_GLASS:11)
B(12,-18,13,STAINED_GLASS:11)
B(13,-18,13,STAINED_GLASS:11)
B(14,-18,13,STAINED_GLASS:9)
B(15,-18,13,STAINED_GLASS:15)
B(8,-18,14,STAINED_GLASS:9)
B(9,-18,14,STAINED_GLASS:9)
B(10,-18,14,STAINED_GLASS:9)
B(11,-18,14,STAINED_GLASS:11)
B(12,-18,14,STAINED_GLASS:11)
B(13,-18,14,STAINED_GLASS:9)
B(14,-18,14,STAINED_GLASS:9)
B(15,-18,14,STAINED_GLASS:15)
B(9,-18,15,STAINED_GLASS:15)
B(10,-18,15,STAINED_GLASS:9)
B(11,-18,15,STAINED_GLASS:9)
B(12,-18,15,STAINED_GLASS:9)
B(13,-18,15,STAINED_GLASS:15)
B(14,-18,15,STAINED_GLASS:15)
B(11,-17,6,STAINED_GLASS:15)
B(10,-17,7,STAINED_GLASS:15)
B(11,-17,7,STAINED_GLASS:9)
B(12,-17,7,STAINED_GLASS:9)
B(9,-17,8,STAINED_GLASS:15)
B(10,-17,8,STAINED_GLASS:9)
B(11,-17,8,STAINED_GLASS:11)
B(12,-17,8,STAINED_GLASS:9)
B(13,-17,8,STAINED_GLASS:9)
B(14,-17,8,STAINED_GLASS:9)
B(8,-17,9,STAINED_GLASS:15)
B(9,-17,9,STAINED_GLASS:9)
B(10,-17,9,STAINED_GLASS:11)
B(11,-17,9,STAINED_GLASS:11)
B(12,-17,9,STAINED_GLASS:11)
B(13,-17,9,STAINED_GLASS:9)
B(14,-17,9,STAINED_GLASS:9)
B(15,-17,9,STAINED_GLASS:15)
B(7,-17,10,STAINED_GLASS:15)
B(8,-17,10,STAINED_GLASS:9)
B(9,-17,10,STAINED_GLASS:11)
B(10,-17,10,STAINED_GLASS:11)
B(11,-17,10,SEA_LANTERN)
B(12,-17,10,STAINED_GLASS:11)
B(13,-17,10,STAINED_GLASS:11)
B(14,-17,10,STAINED_GLASS:9)
B(15,-17,10,STAINED_GLASS:15)
B(6,-17,11,STAINED_GLASS:15)
B(7,-17,11,STAINED_GLASS:9)
B(8,-17,11,STAINED_GLASS:11)
B(9,-17,11,STAINED_GLASS:11)
B(10,-17,11,SEA_LANTERN)
B(11,-17,11,SEA_LANTERN)
B(12,-17,11,SEA_LANTERN)
B(13,-17,11,STAINED_GLASS:11)
B(14,-17,11,STAINED_GLASS:11)
B(15,-17,11,STAINED_GLASS:15)
B(7,-17,12,STAINED_GLASS:9)
B(8,-17,12,STAINED_GLASS:9)
B(9,-17,12,STAINED_GLASS:11)
B(10,-17,12,STAINED_GLASS:11)
B(11,-17,12,SEA_LANTERN)
B(12,-17,12,STAINED_GLASS:11)
B(13,-17,12,STAINED_GLASS:11)
B(14,-17,12,STAINED_GLASS:9)
B(15,-17,12,STAINED_GLASS:15)
B(8,-17,13,STAINED_GLASS:9)
B(9,-17,13,STAINED_GLASS:9)
B(10,-17,13,STAINED_GLASS:11)
B(11,-17,13,STAINED_GLASS:11)
B(12,-17,13,STAINED_GLASS:11)
B(13,-17,13,STAINED_GLASS:9)
B(14,-17,13,STAINED_GLASS:9)
B(15,-17,13,STAINED_GLASS:15)
B(8,-17,14,STAINED_GLASS:9)
B(9,-17,14,STAINED_GLASS:9)
B(10,-17,14,STAINED_GLASS:9)
B(11,-17,14,STAINED_GLASS:11)
B(12,-17,14,STAINED_GLASS:9)
B(13,-17,14,STAINED_GLASS:9)
B(14,-17,14,STAINED_GLASS:15)
B(9,-17,15,STAINED_GLASS:15)
B(10,-17,15,STAINED_GLASS:15)
B(11,-17,15,STAINED_GLASS:9)
B(12,-17,15,STAINED_GLASS:15)
B(13,-17,15,STAINED_GLASS:15)
B(10,-16,6,STAINED_GLASS:15)
B(11,-16,6,STAINED_GLASS:9)
B(9,-16,7,STAINED_GLASS:15)
B(10,-16,7,STAINED_GLASS:9)
B(11,-16,7,STAINED_GLASS:9)
B(12,-16,7,STAINED_GLASS:9)
B(13,-16,7,STAINED_GLASS:9)
B(8,-16,8,STAINED_GLASS:15)
B(9,-16,8,STAINED_GLASS:9)
B(10,-16,8,STAINED_GLASS:11)
B(11,-16,8,STAINED_GLASS:11)
B(12,-16,8,STAINED_GLASS:9)
B(13,-16,8,STAINED_GLASS:9)
B(14,-16,8,STAINED_GLASS:9)
B(7,-16,9,STAINED_GLASS:15)
B(8,-16,9,STAINED_GLASS:9)
B(9,-16,9,STAINED_GLASS:11)
B(10,-16,9,STAINED_GLASS:11)
B(11,-16,9,STAINED_GLASS:11)
B(12,-16,9,STAINED_GLASS:11)
B(13,-16,9,STAINED_GLASS:9)
B(14,-16,9,STAINED_GLASS:9)
B(15,-16,9,STAINED_GLASS:15)
B(6,-16,10,STAINED_GLASS:15)
B(7,-16,10,STAINED_GLASS:9)
B(8,-16,10,STAINED_GLASS:11)
B(9,-16,10,STAINED_GLASS:11)
B(10,-16,10,SEA_LANTERN)
B(11,-16,10,SEA_LANTERN)
B(12,-16,10,STAINED_GLASS:11)
B(13,-16,10,STAINED_GLASS:11)
B(14,-16,10,STAINED_GLASS:9)
B(15,-16,10,STAINED_GLASS:15)
B(6,-16,11,STAINED_GLASS:15)
B(7,-16,11,STAINED_GLASS:9)
B(8,-16,11,STAINED_GLASS:11)
B(9,-16,11,STAINED_GLASS:11)
B(10,-16,11,SEA_LANTERN)
B(11,-16,11,SEA_LANTERN)
B(12,-16,11,STAINED_GLASS:11)
B(13,-16,11,STAINED_GLASS:11)
B(14,-16,11,STAINED_GLASS:9)
B(15,-16,11,STAINED_GLASS:15)
B(7,-16,12,STAINED_GLASS:15)
B(8,-16,12,STAINED_GLASS:9)
B(9,-16,12,STAINED_GLASS:11)
B(10,-16,12,STAINED_GLASS:11)
B(11,-16,12,STAINED_GLASS:11)
B(12,-16,12,STAINED_GLASS:11)
B(13,-16,12,STAINED_GLASS:9)
B(14,-16,12,STAINED_GLASS:15)
B(7,-16,13,STAINED_GLASS:9)
B(8,-16,13,STAINED_GLASS:9)
B(9,-16,13,STAINED_GLASS:9)
B(10,-16,13,STAINED_GLASS:11)
B(11,-16,13,STAINED_GLASS:11)
B(12,-16,13,STAINED_GLASS:9)
B(13,-16,13,STAINED_GLASS:9)
B(14,-16,13,STAINED_GLASS:15)
B(8,-16,14,STAINED_GLASS:9)
B(9,-16,14,STAINED_GLASS:9)
B(10,-16,14,STAINED_GLASS:9)
B(11,-16,14,STAINED_GLASS:9)
B(12,-16,14,STAINED_GLASS:15)
B(13,-16,14,STAINED_GLASS:15)
B(9,-16,15,STAINED_GLASS:15)
B(10,-16,15,STAINED_GLASS:15)
B(11,-16,15,STAINED_GLASS:15)
B(10,-15,5,STAINED_GLASS:15)
B(9,-15,6,STAINED_GLASS:15)
B(10,-15,6,STAINED_GLASS:9)
B(11,-15,6,STAINED_GLASS:9)
B(8,-15,7,STAINED_GLASS:15)
B(9,-15,7,STAINED_GLASS:9)
B(10,-15,7,STAINED_GLASS:11)
B(11,-15,7,STAINED_GLASS:9)
B(12,-15,7,STAINED_GLASS:9)
B(13,-15,7,STAINED_GLASS:9)
B(7,-15,8,STAINED_GLASS:15)
B(8,-15,8,STAINED_GLASS:9)
B(9,-15,8,STAINED_GLASS:11)
B(10,-15,8,STAINED_GLASS:11)
B(11,-15,8,STAINED_GLASS:11)
B(12,-15,8,STAINED_GLASS:9)
B(13,-15,8,STAINED_GLASS:9)
B(14,-15,8,STAINED_GLASS:15)
B(6,-15,9,STAINED_GLASS:15)
B(7,-15,9,STAINED_GLASS:9)
B(8,-15,9,STAINED_GLASS:11)
B(9,-15,9,STAINED_GLASS:11)
B(10,-15,9,SEA_LANTERN)
B(11,-15,9,STAINED_GLASS:11)
B(12,-15,9,STAINED_GLASS:11)
B(13,-15,9,STAINED_GLASS:9)
B(14,-15,9,STAINED_GLASS:15)
B(5,-15,10,STAINED_GLASS:15)
B(6,-15,10,STAINED_GLASS:9)
B(7,-15,10,STAINED_GLASS:11)
B(8,-15,10,STAINED_GLASS:11)
B(9,-15,10,SEA_LANTERN)
B(10,-15,10,SEA_LANTERN)
B(11,-15,10,SEA_LANTERN)
B(12,-15,10,STAINED_GLASS:11)
B(13,-15,10,STAINED_GLASS:11)
B(14,-15,10,STAINED_GLASS:9)
B(15,-15,10,STAINED_GLASS:15)
B(6,-15,11,STAINED_GLASS:15)
B(7,-15,11,STAINED_GLASS:9)
B(8,-15,11,STAINED_GLASS:11)
B(9,-15,11,STAINED_GLASS:11)
B(10,-15,11,SEA_LANTERN)
B(11,-15,11,STAINED_GLASS:11)
B(12,-15,11,STAINED_GLASS:11)
B(13,-15,11,STAINED_GLASS:9)
B(14,-15,11,STAINED_GLASS:15)
B(7,-15,12,STAINED_GLASS:9)
B(8,-15,12,STAINED_GLASS:9)
B(9,-15,12,STAINED_GLASS:11)
B(10,-15,12,STAINED_GLASS:11)
B(11,-15,12,STAINED_GLASS:11)
B(12,-15,12,STAINED_GLASS:9)
B(13,-15,12,STAINED_GLASS:9)
B(14,-15,12,STAINED_GLASS:15)
B(7,-15,13,STAINED_GLASS:9)
B(8,-15,13,STAINED_GLASS:9)
B(9,-15,13,STAINED_GLASS:9)
B(10,-15,13,STAINED_GLASS:11)
B(11,-15,13,STAINED_GLASS:9)
B(12,-15,13,STAINED_GLASS:9)
B(13,-15,13,STAINED_GLASS:15)
B(8,-15,14,STAINED_GLASS:15)
B(9,-15,14,STAINED_GLASS:15)
B(10,-15,14,STAINED_GLASS:9)
B(11,-15,14,STAINED_GLASS:15)
B(12,-15,14,STAINED_GLASS:15)
B(10,-15,15,STAINED_GLASS:15)
B(9,-14,5,STAINED_GLASS:9)
B(10,-14,5,STAINED_GLASS:15)
B(8,-14,6,STAINED_GLASS:9)
B(9,-14,6,STAINED_GLASS:9)
B(10,-14,6,STAINED_GLASS:9)
B(11,-14,6,STAINED_GLASS:9)
B(12,-14,6,STAINED_GLASS:9)
B(7,-14,7,STAINED_GLASS:15)
B(8,-14,7,STAINED_GLASS:9)
B(9,-14,7,STAINED_GLASS:11)
B(10,-14,7,STAINED_GLASS:11)
B(11,-14,7,STAINED_GLASS:9)
B(12,-14,7,STAINED_GLASS:9)
B(13,-14,7,STAINED_GLASS:9)
B(6,-14,8,STAINED_GLASS:15)
B(7,-14,8,STAINED_GLASS:9)
B(8,-14,8,STAINED_GLASS:11)
B(9,-14,8,STAINED_GLASS:11)
B(10,-14,8,STAINED_GLASS:11)
B(11,-14,8,STAINED_GLASS:11)
B(12,-14,8,STAINED_GLASS:9)
B(13,-14,8,STAINED_GLASS:9)
B(14,-14,8,STAINED_GLASS:15)
B(5,-14,9,STAINED_GLASS:15)
B(6,-14,9,STAINED_GLASS:9)
B(7,-14,9,STAINED_GLASS:11)
B(8,-14,9,STAINED_GLASS:11)
B(9,-14,9,SEA_LANTERN)
B(10,-14,9,SEA_LANTERN)
B(11,-14,9,STAINED_GLASS:11)
B(12,-14,9,STAINED_GLASS:11)
B(13,-14,9,STAINED_GLASS:9)
B(14,-14,9,STAINED_GLASS:15)
B(5,-14,10,STAINED_GLASS:15)
B(6,-14,10,STAINED_GLASS:9)
B(7,-14,10,STAINED_GLASS:11)
B(8,-14,10,STAINED_GLASS:11)
B(9,-14,10,SEA_LANTERN)
B(10,-14,10,SEA_LANTERN)
B(11,-14,10,STAINED_GLASS:11)
B(12,-14,10,STAINED_GLASS:11)
B(13,-14,10,STAINED_GLASS:9)
B(14,-14,10,STAINED_GLASS:15)
B(6,-14,11,STAINED_GLASS:15)
B(7,-14,11,STAINED_GLASS:9)
B(8,-14,11,STAINED_GLASS:11)
B(9,-14,11,STAINED_GLASS:11)
B(10,-14,11,STAINED_GLASS:11)
B(11,-14,11,STAINED_GLASS:11)
B(12,-14,11,STAINED_GLASS:9)
B(13,-14,11,STAINED_GLASS:15)
B(6,-14,12,STAINED_GLASS:9)
B(7,-14,12,STAINED_GLASS:9)
B(8,-14,12,STAINED_GLASS:9)
B(9,-14,12,STAINED_GLASS:11)
B(10,-14,12,STAINED_GLASS:11)
B(11,-14,12,STAINED_GLASS:9)
B(12,-14,12,STAINED_GLASS:9)
B(13,-14,12,STAINED_GLASS:15)
B(7,-14,13,STAINED_GLASS:9)
B(8,-14,13,STAINED_GLASS:9)
B(9,-14,13,STAINED_GLASS:9)
B(10,-14,13,STAINED_GLASS:9)
B(11,-14,13,STAINED_GLASS:15)
B(12,-14,13,STAINED_GLASS:15)
B(8,-14,14,STAINED_GLASS:9)
B(9,-14,14,STAINED_GLASS:15)
B(10,-14,14,STAINED_GLASS:15)
B(9,-13,4,STAINED_GLASS:9)
B(8,-13,5,STAINED_GLASS:9)
B(9,-13,5,STAINED_GLASS:9)
B(10,-13,5,STAINED_GLASS:9)
B(7,-13,6,STAINED_GLASS:9)
B(8,-13,6,STAINED_GLASS:9)
B(9,-13,6,STAINED_GLASS:11)
B(10,-13,6,STAINED_GLASS:9)
B(11,-13,6,STAINED_GLASS:9)
B(12,-13,6,STAINED_GLASS:9)
B(6,-13,7,STAINED_GLASS:15)
B(7,-13,7,STAINED_GLASS:9)
B(8,-13,7,STAINED_GLASS:11)
B(9,-13,7,STAINED_GLASS:11)
B(10,-13,7,STAINED_GLASS:11)
B(11,-13,7,STAINED_GLASS:9)
B(12,-13,7,STAINED_GLASS:9)
B(13,-13,7,STAINED_GLASS:15)
B(5,-13,8,STAINED_GLASS:15)
B(6,-13,8,STAINED_GLASS:9)
B(7,-13,8,STAINED_GLASS:11)
B(8,-13,8,STAINED_GLASS:11)
B(9,-13,8,SEA_LANTERN)
B(10,-13,8,STAINED_GLASS:11)
B(11,-13,8,STAINED_GLASS:11)
B(12,-13,8,STAINED_GLASS:9)
B(13,-13,8,STAINED_GLASS:15)
B(4,-13,9,STAINED_GLASS:15)
B(5,-13,9,STAINED_GLASS:9)
B(6,-13,9,STAINED_GLASS:11)
B(7,-13,9,STAINED_GLASS:11)
B(8,-13,9,SEA_LANTERN)
B(9,-13,9,SEA_LANTERN)
B(10,-13,9,SEA_LANTERN)
B(11,-13,9,STAINED_GLASS:11)
B(12,-13,9,STAINED_GLASS:11)
B(13,-13,9,STAINED_GLASS:9)
B(14,-13,9,STAINED_GLASS:15)
B(5,-13,10,STAINED_GLASS:15)
B(6,-13,10,STAINED_GLASS:9)
B(7,-13,10,STAINED_GLASS:11)
B(8,-13,10,STAINED_GLASS:11)
B(9,-13,10,SEA_LANTERN)
B(10,-13,10,STAINED_GLASS:11)
B(11,-13,10,STAINED_GLASS:11)
B(12,-13,10,STAINED_GLASS:9)
B(13,-13,10,STAINED_GLASS:15)
B(6,-13,11,STAINED_GLASS:15)
B(7,-13,11,STAINED_GLASS:9)
B(8,-13,11,STAINED_GLASS:11)
B(9,-13,11,STAINED_GLASS:11)
B(10,-13,11,STAINED_GLASS:11)
B(11,-13,11,STAINED_GLASS:9)
B(12,-13,11,STAINED_GLASS:9)
B(13,-13,11,STAINED_GLASS:15)
B(6,-13,12,STAINED_GLASS:15)
B(7,-13,12,STAINED_GLASS:9)
B(8,-13,12,STAINED_GLASS:9)
B(9,-13,12,STAINED_GLASS:11)
B(10,-13,12,STAINED_GLASS:9)
B(11,-13,12,STAINED_GLASS:9)
B(12,-13,12,STAINED_GLASS:15)
B(7,-13,13,STAINED_GLASS:9)
B(8,-13,13,STAINED_GLASS:9)
B(9,-13,13,STAINED_GLASS:9)
B(10,-13,13,STAINED_GLASS:15)
B(11,-13,13,STAINED_GLASS:15)
B(9,-13,14,STAINED_GLASS:9)
B(8,-12,4,STAINED_GLASS:9)
B(9,-12,4,STAINED_GLASS:15)
B(7,-12,5,STAINED_GLASS:9)
B(8,-12,5,STAINED_GLASS:9)
B(9,-12,5,STAINED_GLASS:9)
B(10,-12,5,STAINED_GLASS:9)
B(11,-12,5,STAINED_GLASS:9)
B(6,-12,6,STAINED_GLASS:15)
B(7,-12,6,STAINED_GLASS:9)
B(8,-12,6,STAINED_GLASS:11)
B(9,-12,6,STAINED_GLASS:11)
B(10,-12,6,STAINED_GLASS:9)
B(11,-12,6,STAINED_GLASS:9)
B(12,-12,6,STAINED_GLASS:9)
B(5,-12,7,STAINED_GLASS:15)
B(6,-12,7,STAINED_GLASS:9)
B(7,-12,7,STAINED_GLASS:11)
B(8,-12,7,STAINED_GLASS:11)
B(9,-12,7,STAINED_GLASS:11)
B(10,-12,7,STAINED_GLASS:11)
B(11,-12,7,STAINED_GLASS:9)
B(12,-12,7,STAINED_GLASS:9)
B(13,-12,7,STAINED_GLASS:15)
B(4,-12,8,STAINED_GLASS:15)
B(5,-12,8,STAINED_GLASS:9)
B(6,-12,8,STAINED_GLASS:11)
B(7,-12,8,STAINED_GLASS:11)
B(8,-12,8,SEA_LANTERN)
B(9,-12,8,SEA_LANTERN)
B(10,-12,8,STAINED_GLASS:11)
B(11,-12,8,STAINED_GLASS:11)
B(12,-12,8,STAINED_GLASS:9)
B(13,-12,8,STAINED_GLASS:15)
B(4,-12,9,STAINED_GLASS:15)
B(5,-12,9,STAINED_GLASS:9)
B(6,-12,9,STAINED_GLASS:11)
B(7,-12,9,STAINED_GLASS:11)
B(8,-12,9,SEA_LANTERN)
B(9,-12,9,SEA_LANTERN)
B(10,-12,9,STAINED_GLASS:11)
B(11,-12,9,STAINED_GLASS:11)
B(12,-12,9,STAINED_GLASS:9)
B(13,-12,9,STAINED_GLASS:15)
B(5,-12,10,STAINED_GLASS:15)
B(6,-12,10,STAINED_GLASS:9)
B(7,-12,10,STAINED_GLASS:11)
B(8,-12,10,STAINED_GLASS:11)
B(9,-12,10,STAINED_GLASS:11)
B(10,-12,10,STAINED_GLASS:11)
B(11,-12,10,STAINED_GLASS:9)
B(12,-12,10,STAINED_GLASS:15)
B(5,-12,11,STAINED_GLASS:15)
B(6,-12,11,STAINED_GLASS:9)
B(7,-12,11,STAINED_GLASS:9)
B(8,-12,11,STAINED_GLASS:11)
B(9,-12,11,STAINED_GLASS:11)
B(10,-12,11,STAINED_GLASS:9)
B(11,-12,11,STAINED_GLASS:9)
B(12,-12,11,STAINED_GLASS:15)
B(6,-12,12,STAINED_GLASS:15)
B(7,-12,12,STAINED_GLASS:9)
B(8,-12,12,STAINED_GLASS:9)
B(9,-12,12,STAINED_GLASS:9)
B(10,-12,12,STAINED_GLASS:15)
B(11,-12,12,STAINED_GLASS:15)
B(7,-12,13,STAINED_GLASS:15)
B(8,-12,13,STAINED_GLASS:15)
B(9,-12,13,STAINED_GLASS:9)
B(8,-11,3,STAINED_GLASS:9)
B(7,-11,4,STAINED_GLASS:9)
B(8,-11,4,STAINED_GLASS:9)
B(9,-11,4,STAINED_GLASS:9)
B(6,-11,5,STAINED_GLASS:9)
B(7,-11,5,STAINED_GLASS:9)
B(8,-11,5,STAINED_GLASS:11)
B(9,-11,5,STAINED_GLASS:9)
B(10,-11,5,STAINED_GLASS:9)
B(11,-11,5,STAINED_GLASS:9)
B(5,-11,6,STAINED_GLASS:15)
B(6,-11,6,STAINED_GLASS:9)
B(7,-11,6,STAINED_GLASS:11)
B(8,-11,6,STAINED_GLASS:11)
B(9,-11,6,STAINED_GLASS:11)
B(10,-11,6,STAINED_GLASS:9)
B(11,-11,6,STAINED_GLASS:9)
B(12,-11,6,STAINED_GLASS:15)
B(4,-11,7,STAINED_GLASS:15)
B(5,-11,7,STAINED_GLASS:9)
B(6,-11,7,STAINED_GLASS:11)
B(7,-11,7,STAINED_GLASS:11)
B(8,-11,7,SEA_LANTERN)
B(9,-11,7,STAINED_GLASS:11)
B(10,-11,7,STAINED_GLASS:11)
B(11,-11,7,STAINED_GLASS:9)
B(12,-11,7,STAINED_GLASS:15)
B(3,-11,8,STAINED_GLASS:15)
B(4,-11,8,STAINED_GLASS:9)
B(5,-11,8,STAINED_GLASS:11)
B(6,-11,8,STAINED_GLASS:11)
B(7,-11,8,SEA_LANTERN)
B(8,-11,8,SEA_LANTERN)
B(9,-11,8,SEA_LANTERN)
B(10,-11,8,STAINED_GLASS:11)
B(11,-11,8,STAINED_GLASS:11)
B(12,-11,8,STAINED_GLASS:9)
B(13,-11,8,STAINED_GLASS:15)
B(4,-11,9,STAINED_GLASS:15)
B(5,-11,9,STAINED_GLASS:9)
B(6,-11,9,STAINED_GLASS:11)
B(7,-11,9,STAINED_GLASS:11)
B(8,-11,9,SEA_LANTERN)
B(9,-11,9,STAINED_GLASS:11)
B(10,-11,9,STAINED_GLASS:11)
B(11,-11,9,STAINED_GLASS:9)
B(12,-11,9,STAINED_GLASS:15)
B(5,-11,10,STAINED_GLASS:15)
B(6,-11,10,STAINED_GLASS:9)
B(7,-11,10,STAINED_GLASS:11)
B(8,-11,10,STAINED_GLASS:11)
B(9,-11,10,STAINED_GLASS:11)
B(10,-11,10,STAINED_GLASS:9)
B(11,-11,10,STAINED_GLASS:9)
B(12,-11,10,STAINED_GLASS:15)
B(5,-11,11,STAINED_GLASS:15)
B(6,-11,11,STAINED_GLASS:9)
B(7,-11,11,STAINED_GLASS:9)
B(8,-11,11,STAINED_GLASS:11)
B(9,-11,11,STAINED_GLASS:9)
B(10,-11,11,STAINED_GLASS:9)
B(11,-11,11,STAINED_GLASS:15)
B(6,-11,12,STAINED_GLASS:15)
B(7,-11,12,STAINED_GLASS:15)
B(8,-11,12,STAINED_GLASS:9)
B(9,-11,12,STAINED_GLASS:9)
B(10,-11,12,STAINED_GLASS:15)
B(8,-11,13,STAINED_GLASS:9)
B(7,-10,3,STAINED_GLASS:9)
B(8,-10,3,STAINED_GLASS:9)
B(6,-10,4,STAINED_GLASS:9)
B(7,-10,4,STAINED_GLASS:9)
B(8,-10,4,STAINED_GLASS:9)
B(9,-10,4,STAINED_GLASS:9)
B(10,-10,4,STAINED_GLASS:9)
B(5,-10,5,STAINED_GLASS:9)
B(6,-10,5,STAINED_GLASS:9)
B(7,-10,5,STAINED_GLASS:11)
B(8,-10,5,STAINED_GLASS:11)
B(9,-10,5,STAINED_GLASS:9)
B(10,-10,5,STAINED_GLASS:9)
B(11,-10,5,STAINED_GLASS:15)
B(4,-10,6,STAINED_GLASS:9)
B(5,-10,6,STAINED_GLASS:9)
B(6,-10,6,STAINED_GLASS:11)
B(7,-10,6,STAINED_GLASS:11)
B(8,-10,6,STAINED_GLASS:11)
B(9,-10,6,STAINED_GLASS:11)
B(10,-10,6,STAINED_GLASS:9)
B(11,-10,6,STAINED_GLASS:9)
B(12,-10,6,STAINED_GLASS:15)
B(3,-10,7,STAINED_GLASS:15)
B(4,-10,7,STAINED_GLASS:9)
B(5,-10,7,STAINED_GLASS:11)
B(6,-10,7,STAINED_GLASS:11)
B(7,-10,7,SEA_LANTERN)
B(8,-10,7,SEA_LANTERN)
B(9,-10,7,STAINED_GLASS:11)
B(10,-10,7,STAINED_GLASS:11)
B(11,-10,7,STAINED_GLASS:9)
B(12,-10,7,STAINED_GLASS:15)
B(3,-10,8,STAINED_GLASS:15)
B(4,-10,8,STAINED_GLASS:9)
B(5,-10,8,STAINED_GLASS:11)
B(6,-10,8,STAINED_GLASS:11)
B(7,-10,8,SEA_LANTERN)
B(8,-10,8,SEA_LANTERN)
B(9,-10,8,STAINED_GLASS:11)
B(10,-10,8,STAINED_GLASS:11)
B(11,-10,8,STAINED_GLASS:9)
B(12,-10,8,STAINED_GLASS:15)
B(4,-10,9,STAINED_GLASS:15)
B(5,-10,9,STAINED_GLASS:9)
B(6,-10,9,STAINED_GLASS:11)
B(7,-10,9,STAINED_GLASS:11)
B(8,-10,9,STAINED_GLASS:11)
B(9,-10,9,STAINED_GLASS:11)
B(10,-10,9,STAINED_GLASS:9)
B(11,-10,9,STAINED_GLASS:15)
B(4,-10,10,STAINED_GLASS:15)
B(5,-10,10,STAINED_GLASS:9)
B(6,-10,10,STAINED_GLASS:9)
B(7,-10,10,STAINED_GLASS:11)
B(8,-10,10,STAINED_GLASS:11)
B(9,-10,10,STAINED_GLASS:9)
B(10,-10,10,STAINED_GLASS:9)
B(11,-10,10,STAINED_GLASS:9)
B(5,-10,11,STAINED_GLASS:15)
B(6,-10,11,STAINED_GLASS:9)
B(7,-10,11,STAINED_GLASS:9)
B(8,-10,11,STAINED_GLASS:9)
B(9,-10,11,STAINED_GLASS:9)
B(10,-10,11,STAINED_GLASS:9)
B(6,-10,12,STAINED_GLASS:15)
B(7,-10,12,STAINED_GLASS:15)
B(8,-10,12,STAINED_GLASS:9)
B(7,-9,2,STAINED_GLASS:15)
B(6,-9,3,STAINED_GLASS:9)
B(7,-9,3,STAINED_GLASS:9)
B(8,-9,3,STAINED_GLASS:9)
B(5,-9,4,STAINED_GLASS:9)
B(6,-9,4,STAINED_GLASS:9)
B(7,-9,4,STAINED_GLASS:11)
B(8,-9,4,STAINED_GLASS:9)
B(9,-9,4,STAINED_GLASS:9)
B(10,-9,4,STAINED_GLASS:9)
B(4,-9,5,STAINED_GLASS:9)
B(5,-9,5,STAINED_GLASS:9)
B(6,-9,5,STAINED_GLASS:11)
B(7,-9,5,STAINED_GLASS:11)
B(8,-9,5,STAINED_GLASS:11)
B(9,-9,5,STAINED_GLASS:9)
B(10,-9,5,STAINED_GLASS:9)
B(11,-9,5,STAINED_GLASS:15)
B(3,-9,6,STAINED_GLASS:9)
B(4,-9,6,STAINED_GLASS:9)
B(5,-9,6,STAINED_GLASS:11)
B(6,-9,6,STAINED_GLASS:11)
B(7,-9,6,SEA_LANTERN)
B(8,-9,6,STAINED_GLASS:11)
B(9,-9,6,STAINED_GLASS:11)
B(10,-9,6,STAINED_GLASS:9)
B(11,-9,6,STAINED_GLASS:15)
B(2,-9,7,STAINED_GLASS:9)
B(3,-9,7,STAINED_GLASS:9)
B(4,-9,7,STAINED_GLASS:11)
B(5,-9,7,STAINED_GLASS:11)
B(6,-9,7,SEA_LANTERN)
B(7,-9,7,SEA_LANTERN)
B(8,-9,7,SEA_LANTERN)
B(9,-9,7,STAINED_GLASS:11)
B(10,-9,7,STAINED_GLASS:11)
B(11,-9,7,STAINED_GLASS:9)
B(12,-9,7,STAINED_GLASS:15)
B(3,-9,8,STAINED_GLASS:15)
B(4,-9,8,STAINED_GLASS:9)
B(5,-9,8,STAINED_GLASS:11)
B(6,-9,8,STAINED_GLASS:11)
B(7,-9,8,SEA_LANTERN)
B(8,-9,8,STAINED_GLASS:11)
B(9,-9,8,STAINED_GLASS:11)
B(10,-9,8,STAINED_GLASS:9)
B(11,-9,8,STAINED_GLASS:15)
B(4,-9,9,STAINED_GLASS:15)
B(5,-9,9,STAINED_GLASS:9)
B(6,-9,9,STAINED_GLASS:11)
B(7,-9,9,STAINED_GLASS:11)
B(8,-9,9,STAINED_GLASS:11)
B(9,-9,9,STAINED_GLASS:9)
B(10,-9,9,STAINED_GLASS:9)
B(11,-9,9,STAINED_GLASS:9)
B(4,-9,10,STAINED_GLASS:15)
B(5,-9,10,STAINED_GLASS:9)
B(6,-9,10,STAINED_GLASS:9)
B(7,-9,10,STAINED_GLASS:11)
B(8,-9,10,STAINED_GLASS:9)
B(9,-9,10,STAINED_GLASS:9)
B(10,-9,10,STAINED_GLASS:9)
B(5,-9,11,STAINED_GLASS:15)
B(6,-9,11,STAINED_GLASS:15)
B(7,-9,11,STAINED_GLASS:9)
B(8,-9,11,STAINED_GLASS:9)
B(9,-9,11,STAINED_GLASS:9)
B(7,-9,12,STAINED_GLASS:15)
B(6,-8,2,STAINED_GLASS:15)
B(7,-8,2,STAINED_GLASS:15)
B(5,-8,3,STAINED_GLASS:15)
B(6,-8,3,STAINED_GLASS:9)
B(7,-8,3,STAINED_GLASS:9)
B(8,-8,3,STAINED_GLASS:9)
B(9,-8,3,STAINED_GLASS:9)
B(4,-8,4,STAINED_GLASS:9)
B(5,-8,4,STAINED_GLASS:9)
B(6,-8,4,STAINED_GLASS:11)
B(7,-8,4,STAINED_GLASS:11)
B(8,-8,4,STAINED_GLASS:9)
B(9,-8,4,STAINED_GLASS:9)
B(10,-8,4,STAINED_GLASS:9)
B(3,-8,5,STAINED_GLASS:9)
B(4,-8,5,STAINED_GLASS:9)
B(5,-8,5,STAINED_GLASS:11)
B(6,-8,5,STAINED_GLASS:11)
B(7,-8,5,STAINED_GLASS:11)
B(8,-8,5,STAINED_GLASS:11)
B(9,-8,5,STAINED_GLASS:9)
B(10,-8,5,STAINED_GLASS:9)
B(11,-8,5,STAINED_GLASS:15)
B(2,-8,6,STAINED_GLASS:9)
B(3,-8,6,STAINED_GLASS:9)
B(4,-8,6,STAINED_GLASS:11)
B(5,-8,6,STAINED_GLASS:11)
B(6,-8,6,SEA_LANTERN)
B(7,-8,6,SEA_LANTERN)
B(8,-8,6,STAINED_GLASS:11)
B(9,-8,6,STAINED_GLASS:11)
B(10,-8,6,STAINED_GLASS:9)
B(11,-8,6,STAINED_GLASS:15)
B(2,-8,7,STAINED_GLASS:9)
B(3,-8,7,STAINED_GLASS:9)
B(4,-8,7,STAINED_GLASS:11)
B(5,-8,7,STAINED_GLASS:11)
B(6,-8,7,SEA_LANTERN)
B(7,-8,7,SEA_LANTERN)
B(8,-8,7,STAINED_GLASS:11)
B(9,-8,7,STAINED_GLASS:11)
B(10,-8,7,STAINED_GLASS:9)
B(11,-8,7,STAINED_GLASS:15)
B(3,-8,8,STAINED_GLASS:9)
B(4,-8,8,STAINED_GLASS:9)
B(5,-8,8,STAINED_GLASS:11)
B(6,-8,8,STAINED_GLASS:11)
B(7,-8,8,STAINED_GLASS:11)
B(8,-8,8,STAINED_GLASS:11)
B(9,-8,8,STAINED_GLASS:9)
B(10,-8,8,STAINED_GLASS:9)
B(3,-8,9,STAINED_GLASS:15)
B(4,-8,9,STAINED_GLASS:9)
B(5,-8,9,STAINED_GLASS:9)
B(6,-8,9,STAINED_GLASS:11)
B(7,-8,9,STAINED_GLASS:11)
B(8,-8,9,STAINED_GLASS:9)
B(9,-8,9,STAINED_GLASS:9)
B(10,-8,9,STAINED_GLASS:9)
B(4,-8,10,STAINED_GLASS:15)
B(5,-8,10,STAINED_GLASS:9)
B(6,-8,10,STAINED_GLASS:9)
B(7,-8,10,STAINED_GLASS:9)
B(8,-8,10,STAINED_GLASS:15)
B(9,-8,10,STAINED_GLASS:9)
B(5,-8,11,STAINED_GLASS:15)
B(6,-8,11,STAINED_GLASS:15)
B(7,-8,11,STAINED_GLASS:15)
B(6,-7,1,STAINED_GLASS:15)
B(5,-7,2,STAINED_GLASS:15)
B(6,-7,2,STAINED_GLASS:9)
B(7,-7,2,STAINED_GLASS:15)
B(4,-7,3,STAINED_GLASS:15)
B(5,-7,3,STAINED_GLASS:9)
B(6,-7,3,STAINED_GLASS:11)
B(7,-7,3,STAINED_GLASS:9)
B(8,-7,3,STAINED_GLASS:9)
B(9,-7,3,STAINED_GLASS:9)
B(3,-7,4,STAINED_GLASS:9)
B(4,-7,4,STAINED_GLASS:9)
B(5,-7,4,STAINED_GLASS:11)
B(6,-7,4,STAINED_GLASS:11)
B(7,-7,4,STAINED_GLASS:11)
B(8,-7,4,STAINED_GLASS:9)
B(9,-7,4,STAINED_GLASS:9)
B(10,-7,4,STAINED_GLASS:9)
B(2,-7,5,STAINED_GLASS:9)
B(3,-7,5,STAINED_GLASS:9)
B(4,-7,5,STAINED_GLASS:11)
B(5,-7,5,STAINED_GLASS:11)
B(6,-7,5,SEA_LANTERN)
B(7,-7,5,STAINED_GLASS:11)
B(8,-7,5,STAINED_GLASS:11)
B(9,-7,5,STAINED_GLASS:9)
B(10,-7,5,STAINED_GLASS:15)
B(1,-7,6,STAINED_GLASS:15)
B(2,-7,6,STAINED_GLASS:9)
B(3,-7,6,STAINED_GLASS:11)
B(4,-7,6,STAINED_GLASS:11)
B(5,-7,6,SEA_LANTERN)
B(6,-7,6,SEA_LANTERN)
B(7,-7,6,SEA_LANTERN)
B(8,-7,6,STAINED_GLASS:11)
B(9,-7,6,STAINED_GLASS:11)
B(10,-7,6,STAINED_GLASS:9)
B(11,-7,6,STAINED_GLASS:15)
B(2,-7,7,STAINED_GLASS:9)
B(3,-7,7,STAINED_GLASS:9)
B(4,-7,7,STAINED_GLASS:11)
B(5,-7,7,STAINED_GLASS:11)
B(6,-7,7,SEA_LANTERN)
B(7,-7,7,STAINED_GLASS:11)
B(8,-7,7,STAINED_GLASS:11)
B(9,-7,7,STAINED_GLASS:9)
B(10,-7,7,STAINED_GLASS:9)
B(3,-7,8,STAINED_GLASS:15)
B(4,-7,8,STAINED_GLASS:9)
B(5,-7,8,STAINED_GLASS:11)
B(6,-7,8,STAINED_GLASS:11)
B(7,-7,8,STAINED_GLASS:11)
B(8,-7,8,STAINED_GLASS:9)
B(9,-7,8,STAINED_GLASS:9)
B(10,-7,8,STAINED_GLASS:9)
B(3,-7,9,STAINED_GLASS:15)
B(4,-7,9,STAINED_GLASS:9)
B(5,-7,9,STAINED_GLASS:9)
B(6,-7,9,STAINED_GLASS:11)
B(7,-7,9,STAINED_GLASS:9)
B(8,-7,9,STAINED_GLASS:9)
B(9,-7,9,STAINED_GLASS:9)
B(4,-7,10,STAINED_GLASS:15)
B(5,-7,10,STAINED_GLASS:15)
B(6,-7,10,STAINED_GLASS:9)
B(7,-7,10,STAINED_GLASS:15)
B(8,-7,10,STAINED_GLASS:15)
B(6,-7,11,STAINED_GLASS:15)
B(5,-6,1,STAINED_GLASS:15)
B(6,-6,1,STAINED_GLASS:15)
B(4,-6,2,STAINED_GLASS:15)
B(5,-6,2,STAINED_GLASS:9)
B(6,-6,2,STAINED_GLASS:9)
B(7,-6,2,STAINED_GLASS:9)
B(8,-6,2,STAINED_GLASS:9)
B(3,-6,3,STAINED_GLASS:15)
B(4,-6,3,STAINED_GLASS:9)
B(5,-6,3,STAINED_GLASS:11)
B(6,-6,3,STAINED_GLASS:11)
B(7,-6,3,STAINED_GLASS:9)
B(8,-6,3,STAINED_GLASS:9)
B(9,-6,3,STAINED_GLASS:9)
B(2,-6,4,STAINED_GLASS:15)
B(3,-6,4,STAINED_GLASS:9)
B(4,-6,4,STAINED_GLASS:11)
B(5,-6,4,STAINED_GLASS:11)
B(6,-6,4,STAINED_GLASS:11)
B(7,-6,4,STAINED_GLASS:11)
B(8,-6,4,STAINED_GLASS:9)
B(9,-6,4,STAINED_GLASS:9)
B(10,-6,4,STAINED_GLASS:15)
B(1,-6,5,STAINED_GLASS:15)
B(2,-6,5,STAINED_GLASS:9)
B(3,-6,5,STAINED_GLASS:11)
B(4,-6,5,STAINED_GLASS:11)
B(5,-6,5,SEA_LANTERN)
B(6,-6,5,SEA_LANTERN)
B(7,-6,5,STAINED_GLASS:11)
B(8,-6,5,STAINED_GLASS:11)
B(9,-6,5,STAINED_GLASS:9)
B(10,-6,5,STAINED_GLASS:15)
B(1,-6,6,STAINED_GLASS:9)
B(2,-6,6,STAINED_GLASS:9)
B(3,-6,6,STAINED_GLASS:11)
B(4,-6,6,STAINED_GLASS:11)
B(5,-6,6,SEA_LANTERN)
B(6,-6,6,SEA_LANTERN)
B(7,-6,6,STAINED_GLASS:11)
B(8,-6,6,STAINED_GLASS:11)
B(9,-6,6,STAINED_GLASS:9)
B(10,-6,6,STAINED_GLASS:15)
B(2,-6,7,STAINED_GLASS:9)
B(3,-6,7,STAINED_GLASS:9)
B(4,-6,7,STAINED_GLASS:11)
B(5,-6,7,STAINED_GLASS:11)
B(6,-6,7,STAINED_GLASS:11)
B(7,-6,7,STAINED_GLASS:11)
B(8,-6,7,STAINED_GLASS:9)
B(9,-6,7,STAINED_GLASS:9)
B(2,-6,8,STAINED_GLASS:9)
B(3,-6,8,STAINED_GLASS:9)
B(4,-6,8,STAINED_GLASS:9)
B(5,-6,8,STAINED_GLASS:11)
B(6,-6,8,STAINED_GLASS:11)
B(7,-6,8,STAINED_GLASS:9)
B(8,-6,8,STAINED_GLASS:9)
B(9,-6,8,STAINED_GLASS:9)
B(3,-6,9,STAINED_GLASS:15)
B(4,-6,9,STAINED_GLASS:9)
B(5,-6,9,STAINED_GLASS:9)
B(6,-6,9,STAINED_GLASS:9)
B(7,-6,9,STAINED_GLASS:15)
B(8,-6,9,STAINED_GLASS:15)
B(4,-6,10,STAINED_GLASS:15)
B(5,-6,10,STAINED_GLASS:15)
B(6,-6,10,STAINED_GLASS:15)
B(5,-5,0,STAINED_GLASS:15)
B(4,-5,1,STAINED_GLASS:15)
B(5,-5,1,STAINED_GLASS:9)
B(6,-5,1,STAINED_GLASS:15)
B(3,-5,2,STAINED_GLASS:15)
B(4,-5,2,STAINED_GLASS:9)
B(5,-5,2,STAINED_GLASS:11)
B(6,-5,2,STAINED_GLASS:9)
B(7,-5,2,STAINED_GLASS:9)
B(8,-5,2,STAINED_GLASS:9)
B(2,-5,3,STAINED_GLASS:15)
B(3,-5,3,STAINED_GLASS:9)
B(4,-5,3,STAINED_GLASS:11)
B(5,-5,3,STAINED_GLASS:11)
B(6,-5,3,STAINED_GLASS:11)
B(7,-5,3,STAINED_GLASS:9)
B(8,-5,3,STAINED_GLASS:9)
B(9,-5,3,STAINED_GLASS:9)
B(1,-5,4,STAINED_GLASS:15)
B(2,-5,4,STAINED_GLASS:9)
B(3,-5,4,STAINED_GLASS:11)
B(4,-5,4,STAINED_GLASS:11)
B(5,-5,4,SEA_LANTERN)
B(6,-5,4,STAINED_GLASS:11)
B(7,-5,4,STAINED_GLASS:11)
B(8,-5,4,STAINED_GLASS:9)
B(9,-5,4,STAINED_GLASS:15)
B(0,-5,5,STAINED_GLASS:15)
B(1,-5,5,STAINED_GLASS:9)
B(2,-5,5,STAINED_GLASS:11)
B(3,-5,5,STAINED_GLASS:11)
B(4,-5,5,SEA_LANTERN)
B(5,-5,5,SEA_LANTERN)
B(6,-5,5,SEA_LANTERN)
B(7,-5,5,STAINED_GLASS:11)
B(8,-5,5,STAINED_GLASS:11)
B(9,-5,5,STAINED_GLASS:9)
B(10,-5,5,STAINED_GLASS:15)
B(1,-5,6,STAINED_GLASS:9)
B(2,-5,6,STAINED_GLASS:9)
B(3,-5,6,STAINED_GLASS:11)
B(4,-5,6,STAINED_GLASS:11)
B(5,-5,6,SEA_LANTERN)
B(6,-5,6,STAINED_GLASS:11)
B(7,-5,6,STAINED_GLASS:11)
B(8,-5,6,STAINED_GLASS:9)
B(9,-5,6,STAINED_GLASS:9)
B(2,-5,7,STAINED_GLASS:9)
B(3,-5,7,STAINED_GLASS:9)
B(4,-5,7,STAINED_GLASS:11)
B(5,-5,7,STAINED_GLASS:11)
B(6,-5,7,STAINED_GLASS:11)
B(7,-5,7,STAINED_GLASS:9)
B(8,-5,7,STAINED_GLASS:9)
B(9,-5,7,STAINED_GLASS:9)
B(2,-5,8,STAINED_GLASS:9)
B(3,-5,8,STAINED_GLASS:9)
B(4,-5,8,STAINED_GLASS:9)
B(5,-5,8,STAINED_GLASS:11)
B(6,-5,8,STAINED_GLASS:9)
B(7,-5,8,STAINED_GLASS:9)
B(8,-5,8,STAINED_GLASS:9)
B(3,-5,9,STAINED_GLASS:15)
B(4,-5,9,STAINED_GLASS:15)
B(5,-5,9,STAINED_GLASS:9)
B(6,-5,9,STAINED_GLASS:15)
B(7,-5,9,STAINED_GLASS:15)
B(5,-5,10,STAINED_GLASS:15)
B(4,-4,0,STAINED_GLASS:15)
B(5,-4,0,STAINED_GLASS:15)
B(3,-4,1,STAINED_GLASS:15)
B(4,-4,1,STAINED_GLASS:9)
B(5,-4,1,STAINED_GLASS:9)
B(6,-4,1,STAINED_GLASS:9)
B(7,-4,1,STAINED_GLASS:9)
B(2,-4,2,STAINED_GLASS:15)
B(3,-4,2,STAINED_GLASS:9)
B(4,-4,2,STAINED_GLASS:11)
B(5,-4,2,STAINED_GLASS:11)
B(6,-4,2,STAINED_GLASS:9)
B(7,-4,2,STAINED_GLASS:9)
B(8,-4,2,STAINED_GLASS:9)
B(1,-4,3,STAINED_GLASS:15)
B(2,-4,3,STAINED_GLASS:9)
B(3,-4,3,STAINED_GLASS:11)
B(4,-4,3,STAINED_GLASS:11)
B(5,-4,3,STAINED_GLASS:11)
B(6,-4,3,STAINED_GLASS:11)
B(7,-4,3,STAINED_GLASS:9)
B(8,-4,3,STAINED_GLASS:9)
B(9,-4,3,STAINED_GLASS:15)
B(0,-4,4,STAINED_GLASS:15)
B(1,-4,4,STAINED_GLASS:9)
B(2,-4,4,STAINED_GLASS:11)
B(3,-4,4,STAINED_GLASS:11)
B(4,-4,4,SEA_LANTERN)
B(5,-4,4,SEA_LANTERN)
B(6,-4,4,STAINED_GLASS:11)
B(7,-4,4,STAINED_GLASS:11)
B(8,-4,4,STAINED_GLASS:9)
B(9,-4,4,STAINED_GLASS:15)
B(0,-4,5,STAINED_GLASS:9)
B(1,-4,5,STAINED_GLASS:9)
B(2,-4,5,STAINED_GLASS:11)
B(3,-4,5,STAINED_GLASS:11)
B(4,-4,5,SEA_LANTERN)
B(5,-4,5,SEA_LANTERN)
B(6,-4,5,STAINED_GLASS:11)
B(7,-4,5,STAINED_GLASS:11)
B(8,-4,5,STAINED_GLASS:9)
B(9,-4,5,STAINED_GLASS:9)
B(1,-4,6,STAINED_GLASS:9)
B(2,-4,6,STAINED_GLASS:9)
B(3,-4,6,STAINED_GLASS:11)
B(4,-4,6,STAINED_GLASS:11)
B(5,-4,6,STAINED_GLASS:11)
B(6,-4,6,STAINED_GLASS:11)
B(7,-4,6,STAINED_GLASS:9)
B(8,-4,6,STAINED_GLASS:9)
B(1,-4,7,STAINED_GLASS:9)
B(2,-4,7,STAINED_GLASS:9)
B(3,-4,7,STAINED_GLASS:9)
B(4,-4,7,STAINED_GLASS:11)
B(5,-4,7,STAINED_GLASS:11)
B(6,-4,7,STAINED_GLASS:9)
B(7,-4,7,STAINED_GLASS:9)
B(8,-4,7,STAINED_GLASS:9)
B(2,-4,8,STAINED_GLASS:15)
B(3,-4,8,STAINED_GLASS:9)
B(4,-4,8,STAINED_GLASS:9)
B(5,-4,8,STAINED_GLASS:9)
B(6,-4,8,STAINED_GLASS:15)
B(7,-4,8,STAINED_GLASS:15)
B(3,-4,9,STAINED_GLASS:15)
B(4,-4,9,STAINED_GLASS:15)
B(5,-4,9,STAINED_GLASS:15)
B(4,-3,0,STAINED_GLASS:15)
B(5,-3,0,STAINED_GLASS:15)
B(3,-3,1,STAINED_GLASS:15)
B(4,-3,1,STAINED_GLASS:9)
B(5,-3,1,STAINED_GLASS:9)
B(6,-3,1,STAINED_GLASS:9)
B(7,-3,1,STAINED_GLASS:9)
B(2,-3,2,STAINED_GLASS:15)
B(3,-3,2,STAINED_GLASS:9)
B(4,-3,2,STAINED_GLASS:11)
B(5,-3,2,STAINED_GLASS:11)
B(6,-3,2,STAINED_GLASS:9)
B(7,-3,2,STAINED_GLASS:9)
B(8,-3,2,STAINED_GLASS:9)
B(1,-3,3,STAINED_GLASS:15)
B(2,-3,3,STAINED_GLASS:9)
B(3,-3,3,STAINED_GLASS:11)
B(4,-3,3,SEA_LANTERN)
B(5,-3,3,STAINED_GLASS:11)
B(6,-3,3,STAINED_GLASS:11)
B(7,-3,3,STAINED_GLASS:9)
B(8,-3,3,STAINED_GLASS:15)
B(0,-3,4,STAINED_GLASS:15)
B(1,-3,4,STAINED_GLASS:9)
B(2,-3,4,STAINED_GLASS:11)
B(3,-3,4,SEA_LANTERN)
B(4,-3,4,SEA_LANTERN)
B(5,-3,4,SEA_LANTERN)
B(6,-3,4,STAINED_GLASS:11)
B(7,-3,4,STAINED_GLASS:11)
B(8,-3,4,STAINED_GLASS:9)
B(9,-3,4,STAINED_GLASS:15)
B(0,-3,5,STAINED_GLASS:9)
B(1,-3,5,STAINED_GLASS:9)
B(2,-3,5,STAINED_GLASS:11)
B(3,-3,5,STAINED_GLASS:11)
B(4,-3,5,SEA_LANTERN)
B(5,-3,5,STAINED_GLASS:11)
B(6,-3,5,STAINED_GLASS:11)
B(7,-3,5,STAINED_GLASS:9)
B(8,-3,5,STAINED_GLASS:9)
B(1,-3,6,STAINED_GLASS:9)
B(2,-3,6,STAINED_GLASS:9)
B(3,-3,6,STAINED_GLASS:11)
B(4,-3,6,STAINED_GLASS:11)
B(5,-3,6,STAINED_GLASS:11)
B(6,-3,6,STAINED_GLASS:9)
B(7,-3,6,STAINED_GLASS:9)
B(8,-3,6,STAINED_GLASS:9)
B(1,-3,7,STAINED_GLASS:9)
B(2,-3,7,STAINED_GLASS:9)
B(3,-3,7,STAINED_GLASS:9)
B(4,-3,7,STAINED_GLASS:11)
B(5,-3,7,STAINED_GLASS:9)
B(6,-3,7,STAINED_GLASS:9)
B(7,-3,7,STAINED_GLASS:15)
B(2,-3,8,STAINED_GLASS:15)
B(3,-3,8,STAINED_GLASS:15)
B(4,-3,8,STAINED_GLASS:9)
B(5,-3,8,STAINED_GLASS:15)
B(6,-3,8,STAINED_GLASS:15)
B(4,-3,9,STAINED_GLASS:15)
B(3,-2,0,STAINED_GLASS:15)
B(4,-2,0,STAINED_GLASS:15)
B(5,-2,0,STAINED_GLASS:15)
B(2,-2,1,STAINED_GLASS:15)
B(3,-2,1,STAINED_GLASS:9)
B(4,-2,1,STAINED_GLASS:9)
B(5,-2,1,STAINED_GLASS:9)
B(6,-2,1,STAINED_GLASS:9)
B(1,-2,2,STAINED_GLASS:15)
B(2,-2,2,STAINED_GLASS:9)
B(3,-2,2,STAINED_GLASS:11)
B(4,-2,2,STAINED_GLASS:11)
B(5,-2,2,STAINED_GLASS:11)
B(6,-2,2,STAINED_GLASS:9)
B(7,-2,2,STAINED_GLASS:9)
B(0,-2,3,STAINED_GLASS:15)
B(1,-2,3,STAINED_GLASS:9)
B(2,-2,3,STAINED_GLASS:11)
B(3,-2,3,SEA_LANTERN)
B(4,-2,3,SEA_LANTERN)
B(5,-2,3,STAINED_GLASS:11)
B(6,-2,3,STAINED_GLASS:11)
B(7,-2,3,STAINED_GLASS:9)
B(8,-2,3,STAINED_GLASS:15)
B(0,-2,4,STAINED_GLASS:15)
B(1,-2,4,STAINED_GLASS:9)
B(2,-2,4,STAINED_GLASS:11)
B(3,-2,4,SEA_LANTERN)
B(4,-2,4,SEA_LANTERN)
B(5,-2,4,STAINED_GLASS:11)
B(6,-2,4,STAINED_GLASS:11)
B(7,-2,4,STAINED_GLASS:9)
B(8,-2,4,STAINED_GLASS:9)
B(0,-2,5,STAINED_GLASS:15)
B(1,-2,5,STAINED_GLASS:9)
B(2,-2,5,STAINED_GLASS:11)
B(3,-2,5,STAINED_GLASS:11)
B(4,-2,5,STAINED_GLASS:11)
B(5,-2,5,STAINED_GLASS:11)
B(6,-2,5,STAINED_GLASS:9)
B(7,-2,5,STAINED_GLASS:9)
B(1,-2,6,STAINED_GLASS:9)
B(2,-2,6,STAINED_GLASS:9)
B(3,-2,6,STAINED_GLASS:11)
B(4,-2,6,STAINED_GLASS:11)
B(5,-2,6,STAINED_GLASS:9)
B(6,-2,6,STAINED_GLASS:9)
B(7,-2,6,STAINED_GLASS:15)
B(2,-2,7,STAINED_GLASS:15)
B(3,-2,7,STAINED_GLASS:9)
B(4,-2,7,STAINED_GLASS:9)
B(5,-2,7,STAINED_GLASS:15)
B(6,-2,7,STAINED_GLASS:15)
B(3,-2,8,STAINED_GLASS:15)
B(4,-2,8,STAINED_GLASS:15)
B(3,-1,0,STAINED_GLASS:15)
B(4,-1,0,STAINED_GLASS:15)
B(2,-1,1,STAINED_GLASS:15)
B(3,-1,1,STAINED_GLASS:9)
B(4,-1,1,STAINED_GLASS:9)
B(5,-1,1,STAINED_GLASS:9)
B(1,-1,2,STAINED_GLASS:15)
B(2,-1,2,STAINED_GLASS:9)
B(3,-1,2,STAINED_GLASS:11)
B(4,-1,2,STAINED_GLASS:11)
B(5,-1,2,STAINED_GLASS:9)
B(6,-1,2,STAINED_GLASS:9)
B(0,-1,3,STAINED_GLASS:15)
B(1,-1,3,STAINED_GLASS:9)
B(2,-1,3,STAINED_GLASS:11)
B(3,-1,3,SEA_LANTERN)
B(4,-1,3,STAINED_GLASS:11)
B(5,-1,3,STAINED_GLASS:11)
B(6,-1,3,STAINED_GLASS:9)
B(7,-1,3,STAINED_GLASS:9)
B(0,-1,4,STAINED_GLASS:15)
B(1,-1,4,STAINED_GLASS:9)
B(2,-1,4,STAINED_GLASS:11)
B(3,-1,4,STAINED_GLASS:11)
B(4,-1,4,STAINED_GLASS:11)
B(5,-1,4,STAINED_GLASS:11)
B(6,-1,4,STAINED_GLASS:9)
B(7,-1,4,STAINED_GLASS:9)
B(1,-1,5,STAINED_GLASS:9)
B(2,-1,5,STAINED_GLASS:9)
B(3,-1,5,STAINED_GLASS:11)
B(4,-1,5,STAINED_GLASS:11)
B(5,-1,5,STAINED_GLASS:9)
B(6,-1,5,STAINED_GLASS:9)
B(7,-1,5,STAINED_GLASS:9)
B(2,-1,6,STAINED_GLASS:9)
B(3,-1,6,STAINED_GLASS:9)
B(4,-1,6,STAINED_GLASS:9)
B(5,-1,6,STAINED_GLASS:9)
B(6,-1,6,STAINED_GLASS:15)
B(3,-1,7,STAINED_GLASS:15)
B(4,-1,7,STAINED_GLASS:15)
B(5,-1,7,STAINED_GLASS:15)
B(2,0,0,STAINED_GLASS:15)
B(3,0,0,STAINED_GLASS:15)
B(4,0,0,STAINED_GLASS:9)
B(1,0,1,STAINED_GLASS:15)
B(2,0,1,STAINED_GLASS:9)
B(3,0,1,STAINED_GLASS:9)
B(4,0,1,STAINED_GLASS:9)
B(5,0,1,STAINED_GLASS:9)
B(0,0,2,STAINED_GLASS:15)
B(1,0,2,STAINED_GLASS:9)
B(2,0,2,STAINED_GLASS:9)
B(3,0,2,STAINED_GLASS:11)
B(4,0,2,STAINED_GLASS:9)
B(5,0,2,STAINED_GLASS:9)
B(6,0,2,STAINED_GLASS:9)
B(0,0,3,STAINED_GLASS:15)
B(1,0,3,STAINED_GLASS:9)
B(2,0,3,STAINED_GLASS:11)
B(3,0,3,STAINED_GLASS:11)
B(4,0,3,STAINED_GLASS:11)
B(5,0,3,STAINED_GLASS:9)
B(6,0,3,STAINED_GLASS:9)
B(0,0,4,STAINED_GLASS:15)
B(1,0,4,STAINED_GLASS:9)
B(2,0,4,STAINED_GLASS:9)
B(3,0,4,STAINED_GLASS:11)
B(5,0,4,STAINED_GLASS:9)
B(6,0,4,STAINED_GLASS:9)
B(1,0,5,STAINED_GLASS:9)
B(2,0,5,STAINED_GLASS:9)
B(3,0,5,STAINED_GLASS:9)
B(4,0,5,STAINED_GLASS:9)
B(5,0,5,STAINED_GLASS:9)
B(6,0,5,STAINED_GLASS:15)
B(2,0,6,STAINED_GLASS:9)
B(3,0,6,STAINED_GLASS:15)
B(4,0,6,STAINED_GLASS:15)
B(5,0,6,STAINED_GLASS:15)
B(2,1,0,STAINED_GLASS:15)
B(3,1,0,STAINED_GLASS:15)
B(1,1,1,STAINED_GLASS:15)
B(2,1,1,STAINED_GLASS:9)
B(3,1,1,STAINED_GLASS:9)
B(4,1,1,STAINED_GLASS:9)
B(0,1,2,STAINED_GLASS:15)
B(1,1,2,STAINED_GLASS:9)
B(2,1,2,STAINED_GLASS:11)
B(3,1,2,STAINED_GLASS:9)
B(4,1,2,STAINED_GLASS:9)
B(5,1,2,STAINED_GLASS:9)
B(0,1,3,STAINED_GLASS:15)
B(1,1,3,STAINED_GLASS:9)
B(2,1,3,STAINED_GLASS:9)
B(3,1,3,STAINED_GLASS:11)
B(4,1,3,STAINED_GLASS:9)
B(5,1,3,STAINED_GLASS:15)
B(1,1,4,STAINED_GLASS:9)
B(2,1,4,STAINED_GLASS:9)
B(3,1,4,STAINED_GLASS:9)
B(4,1,4,STAINED_GLASS:9)
B(5,1,4,STAINED_GLASS:9)
B(6,1,4,STAINED_GLASS:15)
B(2,1,5,STAINED_GLASS:9)
B(3,1,5,STAINED_GLASS:9)
B(4,1,5,STAINED_GLASS:9)
B(5,1,5,STAINED_GLASS:15)
B(4,1,6,STAINED_GLASS:15)
B(2,2,0,STAINED_GLASS:15)
B(3,2,0,STAINED_GLASS:9)
B(1,2,1,STAINED_GLASS:15)
B(2,2,1,STAINED_GLASS:9)
B(3,2,1,STAINED_GLASS:9)
B(4,2,1,STAINED_GLASS:9)
B(0,2,2,STAINED_GLASS:15)
B(1,2,2,STAINED_GLASS:9)
B(2,2,2,STAINED_GLASS:11)
B(3,2,2,STAINED_GLASS:9)
B(4,2,2,STAINED_GLASS:9)
B(0,2,3,STAINED_GLASS:15)
B(1,2,3,STAINED_GLASS:9)
B(2,2,3,STAINED_GLASS:9)
B(3,2,3,STAINED_GLASS:9)
B(4,2,3,STAINED_GLASS:9)
B(5,2,3,STAINED_GLASS:15)
B(1,2,4,STAINED_GLASS:9)
B(2,2,4,STAINED_GLASS:9)
B(3,2,4,STAINED_GLASS:9)
B(4,2,4,STAINED_GLASS:15)
B(5,2,4,STAINED_GLASS:15)
B(3,2,5,STAINED_GLASS:9)
B(4,2,5,STAINED_GLASS:15)
B(1,3,0,STAINED_GLASS:15)
B(2,3,0,STAINED_GLASS:15)
B(0,3,1,STAINED_GLASS:15)
B(1,3,1,STAINED_GLASS:9)
B(2,3,1,STAINED_GLASS:9)
B(3,3,1,STAINED_GLASS:9)
B(0,3,2,STAINED_GLASS:15)
B(1,3,2,STAINED_GLASS:9)
B(2,3,2,STAINED_GLASS:9)
B(3,3,2,STAINED_GLASS:9)
B(4,3,2,STAINED_GLASS:9)
B(1,3,3,STAINED_GLASS:9)
B(2,3,3,STAINED_GLASS:9)
B(3,3,3,STAINED_GLASS:9)
B(4,3,3,STAINED_GLASS:15)
B(2,3,4,STAINED_GLASS:9)
B(3,3,4,STAINED_GLASS:9)
B(1,4,0,STAINED_GLASS:15)
B(2,4,0,STAINED_GLASS:9)
B(0,4,1,STAINED_GLASS:15)
B(1,4,1,STAINED_GLASS:9)
B(2,4,1,STAINED_GLASS:9)
B(3,4,1,STAINED_GLASS:9)
B(0,4,2,STAINED_GLASS:15)
B(1,4,2,STAINED_GLASS:9)
B(2,4,2,STAINED_GLASS:9)
B(3,4,2,STAINED_GLASS:9)
B(1,4,3,STAINED_GLASS:15)
B(2,4,3,STAINED_GLASS:9)
B(0,5,0,STAINED_GLASS:15)
B(1,5,0,STAINED_GLASS:15)
B(0,5,1,STAINED_GLASS:15)
B(1,5,1,STAINED_GLASS:9)
B(2,5,1,STAINED_GLASS:9)
B(1,5,2,STAINED_GLASS:15)
B(0,6,0,STAINED_GLASS:15)
B(1,6,0,STAINED_GLASS:15)
B(0,6,1,STAINED_GLASS:15)
B(1,6,1,STAINED_GLASS:15)
B(0,7,0,STAINED_GLASS:15)

#######################################################################
# +-----------------------------------------------------------------+ #
# |                             Branches                            | #
# +-----------------------------------------------------------------+ #
#######################################################################

BR(0,0,16,true,CEILING_SPIKE-MED-EXTREME-01_0x1,NORTH,100,0)
BR(16,0,0,true,CEILING_SPIKE-MED-EXTREME-01_1x0,NORTH,100,0)
