#######################################################################
# +-----------------------------------------------------------------+ #
# |                            BO3 object                           | #
# +-----------------------------------------------------------------+ #
#######################################################################

Author: Bo3 BulkEdit

Description: Converted Schematic - Modified by Bo3BulkEdit

Version: 3

SettingsMode: WriteDisable

#######################################################################
# +-----------------------------------------------------------------+ #
# |                          Main settings                          | #
# +-----------------------------------------------------------------+ #
#######################################################################

IsOTGPlus: true
Tree: false
Frequency: 1
Rarity: 100.0
RotateRandomly: false
SpawnHeight: randomY
MaxBranchDepth: 10
ExcludedBiomes: All

##############################
# Height Limits for the BO3. #
##############################

MinHeight: 0
MaxHeight: 255

#######################################################################
# +-----------------------------------------------------------------+ #
# |                      Source block settings                      | #
# +-----------------------------------------------------------------+ #
#######################################################################

CanOverride: true
MaxPercentageOutsideSourceBlock: 100
OutsideSourceBlock: placeAnyway

#######################################################################
# +-----------------------------------------------------------------+ #
# |                               OTG+                              | #
# +-----------------------------------------------------------------+ #
#######################################################################

BO3Group: CeilingCrystals:0

#######################################################################
# +-----------------------------------------------------------------+ #
# |                              Blocks                             | #
# +-----------------------------------------------------------------+ #
#######################################################################

B(0,750,0,AIR)
B(15,750,15,AIR)
B(5,-23,10,STAINED_GLASS:15)
B(4,-23,11,STAINED_GLASS:15)
B(5,-23,11,STAINED_GLASS:15)
B(3,-23,12,STAINED_GLASS:15)
B(4,-23,12,STAINED_GLASS:15)
B(5,-23,12,STAINED_GLASS:15)
B(6,-23,12,STAINED_GLASS:15)
B(4,-23,13,STAINED_GLASS:15)
B(5,-23,13,STAINED_GLASS:15)
B(6,-23,13,STAINED_GLASS:15)
B(5,-23,14,STAINED_GLASS:15)
B(6,-23,14,STAINED_GLASS:15)
B(4,-22,7,STAINED_GLASS:10)
B(5,-22,7,STAINED_GLASS:10)
B(2,-22,8,STAINED_GLASS:15)
B(3,-22,8,STAINED_GLASS:15)
B(4,-22,8,STAINED_GLASS:15)
B(5,-22,8,STAINED_GLASS:15)
B(6,-22,8,STAINED_GLASS:10)
B(2,-22,9,STAINED_GLASS:15)
B(3,-22,9,STAINED_GLASS:15)
B(4,-22,9,STAINED_GLASS:15)
B(5,-22,9,STAINED_GLASS:15)
B(6,-22,9,STAINED_GLASS:15)
B(7,-22,9,STAINED_GLASS:15)
B(1,-22,10,STAINED_GLASS:15)
B(2,-22,10,STAINED_GLASS:15)
B(3,-22,10,STAINED_GLASS:15)
B(4,-22,10,STAINED_GLASS:9)
B(5,-22,10,STAINED_GLASS:15)
B(6,-22,10,STAINED_GLASS:15)
B(7,-22,10,STAINED_GLASS:15)
B(2,-22,11,STAINED_GLASS:15)
B(3,-22,11,STAINED_GLASS:15)
B(4,-22,11,STAINED_GLASS:15)
B(5,-22,11,STAINED_GLASS:15)
B(6,-22,11,STAINED_GLASS:15)
B(7,-22,11,STAINED_GLASS:15)
B(2,-22,12,STAINED_GLASS:15)
B(3,-22,12,STAINED_GLASS:15)
B(4,-22,12,STAINED_GLASS:15)
B(5,-22,12,STAINED_GLASS:15)
B(6,-22,12,STAINED_GLASS:15)
B(4,-22,13,STAINED_GLASS:15)
B(5,-22,13,STAINED_GLASS:15)
B(6,-22,13,STAINED_GLASS:15)
B(5,-22,14,STAINED_GLASS:15)
B(6,-22,14,STAINED_GLASS:15)
B(3,-21,5,STAINED_GLASS:10)
B(4,-21,5,STAINED_GLASS:10)
B(5,-21,5,STAINED_GLASS:10)
B(2,-21,6,STAINED_GLASS:15)
B(3,-21,6,STAINED_GLASS:10)
B(4,-21,6,STAINED_GLASS:10)
B(5,-21,6,STAINED_GLASS:10)
B(0,-21,7,STAINED_GLASS:15)
B(1,-21,7,STAINED_GLASS:15)
B(2,-21,7,STAINED_GLASS:15)
B(3,-21,7,STAINED_GLASS:10)
B(4,-21,7,STAINED_GLASS:10)
B(5,-21,7,STAINED_GLASS:10)
B(6,-21,7,STAINED_GLASS:10)
B(0,-21,8,STAINED_GLASS:15)
B(1,-21,8,STAINED_GLASS:15)
B(2,-21,8,STAINED_GLASS:15)
B(3,-21,8,STAINED_GLASS:9)
B(4,-21,8,STAINED_GLASS:10)
B(5,-21,8,STAINED_GLASS:10)
B(6,-21,8,STAINED_GLASS:10)
B(0,-21,9,STAINED_GLASS:15)
B(1,-21,9,STAINED_GLASS:15)
B(2,-21,9,STAINED_GLASS:15)
B(3,-21,9,STAINED_GLASS:15)
B(4,-21,9,STAINED_GLASS:9)
B(5,-21,9,STAINED_GLASS:15)
B(6,-21,9,STAINED_GLASS:10)
B(7,-21,9,STAINED_GLASS:11)
B(1,-21,10,STAINED_GLASS:15)
B(2,-21,10,STAINED_GLASS:15)
B(3,-21,10,STAINED_GLASS:15)
B(4,-21,10,SEA_LANTERN)
B(5,-21,10,STAINED_GLASS:11)
B(6,-21,10,STAINED_GLASS:10)
B(7,-21,10,STAINED_GLASS:10)
B(2,-21,11,STAINED_GLASS:9)
B(3,-21,11,STAINED_GLASS:15)
B(4,-21,11,STAINED_GLASS:15)
B(5,-21,11,STAINED_GLASS:11)
B(6,-21,11,STAINED_GLASS:15)
B(7,-21,11,STAINED_GLASS:15)
B(3,-21,12,STAINED_GLASS:15)
B(4,-21,12,STAINED_GLASS:15)
B(5,-21,12,STAINED_GLASS:15)
B(6,-21,12,STAINED_GLASS:15)
B(4,-21,13,STAINED_GLASS:15)
B(5,-21,13,STAINED_GLASS:15)
B(6,-21,13,STAINED_GLASS:15)
B(3,-20,3,STAINED_GLASS:10)
B(0,-20,4,STAINED_GLASS:15)
B(1,-20,4,STAINED_GLASS:10)
B(2,-20,4,STAINED_GLASS:10)
B(3,-20,4,STAINED_GLASS:10)
B(4,-20,4,STAINED_GLASS:10)
B(0,-20,5,STAINED_GLASS:15)
B(1,-20,5,STAINED_GLASS:15)
B(2,-20,5,STAINED_GLASS:10)
B(3,-20,5,STAINED_GLASS:10)
B(4,-20,5,STAINED_GLASS:10)
B(5,-20,5,STAINED_GLASS:10)
B(0,-20,6,STAINED_GLASS:15)
B(1,-20,6,STAINED_GLASS:15)
B(2,-20,6,STAINED_GLASS:15)
B(3,-20,6,STAINED_GLASS:10)
B(4,-20,6,STAINED_GLASS:10)
B(5,-20,6,STAINED_GLASS:10)
B(0,-20,7,STAINED_GLASS:15)
B(1,-20,7,STAINED_GLASS:15)
B(2,-20,7,STAINED_GLASS:15)
B(3,-20,7,STAINED_GLASS:10)
B(4,-20,7,STAINED_GLASS:10)
B(5,-20,7,STAINED_GLASS:10)
B(6,-20,7,STAINED_GLASS:10)
B(0,-20,8,STAINED_GLASS:15)
B(1,-20,8,STAINED_GLASS:15)
B(2,-20,8,STAINED_GLASS:15)
B(3,-20,8,STAINED_GLASS:9)
B(4,-20,8,STAINED_GLASS:11)
B(5,-20,8,STAINED_GLASS:11)
B(6,-20,8,STAINED_GLASS:11)
B(0,-20,9,STAINED_GLASS:15)
B(1,-20,9,STAINED_GLASS:15)
B(2,-20,9,STAINED_GLASS:15)
B(3,-20,9,STAINED_GLASS:9)
B(4,-20,9,SEA_LANTERN)
B(5,-20,9,STAINED_GLASS:11)
B(6,-20,9,STAINED_GLASS:11)
B(7,-20,9,STAINED_GLASS:11)
B(1,-20,10,STAINED_GLASS:9)
B(2,-20,10,STAINED_GLASS:15)
B(3,-20,10,STAINED_GLASS:9)
B(4,-20,10,SEA_LANTERN)
B(5,-20,10,SEA_LANTERN)
B(6,-20,10,STAINED_GLASS:15)
B(7,-20,10,STAINED_GLASS:15)
B(2,-20,11,STAINED_GLASS:15)
B(3,-20,11,STAINED_GLASS:15)
B(4,-20,11,SEA_LANTERN)
B(5,-20,11,SEA_LANTERN)
B(6,-20,11,STAINED_GLASS:15)
B(7,-20,11,STAINED_GLASS:15)
B(3,-20,12,STAINED_GLASS:15)
B(4,-20,12,STAINED_GLASS:15)
B(5,-20,12,STAINED_GLASS:15)
B(6,-20,12,STAINED_GLASS:15)
B(5,-20,13,STAINED_GLASS:15)
B(6,-20,13,STAINED_GLASS:15)
B(2,-19,1,STAINED_GLASS:15)
B(3,-19,1,STAINED_GLASS:10)
B(0,-19,2,STAINED_GLASS:15)
B(1,-19,2,STAINED_GLASS:15)
B(2,-19,2,STAINED_GLASS:10)
B(3,-19,2,STAINED_GLASS:10)
B(0,-19,3,STAINED_GLASS:15)
B(1,-19,3,STAINED_GLASS:15)
B(2,-19,3,STAINED_GLASS:10)
B(3,-19,3,STAINED_GLASS:10)
B(4,-19,3,STAINED_GLASS:10)
B(0,-19,4,STAINED_GLASS:15)
B(1,-19,4,STAINED_GLASS:9)
B(2,-19,4,STAINED_GLASS:10)
B(3,-19,4,STAINED_GLASS:10)
B(4,-19,4,STAINED_GLASS:11)
B(0,-19,5,STAINED_GLASS:15)
B(1,-19,5,STAINED_GLASS:15)
B(2,-19,5,STAINED_GLASS:9)
B(3,-19,5,STAINED_GLASS:10)
B(4,-19,5,STAINED_GLASS:11)
B(5,-19,5,STAINED_GLASS:11)
B(0,-19,6,STAINED_GLASS:15)
B(1,-19,6,STAINED_GLASS:15)
B(2,-19,6,STAINED_GLASS:15)
B(3,-19,6,STAINED_GLASS:10)
B(4,-19,6,STAINED_GLASS:11)
B(5,-19,6,STAINED_GLASS:11)
B(0,-19,7,STAINED_GLASS:15)
B(1,-19,7,STAINED_GLASS:9)
B(2,-19,7,STAINED_GLASS:9)
B(3,-19,7,STAINED_GLASS:11)
B(4,-19,7,STAINED_GLASS:11)
B(5,-19,7,STAINED_GLASS:11)
B(6,-19,7,STAINED_GLASS:11)
B(0,-19,8,STAINED_GLASS:9)
B(1,-19,8,STAINED_GLASS:15)
B(2,-19,8,STAINED_GLASS:9)
B(3,-19,8,SEA_LANTERN)
B(4,-19,8,STAINED_GLASS:10)
B(5,-19,8,STAINED_GLASS:10)
B(6,-19,8,STAINED_GLASS:11)
B(0,-19,9,STAINED_GLASS:9)
B(1,-19,9,STAINED_GLASS:9)
B(2,-19,9,STAINED_GLASS:9)
B(3,-19,9,SEA_LANTERN)
B(4,-19,9,SEA_LANTERN)
B(5,-19,9,SEA_LANTERN)
B(6,-19,9,STAINED_GLASS:11)
B(7,-19,9,STAINED_GLASS:15)
B(1,-19,10,STAINED_GLASS:9)
B(2,-19,10,STAINED_GLASS:15)
B(3,-19,10,SEA_LANTERN)
B(4,-19,10,SEA_LANTERN)
B(5,-19,10,STAINED_GLASS:10)
B(6,-19,10,STAINED_GLASS:15)
B(7,-19,10,STAINED_GLASS:15)
B(2,-19,11,STAINED_GLASS:15)
B(3,-19,11,STAINED_GLASS:15)
B(4,-19,11,STAINED_GLASS:10)
B(5,-19,11,STAINED_GLASS:10)
B(6,-19,11,STAINED_GLASS:15)
B(3,-19,12,STAINED_GLASS:15)
B(4,-19,12,STAINED_GLASS:15)
B(5,-19,12,STAINED_GLASS:15)
B(6,-19,12,STAINED_GLASS:15)
B(0,-18,0,STAINED_GLASS:15)
B(1,-18,0,STAINED_GLASS:15)
B(2,-18,0,STAINED_GLASS:15)
B(3,-18,0,STAINED_GLASS:15)
B(0,-18,1,STAINED_GLASS:15)
B(1,-18,1,STAINED_GLASS:15)
B(2,-18,1,STAINED_GLASS:15)
B(3,-18,1,STAINED_GLASS:15)
B(0,-18,2,STAINED_GLASS:15)
B(1,-18,2,STAINED_GLASS:15)
B(2,-18,2,STAINED_GLASS:15)
B(3,-18,2,STAINED_GLASS:10)
B(0,-18,3,STAINED_GLASS:15)
B(1,-18,3,STAINED_GLASS:9)
B(2,-18,3,STAINED_GLASS:15)
B(3,-18,3,STAINED_GLASS:10)
B(4,-18,3,STAINED_GLASS:10)
B(0,-18,4,STAINED_GLASS:15)
B(1,-18,4,STAINED_GLASS:9)
B(2,-18,4,STAINED_GLASS:10)
B(3,-18,4,STAINED_GLASS:11)
B(4,-18,4,STAINED_GLASS:11)
B(0,-18,5,STAINED_GLASS:15)
B(1,-18,5,STAINED_GLASS:9)
B(2,-18,5,SEA_LANTERN)
B(3,-18,5,STAINED_GLASS:11)
B(4,-18,5,STAINED_GLASS:11)
B(5,-18,5,STAINED_GLASS:11)
B(0,-18,6,STAINED_GLASS:9)
B(1,-18,6,STAINED_GLASS:9)
B(2,-18,6,STAINED_GLASS:9)
B(3,-18,6,STAINED_GLASS:11)
B(4,-18,6,STAINED_GLASS:11)
B(5,-18,6,STAINED_GLASS:11)
B(0,-18,7,STAINED_GLASS:9)
B(1,-18,7,STAINED_GLASS:15)
B(2,-18,7,SEA_LANTERN)
B(3,-18,7,STAINED_GLASS:11)
B(4,-18,7,STAINED_GLASS:11)
B(5,-18,7,STAINED_GLASS:11)
B(6,-18,7,STAINED_GLASS:11)
B(0,-18,8,STAINED_GLASS:9)
B(1,-18,8,STAINED_GLASS:10)
B(2,-18,8,STAINED_GLASS:15)
B(3,-18,8,SEA_LANTERN)
B(4,-18,8,STAINED_GLASS:11)
B(5,-18,8,STAINED_GLASS:11)
B(6,-18,8,STAINED_GLASS:11)
B(0,-18,9,STAINED_GLASS:9)
B(1,-18,9,STAINED_GLASS:9)
B(2,-18,9,STAINED_GLASS:9)
B(3,-18,9,STAINED_GLASS:9)
B(4,-18,9,STAINED_GLASS:15)
B(5,-18,9,STAINED_GLASS:10)
B(6,-18,9,STAINED_GLASS:11)
B(7,-18,9,STAINED_GLASS:11)
B(1,-18,10,STAINED_GLASS:9)
B(2,-18,10,STAINED_GLASS:15)
B(3,-18,10,STAINED_GLASS:10)
B(4,-18,10,STAINED_GLASS:15)
B(5,-18,10,STAINED_GLASS:10)
B(6,-18,10,STAINED_GLASS:15)
B(2,-18,11,STAINED_GLASS:15)
B(3,-18,11,STAINED_GLASS:15)
B(4,-18,11,STAINED_GLASS:15)
B(5,-18,11,STAINED_GLASS:10)
B(6,-18,11,STAINED_GLASS:15)
B(4,-18,12,STAINED_GLASS:15)
B(5,-18,12,STAINED_GLASS:15)
B(6,-18,12,STAINED_GLASS:15)
B(0,-17,0,STAINED_GLASS:9)
B(1,-17,0,STAINED_GLASS:15)
B(2,-17,0,STAINED_GLASS:15)
B(3,-17,0,STAINED_GLASS:11)
B(0,-17,1,STAINED_GLASS:9)
B(1,-17,1,STAINED_GLASS:15)
B(2,-17,1,STAINED_GLASS:11)
B(3,-17,1,STAINED_GLASS:11)
B(0,-17,2,STAINED_GLASS:15)
B(1,-17,2,STAINED_GLASS:15)
B(2,-17,2,STAINED_GLASS:11)
B(3,-17,2,STAINED_GLASS:11)
B(0,-17,3,STAINED_GLASS:9)
B(1,-17,3,SEA_LANTERN)
B(2,-17,3,STAINED_GLASS:15)
B(3,-17,3,STAINED_GLASS:11)
B(4,-17,3,STAINED_GLASS:11)
B(0,-17,4,STAINED_GLASS:9)
B(1,-17,4,SEA_LANTERN)
B(2,-17,4,SEA_LANTERN)
B(3,-17,4,STAINED_GLASS:11)
B(4,-17,4,STAINED_GLASS:11)
B(0,-17,5,STAINED_GLASS:10)
B(1,-17,5,SEA_LANTERN)
B(2,-17,5,SEA_LANTERN)
B(3,-17,5,SEA_LANTERN)
B(4,-17,5,STAINED_GLASS:11)
B(5,-17,5,STAINED_GLASS:11)
B(0,-17,6,STAINED_GLASS:15)
B(1,-17,6,STAINED_GLASS:15)
B(2,-17,6,SEA_LANTERN)
B(3,-17,6,SEA_LANTERN)
B(4,-17,6,STAINED_GLASS:11)
B(5,-17,6,STAINED_GLASS:11)
B(0,-17,7,STAINED_GLASS:10)
B(1,-17,7,STAINED_GLASS:10)
B(2,-17,7,STAINED_GLASS:10)
B(3,-17,7,STAINED_GLASS:11)
B(4,-17,7,STAINED_GLASS:11)
B(5,-17,7,STAINED_GLASS:11)
B(6,-17,7,STAINED_GLASS:11)
B(0,-17,8,STAINED_GLASS:9)
B(1,-17,8,STAINED_GLASS:9)
B(2,-17,8,STAINED_GLASS:10)
B(3,-17,8,STAINED_GLASS:15)
B(4,-17,8,STAINED_GLASS:11)
B(5,-17,8,STAINED_GLASS:15)
B(6,-17,8,STAINED_GLASS:15)
B(0,-17,9,STAINED_GLASS:9)
B(1,-17,9,STAINED_GLASS:9)
B(2,-17,9,STAINED_GLASS:9)
B(3,-17,9,STAINED_GLASS:9)
B(4,-17,9,STAINED_GLASS:11)
B(5,-17,9,STAINED_GLASS:15)
B(6,-17,9,STAINED_GLASS:15)
B(7,-17,9,STAINED_GLASS:11)
B(1,-17,10,STAINED_GLASS:9)
B(2,-17,10,STAINED_GLASS:15)
B(3,-17,10,STAINED_GLASS:15)
B(4,-17,10,STAINED_GLASS:10)
B(5,-17,10,STAINED_GLASS:15)
B(6,-17,10,STAINED_GLASS:10)
B(4,-17,11,STAINED_GLASS:15)
B(5,-17,11,STAINED_GLASS:15)
B(6,-17,11,STAINED_GLASS:15)
B(0,-16,0,STAINED_GLASS:9)
B(1,-16,0,STAINED_GLASS:11)
B(2,-16,0,STAINED_GLASS:11)
B(3,-16,0,STAINED_GLASS:11)
B(0,-16,1,SEA_LANTERN)
B(1,-16,1,STAINED_GLASS:11)
B(2,-16,1,STAINED_GLASS:11)
B(3,-16,1,STAINED_GLASS:11)
B(0,-16,2,STAINED_GLASS:9)
B(1,-16,2,STAINED_GLASS:11)
B(2,-16,2,STAINED_GLASS:11)
B(3,-16,2,STAINED_GLASS:10)
B(0,-16,3,STAINED_GLASS:15)
B(1,-16,3,SEA_LANTERN)
B(2,-16,3,SEA_LANTERN)
B(3,-16,3,STAINED_GLASS:11)
B(4,-16,3,STAINED_GLASS:11)
B(0,-16,4,STAINED_GLASS:15)
B(1,-16,4,SEA_LANTERN)
B(2,-16,4,STAINED_GLASS:11)
B(3,-16,4,STAINED_GLASS:10)
B(4,-16,4,STAINED_GLASS:11)
B(0,-16,5,STAINED_GLASS:9)
B(1,-16,5,STAINED_GLASS:9)
B(2,-16,5,STAINED_GLASS:15)
B(3,-16,5,STAINED_GLASS:10)
B(4,-16,5,STAINED_GLASS:11)
B(5,-16,5,STAINED_GLASS:11)
B(0,-16,6,STAINED_GLASS:10)
B(1,-16,6,STAINED_GLASS:10)
B(2,-16,6,STAINED_GLASS:10)
B(3,-16,6,STAINED_GLASS:10)
B(4,-16,6,STAINED_GLASS:10)
B(5,-16,6,STAINED_GLASS:11)
B(0,-16,7,STAINED_GLASS:9)
B(1,-16,7,STAINED_GLASS:10)
B(2,-16,7,STAINED_GLASS:15)
B(3,-16,7,STAINED_GLASS:11)
B(4,-16,7,STAINED_GLASS:11)
B(5,-16,7,STAINED_GLASS:11)
B(6,-16,7,STAINED_GLASS:11)
B(0,-16,8,STAINED_GLASS:9)
B(1,-16,8,STAINED_GLASS:9)
B(2,-16,8,STAINED_GLASS:15)
B(3,-16,8,STAINED_GLASS:9)
B(4,-16,8,STAINED_GLASS:15)
B(5,-16,8,STAINED_GLASS:15)
B(6,-16,8,STAINED_GLASS:15)
B(0,-16,9,STAINED_GLASS:9)
B(1,-16,9,STAINED_GLASS:9)
B(2,-16,9,STAINED_GLASS:15)
B(3,-16,9,STAINED_GLASS:15)
B(4,-16,9,STAINED_GLASS:15)
B(5,-16,9,STAINED_GLASS:15)
B(6,-16,9,STAINED_GLASS:15)
B(1,-16,10,STAINED_GLASS:9)
B(2,-16,10,STAINED_GLASS:15)
B(3,-16,10,STAINED_GLASS:15)
B(4,-16,10,STAINED_GLASS:15)
B(3,-16,11,STAINED_GLASS:15)
B(0,-15,0,SEA_LANTERN)
B(1,-15,0,SEA_LANTERN)
B(2,-15,0,STAINED_GLASS:10)
B(3,-15,0,STAINED_GLASS:11)
B(0,-15,1,SEA_LANTERN)
B(1,-15,1,STAINED_GLASS:11)
B(2,-15,1,STAINED_GLASS:10)
B(3,-15,1,STAINED_GLASS:11)
B(0,-15,2,SEA_LANTERN)
B(1,-15,2,SEA_LANTERN)
B(2,-15,2,STAINED_GLASS:10)
B(3,-15,2,STAINED_GLASS:11)
B(0,-15,3,STAINED_GLASS:9)
B(1,-15,3,SEA_LANTERN)
B(2,-15,3,STAINED_GLASS:10)
B(3,-15,3,STAINED_GLASS:10)
B(4,-15,3,STAINED_GLASS:11)
B(0,-15,4,STAINED_GLASS:10)
B(1,-15,4,STAINED_GLASS:15)
B(2,-15,4,STAINED_GLASS:10)
B(3,-15,4,STAINED_GLASS:11)
B(4,-15,4,STAINED_GLASS:11)
B(0,-15,5,STAINED_GLASS:9)
B(1,-15,5,STAINED_GLASS:9)
B(2,-15,5,STAINED_GLASS:10)
B(3,-15,5,STAINED_GLASS:15)
B(4,-15,5,STAINED_GLASS:11)
B(5,-15,5,STAINED_GLASS:11)
B(0,-15,6,STAINED_GLASS:9)
B(1,-15,6,STAINED_GLASS:9)
B(2,-15,6,STAINED_GLASS:10)
B(3,-15,6,STAINED_GLASS:15)
B(4,-15,6,STAINED_GLASS:11)
B(5,-15,6,STAINED_GLASS:11)
B(0,-15,7,STAINED_GLASS:10)
B(1,-15,7,STAINED_GLASS:10)
B(2,-15,7,STAINED_GLASS:10)
B(3,-15,7,STAINED_GLASS:15)
B(4,-15,7,STAINED_GLASS:15)
B(5,-15,7,STAINED_GLASS:15)
B(6,-15,7,STAINED_GLASS:11)
B(0,-15,8,STAINED_GLASS:9)
B(1,-15,8,STAINED_GLASS:10)
B(2,-15,8,STAINED_GLASS:10)
B(3,-15,8,STAINED_GLASS:15)
B(4,-15,8,STAINED_GLASS:15)
B(0,-15,9,STAINED_GLASS:10)
B(1,-15,9,STAINED_GLASS:10)
B(2,-15,9,STAINED_GLASS:15)
B(3,-15,9,STAINED_GLASS:15)
B(0,-14,0,SEA_LANTERN)
B(1,-14,0,STAINED_GLASS:11)
B(2,-14,0,STAINED_GLASS:11)
B(3,-14,0,STAINED_GLASS:11)
B(0,-14,1,STAINED_GLASS:15)
B(1,-14,1,STAINED_GLASS:10)
B(2,-14,1,STAINED_GLASS:11)
B(3,-14,1,STAINED_GLASS:11)
B(0,-14,2,STAINED_GLASS:9)
B(1,-14,2,STAINED_GLASS:10)
B(2,-14,2,STAINED_GLASS:10)
B(3,-14,2,STAINED_GLASS:11)
B(0,-14,3,STAINED_GLASS:10)
B(1,-14,3,STAINED_GLASS:15)
B(2,-14,3,STAINED_GLASS:11)
B(3,-14,3,STAINED_GLASS:9)
B(4,-14,3,STAINED_GLASS:11)
B(0,-14,4,STAINED_GLASS:9)
B(1,-14,4,STAINED_GLASS:9)
B(2,-14,4,STAINED_GLASS:15)
B(3,-14,4,STAINED_GLASS:11)
B(4,-14,4,STAINED_GLASS:11)
B(0,-14,5,STAINED_GLASS:9)
B(1,-14,5,STAINED_GLASS:10)
B(2,-14,5,STAINED_GLASS:10)
B(3,-14,5,STAINED_GLASS:15)
B(4,-14,5,STAINED_GLASS:11)
B(0,-14,6,STAINED_GLASS:10)
B(1,-14,6,STAINED_GLASS:10)
B(2,-14,6,STAINED_GLASS:10)
B(3,-14,6,STAINED_GLASS:15)
B(4,-14,6,STAINED_GLASS:9)
B(0,-14,7,STAINED_GLASS:10)
B(1,-14,7,STAINED_GLASS:10)
B(0,-13,0,STAINED_GLASS:15)
B(1,-13,0,STAINED_GLASS:11)
B(2,-13,0,STAINED_GLASS:11)
B(3,-13,0,STAINED_GLASS:11)
B(0,-13,1,STAINED_GLASS:9)
B(1,-13,1,STAINED_GLASS:11)
B(2,-13,1,STAINED_GLASS:11)
B(3,-13,1,STAINED_GLASS:11)
B(0,-13,2,STAINED_GLASS:10)
B(1,-13,2,STAINED_GLASS:15)
B(2,-13,2,STAINED_GLASS:11)
B(3,-13,2,STAINED_GLASS:11)
B(0,-13,3,STAINED_GLASS:10)
B(1,-13,3,STAINED_GLASS:9)
B(2,-13,3,STAINED_GLASS:15)
B(3,-13,3,STAINED_GLASS:15)
B(4,-13,3,STAINED_GLASS:9)
B(0,-13,4,STAINED_GLASS:10)
B(1,-13,4,STAINED_GLASS:15)
B(2,-13,4,STAINED_GLASS:15)
B(0,-13,5,STAINED_GLASS:10)
B(1,-13,5,STAINED_GLASS:10)
B(0,-12,0,STAINED_GLASS:9)
B(1,-12,0,STAINED_GLASS:15)
B(2,-12,0,STAINED_GLASS:11)
B(3,-12,0,STAINED_GLASS:11)
B(0,-12,1,STAINED_GLASS:15)
B(1,-12,1,STAINED_GLASS:15)
B(2,-12,1,STAINED_GLASS:15)
B(0,-12,2,STAINED_GLASS:10)
B(1,-12,2,STAINED_GLASS:15)
B(2,-12,2,STAINED_GLASS:15)
B(0,-12,3,STAINED_GLASS:10)
B(1,-12,3,STAINED_GLASS:15)
B(0,-11,0,STAINED_GLASS:15)
B(1,-11,0,STAINED_GLASS:15)
B(2,-11,0,STAINED_GLASS:9)

