#######################################################################
# +-----------------------------------------------------------------+ #
# |                            BO3 object                           | #
# +-----------------------------------------------------------------+ #
#######################################################################

Author: Bo3 BulkEdit

Description: Converted Schematic - Modified by Bo3BulkEdit

Version: 3

SettingsMode: WriteDisable

#######################################################################
# +-----------------------------------------------------------------+ #
# |                          Main settings                          | #
# +-----------------------------------------------------------------+ #
#######################################################################

IsOTGPlus: true
Tree: false
Frequency: 1
Rarity: 100.0
RotateRandomly: false
SpawnHeight: randomY
MaxBranchDepth: 10
ExcludedBiomes: All

##############################
# Height Limits for the BO3. #
##############################

MinHeight: 0
MaxHeight: 255

#######################################################################
# +-----------------------------------------------------------------+ #
# |                      Source block settings                      | #
# +-----------------------------------------------------------------+ #
#######################################################################

CanOverride: true
MaxPercentageOutsideSourceBlock: 100
OutsideSourceBlock: placeAnyway

#######################################################################
# +-----------------------------------------------------------------+ #
# |                               OTG+                              | #
# +-----------------------------------------------------------------+ #
#######################################################################

BO3Group: CeilingCrystals:0

#######################################################################
# +-----------------------------------------------------------------+ #
# |                              Blocks                             | #
# +-----------------------------------------------------------------+ #
#######################################################################

B(0,750,0,AIR)
B(15,750,15,AIR)
B(8,-9,14,STAINED_GLASS:15)
B(9,-9,14,STAINED_GLASS:15)
B(10,-9,14,STAINED_GLASS:15)
B(7,-9,15,STAINED_GLASS:15)
B(8,-9,15,STAINED_GLASS:15)
B(9,-9,15,STAINED_GLASS:15)
B(10,-9,15,STAINED_GLASS:15)
B(11,-9,15,STAINED_GLASS:11)
B(8,-8,12,STAINED_GLASS:15)
B(5,-8,13,STAINED_GLASS:9)
B(6,-8,13,STAINED_GLASS:15)
B(7,-8,13,STAINED_GLASS:15)
B(8,-8,13,STAINED_GLASS:15)
B(9,-8,13,STAINED_GLASS:10)
B(10,-8,13,STAINED_GLASS:10)
B(5,-8,14,STAINED_GLASS:11)
B(6,-8,14,STAINED_GLASS:15)
B(7,-8,14,STAINED_GLASS:15)
B(8,-8,14,STAINED_GLASS:15)
B(9,-8,14,STAINED_GLASS:10)
B(10,-8,14,STAINED_GLASS:10)
B(5,-8,15,STAINED_GLASS:11)
B(6,-8,15,STAINED_GLASS:11)
B(7,-8,15,STAINED_GLASS:15)
B(8,-8,15,STAINED_GLASS:9)
B(9,-8,15,STAINED_GLASS:15)
B(10,-8,15,STAINED_GLASS:11)
B(11,-8,15,STAINED_GLASS:11)
B(6,-7,10,STAINED_GLASS:15)
B(8,-7,10,STAINED_GLASS:10)
B(9,-7,10,STAINED_GLASS:10)
B(5,-7,11,STAINED_GLASS:15)
B(6,-7,11,STAINED_GLASS:15)
B(7,-7,11,STAINED_GLASS:15)
B(8,-7,11,STAINED_GLASS:10)
B(9,-7,11,STAINED_GLASS:10)
B(4,-7,12,STAINED_GLASS:11)
B(5,-7,12,STAINED_GLASS:11)
B(6,-7,12,STAINED_GLASS:15)
B(7,-7,12,STAINED_GLASS:15)
B(8,-7,12,STAINED_GLASS:10)
B(9,-7,12,STAINED_GLASS:10)
B(3,-7,13,STAINED_GLASS:11)
B(4,-7,13,STAINED_GLASS:11)
B(5,-7,13,STAINED_GLASS:15)
B(6,-7,13,STAINED_GLASS:9)
B(7,-7,13,STAINED_GLASS:9)
B(8,-7,13,STAINED_GLASS:10)
B(9,-7,13,STAINED_GLASS:10)
B(10,-7,13,STAINED_GLASS:10)
B(4,-7,14,STAINED_GLASS:11)
B(5,-7,14,STAINED_GLASS:11)
B(6,-7,14,STAINED_GLASS:15)
B(7,-7,14,STAINED_GLASS:9)
B(8,-7,14,STAINED_GLASS:11)
B(9,-7,14,STAINED_GLASS:10)
B(10,-7,14,STAINED_GLASS:10)
B(5,-7,15,STAINED_GLASS:11)
B(6,-7,15,STAINED_GLASS:11)
B(7,-7,15,STAINED_GLASS:11)
B(8,-7,15,STAINED_GLASS:15)
B(9,-7,15,STAINED_GLASS:11)
B(10,-7,15,STAINED_GLASS:11)
B(11,-7,15,STAINED_GLASS:11)
B(6,-6,8,STAINED_GLASS:10)
B(5,-6,9,STAINED_GLASS:15)
B(6,-6,9,STAINED_GLASS:10)
B(7,-6,9,STAINED_GLASS:10)
B(8,-6,9,STAINED_GLASS:10)
B(3,-6,10,STAINED_GLASS:11)
B(4,-6,10,STAINED_GLASS:15)
B(5,-6,10,STAINED_GLASS:15)
B(6,-6,10,STAINED_GLASS:10)
B(7,-6,10,STAINED_GLASS:10)
B(8,-6,10,STAINED_GLASS:10)
B(9,-6,10,STAINED_GLASS:10)
B(3,-6,11,STAINED_GLASS:11)
B(4,-6,11,STAINED_GLASS:11)
B(5,-6,11,STAINED_GLASS:15)
B(6,-6,11,STAINED_GLASS:9)
B(7,-6,11,STAINED_GLASS:10)
B(8,-6,11,STAINED_GLASS:10)
B(9,-6,11,STAINED_GLASS:11)
B(4,-6,12,STAINED_GLASS:11)
B(5,-6,12,STAINED_GLASS:11)
B(6,-6,12,STAINED_GLASS:9)
B(7,-6,12,STAINED_GLASS:15)
B(8,-6,12,STAINED_GLASS:11)
B(9,-6,12,STAINED_GLASS:11)
B(3,-6,13,STAINED_GLASS:11)
B(4,-6,13,STAINED_GLASS:11)
B(5,-6,13,STAINED_GLASS:11)
B(6,-6,13,STAINED_GLASS:15)
B(7,-6,13,STAINED_GLASS:15)
B(8,-6,13,STAINED_GLASS:11)
B(9,-6,13,STAINED_GLASS:11)
B(10,-6,13,STAINED_GLASS:11)
B(4,-6,14,STAINED_GLASS:11)
B(5,-6,14,STAINED_GLASS:15)
B(6,-6,14,STAINED_GLASS:9)
B(7,-6,14,SEA_LANTERN)
B(8,-6,14,STAINED_GLASS:11)
B(9,-6,14,STAINED_GLASS:11)
B(10,-6,14,STAINED_GLASS:11)
B(5,-6,15,STAINED_GLASS:11)
B(6,-6,15,STAINED_GLASS:9)
B(7,-6,15,STAINED_GLASS:9)
B(8,-6,15,SEA_LANTERN)
B(9,-6,15,STAINED_GLASS:10)
B(10,-6,15,STAINED_GLASS:11)
B(11,-6,15,STAINED_GLASS:11)
B(6,-5,6,STAINED_GLASS:15)
B(7,-5,6,STAINED_GLASS:15)
B(3,-5,7,STAINED_GLASS:15)
B(4,-5,7,STAINED_GLASS:15)
B(5,-5,7,STAINED_GLASS:15)
B(6,-5,7,STAINED_GLASS:10)
B(7,-5,7,STAINED_GLASS:15)
B(2,-5,8,STAINED_GLASS:15)
B(3,-5,8,STAINED_GLASS:11)
B(4,-5,8,STAINED_GLASS:15)
B(5,-5,8,STAINED_GLASS:15)
B(6,-5,8,STAINED_GLASS:10)
B(7,-5,8,STAINED_GLASS:10)
B(2,-5,9,STAINED_GLASS:11)
B(3,-5,9,STAINED_GLASS:11)
B(4,-5,9,STAINED_GLASS:15)
B(5,-5,9,STAINED_GLASS:9)
B(6,-5,9,STAINED_GLASS:10)
B(7,-5,9,STAINED_GLASS:10)
B(8,-5,9,STAINED_GLASS:10)
B(2,-5,10,STAINED_GLASS:11)
B(3,-5,10,STAINED_GLASS:11)
B(4,-5,10,STAINED_GLASS:15)
B(5,-5,10,STAINED_GLASS:9)
B(6,-5,10,STAINED_GLASS:11)
B(7,-5,10,STAINED_GLASS:10)
B(8,-5,10,STAINED_GLASS:10)
B(9,-5,10,STAINED_GLASS:10)
B(3,-5,11,STAINED_GLASS:11)
B(4,-5,11,STAINED_GLASS:11)
B(5,-5,11,STAINED_GLASS:11)
B(6,-5,11,STAINED_GLASS:15)
B(7,-5,11,STAINED_GLASS:11)
B(8,-5,11,STAINED_GLASS:11)
B(9,-5,11,STAINED_GLASS:11)
B(4,-5,12,STAINED_GLASS:11)
B(5,-5,12,STAINED_GLASS:11)
B(6,-5,12,STAINED_GLASS:15)
B(7,-5,12,STAINED_GLASS:11)
B(8,-5,12,STAINED_GLASS:11)
B(9,-5,12,STAINED_GLASS:11)
B(3,-5,13,STAINED_GLASS:11)
B(4,-5,13,STAINED_GLASS:11)
B(5,-5,13,STAINED_GLASS:10)
B(6,-5,13,SEA_LANTERN)
B(7,-5,13,SEA_LANTERN)
B(8,-5,13,SEA_LANTERN)
B(9,-5,13,STAINED_GLASS:11)
B(10,-5,13,STAINED_GLASS:11)
B(4,-5,14,STAINED_GLASS:11)
B(5,-5,14,STAINED_GLASS:10)
B(6,-5,14,SEA_LANTERN)
B(7,-5,14,SEA_LANTERN)
B(8,-5,14,SEA_LANTERN)
B(9,-5,14,STAINED_GLASS:11)
B(10,-5,14,STAINED_GLASS:11)
B(5,-5,15,STAINED_GLASS:15)
B(6,-5,15,STAINED_GLASS:15)
B(7,-5,15,SEA_LANTERN)
B(8,-5,15,STAINED_GLASS:15)
B(9,-5,15,STAINED_GLASS:11)
B(10,-5,15,STAINED_GLASS:11)
B(11,-5,15,STAINED_GLASS:11)
B(4,-4,4,STAINED_GLASS:15)
B(3,-4,5,STAINED_GLASS:15)
B(4,-4,5,STAINED_GLASS:15)
B(5,-4,5,STAINED_GLASS:15)
B(6,-4,5,STAINED_GLASS:15)
B(2,-4,6,STAINED_GLASS:15)
B(3,-4,6,STAINED_GLASS:15)
B(4,-4,6,STAINED_GLASS:15)
B(5,-4,6,STAINED_GLASS:15)
B(6,-4,6,STAINED_GLASS:15)
B(7,-4,6,STAINED_GLASS:15)
B(1,-4,7,STAINED_GLASS:15)
B(2,-4,7,STAINED_GLASS:15)
B(3,-4,7,STAINED_GLASS:15)
B(4,-4,7,STAINED_GLASS:15)
B(5,-4,7,STAINED_GLASS:15)
B(6,-4,7,STAINED_GLASS:10)
B(7,-4,7,STAINED_GLASS:15)
B(1,-4,8,STAINED_GLASS:15)
B(2,-4,8,STAINED_GLASS:15)
B(3,-4,8,STAINED_GLASS:15)
B(4,-4,8,STAINED_GLASS:9)
B(5,-4,8,STAINED_GLASS:15)
B(6,-4,8,STAINED_GLASS:11)
B(7,-4,8,STAINED_GLASS:10)
B(2,-4,9,STAINED_GLASS:11)
B(3,-4,9,STAINED_GLASS:11)
B(4,-4,9,STAINED_GLASS:15)
B(5,-4,9,STAINED_GLASS:15)
B(6,-4,9,STAINED_GLASS:11)
B(7,-4,9,STAINED_GLASS:10)
B(8,-4,9,STAINED_GLASS:10)
B(2,-4,10,STAINED_GLASS:11)
B(3,-4,10,STAINED_GLASS:11)
B(4,-4,10,STAINED_GLASS:11)
B(5,-4,10,STAINED_GLASS:15)
B(6,-4,10,STAINED_GLASS:11)
B(7,-4,10,STAINED_GLASS:11)
B(8,-4,10,STAINED_GLASS:10)
B(9,-4,10,STAINED_GLASS:10)
B(3,-4,11,STAINED_GLASS:11)
B(4,-4,11,STAINED_GLASS:11)
B(5,-4,11,STAINED_GLASS:9)
B(6,-4,11,SEA_LANTERN)
B(7,-4,11,STAINED_GLASS:10)
B(8,-4,11,STAINED_GLASS:11)
B(9,-4,11,STAINED_GLASS:11)
B(4,-4,12,STAINED_GLASS:10)
B(5,-4,12,STAINED_GLASS:10)
B(6,-4,12,SEA_LANTERN)
B(7,-4,12,SEA_LANTERN)
B(8,-4,12,STAINED_GLASS:11)
B(9,-4,12,STAINED_GLASS:11)
B(3,-4,13,STAINED_GLASS:11)
B(4,-4,13,STAINED_GLASS:10)
B(5,-4,13,STAINED_GLASS:10)
B(6,-4,13,SEA_LANTERN)
B(7,-4,13,SEA_LANTERN)
B(8,-4,13,STAINED_GLASS:11)
B(9,-4,13,STAINED_GLASS:11)
B(10,-4,13,STAINED_GLASS:11)
B(4,-4,14,STAINED_GLASS:10)
B(5,-4,14,STAINED_GLASS:10)
B(6,-4,14,STAINED_GLASS:10)
B(7,-4,14,STAINED_GLASS:15)
B(8,-4,14,STAINED_GLASS:9)
B(9,-4,14,STAINED_GLASS:11)
B(10,-4,14,STAINED_GLASS:11)
B(5,-4,15,STAINED_GLASS:15)
B(6,-4,15,STAINED_GLASS:10)
B(7,-4,15,STAINED_GLASS:10)
B(8,-4,15,STAINED_GLASS:9)
B(9,-4,15,STAINED_GLASS:11)
B(10,-4,15,STAINED_GLASS:11)
B(11,-4,15,STAINED_GLASS:11)
B(4,-3,4,STAINED_GLASS:15)
B(3,-3,5,STAINED_GLASS:15)
B(4,-3,5,STAINED_GLASS:15)
B(5,-3,5,STAINED_GLASS:15)
B(6,-3,5,STAINED_GLASS:15)
B(2,-3,6,STAINED_GLASS:15)
B(3,-3,6,STAINED_GLASS:15)
B(4,-3,6,STAINED_GLASS:9)
B(5,-3,6,STAINED_GLASS:15)
B(6,-3,6,STAINED_GLASS:15)
B(7,-3,6,STAINED_GLASS:15)
B(1,-3,7,STAINED_GLASS:15)
B(2,-3,7,STAINED_GLASS:15)
B(3,-3,7,STAINED_GLASS:11)
B(4,-3,7,STAINED_GLASS:11)
B(5,-3,7,STAINED_GLASS:11)
B(6,-3,7,STAINED_GLASS:15)
B(7,-3,7,STAINED_GLASS:15)
B(1,-3,8,STAINED_GLASS:11)
B(2,-3,8,STAINED_GLASS:15)
B(3,-3,8,STAINED_GLASS:11)
B(4,-3,8,STAINED_GLASS:15)
B(5,-3,8,STAINED_GLASS:11)
B(6,-3,8,STAINED_GLASS:11)
B(7,-3,8,STAINED_GLASS:10)
B(2,-3,9,STAINED_GLASS:15)
B(3,-3,9,STAINED_GLASS:15)
B(4,-3,9,STAINED_GLASS:9)
B(5,-3,9,SEA_LANTERN)
B(6,-3,9,SEA_LANTERN)
B(7,-3,9,STAINED_GLASS:11)
B(8,-3,9,STAINED_GLASS:11)
B(2,-3,10,STAINED_GLASS:11)
B(3,-3,10,STAINED_GLASS:11)
B(4,-3,10,SEA_LANTERN)
B(5,-3,10,SEA_LANTERN)
B(6,-3,10,SEA_LANTERN)
B(7,-3,10,STAINED_GLASS:10)
B(8,-3,10,STAINED_GLASS:11)
B(9,-3,10,STAINED_GLASS:11)
B(3,-3,11,STAINED_GLASS:10)
B(4,-3,11,STAINED_GLASS:10)
B(5,-3,11,SEA_LANTERN)
B(6,-3,11,SEA_LANTERN)
B(7,-3,11,STAINED_GLASS:11)
B(8,-3,11,STAINED_GLASS:11)
B(9,-3,11,STAINED_GLASS:11)
B(4,-3,12,STAINED_GLASS:10)
B(5,-3,12,STAINED_GLASS:10)
B(6,-3,12,SEA_LANTERN)
B(7,-3,12,STAINED_GLASS:9)
B(8,-3,12,STAINED_GLASS:11)
B(9,-3,12,STAINED_GLASS:11)
B(3,-3,13,STAINED_GLASS:10)
B(4,-3,13,STAINED_GLASS:10)
B(5,-3,13,STAINED_GLASS:10)
B(6,-3,13,STAINED_GLASS:15)
B(7,-3,13,STAINED_GLASS:15)
B(8,-3,13,STAINED_GLASS:11)
B(9,-3,13,STAINED_GLASS:11)
B(10,-3,13,STAINED_GLASS:11)
B(4,-3,14,STAINED_GLASS:10)
B(5,-3,14,STAINED_GLASS:10)
B(6,-3,14,STAINED_GLASS:15)
B(7,-3,14,STAINED_GLASS:9)
B(8,-3,14,STAINED_GLASS:11)
B(9,-3,14,STAINED_GLASS:11)
B(10,-3,14,STAINED_GLASS:11)
B(5,-3,15,STAINED_GLASS:15)
B(6,-3,15,STAINED_GLASS:15)
B(7,-3,15,STAINED_GLASS:15)
B(8,-3,15,STAINED_GLASS:9)
B(9,-3,15,STAINED_GLASS:11)
B(10,-3,15,STAINED_GLASS:11)
B(11,-3,15,STAINED_GLASS:15)
B(4,-2,3,STAINED_GLASS:15)
B(1,-2,4,STAINED_GLASS:15)
B(2,-2,4,STAINED_GLASS:15)
B(3,-2,4,STAINED_GLASS:15)
B(4,-2,4,STAINED_GLASS:15)
B(1,-2,5,STAINED_GLASS:11)
B(2,-2,5,STAINED_GLASS:15)
B(3,-2,5,STAINED_GLASS:11)
B(4,-2,5,STAINED_GLASS:15)
B(5,-2,5,STAINED_GLASS:15)
B(6,-2,5,STAINED_GLASS:11)
B(2,-2,6,STAINED_GLASS:15)
B(3,-2,6,STAINED_GLASS:15)
B(4,-2,6,STAINED_GLASS:15)
B(5,-2,6,STAINED_GLASS:11)
B(6,-2,6,STAINED_GLASS:11)
B(7,-2,6,STAINED_GLASS:11)
B(1,-2,7,STAINED_GLASS:11)
B(2,-2,7,STAINED_GLASS:11)
B(3,-2,7,STAINED_GLASS:11)
B(4,-2,7,STAINED_GLASS:11)
B(5,-2,7,STAINED_GLASS:11)
B(6,-2,7,STAINED_GLASS:11)
B(7,-2,7,STAINED_GLASS:11)
B(1,-2,8,STAINED_GLASS:11)
B(2,-2,8,STAINED_GLASS:11)
B(3,-2,8,STAINED_GLASS:15)
B(4,-2,8,SEA_LANTERN)
B(5,-2,8,SEA_LANTERN)
B(6,-2,8,STAINED_GLASS:15)
B(7,-2,8,STAINED_GLASS:11)
B(2,-2,9,STAINED_GLASS:11)
B(3,-2,9,STAINED_GLASS:11)
B(4,-2,9,SEA_LANTERN)
B(5,-2,9,SEA_LANTERN)
B(6,-2,9,STAINED_GLASS:11)
B(7,-2,9,STAINED_GLASS:11)
B(8,-2,9,STAINED_GLASS:11)
B(2,-2,10,STAINED_GLASS:15)
B(3,-2,10,STAINED_GLASS:10)
B(4,-2,10,STAINED_GLASS:9)
B(5,-2,10,SEA_LANTERN)
B(6,-2,10,STAINED_GLASS:11)
B(7,-2,10,STAINED_GLASS:11)
B(8,-2,10,STAINED_GLASS:11)
B(9,-2,10,STAINED_GLASS:11)
B(3,-2,11,STAINED_GLASS:10)
B(4,-2,11,STAINED_GLASS:9)
B(5,-2,11,STAINED_GLASS:9)
B(6,-2,11,STAINED_GLASS:9)
B(7,-2,11,STAINED_GLASS:11)
B(8,-2,11,STAINED_GLASS:11)
B(9,-2,11,STAINED_GLASS:11)
B(4,-2,12,STAINED_GLASS:10)
B(5,-2,12,STAINED_GLASS:10)
B(6,-2,12,STAINED_GLASS:9)
B(7,-2,12,STAINED_GLASS:11)
B(8,-2,12,STAINED_GLASS:11)
B(9,-2,12,STAINED_GLASS:11)
B(3,-2,13,STAINED_GLASS:10)
B(4,-2,13,STAINED_GLASS:10)
B(5,-2,13,STAINED_GLASS:10)
B(6,-2,13,STAINED_GLASS:9)
B(7,-2,13,STAINED_GLASS:9)
B(8,-2,13,STAINED_GLASS:11)
B(9,-2,13,STAINED_GLASS:11)
B(10,-2,13,STAINED_GLASS:11)
B(4,-2,14,STAINED_GLASS:10)
B(5,-2,14,STAINED_GLASS:10)
B(6,-2,14,STAINED_GLASS:15)
B(7,-2,14,STAINED_GLASS:15)
B(8,-2,14,STAINED_GLASS:11)
B(9,-2,14,STAINED_GLASS:11)
B(5,-2,15,STAINED_GLASS:15)
B(6,-2,15,STAINED_GLASS:15)
B(7,-2,15,STAINED_GLASS:15)
B(8,-2,15,STAINED_GLASS:15)
B(9,-2,15,STAINED_GLASS:11)
B(3,-1,3,STAINED_GLASS:15)
B(4,-1,3,STAINED_GLASS:15)
B(1,-1,4,STAINED_GLASS:11)
B(2,-1,4,STAINED_GLASS:15)
B(3,-1,4,STAINED_GLASS:15)
B(4,-1,4,STAINED_GLASS:11)
B(1,-1,5,STAINED_GLASS:11)
B(2,-1,5,STAINED_GLASS:11)
B(3,-1,5,STAINED_GLASS:11)
B(4,-1,5,STAINED_GLASS:11)
B(5,-1,5,STAINED_GLASS:11)
B(6,-1,5,STAINED_GLASS:11)
B(2,-1,6,STAINED_GLASS:11)
B(3,-1,6,STAINED_GLASS:11)
B(4,-1,6,SEA_LANTERN)
B(5,-1,6,STAINED_GLASS:11)
B(6,-1,6,STAINED_GLASS:11)
B(7,-1,6,STAINED_GLASS:11)
B(1,-1,7,STAINED_GLASS:11)
B(2,-1,7,STAINED_GLASS:15)
B(3,-1,7,STAINED_GLASS:15)
B(4,-1,7,SEA_LANTERN)
B(5,-1,7,STAINED_GLASS:11)
B(6,-1,7,STAINED_GLASS:11)
B(7,-1,7,STAINED_GLASS:11)
B(1,-1,8,STAINED_GLASS:11)
B(2,-1,8,STAINED_GLASS:11)
B(3,-1,8,STAINED_GLASS:11)
B(4,-1,8,STAINED_GLASS:15)
B(5,-1,8,STAINED_GLASS:11)
B(6,-1,8,STAINED_GLASS:11)
B(7,-1,8,STAINED_GLASS:11)
B(2,-1,9,STAINED_GLASS:11)
B(3,-1,9,STAINED_GLASS:15)
B(4,-1,9,STAINED_GLASS:9)
B(5,-1,9,STAINED_GLASS:15)
B(6,-1,9,STAINED_GLASS:11)
B(7,-1,9,STAINED_GLASS:11)
B(8,-1,9,STAINED_GLASS:11)
B(2,-1,10,STAINED_GLASS:15)
B(3,-1,10,STAINED_GLASS:15)
B(4,-1,10,STAINED_GLASS:15)
B(5,-1,10,STAINED_GLASS:9)
B(6,-1,10,STAINED_GLASS:11)
B(7,-1,10,STAINED_GLASS:11)
B(8,-1,10,STAINED_GLASS:11)
B(9,-1,10,STAINED_GLASS:11)
B(3,-1,11,STAINED_GLASS:10)
B(4,-1,11,STAINED_GLASS:15)
B(5,-1,11,STAINED_GLASS:15)
B(6,-1,11,STAINED_GLASS:9)
B(7,-1,11,STAINED_GLASS:11)
B(8,-1,11,STAINED_GLASS:11)
B(9,-1,11,STAINED_GLASS:11)
B(4,-1,12,STAINED_GLASS:10)
B(5,-1,12,STAINED_GLASS:10)
B(6,-1,12,STAINED_GLASS:9)
B(7,-1,12,STAINED_GLASS:11)
B(8,-1,12,STAINED_GLASS:11)
B(9,-1,12,STAINED_GLASS:11)
B(3,-1,13,STAINED_GLASS:10)
B(4,-1,13,STAINED_GLASS:10)
B(5,-1,13,STAINED_GLASS:15)
B(6,-1,13,STAINED_GLASS:15)
B(7,-1,13,STAINED_GLASS:15)
B(8,-1,13,STAINED_GLASS:15)
B(9,-1,13,STAINED_GLASS:11)
B(4,-1,14,STAINED_GLASS:10)
B(5,-1,14,STAINED_GLASS:15)
B(6,-1,14,STAINED_GLASS:15)
B(2,0,1,STAINED_GLASS:15)
B(1,0,2,STAINED_GLASS:15)
B(2,0,2,STAINED_GLASS:15)
B(3,0,2,STAINED_GLASS:15)
B(1,0,3,STAINED_GLASS:11)
B(2,0,3,STAINED_GLASS:15)
B(3,0,3,STAINED_GLASS:15)
B(4,0,3,STAINED_GLASS:11)
B(1,0,4,STAINED_GLASS:11)
B(2,0,4,STAINED_GLASS:11)
B(3,0,4,STAINED_GLASS:11)
B(4,0,4,STAINED_GLASS:11)
B(1,0,5,STAINED_GLASS:11)
B(2,0,5,STAINED_GLASS:11)
B(3,0,5,STAINED_GLASS:11)
B(4,0,5,STAINED_GLASS:11)
B(5,0,5,STAINED_GLASS:11)
B(6,0,5,STAINED_GLASS:11)
B(2,0,6,STAINED_GLASS:11)
B(3,0,6,STAINED_GLASS:11)
B(4,0,6,STAINED_GLASS:9)
B(5,0,6,STAINED_GLASS:11)
B(6,0,6,STAINED_GLASS:11)
B(7,0,6,STAINED_GLASS:11)
B(1,0,7,STAINED_GLASS:11)
B(2,0,7,STAINED_GLASS:11)
B(3,0,7,STAINED_GLASS:11)
B(5,0,7,STAINED_GLASS:11)
B(6,0,7,STAINED_GLASS:11)
B(7,0,7,STAINED_GLASS:11)
B(1,0,8,STAINED_GLASS:11)
B(2,0,8,STAINED_GLASS:11)
B(3,0,8,STAINED_GLASS:15)
B(4,0,8,STAINED_GLASS:9)
B(5,0,8,STAINED_GLASS:11)
B(6,0,8,STAINED_GLASS:11)
B(7,0,8,STAINED_GLASS:11)
B(2,0,9,STAINED_GLASS:11)
B(3,0,9,STAINED_GLASS:15)
B(4,0,9,STAINED_GLASS:15)
B(5,0,9,STAINED_GLASS:9)
B(6,0,9,STAINED_GLASS:11)
B(7,0,9,STAINED_GLASS:11)
B(8,0,9,STAINED_GLASS:11)
B(2,0,10,STAINED_GLASS:15)
B(3,0,10,STAINED_GLASS:15)
B(4,0,10,STAINED_GLASS:15)
B(5,0,10,STAINED_GLASS:15)
B(6,0,10,STAINED_GLASS:11)
B(7,0,10,STAINED_GLASS:11)
B(8,0,10,STAINED_GLASS:11)
B(3,0,11,STAINED_GLASS:15)
B(4,0,11,STAINED_GLASS:15)
B(5,0,11,STAINED_GLASS:15)
B(6,0,11,STAINED_GLASS:15)
B(7,0,11,STAINED_GLASS:11)
B(4,0,12,STAINED_GLASS:15)
B(5,0,12,STAINED_GLASS:15)
B(6,0,12,STAINED_GLASS:15)
B(1,1,1,STAINED_GLASS:11)
B(2,1,1,STAINED_GLASS:15)
B(1,1,2,STAINED_GLASS:11)
B(2,1,2,STAINED_GLASS:15)
B(3,1,2,STAINED_GLASS:15)
B(1,1,3,STAINED_GLASS:11)
B(2,1,3,STAINED_GLASS:11)
B(3,1,3,STAINED_GLASS:15)
B(4,1,3,STAINED_GLASS:11)
B(1,1,4,STAINED_GLASS:11)
B(2,1,4,STAINED_GLASS:11)
B(3,1,4,STAINED_GLASS:11)
B(4,1,4,STAINED_GLASS:11)
B(1,1,5,STAINED_GLASS:11)
B(2,1,5,STAINED_GLASS:11)
B(3,1,5,STAINED_GLASS:11)
B(4,1,5,STAINED_GLASS:11)
B(5,1,5,STAINED_GLASS:11)
B(6,1,5,STAINED_GLASS:11)
B(2,1,6,STAINED_GLASS:11)
B(3,1,6,STAINED_GLASS:15)
B(4,1,6,STAINED_GLASS:11)
B(5,1,6,STAINED_GLASS:11)
B(6,1,6,STAINED_GLASS:11)
B(7,1,6,STAINED_GLASS:11)
B(1,1,7,STAINED_GLASS:11)
B(2,1,7,STAINED_GLASS:15)
B(3,1,7,STAINED_GLASS:15)
B(4,1,7,STAINED_GLASS:11)
B(5,1,7,STAINED_GLASS:11)
B(6,1,7,STAINED_GLASS:11)
B(7,1,7,STAINED_GLASS:11)
B(1,1,8,STAINED_GLASS:11)
B(2,1,8,STAINED_GLASS:15)
B(3,1,8,STAINED_GLASS:15)
B(4,1,8,STAINED_GLASS:9)
B(5,1,8,STAINED_GLASS:11)
B(6,1,8,STAINED_GLASS:11)
B(7,1,8,STAINED_GLASS:11)
B(2,1,9,STAINED_GLASS:15)
B(3,1,9,STAINED_GLASS:15)
B(4,1,9,STAINED_GLASS:15)
B(5,1,9,STAINED_GLASS:15)
B(6,1,9,STAINED_GLASS:11)
B(7,1,9,STAINED_GLASS:11)
B(2,1,10,STAINED_GLASS:15)
B(3,1,10,STAINED_GLASS:15)
B(4,1,10,STAINED_GLASS:15)
B(1,2,0,STAINED_GLASS:11)
B(2,2,0,STAINED_GLASS:11)
B(0,2,1,STAINED_GLASS:11)
B(1,2,1,STAINED_GLASS:11)
B(2,2,1,STAINED_GLASS:11)
B(1,2,2,STAINED_GLASS:11)
B(2,2,2,STAINED_GLASS:11)
B(3,2,2,STAINED_GLASS:15)
B(1,2,3,STAINED_GLASS:11)
B(2,2,3,STAINED_GLASS:11)
B(3,2,3,STAINED_GLASS:15)
B(4,2,3,STAINED_GLASS:11)
B(1,2,4,STAINED_GLASS:11)
B(2,2,4,STAINED_GLASS:11)
B(3,2,4,STAINED_GLASS:11)
B(4,2,4,STAINED_GLASS:11)
B(1,2,5,STAINED_GLASS:11)
B(2,2,5,STAINED_GLASS:11)
B(3,2,5,STAINED_GLASS:11)
B(4,2,5,STAINED_GLASS:11)
B(5,2,5,STAINED_GLASS:11)
B(2,2,6,STAINED_GLASS:11)
B(3,2,6,STAINED_GLASS:15)
B(4,2,6,STAINED_GLASS:11)
B(5,2,6,STAINED_GLASS:11)
B(6,2,6,STAINED_GLASS:11)
B(1,2,7,STAINED_GLASS:15)
B(2,2,7,STAINED_GLASS:15)
B(3,2,7,STAINED_GLASS:15)
B(4,2,7,STAINED_GLASS:11)
B(5,2,7,STAINED_GLASS:11)
B(2,2,8,STAINED_GLASS:15)
B(3,2,8,STAINED_GLASS:15)
B(4,2,8,STAINED_GLASS:15)
B(1,3,0,STAINED_GLASS:11)
B(2,3,0,STAINED_GLASS:11)
B(0,3,1,STAINED_GLASS:11)
B(1,3,1,STAINED_GLASS:11)
B(2,3,1,STAINED_GLASS:11)
B(1,3,2,STAINED_GLASS:11)
B(2,3,2,STAINED_GLASS:11)
B(2,3,3,STAINED_GLASS:11)
B(3,3,3,STAINED_GLASS:15)
B(2,3,4,STAINED_GLASS:15)
B(3,3,4,STAINED_GLASS:15)
B(4,3,4,STAINED_GLASS:11)
B(2,3,5,STAINED_GLASS:15)
B(3,3,5,STAINED_GLASS:15)
B(4,3,5,STAINED_GLASS:11)
B(2,3,6,STAINED_GLASS:15)
B(3,3,6,STAINED_GLASS:15)
B(4,3,6,STAINED_GLASS:15)
B(5,3,6,STAINED_GLASS:11)
B(2,3,7,STAINED_GLASS:15)
B(1,4,0,STAINED_GLASS:9)
B(1,4,1,STAINED_GLASS:11)
B(2,4,3,STAINED_GLASS:15)
B(2,4,4,STAINED_GLASS:15)

#######################################################################
# +-----------------------------------------------------------------+ #
# |                             Branches                            | #
# +-----------------------------------------------------------------+ #
#######################################################################

BR(0,0,16,true,CEILING_SPIKE-SET-DIAG-THIN-05_0x1,NORTH,100,0)
