#######################################################################
# +-----------------------------------------------------------------+ #
# |                            BO3 object                           | #
# +-----------------------------------------------------------------+ #
#######################################################################

# This is the config file of a custom object.
# If you add this object correctly to your BiomeConfigs, it will spawn in the world.

# This is the creator of this BO3 object
Author: BO3 BulkEdit (by LanToaster)

# A short description of this BO3 object
Description: Bo3 spikes created by NLBlackEagle

# The BO3 version, don't change this! It can be used by external applications to do a version check.
Version: 3

# The settings mode, WriteAll, WriteWithoutComments or WriteDisable. See WorldConfig.
SettingsMode: WriteDisable


#######################################################################
# +-----------------------------------------------------------------+ #
# |                          Main settings                          | #
# +-----------------------------------------------------------------+ #
#######################################################################

# This needs to be set to true to spawn the object in the Tree and Sapling resources.
Tree: false

# The frequency of the BO3 from 1 to 200. Tries this many times to spawn this BO3 when using the CustomObject(...) resource.

Frequency: 10

# The rarity of the BO3 from 0 to 100. Each spawn attempt has rarity% chance to succeed when using the CustomObject(...) resource.

Rarity: 100

# If you set this to true, the BO3 will be placed with a random rotation.
RotateRandomly: true

# The spawn height of the BO3 - randomY, highestBlock or highestSolidBlock.
SpawnHeight: randomY

# The height limits for the BO3.
MinHeight: 70

MaxHeight: 170

# Objects can have other objects attacthed to it: branches. Branches can also
# have branches attached to it, which can also have branches, etc. This is the
# maximum branch depth for this objects.
MaxBranchDepth: 10

# When spawned with the UseWorld keyword, this BO3 should NOT spawn in the following biomes.
# If you writer.write the BO3 name directly in the BiomeConfigs, this will be ignored.
ExcludedBiomes: All


#######################################################################
# +-----------------------------------------------------------------+ #
# |                      Source block settings                      | #
# +-----------------------------------------------------------------+ #
#######################################################################

# The block(s) the BO3 should spawn in.
SourceBlocks: AIR

# The maximum percentage of the BO3 that can be outside the SourceBlock.
# The BO3 won't be placed on a location with more blocks outside the SourceBlock than this percentage.
MaxPercentageOutsideSourceBlock: 60

# What to do when a block is about to be placed outside the SourceBlock? (dontPlace, placeAnyway)
OutsideSourceBlock: placeAnyway


#######################################################################
# +-----------------------------------------------------------------+ #
# |                              Blocks                             | #
# +-----------------------------------------------------------------+ #
#######################################################################

# All the blocks used in the BO3 are listed here. Possible blocks:
# Block(x,y,z,id[.data][,nbtfile.nbt)
# RandomBlock(x,y,z,id[:data][,nbtfile.nbt],chance[,id[:data][,nbtfile.nbt],chance[,...]])
# So RandomBlock(0,0,0,CHEST,chest.nbt,50,CHEST,anotherchest.nbt,100) will spawn a chest at
# the BO3 origin, and give it a 50% chance to have the contents of chest.nbt, or, if that
# fails, a 100% percent chance to have the contents of anotherchest.nbt.
Block(-4,0,-7,STONE:0)
Block(-3,0,-7,STONE:0)
Block(-2,0,-7,STONE:0)
Block(-1,0,-7,STONE:0)
Block(0,0,-7,STONE:0)
Block(1,0,-7,STONE:0)
Block(2,0,-7,STONE:0)
Block(-4,0,-6,STONE:0)
Block(-3,0,-6,STONE:0)
Block(-2,0,-6,STONE:0)
Block(-1,0,-6,STONE:0)
Block(0,0,-6,STONE:0)
Block(1,0,-6,STONE:0)
Block(2,0,-6,STONE:0)
Block(3,0,-6,STONE:0)
Block(-6,0,-5,STONE:0)
Block(-5,0,-5,STONE:0)
Block(-4,0,-5,STONE:0)
Block(-3,0,-5,STONE:0)
Block(-2,0,-5,STONE:0)
Block(-1,0,-5,STONE:0)
Block(0,0,-5,STONE:0)
Block(1,0,-5,STONE:0)
Block(2,0,-5,STONE:0)
Block(3,0,-5,STONE:0)
Block(4,0,-5,STONE:0)
Block(5,0,-5,STONE:0)
Block(-6,0,-4,STONE:0)
Block(-5,0,-4,STONE:0)
Block(-4,0,-4,STONE:0)
Block(-3,0,-4,STONE:0)
Block(-2,0,-4,STONE:0)
Block(-1,0,-4,STONE:0)
Block(0,0,-4,STONE:0)
Block(1,0,-4,STONE:0)
Block(2,0,-4,STONE:0)
Block(3,0,-4,STONE:0)
Block(4,0,-4,STONE:0)
Block(5,0,-4,STONE:0)
Block(6,0,-4,STONE:0)
Block(-7,0,-3,STONE:0)
Block(-6,0,-3,STONE:0)
Block(-5,0,-3,STONE:0)
Block(-4,0,-3,STONE:0)
Block(-3,0,-3,STONE:0)
Block(-2,0,-3,STONE:0)
Block(-1,0,-3,STONE:0)
Block(0,0,-3,STONE:0)
Block(1,0,-3,STONE:0)
Block(2,0,-3,STONE:0)
Block(3,0,-3,STONE:0)
Block(4,0,-3,STONE:0)
Block(5,0,-3,STONE:0)
Block(6,0,-3,STONE:0)
Block(-8,0,-2,STONE:0)
Block(-7,0,-2,STONE:0)
Block(-6,0,-2,STONE:0)
Block(-5,0,-2,STONE:0)
Block(-4,0,-2,STONE:0)
Block(-3,0,-2,STONE:0)
Block(-2,0,-2,STONE:0)
Block(-1,0,-2,STONE:0)
Block(0,0,-2,STONE:0)
Block(1,0,-2,STONE:0)
Block(2,0,-2,STONE:0)
Block(3,0,-2,STONE:0)
Block(4,0,-2,STONE:0)
Block(5,0,-2,STONE:0)
Block(6,0,-2,STONE:0)
Block(-8,0,-1,STONE:0)
Block(-7,0,-1,STONE:0)
Block(-6,0,-1,STONE:0)
Block(-5,0,-1,STONE:0)
Block(-4,0,-1,STONE:0)
Block(-3,0,-1,STONE:0)
Block(-2,0,-1,STONE:0)
Block(-1,0,-1,STONE:0)
Block(0,0,-1,STONE:0)
Block(1,0,-1,STONE:0)
Block(2,0,-1,STONE:0)
Block(3,0,-1,STONE:0)
Block(4,0,-1,STONE:0)
Block(5,0,-1,STONE:0)
Block(6,0,-1,STONE:0)
Block(7,0,-1,STONE:0)
Block(-8,0,0,STONE:0)
Block(-7,0,0,STONE:0)
Block(-6,0,0,STONE:0)
Block(-5,0,0,STONE:0)
Block(-4,0,0,STONE:0)
Block(-3,0,0,STONE:0)
Block(-2,0,0,STONE:0)
Block(-1,0,0,STONE:0)
Block(0,0,0,STONE:0)
Block(1,0,0,STONE:0)
Block(2,0,0,STONE:0)
Block(3,0,0,STONE:0)
Block(4,0,0,STONE:0)
Block(5,0,0,STONE:0)
Block(6,0,0,STONE:0)
Block(7,0,0,STONE:0)
Block(-8,0,1,STONE:0)
Block(-7,0,1,STONE:0)
Block(-6,0,1,STONE:0)
Block(-5,0,1,STONE:0)
Block(-4,0,1,STONE:0)
Block(-3,0,1,STONE:0)
Block(-2,0,1,STONE:0)
Block(-1,0,1,STONE:0)
Block(0,0,1,STONE:0)
Block(1,0,1,STONE:0)
Block(2,0,1,STONE:0)
Block(3,0,1,STONE:0)
Block(4,0,1,STONE:0)
Block(5,0,1,STONE:0)
Block(6,0,1,STONE:0)
Block(7,0,1,STONE:0)
Block(-7,0,2,STONE:0)
Block(-6,0,2,STONE:0)
Block(-5,0,2,STONE:0)
Block(-4,0,2,STONE:0)
Block(-3,0,2,STONE:0)
Block(-2,0,2,STONE:0)
Block(-1,0,2,STONE:0)
Block(0,0,2,STONE:0)
Block(1,0,2,STONE:0)
Block(2,0,2,STONE:0)
Block(3,0,2,STONE:0)
Block(4,0,2,STONE:0)
Block(5,0,2,STONE:0)
Block(6,0,2,STONE:0)
Block(-6,0,3,STONE:0)
Block(-5,0,3,STONE:0)
Block(-4,0,3,STONE:0)
Block(-3,0,3,STONE:0)
Block(-2,0,3,STONE:0)
Block(-1,0,3,STONE:0)
Block(0,0,3,STONE:0)
Block(1,0,3,STONE:0)
Block(2,0,3,STONE:0)
Block(3,0,3,STONE:0)
Block(4,0,3,STONE:0)
Block(5,0,3,STONE:0)
Block(6,0,3,STONE:0)
Block(-6,0,4,STONE:0)
Block(-5,0,4,STONE:0)
Block(-4,0,4,STONE:0)
Block(-3,0,4,STONE:0)
Block(-2,0,4,STONE:0)
Block(-1,0,4,STONE:0)
Block(0,0,4,STONE:0)
Block(1,0,4,STONE:0)
Block(2,0,4,STONE:0)
Block(3,0,4,STONE:0)
Block(4,0,4,STONE:0)
Block(5,0,4,STONE:0)
Block(-5,0,5,STONE:0)
Block(-4,0,5,STONE:0)
Block(-3,0,5,STONE:0)
Block(-2,0,5,STONE:0)
Block(-1,0,5,STONE:0)
Block(0,0,5,STONE:0)
Block(1,0,5,STONE:0)
Block(2,0,5,STONE:0)
Block(3,0,5,STONE:0)
Block(4,0,5,STONE:0)
Block(5,0,5,STONE:0)
Block(-4,0,6,STONE:0)
Block(-3,0,6,STONE:0)
Block(-2,0,6,STONE:0)
Block(-1,0,6,STONE:0)
Block(0,0,6,STONE:0)
Block(1,0,6,STONE:0)
Block(2,0,6,STONE:0)
Block(3,0,6,STONE:0)
Block(-1,0,7,STONE:0)
Block(0,0,7,STONE:0)
Block(1,0,7,STONE:0)
Block(2,0,7,STONE:0)
Block(3,0,7,STONE:0)
Block(-2,1,-7,STONE:0)
Block(-1,1,-7,STONE:0)
Block(0,1,-7,STONE:0)
Block(-3,1,-6,STONE:0)
Block(-2,1,-6,STONE:0)
Block(-1,1,-6,STONE:0)
Block(0,1,-6,STONE:0)
Block(1,1,-6,STONE:0)
Block(2,1,-6,STONE:0)
Block(3,1,-6,STONE:0)
Block(-5,1,-5,STONE:0)
Block(-4,1,-5,STONE:0)
Block(-3,1,-5,STONE:0)
Block(-2,1,-5,STONE:0)
Block(-1,1,-5,STONE:0)
Block(0,1,-5,STONE:0)
Block(1,1,-5,STONE:0)
Block(2,1,-5,STONE:0)
Block(3,1,-5,STONE:0)
Block(4,1,-5,STONE:0)
Block(-5,1,-4,STONE:0)
Block(-4,1,-4,STONE:0)
Block(-3,1,-4,STONE:0)
Block(-2,1,-4,STONE:0)
Block(-1,1,-4,STONE:0)
Block(0,1,-4,STONE:0)
Block(1,1,-4,STONE:0)
Block(2,1,-4,STONE:0)
Block(3,1,-4,STONE:0)
Block(4,1,-4,STONE:0)
Block(5,1,-4,STONE:0)
Block(-6,1,-3,STONE:0)
Block(-5,1,-3,STONE:0)
Block(-4,1,-3,STONE:0)
Block(-3,1,-3,STONE:0)
Block(-2,1,-3,STONE:0)
Block(-1,1,-3,STONE:0)
Block(0,1,-3,STONE:0)
Block(1,1,-3,STONE:0)
Block(2,1,-3,STONE:0)
Block(3,1,-3,STONE:0)
Block(4,1,-3,STONE:0)
Block(5,1,-3,STONE:0)
Block(-7,1,-2,STONE:0)
Block(-6,1,-2,STONE:0)
Block(-5,1,-2,STONE:0)
Block(-4,1,-2,STONE:0)
Block(-3,1,-2,STONE:0)
Block(-2,1,-2,STONE:0)
Block(-1,1,-2,STONE:0)
Block(0,1,-2,STONE:0)
Block(1,1,-2,STONE:0)
Block(2,1,-2,STONE:0)
Block(3,1,-2,STONE:0)
Block(4,1,-2,STONE:0)
Block(5,1,-2,STONE:0)
Block(-7,1,-1,STONE:0)
Block(-6,1,-1,STONE:0)
Block(-5,1,-1,STONE:0)
Block(-4,1,-1,STONE:0)
Block(-3,1,-1,STONE:0)
Block(-2,1,-1,STONE:0)
Block(-1,1,-1,STONE:0)
Block(0,1,-1,STONE:0)
Block(1,1,-1,STONE:0)
Block(2,1,-1,STONE:0)
Block(3,1,-1,STONE:0)
Block(4,1,-1,STONE:0)
Block(5,1,-1,STONE:0)
Block(6,1,-1,STONE:0)
Block(-7,1,0,STONE:0)
Block(-6,1,0,STONE:0)
Block(-5,1,0,STONE:0)
Block(-4,1,0,STONE:0)
Block(-3,1,0,STONE:0)
Block(-2,1,0,STONE:0)
Block(-1,1,0,STONE:0)
Block(0,1,0,STONE:0)
Block(1,1,0,STONE:0)
Block(2,1,0,STONE:0)
Block(3,1,0,STONE:0)
Block(4,1,0,STONE:0)
Block(5,1,0,STONE:0)
Block(6,1,0,STONE:0)
Block(-7,1,1,STONE:0)
Block(-6,1,1,STONE:0)
Block(-5,1,1,STONE:0)
Block(-4,1,1,STONE:0)
Block(-3,1,1,STONE:0)
Block(-2,1,1,STONE:0)
Block(-1,1,1,STONE:0)
Block(0,1,1,STONE:0)
Block(1,1,1,STONE:0)
Block(2,1,1,STONE:0)
Block(3,1,1,STONE:0)
Block(4,1,1,STONE:0)
Block(5,1,1,STONE:0)
Block(6,1,1,STONE:0)
Block(-6,1,2,STONE:0)
Block(-5,1,2,STONE:0)
Block(-4,1,2,STONE:0)
Block(-3,1,2,STONE:0)
Block(-2,1,2,STONE:0)
Block(-1,1,2,STONE:0)
Block(0,1,2,STONE:0)
Block(1,1,2,STONE:0)
Block(2,1,2,STONE:0)
Block(3,1,2,STONE:0)
Block(4,1,2,STONE:0)
Block(5,1,2,STONE:0)
Block(-6,1,3,STONE:0)
Block(-5,1,3,STONE:0)
Block(-4,1,3,STONE:0)
Block(-3,1,3,STONE:0)
Block(-2,1,3,STONE:0)
Block(-1,1,3,STONE:0)
Block(0,1,3,STONE:0)
Block(1,1,3,STONE:0)
Block(2,1,3,STONE:0)
Block(3,1,3,STONE:0)
Block(4,1,3,STONE:0)
Block(5,1,3,STONE:0)
Block(-5,1,4,STONE:0)
Block(-4,1,4,STONE:0)
Block(-3,1,4,STONE:0)
Block(-2,1,4,STONE:0)
Block(-1,1,4,STONE:0)
Block(0,1,4,STONE:0)
Block(1,1,4,STONE:0)
Block(2,1,4,STONE:0)
Block(3,1,4,STONE:0)
Block(4,1,4,STONE:0)
Block(-4,1,5,STONE:0)
Block(-3,1,5,STONE:0)
Block(-2,1,5,STONE:0)
Block(-1,1,5,STONE:0)
Block(0,1,5,STONE:0)
Block(1,1,5,STONE:0)
Block(2,1,5,STONE:0)
Block(3,1,5,STONE:0)
Block(-4,1,6,STONE:0)
Block(-3,1,6,STONE:0)
Block(-2,1,6,STONE:0)
Block(-1,1,6,STONE:0)
Block(0,1,6,STONE:0)
Block(1,1,6,STONE:0)
Block(2,1,6,STONE:0)
Block(-3,2,-6,STONE:0)
Block(-2,2,-6,STONE:0)
Block(-1,2,-6,STONE:0)
Block(0,2,-6,STONE:0)
Block(1,2,-6,STONE:0)
Block(2,2,-6,STONE:0)
Block(-4,2,-5,STONE:0)
Block(-3,2,-5,STONE:0)
Block(-2,2,-5,STONE:0)
Block(-1,2,-5,STONE:0)
Block(0,2,-5,STONE:0)
Block(1,2,-5,STONE:0)
Block(2,2,-5,STONE:0)
Block(3,2,-5,STONE:0)
Block(-5,2,-4,STONE:0)
Block(-4,2,-4,STONE:0)
Block(-3,2,-4,STONE:0)
Block(-2,2,-4,STONE:0)
Block(-1,2,-4,STONE:0)
Block(0,2,-4,STONE:0)
Block(1,2,-4,STONE:0)
Block(2,2,-4,STONE:0)
Block(3,2,-4,STONE:0)
Block(4,2,-4,STONE:0)
Block(-5,2,-3,STONE:0)
Block(-4,2,-3,STONE:0)
Block(-3,2,-3,STONE:0)
Block(-2,2,-3,STONE:0)
Block(-1,2,-3,STONE:0)
Block(0,2,-3,STONE:0)
Block(1,2,-3,STONE:0)
Block(2,2,-3,STONE:0)
Block(3,2,-3,STONE:0)
Block(4,2,-3,STONE:0)
Block(5,2,-3,STONE:0)
Block(-7,2,-2,STONE:0)
Block(-6,2,-2,STONE:0)
Block(-5,2,-2,STONE:0)
Block(-4,2,-2,STONE:0)
Block(-3,2,-2,STONE:0)
Block(-2,2,-2,STONE:0)
Block(-1,2,-2,STONE:0)
Block(0,2,-2,STONE:0)
Block(1,2,-2,STONE:0)
Block(2,2,-2,STONE:0)
Block(3,2,-2,STONE:0)
Block(4,2,-2,STONE:0)
Block(5,2,-2,STONE:0)
Block(-7,2,-1,STONE:0)
Block(-6,2,-1,STONE:0)
Block(-5,2,-1,STONE:0)
Block(-4,2,-1,STONE:0)
Block(-3,2,-1,STONE:0)
Block(-2,2,-1,STONE:0)
Block(-1,2,-1,STONE:0)
Block(0,2,-1,STONE:0)
Block(1,2,-1,STONE:0)
Block(2,2,-1,STONE:0)
Block(3,2,-1,STONE:0)
Block(4,2,-1,STONE:0)
Block(5,2,-1,STONE:0)
Block(-7,2,0,STONE:0)
Block(-6,2,0,STONE:0)
Block(-5,2,0,STONE:0)
Block(-4,2,0,STONE:0)
Block(-3,2,0,STONE:0)
Block(-2,2,0,STONE:0)
Block(-1,2,0,STONE:0)
Block(0,2,0,STONE:0)
Block(1,2,0,STONE:0)
Block(2,2,0,STONE:0)
Block(3,2,0,STONE:0)
Block(4,2,0,STONE:0)
Block(5,2,0,STONE:0)
Block(-7,2,1,STONE:0)
Block(-6,2,1,STONE:0)
Block(-5,2,1,STONE:0)
Block(-4,2,1,STONE:0)
Block(-3,2,1,STONE:0)
Block(-2,2,1,STONE:0)
Block(-1,2,1,STONE:0)
Block(0,2,1,STONE:0)
Block(1,2,1,STONE:0)
Block(2,2,1,STONE:0)
Block(3,2,1,STONE:0)
Block(4,2,1,STONE:0)
Block(5,2,1,STONE:0)
Block(-6,2,2,STONE:0)
Block(-5,2,2,STONE:0)
Block(-4,2,2,STONE:0)
Block(-3,2,2,STONE:0)
Block(-2,2,2,STONE:0)
Block(-1,2,2,STONE:0)
Block(0,2,2,STONE:0)
Block(1,2,2,STONE:0)
Block(2,2,2,STONE:0)
Block(3,2,2,STONE:0)
Block(4,2,2,STONE:0)
Block(-6,2,3,STONE:0)
Block(-5,2,3,STONE:0)
Block(-4,2,3,STONE:0)
Block(-3,2,3,STONE:0)
Block(-2,2,3,STONE:0)
Block(-1,2,3,STONE:0)
Block(0,2,3,STONE:0)
Block(1,2,3,STONE:0)
Block(2,2,3,STONE:0)
Block(3,2,3,STONE:0)
Block(4,2,3,STONE:0)
Block(-5,2,4,STONE:0)
Block(-4,2,4,STONE:0)
Block(-3,2,4,STONE:0)
Block(-2,2,4,STONE:0)
Block(-1,2,4,STONE:0)
Block(0,2,4,STONE:0)
Block(1,2,4,STONE:0)
Block(2,2,4,STONE:0)
Block(3,2,4,STONE:0)
Block(-4,2,5,STONE:0)
Block(-3,2,5,STONE:0)
Block(-2,2,5,STONE:0)
Block(-1,2,5,STONE:0)
Block(0,2,5,STONE:0)
Block(1,2,5,STONE:0)
Block(2,2,5,STONE:0)
Block(-4,2,6,STONE:0)
Block(-3,2,6,STONE:0)
Block(-2,2,6,STONE:0)
Block(-1,2,6,STONE:0)
Block(0,2,6,STONE:0)
Block(-1,3,-6,STONE:0)
Block(0,3,-6,STONE:0)
Block(1,3,-6,STONE:0)
Block(-4,3,-5,STONE:0)
Block(-3,3,-5,STONE:0)
Block(-2,3,-5,STONE:0)
Block(-1,3,-5,STONE:0)
Block(0,3,-5,STONE:0)
Block(1,3,-5,STONE:0)
Block(2,3,-5,STONE:0)
Block(-5,3,-4,STONE:0)
Block(-4,3,-4,STONE:0)
Block(-3,3,-4,STONE:0)
Block(-2,3,-4,STONE:0)
Block(-1,3,-4,STONE:0)
Block(0,3,-4,STONE:0)
Block(1,3,-4,STONE:0)
Block(2,3,-4,STONE:0)
Block(3,3,-4,STONE:0)
Block(-5,3,-3,STONE:0)
Block(-4,3,-3,STONE:0)
Block(-3,3,-3,STONE:0)
Block(-2,3,-3,STONE:0)
Block(-1,3,-3,STONE:0)
Block(0,3,-3,STONE:0)
Block(1,3,-3,STONE:0)
Block(2,3,-3,STONE:0)
Block(3,3,-3,STONE:0)
Block(4,3,-3,STONE:0)
Block(-5,3,-2,STONE:0)
Block(-4,3,-2,STONE:0)
Block(-3,3,-2,STONE:0)
Block(-2,3,-2,STONE:0)
Block(-1,3,-2,STONE:0)
Block(0,3,-2,STONE:0)
Block(1,3,-2,STONE:0)
Block(2,3,-2,STONE:0)
Block(3,3,-2,STONE:0)
Block(4,3,-2,STONE:0)
Block(5,3,-2,STONE:0)
Block(-6,3,-1,STONE:0)
Block(-5,3,-1,STONE:0)
Block(-4,3,-1,STONE:0)
Block(-3,3,-1,STONE:0)
Block(-2,3,-1,STONE:0)
Block(-1,3,-1,STONE:0)
Block(0,3,-1,STONE:0)
Block(1,3,-1,STONE:0)
Block(2,3,-1,STONE:0)
Block(3,3,-1,STONE:0)
Block(4,3,-1,STONE:0)
Block(5,3,-1,STONE:0)
Block(-6,3,0,STONE:0)
Block(-5,3,0,STONE:0)
Block(-4,3,0,STONE:0)
Block(-3,3,0,STONE:0)
Block(-2,3,0,STONE:0)
Block(-1,3,0,STONE:0)
Block(0,3,0,STONE:0)
Block(1,3,0,STONE:0)
Block(2,3,0,STONE:0)
Block(3,3,0,STONE:0)
Block(4,3,0,STONE:0)
Block(5,3,0,STONE:0)
Block(-6,3,1,STONE:0)
Block(-5,3,1,STONE:0)
Block(-4,3,1,STONE:0)
Block(-3,3,1,STONE:0)
Block(-2,3,1,STONE:0)
Block(-1,3,1,STONE:0)
Block(0,3,1,STONE:0)
Block(1,3,1,STONE:0)
Block(2,3,1,STONE:0)
Block(3,3,1,STONE:0)
Block(4,3,1,STONE:0)
Block(5,3,1,STONE:0)
Block(-6,3,2,STONE:0)
Block(-5,3,2,STONE:0)
Block(-4,3,2,STONE:0)
Block(-3,3,2,STONE:0)
Block(-2,3,2,STONE:0)
Block(-1,3,2,STONE:0)
Block(0,3,2,STONE:0)
Block(1,3,2,STONE:0)
Block(2,3,2,STONE:0)
Block(3,3,2,STONE:0)
Block(4,3,2,STONE:0)
Block(5,3,2,STONE:0)
Block(-5,3,3,STONE:0)
Block(-4,3,3,STONE:0)
Block(-3,3,3,STONE:0)
Block(-2,3,3,STONE:0)
Block(-1,3,3,STONE:0)
Block(0,3,3,STONE:0)
Block(1,3,3,STONE:0)
Block(2,3,3,STONE:0)
Block(3,3,3,STONE:0)
Block(4,3,3,STONE:0)
Block(-4,3,4,STONE:0)
Block(-3,3,4,STONE:0)
Block(-2,3,4,STONE:0)
Block(-1,3,4,STONE:0)
Block(0,3,4,STONE:0)
Block(1,3,4,STONE:0)
Block(2,3,4,STONE:0)
Block(3,3,4,STONE:0)
Block(-4,3,5,STONE:0)
Block(-3,3,5,STONE:0)
Block(-2,3,5,STONE:0)
Block(-1,3,5,STONE:0)
Block(0,3,5,STONE:0)
Block(-3,3,6,STONE:0)
Block(0,3,6,STONE:0)
Block(-4,4,-5,STONE:0)
Block(-3,4,-5,STONE:0)
Block(-2,4,-5,STONE:0)
Block(-1,4,-5,STONE:0)
Block(0,4,-5,STONE:0)
Block(1,4,-5,STONE:0)
Block(2,4,-5,STONE:0)
Block(-5,4,-4,STONE:0)
Block(-4,4,-4,STONE:0)
Block(-3,4,-4,STONE:0)
Block(-2,4,-4,STONE:0)
Block(-1,4,-4,STONE:0)
Block(0,4,-4,STONE:0)
Block(1,4,-4,STONE:0)
Block(2,4,-4,STONE:0)
Block(3,4,-4,STONE:0)
Block(-5,4,-3,STONE:0)
Block(-4,4,-3,STONE:0)
Block(-3,4,-3,STONE:0)
Block(-2,4,-3,STONE:0)
Block(-1,4,-3,STONE:0)
Block(0,4,-3,STONE:0)
Block(1,4,-3,STONE:0)
Block(2,4,-3,STONE:0)
Block(3,4,-3,STONE:0)
Block(4,4,-3,STONE:0)
Block(-5,4,-2,STONE:0)
Block(-4,4,-2,STONE:0)
Block(-3,4,-2,STONE:0)
Block(-2,4,-2,STONE:0)
Block(-1,4,-2,STONE:0)
Block(0,4,-2,STONE:0)
Block(1,4,-2,STONE:0)
Block(2,4,-2,STONE:0)
Block(3,4,-2,STONE:0)
Block(4,4,-2,STONE:0)
Block(-5,4,-1,STONE:0)
Block(-4,4,-1,STONE:0)
Block(-3,4,-1,STONE:0)
Block(-2,4,-1,STONE:0)
Block(-1,4,-1,STONE:0)
Block(0,4,-1,STONE:0)
Block(1,4,-1,STONE:0)
Block(2,4,-1,STONE:0)
Block(3,4,-1,STONE:0)
Block(4,4,-1,STONE:0)
Block(5,4,-1,STONE:0)
Block(-6,4,0,STONE:0)
Block(-5,4,0,STONE:0)
Block(-4,4,0,STONE:0)
Block(-3,4,0,STONE:0)
Block(-2,4,0,STONE:0)
Block(-1,4,0,STONE:0)
Block(0,4,0,STONE:0)
Block(1,4,0,STONE:0)
Block(2,4,0,STONE:0)
Block(3,4,0,STONE:0)
Block(4,4,0,STONE:0)
Block(-5,4,1,STONE:0)
Block(-4,4,1,STONE:0)
Block(-3,4,1,STONE:0)
Block(-2,4,1,STONE:0)
Block(-1,4,1,STONE:0)
Block(0,4,1,STONE:0)
Block(1,4,1,STONE:0)
Block(2,4,1,STONE:0)
Block(3,4,1,STONE:0)
Block(4,4,1,STONE:0)
Block(5,4,1,STONE:0)
Block(-6,4,2,STONE:0)
Block(-5,4,2,STONE:0)
Block(-4,4,2,STONE:0)
Block(-3,4,2,STONE:0)
Block(-2,4,2,STONE:0)
Block(-1,4,2,STONE:0)
Block(0,4,2,STONE:0)
Block(1,4,2,STONE:0)
Block(2,4,2,STONE:0)
Block(3,4,2,STONE:0)
Block(4,4,2,STONE:0)
Block(-5,4,3,STONE:0)
Block(-4,4,3,STONE:0)
Block(-3,4,3,STONE:0)
Block(-2,4,3,STONE:0)
Block(-1,4,3,STONE:0)
Block(0,4,3,STONE:0)
Block(1,4,3,STONE:0)
Block(2,4,3,STONE:0)
Block(3,4,3,STONE:0)
Block(-4,4,4,STONE:0)
Block(-3,4,4,STONE:0)
Block(-2,4,4,STONE:0)
Block(-1,4,4,STONE:0)
Block(0,4,4,STONE:0)
Block(1,4,4,STONE:0)
Block(2,4,4,STONE:0)
Block(3,4,4,STONE:0)
Block(-4,4,5,STONE:0)
Block(-3,4,5,STONE:0)
Block(-2,4,5,STONE:0)
Block(-1,4,5,STONE:0)
Block(0,4,5,STONE:0)
Block(1,4,5,STONE:0)
Block(-4,5,-5,STONE:0)
Block(-3,5,-5,STONE:0)
Block(-2,5,-5,STONE:0)
Block(-1,5,-5,STONE:0)
Block(0,5,-5,STONE:0)
Block(1,5,-5,STONE:0)
Block(-4,5,-4,STONE:0)
Block(-3,5,-4,STONE:0)
Block(-2,5,-4,STONE:0)
Block(-1,5,-4,STONE:0)
Block(0,5,-4,STONE:0)
Block(1,5,-4,STONE:0)
Block(2,5,-4,STONE:0)
Block(-5,5,-3,STONE:0)
Block(-4,5,-3,STONE:0)
Block(-3,5,-3,STONE:0)
Block(-2,5,-3,STONE:0)
Block(-1,5,-3,STONE:0)
Block(0,5,-3,STONE:0)
Block(1,5,-3,STONE:0)
Block(2,5,-3,STONE:0)
Block(3,5,-3,STONE:0)
Block(-5,5,-2,STONE:0)
Block(-4,5,-2,STONE:0)
Block(-3,5,-2,STONE:0)
Block(-2,5,-2,STONE:0)
Block(-1,5,-2,STONE:0)
Block(0,5,-2,STONE:0)
Block(1,5,-2,STONE:0)
Block(2,5,-2,STONE:0)
Block(3,5,-2,STONE:0)
Block(4,5,-2,STONE:0)
Block(-5,5,-1,STONE:0)
Block(-4,5,-1,STONE:0)
Block(-3,5,-1,STONE:0)
Block(-2,5,-1,STONE:0)
Block(-1,5,-1,STONE:0)
Block(0,5,-1,STONE:0)
Block(1,5,-1,STONE:0)
Block(2,5,-1,STONE:0)
Block(3,5,-1,STONE:0)
Block(4,5,-1,STONE:0)
Block(-6,5,0,STONE:0)
Block(-5,5,0,STONE:0)
Block(-4,5,0,STONE:0)
Block(-3,5,0,STONE:0)
Block(-2,5,0,STONE:0)
Block(-1,5,0,STONE:0)
Block(0,5,0,STONE:0)
Block(1,5,0,STONE:0)
Block(2,5,0,STONE:0)
Block(3,5,0,STONE:0)
Block(4,5,0,STONE:0)
Block(-5,5,1,STONE:0)
Block(-4,5,1,STONE:0)
Block(-3,5,1,STONE:0)
Block(-2,5,1,STONE:0)
Block(-1,5,1,STONE:0)
Block(0,5,1,STONE:0)
Block(1,5,1,STONE:0)
Block(2,5,1,STONE:0)
Block(3,5,1,STONE:0)
Block(4,5,1,STONE:0)
Block(-5,5,2,STONE:0)
Block(-4,5,2,STONE:0)
Block(-3,5,2,STONE:0)
Block(-2,5,2,STONE:0)
Block(-1,5,2,STONE:0)
Block(0,5,2,STONE:0)
Block(1,5,2,STONE:0)
Block(2,5,2,STONE:0)
Block(3,5,2,STONE:0)
Block(4,5,2,STONE:0)
Block(-5,5,3,STONE:0)
Block(-4,5,3,STONE:0)
Block(-3,5,3,STONE:0)
Block(-2,5,3,STONE:0)
Block(-1,5,3,STONE:0)
Block(0,5,3,STONE:0)
Block(1,5,3,STONE:0)
Block(2,5,3,STONE:0)
Block(3,5,3,STONE:0)
Block(-4,5,4,STONE:0)
Block(-3,5,4,STONE:0)
Block(-2,5,4,STONE:0)
Block(-1,5,4,STONE:0)
Block(0,5,4,STONE:0)
Block(1,5,4,STONE:0)
Block(2,5,4,STONE:0)
Block(3,5,4,STONE:0)
Block(-3,5,5,STONE:0)
Block(-2,5,5,STONE:0)
Block(-1,5,5,STONE:0)
Block(0,5,5,STONE:0)
Block(-3,6,-5,STONE:0)
Block(-2,6,-5,STONE:0)
Block(-1,6,-5,STONE:0)
Block(0,6,-5,STONE:0)
Block(1,6,-5,STONE:0)
Block(-4,6,-4,STONE:0)
Block(-3,6,-4,STONE:0)
Block(-2,6,-4,STONE:0)
Block(-1,6,-4,STONE:0)
Block(0,6,-4,STONE:0)
Block(1,6,-4,STONE:0)
Block(2,6,-4,STONE:0)
Block(-4,6,-3,STONE:0)
Block(-3,6,-3,STONE:0)
Block(-2,6,-3,STONE:0)
Block(-1,6,-3,STONE:0)
Block(0,6,-3,STONE:0)
Block(1,6,-3,STONE:0)
Block(2,6,-3,STONE:0)
Block(3,6,-3,STONE:0)
Block(4,6,-3,STONE:0)
Block(-5,6,-2,STONE:0)
Block(-4,6,-2,STONE:0)
Block(-3,6,-2,STONE:0)
Block(-2,6,-2,STONE:0)
Block(-1,6,-2,STONE:0)
Block(0,6,-2,STONE:0)
Block(1,6,-2,STONE:0)
Block(2,6,-2,STONE:0)
Block(3,6,-2,STONE:0)
Block(4,6,-2,STONE:0)
Block(-5,6,-1,STONE:0)
Block(-4,6,-1,STONE:0)
Block(-3,6,-1,STONE:0)
Block(-2,6,-1,STONE:0)
Block(-1,6,-1,STONE:0)
Block(0,6,-1,STONE:0)
Block(1,6,-1,STONE:0)
Block(2,6,-1,STONE:0)
Block(3,6,-1,STONE:0)
Block(4,6,-1,STONE:0)
Block(-5,6,0,STONE:0)
Block(-4,6,0,STONE:0)
Block(-3,6,0,STONE:0)
Block(-2,6,0,STONE:0)
Block(-1,6,0,STONE:0)
Block(0,6,0,STONE:0)
Block(1,6,0,STONE:0)
Block(2,6,0,STONE:0)
Block(3,6,0,STONE:0)
Block(4,6,0,STONE:0)
Block(-5,6,1,STONE:0)
Block(-4,6,1,STONE:0)
Block(-3,6,1,STONE:0)
Block(-2,6,1,STONE:0)
Block(-1,6,1,STONE:0)
Block(0,6,1,STONE:0)
Block(1,6,1,STONE:0)
Block(2,6,1,STONE:0)
Block(3,6,1,STONE:0)
Block(4,6,1,STONE:0)
Block(-5,6,2,STONE:0)
Block(-4,6,2,STONE:0)
Block(-3,6,2,STONE:0)
Block(-2,6,2,STONE:0)
Block(-1,6,2,STONE:0)
Block(0,6,2,STONE:0)
Block(1,6,2,STONE:0)
Block(2,6,2,STONE:0)
Block(3,6,2,STONE:0)
Block(4,6,2,STONE:0)
Block(-5,6,3,STONE:0)
Block(-4,6,3,STONE:0)
Block(-3,6,3,STONE:0)
Block(-2,6,3,STONE:0)
Block(-1,6,3,STONE:0)
Block(0,6,3,STONE:0)
Block(1,6,3,STONE:0)
Block(2,6,3,STONE:0)
Block(3,6,3,STONE:0)
Block(-4,6,4,STONE:0)
Block(-3,6,4,STONE:0)
Block(-2,6,4,STONE:0)
Block(-1,6,4,STONE:0)
Block(0,6,4,STONE:0)
Block(1,6,4,STONE:0)
Block(2,6,4,STONE:0)
Block(-3,6,5,STONE:0)
Block(-2,6,5,STONE:0)
Block(-1,6,5,STONE:0)
Block(0,6,5,STONE:0)
Block(-2,7,-5,STONE:0)
Block(-1,7,-5,STONE:0)
Block(0,7,-5,STONE:0)
Block(1,7,-5,STONE:0)
Block(-4,7,-4,STONE:0)
Block(-3,7,-4,STONE:0)
Block(-2,7,-4,STONE:0)
Block(-1,7,-4,STONE:0)
Block(0,7,-4,STONE:0)
Block(1,7,-4,STONE:0)
Block(2,7,-4,STONE:0)
Block(-4,7,-3,STONE:0)
Block(-3,7,-3,STONE:0)
Block(-2,7,-3,STONE:0)
Block(-1,7,-3,STONE:0)
Block(0,7,-3,STONE:0)
Block(1,7,-3,STONE:0)
Block(2,7,-3,STONE:0)
Block(3,7,-3,STONE:0)
Block(-4,7,-2,STONE:0)
Block(-3,7,-2,STONE:0)
Block(-2,7,-2,STONE:0)
Block(-1,7,-2,STONE:0)
Block(0,7,-2,STONE:0)
Block(1,7,-2,STONE:0)
Block(2,7,-2,STONE:0)
Block(3,7,-2,STONE:0)
Block(4,7,-2,STONE:0)
Block(-5,7,-1,STONE:0)
Block(-4,7,-1,STONE:0)
Block(-3,7,-1,STONE:0)
Block(-2,7,-1,STONE:0)
Block(-1,7,-1,STONE:0)
Block(0,7,-1,STONE:0)
Block(1,7,-1,STONE:0)
Block(2,7,-1,STONE:0)
Block(3,7,-1,STONE:0)
Block(4,7,-1,STONE:0)
Block(-5,7,0,STONE:0)
Block(-4,7,0,STONE:0)
Block(-3,7,0,STONE:0)
Block(-2,7,0,STONE:0)
Block(-1,7,0,STONE:0)
Block(0,7,0,STONE:0)
Block(1,7,0,STONE:0)
Block(2,7,0,STONE:0)
Block(3,7,0,STONE:0)
Block(4,7,0,STONE:0)
Block(-5,7,1,STONE:0)
Block(-4,7,1,STONE:0)
Block(-3,7,1,STONE:0)
Block(-2,7,1,STONE:0)
Block(-1,7,1,STONE:0)
Block(0,7,1,STONE:0)
Block(1,7,1,STONE:0)
Block(2,7,1,STONE:0)
Block(3,7,1,STONE:0)
Block(4,7,1,STONE:0)
Block(-4,7,2,STONE:0)
Block(-3,7,2,STONE:0)
Block(-2,7,2,STONE:0)
Block(-1,7,2,STONE:0)
Block(0,7,2,STONE:0)
Block(1,7,2,STONE:0)
Block(2,7,2,STONE:0)
Block(3,7,2,STONE:0)
Block(4,7,2,STONE:0)
Block(-4,7,3,STONE:0)
Block(-3,7,3,STONE:0)
Block(-2,7,3,STONE:0)
Block(-1,7,3,STONE:0)
Block(0,7,3,STONE:0)
Block(1,7,3,STONE:0)
Block(2,7,3,STONE:0)
Block(3,7,3,STONE:0)
Block(-4,7,4,STONE:0)
Block(-3,7,4,STONE:0)
Block(-2,7,4,STONE:0)
Block(-1,7,4,STONE:0)
Block(0,7,4,STONE:0)
Block(1,7,4,STONE:0)
Block(2,7,4,STONE:0)
Block(-2,7,5,STONE:0)
Block(-2,8,-5,STONE:0)
Block(-1,8,-5,STONE:0)
Block(0,8,-5,STONE:0)
Block(-4,8,-4,STONE:0)
Block(-3,8,-4,STONE:0)
Block(-2,8,-4,STONE:0)
Block(-1,8,-4,STONE:0)
Block(0,8,-4,STONE:0)
Block(1,8,-4,STONE:0)
Block(-4,8,-3,STONE:0)
Block(-3,8,-3,STONE:0)
Block(-2,8,-3,STONE:0)
Block(-1,8,-3,STONE:0)
Block(0,8,-3,STONE:0)
Block(1,8,-3,STONE:0)
Block(2,8,-3,STONE:0)
Block(3,8,-3,STONE:0)
Block(-4,8,-2,STONE:0)
Block(-3,8,-2,STONE:0)
Block(-2,8,-2,STONE:0)
Block(-1,8,-2,STONE:0)
Block(0,8,-2,STONE:0)
Block(1,8,-2,STONE:0)
Block(2,8,-2,STONE:0)
Block(3,8,-2,STONE:0)
Block(-5,8,-1,STONE:0)
Block(-4,8,-1,STONE:0)
Block(-3,8,-1,STONE:0)
Block(-2,8,-1,STONE:0)
Block(-1,8,-1,STONE:0)
Block(0,8,-1,STONE:0)
Block(1,8,-1,STONE:0)
Block(2,8,-1,STONE:0)
Block(3,8,-1,STONE:0)
Block(-4,8,0,STONE:0)
Block(-3,8,0,STONE:0)
Block(-2,8,0,STONE:0)
Block(-1,8,0,STONE:0)
Block(0,8,0,STONE:0)
Block(1,8,0,STONE:0)
Block(2,8,0,STONE:0)
Block(3,8,0,STONE:0)
Block(4,8,0,STONE:0)
Block(-4,8,1,STONE:0)
Block(-3,8,1,STONE:0)
Block(-2,8,1,STONE:0)
Block(-1,8,1,STONE:0)
Block(0,8,1,STONE:0)
Block(1,8,1,STONE:0)
Block(2,8,1,STONE:0)
Block(3,8,1,STONE:0)
Block(4,8,1,STONE:0)
Block(-4,8,2,STONE:0)
Block(-3,8,2,STONE:0)
Block(-2,8,2,STONE:0)
Block(-1,8,2,STONE:0)
Block(0,8,2,STONE:0)
Block(1,8,2,STONE:0)
Block(2,8,2,STONE:0)
Block(3,8,2,STONE:0)
Block(4,8,2,STONE:0)
Block(-4,8,3,STONE:0)
Block(-3,8,3,STONE:0)
Block(-2,8,3,STONE:0)
Block(-1,8,3,STONE:0)
Block(0,8,3,STONE:0)
Block(1,8,3,STONE:0)
Block(2,8,3,STONE:0)
Block(3,8,3,STONE:0)
Block(-3,8,4,STONE:0)
Block(-2,8,4,STONE:0)
Block(-1,8,4,STONE:0)
Block(0,8,4,STONE:0)
Block(1,8,4,STONE:0)
Block(-2,9,-5,STONE:0)
Block(-1,9,-5,STONE:0)
Block(0,9,-5,STONE:0)
Block(-3,9,-4,STONE:0)
Block(-2,9,-4,STONE:0)
Block(-1,9,-4,STONE:0)
Block(0,9,-4,STONE:0)
Block(1,9,-4,STONE:0)
Block(-4,9,-3,STONE:0)
Block(-3,9,-3,STONE:0)
Block(-2,9,-3,STONE:0)
Block(-1,9,-3,STONE:0)
Block(0,9,-3,STONE:0)
Block(1,9,-3,STONE:0)
Block(2,9,-3,STONE:0)
Block(3,9,-3,STONE:0)
Block(-4,9,-2,STONE:0)
Block(-3,9,-2,STONE:0)
Block(-2,9,-2,STONE:0)
Block(-1,9,-2,STONE:0)
Block(0,9,-2,STONE:0)
Block(1,9,-2,STONE:0)
Block(2,9,-2,STONE:0)
Block(3,9,-2,STONE:0)
Block(-4,9,-1,STONE:0)
Block(-3,9,-1,STONE:0)
Block(-2,9,-1,STONE:0)
Block(-1,9,-1,STONE:0)
Block(0,9,-1,STONE:0)
Block(1,9,-1,STONE:0)
Block(2,9,-1,STONE:0)
Block(3,9,-1,STONE:0)
Block(-4,9,0,STONE:0)
Block(-3,9,0,STONE:0)
Block(-2,9,0,STONE:0)
Block(-1,9,0,STONE:0)
Block(0,9,0,STONE:0)
Block(1,9,0,STONE:0)
Block(2,9,0,STONE:0)
Block(3,9,0,STONE:0)
Block(4,9,0,STONE:0)
Block(-4,9,1,STONE:0)
Block(-3,9,1,STONE:0)
Block(-2,9,1,STONE:0)
Block(-1,9,1,STONE:0)
Block(0,9,1,STONE:0)
Block(1,9,1,STONE:0)
Block(2,9,1,STONE:0)
Block(3,9,1,STONE:0)
Block(4,9,1,STONE:0)
Block(-4,9,2,STONE:0)
Block(-3,9,2,STONE:0)
Block(-2,9,2,STONE:0)
Block(-1,9,2,STONE:0)
Block(0,9,2,STONE:0)
Block(1,9,2,STONE:0)
Block(2,9,2,STONE:0)
Block(3,9,2,STONE:0)
Block(-4,9,3,STONE:0)
Block(-3,9,3,STONE:0)
Block(-2,9,3,STONE:0)
Block(-1,9,3,STONE:0)
Block(0,9,3,STONE:0)
Block(1,9,3,STONE:0)
Block(2,9,3,STONE:0)
Block(-3,9,4,STONE:0)
Block(-2,9,4,STONE:0)
Block(-1,9,4,STONE:0)
Block(0,9,4,STONE:0)
Block(1,9,4,STONE:0)
Block(-1,10,-5,STONE:0)
Block(-3,10,-4,STONE:0)
Block(-2,10,-4,STONE:0)
Block(-1,10,-4,STONE:0)
Block(0,10,-4,STONE:0)
Block(1,10,-4,STONE:0)
Block(-3,10,-3,STONE:0)
Block(-2,10,-3,STONE:0)
Block(-1,10,-3,STONE:0)
Block(0,10,-3,STONE:0)
Block(1,10,-3,STONE:0)
Block(2,10,-3,STONE:0)
Block(-3,10,-2,STONE:0)
Block(-2,10,-2,STONE:0)
Block(-1,10,-2,STONE:0)
Block(0,10,-2,STONE:0)
Block(1,10,-2,STONE:0)
Block(2,10,-2,STONE:0)
Block(3,10,-2,STONE:0)
Block(-4,10,-1,STONE:0)
Block(-3,10,-1,STONE:0)
Block(-2,10,-1,STONE:0)
Block(-1,10,-1,STONE:0)
Block(0,10,-1,STONE:0)
Block(1,10,-1,STONE:0)
Block(2,10,-1,STONE:0)
Block(3,10,-1,STONE:0)
Block(-4,10,0,STONE:0)
Block(-3,10,0,STONE:0)
Block(-2,10,0,STONE:0)
Block(-1,10,0,STONE:0)
Block(0,10,0,STONE:0)
Block(1,10,0,STONE:0)
Block(2,10,0,STONE:0)
Block(3,10,0,STONE:0)
Block(-4,10,1,STONE:0)
Block(-3,10,1,STONE:0)
Block(-2,10,1,STONE:0)
Block(-1,10,1,STONE:0)
Block(0,10,1,STONE:0)
Block(1,10,1,STONE:0)
Block(2,10,1,STONE:0)
Block(3,10,1,STONE:0)
Block(4,10,1,STONE:0)
Block(-3,10,2,STONE:0)
Block(-2,10,2,STONE:0)
Block(-1,10,2,STONE:0)
Block(0,10,2,STONE:0)
Block(1,10,2,STONE:0)
Block(2,10,2,STONE:0)
Block(3,10,2,STONE:0)
Block(-3,10,3,STONE:0)
Block(-2,10,3,STONE:0)
Block(-1,10,3,STONE:0)
Block(0,10,3,STONE:0)
Block(1,10,3,STONE:0)
Block(2,10,3,STONE:0)
Block(-1,10,4,STONE:0)
Block(-2,11,-4,STONE:0)
Block(-1,11,-4,STONE:0)
Block(0,11,-4,STONE:0)
Block(-2,11,-3,STONE:0)
Block(-1,11,-3,STONE:0)
Block(0,11,-3,STONE:0)
Block(1,11,-3,STONE:0)
Block(2,11,-3,STONE:0)
Block(-3,11,-2,STONE:0)
Block(-2,11,-2,STONE:0)
Block(-1,11,-2,STONE:0)
Block(0,11,-2,STONE:0)
Block(1,11,-2,STONE:0)
Block(2,11,-2,STONE:0)
Block(-4,11,-1,STONE:0)
Block(-3,11,-1,STONE:0)
Block(-2,11,-1,STONE:0)
Block(-1,11,-1,STONE:0)
Block(0,11,-1,STONE:0)
Block(1,11,-1,STONE:0)
Block(2,11,-1,STONE:0)
Block(-4,11,0,STONE:0)
Block(-3,11,0,STONE:0)
Block(-2,11,0,STONE:0)
Block(-1,11,0,STONE:0)
Block(0,11,0,STONE:0)
Block(1,11,0,STONE:0)
Block(2,11,0,STONE:0)
Block(3,11,0,STONE:0)
Block(-3,11,1,STONE:0)
Block(-2,11,1,STONE:0)
Block(-1,11,1,STONE:0)
Block(0,11,1,STONE:0)
Block(1,11,1,STONE:0)
Block(2,11,1,STONE:0)
Block(3,11,1,STONE:0)
Block(-3,11,2,STONE:0)
Block(-2,11,2,STONE:0)
Block(-1,11,2,STONE:0)
Block(0,11,2,STONE:0)
Block(1,11,2,STONE:0)
Block(2,11,2,STONE:0)
Block(-2,11,3,STONE:0)
Block(-1,11,3,STONE:0)
Block(0,11,3,STONE:0)
Block(1,11,3,STONE:0)
Block(-2,12,-3,STONE:0)
Block(-1,12,-3,STONE:0)
Block(0,12,-3,STONE:0)
Block(1,12,-3,STONE:0)
Block(-3,12,-2,STONE:0)
Block(-2,12,-2,STONE:0)
Block(-1,12,-2,STONE:0)
Block(0,12,-2,STONE:0)
Block(1,12,-2,STONE:0)
Block(2,12,-2,STONE:0)
Block(-4,12,-1,STONE:0)
Block(-3,12,-1,STONE:0)
Block(-2,12,-1,STONE:0)
Block(-1,12,-1,STONE:0)
Block(0,12,-1,STONE:0)
Block(1,12,-1,STONE:0)
Block(2,12,-1,STONE:0)
Block(-4,12,0,STONE:0)
Block(-3,12,0,STONE:0)
Block(-2,12,0,STONE:0)
Block(-1,12,0,STONE:0)
Block(0,12,0,STONE:0)
Block(1,12,0,STONE:0)
Block(2,12,0,STONE:0)
Block(3,12,0,STONE:0)
Block(-4,12,1,STONE:0)
Block(-3,12,1,STONE:0)
Block(-2,12,1,STONE:0)
Block(-1,12,1,STONE:0)
Block(0,12,1,STONE:0)
Block(1,12,1,STONE:0)
Block(2,12,1,STONE:0)
Block(3,12,1,STONE:0)
Block(-3,12,2,STONE:0)
Block(-2,12,2,STONE:0)
Block(-1,12,2,STONE:0)
Block(0,12,2,STONE:0)
Block(1,12,2,STONE:0)
Block(2,12,2,STONE:0)
Block(0,12,3,STONE:0)
Block(-2,13,-3,STONE:0)
Block(-3,13,-2,STONE:0)
Block(-2,13,-2,STONE:0)
Block(-1,13,-2,STONE:0)
Block(0,13,-2,STONE:0)
Block(1,13,-2,STONE:0)
Block(-4,13,-1,STONE:0)
Block(-3,13,-1,STONE:0)
Block(-2,13,-1,STONE:0)
Block(-1,13,-1,STONE:0)
Block(0,13,-1,STONE:0)
Block(1,13,-1,STONE:0)
Block(2,13,-1,STONE:0)
Block(-4,13,0,STONE:0)
Block(-3,13,0,STONE:0)
Block(-2,13,0,STONE:0)
Block(-1,13,0,STONE:0)
Block(0,13,0,STONE:0)
Block(1,13,0,STONE:0)
Block(2,13,0,STONE:0)
Block(-3,13,1,STONE:0)
Block(-2,13,1,STONE:0)
Block(-1,13,1,STONE:0)
Block(0,13,1,STONE:0)
Block(1,13,1,STONE:0)
Block(2,13,1,STONE:0)
Block(-2,13,2,STONE:0)
Block(-1,13,2,STONE:0)
Block(0,13,2,STONE:0)
Block(1,13,2,STONE:0)
Block(2,13,2,STONE:0)
Block(-2,14,-3,STONE:0)
Block(-3,14,-2,STONE:0)
Block(-2,14,-2,STONE:0)
Block(-1,14,-2,STONE:0)
Block(0,14,-2,STONE:0)
Block(1,14,-2,STONE:0)
Block(2,14,-2,STONE:0)
Block(-3,14,-1,STONE:0)
Block(-2,14,-1,STONE:0)
Block(-1,14,-1,STONE:0)
Block(0,14,-1,STONE:0)
Block(1,14,-1,STONE:0)
Block(2,14,-1,STONE:0)
Block(-3,14,0,STONE:0)
Block(-2,14,0,STONE:0)
Block(-1,14,0,STONE:0)
Block(0,14,0,STONE:0)
Block(1,14,0,STONE:0)
Block(2,14,0,STONE:0)
Block(-2,14,1,STONE:0)
Block(-1,14,1,STONE:0)
Block(0,14,1,STONE:0)
Block(1,14,1,STONE:0)
Block(2,14,1,STONE:0)
Block(-1,14,2,STONE:0)
Block(0,14,2,STONE:0)
Block(1,14,2,STONE:0)
Block(2,14,2,STONE:0)
Block(-2,15,-2,STONE:0)
Block(-1,15,-2,STONE:0)
Block(0,15,-2,STONE:0)
Block(1,15,-2,STONE:0)
Block(-3,15,-1,STONE:0)
Block(-2,15,-1,STONE:0)
Block(-1,15,-1,STONE:0)
Block(0,15,-1,STONE:0)
Block(1,15,-1,STONE:0)
Block(2,15,-1,STONE:0)
Block(-3,15,0,STONE:0)
Block(-2,15,0,STONE:0)
Block(-1,15,0,STONE:0)
Block(0,15,0,STONE:0)
Block(1,15,0,STONE:0)
Block(2,15,0,STONE:0)
Block(-2,15,1,STONE:0)
Block(-1,15,1,STONE:0)
Block(0,15,1,STONE:0)
Block(1,15,1,STONE:0)
Block(2,15,1,STONE:0)
Block(-1,15,2,STONE:0)
Block(0,15,2,STONE:0)
Block(1,15,2,STONE:0)
Block(-2,16,-2,STONE:0)
Block(-1,16,-2,STONE:0)
Block(0,16,-2,STONE:0)
Block(-2,16,-1,STONE:0)
Block(-1,16,-1,STONE:0)
Block(0,16,-1,STONE:0)
Block(1,16,-1,STONE:0)
Block(2,16,-1,STONE:0)
Block(-2,16,0,STONE:0)
Block(-1,16,0,STONE:0)
Block(0,16,0,STONE:0)
Block(1,16,0,STONE:0)
Block(2,16,0,STONE:0)
Block(-2,16,1,STONE:0)
Block(-1,16,1,STONE:0)
Block(0,16,1,STONE:0)
Block(1,16,1,STONE:0)
Block(2,16,1,STONE:0)
Block(-1,16,2,STONE:0)
Block(0,16,2,STONE:0)
Block(1,16,2,STONE:0)
Block(-1,17,-2,STONE:0)
Block(-2,17,-1,STONE:0)
Block(-1,17,-1,STONE:0)
Block(0,17,-1,STONE:0)
Block(1,17,-1,STONE:0)
Block(2,17,-1,STONE:0)
Block(-2,17,0,STONE:0)
Block(-1,17,0,STONE:0)
Block(0,17,0,STONE:0)
Block(1,17,0,STONE:0)
Block(2,17,0,STONE:0)
Block(-2,17,1,STONE:0)
Block(-1,17,1,STONE:0)
Block(0,17,1,STONE:0)
Block(1,17,1,STONE:0)
Block(0,17,2,STONE:0)
Block(1,17,2,STONE:0)
Block(-1,18,-1,STONE:0)
Block(0,18,-1,STONE:0)
Block(1,18,-1,STONE:0)
Block(2,18,-1,STONE:0)
Block(-2,18,0,STONE:0)
Block(-1,18,0,STONE:0)
Block(0,18,0,STONE:0)
Block(1,18,0,STONE:0)
Block(2,18,0,STONE:0)
Block(-2,18,1,STONE:0)
Block(-1,18,1,STONE:0)
Block(0,18,1,STONE:0)
Block(1,18,1,STONE:0)
Block(0,18,2,STONE:0)
Block(-1,19,-1,STONE:0)
Block(0,19,-1,STONE:0)
Block(1,19,-1,STONE:0)
Block(2,19,-1,STONE:0)
Block(-2,19,0,STONE:0)
Block(-1,19,0,STONE:0)
Block(0,19,0,STONE:0)
Block(1,19,0,STONE:0)
Block(2,19,0,STONE:0)
Block(-2,19,1,STONE:0)
Block(-1,19,1,STONE:0)
Block(0,19,1,STONE:0)
Block(1,19,1,STONE:0)
Block(0,19,2,STONE:0)
Block(-1,20,-1,STONE:0)
Block(0,20,-1,STONE:0)
Block(1,20,-1,STONE:0)
Block(-2,20,0,STONE:0)
Block(-1,20,0,STONE:0)
Block(0,20,0,STONE:0)
Block(1,20,0,STONE:0)
Block(2,20,0,STONE:0)
Block(-2,20,1,STONE:0)
Block(-1,20,1,STONE:0)
Block(0,20,1,STONE:0)
Block(1,20,1,STONE:0)
Block(-1,21,-1,STONE:0)
Block(0,21,-1,STONE:0)
Block(1,21,-1,STONE:0)
Block(-2,21,0,STONE:0)
Block(-1,21,0,STONE:0)
Block(0,21,0,STONE:0)
Block(1,21,0,STONE:0)
Block(-2,21,1,STONE:0)
Block(-1,21,1,STONE:0)
Block(0,21,1,STONE:0)
Block(1,21,1,STONE:0)
Block(-1,22,-1,STONE:0)
Block(0,22,-1,STONE:0)
Block(-2,22,0,STONE:0)
Block(-1,22,0,STONE:0)
Block(0,22,0,STONE:0)
Block(1,22,0,STONE:0)
Block(-2,22,1,STONE:0)
Block(-1,22,1,STONE:0)
Block(0,22,1,STONE:0)
Block(-1,23,-1,STONE:0)
Block(0,23,-1,STONE:0)
Block(-2,23,0,STONE:0)
Block(-1,23,0,STONE:0)
Block(0,23,0,STONE:0)
Block(-1,23,1,STONE:0)
Block(0,23,1,STONE:0)
Block(-1,24,-1,STONE:0)
Block(0,24,-1,STONE:0)
Block(-2,24,0,STONE:0)
Block(-1,24,0,STONE:0)
Block(0,24,0,STONE:0)
Block(-1,24,1,STONE:0)
Block(0,24,1,STONE:0)
Block(-1,25,-1,STONE:0)
Block(0,25,-1,STONE:0)
Block(-1,25,0,STONE:0)
Block(0,25,0,STONE:0)
Block(-1,25,1,STONE:0)
Block(0,25,1,STONE:0)
Block(-1,26,-1,STONE:0)
Block(0,26,-1,STONE:0)
Block(-1,26,0,STONE:0)
Block(0,26,0,STONE:0)
Block(-1,26,1,STONE:0)
Block(0,26,1,STONE:0)
Block(-1,27,-1,STONE:0)
Block(0,27,-1,STONE:0)
Block(-1,27,0,STONE:0)
Block(0,27,0,STONE:0)
Block(-1,27,1,STONE:0)
Block(-1,28,-1,STONE:0)
Block(0,28,-1,STONE:0)
Block(-1,28,0,STONE:0)
Block(0,28,0,STONE:0)
Block(-1,28,1,STONE:0)
Block(-1,29,-1,STONE:0)
Block(0,29,-1,STONE:0)
Block(-1,29,0,STONE:0)
Block(0,29,0,STONE:0)
Block(-1,29,1,STONE:0)
Block(-1,30,-1,STONE:0)
Block(0,30,-1,STONE:0)
Block(-2,30,0,STONE:0)
Block(-1,30,0,STONE:0)
Block(0,30,0,STONE:0)
Block(1,30,0,STONE:0)
Block(-1,30,1,STONE:0)
Block(0,30,1,STONE:0)
Block(-1,31,-1,STONE:0)
Block(0,31,-1,STONE:0)
Block(-2,31,0,STONE:0)
Block(-1,31,0,STONE:0)
Block(0,31,0,STONE:0)
Block(1,31,0,STONE:0)
Block(-1,31,1,STONE:0)
Block(0,31,1,STONE:0)
Block(1,31,1,STONE:0)
Block(-1,32,-1,STONE:0)
Block(0,32,-1,STONE:0)
Block(-2,32,0,STONE:0)
Block(-1,32,0,STONE:0)
Block(0,32,0,STONE:0)
Block(1,32,0,STONE:0)
Block(-1,32,1,STONE:0)
Block(0,32,1,STONE:0)
Block(1,32,1,STONE:0)
Block(-2,33,-2,STONE:0)
Block(-1,33,-2,STONE:0)
Block(-2,33,-1,STONE:0)
Block(-1,33,-1,STONE:0)
Block(0,33,-1,STONE:0)
Block(-2,33,0,STONE:0)
Block(-1,33,0,STONE:0)
Block(0,33,0,STONE:0)
Block(1,33,0,STONE:0)
Block(-1,33,1,STONE:0)
Block(0,33,1,STONE:0)
Block(1,33,1,STONE:0)
Block(-2,34,-2,STONE:0)
Block(-1,34,-2,STONE:0)
Block(0,34,-2,STONE:0)
Block(-2,34,-1,STONE:0)
Block(-1,34,-1,STONE:0)
Block(0,34,-1,STONE:0)
Block(1,34,-1,STONE:0)
Block(-3,34,0,STONE:0)
Block(-2,34,0,STONE:0)
Block(-1,34,0,STONE:0)
Block(0,34,0,STONE:0)
Block(1,34,0,STONE:0)
Block(2,34,0,STONE:0)
Block(-2,34,1,STONE:0)
Block(-1,34,1,STONE:0)
Block(0,34,1,STONE:0)
Block(1,34,1,STONE:0)
Block(-2,35,-2,STONE:0)
Block(-1,35,-2,STONE:0)
Block(0,35,-2,STONE:0)
Block(-3,35,-1,STONE:0)
Block(-2,35,-1,STONE:0)
Block(-1,35,-1,STONE:0)
Block(0,35,-1,STONE:0)
Block(1,35,-1,STONE:0)
Block(2,35,-1,STONE:0)
Block(-3,35,0,STONE:0)
Block(-2,35,0,STONE:0)
Block(-1,35,0,STONE:0)
Block(0,35,0,STONE:0)
Block(1,35,0,STONE:0)
Block(2,35,0,STONE:0)
Block(-3,35,1,STONE:0)
Block(-2,35,1,STONE:0)
Block(-1,35,1,STONE:0)
Block(0,35,1,STONE:0)
Block(1,35,1,STONE:0)
Block(-1,35,2,STONE:0)
Block(-3,36,-3,STONE:0)
Block(-3,36,-2,STONE:0)
Block(-2,36,-2,STONE:0)
Block(-1,36,-2,STONE:0)
Block(0,36,-2,STONE:0)
Block(-4,36,-1,STONE:0)
Block(-3,36,-1,STONE:0)
Block(-2,36,-1,STONE:0)
Block(-1,36,-1,STONE:0)
Block(0,36,-1,STONE:0)
Block(1,36,-1,STONE:0)
Block(2,36,-1,STONE:0)
Block(-4,36,0,STONE:0)
Block(-3,36,0,STONE:0)
Block(-2,36,0,STONE:0)
Block(-1,36,0,STONE:0)
Block(0,36,0,STONE:0)
Block(1,36,0,STONE:0)
Block(2,36,0,STONE:0)
Block(-4,36,1,STONE:0)
Block(-3,36,1,STONE:0)
Block(-2,36,1,STONE:0)
Block(-1,36,1,STONE:0)
Block(0,36,1,STONE:0)
Block(1,36,1,STONE:0)
Block(2,36,1,STONE:0)
Block(-2,36,2,STONE:0)
Block(-1,36,2,STONE:0)
Block(-3,37,-3,STONE:0)
Block(-2,37,-3,STONE:0)
Block(-1,37,-3,STONE:0)
Block(-4,37,-2,STONE:0)
Block(-3,37,-2,STONE:0)
Block(-2,37,-2,STONE:0)
Block(-1,37,-2,STONE:0)
Block(0,37,-2,STONE:0)
Block(1,37,-2,STONE:0)
Block(2,37,-2,STONE:0)
Block(-5,37,-1,STONE:0)
Block(-4,37,-1,STONE:0)
Block(-3,37,-1,STONE:0)
Block(-2,37,-1,STONE:0)
Block(-1,37,-1,STONE:0)
Block(0,37,-1,STONE:0)
Block(1,37,-1,STONE:0)
Block(2,37,-1,STONE:0)
Block(-4,37,0,STONE:0)
Block(-3,37,0,STONE:0)
Block(-2,37,0,STONE:0)
Block(-1,37,0,STONE:0)
Block(0,37,0,STONE:0)
Block(1,37,0,STONE:0)
Block(2,37,0,STONE:0)
Block(3,37,0,STONE:0)
Block(-4,37,1,STONE:0)
Block(-3,37,1,STONE:0)
Block(-2,37,1,STONE:0)
Block(-1,37,1,STONE:0)
Block(0,37,1,STONE:0)
Block(1,37,1,STONE:0)
Block(2,37,1,STONE:0)
Block(-2,37,2,STONE:0)
Block(-1,37,2,STONE:0)
Block(0,37,2,STONE:0)
Block(-4,38,-3,STONE:0)
Block(-3,38,-3,STONE:0)
Block(-2,38,-3,STONE:0)
Block(-1,38,-3,STONE:0)
Block(0,38,-3,STONE:0)
Block(-4,38,-2,STONE:0)
Block(-3,38,-2,STONE:0)
Block(-2,38,-2,STONE:0)
Block(-1,38,-2,STONE:0)
Block(0,38,-2,STONE:0)
Block(1,38,-2,STONE:0)
Block(2,38,-2,STONE:0)
Block(3,38,-2,STONE:0)
Block(-5,38,-1,STONE:0)
Block(-4,38,-1,STONE:0)
Block(-3,38,-1,STONE:0)
Block(-2,38,-1,STONE:0)
Block(-1,38,-1,STONE:0)
Block(0,38,-1,STONE:0)
Block(1,38,-1,STONE:0)
Block(2,38,-1,STONE:0)
Block(3,38,-1,STONE:0)
Block(-5,38,0,STONE:0)
Block(-4,38,0,STONE:0)
Block(-3,38,0,STONE:0)
Block(-2,38,0,STONE:0)
Block(-1,38,0,STONE:0)
Block(0,38,0,STONE:0)
Block(1,38,0,STONE:0)
Block(2,38,0,STONE:0)
Block(3,38,0,STONE:0)
Block(-4,38,1,STONE:0)
Block(-3,38,1,STONE:0)
Block(-2,38,1,STONE:0)
Block(-1,38,1,STONE:0)
Block(0,38,1,STONE:0)
Block(1,38,1,STONE:0)
Block(2,38,1,STONE:0)
Block(3,38,1,STONE:0)
Block(-4,38,2,STONE:0)
Block(-3,38,2,STONE:0)
Block(-2,38,2,STONE:0)
Block(-1,38,2,STONE:0)
Block(0,38,2,STONE:0)
Block(1,38,2,STONE:0)
Block(2,38,2,STONE:0)
Block(1,39,-4,STONE:0)
Block(-4,39,-3,STONE:0)
Block(-3,39,-3,STONE:0)
Block(-2,39,-3,STONE:0)
Block(-1,39,-3,STONE:0)
Block(0,39,-3,STONE:0)
Block(1,39,-3,STONE:0)
Block(-5,39,-2,STONE:0)
Block(-4,39,-2,STONE:0)
Block(-3,39,-2,STONE:0)
Block(-2,39,-2,STONE:0)
Block(-1,39,-2,STONE:0)
Block(0,39,-2,STONE:0)
Block(1,39,-2,STONE:0)
Block(2,39,-2,STONE:0)
Block(3,39,-2,STONE:0)
Block(-5,39,-1,STONE:0)
Block(-4,39,-1,STONE:0)
Block(-3,39,-1,STONE:0)
Block(-2,39,-1,STONE:0)
Block(-1,39,-1,STONE:0)
Block(0,39,-1,STONE:0)
Block(1,39,-1,STONE:0)
Block(2,39,-1,STONE:0)
Block(3,39,-1,STONE:0)
Block(-5,39,0,STONE:0)
Block(-4,39,0,STONE:0)
Block(-3,39,0,STONE:0)
Block(-2,39,0,STONE:0)
Block(-1,39,0,STONE:0)
Block(0,39,0,STONE:0)
Block(1,39,0,STONE:0)
Block(2,39,0,STONE:0)
Block(3,39,0,STONE:0)
Block(-4,39,1,STONE:0)
Block(-3,39,1,STONE:0)
Block(-2,39,1,STONE:0)
Block(-1,39,1,STONE:0)
Block(0,39,1,STONE:0)
Block(1,39,1,STONE:0)
Block(2,39,1,STONE:0)
Block(3,39,1,STONE:0)
Block(-4,39,2,STONE:0)
Block(-3,39,2,STONE:0)
Block(-2,39,2,STONE:0)
Block(-1,39,2,STONE:0)
Block(0,39,2,STONE:0)
Block(1,39,2,STONE:0)
Block(2,39,2,STONE:0)
Block(3,39,2,STONE:0)
Block(-3,39,3,STONE:0)
Block(-2,39,3,STONE:0)
Block(-1,39,3,STONE:0)
Block(0,39,3,STONE:0)
Block(-2,40,-4,STONE:0)
Block(-1,40,-4,STONE:0)
Block(0,40,-4,STONE:0)
Block(1,40,-4,STONE:0)
Block(-5,40,-3,STONE:0)
Block(-4,40,-3,STONE:0)
Block(-3,40,-3,STONE:0)
Block(-2,40,-3,STONE:0)
Block(-1,40,-3,STONE:0)
Block(0,40,-3,STONE:0)
Block(1,40,-3,STONE:0)
Block(2,40,-3,STONE:0)
Block(-5,40,-2,STONE:0)
Block(-4,40,-2,STONE:0)
Block(-3,40,-2,STONE:0)
Block(-2,40,-2,STONE:0)
Block(-1,40,-2,STONE:0)
Block(0,40,-2,STONE:0)
Block(1,40,-2,STONE:0)
Block(2,40,-2,STONE:0)
Block(3,40,-2,STONE:0)
Block(-5,40,-1,STONE:0)
Block(-4,40,-1,STONE:0)
Block(-3,40,-1,STONE:0)
Block(-2,40,-1,STONE:0)
Block(-1,40,-1,STONE:0)
Block(0,40,-1,STONE:0)
Block(1,40,-1,STONE:0)
Block(2,40,-1,STONE:0)
Block(3,40,-1,STONE:0)
Block(-5,40,0,STONE:0)
Block(-4,40,0,STONE:0)
Block(-3,40,0,STONE:0)
Block(-2,40,0,STONE:0)
Block(-1,40,0,STONE:0)
Block(0,40,0,STONE:0)
Block(1,40,0,STONE:0)
Block(2,40,0,STONE:0)
Block(3,40,0,STONE:0)
Block(4,40,0,STONE:0)
Block(-5,40,1,STONE:0)
Block(-4,40,1,STONE:0)
Block(-3,40,1,STONE:0)
Block(-2,40,1,STONE:0)
Block(-1,40,1,STONE:0)
Block(0,40,1,STONE:0)
Block(1,40,1,STONE:0)
Block(2,40,1,STONE:0)
Block(3,40,1,STONE:0)
Block(4,40,1,STONE:0)
Block(-5,40,2,STONE:0)
Block(-4,40,2,STONE:0)
Block(-3,40,2,STONE:0)
Block(-2,40,2,STONE:0)
Block(-1,40,2,STONE:0)
Block(0,40,2,STONE:0)
Block(1,40,2,STONE:0)
Block(2,40,2,STONE:0)
Block(3,40,2,STONE:0)
Block(-4,40,3,STONE:0)
Block(-3,40,3,STONE:0)
Block(-2,40,3,STONE:0)
Block(-1,40,3,STONE:0)
Block(0,40,3,STONE:0)
Block(1,40,3,STONE:0)
Block(2,40,3,STONE:0)
Block(-3,40,4,STONE:0)
Block(-2,40,4,STONE:0)
Block(-1,40,4,STONE:0)
Block(0,40,4,STONE:0)
Block(1,40,4,STONE:0)
Block(-1,40,5,STONE:0)
Block(-3,41,-4,STONE:0)
Block(-2,41,-4,STONE:0)
Block(-1,41,-4,STONE:0)
Block(0,41,-4,STONE:0)
Block(1,41,-4,STONE:0)
Block(-5,41,-3,STONE:0)
Block(-4,41,-3,STONE:0)
Block(-3,41,-3,STONE:0)
Block(-2,41,-3,STONE:0)
Block(-1,41,-3,STONE:0)
Block(0,41,-3,STONE:0)
Block(1,41,-3,STONE:0)
Block(2,41,-3,STONE:0)
Block(-6,41,-2,STONE:0)
Block(-5,41,-2,STONE:0)
Block(-4,41,-2,STONE:0)
Block(-3,41,-2,STONE:0)
Block(-2,41,-2,STONE:0)
Block(-1,41,-2,STONE:0)
Block(0,41,-2,STONE:0)
Block(1,41,-2,STONE:0)
Block(2,41,-2,STONE:0)
Block(3,41,-2,STONE:0)
Block(-6,41,-1,STONE:0)
Block(-5,41,-1,STONE:0)
Block(-4,41,-1,STONE:0)
Block(-3,41,-1,STONE:0)
Block(-2,41,-1,STONE:0)
Block(-1,41,-1,STONE:0)
Block(0,41,-1,STONE:0)
Block(1,41,-1,STONE:0)
Block(2,41,-1,STONE:0)
Block(3,41,-1,STONE:0)
Block(4,41,-1,STONE:0)
Block(-5,41,0,STONE:0)
Block(-4,41,0,STONE:0)
Block(-3,41,0,STONE:0)
Block(-2,41,0,STONE:0)
Block(-1,41,0,STONE:0)
Block(0,41,0,STONE:0)
Block(1,41,0,STONE:0)
Block(2,41,0,STONE:0)
Block(3,41,0,STONE:0)
Block(4,41,0,STONE:0)
Block(-5,41,1,STONE:0)
Block(-4,41,1,STONE:0)
Block(-3,41,1,STONE:0)
Block(-2,41,1,STONE:0)
Block(-1,41,1,STONE:0)
Block(0,41,1,STONE:0)
Block(1,41,1,STONE:0)
Block(2,41,1,STONE:0)
Block(3,41,1,STONE:0)
Block(4,41,1,STONE:0)
Block(-5,41,2,STONE:0)
Block(-4,41,2,STONE:0)
Block(-3,41,2,STONE:0)
Block(-2,41,2,STONE:0)
Block(-1,41,2,STONE:0)
Block(0,41,2,STONE:0)
Block(1,41,2,STONE:0)
Block(2,41,2,STONE:0)
Block(3,41,2,STONE:0)
Block(-5,41,3,STONE:0)
Block(-4,41,3,STONE:0)
Block(-3,41,3,STONE:0)
Block(-2,41,3,STONE:0)
Block(-1,41,3,STONE:0)
Block(0,41,3,STONE:0)
Block(1,41,3,STONE:0)
Block(2,41,3,STONE:0)
Block(3,41,3,STONE:0)
Block(-4,41,4,STONE:0)
Block(-3,41,4,STONE:0)
Block(-2,41,4,STONE:0)
Block(-1,41,4,STONE:0)
Block(0,41,4,STONE:0)
Block(1,41,4,STONE:0)
Block(2,41,4,STONE:0)
Block(-3,41,5,STONE:0)
Block(-2,41,5,STONE:0)
Block(-1,41,5,STONE:0)
Block(1,42,-5,STONE:0)
Block(-3,42,-4,STONE:0)
Block(-2,42,-4,STONE:0)
Block(-1,42,-4,STONE:0)
Block(0,42,-4,STONE:0)
Block(1,42,-4,STONE:0)
Block(-6,42,-3,STONE:0)
Block(-5,42,-3,STONE:0)
Block(-4,42,-3,STONE:0)
Block(-3,42,-3,STONE:0)
Block(-2,42,-3,STONE:0)
Block(-1,42,-3,STONE:0)
Block(0,42,-3,STONE:0)
Block(1,42,-3,STONE:0)
Block(2,42,-3,STONE:0)
Block(-6,42,-2,STONE:0)
Block(-5,42,-2,STONE:0)
Block(-4,42,-2,STONE:0)
Block(-3,42,-2,STONE:0)
Block(-2,42,-2,STONE:0)
Block(-1,42,-2,STONE:0)
Block(0,42,-2,STONE:0)
Block(1,42,-2,STONE:0)
Block(2,42,-2,STONE:0)
Block(3,42,-2,STONE:0)
Block(-7,42,-1,STONE:0)
Block(-6,42,-1,STONE:0)
Block(-5,42,-1,STONE:0)
Block(-4,42,-1,STONE:0)
Block(-3,42,-1,STONE:0)
Block(-2,42,-1,STONE:0)
Block(-1,42,-1,STONE:0)
Block(0,42,-1,STONE:0)
Block(1,42,-1,STONE:0)
Block(2,42,-1,STONE:0)
Block(3,42,-1,STONE:0)
Block(4,42,-1,STONE:0)
Block(5,42,-1,STONE:0)
Block(-6,42,0,STONE:0)
Block(-5,42,0,STONE:0)
Block(-4,42,0,STONE:0)
Block(-3,42,0,STONE:0)
Block(-2,42,0,STONE:0)
Block(-1,42,0,STONE:0)
Block(0,42,0,STONE:0)
Block(1,42,0,STONE:0)
Block(2,42,0,STONE:0)
Block(3,42,0,STONE:0)
Block(4,42,0,STONE:0)
Block(-6,42,1,STONE:0)
Block(-5,42,1,STONE:0)
Block(-4,42,1,STONE:0)
Block(-3,42,1,STONE:0)
Block(-2,42,1,STONE:0)
Block(-1,42,1,STONE:0)
Block(0,42,1,STONE:0)
Block(1,42,1,STONE:0)
Block(2,42,1,STONE:0)
Block(3,42,1,STONE:0)
Block(4,42,1,STONE:0)
Block(-5,42,2,STONE:0)
Block(-4,42,2,STONE:0)
Block(-3,42,2,STONE:0)
Block(-2,42,2,STONE:0)
Block(-1,42,2,STONE:0)
Block(0,42,2,STONE:0)
Block(1,42,2,STONE:0)
Block(2,42,2,STONE:0)
Block(3,42,2,STONE:0)
Block(4,42,2,STONE:0)
Block(5,42,2,STONE:0)
Block(-5,42,3,STONE:0)
Block(-4,42,3,STONE:0)
Block(-3,42,3,STONE:0)
Block(-2,42,3,STONE:0)
Block(-1,42,3,STONE:0)
Block(0,42,3,STONE:0)
Block(1,42,3,STONE:0)
Block(2,42,3,STONE:0)
Block(3,42,3,STONE:0)
Block(4,42,3,STONE:0)
Block(-5,42,4,STONE:0)
Block(-4,42,4,STONE:0)
Block(-3,42,4,STONE:0)
Block(-2,42,4,STONE:0)
Block(-1,42,4,STONE:0)
Block(0,42,4,STONE:0)
Block(1,42,4,STONE:0)
Block(2,42,4,STONE:0)
Block(3,42,4,STONE:0)
Block(-4,42,5,STONE:0)
Block(-3,42,5,STONE:0)
Block(-2,42,5,STONE:0)
Block(-1,42,5,STONE:0)
Block(0,42,5,STONE:0)
Block(-3,43,-5,STONE:0)
Block(-2,43,-5,STONE:0)
Block(-1,43,-5,STONE:0)
Block(0,43,-5,STONE:0)
Block(1,43,-5,STONE:0)
Block(-4,43,-4,STONE:0)
Block(-3,43,-4,STONE:0)
Block(-2,43,-4,STONE:0)
Block(-1,43,-4,STONE:0)
Block(0,43,-4,STONE:0)
Block(1,43,-4,STONE:0)
Block(2,43,-4,STONE:0)
Block(-7,43,-3,STONE:0)
Block(-6,43,-3,STONE:0)
Block(-5,43,-3,STONE:0)
Block(-4,43,-3,STONE:0)
Block(-3,43,-3,STONE:0)
Block(-2,43,-3,STONE:0)
Block(-1,43,-3,STONE:0)
Block(0,43,-3,STONE:0)
Block(1,43,-3,STONE:0)
Block(2,43,-3,STONE:0)
Block(3,43,-3,STONE:0)
Block(-7,43,-2,STONE:0)
Block(-6,43,-2,STONE:0)
Block(-5,43,-2,STONE:0)
Block(-4,43,-2,STONE:0)
Block(-3,43,-2,STONE:0)
Block(-2,43,-2,STONE:0)
Block(-1,43,-2,STONE:0)
Block(0,43,-2,STONE:0)
Block(1,43,-2,STONE:0)
Block(2,43,-2,STONE:0)
Block(3,43,-2,STONE:0)
Block(4,43,-2,STONE:0)
Block(-7,43,-1,STONE:0)
Block(-6,43,-1,STONE:0)
Block(-5,43,-1,STONE:0)
Block(-4,43,-1,STONE:0)
Block(-3,43,-1,STONE:0)
Block(-2,43,-1,STONE:0)
Block(-1,43,-1,STONE:0)
Block(0,43,-1,STONE:0)
Block(1,43,-1,STONE:0)
Block(2,43,-1,STONE:0)
Block(3,43,-1,STONE:0)
Block(4,43,-1,STONE:0)
Block(5,43,-1,STONE:0)
Block(-7,43,0,STONE:0)
Block(-6,43,0,STONE:0)
Block(-5,43,0,STONE:0)
Block(-4,43,0,STONE:0)
Block(-3,43,0,STONE:0)
Block(-2,43,0,STONE:0)
Block(-1,43,0,STONE:0)
Block(0,43,0,STONE:0)
Block(1,43,0,STONE:0)
Block(2,43,0,STONE:0)
Block(3,43,0,STONE:0)
Block(4,43,0,STONE:0)
Block(-6,43,1,STONE:0)
Block(-5,43,1,STONE:0)
Block(-4,43,1,STONE:0)
Block(-3,43,1,STONE:0)
Block(-2,43,1,STONE:0)
Block(-1,43,1,STONE:0)
Block(0,43,1,STONE:0)
Block(1,43,1,STONE:0)
Block(2,43,1,STONE:0)
Block(3,43,1,STONE:0)
Block(4,43,1,STONE:0)
Block(-5,43,2,STONE:0)
Block(-4,43,2,STONE:0)
Block(-3,43,2,STONE:0)
Block(-2,43,2,STONE:0)
Block(-1,43,2,STONE:0)
Block(0,43,2,STONE:0)
Block(1,43,2,STONE:0)
Block(2,43,2,STONE:0)
Block(3,43,2,STONE:0)
Block(4,43,2,STONE:0)
Block(5,43,2,STONE:0)
Block(-5,43,3,STONE:0)
Block(-4,43,3,STONE:0)
Block(-3,43,3,STONE:0)
Block(-2,43,3,STONE:0)
Block(-1,43,3,STONE:0)
Block(0,43,3,STONE:0)
Block(1,43,3,STONE:0)
Block(2,43,3,STONE:0)
Block(3,43,3,STONE:0)
Block(4,43,3,STONE:0)
Block(-5,43,4,STONE:0)
Block(-4,43,4,STONE:0)
Block(-3,43,4,STONE:0)
Block(-2,43,4,STONE:0)
Block(-1,43,4,STONE:0)
Block(0,43,4,STONE:0)
Block(1,43,4,STONE:0)
Block(2,43,4,STONE:0)
Block(3,43,4,STONE:0)
Block(-5,43,5,STONE:0)
Block(-4,43,5,STONE:0)
Block(-3,43,5,STONE:0)
Block(-2,43,5,STONE:0)
Block(-1,43,5,STONE:0)
Block(0,43,5,STONE:0)
Block(1,43,5,STONE:0)
Block(2,43,5,STONE:0)
Block(3,43,5,STONE:0)
Block(-1,43,6,STONE:0)
Block(-2,44,-6,STONE:0)
Block(-1,44,-6,STONE:0)
Block(0,44,-6,STONE:0)
Block(1,44,-6,STONE:0)
Block(-3,44,-5,STONE:0)
Block(-2,44,-5,STONE:0)
Block(-1,44,-5,STONE:0)
Block(0,44,-5,STONE:0)
Block(1,44,-5,STONE:0)
Block(2,44,-5,STONE:0)
Block(-5,44,-4,STONE:0)
Block(-4,44,-4,STONE:0)
Block(-3,44,-4,STONE:0)
Block(-2,44,-4,STONE:0)
Block(-1,44,-4,STONE:0)
Block(0,44,-4,STONE:0)
Block(1,44,-4,STONE:0)
Block(2,44,-4,STONE:0)
Block(3,44,-4,STONE:0)
Block(-7,44,-3,STONE:0)
Block(-6,44,-3,STONE:0)
Block(-5,44,-3,STONE:0)
Block(-4,44,-3,STONE:0)
Block(-3,44,-3,STONE:0)
Block(-2,44,-3,STONE:0)
Block(-1,44,-3,STONE:0)
Block(0,44,-3,STONE:0)
Block(1,44,-3,STONE:0)
Block(2,44,-3,STONE:0)
Block(3,44,-3,STONE:0)
Block(-8,44,-2,STONE:0)
Block(-7,44,-2,STONE:0)
Block(-6,44,-2,STONE:0)
Block(-5,44,-2,STONE:0)
Block(-4,44,-2,STONE:0)
Block(-3,44,-2,STONE:0)
Block(-2,44,-2,STONE:0)
Block(-1,44,-2,STONE:0)
Block(0,44,-2,STONE:0)
Block(1,44,-2,STONE:0)
Block(2,44,-2,STONE:0)
Block(3,44,-2,STONE:0)
Block(4,44,-2,STONE:0)
Block(-7,44,-1,STONE:0)
Block(-6,44,-1,STONE:0)
Block(-5,44,-1,STONE:0)
Block(-4,44,-1,STONE:0)
Block(-3,44,-1,STONE:0)
Block(-2,44,-1,STONE:0)
Block(-1,44,-1,STONE:0)
Block(0,44,-1,STONE:0)
Block(1,44,-1,STONE:0)
Block(2,44,-1,STONE:0)
Block(3,44,-1,STONE:0)
Block(4,44,-1,STONE:0)
Block(5,44,-1,STONE:0)
Block(-7,44,0,STONE:0)
Block(-6,44,0,STONE:0)
Block(-5,44,0,STONE:0)
Block(-4,44,0,STONE:0)
Block(-3,44,0,STONE:0)
Block(-2,44,0,STONE:0)
Block(-1,44,0,STONE:0)
Block(0,44,0,STONE:0)
Block(1,44,0,STONE:0)
Block(2,44,0,STONE:0)
Block(3,44,0,STONE:0)
Block(4,44,0,STONE:0)
Block(-7,44,1,STONE:0)
Block(-6,44,1,STONE:0)
Block(-5,44,1,STONE:0)
Block(-4,44,1,STONE:0)
Block(-3,44,1,STONE:0)
Block(-2,44,1,STONE:0)
Block(-1,44,1,STONE:0)
Block(0,44,1,STONE:0)
Block(1,44,1,STONE:0)
Block(2,44,1,STONE:0)
Block(3,44,1,STONE:0)
Block(4,44,1,STONE:0)
Block(5,44,1,STONE:0)
Block(-6,44,2,STONE:0)
Block(-5,44,2,STONE:0)
Block(-4,44,2,STONE:0)
Block(-3,44,2,STONE:0)
Block(-2,44,2,STONE:0)
Block(-1,44,2,STONE:0)
Block(0,44,2,STONE:0)
Block(1,44,2,STONE:0)
Block(2,44,2,STONE:0)
Block(3,44,2,STONE:0)
Block(4,44,2,STONE:0)
Block(5,44,2,STONE:0)
Block(-5,44,3,STONE:0)
Block(-4,44,3,STONE:0)
Block(-3,44,3,STONE:0)
Block(-2,44,3,STONE:0)
Block(-1,44,3,STONE:0)
Block(0,44,3,STONE:0)
Block(1,44,3,STONE:0)
Block(2,44,3,STONE:0)
Block(3,44,3,STONE:0)
Block(4,44,3,STONE:0)
Block(5,44,3,STONE:0)
Block(-5,44,4,STONE:0)
Block(-4,44,4,STONE:0)
Block(-3,44,4,STONE:0)
Block(-2,44,4,STONE:0)
Block(-1,44,4,STONE:0)
Block(0,44,4,STONE:0)
Block(1,44,4,STONE:0)
Block(2,44,4,STONE:0)
Block(3,44,4,STONE:0)
Block(4,44,4,STONE:0)
Block(-4,44,5,STONE:0)
Block(-3,44,5,STONE:0)
Block(-2,44,5,STONE:0)
Block(-1,44,5,STONE:0)
Block(0,44,5,STONE:0)
Block(1,44,5,STONE:0)
Block(2,44,5,STONE:0)
Block(3,44,5,STONE:0)
Block(-2,44,6,STONE:0)
Block(-1,44,6,STONE:0)
Block(-2,45,-6,STONE:0)
Block(-1,45,-6,STONE:0)
Block(0,45,-6,STONE:0)
Block(1,45,-6,STONE:0)
Block(2,45,-6,STONE:0)
Block(-4,45,-5,STONE:0)
Block(-3,45,-5,STONE:0)
Block(-2,45,-5,STONE:0)
Block(-1,45,-5,STONE:0)
Block(0,45,-5,STONE:0)
Block(1,45,-5,STONE:0)
Block(2,45,-5,STONE:0)
Block(3,45,-5,STONE:0)
Block(-5,45,-4,STONE:0)
Block(-4,45,-4,STONE:0)
Block(-3,45,-4,STONE:0)
Block(-2,45,-4,STONE:0)
Block(-1,45,-4,STONE:0)
Block(0,45,-4,STONE:0)
Block(1,45,-4,STONE:0)
Block(2,45,-4,STONE:0)
Block(3,45,-4,STONE:0)
Block(4,45,-4,STONE:0)
Block(-7,45,-3,STONE:0)
Block(-6,45,-3,STONE:0)
Block(-5,45,-3,STONE:0)
Block(-4,45,-3,STONE:0)
Block(-3,45,-3,STONE:0)
Block(-2,45,-3,STONE:0)
Block(-1,45,-3,STONE:0)
Block(0,45,-3,STONE:0)
Block(1,45,-3,STONE:0)
Block(2,45,-3,STONE:0)
Block(3,45,-3,STONE:0)
Block(4,45,-3,STONE:0)
Block(-8,45,-2,STONE:0)
Block(-7,45,-2,STONE:0)
Block(-6,45,-2,STONE:0)
Block(-5,45,-2,STONE:0)
Block(-4,45,-2,STONE:0)
Block(-3,45,-2,STONE:0)
Block(-2,45,-2,STONE:0)
Block(-1,45,-2,STONE:0)
Block(0,45,-2,STONE:0)
Block(1,45,-2,STONE:0)
Block(2,45,-2,STONE:0)
Block(3,45,-2,STONE:0)
Block(4,45,-2,STONE:0)
Block(5,45,-2,STONE:0)
Block(-8,45,-1,STONE:0)
Block(-7,45,-1,STONE:0)
Block(-6,45,-1,STONE:0)
Block(-5,45,-1,STONE:0)
Block(-4,45,-1,STONE:0)
Block(-3,45,-1,STONE:0)
Block(-2,45,-1,STONE:0)
Block(-1,45,-1,STONE:0)
Block(0,45,-1,STONE:0)
Block(1,45,-1,STONE:0)
Block(2,45,-1,STONE:0)
Block(3,45,-1,STONE:0)
Block(4,45,-1,STONE:0)
Block(5,45,-1,STONE:0)
Block(-8,45,0,STONE:0)
Block(-7,45,0,STONE:0)
Block(-6,45,0,STONE:0)
Block(-5,45,0,STONE:0)
Block(-4,45,0,STONE:0)
Block(-3,45,0,STONE:0)
Block(-2,45,0,STONE:0)
Block(-1,45,0,STONE:0)
Block(0,45,0,STONE:0)
Block(1,45,0,STONE:0)
Block(2,45,0,STONE:0)
Block(3,45,0,STONE:0)
Block(4,45,0,STONE:0)
Block(5,45,0,STONE:0)
Block(-7,45,1,STONE:0)
Block(-6,45,1,STONE:0)
Block(-5,45,1,STONE:0)
Block(-4,45,1,STONE:0)
Block(-3,45,1,STONE:0)
Block(-2,45,1,STONE:0)
Block(-1,45,1,STONE:0)
Block(0,45,1,STONE:0)
Block(1,45,1,STONE:0)
Block(2,45,1,STONE:0)
Block(3,45,1,STONE:0)
Block(4,45,1,STONE:0)
Block(5,45,1,STONE:0)
Block(-6,45,2,STONE:0)
Block(-5,45,2,STONE:0)
Block(-4,45,2,STONE:0)
Block(-3,45,2,STONE:0)
Block(-2,45,2,STONE:0)
Block(-1,45,2,STONE:0)
Block(0,45,2,STONE:0)
Block(1,45,2,STONE:0)
Block(2,45,2,STONE:0)
Block(3,45,2,STONE:0)
Block(4,45,2,STONE:0)
Block(5,45,2,STONE:0)
Block(6,45,2,STONE:0)
Block(-6,45,3,STONE:0)
Block(-5,45,3,STONE:0)
Block(-4,45,3,STONE:0)
Block(-3,45,3,STONE:0)
Block(-2,45,3,STONE:0)
Block(-1,45,3,STONE:0)
Block(0,45,3,STONE:0)
Block(1,45,3,STONE:0)
Block(2,45,3,STONE:0)
Block(3,45,3,STONE:0)
Block(4,45,3,STONE:0)
Block(5,45,3,STONE:0)
Block(6,45,3,STONE:0)
Block(-5,45,4,STONE:0)
Block(-4,45,4,STONE:0)
Block(-3,45,4,STONE:0)
Block(-2,45,4,STONE:0)
Block(-1,45,4,STONE:0)
Block(0,45,4,STONE:0)
Block(1,45,4,STONE:0)
Block(2,45,4,STONE:0)
Block(3,45,4,STONE:0)
Block(4,45,4,STONE:0)
Block(5,45,4,STONE:0)
Block(-5,45,5,STONE:0)
Block(-4,45,5,STONE:0)
Block(-3,45,5,STONE:0)
Block(-2,45,5,STONE:0)
Block(-1,45,5,STONE:0)
Block(0,45,5,STONE:0)
Block(1,45,5,STONE:0)
Block(2,45,5,STONE:0)
Block(3,45,5,STONE:0)
Block(4,45,5,STONE:0)
Block(-3,45,6,STONE:0)
Block(-2,45,6,STONE:0)
Block(-1,45,6,STONE:0)
Block(0,45,6,STONE:0)
Block(1,45,6,STONE:0)
Block(2,45,6,STONE:0)
Block(3,45,6,STONE:0)
Block(-1,45,7,STONE:0)
Block(0,45,7,STONE:0)
Block(-3,46,-7,STONE:0)
Block(-2,46,-7,STONE:0)
Block(-1,46,-7,STONE:0)
Block(0,46,-7,STONE:0)
Block(-4,46,-6,STONE:0)
Block(-3,46,-6,STONE:0)
Block(-2,46,-6,STONE:0)
Block(-1,46,-6,STONE:0)
Block(0,46,-6,STONE:0)
Block(1,46,-6,STONE:0)
Block(2,46,-6,STONE:0)
Block(3,46,-6,STONE:0)
Block(-5,46,-5,STONE:0)
Block(-4,46,-5,STONE:0)
Block(-3,46,-5,STONE:0)
Block(-2,46,-5,STONE:0)
Block(-1,46,-5,STONE:0)
Block(0,46,-5,STONE:0)
Block(1,46,-5,STONE:0)
Block(2,46,-5,STONE:0)
Block(3,46,-5,STONE:0)
Block(4,46,-5,STONE:0)
Block(-6,46,-4,STONE:0)
Block(-5,46,-4,STONE:0)
Block(-4,46,-4,STONE:0)
Block(-3,46,-4,STONE:0)
Block(-2,46,-4,STONE:0)
Block(-1,46,-4,STONE:0)
Block(0,46,-4,STONE:0)
Block(1,46,-4,STONE:0)
Block(2,46,-4,STONE:0)
Block(3,46,-4,STONE:0)
Block(4,46,-4,STONE:0)
Block(-7,46,-3,STONE:0)
Block(-6,46,-3,STONE:0)
Block(-5,46,-3,STONE:0)
Block(-4,46,-3,STONE:0)
Block(-3,46,-3,STONE:0)
Block(-2,46,-3,STONE:0)
Block(-1,46,-3,STONE:0)
Block(0,46,-3,STONE:0)
Block(1,46,-3,STONE:0)
Block(2,46,-3,STONE:0)
Block(3,46,-3,STONE:0)
Block(4,46,-3,STONE:0)
Block(5,46,-3,STONE:0)
Block(-8,46,-2,STONE:0)
Block(-7,46,-2,STONE:0)
Block(-6,46,-2,STONE:0)
Block(-5,46,-2,STONE:0)
Block(-4,46,-2,STONE:0)
Block(-3,46,-2,STONE:0)
Block(-2,46,-2,STONE:0)
Block(-1,46,-2,STONE:0)
Block(0,46,-2,STONE:0)
Block(1,46,-2,STONE:0)
Block(2,46,-2,STONE:0)
Block(3,46,-2,STONE:0)
Block(4,46,-2,STONE:0)
Block(5,46,-2,STONE:0)
Block(-8,46,-1,STONE:0)
Block(-7,46,-1,STONE:0)
Block(-6,46,-1,STONE:0)
Block(-5,46,-1,STONE:0)
Block(-4,46,-1,STONE:0)
Block(-3,46,-1,STONE:0)
Block(-2,46,-1,STONE:0)
Block(-1,46,-1,STONE:0)
Block(0,46,-1,STONE:0)
Block(1,46,-1,STONE:0)
Block(2,46,-1,STONE:0)
Block(3,46,-1,STONE:0)
Block(4,46,-1,STONE:0)
Block(5,46,-1,STONE:0)
Block(6,46,-1,STONE:0)
Block(-8,46,0,STONE:0)
Block(-7,46,0,STONE:0)
Block(-6,46,0,STONE:0)
Block(-5,46,0,STONE:0)
Block(-4,46,0,STONE:0)
Block(-3,46,0,STONE:0)
Block(-2,46,0,STONE:0)
Block(-1,46,0,STONE:0)
Block(0,46,0,STONE:0)
Block(1,46,0,STONE:0)
Block(2,46,0,STONE:0)
Block(3,46,0,STONE:0)
Block(4,46,0,STONE:0)
Block(5,46,0,STONE:0)
Block(6,46,0,STONE:0)
Block(-8,46,1,STONE:0)
Block(-7,46,1,STONE:0)
Block(-6,46,1,STONE:0)
Block(-5,46,1,STONE:0)
Block(-4,46,1,STONE:0)
Block(-3,46,1,STONE:0)
Block(-2,46,1,STONE:0)
Block(-1,46,1,STONE:0)
Block(0,46,1,STONE:0)
Block(1,46,1,STONE:0)
Block(2,46,1,STONE:0)
Block(3,46,1,STONE:0)
Block(4,46,1,STONE:0)
Block(5,46,1,STONE:0)
Block(6,46,1,STONE:0)
Block(-7,46,2,STONE:0)
Block(-6,46,2,STONE:0)
Block(-5,46,2,STONE:0)
Block(-4,46,2,STONE:0)
Block(-3,46,2,STONE:0)
Block(-2,46,2,STONE:0)
Block(-1,46,2,STONE:0)
Block(0,46,2,STONE:0)
Block(1,46,2,STONE:0)
Block(2,46,2,STONE:0)
Block(3,46,2,STONE:0)
Block(4,46,2,STONE:0)
Block(5,46,2,STONE:0)
Block(6,46,2,STONE:0)
Block(-6,46,3,STONE:0)
Block(-5,46,3,STONE:0)
Block(-4,46,3,STONE:0)
Block(-3,46,3,STONE:0)
Block(-2,46,3,STONE:0)
Block(-1,46,3,STONE:0)
Block(0,46,3,STONE:0)
Block(1,46,3,STONE:0)
Block(2,46,3,STONE:0)
Block(3,46,3,STONE:0)
Block(4,46,3,STONE:0)
Block(5,46,3,STONE:0)
Block(6,46,3,STONE:0)
Block(-6,46,4,STONE:0)
Block(-5,46,4,STONE:0)
Block(-4,46,4,STONE:0)
Block(-3,46,4,STONE:0)
Block(-2,46,4,STONE:0)
Block(-1,46,4,STONE:0)
Block(0,46,4,STONE:0)
Block(1,46,4,STONE:0)
Block(2,46,4,STONE:0)
Block(3,46,4,STONE:0)
Block(4,46,4,STONE:0)
Block(5,46,4,STONE:0)
Block(6,46,4,STONE:0)
Block(-5,46,5,STONE:0)
Block(-4,46,5,STONE:0)
Block(-3,46,5,STONE:0)
Block(-2,46,5,STONE:0)
Block(-1,46,5,STONE:0)
Block(0,46,5,STONE:0)
Block(1,46,5,STONE:0)
Block(2,46,5,STONE:0)
Block(3,46,5,STONE:0)
Block(4,46,5,STONE:0)
Block(5,46,5,STONE:0)
Block(-4,46,6,STONE:0)
Block(-3,46,6,STONE:0)
Block(-2,46,6,STONE:0)
Block(-1,46,6,STONE:0)
Block(0,46,6,STONE:0)
Block(1,46,6,STONE:0)
Block(2,46,6,STONE:0)
Block(3,46,6,STONE:0)
Block(4,46,6,STONE:0)
Block(-2,46,7,STONE:0)
Block(-1,46,7,STONE:0)
Block(0,46,7,STONE:0)
Block(1,46,7,STONE:0)
Block(2,46,7,STONE:0)
Block(3,46,7,STONE:0)

#######################################################################
# +-----------------------------------------------------------------+ #
# |                            BO3 checks                           | #
# +-----------------------------------------------------------------+ #
#######################################################################

# Require a condition at a certain location in order for the BO3 to be spawned.
# BlockCheck(x,y,z,BlockName[,BlockName[,...]]) - one of the blocks must be at the location
# BlockCheckNot(x,y,z,BlockName[,BlockName[,...]]) - all the blocks must not be at the location
# LightCheck(x,y,z,minLightLevel,maxLightLevel) - light must be between min and max (inclusive)

# You can use "Solid" as a BlockName for matching all solid blocks or "All" to match all blocks that aren't air.

# Examples:
#   BlockCheck(0,-1,0,GRASS,DIRT)  Require grass or dirt just below the object
#   BlockCheck(0,-1,0,Solid)       Require any solid block just below the object
#   BlockCheck(0,-1,0,WOOL)        Require any type of wool just below the object
#   BlockCheck(0,-1,0,WOOL:0)      Require white wool just below the object
#   BlockCheckNot(0,-1,0,WOOL:0)   Require that there is no white wool below the object
#   LightCheck(0,0,0,0,1)          Require almost complete darkness just below the object

#######################################################################
# +-----------------------------------------------------------------+ #
# |                             Branches                            | #
# +-----------------------------------------------------------------+ #
#######################################################################

# Branches are objects that will spawn when this object spawns when it is used in
# the CustomStructure resource. Branches can also have branches, making complex
# structures possible. See the wiki for more details.

# Regular Branches spawn each branch with an independent chance of spawning.
# Branch(x,y,z,branchName,rotation,chance[,anotherBranchName,rotation,chance[,...]][IndividualChance])
# branchName - name of the object to spawn.
# rotation - NORTH, SOUTH, EAST or WEST.
# IndividualChance - The chance each branch has to spawn, assumed to be 100 when left blank

# Weighted Branches spawn branches with a dependent chance of spawning.
# WeightedBranch(x,y,z,branchName,rotation,chance[,anotherBranchName,rotation,chance[,...]][MaxChanceOutOf])
# MaxChanceOutOf - The chance all branches have to spawn out of, assumed to be 100 when left blank
BlockCheck(-5,0,-6,Solid)
BlockCheck(4,0,-6,Solid)
BlockCheck(7,0,-2,Solid)
BlockCheck(-8,0,2,Solid)
BlockCheck(7,0,2,Solid)
BlockCheck(-5,0,6,Solid)
BlockCheck(4,0,6,Solid)
BlockCheck(-4,46,-7,Solid)
BlockCheck(4,46,-6,Solid)
BlockCheck(-7,46,-4,Solid)
BlockCheck(6,46,-2,Solid)
BlockCheck(-8,46,2,Solid)
BlockCheck(6,46,5,Solid)
BlockCheck(-5,46,6,Solid)
BlockCheck(4,46,7,Solid)


BlockCheck(-1,20,-2,AIR)
BlockCheck(-1,20,2,AIR)
BlockCheck(-1,22,-2,AIR)
BlockCheck(-1,22,2,AIR)
BlockCheck(1,23,0,AIR)
BlockCheck(-1,24,-2,AIR)
BlockCheck(-1,24,2,AIR)
BlockCheck(-2,25,0,AIR)
BlockCheck(1,25,0,AIR)
BlockCheck(-1,26,-2,AIR)
BlockCheck(-1,26,2,AIR)
BlockCheck(-2,27,0,AIR)
BlockCheck(1,27,0,AIR)
BlockCheck(-1,28,-2,AIR)
BlockCheck(-1,28,2,AIR)
BlockCheck(-2,29,0,AIR)
BlockCheck(1,29,0,AIR)
BlockCheck(-1,30,-2,AIR)
BlockCheck(-1,30,2,AIR)
BlockCheck(-1,32,-2,AIR)
