#######################################################################
# +-----------------------------------------------------------------+ #
# |                            BO3 object                           | #
# +-----------------------------------------------------------------+ #
#######################################################################

Author: Bo3 BulkEdit

Description: Converted Schematic - Modified by Bo3BulkEdit

Version: 3

SettingsMode: WriteDisable

#######################################################################
# +-----------------------------------------------------------------+ #
# |                          Main settings                          | #
# +-----------------------------------------------------------------+ #
#######################################################################



Frequency: 0


SpawnHeight: randomY





##############################
# Height Limits for the BO3. #
##############################

MinHeight: 0
MaxHeight: 256

#######################################################################
# +-----------------------------------------------------------------+ #
# |                      Source block settings                      | #
# +-----------------------------------------------------------------+ #
#######################################################################

CanOverride: true
MaxPercentageOutsideSourceBlock: 100
OutsideSourceBlock: placeAnyway

#######################################################################
# +-----------------------------------------------------------------+ #
# |                               OTG+                              | #
# +-----------------------------------------------------------------+ #
#######################################################################

#######################################################################
# +-----------------------------------------------------------------+ #
# |                              Blocks                             | #
# +-----------------------------------------------------------------+ #
#######################################################################

B(0,750,0,AIR)
B(15,750,15,AIR)
B(15,2,15,STAINED_GLASS:15)
B(15,3,14,STAINED_GLASS:15)
B(14,3,15,STAINED_GLASS:15)
B(15,3,15,STAINED_GLASS:15)
B(15,4,13,STAINED_GLASS:15)
B(14,4,14,STAINED_GLASS:6)
B(15,4,14,STAINED_GLASS:15)
B(13,4,15,STAINED_GLASS:15)
B(14,4,15,STAINED_GLASS:15)
B(15,4,15,SEA_LANTERN)
B(15,5,12,STAINED_GLASS:15)
B(14,5,13,STAINED_GLASS:15)
B(15,5,13,STAINED_GLASS:15)
B(13,5,14,STAINED_GLASS:15)
B(14,5,14,STAINED_GLASS:15)
B(15,5,14,SEA_LANTERN)
B(12,5,15,STAINED_GLASS:6)
B(13,5,15,STAINED_GLASS:15)
B(14,5,15,SEA_LANTERN)
B(15,5,15,SEA_LANTERN)
B(14,6,12,STAINED_GLASS:15)
B(15,6,12,STAINED_GLASS:15)
B(13,6,13,STAINED_GLASS:6)
B(14,6,13,STAINED_GLASS:15)
B(15,6,13,STAINED_GLASS:6)
B(12,6,14,STAINED_GLASS:15)
B(13,6,14,STAINED_GLASS:15)
B(14,6,14,SEA_LANTERN)
B(15,6,14,SEA_LANTERN)
B(12,6,15,STAINED_GLASS:15)
B(13,6,15,STAINED_GLASS:15)
B(14,6,15,SEA_LANTERN)
B(15,6,15,SEA_LANTERN)
B(14,7,11,STAINED_GLASS:15)
B(13,7,12,STAINED_GLASS:6)
B(14,7,12,STAINED_GLASS:15)
B(15,7,12,STAINED_GLASS:15)
B(12,7,13,STAINED_GLASS:15)
B(13,7,13,STAINED_GLASS:15)
B(14,7,13,SEA_LANTERN)
B(15,7,13,STAINED_GLASS:15)
B(11,7,14,STAINED_GLASS:15)
B(12,7,14,STAINED_GLASS:15)
B(13,7,14,SEA_LANTERN)
B(14,7,14,SEA_LANTERN)
B(15,7,14,SEA_LANTERN)
B(12,7,15,STAINED_GLASS:15)
B(13,7,15,STAINED_GLASS:15)
B(14,7,15,SEA_LANTERN)
B(15,7,15,STAINED_GLASS:6)
B(13,8,11,STAINED_GLASS:6)
B(14,8,11,STAINED_GLASS:15)
B(12,8,12,STAINED_GLASS:6)
B(13,8,12,STAINED_GLASS:6)
B(14,8,12,STAINED_GLASS:15)
B(15,8,12,STAINED_GLASS:15)
B(11,8,13,STAINED_GLASS:15)
B(12,8,13,STAINED_GLASS:15)
B(13,8,13,SEA_LANTERN)
B(14,8,13,SEA_LANTERN)
B(15,8,13,STAINED_GLASS:6)
B(11,8,14,STAINED_GLASS:15)
B(12,8,14,STAINED_GLASS:15)
B(13,8,14,SEA_LANTERN)
B(14,8,14,SEA_LANTERN)
B(15,8,14,STAINED_GLASS:15)
B(12,8,15,STAINED_GLASS:15)
B(13,8,15,STAINED_GLASS:15)
B(14,8,15,STAINED_GLASS:15)
B(15,8,15,STAINED_GLASS:15)
B(13,9,10,STAINED_GLASS:15)
B(12,9,11,STAINED_GLASS:15)
B(13,9,11,STAINED_GLASS:6)
B(14,9,11,STAINED_GLASS:6)
B(11,9,12,STAINED_GLASS:15)
B(12,9,12,STAINED_GLASS:15)
B(13,9,12,SEA_LANTERN)
B(14,9,12,STAINED_GLASS:15)
B(15,9,12,STAINED_GLASS:6)
B(10,9,13,STAINED_GLASS:15)
B(11,9,13,STAINED_GLASS:15)
B(12,9,13,SEA_LANTERN)
B(13,9,13,SEA_LANTERN)
B(14,9,13,SEA_LANTERN)
B(15,9,13,STAINED_GLASS:15)
B(11,9,14,STAINED_GLASS:6)
B(12,9,14,STAINED_GLASS:15)
B(13,9,14,SEA_LANTERN)
B(14,9,14,STAINED_GLASS:15)
B(15,9,14,STAINED_GLASS:6)
B(12,9,15,STAINED_GLASS:6)
B(13,9,15,STAINED_GLASS:6)
B(14,9,15,STAINED_GLASS:15)
B(12,10,10,STAINED_GLASS:15)
B(13,10,10,STAINED_GLASS:6)
B(11,10,11,STAINED_GLASS:6)
B(12,10,11,STAINED_GLASS:6)
B(13,10,11,STAINED_GLASS:6)
B(14,10,11,STAINED_GLASS:15)
B(10,10,12,STAINED_GLASS:15)
B(11,10,12,STAINED_GLASS:15)
B(12,10,12,SEA_LANTERN)
B(13,10,12,SEA_LANTERN)
B(14,10,12,STAINED_GLASS:15)
B(15,10,12,STAINED_GLASS:6)
B(10,10,13,STAINED_GLASS:15)
B(11,10,13,STAINED_GLASS:15)
B(12,10,13,SEA_LANTERN)
B(13,10,13,SEA_LANTERN)
B(14,10,13,STAINED_GLASS:15)
B(15,10,13,STAINED_GLASS:15)
B(11,10,14,STAINED_GLASS:6)
B(12,10,14,STAINED_GLASS:6)
B(13,10,14,STAINED_GLASS:15)
B(14,10,14,STAINED_GLASS:15)
B(12,10,15,STAINED_GLASS:15)
B(13,10,15,STAINED_GLASS:15)
B(12,11,9,STAINED_GLASS:15)
B(11,11,10,STAINED_GLASS:15)
B(12,11,10,STAINED_GLASS:15)
B(13,11,10,STAINED_GLASS:15)
B(10,11,11,STAINED_GLASS:6)
B(11,11,11,STAINED_GLASS:15)
B(12,11,11,SEA_LANTERN)
B(13,11,11,STAINED_GLASS:15)
B(14,11,11,STAINED_GLASS:6)
B(9,11,12,STAINED_GLASS:15)
B(10,11,12,STAINED_GLASS:15)
B(11,11,12,SEA_LANTERN)
B(12,11,12,SEA_LANTERN)
B(13,11,12,SEA_LANTERN)
B(14,11,12,STAINED_GLASS:15)
B(15,11,12,STAINED_GLASS:6)
B(10,11,13,STAINED_GLASS:6)
B(11,11,13,STAINED_GLASS:15)
B(12,11,13,SEA_LANTERN)
B(13,11,13,STAINED_GLASS:15)
B(14,11,13,STAINED_GLASS:6)
B(11,11,14,STAINED_GLASS:15)
B(12,11,14,STAINED_GLASS:6)
B(13,11,14,STAINED_GLASS:15)
B(12,11,15,STAINED_GLASS:6)
B(11,12,9,STAINED_GLASS:6)
B(12,12,9,STAINED_GLASS:6)
B(10,12,10,STAINED_GLASS:15)
B(11,12,10,STAINED_GLASS:15)
B(12,12,10,STAINED_GLASS:6)
B(13,12,10,STAINED_GLASS:6)
B(9,12,11,STAINED_GLASS:15)
B(10,12,11,STAINED_GLASS:15)
B(11,12,11,SEA_LANTERN)
B(12,12,11,SEA_LANTERN)
B(13,12,11,STAINED_GLASS:15)
B(14,12,11,STAINED_GLASS:15)
B(9,12,12,STAINED_GLASS:15)
B(10,12,12,STAINED_GLASS:15)
B(11,12,12,SEA_LANTERN)
B(12,12,12,SEA_LANTERN)
B(13,12,12,STAINED_GLASS:15)
B(14,12,12,STAINED_GLASS:6)
B(10,12,13,STAINED_GLASS:15)
B(11,12,13,STAINED_GLASS:15)
B(12,12,13,STAINED_GLASS:15)
B(13,12,13,STAINED_GLASS:6)
B(11,12,14,STAINED_GLASS:15)
B(12,12,14,STAINED_GLASS:15)
B(11,13,8,STAINED_GLASS:15)
B(10,13,9,STAINED_GLASS:6)
B(11,13,9,STAINED_GLASS:15)
B(12,13,9,STAINED_GLASS:15)
B(9,13,10,STAINED_GLASS:15)
B(10,13,10,STAINED_GLASS:6)
B(11,13,10,SEA_LANTERN)
B(12,13,10,STAINED_GLASS:15)
B(13,13,10,STAINED_GLASS:15)
B(8,13,11,STAINED_GLASS:15)
B(9,13,11,STAINED_GLASS:15)
B(10,13,11,SEA_LANTERN)
B(11,13,11,SEA_LANTERN)
B(12,13,11,SEA_LANTERN)
B(13,13,11,STAINED_GLASS:15)
B(14,13,11,STAINED_GLASS:15)
B(9,13,12,STAINED_GLASS:15)
B(10,13,12,STAINED_GLASS:6)
B(11,13,12,SEA_LANTERN)
B(12,13,12,STAINED_GLASS:15)
B(13,13,12,STAINED_GLASS:15)
B(10,13,13,STAINED_GLASS:15)
B(11,13,13,STAINED_GLASS:15)
B(12,13,13,STAINED_GLASS:15)
B(11,13,14,STAINED_GLASS:15)
B(10,14,8,STAINED_GLASS:15)
B(11,14,8,STAINED_GLASS:15)
B(9,14,9,STAINED_GLASS:6)
B(10,14,9,STAINED_GLASS:15)
B(11,14,9,STAINED_GLASS:15)
B(12,14,9,STAINED_GLASS:6)
B(8,14,10,STAINED_GLASS:15)
B(9,14,10,STAINED_GLASS:15)
B(10,14,10,SEA_LANTERN)
B(11,14,10,SEA_LANTERN)
B(12,14,10,STAINED_GLASS:6)
B(13,14,10,STAINED_GLASS:6)
B(8,14,11,STAINED_GLASS:15)
B(9,14,11,STAINED_GLASS:15)
B(10,14,11,SEA_LANTERN)
B(11,14,11,SEA_LANTERN)
B(12,14,11,STAINED_GLASS:6)
B(13,14,11,STAINED_GLASS:6)
B(9,14,12,STAINED_GLASS:15)
B(10,14,12,STAINED_GLASS:15)
B(11,14,12,STAINED_GLASS:15)
B(12,14,12,STAINED_GLASS:6)
B(10,14,13,STAINED_GLASS:6)
B(11,14,13,STAINED_GLASS:6)
B(10,15,7,STAINED_GLASS:6)
B(9,15,8,STAINED_GLASS:15)
B(10,15,8,STAINED_GLASS:15)
B(11,15,8,STAINED_GLASS:6)
B(8,15,9,STAINED_GLASS:15)
B(9,15,9,STAINED_GLASS:15)
B(10,15,9,SEA_LANTERN)
B(11,15,9,STAINED_GLASS:15)
B(12,15,9,STAINED_GLASS:15)
B(7,15,10,STAINED_GLASS:6)
B(8,15,10,STAINED_GLASS:6)
B(9,15,10,SEA_LANTERN)
B(10,15,10,SEA_LANTERN)
B(11,15,10,SEA_LANTERN)
B(12,15,10,STAINED_GLASS:15)
B(13,15,10,STAINED_GLASS:15)
B(8,15,11,STAINED_GLASS:15)
B(9,15,11,STAINED_GLASS:15)
B(10,15,11,SEA_LANTERN)
B(11,15,11,STAINED_GLASS:15)
B(12,15,11,STAINED_GLASS:15)
B(9,15,12,STAINED_GLASS:15)
B(10,15,12,STAINED_GLASS:15)
B(11,15,12,STAINED_GLASS:15)
B(10,15,13,STAINED_GLASS:15)
B(9,16,7,STAINED_GLASS:15)
B(10,16,7,STAINED_GLASS:6)
B(8,16,8,STAINED_GLASS:15)
B(9,16,8,STAINED_GLASS:15)
B(10,16,8,STAINED_GLASS:6)
B(11,16,8,STAINED_GLASS:15)
B(7,16,9,STAINED_GLASS:6)
B(8,16,9,STAINED_GLASS:15)
B(9,16,9,SEA_LANTERN)
B(10,16,9,SEA_LANTERN)
B(11,16,9,STAINED_GLASS:15)
B(12,16,9,STAINED_GLASS:15)
B(7,16,10,STAINED_GLASS:6)
B(8,16,10,STAINED_GLASS:6)
B(9,16,10,SEA_LANTERN)
B(10,16,10,SEA_LANTERN)
B(11,16,10,STAINED_GLASS:6)
B(12,16,10,STAINED_GLASS:15)
B(8,16,11,STAINED_GLASS:6)
B(9,16,11,STAINED_GLASS:15)
B(10,16,11,STAINED_GLASS:6)
B(11,16,11,STAINED_GLASS:6)
B(9,16,12,STAINED_GLASS:6)
B(10,16,12,STAINED_GLASS:15)
B(9,17,6,STAINED_GLASS:15)
B(8,17,7,STAINED_GLASS:15)
B(9,17,7,STAINED_GLASS:6)
B(10,17,7,STAINED_GLASS:6)
B(7,17,8,STAINED_GLASS:15)
B(8,17,8,STAINED_GLASS:15)
B(9,17,8,SEA_LANTERN)
B(10,17,8,STAINED_GLASS:15)
B(11,17,8,STAINED_GLASS:6)
B(6,17,9,STAINED_GLASS:15)
B(7,17,9,STAINED_GLASS:15)
B(8,17,9,SEA_LANTERN)
B(9,17,9,SEA_LANTERN)
B(10,17,9,SEA_LANTERN)
B(11,17,9,STAINED_GLASS:6)
B(12,17,9,STAINED_GLASS:15)
B(7,17,10,STAINED_GLASS:15)
B(8,17,10,STAINED_GLASS:15)
B(9,17,10,SEA_LANTERN)
B(10,17,10,STAINED_GLASS:6)
B(11,17,10,STAINED_GLASS:6)
B(8,17,11,STAINED_GLASS:6)
B(9,17,11,STAINED_GLASS:6)
B(10,17,11,STAINED_GLASS:15)
B(9,17,12,STAINED_GLASS:15)
B(8,18,6,STAINED_GLASS:15)
B(9,18,6,STAINED_GLASS:15)
B(7,18,7,STAINED_GLASS:6)
B(8,18,7,STAINED_GLASS:6)
B(9,18,7,STAINED_GLASS:6)
B(10,18,7,STAINED_GLASS:15)
B(6,18,8,STAINED_GLASS:15)
B(7,18,8,STAINED_GLASS:6)
B(8,18,8,SEA_LANTERN)
B(9,18,8,SEA_LANTERN)
B(10,18,8,STAINED_GLASS:6)
B(11,18,8,STAINED_GLASS:15)
B(6,18,9,STAINED_GLASS:15)
B(7,18,9,STAINED_GLASS:15)
B(8,18,9,SEA_LANTERN)
B(9,18,9,SEA_LANTERN)
B(10,18,9,STAINED_GLASS:15)
B(11,18,9,STAINED_GLASS:6)
B(7,18,10,STAINED_GLASS:15)
B(8,18,10,STAINED_GLASS:15)
B(9,18,10,STAINED_GLASS:6)
B(10,18,10,STAINED_GLASS:15)
B(8,18,11,STAINED_GLASS:6)
B(9,18,11,STAINED_GLASS:15)
B(8,19,5,STAINED_GLASS:15)
B(7,19,6,STAINED_GLASS:6)
B(8,19,6,STAINED_GLASS:15)
B(9,19,6,STAINED_GLASS:15)
B(6,19,7,STAINED_GLASS:15)
B(7,19,7,STAINED_GLASS:6)
B(8,19,7,SEA_LANTERN)
B(9,19,7,STAINED_GLASS:15)
B(10,19,7,STAINED_GLASS:6)
B(5,19,8,STAINED_GLASS:6)
B(6,19,8,STAINED_GLASS:6)
B(7,19,8,SEA_LANTERN)
B(8,19,8,SEA_LANTERN)
B(9,19,8,SEA_LANTERN)
B(10,19,8,STAINED_GLASS:15)
B(11,19,8,STAINED_GLASS:15)
B(6,19,9,STAINED_GLASS:15)
B(7,19,9,STAINED_GLASS:15)
B(8,19,9,SEA_LANTERN)
B(9,19,9,STAINED_GLASS:6)
B(10,19,9,STAINED_GLASS:15)
B(7,19,10,STAINED_GLASS:15)
B(8,19,10,STAINED_GLASS:6)
B(9,19,10,STAINED_GLASS:15)
B(8,19,11,STAINED_GLASS:6)
B(7,20,5,STAINED_GLASS:6)
B(8,20,5,STAINED_GLASS:15)
B(6,20,6,STAINED_GLASS:15)
B(7,20,6,STAINED_GLASS:15)
B(8,20,6,STAINED_GLASS:15)
B(9,20,6,STAINED_GLASS:15)
B(5,20,7,STAINED_GLASS:15)
B(6,20,7,STAINED_GLASS:15)
B(7,20,7,SEA_LANTERN)
B(8,20,7,SEA_LANTERN)
B(9,20,7,STAINED_GLASS:15)
B(10,20,7,STAINED_GLASS:15)
B(5,20,8,STAINED_GLASS:15)
B(6,20,8,STAINED_GLASS:15)
B(7,20,8,SEA_LANTERN)
B(8,20,8,SEA_LANTERN)
B(9,20,8,STAINED_GLASS:6)
B(10,20,8,STAINED_GLASS:15)
B(6,20,9,STAINED_GLASS:15)
B(7,20,9,STAINED_GLASS:6)
B(8,20,9,STAINED_GLASS:15)
B(9,20,9,STAINED_GLASS:6)
B(7,20,10,STAINED_GLASS:15)
B(8,20,10,STAINED_GLASS:6)
B(7,21,4,STAINED_GLASS:15)
B(6,21,5,STAINED_GLASS:15)
B(7,21,5,STAINED_GLASS:15)
B(8,21,5,STAINED_GLASS:15)
B(5,21,6,STAINED_GLASS:15)
B(6,21,6,STAINED_GLASS:15)
B(7,21,6,SEA_LANTERN)
B(8,21,6,STAINED_GLASS:15)
B(9,21,6,STAINED_GLASS:15)
B(4,21,7,STAINED_GLASS:6)
B(5,21,7,STAINED_GLASS:15)
B(6,21,7,SEA_LANTERN)
B(7,21,7,SEA_LANTERN)
B(8,21,7,SEA_LANTERN)
B(9,21,7,STAINED_GLASS:15)
B(10,21,7,STAINED_GLASS:15)
B(5,21,8,STAINED_GLASS:15)
B(6,21,8,STAINED_GLASS:6)
B(7,21,8,SEA_LANTERN)
B(8,21,8,STAINED_GLASS:15)
B(9,21,8,STAINED_GLASS:6)
B(6,21,9,STAINED_GLASS:15)
B(7,21,9,STAINED_GLASS:15)
B(8,21,9,STAINED_GLASS:15)
B(7,21,10,STAINED_GLASS:15)
B(6,22,4,STAINED_GLASS:15)
B(7,22,4,STAINED_GLASS:6)
B(5,22,5,STAINED_GLASS:15)
B(6,22,5,STAINED_GLASS:15)
B(7,22,5,STAINED_GLASS:6)
B(8,22,5,STAINED_GLASS:15)
B(4,22,6,STAINED_GLASS:15)
B(5,22,6,STAINED_GLASS:15)
B(6,22,6,SEA_LANTERN)
B(7,22,6,SEA_LANTERN)
B(8,22,6,STAINED_GLASS:15)
B(9,22,6,STAINED_GLASS:15)
B(4,22,7,STAINED_GLASS:15)
B(5,22,7,STAINED_GLASS:15)
B(6,22,7,SEA_LANTERN)
B(7,22,7,SEA_LANTERN)
B(8,22,7,STAINED_GLASS:15)
B(9,22,7,STAINED_GLASS:6)
B(5,22,8,STAINED_GLASS:15)
B(6,22,8,STAINED_GLASS:6)
B(7,22,8,STAINED_GLASS:15)
B(8,22,8,STAINED_GLASS:15)
B(6,22,9,STAINED_GLASS:15)
B(7,22,9,STAINED_GLASS:15)
B(6,23,3,STAINED_GLASS:15)
B(5,23,4,STAINED_GLASS:15)
B(6,23,4,STAINED_GLASS:15)
B(7,23,4,STAINED_GLASS:15)
B(4,23,5,STAINED_GLASS:6)
B(5,23,5,STAINED_GLASS:15)
B(6,23,5,SEA_LANTERN)
B(7,23,5,STAINED_GLASS:15)
B(8,23,5,STAINED_GLASS:6)
B(3,23,6,STAINED_GLASS:6)
B(4,23,6,STAINED_GLASS:15)
B(5,23,6,SEA_LANTERN)
B(6,23,6,SEA_LANTERN)
B(7,23,6,SEA_LANTERN)
B(8,23,6,STAINED_GLASS:15)
B(9,23,6,STAINED_GLASS:15)
B(4,23,7,STAINED_GLASS:6)
B(5,23,7,STAINED_GLASS:15)
B(6,23,7,SEA_LANTERN)
B(7,23,7,STAINED_GLASS:15)
B(8,23,7,STAINED_GLASS:6)
B(5,23,8,STAINED_GLASS:6)
B(6,23,8,STAINED_GLASS:15)
B(7,23,8,STAINED_GLASS:15)
B(6,23,9,STAINED_GLASS:15)
B(5,24,3,STAINED_GLASS:6)
B(6,24,3,STAINED_GLASS:6)
B(4,24,4,STAINED_GLASS:15)
B(5,24,4,STAINED_GLASS:15)
B(6,24,4,STAINED_GLASS:15)
B(7,24,4,STAINED_GLASS:15)
B(3,24,5,STAINED_GLASS:6)
B(4,24,5,STAINED_GLASS:6)
B(5,24,5,SEA_LANTERN)
B(6,24,5,SEA_LANTERN)
B(7,24,5,STAINED_GLASS:6)
B(8,24,5,STAINED_GLASS:15)
B(3,24,6,STAINED_GLASS:15)
B(4,24,6,STAINED_GLASS:15)
B(5,24,6,SEA_LANTERN)
B(6,24,6,SEA_LANTERN)
B(7,24,6,STAINED_GLASS:15)
B(8,24,6,STAINED_GLASS:15)
B(4,24,7,STAINED_GLASS:6)
B(5,24,7,STAINED_GLASS:15)
B(6,24,7,STAINED_GLASS:15)
B(7,24,7,STAINED_GLASS:15)
B(5,24,8,STAINED_GLASS:15)
B(6,24,8,STAINED_GLASS:6)
B(5,25,2,STAINED_GLASS:15)
B(4,25,3,STAINED_GLASS:6)
B(5,25,3,STAINED_GLASS:6)
B(6,25,3,STAINED_GLASS:15)
B(3,25,4,STAINED_GLASS:15)
B(4,25,4,STAINED_GLASS:15)
B(5,25,4,SEA_LANTERN)
B(6,25,4,STAINED_GLASS:15)
B(7,25,4,STAINED_GLASS:6)
B(2,25,5,STAINED_GLASS:15)
B(3,25,5,STAINED_GLASS:15)
B(4,25,5,SEA_LANTERN)
B(5,25,5,SEA_LANTERN)
B(6,25,5,SEA_LANTERN)
B(7,25,5,STAINED_GLASS:6)
B(8,25,5,STAINED_GLASS:15)
B(3,25,6,STAINED_GLASS:15)
B(4,25,6,STAINED_GLASS:15)
B(5,25,6,SEA_LANTERN)
B(6,25,6,STAINED_GLASS:15)
B(7,25,6,STAINED_GLASS:15)
B(4,25,7,STAINED_GLASS:15)
B(5,25,7,STAINED_GLASS:15)
B(6,25,7,STAINED_GLASS:15)
B(5,25,8,STAINED_GLASS:15)
B(4,26,2,STAINED_GLASS:15)
B(5,26,2,STAINED_GLASS:15)
B(3,26,3,STAINED_GLASS:15)
B(4,26,3,STAINED_GLASS:15)
B(5,26,3,STAINED_GLASS:6)
B(6,26,3,STAINED_GLASS:15)
B(2,26,4,STAINED_GLASS:6)
B(3,26,4,STAINED_GLASS:15)
B(4,26,4,SEA_LANTERN)
B(5,26,4,SEA_LANTERN)
B(6,26,4,STAINED_GLASS:15)
B(7,26,4,STAINED_GLASS:6)
B(2,26,5,STAINED_GLASS:15)
B(3,26,5,STAINED_GLASS:15)
B(4,26,5,SEA_LANTERN)
B(5,26,5,SEA_LANTERN)
B(6,26,5,STAINED_GLASS:15)
B(7,26,5,STAINED_GLASS:15)
B(3,26,6,STAINED_GLASS:15)
B(4,26,6,STAINED_GLASS:15)
B(5,26,6,STAINED_GLASS:15)
B(6,26,6,STAINED_GLASS:6)
B(4,26,7,STAINED_GLASS:15)
B(5,26,7,STAINED_GLASS:6)
B(4,27,1,STAINED_GLASS:15)
B(3,27,2,STAINED_GLASS:15)
B(4,27,2,STAINED_GLASS:6)
B(5,27,2,STAINED_GLASS:15)
B(2,27,3,STAINED_GLASS:15)
B(3,27,3,STAINED_GLASS:15)
B(4,27,3,SEA_LANTERN)
B(5,27,3,STAINED_GLASS:15)
B(6,27,3,STAINED_GLASS:15)
B(1,27,4,STAINED_GLASS:15)
B(2,27,4,STAINED_GLASS:15)
B(3,27,4,SEA_LANTERN)
B(4,27,4,SEA_LANTERN)
B(5,27,4,SEA_LANTERN)
B(6,27,4,STAINED_GLASS:15)
B(7,27,4,STAINED_GLASS:15)
B(2,27,5,STAINED_GLASS:6)
B(3,27,5,STAINED_GLASS:15)
B(4,27,5,SEA_LANTERN)
B(5,27,5,STAINED_GLASS:15)
B(6,27,5,STAINED_GLASS:6)
B(3,27,6,STAINED_GLASS:15)
B(4,27,6,STAINED_GLASS:15)
B(5,27,6,STAINED_GLASS:15)
B(4,27,7,STAINED_GLASS:6)
B(3,28,1,STAINED_GLASS:6)
B(4,28,1,STAINED_GLASS:6)
B(2,28,2,STAINED_GLASS:15)
B(3,28,2,STAINED_GLASS:15)
B(4,28,2,STAINED_GLASS:15)
B(5,28,2,STAINED_GLASS:15)
B(1,28,3,STAINED_GLASS:6)
B(2,28,3,STAINED_GLASS:15)
B(3,28,3,SEA_LANTERN)
B(4,28,3,SEA_LANTERN)
B(5,28,3,STAINED_GLASS:15)
B(6,28,3,STAINED_GLASS:15)
B(1,28,4,STAINED_GLASS:15)
B(2,28,4,STAINED_GLASS:15)
B(3,28,4,SEA_LANTERN)
B(4,28,4,SEA_LANTERN)
B(5,28,4,STAINED_GLASS:6)
B(6,28,4,STAINED_GLASS:15)
B(2,28,5,STAINED_GLASS:15)
B(3,28,5,STAINED_GLASS:15)
B(4,28,5,STAINED_GLASS:15)
B(5,28,5,STAINED_GLASS:15)
B(3,28,6,STAINED_GLASS:6)
B(4,28,6,STAINED_GLASS:15)
B(3,29,0,STAINED_GLASS:6)
B(2,29,1,STAINED_GLASS:15)
B(3,29,1,STAINED_GLASS:15)
B(4,29,1,STAINED_GLASS:15)
B(1,29,2,STAINED_GLASS:15)
B(2,29,2,STAINED_GLASS:6)
B(3,29,2,SEA_LANTERN)
B(4,29,2,STAINED_GLASS:15)
B(5,29,2,STAINED_GLASS:15)
B(0,29,3,STAINED_GLASS:6)
B(1,29,3,STAINED_GLASS:6)
B(2,29,3,SEA_LANTERN)
B(3,29,3,SEA_LANTERN)
B(4,29,3,SEA_LANTERN)
B(5,29,3,STAINED_GLASS:6)
B(6,29,3,STAINED_GLASS:6)
B(1,29,4,STAINED_GLASS:15)
B(2,29,4,STAINED_GLASS:15)
B(3,29,4,SEA_LANTERN)
B(4,29,4,STAINED_GLASS:15)
B(5,29,4,STAINED_GLASS:15)
B(2,29,5,STAINED_GLASS:6)
B(3,29,5,STAINED_GLASS:6)
B(4,29,5,STAINED_GLASS:15)
B(3,29,6,STAINED_GLASS:15)
B(2,30,0,STAINED_GLASS:15)
B(3,30,0,STAINED_GLASS:15)
B(1,30,1,STAINED_GLASS:6)
B(2,30,1,STAINED_GLASS:15)
B(3,30,1,STAINED_GLASS:6)
B(4,30,1,STAINED_GLASS:6)
B(0,30,2,STAINED_GLASS:15)
B(1,30,2,STAINED_GLASS:15)
B(2,30,2,SEA_LANTERN)
B(3,30,2,SEA_LANTERN)
B(4,30,2,STAINED_GLASS:15)
B(5,30,2,STAINED_GLASS:6)
B(0,30,3,STAINED_GLASS:15)
B(1,30,3,STAINED_GLASS:6)
B(2,30,3,SEA_LANTERN)
B(3,30,3,SEA_LANTERN)
B(4,30,3,STAINED_GLASS:15)
B(5,30,3,STAINED_GLASS:15)
B(1,30,4,STAINED_GLASS:15)
B(2,30,4,STAINED_GLASS:6)
B(3,30,4,STAINED_GLASS:15)
B(4,30,4,STAINED_GLASS:6)
B(2,30,5,STAINED_GLASS:6)
B(3,30,5,STAINED_GLASS:6)
B(2,31,0,STAINED_GLASS:6)
B(3,31,0,STAINED_GLASS:15)
B(1,31,1,STAINED_GLASS:15)
B(2,31,1,SEA_LANTERN)
B(3,31,1,STAINED_GLASS:15)
B(4,31,1,STAINED_GLASS:15)
B(0,31,2,STAINED_GLASS:15)
B(1,31,2,SEA_LANTERN)
B(2,31,2,SEA_LANTERN)
B(3,31,2,SEA_LANTERN)
B(4,31,2,STAINED_GLASS:15)
B(5,31,2,STAINED_GLASS:15)
B(0,31,3,STAINED_GLASS:15)
B(1,31,3,STAINED_GLASS:15)
B(2,31,3,SEA_LANTERN)
B(3,31,3,STAINED_GLASS:6)
B(4,31,3,STAINED_GLASS:15)
B(1,31,4,STAINED_GLASS:15)
B(2,31,4,STAINED_GLASS:15)
B(3,31,4,STAINED_GLASS:15)
B(2,31,5,STAINED_GLASS:15)
B(1,32,0,STAINED_GLASS:15)
B(2,32,0,STAINED_GLASS:15)
B(3,32,0,STAINED_GLASS:15)
B(0,32,1,STAINED_GLASS:15)
B(1,32,1,SEA_LANTERN)
B(2,32,1,SEA_LANTERN)
B(3,32,1,STAINED_GLASS:15)
B(4,32,1,STAINED_GLASS:15)
B(0,32,2,STAINED_GLASS:15)
B(1,32,2,SEA_LANTERN)
B(2,32,2,SEA_LANTERN)
B(3,32,2,STAINED_GLASS:15)
B(4,32,2,STAINED_GLASS:6)
B(0,32,3,STAINED_GLASS:15)
B(1,32,3,STAINED_GLASS:6)
B(2,32,3,STAINED_GLASS:15)
B(3,32,3,STAINED_GLASS:6)
B(1,32,4,STAINED_GLASS:15)
B(2,32,4,STAINED_GLASS:15)
B(1,33,0,STAINED_GLASS:15)
B(2,33,0,STAINED_GLASS:15)
B(0,33,1,STAINED_GLASS:15)
B(1,33,1,SEA_LANTERN)
B(2,33,1,STAINED_GLASS:15)
B(3,33,1,STAINED_GLASS:15)
B(0,33,2,STAINED_GLASS:15)
B(1,33,2,STAINED_GLASS:15)
B(2,33,2,STAINED_GLASS:15)
B(3,33,2,STAINED_GLASS:15)
B(1,33,3,STAINED_GLASS:15)
B(2,33,3,STAINED_GLASS:15)
B(1,34,0,STAINED_GLASS:6)
B(0,34,1,STAINED_GLASS:15)
B(1,34,1,STAINED_GLASS:15)
B(2,34,1,STAINED_GLASS:6)
B(1,34,2,STAINED_GLASS:15)
B(2,34,2,STAINED_GLASS:15)
B(1,35,1,STAINED_GLASS:15)

