
#######################################################################
# +-----------------------------------------------------------------+ #
# |                            BO3 object                           | #
# +-----------------------------------------------------------------+ #
#######################################################################

Author: NLBlackEagle

Description: No description given

Version: 3

SettingsMode: WriteDisable


#######################################################################
# +-----------------------------------------------------------------+ #
# |                          Main settings                          | #
# +-----------------------------------------------------------------+ #
#######################################################################

Tree: false

Frequency: 1

Rarity: 100.0

RotateRandomly: false

SpawnHeight: highestSolidBlock

SpawnHeightOffset: 5

SpawnHeightVariance: 0

##############################
# Height Limits for the BO3. #
##############################

MinHeight: 0

MaxHeight: 256

######################
# Extrusion settings #
######################

ExtrudeMode: None

ExtrudeThroughBlocks: AIR

MaxBranchDepth: 10

ExcludedBiomes: All


#######################################################################
# +-----------------------------------------------------------------+ #
# |                      Source block settings                      | #
# +-----------------------------------------------------------------+ #
#######################################################################

SourceBlocks: AIR

MaxPercentageOutsideSourceBlock: 100

OutsideSourceBlock: placeAnyway

IsOTGPlus: false

InheritBO3: 

InheritBO3Rotation: NORTH

OverrideChildSettings: true

OverrideParentHeight: false

CanOverride: false

BranchFrequency: 0

BranchFrequencyGroup: 

MustBeBelowOther: false

MustBeInside: 

CannotBeInside: 

ReplacesBO3: 

CanSpawnOnWater: true

SpawnOnWaterOnly: false

SpawnUnderWater: false

SpawnAtWaterLevel: false

HeightOffset: 0

RemoveAir: true

ReplaceAbove: 

ReplaceBelow: 

ReplaceWithBiomeBlocks: true

ReplaceWithGroundBlock: DIRT

ReplaceWithSurfaceBlock: GRASS

SmoothRadius: 0

SmoothHeightOffset: 0

SmoothStartTop: false

SmoothStartWood: false

SmoothingSurfaceBlock: 

SmoothingGroundBlock: 

BO3Group: 

IsSpawnPoint: false


#######################################################################
# +-----------------------------------------------------------------+ #
# |                              Blocks                             | #
# +-----------------------------------------------------------------+ #
#######################################################################

Block(-6,0,-6,WOOD_STEP:13)
Block(-6,0,-5,WOOD_STEP:13)
Block(-6,0,-3,WOOD_STEP:13)
Block(-6,0,-2,WOOD_STEP:13)
Block(-6,0,-1,WOOD_STEP:13)
Block(-6,0,0,WOOD_STEP:13)
Block(-6,0,1,WOOD_STEP:13)
Block(-6,0,3,WOOD_STEP:13)
Block(-6,0,4,WOOD_STEP:13)
Block(-6,0,5,WOOD_STEP:13)
Block(-6,0,6,WOOD_STEP:13)
Block(-6,0,7,WOOD_STEP:13)
Block(-6,1,-7,LOG:1)
Block(-6,1,-6,SPRUCE_FENCE)
Block(-6,1,-5,SPRUCE_FENCE)
Block(-6,1,-4,LOG:1)
Block(-6,1,-3,SPRUCE_FENCE)
Block(-6,1,-2,DARK_OAK_FENCE_GATE:3)
Block(-6,1,-1,SPRUCE_FENCE)
Block(-6,1,0,DARK_OAK_FENCE_GATE:3)
Block(-6,1,1,SPRUCE_FENCE)
Block(-6,1,2,LOG:1)
Block(-6,1,3,SPRUCE_FENCE)
Block(-6,1,4,DARK_OAK_FENCE_GATE:3)
Block(-6,1,5,SPRUCE_FENCE)
Block(-6,1,6,DARK_OAK_FENCE_GATE:3)
Block(-6,1,7,SPRUCE_FENCE)
Block(-6,1,8,LOG:1)
Block(-6,2,-7,WOOD_STEP:5)
Block(-6,2,-4,WOOD_STEP:5)
Block(-6,2,2,WOOD_STEP:5)
Block(-6,2,8,WOOD_STEP:5)
Block(-5,0,-7,WOOD_STEP:13)
Block(-5,0,-6,WOOD_STEP:13)
Block(-5,0,-5,WOOD_STEP:13)
Block(-5,0,-4,WOOD_STEP:13)
Block(-5,0,-3,WOOD_STEP:13)
Block(-5,0,-2,WOOD_STEP:13)
Block(-5,0,-1,WOOD_STEP:13)
Block(-5,0,0,WOOD_STEP:13)
Block(-5,0,1,WOOD_STEP:13)
Block(-5,0,2,WOOD_STEP:13)
Block(-5,0,3,WOOD_STEP:13)
Block(-5,0,4,WOOD_STEP:13)
Block(-5,0,5,WOOD_STEP:13)
Block(-5,0,6,WOOD_STEP:13)
Block(-5,0,7,WOOD_STEP:13)
Block(-5,0,8,WOOD_STEP:13)
Block(-5,1,-7,SPRUCE_FENCE)
Block(-5,1,8,SPRUCE_FENCE)
Block(-4,0,-7,WOOD_STEP:13)
Block(-4,0,-6,WOOD_STEP:13)
Block(-4,0,-5,WOOD_STEP:13)
Block(-4,0,-4,WOOD_STEP:13)
Block(-4,0,-3,WOOD_STEP:13)
Block(-4,0,-2,WOOD_STEP:13)
Block(-4,0,-1,WOOD_STEP:13)
Block(-4,0,0,WOOD_STEP:13)
Block(-4,0,1,WOOD_STEP:13)
Block(-4,0,2,WOOD_STEP:13)
Block(-4,0,3,WOOD_STEP:13)
Block(-4,0,4,WOOD_STEP:13)
Block(-4,0,5,WOOD_STEP:13)
Block(-4,0,6,WOOD_STEP:13)
Block(-4,0,7,WOOD_STEP:13)
Block(-4,0,8,WOOD_STEP:13)
Block(-4,1,-7,DARK_OAK_FENCE_GATE:0)
Block(-4,1,8,DARK_OAK_FENCE_GATE)
Block(-4,3,-6,DARK_OAK_STAIRS:0)
Block(-4,3,-5,DARK_OAK_STAIRS:0)
Block(-4,3,-4,DARK_OAK_STAIRS:0)
Block(-4,3,-3,DARK_OAK_STAIRS:0)
Block(-4,3,-2,DARK_OAK_STAIRS:0)
Block(-4,3,-1,DARK_OAK_STAIRS:0)
Block(-3,0,-7,WOOD_STEP:13)
Block(-3,0,-6,WOOD_STEP:13)
Block(-3,0,-4,WOOD:1)
Block(-3,0,-3,WOOD:1)
Block(-3,0,-1,WOOD_STEP:13)
Block(-3,0,0,WOOD_STEP:13)
Block(-3,0,1,WOOD_STEP:13)
Block(-3,0,2,WOOD_STEP:13)
Block(-3,0,4,WOOD_DOUBLE_STEP:5)
Block(-3,0,5,WOOD_DOUBLE_STEP:5)
Block(-3,0,7,WOOD_STEP:13)
Block(-3,0,8,WOOD_STEP:13)
Block(-3,1,-7,SPRUCE_FENCE)
Block(-3,1,-5,LOG:1)
Block(-3,1,-4,WOOD:1)
Block(-3,1,-3,WOOD:1)
Block(-3,1,-2,LOG:1)
Block(-3,1,3,LOG:1)
Block(-3,1,6,LOG:1)
Block(-3,1,8,SPRUCE_FENCE)
Block(-3,2,-5,LOG:1)
Block(-3,2,-4,WOOD:1)
Block(-3,2,-3,WOOD:1)
Block(-3,2,-2,LOG:1)
Block(-3,2,3,LOG:1)
Block(-3,2,6,LOG:1)
Block(-3,3,-6,DARK_OAK_STAIRS:5)
Block(-3,3,-5,LOG:1)
Block(-3,3,-4,WOOD:1)
Block(-3,3,-3,WOOD:1)
Block(-3,3,-2,LOG:1)
Block(-3,3,-1,DARK_OAK_STAIRS:5)
Block(-3,3,3,LOG:1)
Block(-3,3,4,WOOD_STEP:13)
Block(-3,3,5,WOOD_STEP:13)
Block(-3,3,6,LOG:1)
Block(-3,4,-6,DARK_OAK_STAIRS:0)
Block(-3,4,-5,SPRUCE_WOOD_STAIRS:0)
Block(-3,4,-4,SPRUCE_WOOD_STAIRS:0)
Block(-3,4,-3,SPRUCE_WOOD_STAIRS:0)
Block(-3,4,-2,SPRUCE_WOOD_STAIRS:0)
Block(-3,4,-1,DARK_OAK_STAIRS:0)
Block(-3,4,3,LOG:1)
Block(-3,4,4,WOOD_STEP:1)
Block(-3,4,5,WOOD_STEP:1)
Block(-3,4,6,LOG:1)
Block(-3,5,3,LOG:1)
Block(-3,5,6,LOG:1)
Block(-3,6,3,LOG:1)
Block(-3,6,4,TRAP_DOOR:6)
Block(-3,6,5,TRAP_DOOR:6)
Block(-3,6,6,LOG:1)
Block(-3,7,3,LOG:1)
Block(-3,7,4,WOOD_STEP:13)
Block(-3,7,5,WOOD_STEP:13)
Block(-3,7,6,LOG:1)
Block(-3,8,3,DARK_OAK_STAIRS:0)
Block(-3,8,4,WOOD_STEP:1)
Block(-3,8,5,WOOD_STEP:1)
Block(-3,8,6,DARK_OAK_STAIRS:0)
Block(-2,0,-5,WOOD:1)
Block(-2,0,-4,WOOD:1)
Block(-2,0,-3,WOOD:1)
Block(-2,0,-2,WOOD:1)
Block(-2,0,-1,WOOD_STEP:13)
Block(-2,0,0,WOOD_DOUBLE_STEP:5)
Block(-2,0,1,WOOD_DOUBLE_STEP:5)
Block(-2,0,3,AIR)
Block(-2,0,4,AIR)
Block(-2,0,5,AIR)
Block(-2,0,6,AIR)
Block(-2,1,-7,LOG:1)
Block(-2,1,-6,LOG:1)
Block(-2,1,-5,WOOD_STEP:13)
Block(-2,1,-4,AIR)
Block(-2,1,-3,AIR)
Block(-2,1,-2,WOOD:1)
Block(-2,1,2,LOG:1)
Block(-2,1,3,AIR)
Block(-2,1,4,TRAP_DOOR:15)
Block(-2,1,5,TRAP_DOOR:15)
Block(-2,1,6,AIR)
Block(-2,1,7,LOG:1)
Block(-2,1,8,LOG:1)
Block(-2,2,-7,DARK_OAK_STAIRS:2)
Block(-2,2,-6,WOOD:1)
Block(-2,2,-5,TORCH)
Block(-2,2,-4,AIR)
Block(-2,2,-3,AIR)
Block(-2,2,-2,WOOD:1)
Block(-2,2,2,LOG:1)
Block(-2,2,3,AIR)
Block(-2,2,4,TRAP_DOOR:7)
Block(-2,2,5,TRAP_DOOR:7)
Block(-2,2,6,AIR)
Block(-2,2,7,LOG:1)
Block(-2,2,8,DARK_OAK_STAIRS:0)
Block(-2,3,-5,WOOD:1)
Block(-2,3,-4,AIR)
Block(-2,3,-3,AIR)
Block(-2,3,-2,WOOD:1)
Block(-2,3,2,LOG:1)
Block(-2,3,3,AIR)
Block(-2,3,4,TRAP_DOOR:15)
Block(-2,3,5,TRAP_DOOR:15)
Block(-2,3,6,AIR)
Block(-2,3,7,LOG:1)
Block(-2,4,-6,DARK_OAK_STAIRS:5)
Block(-2,4,-5,WOOD:1)
Block(-2,4,-4,SPRUCE_WOOD_STAIRS:5)
Block(-2,4,-3,SPRUCE_WOOD_STAIRS:5)
Block(-2,4,-2,WOOD:1)
Block(-2,4,-1,DARK_OAK_STAIRS:5)
Block(-2,4,2,LOG:1)
Block(-2,4,3,LOG:5)
Block(-2,4,4,LOG:9)
Block(-2,4,5,LOG:9)
Block(-2,4,6,LOG:9)
Block(-2,4,7,LOG:1)
Block(-2,5,-6,DARK_OAK_STAIRS:0)
Block(-2,5,-5,SPRUCE_WOOD_STAIRS:0)
Block(-2,5,-4,SPRUCE_WOOD_STAIRS:0)
Block(-2,5,-3,SPRUCE_WOOD_STAIRS:0)
Block(-2,5,-2,SPRUCE_WOOD_STAIRS:0)
Block(-2,5,-1,DARK_OAK_STAIRS:0)
Block(-2,5,2,LOG:1)
Block(-2,5,3,AIR)
Block(-2,5,4,TRAP_DOOR:7)
Block(-2,5,5,TRAP_DOOR:7)
Block(-2,5,6,AIR)
Block(-2,5,7,LOG:1)
Block(-2,6,2,LOG:1)
Block(-2,6,3,WOOD_STEP:13)
Block(-2,6,4,WOOD_STEP:13)
Block(-2,6,5,WOOD_STEP:13)
Block(-2,6,6,WOOD_STEP:13)
Block(-2,6,7,LOG:1)
Block(-2,7,2,LOG:1)
Block(-2,7,3,AIR)
Block(-2,7,4,TRAP_DOOR:15)
Block(-2,7,5,TRAP_DOOR:15)
Block(-2,7,6,AIR)
Block(-2,7,7,LOG:1)
Block(-2,8,2,DARK_OAK_STAIRS:2)
Block(-2,8,3,LOG:9)
Block(-2,8,4,LOG:9)
Block(-2,8,5,LOG:9)
Block(-2,8,6,LOG:5)
Block(-2,8,7,DARK_OAK_STAIRS:0)
Block(-1,0,-7,WOOD_STEP:13)
Block(-1,0,-6,WOOD:1)
Block(-1,0,-5,WOOD:1)
Block(-1,0,-4,WOOD:1)
Block(-1,0,-3,WOOD:1)
Block(-1,0,-2,WOOD:1)
Block(-1,0,-1,WOOD_STEP:13)
Block(-1,0,0,DARK_OAK_STAIRS:0)
Block(-1,0,2,SPRUCE_DOOR)
Block(-1,0,3,AIR)
Block(-1,0,4,AIR)
Block(-1,0,5,AIR)
Block(-1,0,6,AIR)
Block(-1,0,7,WOOD_DOUBLE_STEP:5)
Block(-1,0,8,WOOD_STEP:13)
Block(-1,1,-7,SPRUCE_FENCE)
Block(-1,1,-6,WOOD:1)
Block(-1,1,-5,WOOD_STEP:13)
Block(-1,1,-4,AIR)
Block(-1,1,-3,AIR)
Block(-1,1,-2,SPRUCE_DOOR:1)
Block(-1,1,2,SPRUCE_DOOR:8)
Block(-1,1,3,AIR)
Block(-1,1,4,AIR)
Block(-1,1,5,AIR)
Block(-1,1,6,TRAP_DOOR:12)
Block(-1,1,8,SPRUCE_FENCE)
Block(-1,2,-6,WOOD:1)
Block(-1,2,-5,AIR)
Block(-1,2,-4,AIR)
Block(-1,2,-3,AIR)
Block(-1,2,-2,SPRUCE_DOOR:9)
Block(-1,2,2,WOOD_STEP:5)
Block(-1,2,3,TRAP_DOOR:5)
Block(-1,2,4,AIR)
Block(-1,2,5,AIR)
Block(-1,2,6,TRAP_DOOR:4)
Block(-1,3,-6,DARK_OAK_STAIRS:2)
Block(-1,3,-5,SPRUCE_WOOD_STAIRS:7)
Block(-1,3,-4,AIR)
Block(-1,3,-3,AIR)
Block(-1,3,-2,WOOD:1)
Block(-1,3,2,WOOD_STEP:13)
Block(-1,3,3,TRAP_DOOR:13)
Block(-1,3,4,AIR)
Block(-1,3,5,AIR)
Block(-1,3,6,TRAP_DOOR:12)
Block(-1,3,7,WOOD_STEP:13)
Block(-1,4,-5,WOOD:1)
Block(-1,4,-4,AIR)
Block(-1,4,-3,AIR)
Block(-1,4,-2,WOOD:1)
Block(-1,4,2,WOOD_STEP:1)
Block(-1,4,3,LOG:5)
Block(-1,4,4,AIR)
Block(-1,4,5,AIR)
Block(-1,4,6,LOG:5)
Block(-1,4,7,WOOD_STEP:1)
Block(-1,5,-6,DARK_OAK_STAIRS:5)
Block(-1,5,-5,WOOD:1)
Block(-1,5,-4,SPRUCE_WOOD_STAIRS:5)
Block(-1,5,-3,SPRUCE_WOOD_STAIRS:5)
Block(-1,5,-2,WOOD:1)
Block(-1,5,-1,DARK_OAK_STAIRS:5)
Block(-1,5,3,TRAP_DOOR:5)
Block(-1,5,4,AIR)
Block(-1,5,5,AIR)
Block(-1,5,6,TRAP_DOOR:4)
Block(-1,6,-6,DARK_OAK_STAIRS:0)
Block(-1,6,-5,SPRUCE_WOOD_STAIRS:0)
Block(-1,6,-4,SPRUCE_WOOD_STAIRS:0)
Block(-1,6,-3,SPRUCE_WOOD_STAIRS:0)
Block(-1,6,-2,SPRUCE_WOOD_STAIRS:0)
Block(-1,6,-1,DARK_OAK_STAIRS:0)
Block(-1,6,2,TRAP_DOOR:4)
Block(-1,6,3,WOOD_STEP:13)
Block(-1,6,4,AIR)
Block(-1,6,5,AIR)
Block(-1,6,6,WOOD_STEP:13)
Block(-1,6,7,TRAP_DOOR:5)
Block(-1,7,2,WOOD_STEP:13)
Block(-1,7,3,TRAP_DOOR:13)
Block(-1,7,4,AIR)
Block(-1,7,5,AIR)
Block(-1,7,6,TRAP_DOOR:12)
Block(-1,7,7,WOOD_STEP:13)
Block(-1,8,2,WOOD_STEP:1)
Block(-1,8,3,LOG:5)
Block(-1,8,4,WOOD_STEP:9)
Block(-1,8,5,WOOD_STEP:9)
Block(-1,8,6,LOG:5)
Block(-1,8,7,WOOD_STEP:1)
B(0,0,-7,WOOD_STEP:13)
B(0,0,-6,WOOD:1)
B(0,0,-5,WOOD:1)
B(0,0,-4,WOOD:1)
B(0,0,-3,LADDER:4)
B(0,0,-2,WOOD:1)
B(0,0,-1,WOOD_STEP:13)
B(0,0,0,DARK_OAK_STAIRS:0)
B(0,0,2,SPRUCE_DOOR)
B(0,0,3,AIR)
B(0,0,4,AIR)
B(0,0,5,AIR)
B(0,0,6,AIR)
B(0,0,7,WOOD_DOUBLE_STEP:5)
B(0,0,8,WOOD_STEP:13)
B(0,1,-7,SPRUCE_FENCE)
B(0,1,-6,WOOD:1)
B(0,1,-5,WOOD_STEP:13)
B(0,1,-4,AIR)
B(0,1,-3,AIR)
B(0,1,-2,SPRUCE_DOOR:1)
B(0,1,2,SPRUCE_DOOR:9)
B(0,1,3,AIR)
B(0,1,4,AIR)
B(0,1,5,AIR)
B(0,1,6,TRAP_DOOR:12)
B(0,1,8,SPRUCE_FENCE)
B(0,2,-6,WOOD:1)
B(0,2,-5,AIR)
B(0,2,-4,AIR)
B(0,2,-3,AIR)
B(0,2,-2,SPRUCE_DOOR:8)
B(0,2,2,WOOD_STEP:5)
B(0,2,3,TRAP_DOOR:5)
B(0,2,4,AIR)
B(0,2,5,AIR)
B(0,2,6,TRAP_DOOR:4)
B(0,3,-6,DARK_OAK_STAIRS:2)
B(0,3,-5,SPRUCE_WOOD_STAIRS:7)
B(0,3,-4,AIR)
B(0,3,-3,AIR)
B(0,3,-2,WOOD:1)
B(0,3,2,WOOD_STEP:13)
B(0,3,3,TRAP_DOOR:13)
B(0,3,4,AIR)
B(0,3,5,AIR)
B(0,3,6,TRAP_DOOR:12)
B(0,3,7,WOOD_STEP:13)
B(0,4,-5,WOOD:1)
B(0,4,-4,AIR)
B(0,4,-3,AIR)
B(0,4,-2,WOOD:1)
B(0,4,2,WOOD_STEP:1)
B(0,4,3,LOG:5)
B(0,4,4,AIR)
B(0,4,5,AIR)
B(0,4,6,LOG:5)
B(0,4,7,WOOD_STEP:1)
B(0,5,-6,DARK_OAK_STAIRS:4)
B(0,5,-5,WOOD:1)
B(0,5,-4,SPRUCE_WOOD_STAIRS:4)
B(0,5,-3,SPRUCE_WOOD_STAIRS:4)
B(0,5,-2,WOOD:1)
B(0,5,-1,DARK_OAK_STAIRS:4)
B(0,5,3,TRAP_DOOR:5)
B(0,5,4,AIR)
B(0,5,5,AIR)
B(0,5,6,TRAP_DOOR:4)
B(0,6,-6,DARK_OAK_STAIRS:1)
B(0,6,-5,SPRUCE_WOOD_STAIRS:1)
B(0,6,-4,SPRUCE_WOOD_STAIRS:1)
B(0,6,-3,SPRUCE_WOOD_STAIRS:1)
B(0,6,-2,SPRUCE_WOOD_STAIRS:1)
B(0,6,-1,DARK_OAK_STAIRS:1)
B(0,6,2,TRAP_DOOR:4)
B(0,6,3,WOOD_STEP:13)
B(0,6,4,AIR)
B(0,6,5,AIR)
B(0,6,6,WOOD_STEP:13)
B(0,6,7,TRAP_DOOR:5)
B(0,7,2,WOOD_STEP:13)
B(0,7,3,TRAP_DOOR:13)
B(0,7,4,AIR)
B(0,7,5,AIR)
B(0,7,6,TRAP_DOOR:12)
B(0,7,7,WOOD_STEP:13)
B(0,8,2,WOOD_STEP:1)
B(0,8,3,LOG:5)
B(0,8,4,WOOD_STEP:9)
B(0,8,5,WOOD_STEP:9)
B(0,8,6,LOG:5)
B(0,8,7,WOOD_STEP:1)
B(1,0,-5,WOOD:1)
B(1,0,-4,WOOD:1)
B(1,0,-3,WOOD:1)
B(1,0,-2,WOOD:1)
B(1,0,-1,WOOD_STEP:13)
B(1,0,0,WOOD_DOUBLE_STEP:5)
B(1,0,1,WOOD_DOUBLE_STEP:5)
B(1,0,3,AIR)
B(1,0,4,AIR)
B(1,0,5,AIR)
B(1,0,6,AIR)
B(1,1,-7,LOG:1)
B(1,1,-6,LOG:1)
B(1,1,-5,WOOD_STEP:13)
B(1,1,-4,AIR)
B(1,1,-3,AIR)
B(1,1,-2,WOOD:1)
B(1,1,2,LOG:1)
B(1,1,3,AIR)
B(1,1,4,TRAP_DOOR:14)
B(1,1,5,TRAP_DOOR:14)
B(1,1,6,AIR)
B(1,1,7,LOG:1)
B(1,1,8,LOG:1)
B(1,2,-7,DARK_OAK_STAIRS:2)
B(1,2,-6,WOOD:1)
B(1,2,-5,AIR)
B(1,2,-4,AIR)
B(1,2,-3,AIR)
B(1,2,-2,WOOD:1)
B(1,2,2,LOG:1)
B(1,2,3,AIR)
B(1,2,4,TRAP_DOOR:6)
B(1,2,5,TRAP_DOOR:6)
B(1,2,6,AIR)
B(1,2,7,LOG:1)
B(1,2,8,DARK_OAK_STAIRS:0)
B(1,3,-5,WOOD:1)
B(1,3,-4,AIR)
B(1,3,-3,AIR)
B(1,3,-2,WOOD:1)
B(1,3,2,LOG:1)
B(1,3,3,AIR)
B(1,3,4,TRAP_DOOR:14)
B(1,3,5,TRAP_DOOR:14)
B(1,3,6,AIR)
B(1,3,7,LOG:1)
B(1,4,-6,DARK_OAK_STAIRS:4)
B(1,4,-5,WOOD:1)
B(1,4,-4,SPRUCE_WOOD_STAIRS:4)
B(1,4,-3,SPRUCE_WOOD_STAIRS:4)
B(1,4,-2,WOOD:1)
B(1,4,-1,DARK_OAK_STAIRS:4)
B(1,4,2,LOG:1)
B(1,4,3,LOG:5)
B(1,4,4,LOG:9)
B(1,4,5,LOG:9)
B(1,4,6,LOG:9)
B(1,4,7,LOG:1)
B(1,5,-6,DARK_OAK_STAIRS:1)
B(1,5,-5,SPRUCE_WOOD_STAIRS:1)
B(1,5,-4,SPRUCE_WOOD_STAIRS:1)
B(1,5,-3,SPRUCE_WOOD_STAIRS:1)
B(1,5,-2,SPRUCE_WOOD_STAIRS:1)
B(1,5,-1,DARK_OAK_STAIRS:1)
B(1,5,2,LOG:1)
B(1,5,3,AIR)
B(1,5,4,TRAP_DOOR:6)
B(1,5,5,TRAP_DOOR:6)
B(1,5,6,AIR)
B(1,5,7,LOG:1)
B(1,6,2,LOG:1)
B(1,6,3,WOOD_STEP:13)
B(1,6,4,WOOD_STEP:13)
B(1,6,5,WOOD_STEP:13)
B(1,6,6,WOOD_STEP:13)
B(1,6,7,LOG:1)
B(1,7,2,LOG:1)
B(1,7,4,TRAP_DOOR:14)
B(1,7,5,TRAP_DOOR:14)
B(1,7,6,AIR)
B(1,7,7,LOG:1)
B(1,8,2,DARK_OAK_STAIRS:2)
B(1,8,3,LOG:5)
B(1,8,4,LOG:9)
B(1,8,5,LOG:9)
B(1,8,6,LOG:9)
B(1,8,7,DARK_OAK_STAIRS:0)
B(2,0,-7,WOOD_STEP:13)
B(2,0,-6,WOOD_STEP:13)
B(2,0,-4,WOOD:1)
B(2,0,-3,WOOD:1)
B(2,0,-1,WOOD_STEP:13)
B(2,0,0,WOOD_STEP:13)
B(2,0,1,WOOD_STEP:13)
B(2,0,2,WOOD_STEP:13)
B(2,0,4,WOOD_DOUBLE_STEP:5)
B(2,0,5,WOOD_DOUBLE_STEP:5)
B(2,0,7,WOOD_STEP:13)
B(2,0,8,WOOD_STEP:13)
B(2,1,-7,SPRUCE_FENCE)
B(2,1,-5,LOG:1)
B(2,1,-4,WOOD:1)
B(2,1,-3,WOOD:1)
B(2,1,-2,LOG:1)
B(2,1,3,LOG:1)
B(2,1,6,LOG:1)
B(2,1,8,SPRUCE_FENCE)
B(2,2,-5,LOG:1)
B(2,2,-4,WOOD:1)
B(2,2,-3,WOOD:1)
B(2,2,-2,LOG:1)
B(2,2,3,LOG:1)
B(2,2,6,LOG:1)
B(2,3,-6,DARK_OAK_STAIRS:4)
B(2,3,-5,LOG:1)
B(2,3,-4,WOOD:1)
B(2,3,-3,WOOD:1)
B(2,3,-2,LOG:1)
B(2,3,-1,DARK_OAK_STAIRS:4)
B(2,3,3,LOG:1)
B(2,3,4,WOOD_STEP:13)
B(2,3,5,WOOD_STEP:13)
B(2,3,6,LOG:1)
B(2,4,-6,DARK_OAK_STAIRS:1)
B(2,4,-5,SPRUCE_WOOD_STAIRS:1)
B(2,4,-4,SPRUCE_WOOD_STAIRS:1)
B(2,4,-3,SPRUCE_WOOD_STAIRS:1)
B(2,4,-2,SPRUCE_WOOD_STAIRS:1)
B(2,4,-1,DARK_OAK_STAIRS:1)
B(2,4,3,LOG:1)
B(2,4,4,WOOD_STEP:1)
B(2,4,5,WOOD_STEP:1)
B(2,4,6,LOG:1)
B(2,5,3,LOG:1)
B(2,5,6,LOG:1)
B(2,6,3,LOG:1)
B(2,6,4,TRAP_DOOR:7)
B(2,6,5,TRAP_DOOR:7)
B(2,6,6,LOG:1)
B(2,7,3,LOG:1)
B(2,7,4,WOOD_STEP:13)
B(2,7,5,WOOD_STEP:13)
B(2,7,6,LOG:1)
B(2,8,3,DARK_OAK_STAIRS:1)
B(2,8,4,WOOD_STEP:1)
B(2,8,5,WOOD_STEP:1)
B(2,8,6,DARK_OAK_STAIRS:1)
B(3,0,-7,WOOD_STEP:13)
B(3,0,-6,WOOD_STEP:13)
B(3,0,-5,WOOD_STEP:13)
B(3,0,-4,WOOD_STEP:13)
B(3,0,-3,WOOD_STEP:13)
B(3,0,-2,WOOD_STEP:13)
B(3,0,-1,WOOD_STEP:13)
B(3,0,0,WOOD_STEP:13)
B(3,0,1,WOOD_STEP:13)
B(3,0,2,WOOD_STEP:13)
B(3,0,3,WOOD_STEP:13)
B(3,0,4,WOOD_STEP:13)
B(3,0,5,WOOD_STEP:13)
B(3,0,6,WOOD_STEP:13)
B(3,0,7,WOOD_STEP:13)
B(3,0,8,WOOD_STEP:13)
B(3,1,-7,DARK_OAK_FENCE_GATE:0)
B(3,1,8,DARK_OAK_FENCE_GATE)
B(3,3,-6,DARK_OAK_STAIRS:1)
B(3,3,-5,DARK_OAK_STAIRS:1)
B(3,3,-4,DARK_OAK_STAIRS:1)
B(3,3,-3,DARK_OAK_STAIRS:1)
B(3,3,-2,DARK_OAK_STAIRS:1)
B(3,3,-1,DARK_OAK_STAIRS:1)
B(4,0,-7,WOOD_STEP:13)
B(4,0,-6,WOOD_STEP:13)
B(4,0,-5,WOOD_STEP:13)
B(4,0,-4,WOOD_STEP:13)
B(4,0,-3,WOOD_STEP:13)
B(4,0,-2,WOOD_STEP:13)
B(4,0,-1,WOOD_STEP:13)
B(4,0,0,WOOD_STEP:13)
B(4,0,1,WOOD_STEP:13)
B(4,0,2,WOOD_STEP:13)
B(4,0,3,WOOD_STEP:13)
B(4,0,4,WOOD_STEP:13)
B(4,0,5,WOOD_STEP:13)
B(4,0,6,WOOD_STEP:13)
B(4,0,7,WOOD_STEP:13)
B(4,0,8,WOOD_STEP:13)
B(4,1,-7,SPRUCE_FENCE)
B(4,1,8,SPRUCE_FENCE)
B(5,0,-6,WOOD_STEP:13)
B(5,0,-5,WOOD_STEP:13)
B(5,0,-3,WOOD_STEP:13)
B(5,0,-2,WOOD_STEP:13)
B(5,0,-1,WOOD_STEP:13)
B(5,0,0,WOOD_STEP:13)
B(5,0,1,WOOD_STEP:13)
B(5,0,3,WOOD_STEP:13)
B(5,0,4,WOOD_STEP:13)
B(5,0,5,WOOD_STEP:13)
B(5,0,6,WOOD_STEP:13)
B(5,0,7,WOOD_STEP:13)
B(5,1,-7,LOG:1)
B(5,1,-6,SPRUCE_FENCE)
B(5,1,-5,SPRUCE_FENCE)
B(5,1,-4,LOG:1)
B(5,1,-3,SPRUCE_FENCE)
B(5,1,-2,DARK_OAK_FENCE_GATE:1)
B(5,1,-1,SPRUCE_FENCE)
B(5,1,0,DARK_OAK_FENCE_GATE:1)
B(5,1,1,SPRUCE_FENCE)
B(5,1,2,LOG:1)
B(5,1,3,SPRUCE_FENCE)
B(5,1,4,DARK_OAK_FENCE_GATE:1)
B(5,1,5,SPRUCE_FENCE)
B(5,1,6,DARK_OAK_FENCE_GATE:1)
B(5,1,7,SPRUCE_FENCE)
B(5,1,8,LOG:1)
B(5,2,-7,WOOD_STEP:5)
B(5,2,-4,WOOD_STEP:5)
B(5,2,2,WOOD_STEP:5)
B(5,2,8,WOOD_STEP:5)
Block(-3,0,3,LOG:1)
Block(-3,0,-5,LOG:1)
Block(-3,0,-2,LOG:1)
Block(-2,0,-6,LOG:1)
Block(-2,0,2,LOG:1)
Block(-2,0,7,LOG:1)
B(1,0,-6,LOG:1)
B(1,0,2,LOG:1)
B(2,0,-5,LOG:1)
B(2,0,3,LOG:1)
B(2,0,6,LOG:1)
B(2,0,-2,LOG:1)
B(1,0,7,LOG:1)
Block(-3,0,6,LOG:1)
Block(-6,0,-7,LOG:1)
Block(-6,0,-4,LOG:1)
Block(-6,0,2,LOG:1)
Block(-6,0,8,LOG:1)
Block(-2,0,-7,LOG:1)
Block(-2,0,8,LOG:1)
B(1,0,-7,LOG:1)
B(1,0,8,LOG:1)
B(5,0,-7,LOG:1)
B(5,0,-4,LOG:1)
B(5,0,2,LOG:1)
B(5,0,8,LOG:1)
Block(-3,-15,3,LOG:1)
Block(-3,-15,-5,LOG:1)
Block(-3,-15,-2,LOG:1)
Block(-2,-15,-6,LOG:1)
Block(-2,-15,2,LOG:1)
Block(-2,-15,7,LOG:1)
B(1,-15,-6,LOG:1)
B(1,-15,2,LOG:1)
B(2,-15,-5,LOG:1)
B(2,-15,3,LOG:1)
B(2,-15,6,LOG:1)
B(2,-15,-2,LOG:1)
B(1,-15,7,LOG:1)
Block(-3,-15,6,LOG:1)
Block(-6,-15,-7,LOG:1)
Block(-6,-15,-5,LOG:1)
Block(-6,-15,2,LOG:1)
Block(-6,-15,8,LOG:1)
Block(-2,-15,-7,LOG:1)
Block(-2,-15,8,LOG:1)
B(1,-15,-7,LOG:1)
B(1,-15,8,LOG:1)
B(5,-15,-7,LOG:1)
B(5,-15,-5,LOG:1)
B(5,-15,2,LOG:1)
B(5,-15,8,LOG:1)
Block(-3,-14,3,LOG:1)
Block(-3,-14,-5,LOG:1)
Block(-3,-14,-2,LOG:1)
Block(-2,-14,-6,LOG:1)
Block(-2,-14,2,LOG:1)
Block(-2,-14,7,LOG:1)
B(1,-14,-6,LOG:1)
B(1,-14,2,LOG:1)
B(2,-14,-5,LOG:1)
B(2,-14,3,LOG:1)
B(2,-14,6,LOG:1)
B(2,-14,-2,LOG:1)
B(1,-14,7,LOG:1)
Block(-3,-14,6,LOG:1)
Block(-6,-14,-7,LOG:1)
Block(-6,-14,-5,LOG:1)
Block(-6,-14,2,LOG:1)
Block(-6,-14,8,LOG:1)
Block(-2,-14,-7,LOG:1)
Block(-2,-14,8,LOG:1)
B(1,-14,-7,LOG:1)
B(1,-14,8,LOG:1)
B(5,-14,-7,LOG:1)
B(5,-14,-5,LOG:1)
B(5,-14,2,LOG:1)
B(5,-14,8,LOG:1)
Block(-3,-13,3,LOG:1)
Block(-3,-13,-5,LOG:1)
Block(-3,-13,-2,LOG:1)
Block(-2,-13,-6,LOG:1)
Block(-2,-13,2,LOG:1)
Block(-2,-13,7,LOG:1)
B(1,-13,-6,LOG:1)
B(1,-13,2,LOG:1)
B(2,-13,-5,LOG:1)
B(2,-13,3,LOG:1)
B(2,-13,6,LOG:1)
B(2,-13,-2,LOG:1)
B(1,-13,7,LOG:1)
Block(-3,-13,6,LOG:1)
Block(-6,-13,-7,LOG:1)
Block(-6,-13,-5,LOG:1)
Block(-6,-13,2,LOG:1)
Block(-6,-13,8,LOG:1)
Block(-2,-13,-7,LOG:1)
Block(-2,-13,8,LOG:1)
B(1,-13,-7,LOG:1)
B(1,-13,8,LOG:1)
B(5,-13,-7,LOG:1)
B(5,-13,-5,LOG:1)
B(5,-13,2,LOG:1)
B(5,-13,8,LOG:1)
Block(-3,-12,3,LOG:1)
Block(-3,-12,-5,LOG:1)
Block(-3,-12,-2,LOG:1)
Block(-2,-12,-6,LOG:1)
Block(-2,-12,2,LOG:1)
Block(-2,-12,7,LOG:1)
B(1,-12,-6,LOG:1)
B(1,-12,2,LOG:1)
B(2,-12,-5,LOG:1)
B(2,-12,3,LOG:1)
B(2,-12,6,LOG:1)
B(2,-12,-2,LOG:1)
B(1,-12,7,LOG:1)
Block(-3,-12,6,LOG:1)
Block(-6,-12,-7,LOG:1)
Block(-6,-12,-5,LOG:1)
Block(-6,-12,2,LOG:1)
Block(-6,-12,8,LOG:1)
Block(-2,-12,-7,LOG:1)
Block(-2,-12,8,LOG:1)
B(1,-12,-7,LOG:1)
B(1,-12,8,LOG:1)
B(5,-12,-7,LOG:1)
B(5,-12,-5,LOG:1)
B(5,-12,2,LOG:1)
B(5,-12,8,LOG:1)
Block(-3,-11,3,LOG:1)
Block(-3,-11,-5,LOG:1)
Block(-3,-11,-2,LOG:1)
Block(-2,-11,-6,LOG:1)
Block(-2,-11,2,LOG:1)
Block(-2,-11,7,LOG:1)
B(1,-11,-6,LOG:1)
B(1,-11,2,LOG:1)
B(2,-11,-5,LOG:1)
B(2,-11,3,LOG:1)
B(2,-11,6,LOG:1)
B(2,-11,-2,LOG:1)
B(1,-11,7,LOG:1)
Block(-3,-11,6,LOG:1)
Block(-6,-11,-7,LOG:1)
Block(-6,-11,-5,LOG:1)
Block(-6,-11,2,LOG:1)
Block(-6,-11,8,LOG:1)
Block(-2,-11,-7,LOG:1)
Block(-2,-11,8,LOG:1)
B(1,-11,-7,LOG:1)
B(1,-11,8,LOG:1)
B(5,-11,-7,LOG:1)
B(5,-11,-5,LOG:1)
B(5,-11,2,LOG:1)
B(5,-11,8,LOG:1)
Block(-3,-10,3,LOG:1)
Block(-3,-10,-5,LOG:1)
Block(-3,-10,-2,LOG:1)
Block(-2,-10,-6,LOG:1)
Block(-2,-10,2,LOG:1)
Block(-2,-10,7,LOG:1)
B(1,-10,-6,LOG:1)
B(1,-10,2,LOG:1)
B(2,-10,-5,LOG:1)
B(2,-10,3,LOG:1)
B(2,-10,6,LOG:1)
B(2,-10,-2,LOG:1)
B(1,-10,7,LOG:1)
Block(-3,-10,6,LOG:1)
Block(-6,-10,-7,LOG:1)
Block(-6,-10,-5,LOG:1)
Block(-6,-10,2,LOG:1)
Block(-6,-10,8,LOG:1)
Block(-2,-10,-7,LOG:1)
Block(-2,-10,8,LOG:1)
B(1,-10,-7,LOG:1)
B(1,-10,8,LOG:1)
B(5,-10,-7,LOG:1)
B(5,-10,-5,LOG:1)
B(5,-10,2,LOG:1)
B(5,-10,8,LOG:1)
Block(-3,-9,3,LOG:1)
Block(-3,-9,-5,LOG:1)
Block(-3,-9,-2,LOG:1)
Block(-2,-9,-6,LOG:1)
Block(-2,-9,2,LOG:1)
Block(-2,-9,7,LOG:1)
B(1,-9,-6,LOG:1)
B(1,-9,2,LOG:1)
B(2,-9,-5,LOG:1)
B(2,-9,3,LOG:1)
B(2,-9,6,LOG:1)
B(2,-9,-2,LOG:1)
B(1,-9,7,LOG:1)
Block(-3,-9,6,LOG:1)
Block(-6,-9,-7,LOG:1)
Block(-6,-9,-5,LOG:1)
Block(-6,-9,2,LOG:1)
Block(-6,-9,8,LOG:1)
Block(-2,-9,-7,LOG:1)
Block(-2,-9,8,LOG:1)
B(1,-9,-7,LOG:1)
B(1,-9,8,LOG:1)
B(5,-9,-7,LOG:1)
B(5,-9,-5,LOG:1)
B(5,-9,2,LOG:1)
B(5,-9,8,LOG:1)
Block(-3,-9,3,LOG:1)
Block(-3,-9,-5,LOG:1)
Block(-3,-9,-2,LOG:1)
Block(-2,-9,-6,LOG:1)
Block(-2,-9,2,LOG:1)
Block(-2,-9,7,LOG:1)
B(1,-9,-6,LOG:1)
B(1,-9,2,LOG:1)
B(2,-9,-5,LOG:1)
B(2,-9,3,LOG:1)
B(2,-9,6,LOG:1)
B(2,-9,-2,LOG:1)
B(1,-9,7,LOG:1)
Block(-3,-9,6,LOG:1)
Block(-6,-9,-7,LOG:1)
Block(-6,-9,-5,LOG:1)
Block(-6,-9,2,LOG:1)
Block(-6,-9,8,LOG:1)
Block(-2,-9,-7,LOG:1)
Block(-2,-9,8,LOG:1)
B(1,-9,-7,LOG:1)
B(1,-9,8,LOG:1)
B(5,-9,-7,LOG:1)
B(5,-9,-5,LOG:1)
B(5,-9,2,LOG:1)
B(5,-9,8,LOG:1)
Block(-3,-8,3,LOG:1)
Block(-3,-8,-5,LOG:1)
Block(-3,-8,-2,LOG:1)
Block(-2,-8,-6,LOG:1)
Block(-2,-8,2,LOG:1)
Block(-2,-8,7,LOG:1)
B(1,-8,-6,LOG:1)
B(1,-8,2,LOG:1)
B(2,-8,-5,LOG:1)
B(2,-8,3,LOG:1)
B(2,-8,6,LOG:1)
B(2,-8,-2,LOG:1)
B(1,-8,7,LOG:1)
Block(-3,-8,6,LOG:1)
Block(-6,-8,-7,LOG:1)
Block(-6,-8,-5,LOG:1)
Block(-6,-8,2,LOG:1)
Block(-6,-8,8,LOG:1)
Block(-2,-8,-7,LOG:1)
Block(-2,-8,8,LOG:1)
B(1,-8,-7,LOG:1)
B(1,-8,8,LOG:1)
B(5,-8,-7,LOG:1)
B(5,-8,-5,LOG:1)
B(5,-8,2,LOG:1)
B(5,-8,8,LOG:1)
Block(-3,-7,3,LOG:1)
Block(-3,-7,-5,LOG:1)
Block(-3,-7,-2,LOG:1)
Block(-2,-7,-6,LOG:1)
Block(-2,-7,2,LOG:1)
Block(-2,-7,7,LOG:1)
B(1,-7,-6,LOG:1)
B(1,-7,2,LOG:1)
B(2,-7,-5,LOG:1)
B(2,-7,3,LOG:1)
B(2,-7,6,LOG:1)
B(2,-7,-2,LOG:1)
B(1,-7,7,LOG:1)
Block(-3,-7,6,LOG:1)
Block(-6,-7,-7,LOG:1)
Block(-6,-7,-5,LOG:1)
Block(-6,-7,2,LOG:1)
Block(-6,-7,8,LOG:1)
Block(-2,-7,-7,LOG:1)
Block(-2,-7,8,LOG:1)
B(1,-7,-7,LOG:1)
B(1,-7,8,LOG:1)
B(5,-7,-7,LOG:1)
B(5,-7,-5,LOG:1)
B(5,-7,2,LOG:1)
B(5,-7,8,LOG:1)
Block(-3,-6,3,LOG:1)
Block(-3,-6,-5,LOG:1)
Block(-3,-6,-2,LOG:1)
Block(-2,-6,-6,LOG:1)
Block(-2,-6,2,LOG:1)
Block(-2,-6,7,LOG:1)
B(1,-6,-6,LOG:1)
B(1,-6,2,LOG:1)
B(2,-6,-5,LOG:1)
B(2,-6,3,LOG:1)
B(2,-6,6,LOG:1)
B(2,-6,-2,LOG:1)
B(1,-6,7,LOG:1)
Block(-3,-6,6,LOG:1)
Block(-6,-6,-7,LOG:1)
Block(-6,-6,-5,LOG:1)
Block(-6,-6,2,LOG:1)
Block(-6,-6,8,LOG:1)
Block(-2,-6,-7,LOG:1)
Block(-2,-6,8,LOG:1)
B(1,-6,-7,LOG:1)
B(1,-6,8,LOG:1)
B(5,-6,-7,LOG:1)
B(5,-6,-5,LOG:1)
B(5,-6,2,LOG:1)
B(5,-6,8,LOG:1)
Block(-3,-5,3,LOG:1)
Block(-3,-5,-5,LOG:1)
Block(-3,-5,-2,LOG:1)
Block(-2,-5,-6,LOG:1)
Block(-2,-5,2,LOG:1)
Block(-2,-5,7,LOG:1)
B(1,-5,-6,LOG:1)
B(1,-5,2,LOG:1)
B(2,-5,-5,LOG:1)
B(2,-5,3,LOG:1)
B(2,-5,6,LOG:1)
B(2,-5,-2,LOG:1)
B(1,-5,7,LOG:1)
Block(-3,-5,6,LOG:1)
Block(-6,-5,-7,LOG:1)
Block(-6,-5,-5,LOG:1)
Block(-6,-5,2,LOG:1)
Block(-6,-5,8,LOG:1)
Block(-2,-5,-7,LOG:1)
Block(-2,-5,8,LOG:1)
B(1,-5,-7,LOG:1)
B(1,-5,8,LOG:1)
B(5,-5,-7,LOG:1)
B(5,-5,-5,LOG:1)
B(5,-5,2,LOG:1)
B(5,-5,8,LOG:1)
Block(-3,-4,3,LOG:1)
Block(-3,-4,-5,LOG:1)
Block(-3,-4,-2,LOG:1)
Block(-2,-4,-6,LOG:1)
Block(-2,-4,2,LOG:1)
Block(-2,-4,7,LOG:1)
B(1,-4,-6,LOG:1)
B(1,-4,2,LOG:1)
B(2,-4,-5,LOG:1)
B(2,-4,3,LOG:1)
B(2,-4,6,LOG:1)
B(2,-4,-2,LOG:1)
B(1,-4,7,LOG:1)
Block(-3,-4,6,LOG:1)
Block(-6,-4,-7,LOG:1)
Block(-6,-4,-4,LOG:1)
Block(-6,-4,2,LOG:1)
Block(-6,-4,8,LOG:1)
Block(-2,-4,-7,LOG:1)
Block(-2,-4,8,LOG:1)
B(1,-4,-7,LOG:1)
B(1,-4,8,LOG:1)
B(5,-4,-7,LOG:1)
B(5,-4,-4,LOG:1)
B(5,-4,2,LOG:1)
B(5,-4,8,LOG:1)
Block(-3,-3,3,LOG:1)
Block(-3,-3,-5,LOG:1)
Block(-3,-3,-2,LOG:1)
Block(-2,-3,-6,LOG:1)
Block(-2,-3,2,LOG:1)
Block(-2,-3,7,LOG:1)
B(1,-3,-6,LOG:1)
B(1,-3,2,LOG:1)
B(2,-3,-5,LOG:1)
B(2,-3,3,LOG:1)
B(2,-3,6,LOG:1)
B(2,-3,-2,LOG:1)
B(1,-3,7,LOG:1)
Block(-3,-3,6,LOG:1)
Block(-6,-3,-7,LOG:1)
Block(-6,-3,-4,LOG:1)
Block(-6,-3,2,LOG:1)
Block(-6,-3,8,LOG:1)
Block(-2,-3,-7,LOG:1)
Block(-2,-3,8,LOG:1)
B(1,-3,-7,LOG:1)
B(1,-3,8,LOG:1)
B(5,-3,-7,LOG:1)
B(5,-3,-4,LOG:1)
B(5,-3,2,LOG:1)
B(5,-3,8,LOG:1)
Block(-3,-2,3,LOG:1)
Block(-3,-2,-5,LOG:1)
Block(-3,-2,-2,LOG:1)
Block(-2,-2,-6,LOG:1)
Block(-2,-2,2,LOG:1)
Block(-2,-2,7,LOG:1)
B(1,-2,-6,LOG:1)
B(1,-2,2,LOG:1)
B(2,-2,-5,LOG:1)
B(2,-2,3,LOG:1)
B(2,-2,6,LOG:1)
B(2,-2,-2,LOG:1)
B(1,-2,7,LOG:1)
Block(-3,-2,6,LOG:1)
Block(-6,-2,-7,LOG:1)
Block(-6,-2,-4,LOG:1)
Block(-6,-2,2,LOG:1)
Block(-6,-2,8,LOG:1)
Block(-2,-2,-7,LOG:1)
Block(-2,-2,8,LOG:1)
B(1,-2,-7,LOG:1)
B(1,-2,8,LOG:1)
B(5,-2,-7,LOG:1)
B(5,-2,-4,LOG:1)
B(5,-2,2,LOG:1)
B(5,-2,8,LOG:1)
Block(-3,-1,3,LOG:1)
Block(-3,-1,-5,LOG:1)
Block(-3,-1,-2,LOG:1)
Block(-2,-1,-6,LOG:1)
Block(-2,-1,2,LOG:1)
Block(-2,-1,7,LOG:1)
B(1,-1,-6,LOG:1)
B(1,-1,2,LOG:1)
B(2,-1,-5,LOG:1)
B(2,-1,3,LOG:1)
B(2,-1,6,LOG:1)
B(2,-1,-2,LOG:1)
B(1,-1,7,LOG:1)
Block(-3,-1,6,LOG:1)
Block(-6,-1,-7,LOG:1)
Block(-6,-1,-4,LOG:1)
Block(-6,-1,2,LOG:1)
Block(-6,-1,8,LOG:1)
Block(-2,-1,-7,LOG:1)
Block(-2,-1,8,LOG:1)
B(1,-1,-7,LOG:1)
B(1,-1,8,LOG:1)
B(5,-1,-7,LOG:1)
B(5,-1,-4,LOG:1)
B(5,-1,2,LOG:1)
B(5,-1,8,LOG:1)

#######################################################################
# +-----------------------------------------------------------------+ #
# |                            BO3 checks                           | #
# +-----------------------------------------------------------------+ #
#######################################################################

BlockCheck(0,-1,0,WOOD_STEP:13)
LightCheck(0,3,0,15,15)

#######################################################################
# +-----------------------------------------------------------------+ #
# |                             Branches                            | #
# +-----------------------------------------------------------------+ #
#######################################################################

Branch(-3,-1,3, MineShaftWoodFoundation,NORTH,100.0)
Branch(-3,-1,-5, MineShaftWoodFoundation,NORTH,100.0)
Branch(-3,-1,-2, MineShaftWoodFoundation,NORTH,100.0)
Branch(-2,-1,-6, MineShaftWoodFoundation,NORTH,100.0)
Branch(-2,-1,2, MineShaftWoodFoundation,NORTH,100.0)
Branch(-2,-1,7, MineShaftWoodFoundation,NORTH,100.0)
Branch(1,-1,-6, MineShaftWoodFoundation,NORTH,100.0)
Branch(1,-1,2, MineShaftWoodFoundation,NORTH,100.0)
Branch(2,-1,-5, MineShaftWoodFoundation,NORTH,100.0)
Branch(2,-1,3, MineShaftWoodFoundation,NORTH,100.0)
Branch(2,-1,6, MineShaftWoodFoundation,NORTH,100.0)
Branch(2,-1,-2, MineShaftWoodFoundation,NORTH,100.0)
Branch(1,-1,7, MineShaftWoodFoundation,NORTH,100.0)
Branch(-3,-1,6, MineShaftWoodFoundation,NORTH,100.0)
Branch(-6,-1,-7, MineShaftWoodFoundation,NORTH,100.0)
Branch(-6,-1,-4, MineShaftWoodFoundation,NORTH,100.0)
Branch(-6,-1,2, MineShaftWoodFoundation,NORTH,100.0)
Branch(-6,-1,8, MineShaftWoodFoundation,NORTH,100.0)
Branch(-2,-1,-7, MineShaftWoodFoundation,NORTH,100.0)
Branch(-2,-1,8, MineShaftWoodFoundation,NORTH,100.0)
Branch(1,-1,-7, MineShaftWoodFoundation,NORTH,100.0)
Branch(1,-1,8, MineShaftWoodFoundation,NORTH,100.0)
Branch(5,-1,-7, MineShaftWoodFoundation,NORTH,100.0)
Branch(5,-1,-4, MineShaftWoodFoundation,NORTH,100.0)
Branch(5,-1,2, MineShaftWoodFoundation,NORTH,100.0)
Branch(5,-1,8, MineShaftWoodFoundation,NORTH,100.0)

#######################################################################
# +-----------------------------------------------------------------+ #
# |                             Entities                            | #
# +-----------------------------------------------------------------+ #
#######################################################################


#######################################################################
# +-----------------------------------------------------------------+ #
# |                            Particles                            | #
# +-----------------------------------------------------------------+ #
#######################################################################


#######################################################################
# +-----------------------------------------------------------------+ #
# |                             Spawners                            | #
# +-----------------------------------------------------------------+ #
#######################################################################


#######################################################################
# +-----------------------------------------------------------------+ #
# |                             ModData                             | #
# +-----------------------------------------------------------------+ #
#######################################################################

