#######################################################################
# +-----------------------------------------------------------------+ #
# |                            BO3 object                           | #
# +-----------------------------------------------------------------+ #
#######################################################################

Author: Bo3 BulkEdit

Description: Converted Schematic - Modified by Bo3BulkEdit

Version: 3

SettingsMode: WriteDisable

#######################################################################
# +-----------------------------------------------------------------+ #
# |                          Main settings                          | #
# +-----------------------------------------------------------------+ #
#######################################################################

IsOTGPlus: true
Tree: false
Frequency: 1
Rarity: 100.0
RotateRandomly: false
SpawnHeight: randomY
MaxBranchDepth: 10
ExcludedBiomes: All

##############################
# Height Limits for the BO3. #
##############################

MinHeight: 0
MaxHeight: 255

#######################################################################
# +-----------------------------------------------------------------+ #
# |                      Source block settings                      | #
# +-----------------------------------------------------------------+ #
#######################################################################

CanOverride: true
MaxPercentageOutsideSourceBlock: 100
OutsideSourceBlock: placeAnyway

#######################################################################
# +-----------------------------------------------------------------+ #
# |                               OTG+                              | #
# +-----------------------------------------------------------------+ #
#######################################################################

BO3Group: CeilingCrystals:0

#######################################################################
# +-----------------------------------------------------------------+ #
# |                              Blocks                             | #
# +-----------------------------------------------------------------+ #
#######################################################################

B(0,750,0,AIR)
B(15,750,15,AIR)
B(0,-41,15,STAINED_GLASS:15)
B(1,-41,15,STAINED_GLASS:15)
B(0,-40,13,STAINED_GLASS:15)
B(0,-40,14,STAINED_GLASS:15)
B(0,-40,15,STAINED_GLASS:15)
B(1,-40,15,STAINED_GLASS:15)
B(2,-40,15,STAINED_GLASS:15)
B(0,-39,12,STAINED_GLASS:15)
B(0,-39,13,STAINED_GLASS:15)
B(1,-39,13,STAINED_GLASS:15)
B(2,-39,13,STAINED_GLASS:15)
B(0,-39,14,STAINED_GLASS:15)
B(1,-39,14,STAINED_GLASS:15)
B(2,-39,14,STAINED_GLASS:15)
B(3,-39,14,STAINED_GLASS:15)
B(4,-39,14,STAINED_GLASS:15)
B(0,-39,15,STAINED_GLASS:15)
B(1,-39,15,STAINED_GLASS:15)
B(2,-39,15,STAINED_GLASS:15)
B(3,-39,15,STAINED_GLASS:15)
B(4,-39,15,STAINED_GLASS:15)
B(0,-38,10,STAINED_GLASS:15)
B(0,-38,11,STAINED_GLASS:15)
B(1,-38,11,STAINED_GLASS:15)
B(0,-38,12,STAINED_GLASS:15)
B(1,-38,12,STAINED_GLASS:15)
B(2,-38,12,STAINED_GLASS:15)
B(0,-38,13,STAINED_GLASS:15)
B(1,-38,13,STAINED_GLASS:15)
B(2,-38,13,STAINED_GLASS:15)
B(3,-38,13,STAINED_GLASS:15)
B(4,-38,13,STAINED_GLASS:15)
B(0,-38,14,STAINED_GLASS:15)
B(1,-38,14,STAINED_GLASS:15)
B(2,-38,14,STAINED_GLASS:15)
B(3,-38,14,STAINED_GLASS:15)
B(4,-38,14,STAINED_GLASS:15)
B(0,-38,15,STAINED_GLASS:15)
B(1,-38,15,STAINED_GLASS:15)
B(2,-38,15,STAINED_GLASS:15)
B(3,-38,15,STAINED_GLASS:15)
B(0,-37,8,STAINED_GLASS:15)
B(0,-37,9,STAINED_GLASS:15)
B(0,-37,10,STAINED_GLASS:15)
B(1,-37,10,STAINED_GLASS:15)
B(0,-37,11,STAINED_GLASS:15)
B(1,-37,11,STAINED_GLASS:15)
B(2,-37,11,STAINED_GLASS:15)
B(0,-37,12,STAINED_GLASS:15)
B(1,-37,12,STAINED_GLASS:15)
B(2,-37,12,STAINED_GLASS:15)
B(3,-37,12,STAINED_GLASS:15)
B(4,-37,12,STAINED_GLASS:15)
B(0,-37,13,STAINED_GLASS:15)
B(1,-37,13,STAINED_GLASS:15)
B(2,-37,13,STAINED_GLASS:15)
B(3,-37,13,STAINED_GLASS:15)
B(4,-37,13,STAINED_GLASS:15)
B(0,-37,14,STAINED_GLASS:15)
B(1,-37,14,STAINED_GLASS:15)
B(2,-37,14,STAINED_GLASS:15)
B(3,-37,14,STAINED_GLASS:15)
B(0,-37,15,STAINED_GLASS:15)
B(1,-37,15,STAINED_GLASS:15)
B(2,-37,15,STAINED_GLASS:15)
B(3,-37,15,STAINED_GLASS:15)
B(0,-36,7,STAINED_GLASS:15)
B(0,-36,8,STAINED_GLASS:15)
B(0,-36,9,STAINED_GLASS:15)
B(1,-36,9,STAINED_GLASS:15)
B(0,-36,10,STAINED_GLASS:15)
B(1,-36,10,STAINED_GLASS:15)
B(0,-36,11,STAINED_GLASS:15)
B(1,-36,11,STAINED_GLASS:15)
B(2,-36,11,STAINED_GLASS:15)
B(3,-36,11,STAINED_GLASS:15)
B(0,-36,12,STAINED_GLASS:10)
B(1,-36,12,STAINED_GLASS:10)
B(2,-36,12,STAINED_GLASS:11)
B(3,-36,12,STAINED_GLASS:15)
B(0,-36,13,STAINED_GLASS:10)
B(1,-36,13,STAINED_GLASS:11)
B(2,-36,13,STAINED_GLASS:11)
B(3,-36,13,STAINED_GLASS:15)
B(0,-36,14,STAINED_GLASS:11)
B(1,-36,14,STAINED_GLASS:15)
B(2,-36,14,STAINED_GLASS:15)
B(3,-36,14,STAINED_GLASS:15)
B(0,-36,15,STAINED_GLASS:15)
B(0,-35,7,STAINED_GLASS:15)
B(1,-35,7,STAINED_GLASS:9)
B(0,-35,8,STAINED_GLASS:15)
B(1,-35,8,STAINED_GLASS:9)
B(2,-35,8,STAINED_GLASS:9)
B(0,-35,9,STAINED_GLASS:15)
B(1,-35,9,STAINED_GLASS:15)
B(2,-35,9,STAINED_GLASS:11)
B(0,-35,10,STAINED_GLASS:10)
B(1,-35,10,STAINED_GLASS:15)
B(2,-35,10,STAINED_GLASS:11)
B(0,-35,11,STAINED_GLASS:10)
B(1,-35,11,STAINED_GLASS:10)
B(2,-35,11,STAINED_GLASS:11)
B(3,-35,11,STAINED_GLASS:15)
B(0,-35,12,STAINED_GLASS:10)
B(1,-35,12,STAINED_GLASS:11)
B(2,-35,12,STAINED_GLASS:11)
B(3,-35,12,STAINED_GLASS:15)
B(0,-35,13,STAINED_GLASS:11)
B(1,-35,13,STAINED_GLASS:15)
B(2,-35,13,STAINED_GLASS:15)
B(0,-35,14,STAINED_GLASS:11)
B(1,-35,14,STAINED_GLASS:15)
B(0,-34,7,STAINED_GLASS:15)
B(1,-34,7,STAINED_GLASS:15)
B(0,-34,8,STAINED_GLASS:11)
B(1,-34,8,STAINED_GLASS:14)
B(2,-34,8,STAINED_GLASS:15)
B(0,-34,9,STAINED_GLASS:11)
B(1,-34,9,STAINED_GLASS:11)
B(2,-34,9,STAINED_GLASS:11)
B(0,-34,10,STAINED_GLASS:10)
B(1,-34,10,STAINED_GLASS:11)
B(2,-34,10,STAINED_GLASS:15)
B(0,-34,11,STAINED_GLASS:10)
B(1,-34,11,STAINED_GLASS:10)
B(2,-34,11,STAINED_GLASS:15)
B(0,-34,12,STAINED_GLASS:11)
B(1,-34,12,STAINED_GLASS:14)
B(2,-34,12,STAINED_GLASS:11)
B(3,-34,12,STAINED_GLASS:14)
B(0,-34,13,STAINED_GLASS:11)
B(1,-34,13,STAINED_GLASS:15)
B(0,-34,14,STAINED_GLASS:15)
B(0,-33,6,STAINED_GLASS:15)
B(1,-33,6,STAINED_GLASS:15)
B(0,-33,7,STAINED_GLASS:15)
B(1,-33,7,STAINED_GLASS:15)
B(0,-33,8,STAINED_GLASS:11)
B(1,-33,8,STAINED_GLASS:11)
B(2,-33,8,STAINED_GLASS:15)
B(0,-33,9,STAINED_GLASS:11)
B(1,-33,9,STAINED_GLASS:11)
B(2,-33,9,STAINED_GLASS:11)
B(0,-33,10,STAINED_GLASS:10)
B(1,-33,10,STAINED_GLASS:11)
B(2,-33,10,STAINED_GLASS:14)
B(0,-33,11,STAINED_GLASS:10)
B(1,-33,11,STAINED_GLASS:11)
B(2,-33,11,STAINED_GLASS:14)
B(0,-33,12,STAINED_GLASS:15)
B(2,-33,12,STAINED_GLASS:14)
B(0,-33,13,STAINED_GLASS:15)
B(0,-32,6,STAINED_GLASS:15)
B(1,-32,6,STAINED_GLASS:15)
B(0,-32,7,STAINED_GLASS:15)
B(1,-32,7,STAINED_GLASS:15)
B(0,-32,8,STAINED_GLASS:11)
B(1,-32,8,STAINED_GLASS:11)
B(2,-32,8,STAINED_GLASS:14)
B(0,-32,9,STAINED_GLASS:11)
B(1,-32,9,STAINED_GLASS:14)
B(2,-32,9,STAINED_GLASS:14)
B(0,-32,10,STAINED_GLASS:10)
B(1,-32,10,STAINED_GLASS:11)
B(2,-32,10,STAINED_GLASS:14)
B(0,-32,11,STAINED_GLASS:11)
B(1,-32,11,STAINED_GLASS:14)
B(2,-32,11,STAINED_GLASS:14)
B(0,-32,12,STAINED_GLASS:15)
B(0,-31,4,STAINED_GLASS:15)
B(0,-31,5,STAINED_GLASS:15)
B(0,-31,6,STAINED_GLASS:15)
B(1,-31,6,STAINED_GLASS:15)
B(0,-31,7,STAINED_GLASS:11)
B(1,-31,7,STAINED_GLASS:14)
B(0,-31,8,STAINED_GLASS:11)
B(1,-31,8,STAINED_GLASS:11)
B(2,-31,8,STAINED_GLASS:14)
B(0,-31,9,STAINED_GLASS:11)
B(1,-31,9,STAINED_GLASS:14)
B(2,-31,9,STAINED_GLASS:14)
B(0,-31,10,STAINED_GLASS:11)
B(1,-31,10,STAINED_GLASS:14)
B(0,-31,11,STAINED_GLASS:14)
B(0,-30,4,STAINED_GLASS:9)
B(0,-30,5,STAINED_GLASS:9)
B(0,-30,6,STAINED_GLASS:14)
B(1,-30,6,STAINED_GLASS:14)
B(0,-30,7,STAINED_GLASS:11)
B(1,-30,7,STAINED_GLASS:14)
B(0,-30,8,STAINED_GLASS:11)
B(1,-30,8,STAINED_GLASS:14)
B(0,-30,9,STAINED_GLASS:11)
B(1,-30,9,STAINED_GLASS:14)
B(2,-30,9,STAINED_GLASS:14)
B(0,-30,10,STAINED_GLASS:14)
B(0,-30,11,STAINED_GLASS:15)
B(0,-29,4,STAINED_GLASS:9)
B(0,-29,5,STAINED_GLASS:9)
B(0,-29,6,STAINED_GLASS:14)
B(1,-29,6,STAINED_GLASS:14)
B(0,-29,7,STAINED_GLASS:11)
B(1,-29,7,STAINED_GLASS:14)
B(0,-29,8,STAINED_GLASS:11)
B(1,-29,8,STAINED_GLASS:14)
B(0,-29,9,STAINED_GLASS:14)
B(0,-28,4,STAINED_GLASS:14)
B(0,-28,5,STAINED_GLASS:14)
B(0,-28,6,STAINED_GLASS:14)
B(1,-28,6,STAINED_GLASS:14)
B(0,-28,7,STAINED_GLASS:14)
B(0,-28,8,STAINED_GLASS:11)
B(1,-28,8,STAINED_GLASS:14)
B(0,-27,4,STAINED_GLASS:14)
B(0,-27,5,STAINED_GLASS:14)
B(0,-27,6,STAINED_GLASS:15)
B(1,-27,6,STAINED_GLASS:15)
B(0,-27,7,STAINED_GLASS:15)
B(0,-27,8,STAINED_GLASS:15)
B(0,-26,4,STAINED_GLASS:14)
B(0,-26,5,STAINED_GLASS:14)
B(0,-26,7,STAINED_GLASS:15)
B(0,-25,4,STAINED_GLASS:14)
B(0,-25,5,STAINED_GLASS:14)

