#######################################################################
# +-----------------------------------------------------------------+ #
# |                            BO3 object                           | #
# +-----------------------------------------------------------------+ #
#######################################################################

Author: Bo3 BulkEdit

Description: Converted Schematic - Modified by Bo3BulkEdit

Version: 3

SettingsMode: WriteDisable

#######################################################################
# +-----------------------------------------------------------------+ #
# |                          Main settings                          | #
# +-----------------------------------------------------------------+ #
#######################################################################



Frequency: 0


SpawnHeight: randomY





##############################
# Height Limits for the BO3. #
##############################

MinHeight: 0
MaxHeight: 256

#######################################################################
# +-----------------------------------------------------------------+ #
# |                      Source block settings                      | #
# +-----------------------------------------------------------------+ #
#######################################################################

CanOverride: true
MaxPercentageOutsideSourceBlock: 100
OutsideSourceBlock: placeAnyway

#######################################################################
# +-----------------------------------------------------------------+ #
# |                               OTG+                              | #
# +-----------------------------------------------------------------+ #
#######################################################################

#######################################################################
# +-----------------------------------------------------------------+ #
# |                              Blocks                             | #
# +-----------------------------------------------------------------+ #
#######################################################################

B(0,750,0,AIR)
B(15,750,15,AIR)
B(3,-2,15,STAINED_GLASS:15)
B(2,-1,12,STAINED_GLASS:15)
B(2,-1,13,STAINED_GLASS:15)
B(0,-1,14,STAINED_GLASS:15)
B(1,-1,14,STAINED_GLASS:15)
B(2,-1,14,STAINED_GLASS:15)
B(3,-1,14,STAINED_GLASS:15)
B(0,-1,15,STAINED_GLASS:15)
B(1,-1,15,STAINED_GLASS:15)
B(2,-1,15,STAINED_GLASS:15)
B(3,-1,15,STAINED_GLASS:15)
B(1,0,11,STAINED_GLASS:15)
B(1,0,12,STAINED_GLASS:15)
B(2,0,12,STAINED_GLASS:15)
B(0,0,13,STAINED_GLASS:15)
B(1,0,13,STAINED_GLASS:15)
B(2,0,13,STAINED_GLASS:15)
B(0,0,14,STAINED_GLASS:15)
B(1,0,14,STAINED_GLASS:15)
B(2,0,14,STAINED_GLASS:15)
B(3,0,14,STAINED_GLASS:15)
B(0,0,15,SEA_LANTERN)
B(3,0,15,STAINED_GLASS:15)
B(0,1,10,STAINED_GLASS:15)
B(0,1,11,STAINED_GLASS:15)
B(1,1,11,STAINED_GLASS:15)
B(0,1,12,STAINED_GLASS:15)
B(1,1,12,STAINED_GLASS:15)
B(2,1,12,STAINED_GLASS:14)
B(0,1,13,STAINED_GLASS:10)
B(1,1,13,STAINED_GLASS:11)
B(2,1,13,STAINED_GLASS:11)
B(3,1,13,STAINED_GLASS:15)
B(0,1,14,STAINED_GLASS:10)
B(1,1,14,STAINED_GLASS:10)
B(2,1,14,STAINED_GLASS:11)
B(3,1,14,STAINED_GLASS:15)
B(0,1,15,STAINED_GLASS:10)
B(1,1,15,STAINED_GLASS:10)
B(2,1,15,STAINED_GLASS:11)
B(3,1,15,STAINED_GLASS:15)
B(0,2,10,STAINED_GLASS:14)
B(0,2,11,STAINED_GLASS:14)
B(1,2,11,STAINED_GLASS:14)
B(0,2,12,STAINED_GLASS:11)
B(1,2,12,STAINED_GLASS:11)
B(2,2,12,STAINED_GLASS:15)
B(0,2,13,STAINED_GLASS:10)
B(1,2,13,STAINED_GLASS:11)
B(2,2,13,STAINED_GLASS:15)
B(0,2,14,STAINED_GLASS:10)
B(1,2,14,STAINED_GLASS:10)
B(2,2,14,STAINED_GLASS:11)
B(3,2,14,STAINED_GLASS:15)
B(0,2,15,STAINED_GLASS:10)
B(1,2,15,STAINED_GLASS:11)
B(2,2,15,STAINED_GLASS:15)
B(0,3,10,STAINED_GLASS:14)
B(0,3,11,STAINED_GLASS:11)
B(1,3,11,STAINED_GLASS:14)
B(0,3,12,STAINED_GLASS:11)
B(1,3,12,STAINED_GLASS:11)
B(2,3,12,STAINED_GLASS:15)
B(0,3,13,STAINED_GLASS:10)
B(1,3,13,STAINED_GLASS:11)
B(2,3,13,STAINED_GLASS:14)
B(0,3,14,STAINED_GLASS:10)
B(1,3,14,STAINED_GLASS:11)
B(2,3,14,STAINED_GLASS:15)
B(0,3,15,STAINED_GLASS:11)
B(1,3,15,STAINED_GLASS:15)
B(0,4,10,STAINED_GLASS:15)
B(0,4,11,STAINED_GLASS:11)
B(1,4,11,STAINED_GLASS:15)
B(0,4,12,STAINED_GLASS:11)
B(1,4,12,STAINED_GLASS:15)
B(0,4,13,STAINED_GLASS:10)
B(1,4,13,STAINED_GLASS:11)
B(2,4,13,STAINED_GLASS:14)
B(0,4,14,STAINED_GLASS:11)
B(1,4,14,STAINED_GLASS:14)
B(0,4,15,STAINED_GLASS:11)
B(1,4,15,STAINED_GLASS:15)
B(0,5,10,STAINED_GLASS:15)
B(0,5,11,STAINED_GLASS:11)
B(1,5,11,STAINED_GLASS:14)
B(0,5,12,STAINED_GLASS:11)
B(1,5,12,STAINED_GLASS:14)
B(0,5,13,STAINED_GLASS:11)
B(1,5,13,STAINED_GLASS:14)
B(0,5,14,STAINED_GLASS:15)
B(0,5,15,STAINED_GLASS:15)
B(0,6,10,STAINED_GLASS:14)
B(0,6,11,STAINED_GLASS:14)
B(0,6,12,STAINED_GLASS:11)
B(1,6,12,STAINED_GLASS:14)
B(0,6,13,STAINED_GLASS:14)
B(0,6,14,STAINED_GLASS:15)
B(0,7,10,STAINED_GLASS:14)
B(0,7,11,STAINED_GLASS:14)
B(0,7,12,STAINED_GLASS:14)
B(0,8,11,STAINED_GLASS:14)

