#######################################################################
# +-----------------------------------------------------------------+ #
# |                            BO3 object                           | #
# +-----------------------------------------------------------------+ #
#######################################################################

Author: Bo3 BulkEdit

Description: Converted Schematic - Modified by Bo3BulkEdit

Version: 3

SettingsMode: WriteDisable

#######################################################################
# +-----------------------------------------------------------------+ #
# |                          Main settings                          | #
# +-----------------------------------------------------------------+ #
#######################################################################



Frequency: 0


SpawnHeight: randomY





##############################
# Height Limits for the BO3. #
##############################

MinHeight: 0
MaxHeight: 256

#######################################################################
# +-----------------------------------------------------------------+ #
# |                      Source block settings                      | #
# +-----------------------------------------------------------------+ #
#######################################################################

CanOverride: true
MaxPercentageOutsideSourceBlock: 100
OutsideSourceBlock: placeAnyway

#######################################################################
# +-----------------------------------------------------------------+ #
# |                               OTG+                              | #
# +-----------------------------------------------------------------+ #
#######################################################################

#######################################################################
# +-----------------------------------------------------------------+ #
# |                              Blocks                             | #
# +-----------------------------------------------------------------+ #
#######################################################################

B(0,750,0,AIR)
B(15,750,15,AIR)
B(3,-3,8,STAINED_GLASS:15)
B(2,-3,9,STAINED_GLASS:15)
B(3,-3,9,STAINED_GLASS:15)
B(2,-2,7,STAINED_GLASS:15)
B(1,-2,8,STAINED_GLASS:15)
B(2,-2,8,STAINED_GLASS:15)
B(3,-2,8,STAINED_GLASS:15)
B(2,-2,9,STAINED_GLASS:15)
B(3,-2,9,STAINED_GLASS:15)
B(1,-1,6,STAINED_GLASS:15)
B(2,-1,6,STAINED_GLASS:15)
B(0,-1,7,STAINED_GLASS:15)
B(1,-1,7,STAINED_GLASS:15)
B(2,-1,7,STAINED_GLASS:15)
B(3,-1,7,STAINED_GLASS:15)
B(1,-1,8,STAINED_GLASS:15)
B(2,-1,8,STAINED_GLASS:15)
B(3,-1,8,STAINED_GLASS:15)
B(2,-1,9,STAINED_GLASS:15)
B(1,0,4,STAINED_GLASS:15)
B(1,0,5,STAINED_GLASS:15)
B(2,0,5,STAINED_GLASS:15)
B(0,0,6,STAINED_GLASS:15)
B(1,0,6,STAINED_GLASS:15)
B(2,0,6,STAINED_GLASS:15)
B(0,0,7,STAINED_GLASS:15)
B(2,0,7,STAINED_GLASS:15)
B(1,0,8,STAINED_GLASS:15)
B(2,0,8,STAINED_GLASS:15)
B(3,0,8,STAINED_GLASS:15)
B(0,1,3,STAINED_GLASS:15)
B(1,1,3,STAINED_GLASS:15)
B(0,1,4,STAINED_GLASS:15)
B(1,1,4,STAINED_GLASS:15)
B(0,1,5,STAINED_GLASS:15)
B(1,1,5,STAINED_GLASS:15)
B(2,1,5,STAINED_GLASS:15)
B(0,1,6,STAINED_GLASS:15)
B(1,1,6,STAINED_GLASS:15)
B(2,1,6,STAINED_GLASS:15)
B(0,1,7,STAINED_GLASS:15)
B(1,1,7,STAINED_GLASS:15)
B(2,1,7,STAINED_GLASS:15)
B(1,1,8,STAINED_GLASS:15)
B(2,1,8,STAINED_GLASS:15)
B(0,2,2,STAINED_GLASS:15)
B(1,2,2,STAINED_GLASS:15)
B(0,2,3,STAINED_GLASS:15)
B(1,2,3,STAINED_GLASS:15)
B(0,2,4,STAINED_GLASS:15)
B(1,2,4,STAINED_GLASS:15)
B(2,2,4,STAINED_GLASS:15)
B(0,2,5,STAINED_GLASS:15)
B(1,2,5,STAINED_GLASS:15)
B(2,2,5,STAINED_GLASS:15)
B(0,2,6,STAINED_GLASS:15)
B(1,2,6,STAINED_GLASS:15)
B(2,2,6,STAINED_GLASS:15)
B(0,2,7,STAINED_GLASS:15)
B(1,2,7,STAINED_GLASS:15)
B(2,2,7,STAINED_GLASS:15)
B(1,2,8,STAINED_GLASS:15)
B(0,3,1,STAINED_GLASS:15)
B(0,3,2,STAINED_GLASS:15)
B(1,3,2,STAINED_GLASS:15)
B(0,3,3,STAINED_GLASS:15)
B(1,3,3,STAINED_GLASS:15)
B(0,3,4,STAINED_GLASS:15)
B(1,3,4,STAINED_GLASS:15)
B(2,3,4,STAINED_GLASS:15)
B(0,3,5,STAINED_GLASS:15)
B(1,3,5,STAINED_GLASS:15)
B(2,3,5,STAINED_GLASS:15)
B(0,3,6,STAINED_GLASS:15)
B(1,3,6,STAINED_GLASS:15)
B(2,3,6,STAINED_GLASS:15)
B(0,3,7,STAINED_GLASS:15)
B(1,3,7,STAINED_GLASS:15)
B(2,3,7,STAINED_GLASS:15)
B(0,4,1,STAINED_GLASS:15)
B(0,4,2,STAINED_GLASS:15)
B(1,4,2,STAINED_GLASS:15)
B(0,4,3,STAINED_GLASS:15)
B(1,4,3,STAINED_GLASS:15)
B(0,4,4,STAINED_GLASS:15)
B(1,4,4,STAINED_GLASS:15)
B(2,4,4,STAINED_GLASS:15)
B(0,4,5,STAINED_GLASS:15)
B(1,4,5,STAINED_GLASS:15)
B(2,4,5,STAINED_GLASS:15)
B(0,4,6,STAINED_GLASS:15)
B(1,4,6,STAINED_GLASS:15)
B(2,4,6,STAINED_GLASS:15)
B(0,4,7,STAINED_GLASS:15)
B(1,4,7,STAINED_GLASS:15)
B(0,5,1,STAINED_GLASS:15)
B(0,5,2,STAINED_GLASS:15)
B(1,5,2,STAINED_GLASS:15)
B(0,5,3,STAINED_GLASS:15)
B(1,5,3,STAINED_GLASS:15)
B(0,5,4,STAINED_GLASS:15)
B(1,5,4,STAINED_GLASS:15)
B(0,5,5,STAINED_GLASS:15)
B(1,5,5,STAINED_GLASS:15)
B(2,5,5,STAINED_GLASS:15)
B(0,5,6,STAINED_GLASS:15)
B(1,5,6,STAINED_GLASS:15)
B(2,5,6,STAINED_GLASS:15)
B(0,5,7,STAINED_GLASS:15)
B(0,6,0,STAINED_GLASS:15)
B(0,6,1,STAINED_GLASS:15)
B(0,6,2,STAINED_GLASS:15)
B(1,6,2,STAINED_GLASS:15)
B(0,6,3,STAINED_GLASS:15)
B(1,6,3,STAINED_GLASS:15)
B(0,6,4,STAINED_GLASS:15)
B(1,6,4,STAINED_GLASS:15)
B(0,6,5,STAINED_GLASS:15)
B(1,6,5,STAINED_GLASS:15)
B(0,6,6,STAINED_GLASS:15)
B(0,7,0,STAINED_GLASS:15)
B(0,7,1,STAINED_GLASS:15)
B(0,7,2,STAINED_GLASS:15)
B(1,7,2,STAINED_GLASS:15)
B(0,7,3,STAINED_GLASS:15)
B(1,7,3,STAINED_GLASS:15)
B(0,7,4,STAINED_GLASS:15)
B(1,7,4,STAINED_GLASS:15)
B(0,7,5,STAINED_GLASS:15)
B(1,7,5,STAINED_GLASS:15)
B(0,8,0,STAINED_GLASS:15)
B(0,8,1,STAINED_GLASS:15)
B(0,8,2,STAINED_GLASS:15)
B(1,8,2,STAINED_GLASS:15)
B(0,8,3,STAINED_GLASS:15)
B(1,8,3,STAINED_GLASS:15)
B(0,8,4,STAINED_GLASS:15)
B(1,8,4,STAINED_GLASS:15)
B(0,9,1,STAINED_GLASS:15)
B(0,9,2,STAINED_GLASS:15)
B(1,9,2,STAINED_GLASS:15)
B(0,9,3,STAINED_GLASS:15)
B(1,9,3,STAINED_GLASS:15)
B(0,9,4,STAINED_GLASS:15)
B(1,9,4,STAINED_GLASS:15)
B(0,10,1,STAINED_GLASS:15)
B(0,10,2,STAINED_GLASS:15)
B(1,10,2,STAINED_GLASS:15)
B(0,10,3,STAINED_GLASS:15)
B(1,10,3,STAINED_GLASS:15)
B(0,10,4,STAINED_GLASS:15)
B(1,10,4,STAINED_GLASS:15)
B(0,11,1,STAINED_GLASS:15)
B(0,11,2,STAINED_GLASS:15)
B(0,11,3,STAINED_GLASS:15)
B(0,12,1,STAINED_GLASS:15)
B(0,12,2,STAINED_GLASS:15)
B(0,12,3,STAINED_GLASS:15)
B(0,13,1,STAINED_GLASS:15)
B(0,13,2,STAINED_GLASS:15)

#######################################################################
# +-----------------------------------------------------------------+ #
# |                             Branches                            | #
# +-----------------------------------------------------------------+ #
#######################################################################

BR(-16,0,0,true,SPIKE-SET-MED-BIG-16_0x1,NORTH,100,0)
BR(0,0,-16,true,SPIKE-SET-MED-BIG-16_1x0,NORTH,100,0)
