#######################################################################
# +-----------------------------------------------------------------+ #
# |                            BO3 object                           | #
# +-----------------------------------------------------------------+ #
#######################################################################

# This is the config file of a custom object.
# If you add this object correctly to your BiomeConfigs, it will spawn in the world.

# This is the creator of this BO3 object
Author: BO3 BulkEdit (by LanToaster)

# A short description of this BO3 object
Description: This Object was Created with BO3_BulkEdit

# The BO3 version, don't change this! It can be used by external applications to do a version check.
Version: 3

# The settings mode, WriteAll, WriteWithoutComments or WriteDisable. See WorldConfig.
SettingsMode: WriteDisable


#######################################################################
# +-----------------------------------------------------------------+ #
# |                          Main settings                          | #
# +-----------------------------------------------------------------+ #
#######################################################################

# This needs to be set to true to spawn the object in the Tree and Sapling resources.
Tree: false

# The frequency of the BO3 from 1 to 200. Tries this many times to spawn this BO3 when using the CustomObject(...) resource.
# Ignored by Tree(..), Sapling(..) and CustomStructure(..)
Frequency: 1

# The rarity of the BO3 from 0 to 100. Each spawn attempt has rarity% chance to succeed when using the CustomObject(...) resource.
# Ignored by Tree(..), Sapling(..) and CustomStructure(..)
Rarity: 100.0

# If you set this to true, the BO3 will be placed with a random rotation.
RotateRandomly: false

# The spawn height of the BO3 - randomY, highestBlock or highestSolidBlock.
SpawnHeight: randomY

# The height limits for the BO3.
MinHeight: 73

MaxHeight: 73

# Objects can have other objects attacthed to it: branches. Branches can also
# have branches attached to it, which can also have branches, etc. This is the
# maximum branch depth for this objects.
MaxBranchDepth: 10

# When spawned with the UseWorld keyword, this BO3 should NOT spawn in the following biomes.
# If you writer.write the BO3 name directly in the BiomeConfigs, this will be ignored.
ExcludedBiomes: All


#######################################################################
# +-----------------------------------------------------------------+ #
# |                      Source block settings                      | #
# +-----------------------------------------------------------------+ #
#######################################################################

# The block(s) the BO3 should spawn in.
SourceBlocks: AIR

# The maximum percentage of the BO3 that can be outside the SourceBlock.
# The BO3 won't be placed on a location with more blocks outside the SourceBlock than this percentage.
MaxPercentageOutsideSourceBlock: 100

# What to do when a block is about to be placed outside the SourceBlock? (dontPlace, placeAnyway)
OutsideSourceBlock: placeAnyway


#######################################################################
# +-----------------------------------------------------------------+ #
# |                              Blocks                             | #
# +-----------------------------------------------------------------+ #
#######################################################################

# All the blocks used in the BO3 are listed here. Possible blocks:
# Block(x,y,z,id[.data][,nbtfile.nbt)
# RandomBlock(x,y,z,id[:data][,nbtfile.nbt],chance[,id[:data][,nbtfile.nbt],chance[,...]])
# So RandomBlock(0,0,0,CHEST,chest.nbt,50,CHEST,anotherchest.nbt,100) will spawn a chest at
# the BO3 origin, and give it a 50% chance to have the contents of chest.nbt, or, if that
# fails, a 100% percent chance to have the contents of anotherchest.nbt.
Block(-7,0,-7,STONE:0)
Block(-6,0,-7,STONE:0)
Block(-5,0,-7,DIRT:0)
Block(-4,0,-7,STONE:0)
Block(-3,0,-7,STONE:0)
Block(-2,0,-7,STONE:0)
Block(-1,0,-7,STONE:0)
Block(0,0,-7,DIRT:0)
Block(1,0,-7,STONE:0)
Block(2,0,-7,STONE:0)
Block(3,0,-7,STONE:0)
Block(4,0,-7,STONE:0)
Block(5,0,-7,DIRT:0)
Block(6,0,-7,WATER:9)
Block(7,0,-7,WATER:9)
Block(-7,0,-6,STONE:0)
Block(-6,0,-6,DIRT:0)
Block(-5,0,-6,STONE:0)
Block(-4,0,-6,STONE:0)
Block(-3,0,-6,STONE:0)
Block(-2,0,-6,STONE:0)
Block(-1,0,-6,DIRT:0)
Block(0,0,-6,DIRT:0)
Block(1,0,-6,DIRT:0)
Block(2,0,-6,STONE:0)
Block(3,0,-6,DIRT:0)
Block(4,0,-6,STONE:0)
Block(5,0,-6,WATER:9)
Block(-7,0,-5,DIRT:0)
Block(-6,0,-5,STONE:0)
Block(-5,0,-5,DIRT:0)
Block(-4,0,-5,STONE:0)
Block(-3,0,-5,DIRT:0)
Block(-2,0,-5,STONE:0)
Block(-1,0,-5,STONE:0)
Block(0,0,-5,STONE:0)
Block(1,0,-5,DIRT:0)
Block(2,0,-5,STONE:0)
Block(4,0,-5,WATER:9)
Block(-7,0,-4,DIRT:0)
Block(-6,0,-4,STONE:0)
Block(-5,0,-4,STONE:0)
Block(-4,0,-4,STONE:0)
Block(-3,0,-4,STONE:0)
Block(-2,0,-4,DIRT:0)
Block(-1,0,-4,DIRT:0)
Block(0,0,-4,DIRT:0)
Block(1,0,-4,STONE:0)
Block(2,0,-4,DIRT:0)
Block(4,0,-4,WATER:9)
Block(-7,0,-3,DIRT:0)
Block(-6,0,-3,DIRT:0)
Block(-5,0,-3,STONE:0)
Block(-4,0,-3,DIRT:0)
Block(-3,0,-3,DIRT:0)
Block(-2,0,-3,STONE:0)
Block(-1,0,-3,DIRT:0)
Block(0,0,-3,STONE:0)
Block(1,0,-3,DIRT:0)
Block(2,0,-3,DIRT:0)
Block(4,0,-3,WATER:9)
Block(-7,0,-2,DIRT:0)
Block(-6,0,-2,STONE:0)
Block(-5,0,-2,DIRT:0)
Block(-4,0,-2,DIRT:0)
Block(-3,0,-2,STONE:0)
Block(-2,0,-2,STONE:0)
Block(-1,0,-2,STONE:0)
Block(0,0,-2,STONE:0)
Block(1,0,-2,STONE:0)
Block(2,0,-2,DIRT:0)
Block(-7,0,-1,DIRT:0)
Block(-6,0,-1,STONE:0)
Block(-5,0,-1,STONE:0)
Block(-4,0,-1,DIRT:0)
Block(-3,0,-1,STONE:0)
Block(-2,0,-1,DIRT:0)
Block(-1,0,-1,STONE:0)
Block(0,0,-1,DIRT:0)
Block(1,0,-1,STONE:0)
Block(2,0,-1,DIRT:0)
Block(-7,0,0,STONE:0)
Block(-6,0,0,DIRT:0)
Block(-5,0,0,DIRT:0)
Block(-4,0,0,STONE:0)
Block(-3,0,0,STONE:0)
Block(-2,0,0,STONE:0)
Block(-1,0,0,STONE:0)
Block(0,0,0,DIRT:0)
Block(1,0,0,STONE:0)
Block(2,0,0,STONE:0)
Block(3,0,0,STONE:0)
Block(-7,0,1,DIRT:0)
Block(-6,0,1,STONE:0)
Block(-5,0,1,DIRT:0)
Block(-4,0,1,DIRT:0)
Block(-3,0,1,DIRT:0)
Block(-2,0,1,STONE:0)
Block(-1,0,1,STONE:0)
Block(0,0,1,STONE:0)
Block(1,0,1,STONE:0)
Block(-7,0,2,DIRT:0)
Block(-6,0,2,DIRT:0)
Block(-5,0,2,DIRT:0)
Block(-4,0,2,DIRT:0)
Block(-3,0,2,STONE:0)
Block(-2,0,2,DIRT:0)
Block(-1,0,2,STONE:0)
Block(0,0,2,DIRT:0)
Block(-7,0,3,STONE:0)
Block(-6,0,3,DIRT:0)
Block(-5,0,3,DIRT:0)
Block(-4,0,3,STONE:0)
Block(-3,0,3,DIRT:0)
Block(-2,0,3,STONE:0)
Block(-1,0,3,STONE:0)
Block(0,0,3,STONE:0)
Block(-7,1,-7,DIRT:0)
Block(-6,1,-7,DIRT:0)
Block(-5,1,-7,STONE:0)
Block(-4,1,-7,STONE:0)
Block(-3,1,-7,STONE:0)
Block(-2,1,-7,DIRT:0)
Block(-1,1,-7,STONE:0)
Block(0,1,-7,DIRT:0)
Block(1,1,-7,DIRT:0)
Block(2,1,-7,DIRT:0)
Block(3,1,-7,STONE:0)
Block(4,1,-7,DIRT:0)
Block(5,1,-7,DIRT:0)
Block(6,1,-7,WATER:9)
Block(7,1,-7,WATER:9)
Block(-7,1,-6,DIRT:0)
Block(-6,1,-6,STONE:0)
Block(-5,1,-6,STONE:0)
Block(-4,1,-6,DIRT:0)
Block(-3,1,-6,DIRT:0)
Block(-2,1,-6,DIRT:0)
Block(-1,1,-6,DIRT:0)
Block(0,1,-6,STONE:0)
Block(1,1,-6,STONE:0)
Block(2,1,-6,STONE:0)
Block(3,1,-6,DIRT:0)
Block(4,1,-6,DIRT:0)
Block(5,1,-6,WATER:9)
Block(-7,1,-5,DIRT:0)
Block(-6,1,-5,STONE:0)
Block(-5,1,-5,DIRT:0)
Block(-4,1,-5,STONE:0)
Block(-3,1,-5,DIRT:0)
Block(-2,1,-5,STONE:0)
Block(-1,1,-5,STONE:0)
Block(0,1,-5,STONE:0)
Block(1,1,-5,DIRT:0)
Block(2,1,-5,STONE:0)
Block(3,1,-5,STONE:0)
Block(4,1,-5,WATER:9)
Block(-7,1,-4,DIRT:0)
Block(-6,1,-4,STONE:0)
Block(-5,1,-4,DIRT:0)
Block(-4,1,-4,STONE:0)
Block(-3,1,-4,STONE:0)
Block(-2,1,-4,STONE:0)
Block(-1,1,-4,DIRT:0)
Block(0,1,-4,DIRT:0)
Block(1,1,-4,STONE:0)
Block(2,1,-4,STONE:0)
Block(4,1,-4,WATER:9)
Block(-7,1,-3,STONE:0)
Block(-6,1,-3,DIRT:0)
Block(-5,1,-3,DIRT:0)
Block(-4,1,-3,DIRT:0)
Block(-3,1,-3,DIRT:0)
Block(-2,1,-3,DIRT:0)
Block(-1,1,-3,STONE:0)
Block(0,1,-3,STONE:0)
Block(1,1,-3,STONE:0)
Block(2,1,-3,STONE:0)
Block(4,1,-3,WATER:9)
Block(-7,1,-2,DIRT:0)
Block(-6,1,-2,DIRT:0)
Block(-5,1,-2,STONE:0)
Block(-4,1,-2,STONE:0)
Block(-3,1,-2,DIRT:0)
Block(-2,1,-2,DIRT:0)
Block(-1,1,-2,STONE:0)
Block(0,1,-2,DIRT:0)
Block(1,1,-2,DIRT:0)
Block(2,1,-2,DIRT:0)
Block(-7,1,-1,DIRT:0)
Block(-6,1,-1,DIRT:0)
Block(-5,1,-1,DIRT:0)
Block(-4,1,-1,STONE:0)
Block(-3,1,-1,DIRT:0)
Block(-2,1,-1,STONE:0)
Block(-1,1,-1,DIRT:0)
Block(0,1,-1,DIRT:0)
Block(1,1,-1,STONE:0)
Block(2,1,-1,STONE:0)
Block(-7,1,0,STONE:0)
Block(-6,1,0,STONE:0)
Block(-5,1,0,STONE:0)
Block(-4,1,0,STONE:0)
Block(-3,1,0,DIRT:0)
Block(-2,1,0,STONE:0)
Block(-1,1,0,STONE:0)
Block(0,1,0,STONE:0)
Block(1,1,0,STONE:0)
Block(2,1,0,STONE:0)
Block(-7,1,1,DIRT:0)
Block(-6,1,1,STONE:0)
Block(-5,1,1,STONE:0)
Block(-4,1,1,STONE:0)
Block(-3,1,1,DIRT:0)
Block(-2,1,1,DIRT:0)
Block(-1,1,1,DIRT:0)
Block(0,1,1,DIRT:0)
Block(1,1,1,DIRT:0)
Block(-7,1,2,DIRT:0)
Block(-6,1,2,STONE:0)
Block(-5,1,2,DIRT:0)
Block(-4,1,2,DIRT:0)
Block(-3,1,2,STONE:0)
Block(-2,1,2,STONE:0)
Block(-1,1,2,STONE:0)
Block(0,1,2,STONE:0)
Block(1,1,2,DIRT:0)
Block(-7,1,3,STONE:0)
Block(-6,1,3,STONE:0)
Block(-5,1,3,STONE:0)
Block(-4,1,3,STONE:0)
Block(-3,1,3,DIRT:0)
Block(-2,1,3,DIRT:0)
Block(-1,1,3,STONE:0)
Block(0,1,3,DIRT:0)
Block(-7,1,4,DIRT:0)
Block(-6,1,4,DIRT:0)
Block(-5,1,4,STONE:0)
Block(-4,1,4,STONE:0)
Block(-3,1,4,DIRT:0)
Block(-2,1,4,STONE:0)
Block(-1,1,4,DIRT:0)
Block(0,1,4,DIRT:0)
Block(-7,2,-7,DIRT:0)
Block(-6,2,-7,DIRT:0)
Block(-5,2,-7,STONE:0)
Block(-4,2,-7,STONE:0)
Block(-3,2,-7,DIRT:0)
Block(-2,2,-7,STONE:0)
Block(-1,2,-7,STONE:0)
Block(0,2,-7,DIRT:0)
Block(1,2,-7,DIRT:0)
Block(2,2,-7,STONE:0)
Block(3,2,-7,DIRT:0)
Block(4,2,-7,STONE:0)
Block(5,2,-7,DIRT:0)
Block(6,2,-7,WATER:9)
Block(7,2,-7,WATER:1)
Block(-7,2,-6,DIRT:0)
Block(-6,2,-6,DIRT:0)
Block(-5,2,-6,DIRT:0)
Block(-4,2,-6,STONE:0)
Block(-3,2,-6,DIRT:0)
Block(-2,2,-6,DIRT:0)
Block(-1,2,-6,STONE:0)
Block(0,2,-6,DIRT:0)
Block(1,2,-6,DIRT:0)
Block(2,2,-6,DIRT:0)
Block(3,2,-6,DIRT:0)
Block(4,2,-6,STONE:0)
Block(5,2,-6,WATER:9)
Block(-7,2,-5,STONE:0)
Block(-6,2,-5,DIRT:0)
Block(-5,2,-5,STONE:0)
Block(-4,2,-5,STONE:0)
Block(-3,2,-5,DIRT:0)
Block(-2,2,-5,STONE:0)
Block(-1,2,-5,STONE:0)
Block(0,2,-5,DIRT:0)
Block(1,2,-5,STONE:0)
Block(2,2,-5,DIRT:0)
Block(4,2,-5,WATER:9)
Block(-7,2,-4,DIRT:0)
Block(-6,2,-4,DIRT:0)
Block(-5,2,-4,DIRT:0)
Block(-4,2,-4,STONE:0)
Block(-3,2,-4,DIRT:0)
Block(-2,2,-4,DIRT:0)
Block(-1,2,-4,STONE:0)
Block(0,2,-4,DIRT:0)
Block(1,2,-4,DIRT:0)
Block(3,2,-4,WATER:9)
Block(4,2,-4,WATER:1)
Block(-7,2,-3,DIRT:0)
Block(-6,2,-3,DIRT:0)
Block(-5,2,-3,DIRT:0)
Block(-4,2,-3,DIRT:0)
Block(-3,2,-3,STONE:0)
Block(-2,2,-3,DIRT:0)
Block(-1,2,-3,STONE:0)
Block(0,2,-3,STONE:0)
Block(3,2,-3,WATER:10)
Block(4,2,-3,WATER:1)
Block(-7,2,-2,DIRT:0)
Block(-6,2,-2,DIRT:0)
Block(-5,2,-2,DIRT:0)
Block(-4,2,-2,STONE:0)
Block(-3,2,-2,STONE:0)
Block(-2,2,-2,STONE:0)
Block(-1,2,-2,DIRT:0)
Block(-7,2,-1,STONE:0)
Block(-6,2,-1,STONE:0)
Block(-5,2,-1,DIRT:0)
Block(-4,2,-1,STONE:0)
Block(-3,2,-1,DIRT:0)
Block(-2,2,-1,STONE:0)
Block(-7,2,0,STONE:0)
Block(-6,2,0,STONE:0)
Block(-5,2,0,STONE:0)
Block(-4,2,0,DIRT:0)
Block(-3,2,0,DIRT:0)
Block(-2,2,0,STONE:0)
Block(-1,2,0,STONE:0)
Block(-7,2,1,STONE:0)
Block(-6,2,1,STONE:0)
Block(-5,2,1,STONE:0)
Block(-4,2,1,STONE:0)
Block(-3,2,1,STONE:0)
Block(-2,2,1,STONE:0)
Block(-1,2,1,DIRT:0)
Block(0,2,1,STONE:0)
Block(-7,2,2,DIRT:0)
Block(-6,2,2,DIRT:0)
Block(-5,2,2,DIRT:0)
Block(-4,2,2,DIRT:0)
Block(-3,2,2,DIRT:0)
Block(-2,2,2,STONE:0)
Block(-1,2,2,STONE:0)
Block(0,2,2,STONE:0)
Block(-7,2,3,STONE:0)
Block(-6,2,3,STONE:0)
Block(-5,2,3,STONE:0)
Block(-4,2,3,DIRT:0)
Block(-3,2,3,STONE:0)
Block(-2,2,3,STONE:0)
Block(-1,2,3,STONE:0)
Block(-7,2,4,DIRT:0)
Block(-6,2,4,DIRT:0)
Block(-5,2,4,STONE:0)
Block(-4,2,4,DIRT:0)
Block(-3,2,4,DIRT:0)
Block(-6,2,5,STONE:0)
Block(-5,2,5,DIRT:0)
Block(-4,2,5,STONE:0)
Block(-7,3,-7,STONE:0)
Block(-6,3,-7,DIRT:0)
Block(-5,3,-7,DIRT:0)
Block(-4,3,-7,DIRT:0)
Block(-3,3,-7,STONE:0)
Block(-2,3,-7,STONE:0)
Block(-1,3,-7,STONE:0)
Block(0,3,-7,STONE:0)
Block(1,3,-7,DIRT:0)
Block(2,3,-7,DIRT:0)
Block(3,3,-7,STONE:0)
Block(4,3,-7,STONE:0)
Block(5,3,-7,WATER:9)
Block(6,3,-7,WATER:1)
Block(-7,3,-6,STONE:0)
Block(-6,3,-6,STONE:0)
Block(-5,3,-6,STONE:0)
Block(-4,3,-6,STONE:0)
Block(-3,3,-6,DIRT:0)
Block(-2,3,-6,STONE:0)
Block(-1,3,-6,DIRT:0)
Block(0,3,-6,DIRT:0)
Block(1,3,-6,STONE:0)
Block(2,3,-6,DIRT:0)
Block(3,3,-6,STONE:0)
Block(4,3,-6,WATER:9)
Block(5,3,-6,WATER:1)
Block(-7,3,-5,STONE:0)
Block(-6,3,-5,STONE:0)
Block(-5,3,-5,DIRT:0)
Block(-4,3,-5,STONE:0)
Block(-3,3,-5,STONE:0)
Block(-2,3,-5,STONE:0)
Block(-1,3,-5,STONE:0)
Block(0,3,-5,DIRT:0)
Block(1,3,-5,STONE:0)
Block(3,3,-5,WATER:9)
Block(4,3,-5,WATER:1)
Block(-7,3,-4,STONE:0)
Block(-6,3,-4,DIRT:0)
Block(-5,3,-4,DIRT:0)
Block(-4,3,-4,DIRT:0)
Block(-3,3,-4,DIRT:0)
Block(-2,3,-4,DIRT:0)
Block(-1,3,-4,STONE:0)
Block(2,3,-4,WATER:9)
Block(3,3,-4,WATER:1)
Block(-7,3,-3,STONE:0)
Block(-6,3,-3,STONE:0)
Block(-5,3,-3,DIRT:0)
Block(-4,3,-3,STONE:0)
Block(-3,3,-3,DIRT:0)
Block(-2,3,-3,STONE:0)
Block(1,3,-3,WATER:9)
Block(2,3,-3,WATER:1)
Block(3,3,-3,WATER:2)
Block(-7,3,-2,STONE:0)
Block(-6,3,-2,DIRT:0)
Block(-5,3,-2,DIRT:0)
Block(-4,3,-2,STONE:0)
Block(-3,3,-2,STONE:0)
Block(-2,3,-2,STONE:0)
Block(-7,3,-1,DIRT:0)
Block(-6,3,-1,STONE:0)
Block(-5,3,-1,DIRT:0)
Block(-4,3,-1,STONE:0)
Block(-3,3,-1,DIRT:0)
Block(-7,3,0,STONE:0)
Block(-6,3,0,STONE:0)
Block(-5,3,0,DIRT:0)
Block(-4,3,0,DIRT:0)
Block(-3,3,0,STONE:0)
Block(-2,3,0,DIRT:0)
Block(-7,3,1,DIRT:0)
Block(-6,3,1,DIRT:0)
Block(-5,3,1,STONE:0)
Block(-4,3,1,DIRT:0)
Block(-3,3,1,STONE:0)
Block(-2,3,1,DIRT:0)
Block(-7,3,2,DIRT:0)
Block(-6,3,2,DIRT:0)
Block(-5,3,2,DIRT:0)
Block(-4,3,2,DIRT:0)
Block(-3,3,2,DIRT:0)
Block(-7,3,3,STONE:0)
Block(-6,3,3,STONE:0)
Block(-5,3,3,DIRT:0)
Block(-4,3,3,STONE:0)
Block(-3,3,3,DIRT:0)
Block(-6,3,4,DIRT:0)
Block(-5,3,4,STONE:0)
Block(-4,3,4,STONE:0)
Block(-5,3,5,STONE:0)
Block(-7,4,-7,DIRT:0)
Block(-6,4,-7,STONE:0)
Block(-5,4,-7,STONE:0)
Block(-4,4,-7,STONE:0)
Block(-3,4,-7,DIRT:0)
Block(-2,4,-7,STONE:0)
Block(-1,4,-7,DIRT:0)
Block(0,4,-7,STONE:0)
Block(1,4,-7,STONE:0)
Block(2,4,-7,STONE:0)
Block(3,4,-7,STONE:0)
Block(4,4,-7,WATER:9)
Block(5,4,-7,WATER:1)
Block(-7,4,-6,STONE:0)
Block(-6,4,-6,DIRT:0)
Block(-5,4,-6,DIRT:0)
Block(-4,4,-6,DIRT:0)
Block(-3,4,-6,DIRT:0)
Block(-2,4,-6,DIRT:0)
Block(-1,4,-6,STONE:0)
Block(0,4,-6,DIRT:0)
Block(1,4,-6,STONE:0)
Block(2,4,-6,DIRT:0)
Block(3,4,-6,WATER:9)
Block(4,4,-6,WATER:1)
Block(-7,4,-5,DIRT:0)
Block(-6,4,-5,STONE:0)
Block(-5,4,-5,DIRT:0)
Block(-4,4,-5,STONE:0)
Block(-3,4,-5,STONE:0)
Block(-2,4,-5,DIRT:0)
Block(-1,4,-5,STONE:0)
Block(2,4,-5,WATER:9)
Block(3,4,-5,WATER:1)
Block(-7,4,-4,STONE:0)
Block(-6,4,-4,STONE:0)
Block(-5,4,-4,STONE:0)
Block(-4,4,-4,DIRT:0)
Block(-3,4,-4,STONE:0)
Block(-2,4,-4,DIRT:0)
Block(1,4,-4,WATER:9)
Block(2,4,-4,WATER:1)
Block(-7,4,-3,DIRT:0)
Block(-6,4,-3,STONE:0)
Block(-5,4,-3,DIRT:0)
Block(-4,4,-3,DIRT:0)
Block(-3,4,-3,STONE:0)
Block(-2,4,-3,DIRT:0)
Block(1,4,-3,WATER:1)
Block(-7,4,-2,DIRT:0)
Block(-6,4,-2,DIRT:0)
Block(-5,4,-2,STONE:0)
Block(-4,4,-2,STONE:0)
Block(-3,4,-2,DIRT:0)
Block(-7,4,-1,STONE:0)
Block(-6,4,-1,DIRT:0)
Block(-5,4,-1,STONE:0)
Block(-4,4,-1,STONE:0)
Block(-3,4,-1,STONE:0)
Block(-7,4,0,DIRT:0)
Block(-6,4,0,DIRT:0)
Block(-5,4,0,STONE:0)
Block(-4,4,0,STONE:0)
Block(-3,4,0,STONE:0)
Block(-7,4,1,STONE:0)
Block(-6,4,1,DIRT:0)
Block(-5,4,1,DIRT:0)
Block(-4,4,1,STONE:0)
Block(-3,4,1,STONE:0)
Block(-7,4,2,DIRT:0)
Block(-6,4,2,STONE:0)
Block(-5,4,2,DIRT:0)
Block(-4,4,2,DIRT:0)
Block(-3,4,2,STONE:0)
Block(-5,4,3,STONE:0)
Block(-4,4,3,DIRT:0)
Block(-4,4,4,DIRT:0)
Block(-7,5,-7,STONE:0)
Block(-6,5,-7,DIRT:0)
Block(-5,5,-7,DIRT:0)
Block(-4,5,-7,STONE:0)
Block(-3,5,-7,DIRT:0)
Block(-2,5,-7,STONE:0)
Block(-1,5,-7,DIRT:0)
Block(0,5,-7,STONE:0)
Block(1,5,-7,STONE:0)
Block(2,5,-7,STONE:0)
Block(3,5,-7,WATER:9)
Block(4,5,-7,WATER:9)
Block(-7,5,-6,STONE:0)
Block(-6,5,-6,DIRT:0)
Block(-5,5,-6,STONE:0)
Block(-4,5,-6,DIRT:0)
Block(-3,5,-6,STONE:0)
Block(-2,5,-6,DIRT:0)
Block(-1,5,-6,DIRT:0)
Block(0,5,-6,DIRT:0)
Block(2,5,-6,WATER:9)
Block(3,5,-6,WATER:1)
Block(-7,5,-5,DIRT:0)
Block(-6,5,-5,STONE:0)
Block(-5,5,-5,STONE:0)
Block(-4,5,-5,DIRT:0)
Block(-3,5,-5,STONE:0)
Block(-2,5,-5,DIRT:0)
Block(-1,5,-5,STONE:0)
Block(1,5,-5,WATER:9)
Block(2,5,-5,WATER:1)
Block(-7,5,-4,STONE:0)
Block(-6,5,-4,DIRT:0)
Block(-5,5,-4,STONE:0)
Block(-4,5,-4,DIRT:0)
Block(-3,5,-4,STONE:0)
Block(-2,5,-4,DIRT:0)
Block(1,5,-4,WATER:1)
Block(-7,5,-3,DIRT:0)
Block(-6,5,-3,DIRT:0)
Block(-5,5,-3,DIRT:0)
Block(-4,5,-3,DIRT:0)
Block(-3,5,-3,DIRT:0)
Block(-7,5,-2,STONE:0)
Block(-6,5,-2,STONE:0)
Block(-5,5,-2,IRON_ORE:0)
Block(-4,5,-2,STONE:0)
Block(-3,5,-2,STONE:0)
Block(-7,5,-1,DIRT:0)
Block(-6,5,-1,STONE:0)
Block(-5,5,-1,IRON_ORE:0)
Block(-4,5,-1,IRON_ORE:0)
Block(-3,5,-1,IRON_ORE:0)
Block(-7,5,0,DIRT:0)
Block(-6,5,0,STONE:0)
Block(-5,5,0,DIRT:0)
Block(-4,5,0,DIRT:0)
Block(-3,5,0,DIRT:0)
Block(-7,5,1,STONE:0)
Block(-6,5,1,STONE:0)
Block(-5,5,1,STONE:0)
Block(-4,5,1,STONE:0)
Block(-3,5,1,DIRT:0)
Block(-7,5,2,DIRT:0)
Block(-5,5,2,STONE:0)
Block(-4,5,2,DIRT:0)
Block(-7,6,-7,STONE:0)
Block(-6,6,-7,STONE:0)
Block(-5,6,-7,DIRT:0)
Block(-4,6,-7,STONE:0)
Block(-3,6,-7,STONE:0)
Block(-2,6,-7,DIRT:0)
Block(-1,6,-7,DIRT:0)
Block(0,6,-7,STONE:0)
Block(1,6,-7,STONE:0)
Block(2,6,-7,WATER:10)
Block(3,6,-7,WATER:9)
Block(4,6,-7,WATER:1)
Block(-7,6,-6,DIRT:0)
Block(-6,6,-6,STONE:0)
Block(-5,6,-6,DIRT:0)
Block(-4,6,-6,STONE:0)
Block(-3,6,-6,STONE:0)
Block(-2,6,-6,DIRT:0)
Block(-1,6,-6,DIRT:0)
Block(0,6,-6,STONE:0)
Block(1,6,-6,WATER:10)
Block(2,6,-6,WATER:1)
Block(-7,6,-5,DIRT:0)
Block(-6,6,-5,DIRT:0)
Block(-5,6,-5,DIRT:0)
Block(-4,6,-5,STONE:0)
Block(-3,6,-5,DIRT:0)
Block(-2,6,-5,DIRT:0)
Block(-1,6,-5,DIRT:0)
Block(1,6,-5,WATER:1)
Block(-7,6,-4,STONE:0)
Block(-6,6,-4,STONE:0)
Block(-5,6,-4,STONE:0)
Block(-4,6,-4,DIRT:0)
Block(-3,6,-4,STONE:0)
Block(-2,6,-4,DIRT:0)
Block(-7,6,-3,STONE:0)
Block(-6,6,-3,STONE:0)
Block(-5,6,-3,STONE:0)
Block(-4,6,-3,STONE:0)
Block(-3,6,-3,DIRT:0)
Block(-7,6,-2,DIRT:0)
Block(-6,6,-2,DIRT:0)
Block(-5,6,-2,DIRT:0)
Block(-4,6,-2,DIRT:0)
Block(-3,6,-2,STONE:0)
Block(-7,6,-1,DIRT:0)
Block(-6,6,-1,DIRT:0)
Block(-5,6,-1,DIRT:0)
Block(-4,6,-1,STONE:0)
Block(-7,6,0,STONE:0)
Block(-6,6,0,DIRT:0)
Block(-5,6,0,DIRT:0)
Block(-4,6,0,DIRT:0)
Block(-7,6,1,STONE:0)
Block(-5,6,1,DIRT:0)
Block(-4,6,1,STONE:0)
Block(-7,7,-7,DIRT:0)
Block(-6,7,-7,STONE:0)
Block(-5,7,-7,DIRT:0)
Block(-4,7,-7,STONE:0)
Block(-3,7,-7,DIRT:0)
Block(-2,7,-7,STONE:0)
Block(-1,7,-7,STONE:0)
Block(0,7,-7,STONE:0)
Block(1,7,-7,WATER:1)
Block(2,7,-7,WATER:2)
Block(3,7,-7,WATER:1)
Block(-7,7,-6,DIRT:0)
Block(-6,7,-6,STONE:0)
Block(-5,7,-6,DIRT:0)
Block(-4,7,-6,STONE:0)
Block(-3,7,-6,DIRT:0)
Block(-2,7,-6,DIRT:0)
Block(-1,7,-6,DIRT:0)
Block(1,7,-6,WATER:2)
Block(-7,7,-5,DIRT:0)
Block(-6,7,-5,DIRT:0)
Block(-5,7,-5,DIRT:0)
Block(-4,7,-5,DIRT:0)
Block(-3,7,-5,STONE:0)
Block(-2,7,-5,STONE:0)
Block(-7,7,-4,DIRT:0)
Block(-6,7,-4,DIRT:0)
Block(-5,7,-4,DIRT:0)
Block(-4,7,-4,DIRT:0)
Block(-3,7,-4,DIRT:0)
Block(-7,7,-3,STONE:0)
Block(-6,7,-3,DIRT:0)
Block(-5,7,-3,DIRT:0)
Block(-4,7,-3,STONE:0)
Block(-7,7,-2,STONE:0)
Block(-6,7,-2,DIRT:0)
Block(-5,7,-2,DIRT:0)
Block(-4,7,-2,DIRT:0)
Block(-7,7,-1,STONE:0)
Block(-6,7,-1,DIRT:0)
Block(-5,7,-1,DIRT:0)
Block(-7,7,0,DIRT:0)
Block(-7,8,-7,DIRT:0)
Block(-6,8,-7,STONE:0)
Block(-5,8,-7,DIRT:0)
Block(-4,8,-7,STONE:0)
Block(-3,8,-7,STONE:0)
Block(-2,8,-7,STONE:0)
Block(-1,8,-7,STONE:0)
Block(-7,8,-6,STONE:0)
Block(-6,8,-6,STONE:0)
Block(-5,8,-6,STONE:0)
Block(-4,8,-6,STONE:0)
Block(-3,8,-6,STONE:0)
Block(-2,8,-6,DIRT:0)
Block(-1,8,-6,DIRT:0)
Block(-7,8,-5,STONE:0)
Block(-6,8,-5,DIRT:0)
Block(-5,8,-5,DIRT:0)
Block(-4,8,-5,STONE:0)
Block(-3,8,-5,STONE:0)
Block(-7,8,-4,STONE:0)
Block(-6,8,-4,STONE:0)
Block(-5,8,-4,STONE:0)
Block(-4,8,-4,STONE:0)
Block(-7,8,-3,STONE:0)
Block(-6,8,-3,DIRT:0)
Block(-5,8,-3,DIRT:0)
Block(-7,8,-2,STONE:0)
Block(-6,8,-2,STONE:0)
Block(-7,8,-1,STONE:0)
Block(-7,9,-7,STONE:0)
Block(-6,9,-7,STONE:0)
Block(-5,9,-7,DIRT:0)
Block(-4,9,-7,DIRT:0)
Block(-3,9,-7,STONE:0)
Block(-2,9,-7,DIRT:0)
Block(-7,9,-6,DIRT:0)
Block(-6,9,-6,DIRT:0)
Block(-5,9,-6,DIRT:0)
Block(-4,9,-6,STONE:0)
Block(-3,9,-6,STONE:0)
Block(-2,9,-6,DIRT:0)
Block(-1,9,-6,STONE:0)
Block(-7,9,-5,DIRT:0)
Block(-6,9,-5,DIRT:0)
Block(-5,9,-5,DIRT:0)
Block(-4,9,-5,DIRT:0)
Block(-3,9,-5,STONE:0)
Block(-7,9,-4,DIRT:0)
Block(-6,9,-4,STONE:0)
Block(-5,9,-4,STONE:0)
Block(-4,9,-4,STONE:0)
Block(-7,9,-3,STONE:0)
Block(-6,9,-3,DIRT:0)
Block(-7,9,-2,STONE:0)
Block(-7,9,0,LEAVES:7)
Block(-7,10,-7,DIRT:0)
Block(-6,10,-7,DIRT:0)
Block(-5,10,-7,DIRT:0)
Block(-4,10,-7,STONE:0)
Block(-3,10,-7,STONE:0)
Block(-2,10,-7,DIRT:0)
Block(-7,10,-6,STONE:0)
Block(-6,10,-6,STONE:0)
Block(-5,10,-6,STONE:0)
Block(-4,10,-6,STONE:0)
Block(-3,10,-6,DIRT:0)
Block(-2,10,-6,STONE:0)
Block(-7,10,-5,STONE:0)
Block(-6,10,-5,DIRT:0)
Block(-5,10,-5,STONE:0)
Block(-4,10,-5,DIRT:0)
Block(-7,10,-4,DIRT:0)
Block(-6,10,-4,DIRT:0)
Block(-5,10,-4,STONE:0)
Block(-4,10,-4,DIRT:0)
Block(-7,10,-3,STONE:0)
Block(-7,10,-2,STONE:0)
Block(-7,10,-1,LEAVES:7)
Block(-7,10,0,LEAVES:7)
Block(-7,10,1,LEAVES:7)
Block(-7,11,-7,STONE:0)
Block(-6,11,-7,STONE:0)
Block(-5,11,-7,STONE:0)
Block(-4,11,-7,STONE:0)
Block(-3,11,-7,DIRT:0)
Block(-7,11,-6,STONE:0)
Block(-6,11,-6,DIRT:0)
Block(-5,11,-6,DIRT:0)
Block(-4,11,-6,DIRT:0)
Block(-7,11,-5,STONE:0)
Block(-6,11,-5,STONE:0)
Block(-5,11,-5,STONE:0)
Block(-7,11,-4,STONE:0)
Block(-6,11,-4,DIRT:0)
Block(-7,11,-2,LEAVES:7)
Block(-7,11,-1,LEAVES:7)
Block(-7,11,0,LEAVES:7)
Block(-7,12,-7,STONE:0)
Block(-6,12,-7,DIRT:0)
Block(-5,12,-7,DIRT:0)
Block(-4,12,-7,DIRT:0)
Block(-7,12,-6,STONE:0)
Block(-6,12,-6,DIRT:0)
Block(-5,12,-6,DIRT:0)
Block(-4,12,-6,DIRT:0)
Block(-7,12,-5,STONE:0)
Block(-6,12,-5,STONE:0)
Block(-7,12,-2,LEAVES:7)
Block(-7,12,-1,LEAVES:7)
Block(-7,12,0,LEAVES:7)
Block(-7,13,-7,DIRT:0)
Block(-6,13,-7,DIRT:0)
Block(-5,13,-7,STONE:0)
Block(-7,13,-6,STONE:0)
Block(-6,13,-6,STONE:0)
Block(-5,13,-6,DIRT:0)
Block(-7,13,-5,DIRT:0)
Block(-6,13,-5,STONE:0)
Block(-7,13,-1,LEAVES:7)
Block(-7,14,-7,STONE:0)
Block(-6,14,-7,STONE:0)
Block(-7,14,-6,STONE:0)
Block(-7,14,-5,STONE:0)
Block(-7,14,-3,LEAVES:7)
Block(-7,15,-7,STONE:0)
Block(-7,15,-4,LEAVES:7)
Block(-7,15,-3,LEAVES:7)
Block(-7,15,-2,LEAVES:7)
Block(-7,16,-3,LEAVES:7)
