#######################################################################
# +-----------------------------------------------------------------+ #
# |                            BO3 object                           | #
# +-----------------------------------------------------------------+ #
#######################################################################

Author: Bo3 BulkEdit

Description: Converted Schematic - Modified by Bo3BulkEdit

Version: 3

SettingsMode: WriteDisable

#######################################################################
# +-----------------------------------------------------------------+ #
# |                          Main settings                          | #
# +-----------------------------------------------------------------+ #
#######################################################################



Frequency: 0


SpawnHeight: randomY





##############################
# Height Limits for the BO3. #
##############################

MinHeight: 0
MaxHeight: 256

#######################################################################
# +-----------------------------------------------------------------+ #
# |                      Source block settings                      | #
# +-----------------------------------------------------------------+ #
#######################################################################

CanOverride: true
MaxPercentageOutsideSourceBlock: 100
OutsideSourceBlock: placeAnyway

#######################################################################
# +-----------------------------------------------------------------+ #
# |                               OTG+                              | #
# +-----------------------------------------------------------------+ #
#######################################################################

#######################################################################
# +-----------------------------------------------------------------+ #
# |                              Blocks                             | #
# +-----------------------------------------------------------------+ #
#######################################################################

B(0,750,0,AIR)
B(15,750,15,AIR)
B(15,-2,11,STAINED_GLASS:15)
B(15,-2,12,STAINED_GLASS:15)
B(15,-1,8,STAINED_GLASS:15)
B(14,-1,9,STAINED_GLASS:15)
B(15,-1,9,STAINED_GLASS:15)
B(13,-1,10,STAINED_GLASS:15)
B(14,-1,10,STAINED_GLASS:15)
B(15,-1,10,STAINED_GLASS:15)
B(13,-1,11,STAINED_GLASS:15)
B(14,-1,11,STAINED_GLASS:15)
B(15,-1,11,STAINED_GLASS:15)
B(15,-1,12,STAINED_GLASS:15)
B(13,0,7,STAINED_GLASS:15)
B(14,0,7,STAINED_GLASS:15)
B(15,0,7,STAINED_GLASS:15)
B(12,0,8,STAINED_GLASS:15)
B(13,0,8,STAINED_GLASS:15)
B(14,0,8,STAINED_GLASS:11)
B(15,0,8,STAINED_GLASS:11)
B(11,0,9,STAINED_GLASS:15)
B(12,0,9,STAINED_GLASS:15)
B(13,0,9,STAINED_GLASS:15)
B(14,0,9,SEA_LANTERN)
B(15,0,9,STAINED_GLASS:6)
B(11,0,10,STAINED_GLASS:15)
B(12,0,10,STAINED_GLASS:15)
B(14,0,10,SEA_LANTERN)
B(15,0,10,SEA_LANTERN)
B(12,0,11,STAINED_GLASS:15)
B(13,0,11,SEA_LANTERN)
B(14,0,11,STAINED_GLASS:15)
B(15,0,11,STAINED_GLASS:15)
B(13,0,12,STAINED_GLASS:15)
B(15,0,12,STAINED_GLASS:15)
B(12,1,7,STAINED_GLASS:15)
B(13,1,7,STAINED_GLASS:15)
B(14,1,7,STAINED_GLASS:11)
B(15,1,7,STAINED_GLASS:11)
B(11,1,8,STAINED_GLASS:15)
B(12,1,8,STAINED_GLASS:15)
B(13,1,8,STAINED_GLASS:15)
B(14,1,8,STAINED_GLASS:6)
B(15,1,8,STAINED_GLASS:11)
B(11,1,9,STAINED_GLASS:15)
B(12,1,9,STAINED_GLASS:15)
B(13,1,9,SEA_LANTERN)
B(14,1,9,SEA_LANTERN)
B(15,1,9,SEA_LANTERN)
B(11,1,10,STAINED_GLASS:15)
B(12,1,10,STAINED_GLASS:15)
B(13,1,10,SEA_LANTERN)
B(14,1,10,SEA_LANTERN)
B(15,1,10,SEA_LANTERN)
B(12,1,11,STAINED_GLASS:15)
B(13,1,11,SEA_LANTERN)
B(14,1,11,SEA_LANTERN)
B(15,1,11,STAINED_GLASS:15)
B(13,1,12,STAINED_GLASS:15)
B(14,1,12,STAINED_GLASS:15)
B(15,1,12,STAINED_GLASS:15)
B(13,2,6,STAINED_GLASS:15)
B(14,2,6,STAINED_GLASS:15)
B(10,2,7,STAINED_GLASS:15)
B(11,2,7,STAINED_GLASS:15)
B(12,2,7,STAINED_GLASS:15)
B(13,2,7,SEA_LANTERN)
B(14,2,7,STAINED_GLASS:11)
B(15,2,7,STAINED_GLASS:11)
B(11,2,8,STAINED_GLASS:15)
B(12,2,8,STAINED_GLASS:6)
B(13,2,8,SEA_LANTERN)
B(14,2,8,STAINED_GLASS:6)
B(15,2,8,STAINED_GLASS:11)
B(11,2,9,STAINED_GLASS:15)
B(12,2,9,STAINED_GLASS:15)
B(13,2,9,SEA_LANTERN)
B(14,2,9,SEA_LANTERN)
B(15,2,9,SEA_LANTERN)
B(11,2,10,STAINED_GLASS:15)
B(12,2,10,STAINED_GLASS:15)
B(13,2,10,SEA_LANTERN)
B(14,2,10,SEA_LANTERN)
B(15,2,10,SEA_LANTERN)
B(12,2,11,STAINED_GLASS:15)
B(13,2,11,STAINED_GLASS:6)
B(14,2,11,STAINED_GLASS:15)
B(15,2,11,STAINED_GLASS:15)
B(13,2,12,STAINED_GLASS:15)
B(13,3,5,STAINED_GLASS:15)
B(12,3,6,STAINED_GLASS:15)
B(13,3,6,STAINED_GLASS:15)
B(14,3,6,STAINED_GLASS:15)
B(10,3,7,STAINED_GLASS:11)
B(11,3,7,STAINED_GLASS:15)
B(12,3,7,SEA_LANTERN)
B(13,3,7,SEA_LANTERN)
B(14,3,7,STAINED_GLASS:15)
B(15,3,7,STAINED_GLASS:15)
B(11,3,8,STAINED_GLASS:11)
B(12,3,8,STAINED_GLASS:6)
B(13,3,8,SEA_LANTERN)
B(14,3,8,SEA_LANTERN)
B(15,3,8,STAINED_GLASS:11)
B(11,3,9,STAINED_GLASS:15)
B(12,3,9,STAINED_GLASS:11)
B(13,3,9,SEA_LANTERN)
B(14,3,9,SEA_LANTERN)
B(15,3,9,STAINED_GLASS:6)
B(11,3,10,STAINED_GLASS:11)
B(12,3,10,STAINED_GLASS:11)
B(13,3,10,SEA_LANTERN)
B(14,3,10,STAINED_GLASS:15)
B(15,3,10,STAINED_GLASS:15)
B(12,3,11,STAINED_GLASS:15)
B(13,3,11,STAINED_GLASS:15)
B(14,3,11,STAINED_GLASS:15)
B(13,4,4,STAINED_GLASS:15)
B(12,4,5,STAINED_GLASS:15)
B(13,4,5,STAINED_GLASS:15)
B(10,4,6,STAINED_GLASS:11)
B(11,4,6,STAINED_GLASS:11)
B(12,4,6,STAINED_GLASS:15)
B(13,4,6,SEA_LANTERN)
B(14,4,6,STAINED_GLASS:15)
B(10,4,7,STAINED_GLASS:11)
B(11,4,7,STAINED_GLASS:6)
B(12,4,7,SEA_LANTERN)
B(13,4,7,SEA_LANTERN)
B(14,4,7,STAINED_GLASS:11)
B(15,4,7,STAINED_GLASS:11)
B(11,4,8,STAINED_GLASS:11)
B(12,4,8,SEA_LANTERN)
B(13,4,8,SEA_LANTERN)
B(14,4,8,SEA_LANTERN)
B(15,4,8,STAINED_GLASS:11)
B(11,4,9,STAINED_GLASS:11)
B(12,4,9,STAINED_GLASS:11)
B(13,4,9,SEA_LANTERN)
B(14,4,9,SEA_LANTERN)
B(15,4,9,STAINED_GLASS:11)
B(11,4,10,STAINED_GLASS:11)
B(12,4,10,STAINED_GLASS:11)
B(13,4,10,STAINED_GLASS:15)
B(14,4,10,STAINED_GLASS:15)
B(15,4,10,STAINED_GLASS:15)
B(12,5,4,STAINED_GLASS:15)
B(13,5,4,STAINED_GLASS:15)
B(10,5,5,STAINED_GLASS:11)
B(11,5,5,STAINED_GLASS:15)
B(12,5,5,STAINED_GLASS:15)
B(13,5,5,STAINED_GLASS:6)
B(10,5,6,STAINED_GLASS:11)
B(11,5,6,STAINED_GLASS:15)
B(12,5,6,SEA_LANTERN)
B(13,5,6,SEA_LANTERN)
B(14,5,6,STAINED_GLASS:15)
B(10,5,7,STAINED_GLASS:11)
B(11,5,7,STAINED_GLASS:6)
B(12,5,7,SEA_LANTERN)
B(13,5,7,SEA_LANTERN)
B(14,5,7,STAINED_GLASS:11)
B(15,5,7,STAINED_GLASS:11)
B(11,5,8,STAINED_GLASS:11)
B(12,5,8,SEA_LANTERN)
B(13,5,8,SEA_LANTERN)
B(14,5,8,STAINED_GLASS:6)
B(15,5,8,STAINED_GLASS:11)
B(11,5,9,STAINED_GLASS:15)
B(12,5,9,STAINED_GLASS:11)
B(13,5,9,SEA_LANTERN)
B(14,5,9,STAINED_GLASS:11)
B(15,5,9,STAINED_GLASS:11)
B(11,5,10,STAINED_GLASS:11)
B(12,5,10,STAINED_GLASS:11)
B(13,5,10,STAINED_GLASS:15)
B(13,6,3,STAINED_GLASS:15)
B(10,6,4,STAINED_GLASS:11)
B(11,6,4,STAINED_GLASS:15)
B(12,6,4,STAINED_GLASS:15)
B(13,6,4,STAINED_GLASS:15)
B(9,6,5,STAINED_GLASS:11)
B(10,6,5,STAINED_GLASS:11)
B(11,6,5,STAINED_GLASS:15)
B(12,6,5,SEA_LANTERN)
B(13,6,5,STAINED_GLASS:6)
B(10,6,6,STAINED_GLASS:11)
B(11,6,6,STAINED_GLASS:6)
B(12,6,6,SEA_LANTERN)
B(13,6,6,SEA_LANTERN)
B(14,6,6,STAINED_GLASS:15)
B(10,6,7,STAINED_GLASS:15)
B(11,6,7,SEA_LANTERN)
B(12,6,7,SEA_LANTERN)
B(13,6,7,SEA_LANTERN)
B(14,6,7,STAINED_GLASS:11)
B(15,6,7,STAINED_GLASS:11)
B(11,6,8,STAINED_GLASS:15)
B(12,6,8,STAINED_GLASS:6)
B(13,6,8,SEA_LANTERN)
B(14,6,8,STAINED_GLASS:11)
B(11,6,9,STAINED_GLASS:15)
B(12,6,9,STAINED_GLASS:15)
B(13,6,9,STAINED_GLASS:15)
B(14,6,9,STAINED_GLASS:11)
B(12,7,3,STAINED_GLASS:15)
B(13,7,3,STAINED_GLASS:15)
B(9,7,4,STAINED_GLASS:11)
B(10,7,4,STAINED_GLASS:11)
B(11,7,4,STAINED_GLASS:15)
B(12,7,4,STAINED_GLASS:6)
B(13,7,4,STAINED_GLASS:15)
B(9,7,5,STAINED_GLASS:11)
B(10,7,5,STAINED_GLASS:11)
B(11,7,5,SEA_LANTERN)
B(12,7,5,SEA_LANTERN)
B(13,7,5,SEA_LANTERN)
B(10,7,6,STAINED_GLASS:15)
B(11,7,6,STAINED_GLASS:6)
B(12,7,6,SEA_LANTERN)
B(13,7,6,SEA_LANTERN)
B(14,7,6,STAINED_GLASS:15)
B(10,7,7,STAINED_GLASS:15)
B(11,7,7,SEA_LANTERN)
B(12,7,7,SEA_LANTERN)
B(13,7,7,STAINED_GLASS:11)
B(14,7,7,STAINED_GLASS:11)
B(15,7,7,STAINED_GLASS:11)
B(11,7,8,STAINED_GLASS:15)
B(12,7,8,STAINED_GLASS:15)
B(13,7,8,STAINED_GLASS:11)
B(14,7,8,STAINED_GLASS:11)
B(11,7,9,STAINED_GLASS:15)
B(12,7,9,STAINED_GLASS:15)
B(13,7,9,STAINED_GLASS:11)
B(11,8,2,STAINED_GLASS:11)
B(12,8,2,STAINED_GLASS:11)
B(10,8,3,STAINED_GLASS:11)
B(11,8,3,STAINED_GLASS:11)
B(12,8,3,STAINED_GLASS:15)
B(13,8,3,STAINED_GLASS:15)
B(8,8,4,STAINED_GLASS:11)
B(9,8,4,STAINED_GLASS:11)
B(10,8,4,STAINED_GLASS:6)
B(11,8,4,SEA_LANTERN)
B(12,8,4,STAINED_GLASS:6)
B(13,8,4,STAINED_GLASS:15)
B(9,8,5,STAINED_GLASS:11)
B(10,8,5,STAINED_GLASS:15)
B(11,8,5,SEA_LANTERN)
B(12,8,5,SEA_LANTERN)
B(13,8,5,SEA_LANTERN)
B(10,8,6,STAINED_GLASS:15)
B(11,8,6,SEA_LANTERN)
B(12,8,6,SEA_LANTERN)
B(13,8,6,SEA_LANTERN)
B(14,8,6,STAINED_GLASS:15)
B(10,8,7,STAINED_GLASS:15)
B(11,8,7,STAINED_GLASS:6)
B(12,8,7,STAINED_GLASS:11)
B(13,8,7,STAINED_GLASS:11)
B(11,8,8,STAINED_GLASS:15)
B(12,8,8,STAINED_GLASS:11)
B(13,8,8,STAINED_GLASS:11)
B(11,9,1,STAINED_GLASS:11)
B(10,9,2,STAINED_GLASS:11)
B(11,9,2,STAINED_GLASS:11)
B(12,9,2,STAINED_GLASS:11)
B(8,9,3,STAINED_GLASS:11)
B(9,9,3,STAINED_GLASS:11)
B(10,9,3,STAINED_GLASS:11)
B(11,9,3,STAINED_GLASS:11)
B(12,9,3,STAINED_GLASS:6)
B(13,9,3,STAINED_GLASS:15)
B(8,9,4,STAINED_GLASS:11)
B(9,9,4,STAINED_GLASS:11)
B(10,9,4,STAINED_GLASS:6)
B(11,9,4,SEA_LANTERN)
B(12,9,4,SEA_LANTERN)
B(13,9,4,STAINED_GLASS:15)
B(9,9,5,STAINED_GLASS:15)
B(10,9,5,STAINED_GLASS:15)
B(11,9,5,SEA_LANTERN)
B(12,9,5,SEA_LANTERN)
B(13,9,5,STAINED_GLASS:6)
B(10,9,6,STAINED_GLASS:15)
B(11,9,6,SEA_LANTERN)
B(12,9,6,SEA_LANTERN)
B(13,9,6,STAINED_GLASS:11)
B(14,9,6,STAINED_GLASS:15)
B(10,9,7,STAINED_GLASS:15)
B(11,9,7,STAINED_GLASS:11)
B(12,9,7,STAINED_GLASS:11)
B(11,9,8,STAINED_GLASS:11)
B(10,10,1,STAINED_GLASS:11)
B(11,10,1,STAINED_GLASS:11)
B(8,10,2,STAINED_GLASS:15)
B(9,10,2,STAINED_GLASS:11)
B(10,10,2,STAINED_GLASS:11)
B(11,10,2,SEA_LANTERN)
B(12,10,2,STAINED_GLASS:11)
B(8,10,3,STAINED_GLASS:15)
B(9,10,3,STAINED_GLASS:15)
B(10,10,3,STAINED_GLASS:6)
B(11,10,3,SEA_LANTERN)
B(12,10,3,STAINED_GLASS:6)
B(13,10,3,STAINED_GLASS:15)
B(8,10,4,STAINED_GLASS:15)
B(9,10,4,STAINED_GLASS:15)
B(10,10,4,SEA_LANTERN)
B(11,10,4,SEA_LANTERN)
B(12,10,4,SEA_LANTERN)
B(13,10,4,STAINED_GLASS:15)
B(9,10,5,STAINED_GLASS:15)
B(10,10,5,STAINED_GLASS:15)
B(11,10,5,SEA_LANTERN)
B(12,10,5,SEA_LANTERN)
B(13,10,5,STAINED_GLASS:11)
B(10,10,6,STAINED_GLASS:15)
B(11,10,6,STAINED_GLASS:6)
B(12,10,6,STAINED_GLASS:11)
B(13,10,6,STAINED_GLASS:11)
B(11,10,7,STAINED_GLASS:11)
B(11,11,0,STAINED_GLASS:11)
B(8,11,1,STAINED_GLASS:15)
B(9,11,1,STAINED_GLASS:11)
B(10,11,1,STAINED_GLASS:11)
B(11,11,1,STAINED_GLASS:6)
B(8,11,2,STAINED_GLASS:15)
B(9,11,2,STAINED_GLASS:15)
B(10,11,2,SEA_LANTERN)
B(11,11,2,SEA_LANTERN)
B(12,11,2,STAINED_GLASS:15)
B(8,11,3,STAINED_GLASS:15)
B(9,11,3,STAINED_GLASS:15)
B(10,11,3,STAINED_GLASS:6)
B(11,11,3,SEA_LANTERN)
B(12,11,3,SEA_LANTERN)
B(13,11,3,STAINED_GLASS:15)
B(8,11,4,STAINED_GLASS:15)
B(9,11,4,STAINED_GLASS:15)
B(10,11,4,SEA_LANTERN)
B(11,11,4,SEA_LANTERN)
B(12,11,4,STAINED_GLASS:6)
B(13,11,4,STAINED_GLASS:15)
B(9,11,5,STAINED_GLASS:15)
B(10,11,5,STAINED_GLASS:11)
B(11,11,5,SEA_LANTERN)
B(12,11,5,STAINED_GLASS:11)
B(13,11,5,STAINED_GLASS:11)
B(10,11,6,STAINED_GLASS:15)
B(11,11,6,STAINED_GLASS:11)
B(12,11,6,STAINED_GLASS:11)
B(10,12,0,STAINED_GLASS:11)
B(11,12,0,STAINED_GLASS:15)
B(7,12,1,STAINED_GLASS:15)
B(8,12,1,STAINED_GLASS:15)
B(9,12,1,STAINED_GLASS:15)
B(10,12,1,SEA_LANTERN)
B(11,12,1,STAINED_GLASS:6)
B(8,12,2,STAINED_GLASS:15)
B(9,12,2,STAINED_GLASS:6)
B(10,12,2,SEA_LANTERN)
B(11,12,2,SEA_LANTERN)
B(12,12,2,STAINED_GLASS:15)
B(8,12,3,STAINED_GLASS:15)
B(9,12,3,STAINED_GLASS:15)
B(10,12,3,SEA_LANTERN)
B(11,12,3,SEA_LANTERN)
B(12,12,3,SEA_LANTERN)
B(13,12,3,STAINED_GLASS:15)
B(8,12,4,STAINED_GLASS:15)
B(9,12,4,STAINED_GLASS:15)
B(10,12,4,STAINED_GLASS:6)
B(11,12,4,SEA_LANTERN)
B(12,12,4,STAINED_GLASS:15)
B(9,12,5,STAINED_GLASS:11)
B(10,12,5,STAINED_GLASS:11)
B(11,12,5,STAINED_GLASS:11)
B(12,12,5,STAINED_GLASS:11)
B(11,12,6,STAINED_GLASS:11)
B(7,13,0,STAINED_GLASS:15)
B(8,13,0,STAINED_GLASS:15)
B(9,13,0,STAINED_GLASS:11)
B(10,13,0,STAINED_GLASS:11)
B(11,13,0,STAINED_GLASS:6)
B(7,13,1,STAINED_GLASS:15)
B(8,13,1,STAINED_GLASS:15)
B(9,13,1,SEA_LANTERN)
B(10,13,1,SEA_LANTERN)
B(11,13,1,SEA_LANTERN)
B(8,13,2,STAINED_GLASS:15)
B(9,13,2,STAINED_GLASS:6)
B(10,13,2,SEA_LANTERN)
B(11,13,2,SEA_LANTERN)
B(12,13,2,STAINED_GLASS:15)
B(8,13,3,STAINED_GLASS:15)
B(9,13,3,STAINED_GLASS:15)
B(10,13,3,SEA_LANTERN)
B(11,13,3,SEA_LANTERN)
B(12,13,3,STAINED_GLASS:6)
B(13,13,3,STAINED_GLASS:15)
B(8,13,4,STAINED_GLASS:11)
B(9,13,4,STAINED_GLASS:11)
B(10,13,4,STAINED_GLASS:11)
B(11,13,4,STAINED_GLASS:15)
B(12,13,4,STAINED_GLASS:15)
B(9,13,5,STAINED_GLASS:11)
B(10,13,5,STAINED_GLASS:11)
B(11,13,5,STAINED_GLASS:11)
B(6,14,0,STAINED_GLASS:15)
B(7,14,0,STAINED_GLASS:15)
B(8,14,0,STAINED_GLASS:15)
B(9,14,0,STAINED_GLASS:15)
B(10,14,0,SEA_LANTERN)
B(11,14,0,STAINED_GLASS:6)
B(7,14,1,STAINED_GLASS:15)
B(8,14,1,STAINED_GLASS:11)
B(9,14,1,SEA_LANTERN)
B(10,14,1,SEA_LANTERN)
B(11,14,1,SEA_LANTERN)
B(8,14,2,STAINED_GLASS:11)
B(9,14,2,SEA_LANTERN)
B(10,14,2,SEA_LANTERN)
B(11,14,2,SEA_LANTERN)
B(12,14,2,STAINED_GLASS:15)
B(8,14,3,STAINED_GLASS:11)
B(9,14,3,STAINED_GLASS:11)
B(10,14,3,STAINED_GLASS:6)
B(11,14,3,SEA_LANTERN)
B(12,14,3,STAINED_GLASS:15)
B(8,14,4,STAINED_GLASS:11)
B(9,14,4,STAINED_GLASS:11)
B(10,14,4,STAINED_GLASS:11)
B(11,14,4,STAINED_GLASS:15)
B(6,15,0,STAINED_GLASS:11)
B(7,15,0,STAINED_GLASS:11)
B(8,15,0,STAINED_GLASS:11)
B(9,15,0,SEA_LANTERN)
B(10,15,0,SEA_LANTERN)
B(11,15,0,SEA_LANTERN)
B(7,15,1,STAINED_GLASS:11)
B(8,15,1,STAINED_GLASS:11)
B(9,15,1,SEA_LANTERN)
B(10,15,1,SEA_LANTERN)
B(11,15,1,STAINED_GLASS:6)
B(8,15,2,STAINED_GLASS:11)
B(9,15,2,SEA_LANTERN)
B(10,15,2,SEA_LANTERN)
B(11,15,2,STAINED_GLASS:15)
B(12,15,2,STAINED_GLASS:15)
B(8,15,3,STAINED_GLASS:11)
B(9,15,3,STAINED_GLASS:11)
B(10,15,3,STAINED_GLASS:11)
B(11,15,3,STAINED_GLASS:15)
B(12,15,3,STAINED_GLASS:15)
B(8,15,4,STAINED_GLASS:11)
B(9,15,4,STAINED_GLASS:11)
B(6,16,0,STAINED_GLASS:11)
B(7,16,0,STAINED_GLASS:11)
B(8,16,0,STAINED_GLASS:11)
B(9,16,0,SEA_LANTERN)
B(10,16,0,SEA_LANTERN)
B(11,16,0,SEA_LANTERN)
B(7,16,1,STAINED_GLASS:11)
B(8,16,1,STAINED_GLASS:11)
B(9,16,1,SEA_LANTERN)
B(10,16,1,SEA_LANTERN)
B(11,16,1,STAINED_GLASS:15)
B(8,16,2,STAINED_GLASS:11)
B(9,16,2,STAINED_GLASS:6)
B(10,16,2,STAINED_GLASS:15)
B(11,16,2,STAINED_GLASS:15)
B(8,16,3,STAINED_GLASS:11)
B(9,16,3,STAINED_GLASS:11)
B(10,16,3,STAINED_GLASS:15)
B(11,16,3,STAINED_GLASS:15)
B(6,17,0,STAINED_GLASS:11)
B(7,17,0,STAINED_GLASS:11)
B(8,17,0,STAINED_GLASS:11)
B(9,17,0,SEA_LANTERN)
B(10,17,0,SEA_LANTERN)
B(11,17,0,STAINED_GLASS:6)
B(7,17,1,STAINED_GLASS:11)
B(8,17,1,STAINED_GLASS:11)
B(9,17,1,SEA_LANTERN)
B(10,17,1,STAINED_GLASS:15)
B(11,17,1,STAINED_GLASS:15)
B(8,17,2,STAINED_GLASS:11)
B(9,17,2,STAINED_GLASS:15)
B(10,17,2,STAINED_GLASS:15)
B(8,17,3,STAINED_GLASS:11)
B(9,17,3,STAINED_GLASS:11)
B(6,18,0,STAINED_GLASS:11)
B(7,18,0,STAINED_GLASS:11)
B(8,18,0,STAINED_GLASS:11)
B(9,18,0,SEA_LANTERN)
B(10,18,0,SEA_LANTERN)
B(11,18,0,STAINED_GLASS:15)
B(7,18,1,STAINED_GLASS:11)
B(8,18,1,STAINED_GLASS:15)
B(9,18,1,STAINED_GLASS:15)
B(10,18,1,STAINED_GLASS:15)
B(9,18,2,STAINED_GLASS:15)
B(6,19,0,STAINED_GLASS:11)
B(7,19,0,STAINED_GLASS:11)
B(8,19,0,STAINED_GLASS:11)
B(9,19,0,SEA_LANTERN)
B(10,19,0,STAINED_GLASS:15)
B(11,19,0,STAINED_GLASS:15)
B(7,19,1,STAINED_GLASS:15)
B(8,19,1,STAINED_GLASS:15)
B(9,19,1,STAINED_GLASS:15)
B(6,20,0,STAINED_GLASS:11)
B(7,20,0,STAINED_GLASS:11)
B(8,20,0,STAINED_GLASS:11)
B(9,20,0,STAINED_GLASS:15)
B(10,20,0,STAINED_GLASS:15)
B(6,21,0,STAINED_GLASS:11)
B(7,21,0,STAINED_GLASS:11)
B(8,21,0,STAINED_GLASS:11)
B(9,21,0,STAINED_GLASS:11)

#######################################################################
# +-----------------------------------------------------------------+ #
# |                             Branches                            | #
# +-----------------------------------------------------------------+ #
#######################################################################

BR(16,0,0,true,SPIKE-SET-MED-BIG-19_1x1,NORTH,100,0)
BR(0,0,-16,true,SPIKE-SET-MED-BIG-19_0x0,NORTH,100,0)
