Author: Bo3 BulkEdit

Description: Converted Schematic - Modified by Bo3BulkEdit

Version: 3

SettingsMode: WriteDisable

IsOTGPlus: false
Tree: false
Frequency: 1
Rarity: 100
RotateRandomly: false
SpawnHeight: randomY
MaxBranchDepth: 20
ExcludedBiomes: All

MinHeight: 0
MaxHeight: 256

SourceBlocks: AIR
MaxPercentageOutsideSourceBlock: 100
OutsideSourceBlock: placeAnyway

B(-8,0,-8,MOSSY_COBBLESTONE:0)
B(-7,0,-8,MOSSY_COBBLESTONE:0)
B(-6,0,-8,MOSSY_COBBLESTONE:0)
B(-5,0,-8,STONE:0)
B(-4,0,-8,MOSSY_COBBLESTONE:0)
B(-3,0,-8,MOSSY_COBBLESTONE:0)
B(-2,0,-8,DIRT:1)
B(-1,0,-8,MOSSY_COBBLESTONE:0)
B(-8,0,-7,MONSTER_EGG:1)
B(-7,0,-7,STONE:0)
B(-6,0,-7,STONE:0)
B(-5,0,-7,MOSSY_COBBLESTONE:0)
B(-4,0,-7,MOSSY_COBBLESTONE:0)
B(-3,0,-7,MOSSY_COBBLESTONE:0)
B(-2,0,-7,STONE:0)
B(-1,0,-7,COBBLESTONE:0)
B(-8,0,-6,STONE:0)
B(-7,0,-6,DIRT:1)
B(-6,0,-6,MOSSY_COBBLESTONE:0)
B(-5,0,-6,STONE:0)
B(-4,0,-6,MOSSY_COBBLESTONE:0)
B(-3,0,-6,STONE:0)
B(-2,0,-6,DIRT:2)
B(-1,0,-6,COBBLESTONE:0)
B(-8,0,-5,DIRT:1)
B(-7,0,-5,MOSSY_COBBLESTONE:0)
B(-6,0,-5,MOSSY_COBBLESTONE:0)
B(-5,0,-5,STONE:0)
B(-4,0,-5,MOSSY_COBBLESTONE:0)
B(-3,0,-5,STONE:0)
B(-2,0,-5,MOSSY_COBBLESTONE:0)
B(-1,0,-5,MOSSY_COBBLESTONE:0)
B(-8,0,-4,STONE:0)
B(-7,0,-4,DIRT:2)
B(-6,0,-4,MOSSY_COBBLESTONE:0)
B(-5,0,-4,DIRT:2)
B(-4,0,-4,MOSSY_COBBLESTONE:0)
B(-3,0,-4,STONE:0)
B(-2,0,-4,MOSSY_COBBLESTONE:0)
B(-1,0,-4,DIRT:1)
B(-8,0,-3,MONSTER_EGG:1)
B(-7,0,-3,MOSSY_COBBLESTONE:0)
B(-6,0,-3,STONE:0)
B(-5,0,-3,DIRT:2)
B(-4,0,-3,MOSSY_COBBLESTONE:0)
B(-3,0,-3,MOSSY_COBBLESTONE:0)
B(-2,0,-3,MOSSY_COBBLESTONE:0)
B(-1,0,-3,MOSSY_COBBLESTONE:0)
B(-8,0,-2,DIRT:2)
B(-7,0,-2,STONE:0)
B(-6,0,-2,MOSSY_COBBLESTONE:0)
B(-5,0,-2,DIRT:2)
B(-4,0,-2,MOSSY_COBBLESTONE:0)
B(-3,0,-2,STONE:0)
B(-2,0,-2,DIRT:1)
B(-1,0,-2,MOSSY_COBBLESTONE:0)
B(-8,0,-1,DIRT:1)
B(-7,0,-1,MOSSY_COBBLESTONE:0)
B(-6,0,-1,STONE:0)
B(-5,0,-1,MOSSY_COBBLESTONE:0)
B(-4,0,-1,DIRT:2)
B(-3,0,-1,MOSSY_COBBLESTONE:0)
B(-2,0,-1,STONE:0)
B(-1,0,-1,STONE:0)
B(-8,1,-8,STONE:0)
B(-7,1,-8,STONE:0)
B(-6,1,-8,STONE:0)
B(-5,1,-8,STONE:0)
B(-4,1,-8,STONE:0)
B(-3,1,-8,COBBLESTONE:0)
B(-2,1,-8,DIRT:1)
B(-1,1,-8,MONSTER_EGG:1)
B(-8,1,-7,DIRT:1)
B(-7,1,-7,STONE:0)
B(-6,1,-7,STONE:0)
B(-5,1,-7,STONE:0)
B(-4,1,-7,STONE:0)
B(-3,1,-7,STONE:0)
B(-2,1,-7,DIRT:2)
B(-1,1,-7,STONE:0)
B(-8,1,-6,MOSSY_COBBLESTONE:0)
B(-7,1,-6,STONE:0)
B(-6,1,-6,STONE:0)
B(-5,1,-6,STONE:0)
B(-4,1,-6,STONE:0)
B(-3,1,-6,STONE:0)
B(-2,1,-6,STONE:0)
B(-1,1,-6,STONE:0)
B(-8,1,-5,COBBLESTONE:0)
B(-7,1,-5,COBBLESTONE:0)
B(-6,1,-5,STONE:0)
B(-5,1,-5,DIRT:2)
B(-4,1,-5,DIRT:1)
B(-3,1,-5,MONSTER_EGG:1)
B(-2,1,-5,DIRT:1)
B(-1,1,-5,DIRT:2)
B(-8,1,-4,COBBLESTONE:0)
B(-7,1,-4,DIRT:1)
B(-6,1,-4,MOSSY_COBBLESTONE:0)
B(-5,1,-4,STONE:0)
B(-4,1,-4,DIRT:2)
B(-3,1,-4,STONE:0)
B(-2,1,-4,MOSSY_COBBLESTONE:0)
B(-1,1,-4,STONE:0)
B(-8,1,-3,MOSSY_COBBLESTONE:0)
B(-7,1,-3,STONE:0)
B(-6,1,-3,COBBLESTONE:0)
B(-5,1,-3,STONE:0)
B(-4,1,-3,DIRT:2)
B(-3,1,-3,COBBLESTONE:0)
B(-2,1,-3,DIRT:2)
B(-1,1,-3,MONSTER_EGG:1)
B(-8,1,-2,COBBLESTONE:0)
B(-7,1,-2,DIRT:2)
B(-6,1,-2,DIRT:2)
B(-5,1,-2,STONE:0)
B(-4,1,-2,STONE:0)
B(-3,1,-2,DIRT:2)
B(-2,1,-2,COBBLESTONE:0)
B(-1,1,-2,DIRT:1)
B(-8,1,-1,MONSTER_EGG:1)
B(-7,1,-1,COBBLESTONE:0)
B(-6,1,-1,MONSTER_EGG:1)
B(-5,1,-1,DIRT:1)
B(-4,1,-1,STONE:0)
B(-3,1,-1,STONE:0)
B(-2,1,-1,STONE:0)
B(-1,1,-1,COBBLESTONE:0)
B(-8,2,-8,STONE:0)
B(-7,2,-8,STONE:0)
B(-6,2,-8,STONE:0)
B(-5,2,-8,STONE:0)
B(-4,2,-8,COBBLESTONE:0)
B(-3,2,-8,MONSTER_EGG:1)
B(-2,2,-8,DIRT:2)
B(-1,2,-8,STONE:0)
B(-8,2,-7,DIRT:2)
B(-7,2,-7,STONE:0)
B(-6,2,-7,STONE:0)
B(-5,2,-7,STONE:0)
B(-4,2,-7,DIRT:1)
B(-3,2,-7,COBBLESTONE:0)
B(-2,2,-7,STONE:0)
B(-1,2,-7,DIRT:2)
B(-8,2,-6,MONSTER_EGG:1)
B(-7,2,-6,MOSSY_COBBLESTONE:0)
B(-6,2,-6,STONE:0)
B(-5,2,-6,STONE:0)
B(-4,2,-6,MOSSY_COBBLESTONE:0)
B(-3,2,-6,DIRT:2)
B(-2,2,-6,DIRT:1)
B(-1,2,-6,DIRT:2)
B(-8,2,-5,DIRT:2)
B(-7,2,-5,STONE:0)
B(-6,2,-5,COBBLESTONE:0)
B(-5,2,-5,STONE:0)
B(-4,2,-5,COBBLESTONE:0)
B(-3,2,-5,STONE:0)
B(-2,2,-5,STONE:0)
B(-1,2,-5,MOSSY_COBBLESTONE:0)
B(-8,2,-4,COBBLESTONE:0)
B(-7,2,-4,MONSTER_EGG:1)
B(-6,2,-4,COBBLESTONE:0)
B(-5,2,-4,STONE:0)
B(-4,2,-4,MONSTER_EGG:1)
B(-3,2,-4,MOSSY_COBBLESTONE:0)
B(-2,2,-4,MOSSY_COBBLESTONE:0)
B(-1,2,-4,DIRT:2)
B(-8,2,-3,MOSSY_COBBLESTONE:0)
B(-7,2,-3,DIRT:1)
B(-6,2,-3,MOSSY_COBBLESTONE:0)
B(-5,2,-3,COBBLESTONE:0)
B(-4,2,-3,DIRT:1)
B(-3,2,-3,DIRT:1)
B(-2,2,-3,STONE:0)
B(-1,2,-3,DIRT:1)
B(-8,2,-2,MOSSY_COBBLESTONE:0)
B(-7,2,-2,MOSSY_COBBLESTONE:0)
B(-6,2,-2,DIRT:2)
B(-5,2,-2,DIRT:1)
B(-4,2,-2,COBBLESTONE:0)
B(-3,2,-2,STONE:0)
B(-2,2,-2,STONE:0)
B(-1,2,-2,STONE:0)
B(-8,2,-1,DIRT:2)
B(-7,2,-1,STONE:0)
B(-6,2,-1,DIRT:1)
B(-5,2,-1,STONE:0)
B(-4,2,-1,STONE:0)
B(-3,2,-1,STONE:0)
B(-2,2,-1,STONE:0)
B(-1,2,-1,STONE:0)
B(-8,3,-8,STONE:0)
B(-7,3,-8,STONE:0)
B(-6,3,-8,STONE:0)
B(-5,3,-8,STONE:0)
B(-4,3,-8,STONE:0)
B(-3,3,-8,STONE:0)
B(-2,3,-8,STONE:0)
B(-1,3,-8,DIRT:2)
B(-8,3,-7,STONE:0)
B(-7,3,-7,STONE:0)
B(-6,3,-7,STONE:0)
B(-5,3,-7,STONE:0)
B(-4,3,-7,DIRT:2)
B(-3,3,-7,MOSSY_COBBLESTONE:0)
B(-2,3,-7,COBBLESTONE:0)
B(-1,3,-7,DIRT:2)
B(-8,3,-6,STONE:0)
B(-7,3,-6,STONE:0)
B(-6,3,-6,STONE:0)
B(-5,3,-6,STONE:0)
B(-4,3,-6,DIRT:1)
B(-3,3,-6,STONE:0)
B(-2,3,-6,DIRT:2)
B(-1,3,-6,COBBLESTONE:0)
B(-8,3,-5,STONE:0)
B(-7,3,-5,STONE:0)
B(-6,3,-5,MONSTER_EGG:1)
B(-5,3,-5,DIRT:2)
B(-4,3,-5,DIRT:1)
B(-3,3,-5,STONE:0)
B(-2,3,-5,MONSTER_EGG:1)
B(-1,3,-5,DIRT:2)
B(-8,3,-4,WATER:0)
B(-7,3,-4,WATER:0)
B(-6,3,-4,COBBLESTONE:0)
B(-5,3,-4,DIRT:1)
B(-4,3,-4,DIRT:2)
B(-3,3,-4,COBBLESTONE:0)
B(-2,3,-4,DIRT:2)
B(-1,3,-4,DIRT:1)
B(-8,3,-3,WATER:0)
B(-7,3,-3,WATER:0)
B(-6,3,-3,WATER:0)
B(-5,3,-3,STONE:0)
B(-4,3,-3,COBBLESTONE:0)
B(-3,3,-3,DIRT:1)
B(-2,3,-3,DIRT:2)
B(-1,3,-3,DIRT:1)
B(-8,3,-2,WATER:0)
B(-7,3,-2,WATER:0)
B(-6,3,-2,COBBLESTONE:0)
B(-5,3,-2,STONE:0)
B(-4,3,-2,COBBLESTONE:0)
B(-3,3,-2,DIRT:2)
B(-2,3,-2,DIRT:2)
B(-1,3,-2,MOSSY_COBBLESTONE:0)
B(-8,3,-1,WATER:0)
B(-7,3,-1,DIRT:1)
B(-6,3,-1,DIRT:1)
B(-5,3,-1,DIRT:1)
B(-4,3,-1,DIRT:2)
B(-3,3,-1,COBBLESTONE:0)
B(-2,3,-1,DIRT:2)
B(-1,3,-1,MOSSY_COBBLESTONE:0)
B(-8,4,-8,DIRT:2)
B(-7,4,-8,STONE:0)
B(-6,4,-8,STONE:0)
B(-5,4,-8,STONE:0)
B(-4,4,-8,DIRT:1)
B(-3,4,-8,MOSSY_COBBLESTONE:0)
B(-2,4,-8,DIRT:2)
B(-1,4,-8,DIRT:2)
B(-8,4,-7,DIRT:2)
B(-7,4,-7,STONE:0)
B(-6,4,-7,STONE:0)
B(-5,4,-7,STONE:0)
B(-4,4,-7,STONE:0)
B(-3,4,-7,COBBLESTONE:0)
B(-2,4,-7,MOSSY_COBBLESTONE:0)
B(-1,4,-7,MOSSY_COBBLESTONE:0)
B(-8,4,-6,STONE:0)
B(-7,4,-6,STONE:0)
B(-6,4,-6,STONE:0)
B(-5,4,-6,STONE:0)
B(-4,4,-6,DIRT:1)
B(-3,4,-6,MOSSY_COBBLESTONE:0)
B(-2,4,-6,DIRT:2)
B(-1,4,-6,WATER:0)
B(-8,4,-5,STONE:0)
B(-7,4,-5,STONE:0)
B(-6,4,-5,DIRT:2)
B(-5,4,-5,STONE:0)
B(-4,4,-5,COBBLESTONE:0)
B(-3,4,-5,DIRT:1)
B(-2,4,-5,DIRT:2)
B(-1,4,-5,DIRT:1)
B(-8,4,-4,AIR:0)
B(-7,4,-4,AIR:0)
B(-6,4,-4,AIR:0)
B(-5,4,-4,BROWN_MUSHROOM:0)
B(-4,4,-4,STONE:0)
B(-3,4,-4,MONSTER_EGG:1)
B(-2,4,-4,BROWN_MUSHROOM_BLOCK:3)
B(-1,4,-4,WATER:0)
B(-8,4,-3,AIR:0)
B(-7,4,-3,AIR:0)
B(-6,4,-3,WATER:6)
B(-5,4,-3,WATER:5)
B(-4,4,-3,BROWN_MUSHROOM_BLOCK:1)
B(-3,4,-3,RED_MUSHROOM_BLOCK:1)
B(-2,4,-3,WATER:0)
B(-1,4,-3,DIRT:2)
B(-8,4,-2,AIR:0)
B(-7,4,-2,WATER:6)
B(-6,4,-2,WATER:5)
B(-5,4,-2,WATER:4)
B(-4,4,-2,RED_MUSHROOM_BLOCK:7)
B(-3,4,-2,WATER:10)
B(-2,4,-2,DIRT:2)
B(-1,4,-2,DIRT:2)
B(-8,4,-1,WATER:6)
B(-7,4,-1,WATER:5)
B(-6,4,-1,WATER:4)
B(-5,4,-1,WATER:3)
B(-4,4,-1,WATER:2)
B(-3,4,-1,WATER:1)
B(-2,4,-1,COBBLESTONE:0)
B(-1,4,-1,DIRT:2)
B(-8,5,-8,DIRT:2)
B(-7,5,-8,STONE:0)
B(-6,5,-8,STONE:0)
B(-5,5,-8,STONE:0)
B(-4,5,-8,DIRT:2)
B(-3,5,-8,DIRT:1)
B(-2,5,-8,STONE:0)
B(-1,5,-8,WATER:0)
B(-8,5,-7,DIRT:2)
B(-7,5,-7,STONE:0)
B(-6,5,-7,STONE:0)
B(-5,5,-7,STONE:0)
B(-4,5,-7,COBBLESTONE:0)
B(-3,5,-7,STONE:0)
B(-2,5,-7,WATER:0)
B(-1,5,-7,WATER:0)
B(-8,5,-6,STONE:0)
B(-7,5,-6,STONE:0)
B(-6,5,-6,STONE:0)
B(-5,5,-6,STONE:0)
B(-4,5,-6,STONE:0)
B(-3,5,-6,STONE:0)
B(-2,5,-6,WATER:0)
B(-1,5,-6,WATER:0)
B(-8,5,-5,AIR:0)
B(-7,5,-5,STONE:0)
B(-6,5,-5,STONE:0)
B(-5,5,-5,BROWN_MUSHROOM:0)
B(-4,5,-5,DIRT:1)
B(-3,5,-5,RED_MUSHROOM_BLOCK:1)
B(-2,5,-5,WATER:0)
B(-1,5,-5,WATER:0)
B(-8,5,-4,AIR:0)
B(-7,5,-4,AIR:0)
B(-6,5,-4,AIR:0)
B(-5,5,-4,AIR:0)
B(-4,5,-4,BROWN_MUSHROOM:0)
B(-3,5,-4,RED_MUSHROOM_BLOCK:7)
B(-2,5,-4,WATER:0)
B(-1,5,-4,WATER:0)
B(-8,5,-3,AIR:0)
B(-7,5,-3,AIR:0)
B(-6,5,-3,AIR:0)
B(-5,5,-3,AIR:0)
B(-4,5,-3,AIR:0)
B(-3,5,-3,WATER:1)
B(-2,5,-3,WATER:0)
B(-1,5,-3,WATER:0)
B(-8,5,-2,AIR:0)
B(-7,5,-2,AIR:0)
B(-6,5,-2,AIR:0)
B(-5,5,-2,AIR:0)
B(-4,5,-2,AIR:0)
B(-3,5,-2,WATER:2)
B(-2,5,-2,WATER:1)
B(-1,5,-2,MONSTER_EGG:1)
B(-8,5,-1,AIR:0)
B(-7,5,-1,AIR:0)
B(-6,5,-1,AIR:0)
B(-5,5,-1,AIR:0)
B(-4,5,-1,AIR:0)
B(-3,5,-1,AIR:0)
B(-2,5,-1,BROWN_MUSHROOM:0)
B(-1,5,-1,MOSSY_COBBLESTONE:0)
B(-8,6,-8,DIRT:2)
B(-7,6,-8,STONE:0)
B(-6,6,-8,STONE:0)
B(-5,6,-8,STONE:0)
B(-4,6,-8,DIRT:2)
B(-3,6,-8,STONE:0)
B(-2,6,-8,BROWN_MUSHROOM:0)
B(-1,6,-8,AIR:0)
B(-8,6,-7,DIRT:2)
B(-7,6,-7,STONE:0)
B(-6,6,-7,STONE:0)
B(-5,6,-7,STONE:0)
B(-4,6,-7,STONE:0)
B(-3,6,-7,BROWN_MUSHROOM:0)
B(-2,6,-7,AIR:0)
B(-1,6,-7,AIR:0)
B(-8,6,-6,AIR:0)
B(-7,6,-6,STONE:0)
B(-6,6,-6,STONE:0)
B(-5,6,-6,BROWN_MUSHROOM:0)
B(-4,6,-6,DIRT:1)
B(-3,6,-6,BROWN_MUSHROOM:0)
B(-2,6,-6,AIR:0)
B(-1,6,-6,AIR:0)
B(-8,6,-5,AIR:0)
B(-7,6,-5,AIR:0)
B(-6,6,-5,BROWN_MUSHROOM:0)
B(-5,6,-5,AIR:0)
B(-4,6,-5,BROWN_MUSHROOM:0)
B(-3,6,-5,AIR:0)
B(-2,6,-5,AIR:0)
B(-1,6,-5,AIR:0)
B(-8,6,-4,AIR:0)
B(-7,6,-4,AIR:0)
B(-6,6,-4,AIR:0)
B(-5,6,-4,AIR:0)
B(-4,6,-4,AIR:0)
B(-3,6,-4,AIR:0)
B(-2,6,-4,AIR:0)
B(-1,6,-4,AIR:0)
B(-8,6,-3,AIR:0)
B(-7,6,-3,AIR:0)
B(-6,6,-3,AIR:0)
B(-5,6,-3,AIR:0)
B(-4,6,-3,AIR:0)
B(-3,6,-3,AIR:0)
B(-2,6,-3,AIR:0)
B(-1,6,-3,AIR:0)
B(-8,6,-2,AIR:0)
B(-7,6,-2,AIR:0)
B(-6,6,-2,AIR:0)
B(-5,6,-2,AIR:0)
B(-4,6,-2,AIR:0)
B(-3,6,-2,AIR:0)
B(-2,6,-2,AIR:0)
B(-1,6,-2,RED_MUSHROOM:0)
B(-8,6,-1,AIR:0)
B(-7,6,-1,AIR:0)
B(-6,6,-1,AIR:0)
B(-5,6,-1,AIR:0)
B(-4,6,-1,AIR:0)
B(-3,6,-1,AIR:0)
B(-2,6,-1,AIR:0)
B(-1,6,-1,BROWN_MUSHROOM:0)
B(-8,7,-8,STONE:0)
B(-7,7,-8,STONE:0)
B(-6,7,-8,STONE:0)
B(-5,7,-8,STONE:0)
B(-4,7,-8,BROWN_MUSHROOM:0)
B(-3,7,-8,BROWN_MUSHROOM:0)
B(-2,7,-8,AIR:0)
B(-1,7,-8,AIR:0)
B(-8,7,-7,BROWN_MUSHROOM_BLOCK:1)
B(-7,7,-7,STONE:0)
B(-6,7,-7,STONE:0)
B(-5,7,-7,STONE:0)
B(-4,7,-7,BROWN_MUSHROOM:0)
B(-3,7,-7,AIR:0)
B(-2,7,-7,AIR:0)
B(-1,7,-7,AIR:0)
B(-8,7,-6,AIR:0)
B(-7,7,-6,RED_MUSHROOM_BLOCK:1)
B(-6,7,-6,STONE:0)
B(-5,7,-6,AIR:0)
B(-4,7,-6,BROWN_MUSHROOM:0)
B(-3,7,-6,AIR:0)
B(-2,7,-6,AIR:0)
B(-1,7,-6,AIR:0)
B(-8,7,-5,AIR:0)
B(-7,7,-5,AIR:0)
B(-6,7,-5,AIR:0)
B(-5,7,-5,AIR:0)
B(-4,7,-5,AIR:0)
B(-3,7,-5,AIR:0)
B(-2,7,-5,AIR:0)
B(-1,7,-5,AIR:0)
B(-8,7,-4,AIR:0)
B(-7,7,-4,AIR:0)
B(-6,7,-4,AIR:0)
B(-5,7,-4,AIR:0)
B(-4,7,-4,AIR:0)
B(-3,7,-4,AIR:0)
B(-2,7,-4,AIR:0)
B(-1,7,-4,AIR:0)
B(-8,7,-3,AIR:0)
B(-7,7,-3,AIR:0)
B(-6,7,-3,AIR:0)
B(-5,7,-3,AIR:0)
B(-4,7,-3,AIR:0)
B(-3,7,-3,AIR:0)
B(-2,7,-3,AIR:0)
B(-1,7,-3,AIR:0)
B(-8,7,-2,AIR:0)
B(-7,7,-2,AIR:0)
B(-6,7,-2,AIR:0)
B(-5,7,-2,AIR:0)
B(-4,7,-2,AIR:0)
B(-3,7,-2,AIR:0)
B(-2,7,-2,AIR:0)
B(-1,7,-2,AIR:0)
B(-8,7,-1,AIR:0)
B(-7,7,-1,AIR:0)
B(-6,7,-1,AIR:0)
B(-5,7,-1,AIR:0)
B(-4,7,-1,AIR:0)
B(-3,7,-1,AIR:0)
B(-2,7,-1,AIR:0)
B(-1,7,-1,AIR:0)
B(-8,8,-8,RED_MUSHROOM_BLOCK:7)
B(-7,8,-8,MOSSY_COBBLESTONE:0)
B(-6,8,-8,MOSSY_COBBLESTONE:0)
B(-5,8,-8,BROWN_MUSHROOM:0)
B(-4,8,-8,AIR:0)
B(-3,8,-8,AIR:0)
B(-2,8,-8,AIR:0)
B(-1,8,-8,AIR:0)
B(-8,8,-7,AIR:0)
B(-7,8,-7,RED_MUSHROOM_BLOCK:3)
B(-6,8,-7,RED_MUSHROOM_BLOCK:7)
B(-5,8,-7,BROWN_MUSHROOM:0)
B(-4,8,-7,AIR:0)
B(-3,8,-7,AIR:0)
B(-2,8,-7,AIR:0)
B(-1,8,-7,AIR:0)
B(-8,8,-6,AIR:0)
B(-7,8,-6,AIR:0)
B(-6,8,-6,BROWN_MUSHROOM:0)
B(-5,8,-6,AIR:0)
B(-4,8,-6,AIR:0)
B(-3,8,-6,AIR:0)
B(-2,8,-6,AIR:0)
B(-1,8,-6,AIR:0)
B(-8,8,-5,AIR:0)
B(-7,8,-5,AIR:0)
B(-6,8,-5,AIR:0)
B(-5,8,-5,AIR:0)
B(-4,8,-5,AIR:0)
B(-3,8,-5,AIR:0)
B(-2,8,-5,AIR:0)
B(-1,8,-5,AIR:0)
B(-8,8,-4,AIR:0)
B(-7,8,-4,AIR:0)
B(-6,8,-4,AIR:0)
B(-5,8,-4,AIR:0)
B(-4,8,-4,AIR:0)
B(-3,8,-4,AIR:0)
B(-2,8,-4,AIR:0)
B(-1,8,-4,AIR:0)
B(-8,8,-3,AIR:0)
B(-7,8,-3,AIR:0)
B(-6,8,-3,AIR:0)
B(-5,8,-3,AIR:0)
B(-4,8,-3,AIR:0)
B(-3,8,-3,AIR:0)
B(-2,8,-3,AIR:0)
B(-1,8,-3,AIR:0)
B(-8,8,-2,AIR:0)
B(-7,8,-2,AIR:0)
B(-6,8,-2,AIR:0)
B(-5,8,-2,AIR:0)
B(-4,8,-2,AIR:0)
B(-3,8,-2,AIR:0)
B(-2,8,-2,AIR:0)
B(-1,8,-2,AIR:0)
B(-8,8,-1,AIR:0)
B(-7,8,-1,AIR:0)
B(-6,8,-1,AIR:0)
B(-5,8,-1,AIR:0)
B(-4,8,-1,AIR:0)
B(-3,8,-1,AIR:0)
B(-2,8,-1,AIR:0)
B(-1,8,-1,AIR:0)
B(-8,9,-8,AIR:0)
B(-7,9,-8,BROWN_MUSHROOM:0)
B(-6,9,-8,MOSSY_COBBLESTONE:0)
B(-5,9,-8,AIR:0)
B(-4,9,-8,AIR:0)
B(-3,9,-8,AIR:0)
B(-2,9,-8,AIR:0)
B(-1,9,-8,AIR:0)
B(-8,9,-7,AIR:0)
B(-7,9,-7,AIR:0)
B(-6,9,-7,AIR:0)
B(-5,9,-7,AIR:0)
B(-4,9,-7,AIR:0)
B(-3,9,-7,AIR:0)
B(-2,9,-7,AIR:0)
B(-1,9,-7,AIR:0)
B(-8,9,-6,AIR:0)
B(-7,9,-6,AIR:0)
B(-6,9,-6,AIR:0)
B(-5,9,-6,AIR:0)
B(-4,9,-6,AIR:0)
B(-3,9,-6,AIR:0)
B(-2,9,-6,AIR:0)
B(-1,9,-6,AIR:0)
B(-8,9,-5,AIR:0)
B(-7,9,-5,AIR:0)
B(-6,9,-5,AIR:0)
B(-5,9,-5,AIR:0)
B(-4,9,-5,AIR:0)
B(-3,9,-5,AIR:0)
B(-2,9,-5,AIR:0)
B(-1,9,-5,AIR:0)
B(-8,9,-4,AIR:0)
B(-7,9,-4,AIR:0)
B(-6,9,-4,AIR:0)
B(-5,9,-4,AIR:0)
B(-4,9,-4,AIR:0)
B(-3,9,-4,AIR:0)
B(-2,9,-4,AIR:0)
B(-1,9,-4,AIR:0)
B(-8,9,-3,AIR:0)
B(-7,9,-3,AIR:0)
B(-6,9,-3,AIR:0)
B(-5,9,-3,AIR:0)
B(-4,9,-3,AIR:0)
B(-3,9,-3,AIR:0)
B(-2,9,-3,AIR:0)
B(-1,9,-3,AIR:0)
B(-8,9,-2,AIR:0)
B(-7,9,-2,AIR:0)
B(-6,9,-2,AIR:0)
B(-5,9,-2,AIR:0)
B(-4,9,-2,AIR:0)
B(-3,9,-2,AIR:0)
B(-2,9,-2,AIR:0)
B(-1,9,-2,AIR:0)
B(-8,9,-1,AIR:0)
B(-7,9,-1,AIR:0)
B(-6,9,-1,AIR:0)
B(-5,9,-1,AIR:0)
B(-4,9,-1,AIR:0)
B(-3,9,-1,AIR:0)
B(-2,9,-1,AIR:0)
B(-1,9,-1,AIR:0)
B(-8,10,-8,AIR:0)
B(-7,10,-8,AIR:0)
B(-6,10,-8,BROWN_MUSHROOM:0)
B(-5,10,-8,AIR:0)
B(-4,10,-8,AIR:0)
B(-3,10,-8,AIR:0)
B(-2,10,-8,AIR:0)
B(-1,10,-8,AIR:0)
B(-8,10,-7,AIR:0)
B(-7,10,-7,AIR:0)
B(-6,10,-7,AIR:0)
B(-5,10,-7,AIR:0)
B(-4,10,-7,AIR:0)
B(-3,10,-7,AIR:0)
B(-2,10,-7,AIR:0)
B(-1,10,-7,AIR:0)
B(-8,10,-6,AIR:0)
B(-7,10,-6,AIR:0)
B(-6,10,-6,AIR:0)
B(-5,10,-6,AIR:0)
B(-4,10,-6,AIR:0)
B(-3,10,-6,AIR:0)
B(-2,10,-6,AIR:0)
B(-1,10,-6,AIR:0)
B(-8,10,-5,AIR:0)
B(-7,10,-5,AIR:0)
B(-6,10,-5,AIR:0)
B(-5,10,-5,AIR:0)
B(-4,10,-5,AIR:0)
B(-3,10,-5,AIR:0)
B(-2,10,-5,AIR:0)
B(-1,10,-5,AIR:0)
B(-8,10,-4,AIR:0)
B(-7,10,-4,AIR:0)
B(-6,10,-4,AIR:0)
B(-5,10,-4,AIR:0)
B(-4,10,-4,AIR:0)
B(-3,10,-4,AIR:0)
B(-2,10,-4,AIR:0)
B(-1,10,-4,AIR:0)
B(-8,10,-3,AIR:0)
B(-7,10,-3,AIR:0)
B(-6,10,-3,AIR:0)
B(-5,10,-3,AIR:0)
B(-4,10,-3,AIR:0)
B(-3,10,-3,AIR:0)
B(-2,10,-3,AIR:0)
B(-1,10,-3,AIR:0)
B(-8,10,-2,AIR:0)
B(-7,10,-2,AIR:0)
B(-6,10,-2,AIR:0)
B(-5,10,-2,AIR:0)
B(-4,10,-2,AIR:0)
B(-3,10,-2,AIR:0)
B(-2,10,-2,AIR:0)
B(-1,10,-2,AIR:0)
B(-8,10,-1,AIR:0)
B(-7,10,-1,AIR:0)
B(-6,10,-1,AIR:0)
B(-5,10,-1,AIR:0)
B(-4,10,-1,AIR:0)
B(-3,10,-1,AIR:0)
B(-2,10,-1,AIR:0)
B(-1,10,-1,AIR:0)
B(-8,11,-8,AIR:0)
B(-7,11,-8,AIR:0)
B(-6,11,-8,AIR:0)
B(-5,11,-8,AIR:0)
B(-4,11,-8,AIR:0)
B(-3,11,-8,AIR:0)
B(-2,11,-8,AIR:0)
B(-1,11,-8,AIR:0)
B(-8,11,-7,AIR:0)
B(-7,11,-7,AIR:0)
B(-6,11,-7,AIR:0)
B(-5,11,-7,AIR:0)
B(-4,11,-7,AIR:0)
B(-3,11,-7,AIR:0)
B(-2,11,-7,AIR:0)
B(-1,11,-7,AIR:0)
B(-8,11,-6,AIR:0)
B(-7,11,-6,AIR:0)
B(-6,11,-6,AIR:0)
B(-5,11,-6,AIR:0)
B(-4,11,-6,AIR:0)
B(-3,11,-6,AIR:0)
B(-2,11,-6,AIR:0)
B(-1,11,-6,AIR:0)
B(-8,11,-5,AIR:0)
B(-7,11,-5,AIR:0)
B(-6,11,-5,AIR:0)
B(-5,11,-5,AIR:0)
B(-4,11,-5,AIR:0)
B(-3,11,-5,AIR:0)
B(-2,11,-5,AIR:0)
B(-1,11,-5,AIR:0)
B(-8,11,-4,AIR:0)
B(-7,11,-4,AIR:0)
B(-6,11,-4,AIR:0)
B(-5,11,-4,AIR:0)
B(-4,11,-4,AIR:0)
B(-3,11,-4,AIR:0)
B(-2,11,-4,AIR:0)
B(-1,11,-4,AIR:0)
B(-8,11,-3,AIR:0)
B(-7,11,-3,AIR:0)
B(-6,11,-3,AIR:0)
B(-5,11,-3,AIR:0)
B(-4,11,-3,AIR:0)
B(-3,11,-3,AIR:0)
B(-2,11,-3,AIR:0)
B(-1,11,-3,AIR:0)
B(-8,11,-2,AIR:0)
B(-7,11,-2,AIR:0)
B(-6,11,-2,AIR:0)
B(-5,11,-2,AIR:0)
B(-4,11,-2,AIR:0)
B(-3,11,-2,AIR:0)
B(-2,11,-2,AIR:0)
B(-1,11,-2,AIR:0)
B(-8,11,-1,AIR:0)
B(-7,11,-1,AIR:0)
B(-6,11,-1,AIR:0)
B(-5,11,-1,AIR:0)
B(-4,11,-1,AIR:0)
B(-3,11,-1,AIR:0)
B(-2,11,-1,AIR:0)
B(-1,11,-1,AIR:0)
B(-8,12,-8,AIR:0)
B(-7,12,-8,AIR:0)
B(-6,12,-8,AIR:0)
B(-5,12,-8,AIR:0)
B(-4,12,-8,AIR:0)
B(-3,12,-8,AIR:0)
B(-2,12,-8,AIR:0)
B(-1,12,-8,AIR:0)
B(-8,12,-7,AIR:0)
B(-7,12,-7,AIR:0)
B(-6,12,-7,AIR:0)
B(-5,12,-7,AIR:0)
B(-4,12,-7,AIR:0)
B(-3,12,-7,AIR:0)
B(-2,12,-7,AIR:0)
B(-1,12,-7,AIR:0)
B(-8,12,-6,AIR:0)
B(-7,12,-6,AIR:0)
B(-6,12,-6,AIR:0)
B(-5,12,-6,AIR:0)
B(-4,12,-6,AIR:0)
B(-3,12,-6,AIR:0)
B(-2,12,-6,AIR:0)
B(-1,12,-6,AIR:0)
B(-8,12,-5,AIR:0)
B(-7,12,-5,AIR:0)
B(-6,12,-5,AIR:0)
B(-5,12,-5,AIR:0)
B(-4,12,-5,AIR:0)
B(-3,12,-5,AIR:0)
B(-2,12,-5,AIR:0)
B(-1,12,-5,AIR:0)
B(-8,12,-4,AIR:0)
B(-7,12,-4,AIR:0)
B(-6,12,-4,AIR:0)
B(-5,12,-4,AIR:0)
B(-4,12,-4,AIR:0)
B(-3,12,-4,AIR:0)
B(-2,12,-4,AIR:0)
B(-1,12,-4,AIR:0)
B(-8,12,-3,AIR:0)
B(-7,12,-3,AIR:0)
B(-6,12,-3,AIR:0)
B(-5,12,-3,AIR:0)
B(-4,12,-3,AIR:0)
B(-3,12,-3,AIR:0)
B(-2,12,-3,AIR:0)
B(-1,12,-3,AIR:0)
B(-8,12,-2,AIR:0)
B(-7,12,-2,AIR:0)
B(-6,12,-2,AIR:0)
B(-5,12,-2,AIR:0)
B(-4,12,-2,AIR:0)
B(-3,12,-2,AIR:0)
B(-2,12,-2,AIR:0)
B(-1,12,-2,AIR:0)
B(-8,12,-1,AIR:0)
B(-7,12,-1,AIR:0)
B(-6,12,-1,AIR:0)
B(-5,12,-1,AIR:0)
B(-4,12,-1,AIR:0)
B(-3,12,-1,AIR:0)
B(-2,12,-1,AIR:0)
B(-1,12,-1,AIR:0)
B(-8,13,-8,AIR:0)
B(-7,13,-8,AIR:0)
B(-6,13,-8,AIR:0)
B(-5,13,-8,AIR:0)
B(-4,13,-8,AIR:0)
B(-3,13,-8,AIR:0)
B(-2,13,-8,AIR:0)
B(-1,13,-8,AIR:0)
B(-8,13,-7,AIR:0)
B(-7,13,-7,AIR:0)
B(-6,13,-7,AIR:0)
B(-5,13,-7,AIR:0)
B(-4,13,-7,AIR:0)
B(-3,13,-7,AIR:0)
B(-2,13,-7,AIR:0)
B(-1,13,-7,AIR:0)
B(-8,13,-6,AIR:0)
B(-7,13,-6,AIR:0)
B(-6,13,-6,AIR:0)
B(-5,13,-6,AIR:0)
B(-4,13,-6,AIR:0)
B(-3,13,-6,AIR:0)
B(-2,13,-6,AIR:0)
B(-1,13,-6,AIR:0)
B(-8,13,-5,AIR:0)
B(-7,13,-5,AIR:0)
B(-6,13,-5,AIR:0)
B(-5,13,-5,AIR:0)
B(-4,13,-5,AIR:0)
B(-3,13,-5,AIR:0)
B(-2,13,-5,AIR:0)
B(-1,13,-5,AIR:0)
B(-8,13,-4,AIR:0)
B(-7,13,-4,AIR:0)
B(-6,13,-4,AIR:0)
B(-5,13,-4,AIR:0)
B(-4,13,-4,AIR:0)
B(-3,13,-4,AIR:0)
B(-2,13,-4,AIR:0)
B(-1,13,-4,AIR:0)
B(-8,13,-3,AIR:0)
B(-7,13,-3,AIR:0)
B(-6,13,-3,AIR:0)
B(-5,13,-3,AIR:0)
B(-4,13,-3,AIR:0)
B(-3,13,-3,AIR:0)
B(-2,13,-3,AIR:0)
B(-1,13,-3,AIR:0)
B(-8,13,-2,AIR:0)
B(-7,13,-2,AIR:0)
B(-6,13,-2,AIR:0)
B(-5,13,-2,AIR:0)
B(-4,13,-2,AIR:0)
B(-3,13,-2,AIR:0)
B(-2,13,-2,AIR:0)
B(-1,13,-2,AIR:0)
B(-8,13,-1,AIR:0)
B(-7,13,-1,AIR:0)
B(-6,13,-1,AIR:0)
B(-5,13,-1,AIR:0)
B(-4,13,-1,AIR:0)
B(-3,13,-1,AIR:0)
B(-2,13,-1,AIR:0)
B(-1,13,-1,AIR:0)
B(-8,14,-8,AIR:0)
B(-7,14,-8,AIR:0)
B(-6,14,-8,AIR:0)
B(-5,14,-8,AIR:0)
B(-4,14,-8,AIR:0)
B(-3,14,-8,AIR:0)
B(-2,14,-8,AIR:0)
B(-1,14,-8,AIR:0)
B(-8,14,-7,AIR:0)
B(-7,14,-7,AIR:0)
B(-6,14,-7,AIR:0)
B(-5,14,-7,AIR:0)
B(-4,14,-7,AIR:0)
B(-3,14,-7,AIR:0)
B(-2,14,-7,AIR:0)
B(-1,14,-7,AIR:0)
B(-8,14,-6,AIR:0)
B(-7,14,-6,AIR:0)
B(-6,14,-6,AIR:0)
B(-5,14,-6,AIR:0)
B(-4,14,-6,AIR:0)
B(-3,14,-6,AIR:0)
B(-2,14,-6,AIR:0)
B(-1,14,-6,AIR:0)
B(-8,14,-5,AIR:0)
B(-7,14,-5,AIR:0)
B(-6,14,-5,AIR:0)
B(-5,14,-5,AIR:0)
B(-4,14,-5,AIR:0)
B(-3,14,-5,AIR:0)
B(-2,14,-5,AIR:0)
B(-1,14,-5,AIR:0)
B(-8,14,-4,AIR:0)
B(-7,14,-4,AIR:0)
B(-6,14,-4,AIR:0)
B(-5,14,-4,AIR:0)
B(-4,14,-4,AIR:0)
B(-3,14,-4,AIR:0)
B(-2,14,-4,AIR:0)
B(-1,14,-4,AIR:0)
B(-8,14,-3,AIR:0)
B(-7,14,-3,AIR:0)
B(-6,14,-3,AIR:0)
B(-5,14,-3,AIR:0)
B(-4,14,-3,AIR:0)
B(-3,14,-3,AIR:0)
B(-2,14,-3,AIR:0)
B(-1,14,-3,AIR:0)
B(-8,14,-2,AIR:0)
B(-7,14,-2,AIR:0)
B(-6,14,-2,AIR:0)
B(-5,14,-2,AIR:0)
B(-4,14,-2,AIR:0)
B(-3,14,-2,AIR:0)
B(-2,14,-2,AIR:0)
B(-1,14,-2,AIR:0)
B(-8,14,-1,AIR:0)
B(-7,14,-1,AIR:0)
B(-6,14,-1,AIR:0)
B(-5,14,-1,AIR:0)
B(-4,14,-1,AIR:0)
B(-3,14,-1,AIR:0)
B(-2,14,-1,AIR:0)
B(-1,14,-1,AIR:0)
B(-8,15,-8,AIR:0)
B(-7,15,-8,AIR:0)
B(-6,15,-8,AIR:0)
B(-5,15,-8,AIR:0)
B(-4,15,-8,AIR:0)
B(-3,15,-8,AIR:0)
B(-2,15,-8,AIR:0)
B(-1,15,-8,AIR:0)
B(-8,15,-7,AIR:0)
B(-7,15,-7,AIR:0)
B(-6,15,-7,AIR:0)
B(-5,15,-7,AIR:0)
B(-4,15,-7,AIR:0)
B(-3,15,-7,AIR:0)
B(-2,15,-7,AIR:0)
B(-1,15,-7,AIR:0)
B(-8,15,-6,AIR:0)
B(-7,15,-6,AIR:0)
B(-6,15,-6,AIR:0)
B(-5,15,-6,AIR:0)
B(-4,15,-6,AIR:0)
B(-3,15,-6,AIR:0)
B(-2,15,-6,AIR:0)
B(-1,15,-6,AIR:0)
B(-8,15,-5,AIR:0)
B(-7,15,-5,AIR:0)
B(-6,15,-5,AIR:0)
B(-5,15,-5,AIR:0)
B(-4,15,-5,AIR:0)
B(-3,15,-5,AIR:0)
B(-2,15,-5,AIR:0)
B(-1,15,-5,AIR:0)
B(-8,15,-4,AIR:0)
B(-7,15,-4,AIR:0)
B(-6,15,-4,AIR:0)
B(-5,15,-4,AIR:0)
B(-4,15,-4,AIR:0)
B(-3,15,-4,AIR:0)
B(-2,15,-4,AIR:0)
B(-1,15,-4,AIR:0)
B(-8,15,-3,AIR:0)
B(-7,15,-3,AIR:0)
B(-6,15,-3,AIR:0)
B(-5,15,-3,AIR:0)
B(-4,15,-3,AIR:0)
B(-3,15,-3,AIR:0)
B(-2,15,-3,AIR:0)
B(-1,15,-3,AIR:0)
B(-8,15,-2,AIR:0)
B(-7,15,-2,AIR:0)
B(-6,15,-2,AIR:0)
B(-5,15,-2,AIR:0)
B(-4,15,-2,AIR:0)
B(-3,15,-2,AIR:0)
B(-2,15,-2,AIR:0)
B(-1,15,-2,AIR:0)
B(-8,15,-1,AIR:0)
B(-7,15,-1,AIR:0)
B(-6,15,-1,AIR:0)
B(-5,15,-1,AIR:0)
B(-4,15,-1,AIR:0)
B(-3,15,-1,AIR:0)
B(-2,15,-1,AIR:0)
B(-1,15,-1,AIR:0)
B(-8,16,-8,AIR:0)
B(-7,16,-8,AIR:0)
B(-6,16,-8,AIR:0)
B(-5,16,-8,AIR:0)
B(-4,16,-8,AIR:0)
B(-3,16,-8,AIR:0)
B(-2,16,-8,AIR:0)
B(-1,16,-8,AIR:0)
B(-8,16,-7,AIR:0)
B(-7,16,-7,AIR:0)
B(-6,16,-7,AIR:0)
B(-5,16,-7,AIR:0)
B(-4,16,-7,AIR:0)
B(-3,16,-7,AIR:0)
B(-2,16,-7,AIR:0)
B(-1,16,-7,AIR:0)
B(-8,16,-6,AIR:0)
B(-7,16,-6,AIR:0)
B(-6,16,-6,AIR:0)
B(-5,16,-6,AIR:0)
B(-4,16,-6,AIR:0)
B(-3,16,-6,AIR:0)
B(-2,16,-6,AIR:0)
B(-1,16,-6,AIR:0)
B(-8,16,-5,AIR:0)
B(-7,16,-5,AIR:0)
B(-6,16,-5,AIR:0)
B(-5,16,-5,AIR:0)
B(-4,16,-5,AIR:0)
B(-3,16,-5,AIR:0)
B(-2,16,-5,AIR:0)
B(-1,16,-5,AIR:0)
B(-8,16,-4,AIR:0)
B(-7,16,-4,AIR:0)
B(-6,16,-4,AIR:0)
B(-5,16,-4,AIR:0)
B(-4,16,-4,AIR:0)
B(-3,16,-4,AIR:0)
B(-2,16,-4,AIR:0)
B(-1,16,-4,AIR:0)
B(-8,16,-3,AIR:0)
B(-7,16,-3,AIR:0)
B(-6,16,-3,AIR:0)
B(-5,16,-3,AIR:0)
B(-4,16,-3,AIR:0)
B(-3,16,-3,AIR:0)
B(-2,16,-3,AIR:0)
B(-1,16,-3,AIR:0)
B(-8,16,-2,AIR:0)
B(-7,16,-2,AIR:0)
B(-6,16,-2,AIR:0)
B(-5,16,-2,AIR:0)
B(-4,16,-2,AIR:0)
B(-3,16,-2,AIR:0)
B(-2,16,-2,AIR:0)
B(-1,16,-2,AIR:0)
B(-8,16,-1,AIR:0)
B(-7,16,-1,AIR:0)
B(-6,16,-1,AIR:0)
B(-5,16,-1,AIR:0)
B(-4,16,-1,AIR:0)
B(-3,16,-1,AIR:0)
B(-2,16,-1,AIR:0)
B(-1,16,-1,AIR:0)
B(-8,17,-8,AIR:0)
B(-7,17,-8,MOSSY_COBBLESTONE:0)
B(-6,17,-8,AIR:0)
B(-5,17,-8,AIR:0)
B(-4,17,-8,AIR:0)
B(-3,17,-8,AIR:0)
B(-2,17,-8,AIR:0)
B(-1,17,-8,STONE:0)
B(-8,17,-7,AIR:0)
B(-7,17,-7,AIR:0)
B(-6,17,-7,AIR:0)
B(-5,17,-7,AIR:0)
B(-4,17,-7,AIR:0)
B(-3,17,-7,AIR:0)
B(-2,17,-7,AIR:0)
B(-1,17,-7,AIR:0)
B(-8,17,-6,AIR:0)
B(-7,17,-6,AIR:0)
B(-6,17,-6,AIR:0)
B(-5,17,-6,AIR:0)
B(-4,17,-6,AIR:0)
B(-3,17,-6,AIR:0)
B(-2,17,-6,AIR:0)
B(-1,17,-6,AIR:0)
B(-8,17,-5,AIR:0)
B(-7,17,-5,AIR:0)
B(-6,17,-5,AIR:0)
B(-5,17,-5,AIR:0)
B(-4,17,-5,AIR:0)
B(-3,17,-5,AIR:0)
B(-2,17,-5,AIR:0)
B(-1,17,-5,AIR:0)
B(-8,17,-4,AIR:0)
B(-7,17,-4,AIR:0)
B(-6,17,-4,AIR:0)
B(-5,17,-4,AIR:0)
B(-4,17,-4,AIR:0)
B(-3,17,-4,AIR:0)
B(-2,17,-4,AIR:0)
B(-1,17,-4,AIR:0)
B(-8,17,-3,AIR:0)
B(-7,17,-3,AIR:0)
B(-6,17,-3,AIR:0)
B(-5,17,-3,AIR:0)
B(-4,17,-3,AIR:0)
B(-3,17,-3,AIR:0)
B(-2,17,-3,AIR:0)
B(-1,17,-3,AIR:0)
B(-8,17,-2,AIR:0)
B(-7,17,-2,AIR:0)
B(-6,17,-2,AIR:0)
B(-5,17,-2,AIR:0)
B(-4,17,-2,AIR:0)
B(-3,17,-2,AIR:0)
B(-2,17,-2,AIR:0)
B(-1,17,-2,AIR:0)
B(-8,17,-1,AIR:0)
B(-7,17,-1,AIR:0)
B(-6,17,-1,AIR:0)
B(-5,17,-1,AIR:0)
B(-4,17,-1,AIR:0)
B(-3,17,-1,AIR:0)
B(-2,17,-1,AIR:0)
B(-1,17,-1,AIR:0)
B(-8,18,-8,STONE:0)
B(-7,18,-8,MOSSY_COBBLESTONE:0)
B(-6,18,-8,MOSSY_COBBLESTONE:0)
B(-5,18,-8,MOSSY_COBBLESTONE:0)
B(-4,18,-8,MOSSY_COBBLESTONE:0)
B(-3,18,-8,AIR:0)
B(-2,18,-8,STONE:0)
B(-1,18,-8,STONE:0)
B(-8,18,-7,AIR:0)
B(-7,18,-7,MOSSY_COBBLESTONE:0)
B(-6,18,-7,MOSSY_COBBLESTONE:0)
B(-5,18,-7,AIR:0)
B(-4,18,-7,AIR:0)
B(-3,18,-7,AIR:0)
B(-2,18,-7,COBBLESTONE:0)
B(-1,18,-7,COBBLESTONE:0)
B(-8,18,-6,AIR:0)
B(-7,18,-6,AIR:0)
B(-6,18,-6,AIR:0)
B(-5,18,-6,AIR:0)
B(-4,18,-6,AIR:0)
B(-3,18,-6,AIR:0)
B(-2,18,-6,AIR:0)
B(-1,18,-6,AIR:0)
B(-8,18,-5,AIR:0)
B(-7,18,-5,AIR:0)
B(-6,18,-5,AIR:0)
B(-5,18,-5,AIR:0)
B(-4,18,-5,AIR:0)
B(-3,18,-5,AIR:0)
B(-2,18,-5,AIR:0)
B(-1,18,-5,AIR:0)
B(-8,18,-4,AIR:0)
B(-7,18,-4,AIR:0)
B(-6,18,-4,AIR:0)
B(-5,18,-4,AIR:0)
B(-4,18,-4,AIR:0)
B(-3,18,-4,AIR:0)
B(-2,18,-4,AIR:0)
B(-1,18,-4,AIR:0)
B(-8,18,-3,AIR:0)
B(-7,18,-3,AIR:0)
B(-6,18,-3,AIR:0)
B(-5,18,-3,AIR:0)
B(-4,18,-3,AIR:0)
B(-3,18,-3,AIR:0)
B(-2,18,-3,AIR:0)
B(-1,18,-3,AIR:0)
B(-8,18,-2,AIR:0)
B(-7,18,-2,AIR:0)
B(-6,18,-2,AIR:0)
B(-5,18,-2,AIR:0)
B(-4,18,-2,AIR:0)
B(-3,18,-2,AIR:0)
B(-2,18,-2,AIR:0)
B(-1,18,-2,AIR:0)
B(-8,18,-1,AIR:0)
B(-7,18,-1,AIR:0)
B(-6,18,-1,AIR:0)
B(-5,18,-1,AIR:0)
B(-4,18,-1,AIR:0)
B(-3,18,-1,AIR:0)
B(-2,18,-1,AIR:0)
B(-1,18,-1,AIR:0)
B(-8,19,-8,MOSSY_COBBLESTONE:0)
B(-7,19,-8,MOSSY_COBBLESTONE:0)
B(-6,19,-8,MOSSY_COBBLESTONE:0)
B(-5,19,-8,MOSSY_COBBLESTONE:0)
B(-4,19,-8,MOSSY_COBBLESTONE:0)
B(-3,19,-8,MOSSY_COBBLESTONE:0)
B(-2,19,-8,STONE:0)
B(-1,19,-8,COBBLESTONE:0)
B(-8,19,-7,MOSSY_COBBLESTONE:0)
B(-7,19,-7,MOSSY_COBBLESTONE:0)
B(-6,19,-7,MOSSY_COBBLESTONE:0)
B(-5,19,-7,MOSSY_COBBLESTONE:0)
B(-4,19,-7,MOSSY_COBBLESTONE:0)
B(-3,19,-7,MOSSY_COBBLESTONE:0)
B(-2,19,-7,STONE:0)
B(-1,19,-7,STONE:0)
B(-8,19,-6,MOSSY_COBBLESTONE:0)
B(-7,19,-6,MOSSY_COBBLESTONE:0)
B(-6,19,-6,MOSSY_COBBLESTONE:0)
B(-5,19,-6,MOSSY_COBBLESTONE:0)
B(-4,19,-6,MOSSY_COBBLESTONE:0)
B(-3,19,-6,MOSSY_COBBLESTONE:0)
B(-2,19,-6,STONE:0)
B(-1,19,-6,STONE:0)
B(-8,19,-5,AIR:0)
B(-7,19,-5,MOSSY_COBBLESTONE:0)
B(-6,19,-5,MOSSY_COBBLESTONE:0)
B(-5,19,-5,MOSSY_COBBLESTONE:0)
B(-4,19,-5,MOSSY_COBBLESTONE:0)
B(-3,19,-5,MOSSY_COBBLESTONE:0)
B(-2,19,-5,STONE:0)
B(-1,19,-5,STONE:0)
B(-8,19,-4,AIR:0)
B(-7,19,-4,AIR:0)
B(-6,19,-4,AIR:0)
B(-5,19,-4,AIR:0)
B(-4,19,-4,AIR:0)
B(-3,19,-4,MOSSY_COBBLESTONE:0)
B(-2,19,-4,AIR:0)
B(-1,19,-4,AIR:0)
B(-8,19,-3,AIR:0)
B(-7,19,-3,AIR:0)
B(-6,19,-3,AIR:0)
B(-5,19,-3,AIR:0)
B(-4,19,-3,AIR:0)
B(-3,19,-3,AIR:0)
B(-2,19,-3,AIR:0)
B(-1,19,-3,AIR:0)
B(-8,19,-2,AIR:0)
B(-7,19,-2,AIR:0)
B(-6,19,-2,AIR:0)
B(-5,19,-2,AIR:0)
B(-4,19,-2,AIR:0)
B(-3,19,-2,AIR:0)
B(-2,19,-2,AIR:0)
B(-1,19,-2,AIR:0)
B(-8,19,-1,AIR:0)
B(-7,19,-1,AIR:0)
B(-6,19,-1,AIR:0)
B(-5,19,-1,AIR:0)
B(-4,19,-1,AIR:0)
B(-3,19,-1,AIR:0)
B(-2,19,-1,AIR:0)
B(-1,19,-1,AIR:0)
B(-8,20,-8,MOSSY_COBBLESTONE:0)
B(-7,20,-8,MOSSY_COBBLESTONE:0)
B(-6,20,-8,MOSSY_COBBLESTONE:0)
B(-5,20,-8,MOSSY_COBBLESTONE:0)
B(-4,20,-8,MOSSY_COBBLESTONE:0)
B(-3,20,-8,MOSSY_COBBLESTONE:0)
B(-2,20,-8,STONE:0)
B(-1,20,-8,STONE:0)
B(-8,20,-7,STONE:0)
B(-7,20,-7,MOSSY_COBBLESTONE:0)
B(-6,20,-7,MOSSY_COBBLESTONE:0)
B(-5,20,-7,MOSSY_COBBLESTONE:0)
B(-4,20,-7,MOSSY_COBBLESTONE:0)
B(-3,20,-7,MOSSY_COBBLESTONE:0)
B(-2,20,-7,MOSSY_COBBLESTONE:0)
B(-1,20,-7,STONE:0)
B(-8,20,-6,MOSSY_COBBLESTONE:0)
B(-7,20,-6,STONE:0)
B(-6,20,-6,MOSSY_COBBLESTONE:0)
B(-5,20,-6,MOSSY_COBBLESTONE:0)
B(-4,20,-6,MOSSY_COBBLESTONE:0)
B(-3,20,-6,MOSSY_COBBLESTONE:0)
B(-2,20,-6,MOSSY_COBBLESTONE:0)
B(-1,20,-6,STONE:0)
B(-8,20,-5,MOSSY_COBBLESTONE:0)
B(-7,20,-5,MOSSY_COBBLESTONE:0)
B(-6,20,-5,MOSSY_COBBLESTONE:0)
B(-5,20,-5,MOSSY_COBBLESTONE:0)
B(-4,20,-5,MOSSY_COBBLESTONE:0)
B(-3,20,-5,MOSSY_COBBLESTONE:0)
B(-2,20,-5,MOSSY_COBBLESTONE:0)
B(-1,20,-5,MOSSY_COBBLESTONE:0)
B(-8,20,-4,AIR:0)
B(-7,20,-4,MOSSY_COBBLESTONE:0)
B(-6,20,-4,MOSSY_COBBLESTONE:0)
B(-5,20,-4,MOSSY_COBBLESTONE:0)
B(-4,20,-4,MOSSY_COBBLESTONE:0)
B(-3,20,-4,MOSSY_COBBLESTONE:0)
B(-2,20,-4,AIR:0)
B(-1,20,-4,AIR:0)
B(-8,20,-3,AIR:0)
B(-7,20,-3,MOSSY_COBBLESTONE:0)
B(-6,20,-3,MOSSY_COBBLESTONE:0)
B(-5,20,-3,MOSSY_COBBLESTONE:0)
B(-4,20,-3,MOSSY_COBBLESTONE:0)
B(-3,20,-3,MOSSY_COBBLESTONE:0)
B(-2,20,-3,MOSSY_COBBLESTONE:0)
B(-1,20,-3,AIR:0)
B(-8,20,-2,AIR:0)
B(-7,20,-2,AIR:0)
B(-6,20,-2,AIR:0)
B(-5,20,-2,MOSSY_COBBLESTONE:0)
B(-4,20,-2,MOSSY_COBBLESTONE:0)
B(-3,20,-2,MOSSY_COBBLESTONE:0)
B(-2,20,-2,AIR:0)
B(-1,20,-2,AIR:0)
B(-8,20,-1,AIR:0)
B(-7,20,-1,AIR:0)
B(-6,20,-1,AIR:0)
B(-5,20,-1,AIR:0)
B(-4,20,-1,AIR:0)
B(-3,20,-1,AIR:0)
B(-2,20,-1,AIR:0)
B(-1,20,-1,MOSSY_COBBLESTONE:0)
B(-8,21,-8,MOSSY_COBBLESTONE:0)
B(-7,21,-8,MOSSY_COBBLESTONE:0)
B(-6,21,-8,MOSSY_COBBLESTONE:0)
B(-5,21,-8,MOSSY_COBBLESTONE:0)
B(-4,21,-8,MOSSY_COBBLESTONE:0)
B(-3,21,-8,MOSSY_COBBLESTONE:0)
B(-2,21,-8,MOSSY_COBBLESTONE:0)
B(-1,21,-8,MOSSY_COBBLESTONE:0)
B(-8,21,-7,MOSSY_COBBLESTONE:0)
B(-7,21,-7,MOSSY_COBBLESTONE:0)
B(-6,21,-7,MOSSY_COBBLESTONE:0)
B(-5,21,-7,MOSSY_COBBLESTONE:0)
B(-4,21,-7,MOSSY_COBBLESTONE:0)
B(-3,21,-7,MOSSY_COBBLESTONE:0)
B(-2,21,-7,MOSSY_COBBLESTONE:0)
B(-1,21,-7,MOSSY_COBBLESTONE:0)
B(-8,21,-6,MOSSY_COBBLESTONE:0)
B(-7,21,-6,MOSSY_COBBLESTONE:0)
B(-6,21,-6,MOSSY_COBBLESTONE:0)
B(-5,21,-6,MOSSY_COBBLESTONE:0)
B(-4,21,-6,MOSSY_COBBLESTONE:0)
B(-3,21,-6,MOSSY_COBBLESTONE:0)
B(-2,21,-6,MOSSY_COBBLESTONE:0)
B(-1,21,-6,MOSSY_COBBLESTONE:0)
B(-8,21,-5,MOSSY_COBBLESTONE:0)
B(-7,21,-5,STONE:0)
B(-6,21,-5,MOSSY_COBBLESTONE:0)
B(-5,21,-5,MOSSY_COBBLESTONE:0)
B(-4,21,-5,MOSSY_COBBLESTONE:0)
B(-3,21,-5,MOSSY_COBBLESTONE:0)
B(-2,21,-5,MOSSY_COBBLESTONE:0)
B(-1,21,-5,MOSSY_COBBLESTONE:0)
B(-8,21,-4,MOSSY_COBBLESTONE:0)
B(-7,21,-4,MOSSY_COBBLESTONE:0)
B(-6,21,-4,MOSSY_COBBLESTONE:0)
B(-5,21,-4,MOSSY_COBBLESTONE:0)
B(-4,21,-4,MOSSY_COBBLESTONE:0)
B(-3,21,-4,STONE:0)
B(-2,21,-4,MOSSY_COBBLESTONE:0)
B(-1,21,-4,STONE:0)
B(-8,21,-3,COBBLESTONE:0)
B(-7,21,-3,STONE:0)
B(-6,21,-3,MOSSY_COBBLESTONE:0)
B(-5,21,-3,MOSSY_COBBLESTONE:0)
B(-4,21,-3,STONE:0)
B(-3,21,-3,MOSSY_COBBLESTONE:0)
B(-2,21,-3,MOSSY_COBBLESTONE:0)
B(-1,21,-3,MOSSY_COBBLESTONE:0)
B(-8,21,-2,STONE:0)
B(-7,21,-2,MOSSY_COBBLESTONE:0)
B(-6,21,-2,STONE:0)
B(-5,21,-2,MOSSY_COBBLESTONE:0)
B(-4,21,-2,MOSSY_COBBLESTONE:0)
B(-3,21,-2,STONE:0)
B(-2,21,-2,STONE:0)
B(-1,21,-2,MOSSY_COBBLESTONE:0)
B(-8,21,-1,COBBLESTONE:0)
B(-7,21,-1,MOSSY_COBBLESTONE:0)
B(-6,21,-1,MOSSY_COBBLESTONE:0)
B(-5,21,-1,STONE:0)
B(-4,21,-1,STONE:0)
B(-3,21,-1,STONE:0)
B(-2,21,-1,MOSSY_COBBLESTONE:0)
B(-1,21,-1,STONE:0)
B(-8,22,-8,MOSSY_COBBLESTONE:0)
B(-7,22,-8,MOSSY_COBBLESTONE:0)
B(-6,22,-8,MOSSY_COBBLESTONE:0)
B(-5,22,-8,MOSSY_COBBLESTONE:0)
B(-4,22,-8,MOSSY_COBBLESTONE:0)
B(-3,22,-8,MOSSY_COBBLESTONE:0)
B(-2,22,-8,MOSSY_COBBLESTONE:0)
B(-1,22,-8,MOSSY_COBBLESTONE:0)
B(-8,22,-7,MOSSY_COBBLESTONE:0)
B(-7,22,-7,MOSSY_COBBLESTONE:0)
B(-6,22,-7,MOSSY_COBBLESTONE:0)
B(-5,22,-7,STONE:0)
B(-4,22,-7,MOSSY_COBBLESTONE:0)
B(-3,22,-7,MOSSY_COBBLESTONE:0)
B(-2,22,-7,MOSSY_COBBLESTONE:0)
B(-1,22,-7,MOSSY_COBBLESTONE:0)
B(-8,22,-6,MOSSY_COBBLESTONE:0)
B(-7,22,-6,MOSSY_COBBLESTONE:0)
B(-6,22,-6,MOSSY_COBBLESTONE:0)
B(-5,22,-6,MOSSY_COBBLESTONE:0)
B(-4,22,-6,MOSSY_COBBLESTONE:0)
B(-3,22,-6,MOSSY_COBBLESTONE:0)
B(-2,22,-6,MOSSY_COBBLESTONE:0)
B(-1,22,-6,MOSSY_COBBLESTONE:0)
B(-8,22,-5,MOSSY_COBBLESTONE:0)
B(-7,22,-5,MOSSY_COBBLESTONE:0)
B(-6,22,-5,MOSSY_COBBLESTONE:0)
B(-5,22,-5,MOSSY_COBBLESTONE:0)
B(-4,22,-5,MOSSY_COBBLESTONE:0)
B(-3,22,-5,MOSSY_COBBLESTONE:0)
B(-2,22,-5,MOSSY_COBBLESTONE:0)
B(-1,22,-5,MOSSY_COBBLESTONE:0)
B(-8,22,-4,COBBLESTONE:0)
B(-7,22,-4,MOSSY_COBBLESTONE:0)
B(-6,22,-4,MOSSY_COBBLESTONE:0)
B(-5,22,-4,MOSSY_COBBLESTONE:0)
B(-4,22,-4,MOSSY_COBBLESTONE:0)
B(-3,22,-4,MOSSY_COBBLESTONE:0)
B(-2,22,-4,MOSSY_COBBLESTONE:0)
B(-1,22,-4,STONE:0)
B(-8,22,-3,COBBLESTONE:0)
B(-7,22,-3,MOSSY_COBBLESTONE:0)
B(-6,22,-3,MOSSY_COBBLESTONE:0)
B(-5,22,-3,MOSSY_COBBLESTONE:0)
B(-4,22,-3,MOSSY_COBBLESTONE:0)
B(-3,22,-3,MOSSY_COBBLESTONE:0)
B(-2,22,-3,MOSSY_COBBLESTONE:0)
B(-1,22,-3,MOSSY_COBBLESTONE:0)
B(-8,22,-2,COBBLESTONE:0)
B(-7,22,-2,MOSSY_COBBLESTONE:0)
B(-6,22,-2,MOSSY_COBBLESTONE:0)
B(-5,22,-2,MOSSY_COBBLESTONE:0)
B(-4,22,-2,STONE:0)
B(-3,22,-2,MOSSY_COBBLESTONE:0)
B(-2,22,-2,STONE:0)
B(-1,22,-2,MOSSY_COBBLESTONE:0)
B(-8,22,-1,STONE:0)
B(-7,22,-1,MOSSY_COBBLESTONE:0)
B(-6,22,-1,STONE:0)
B(-5,22,-1,MOSSY_COBBLESTONE:0)
B(-4,22,-1,MOSSY_COBBLESTONE:0)
B(-3,22,-1,STONE:0)
B(-2,22,-1,MOSSY_COBBLESTONE:0)
B(-1,22,-1,STONE:0)
B(-8,23,-8,MOSSY_COBBLESTONE:0)
B(-7,23,-8,STONE:0)
B(-6,23,-8,MOSSY_COBBLESTONE:0)
B(-5,23,-8,MOSSY_COBBLESTONE:0)
B(-4,23,-8,MOSSY_COBBLESTONE:0)
B(-3,23,-8,MOSSY_COBBLESTONE:0)
B(-2,23,-8,MOSSY_COBBLESTONE:0)
B(-1,23,-8,MOSSY_COBBLESTONE:0)
B(-8,23,-7,MOSSY_COBBLESTONE:0)
B(-7,23,-7,MOSSY_COBBLESTONE:0)
B(-6,23,-7,MOSSY_COBBLESTONE:0)
B(-5,23,-7,MOSSY_COBBLESTONE:0)
B(-4,23,-7,MOSSY_COBBLESTONE:0)
B(-3,23,-7,STONE:0)
B(-2,23,-7,MOSSY_COBBLESTONE:0)
B(-1,23,-7,MOSSY_COBBLESTONE:0)
B(-8,23,-6,MOSSY_COBBLESTONE:0)
B(-7,23,-6,MOSSY_COBBLESTONE:0)
B(-6,23,-6,MOSSY_COBBLESTONE:0)
B(-5,23,-6,MOSSY_COBBLESTONE:0)
B(-4,23,-6,MOSSY_COBBLESTONE:0)
B(-3,23,-6,MOSSY_COBBLESTONE:0)
B(-2,23,-6,MOSSY_COBBLESTONE:0)
B(-1,23,-6,MOSSY_COBBLESTONE:0)
B(-8,23,-5,MOSSY_COBBLESTONE:0)
B(-7,23,-5,MOSSY_COBBLESTONE:0)
B(-6,23,-5,MOSSY_COBBLESTONE:0)
B(-5,23,-5,MOSSY_COBBLESTONE:0)
B(-4,23,-5,MOSSY_COBBLESTONE:0)
B(-3,23,-5,STONE:0)
B(-2,23,-5,MOSSY_COBBLESTONE:0)
B(-1,23,-5,MOSSY_COBBLESTONE:0)
B(-8,23,-4,STONE:0)
B(-7,23,-4,MOSSY_COBBLESTONE:0)
B(-6,23,-4,MOSSY_COBBLESTONE:0)
B(-5,23,-4,MOSSY_COBBLESTONE:0)
B(-4,23,-4,STONE:0)
B(-3,23,-4,STONE:0)
B(-2,23,-4,MOSSY_COBBLESTONE:0)
B(-1,23,-4,MOSSY_COBBLESTONE:0)
B(-8,23,-3,STONE:0)
B(-7,23,-3,MOSSY_COBBLESTONE:0)
B(-6,23,-3,STONE:0)
B(-5,23,-3,MOSSY_COBBLESTONE:0)
B(-4,23,-3,MOSSY_COBBLESTONE:0)
B(-3,23,-3,STONE:0)
B(-2,23,-3,MOSSY_COBBLESTONE:0)
B(-1,23,-3,MOSSY_COBBLESTONE:0)
B(-8,23,-2,STONE:0)
B(-7,23,-2,STONE:0)
B(-6,23,-2,STONE:0)
B(-5,23,-2,MOSSY_COBBLESTONE:0)
B(-4,23,-2,STONE:0)
B(-3,23,-2,MOSSY_COBBLESTONE:0)
B(-2,23,-2,MOSSY_COBBLESTONE:0)
B(-1,23,-2,STONE:0)
B(-8,23,-1,STONE:0)
B(-7,23,-1,STONE:0)
B(-6,23,-1,STONE:0)
B(-5,23,-1,STONE:0)
B(-4,23,-1,STONE:0)
B(-3,23,-1,STONE:0)
B(-2,23,-1,STONE:0)
B(-1,23,-1,STONE:0)
B(-8,24,-8,MOSSY_COBBLESTONE:0)
B(-7,24,-8,MOSSY_COBBLESTONE:0)
B(-6,24,-8,STONE:0)
B(-5,24,-8,STONE:0)
B(-4,24,-8,STONE:0)
B(-3,24,-8,STONE:0)
B(-2,24,-8,MOSSY_COBBLESTONE:0)
B(-1,24,-8,MOSSY_COBBLESTONE:0)
B(-8,24,-7,STONE:0)
B(-7,24,-7,STONE:0)
B(-6,24,-7,STONE:0)
B(-5,24,-7,STONE:0)
B(-4,24,-7,MOSSY_COBBLESTONE:0)
B(-3,24,-7,MOSSY_COBBLESTONE:0)
B(-2,24,-7,STONE:0)
B(-1,24,-7,STONE:0)
B(-8,24,-6,MOSSY_COBBLESTONE:0)
B(-7,24,-6,MOSSY_COBBLESTONE:0)
B(-6,24,-6,MOSSY_COBBLESTONE:0)
B(-5,24,-6,MOSSY_COBBLESTONE:0)
B(-4,24,-6,MOSSY_COBBLESTONE:0)
B(-3,24,-6,STONE:0)
B(-2,24,-6,MOSSY_COBBLESTONE:0)
B(-1,24,-6,MOSSY_COBBLESTONE:0)
B(-8,24,-5,MOSSY_COBBLESTONE:0)
B(-7,24,-5,MOSSY_COBBLESTONE:0)
B(-6,24,-5,STONE:0)
B(-5,24,-5,MOSSY_COBBLESTONE:0)
B(-4,24,-5,STONE:0)
B(-3,24,-5,MOSSY_COBBLESTONE:0)
B(-2,24,-5,MOSSY_COBBLESTONE:0)
B(-1,24,-5,STONE:0)
B(-8,24,-4,STONE:0)
B(-7,24,-4,STONE:0)
B(-6,24,-4,STONE:0)
B(-5,24,-4,MOSSY_COBBLESTONE:0)
B(-4,24,-4,MOSSY_COBBLESTONE:0)
B(-3,24,-4,MOSSY_COBBLESTONE:0)
B(-2,24,-4,MOSSY_COBBLESTONE:0)
B(-1,24,-4,MOSSY_COBBLESTONE:0)
B(-8,24,-3,COBBLESTONE:0)
B(-7,24,-3,MOSSY_COBBLESTONE:0)
B(-6,24,-3,MOSSY_COBBLESTONE:0)
B(-5,24,-3,MOSSY_COBBLESTONE:0)
B(-4,24,-3,MOSSY_COBBLESTONE:0)
B(-3,24,-3,STONE:0)
B(-2,24,-3,STONE:0)
B(-1,24,-3,STONE:0)
B(-8,24,-2,COBBLESTONE:0)
B(-7,24,-2,STONE:0)
B(-6,24,-2,STONE:0)
B(-5,24,-2,STONE:0)
B(-4,24,-2,STONE:0)
B(-3,24,-2,STONE:0)
B(-2,24,-2,STONE:0)
B(-1,24,-2,STONE:0)
B(-8,24,-1,STONE:0)
B(-7,24,-1,STONE:0)
B(-6,24,-1,STONE:0)
B(-5,24,-1,STONE:0)
B(-4,24,-1,STONE:0)
B(-3,24,-1,STONE:0)
B(-2,24,-1,STONE:0)
B(-1,24,-1,STONE:0)
B(-8,25,-8,MOSSY_COBBLESTONE:0)
B(-7,25,-8,STONE:0)
B(-6,25,-8,STONE:0)
B(-5,25,-8,STONE:0)
B(-4,25,-8,STONE:0)
B(-3,25,-8,STONE:0)
B(-2,25,-8,STONE:0)
B(-1,25,-8,STONE:0)
B(-8,25,-7,STONE:0)
B(-7,25,-7,STONE:0)
B(-6,25,-7,STONE:0)
B(-5,25,-7,STONE:0)
B(-4,25,-7,STONE:0)
B(-3,25,-7,STONE:0)
B(-2,25,-7,STONE:0)
B(-1,25,-7,STONE:0)
B(-8,25,-6,STONE:0)
B(-7,25,-6,STONE:0)
B(-6,25,-6,STONE:0)
B(-5,25,-6,STONE:0)
B(-4,25,-6,STONE:0)
B(-3,25,-6,STONE:0)
B(-2,25,-6,STONE:0)
B(-1,25,-6,STONE:0)
B(-8,25,-5,MOSSY_COBBLESTONE:0)
B(-7,25,-5,STONE:0)
B(-6,25,-5,MOSSY_COBBLESTONE:0)
B(-5,25,-5,STONE:0)
B(-4,25,-5,STONE:0)
B(-3,25,-5,STONE:0)
B(-2,25,-5,STONE:0)
B(-1,25,-5,STONE:0)
B(-8,25,-4,STONE:0)
B(-7,25,-4,MOSSY_COBBLESTONE:0)
B(-6,25,-4,MOSSY_COBBLESTONE:0)
B(-5,25,-4,STONE:0)
B(-4,25,-4,STONE:0)
B(-3,25,-4,STONE:0)
B(-2,25,-4,STONE:0)
B(-1,25,-4,STONE:0)
B(-8,25,-3,STONE:0)
B(-7,25,-3,STONE:0)
B(-6,25,-3,STONE:0)
B(-5,25,-3,STONE:0)
B(-4,25,-3,STONE:0)
B(-3,25,-3,STONE:0)
B(-2,25,-3,STONE:0)
B(-1,25,-3,STONE:0)
B(-8,25,-2,COBBLESTONE:0)
B(-7,25,-2,MOSSY_COBBLESTONE:0)
B(-6,25,-2,MOSSY_COBBLESTONE:0)
B(-5,25,-2,STONE:0)
B(-4,25,-2,STONE:0)
B(-3,25,-2,STONE:0)
B(-2,25,-2,STONE:0)
B(-1,25,-2,STONE:0)
B(-8,25,-1,STONE:0)
B(-7,25,-1,STONE:0)
B(-6,25,-1,STONE:0)
B(-5,25,-1,STONE:0)
B(-4,25,-1,STONE:0)
B(-3,25,-1,STONE:0)
B(-2,25,-1,STONE:0)
B(-1,25,-1,STONE:0)
B(-8,26,-8,STONE:0)
B(-7,26,-8,STONE:0)
B(-6,26,-8,STONE:0)
B(-5,26,-8,STONE:0)
B(-4,26,-8,STONE:0)
B(-3,26,-8,STONE:0)
B(-2,26,-8,STONE:0)
B(-1,26,-8,STONE:0)
B(-8,26,-7,STONE:0)
B(-7,26,-7,STONE:0)
B(-6,26,-7,STONE:0)
B(-5,26,-7,STONE:0)
B(-4,26,-7,STONE:0)
B(-3,26,-7,STONE:0)
B(-2,26,-7,STONE:0)
B(-1,26,-7,STONE:0)
B(-8,26,-6,STONE:0)
B(-7,26,-6,STONE:0)
B(-6,26,-6,STONE:0)
B(-5,26,-6,STONE:0)
B(-4,26,-6,STONE:0)
B(-3,26,-6,STONE:0)
B(-2,26,-6,STONE:0)
B(-1,26,-6,STONE:0)
B(-8,26,-5,MOSSY_COBBLESTONE:0)
B(-7,26,-5,STONE:0)
B(-6,26,-5,STONE:0)
B(-5,26,-5,STONE:0)
B(-4,26,-5,STONE:0)
B(-3,26,-5,STONE:0)
B(-2,26,-5,STONE:0)
B(-1,26,-5,STONE:0)
B(-8,26,-4,STONE:0)
B(-7,26,-4,STONE:0)
B(-6,26,-4,STONE:0)
B(-5,26,-4,STONE:0)
B(-4,26,-4,STONE:0)
B(-3,26,-4,STONE:0)
B(-2,26,-4,STONE:0)
B(-1,26,-4,STONE:0)
B(-8,26,-3,STONE:0)
B(-7,26,-3,STONE:0)
B(-6,26,-3,STONE:0)
B(-5,26,-3,STONE:0)
B(-4,26,-3,STONE:0)
B(-3,26,-3,STONE:0)
B(-2,26,-3,STONE:0)
B(-1,26,-3,STONE:0)
B(-8,26,-2,STONE:0)
B(-7,26,-2,MOSSY_COBBLESTONE:0)
B(-6,26,-2,STONE:0)
B(-5,26,-2,STONE:0)
B(-4,26,-2,STONE:0)
B(-3,26,-2,STONE:0)
B(-2,26,-2,STONE:0)
B(-1,26,-2,STONE:0)
B(-8,26,-1,STONE:0)
B(-7,26,-1,STONE:0)
B(-6,26,-1,STONE:0)
B(-5,26,-1,STONE:0)
B(-4,26,-1,STONE:0)
B(-3,26,-1,STONE:0)
B(-2,26,-1,STONE:0)
B(-1,26,-1,STONE:0)
B(-8,27,-8,STONE:0)
B(-7,27,-8,STONE:0)
B(-6,27,-8,STONE:0)
B(-5,27,-8,STONE:0)
B(-4,27,-8,STONE:0)
B(-3,27,-8,STONE:0)
B(-2,27,-8,STONE:0)
B(-1,27,-8,STONE:0)
B(-8,27,-7,STONE:0)
B(-7,27,-7,STONE:0)
B(-6,27,-7,STONE:0)
B(-5,27,-7,STONE:0)
B(-4,27,-7,STONE:0)
B(-3,27,-7,STONE:0)
B(-2,27,-7,STONE:0)
B(-1,27,-7,STONE:0)
B(-8,27,-6,STONE:0)
B(-7,27,-6,STONE:0)
B(-6,27,-6,STONE:0)
B(-5,27,-6,STONE:0)
B(-4,27,-6,STONE:0)
B(-3,27,-6,STONE:0)
B(-2,27,-6,STONE:0)
B(-1,27,-6,STONE:0)
B(-8,27,-5,MOSSY_COBBLESTONE:0)
B(-7,27,-5,STONE:0)
B(-6,27,-5,STONE:0)
B(-5,27,-5,STONE:0)
B(-4,27,-5,STONE:0)
B(-3,27,-5,STONE:0)
B(-2,27,-5,STONE:0)
B(-1,27,-5,STONE:0)
B(-8,27,-4,MOSSY_COBBLESTONE:0)
B(-7,27,-4,STONE:0)
B(-6,27,-4,STONE:0)
B(-5,27,-4,STONE:0)
B(-4,27,-4,STONE:0)
B(-3,27,-4,STONE:0)
B(-2,27,-4,STONE:0)
B(-1,27,-4,STONE:0)
B(-8,27,-3,STONE:0)
B(-7,27,-3,STONE:0)
B(-6,27,-3,STONE:0)
B(-5,27,-3,STONE:0)
B(-4,27,-3,STONE:0)
B(-3,27,-3,STONE:0)
B(-2,27,-3,STONE:0)
B(-1,27,-3,STONE:0)
B(-8,27,-2,STONE:0)
B(-7,27,-2,STONE:0)
B(-6,27,-2,STONE:0)
B(-5,27,-2,STONE:0)
B(-4,27,-2,STONE:0)
B(-3,27,-2,STONE:0)
B(-2,27,-2,STONE:0)
B(-1,27,-2,STONE:0)
B(-8,27,-1,STONE:0)
B(-7,27,-1,STONE:0)
B(-6,27,-1,STONE:0)
B(-5,27,-1,STONE:0)
B(-4,27,-1,STONE:0)
B(-3,27,-1,STONE:0)
B(-2,27,-1,STONE:0)
B(-1,27,-1,STONE:0)
B(-8,28,-8,STONE:0)
B(-7,28,-8,STONE:0)
B(-6,28,-8,STONE:0)
B(-5,28,-8,STONE:0)
B(-4,28,-8,STONE:0)
B(-3,28,-8,STONE:0)
B(-2,28,-8,STONE:0)
B(-1,28,-8,STONE:0)
B(-8,28,-7,STONE:0)
B(-7,28,-7,STONE:0)
B(-6,28,-7,STONE:0)
B(-5,28,-7,STONE:0)
B(-4,28,-7,STONE:0)
B(-3,28,-7,STONE:0)
B(-2,28,-7,STONE:0)
B(-1,28,-7,STONE:0)
B(-8,28,-6,STONE:0)
B(-7,28,-6,STONE:0)
B(-6,28,-6,STONE:0)
B(-5,28,-6,STONE:0)
B(-4,28,-6,STONE:0)
B(-3,28,-6,STONE:0)
B(-2,28,-6,STONE:0)
B(-1,28,-6,STONE:0)
B(-8,28,-5,STONE:0)
B(-7,28,-5,STONE:0)
B(-6,28,-5,STONE:0)
B(-5,28,-5,STONE:0)
B(-4,28,-5,STONE:0)
B(-3,28,-5,STONE:0)
B(-2,28,-5,STONE:0)
B(-1,28,-5,STONE:0)
B(-8,28,-4,STONE:0)
B(-7,28,-4,STONE:0)
B(-6,28,-4,STONE:0)
B(-5,28,-4,STONE:0)
B(-4,28,-4,STONE:0)
B(-3,28,-4,STONE:0)
B(-2,28,-4,STONE:0)
B(-1,28,-4,STONE:0)
B(-8,28,-3,STONE:0)
B(-7,28,-3,STONE:0)
B(-6,28,-3,STONE:0)
B(-5,28,-3,STONE:0)
B(-4,28,-3,STONE:0)
B(-3,28,-3,STONE:0)
B(-2,28,-3,STONE:0)
B(-1,28,-3,STONE:0)
B(-8,28,-2,STONE:0)
B(-7,28,-2,STONE:0)
B(-6,28,-2,STONE:0)
B(-5,28,-2,STONE:0)
B(-4,28,-2,STONE:0)
B(-3,28,-2,STONE:0)
B(-2,28,-2,STONE:0)
B(-1,28,-2,STONE:0)
B(-8,28,-1,STONE:0)
B(-7,28,-1,STONE:0)
B(-6,28,-1,STONE:0)
B(-5,28,-1,STONE:0)
B(-4,28,-1,STONE:0)
B(-3,28,-1,STONE:0)
B(-2,28,-1,STONE:0)
B(-1,28,-1,STONE:0)
B(-8,29,-8,MOSSY_COBBLESTONE:0)
B(-7,29,-8,MOSSY_COBBLESTONE:0)
B(-6,29,-8,MOSSY_COBBLESTONE:0)
B(-5,29,-8,STONE:0)
B(-4,29,-8,MOSSY_COBBLESTONE:0)
B(-3,29,-8,MOSSY_COBBLESTONE:0)
B(-2,29,-8,STONE:0)
B(-1,29,-8,STONE:0)
B(-8,29,-7,MOSSY_COBBLESTONE:0)
B(-7,29,-7,STONE:0)
B(-6,29,-7,STONE:0)
B(-5,29,-7,STONE:0)
B(-4,29,-7,MOSSY_COBBLESTONE:0)
B(-3,29,-7,STONE:0)
B(-2,29,-7,MOSSY_COBBLESTONE:0)
B(-1,29,-7,MOSSY_COBBLESTONE:0)
B(-8,29,-6,MOSSY_COBBLESTONE:0)
B(-7,29,-6,MOSSY_COBBLESTONE:0)
B(-6,29,-6,MOSSY_COBBLESTONE:0)
B(-5,29,-6,STONE:0)
B(-4,29,-6,STONE:0)
B(-3,29,-6,MOSSY_COBBLESTONE:0)
B(-2,29,-6,STONE:0)
B(-1,29,-6,MOSSY_COBBLESTONE:0)
B(-8,29,-5,MOSSY_COBBLESTONE:0)
B(-7,29,-5,STONE:0)
B(-6,29,-5,MOSSY_COBBLESTONE:0)
B(-5,29,-5,STONE:0)
B(-4,29,-5,MOSSY_COBBLESTONE:0)
B(-3,29,-5,MOSSY_COBBLESTONE:0)
B(-2,29,-5,MOSSY_COBBLESTONE:0)
B(-1,29,-5,STONE:0)
B(-8,29,-4,STONE:0)
B(-7,29,-4,STONE:0)
B(-6,29,-4,MOSSY_COBBLESTONE:0)
B(-5,29,-4,STONE:0)
B(-4,29,-4,MOSSY_COBBLESTONE:0)
B(-3,29,-4,MOSSY_COBBLESTONE:0)
B(-2,29,-4,STONE:0)
B(-1,29,-4,MOSSY_COBBLESTONE:0)
B(-8,29,-3,MOSSY_COBBLESTONE:0)
B(-7,29,-3,STONE:0)
B(-6,29,-3,STONE:0)
B(-5,29,-3,MOSSY_COBBLESTONE:0)
B(-4,29,-3,STONE:0)
B(-3,29,-3,STONE:0)
B(-2,29,-3,MOSSY_COBBLESTONE:0)
B(-1,29,-3,STONE:0)
B(-8,29,-2,MOSSY_COBBLESTONE:0)
B(-7,29,-2,STONE:0)
B(-6,29,-2,STONE:0)
B(-5,29,-2,STONE:0)
B(-4,29,-2,MOSSY_COBBLESTONE:0)
B(-3,29,-2,STONE:0)
B(-2,29,-2,MOSSY_COBBLESTONE:0)
B(-1,29,-2,STONE:0)
B(-8,29,-1,MOSSY_COBBLESTONE:0)
B(-7,29,-1,MOSSY_COBBLESTONE:0)
B(-6,29,-1,MOSSY_COBBLESTONE:0)
B(-5,29,-1,STONE:0)
B(-4,29,-1,MOSSY_COBBLESTONE:0)
B(-3,29,-1,MOSSY_COBBLESTONE:0)
B(-2,29,-1,MOSSY_COBBLESTONE:0)
B(-1,29,-1,STONE:0)

BR(8,0,0,BigMushCave_8x5,NORTH,100)
