
#######################################################################
# +-----------------------------------------------------------------+ #
# |                            BO3 object                           | #
# +-----------------------------------------------------------------+ #
#######################################################################

Author: NLBlackEagle

Description: No description given

Version: 3

SettingsMode: WriteWithoutComments


#######################################################################
# +-----------------------------------------------------------------+ #
# |                          Main settings                          | #
# +-----------------------------------------------------------------+ #
#######################################################################

Tree: false

Frequency: 1

Rarity: 100.0

RotateRandomly: false

SpawnHeight: randomY

SpawnHeightOffset: 0

SpawnHeightVariance: 0

##############################
# Height Limits for the BO3. #
##############################

MinHeight: 0

MaxHeight: 255

######################
# Extrusion settings #
######################

ExtrudeMode: None

ExtrudeThroughBlocks: otg:air

MaxBranchDepth: 10


#######################################################################
# +-----------------------------------------------------------------+ #
# |                      Source block settings                      | #
# +-----------------------------------------------------------------+ #
#######################################################################

SourceBlocks: otg:air

MaxPercentageOutsideSourceBlock: 100

OutsideSourceBlock: placeAnyway

DoReplaceBlocks: true

IsOTGPlus: false


#######################################################################
# +-----------------------------------------------------------------+ #
# |                              Blocks                             | #
# +-----------------------------------------------------------------+ #
#######################################################################

B(-6,0,-2,minecraft:spruce_fence[east=true,north=false,south=true,waterlogged=false,west=false])
B(-6,1,-2,minecraft:spruce_fence[east=true,north=false,south=true,waterlogged=false,west=false])
B(-6,2,-2,minecraft:spruce_fence[east=true,north=false,south=true,waterlogged=false,west=false])
B(-6,0,-1,minecraft:spruce_fence[east=false,north=true,south=true,waterlogged=false,west=false])
B(-6,1,-1,minecraft:spruce_fence[east=false,north=true,south=true,waterlogged=false,west=false])
B(-6,2,-1,minecraft:spruce_fence[east=false,north=true,south=true,waterlogged=false,west=false])
B(-6,0,0,minecraft:spruce_fence[east=false,north=true,south=true,waterlogged=false,west=false])
B(-6,1,0,minecraft:spruce_fence[east=false,north=true,south=true,waterlogged=false,west=false])
B(-6,2,0,minecraft:spruce_fence[east=false,north=true,south=true,waterlogged=false,west=false])
B(-6,0,1,minecraft:spruce_fence[east=true,north=true,south=false,waterlogged=false,west=false])
B(-6,1,1,minecraft:spruce_fence[east=true,north=true,south=false,waterlogged=false,west=false])
B(-6,2,1,minecraft:spruce_fence[east=true,north=true,south=false,waterlogged=false,west=false])
B(-5,0,-4,minecraft:spruce_fence[east=true,north=false,south=true,waterlogged=false,west=false])
B(-5,1,-4,minecraft:spruce_fence[east=true,north=false,south=true,waterlogged=false,west=false])
B(-5,2,-4,minecraft:spruce_fence[east=true,north=false,south=true,waterlogged=false,west=false])
B(-5,0,-3,minecraft:spruce_fence[east=false,north=true,south=true,waterlogged=false,west=false])
B(-5,1,-3,minecraft:spruce_fence[east=false,north=true,south=true,waterlogged=false,west=false])
B(-5,2,-3,minecraft:spruce_fence[east=false,north=true,south=true,waterlogged=false,west=false])
B(-5,0,-2,minecraft:spruce_fence[east=true,north=true,south=false,waterlogged=false,west=true])
B(-5,1,-2,minecraft:spruce_fence[east=true,north=true,south=false,waterlogged=false,west=true])
B(-5,2,-2,minecraft:spruce_fence[east=true,north=true,south=false,waterlogged=false,west=true])
B(-5,0,-1,minecraft:ladder[facing=west,waterlogged=false])
B(-5,1,-1,minecraft:ladder[facing=west,waterlogged=false])
B(-5,2,-1,minecraft:ladder[facing=west,waterlogged=false])
B(-5,0,0,minecraft:ladder[facing=west,waterlogged=false])
B(-5,1,0,minecraft:ladder[facing=west,waterlogged=false])
B(-5,2,0,minecraft:ladder[facing=west,waterlogged=false])
B(-5,0,1,minecraft:spruce_fence[east=true,north=false,south=true,waterlogged=false,west=true])
B(-5,1,1,minecraft:spruce_fence[east=true,north=false,south=true,waterlogged=false,west=true])
B(-5,2,1,minecraft:spruce_fence[east=true,north=false,south=true,waterlogged=false,west=true])
B(-5,0,2,minecraft:spruce_fence[east=false,north=true,south=true,waterlogged=false,west=false])
B(-5,1,2,minecraft:spruce_fence[east=false,north=true,south=true,waterlogged=false,west=false])
B(-5,2,2,minecraft:spruce_fence[east=false,north=true,south=true,waterlogged=false,west=false])
B(-5,0,3,minecraft:spruce_fence[east=true,north=true,south=false,waterlogged=false,west=false])
B(-5,1,3,minecraft:spruce_fence[east=true,north=true,south=false,waterlogged=false,west=false])
B(-5,2,3,minecraft:spruce_fence[east=true,north=true,south=false,waterlogged=false,west=false])
B(-4,0,-4,minecraft:spruce_fence[east=true,north=false,south=false,waterlogged=false,west=true])
B(-4,1,-4,minecraft:spruce_fence[east=true,north=false,south=false,waterlogged=false,west=true])
B(-4,2,-4,minecraft:spruce_fence[east=true,north=false,south=false,waterlogged=false,west=true])
B(-4,0,-2,minecraft:spruce_planks)
B(-4,1,-2,minecraft:spruce_planks)
B(-4,2,-2,minecraft:spruce_planks)
B(-4,2,-1,minecraft:spruce_planks)
B(-4,2,0,minecraft:spruce_planks)
B(-4,0,1,minecraft:spruce_planks)
B(-4,1,1,minecraft:spruce_planks)
B(-4,2,1,minecraft:spruce_planks)
B(-4,0,3,minecraft:spruce_fence[east=true,north=false,south=false,waterlogged=false,west=true])
B(-4,1,3,minecraft:spruce_fence[east=true,north=false,south=false,waterlogged=false,west=true])
B(-4,2,3,minecraft:spruce_fence[east=true,north=false,south=false,waterlogged=false,west=true])
B(-3,0,-4,minecraft:spruce_fence[east=true,north=false,south=false,waterlogged=false,west=true])
B(-3,1,-4,minecraft:spruce_fence[east=true,north=false,south=false,waterlogged=false,west=true])
B(-3,2,-4,minecraft:spruce_fence[east=true,north=false,south=false,waterlogged=false,west=true])
B(-3,0,3,minecraft:spruce_fence[east=true,north=false,south=false,waterlogged=false,west=true])
B(-3,1,3,minecraft:spruce_fence[east=true,north=false,south=false,waterlogged=false,west=true])
B(-3,2,3,minecraft:spruce_fence[east=true,north=false,south=false,waterlogged=false,west=true])
B(-2,0,-4,minecraft:spruce_planks)
B(-2,1,-4,minecraft:spruce_planks)
B(-2,2,-4,minecraft:spruce_planks)
B(-2,0,-3,minecraft:cobblestone_stairs[facing=north,half=top,shape=straight,waterlogged=false])
B(-2,1,-3,minecraft:cobblestone_stairs)
B(-2,2,-3,minecraft:cobblestone_stairs[facing=north,half=top,shape=straight,waterlogged=false])
B(-2,0,2,minecraft:cobblestone_stairs[facing=south,half=top,shape=straight,waterlogged=false])
B(-2,1,2,minecraft:cobblestone_stairs[facing=south,half=bottom,shape=straight,waterlogged=false])
B(-2,2,2,minecraft:cobblestone_stairs[facing=south,half=top,shape=straight,waterlogged=false])
B(-2,0,3,minecraft:spruce_planks)
B(-2,1,3,minecraft:spruce_planks)
B(-2,2,3,minecraft:spruce_planks)
B(-1,0,-4,minecraft:spruce_fence[east=true,north=false,south=false,waterlogged=false,west=true])
B(-1,1,-4,minecraft:spruce_fence[east=true,north=false,south=false,waterlogged=false,west=true])
B(-1,2,-4,minecraft:spruce_fence[east=true,north=false,south=false,waterlogged=false,west=true])
B(-1,0,3,minecraft:spruce_fence[east=true,north=false,south=false,waterlogged=false,west=true])
B(-1,1,3,minecraft:spruce_fence[east=true,north=false,south=false,waterlogged=false,west=true])
B(-1,2,3,minecraft:spruce_fence[east=true,north=false,south=false,waterlogged=false,west=true])
B(0,0,-4,minecraft:spruce_fence[east=true,north=false,south=false,waterlogged=false,west=true])
B(0,1,-4,minecraft:spruce_fence[east=true,north=false,south=false,waterlogged=false,west=true])
B(0,2,-4,minecraft:spruce_fence[east=true,north=false,south=false,waterlogged=false,west=true])
B(0,0,3,minecraft:spruce_fence[east=true,north=false,south=false,waterlogged=false,west=true])
B(0,1,3,minecraft:spruce_fence[east=true,north=false,south=false,waterlogged=false,west=true])
B(0,2,3,minecraft:spruce_fence[east=true,north=false,south=false,waterlogged=false,west=true])
B(1,0,-4,minecraft:spruce_planks)
B(1,1,-4,minecraft:spruce_planks)
B(1,2,-4,minecraft:spruce_planks)
B(1,0,-3,minecraft:cobblestone_stairs[facing=north,half=top,shape=straight,waterlogged=false])
B(1,1,-3,minecraft:cobblestone_stairs)
B(1,2,-3,minecraft:cobblestone_stairs[facing=north,half=top,shape=straight,waterlogged=false])
B(1,0,2,minecraft:cobblestone_stairs[facing=south,half=top,shape=straight,waterlogged=false])
B(1,1,2,minecraft:cobblestone_stairs[facing=south,half=bottom,shape=straight,waterlogged=false])
B(1,2,2,minecraft:cobblestone_stairs[facing=south,half=top,shape=straight,waterlogged=false])
B(1,0,3,minecraft:spruce_planks)
B(1,1,3,minecraft:spruce_planks)
B(1,2,3,minecraft:spruce_planks)
B(2,0,-4,minecraft:spruce_fence[east=true,north=false,south=false,waterlogged=false,west=true])
B(2,1,-4,minecraft:spruce_fence[east=true,north=false,south=false,waterlogged=false,west=true])
B(2,2,-4,minecraft:spruce_fence[east=true,north=false,south=false,waterlogged=false,west=true])
B(2,0,3,minecraft:spruce_fence[east=true,north=false,south=false,waterlogged=false,west=true])
B(2,1,3,minecraft:spruce_fence[east=true,north=false,south=false,waterlogged=false,west=true])
B(2,2,3,minecraft:spruce_fence[east=true,north=false,south=false,waterlogged=false,west=true])
B(3,0,-4,minecraft:spruce_fence[east=true,north=false,south=false,waterlogged=false,west=true])
B(3,1,-4,minecraft:spruce_fence[east=true,north=false,south=false,waterlogged=false,west=true])
B(3,2,-4,minecraft:spruce_fence[east=true,north=false,south=false,waterlogged=false,west=true])
B(3,0,-2,minecraft:spruce_planks)
B(3,1,-2,minecraft:spruce_planks)
B(3,2,-2,minecraft:spruce_planks)
B(3,2,-1,minecraft:spruce_planks)
B(3,2,0,minecraft:spruce_planks)
B(3,0,1,minecraft:spruce_planks)
B(3,1,1,minecraft:spruce_planks)
B(3,2,1,minecraft:spruce_planks)
B(3,0,3,minecraft:spruce_fence[east=true,north=false,south=false,waterlogged=false,west=true])
B(3,1,3,minecraft:spruce_fence[east=true,north=false,south=false,waterlogged=false,west=true])
B(3,2,3,minecraft:spruce_fence[east=true,north=false,south=false,waterlogged=false,west=true])
B(4,0,-4,minecraft:spruce_fence[east=false,north=false,south=true,waterlogged=false,west=true])
B(4,1,-4,minecraft:spruce_fence[east=false,north=false,south=true,waterlogged=false,west=true])
B(4,2,-4,minecraft:spruce_fence[east=false,north=false,south=true,waterlogged=false,west=true])
B(4,0,-3,minecraft:spruce_fence[east=false,north=true,south=true,waterlogged=false,west=false])
B(4,1,-3,minecraft:spruce_fence[east=false,north=true,south=true,waterlogged=false,west=false])
B(4,2,-3,minecraft:spruce_fence[east=false,north=true,south=true,waterlogged=false,west=false])
B(4,0,-2,minecraft:spruce_fence[east=true,north=true,south=false,waterlogged=false,west=true])
B(4,1,-2,minecraft:spruce_fence[east=true,north=true,south=false,waterlogged=false,west=true])
B(4,2,-2,minecraft:spruce_fence[east=true,north=true,south=false,waterlogged=false,west=true])
B(4,0,-1,minecraft:ladder[facing=east,waterlogged=false])
B(4,1,-1,minecraft:ladder[facing=east,waterlogged=false])
B(4,2,-1,minecraft:ladder[facing=east,waterlogged=false])
B(4,0,0,minecraft:ladder[facing=east,waterlogged=false])
B(4,1,0,minecraft:ladder[facing=east,waterlogged=false])
B(4,2,0,minecraft:ladder[facing=east,waterlogged=false])
B(4,0,1,minecraft:spruce_fence[east=true,north=false,south=true,waterlogged=false,west=true])
B(4,1,1,minecraft:spruce_fence[east=true,north=false,south=true,waterlogged=false,west=true])
B(4,2,1,minecraft:spruce_fence[east=true,north=false,south=true,waterlogged=false,west=true])
B(4,0,2,minecraft:spruce_fence[east=false,north=true,south=true,waterlogged=false,west=false])
B(4,1,2,minecraft:spruce_fence[east=false,north=true,south=true,waterlogged=false,west=false])
B(4,2,2,minecraft:spruce_fence[east=false,north=true,south=true,waterlogged=false,west=false])
B(4,0,3,minecraft:spruce_fence[east=false,north=true,south=false,waterlogged=false,west=true])
B(4,1,3,minecraft:spruce_fence[east=false,north=true,south=false,waterlogged=false,west=true])
B(4,2,3,minecraft:spruce_fence[east=false,north=true,south=false,waterlogged=false,west=true])
B(5,0,-2,minecraft:spruce_fence[east=false,north=false,south=true,waterlogged=false,west=true])
B(5,1,-2,minecraft:spruce_fence[east=false,north=false,south=true,waterlogged=false,west=true])
B(5,2,-2,minecraft:spruce_fence[east=false,north=false,south=true,waterlogged=false,west=true])
B(5,0,-1,minecraft:spruce_fence[east=false,north=true,south=true,waterlogged=false,west=false])
B(5,1,-1,minecraft:spruce_fence[east=false,north=true,south=true,waterlogged=false,west=false])
B(5,2,-1,minecraft:spruce_fence[east=false,north=true,south=true,waterlogged=false,west=false])
B(5,0,0,minecraft:spruce_fence[east=false,north=true,south=true,waterlogged=false,west=false])
B(5,1,0,minecraft:spruce_fence[east=false,north=true,south=true,waterlogged=false,west=false])
B(5,2,0,minecraft:spruce_fence[east=false,north=true,south=true,waterlogged=false,west=false])
B(5,0,1,minecraft:spruce_fence[east=false,north=true,south=false,waterlogged=false,west=true])
B(5,1,1,minecraft:spruce_fence[east=false,north=true,south=false,waterlogged=false,west=true])
B(5,2,1,minecraft:spruce_fence[east=false,north=true,south=false,waterlogged=false,west=true])

#######################################################################
# +-----------------------------------------------------------------+ #
# |                            BO3 checks                           | #
# +-----------------------------------------------------------------+ #
#######################################################################

LightCheck(-10,0,-10,0,0)
LightCheck(10,0,10,0,0)
LightCheck(10,0,-10,0,0)
LightCheck(-10,0,10,0,0)
BlockCheckNot(-2,-1,-3,minecraft:spruce_stairs[facing=west,half=bottom,shape=straight,waterlogged=false])
BlockCheckNot(-2,-1,2,minecraft:spruce_stairs[facing=east,half=bottom,shape=straight,waterlogged=false])
BlockCheckNot(1,-1,-3,minecraft:spruce_stairs[facing=west,half=bottom,shape=straight,waterlogged=false])
BlockCheckNot(1,-1,2,minecraft:spruce_stairs[facing=east,half=bottom,shape=straight,waterlogged=false])
BlockCheckNot(-2,-2,-3,minecraft:spruce_stairs[facing=west,half=bottom,shape=straight,waterlogged=false])
BlockCheckNot(-2,-2,2,minecraft:spruce_stairs[facing=east,half=bottom,shape=straight,waterlogged=false])
BlockCheckNot(1,-2,-3,minecraft:spruce_stairs[facing=west,half=bottom,shape=straight,waterlogged=false])
BlockCheckNot(1,-2,2,minecraft:spruce_stairs[facing=east,half=bottom,shape=straight,waterlogged=false])
BlockCheckNot(-2,7,-3,minecraft:dark_oak_slab[type=top,waterlogged=false])
BlockCheckNot(-2,7,2,minecraft:dark_oak_slab[type=top,waterlogged=false])
BlockCheckNot(1,7,-3,minecraft:dark_oak_slab[type=top,waterlogged=false])
BlockCheckNot(1,7,2,minecraft:dark_oak_slab[type=top,waterlogged=false])
BlockCheckNot(-2,5,-3,minecraft:dark_oak_slab[type=top,waterlogged=false])
BlockCheckNot(-2,5,2,minecraft:dark_oak_slab[type=top,waterlogged=false])
BlockCheckNot(1,5,-3,minecraft:dark_oak_slab[type=top,waterlogged=false])
BlockCheckNot(1,5,2,minecraft:dark_oak_slab[type=top,waterlogged=false])
BlockCheckNot(-2,6,-3,minecraft:dark_oak_slab[type=top,waterlogged=false])
BlockCheckNot(-2,6,2,minecraft:dark_oak_slab[type=top,waterlogged=false])
BlockCheckNot(1,6,-3,minecraft:dark_oak_slab[type=top,waterlogged=false])
BlockCheckNot(1,6,2,minecraft:dark_oak_slab[type=top,waterlogged=false])
BlockCheck(-2,-1,-3,minecraft:cobblestone_stairs[facing=north,half=top,shape=straight,waterlogged=false])
BlockCheck(-2,-1,2,minecraft:cobblestone_stairs[facing=south,half=top,shape=straight,waterlogged=false])
BlockCheck(1,-1,-3,minecraft:cobblestone_stairs[facing=north,half=top,shape=straight,waterlogged=false])
BlockCheck(1,-1,2,minecraft:cobblestone_stairs[facing=south,half=top,shape=straight,waterlogged=false])

#######################################################################
# +-----------------------------------------------------------------+ #
# |                             Branches                            | #
# +-----------------------------------------------------------------+ #
#######################################################################

Branch(0,-3,0,MineShaftDynamic100,NORTH,100.0)

#######################################################################
# +-----------------------------------------------------------------+ #
# |                             Entities                            | #
# +-----------------------------------------------------------------+ #
#######################################################################

