
#######################################################################
# +-----------------------------------------------------------------+ #
# |                            BO3 object                           | #
# +-----------------------------------------------------------------+ #
#######################################################################

Author: NLBlackEagle

Description: No description given

Version: 3

SettingsMode: WriteWithoutComments


#######################################################################
# +-----------------------------------------------------------------+ #
# |                          Main settings                          | #
# +-----------------------------------------------------------------+ #
#######################################################################

Tree: false

Frequency: 1

Rarity: 100.0

RotateRandomly: false

SpawnHeight: highestSolidBlock

SpawnHeightOffset: 5

SpawnHeightVariance: 0

##############################
# Height Limits for the BO3. #
##############################

MinHeight: 0

MaxHeight: 255

######################
# Extrusion settings #
######################

ExtrudeMode: None

ExtrudeThroughBlocks: otg:air

MaxBranchDepth: 10


#######################################################################
# +-----------------------------------------------------------------+ #
# |                      Source block settings                      | #
# +-----------------------------------------------------------------+ #
#######################################################################

SourceBlocks: otg:air

MaxPercentageOutsideSourceBlock: 100

OutsideSourceBlock: placeAnyway

DoReplaceBlocks: true

IsOTGPlus: false


#######################################################################
# +-----------------------------------------------------------------+ #
# |                              Blocks                             | #
# +-----------------------------------------------------------------+ #
#######################################################################

B(-6,-15,-7,minecraft:spruce_log)
B(-6,-14,-7,minecraft:spruce_log)
B(-6,-13,-7,minecraft:spruce_log)
B(-6,-12,-7,minecraft:spruce_log)
B(-6,-11,-7,minecraft:spruce_log)
B(-6,-10,-7,minecraft:spruce_log)
B(-6,-9,-7,minecraft:spruce_log)
B(-6,-8,-7,minecraft:spruce_log)
B(-6,-7,-7,minecraft:spruce_log)
B(-6,-6,-7,minecraft:spruce_log)
B(-6,-5,-7,minecraft:spruce_log)
B(-6,-4,-7,minecraft:spruce_log)
B(-6,-3,-7,minecraft:spruce_log)
B(-6,-2,-7,minecraft:spruce_log)
B(-6,-1,-7,minecraft:spruce_log)
B(-6,0,-7,minecraft:spruce_log)
B(-6,1,-7,minecraft:spruce_log)
B(-6,2,-7,minecraft:dark_oak_slab)
B(-6,0,-6,minecraft:dark_oak_slab[type=top,waterlogged=false])
B(-6,1,-6,minecraft:spruce_fence[east=false,north=true,south=true,waterlogged=false,west=false])
B(-6,-15,-5,minecraft:spruce_log)
B(-6,-14,-5,minecraft:spruce_log)
B(-6,-13,-5,minecraft:spruce_log)
B(-6,-12,-5,minecraft:spruce_log)
B(-6,-11,-5,minecraft:spruce_log)
B(-6,-10,-5,minecraft:spruce_log)
B(-6,-9,-5,minecraft:spruce_log)
B(-6,-8,-5,minecraft:spruce_log)
B(-6,-7,-5,minecraft:spruce_log)
B(-6,-6,-5,minecraft:spruce_log)
B(-6,-5,-5,minecraft:spruce_log)
B(-6,0,-5,minecraft:dark_oak_slab[type=top,waterlogged=false])
B(-6,1,-5,minecraft:spruce_fence[east=false,north=true,south=true,waterlogged=false,west=false])
B(-6,-4,-4,minecraft:spruce_log)
B(-6,-3,-4,minecraft:spruce_log)
B(-6,-2,-4,minecraft:spruce_log)
B(-6,-1,-4,minecraft:spruce_log)
B(-6,0,-4,minecraft:spruce_log)
B(-6,1,-4,minecraft:spruce_log)
B(-6,2,-4,minecraft:dark_oak_slab)
B(-6,0,-3,minecraft:dark_oak_slab[type=top,waterlogged=false])
B(-6,1,-3,minecraft:spruce_fence[east=false,north=true,south=true,waterlogged=false,west=false])
B(-6,0,-2,minecraft:dark_oak_slab[type=top,waterlogged=false])
B(-6,1,-2,minecraft:dark_oak_fence_gate[facing=east,in_wall=false,open=false,powered=false])
B(-6,0,-1,minecraft:dark_oak_slab[type=top,waterlogged=false])
B(-6,1,-1,minecraft:spruce_fence[east=false,north=true,south=true,waterlogged=false,west=false])
B(-6,0,0,minecraft:dark_oak_slab[type=top,waterlogged=false])
B(-6,1,0,minecraft:dark_oak_fence_gate[facing=east,in_wall=false,open=false,powered=false])
B(-6,0,1,minecraft:dark_oak_slab[type=top,waterlogged=false])
B(-6,1,1,minecraft:spruce_fence[east=false,north=true,south=true,waterlogged=false,west=false])
B(-6,-15,2,minecraft:spruce_log)
B(-6,-14,2,minecraft:spruce_log)
B(-6,-13,2,minecraft:spruce_log)
B(-6,-12,2,minecraft:spruce_log)
B(-6,-11,2,minecraft:spruce_log)
B(-6,-10,2,minecraft:spruce_log)
B(-6,-9,2,minecraft:spruce_log)
B(-6,-8,2,minecraft:spruce_log)
B(-6,-7,2,minecraft:spruce_log)
B(-6,-6,2,minecraft:spruce_log)
B(-6,-5,2,minecraft:spruce_log)
B(-6,-4,2,minecraft:spruce_log)
B(-6,-3,2,minecraft:spruce_log)
B(-6,-2,2,minecraft:spruce_log)
B(-6,-1,2,minecraft:spruce_log)
B(-6,0,2,minecraft:spruce_log)
B(-6,1,2,minecraft:spruce_log)
B(-6,2,2,minecraft:dark_oak_slab)
B(-6,0,3,minecraft:dark_oak_slab[type=top,waterlogged=false])
B(-6,1,3,minecraft:spruce_fence[east=false,north=true,south=true,waterlogged=false,west=false])
B(-6,0,4,minecraft:dark_oak_slab[type=top,waterlogged=false])
B(-6,1,4,minecraft:dark_oak_fence_gate[facing=east,in_wall=false,open=false,powered=false])
B(-6,0,5,minecraft:dark_oak_slab[type=top,waterlogged=false])
B(-6,1,5,minecraft:spruce_fence[east=false,north=true,south=true,waterlogged=false,west=false])
B(-6,0,6,minecraft:dark_oak_slab[type=top,waterlogged=false])
B(-6,1,6,minecraft:dark_oak_fence_gate[facing=east,in_wall=false,open=false,powered=false])
B(-6,0,7,minecraft:dark_oak_slab[type=top,waterlogged=false])
B(-6,1,7,minecraft:spruce_fence[east=false,north=true,south=true,waterlogged=false,west=false])
B(-6,-15,8,minecraft:spruce_log)
B(-6,-14,8,minecraft:spruce_log)
B(-6,-13,8,minecraft:spruce_log)
B(-6,-12,8,minecraft:spruce_log)
B(-6,-11,8,minecraft:spruce_log)
B(-6,-10,8,minecraft:spruce_log)
B(-6,-9,8,minecraft:spruce_log)
B(-6,-8,8,minecraft:spruce_log)
B(-6,-7,8,minecraft:spruce_log)
B(-6,-6,8,minecraft:spruce_log)
B(-6,-5,8,minecraft:spruce_log)
B(-6,-4,8,minecraft:spruce_log)
B(-6,-3,8,minecraft:spruce_log)
B(-6,-2,8,minecraft:spruce_log)
B(-6,-1,8,minecraft:spruce_log)
B(-6,0,8,minecraft:spruce_log)
B(-6,1,8,minecraft:spruce_log)
B(-6,2,8,minecraft:dark_oak_slab)
B(-5,0,-7,minecraft:dark_oak_slab[type=top,waterlogged=false])
B(-5,1,-7,minecraft:spruce_fence[east=true,north=false,south=false,waterlogged=false,west=true])
B(-5,0,-6,minecraft:dark_oak_slab[type=top,waterlogged=false])
B(-5,0,-5,minecraft:dark_oak_slab[type=top,waterlogged=false])
B(-5,0,-4,minecraft:dark_oak_slab[type=top,waterlogged=false])
B(-5,0,-3,minecraft:dark_oak_slab[type=top,waterlogged=false])
B(-5,0,-2,minecraft:dark_oak_slab[type=top,waterlogged=false])
B(-5,0,-1,minecraft:dark_oak_slab[type=top,waterlogged=false])
B(-5,0,0,minecraft:dark_oak_slab[type=top,waterlogged=false])
B(-5,0,1,minecraft:dark_oak_slab[type=top,waterlogged=false])
B(-5,0,2,minecraft:dark_oak_slab[type=top,waterlogged=false])
B(-5,0,3,minecraft:dark_oak_slab[type=top,waterlogged=false])
B(-5,0,4,minecraft:dark_oak_slab[type=top,waterlogged=false])
B(-5,0,5,minecraft:dark_oak_slab[type=top,waterlogged=false])
B(-5,0,6,minecraft:dark_oak_slab[type=top,waterlogged=false])
B(-5,0,7,minecraft:dark_oak_slab[type=top,waterlogged=false])
B(-5,0,8,minecraft:dark_oak_slab[type=top,waterlogged=false])
B(-5,1,8,minecraft:spruce_fence[east=true,north=false,south=false,waterlogged=false,west=true])
B(-4,0,-7,minecraft:dark_oak_slab[type=top,waterlogged=false])
B(-4,1,-7,minecraft:dark_oak_fence_gate[facing=south,in_wall=false,open=false,powered=false])
B(-4,0,-6,minecraft:dark_oak_slab[type=top,waterlogged=false])
B(-4,3,-6,minecraft:dark_oak_stairs[facing=east,half=bottom,shape=straight,waterlogged=false])
B(-4,0,-5,minecraft:dark_oak_slab[type=top,waterlogged=false])
B(-4,3,-5,minecraft:dark_oak_stairs[facing=east,half=bottom,shape=straight,waterlogged=false])
B(-4,0,-4,minecraft:dark_oak_slab[type=top,waterlogged=false])
B(-4,3,-4,minecraft:dark_oak_stairs[facing=east,half=bottom,shape=straight,waterlogged=false])
B(-4,0,-3,minecraft:dark_oak_slab[type=top,waterlogged=false])
B(-4,3,-3,minecraft:dark_oak_stairs[facing=east,half=bottom,shape=straight,waterlogged=false])
B(-4,0,-2,minecraft:dark_oak_slab[type=top,waterlogged=false])
B(-4,3,-2,minecraft:dark_oak_stairs[facing=east,half=bottom,shape=straight,waterlogged=false])
B(-4,0,-1,minecraft:dark_oak_slab[type=top,waterlogged=false])
B(-4,3,-1,minecraft:dark_oak_stairs[facing=east,half=bottom,shape=straight,waterlogged=false])
B(-4,0,0,minecraft:dark_oak_slab[type=top,waterlogged=false])
B(-4,0,1,minecraft:dark_oak_slab[type=top,waterlogged=false])
B(-4,0,2,minecraft:dark_oak_slab[type=top,waterlogged=false])
B(-4,0,3,minecraft:dark_oak_slab[type=top,waterlogged=false])
B(-4,0,4,minecraft:dark_oak_slab[type=top,waterlogged=false])
B(-4,0,5,minecraft:dark_oak_slab[type=top,waterlogged=false])
B(-4,0,6,minecraft:dark_oak_slab[type=top,waterlogged=false])
B(-4,0,7,minecraft:dark_oak_slab[type=top,waterlogged=false])
B(-4,0,8,minecraft:dark_oak_slab[type=top,waterlogged=false])
B(-4,1,8,minecraft:dark_oak_fence_gate)
B(-3,0,-7,minecraft:dark_oak_slab[type=top,waterlogged=false])
B(-3,1,-7,minecraft:spruce_fence[east=true,north=false,south=false,waterlogged=false,west=true])
B(-3,0,-6,minecraft:dark_oak_slab[type=top,waterlogged=false])
B(-3,3,-6,minecraft:dark_oak_stairs[facing=west,half=top,shape=straight,waterlogged=false])
B(-3,4,-6,minecraft:dark_oak_stairs[facing=east,half=bottom,shape=straight,waterlogged=false])
B(-3,-15,-5,minecraft:spruce_log)
B(-3,-14,-5,minecraft:spruce_log)
B(-3,-13,-5,minecraft:spruce_log)
B(-3,-12,-5,minecraft:spruce_log)
B(-3,-11,-5,minecraft:spruce_log)
B(-3,-10,-5,minecraft:spruce_log)
B(-3,-9,-5,minecraft:spruce_log)
B(-3,-8,-5,minecraft:spruce_log)
B(-3,-7,-5,minecraft:spruce_log)
B(-3,-6,-5,minecraft:spruce_log)
B(-3,-5,-5,minecraft:spruce_log)
B(-3,-4,-5,minecraft:spruce_log)
B(-3,-3,-5,minecraft:spruce_log)
B(-3,-2,-5,minecraft:spruce_log)
B(-3,-1,-5,minecraft:spruce_log)
B(-3,0,-5,minecraft:spruce_log)
B(-3,1,-5,minecraft:spruce_log)
B(-3,2,-5,minecraft:spruce_log)
B(-3,3,-5,minecraft:spruce_log)
B(-3,4,-5,minecraft:spruce_stairs[facing=east,half=bottom,shape=straight,waterlogged=false])
B(-3,0,-4,minecraft:spruce_planks)
B(-3,1,-4,minecraft:spruce_planks)
B(-3,2,-4,minecraft:spruce_planks)
B(-3,3,-4,minecraft:spruce_planks)
B(-3,4,-4,minecraft:spruce_stairs[facing=east,half=bottom,shape=straight,waterlogged=false])
B(-3,0,-3,minecraft:spruce_planks)
B(-3,1,-3,minecraft:spruce_planks)
B(-3,2,-3,minecraft:spruce_planks)
B(-3,3,-3,minecraft:spruce_planks)
B(-3,4,-3,minecraft:spruce_stairs[facing=east,half=bottom,shape=straight,waterlogged=false])
B(-3,-15,-2,minecraft:spruce_log)
B(-3,-14,-2,minecraft:spruce_log)
B(-3,-13,-2,minecraft:spruce_log)
B(-3,-12,-2,minecraft:spruce_log)
B(-3,-11,-2,minecraft:spruce_log)
B(-3,-10,-2,minecraft:spruce_log)
B(-3,-9,-2,minecraft:spruce_log)
B(-3,-8,-2,minecraft:spruce_log)
B(-3,-7,-2,minecraft:spruce_log)
B(-3,-6,-2,minecraft:spruce_log)
B(-3,-5,-2,minecraft:spruce_log)
B(-3,-4,-2,minecraft:spruce_log)
B(-3,-3,-2,minecraft:spruce_log)
B(-3,-2,-2,minecraft:spruce_log)
B(-3,-1,-2,minecraft:spruce_log)
B(-3,0,-2,minecraft:spruce_log)
B(-3,1,-2,minecraft:spruce_log)
B(-3,2,-2,minecraft:spruce_log)
B(-3,3,-2,minecraft:spruce_log)
B(-3,4,-2,minecraft:spruce_stairs[facing=east,half=bottom,shape=straight,waterlogged=false])
B(-3,0,-1,minecraft:dark_oak_slab[type=top,waterlogged=false])
B(-3,3,-1,minecraft:dark_oak_stairs[facing=west,half=top,shape=straight,waterlogged=false])
B(-3,4,-1,minecraft:dark_oak_stairs[facing=east,half=bottom,shape=straight,waterlogged=false])
B(-3,0,0,minecraft:dark_oak_slab[type=top,waterlogged=false])
B(-3,0,1,minecraft:dark_oak_slab[type=top,waterlogged=false])
B(-3,0,2,minecraft:dark_oak_slab[type=top,waterlogged=false])
B(-3,-15,3,minecraft:spruce_log)
B(-3,-14,3,minecraft:spruce_log)
B(-3,-13,3,minecraft:spruce_log)
B(-3,-12,3,minecraft:spruce_log)
B(-3,-11,3,minecraft:spruce_log)
B(-3,-10,3,minecraft:spruce_log)
B(-3,-9,3,minecraft:spruce_log)
B(-3,-8,3,minecraft:spruce_log)
B(-3,-7,3,minecraft:spruce_log)
B(-3,-6,3,minecraft:spruce_log)
B(-3,-5,3,minecraft:spruce_log)
B(-3,-4,3,minecraft:spruce_log)
B(-3,-3,3,minecraft:spruce_log)
B(-3,-2,3,minecraft:spruce_log)
B(-3,-1,3,minecraft:spruce_log)
B(-3,0,3,minecraft:spruce_log)
B(-3,1,3,minecraft:spruce_log)
B(-3,2,3,minecraft:spruce_log)
B(-3,3,3,minecraft:spruce_log)
B(-3,4,3,minecraft:spruce_log)
B(-3,5,3,minecraft:spruce_log)
B(-3,6,3,minecraft:spruce_log)
B(-3,7,3,minecraft:spruce_log)
B(-3,8,3,minecraft:dark_oak_stairs[facing=east,half=bottom,shape=straight,waterlogged=false])
B(-3,0,4,minecraft:dark_oak_slab[type=double,waterlogged=false])
B(-3,3,4,minecraft:dark_oak_slab[type=top,waterlogged=false])
B(-3,4,4,minecraft:spruce_slab)
B(-3,6,4,minecraft:oak_trapdoor[facing=east,half=bottom,open=true,powered=false,waterlogged=false])
B(-3,7,4,minecraft:dark_oak_slab[type=top,waterlogged=false])
B(-3,8,4,minecraft:spruce_slab)
B(-3,0,5,minecraft:dark_oak_slab[type=double,waterlogged=false])
B(-3,3,5,minecraft:dark_oak_slab[type=top,waterlogged=false])
B(-3,4,5,minecraft:spruce_slab)
B(-3,6,5,minecraft:oak_trapdoor[facing=east,half=bottom,open=true,powered=false,waterlogged=false])
B(-3,7,5,minecraft:dark_oak_slab[type=top,waterlogged=false])
B(-3,8,5,minecraft:spruce_slab)
B(-3,-15,6,minecraft:spruce_log)
B(-3,-14,6,minecraft:spruce_log)
B(-3,-13,6,minecraft:spruce_log)
B(-3,-12,6,minecraft:spruce_log)
B(-3,-11,6,minecraft:spruce_log)
B(-3,-10,6,minecraft:spruce_log)
B(-3,-9,6,minecraft:spruce_log)
B(-3,-8,6,minecraft:spruce_log)
B(-3,-7,6,minecraft:spruce_log)
B(-3,-6,6,minecraft:spruce_log)
B(-3,-5,6,minecraft:spruce_log)
B(-3,-4,6,minecraft:spruce_log)
B(-3,-3,6,minecraft:spruce_log)
B(-3,-2,6,minecraft:spruce_log)
B(-3,-1,6,minecraft:spruce_log)
B(-3,0,6,minecraft:spruce_log)
B(-3,1,6,minecraft:spruce_log)
B(-3,2,6,minecraft:spruce_log)
B(-3,3,6,minecraft:spruce_log)
B(-3,4,6,minecraft:spruce_log)
B(-3,5,6,minecraft:spruce_log)
B(-3,6,6,minecraft:spruce_log)
B(-3,7,6,minecraft:spruce_log)
B(-3,8,6,minecraft:dark_oak_stairs[facing=east,half=bottom,shape=straight,waterlogged=false])
B(-3,0,7,minecraft:dark_oak_slab[type=top,waterlogged=false])
B(-3,0,8,minecraft:dark_oak_slab[type=top,waterlogged=false])
B(-3,1,8,minecraft:spruce_fence[east=true,north=false,south=false,waterlogged=false,west=true])
B(-2,-15,-7,minecraft:spruce_log)
B(-2,-14,-7,minecraft:spruce_log)
B(-2,-13,-7,minecraft:spruce_log)
B(-2,-12,-7,minecraft:spruce_log)
B(-2,-11,-7,minecraft:spruce_log)
B(-2,-10,-7,minecraft:spruce_log)
B(-2,-9,-7,minecraft:spruce_log)
B(-2,-8,-7,minecraft:spruce_log)
B(-2,-7,-7,minecraft:spruce_log)
B(-2,-6,-7,minecraft:spruce_log)
B(-2,-5,-7,minecraft:spruce_log)
B(-2,-4,-7,minecraft:spruce_log)
B(-2,-3,-7,minecraft:spruce_log)
B(-2,-2,-7,minecraft:spruce_log)
B(-2,-1,-7,minecraft:spruce_log)
B(-2,0,-7,minecraft:spruce_log)
B(-2,1,-7,minecraft:spruce_log)
B(-2,2,-7,minecraft:dark_oak_stairs[facing=south,half=bottom,shape=straight,waterlogged=false])
B(-2,-15,-6,minecraft:spruce_log)
B(-2,-14,-6,minecraft:spruce_log)
B(-2,-13,-6,minecraft:spruce_log)
B(-2,-12,-6,minecraft:spruce_log)
B(-2,-11,-6,minecraft:spruce_log)
B(-2,-10,-6,minecraft:spruce_log)
B(-2,-9,-6,minecraft:spruce_log)
B(-2,-8,-6,minecraft:spruce_log)
B(-2,-7,-6,minecraft:spruce_log)
B(-2,-6,-6,minecraft:spruce_log)
B(-2,-5,-6,minecraft:spruce_log)
B(-2,-4,-6,minecraft:spruce_log)
B(-2,-3,-6,minecraft:spruce_log)
B(-2,-2,-6,minecraft:spruce_log)
B(-2,-1,-6,minecraft:spruce_log)
B(-2,0,-6,minecraft:spruce_log)
B(-2,1,-6,minecraft:spruce_log)
B(-2,2,-6,minecraft:spruce_planks)
B(-2,4,-6,minecraft:dark_oak_stairs[facing=west,half=top,shape=straight,waterlogged=false])
B(-2,5,-6,minecraft:dark_oak_stairs[facing=east,half=bottom,shape=straight,waterlogged=false])
B(-2,0,-5,minecraft:spruce_planks)
B(-2,1,-5,minecraft:dark_oak_slab[type=top,waterlogged=false])
B(-2,2,-5,minecraft:torch)
B(-2,3,-5,minecraft:spruce_planks)
B(-2,4,-5,minecraft:spruce_planks)
B(-2,5,-5,minecraft:spruce_stairs[facing=east,half=bottom,shape=straight,waterlogged=false])
B(-2,0,-4,minecraft:spruce_planks)
B(-2,4,-4,minecraft:spruce_stairs[facing=west,half=top,shape=straight,waterlogged=false])
B(-2,5,-4,minecraft:spruce_stairs[facing=east,half=bottom,shape=straight,waterlogged=false])
B(-2,0,-3,minecraft:spruce_planks)
B(-2,4,-3,minecraft:spruce_stairs[facing=west,half=top,shape=straight,waterlogged=false])
B(-2,5,-3,minecraft:spruce_stairs[facing=east,half=bottom,shape=straight,waterlogged=false])
B(-2,0,-2,minecraft:spruce_planks)
B(-2,1,-2,minecraft:spruce_planks)
B(-2,2,-2,minecraft:spruce_planks)
B(-2,3,-2,minecraft:spruce_planks)
B(-2,4,-2,minecraft:spruce_planks)
B(-2,5,-2,minecraft:spruce_stairs[facing=east,half=bottom,shape=straight,waterlogged=false])
B(-2,0,-1,minecraft:dark_oak_slab[type=top,waterlogged=false])
B(-2,4,-1,minecraft:dark_oak_stairs[facing=west,half=top,shape=straight,waterlogged=false])
B(-2,5,-1,minecraft:dark_oak_stairs[facing=east,half=bottom,shape=straight,waterlogged=false])
B(-2,0,0,minecraft:dark_oak_slab[type=double,waterlogged=false])
B(-2,0,1,minecraft:dark_oak_slab[type=double,waterlogged=false])
B(-2,-15,2,minecraft:spruce_log)
B(-2,-14,2,minecraft:spruce_log)
B(-2,-13,2,minecraft:spruce_log)
B(-2,-12,2,minecraft:spruce_log)
B(-2,-11,2,minecraft:spruce_log)
B(-2,-10,2,minecraft:spruce_log)
B(-2,-9,2,minecraft:spruce_log)
B(-2,-8,2,minecraft:spruce_log)
B(-2,-7,2,minecraft:spruce_log)
B(-2,-6,2,minecraft:spruce_log)
B(-2,-5,2,minecraft:spruce_log)
B(-2,-4,2,minecraft:spruce_log)
B(-2,-3,2,minecraft:spruce_log)
B(-2,-2,2,minecraft:spruce_log)
B(-2,-1,2,minecraft:spruce_log)
B(-2,0,2,minecraft:spruce_log)
B(-2,1,2,minecraft:spruce_log)
B(-2,2,2,minecraft:spruce_log)
B(-2,3,2,minecraft:spruce_log)
B(-2,4,2,minecraft:spruce_log)
B(-2,5,2,minecraft:spruce_log)
B(-2,6,2,minecraft:spruce_log)
B(-2,7,2,minecraft:spruce_log)
B(-2,8,2,minecraft:dark_oak_stairs[facing=south,half=bottom,shape=straight,waterlogged=false])
B(-2,4,3,minecraft:spruce_log[axis=x])
B(-2,6,3,minecraft:dark_oak_slab[type=top,waterlogged=false])
B(-2,8,3,minecraft:spruce_log[axis=z])
B(-2,1,4,minecraft:oak_trapdoor[facing=west,half=top,open=true,powered=false,waterlogged=false])
B(-2,2,4,minecraft:oak_trapdoor[facing=west,half=bottom,open=true,powered=false,waterlogged=false])
B(-2,3,4,minecraft:oak_trapdoor[facing=west,half=top,open=true,powered=false,waterlogged=false])
B(-2,4,4,minecraft:spruce_log[axis=z])
B(-2,5,4,minecraft:oak_trapdoor[facing=west,half=bottom,open=true,powered=false,waterlogged=false])
B(-2,6,4,minecraft:dark_oak_slab[type=top,waterlogged=false])
B(-2,7,4,minecraft:oak_trapdoor[facing=west,half=top,open=true,powered=false,waterlogged=false])
B(-2,8,4,minecraft:spruce_log[axis=z])
B(-2,1,5,minecraft:oak_trapdoor[facing=west,half=top,open=true,powered=false,waterlogged=false])
B(-2,2,5,minecraft:oak_trapdoor[facing=west,half=bottom,open=true,powered=false,waterlogged=false])
B(-2,3,5,minecraft:oak_trapdoor[facing=west,half=top,open=true,powered=false,waterlogged=false])
B(-2,4,5,minecraft:spruce_log[axis=z])
B(-2,5,5,minecraft:oak_trapdoor[facing=west,half=bottom,open=true,powered=false,waterlogged=false])
B(-2,6,5,minecraft:dark_oak_slab[type=top,waterlogged=false])
B(-2,7,5,minecraft:oak_trapdoor[facing=west,half=top,open=true,powered=false,waterlogged=false])
B(-2,8,5,minecraft:spruce_log[axis=z])
B(-2,4,6,minecraft:spruce_log[axis=z])
B(-2,6,6,minecraft:dark_oak_slab[type=top,waterlogged=false])
B(-2,8,6,minecraft:spruce_log[axis=x])
B(-2,-15,7,minecraft:spruce_log)
B(-2,-14,7,minecraft:spruce_log)
B(-2,-13,7,minecraft:spruce_log)
B(-2,-12,7,minecraft:spruce_log)
B(-2,-11,7,minecraft:spruce_log)
B(-2,-10,7,minecraft:spruce_log)
B(-2,-9,7,minecraft:spruce_log)
B(-2,-8,7,minecraft:spruce_log)
B(-2,-7,7,minecraft:spruce_log)
B(-2,-6,7,minecraft:spruce_log)
B(-2,-5,7,minecraft:spruce_log)
B(-2,-4,7,minecraft:spruce_log)
B(-2,-3,7,minecraft:spruce_log)
B(-2,-2,7,minecraft:spruce_log)
B(-2,-1,7,minecraft:spruce_log)
B(-2,0,7,minecraft:spruce_log)
B(-2,1,7,minecraft:spruce_log)
B(-2,2,7,minecraft:spruce_log)
B(-2,3,7,minecraft:spruce_log)
B(-2,4,7,minecraft:spruce_log)
B(-2,5,7,minecraft:spruce_log)
B(-2,6,7,minecraft:spruce_log)
B(-2,7,7,minecraft:spruce_log)
B(-2,8,7,minecraft:dark_oak_stairs[facing=east,half=bottom,shape=straight,waterlogged=false])
B(-2,-15,8,minecraft:spruce_log)
B(-2,-14,8,minecraft:spruce_log)
B(-2,-13,8,minecraft:spruce_log)
B(-2,-12,8,minecraft:spruce_log)
B(-2,-11,8,minecraft:spruce_log)
B(-2,-10,8,minecraft:spruce_log)
B(-2,-9,8,minecraft:spruce_log)
B(-2,-8,8,minecraft:spruce_log)
B(-2,-7,8,minecraft:spruce_log)
B(-2,-6,8,minecraft:spruce_log)
B(-2,-5,8,minecraft:spruce_log)
B(-2,-4,8,minecraft:spruce_log)
B(-2,-3,8,minecraft:spruce_log)
B(-2,-2,8,minecraft:spruce_log)
B(-2,-1,8,minecraft:spruce_log)
B(-2,0,8,minecraft:spruce_log)
B(-2,1,8,minecraft:spruce_log)
B(-2,2,8,minecraft:dark_oak_stairs[facing=east,half=bottom,shape=straight,waterlogged=false])
B(-1,0,-7,minecraft:dark_oak_slab[type=top,waterlogged=false])
B(-1,1,-7,minecraft:spruce_fence[east=true,north=false,south=true,waterlogged=false,west=true])
B(-1,0,-6,minecraft:spruce_planks)
B(-1,1,-6,minecraft:spruce_planks)
B(-1,2,-6,minecraft:spruce_planks)
B(-1,3,-6,minecraft:dark_oak_stairs[facing=south,half=bottom,shape=straight,waterlogged=false])
B(-1,5,-6,minecraft:dark_oak_stairs[facing=west,half=top,shape=straight,waterlogged=false])
B(-1,6,-6,minecraft:dark_oak_stairs[facing=east,half=bottom,shape=straight,waterlogged=false])
B(-1,0,-5,minecraft:spruce_planks)
B(-1,1,-5,minecraft:dark_oak_slab[type=top,waterlogged=false])
B(-1,3,-5,minecraft:spruce_stairs[facing=north,half=top,shape=straight,waterlogged=false])
B(-1,4,-5,minecraft:spruce_planks)
B(-1,5,-5,minecraft:spruce_planks)
B(-1,6,-5,minecraft:spruce_stairs[facing=east,half=bottom,shape=straight,waterlogged=false])
B(-1,0,-4,minecraft:spruce_planks)
B(-1,5,-4,minecraft:spruce_stairs[facing=west,half=top,shape=straight,waterlogged=false])
B(-1,6,-4,minecraft:spruce_stairs[facing=east,half=bottom,shape=straight,waterlogged=false])
B(-1,0,-3,minecraft:spruce_planks)
B(-1,5,-3,minecraft:spruce_stairs[facing=west,half=top,shape=straight,waterlogged=false])
B(-1,6,-3,minecraft:spruce_stairs[facing=east,half=bottom,shape=straight,waterlogged=false])
B(-1,0,-2,minecraft:spruce_planks)
B(-1,1,-2,minecraft:spruce_door[facing=south,half=lower,hinge=left,open=false,powered=false])
B(-1,2,-2,minecraft:spruce_door[facing=south,half=upper,hinge=left,open=false,powered=false])
B(-1,3,-2,minecraft:spruce_planks)
B(-1,4,-2,minecraft:spruce_planks)
B(-1,5,-2,minecraft:spruce_planks)
B(-1,6,-2,minecraft:spruce_stairs[facing=east,half=bottom,shape=straight,waterlogged=false])
B(-1,0,-1,minecraft:dark_oak_slab[type=top,waterlogged=false])
B(-1,5,-1,minecraft:dark_oak_stairs[facing=west,half=top,shape=straight,waterlogged=false])
B(-1,6,-1,minecraft:dark_oak_stairs[facing=east,half=bottom,shape=straight,waterlogged=false])
B(-1,0,0,minecraft:dark_oak_stairs[facing=east,half=bottom,shape=straight,waterlogged=false])
B(-1,2,2,minecraft:dark_oak_slab)
B(-1,3,2,minecraft:dark_oak_slab[type=top,waterlogged=false])
B(-1,4,2,minecraft:spruce_slab)
B(-1,6,2,minecraft:oak_trapdoor[facing=south,half=bottom,open=true,powered=false,waterlogged=false])
B(-1,7,2,minecraft:dark_oak_slab[type=top,waterlogged=false])
B(-1,8,2,minecraft:spruce_slab)
B(-1,2,3,minecraft:oak_trapdoor[facing=north,half=bottom,open=true,powered=false,waterlogged=false])
B(-1,3,3,minecraft:oak_trapdoor[facing=north,half=top,open=true,powered=false,waterlogged=false])
B(-1,4,3,minecraft:spruce_log[axis=x])
B(-1,5,3,minecraft:oak_trapdoor[facing=north,half=bottom,open=true,powered=false,waterlogged=false])
B(-1,6,3,minecraft:dark_oak_slab[type=top,waterlogged=false])
B(-1,7,3,minecraft:oak_trapdoor[facing=north,half=top,open=true,powered=false,waterlogged=false])
B(-1,8,3,minecraft:spruce_log[axis=x])
B(-1,8,4,minecraft:spruce_slab[type=top,waterlogged=false])
B(-1,8,5,minecraft:spruce_slab[type=top,waterlogged=false])
B(-1,1,6,minecraft:oak_trapdoor[facing=south,half=top,open=true,powered=false,waterlogged=false])
B(-1,2,6,minecraft:oak_trapdoor[facing=south,half=bottom,open=true,powered=false,waterlogged=false])
B(-1,3,6,minecraft:oak_trapdoor[facing=south,half=top,open=true,powered=false,waterlogged=false])
B(-1,4,6,minecraft:spruce_log[axis=x])
B(-1,5,6,minecraft:oak_trapdoor[facing=south,half=bottom,open=true,powered=false,waterlogged=false])
B(-1,6,6,minecraft:dark_oak_slab[type=top,waterlogged=false])
B(-1,7,6,minecraft:oak_trapdoor[facing=south,half=top,open=true,powered=false,waterlogged=false])
B(-1,8,6,minecraft:spruce_log[axis=x])
B(-1,0,7,minecraft:dark_oak_slab[type=double,waterlogged=false])
B(-1,3,7,minecraft:dark_oak_slab[type=top,waterlogged=false])
B(-1,4,7,minecraft:spruce_slab)
B(-1,6,7,minecraft:oak_trapdoor[facing=north,half=bottom,open=true,powered=false,waterlogged=false])
B(-1,7,7,minecraft:dark_oak_slab[type=top,waterlogged=false])
B(-1,8,7,minecraft:spruce_slab)
B(-1,0,8,minecraft:dark_oak_slab[type=top,waterlogged=false])
B(-1,1,8,minecraft:spruce_fence[east=true,north=false,south=false,waterlogged=false,west=true])
B(0,0,-7,minecraft:dark_oak_slab[type=top,waterlogged=false])
B(0,1,-7,minecraft:spruce_fence[east=true,north=false,south=true,waterlogged=false,west=true])
B(0,0,-6,minecraft:spruce_planks)
B(0,1,-6,minecraft:spruce_planks)
B(0,2,-6,minecraft:spruce_planks)
B(0,3,-6,minecraft:dark_oak_stairs[facing=south,half=bottom,shape=straight,waterlogged=false])
B(0,5,-6,minecraft:dark_oak_stairs[facing=east,half=top,shape=straight,waterlogged=false])
B(0,6,-6,minecraft:dark_oak_stairs[facing=west,half=bottom,shape=straight,waterlogged=false])
B(0,0,-5,minecraft:spruce_planks)
B(0,1,-5,minecraft:dark_oak_slab[type=top,waterlogged=false])
B(0,3,-5,minecraft:spruce_stairs[facing=north,half=top,shape=straight,waterlogged=false])
B(0,4,-5,minecraft:spruce_planks)
B(0,5,-5,minecraft:spruce_planks)
B(0,6,-5,minecraft:spruce_stairs[facing=west,half=bottom,shape=straight,waterlogged=false])
B(0,0,-4,minecraft:spruce_planks)
B(0,5,-4,minecraft:spruce_stairs[facing=east,half=top,shape=straight,waterlogged=false])
B(0,6,-4,minecraft:spruce_stairs[facing=west,half=bottom,shape=straight,waterlogged=false])
B(0,0,-3,minecraft:ladder[facing=west,waterlogged=false])
B(0,5,-3,minecraft:spruce_stairs[facing=east,half=top,shape=straight,waterlogged=false])
B(0,6,-3,minecraft:spruce_stairs[facing=west,half=bottom,shape=straight,waterlogged=false])
B(0,0,-2,minecraft:spruce_planks)
B(0,1,-2,minecraft:spruce_door[facing=south,half=lower,hinge=left,open=false,powered=false])
B(0,2,-2,minecraft:spruce_door[facing=south,half=upper,hinge=left,open=false,powered=false])
B(0,3,-2,minecraft:spruce_planks)
B(0,4,-2,minecraft:spruce_planks)
B(0,5,-2,minecraft:spruce_planks)
B(0,6,-2,minecraft:spruce_stairs[facing=west,half=bottom,shape=straight,waterlogged=false])
B(0,0,-1,minecraft:dark_oak_slab[type=top,waterlogged=false])
B(0,5,-1,minecraft:dark_oak_stairs[facing=east,half=top,shape=straight,waterlogged=false])
B(0,6,-1,minecraft:dark_oak_stairs[facing=west,half=bottom,shape=straight,waterlogged=false])
B(0,0,0,minecraft:dark_oak_stairs[facing=east,half=bottom,shape=straight,waterlogged=false])
B(0,2,2,minecraft:dark_oak_slab)
B(0,3,2,minecraft:dark_oak_slab[type=top,waterlogged=false])
B(0,4,2,minecraft:spruce_slab)
B(0,6,2,minecraft:oak_trapdoor[facing=south,half=bottom,open=true,powered=false,waterlogged=false])
B(0,7,2,minecraft:dark_oak_slab[type=top,waterlogged=false])
B(0,8,2,minecraft:spruce_slab)
B(0,2,3,minecraft:oak_trapdoor[facing=north,half=bottom,open=true,powered=false,waterlogged=false])
B(0,3,3,minecraft:oak_trapdoor[facing=north,half=top,open=true,powered=false,waterlogged=false])
B(0,4,3,minecraft:spruce_log[axis=x])
B(0,5,3,minecraft:oak_trapdoor[facing=north,half=bottom,open=true,powered=false,waterlogged=false])
B(0,6,3,minecraft:dark_oak_slab[type=top,waterlogged=false])
B(0,7,3,minecraft:oak_trapdoor[facing=north,half=top,open=true,powered=false,waterlogged=false])
B(0,8,3,minecraft:spruce_log[axis=x])
B(0,8,4,minecraft:spruce_slab[type=top,waterlogged=false])
B(0,8,5,minecraft:spruce_slab[type=top,waterlogged=false])
B(0,1,6,minecraft:oak_trapdoor[facing=south,half=top,open=true,powered=false,waterlogged=false])
B(0,2,6,minecraft:oak_trapdoor[facing=south,half=bottom,open=true,powered=false,waterlogged=false])
B(0,3,6,minecraft:oak_trapdoor[facing=south,half=top,open=true,powered=false,waterlogged=false])
B(0,4,6,minecraft:spruce_log[axis=x])
B(0,5,6,minecraft:oak_trapdoor[facing=south,half=bottom,open=true,powered=false,waterlogged=false])
B(0,6,6,minecraft:dark_oak_slab[type=top,waterlogged=false])
B(0,7,6,minecraft:oak_trapdoor[facing=south,half=top,open=true,powered=false,waterlogged=false])
B(0,8,6,minecraft:spruce_log[axis=x])
B(0,0,7,minecraft:dark_oak_slab[type=double,waterlogged=false])
B(0,3,7,minecraft:dark_oak_slab[type=top,waterlogged=false])
B(0,4,7,minecraft:spruce_slab)
B(0,6,7,minecraft:oak_trapdoor[facing=north,half=bottom,open=true,powered=false,waterlogged=false])
B(0,7,7,minecraft:dark_oak_slab[type=top,waterlogged=false])
B(0,8,7,minecraft:spruce_slab)
B(0,0,8,minecraft:dark_oak_slab[type=top,waterlogged=false])
B(0,1,8,minecraft:spruce_fence[east=true,north=false,south=false,waterlogged=false,west=true])
B(1,-15,-7,minecraft:spruce_log)
B(1,-14,-7,minecraft:spruce_log)
B(1,-13,-7,minecraft:spruce_log)
B(1,-12,-7,minecraft:spruce_log)
B(1,-11,-7,minecraft:spruce_log)
B(1,-10,-7,minecraft:spruce_log)
B(1,-9,-7,minecraft:spruce_log)
B(1,-8,-7,minecraft:spruce_log)
B(1,-7,-7,minecraft:spruce_log)
B(1,-6,-7,minecraft:spruce_log)
B(1,-5,-7,minecraft:spruce_log)
B(1,-4,-7,minecraft:spruce_log)
B(1,-3,-7,minecraft:spruce_log)
B(1,-2,-7,minecraft:spruce_log)
B(1,-1,-7,minecraft:spruce_log)
B(1,0,-7,minecraft:spruce_log)
B(1,1,-7,minecraft:spruce_log)
B(1,2,-7,minecraft:dark_oak_stairs[facing=south,half=bottom,shape=straight,waterlogged=false])
B(1,-15,-6,minecraft:spruce_log)
B(1,-14,-6,minecraft:spruce_log)
B(1,-13,-6,minecraft:spruce_log)
B(1,-12,-6,minecraft:spruce_log)
B(1,-11,-6,minecraft:spruce_log)
B(1,-10,-6,minecraft:spruce_log)
B(1,-9,-6,minecraft:spruce_log)
B(1,-8,-6,minecraft:spruce_log)
B(1,-7,-6,minecraft:spruce_log)
B(1,-6,-6,minecraft:spruce_log)
B(1,-5,-6,minecraft:spruce_log)
B(1,-4,-6,minecraft:spruce_log)
B(1,-3,-6,minecraft:spruce_log)
B(1,-2,-6,minecraft:spruce_log)
B(1,-1,-6,minecraft:spruce_log)
B(1,0,-6,minecraft:spruce_log)
B(1,1,-6,minecraft:spruce_log)
B(1,2,-6,minecraft:spruce_planks)
B(1,4,-6,minecraft:dark_oak_stairs[facing=east,half=top,shape=straight,waterlogged=false])
B(1,5,-6,minecraft:dark_oak_stairs[facing=west,half=bottom,shape=straight,waterlogged=false])
B(1,0,-5,minecraft:spruce_planks)
B(1,1,-5,minecraft:dark_oak_slab[type=top,waterlogged=false])
B(1,3,-5,minecraft:spruce_planks)
B(1,4,-5,minecraft:spruce_planks)
B(1,5,-5,minecraft:spruce_stairs[facing=west,half=bottom,shape=straight,waterlogged=false])
B(1,0,-4,minecraft:spruce_planks)
B(1,4,-4,minecraft:spruce_stairs[facing=east,half=top,shape=straight,waterlogged=false])
B(1,5,-4,minecraft:spruce_stairs[facing=west,half=bottom,shape=straight,waterlogged=false])
B(1,0,-3,minecraft:spruce_planks)
B(1,4,-3,minecraft:spruce_stairs[facing=east,half=top,shape=straight,waterlogged=false])
B(1,5,-3,minecraft:spruce_stairs[facing=west,half=bottom,shape=straight,waterlogged=false])
B(1,0,-2,minecraft:spruce_planks)
B(1,1,-2,minecraft:spruce_planks)
B(1,2,-2,minecraft:spruce_planks)
B(1,3,-2,minecraft:spruce_planks)
B(1,4,-2,minecraft:spruce_planks)
B(1,5,-2,minecraft:spruce_stairs[facing=west,half=bottom,shape=straight,waterlogged=false])
B(1,0,-1,minecraft:dark_oak_slab[type=top,waterlogged=false])
B(1,4,-1,minecraft:dark_oak_stairs[facing=east,half=top,shape=straight,waterlogged=false])
B(1,5,-1,minecraft:dark_oak_stairs[facing=west,half=bottom,shape=straight,waterlogged=false])
B(1,0,0,minecraft:dark_oak_slab[type=double,waterlogged=false])
B(1,0,1,minecraft:dark_oak_slab[type=double,waterlogged=false])
B(1,-15,2,minecraft:spruce_log)
B(1,-14,2,minecraft:spruce_log)
B(1,-13,2,minecraft:spruce_log)
B(1,-12,2,minecraft:spruce_log)
B(1,-11,2,minecraft:spruce_log)
B(1,-10,2,minecraft:spruce_log)
B(1,-9,2,minecraft:spruce_log)
B(1,-8,2,minecraft:spruce_log)
B(1,-7,2,minecraft:spruce_log)
B(1,-6,2,minecraft:spruce_log)
B(1,-5,2,minecraft:spruce_log)
B(1,-4,2,minecraft:spruce_log)
B(1,-3,2,minecraft:spruce_log)
B(1,-2,2,minecraft:spruce_log)
B(1,-1,2,minecraft:spruce_log)
B(1,0,2,minecraft:spruce_log)
B(1,1,2,minecraft:spruce_log)
B(1,2,2,minecraft:spruce_log)
B(1,3,2,minecraft:spruce_log)
B(1,4,2,minecraft:spruce_log)
B(1,5,2,minecraft:spruce_log)
B(1,6,2,minecraft:spruce_log)
B(1,7,2,minecraft:spruce_log)
B(1,8,2,minecraft:dark_oak_stairs[facing=south,half=bottom,shape=straight,waterlogged=false])
B(1,4,3,minecraft:spruce_log[axis=x])
B(1,6,3,minecraft:dark_oak_slab[type=top,waterlogged=false])
B(1,8,3,minecraft:spruce_log[axis=x])
B(1,1,4,minecraft:oak_trapdoor[facing=east,half=top,open=true,powered=false,waterlogged=false])
B(1,2,4,minecraft:oak_trapdoor[facing=east,half=bottom,open=true,powered=false,waterlogged=false])
B(1,3,4,minecraft:oak_trapdoor[facing=east,half=top,open=true,powered=false,waterlogged=false])
B(1,4,4,minecraft:spruce_log[axis=z])
B(1,5,4,minecraft:oak_trapdoor[facing=east,half=bottom,open=true,powered=false,waterlogged=false])
B(1,6,4,minecraft:dark_oak_slab[type=top,waterlogged=false])
B(1,7,4,minecraft:oak_trapdoor[facing=east,half=top,open=true,powered=false,waterlogged=false])
B(1,8,4,minecraft:spruce_log[axis=z])
B(1,1,5,minecraft:oak_trapdoor[facing=east,half=top,open=true,powered=false,waterlogged=false])
B(1,2,5,minecraft:oak_trapdoor[facing=east,half=bottom,open=true,powered=false,waterlogged=false])
B(1,3,5,minecraft:oak_trapdoor[facing=east,half=top,open=true,powered=false,waterlogged=false])
B(1,4,5,minecraft:spruce_log[axis=z])
B(1,5,5,minecraft:oak_trapdoor[facing=east,half=bottom,open=true,powered=false,waterlogged=false])
B(1,6,5,minecraft:dark_oak_slab[type=top,waterlogged=false])
B(1,7,5,minecraft:oak_trapdoor[facing=east,half=top,open=true,powered=false,waterlogged=false])
B(1,8,5,minecraft:spruce_log[axis=z])
B(1,4,6,minecraft:spruce_log[axis=z])
B(1,6,6,minecraft:dark_oak_slab[type=top,waterlogged=false])
B(1,8,6,minecraft:spruce_log[axis=z])
B(1,-15,7,minecraft:spruce_log)
B(1,-14,7,minecraft:spruce_log)
B(1,-13,7,minecraft:spruce_log)
B(1,-12,7,minecraft:spruce_log)
B(1,-11,7,minecraft:spruce_log)
B(1,-10,7,minecraft:spruce_log)
B(1,-9,7,minecraft:spruce_log)
B(1,-8,7,minecraft:spruce_log)
B(1,-7,7,minecraft:spruce_log)
B(1,-6,7,minecraft:spruce_log)
B(1,-5,7,minecraft:spruce_log)
B(1,-4,7,minecraft:spruce_log)
B(1,-3,7,minecraft:spruce_log)
B(1,-2,7,minecraft:spruce_log)
B(1,-1,7,minecraft:spruce_log)
B(1,0,7,minecraft:spruce_log)
B(1,1,7,minecraft:spruce_log)
B(1,2,7,minecraft:spruce_log)
B(1,3,7,minecraft:spruce_log)
B(1,4,7,minecraft:spruce_log)
B(1,5,7,minecraft:spruce_log)
B(1,6,7,minecraft:spruce_log)
B(1,7,7,minecraft:spruce_log)
B(1,8,7,minecraft:dark_oak_stairs[facing=east,half=bottom,shape=straight,waterlogged=false])
B(1,-15,8,minecraft:spruce_log)
B(1,-14,8,minecraft:spruce_log)
B(1,-13,8,minecraft:spruce_log)
B(1,-12,8,minecraft:spruce_log)
B(1,-11,8,minecraft:spruce_log)
B(1,-10,8,minecraft:spruce_log)
B(1,-9,8,minecraft:spruce_log)
B(1,-8,8,minecraft:spruce_log)
B(1,-7,8,minecraft:spruce_log)
B(1,-6,8,minecraft:spruce_log)
B(1,-5,8,minecraft:spruce_log)
B(1,-4,8,minecraft:spruce_log)
B(1,-3,8,minecraft:spruce_log)
B(1,-2,8,minecraft:spruce_log)
B(1,-1,8,minecraft:spruce_log)
B(1,0,8,minecraft:spruce_log)
B(1,1,8,minecraft:spruce_log)
B(1,2,8,minecraft:dark_oak_stairs[facing=east,half=bottom,shape=straight,waterlogged=false])
B(2,0,-7,minecraft:dark_oak_slab[type=top,waterlogged=false])
B(2,1,-7,minecraft:spruce_fence[east=true,north=false,south=false,waterlogged=false,west=true])
B(2,0,-6,minecraft:dark_oak_slab[type=top,waterlogged=false])
B(2,3,-6,minecraft:dark_oak_stairs[facing=east,half=top,shape=straight,waterlogged=false])
B(2,4,-6,minecraft:dark_oak_stairs[facing=west,half=bottom,shape=straight,waterlogged=false])
B(2,-15,-5,minecraft:spruce_log)
B(2,-14,-5,minecraft:spruce_log)
B(2,-13,-5,minecraft:spruce_log)
B(2,-12,-5,minecraft:spruce_log)
B(2,-11,-5,minecraft:spruce_log)
B(2,-10,-5,minecraft:spruce_log)
B(2,-9,-5,minecraft:spruce_log)
B(2,-8,-5,minecraft:spruce_log)
B(2,-7,-5,minecraft:spruce_log)
B(2,-6,-5,minecraft:spruce_log)
B(2,-5,-5,minecraft:spruce_log)
B(2,-4,-5,minecraft:spruce_log)
B(2,-3,-5,minecraft:spruce_log)
B(2,-2,-5,minecraft:spruce_log)
B(2,-1,-5,minecraft:spruce_log)
B(2,0,-5,minecraft:spruce_log)
B(2,1,-5,minecraft:spruce_log)
B(2,2,-5,minecraft:spruce_log)
B(2,3,-5,minecraft:spruce_log)
B(2,4,-5,minecraft:spruce_stairs[facing=west,half=bottom,shape=straight,waterlogged=false])
B(2,0,-4,minecraft:spruce_planks)
B(2,1,-4,minecraft:spruce_planks)
B(2,2,-4,minecraft:spruce_planks)
B(2,3,-4,minecraft:spruce_planks)
B(2,4,-4,minecraft:spruce_stairs[facing=west,half=bottom,shape=straight,waterlogged=false])
B(2,0,-3,minecraft:spruce_planks)
B(2,1,-3,minecraft:spruce_planks)
B(2,2,-3,minecraft:spruce_planks)
B(2,3,-3,minecraft:spruce_planks)
B(2,4,-3,minecraft:spruce_stairs[facing=west,half=bottom,shape=straight,waterlogged=false])
B(2,-15,-2,minecraft:spruce_log)
B(2,-14,-2,minecraft:spruce_log)
B(2,-13,-2,minecraft:spruce_log)
B(2,-12,-2,minecraft:spruce_log)
B(2,-11,-2,minecraft:spruce_log)
B(2,-10,-2,minecraft:spruce_log)
B(2,-9,-2,minecraft:spruce_log)
B(2,-8,-2,minecraft:spruce_log)
B(2,-7,-2,minecraft:spruce_log)
B(2,-6,-2,minecraft:spruce_log)
B(2,-5,-2,minecraft:spruce_log)
B(2,-4,-2,minecraft:spruce_log)
B(2,-3,-2,minecraft:spruce_log)
B(2,-2,-2,minecraft:spruce_log)
B(2,-1,-2,minecraft:spruce_log)
B(2,0,-2,minecraft:spruce_log)
B(2,1,-2,minecraft:spruce_log)
B(2,2,-2,minecraft:spruce_log)
B(2,3,-2,minecraft:spruce_log)
B(2,4,-2,minecraft:spruce_stairs[facing=west,half=bottom,shape=straight,waterlogged=false])
B(2,0,-1,minecraft:dark_oak_slab[type=top,waterlogged=false])
B(2,3,-1,minecraft:dark_oak_stairs[facing=east,half=top,shape=straight,waterlogged=false])
B(2,4,-1,minecraft:dark_oak_stairs[facing=west,half=bottom,shape=straight,waterlogged=false])
B(2,0,0,minecraft:dark_oak_slab[type=top,waterlogged=false])
B(2,0,1,minecraft:dark_oak_slab[type=top,waterlogged=false])
B(2,0,2,minecraft:dark_oak_slab[type=top,waterlogged=false])
B(2,-15,3,minecraft:spruce_log)
B(2,-14,3,minecraft:spruce_log)
B(2,-13,3,minecraft:spruce_log)
B(2,-12,3,minecraft:spruce_log)
B(2,-11,3,minecraft:spruce_log)
B(2,-10,3,minecraft:spruce_log)
B(2,-9,3,minecraft:spruce_log)
B(2,-8,3,minecraft:spruce_log)
B(2,-7,3,minecraft:spruce_log)
B(2,-6,3,minecraft:spruce_log)
B(2,-5,3,minecraft:spruce_log)
B(2,-4,3,minecraft:spruce_log)
B(2,-3,3,minecraft:spruce_log)
B(2,-2,3,minecraft:spruce_log)
B(2,-1,3,minecraft:spruce_log)
B(2,0,3,minecraft:spruce_log)
B(2,1,3,minecraft:spruce_log)
B(2,2,3,minecraft:spruce_log)
B(2,3,3,minecraft:spruce_log)
B(2,4,3,minecraft:spruce_log)
B(2,5,3,minecraft:spruce_log)
B(2,6,3,minecraft:spruce_log)
B(2,7,3,minecraft:spruce_log)
B(2,8,3,minecraft:dark_oak_stairs[facing=west,half=bottom,shape=straight,waterlogged=false])
B(2,0,4,minecraft:dark_oak_slab[type=double,waterlogged=false])
B(2,3,4,minecraft:dark_oak_slab[type=top,waterlogged=false])
B(2,4,4,minecraft:spruce_slab)
B(2,6,4,minecraft:oak_trapdoor[facing=west,half=bottom,open=true,powered=false,waterlogged=false])
B(2,7,4,minecraft:dark_oak_slab[type=top,waterlogged=false])
B(2,8,4,minecraft:spruce_slab)
B(2,0,5,minecraft:dark_oak_slab[type=double,waterlogged=false])
B(2,3,5,minecraft:dark_oak_slab[type=top,waterlogged=false])
B(2,4,5,minecraft:spruce_slab)
B(2,6,5,minecraft:oak_trapdoor[facing=west,half=bottom,open=true,powered=false,waterlogged=false])
B(2,7,5,minecraft:dark_oak_slab[type=top,waterlogged=false])
B(2,8,5,minecraft:spruce_slab)
B(2,-15,6,minecraft:spruce_log)
B(2,-14,6,minecraft:spruce_log)
B(2,-13,6,minecraft:spruce_log)
B(2,-12,6,minecraft:spruce_log)
B(2,-11,6,minecraft:spruce_log)
B(2,-10,6,minecraft:spruce_log)
B(2,-9,6,minecraft:spruce_log)
B(2,-8,6,minecraft:spruce_log)
B(2,-7,6,minecraft:spruce_log)
B(2,-6,6,minecraft:spruce_log)
B(2,-5,6,minecraft:spruce_log)
B(2,-4,6,minecraft:spruce_log)
B(2,-3,6,minecraft:spruce_log)
B(2,-2,6,minecraft:spruce_log)
B(2,-1,6,minecraft:spruce_log)
B(2,0,6,minecraft:spruce_log)
B(2,1,6,minecraft:spruce_log)
B(2,2,6,minecraft:spruce_log)
B(2,3,6,minecraft:spruce_log)
B(2,4,6,minecraft:spruce_log)
B(2,5,6,minecraft:spruce_log)
B(2,6,6,minecraft:spruce_log)
B(2,7,6,minecraft:spruce_log)
B(2,8,6,minecraft:dark_oak_stairs[facing=west,half=bottom,shape=straight,waterlogged=false])
B(2,0,7,minecraft:dark_oak_slab[type=top,waterlogged=false])
B(2,0,8,minecraft:dark_oak_slab[type=top,waterlogged=false])
B(2,1,8,minecraft:spruce_fence[east=true,north=false,south=false,waterlogged=false,west=true])
B(3,0,-7,minecraft:dark_oak_slab[type=top,waterlogged=false])
B(3,1,-7,minecraft:dark_oak_fence_gate[facing=south,in_wall=false,open=false,powered=false])
B(3,0,-6,minecraft:dark_oak_slab[type=top,waterlogged=false])
B(3,3,-6,minecraft:dark_oak_stairs[facing=west,half=bottom,shape=straight,waterlogged=false])
B(3,0,-5,minecraft:dark_oak_slab[type=top,waterlogged=false])
B(3,3,-5,minecraft:dark_oak_stairs[facing=west,half=bottom,shape=straight,waterlogged=false])
B(3,0,-4,minecraft:dark_oak_slab[type=top,waterlogged=false])
B(3,3,-4,minecraft:dark_oak_stairs[facing=west,half=bottom,shape=straight,waterlogged=false])
B(3,0,-3,minecraft:dark_oak_slab[type=top,waterlogged=false])
B(3,3,-3,minecraft:dark_oak_stairs[facing=west,half=bottom,shape=straight,waterlogged=false])
B(3,0,-2,minecraft:dark_oak_slab[type=top,waterlogged=false])
B(3,3,-2,minecraft:dark_oak_stairs[facing=west,half=bottom,shape=straight,waterlogged=false])
B(3,0,-1,minecraft:dark_oak_slab[type=top,waterlogged=false])
B(3,3,-1,minecraft:dark_oak_stairs[facing=west,half=bottom,shape=straight,waterlogged=false])
B(3,0,0,minecraft:dark_oak_slab[type=top,waterlogged=false])
B(3,0,1,minecraft:dark_oak_slab[type=top,waterlogged=false])
B(3,0,2,minecraft:dark_oak_slab[type=top,waterlogged=false])
B(3,0,3,minecraft:dark_oak_slab[type=top,waterlogged=false])
B(3,0,4,minecraft:dark_oak_slab[type=top,waterlogged=false])
B(3,0,5,minecraft:dark_oak_slab[type=top,waterlogged=false])
B(3,0,6,minecraft:dark_oak_slab[type=top,waterlogged=false])
B(3,0,7,minecraft:dark_oak_slab[type=top,waterlogged=false])
B(3,0,8,minecraft:dark_oak_slab[type=top,waterlogged=false])
B(3,1,8,minecraft:dark_oak_fence_gate)
B(4,0,-7,minecraft:dark_oak_slab[type=top,waterlogged=false])
B(4,1,-7,minecraft:spruce_fence[east=true,north=false,south=false,waterlogged=false,west=true])
B(4,0,-6,minecraft:dark_oak_slab[type=top,waterlogged=false])
B(4,0,-5,minecraft:dark_oak_slab[type=top,waterlogged=false])
B(4,0,-4,minecraft:dark_oak_slab[type=top,waterlogged=false])
B(4,0,-3,minecraft:dark_oak_slab[type=top,waterlogged=false])
B(4,0,-2,minecraft:dark_oak_slab[type=top,waterlogged=false])
B(4,0,-1,minecraft:dark_oak_slab[type=top,waterlogged=false])
B(4,0,0,minecraft:dark_oak_slab[type=top,waterlogged=false])
B(4,0,1,minecraft:dark_oak_slab[type=top,waterlogged=false])
B(4,0,2,minecraft:dark_oak_slab[type=top,waterlogged=false])
B(4,0,3,minecraft:dark_oak_slab[type=top,waterlogged=false])
B(4,0,4,minecraft:dark_oak_slab[type=top,waterlogged=false])
B(4,0,5,minecraft:dark_oak_slab[type=top,waterlogged=false])
B(4,0,6,minecraft:dark_oak_slab[type=top,waterlogged=false])
B(4,0,7,minecraft:dark_oak_slab[type=top,waterlogged=false])
B(4,0,8,minecraft:dark_oak_slab[type=top,waterlogged=false])
B(4,1,8,minecraft:spruce_fence[east=true,north=false,south=false,waterlogged=false,west=true])
B(5,-15,-7,minecraft:spruce_log)
B(5,-14,-7,minecraft:spruce_log)
B(5,-13,-7,minecraft:spruce_log)
B(5,-12,-7,minecraft:spruce_log)
B(5,-11,-7,minecraft:spruce_log)
B(5,-10,-7,minecraft:spruce_log)
B(5,-9,-7,minecraft:spruce_log)
B(5,-8,-7,minecraft:spruce_log)
B(5,-7,-7,minecraft:spruce_log)
B(5,-6,-7,minecraft:spruce_log)
B(5,-5,-7,minecraft:spruce_log)
B(5,-4,-7,minecraft:spruce_log)
B(5,-3,-7,minecraft:spruce_log)
B(5,-2,-7,minecraft:spruce_log)
B(5,-1,-7,minecraft:spruce_log)
B(5,0,-7,minecraft:spruce_log)
B(5,1,-7,minecraft:spruce_log)
B(5,2,-7,minecraft:dark_oak_slab)
B(5,0,-6,minecraft:dark_oak_slab[type=top,waterlogged=false])
B(5,1,-6,minecraft:spruce_fence[east=false,north=true,south=true,waterlogged=false,west=false])
B(5,-15,-5,minecraft:spruce_log)
B(5,-14,-5,minecraft:spruce_log)
B(5,-13,-5,minecraft:spruce_log)
B(5,-12,-5,minecraft:spruce_log)
B(5,-11,-5,minecraft:spruce_log)
B(5,-10,-5,minecraft:spruce_log)
B(5,-9,-5,minecraft:spruce_log)
B(5,-8,-5,minecraft:spruce_log)
B(5,-7,-5,minecraft:spruce_log)
B(5,-6,-5,minecraft:spruce_log)
B(5,-5,-5,minecraft:spruce_log)
B(5,0,-5,minecraft:dark_oak_slab[type=top,waterlogged=false])
B(5,1,-5,minecraft:spruce_fence[east=false,north=true,south=true,waterlogged=false,west=false])
B(5,-4,-4,minecraft:spruce_log)
B(5,-3,-4,minecraft:spruce_log)
B(5,-2,-4,minecraft:spruce_log)
B(5,-1,-4,minecraft:spruce_log)
B(5,0,-4,minecraft:spruce_log)
B(5,1,-4,minecraft:spruce_log)
B(5,2,-4,minecraft:dark_oak_slab)
B(5,0,-3,minecraft:dark_oak_slab[type=top,waterlogged=false])
B(5,1,-3,minecraft:spruce_fence[east=false,north=true,south=true,waterlogged=false,west=false])
B(5,0,-2,minecraft:dark_oak_slab[type=top,waterlogged=false])
B(5,1,-2,minecraft:dark_oak_fence_gate[facing=west,in_wall=false,open=false,powered=false])
B(5,0,-1,minecraft:dark_oak_slab[type=top,waterlogged=false])
B(5,1,-1,minecraft:spruce_fence[east=false,north=true,south=true,waterlogged=false,west=false])
B(5,0,0,minecraft:dark_oak_slab[type=top,waterlogged=false])
B(5,1,0,minecraft:dark_oak_fence_gate[facing=west,in_wall=false,open=false,powered=false])
B(5,0,1,minecraft:dark_oak_slab[type=top,waterlogged=false])
B(5,1,1,minecraft:spruce_fence[east=false,north=true,south=true,waterlogged=false,west=false])
B(5,-15,2,minecraft:spruce_log)
B(5,-14,2,minecraft:spruce_log)
B(5,-13,2,minecraft:spruce_log)
B(5,-12,2,minecraft:spruce_log)
B(5,-11,2,minecraft:spruce_log)
B(5,-10,2,minecraft:spruce_log)
B(5,-9,2,minecraft:spruce_log)
B(5,-8,2,minecraft:spruce_log)
B(5,-7,2,minecraft:spruce_log)
B(5,-6,2,minecraft:spruce_log)
B(5,-5,2,minecraft:spruce_log)
B(5,-4,2,minecraft:spruce_log)
B(5,-3,2,minecraft:spruce_log)
B(5,-2,2,minecraft:spruce_log)
B(5,-1,2,minecraft:spruce_log)
B(5,0,2,minecraft:spruce_log)
B(5,1,2,minecraft:spruce_log)
B(5,2,2,minecraft:dark_oak_slab)
B(5,0,3,minecraft:dark_oak_slab[type=top,waterlogged=false])
B(5,1,3,minecraft:spruce_fence[east=false,north=true,south=true,waterlogged=false,west=false])
B(5,0,4,minecraft:dark_oak_slab[type=top,waterlogged=false])
B(5,1,4,minecraft:dark_oak_fence_gate[facing=west,in_wall=false,open=false,powered=false])
B(5,0,5,minecraft:dark_oak_slab[type=top,waterlogged=false])
B(5,1,5,minecraft:spruce_fence[east=false,north=true,south=true,waterlogged=false,west=false])
B(5,0,6,minecraft:dark_oak_slab[type=top,waterlogged=false])
B(5,1,6,minecraft:dark_oak_fence_gate[facing=west,in_wall=false,open=false,powered=false])
B(5,0,7,minecraft:dark_oak_slab[type=top,waterlogged=false])
B(5,1,7,minecraft:spruce_fence[east=false,north=true,south=true,waterlogged=false,west=false])
B(5,-15,8,minecraft:spruce_log)
B(5,-14,8,minecraft:spruce_log)
B(5,-13,8,minecraft:spruce_log)
B(5,-12,8,minecraft:spruce_log)
B(5,-11,8,minecraft:spruce_log)
B(5,-10,8,minecraft:spruce_log)
B(5,-9,8,minecraft:spruce_log)
B(5,-8,8,minecraft:spruce_log)
B(5,-7,8,minecraft:spruce_log)
B(5,-6,8,minecraft:spruce_log)
B(5,-5,8,minecraft:spruce_log)
B(5,-4,8,minecraft:spruce_log)
B(5,-3,8,minecraft:spruce_log)
B(5,-2,8,minecraft:spruce_log)
B(5,-1,8,minecraft:spruce_log)
B(5,0,8,minecraft:spruce_log)
B(5,1,8,minecraft:spruce_log)
B(5,2,8,minecraft:dark_oak_slab)

#######################################################################
# +-----------------------------------------------------------------+ #
# |                            BO3 checks                           | #
# +-----------------------------------------------------------------+ #
#######################################################################

BlockCheck(0,-1,0,minecraft:dark_oak_slab[type=top,waterlogged=false])
LightCheck(0,3,0,15,15)

#######################################################################
# +-----------------------------------------------------------------+ #
# |                             Branches                            | #
# +-----------------------------------------------------------------+ #
#######################################################################

Branch(-3,-1,3,MineShaftWoodFoundation,NORTH,100.0)
Branch(-3,-1,-5,MineShaftWoodFoundation,NORTH,100.0)
Branch(-3,-1,-2,MineShaftWoodFoundation,NORTH,100.0)
Branch(-2,-1,-6,MineShaftWoodFoundation,NORTH,100.0)
Branch(-2,-1,2,MineShaftWoodFoundation,NORTH,100.0)
Branch(-2,-1,7,MineShaftWoodFoundation,NORTH,100.0)
Branch(1,-1,-6,MineShaftWoodFoundation,NORTH,100.0)
Branch(1,-1,2,MineShaftWoodFoundation,NORTH,100.0)
Branch(2,-1,-5,MineShaftWoodFoundation,NORTH,100.0)
Branch(2,-1,3,MineShaftWoodFoundation,NORTH,100.0)
Branch(2,-1,6,MineShaftWoodFoundation,NORTH,100.0)
Branch(2,-1,-2,MineShaftWoodFoundation,NORTH,100.0)
Branch(1,-1,7,MineShaftWoodFoundation,NORTH,100.0)
Branch(-3,-1,6,MineShaftWoodFoundation,NORTH,100.0)
Branch(-6,-1,-7,MineShaftWoodFoundation,NORTH,100.0)
Branch(-6,-1,-4,MineShaftWoodFoundation,NORTH,100.0)
Branch(-6,-1,2,MineShaftWoodFoundation,NORTH,100.0)
Branch(-6,-1,8,MineShaftWoodFoundation,NORTH,100.0)
Branch(-2,-1,-7,MineShaftWoodFoundation,NORTH,100.0)
Branch(-2,-1,8,MineShaftWoodFoundation,NORTH,100.0)
Branch(1,-1,-7,MineShaftWoodFoundation,NORTH,100.0)
Branch(1,-1,8,MineShaftWoodFoundation,NORTH,100.0)
Branch(5,-1,-7,MineShaftWoodFoundation,NORTH,100.0)
Branch(5,-1,-4,MineShaftWoodFoundation,NORTH,100.0)
Branch(5,-1,2,MineShaftWoodFoundation,NORTH,100.0)
Branch(5,-1,8,MineShaftWoodFoundation,NORTH,100.0)

#######################################################################
# +-----------------------------------------------------------------+ #
# |                             Entities                            | #
# +-----------------------------------------------------------------+ #
#######################################################################

