#######################################################################
# +-----------------------------------------------------------------+ #
# |                            BO3 object                           | #
# +-----------------------------------------------------------------+ #
#######################################################################

Author: Bo3 BulkEdit

Description: Converted Schematic - Modified by Bo3BulkEdit

Version: 3

SettingsMode: WriteDisable

#######################################################################
# +-----------------------------------------------------------------+ #
# |                          Main settings                          | #
# +-----------------------------------------------------------------+ #
#######################################################################

IsOTGPlus: true
Tree: false
Frequency: 1
Rarity: 100.0
RotateRandomly: false
SpawnHeight: randomY
MaxBranchDepth: 10
ExcludedBiomes: All

##############################
# Height Limits for the BO3. #
##############################

MinHeight: 0
MaxHeight: 255

#######################################################################
# +-----------------------------------------------------------------+ #
# |                      Source block settings                      | #
# +-----------------------------------------------------------------+ #
#######################################################################

CanOverride: true
MaxPercentageOutsideSourceBlock: 100
OutsideSourceBlock: placeAnyway

#######################################################################
# +-----------------------------------------------------------------+ #
# |                               OTG+                              | #
# +-----------------------------------------------------------------+ #
#######################################################################

BO3Group: CeilingCrystals:0

#######################################################################
# +-----------------------------------------------------------------+ #
# |                              Blocks                             | #
# +-----------------------------------------------------------------+ #
#######################################################################

B(0,750,0,AIR)
B(15,750,15,AIR)
B(3,-35,15,STAINED_GLASS:15)
B(2,-34,15,STAINED_GLASS:15)
B(3,-34,15,STAINED_GLASS:15)
B(2,-33,14,STAINED_GLASS:15)
B(1,-33,15,STAINED_GLASS:15)
B(2,-33,15,CYAN_GLAZED_TERRACOTTA:2)
B(3,-33,15,STAINED_GLASS:15)
B(1,-32,14,STAINED_GLASS:15)
B(2,-32,14,STAINED_GLASS:15)
B(0,-32,15,STAINED_GLASS:15)
B(1,-32,15,CYAN_GLAZED_TERRACOTTA:2)
B(2,-32,15,CYAN_GLAZED_TERRACOTTA:2)
B(3,-32,15,STAINED_GLASS:15)
B(4,-32,15,STAINED_GLASS:15)
B(1,-31,13,STAINED_GLASS:15)
B(0,-31,14,STAINED_GLASS:15)
B(1,-31,14,CYAN_GLAZED_TERRACOTTA:2)
B(2,-31,14,STAINED_GLASS:15)
B(0,-31,15,CYAN_GLAZED_TERRACOTTA:2)
B(1,-31,15,CYAN_GLAZED_TERRACOTTA:2)
B(2,-31,15,STAINED_GLASS:11)
B(3,-31,15,STAINED_GLASS:15)
B(4,-31,15,STAINED_GLASS:15)
B(0,-30,13,STAINED_GLASS:15)
B(1,-30,13,STAINED_GLASS:15)
B(0,-30,14,CYAN_GLAZED_TERRACOTTA:2)
B(1,-30,14,CYAN_GLAZED_TERRACOTTA:2)
B(2,-30,14,STAINED_GLASS:15)
B(3,-30,14,STAINED_GLASS:15)
B(0,-30,15,CYAN_GLAZED_TERRACOTTA:2)
B(1,-30,15,STAINED_GLASS:11)
B(2,-30,15,STAINED_GLASS:11)
B(3,-30,15,STAINED_GLASS:15)
B(4,-30,15,STAINED_GLASS:15)
B(0,-29,12,STAINED_GLASS:15)
B(0,-29,13,STAINED_GLASS:14)
B(1,-29,13,STAINED_GLASS:15)
B(0,-29,14,CYAN_GLAZED_TERRACOTTA:2)
B(1,-29,14,STAINED_GLASS:14)
B(2,-29,14,STAINED_GLASS:15)
B(3,-29,14,STAINED_GLASS:15)
B(0,-29,15,SEA_LANTERN)
B(1,-29,15,STAINED_GLASS:11)
B(2,-29,15,STAINED_GLASS:11)
B(3,-29,15,STAINED_GLASS:15)
B(0,-28,12,STAINED_GLASS:15)
B(0,-28,13,STAINED_GLASS:14)
B(1,-28,13,STAINED_GLASS:15)
B(2,-28,13,STAINED_GLASS:15)
B(0,-28,14,STAINED_GLASS:11)
B(1,-28,14,STAINED_GLASS:14)
B(2,-28,14,STAINED_GLASS:15)
B(3,-28,14,STAINED_GLASS:15)
B(0,-28,15,SEA_LANTERN)
B(1,-28,15,STAINED_GLASS:11)
B(2,-28,15,CYAN_GLAZED_TERRACOTTA:2)
B(3,-28,15,STAINED_GLASS:15)
B(0,-27,12,STAINED_GLASS:15)
B(0,-27,13,STAINED_GLASS:11)
B(1,-27,13,STAINED_GLASS:15)
B(2,-27,13,STAINED_GLASS:15)
B(0,-27,14,STAINED_GLASS:11)
B(1,-27,14,STAINED_GLASS:11)
B(2,-27,14,STAINED_GLASS:15)
B(0,-27,15,SEA_LANTERN)
B(1,-27,15,CYAN_GLAZED_TERRACOTTA:2)
B(2,-27,15,CYAN_GLAZED_TERRACOTTA:2)
B(3,-27,15,STAINED_GLASS:15)
B(0,-26,12,STAINED_GLASS:15)
B(1,-26,12,STAINED_GLASS:15)
B(0,-26,13,STAINED_GLASS:14)
B(1,-26,13,STAINED_GLASS:15)
B(2,-26,13,STAINED_GLASS:15)
B(0,-26,14,STAINED_GLASS:11)
B(1,-26,14,CYAN_GLAZED_TERRACOTTA:2)
B(2,-26,14,STAINED_GLASS:15)
B(0,-26,15,STAINED_GLASS:11)
B(1,-26,15,CYAN_GLAZED_TERRACOTTA:2)
B(2,-26,15,STAINED_GLASS:15)
B(0,-25,12,STAINED_GLASS:15)
B(1,-25,12,STAINED_GLASS:15)
B(0,-25,13,STAINED_GLASS:11)
B(1,-25,13,STAINED_GLASS:15)
B(0,-25,14,CYAN_GLAZED_TERRACOTTA:2)
B(1,-25,14,CYAN_GLAZED_TERRACOTTA:2)
B(2,-25,14,STAINED_GLASS:15)
B(0,-25,15,STAINED_GLASS:11)
B(1,-25,15,STAINED_GLASS:15)
B(0,-24,11,STAINED_GLASS:15)
B(0,-24,12,STAINED_GLASS:15)
B(1,-24,12,STAINED_GLASS:15)
B(0,-24,13,CYAN_GLAZED_TERRACOTTA:2)
B(1,-24,13,STAINED_GLASS:15)
B(0,-24,14,CYAN_GLAZED_TERRACOTTA:2)
B(1,-24,14,STAINED_GLASS:15)
B(0,-24,15,STAINED_GLASS:15)
B(0,-23,11,STAINED_GLASS:15)
B(0,-23,12,STAINED_GLASS:15)
B(0,-23,13,CYAN_GLAZED_TERRACOTTA:2)
B(1,-23,13,STAINED_GLASS:15)
B(0,-23,14,STAINED_GLASS:15)
B(0,-23,15,STAINED_GLASS:15)
B(0,-22,11,STAINED_GLASS:15)
B(0,-22,12,STAINED_GLASS:15)
B(0,-22,13,STAINED_GLASS:15)
B(0,-21,12,STAINED_GLASS:15)

