
#######################################################################
# +-----------------------------------------------------------------+ #
# |                            BO3 object                           | #
# +-----------------------------------------------------------------+ #
#######################################################################

Author: BO3 BulkEdit (by LanToaster)

Description: This Object was Created with BO3_BulkEdit

Version: 3

SettingsMode: WriteWithoutComments


#######################################################################
# +-----------------------------------------------------------------+ #
# |                          Main settings                          | #
# +-----------------------------------------------------------------+ #
#######################################################################

Tree: false

Frequency: 1

Rarity: 100.0

RotateRandomly: false

SpawnHeight: highestBlock

SpawnHeightOffset: 0

SpawnHeightVariance: 0

##############################
# Height Limits for the BO3. #
##############################

MinHeight: 0

MaxHeight: 255

######################
# Extrusion settings #
######################

ExtrudeMode: None

ExtrudeThroughBlocks: otg:air

MaxBranchDepth: 10


#######################################################################
# +-----------------------------------------------------------------+ #
# |                      Source block settings                      | #
# +-----------------------------------------------------------------+ #
#######################################################################

SourceBlocks: otg:stone,otg:dirt,minecraft:sand,minecraft:grass_block,minecraft:obsidian,minecraft:granite,minecraft:andesite,minecraft:diorite,minecraft:gravel,minecraft:coal_ore,minecraft:iron_ore,minecraft:gold_ore,minecraft:redstone_ore,minecraft:diamond_ore,minecraft:lapis_ore,minecraft:clay,minecraft:black_concrete,minecraft:black_concrete_powder

MaxPercentageOutsideSourceBlock: 100

OutsideSourceBlock: dontPlace

DoReplaceBlocks: true

IsOTGPlus: false


#######################################################################
# +-----------------------------------------------------------------+ #
# |                              Blocks                             | #
# +-----------------------------------------------------------------+ #
#######################################################################

B(-7,4,0,minecraft:grass_block)
B(-7,4,1,minecraft:grass_block)
B(-7,4,2,minecraft:grass_block)
B(-7,4,3,minecraft:grass_block)
B(-7,4,4,minecraft:grass_block)
B(-7,3,6,minecraft:grass_block)
B(-7,3,7,minecraft:grass_block)
B(-6,5,-1,minecraft:grass_block)
B(-6,5,0,minecraft:grass_block)
B(-6,5,1,minecraft:grass_block)
B(-6,4,2,minecraft:grass_block)
B(-6,4,3,minecraft:grass_block)
B(-6,4,4,minecraft:grass_block)
B(-6,4,5,minecraft:grass_block)
B(-6,3,7,minecraft:grass_block)
B(-5,5,-2,minecraft:grass_block)
B(-5,5,-1,minecraft:grass_block)
B(-5,5,0,minecraft:grass_block)
B(-5,5,1,minecraft:grass_block)
B(-5,4,2,minecraft:grass_block)
B(-5,4,3,minecraft:grass_block)
B(-5,4,4,minecraft:grass_block)
B(-5,4,5,minecraft:grass_block)
B(-5,3,6,minecraft:grass_block)
B(-5,3,7,minecraft:grass_block)
B(-5,3,8,minecraft:grass_block)
B(-4,5,-3,minecraft:grass_block)
B(-4,5,-2,minecraft:grass_block)
B(-4,5,-1,minecraft:grass_block)
B(-4,5,0,minecraft:grass_block)
B(-4,5,1,minecraft:grass_block)
B(-4,4,2,minecraft:grass_block)
B(-4,4,3,minecraft:grass_block)
B(-4,4,4,minecraft:grass_block)
B(-4,4,5,minecraft:grass_block)
B(-4,4,6,minecraft:grass_block)
B(-4,3,7,minecraft:grass_block)
B(-4,3,8,minecraft:grass_block)
B(-3,5,-4,minecraft:grass_block)
B(-3,5,-3,minecraft:grass_block)
B(-3,5,-2,minecraft:grass_block)
B(-3,5,-1,minecraft:grass_block)
B(-3,5,0,minecraft:grass_block)
B(-3,5,1,minecraft:grass_block)
B(-3,4,2,minecraft:grass_block)
B(-3,4,3,minecraft:grass_block)
B(-3,4,4,minecraft:grass_block)
B(-3,4,5,minecraft:grass_block)
B(-3,4,6,minecraft:grass_block)
B(-3,4,7,minecraft:grass_block)
B(-3,3,8,minecraft:grass_block)
B(-2,5,-3,minecraft:grass_block)
B(-2,5,-2,minecraft:grass_block)
B(-2,5,-1,minecraft:grass_block)
B(-2,5,0,minecraft:grass_block)
B(-2,5,1,minecraft:grass_block)
B(-2,5,2,minecraft:grass_block)
B(-2,4,3,minecraft:grass_block)
B(-2,4,4,minecraft:grass_block)
B(-2,4,5,minecraft:grass_block)
B(-2,4,6,minecraft:grass_block)
B(-2,3,7,minecraft:grass_block)
B(-2,3,8,minecraft:grass_block)
B(-1,7,-4,minecraft:grass_block)
B(-1,6,-3,minecraft:grass_block)
B(-1,5,-2,minecraft:grass_block)
B(-1,5,-1,minecraft:grass_block)
B(-1,5,0,minecraft:grass_block)
B(-1,5,1,minecraft:grass_block)
B(-1,5,2,minecraft:grass_block)
B(-1,5,3,minecraft:grass_block)
B(-1,4,4,minecraft:grass_block)
B(-1,3,5,minecraft:grass_block)
B(-1,3,6,minecraft:grass_block)
B(-1,2,7,minecraft:grass_block)
B(-1,2,8,minecraft:grass_block)
B(0,7,-3,minecraft:grass_block)
B(0,6,-2,minecraft:grass_block)
B(0,6,-1,minecraft:grass_block)
B(0,6,0,minecraft:grass_block)
B(0,5,1,minecraft:grass_block)
B(0,5,2,minecraft:grass_block)
B(0,5,3,minecraft:grass_block)
B(0,4,4,minecraft:grass_block)
B(0,3,5,minecraft:grass_block)
B(0,3,6,minecraft:grass_block)
B(0,2,7,minecraft:grass_block)
B(0,2,8,minecraft:grass_block)
B(1,7,-1,minecraft:grass_block)
B(1,6,0,minecraft:grass_block)
B(1,6,1,minecraft:grass_block)
B(1,5,2,minecraft:grass_block)
B(1,5,3,minecraft:grass_block)
B(1,5,4,minecraft:grass_block)
B(1,3,5,minecraft:grass_block)
B(1,3,6,minecraft:grass_block)
B(1,2,7,minecraft:grass_block)
B(1,2,8,minecraft:grass_block)
B(2,7,0,minecraft:grass_block)
B(2,6,1,minecraft:grass_block)
B(2,6,2,minecraft:grass_block)
B(2,5,3,minecraft:grass_block)
B(2,5,4,minecraft:grass_block)
B(2,4,5,minecraft:grass_block)
B(2,3,6,minecraft:grass_block)
B(2,2,7,minecraft:grass_block)
B(2,2,8,minecraft:grass_block)
B(3,7,1,minecraft:grass_block)
B(3,6,2,minecraft:grass_block)
B(3,6,3,minecraft:grass_block)
B(3,5,4,minecraft:grass_block)
B(3,4,5,minecraft:grass_block)
B(3,3,6,minecraft:grass_block)
B(3,3,7,minecraft:grass_block)
B(3,2,8,minecraft:grass_block)
B(4,7,2,minecraft:grass_block)
B(4,6,3,minecraft:grass_block)
B(4,4,4,minecraft:grass_block)
B(4,5,5,minecraft:grass_block)
B(4,3,6,minecraft:grass_block)
B(4,2,7,minecraft:grass_block)
B(4,3,8,minecraft:grass_block)
B(5,6,3,minecraft:grass_block)
B(5,5,4,minecraft:grass_block)
B(5,5,5,minecraft:grass_block)
B(5,4,6,minecraft:grass_block)
B(5,3,7,minecraft:grass_block)
B(5,3,8,minecraft:grass_block)
B(6,6,3,minecraft:grass_block)
B(6,5,4,minecraft:grass_block)
B(6,5,5,minecraft:grass_block)
B(6,5,6,minecraft:grass_block)
B(6,3,7,minecraft:grass_block)
B(6,3,8,minecraft:grass_block)
B(7,7,2,minecraft:grass_block)
B(7,6,3,minecraft:grass_block)
B(7,5,4,minecraft:grass_block)
B(7,5,5,minecraft:grass_block)
B(7,5,6,minecraft:grass_block)
B(7,3,7,minecraft:grass_block)
B(7,4,8,minecraft:grass_block)
B(8,5,3,minecraft:grass_block)
B(8,5,4,minecraft:grass_block)
B(8,5,5,minecraft:grass_block)
B(8,5,6,minecraft:grass_block)
B(8,4,7,minecraft:grass_block)
B(8,5,8,minecraft:grass_block)

#######################################################################
# +-----------------------------------------------------------------+ #
# |                            BO3 checks                           | #
# +-----------------------------------------------------------------+ #
#######################################################################


#######################################################################
# +-----------------------------------------------------------------+ #
# |                             Branches                            | #
# +-----------------------------------------------------------------+ #
#######################################################################

Branch(16,0,0,RF_CaveShip_04-02,NORTH,100.0)
Branch(0,0,-16,RF_CaveShip_03-01,NORTH,100.0)
Branch(0,0,16,RF_CaveShip_03-03,NORTH,100.0)

#######################################################################
# +-----------------------------------------------------------------+ #
# |                             Entities                            | #
# +-----------------------------------------------------------------+ #
#######################################################################

