#######################################################################
# +-----------------------------------------------------------------+ #
# |                            BO3 object                           | #
# +-----------------------------------------------------------------+ #
#######################################################################

Author: Bo3 BulkEdit

Description: Converted Schematic - Modified by Bo3BulkEdit

Version: 3

SettingsMode: WriteDisable

#######################################################################
# +-----------------------------------------------------------------+ #
# |                          Main settings                          | #
# +-----------------------------------------------------------------+ #
#######################################################################



Frequency: 0


SpawnHeight: randomY





##############################
# Height Limits for the BO3. #
##############################

MinHeight: 0
MaxHeight: 256

#######################################################################
# +-----------------------------------------------------------------+ #
# |                      Source block settings                      | #
# +-----------------------------------------------------------------+ #
#######################################################################

CanOverride: true
MaxPercentageOutsideSourceBlock: 100
OutsideSourceBlock: placeAnyway

#######################################################################
# +-----------------------------------------------------------------+ #
# |                               OTG+                              | #
# +-----------------------------------------------------------------+ #
#######################################################################

#######################################################################
# +-----------------------------------------------------------------+ #
# |                              Blocks                             | #
# +-----------------------------------------------------------------+ #
#######################################################################

B(0,750,0,AIR)
B(15,750,15,AIR)
B(5,1,10,STAINED_GLASS:15)
B(4,1,11,STAINED_GLASS:15)
B(5,1,11,STAINED_GLASS:15)
B(3,1,12,STAINED_GLASS:15)
B(4,1,12,STAINED_GLASS:15)
B(5,1,12,STAINED_GLASS:15)
B(6,1,12,STAINED_GLASS:15)
B(4,1,13,STAINED_GLASS:15)
B(5,1,13,STAINED_GLASS:15)
B(6,1,13,STAINED_GLASS:15)
B(5,1,14,STAINED_GLASS:15)
B(6,1,14,STAINED_GLASS:15)
B(4,2,7,STAINED_GLASS:10)
B(5,2,7,STAINED_GLASS:10)
B(2,2,8,STAINED_GLASS:15)
B(3,2,8,STAINED_GLASS:15)
B(4,2,8,STAINED_GLASS:15)
B(5,2,8,STAINED_GLASS:15)
B(6,2,8,STAINED_GLASS:10)
B(2,2,9,STAINED_GLASS:15)
B(3,2,9,STAINED_GLASS:15)
B(4,2,9,STAINED_GLASS:15)
B(5,2,9,STAINED_GLASS:15)
B(6,2,9,STAINED_GLASS:15)
B(7,2,9,STAINED_GLASS:15)
B(1,2,10,STAINED_GLASS:15)
B(2,2,10,STAINED_GLASS:15)
B(3,2,10,STAINED_GLASS:15)
B(4,2,10,STAINED_GLASS:9)
B(5,2,10,STAINED_GLASS:15)
B(6,2,10,STAINED_GLASS:15)
B(7,2,10,STAINED_GLASS:15)
B(2,2,11,STAINED_GLASS:15)
B(3,2,11,STAINED_GLASS:15)
B(4,2,11,STAINED_GLASS:15)
B(5,2,11,STAINED_GLASS:15)
B(6,2,11,STAINED_GLASS:15)
B(7,2,11,STAINED_GLASS:15)
B(2,2,12,STAINED_GLASS:15)
B(3,2,12,STAINED_GLASS:15)
B(4,2,12,STAINED_GLASS:15)
B(5,2,12,STAINED_GLASS:15)
B(6,2,12,STAINED_GLASS:15)
B(4,2,13,STAINED_GLASS:15)
B(5,2,13,STAINED_GLASS:15)
B(6,2,13,STAINED_GLASS:15)
B(5,2,14,STAINED_GLASS:15)
B(6,2,14,STAINED_GLASS:15)
B(3,3,5,STAINED_GLASS:10)
B(4,3,5,STAINED_GLASS:10)
B(5,3,5,STAINED_GLASS:10)
B(2,3,6,STAINED_GLASS:15)
B(3,3,6,STAINED_GLASS:10)
B(4,3,6,STAINED_GLASS:10)
B(5,3,6,STAINED_GLASS:10)
B(0,3,7,STAINED_GLASS:15)
B(1,3,7,STAINED_GLASS:15)
B(2,3,7,STAINED_GLASS:15)
B(3,3,7,STAINED_GLASS:10)
B(4,3,7,STAINED_GLASS:10)
B(5,3,7,STAINED_GLASS:10)
B(6,3,7,STAINED_GLASS:10)
B(0,3,8,STAINED_GLASS:15)
B(1,3,8,STAINED_GLASS:15)
B(2,3,8,STAINED_GLASS:15)
B(3,3,8,STAINED_GLASS:9)
B(4,3,8,STAINED_GLASS:10)
B(5,3,8,STAINED_GLASS:10)
B(6,3,8,STAINED_GLASS:10)
B(0,3,9,STAINED_GLASS:15)
B(1,3,9,STAINED_GLASS:15)
B(2,3,9,STAINED_GLASS:15)
B(3,3,9,STAINED_GLASS:15)
B(4,3,9,STAINED_GLASS:9)
B(5,3,9,STAINED_GLASS:15)
B(6,3,9,STAINED_GLASS:10)
B(7,3,9,STAINED_GLASS:11)
B(1,3,10,STAINED_GLASS:15)
B(2,3,10,STAINED_GLASS:15)
B(3,3,10,STAINED_GLASS:15)
B(4,3,10,SEA_LANTERN)
B(5,3,10,STAINED_GLASS:11)
B(6,3,10,STAINED_GLASS:10)
B(7,3,10,STAINED_GLASS:10)
B(2,3,11,STAINED_GLASS:9)
B(3,3,11,STAINED_GLASS:15)
B(4,3,11,STAINED_GLASS:15)
B(5,3,11,STAINED_GLASS:11)
B(6,3,11,STAINED_GLASS:15)
B(7,3,11,STAINED_GLASS:15)
B(3,3,12,STAINED_GLASS:15)
B(4,3,12,STAINED_GLASS:15)
B(5,3,12,STAINED_GLASS:15)
B(6,3,12,STAINED_GLASS:15)
B(4,3,13,STAINED_GLASS:15)
B(5,3,13,STAINED_GLASS:15)
B(6,3,13,STAINED_GLASS:15)
B(3,4,3,STAINED_GLASS:10)
B(0,4,4,STAINED_GLASS:15)
B(1,4,4,STAINED_GLASS:10)
B(2,4,4,STAINED_GLASS:10)
B(3,4,4,STAINED_GLASS:10)
B(4,4,4,STAINED_GLASS:10)
B(0,4,5,STAINED_GLASS:15)
B(1,4,5,STAINED_GLASS:15)
B(2,4,5,STAINED_GLASS:10)
B(3,4,5,STAINED_GLASS:10)
B(4,4,5,STAINED_GLASS:10)
B(5,4,5,STAINED_GLASS:10)
B(0,4,6,STAINED_GLASS:15)
B(1,4,6,STAINED_GLASS:15)
B(2,4,6,STAINED_GLASS:15)
B(3,4,6,STAINED_GLASS:10)
B(4,4,6,STAINED_GLASS:10)
B(5,4,6,STAINED_GLASS:10)
B(0,4,7,STAINED_GLASS:15)
B(1,4,7,STAINED_GLASS:15)
B(2,4,7,STAINED_GLASS:15)
B(3,4,7,STAINED_GLASS:10)
B(4,4,7,STAINED_GLASS:10)
B(5,4,7,STAINED_GLASS:10)
B(6,4,7,STAINED_GLASS:10)
B(0,4,8,STAINED_GLASS:15)
B(1,4,8,STAINED_GLASS:15)
B(2,4,8,STAINED_GLASS:15)
B(3,4,8,STAINED_GLASS:9)
B(4,4,8,STAINED_GLASS:11)
B(5,4,8,STAINED_GLASS:11)
B(6,4,8,STAINED_GLASS:11)
B(0,4,9,STAINED_GLASS:15)
B(1,4,9,STAINED_GLASS:15)
B(2,4,9,STAINED_GLASS:15)
B(3,4,9,STAINED_GLASS:9)
B(4,4,9,SEA_LANTERN)
B(5,4,9,STAINED_GLASS:11)
B(6,4,9,STAINED_GLASS:11)
B(7,4,9,STAINED_GLASS:11)
B(1,4,10,STAINED_GLASS:9)
B(2,4,10,STAINED_GLASS:15)
B(3,4,10,STAINED_GLASS:9)
B(4,4,10,SEA_LANTERN)
B(5,4,10,SEA_LANTERN)
B(6,4,10,STAINED_GLASS:15)
B(7,4,10,STAINED_GLASS:15)
B(2,4,11,STAINED_GLASS:15)
B(3,4,11,STAINED_GLASS:15)
B(4,4,11,SEA_LANTERN)
B(5,4,11,SEA_LANTERN)
B(6,4,11,STAINED_GLASS:15)
B(7,4,11,STAINED_GLASS:15)
B(3,4,12,STAINED_GLASS:15)
B(4,4,12,STAINED_GLASS:15)
B(5,4,12,STAINED_GLASS:15)
B(6,4,12,STAINED_GLASS:15)
B(5,4,13,STAINED_GLASS:15)
B(6,4,13,STAINED_GLASS:15)
B(2,5,1,STAINED_GLASS:15)
B(3,5,1,STAINED_GLASS:10)
B(0,5,2,STAINED_GLASS:15)
B(1,5,2,STAINED_GLASS:15)
B(2,5,2,STAINED_GLASS:10)
B(3,5,2,STAINED_GLASS:10)
B(0,5,3,STAINED_GLASS:15)
B(1,5,3,STAINED_GLASS:15)
B(2,5,3,STAINED_GLASS:10)
B(3,5,3,STAINED_GLASS:10)
B(4,5,3,STAINED_GLASS:10)
B(0,5,4,STAINED_GLASS:15)
B(1,5,4,STAINED_GLASS:9)
B(2,5,4,STAINED_GLASS:10)
B(3,5,4,STAINED_GLASS:10)
B(4,5,4,STAINED_GLASS:11)
B(0,5,5,STAINED_GLASS:15)
B(1,5,5,STAINED_GLASS:15)
B(2,5,5,STAINED_GLASS:9)
B(3,5,5,STAINED_GLASS:10)
B(4,5,5,STAINED_GLASS:11)
B(5,5,5,STAINED_GLASS:11)
B(0,5,6,STAINED_GLASS:15)
B(1,5,6,STAINED_GLASS:15)
B(2,5,6,STAINED_GLASS:15)
B(3,5,6,STAINED_GLASS:10)
B(4,5,6,STAINED_GLASS:11)
B(5,5,6,STAINED_GLASS:11)
B(0,5,7,STAINED_GLASS:15)
B(1,5,7,STAINED_GLASS:9)
B(2,5,7,STAINED_GLASS:9)
B(3,5,7,STAINED_GLASS:11)
B(4,5,7,STAINED_GLASS:11)
B(5,5,7,STAINED_GLASS:11)
B(6,5,7,STAINED_GLASS:11)
B(0,5,8,STAINED_GLASS:9)
B(1,5,8,STAINED_GLASS:15)
B(2,5,8,STAINED_GLASS:9)
B(3,5,8,SEA_LANTERN)
B(4,5,8,STAINED_GLASS:10)
B(5,5,8,STAINED_GLASS:10)
B(6,5,8,STAINED_GLASS:11)
B(0,5,9,STAINED_GLASS:9)
B(1,5,9,STAINED_GLASS:9)
B(2,5,9,STAINED_GLASS:9)
B(3,5,9,SEA_LANTERN)
B(4,5,9,SEA_LANTERN)
B(5,5,9,SEA_LANTERN)
B(6,5,9,STAINED_GLASS:11)
B(7,5,9,STAINED_GLASS:15)
B(1,5,10,STAINED_GLASS:9)
B(2,5,10,STAINED_GLASS:15)
B(3,5,10,SEA_LANTERN)
B(4,5,10,SEA_LANTERN)
B(5,5,10,STAINED_GLASS:10)
B(6,5,10,STAINED_GLASS:15)
B(7,5,10,STAINED_GLASS:15)
B(2,5,11,STAINED_GLASS:15)
B(3,5,11,STAINED_GLASS:15)
B(4,5,11,STAINED_GLASS:10)
B(5,5,11,STAINED_GLASS:10)
B(6,5,11,STAINED_GLASS:15)
B(3,5,12,STAINED_GLASS:15)
B(4,5,12,STAINED_GLASS:15)
B(5,5,12,STAINED_GLASS:15)
B(6,5,12,STAINED_GLASS:15)
B(0,6,0,STAINED_GLASS:15)
B(1,6,0,STAINED_GLASS:15)
B(2,6,0,STAINED_GLASS:15)
B(3,6,0,STAINED_GLASS:15)
B(0,6,1,STAINED_GLASS:15)
B(1,6,1,STAINED_GLASS:15)
B(2,6,1,STAINED_GLASS:15)
B(3,6,1,STAINED_GLASS:15)
B(0,6,2,STAINED_GLASS:15)
B(1,6,2,STAINED_GLASS:15)
B(2,6,2,STAINED_GLASS:15)
B(3,6,2,STAINED_GLASS:10)
B(0,6,3,STAINED_GLASS:15)
B(1,6,3,STAINED_GLASS:9)
B(2,6,3,STAINED_GLASS:15)
B(3,6,3,STAINED_GLASS:10)
B(4,6,3,STAINED_GLASS:10)
B(0,6,4,STAINED_GLASS:15)
B(1,6,4,STAINED_GLASS:9)
B(2,6,4,STAINED_GLASS:10)
B(3,6,4,STAINED_GLASS:11)
B(4,6,4,STAINED_GLASS:11)
B(0,6,5,STAINED_GLASS:15)
B(1,6,5,STAINED_GLASS:9)
B(2,6,5,SEA_LANTERN)
B(3,6,5,STAINED_GLASS:11)
B(4,6,5,STAINED_GLASS:11)
B(5,6,5,STAINED_GLASS:11)
B(0,6,6,STAINED_GLASS:9)
B(1,6,6,STAINED_GLASS:9)
B(2,6,6,STAINED_GLASS:9)
B(3,6,6,STAINED_GLASS:11)
B(4,6,6,STAINED_GLASS:11)
B(5,6,6,STAINED_GLASS:11)
B(0,6,7,STAINED_GLASS:9)
B(1,6,7,STAINED_GLASS:15)
B(2,6,7,SEA_LANTERN)
B(3,6,7,STAINED_GLASS:11)
B(4,6,7,STAINED_GLASS:11)
B(5,6,7,STAINED_GLASS:11)
B(6,6,7,STAINED_GLASS:11)
B(0,6,8,STAINED_GLASS:9)
B(1,6,8,STAINED_GLASS:10)
B(2,6,8,STAINED_GLASS:15)
B(3,6,8,SEA_LANTERN)
B(4,6,8,STAINED_GLASS:11)
B(5,6,8,STAINED_GLASS:11)
B(6,6,8,STAINED_GLASS:11)
B(0,6,9,STAINED_GLASS:9)
B(1,6,9,STAINED_GLASS:9)
B(2,6,9,STAINED_GLASS:9)
B(3,6,9,STAINED_GLASS:9)
B(4,6,9,STAINED_GLASS:15)
B(5,6,9,STAINED_GLASS:10)
B(6,6,9,STAINED_GLASS:11)
B(7,6,9,STAINED_GLASS:11)
B(1,6,10,STAINED_GLASS:9)
B(2,6,10,STAINED_GLASS:15)
B(3,6,10,STAINED_GLASS:10)
B(4,6,10,STAINED_GLASS:15)
B(5,6,10,STAINED_GLASS:10)
B(6,6,10,STAINED_GLASS:15)
B(2,6,11,STAINED_GLASS:15)
B(3,6,11,STAINED_GLASS:15)
B(4,6,11,STAINED_GLASS:15)
B(5,6,11,STAINED_GLASS:10)
B(6,6,11,STAINED_GLASS:15)
B(4,6,12,STAINED_GLASS:15)
B(5,6,12,STAINED_GLASS:15)
B(6,6,12,STAINED_GLASS:15)
B(0,7,0,STAINED_GLASS:9)
B(1,7,0,STAINED_GLASS:15)
B(2,7,0,STAINED_GLASS:15)
B(3,7,0,STAINED_GLASS:11)
B(0,7,1,STAINED_GLASS:9)
B(1,7,1,STAINED_GLASS:15)
B(2,7,1,STAINED_GLASS:11)
B(3,7,1,STAINED_GLASS:11)
B(0,7,2,STAINED_GLASS:15)
B(1,7,2,STAINED_GLASS:15)
B(2,7,2,STAINED_GLASS:11)
B(3,7,2,STAINED_GLASS:11)
B(0,7,3,STAINED_GLASS:9)
B(1,7,3,SEA_LANTERN)
B(2,7,3,STAINED_GLASS:15)
B(3,7,3,STAINED_GLASS:11)
B(4,7,3,STAINED_GLASS:11)
B(0,7,4,STAINED_GLASS:9)
B(1,7,4,SEA_LANTERN)
B(2,7,4,SEA_LANTERN)
B(3,7,4,STAINED_GLASS:11)
B(4,7,4,STAINED_GLASS:11)
B(0,7,5,STAINED_GLASS:10)
B(1,7,5,SEA_LANTERN)
B(2,7,5,SEA_LANTERN)
B(3,7,5,SEA_LANTERN)
B(4,7,5,STAINED_GLASS:11)
B(5,7,5,STAINED_GLASS:11)
B(0,7,6,STAINED_GLASS:15)
B(1,7,6,STAINED_GLASS:15)
B(2,7,6,SEA_LANTERN)
B(3,7,6,SEA_LANTERN)
B(4,7,6,STAINED_GLASS:11)
B(5,7,6,STAINED_GLASS:11)
B(0,7,7,STAINED_GLASS:10)
B(1,7,7,STAINED_GLASS:10)
B(2,7,7,STAINED_GLASS:10)
B(3,7,7,STAINED_GLASS:11)
B(4,7,7,STAINED_GLASS:11)
B(5,7,7,STAINED_GLASS:11)
B(6,7,7,STAINED_GLASS:11)
B(0,7,8,STAINED_GLASS:9)
B(1,7,8,STAINED_GLASS:9)
B(2,7,8,STAINED_GLASS:10)
B(3,7,8,STAINED_GLASS:15)
B(4,7,8,STAINED_GLASS:11)
B(5,7,8,STAINED_GLASS:15)
B(6,7,8,STAINED_GLASS:15)
B(0,7,9,STAINED_GLASS:9)
B(1,7,9,STAINED_GLASS:9)
B(2,7,9,STAINED_GLASS:9)
B(3,7,9,STAINED_GLASS:9)
B(4,7,9,STAINED_GLASS:11)
B(5,7,9,STAINED_GLASS:15)
B(6,7,9,STAINED_GLASS:15)
B(7,7,9,STAINED_GLASS:11)
B(1,7,10,STAINED_GLASS:9)
B(2,7,10,STAINED_GLASS:15)
B(3,7,10,STAINED_GLASS:15)
B(4,7,10,STAINED_GLASS:10)
B(5,7,10,STAINED_GLASS:15)
B(6,7,10,STAINED_GLASS:10)
B(4,7,11,STAINED_GLASS:15)
B(5,7,11,STAINED_GLASS:15)
B(6,7,11,STAINED_GLASS:15)
B(0,8,0,STAINED_GLASS:9)
B(1,8,0,STAINED_GLASS:11)
B(2,8,0,STAINED_GLASS:11)
B(3,8,0,STAINED_GLASS:11)
B(0,8,1,SEA_LANTERN)
B(1,8,1,STAINED_GLASS:11)
B(2,8,1,STAINED_GLASS:11)
B(3,8,1,STAINED_GLASS:11)
B(0,8,2,STAINED_GLASS:9)
B(1,8,2,STAINED_GLASS:11)
B(2,8,2,STAINED_GLASS:11)
B(3,8,2,STAINED_GLASS:10)
B(0,8,3,STAINED_GLASS:15)
B(1,8,3,SEA_LANTERN)
B(2,8,3,SEA_LANTERN)
B(3,8,3,STAINED_GLASS:11)
B(4,8,3,STAINED_GLASS:11)
B(0,8,4,STAINED_GLASS:15)
B(1,8,4,SEA_LANTERN)
B(2,8,4,STAINED_GLASS:11)
B(3,8,4,STAINED_GLASS:10)
B(4,8,4,STAINED_GLASS:11)
B(0,8,5,STAINED_GLASS:9)
B(1,8,5,STAINED_GLASS:9)
B(2,8,5,STAINED_GLASS:15)
B(3,8,5,STAINED_GLASS:10)
B(4,8,5,STAINED_GLASS:11)
B(5,8,5,STAINED_GLASS:11)
B(0,8,6,STAINED_GLASS:10)
B(1,8,6,STAINED_GLASS:10)
B(2,8,6,STAINED_GLASS:10)
B(3,8,6,STAINED_GLASS:10)
B(4,8,6,STAINED_GLASS:10)
B(5,8,6,STAINED_GLASS:11)
B(0,8,7,STAINED_GLASS:9)
B(1,8,7,STAINED_GLASS:10)
B(2,8,7,STAINED_GLASS:15)
B(3,8,7,STAINED_GLASS:11)
B(4,8,7,STAINED_GLASS:11)
B(5,8,7,STAINED_GLASS:11)
B(6,8,7,STAINED_GLASS:11)
B(0,8,8,STAINED_GLASS:9)
B(1,8,8,STAINED_GLASS:9)
B(2,8,8,STAINED_GLASS:15)
B(3,8,8,STAINED_GLASS:9)
B(4,8,8,STAINED_GLASS:15)
B(5,8,8,STAINED_GLASS:15)
B(6,8,8,STAINED_GLASS:15)
B(0,8,9,STAINED_GLASS:9)
B(1,8,9,STAINED_GLASS:9)
B(2,8,9,STAINED_GLASS:15)
B(3,8,9,STAINED_GLASS:15)
B(4,8,9,STAINED_GLASS:15)
B(5,8,9,STAINED_GLASS:15)
B(6,8,9,STAINED_GLASS:15)
B(1,8,10,STAINED_GLASS:9)
B(2,8,10,STAINED_GLASS:15)
B(3,8,10,STAINED_GLASS:15)
B(4,8,10,STAINED_GLASS:15)
B(3,8,11,STAINED_GLASS:15)
B(0,9,0,SEA_LANTERN)
B(1,9,0,SEA_LANTERN)
B(2,9,0,STAINED_GLASS:10)
B(3,9,0,STAINED_GLASS:11)
B(0,9,1,SEA_LANTERN)
B(1,9,1,STAINED_GLASS:11)
B(2,9,1,STAINED_GLASS:10)
B(3,9,1,STAINED_GLASS:11)
B(0,9,2,SEA_LANTERN)
B(1,9,2,SEA_LANTERN)
B(2,9,2,STAINED_GLASS:10)
B(3,9,2,STAINED_GLASS:11)
B(0,9,3,STAINED_GLASS:9)
B(1,9,3,SEA_LANTERN)
B(2,9,3,STAINED_GLASS:10)
B(3,9,3,STAINED_GLASS:10)
B(4,9,3,STAINED_GLASS:11)
B(0,9,4,STAINED_GLASS:10)
B(1,9,4,STAINED_GLASS:15)
B(2,9,4,STAINED_GLASS:10)
B(3,9,4,STAINED_GLASS:11)
B(4,9,4,STAINED_GLASS:11)
B(0,9,5,STAINED_GLASS:9)
B(1,9,5,STAINED_GLASS:9)
B(2,9,5,STAINED_GLASS:10)
B(3,9,5,STAINED_GLASS:15)
B(4,9,5,STAINED_GLASS:11)
B(5,9,5,STAINED_GLASS:11)
B(0,9,6,STAINED_GLASS:9)
B(1,9,6,STAINED_GLASS:9)
B(2,9,6,STAINED_GLASS:10)
B(3,9,6,STAINED_GLASS:15)
B(4,9,6,STAINED_GLASS:11)
B(5,9,6,STAINED_GLASS:11)
B(0,9,7,STAINED_GLASS:10)
B(1,9,7,STAINED_GLASS:10)
B(2,9,7,STAINED_GLASS:10)
B(3,9,7,STAINED_GLASS:15)
B(4,9,7,STAINED_GLASS:15)
B(5,9,7,STAINED_GLASS:15)
B(6,9,7,STAINED_GLASS:11)
B(0,9,8,STAINED_GLASS:9)
B(1,9,8,STAINED_GLASS:10)
B(2,9,8,STAINED_GLASS:10)
B(3,9,8,STAINED_GLASS:15)
B(4,9,8,STAINED_GLASS:15)
B(0,9,9,STAINED_GLASS:10)
B(1,9,9,STAINED_GLASS:10)
B(2,9,9,STAINED_GLASS:15)
B(3,9,9,STAINED_GLASS:15)
B(0,10,0,SEA_LANTERN)
B(1,10,0,STAINED_GLASS:11)
B(2,10,0,STAINED_GLASS:11)
B(3,10,0,STAINED_GLASS:11)
B(0,10,1,STAINED_GLASS:15)
B(1,10,1,STAINED_GLASS:10)
B(2,10,1,STAINED_GLASS:11)
B(3,10,1,STAINED_GLASS:11)
B(0,10,2,STAINED_GLASS:9)
B(1,10,2,STAINED_GLASS:10)
B(2,10,2,STAINED_GLASS:10)
B(3,10,2,STAINED_GLASS:11)
B(0,10,3,STAINED_GLASS:10)
B(1,10,3,STAINED_GLASS:15)
B(2,10,3,STAINED_GLASS:11)
B(3,10,3,STAINED_GLASS:9)
B(4,10,3,STAINED_GLASS:11)
B(0,10,4,STAINED_GLASS:9)
B(1,10,4,STAINED_GLASS:9)
B(2,10,4,STAINED_GLASS:15)
B(3,10,4,STAINED_GLASS:11)
B(4,10,4,STAINED_GLASS:11)
B(0,10,5,STAINED_GLASS:9)
B(1,10,5,STAINED_GLASS:10)
B(2,10,5,STAINED_GLASS:10)
B(3,10,5,STAINED_GLASS:15)
B(4,10,5,STAINED_GLASS:11)
B(0,10,6,STAINED_GLASS:10)
B(1,10,6,STAINED_GLASS:10)
B(2,10,6,STAINED_GLASS:10)
B(3,10,6,STAINED_GLASS:15)
B(4,10,6,STAINED_GLASS:9)
B(0,10,7,STAINED_GLASS:10)
B(1,10,7,STAINED_GLASS:10)
B(0,11,0,STAINED_GLASS:15)
B(1,11,0,STAINED_GLASS:11)
B(2,11,0,STAINED_GLASS:11)
B(3,11,0,STAINED_GLASS:11)
B(0,11,1,STAINED_GLASS:9)
B(1,11,1,STAINED_GLASS:11)
B(2,11,1,STAINED_GLASS:11)
B(3,11,1,STAINED_GLASS:11)
B(0,11,2,STAINED_GLASS:10)
B(1,11,2,STAINED_GLASS:15)
B(2,11,2,STAINED_GLASS:11)
B(3,11,2,STAINED_GLASS:11)
B(0,11,3,STAINED_GLASS:10)
B(1,11,3,STAINED_GLASS:9)
B(2,11,3,STAINED_GLASS:15)
B(3,11,3,STAINED_GLASS:15)
B(4,11,3,STAINED_GLASS:9)
B(0,11,4,STAINED_GLASS:10)
B(1,11,4,STAINED_GLASS:15)
B(2,11,4,STAINED_GLASS:15)
B(0,11,5,STAINED_GLASS:10)
B(1,11,5,STAINED_GLASS:10)
B(0,12,0,STAINED_GLASS:9)
B(1,12,0,STAINED_GLASS:15)
B(2,12,0,STAINED_GLASS:11)
B(3,12,0,STAINED_GLASS:11)
B(0,12,1,STAINED_GLASS:15)
B(1,12,1,STAINED_GLASS:15)
B(2,12,1,STAINED_GLASS:15)
B(0,12,2,STAINED_GLASS:10)
B(1,12,2,STAINED_GLASS:15)
B(2,12,2,STAINED_GLASS:15)
B(0,12,3,STAINED_GLASS:10)
B(1,12,3,STAINED_GLASS:15)
B(0,13,0,STAINED_GLASS:15)
B(1,13,0,STAINED_GLASS:15)
B(2,13,0,STAINED_GLASS:9)

