#######################################################################
# +-----------------------------------------------------------------+ #
# |                            BO3 object                           | #
# +-----------------------------------------------------------------+ #
#######################################################################

Author: Bo3 BulkEdit

Description: Converted Schematic - Modified by Bo3BulkEdit

Version: 3

SettingsMode: WriteDisable

#######################################################################
# +-----------------------------------------------------------------+ #
# |                          Main settings                          | #
# +-----------------------------------------------------------------+ #
#######################################################################



Frequency: 0


SpawnHeight: randomY





##############################
# Height Limits for the BO3. #
##############################

MinHeight: 0
MaxHeight: 256

#######################################################################
# +-----------------------------------------------------------------+ #
# |                      Source block settings                      | #
# +-----------------------------------------------------------------+ #
#######################################################################

CanOverride: true
MaxPercentageOutsideSourceBlock: 100
OutsideSourceBlock: placeAnyway

#######################################################################
# +-----------------------------------------------------------------+ #
# |                               OTG+                              | #
# +-----------------------------------------------------------------+ #
#######################################################################

#######################################################################
# +-----------------------------------------------------------------+ #
# |                              Blocks                             | #
# +-----------------------------------------------------------------+ #
#######################################################################

B(0,750,0,AIR)
B(15,750,15,AIR)
B(7,-5,15,STAINED_GLASS:15)
B(8,-5,15,STAINED_GLASS:15)
B(6,-4,13,STAINED_GLASS:15)
B(7,-4,13,STAINED_GLASS:15)
B(6,-4,14,STAINED_GLASS:15)
B(7,-4,14,STAINED_GLASS:15)
B(8,-4,14,STAINED_GLASS:15)
B(6,-4,15,STAINED_GLASS:15)
B(7,-4,15,STAINED_GLASS:15)
B(8,-4,15,STAINED_GLASS:15)
B(4,-3,11,STAINED_GLASS:15)
B(4,-3,12,STAINED_GLASS:15)
B(5,-3,12,STAINED_GLASS:15)
B(6,-3,12,STAINED_GLASS:15)
B(7,-3,12,STAINED_GLASS:15)
B(4,-3,13,STAINED_GLASS:15)
B(5,-3,13,STAINED_GLASS:15)
B(6,-3,13,STAINED_GLASS:15)
B(7,-3,13,STAINED_GLASS:15)
B(8,-3,13,STAINED_GLASS:15)
B(5,-3,14,STAINED_GLASS:15)
B(6,-3,14,STAINED_GLASS:15)
B(7,-3,14,STAINED_GLASS:15)
B(8,-3,14,STAINED_GLASS:15)
B(5,-3,15,STAINED_GLASS:15)
B(6,-3,15,STAINED_GLASS:15)
B(7,-3,15,STAINED_GLASS:15)
B(8,-3,15,STAINED_GLASS:15)
B(3,-2,10,STAINED_GLASS:15)
B(4,-2,10,STAINED_GLASS:15)
B(5,-2,10,STAINED_GLASS:15)
B(6,-2,10,STAINED_GLASS:15)
B(3,-2,11,STAINED_GLASS:15)
B(4,-2,11,STAINED_GLASS:15)
B(5,-2,11,STAINED_GLASS:15)
B(6,-2,11,STAINED_GLASS:15)
B(3,-2,12,STAINED_GLASS:15)
B(4,-2,12,STAINED_GLASS:15)
B(5,-2,12,STAINED_GLASS:15)
B(6,-2,12,STAINED_GLASS:15)
B(7,-2,12,STAINED_GLASS:15)
B(8,-2,12,STAINED_GLASS:15)
B(3,-2,13,STAINED_GLASS:15)
B(4,-2,13,STAINED_GLASS:15)
B(5,-2,13,STAINED_GLASS:15)
B(6,-2,13,STAINED_GLASS:15)
B(7,-2,13,STAINED_GLASS:15)
B(8,-2,13,STAINED_GLASS:15)
B(4,-2,14,STAINED_GLASS:15)
B(5,-2,14,STAINED_GLASS:15)
B(6,-2,14,STAINED_GLASS:15)
B(7,-2,14,STAINED_GLASS:15)
B(8,-2,14,STAINED_GLASS:15)
B(4,-2,15,STAINED_GLASS:15)
B(5,-2,15,STAINED_GLASS:15)
B(6,-2,15,STAINED_GLASS:15)
B(7,-2,15,STAINED_GLASS:15)
B(8,-2,15,STAINED_GLASS:15)
B(3,-1,8,STAINED_GLASS:15)
B(4,-1,8,STAINED_GLASS:15)
B(5,-1,8,STAINED_GLASS:15)
B(2,-1,9,STAINED_GLASS:15)
B(3,-1,9,STAINED_GLASS:15)
B(4,-1,9,STAINED_GLASS:15)
B(5,-1,9,STAINED_GLASS:15)
B(6,-1,9,STAINED_GLASS:15)
B(1,-1,10,STAINED_GLASS:15)
B(2,-1,10,STAINED_GLASS:15)
B(3,-1,10,STAINED_GLASS:15)
B(4,-1,10,STAINED_GLASS:15)
B(5,-1,10,STAINED_GLASS:15)
B(6,-1,10,STAINED_GLASS:15)
B(7,-1,10,STAINED_GLASS:15)
B(0,-1,11,STAINED_GLASS:15)
B(1,-1,11,STAINED_GLASS:15)
B(2,-1,11,STAINED_GLASS:15)
B(3,-1,11,STAINED_GLASS:15)
B(4,-1,11,STAINED_GLASS:15)
B(5,-1,11,STAINED_GLASS:15)
B(6,-1,11,STAINED_GLASS:15)
B(7,-1,11,STAINED_GLASS:15)
B(8,-1,11,STAINED_GLASS:15)
B(2,-1,12,STAINED_GLASS:15)
B(3,-1,12,STAINED_GLASS:15)
B(4,-1,12,STAINED_GLASS:15)
B(5,-1,12,STAINED_GLASS:15)
B(6,-1,12,STAINED_GLASS:15)
B(7,-1,12,STAINED_GLASS:15)
B(8,-1,12,STAINED_GLASS:15)
B(2,-1,13,STAINED_GLASS:15)
B(3,-1,13,STAINED_GLASS:15)
B(4,-1,13,STAINED_GLASS:15)
B(5,-1,13,STAINED_GLASS:15)
B(6,-1,13,STAINED_GLASS:15)
B(8,-1,13,STAINED_GLASS:15)
B(3,-1,14,STAINED_GLASS:15)
B(4,-1,14,STAINED_GLASS:15)
B(5,-1,14,STAINED_GLASS:9)
B(6,-1,14,STAINED_GLASS:15)
B(7,-1,14,STAINED_GLASS:15)
B(3,-1,15,STAINED_GLASS:15)
B(4,-1,15,STAINED_GLASS:15)
B(5,-1,15,STAINED_GLASS:15)
B(6,-1,15,STAINED_GLASS:15)
B(7,-1,15,STAINED_GLASS:15)
B(3,0,6,STAINED_GLASS:15)
B(2,0,7,STAINED_GLASS:15)
B(3,0,7,STAINED_GLASS:15)
B(4,0,7,STAINED_GLASS:15)
B(1,0,8,STAINED_GLASS:15)
B(2,0,8,STAINED_GLASS:15)
B(3,0,8,STAINED_GLASS:15)
B(4,0,8,STAINED_GLASS:15)
B(5,0,8,STAINED_GLASS:15)
B(0,0,9,STAINED_GLASS:15)
B(1,0,9,STAINED_GLASS:15)
B(2,0,9,STAINED_GLASS:15)
B(3,0,9,STAINED_GLASS:15)
B(4,0,9,STAINED_GLASS:15)
B(5,0,9,STAINED_GLASS:15)
B(6,0,9,STAINED_GLASS:15)
B(0,0,10,STAINED_GLASS:15)
B(1,0,10,STAINED_GLASS:15)
B(2,0,10,STAINED_GLASS:15)
B(3,0,10,STAINED_GLASS:15)
B(4,0,10,STAINED_GLASS:15)
B(5,0,10,STAINED_GLASS:15)
B(6,0,10,STAINED_GLASS:14)
B(7,0,10,STAINED_GLASS:15)
B(0,0,11,STAINED_GLASS:15)
B(1,0,11,STAINED_GLASS:15)
B(2,0,11,STAINED_GLASS:9)
B(3,0,11,STAINED_GLASS:15)
B(5,0,11,STAINED_GLASS:15)
B(6,0,11,SEA_LANTERN)
B(7,0,11,STAINED_GLASS:15)
B(8,0,11,STAINED_GLASS:15)
B(1,0,12,STAINED_GLASS:15)
B(2,0,12,STAINED_GLASS:15)
B(3,0,12,SEA_LANTERN)
B(4,0,12,STAINED_GLASS:15)
B(5,0,12,STAINED_GLASS:15)
B(6,0,12,STAINED_GLASS:9)
B(7,0,12,STAINED_GLASS:11)
B(8,0,12,STAINED_GLASS:15)
B(2,0,13,STAINED_GLASS:15)
B(3,0,13,STAINED_GLASS:15)
B(4,0,13,STAINED_GLASS:9)
B(5,0,13,SEA_LANTERN)
B(6,0,13,STAINED_GLASS:15)
B(7,0,13,STAINED_GLASS:15)
B(3,0,14,STAINED_GLASS:15)
B(4,0,14,STAINED_GLASS:9)
B(5,0,14,STAINED_GLASS:15)
B(6,0,14,STAINED_GLASS:9)
B(7,0,14,STAINED_GLASS:15)
B(3,0,15,STAINED_GLASS:15)
B(4,0,15,STAINED_GLASS:15)
B(5,0,15,STAINED_GLASS:15)
B(6,0,15,STAINED_GLASS:15)
B(7,0,15,STAINED_GLASS:15)
B(2,1,6,STAINED_GLASS:15)
B(3,1,6,STAINED_GLASS:15)
B(1,1,7,STAINED_GLASS:15)
B(2,1,7,STAINED_GLASS:15)
B(3,1,7,STAINED_GLASS:15)
B(4,1,7,STAINED_GLASS:15)
B(0,1,8,STAINED_GLASS:15)
B(1,1,8,STAINED_GLASS:15)
B(2,1,8,STAINED_GLASS:9)
B(3,1,8,STAINED_GLASS:15)
B(4,1,8,STAINED_GLASS:15)
B(5,1,8,STAINED_GLASS:15)
B(0,1,9,STAINED_GLASS:15)
B(1,1,9,STAINED_GLASS:15)
B(2,1,9,STAINED_GLASS:15)
B(3,1,9,STAINED_GLASS:15)
B(4,1,9,STAINED_GLASS:14)
B(5,1,9,STAINED_GLASS:15)
B(6,1,9,STAINED_GLASS:15)
B(0,1,10,STAINED_GLASS:15)
B(1,1,10,STAINED_GLASS:15)
B(2,1,10,STAINED_GLASS:9)
B(3,1,10,SEA_LANTERN)
B(4,1,10,STAINED_GLASS:9)
B(5,1,10,SEA_LANTERN)
B(6,1,10,STAINED_GLASS:14)
B(7,1,10,STAINED_GLASS:15)
B(0,1,11,STAINED_GLASS:15)
B(1,1,11,STAINED_GLASS:15)
B(2,1,11,SEA_LANTERN)
B(3,1,11,SEA_LANTERN)
B(4,1,11,SEA_LANTERN)
B(5,1,11,STAINED_GLASS:14)
B(6,1,11,STAINED_GLASS:14)
B(7,1,11,STAINED_GLASS:15)
B(8,1,11,STAINED_GLASS:11)
B(1,1,12,STAINED_GLASS:15)
B(2,1,12,STAINED_GLASS:9)
B(3,1,12,SEA_LANTERN)
B(4,1,12,SEA_LANTERN)
B(5,1,12,STAINED_GLASS:9)
B(6,1,12,STAINED_GLASS:15)
B(7,1,12,STAINED_GLASS:11)
B(8,1,12,STAINED_GLASS:11)
B(2,1,13,STAINED_GLASS:15)
B(3,1,13,STAINED_GLASS:9)
B(4,1,13,STAINED_GLASS:9)
B(5,1,13,STAINED_GLASS:9)
B(6,1,13,STAINED_GLASS:15)
B(7,1,13,STAINED_GLASS:15)
B(8,1,13,STAINED_GLASS:11)
B(3,1,14,STAINED_GLASS:15)
B(4,1,14,STAINED_GLASS:2)
B(5,1,14,STAINED_GLASS:2)
B(6,1,14,STAINED_GLASS:2)
B(7,1,14,STAINED_GLASS:15)
B(3,1,15,STAINED_GLASS:2)
B(4,1,15,STAINED_GLASS:2)
B(5,1,15,STAINED_GLASS:2)
B(6,1,15,STAINED_GLASS:15)
B(1,2,5,STAINED_GLASS:15)
B(2,2,5,STAINED_GLASS:15)
B(3,2,5,STAINED_GLASS:15)
B(0,2,6,STAINED_GLASS:15)
B(1,2,6,STAINED_GLASS:15)
B(2,2,6,STAINED_GLASS:15)
B(3,2,6,STAINED_GLASS:15)
B(0,2,7,STAINED_GLASS:15)
B(1,2,7,STAINED_GLASS:9)
B(2,2,7,STAINED_GLASS:15)
B(3,2,7,STAINED_GLASS:14)
B(4,2,7,STAINED_GLASS:15)
B(0,2,8,STAINED_GLASS:15)
B(1,2,8,STAINED_GLASS:15)
B(2,2,8,SEA_LANTERN)
B(3,2,8,STAINED_GLASS:14)
B(4,2,8,STAINED_GLASS:15)
B(5,2,8,STAINED_GLASS:15)
B(0,2,9,STAINED_GLASS:15)
B(1,2,9,STAINED_GLASS:9)
B(2,2,9,STAINED_GLASS:9)
B(3,2,9,STAINED_GLASS:14)
B(4,2,9,SEA_LANTERN)
B(5,2,9,STAINED_GLASS:14)
B(6,2,9,STAINED_GLASS:15)
B(0,2,10,STAINED_GLASS:15)
B(1,2,10,STAINED_GLASS:15)
B(2,2,10,SEA_LANTERN)
B(3,2,10,SEA_LANTERN)
B(4,2,10,SEA_LANTERN)
B(5,2,10,STAINED_GLASS:14)
B(6,2,10,STAINED_GLASS:15)
B(7,2,10,STAINED_GLASS:15)
B(0,2,11,STAINED_GLASS:15)
B(1,2,11,STAINED_GLASS:9)
B(2,2,11,STAINED_GLASS:9)
B(3,2,11,SEA_LANTERN)
B(4,2,11,STAINED_GLASS:14)
B(5,2,11,STAINED_GLASS:15)
B(6,2,11,STAINED_GLASS:15)
B(7,2,11,STAINED_GLASS:15)
B(8,2,11,STAINED_GLASS:15)
B(1,2,12,STAINED_GLASS:15)
B(2,2,12,STAINED_GLASS:2)
B(3,2,12,STAINED_GLASS:9)
B(4,2,12,STAINED_GLASS:9)
B(5,2,12,STAINED_GLASS:15)
B(6,2,12,STAINED_GLASS:15)
B(7,2,12,STAINED_GLASS:11)
B(2,2,13,STAINED_GLASS:2)
B(3,2,13,STAINED_GLASS:2)
B(4,2,13,STAINED_GLASS:15)
B(5,2,13,STAINED_GLASS:15)
B(6,2,13,STAINED_GLASS:15)
B(3,2,14,STAINED_GLASS:2)
B(4,2,14,STAINED_GLASS:2)
B(5,2,14,STAINED_GLASS:2)
B(3,2,15,STAINED_GLASS:2)
B(4,2,15,STAINED_GLASS:2)
B(2,3,4,STAINED_GLASS:15)
B(3,3,4,STAINED_GLASS:15)
B(0,3,5,STAINED_GLASS:15)
B(1,3,5,STAINED_GLASS:15)
B(2,3,5,STAINED_GLASS:15)
B(3,3,5,STAINED_GLASS:15)
B(0,3,6,STAINED_GLASS:15)
B(1,3,6,STAINED_GLASS:15)
B(2,3,6,STAINED_GLASS:15)
B(3,3,6,STAINED_GLASS:15)
B(0,3,7,STAINED_GLASS:15)
B(1,3,7,STAINED_GLASS:9)
B(2,3,7,STAINED_GLASS:9)
B(3,3,7,STAINED_GLASS:14)
B(4,3,7,STAINED_GLASS:15)
B(0,3,8,STAINED_GLASS:15)
B(1,3,8,STAINED_GLASS:9)
B(2,3,8,SEA_LANTERN)
B(3,3,8,SEA_LANTERN)
B(4,3,8,STAINED_GLASS:14)
B(5,3,8,STAINED_GLASS:15)
B(0,3,9,STAINED_GLASS:15)
B(1,3,9,STAINED_GLASS:9)
B(2,3,9,SEA_LANTERN)
B(3,3,9,SEA_LANTERN)
B(4,3,9,SEA_LANTERN)
B(5,3,9,STAINED_GLASS:15)
B(6,3,9,STAINED_GLASS:15)
B(0,3,10,STAINED_GLASS:15)
B(1,3,10,STAINED_GLASS:9)
B(2,3,10,SEA_LANTERN)
B(3,3,10,SEA_LANTERN)
B(4,3,10,STAINED_GLASS:14)
B(5,3,10,STAINED_GLASS:14)
B(6,3,10,STAINED_GLASS:15)
B(7,3,10,STAINED_GLASS:15)
B(0,3,11,STAINED_GLASS:15)
B(1,3,11,STAINED_GLASS:2)
B(2,3,11,STAINED_GLASS:9)
B(3,3,11,SEA_LANTERN)
B(4,3,11,STAINED_GLASS:15)
B(5,3,11,STAINED_GLASS:15)
B(6,3,11,STAINED_GLASS:15)
B(7,3,11,STAINED_GLASS:15)
B(1,3,12,STAINED_GLASS:2)
B(2,3,12,STAINED_GLASS:2)
B(3,3,12,STAINED_GLASS:15)
B(4,3,12,STAINED_GLASS:9)
B(5,3,12,STAINED_GLASS:15)
B(6,3,12,STAINED_GLASS:15)
B(2,3,13,STAINED_GLASS:2)
B(3,3,13,STAINED_GLASS:2)
B(4,3,13,STAINED_GLASS:2)
B(5,3,13,STAINED_GLASS:15)
B(3,3,14,STAINED_GLASS:2)
B(4,3,14,STAINED_GLASS:2)
B(1,4,4,STAINED_GLASS:15)
B(2,4,4,STAINED_GLASS:15)
B(3,4,4,STAINED_GLASS:15)
B(0,4,5,STAINED_GLASS:15)
B(1,4,5,STAINED_GLASS:15)
B(2,4,5,STAINED_GLASS:15)
B(3,4,5,STAINED_GLASS:15)
B(0,4,6,STAINED_GLASS:9)
B(1,4,6,STAINED_GLASS:15)
B(2,4,6,STAINED_GLASS:9)
B(3,4,6,STAINED_GLASS:15)
B(0,4,7,STAINED_GLASS:15)
B(1,4,7,SEA_LANTERN)
B(2,4,7,STAINED_GLASS:9)
B(3,4,7,SEA_LANTERN)
B(4,4,7,STAINED_GLASS:15)
B(0,4,8,STAINED_GLASS:9)
B(1,4,8,STAINED_GLASS:9)
B(2,4,8,SEA_LANTERN)
B(3,4,8,SEA_LANTERN)
B(4,4,8,STAINED_GLASS:14)
B(5,4,8,STAINED_GLASS:15)
B(0,4,9,STAINED_GLASS:2)
B(1,4,9,SEA_LANTERN)
B(2,4,9,SEA_LANTERN)
B(3,4,9,SEA_LANTERN)
B(4,4,9,STAINED_GLASS:14)
B(5,4,9,STAINED_GLASS:15)
B(6,4,9,STAINED_GLASS:15)
B(0,4,10,STAINED_GLASS:2)
B(1,4,10,STAINED_GLASS:9)
B(2,4,10,STAINED_GLASS:9)
B(3,4,10,SEA_LANTERN)
B(4,4,10,STAINED_GLASS:14)
B(5,4,10,STAINED_GLASS:15)
B(6,4,10,STAINED_GLASS:15)
B(7,4,10,STAINED_GLASS:15)
B(0,4,11,STAINED_GLASS:2)
B(1,4,11,STAINED_GLASS:2)
B(2,4,11,STAINED_GLASS:2)
B(3,4,11,STAINED_GLASS:9)
B(4,4,11,STAINED_GLASS:15)
B(5,4,11,STAINED_GLASS:15)
B(6,4,11,STAINED_GLASS:15)
B(7,4,11,STAINED_GLASS:15)
B(1,4,12,STAINED_GLASS:2)
B(2,4,12,STAINED_GLASS:2)
B(3,4,12,STAINED_GLASS:15)
B(4,4,12,STAINED_GLASS:15)
B(5,4,12,STAINED_GLASS:15)
B(2,4,13,STAINED_GLASS:2)
B(3,4,13,STAINED_GLASS:2)
B(4,4,13,STAINED_GLASS:15)
B(3,4,14,STAINED_GLASS:2)
B(0,5,3,STAINED_GLASS:15)
B(1,5,3,STAINED_GLASS:15)
B(2,5,3,STAINED_GLASS:15)
B(0,5,4,STAINED_GLASS:15)
B(1,5,4,STAINED_GLASS:15)
B(2,5,4,STAINED_GLASS:15)
B(3,5,4,STAINED_GLASS:15)
B(0,5,5,STAINED_GLASS:15)
B(1,5,5,STAINED_GLASS:9)
B(2,5,5,STAINED_GLASS:15)
B(3,5,5,STAINED_GLASS:15)
B(0,5,6,SEA_LANTERN)
B(1,5,6,STAINED_GLASS:9)
B(2,5,6,SEA_LANTERN)
B(3,5,6,STAINED_GLASS:14)
B(0,5,7,STAINED_GLASS:9)
B(1,5,7,SEA_LANTERN)
B(2,5,7,SEA_LANTERN)
B(3,5,7,STAINED_GLASS:14)
B(4,5,7,STAINED_GLASS:15)
B(0,5,8,SEA_LANTERN)
B(1,5,8,SEA_LANTERN)
B(2,5,8,SEA_LANTERN)
B(3,5,8,STAINED_GLASS:14)
B(4,5,8,STAINED_GLASS:15)
B(5,5,8,STAINED_GLASS:15)
B(0,5,9,STAINED_GLASS:9)
B(1,5,9,STAINED_GLASS:9)
B(2,5,9,STAINED_GLASS:9)
B(3,5,9,STAINED_GLASS:14)
B(4,5,9,STAINED_GLASS:15)
B(5,5,9,STAINED_GLASS:15)
B(6,5,9,STAINED_GLASS:15)
B(0,5,10,STAINED_GLASS:2)
B(1,5,10,STAINED_GLASS:2)
B(2,5,10,STAINED_GLASS:2)
B(3,5,10,STAINED_GLASS:9)
B(4,5,10,STAINED_GLASS:15)
B(5,5,10,STAINED_GLASS:15)
B(6,5,10,STAINED_GLASS:15)
B(0,5,11,STAINED_GLASS:2)
B(1,5,11,STAINED_GLASS:2)
B(2,5,11,STAINED_GLASS:15)
B(3,5,11,STAINED_GLASS:15)
B(4,5,11,STAINED_GLASS:15)
B(1,5,12,STAINED_GLASS:2)
B(2,5,12,STAINED_GLASS:2)
B(3,5,12,STAINED_GLASS:15)
B(0,6,2,STAINED_GLASS:15)
B(1,6,2,STAINED_GLASS:15)
B(0,6,3,STAINED_GLASS:15)
B(1,6,3,STAINED_GLASS:15)
B(2,6,3,STAINED_GLASS:15)
B(0,6,4,STAINED_GLASS:15)
B(1,6,4,STAINED_GLASS:15)
B(2,6,4,STAINED_GLASS:15)
B(3,6,4,STAINED_GLASS:15)
B(0,6,5,STAINED_GLASS:9)
B(1,6,5,STAINED_GLASS:9)
B(2,6,5,STAINED_GLASS:9)
B(3,6,5,STAINED_GLASS:9)
B(0,6,6,SEA_LANTERN)
B(1,6,6,SEA_LANTERN)
B(2,6,6,SEA_LANTERN)
B(3,6,6,STAINED_GLASS:15)
B(0,6,7,SEA_LANTERN)
B(1,6,7,SEA_LANTERN)
B(2,6,7,STAINED_GLASS:9)
B(3,6,7,STAINED_GLASS:14)
B(4,6,7,STAINED_GLASS:15)
B(0,6,8,SEA_LANTERN)
B(1,6,8,STAINED_GLASS:9)
B(2,6,8,SEA_LANTERN)
B(3,6,8,STAINED_GLASS:15)
B(4,6,8,STAINED_GLASS:15)
B(5,6,8,STAINED_GLASS:15)
B(0,6,9,STAINED_GLASS:2)
B(1,6,9,STAINED_GLASS:9)
B(2,6,9,STAINED_GLASS:15)
B(3,6,9,STAINED_GLASS:15)
B(4,6,9,STAINED_GLASS:15)
B(5,6,9,STAINED_GLASS:15)
B(0,6,10,STAINED_GLASS:2)
B(1,6,10,STAINED_GLASS:2)
B(2,6,10,STAINED_GLASS:15)
B(3,6,10,STAINED_GLASS:9)
B(4,6,10,STAINED_GLASS:15)
B(5,6,10,STAINED_GLASS:15)
B(0,6,11,STAINED_GLASS:2)
B(1,6,11,STAINED_GLASS:2)
B(2,6,11,STAINED_GLASS:15)
B(3,6,11,STAINED_GLASS:15)
B(0,7,1,STAINED_GLASS:15)
B(0,7,2,STAINED_GLASS:15)
B(1,7,2,STAINED_GLASS:15)
B(0,7,3,STAINED_GLASS:15)
B(1,7,3,STAINED_GLASS:15)
B(2,7,3,STAINED_GLASS:15)
B(0,7,4,STAINED_GLASS:9)
B(1,7,4,STAINED_GLASS:9)
B(2,7,4,STAINED_GLASS:9)
B(3,7,4,STAINED_GLASS:15)
B(0,7,5,SEA_LANTERN)
B(1,7,5,SEA_LANTERN)
B(2,7,5,STAINED_GLASS:15)
B(3,7,5,STAINED_GLASS:15)
B(0,7,6,SEA_LANTERN)
B(1,7,6,STAINED_GLASS:9)
B(2,7,6,STAINED_GLASS:14)
B(3,7,6,STAINED_GLASS:15)
B(0,7,7,STAINED_GLASS:9)
B(1,7,7,SEA_LANTERN)
B(2,7,7,STAINED_GLASS:15)
B(3,7,7,STAINED_GLASS:15)
B(4,7,7,STAINED_GLASS:15)
B(0,7,8,STAINED_GLASS:9)
B(1,7,8,STAINED_GLASS:15)
B(2,7,8,STAINED_GLASS:9)
B(3,7,8,STAINED_GLASS:15)
B(4,7,8,STAINED_GLASS:15)
B(0,7,9,STAINED_GLASS:15)
B(1,7,9,STAINED_GLASS:15)
B(2,7,9,STAINED_GLASS:15)
B(3,7,9,STAINED_GLASS:15)
B(4,7,9,STAINED_GLASS:15)
B(0,7,10,STAINED_GLASS:15)
B(1,7,10,STAINED_GLASS:15)
B(2,7,10,STAINED_GLASS:15)
B(3,7,10,STAINED_GLASS:15)
B(0,8,1,STAINED_GLASS:15)
B(0,8,2,STAINED_GLASS:15)
B(1,8,2,STAINED_GLASS:15)
B(0,8,3,STAINED_GLASS:9)
B(1,8,3,STAINED_GLASS:15)
B(2,8,3,STAINED_GLASS:15)
B(0,8,4,STAINED_GLASS:9)
B(1,8,4,SEA_LANTERN)
B(2,8,4,STAINED_GLASS:9)
B(3,8,4,STAINED_GLASS:15)
B(0,8,5,SEA_LANTERN)
B(1,8,5,STAINED_GLASS:14)
B(2,8,5,STAINED_GLASS:15)
B(3,8,5,STAINED_GLASS:15)
B(0,8,6,SEA_LANTERN)
B(1,8,6,STAINED_GLASS:14)
B(2,8,6,STAINED_GLASS:15)
B(3,8,6,STAINED_GLASS:15)
B(0,8,7,STAINED_GLASS:9)
B(1,8,7,STAINED_GLASS:14)
B(2,8,7,STAINED_GLASS:15)
B(3,8,7,STAINED_GLASS:15)
B(4,8,7,STAINED_GLASS:15)
B(0,8,8,STAINED_GLASS:15)
B(1,8,8,STAINED_GLASS:15)
B(2,8,8,STAINED_GLASS:15)
B(3,8,8,STAINED_GLASS:15)
B(4,8,8,STAINED_GLASS:15)
B(0,8,9,STAINED_GLASS:15)
B(1,8,9,STAINED_GLASS:15)
B(2,8,9,STAINED_GLASS:15)
B(3,8,9,STAINED_GLASS:15)
B(0,8,10,STAINED_GLASS:15)
B(1,8,10,STAINED_GLASS:15)
B(0,9,1,STAINED_GLASS:15)
B(0,9,2,STAINED_GLASS:15)
B(1,9,2,STAINED_GLASS:15)
B(0,9,3,STAINED_GLASS:9)
B(1,9,3,STAINED_GLASS:9)
B(2,9,3,STAINED_GLASS:15)
B(0,9,4,SEA_LANTERN)
B(1,9,4,SEA_LANTERN)
B(2,9,4,STAINED_GLASS:15)
B(3,9,4,STAINED_GLASS:15)
B(0,9,5,STAINED_GLASS:9)
B(1,9,5,STAINED_GLASS:14)
B(2,9,5,STAINED_GLASS:15)
B(3,9,5,STAINED_GLASS:15)
B(0,9,6,SEA_LANTERN)
B(1,9,6,STAINED_GLASS:15)
B(2,9,6,STAINED_GLASS:15)
B(3,9,6,STAINED_GLASS:15)
B(0,9,7,STAINED_GLASS:15)
B(1,9,7,STAINED_GLASS:14)
B(2,9,7,STAINED_GLASS:15)
B(3,9,7,STAINED_GLASS:15)
B(0,9,8,STAINED_GLASS:15)
B(1,9,8,STAINED_GLASS:15)
B(2,9,8,STAINED_GLASS:15)
B(0,9,9,STAINED_GLASS:15)
B(1,9,9,STAINED_GLASS:15)
B(0,10,1,STAINED_GLASS:15)
B(0,10,2,STAINED_GLASS:9)
B(1,10,2,STAINED_GLASS:15)
B(0,10,3,SEA_LANTERN)
B(1,10,3,STAINED_GLASS:15)
B(2,10,3,STAINED_GLASS:15)
B(0,10,4,STAINED_GLASS:14)
B(1,10,4,STAINED_GLASS:14)
B(2,10,4,STAINED_GLASS:15)
B(3,10,4,STAINED_GLASS:15)
B(0,10,5,STAINED_GLASS:15)
B(1,10,5,STAINED_GLASS:15)
B(2,10,5,STAINED_GLASS:15)
B(3,10,5,STAINED_GLASS:15)
B(0,10,6,STAINED_GLASS:14)
B(1,10,6,STAINED_GLASS:15)
B(2,10,6,STAINED_GLASS:15)
B(0,10,7,STAINED_GLASS:15)
B(1,10,7,STAINED_GLASS:15)
B(0,10,8,STAINED_GLASS:15)
B(0,11,1,STAINED_GLASS:15)
B(0,11,2,STAINED_GLASS:9)
B(1,11,2,STAINED_GLASS:15)
B(0,11,3,STAINED_GLASS:14)
B(1,11,3,STAINED_GLASS:15)
B(2,11,3,STAINED_GLASS:15)
B(0,11,4,STAINED_GLASS:14)
B(1,11,4,STAINED_GLASS:15)
B(2,11,4,STAINED_GLASS:15)
B(3,11,4,STAINED_GLASS:15)
B(0,11,5,STAINED_GLASS:15)
B(1,11,5,STAINED_GLASS:15)
B(2,11,5,STAINED_GLASS:15)
B(3,11,5,STAINED_GLASS:15)
B(0,11,6,STAINED_GLASS:15)
B(1,11,6,STAINED_GLASS:15)
B(0,11,7,STAINED_GLASS:15)
B(0,12,1,STAINED_GLASS:15)
B(0,12,2,STAINED_GLASS:15)
B(1,12,2,STAINED_GLASS:15)
B(0,12,3,STAINED_GLASS:15)
B(1,12,3,STAINED_GLASS:15)
B(2,12,3,STAINED_GLASS:15)
B(0,12,4,STAINED_GLASS:15)
B(1,12,4,STAINED_GLASS:15)
B(2,12,4,STAINED_GLASS:15)
B(0,12,5,STAINED_GLASS:15)
B(0,13,1,STAINED_GLASS:15)
B(0,13,2,STAINED_GLASS:15)
B(1,13,2,STAINED_GLASS:15)
B(0,13,3,STAINED_GLASS:15)
B(1,13,3,STAINED_GLASS:15)
B(0,13,4,STAINED_GLASS:15)
B(1,13,4,STAINED_GLASS:15)
B(0,14,1,STAINED_GLASS:15)
B(0,14,2,STAINED_GLASS:15)
B(0,14,3,STAINED_GLASS:15)
B(0,15,1,STAINED_GLASS:15)
B(0,15,2,STAINED_GLASS:15)

#######################################################################
# +-----------------------------------------------------------------+ #
# |                             Branches                            | #
# +-----------------------------------------------------------------+ #
#######################################################################

BR(0,0,16,true,SPIKE-SET-FAT-BIG-06_1x2,NORTH,100,0)
BR(-16,0,0,true,SPIKE-SET-FAT-BIG-06_0x1,NORTH,100,0)
BR(0,0,-16,true,SPIKE-SET-FAT-BIG-06_1x0,NORTH,100,0)
