
#
# +-----------------------------------------------------------------+ #
# |                            BO3 object                           | #
# +-----------------------------------------------------------------+ #
#

Author: NLBlackEagle

Description: No description given

Version: 3

SettingsMode: WriteDisable


#
# +-----------------------------------------------------------------+ #
# |                          Main settings                          | #
# +-----------------------------------------------------------------+ #
#

Tree: true

Frequency: 1

Rarity: 10.0

RotateRandomly: true

SpawnHeight: highestSolidBlock

SpawnHeightOffset: 0

SpawnHeightVariance: 0


# Height Limits for the BO3. #


MinHeight: 0

MaxHeight: 256


# Extrusion settings #


ExtrudeMode: None

ExtrudeThroughBlocks: air

MaxBranchDepth: 10

ExcludedBiomes: All


#
# +-----------------------------------------------------------------+ #
# |                      Source block settings                      | #
# +-----------------------------------------------------------------+ #
#

SourceBlocks: AIR,GRASS,STONE,DIRT

MaxPercentageOutsideSourceBlock: 0

OutsideSourceBlock: placeAnyway


#
# +-----------------------------------------------------------------+ #
# |                              Blocks                             | #
# +-----------------------------------------------------------------+ #
#

B(-6,-1,0,stone)
B(-6,-1,1,stone)
B(-6,-1,2,stone)
B(-6,0,0,stone)
B(-6,0,1,stone)
B(-6,0,2,grass)
B(-6,1,0,grass)
B(-6,1,1,gravel)
B(-6,1,2,tallgrass:1)
B(-6,2,0,tallgrass:1)
B(-5,-2,0,stone)
B(-5,-2,1,stone)
B(-5,-2,2,stone)
B(-5,-1,-1,stone)
B(-5,-1,0,stone)
B(-5,-1,1,stone)
B(-5,-1,2,stone)
B(-5,-1,3,stone)
B(-5,0,-1,stone)
B(-5,0,0,stone)
B(-5,0,1,stone)
B(-5,0,2,stone)
B(-5,0,3,grass)
B(-5,1,-1,grass)
B(-5,1,0,stone)
B(-5,1,1,stone)
B(-5,1,2,gravel)
B(-5,1,3,tallgrass:1)
B(-5,2,-1,tallgrass:1)
B(-5,2,0,gravel)
B(-5,2,1,leaves)
B(-5,2,2,leaves)
B(-4,-2,0,stone)
B(-4,-2,1,stone)
B(-4,-2,2,stone)
B(-4,-1,-2,stone)
B(-4,-1,-1,stone)
B(-4,-1,0,stone)
B(-4,-1,1,stone)
B(-4,-1,2,stone)
B(-4,-1,3,stone)
B(-4,0,-2,stone)
B(-4,0,-1,stone)
B(-4,0,0,stone)
B(-4,0,1,stone)
B(-4,0,2,stone)
B(-4,0,3,stone)
B(-4,1,-2,stone)
B(-4,1,-1,stone)
B(-4,1,0,stone)
B(-4,1,1,stone)
B(-4,1,2,stone)
B(-4,1,3,leaves)
B(-4,2,-2,gravel)
B(-4,2,-1,stone)
B(-4,2,0,stone)
B(-4,2,1,grass)
B(-4,2,2,gravel)
B(-4,2,3,leaves)
B(-4,3,1,tallgrass:1)
B(-3,-3,1,stone)
B(-3,-3,2,stone)
B(-3,-2,-2,stone)
B(-3,-2,-1,stone)
B(-3,-2,0,stone)
B(-3,-2,1,stone)
B(-3,-2,2,stone)
B(-3,-1,-4,stone)
B(-3,-1,-3,stone)
B(-3,-1,-2,stone)
B(-3,-1,-1,stone)
B(-3,-1,0,stone)
B(-3,-1,1,stone)
B(-3,-1,2,stone)
B(-3,-1,3,stone)
B(-3,0,-4,stone)
B(-3,0,-3,stone)
B(-3,0,-2,stone)
B(-3,0,-1,stone)
B(-3,0,0,stone)
B(-3,0,1,stone)
B(-3,0,2,stone)
B(-3,0,3,stone)
B(-3,1,-4,leaves)
B(-3,1,-3,stone)
B(-3,1,-2,stone)
B(-3,1,-1,stone)
B(-3,1,0,stone)
B(-3,1,1,stone)
B(-3,1,2,stone)
B(-3,1,3,stone)
B(-3,2,-3,leaves)
B(-3,2,-2,stone)
B(-3,2,-1,stone)
B(-3,2,0,stone)
B(-3,2,1,stone)
B(-3,2,2,grass)
B(-3,2,3,gravel)
B(-3,3,-2,leaves)
B(-3,3,-1,leaves)
B(-3,3,0,grass)
B(-3,3,2,tallgrass:1)
B(-2,-3,0,stone)
B(-2,-3,1,stone)
B(-2,-3,2,stone)
B(-2,-2,-4,stone)
B(-2,-2,-3,stone)
B(-2,-2,-2,stone)
B(-2,-2,-1,stone)
B(-2,-2,0,stone)
B(-2,-2,1,stone)
B(-2,-2,2,stone)
B(-2,-2,3,stone)
B(-2,-1,-5,stone)
B(-2,-1,-4,stone)
B(-2,-1,-3,stone)
B(-2,-1,-2,stone)
B(-2,-1,-1,stone)
B(-2,-1,0,stone)
B(-2,-1,1,stone)
B(-2,-1,2,stone)
B(-2,-1,3,stone)
B(-2,0,-5,stone)
B(-2,0,-4,stone)
B(-2,0,-3,stone)
B(-2,0,-2,stone)
B(-2,0,-1,stone)
B(-2,0,0,stone)
B(-2,0,1,stone)
B(-2,0,2,stone)
B(-2,0,3,stone)
B(-2,0,4,leaves)
B(-2,1,-5,grass)
B(-2,1,-4,stone)
B(-2,1,-3,stone)
B(-2,1,-2,stone)
B(-2,1,-1,stone)
B(-2,1,0,stone)
B(-2,1,1,stone)
B(-2,1,2,stone)
B(-2,1,3,stone)
B(-2,1,4,leaves)
B(-2,2,-5,tallgrass:1)
B(-2,2,-3,stone)
B(-2,2,-2,stone)
B(-2,2,-1,stone)
B(-2,2,0,stone)
B(-2,2,1,stone)
B(-2,2,2,stone)
B(-2,2,3,grass)
B(-2,3,-3,gravel)
B(-2,3,-2,grass)
B(-2,3,-1,stone)
B(-2,3,0,grass)
B(-2,3,1,gravel)
B(-2,3,3,double_plant:3)
B(-2,4,-2,tallgrass:2)
B(-2,4,-1,leaves)
B(-2,4,3,double_plant:10)
B(-1,-4,1,stone)
B(-1,-4,2,stone)
B(-1,-3,0,stone)
B(-1,-3,1,stone)
B(-1,-3,2,stone)
B(-1,-3,3,stone)
B(-1,-2,-4,stone)
B(-1,-2,-3,stone)
B(-1,-2,-2,stone)
B(-1,-2,-1,stone)
B(-1,-2,0,stone)
B(-1,-2,1,stone)
B(-1,-2,2,stone)
B(-1,-2,3,stone)
B(-1,-2,4,stone)
B(-1,-1,-5,stone)
B(-1,-1,-4,stone)
B(-1,-1,-3,stone)
B(-1,-1,-2,stone)
B(-1,-1,-1,stone)
B(-1,-1,0,stone)
B(-1,-1,1,stone)
B(-1,-1,2,stone)
B(-1,-1,3,stone)
B(-1,-1,4,stone)
B(-1,-1,5,stone)
B(-1,0,-5,stone)
B(-1,0,-4,stone)
B(-1,0,-3,stone)
B(-1,0,-2,stone)
B(-1,0,-1,stone)
B(-1,0,0,stone)
B(-1,0,1,stone)
B(-1,0,2,stone)
B(-1,0,3,stone)
B(-1,0,4,stone)
B(-1,0,5,grass)
B(-1,1,-5,grass)
B(-1,1,-4,stone)
B(-1,1,-3,stone)
B(-1,1,-2,stone)
B(-1,1,-1,stone)
B(-1,1,0,stone)
B(-1,1,1,stone)
B(-1,1,2,stone)
B(-1,1,3,stone)
B(-1,1,4,stone)
B(-1,1,5,tallgrass:1)
B(-1,2,-5,tallgrass:1)
B(-1,2,-4,gravel)
B(-1,2,-3,stone)
B(-1,2,-2,stone)
B(-1,2,-1,stone)
B(-1,2,0,stone)
B(-1,2,1,stone)
B(-1,2,2,stone)
B(-1,2,3,stone)
B(-1,2,4,leaves)
B(-1,3,-3,grass)
B(-1,3,-2,stone)
B(-1,3,-1,stone)
B(-1,3,0,stone)
B(-1,3,1,stone)
B(-1,3,3,leaves)
B(-1,4,-3,tallgrass:1)
B(-1,4,-1,leaves)
B(-1,4,0,grass)
B(-1,4,1,gravel)
B(-1,5,0,tallgrass:2)
B(0,-4,1,stone)
B(0,-4,2,stone)
B(0,-3,-2,stone)
B(0,-3,-1,stone)
B(0,-3,0,stone)
B(0,-3,1,stone)
B(0,-3,2,stone)
B(0,-3,3,stone)
B(0,-2,-3,stone)
B(0,-2,-2,stone)
B(0,-2,-1,stone)
B(0,-2,0,stone)
B(0,-2,1,stone)
B(0,-2,2,stone)
B(0,-2,3,stone)
B(0,-2,4,stone)
B(0,-1,-5,stone)
B(0,-1,-4,stone)
B(0,-1,-3,stone)
B(0,-1,-2,stone)
B(0,-1,-1,stone)
B(0,-1,0,stone)
B(0,-1,1,stone)
B(0,-1,2,stone)
B(0,-1,3,stone)
B(0,-1,4,stone)
B(0,-1,5,stone)
B(0,0,-5,grass)
B(0,0,-4,stone)
B(0,0,-3,stone)
B(0,0,-2,stone)
B(0,0,-1,stone)
B(0,0,0,stone)
B(0,0,1,stone)
B(0,0,2,stone)
B(0,0,3,stone)
B(0,0,4,stone)
B(0,0,5,stone)
B(0,1,-5,tallgrass:1)
B(0,1,-4,stone)
B(0,1,-3,stone)
B(0,1,-2,stone)
B(0,1,-1,stone)
B(0,1,0,stone)
B(0,1,1,stone)
B(0,1,2,stone)
B(0,1,3,stone)
B(0,1,4,stone)
B(0,1,5,gravel)
B(0,2,-3,grass)
B(0,2,-2,stone)
B(0,2,-1,stone)
B(0,2,0,stone)
B(0,2,1,stone)
B(0,2,2,stone)
B(0,2,3,stone)
B(0,2,4,gravel)
B(0,3,-3,red_flower:3)
B(0,3,-2,stone)
B(0,3,-1,stone)
B(0,3,0,dirt)
B(0,3,1,dirt)
B(0,3,2,stone)
B(0,3,3,leaves)
B(0,4,-2,grass)
B(0,4,-1,leaves)
B(0,4,0,grass)
B(0,4,1,grass)
B(0,4,2,leaves)
B(0,5,-2,tallgrass:1)
B(0,5,0,tallgrass:1)
B(0,5,1,tallgrass:1)
B(1,-4,-1,stone)
B(1,-4,0,stone)
B(1,-4,1,stone)
B(1,-4,2,stone)
B(1,-3,-2,stone)
B(1,-3,-1,stone)
B(1,-3,0,stone)
B(1,-3,1,stone)
B(1,-3,2,stone)
B(1,-3,3,stone)
B(1,-2,-3,stone)
B(1,-2,-2,stone)
B(1,-2,-1,stone)
B(1,-2,0,stone)
B(1,-2,1,stone)
B(1,-2,2,stone)
B(1,-2,3,stone)
B(1,-2,4,stone)
B(1,-1,-4,stone)
B(1,-1,-3,stone)
B(1,-1,-2,stone)
B(1,-1,-1,stone)
B(1,-1,0,stone)
B(1,-1,1,stone)
B(1,-1,2,stone)
B(1,-1,3,stone)
B(1,-1,4,stone)
B(1,-1,5,stone)
B(1,0,-4,stone)
B(1,0,-3,stone)
B(1,0,-2,stone)
B(1,0,-1,stone)
B(1,0,0,stone)
B(1,0,1,stone)
B(1,0,2,stone)
B(1,0,3,stone)
B(1,0,4,stone)
B(1,0,5,stone)
B(1,1,-4,stone)
B(1,1,-3,stone)
B(1,1,-2,stone)
B(1,1,-1,stone)
B(1,1,0,stone)
B(1,1,1,stone)
B(1,1,2,stone)
B(1,1,3,stone)
B(1,1,4,stone)
B(1,2,-4,gravel)
B(1,2,-3,grass)
B(1,2,-2,stone)
B(1,2,-1,stone)
B(1,2,0,stone)
B(1,2,1,stone)
B(1,2,2,stone)
B(1,2,3,stone)
B(1,2,4,gravel)
B(1,3,-3,tallgrass:2)
B(1,3,-2,stone)
B(1,3,-1,stone)
B(1,3,0,dirt)
B(1,3,1,stone)
B(1,3,2,stone)
B(1,3,3,stone)
B(1,4,-2,grass)
B(1,4,-1,leaves)
B(1,4,0,grass)
B(1,4,1,leaves)
B(1,4,2,leaves)
B(1,5,-2,tallgrass:1)
B(1,5,0,tallgrass:1)
B(2,-4,-2,stone)
B(2,-4,-1,stone)
B(2,-4,0,stone)
B(2,-4,1,stone)
B(2,-3,-3,stone)
B(2,-3,-2,stone)
B(2,-3,-1,stone)
B(2,-3,0,stone)
B(2,-3,1,stone)
B(2,-3,2,stone)
B(2,-2,-3,stone)
B(2,-2,-2,stone)
B(2,-2,-1,stone)
B(2,-2,0,stone)
B(2,-2,1,stone)
B(2,-2,2,stone)
B(2,-2,3,stone)
B(2,-1,-4,stone)
B(2,-1,-3,stone)
B(2,-1,-2,stone)
B(2,-1,-1,stone)
B(2,-1,0,stone)
B(2,-1,1,stone)
B(2,-1,2,stone)
B(2,-1,3,stone)
B(2,-1,4,stone)
B(2,0,-4,stone)
B(2,0,-3,stone)
B(2,0,-2,stone)
B(2,0,-1,stone)
B(2,0,0,stone)
B(2,0,1,stone)
B(2,0,2,stone)
B(2,0,3,stone)
B(2,0,4,stone)
B(2,1,-4,stone)
B(2,1,-3,stone)
B(2,1,-2,stone)
B(2,1,-1,stone)
B(2,1,0,stone)
B(2,1,1,stone)
B(2,1,2,stone)
B(2,1,3,stone)
B(2,1,4,stone)
B(2,2,-4,grass)
B(2,2,-3,stone)
B(2,2,-2,stone)
B(2,2,-1,stone)
B(2,2,0,stone)
B(2,2,1,stone)
B(2,2,2,stone)
B(2,2,3,stone)
B(2,2,4,grass)
B(2,3,-4,tallgrass:1)
B(2,3,-3,leaves)
B(2,3,-2,grass)
B(2,3,-1,stone)
B(2,3,0,stone)
B(2,3,1,stone)
B(2,3,2,stone)
B(2,3,3,grass)
B(2,3,4,red_flower:1)
B(2,4,-2,leaves)
B(2,4,-1,grass)
B(2,4,0,leaves)
B(2,4,1,grass)
B(2,4,2,grass)
B(2,4,3,red_flower:3)
B(2,5,-1,red_flower:3)
B(2,5,1,red_flower:1)
B(2,5,2,tallgrass:2)
B(3,-4,-1,stone)
B(3,-3,-3,stone)
B(3,-3,-2,stone)
B(3,-3,-1,stone)
B(3,-3,0,stone)
B(3,-3,1,stone)
B(3,-2,-4,stone)
B(3,-2,-3,stone)
B(3,-2,-2,stone)
B(3,-2,-1,stone)
B(3,-2,0,stone)
B(3,-2,1,stone)
B(3,-2,2,stone)
B(3,-2,3,stone)
B(3,-1,-4,stone)
B(3,-1,-3,stone)
B(3,-1,-2,stone)
B(3,-1,-1,stone)
B(3,-1,0,stone)
B(3,-1,1,stone)
B(3,-1,2,stone)
B(3,-1,3,stone)
B(3,-1,4,stone)
B(3,0,-5,stone)
B(3,0,-4,stone)
B(3,0,-3,stone)
B(3,0,-2,stone)
B(3,0,-1,stone)
B(3,0,0,stone)
B(3,0,1,stone)
B(3,0,2,stone)
B(3,0,3,stone)
B(3,0,4,stone)
B(3,0,5,grass)
B(3,1,-5,gravel)
B(3,1,-4,stone)
B(3,1,-3,stone)
B(3,1,-2,stone)
B(3,1,-1,stone)
B(3,1,0,stone)
B(3,1,1,stone)
B(3,1,2,stone)
B(3,1,3,stone)
B(3,1,4,stone)
B(3,1,5,leaves)
B(3,2,-4,stone)
B(3,2,-3,stone)
B(3,2,-2,stone)
B(3,2,-1,stone)
B(3,2,0,stone)
B(3,2,1,stone)
B(3,2,2,stone)
B(3,2,3,stone)
B(3,2,4,leaves)
B(3,3,-3,leaves)
B(3,3,-2,grass)
B(3,3,-1,stone)
B(3,3,0,stone)
B(3,3,1,stone)
B(3,3,2,stone)
B(3,3,3,gravel)
B(3,4,-1,leaves)
B(3,4,0,leaves)
B(3,4,1,grass)
B(3,5,1,tallgrass:2)
B(4,-3,-3,stone)
B(4,-3,-2,stone)
B(4,-3,-1,stone)
B(4,-2,-4,stone)
B(4,-2,-3,stone)
B(4,-2,-2,stone)
B(4,-2,-1,stone)
B(4,-2,0,stone)
B(4,-2,1,stone)
B(4,-1,-5,stone)
B(4,-1,-4,stone)
B(4,-1,-3,stone)
B(4,-1,-2,stone)
B(4,-1,-1,stone)
B(4,-1,0,stone)
B(4,-1,1,stone)
B(4,-1,2,stone)
B(4,-1,3,stone)
B(4,0,-5,stone)
B(4,0,-4,stone)
B(4,0,-3,stone)
B(4,0,-2,stone)
B(4,0,-1,stone)
B(4,0,0,stone)
B(4,0,1,stone)
B(4,0,2,stone)
B(4,0,3,stone)
B(4,0,4,stone)
B(4,1,-5,grass)
B(4,1,-4,stone)
B(4,1,-3,stone)
B(4,1,-2,stone)
B(4,1,-1,stone)
B(4,1,0,stone)
B(4,1,1,stone)
B(4,1,2,stone)
B(4,1,3,stone)
B(4,1,4,leaves)
B(4,2,-4,leaves)
B(4,2,-3,stone)
B(4,2,-2,stone)
B(4,2,-1,stone)
B(4,2,0,stone)
B(4,2,1,stone)
B(4,2,2,stone)
B(4,2,3,grass)
B(4,3,-2,grass)
B(4,3,-1,stone)
B(4,3,0,stone)
B(4,3,1,stone)
B(4,3,2,leaves)
B(4,3,3,tallgrass:2)
B(4,4,-2,red_flower:3)
B(4,4,0,gravel)
B(4,4,1,leaves)
B(5,-3,-3,stone)
B(5,-2,-4,stone)
B(5,-2,-3,stone)
B(5,-2,-2,stone)
B(5,-1,-5,stone)
B(5,-1,-4,stone)
B(5,-1,-3,stone)
B(5,-1,-2,stone)
B(5,-1,-1,stone)
B(5,0,-5,grass)
B(5,0,-4,stone)
B(5,0,-3,stone)
B(5,0,-2,stone)
B(5,0,-1,stone)
B(5,0,0,stone)
B(5,0,1,stone)
B(5,1,-5,tallgrass:1)
B(5,1,-4,grass)
B(5,1,-3,stone)
B(5,1,-2,stone)
B(5,1,-1,stone)
B(5,1,0,stone)
B(5,1,1,stone)
B(5,1,2,leaves)
B(5,2,-4,tallgrass:1)
B(5,2,-2,grass)
B(5,2,-1,stone)
B(5,2,0,stone)
B(5,2,1,gravel)
B(5,2,2,leaves)
B(5,3,-2,red_flower:1)
B(5,3,0,gravel)
B(6,-3,-3,stone)
B(6,-2,-4,stone)
B(6,-2,-3,stone)
B(6,-1,-4,stone)
B(6,-1,-3,stone)
B(6,-1,-2,stone)
B(6,0,-4,stone)
B(6,0,-3,stone)
B(6,0,-2,stone)
B(6,0,-1,stone)
B(6,1,-2,gravel)
B(6,1,-1,gravel)
B(6,2,-1,gravel)

#
# +-----------------------------------------------------------------+ #
# |                            BO3 checks                           | #
# +-----------------------------------------------------------------+ #
#

BlockCheck(0,-1,0,grass,dirt,dirt:2)
BlockCheck(0,-2,0,dirt)

#
# +-----------------------------------------------------------------+ #
# |                             Branches                            | #
# +-----------------------------------------------------------------+ #
#

