
#
# +-----------------------------------------------------------------+ #
# |                            BO3 object                           | #
# +-----------------------------------------------------------------+ #
#

Author: NLBlackEagle

Description: No description given

Version: 3

SettingsMode: WriteDisable


#
# +-----------------------------------------------------------------+ #
# |                          Main settings                          | #
# +-----------------------------------------------------------------+ #
#

Tree: true

Frequency: 1

Rarity: 30.0

RotateRandomly: true

SpawnHeight: highestSolidBlock

SpawnHeightOffset: -6

SpawnHeightVariance: 0


# Height Limits for the BO3. #


MinHeight: 0

MaxHeight: 256


# Extrusion settings #


ExtrudeMode: None

ExtrudeThroughBlocks: air

MaxBranchDepth: 10

ExcludedBiomes: All


#
# +-----------------------------------------------------------------+ #
# |                      Source block settings                      | #
# +-----------------------------------------------------------------+ #
#

SourceBlocks: AIR,GRASS,STONE,DIRT

MaxPercentageOutsideSourceBlock: 0

OutsideSourceBlock: placeAnyway


#
# +-----------------------------------------------------------------+ #
# |                              Blocks                             | #
# +-----------------------------------------------------------------+ #
#

B(-3,3,1,stone)
B(-3,4,0,stone)
B(-3,4,1,stone)
B(-3,4,2,stone)
B(-3,5,0,Leaves:5)
B(-3,5,1,stone)
B(-3,5,2,grass)
B(-3,6,1,grass)
B(-3,6,2,yellow_flower)
B(-3,7,1,tallgrass:2)
B(-2,2,1,gold_ore)
B(-2,2,4,stone)
B(-2,3,0,stone)
B(-2,3,1,stone)
B(-2,3,2,gold_ore)
B(-2,3,3,stone)
B(-2,3,4,stone)
B(-2,3,5,gold_ore)
B(-2,4,-1,stone)
B(-2,4,0,stone)
B(-2,4,1,stone)
B(-2,4,2,stone)
B(-2,4,3,stone)
B(-2,4,4,stone)
B(-2,5,-1,gold_ore)
B(-2,5,0,LOG:1)
B(-2,5,1,stone)
B(-2,5,2,stone)
B(-2,5,3,grass)
B(-2,6,-1,grass)
B(-2,6,0,gold_ore)
B(-2,6,1,stone)
B(-2,6,2,grass)
B(-2,6,3,Leaves:5)
B(-2,7,-1,yellow_flower)
B(-2,7,1,grass)
B(-2,7,2,Leaves:5)
B(-2,8,1,yellow_flower)
B(-1,1,3,stone)
B(-1,1,4,stone)
B(-1,2,0,stone)
B(-1,2,1,stone)
B(-1,2,2,stone)
B(-1,2,3,stone)
B(-1,2,4,stone)
B(-1,2,5,gold_ore)
B(-1,3,-1,stone)
B(-1,3,0,stone)
B(-1,3,1,stone)
B(-1,3,2,stone)
B(-1,3,3,stone)
B(-1,3,4,gold_ore)
B(-1,3,5,stone)
B(-1,3,6,stone)
B(-1,4,-1,stone)
B(-1,4,0,gold_ore)
B(-1,4,1,stone)
B(-1,4,2,stone)
B(-1,4,3,stone)
B(-1,4,4,gold_ore)
B(-1,4,5,stone)
B(-1,5,-2,stone)
B(-1,5,-1,stone)
B(-1,5,0,stone)
B(-1,5,1,stone)
B(-1,5,2,stone)
B(-1,5,3,stone)
B(-1,5,4,stone)
B(-1,6,-2,grass)
B(-1,6,-1,stone)
B(-1,6,0,stone)
B(-1,6,1,stone)
B(-1,6,2,LOG:1)
B(-1,6,3,grass)
B(-1,7,-2,Leaves:5)
B(-1,7,-1,grass)
B(-1,7,0,stone)
B(-1,7,1,stone)
B(-1,7,2,Leaves:5)
B(-1,7,3,yellow_flower)
B(-1,8,-1,double_plant:3)
B(-1,9,-1,double_plant:10)
B(0,0,3,stone)
B(0,1,2,stone)
B(0,1,3,stone)
B(0,1,4,stone)
B(0,1,5,gold_ore)
B(0,2,1,gold_ore)
B(0,2,2,stone)
B(0,2,3,stone)
B(0,2,4,stone)
B(0,2,5,stone)
B(0,2,6,stone)
B(0,3,-1,stone)
B(0,3,0,stone)
B(0,3,1,stone)
B(0,3,2,stone)
B(0,3,3,stone)
B(0,3,4,stone)
B(0,3,5,stone)
B(0,3,6,stone)
B(0,4,-2,stone)
B(0,4,-1,stone)
B(0,4,0,gold_ore)
B(0,4,1,stone)
B(0,4,2,stone)
B(0,4,3,stone)
B(0,4,4,stone)
B(0,4,5,stone)
B(0,4,6,stone)
B(0,5,-2,stone)
B(0,5,-1,stone)
B(0,5,0,stone)
B(0,5,1,gold_ore)
B(0,5,2,gold_ore)
B(0,5,3,stone)
B(0,5,4,stone)
B(0,5,5,stone)
B(0,6,-2,stone)
B(0,6,-1,LOG:1)
B(0,6,0,stone)
B(0,6,1,LOG:1)
B(0,6,2,stone)
B(0,6,3,stone)
B(0,6,4,grass)
B(0,7,-1,Leaves:5)
B(0,7,0,Leaves:5)
B(0,7,1,Leaves:5)
B(0,7,2,stone)
B(0,7,4,tallgrass:2)
B(1,0,3,stone)
B(1,1,1,gold_ore)
B(1,1,2,stone)
B(1,1,3,stone)
B(1,1,4,stone)
B(1,1,5,stone)
B(1,2,1,stone)
B(1,2,2,gold_ore)
B(1,2,3,stone)
B(1,2,4,stone)
B(1,2,5,stone)
B(1,3,0,stone)
B(1,3,1,stone)
B(1,3,2,stone)
B(1,3,3,stone)
B(1,3,4,stone)
B(1,3,5,gold_ore)
B(1,3,6,stone)
B(1,4,-1,stone)
B(1,4,0,stone)
B(1,4,1,stone)
B(1,4,2,stone)
B(1,4,3,stone)
B(1,4,4,stone)
B(1,4,5,stone)
B(1,4,6,stone)
B(1,5,-2,stone)
B(1,5,-1,stone)
B(1,5,0,gold_ore)
B(1,5,1,stone)
B(1,5,2,stone)
B(1,5,3,stone)
B(1,5,4,stone)
B(1,5,5,stone)
B(1,6,-2,grass)
B(1,6,-1,stone)
B(1,6,0,stone)
B(1,6,1,gold_ore)
B(1,6,2,stone)
B(1,6,3,stone)
B(1,6,4,gold_ore)
B(1,7,-2,yellow_flower)
B(1,7,-1,stone)
B(1,7,0,gold_ore)
B(1,7,1,stone)
B(1,7,2,stone)
B(2,1,2,stone)
B(2,1,3,stone)
B(2,1,4,stone)
B(2,2,1,stone)
B(2,2,2,stone)
B(2,2,3,stone)
B(2,2,4,stone)
B(2,2,5,gold_ore)
B(2,3,0,stone)
B(2,3,1,stone)
B(2,3,2,stone)
B(2,3,3,stone)
B(2,3,4,stone)
B(2,3,5,stone)
B(2,3,6,stone)
B(2,4,-1,stone)
B(2,4,0,stone)
B(2,4,1,stone)
B(2,4,2,gold_ore)
B(2,4,3,stone)
B(2,4,4,stone)
B(2,4,5,stone)
B(2,4,6,stone)
B(2,5,-1,stone)
B(2,5,0,stone)
B(2,5,1,stone)
B(2,5,2,gold_ore)
B(2,5,3,stone)
B(2,5,4,stone)
B(2,5,5,stone)
B(2,5,6,stone)
B(2,6,-1,stone)
B(2,6,0,gold_ore)
B(2,6,1,gold_ore)
B(2,6,2,stone)
B(2,6,3,stone)
B(2,6,4,stone)
B(2,6,5,stone)
B(2,7,0,stone)
B(2,7,1,stone)
B(2,7,2,grass)
B(3,1,3,stone)
B(3,2,0,stone)
B(3,2,1,stone)
B(3,2,2,stone)
B(3,2,3,stone)
B(3,2,4,stone)
B(3,3,-1,stone)
B(3,3,0,stone)
B(3,3,1,stone)
B(3,3,2,stone)
B(3,3,3,stone)
B(3,3,4,stone)
B(3,3,5,gold_ore)
B(3,4,-1,stone)
B(3,4,0,stone)
B(3,4,1,stone)
B(3,4,2,stone)
B(3,4,3,stone)
B(3,4,4,stone)
B(3,4,5,stone)
B(3,4,6,stone)
B(3,5,-1,stone)
B(3,5,0,stone)
B(3,5,1,stone)
B(3,5,2,stone)
B(3,5,3,stone)
B(3,5,4,gold_ore)
B(3,5,5,stone)
B(3,6,0,stone)
B(3,6,1,stone)
B(3,6,2,gold_ore)
B(3,6,3,LOG:1)
B(3,6,4,log:5)
B(3,6,5,grass)
B(3,7,0,grass)
B(3,7,1,stone)
B(3,7,3,Leaves:5)
B(3,7,4,Leaves:5)
B(3,7,5,yellow_flower)
B(3,8,0,yellow_flower)
B(4,2,1,stone)
B(4,2,2,stone)
B(4,2,3,gold_ore)
B(4,3,0,stone)
B(4,3,1,stone)
B(4,3,2,stone)
B(4,3,3,stone)
B(4,3,4,stone)
B(4,4,-1,stone)
B(4,4,0,stone)
B(4,4,1,stone)
B(4,4,2,stone)
B(4,4,3,stone)
B(4,4,4,stone)
B(4,4,5,gold_ore)
B(4,5,-1,grass)
B(4,5,0,gold_ore)
B(4,5,1,stone)
B(4,5,2,stone)
B(4,5,3,stone)
B(4,5,4,stone)
B(4,5,5,grass)
B(4,6,-1,tallgrass:2)
B(4,6,0,grass)
B(4,6,1,stone)
B(4,6,2,stone)
B(4,6,3,stone)
B(4,6,4,grass)
B(4,6,5,yellow_flower)
B(4,7,0,yellow_flower)
B(4,7,2,Leaves:5)
B(4,7,3,Leaves:5)
B(4,7,4,yellow_flower)
B(5,2,2,stone)
B(5,3,1,stone)
B(5,3,2,stone)
B(5,3,3,stone)
B(5,4,0,stone)
B(5,4,1,stone)
B(5,4,2,stone)
B(5,4,3,stone)
B(5,4,4,stone)
B(5,5,0,grass)
B(5,5,1,stone)
B(5,5,2,stone)
B(5,5,3,stone)
B(5,5,4,grass)
B(5,6,0,yellow_flower)
B(5,6,1,grass)
B(5,6,2,LOG:1)
B(5,6,3,grass)
B(5,6,4,yellow_flower)
B(5,7,1,yellow_flower)
B(5,7,2,Leaves:5)
B(5,7,3,yellow_flower)
B(6,3,2,stone)
B(6,4,1,stone)
B(6,4,2,stone)
B(6,4,3,stone)
B(6,5,2,stone)
B(6,5,3,Leaves:5)
B(6,6,2,Leaves:5)

#
# +-----------------------------------------------------------------+ #
# |                            BO3 checks                           | #
# +-----------------------------------------------------------------+ #
#

BlockCheck(0,-1,0,grass,dirt,dirt:2,stone,snow)

#
# +-----------------------------------------------------------------+ #
# |                             Branches                            | #
# +-----------------------------------------------------------------+ #
#

