
#
# +-----------------------------------------------------------------+ #
# |                            BO3 object                           | #
# +-----------------------------------------------------------------+ #
#

Author: NLBlackEagle

Description: No description given

Version: 3

SettingsMode: WriteDisable


#
# +-----------------------------------------------------------------+ #
# |                          Main settings                          | #
# +-----------------------------------------------------------------+ #
#

Tree: false

Frequency: 1

Rarity: 30.0

RotateRandomly: true

SpawnHeight: highestSolidBlock

SpawnHeightOffset: -6

SpawnHeightVariance: 0


# Height Limits for the BO3. #


MinHeight: 0

MaxHeight: 256


# Extrusion settings #


ExtrudeMode: None

ExtrudeThroughBlocks: air

MaxBranchDepth: 10

ExcludedBiomes: All


#
# +-----------------------------------------------------------------+ #
# |                      Source block settings                      | #
# +-----------------------------------------------------------------+ #
#

SourceBlocks: AIR,GRASS,STONE,DIRT

MaxPercentageOutsideSourceBlock: 0

OutsideSourceBlock: placeAnyway


#
# +-----------------------------------------------------------------+ #
# |                              Blocks                             | #
# +-----------------------------------------------------------------+ #
#

B(-2,3,0,iron_ore)
B(-2,3,3,stone)
B(-2,4,-1,iron_ore)
B(-2,4,0,stone)
B(-2,4,1,iron_ore)
B(-2,4,2,stone)
B(-2,4,3,stone)
B(-2,4,4,stone)
B(-2,5,0,stone)
B(-2,5,1,grass)
B(-2,5,3,stone)
B(-1,0,2,stone)
B(-1,0,3,stone)
B(-1,1,2,stone)
B(-1,1,3,iron_ore)
B(-1,1,4,iron_ore)
B(-1,2,0,iron_ore)
B(-1,2,2,iron_ore)
B(-1,2,3,iron_ore)
B(-1,3,-2,stone)
B(-1,3,-1,iron_ore)
B(-1,3,0,stone)
B(-1,3,1,stone)
B(-1,3,2,stone)
B(-1,3,3,stone)
B(-1,3,4,stone)
B(-1,4,-3,stone)
B(-1,4,-2,iron_ore)
B(-1,4,-1,stone)
B(-1,4,0,iron_ore)
B(-1,4,1,stone)
B(-1,4,2,stone)
B(-1,4,3,stone)
B(-1,4,4,iron_ore)
B(-1,4,5,stone)
B(-1,5,-2,stone)
B(-1,5,-1,iron_ore)
B(-1,5,0,stone)
B(-1,5,1,stone)
B(-1,5,2,stone)
B(-1,5,3,stone)
B(-1,5,4,stone)
B(-1,6,-1,dirt)
B(-1,6,0,stone)
B(-1,6,1,iron_ore)
B(-1,6,3,iron_ore)
B(-1,7,-1,grass)
B(-1,7,0,stone)
B(-1,7,1,stone)
B(-1,7,2,stone)
B(-1,7,3,grass)
B(-1,8,0,grass)
B(-1,8,1,iron_ore)
B(0,0,1,stone)
B(0,0,2,stone)
B(0,0,3,stone)
B(0,0,4,iron_ore)
B(0,1,1,iron_ore)
B(0,1,2,stone)
B(0,1,3,stone)
B(0,1,4,stone)
B(0,1,5,stone)
B(0,2,-2,stone)
B(0,2,-1,stone)
B(0,2,0,iron_ore)
B(0,2,1,iron_ore)
B(0,2,2,iron_ore)
B(0,2,3,stone)
B(0,2,4,stone)
B(0,3,-3,stone)
B(0,3,-2,iron_ore)
B(0,3,-1,stone)
B(0,3,0,iron_ore)
B(0,3,1,stone)
B(0,3,2,stone)
B(0,3,3,stone)
B(0,3,4,stone)
B(0,3,5,stone)
B(0,4,-4,stone)
B(0,4,-3,stone)
B(0,4,-2,stone)
B(0,4,-1,stone)
B(0,4,0,stone)
B(0,4,1,iron_ore)
B(0,4,2,iron_ore)
B(0,4,3,stone)
B(0,4,4,stone)
B(0,4,5,stone)
B(0,5,-3,stone)
B(0,5,-2,iron_ore)
B(0,5,-1,iron_ore)
B(0,5,0,iron_ore)
B(0,5,1,iron_ore)
B(0,5,2,stone)
B(0,5,3,iron_ore)
B(0,5,4,iron_ore)
B(0,5,5,iron_ore)
B(0,6,-3,grass)
B(0,6,-2,stone)
B(0,6,-1,stone)
B(0,6,0,stone)
B(0,6,1,iron_ore)
B(0,6,2,iron_ore)
B(0,6,3,stone)
B(0,6,4,iron_ore)
B(0,7,-1,stone)
B(0,7,0,stone)
B(0,7,1,stone)
B(0,7,2,iron_ore)
B(0,7,3,stone)
B(0,8,0,stone)
B(0,8,1,stone)
B(0,8,2,iron_ore)
B(0,8,3,grass)
B(0,9,0,grass)
B(0,9,1,stone)
B(1,0,0,iron_ore)
B(1,0,1,stone)
B(1,0,2,stone)
B(1,0,3,stone)
B(1,0,4,stone)
B(1,0,5,iron_ore)
B(1,1,1,stone)
B(1,1,2,iron_ore)
B(1,1,3,stone)
B(1,1,4,stone)
B(1,1,5,stone)
B(1,2,-3,stone)
B(1,2,-2,iron_ore)
B(1,2,-1,stone)
B(1,2,0,stone)
B(1,2,1,stone)
B(1,2,2,iron_ore)
B(1,2,3,stone)
B(1,2,4,stone)
B(1,2,5,stone)
B(1,3,-4,iron_ore)
B(1,3,-3,stone)
B(1,3,-2,stone)
B(1,3,-1,stone)
B(1,3,0,stone)
B(1,3,1,stone)
B(1,3,2,stone)
B(1,3,3,stone)
B(1,3,4,stone)
B(1,4,-4,iron_ore)
B(1,4,-3,iron_ore)
B(1,4,-2,stone)
B(1,4,-1,stone)
B(1,4,0,stone)
B(1,4,1,stone)
B(1,4,2,stone)
B(1,4,3,iron_ore)
B(1,4,4,iron_ore)
B(1,4,5,stone)
B(1,5,-4,stone)
B(1,5,-3,stone)
B(1,5,-2,stone)
B(1,5,-1,iron_ore)
B(1,5,0,stone)
B(1,5,1,iron_ore)
B(1,5,2,stone)
B(1,5,3,stone)
B(1,5,4,iron_ore)
B(1,5,5,stone)
B(1,6,-4,grass)
B(1,6,-3,iron_ore)
B(1,6,-2,stone)
B(1,6,-1,stone)
B(1,6,0,stone)
B(1,6,1,iron_ore)
B(1,6,2,stone)
B(1,6,3,stone)
B(1,6,4,stone)
B(1,6,5,grass)
B(1,7,-2,grass)
B(1,7,-1,iron_ore)
B(1,7,0,stone)
B(1,7,1,stone)
B(1,7,2,stone)
B(1,7,3,stone)
B(1,7,4,grass)
B(1,8,-1,stone)
B(1,8,0,iron_ore)
B(1,8,1,stone)
B(1,8,2,stone)
B(1,8,3,stone)
B(1,9,0,stone)
B(1,9,1,stone)
B(1,9,2,stone)
B(2,0,1,stone)
B(2,0,2,stone)
B(2,0,3,stone)
B(2,0,4,stone)
B(2,1,1,stone)
B(2,1,2,stone)
B(2,1,3,stone)
B(2,1,4,stone)
B(2,1,5,iron_ore)
B(2,2,-2,iron_ore)
B(2,2,1,stone)
B(2,2,2,stone)
B(2,2,3,iron_ore)
B(2,2,4,stone)
B(2,3,-3,stone)
B(2,3,-2,stone)
B(2,3,-1,stone)
B(2,3,0,stone)
B(2,3,1,iron_ore)
B(2,3,2,stone)
B(2,3,3,stone)
B(2,3,4,stone)
B(2,4,-4,stone)
B(2,4,-3,stone)
B(2,4,-2,stone)
B(2,4,-1,stone)
B(2,4,0,stone)
B(2,4,1,iron_ore)
B(2,4,2,stone)
B(2,4,3,stone)
B(2,4,4,stone)
B(2,4,5,iron_ore)
B(2,5,-4,grass)
B(2,5,-3,stone)
B(2,5,-2,stone)
B(2,5,-1,stone)
B(2,5,0,iron_ore)
B(2,5,1,stone)
B(2,5,2,stone)
B(2,5,3,stone)
B(2,5,4,iron_ore)
B(2,5,5,stone)
B(2,6,-3,grass)
B(2,6,-2,stone)
B(2,6,-1,iron_ore)
B(2,6,0,stone)
B(2,6,1,stone)
B(2,6,2,stone)
B(2,6,3,stone)
B(2,6,4,stone)
B(2,6,5,stone)
B(2,7,-2,grass)
B(2,7,-1,iron_ore)
B(2,7,0,iron_ore)
B(2,7,1,iron_ore)
B(2,7,2,iron_ore)
B(2,7,3,iron_ore)
B(2,7,4,stone)
B(2,8,0,stone)
B(2,8,1,stone)
B(2,8,2,stone)
B(2,9,1,iron_ore)
B(3,0,2,stone)
B(3,0,3,iron_ore)
B(3,1,2,stone)
B(3,1,3,stone)
B(3,1,4,stone)
B(3,2,1,stone)
B(3,2,2,stone)
B(3,2,3,stone)
B(3,3,-2,stone)
B(3,3,-1,stone)
B(3,3,0,iron_ore)
B(3,3,1,iron_ore)
B(3,3,2,iron_ore)
B(3,3,3,stone)
B(3,3,4,stone)
B(3,4,-3,stone)
B(3,4,-2,stone)
B(3,4,-1,stone)
B(3,4,0,iron_ore)
B(3,4,1,stone)
B(3,4,2,stone)
B(3,4,3,iron_ore)
B(3,4,4,stone)
B(3,5,-3,grass)
B(3,5,-2,iron_ore)
B(3,5,-1,iron_ore)
B(3,5,0,iron_ore)
B(3,5,1,stone)
B(3,5,2,stone)
B(3,5,3,stone)
B(3,5,4,iron_ore)
B(3,5,5,stone)
B(3,6,-2,stone)
B(3,6,-1,iron_ore)
B(3,6,0,stone)
B(3,6,1,iron_ore)
B(3,6,2,iron_ore)
B(3,6,3,stone)
B(3,6,4,iron_ore)
B(3,6,5,grass)
B(3,7,-1,stone)
B(3,7,0,stone)
B(3,7,1,stone)
B(3,7,2,iron_ore)
B(3,7,3,stone)
B(3,7,4,grass)
B(3,8,1,stone)
B(3,8,2,grass)
B(4,2,2,iron_ore)
B(4,3,0,stone)
B(4,3,1,stone)
B(4,3,2,stone)
B(4,3,3,stone)
B(4,4,-1,stone)
B(4,4,0,stone)
B(4,4,1,stone)
B(4,4,2,stone)
B(4,4,3,stone)
B(4,4,4,iron_ore)
B(4,5,-2,stone)
B(4,5,-1,iron_ore)
B(4,5,0,stone)
B(4,5,1,stone)
B(4,5,2,iron_ore)
B(4,5,3,stone)
B(4,5,4,stone)
B(4,6,-2,grass)
B(4,6,-1,stone)
B(4,6,0,stone)
B(4,6,1,stone)
B(4,6,2,stone)
B(4,6,3,stone)
B(4,6,4,grass)
B(4,7,-1,grass)
B(4,7,0,iron_ore)
B(4,7,1,grass)
B(4,7,2,grass)
B(5,3,2,stone)
B(5,4,0,iron_ore)
B(5,4,1,stone)
B(5,4,2,stone)
B(5,4,3,stone)
B(5,5,-1,stone)
B(5,5,0,iron_ore)
B(5,5,1,stone)
B(5,5,2,iron_ore)
B(5,6,-1,grass)
B(5,6,0,stone)
B(5,6,1,grass)

#
# +-----------------------------------------------------------------+ #
# |                            BO3 checks                           | #
# +-----------------------------------------------------------------+ #
#

BlockCheck(0,-1,0,grass,dirt,dirt:2,stone,snow)

#
# +-----------------------------------------------------------------+ #
# |                             Branches                            | #
# +-----------------------------------------------------------------+ #
#

