Author: Bo3 BulkEdit

Description: Converted Schematic - Modified by Bo3BulkEdit

Version: 3

SettingsMode: WriteDisable

IsOTGPlus: false
Tree: false
Frequency: 10
Rarity: 40
RotateRandomly: true
SpawnHeight: highestSolidBlock
MaxBranchDepth: 10
ExcludedBiomes: All

MinHeight: 0
MaxHeight: 256

SourceBlocks: AIR,GRASS,STONE,DIRT
MaxPercentageOutsideSourceBlock: 0
OutsideSourceBlock: placeAnyway

BlockCheck(-1,0,-9,GRASS,DIRT,DIRT:1)
BlockCheck(4,0,-9,GRASS,DIRT,DIRT:1)
BlockCheck(5,0,8,GRASS,DIRT,DIRT:1)
BlockCheck(7,0,4,GRASS,DIRT,DIRT:1)
BlockCheck(-9,0,5,GRASS,DIRT,DIRT:1)
BlockCheck(10,0,1,GRASS,DIRT,DIRT:1)
BlockCheck(7,0,-6,GRASS,DIRT,DIRT:1)
BlockCheck(10,0,-3,GRASS,DIRT,DIRT:1)
BlockCheck(-9,0,-1,GRASS,DIRT,DIRT:1)
BlockCheck(-6,0,10,GRASS,DIRT,DIRT:1)
BlockCheck(2,0,11,GRASS,DIRT,DIRT:1)
BlockCheck(-2,0,12,GRASS,DIRT,DIRT:1)
BlockCheck(-5,1,-5,GRASS,DIRT,DIRT:1)
B(-1,0,-8,STONE:0)
B(0,0,-8,STONE:0)
B(1,0,-8,STONE:0)
B(2,0,-8,STONE:0)
B(3,0,-8,STONE:0)
B(4,0,-8,STONE:0)
B(-2,0,-7,STONE:0)
B(-1,0,-7,STONE:0)
B(0,0,-7,STONE:0)
B(1,0,-7,STONE:0)
B(2,0,-7,STONE:0)
B(3,0,-7,STONE:0)
B(4,0,-7,STONE:0)
B(5,0,-7,STONE:0)
B(-3,0,-6,STONE:0)
B(-2,0,-6,STONE:0)
B(-1,0,-6,STONE:0)
B(0,0,-6,STONE:0)
B(1,0,-6,STONE:0)
B(2,0,-6,STONE:0)
B(3,0,-6,STONE:0)
B(4,0,-6,STONE:0)
B(5,0,-6,STONE:0)
B(6,0,-6,STONE:0)
B(-4,0,-5,STONE:0)
B(-3,0,-5,STONE:0)
B(-2,0,-5,STONE:0)
B(-1,0,-5,STONE:0)
B(0,0,-5,STONE:0)
B(1,0,-5,STONE:0)
B(2,0,-5,STONE:0)
B(3,0,-5,STONE:0)
B(4,0,-5,STONE:0)
B(5,0,-5,STONE:0)
B(6,0,-5,STONE:0)
B(7,0,-5,STONE:0)
B(-5,0,-4,STONE:0)
B(-4,0,-4,STONE:0)
B(-3,0,-4,STONE:0)
B(-2,0,-4,STONE:0)
B(-1,0,-4,STONE:0)
B(0,0,-4,STONE:0)
B(1,0,-4,STONE:0)
B(2,0,-4,STONE:0)
B(3,0,-4,STONE:0)
B(4,0,-4,STONE:0)
B(5,0,-4,STONE:0)
B(6,0,-4,STONE:0)
B(7,0,-4,STONE:0)
B(8,0,-4,STONE:0)
B(-6,0,-3,STONE:0)
B(-5,0,-3,STONE:0)
B(-4,0,-3,STONE:0)
B(-3,0,-3,STONE:0)
B(-2,0,-3,STONE:0)
B(-1,0,-3,STONE:0)
B(0,0,-3,STONE:0)
B(1,0,-3,STONE:0)
B(2,0,-3,STONE:0)
B(3,0,-3,STONE:0)
B(4,0,-3,STONE:0)
B(5,0,-3,STONE:0)
B(6,0,-3,STONE:0)
B(7,0,-3,STONE:0)
B(8,0,-3,STONE:0)
B(9,0,-3,STONE:0)
B(-7,0,-2,STONE:0)
B(-6,0,-2,STONE:0)
B(-5,0,-2,STONE:0)
B(-4,0,-2,STONE:0)
B(-3,0,-2,STONE:0)
B(-2,0,-2,STONE:0)
B(-1,0,-2,STONE:0)
B(0,0,-2,STONE:0)
B(1,0,-2,STONE:0)
B(2,0,-2,STONE:0)
B(3,0,-2,STONE:0)
B(4,0,-2,STONE:0)
B(5,0,-2,STONE:0)
B(6,0,-2,STONE:0)
B(7,0,-2,STONE:0)
B(8,0,-2,STONE:0)
B(9,0,-2,STONE:0)
B(-8,0,-1,STONE:0)
B(-7,0,-1,STONE:0)
B(-6,0,-1,STONE:0)
B(-5,0,-1,STONE:0)
B(-4,0,-1,STONE:0)
B(-3,0,-1,STONE:0)
B(-2,0,-1,STONE:0)
B(-1,0,-1,STONE:0)
B(0,0,-1,STONE:0)
B(1,0,-1,STONE:0)
B(2,0,-1,STONE:0)
B(3,0,-1,STONE:0)
B(4,0,-1,STONE:0)
B(5,0,-1,STONE:0)
B(6,0,-1,STONE:0)
B(7,0,-1,STONE:0)
B(8,0,-1,STONE:0)
B(9,0,-1,STONE:0)
B(-9,0,0,STONE:0)
B(-8,0,0,STONE:0)
B(-7,0,0,STONE:0)
B(-6,0,0,STONE:0)
B(-5,0,0,STONE:0)
B(-4,0,0,STONE:0)
B(-3,0,0,STONE:0)
B(-2,0,0,STONE:0)
B(-1,0,0,STONE:0)
B(1,0,0,STONE:0)
B(2,0,0,STONE:0)
B(3,0,0,STONE:0)
B(4,0,0,STONE:0)
B(5,0,0,STONE:0)
B(6,0,0,STONE:0)
B(7,0,0,STONE:0)
B(8,0,0,STONE:0)
B(9,0,0,STONE:0)
B(-10,0,1,STONE:0)
B(-9,0,1,STONE:0)
B(-8,0,1,STONE:0)
B(-7,0,1,STONE:0)
B(-6,0,1,STONE:0)
B(-5,0,1,STONE:0)
B(-4,0,1,STONE:0)
B(-3,0,1,STONE:0)
B(-2,0,1,STONE:0)
B(-1,0,1,STONE:0)
B(0,0,1,STONE:0)
B(1,0,1,STONE:0)
B(2,0,1,STONE:0)
B(3,0,1,STONE:0)
B(4,0,1,STONE:0)
B(5,0,1,STONE:0)
B(6,0,1,STONE:0)
B(7,0,1,STONE:0)
B(8,0,1,STONE:0)
B(9,0,1,STONE:0)
B(-10,0,2,STONE:0)
B(-9,0,2,STONE:0)
B(-8,0,2,STONE:0)
B(-7,0,2,STONE:0)
B(-6,0,2,STONE:0)
B(-5,0,2,STONE:0)
B(-4,0,2,STONE:0)
B(-3,0,2,STONE:0)
B(-2,0,2,STONE:0)
B(-1,0,2,STONE:0)
B(0,0,2,STONE:0)
B(1,0,2,STONE:0)
B(2,0,2,STONE:0)
B(3,0,2,STONE:0)
B(4,0,2,STONE:0)
B(5,0,2,STONE:0)
B(6,0,2,STONE:0)
B(7,0,2,STONE:0)
B(8,0,2,STONE:0)
B(-9,0,3,STONE:0)
B(-8,0,3,STONE:0)
B(-7,0,3,STONE:0)
B(-6,0,3,STONE:0)
B(-5,0,3,STONE:0)
B(-4,0,3,STONE:0)
B(-3,0,3,STONE:0)
B(-2,0,3,STONE:0)
B(-1,0,3,STONE:0)
B(0,0,3,STONE:0)
B(1,0,3,STONE:0)
B(2,0,3,STONE:0)
B(3,0,3,STONE:0)
B(4,0,3,STONE:0)
B(5,0,3,STONE:0)
B(6,0,3,STONE:0)
B(7,0,3,STONE:0)
B(-9,0,4,STONE:0)
B(-8,0,4,STONE:0)
B(-7,0,4,STONE:0)
B(-6,0,4,STONE:0)
B(-5,0,4,STONE:0)
B(-4,0,4,STONE:0)
B(-3,0,4,STONE:0)
B(-2,0,4,STONE:0)
B(-1,0,4,STONE:0)
B(0,0,4,STONE:0)
B(1,0,4,STONE:0)
B(2,0,4,STONE:0)
B(3,0,4,STONE:0)
B(4,0,4,STONE:0)
B(5,0,4,STONE:0)
B(6,0,4,STONE:0)
B(-8,0,5,STONE:0)
B(-7,0,5,STONE:0)
B(-6,0,5,STONE:0)
B(-5,0,5,STONE:0)
B(-4,0,5,STONE:0)
B(-3,0,5,STONE:0)
B(-2,0,5,STONE:0)
B(-1,0,5,STONE:0)
B(0,0,5,STONE:0)
B(1,0,5,STONE:0)
B(2,0,5,STONE:0)
B(3,0,5,STONE:0)
B(4,0,5,STONE:0)
B(5,0,5,STONE:0)
B(6,0,5,STONE:0)
B(-8,0,6,STONE:0)
B(-7,0,6,STONE:0)
B(-6,0,6,STONE:0)
B(-5,0,6,STONE:0)
B(-4,0,6,STONE:0)
B(-3,0,6,STONE:0)
B(-2,0,6,STONE:0)
B(-1,0,6,STONE:0)
B(0,0,6,STONE:0)
B(1,0,6,STONE:0)
B(2,0,6,STONE:0)
B(3,0,6,STONE:0)
B(4,0,6,STONE:0)
B(5,0,6,STONE:0)
B(6,0,6,STONE:0)
B(-7,0,7,STONE:0)
B(-6,0,7,STONE:0)
B(-5,0,7,STONE:0)
B(-4,0,7,STONE:0)
B(-3,0,7,STONE:0)
B(-2,0,7,STONE:0)
B(-1,0,7,STONE:0)
B(0,0,7,STONE:0)
B(1,0,7,STONE:0)
B(2,0,7,STONE:0)
B(3,0,7,STONE:0)
B(4,0,7,STONE:0)
B(5,0,7,STONE:0)
B(-7,0,8,STONE:0)
B(-6,0,8,STONE:0)
B(-5,0,8,STONE:0)
B(-4,0,8,STONE:0)
B(-3,0,8,STONE:0)
B(-2,0,8,STONE:0)
B(-1,0,8,STONE:0)
B(0,0,8,STONE:0)
B(1,0,8,STONE:0)
B(2,0,8,STONE:0)
B(3,0,8,STONE:0)
B(4,0,8,STONE:0)
B(-6,0,9,STONE:0)
B(-5,0,9,STONE:0)
B(-4,0,9,STONE:0)
B(-3,0,9,STONE:0)
B(-2,0,9,STONE:0)
B(-1,0,9,STONE:0)
B(0,0,9,STONE:0)
B(1,0,9,STONE:0)
B(2,0,9,STONE:0)
B(3,0,9,STONE:0)
B(-5,0,10,STONE:0)
B(-4,0,10,STONE:0)
B(-3,0,10,STONE:0)
B(-2,0,10,STONE:0)
B(-1,0,10,STONE:0)
B(0,0,10,STONE:0)
B(1,0,10,STONE:0)
B(2,0,10,STONE:0)
B(-4,0,11,STONE:0)
B(-3,0,11,STONE:0)
B(-2,0,11,STONE:0)
B(-1,0,11,STONE:0)
B(0,0,11,STONE:0)
B(1,0,11,STONE:0)
B(-1,1,-8,STONE:0)
B(0,1,-8,STONE:0)
B(1,1,-8,STONE:0)
B(2,1,-8,STONE:0)
B(3,1,-8,STONE:0)
B(4,1,-8,STONE:0)
B(-2,1,-7,STONE:0)
B(-1,1,-7,STONE:0)
B(0,1,-7,STONE:0)
B(1,1,-7,STONE:0)
B(2,1,-7,STONE:0)
B(3,1,-7,STONE:0)
B(4,1,-7,STONE:0)
B(5,1,-7,STONE:0)
B(-3,1,-6,STONE:0)
B(-2,1,-6,STONE:0)
B(-1,1,-6,STONE:0)
B(0,1,-6,STONE:0)
B(1,1,-6,STONE:0)
B(2,1,-6,STONE:0)
B(3,1,-6,STONE:0)
B(4,1,-6,STONE:0)
B(5,1,-6,STONE:0)
B(6,1,-6,STONE:0)
B(-4,1,-5,STONE:0)
B(-3,1,-5,STONE:0)
B(-2,1,-5,STONE:0)
B(-1,1,-5,STONE:0)
B(0,1,-5,STONE:0)
B(1,1,-5,STONE:0)
B(2,1,-5,STONE:0)
B(3,1,-5,STONE:0)
B(4,1,-5,STONE:0)
B(5,1,-5,STONE:0)
B(6,1,-5,STONE:0)
B(7,1,-5,STONE:0)
B(-5,1,-4,STONE:0)
B(-4,1,-4,STONE:0)
B(-3,1,-4,STONE:0)
B(-2,1,-4,STONE:0)
B(-1,1,-4,STONE:0)
B(0,1,-4,STONE:0)
B(1,1,-4,STONE:0)
B(2,1,-4,STONE:0)
B(3,1,-4,STONE:0)
B(4,1,-4,STONE:0)
B(5,1,-4,STONE:0)
B(6,1,-4,STONE:0)
B(7,1,-4,STONE:0)
B(8,1,-4,STONE:0)
B(-6,1,-3,STONE:0)
B(-5,1,-3,STONE:0)
B(-4,1,-3,STONE:0)
B(-3,1,-3,STONE:0)
B(-2,1,-3,STONE:0)
B(-1,1,-3,STONE:0)
B(0,1,-3,STONE:0)
B(1,1,-3,STONE:0)
B(2,1,-3,STONE:0)
B(3,1,-3,STONE:0)
B(4,1,-3,STONE:0)
B(5,1,-3,STONE:0)
B(6,1,-3,STONE:0)
B(7,1,-3,STONE:0)
B(8,1,-3,STONE:0)
B(9,1,-3,STONE:0)
B(-7,1,-2,STONE:0)
B(-6,1,-2,STONE:0)
B(-5,1,-2,STONE:0)
B(-4,1,-2,STONE:0)
B(-3,1,-2,STONE:0)
B(-2,1,-2,STONE:0)
B(-1,1,-2,STONE:0)
B(0,1,-2,STONE:0)
B(1,1,-2,STONE:0)
B(2,1,-2,STONE:0)
B(3,1,-2,STONE:0)
B(4,1,-2,STONE:0)
B(5,1,-2,STONE:0)
B(6,1,-2,STONE:0)
B(7,1,-2,STONE:0)
B(8,1,-2,STONE:0)
B(9,1,-2,STONE:0)
B(-8,1,-1,STONE:0)
B(-7,1,-1,STONE:0)
B(-6,1,-1,STONE:0)
B(-5,1,-1,STONE:0)
B(-4,1,-1,STONE:0)
B(-3,1,-1,STONE:0)
B(-2,1,-1,STONE:0)
B(-1,1,-1,STONE:0)
B(0,1,-1,STONE:0)
B(1,1,-1,STONE:0)
B(2,1,-1,STONE:0)
B(3,1,-1,STONE:0)
B(4,1,-1,STONE:0)
B(5,1,-1,STONE:0)
B(6,1,-1,STONE:0)
B(7,1,-1,STONE:0)
B(8,1,-1,STONE:0)
B(9,1,-1,STONEBRICK:3)
B(-9,1,0,STONE:0)
B(-8,1,0,STONE:0)
B(-7,1,0,STONE:0)
B(-6,1,0,STONE:0)
B(-5,1,0,STONE:0)
B(-4,1,0,STONE:0)
B(-3,1,0,STONE:0)
B(-2,1,0,STONE:0)
B(-1,1,0,STONE:0)
B(0,1,0,STONE:0)
B(1,1,0,STONE:0)
B(2,1,0,STONE:0)
B(3,1,0,STONE:0)
B(4,1,0,STONE:0)
B(5,1,0,STONE:0)
B(6,1,0,STONE:0)
B(7,1,0,STONE:0)
B(8,1,0,STONE:0)
B(9,1,0,STONE:0)
B(-10,1,1,STONE:0)
B(-9,1,1,STONE:0)
B(-8,1,1,STONE:0)
B(-7,1,1,STONE:0)
B(-6,1,1,STONE:0)
B(-5,1,1,STONE:0)
B(-4,1,1,STONE:0)
B(-3,1,1,STONE:0)
B(-2,1,1,STONE:0)
B(-1,1,1,STONE:0)
B(0,1,1,STONE:0)
B(1,1,1,STONE:0)
B(2,1,1,STONE:0)
B(3,1,1,STONE:0)
B(4,1,1,STONE:0)
B(5,1,1,STONE:0)
B(6,1,1,STONE:0)
B(7,1,1,STONE:0)
B(8,1,1,STONE:0)
B(9,1,1,STONE:0)
B(-10,1,2,STONE:0)
B(-9,1,2,STONE:0)
B(-8,1,2,STONE:0)
B(-7,1,2,STONE:0)
B(-6,1,2,STONE:0)
B(-5,1,2,STONE:0)
B(-4,1,2,STONE:0)
B(-3,1,2,STONE:0)
B(-2,1,2,STONE:0)
B(-1,1,2,STONE:0)
B(0,1,2,STONE:0)
B(1,1,2,STONE:0)
B(2,1,2,STONE:0)
B(3,1,2,STONE:0)
B(4,1,2,STONE:0)
B(5,1,2,STONE:0)
B(6,1,2,STONE:0)
B(7,1,2,STONE:0)
B(8,1,2,STONE:0)
B(-9,1,3,STONE:0)
B(-8,1,3,STONE:0)
B(-7,1,3,STONE:0)
B(-6,1,3,STONE:0)
B(-5,1,3,STONE:0)
B(-4,1,3,STONE:0)
B(-3,1,3,STONE:0)
B(-2,1,3,STONE:0)
B(-1,1,3,STONE:0)
B(0,1,3,STONE:0)
B(1,1,3,STONE:0)
B(2,1,3,STONE:0)
B(3,1,3,STONE:0)
B(4,1,3,STONE:0)
B(5,1,3,STONE:0)
B(6,1,3,STONE:0)
B(7,1,3,STONE:0)
B(-9,1,4,STONE:0)
B(-8,1,4,STONE:0)
B(-7,1,4,STONE:0)
B(-6,1,4,STONE:0)
B(-5,1,4,STONE:0)
B(-4,1,4,STONE:0)
B(-3,1,4,STONE:0)
B(-2,1,4,STONE:0)
B(-1,1,4,STONE:0)
B(0,1,4,STONE:0)
B(1,1,4,STONE:0)
B(2,1,4,STONE:0)
B(3,1,4,STONE:0)
B(4,1,4,STONE:0)
B(5,1,4,STONE:0)
B(6,1,4,STONE:0)
B(-8,1,5,STONE:0)
B(-7,1,5,STONE:0)
B(-6,1,5,STONE:0)
B(-5,1,5,STONE:0)
B(-4,1,5,STONE:0)
B(-3,1,5,STONE:0)
B(-2,1,5,STONE:0)
B(-1,1,5,STONE:0)
B(0,1,5,STONE:0)
B(1,1,5,STONE:0)
B(2,1,5,STONE:0)
B(3,1,5,STONE:0)
B(4,1,5,STONE:0)
B(5,1,5,STONE:0)
B(6,1,5,STONE:0)
B(-8,1,6,STONE:0)
B(-7,1,6,STONE:0)
B(-6,1,6,STONE:0)
B(-5,1,6,STONE:0)
B(-4,1,6,STONE:0)
B(-3,1,6,STONE:0)
B(-2,1,6,STONE:0)
B(-1,1,6,STONE:0)
B(0,1,6,STONE:0)
B(1,1,6,STONE:0)
B(2,1,6,STONE:0)
B(3,1,6,STONE:0)
B(4,1,6,STONE:0)
B(5,1,6,STONE:0)
B(6,1,6,STONE:0)
B(-7,1,7,STONE:0)
B(-6,1,7,STONE:0)
B(-5,1,7,STONE:0)
B(-4,1,7,STONE:0)
B(-3,1,7,STONE:0)
B(-2,1,7,STONE:0)
B(-1,1,7,STONE:0)
B(0,1,7,STONE:0)
B(1,1,7,STONE:0)
B(2,1,7,STONE:0)
B(3,1,7,STONE:0)
B(4,1,7,STONE:0)
B(5,1,7,STONE:0)
B(-7,1,8,STONE:0)
B(-6,1,8,STONE:0)
B(-5,1,8,STONE:0)
B(-4,1,8,STONE:0)
B(-3,1,8,STONE:0)
B(-2,1,8,STONE:0)
B(-1,1,8,STONE:0)
B(0,1,8,STONE:0)
B(1,1,8,STONE:0)
B(2,1,8,STONE:0)
B(3,1,8,STONE:0)
B(4,1,8,STONE:0)
B(-6,1,9,STONE:0)
B(-5,1,9,STONE:0)
B(-4,1,9,STONE:0)
B(-3,1,9,STONE:0)
B(-2,1,9,STONE:0)
B(-1,1,9,STONE:0)
B(0,1,9,STONE:0)
B(1,1,9,STONE:0)
B(2,1,9,STONE:0)
B(3,1,9,STONE:0)
B(-5,1,10,STONE:0)
B(-4,1,10,STONE:0)
B(-3,1,10,STONE:0)
B(-2,1,10,STONE:0)
B(-1,1,10,STONE:0)
B(0,1,10,STONE:0)
B(1,1,10,STONE:0)
B(2,1,10,STONE:0)
B(-4,1,11,STONE:0)
B(-3,1,11,STONE:0)
B(-2,1,11,STONE:0)
B(-1,1,11,STONE:0)
B(0,1,11,STONE:0)
B(1,1,11,STONE:0)
B(-1,2,-8,STONE:0)
B(0,2,-8,STONE:0)
B(1,2,-8,STONEBRICK:3)
B(2,2,-8,STONEBRICK:3)
B(3,2,-8,STONE:0)
B(4,2,-8,STONE:0)
B(-2,2,-7,STONE:0)
B(-1,2,-7,STONE:0)
B(0,2,-7,STONE:0)
B(1,2,-7,STONE:0)
B(2,2,-7,STONE:0)
B(3,2,-7,STONE:0)
B(4,2,-7,STONE:0)
B(5,2,-7,STONE:0)
B(-3,2,-6,STONE:0)
B(-2,2,-6,STONE:0)
B(-1,2,-6,STONE:0)
B(0,2,-6,STONE:0)
B(1,2,-6,STONE:0)
B(2,2,-6,STONE:0)
B(3,2,-6,STONE:0)
B(4,2,-6,STONE:0)
B(5,2,-6,STONE:0)
B(6,2,-6,STONE:0)
B(-4,2,-5,STONE:0)
B(-3,2,-5,STONE:0)
B(-2,2,-5,STONE:0)
B(-1,2,-5,STONE:0)
B(0,2,-5,STONE:0)
B(1,2,-5,STONE:0)
B(2,2,-5,STONE:0)
B(3,2,-5,STONE:0)
B(4,2,-5,STONE:0)
B(5,2,-5,STONE:0)
B(6,2,-5,STONE:0)
B(7,2,-5,STONE:0)
B(-5,2,-4,STONE:0)
B(-4,2,-4,STONE:0)
B(-3,2,-4,STONE:0)
B(-2,2,-4,STONE:0)
B(-1,2,-4,STONE:0)
B(0,2,-4,STONE:0)
B(1,2,-4,STONE:0)
B(2,2,-4,STONE:0)
B(3,2,-4,STONE:0)
B(4,2,-4,STONE:0)
B(5,2,-4,STONE:0)
B(6,2,-4,STONE:0)
B(7,2,-4,STONE:0)
B(8,2,-4,STONE:0)
B(-6,2,-3,STONE:0)
B(-5,2,-3,STONE:0)
B(-4,2,-3,STONE:0)
B(-3,2,-3,STONE:0)
B(-2,2,-3,STONE:0)
B(-1,2,-3,STONE:0)
B(0,2,-3,STONE:0)
B(1,2,-3,STONE:0)
B(2,2,-3,STONE:0)
B(3,2,-3,STONE:0)
B(4,2,-3,STONE:0)
B(5,2,-3,STONE:0)
B(6,2,-3,STONE:0)
B(7,2,-3,STONE:0)
B(8,2,-3,STONE:0)
B(9,2,-3,STONE:0)
B(-7,2,-2,STONE:0)
B(-6,2,-2,STONE:0)
B(-5,2,-2,STONE:0)
B(-4,2,-2,STONE:0)
B(-3,2,-2,STONE:0)
B(-2,2,-2,STONE:0)
B(-1,2,-2,STONE:0)
B(0,2,-2,STONE:0)
B(1,2,-2,STONE:0)
B(2,2,-2,STONE:0)
B(3,2,-2,STONE:0)
B(4,2,-2,STONE:0)
B(5,2,-2,STONE:0)
B(6,2,-2,STONE:0)
B(7,2,-2,STONE:0)
B(8,2,-2,STONE:0)
B(9,2,-2,STONEBRICK:3)
B(-8,2,-1,STONE:0)
B(-7,2,-1,STONE:0)
B(-6,2,-1,STONE:0)
B(-5,2,-1,STONE:0)
B(-4,2,-1,STONE:0)
B(-3,2,-1,STONE:0)
B(-2,2,-1,STONE:0)
B(-1,2,-1,STONE:0)
B(0,2,-1,STONE:0)
B(1,2,-1,STONE:0)
B(2,2,-1,STONE:0)
B(3,2,-1,STONE:0)
B(4,2,-1,STONE:0)
B(5,2,-1,STONE:0)
B(6,2,-1,STONE:0)
B(7,2,-1,STONE:0)
B(8,2,-1,STONE:0)
B(9,2,-1,STONEBRICK:3)
B(-9,2,0,STONE:0)
B(-8,2,0,STONE:0)
B(-7,2,0,STONE:0)
B(-6,2,0,STONE:0)
B(-5,2,0,STONE:0)
B(-4,2,0,STONE:0)
B(-3,2,0,STONE:0)
B(-2,2,0,STONE:0)
B(-1,2,0,STONE:0)
B(0,2,0,STONE:0)
B(1,2,0,STONE:0)
B(2,2,0,STONE:0)
B(3,2,0,STONE:0)
B(4,2,0,STONE:0)
B(5,2,0,STONE:0)
B(6,2,0,STONE:0)
B(7,2,0,STONE:0)
B(8,2,0,STONE:0)
B(9,2,0,STONEBRICK:3)
B(-10,2,1,STONE:0)
B(-9,2,1,STONE:0)
B(-8,2,1,STONE:0)
B(-7,2,1,STONE:0)
B(-6,2,1,STONE:0)
B(-5,2,1,STONE:0)
B(-4,2,1,STONE:0)
B(-3,2,1,STONE:0)
B(-2,2,1,STONE:0)
B(-1,2,1,STONE:0)
B(0,2,1,STONE:0)
B(1,2,1,STONE:0)
B(2,2,1,STONE:0)
B(3,2,1,STONE:0)
B(4,2,1,STONE:0)
B(5,2,1,STONE:0)
B(6,2,1,STONE:0)
B(7,2,1,STONE:0)
B(8,2,1,STONE:0)
B(9,2,1,STONE:0)
B(-10,2,2,STONE:0)
B(-9,2,2,STONE:0)
B(-8,2,2,STONE:0)
B(-7,2,2,STONE:0)
B(-6,2,2,STONE:0)
B(-5,2,2,STONE:0)
B(-4,2,2,STONE:0)
B(-3,2,2,STONE:0)
B(-2,2,2,STONE:0)
B(-1,2,2,STONE:0)
B(0,2,2,STONE:0)
B(1,2,2,STONE:0)
B(2,2,2,STONE:0)
B(3,2,2,STONE:0)
B(4,2,2,STONE:0)
B(5,2,2,STONE:0)
B(6,2,2,STONE:0)
B(7,2,2,STONE:0)
B(-9,2,3,STONE:0)
B(-8,2,3,STONE:0)
B(-7,2,3,STONE:0)
B(-6,2,3,STONE:0)
B(-5,2,3,STONE:0)
B(-4,2,3,STONE:0)
B(-3,2,3,STONE:0)
B(-2,2,3,STONE:0)
B(-1,2,3,STONE:0)
B(0,2,3,STONE:0)
B(1,2,3,STONE:0)
B(2,2,3,STONE:0)
B(3,2,3,STONE:0)
B(4,2,3,STONE:0)
B(5,2,3,STONE:0)
B(6,2,3,STONE:0)
B(7,2,3,STONE:0)
B(-9,2,4,STONE:0)
B(-8,2,4,STONE:0)
B(-7,2,4,STONE:0)
B(-6,2,4,STONE:0)
B(-5,2,4,STONE:0)
B(-4,2,4,STONE:0)
B(-3,2,4,STONE:0)
B(-2,2,4,STONE:0)
B(-1,2,4,STONE:0)
B(0,2,4,STONE:0)
B(1,2,4,STONE:0)
B(2,2,4,STONE:0)
B(3,2,4,STONE:0)
B(4,2,4,STONE:0)
B(5,2,4,STONE:0)
B(6,2,4,STONE:0)
B(-8,2,5,STONE:0)
B(-7,2,5,STONE:0)
B(-6,2,5,STONE:0)
B(-5,2,5,STONE:0)
B(-4,2,5,STONE:0)
B(-3,2,5,STONE:0)
B(-2,2,5,STONE:0)
B(-1,2,5,STONE:0)
B(0,2,5,STONE:0)
B(1,2,5,STONE:0)
B(2,2,5,STONE:0)
B(3,2,5,STONE:0)
B(4,2,5,STONE:0)
B(5,2,5,STONE:0)
B(6,2,5,STONE:0)
B(-8,2,6,STONE:0)
B(-7,2,6,STONE:0)
B(-6,2,6,STONE:0)
B(-5,2,6,STONE:0)
B(-4,2,6,STONE:0)
B(-3,2,6,STONE:0)
B(-2,2,6,STONE:0)
B(-1,2,6,STONE:0)
B(0,2,6,STONE:0)
B(1,2,6,STONE:0)
B(2,2,6,STONE:0)
B(3,2,6,STONE:0)
B(4,2,6,STONE:0)
B(5,2,6,STONE:0)
B(-7,2,7,STONE:0)
B(-6,2,7,STONE:0)
B(-5,2,7,STONE:0)
B(-4,2,7,STONE:0)
B(-3,2,7,STONE:0)
B(-2,2,7,STONE:0)
B(-1,2,7,STONE:0)
B(0,2,7,STONE:0)
B(1,2,7,STONE:0)
B(2,2,7,STONE:0)
B(3,2,7,STONE:0)
B(4,2,7,STONE:0)
B(5,2,7,STONE:0)
B(-7,2,8,STONE:0)
B(-6,2,8,STONE:0)
B(-5,2,8,STONE:0)
B(-4,2,8,STONE:0)
B(-3,2,8,STONE:0)
B(-2,2,8,STONE:0)
B(-1,2,8,STONE:0)
B(0,2,8,STONE:0)
B(1,2,8,STONE:0)
B(2,2,8,STONE:0)
B(3,2,8,STONE:0)
B(4,2,8,STONE:0)
B(-6,2,9,STONE:0)
B(-5,2,9,STONE:0)
B(-4,2,9,STONE:0)
B(-3,2,9,STONE:0)
B(-2,2,9,STONE:0)
B(-1,2,9,STONE:0)
B(0,2,9,STONE:0)
B(1,2,9,STONE:0)
B(2,2,9,STONE:0)
B(3,2,9,STONE:0)
B(-5,2,10,STONE:0)
B(-4,2,10,STONE:0)
B(-3,2,10,STONE:0)
B(-2,2,10,STONE:0)
B(-1,2,10,STONE:0)
B(0,2,10,STONE:0)
B(1,2,10,STONE:0)
B(-4,2,11,STONE:0)
B(-3,2,11,STONE:0)
B(-2,2,11,STONEBRICK:3)
B(-1,2,11,STONEBRICK:3)
B(0,2,11,STONE:0)
B(1,2,11,STONE:0)
B(-1,3,-8,STONE:0)
B(0,3,-8,STONE:0)
B(1,3,-8,STONEBRICK:3)
B(2,3,-8,STONEBRICK:3)
B(3,3,-8,STONE:0)
B(4,3,-8,STONE:0)
B(-2,3,-7,STONE:0)
B(-1,3,-7,STONE:0)
B(0,3,-7,STONE:0)
B(1,3,-7,STONE:0)
B(2,3,-7,STONE:0)
B(3,3,-7,STONE:0)
B(4,3,-7,STONE:0)
B(-3,3,-6,STONE:0)
B(-2,3,-6,STONE:0)
B(-1,3,-6,STONE:0)
B(0,3,-6,STONE:0)
B(1,3,-6,STONE:0)
B(2,3,-6,STONE:0)
B(3,3,-6,STONE:0)
B(4,3,-6,STONE:0)
B(5,3,-6,STONE:0)
B(-4,3,-5,STONE:0)
B(-3,3,-5,STONE:0)
B(-2,3,-5,STONE:0)
B(-1,3,-5,STONE:0)
B(0,3,-5,STONE:0)
B(1,3,-5,STONE:0)
B(2,3,-5,STONE:0)
B(3,3,-5,STONE:0)
B(4,3,-5,STONE:0)
B(5,3,-5,STONE:0)
B(6,3,-5,STONE:0)
B(-5,3,-4,STONE:0)
B(-4,3,-4,STONE:0)
B(-3,3,-4,STONE:0)
B(-2,3,-4,STONE:0)
B(-1,3,-4,STONE:0)
B(0,3,-4,STONE:0)
B(1,3,-4,STONE:0)
B(2,3,-4,STONE:0)
B(3,3,-4,STONE:0)
B(4,3,-4,STONE:0)
B(5,3,-4,STONE:0)
B(6,3,-4,STONE:0)
B(7,3,-4,STONE:0)
B(8,3,-4,STONE:0)
B(-6,3,-3,STONE:0)
B(-5,3,-3,STONE:0)
B(-4,3,-3,STONE:0)
B(-3,3,-3,STONE:0)
B(-2,3,-3,STONE:0)
B(-1,3,-3,STONE:0)
B(0,3,-3,STONE:0)
B(1,3,-3,STONE:0)
B(2,3,-3,STONE:0)
B(3,3,-3,STONE:0)
B(4,3,-3,STONE:0)
B(5,3,-3,STONE:0)
B(6,3,-3,STONE:0)
B(7,3,-3,STONE:0)
B(8,3,-3,STONE:0)
B(-7,3,-2,STONE:0)
B(-6,3,-2,STONE:0)
B(-5,3,-2,STONE:0)
B(-4,3,-2,STONE:0)
B(-3,3,-2,STONE:0)
B(-2,3,-2,STONE:0)
B(-1,3,-2,STONE:0)
B(0,3,-2,STONE:0)
B(1,3,-2,STONE:0)
B(2,3,-2,STONE:0)
B(3,3,-2,STONE:0)
B(4,3,-2,STONE:0)
B(5,3,-2,STONE:0)
B(6,3,-2,STONE:0)
B(7,3,-2,STONE:0)
B(8,3,-2,STONE:0)
B(9,3,-2,STONE:0)
B(-8,3,-1,STONE:0)
B(-7,3,-1,STONE:0)
B(-6,3,-1,STONE:0)
B(-5,3,-1,STONE:0)
B(-4,3,-1,STONE:0)
B(-3,3,-1,STONE:0)
B(-2,3,-1,STONE:0)
B(-1,3,-1,STONE:0)
B(0,3,-1,STONE:0)
B(1,3,-1,STONE:0)
B(2,3,-1,STONE:0)
B(3,3,-1,STONE:0)
B(4,3,-1,STONE:0)
B(5,3,-1,STONE:0)
B(6,3,-1,STONE:0)
B(7,3,-1,STONE:0)
B(8,3,-1,STONE:0)
B(9,3,-1,STONEBRICK:3)
B(-9,3,0,STONE:0)
B(-8,3,0,STONE:0)
B(-7,3,0,STONE:0)
B(-6,3,0,STONE:0)
B(-5,3,0,STONE:0)
B(-4,3,0,STONE:0)
B(-3,3,0,STONE:0)
B(-2,3,0,STONE:0)
B(-1,3,0,STONE:0)
B(0,3,0,STONE:0)
B(1,3,0,STONE:0)
B(2,3,0,STONE:0)
B(3,3,0,STONE:0)
B(4,3,0,STONE:0)
B(5,3,0,STONE:0)
B(6,3,0,STONE:0)
B(7,3,0,STONE:0)
B(8,3,0,STONE:0)
B(9,3,0,STONE:0)
B(-10,3,1,STONE:0)
B(-9,3,1,STONE:0)
B(-8,3,1,STONE:0)
B(-7,3,1,STONE:0)
B(-6,3,1,STONE:0)
B(-5,3,1,STONE:0)
B(-4,3,1,STONE:0)
B(-3,3,1,STONE:0)
B(-2,3,1,STONE:0)
B(-1,3,1,STONE:0)
B(0,3,1,STONE:0)
B(1,3,1,STONE:0)
B(2,3,1,STONE:0)
B(3,3,1,STONE:0)
B(4,3,1,STONE:0)
B(5,3,1,STONE:0)
B(6,3,1,STONE:0)
B(7,3,1,STONE:0)
B(8,3,1,STONE:0)
B(-10,3,2,STONE:0)
B(-9,3,2,STONE:0)
B(-8,3,2,STONE:0)
B(-7,3,2,STONE:0)
B(-6,3,2,STONE:0)
B(-5,3,2,STONE:0)
B(-4,3,2,STONE:0)
B(-3,3,2,STONE:0)
B(-2,3,2,STONE:0)
B(-1,3,2,STONE:0)
B(0,3,2,STONE:0)
B(1,3,2,STONE:0)
B(2,3,2,STONE:0)
B(3,3,2,STONE:0)
B(4,3,2,STONE:0)
B(5,3,2,STONE:0)
B(6,3,2,STONE:0)
B(7,3,2,STONE:0)
B(-9,3,3,STONE:0)
B(-8,3,3,STONE:0)
B(-7,3,3,STONE:0)
B(-6,3,3,STONE:0)
B(-5,3,3,STONE:0)
B(-4,3,3,STONE:0)
B(-3,3,3,STONE:0)
B(-2,3,3,STONE:0)
B(-1,3,3,STONE:0)
B(0,3,3,STONE:0)
B(1,3,3,STONE:0)
B(2,3,3,STONE:0)
B(3,3,3,STONE:0)
B(4,3,3,STONE:0)
B(5,3,3,STONE:0)
B(6,3,3,STONE:0)
B(-9,3,4,STONE:0)
B(-8,3,4,STONE:0)
B(-7,3,4,STONE:0)
B(-6,3,4,STONE:0)
B(-5,3,4,STONE:0)
B(-4,3,4,STONE:0)
B(-3,3,4,STONE:0)
B(-2,3,4,STONE:0)
B(-1,3,4,STONE:0)
B(0,3,4,STONE:0)
B(1,3,4,STONE:0)
B(2,3,4,STONE:0)
B(3,3,4,STONE:0)
B(4,3,4,STONE:0)
B(5,3,4,STONE:0)
B(6,3,4,STONE:0)
B(-8,3,5,STONE:0)
B(-7,3,5,STONE:0)
B(-6,3,5,STONE:0)
B(-5,3,5,STONE:0)
B(-4,3,5,STONE:0)
B(-3,3,5,STONE:0)
B(-2,3,5,STONE:0)
B(-1,3,5,STONE:0)
B(0,3,5,STONE:0)
B(1,3,5,STONE:0)
B(2,3,5,STONE:0)
B(3,3,5,STONE:0)
B(4,3,5,STONE:0)
B(5,3,5,STONE:0)
B(6,3,5,STONE:0)
B(-8,3,6,STONE:0)
B(-7,3,6,STONE:0)
B(-6,3,6,STONE:0)
B(-5,3,6,STONE:0)
B(-4,3,6,STONE:0)
B(-3,3,6,STONE:0)
B(-2,3,6,STONE:0)
B(-1,3,6,STONE:0)
B(0,3,6,STONE:0)
B(1,3,6,STONE:0)
B(2,3,6,STONE:0)
B(3,3,6,STONE:0)
B(4,3,6,STONE:0)
B(5,3,6,STONE:0)
B(-7,3,7,STONE:0)
B(-6,3,7,STONE:0)
B(-5,3,7,STONE:0)
B(-4,3,7,STONE:0)
B(-3,3,7,STONE:0)
B(-2,3,7,STONE:0)
B(-1,3,7,STONE:0)
B(0,3,7,STONE:0)
B(1,3,7,STONE:0)
B(2,3,7,STONE:0)
B(3,3,7,STONE:0)
B(4,3,7,STONE:0)
B(-7,3,8,STONE:0)
B(-6,3,8,STONE:0)
B(-5,3,8,STONE:0)
B(-4,3,8,STONE:0)
B(-3,3,8,STONE:0)
B(-2,3,8,STONE:0)
B(-1,3,8,STONE:0)
B(0,3,8,STONE:0)
B(1,3,8,STONE:0)
B(2,3,8,STONE:0)
B(3,3,8,STONE:0)
B(-6,3,9,STONE:0)
B(-5,3,9,STONE:0)
B(-4,3,9,STONE:0)
B(-3,3,9,STONE:0)
B(-2,3,9,STONE:0)
B(-1,3,9,STONE:0)
B(0,3,9,STONE:0)
B(1,3,9,STONE:0)
B(2,3,9,STONE:0)
B(3,3,9,STONE:0)
B(-5,3,10,STONE:0)
B(-4,3,10,STONE:0)
B(-3,3,10,STONE:0)
B(-2,3,10,STONE:0)
B(-1,3,10,STONE:0)
B(0,3,10,STONE:0)
B(1,3,10,STONE:0)
B(-4,3,11,STONE:0)
B(-3,3,11,STONE:0)
B(-2,3,11,STONEBRICK:3)
B(-1,3,11,STONEBRICK:3)
B(0,3,11,STONE:0)
B(-1,4,-8,STONE:0)
B(0,4,-8,STONE:0)
B(1,4,-8,STONEBRICK:3)
B(2,4,-8,STONEBRICK:3)
B(3,4,-8,STONE:0)
B(-1,4,-7,STONE:0)
B(0,4,-7,STONE:0)
B(1,4,-7,STONE:0)
B(2,4,-7,STONE:0)
B(3,4,-7,STONE:0)
B(4,4,-7,STONE:0)
B(-2,4,-6,STONE:0)
B(-1,4,-6,STONE:0)
B(0,4,-6,STONE:0)
B(1,4,-6,STONE:0)
B(2,4,-6,STONE:0)
B(3,4,-6,STONE:0)
B(4,4,-6,STONE:0)
B(5,4,-6,STONE:0)
B(-4,4,-5,STONE:0)
B(-3,4,-5,STONE:0)
B(-2,4,-5,STONE:0)
B(-1,4,-5,STONE:0)
B(0,4,-5,STONE:0)
B(1,4,-5,STONE:0)
B(2,4,-5,STONE:0)
B(3,4,-5,STONE:0)
B(4,4,-5,STONE:0)
B(5,4,-5,STONE:0)
B(6,4,-5,STONE:0)
B(-4,4,-4,STONE:0)
B(-3,4,-4,STONE:0)
B(-2,4,-4,STONE:0)
B(-1,4,-4,STONE:0)
B(0,4,-4,STONE:0)
B(1,4,-4,STONE:0)
B(2,4,-4,STONE:0)
B(3,4,-4,STONE:0)
B(4,4,-4,STONE:0)
B(5,4,-4,STONE:0)
B(6,4,-4,STONE:0)
B(7,4,-4,STONE:0)
B(-5,4,-3,STONE:0)
B(-4,4,-3,STONE:0)
B(-3,4,-3,STONE:0)
B(-2,4,-3,STONE:0)
B(-1,4,-3,STONE:0)
B(0,4,-3,STONE:0)
B(1,4,-3,STONE:0)
B(2,4,-3,STONE:0)
B(3,4,-3,STONE:0)
B(4,4,-3,STONE:0)
B(5,4,-3,STONE:0)
B(6,4,-3,STONE:0)
B(7,4,-3,STONE:0)
B(8,4,-3,STONE:0)
B(-6,4,-2,STONE:0)
B(-5,4,-2,STONE:0)
B(-4,4,-2,STONE:0)
B(-3,4,-2,STONE:0)
B(-2,4,-2,STONE:0)
B(-1,4,-2,STONE:0)
B(0,4,-2,STONE:0)
B(1,4,-2,STONE:0)
B(2,4,-2,STONE:0)
B(3,4,-2,STONE:0)
B(4,4,-2,STONE:0)
B(5,4,-2,STONE:0)
B(6,4,-2,STONE:0)
B(7,4,-2,STONE:0)
B(8,4,-2,STONE:0)
B(-8,4,-1,STONE:0)
B(-7,4,-1,STONE:0)
B(-6,4,-1,STONE:0)
B(-5,4,-1,STONE:0)
B(-4,4,-1,STONE:0)
B(-3,4,-1,STONE:0)
B(-2,4,-1,STONE:0)
B(-1,4,-1,STONE:0)
B(0,4,-1,STONE:0)
B(1,4,-1,STONE:0)
B(2,4,-1,STONE:0)
B(3,4,-1,STONE:0)
B(4,4,-1,STONE:0)
B(5,4,-1,STONE:0)
B(6,4,-1,STONE:0)
B(7,4,-1,STONE:0)
B(8,4,-1,STONE:0)
B(-9,4,0,STONE:0)
B(-8,4,0,STONE:0)
B(-7,4,0,STONE:0)
B(-6,4,0,STONE:0)
B(-5,4,0,STONE:0)
B(-4,4,0,STONE:0)
B(-3,4,0,STONE:0)
B(-2,4,0,STONE:0)
B(-1,4,0,STONE:0)
B(0,4,0,STONE:0)
B(1,4,0,STONE:0)
B(2,4,0,STONE:0)
B(3,4,0,STONE:0)
B(4,4,0,STONE:0)
B(5,4,0,STONE:0)
B(6,4,0,STONE:0)
B(7,4,0,STONE:0)
B(8,4,0,STONE:0)
B(-10,4,1,STONE:0)
B(-9,4,1,STONE:0)
B(-8,4,1,STONE:0)
B(-7,4,1,STONE:0)
B(-6,4,1,STONE:0)
B(-5,4,1,STONE:0)
B(-4,4,1,STONE:0)
B(-3,4,1,STONE:0)
B(-2,4,1,STONE:0)
B(-1,4,1,STONE:0)
B(0,4,1,STONE:0)
B(1,4,1,STONE:0)
B(2,4,1,STONE:0)
B(3,4,1,STONE:0)
B(4,4,1,STONE:0)
B(5,4,1,STONE:0)
B(6,4,1,STONE:0)
B(7,4,1,STONE:0)
B(-10,4,2,STONE:0)
B(-9,4,2,STONE:0)
B(-8,4,2,STONE:0)
B(-7,4,2,STONE:0)
B(-6,4,2,STONE:0)
B(-5,4,2,STONE:0)
B(-4,4,2,STONE:0)
B(-3,4,2,STONE:0)
B(-2,4,2,STONE:0)
B(-1,4,2,STONE:0)
B(0,4,2,STONE:0)
B(1,4,2,STONE:0)
B(2,4,2,STONE:0)
B(3,4,2,STONE:0)
B(4,4,2,STONE:0)
B(5,4,2,STONE:0)
B(6,4,2,STONE:0)
B(7,4,2,STONE:0)
B(-9,4,3,STONE:0)
B(-8,4,3,STONE:0)
B(-7,4,3,STONE:0)
B(-6,4,3,STONE:0)
B(-5,4,3,STONE:0)
B(-4,4,3,STONE:0)
B(-3,4,3,STONE:0)
B(-2,4,3,STONE:0)
B(-1,4,3,STONE:0)
B(0,4,3,STONE:0)
B(1,4,3,STONE:0)
B(2,4,3,STONE:0)
B(3,4,3,STONE:0)
B(4,4,3,STONE:0)
B(5,4,3,STONE:0)
B(6,4,3,STONE:0)
B(-8,4,4,STONE:0)
B(-7,4,4,STONE:0)
B(-6,4,4,STONE:0)
B(-5,4,4,STONE:0)
B(-4,4,4,STONE:0)
B(-3,4,4,STONE:0)
B(-2,4,4,STONE:0)
B(-1,4,4,STONE:0)
B(0,4,4,STONE:0)
B(1,4,4,STONE:0)
B(2,4,4,STONE:0)
B(3,4,4,STONE:0)
B(4,4,4,STONE:0)
B(5,4,4,STONE:0)
B(-8,4,5,STONE:0)
B(-7,4,5,STONE:0)
B(-6,4,5,STONE:0)
B(-5,4,5,STONE:0)
B(-4,4,5,STONE:0)
B(-3,4,5,STONE:0)
B(-2,4,5,STONE:0)
B(-1,4,5,STONE:0)
B(0,4,5,STONE:0)
B(1,4,5,STONE:0)
B(2,4,5,STONE:0)
B(3,4,5,STONE:0)
B(4,4,5,STONE:0)
B(5,4,5,STONE:0)
B(-8,4,6,STONE:0)
B(-7,4,6,STONE:0)
B(-6,4,6,STONE:0)
B(-5,4,6,STONE:0)
B(-4,4,6,STONE:0)
B(-3,4,6,STONE:0)
B(-2,4,6,STONE:0)
B(-1,4,6,STONE:0)
B(0,4,6,STONE:0)
B(1,4,6,STONE:0)
B(2,4,6,STONE:0)
B(3,4,6,STONE:0)
B(4,4,6,STONE:0)
B(5,4,6,STONE:0)
B(-7,4,7,STONE:0)
B(-6,4,7,STONE:0)
B(-5,4,7,STONE:0)
B(-4,4,7,STONE:0)
B(-3,4,7,STONE:0)
B(-2,4,7,STONE:0)
B(-1,4,7,STONE:0)
B(0,4,7,STONE:0)
B(1,4,7,STONE:0)
B(2,4,7,STONE:0)
B(3,4,7,STONE:0)
B(4,4,7,STONE:0)
B(-7,4,8,STONE:0)
B(-6,4,8,STONE:0)
B(-5,4,8,STONE:0)
B(-4,4,8,STONE:0)
B(-3,4,8,STONE:0)
B(-2,4,8,STONE:0)
B(-1,4,8,STONE:0)
B(0,4,8,STONE:0)
B(1,4,8,STONE:0)
B(2,4,8,STONE:0)
B(3,4,8,STONE:0)
B(-6,4,9,STONE:0)
B(-5,4,9,STONE:0)
B(-4,4,9,STONE:0)
B(-3,4,9,STONE:0)
B(-2,4,9,STONE:0)
B(-1,4,9,STONE:0)
B(0,4,9,STONE:0)
B(1,4,9,STONE:0)
B(2,4,9,STONE:0)
B(-5,4,10,STONE:0)
B(-4,4,10,STONE:0)
B(-3,4,10,STONE:0)
B(-2,4,10,STONE:0)
B(-1,4,10,STONE:0)
B(0,4,10,STONE:0)
B(1,4,10,STONE:0)
B(-3,4,11,STONE:0)
B(-2,4,11,STONE:0)
B(-1,4,11,STONE:0)
B(0,4,11,STONE:0)
B(-1,5,-8,STONE:0)
B(0,5,-8,STONE:0)
B(1,5,-8,STONE:0)
B(2,5,-8,STONE:0)
B(3,5,-8,STONE:0)
B(-1,5,-7,STONE:0)
B(0,5,-7,STONE:0)
B(1,5,-7,STONE:0)
B(2,5,-7,STONE:0)
B(3,5,-7,STONE:0)
B(4,5,-7,STONE:0)
B(-2,5,-6,STONE:0)
B(-1,5,-6,STONE:0)
B(0,5,-6,STONE:0)
B(1,5,-6,STONE:0)
B(2,5,-6,STONE:0)
B(3,5,-6,STONE:0)
B(4,5,-6,STONE:0)
B(-3,5,-5,STONE:0)
B(-2,5,-5,STONE:0)
B(-1,5,-5,STONE:0)
B(0,5,-5,STONE:0)
B(1,5,-5,STONE:0)
B(2,5,-5,STONE:0)
B(3,5,-5,STONE:0)
B(4,5,-5,STONE:0)
B(5,5,-5,STONE:0)
B(6,5,-5,STONE:0)
B(-4,5,-4,STONE:0)
B(-3,5,-4,STONE:0)
B(-2,5,-4,STONE:0)
B(-1,5,-4,STONE:0)
B(0,5,-4,STONE:0)
B(1,5,-4,STONE:0)
B(2,5,-4,STONE:0)
B(3,5,-4,STONE:0)
B(4,5,-4,STONE:0)
B(5,5,-4,STONE:0)
B(6,5,-4,STONE:0)
B(7,5,-4,STONE:0)
B(-4,5,-3,STONE:0)
B(-3,5,-3,STONE:0)
B(-2,5,-3,STONE:0)
B(-1,5,-3,STONE:0)
B(0,5,-3,STONE:0)
B(1,5,-3,STONE:0)
B(2,5,-3,STONE:0)
B(3,5,-3,STONE:0)
B(4,5,-3,STONE:0)
B(5,5,-3,STONE:0)
B(6,5,-3,STONE:0)
B(7,5,-3,STONE:0)
B(8,5,-3,STONE:0)
B(-5,5,-2,STONE:0)
B(-4,5,-2,STONE:0)
B(-3,5,-2,STONE:0)
B(-2,5,-2,STONE:0)
B(-1,5,-2,STONE:0)
B(0,5,-2,STONE:0)
B(1,5,-2,STONE:0)
B(2,5,-2,STONE:0)
B(3,5,-2,STONE:0)
B(4,5,-2,STONE:0)
B(5,5,-2,STONE:0)
B(6,5,-2,STONE:0)
B(7,5,-2,STONE:0)
B(8,5,-2,STONE:0)
B(-7,5,-1,STONE:0)
B(-6,5,-1,STONE:0)
B(-5,5,-1,STONE:0)
B(-4,5,-1,STONE:0)
B(-3,5,-1,STONE:0)
B(-2,5,-1,STONE:0)
B(-1,5,-1,STONE:0)
B(0,5,-1,STONE:0)
B(1,5,-1,STONE:0)
B(2,5,-1,STONE:0)
B(3,5,-1,STONE:0)
B(4,5,-1,STONE:0)
B(5,5,-1,STONE:0)
B(6,5,-1,STONE:0)
B(7,5,-1,STONE:0)
B(-9,5,0,STONE:0)
B(-8,5,0,STONE:0)
B(-7,5,0,STONE:0)
B(-6,5,0,STONE:0)
B(-5,5,0,STONE:0)
B(-4,5,0,STONE:0)
B(-3,5,0,STONE:0)
B(-2,5,0,STONE:0)
B(-1,5,0,STONE:0)
B(0,5,0,STONE:0)
B(1,5,0,STONE:0)
B(2,5,0,STONE:0)
B(3,5,0,STONE:0)
B(4,5,0,STONE:0)
B(5,5,0,STONE:0)
B(6,5,0,STONE:0)
B(7,5,0,STONE:0)
B(-9,5,1,STONE:0)
B(-8,5,1,STONE:0)
B(-7,5,1,STONE:0)
B(-6,5,1,STONE:0)
B(-5,5,1,STONE:0)
B(-4,5,1,STONE:0)
B(-3,5,1,STONE:0)
B(-2,5,1,STONE:0)
B(-1,5,1,STONE:0)
B(0,5,1,STONE:0)
B(1,5,1,STONE:0)
B(2,5,1,STONE:0)
B(3,5,1,STONE:0)
B(4,5,1,STONE:0)
B(5,5,1,STONE:0)
B(6,5,1,STONE:0)
B(7,5,1,STONE:0)
B(-9,5,2,STONE:0)
B(-8,5,2,STONE:0)
B(-7,5,2,STONE:0)
B(-6,5,2,STONE:0)
B(-5,5,2,STONE:0)
B(-4,5,2,STONE:0)
B(-3,5,2,STONE:0)
B(-2,5,2,STONE:0)
B(-1,5,2,STONE:0)
B(0,5,2,STONE:0)
B(1,5,2,STONE:0)
B(2,5,2,STONE:0)
B(3,5,2,STONE:0)
B(4,5,2,STONE:0)
B(5,5,2,STONE:0)
B(6,5,2,STONE:0)
B(-8,5,3,STONE:0)
B(-7,5,3,STONE:0)
B(-6,5,3,STONE:0)
B(-5,5,3,STONE:0)
B(-4,5,3,STONE:0)
B(-3,5,3,STONE:0)
B(-2,5,3,STONE:0)
B(-1,5,3,STONE:0)
B(0,5,3,STONE:0)
B(1,5,3,STONE:0)
B(2,5,3,STONE:0)
B(3,5,3,STONE:0)
B(4,5,3,STONE:0)
B(5,5,3,STONE:0)
B(6,5,3,STONE:0)
B(-7,5,4,STONE:0)
B(-6,5,4,STONE:0)
B(-5,5,4,STONE:0)
B(-4,5,4,STONE:0)
B(-3,5,4,STONE:0)
B(-2,5,4,STONE:0)
B(-1,5,4,STONE:0)
B(0,5,4,STONE:0)
B(1,5,4,STONE:0)
B(2,5,4,STONE:0)
B(3,5,4,STONE:0)
B(4,5,4,STONE:0)
B(-7,5,5,STONE:0)
B(-6,5,5,STONE:0)
B(-5,5,5,STONE:0)
B(-4,5,5,STONE:0)
B(-3,5,5,STONE:0)
B(-2,5,5,STONE:0)
B(-1,5,5,STONE:0)
B(0,5,5,STONE:0)
B(1,5,5,STONE:0)
B(2,5,5,STONE:0)
B(3,5,5,STONE:0)
B(4,5,5,STONE:0)
B(-7,5,6,STONE:0)
B(-6,5,6,STONE:0)
B(-5,5,6,STONE:0)
B(-4,5,6,STONE:0)
B(-3,5,6,STONE:0)
B(-2,5,6,STONE:0)
B(-1,5,6,STONE:0)
B(0,5,6,STONE:0)
B(1,5,6,STONE:0)
B(2,5,6,STONE:0)
B(3,5,6,STONE:0)
B(4,5,6,STONE:0)
B(5,5,6,STONE:0)
B(-7,5,7,STONE:0)
B(-6,5,7,STONE:0)
B(-5,5,7,STONE:0)
B(-4,5,7,STONE:0)
B(-3,5,7,STONE:0)
B(-2,5,7,STONE:0)
B(-1,5,7,STONE:0)
B(0,5,7,STONE:0)
B(1,5,7,STONE:0)
B(2,5,7,STONE:0)
B(3,5,7,STONE:0)
B(-7,5,8,STONE:0)
B(-6,5,8,STONE:0)
B(-5,5,8,STONE:0)
B(-4,5,8,STONE:0)
B(-3,5,8,STONE:0)
B(-2,5,8,STONE:0)
B(-1,5,8,STONE:0)
B(0,5,8,STONE:0)
B(1,5,8,STONE:0)
B(2,5,8,STONE:0)
B(-6,5,9,STONE:0)
B(-5,5,9,STONE:0)
B(-4,5,9,STONE:0)
B(-3,5,9,STONE:0)
B(-2,5,9,STONE:0)
B(-1,5,9,STONE:0)
B(0,5,9,STONE:0)
B(1,5,9,STONE:0)
B(2,5,9,STONE:0)
B(-3,5,10,STONE:0)
B(-2,5,10,STONE:0)
B(-1,5,10,STONE:0)
B(0,5,10,STONE:0)
B(1,5,10,STONE:0)
B(-1,5,11,STONE:0)
B(0,6,-8,STONE:0)
B(1,6,-8,STONE:0)
B(2,6,-8,STONE:0)
B(3,6,-8,STONE:0)
B(-1,6,-7,STONE:0)
B(0,6,-7,STONE:0)
B(1,6,-7,STONE:0)
B(2,6,-7,STONE:0)
B(3,6,-7,STONE:0)
B(-1,6,-6,STONE:0)
B(0,6,-6,STONE:0)
B(1,6,-6,STONE:0)
B(2,6,-6,STONE:0)
B(3,6,-6,STONE:0)
B(4,6,-6,STONE:0)
B(-2,6,-5,STONE:0)
B(-1,6,-5,STONE:0)
B(0,6,-5,STONE:0)
B(1,6,-5,STONE:0)
B(2,6,-5,STONE:0)
B(3,6,-5,STONE:0)
B(4,6,-5,STONE:0)
B(5,6,-5,STONE:0)
B(-4,6,-4,STONE:0)
B(-3,6,-4,STONE:0)
B(-2,6,-4,STONE:0)
B(-1,6,-4,STONE:0)
B(0,6,-4,STONE:0)
B(1,6,-4,STONE:0)
B(2,6,-4,STONE:0)
B(3,6,-4,STONE:0)
B(4,6,-4,STONE:0)
B(5,6,-4,STONE:0)
B(6,6,-4,STONE:0)
B(-4,6,-3,STONE:0)
B(-3,6,-3,STONE:0)
B(-2,6,-3,STONE:0)
B(-1,6,-3,STONE:0)
B(0,6,-3,STONE:0)
B(1,6,-3,STONE:0)
B(2,6,-3,STONE:0)
B(3,6,-3,STONE:0)
B(4,6,-3,STONE:0)
B(5,6,-3,STONE:0)
B(6,6,-3,STONE:0)
B(-5,6,-2,STONE:0)
B(-4,6,-2,STONE:0)
B(-3,6,-2,STONE:0)
B(-2,6,-2,STONE:0)
B(-1,6,-2,STONE:0)
B(0,6,-2,STONE:0)
B(1,6,-2,STONE:0)
B(2,6,-2,STONE:0)
B(3,6,-2,STONE:0)
B(4,6,-2,STONE:0)
B(5,6,-2,STONE:0)
B(6,6,-2,STONE:0)
B(-6,6,-1,STONE:0)
B(-5,6,-1,STONE:0)
B(-4,6,-1,STONE:0)
B(-3,6,-1,STONE:0)
B(-2,6,-1,STONE:0)
B(-1,6,-1,STONE:0)
B(0,6,-1,STONE:0)
B(1,6,-1,STONE:0)
B(2,6,-1,STONE:0)
B(3,6,-1,STONE:0)
B(4,6,-1,STONE:0)
B(5,6,-1,STONE:0)
B(6,6,-1,STONE:0)
B(-8,6,0,STONE:0)
B(-7,6,0,STONE:0)
B(-6,6,0,STONE:0)
B(-5,6,0,STONE:0)
B(-4,6,0,STONE:0)
B(-3,6,0,STONE:0)
B(-2,6,0,STONE:0)
B(-1,6,0,STONE:0)
B(0,6,0,STONE:0)
B(1,6,0,STONE:0)
B(2,6,0,STONE:0)
B(3,6,0,STONE:0)
B(4,6,0,STONE:0)
B(5,6,0,STONE:0)
B(6,6,0,STONE:0)
B(-8,6,1,STONE:0)
B(-7,6,1,STONE:0)
B(-6,6,1,STONE:0)
B(-5,6,1,STONE:0)
B(-4,6,1,STONE:0)
B(-3,6,1,STONE:0)
B(-2,6,1,STONE:0)
B(-1,6,1,STONE:0)
B(0,6,1,STONE:0)
B(1,6,1,STONE:0)
B(2,6,1,STONE:0)
B(3,6,1,STONE:0)
B(4,6,1,STONE:0)
B(5,6,1,STONE:0)
B(6,6,1,STONE:0)
B(-8,6,2,STONE:0)
B(-7,6,2,STONE:0)
B(-6,6,2,STONE:0)
B(-5,6,2,STONE:0)
B(-4,6,2,STONE:0)
B(-3,6,2,STONE:0)
B(-2,6,2,STONE:0)
B(-1,6,2,STONE:0)
B(0,6,2,STONE:0)
B(1,6,2,STONE:0)
B(2,6,2,STONE:0)
B(3,6,2,STONE:0)
B(4,6,2,STONE:0)
B(5,6,2,STONE:0)
B(6,6,2,STONE:0)
B(-7,6,3,STONE:0)
B(-6,6,3,STONE:0)
B(-5,6,3,STONE:0)
B(-4,6,3,STONE:0)
B(-3,6,3,STONE:0)
B(-2,6,3,STONE:0)
B(-1,6,3,STONE:0)
B(0,6,3,STONE:0)
B(1,6,3,STONE:0)
B(2,6,3,STONE:0)
B(3,6,3,STONE:0)
B(4,6,3,STONE:0)
B(5,6,3,STONE:0)
B(-7,6,4,STONE:0)
B(-6,6,4,STONE:0)
B(-5,6,4,STONE:0)
B(-4,6,4,STONE:0)
B(-3,6,4,STONE:0)
B(-2,6,4,STONE:0)
B(-1,6,4,STONE:0)
B(0,6,4,STONE:0)
B(1,6,4,STONE:0)
B(2,6,4,STONE:0)
B(3,6,4,STONE:0)
B(4,6,4,STONE:0)
B(-6,6,5,STONE:0)
B(-5,6,5,STONE:0)
B(-4,6,5,STONE:0)
B(-3,6,5,STONE:0)
B(-2,6,5,STONE:0)
B(-1,6,5,STONE:0)
B(0,6,5,STONE:0)
B(1,6,5,STONE:0)
B(2,6,5,STONE:0)
B(3,6,5,STONE:0)
B(-6,6,6,STONE:0)
B(-5,6,6,STONE:0)
B(-4,6,6,STONE:0)
B(-3,6,6,STONE:0)
B(-2,6,6,STONE:0)
B(-1,6,6,STONE:0)
B(0,6,6,STONE:0)
B(1,6,6,STONE:0)
B(2,6,6,STONE:0)
B(3,6,6,STONE:0)
B(-6,6,7,STONE:0)
B(-5,6,7,STONE:0)
B(-4,6,7,STONE:0)
B(-3,6,7,STONE:0)
B(-2,6,7,STONE:0)
B(-1,6,7,STONE:0)
B(0,6,7,STONE:0)
B(1,6,7,STONE:0)
B(2,6,7,STONE:0)
B(3,6,7,STONE:0)
B(-7,6,8,STONE:0)
B(-6,6,8,STONE:0)
B(-5,6,8,STONE:0)
B(-4,6,8,STONE:0)
B(-3,6,8,STONE:0)
B(-2,6,8,STONE:0)
B(-1,6,8,STONE:0)
B(0,6,8,STONE:0)
B(1,6,8,STONE:0)
B(-5,6,9,STONE:0)
B(-4,6,9,STONE:0)
B(-3,6,9,STONE:0)
B(-2,6,9,STONE:0)
B(-1,6,9,STONE:0)
B(0,6,9,STONE:0)
B(1,6,9,STONE:0)
B(0,7,-7,STONE:0)
B(1,7,-7,STONE:0)
B(2,7,-7,STONE:0)
B(3,7,-7,STONE:0)
B(-1,7,-6,STONE:0)
B(0,7,-6,STONE:0)
B(1,7,-6,STONE:0)
B(2,7,-6,STONE:0)
B(3,7,-6,STONE:0)
B(4,7,-6,STONE:0)
B(-1,7,-5,STONE:0)
B(0,7,-5,STONE:0)
B(1,7,-5,STONE:0)
B(2,7,-5,STONE:0)
B(3,7,-5,STONE:0)
B(4,7,-5,STONE:0)
B(-3,7,-4,STONE:0)
B(-2,7,-4,STONE:0)
B(-1,7,-4,STONE:0)
B(0,7,-4,STONE:0)
B(1,7,-4,STONE:0)
B(2,7,-4,STONE:0)
B(3,7,-4,STONE:0)
B(4,7,-4,STONE:0)
B(-3,7,-3,STONE:0)
B(-2,7,-3,STONE:0)
B(-1,7,-3,STONE:0)
B(0,7,-3,STONE:0)
B(1,7,-3,STONE:0)
B(2,7,-3,STONE:0)
B(3,7,-3,STONE:0)
B(4,7,-3,STONE:0)
B(5,7,-3,STONE:0)
B(-4,7,-2,STONE:0)
B(-3,7,-2,STONE:0)
B(-2,7,-2,STONE:0)
B(-1,7,-2,STONE:0)
B(0,7,-2,STONE:0)
B(1,7,-2,STONE:0)
B(2,7,-2,STONE:0)
B(3,7,-2,STONE:0)
B(4,7,-2,STONE:0)
B(5,7,-2,STONE:0)
B(6,7,-2,STONE:0)
B(-5,7,-1,STONE:0)
B(-4,7,-1,STONE:0)
B(-3,7,-1,STONE:0)
B(-2,7,-1,STONE:0)
B(-1,7,-1,STONE:0)
B(0,7,-1,STONE:0)
B(1,7,-1,STONE:0)
B(2,7,-1,STONE:0)
B(3,7,-1,STONE:0)
B(4,7,-1,STONE:0)
B(5,7,-1,STONE:0)
B(6,7,-1,STONE:0)
B(-7,7,0,STONE:0)
B(-6,7,0,STONE:0)
B(-5,7,0,STONE:0)
B(-4,7,0,STONE:0)
B(-3,7,0,STONE:0)
B(-2,7,0,STONE:0)
B(-1,7,0,STONE:0)
B(0,7,0,STONE:0)
B(1,7,0,STONE:0)
B(2,7,0,STONE:0)
B(3,7,0,STONE:0)
B(4,7,0,STONE:0)
B(5,7,0,STONE:0)
B(6,7,0,STONE:0)
B(-7,7,1,STONE:0)
B(-6,7,1,STONE:0)
B(-5,7,1,STONE:0)
B(-4,7,1,STONE:0)
B(-3,7,1,STONE:0)
B(-2,7,1,STONE:0)
B(-1,7,1,STONE:0)
B(0,7,1,STONE:0)
B(1,7,1,STONE:0)
B(2,7,1,STONE:0)
B(3,7,1,STONE:0)
B(4,7,1,STONE:0)
B(5,7,1,STONE:0)
B(6,7,1,STONE:0)
B(-7,7,2,STONE:0)
B(-6,7,2,STONE:0)
B(-5,7,2,STONE:0)
B(-4,7,2,STONE:0)
B(-3,7,2,STONE:0)
B(-2,7,2,STONE:0)
B(-1,7,2,STONE:0)
B(0,7,2,STONE:0)
B(1,7,2,STONE:0)
B(2,7,2,STONE:0)
B(3,7,2,STONE:0)
B(4,7,2,STONE:0)
B(5,7,2,STONE:0)
B(6,7,2,STONE:0)
B(-7,7,3,STONE:0)
B(-6,7,3,STONE:0)
B(-5,7,3,STONE:0)
B(-4,7,3,STONE:0)
B(-3,7,3,STONE:0)
B(-2,7,3,STONE:0)
B(-1,7,3,STONE:0)
B(0,7,3,STONE:0)
B(1,7,3,STONE:0)
B(2,7,3,STONE:0)
B(3,7,3,STONE:0)
B(4,7,3,STONE:0)
B(-6,7,4,STONE:0)
B(-5,7,4,STONE:0)
B(-4,7,4,STONE:0)
B(-3,7,4,STONE:0)
B(-2,7,4,STONE:0)
B(-1,7,4,STONE:0)
B(0,7,4,STONE:0)
B(1,7,4,STONE:0)
B(2,7,4,STONE:0)
B(3,7,4,STONE:0)
B(4,7,4,STONE:0)
B(-6,7,5,STONE:0)
B(-5,7,5,STONE:0)
B(-4,7,5,STONE:0)
B(-3,7,5,STONE:0)
B(-2,7,5,STONE:0)
B(-1,7,5,STONE:0)
B(0,7,5,STONE:0)
B(1,7,5,STONE:0)
B(2,7,5,STONE:0)
B(3,7,5,STONE:0)
B(-6,7,6,STONE:0)
B(-5,7,6,STONE:0)
B(-4,7,6,STONE:0)
B(-3,7,6,STONE:0)
B(-2,7,6,STONE:0)
B(-1,7,6,STONE:0)
B(0,7,6,STONE:0)
B(1,7,6,STONE:0)
B(2,7,6,STONE:0)
B(3,7,6,STONE:0)
B(-6,7,7,STONE:0)
B(-5,7,7,STONE:0)
B(-4,7,7,STONE:0)
B(-3,7,7,STONE:0)
B(-2,7,7,STONE:0)
B(-1,7,7,STONE:0)
B(0,7,7,STONE:0)
B(1,7,7,STONE:0)
B(2,7,7,STONE:0)
B(-6,7,8,STONE:0)
B(-5,7,8,STONE:0)
B(-4,7,8,STONE:0)
B(-3,7,8,STONE:0)
B(-2,7,8,STONE:0)
B(-1,7,8,STONE:0)
B(0,7,8,STONE:0)
B(1,7,8,STONE:0)
B(-5,7,9,STONE:0)
B(-4,7,9,STONE:0)
B(-3,7,9,STONE:0)
B(-2,7,9,STONE:0)
B(-1,7,9,STONE:0)
B(0,7,9,STONE:0)
B(2,8,-6,STONE:0)
B(3,8,-6,STONE:0)
B(1,8,-5,STONE:0)
B(2,8,-5,STONE:0)
B(3,8,-5,STONE:0)
B(0,8,-4,STONE:0)
B(1,8,-4,STONE:0)
B(2,8,-4,STONE:0)
B(3,8,-4,STONE:0)
B(-1,8,-3,STONE:0)
B(0,8,-3,STONE:0)
B(1,8,-3,STONE:0)
B(2,8,-3,STONE:0)
B(3,8,-3,STONE:0)
B(-3,8,-2,STONE:0)
B(-2,8,-2,STONE:0)
B(-1,8,-2,STONE:0)
B(0,8,-2,STONE:0)
B(1,8,-2,STONE:0)
B(2,8,-2,STONE:0)
B(3,8,-2,STONE:0)
B(4,8,-2,STONE:0)
B(-4,8,-1,STONE:0)
B(-3,8,-1,STONE:0)
B(-2,8,-1,STONE:0)
B(-1,8,-1,STONE:0)
B(0,8,-1,STONE:0)
B(1,8,-1,STONE:0)
B(2,8,-1,STONE:0)
B(3,8,-1,STONE:0)
B(4,8,-1,STONE:0)
B(5,8,-1,STONE:0)
B(-4,8,0,STONE:0)
B(-3,8,0,STONE:0)
B(-2,8,0,STONE:0)
B(-1,8,0,STONE:0)
B(0,8,0,STONE:0)
B(1,8,0,STONE:0)
B(2,8,0,STONE:0)
B(3,8,0,STONE:0)
B(4,8,0,STONE:0)
B(5,8,0,STONE:0)
B(-5,8,1,STONE:0)
B(-4,8,1,STONE:0)
B(-3,8,1,STONE:0)
B(-2,8,1,STONE:0)
B(-1,8,1,STONE:0)
B(0,8,1,STONE:0)
B(1,8,1,STONE:0)
B(2,8,1,STONE:0)
B(3,8,1,STONE:0)
B(4,8,1,STONE:0)
B(5,8,1,STONE:0)
B(-6,8,2,STONE:0)
B(-5,8,2,STONE:0)
B(-4,8,2,STONE:0)
B(-3,8,2,STONE:0)
B(-2,8,2,STONE:0)
B(-1,8,2,STONE:0)
B(0,8,2,STONE:0)
B(1,8,2,STONE:0)
B(2,8,2,STONE:0)
B(3,8,2,STONE:0)
B(4,8,2,STONE:0)
B(5,8,2,STONE:0)
B(6,8,2,STONE:0)
B(-6,8,3,STONE:0)
B(-5,8,3,STONE:0)
B(-4,8,3,STONE:0)
B(-3,8,3,STONE:0)
B(-2,8,3,STONE:0)
B(-1,8,3,STONE:0)
B(0,8,3,STONE:0)
B(1,8,3,STONE:0)
B(2,8,3,STONE:0)
B(3,8,3,STONE:0)
B(4,8,3,STONE:0)
B(-6,8,4,STONE:0)
B(-5,8,4,STONE:0)
B(-4,8,4,STONE:0)
B(-3,8,4,STONE:0)
B(-2,8,4,STONE:0)
B(-1,8,4,STONE:0)
B(0,8,4,STONE:0)
B(1,8,4,STONE:0)
B(2,8,4,STONE:0)
B(3,8,4,STONE:0)
B(4,8,4,STONE:0)
B(-6,8,5,STONE:0)
B(-5,8,5,STONE:0)
B(-4,8,5,STONE:0)
B(-3,8,5,STONE:0)
B(-2,8,5,STONE:0)
B(-1,8,5,STONE:0)
B(0,8,5,STONE:0)
B(1,8,5,STONE:0)
B(2,8,5,STONE:0)
B(3,8,5,STONE:0)
B(-5,8,6,STONE:0)
B(-4,8,6,STONE:0)
B(-3,8,6,STONE:0)
B(-2,8,6,STONE:0)
B(-1,8,6,STONE:0)
B(0,8,6,STONE:0)
B(1,8,6,STONE:0)
B(2,8,6,STONE:0)
B(3,8,6,STONE:0)
B(-5,8,7,STONE:0)
B(-4,8,7,STONE:0)
B(-3,8,7,STONE:0)
B(-2,8,7,STONE:0)
B(-1,8,7,STONE:0)
B(0,8,7,STONE:0)
B(1,8,7,STONE:0)
B(2,8,7,STONE:0)
B(-5,8,8,STONE:0)
B(-4,8,8,STONE:0)
B(-3,8,8,STONE:0)
B(-2,8,8,STONE:0)
B(-1,8,8,STONE:0)
B(0,8,8,STONE:0)
B(-4,8,9,STONE:0)
B(-3,8,9,STONE:0)
B(-2,8,9,STONE:0)
B(-1,8,9,STONE:0)
B(-1,9,-2,STONE:0)
B(0,9,-2,STONE:0)
B(1,9,-2,STONE:0)
B(-2,9,-1,STONE:0)
B(-1,9,-1,STONE:0)
B(0,9,-1,STONE:0)
B(1,9,-1,STONE:0)
B(-2,9,0,STONE:0)
B(-1,9,0,STONE:0)
B(0,9,0,STONE:0)
B(1,9,0,STONE:0)
B(-2,9,1,STONE:0)
B(-1,9,1,STONE:0)
B(0,9,1,STONE:0)
B(1,9,1,STONE:0)
B(2,9,1,STONE:0)
B(4,9,1,STONE:0)
B(-2,9,2,STONE:0)
B(-1,9,2,STONE:0)
B(0,9,2,STONE:0)
B(1,9,2,STONE:0)
B(2,9,2,STONE:0)
B(3,9,2,STONE:0)
B(4,9,2,STONE:0)
B(-4,9,3,STONE:0)
B(-3,9,3,STONE:0)
B(-2,9,3,STONE:0)
B(-1,9,3,STONE:0)
B(0,9,3,STONE:0)
B(1,9,3,STONE:0)
B(2,9,3,STONE:0)
B(3,9,3,STONE:0)
B(4,9,3,STONE:0)
B(-4,9,4,STONE:0)
B(-3,9,4,STONE:0)
B(-2,9,4,STONE:0)
B(-1,9,4,STONE:0)
B(0,9,4,STONE:0)
B(1,9,4,STONE:0)
B(2,9,4,STONE:0)
B(3,9,4,STONE:0)
B(4,9,4,STONE:0)
B(-3,9,5,STONE:0)
B(-2,9,5,STONE:0)
B(-1,9,5,STONE:0)
B(0,9,5,STONE:0)
B(1,9,5,STONE:0)
B(2,9,5,STONE:0)
B(-3,9,6,STONE:0)
B(-2,9,6,STONE:0)
B(-1,9,6,STONE:0)
B(0,9,6,STONE:0)
B(1,9,6,STONE:0)
B(2,9,6,STONE:0)
B(3,9,6,STONE:0)
B(-3,9,7,STONE:0)
B(-2,9,7,STONE:0)
B(-1,9,7,STONE:0)
B(0,9,7,STONE:0)
B(1,9,7,STONE:0)
B(-3,9,8,STONE:0)
B(-2,9,8,STONE:0)
B(-1,9,8,STONE:0)
B(0,9,8,STONE:0)
B(-1,10,0,STONE:0)
B(-1,10,1,STONE:0)
B(0,10,1,STONE:0)
B(1,10,1,STONE:0)
B(-1,10,2,STONE:0)
B(0,10,2,STONE:0)
B(1,10,2,STONE:0)
B(2,10,2,STONE:0)
B(-2,10,3,STONE:0)
B(-1,10,3,STONE:0)
B(0,10,3,STONE:0)
B(1,10,3,STONE:0)
B(2,10,3,STONE:0)
B(3,10,3,STONE:0)
B(4,10,3,STONE:0)
B(-2,10,4,STONE:0)
B(-1,10,4,STONE:0)
B(0,10,4,STONE:0)
B(1,10,4,STONE:0)
B(2,10,4,STONE:0)
B(3,10,4,STONE:0)
B(-1,10,5,STONE:0)
B(0,10,5,STONE:0)
B(1,10,5,STONE:0)
B(2,10,5,STONE:0)
B(-2,10,6,STONE:0)
B(-1,10,6,STONE:0)
B(0,10,6,STONE:0)
B(1,10,6,STONE:0)
B(2,10,6,STONE:0)
B(-2,10,7,STONE:0)
B(-1,10,7,STONE:0)
B(0,10,7,STONE:0)
B(1,10,7,STONE:0)

