
#######################################################################
# +-----------------------------------------------------------------+ #
# |                            BO3 object                           | #
# +-----------------------------------------------------------------+ #
#######################################################################

Author: NLBlackEagle

Description: No description given

Version: 3

SettingsMode: WriteDisable


#######################################################################
# +-----------------------------------------------------------------+ #
# |                          Main settings                          | #
# +-----------------------------------------------------------------+ #
#######################################################################

Tree: false

Frequency: 1

Rarity: 4.0

RotateRandomly: true

SpawnHeight: highestBlock

SpawnHeightOffset: 0

SpawnHeightVariance: 0

##############################
# Height Limits for the BO3. #
##############################

MinHeight: 0

MaxHeight: 80

######################
# Extrusion settings #
######################

ExtrudeMode: None

ExtrudeThroughBlocks: AIR

MaxBranchDepth: 10

ExcludedBiomes: All


#######################################################################
# +-----------------------------------------------------------------+ #
# |                      Source block settings                      | #
# +-----------------------------------------------------------------+ #
#######################################################################

SourceBlocks: AIR,GRASS,STONE,DIRT

MaxPercentageOutsideSourceBlock: 0

OutsideSourceBlock: placeAnyway

IsOTGPlus: false

InheritBO3: 

InheritBO3Rotation: NORTH

OverrideChildSettings: true

OverrideParentHeight: false

CanOverride: false

BranchFrequency: 0

BranchFrequencyGroup: 

MustBeBelowOther: false

MustBeInside: 

CannotBeInside: 

ReplacesBO3: 

CanSpawnOnWater: true

SpawnOnWaterOnly: false

SpawnUnderWater: false

SpawnAtWaterLevel: false

HeightOffset: 0

RemoveAir: true

ReplaceAbove: 

ReplaceBelow: 

ReplaceWithBiomeBlocks: true

ReplaceWithGroundBlock: DIRT

ReplaceWithSurfaceBlock: GRASS

SmoothRadius: 0

SmoothHeightOffset: 0

SmoothStartTop: false

SmoothStartWood: false

SmoothingSurfaceBlock: 

SmoothingGroundBlock: 

BO3Group: 

IsSpawnPoint: false


#######################################################################
# +-----------------------------------------------------------------+ #
# |                              Blocks                             | #
# +-----------------------------------------------------------------+ #
#######################################################################

Block(-10,-8,3,STONE:1)
Block(-10,-8,4,STONE:1)
Block(-10,-7,3,STONE:1)
Block(-10,-7,4,STONE:1)
Block(-10,-7,5,STONE:1)
Block(-10,-7,6,STONE:1)
Block(-10,-6,1,STAINED_CLAY:14)
Block(-10,-6,2,STAINED_CLAY:14)
Block(-10,-6,3,STONE:1)
Block(-10,-6,4,STONE:1)
Block(-10,-6,5,STONE:1)
Block(-10,-6,6,STONE:1)
Block(-10,-5,1,STAINED_CLAY:14)
Block(-10,-5,2,STAINED_CLAY:14)
Block(-10,-5,3,STONE:1)
Block(-10,-5,4,STONE:1)
Block(-10,-5,5,STONE:1)
Block(-10,-5,6,STONE:1)
Block(-10,-5,7,STONE:1)
Block(-10,-4,2,STAINED_CLAY:14)
Block(-10,-4,3,STAINED_CLAY:14)
Block(-10,-4,4,STONE:1)
Block(-10,-4,5,STONE:1)
Block(-10,-4,6,STONE:1)
Block(-10,-3,2,STAINED_CLAY:14)
Block(-10,-3,3,STAINED_CLAY:14)
Block(-10,-3,4,STONE:1)
Block(-10,-3,5,STONE:1)
Block(-10,-3,6,STONE:1)
Block(-10,-2,2,STAINED_CLAY:14)
Block(-10,-2,3,STAINED_CLAY:14)
Block(-10,-2,4,STONE:1)
Block(-10,-2,5,STONE:1)
Block(-10,-1,4,STONE:1)
Block(-9,-8,3,STONE:1)
Block(-9,-8,4,STONE:1)
Block(-9,-7,0,STAINED_CLAY:14)
Block(-9,-7,2,STAINED_CLAY:14)
Block(-9,-7,3,STONE:1)
Block(-9,-7,4,STONE:1)
Block(-9,-7,5,STONE:1)
Block(-9,-7,6,STONE:1)
Block(-9,-7,7,STONE:1)
Block(-9,-6,0,STAINED_CLAY:14)
Block(-9,-6,1,STAINED_CLAY:14)
Block(-9,-6,2,STAINED_CLAY:14)
Block(-9,-6,3,STONE:1)
Block(-9,-6,4,STONE:1)
Block(-9,-6,5,STONE:1)
Block(-9,-6,6,STONE:1)
Block(-9,-6,7,STONE:1)
Block(-9,-5,0,STAINED_CLAY:14)
Block(-9,-5,1,STAINED_CLAY:14)
Block(-9,-5,2,STAINED_CLAY:14)
Block(-9,-5,3,STONE:1)
Block(-9,-5,4,STONE:1)
Block(-9,-5,5,STONE:1)
Block(-9,-5,6,STONE:1)
Block(-9,-5,7,STONE:1)
Block(-9,-5,8,STONE:1)
Block(-9,-4,0,STAINED_CLAY:14)
Block(-9,-4,1,STAINED_CLAY:14)
Block(-9,-4,2,STAINED_CLAY:14)
Block(-9,-4,3,STAINED_CLAY:14)
Block(-9,-4,4,STONE:1)
Block(-9,-4,5,STONE:1)
Block(-9,-4,6,STONE:1)
Block(-9,-4,7,STONE:1)
Block(-9,-3,1,STAINED_CLAY:14)
Block(-9,-3,2,STAINED_CLAY:14)
Block(-9,-3,3,STAINED_CLAY:14)
Block(-9,-3,4,STONE:1)
Block(-9,-3,5,STONE:1)
Block(-9,-3,6,STONE:1)
Block(-9,-3,7,STONE:1)
Block(-9,-2,1,STAINED_CLAY:14)
Block(-9,-2,2,STAINED_CLAY:14)
Block(-9,-2,3,STAINED_CLAY:14)
Block(-9,-2,4,STONE:1)
Block(-9,-2,5,STONE:1)
Block(-9,-2,6,STONE:1)
Block(-9,-2,7,STONE:1)
Block(-9,-1,0,STONE:1)
Block(-9,-1,1,STAINED_CLAY:14)
Block(-9,-1,2,STAINED_CLAY:14)
Block(-9,-1,3,STAINED_CLAY:14)
Block(-9,-1,4,STONE:1)
Block(-9,-1,5,STONE:1)
Block(-9,-1,6,STONE:1)
Block(-9,0,2,STAINED_CLAY:14)
Block(-9,0,3,STAINED_CLAY:14)
Block(-9,0,4,STONE:1)
Block(-9,0,5,STONE:1)
Block(-9,0,6,STONE:1)
Block(-9,1,3,STAINED_CLAY:14)
Block(-9,1,4,STONE:1)
Block(-9,1,5,STONE:1)
Block(-9,1,6,STONE:1)
Block(-9,2,3,STAINED_CLAY:14)
Block(-9,2,4,STONE:1)
Block(-9,2,5,STONE:1)
Block(-9,2,6,STONE:1)
Block(-9,3,3,STAINED_CLAY:14)
Block(-9,3,4,STONE:1)
Block(-9,3,5,STONE:1)
Block(-9,4,3,STAINED_CLAY:14)
Block(-9,4,4,STONE:1)
Block(-8,-9,2,STONE:1)
Block(-8,-9,3,STONE:1)
Block(-8,-8,1,STONE:1)
Block(-8,-8,2,STONE:1)
Block(-8,-8,3,STONE:1)
Block(-8,-8,4,STONE:1)
Block(-8,-8,5,STONE:1)
Block(-8,-8,6,STONE:1)
Block(-8,-7,-1,STONE:1)
Block(-8,-7,0,STONE:1)
Block(-8,-7,1,STONE:1)
Block(-8,-7,2,STONE:1)
Block(-8,-7,3,STONE:1)
Block(-8,-7,4,STONE:1)
Block(-8,-7,5,STONE:1)
Block(-8,-7,6,STONE:1)
Block(-8,-7,7,STONE:1)
Block(-8,-6,-1,STONE:1)
Block(-8,-6,0,STONE:1)
Block(-8,-6,1,STONE:1)
Block(-8,-6,2,STONE:1)
Block(-8,-6,3,STONE:1)
Block(-8,-6,4,STONE:1)
Block(-8,-6,5,STONE:1)
Block(-8,-6,6,STONE:1)
Block(-8,-6,7,STONE:1)
Block(-8,-6,8,STONE:1)
Block(-8,-5,0,STONE:1)
Block(-8,-5,1,STONE:1)
Block(-8,-5,2,STONE:1)
Block(-8,-5,3,STONE:1)
Block(-8,-5,4,STONE:1)
Block(-8,-5,5,STONE:1)
Block(-8,-5,6,STONE:1)
Block(-8,-5,7,STONE:1)
Block(-8,-5,8,STONE:1)
Block(-8,-4,0,STONE:1)
Block(-8,-4,1,STONE:1)
Block(-8,-4,2,STONE:1)
Block(-8,-4,3,STONE:1)
Block(-8,-4,4,STONE:1)
Block(-8,-4,5,STONE:1)
Block(-8,-4,6,STONE:1)
Block(-8,-4,7,STONE:1)
Block(-8,-4,8,STONE:1)
Block(-8,-3,0,STONE:1)
Block(-8,-3,1,STONE:1)
Block(-8,-3,2,STONE:1)
Block(-8,-3,3,STONE:1)
Block(-8,-3,4,STONE:1)
Block(-8,-3,5,STONE:1)
Block(-8,-3,6,STONE:1)
Block(-8,-3,7,STONE:1)
Block(-8,-3,8,STONE:1)
Block(-8,-2,0,STONE:1)
Block(-8,-2,1,STONE:1)
Block(-8,-2,2,STONE:1)
Block(-8,-2,3,STONE:1)
Block(-8,-2,4,STONE:1)
Block(-8,-2,5,STONE:1)
Block(-8,-2,6,STONE:1)
Block(-8,-2,7,STONE:1)
Block(-8,-1,0,STONE:1)
Block(-8,-1,1,STAINED_CLAY:14)
Block(-8,-1,2,STAINED_CLAY:14)
Block(-8,-1,3,STAINED_CLAY:14)
Block(-8,-1,4,STONE:1)
Block(-8,-1,5,STONE:1)
Block(-8,-1,6,STONE:1)
Block(-8,-1,7,STONE:1)
Block(-8,0,0,STONE:1)
Block(-8,0,1,STAINED_CLAY:14)
Block(-8,0,2,STAINED_CLAY:14)
Block(-8,0,3,STAINED_CLAY:14)
Block(-8,0,4,STONE:1)
Block(-8,0,5,STONE:1)
Block(-8,0,6,STONE:1)
Block(-8,0,7,STONE:1)
Block(-8,1,2,STAINED_CLAY:14)
Block(-8,1,3,STAINED_CLAY:14)
Block(-8,1,4,STONE:1)
Block(-8,1,5,STONE:1)
Block(-8,1,6,STONE:1)
Block(-8,1,7,STONE:1)
Block(-8,2,2,STAINED_CLAY:14)
Block(-8,2,3,STAINED_CLAY:14)
Block(-8,2,4,STONE:1)
Block(-8,2,5,STONE:1)
Block(-8,2,6,STONE:1)
Block(-8,2,7,STONE:1)
Block(-8,3,2,STAINED_CLAY:14)
Block(-8,3,3,STAINED_CLAY:14)
Block(-8,3,4,STONE:1)
Block(-8,3,5,STONE:1)
Block(-8,3,6,STONE:1)
Block(-8,4,2,STAINED_CLAY:14)
Block(-8,4,3,STAINED_CLAY:14)
Block(-8,4,4,STONE:1)
Block(-8,4,5,STONE:1)
Block(-8,4,6,STONE:1)
Block(-8,5,3,STAINED_CLAY:14)
Block(-8,5,4,STONE:1)
Block(-8,5,5,STONE:1)
Block(-8,6,3,STAINED_CLAY:14)
Block(-7,-10,1,STONE:1)
Block(-7,-10,2,STONE:1)
Block(-7,-9,1,STONE:1)
Block(-7,-9,2,STONE:1)
Block(-7,-9,3,STONE:1)
Block(-7,-9,4,STONE:1)
Block(-7,-9,5,STONE:1)
Block(-7,-9,6,STONE:1)
Block(-7,-8,1,STONE:1)
Block(-7,-8,2,STONE:1)
Block(-7,-8,3,STONE:1)
Block(-7,-8,4,STONE:1)
Block(-7,-8,5,STONE:1)
Block(-7,-8,6,STONE:1)
Block(-7,-7,-1,STONE:1)
Block(-7,-7,0,STONE:1)
Block(-7,-7,1,STONE:1)
Block(-7,-7,2,STONE:1)
Block(-7,-7,3,STONE:1)
Block(-7,-7,4,STONE:1)
Block(-7,-7,5,STONE:1)
Block(-7,-7,6,STONE:1)
Block(-7,-6,-1,STONE:1)
Block(-7,-6,0,STONE:1)
Block(-7,-6,1,STONE:1)
Block(-7,-6,2,STONE:1)
Block(-7,-6,3,STONE:1)
Block(-7,-6,4,STONE:1)
Block(-7,-6,5,STONE:1)
Block(-7,-6,6,STONE:1)
Block(-7,-6,7,STONE:1)
Block(-7,-6,8,STONE:1)
Block(-7,-5,-1,STONE:1)
Block(-7,-5,0,STONE:1)
Block(-7,-5,1,STONE:1)
Block(-7,-5,2,STONE:1)
Block(-7,-5,3,STONE:1)
Block(-7,-5,4,STONE:1)
Block(-7,-5,5,STONE:1)
Block(-7,-5,6,STONE:1)
Block(-7,-5,7,STONE:1)
Block(-7,-5,8,STONE:1)
Block(-7,-4,-1,STONE:1)
Block(-7,-4,0,STONE:1)
Block(-7,-4,1,STONE:1)
Block(-7,-4,2,STONE:1)
Block(-7,-4,3,STONE:1)
Block(-7,-4,4,STONE:1)
Block(-7,-4,5,STONE:1)
Block(-7,-4,6,STONE:1)
Block(-7,-4,7,STONE:1)
Block(-7,-4,8,STONE:1)
Block(-7,-3,0,STONE:1)
Block(-7,-3,1,STONE:1)
Block(-7,-3,2,STONE:1)
Block(-7,-3,3,STONE:1)
Block(-7,-3,4,STONE:1)
Block(-7,-3,5,STONE:1)
Block(-7,-3,6,STONE:1)
Block(-7,-3,7,STONE:1)
Block(-7,-3,8,STONE:1)
Block(-7,-2,0,STONE:1)
Block(-7,-2,1,STONE:1)
Block(-7,-2,2,STONE:1)
Block(-7,-2,3,STONE:1)
Block(-7,-2,4,STONE:1)
Block(-7,-2,5,STONE:1)
Block(-7,-2,6,STONE:1)
Block(-7,-2,7,STONE:1)
Block(-7,-2,8,STONE:1)
Block(-7,-1,0,STONE:1)
Block(-7,-1,1,STONE:1)
Block(-7,-1,2,STONE:1)
Block(-7,-1,3,STONE:1)
Block(-7,-1,4,STONE:1)
Block(-7,-1,5,STONE:1)
Block(-7,-1,6,STONE:1)
Block(-7,-1,7,STONE:1)
Block(-7,-1,8,STONE:1)
Block(-7,0,0,STONE:1)
Block(-7,0,1,STONE:1)
Block(-7,0,2,STONE:1)
Block(-7,0,3,STONE:1)
Block(-7,0,4,STONE:1)
Block(-7,0,5,STONE:1)
Block(-7,0,6,STONE:1)
Block(-7,0,7,STONE:1)
Block(-7,0,8,STONE:1)
Block(-7,1,1,STAINED_CLAY:14)
Block(-7,1,2,STAINED_CLAY:14)
Block(-7,1,3,STAINED_CLAY:14)
Block(-7,1,4,STONE:1)
Block(-7,1,5,STONE:1)
Block(-7,1,6,STONE:1)
Block(-7,1,7,STONE:1)
Block(-7,2,2,STAINED_CLAY:14)
Block(-7,2,3,STAINED_CLAY:14)
Block(-7,2,4,STONE:1)
Block(-7,2,5,STONE:1)
Block(-7,2,6,STAINED_CLAY:14)
Block(-7,2,7,STAINED_CLAY:14)
Block(-7,3,2,STAINED_CLAY:14)
Block(-7,3,3,STAINED_CLAY:14)
Block(-7,3,4,STONE:1)
Block(-7,3,5,STONE:1)
Block(-7,3,6,STAINED_CLAY:14)
Block(-7,3,7,STAINED_CLAY:14)
Block(-7,4,2,STAINED_CLAY:14)
Block(-7,4,3,STAINED_CLAY:14)
Block(-7,4,4,STONE:1)
Block(-7,4,5,STONE:1)
Block(-7,4,6,STAINED_CLAY:14)
Block(-7,5,2,STAINED_CLAY:14)
Block(-7,5,3,STAINED_CLAY:14)
Block(-7,5,4,STONE:1)
Block(-7,5,5,STONE:1)
Block(-7,5,6,STONE:1)
Block(-7,6,2,STAINED_CLAY:14)
Block(-7,6,3,STAINED_CLAY:14)
Block(-7,6,4,STONE:1)
Block(-7,6,5,STONE:1)
Block(-7,7,3,STAINED_CLAY:14)
Block(-6,-10,1,STONE:1)
Block(-6,-10,2,STONE:1)
Block(-6,-10,3,STONE:1)
Block(-6,-10,5,STONE:1)
Block(-6,-9,1,STONE:1)
Block(-6,-9,2,STONE:1)
Block(-6,-9,3,STONE:1)
Block(-6,-9,4,STONE:1)
Block(-6,-9,5,STONE:1)
Block(-6,-9,6,STONE:1)
Block(-6,-8,0,STONE:1)
Block(-6,-8,1,STONE:1)
Block(-6,-8,2,STONE:1)
Block(-6,-8,3,STONE:1)
Block(-6,-8,4,STONE:1)
Block(-6,-8,5,STONE:1)
Block(-6,-8,6,STONE:1)
Block(-6,-7,-1,STONE:1)
Block(-6,-7,0,STONE:1)
Block(-6,-7,1,STONE:1)
Block(-6,-7,2,STONE:1)
Block(-6,-7,3,STONE:1)
Block(-6,-7,4,STONE:1)
Block(-6,-7,5,STONE:1)
Block(-6,-7,6,STONE:1)
Block(-6,-7,7,STONE:1)
Block(-6,-6,0,STONE:1)
Block(-6,-6,1,STONE:1)
Block(-6,-6,2,STONE:1)
Block(-6,-6,3,STONE:1)
Block(-6,-6,4,STONE:1)
Block(-6,-6,5,STONE:1)
Block(-6,-6,6,STONE:1)
Block(-6,-6,7,STONE:1)
Block(-6,-6,8,STONE:1)
Block(-6,-5,0,STONE:1)
Block(-6,-5,1,STONE:1)
Block(-6,-5,2,STONE:1)
Block(-6,-5,3,STONE:1)
Block(-6,-5,4,STONE:1)
Block(-6,-5,5,STONE:1)
Block(-6,-5,6,STONE:1)
Block(-6,-5,7,STONE:1)
Block(-6,-5,8,STONE:1)
Block(-6,-4,0,STONE:1)
Block(-6,-4,1,STONE:1)
Block(-6,-4,2,STONE:1)
Block(-6,-4,3,STONE:1)
Block(-6,-4,4,STONE:1)
Block(-6,-4,5,STONE:1)
Block(-6,-4,6,STONE:1)
Block(-6,-4,7,STONE:1)
Block(-6,-4,8,STONE:1)
Block(-6,-3,0,STONE:1)
Block(-6,-3,1,STONE:1)
Block(-6,-3,2,STONE:1)
Block(-6,-3,3,STONE:1)
Block(-6,-3,4,STONE:1)
Block(-6,-3,5,STONE:1)
Block(-6,-3,6,STONE:1)
Block(-6,-3,7,STONE:1)
Block(-6,-3,8,STONE:1)
Block(-6,-2,0,STONE:1)
Block(-6,-2,1,STONE:1)
Block(-6,-2,2,STONE:1)
Block(-6,-2,3,STONE:1)
Block(-6,-2,4,STONE:1)
Block(-6,-2,5,STONE:1)
Block(-6,-2,6,STONE:1)
Block(-6,-2,7,STONE:1)
Block(-6,-2,8,STONE:1)
Block(-6,-1,0,STONE:1)
Block(-6,-1,1,STONE:1)
Block(-6,-1,2,STONE:1)
Block(-6,-1,3,STONE:1)
Block(-6,-1,4,STONE:1)
Block(-6,-1,5,STONE:1)
Block(-6,-1,6,STONE:1)
Block(-6,-1,7,STONE:1)
Block(-6,-1,8,STONE:1)
Block(-6,0,0,STONE:1)
Block(-6,0,1,STONE:1)
Block(-6,0,2,STONE:1)
Block(-6,0,3,STONE:1)
Block(-6,0,4,STONE:1)
Block(-6,0,5,STONE:1)
Block(-6,0,6,STONE:1)
Block(-6,0,7,STONE:1)
Block(-6,0,8,STONE:1)
Block(-6,1,1,STONE:1)
Block(-6,1,2,STONE:1)
Block(-6,1,3,STONE:1)
Block(-6,1,4,STONE:1)
Block(-6,1,5,STONE:1)
Block(-6,1,6,STONE:1)
Block(-6,1,7,STONE:1)
Block(-6,1,8,STONE:1)
Block(-6,2,1,STONE:1)
Block(-6,2,2,STONE:1)
Block(-6,2,3,STONE:1)
Block(-6,2,4,STONE:1)
Block(-6,2,5,STONE:1)
Block(-6,2,6,STAINED_CLAY:14)
Block(-6,2,7,STAINED_CLAY:14)
Block(-6,2,8,STAINED_CLAY:14)
Block(-6,3,1,STONE:1)
Block(-6,3,2,STONE:1)
Block(-6,3,3,STONE:1)
Block(-6,3,4,STONE:1)
Block(-6,3,5,STONE:1)
Block(-6,3,6,STAINED_CLAY:14)
Block(-6,3,7,STAINED_CLAY:14)
Block(-6,4,2,STONE:1)
Block(-6,4,3,STONE:1)
Block(-6,4,4,STONE:1)
Block(-6,4,5,STONE:1)
Block(-6,4,6,STAINED_CLAY:14)
Block(-6,5,2,STAINED_CLAY:14)
Block(-6,5,3,STAINED_CLAY:14)
Block(-6,5,4,STONE:1)
Block(-6,5,5,STONE:1)
Block(-6,5,6,STONE:1)
Block(-6,6,2,STAINED_CLAY:14)
Block(-6,6,3,STAINED_CLAY:14)
Block(-6,6,4,STONE:1)
Block(-6,6,5,STONE:1)
Block(-6,7,3,STAINED_CLAY:14)
Block(-6,7,4,STONE:1)
Block(-5,-10,0,STONE:1)
Block(-5,-10,1,STONE:1)
Block(-5,-9,0,STONE:1)
Block(-5,-9,1,STONE:1)
Block(-5,-9,2,STONE:1)
Block(-5,-9,3,STONE:1)
Block(-5,-9,4,STONE:1)
Block(-5,-9,5,STONE:1)
Block(-5,-9,6,STONE:1)
Block(-5,-9,7,STONE:1)
Block(-5,-8,0,STONE:1)
Block(-5,-8,1,STONE:1)
Block(-5,-8,2,STONE:1)
Block(-5,-8,3,STONE:1)
Block(-5,-8,4,STONE:1)
Block(-5,-8,5,STONE:1)
Block(-5,-8,6,STONE:1)
Block(-5,-7,0,STONE:1)
Block(-5,-7,1,STONE:1)
Block(-5,-7,2,STONE:1)
Block(-5,-7,3,STONE:1)
Block(-5,-7,4,STONE:1)
Block(-5,-7,5,STONE:1)
Block(-5,-7,6,STONE:1)
Block(-5,-7,7,STONE:1)
Block(-5,-6,0,STONE:1)
Block(-5,-6,1,STONE:1)
Block(-5,-6,2,STONE:1)
Block(-5,-6,3,STONE:1)
Block(-5,-6,4,STONE:1)
Block(-5,-6,5,STONE:1)
Block(-5,-6,6,STONE:1)
Block(-5,-6,7,STONE:1)
Block(-5,-6,8,STONE:1)
Block(-5,-5,0,STONE:1)
Block(-5,-5,1,STONE:1)
Block(-5,-5,2,STONE:1)
Block(-5,-5,3,STONE:1)
Block(-5,-5,4,STONE:1)
Block(-5,-5,5,STONE:1)
Block(-5,-5,6,STONE:1)
Block(-5,-5,7,STONE:1)
Block(-5,-5,8,STONE:1)
Block(-5,-4,0,STONE:1)
Block(-5,-4,1,STONE:1)
Block(-5,-4,2,STONE:1)
Block(-5,-4,3,STONE:1)
Block(-5,-4,4,STONE:1)
Block(-5,-4,5,STONE:1)
Block(-5,-4,6,STONE:1)
Block(-5,-4,7,STONE:1)
Block(-5,-4,8,STONE:1)
Block(-5,-3,0,STONE:1)
Block(-5,-3,1,STONE:1)
Block(-5,-3,2,STONE:1)
Block(-5,-3,3,STONE:1)
Block(-5,-3,4,STONE:1)
Block(-5,-3,5,STONE:1)
Block(-5,-3,6,STONE:1)
Block(-5,-3,7,STONE:1)
Block(-5,-3,8,STONE:1)
Block(-5,-2,0,STONE:1)
Block(-5,-2,1,STONE:1)
Block(-5,-2,2,STONE:1)
Block(-5,-2,3,STONE:1)
Block(-5,-2,4,STONE:1)
Block(-5,-2,5,STONE:1)
Block(-5,-2,6,STONE:1)
Block(-5,-2,7,STONE:1)
Block(-5,-2,8,STONE:1)
Block(-5,-1,0,STONE:1)
Block(-5,-1,1,STONE:1)
Block(-5,-1,2,STONE:1)
Block(-5,-1,3,STONE:1)
Block(-5,-1,4,STONE:1)
Block(-5,-1,5,STONE:1)
Block(-5,-1,6,STONE:1)
Block(-5,-1,7,STONE:1)
Block(-5,-1,8,STONE:1)
Block(-5,0,0,STONE:1)
Block(-5,0,1,STONE:1)
Block(-5,0,2,STONE:1)
Block(-5,0,3,STONE:1)
Block(-5,0,4,STONE:1)
Block(-5,0,5,STONE:1)
Block(-5,0,6,STONE:1)
Block(-5,0,7,STONE:1)
Block(-5,0,8,STONE:1)
Block(-5,1,0,STONE:1)
Block(-5,1,1,STONE:1)
Block(-5,1,2,STONE:1)
Block(-5,1,3,STONE:1)
Block(-5,1,4,STONE:1)
Block(-5,1,5,STONE:1)
Block(-5,1,6,STONE:1)
Block(-5,1,7,STONE:1)
Block(-5,1,8,STONE:1)
Block(-5,2,0,STONE:1)
Block(-5,2,1,STONE:1)
Block(-5,2,2,STONE:1)
Block(-5,2,3,STONE:1)
Block(-5,2,4,STONE:1)
Block(-5,2,5,STONE:1)
Block(-5,2,6,STAINED_CLAY:14)
Block(-5,2,7,STAINED_CLAY:14)
Block(-5,2,8,STAINED_CLAY:14)
Block(-5,3,1,STONE:1)
Block(-5,3,2,STONE:1)
Block(-5,3,3,STONE:1)
Block(-5,3,4,STONE:1)
Block(-5,3,5,STONE:1)
Block(-5,3,6,STAINED_CLAY:14)
Block(-5,3,7,STAINED_CLAY:14)
Block(-5,4,1,STONE:1)
Block(-5,4,2,STONE:1)
Block(-5,4,3,STONE:1)
Block(-5,4,4,STONE:1)
Block(-5,4,5,STONE:1)
Block(-5,4,6,STAINED_CLAY:14)
Block(-5,5,1,STAINED_CLAY:14)
Block(-5,5,2,STAINED_CLAY:14)
Block(-5,5,3,STAINED_CLAY:14)
Block(-5,5,4,STONE:1)
Block(-5,5,5,STONE:1)
Block(-5,5,6,STONE:1)
Block(-5,6,2,STAINED_CLAY:14)
Block(-5,6,3,STAINED_CLAY:14)
Block(-5,6,4,STONE:1)
Block(-5,6,5,STONE:1)
Block(-5,7,2,STAINED_CLAY:14)
Block(-5,7,3,STAINED_CLAY:14)
Block(-5,7,4,STONE:1)
Block(-5,8,3,STONE:1)
Block(-4,-9,1,STONE:1)
Block(-4,-9,2,STONE:1)
Block(-4,-9,3,STONE:1)
Block(-4,-9,4,STONE:1)
Block(-4,-9,5,STONE:1)
Block(-4,-8,0,STONE:1)
Block(-4,-8,1,STONE:1)
Block(-4,-8,2,STONE:1)
Block(-4,-8,3,STONE:1)
Block(-4,-8,4,STONE:1)
Block(-4,-8,5,STONE:1)
Block(-4,-8,6,STONE:1)
Block(-4,-7,0,STAINED_CLAY:14)
Block(-4,-7,1,STONE:1)
Block(-4,-7,2,STONE:1)
Block(-4,-7,3,STONE:1)
Block(-4,-7,4,STONE:1)
Block(-4,-7,5,STONE:1)
Block(-4,-7,6,STONE:1)
Block(-4,-6,0,STAINED_CLAY:14)
Block(-4,-6,1,STONE:1)
Block(-4,-6,2,STONE:1)
Block(-4,-6,3,STONE:1)
Block(-4,-6,4,STONE:1)
Block(-4,-6,5,STONE:1)
Block(-4,-6,6,STONE:1)
Block(-4,-6,7,STONE:1)
Block(-4,-6,8,STONE:1)
Block(-4,-5,0,STAINED_CLAY:14)
Block(-4,-5,1,STONE:1)
Block(-4,-5,2,STONE:1)
Block(-4,-5,3,STONE:1)
Block(-4,-5,4,STONE:1)
Block(-4,-5,5,STONE:1)
Block(-4,-5,6,STONE:1)
Block(-4,-5,7,STONE:1)
Block(-4,-5,8,STONE:1)
Block(-4,-4,-1,STONE:1)
Block(-4,-4,0,STONE:1)
Block(-4,-4,1,STONE:1)
Block(-4,-4,2,STONE:1)
Block(-4,-4,3,STONE:1)
Block(-4,-4,4,STONE:1)
Block(-4,-4,5,STONE:1)
Block(-4,-4,6,STONE:1)
Block(-4,-4,7,STONE:1)
Block(-4,-4,8,STONE:1)
Block(-4,-3,-1,STONE:1)
Block(-4,-3,0,STONE:1)
Block(-4,-3,1,STONE:1)
Block(-4,-3,2,STONE:1)
Block(-4,-3,3,STONE:1)
Block(-4,-3,4,STONE:1)
Block(-4,-3,5,STONE:1)
Block(-4,-3,6,STONE:1)
Block(-4,-3,7,STONE:1)
Block(-4,-3,8,STONE:1)
Block(-4,-2,0,STONE:1)
Block(-4,-2,1,STONE:1)
Block(-4,-2,2,STONE:1)
Block(-4,-2,3,STONE:1)
Block(-4,-2,4,STONE:1)
Block(-4,-2,5,STONE:1)
Block(-4,-2,6,STONE:1)
Block(-4,-2,7,STONE:1)
Block(-4,-2,8,STONE:1)
Block(-4,-1,0,STONE:1)
Block(-4,-1,1,STONE:1)
Block(-4,-1,2,STONE:1)
Block(-4,-1,3,STONE:1)
Block(-4,-1,4,STONE:1)
Block(-4,-1,5,STONE:1)
Block(-4,-1,6,STAINED_CLAY:14)
Block(-4,-1,7,STAINED_CLAY:14)
Block(-4,0,0,STONE:1)
Block(-4,0,1,STONE:1)
Block(-4,0,2,STONE:1)
Block(-4,0,3,STONE:1)
Block(-4,0,4,STONE:1)
Block(-4,0,5,STONE:1)
Block(-4,0,6,STAINED_CLAY:14)
Block(-4,0,7,STAINED_CLAY:14)
Block(-4,1,0,STONE:1)
Block(-4,1,1,STONE:1)
Block(-4,1,2,STONE:1)
Block(-4,1,3,STONE:1)
Block(-4,1,4,STONE:1)
Block(-4,1,5,STONE:1)
Block(-4,1,6,STAINED_CLAY:14)
Block(-4,1,7,STAINED_CLAY:14)
Block(-4,2,0,STONE:1)
Block(-4,2,1,STONE:1)
Block(-4,2,2,STONE:1)
Block(-4,2,3,STONE:1)
Block(-4,2,4,STONE:1)
Block(-4,2,5,STONE:1)
Block(-4,2,6,STAINED_CLAY:14)
Block(-4,2,7,STAINED_CLAY:14)
Block(-4,3,0,STONE:1)
Block(-4,3,1,STONE:1)
Block(-4,3,2,STONE:1)
Block(-4,3,3,STONE:1)
Block(-4,3,4,STONE:1)
Block(-4,3,5,STONE:1)
Block(-4,3,6,STAINED_CLAY:14)
Block(-4,3,7,STAINED_CLAY:14)
Block(-4,4,1,STONE:1)
Block(-4,4,2,STONE:1)
Block(-4,4,3,STONE:1)
Block(-4,4,4,STONE:1)
Block(-4,4,5,STONE:1)
Block(-4,4,6,STAINED_CLAY:14)
Block(-4,5,1,STAINED_CLAY:14)
Block(-4,5,2,STAINED_CLAY:14)
Block(-4,5,3,STAINED_CLAY:14)
Block(-4,5,4,STONE:1)
Block(-4,5,5,STONE:1)
Block(-4,5,6,STONE:1)
Block(-4,6,2,STAINED_CLAY:14)
Block(-4,6,3,STAINED_CLAY:14)
Block(-4,6,4,STONE:1)
Block(-4,6,5,STONE:1)
Block(-4,7,3,STAINED_CLAY:14)
Block(-4,7,4,STONE:1)
Block(-3,-9,2,STONE:1)
Block(-3,-9,3,STONE:1)
Block(-3,-9,4,STONE:1)
Block(-3,-9,5,STONE:1)
Block(-3,-8,0,STONE:1)
Block(-3,-8,1,STONE:1)
Block(-3,-8,2,STONE:1)
Block(-3,-8,3,STONE:1)
Block(-3,-8,4,STONE:1)
Block(-3,-8,5,STONE:1)
Block(-3,-8,6,STONE:1)
Block(-3,-7,0,STAINED_CLAY:14)
Block(-3,-7,1,STONE:1)
Block(-3,-7,2,STONE:1)
Block(-3,-7,3,STONE:1)
Block(-3,-7,4,STONE:1)
Block(-3,-7,5,STONE:1)
Block(-3,-7,6,STONE:1)
Block(-3,-7,7,STONE:1)
Block(-3,-6,-1,STAINED_CLAY:14)
Block(-3,-6,0,STAINED_CLAY:14)
Block(-3,-6,1,STONE:1)
Block(-3,-6,2,STONE:1)
Block(-3,-6,3,STONE:1)
Block(-3,-6,4,STONE:1)
Block(-3,-6,5,STONE:1)
Block(-3,-6,6,STONE:1)
Block(-3,-6,7,STONE:1)
Block(-3,-6,8,STONE:1)
Block(-3,-5,-1,STAINED_CLAY:14)
Block(-3,-5,0,STAINED_CLAY:14)
Block(-3,-5,1,STONE:1)
Block(-3,-5,2,STONE:1)
Block(-3,-5,3,STONE:1)
Block(-3,-5,4,STONE:1)
Block(-3,-5,5,STONE:1)
Block(-3,-5,6,STONE:1)
Block(-3,-5,7,STONE:1)
Block(-3,-5,8,STONE:1)
Block(-3,-4,-1,STAINED_CLAY:14)
Block(-3,-4,0,STAINED_CLAY:14)
Block(-3,-4,1,STONE:1)
Block(-3,-4,2,STONE:1)
Block(-3,-4,3,STONE:1)
Block(-3,-4,4,STONE:1)
Block(-3,-4,5,STONE:1)
Block(-3,-4,6,STONE:1)
Block(-3,-4,7,STONE:1)
Block(-3,-4,8,STONE:1)
Block(-3,-3,-1,STAINED_CLAY:14)
Block(-3,-3,0,STAINED_CLAY:14)
Block(-3,-3,1,STAINED_CLAY:14)
Block(-3,-3,2,STONE:1)
Block(-3,-3,3,STONE:1)
Block(-3,-3,4,STONE:1)
Block(-3,-3,5,STONE:1)
Block(-3,-3,6,STONE:1)
Block(-3,-3,7,STONE:1)
Block(-3,-3,8,STONE:1)
Block(-3,-2,-1,STAINED_CLAY:14)
Block(-3,-2,0,STAINED_CLAY:14)
Block(-3,-2,1,STAINED_CLAY:14)
Block(-3,-2,2,STONE:1)
Block(-3,-2,3,STONE:1)
Block(-3,-2,4,STONE:1)
Block(-3,-2,5,STONE:1)
Block(-3,-2,6,STONE:1)
Block(-3,-2,7,STONE:1)
Block(-3,-1,0,STAINED_CLAY:14)
Block(-3,-1,1,STAINED_CLAY:14)
Block(-3,-1,2,STONE:1)
Block(-3,-1,3,STONE:1)
Block(-3,-1,4,STONE:1)
Block(-3,-1,5,STONE:1)
Block(-3,-1,6,STAINED_CLAY:14)
Block(-3,-1,7,STAINED_CLAY:14)
Block(-3,0,-1,STAINED_CLAY:14)
Block(-3,0,0,STAINED_CLAY:14)
Block(-3,0,1,STAINED_CLAY:14)
Block(-3,0,2,STONE:1)
Block(-3,0,3,STAINED_CLAY:14)
Block(-3,0,4,STONE:1)
Block(-3,0,5,STONE:1)
Block(-3,0,6,STAINED_CLAY:14)
Block(-3,0,7,STAINED_CLAY:14)
Block(-3,1,0,STONE:1)
Block(-3,1,1,STONE:1)
Block(-3,1,2,STONE:1)
Block(-3,1,3,STAINED_CLAY:14)
Block(-3,1,4,STONE:1)
Block(-3,1,5,STONE:1)
Block(-3,1,6,STAINED_CLAY:14)
Block(-3,1,7,STAINED_CLAY:14)
Block(-3,2,0,STONE:1)
Block(-3,2,1,STONE:1)
Block(-3,2,2,STONE:1)
Block(-3,2,3,STONE:1)
Block(-3,2,4,STONE:1)
Block(-3,2,5,STONE:1)
Block(-3,2,6,STAINED_CLAY:14)
Block(-3,2,7,STAINED_CLAY:14)
Block(-3,3,1,STONE:1)
Block(-3,3,2,STONE:1)
Block(-3,3,3,STONE:1)
Block(-3,3,4,STONE:1)
Block(-3,3,5,STONE:1)
Block(-3,3,6,STAINED_CLAY:14)
Block(-3,4,1,STONE:1)
Block(-3,4,2,STONE:1)
Block(-3,4,3,STONE:1)
Block(-3,4,4,STONE:1)
Block(-3,4,5,STONE:1)
Block(-3,4,6,STAINED_CLAY:14)
Block(-3,5,2,STONE:1)
Block(-3,5,3,STONE:1)
Block(-3,5,4,STONE:1)
Block(-3,5,5,STONE:1)
Block(-3,6,3,STONE:1)
Block(-3,6,4,STONE:1)
Block(-3,6,5,STONE:1)
Block(-2,-9,2,STONE:1)
Block(-2,-9,3,STONE:1)
Block(-2,-9,4,STONE:1)
Block(-2,-9,5,STONE:1)
Block(-2,-8,0,STONE:1)
Block(-2,-8,1,STONE:1)
Block(-2,-8,2,STONE:1)
Block(-2,-8,3,STONE:1)
Block(-2,-8,4,STONE:1)
Block(-2,-8,5,STAINED_CLAY:14)
Block(-2,-8,6,STAINED_CLAY:14)
Block(-2,-7,0,STAINED_CLAY:14)
Block(-2,-7,1,STONE:1)
Block(-2,-7,2,STONE:1)
Block(-2,-7,3,STONE:1)
Block(-2,-7,4,STONE:1)
Block(-2,-7,5,STAINED_CLAY:14)
Block(-2,-7,6,STAINED_CLAY:14)
Block(-2,-6,-1,STAINED_CLAY:14)
Block(-2,-6,0,STAINED_CLAY:14)
Block(-2,-6,1,STONE:1)
Block(-2,-6,2,STONE:1)
Block(-2,-6,3,STONE:1)
Block(-2,-6,4,STONE:1)
Block(-2,-6,5,STAINED_CLAY:14)
Block(-2,-6,6,STAINED_CLAY:14)
Block(-2,-6,7,STAINED_CLAY:14)
Block(-2,-6,8,STONE:1)
Block(-2,-5,-1,STAINED_CLAY:14)
Block(-2,-5,0,STAINED_CLAY:14)
Block(-2,-5,1,STONE:1)
Block(-2,-5,2,STONE:1)
Block(-2,-5,3,STONE:1)
Block(-2,-5,4,STONE:1)
Block(-2,-5,5,STONE:1)
Block(-2,-5,6,STONE:1)
Block(-2,-5,7,STONE:1)
Block(-2,-5,8,STONE:1)
Block(-2,-4,-1,STAINED_CLAY:14)
Block(-2,-4,0,STAINED_CLAY:14)
Block(-2,-4,1,STONE:1)
Block(-2,-4,2,STONE:1)
Block(-2,-4,3,STONE:1)
Block(-2,-4,4,STONE:1)
Block(-2,-4,5,STONE:1)
Block(-2,-4,6,STONE:1)
Block(-2,-4,7,STONE:1)
Block(-2,-4,8,STONE:1)
Block(-2,-3,-1,STAINED_CLAY:14)
Block(-2,-3,0,STAINED_CLAY:14)
Block(-2,-3,1,STAINED_CLAY:14)
Block(-2,-3,2,STONE:1)
Block(-2,-3,3,STONE:1)
Block(-2,-3,4,STONE:1)
Block(-2,-3,5,STONE:1)
Block(-2,-3,6,STONE:1)
Block(-2,-3,7,STONE:1)
Block(-2,-2,0,STAINED_CLAY:14)
Block(-2,-2,1,STAINED_CLAY:14)
Block(-2,-2,2,STONE:1)
Block(-2,-2,3,STONE:1)
Block(-2,-2,4,STONE:1)
Block(-2,-2,5,STONE:1)
Block(-2,-2,6,STONE:1)
Block(-2,-2,7,STONE:1)
Block(-2,-1,0,STAINED_CLAY:14)
Block(-2,-1,1,STAINED_CLAY:14)
Block(-2,-1,2,STAINED_CLAY:14)
Block(-2,-1,3,STONE:1)
Block(-2,-1,4,STONE:1)
Block(-2,-1,5,STONE:1)
Block(-2,-1,6,STAINED_CLAY:14)
Block(-2,0,0,STAINED_CLAY:14)
Block(-2,0,1,STAINED_CLAY:14)
Block(-2,0,2,STAINED_CLAY:14)
Block(-2,0,3,STAINED_CLAY:14)
Block(-2,0,4,STAINED_CLAY:14)
Block(-2,0,5,STAINED_CLAY:14)
Block(-2,0,6,STAINED_CLAY:14)
Block(-2,1,0,STAINED_CLAY:14)
Block(-2,1,1,STAINED_CLAY:14)
Block(-2,1,2,STAINED_CLAY:14)
Block(-2,1,3,STAINED_CLAY:14)
Block(-2,1,4,STAINED_CLAY:14)
Block(-2,1,5,STAINED_CLAY:14)
Block(-2,1,6,STAINED_CLAY:14)
Block(-2,2,1,STAINED_CLAY:14)
Block(-2,2,2,STAINED_CLAY:14)
Block(-2,2,3,STAINED_CLAY:14)
Block(-2,2,4,STAINED_CLAY:14)
Block(-2,2,5,STAINED_CLAY:14)
Block(-2,2,6,STAINED_CLAY:14)
Block(-2,3,1,STONE:1)
Block(-2,3,2,STONE:1)
Block(-2,3,3,STONE:1)
Block(-2,3,4,STONE:1)
Block(-2,3,5,STONE:1)
Block(-2,4,2,STONE:1)
Block(-2,4,3,STONE:1)
Block(-2,4,4,STONE:1)
Block(-2,4,5,STONE:1)
Block(-2,5,3,STONE:1)
Block(-2,5,4,STONE:1)
Block(-1,-9,5,STONE:1)
Block(-1,-8,1,STONE:1)
Block(-1,-8,2,STONE:1)
Block(-1,-8,3,STONE:1)
Block(-1,-8,4,STONE:1)
Block(-1,-8,5,STAINED_CLAY:14)
Block(-1,-7,1,STONE:1)
Block(-1,-7,2,STONE:1)
Block(-1,-7,3,STONE:1)
Block(-1,-7,4,STONE:1)
Block(-1,-7,5,STAINED_CLAY:14)
Block(-1,-7,6,STAINED_CLAY:14)
Block(-1,-7,7,STAINED_CLAY:14)
Block(-1,-6,0,STONE:1)
Block(-1,-6,1,STONE:1)
Block(-1,-6,2,STONE:1)
Block(-1,-6,3,STONE:1)
Block(-1,-6,4,STAINED_CLAY:14)
Block(-1,-6,5,STAINED_CLAY:14)
Block(-1,-6,6,STAINED_CLAY:14)
Block(-1,-6,7,STAINED_CLAY:14)
Block(-1,-5,0,STONE:1)
Block(-1,-5,1,STONE:1)
Block(-1,-5,2,STONE:1)
Block(-1,-5,3,STONE:1)
Block(-1,-5,4,STAINED_CLAY:14)
Block(-1,-5,5,STAINED_CLAY:14)
Block(-1,-5,6,STAINED_CLAY:14)
Block(-1,-5,7,STONE:1)
Block(-1,-4,0,STAINED_CLAY:14)
Block(-1,-4,1,STONE:1)
Block(-1,-4,2,STONE:1)
Block(-1,-4,3,STONE:1)
Block(-1,-4,4,STAINED_CLAY:14)
Block(-1,-4,5,STAINED_CLAY:14)
Block(-1,-4,6,STAINED_CLAY:14)
Block(-1,-4,7,STONE:1)
Block(-1,-3,0,STAINED_CLAY:14)
Block(-1,-3,1,STAINED_CLAY:14)
Block(-1,-3,2,STONE:1)
Block(-1,-3,3,STONE:1)
Block(-1,-3,4,STONE:1)
Block(-1,-3,5,STONE:1)
Block(-1,-3,6,STONE:1)
Block(-1,-3,7,STONE:1)
Block(-1,-2,1,STAINED_CLAY:14)
Block(-1,-2,2,STONE:1)
Block(-1,-2,3,STONE:1)
Block(-1,-2,4,STAINED_CLAY:14)
Block(-1,-2,5,STAINED_CLAY:14)
Block(-1,-2,6,STAINED_CLAY:14)
Block(-1,-1,1,STAINED_CLAY:14)
Block(-1,-1,2,STAINED_CLAY:14)
Block(-1,-1,3,STONE:1)
Block(-1,-1,4,STAINED_CLAY:14)
Block(-1,-1,5,STAINED_CLAY:14)
Block(-1,-1,6,STAINED_CLAY:14)
Block(-1,0,1,STAINED_CLAY:14)
Block(-1,0,2,STAINED_CLAY:14)
Block(-1,0,3,STAINED_CLAY:14)
Block(-1,0,4,STAINED_CLAY:14)
Block(-1,0,5,STAINED_CLAY:14)
Block(-1,1,1,STAINED_CLAY:14)
Block(-1,1,2,STAINED_CLAY:14)
Block(-1,1,3,STAINED_CLAY:14)
Block(-1,1,4,STAINED_CLAY:14)
Block(-1,1,5,STAINED_CLAY:14)
Block(-1,2,2,STAINED_CLAY:14)
Block(-1,2,3,STAINED_CLAY:14)
Block(-1,2,4,STAINED_CLAY:14)
Block(-1,2,5,STAINED_CLAY:14)
Block(-1,3,4,STONE:1)
Block(0,-8,2,STONE:1)
Block(0,-8,3,STONE:1)
Block(0,-8,4,STONE:1)
Block(0,-8,5,STAINED_CLAY:14)
Block(0,-7,2,STONE:1)
Block(0,-7,3,STONE:1)
Block(0,-7,4,STONE:1)
Block(0,-7,5,STAINED_CLAY:14)
Block(0,-6,1,STONE:1)
Block(0,-6,2,STONE:1)
Block(0,-6,3,STONE:1)
Block(0,-6,4,STAINED_CLAY:14)
Block(0,-6,5,STAINED_CLAY:14)
Block(0,-6,6,STAINED_CLAY:14)
Block(0,-5,1,STONE:1)
Block(0,-5,2,STONE:1)
Block(0,-5,3,STONE:1)
Block(0,-5,4,STAINED_CLAY:14)
Block(0,-5,5,STAINED_CLAY:14)
Block(0,-5,6,STAINED_CLAY:14)
Block(0,-4,2,STONE:1)
Block(0,-4,3,STONE:1)
Block(0,-4,4,STAINED_CLAY:14)
Block(0,-4,5,STAINED_CLAY:14)
Block(0,-4,6,STAINED_CLAY:14)
Block(0,-3,2,STONE:1)
Block(0,-3,3,STONE:1)
Block(0,-3,4,STONE:1)
Block(0,-3,5,STONE:1)
Block(0,-3,6,STONE:1)
Block(0,-2,2,STONE:1)
Block(0,-2,3,STONE:1)
Block(0,-2,4,STAINED_CLAY:14)
Block(0,-2,5,STAINED_CLAY:14)
Block(0,-1,3,STONE:1)
Block(0,-1,4,STAINED_CLAY:14)
Block(0,-1,5,STAINED_CLAY:14)
Block(0,0,4,STAINED_CLAY:14)

#######################################################################
# +-----------------------------------------------------------------+ #
# |                            BO3 checks                           | #
# +-----------------------------------------------------------------+ #
#######################################################################

BlockCheck(-4,-5,-1,Solid)

#######################################################################
# +-----------------------------------------------------------------+ #
# |                             Branches                            | #
# +-----------------------------------------------------------------+ #
#######################################################################


#######################################################################
# +-----------------------------------------------------------------+ #
# |                             Entities                            | #
# +-----------------------------------------------------------------+ #
#######################################################################


#######################################################################
# +-----------------------------------------------------------------+ #
# |                            Particles                            | #
# +-----------------------------------------------------------------+ #
#######################################################################


#######################################################################
# +-----------------------------------------------------------------+ #
# |                             Spawners                            | #
# +-----------------------------------------------------------------+ #
#######################################################################


#######################################################################
# +-----------------------------------------------------------------+ #
# |                             ModData                             | #
# +-----------------------------------------------------------------+ #
#######################################################################

