
#######################################################################
# +-----------------------------------------------------------------+ #
# |                            BO3 object                           | #
# +-----------------------------------------------------------------+ #
#######################################################################

Author: NLBlackEagle

Description: No description given

Version: 3

SettingsMode: WriteDisable


#######################################################################
# +-----------------------------------------------------------------+ #
# |                          Main settings                          | #
# +-----------------------------------------------------------------+ #
#######################################################################

Tree: true

Frequency: 1

Rarity: 4.0

RotateRandomly: true

SpawnHeight: highestBlock

SpawnHeightOffset: 0

SpawnHeightVariance: 0

##############################
# Height Limits for the BO3. #
##############################

MinHeight: 0

MaxHeight: 80

######################
# Extrusion settings #
######################

ExtrudeMode: None

ExtrudeThroughBlocks: AIR

MaxBranchDepth: 10

ExcludedBiomes: All


#######################################################################
# +-----------------------------------------------------------------+ #
# |                      Source block settings                      | #
# +-----------------------------------------------------------------+ #
#######################################################################

SourceBlocks: AIR,GRASS,STONE,DIRT

MaxPercentageOutsideSourceBlock: 0

OutsideSourceBlock: placeAnyway

IsOTGPlus: false

InheritBO3: 

InheritBO3Rotation: NORTH

OverrideChildSettings: true

OverrideParentHeight: false

CanOverride: false

BranchFrequency: 0

BranchFrequencyGroup: 

MustBeBelowOther: false

MustBeInside: 

CannotBeInside: 

ReplacesBO3: 

CanSpawnOnWater: true

SpawnOnWaterOnly: false

SpawnUnderWater: false

SpawnAtWaterLevel: false

HeightOffset: 0

RemoveAir: true

ReplaceAbove: 

ReplaceBelow: 

ReplaceWithBiomeBlocks: true

ReplaceWithGroundBlock: DIRT

ReplaceWithSurfaceBlock: GRASS

SmoothRadius: 0

SmoothHeightOffset: 0

SmoothStartTop: false

SmoothStartWood: false

SmoothingSurfaceBlock: 

SmoothingGroundBlock: 

BO3Group: 

IsSpawnPoint: false


#######################################################################
# +-----------------------------------------------------------------+ #
# |                              Blocks                             | #
# +-----------------------------------------------------------------+ #
#######################################################################

Block(-6,-4,-1,STONE:1)
Block(-6,-4,0,STONE:1)
Block(-6,-4,1,STONE:1)
Block(-6,-3,-1,STAINED_CLAY:14)
Block(-6,-3,0,STONE:1)
Block(-6,-3,1,STONE:1)
Block(-6,-2,-1,STAINED_CLAY:14)
Block(-6,-2,0,STAINED_CLAY:14)
Block(-6,-2,1,STONE:1)
Block(-6,-1,-1,STAINED_CLAY:14)
Block(-6,-1,0,STONE:1)
Block(-6,-1,1,STONE:1)
Block(-6,0,-1,STAINED_CLAY:14)
Block(-6,0,0,STONE:1)
Block(-6,0,1,STONE:1)
Block(-6,1,-1,STAINED_CLAY:14)
Block(-6,1,0,STAINED_CLAY:14)
Block(-6,1,1,STONE:1)
Block(-6,2,-1,STAINED_CLAY:14)
Block(-6,2,0,LEAVES:7)
Block(-6,2,1,STONE:1)
Block(-6,3,-1,STAINED_CLAY:14)
Block(-6,3,0,LEAVES:7)
Block(-6,3,1,STONE:1)
Block(-6,4,-1,LEAVES:7)
Block(-6,4,0,LEAVES:7)
Block(-6,4,1,LEAVES:7)
Block(-5,-7,-2,STAINED_CLAY:14)
Block(-5,-6,-2,STAINED_CLAY:14)
Block(-5,-5,-2,STONE:1)
Block(-5,-5,-1,STONE:1)
Block(-5,-5,1,STONE:1)
Block(-5,-4,-2,STONE:1)
Block(-5,-4,-1,STONE:1)
Block(-5,-4,0,STONE:1)
Block(-5,-4,1,STONE:1)
Block(-5,-3,-2,STONE:1)
Block(-5,-3,-1,STONE:1)
Block(-5,-3,0,STONE:1)
Block(-5,-3,1,STONE:1)
Block(-5,-2,-2,STONE:1)
Block(-5,-2,-1,STAINED_CLAY:14)
Block(-5,-2,0,STONE:1)
Block(-5,-2,1,STONE:1)
Block(-5,-1,-2,STONE:1)
Block(-5,-1,-1,STONE:1)
Block(-5,-1,0,STONE:1)
Block(-5,-1,1,STONE:1)
Block(-5,0,-2,STONE:1)
Block(-5,0,-1,STONE:1)
Block(-5,0,0,STONE:1)
Block(-5,0,1,STONE:1)
Block(-5,1,-2,STONE:1)
Block(-5,1,-1,STAINED_CLAY:14)
Block(-5,1,0,STONE:1)
Block(-5,1,1,STONE:1)
Block(-5,2,-2,STONE:1)
Block(-5,2,-1,STONE:1)
Block(-5,2,0,STONE:1)
Block(-5,2,1,STONE:1)
Block(-5,3,-2,STONE:1)
Block(-5,3,-1,STONE:1)
Block(-5,3,0,STONE:1)
Block(-5,3,1,STONE:1)
Block(-5,4,-2,STONE:1)
Block(-5,4,-1,STONE:1)
Block(-5,4,0,STONE:1)
Block(-5,4,1,LEAVES:7)
Block(-5,5,-2,LEAVES:7)
Block(-5,5,-1,STONE:1)
Block(-5,5,0,STONE:1)
Block(-5,6,-1,LEAVES:7)
Block(-5,6,0,STONE:1)
Block(-5,7,0,LEAVES:7)
Block(-5,8,0,LEAVES:7)
Block(-4,-7,-1,STONE:1)
Block(-4,-7,1,STONE:1)
Block(-4,-7,2,STONE:1)
Block(-4,-6,-4,STAINED_CLAY:14)
Block(-4,-6,-3,STAINED_CLAY:14)
Block(-4,-6,-2,STONE:1)
Block(-4,-6,-1,STONE:1)
Block(-4,-6,0,STONE:1)
Block(-4,-6,1,STONE:1)
Block(-4,-6,2,STONE:1)
Block(-4,-5,-5,STAINED_CLAY:14)
Block(-4,-5,-4,STONE:1)
Block(-4,-5,-3,STONE:1)
Block(-4,-5,-2,STONE:1)
Block(-4,-5,-1,STONE:1)
Block(-4,-5,0,STONE:1)
Block(-4,-5,1,STONE:1)
Block(-4,-5,2,STONE:1)
Block(-4,-5,3,STAINED_CLAY:14)
Block(-4,-5,4,STAINED_CLAY:14)
Block(-4,-4,-5,STAINED_CLAY:14)
Block(-4,-4,-4,STONE:1)
Block(-4,-4,-3,STONE:1)
Block(-4,-4,-2,STONE:1)
Block(-4,-4,-1,STONE:1)
Block(-4,-4,0,STONE:1)
Block(-4,-4,1,STONE:1)
Block(-4,-4,2,STAINED_CLAY:14)
Block(-4,-4,3,STAINED_CLAY:14)
Block(-4,-4,4,STAINED_CLAY:14)
Block(-4,-3,-5,STAINED_CLAY:14)
Block(-4,-3,-4,STAINED_CLAY:14)
Block(-4,-3,-3,STONE:1)
Block(-4,-3,-2,STONE:1)
Block(-4,-3,-1,STONE:1)
Block(-4,-3,0,STONE:1)
Block(-4,-3,1,STONE:1)
Block(-4,-3,2,STONE:1)
Block(-4,-3,3,STAINED_CLAY:14)
Block(-4,-3,4,STONE:1)
Block(-4,-2,-5,STAINED_CLAY:14)
Block(-4,-2,-4,STAINED_CLAY:14)
Block(-4,-2,-3,STONE:1)
Block(-4,-2,-2,STONE:1)
Block(-4,-2,-1,STONE:1)
Block(-4,-2,0,STONE:1)
Block(-4,-2,1,STONE:1)
Block(-4,-2,2,STONE:1)
Block(-4,-2,3,STAINED_CLAY:14)
Block(-4,-2,4,STONE:1)
Block(-4,-1,-5,STAINED_CLAY:14)
Block(-4,-1,-4,STAINED_CLAY:14)
Block(-4,-1,-3,STAINED_CLAY:14)
Block(-4,-1,-2,STONE:1)
Block(-4,-1,-1,STONE:1)
Block(-4,-1,0,STONE:1)
Block(-4,-1,1,STONE:1)
Block(-4,-1,2,STAINED_CLAY:14)
Block(-4,-1,3,STAINED_CLAY:14)
Block(-4,-1,4,STAINED_CLAY:14)
Block(-4,0,-5,STAINED_CLAY:14)
Block(-4,0,-4,STAINED_CLAY:14)
Block(-4,0,-3,STONE:1)
Block(-4,0,-2,STONE:1)
Block(-4,0,-1,STONE:1)
Block(-4,0,0,STONE:1)
Block(-4,0,1,STONE:1)
Block(-4,0,2,STAINED_CLAY:14)
Block(-4,0,3,STAINED_CLAY:14)
Block(-4,1,-5,STAINED_CLAY:14)
Block(-4,1,-4,STAINED_CLAY:14)
Block(-4,1,-3,STONE:1)
Block(-4,1,-2,STONE:1)
Block(-4,1,-1,STONE:1)
Block(-4,1,0,STONE:1)
Block(-4,1,1,STAINED_CLAY:14)
Block(-4,1,2,STAINED_CLAY:14)
Block(-4,1,3,STAINED_CLAY:14)
Block(-4,2,-3,STONE:1)
Block(-4,2,-2,STONE:1)
Block(-4,2,-1,STONE:1)
Block(-4,2,0,STONE:1)
Block(-4,2,1,STONE:1)
Block(-4,2,2,STAINED_CLAY:14)
Block(-4,2,3,STONE:1)
Block(-4,3,-3,STONE:1)
Block(-4,3,-2,STONE:1)
Block(-4,3,-1,STONE:1)
Block(-4,3,0,STONE:1)
Block(-4,3,1,STONE:1)
Block(-4,3,2,STAINED_CLAY:14)
Block(-4,3,3,STONE:1)
Block(-4,4,-3,STONE:1)
Block(-4,4,-2,STONE:1)
Block(-4,4,-1,STONE:1)
Block(-4,4,0,STONE:1)
Block(-4,4,1,STONE:1)
Block(-4,4,2,STONE:1)
Block(-4,4,3,LEAVES:7)
Block(-4,5,-3,STONE:1)
Block(-4,5,-2,STONE:1)
Block(-4,5,-1,STONE:1)
Block(-4,5,0,STONE:1)
Block(-4,5,1,STONE:1)
Block(-4,5,2,STONE:1)
Block(-4,5,3,LEAVES:7)
Block(-4,6,-3,LEAVES:7)
Block(-4,6,-2,STONE:1)
Block(-4,6,-1,STONE:1)
Block(-4,6,0,STONE:1)
Block(-4,6,1,STONE:1)
Block(-4,6,2,STONE:1)
Block(-4,6,3,LEAVES:7)
Block(-4,7,-2,STONE:1)
Block(-4,7,-1,STONE:1)
Block(-4,7,0,STONE:1)
Block(-4,7,1,STONE:1)
Block(-4,7,2,LEAVES:7)
Block(-4,8,-1,STONE:1)
Block(-4,8,0,STONE:1)
Block(-4,8,1,LEAVES:7)
Block(-4,9,0,LEAVES:7)
Block(-3,-9,-2,STONE:1)
Block(-3,-9,-1,STONE:1)
Block(-3,-9,0,STONE:1)
Block(-3,-8,-1,STONE:1)
Block(-3,-8,0,STONE:1)
Block(-3,-8,1,STONE:1)
Block(-3,-8,3,STONE:1)
Block(-3,-7,-4,STONE:1)
Block(-3,-7,-2,STONE:1)
Block(-3,-7,-1,STONE:1)
Block(-3,-7,0,STONE:1)
Block(-3,-7,1,STONE:1)
Block(-3,-7,2,STONE:1)
Block(-3,-6,-4,STONE:1)
Block(-3,-6,-3,STONE:1)
Block(-3,-6,-2,STONE:1)
Block(-3,-6,-1,STONE:1)
Block(-3,-6,0,STONE:1)
Block(-3,-6,1,STONE:1)
Block(-3,-6,2,STONE:1)
Block(-3,-6,3,STONE:1)
Block(-3,-5,-4,STONE:1)
Block(-3,-5,-3,STONE:1)
Block(-3,-5,-2,STONE:1)
Block(-3,-5,-1,STONE:1)
Block(-3,-5,0,STONE:1)
Block(-3,-5,1,STONE:1)
Block(-3,-5,2,STONE:1)
Block(-3,-5,3,STONE:1)
Block(-3,-5,4,STONE:1)
Block(-3,-4,-6,STONE:1)
Block(-3,-4,-5,STONE:1)
Block(-3,-4,-4,STONE:1)
Block(-3,-4,-3,STONE:1)
Block(-3,-4,-2,STONE:1)
Block(-3,-4,-1,STONE:1)
Block(-3,-4,0,STONE:1)
Block(-3,-4,1,STONE:1)
Block(-3,-4,2,STONE:1)
Block(-3,-4,3,STAINED_CLAY:14)
Block(-3,-4,4,STONE:1)
Block(-3,-3,-6,STONE:1)
Block(-3,-3,-5,STAINED_CLAY:14)
Block(-3,-3,-4,STONE:1)
Block(-3,-3,-3,STONE:1)
Block(-3,-3,-2,STONE:1)
Block(-3,-3,-1,STONE:1)
Block(-3,-3,0,STONE:1)
Block(-3,-3,1,STONE:1)
Block(-3,-3,2,STONE:1)
Block(-3,-3,3,STONE:1)
Block(-3,-3,4,STONE:1)
Block(-3,-2,-6,STONE:1)
Block(-3,-2,-5,STONE:1)
Block(-3,-2,-4,STONE:1)
Block(-3,-2,-3,STONE:1)
Block(-3,-2,-2,STONE:1)
Block(-3,-2,-1,STONE:1)
Block(-3,-2,0,STONE:1)
Block(-3,-2,1,STONE:1)
Block(-3,-2,2,STONE:1)
Block(-3,-2,3,STONE:1)
Block(-3,-2,4,STONE:1)
Block(-3,-1,-6,STONE:1)
Block(-3,-1,-5,STONE:1)
Block(-3,-1,-4,STAINED_CLAY:14)
Block(-3,-1,-3,STONE:1)
Block(-3,-1,-2,STONE:1)
Block(-3,-1,-1,STONE:1)
Block(-3,-1,0,STONE:1)
Block(-3,-1,1,STONE:1)
Block(-3,-1,2,STONE:1)
Block(-3,-1,3,STAINED_CLAY:14)
Block(-3,-1,4,STONE:1)
Block(-3,0,-6,STONE:1)
Block(-3,0,-5,STONE:1)
Block(-3,0,-4,STONE:1)
Block(-3,0,-3,STONE:1)
Block(-3,0,-2,STONE:1)
Block(-3,0,-1,STONE:1)
Block(-3,0,0,STONE:1)
Block(-3,0,1,STONE:1)
Block(-3,0,2,STONE:1)
Block(-3,0,3,STONE:1)
Block(-3,0,4,STONE:1)
Block(-3,1,-6,LEAVES:7)
Block(-3,1,-5,STAINED_CLAY:14)
Block(-3,1,-4,STONE:1)
Block(-3,1,-3,STONE:1)
Block(-3,1,-2,STONE:1)
Block(-3,1,-1,STONE:1)
Block(-3,1,0,STONE:1)
Block(-3,1,1,STONE:1)
Block(-3,1,2,STAINED_CLAY:14)
Block(-3,1,3,STONE:1)
Block(-3,1,4,STONE:1)
Block(-3,2,-6,LEAVES:7)
Block(-3,2,-5,STONE:1)
Block(-3,2,-4,STONE:1)
Block(-3,2,-3,STONE:1)
Block(-3,2,-2,STONE:1)
Block(-3,2,-1,STONE:1)
Block(-3,2,0,STONE:1)
Block(-3,2,1,STONE:1)
Block(-3,2,2,STONE:1)
Block(-3,2,3,STONE:1)
Block(-3,2,4,STONE:1)
Block(-3,3,-5,LEAVES:7)
Block(-3,3,-4,STONE:1)
Block(-3,3,-3,STONE:1)
Block(-3,3,-2,STONE:1)
Block(-3,3,-1,STONE:1)
Block(-3,3,0,STONE:1)
Block(-3,3,1,STONE:1)
Block(-3,3,2,STONE:1)
Block(-3,3,3,STONE:1)
Block(-3,3,4,STONE:1)
Block(-3,4,-5,LEAVES:7)
Block(-3,4,-4,STONE:1)
Block(-3,4,-3,STONE:1)
Block(-3,4,-2,STONE:1)
Block(-3,4,-1,STONE:1)
Block(-3,4,0,STONE:1)
Block(-3,4,1,STONE:1)
Block(-3,4,2,STONE:1)
Block(-3,4,3,STONE:1)
Block(-3,4,4,STONE:1)
Block(-3,5,-5,LEAVES:7)
Block(-3,5,-4,STONE:1)
Block(-3,5,-3,STONE:1)
Block(-3,5,-2,STONE:1)
Block(-3,5,-1,STONE:1)
Block(-3,5,0,STONE:1)
Block(-3,5,1,STONE:1)
Block(-3,5,2,STONE:1)
Block(-3,5,3,STONE:1)
Block(-3,5,4,LEAVES:7)
Block(-3,6,-4,LEAVES:7)
Block(-3,6,-3,STONE:1)
Block(-3,6,-2,STONE:1)
Block(-3,6,-1,STONE:1)
Block(-3,6,0,STONE:1)
Block(-3,6,1,STONE:1)
Block(-3,6,2,STONE:1)
Block(-3,6,3,STONE:1)
Block(-3,7,-3,STONE:1)
Block(-3,7,-2,STONE:1)
Block(-3,7,-1,STONE:1)
Block(-3,7,0,STONE:1)
Block(-3,7,1,STONE:1)
Block(-3,7,2,STONE:1)
Block(-3,8,-2,STONE:1)
Block(-3,8,-1,STONE:1)
Block(-3,8,0,STONE:1)
Block(-3,8,1,STONE:1)
Block(-3,8,2,STONE:1)
Block(-3,9,-2,LEAVES:7)
Block(-3,9,-1,LEAVES:7)
Block(-3,9,0,STONE:1)
Block(-2,-9,-2,STONE:1)
Block(-2,-9,2,STONE:1)
Block(-2,-8,-2,STONE:1)
Block(-2,-8,-1,STONE:1)
Block(-2,-8,0,STONE:1)
Block(-2,-8,1,STONE:1)
Block(-2,-8,2,STONE:1)
Block(-2,-8,3,STONE:1)
Block(-2,-7,-5,STONE:1)
Block(-2,-7,-4,STONE:1)
Block(-2,-7,-3,STONE:1)
Block(-2,-7,-2,STONE:1)
Block(-2,-7,-1,STONE:1)
Block(-2,-7,0,STONE:1)
Block(-2,-7,1,STONE:1)
Block(-2,-7,2,STONE:1)
Block(-2,-7,3,STONE:1)
Block(-2,-7,4,STAINED_CLAY:14)
Block(-2,-6,-4,STONE:1)
Block(-2,-6,-3,STONE:1)
Block(-2,-6,-2,STONE:1)
Block(-2,-6,-1,STONE:1)
Block(-2,-6,0,STONE:1)
Block(-2,-6,1,STONE:1)
Block(-2,-6,2,STONE:1)
Block(-2,-6,3,STONE:1)
Block(-2,-6,4,STONE:1)
Block(-2,-6,5,STAINED_CLAY:14)
Block(-2,-5,-5,STONE:1)
Block(-2,-5,-4,STONE:1)
Block(-2,-5,-3,STONE:1)
Block(-2,-5,-2,STONE:1)
Block(-2,-5,-1,STONE:1)
Block(-2,-5,0,STONE:1)
Block(-2,-5,1,STONE:1)
Block(-2,-5,2,STONE:1)
Block(-2,-5,3,STONE:1)
Block(-2,-5,4,STAINED_CLAY:14)
Block(-2,-5,5,STAINED_CLAY:14)
Block(-2,-4,-6,STONE:1)
Block(-2,-4,-5,STONE:1)
Block(-2,-4,-4,STONE:1)
Block(-2,-4,-3,STONE:1)
Block(-2,-4,-2,STONE:1)
Block(-2,-4,-1,STONE:1)
Block(-2,-4,0,STONE:1)
Block(-2,-4,1,STONE:1)
Block(-2,-4,2,STONE:1)
Block(-2,-4,3,STONE:1)
Block(-2,-4,4,STONE:1)
Block(-2,-4,5,STAINED_CLAY:14)
Block(-2,-3,-6,STONE:1)
Block(-2,-3,-5,STONE:1)
Block(-2,-3,-4,STONE:1)
Block(-2,-3,-3,STONE:1)
Block(-2,-3,-2,STONE:1)
Block(-2,-3,-1,STONE:1)
Block(-2,-3,0,STONE:1)
Block(-2,-3,1,STONE:1)
Block(-2,-3,2,STONE:1)
Block(-2,-3,3,STONE:1)
Block(-2,-3,4,STONE:1)
Block(-2,-3,5,STONE:1)
Block(-2,-2,-6,STONE:1)
Block(-2,-2,-5,STONE:1)
Block(-2,-2,-4,STONE:1)
Block(-2,-2,-3,STONE:1)
Block(-2,-2,-2,STONE:1)
Block(-2,-2,-1,STONE:1)
Block(-2,-2,0,STONE:1)
Block(-2,-2,1,STONE:1)
Block(-2,-2,2,STONE:1)
Block(-2,-2,3,STONE:1)
Block(-2,-2,4,STONE:1)
Block(-2,-2,5,STONE:1)
Block(-2,-1,-6,STONE:1)
Block(-2,-1,-5,STONE:1)
Block(-2,-1,-4,STONE:1)
Block(-2,-1,-3,STONE:1)
Block(-2,-1,-2,STONE:1)
Block(-2,-1,-1,STONE:1)
Block(-2,-1,0,STONE:1)
Block(-2,-1,1,STONE:1)
Block(-2,-1,2,STONE:1)
Block(-2,-1,3,STONE:1)
Block(-2,-1,4,STONE:1)
Block(-2,-1,5,STONE:1)
Block(-2,0,-6,STONE:1)
Block(-2,0,-5,STONE:1)
Block(-2,0,-4,STONE:1)
Block(-2,0,-3,STONE:1)
Block(-2,0,-2,STONE:1)
Block(-2,0,-1,STONE:1)
Block(-2,0,0,STONE:1)
Block(-2,0,1,STONE:1)
Block(-2,0,2,STONE:1)
Block(-2,0,3,STONE:1)
Block(-2,0,4,STONE:1)
Block(-2,0,5,STONE:1)
Block(-2,1,-6,STONE:1)
Block(-2,1,-5,STONE:1)
Block(-2,1,-4,STONE:1)
Block(-2,1,-3,STONE:1)
Block(-2,1,-2,STONE:1)
Block(-2,1,-1,STONE:1)
Block(-2,1,0,STONE:1)
Block(-2,1,1,STONE:1)
Block(-2,1,2,STONE:1)
Block(-2,1,3,STONE:1)
Block(-2,1,4,STONE:1)
Block(-2,1,5,STONE:1)
Block(-2,2,-6,STAINED_CLAY:14)
Block(-2,2,-5,STONE:1)
Block(-2,2,-4,STONE:1)
Block(-2,2,-3,STONE:1)
Block(-2,2,-2,STONE:1)
Block(-2,2,-1,STONE:1)
Block(-2,2,0,STONE:1)
Block(-2,2,1,STONE:1)
Block(-2,2,2,STONE:1)
Block(-2,2,3,STONE:1)
Block(-2,2,4,STONE:1)
Block(-2,2,5,STAINED_CLAY:14)
Block(-2,3,-6,LEAVES:7)
Block(-2,3,-5,STONE:1)
Block(-2,3,-4,STONE:1)
Block(-2,3,-3,STONE:1)
Block(-2,3,-2,STONE:1)
Block(-2,3,-1,STONE:1)
Block(-2,3,0,STONE:1)
Block(-2,3,1,STONE:1)
Block(-2,3,2,STONE:1)
Block(-2,3,3,STONE:1)
Block(-2,3,4,STAINED_CLAY:14)
Block(-2,3,5,STAINED_CLAY:14)
Block(-2,4,-6,LEAVES:7)
Block(-2,4,-5,STONE:1)
Block(-2,4,-4,STONE:1)
Block(-2,4,-3,STONE:1)
Block(-2,4,-2,STONE:1)
Block(-2,4,-1,STONE:1)
Block(-2,4,0,STONE:1)
Block(-2,4,1,STONE:1)
Block(-2,4,2,STONE:1)
Block(-2,4,3,STONE:1)
Block(-2,4,4,STONE:1)
Block(-2,4,5,STAINED_CLAY:14)
Block(-2,5,-6,LEAVES:7)
Block(-2,5,-5,STONE:1)
Block(-2,5,-4,STONE:1)
Block(-2,5,-3,STONE:1)
Block(-2,5,-2,STONE:1)
Block(-2,5,-1,STONE:1)
Block(-2,5,0,STONE:1)
Block(-2,5,1,STONE:1)
Block(-2,5,2,STONE:1)
Block(-2,5,3,STONE:1)
Block(-2,5,4,STONE:1)
Block(-2,6,-5,STONE:1)
Block(-2,6,-4,STONE:1)
Block(-2,6,-3,STONE:1)
Block(-2,6,-2,STONE:1)
Block(-2,6,-1,STONE:1)
Block(-2,6,0,STONE:1)
Block(-2,6,1,STONE:1)
Block(-2,6,2,STONE:1)
Block(-2,6,3,STONE:1)
Block(-2,6,4,LEAVES:7)
Block(-2,7,-5,LEAVES:7)
Block(-2,7,-4,STONE:1)
Block(-2,7,-3,STONE:1)
Block(-2,7,-2,STONE:1)
Block(-2,7,-1,STONE:1)
Block(-2,7,0,STONE:1)
Block(-2,7,1,STONE:1)
Block(-2,7,2,STONE:1)
Block(-2,7,3,STONE:1)
Block(-2,8,-3,STONE:1)
Block(-2,8,-2,STONE:1)
Block(-2,8,-1,STONE:1)
Block(-2,8,0,STONE:1)
Block(-2,8,1,STONE:1)
Block(-2,8,2,STONE:1)
Block(-2,9,-3,LEAVES:7)
Block(-2,9,-2,STONE:1)
Block(-2,9,-1,STONE:1)
Block(-2,9,0,STONE:1)
Block(-2,9,1,STONE:1)
Block(-1,-9,-2,STONE:1)
Block(-1,-9,2,STONE:1)
Block(-1,-8,-5,STONE:1)
Block(-1,-8,-3,STONE:1)
Block(-1,-8,-2,STONE:1)
Block(-1,-8,-1,STONE:1)
Block(-1,-8,0,STONE:1)
Block(-1,-8,1,STONE:1)
Block(-1,-8,2,STONE:1)
Block(-1,-7,-6,STONE:1)
Block(-1,-7,-5,STONE:1)
Block(-1,-7,-4,STONE:1)
Block(-1,-7,-3,STONE:1)
Block(-1,-7,-2,STONE:1)
Block(-1,-7,-1,STONE:1)
Block(-1,-7,0,STONE:1)
Block(-1,-7,1,STONE:1)
Block(-1,-7,2,STONE:1)
Block(-1,-7,3,STONE:1)
Block(-1,-7,4,STONE:1)
Block(-1,-6,-6,STONE:1)
Block(-1,-6,-5,STONE:1)
Block(-1,-6,-4,STONE:1)
Block(-1,-6,-3,STONE:1)
Block(-1,-6,-2,STONE:1)
Block(-1,-6,-1,STONE:1)
Block(-1,-6,0,STONE:1)
Block(-1,-6,1,STONE:1)
Block(-1,-6,2,STONE:1)
Block(-1,-6,3,STONE:1)
Block(-1,-6,4,STONE:1)
Block(-1,-5,-6,STONE:1)
Block(-1,-5,-5,STONE:1)
Block(-1,-5,-4,STONE:1)
Block(-1,-5,-3,STONE:1)
Block(-1,-5,-2,STONE:1)
Block(-1,-5,-1,STONE:1)
Block(-1,-5,0,STONE:1)
Block(-1,-5,1,STONE:1)
Block(-1,-5,2,STONE:1)
Block(-1,-5,3,STONE:1)
Block(-1,-5,4,STONE:1)
Block(-1,-5,5,STAINED_CLAY:14)
Block(-1,-4,-6,STONE:1)
Block(-1,-4,-5,STONE:1)
Block(-1,-4,-4,STONE:1)
Block(-1,-4,-3,STONE:1)
Block(-1,-4,-2,STONE:1)
Block(-1,-4,-1,STONE:1)
Block(-1,-4,0,STONE:1)
Block(-1,-4,1,STONE:1)
Block(-1,-4,2,STONE:1)
Block(-1,-4,3,STONE:1)
Block(-1,-4,4,STAINED_CLAY:14)
Block(-1,-4,5,STONE:1)
Block(-1,-3,-6,STONE:1)
Block(-1,-3,-5,STONE:1)
Block(-1,-3,-4,STONE:1)
Block(-1,-3,-3,STONE:1)
Block(-1,-3,-2,STONE:1)
Block(-1,-3,-1,STONE:1)
Block(-1,-3,0,STONE:1)
Block(-1,-3,1,STONE:1)
Block(-1,-3,2,STONE:1)
Block(-1,-3,3,STONE:1)
Block(-1,-3,4,STONE:1)
Block(-1,-3,5,STONE:1)
Block(-1,-2,-6,STONE:1)
Block(-1,-2,-5,STONE:1)
Block(-1,-2,-4,STONE:1)
Block(-1,-2,-3,STONE:1)
Block(-1,-2,-2,STONE:1)
Block(-1,-2,-1,STONE:1)
Block(-1,-2,0,STONE:1)
Block(-1,-2,1,STONE:1)
Block(-1,-2,2,STONE:1)
Block(-1,-2,3,STONE:1)
Block(-1,-2,4,STONE:1)
Block(-1,-2,5,STONE:1)
Block(-1,-1,-6,STONE:1)
Block(-1,-1,-5,STONE:1)
Block(-1,-1,-4,STONE:1)
Block(-1,-1,-3,STONE:1)
Block(-1,-1,-2,STONE:1)
Block(-1,-1,-1,STONE:1)
Block(-1,-1,0,STONE:1)
Block(-1,-1,1,STONE:1)
Block(-1,-1,2,STONE:1)
Block(-1,-1,3,STONE:1)
Block(-1,-1,4,STONE:1)
Block(-1,-1,5,STAINED_CLAY:14)
Block(-1,0,-6,STONE:1)
Block(-1,0,-5,STONE:1)
Block(-1,0,-4,STONE:1)
Block(-1,0,-3,STONE:1)
Block(-1,0,-2,STONE:1)
Block(-1,0,-1,STONE:1)
Block(-1,0,0,STONE:1)
Block(-1,0,1,STONE:1)
Block(-1,0,2,STONE:1)
Block(-1,0,3,STONE:1)
Block(-1,0,4,STONE:1)
Block(-1,0,5,STAINED_CLAY:14)
Block(-1,1,-6,STONE:1)
Block(-1,1,-5,STONE:1)
Block(-1,1,-4,STONE:1)
Block(-1,1,-3,STONE:1)
Block(-1,1,-2,STONE:1)
Block(-1,1,-1,STONE:1)
Block(-1,1,0,STONE:1)
Block(-1,1,1,STONE:1)
Block(-1,1,2,STONE:1)
Block(-1,1,3,STONE:1)
Block(-1,1,4,STONE:1)
Block(-1,2,-6,STAINED_CLAY:14)
Block(-1,2,-5,STONE:1)
Block(-1,2,-4,STONE:1)
Block(-1,2,-3,STONE:1)
Block(-1,2,-2,STONE:1)
Block(-1,2,-1,STONE:1)
Block(-1,2,0,STONE:1)
Block(-1,2,1,STONE:1)
Block(-1,2,2,STONE:1)
Block(-1,2,3,STONE:1)
Block(-1,2,4,STONE:1)
Block(-1,3,-6,STAINED_CLAY:14)
Block(-1,3,-5,STONE:1)
Block(-1,3,-4,STONE:1)
Block(-1,3,-3,STONE:1)
Block(-1,3,-2,STONE:1)
Block(-1,3,-1,STONE:1)
Block(-1,3,0,STONE:1)
Block(-1,3,1,STONE:1)
Block(-1,3,2,STONE:1)
Block(-1,3,3,STONE:1)
Block(-1,3,4,STONE:1)
Block(-1,4,-6,STONE:1)
Block(-1,4,-5,STONE:1)
Block(-1,4,-4,STONE:1)
Block(-1,4,-3,STONE:1)
Block(-1,4,-2,STONE:1)
Block(-1,4,-1,STONE:1)
Block(-1,4,0,STONE:1)
Block(-1,4,1,STONE:1)
Block(-1,4,2,STONE:1)
Block(-1,4,3,STONE:1)
Block(-1,4,4,STONE:1)
Block(-1,5,-6,STONE:1)
Block(-1,5,-5,STONE:1)
Block(-1,5,-4,STONE:1)
Block(-1,5,-3,STONE:1)
Block(-1,5,-2,STONE:1)
Block(-1,5,-1,STONE:1)
Block(-1,5,0,STONE:1)
Block(-1,5,1,STONE:1)
Block(-1,5,2,STONE:1)
Block(-1,5,3,STONE:1)
Block(-1,5,4,STONE:1)
Block(-1,6,-6,LEAVES:7)
Block(-1,6,-5,STONE:1)
Block(-1,6,-4,STONE:1)
Block(-1,6,-3,STONE:1)
Block(-1,6,-2,STONE:1)
Block(-1,6,-1,STONE:1)
Block(-1,6,0,STONE:1)
Block(-1,6,1,STONE:1)
Block(-1,6,2,STONE:1)
Block(-1,6,3,STONE:1)
Block(-1,6,4,STONE:1)
Block(-1,7,-5,STONE:1)
Block(-1,7,-4,STONE:1)
Block(-1,7,-3,STONE:1)
Block(-1,7,-2,STONE:1)
Block(-1,7,-1,STONE:1)
Block(-1,7,0,STONE:1)
Block(-1,7,1,STONE:1)
Block(-1,7,2,STONE:1)
Block(-1,7,3,STONE:1)
Block(-1,7,4,LEAVES:7)
Block(-1,8,-5,LEAVES:7)
Block(-1,8,-4,STONE:1)
Block(-1,8,-3,STONE:1)
Block(-1,8,-2,STONE:1)
Block(-1,8,-1,STONE:1)
Block(-1,8,0,STONE:1)
Block(-1,8,1,STONE:1)
Block(-1,8,2,STONE:1)
Block(-1,8,3,LEAVES:7)
Block(-1,9,-4,LEAVES:7)
Block(-1,9,-3,LEAVES:7)
Block(-1,9,-2,STONE:1)
Block(-1,9,-1,STONE:1)
Block(-1,9,0,STONE:1)
Block(-1,9,1,STONE:1)
Block(-1,9,2,STONE:1)
Block(-1,10,-1,STONE:1)
Block(-1,10,0,STONE:1)
Block(-1,10,1,STONE:1)
Block(-1,11,0,STONE:1)
Block(0,-9,-2,STONE:1)
Block(0,-9,2,STONE:1)
Block(0,-8,-4,STONE:1)
Block(0,-8,-3,STONE:1)
Block(0,-8,-2,STONE:1)
Block(0,-8,-1,STONE:1)
Block(0,-8,0,STONE:1)
Block(0,-8,1,STONE:1)
Block(0,-8,2,STONE:1)
Block(0,-8,3,STONE:1)
Block(0,-7,-7,STONE:1)
Block(0,-7,-6,STONE:1)
Block(0,-7,-5,STONE:1)
Block(0,-7,-4,STONE:1)
Block(0,-7,-3,STONE:1)
Block(0,-7,-2,STONE:1)
Block(0,-7,-1,STONE:1)
Block(0,-7,0,STONE:1)
Block(0,-7,1,STONE:1)
Block(0,-7,2,STONE:1)
Block(0,-6,-7,STAINED_CLAY:14)
Block(0,-6,-6,STONE:1)
Block(0,-6,-5,STONE:1)
Block(0,-6,-4,STONE:1)
Block(0,-6,-3,STONE:1)
Block(0,-6,-2,STONE:1)
Block(0,-6,-1,STONE:1)
Block(0,-6,0,STONE:1)
Block(0,-6,1,STONE:1)
Block(0,-6,2,STONE:1)
Block(0,-6,3,STONE:1)
Block(0,-5,-7,STAINED_CLAY:14)
Block(0,-5,-6,STAINED_CLAY:14)
Block(0,-5,-5,STONE:1)
Block(0,-5,-4,STONE:1)
Block(0,-5,-3,STONE:1)
Block(0,-5,-2,STONE:1)
Block(0,-5,-1,STONE:1)
Block(0,-5,0,STONE:1)
Block(0,-5,1,STONE:1)
Block(0,-5,2,STONE:1)
Block(0,-5,3,STONE:1)
Block(0,-5,4,STAINED_CLAY:14)
Block(0,-4,-7,STAINED_CLAY:14)
Block(0,-4,-6,STONE:1)
Block(0,-4,-5,STONE:1)
Block(0,-4,-4,STONE:1)
Block(0,-4,-3,STONE:1)
Block(0,-4,-2,STONE:1)
Block(0,-4,-1,STONE:1)
Block(0,-4,0,STONE:1)
Block(0,-4,1,STONE:1)
Block(0,-4,2,STONE:1)
Block(0,-4,3,STAINED_CLAY:14)
Block(0,-4,4,STAINED_CLAY:14)
Block(0,-3,-7,STONE:1)
Block(0,-3,-6,STONE:1)
Block(0,-3,-5,STONE:1)
Block(0,-3,-4,STONE:1)
Block(0,-3,-3,STONE:1)
Block(0,-3,-2,STONE:1)
Block(0,-3,-1,STONE:1)
Block(0,-3,0,STONE:1)
Block(0,-3,1,STONE:1)
Block(0,-3,2,STONE:1)
Block(0,-3,3,STONE:1)
Block(0,-3,4,STAINED_CLAY:14)
Block(0,-3,5,STONE:1)
Block(0,-2,-7,STAINED_CLAY:14)
Block(0,-2,-6,STONE:1)
Block(0,-2,-5,STONE:1)
Block(0,-2,-4,STONE:1)
Block(0,-2,-3,STONE:1)
Block(0,-2,-2,STONE:1)
Block(0,-2,-1,STONE:1)
Block(0,-2,0,STONE:1)
Block(0,-2,1,STONE:1)
Block(0,-2,2,STONE:1)
Block(0,-2,3,STONE:1)
Block(0,-2,4,STONE:1)
Block(0,-2,5,STAINED_CLAY:14)
Block(0,-1,-7,STONE:1)
Block(0,-1,-6,STONE:1)
Block(0,-1,-5,STONE:1)
Block(0,-1,-4,STONE:1)
Block(0,-1,-3,STONE:1)
Block(0,-1,-2,STONE:1)
Block(0,-1,-1,STONE:1)
Block(0,-1,0,STONE:1)
Block(0,-1,1,STONE:1)
Block(0,-1,2,STONE:1)
Block(0,-1,3,STONE:1)
Block(0,-1,4,STAINED_CLAY:14)
Block(0,-1,5,STAINED_CLAY:14)
Block(0,0,-7,STAINED_CLAY:14)
Block(0,0,-6,STONE:1)
Block(0,0,-5,STONE:1)
Block(0,0,-4,STONE:1)
Block(0,0,-3,STONE:1)
Block(0,0,-2,STONE:1)
Block(0,0,-1,STONE:1)
Block(0,0,0,STONE:1)
Block(0,0,1,STONE:1)
Block(0,0,2,STONE:1)
Block(0,0,3,STONE:1)
Block(0,0,4,STAINED_CLAY:14)
Block(0,0,5,STAINED_CLAY:14)
Block(0,1,-7,STONE:1)
Block(0,1,-6,STONE:1)
Block(0,1,-5,STONE:1)
Block(0,1,-4,STONE:1)
Block(0,1,-3,STONE:1)
Block(0,1,-2,STONE:1)
Block(0,1,-1,STONE:1)
Block(0,1,0,STONE:1)
Block(0,1,1,STONE:1)
Block(0,1,2,STONE:1)
Block(0,1,3,STONE:1)
Block(0,1,4,STAINED_CLAY:14)
Block(0,1,5,STAINED_CLAY:14)
Block(0,2,-7,STONE:1)
Block(0,2,-6,STONE:1)
Block(0,2,-5,STONE:1)
Block(0,2,-4,STONE:1)
Block(0,2,-3,STONE:1)
Block(0,2,-2,STONE:1)
Block(0,2,-1,STONE:1)
Block(0,2,0,STONE:1)
Block(0,2,1,STONE:1)
Block(0,2,2,STONE:1)
Block(0,2,3,STONE:1)
Block(0,2,4,STONE:1)
Block(0,2,5,STONE:1)
Block(0,3,-7,STAINED_CLAY:14)
Block(0,3,-6,STAINED_CLAY:14)
Block(0,3,-5,STONE:1)
Block(0,3,-4,STONE:1)
Block(0,3,-3,STONE:1)
Block(0,3,-2,STONE:1)
Block(0,3,-1,STONE:1)
Block(0,3,0,STONE:1)
Block(0,3,1,STONE:1)
Block(0,3,2,STONE:1)
Block(0,3,3,STONE:1)
Block(0,3,4,STONE:1)
Block(0,3,5,STONE:1)
Block(0,4,-7,STONE:1)
Block(0,4,-6,STAINED_CLAY:14)
Block(0,4,-5,STONE:1)
Block(0,4,-4,STONE:1)
Block(0,4,-3,STONE:1)
Block(0,4,-2,STONE:1)
Block(0,4,-1,STONE:1)
Block(0,4,0,STONE:1)
Block(0,4,1,STONE:1)
Block(0,4,2,STONE:1)
Block(0,4,3,STONE:1)
Block(0,4,4,STONE:1)
Block(0,5,-7,LEAVES:7)
Block(0,5,-6,STONE:1)
Block(0,5,-5,STONE:1)
Block(0,5,-4,STONE:1)
Block(0,5,-3,STONE:1)
Block(0,5,-2,STONE:1)
Block(0,5,-1,STONE:1)
Block(0,5,0,STONE:1)
Block(0,5,1,STONE:1)
Block(0,5,2,STONE:1)
Block(0,5,3,STONE:1)
Block(0,5,4,STONE:1)
Block(0,6,-6,STONE:1)
Block(0,6,-5,STONE:1)
Block(0,6,-4,STONE:1)
Block(0,6,-3,STONE:1)
Block(0,6,-2,STONE:1)
Block(0,6,-1,STONE:1)
Block(0,6,0,STONE:1)
Block(0,6,1,STONE:1)
Block(0,6,2,STONE:1)
Block(0,6,3,STONE:1)
Block(0,6,4,LEAVES:7)
Block(0,7,-6,STONE:1)
Block(0,7,-5,STONE:1)
Block(0,7,-4,STONE:1)
Block(0,7,-3,STONE:1)
Block(0,7,-2,STONE:1)
Block(0,7,-1,STONE:1)
Block(0,7,0,STONE:1)
Block(0,7,1,STONE:1)
Block(0,7,2,STONE:1)
Block(0,7,3,STONE:1)
Block(0,8,-6,LEAVES:7)
Block(0,8,-5,STONE:1)
Block(0,8,-4,STONE:1)
Block(0,8,-3,STONE:1)
Block(0,8,-2,STONE:1)
Block(0,8,-1,STONE:1)
Block(0,8,0,STONE:1)
Block(0,8,1,STONE:1)
Block(0,8,2,STONE:1)
Block(0,8,3,LEAVES:7)
Block(0,9,-4,STONE:1)
Block(0,9,-3,STONE:1)
Block(0,9,-2,STONE:1)
Block(0,9,-1,STONE:1)
Block(0,9,0,STONE:1)
Block(0,9,1,STONE:1)
Block(0,10,-2,STONE:1)
Block(0,10,-1,STONE:1)
Block(0,10,0,STONE:1)
Block(0,10,1,STONE:1)
Block(1,-9,-2,STONE:1)
Block(1,-9,-1,STONE:1)
Block(1,-9,0,STONE:1)
Block(1,-9,1,STONE:1)
Block(1,-9,2,STONE:1)
Block(1,-8,-7,STAINED_CLAY:14)
Block(1,-8,-5,STONE:1)
Block(1,-8,-4,STONE:1)
Block(1,-8,-3,STONE:1)
Block(1,-8,-2,STONE:1)
Block(1,-8,-1,STONE:1)
Block(1,-8,0,STONE:1)
Block(1,-8,1,STONE:1)
Block(1,-8,2,STONE:1)
Block(1,-7,-6,STONE:1)
Block(1,-7,-5,STONE:1)
Block(1,-7,-4,STONE:1)
Block(1,-7,-3,STONE:1)
Block(1,-7,-2,STONE:1)
Block(1,-7,-1,STONE:1)
Block(1,-7,0,STONE:1)
Block(1,-7,1,STONE:1)
Block(1,-7,2,STAINED_CLAY:14)
Block(1,-6,-7,STONE:1)
Block(1,-6,-6,STONE:1)
Block(1,-6,-5,STONE:1)
Block(1,-6,-4,STONE:1)
Block(1,-6,-3,STONE:1)
Block(1,-6,-2,STONE:1)
Block(1,-6,-1,STONE:1)
Block(1,-6,0,STONE:1)
Block(1,-6,1,STONE:1)
Block(1,-6,2,STONE:1)
Block(1,-5,-7,STAINED_CLAY:14)
Block(1,-5,-6,STONE:1)
Block(1,-5,-5,STONE:1)
Block(1,-5,-4,STONE:1)
Block(1,-5,-3,STONE:1)
Block(1,-5,-2,STONE:1)
Block(1,-5,-1,STONE:1)
Block(1,-5,0,STONE:1)
Block(1,-5,1,STONE:1)
Block(1,-5,2,STONE:1)
Block(1,-5,3,STONE:1)
Block(1,-5,4,STONE:1)
Block(1,-4,-7,STONE:1)
Block(1,-4,-6,STONE:1)
Block(1,-4,-5,STONE:1)
Block(1,-4,-4,STONE:1)
Block(1,-4,-3,STONE:1)
Block(1,-4,-2,STONE:1)
Block(1,-4,-1,STONE:1)
Block(1,-4,0,STONE:1)
Block(1,-4,1,STONE:1)
Block(1,-4,2,STONE:1)
Block(1,-4,3,STONE:1)
Block(1,-4,4,STAINED_CLAY:14)
Block(1,-3,-7,STAINED_CLAY:14)
Block(1,-3,-6,STONE:1)
Block(1,-3,-5,STONE:1)
Block(1,-3,-4,STONE:1)
Block(1,-3,-3,STONE:1)
Block(1,-3,-2,STONE:1)
Block(1,-3,-1,STONE:1)
Block(1,-3,0,STONE:1)
Block(1,-3,1,STONE:1)
Block(1,-3,2,STONE:1)
Block(1,-3,3,STONE:1)
Block(1,-3,4,STONE:1)
Block(1,-2,-7,STAINED_CLAY:14)
Block(1,-2,-6,STAINED_CLAY:14)
Block(1,-2,-5,STONE:1)
Block(1,-2,-4,STONE:1)
Block(1,-2,-3,STONE:1)
Block(1,-2,-2,STONE:1)
Block(1,-2,-1,STONE:1)
Block(1,-2,0,STONE:1)
Block(1,-2,1,STONE:1)
Block(1,-2,2,STAINED_CLAY:14)
Block(1,-2,3,STONE:1)
Block(1,-2,4,STONE:1)
Block(1,-1,-7,STONE:1)
Block(1,-1,-6,STONE:1)
Block(1,-1,-5,STONE:1)
Block(1,-1,-4,STONE:1)
Block(1,-1,-3,STONE:1)
Block(1,-1,-2,STONE:1)
Block(1,-1,-1,STONE:1)
Block(1,-1,0,STONE:1)
Block(1,-1,1,STONE:1)
Block(1,-1,2,STONE:1)
Block(1,-1,3,STONE:1)
Block(1,-1,4,STONE:1)
Block(1,0,-7,STONE:1)
Block(1,0,-6,STONE:1)
Block(1,0,-5,STONE:1)
Block(1,0,-4,STONE:1)
Block(1,0,-3,STONE:1)
Block(1,0,-2,STONE:1)
Block(1,0,-1,STONE:1)
Block(1,0,0,STONE:1)
Block(1,0,1,STONE:1)
Block(1,0,2,STONE:1)
Block(1,0,3,STAINED_CLAY:14)
Block(1,0,4,STAINED_CLAY:14)
Block(1,1,-7,STAINED_CLAY:14)
Block(1,1,-6,STONE:1)
Block(1,1,-5,STONE:1)
Block(1,1,-4,STONE:1)
Block(1,1,-3,STONE:1)
Block(1,1,-2,STONE:1)
Block(1,1,-1,STONE:1)
Block(1,1,0,STONE:1)
Block(1,1,1,STONE:1)
Block(1,1,2,STONE:1)
Block(1,1,3,STAINED_CLAY:14)
Block(1,1,4,STAINED_CLAY:14)
Block(1,2,-7,STAINED_CLAY:14)
Block(1,2,-6,STONE:1)
Block(1,2,-5,STONE:1)
Block(1,2,-4,STONE:1)
Block(1,2,-3,STONE:1)
Block(1,2,-2,STONE:1)
Block(1,2,-1,STONE:1)
Block(1,2,0,STONE:1)
Block(1,2,1,STONE:1)
Block(1,2,2,STONE:1)
Block(1,2,3,STONE:1)
Block(1,2,4,STAINED_CLAY:14)
Block(1,3,-7,STAINED_CLAY:14)
Block(1,3,-6,STAINED_CLAY:14)
Block(1,3,-5,STONE:1)
Block(1,3,-4,STONE:1)
Block(1,3,-3,STONE:1)
Block(1,3,-2,STONE:1)
Block(1,3,-1,STONE:1)
Block(1,3,0,STONE:1)
Block(1,3,1,STONE:1)
Block(1,3,2,STONE:1)
Block(1,3,3,STONE:1)
Block(1,3,4,STONE:1)
Block(1,4,-7,STAINED_CLAY:14)
Block(1,4,-6,STONE:1)
Block(1,4,-5,STONE:1)
Block(1,4,-4,STONE:1)
Block(1,4,-3,STONE:1)
Block(1,4,-2,STONE:1)
Block(1,4,-1,STONE:1)
Block(1,4,0,STONE:1)
Block(1,4,1,STONE:1)
Block(1,4,2,STONE:1)
Block(1,4,3,STONE:1)
Block(1,4,4,LEAVES:7)
Block(1,5,-7,STONE:1)
Block(1,5,-6,STONE:1)
Block(1,5,-5,STONE:1)
Block(1,5,-4,STONE:1)
Block(1,5,-3,STONE:1)
Block(1,5,-2,STONE:1)
Block(1,5,-1,STONE:1)
Block(1,5,0,STONE:1)
Block(1,5,1,STONE:1)
Block(1,5,2,STONE:1)
Block(1,5,3,STONE:1)
Block(1,5,4,LEAVES:7)
Block(1,6,-7,LEAVES:7)
Block(1,6,-6,STONE:1)
Block(1,6,-5,STONE:1)
Block(1,6,-4,STONE:1)
Block(1,6,-3,STONE:1)
Block(1,6,-2,STONE:1)
Block(1,6,-1,STONE:1)
Block(1,6,0,STONE:1)
Block(1,6,1,STONE:1)
Block(1,6,2,STONE:1)
Block(1,6,3,STONE:1)
Block(1,7,-6,STONE:1)
Block(1,7,-5,STONE:1)
Block(1,7,-4,STONE:1)
Block(1,7,-3,STONE:1)
Block(1,7,-2,STONE:1)
Block(1,7,-1,STONE:1)
Block(1,7,0,STONE:1)
Block(1,7,1,STONE:1)
Block(1,7,2,STONE:1)
Block(1,8,-6,LEAVES:7)
Block(1,8,-5,STONE:1)
Block(1,8,-4,STONE:1)
Block(1,8,-3,STONE:1)
Block(1,8,-2,STONE:1)
Block(1,8,-1,STONE:1)
Block(1,8,0,STONE:1)
Block(1,8,1,STONE:1)
Block(1,8,2,LEAVES:7)
Block(1,9,-4,STONE:1)
Block(1,9,-3,STONE:1)
Block(1,9,-2,STONE:1)
Block(1,9,-1,STONE:1)
Block(1,9,0,STONE:1)
Block(1,9,1,STONE:1)
Block(1,10,-2,STONE:1)
Block(1,10,0,STONE:1)
Block(2,-9,-5,STONE:1)
Block(2,-9,-4,STONE:1)
Block(2,-9,-3,STONE:1)
Block(2,-9,-2,STONE:1)
Block(2,-9,0,STONE:1)
Block(2,-8,-6,STONE:1)
Block(2,-8,-5,STONE:1)
Block(2,-8,-4,STONE:1)
Block(2,-8,-3,STONE:1)
Block(2,-8,-2,STONE:1)
Block(2,-8,-1,STONE:1)
Block(2,-8,0,STONE:1)
Block(2,-8,1,STONE:1)
Block(2,-8,2,STAINED_CLAY:14)
Block(2,-7,-6,STONE:1)
Block(2,-7,-5,STONE:1)
Block(2,-7,-4,STONE:1)
Block(2,-7,-3,STONE:1)
Block(2,-7,-2,STONE:1)
Block(2,-7,-1,STONE:1)
Block(2,-7,0,STONE:1)
Block(2,-7,1,STAINED_CLAY:14)
Block(2,-7,2,STAINED_CLAY:14)
Block(2,-6,-6,STONE:1)
Block(2,-6,-5,STONE:1)
Block(2,-6,-4,STONE:1)
Block(2,-6,-3,STONE:1)
Block(2,-6,-2,STONE:1)
Block(2,-6,-1,STONE:1)
Block(2,-6,0,STONE:1)
Block(2,-6,1,STONE:1)
Block(2,-6,2,STAINED_CLAY:14)
Block(2,-5,-8,STONE:1)
Block(2,-5,-7,STONE:1)
Block(2,-5,-6,STONE:1)
Block(2,-5,-5,STONE:1)
Block(2,-5,-4,STONE:1)
Block(2,-5,-3,STONE:1)
Block(2,-5,-2,STONE:1)
Block(2,-5,-1,STONE:1)
Block(2,-5,0,STONE:1)
Block(2,-5,1,STONE:1)
Block(2,-5,2,STONE:1)
Block(2,-4,-8,STONE:1)
Block(2,-4,-7,STONE:1)
Block(2,-4,-6,STONE:1)
Block(2,-4,-5,STONE:1)
Block(2,-4,-4,STONE:1)
Block(2,-4,-3,STONE:1)
Block(2,-4,-2,STONE:1)
Block(2,-4,-1,STONE:1)
Block(2,-4,0,STONE:1)
Block(2,-4,1,STONE:1)
Block(2,-4,2,STONE:1)
Block(2,-4,3,STONE:1)
Block(2,-3,-8,STONE:1)
Block(2,-3,-7,STONE:1)
Block(2,-3,-6,STONE:1)
Block(2,-3,-5,STONE:1)
Block(2,-3,-4,STONE:1)
Block(2,-3,-3,STONE:1)
Block(2,-3,-2,STONE:1)
Block(2,-3,-1,STONE:1)
Block(2,-3,0,STONE:1)
Block(2,-3,1,STONE:1)
Block(2,-3,2,STAINED_CLAY:14)
Block(2,-3,3,STONE:1)
Block(2,-2,-8,STONE:1)
Block(2,-2,-7,STAINED_CLAY:14)
Block(2,-2,-6,STONE:1)
Block(2,-2,-5,STONE:1)
Block(2,-2,-4,STONE:1)
Block(2,-2,-3,STONE:1)
Block(2,-2,-2,STONE:1)
Block(2,-2,-1,STONE:1)
Block(2,-2,0,STONE:1)
Block(2,-2,1,STAINED_CLAY:14)
Block(2,-2,2,STAINED_CLAY:14)
Block(2,-2,3,STAINED_CLAY:14)
Block(2,-1,-8,STONE:1)
Block(2,-1,-7,STONE:1)
Block(2,-1,-6,STONE:1)
Block(2,-1,-5,STONE:1)
Block(2,-1,-4,STONE:1)
Block(2,-1,-3,STONE:1)
Block(2,-1,-2,STONE:1)
Block(2,-1,-1,STONE:1)
Block(2,-1,0,STONE:1)
Block(2,-1,1,STONE:1)
Block(2,-1,2,STAINED_CLAY:14)
Block(2,-1,3,STAINED_CLAY:14)
Block(2,0,-8,STONE:1)
Block(2,0,-7,STAINED_CLAY:14)
Block(2,0,-6,STONE:1)
Block(2,0,-5,STONE:1)
Block(2,0,-4,STONE:1)
Block(2,0,-3,STONE:1)
Block(2,0,-2,STONE:1)
Block(2,0,-1,STONE:1)
Block(2,0,0,STONE:1)
Block(2,0,1,STONE:1)
Block(2,0,2,STAINED_CLAY:14)
Block(2,0,3,STAINED_CLAY:14)
Block(2,1,-8,STONE:1)
Block(2,1,-7,STONE:1)
Block(2,1,-6,STONE:1)
Block(2,1,-5,STONE:1)
Block(2,1,-4,STONE:1)
Block(2,1,-3,STONE:1)
Block(2,1,-2,STONE:1)
Block(2,1,-1,STONE:1)
Block(2,1,0,STONE:1)
Block(2,1,1,STONE:1)
Block(2,1,2,STAINED_CLAY:14)
Block(2,1,3,STAINED_CLAY:14)
Block(2,2,-8,STONE:1)
Block(2,2,-7,STONE:1)
Block(2,2,-6,STONE:1)
Block(2,2,-5,STONE:1)
Block(2,2,-4,STONE:1)
Block(2,2,-3,STONE:1)
Block(2,2,-2,STONE:1)
Block(2,2,-1,STONE:1)
Block(2,2,0,STONE:1)
Block(2,2,1,STONE:1)
Block(2,2,2,STONE:1)
Block(2,2,3,STONE:1)
Block(2,3,-8,STONE:1)
Block(2,3,-7,STAINED_CLAY:14)
Block(2,3,-6,STONE:1)
Block(2,3,-5,STONE:1)
Block(2,3,-4,STONE:1)
Block(2,3,-3,STONE:1)
Block(2,3,-2,STONE:1)
Block(2,3,-1,STONE:1)
Block(2,3,0,STONE:1)
Block(2,3,1,STONE:1)
Block(2,3,2,STONE:1)
Block(2,3,3,STONE:1)
Block(2,4,-8,STONE:1)
Block(2,4,-7,STONE:1)
Block(2,4,-6,STONE:1)
Block(2,4,-5,STONE:1)
Block(2,4,-4,STONE:1)
Block(2,4,-3,STONE:1)
Block(2,4,-2,STONE:1)
Block(2,4,-1,STONE:1)
Block(2,4,0,STONE:1)
Block(2,4,1,STONE:1)
Block(2,4,2,STONE:1)
Block(2,4,3,STONE:1)
Block(2,5,-8,STONE:1)
Block(2,5,-7,STONE:1)
Block(2,5,-6,STONE:1)
Block(2,5,-5,STONE:1)
Block(2,5,-4,STONE:1)
Block(2,5,-3,STONE:1)
Block(2,5,-2,STONE:1)
Block(2,5,-1,STONE:1)
Block(2,5,0,STONE:1)
Block(2,5,1,STONE:1)
Block(2,5,2,STONE:1)
Block(2,5,3,LEAVES:7)
Block(2,6,-7,STONE:1)
Block(2,6,-6,STONE:1)
Block(2,6,-5,STONE:1)
Block(2,6,-4,STONE:1)
Block(2,6,-3,STONE:1)
Block(2,6,-2,STONE:1)
Block(2,6,-1,STONE:1)
Block(2,6,0,STONE:1)
Block(2,6,1,STONE:1)
Block(2,6,2,STONE:1)
Block(2,7,-7,LEAVES:7)
Block(2,7,-6,STONE:1)
Block(2,7,-5,STONE:1)
Block(2,7,-4,STONE:1)
Block(2,7,-3,STONE:1)
Block(2,7,-2,STONE:1)
Block(2,7,-1,STONE:1)
Block(2,7,0,STONE:1)
Block(2,7,1,STONE:1)
Block(2,8,-6,LEAVES:7)
Block(2,8,-5,STONE:1)
Block(2,8,-4,STONE:1)
Block(2,8,-3,STONE:1)
Block(2,8,-2,STONE:1)
Block(2,8,-1,STONE:1)
Block(2,8,0,STONE:1)
Block(2,8,1,STONE:1)
Block(2,9,-4,STONE:1)
Block(2,9,-3,STONE:1)
Block(2,9,-2,STONE:1)
Block(2,9,-1,LEAVES:7)
Block(2,9,0,LEAVES:7)
Block(2,9,1,LEAVES:7)
Block(3,-8,-5,STONE:1)
Block(3,-8,-4,STONE:1)
Block(3,-8,-3,STONE:1)
Block(3,-8,-2,STONE:1)
Block(3,-8,-1,STONE:1)
Block(3,-8,1,STONE:1)
Block(3,-8,2,STAINED_CLAY:14)
Block(3,-7,-6,STONE:1)
Block(3,-7,-5,STONE:1)
Block(3,-7,-4,STONE:1)
Block(3,-7,-2,STONE:1)
Block(3,-7,-1,STONE:1)
Block(3,-7,0,STONE:1)
Block(3,-7,1,STONE:1)
Block(3,-7,2,STAINED_CLAY:14)
Block(3,-6,-5,STONE:1)
Block(3,-6,-1,STONE:1)
Block(3,-6,0,STONE:1)
Block(3,-6,1,STONE:1)
Block(3,-6,2,STONE:1)
Block(3,-5,-6,STONE:1)
Block(3,-5,-5,STONE:1)
Block(3,-5,-4,STONE:1)
Block(3,-5,-2,STONE:1)
Block(3,-5,-1,STONE:1)
Block(3,-5,0,STONE:1)
Block(3,-5,1,STONE:1)
Block(3,-5,2,STONE:1)
Block(3,-4,-7,STONE:1)
Block(3,-4,-6,STONE:1)
Block(3,-4,-5,STONE:1)
Block(3,-4,-4,STONE:1)
Block(3,-4,-3,STONE:1)
Block(3,-4,-2,STONE:1)
Block(3,-4,-1,STONE:1)
Block(3,-4,0,STONE:1)
Block(3,-4,1,STONE:1)
Block(3,-4,2,STONE:1)
Block(3,-3,-7,STAINED_CLAY:14)
Block(3,-3,-6,STONE:1)
Block(3,-3,-5,STONE:1)
Block(3,-3,-4,STONE:1)
Block(3,-3,-3,STAINED_CLAY:14)
Block(3,-3,-2,STONE:1)
Block(3,-3,-1,STONE:1)
Block(3,-3,0,STONE:1)
Block(3,-3,1,STONE:1)
Block(3,-3,2,STONE:1)
Block(3,-2,-7,STONE:1)
Block(3,-2,-6,STONE:1)
Block(3,-2,-5,STONE:1)
Block(3,-2,-4,STONE:1)
Block(3,-2,-3,STONE:1)
Block(3,-2,-2,STONE:1)
Block(3,-2,-1,STONE:1)
Block(3,-2,0,STONE:1)
Block(3,-2,1,STONE:1)
Block(3,-2,2,STAINED_CLAY:14)
Block(3,-1,-7,STONE:1)
Block(3,-1,-6,STONE:1)
Block(3,-1,-5,STONE:1)
Block(3,-1,-4,STONE:1)
Block(3,-1,-3,STONE:1)
Block(3,-1,-2,STAINED_CLAY:14)
Block(3,-1,-1,STONE:1)
Block(3,-1,0,STONE:1)
Block(3,-1,1,STONE:1)
Block(3,-1,2,STONE:1)
Block(3,0,-8,LEAVES:7)
Block(3,0,-7,STONE:1)
Block(3,0,-6,STAINED_CLAY:14)
Block(3,0,-5,STONE:1)
Block(3,0,-4,STONE:1)
Block(3,0,-3,STONE:1)
Block(3,0,-2,STAINED_CLAY:14)
Block(3,0,-1,STONE:1)
Block(3,0,0,STONE:1)
Block(3,0,1,STONE:1)
Block(3,0,2,STAINED_CLAY:14)
Block(3,1,-8,LEAVES:7)
Block(3,1,-7,STONE:1)
Block(3,1,-6,STONE:1)
Block(3,1,-5,STONE:1)
Block(3,1,-4,STONE:1)
Block(3,1,-3,STONE:1)
Block(3,1,-2,STONE:1)
Block(3,1,-1,STONE:1)
Block(3,1,0,STONE:1)
Block(3,1,1,STAINED_CLAY:14)
Block(3,1,2,STAINED_CLAY:14)
Block(3,2,-8,LEAVES:7)
Block(3,2,-7,STONE:1)
Block(3,2,-6,STONE:1)
Block(3,2,-5,STONE:1)
Block(3,2,-4,STONE:1)
Block(3,2,-3,STONE:1)
Block(3,2,-2,STONE:1)
Block(3,2,-1,STAINED_CLAY:14)
Block(3,2,0,STONE:1)
Block(3,2,1,STONE:1)
Block(3,2,2,STAINED_CLAY:14)
Block(3,3,-7,STONE:1)
Block(3,3,-6,STONE:1)
Block(3,3,-5,STONE:1)
Block(3,3,-4,STONE:1)
Block(3,3,-3,STONE:1)
Block(3,3,-2,STONE:1)
Block(3,3,-1,STAINED_CLAY:14)
Block(3,3,0,STONE:1)
Block(3,3,1,STONE:1)
Block(3,3,2,STONE:1)
Block(3,4,-7,STONE:1)
Block(3,4,-6,STONE:1)
Block(3,4,-5,STONE:1)
Block(3,4,-4,STONE:1)
Block(3,4,-3,STONE:1)
Block(3,4,-2,STONE:1)
Block(3,4,-1,STONE:1)
Block(3,4,0,STONE:1)
Block(3,4,1,STONE:1)
Block(3,4,2,STONE:1)
Block(3,5,-7,STONE:1)
Block(3,5,-6,STONE:1)
Block(3,5,-5,STONE:1)
Block(3,5,-4,STONE:1)
Block(3,5,-3,STONE:1)
Block(3,5,-2,STONE:1)
Block(3,5,-1,STAINED_CLAY:14)
Block(3,5,0,STONE:1)
Block(3,5,1,STONE:1)
Block(3,5,2,LEAVES:7)
Block(3,6,-7,STONE:1)
Block(3,6,-6,STONE:1)
Block(3,6,-5,STONE:1)
Block(3,6,-4,STONE:1)
Block(3,6,-3,STONE:1)
Block(3,6,-2,STONE:1)
Block(3,6,-1,STONE:1)
Block(3,6,0,STONE:1)
Block(3,6,1,STONE:1)
Block(3,7,-6,STONE:1)
Block(3,7,-5,STONE:1)
Block(3,7,-4,STONE:1)
Block(3,7,-3,STONE:1)
Block(3,7,-2,STONE:1)
Block(3,7,-1,STONE:1)
Block(3,7,0,STONE:1)
Block(3,7,1,STONE:1)
Block(3,8,-6,LEAVES:7)
Block(3,8,-5,STONE:1)
Block(3,8,-4,STONE:1)
Block(3,8,-3,STONE:1)
Block(3,8,-2,LEAVES:7)
Block(3,8,-1,LEAVES:7)
Block(3,9,-4,STONE:1)
Block(3,9,-3,LEAVES:7)
Block(4,-7,-5,STONE:1)
Block(4,-6,1,STONE:1)
Block(4,-4,-7,STAINED_CLAY:14)
Block(4,-4,-6,STONE:1)
Block(4,-4,-4,STONE:1)
Block(4,-4,-3,STAINED_CLAY:14)
Block(4,-4,-2,STONE:1)
Block(4,-4,-1,STONE:1)
Block(4,-4,1,STONE:1)
Block(4,-3,-7,STAINED_CLAY:14)
Block(4,-3,-6,STAINED_CLAY:14)
Block(4,-3,-5,STONE:1)
Block(4,-3,-4,STAINED_CLAY:14)
Block(4,-3,-3,STAINED_CLAY:14)
Block(4,-3,-2,STAINED_CLAY:14)
Block(4,-3,-1,STONE:1)
Block(4,-3,0,STONE:1)
Block(4,-3,1,STONE:1)
Block(4,-2,-7,STAINED_CLAY:14)
Block(4,-2,-6,STONE:1)
Block(4,-2,-5,STONE:1)
Block(4,-2,-4,STONE:1)
Block(4,-2,-3,STAINED_CLAY:14)
Block(4,-2,-2,STAINED_CLAY:14)
Block(4,-2,-1,STONE:1)
Block(4,-2,0,STONE:1)
Block(4,-2,1,STONE:1)
Block(4,-1,-7,STONE:1)
Block(4,-1,-6,STAINED_CLAY:14)
Block(4,-1,-5,STONE:1)
Block(4,-1,-4,STONE:1)
Block(4,-1,-3,STAINED_CLAY:14)
Block(4,-1,-2,STAINED_CLAY:14)
Block(4,-1,-1,STAINED_CLAY:14)
Block(4,-1,0,STONE:1)
Block(4,-1,1,STONE:1)
Block(4,0,-7,STAINED_CLAY:14)
Block(4,0,-6,STAINED_CLAY:14)
Block(4,0,-5,STAINED_CLAY:14)
Block(4,0,-4,STONE:1)
Block(4,0,-3,STAINED_CLAY:14)
Block(4,0,-2,STAINED_CLAY:14)
Block(4,0,-1,STAINED_CLAY:14)
Block(4,0,0,STONE:1)
Block(4,0,1,STONE:1)
Block(4,1,-7,STONE:1)
Block(4,1,-6,STAINED_CLAY:14)
Block(4,1,-5,STONE:1)
Block(4,1,-4,STONE:1)
Block(4,1,-3,STONE:1)
Block(4,1,-2,STAINED_CLAY:14)
Block(4,1,-1,STAINED_CLAY:14)
Block(4,1,0,STONE:1)
Block(4,1,1,STONE:1)
Block(4,2,-7,STONE:1)
Block(4,2,-6,STAINED_CLAY:14)
Block(4,2,-5,STONE:1)
Block(4,2,-4,STONE:1)
Block(4,2,-3,STONE:1)
Block(4,2,-2,LEAVES:7)
Block(4,2,-1,STAINED_CLAY:14)
Block(4,2,0,STAINED_CLAY:14)
Block(4,2,1,STONE:1)
Block(4,3,-7,LEAVES:7)
Block(4,3,-6,STONE:1)
Block(4,3,-5,STONE:1)
Block(4,3,-4,STONE:1)
Block(4,3,-3,STONE:1)
Block(4,3,-2,LEAVES:7)
Block(4,3,-1,STAINED_CLAY:14)
Block(4,3,0,STAINED_CLAY:14)
Block(4,3,1,STONE:1)
Block(4,4,-7,LEAVES:7)
Block(4,4,-6,STONE:1)
Block(4,4,-5,STONE:1)
Block(4,4,-4,STONE:1)
Block(4,4,-3,STONE:1)
Block(4,4,-1,LEAVES:7)
Block(4,4,0,LEAVES:7)
Block(4,4,1,STONE:1)
Block(4,5,-7,LEAVES:7)
Block(4,5,-6,STONE:1)
Block(4,5,-5,STONE:1)
Block(4,5,-4,STONE:1)
Block(4,5,-3,STONE:1)
Block(4,5,0,LEAVES:7)
Block(4,5,1,STONE:1)
Block(4,6,-7,LEAVES:7)
Block(4,6,-6,STONE:1)
Block(4,6,-5,STONE:1)
Block(4,6,-4,STONE:1)
Block(4,6,-3,STONE:1)
Block(4,6,1,LEAVES:7)
Block(4,7,-6,LEAVES:7)
Block(4,7,-5,STONE:1)
Block(4,7,-4,STONE:1)
Block(4,8,-5,LEAVES:7)
Block(4,8,-4,LEAVES:7)
Block(4,9,-4,LEAVES:7)
Block(5,-4,-3,STONE:1)
Block(5,-3,-6,STONE:1)
Block(5,-3,-5,STONE:1)
Block(5,-3,-4,STONE:1)
Block(5,-3,-3,STAINED_CLAY:14)
Block(5,-3,0,STONE:1)
Block(5,-2,-6,STONE:1)
Block(5,-2,-5,STONE:1)
Block(5,-2,-4,STONE:1)
Block(5,-2,-3,STONE:1)
Block(5,-2,0,STONE:1)
Block(5,-1,-6,STONE:1)
Block(5,-1,-5,STONE:1)
Block(5,-1,-4,STONE:1)
Block(5,-1,-3,STONE:1)
Block(5,-1,0,STONE:1)
Block(5,0,-6,STAINED_CLAY:14)
Block(5,0,-5,STONE:1)
Block(5,0,-4,STONE:1)
Block(5,0,-3,STONE:1)
Block(5,0,0,STONE:1)
Block(5,1,-6,STAINED_CLAY:14)
Block(5,1,-5,STAINED_CLAY:14)
Block(5,1,-4,STONE:1)
Block(5,1,-3,STONE:1)
Block(5,1,0,STONE:1)
Block(5,2,-6,STAINED_CLAY:14)
Block(5,2,-5,STONE:1)
Block(5,2,-4,STONE:1)
Block(5,2,-3,LEAVES:7)
Block(5,2,0,STONE:1)
Block(5,3,-6,STONE:1)
Block(5,3,-5,STONE:1)
Block(5,3,-4,STONE:1)
Block(5,3,0,STONE:1)
Block(5,4,-6,LEAVES:7)
Block(5,4,-5,STONE:1)
Block(5,4,-4,STONE:1)
Block(5,5,-6,LEAVES:7)
Block(5,5,-5,STONE:1)
Block(5,5,-4,STONE:1)
Block(6,-3,-5,STONE:1)
Block(6,-2,-5,STONE:1)
Block(6,-1,-5,STONE:1)
Block(6,0,-5,STONE:1)
Block(6,1,-5,STONE:1)
Block(6,2,-5,STONE:1)
Block(6,2,-4,LEAVES:7)
Block(6,3,-5,LEAVES:7)

#######################################################################
# +-----------------------------------------------------------------+ #
# |                            BO3 checks                           | #
# +-----------------------------------------------------------------+ #
#######################################################################

BlockCheck(6,-3,-5,GRASS,SAND,DIRT,STONE:1)

#######################################################################
# +-----------------------------------------------------------------+ #
# |                             Branches                            | #
# +-----------------------------------------------------------------+ #
#######################################################################


#######################################################################
# +-----------------------------------------------------------------+ #
# |                             Entities                            | #
# +-----------------------------------------------------------------+ #
#######################################################################


#######################################################################
# +-----------------------------------------------------------------+ #
# |                            Particles                            | #
# +-----------------------------------------------------------------+ #
#######################################################################


#######################################################################
# +-----------------------------------------------------------------+ #
# |                             Spawners                            | #
# +-----------------------------------------------------------------+ #
#######################################################################


#######################################################################
# +-----------------------------------------------------------------+ #
# |                             ModData                             | #
# +-----------------------------------------------------------------+ #
#######################################################################

