
#######################################################################
# +-----------------------------------------------------------------+ #
# |                            BO3 object                           | #
# +-----------------------------------------------------------------+ #
#######################################################################

Author: BO3 BulkEdit (by LanToaster)

Description: This Object was Created with BO3_BulkEdit

Version: 3

SettingsMode: WriteWithoutComments


#######################################################################
# +-----------------------------------------------------------------+ #
# |                          Main settings                          | #
# +-----------------------------------------------------------------+ #
#######################################################################

Tree: false

Frequency: 1

Rarity: 100.0

RotateRandomly: false

SpawnHeight: randomY

SpawnHeightOffset: 0

SpawnHeightVariance: 0

##############################
# Height Limits for the BO3. #
##############################

MinHeight: 70

MaxHeight: 75

######################
# Extrusion settings #
######################

ExtrudeMode: None

ExtrudeThroughBlocks: otg:air

MaxBranchDepth: 10


#######################################################################
# +-----------------------------------------------------------------+ #
# |                      Source block settings                      | #
# +-----------------------------------------------------------------+ #
#######################################################################

SourceBlocks: Solid

MaxPercentageOutsideSourceBlock: 80

OutsideSourceBlock: placeAnyway

DoReplaceBlocks: true

IsOTGPlus: false


#######################################################################
# +-----------------------------------------------------------------+ #
# |                              Blocks                             | #
# +-----------------------------------------------------------------+ #
#######################################################################

B(-7,7,-5,minecraft:quartz_stairs[facing=south,half=bottom,shape=straight,waterlogged=false])
B(-7,7,-4,minecraft:bone_block)
B(-7,10,-4,minecraft:bone_block)
B(-7,7,-3,minecraft:quartz_stairs[facing=east,half=bottom,shape=straight,waterlogged=false])
B(-6,7,-4,minecraft:bone_block)
B(-6,10,-4,minecraft:bone_block)
B(-6,11,-4,minecraft:quartz_stairs[facing=west,half=bottom,shape=straight,waterlogged=false])
B(-5,5,-5,minecraft:quartz_stairs[facing=south,half=top,shape=straight,waterlogged=false])
B(-5,6,-5,minecraft:bone_block[axis=x])
B(-5,7,-5,minecraft:quartz_stairs[facing=south,half=bottom,shape=straight,waterlogged=false])
B(-5,7,-4,minecraft:bone_block)
B(-5,9,-4,minecraft:bone_block)
B(-5,10,-4,minecraft:quartz_stairs[facing=west,half=bottom,shape=straight,waterlogged=false])
B(-5,5,-3,minecraft:quartz_stairs[facing=north,half=top,shape=straight,waterlogged=false])
B(-5,6,-3,minecraft:bone_block[axis=x])
B(-5,7,-3,minecraft:quartz_stairs[facing=east,half=bottom,shape=straight,waterlogged=false])
B(-4,7,-4,minecraft:bone_block)
B(-4,8,-4,minecraft:bone_block)
B(-4,9,-4,minecraft:bone_block)
B(-3,6,-5,minecraft:quartz_stairs[facing=south,half=top,shape=straight,waterlogged=false])
B(-3,7,-5,minecraft:quartz_stairs[facing=south,half=bottom,shape=straight,waterlogged=false])
B(-3,7,-4,minecraft:bone_block)
B(-3,8,-4,minecraft:bone_block[axis=x])
B(-3,9,-4,minecraft:bone_block[axis=x])
B(-3,6,-3,minecraft:quartz_stairs[facing=north,half=top,shape=straight,waterlogged=false])
B(-3,7,-3,minecraft:quartz_stairs[facing=east,half=bottom,shape=straight,waterlogged=false])
B(-2,7,-4,minecraft:bone_block)
B(-2,8,-4,minecraft:bone_block)
B(-2,9,-4,minecraft:quartz_stairs[facing=west,half=bottom,shape=straight,waterlogged=false])
B(-1,7,-4,minecraft:quartz_stairs[facing=west,half=top,shape=straight,waterlogged=false])
B(-1,8,-4,minecraft:bone_block)
B(0,7,-5,minecraft:quartz_stairs[facing=south,half=top,shape=straight,waterlogged=false])
B(0,8,-5,minecraft:quartz_stairs[facing=south,half=bottom,shape=straight,waterlogged=false])
B(0,8,-4,minecraft:bone_block)
B(0,7,-3,minecraft:quartz_stairs[facing=north,half=top,shape=straight,waterlogged=false])
B(0,8,-3,minecraft:quartz_stairs[facing=east,half=bottom,shape=straight,waterlogged=false])
B(1,8,-4,minecraft:bone_block)
B(2,8,-4,minecraft:bone_block)

#######################################################################
# +-----------------------------------------------------------------+ #
# |                            BO3 checks                           | #
# +-----------------------------------------------------------------+ #
#######################################################################


#######################################################################
# +-----------------------------------------------------------------+ #
# |                             Branches                            | #
# +-----------------------------------------------------------------+ #
#######################################################################

Branch(0,0,-16,CO-Worm_Skeleton_07-00,NORTH,100.0)
Branch(0,0,16,CO-Worm_Skeleton_07-02,NORTH,100.0)

#######################################################################
# +-----------------------------------------------------------------+ #
# |                             Entities                            | #
# +-----------------------------------------------------------------+ #
#######################################################################

