#######################################################################
# +-----------------------------------------------------------------+ #
# |                            BO3 object                           | #
# +-----------------------------------------------------------------+ #
#######################################################################

# This is the config file of a custom object.
# If you add this object correctly to your BiomeConfigs, it will spawn in the world.

# This is the creator of this BO3 object
Author: BO3 BulkEdit (by LanToaster)

# A short description of this BO3 object
Description: This Object was Created with BO3_BulkEdit

# The BO3 version, don't change this! It can be used by external applications to do a version check.
Version: 3

# The settings mode, WriteAll, WriteWithoutComments or WriteDisable. See WorldConfig.
SettingsMode: WriteDisable


#######################################################################
# +-----------------------------------------------------------------+ #
# |                          Main settings                          | #
# +-----------------------------------------------------------------+ #
#######################################################################

# This needs to be set to true to spawn the object in the Tree and Sapling resources.
Tree: false

# The frequency of the BO3 from 1 to 200. Tries this many times to spawn this BO3 when using the CustomObject(...) resource.

Frequency: 1

# The rarity of the BO3 from 0 to 100. Each spawn attempt has rarity% chance to succeed when using the CustomObject(...) resource.

Rarity: 100.0

# If you set this to true, the BO3 will be placed with a random rotation.
RotateRandomly: false

# The spawn height of the BO3 - randomY, highestBlock or highestSolidBlock.
SpawnHeight: highestBlock

# The height limits for the BO3.
MinHeight: 0

MaxHeight: 256

# Objects can have other objects attacthed to it: branches. Branches can also
# have branches attached to it, which can also have branches, etc. This is the
# maximum branch depth for this objects.
MaxBranchDepth: 10

# When spawned with the UseWorld keyword, this BO3 should NOT spawn in the following biomes.
# If you writer.write the BO3 name directly in the BiomeConfigs, this will be ignored.
ExcludedBiomes: All


#######################################################################
# +-----------------------------------------------------------------+ #
# |                      Source block settings                      | #
# +-----------------------------------------------------------------+ #
#######################################################################

# The block(s) the BO3 should spawn in.
SourceBlocks: AIR

# The maximum percentage of the BO3 that can be outside the SourceBlock.
# The BO3 won't be placed on a location with more blocks outside the SourceBlock than this percentage.
MaxPercentageOutsideSourceBlock: 100

# What to do when a block is about to be placed outside the SourceBlock? (dontPlace, placeAnyway)
OutsideSourceBlock: placeAnyway


#######################################################################
# +-----------------------------------------------------------------+ #
# |                              Blocks                             | #
# +-----------------------------------------------------------------+ #
#######################################################################

# All the blocks used in the BO3 are listed here. Possible blocks:
# Block(x,y,z,id[.data][,nbtfile.nbt)
# RandomBlock(x,y,z,id[:data][,nbtfile.nbt],chance[,id[:data][,nbtfile.nbt],chance[,...]])
# So RandomBlock(0,0,0,CHEST,chest.nbt,50,CHEST,anotherchest.nbt,100) will spawn a chest at
# the BO3 origin, and give it a 50% chance to have the contents of chest.nbt, or, if that
# fails, a 100% percent chance to have the contents of anotherchest.nbt.
Block(-1,0,-2,STAINED_GLASS:15)
Block(0,0,-2,STAINED_GLASS:15)
Block(1,0,-2,STAINED_GLASS:15)
Block(2,0,-2,STAINED_GLASS:15)
Block(3,0,-2,STAINED_GLASS:15)
Block(-2,0,-1,STAINED_GLASS:15)
Block(-1,0,-1,STAINED_GLASS:15)
Block(0,0,-1,STAINED_GLASS:15)
Block(1,0,-1,STAINED_GLASS:15)
Block(-2,0,0,STAINED_GLASS:15)
Block(-1,0,0,STAINED_GLASS:15)
Block(1,0,0,STAINED_GLASS:15)
Block(-3,0,1,STAINED_GLASS:15)
Block(0,1,-3,STAINED_GLASS:15)
Block(1,1,-3,STAINED_GLASS:15)
Block(2,1,-3,STAINED_GLASS:15)
Block(-3,1,-2,STAINED_GLASS:15)
Block(-2,1,-2,STAINED_GLASS:15)
Block(-1,1,-2,STAINED_GLASS:15)
Block(0,1,-2,STAINED_GLASS:15)
Block(1,1,-2,STAINED_GLASS:15)
Block(2,1,-2,STAINED_GLASS:15)
Block(3,1,-2,STAINED_GLASS:15)
Block(-3,1,-1,STAINED_GLASS:15)
Block(-2,1,-1,STAINED_GLASS:15)
Block(-1,1,-1,STAINED_GLASS:15)
Block(0,1,-1,STAINED_GLASS:15)
Block(1,1,-1,STAINED_GLASS:15)
Block(2,1,-1,STAINED_GLASS:15)
Block(-3,1,0,STAINED_GLASS:15)
Block(-2,1,0,STAINED_GLASS:15)
Block(-1,1,0,STAINED_GLASS:15)
Block(0,1,0,STAINED_GLASS:15)
Block(1,1,0,STAINED_GLASS:15)
Block(2,1,0,STAINED_GLASS:15)
Block(-3,1,1,STAINED_GLASS:15)
Block(-2,1,1,STAINED_GLASS:11)
Block(-1,1,1,STAINED_GLASS:15)
Block(0,1,1,STAINED_GLASS:15)
Block(0,2,-4,STAINED_GLASS:15)
Block(-1,2,-3,STAINED_GLASS:15)
Block(0,2,-3,STAINED_GLASS:15)
Block(1,2,-3,STAINED_GLASS:15)
Block(2,2,-3,STAINED_GLASS:15)
Block(-3,2,-2,STAINED_GLASS:15)
Block(-2,2,-2,STAINED_GLASS:15)
Block(-1,2,-2,STAINED_GLASS:11)
Block(0,2,-2,STAINED_GLASS:15)
Block(1,2,-2,STAINED_GLASS:15)
Block(2,2,-2,STAINED_GLASS:15)
Block(3,2,-2,STAINED_GLASS:15)
Block(-3,2,-1,STAINED_GLASS:15)
Block(-2,2,-1,STAINED_GLASS:15)
Block(-1,2,-1,STAINED_GLASS:15)
Block(0,2,-1,STAINED_GLASS:15)
Block(1,2,-1,STAINED_GLASS:11)
Block(2,2,-1,STAINED_GLASS:15)
Block(-3,2,0,STAINED_GLASS:15)
Block(-2,2,0,STAINED_GLASS:15)
Block(-1,2,0,STAINED_GLASS:11)
Block(0,2,0,SEA_LANTERN:0)
Block(1,2,0,STAINED_GLASS:11)
Block(2,2,0,SEA_LANTERN:0)
Block(3,2,0,STAINED_GLASS:15)
Block(-3,2,1,STAINED_GLASS:11)
Block(-2,2,1,STAINED_GLASS:11)
Block(-1,2,1,SEA_LANTERN:0)
Block(0,2,1,SEA_LANTERN:0)
Block(1,2,1,STAINED_GLASS:15)
Block(2,2,1,STAINED_GLASS:15)
Block(3,2,1,STAINED_GLASS:15)
Block(-2,2,2,STAINED_GLASS:11)
Block(-1,2,2,STAINED_GLASS:11)
Block(0,2,2,STAINED_GLASS:15)
Block(1,2,2,STAINED_GLASS:15)
Block(-1,3,-5,STAINED_GLASS:15)
Block(0,3,-5,STAINED_GLASS:15)
Block(-3,3,-4,STAINED_GLASS:15)
Block(-2,3,-4,STAINED_GLASS:15)
Block(-1,3,-4,STAINED_GLASS:15)
Block(0,3,-4,STAINED_GLASS:15)
Block(1,3,-4,STAINED_GLASS:15)
Block(-3,3,-3,STAINED_GLASS:15)
Block(-2,3,-3,STAINED_GLASS:15)
Block(-1,3,-3,STAINED_GLASS:11)
Block(0,3,-3,STAINED_GLASS:15)
Block(1,3,-3,STAINED_GLASS:15)
Block(2,3,-3,STAINED_GLASS:15)
Block(-4,3,-2,STAINED_GLASS:15)
Block(-3,3,-2,STAINED_GLASS:15)
Block(-2,3,-2,STAINED_GLASS:15)
Block(-1,3,-2,SEA_LANTERN:0)
Block(0,3,-2,STAINED_GLASS:11)
Block(1,3,-2,STAINED_GLASS:15)
Block(2,3,-2,STAINED_GLASS:15)
Block(3,3,-2,STAINED_GLASS:15)
Block(-3,3,-1,STAINED_GLASS:15)
Block(-2,3,-1,STAINED_GLASS:11)
Block(-1,3,-1,STAINED_GLASS:11)
Block(0,3,-1,STAINED_GLASS:11)
Block(1,3,-1,SEA_LANTERN:0)
Block(2,3,-1,STAINED_GLASS:11)
Block(-3,3,0,STAINED_GLASS:15)
Block(-2,3,0,STAINED_GLASS:15)
Block(-1,3,0,SEA_LANTERN:0)
Block(0,3,0,SEA_LANTERN:0)
Block(1,3,0,SEA_LANTERN:0)
Block(2,3,0,STAINED_GLASS:11)
Block(3,3,0,STAINED_GLASS:11)
Block(-3,3,1,STAINED_GLASS:15)
Block(-2,3,1,STAINED_GLASS:11)
Block(-1,3,1,STAINED_GLASS:11)
Block(0,3,1,SEA_LANTERN:0)
Block(1,3,1,STAINED_GLASS:11)
Block(2,3,1,STAINED_GLASS:11)
Block(3,3,1,STAINED_GLASS:11)
Block(4,3,1,STAINED_GLASS:15)
Block(-2,3,2,STAINED_GLASS:11)
Block(-1,3,2,STAINED_GLASS:11)
Block(0,3,2,STAINED_GLASS:11)
Block(1,3,2,STAINED_GLASS:11)
Block(2,3,2,STAINED_GLASS:15)
Block(-1,3,3,STAINED_GLASS:15)
Block(0,3,3,STAINED_GLASS:15)
Block(1,3,3,STAINED_GLASS:15)
Block(0,4,-6,STAINED_GLASS:15)
Block(-3,4,-5,STAINED_GLASS:15)
Block(-2,4,-5,STAINED_GLASS:15)
Block(-1,4,-5,STAINED_GLASS:15)
Block(0,4,-5,STAINED_GLASS:15)
Block(1,4,-5,STAINED_GLASS:15)
Block(-4,4,-4,STAINED_GLASS:15)
Block(-3,4,-4,STAINED_GLASS:15)
Block(-2,4,-4,STAINED_GLASS:15)
Block(-1,4,-4,STAINED_GLASS:15)
Block(0,4,-4,STAINED_GLASS:15)
Block(1,4,-4,STAINED_GLASS:15)
Block(-5,4,-3,STAINED_GLASS:15)
Block(-4,4,-3,STAINED_GLASS:15)
Block(-3,4,-3,STAINED_GLASS:15)
Block(-2,4,-3,STAINED_GLASS:15)
Block(-1,4,-3,STAINED_GLASS:11)
Block(0,4,-3,STAINED_GLASS:11)
Block(1,4,-3,STAINED_GLASS:15)
Block(2,4,-3,STAINED_GLASS:15)
Block(-4,4,-2,STAINED_GLASS:15)
Block(-3,4,-2,STAINED_GLASS:15)
Block(-2,4,-2,STAINED_GLASS:11)
Block(-1,4,-2,SEA_LANTERN:0)
Block(0,4,-2,SEA_LANTERN:0)
Block(1,4,-2,STAINED_GLASS:11)
Block(2,4,-2,STAINED_GLASS:11)
Block(3,4,-2,STAINED_GLASS:11)
Block(-3,4,-1,STAINED_GLASS:15)
Block(-2,4,-1,STAINED_GLASS:11)
Block(-1,4,-1,SEA_LANTERN:0)
Block(0,4,-1,SEA_LANTERN:0)
Block(1,4,-1,SEA_LANTERN:0)
Block(2,4,-1,STAINED_GLASS:11)
Block(-3,4,0,STAINED_GLASS:15)
Block(-2,4,0,STAINED_GLASS:11)
Block(-1,4,0,SEA_LANTERN:0)
Block(0,4,0,SEA_LANTERN:0)
Block(1,4,0,STAINED_GLASS:11)
Block(2,4,0,STAINED_GLASS:11)
Block(3,4,0,STAINED_GLASS:11)
Block(-3,4,1,STAINED_GLASS:11)
Block(-2,4,1,STAINED_GLASS:11)
Block(-1,4,1,STAINED_GLASS:11)
Block(0,4,1,SEA_LANTERN:0)
Block(1,4,1,STAINED_GLASS:11)
Block(2,4,1,STAINED_GLASS:11)
Block(3,4,1,STAINED_GLASS:11)
Block(4,4,1,STAINED_GLASS:11)
Block(-2,4,2,STAINED_GLASS:15)
Block(-1,4,2,STAINED_GLASS:15)
Block(0,4,2,STAINED_GLASS:15)
Block(1,4,2,STAINED_GLASS:11)
Block(2,4,2,STAINED_GLASS:11)
Block(3,4,2,STAINED_GLASS:11)
Block(-1,4,3,STAINED_GLASS:15)
Block(0,4,3,STAINED_GLASS:15)
Block(1,4,3,STAINED_GLASS:15)
Block(-2,5,-7,STAINED_GLASS:15)
Block(-1,5,-7,STAINED_GLASS:15)
Block(0,5,-7,STAINED_GLASS:15)
Block(-3,5,-6,STAINED_GLASS:15)
Block(-2,5,-6,STAINED_GLASS:15)
Block(-1,5,-6,STAINED_GLASS:15)
Block(0,5,-6,STAINED_GLASS:15)
Block(-5,5,-5,STAINED_GLASS:15)
Block(-4,5,-5,STAINED_GLASS:15)
Block(-3,5,-5,STAINED_GLASS:15)
Block(-2,5,-5,STAINED_GLASS:15)
Block(-1,5,-5,STAINED_GLASS:15)
Block(0,5,-5,STAINED_GLASS:15)
Block(1,5,-5,STAINED_GLASS:15)
Block(-5,5,-4,STAINED_GLASS:15)
Block(-4,5,-4,STAINED_GLASS:15)
Block(-3,5,-4,STAINED_GLASS:15)
Block(-2,5,-4,STAINED_GLASS:11)
Block(-1,5,-4,STAINED_GLASS:11)
Block(0,5,-4,STAINED_GLASS:11)
Block(1,5,-4,STAINED_GLASS:15)
Block(-5,5,-3,STAINED_GLASS:15)
Block(-4,5,-3,STAINED_GLASS:15)
Block(-3,5,-3,STAINED_GLASS:15)
Block(-2,5,-3,STAINED_GLASS:11)
Block(-1,5,-3,SEA_LANTERN:0)
Block(0,5,-3,SEA_LANTERN:0)
Block(1,5,-3,STAINED_GLASS:11)
Block(2,5,-3,STAINED_GLASS:15)
Block(-4,5,-2,STAINED_GLASS:15)
Block(-3,5,-2,STAINED_GLASS:11)
Block(-2,5,-2,SEA_LANTERN:0)
Block(-1,5,-2,SEA_LANTERN:0)
Block(0,5,-2,STAINED_GLASS:11)
Block(1,5,-2,STAINED_GLASS:15)
Block(2,5,-2,STAINED_GLASS:15)
Block(3,5,-2,STAINED_GLASS:15)
Block(-3,5,-1,STAINED_GLASS:11)
Block(-2,5,-1,SEA_LANTERN:0)
Block(-1,5,-1,STAINED_GLASS:11)
Block(0,5,-1,STAINED_GLASS:11)
Block(1,5,-1,STAINED_GLASS:11)
Block(2,5,-1,STAINED_GLASS:11)
Block(-3,5,0,STAINED_GLASS:11)
Block(-2,5,0,STAINED_GLASS:11)
Block(-1,5,0,STAINED_GLASS:11)
Block(0,5,0,SEA_LANTERN:0)
Block(1,5,0,STAINED_GLASS:15)
Block(2,5,0,STAINED_GLASS:11)
Block(3,5,0,STAINED_GLASS:11)
Block(-3,5,1,STAINED_GLASS:11)
Block(-2,5,1,STAINED_GLASS:11)
Block(-1,5,1,STAINED_GLASS:15)
Block(0,5,1,STAINED_GLASS:11)
Block(1,5,1,STAINED_GLASS:11)
Block(2,5,1,STAINED_GLASS:11)
Block(3,5,1,STAINED_GLASS:11)
Block(-2,5,2,STAINED_GLASS:11)
Block(-1,5,2,STAINED_GLASS:15)
Block(0,5,2,STAINED_GLASS:15)
Block(1,5,2,STAINED_GLASS:11)
Block(0,5,3,STAINED_GLASS:15)
Block(-3,6,-7,STAINED_GLASS:15)
Block(-2,6,-7,STAINED_GLASS:15)
Block(-1,6,-7,STAINED_GLASS:15)
Block(0,6,-7,STAINED_GLASS:15)
Block(-5,6,-6,STAINED_GLASS:15)
Block(-4,6,-6,STAINED_GLASS:15)
Block(-3,6,-6,STAINED_GLASS:15)
Block(-2,6,-6,STAINED_GLASS:15)
Block(-1,6,-6,STAINED_GLASS:15)
Block(0,6,-6,STAINED_GLASS:15)
Block(-5,6,-5,STAINED_GLASS:15)
Block(-4,6,-5,STAINED_GLASS:15)
Block(-3,6,-5,STAINED_GLASS:15)
Block(-2,6,-5,STAINED_GLASS:15)
Block(-1,6,-5,STAINED_GLASS:11)
Block(0,6,-5,STAINED_GLASS:15)
Block(1,6,-5,STAINED_GLASS:15)
Block(-5,6,-4,STAINED_GLASS:15)
Block(-4,6,-4,STAINED_GLASS:15)
Block(-3,6,-4,STAINED_GLASS:11)
Block(-2,6,-4,SEA_LANTERN:0)
Block(-1,6,-4,STAINED_GLASS:11)
Block(0,6,-4,SEA_LANTERN:0)
Block(1,6,-4,STAINED_GLASS:15)
Block(-5,6,-3,STAINED_GLASS:15)
Block(-4,6,-3,STAINED_GLASS:15)
Block(-3,6,-3,STAINED_GLASS:15)
Block(-2,6,-3,STAINED_GLASS:11)
Block(-1,6,-3,SEA_LANTERN:0)
Block(0,6,-3,SEA_LANTERN:0)
Block(1,6,-3,STAINED_GLASS:11)
Block(2,6,-3,STAINED_GLASS:15)
Block(-4,6,-2,STAINED_GLASS:15)
Block(-3,6,-2,STAINED_GLASS:11)
Block(-2,6,-2,SEA_LANTERN:0)
Block(-1,6,-2,SEA_LANTERN:0)
Block(0,6,-2,STAINED_GLASS:11)
Block(1,6,-2,STAINED_GLASS:15)
Block(2,6,-2,STAINED_GLASS:15)
Block(3,6,-2,STAINED_GLASS:15)
Block(-3,6,-1,STAINED_GLASS:15)
Block(-2,6,-1,STAINED_GLASS:11)
Block(-1,6,-1,STAINED_GLASS:11)
Block(0,6,-1,STAINED_GLASS:11)
Block(1,6,-1,STAINED_GLASS:11)
Block(2,6,-1,STAINED_GLASS:15)
Block(-3,6,0,STAINED_GLASS:15)
Block(-2,6,0,STAINED_GLASS:11)
Block(-1,6,0,STAINED_GLASS:15)
Block(0,6,0,STAINED_GLASS:11)
Block(1,6,0,STAINED_GLASS:11)
Block(2,6,0,STAINED_GLASS:11)
Block(3,6,0,STAINED_GLASS:15)
Block(-3,6,1,STAINED_GLASS:11)
Block(-2,6,1,STAINED_GLASS:11)
Block(-1,6,1,STAINED_GLASS:15)
Block(0,6,1,STAINED_GLASS:11)
Block(1,6,1,STAINED_GLASS:11)
Block(2,6,1,STAINED_GLASS:11)
Block(3,6,1,STAINED_GLASS:11)
Block(-2,6,2,STAINED_GLASS:15)
Block(-1,6,2,STAINED_GLASS:15)
Block(0,6,2,STAINED_GLASS:11)
Block(-5,7,-7,STAINED_GLASS:15)
Block(-4,7,-7,STAINED_GLASS:15)
Block(-3,7,-7,STAINED_GLASS:11)
Block(-2,7,-7,STAINED_GLASS:15)
Block(-1,7,-7,STAINED_GLASS:15)
Block(0,7,-7,STAINED_GLASS:15)
Block(-6,7,-6,STAINED_GLASS:15)
Block(-5,7,-6,STAINED_GLASS:15)
Block(-4,7,-6,STAINED_GLASS:15)
Block(-3,7,-6,STAINED_GLASS:15)
Block(-2,7,-6,STAINED_GLASS:15)
Block(-1,7,-6,STAINED_GLASS:11)
Block(0,7,-6,STAINED_GLASS:15)
Block(-5,7,-5,STAINED_GLASS:15)
Block(-4,7,-5,STAINED_GLASS:11)
Block(-3,7,-5,STAINED_GLASS:11)
Block(-2,7,-5,STAINED_GLASS:11)
Block(-1,7,-5,SEA_LANTERN:0)
Block(0,7,-5,STAINED_GLASS:11)
Block(1,7,-5,STAINED_GLASS:15)
Block(-5,7,-4,STAINED_GLASS:15)
Block(-4,7,-4,STAINED_GLASS:15)
Block(-3,7,-4,SEA_LANTERN:0)
Block(-2,7,-4,SEA_LANTERN:0)
Block(-1,7,-4,SEA_LANTERN:0)
Block(0,7,-4,STAINED_GLASS:11)
Block(1,7,-4,STAINED_GLASS:15)
Block(-5,7,-3,STAINED_GLASS:15)
Block(-4,7,-3,STAINED_GLASS:15)
Block(-3,7,-3,STAINED_GLASS:11)
Block(-2,7,-3,SEA_LANTERN:0)
Block(-1,7,-3,SEA_LANTERN:0)
Block(0,7,-3,STAINED_GLASS:11)
Block(1,7,-3,STAINED_GLASS:15)
Block(2,7,-3,STAINED_GLASS:15)
Block(-4,7,-2,STAINED_GLASS:11)
Block(-3,7,-2,STAINED_GLASS:11)
Block(-2,7,-2,STAINED_GLASS:11)
Block(-1,7,-2,STAINED_GLASS:11)
Block(0,7,-2,STAINED_GLASS:11)
Block(1,7,-2,STAINED_GLASS:15)
Block(2,7,-2,STAINED_GLASS:15)
Block(3,7,-2,STAINED_GLASS:15)
Block(-3,7,-1,STAINED_GLASS:15)
Block(-2,7,-1,STAINED_GLASS:15)
Block(-1,7,-1,STAINED_GLASS:15)
Block(0,7,-1,STAINED_GLASS:11)
Block(1,7,-1,STAINED_GLASS:11)
Block(2,7,-1,STAINED_GLASS:11)
Block(-3,7,0,STAINED_GLASS:15)
Block(-2,7,0,STAINED_GLASS:15)
Block(-1,7,0,STAINED_GLASS:15)
Block(0,7,0,STAINED_GLASS:11)
Block(1,7,0,STAINED_GLASS:11)
Block(-3,7,1,STAINED_GLASS:15)
Block(-2,7,1,STAINED_GLASS:15)
Block(-6,8,-7,STAINED_GLASS:15)
Block(-5,8,-7,STAINED_GLASS:15)
Block(-4,8,-7,STAINED_GLASS:15)
Block(-3,8,-7,STAINED_GLASS:11)
Block(-2,8,-7,STAINED_GLASS:11)
Block(-1,8,-7,STAINED_GLASS:15)
Block(0,8,-7,STAINED_GLASS:15)
Block(-6,8,-6,STAINED_GLASS:15)
Block(-5,8,-6,STAINED_GLASS:15)
Block(-4,8,-6,STAINED_GLASS:15)
Block(-3,8,-6,STAINED_GLASS:11)
Block(-2,8,-6,STAINED_GLASS:11)
Block(-1,8,-6,STAINED_GLASS:11)
Block(0,8,-6,STAINED_GLASS:11)
Block(-5,8,-5,STAINED_GLASS:15)
Block(-4,8,-5,STAINED_GLASS:11)
Block(-3,8,-5,SEA_LANTERN:0)
Block(-2,8,-5,SEA_LANTERN:0)
Block(-1,8,-5,SEA_LANTERN:0)
Block(0,8,-5,STAINED_GLASS:15)
Block(1,8,-5,STAINED_GLASS:15)
Block(-5,8,-4,STAINED_GLASS:15)
Block(-4,8,-4,STAINED_GLASS:11)
Block(-3,8,-4,SEA_LANTERN:0)
Block(-2,8,-4,SEA_LANTERN:0)
Block(-1,8,-4,STAINED_GLASS:11)
Block(0,8,-4,STAINED_GLASS:11)
Block(1,8,-4,STAINED_GLASS:15)
Block(-5,8,-3,STAINED_GLASS:11)
Block(-4,8,-3,STAINED_GLASS:11)
Block(-3,8,-3,STAINED_GLASS:11)
Block(-2,8,-3,STAINED_GLASS:11)
Block(-1,8,-3,SEA_LANTERN:0)
Block(0,8,-3,STAINED_GLASS:11)
Block(1,8,-3,STAINED_GLASS:15)
Block(2,8,-3,STAINED_GLASS:15)
Block(-4,8,-2,STAINED_GLASS:11)
Block(-3,8,-2,STAINED_GLASS:11)
Block(-2,8,-2,STAINED_GLASS:11)
Block(-1,8,-2,STAINED_GLASS:11)
Block(0,8,-2,STAINED_GLASS:11)
Block(1,8,-2,STAINED_GLASS:15)
Block(2,8,-2,STAINED_GLASS:15)
Block(-3,8,-1,STAINED_GLASS:11)
Block(-2,8,-1,STAINED_GLASS:15)
Block(-1,8,-1,STAINED_GLASS:11)
Block(0,8,-1,STAINED_GLASS:11)
Block(1,8,-1,STAINED_GLASS:11)
Block(-3,8,0,STAINED_GLASS:11)
Block(-2,8,0,STAINED_GLASS:15)
Block(-1,8,0,STAINED_GLASS:15)
Block(0,8,0,STAINED_GLASS:11)
Block(-6,9,-7,STAINED_GLASS:15)
Block(-5,9,-7,STAINED_GLASS:15)
Block(-4,9,-7,STAINED_GLASS:15)
Block(-3,9,-7,SEA_LANTERN:0)
Block(-2,9,-7,STAINED_GLASS:11)
Block(-1,9,-7,STAINED_GLASS:15)
Block(0,9,-7,STAINED_GLASS:15)
Block(-6,9,-6,STAINED_GLASS:15)
Block(-5,9,-6,STAINED_GLASS:11)
Block(-4,9,-6,STAINED_GLASS:11)
Block(-3,9,-6,STAINED_GLASS:11)
Block(-2,9,-6,STAINED_GLASS:11)
Block(-1,9,-6,SEA_LANTERN:0)
Block(0,9,-6,STAINED_GLASS:11)
Block(-5,9,-5,STAINED_GLASS:15)
Block(-4,9,-5,SEA_LANTERN:0)
Block(-3,9,-5,SEA_LANTERN:0)
Block(-2,9,-5,SEA_LANTERN:0)
Block(-1,9,-5,STAINED_GLASS:11)
Block(0,9,-5,STAINED_GLASS:15)
Block(1,9,-5,STAINED_GLASS:15)
Block(-5,9,-4,STAINED_GLASS:15)
Block(-4,9,-4,STAINED_GLASS:11)
Block(-3,9,-4,STAINED_GLASS:11)
Block(-2,9,-4,SEA_LANTERN:0)
Block(-1,9,-4,STAINED_GLASS:11)
Block(0,9,-4,STAINED_GLASS:15)
Block(1,9,-4,STAINED_GLASS:15)
Block(-5,9,-3,STAINED_GLASS:15)
Block(-4,9,-3,STAINED_GLASS:15)
Block(-3,9,-3,STAINED_GLASS:11)
Block(-2,9,-3,STAINED_GLASS:11)
Block(-1,9,-3,STAINED_GLASS:11)
Block(0,9,-3,STAINED_GLASS:11)
Block(1,9,-3,STAINED_GLASS:15)
Block(2,9,-3,STAINED_GLASS:15)
Block(-4,9,-2,STAINED_GLASS:11)
Block(-3,9,-2,STAINED_GLASS:11)
Block(-2,9,-2,STAINED_GLASS:11)
Block(-1,9,-2,STAINED_GLASS:11)
Block(0,9,-2,STAINED_GLASS:11)
Block(1,9,-2,STAINED_GLASS:15)
Block(2,9,-2,STAINED_GLASS:15)
Block(-3,9,-1,STAINED_GLASS:15)
Block(-2,9,-1,STAINED_GLASS:11)
Block(-1,9,-1,STAINED_GLASS:11)
Block(0,9,-1,STAINED_GLASS:11)
Block(-3,9,0,STAINED_GLASS:15)
Block(-2,9,0,STAINED_GLASS:15)
Block(-6,10,-7,STAINED_GLASS:15)
Block(-5,10,-7,STAINED_GLASS:15)
Block(-4,10,-7,STAINED_GLASS:11)
Block(-3,10,-7,SEA_LANTERN:0)
Block(-2,10,-7,SEA_LANTERN:0)
Block(-1,10,-7,STAINED_GLASS:11)
Block(0,10,-7,STAINED_GLASS:15)
Block(-6,10,-6,STAINED_GLASS:15)
Block(-5,10,-6,SEA_LANTERN:0)
Block(-4,10,-6,SEA_LANTERN:0)
Block(-3,10,-6,SEA_LANTERN:0)
Block(-2,10,-6,SEA_LANTERN:0)
Block(-1,10,-6,STAINED_GLASS:11)
Block(0,10,-6,STAINED_GLASS:15)
Block(-5,10,-5,STAINED_GLASS:11)
Block(-4,10,-5,STAINED_GLASS:11)
Block(-3,10,-5,STAINED_GLASS:11)
Block(-2,10,-5,STAINED_GLASS:11)
Block(-1,10,-5,STAINED_GLASS:15)
Block(0,10,-5,STAINED_GLASS:15)
Block(1,10,-5,STAINED_GLASS:15)
Block(-5,10,-4,STAINED_GLASS:15)
Block(-4,10,-4,STAINED_GLASS:11)
Block(-3,10,-4,STAINED_GLASS:11)
Block(-2,10,-4,STAINED_GLASS:11)
Block(-1,10,-4,STAINED_GLASS:15)
Block(0,10,-4,STAINED_GLASS:15)
Block(1,10,-4,STAINED_GLASS:15)
Block(-5,10,-3,STAINED_GLASS:11)
Block(-4,10,-3,STAINED_GLASS:11)
Block(-3,10,-3,STAINED_GLASS:11)
Block(-2,10,-3,STAINED_GLASS:11)
Block(-1,10,-3,STAINED_GLASS:11)
Block(0,10,-3,STAINED_GLASS:11)
Block(1,10,-3,STAINED_GLASS:15)
Block(-4,10,-2,STAINED_GLASS:15)
Block(-3,10,-2,STAINED_GLASS:15)
Block(-2,10,-2,STAINED_GLASS:11)
Block(-6,11,-7,STAINED_GLASS:15)
Block(-5,11,-7,STAINED_GLASS:11)
Block(-4,11,-7,SEA_LANTERN:0)
Block(-3,11,-7,SEA_LANTERN:0)
Block(-2,11,-7,STAINED_GLASS:11)
Block(-1,11,-7,STAINED_GLASS:15)
Block(0,11,-7,STAINED_GLASS:15)
Block(-6,11,-6,STAINED_GLASS:15)
Block(-5,11,-6,SEA_LANTERN:0)
Block(-4,11,-6,SEA_LANTERN:0)
Block(-3,11,-6,STAINED_GLASS:11)
Block(-2,11,-6,STAINED_GLASS:11)
Block(-1,11,-6,STAINED_GLASS:11)
Block(0,11,-6,STAINED_GLASS:15)
Block(-5,11,-5,STAINED_GLASS:15)
Block(-4,11,-5,STAINED_GLASS:11)
Block(-3,11,-5,STAINED_GLASS:11)
Block(-2,11,-5,STAINED_GLASS:11)
Block(-1,11,-5,STAINED_GLASS:15)
Block(0,11,-5,STAINED_GLASS:15)
Block(1,11,-5,STAINED_GLASS:15)
Block(-5,11,-4,STAINED_GLASS:11)
Block(-4,11,-4,STAINED_GLASS:11)
Block(-3,11,-4,STAINED_GLASS:11)
Block(-2,11,-4,STAINED_GLASS:11)
Block(-1,11,-4,STAINED_GLASS:11)
Block(0,11,-4,STAINED_GLASS:15)
Block(-5,11,-3,STAINED_GLASS:11)
Block(-4,11,-3,STAINED_GLASS:11)
Block(-3,11,-3,STAINED_GLASS:11)
Block(-2,11,-3,STAINED_GLASS:11)
Block(-1,11,-3,STAINED_GLASS:11)
Block(-6,12,-7,STAINED_GLASS:15)
Block(-5,12,-7,STAINED_GLASS:11)
Block(-4,12,-7,STAINED_GLASS:11)
Block(-3,12,-7,SEA_LANTERN:0)
Block(-2,12,-7,STAINED_GLASS:15)
Block(-1,12,-7,STAINED_GLASS:15)
Block(0,12,-7,STAINED_GLASS:15)
Block(-6,12,-6,STAINED_GLASS:11)
Block(-5,12,-6,STAINED_GLASS:11)
Block(-4,12,-6,STAINED_GLASS:11)
Block(-3,12,-6,STAINED_GLASS:15)
Block(-2,12,-6,STAINED_GLASS:15)
Block(-1,12,-6,STAINED_GLASS:15)
Block(0,12,-6,STAINED_GLASS:15)
Block(-5,12,-5,STAINED_GLASS:11)
Block(-4,12,-5,STAINED_GLASS:15)
Block(-3,12,-5,STAINED_GLASS:11)
Block(-2,12,-5,STAINED_GLASS:11)
Block(-1,12,-5,STAINED_GLASS:11)
Block(-5,12,-4,STAINED_GLASS:15)
Block(-4,12,-4,STAINED_GLASS:11)
Block(-3,12,-4,STAINED_GLASS:11)
Block(-2,12,-4,STAINED_GLASS:11)
Block(-6,13,-7,STAINED_GLASS:11)
Block(-5,13,-7,STAINED_GLASS:11)
Block(-4,13,-7,STAINED_GLASS:11)
Block(-3,13,-7,STAINED_GLASS:11)
Block(-2,13,-7,STAINED_GLASS:11)
Block(-1,13,-7,STAINED_GLASS:15)
Block(0,13,-7,STAINED_GLASS:15)
Block(-6,13,-6,STAINED_GLASS:11)
Block(-5,13,-6,STAINED_GLASS:11)
Block(-4,13,-6,STAINED_GLASS:11)
Block(-3,13,-6,STAINED_GLASS:15)
Block(-2,13,-6,STAINED_GLASS:11)
Block(-1,13,-6,STAINED_GLASS:11)
Block(0,13,-6,STAINED_GLASS:15)
Block(-5,13,-5,STAINED_GLASS:11)
Block(-4,13,-5,STAINED_GLASS:15)
Block(-3,13,-5,STAINED_GLASS:11)
Block(-2,13,-5,STAINED_GLASS:11)
Block(-5,13,-4,STAINED_GLASS:11)
Block(-4,13,-4,STAINED_GLASS:15)
Block(-6,14,-7,STAINED_GLASS:11)
Block(-5,14,-7,STAINED_GLASS:11)
Block(-4,14,-7,STAINED_GLASS:15)
Block(-3,14,-7,STAINED_GLASS:11)
Block(-2,14,-7,STAINED_GLASS:11)
Block(-1,14,-7,STAINED_GLASS:11)
Block(-6,14,-6,STAINED_GLASS:11)
Block(-5,14,-6,STAINED_GLASS:15)
Block(-4,14,-6,STAINED_GLASS:15)
Block(-3,14,-6,STAINED_GLASS:11)
Block(-2,14,-6,STAINED_GLASS:11)
Block(-1,14,-6,STAINED_GLASS:11)
Block(-5,14,-5,STAINED_GLASS:11)
Block(-4,14,-5,STAINED_GLASS:15)
Block(-6,15,-7,STAINED_GLASS:11)
Block(-5,15,-7,STAINED_GLASS:11)
Block(-4,15,-7,STAINED_GLASS:15)
Block(-3,15,-7,STAINED_GLASS:11)
Block(-5,15,-6,STAINED_GLASS:15)
Block(-4,15,-6,STAINED_GLASS:15)
Block(-6,16,-7,STAINED_GLASS:15)
Block(-5,16,-7,STAINED_GLASS:15)
Block(-4,16,-7,STAINED_GLASS:11)
Branch(-16,0,0,spike-IL-23_00-02,NORTH,100)
Branch(0,0,-16,spike-IL-23_01-01,NORTH,100)
