
#######################################################################
# +-----------------------------------------------------------------+ #
# |                            BO3 object                           | #
# +-----------------------------------------------------------------+ #
#######################################################################

Author: BO3 BulkEdit (by LanToaster)

Description: This Object was Created with BO3_BulkEdit

Version: 3

SettingsMode: WriteWithoutComments


#######################################################################
# +-----------------------------------------------------------------+ #
# |                          Main settings                          | #
# +-----------------------------------------------------------------+ #
#######################################################################

Tree: false

Frequency: 1

Rarity: 100.0

RotateRandomly: false

SpawnHeight: randomY

SpawnHeightOffset: 0

SpawnHeightVariance: 0

##############################
# Height Limits for the BO3. #
##############################

MinHeight: 82

MaxHeight: 82

######################
# Extrusion settings #
######################

ExtrudeMode: None

ExtrudeThroughBlocks: minecraft:air

MaxBranchDepth: 10


#######################################################################
# +-----------------------------------------------------------------+ #
# |                      Source block settings                      | #
# +-----------------------------------------------------------------+ #
#######################################################################

SourceBlocks: otg:air

MaxPercentageOutsideSourceBlock: 100

OutsideSourceBlock: placeAnyway

DoReplaceBlocks: true

IsOTGPlus: false


#######################################################################
# +-----------------------------------------------------------------+ #
# |                              Blocks                             | #
# +-----------------------------------------------------------------+ #
#######################################################################

B(0,0,-2,minecraft:stone_brick_stairs[facing=east,half=bottom,shape=straight,waterlogged=false])
B(0,0,1,minecraft:stone_brick_stairs[facing=east,half=bottom,shape=straight,waterlogged=false])
B(1,1,-2,minecraft:stone_brick_slab)
B(1,0,-1,minecraft:stone_brick_stairs[facing=east,half=bottom,shape=straight,waterlogged=false])
B(1,0,0,minecraft:stone_brick_stairs[facing=east,half=bottom,shape=straight,waterlogged=false])
B(1,1,1,minecraft:stone_brick_stairs[facing=east,half=bottom,shape=straight,waterlogged=false])
B(2,2,-2,minecraft:stone_brick_stairs[facing=east,half=bottom,shape=straight,waterlogged=false])
B(2,1,-1,minecraft:stone_brick_stairs[facing=east,half=bottom,shape=straight,waterlogged=false])
B(2,1,0,minecraft:stone_brick_slab)
B(2,-1,1,minecraft:jungle_leaves[distance=7,persistent=true])
B(2,0,1,minecraft:jungle_leaves[distance=7,persistent=true])
B(2,2,1,minecraft:stone_brick_stairs[facing=east,half=bottom,shape=straight,waterlogged=false])
B(2,-1,2,minecraft:jungle_leaves[distance=7,persistent=true])
B(2,0,2,minecraft:jungle_leaves[distance=7,persistent=true])
B(3,3,-2,minecraft:stone_brick_stairs[facing=east,half=bottom,shape=straight,waterlogged=false])
B(3,2,-1,minecraft:stone_brick_stairs[facing=east,half=bottom,shape=straight,waterlogged=false])
B(3,2,0,minecraft:stone_brick_stairs[facing=east,half=bottom,shape=straight,waterlogged=false])
B(3,-1,1,minecraft:jungle_leaves[distance=7,persistent=true])
B(3,0,1,minecraft:jungle_leaves[distance=7,persistent=true])
B(3,1,1,minecraft:jungle_leaves[distance=7,persistent=true])
B(3,3,1,minecraft:stone_brick_stairs[facing=east,half=bottom,shape=straight,waterlogged=false])
B(3,-1,7,minecraft:jungle_leaves[distance=7,persistent=true])
B(3,0,7,minecraft:jungle_leaves[distance=7,persistent=true])
B(3,-1,8,minecraft:jungle_leaves[distance=7,persistent=true])
B(3,0,8,minecraft:jungle_leaves[distance=7,persistent=true])
B(4,0,-7,minecraft:stone_brick_stairs[facing=east,half=bottom,shape=straight,waterlogged=false])
B(4,0,-6,minecraft:stone_brick_slab)
B(4,-1,-5,minecraft:jungle_leaves[distance=7,persistent=true])
B(4,0,-5,minecraft:jungle_leaves[distance=7,persistent=true])
B(4,0,-4,minecraft:stone_brick_stairs[facing=east,half=bottom,shape=straight,waterlogged=false])
B(4,0,-3,minecraft:stone_brick_stairs[facing=east,half=bottom,shape=straight,waterlogged=false])
B(4,4,-2,minecraft:stone_brick_stairs[facing=east,half=bottom,shape=straight,waterlogged=false])
B(4,3,-1,minecraft:stone_brick_stairs[facing=east,half=bottom,shape=straight,waterlogged=false])
B(4,3,0,minecraft:stone_brick_stairs[facing=east,half=bottom,shape=straight,waterlogged=false])
B(4,1,1,minecraft:jungle_leaves[distance=7,persistent=true])
B(4,2,1,minecraft:jungle_leaves[distance=7,persistent=true])
B(4,4,1,minecraft:stone_brick_slab)
B(4,0,2,minecraft:stone_brick_stairs[facing=east,half=bottom,shape=straight,waterlogged=false])
B(4,0,3,minecraft:stone_brick_stairs[facing=east,half=bottom,shape=straight,waterlogged=false])
B(4,0,4,minecraft:stone_brick_stairs[facing=east,half=bottom,shape=straight,waterlogged=false])
B(4,0,5,minecraft:stone_brick_stairs[facing=east,half=bottom,shape=straight,waterlogged=false])
B(4,1,5,minecraft:vine[east=true,north=false,south=false,up=false,west=false])
B(4,2,5,minecraft:vine[east=true,north=false,south=false,up=false,west=false])
B(4,3,5,minecraft:vine[east=true,north=false,south=false,up=false,west=false])
B(4,4,5,minecraft:vine[east=true,north=false,south=false,up=false,west=false])
B(4,0,6,minecraft:stone_brick_stairs[facing=east,half=bottom,shape=straight,waterlogged=false])
B(4,0,7,minecraft:stone_brick_stairs[facing=east,half=bottom,shape=straight,waterlogged=false])
B(4,-1,8,minecraft:jungle_leaves[distance=7,persistent=true])
B(4,0,8,minecraft:jungle_leaves[distance=7,persistent=true])
B(4,1,8,minecraft:jungle_leaves[distance=7,persistent=true])
B(4,2,8,minecraft:vine[east=true,north=false,south=false,up=false,west=false])
B(4,3,8,minecraft:vine[east=true,north=false,south=false,up=false,west=false])
B(5,1,-7,minecraft:stone_brick_stairs[facing=east,half=bottom,shape=straight,waterlogged=false])
B(5,3,-7,minecraft:stone_brick_stairs[facing=east,half=top,shape=straight,waterlogged=false])
B(5,3,-6,minecraft:smooth_stone_slab[type=top,waterlogged=false])
B(5,1,-5,minecraft:jungle_leaves[distance=7,persistent=true])
B(5,3,-5,minecraft:smooth_stone_slab[type=top,waterlogged=false])
B(5,1,-4,minecraft:stone_brick_stairs[facing=east,half=bottom,shape=straight,waterlogged=false])
B(5,3,-4,minecraft:stone_brick_stairs[facing=east,half=top,shape=straight,waterlogged=false])
B(5,2,-3,minecraft:jungle_leaves[distance=7,persistent=true])
B(5,3,-3,minecraft:jungle_leaves[distance=7,persistent=true])
B(5,5,-2,minecraft:stone_brick_stairs[facing=east,half=bottom,shape=straight,waterlogged=false])
B(5,4,-1,minecraft:stone_brick_slab)
B(5,4,0,minecraft:stone_brick_stairs[facing=east,half=bottom,shape=straight,waterlogged=false])
B(5,5,1,minecraft:stone_brick_stairs[facing=east,half=bottom,shape=straight,waterlogged=false])
B(5,1,2,minecraft:jungle_leaves[distance=7,persistent=true])
B(5,2,2,minecraft:jungle_leaves[distance=7,persistent=true])
B(5,3,2,minecraft:jungle_leaves[distance=7,persistent=true])
B(5,1,3,minecraft:stone_brick_stairs[facing=east,half=bottom,shape=straight,waterlogged=false])
B(5,3,3,minecraft:stone_brick_stairs[facing=east,half=top,shape=straight,waterlogged=false])
B(5,1,4,minecraft:vine[east=true,north=false,south=true,up=false,west=false])
B(5,2,4,minecraft:vine[east=true,north=false,south=true,up=false,west=false])
B(5,3,4,minecraft:vine[east=false,north=false,south=true,up=false,west=false])
B(5,4,4,minecraft:vine[east=false,north=false,south=true,up=false,west=false])
B(5,2,5,minecraft:jungle_leaves[distance=7,persistent=true])
B(5,3,5,minecraft:jungle_leaves[distance=7,persistent=true])
B(5,4,5,minecraft:jungle_leaves[distance=7,persistent=true])
B(5,1,6,minecraft:stone_brick_stairs[facing=east,half=bottom,shape=straight,waterlogged=false])
B(5,3,6,minecraft:stone_brick_stairs[facing=east,half=top,shape=straight,waterlogged=false])
B(5,4,6,minecraft:vine[east=false,north=true,south=false,up=false,west=false])
B(5,1,7,minecraft:jungle_leaves[distance=7,persistent=true])
B(5,3,7,minecraft:smooth_stone_slab[type=top,waterlogged=false])
B(5,1,8,minecraft:jungle_leaves[distance=7,persistent=true])
B(5,2,8,minecraft:jungle_leaves[distance=7,persistent=true])
B(5,3,8,minecraft:jungle_leaves[distance=7,persistent=true])
B(5,4,8,minecraft:vine[east=true,north=false,south=false,up=false,west=false])
B(6,4,-7,minecraft:vine[east=true,north=false,south=false,up=false,west=false])
B(6,5,-7,minecraft:vine[east=true,north=false,south=false,up=false,west=false])
B(6,6,-7,minecraft:vine[east=true,north=false,south=false,up=false,west=false])
B(6,4,-6,minecraft:jungle_leaves[distance=7,persistent=true])
B(6,1,-5,minecraft:jungle_leaves[distance=7,persistent=true])
B(6,4,-4,minecraft:jungle_leaves[distance=7,persistent=true])
B(6,4,-3,minecraft:jungle_leaves[distance=7,persistent=true])
B(6,6,-2,minecraft:stone_brick_stairs[facing=east,half=bottom,shape=straight,waterlogged=false])
B(6,5,-1,minecraft:stone_brick_stairs[facing=east,half=bottom,shape=straight,waterlogged=false])
B(6,5,0,minecraft:stone_brick_stairs[facing=east,half=bottom,shape=straight,waterlogged=false])
B(6,4,1,minecraft:jungle_leaves[distance=7,persistent=true])
B(6,6,1,minecraft:stone_brick_stairs[facing=east,half=bottom,shape=straight,waterlogged=false])
B(6,3,2,minecraft:jungle_leaves[distance=7,persistent=true])
B(6,4,2,minecraft:vine[east=true,north=false,south=false,up=false,west=false])
B(6,5,2,minecraft:vine[east=true,north=false,south=false,up=false,west=false])
B(6,6,2,minecraft:vine[east=true,north=false,south=false,up=false,west=false])
B(6,7,2,minecraft:vine[east=true,north=false,south=false,up=false,west=false])
B(6,4,3,minecraft:vine[east=true,north=false,south=false,up=false,west=false])
B(6,5,3,minecraft:vine[east=true,north=false,south=false,up=false,west=false])
B(6,6,3,minecraft:vine[east=true,north=false,south=false,up=false,west=false])
B(6,7,3,minecraft:vine[east=true,north=false,south=false,up=false,west=false])
B(6,4,4,minecraft:vine[east=true,north=false,south=false,up=false,west=false])
B(6,5,4,minecraft:vine[east=true,north=false,south=false,up=false,west=false])
B(6,6,4,minecraft:vine[east=true,north=false,south=false,up=false,west=false])
B(6,7,4,minecraft:vine[east=true,north=false,south=false,up=false,west=false])
B(6,4,5,minecraft:jungle_leaves[distance=7,persistent=true])
B(6,4,8,minecraft:jungle_leaves[distance=7,persistent=true])
B(7,3,-7,minecraft:smooth_stone_slab[type=top,waterlogged=false])
B(7,5,-7,minecraft:jungle_leaves[distance=7,persistent=true])
B(7,6,-7,minecraft:jungle_leaves[distance=7,persistent=true])
B(7,1,-6,minecraft:jungle_leaves[distance=7,persistent=true])
B(7,3,-6,minecraft:smooth_stone_slab[type=top,waterlogged=false])
B(7,4,-6,minecraft:jungle_leaves[distance=7,persistent=true])
B(7,6,-6,minecraft:jungle_leaves[distance=7,persistent=true])
B(7,7,-6,minecraft:jungle_leaves[distance=7,persistent=true])
B(7,1,-5,minecraft:jungle_leaves[distance=7,persistent=true])
B(7,3,-5,minecraft:smooth_stone_slab[type=top,waterlogged=false])
B(7,4,-5,minecraft:stone_brick_stairs[facing=east,half=bottom,shape=straight,waterlogged=false])
B(7,3,-4,minecraft:smooth_stone_slab[type=top,waterlogged=false])
B(7,4,-4,minecraft:jungle_leaves[distance=7,persistent=true])
B(7,3,-3,minecraft:smooth_stone_slab[type=top,waterlogged=false])
B(7,4,-3,minecraft:jungle_leaves[distance=7,persistent=true])
B(7,5,-3,minecraft:jungle_leaves[distance=7,persistent=true])
B(7,7,-2,minecraft:stone_brick_stairs[facing=east,half=bottom,shape=straight,waterlogged=false])
B(7,6,-1,minecraft:stone_brick_stairs[facing=east,half=bottom,shape=straight,waterlogged=false])
B(7,6,0,minecraft:stone_brick_stairs[facing=east,half=bottom,shape=straight,waterlogged=false])
B(7,4,1,minecraft:jungle_leaves[distance=7,persistent=true])
B(7,7,1,minecraft:stone_brick_stairs[facing=east,half=bottom,shape=straight,waterlogged=false])
B(7,8,1,minecraft:vine[east=true,north=false,south=false,up=false,west=false])
B(7,9,1,minecraft:vine[east=true,north=false,south=false,up=false,west=false])
B(7,10,1,minecraft:vine[east=true,north=false,south=false,up=false,west=false])
B(7,11,1,minecraft:vine[east=true,north=false,south=false,up=false,west=false])
B(7,12,1,minecraft:vine[east=true,north=false,south=false,up=false,west=false])
B(7,3,2,minecraft:smooth_stone_slab[type=top,waterlogged=false])
B(7,4,2,minecraft:jungle_leaves[distance=7,persistent=true])
B(7,6,2,minecraft:smooth_stone_slab[type=top,waterlogged=false])
B(7,7,2,minecraft:jungle_leaves[distance=7,persistent=true])
B(7,3,3,minecraft:smooth_stone_slab[type=top,waterlogged=false])
B(7,4,3,minecraft:jungle_leaves[distance=7,persistent=true])
B(7,6,3,minecraft:smooth_stone_slab[type=top,waterlogged=false])
B(7,7,3,minecraft:jungle_leaves[distance=7,persistent=true])
B(7,3,4,minecraft:smooth_stone_slab[type=top,waterlogged=false])
B(7,4,4,minecraft:stone_brick_slab)
B(7,6,4,minecraft:jungle_leaves[distance=7,persistent=true])
B(7,7,4,minecraft:jungle_leaves[distance=7,persistent=true])
B(7,3,5,minecraft:smooth_stone_slab[type=top,waterlogged=false])
B(7,4,5,minecraft:jungle_leaves[distance=7,persistent=true])
B(7,6,5,minecraft:smooth_stone_slab[type=top,waterlogged=false])
B(7,7,5,minecraft:jungle_leaves[distance=7,persistent=true])
B(7,1,6,minecraft:jungle_leaves[distance=7,persistent=true])
B(7,3,6,minecraft:smooth_stone_slab[type=top,waterlogged=false])
B(7,4,6,minecraft:jungle_leaves[distance=7,persistent=true])
B(7,6,6,minecraft:smooth_stone_slab[type=top,waterlogged=false])
B(7,7,6,minecraft:vine[east=false,north=true,south=false,up=false,west=false])
B(7,3,7,minecraft:smooth_stone_slab[type=top,waterlogged=false])
B(7,4,7,minecraft:stone_brick_stairs[facing=east,half=bottom,shape=straight,waterlogged=false])
B(7,6,7,minecraft:stone_brick_stairs[facing=east,half=top,shape=straight,waterlogged=false])
B(7,1,8,minecraft:jungle_leaves[distance=7,persistent=true])
B(7,3,8,minecraft:smooth_stone_slab[type=top,waterlogged=false])
B(7,4,8,minecraft:jungle_leaves[distance=7,persistent=true])
B(7,5,8,minecraft:jungle_leaves[distance=7,persistent=true])
B(7,6,8,minecraft:smooth_stone_slab[type=top,waterlogged=false])
B(8,7,-7,minecraft:stone_brick_stairs[facing=east,half=bottom,shape=straight,waterlogged=false])
B(8,10,-7,minecraft:stone_brick_stairs[facing=east,half=top,shape=straight,waterlogged=false])
B(8,11,-7,minecraft:stone_brick_stairs[facing=east,half=bottom,shape=straight,waterlogged=false])
B(8,1,-6,minecraft:jungle_leaves[distance=7,persistent=true])
B(8,4,-6,minecraft:jungle_leaves[distance=7,persistent=true])
B(8,7,-6,minecraft:jungle_leaves[distance=7,persistent=true])
B(8,10,-6,minecraft:smooth_stone_slab[type=top,waterlogged=false])
B(8,11,-6,minecraft:vine[east=true,north=false,south=false,up=false,west=false])
B(8,7,-5,minecraft:stone_brick_stairs[facing=east,half=bottom,shape=straight,waterlogged=false])
B(8,8,-5,minecraft:vine[east=true,north=false,south=false,up=false,west=false])
B(8,9,-5,minecraft:vine[east=true,north=false,south=false,up=false,west=false])
B(8,10,-5,minecraft:vine[east=true,north=false,south=false,up=false,west=false])
B(8,4,-4,minecraft:jungle_leaves[distance=7,persistent=true])
B(8,7,-4,minecraft:jungle_leaves[distance=7,persistent=true])
B(8,10,-4,minecraft:smooth_stone_slab[type=top,waterlogged=false])
B(8,11,-4,minecraft:vine[east=true,north=false,south=false,up=false,west=false])
B(8,7,-3,minecraft:jungle_leaves[distance=7,persistent=true])
B(8,10,-3,minecraft:smooth_stone_slab[type=top,waterlogged=false])
B(8,8,-2,minecraft:stone_brick_stairs[facing=east,half=bottom,shape=straight,waterlogged=false])
B(8,7,-1,minecraft:stone_brick_stairs[facing=east,half=bottom,shape=straight,waterlogged=false])
B(8,7,0,minecraft:stone_brick_slab)
B(8,8,0,minecraft:vine[east=false,north=false,south=true,up=false,west=false])
B(8,9,0,minecraft:vine[east=false,north=false,south=true,up=false,west=false])
B(8,10,0,minecraft:vine[east=false,north=false,south=true,up=false,west=false])
B(8,11,0,minecraft:vine[east=false,north=false,south=true,up=false,west=false])
B(8,12,0,minecraft:vine[east=false,north=false,south=true,up=false,west=false])
B(8,8,1,minecraft:stone_brick_stairs[facing=east,half=bottom,shape=straight,waterlogged=false])
B(8,9,1,minecraft:jungle_leaves[distance=7,persistent=true])
B(8,10,1,minecraft:jungle_leaves[distance=7,persistent=true])
B(8,11,1,minecraft:jungle_leaves[distance=7,persistent=true])
B(8,12,1,minecraft:jungle_leaves[distance=7,persistent=true])
B(8,4,2,minecraft:jungle_leaves[distance=7,persistent=true])
B(8,5,2,minecraft:jungle_leaves[distance=7,persistent=true])
B(8,7,2,minecraft:jungle_leaves[distance=7,persistent=true])
B(8,8,2,minecraft:vine[east=false,north=true,south=false,up=false,west=false])
B(8,9,2,minecraft:vine[east=false,north=true,south=false,up=false,west=false])
B(8,10,2,minecraft:smooth_stone_slab[type=top,waterlogged=false])
B(8,11,2,minecraft:vine[east=true,north=true,south=false,up=false,west=false])
B(8,4,3,minecraft:jungle_leaves[distance=7,persistent=true])
B(8,5,3,minecraft:jungle_leaves[distance=7,persistent=true])
B(8,8,3,minecraft:jungle_leaves[distance=7,persistent=true])
B(8,9,3,minecraft:jungle_leaves[distance=7,persistent=true])
B(8,10,3,minecraft:jungle_leaves[distance=7,persistent=true])
B(8,7,4,minecraft:stone_brick_stairs[facing=east,half=bottom,shape=straight,waterlogged=false])
B(8,10,4,minecraft:stone_brick_stairs[facing=east,half=top,shape=straight,waterlogged=false])
B(8,11,4,minecraft:stone_brick_stairs[facing=east,half=bottom,shape=straight,waterlogged=false])
B(8,10,5,minecraft:smooth_stone_slab[type=top,waterlogged=false])
B(8,4,6,minecraft:jungle_leaves[distance=7,persistent=true])
B(8,5,6,minecraft:jungle_leaves[distance=7,persistent=true])
B(8,7,6,minecraft:stone_brick_slab)
B(8,1,7,minecraft:jungle_leaves[distance=7,persistent=true])
B(8,3,8,minecraft:smooth_stone_slab[type=top,waterlogged=false])
B(8,4,8,minecraft:stone_brick_stairs)
B(8,6,8,minecraft:stone_brick_stairs[facing=north,half=top,shape=straight,waterlogged=false])
B(8,7,8,minecraft:jungle_leaves[distance=7,persistent=true])
RB(4,-1,-7,minecraft:mossy_stone_bricks,10,minecraft:cracked_stone_bricks,10,minecraft:cobblestone,10,minecraft:mossy_cobblestone,10,minecraft:stone_bricks,100)
RB(5,-1,-7,minecraft:mossy_stone_bricks,10,minecraft:cracked_stone_bricks,10,minecraft:cobblestone,10,minecraft:mossy_cobblestone,10,minecraft:stone_bricks,100)
RB(6,-1,-7,minecraft:mossy_stone_bricks,10,minecraft:cracked_stone_bricks,10,minecraft:cobblestone,10,minecraft:mossy_cobblestone,10,minecraft:stone_bricks,100)
RB(7,-1,-7,minecraft:mossy_stone_bricks,10,minecraft:cracked_stone_bricks,10,minecraft:cobblestone,10,minecraft:mossy_cobblestone,10,minecraft:stone_bricks,100)
RB(8,-1,-7,minecraft:mossy_stone_bricks,10,minecraft:cracked_stone_bricks,10,minecraft:cobblestone,10,minecraft:mossy_cobblestone,10,minecraft:stone_bricks,100)
RB(4,-1,-6,minecraft:mossy_stone_bricks,10,minecraft:cracked_stone_bricks,10,minecraft:cobblestone,10,minecraft:mossy_cobblestone,10,minecraft:stone_bricks,100)
RB(5,-1,-6,minecraft:mossy_stone_bricks,10,minecraft:cracked_stone_bricks,10,minecraft:cobblestone,10,minecraft:mossy_cobblestone,10,minecraft:stone_bricks,100)
RB(6,-1,-6,minecraft:mossy_stone_bricks,10,minecraft:cracked_stone_bricks,10,minecraft:cobblestone,10,minecraft:mossy_cobblestone,10,minecraft:stone_bricks,100)
RB(7,-1,-6,minecraft:mossy_stone_bricks,10,minecraft:cracked_stone_bricks,10,minecraft:cobblestone,10,minecraft:mossy_cobblestone,10,minecraft:stone_bricks,100)
RB(8,-1,-6,minecraft:mossy_stone_bricks,10,minecraft:cracked_stone_bricks,10,minecraft:cobblestone,10,minecraft:mossy_cobblestone,10,minecraft:stone_bricks,100)
RB(5,-1,-5,minecraft:mossy_stone_bricks,10,minecraft:cracked_stone_bricks,10,minecraft:cobblestone,10,minecraft:mossy_cobblestone,10,minecraft:stone_bricks,100)
RB(6,-1,-5,minecraft:mossy_stone_bricks,10,minecraft:cracked_stone_bricks,10,minecraft:cobblestone,10,minecraft:mossy_cobblestone,10,minecraft:stone_bricks,100)
RB(7,-1,-5,minecraft:mossy_stone_bricks,10,minecraft:cracked_stone_bricks,10,minecraft:cobblestone,10,minecraft:mossy_cobblestone,10,minecraft:stone_bricks,100)
RB(8,-1,-5,minecraft:mossy_stone_bricks,10,minecraft:cracked_stone_bricks,10,minecraft:cobblestone,10,minecraft:mossy_cobblestone,10,minecraft:stone_bricks,100)
RB(4,-1,-4,minecraft:mossy_stone_bricks,10,minecraft:cracked_stone_bricks,10,minecraft:cobblestone,10,minecraft:mossy_cobblestone,10,minecraft:stone_bricks,100)
RB(5,-1,-4,minecraft:mossy_stone_bricks,10,minecraft:cracked_stone_bricks,10,minecraft:cobblestone,10,minecraft:mossy_cobblestone,10,minecraft:stone_bricks,100)
RB(6,-1,-4,minecraft:mossy_stone_bricks,10,minecraft:cracked_stone_bricks,10,minecraft:cobblestone,10,minecraft:mossy_cobblestone,10,minecraft:stone_bricks,100)
RB(7,-1,-4,minecraft:mossy_stone_bricks,10,minecraft:cracked_stone_bricks,10,minecraft:cobblestone,10,minecraft:mossy_cobblestone,10,minecraft:stone_bricks,100)
RB(8,-1,-4,minecraft:mossy_stone_bricks,10,minecraft:cracked_stone_bricks,10,minecraft:cobblestone,10,minecraft:mossy_cobblestone,10,minecraft:stone_bricks,100)
RB(4,-1,-3,minecraft:mossy_stone_bricks,10,minecraft:cracked_stone_bricks,10,minecraft:cobblestone,10,minecraft:mossy_cobblestone,10,minecraft:stone_bricks,100)
RB(5,-1,-3,minecraft:mossy_stone_bricks,10,minecraft:cracked_stone_bricks,10,minecraft:cobblestone,10,minecraft:mossy_cobblestone,10,minecraft:stone_bricks,100)
RB(6,-1,-3,minecraft:mossy_stone_bricks,10,minecraft:cracked_stone_bricks,10,minecraft:cobblestone,10,minecraft:mossy_cobblestone,10,minecraft:stone_bricks,100)
RB(7,-1,-3,minecraft:mossy_stone_bricks,10,minecraft:cracked_stone_bricks,10,minecraft:cobblestone,10,minecraft:mossy_cobblestone,10,minecraft:stone_bricks,100)
RB(8,-1,-3,minecraft:mossy_stone_bricks,10,minecraft:cracked_stone_bricks,10,minecraft:cobblestone,10,minecraft:mossy_cobblestone,10,minecraft:stone_bricks,100)
RB(0,-1,-2,minecraft:mossy_stone_bricks,10,minecraft:cracked_stone_bricks,10,minecraft:cobblestone,10,minecraft:mossy_cobblestone,10,minecraft:stone_bricks,100)
RB(1,-1,-2,minecraft:mossy_stone_bricks,10,minecraft:cracked_stone_bricks,10,minecraft:cobblestone,10,minecraft:mossy_cobblestone,10,minecraft:stone_bricks,100)
RB(2,-1,-2,minecraft:mossy_stone_bricks,10,minecraft:cracked_stone_bricks,10,minecraft:cobblestone,10,minecraft:mossy_cobblestone,10,minecraft:stone_bricks,100)
RB(3,-1,-2,minecraft:mossy_stone_bricks,10,minecraft:cracked_stone_bricks,10,minecraft:cobblestone,10,minecraft:mossy_cobblestone,10,minecraft:stone_bricks,100)
RB(4,-1,-2,minecraft:mossy_stone_bricks,10,minecraft:cracked_stone_bricks,10,minecraft:cobblestone,10,minecraft:mossy_cobblestone,10,minecraft:stone_bricks,100)
RB(5,-1,-2,minecraft:mossy_stone_bricks,10,minecraft:cracked_stone_bricks,10,minecraft:cobblestone,10,minecraft:mossy_cobblestone,10,minecraft:stone_bricks,100)
RB(6,-1,-2,minecraft:mossy_stone_bricks,10,minecraft:cracked_stone_bricks,10,minecraft:cobblestone,10,minecraft:mossy_cobblestone,10,minecraft:stone_bricks,100)
RB(7,-1,-2,minecraft:mossy_stone_bricks,10,minecraft:cracked_stone_bricks,10,minecraft:cobblestone,10,minecraft:mossy_cobblestone,10,minecraft:stone_bricks,100)
RB(8,-1,-2,minecraft:mossy_stone_bricks,10,minecraft:cracked_stone_bricks,10,minecraft:cobblestone,10,minecraft:mossy_cobblestone,10,minecraft:stone_bricks,100)
RB(1,-1,-1,minecraft:mossy_stone_bricks,10,minecraft:cracked_stone_bricks,10,minecraft:cobblestone,10,minecraft:mossy_cobblestone,10,minecraft:stone_bricks,100)
RB(2,-1,-1,minecraft:mossy_stone_bricks,10,minecraft:cracked_stone_bricks,10,minecraft:cobblestone,10,minecraft:mossy_cobblestone,10,minecraft:stone_bricks,100)
RB(3,-1,-1,minecraft:mossy_stone_bricks,10,minecraft:cracked_stone_bricks,10,minecraft:cobblestone,10,minecraft:mossy_cobblestone,10,minecraft:stone_bricks,100)
RB(4,-1,-1,minecraft:mossy_stone_bricks,10,minecraft:cracked_stone_bricks,10,minecraft:cobblestone,10,minecraft:mossy_cobblestone,10,minecraft:stone_bricks,100)
RB(5,-1,-1,minecraft:mossy_stone_bricks,10,minecraft:cracked_stone_bricks,10,minecraft:cobblestone,10,minecraft:mossy_cobblestone,10,minecraft:stone_bricks,100)
RB(6,-1,-1,minecraft:mossy_stone_bricks,10,minecraft:cracked_stone_bricks,10,minecraft:cobblestone,10,minecraft:mossy_cobblestone,10,minecraft:stone_bricks,100)
RB(7,-1,-1,minecraft:mossy_stone_bricks,10,minecraft:cracked_stone_bricks,10,minecraft:cobblestone,10,minecraft:mossy_cobblestone,10,minecraft:stone_bricks,100)
RB(8,-1,-1,minecraft:mossy_stone_bricks,10,minecraft:cracked_stone_bricks,10,minecraft:cobblestone,10,minecraft:mossy_cobblestone,10,minecraft:stone_bricks,100)
RB(1,-1,0,minecraft:mossy_stone_bricks,10,minecraft:cracked_stone_bricks,10,minecraft:cobblestone,10,minecraft:mossy_cobblestone,10,minecraft:stone_bricks,100)
RB(2,-1,0,minecraft:mossy_stone_bricks,10,minecraft:cracked_stone_bricks,10,minecraft:cobblestone,10,minecraft:mossy_cobblestone,10,minecraft:stone_bricks,100)
RB(3,-1,0,minecraft:mossy_stone_bricks,10,minecraft:cracked_stone_bricks,10,minecraft:cobblestone,10,minecraft:mossy_cobblestone,10,minecraft:stone_bricks,100)
RB(4,-1,0,minecraft:mossy_stone_bricks,10,minecraft:cracked_stone_bricks,10,minecraft:cobblestone,10,minecraft:mossy_cobblestone,10,minecraft:stone_bricks,100)
RB(5,-1,0,minecraft:mossy_stone_bricks,10,minecraft:cracked_stone_bricks,10,minecraft:cobblestone,10,minecraft:mossy_cobblestone,10,minecraft:stone_bricks,100)
RB(6,-1,0,minecraft:mossy_stone_bricks,10,minecraft:cracked_stone_bricks,10,minecraft:cobblestone,10,minecraft:mossy_cobblestone,10,minecraft:stone_bricks,100)
RB(7,-1,0,minecraft:mossy_stone_bricks,10,minecraft:cracked_stone_bricks,10,minecraft:cobblestone,10,minecraft:mossy_cobblestone,10,minecraft:stone_bricks,100)
RB(8,-1,0,minecraft:mossy_stone_bricks,10,minecraft:cracked_stone_bricks,10,minecraft:cobblestone,10,minecraft:mossy_cobblestone,10,minecraft:stone_bricks,100)
RB(0,-1,1,minecraft:mossy_stone_bricks,10,minecraft:cracked_stone_bricks,10,minecraft:cobblestone,10,minecraft:mossy_cobblestone,10,minecraft:stone_bricks,100)
RB(1,-1,1,minecraft:mossy_stone_bricks,10,minecraft:cracked_stone_bricks,10,minecraft:cobblestone,10,minecraft:mossy_cobblestone,10,minecraft:stone_bricks,100)
RB(4,-1,1,minecraft:mossy_stone_bricks,10,minecraft:cracked_stone_bricks,10,minecraft:cobblestone,10,minecraft:mossy_cobblestone,10,minecraft:stone_bricks,100)
RB(5,-1,1,minecraft:mossy_stone_bricks,10,minecraft:cracked_stone_bricks,10,minecraft:cobblestone,10,minecraft:mossy_cobblestone,10,minecraft:stone_bricks,100)
RB(6,-1,1,minecraft:mossy_stone_bricks,10,minecraft:cracked_stone_bricks,10,minecraft:cobblestone,10,minecraft:mossy_cobblestone,10,minecraft:stone_bricks,100)
RB(7,-1,1,minecraft:mossy_stone_bricks,10,minecraft:cracked_stone_bricks,10,minecraft:cobblestone,10,minecraft:mossy_cobblestone,10,minecraft:stone_bricks,100)
RB(8,-1,1,minecraft:mossy_stone_bricks,10,minecraft:cracked_stone_bricks,10,minecraft:cobblestone,10,minecraft:mossy_cobblestone,10,minecraft:stone_bricks,100)
RB(4,-1,2,minecraft:mossy_stone_bricks,10,minecraft:cracked_stone_bricks,10,minecraft:cobblestone,10,minecraft:mossy_cobblestone,10,minecraft:stone_bricks,100)
RB(5,-1,2,minecraft:mossy_stone_bricks,10,minecraft:cracked_stone_bricks,10,minecraft:cobblestone,10,minecraft:mossy_cobblestone,10,minecraft:stone_bricks,100)
RB(6,-1,2,minecraft:mossy_stone_bricks,10,minecraft:cracked_stone_bricks,10,minecraft:cobblestone,10,minecraft:mossy_cobblestone,10,minecraft:stone_bricks,100)
RB(7,-1,2,minecraft:mossy_stone_bricks,10,minecraft:cracked_stone_bricks,10,minecraft:cobblestone,10,minecraft:mossy_cobblestone,10,minecraft:stone_bricks,100)
RB(8,-1,2,minecraft:mossy_stone_bricks,10,minecraft:cracked_stone_bricks,10,minecraft:cobblestone,10,minecraft:mossy_cobblestone,10,minecraft:stone_bricks,100)
RB(4,-1,3,minecraft:mossy_stone_bricks,10,minecraft:cracked_stone_bricks,10,minecraft:cobblestone,10,minecraft:mossy_cobblestone,10,minecraft:stone_bricks,100)
RB(5,-1,3,minecraft:mossy_stone_bricks,10,minecraft:cracked_stone_bricks,10,minecraft:cobblestone,10,minecraft:mossy_cobblestone,10,minecraft:stone_bricks,100)
RB(6,-1,3,minecraft:mossy_stone_bricks,10,minecraft:cracked_stone_bricks,10,minecraft:cobblestone,10,minecraft:mossy_cobblestone,10,minecraft:stone_bricks,100)
RB(7,-1,3,minecraft:mossy_stone_bricks,10,minecraft:cracked_stone_bricks,10,minecraft:cobblestone,10,minecraft:mossy_cobblestone,10,minecraft:stone_bricks,100)
RB(8,-1,3,minecraft:mossy_stone_bricks,10,minecraft:cracked_stone_bricks,10,minecraft:cobblestone,10,minecraft:mossy_cobblestone,10,minecraft:stone_bricks,100)
RB(4,-1,4,minecraft:mossy_stone_bricks,10,minecraft:cracked_stone_bricks,10,minecraft:cobblestone,10,minecraft:mossy_cobblestone,10,minecraft:stone_bricks,100)
RB(5,-1,4,minecraft:mossy_stone_bricks,10,minecraft:cracked_stone_bricks,10,minecraft:cobblestone,10,minecraft:mossy_cobblestone,10,minecraft:stone_bricks,100)
RB(6,-1,4,minecraft:mossy_stone_bricks,10,minecraft:cracked_stone_bricks,10,minecraft:cobblestone,10,minecraft:mossy_cobblestone,10,minecraft:stone_bricks,100)
RB(7,-1,4,minecraft:mossy_stone_bricks,10,minecraft:cracked_stone_bricks,10,minecraft:cobblestone,10,minecraft:mossy_cobblestone,10,minecraft:stone_bricks,100)
RB(8,-1,4,minecraft:mossy_stone_bricks,10,minecraft:cracked_stone_bricks,10,minecraft:cobblestone,10,minecraft:mossy_cobblestone,10,minecraft:stone_bricks,100)
RB(4,-1,5,minecraft:mossy_stone_bricks,10,minecraft:cracked_stone_bricks,10,minecraft:cobblestone,10,minecraft:mossy_cobblestone,10,minecraft:stone_bricks,100)
RB(5,-1,5,minecraft:mossy_stone_bricks,10,minecraft:cracked_stone_bricks,10,minecraft:cobblestone,10,minecraft:mossy_cobblestone,10,minecraft:stone_bricks,100)
RB(6,-1,5,minecraft:mossy_stone_bricks,10,minecraft:cracked_stone_bricks,10,minecraft:cobblestone,10,minecraft:mossy_cobblestone,10,minecraft:stone_bricks,100)
RB(7,-1,5,minecraft:mossy_stone_bricks,10,minecraft:cracked_stone_bricks,10,minecraft:cobblestone,10,minecraft:mossy_cobblestone,10,minecraft:stone_bricks,100)
RB(8,-1,5,minecraft:mossy_stone_bricks,10,minecraft:cracked_stone_bricks,10,minecraft:cobblestone,10,minecraft:mossy_cobblestone,10,minecraft:stone_bricks,100)
RB(4,-1,6,minecraft:mossy_stone_bricks,10,minecraft:cracked_stone_bricks,10,minecraft:cobblestone,10,minecraft:mossy_cobblestone,10,minecraft:stone_bricks,100)
RB(5,-1,6,minecraft:mossy_stone_bricks,10,minecraft:cracked_stone_bricks,10,minecraft:cobblestone,10,minecraft:mossy_cobblestone,10,minecraft:stone_bricks,100)
RB(6,-1,6,minecraft:mossy_stone_bricks,10,minecraft:cracked_stone_bricks,10,minecraft:cobblestone,10,minecraft:mossy_cobblestone,10,minecraft:stone_bricks,100)
RB(7,-1,6,minecraft:mossy_stone_bricks,10,minecraft:cracked_stone_bricks,10,minecraft:cobblestone,10,minecraft:mossy_cobblestone,10,minecraft:stone_bricks,100)
RB(8,-1,6,minecraft:mossy_stone_bricks,10,minecraft:cracked_stone_bricks,10,minecraft:cobblestone,10,minecraft:mossy_cobblestone,10,minecraft:stone_bricks,100)
RB(4,-1,7,minecraft:mossy_stone_bricks,10,minecraft:cracked_stone_bricks,10,minecraft:cobblestone,10,minecraft:mossy_cobblestone,10,minecraft:stone_bricks,100)
RB(5,-1,7,minecraft:mossy_stone_bricks,10,minecraft:cracked_stone_bricks,10,minecraft:cobblestone,10,minecraft:mossy_cobblestone,10,minecraft:stone_bricks,100)
RB(6,-1,7,minecraft:mossy_stone_bricks,10,minecraft:cracked_stone_bricks,10,minecraft:cobblestone,10,minecraft:mossy_cobblestone,10,minecraft:stone_bricks,100)
RB(7,-1,7,minecraft:mossy_stone_bricks,10,minecraft:cracked_stone_bricks,10,minecraft:cobblestone,10,minecraft:mossy_cobblestone,10,minecraft:stone_bricks,100)
RB(8,-1,7,minecraft:mossy_stone_bricks,10,minecraft:cracked_stone_bricks,10,minecraft:cobblestone,10,minecraft:mossy_cobblestone,10,minecraft:stone_bricks,100)
RB(5,-1,8,minecraft:mossy_stone_bricks,10,minecraft:cracked_stone_bricks,10,minecraft:cobblestone,10,minecraft:mossy_cobblestone,10,minecraft:stone_bricks,100)
RB(6,-1,8,minecraft:mossy_stone_bricks,10,minecraft:cracked_stone_bricks,10,minecraft:cobblestone,10,minecraft:mossy_cobblestone,10,minecraft:stone_bricks,100)
RB(7,-1,8,minecraft:mossy_stone_bricks,10,minecraft:cracked_stone_bricks,10,minecraft:cobblestone,10,minecraft:mossy_cobblestone,10,minecraft:stone_bricks,100)
RB(8,-1,8,minecraft:mossy_stone_bricks,10,minecraft:cracked_stone_bricks,10,minecraft:cobblestone,10,minecraft:mossy_cobblestone,10,minecraft:stone_bricks,100)
RB(5,0,-7,minecraft:mossy_stone_bricks,10,minecraft:cracked_stone_bricks,10,minecraft:cobblestone,10,minecraft:mossy_cobblestone,10,minecraft:stone_bricks,100)
RB(6,0,-7,minecraft:mossy_stone_bricks,10,minecraft:cracked_stone_bricks,10,minecraft:cobblestone,10,minecraft:mossy_cobblestone,10,minecraft:stone_bricks,100)
RB(7,0,-7,minecraft:mossy_stone_bricks,10,minecraft:cracked_stone_bricks,10,minecraft:cobblestone,10,minecraft:mossy_cobblestone,10,minecraft:stone_bricks,100)
RB(8,0,-7,minecraft:mossy_stone_bricks,10,minecraft:cracked_stone_bricks,10,minecraft:cobblestone,10,minecraft:mossy_cobblestone,10,minecraft:stone_bricks,100)
RB(5,0,-6,minecraft:mossy_stone_bricks,10,minecraft:cracked_stone_bricks,10,minecraft:cobblestone,10,minecraft:mossy_cobblestone,10,minecraft:stone_bricks,100)
RB(6,0,-6,minecraft:mossy_stone_bricks,10,minecraft:cracked_stone_bricks,10,minecraft:cobblestone,10,minecraft:mossy_cobblestone,10,minecraft:stone_bricks,100)
RB(7,0,-6,minecraft:mossy_stone_bricks,10,minecraft:cracked_stone_bricks,10,minecraft:cobblestone,10,minecraft:mossy_cobblestone,10,minecraft:stone_bricks,100)
RB(8,0,-6,minecraft:mossy_stone_bricks,10,minecraft:cracked_stone_bricks,10,minecraft:cobblestone,10,minecraft:mossy_cobblestone,10,minecraft:stone_bricks,100)
RB(5,0,-5,minecraft:mossy_stone_bricks,10,minecraft:cracked_stone_bricks,10,minecraft:cobblestone,10,minecraft:mossy_cobblestone,10,minecraft:stone_bricks,100)
RB(6,0,-5,minecraft:mossy_stone_bricks,10,minecraft:cracked_stone_bricks,10,minecraft:cobblestone,10,minecraft:mossy_cobblestone,10,minecraft:stone_bricks,100)
RB(7,0,-5,minecraft:mossy_stone_bricks,10,minecraft:cracked_stone_bricks,10,minecraft:cobblestone,10,minecraft:mossy_cobblestone,10,minecraft:stone_bricks,100)
RB(8,0,-5,minecraft:mossy_stone_bricks,10,minecraft:cracked_stone_bricks,10,minecraft:cobblestone,10,minecraft:mossy_cobblestone,10,minecraft:stone_bricks,100)
RB(5,0,-4,minecraft:mossy_stone_bricks,10,minecraft:cracked_stone_bricks,10,minecraft:cobblestone,10,minecraft:mossy_cobblestone,10,minecraft:stone_bricks,100)
RB(6,0,-4,minecraft:mossy_stone_bricks,10,minecraft:cracked_stone_bricks,10,minecraft:cobblestone,10,minecraft:mossy_cobblestone,10,minecraft:stone_bricks,100)
RB(7,0,-4,minecraft:mossy_stone_bricks,10,minecraft:cracked_stone_bricks,10,minecraft:cobblestone,10,minecraft:mossy_cobblestone,10,minecraft:stone_bricks,100)
RB(8,0,-4,minecraft:mossy_stone_bricks,10,minecraft:cracked_stone_bricks,10,minecraft:cobblestone,10,minecraft:mossy_cobblestone,10,minecraft:stone_bricks,100)
RB(5,0,-3,minecraft:mossy_stone_bricks,10,minecraft:cracked_stone_bricks,10,minecraft:cobblestone,10,minecraft:mossy_cobblestone,10,minecraft:stone_bricks,100)
RB(6,0,-3,minecraft:mossy_stone_bricks,10,minecraft:cracked_stone_bricks,10,minecraft:cobblestone,10,minecraft:mossy_cobblestone,10,minecraft:stone_bricks,100)
RB(7,0,-3,minecraft:mossy_stone_bricks,10,minecraft:cracked_stone_bricks,10,minecraft:cobblestone,10,minecraft:mossy_cobblestone,10,minecraft:stone_bricks,100)
RB(8,0,-3,minecraft:mossy_stone_bricks,10,minecraft:cracked_stone_bricks,10,minecraft:cobblestone,10,minecraft:mossy_cobblestone,10,minecraft:stone_bricks,100)
RB(1,0,-2,minecraft:mossy_stone_bricks,10,minecraft:cracked_stone_bricks,10,minecraft:cobblestone,10,minecraft:mossy_cobblestone,10,minecraft:stone_bricks,100)
RB(2,0,-2,minecraft:mossy_stone_bricks,10,minecraft:cracked_stone_bricks,10,minecraft:cobblestone,10,minecraft:mossy_cobblestone,10,minecraft:stone_bricks,100)
RB(3,0,-2,minecraft:mossy_stone_bricks,10,minecraft:cracked_stone_bricks,10,minecraft:cobblestone,10,minecraft:mossy_cobblestone,10,minecraft:stone_bricks,100)
RB(4,0,-2,minecraft:mossy_stone_bricks,10,minecraft:cracked_stone_bricks,10,minecraft:cobblestone,10,minecraft:mossy_cobblestone,10,minecraft:stone_bricks,100)
RB(5,0,-2,minecraft:mossy_stone_bricks,10,minecraft:cracked_stone_bricks,10,minecraft:cobblestone,10,minecraft:mossy_cobblestone,10,minecraft:stone_bricks,100)
RB(6,0,-2,minecraft:mossy_stone_bricks,10,minecraft:cracked_stone_bricks,10,minecraft:cobblestone,10,minecraft:mossy_cobblestone,10,minecraft:stone_bricks,100)
RB(7,0,-2,minecraft:mossy_stone_bricks,10,minecraft:cracked_stone_bricks,10,minecraft:cobblestone,10,minecraft:mossy_cobblestone,10,minecraft:stone_bricks,100)
RB(8,0,-2,minecraft:mossy_stone_bricks,10,minecraft:cracked_stone_bricks,10,minecraft:cobblestone,10,minecraft:mossy_cobblestone,10,minecraft:stone_bricks,100)
RB(2,0,-1,minecraft:mossy_stone_bricks,10,minecraft:cracked_stone_bricks,10,minecraft:cobblestone,10,minecraft:mossy_cobblestone,10,minecraft:stone_bricks,100)
RB(3,0,-1,minecraft:mossy_stone_bricks,10,minecraft:cracked_stone_bricks,10,minecraft:cobblestone,10,minecraft:mossy_cobblestone,10,minecraft:stone_bricks,100)
RB(4,0,-1,minecraft:mossy_stone_bricks,10,minecraft:cracked_stone_bricks,10,minecraft:cobblestone,10,minecraft:mossy_cobblestone,10,minecraft:stone_bricks,100)
RB(5,0,-1,minecraft:mossy_stone_bricks,10,minecraft:cracked_stone_bricks,10,minecraft:cobblestone,10,minecraft:mossy_cobblestone,10,minecraft:stone_bricks,100)
RB(6,0,-1,minecraft:mossy_stone_bricks,10,minecraft:cracked_stone_bricks,10,minecraft:cobblestone,10,minecraft:mossy_cobblestone,10,minecraft:stone_bricks,100)
RB(7,0,-1,minecraft:mossy_stone_bricks,10,minecraft:cracked_stone_bricks,10,minecraft:cobblestone,10,minecraft:mossy_cobblestone,10,minecraft:stone_bricks,100)
RB(8,0,-1,minecraft:mossy_stone_bricks,10,minecraft:cracked_stone_bricks,10,minecraft:cobblestone,10,minecraft:mossy_cobblestone,10,minecraft:stone_bricks,100)
RB(2,0,0,minecraft:mossy_stone_bricks,10,minecraft:cracked_stone_bricks,10,minecraft:cobblestone,10,minecraft:mossy_cobblestone,10,minecraft:stone_bricks,100)
RB(3,0,0,minecraft:mossy_stone_bricks,10,minecraft:cracked_stone_bricks,10,minecraft:cobblestone,10,minecraft:mossy_cobblestone,10,minecraft:stone_bricks,100)
RB(4,0,0,minecraft:mossy_stone_bricks,10,minecraft:cracked_stone_bricks,10,minecraft:cobblestone,10,minecraft:mossy_cobblestone,10,minecraft:stone_bricks,100)
RB(5,0,0,minecraft:mossy_stone_bricks,10,minecraft:cracked_stone_bricks,10,minecraft:cobblestone,10,minecraft:mossy_cobblestone,10,minecraft:stone_bricks,100)
RB(6,0,0,minecraft:mossy_stone_bricks,10,minecraft:cracked_stone_bricks,10,minecraft:cobblestone,10,minecraft:mossy_cobblestone,10,minecraft:stone_bricks,100)
RB(7,0,0,minecraft:mossy_stone_bricks,10,minecraft:cracked_stone_bricks,10,minecraft:cobblestone,10,minecraft:mossy_cobblestone,10,minecraft:stone_bricks,100)
RB(8,0,0,minecraft:mossy_stone_bricks,10,minecraft:cracked_stone_bricks,10,minecraft:cobblestone,10,minecraft:mossy_cobblestone,10,minecraft:stone_bricks,100)
RB(1,0,1,minecraft:mossy_stone_bricks,10,minecraft:cracked_stone_bricks,10,minecraft:cobblestone,10,minecraft:mossy_cobblestone,10,minecraft:stone_bricks,100)
RB(4,0,1,minecraft:mossy_stone_bricks,10,minecraft:cracked_stone_bricks,10,minecraft:cobblestone,10,minecraft:mossy_cobblestone,10,minecraft:stone_bricks,100)
RB(5,0,1,minecraft:mossy_stone_bricks,10,minecraft:cracked_stone_bricks,10,minecraft:cobblestone,10,minecraft:mossy_cobblestone,10,minecraft:stone_bricks,100)
RB(6,0,1,minecraft:mossy_stone_bricks,10,minecraft:cracked_stone_bricks,10,minecraft:cobblestone,10,minecraft:mossy_cobblestone,10,minecraft:stone_bricks,100)
RB(7,0,1,minecraft:mossy_stone_bricks,10,minecraft:cracked_stone_bricks,10,minecraft:cobblestone,10,minecraft:mossy_cobblestone,10,minecraft:stone_bricks,100)
RB(8,0,1,minecraft:mossy_stone_bricks,10,minecraft:cracked_stone_bricks,10,minecraft:cobblestone,10,minecraft:mossy_cobblestone,10,minecraft:stone_bricks,100)
RB(5,0,2,minecraft:mossy_stone_bricks,10,minecraft:cracked_stone_bricks,10,minecraft:cobblestone,10,minecraft:mossy_cobblestone,10,minecraft:stone_bricks,100)
RB(6,0,2,minecraft:mossy_stone_bricks,10,minecraft:cracked_stone_bricks,10,minecraft:cobblestone,10,minecraft:mossy_cobblestone,10,minecraft:stone_bricks,100)
RB(7,0,2,minecraft:mossy_stone_bricks,10,minecraft:cracked_stone_bricks,10,minecraft:cobblestone,10,minecraft:mossy_cobblestone,10,minecraft:stone_bricks,100)
RB(8,0,2,minecraft:mossy_stone_bricks,10,minecraft:cracked_stone_bricks,10,minecraft:cobblestone,10,minecraft:mossy_cobblestone,10,minecraft:stone_bricks,100)
RB(5,0,3,minecraft:mossy_stone_bricks,10,minecraft:cracked_stone_bricks,10,minecraft:cobblestone,10,minecraft:mossy_cobblestone,10,minecraft:stone_bricks,100)
RB(6,0,3,minecraft:mossy_stone_bricks,10,minecraft:cracked_stone_bricks,10,minecraft:cobblestone,10,minecraft:mossy_cobblestone,10,minecraft:stone_bricks,100)
RB(7,0,3,minecraft:mossy_stone_bricks,10,minecraft:cracked_stone_bricks,10,minecraft:cobblestone,10,minecraft:mossy_cobblestone,10,minecraft:stone_bricks,100)
RB(8,0,3,minecraft:mossy_stone_bricks,10,minecraft:cracked_stone_bricks,10,minecraft:cobblestone,10,minecraft:mossy_cobblestone,10,minecraft:stone_bricks,100)
RB(5,0,4,minecraft:mossy_stone_bricks,10,minecraft:cracked_stone_bricks,10,minecraft:cobblestone,10,minecraft:mossy_cobblestone,10,minecraft:stone_bricks,100)
RB(6,0,4,minecraft:mossy_stone_bricks,10,minecraft:cracked_stone_bricks,10,minecraft:cobblestone,10,minecraft:mossy_cobblestone,10,minecraft:stone_bricks,100)
RB(7,0,4,minecraft:mossy_stone_bricks,10,minecraft:cracked_stone_bricks,10,minecraft:cobblestone,10,minecraft:mossy_cobblestone,10,minecraft:stone_bricks,100)
RB(8,0,4,minecraft:mossy_stone_bricks,10,minecraft:cracked_stone_bricks,10,minecraft:cobblestone,10,minecraft:mossy_cobblestone,10,minecraft:stone_bricks,100)
RB(5,0,5,minecraft:mossy_stone_bricks,10,minecraft:cracked_stone_bricks,10,minecraft:cobblestone,10,minecraft:mossy_cobblestone,10,minecraft:stone_bricks,100)
RB(6,0,5,minecraft:mossy_stone_bricks,10,minecraft:cracked_stone_bricks,10,minecraft:cobblestone,10,minecraft:mossy_cobblestone,10,minecraft:stone_bricks,100)
RB(7,0,5,minecraft:mossy_stone_bricks,10,minecraft:cracked_stone_bricks,10,minecraft:cobblestone,10,minecraft:mossy_cobblestone,10,minecraft:stone_bricks,100)
RB(8,0,5,minecraft:mossy_stone_bricks,10,minecraft:cracked_stone_bricks,10,minecraft:cobblestone,10,minecraft:mossy_cobblestone,10,minecraft:stone_bricks,100)
RB(5,0,6,minecraft:mossy_stone_bricks,10,minecraft:cracked_stone_bricks,10,minecraft:cobblestone,10,minecraft:mossy_cobblestone,10,minecraft:stone_bricks,100)
RB(6,0,6,minecraft:mossy_stone_bricks,10,minecraft:cracked_stone_bricks,10,minecraft:cobblestone,10,minecraft:mossy_cobblestone,10,minecraft:stone_bricks,100)
RB(7,0,6,minecraft:mossy_stone_bricks,10,minecraft:cracked_stone_bricks,10,minecraft:cobblestone,10,minecraft:mossy_cobblestone,10,minecraft:stone_bricks,100)
RB(8,0,6,minecraft:mossy_stone_bricks,10,minecraft:cracked_stone_bricks,10,minecraft:cobblestone,10,minecraft:mossy_cobblestone,10,minecraft:stone_bricks,100)
RB(5,0,7,minecraft:mossy_stone_bricks,10,minecraft:cracked_stone_bricks,10,minecraft:cobblestone,10,minecraft:mossy_cobblestone,10,minecraft:stone_bricks,100)
RB(6,0,7,minecraft:mossy_stone_bricks,10,minecraft:cracked_stone_bricks,10,minecraft:cobblestone,10,minecraft:mossy_cobblestone,10,minecraft:stone_bricks,100)
RB(7,0,7,minecraft:mossy_stone_bricks,10,minecraft:cracked_stone_bricks,10,minecraft:cobblestone,10,minecraft:mossy_cobblestone,10,minecraft:stone_bricks,100)
RB(8,0,7,minecraft:mossy_stone_bricks,10,minecraft:cracked_stone_bricks,10,minecraft:cobblestone,10,minecraft:mossy_cobblestone,10,minecraft:stone_bricks,100)
RB(5,0,8,minecraft:mossy_stone_bricks,10,minecraft:cracked_stone_bricks,10,minecraft:cobblestone,10,minecraft:mossy_cobblestone,10,minecraft:stone_bricks,100)
RB(6,0,8,minecraft:mossy_stone_bricks,10,minecraft:cracked_stone_bricks,10,minecraft:cobblestone,10,minecraft:mossy_cobblestone,10,minecraft:stone_bricks,100)
RB(7,0,8,minecraft:mossy_stone_bricks,10,minecraft:cracked_stone_bricks,10,minecraft:cobblestone,10,minecraft:mossy_cobblestone,10,minecraft:stone_bricks,100)
RB(8,0,8,minecraft:mossy_stone_bricks,10,minecraft:cracked_stone_bricks,10,minecraft:cobblestone,10,minecraft:mossy_cobblestone,10,minecraft:stone_bricks,100)
RB(6,1,-7,minecraft:mossy_stone_bricks,10,minecraft:cracked_stone_bricks,10,minecraft:cobblestone,10,minecraft:mossy_cobblestone,10,minecraft:stone_bricks,100)
RB(8,1,-7,minecraft:mossy_stone_bricks,10,minecraft:cracked_stone_bricks,10,minecraft:cobblestone,10,minecraft:mossy_cobblestone,10,minecraft:stone_bricks,100)
RB(6,1,-4,minecraft:mossy_stone_bricks,10,minecraft:cracked_stone_bricks,10,minecraft:cobblestone,10,minecraft:mossy_cobblestone,10,minecraft:stone_bricks,100)
RB(8,1,-4,minecraft:mossy_stone_bricks,10,minecraft:cracked_stone_bricks,10,minecraft:cobblestone,10,minecraft:mossy_cobblestone,10,minecraft:stone_bricks,100)
RB(2,1,-2,minecraft:mossy_stone_bricks,10,minecraft:cracked_stone_bricks,10,minecraft:cobblestone,10,minecraft:mossy_cobblestone,10,minecraft:stone_bricks,100)
RB(3,1,-2,minecraft:mossy_stone_bricks,10,minecraft:cracked_stone_bricks,10,minecraft:cobblestone,10,minecraft:mossy_cobblestone,10,minecraft:stone_bricks,100)
RB(4,1,-2,minecraft:mossy_stone_bricks,10,minecraft:cracked_stone_bricks,10,minecraft:cobblestone,10,minecraft:mossy_cobblestone,10,minecraft:stone_bricks,100)
RB(5,1,-2,minecraft:mossy_stone_bricks,10,minecraft:cracked_stone_bricks,10,minecraft:cobblestone,10,minecraft:mossy_cobblestone,10,minecraft:stone_bricks,100)
RB(6,1,-2,minecraft:mossy_stone_bricks,10,minecraft:cracked_stone_bricks,10,minecraft:cobblestone,10,minecraft:mossy_cobblestone,10,minecraft:stone_bricks,100)
RB(7,1,-2,minecraft:mossy_stone_bricks,10,minecraft:cracked_stone_bricks,10,minecraft:cobblestone,10,minecraft:mossy_cobblestone,10,minecraft:stone_bricks,100)
RB(8,1,-2,minecraft:mossy_stone_bricks,10,minecraft:cracked_stone_bricks,10,minecraft:cobblestone,10,minecraft:mossy_cobblestone,10,minecraft:stone_bricks,100)
RB(3,1,-1,minecraft:mossy_stone_bricks,10,minecraft:cracked_stone_bricks,10,minecraft:cobblestone,10,minecraft:mossy_cobblestone,10,minecraft:stone_bricks,100)
RB(4,1,-1,minecraft:mossy_stone_bricks,10,minecraft:cracked_stone_bricks,10,minecraft:cobblestone,10,minecraft:mossy_cobblestone,10,minecraft:stone_bricks,100)
RB(5,1,-1,minecraft:mossy_stone_bricks,10,minecraft:cracked_stone_bricks,10,minecraft:cobblestone,10,minecraft:mossy_cobblestone,10,minecraft:stone_bricks,100)
RB(6,1,-1,minecraft:mossy_stone_bricks,10,minecraft:cracked_stone_bricks,10,minecraft:cobblestone,10,minecraft:mossy_cobblestone,10,minecraft:stone_bricks,100)
RB(7,1,-1,minecraft:mossy_stone_bricks,10,minecraft:cracked_stone_bricks,10,minecraft:cobblestone,10,minecraft:mossy_cobblestone,10,minecraft:stone_bricks,100)
RB(8,1,-1,minecraft:mossy_stone_bricks,10,minecraft:cracked_stone_bricks,10,minecraft:cobblestone,10,minecraft:mossy_cobblestone,10,minecraft:stone_bricks,100)
RB(3,1,0,minecraft:mossy_stone_bricks,10,minecraft:cracked_stone_bricks,10,minecraft:cobblestone,10,minecraft:mossy_cobblestone,10,minecraft:stone_bricks,100)
RB(4,1,0,minecraft:mossy_stone_bricks,10,minecraft:cracked_stone_bricks,10,minecraft:cobblestone,10,minecraft:mossy_cobblestone,10,minecraft:stone_bricks,100)
RB(5,1,0,minecraft:mossy_stone_bricks,10,minecraft:cracked_stone_bricks,10,minecraft:cobblestone,10,minecraft:mossy_cobblestone,10,minecraft:stone_bricks,100)
RB(6,1,0,minecraft:mossy_stone_bricks,10,minecraft:cracked_stone_bricks,10,minecraft:cobblestone,10,minecraft:mossy_cobblestone,10,minecraft:stone_bricks,100)
RB(7,1,0,minecraft:mossy_stone_bricks,10,minecraft:cracked_stone_bricks,10,minecraft:cobblestone,10,minecraft:mossy_cobblestone,10,minecraft:stone_bricks,100)
RB(8,1,0,minecraft:mossy_stone_bricks,10,minecraft:cracked_stone_bricks,10,minecraft:cobblestone,10,minecraft:mossy_cobblestone,10,minecraft:stone_bricks,100)
RB(2,1,1,minecraft:mossy_stone_bricks,10,minecraft:cracked_stone_bricks,10,minecraft:cobblestone,10,minecraft:mossy_cobblestone,10,minecraft:stone_bricks,100)
RB(5,1,1,minecraft:mossy_stone_bricks,10,minecraft:cracked_stone_bricks,10,minecraft:cobblestone,10,minecraft:mossy_cobblestone,10,minecraft:stone_bricks,100)
RB(6,1,1,minecraft:mossy_stone_bricks,10,minecraft:cracked_stone_bricks,10,minecraft:cobblestone,10,minecraft:mossy_cobblestone,10,minecraft:stone_bricks,100)
RB(7,1,1,minecraft:mossy_stone_bricks,10,minecraft:cracked_stone_bricks,10,minecraft:cobblestone,10,minecraft:mossy_cobblestone,10,minecraft:stone_bricks,100)
RB(8,1,1,minecraft:mossy_stone_bricks,10,minecraft:cracked_stone_bricks,10,minecraft:cobblestone,10,minecraft:mossy_cobblestone,10,minecraft:stone_bricks,100)
RB(6,1,3,minecraft:mossy_stone_bricks,10,minecraft:cracked_stone_bricks,10,minecraft:cobblestone,10,minecraft:mossy_cobblestone,10,minecraft:stone_bricks,100)
RB(8,1,3,minecraft:mossy_stone_bricks,10,minecraft:cracked_stone_bricks,10,minecraft:cobblestone,10,minecraft:mossy_cobblestone,10,minecraft:stone_bricks,100)
RB(6,1,6,minecraft:mossy_stone_bricks,10,minecraft:cracked_stone_bricks,10,minecraft:cobblestone,10,minecraft:mossy_cobblestone,10,minecraft:stone_bricks,100)
RB(8,1,6,minecraft:mossy_stone_bricks,10,minecraft:cracked_stone_bricks,10,minecraft:cobblestone,10,minecraft:mossy_cobblestone,10,minecraft:stone_bricks,100)
RB(6,2,-7,minecraft:mossy_stone_bricks,10,minecraft:cracked_stone_bricks,10,minecraft:cobblestone,10,minecraft:mossy_cobblestone,10,minecraft:stone_bricks,100)
RB(8,2,-7,minecraft:mossy_stone_bricks,10,minecraft:cracked_stone_bricks,10,minecraft:cobblestone,10,minecraft:mossy_cobblestone,10,minecraft:stone_bricks,100)
RB(6,2,-4,minecraft:mossy_stone_bricks,10,minecraft:cracked_stone_bricks,10,minecraft:cobblestone,10,minecraft:mossy_cobblestone,10,minecraft:stone_bricks,100)
RB(8,2,-4,minecraft:mossy_stone_bricks,10,minecraft:cracked_stone_bricks,10,minecraft:cobblestone,10,minecraft:mossy_cobblestone,10,minecraft:stone_bricks,100)
RB(3,2,-2,minecraft:mossy_stone_bricks,10,minecraft:cracked_stone_bricks,10,minecraft:cobblestone,10,minecraft:mossy_cobblestone,10,minecraft:stone_bricks,100)
RB(4,2,-2,minecraft:mossy_stone_bricks,10,minecraft:cracked_stone_bricks,10,minecraft:cobblestone,10,minecraft:mossy_cobblestone,10,minecraft:stone_bricks,100)
RB(5,2,-2,minecraft:mossy_stone_bricks,10,minecraft:cracked_stone_bricks,10,minecraft:cobblestone,10,minecraft:mossy_cobblestone,10,minecraft:stone_bricks,100)
RB(6,2,-2,minecraft:mossy_stone_bricks,10,minecraft:cracked_stone_bricks,10,minecraft:cobblestone,10,minecraft:mossy_cobblestone,10,minecraft:stone_bricks,100)
RB(7,2,-2,minecraft:mossy_stone_bricks,10,minecraft:cracked_stone_bricks,10,minecraft:cobblestone,10,minecraft:mossy_cobblestone,10,minecraft:stone_bricks,100)
RB(8,2,-2,minecraft:mossy_stone_bricks,10,minecraft:cracked_stone_bricks,10,minecraft:cobblestone,10,minecraft:mossy_cobblestone,10,minecraft:stone_bricks,100)
RB(4,2,-1,minecraft:mossy_stone_bricks,10,minecraft:cracked_stone_bricks,10,minecraft:cobblestone,10,minecraft:mossy_cobblestone,10,minecraft:stone_bricks,100)
RB(5,2,-1,minecraft:mossy_stone_bricks,10,minecraft:cracked_stone_bricks,10,minecraft:cobblestone,10,minecraft:mossy_cobblestone,10,minecraft:stone_bricks,100)
RB(6,2,-1,minecraft:mossy_stone_bricks,10,minecraft:cracked_stone_bricks,10,minecraft:cobblestone,10,minecraft:mossy_cobblestone,10,minecraft:stone_bricks,100)
RB(7,2,-1,minecraft:mossy_stone_bricks,10,minecraft:cracked_stone_bricks,10,minecraft:cobblestone,10,minecraft:mossy_cobblestone,10,minecraft:stone_bricks,100)
RB(8,2,-1,minecraft:mossy_stone_bricks,10,minecraft:cracked_stone_bricks,10,minecraft:cobblestone,10,minecraft:mossy_cobblestone,10,minecraft:stone_bricks,100)
RB(4,2,0,minecraft:mossy_stone_bricks,10,minecraft:cracked_stone_bricks,10,minecraft:cobblestone,10,minecraft:mossy_cobblestone,10,minecraft:stone_bricks,100)
RB(5,2,0,minecraft:mossy_stone_bricks,10,minecraft:cracked_stone_bricks,10,minecraft:cobblestone,10,minecraft:mossy_cobblestone,10,minecraft:stone_bricks,100)
RB(6,2,0,minecraft:mossy_stone_bricks,10,minecraft:cracked_stone_bricks,10,minecraft:cobblestone,10,minecraft:mossy_cobblestone,10,minecraft:stone_bricks,100)
RB(7,2,0,minecraft:mossy_stone_bricks,10,minecraft:cracked_stone_bricks,10,minecraft:cobblestone,10,minecraft:mossy_cobblestone,10,minecraft:stone_bricks,100)
RB(8,2,0,minecraft:mossy_stone_bricks,10,minecraft:cracked_stone_bricks,10,minecraft:cobblestone,10,minecraft:mossy_cobblestone,10,minecraft:stone_bricks,100)
RB(3,2,1,minecraft:mossy_stone_bricks,10,minecraft:cracked_stone_bricks,10,minecraft:cobblestone,10,minecraft:mossy_cobblestone,10,minecraft:stone_bricks,100)
RB(5,2,1,minecraft:mossy_stone_bricks,10,minecraft:cracked_stone_bricks,10,minecraft:cobblestone,10,minecraft:mossy_cobblestone,10,minecraft:stone_bricks,100)
RB(6,2,1,minecraft:mossy_stone_bricks,10,minecraft:cracked_stone_bricks,10,minecraft:cobblestone,10,minecraft:mossy_cobblestone,10,minecraft:stone_bricks,100)
RB(7,2,1,minecraft:mossy_stone_bricks,10,minecraft:cracked_stone_bricks,10,minecraft:cobblestone,10,minecraft:mossy_cobblestone,10,minecraft:stone_bricks,100)
RB(8,2,1,minecraft:mossy_stone_bricks,10,minecraft:cracked_stone_bricks,10,minecraft:cobblestone,10,minecraft:mossy_cobblestone,10,minecraft:stone_bricks,100)
RB(6,2,3,minecraft:mossy_stone_bricks,10,minecraft:cracked_stone_bricks,10,minecraft:cobblestone,10,minecraft:mossy_cobblestone,10,minecraft:stone_bricks,100)
RB(8,2,3,minecraft:mossy_stone_bricks,10,minecraft:cracked_stone_bricks,10,minecraft:cobblestone,10,minecraft:mossy_cobblestone,10,minecraft:stone_bricks,100)
RB(6,2,6,minecraft:mossy_stone_bricks,10,minecraft:cracked_stone_bricks,10,minecraft:cobblestone,10,minecraft:mossy_cobblestone,10,minecraft:stone_bricks,100)
RB(8,2,6,minecraft:mossy_stone_bricks,10,minecraft:cracked_stone_bricks,10,minecraft:cobblestone,10,minecraft:mossy_cobblestone,10,minecraft:stone_bricks,100)
RB(6,3,-7,minecraft:mossy_stone_bricks,10,minecraft:cracked_stone_bricks,10,minecraft:cobblestone,10,minecraft:mossy_cobblestone,10,minecraft:stone_bricks,100)
RB(8,3,-7,minecraft:mossy_stone_bricks,10,minecraft:cracked_stone_bricks,10,minecraft:cobblestone,10,minecraft:mossy_cobblestone,10,minecraft:stone_bricks,100)
RB(6,3,-6,minecraft:mossy_stone_bricks,10,minecraft:cracked_stone_bricks,10,minecraft:cobblestone,10,minecraft:mossy_cobblestone,10,minecraft:stone_bricks,100)
RB(8,3,-6,minecraft:mossy_stone_bricks,10,minecraft:cracked_stone_bricks,10,minecraft:cobblestone,10,minecraft:mossy_cobblestone,10,minecraft:stone_bricks,100)
RB(6,3,-5,minecraft:mossy_stone_bricks,10,minecraft:cracked_stone_bricks,10,minecraft:cobblestone,10,minecraft:mossy_cobblestone,10,minecraft:stone_bricks,100)
RB(8,3,-5,minecraft:mossy_stone_bricks,10,minecraft:cracked_stone_bricks,10,minecraft:cobblestone,10,minecraft:mossy_cobblestone,10,minecraft:stone_bricks,100)
RB(6,3,-4,minecraft:mossy_stone_bricks,10,minecraft:cracked_stone_bricks,10,minecraft:cobblestone,10,minecraft:mossy_cobblestone,10,minecraft:stone_bricks,100)
RB(8,3,-4,minecraft:mossy_stone_bricks,10,minecraft:cracked_stone_bricks,10,minecraft:cobblestone,10,minecraft:mossy_cobblestone,10,minecraft:stone_bricks,100)
RB(6,3,-3,minecraft:mossy_stone_bricks,10,minecraft:cracked_stone_bricks,10,minecraft:cobblestone,10,minecraft:mossy_cobblestone,10,minecraft:stone_bricks,100)
RB(8,3,-3,minecraft:mossy_stone_bricks,10,minecraft:cracked_stone_bricks,10,minecraft:cobblestone,10,minecraft:mossy_cobblestone,10,minecraft:stone_bricks,100)
RB(4,3,-2,minecraft:mossy_stone_bricks,10,minecraft:cracked_stone_bricks,10,minecraft:cobblestone,10,minecraft:mossy_cobblestone,10,minecraft:stone_bricks,100)
RB(5,3,-2,minecraft:mossy_stone_bricks,10,minecraft:cracked_stone_bricks,10,minecraft:cobblestone,10,minecraft:mossy_cobblestone,10,minecraft:stone_bricks,100)
RB(6,3,-2,minecraft:mossy_stone_bricks,10,minecraft:cracked_stone_bricks,10,minecraft:cobblestone,10,minecraft:mossy_cobblestone,10,minecraft:stone_bricks,100)
RB(7,3,-2,minecraft:mossy_stone_bricks,10,minecraft:cracked_stone_bricks,10,minecraft:cobblestone,10,minecraft:mossy_cobblestone,10,minecraft:stone_bricks,100)
RB(8,3,-2,minecraft:mossy_stone_bricks,10,minecraft:cracked_stone_bricks,10,minecraft:cobblestone,10,minecraft:mossy_cobblestone,10,minecraft:stone_bricks,100)
RB(5,3,-1,minecraft:mossy_stone_bricks,10,minecraft:cracked_stone_bricks,10,minecraft:cobblestone,10,minecraft:mossy_cobblestone,10,minecraft:stone_bricks,100)
RB(6,3,-1,minecraft:mossy_stone_bricks,10,minecraft:cracked_stone_bricks,10,minecraft:cobblestone,10,minecraft:mossy_cobblestone,10,minecraft:stone_bricks,100)
RB(7,3,-1,minecraft:mossy_stone_bricks,10,minecraft:cracked_stone_bricks,10,minecraft:cobblestone,10,minecraft:mossy_cobblestone,10,minecraft:stone_bricks,100)
RB(8,3,-1,minecraft:mossy_stone_bricks,10,minecraft:cracked_stone_bricks,10,minecraft:cobblestone,10,minecraft:mossy_cobblestone,10,minecraft:stone_bricks,100)
RB(5,3,0,minecraft:mossy_stone_bricks,10,minecraft:cracked_stone_bricks,10,minecraft:cobblestone,10,minecraft:mossy_cobblestone,10,minecraft:stone_bricks,100)
RB(6,3,0,minecraft:mossy_stone_bricks,10,minecraft:cracked_stone_bricks,10,minecraft:cobblestone,10,minecraft:mossy_cobblestone,10,minecraft:stone_bricks,100)
RB(7,3,0,minecraft:mossy_stone_bricks,10,minecraft:cracked_stone_bricks,10,minecraft:cobblestone,10,minecraft:mossy_cobblestone,10,minecraft:stone_bricks,100)
RB(8,3,0,minecraft:mossy_stone_bricks,10,minecraft:cracked_stone_bricks,10,minecraft:cobblestone,10,minecraft:mossy_cobblestone,10,minecraft:stone_bricks,100)
RB(4,3,1,minecraft:mossy_stone_bricks,10,minecraft:cracked_stone_bricks,10,minecraft:cobblestone,10,minecraft:mossy_cobblestone,10,minecraft:stone_bricks,100)
RB(5,3,1,minecraft:mossy_stone_bricks,10,minecraft:cracked_stone_bricks,10,minecraft:cobblestone,10,minecraft:mossy_cobblestone,10,minecraft:stone_bricks,100)
RB(6,3,1,minecraft:mossy_stone_bricks,10,minecraft:cracked_stone_bricks,10,minecraft:cobblestone,10,minecraft:mossy_cobblestone,10,minecraft:stone_bricks,100)
RB(7,3,1,minecraft:mossy_stone_bricks,10,minecraft:cracked_stone_bricks,10,minecraft:cobblestone,10,minecraft:mossy_cobblestone,10,minecraft:stone_bricks,100)
RB(8,3,1,minecraft:mossy_stone_bricks,10,minecraft:cracked_stone_bricks,10,minecraft:cobblestone,10,minecraft:mossy_cobblestone,10,minecraft:stone_bricks,100)
RB(8,3,2,minecraft:mossy_stone_bricks,10,minecraft:cracked_stone_bricks,10,minecraft:cobblestone,10,minecraft:mossy_cobblestone,10,minecraft:stone_bricks,100)
RB(6,3,3,minecraft:mossy_stone_bricks,10,minecraft:cracked_stone_bricks,10,minecraft:cobblestone,10,minecraft:mossy_cobblestone,10,minecraft:stone_bricks,100)
RB(8,3,3,minecraft:mossy_stone_bricks,10,minecraft:cracked_stone_bricks,10,minecraft:cobblestone,10,minecraft:mossy_cobblestone,10,minecraft:stone_bricks,100)
RB(6,3,4,minecraft:mossy_stone_bricks,10,minecraft:cracked_stone_bricks,10,minecraft:cobblestone,10,minecraft:mossy_cobblestone,10,minecraft:stone_bricks,100)
RB(8,3,4,minecraft:mossy_stone_bricks,10,minecraft:cracked_stone_bricks,10,minecraft:cobblestone,10,minecraft:mossy_cobblestone,10,minecraft:stone_bricks,100)
RB(6,3,5,minecraft:mossy_stone_bricks,10,minecraft:cracked_stone_bricks,10,minecraft:cobblestone,10,minecraft:mossy_cobblestone,10,minecraft:stone_bricks,100)
RB(8,3,5,minecraft:mossy_stone_bricks,10,minecraft:cracked_stone_bricks,10,minecraft:cobblestone,10,minecraft:mossy_cobblestone,10,minecraft:stone_bricks,100)
RB(6,3,6,minecraft:mossy_stone_bricks,10,minecraft:cracked_stone_bricks,10,minecraft:cobblestone,10,minecraft:mossy_cobblestone,10,minecraft:stone_bricks,100)
RB(8,3,6,minecraft:mossy_stone_bricks,10,minecraft:cracked_stone_bricks,10,minecraft:cobblestone,10,minecraft:mossy_cobblestone,10,minecraft:stone_bricks,100)
RB(6,3,7,minecraft:mossy_stone_bricks,10,minecraft:cracked_stone_bricks,10,minecraft:cobblestone,10,minecraft:mossy_cobblestone,10,minecraft:stone_bricks,100)
RB(8,3,7,minecraft:mossy_stone_bricks,10,minecraft:cracked_stone_bricks,10,minecraft:cobblestone,10,minecraft:mossy_cobblestone,10,minecraft:stone_bricks,100)
RB(6,3,8,minecraft:mossy_stone_bricks,10,minecraft:cracked_stone_bricks,10,minecraft:cobblestone,10,minecraft:mossy_cobblestone,10,minecraft:stone_bricks,100)
RB(8,4,-5,minecraft:mossy_stone_bricks,10,minecraft:cracked_stone_bricks,10,minecraft:cobblestone,10,minecraft:mossy_cobblestone,10,minecraft:stone_bricks,100)
RB(5,4,-2,minecraft:mossy_stone_bricks,10,minecraft:cracked_stone_bricks,10,minecraft:cobblestone,10,minecraft:mossy_cobblestone,10,minecraft:stone_bricks,100)
RB(6,4,-2,minecraft:mossy_stone_bricks,10,minecraft:cracked_stone_bricks,10,minecraft:cobblestone,10,minecraft:mossy_cobblestone,10,minecraft:stone_bricks,100)
RB(7,4,-2,minecraft:mossy_stone_bricks,10,minecraft:cracked_stone_bricks,10,minecraft:cobblestone,10,minecraft:mossy_cobblestone,10,minecraft:stone_bricks,100)
RB(8,4,-2,minecraft:mossy_stone_bricks,10,minecraft:cracked_stone_bricks,10,minecraft:cobblestone,10,minecraft:mossy_cobblestone,10,minecraft:stone_bricks,100)
RB(6,4,-1,minecraft:mossy_stone_bricks,10,minecraft:cracked_stone_bricks,10,minecraft:cobblestone,10,minecraft:mossy_cobblestone,10,minecraft:stone_bricks,100)
RB(7,4,-1,minecraft:mossy_stone_bricks,10,minecraft:cracked_stone_bricks,10,minecraft:cobblestone,10,minecraft:mossy_cobblestone,10,minecraft:stone_bricks,100)
RB(8,4,-1,minecraft:mossy_stone_bricks,10,minecraft:cracked_stone_bricks,10,minecraft:cobblestone,10,minecraft:mossy_cobblestone,10,minecraft:stone_bricks,100)
RB(6,4,0,minecraft:mossy_stone_bricks,10,minecraft:cracked_stone_bricks,10,minecraft:cobblestone,10,minecraft:mossy_cobblestone,10,minecraft:stone_bricks,100)
RB(7,4,0,minecraft:mossy_stone_bricks,10,minecraft:cracked_stone_bricks,10,minecraft:cobblestone,10,minecraft:mossy_cobblestone,10,minecraft:stone_bricks,100)
RB(8,4,0,minecraft:mossy_stone_bricks,10,minecraft:cracked_stone_bricks,10,minecraft:cobblestone,10,minecraft:mossy_cobblestone,10,minecraft:stone_bricks,100)
RB(5,4,1,minecraft:mossy_stone_bricks,10,minecraft:cracked_stone_bricks,10,minecraft:cobblestone,10,minecraft:mossy_cobblestone,10,minecraft:stone_bricks,100)
RB(8,4,1,minecraft:mossy_stone_bricks,10,minecraft:cracked_stone_bricks,10,minecraft:cobblestone,10,minecraft:mossy_cobblestone,10,minecraft:stone_bricks,100)
RB(8,4,4,minecraft:mossy_stone_bricks,10,minecraft:cracked_stone_bricks,10,minecraft:cobblestone,10,minecraft:mossy_cobblestone,10,minecraft:stone_bricks,100)
RB(8,4,7,minecraft:mossy_stone_bricks,10,minecraft:cracked_stone_bricks,10,minecraft:cobblestone,10,minecraft:mossy_cobblestone,10,minecraft:stone_bricks,100)
RB(8,5,-5,minecraft:mossy_stone_bricks,10,minecraft:cracked_stone_bricks,10,minecraft:cobblestone,10,minecraft:mossy_cobblestone,10,minecraft:stone_bricks,100)
RB(6,5,-2,minecraft:mossy_stone_bricks,10,minecraft:cracked_stone_bricks,10,minecraft:cobblestone,10,minecraft:mossy_cobblestone,10,minecraft:stone_bricks,100)
RB(7,5,-2,minecraft:mossy_stone_bricks,10,minecraft:cracked_stone_bricks,10,minecraft:cobblestone,10,minecraft:mossy_cobblestone,10,minecraft:stone_bricks,100)
RB(8,5,-2,minecraft:mossy_stone_bricks,10,minecraft:cracked_stone_bricks,10,minecraft:cobblestone,10,minecraft:mossy_cobblestone,10,minecraft:stone_bricks,100)
RB(7,5,-1,minecraft:mossy_stone_bricks,10,minecraft:cracked_stone_bricks,10,minecraft:cobblestone,10,minecraft:mossy_cobblestone,10,minecraft:stone_bricks,100)
RB(8,5,-1,minecraft:mossy_stone_bricks,10,minecraft:cracked_stone_bricks,10,minecraft:cobblestone,10,minecraft:mossy_cobblestone,10,minecraft:stone_bricks,100)
RB(7,5,0,minecraft:mossy_stone_bricks,10,minecraft:cracked_stone_bricks,10,minecraft:cobblestone,10,minecraft:mossy_cobblestone,10,minecraft:stone_bricks,100)
RB(8,5,0,minecraft:mossy_stone_bricks,10,minecraft:cracked_stone_bricks,10,minecraft:cobblestone,10,minecraft:mossy_cobblestone,10,minecraft:stone_bricks,100)
RB(6,5,1,minecraft:mossy_stone_bricks,10,minecraft:cracked_stone_bricks,10,minecraft:cobblestone,10,minecraft:mossy_cobblestone,10,minecraft:stone_bricks,100)
RB(7,5,1,minecraft:mossy_stone_bricks,10,minecraft:cracked_stone_bricks,10,minecraft:cobblestone,10,minecraft:mossy_cobblestone,10,minecraft:stone_bricks,100)
RB(8,5,1,minecraft:mossy_stone_bricks,10,minecraft:cracked_stone_bricks,10,minecraft:cobblestone,10,minecraft:mossy_cobblestone,10,minecraft:stone_bricks,100)
RB(8,5,4,minecraft:mossy_stone_bricks,10,minecraft:cracked_stone_bricks,10,minecraft:cobblestone,10,minecraft:mossy_cobblestone,10,minecraft:stone_bricks,100)
RB(8,5,7,minecraft:mossy_stone_bricks,10,minecraft:cracked_stone_bricks,10,minecraft:cobblestone,10,minecraft:mossy_cobblestone,10,minecraft:stone_bricks,100)
RB(8,6,-7,minecraft:mossy_stone_bricks,10,minecraft:cracked_stone_bricks,10,minecraft:cobblestone,10,minecraft:mossy_cobblestone,10,minecraft:stone_bricks,100)
RB(8,6,-6,minecraft:mossy_stone_bricks,10,minecraft:cracked_stone_bricks,10,minecraft:cobblestone,10,minecraft:mossy_cobblestone,10,minecraft:stone_bricks,100)
RB(8,6,-5,minecraft:mossy_stone_bricks,10,minecraft:cracked_stone_bricks,10,minecraft:cobblestone,10,minecraft:mossy_cobblestone,10,minecraft:stone_bricks,100)
RB(8,6,-4,minecraft:mossy_stone_bricks,10,minecraft:cracked_stone_bricks,10,minecraft:cobblestone,10,minecraft:mossy_cobblestone,10,minecraft:stone_bricks,100)
RB(8,6,-3,minecraft:mossy_stone_bricks,10,minecraft:cracked_stone_bricks,10,minecraft:cobblestone,10,minecraft:mossy_cobblestone,10,minecraft:stone_bricks,100)
RB(7,6,-2,minecraft:mossy_stone_bricks,10,minecraft:cracked_stone_bricks,10,minecraft:cobblestone,10,minecraft:mossy_cobblestone,10,minecraft:stone_bricks,100)
RB(8,6,-2,minecraft:mossy_stone_bricks,10,minecraft:cracked_stone_bricks,10,minecraft:cobblestone,10,minecraft:mossy_cobblestone,10,minecraft:stone_bricks,100)
RB(8,6,-1,minecraft:mossy_stone_bricks,10,minecraft:cracked_stone_bricks,10,minecraft:cobblestone,10,minecraft:mossy_cobblestone,10,minecraft:stone_bricks,100)
RB(8,6,0,minecraft:mossy_stone_bricks,10,minecraft:cracked_stone_bricks,10,minecraft:cobblestone,10,minecraft:mossy_cobblestone,10,minecraft:stone_bricks,100)
RB(7,6,1,minecraft:mossy_stone_bricks,10,minecraft:cracked_stone_bricks,10,minecraft:cobblestone,10,minecraft:mossy_cobblestone,10,minecraft:stone_bricks,100)
RB(8,6,1,minecraft:mossy_stone_bricks,10,minecraft:cracked_stone_bricks,10,minecraft:cobblestone,10,minecraft:mossy_cobblestone,10,minecraft:stone_bricks,100)
RB(8,6,2,minecraft:mossy_stone_bricks,10,minecraft:cracked_stone_bricks,10,minecraft:cobblestone,10,minecraft:mossy_cobblestone,10,minecraft:stone_bricks,100)
RB(8,6,3,minecraft:mossy_stone_bricks,10,minecraft:cracked_stone_bricks,10,minecraft:cobblestone,10,minecraft:mossy_cobblestone,10,minecraft:stone_bricks,100)
RB(8,6,4,minecraft:mossy_stone_bricks,10,minecraft:cracked_stone_bricks,10,minecraft:cobblestone,10,minecraft:mossy_cobblestone,10,minecraft:stone_bricks,100)
RB(8,6,5,minecraft:mossy_stone_bricks,10,minecraft:cracked_stone_bricks,10,minecraft:cobblestone,10,minecraft:mossy_cobblestone,10,minecraft:stone_bricks,100)
RB(8,6,6,minecraft:mossy_stone_bricks,10,minecraft:cracked_stone_bricks,10,minecraft:cobblestone,10,minecraft:mossy_cobblestone,10,minecraft:stone_bricks,100)
RB(8,6,7,minecraft:mossy_stone_bricks,10,minecraft:cracked_stone_bricks,10,minecraft:cobblestone,10,minecraft:mossy_cobblestone,10,minecraft:stone_bricks,100)
RB(8,7,-2,minecraft:mossy_stone_bricks,10,minecraft:cracked_stone_bricks,10,minecraft:cobblestone,10,minecraft:mossy_cobblestone,10,minecraft:stone_bricks,100)
RB(8,7,1,minecraft:mossy_stone_bricks,10,minecraft:cracked_stone_bricks,10,minecraft:cobblestone,10,minecraft:mossy_cobblestone,10,minecraft:stone_bricks,100)

#######################################################################
# +-----------------------------------------------------------------+ #
# |                            BO3 checks                           | #
# +-----------------------------------------------------------------+ #
#######################################################################


#######################################################################
# +-----------------------------------------------------------------+ #
# |                             Branches                            | #
# +-----------------------------------------------------------------+ #
#######################################################################

Branch(0,0,-16,MayaTemple05_Ruin01_00-00,NORTH,100.0)
Branch(0,0,16,MayaTemple05_Ruin01_00-02,NORTH,100.0)

#######################################################################
# +-----------------------------------------------------------------+ #
# |                             Entities                            | #
# +-----------------------------------------------------------------+ #
#######################################################################

Entity(6,4,-5,minecraft:villager,1,../JungleNBT/entities/tribalruinsguard.txt)
Entity(6,6,-1,minecraft:villager,1,../JungleNBT/entities/tribalruinsguard.txt)
Entity(7,7,7,minecraft:villager,1,../JungleNBT/entities/tribalruinsguard.txt)
