
#######################################################################
# +-----------------------------------------------------------------+ #
# |                            BO3 object                           | #
# +-----------------------------------------------------------------+ #
#######################################################################

Author: Bo3 BulkEdit

Description: Converted Schematic - Modified by Bo3BulkEdit

Version: 3

SettingsMode: WriteWithoutComments


#######################################################################
# +-----------------------------------------------------------------+ #
# |                          Main settings                          | #
# +-----------------------------------------------------------------+ #
#######################################################################

Tree: false

Frequency: 1

Rarity: 100.0

RotateRandomly: false

SpawnHeight: randomY

SpawnHeightOffset: 0

SpawnHeightVariance: 0

##############################
# Height Limits for the BO3. #
##############################

MinHeight: 0

MaxHeight: 255

######################
# Extrusion settings #
######################

ExtrudeMode: None

ExtrudeThroughBlocks: minecraft:air

MaxBranchDepth: 20


#######################################################################
# +-----------------------------------------------------------------+ #
# |                      Source block settings                      | #
# +-----------------------------------------------------------------+ #
#######################################################################

SourceBlocks: otg:air

MaxPercentageOutsideSourceBlock: 100

OutsideSourceBlock: placeAnyway

DoReplaceBlocks: true

IsOTGPlus: false


#######################################################################
# +-----------------------------------------------------------------+ #
# |                              Blocks                             | #
# +-----------------------------------------------------------------+ #
#######################################################################

B(-8,-6,-7,minecraft:spruce_planks)
B(-8,-5,-7,minecraft:spruce_planks)
B(-8,-4,-7,minecraft:dark_oak_planks)
B(-8,-3,-7,minecraft:dark_oak_planks)
B(-8,-2,-7,minecraft:oak_planks)
B(-8,-1,-7,minecraft:dark_oak_planks)
B(-8,0,-7,minecraft:oak_fence[east=true,north=false,south=false,waterlogged=false,west=false])
B(-8,-7,-6,minecraft:spruce_planks)
B(-8,-6,-6,minecraft:stone)
B(-8,-4,-6,minecraft:oak_slab[type=top,waterlogged=false])
B(-8,-3,-6,minecraft:oak_button[face=wall,facing=east,powered=false])
B(-8,-1,-6,minecraft:oak_slab[type=top,waterlogged=false])
B(-8,-8,-5,minecraft:spruce_planks)
B(-8,-7,-5,minecraft:redstone_ore)
B(-8,-4,-5,minecraft:oak_slab[type=top,waterlogged=false])
B(-8,-1,-5,minecraft:oak_slab[type=top,waterlogged=false])
B(-8,0,-5,minecraft:stone_button[face=wall,facing=west,powered=false])
B(-8,-8,-4,minecraft:spruce_planks)
B(-8,-4,-4,minecraft:oak_slab[type=top,waterlogged=false])
B(-8,-1,-4,minecraft:oak_slab[type=top,waterlogged=false])
B(-8,2,-4,minecraft:oak_button)
B(-8,-8,-3,minecraft:spruce_planks)
B(-8,-3,-3,minecraft:oak_trapdoor[facing=south,half=bottom,open=false,powered=false,waterlogged=false])
B(-8,0,-3,minecraft:oak_trapdoor[facing=south,half=bottom,open=false,powered=false,waterlogged=false])
B(-8,1,-3,minecraft:spruce_stairs[facing=south,half=top,shape=straight,waterlogged=false])
B(-8,2,-3,minecraft:spruce_slab[type=double,waterlogged=false])
B(-8,5,-3,minecraft:white_wool)
B(-8,13,-3,minecraft:white_wool)
B(-8,14,-3,minecraft:white_wool)
B(-8,15,-3,minecraft:white_wool)
B(-8,-9,-2,minecraft:spruce_planks)
B(-8,-8,-2,minecraft:spruce_planks)
B(-8,-7,-2,minecraft:clay)
B(-8,-3,-2,minecraft:spruce_slab)
B(-8,-1,-2,minecraft:spruce_slab[type=top,waterlogged=false])
B(-8,0,-2,minecraft:spruce_slab)
B(-8,1,-2,minecraft:spruce_slab)
B(-8,2,-2,minecraft:oak_trapdoor[facing=south,half=bottom,open=false,powered=false,waterlogged=false])
B(-8,4,-2,minecraft:white_wool)
B(-8,6,-2,minecraft:white_wool)
B(-8,7,-2,minecraft:white_wool)
B(-8,8,-2,minecraft:spruce_fence[east=true,north=false,south=false,waterlogged=false,west=false])
B(-8,9,-2,minecraft:spruce_fence[east=true,north=false,south=false,waterlogged=false,west=false])
B(-8,16,-2,minecraft:white_wool)
B(-8,17,-2,minecraft:white_wool)
B(-8,18,-2,minecraft:spruce_fence[east=true,north=false,south=false,waterlogged=false,west=false])
B(-8,19,-2,minecraft:spruce_fence[east=true,north=false,south=false,waterlogged=false,west=false])
B(-8,28,-2,minecraft:spruce_fence[east=true,north=false,south=false,waterlogged=false,west=false])
B(-8,-8,-1,minecraft:spruce_planks)
B(-8,-7,-1,minecraft:clay)
B(-8,-3,-1,minecraft:oak_trapdoor)
B(-8,0,-1,minecraft:oak_trapdoor)
B(-8,1,-1,minecraft:spruce_stairs[facing=north,half=top,shape=straight,waterlogged=false])
B(-8,2,-1,minecraft:spruce_slab[type=double,waterlogged=false])
B(-7,-4,-8,minecraft:ladder)
B(-7,-3,-8,minecraft:ladder)
B(-7,-2,-8,minecraft:ladder)
B(-7,-1,-8,minecraft:ladder)
B(-7,-6,-7,minecraft:spruce_planks)
B(-7,-5,-7,minecraft:spruce_planks)
B(-7,-4,-7,minecraft:dark_oak_planks)
B(-7,-3,-7,minecraft:dark_oak_planks)
B(-7,-2,-7,minecraft:oak_planks)
B(-7,-1,-7,minecraft:dark_oak_planks)
B(-7,0,-7,minecraft:oak_fence_gate)
B(-7,-7,-6,minecraft:spruce_planks)
B(-7,-6,-6,minecraft:stone)
B(-7,-4,-6,minecraft:oak_slab[type=top,waterlogged=false])
B(-7,-3,-6,minecraft:oak_button[face=wall,facing=west,powered=false])
B(-7,-1,-6,minecraft:oak_slab[type=top,waterlogged=false])
B(-7,0,-6,minecraft:stone_button)
B(-7,-7,-5,minecraft:spruce_planks)
B(-7,-6,-5,minecraft:clay)
B(-7,-4,-5,minecraft:oak_slab[type=top,waterlogged=false])
B(-7,-1,-5,minecraft:oak_slab[type=top,waterlogged=false])
B(-7,0,-5,minecraft:birch_planks)
B(-7,1,-5,minecraft:stone_button[face=floor,facing=east,powered=false])
B(-7,-8,-4,minecraft:spruce_planks)
B(-7,-7,-4,minecraft:clay)
B(-7,-4,-4,minecraft:oak_slab[type=top,waterlogged=false])
B(-7,-1,-4,minecraft:oak_slab[type=top,waterlogged=false])
B(-7,0,-4,minecraft:stone_button[face=wall,facing=south,powered=false])
B(-7,-8,-3,minecraft:spruce_planks)
B(-7,-3,-3,minecraft:oak_trapdoor[facing=south,half=bottom,open=false,powered=false,waterlogged=false])
B(-7,0,-3,minecraft:oak_trapdoor[facing=south,half=bottom,open=false,powered=false,waterlogged=false])
B(-7,1,-3,minecraft:spruce_stairs[facing=south,half=top,shape=straight,waterlogged=false])
B(-7,2,-3,minecraft:spruce_slab)
B(-7,5,-3,minecraft:white_wool)
B(-7,6,-3,minecraft:white_wool)
B(-7,7,-3,minecraft:white_wool)
B(-7,13,-3,minecraft:white_wool)
B(-7,14,-3,minecraft:white_wool)
B(-7,15,-3,minecraft:white_wool)
B(-7,16,-3,minecraft:white_wool)
B(-7,-9,-2,minecraft:spruce_planks)
B(-7,-8,-2,minecraft:spruce_planks)
B(-7,-3,-2,minecraft:spruce_slab)
B(-7,-1,-2,minecraft:spruce_slab[type=top,waterlogged=false])
B(-7,0,-2,minecraft:spruce_slab)
B(-7,1,-2,minecraft:spruce_slab)
B(-7,4,-2,minecraft:white_wool)
B(-7,8,-2,minecraft:white_wool)
B(-7,9,-2,minecraft:spruce_fence[east=true,north=false,south=false,waterlogged=false,west=true])
B(-7,10,-2,minecraft:spruce_fence[east=true,north=false,south=false,waterlogged=false,west=false])
B(-7,12,-2,minecraft:white_wool)
B(-7,17,-2,minecraft:white_wool)
B(-7,18,-2,minecraft:white_wool)
B(-7,19,-2,minecraft:spruce_fence[east=true,north=false,south=false,waterlogged=false,west=true])
B(-7,20,-2,minecraft:spruce_fence[east=true,north=false,south=false,waterlogged=false,west=false])
B(-7,28,-2,minecraft:spruce_fence[east=false,north=false,south=false,waterlogged=false,west=true])
B(-7,29,-2,minecraft:spruce_fence[east=true,north=false,south=false,waterlogged=false,west=false])
B(-7,-8,-1,minecraft:spruce_planks)
B(-7,-7,-1,minecraft:stone)
B(-7,-3,-1,minecraft:oak_trapdoor)
B(-7,0,-1,minecraft:oak_trapdoor)
B(-7,1,-1,minecraft:spruce_stairs[facing=north,half=top,shape=straight,waterlogged=false])
B(-7,2,-1,minecraft:spruce_slab)
B(-6,-3,-8,minecraft:dispenser)
B(-6,-2,-8,minecraft:oak_slab[type=top,waterlogged=false])
B(-6,-6,-7,minecraft:spruce_planks)
B(-6,-5,-7,minecraft:spruce_planks)
B(-6,-4,-7,minecraft:dark_oak_planks)
B(-6,-3,-7,minecraft:black_concrete)
B(-6,-1,-7,minecraft:dark_oak_planks)
B(-6,0,-7,minecraft:oak_fence[east=true,north=false,south=false,waterlogged=false,west=true])
B(-6,-7,-6,minecraft:spruce_planks)
B(-6,-6,-6,minecraft:iron_ore)
B(-6,-5,-6,minecraft:clay)
B(-6,-4,-6,minecraft:oak_slab[type=top,waterlogged=false])
B(-6,-3,-6,minecraft:dispenser[facing=up,triggered=true])
B(-6,-2,-6,minecraft:lever[face=floor,facing=south,powered=true])
B(-6,-1,-6,minecraft:oak_slab[type=top,waterlogged=false])
B(-6,0,-6,minecraft:stone_button)
B(-6,-7,-5,minecraft:spruce_planks)
B(-6,-6,-5,minecraft:redstone_ore)
B(-6,-4,-5,minecraft:oak_slab[type=top,waterlogged=false])
B(-6,-3,-5,minecraft:spruce_stairs)
B(-6,-1,-5,minecraft:oak_slab[type=top,waterlogged=false])
B(-6,0,-5,minecraft:birch_planks)
B(-6,1,-5,minecraft:stone_button[face=floor,facing=east,powered=false])
B(-6,-8,-4,minecraft:spruce_planks)
B(-6,-7,-4,minecraft:clay)
B(-6,-4,-4,minecraft:oak_slab[type=top,waterlogged=false])
B(-6,-1,-4,minecraft:oak_slab[type=top,waterlogged=false])
B(-6,0,-4,minecraft:stone_button[face=wall,facing=south,powered=false])
B(-6,-8,-3,minecraft:spruce_planks)
B(-6,-3,-3,minecraft:oak_trapdoor[facing=south,half=bottom,open=false,powered=false,waterlogged=false])
B(-6,0,-3,minecraft:oak_trapdoor[facing=south,half=bottom,open=false,powered=false,waterlogged=false])
B(-6,1,-3,minecraft:spruce_stairs[facing=south,half=top,shape=straight,waterlogged=false])
B(-6,2,-3,minecraft:spruce_slab)
B(-6,4,-3,minecraft:white_wool)
B(-6,5,-3,minecraft:white_wool)
B(-6,7,-3,minecraft:white_wool)
B(-6,8,-3,minecraft:white_wool)
B(-6,14,-3,minecraft:white_wool)
B(-6,16,-3,minecraft:white_wool)
B(-6,17,-3,minecraft:white_wool)
B(-6,-9,-2,minecraft:spruce_planks)
B(-6,-8,-2,minecraft:spruce_planks)
B(-6,-3,-2,minecraft:spruce_slab)
B(-6,-1,-2,minecraft:spruce_slab[type=top,waterlogged=false])
B(-6,0,-2,minecraft:spruce_slab)
B(-6,1,-2,minecraft:spruce_slab)
B(-6,2,-2,minecraft:oak_trapdoor[facing=south,half=bottom,open=false,powered=false,waterlogged=false])
B(-6,6,-2,minecraft:white_wool)
B(-6,9,-2,minecraft:white_wool)
B(-6,10,-2,minecraft:spruce_fence[east=true,north=false,south=false,waterlogged=false,west=true])
B(-6,11,-2,minecraft:spruce_fence[east=true,north=false,south=false,waterlogged=false,west=false])
B(-6,13,-2,minecraft:white_wool)
B(-6,15,-2,minecraft:white_wool)
B(-6,18,-2,minecraft:white_wool)
B(-6,19,-2,minecraft:white_wool)
B(-6,20,-2,minecraft:spruce_fence[east=true,north=false,south=false,waterlogged=false,west=true])
B(-6,21,-2,minecraft:spruce_fence[east=true,north=false,south=false,waterlogged=false,west=false])
B(-6,29,-2,minecraft:spruce_fence[east=true,north=false,south=false,waterlogged=false,west=true])
B(-6,-8,-1,minecraft:spruce_planks)
B(-6,-3,-1,minecraft:oak_trapdoor)
B(-6,0,-1,minecraft:oak_trapdoor)
B(-6,1,-1,minecraft:spruce_stairs[facing=north,half=top,shape=straight,waterlogged=false])
B(-6,2,-1,minecraft:spruce_slab)
B(-5,-4,-8,minecraft:ladder)
B(-5,-3,-8,minecraft:ladder)
B(-5,-2,-8,minecraft:ladder)
B(-5,-1,-8,minecraft:ladder)
B(-5,-6,-7,minecraft:spruce_planks)
B(-5,-5,-7,minecraft:spruce_planks)
B(-5,-4,-7,minecraft:dark_oak_planks)
B(-5,-3,-7,minecraft:dark_oak_planks)
B(-5,-2,-7,minecraft:oak_planks)
B(-5,-1,-7,minecraft:dark_oak_planks)
B(-5,0,-7,minecraft:oak_fence_gate)
B(-5,-7,-6,minecraft:spruce_planks)
B(-5,-6,-6,minecraft:iron_ore)
B(-5,-5,-6,minecraft:stone)
B(-5,-4,-6,minecraft:oak_slab[type=top,waterlogged=false])
B(-5,-3,-6,minecraft:oak_button[face=wall,facing=east,powered=false])
B(-5,-1,-6,minecraft:oak_slab[type=top,waterlogged=false])
B(-5,-7,-5,minecraft:spruce_planks)
B(-5,-6,-5,minecraft:stone)
B(-5,-4,-5,minecraft:oak_slab[type=top,waterlogged=false])
B(-5,-1,-5,minecraft:oak_slab[type=top,waterlogged=false])
B(-5,0,-5,minecraft:stone_button[face=wall,facing=east,powered=false])
B(-5,-8,-4,minecraft:spruce_planks)
B(-5,-7,-4,minecraft:stone)
B(-5,-6,-4,minecraft:clay)
B(-5,-4,-4,minecraft:oak_slab[type=top,waterlogged=false])
B(-5,-1,-4,minecraft:oak_slab[type=top,waterlogged=false])
B(-5,36,-4,minecraft:black_wool)
B(-5,-8,-3,minecraft:spruce_planks)
B(-5,-3,-3,minecraft:oak_trapdoor[facing=south,half=bottom,open=false,powered=false,waterlogged=false])
B(-5,0,-3,minecraft:oak_trapdoor[facing=south,half=bottom,open=false,powered=false,waterlogged=false])
B(-5,1,-3,minecraft:spruce_stairs[facing=south,half=top,shape=straight,waterlogged=false])
B(-5,2,-3,minecraft:spruce_slab)
B(-5,3,-3,minecraft:white_wool)
B(-5,4,-3,minecraft:white_wool)
B(-5,8,-3,minecraft:white_wool)
B(-5,-9,-2,minecraft:spruce_planks)
B(-5,-8,-2,minecraft:spruce_planks)
B(-5,-3,-2,minecraft:spruce_slab)
B(-5,-1,-2,minecraft:spruce_slab[type=top,waterlogged=false])
B(-5,0,-2,minecraft:spruce_slab)
B(-5,1,-2,minecraft:spruce_slab)
B(-5,4,-2,minecraft:white_wool)
B(-5,5,-2,minecraft:white_wool)
B(-5,7,-2,minecraft:white_wool)
B(-5,9,-2,minecraft:white_wool)
B(-5,10,-2,minecraft:white_wool)
B(-5,11,-2,minecraft:spruce_fence[east=true,north=false,south=false,waterlogged=false,west=true])
B(-5,12,-2,minecraft:spruce_fence[east=true,north=false,south=false,waterlogged=false,west=false])
B(-5,13,-2,minecraft:white_wool)
B(-5,14,-2,minecraft:white_wool)
B(-5,19,-2,minecraft:white_wool)
B(-5,20,-2,minecraft:white_wool)
B(-5,21,-2,minecraft:spruce_fence[east=false,north=false,south=false,waterlogged=false,west=true])
B(-5,22,-2,minecraft:spruce_fence[east=true,north=false,south=false,waterlogged=false,west=false])
B(-5,29,-2,minecraft:spruce_fence[east=false,north=false,south=false,waterlogged=false,west=true])
B(-5,30,-2,minecraft:spruce_fence[east=true,north=false,south=false,waterlogged=false,west=false])
B(-5,-8,-1,minecraft:spruce_planks)
B(-5,-7,-1,minecraft:redstone_ore)
B(-5,-6,-1,minecraft:clay)
B(-5,-3,-1,minecraft:oak_trapdoor)
B(-5,0,-1,minecraft:oak_trapdoor)
B(-5,1,-1,minecraft:spruce_stairs[facing=north,half=top,shape=straight,waterlogged=false])
B(-5,2,-1,minecraft:spruce_slab)
B(-4,-6,-7,minecraft:spruce_planks)
B(-4,-5,-7,minecraft:spruce_planks)
B(-4,-4,-7,minecraft:dark_oak_planks)
B(-4,-3,-7,minecraft:dark_oak_planks)
B(-4,-2,-7,minecraft:oak_planks)
B(-4,-1,-7,minecraft:dark_oak_planks)
B(-4,0,-7,minecraft:oak_fence[east=true,north=false,south=false,waterlogged=false,west=true])
B(-4,-7,-6,minecraft:spruce_planks)
B(-4,-6,-6,minecraft:stone)
B(-4,-5,-6,minecraft:stone)
B(-4,-4,-6,minecraft:oak_slab[type=top,waterlogged=false])
B(-4,-3,-6,minecraft:oak_button[face=wall,facing=west,powered=false])
B(-4,-1,-6,minecraft:oak_slab[type=top,waterlogged=false])
B(-4,-7,-5,minecraft:spruce_planks)
B(-4,-6,-5,minecraft:stone)
B(-4,-5,-5,minecraft:clay)
B(-4,-4,-5,minecraft:oak_slab[type=top,waterlogged=false])
B(-4,-1,-5,minecraft:oak_slab[type=top,waterlogged=false])
B(-4,-8,-4,minecraft:spruce_planks)
B(-4,-7,-4,minecraft:stone)
B(-4,-6,-4,minecraft:clay)
B(-4,-4,-4,minecraft:oak_slab[type=top,waterlogged=false])
B(-4,-1,-4,minecraft:oak_slab[type=top,waterlogged=false])
B(-4,-8,-3,minecraft:spruce_planks)
B(-4,-7,-3,minecraft:clay)
B(-4,-3,-3,minecraft:oak_trapdoor[facing=south,half=bottom,open=false,powered=false,waterlogged=false])
B(-4,0,-3,minecraft:oak_trapdoor[facing=south,half=bottom,open=false,powered=false,waterlogged=false])
B(-4,1,-3,minecraft:spruce_stairs[facing=south,half=top,shape=straight,waterlogged=false])
B(-4,2,-3,minecraft:spruce_slab)
B(-4,3,-3,minecraft:white_wool)
B(-4,9,-3,minecraft:white_wool)
B(-4,36,-3,minecraft:black_wool)
B(-4,-9,-2,minecraft:spruce_planks)
B(-4,-8,-2,minecraft:spruce_planks)
B(-4,-3,-2,minecraft:spruce_slab)
B(-4,-1,-2,minecraft:spruce_slab[type=top,waterlogged=false])
B(-4,0,-2,minecraft:spruce_slab)
B(-4,1,-2,minecraft:spruce_slab)
B(-4,2,-2,minecraft:oak_trapdoor[facing=south,half=bottom,open=false,powered=false,waterlogged=false])
B(-4,10,-2,minecraft:white_wool)
B(-4,11,-2,minecraft:white_wool)
B(-4,12,-2,minecraft:spruce_fence[east=true,north=false,south=false,waterlogged=false,west=true])
B(-4,13,-2,minecraft:white_wool)
B(-4,22,-2,minecraft:spruce_fence[east=true,north=false,south=false,waterlogged=false,west=true])
B(-4,23,-2,minecraft:spruce_fence[east=true,north=false,south=false,waterlogged=false,west=false])
B(-4,30,-2,minecraft:spruce_fence[east=true,north=false,south=false,waterlogged=false,west=true])
B(-4,-8,-1,minecraft:spruce_planks)
B(-4,-7,-1,minecraft:stone)
B(-4,-6,-1,minecraft:redstone_ore)
B(-4,-3,-1,minecraft:oak_trapdoor)
B(-4,0,-1,minecraft:oak_trapdoor)
B(-4,1,-1,minecraft:spruce_stairs[facing=north,half=top,shape=straight,waterlogged=false])
B(-4,2,-1,minecraft:spruce_slab)
B(-3,-3,-8,minecraft:dispenser)
B(-3,-2,-8,minecraft:oak_slab[type=top,waterlogged=false])
B(-3,-6,-7,minecraft:spruce_planks)
B(-3,-5,-7,minecraft:spruce_planks)
B(-3,-4,-7,minecraft:dark_oak_planks)
B(-3,-3,-7,minecraft:black_concrete)
B(-3,-1,-7,minecraft:dark_oak_planks)
B(-3,0,-7,minecraft:oak_fence[east=true,north=false,south=false,waterlogged=false,west=true])
B(-3,-7,-6,minecraft:spruce_planks)
B(-3,-6,-6,minecraft:stone)
B(-3,-5,-6,minecraft:redstone_ore)
B(-3,-4,-6,minecraft:oak_slab[type=top,waterlogged=false])
B(-3,-3,-6,minecraft:dispenser[facing=up,triggered=true])
B(-3,-2,-6,minecraft:lever[face=floor,facing=south,powered=true])
B(-3,-1,-6,minecraft:oak_slab[type=top,waterlogged=false])
B(-3,-7,-5,minecraft:spruce_planks)
B(-3,-6,-5,minecraft:clay)
B(-3,-4,-5,minecraft:oak_slab[type=top,waterlogged=false])
B(-3,-3,-5,minecraft:spruce_stairs)
B(-3,-1,-5,minecraft:oak_slab[type=top,waterlogged=false])
B(-3,23,-5,minecraft:black_wool)
B(-3,-7,-4,minecraft:spruce_planks)
B(-3,-4,-4,minecraft:oak_slab[type=top,waterlogged=false])
B(-3,-1,-4,minecraft:oak_slab[type=top,waterlogged=false])
B(-3,22,-4,minecraft:black_wool)
B(-3,23,-4,minecraft:black_wool)
B(-3,24,-4,minecraft:black_wool)
B(-3,-8,-3,minecraft:spruce_planks)
B(-3,-7,-3,minecraft:clay)
B(-3,-4,-3,minecraft:oak_slab[type=top,waterlogged=false])
B(-3,-3,-3,minecraft:cyan_bed)
B(-3,-1,-3,minecraft:oak_slab[type=top,waterlogged=false])
B(-3,0,-3,minecraft:spruce_stairs[facing=south,half=bottom,shape=straight,waterlogged=false])
B(-3,1,-3,minecraft:spruce_stairs[facing=south,half=top,shape=straight,waterlogged=false])
B(-3,2,-3,minecraft:spruce_slab)
B(-3,3,-3,minecraft:spruce_fence[east=true,north=false,south=false,waterlogged=false,west=true])
B(-3,22,-3,minecraft:white_wool)
B(-3,23,-3,minecraft:white_wool)
B(-3,24,-3,minecraft:white_wool)
B(-3,37,-3,minecraft:black_wool)
B(-3,-9,-2,minecraft:spruce_planks)
B(-3,-8,-2,minecraft:spruce_planks)
B(-3,-4,-2,minecraft:oak_slab[type=top,waterlogged=false])
B(-3,-1,-2,minecraft:oak_slab[type=top,waterlogged=false])
B(-3,1,-2,minecraft:spruce_slab)
B(-3,5,-2,minecraft:white_wool)
B(-3,11,-2,minecraft:white_wool)
B(-3,12,-2,minecraft:spruce_fence[east=false,north=false,south=false,waterlogged=false,west=true])
B(-3,13,-2,minecraft:spruce_fence[east=true,north=false,south=false,waterlogged=false,west=true])
B(-3,22,-2,minecraft:white_wool)
B(-3,23,-2,minecraft:white_wool)
B(-3,24,-2,minecraft:white_wool)
B(-3,30,-2,minecraft:spruce_fence[east=false,north=false,south=false,waterlogged=false,west=true])
B(-3,31,-2,minecraft:spruce_fence[east=true,north=false,south=false,waterlogged=false,west=false])
B(-3,-8,-1,minecraft:spruce_planks)
B(-3,-7,-1,minecraft:stone)
B(-3,-6,-1,minecraft:stone)
B(-3,-4,-1,minecraft:oak_slab[type=top,waterlogged=false])
B(-3,-3,-1,minecraft:cyan_bed)
B(-3,-1,-1,minecraft:oak_slab[type=top,waterlogged=false])
B(-3,0,-1,minecraft:spruce_stairs)
B(-3,1,-1,minecraft:spruce_stairs[facing=north,half=top,shape=straight,waterlogged=false])
B(-3,2,-1,minecraft:spruce_slab)
B(-3,5,-1,minecraft:white_wool)
B(-3,6,-1,minecraft:white_wool)
B(-3,15,-1,minecraft:white_wool)
B(-3,22,-1,minecraft:black_wool)
B(-3,23,-1,minecraft:white_wool)
B(-3,24,-1,minecraft:white_wool)
B(-3,25,-1,minecraft:white_wool)
B(-2,-6,-7,minecraft:spruce_planks)
B(-2,-5,-7,minecraft:spruce_planks)
B(-2,-4,-7,minecraft:dark_oak_planks)
B(-2,-3,-7,minecraft:dark_oak_planks)
B(-2,-2,-7,minecraft:oak_planks)
B(-2,-1,-7,minecraft:dark_oak_stairs[facing=west,half=bottom,shape=straight,waterlogged=false])
B(-2,0,-7,minecraft:dark_oak_stairs[facing=west,half=top,shape=inner_left,waterlogged=false])
B(-2,22,-7,minecraft:black_wool)
B(-2,-7,-6,minecraft:spruce_planks)
B(-2,-6,-6,minecraft:iron_ore)
B(-2,-5,-6,minecraft:stone)
B(-2,-4,-6,minecraft:oak_slab[type=top,waterlogged=false])
B(-2,-3,-6,minecraft:oak_button[face=wall,facing=east,powered=false])
B(-2,-1,-6,minecraft:oak_slab[type=top,waterlogged=false])
B(-2,0,-6,minecraft:stone_button[face=wall,facing=west,powered=false])
B(-2,22,-6,minecraft:black_wool)
B(-2,23,-6,minecraft:black_wool)
B(-2,24,-6,minecraft:black_wool)
B(-2,-7,-5,minecraft:spruce_planks)
B(-2,-6,-5,minecraft:stone)
B(-2,-4,-5,minecraft:oak_slab[type=top,waterlogged=false])
B(-2,-1,-5,minecraft:oak_slab[type=top,waterlogged=false])
B(-2,0,-5,minecraft:stone_button[face=wall,facing=west,powered=false])
B(-2,21,-5,minecraft:black_wool)
B(-2,22,-5,minecraft:black_wool)
B(-2,24,-5,minecraft:black_wool)
B(-2,25,-5,minecraft:black_wool)
B(-2,26,-5,minecraft:black_wool)
B(-2,-7,-4,minecraft:spruce_planks)
B(-2,-4,-4,minecraft:oak_slab[type=top,waterlogged=false])
B(-2,-1,-4,minecraft:oak_slab[type=top,waterlogged=false])
B(-2,5,-4,minecraft:white_wool)
B(-2,14,-4,minecraft:white_wool)
B(-2,21,-4,minecraft:white_wool)
B(-2,25,-4,minecraft:black_wool)
B(-2,26,-4,minecraft:black_wool)
B(-2,27,-4,minecraft:oak_button[face=wall,facing=west,powered=false])
B(-2,-8,-3,minecraft:spruce_planks)
B(-2,-4,-3,minecraft:oak_slab[type=top,waterlogged=false])
B(-2,-3,-3,minecraft:orange_bed)
B(-2,-1,-3,minecraft:oak_slab[type=top,waterlogged=false])
B(-2,1,-3,minecraft:spruce_slab[type=top,waterlogged=false])
B(-2,2,-3,minecraft:spruce_slab)
B(-2,3,-3,minecraft:spruce_fence[east=true,north=false,south=false,waterlogged=false,west=true])
B(-2,4,-3,minecraft:white_wool)
B(-2,5,-3,minecraft:white_wool)
B(-2,6,-3,minecraft:white_wool)
B(-2,14,-3,minecraft:white_wool)
B(-2,15,-3,minecraft:white_wool)
B(-2,21,-3,minecraft:white_wool)
B(-2,25,-3,minecraft:black_wool)
B(-2,27,-3,minecraft:oak_button[face=wall,facing=west,powered=false])
B(-2,38,-3,minecraft:black_wool)
B(-2,-9,-2,minecraft:spruce_planks)
B(-2,-8,-2,minecraft:spruce_planks)
B(-2,-4,-2,minecraft:oak_slab[type=top,waterlogged=false])
B(-2,-1,-2,minecraft:oak_slab[type=top,waterlogged=false])
B(-2,1,-2,minecraft:spruce_stairs[facing=west,half=top,shape=straight,waterlogged=false])
B(-2,4,-2,minecraft:white_wool)
B(-2,6,-2,minecraft:white_wool)
B(-2,13,-2,minecraft:white_wool)
B(-2,14,-2,minecraft:white_wool)
B(-2,15,-2,minecraft:white_wool)
B(-2,16,-2,minecraft:white_wool)
B(-2,21,-2,minecraft:white_wool)
B(-2,23,-2,minecraft:spruce_fence[east=false,north=false,south=false,waterlogged=false,west=true])
B(-2,24,-2,minecraft:spruce_fence[east=true,north=false,south=false,waterlogged=false,west=true])
B(-2,25,-2,minecraft:white_wool)
B(-2,27,-2,minecraft:oak_button[face=wall,facing=west,powered=false])
B(-2,31,-2,minecraft:spruce_fence[east=true,north=false,south=false,waterlogged=false,west=true])
B(-2,-8,-1,minecraft:spruce_planks)
B(-2,-7,-1,minecraft:stone)
B(-2,-4,-1,minecraft:oak_slab[type=top,waterlogged=false])
B(-2,-3,-1,minecraft:orange_bed)
B(-2,-1,-1,minecraft:oak_slab[type=top,waterlogged=false])
B(-2,1,-1,minecraft:spruce_slab[type=top,waterlogged=false])
B(-2,2,-1,minecraft:spruce_slab)
B(-2,4,-1,minecraft:white_wool)
B(-2,6,-1,minecraft:white_wool)
B(-2,12,-1,minecraft:black_wool)
B(-2,13,-1,minecraft:white_wool)
B(-2,14,-1,minecraft:white_wool)
B(-2,16,-1,minecraft:white_wool)
B(-2,17,-1,minecraft:white_wool)
B(-2,21,-1,minecraft:black_wool)
B(-2,27,-1,minecraft:oak_button[face=wall,facing=west,powered=false])
B(-1,-6,-7,minecraft:spruce_planks)
B(-1,-5,-7,minecraft:spruce_planks)
B(-1,-4,-7,minecraft:dark_oak_planks)
B(-1,-3,-7,minecraft:dark_oak_planks)
B(-1,-2,-7,minecraft:oak_planks)
B(-1,-1,-7,minecraft:dark_oak_slab)
B(-1,0,-7,minecraft:dark_oak_stairs[facing=south,half=top,shape=straight,waterlogged=false])
B(-1,5,-7,minecraft:white_wool)
B(-1,14,-7,minecraft:black_wool)
B(-1,21,-7,minecraft:black_wool)
B(-1,25,-7,minecraft:white_wool)
B(-1,27,-7,minecraft:oak_button[face=wall,facing=west,powered=false])
B(-1,-7,-6,minecraft:spruce_planks)
B(-1,-6,-6,minecraft:emerald_ore)
B(-1,-5,-6,minecraft:stone)
B(-1,-4,-6,minecraft:oak_slab[type=top,waterlogged=false])
B(-1,-3,-6,minecraft:oak_button[face=wall,facing=west,powered=false])
B(-1,-1,-6,minecraft:oak_slab[type=top,waterlogged=false])
B(-1,0,-6,minecraft:birch_planks)
B(-1,1,-6,minecraft:stone_button[face=floor,facing=east,powered=false])
B(-1,4,-6,minecraft:white_wool)
B(-1,5,-6,minecraft:white_wool)
B(-1,6,-6,minecraft:white_wool)
B(-1,13,-6,minecraft:black_wool)
B(-1,14,-6,minecraft:black_wool)
B(-1,15,-6,minecraft:black_wool)
B(-1,21,-6,minecraft:black_wool)
B(-1,25,-6,minecraft:white_wool)
B(-1,26,-6,minecraft:white_wool)
B(-1,27,-6,minecraft:oak_button[face=wall,facing=west,powered=false])
B(-1,-7,-5,minecraft:spruce_planks)
B(-1,-6,-5,minecraft:redstone_ore)
B(-1,-5,-5,minecraft:clay)
B(-1,-4,-5,minecraft:oak_slab[type=top,waterlogged=false])
B(-1,-1,-5,minecraft:oak_slab[type=top,waterlogged=false])
B(-1,0,-5,minecraft:birch_planks)
B(-1,1,-5,minecraft:stone_button[face=floor,facing=east,powered=false])
B(-1,4,-5,minecraft:white_wool)
B(-1,5,-5,minecraft:white_wool)
B(-1,6,-5,minecraft:white_wool)
B(-1,13,-5,minecraft:white_wool)
B(-1,14,-5,minecraft:white_wool)
B(-1,15,-5,minecraft:black_wool)
B(-1,16,-5,minecraft:black_wool)
B(-1,21,-5,minecraft:white_wool)
B(-1,27,-5,minecraft:oak_button[face=wall,facing=west,powered=false])
B(-1,-7,-4,minecraft:spruce_planks)
B(-1,-6,-4,minecraft:clay)
B(-1,-4,-4,minecraft:oak_slab[type=top,waterlogged=false])
B(-1,-1,-4,minecraft:oak_slab[type=top,waterlogged=false])
B(-1,0,-4,minecraft:stone_button[face=wall,facing=south,powered=false])
B(-1,4,-4,minecraft:white_wool)
B(-1,6,-4,minecraft:white_wool)
B(-1,7,-4,minecraft:white_wool)
B(-1,12,-4,minecraft:white_wool)
B(-1,13,-4,minecraft:white_wool)
B(-1,15,-4,minecraft:black_wool)
B(-1,16,-4,minecraft:black_wool)
B(-1,17,-4,minecraft:black_wool)
B(-1,26,-4,minecraft:spruce_fence[east=false,north=false,south=false,waterlogged=false,west=true])
B(-1,27,-4,minecraft:spruce_log[axis=z])
B(-1,-8,-3,minecraft:spruce_planks)
B(-1,-4,-3,minecraft:oak_slab[type=top,waterlogged=false])
B(-1,-3,-3,minecraft:light_blue_bed)
B(-1,-1,-3,minecraft:oak_slab[type=top,waterlogged=false])
B(-1,0,-3,minecraft:cobblestone_wall)
B(-1,1,-3,minecraft:oak_fence)
B(-1,2,-3,minecraft:spruce_slab)
B(-1,3,-3,minecraft:spruce_fence[east=false,north=false,south=true,waterlogged=false,west=true])
B(-1,4,-3,minecraft:white_wool)
B(-1,7,-3,minecraft:white_wool)
B(-1,11,-3,minecraft:white_wool)
B(-1,12,-3,minecraft:white_wool)
B(-1,13,-3,minecraft:white_wool)
B(-1,16,-3,minecraft:black_wool)
B(-1,17,-3,minecraft:black_wool)
B(-1,19,-3,minecraft:oak_button[face=wall,facing=west,powered=false])
B(-1,27,-3,minecraft:spruce_log[axis=z])
B(-1,-9,-2,minecraft:spruce_planks)
B(-1,-8,-2,minecraft:spruce_planks)
B(-1,-4,-2,minecraft:oak_slab[type=top,waterlogged=false])
B(-1,-1,-2,minecraft:oak_slab[type=top,waterlogged=false])
B(-1,2,-2,minecraft:spruce_stairs[facing=east,half=bottom,shape=straight,waterlogged=false])
B(-1,3,-2,minecraft:white_wool)
B(-1,7,-2,minecraft:white_wool)
B(-1,11,-2,minecraft:white_wool)
B(-1,12,-2,minecraft:white_wool)
B(-1,14,-2,minecraft:spruce_fence[east=false,north=false,south=false,waterlogged=false,west=true])
B(-1,15,-2,minecraft:spruce_fence[east=false,north=false,south=false,waterlogged=false,west=true])
B(-1,17,-2,minecraft:white_wool)
B(-1,19,-2,minecraft:oak_button[face=wall,facing=west,powered=false])
B(-1,24,-2,minecraft:spruce_fence[east=false,north=false,south=false,waterlogged=false,west=true])
B(-1,25,-2,minecraft:spruce_fence[east=false,north=false,south=false,waterlogged=false,west=true])
B(-1,27,-2,minecraft:dark_oak_planks)
B(-1,31,-2,minecraft:spruce_fence[east=false,north=false,south=false,waterlogged=false,west=true])
B(-1,38,-2,minecraft:black_wool)
B(-1,-8,-1,minecraft:spruce_planks)
B(-1,-7,-1,minecraft:stone)
B(-1,-4,-1,minecraft:oak_slab[type=top,waterlogged=false])
B(-1,-3,-1,minecraft:light_blue_bed)
B(-1,-1,-1,minecraft:oak_slab[type=top,waterlogged=false])
B(-1,0,-1,minecraft:cobblestone_wall)
B(-1,1,-1,minecraft:oak_fence)
B(-1,2,-1,minecraft:spruce_slab)
B(-1,3,-1,minecraft:white_wool)
B(-1,7,-1,minecraft:white_wool)
B(-1,11,-1,minecraft:black_wool)
B(-1,19,-1,minecraft:oak_button[face=wall,facing=west,powered=false])
B(-1,27,-1,minecraft:spruce_log[axis=z])
RB(-2,-7,-3,minecraft:chest[facing=south,type=single,waterlogged=false],../NBT/StructureLoot/JunkChest_1.nbt,15,minecraft:chest[facing=south,type=single,waterlogged=false],../NBT/StructureLoot/JunkChest_2.nbt,15,minecraft:chest[facing=south,type=single,waterlogged=false],../NBT/StructureLoot/JunkChest_3.nbt,15,minecraft:chest[facing=south,type=single,waterlogged=false],../NBT/StructureLoot/JunkChest_4.nbt,15,minecraft:chest[facing=south,type=single,waterlogged=false],../NBT/StructureLoot/JunkChest_5.nbt,15,minecraft:chest[facing=south,type=single,waterlogged=false],../NBT/StructureLoot/Common1.nbt,15,minecraft:chest[facing=south,type=single,waterlogged=false],../NBT/StructureLoot/Common2.nbt,15,minecraft:chest[facing=south,type=single,waterlogged=false],../NBT/StructureLoot/Common3.nbt,15,minecraft:chest[facing=south,type=single,waterlogged=false],../NBT/StructureLoot/Common4.nbt,15,minecraft:chest[facing=south,type=single,waterlogged=false],../NBT/StructureLoot/Common5.nbt,15,minecraft:chest[facing=south,type=single,waterlogged=false],../NBT/StructureLoot/Common6.nbt,15,minecraft:chest[facing=south,type=single,waterlogged=false],../NBT/StructureLoot/Common7.nbt,15,minecraft:chest[facing=south,type=single,waterlogged=false],../NBT/StructureLoot/Common8.nbt,15,minecraft:chest[facing=south,type=single,waterlogged=false],../NBT/StructureLoot/Common9.nbt,15,minecraft:chest[facing=south,type=single,waterlogged=false],../NBT/StructureLoot/Common10.nbt,15,minecraft:chest[facing=south,type=single,waterlogged=false],../NBT/StructureLoot/Common11.nbt,15,minecraft:chest[facing=south,type=single,waterlogged=false],../NBT/StructureLoot/Common12.nbt,15,minecraft:chest[facing=south,type=single,waterlogged=false],../NBT/StructureLoot/Common13.nbt,15,minecraft:chest[facing=south,type=single,waterlogged=false],../NBT/StructureLoot/Common14.nbt,15,minecraft:chest[facing=south,type=single,waterlogged=false],../NBT/StructureLoot/Common15.nbt,100)
RB(-1,-7,-3,minecraft:chest[facing=south,type=single,waterlogged=false],../NBT/StructureLoot/JunkChest_1.nbt,15,minecraft:chest[facing=south,type=single,waterlogged=false],../NBT/StructureLoot/JunkChest_2.nbt,15,minecraft:chest[facing=south,type=single,waterlogged=false],../NBT/StructureLoot/JunkChest_3.nbt,15,minecraft:chest[facing=south,type=single,waterlogged=false],../NBT/StructureLoot/JunkChest_4.nbt,15,minecraft:chest[facing=south,type=single,waterlogged=false],../NBT/StructureLoot/JunkChest_5.nbt,15,minecraft:chest[facing=south,type=single,waterlogged=false],../NBT/StructureLoot/Common1.nbt,15,minecraft:chest[facing=south,type=single,waterlogged=false],../NBT/StructureLoot/Common2.nbt,15,minecraft:chest[facing=south,type=single,waterlogged=false],../NBT/StructureLoot/Common3.nbt,15,minecraft:chest[facing=south,type=single,waterlogged=false],../NBT/StructureLoot/Common4.nbt,15,minecraft:chest[facing=south,type=single,waterlogged=false],../NBT/StructureLoot/Common5.nbt,15,minecraft:chest[facing=south,type=single,waterlogged=false],../NBT/StructureLoot/Common6.nbt,15,minecraft:chest[facing=south,type=single,waterlogged=false],../NBT/StructureLoot/Common7.nbt,15,minecraft:chest[facing=south,type=single,waterlogged=false],../NBT/StructureLoot/Common8.nbt,15,minecraft:chest[facing=south,type=single,waterlogged=false],../NBT/StructureLoot/Common9.nbt,15,minecraft:chest[facing=south,type=single,waterlogged=false],../NBT/StructureLoot/Common10.nbt,15,minecraft:chest[facing=south,type=single,waterlogged=false],../NBT/StructureLoot/Common11.nbt,15,minecraft:chest[facing=south,type=single,waterlogged=false],../NBT/StructureLoot/Common12.nbt,15,minecraft:chest[facing=south,type=single,waterlogged=false],../NBT/StructureLoot/Common13.nbt,15,minecraft:chest[facing=south,type=single,waterlogged=false],../NBT/StructureLoot/Common14.nbt,15,minecraft:chest[facing=south,type=single,waterlogged=false],../NBT/StructureLoot/Common15.nbt,100)
RB(-3,-6,-4,minecraft:chest[facing=south,type=single,waterlogged=false],../NBT/StructureLoot/JunkChest_1.nbt,15,minecraft:chest[facing=south,type=single,waterlogged=false],../NBT/StructureLoot/JunkChest_2.nbt,15,minecraft:chest[facing=south,type=single,waterlogged=false],../NBT/StructureLoot/JunkChest_3.nbt,15,minecraft:chest[facing=south,type=single,waterlogged=false],../NBT/StructureLoot/JunkChest_4.nbt,15,minecraft:chest[facing=south,type=single,waterlogged=false],../NBT/StructureLoot/JunkChest_5.nbt,15,minecraft:chest[facing=south,type=single,waterlogged=false],../NBT/StructureLoot/Common1.nbt,15,minecraft:chest[facing=south,type=single,waterlogged=false],../NBT/StructureLoot/Common2.nbt,15,minecraft:chest[facing=south,type=single,waterlogged=false],../NBT/StructureLoot/Common3.nbt,15,minecraft:chest[facing=south,type=single,waterlogged=false],../NBT/StructureLoot/Common4.nbt,15,minecraft:chest[facing=south,type=single,waterlogged=false],../NBT/StructureLoot/Common5.nbt,15,minecraft:chest[facing=south,type=single,waterlogged=false],../NBT/StructureLoot/Common6.nbt,15,minecraft:chest[facing=south,type=single,waterlogged=false],../NBT/StructureLoot/Common7.nbt,15,minecraft:chest[facing=south,type=single,waterlogged=false],../NBT/StructureLoot/Common8.nbt,15,minecraft:chest[facing=south,type=single,waterlogged=false],../NBT/StructureLoot/Common9.nbt,15,minecraft:chest[facing=south,type=single,waterlogged=false],../NBT/StructureLoot/Common10.nbt,15,minecraft:chest[facing=south,type=single,waterlogged=false],../NBT/StructureLoot/Common11.nbt,15,minecraft:chest[facing=south,type=single,waterlogged=false],../NBT/StructureLoot/Common12.nbt,15,minecraft:chest[facing=south,type=single,waterlogged=false],../NBT/StructureLoot/Common13.nbt,15,minecraft:chest[facing=south,type=single,waterlogged=false],../NBT/StructureLoot/Common14.nbt,15,minecraft:chest[facing=south,type=single,waterlogged=false],../NBT/StructureLoot/Common15.nbt,100)
RB(-2,-6,-4,minecraft:chest[facing=south,type=single,waterlogged=false],../NBT/StructureLoot/JunkChest_1.nbt,15,minecraft:chest[facing=south,type=single,waterlogged=false],../NBT/StructureLoot/JunkChest_2.nbt,15,minecraft:chest[facing=south,type=single,waterlogged=false],../NBT/StructureLoot/JunkChest_3.nbt,15,minecraft:chest[facing=south,type=single,waterlogged=false],../NBT/StructureLoot/JunkChest_4.nbt,15,minecraft:chest[facing=south,type=single,waterlogged=false],../NBT/StructureLoot/JunkChest_5.nbt,15,minecraft:chest[facing=south,type=single,waterlogged=false],../NBT/StructureLoot/Common1.nbt,15,minecraft:chest[facing=south,type=single,waterlogged=false],../NBT/StructureLoot/Common2.nbt,15,minecraft:chest[facing=south,type=single,waterlogged=false],../NBT/StructureLoot/Common3.nbt,15,minecraft:chest[facing=south,type=single,waterlogged=false],../NBT/StructureLoot/Common4.nbt,15,minecraft:chest[facing=south,type=single,waterlogged=false],../NBT/StructureLoot/Common5.nbt,15,minecraft:chest[facing=south,type=single,waterlogged=false],../NBT/StructureLoot/Common6.nbt,15,minecraft:chest[facing=south,type=single,waterlogged=false],../NBT/StructureLoot/Common7.nbt,15,minecraft:chest[facing=south,type=single,waterlogged=false],../NBT/StructureLoot/Common8.nbt,15,minecraft:chest[facing=south,type=single,waterlogged=false],../NBT/StructureLoot/Common9.nbt,15,minecraft:chest[facing=south,type=single,waterlogged=false],../NBT/StructureLoot/Common10.nbt,15,minecraft:chest[facing=south,type=single,waterlogged=false],../NBT/StructureLoot/Common11.nbt,15,minecraft:chest[facing=south,type=single,waterlogged=false],../NBT/StructureLoot/Common12.nbt,15,minecraft:chest[facing=south,type=single,waterlogged=false],../NBT/StructureLoot/Common13.nbt,15,minecraft:chest[facing=south,type=single,waterlogged=false],../NBT/StructureLoot/Common14.nbt,15,minecraft:chest[facing=south,type=single,waterlogged=false],../NBT/StructureLoot/Common15.nbt,100)
RB(-6,-5,-5,minecraft:chest[facing=south,type=single,waterlogged=false],../NBT/StructureLoot/JunkChest_1.nbt,15,minecraft:chest[facing=south,type=single,waterlogged=false],../NBT/StructureLoot/JunkChest_2.nbt,15,minecraft:chest[facing=south,type=single,waterlogged=false],../NBT/StructureLoot/JunkChest_3.nbt,15,minecraft:chest[facing=south,type=single,waterlogged=false],../NBT/StructureLoot/JunkChest_4.nbt,15,minecraft:chest[facing=south,type=single,waterlogged=false],../NBT/StructureLoot/JunkChest_5.nbt,15,minecraft:chest[facing=south,type=single,waterlogged=false],../NBT/StructureLoot/Common1.nbt,15,minecraft:chest[facing=south,type=single,waterlogged=false],../NBT/StructureLoot/Common2.nbt,15,minecraft:chest[facing=south,type=single,waterlogged=false],../NBT/StructureLoot/Common3.nbt,15,minecraft:chest[facing=south,type=single,waterlogged=false],../NBT/StructureLoot/Common4.nbt,15,minecraft:chest[facing=south,type=single,waterlogged=false],../NBT/StructureLoot/Common5.nbt,15,minecraft:chest[facing=south,type=single,waterlogged=false],../NBT/StructureLoot/Common6.nbt,15,minecraft:chest[facing=south,type=single,waterlogged=false],../NBT/StructureLoot/Common7.nbt,15,minecraft:chest[facing=south,type=single,waterlogged=false],../NBT/StructureLoot/Common8.nbt,15,minecraft:chest[facing=south,type=single,waterlogged=false],../NBT/StructureLoot/Common9.nbt,15,minecraft:chest[facing=south,type=single,waterlogged=false],../NBT/StructureLoot/Common10.nbt,15,minecraft:chest[facing=south,type=single,waterlogged=false],../NBT/StructureLoot/Common11.nbt,15,minecraft:chest[facing=south,type=single,waterlogged=false],../NBT/StructureLoot/Common12.nbt,15,minecraft:chest[facing=south,type=single,waterlogged=false],../NBT/StructureLoot/Common13.nbt,15,minecraft:chest[facing=south,type=single,waterlogged=false],../NBT/StructureLoot/Common14.nbt,15,minecraft:chest[facing=south,type=single,waterlogged=false],../NBT/StructureLoot/Common15.nbt,100)
RB(-5,-5,-5,minecraft:chest[facing=south,type=single,waterlogged=false],../NBT/StructureLoot/JunkChest_1.nbt,15,minecraft:chest[facing=south,type=single,waterlogged=false],../NBT/StructureLoot/JunkChest_2.nbt,15,minecraft:chest[facing=south,type=single,waterlogged=false],../NBT/StructureLoot/JunkChest_3.nbt,15,minecraft:chest[facing=south,type=single,waterlogged=false],../NBT/StructureLoot/JunkChest_4.nbt,15,minecraft:chest[facing=south,type=single,waterlogged=false],../NBT/StructureLoot/JunkChest_5.nbt,15,minecraft:chest[facing=south,type=single,waterlogged=false],../NBT/StructureLoot/Common1.nbt,15,minecraft:chest[facing=south,type=single,waterlogged=false],../NBT/StructureLoot/Common2.nbt,15,minecraft:chest[facing=south,type=single,waterlogged=false],../NBT/StructureLoot/Common3.nbt,15,minecraft:chest[facing=south,type=single,waterlogged=false],../NBT/StructureLoot/Common4.nbt,15,minecraft:chest[facing=south,type=single,waterlogged=false],../NBT/StructureLoot/Common5.nbt,15,minecraft:chest[facing=south,type=single,waterlogged=false],../NBT/StructureLoot/Common6.nbt,15,minecraft:chest[facing=south,type=single,waterlogged=false],../NBT/StructureLoot/Common7.nbt,15,minecraft:chest[facing=south,type=single,waterlogged=false],../NBT/StructureLoot/Common8.nbt,15,minecraft:chest[facing=south,type=single,waterlogged=false],../NBT/StructureLoot/Common9.nbt,15,minecraft:chest[facing=south,type=single,waterlogged=false],../NBT/StructureLoot/Common10.nbt,15,minecraft:chest[facing=south,type=single,waterlogged=false],../NBT/StructureLoot/Common11.nbt,15,minecraft:chest[facing=south,type=single,waterlogged=false],../NBT/StructureLoot/Common12.nbt,15,minecraft:chest[facing=south,type=single,waterlogged=false],../NBT/StructureLoot/Common13.nbt,15,minecraft:chest[facing=south,type=single,waterlogged=false],../NBT/StructureLoot/Common14.nbt,15,minecraft:chest[facing=south,type=single,waterlogged=false],../NBT/StructureLoot/Common15.nbt,100)

#######################################################################
# +-----------------------------------------------------------------+ #
# |                            BO3 checks                           | #
# +-----------------------------------------------------------------+ #
#######################################################################


#######################################################################
# +-----------------------------------------------------------------+ #
# |                             Branches                            | #
# +-----------------------------------------------------------------+ #
#######################################################################

Branch(-8,0,0,WestPortShipAgile_5x3,NORTH,100.0)

#######################################################################
# +-----------------------------------------------------------------+ #
# |                             Entities                            | #
# +-----------------------------------------------------------------+ #
#######################################################################

Entity(-4,-2,-4,minecraft:villager,1,../NBT/MOBS/RandomVillager.txt)
