

Author: BO3 BulkEdit (by LanToaster)

Description: Vines Created by NLBlackEagle for Dregora

Version: 3

SettingsMode: WriteDisable


Tree: false

Frequency: 200

Rarity: 100.0

RotateRandomly: true

SpawnHeight: randomY

MinHeight: 110

MaxHeight: 120

MaxBranchDepth: 10

ExcludedBiomes: All


SourceBlocks: AIR

MaxPercentageOutsideSourceBlock: 100

OutsideSourceBlock: placeAnyway


Block(-2,0,-6,COBBLESTONE:0)
Block(-1,0,-6,COBBLESTONE:0)
Block(0,0,-6,COBBLESTONE:0)
Block(1,0,-6,COBBLESTONE:0)
Block(2,0,-6,COBBLESTONE:0)
Block(3,0,-6,COBBLESTONE:0)
Block(4,0,-6,COBBLESTONE:0)
Block(5,0,-6,COBBLESTONE:0)
Block(6,0,-6,COBBLESTONE:0)
Block(-3,0,-5,STONE:0)
Block(-2,0,-5,COBBLESTONE:0)
Block(-1,0,-5,STONE:0)
Block(0,0,-5,WOODEN_SLAB:11)
Block(1,0,-5,WOODEN_SLAB:11)
Block(2,0,-5,STONE:0)
Block(3,0,-5,WOODEN_SLAB:11)
Block(4,0,-5,STONE:0)
Block(5,0,-5,WOODEN_SLAB:11)
Block(6,0,-5,COBBLESTONE:0)
Block(-5,0,-4,STONE:0)
Block(-4,0,-4,STONE:0)
Block(-3,0,-4,STONE:0)
Block(-2,0,-4,STONE:0)
Block(-1,0,-4,STONE:0)
Block(0,0,-4,WOODEN_SLAB:11)
Block(1,0,-4,STONE:0)
Block(2,0,-4,STONE:0)
Block(3,0,-4,WOODEN_SLAB:11)
Block(4,0,-4,WOODEN_SLAB:11)
Block(5,0,-4,WOODEN_SLAB:11)
Block(6,0,-4,COBBLESTONE:0)
Block(7,0,-4,STONE:0)
Block(-6,0,-3,STONE:0)
Block(-5,0,-3,STONE:0)
Block(-4,0,-3,STONE:0)
Block(-3,0,-3,STONE:0)
Block(-2,0,-3,STONE:0)
Block(-1,0,-3,STONE:0)
Block(0,0,-3,STONE:0)
Block(1,0,-3,STONE:0)
Block(2,0,-3,STONE:0)
Block(3,0,-3,WOODEN_SLAB:11)
Block(4,0,-3,STONE:0)
Block(5,0,-3,STONE:0)
Block(6,0,-3,COBBLESTONE:0)
Block(7,0,-3,STONE:0)
Block(8,0,-3,STONE:0)
Block(-6,0,-2,STONE:0)
Block(-5,0,-2,MAGMA:0)
Block(-4,0,-2,STONE:0)
Block(-3,0,-2,WOODEN_SLAB:11)
Block(-2,0,-2,WOODEN_SLAB:11)
Block(-1,0,-2,STONE:0)
Block(0,0,-2,WOODEN_SLAB:11)
Block(1,0,-2,STONE:0)
Block(2,0,-2,WOODEN_SLAB:11)
Block(3,0,-2,WOODEN_SLAB:11)
Block(4,0,-2,WOODEN_SLAB:11)
Block(5,0,-2,WOODEN_SLAB:11)
Block(6,0,-2,COBBLESTONE:0)
Block(7,0,-2,STONE:0)
Block(8,0,-2,STONE:0)
Block(-6,0,-1,STONE:0)
Block(-5,0,-1,STONE:0)
Block(-4,0,-1,STONE:0)
Block(-3,0,-1,WOODEN_SLAB:11)
Block(-2,0,-1,STONE:0)
Block(-1,0,-1,STONE:0)
Block(0,0,-1,WOODEN_SLAB:11)
Block(1,0,-1,WOODEN_SLAB:11)
Block(2,0,-1,WOODEN_SLAB:11)
Block(3,0,-1,WOODEN_SLAB:11)
Block(4,0,-1,WOODEN_SLAB:11)
Block(5,0,-1,WOODEN_SLAB:11)
Block(6,0,-1,COBBLESTONE:0)
Block(7,0,-1,STONE:0)
Block(-6,0,0,STONE:0)
Block(-5,0,0,STONE:0)
Block(-4,0,0,STONE:0)
Block(-3,0,0,STONE:0)
Block(-2,0,0,COBBLESTONE:0)
Block(-1,0,0,STONE:0)
Block(1,0,0,WOODEN_SLAB:11)
Block(2,0,0,STONE:0)
Block(3,0,0,WOODEN_SLAB:11)
Block(4,0,0,COBBLESTONE:0)
Block(5,0,0,COBBLESTONE:0)
Block(6,0,0,COBBLESTONE:0)
Block(7,0,0,STONE:0)
Block(-5,0,1,STONE:0)
Block(-4,0,1,STONE:0)
Block(-3,0,1,STONE:0)
Block(-2,0,1,COBBLESTONE:0)
Block(-1,0,1,WOODEN_SLAB:11)
Block(0,0,1,WOODEN_SLAB:11)
Block(1,0,1,WOODEN_SLAB:11)
Block(2,0,1,WOODEN_SLAB:11)
Block(3,0,1,WOODEN_SLAB:11)
Block(4,0,1,COBBLESTONE:0)
Block(5,0,1,STONE:0)
Block(6,0,1,STONE:0)
Block(7,0,1,STONE:0)
Block(-2,0,2,COBBLESTONE:0)
Block(-1,0,2,WOODEN_SLAB:11)
Block(0,0,2,WOODEN_SLAB:11)
Block(1,0,2,STONE:0)
Block(2,0,2,STONE:0)
Block(3,0,2,WOODEN_SLAB:11)
Block(4,0,2,COBBLESTONE:0)
Block(-2,0,3,COBBLESTONE:0)
Block(-1,0,3,COBBLESTONE:0)
Block(0,0,3,COBBLESTONE:0)
Block(1,0,3,COBBLESTONE:0)
Block(2,0,3,COBBLESTONE:0)
Block(3,0,3,COBBLESTONE:0)
Block(4,0,3,COBBLESTONE:0)
Block(-2,0,4,WOODEN_SLAB:11)
Block(-1,0,4,DOUBLE_WOODEN_SLAB:3)
Block(0,0,4,WOODEN_SLAB:11)
Block(1,0,4,WOODEN_SLAB:11)
Block(2,0,4,WOODEN_SLAB:11)
Block(3,0,4,DOUBLE_WOODEN_SLAB:3)
Block(4,0,4,WOODEN_SLAB:11)
Block(-2,0,5,WOODEN_SLAB:11)
Block(-1,0,5,WOODEN_SLAB:11)
Block(0,0,5,WOODEN_SLAB:11)
Block(1,0,5,DOUBLE_WOODEN_SLAB:3)
Block(2,0,5,WOODEN_SLAB:11)
Block(3,0,5,DOUBLE_WOODEN_SLAB:3)
Block(4,0,5,WOODEN_SLAB:11)
Block(0,0,6,WOODEN_SLAB:11)
Block(1,0,6,WOODEN_SLAB:11)
Block(2,0,6,WOODEN_SLAB:11)
Block(3,0,6,WOODEN_SLAB:11)
Block(-2,1,-6,COBBLESTONE:0)
Block(-1,1,-6,COBBLESTONE:0)
Block(0,1,-6,STONE:0)
Block(1,1,-6,COBBLESTONE:0)
Block(2,1,-6,COBBLESTONE:0)
Block(3,1,-6,STONE:0)
Block(4,1,-6,STONE:0)
Block(5,1,-6,STONE:0)
Block(6,1,-6,COBBLESTONE:0)
Block(-3,1,-5,STONE:0)
Block(-2,1,-5,STONE:0)
Block(-1,1,-5,STONE:0)
Block(0,1,-5,BOOKSHELF:0)
Block(1,1,-5,JUNGLE_FENCE:0)
Block(2,1,-5,AIR)
Block(3,1,-5,AIR)
RandomBlock(4,1,-5,CHEST:3,./StructureNBT/StructureLoot/JunkChest_1.nbt,20,CHEST:3,./StructureNBT/StructureLoot/JunkChest_2.nbt,15,CHEST:3,./StructureNBT/StructureLoot/JunkChest_3.nbt,15,CHEST:3,./StructureNBT/StructureLoot/JunkChest_4.nbt,15,CHEST:3,./StructureNBT/StructureLoot/JunkChest_5.nbt,15,CHEST:3,./StructureNBT/StructureLoot/Common1.nbt,25,CHEST:3,./StructureNBT/StructureLoot/Common2.nbt,25,CHEST:3,./StructureNBT/StructureLoot/Common3.nbt,25,CHEST:3,./StructureNBT/StructureLoot/Common4.nbt,25,CHEST:3,./StructureNBT/StructureLoot/Common5.nbt,25,CHEST:3,./StructureNBT/StructureLoot/Common6.nbt,25,CHEST:3,./StructureNBT/StructureLoot/Common7.nbt,25,CHEST:3,./StructureNBT/StructureLoot/Common8.nbt,25,CHEST:3,./StructureNBT/StructureLoot/Common9.nbt,25,CHEST:3,./StructureNBT/StructureLoot/Common10.nbt,25,CHEST:3,./StructureNBT/StructureLoot/Common11.nbt,25,CHEST:3,./StructureNBT/StructureLoot/Common12.nbt,25,CHEST:3,./StructureNBT/StructureLoot/Common13.nbt,25,CHEST:3,./StructureNBT/StructureLoot/Common14.nbt,25,CHEST:3,./StructureNBT/StructureLoot/Common15.nbt,25,CHEST:3,./StructureNBT/StructureLoot/Rare1.nbt,10,CHEST:3,./StructureNBT/StructureLoot/Rare2.nbt,10,CHEST:3,./StructureNBT/StructureLoot/Rare3.nbt,10,CHEST:3,./StructureNBT/StructureLoot/Rare4.nbt,10,CHEST:3,./StructureNBT/StructureLoot/Rare5.nbt,10,CHEST:3,./StructureNBT/StructureLoot/Rare6.nbt,10,CHEST:3,./StructureNBT/StructureLoot/Rare7.nbt,10,CHEST:3,./StructureNBT/StructureLoot/Rare8.nbt,10,CHEST:3,./StructureNBT/StructureLoot/Rare9.nbt,10,CHEST:3,./StructureNBT/StructureLoot/Rare10.nbt,10,CHEST:3,./StructureNBT/StructureLoot/Rare11.nbt,10,CHEST:3,./StructureNBT/StructureLoot/Rare12.nbt,10,CHEST:3,./StructureNBT/StructureLoot/Rare13.nbt,10,CHEST:3,./StructureNBT/StructureLoot/Rare14.nbt,10,CHEST:3,./StructureNBT/StructureLoot/Rare15.nbt,10,CHEST:3,./StructureNBT/StructureLoot/Common15.nbt,100)
Block(5,1,-5,JUNGLE_FENCE:0)
Block(6,1,-5,STONE:0)
Block(-5,1,-4,STONE:0)
Block(-4,1,-4,STONE:0)
Block(-3,1,-4,STONE:0)
Block(-2,1,-4,FURNACE:3)
Block(-1,1,-4,CRAFTING_TABLE:0)
Block(0,1,-4,AIR)
Block(1,1,-4,BIRCH_DOOR:1)
Block(2,1,-4,BIRCH_DOOR:1)
Block(3,1,-4,BIRCH_DOOR:1)
Block(4,1,-4,BIRCH_DOOR:1)
Block(5,1,-4,COBBLESTONE_WALL:0)
Block(6,1,-4,COBBLESTONE:0)
Block(7,1,-4,STONE:0)
Block(-6,1,-3,STONE:0)
Block(-5,1,-3,COBBLESTONE:0)
Block(-4,1,-3,STONE_STAIRS:1)

Block(-5,1,-2,FIRE)

Block(-3,1,-1,IRON_BARS:0)
Block(-3,1,-2,IRON_BARS:0)
Block(-3,1,-3,IRON_BARS:0)
Block(-5,6,-2,IRON_BARS:0)
Block(-5,3,-2,IRON_BARS:0)
Block(2,2,3,IRON_BARS:0)
Block(3,2,3,IRON_BARS:0)

Block(-2,1,-3,AIR)
Block(-1,1,-3,AIR)
Block(0,1,-3,AIR)
Block(1,1,-3,AIR)
Block(2,1,-3,AIR)
Block(3,1,-3,AIR)
Block(4,1,-3,AIR)
Block(5,1,-3,AIR)
Block(6,1,-3,BED:3)
Block(7,1,-3,BED:11)
Block(8,1,-3,STONE:0)
Block(-6,1,-2,STONE:0)

Block(-4,1,-2,AIR)
Block(-2,1,-2,AIR)
Block(-1,1,-2,AIR)
Block(0,1,-2,AIR)
Block(1,1,-2,AIR)
Block(2,1,-2,AIR)
Block(3,1,-2,JUNGLE_STAIRS:3)
Block(4,1,-2,AIR)
Block(5,1,-2,AIR)
Block(6,1,-2,BED:3)
Block(7,1,-2,BED:11)
Block(8,1,-2,STONE:0)
Block(-6,1,-1,STONE:0)
Block(-5,1,-1,COBBLESTONE:0)
Block(-4,1,-1,STONE_STAIRS:1)
Block(-2,1,-1,CAULDRON:3)
Block(-1,1,-1,PLANKS:3)
Block(0,1,-1,AIR)
Block(1,1,-1,AIR)
Block(2,1,-1,JUNGLE_FENCE:0)
Block(3,1,-1,JUNGLE_FENCE:0)
Block(4,1,-1,JUNGLE_FENCE:0)
Block(5,1,-1,PLANKS:3)
Block(6,1,-1,AIR)
Block(7,1,-1,STONE:0)
Block(-6,1,0,STONE:0)
Block(-4,1,0,STONE:0)
Block(-3,1,0,STONE:0)
Block(-2,1,0,COBBLESTONE:0)
Block(-1,1,0,COBBLESTONE_WALL:0)
Block(0,1,0,AIR)
Block(1,1,0,AIR)
Block(2,1,0,JUNGLE_STAIRS:2)
Block(3,1,0,AIR)
Block(4,1,0,COBBLESTONE:0)
Block(5,1,0,COBBLESTONE:0)
Block(6,1,0,STONE:0)
Block(7,1,0,STONE:0)
Block(-5,1,1,STONE:0)
Block(-4,1,1,STONE:0)
Block(-3,1,1,STONE:0)
Block(-2,1,1,STONE:0)
Block(-1,1,1,JUNGLE_FENCE:0)
Block(0,1,1,AIR)
Block(1,1,1,AIR)
Block(2,1,1,AIR)
Block(3,1,1,AIR)
Block(4,1,1,COBBLESTONE:0)
Block(5,1,1,STONE:0)
Block(6,1,1,STONE:0)
Block(7,1,1,STONE:0)
Block(-2,1,2,STONE:0)
Block(-1,1,2,AIR)
Block(0,1,2,AIR)
Block(1,1,2,JUNGLE_STAIRS:5)
Block(2,1,2,WOODEN_SLAB:11)
Block(3,1,2,WOODEN_SLAB:11)
Block(4,1,2,COBBLESTONE:0)
Block(-2,1,3,COBBLESTONE:0)
Block(-1,1,3,COBBLESTONE:0)
Block(0,1,3,JUNGLE_DOOR:1)
Block(1,1,3,COBBLESTONE:0)
Block(2,1,3,COBBLESTONE:0)
Block(3,1,3,COBBLESTONE:0)
Block(4,1,3,COBBLESTONE:0)
Block(-2,1,4,JUNGLE_FENCE_GATE:3)
Block(-1,1,4,AIR)
Block(0,1,4,AIR)
Block(1,1,4,AIR)
Block(2,1,4,AIR)
Block(3,1,4,AIR)
Block(4,1,4,JUNGLE_FENCE_GATE:1)
Block(-2,1,5,JUNGLE_FENCE:0)
Block(-1,1,5,JUNGLE_FENCE:0)
Block(0,1,5,JUNGLE_FENCE:0)
Block(1,1,5,AIR)
Block(2,1,5,AIR)
Block(3,1,5,JUNGLE_FENCE:0)
Block(4,1,5,JUNGLE_FENCE:0)
Block(0,1,6,JUNGLE_FENCE:0)
Block(1,1,6,JUNGLE_FENCE:0)
Block(2,1,6,JUNGLE_FENCE_GATE:2)
Block(3,1,6,JUNGLE_FENCE:0)
Block(-2,2,-6,COBBLESTONE:0)
Block(-1,2,-6,COBBLESTONE:0)
Block(0,2,-6,STONE:0)
Block(1,2,-6,COBBLESTONE:0)
Block(2,2,-6,COBBLESTONE:0)
Block(3,2,-6,STONE:0)
Block(4,2,-6,STONE:0)
Block(5,2,-6,STONE:0)
Block(-3,2,-5,STONE:0)
Block(-2,2,-5,STONE:0)
Block(-1,2,-5,STONE:0)
Block(0,2,-5,BOOKSHELF:0)
Block(1,2,-5,JUNGLE_FENCE:0)
Block(2,2,-5,AIR)
Entity(2,2,-5,armor_stand,1,./StructureNBT/Mobs/Armorstand.txt)
Block(3,2,-5,AIR)
Entity(3,2,-5,armor_stand,1,./StructureNBT/Mobs/Armorstand.txt)
Block(4,2,-5,AIR)
Block(5,2,-5,JUNGLE_FENCE:0)
Block(6,2,-5,STONE:0)
Block(-5,2,-4,STONE:0)
Block(-4,2,-4,STONE:0)
Block(-3,2,-4,STONE:0)
Block(-2,2,-4,TRAPDOOR:5)
Block(-1,2,-4,TRAPDOOR:5)
Block(0,2,-4,AIR)
Block(1,2,-4,BIRCH_DOOR:9)
Block(2,2,-4,BIRCH_DOOR:8)
Block(3,2,-4,BIRCH_DOOR:9)
Block(4,2,-4,BIRCH_DOOR:8)
Block(5,2,-4,TORCH:5)
Block(6,2,-4,STONE:0)
Block(7,2,-4,STONE:0)
Block(-6,2,-3,STONE:0)
Block(-5,2,-3,COBBLESTONE:0)
Block(-4,2,-3,STONE_STAIRS:5)
Block(-3,2,-3,AIR)
Block(-2,2,-3,AIR)
Block(-1,2,-3,AIR)
Block(0,2,-3,AIR)
Block(1,2,-3,AIR)
Entity(1,2,-3,VILLAGER,1,./StructureNBT/Mobs/VillagerParent.txt)
Block(2,2,-3,AIR)
Entity(2,2,-3,VILLAGER,1,./StructureNBT/Mobs/VillagerParent.txt)
Block(3,2,-3,AIR)
Block(4,2,-3,AIR)
Block(5,2,-3,AIR)
Block(6,2,-3,AIR)
Block(7,2,-3,AIR)
Block(8,2,-3,STONE:0)
Block(-6,2,-2,STONE:0)
Block(-5,2,-2,AIR)
Block(-4,2,-2,AIR)
Block(-3,2,-2,AIR)
Block(-2,2,-2,AIR)
Block(-1,2,-2,AIR)
Block(0,2,-2,AIR)
Block(1,2,-2,AIR)
Entity(1,2,-2,VILLAGER,1,./StructureNBT/Mobs/VillagerKid.txt)
Block(2,2,-2,AIR)
Block(3,2,-2,AIR)
Block(4,2,-2,AIR)
Block(5,2,-2,AIR)
Block(6,2,-2,AIR)
Block(7,2,-2,AIR)
Block(8,2,-2,STONE:0)
Block(-6,2,-1,STONE:0)
Block(-5,2,-1,COBBLESTONE:0)
Block(-4,2,-1,STONE_STAIRS:5)
Block(-3,2,-1,AIR)
Block(-2,2,-1,AIR)
Block(-1,2,-1,PLANKS:3)
Block(0,2,-1,AIR)
Block(1,2,-1,AIR)
Block(2,2,-1,CARPET:13)
Block(3,2,-1,CARPET:13)
Block(4,2,-1,CARPET:13)
Block(5,2,-1,PLANKS:3)
Block(6,2,-1,AIR)
Block(7,2,-1,STONE:0)
Block(-6,2,0,STONE:0)
Block(-5,2,0,STONE:0)
Block(-4,2,0,STONE:0)
Block(-3,2,0,STONE:0)
Block(-2,2,0,STONE:0)
Block(-1,2,0,TORCH:5)
Block(0,2,0,AIR)
Block(1,2,0,AIR)
Block(2,2,0,AIR)
Block(3,2,0,AIR)
RandomBlock(4,2,0,FLOWER_POT:0,./StructureNBT/Flowers/flower_pot_01.nbt,20,FLOWER_POT:0,./StructureNBT/Flowers/flower_pot_02.nbt,5,FLOWER_POT:0,./StructureNBT/Flowers/flower_pot_03.nbt,5,FLOWER_POT:0,./StructureNBT/Flowers/flower_pot_04.nbt,5,FLOWER_POT:0,./StructureNBT/Flowers/flower_pot_05.nbt,5,FLOWER_POT:0,./StructureNBT/Flowers/flower_pot_06.nbt,5,FLOWER_POT:0,./StructureNBT/Flowers/flower_pot_07.nbt,5,FLOWER_POT:0,./StructureNBT/Flowers/flower_pot_08.nbt,5,FLOWER_POT:0,./StructureNBT/Flowers/flower_pot_09.nbt,5,FLOWER_POT:0,./StructureNBT/Flowers/flower_pot_10.nbt,5,FLOWER_POT:0,./StructureNBT/Flowers/flower_pot_11.nbt,5,FLOWER_POT:0,./StructureNBT/Flowers/flower_pot_12.nbt,5,FLOWER_POT:0,./StructureNBT/Flowers/flower_pot_13.nbt,5,FLOWER_POT:0,./StructureNBT/Flowers/flower_pot_14.nbt,5,FLOWER_POT:0,./StructureNBT/Flowers/flower_pot_15.nbt,5,FLOWER_POT:0,./StructureNBT/Flowers/flower_pot_16.nbt,5,FLOWER_POT:0,./StructureNBT/Flowers/flower_pot_17.nbt,5,FLOWER_POT:0,./StructureNBT/Flowers/flower_pot_18.nbt,5,FLOWER_POT:0,./StructureNBT/Flowers/flower_pot_19.nbt,5,FLOWER_POT:0,./StructureNBT/Flowers/flower_pot_20.nbt,100)
Block(5,2,0,AIR)
Block(6,2,0,STONE:0)
Block(7,2,0,STONE:0)
Block(-5,2,1,STONE:0)
Block(-4,2,1,STONE:0)
Block(-3,2,1,STONE:0)
Block(-2,2,1,STONE:0)
Block(-1,2,1,JUNGLE_FENCE:0)
Block(0,2,1,AIR)
Block(1,2,1,AIR)
Block(2,2,1,AIR)
Block(3,2,1,AIR)
Block(4,2,1,COBBLESTONE:0)
Block(5,2,1,STONE:0)
Block(6,2,1,STONE:0)
Block(7,2,1,STONE:0)
Block(-2,2,2,STONE:0)
Block(-1,2,2,AIR)
Block(0,2,2,AIR)
Block(1,2,2,AIR)
Block(2,2,2,AIR)
Block(3,2,2,AIR)
Block(4,2,2,COBBLESTONE:0)
Block(-2,2,3,COBBLESTONE:0)
Block(-1,2,3,COBBLESTONE:0)
Block(0,2,3,JUNGLE_DOOR:9)
Block(1,2,3,COBBLESTONE:0)

Block(4,2,3,COBBLESTONE:0)
Block(-1,2,4,AIR)
Block(0,2,4,AIR)
Block(1,2,4,AIR)
Block(2,2,4,TRAPDOOR:9)
Block(3,2,4,TRAPDOOR:9)
Block(4,2,4,AIR)
Block(1,2,5,AIR)
Block(2,2,5,AIR)
Block(0,3,-6,STONE:0)
Block(1,3,-6,STONE:0)
Block(2,3,-6,STONE:0)
Block(0,3,-5,STONE:0)
Block(1,3,-5,STONE:0)
Block(2,3,-5,STONE:0)
Block(3,3,-5,STONE:0)
Block(4,3,-5,STONE:0)
Block(5,3,-5,STONE:0)
Block(-3,3,-4,STONE:0)
Block(-2,3,-4,STONE:0)
Block(-1,3,-4,STONE:0)
Block(0,3,-4,STONE:0)
Block(1,3,-4,JUNGLE_STAIRS:7)
Block(2,3,-4,JUNGLE_STAIRS:7)
Block(3,3,-4,JUNGLE_STAIRS:7)
Block(4,3,-4,JUNGLE_STAIRS:7)
Block(5,3,-4,STONE:0)
Block(-6,3,-3,COBBLESTONE:0)
Block(-5,3,-3,COBBLESTONE:0)
Block(-4,3,-3,COBBLESTONE:0)
Block(-3,3,-3,STONE:0)
Block(-2,3,-3,AIR)
Block(-1,3,-3,AIR)
Block(0,3,-3,AIR)
Block(1,3,-3,AIR)
Block(2,3,-3,AIR)
Block(3,3,-3,AIR)
Block(4,3,-3,AIR)
Block(5,3,-3,STONE:0)
Block(6,3,-3,STONE:0)
Block(7,3,-3,STONE:0)
Block(-6,3,-2,COBBLESTONE:0)

Block(-4,3,-2,COBBLESTONE:0)
Block(-3,3,-2,STONE:0)
Block(-2,3,-2,AIR)
Block(-1,3,-2,AIR)
Block(0,3,-2,AIR)
Block(1,3,-2,AIR)
Block(2,3,-2,AIR)
Block(3,3,-2,AIR)
Block(4,3,-2,AIR)
Block(5,3,-2,AIR)
Block(6,3,-2,STONE:0)
Block(7,3,-2,STONE:0)
Block(-6,3,-1,COBBLESTONE:0)
Block(-5,3,-1,COBBLESTONE:0)
Block(-4,3,-1,COBBLESTONE:0)
Block(-3,3,-1,STONE:0)
Block(-2,3,-1,STONE:0)
Block(-1,3,-1,PLANKS:3)
Block(0,3,-1,WOODEN_SLAB:11)
Block(1,3,-1,WOODEN_SLAB:11)
Block(2,3,-1,WOODEN_SLAB:11)
Block(3,3,-1,WOODEN_SLAB:11)
Block(4,3,-1,WOODEN_SLAB:11)
Block(5,3,-1,PLANKS:3)
Block(6,3,-1,STONE:0)
Block(-4,3,0,STONE:0)
Block(-3,3,0,STONE:0)
Block(-2,3,0,STONE:0)
Block(-1,3,0,AIR)
Block(0,3,0,AIR)
Block(1,3,0,AIR)
Block(2,3,0,AIR)
Block(3,3,0,AIR)
Block(4,3,0,AIR)
Block(5,3,0,AIR)
Block(6,3,0,STONE:0)
Block(-2,3,1,STONE:0)
Block(-1,3,1,JUNGLE_FENCE:0)
Block(0,3,1,AIR)
Block(1,3,1,AIR)
Block(2,3,1,AIR)
Block(3,3,1,AIR)
Block(4,3,1,STONE:0)
Block(5,3,1,STONE:0)
Block(6,3,1,STONE:0)
Block(-2,3,2,STONE:0)
Block(-1,3,2,AIR)
Block(1,3,2,AIR)
Block(2,3,2,AIR)
Block(3,3,2,AIR)
Block(4,3,2,STONE:0)
Block(-1,3,3,COBBLESTONE:0)
Block(0,3,3,COBBLESTONE:0)
Block(1,3,3,COBBLESTONE:0)
Block(2,3,3,COBBLESTONE:0)
Block(3,3,3,COBBLESTONE:0)
Block(4,3,3,COBBLESTONE:0)
Block(0,3,4,AIR)
Block(1,3,4,AIR)
Block(2,3,4,AIR)
Block(3,3,4,AIR)
Block(1,4,-5,STONE:0)
Block(2,4,-5,STONE:0)
Block(-2,4,-4,STONE:0)
Block(-1,4,-4,STONE:0)
Block(0,4,-4,STONE:0)
Block(1,4,-4,STONE:0)
Block(2,4,-4,STONE:0)
Block(3,4,-4,STONE:0)
Block(4,4,-4,STONE:0)
Block(-6,4,-3,COBBLESTONE:0)
Block(-5,4,-3,COBBLESTONE:0)
Block(-4,4,-3,COBBLESTONE:0)
Block(-3,4,-3,STONE:0)
Block(-2,4,-3,STONE:0)
Block(-1,4,-3,STONE:0)
Block(0,4,-3,STONE:0)
Block(1,4,-3,STONE:0)
Block(2,4,-3,STONE:0)
Block(3,4,-3,STONE:0)
Block(4,4,-3,STONE:0)
Block(-6,4,-2,COBBLESTONE:0)
Block(-5,4,-2,AIR)
Block(-4,4,-2,COBBLESTONE:0)
Block(-3,4,-2,STONE:0)
Block(-2,4,-2,STONE:0)
Block(-1,4,-2,STONE:0)
Block(0,4,-2,STONE:0)
Block(1,4,-2,STONE:0)
Block(2,4,-2,STONE:0)
Block(3,4,-2,STONE:0)
Block(4,4,-2,STONE:0)
Block(5,4,-2,STONE:0)
Block(-6,4,-1,COBBLESTONE:0)
Block(-5,4,-1,COBBLESTONE:0)
Block(-4,4,-1,COBBLESTONE:0)
Block(-2,4,-1,STONE:0)
Block(-1,4,-1,STONE:0)
Block(0,4,-1,STONE:0)
Block(1,4,-1,STONE:0)
Block(2,4,-1,STONE:0)
Block(3,4,-1,STONE:0)
Block(4,4,-1,STONE:0)
Block(5,4,-1,STONE:0)
Block(-1,4,0,STONE:0)
Block(0,4,0,STONE:0)
Block(1,4,0,STONE:0)
Block(2,4,0,STONE:0)
Block(3,4,0,STONE:0)
Block(4,4,0,STONE:0)
Block(5,4,0,STONE:0)
Block(-1,4,1,STONE:0)
Block(0,4,1,STONE:0)
Block(1,4,1,STONE:0)
Block(2,4,1,STONE:0)
Block(3,4,1,STONE:0)
Block(-1,4,2,STONE:0)
Block(0,4,2,STONE:0)
Block(1,4,2,STONE:0)
Block(2,4,2,STONE:0)
Block(3,4,2,STONE:0)
Block(-5,5,-3,COBBLESTONE:0)
Block(-6,5,-2,COBBLESTONE:0)
Block(-5,5,-2,AIR)
Block(-4,5,-2,COBBLESTONE:0)
Block(-5,5,-1,COBBLESTONE:0)
Block(-5,6,-3,COBBLESTONE:0)
Block(-6,6,-2,COBBLESTONE:0)

Block(-4,6,-2,COBBLESTONE:0)
Block(-5,6,-1,COBBLESTONE:0)
Block(-5,7,-2,AIR)
Block(-5,8,-2,AIR)
Block(-5,9,-2,AIR)
Block(-5,10,-2,AIR)
Block(-5,11,-2,AIR)
Block(0,0,0,STONE:0)

BlockCheck(-3,0,4,AIR)
BlockCheck(5,0,4,AIR)
BlockCheck(-1,0,6,AIR)
BlockCheck(4,0,6,AIR)
BlockCheck(1,2,6,AIR)
BlockCheck(-1,3,4,AIR)
BlockCheck(4,3,4,AIR)

BlockCheck(-2,0,-7,Solid)
BlockCheck(4,0,-7,Solid)
BlockCheck(-5,0,-5,Solid)
BlockCheck(7,0,-5,Solid)
BlockCheck(8,0,-1,Solid)
BlockCheck(-6,0,1,Solid)
BlockCheck(-3,0,2,Solid)
BlockCheck(5,0,2,Solid)
BlockCheck(-5,3,-4,Solid)
BlockCheck(7,3,-4,Solid)
BlockCheck(7,3,-1,Solid)
BlockCheck(-5,3,0,Solid)
BlockCheck(-2,3,3,Solid)
BlockCheck(0,4,-5,Solid)
BlockCheck(4,4,-5,Solid)
BlockCheck(-2,4,0,Solid)
BlockCheck(4,4,2,Solid)
BlockCheck(1,5,-1,Solid)
