
#
# +-----------------------------------------------------------------+ #
# |                            BO3 object                           | #
# +-----------------------------------------------------------------+ #
#

Author: NLBlackEagle

Description: No description given

Version: 3

SettingsMode: WriteDisable


#
# +-----------------------------------------------------------------+ #
# |                          Main settings                          | #
# +-----------------------------------------------------------------+ #
#

Tree: false

Frequency: 1

Rarity: 100.0

RotateRandomly: false

SpawnHeight: randomY

SpawnHeightOffset: 0

SpawnHeightVariance: 0


# Height Limits for the BO3. #


MinHeight: 48

MaxHeight: 48


# Extrusion settings #


ExtrudeMode: None

ExtrudeThroughBlocks: water

MaxBranchDepth: 10

ExcludedBiomes: All


#
# +-----------------------------------------------------------------+ #
# |                      Source block settings                      | #
# +-----------------------------------------------------------------+ #
#

SourceBlocks: water

MaxPercentageOutsideSourceBlock: 100

OutsideSourceBlock: placeAnyway


#
# +-----------------------------------------------------------------+ #
# |                              Blocks                             | #
# +-----------------------------------------------------------------+ #
#

RandomBlock(5,5,4,CHEST:3,./StructureNBT/StructureLoot/JunkChest_1.nbt,20,CHEST:3,./StructureNBT/StructureLoot/JunkChest_2.nbt,15,CHEST:3,./StructureNBT/StructureLoot/JunkChest_3.nbt,15,CHEST:3,./StructureNBT/StructureLoot/JunkChest_4.nbt,15,CHEST:3,./StructureNBT/StructureLoot/JunkChest_5.nbt,15,CHEST:3,./StructureNBT/LoreStoryline/LoreGeneric_5.nbt,2,CHEST:3,./StructureNBT/LoreStoryline/LoreGeneric_4.nbt,2,CHEST:3,./StructureNBT/LoreStoryline/LoreGeneric_3.nbt,2,CHEST:3,./StructureNBT/LoreStoryline/LoreGeneric_2.nbt,2,CHEST:3,./StructureNBT/LoreStoryline/LoreGeneric_1.nbt,2,CHEST:3,./StructureNBT/LoreStoryline/LorePirate_5.nbt,3,CHEST:3,./StructureNBT/LoreStoryline/LorePirate_4.nbt,3,CHEST:3,./StructureNBT/LoreStoryline/LorePirate_3.nbt,3,CHEST:3,./StructureNBT/LoreStoryline/LorePirate_2.nbt,3,CHEST:3,./StructureNBT/LoreStoryline/LorePirate_1.nbt,3,CHEST:3,./StructureNBT/StructureLoot/Common1.nbt,3,CHEST:3,./StructureNBT/StructureLoot/Common2.nbt,3,CHEST:3,./StructureNBT/StructureLoot/Common3.nbt,3,CHEST:3,./StructureNBT/StructureLoot/Common4.nbt,3,CHEST:3,./StructureNBT/StructureLoot/Common5.nbt,3,CHEST:3,./StructureNBT/StructureLoot/Common5.nbt,3,CHEST:3,./StructureNBT/StructureLoot/Common6.nbt,3,CHEST:3,./StructureNBT/StructureLoot/Common7.nbt,3,CHEST:3,./StructureNBT/StructureLoot/Common8.nbt,3,CHEST:3,./StructureNBT/StructureLoot/Common9.nbt,3,CHEST:3,./StructureNBT/StructureLoot/Common10.nbt,3,CHEST:3,./StructureNBT/StructureLoot/Common11.nbt,3,CHEST:3,./StructureNBT/StructureLoot/Common12.nbt,3,CHEST:3,./StructureNBT/StructureLoot/Common13.nbt,3,CHEST:3,./StructureNBT/StructureLoot/Common14.nbt,3,CHEST:3,./StructureNBT/StructureLoot/Common15.nbt,3,CHEST:3,./StructureNBT/StructureLoot/Rare1.nbt,3,CHEST:3,./StructureNBT/StructureLoot/Rare2.nbt,3,CHEST:3,./StructureNBT/StructureLoot/Rare3.nbt,3,CHEST:3,./StructureNBT/StructureLoot/Rare4.nbt,3,CHEST:3,./StructureNBT/StructureLoot/Rare5.nbt,3,CHEST:3,./StructureNBT/StructureLoot/Rare6.nbt,3,CHEST:3,./StructureNBT/StructureLoot/Rare7.nbt,3,CHEST:3,./StructureNBT/StructureLoot/Rare8.nbt,3,CHEST:3,./StructureNBT/StructureLoot/Rare9.nbt,3,CHEST:3,./StructureNBT/StructureLoot/Rare10.nbt,3,CHEST:3,./StructureNBT/StructureLoot/Rare11.nbt,3,CHEST:3,./StructureNBT/StructureLoot/Rare12.nbt,3,CHEST:3,./StructureNBT/StructureLoot/Rare13.nbt,3,CHEST:3,./StructureNBT/StructureLoot/Rare14.nbt,3,CHEST:3,./StructureNBT/StructureLoot/Rare15.nbt,3,CHEST:3,./StructureNBT/StructureLoot/Epic1.nbt,3,CHEST:3,./StructureNBT/StructureLoot/Epic2.nbt,3,CHEST:3,./StructureNBT/StructureLoot/Epic3.nbt,3,CHEST:3,./StructureNBT/StructureLoot/Epic4.nbt,3,CHEST:3,./StructureNBT/StructureLoot/Epic5.nbt,3,CHEST:3,./StructureNBT/StructureLoot/Epic6.nbt,3,CHEST:3,./StructureNBT/StructureLoot/Epic7.nbt,3,CHEST:3,./StructureNBT/StructureLoot/Epic8.nbt,3,CHEST:3,./StructureNBT/StructureLoot/Epic9.nbt,3,CHEST:3,./StructureNBT/StructureLoot/Epic10.nbt,3,CHEST:3,./StructureNBT/StructureLoot/Epic11.nbt,3,CHEST:3,./StructureNBT/StructureLoot/Epic12.nbt,3,CHEST:3,./StructureNBT/StructureLoot/Epic13.nbt,3,CHEST:3,./StructureNBT/StructureLoot/Epic14.nbt,3,CHEST:3,./StructureNBT/StructureLoot/Epic15.nbt,1,CHEST:3,./StructureNBT/StructureLoot/Common15.nbt,100)
B(6,4,5,jukebox,StructureNBT/PirateBo3/pir26/2-RecordPlayer.nbt)
RandomBlock(6,4,8,CHEST:3,./StructureNBT/StructureLoot/JunkChest_1.nbt,20,CHEST:3,./StructureNBT/StructureLoot/JunkChest_2.nbt,15,CHEST:3,./StructureNBT/StructureLoot/JunkChest_3.nbt,15,CHEST:3,./StructureNBT/StructureLoot/JunkChest_4.nbt,15,CHEST:3,./StructureNBT/StructureLoot/JunkChest_5.nbt,15,CHEST:3,./StructureNBT/LoreStoryline/LoreGeneric_5.nbt,2,CHEST:3,./StructureNBT/LoreStoryline/LoreGeneric_4.nbt,2,CHEST:3,./StructureNBT/LoreStoryline/LoreGeneric_3.nbt,2,CHEST:3,./StructureNBT/LoreStoryline/LoreGeneric_2.nbt,2,CHEST:3,./StructureNBT/LoreStoryline/LoreGeneric_1.nbt,2,CHEST:3,./StructureNBT/LoreStoryline/LorePirate_5.nbt,3,CHEST:3,./StructureNBT/LoreStoryline/LorePirate_4.nbt,3,CHEST:3,./StructureNBT/LoreStoryline/LorePirate_3.nbt,3,CHEST:3,./StructureNBT/LoreStoryline/LorePirate_2.nbt,3,CHEST:3,./StructureNBT/LoreStoryline/LorePirate_1.nbt,3,CHEST:3,./StructureNBT/StructureLoot/Common1.nbt,3,CHEST:3,./StructureNBT/StructureLoot/Common2.nbt,3,CHEST:3,./StructureNBT/StructureLoot/Common3.nbt,3,CHEST:3,./StructureNBT/StructureLoot/Common4.nbt,3,CHEST:3,./StructureNBT/StructureLoot/Common5.nbt,3,CHEST:3,./StructureNBT/StructureLoot/Common5.nbt,3,CHEST:3,./StructureNBT/StructureLoot/Common6.nbt,3,CHEST:3,./StructureNBT/StructureLoot/Common7.nbt,3,CHEST:3,./StructureNBT/StructureLoot/Common8.nbt,3,CHEST:3,./StructureNBT/StructureLoot/Common9.nbt,3,CHEST:3,./StructureNBT/StructureLoot/Common10.nbt,3,CHEST:3,./StructureNBT/StructureLoot/Common11.nbt,3,CHEST:3,./StructureNBT/StructureLoot/Common12.nbt,3,CHEST:3,./StructureNBT/StructureLoot/Common13.nbt,3,CHEST:3,./StructureNBT/StructureLoot/Common14.nbt,3,CHEST:3,./StructureNBT/StructureLoot/Common15.nbt,3,CHEST:3,./StructureNBT/StructureLoot/Rare1.nbt,3,CHEST:3,./StructureNBT/StructureLoot/Rare2.nbt,3,CHEST:3,./StructureNBT/StructureLoot/Rare3.nbt,3,CHEST:3,./StructureNBT/StructureLoot/Rare4.nbt,3,CHEST:3,./StructureNBT/StructureLoot/Rare5.nbt,3,CHEST:3,./StructureNBT/StructureLoot/Rare6.nbt,3,CHEST:3,./StructureNBT/StructureLoot/Rare7.nbt,3,CHEST:3,./StructureNBT/StructureLoot/Rare8.nbt,3,CHEST:3,./StructureNBT/StructureLoot/Rare9.nbt,3,CHEST:3,./StructureNBT/StructureLoot/Rare10.nbt,3,CHEST:3,./StructureNBT/StructureLoot/Rare11.nbt,3,CHEST:3,./StructureNBT/StructureLoot/Rare12.nbt,3,CHEST:3,./StructureNBT/StructureLoot/Rare13.nbt,3,CHEST:3,./StructureNBT/StructureLoot/Rare14.nbt,3,CHEST:3,./StructureNBT/StructureLoot/Rare15.nbt,3,CHEST:3,./StructureNBT/StructureLoot/Epic1.nbt,3,CHEST:3,./StructureNBT/StructureLoot/Epic2.nbt,3,CHEST:3,./StructureNBT/StructureLoot/Epic3.nbt,3,CHEST:3,./StructureNBT/StructureLoot/Epic4.nbt,3,CHEST:3,./StructureNBT/StructureLoot/Epic5.nbt,3,CHEST:3,./StructureNBT/StructureLoot/Epic6.nbt,3,CHEST:3,./StructureNBT/StructureLoot/Epic7.nbt,3,CHEST:3,./StructureNBT/StructureLoot/Epic8.nbt,3,CHEST:3,./StructureNBT/StructureLoot/Epic9.nbt,3,CHEST:3,./StructureNBT/StructureLoot/Epic10.nbt,3,CHEST:3,./StructureNBT/StructureLoot/Epic11.nbt,3,CHEST:3,./StructureNBT/StructureLoot/Epic12.nbt,3,CHEST:3,./StructureNBT/StructureLoot/Epic13.nbt,3,CHEST:3,./StructureNBT/StructureLoot/Epic14.nbt,3,CHEST:3,./StructureNBT/StructureLoot/Epic15.nbt,1,CHEST:3,./StructureNBT/StructureLoot/Common15.nbt,100)
RandomBlock(6,5,4,CHEST:3,./StructureNBT/StructureLoot/JunkChest_1.nbt,20,CHEST:3,./StructureNBT/StructureLoot/JunkChest_2.nbt,15,CHEST:3,./StructureNBT/StructureLoot/JunkChest_3.nbt,15,CHEST:3,./StructureNBT/StructureLoot/JunkChest_4.nbt,15,CHEST:3,./StructureNBT/StructureLoot/JunkChest_5.nbt,15,CHEST:3,./StructureNBT/LoreStoryline/LoreGeneric_5.nbt,2,CHEST:3,./StructureNBT/LoreStoryline/LoreGeneric_4.nbt,2,CHEST:3,./StructureNBT/LoreStoryline/LoreGeneric_3.nbt,2,CHEST:3,./StructureNBT/LoreStoryline/LoreGeneric_2.nbt,2,CHEST:3,./StructureNBT/LoreStoryline/LoreGeneric_1.nbt,2,CHEST:3,./StructureNBT/LoreStoryline/LorePirate_5.nbt,3,CHEST:3,./StructureNBT/LoreStoryline/LorePirate_4.nbt,3,CHEST:3,./StructureNBT/LoreStoryline/LorePirate_3.nbt,3,CHEST:3,./StructureNBT/LoreStoryline/LorePirate_2.nbt,3,CHEST:3,./StructureNBT/LoreStoryline/LorePirate_1.nbt,3,CHEST:3,./StructureNBT/StructureLoot/Common1.nbt,3,CHEST:3,./StructureNBT/StructureLoot/Common2.nbt,3,CHEST:3,./StructureNBT/StructureLoot/Common3.nbt,3,CHEST:3,./StructureNBT/StructureLoot/Common4.nbt,3,CHEST:3,./StructureNBT/StructureLoot/Common5.nbt,3,CHEST:3,./StructureNBT/StructureLoot/Common5.nbt,3,CHEST:3,./StructureNBT/StructureLoot/Common6.nbt,3,CHEST:3,./StructureNBT/StructureLoot/Common7.nbt,3,CHEST:3,./StructureNBT/StructureLoot/Common8.nbt,3,CHEST:3,./StructureNBT/StructureLoot/Common9.nbt,3,CHEST:3,./StructureNBT/StructureLoot/Common10.nbt,3,CHEST:3,./StructureNBT/StructureLoot/Common11.nbt,3,CHEST:3,./StructureNBT/StructureLoot/Common12.nbt,3,CHEST:3,./StructureNBT/StructureLoot/Common13.nbt,3,CHEST:3,./StructureNBT/StructureLoot/Common14.nbt,3,CHEST:3,./StructureNBT/StructureLoot/Common15.nbt,3,CHEST:3,./StructureNBT/StructureLoot/Rare1.nbt,3,CHEST:3,./StructureNBT/StructureLoot/Rare2.nbt,3,CHEST:3,./StructureNBT/StructureLoot/Rare3.nbt,3,CHEST:3,./StructureNBT/StructureLoot/Rare4.nbt,3,CHEST:3,./StructureNBT/StructureLoot/Rare5.nbt,3,CHEST:3,./StructureNBT/StructureLoot/Rare6.nbt,3,CHEST:3,./StructureNBT/StructureLoot/Rare7.nbt,3,CHEST:3,./StructureNBT/StructureLoot/Rare8.nbt,3,CHEST:3,./StructureNBT/StructureLoot/Rare9.nbt,3,CHEST:3,./StructureNBT/StructureLoot/Rare10.nbt,3,CHEST:3,./StructureNBT/StructureLoot/Rare11.nbt,3,CHEST:3,./StructureNBT/StructureLoot/Rare12.nbt,3,CHEST:3,./StructureNBT/StructureLoot/Rare13.nbt,3,CHEST:3,./StructureNBT/StructureLoot/Rare14.nbt,3,CHEST:3,./StructureNBT/StructureLoot/Rare15.nbt,3,CHEST:3,./StructureNBT/StructureLoot/Epic1.nbt,3,CHEST:3,./StructureNBT/StructureLoot/Epic2.nbt,3,CHEST:3,./StructureNBT/StructureLoot/Epic3.nbt,3,CHEST:3,./StructureNBT/StructureLoot/Epic4.nbt,3,CHEST:3,./StructureNBT/StructureLoot/Epic5.nbt,3,CHEST:3,./StructureNBT/StructureLoot/Epic6.nbt,3,CHEST:3,./StructureNBT/StructureLoot/Epic7.nbt,3,CHEST:3,./StructureNBT/StructureLoot/Epic8.nbt,3,CHEST:3,./StructureNBT/StructureLoot/Epic9.nbt,3,CHEST:3,./StructureNBT/StructureLoot/Epic10.nbt,3,CHEST:3,./StructureNBT/StructureLoot/Epic11.nbt,3,CHEST:3,./StructureNBT/StructureLoot/Epic12.nbt,3,CHEST:3,./StructureNBT/StructureLoot/Epic13.nbt,3,CHEST:3,./StructureNBT/StructureLoot/Epic14.nbt,3,CHEST:3,./StructureNBT/StructureLoot/Epic15.nbt,1,CHEST:3,./StructureNBT/StructureLoot/Common15.nbt,100)
B(2,1,3,cobblestone)
B(2,1,4,stonebrick)
B(2,1,5,stonebrick:2)
B(2,1,6,stonebrick)
B(2,1,7,cobblestone)
B(2,1,8,stonebrick)
B(2,2,3,cobblestone)
B(2,2,4,stonebrick)
B(2,2,5,stonebrick)
B(2,2,6,stonebrick:1)
B(2,2,7,cobblestone)
B(2,2,8,stonebrick:1)
B(2,3,3,cobblestone)
B(2,3,4,stonebrick)
B(2,3,5,monster_egg:2)
B(2,3,6,monster_egg:2)
B(2,3,7,cobblestone)
B(2,3,8,stonebrick:1)
B(2,4,3,cobblestone)
B(2,4,4,stonebrick:2)
B(2,4,5,stonebrick:2)
B(2,4,6,stonebrick:2)
B(2,4,7,cobblestone)
B(2,4,8,stonebrick:1)
B(2,5,3,cobblestone)
B(2,5,4,stonebrick:1)
B(2,5,5,stonebrick:1)
B(2,5,6,stonebrick)
B(2,5,7,cobblestone)
B(2,5,8,monster_egg:4)
B(2,6,3,cobblestone)
B(2,6,4,stonebrick:1)
B(2,6,5,monster_egg:2)
B(2,6,6,stonebrick:1)
B(2,6,7,cobblestone)
B(2,6,8,stonebrick:1)
B(2,7,3,cobblestone)
B(2,7,7,cobblestone)
B(2,8,3,cobblestone)
B(2,8,7,cobblestone)
B(2,9,3,log:3)
B(2,9,7,log:3)
B(2,10,3,log:3)
B(2,10,7,log:3)
B(2,11,3,log:3)
B(2,11,7,log:3)
B(2,12,3,log:3)
B(2,12,7,log:3)
B(2,13,3,log:3)
B(2,13,7,log:3)
B(2,14,3,log:3)
B(2,14,7,log:3)
B(2,15,3,log:3)
B(2,15,7,log:3)
B(2,16,3,log:3)
B(2,16,7,log:3)
B(2,17,3,log:3)
B(2,17,7,log:3)
B(2,18,3,log:3)
B(2,18,7,log:3)
B(2,19,3,log:3)
B(2,19,7,log:3)
B(2,20,3,log:3)
B(2,20,7,log:3)
B(2,21,3,log:3)
B(2,21,7,log:3)
B(2,22,3,log:3)
B(2,22,4,stone_brick_stairs:4)
B(2,22,5,stone_brick_stairs:4)
B(2,22,6,stone_brick_stairs:4)
B(2,22,7,log:3)
B(2,23,3,log:3)
B(2,23,4,wooden_slab:5)
B(2,23,5,wooden_slab:5)
B(2,23,6,wooden_slab:5)
B(2,23,7,log:3)
B(2,24,3,cobblestone_wall)
B(2,24,7,cobblestone_wall)
B(2,25,3,fence)
B(2,25,7,fence)
B(2,26,3,dark_oak_stairs:0)
B(2,26,4,dark_oak_stairs:0)
B(2,26,5,dark_oak_stairs:0)
B(2,26,6,dark_oak_stairs:0)
B(2,26,7,dark_oak_stairs:0)
B(3,1,3,stonebrick)
B(3,1,4,monster_egg:2)
B(3,1,5,stonebrick:1)
B(3,1,6,stonebrick:2)
B(3,1,7,stonebrick)
B(3,1,8,monster_egg:2)
B(3,2,3,stonebrick:1)
B(3,2,4,stonebrick:1)
B(3,2,5,stonebrick:2)
B(3,2,6,stonebrick:2)
B(3,2,7,monster_egg:4)
B(3,2,8,stonebrick)
B(3,3,3,stonebrick:1)
B(3,3,4,stonebrick:1)
B(3,3,5,stonebrick:2)
B(3,3,6,monster_egg:2)
B(3,3,7,stonebrick)
B(3,3,8,stonebrick)
B(3,4,3,monster_egg:2)
B(3,4,4,dark_oak_fence)
B(3,4,5,lapis_block)
B(3,4,6,web)
B(3,4,7,cobblestone)
B(3,4,8,web)
B(3,5,3,stonebrick:1)
B(3,5,4,torch)
B(3,5,5,web)
B(3,5,6,air)
B(3,5,7,cobblestone)
B(3,5,8,lever:3)
B(3,6,3,monster_egg:4)
B(3,6,4,stonebrick)
B(3,6,5,stonebrick)
B(3,6,6,stonebrick)
B(3,6,7,stonebrick:2)
B(3,6,8,stonebrick:1)
B(3,20,3,log:7)
B(3,20,7,log:7)
B(3,21,5,stone_slab:11)
B(3,22,3,stone_brick_stairs:6)
B(3,22,4,stone:6)
B(3,22,5,stone:6)
B(3,22,6,stone:6)
B(3,22,7,stone_brick_stairs:7)
B(3,23,3,wooden_slab:5)
B(3,23,4,stone_slab:3)
B(3,23,5,stone_slab:3)
B(3,23,6,stone_slab:3)
B(3,23,7,wooden_slab:5)
B(3,26,3,dark_oak_stairs:5)
B(3,26,7,dark_oak_stairs:5)
B(3,27,3,dark_oak_stairs:2)
B(3,27,4,dark_oak_stairs:7)
B(3,27,5,wooden_slab:13)
B(3,27,6,dark_oak_stairs:6)
B(3,27,7,dark_oak_STAIRS:0)
B(4,1,3,stonebrick:2)
B(4,1,4,stonebrick:1)
B(4,1,5,monster_egg:3)
B(4,1,6,monster_egg:2)
B(4,1,7,stonebrick:2)
B(4,1,8,stonebrick)
B(4,2,3,stonebrick)
B(4,2,4,monster_egg:3)
B(4,2,5,stonebrick)
B(4,2,6,monster_egg:4)
B(4,2,7,stonebrick)
B(4,2,8,monster_egg:2)
B(4,3,3,stonebrick:2)
B(4,3,4,stonebrick:1)
B(4,3,5,monster_egg:2)
B(4,3,6,stonebrick)
B(4,3,7,monster_egg:3)
B(4,3,8,stonebrick:1)
B(4,4,3,stonebrick)
B(4,4,4,gold_block)
B(4,4,5,lapis_block)
B(4,4,6,web)
B(4,4,7,iron_door)
B(4,4,8,air)
B(4,5,3,stonebrick:2)
B(4,5,4,emerald_block)
B(4,5,5,web)
B(4,5,6,web)
B(4,5,7,iron_door:8)
B(4,5,8,air)
B(4,6,3,stonebrick:1)
B(4,6,4,stonebrick:2)
B(4,6,5,stonebrick)
B(4,6,6,stonebrick:2)
B(4,6,7,stonebrick)
B(4,6,8,stonebrick:1)
B(4,20,3,log:7)
B(4,20,4,log:11)
B(4,20,5,log:11)
B(4,20,6,log:11)
B(4,20,7,log:7)
B(4,21,4,stone_slab:11)
B(4,21,5,double_stone_slab:3)
B(4,21,6,stone_slab:11)
B(4,22,3,stone_brick_stairs:6)
B(4,22,4,stone:6)
B(4,22,5,netherrack)
B(4,22,6,stone:6)
B(4,22,7,stone_brick_stairs:7)
B(4,23,3,wooden_slab:5)
B(4,23,4,double_stone_slab:3)
B(4,23,5,magma:15)
B(4,23,6,double_stone_slab:3)
B(4,23,7,wooden_slab:5)
B(4,24,4,fence)
B(4,24,5,dark_oak_fence_gate:1)
B(4,24,6,fence)
B(4,26,3,dark_oak_stairs:6)
B(4,26,7,dark_oak_stairs:7)
B(4,27,3,dark_oak_stairs:2)
B(4,27,4,wooden_slab:13)
B(4,27,6,wooden_slab:13)
B(4,27,7,dark_oak_STAIRS:0)
B(5,1,3,stonebrick)
B(5,1,4,stonebrick:1)
B(5,1,5,stonebrick:2)
B(5,1,6,monster_egg:4)
B(5,1,7,monster_egg:4)
B(5,1,8,monster_egg:2)
B(5,2,3,stonebrick)
B(5,2,4,stonebrick:2)
B(5,2,5,stonebrick:2)
B(5,2,6,stonebrick:1)
B(5,2,7,stonebrick)
B(5,2,8,stonebrick:2)
B(5,3,3,stonebrick)
B(5,3,4,stonebrick)
B(5,3,5,stonebrick)
B(5,3,6,monster_egg:2)
B(5,3,7,stonebrick:1)
B(5,3,8,stonebrick:2)
B(5,4,3,stonebrick:1)
B(5,4,4,lapis_block)
B(5,4,5,anvil:3)
B(5,4,6,air)
B(5,4,7,iron_door)
B(5,4,8,air)
B(5,5,3,stonebrick)
B(5,5,5,air)
B(5,5,6,web)
B(5,5,7,iron_door:9)
B(5,5,8,air)
B(5,6,3,stonebrick)
B(5,6,4,stonebrick:1)
B(5,6,5,stonebrick:1)
B(5,6,6,monster_egg:3)
B(5,6,7,stonebrick:2)
B(5,6,8,stonebrick:1)
B(5,20,3,log:7)
B(5,20,7,log:7)
B(5,21,5,stone_slab:11)
B(5,22,3,stone_brick_stairs:6)
B(5,22,4,stone:6)
B(5,22,5,stone:6)
B(5,22,6,stone:6)
B(5,22,7,stone_brick_stairs:7)
B(5,23,3,wooden_slab:5)
B(5,23,4,stone_slab:3)
B(5,23,5,stone_slab:3)
B(5,23,6,stone_slab:3)
B(5,23,7,wooden_slab:5)
B(5,26,3,dark_oak_stairs:4)
B(5,26,7,dark_oak_stairs:4)
B(5,27,3,dark_oak_stairs:2)
B(5,27,4,dark_oak_stairs:7)
B(5,27,5,wooden_slab:13)
B(5,27,6,dark_oak_stairs:6)
B(5,27,7,dark_oak_STAIRS:0)
B(6,1,-5,cobblestone)
B(6,1,-4,stonebrick)
B(6,1,-3,stonebrick)
B(6,1,-2,cobblestone)
B(6,1,3,cobblestone)
B(6,1,4,stonebrick:2)
B(6,1,5,stonebrick)
B(6,1,6,monster_egg:4)
B(6,1,7,cobblestone)
B(6,1,8,stonebrick:2)
B(6,2,-5,cobblestone)
B(6,2,-4,stonebrick)
B(6,2,-3,stonebrick)
B(6,2,-2,cobblestone)
B(6,2,3,cobblestone)
B(6,2,4,stonebrick)
B(6,2,5,monster_egg:3)
B(6,2,6,monster_egg:3)
B(6,2,7,cobblestone)
B(6,2,8,stonebrick)
B(6,3,-5,cobblestone)
B(6,3,-4,stonebrick)
B(6,3,-3,stonebrick)
B(6,3,-2,cobblestone)
B(6,3,3,cobblestone)
B(6,3,4,stonebrick:1)
B(6,3,5,stonebrick:2)
B(6,3,6,stonebrick)
B(6,3,7,cobblestone)
B(6,3,8,stonebrick:2)
B(6,4,-5,cobblestone)
B(6,4,-4,stonebrick)
B(6,4,-3,stonebrick)
B(6,4,-2,cobblestone)
B(6,4,3,cobblestone)
B(6,4,4,emerald_block)
B(6,4,6,web)
B(6,4,7,cobblestone)
B(6,5,-5,cobblestone)
B(6,5,-4,stonebrick)
B(6,5,-3,stonebrick)
B(6,5,-2,cobblestone)
B(6,5,3,cobblestone)
B(6,5,5,air)
B(6,5,6,air)
B(6,5,7,cobblestone)
B(6,5,8,lever:3)
B(6,6,-5,cobblestone)
B(6,6,-4,stonebrick)
B(6,6,-3,stonebrick)
B(6,6,-2,cobblestone)
B(6,6,3,cobblestone)
B(6,6,4,stonebrick:2)
B(6,6,5,stonebrick:1)
B(6,6,6,stonebrick:1)
B(6,6,7,cobblestone)
B(6,6,8,stonebrick:2)
B(6,7,-5,cobblestone)
B(6,7,-2,cobblestone)
B(6,7,3,cobblestone)
B(6,7,7,cobblestone)
B(6,8,-5,cobblestone)
B(6,8,-2,cobblestone)
B(6,8,3,cobblestone)
B(6,8,7,cobblestone)
B(6,9,-5,log:3)
B(6,9,-2,log:3)
B(6,9,3,log:3)
B(6,9,7,log:3)
B(6,10,-5,log:3)
B(6,10,-2,log:3)
B(6,10,3,log:3)
B(6,10,7,log:3)
B(6,11,-5,log:3)
B(6,11,-2,log:3)
B(6,11,3,log:3)
B(6,11,7,log:3)
B(6,12,-5,log:3)
B(6,12,-2,log:3)
B(6,12,3,log:3)
B(6,12,7,log:3)
B(6,13,-5,log:3)
B(6,13,-2,log:3)
B(6,13,3,log:3)
B(6,13,7,log:3)
B(6,14,-5,log:3)
B(6,14,-2,log:3)
B(6,14,3,log:3)
B(6,14,7,log:3)
B(6,15,-5,log:3)
B(6,15,-2,log:3)
B(6,15,3,log:3)
B(6,15,7,log:3)
B(6,16,-5,log:3)
B(6,16,-2,log:3)
B(6,16,3,log:3)
B(6,16,7,log:3)
B(6,17,-5,log:3)
B(6,17,-2,log:3)
B(6,17,3,log:3)
B(6,17,7,log:3)
B(6,18,-5,log:3)
B(6,18,-2,log:3)
B(6,18,3,log:3)
B(6,18,7,log:3)
B(6,19,-5,log:3)
B(6,19,-2,log:3)
B(6,19,3,log:3)
B(6,19,7,log:3)
B(6,20,-5,log:3)
B(6,20,-2,log:3)
B(6,20,3,log:3)
B(6,20,7,log:3)
B(6,21,-5,log:3)
B(6,21,-2,log:3)
B(6,21,3,log:3)
B(6,21,7,log:3)
B(6,22,-5,log:3)
B(6,22,-4,oak_stairs:7)
B(6,22,-3,oak_stairs:6)
B(6,22,-2,log:3)
B(6,22,3,log:3)
B(6,22,4,stone_brick_stairs:5)
B(6,22,5,stone_brick_stairs:5)
B(6,22,6,stone_brick_stairs:5)
B(6,22,7,log:3)
B(6,23,-5,cobblestone_wall)
B(6,23,-2,cobblestone_wall)
B(6,23,3,log:3)
B(6,23,4,wooden_slab:5)
B(6,23,5,wooden_slab:5)
B(6,23,6,wooden_slab:5)
B(6,23,7,log:3)
B(6,24,3,cobblestone_wall)
B(6,24,7,cobblestone_wall)
B(6,25,3,fence)
B(6,25,7,fence)
B(6,26,3,dark_oak_stairs:1)
B(6,26,4,dark_oak_stairs:1)
B(6,26,5,dark_oak_stairs:1)
B(6,26,6,dark_oak_stairs:1)
B(6,26,7,dark_oak_stairs:1)
B(7,1,-5,stonebrick)
B(7,1,-4,stonebrick)
B(7,1,-3,stonebrick)
B(7,1,-2,stonebrick)
B(7,1,3,monster_egg:4)
B(7,1,4,stonebrick)
B(7,1,5,stonebrick:2)
B(7,1,6,monster_egg:4)
B(7,1,7,stonebrick:2)
B(7,1,8,stonebrick:2)
B(7,2,-5,stonebrick)
B(7,2,-4,stonebrick)
B(7,2,-3,stonebrick)
B(7,2,-2,stonebrick)
B(7,2,3,stonebrick)
B(7,2,4,stonebrick:1)
B(7,2,5,stonebrick:2)
B(7,2,6,monster_egg:3)
B(7,2,7,stonebrick:2)
B(7,2,8,stonebrick:2)
B(7,3,-5,stonebrick)
B(7,3,-4,stonebrick)
B(7,3,-3,stonebrick)
B(7,3,-2,stonebrick)
B(7,3,3,stonebrick)
B(7,3,4,stonebrick:2)
B(7,3,5,stonebrick:1)
B(7,3,6,stonebrick)
B(7,3,7,stonebrick:1)
B(7,3,8,monster_egg:2)
B(7,4,-5,stonebrick)
B(7,4,-4,stonebrick)
B(7,4,-3,stonebrick)
B(7,4,-2,stonebrick)
B(7,4,3,stonebrick:2)
B(7,4,4,gold_block)
B(7,4,5,air)
B(7,4,6,web)
B(7,4,7,iron_bars)
B(7,4,8,web)
B(7,5,-5,stonebrick)
B(7,5,-4,stonebrick)
B(7,5,-3,stonebrick)
B(7,5,-2,stonebrick)
B(7,5,3,stonebrick:1)
B(7,5,4,lapis_block)
B(7,5,5,web)
B(7,5,6,air)
B(7,5,7,iron_bars)
B(7,5,8,air)
B(7,6,-5,stonebrick)
B(7,6,-4,stonebrick)
B(7,6,-3,stonebrick)
B(7,6,-2,stonebrick)
B(7,6,3,stonebrick)
B(7,6,4,stonebrick:1)
B(7,6,5,monster_egg:2)
B(7,6,6,monster_egg:4)
B(7,6,7,stonebrick:2)
B(7,6,8,stonebrick)
B(7,22,-5,oak_stairs:5)
B(7,22,-4,wooden_slab:9)
B(7,22,-3,wooden_slab:13)
B(7,22,-2,oak_stairs:5)
B(7,22,4,oak_stairs:5)
B(7,22,6,oak_stairs:5)
B(7,23,4,oak_stairs:0)
B(7,23,5,wooden_slab:5)
B(7,23,6,oak_stairs:0)

#
# +-----------------------------------------------------------------+ #
# |                            BO3 checks                           | #
# +-----------------------------------------------------------------+ #
#


#
# +-----------------------------------------------------------------+ #
# |                             Branches                            | #
# +-----------------------------------------------------------------+ #
#

