
#
# +-----------------------------------------------------------------+ #
# |                            BO3 object                           | #
# +-----------------------------------------------------------------+ #
#

Author: NLBlackEagle

Description: No description given

Version: 3

SettingsMode: WriteDisable


#
# +-----------------------------------------------------------------+ #
# |                          Main settings                          | #
# +-----------------------------------------------------------------+ #
#

Tree: false

Frequency: 1

Rarity: 100.0

RotateRandomly: false

SpawnHeight: randomY

SpawnHeightOffset: 0

SpawnHeightVariance: 0


# Height Limits for the BO3. #


MinHeight: 48

MaxHeight: 48


# Extrusion settings #


ExtrudeMode: None

ExtrudeThroughBlocks: water

MaxBranchDepth: 10

ExcludedBiomes: All


#
# +-----------------------------------------------------------------+ #
# |                      Source block settings                      | #
# +-----------------------------------------------------------------+ #
#

SourceBlocks: water

MaxPercentageOutsideSourceBlock: 100

OutsideSourceBlock: placeAnyway


#
# +-----------------------------------------------------------------+ #
# |                              Blocks                             | #
# +-----------------------------------------------------------------+ #
#

RandomBlock(2,25,5,CHEST:3,./StructureNBT/StructureLoot/JunkChest_1.nbt,20,CHEST:3,./StructureNBT/StructureLoot/JunkChest_2.nbt,15,CHEST:3,./StructureNBT/StructureLoot/JunkChest_3.nbt,15,CHEST:3,./StructureNBT/StructureLoot/JunkChest_4.nbt,15,CHEST:3,./StructureNBT/StructureLoot/JunkChest_5.nbt,15,CHEST:3,./StructureNBT/LoreStoryline/LoreGeneric_5.nbt,2,CHEST:3,./StructureNBT/LoreStoryline/LoreGeneric_4.nbt,2,CHEST:3,./StructureNBT/LoreStoryline/LoreGeneric_3.nbt,2,CHEST:3,./StructureNBT/LoreStoryline/LoreGeneric_2.nbt,2,CHEST:3,./StructureNBT/LoreStoryline/LoreGeneric_1.nbt,2,CHEST:3,./StructureNBT/LoreStoryline/LorePirate_5.nbt,3,CHEST:3,./StructureNBT/LoreStoryline/LorePirate_4.nbt,3,CHEST:3,./StructureNBT/LoreStoryline/LorePirate_3.nbt,3,CHEST:3,./StructureNBT/LoreStoryline/LorePirate_2.nbt,3,CHEST:3,./StructureNBT/LoreStoryline/LorePirate_1.nbt,3,CHEST:3,./StructureNBT/StructureLoot/Common1.nbt,3,CHEST:3,./StructureNBT/StructureLoot/Common2.nbt,3,CHEST:3,./StructureNBT/StructureLoot/Common3.nbt,3,CHEST:3,./StructureNBT/StructureLoot/Common4.nbt,3,CHEST:3,./StructureNBT/StructureLoot/Common5.nbt,3,CHEST:3,./StructureNBT/StructureLoot/Common5.nbt,3,CHEST:3,./StructureNBT/StructureLoot/Common6.nbt,3,CHEST:3,./StructureNBT/StructureLoot/Common7.nbt,3,CHEST:3,./StructureNBT/StructureLoot/Common8.nbt,3,CHEST:3,./StructureNBT/StructureLoot/Common9.nbt,3,CHEST:3,./StructureNBT/StructureLoot/Common10.nbt,3,CHEST:3,./StructureNBT/StructureLoot/Common11.nbt,3,CHEST:3,./StructureNBT/StructureLoot/Common12.nbt,3,CHEST:3,./StructureNBT/StructureLoot/Common13.nbt,3,CHEST:3,./StructureNBT/StructureLoot/Common14.nbt,3,CHEST:3,./StructureNBT/StructureLoot/Common15.nbt,3,CHEST:3,./StructureNBT/StructureLoot/Rare1.nbt,3,CHEST:3,./StructureNBT/StructureLoot/Rare2.nbt,3,CHEST:3,./StructureNBT/StructureLoot/Rare3.nbt,3,CHEST:3,./StructureNBT/StructureLoot/Rare4.nbt,3,CHEST:3,./StructureNBT/StructureLoot/Rare5.nbt,3,CHEST:3,./StructureNBT/StructureLoot/Rare6.nbt,3,CHEST:3,./StructureNBT/StructureLoot/Rare7.nbt,3,CHEST:3,./StructureNBT/StructureLoot/Rare8.nbt,3,CHEST:3,./StructureNBT/StructureLoot/Rare9.nbt,3,CHEST:3,./StructureNBT/StructureLoot/Rare10.nbt,3,CHEST:3,./StructureNBT/StructureLoot/Rare11.nbt,3,CHEST:3,./StructureNBT/StructureLoot/Rare12.nbt,3,CHEST:3,./StructureNBT/StructureLoot/Rare13.nbt,3,CHEST:3,./StructureNBT/StructureLoot/Rare14.nbt,3,CHEST:3,./StructureNBT/StructureLoot/Rare15.nbt,3,CHEST:3,./StructureNBT/StructureLoot/Epic1.nbt,3,CHEST:3,./StructureNBT/StructureLoot/Epic2.nbt,3,CHEST:3,./StructureNBT/StructureLoot/Epic3.nbt,3,CHEST:3,./StructureNBT/StructureLoot/Epic4.nbt,3,CHEST:3,./StructureNBT/StructureLoot/Epic5.nbt,3,CHEST:3,./StructureNBT/StructureLoot/Epic6.nbt,3,CHEST:3,./StructureNBT/StructureLoot/Epic7.nbt,3,CHEST:3,./StructureNBT/StructureLoot/Epic8.nbt,3,CHEST:3,./StructureNBT/StructureLoot/Epic9.nbt,3,CHEST:3,./StructureNBT/StructureLoot/Epic10.nbt,3,CHEST:3,./StructureNBT/StructureLoot/Epic11.nbt,3,CHEST:3,./StructureNBT/StructureLoot/Epic12.nbt,3,CHEST:3,./StructureNBT/StructureLoot/Epic13.nbt,3,CHEST:3,./StructureNBT/StructureLoot/Epic14.nbt,3,CHEST:3,./StructureNBT/StructureLoot/Epic15.nbt,1,CHEST:3,./StructureNBT/StructureLoot/Common15.nbt,100)
RandomBlock(3,25,5,CHEST:3,./StructureNBT/StructureLoot/JunkChest_1.nbt,20,CHEST:3,./StructureNBT/StructureLoot/JunkChest_2.nbt,15,CHEST:3,./StructureNBT/StructureLoot/JunkChest_3.nbt,15,CHEST:3,./StructureNBT/StructureLoot/JunkChest_4.nbt,15,CHEST:3,./StructureNBT/StructureLoot/JunkChest_5.nbt,15,CHEST:3,./StructureNBT/LoreStoryline/LoreGeneric_5.nbt,2,CHEST:3,./StructureNBT/LoreStoryline/LoreGeneric_4.nbt,2,CHEST:3,./StructureNBT/LoreStoryline/LoreGeneric_3.nbt,2,CHEST:3,./StructureNBT/LoreStoryline/LoreGeneric_2.nbt,2,CHEST:3,./StructureNBT/LoreStoryline/LoreGeneric_1.nbt,2,CHEST:3,./StructureNBT/LoreStoryline/LorePirate_5.nbt,3,CHEST:3,./StructureNBT/LoreStoryline/LorePirate_4.nbt,3,CHEST:3,./StructureNBT/LoreStoryline/LorePirate_3.nbt,3,CHEST:3,./StructureNBT/LoreStoryline/LorePirate_2.nbt,3,CHEST:3,./StructureNBT/LoreStoryline/LorePirate_1.nbt,3,CHEST:3,./StructureNBT/StructureLoot/Common1.nbt,3,CHEST:3,./StructureNBT/StructureLoot/Common2.nbt,3,CHEST:3,./StructureNBT/StructureLoot/Common3.nbt,3,CHEST:3,./StructureNBT/StructureLoot/Common4.nbt,3,CHEST:3,./StructureNBT/StructureLoot/Common5.nbt,3,CHEST:3,./StructureNBT/StructureLoot/Common5.nbt,3,CHEST:3,./StructureNBT/StructureLoot/Common6.nbt,3,CHEST:3,./StructureNBT/StructureLoot/Common7.nbt,3,CHEST:3,./StructureNBT/StructureLoot/Common8.nbt,3,CHEST:3,./StructureNBT/StructureLoot/Common9.nbt,3,CHEST:3,./StructureNBT/StructureLoot/Common10.nbt,3,CHEST:3,./StructureNBT/StructureLoot/Common11.nbt,3,CHEST:3,./StructureNBT/StructureLoot/Common12.nbt,3,CHEST:3,./StructureNBT/StructureLoot/Common13.nbt,3,CHEST:3,./StructureNBT/StructureLoot/Common14.nbt,3,CHEST:3,./StructureNBT/StructureLoot/Common15.nbt,3,CHEST:3,./StructureNBT/StructureLoot/Rare1.nbt,3,CHEST:3,./StructureNBT/StructureLoot/Rare2.nbt,3,CHEST:3,./StructureNBT/StructureLoot/Rare3.nbt,3,CHEST:3,./StructureNBT/StructureLoot/Rare4.nbt,3,CHEST:3,./StructureNBT/StructureLoot/Rare5.nbt,3,CHEST:3,./StructureNBT/StructureLoot/Rare6.nbt,3,CHEST:3,./StructureNBT/StructureLoot/Rare7.nbt,3,CHEST:3,./StructureNBT/StructureLoot/Rare8.nbt,3,CHEST:3,./StructureNBT/StructureLoot/Rare9.nbt,3,CHEST:3,./StructureNBT/StructureLoot/Rare10.nbt,3,CHEST:3,./StructureNBT/StructureLoot/Rare11.nbt,3,CHEST:3,./StructureNBT/StructureLoot/Rare12.nbt,3,CHEST:3,./StructureNBT/StructureLoot/Rare13.nbt,3,CHEST:3,./StructureNBT/StructureLoot/Rare14.nbt,3,CHEST:3,./StructureNBT/StructureLoot/Rare15.nbt,3,CHEST:3,./StructureNBT/StructureLoot/Epic1.nbt,3,CHEST:3,./StructureNBT/StructureLoot/Epic2.nbt,3,CHEST:3,./StructureNBT/StructureLoot/Epic3.nbt,3,CHEST:3,./StructureNBT/StructureLoot/Epic4.nbt,3,CHEST:3,./StructureNBT/StructureLoot/Epic5.nbt,3,CHEST:3,./StructureNBT/StructureLoot/Epic6.nbt,3,CHEST:3,./StructureNBT/StructureLoot/Epic7.nbt,3,CHEST:3,./StructureNBT/StructureLoot/Epic8.nbt,3,CHEST:3,./StructureNBT/StructureLoot/Epic9.nbt,3,CHEST:3,./StructureNBT/StructureLoot/Epic10.nbt,3,CHEST:3,./StructureNBT/StructureLoot/Epic11.nbt,3,CHEST:3,./StructureNBT/StructureLoot/Epic12.nbt,3,CHEST:3,./StructureNBT/StructureLoot/Epic13.nbt,3,CHEST:3,./StructureNBT/StructureLoot/Epic14.nbt,3,CHEST:3,./StructureNBT/StructureLoot/Epic15.nbt,1,CHEST:3,./StructureNBT/StructureLoot/Common15.nbt,100)
B(-1,1,6,cobblestone)
B(-1,1,7,stonebrick)
B(-1,1,8,stonebrick:2)
B(-1,2,6,cobblestone)
B(-1,2,7,monster_egg:3)
B(-1,2,8,stonebrick)
B(-1,3,6,cobblestone)
B(-1,3,7,stonebrick:1)
B(-1,3,8,monster_egg:4)
B(-1,4,6,cobblestone)
B(-1,4,7,stonebrick:2)
B(-1,4,8,stonebrick:2)
B(-1,5,6,cobblestone)
B(-1,5,7,monster_egg:2)
B(-1,5,8,stonebrick)
B(-1,6,6,cobblestone)
B(-1,6,7,monster_egg:3)
B(-1,6,8,stonebrick:1)
B(-1,7,6,cobblestone)
B(-1,8,6,cobblestone)
B(-1,9,6,log:3)
B(-1,10,6,log:3)
B(-1,11,6,log:3)
B(-1,12,6,log:3)
B(-1,13,6,log:3)
B(-1,14,6,log:3)
B(-1,15,6,log:3)
B(-1,16,6,log:3)
B(-1,17,6,log:3)
B(-1,18,6,log:3)
B(-1,19,6,log:3)
B(-1,20,6,log:3)
B(-1,21,6,log:3)
B(-1,22,6,log:3)
B(-1,23,6,log:3)
B(-1,24,5,oak_stairs:6)
B(-1,24,6,log:3)
B(-1,24,7,oak_stairs:7)
B(-1,24,8,wooden_slab:13)
B(-1,25,5,wooden_slab:5)
B(-1,25,6,wooden_slab:5)
B(-1,25,7,wooden_slab:5)
B(-1,25,8,cobblestone_wall)
B(0,1,6,stonebrick)
B(0,1,7,monster_egg:2)
B(0,1,8,monster_egg:3)
B(0,2,6,stonebrick:1)
B(0,2,7,monster_egg:3)
B(0,2,8,stonebrick)
B(0,3,6,monster_egg:4)
B(0,3,7,stonebrick:1)
B(0,3,8,monster_egg:2)
B(0,4,6,stonebrick:2)
B(0,4,7,bookshelf)
B(0,4,8,bookshelf)
B(0,5,6,stonebrick:1)
B(0,5,7,bookshelf)
B(0,5,8,bookshelf)
B(0,6,6,stonebrick:1)
B(0,6,7,stonebrick:2)
B(0,6,8,stonebrick:2)
B(0,24,5,wooden_slab:13)
B(0,24,6,log:7)
B(0,24,7,log:11)
B(0,24,8,log:11)
B(0,25,5,hay_block)
B(0,25,6,hay_block)
B(0,38,8,wool:15)
B(1,1,6,stonebrick:1)
B(1,1,7,stonebrick)
B(1,1,8,stonebrick:2)
B(1,2,6,monster_egg:2)
B(1,2,7,stonebrick:2)
B(1,2,8,stonebrick:2)
B(1,3,6,stonebrick)
B(1,3,7,stonebrick:1)
B(1,3,8,monster_egg:2)
B(1,4,6,stonebrick)
B(1,4,7,web)
B(1,4,8,carpet:15)
B(1,5,6,stonebrick)
B(1,5,7,web)
B(1,5,8,air)
B(1,6,6,stonebrick:2)
B(1,6,7,stonebrick)
B(1,6,8,stonebrick)
B(1,24,5,wooden_slab:13)
B(1,24,6,log:7)
B(1,24,7,wooden_slab:8)
B(1,24,8,wooden_slab:8)
B(1,37,7,wool:15)
B(1,38,7,wool:15)
B(2,1,6,stonebrick:1)
B(2,1,7,stonebrick:1)
B(2,1,8,stonebrick:2)
B(2,2,6,stonebrick)
B(2,2,7,stonebrick:2)
B(2,2,8,stonebrick:2)
B(2,3,6,stonebrick:1)
B(2,3,7,stonebrick:2)
B(2,3,8,monster_egg:3)
B(2,4,6,stonebrick)
B(2,4,7,web)
B(2,4,8,carpet:15)
B(2,5,6,stonebrick)
B(2,5,7,air)
B(2,5,8,air)
B(2,6,6,stonebrick:2)
B(2,6,7,monster_egg:3)
B(2,6,8,monster_egg:4)
B(2,24,5,wooden_slab:13)
B(2,24,6,log:7)
B(2,24,7,wooden_slab:13)
B(2,24,8,wooden_slab:13)
B(2,25,6,hay_block)
B(2,27,7,wool:15)
B(2,27,8,wool:15)
B(2,35,4,wool:15)
B(2,36,4,wool:15)
B(2,37,5,wool:15)
B(2,37,6,wool:15)
B(3,1,6,monster_egg:3)
B(3,1,7,stonebrick:1)
B(3,1,8,stonebrick)
B(3,2,6,stonebrick:2)
B(3,2,7,stonebrick:2)
B(3,2,8,monster_egg:4)
B(3,3,6,monster_egg:3)
B(3,3,7,stonebrick:2)
B(3,3,8,stonebrick)
B(3,4,6,monster_egg:3)
B(3,4,7,dark_oak_fence)
B(3,4,8,air)
B(3,5,6,stonebrick)
B(3,5,7,torch)
B(3,5,8,air)
B(3,6,6,stonebrick:2)
B(3,6,7,stonebrick)
B(3,6,8,stonebrick)
B(3,24,5,wooden_slab:13)
B(3,24,6,log:7)
B(3,24,7,log:11)
B(3,24,8,log:11)
B(3,25,6,hay_block)
B(3,25,7,hay_block)
B(3,25,8,hay_block)
B(3,28,6,wool:15)
B(3,28,7,wool:15)
B(3,29,4,wool:15)
B(3,29,5,wool:15)
B(3,34,4,wool:15)
B(3,35,4,wool:15)
B(3,36,5,wool:15)
B(3,49,8,wool:15)
B(4,1,6,cobblestone)
B(4,1,7,stonebrick:2)
B(4,1,8,monster_egg:4)
B(4,2,6,cobblestone)
B(4,2,7,monster_egg:4)
B(4,2,8,stonebrick)
B(4,3,6,cobblestone)
B(4,3,7,stonebrick)
B(4,3,8,stonebrick)
B(4,4,6,cobblestone)
B(4,4,7,stonebrick:2)
B(4,4,8,stonebrick:2)
B(4,5,6,cobblestone)
B(4,5,7,monster_egg:2)
B(4,5,8,stonebrick:2)
B(4,6,6,cobblestone)
B(4,6,7,stonebrick)
B(4,6,8,monster_egg:4)
B(4,7,6,cobblestone)
B(4,8,6,cobblestone)
B(4,9,6,log:3)
B(4,10,6,log:3)
B(4,11,6,log:3)
B(4,12,6,log:3)
B(4,13,6,log:3)
B(4,14,6,log:3)
B(4,15,6,log:3)
B(4,16,6,log:3)
B(4,17,6,log:3)
B(4,18,6,log:3)
B(4,19,6,log:3)
B(4,20,6,log:3)
B(4,21,6,log:3)
B(4,22,6,log:3)
B(4,23,6,log:3)
B(4,24,5,oak_stairs:6)
B(4,24,6,log:3)
B(4,24,7,oak_stairs:7)
B(4,24,8,wooden_slab:11)
B(4,25,5,wooden_slab:5)
B(4,25,6,wooden_slab:5)
B(4,25,7,wooden_slab:5)
B(4,25,8,cobblestone_wall)
B(4,28,5,wool:15)
B(4,29,5,wool:15)
B(4,30,4,wool:15)
B(4,31,4,wool:15)
B(4,33,4,wool:15)
B(4,34,4,wool:15)
B(4,35,4,wool:15)
B(4,36,5,wool:15)
B(4,36,6,spruce_fence)
B(4,37,6,log:5)
B(4,38,6,wool:15)
B(4,49,8,wool:15)
B(5,28,5,wool:15)
B(5,29,5,wool:15)
B(5,30,5,wool:15)
B(5,31,4,wool:15)
B(5,32,4,wool:15)
B(5,33,4,wool:15)
B(5,34,4,wool:15)
B(5,35,5,wool:15)
B(5,36,5,wool:15)
B(5,36,6,spruce_fence)
B(5,37,6,log:5)
B(5,38,6,wool:15)
B(5,39,6,wool:15)
B(5,40,6,wool:15)
B(5,41,5,wool:15)
B(5,46,5,wool:15)
B(5,47,6,wool:15)
B(5,48,7,wool:15)
B(6,28,5,wool:15)
B(6,29,5,wool:15)
B(6,30,5,wool:15)
B(6,31,4,wool:15)
B(6,32,4,wool:15)
B(6,33,4,wool:15)
B(6,34,5,wool:15)
B(6,35,5,wool:15)
B(6,36,5,wool:15)
B(6,36,6,spruce_fence)
B(6,37,6,log:5)
B(6,38,6,wool:15)
B(6,39,6,wool:15)
B(6,40,6,wool:15)
B(6,41,6,wool:15)
B(6,42,5,wool:15)
B(6,45,5,wool:15)
B(6,46,6,wool:15)
B(6,47,6,wool:15)
B(6,48,6,wool:15)
B(6,48,7,spruce_fence)
B(6,49,7,log:5)
B(6,50,7,wool:15)
B(7,28,6,wool:15)
B(7,29,6,wool:15)
B(7,30,5,wool:15)
B(7,31,5,wool:15)
B(7,32,4,wool:15)
B(7,33,5,wool:15)
B(7,34,5,wool:15)
B(7,35,5,wool:15)
B(7,36,6,wool:15)
B(7,36,7,spruce_fence)
B(7,37,7,log:5)
B(7,38,7,wool:15)
B(7,39,6,wool:15)
B(7,40,6,wool:15)
B(7,41,6,wool:15)
B(7,42,5,wool:15)
B(7,43,5,wool:15)
B(7,44,5,wool:15)
B(7,45,5,wool:15)
B(7,46,6,wool:15)
B(7,47,6,wool:15)
B(7,48,6,wool:15)
B(7,48,7,spruce_fence)
B(7,49,7,log:5)
B(7,50,6,wool:15)
B(7,50,7,wool:15)

#
# +-----------------------------------------------------------------+ #
# |                            BO3 checks                           | #
# +-----------------------------------------------------------------+ #
#


#
# +-----------------------------------------------------------------+ #
# |                             Branches                            | #
# +-----------------------------------------------------------------+ #
#

