
#
# +-----------------------------------------------------------------+ #
# |                            BO3 object                           | #
# +-----------------------------------------------------------------+ #
#

Author: NLBlackEagle

Description: No description given

Version: 3

SettingsMode: WriteDisable


#
# +-----------------------------------------------------------------+ #
# |                          Main settings                          | #
# +-----------------------------------------------------------------+ #
#

Tree: false

Frequency: 1

Rarity: 100.0

RotateRandomly: false

SpawnHeight: randomY

SpawnHeightOffset: 0

SpawnHeightVariance: 0


# Height Limits for the BO3. #


MinHeight: 48

MaxHeight: 48


# Extrusion settings #


ExtrudeMode: None

ExtrudeThroughBlocks: water

MaxBranchDepth: 10

ExcludedBiomes: All


#
# +-----------------------------------------------------------------+ #
# |                      Source block settings                      | #
# +-----------------------------------------------------------------+ #
#

SourceBlocks: water

MaxPercentageOutsideSourceBlock: 100

OutsideSourceBlock: placeAnyway


#
# +-----------------------------------------------------------------+ #
# |                              Blocks                             | #
# +-----------------------------------------------------------------+ #
#

B(6,23,7,dispenser:4,StructureNBT/PirateBo3/pir54/1-Trap.nbt)
B(-2,29,8,wool)
B(-1,28,6,wool)
B(-1,28,7,wool)
B(0,28,6,wool)
B(0,29,5,wool)
B(0,30,4,wool)
B(0,33,6,wool)
B(0,34,7,wool)
B(0,34,8,wool)
B(1,28,5,wool)
B(1,29,4,wool)
B(1,30,3,wool)
B(1,31,3,wool)
B(1,32,4,wool)
B(1,33,5,wool)
B(1,34,6,wool)
B(1,35,5,wooden_button)
B(1,35,6,log:5)
B(1,35,7,wooden_button:3)
B(2,28,5,wool)
B(2,29,4,wool)
B(2,30,3,wool)
B(2,31,3,wool)
B(2,32,3,wool)
B(2,33,4,wool)
B(2,34,5,wool)
B(2,34,6,spruce_fence)
B(2,35,5,wooden_button)
B(2,35,6,log:5)
B(2,35,7,wooden_button:3)
B(2,36,8,wool)
B(2,44,8,wool)
B(3,28,5,wool)
B(3,29,4,wool)
B(3,30,3,wool)
B(3,31,3,wool)
B(3,32,4,wool)
B(3,33,4,wool)
B(3,34,5,wool)
B(3,34,6,spruce_fence)
B(3,35,5,wooden_button)
B(3,35,6,log:5)
B(3,35,7,wooden_button:3)
B(3,36,7,wool)
B(3,37,6,wool)
B(3,38,5,wool)
B(3,42,5,wool)
B(3,43,6,wool)
B(3,44,7,wool)
B(4,28,6,wool)
B(4,29,-7,wool)
B(4,29,-6,wool)
B(4,29,4,wool)
B(4,29,5,wool)
B(4,30,4,wool)
B(4,31,4,wool)
B(4,32,4,wool)
B(4,33,5,wool)
B(4,34,5,wool)
B(4,35,7,log:5)
B(4,35,8,wooden_button:3)
B(4,36,6,wool)
B(4,37,6,wool)
B(4,38,5,wool)
B(4,39,4,wool)
B(4,40,4,wool)
B(4,41,4,wool)
B(4,42,5,wool)
B(4,43,5,wool)
B(4,44,6,wool)
B(4,45,5,wooden_button)
B(4,45,6,log:5)
B(4,45,7,wooden_button:3)
B(4,46,7,wool)
B(4,46,8,wool)
B(4,47,5,wool)
B(4,47,6,wool)
B(4,53,8,wool)
B(5,24,-7,wool)
B(5,28,6,wool)
B(5,29,5,wool)
B(5,30,4,wool)
B(5,31,4,wool)
B(5,32,4,wool)
B(5,33,5,wool)
B(5,34,6,wool)
B(5,34,7,spruce_fence)
B(5,35,7,log:5)
B(5,35,8,wooden_button:3)
B(5,36,6,wool)
B(5,37,5,wool)
B(5,38,5,wool)
B(5,39,4,wool)
B(5,40,4,wool)
B(5,41,4,wool)
B(5,42,4,wool)
B(5,43,5,wool)
B(5,44,5,wool)
B(5,44,6,spruce_fence)
B(5,45,5,wooden_button)
B(5,45,6,log:5)
B(5,45,7,wooden_button:3)
B(5,46,6,wool)
B(5,47,5,wool)
B(5,47,6,wool)
B(5,48,4,wool)
B(5,51,5,wool)
B(5,52,6,wool)
B(5,53,6,wool)
B(5,53,7,wool)
B(6,24,7,wooden_slab:8)
B(6,28,6,wool)
B(6,29,5,wool)
B(6,30,4,wool)
B(6,31,4,wool)
B(6,32,5,wool)
B(6,33,5,wool)
B(6,34,6,wool)
B(6,34,7,spruce_fence)
B(6,35,7,log:5)
B(6,35,8,wooden_button:3)
B(6,36,6,wool)
B(6,37,5,wool)
B(6,38,5,wool)
B(6,39,4,wool)
B(6,40,4,wool)
B(6,41,4,wool)
B(6,42,4,wool)
B(6,43,5,wool)
B(6,44,5,wool)
B(6,44,6,spruce_fence)
B(6,45,5,wooden_button)
B(6,45,6,log:5)
B(6,45,7,wooden_button:3)
B(6,46,6,wool)
B(6,47,5,wool)
B(6,48,4,wool)
B(6,49,4,wool)
B(6,50,4,wool)
B(6,51,4,wool)
B(6,52,5,wool)
B(6,52,6,spruce_fence)
B(6,53,5,wooden_button)
B(6,53,6,log:5)
B(6,53,7,wooden_button:3)
B(7,20,7,planks:1)
B(7,20,8,planks:1)
B(7,21,6,planks:1)
B(7,21,7,planks:1)
B(7,21,8,planks:1)
B(7,22,6,planks:5)
B(7,22,7,planks:5)
B(7,22,8,planks:5)
B(7,23,6,planks:5)
B(7,23,7,coal_block)
B(7,23,8,planks:5)
B(7,24,5,planks)
B(7,24,6,planks)
B(7,24,8,planks)
B(7,25,5,planks:5)
B(7,25,6,planks:5)
B(7,25,7,planks:5)
B(7,25,8,planks:5)
B(7,26,5,planks:5)
B(7,26,6,dark_oak_stairs:7)
B(7,26,7,wooden_slab:13)
B(7,26,8,wooden_slab:13)
B(7,27,6,dark_oak_stairs:7)
B(7,27,7,dark_oak_stairs:6)
B(7,27,8,planks:5)
B(7,28,6,wooden_slab:5)
B(7,28,7,wool)
B(7,29,6,wool)
B(7,30,5,wool)
B(7,31,5,wool)
B(7,32,5,wool)
B(7,33,6,wool)
B(7,34,7,wool)
B(7,34,8,spruce_fence)
B(7,35,7,wooden_button)
B(7,35,8,log:5)
B(7,36,7,wool)
B(7,37,6,wool)
B(7,38,5,wool)
B(7,39,5,wool)
B(7,40,5,wool)
B(7,41,4,wool)
B(7,42,5,wool)
B(7,43,5,wool)
B(7,44,6,wool)
B(7,44,7,spruce_fence)
B(7,45,7,log:5)
B(7,45,8,wooden_button:3)
B(7,46,6,wool)
B(7,47,5,wool)
B(7,48,4,wool)
B(7,49,4,wool)
B(7,50,4,wool)
B(7,51,5,wool)
B(7,52,5,wool)
B(7,52,6,spruce_fence)
B(7,53,5,wooden_button)
B(7,53,6,log:5)
B(7,53,7,wooden_button:3)

#
# +-----------------------------------------------------------------+ #
# |                            BO3 checks                           | #
# +-----------------------------------------------------------------+ #
#


#
# +-----------------------------------------------------------------+ #
# |                             Branches                            | #
# +-----------------------------------------------------------------+ #
#

