
#######################################################################
# +-----------------------------------------------------------------+ #
# |                            BO3 object                           | #
# +-----------------------------------------------------------------+ #
#######################################################################

Author: NLBlackEagle

Description: No description given

Version: 3

SettingsMode: WriteWithoutComments


#######################################################################
# +-----------------------------------------------------------------+ #
# |                          Main settings                          | #
# +-----------------------------------------------------------------+ #
#######################################################################

Tree: true

Frequency: 1

Rarity: 100.0

RotateRandomly: false

SpawnHeight: highestBlock

SpawnHeightOffset: -27

SpawnHeightVariance: 0

##############################
# Height Limits for the BO3. #
##############################

MinHeight: 0

MaxHeight: 255

######################
# Extrusion settings #
######################

ExtrudeMode: None

ExtrudeThroughBlocks: AIR

MaxBranchDepth: 10

ExcludedBiomes: All


#######################################################################
# +-----------------------------------------------------------------+ #
# |                      Source block settings                      | #
# +-----------------------------------------------------------------+ #
#######################################################################

SourceBlocks: STONE,OBSIDIAN,DIRT,GRASS,COAL_ORE

MaxPercentageOutsideSourceBlock: 47

OutsideSourceBlock: placeAnyway

DoReplaceBlocks: true

IsOTGPlus: false


#######################################################################
# +-----------------------------------------------------------------+ #
# |                              Blocks                             | #
# +-----------------------------------------------------------------+ #
#######################################################################

Block(-15,22,-11,GRASS:0)
Block(-15,22,-10,GRASS:0)
Block(-15,22,-9,GRASS:0)
Block(-15,22,-8,GRASS:0)
Block(-15,22,-7,STONE:0)
Block(-15,22,-6,STONE:0)
Block(-15,22,-5,STONE:0)
Block(-15,22,-4,STONE:0)
Block(-15,22,-3,STONE:0)
Block(-15,22,-2,STONE:0)
Block(-15,22,-1,STONE:0)
Block(-15,22,0,GRASS:0)
Block(-15,22,1,GRASS:0)
Block(-15,22,2,GRASS:0)
Block(-15,22,3,GRASS:0)
Block(-15,22,4,GRASS:0)
Block(-15,22,5,GRASS:0)
Block(-15,22,6,STONE:0)
Block(-15,22,7,STONE:0)
Block(-15,22,8,STONE:0)
Block(-15,22,9,STONE:0)
Block(-15,22,10,GRASS:0)
Block(-15,22,11,GRASS:0)
Block(-15,22,12,GRASS:0)
Block(-15,23,-7,STONE:0)
Block(-15,23,-6,STONE:0)
Block(-15,23,-5,STONE:0)
Block(-15,23,-4,STONE:0)
Block(-15,23,-3,STONE:0)
Block(-15,23,-2,STONE:0)
Block(-15,23,-1,STONE:0)
Block(-15,23,6,GRASS:0)
Block(-15,23,7,STONE:0)
Block(-15,23,8,GRASS:0)
Block(-15,23,9,GRASS:0)
Block(-15,24,-7,GRASS:0)
Block(-15,24,-6,STONE:0)
Block(-15,24,-5,STONE:0)
Block(-15,24,-4,STONE:0)
Block(-15,24,-3,STONE:0)
Block(-15,24,-2,STONE:0)
Block(-15,24,-1,GRASS:0)
Block(-15,24,7,GRASS:0)
Block(-15,25,-6,STONE:0)
Block(-15,25,-5,STONE:0)
Block(-15,25,-4,STONE:0)
Block(-15,25,-3,GRASS:0)
Block(-15,25,-2,STONE:0)
Block(-15,26,-6,GRASS:0)
Block(-15,26,-5,STONE:0)
Block(-15,26,-4,GRASS:0)
Block(-15,26,-2,GRASS:0)
Block(-15,27,-5,GRASS:0)
Block(-14,22,-11,GRASS:0)
Block(-14,22,-10,GRASS:0)
Block(-14,22,-9,GRASS:0)
Block(-14,22,-8,GRASS:0)
Block(-14,22,-7,STONE:0)
Block(-14,22,-6,STONE:0)
Block(-14,22,-5,STONE:0)
Block(-14,22,-4,STONE:0)
Block(-14,22,-3,STONE:0)
Block(-14,22,-2,STONE:0)
Block(-14,22,-1,STONE:0)
Block(-14,22,0,STONE:0)
Block(-14,22,1,STONE:0)
Block(-14,22,2,STONE:0)
Block(-14,22,3,GRASS:0)
Block(-14,22,4,GRASS:0)
Block(-14,22,5,STONE:0)
Block(-14,22,6,STONE:0)
Block(-14,22,7,STONE:0)
Block(-14,22,8,STONE:0)
Block(-14,22,9,STONE:0)
Block(-14,22,10,STONE:0)
Block(-14,22,11,STONE:0)
Block(-14,22,12,GRASS:0)
Block(-14,23,-7,STONE:0)
Block(-14,23,-6,STONE:0)
Block(-14,23,-5,STONE:0)
Block(-14,23,-4,STONE:0)
Block(-14,23,-3,STONE:0)
Block(-14,23,-2,STONE:0)
Block(-14,23,-1,STONE:0)
Block(-14,23,0,STONE:0)
Block(-14,23,1,GRASS:0)
Block(-14,23,2,GRASS:0)
Block(-14,23,5,GRASS:0)
Block(-14,23,6,STONE:0)
Block(-14,23,7,STONE:0)
Block(-14,23,8,GRASS:0)
Block(-14,23,9,STONE:0)
Block(-14,23,10,STONE:0)
Block(-14,23,11,STONE:0)
Block(-14,24,-7,STONE:0)
Block(-14,24,-6,STONE:0)
Block(-14,24,-5,STONE:0)
Block(-14,24,-4,STONE:0)
Block(-14,24,-3,STONE:0)
Block(-14,24,-2,STONE:0)
Block(-14,24,-1,STONE:0)
Block(-14,24,0,GRASS:0)
Block(-14,24,6,GRASS:0)
Block(-14,24,7,STONE:0)
Block(-14,24,9,GRASS:0)
Block(-14,24,10,STONE:0)
Block(-14,24,11,GRASS:0)
Block(-14,25,-7,GRASS:0)
Block(-14,25,-6,STONE:0)
Block(-14,25,-5,STONE:0)
Block(-14,25,-4,STONE:0)
Block(-14,25,-3,STONE:0)
Block(-14,25,-2,STONE:0)
Block(-14,25,-1,GRASS:0)
Block(-14,25,7,STONE:0)
Block(-14,25,10,GRASS:0)
Block(-14,26,-6,STONE:0)
Block(-14,26,-5,STONE:0)
Block(-14,26,-4,STONE:0)
Block(-14,26,-3,STONE:0)
Block(-14,26,-2,STONE:0)
Block(-14,26,7,GRASS:0)
Block(-14,27,-6,GRASS:0)
Block(-14,27,-5,STONE:0)
Block(-14,27,-4,STONE:0)
Block(-14,27,-3,GRASS:0)
Block(-14,27,-2,GRASS:0)
Block(-14,28,-5,STONE:0)
Block(-14,28,-4,GRASS:0)
Block(-14,29,-5,GRASS:0)
Block(-13,22,-11,GRASS:0)
Block(-13,22,-10,GRASS:0)
Block(-13,22,-9,GRASS:0)
Block(-13,22,-8,STONE:0)
Block(-13,22,-7,STONE:0)
Block(-13,22,-6,STONE:0)
Block(-13,22,-5,STONE:0)
Block(-13,22,-4,STONE:0)
Block(-13,22,-3,STONE:0)
Block(-13,22,-2,STONE:0)
Block(-13,22,-1,STONE:0)
Block(-13,22,0,STONE:0)
Block(-13,22,1,STONE:0)
Block(-13,22,2,STONE:0)
Block(-13,22,3,STONE:0)
Block(-13,22,4,STONE:0)
Block(-13,22,5,STONE:0)
Block(-13,22,6,STONE:0)
Block(-13,22,7,STONE:0)
Block(-13,22,8,STONE:0)
Block(-13,22,9,STONE:0)
Block(-13,22,10,STONE:0)
Block(-13,22,11,STONE:0)
Block(-13,22,12,GRASS:0)
Block(-13,23,-8,STONE:0)
Block(-13,23,-7,STONE:0)
Block(-13,23,-6,STONE:0)
Block(-13,23,-5,STONE:0)
Block(-13,23,-4,STONE:0)
Block(-13,23,-3,STONE:0)
Block(-13,23,-2,STONE:0)
Block(-13,23,-1,STONE:0)
Block(-13,23,0,STONE:0)
Block(-13,23,1,STONE:0)
Block(-13,23,2,STONE:0)
Block(-13,23,3,STONE:0)
Block(-13,23,4,GRASS:0)
Block(-13,23,5,GRASS:0)
Block(-13,23,6,STONE:0)
Block(-13,23,7,STONE:0)
Block(-13,23,8,STONE:0)
Block(-13,23,9,STONE:0)
Block(-13,23,10,STONE:0)
Block(-13,23,11,STONE:0)
Block(-13,24,-8,GRASS:0)
Block(-13,24,-7,STONE:0)
Block(-13,24,-6,STONE:0)
Block(-13,24,-5,STONE:0)
Block(-13,24,-4,STONE:0)
Block(-13,24,-3,STONE:0)
Block(-13,24,-2,STONE:0)
Block(-13,24,-1,STONE:0)
Block(-13,24,0,STONE:0)
Block(-13,24,1,STONE:0)
Block(-13,24,2,STONE:0)
Block(-13,24,3,GRASS:0)
Block(-13,24,6,STONE:0)
Block(-13,24,7,STONE:0)
Block(-13,24,8,STONE:0)
Block(-13,24,9,STONE:0)
Block(-13,24,10,STONE:0)
Block(-13,24,11,STONE:0)
Block(-13,25,-7,STONE:0)
Block(-13,25,-6,STONE:0)
Block(-13,25,-5,STONE:0)
Block(-13,25,-4,STONE:0)
Block(-13,25,-3,STONE:0)
Block(-13,25,-2,STONE:0)
Block(-13,25,-1,STONE:0)
Block(-13,25,0,STONE:0)
Block(-13,25,1,STONE:0)
Block(-13,25,2,GRASS:0)
Block(-13,25,6,STONE:0)
Block(-13,25,7,STONE:0)
Block(-13,25,8,STONE:0)
Block(-13,25,9,STONE:0)
Block(-13,25,10,STONE:0)
Block(-13,25,11,STONE:0)
Block(-13,26,-7,STONE:0)
Block(-13,26,-6,STONE:0)
Block(-13,26,-5,STONE:0)
Block(-13,26,-4,STONE:0)
Block(-13,26,-3,STONE:0)
Block(-13,26,-2,STONE:0)
Block(-13,26,-1,GRASS:0)
Block(-13,26,0,STONE:0)
Block(-13,26,1,GRASS:0)
Block(-13,26,6,STONE:0)
Block(-13,26,7,STONE:0)
Block(-13,26,8,STONE:0)
Block(-13,26,9,STONE:0)
Block(-13,26,10,GRASS:0)
Block(-13,26,11,GRASS:0)
Block(-13,27,-7,GRASS:0)
Block(-13,27,-6,STONE:0)
Block(-13,27,-5,STONE:0)
Block(-13,27,-4,STONE:0)
Block(-13,27,-3,STONE:0)
Block(-13,27,-2,STONE:0)
Block(-13,27,0,GRASS:0)
Block(-13,27,6,GRASS:0)
Block(-13,27,7,STONE:0)
Block(-13,27,8,GRASS:0)
Block(-13,27,9,GRASS:0)
Block(-13,28,-6,GRASS:0)
Block(-13,28,-5,GRASS:0)
Block(-13,28,-4,STONE:0)
Block(-13,28,-3,GRASS:0)
Block(-13,28,-2,GRASS:0)
Block(-13,28,7,GRASS:0)
Block(-13,29,-4,GRASS:0)
Block(-12,21,-4,STONE:0)
Block(-12,21,-3,STONE:0)
Block(-12,21,-2,STONE:0)
Block(-12,21,-1,STONE:0)
Block(-12,21,0,STONE:0)
Block(-12,21,1,STONE:0)
Block(-12,21,2,STONE:0)
Block(-12,22,-11,GRASS:0)
Block(-12,22,-10,GRASS:0)
Block(-12,22,-9,STONE:0)
Block(-12,22,-8,STONE:0)
Block(-12,22,-7,STONE:0)
Block(-12,22,-6,STONE:0)
Block(-12,22,-5,STONE:0)
Block(-12,22,-4,FENCE:0)
Block(-12,22,-3,FENCE:0)
Block(-12,22,-2,STONE:0)
Block(-12,22,-1,LOG:1)
Block(-12,22,0,STONE:0)
Block(-12,22,1,STONE:0)
Block(-12,22,2,FENCE:0)
Block(-12,22,3,STONE:0)
Block(-12,22,4,STONE:0)
Block(-12,22,5,STONE:0)
Block(-12,22,6,STONE:0)
Block(-12,22,7,STONE:0)
Block(-12,22,8,STONE:0)
Block(-12,22,9,STONE:0)
Block(-12,22,10,STONE:0)
Block(-12,22,11,STONE:0)
Block(-12,22,12,GRASS:0)
Block(-12,23,-9,GRASS:0)
Block(-12,23,-8,STONE:0)
Block(-12,23,-7,STONE:0)
Block(-12,23,-6,STONE:0)
Block(-12,23,-5,STONE:0)
Block(-12,23,-4,FENCE:0)
Block(-12,23,-3,STONE:0)
Block(-12,23,-2,STONE:0)
Block(-12,23,-1,LOG:1)
Block(-12,23,0,FENCE:0)
Block(-12,23,1,STONE:0)
Block(-12,23,2,FENCE:0)
Block(-12,23,3,STONE:0)
Block(-12,23,4,STONE:0)
Block(-12,23,5,STONE:0)
Block(-12,23,6,STONE:0)
Block(-12,23,7,STONE:0)
Block(-12,23,8,STONE:0)
Block(-12,23,9,STONE:0)
Block(-12,23,10,STONE:0)
Block(-12,23,11,STONE:0)
Block(-12,24,-8,STONE:0)
Block(-12,24,-7,STONE:0)
Block(-12,24,-6,STONE:0)
Block(-12,24,-5,STONE:0)
Block(-12,24,-4,STONE:0)
Block(-12,24,-3,STONE:0)
Block(-12,24,-2,STONE:0)
Block(-12,24,-1,LOG:1)
Block(-12,24,0,FENCE:0)
Block(-12,24,1,STONE:0)
Block(-12,24,2,STONE:0)
Block(-12,24,3,STONE:0)
Block(-12,24,4,STONE:0)
Block(-12,24,5,STONE:0)
Block(-12,24,6,STONE:0)
Block(-12,24,7,STONE:0)
Block(-12,24,8,STONE:0)
Block(-12,24,9,STONE:0)
Block(-12,24,10,STONE:0)
Block(-12,24,11,GRASS:0)
Block(-12,25,-8,STONE:0)
Block(-12,25,-7,STONE:0)
Block(-12,25,-6,STONE:0)
Block(-12,25,-5,STONE:0)
Block(-12,25,-4,STONE:0)
Block(-12,25,-3,STONE:0)
Block(-12,25,-2,STONE:0)
Block(-12,25,-1,STONE:0)
Block(-12,25,0,STONE:0)
Block(-12,25,1,STONE:0)
Block(-12,25,2,STONE:0)
Block(-12,25,3,STONE:0)
Block(-12,25,4,STONE:0)
Block(-12,25,5,GRASS:0)
Block(-12,25,6,STONE:0)
Block(-12,25,7,STONE:0)
Block(-12,25,8,STONE:0)
Block(-12,25,9,STONE:0)
Block(-12,25,10,STONE:0)
Block(-12,26,-8,GRASS:0)
Block(-12,26,-7,STONE:0)
Block(-12,26,-6,STONE:0)
Block(-12,26,-5,STONE:0)
Block(-12,26,-4,STONE:0)
Block(-12,26,-3,STONE:0)
Block(-12,26,-2,STONE:0)
Block(-12,26,-1,STONE:0)
Block(-12,26,0,STONE:0)
Block(-12,26,1,STONE:0)
Block(-12,26,2,STONE:0)
Block(-12,26,3,STONE:0)
Block(-12,26,4,GRASS:0)
Block(-12,26,6,STONE:0)
Block(-12,26,7,STONE:0)
Block(-12,26,8,STONE:0)
Block(-12,26,9,STONE:0)
Block(-12,26,10,STONE:0)
Block(-12,27,-7,GRASS:0)
Block(-12,27,-6,STONE:0)
Block(-12,27,-5,STONE:0)
Block(-12,27,-4,STONE:0)
Block(-12,27,-3,STONE:0)
Block(-12,27,-2,STONE:0)
Block(-12,27,-1,STONE:0)
Block(-12,27,0,STONE:0)
Block(-12,27,1,GRASS:0)
Block(-12,27,2,GRASS:0)
Block(-12,27,3,GRASS:0)
Block(-12,27,6,STONE:0)
Block(-12,27,7,STONE:0)
Block(-12,27,8,STONE:0)
Block(-12,27,9,STONE:0)
Block(-12,27,10,GRASS:0)
Block(-12,28,-6,GRASS:0)
Block(-12,28,-5,STONE:0)
Block(-12,28,-4,STONE:0)
Block(-12,28,-3,STONE:0)
Block(-12,28,-2,STONE:0)
Block(-12,28,-1,STONE:0)
Block(-12,28,0,GRASS:0)
Block(-12,28,6,STONE:0)
Block(-12,28,7,STONE:0)
Block(-12,28,8,STONE:0)
Block(-12,28,9,GRASS:0)
Block(-12,29,-5,GRASS:0)
Block(-12,29,-4,STONE:0)
Block(-12,29,-3,GRASS:0)
Block(-12,29,-2,STONE:0)
Block(-12,29,-1,GRASS:0)
Block(-12,29,6,GRASS:0)
Block(-12,29,7,GRASS:0)
Block(-12,29,8,GRASS:0)
Block(-12,30,-4,GRASS:0)
Block(-12,30,-2,GRASS:0)
Block(-11,21,-5,STONE:0)
Block(-11,21,-4,STONE:0)
Block(-11,21,-3,STONE:0)
Block(-11,21,-2,STONE:0)
Block(-11,21,-1,STONE:0)
Block(-11,21,0,STONE:0)
Block(-11,21,1,STONE:0)
Block(-11,21,2,STONE:0)
Block(-11,22,-11,GRASS:0)
Block(-11,22,-10,GRASS:0)
Block(-11,22,-9,STONE:0)
Block(-11,22,-8,STONE:0)
Block(-11,22,-7,STONE:0)
Block(-11,22,-6,STONE:0)
Block(-11,22,-5,FENCE:0)
Block(-11,22,-4,RAILS:6)
Block(-11,22,-3,RAILS:0)
Block(-11,22,-2,RAILS:0)
Block(-11,22,-1,RAILS:0)
Block(-11,22,0,RAILS:0)
Block(-11,22,1,RAILS:0)
Block(-11,22,2,RAILS:9)
Block(-11,22,3,STONE:0)
Block(-11,22,4,STONE:0)
Block(-11,22,5,STONE:0)
Block(-11,22,6,STONE:0)
Block(-11,22,7,STONE:0)
Block(-11,22,8,STONE:0)
Block(-11,22,9,STONE:0)
Block(-11,22,10,STONE:0)
Block(-11,22,11,STONE:0)
Block(-11,22,12,GRASS:0)
Block(-11,23,-9,STONE:0)
Block(-11,23,-8,STONE:0)
Block(-11,23,-7,STONE:0)
Block(-11,23,-6,STONE:0)
Block(-11,23,-5,FENCE:0)
Block(-11,23,-4,AIR:0)
Block(-11,23,-3,AIR:0)
Block(-11,23,-2,AIR:0)
Block(-11,23,-1,AIR:0)
Block(-11,23,0,AIR:0)
Block(-11,23,1,AIR:0)
Block(-11,23,2,AIR:0)
Block(-11,23,3,FENCE:0)
Block(-11,23,4,STONE:0)
Block(-11,23,5,STONE:0)
Block(-11,23,6,STONE:0)
Block(-11,23,7,STONE:0)
Block(-11,23,8,STONE:0)
Block(-11,23,9,STONE:0)
Block(-11,23,10,STONE:0)
Block(-11,23,11,STONE:0)
Block(-11,24,-9,GRASS:0)
Block(-11,24,-8,STONE:0)
Block(-11,24,-7,STONE:0)
Block(-11,24,-6,STONE:0)
Block(-11,24,-5,FENCE:0)
Block(-11,24,-4,AIR:0)
Block(-11,24,-3,AIR:0)
Block(-11,24,-2,AIR:0)
Block(-11,24,-1,AIR:0)
Block(-11,24,0,AIR:0)
Block(-11,24,1,AIR:0)
Block(-11,24,2,AIR:0)
Block(-11,24,3,FENCE:0)
Block(-11,24,4,STONE:0)
Block(-11,24,5,STONE:0)
Block(-11,24,6,STONE:0)
Block(-11,24,7,STONE:0)
Block(-11,24,8,STONE:0)
Block(-11,24,9,STONE:0)
Block(-11,24,10,STONE:0)
Block(-11,24,11,STONE:0)
Block(-11,25,-8,GRASS:0)
Block(-11,25,-7,STONE:0)
Block(-11,25,-6,STONE:0)
Block(-11,25,-5,STONE:0)
Block(-11,25,-4,STONE:0)
Block(-11,25,-3,STONE:0)
Block(-11,25,-2,STONE:0)
Block(-11,25,-1,LOG:5)
Block(-11,25,0,STONE:0)
Block(-11,25,1,STONE:0)
Block(-11,25,2,STONE:0)
Block(-11,25,3,STONE:0)
Block(-11,25,4,STONE:0)
Block(-11,25,5,STONE:0)
Block(-11,25,6,STONE:0)
Block(-11,25,7,STONE:0)
Block(-11,25,8,STONE:0)
Block(-11,25,9,STONE:0)
Block(-11,25,10,STONE:0)
Block(-11,25,11,GRASS:0)
Block(-11,26,-7,STONE:0)
Block(-11,26,-6,STONE:0)
Block(-11,26,-5,STONE:0)
Block(-11,26,-4,STONE:0)
Block(-11,26,-3,STONE:0)
Block(-11,26,-2,STONE:0)
Block(-11,26,-1,STONE:0)
Block(-11,26,0,STONE:0)
Block(-11,26,1,STONE:0)
Block(-11,26,2,STONE:0)
Block(-11,26,3,STONE:0)
Block(-11,26,4,STONE:0)
Block(-11,26,5,STONE:0)
Block(-11,26,6,STONE:0)
Block(-11,26,7,STONE:0)
Block(-11,26,8,STONE:0)
Block(-11,26,9,STONE:0)
Block(-11,26,10,STONE:0)
Block(-11,27,-7,GRASS:0)
Block(-11,27,-6,STONE:0)
Block(-11,27,-5,STONE:0)
Block(-11,27,-4,STONE:0)
Block(-11,27,-3,STONE:0)
Block(-11,27,-2,STONE:0)
Block(-11,27,-1,STONE:0)
Block(-11,27,0,STONE:0)
Block(-11,27,1,STONE:0)
Block(-11,27,2,STONE:0)
Block(-11,27,3,STONE:0)
Block(-11,27,4,STONE:0)
Block(-11,27,5,GRASS:0)
Block(-11,27,6,STONE:0)
Block(-11,27,7,STONE:0)
Block(-11,27,8,STONE:0)
Block(-11,27,9,STONE:0)
Block(-11,27,10,STONE:0)
Block(-11,28,-6,STONE:0)
Block(-11,28,-5,STONE:0)
Block(-11,28,-4,STONE:0)
Block(-11,28,-3,STONE:0)
Block(-11,28,-2,STONE:0)
Block(-11,28,-1,STONE:0)
Block(-11,28,0,STONE:0)
Block(-11,28,1,GRASS:0)
Block(-11,28,2,STONE:0)
Block(-11,28,3,STONE:0)
Block(-11,28,4,GRASS:0)
Block(-11,28,6,STONE:0)
Block(-11,28,7,STONE:0)
Block(-11,28,8,STONE:0)
Block(-11,28,9,STONE:0)
Block(-11,28,10,GRASS:0)
Block(-11,29,-6,GRASS:0)
Block(-11,29,-5,STONE:0)
Block(-11,29,-4,STONE:0)
Block(-11,29,-3,STONE:0)
Block(-11,29,-2,STONE:0)
Block(-11,29,-1,STONE:0)
Block(-11,29,0,GRASS:0)
Block(-11,29,2,GRASS:0)
Block(-11,29,3,GRASS:0)
Block(-11,29,6,STONE:0)
Block(-11,29,7,STONE:0)
Block(-11,29,8,STONE:0)
Block(-11,29,9,GRASS:0)
Block(-11,30,-5,GRASS:0)
Block(-11,30,-4,GRASS:0)
Block(-11,30,-3,GRASS:0)
Block(-11,30,-2,STONE:0)
Block(-11,30,-1,GRASS:0)
Block(-11,30,6,GRASS:0)
Block(-11,30,7,GRASS:0)
Block(-11,30,8,GRASS:0)
Block(-11,31,-2,GRASS:0)
Block(-10,21,-5,LOG:5)
Block(-10,21,-4,STONE:0)
Block(-10,21,-3,STONE:0)
Block(-10,21,-2,STONE:0)
Block(-10,21,-1,LOG:5)
Block(-10,21,0,STONE:0)
Block(-10,21,1,STONE:0)
Block(-10,21,2,STONE:0)
Block(-10,22,-11,GRASS:0)
Block(-10,22,-10,GRASS:0)
Block(-10,22,-9,STONE:0)
Block(-10,22,-8,STONE:0)
Block(-10,22,-7,STONE:0)
Block(-10,22,-6,STONE:0)
Block(-10,22,-5,STONE:0)
Block(-10,22,-4,RAILS:1)
Block(-10,22,-3,STEP:3)
Block(-10,22,-2,STEP:3)
Block(-10,22,-1,STEP:3)
Block(-10,22,0,STEP:3)
Block(-10,22,1,STEP:3)
Block(-10,22,2,RAILS:1)
Block(-10,22,3,FENCE:0)
Block(-10,22,4,STONE:0)
Block(-10,22,5,STONE:0)
Block(-10,22,6,STONE:0)
Block(-10,22,7,STONE:0)
Block(-10,22,8,STONE:0)
Block(-10,22,9,STONE:0)
Block(-10,22,10,STONE:0)
Block(-10,22,11,GRASS:0)
Block(-10,22,12,GRASS:0)
Block(-10,23,-9,STONE:0)
Block(-10,23,-8,STONE:0)
Block(-10,23,-7,STONE:0)
Block(-10,23,-6,STONE:0)
Block(-10,23,-5,STONE:0)
Block(-10,23,-4,AIR:0)
Block(-10,23,-3,AIR:0)
Block(-10,23,-2,AIR:0)
Block(-10,23,-1,AIR:0)
Block(-10,23,0,AIR:0)
Block(-10,23,1,AIR:0)
Block(-10,23,2,AIR:0)
Block(-10,23,3,FENCE:0)
Block(-10,23,4,STONE:0)
Block(-10,23,5,STONE:0)
Block(-10,23,6,STONE:0)
Block(-10,23,7,STONE:0)
Block(-10,23,8,STONE:0)
Block(-10,23,9,STONE:0)
Block(-10,23,10,STONE:0)
Block(-10,24,-9,STONE:0)
Block(-10,24,-8,STONE:0)
Block(-10,24,-7,STONE:0)
Block(-10,24,-6,STONE:0)
Block(-10,24,-5,FENCE:0)
Block(-10,24,-4,AIR:0)
Block(-10,24,-3,AIR:0)
Block(-10,24,-2,AIR:0)
Block(-10,24,-1,AIR:0)
Block(-10,24,0,AIR:0)
Block(-10,24,1,AIR:0)
Block(-10,24,2,AIR:0)
Block(-10,24,3,STONE:0)
Block(-10,24,4,STONE:0)
Block(-10,24,5,STONE:0)
Block(-10,24,6,STONE:0)
Block(-10,24,7,STONE:0)
Block(-10,24,8,STONE:0)
Block(-10,24,9,STONE:0)
Block(-10,24,10,STONE:0)
Block(-10,25,-9,GRASS:0)
Block(-10,25,-8,STONE:0)
Block(-10,25,-7,STONE:0)
Block(-10,25,-6,STONE:0)
Block(-10,25,-5,STONE:0)
Block(-10,25,-4,STONE:0)
Block(-10,25,-3,STONE:0)
Block(-10,25,-2,STONE:0)
Block(-10,25,-1,LOG:5)
Block(-10,25,0,STONE:0)
Block(-10,25,1,STONE:0)
Block(-10,25,2,STONE:0)
Block(-10,25,3,STONE:0)
Block(-10,25,4,STONE:0)
Block(-10,25,5,STONE:0)
Block(-10,25,6,STONE:0)
Block(-10,25,7,STONE:0)
Block(-10,25,8,STONE:0)
Block(-10,25,9,STONE:0)
Block(-10,25,10,STONE:0)
Block(-10,26,-8,STONE:0)
Block(-10,26,-7,STONE:0)
Block(-10,26,-6,STONE:0)
Block(-10,26,-5,STONE:0)
Block(-10,26,-4,STONE:0)
Block(-10,26,-3,STONE:0)
Block(-10,26,-2,STONE:0)
Block(-10,26,-1,STONE:0)
Block(-10,26,0,STONE:0)
Block(-10,26,1,STONE:0)
Block(-10,26,2,STONE:0)
Block(-10,26,3,STONE:0)
Block(-10,26,4,STONE:0)
Block(-10,26,5,STONE:0)
Block(-10,26,6,STONE:0)
Block(-10,26,7,STONE:0)
Block(-10,26,8,STONE:0)
Block(-10,26,9,STONE:0)
Block(-10,26,10,STONE:0)
Block(-10,27,-8,GRASS:0)
Block(-10,27,-7,STONE:0)
Block(-10,27,-6,STONE:0)
Block(-10,27,-5,STONE:0)
Block(-10,27,-4,STONE:0)
Block(-10,27,-3,STONE:0)
Block(-10,27,-2,STONE:0)
Block(-10,27,-1,STONE:0)
Block(-10,27,0,STONE:0)
Block(-10,27,1,STONE:0)
Block(-10,27,2,STONE:0)
Block(-10,27,3,STONE:0)
Block(-10,27,4,STONE:0)
Block(-10,27,5,STONE:0)
Block(-10,27,6,STONE:0)
Block(-10,27,7,STONE:0)
Block(-10,27,8,STONE:0)
Block(-10,27,9,STONE:0)
Block(-10,27,10,GRASS:0)
Block(-10,28,-7,GRASS:0)
Block(-10,28,-6,STONE:0)
Block(-10,28,-5,STONE:0)
Block(-10,28,-4,STONE:0)
Block(-10,28,-3,STONE:0)
Block(-10,28,-2,STONE:0)
Block(-10,28,-1,STONE:0)
Block(-10,28,0,STONE:0)
Block(-10,28,1,STONE:0)
Block(-10,28,2,STONE:0)
Block(-10,28,3,STONE:0)
Block(-10,28,4,STONE:0)
Block(-10,28,5,STONE:0)
Block(-10,28,6,STONE:0)
Block(-10,28,7,STONE:0)
Block(-10,28,8,STONE:0)
Block(-10,28,9,GRASS:0)
Block(-10,29,-6,STONE:0)
Block(-10,29,-5,STONE:0)
Block(-10,29,-4,STONE:0)
Block(-10,29,-3,STONE:0)
Block(-10,29,-2,STONE:0)
Block(-10,29,-1,STONE:0)
Block(-10,29,0,STONE:0)
Block(-10,29,1,STONE:0)
Block(-10,29,2,GRASS:0)
Block(-10,29,3,GRASS:0)
Block(-10,29,4,GRASS:0)
Block(-10,29,5,STONE:0)
Block(-10,29,6,STONE:0)
Block(-10,29,7,STONE:0)
Block(-10,29,8,STONE:0)
Block(-10,30,-6,STONE:0)
Block(-10,30,-5,STONE:0)
Block(-10,30,-4,STONE:0)
Block(-10,30,-3,STONE:0)
Block(-10,30,-2,STONE:0)
Block(-10,30,-1,STONE:0)
Block(-10,30,0,STONE:0)
Block(-10,30,1,GRASS:0)
Block(-10,30,5,GRASS:0)
Block(-10,30,6,STONE:0)
Block(-10,30,7,STONE:0)
Block(-10,30,8,GRASS:0)
Block(-10,31,-6,GRASS:0)
Block(-10,31,-5,GRASS:0)
Block(-10,31,-4,GRASS:0)
Block(-10,31,-3,GRASS:0)
Block(-10,31,-2,GRASS:0)
Block(-10,31,-1,GRASS:0)
Block(-10,31,0,GRASS:0)
Block(-10,31,6,GRASS:0)
Block(-10,31,7,GRASS:0)
Block(-9,21,-5,LOG:5)
Block(-9,21,-4,STONE:0)
Block(-9,21,-3,STONE:0)
Block(-9,21,-2,STONE:0)
Block(-9,21,-1,LOG:5)
Block(-9,21,0,STONE:0)
Block(-9,21,1,STONE:0)
Block(-9,21,2,STONE:0)
Block(-9,22,-11,GRASS:0)
Block(-9,22,-10,STONE:0)
Block(-9,22,-9,STONE:0)
Block(-9,22,-8,STONE:0)
Block(-9,22,-7,STONE:0)
Block(-9,22,-6,STONE:0)
Block(-9,22,-5,STONE:0)
Block(-9,22,-4,RAILS:1)
Block(-9,22,-3,STEP:3)
Block(-9,22,-2,RAILS:6)
Block(-9,22,-1,RAILS:0)
Block(-9,22,0,RAILS:9)
Block(-9,22,1,STEP:3)
Block(-9,22,2,RAILS:1)
Block(-9,22,3,FENCE:0)
Block(-9,22,4,STONE:0)
Block(-9,22,5,STONE:0)
Block(-9,22,6,STONE:0)
Block(-9,22,7,STONE:0)
Block(-9,22,8,STONE:0)
Block(-9,22,9,STONE:0)
Block(-9,22,10,GRASS:0)
Block(-9,22,11,GRASS:0)
Block(-9,22,12,GRASS:0)
Block(-9,23,-10,GRASS:0)
Block(-9,23,-9,STONE:0)
Block(-9,23,-8,STONE:0)
Block(-9,23,-7,STONE:0)
Block(-9,23,-6,STONE:0)
Block(-9,23,-5,FENCE:0)
Block(-9,23,-4,AIR:0)
Block(-9,23,-3,AIR:0)
Block(-9,23,-2,AIR:0)
Block(-9,23,-1,AIR:0)
Block(-9,23,0,AIR:0)
Block(-9,23,1,AIR:0)
Block(-9,23,2,AIR:0)
Block(-9,23,3,STONE:0)
Block(-9,23,4,STONE:0)
Block(-9,23,5,STONE:0)
Block(-9,23,6,STONE:0)
Block(-9,23,7,STONE:0)
Block(-9,23,8,STONE:0)
Block(-9,23,9,STONE:0)
Block(-9,24,-9,STONE:0)
Block(-9,24,-8,STONE:0)
Block(-9,24,-7,STONE:0)
Block(-9,24,-6,STONE:0)
Block(-9,24,-5,FENCE:0)
Block(-9,24,-4,AIR:0)
Block(-9,24,-3,AIR:0)
Block(-9,24,-2,AIR:0)
Block(-9,24,-1,AIR:0)
Block(-9,24,0,AIR:0)
Block(-9,24,1,AIR:0)
Block(-9,24,2,AIR:0)
Block(-9,24,3,STONE:0)
Block(-9,24,4,STONE:0)
Block(-9,24,5,STONE:0)
Block(-9,24,6,STONE:0)
Block(-9,24,7,STONE:0)
Block(-9,24,8,STONE:0)
Block(-9,24,9,STONE:0)
Block(-9,25,-9,STONE:0)
Block(-9,25,-8,STONE:0)
Block(-9,25,-7,STONE:0)
Block(-9,25,-6,STONE:0)
Block(-9,25,-5,STONE:0)
Block(-9,25,-4,STONE:0)
Block(-9,25,-3,STONE:0)
Block(-9,25,-2,STONE:0)
Block(-9,25,-1,LOG:5)
Block(-9,25,0,STONE:0)
Block(-9,25,1,STONE:0)
Block(-9,25,2,STONE:0)
Block(-9,25,3,STONE:0)
Block(-9,25,4,STONE:0)
Block(-9,25,5,STONE:0)
Block(-9,25,6,STONE:0)
Block(-9,25,7,STONE:0)
Block(-9,25,8,STONE:0)
Block(-9,25,9,STONE:0)
Block(-9,26,-9,GRASS:0)
Block(-9,26,-8,STONE:0)
Block(-9,26,-7,STONE:0)
Block(-9,26,-6,STONE:0)
Block(-9,26,-5,STONE:0)
Block(-9,26,-4,STONE:0)
Block(-9,26,-3,STONE:0)
Block(-9,26,-2,STONE:0)
Block(-9,26,-1,STONE:0)
Block(-9,26,0,STONE:0)
Block(-9,26,1,STONE:0)
Block(-9,26,2,STONE:0)
Block(-9,26,3,STONE:0)
Block(-9,26,4,STONE:0)
Block(-9,26,5,STONE:0)
Block(-9,26,6,STONE:0)
Block(-9,26,7,STONE:0)
Block(-9,26,8,STONE:0)
Block(-9,26,9,GRASS:0)
Block(-9,27,-8,STONE:0)
Block(-9,27,-7,STONE:0)
Block(-9,27,-6,STONE:0)
Block(-9,27,-5,STONE:0)
Block(-9,27,-4,STONE:0)
Block(-9,27,-3,STONE:0)
Block(-9,27,-2,STONE:0)
Block(-9,27,-1,STONE:0)
Block(-9,27,0,STONE:0)
Block(-9,27,1,STONE:0)
Block(-9,27,2,STONE:0)
Block(-9,27,3,STONE:0)
Block(-9,27,4,STONE:0)
Block(-9,27,5,STONE:0)
Block(-9,27,6,STONE:0)
Block(-9,27,7,STONE:0)
Block(-9,27,8,STONE:0)
Block(-9,28,-8,GRASS:0)
Block(-9,28,-7,STONE:0)
Block(-9,28,-6,STONE:0)
Block(-9,28,-5,STONE:0)
Block(-9,28,-4,STONE:0)
Block(-9,28,-3,STONE:0)
Block(-9,28,-2,STONE:0)
Block(-9,28,-1,STONE:0)
Block(-9,28,0,STONE:0)
Block(-9,28,1,STONE:0)
Block(-9,28,2,STONE:0)
Block(-9,28,3,STONE:0)
Block(-9,28,4,STONE:0)
Block(-9,28,5,STONE:0)
Block(-9,28,6,STONE:0)
Block(-9,28,7,STONE:0)
Block(-9,28,8,STONE:0)
Block(-9,29,-7,STONE:0)
Block(-9,29,-6,STONE:0)
Block(-9,29,-5,STONE:0)
Block(-9,29,-4,STONE:0)
Block(-9,29,-3,STONE:0)
Block(-9,29,-2,STONE:0)
Block(-9,29,-1,STONE:0)
Block(-9,29,0,STONE:0)
Block(-9,29,1,STONE:0)
Block(-9,29,2,STONE:0)
Block(-9,29,3,STONE:0)
Block(-9,29,4,STONE:0)
Block(-9,29,5,STONE:0)
Block(-9,29,6,STONE:0)
Block(-9,29,7,STONE:0)
Block(-9,29,8,STONE:0)
Block(-9,30,-7,GRASS:0)
Block(-9,30,-6,STONE:0)
Block(-9,30,-5,STONE:0)
Block(-9,30,-4,STONE:0)
Block(-9,30,-3,STONE:0)
Block(-9,30,-2,STONE:0)
Block(-9,30,-1,STONE:0)
Block(-9,30,0,STONE:0)
Block(-9,30,1,STONE:0)
Block(-9,30,2,STONE:0)
Block(-9,30,3,STONE:0)
Block(-9,30,4,STONE:0)
Block(-9,30,5,STONE:0)
Block(-9,30,6,STONE:0)
Block(-9,30,7,STONE:0)
Block(-9,30,8,GRASS:0)
Block(-9,31,-6,GRASS:0)
Block(-9,31,-5,GRASS:0)
Block(-9,31,-4,STONE:0)
Block(-9,31,-3,STONE:0)
Block(-9,31,-2,STONE:0)
Block(-9,31,-1,STONE:0)
Block(-9,31,0,GRASS:0)
Block(-9,31,1,GRASS:0)
Block(-9,31,2,GRASS:0)
Block(-9,31,3,GRASS:0)
Block(-9,31,4,STONE:0)
Block(-9,31,5,GRASS:0)
Block(-9,31,6,GRASS:0)
Block(-9,31,7,GRASS:0)
Block(-9,32,-2,GRASS:0)
Block(-9,32,4,GRASS:0)
Block(-8,20,-4,STONE:0)
Block(-8,20,-3,STONE:0)
Block(-8,20,-2,STONE:0)
Block(-8,21,-5,LOG:5)
Block(-8,21,-4,STONE:0)
Block(-8,21,-3,STONE:0)
Block(-8,21,-2,STONE:0)
Block(-8,21,-1,LOG:5)
Block(-8,21,0,STONE:0)
Block(-8,21,1,STONE:0)
Block(-8,21,2,STONE:0)
Block(-8,21,3,LOG:1)
Block(-8,22,-11,GRASS:0)
Block(-8,22,-10,STONE:0)
Block(-8,22,-9,STONE:0)
Block(-8,22,-8,STONE:0)
Block(-8,22,-7,STONE:0)
Block(-8,22,-6,STONE:0)
Block(-8,22,-5,LOG:1)
Block(-8,22,-4,RAILS:1)
Block(-8,22,-3,STEP:3)
Block(-8,22,-2,RAILS:1)
Block(-8,22,-1,LOG:1)
Block(-8,22,0,RAILS:2)
Block(-8,22,1,COBBLESTONE_STAIRS:0)
Block(-8,22,2,RAILS:2)
Block(-8,22,3,LOG:1)
Block(-8,22,4,STONE:0)
Block(-8,22,5,STONE:0)
Block(-8,22,6,STONE:0)
Block(-8,22,7,STONE:0)
Block(-8,22,8,STONE:0)
Block(-8,22,9,STONE:0)
Block(-8,22,10,STONE:0)
Block(-8,22,11,GRASS:0)
Block(-8,22,12,GRASS:0)
Block(-8,23,-10,STONE:0)
Block(-8,23,-9,STONE:0)
Block(-8,23,-8,STONE:0)
Block(-8,23,-7,STONE:0)
Block(-8,23,-6,STONE:0)
Block(-8,23,-5,LOG:1)
Block(-8,23,-4,AIR:0)
Block(-8,23,-3,AIR:0)
Block(-8,23,-2,AIR:0)
Block(-8,23,-1,LOG:1)
Block(-8,23,0,AIR:0)
Block(-8,23,1,AIR:0)
Block(-8,23,2,AIR:0)
Block(-8,23,3,LOG:1)
Block(-8,23,4,STONE:0)
Block(-8,23,5,STONE:0)
Block(-8,23,6,STONE:0)
Block(-8,23,7,STONE:0)
Block(-8,23,8,STONE:0)
Block(-8,23,9,STONE:0)
Block(-8,23,10,STONE:0)
Block(-8,24,-10,STONE:0)
Block(-8,24,-9,STONE:0)
Block(-8,24,-8,STONE:0)
Block(-8,24,-7,STONE:0)
Block(-8,24,-6,STONE:0)
Block(-8,24,-5,LOG:1)
Block(-8,24,-4,AIR:0)
Block(-8,24,-3,AIR:0)
Block(-8,24,-2,AIR:0)
Block(-8,24,-1,LOG:1)
Block(-8,24,0,AIR:0)
Block(-8,24,1,AIR:0)
Block(-8,24,2,AIR:0)
Block(-8,24,3,LOG:1)
Block(-8,24,4,STONE:0)
Block(-8,24,5,STONE:0)
Block(-8,24,6,STONE:0)
Block(-8,24,7,STONE:0)
Block(-8,24,8,STONE:0)
Block(-8,24,9,STONE:0)
Block(-8,24,10,STONE:0)
Block(-8,25,-10,GRASS:0)
Block(-8,25,-9,STONE:0)
Block(-8,25,-8,STONE:0)
Block(-8,25,-7,STONE:0)
Block(-8,25,-6,STONE:0)
Block(-8,25,-5,STONE:0)
Block(-8,25,-4,LOG:9)
Block(-8,25,-3,LOG:9)
Block(-8,25,-2,LOG:9)
Block(-8,25,-1,LOG:5)
Block(-8,25,0,AIR:0)
Block(-8,25,1,AIR:0)
Block(-8,25,2,AIR:0)
Block(-8,25,3,LOG:5)
Block(-8,25,4,STONE:0)
Block(-8,25,5,STONE:0)
Block(-8,25,6,STONE:0)
Block(-8,25,7,STONE:0)
Block(-8,25,8,STONE:0)
Block(-8,25,9,STONE:0)
Block(-8,25,10,GRASS:0)
Block(-8,26,-9,STONE:0)
Block(-8,26,-8,STONE:0)
Block(-8,26,-7,STONE:0)
Block(-8,26,-6,STONE:0)
Block(-8,26,-5,STONE:0)
Block(-8,26,-4,STONE:0)
Block(-8,26,-3,STONE:0)
Block(-8,26,-2,STONE:0)
Block(-8,26,-1,STONE:0)
Block(-8,26,0,LOG:9)
Block(-8,26,1,LOG:9)
Block(-8,26,2,LOG:9)
Block(-8,26,3,STONE:0)
Block(-8,26,4,STONE:0)
Block(-8,26,5,STONE:0)
Block(-8,26,6,STONE:0)
Block(-8,26,7,STONE:0)
Block(-8,26,8,STONE:0)
Block(-8,26,9,STONE:0)
Block(-8,27,-9,GRASS:0)
Block(-8,27,-8,STONE:0)
Block(-8,27,-7,STONE:0)
Block(-8,27,-6,STONE:0)
Block(-8,27,-5,STONE:0)
Block(-8,27,-4,STONE:0)
Block(-8,27,-3,STONE:0)
Block(-8,27,-2,STONE:0)
Block(-8,27,-1,STONE:0)
Block(-8,27,0,STONE:0)
Block(-8,27,1,STONE:0)
Block(-8,27,2,STONE:0)
Block(-8,27,3,STONE:0)
Block(-8,27,4,STONE:0)
Block(-8,27,5,STONE:0)
Block(-8,27,6,STONE:0)
Block(-8,27,7,STONE:0)
Block(-8,27,8,STONE:0)
Block(-8,27,9,STONE:0)
Block(-8,28,-8,STONE:0)
Block(-8,28,-7,STONE:0)
Block(-8,28,-6,STONE:0)
Block(-8,28,-5,STONE:0)
Block(-8,28,-4,STONE:0)
Block(-8,28,-3,STONE:0)
Block(-8,28,-2,STONE:0)
Block(-8,28,-1,STONE:0)
Block(-8,28,0,STONE:0)
Block(-8,28,1,STONE:0)
Block(-8,28,2,STONE:0)
Block(-8,28,3,STONE:0)
Block(-8,28,4,STONE:0)
Block(-8,28,5,STONE:0)
Block(-8,28,6,STONE:0)
Block(-8,28,7,STONE:0)
Block(-8,28,8,STONE:0)
Block(-8,28,9,STONE:0)
Block(-8,29,-8,GRASS:0)
Block(-8,29,-7,STONE:0)
Block(-8,29,-6,STONE:0)
Block(-8,29,-5,STONE:0)
Block(-8,29,-4,STONE:0)
Block(-8,29,-3,STONE:0)
Block(-8,29,-2,STONE:0)
Block(-8,29,-1,STONE:0)
Block(-8,29,0,STONE:0)
Block(-8,29,1,STONE:0)
Block(-8,29,2,STONE:0)
Block(-8,29,3,STONE:0)
Block(-8,29,4,STONE:0)
Block(-8,29,5,STONE:0)
Block(-8,29,6,STONE:0)
Block(-8,29,7,STONE:0)
Block(-8,29,8,STONE:0)
Block(-8,29,9,GRASS:0)
Block(-8,30,-7,GRASS:0)
Block(-8,30,-6,GRASS:0)
Block(-8,30,-5,STONE:0)
Block(-8,30,-4,STONE:0)
Block(-8,30,-3,STONE:0)
Block(-8,30,-2,STONE:0)
Block(-8,30,-1,STONE:0)
Block(-8,30,0,STONE:0)
Block(-8,30,1,STONE:0)
Block(-8,30,2,STONE:0)
Block(-8,30,3,STONE:0)
Block(-8,30,4,STONE:0)
Block(-8,30,5,STONE:0)
Block(-8,30,6,STONE:0)
Block(-8,30,7,STONE:0)
Block(-8,30,8,GRASS:0)
Block(-8,31,-5,STONE:0)
Block(-8,31,-4,STONE:0)
Block(-8,31,-3,STONE:0)
Block(-8,31,-2,STONE:0)
Block(-8,31,-1,STONE:0)
Block(-8,31,0,STONE:0)
Block(-8,31,1,STONE:0)
Block(-8,31,2,GRASS:0)
Block(-8,31,3,GRASS:0)
Block(-8,31,4,STONE:0)
Block(-8,31,5,STONE:0)
Block(-8,31,6,STONE:0)
Block(-8,31,7,GRASS:0)
Block(-8,32,-3,GRASS:0)
Block(-8,32,-2,GRASS:0)
Block(-8,32,-1,GRASS:0)
Block(-8,32,0,GRASS:0)
Block(-8,32,1,GRASS:0)
Block(-8,32,4,GRASS:0)
Block(-8,32,5,GRASS:0)
Block(-8,32,6,GRASS:0)
Block(-7,19,-4,STONE:0)
Block(-7,19,-3,STONE:0)
Block(-7,19,-2,STONE:0)
Block(-7,20,-4,STONE:0)
Block(-7,20,-3,STONE:0)
Block(-7,20,-2,STONE:0)
Block(-7,21,-5,LOG:5)
Block(-7,21,-4,RAILS:3)
Block(-7,21,-3,COBBLESTONE_STAIRS:1)
Block(-7,21,-2,RAILS:3)
Block(-7,21,-1,LOG:5)
Block(-7,21,1,STONE:0)
Block(-7,21,2,STONE:0)
Block(-7,22,-11,GRASS:0)
Block(-7,22,-10,STONE:0)
Block(-7,22,-9,STONE:0)
Block(-7,22,-8,STONE:0)
Block(-7,22,-7,STONE:0)
Block(-7,22,-6,STONE:0)
Block(-7,22,-5,STONE:0)
Block(-7,22,-4,AIR:0)
Block(-7,22,-3,AIR:0)
Block(-7,22,-2,AIR:0)
Block(-7,22,-1,FENCE:0)
Block(-7,22,0,STONE:0)
Block(-7,22,1,STONE:0)
Block(-7,22,2,STONE:0)
Block(-7,22,3,STONE:0)
Block(-7,22,4,STONE:0)
Block(-7,22,5,STONE:0)
Block(-7,22,6,STONE:0)
Block(-7,22,7,STONE:0)
Block(-7,22,8,STONE:0)
Block(-7,22,9,STONE:0)
Block(-7,22,10,STONE:0)
Block(-7,22,11,GRASS:0)
Block(-7,22,12,GRASS:0)
Block(-7,23,-10,STONE:0)
Block(-7,23,-9,STONE:0)
Block(-7,23,-8,STONE:0)
Block(-7,23,-7,STONE:0)
Block(-7,23,-6,STONE:0)
Block(-7,23,-5,STONE:0)
Block(-7,23,-4,AIR:0)
Block(-7,23,-3,AIR:0)
Block(-7,23,-2,AIR:0)
Block(-7,23,-1,FENCE:0)
Block(-7,23,0,RAILS:2)
Block(-7,23,1,COBBLESTONE_STAIRS:0)
Block(-7,23,2,RAILS:2)
Block(-7,23,3,STONE:0)
Block(-7,23,4,STONE:0)
Block(-7,23,5,STONE:0)
Block(-7,23,6,STONE:0)
Block(-7,23,7,STONE:0)
Block(-7,23,8,STONE:0)
Block(-7,23,9,STONE:0)
Block(-7,23,10,STONE:0)
Block(-7,24,-10,GRASS:0)
Block(-7,24,-9,STONE:0)
Block(-7,24,-8,STONE:0)
Block(-7,24,-7,STONE:0)
Block(-7,24,-6,STONE:0)
Block(-7,24,-5,STONE:0)
Block(-7,24,-4,AIR:0)
Block(-7,24,-3,AIR:0)
Block(-7,24,-2,AIR:0)
Block(-7,24,-1,FENCE:0)
Block(-7,24,0,AIR:0)
Block(-7,24,1,AIR:0)
Block(-7,24,2,AIR:0)
Block(-7,24,3,STONE:0)
Block(-7,24,4,STONE:0)
Block(-7,24,5,STONE:0)
Block(-7,24,6,STONE:0)
Block(-7,24,7,STONE:0)
Block(-7,24,8,STONE:0)
Block(-7,24,9,STONE:0)
Block(-7,24,10,STONE:0)
Block(-7,25,-9,STONE:0)
Block(-7,25,-8,STONE:0)
Block(-7,25,-7,STONE:0)
Block(-7,25,-6,STONE:0)
Block(-7,25,-5,STONE:0)
Block(-7,25,-4,STONE:0)
Block(-7,25,-3,STONE:0)
Block(-7,25,-2,STONE:0)
Block(-7,25,-1,LOG:5)
Block(-7,25,0,AIR:0)
Block(-7,25,1,AIR:0)
Block(-7,25,2,AIR:0)
Block(-7,25,3,LOG:5)
Block(-7,25,4,STONE:0)
Block(-7,25,5,STONE:0)
Block(-7,25,6,STONE:0)
Block(-7,25,7,STONE:0)
Block(-7,25,8,STONE:0)
Block(-7,25,9,STONE:0)
Block(-7,25,10,STONE:0)
Block(-7,26,-9,STONE:0)
Block(-7,26,-8,STONE:0)
Block(-7,26,-7,STONE:0)
Block(-7,26,-6,STONE:0)
Block(-7,26,-5,STONE:0)
Block(-7,26,-4,STONE:0)
Block(-7,26,-3,STONE:0)
Block(-7,26,-2,STONE:0)
Block(-7,26,-1,STONE:0)
Block(-7,26,0,AIR:0)
Block(-7,26,1,TORCH:1)
Block(-7,26,2,AIR:0)
Block(-7,26,3,STONE:0)
Block(-7,26,4,STONE:0)
Block(-7,26,5,STONE:0)
Block(-7,26,6,STONE:0)
Block(-7,26,7,STONE:0)
Block(-7,26,8,STONE:0)
Block(-7,26,9,STONE:0)
Block(-7,26,10,STONE:0)
Block(-7,27,-9,GRASS:0)
Block(-7,27,-8,STONE:0)
Block(-7,27,-7,STONE:0)
Block(-7,27,-6,STONE:0)
Block(-7,27,-5,STONE:0)
Block(-7,27,-4,STONE:0)
Block(-7,27,-3,STONE:0)
Block(-7,27,-2,STONE:0)
Block(-7,27,-1,STONE:0)
Block(-7,27,0,STONE:0)
Block(-7,27,1,STONE:0)
Block(-7,27,2,STONE:0)
Block(-7,27,3,STONE:0)
Block(-7,27,4,STONE:0)
Block(-7,27,5,STONE:0)
Block(-7,27,6,STONE:0)
Block(-7,27,7,STONE:0)
Block(-7,27,8,STONE:0)
Block(-7,27,9,STONE:0)
Block(-7,27,10,GRASS:0)
Block(-7,28,-8,STONE:0)
Block(-7,28,-7,STONE:0)
Block(-7,28,-6,STONE:0)
Block(-7,28,-5,STONE:0)
Block(-7,28,-4,STONE:0)
Block(-7,28,-3,STONE:0)
Block(-7,28,-2,STONE:0)
Block(-7,28,-1,STONE:0)
Block(-7,28,0,STONE:0)
Block(-7,28,1,STONE:0)
Block(-7,28,2,STONE:0)
Block(-7,28,3,STONE:0)
Block(-7,28,4,STONE:0)
Block(-7,28,5,STONE:0)
Block(-7,28,6,STONE:0)
Block(-7,28,7,STONE:0)
Block(-7,28,8,STONE:0)
Block(-7,28,9,STONE:0)
Block(-7,29,-8,STONE:0)
Block(-7,29,-7,STONE:0)
Block(-7,29,-6,STONE:0)
Block(-7,29,-5,STONE:0)
Block(-7,29,-4,STONE:0)
Block(-7,29,-3,STONE:0)
Block(-7,29,-2,STONE:0)
Block(-7,29,-1,STONE:0)
Block(-7,29,0,STONE:0)
Block(-7,29,1,STONE:0)
Block(-7,29,2,STONE:0)
Block(-7,29,3,STONE:0)
Block(-7,29,4,STONE:0)
Block(-7,29,5,STONE:0)
Block(-7,29,6,STONE:0)
Block(-7,29,7,STONE:0)
Block(-7,29,8,STONE:0)
Block(-7,29,9,STONE:0)
Block(-7,30,-8,GRASS:0)
Block(-7,30,-7,GRASS:0)
Block(-7,30,-6,STONE:0)
Block(-7,30,-5,STONE:0)
Block(-7,30,-4,STONE:0)
Block(-7,30,-3,STONE:0)
Block(-7,30,-2,STONE:0)
Block(-7,30,-1,STONE:0)
Block(-7,30,0,STONE:0)
Block(-7,30,1,STONE:0)
Block(-7,30,2,STONE:0)
Block(-7,30,3,STONE:0)
Block(-7,30,4,STONE:0)
Block(-7,30,5,STONE:0)
Block(-7,30,6,STONE:0)
Block(-7,30,7,STONE:0)
Block(-7,30,8,STONE:0)
Block(-7,30,9,GRASS:0)
Block(-7,31,-6,GRASS:0)
Block(-7,31,-5,STONE:0)
Block(-7,31,-4,STONE:0)
Block(-7,31,-3,STONE:0)
Block(-7,31,-2,STONE:0)
Block(-7,31,-1,STONE:0)
Block(-7,31,0,STONE:0)
Block(-7,31,1,STONE:0)
Block(-7,31,2,STONE:0)
Block(-7,31,3,STONE:0)
Block(-7,31,4,STONE:0)
Block(-7,31,5,STONE:0)
Block(-7,31,6,STONE:0)
Block(-7,31,7,GRASS:0)
Block(-7,31,8,GRASS:0)
Block(-7,32,-4,GRASS:0)
Block(-7,32,-3,GRASS:0)
Block(-7,32,-2,GRASS:0)
Block(-7,32,-1,GRASS:0)
Block(-7,32,0,STONE:0)
Block(-7,32,1,STONE:0)
Block(-7,32,2,GRASS:0)
Block(-7,32,3,GRASS:0)
Block(-7,32,4,GRASS:0)
Block(-7,32,5,GRASS:0)
Block(-7,32,6,GRASS:0)
Block(-7,33,0,GRASS:0)
Block(-7,33,1,GRASS:0)
Block(-6,4,1,AIR:0)
Block(-6,16,-5,LOG:5)
Block(-6,16,-1,LOG:5)
Block(-6,18,-4,STONE:0)
Block(-6,18,-3,STONE:0)
Block(-6,18,-2,STONE:0)
Block(-6,19,-4,STONE:0)
Block(-6,19,-3,STONE:0)
Block(-6,19,-2,STONE:0)
Block(-6,20,-4,RAILS:3)
Block(-6,20,-3,COBBLESTONE_STAIRS:1)
Block(-6,20,-2,RAILS:3)
Block(-6,21,-5,LOG:5)
Block(-6,21,-4,AIR:0)
Block(-6,21,-3,AIR:0)
Block(-6,21,-2,AIR:0)
Block(-6,21,-1,LOG:5)
Block(-6,21,1,STONE:0)
Block(-6,22,-11,GRASS:0)
Block(-6,22,-10,GRASS:0)
Block(-6,22,-9,STONE:0)
Block(-6,22,-8,STONE:0)
Block(-6,22,-7,STONE:0)
Block(-6,22,-6,STONE:0)
Block(-6,22,-5,STONE:0)
Block(-6,22,-4,AIR:0)
Block(-6,22,-3,AIR:0)
Block(-6,22,-2,AIR:0)
Block(-6,22,-1,FENCE:0)
Block(-6,22,0,STONE:0)
Block(-6,22,1,STONE:0)
Block(-6,22,2,STONE:0)
Block(-6,22,3,STONE:0)
Block(-6,22,4,STONE:0)
Block(-6,22,5,STONE:0)
Block(-6,22,6,STONE:0)
Block(-6,22,7,STONE:0)
Block(-6,22,8,STONE:0)
Block(-6,22,9,STONE:0)
Block(-6,22,10,GRASS:0)
Block(-6,22,11,GRASS:0)
Block(-6,22,12,GRASS:0)
Block(-6,23,-9,STONE:0)
Block(-6,23,-8,STONE:0)
Block(-6,23,-7,STONE:0)
Block(-6,23,-6,STONE:0)
Block(-6,23,-5,STONE:0)
Block(-6,23,-4,AIR:0)
Block(-6,23,-3,AIR:0)
Block(-6,23,-2,AIR:0)
Block(-6,23,-1,FENCE:0)
Block(-6,23,0,STONE:0)
Block(-6,23,1,STONE:0)
Block(-6,23,2,STONE:0)
Block(-6,23,3,STONE:0)
Block(-6,23,4,STONE:0)
Block(-6,23,5,STONE:0)
Block(-6,23,6,STONE:0)
Block(-6,23,7,STONE:0)
Block(-6,23,8,STONE:0)
Block(-6,23,9,STONE:0)
Block(-6,24,-9,STONE:0)
Block(-6,24,-8,STONE:0)
Block(-6,24,-7,STONE:0)
Block(-6,24,-6,STONE:0)
Block(-6,24,-5,STONE:0)
Block(-6,24,-4,STONE:0)
Block(-6,24,-3,STONE:0)
Block(-6,24,-2,STONE:0)
Block(-6,24,-1,STONE:0)
Block(-6,24,0,RAILS:2)
Block(-6,24,1,COBBLESTONE_STAIRS:0)
Block(-6,24,2,RAILS:2)
Block(-6,24,3,STONE:0)
Block(-6,24,4,STONE:0)
Block(-6,24,5,STONE:0)
Block(-6,24,6,STONE:0)
Block(-6,24,7,STONE:0)
Block(-6,24,8,STONE:0)
Block(-6,24,9,STONE:0)
Block(-6,25,-9,STONE:0)
Block(-6,25,-8,STONE:0)
Block(-6,25,-7,STONE:0)
Block(-6,25,-6,STONE:0)
Block(-6,25,-5,STONE:0)
Block(-6,25,-4,STONE:0)
Block(-6,25,-3,STONE:0)
Block(-6,25,-2,STONE:0)
Block(-6,25,-1,LOG:5)
Block(-6,25,0,AIR:0)
Block(-6,25,1,AIR:0)
Block(-6,25,2,AIR:0)
Block(-6,25,3,LOG:5)
Block(-6,25,4,STONE:0)
Block(-6,25,5,STONE:0)
Block(-6,25,6,STONE:0)
Block(-6,25,7,STONE:0)
Block(-6,25,8,STONE:0)
Block(-6,25,9,STONE:0)
Block(-6,26,-9,GRASS:0)
Block(-6,26,-8,STONE:0)
Block(-6,26,-7,STONE:0)
Block(-6,26,-6,STONE:0)
Block(-6,26,-5,STONE:0)
Block(-6,26,-4,STONE:0)
Block(-6,26,-3,STONE:0)
Block(-6,26,-2,STONE:0)
Block(-6,26,-1,STONE:0)
Block(-6,26,0,AIR:0)
Block(-6,26,1,AIR:0)
Block(-6,26,2,AIR:0)
Block(-6,26,3,FENCE:0)
Block(-6,26,4,STONE:0)
Block(-6,26,5,STONE:0)
Block(-6,26,6,STONE:0)
Block(-6,26,7,STONE:0)
Block(-6,26,8,STONE:0)
Block(-6,26,9,STONE:0)
Block(-6,27,-8,GRASS:0)
Block(-6,27,-7,STONE:0)
Block(-6,27,-6,STONE:0)
Block(-6,27,-5,STONE:0)
Block(-6,27,-4,STONE:0)
Block(-6,27,-3,STONE:0)
Block(-6,27,-2,STONE:0)
Block(-6,27,-1,STONE:0)
Block(-6,27,0,AIR:0)
Block(-6,27,1,AIR:0)
Block(-6,27,2,AIR:0)
Block(-6,27,3,FENCE:0)
Block(-6,27,4,STONE:0)
Block(-6,27,5,STONE:0)
Block(-6,27,6,STONE:0)
Block(-6,27,7,STONE:0)
Block(-6,27,8,STONE:0)
Block(-6,27,9,GRASS:0)
Block(-6,28,-7,GRASS:0)
Block(-6,28,-6,STONE:0)
Block(-6,28,-5,STONE:0)
Block(-6,28,-4,STONE:0)
Block(-6,28,-3,STONE:0)
Block(-6,28,-2,STONE:0)
Block(-6,28,-1,STONE:0)
Block(-6,28,0,STONE:0)
Block(-6,28,1,STONE:0)
Block(-6,28,2,STONE:0)
Block(-6,28,3,STONE:0)
Block(-6,28,4,STONE:0)
Block(-6,28,5,STONE:0)
Block(-6,28,6,STONE:0)
Block(-6,28,7,STONE:0)
Block(-6,28,8,STONE:0)
Block(-6,29,-6,STONE:0)
Block(-6,29,-5,STONE:0)
Block(-6,29,-4,STONE:0)
Block(-6,29,-3,STONE:0)
Block(-6,29,-2,STONE:0)
Block(-6,29,-1,STONE:0)
Block(-6,29,0,STONE:0)
Block(-6,29,1,STONE:0)
Block(-6,29,2,STONE:0)
Block(-6,29,3,STONE:0)
Block(-6,29,4,STONE:0)
Block(-6,29,5,STONE:0)
Block(-6,29,6,STONE:0)
Block(-6,29,7,STONE:0)
Block(-6,29,8,GRASS:0)
Block(-6,30,-6,GRASS:0)
Block(-6,30,-5,STONE:0)
Block(-6,30,-4,STONE:0)
Block(-6,30,-3,STONE:0)
Block(-6,30,-2,STONE:0)
Block(-6,30,-1,STONE:0)
Block(-6,30,0,STONE:0)
Block(-6,30,1,STONE:0)
Block(-6,30,2,STONE:0)
Block(-6,30,3,STONE:0)
Block(-6,30,4,STONE:0)
Block(-6,30,5,STONE:0)
Block(-6,30,6,STONE:0)
Block(-6,30,7,STONE:0)
Block(-6,31,-5,GRASS:0)
Block(-6,31,-4,STONE:0)
Block(-6,31,-3,STONE:0)
Block(-6,31,-2,STONE:0)
Block(-6,31,-1,STONE:0)
Block(-6,31,0,STONE:0)
Block(-6,31,1,STONE:0)
Block(-6,31,2,STONE:0)
Block(-6,31,3,STONE:0)
Block(-6,31,4,STONE:0)
Block(-6,31,5,STONE:0)
Block(-6,31,6,STONE:0)
Block(-6,31,7,STONE:0)
Block(-6,32,-4,GRASS:0)
Block(-6,32,-3,GRASS:0)
Block(-6,32,-2,GRASS:0)
Block(-6,32,-1,DIRT:0)
Block(-6,32,0,STONE:0)
Block(-6,32,1,STONE:0)
Block(-6,32,2,STONE:0)
Block(-6,32,3,STONE:0)
Block(-6,32,4,GRASS:0)
Block(-6,32,5,GRASS:0)
Block(-6,32,6,GRASS:0)
Block(-6,32,7,GRASS:0)
Block(-6,33,-1,GRASS:0)
Block(-6,33,0,GRASS:0)
Block(-6,33,1,GRASS:0)
Block(-6,33,2,GRASS:0)
Block(-6,33,3,GRASS:0)
Block(-5,0,-1,LOG:1)
Block(-5,1,-1,LOG:1)
Block(-5,2,-1,LOG:1)
Block(-5,3,-2,FENCE:0)
Block(-5,3,-1,LOG:1)
Block(-5,3,1,AIR:0)
Block(-5,3,2,AIR:0)
Block(-5,4,-2,FENCE:0)
Block(-5,4,-1,LOG:1)
Block(-5,4,1,AIR:0)
Block(-5,4,2,AIR:0)
Block(-5,4,3,AIR:0)
Block(-5,5,-2,FENCE:0)
Block(-5,5,-1,LOG:5)
Block(-5,5,1,AIR:0)
Block(-5,5,2,AIR:0)
Block(-5,5,3,AIR:0)
Block(-5,16,-5,LOG:5)
Block(-5,16,-1,LOG:5)
Block(-5,17,-4,STONE:0)
Block(-5,17,-2,STONE:0)
Block(-5,18,-4,STONE:0)
Block(-5,18,-3,STONE:0)
Block(-5,18,-2,STONE:0)
Block(-5,19,-4,RAILS:3)
Block(-5,19,-3,COBBLESTONE_STAIRS:1)
Block(-5,19,-2,RAILS:3)
Block(-5,20,-4,AIR:0)
Block(-5,20,-3,AIR:0)
Block(-5,20,-2,AIR:0)
Block(-5,21,-5,LOG:5)
Block(-5,21,-4,AIR:0)
Block(-5,21,-3,AIR:0)
Block(-5,21,-2,AIR:0)
Block(-5,21,-1,LOG:5)
Block(-5,22,-11,GRASS:0)
Block(-5,22,-10,STONE:0)
Block(-5,22,-9,STONE:0)
Block(-5,22,-8,STONE:0)
Block(-5,22,-7,STONE:0)
Block(-5,22,-6,STONE:0)
Block(-5,22,-5,STONE:0)
Block(-5,22,-4,AIR:0)
Block(-5,22,-3,AIR:0)
Block(-5,22,-2,AIR:0)
Block(-5,22,-1,FENCE:0)
Block(-5,22,0,STONE:0)
Block(-5,22,1,STONE:0)
Block(-5,22,2,STONE:0)
Block(-5,22,3,STONE:0)
Block(-5,22,4,STONE:0)
Block(-5,22,5,STONE:0)
Block(-5,22,6,STONE:0)
Block(-5,22,7,STONE:0)
Block(-5,22,8,STONE:0)
Block(-5,22,9,STONE:0)
Block(-5,22,10,GRASS:0)
Block(-5,22,11,GRASS:0)
Block(-5,22,12,GRASS:0)
Block(-5,23,-10,STONE:0)
Block(-5,23,-9,STONE:0)
Block(-5,23,-8,STONE:0)
Block(-5,23,-7,STONE:0)
Block(-5,23,-6,STONE:0)
Block(-5,23,-5,STONE:0)
Block(-5,23,-4,STONE:0)
Block(-5,23,-3,STONE:0)
Block(-5,23,-2,STONE:0)
Block(-5,23,-1,STONE:0)
Block(-5,23,0,STONE:0)
Block(-5,23,1,STONE:0)
Block(-5,23,2,STONE:0)
Block(-5,23,3,STONE:0)
Block(-5,23,4,STONE:0)
Block(-5,23,5,STONE:0)
Block(-5,23,6,STONE:0)
Block(-5,23,7,STONE:0)
Block(-5,23,8,STONE:0)
Block(-5,23,9,STONE:0)
Block(-5,24,-10,GRASS:0)
Block(-5,24,-9,STONE:0)
Block(-5,24,-8,STONE:0)
Block(-5,24,-7,STONE:0)
Block(-5,24,-6,STONE:0)
Block(-5,24,-5,STONE:0)
Block(-5,24,-4,STONE:0)
Block(-5,24,-3,STONE:0)
Block(-5,24,-2,STONE:0)
Block(-5,24,-1,STONE:0)
Block(-5,24,0,STONE:0)
Block(-5,24,1,STONE:0)
Block(-5,24,2,STONE:0)
Block(-5,24,3,STONE:0)
Block(-5,24,4,STONE:0)
Block(-5,24,5,STONE:0)
Block(-5,24,6,STONE:0)
Block(-5,24,7,STONE:0)
Block(-5,24,8,STONE:0)
Block(-5,24,9,STONE:0)
Block(-5,25,-9,GRASS:0)
Block(-5,25,-8,STONE:0)
Block(-5,25,-7,STONE:0)
Block(-5,25,-6,STONE:0)
Block(-5,25,-5,STONE:0)
Block(-5,25,-4,STONE:0)
Block(-5,25,-3,STONE:0)
Block(-5,25,-2,STONE:0)
Block(-5,25,-1,LOG:5)
Block(-5,25,0,RAILS:2)
Block(-5,25,1,COBBLESTONE_STAIRS:0)
Block(-5,25,2,RAILS:2)
Block(-5,25,3,LOG:5)
Block(-5,25,4,STONE:0)
Block(-5,25,5,STONE:0)
Block(-5,25,6,STONE:0)
Block(-5,25,7,STONE:0)
Block(-5,25,8,STONE:0)
Block(-5,25,9,GRASS:0)
Block(-5,26,-8,STONE:0)
Block(-5,26,-7,STONE:0)
Block(-5,26,-6,STONE:0)
Block(-5,26,-5,STONE:0)
Block(-5,26,-4,STONE:0)
Block(-5,26,-3,STONE:0)
Block(-5,26,-2,STONE:0)
Block(-5,26,-1,LOG:1)
Block(-5,26,0,AIR:0)
Block(-5,26,1,AIR:0)
Block(-5,26,2,AIR:0)
Block(-5,26,3,LOG:1)
Block(-5,26,4,STONE:0)
Block(-5,26,5,STONE:0)
Block(-5,26,6,STONE:0)
Block(-5,26,7,STONE:0)
Block(-5,26,8,STONE:0)
Block(-5,27,-8,GRASS:0)
Block(-5,27,-7,STONE:0)
Block(-5,27,-6,STONE:0)
Block(-5,27,-5,STONE:0)
Block(-5,27,-4,STONE:0)
Block(-5,27,-3,STONE:0)
Block(-5,27,-2,STONE:0)
Block(-5,27,-1,LOG:1)
Block(-5,27,0,AIR:0)
Block(-5,27,1,AIR:0)
Block(-5,27,2,AIR:0)
Block(-5,27,3,LOG:1)
Block(-5,27,4,STONE:0)
Block(-5,27,5,STONE:0)
Block(-5,27,6,STONE:0)
Block(-5,27,7,STONE:0)
Block(-5,27,8,GRASS:0)
Block(-5,28,-7,GRASS:0)
Block(-5,28,-6,STONE:0)
Block(-5,28,-5,STONE:0)
Block(-5,28,-4,STONE:0)
Block(-5,28,-3,STONE:0)
Block(-5,28,-2,STONE:0)
Block(-5,28,-1,LOG:1)
Block(-5,28,3,LOG:1)
Block(-5,28,4,STONE:0)
Block(-5,28,5,STONE:0)
Block(-5,28,6,STONE:0)
Block(-5,28,7,STONE:0)
Block(-5,29,-6,STONE:0)
Block(-5,29,-5,STONE:0)
Block(-5,29,-4,STONE:0)
Block(-5,29,-3,STONE:0)
Block(-5,29,-2,STONE:0)
Block(-5,29,-1,STONE:0)
Block(-5,29,0,LOG:9)
Block(-5,29,1,LOG:9)
Block(-5,29,2,LOG:9)
Block(-5,29,3,STONE:0)
Block(-5,29,4,STONE:0)
Block(-5,29,5,STONE:0)
Block(-5,29,6,STONE:0)
Block(-5,29,7,STONE:0)
Block(-5,30,-6,STONE:0)
Block(-5,30,-5,STONE:0)
Block(-5,30,-4,STONE:0)
Block(-5,30,-3,STONE:0)
Block(-5,30,-2,STONE:0)
Block(-5,30,-1,STONE:0)
Block(-5,30,0,STONE:0)
Block(-5,30,1,STONE:0)
Block(-5,30,2,STONE:0)
Block(-5,30,3,STONE:0)
Block(-5,30,4,STONE:0)
Block(-5,30,5,STONE:0)
Block(-5,30,6,STONE:0)
Block(-5,30,7,GRASS:0)
Block(-5,31,-6,GRASS:0)
Block(-5,31,-5,STONE:0)
Block(-5,31,-4,STONE:0)
Block(-5,31,-3,STONE:0)
Block(-5,31,-2,STONE:0)
Block(-5,31,-1,STONE:0)
Block(-5,31,0,STONE:0)
Block(-5,31,1,STONE:0)
Block(-5,31,2,STONE:0)
Block(-5,31,3,STONE:0)
Block(-5,31,4,STONE:0)
Block(-5,31,5,STONE:0)
Block(-5,31,6,STONE:0)
Block(-5,32,-5,GRASS:0)
Block(-5,32,-4,GRASS:0)
Block(-5,32,-3,GRASS:0)
Block(-5,32,-2,GRASS:0)
Block(-5,32,-1,GRASS:0)
Block(-5,32,0,DIRT:0)
Block(-5,32,1,STONE:0)
Block(-5,32,2,STONE:0)
Block(-5,32,3,STONE:0)
Block(-5,32,4,STONE:0)
Block(-5,32,5,GRASS:0)
Block(-5,32,6,GRASS:0)
Block(-5,33,0,GRASS:0)
Block(-5,33,1,GRASS:0)
Block(-5,33,2,GRASS:0)
Block(-5,33,3,GRASS:0)
Block(-5,33,4,GRASS:0)
Block(-4,3,-4,AIR:0)
Block(-4,3,-3,AIR:0)
Block(-4,3,-2,AIR:0)
Block(-4,3,-1,AIR:0)
Block(-4,3,0,AIR:0)
Block(-4,3,1,AIR:0)
Block(-4,3,2,AIR:0)
Block(-4,3,3,AIR:0)
Block(-4,3,4,AIR:0)
Block(-4,4,-4,AIR:0)
Block(-4,4,-3,AIR:0)
Block(-4,4,-2,AIR:0)
Block(-4,4,-1,AIR:0)
Block(-4,4,0,AIR:0)
Block(-4,4,1,AIR:0)
Block(-4,4,2,AIR:0)
Block(-4,4,3,AIR:0)
Block(-4,4,4,AIR:0)
Block(-4,5,-4,AIR:0)
Block(-4,5,-3,AIR:0)
Block(-4,5,-2,AIR:0)
Block(-4,5,-1,LOG:5)
Block(-4,5,0,AIR:0)
Block(-4,5,1,AIR:0)
Block(-4,5,2,AIR:0)
Block(-4,5,3,AIR:0)
Block(-4,16,-5,LOG:5)
Block(-4,16,-4,STONE:0)
Block(-4,16,-2,STONE:0)
Block(-4,16,-1,LOG:5)
Block(-4,17,-4,STONE:0)
Block(-4,17,-3,STONE:0)
Block(-4,17,-2,STONE:0)
Block(-4,18,-4,RAILS:3)
Block(-4,18,-3,COBBLESTONE_STAIRS:1)
Block(-4,18,-2,RAILS:3)
Block(-4,19,-4,AIR:0)
Block(-4,19,-3,AIR:0)
Block(-4,19,-2,AIR:0)
Block(-4,20,-4,AIR:0)
Block(-4,20,-3,AIR:0)
Block(-4,20,-2,AIR:0)
Block(-4,21,-5,LOG:5)
Block(-4,21,-4,AIR:0)
Block(-4,21,-3,TORCH:2)
Block(-4,21,-2,AIR:0)
Block(-4,21,-1,LOG:5)
Block(-4,22,-11,GRASS:0)
Block(-4,22,-10,STONE:0)
Block(-4,22,-9,STONE:0)
Block(-4,22,-8,STONE:0)
Block(-4,22,-7,STONE:0)
Block(-4,22,-6,STONE:0)
Block(-4,22,-5,STONE:0)
Block(-4,22,-4,STONE:0)
Block(-4,22,-3,STONE:0)
Block(-4,22,-2,STONE:0)
Block(-4,22,-1,STONE:0)
Block(-4,22,0,STONE:0)
Block(-4,22,1,STONE:0)
Block(-4,22,2,STONE:0)
Block(-4,22,3,STONE:0)
Block(-4,22,4,STONE:0)
Block(-4,22,5,STONE:0)
Block(-4,22,6,STONE:0)
Block(-4,22,7,STONE:0)
Block(-4,22,8,STONE:0)
Block(-4,22,9,STONE:0)
Block(-4,22,10,STONE:0)
Block(-4,22,11,GRASS:0)
Block(-4,22,12,GRASS:0)
Block(-4,23,-10,STONE:0)
Block(-4,23,-9,STONE:0)
Block(-4,23,-8,STONE:0)
Block(-4,23,-7,STONE:0)
Block(-4,23,-6,STONE:0)
Block(-4,23,-5,STONE:0)
Block(-4,23,-4,STONE:0)
Block(-4,23,-3,STONE:0)
Block(-4,23,-2,STONE:0)
Block(-4,23,-1,STONE:0)
Block(-4,23,0,STONE:0)
Block(-4,23,1,STONE:0)
Block(-4,23,2,STONE:0)
Block(-4,23,3,STONE:0)
Block(-4,23,4,STONE:0)
Block(-4,23,5,STONE:0)
Block(-4,23,6,STONE:0)
Block(-4,23,7,STONE:0)
Block(-4,23,8,STONE:0)
Block(-4,23,9,STONE:0)
Block(-4,23,10,STONE:0)
Block(-4,24,-10,GRASS:0)
Block(-4,24,-9,STONE:0)
Block(-4,24,-8,STONE:0)
Block(-4,24,-7,STONE:0)
Block(-4,24,-6,STONE:0)
Block(-4,24,-5,STONE:0)
Block(-4,24,-4,STONE:0)
Block(-4,24,-3,STONE:0)
Block(-4,24,-2,STONE:0)
Block(-4,24,-1,STONE:0)
Block(-4,24,0,STONE:0)
Block(-4,24,1,STONE:0)
Block(-4,24,2,STONE:0)
Block(-4,24,3,STONE:0)
Block(-4,24,4,STONE:0)
Block(-4,24,5,STONE:0)
Block(-4,24,6,STONE:0)
Block(-4,24,7,STONE:0)
Block(-4,24,8,STONE:0)
Block(-4,24,9,STONE:0)
Block(-4,24,10,STONE:0)
Block(-4,25,-9,STONE:0)
Block(-4,25,-8,STONE:0)
Block(-4,25,-7,STONE:0)
Block(-4,25,-6,STONE:0)
Block(-4,25,-5,STONE:0)
Block(-4,25,-4,STONE:0)
Block(-4,25,-3,STONE:0)
Block(-4,25,-2,STONE:0)
Block(-4,25,-1,STONE:0)
Block(-4,25,0,STONE:0)
Block(-4,25,1,STONE:0)
Block(-4,25,2,STONE:0)
Block(-4,25,3,STONE:0)
Block(-4,25,4,STONE:0)
Block(-4,25,5,STONE:0)
Block(-4,25,6,STONE:0)
Block(-4,25,7,STONE:0)
Block(-4,25,8,STONE:0)
Block(-4,25,9,STONE:0)
Block(-4,25,10,STONE:0)
Block(-4,26,-9,GRASS:0)
Block(-4,26,-8,STONE:0)
Block(-4,26,-7,STONE:0)
Block(-4,26,-6,STONE:0)
Block(-4,26,-5,STONE:0)
Block(-4,26,-4,STONE:0)
Block(-4,26,-3,STONE:0)
Block(-4,26,-2,STONE:0)
Block(-4,26,-1,STONE:0)
Block(-4,26,0,RAILS:2)
Block(-4,26,1,COBBLESTONE_STAIRS:0)
Block(-4,26,2,RAILS:2)
Block(-4,26,3,STONE:0)
Block(-4,26,4,STONE:0)
Block(-4,26,5,STONE:0)
Block(-4,26,6,STONE:0)
Block(-4,26,7,STONE:0)
Block(-4,26,8,STONE:0)
Block(-4,26,9,STONE:0)
Block(-4,26,10,GRASS:0)
Block(-4,27,-8,GRASS:0)
Block(-4,27,-7,STONE:0)
Block(-4,27,-6,STONE:0)
Block(-4,27,-5,STONE:0)
Block(-4,27,-4,STONE:0)
Block(-4,27,-3,STONE:0)
Block(-4,27,-2,STONE:0)
Block(-4,27,-1,FENCE:0)
Block(-4,27,0,AIR:0)
Block(-4,27,1,AIR:0)
Block(-4,27,2,AIR:0)
Block(-4,27,3,STONE:0)
Block(-4,27,4,STONE:0)
Block(-4,27,5,STONE:0)
Block(-4,27,6,STONE:0)
Block(-4,27,7,STONE:0)
Block(-4,27,8,STONE:0)
Block(-4,27,9,GRASS:0)
Block(-4,28,-7,STONE:0)
Block(-4,28,-6,STONE:0)
Block(-4,28,-5,STONE:0)
Block(-4,28,-4,STONE:0)
Block(-4,28,-3,STONE:0)
Block(-4,28,-2,STONE:0)
Block(-4,28,-1,FENCE:0)
Block(-4,28,3,STONE:0)
Block(-4,28,4,STONE:0)
Block(-4,28,5,STONE:0)
Block(-4,28,6,STONE:0)
Block(-4,28,7,STONE:0)
Block(-4,28,8,STONE:0)
Block(-4,29,-7,GRASS:0)
Block(-4,29,-6,GRASS:0)
Block(-4,29,-5,STONE:0)
Block(-4,29,-4,STONE:0)
Block(-4,29,-3,STONE:0)
Block(-4,29,-2,STONE:0)
Block(-4,29,-1,STONE:0)
Block(-4,29,3,STONE:0)
Block(-4,29,4,STONE:0)
Block(-4,29,5,STONE:0)
Block(-4,29,6,STONE:0)
Block(-4,29,7,GRASS:0)
Block(-4,29,8,GRASS:0)
Block(-4,30,-5,STONE:0)
Block(-4,30,-4,STONE:0)
Block(-4,30,-3,STONE:0)
Block(-4,30,-2,STONE:0)
Block(-4,30,-1,STONE:0)
Block(-4,30,0,STONE:0)
Block(-4,30,1,STONE:0)
Block(-4,30,2,STONE:0)
Block(-4,30,3,STONE:0)
Block(-4,30,4,STONE:0)
Block(-4,30,5,STONE:0)
Block(-4,30,6,STONE:0)
Block(-4,31,-5,GRASS:0)
Block(-4,31,-4,STONE:0)
Block(-4,31,-3,STONE:0)
Block(-4,31,-2,STONE:0)
Block(-4,31,-1,STONE:0)
Block(-4,31,0,STONE:0)
Block(-4,31,1,STONE:0)
Block(-4,31,2,STONE:0)
Block(-4,31,3,STONE:0)
Block(-4,31,4,STONE:0)
Block(-4,31,5,STONE:0)
Block(-4,31,6,STONE:0)
Block(-4,32,-4,GRASS:0)
Block(-4,32,-3,GRASS:0)
Block(-4,32,-2,GRASS:0)
Block(-4,32,-1,GRASS:0)
Block(-4,32,0,GRASS:0)
Block(-4,32,1,GRASS:0)
Block(-4,32,2,STONE:0)
Block(-4,32,3,STONE:0)
Block(-4,32,4,STONE:0)
Block(-4,32,5,STONE:0)
Block(-4,32,6,GRASS:0)
Block(-4,33,2,GRASS:0)
Block(-4,33,3,GRASS:0)
Block(-4,33,4,GRASS:0)
Block(-4,33,5,GRASS:0)
Block(-3,3,-5,AIR:0)
Block(-3,3,-4,AIR:0)
Block(-3,3,-3,AIR:0)
Block(-3,3,-2,AIR:0)
Block(-3,3,-1,AIR:0)
Block(-3,3,0,AIR:0)
Block(-3,3,1,AIR:0)
Block(-3,3,2,AIR:0)
Block(-3,3,3,AIR:0)
Block(-3,3,4,AIR:0)
Block(-3,4,-5,AIR:0)
Block(-3,4,-4,AIR:0)
Block(-3,4,-3,AIR:0)
Block(-3,4,-2,AIR:0)
Block(-3,4,-1,AIR:0)
Block(-3,4,0,AIR:0)
Block(-3,4,1,AIR:0)
Block(-3,4,2,AIR:0)
Block(-3,4,3,AIR:0)
Block(-3,4,4,AIR:0)
Block(-3,5,-5,AIR:0)
Block(-3,5,-4,AIR:0)
Block(-3,5,-3,AIR:0)
Block(-3,5,-2,AIR:0)
Block(-3,5,-1,LOG:5)
Block(-3,5,0,AIR:0)
Block(-3,5,1,AIR:0)
Block(-3,5,2,AIR:0)
Block(-3,5,3,AIR:0)
Block(-3,5,4,AIR:0)
Block(-3,6,-2,AIR:0)
Block(-3,6,0,AIR:0)
Block(-3,6,1,AIR:0)
Block(-3,6,2,AIR:0)
Block(-3,6,3,AIR:0)
Block(-3,15,-4,STONE:0)
Block(-3,15,-2,STONE:0)
Block(-3,16,-5,LOG:5)
Block(-3,16,-4,STONE:0)
Block(-3,16,-3,STONE:0)
Block(-3,16,-2,STONE:0)
Block(-3,16,-1,LOG:5)
Block(-3,17,-5,LOG:1)
Block(-3,17,-4,RAILS:3)
Block(-3,17,-3,COBBLESTONE_STAIRS:1)
Block(-3,17,-2,RAILS:3)
Block(-3,17,-1,LOG:1)
Block(-3,18,-5,LOG:1)
Block(-3,18,-4,AIR:0)
Block(-3,18,-3,AIR:0)
Block(-3,18,-2,AIR:0)
Block(-3,18,-1,LOG:1)
Block(-3,19,-5,LOG:1)
Block(-3,19,-4,AIR:0)
Block(-3,19,-3,AIR:0)
Block(-3,19,-2,AIR:0)
Block(-3,19,-1,LOG:1)
Block(-3,20,-5,LOG:1)
Block(-3,20,-4,AIR:0)
Block(-3,20,-3,AIR:0)
Block(-3,20,-2,AIR:0)
Block(-3,20,-1,LOG:1)
Block(-3,21,-4,LOG:9)
Block(-3,21,-3,LOG:9)
Block(-3,21,-2,LOG:9)
Block(-3,22,-11,GRASS:0)
Block(-3,22,-10,STONE:0)
Block(-3,22,-9,STONE:0)
Block(-3,22,-8,STONE:0)
Block(-3,22,-7,STONE:0)
Block(-3,22,-6,STONE:0)
Block(-3,22,-5,STONE:0)
Block(-3,22,-4,STONE:0)
Block(-3,22,-3,STONE:0)
Block(-3,22,-2,STONE:0)
Block(-3,22,-1,STONE:0)
Block(-3,22,0,STONE:0)
Block(-3,22,1,STONE:0)
Block(-3,22,2,STONE:0)
Block(-3,22,3,STONE:0)
Block(-3,22,4,STONE:0)
Block(-3,22,5,STONE:0)
Block(-3,22,6,STONE:0)
Block(-3,22,7,STONE:0)
Block(-3,22,8,STONE:0)
Block(-3,22,9,STONE:0)
Block(-3,22,10,STONE:0)
Block(-3,22,11,STONE:0)
Block(-3,22,12,GRASS:0)
Block(-3,23,-10,STONE:0)
Block(-3,23,-9,STONE:0)
Block(-3,23,-8,STONE:0)
Block(-3,23,-7,STONE:0)
Block(-3,23,-6,STONE:0)
Block(-3,23,-5,STONE:0)
Block(-3,23,-4,STONE:0)
Block(-3,23,-3,STONE:0)
Block(-3,23,-2,STONE:0)
Block(-3,23,-1,STONE:0)
Block(-3,23,0,STONE:0)
Block(-3,23,1,STONE:0)
Block(-3,23,2,STONE:0)
Block(-3,23,3,STONE:0)
Block(-3,23,4,STONE:0)
Block(-3,23,5,STONE:0)
Block(-3,23,6,STONE:0)
Block(-3,23,7,STONE:0)
Block(-3,23,8,STONE:0)
Block(-3,23,9,STONE:0)
Block(-3,23,10,STONE:0)
Block(-3,23,11,STONE:0)
Block(-3,24,-10,STONE:0)
Block(-3,24,-9,STONE:0)
Block(-3,24,-8,STONE:0)
Block(-3,24,-7,STONE:0)
Block(-3,24,-6,STONE:0)
Block(-3,24,-5,STONE:0)
Block(-3,24,-4,STONE:0)
Block(-3,24,-3,STONE:0)
Block(-3,24,-2,STONE:0)
Block(-3,24,-1,STONE:0)
Block(-3,24,0,STONE:0)
Block(-3,24,1,STONE:0)
Block(-3,24,2,STONE:0)
Block(-3,24,3,STONE:0)
Block(-3,24,4,STONE:0)
Block(-3,24,5,STONE:0)
Block(-3,24,6,STONE:0)
Block(-3,24,7,STONE:0)
Block(-3,24,8,STONE:0)
Block(-3,24,9,STONE:0)
Block(-3,24,10,STONE:0)
Block(-3,24,11,STONE:0)
Block(-3,25,-10,STONE:0)
Block(-3,25,-9,STONE:0)
Block(-3,25,-8,STONE:0)
Block(-3,25,-7,STONE:0)
Block(-3,25,-6,STONE:0)
Block(-3,25,-5,STONE:0)
Block(-3,25,-4,STONE:0)
Block(-3,25,-3,STONE:0)
Block(-3,25,-2,STONE:0)
Block(-3,25,-1,STONE:0)
Block(-3,25,0,STONE:0)
Block(-3,25,1,STONE:0)
Block(-3,25,2,STONE:0)
Block(-3,25,3,STONE:0)
Block(-3,25,4,STONE:0)
Block(-3,25,5,STONE:0)
Block(-3,25,6,STONE:0)
Block(-3,25,7,STONE:0)
Block(-3,25,8,STONE:0)
Block(-3,25,9,STONE:0)
Block(-3,25,10,STONE:0)
Block(-3,25,11,GRASS:0)
Block(-3,26,-10,GRASS:0)
Block(-3,26,-9,STONE:0)
Block(-3,26,-8,STONE:0)
Block(-3,26,-7,STONE:0)
Block(-3,26,-6,STONE:0)
Block(-3,26,-5,STONE:0)
Block(-3,26,-4,STONE:0)
Block(-3,26,-3,STONE:0)
Block(-3,26,-2,STONE:0)
Block(-3,26,-1,STONE:0)
Block(-3,26,0,STONE:0)
Block(-3,26,1,STONE:0)
Block(-3,26,2,STONE:0)
Block(-3,26,3,STONE:0)
Block(-3,26,4,STONE:0)
Block(-3,26,5,STONE:0)
Block(-3,26,6,STONE:0)
Block(-3,26,7,STONE:0)
Block(-3,26,8,STONE:0)
Block(-3,26,9,STONE:0)
Block(-3,26,10,STONE:0)
Block(-3,27,-9,GRASS:0)
Block(-3,27,-8,STONE:0)
Block(-3,27,-7,STONE:0)
Block(-3,27,-6,STONE:0)
Block(-3,27,-5,STONE:0)
Block(-3,27,-4,STONE:0)
Block(-3,27,-3,STONE:0)
Block(-3,27,-2,STONE:0)
Block(-3,27,-1,STONE:0)
Block(-3,27,0,RAILS:2)
Block(-3,27,1,COBBLESTONE_STAIRS:0)
Block(-3,27,2,RAILS:2)
Block(-3,27,3,STONE:0)
Block(-3,27,4,STONE:0)
Block(-3,27,5,STONE:0)
Block(-3,27,6,STONE:0)
Block(-3,27,7,STONE:0)
Block(-3,27,8,STONE:0)
Block(-3,27,9,STONE:0)
Block(-3,27,10,STONE:0)
Block(-3,28,-8,GRASS:0)
Block(-3,28,-7,STONE:0)
Block(-3,28,-6,STONE:0)
Block(-3,28,-5,STONE:0)
Block(-3,28,-4,STONE:0)
Block(-3,28,-3,STONE:0)
Block(-3,28,-2,STONE:0)
Block(-3,28,-1,STONE:0)
Block(-3,28,3,STONE:0)
Block(-3,28,4,STONE:0)
Block(-3,28,5,STONE:0)
Block(-3,28,6,STONE:0)
Block(-3,28,7,STONE:0)
Block(-3,28,8,STONE:0)
Block(-3,28,9,STONE:0)
Block(-3,28,10,GRASS:0)
Block(-3,29,-7,GRASS:0)
Block(-3,29,-6,GRASS:0)
Block(-3,29,-5,STONE:0)
Block(-3,29,-4,STONE:0)
Block(-3,29,-3,STONE:0)
Block(-3,29,-2,STONE:0)
Block(-3,29,-1,STONE:0)
Block(-3,29,3,STONE:0)
Block(-3,29,4,STONE:0)
Block(-3,29,5,STONE:0)
Block(-3,29,6,STONE:0)
Block(-3,29,7,STONE:0)
Block(-3,29,8,GRASS:0)
Block(-3,29,9,GRASS:0)
Block(-3,30,-5,STONE:0)
Block(-3,30,-4,STONE:0)
Block(-3,30,-3,STONE:0)
Block(-3,30,-2,STONE:0)
Block(-3,30,-1,STONE:0)
Block(-3,30,0,STONE:0)
Block(-3,30,1,STONE:0)
Block(-3,30,2,STONE:0)
Block(-3,30,3,STONE:0)
Block(-3,30,4,STONE:0)
Block(-3,30,5,STONE:0)
Block(-3,30,6,STONE:0)
Block(-3,30,7,GRASS:0)
Block(-3,31,-5,GRASS:0)
Block(-3,31,-4,STONE:0)
Block(-3,31,-3,STONE:0)
Block(-3,31,-2,STONE:0)
Block(-3,31,-1,STONE:0)
Block(-3,31,0,STONE:0)
Block(-3,31,1,STONE:0)
Block(-3,31,2,STONE:0)
Block(-3,31,3,STONE:0)
Block(-3,31,4,STONE:0)
Block(-3,31,5,STONE:0)
Block(-3,31,6,STONE:0)
Block(-3,32,-4,GRASS:0)
Block(-3,32,-2,GRASS:0)
Block(-3,32,1,GRASS:0)
Block(-3,32,2,GRASS:0)
Block(-3,32,3,DIRT:0)
Block(-3,32,4,GRASS:0)
Block(-3,32,5,GRASS:0)
Block(-3,32,6,GRASS:0)
Block(-3,33,3,GRASS:0)
Block(-2,3,-6,AIR:0)
Block(-2,3,-5,AIR:0)
Block(-2,3,-4,AIR:0)
Block(-2,3,-3,AIR:0)
Block(-2,3,-2,AIR:0)
Block(-2,3,-1,AIR:0)
Block(-2,3,0,AIR:0)
Block(-2,3,1,AIR:0)
Block(-2,3,2,AIR:0)
Block(-2,3,3,AIR:0)
Block(-2,3,4,AIR:0)
Block(-2,4,-6,AIR:0)
Block(-2,4,-5,AIR:0)
Block(-2,4,-4,AIR:0)
Block(-2,4,-3,AIR:0)
Block(-2,4,-2,AIR:0)
Block(-2,4,-1,AIR:0)
Block(-2,4,0,AIR:0)
Block(-2,4,1,AIR:0)
Block(-2,4,2,AIR:0)
Block(-2,4,3,AIR:0)
Block(-2,4,4,AIR:0)
Block(-2,5,-6,AIR:0)
Block(-2,5,-5,AIR:0)
Block(-2,5,-4,AIR:0)
Block(-2,5,-3,AIR:0)
Block(-2,5,-2,AIR:0)
Block(-2,5,-1,LOG:5)
Block(-2,5,0,AIR:0)
Block(-2,5,1,AIR:0)
Block(-2,5,2,AIR:0)
Block(-2,5,3,AIR:0)
Block(-2,5,4,AIR:0)
Block(-2,6,-7,AIR:0)
Block(-2,6,-6,AIR:0)
Block(-2,6,-5,AIR:0)
Block(-2,6,-2,AIR:0)
Block(-2,6,0,AIR:0)
Block(-2,6,1,AIR:0)
Block(-2,6,2,AIR:0)
Block(-2,14,-4,STONE:0)
Block(-2,14,-2,STONE:0)
Block(-2,15,-4,STONE:0)
Block(-2,15,-3,STONE:0)
Block(-2,15,-2,STONE:0)
Block(-2,16,-5,LOG:5)
Block(-2,16,-4,RAILS:3)
Block(-2,16,-3,COBBLESTONE_STAIRS:1)
Block(-2,16,-2,RAILS:3)
Block(-2,16,-1,LOG:5)
Block(-2,17,-5,FENCE:0)
Block(-2,17,-4,AIR:0)
Block(-2,17,-3,AIR:0)
Block(-2,17,-2,AIR:0)
Block(-2,17,-1,FENCE:0)
Block(-2,18,-5,FENCE:0)
Block(-2,18,-4,AIR:0)
Block(-2,18,-3,AIR:0)
Block(-2,18,-2,AIR:0)
Block(-2,18,-1,FENCE:0)
Block(-2,19,-4,AIR:0)
Block(-2,19,-3,AIR:0)
Block(-2,19,-2,AIR:0)
Block(-2,22,-11,GRASS:0)
Block(-2,22,-10,STONE:0)
Block(-2,22,-9,STONE:0)
Block(-2,22,-8,STONE:0)
Block(-2,22,-7,STONE:0)
Block(-2,22,-6,STONE:0)
Block(-2,22,-5,STONE:0)
Block(-2,22,-4,STONE:0)
Block(-2,22,-3,STONE:0)
Block(-2,22,-2,STONE:0)
Block(-2,22,-1,STONE:0)
Block(-2,22,0,STONE:0)
Block(-2,22,1,STONE:0)
Block(-2,22,2,STONE:0)
Block(-2,22,3,STONE:0)
Block(-2,22,4,STONE:0)
Block(-2,22,5,STONE:0)
Block(-2,22,6,STONE:0)
Block(-2,22,7,STONE:0)
Block(-2,22,8,STONE:0)
Block(-2,22,9,STONE:0)
Block(-2,22,10,STONE:0)
Block(-2,22,11,STONE:0)
Block(-2,22,12,GRASS:0)
Block(-2,23,-10,STONE:0)
Block(-2,23,-9,STONE:0)
Block(-2,23,-8,STONE:0)
Block(-2,23,-7,STONE:0)
Block(-2,23,-6,STONE:0)
Block(-2,23,-5,STONE:0)
Block(-2,23,-4,STONE:0)
Block(-2,23,-3,STONE:0)
Block(-2,23,-2,STONE:0)
Block(-2,23,-1,STONE:0)
Block(-2,23,0,STONE:0)
Block(-2,23,1,STONE:0)
Block(-2,23,2,STONE:0)
Block(-2,23,3,STONE:0)
Block(-2,23,4,STONE:0)
Block(-2,23,5,STONE:0)
Block(-2,23,6,STONE:0)
Block(-2,23,7,STONE:0)
Block(-2,23,8,STONE:0)
Block(-2,23,9,STONE:0)
Block(-2,23,10,STONE:0)
Block(-2,23,11,STONE:0)
Block(-2,24,-10,GRASS:0)
Block(-2,24,-9,STONE:0)
Block(-2,24,-8,STONE:0)
Block(-2,24,-7,STONE:0)
Block(-2,24,-6,STONE:0)
Block(-2,24,-5,STONE:0)
Block(-2,24,-4,STONE:0)
Block(-2,24,-3,STONE:0)
Block(-2,24,-2,STONE:0)
Block(-2,24,-1,STONE:0)
Block(-2,24,0,STONE:0)
Block(-2,24,1,STONE:0)
Block(-2,24,2,STONE:0)
Block(-2,24,3,STONE:0)
Block(-2,24,4,STONE:0)
Block(-2,24,5,STONE:0)
Block(-2,24,6,STONE:0)
Block(-2,24,7,STONE:0)
Block(-2,24,8,STONE:0)
Block(-2,24,9,STONE:0)
Block(-2,24,10,STONE:0)
Block(-2,24,11,GRASS:0)
Block(-2,25,-9,GRASS:0)
Block(-2,25,-8,STONE:0)
Block(-2,25,-7,STONE:0)
Block(-2,25,-6,STONE:0)
Block(-2,25,-5,STONE:0)
Block(-2,25,-4,STONE:0)
Block(-2,25,-3,STONE:0)
Block(-2,25,-2,STONE:0)
Block(-2,25,-1,STONE:0)
Block(-2,25,0,STONE:0)
Block(-2,25,1,STONE:0)
Block(-2,25,2,STONE:0)
Block(-2,25,3,STONE:0)
Block(-2,25,4,STONE:0)
Block(-2,25,5,STONE:0)
Block(-2,25,6,STONE:0)
Block(-2,25,7,STONE:0)
Block(-2,25,8,STONE:0)
Block(-2,25,9,STONE:0)
Block(-2,25,10,STONE:0)
Block(-2,26,-8,STONE:0)
Block(-2,26,-7,STONE:0)
Block(-2,26,-6,STONE:0)
Block(-2,26,-5,STONE:0)
Block(-2,26,-4,STONE:0)
Block(-2,26,-3,STONE:0)
Block(-2,26,-2,STONE:0)
Block(-2,26,-1,STONE:0)
Block(-2,26,0,STONE:0)
Block(-2,26,1,STONE:0)
Block(-2,26,2,STONE:0)
Block(-2,26,3,STONE:0)
Block(-2,26,4,STONE:0)
Block(-2,26,5,STONE:0)
Block(-2,26,6,STONE:0)
Block(-2,26,7,STONE:0)
Block(-2,26,8,STONE:0)
Block(-2,26,9,STONE:0)
Block(-2,26,10,STONE:0)
Block(-2,27,-8,STONE:0)
Block(-2,27,-7,STONE:0)
Block(-2,27,-6,STONE:0)
Block(-2,27,-5,STONE:0)
Block(-2,27,-4,STONE:0)
Block(-2,27,-3,STONE:0)
Block(-2,27,-2,STONE:0)
Block(-2,27,-1,STONE:0)
Block(-2,27,0,STONE:0)
Block(-2,27,1,STONE:0)
Block(-2,27,2,STONE:0)
Block(-2,27,3,STONE:0)
Block(-2,27,4,STONE:0)
Block(-2,27,5,STONE:0)
Block(-2,27,6,STONE:0)
Block(-2,27,7,STONE:0)
Block(-2,27,8,STONE:0)
Block(-2,27,9,STONE:0)
Block(-2,27,10,STONE:0)
Block(-2,28,-8,GRASS:0)
Block(-2,28,-7,STONE:0)
Block(-2,28,-6,STONE:0)
Block(-2,28,-5,STONE:0)
Block(-2,28,-4,STONE:0)
Block(-2,28,-3,STONE:0)
Block(-2,28,-2,STONE:0)
Block(-2,28,-1,MONSTER_EGGS:1)
Block(-2,28,0,RAILS:1)
Block(-2,28,2,RAILS:1)
Block(-2,28,3,MONSTER_EGGS:1)
Block(-2,28,4,STONE:0)
Block(-2,28,5,STONE:0)
Block(-2,28,6,STONE:0)
Block(-2,28,7,STONE:0)
Block(-2,28,8,STONE:0)
Block(-2,28,9,STONE:0)
Block(-2,28,10,GRASS:0)
Block(-2,29,-7,GRASS:0)
Block(-2,29,-6,STONE:0)
Block(-2,29,-5,STONE:0)
Block(-2,29,-4,STONE:0)
Block(-2,29,-3,STONE:0)
Block(-2,29,-2,STONE:0)
Block(-2,29,-1,MONSTER_EGGS:1)
Block(-2,29,3,MONSTER_EGGS:1)
Block(-2,29,4,STONE:0)
Block(-2,29,5,STONE:0)
Block(-2,29,6,STONE:0)
Block(-2,29,7,STONE:0)
Block(-2,29,8,STONE:0)
Block(-2,29,9,STONE:0)
Block(-2,30,-6,GRASS:0)
Block(-2,30,-5,STONE:0)
Block(-2,30,-4,STONE:0)
Block(-2,30,-3,STONE:0)
Block(-2,30,-2,STONE:0)
Block(-2,30,-1,MONSTER_EGGS:1)
Block(-2,30,0,MONSTER_EGGS:1)
Block(-2,30,1,MONSTER_EGGS:1)
Block(-2,30,2,MONSTER_EGGS:1)
Block(-2,30,3,MONSTER_EGGS:1)
Block(-2,30,4,STONE:0)
Block(-2,30,5,STONE:0)
Block(-2,30,6,STONE:0)
Block(-2,30,7,STONE:0)
Block(-2,30,8,STONE:0)
Block(-2,30,9,GRASS:0)
Block(-2,31,-5,GRASS:0)
Block(-2,31,-4,STONE:0)
Block(-2,31,-3,GRASS:0)
Block(-2,31,-2,STONE:0)
Block(-2,31,0,STONE:0)
Block(-2,31,1,STONE:0)
Block(-2,31,2,STONE:0)
Block(-2,31,3,STONE:0)
Block(-2,31,4,STONE:0)
Block(-2,31,5,STONE:0)
Block(-2,31,6,STONE:0)
Block(-2,31,7,STONE:0)
Block(-2,31,8,GRASS:0)
Block(-2,32,-2,GRASS:0)
Block(-2,32,1,GRASS:0)
Block(-2,32,2,GRASS:0)
Block(-2,32,3,GRASS:0)
Block(-2,32,4,GRASS:0)
Block(-2,32,5,GRASS:0)
Block(-2,32,6,GRASS:0)
Block(-2,32,7,GRASS:0)
Block(-1,0,-5,LOG:1)
Block(-1,0,-1,LOG:1)
Block(-1,0,2,LOG:1)
Block(-1,1,-5,LOG:1)
Block(-1,1,-1,LOG:1)
Block(-1,1,2,LOG:1)
Block(-1,2,-5,LOG:1)
Block(-1,2,-1,LOG:1)
Block(-1,2,2,LOG:1)
Block(-1,3,-6,AIR:0)
Block(-1,3,-5,LOG:1)
Block(-1,3,-4,AIR:0)
Block(-1,3,-3,AIR:0)
Block(-1,3,-2,AIR:0)
Block(-1,3,-1,LOG:1)
Block(-1,3,0,AIR:0)
Block(-1,3,1,AIR:0)
Block(-1,3,2,LOG:1)
Block(-1,3,3,AIR:0)
Block(-1,3,4,AIR:0)
Block(-1,4,-6,AIR:0)
Block(-1,4,-5,LOG:1)
Block(-1,4,-4,AIR:0)
Block(-1,4,-3,AIR:0)
Block(-1,4,-2,TORCH:4)
Block(-1,4,-1,LOG:1)
Block(-1,4,0,AIR:0)
Block(-1,4,1,AIR:0)
Block(-1,4,2,LOG:1)
Block(-1,4,3,AIR:0)
Block(-1,4,4,AIR:0)
Block(-1,5,-7,AIR:0)
Block(-1,5,-6,AIR:0)
Block(-1,5,-5,LOG:1)
Block(-1,5,-4,AIR:0)
Block(-1,5,-3,AIR:0)
Block(-1,5,-2,AIR:0)
Block(-1,5,-1,LOG:1)
Block(-1,5,0,AIR:0)
Block(-1,5,1,AIR:0)
Block(-1,5,2,LOG:1)
Block(-1,5,3,AIR:0)
Block(-1,5,4,AIR:0)
Block(-1,6,-7,AIR:0)
Block(-1,6,-6,AIR:0)
Block(-1,6,-5,LOG:1)
Block(-1,6,-4,LOG:9)
Block(-1,6,-3,LOG:9)
Block(-1,6,-2,LOG:9)
Block(-1,6,-1,LOG:1)
Block(-1,6,0,LOG:9)
Block(-1,6,1,LOG:9)
Block(-1,6,2,LOG:9)
Block(-1,6,3,AIR:0)
Block(-1,7,-5,LOG:1)
Block(-1,7,-4,AIR:0)
Block(-1,7,-1,LOG:1)
Block(-1,8,-5,LOG:1)
Block(-1,8,-1,LOG:1)
Block(-1,9,-5,LOG:1)
Block(-1,9,-1,LOG:1)
Block(-1,10,-5,LOG:1)
Block(-1,10,-1,LOG:1)
Block(-1,11,-5,LOG:1)
Block(-1,11,-1,LOG:1)
Block(-1,12,-5,LOG:1)
Block(-1,12,-1,LOG:1)
Block(-1,13,-5,LOG:1)
Block(-1,13,-4,STONE:0)
Block(-1,13,-2,STONE:0)
Block(-1,13,-1,LOG:1)
Block(-1,14,-5,LOG:1)
Block(-1,14,-4,STONE:0)
Block(-1,14,-3,STONE:0)
Block(-1,14,-2,STONE:0)
Block(-1,14,-1,LOG:1)
Block(-1,15,-5,LOG:1)
Block(-1,15,-4,RAILS:3)
Block(-1,15,-3,COBBLESTONE_STAIRS:1)
Block(-1,15,-2,RAILS:3)
Block(-1,15,-1,LOG:1)
Block(-1,16,-5,LOG:5)
Block(-1,16,-4,AIR:0)
Block(-1,16,-3,AIR:0)
Block(-1,16,-2,AIR:0)
Block(-1,16,-1,LOG:5)
Block(-1,17,-5,FENCE:0)
Block(-1,17,-4,AIR:0)
Block(-1,17,-3,AIR:0)
Block(-1,17,-2,AIR:0)
Block(-1,17,-1,FENCE:0)
Block(-1,18,-5,FENCE:0)
Block(-1,18,-4,AIR:0)
Block(-1,18,-3,AIR:0)
Block(-1,18,-2,AIR:0)
Block(-1,18,-1,FENCE:0)
Block(-1,22,-11,GRASS:0)
Block(-1,22,-10,STONE:0)
Block(-1,22,-9,STONE:0)
Block(-1,22,-8,STONE:0)
Block(-1,22,-7,STONE:0)
Block(-1,22,-6,STONE:0)
Block(-1,22,-5,STONE:0)
Block(-1,22,-4,STONE:0)
Block(-1,22,-3,STONE:0)
Block(-1,22,-2,STONE:0)
Block(-1,22,-1,STONE:0)
Block(-1,22,0,STONE:0)
Block(-1,22,1,STONE:0)
Block(-1,22,2,STONE:0)
Block(-1,22,3,STONE:0)
Block(-1,22,4,STONE:0)
Block(-1,22,5,STONE:0)
Block(-1,22,6,STONE:0)
Block(-1,22,7,STONE:0)
Block(-1,22,8,STONE:0)
Block(-1,22,9,STONE:0)
Block(-1,22,10,STONE:0)
Block(-1,22,11,GRASS:0)
Block(-1,22,12,GRASS:0)
Block(-1,23,-10,GRASS:0)
Block(-1,23,-9,STONE:0)
Block(-1,23,-8,STONE:0)
Block(-1,23,-7,STONE:0)
Block(-1,23,-6,STONE:0)
Block(-1,23,-5,STONE:0)
Block(-1,23,-4,STONE:0)
Block(-1,23,-3,STONE:0)
Block(-1,23,-2,STONE:0)
Block(-1,23,-1,STONE:0)
Block(-1,23,0,STONE:0)
Block(-1,23,1,STONE:0)
Block(-1,23,2,STONE:0)
Block(-1,23,3,STONE:0)
Block(-1,23,4,STONE:0)
Block(-1,23,5,STONE:0)
Block(-1,23,6,STONE:0)
Block(-1,23,7,STONE:0)
Block(-1,23,8,STONE:0)
Block(-1,23,9,STONE:0)
Block(-1,23,10,STONE:0)
Block(-1,24,-9,STONE:0)
Block(-1,24,-8,STONE:0)
Block(-1,24,-7,STONE:0)
Block(-1,24,-6,STONE:0)
Block(-1,24,-5,STONE:0)
Block(-1,24,-4,STONE:0)
Block(-1,24,-3,STONE:0)
Block(-1,24,-2,STONE:0)
Block(-1,24,-1,STONE:0)
Block(-1,24,0,STONE:0)
Block(-1,24,1,STONE:0)
Block(-1,24,2,STONE:0)
Block(-1,24,3,STONE:0)
Block(-1,24,4,STONE:0)
Block(-1,24,5,STONE:0)
Block(-1,24,6,STONE:0)
Block(-1,24,7,STONE:0)
Block(-1,24,8,STONE:0)
Block(-1,24,9,STONE:0)
Block(-1,24,10,STONE:0)
Block(-1,25,-9,STONE:0)
Block(-1,25,-8,STONE:0)
Block(-1,25,-7,STONE:0)
Block(-1,25,-6,STONE:0)
Block(-1,25,-5,STONE:0)
Block(-1,25,-4,STONE:0)
Block(-1,25,-3,STONE:0)
Block(-1,25,-2,STONE:0)
Block(-1,25,-1,STONE:0)
Block(-1,25,0,STONE:0)
Block(-1,25,1,STONE:0)
Block(-1,25,2,STONE:0)
Block(-1,25,3,STONE:0)
Block(-1,25,4,STONE:0)
Block(-1,25,5,STONE:0)
Block(-1,25,6,STONE:0)
Block(-1,25,7,STONE:0)
Block(-1,25,8,STONE:0)
Block(-1,25,9,STONE:0)
Block(-1,25,10,STONE:0)
Block(-1,26,-9,GRASS:0)
Block(-1,26,-8,STONE:0)
Block(-1,26,-7,STONE:0)
Block(-1,26,-6,STONE:0)
Block(-1,26,-5,STONE:0)
Block(-1,26,-4,STONE:0)
Block(-1,26,-3,STONE:0)
Block(-1,26,-2,STONE:0)
Block(-1,26,-1,STONE:0)
Block(-1,26,0,STONE:0)
Block(-1,26,1,STONE:0)
Block(-1,26,2,STONE:0)
Block(-1,26,3,STONE:0)
Block(-1,26,4,STONE:0)
Block(-1,26,5,STONE:0)
Block(-1,26,6,STONE:0)
Block(-1,26,7,STONE:0)
Block(-1,26,8,STONE:0)
Block(-1,26,9,STONE:0)
Block(-1,26,10,GRASS:0)
Block(-1,27,-8,STONE:0)
Block(-1,27,-7,STONE:0)
Block(-1,27,-6,STONE:0)
Block(-1,27,-5,STONE:0)
Block(-1,27,-4,STONE:0)
Block(-1,27,-3,STONE:0)
Block(-1,27,-2,STONE:0)
Block(-1,27,-1,STONE:0)
Block(-1,27,0,STONE:0)
Block(-1,27,1,STONE:0)
Block(-1,27,2,STONE:0)
Block(-1,27,3,STONE:0)
Block(-1,27,4,STONE:0)
Block(-1,27,5,STONE:0)
Block(-1,27,6,STONE:0)
Block(-1,27,7,STONE:0)
Block(-1,27,8,STONE:0)
Block(-1,27,9,STONE:0)
Block(-1,28,-8,GRASS:0)
Block(-1,28,-7,GRASS:0)
Block(-1,28,-6,STONE:0)
Block(-1,28,-5,STONE:0)
Block(-1,28,-4,STONE:0)
Block(-1,28,-3,STONE:0)
Block(-1,28,-2,STONE:0)
Block(-1,28,-1,COBBLE_WALL:0)
Block(-1,28,0,RAILS:1)
Block(-1,28,2,RAILS:1)
Block(-1,28,3,COBBLE_WALL:0)
Block(-1,28,4,STONE:0)
Block(-1,28,5,STONE:0)
Block(-1,28,6,STONE:0)
Block(-1,28,7,STONE:0)
Block(-1,28,8,STONE:0)
Block(-1,28,9,STONE:0)
Block(-1,29,-6,GRASS:0)
Block(-1,29,-5,STONE:0)
Block(-1,29,-4,STONE:0)
Block(-1,29,-3,STONE:0)
Block(-1,29,-2,STONE:0)
Block(-1,29,-1,COBBLE_WALL:0)
Block(-1,29,3,COBBLE_WALL:0)
Block(-1,29,4,STONE:0)
Block(-1,29,5,STONE:0)
Block(-1,29,6,STONE:0)
Block(-1,29,7,STONE:0)
Block(-1,29,8,STONE:0)
Block(-1,29,9,STONE:0)
Block(-1,30,-5,GRASS:0)
Block(-1,30,-4,STONE:0)
Block(-1,30,-3,STONE:0)
Block(-1,30,-2,STONE:0)
Block(-1,30,-1,LOG:9)
Block(-1,30,0,LOG:9)
Block(-1,30,1,LOG:9)
Block(-1,30,2,LOG:9)
Block(-1,30,3,LOG:9)
Block(-1,30,4,STONE:0)
Block(-1,30,5,STONE:0)
Block(-1,30,6,STONE:0)
Block(-1,30,7,STONE:0)
Block(-1,30,8,STONE:0)
Block(-1,30,9,STONE:0)
Block(-1,31,-4,GRASS:0)
Block(-1,31,-3,GRASS:0)
Block(-1,31,-2,STONE:0)
Block(-1,31,1,STONE:0)
Block(-1,31,2,STONE:0)
Block(-1,31,3,STONE:0)
Block(-1,31,4,GRASS:0)
Block(-1,31,5,STONE:0)
Block(-1,31,6,GRASS:0)
Block(-1,31,7,STONE:0)
Block(-1,31,8,STONE:0)
Block(-1,31,9,GRASS:0)
Block(-1,32,5,GRASS:0)
Block(-1,32,7,GRASS:0)
Block(-1,32,8,GRASS:0)
Block(0,3,-6,AIR:0)
Block(0,3,-5,AIR:0)
Block(0,3,-4,AIR:0)
Block(0,3,-3,AIR:0)
Block(0,3,-2,AIR:0)
Block(0,3,-1,AIR:0)
Block(0,3,0,AIR:0)
Block(0,3,1,AIR:0)
Block(0,3,2,AIR:0)
Block(0,3,3,AIR:0)
Block(0,3,4,AIR:0)
Block(0,4,-6,AIR:0)
Block(0,4,-5,AIR:0)
Block(0,4,-4,AIR:0)
Block(0,4,-3,AIR:0)
Block(0,4,-2,AIR:0)
Block(0,4,-1,AIR:0)
Block(0,4,0,AIR:0)
Block(0,4,1,AIR:0)
Block(0,4,2,AIR:0)
Block(0,4,3,AIR:0)
Block(0,4,4,AIR:0)
Block(0,5,-7,AIR:0)
Block(0,5,-6,AIR:0)
Block(0,5,-5,AIR:0)
Block(0,5,-4,AIR:0)
Block(0,5,-3,AIR:0)
Block(0,5,-2,AIR:0)
Block(0,5,-1,AIR:0)
Block(0,5,0,AIR:0)
Block(0,5,1,AIR:0)
Block(0,5,2,AIR:0)
Block(0,5,3,AIR:0)
Block(0,5,4,AIR:0)
Block(0,6,-6,AIR:0)
Block(0,6,-5,AIR:0)
Block(0,6,-4,AIR:0)
Block(0,6,-3,AIR:0)
Block(0,6,-1,LOG:5)
Block(0,6,1,AIR:0)
Block(0,6,2,AIR:0)
Block(0,11,-5,LOG:5)
Block(0,11,-1,LOG:5)
Block(0,12,-4,STONE:0)
Block(0,12,-2,STONE:0)
Block(0,13,-4,STONE:0)
Block(0,13,-3,STONE:0)
Block(0,13,-2,STONE:0)
Block(0,14,-4,RAILS:3)
Block(0,14,-3,COBBLESTONE_STAIRS:1)
Block(0,14,-2,RAILS:3)
Block(0,15,-5,FENCE:0)
Block(0,15,-4,AIR:0)
Block(0,15,-3,AIR:0)
Block(0,15,-2,AIR:0)
Block(0,15,-1,FENCE:0)
Block(0,16,-5,LOG:5)
Block(0,16,-4,AIR:0)
Block(0,16,-3,AIR:0)
Block(0,16,-2,AIR:0)
Block(0,16,-1,LOG:5)
Block(0,17,-5,FENCE:0)
Block(0,17,-4,AIR:0)
Block(0,17,-3,AIR:0)
Block(0,17,-2,AIR:0)
Block(0,17,-1,FENCE:0)
Block(0,22,-11,GRASS:0)
Block(0,22,-10,GRASS:0)
Block(0,22,-9,STONE:0)
Block(0,22,-8,STONE:0)
Block(0,22,-7,STONE:0)
Block(0,22,-6,STONE:0)
Block(0,22,-5,STONE:0)
Block(0,22,-4,STONE:0)
Block(0,22,-3,STONE:0)
Block(0,22,-2,STONE:0)
Block(0,22,-1,STONE:0)
Block(0,22,0,STONE:0)
Block(0,22,1,STONE:0)
Block(0,22,2,STONE:0)
Block(0,22,3,STONE:0)
Block(0,22,4,STONE:0)
Block(0,22,5,STONE:0)
Block(0,22,6,STONE:0)
Block(0,22,7,STONE:0)
Block(0,22,8,STONE:0)
Block(0,22,9,STONE:0)
Block(0,22,10,GRASS:0)
Block(0,22,11,GRASS:0)
Block(0,22,12,GRASS:0)
Block(0,23,-9,STONE:0)
Block(0,23,-8,STONE:0)
Block(0,23,-7,STONE:0)
Block(0,23,-6,STONE:0)
Block(0,23,-5,STONE:0)
Block(0,23,-4,STONE:0)
Block(0,23,-3,STONE:0)
Block(0,23,-2,STONE:0)
Block(0,23,-1,STONE:0)
Block(0,23,0,STONE:0)
Block(0,23,1,STONE:0)
Block(0,23,2,STONE:0)
Block(0,23,3,STONE:0)
Block(0,23,4,STONE:0)
Block(0,23,5,STONE:0)
Block(0,23,6,STONE:0)
Block(0,23,7,STONE:0)
Block(0,23,8,STONE:0)
Block(0,23,9,STONE:0)
Block(0,24,-9,GRASS:0)
Block(0,24,-8,STONE:0)
Block(0,24,-7,STONE:0)
Block(0,24,-6,STONE:0)
Block(0,24,-5,STONE:0)
Block(0,24,-4,STONE:0)
Block(0,24,-3,STONE:0)
Block(0,24,-2,STONE:0)
Block(0,24,-1,STONE:0)
Block(0,24,0,STONE:0)
Block(0,24,1,STONE:0)
Block(0,24,2,STONE:0)
Block(0,24,3,STONE:0)
Block(0,24,4,STONE:0)
Block(0,24,5,STONE:0)
Block(0,24,6,STONE:0)
Block(0,24,7,STONE:0)
Block(0,24,8,STONE:0)
Block(0,24,9,STONE:0)
Block(0,25,-8,GRASS:0)
Block(0,25,-7,STONE:0)
Block(0,25,-6,STONE:0)
Block(0,25,-5,STONE:0)
Block(0,25,-4,STONE:0)
Block(0,25,-3,STONE:0)
Block(0,25,-2,STONE:0)
Block(0,25,-1,STONE:0)
Block(0,25,0,STONE:0)
Block(0,25,1,STONE:0)
Block(0,25,2,STONE:0)
Block(0,25,3,STONE:0)
Block(0,25,4,STONE:0)
Block(0,25,5,STONE:0)
Block(0,25,6,STONE:0)
Block(0,25,7,STONE:0)
Block(0,25,8,STONE:0)
Block(0,25,9,GRASS:0)
Block(0,26,-7,STONE:0)
Block(0,26,-6,STONE:0)
Block(0,26,-5,STONE:0)
Block(0,26,-4,STONE:0)
Block(0,26,-3,STONE:0)
Block(0,26,-2,STONE:0)
Block(0,26,-1,STONE:0)
Block(0,26,0,STONE:0)
Block(0,26,1,STONE:0)
Block(0,26,2,STONE:0)
Block(0,26,3,STONE:0)
Block(0,26,4,STONE:0)
Block(0,26,5,STONE:0)
Block(0,26,6,STONE:0)
Block(0,26,7,STONE:0)
Block(0,26,8,STONE:0)
Block(0,27,-7,STONE:0)
Block(0,27,-6,STONE:0)
Block(0,27,-5,STONE:0)
Block(0,27,-4,STONE:0)
Block(0,27,-3,STONE:0)
Block(0,27,-2,STONE:0)
Block(0,27,-1,STONE:0)
Block(0,27,0,STONE:0)
Block(0,27,1,STONE:0)
Block(0,27,2,STONE:0)
Block(0,27,3,STONE:0)
Block(0,27,4,STONE:0)
Block(0,27,5,STONE:0)
Block(0,27,6,STONE:0)
Block(0,27,7,STONE:0)
Block(0,27,8,STONE:0)
Block(0,28,-7,GRASS:0)
Block(0,28,-6,STONE:0)
Block(0,28,-5,STONE:0)
Block(0,28,-4,STONE:0)
Block(0,28,-3,STONE:0)
Block(0,28,-2,STONE:0)
Block(0,28,-1,COBBLESTONE_STAIRS:1)
Block(0,28,0,RAILS:1)
Block(0,28,2,RAILS:1)
Block(0,28,3,COBBLESTONE_STAIRS:1)
Block(0,28,4,STONE:0)
Block(0,28,5,STONE:0)
Block(0,28,6,STONE:0)
Block(0,28,7,STONE:0)
Block(0,28,8,STONE:0)
Block(0,29,-6,GRASS:0)
Block(0,29,-5,GRASS:0)
Block(0,29,-4,STONE:0)
Block(0,29,-3,STONE:0)
Block(0,29,-2,STONE:0)
Block(0,29,4,STONE:0)
Block(0,29,5,STONE:0)
Block(0,29,6,STONE:0)
Block(0,29,7,STONE:0)
Block(0,29,8,STONE:0)
Block(0,30,-4,GRASS:0)
Block(0,30,-3,STONE:0)
Block(0,30,-2,STONE:0)
Block(0,30,4,STONE:0)
Block(0,30,5,STONE:0)
Block(0,30,6,STONE:0)
Block(0,30,7,STONE:0)
Block(0,30,8,GRASS:0)
Block(0,31,-3,GRASS:0)
Block(0,31,-2,STONE:0)
Block(0,31,4,GRASS:0)
Block(0,31,5,STONE:0)
Block(0,31,6,GRASS:0)
Block(0,31,7,MONSTER_EGGS:1)
Block(0,32,5,GRASS:0)
Block(0,32,7,MONSTER_EGGS:1)
Block(0,33,7,COBBLESTONE_STAIRS:0)
Block(1,3,-6,AIR:0)
Block(1,3,-5,AIR:0)
Block(1,3,-4,AIR:0)
Block(1,3,-3,AIR:0)
Block(1,3,-2,AIR:0)
Block(1,3,-1,AIR:0)
Block(1,3,0,AIR:0)
Block(1,3,1,AIR:0)
Block(1,3,2,AIR:0)
Block(1,3,3,AIR:0)
Block(1,4,-7,AIR:0)
Block(1,4,-6,AIR:0)
Block(1,4,-5,AIR:0)
Block(1,4,-4,AIR:0)
Block(1,4,-3,AIR:0)
Block(1,4,-2,AIR:0)
Block(1,4,-1,AIR:0)
Block(1,4,0,AIR:0)
Block(1,4,1,AIR:0)
Block(1,4,2,AIR:0)
Block(1,4,3,AIR:0)
Block(1,4,4,AIR:0)
Block(1,5,-7,AIR:0)
Block(1,5,-6,AIR:0)
Block(1,5,-5,AIR:0)
Block(1,5,-4,AIR:0)
Block(1,5,-3,AIR:0)
Block(1,5,-2,AIR:0)
Block(1,5,-1,AIR:0)
Block(1,5,0,AIR:0)
Block(1,5,1,AIR:0)
Block(1,5,2,AIR:0)
Block(1,5,3,AIR:0)
Block(1,5,4,AIR:0)
Block(1,6,-6,AIR:0)
Block(1,6,-5,AIR:0)
Block(1,6,-4,AIR:0)
Block(1,6,-1,LOG:5)
Block(1,6,1,AIR:0)
Block(1,10,-3,STONE:0)
Block(1,11,-5,LOG:5)
Block(1,11,-4,STONE:0)
Block(1,11,-3,STONE:0)
Block(1,11,-2,STONE:0)
Block(1,11,-1,LOG:5)
Block(1,12,-4,STONE:0)
Block(1,12,-3,STONE:0)
Block(1,12,-2,STONE:0)
Block(1,13,-4,RAILS:3)
Block(1,13,-3,COBBLESTONE_STAIRS:1)
Block(1,13,-2,RAILS:3)
Block(1,14,-5,FENCE:0)
Block(1,14,-4,AIR:0)
Block(1,14,-3,AIR:0)
Block(1,14,-2,AIR:0)
Block(1,15,-5,FENCE:0)
Block(1,15,-4,AIR:0)
Block(1,15,-3,AIR:0)
Block(1,15,-2,AIR:0)
Block(1,15,-1,FENCE:0)
Block(1,16,-5,LOG:5)
Block(1,16,-4,AIR:0)
Block(1,16,-3,TORCH:2)
Block(1,16,-2,AIR:0)
Block(1,16,-1,LOG:5)
Block(1,22,-11,GRASS:0)
Block(1,22,-10,GRASS:0)
Block(1,22,-9,GRASS:0)
Block(1,22,-8,STONE:0)
Block(1,22,-7,STONE:0)
Block(1,22,-6,STONE:0)
Block(1,22,-5,STONE:0)
Block(1,22,-4,STONE:0)
Block(1,22,-3,STONE:0)
Block(1,22,-2,STONE:0)
Block(1,22,-1,STONE:0)
Block(1,22,0,STONE:0)
Block(1,22,1,STONE:0)
Block(1,22,2,STONE:0)
Block(1,22,3,STONE:0)
Block(1,22,4,STONE:0)
Block(1,22,5,STONE:0)
Block(1,22,6,STONE:0)
Block(1,22,7,STONE:0)
Block(1,22,8,STONE:0)
Block(1,22,9,STONE:0)
Block(1,22,10,STONE:0)
Block(1,22,11,GRASS:0)
Block(1,22,12,GRASS:0)
Block(1,23,-8,GRASS:0)
Block(1,23,-7,STONE:0)
Block(1,23,-6,STONE:0)
Block(1,23,-5,STONE:0)
Block(1,23,-4,STONE:0)
Block(1,23,-3,STONE:0)
Block(1,23,-2,STONE:0)
Block(1,23,-1,STONE:0)
Block(1,23,0,STONE:0)
Block(1,23,1,STONE:0)
Block(1,23,2,STONE:0)
Block(1,23,3,STONE:0)
Block(1,23,4,STONE:0)
Block(1,23,5,STONE:0)
Block(1,23,6,STONE:0)
Block(1,23,7,STONE:0)
Block(1,23,8,STONE:0)
Block(1,23,9,STONE:0)
Block(1,23,10,STONE:0)
Block(1,24,-7,GRASS:0)
Block(1,24,-6,STONE:0)
Block(1,24,-5,STONE:0)
Block(1,24,-4,STONE:0)
Block(1,24,-3,STONE:0)
Block(1,24,-2,STONE:0)
Block(1,24,-1,STONE:0)
Block(1,24,0,STONE:0)
Block(1,24,1,STONE:0)
Block(1,24,2,STONE:0)
Block(1,24,3,STONE:0)
Block(1,24,4,STONE:0)
Block(1,24,5,STONE:0)
Block(1,24,6,STONE:0)
Block(1,24,7,STONE:0)
Block(1,24,8,STONE:0)
Block(1,24,9,STONE:0)
Block(1,24,10,STONE:0)
Block(1,25,-6,STONE:0)
Block(1,25,-5,STONE:0)
Block(1,25,-4,STONE:0)
Block(1,25,-3,STONE:0)
Block(1,25,-2,STONE:0)
Block(1,25,-1,STONE:0)
Block(1,25,0,STONE:0)
Block(1,25,1,STONE:0)
Block(1,25,2,STONE:0)
Block(1,25,3,STONE:0)
Block(1,25,4,STONE:0)
Block(1,25,5,STONE:0)
Block(1,25,6,STONE:0)
Block(1,25,7,STONE:0)
Block(1,25,8,STONE:0)
Block(1,25,9,STONE:0)
Block(1,25,10,STONE:0)
Block(1,26,-6,STONE:0)
Block(1,26,-5,STONE:0)
Block(1,26,-4,STONE:0)
Block(1,26,-3,STONE:0)
Block(1,26,-2,STONE:0)
Block(1,26,-1,STONE:0)
Block(1,26,0,STONE:0)
Block(1,26,1,STONE:0)
Block(1,26,2,STONE:0)
Block(1,26,3,STONE:0)
Block(1,26,4,STONE:0)
Block(1,26,5,STONE:0)
Block(1,26,6,STONE:0)
Block(1,26,7,STONE:0)
Block(1,26,8,STONE:0)
Block(1,26,9,STONE:0)
Block(1,26,10,STONE:0)
Block(1,27,-6,GRASS:0)
Block(1,27,-5,STONE:0)
Block(1,27,-4,STONE:0)
Block(1,27,-3,STONE:0)
Block(1,27,-2,STONE:0)
Block(1,27,-1,STONE:0)
Block(1,27,0,STONE:0)
Block(1,27,1,STONE:0)
Block(1,27,2,STONE:0)
Block(1,27,3,STONE:0)
Block(1,27,4,STONE:0)
Block(1,27,5,STONE:0)
Block(1,27,6,STONE:0)
Block(1,27,7,STONE:0)
Block(1,27,8,STONE:0)
Block(1,27,9,STONE:0)
Block(1,27,10,GRASS:0)
Block(1,28,-5,GRASS:0)
Block(1,28,-4,STONE:0)
Block(1,28,-3,STONE:0)
Block(1,28,-2,STONE:0)
Block(1,28,0,RAILS:1)
Block(1,28,2,RAILS:1)
Block(1,28,4,STONE:0)
Block(1,28,5,MONSTER_EGGS:1)
Block(1,28,6,STONE:0)
Block(1,28,7,STONE:0)
Block(1,28,8,STONE:0)
Block(1,28,9,MONSTER_EGGS:1)
Block(1,29,-4,STONE:0)
Block(1,29,-2,STONE:0)
Block(1,29,5,COBBLESTONE_STAIRS:2)
Block(1,29,6,MONSTER_EGGS:1)
Block(1,29,7,MONSTER_EGGS:1)
Block(1,29,8,MONSTER_EGGS:1)
Block(1,29,9,COBBLESTONE_STAIRS:3)
Block(1,30,-4,GRASS:0)
Block(1,30,6,MONSTER_EGGS:1)
Block(1,30,7,MONSTER_EGGS:1)
Block(1,30,8,MONSTER_EGGS:1)
Block(1,31,6,MONSTER_EGGS:1)
Block(1,31,7,MONSTER_EGGS:1)
Block(1,31,8,MONSTER_EGGS:1)
Block(1,32,6,MONSTER_EGGS:1)
Block(1,32,7,MONSTER_EGGS:1)
Block(1,32,8,MONSTER_EGGS:1)
Block(1,33,6,COBBLESTONE_STAIRS:2)
Block(1,33,7,MONSTER_EGGS:1)
Block(1,33,8,COBBLESTONE_STAIRS:0)
Block(1,34,7,MONSTER_EGGS:1)
Block(1,35,7,MONSTER_EGGS:1)
Block(1,36,7,MONSTER_EGGS:1)
Block(1,37,7,MONSTER_EGGS:1)
Block(1,38,7,MONSTER_EGGS:1)
Block(1,39,7,COBBLE_WALL:0)
Block(2,3,-7,AIR:0)
Block(2,3,-6,AIR:0)
Block(2,3,-5,AIR:0)
Block(2,3,-4,AIR:0)
Block(2,3,-3,AIR:0)
Block(2,3,-2,AIR:0)
Block(2,3,-1,AIR:0)
Block(2,3,0,AIR:0)
Block(2,3,1,AIR:0)
Block(2,4,-7,AIR:0)
Block(2,4,-6,AIR:0)
Block(2,4,-5,AIR:0)
Block(2,4,-4,AIR:0)
Block(2,4,-3,AIR:0)
Block(2,4,-2,AIR:0)
Block(2,4,-1,AIR:0)
Block(2,4,0,AIR:0)
Block(2,4,1,AIR:0)
Block(2,5,-7,AIR:0)
Block(2,5,-6,AIR:0)
Block(2,5,-5,AIR:0)
Block(2,5,-4,AIR:0)
Block(2,5,-3,AIR:0)
Block(2,5,-2,AIR:0)
Block(2,5,-1,AIR:0)
Block(2,5,0,AIR:0)
Block(2,5,1,AIR:0)
Block(2,6,-5,AIR:0)
Block(2,6,-4,AIR:0)
Block(2,6,-1,LOG:5)
Block(2,9,-4,STONE:0)
Block(2,10,-4,STONE:0)
Block(2,10,-3,STONE:0)
Block(2,10,-2,STONE:0)
Block(2,11,-5,LOG:5)
Block(2,11,-4,STONE:0)
Block(2,11,-3,STONE:0)
Block(2,11,-2,STONE:0)
Block(2,11,-1,LOG:5)
Block(2,12,-5,LOG:1)
Block(2,12,-4,RAILS:3)
Block(2,12,-3,COBBLESTONE_STAIRS:1)
Block(2,12,-2,RAILS:3)
Block(2,12,-1,LOG:1)
Block(2,13,-5,LOG:1)
Block(2,13,-4,AIR:0)
Block(2,13,-3,AIR:0)
Block(2,13,-2,AIR:0)
Block(2,13,-1,LOG:1)
Block(2,14,-5,LOG:1)
Block(2,14,-4,AIR:0)
Block(2,14,-3,AIR:0)
Block(2,14,-2,AIR:0)
Block(2,14,-1,LOG:1)
Block(2,15,-5,LOG:1)
Block(2,15,-4,AIR:0)
Block(2,15,-3,AIR:0)
Block(2,15,-2,AIR:0)
Block(2,15,-1,LOG:1)
Block(2,16,-5,LOG:9)
Block(2,16,-4,LOG:9)
Block(2,16,-3,LOG:9)
Block(2,16,-2,LOG:9)
Block(2,16,-1,LOG:5)
Block(2,22,-11,GRASS:0)
Block(2,22,-10,GRASS:0)
Block(2,22,-9,GRASS:0)
Block(2,22,-8,GRASS:0)
Block(2,22,-7,STONE:0)
Block(2,22,-6,STONE:0)
Block(2,22,-5,STONE:0)
Block(2,22,-4,STONE:0)
Block(2,22,-3,STONE:0)
Block(2,22,-2,STONE:0)
Block(2,22,-1,STONE:0)
Block(2,22,0,STONE:0)
Block(2,22,1,STONE:0)
Block(2,22,2,STONE:0)
Block(2,22,3,STONE:0)
Block(2,22,4,STONE:0)
Block(2,22,5,STONE:0)
Block(2,22,6,STONE:0)
Block(2,22,7,STONE:0)
Block(2,22,8,STONE:0)
Block(2,22,9,STONE:0)
Block(2,22,10,STONE:0)
Block(2,22,11,STONE:0)
Block(2,22,12,GRASS:0)
Block(2,23,-7,GRASS:0)
Block(2,23,-6,STONE:0)
Block(2,23,-5,STONE:0)
Block(2,23,-4,STONE:0)
Block(2,23,-3,STONE:0)
Block(2,23,-2,STONE:0)
Block(2,23,-1,STONE:0)
Block(2,23,0,STONE:0)
Block(2,23,1,STONE:0)
Block(2,23,2,STONE:0)
Block(2,23,3,STONE:0)
Block(2,23,4,STONE:0)
Block(2,23,5,STONE:0)
Block(2,23,6,STONE:0)
Block(2,23,7,STONE:0)
Block(2,23,8,STONE:0)
Block(2,23,9,STONE:0)
Block(2,23,10,STONE:0)
Block(2,23,11,STONE:0)
Block(2,24,-6,STONE:0)
Block(2,24,-5,STONE:0)
Block(2,24,-4,STONE:0)
Block(2,24,-3,STONE:0)
Block(2,24,-2,STONE:0)
Block(2,24,-1,STONE:0)
Block(2,24,0,STONE:0)
Block(2,24,1,STONE:0)
Block(2,24,2,STONE:0)
Block(2,24,3,STONE:0)
Block(2,24,4,STONE:0)
Block(2,24,5,STONE:0)
Block(2,24,6,STONE:0)
Block(2,24,7,STONE:0)
Block(2,24,8,STONE:0)
Block(2,24,9,STONE:0)
Block(2,24,10,STONE:0)
Block(2,24,11,STONE:0)
Block(2,25,-6,GRASS:0)
Block(2,25,-5,STONE:0)
Block(2,25,-4,STONE:0)
Block(2,25,-3,STONE:0)
Block(2,25,-2,STONE:0)
Block(2,25,-1,STONE:0)
Block(2,25,0,STONE:0)
Block(2,25,1,STONE:0)
Block(2,25,2,STONE:0)
Block(2,25,3,STONE:0)
Block(2,25,4,STONE:0)
Block(2,25,5,STONE:0)
Block(2,25,6,STONE:0)
Block(2,25,7,STONE:0)
Block(2,25,8,STONE:0)
Block(2,25,9,STONE:0)
Block(2,25,10,STONE:0)
Block(2,25,11,GRASS:0)
Block(2,26,-5,STONE:0)
Block(2,26,-4,STONE:0)
Block(2,26,-3,STONE:0)
Block(2,26,-2,STONE:0)
Block(2,26,-1,STONE:0)
Block(2,26,0,STONE:0)
Block(2,26,1,STONE:0)
Block(2,26,2,STONE:0)
Block(2,26,3,STONE:0)
Block(2,26,4,STONE:0)
Block(2,26,5,STONE:0)
Block(2,26,6,STONE:0)
Block(2,26,7,STONE:0)
Block(2,26,8,STONE:0)
Block(2,26,9,STONE:0)
Block(2,26,10,STONE:0)
Block(2,27,-5,GRASS:0)
Block(2,27,-4,STONE:0)
Block(2,27,-3,STONE:0)
Block(2,27,-2,STONE:0)
Block(2,27,-1,STONE:0)
Block(2,27,0,STONE:0)
Block(2,27,1,STONE:0)
Block(2,27,2,STONE:0)
Block(2,27,3,STONE:0)
Block(2,27,4,STONE:0)
Block(2,27,5,STONE:0)
Block(2,27,6,STONE:0)
Block(2,27,7,STONE:0)
Block(2,27,8,STONE:0)
Block(2,27,9,STONE:0)
Block(2,27,10,STONE:0)
Block(2,28,-4,GRASS:0)
Block(2,28,-3,STONE:0)
Block(2,28,-2,STONE:0)
Block(2,28,0,RAILS:1)
Block(2,28,2,RAILS:1)
Block(2,28,5,MONSTER_EGGS:1)
Block(2,28,6,STONE:0)
Block(2,28,7,STONE:0)
Block(2,28,8,STONE:0)
Block(2,28,9,MONSTER_EGGS:1)
Block(2,28,10,GRASS:0)
Block(2,29,5,COBBLESTONE_STAIRS:2)
Block(2,29,6,MONSTER_EGGS:1)
Block(2,29,7,MONSTER_EGGS:1)
Block(2,29,8,MONSTER_EGGS:1)
Block(2,29,9,COBBLESTONE_STAIRS:3)
Block(2,30,6,MONSTER_EGGS:1)
Block(2,30,7,MONSTER_EGGS:1)
Block(2,30,8,MONSTER_EGGS:1)
Block(2,31,2,DARK_OAK_STAIRS:2)
Block(2,31,3,DARK_OAK_STAIRS:7)
Block(2,31,6,MONSTER_EGGS:1)
Block(2,31,7,MAGMA:0)
Block(2,31,8,MONSTER_EGGS:1)
Block(2,31,11,DARK_OAK_STAIRS:6)
Block(2,31,12,DARK_OAK_STAIRS:3)
Block(2,32,3,DARK_OAK_STAIRS:2)
Block(2,32,4,DARK_OAK_STAIRS:7)
Block(2,32,6,MONSTER_EGGS:1)
Block(2,32,8,MONSTER_EGGS:1)
Block(2,32,10,DARK_OAK_STAIRS:6)
Block(2,32,11,DARK_OAK_STAIRS:3)
Block(2,33,4,WOOD:5)
Block(2,33,6,MONSTER_EGGS:1)
Block(2,33,7,IRON_TRAPDOOR:3)
Block(2,33,8,MONSTER_EGGS:1)
Block(2,33,10,WOOD:5)
Block(2,34,4,DARK_OAK_STAIRS:2)
Block(2,34,5,DARK_OAK_STAIRS:7)
Block(2,34,6,COBBLESTONE_STAIRS:2)
Block(2,34,7,MONSTER_EGGS:1)
Block(2,34,8,COBBLESTONE_STAIRS:0)
Block(2,34,9,DARK_OAK_STAIRS:6)
Block(2,34,10,DARK_OAK_STAIRS:3)
Block(2,35,5,DARK_OAK_STAIRS:2)
Block(2,35,6,DARK_OAK_STAIRS:7)
Block(2,35,7,MONSTER_EGGS:1)
Block(2,35,8,DARK_OAK_STAIRS:6)
Block(2,35,9,DARK_OAK_STAIRS:3)
Block(2,36,6,DARK_OAK_STAIRS:2)
Block(2,36,7,MONSTER_EGGS:1)
Block(2,36,8,DARK_OAK_STAIRS:3)
Block(2,37,7,WOOD_STEP:5)
Block(3,0,-1,LOG:1)
Block(3,1,-1,LOG:1)
Block(3,2,-1,LOG:1)
Block(3,3,-7,AIR:0)
Block(3,3,-6,AIR:0)
Block(3,3,-5,AIR:0)
Block(3,3,-4,AIR:0)
Block(3,3,-3,AIR:0)
Block(3,3,-2,AIR:0)
Block(3,3,-1,LOG:1)
Block(3,3,0,FENCE:0)
Block(3,4,-7,AIR:0)
Block(3,4,-6,AIR:0)
Block(3,4,-5,AIR:0)
Block(3,4,-4,AIR:0)
Block(3,4,-3,AIR:0)
Block(3,4,-2,AIR:0)
Block(3,4,-1,LOG:1)
Block(3,4,0,FENCE:0)
Block(3,5,-7,AIR:0)
Block(3,5,-6,AIR:0)
Block(3,5,-5,AIR:0)
Block(3,5,-4,AIR:0)
Block(3,5,-3,AIR:0)
Block(3,5,-2,AIR:0)
Block(3,5,-1,LOG:1)
Block(3,5,0,FENCE:0)
Block(3,6,-7,AIR:0)
Block(3,6,-6,AIR:0)
Block(3,6,-5,AIR:0)
Block(3,6,-4,AIR:0)
Block(3,6,-3,AIR:0)
Block(3,6,-1,LOG:5)
Block(3,7,-5,AIR:0)
Block(3,8,-4,STONE:0)
Block(3,9,-4,STONE:0)
Block(3,9,-3,STONE:0)
Block(3,9,-2,STONE:0)
Block(3,10,-4,STONE:0)
Block(3,10,-3,STONE:0)
Block(3,10,-2,STONE:0)
Block(3,11,-5,LOG:5)
Block(3,11,-4,RAILS:3)
Block(3,11,-3,COBBLESTONE_STAIRS:1)
Block(3,11,-2,RAILS:3)
Block(3,11,-1,LOG:5)
Block(3,12,-5,FENCE:0)
Block(3,12,-4,AIR:0)
Block(3,12,-3,AIR:0)
Block(3,12,-2,AIR:0)
Block(3,12,-1,FENCE:0)
Block(3,13,-5,FENCE:0)
Block(3,13,-4,AIR:0)
Block(3,13,-3,AIR:0)
Block(3,13,-2,AIR:0)
Block(3,13,-1,FENCE:0)
Block(3,14,-4,AIR:0)
Block(3,14,-3,AIR:0)
Block(3,14,-2,AIR:0)
Block(3,14,-1,FENCE:0)
Block(3,22,-11,GRASS:0)
Block(3,22,-10,GRASS:0)
Block(3,22,-9,GRASS:0)
Block(3,22,-8,GRASS:0)
Block(3,22,-7,GRASS:0)
Block(3,22,-6,STONE:0)
Block(3,22,-5,STONE:0)
Block(3,22,-4,STONE:0)
Block(3,22,-3,STONE:0)
Block(3,22,-2,STONE:0)
Block(3,22,-1,STONE:0)
Block(3,22,0,STONE:0)
Block(3,22,1,STONE:0)
Block(3,22,2,STONE:0)
Block(3,22,3,STONE:0)
Block(3,22,4,STONE:0)
Block(3,22,5,STONE:0)
Block(3,22,6,STONE:0)
Block(3,22,7,STONE:0)
Block(3,22,8,STONE:0)
Block(3,22,9,STONE:0)
Block(3,22,10,STONE:0)
Block(3,22,11,STONE:0)
Block(3,22,12,GRASS:0)
Block(3,23,-6,GRASS:0)
Block(3,23,-5,STONE:0)
Block(3,23,-4,STONE:0)
Block(3,23,-3,STONE:0)
Block(3,23,-2,STONE:0)
Block(3,23,-1,STONE:0)
Block(3,23,0,STONE:0)
Block(3,23,1,STONE:0)
Block(3,23,2,STONE:0)
Block(3,23,3,STONE:0)
Block(3,23,4,STONE:0)
Block(3,23,5,STONE:0)
Block(3,23,6,STONE:0)
Block(3,23,7,STONE:0)
Block(3,23,8,STONE:0)
Block(3,23,9,STONE:0)
Block(3,23,10,STONE:0)
Block(3,23,11,LOG:1)
Block(3,24,-5,GRASS:0)
Block(3,24,-4,STONE:0)
Block(3,24,-3,STONE:0)
Block(3,24,-2,STONE:0)
Block(3,24,-1,STONE:0)
Block(3,24,0,STONE:0)
Block(3,24,1,STONE:0)
Block(3,24,2,STONE:0)
Block(3,24,3,STONE:0)
Block(3,24,4,STONE:0)
Block(3,24,5,STONE:0)
Block(3,24,6,STONE:0)
Block(3,24,7,STONE:0)
Block(3,24,8,STONE:0)
Block(3,24,9,STONE:0)
Block(3,24,10,STONE:0)
Block(3,24,11,LOG:1)
Block(3,25,-4,STONE:0)
Block(3,25,-3,STONE:0)
Block(3,25,-2,STONE:0)
Block(3,25,-1,STONE:0)
Block(3,25,0,STONE:0)
Block(3,25,1,STONE:0)
Block(3,25,2,STONE:0)
Block(3,25,3,STONE:0)
Block(3,25,4,STONE:0)
Block(3,25,5,STONE:0)
Block(3,25,6,STONE:0)
Block(3,25,7,STONE:0)
Block(3,25,8,STONE:0)
Block(3,25,9,STONE:0)
Block(3,25,10,STONE:0)
Block(3,25,11,LOG:1)
Block(3,26,-4,STONE:0)
Block(3,26,-3,STONE:0)
Block(3,26,-2,STONE:0)
Block(3,26,-1,STONE:0)
Block(3,26,0,STONE:0)
Block(3,26,1,STONE:0)
Block(3,26,2,STONE:0)
Block(3,26,3,STONE:0)
Block(3,26,4,STONE:0)
Block(3,26,5,STONE:0)
Block(3,26,6,STONE:0)
Block(3,26,7,STONE:0)
Block(3,26,8,STONE:0)
Block(3,26,9,STONE:0)
Block(3,26,10,STONE:0)
Block(3,26,11,LOG:1)
Block(3,27,-4,GRASS:0)
Block(3,27,-3,STONE:0)
Block(3,27,-2,STONE:0)
Block(3,27,-1,STONE:0)
Block(3,27,0,STONE:0)
Block(3,27,1,STONE:0)
Block(3,27,2,STONE:0)
Block(3,27,3,STONE:0)
Block(3,27,4,STONE:0)
Block(3,27,5,STONE:0)
Block(3,27,6,STONE:0)
Block(3,27,7,STONE:0)
Block(3,27,8,STONE:0)
Block(3,27,9,STONE:0)
Block(3,27,10,DIRT:0)
Block(3,27,11,LOG:1)
Block(3,28,-3,COBBLESTONE_STAIRS:2)
Block(3,28,-2,MONSTER_EGGS:1)
Block(3,28,-1,RAILS:0)
Block(3,28,0,RAILS:8)
Block(3,28,2,RAILS:1)
Block(3,28,4,LOG:1)
Block(3,28,5,LOG:9)
Block(3,28,6,LOG:9)
Block(3,28,7,LOG:1)
Block(3,28,8,LOG:9)
Block(3,28,9,LOG:9)
Block(3,28,10,LOG:9)
Block(3,28,11,LOG:1)
Block(3,29,4,LOG:1)
Block(3,29,5,FENCE:0)
Block(3,29,6,FENCE:0)
Block(3,29,7,LOG:1)
Block(3,29,8,WOOD:1)
Block(3,29,9,WOOD:1)
Block(3,29,10,WOOD:1)
Block(3,29,11,LOG:1)
Block(3,30,3,DARK_OAK_STAIRS:6)
Block(3,30,4,LOG:1)
Block(3,30,5,FENCE:0)
Block(3,30,6,FENCE:0)
Block(3,30,7,LOG:1)
Block(3,30,8,WOOD:1)
Block(3,30,9,FENCE:0)
Block(3,30,10,WOOD:1)
Block(3,30,11,LOG:1)
Block(3,31,2,SPRUCE_WOOD_STAIRS:2)
Block(3,31,3,LOG:9)
Block(3,31,4,LOG:9)
Block(3,31,5,LOG:9)
Block(3,31,6,LOG:9)
Block(3,31,7,DOUBLE_STEP:3)
Block(3,31,8,LOG:9)
Block(3,31,9,LOG:9)
Block(3,31,10,LOG:9)
Block(3,31,11,LOG:1)
Block(3,31,12,SPRUCE_WOOD_STAIRS:3)
Block(3,32,3,LOG:1)
Block(3,32,4,WOOD:1)
Block(3,32,5,WOOD:1)
Block(3,32,6,FURNACE:5)
Block(3,32,7,STEP:3)
Block(3,32,8,FURNACE:5)
Block(3,32,9,WOOD:1)
Block(3,32,10,WOOD:1)
Block(3,32,11,LOG:1)
Block(3,33,3,SPRUCE_WOOD_STAIRS:2)
Block(3,33,4,WOOD:1)
Block(3,33,5,WOOD:1)
Block(3,33,6,COBBLE_WALL:0)
Block(3,33,8,COBBLE_WALL:0)
Block(3,33,9,WOOD:1)
Block(3,33,10,WOOD:1)
Block(3,33,11,SPRUCE_WOOD_STAIRS:3)
Block(3,34,4,SPRUCE_WOOD_STAIRS:2)
Block(3,34,5,WOOD:1)
Block(3,34,6,DOUBLE_STEP:3)
Block(3,34,7,DOUBLE_STEP:3)
Block(3,34,8,DOUBLE_STEP:3)
Block(3,34,9,WOOD:1)
Block(3,34,10,SPRUCE_WOOD_STAIRS:3)
Block(3,35,5,SPRUCE_WOOD_STAIRS:2)
Block(3,35,6,WOOD:1)
Block(3,35,7,DOUBLE_STEP:3)
Block(3,35,8,WOOD:1)
Block(3,35,9,SPRUCE_WOOD_STAIRS:3)
Block(3,36,6,SPRUCE_WOOD_STAIRS:2)
Block(3,36,7,DOUBLE_STEP:3)
Block(3,36,8,SPRUCE_WOOD_STAIRS:3)
Block(3,37,7,WOOD_STEP:5)
Block(4,3,-7,AIR:0)
Block(4,3,-6,AIR:0)
Block(4,3,-5,AIR:0)
Block(4,3,-4,AIR:0)
Block(4,4,-7,AIR:0)
Block(4,4,-6,AIR:0)
Block(4,4,-5,AIR:0)
Block(4,4,-4,AIR:0)
Block(4,4,-3,AIR:0)
Block(4,4,-2,AIR:0)
Block(4,5,-7,AIR:0)
Block(4,5,-6,AIR:0)
Block(4,5,-5,AIR:0)
Block(4,5,-4,AIR:0)
Block(4,5,-3,AIR:0)
Block(4,6,-7,AIR:0)
Block(4,6,-6,AIR:0)
Block(4,6,-5,AIR:0)
Block(4,6,-4,AIR:0)
Block(4,6,-3,AIR:0)
Block(4,6,-1,LOG:5)
Block(4,7,-4,STONE:0)
Block(4,8,-4,STONE:0)
Block(4,8,-3,STONE:0)
Block(4,9,-4,STONE:0)
Block(4,9,-3,STONE:0)
Block(4,9,-2,STONE:0)
Block(4,10,-4,RAILS:3)
Block(4,10,-3,COBBLESTONE_STAIRS:1)
Block(4,10,-2,RAILS:3)
Block(4,11,-5,LOG:5)
Block(4,11,-4,AIR:0)
Block(4,11,-3,AIR:0)
Block(4,11,-2,AIR:0)
Block(4,11,-1,LOG:5)
Block(4,12,-4,AIR:0)
Block(4,12,-3,AIR:0)
Block(4,12,-2,AIR:0)
Block(4,12,-1,FENCE:0)
Block(4,13,-4,AIR:0)
Block(4,13,-3,AIR:0)
Block(4,13,-2,AIR:0)
Block(4,22,-11,GRASS:0)
Block(4,22,-10,GRASS:0)
Block(4,22,-9,GRASS:0)
Block(4,22,-8,GRASS:0)
Block(4,22,-7,STONE:0)
Block(4,22,-6,STONE:0)
Block(4,22,-5,STONE:0)
Block(4,22,-4,STONE:0)
Block(4,22,-3,STONE:0)
Block(4,22,-2,STONE:0)
Block(4,22,-1,STONE:0)
Block(4,22,0,STONE:0)
Block(4,22,1,STONE:0)
Block(4,22,2,STONE:0)
Block(4,22,3,STONE:0)
Block(4,22,4,STONE:0)
Block(4,22,5,STONE:0)
Block(4,22,6,STONE:0)
Block(4,22,7,STONE:0)
Block(4,22,8,STONE:0)
Block(4,22,9,STONE:0)
Block(4,22,10,STONE:0)
Block(4,22,11,GRASS:0)
Block(4,22,12,GRASS:0)
Block(4,23,-7,GRASS:0)
Block(4,23,-6,STONE:0)
Block(4,23,-5,STONE:0)
Block(4,23,-4,STONE:0)
Block(4,23,-3,STONE:0)
Block(4,23,-2,STONE:0)
Block(4,23,-1,STONE:0)
Block(4,23,0,STONE:0)
Block(4,23,1,STONE:0)
Block(4,23,2,STONE:0)
Block(4,23,3,STONE:0)
Block(4,23,4,STONE:0)
Block(4,23,5,STONE:0)
Block(4,23,6,STONE:0)
Block(4,23,7,STONE:0)
Block(4,23,8,STONE:0)
Block(4,23,9,STONE:0)
Block(4,23,10,STONE:0)
Block(4,24,-6,STONE:0)
Block(4,24,-5,STONE:0)
Block(4,24,-4,STONE:0)
Block(4,24,-3,STONE:0)
Block(4,24,-2,STONE:0)
Block(4,24,-1,STONE:0)
Block(4,24,0,STONE:0)
Block(4,24,1,STONE:0)
Block(4,24,2,STONE:0)
Block(4,24,3,STONE:0)
Block(4,24,4,STONE:0)
Block(4,24,5,STONE:0)
Block(4,24,6,STONE:0)
Block(4,24,7,STONE:0)
Block(4,24,8,STONE:0)
Block(4,24,9,STONE:0)
Block(4,24,10,STONE:0)
Block(4,25,-6,GRASS:0)
Block(4,25,-5,STONE:0)
Block(4,25,-4,STONE:0)
Block(4,25,-3,STONE:0)
Block(4,25,-2,STONE:0)
Block(4,25,-1,STONE:0)
Block(4,25,0,STONE:0)
Block(4,25,1,STONE:0)
Block(4,25,2,STONE:0)
Block(4,25,3,STONE:0)
Block(4,25,4,STONE:0)
Block(4,25,5,STONE:0)
Block(4,25,6,STONE:0)
Block(4,25,7,STONE:0)
Block(4,25,8,STONE:0)
Block(4,25,9,STONE:0)
Block(4,25,10,STONE:0)
Block(4,26,-5,STONE:0)
Block(4,26,-4,STONE:0)
Block(4,26,-3,STONE:0)
Block(4,26,-2,STONE:0)
Block(4,26,-1,STONE:0)
Block(4,26,0,STONE:0)
Block(4,26,1,STONE:0)
Block(4,26,2,STONE:0)
Block(4,26,3,STONE:0)
Block(4,26,4,STONE:0)
Block(4,26,5,STONE:0)
Block(4,26,6,STONE:0)
Block(4,26,7,STONE:0)
Block(4,26,8,STONE:0)
Block(4,26,9,STONE:0)
Block(4,26,10,GRASS:0)
Block(4,27,-5,STONE:0)
Block(4,27,-4,STONE:0)
Block(4,27,-3,STONE:0)
Block(4,27,-2,STONE:0)
Block(4,27,-1,STONE:0)
Block(4,27,0,STONE:0)
Block(4,27,1,STONE:0)
Block(4,27,2,STONE:0)
Block(4,27,3,STONE:0)
Block(4,27,4,STONE:0)
Block(4,27,5,STONE:0)
Block(4,27,6,STONE:0)
Block(4,27,7,STONE:0)
Block(4,27,8,STONE:0)
Block(4,28,-5,GRASS:0)
Block(4,28,-4,GRASS:0)
Block(4,28,-3,STONE:0)
Block(4,28,-2,STONE:0)
Block(4,28,-1,STONE:0)
Block(4,28,0,FENCE:0)
Block(4,28,2,RAILS:1)
Block(4,28,5,COBBLESTONE_STAIRS:2)
Block(4,28,6,MONSTER_EGGS:1)
Block(4,28,7,LOG:5)
Block(4,28,8,WOOD_STEP:9)
Block(4,28,9,WOOD_STEP:9)
Block(4,28,10,WOOD_STEP:9)
Block(4,28,11,LOG:5)
Block(4,29,-3,STONE:0)
Block(4,29,-2,STONE:0)
Block(4,29,-1,STONE:0)
Block(4,29,0,TORCH:5)
Block(4,29,11,WOOD:1)
Block(4,30,-3,STONE:0)
Block(4,30,-2,GRASS:0)
Block(4,30,-1,GRASS:0)
Block(4,30,11,WOOD:1)
Block(4,31,-3,GRASS:0)
Block(4,31,2,SPRUCE_WOOD_STAIRS:2)
Block(4,31,3,LOG:5)
Block(4,31,4,WOOD_STEP:9)
Block(4,31,5,WOOD_STEP:9)
Block(4,31,6,WOOD_STEP:9)
Block(4,31,7,WOOD_STEP:9)
Block(4,31,8,WOOD_STEP:9)
Block(4,31,9,WOOD_STEP:9)
Block(4,31,10,WOOD_STEP:9)
Block(4,31,11,LOG:5)
Block(4,31,12,SPRUCE_WOOD_STAIRS:3)
Block(4,32,3,SPRUCE_WOOD_STAIRS:2)
Block(4,32,4,WOOD:1)
Block(4,32,5,COBBLE_WALL:0)
Block(4,32,9,COBBLE_WALL:0)
Block(4,32,10,WOOD:1)
Block(4,32,11,SPRUCE_WOOD_STAIRS:3)
Block(4,33,4,FENCE:0)
Block(4,33,5,COBBLE_WALL:0)
Block(4,33,9,COBBLE_WALL:0)
Block(4,33,10,FENCE:0)
Block(4,34,4,SPRUCE_WOOD_STAIRS:2)
Block(4,34,5,STEP:3)
Block(4,34,6,STEP:3)
Block(4,34,7,STEP:3)
Block(4,34,8,STEP:3)
Block(4,34,9,STEP:3)
Block(4,34,10,SPRUCE_WOOD_STAIRS:3)
Block(4,35,5,SPRUCE_WOOD_STAIRS:2)
Block(4,35,9,SPRUCE_WOOD_STAIRS:3)
Block(4,36,6,SPRUCE_WOOD_STAIRS:2)
Block(4,36,8,SPRUCE_WOOD_STAIRS:3)
Block(4,37,7,WOOD_STEP:5)
Block(5,3,-7,AIR:0)
Block(5,3,-6,AIR:0)
Block(5,3,-5,AIR:0)
Block(5,4,-7,AIR:0)
Block(5,4,-6,AIR:0)
Block(5,4,-5,AIR:0)
Block(5,5,-7,AIR:0)
Block(5,5,-6,AIR:0)
Block(5,5,-5,AIR:0)
Block(5,6,-7,AIR:0)
Block(5,6,-6,AIR:0)
Block(5,6,-5,LOG:5)
Block(5,6,-4,STONE:0)
Block(5,6,-1,LOG:5)
Block(5,7,-4,STONE:0)
Block(5,7,-3,STONE:0)
Block(5,7,-2,STONE:0)
Block(5,8,-4,STONE:0)
Block(5,8,-3,STONE:0)
Block(5,8,-2,STONE:0)
Block(5,9,-5,FENCE:0)
Block(5,9,-4,RAILS:3)
Block(5,9,-3,COBBLESTONE_STAIRS:1)
Block(5,9,-2,RAILS:3)
Block(5,10,-5,FENCE:0)
Block(5,10,-4,AIR:0)
Block(5,10,-3,AIR:0)
Block(5,10,-2,AIR:0)
Block(5,11,-5,LOG:5)
Block(5,11,-4,AIR:0)
Block(5,11,-3,AIR:0)
Block(5,11,-2,AIR:0)
Block(5,11,-1,LOG:5)
Block(5,12,-4,AIR:0)
Block(5,12,-3,AIR:0)
Block(5,12,-2,AIR:0)
Block(5,22,-11,GRASS:0)
Block(5,22,-10,GRASS:0)
Block(5,22,-9,STONE:0)
Block(5,22,-8,STONE:0)
Block(5,22,-7,STONE:0)
Block(5,22,-6,STONE:0)
Block(5,22,-5,STONE:0)
Block(5,22,-4,STONE:0)
Block(5,22,-3,STONE:0)
Block(5,22,-2,STONE:0)
Block(5,22,-1,STONE:0)
Block(5,22,0,STONE:0)
Block(5,22,1,STONE:0)
Block(5,22,2,STONE:0)
Block(5,22,3,STONE:0)
Block(5,22,4,STONE:0)
Block(5,22,5,STONE:0)
Block(5,22,6,STONE:0)
Block(5,22,7,STONE:0)
Block(5,22,8,STONE:0)
Block(5,22,9,STONE:0)
Block(5,22,10,STONE:0)
Block(5,22,11,GRASS:0)
Block(5,22,12,GRASS:0)
Block(5,23,-9,STONE:0)
Block(5,23,-8,STONE:0)
Block(5,23,-7,STONE:0)
Block(5,23,-6,STONE:0)
Block(5,23,-5,STONE:0)
Block(5,23,-4,STONE:0)
Block(5,23,-3,STONE:0)
Block(5,23,-2,STONE:0)
Block(5,23,-1,STONE:0)
Block(5,23,0,STONE:0)
Block(5,23,1,STONE:0)
Block(5,23,2,STONE:0)
Block(5,23,3,STONE:0)
Block(5,23,4,STONE:0)
Block(5,23,5,STONE:0)
Block(5,23,6,STONE:0)
Block(5,23,7,STONE:0)
Block(5,23,8,STONE:0)
Block(5,23,9,STONE:0)
Block(5,23,10,STONE:0)
Block(5,24,-9,GRASS:0)
Block(5,24,-8,STONE:0)
Block(5,24,-7,STONE:0)
Block(5,24,-6,STONE:0)
Block(5,24,-5,STONE:0)
Block(5,24,-4,STONE:0)
Block(5,24,-3,STONE:0)
Block(5,24,-2,STONE:0)
Block(5,24,-1,STONE:0)
Block(5,24,0,STONE:0)
Block(5,24,1,STONE:0)
Block(5,24,2,STONE:0)
Block(5,24,3,STONE:0)
Block(5,24,4,STONE:0)
Block(5,24,5,STONE:0)
Block(5,24,6,STONE:0)
Block(5,24,7,STONE:0)
Block(5,24,8,STONE:0)
Block(5,24,9,STONE:0)
Block(5,24,10,STONE:0)
Block(5,25,-8,GRASS:0)
Block(5,25,-7,STONE:0)
Block(5,25,-6,STONE:0)
Block(5,25,-5,STONE:0)
Block(5,25,-4,STONE:0)
Block(5,25,-3,STONE:0)
Block(5,25,-2,STONE:0)
Block(5,25,-1,STONE:0)
Block(5,25,0,STONE:0)
Block(5,25,1,STONE:0)
Block(5,25,2,STONE:0)
Block(5,25,3,STONE:0)
Block(5,25,4,STONE:0)
Block(5,25,5,STONE:0)
Block(5,25,6,STONE:0)
Block(5,25,7,STONE:0)
Block(5,25,8,STONE:0)
Block(5,25,9,STONE:0)
Block(5,25,10,STONE:0)
Block(5,26,-7,GRASS:0)
Block(5,26,-6,STONE:0)
Block(5,26,-5,STONE:0)
Block(5,26,-4,STONE:0)
Block(5,26,-3,STONE:0)
Block(5,26,-2,STONE:0)
Block(5,26,-1,STONE:0)
Block(5,26,0,STONE:0)
Block(5,26,1,STONE:0)
Block(5,26,2,STONE:0)
Block(5,26,3,STONE:0)
Block(5,26,4,STONE:0)
Block(5,26,5,STONE:0)
Block(5,26,6,STONE:0)
Block(5,26,7,STONE:0)
Block(5,26,8,STONE:0)
Block(5,26,9,STONE:0)
Block(5,26,10,STONE:0)
Block(5,27,-6,GRASS:0)
Block(5,27,-5,STONE:0)
Block(5,27,-4,STONE:0)
Block(5,27,-3,STONE:0)
Block(5,27,-2,STONE:0)
Block(5,27,-1,STONE:0)
Block(5,27,0,STONE:0)
Block(5,27,1,STONE:0)
Block(5,27,2,STONE:0)
Block(5,27,3,STONE:0)
Block(5,27,4,STONE:0)
Block(5,27,5,STONE:0)
Block(5,27,6,STONE:0)
Block(5,27,7,STONE:0)
Block(5,27,8,STONE:0)
Block(5,27,9,DIRT:0)
Block(5,28,-5,GRASS:0)
Block(5,28,-4,STONE:0)
Block(5,28,-3,STONE:0)
Block(5,28,-2,STONE:0)
Block(5,28,-1,STONE:0)
Block(5,28,0,STONE:0)
Block(5,28,2,RAILS:7)
Block(5,28,3,RAILS:0)
Block(5,28,4,RAILS:0)
Block(5,28,5,RAILS:5)
Block(5,28,6,MONSTER_EGGS:1)
Block(5,28,7,LOG:5)
Block(5,28,8,WOOD_STEP:9)
Block(5,28,9,WOOD_STEP:9)
Block(5,28,10,WOOD_STEP:9)
Block(5,28,11,LOG:5)
Block(5,29,-4,STONE:0)
Block(5,29,-3,STONE:0)
Block(5,29,-2,STONE:0)
Block(5,29,-1,STONE:0)
Block(5,29,0,GRASS:0)
Block(5,29,6,RAILS:0)
Block(5,29,7,RAILS:0)
Block(5,29,8,RAILS:0)
Block(5,29,9,MONSTER_EGGS:1)
Block(5,29,10,COBBLESTONE_STAIRS:0)
Block(5,29,11,WOOD:1)
Block(5,30,-4,GRASS:0)
Block(5,30,-3,STONE:0)
Block(5,30,-2,STONE:0)
Block(5,30,-1,GRASS:0)
Block(5,30,11,FENCE:0)
Block(5,31,-3,GRASS:0)
Block(5,31,-2,GRASS:0)
Block(5,31,2,SPRUCE_WOOD_STAIRS:2)
Block(5,31,3,LOG:5)
Block(5,31,4,WOOD_STEP:9)
Block(5,31,5,WOOD_STEP:9)
Block(5,31,6,WOOD_STEP:9)
Block(5,31,7,WOOD_STEP:9)
Block(5,31,8,WOOD_STEP:9)
Block(5,31,9,WOOD_STEP:9)
Block(5,31,10,WOOD_STEP:9)
Block(5,31,11,LOG:5)
Block(5,31,12,SPRUCE_WOOD_STAIRS:3)
Block(5,32,3,SPRUCE_WOOD_STAIRS:2)
Block(5,32,4,WOOD:1)
Block(5,32,10,WOOD:1)
Block(5,32,11,SPRUCE_WOOD_STAIRS:3)
Block(5,33,4,FENCE:0)
Block(5,33,10,FENCE:0)
Block(5,34,4,SPRUCE_WOOD_STAIRS:2)
Block(5,34,10,SPRUCE_WOOD_STAIRS:3)
Block(5,35,5,SPRUCE_WOOD_STAIRS:2)
Block(5,35,9,SPRUCE_WOOD_STAIRS:3)
Block(5,36,6,SPRUCE_WOOD_STAIRS:2)
Block(5,36,8,SPRUCE_WOOD_STAIRS:3)
Block(5,37,7,WOOD_STEP:5)
Block(6,3,-7,AIR:0)
Block(6,3,-6,AIR:0)
Block(6,3,-5,AIR:0)
Block(6,4,-7,AIR:0)
Block(6,4,-6,AIR:0)
Block(6,4,-5,AIR:0)
Block(6,5,-7,AIR:0)
Block(6,5,-6,AIR:0)
Block(6,5,-5,AIR:0)
Block(6,5,-4,STONE:0)
Block(6,6,-7,AIR:0)
Block(6,6,-6,AIR:0)
Block(6,6,-5,LOG:5)
Block(6,6,-4,STONE:0)
Block(6,6,-3,STONE:0)
Block(6,6,-2,STONE:0)
Block(6,6,-1,LOG:5)
Block(6,7,-4,STONE:0)
Block(6,7,-3,STONE:0)
Block(6,7,-2,STONE:0)
Block(6,8,-4,RAILS:3)
Block(6,8,-3,COBBLESTONE_STAIRS:1)
Block(6,8,-2,RAILS:3)
Block(6,9,-5,FENCE:0)
Block(6,9,-4,AIR:0)
Block(6,9,-3,AIR:0)
Block(6,9,-2,AIR:0)
Block(6,9,-1,FENCE:0)
Block(6,10,-5,FENCE:0)
Block(6,10,-4,AIR:0)
Block(6,10,-3,AIR:0)
Block(6,10,-2,AIR:0)
Block(6,10,-1,FENCE:0)
Block(6,11,-5,LOG:5)
Block(6,11,-4,AIR:0)
Block(6,11,-3,TORCH:2)
Block(6,11,-2,AIR:0)
Block(6,11,-1,LOG:5)
Block(6,22,-11,GRASS:0)
Block(6,22,-10,STONE:0)
Block(6,22,-9,STONE:0)
Block(6,22,-8,STONE:0)
Block(6,22,-7,STONE:0)
Block(6,22,-6,STONE:0)
Block(6,22,-5,STONE:0)
Block(6,22,-4,STONE:0)
Block(6,22,-3,STONE:0)
Block(6,22,-2,STONE:0)
Block(6,22,-1,STONE:0)
