
#######################################################################
# +-----------------------------------------------------------------+ #
# |                            BO3 object                           | #
# +-----------------------------------------------------------------+ #
#######################################################################

Author: NLBlackEagle

Description: No description given

Version: 3

SettingsMode: WriteDisable


#######################################################################
# +-----------------------------------------------------------------+ #
# |                          Main settings                          | #
# +-----------------------------------------------------------------+ #
#######################################################################

Tree: false

Frequency: 1

Rarity: 25.0

RotateRandomly: false

SpawnHeight: randomY

SpawnHeightOffset: 0

SpawnHeightVariance: 0

##############################
# Height Limits for the BO3. #
##############################

MinHeight: 47

MaxHeight: 47

######################
# Extrusion settings #
######################

ExtrudeMode: None

ExtrudeThroughBlocks: air

MaxBranchDepth: 60

ExcludedBiomes: All


#######################################################################
# +-----------------------------------------------------------------+ #
# |                      Source block settings                      | #
# +-----------------------------------------------------------------+ #
#######################################################################

SourceBlocks: air

MaxPercentageOutsideSourceBlock: 100

OutsideSourceBlock: placeAnyway


#######################################################################
# +-----------------------------------------------------------------+ #
# |                              Blocks                             | #
# +-----------------------------------------------------------------+ #
#######################################################################

Block(-8,30,-4,wall_banner:4,StructureNBT/SapphireCity/sap02/1-Banner.nbt)
Block(-8,31,-4,cobblestone_wall)
Block(-8,32,-4,stone_slab)
Block(-8,33,-4,wooden_slab:8)
Block(-8,34,-4,wooden_slab)
Block(-8,37,-4,wool:15)
Block(-8,38,-4,fence)
Block(-8,39,-4,fence)
Block(-8,41,-2,wool)
Block(-8,42,-1,wool)
Block(-8,43,-2,wool:15)
Block(-8,44,-2,wool:15)
Block(-8,45,-3,wool:15)
Block(-8,46,-3,wool)
Block(-8,47,-4,wool)
Block(-8,48,-4,fence)
Block(-8,49,-4,fence)
Block(-7,30,-4,dark_oak_stairs:4)
Block(-7,31,-5,stone_slab)
Block(-7,31,-4,cobblestone_wall)
Block(-7,31,-3,stone_slab)
Block(-7,32,-5,stone_slab)
Block(-7,32,-4,cobblestone_wall)
Block(-7,32,-3,stone_slab)
Block(-7,33,-4,double_wooden_slab)
Block(-7,37,-4,wool:15)
Block(-7,38,-4,wool:15)
Block(-7,39,-4,fence)
Block(-7,40,-4,fence)
Block(-7,41,-1,wool)
Block(-7,42,-1,wool:15)
Block(-7,43,-1,wool:15)
Block(-7,44,-2,wool:15)
Block(-7,45,-2,wool:15)
Block(-7,46,-3,wool:15)
Block(-7,47,-3,wool:15)
Block(-7,48,-4,wool:15)
Block(-7,49,-4,fence)
Block(-7,50,-4,fence)
Block(-6,29,-5,wall_banner,StructureNBT/SapphireCity/sap02/2-Banner.nbt)
Block(-6,29,-4,dark_oak_stairs:4)
Block(-6,29,-3,wall_banner:3,StructureNBT/SapphireCity/sap02/3-Banner.nbt)
Block(-6,30,-5,stone_slab:8)
Block(-6,30,-4,dark_oak_stairs:1)
Block(-6,30,-3,stone_slab:8)
Block(-6,31,-5,stone_slab:8)
Block(-6,31,-3,stone_slab:8)
Block(-6,32,-4,wooden_slab:8)
Block(-6,33,-4,wooden_slab)
Block(-6,38,-4,wool:15)
Block(-6,39,-4,wool:15)
Block(-6,40,-4,fence)
Block(-6,41,-4,fence)
Block(-6,41,-1,wool)
Block(-6,42,0,wool:15)
Block(-6,43,-1,wool:15)
Block(-6,44,-2,wool:15)
Block(-6,45,-2,wool:15)
Block(-6,46,-2,wool:15)
Block(-6,47,-3,wool:15)
Block(-6,48,-3,wool:15)
Block(-6,49,-4,wool:15)
Block(-6,50,-4,fence)
Block(-6,51,-4,fence)
Block(-5,28,-4,iron_block)
Block(-5,29,-5,dark_oak_stairs:6)
Block(-5,29,-4,iron_block)
Block(-5,29,-3,dark_oak_stairs:7)
Block(-5,30,-5,stone_slab)
Block(-5,30,-4,cobblestone_wall)
Block(-5,30,-3,stone_slab)
Block(-5,31,-5,stone_slab)
Block(-5,31,-4,cobblestone_wall)
Block(-5,31,-3,stone_slab)
Block(-5,32,-4,double_wooden_slab)
Block(-5,38,-3,wool)
Block(-5,39,-3,wool)
Block(-5,40,-4,wool)
Block(-5,41,-4,fence)
Block(-5,41,-1,wool:15)
Block(-5,42,-4,fence)
Block(-5,42,0,wool:15)
Block(-5,43,-1,wool:15)
Block(-5,44,-1,wool:15)
Block(-5,45,-2,wool:15)
Block(-5,46,-2,wool:15)
Block(-5,47,-2,wool:15)
Block(-5,48,-3,wool:15)
Block(-5,49,-3,wool:15)
Block(-5,50,-4,wool:15)
Block(-5,51,-4,fence)
Block(-5,52,-4,fence)
Block(-4,26,-4,iron_block)
Block(-4,27,-4,iron_block)
Block(-4,28,-4,iron_block)
Block(-4,29,-5,wooden_slab:13)
Block(-4,29,-4,planks:3)
Block(-4,29,-3,wooden_slab:13)
Block(-4,30,-6,stone_slab)
Block(-4,30,-5,cobblestone_wall)
Block(-4,30,-4,cobblestone_wall)
Block(-4,30,-3,cobblestone_wall)
Block(-4,30,-2,stone_slab)
Block(-4,31,-6,stone_slab)
Block(-4,31,-4,wooden_slab:8)
Block(-4,31,-2,stone_slab)
Block(-4,32,-4,wooden_slab)
Block(-4,38,-3,wool)
Block(-4,39,-2,wool)
Block(-4,40,-3,wool:15)
Block(-4,41,-4,wool:15)
Block(-4,41,0,wool:15)
Block(-4,42,-4,fence)
Block(-4,42,0,wool:15)
Block(-4,43,-4,fence)
Block(-4,43,0,wool:15)
Block(-4,44,-1,wool)
Block(-4,45,-1,wool)
Block(-4,46,-2,wool)
Block(-4,47,-2,wool)
Block(-4,48,-2,wool)
Block(-4,49,-3,wool:15)
Block(-4,50,-3,wool:15)
Block(-4,51,-4,wool:15)
Block(-4,52,-4,fence)
Block(-4,53,-4,fence)
Block(-3,23,-4,iron_bars)
Block(-3,24,-4,iron_block)
Block(-3,25,-4,iron_block)
Block(-3,26,-4,iron_block)
Block(-3,27,-4,planks:3)
Block(-3,28,-4,planks:3)
Block(-3,29,-6,dark_oak_stairs:4)
Block(-3,29,-5,wooden_slab:13)
Block(-3,29,-4,planks:3)
Block(-3,29,-3,wooden_slab:13)
Block(-3,29,-2,dark_oak_stairs:4)
Block(-3,30,-7,stone_slab)
Block(-3,30,-6,cobblestone_wall)
Block(-3,30,-5,cobblestone_wall)
Block(-3,30,-4,planks:3)
Block(-3,30,-3,cobblestone_wall)
Block(-3,30,-2,cobblestone_wall)
Block(-3,30,-1,stone_slab)
Block(-3,31,-7,stone_slab)
Block(-3,31,-4,double_wooden_slab)
Block(-3,31,-1,stone_slab)
Block(-3,38,-2,wool)
Block(-3,39,-2,wool:15)
Block(-3,40,-3,wool:15)
Block(-3,41,-3,wool:15)
Block(-3,41,0,wool:15)
Block(-3,42,-4,wool:15)
Block(-3,42,1,wool:15)
Block(-3,43,-4,fence)
Block(-3,43,0,wool)
Block(-3,44,-4,fence)
Block(-3,44,0,wool)
Block(-3,45,-1,wool)
Block(-3,46,-2,wool)
Block(-3,47,-2,wool)
Block(-3,48,-2,wool)
Block(-3,49,-2,wool)
Block(-3,50,-3,wool:15)
Block(-3,51,-3,wool:15)
Block(-3,52,-4,wool:15)
Block(-3,53,-4,fence)
Block(-3,54,-4,fence)
Block(-2,16,-4,iron_bars)
Block(-2,22,-4,iron_bars)
Block(-2,23,-4,iron_block)
Block(-2,24,-4,iron_block)
Block(-2,25,-4,planks:3)
Block(-2,26,-4,planks:3)
Block(-2,27,-4,planks:3)
Block(-2,28,-6,oak_stairs:6)
Block(-2,28,-5,planks)
Block(-2,28,-4,planks:5)
Block(-2,28,-3,planks)
Block(-2,28,-2,oak_stairs:7)
Block(-2,29,-7,dark_oak_stairs:6)
Block(-2,29,-6,planks)
Block(-2,29,-5,planks)
Block(-2,29,-4,planks:5)
Block(-2,29,-3,planks)
Block(-2,29,-2,planks)
Block(-2,29,-1,dark_oak_stairs:7)
Block(-2,30,-7,stone_slab:8)
Block(-2,30,-6,cobblestone_wall)
Block(-2,30,-4,wooden_slab:8)
Block(-2,30,-2,cobblestone_wall)
Block(-2,30,-1,stone_slab:8)
Block(-2,31,-7,stone_slab:8)
Block(-2,31,-4,wooden_slab)
Block(-2,31,-1,stone_slab:8)
Block(-2,33,-6,stone_button:2)
Block(-2,33,-2,stone_button:2)
Block(-2,38,-2,wool)
Block(-2,39,-2,wool:15)
Block(-2,40,-2,wool:15)
Block(-2,41,-3,wool:15)
Block(-2,41,1,wool:15)
Block(-2,42,-3,wool:15)
Block(-2,42,1,wool:15)
Block(-2,43,-4,wool)
Block(-2,43,1,wool)
Block(-2,44,-4,fence)
Block(-2,44,0,wool)
Block(-2,45,-4,fence)
Block(-2,45,-1,wool)
Block(-2,46,-1,wool)
Block(-2,47,-2,wool)
Block(-2,48,-2,wool)
Block(-2,49,-2,wool)
Block(-2,50,-2,wool)
Block(-2,51,-3,wool:15)
Block(-2,52,-3,wool:15)
Block(-2,53,-4,wool)
Block(-2,54,-4,fence)
Block(-2,55,-4,fence)
Block(-1,16,-4,iron_block)
Block(-1,17,-4,iron_bars)
Block(-1,21,-4,iron_bars)
Block(-1,22,-4,iron_block)
Block(-1,23,-4,iron_block)
Block(-1,24,-4,planks:3)
Block(-1,25,-5,iron_block)
Block(-1,25,-4,planks:3)
Block(-1,25,-3,iron_block)
Block(-1,26,-5,planks:5)
Block(-1,26,-4,planks:5)
Block(-1,26,-3,planks:5)
Block(-1,27,-5,planks:5)
Block(-1,27,-4,planks:5)
Block(-1,27,-3,planks:5)
Block(-1,28,-6,oak_stairs:6)
Block(-1,28,-5,planks)
Block(-1,28,-4,planks:5)
Block(-1,28,-3,planks)
Block(-1,28,-2,oak_stairs:7)
Block(-1,29,-7,wooden_slab:13)
Block(-1,29,-6,planks)
Block(-1,29,-5,planks)
Block(-1,29,-3,planks)
Block(-1,29,-2,planks)
Block(-1,29,-1,wooden_slab:13)
Block(-1,30,-7,stone_slab:8)
Block(-1,30,-6,cobblestone_wall)
Block(-1,30,-4,double_wooden_slab)
Block(-1,30,-2,cobblestone_wall)
Block(-1,30,-1,stone_slab:8)
Block(-1,31,-7,stone_slab:8)
Block(-1,31,-1,stone_slab:8)
Block(-1,33,-6,iron_block)
Block(-1,33,-2,iron_block)
Block(-1,38,-1,wool:15)
Block(-1,39,-1,wool:15)
Block(-1,40,-2,wool:15)
Block(-1,40,1,wool:15)
Block(-1,41,-2,wool:15)
Block(-1,41,1,wool:15)
Block(-1,42,-3,wool:15)
Block(-1,42,1,wool:15)
Block(-1,43,-3,wool:15)
Block(-1,43,1,wool)
Block(-1,44,-4,wool)
Block(-1,44,0,wool)
Block(-1,45,-4,fence)
Block(-1,45,0,wool)
Block(-1,46,-4,fence)
Block(-1,46,0,wool)
Block(-1,47,-1,wool)
Block(-1,48,-2,wool)
Block(-1,49,-2,wool)
Block(-1,50,-2,wool)
Block(-1,51,-2,wool:15)
Block(-1,52,-3,wool:15)
Block(-1,53,-3,wool:15)
Block(-1,54,-4,wool)
Block(-1,55,-4,fence)
Block(-1,56,-4,fence)
Block(0,16,-4,iron_block)
Block(0,17,-4,iron_block)
Block(0,18,-4,iron_bars)
Block(0,19,-4,iron_bars)
Block(0,20,-4,iron_bars)
Block(0,21,-4,iron_block)
Block(0,22,-4,iron_block)
Block(0,23,-4,planks:3)
Block(0,24,-5,planks:5)
Block(0,24,-4,planks:5)
Block(0,24,-3,planks:5)
Block(0,25,-5,iron_block)
Block(0,25,-4,planks:5)
Block(0,25,-3,iron_block)
Block(0,26,-5,planks:5)
Block(0,26,-4,planks:5)
Block(0,26,-3,planks:5)
Block(0,27,-7,oak_stairs:6)
Block(0,27,-6,planks)
Block(0,27,-5,planks:5)
Block(0,27,-4,planks:5)
Block(0,27,-3,planks:5)
Block(0,27,-2,planks)
Block(0,27,-1,oak_stairs:7)
Block(0,28,-7,planks)
Block(0,28,-6,planks:5)
Block(0,28,-5,planks:5)
Block(0,28,-4,planks:5)
Block(0,28,-3,planks:5)
Block(0,28,-2,planks:5)
Block(0,28,-1,planks)
Block(0,29,-8,dark_oak_stairs:6)
Block(0,29,-7,planks)
Block(0,29,-6,planks)
Block(0,29,-5,planks)
Block(0,29,-4,wooden_slab:8)
Block(0,29,-3,planks)
Block(0,29,-2,planks)
Block(0,29,-1,planks)
Block(0,29,0,dark_oak_stairs:7)
Block(0,30,-8,oak_stairs:2)
Block(0,30,-7,planks:5)
Block(0,30,-6,double_wooden_slab)
Block(0,30,-4,double_wooden_slab)
Block(0,30,-2,double_wooden_slab)
Block(0,30,-1,planks:5)
Block(0,30,0,oak_STAIRS:0)
Block(0,31,-7,oak_stairs:0)
Block(0,31,-6,double_wooden_slab)
Block(0,31,-4,double_wooden_slab)
Block(0,31,-2,double_wooden_slab)
Block(0,31,-1,oak_stairs:0)
Block(0,32,-7,wooden_slab:5)
Block(0,32,-6,double_wooden_slab:5)
Block(0,32,-5,wooden_slab:5)
Block(0,32,-4,double_wooden_slab:5)
Block(0,32,-3,wooden_slab:5)
Block(0,32,-2,double_wooden_slab:5)
Block(0,32,-1,wooden_slab:5)
Block(0,33,-7,stone_slab)
Block(0,33,-6,iron_block)
Block(0,33,-5,stone_slab)
Block(0,33,-4,cobblestone_wall)
Block(0,33,-3,stone_slab)
Block(0,33,-2,iron_block)
Block(0,33,-1,stone_slab)
Block(0,34,-4,torch)
Block(0,38,-1,wool:15)
Block(0,39,-1,wool:15)
Block(0,40,-1,wool:15)
Block(0,40,1,wool:15)
Block(0,41,-2,wool)
Block(0,42,-2,wool:15)
Block(0,43,-3,wool:15)
Block(0,44,-3,wool:15)
Block(0,45,-4,wool:15)
Block(0,46,-4,fence)
Block(0,47,-4,fence)
Block(0,51,-2,wool)
Block(0,52,-2,wool:15)
Block(0,53,-3,wool:15)
Block(0,54,-3,wool)
Block(0,55,-4,wool)
Block(0,56,-4,fence)
Block(0,57,-4,fence)
Block(1,16,-4,planks:3)
Block(1,17,-4,iron_block)
Block(1,18,-4,iron_block)
Block(1,19,-4,iron_bars)
Block(1,20,-4,iron_block)
Block(1,21,-4,iron_block)
Block(1,22,-4,planks:3)
Block(1,23,-5,planks:5)
Block(1,23,-4,planks:5)
Block(1,23,-3,planks:5)
Block(1,24,-6,planks:5)
Block(1,24,-5,wooden_slab:11)
Block(1,24,-4,wooden_slab:11)
Block(1,24,-3,wooden_slab:11)
Block(1,24,-2,planks:5)
Block(1,25,-6,planks:5)
Block(1,25,-5,iron_block)
Block(1,25,-3,iron_block)
Block(1,25,-2,planks:5)
Block(1,26,-6,planks)
Block(1,26,-5,lever:6)
Block(1,26,-3,lever:6)
Block(1,26,-2,planks)
Block(1,27,-7,oak_stairs:6)
Block(1,27,-6,planks)
Block(1,27,-5,planks:5)
Block(1,27,-4,planks:5)
Block(1,27,-3,planks:5)
Block(1,27,-2,planks)
Block(1,27,-1,oak_stairs:7)
Block(1,28,-7,planks:5)
Block(1,28,-6,planks)
Block(1,28,-5,planks)
Block(1,28,-4,planks:5)
Block(1,28,-2,planks)
Block(1,28,-1,planks:5)
Block(1,29,-8,wooden_slab:13)
Block(1,29,-7,planks)
Block(1,29,-6,planks)
Block(1,29,-5,planks)
Block(1,29,-4,double_wooden_slab)
Block(1,29,-3,planks)
Block(1,29,-2,planks)
Block(1,29,-1,planks)
Block(1,29,0,wooden_slab:13)
Block(1,30,-8,planks:5)
Block(1,30,-7,planks)
Block(1,30,-6,planks)
Block(1,30,-2,planks)
Block(1,30,-1,planks)
Block(1,30,0,planks:5)
Block(1,31,-8,oak_stairs:2)
Block(1,31,-7,cobblestone_wall)
Block(1,31,-4,wall_banner:5,StructureNBT/SapphireCity/sap02/4-Banner.nbt)
Block(1,31,-1,cobblestone_wall)
Block(1,31,0,oak_STAIRS:0)
Block(1,32,-8,wooden_slab:5)
Block(1,32,-7,wooden_slab:5)
Block(1,32,-6,double_wooden_slab:5)
Block(1,32,-5,wooden_slab:5)
Block(1,32,-4,wooden_slab:5)
Block(1,32,-3,wooden_slab:5)
Block(1,32,-2,double_wooden_slab:5)
Block(1,32,-1,wooden_slab:5)
Block(1,32,0,wooden_slab:5)
Block(1,33,-8,stone_slab)
Block(1,33,-6,iron_block)
Block(1,33,-5,tripwire_hook:0)
Block(1,33,-3,tripwire_hook)
Block(1,33,-2,iron_block)
Block(1,33,0,stone_slab)
Block(1,34,-6,lever:6)
Block(1,34,-2,lever:6)
Block(1,36,0,fence)
Block(1,37,-1,wool:15)
Block(1,37,0,fence)
Block(1,38,-1,wool:15)
Block(1,38,0,fence)
Block(1,38,1,fence)
Block(1,39,-1,wool)
Block(1,39,1,wool:15)
Block(1,40,-2,wool)
Block(1,41,-2,wool)
Block(1,42,-2,wool)
Block(1,43,-2,wool)
Block(1,44,-3,wool:15)
Block(1,45,-3,wool:15)
Block(1,46,-4,wool:15)
Block(1,47,-4,fence)
Block(1,48,-4,fence)
Block(1,54,-7,wool:15)
Block(1,55,-8,wool:15)
Block(1,55,-7,wool:15)
Block(1,55,-6,wool:15)
Block(1,55,-5,wool:15)
Block(1,55,-3,wool)
Block(1,56,-8,wool)
Block(1,56,-7,wool:15)
Block(1,56,-6,wool:15)
Block(1,56,-4,wool:15)
Block(1,57,-8,wool)
Block(1,57,-7,wool:15)
Block(1,57,-4,fence)
Block(1,58,-4,fence)
Block(2,16,-4,planks:3)
Block(2,17,-4,planks:3)
Block(2,18,-4,iron_block)
Block(2,19,-4,iron_block)
Block(2,20,-4,iron_block)
Block(2,21,-4,planks:3)
Block(2,22,-5,planks:5)
Block(2,22,-4,planks:5)
Block(2,22,-3,planks:5)
Block(2,23,-5,planks:5)
Block(2,23,-4,wooden_slab:3)
Block(2,23,-3,planks:5)
Block(2,24,-6,planks:5)
Block(2,24,-5,wooden_slab:11)
Block(2,24,-4,wooden_slab:11)
Block(2,24,-3,wooden_slab:11)
Block(2,24,-2,planks:5)
Block(2,25,-6,planks:5)
Block(2,25,-5,stone_brick_stairs:1)
Block(2,25,-3,stone_brick_stairs:1)
Block(2,25,-2,planks:5)
Block(2,26,-8,oak_stairs:6)
Block(2,26,-7,planks)
Block(2,26,-6,planks:5)
Block(2,26,-2,planks:5)
Block(2,26,-1,planks)
Block(2,26,0,oak_stairs:7)
Block(2,27,-8,planks)
Block(2,27,-7,planks:5)
Block(2,27,-6,planks)
Block(2,27,-5,planks)
Block(2,27,-4,planks:5)
Block(2,27,-3,planks)
Block(2,27,-2,planks)
Block(2,27,-1,planks:5)
Block(2,27,0,planks)
Block(2,28,-8,planks)
Block(2,28,-7,planks)
Block(2,28,-6,planks)
Block(2,28,-5,planks)
Block(2,28,-4,wooden_slab:8)
Block(2,28,-3,planks)
Block(2,28,-2,planks)
Block(2,28,-1,planks)
Block(2,28,0,planks)
Block(2,29,-8,planks)
Block(2,29,-7,planks)
Block(2,29,-6,planks)
Block(2,29,-5,planks)
Block(2,29,-4,wooden_slab)
Block(2,29,-3,planks)
Block(2,29,-2,planks)
Block(2,29,-1,planks)
Block(2,29,0,planks)
Block(2,29,1,wall_banner:3,StructureNBT/SapphireCity/sap02/5-Banner.nbt)
Block(2,30,-8,oak_stairs:2)
Block(2,30,-7,planks)
Block(2,30,-6,planks)
Block(2,30,-5,ladder:4)
Block(2,30,-3,ladder:4)
Block(2,30,-2,planks)
Block(2,30,-1,planks)
Block(2,30,0,oak_STAIRS:0)
Block(2,31,-5,ladder:4)
Block(2,31,-3,ladder:4)
Block(2,32,-8,double_wooden_slab:5)
Block(2,32,-7,wooden_slab:5)
Block(2,32,-6,double_wooden_slab:5)
Block(2,32,-4,wooden_slab:5)
Block(2,32,-2,double_wooden_slab:5)
Block(2,32,-1,wooden_slab:5)
Block(2,32,0,double_wooden_slab:5)
Block(2,33,-8,cobblestone_wall)
Block(2,33,-6,oak_stairs:1)
Block(2,33,-2,oak_stairs:1)
Block(2,33,0,cobblestone_wall)
Block(2,34,0,fence)
Block(2,35,-1,fence)
Block(2,35,0,fence)
Block(2,36,-1,wool:15)
Block(2,36,0,fence)
Block(2,44,-3,wool:15)
Block(2,45,-3,wool:15)
Block(2,46,-3,wool:15)
Block(2,47,-4,wool)
Block(2,48,-4,fence)
Block(2,49,-4,fence)
Block(2,53,-8,wool:15)
Block(2,53,-7,wool:15)
Block(2,53,-6,wool)
Block(2,54,-8,wool:15)
Block(2,54,-6,wool:15)
Block(2,54,-5,wool)
Block(2,54,-4,wool)
Block(2,54,-3,wool)
Block(2,55,-4,wool)
Block(2,55,-3,wool:15)
Block(2,56,-5,wool:15)
Block(2,56,-4,wool:15)
Block(2,57,-6,wool:15)
Block(2,58,-8,wool:15)
Block(2,58,-7,wool:15)
Block(2,58,-4,fence)
Block(2,59,-4,fence)
Block(2,67,-2,wool:15)
Block(3,16,-4,planks:3)
Block(3,17,-4,planks:3)
Block(3,18,-4,planks:3)
Block(3,19,-4,planks:3)
Block(3,20,-5,planks:5)
Block(3,20,-4,planks:5)
Block(3,20,-3,planks:5)
Block(3,21,-5,planks:5)
Block(3,21,-4,planks:5)
Block(3,21,-3,planks:5)
Block(3,22,-6,planks:5)
Block(3,22,-5,air)
Block(3,22,-4,air)
Block(3,22,-3,air)
Block(3,22,-2,planks:5)
Block(3,23,-6,planks:5)
Block(3,23,-5,wooden_slab:3)
Block(3,23,-4,wooden_slab:3)
Block(3,23,-3,wooden_slab:3)
Block(3,23,-2,planks:5)
Block(3,24,-6,planks:5)
Block(3,24,-5,wooden_slab:11)
Block(3,24,-4,wooden_slab:11)
Block(3,24,-3,wooden_slab:11)
Block(3,24,-2,planks:5)
Block(3,25,-7,planks:5)
Block(3,25,-6,planks:5)
Block(3,25,-2,planks:5)
Block(3,25,-1,planks:5)
Block(3,26,-8,oak_stairs:6)
Block(3,26,-7,planks)
Block(3,26,-6,planks:5)
Block(3,26,-2,planks:5)
Block(3,26,-1,planks)
Block(3,26,0,oak_stairs:7)
Block(3,27,-8,planks:5)
Block(3,27,-7,planks)
Block(3,27,-6,planks)
Block(3,27,-5,planks)
Block(3,27,-4,planks:5)
Block(3,27,-3,planks)
Block(3,27,-2,planks)
Block(3,27,-1,planks)
Block(3,27,0,planks:5)
Block(3,28,-8,planks:5)
Block(3,28,-7,planks)
Block(3,28,-6,planks)
Block(3,28,-5,planks)
Block(3,28,-4,double_wooden_slab)
Block(3,28,-3,planks)
Block(3,28,-2,planks)
Block(3,28,-1,planks)
Block(3,28,0,planks:5)
Block(3,29,-8,planks:5)
Block(3,29,-7,planks)
Block(3,29,-6,planks)
Block(3,29,-5,planks)
Block(3,29,-3,planks)
Block(3,29,-2,planks)
Block(3,29,-1,planks)
Block(3,29,0,planks:5)
Block(3,30,-8,planks:5)
Block(3,30,-7,planks)
Block(3,30,-6,planks)
Block(3,30,-5,planks)
Block(3,30,-3,planks)
Block(3,30,-2,planks)
Block(3,30,-1,planks)
Block(3,30,0,planks:5)
Block(3,31,-8,oak_stairs:2)
Block(3,31,-7,cobblestone_wall)
Block(3,31,-5,planks)
Block(3,31,-3,planks)
Block(3,31,-1,cobblestone_wall)
Block(3,31,0,oak_STAIRS:0)
Block(3,32,-8,wooden_slab:5)
Block(3,32,-7,wooden_slab:5)
Block(3,32,-6,double_wooden_slab:5)
Block(3,32,-5,wooden_slab:5)
Block(3,32,-4,wooden_slab:5)
Block(3,32,-3,wooden_slab:5)
Block(3,32,-2,double_wooden_slab:5)
Block(3,32,-1,wooden_slab:5)
Block(3,32,0,wooden_slab:5)
Block(3,33,-8,stone_slab)
Block(3,33,0,stone_slab)
Block(3,38,-8,wool)
Block(3,38,-7,wool)
Block(3,39,-8,wool:15)
Block(3,39,-7,wool:15)
Block(3,39,-6,wool)
Block(3,40,-8,wool:15)
Block(3,47,-3,wool)
Block(3,48,-4,wool)
Block(3,49,-4,fence)
Block(3,50,-4,fence)
Block(3,52,-8,wool:15)
Block(3,52,-7,wool)
Block(3,52,-6,wool)
Block(3,53,-5,wool)
Block(3,53,-4,wool)
Block(3,53,-3,wool)
Block(3,54,-2,wool:15)
Block(3,55,-2,wool:15)
Block(3,55,-1,wool:15)
Block(3,56,-3,wool:15)
Block(3,56,-2,wool:15)
Block(3,56,-1,wool:15)
Block(3,56,0,wool:15)
Block(3,57,-5,wool:15)
Block(3,57,-4,wool:15)
Block(3,57,-3,wool)
Block(3,57,-2,wool:15)
Block(3,57,-1,wool:15)
Block(3,58,-6,wool:15)
Block(3,58,-5,wool:15)
Block(3,58,-4,wool:15)
Block(3,59,-8,wool)
Block(3,59,-7,wool:15)
Block(3,59,-6,wool)
Block(3,59,-4,fence)
Block(3,60,-4,fence)
Block(3,68,-3,wool:14)
Block(4,16,-4,planks:3)
Block(4,17,-4,planks:3)
Block(4,18,-5,planks:5)
Block(4,18,-4,planks:3)
Block(4,18,-3,planks:5)
Block(4,19,-5,planks:5)
Block(4,19,-4,planks:5)
Block(4,19,-3,planks:5)
Block(4,20,-5,planks:5)
Block(4,20,-4,air)
Block(4,20,-3,planks:5)
Block(4,21,-6,planks:5)
Block(4,21,-5,brick_block)
Block(4,21,-4,brick_block)
Block(4,21,-3,brick_block)
Block(4,21,-2,planks:5)
Block(4,22,-6,planks:5)
Block(4,22,-5,brick_block)
Block(4,22,-4,brick_block)
Block(4,22,-3,brick_block)
Block(4,22,-2,planks:5)
Block(4,23,-7,planks:5)
Block(4,23,-6,wooden_slab:3)
Block(4,23,-5,wooden_slab:3)
Block(4,23,-4,wooden_slab:3)
Block(4,23,-3,wooden_slab:3)
Block(4,23,-2,wooden_slab:3)
Block(4,23,-1,planks:5)
Block(4,24,-7,planks:5)
Block(4,24,-6,wooden_slab:3)
Block(4,24,-5,wooden_slab:3)
Block(4,24,-4,wooden_slab:3)
Block(4,24,-3,wooden_slab:3)
Block(4,24,-2,wooden_slab:3)
Block(4,24,-1,planks:5)
Block(4,25,-7,planks:5)
Block(4,25,-1,planks:5)
Block(4,26,-8,oak_stairs:6)
Block(4,26,-7,planks)
Block(4,26,-1,planks)
Block(4,26,0,oak_stairs:7)
Block(4,27,-8,planks)
Block(4,27,-7,planks)
Block(4,27,-6,planks)
Block(4,27,-5,planks)
Block(4,27,-4,planks)
Block(4,27,-3,planks)
Block(4,27,-2,planks)
Block(4,27,-1,planks)
Block(4,27,0,planks)
Block(4,28,-8,planks)
Block(4,28,-7,planks)
Block(4,28,-6,planks)
Block(4,28,-5,planks)
Block(4,28,-4,wooden_slab)
Block(4,28,-3,planks)
Block(4,28,-2,planks)
Block(4,28,-1,planks)
Block(4,28,0,planks)
Block(4,29,-8,planks)
Block(4,29,-7,planks)
Block(4,29,-6,planks)
Block(4,29,-5,planks)
Block(4,29,-3,planks)
Block(4,29,-2,planks)
Block(4,29,-1,planks)
Block(4,29,0,planks)
Block(4,29,1,wall_banner:3,StructureNBT/SapphireCity/sap02/6-Banner.nbt)
Block(4,30,-8,oak_stairs:2)
Block(4,30,-7,planks)
Block(4,30,-6,planks)
Block(4,30,-5,planks)
Block(4,30,-3,planks)
Block(4,30,-2,planks)
Block(4,30,-1,planks)
Block(4,30,0,oak_STAIRS:0)
Block(4,32,-8,double_wooden_slab:5)
Block(4,32,-7,wooden_slab:5)
Block(4,32,-6,wooden_slab:5)
Block(4,32,-5,wooden_slab:5)
Block(4,32,-4,wooden_slab:5)
Block(4,32,-3,wooden_slab:5)
Block(4,32,-2,wooden_slab:5)
Block(4,32,-1,wooden_slab:5)
Block(4,32,0,double_wooden_slab:5)
Block(4,33,-8,cobblestone_wall)
Block(4,33,0,cobblestone_wall)
Block(4,36,-8,wool)
Block(4,36,-7,wool)
Block(4,37,-8,wool)
Block(4,37,-7,wool)
Block(4,37,-6,wool)
Block(4,37,-5,wool)
Block(4,37,-4,wool)
Block(4,38,-6,wool)
Block(4,38,-5,wool)
Block(4,38,-4,wool)
Block(4,38,-3,wool)
Block(4,38,-2,wool)
Block(4,39,-5,wool)
Block(4,39,-4,wool)
Block(4,39,-3,wool)
Block(4,40,-7,wool:15)
Block(4,40,-6,wool:15)
Block(4,40,-5,wool:15)
Block(4,41,-8,wool:15)
Block(4,41,-7,wool:15)
Block(4,42,-8,wool:15)
Block(4,49,-4,wool)
Block(4,50,-4,fence)
Block(4,51,-4,fence)
Block(4,52,-5,wool)
Block(4,52,-4,wool)
Block(4,52,-3,wool)
Block(4,53,-2,wool)
Block(4,53,-1,wool)
Block(4,54,-1,wool)
Block(4,54,0,wool)
Block(4,54,1,wool)
Block(4,55,0,wool)
Block(4,55,1,wool)
Block(4,57,0,wool:15)
Block(4,58,-3,wool)
Block(4,58,-2,wool:15)
Block(4,58,-1,wool:15)
Block(4,58,0,wool:15)
Block(4,59,-5,wool)
Block(4,59,-4,wool)
Block(4,59,-3,wool)
Block(4,60,-8,log:8)
Block(4,60,-7,log:8)
Block(4,60,-6,log:8)
Block(4,60,-4,fence)
Block(4,61,-8,wooden_slab:5)
Block(4,61,-7,wooden_slab:5)
Block(4,61,-6,wooden_slab:5)
Block(4,61,-4,fence)
Block(4,68,-3,wool:14)
Block(5,16,-4,planks:3)
Block(5,17,-5,planks:5)
Block(5,17,-4,planks:3)
Block(5,17,-3,planks:5)
Block(5,18,-5,planks:5)
Block(5,18,-4,planks:5)
Block(5,18,-3,planks:5)
Block(5,19,-6,planks:5)
Block(5,19,-5,planks:5)
Block(5,19,-4,air)
Block(5,19,-3,planks:5)
Block(5,19,-2,planks:5)
Block(5,20,-6,planks:5)
Block(5,20,-5,brick_block)
Block(5,20,-4,brick_block)
Block(5,20,-3,brick_block)
Block(5,20,-2,planks:5)
Block(5,21,-6,planks:5)
Block(5,21,-5,brick_block)
Block(5,21,-4,brick_block)
Block(5,21,-3,brick_block)
Block(5,21,-2,planks:5)
Block(5,22,-7,planks:5)
Block(5,22,-6,brick_block)
Block(5,22,-5,brick_block)
Block(5,22,-4,brick_block)
Block(5,22,-3,brick_block)
Block(5,22,-2,brick_block)
Block(5,22,-1,planks:5)
Block(5,23,-7,planks:5)
Block(5,23,-6,double_wooden_slab:3)
Block(5,23,-5,double_wooden_slab:3)
Block(5,23,-4,double_wooden_slab:3)
Block(5,23,-3,double_wooden_slab:3)
Block(5,23,-2,double_wooden_slab:3)
Block(5,23,-1,planks:5)
Block(5,24,-7,planks:5)
Block(5,24,-1,planks:5)
Block(5,25,-7,planks)
Block(5,25,-1,planks)
Block(5,26,-7,dark_oak_stairs:5)
Block(5,26,-1,dark_oak_stairs:5)
Block(5,27,-7,planks:5)
Block(5,27,-6,planks)
Block(5,27,-5,planks)
Block(5,27,-4,double_wooden_slab)
Block(5,27,-3,planks)
Block(5,27,-2,planks)
Block(5,27,-1,planks:5)
Block(5,28,-7,planks:5)
Block(5,28,-6,planks)
Block(5,28,-5,planks)
Block(5,28,-3,planks)
Block(5,28,-2,planks)
Block(5,28,-1,planks:5)
Block(5,29,-8,wooden_slab:13)
Block(5,29,-7,planks)
Block(5,29,-6,planks)
Block(5,29,-5,planks)
Block(5,29,-3,planks)
Block(5,29,-2,planks)
Block(5,29,-1,planks)
Block(5,29,0,wooden_slab:13)
Block(5,30,-8,planks:5)
Block(5,30,-7,planks)
Block(5,30,-6,planks)
Block(5,30,-5,planks)
Block(5,30,-3,planks)
Block(5,30,-2,planks)
Block(5,30,-1,planks)
Block(5,30,0,planks:5)
Block(5,31,-8,oak_stairs:2)
Block(5,31,-7,cobblestone_wall)
Block(5,31,-5,cobblestone_wall)
Block(5,31,-3,cobblestone_wall)
Block(5,31,-1,cobblestone_wall)
Block(5,31,0,oak_STAIRS:0)
Block(5,32,-8,wooden_slab:5)
Block(5,32,-7,wooden_slab:5)
Block(5,32,-6,wooden_slab:5)
Block(5,32,-5,wooden_slab:5)
Block(5,32,-4,wooden_slab:5)
Block(5,32,-3,wooden_slab:5)
Block(5,32,-2,wooden_slab:5)
Block(5,32,-1,wooden_slab:5)
Block(5,32,0,wooden_slab:5)
Block(5,33,-8,stone_slab)
Block(5,33,0,stone_slab)
Block(5,35,-8,wool)
Block(5,35,-7,wool)
Block(5,36,-6,wool)
Block(5,36,-5,wool)
Block(5,36,-4,wool)
Block(5,36,-3,wool)
Block(5,36,-2,wool)
Block(5,37,-3,wool)
Block(5,37,-2,wool)
Block(5,37,-1,wool)
Block(5,37,0,wool)
Block(5,38,-1,wool)
Block(5,38,0,wool)
Block(5,38,1,wool)
Block(5,38,2,wool:15)
Block(5,39,-2,wool)
Block(5,39,-1,wool)
Block(5,39,0,wool)
Block(5,39,1,wool)
Block(5,40,-4,wool:15)
Block(5,40,-3,wool)
Block(5,40,-2,wool)
Block(5,40,-1,wool)
Block(5,41,-6,wool:15)
Block(5,41,-5,wool:15)
Block(5,41,-4,wool:15)
Block(5,41,-3,wool)
Block(5,41,-2,wool:15)
Block(5,42,-7,wool:15)
Block(5,42,-6,wool:15)
Block(5,42,-5,wool:15)
Block(5,42,-4,wool:15)
Block(5,43,-8,wool)
Block(5,43,-7,wool)
Block(5,43,-6,wool)
Block(5,43,-5,wool)
Block(5,51,-4,fence)
Block(5,52,-4,fence)
Block(5,52,-2,wool)
Block(5,52,-1,wool)
Block(5,52,0,wool)
Block(5,53,0,wool)
Block(5,53,1,wool)
Block(5,59,-2,wool)
Block(5,59,-1,wool:15)
Block(5,59,0,wool)
Block(5,59,1,wool)
Block(5,60,-5,log:8)
Block(5,60,-4,log:8)
Block(5,60,-3,log:8)
Block(5,61,-5,wooden_slab:5)
Block(5,61,-4,fence)
Block(5,61,-3,wooden_slab:5)
Block(5,62,-4,fence)
Block(5,68,-3,wool:15)
Block(5,69,-4,wool:15)
Block(6,16,-5,planks:5)
Block(6,16,-4,planks:3)
Block(6,16,-3,planks:5)
Block(6,17,-5,planks:5)
Block(6,17,-4,air)
Block(6,17,-3,planks:5)
Block(6,18,-6,planks:5)
Block(6,18,-5,brick_block)
Block(6,18,-4,brick_block)
Block(6,18,-3,brick_block)
Block(6,18,-2,planks:5)
Block(6,19,-6,planks:5)
Block(6,19,-5,brick_block)
Block(6,19,-4,brick_block)
Block(6,19,-3,brick_block)
Block(6,19,-2,planks:5)
Block(6,20,-7,planks:5)
Block(6,20,-6,brick_block)
Block(6,20,-5,brick_block)
Block(6,20,-4,brick_block)
Block(6,20,-3,brick_block)
Block(6,20,-2,brick_block)
Block(6,20,-1,planks:5)
Block(6,21,-7,planks:5)
Block(6,21,-6,brick_block)
Block(6,21,-5,air)
Block(6,21,-4,air)
Block(6,21,-3,air)
Block(6,21,-2,brick_block)
Block(6,21,-1,planks:5)
Block(6,22,-7,planks:5)
Block(6,22,-6,brick_block)
Block(6,22,-5,air)
Block(6,22,-4,air)
Block(6,22,-3,air)
Block(6,22,-2,brick_block)
Block(6,22,-1,planks:5)
Block(6,23,-7,planks:5)
Block(6,23,-6,double_wooden_slab:3)
Block(6,23,-5,brick_block)
Block(6,23,-4,brick_block)
Block(6,23,-3,brick_block)
Block(6,23,-2,double_wooden_slab:3)
Block(6,23,-1,planks:5)
Block(6,24,-7,planks:5)
Block(6,24,-5,brick_block)
Block(6,24,-4,brick_block)
Block(6,24,-3,brick_block)
Block(6,24,-1,planks:5)
Block(6,25,-7,planks)
Block(6,25,-5,brick_block)
Block(6,25,-4,brick_block)
Block(6,25,-3,brick_block)
Block(6,25,-1,planks)
Block(6,26,-7,wooden_slab:13)
Block(6,26,-6,wooden_slab:11)
Block(6,26,-5,double_wooden_slab:3)
Block(6,26,-4,double_wooden_slab)
Block(6,26,-3,double_wooden_slab:3)
Block(6,26,-2,wooden_slab:11)
Block(6,26,-1,wooden_slab:13)
Block(6,27,-7,planks)
Block(6,27,-6,planks)
Block(6,27,-5,planks:5)
Block(6,27,-4,wooden_slab)
Block(6,27,-3,planks:5)
Block(6,27,-2,planks)
Block(6,27,-1,planks)
Block(6,28,-7,planks)
Block(6,28,-6,planks)
Block(6,28,-5,planks:5)
Block(6,28,-3,planks:5)
Block(6,28,-2,planks)
Block(6,28,-1,planks)
Block(6,29,-8,dark_oak_stairs:6)
Block(6,29,-7,planks)
Block(6,29,-6,planks)
Block(6,29,-5,planks:5)
Block(6,29,-3,planks:5)
Block(6,29,-2,planks)
Block(6,29,-1,planks)
Block(6,29,0,dark_oak_stairs:7)
Block(6,30,-8,oak_stairs:2)
Block(6,30,-7,planks:5)
Block(6,30,-6,oak_stairs:1)
Block(6,30,-5,planks:5)
Block(6,30,-4,oak_stairs:1)
Block(6,30,-3,planks:5)
Block(6,30,-2,oak_stairs:1)
Block(6,30,-1,planks:5)
Block(6,30,0,oak_STAIRS:0)
Block(6,31,-7,oak_stairs:1)
Block(6,31,-5,oak_stairs:1)
Block(6,31,-3,oak_stairs:1)
Block(6,31,-1,oak_stairs:1)
Block(6,32,-7,wooden_slab:5)
Block(6,32,-6,double_wooden_slab:5)
Block(6,32,-5,wooden_slab:5)
Block(6,32,-4,double_wooden_slab:5)
Block(6,32,-3,wooden_slab:5)
Block(6,32,-2,double_wooden_slab:5)
Block(6,32,-1,wooden_slab:5)
Block(6,33,-7,stone_slab)
Block(6,33,-6,cobblestone_wall)
Block(6,33,-5,stone_slab)
Block(6,33,-4,cobblestone_wall)
Block(6,33,-3,stone_slab)
Block(6,33,-2,cobblestone_wall)
Block(6,33,-1,stone_slab)
Block(6,35,-6,wool)
Block(6,35,-5,wool)
Block(6,35,-4,wool)
Block(6,35,-3,wool)
Block(6,35,-2,wool)
Block(6,36,-1,wool)
Block(6,36,0,wool)
Block(6,36,1,wool)
Block(6,36,2,wool:15)
Block(6,37,1,wool)
Block(6,37,2,wool:15)
Block(6,37,3,wool:15)
Block(6,37,4,wool:15)
Block(6,38,3,wool:15)
Block(6,38,4,wool:15)
Block(6,38,5,wool)
Block(6,39,2,wool:15)
Block(6,39,3,wool:15)
Block(6,39,4,wool:15)
Block(6,40,0,wool)
Block(6,40,1,wool)
Block(6,40,2,wool)
Block(6,40,3,wool)
Block(6,41,-1,wool:15)
Block(6,41,0,wool:15)
Block(6,41,1,wool:15)
Block(6,41,2,wool:15)
Block(6,42,-3,wool:15)
Block(6,42,-2,wool:15)
Block(6,42,-1,wool:15)
Block(6,42,0,wool:15)
Block(6,42,1,wool:15)
Block(6,42,2,wool:15)
Block(6,43,-4,wool)
Block(6,43,-3,wool:15)
Block(6,43,-2,wool:15)
Block(6,44,-8,log:8)
Block(6,44,-7,log:8)
Block(6,45,-8,wooden_slab:5)
Block(6,45,-7,wooden_slab:5)
Block(6,52,-4,fence)
Block(6,52,1,wool)
Block(6,53,-4,fence)
Block(6,56,-4,dark_oak_stairs:4)
Block(6,57,-4,log)
Block(6,58,-4,log)
Block(6,59,-4,log)
Block(6,60,-4,log)
Block(6,60,-2,log:8)
Block(6,60,-1,log:8)
Block(6,60,0,log:8)
Block(6,60,1,wool)
Block(6,61,-4,log)
Block(6,61,-2,wooden_slab:5)
Block(6,61,-1,wooden_slab:5)
Block(6,61,0,wooden_slab:5)
Block(6,61,1,wooden_slab:5)
Block(6,62,-4,log)
Block(6,63,-4,log)
Block(6,64,-4,log)
Block(6,65,-4,cobblestone_wall)
Block(6,66,-4,cobblestone_wall)
Block(6,67,-4,dark_oak_fence)
Block(6,68,-4,dark_oak_fence)
Block(6,69,-4,dark_oak_fence)
Block(7,16,-5,planks:5)
Block(7,16,-4,planks:3)
Block(7,16,-3,planks:5)
Block(7,17,-6,planks:5)
Block(7,17,-5,air)
Block(7,17,-4,air)
Block(7,17,-3,air)
Block(7,17,-2,planks:5)
Block(7,18,-6,planks:5)
Block(7,18,-5,brick_block)
Block(7,18,-4,brick_block)
Block(7,18,-3,brick_block)
Block(7,18,-2,planks:5)
Block(7,19,-7,planks:5)
Block(7,19,-6,planks)
Block(7,19,-5,brick_block)
Block(7,19,-4,MAGMA)
Block(7,19,-3,brick_block)
Block(7,19,-2,planks)
Block(7,19,-1,planks:5)
Block(7,20,-8,planks:5)
Block(7,20,-7,planks:5)
Block(7,20,-6,brick_block)
Block(7,20,-5,brick_block)
Block(7,20,-4,AIR)
Block(7,20,-3,brick_block)
Block(7,20,-2,brick_block)
Block(7,20,-1,planks:5)
Block(7,20,0,planks:5)
Block(7,21,-8,planks:5)
Block(7,21,-7,planks:5)
Block(7,21,-6,brick_block)
Block(7,21,-5,air)
Block(7,21,-4,cauldron)
Block(7,21,-3,air)
Block(7,21,-2,crafting_table)
Block(7,21,-1,planks:5)
Block(7,21,0,planks:5)
Block(7,22,-8,planks:5)
Block(7,22,-7,planks:5)
Block(7,22,-6,brick_block)
Block(7,22,-5,air)
Block(7,22,-4,air)
Block(7,22,-3,air)
Block(7,22,-2,brick_block)
Block(7,22,-1,brick_block)
Block(7,22,0,planks:5)
Block(7,23,-7,planks:5)
Block(7,23,-6,double_wooden_slab:3)
Block(7,23,-5,brick_block)
Block(7,23,-3,brick_block)
Block(7,23,-2,double_wooden_slab:3)
Block(7,23,-1,planks:5)
Block(7,24,-7,planks:5)
Block(7,24,-5,brick_block)
Block(7,24,-3,brick_block)
Block(7,24,-1,planks:5)
Block(7,25,-7,planks)
Block(7,25,-5,brick_block)
Block(7,25,-4,brick_block)
Block(7,25,-3,brick_block)
Block(7,25,-1,planks)
Block(7,26,-7,dark_oak_stairs:4)
Block(7,26,-6,wooden_slab:11)
Block(7,26,-5,double_wooden_slab:3)
Block(7,26,-4,double_wooden_slab)
Block(7,26,-3,double_wooden_slab:3)
Block(7,26,-2,wooden_slab:11)
Block(7,26,-1,dark_oak_stairs:4)
Block(7,27,-7,planks)
Block(7,27,-6,hay_block:4)
RandomBlock(7,27,-2,CHEST,./StructureNBT/StructureLoot/JunkChest_1.nbt,20,CHEST,./StructureNBT/StructureLoot/JunkChest_2.nbt,15,CHEST,./StructureNBT/StructureLoot/JunkChest_3.nbt,15,CHEST,./StructureNBT/StructureLoot/JunkChest_4.nbt,15,CHEST,./StructureNBT/StructureLoot/JunkChest_5.nbt,15,CHEST,./StructureNBT/LoreStoryline/LoreGeneric_5.nbt,2,CHEST,./StructureNBT/LoreStoryline/LoreGeneric_4.nbt,2,CHEST,./StructureNBT/LoreStoryline/LoreGeneric_3.nbt,2,CHEST,./StructureNBT/LoreStoryline/LoreGeneric_2.nbt,2,CHEST,./StructureNBT/LoreStoryline/LoreGeneric_1.nbt,2,CHEST,./StructureNBT/LoreStoryline/LoreMedievalCity_5.nbt,3,CHEST,./StructureNBT/LoreStoryline/LoreMedievalCity_4.nbt,3,CHEST,./StructureNBT/LoreStoryline/LoreMedievalCity_3.nbt,3,CHEST,./StructureNBT/LoreStoryline/LoreMedievalCity_2.nbt,3,CHEST,./StructureNBT/LoreStoryline/LoreMedievalCity_1.nbt,3,CHEST,./StructureNBT/StructureLoot/Common1.nbt,3,CHEST,./StructureNBT/StructureLoot/Common2.nbt,3,CHEST,./StructureNBT/StructureLoot/Common3.nbt,3,CHEST,./StructureNBT/StructureLoot/Common4.nbt,3,CHEST,./StructureNBT/StructureLoot/Common5.nbt,3,CHEST,./StructureNBT/StructureLoot/Common5.nbt,3,CHEST,./StructureNBT/StructureLoot/Common6.nbt,3,CHEST,./StructureNBT/StructureLoot/Common7.nbt,3,CHEST,./StructureNBT/StructureLoot/Common8.nbt,3,CHEST,./StructureNBT/StructureLoot/Common9.nbt,3,CHEST,./StructureNBT/StructureLoot/Common10.nbt,3,CHEST,./StructureNBT/StructureLoot/Common11.nbt,3,CHEST,./StructureNBT/StructureLoot/Common12.nbt,3,CHEST,./StructureNBT/StructureLoot/Common13.nbt,3,CHEST,./StructureNBT/StructureLoot/Common14.nbt,3,CHEST,./StructureNBT/StructureLoot/Common15.nbt,3,CHEST,./StructureNBT/StructureLoot/Rare1.nbt,3,CHEST,./StructureNBT/StructureLoot/Rare2.nbt,3,CHEST,./StructureNBT/StructureLoot/Rare3.nbt,3,CHEST,./StructureNBT/StructureLoot/Rare4.nbt,3,CHEST,./StructureNBT/StructureLoot/Rare5.nbt,3,CHEST,./StructureNBT/StructureLoot/Rare6.nbt,3,CHEST,./StructureNBT/StructureLoot/Rare7.nbt,3,CHEST,./StructureNBT/StructureLoot/Rare8.nbt,3,CHEST,./StructureNBT/StructureLoot/Rare9.nbt,3,CHEST,./StructureNBT/StructureLoot/Rare10.nbt,3,CHEST,./StructureNBT/StructureLoot/Rare11.nbt,3,CHEST,./StructureNBT/StructureLoot/Rare12.nbt,3,CHEST,./StructureNBT/StructureLoot/Rare13.nbt,3,CHEST,./StructureNBT/StructureLoot/Rare14.nbt,3,CHEST,./StructureNBT/StructureLoot/Rare15.nbt,3,CHEST,./StructureNBT/StructureLoot/Epic1.nbt,3,CHEST,./StructureNBT/StructureLoot/Epic2.nbt,3,CHEST,./StructureNBT/StructureLoot/Epic3.nbt,3,CHEST,./StructureNBT/StructureLoot/Epic4.nbt,3,CHEST,./StructureNBT/StructureLoot/Epic5.nbt,3,CHEST,./StructureNBT/StructureLoot/Epic6.nbt,3,CHEST,./StructureNBT/StructureLoot/Epic7.nbt,3,CHEST,./StructureNBT/StructureLoot/Epic8.nbt,3,CHEST,./StructureNBT/StructureLoot/Epic9.nbt,3,CHEST,./StructureNBT/StructureLoot/Epic10.nbt,3,CHEST,./StructureNBT/StructureLoot/Epic11.nbt,3,CHEST,./StructureNBT/StructureLoot/Epic12.nbt,3,CHEST,./StructureNBT/StructureLoot/Epic13.nbt,3,CHEST,./StructureNBT/StructureLoot/Epic14.nbt,3,CHEST,./StructureNBT/StructureLoot/Epic15.nbt,100	)
Block(7,27,-1,planks)
Block(7,28,-7,planks)
Block(7,28,-6,hay_block:4)
Block(7,28,-1,planks)
Block(7,29,-7,dark_oak_stairs:1)
Block(7,29,-1,dark_oak_stairs:1)
Block(7,30,-5,wall_banner:5,StructureNBT/SapphireCity/sap02/8-Banner.nbt)
Block(7,30,-3,wall_banner:5,StructureNBT/SapphireCity/sap02/9-Banner.nbt)
Block(7,35,-1,wool)
Block(7,35,0,wool)
Block(7,35,1,wool)
Block(7,35,2,wool)
Block(7,36,3,wool:15)
Block(7,36,4,wool)
Block(7,36,5,wool)
Block(7,37,5,wool)
Block(7,38,6,wool)
Block(7,39,5,wool)
Block(7,40,4,wool)
Block(7,40,5,wool)
Block(7,41,3,wool:15)
Block(7,41,4,wool:15)
Block(7,42,3,wool:15)
Block(7,43,-1,wool)
Block(7,43,0,wool)
Block(7,43,1,wool:15)
Block(7,43,2,wool:15)
Block(7,44,-6,log:8)
Block(7,44,-5,log:8)
Block(7,44,-4,log:8)
Block(7,44,-3,log:8)
Block(7,44,-2,log:8)
Block(7,45,-6,wooden_slab:5)
Block(7,45,-5,wooden_slab:5)
Block(7,45,-4,wooden_slab:5)
Block(7,45,-3,wooden_slab:5)
Block(7,45,-2,wooden_slab:5)
Block(7,48,-4,dark_oak_stairs:4)
Block(7,49,-4,log)
Block(7,50,-4,log)
Block(7,51,-4,log)
Block(7,52,-4,log)
Block(7,52,2,wool)
Block(7,53,-4,log)
Block(7,54,-4,log)
Block(7,55,-4,log)
Block(7,56,-4,log)
Block(7,57,-4,log)
Block(7,58,-4,dark_oak_stairs:1)
Block(7,60,2,wool)
Block(7,62,-4,fence)

#######################################################################
# +-----------------------------------------------------------------+ #
# |                            BO3 checks                           | #
# +-----------------------------------------------------------------+ #
#######################################################################


#######################################################################
# +-----------------------------------------------------------------+ #
# |                             Branches                            | #
# +-----------------------------------------------------------------+ #
#######################################################################

Branch(-16,0,0,sap01,NORTH,100.0)
