
#######################################################################
# +-----------------------------------------------------------------+ #
# |                            BO3 object                           | #
# +-----------------------------------------------------------------+ #
#######################################################################

Author: NLBlackEagle

Description: No description given

Version: 3

SettingsMode: WriteDisable


#######################################################################
# +-----------------------------------------------------------------+ #
# |                          Main settings                          | #
# +-----------------------------------------------------------------+ #
#######################################################################

Tree: false

Frequency: 1

Rarity: 25.0

RotateRandomly: false

SpawnHeight: randomY

SpawnHeightOffset: 0

SpawnHeightVariance: 0

##############################
# Height Limits for the BO3. #
##############################

MinHeight: 47

MaxHeight: 47

######################
# Extrusion settings #
######################

ExtrudeMode: None

ExtrudeThroughBlocks: air

MaxBranchDepth: 60

ExcludedBiomes: All


#######################################################################
# +-----------------------------------------------------------------+ #
# |                      Source block settings                      | #
# +-----------------------------------------------------------------+ #
#######################################################################

SourceBlocks: air

MaxPercentageOutsideSourceBlock: 100

OutsideSourceBlock: placeAnyway


#######################################################################
# +-----------------------------------------------------------------+ #
# |                              Blocks                             | #
# +-----------------------------------------------------------------+ #
#######################################################################

Block(-8,21,-8,planks)
Block(-8,21,-7,planks)
Block(-8,21,-6,planks)
Block(-8,21,-5,planks)
Block(-8,21,-4,planks)
Block(-8,21,-3,planks)
Block(-8,21,-2,planks)
Block(-8,21,-1,planks)
Block(-8,21,0,planks)
Block(-8,21,1,planks)
Block(-8,21,2,planks)
Block(-8,21,3,planks)
Block(-8,21,4,planks)
Block(-8,21,5,planks)
Block(-8,21,6,planks)
Block(-8,21,7,planks)
Block(-8,22,-8,planks)
Block(-8,22,-7,crafting_table)
Block(-8,22,-6,hay_block)
Block(-8,22,-5,planks:5)
Block(-8,22,-4,hay_block)
Block(-8,22,-3,hay_block)
Block(-8,22,-2,hay_block:8)
Block(-8,22,-1,air)
Block(-8,22,0,planks:5)
Block(-8,22,1,air)
Block(-8,22,2,hay_block:4)
Block(-8,22,3,melon_block)
Block(-8,22,4,hay_block:4)
Block(-8,22,5,planks:5)
Block(-8,22,6,planks)
Block(-8,22,7,planks)
Block(-8,23,-8,hay_block:4)
Block(-8,23,-5,planks:5)
Block(-8,23,-2,pumpkin:3)
Block(-8,23,0,planks:5)
Block(-8,23,1,hay_block:4)
Block(-8,23,2,hay_block:4)
Block(-8,23,4,hay_block)
Block(-8,23,5,planks:5)
Block(-8,23,7,planks:5)
Block(-8,24,-8,wooden_slab:8)
Block(-8,24,-7,wooden_slab:8)
Block(-8,24,-6,wooden_slab:8)
Block(-8,24,-5,planks:5)
Block(-8,24,-4,oak_stairs:5)
Block(-8,24,-3,oak_stairs:5)
Block(-8,24,-2,oak_stairs:5)
Block(-8,24,-1,oak_stairs:5)
Block(-8,24,0,planks:5)
Block(-8,24,1,oak_stairs:5)
Block(-8,24,2,oak_stairs:5)
Block(-8,24,3,oak_stairs:5)
Block(-8,24,4,oak_stairs:5)
Block(-8,24,5,planks:5)
Block(-8,24,6,wooden_slab:8)
Block(-8,24,7,double_wooden_slab)
Block(-8,25,-8,planks)
Block(-8,25,-7,bed:0)
Block(-8,25,-6,bed:8)
Block(-8,25,-5,planks:5)
Block(-8,25,-4,hay_block:8)
Block(-8,25,-3,bed:0)
Block(-8,25,-2,bed:8)
RandomBlock(-8,25,-1,CHEST:5,./StructureNBT/StructureLoot/JunkChest_1.nbt,20,CHEST:5,./StructureNBT/StructureLoot/JunkChest_2.nbt,15,CHEST:5,./StructureNBT/StructureLoot/JunkChest_3.nbt,15,CHEST:5,./StructureNBT/StructureLoot/JunkChest_4.nbt,15,CHEST:5,./StructureNBT/StructureLoot/JunkChest_5.nbt,15,CHEST:5,./StructureNBT/LoreStoryline/LoreGeneric_5.nbt,2,CHEST:5,./StructureNBT/LoreStoryline/LoreGeneric_4.nbt,2,CHEST:5,./StructureNBT/LoreStoryline/LoreGeneric_3.nbt,2,CHEST:5,./StructureNBT/LoreStoryline/LoreGeneric_2.nbt,2,CHEST:5,./StructureNBT/LoreStoryline/LoreGeneric_1.nbt,2,CHEST:5,./StructureNBT/LoreStoryline/LoreMedievalCity_5.nbt,3,CHEST:5,./StructureNBT/LoreStoryline/LoreMedievalCity_4.nbt,3,CHEST:5,./StructureNBT/LoreStoryline/LoreMedievalCity_3.nbt,3,CHEST:5,./StructureNBT/LoreStoryline/LoreMedievalCity_2.nbt,3,CHEST:5,./StructureNBT/LoreStoryline/LoreMedievalCity_1.nbt,3,CHEST:5,./StructureNBT/StructureLoot/Common1.nbt,3,CHEST:5,./StructureNBT/StructureLoot/Common2.nbt,3,CHEST:5,./StructureNBT/StructureLoot/Common3.nbt,3,CHEST:5,./StructureNBT/StructureLoot/Common4.nbt,3,CHEST:5,./StructureNBT/StructureLoot/Common5.nbt,3,CHEST:5,./StructureNBT/StructureLoot/Common5.nbt,3,CHEST:5,./StructureNBT/StructureLoot/Common6.nbt,3,CHEST:5,./StructureNBT/StructureLoot/Common7.nbt,3,CHEST:5,./StructureNBT/StructureLoot/Common8.nbt,3,CHEST:5,./StructureNBT/StructureLoot/Common9.nbt,3,CHEST:5,./StructureNBT/StructureLoot/Common10.nbt,3,CHEST:5,./StructureNBT/StructureLoot/Common11.nbt,3,CHEST:5,./StructureNBT/StructureLoot/Common12.nbt,3,CHEST:5,./StructureNBT/StructureLoot/Common13.nbt,3,CHEST:5,./StructureNBT/StructureLoot/Common14.nbt,3,CHEST:5,./StructureNBT/StructureLoot/Common15.nbt,3,CHEST:5,./StructureNBT/StructureLoot/Rare1.nbt,3,CHEST:5,./StructureNBT/StructureLoot/Rare2.nbt,3,CHEST:5,./StructureNBT/StructureLoot/Rare3.nbt,3,CHEST:5,./StructureNBT/StructureLoot/Rare4.nbt,3,CHEST:5,./StructureNBT/StructureLoot/Rare5.nbt,3,CHEST:5,./StructureNBT/StructureLoot/Rare6.nbt,3,CHEST:5,./StructureNBT/StructureLoot/Rare7.nbt,3,CHEST:5,./StructureNBT/StructureLoot/Rare8.nbt,3,CHEST:5,./StructureNBT/StructureLoot/Rare9.nbt,3,CHEST:5,./StructureNBT/StructureLoot/Rare10.nbt,3,CHEST:5,./StructureNBT/StructureLoot/Rare11.nbt,3,CHEST:5,./StructureNBT/StructureLoot/Rare12.nbt,3,CHEST:5,./StructureNBT/StructureLoot/Rare13.nbt,3,CHEST:5,./StructureNBT/StructureLoot/Rare14.nbt,3,CHEST:5,./StructureNBT/StructureLoot/Rare15.nbt,3,CHEST:5,./StructureNBT/StructureLoot/Epic1.nbt,3,CHEST:5,./StructureNBT/StructureLoot/Epic2.nbt,3,CHEST:5,./StructureNBT/StructureLoot/Epic3.nbt,3,CHEST:5,./StructureNBT/StructureLoot/Epic4.nbt,3,CHEST:5,./StructureNBT/StructureLoot/Epic5.nbt,3,CHEST:5,./StructureNBT/StructureLoot/Epic6.nbt,3,CHEST:5,./StructureNBT/StructureLoot/Epic7.nbt,3,CHEST:5,./StructureNBT/StructureLoot/Epic8.nbt,3,CHEST:5,./StructureNBT/StructureLoot/Epic9.nbt,3,CHEST:5,./StructureNBT/StructureLoot/Epic10.nbt,3,CHEST:5,./StructureNBT/StructureLoot/Epic11.nbt,3,CHEST:5,./StructureNBT/StructureLoot/Epic12.nbt,3,CHEST:5,./StructureNBT/StructureLoot/Epic13.nbt,3,CHEST:5,./StructureNBT/StructureLoot/Epic14.nbt,3,CHEST:5,./StructureNBT/StructureLoot/Epic15.nbt,100)
Block(-8,25,0,planks:5)
Block(-8,25,1,hay_block:4)
RandomBlock(-8,25,2,CHEST:5,./StructureNBT/StructureLoot/JunkChest_1.nbt,20,CHEST:5,./StructureNBT/StructureLoot/JunkChest_2.nbt,15,CHEST:5,./StructureNBT/StructureLoot/JunkChest_3.nbt,15,CHEST:5,./StructureNBT/StructureLoot/JunkChest_4.nbt,15,CHEST:5,./StructureNBT/StructureLoot/JunkChest_5.nbt,15,CHEST:5,./StructureNBT/LoreStoryline/LoreGeneric_5.nbt,2,CHEST:5,./StructureNBT/LoreStoryline/LoreGeneric_4.nbt,2,CHEST:5,./StructureNBT/LoreStoryline/LoreGeneric_3.nbt,2,CHEST:5,./StructureNBT/LoreStoryline/LoreGeneric_2.nbt,2,CHEST:5,./StructureNBT/LoreStoryline/LoreGeneric_1.nbt,2,CHEST:5,./StructureNBT/LoreStoryline/LoreMedievalCity_5.nbt,3,CHEST:5,./StructureNBT/LoreStoryline/LoreMedievalCity_4.nbt,3,CHEST:5,./StructureNBT/LoreStoryline/LoreMedievalCity_3.nbt,3,CHEST:5,./StructureNBT/LoreStoryline/LoreMedievalCity_2.nbt,3,CHEST:5,./StructureNBT/LoreStoryline/LoreMedievalCity_1.nbt,3,CHEST:5,./StructureNBT/StructureLoot/Common1.nbt,3,CHEST:5,./StructureNBT/StructureLoot/Common2.nbt,3,CHEST:5,./StructureNBT/StructureLoot/Common3.nbt,3,CHEST:5,./StructureNBT/StructureLoot/Common4.nbt,3,CHEST:5,./StructureNBT/StructureLoot/Common5.nbt,3,CHEST:5,./StructureNBT/StructureLoot/Common5.nbt,3,CHEST:5,./StructureNBT/StructureLoot/Common6.nbt,3,CHEST:5,./StructureNBT/StructureLoot/Common7.nbt,3,CHEST:5,./StructureNBT/StructureLoot/Common8.nbt,3,CHEST:5,./StructureNBT/StructureLoot/Common9.nbt,3,CHEST:5,./StructureNBT/StructureLoot/Common10.nbt,3,CHEST:5,./StructureNBT/StructureLoot/Common11.nbt,3,CHEST:5,./StructureNBT/StructureLoot/Common12.nbt,3,CHEST:5,./StructureNBT/StructureLoot/Common13.nbt,3,CHEST:5,./StructureNBT/StructureLoot/Common14.nbt,3,CHEST:5,./StructureNBT/StructureLoot/Common15.nbt,3,CHEST:5,./StructureNBT/StructureLoot/Rare1.nbt,3,CHEST:5,./StructureNBT/StructureLoot/Rare2.nbt,3,CHEST:5,./StructureNBT/StructureLoot/Rare3.nbt,3,CHEST:5,./StructureNBT/StructureLoot/Rare4.nbt,3,CHEST:5,./StructureNBT/StructureLoot/Rare5.nbt,3,CHEST:5,./StructureNBT/StructureLoot/Rare6.nbt,3,CHEST:5,./StructureNBT/StructureLoot/Rare7.nbt,3,CHEST:5,./StructureNBT/StructureLoot/Rare8.nbt,3,CHEST:5,./StructureNBT/StructureLoot/Rare9.nbt,3,CHEST:5,./StructureNBT/StructureLoot/Rare10.nbt,3,CHEST:5,./StructureNBT/StructureLoot/Rare11.nbt,3,CHEST:5,./StructureNBT/StructureLoot/Rare12.nbt,3,CHEST:5,./StructureNBT/StructureLoot/Rare13.nbt,3,CHEST:5,./StructureNBT/StructureLoot/Rare14.nbt,3,CHEST:5,./StructureNBT/StructureLoot/Rare15.nbt,3,CHEST:5,./StructureNBT/StructureLoot/Epic1.nbt,3,CHEST:5,./StructureNBT/StructureLoot/Epic2.nbt,3,CHEST:5,./StructureNBT/StructureLoot/Epic3.nbt,3,CHEST:5,./StructureNBT/StructureLoot/Epic4.nbt,3,CHEST:5,./StructureNBT/StructureLoot/Epic5.nbt,3,CHEST:5,./StructureNBT/StructureLoot/Epic6.nbt,3,CHEST:5,./StructureNBT/StructureLoot/Epic7.nbt,3,CHEST:5,./StructureNBT/StructureLoot/Epic8.nbt,3,CHEST:5,./StructureNBT/StructureLoot/Epic9.nbt,3,CHEST:5,./StructureNBT/StructureLoot/Epic10.nbt,3,CHEST:5,./StructureNBT/StructureLoot/Epic11.nbt,3,CHEST:5,./StructureNBT/StructureLoot/Epic12.nbt,3,CHEST:5,./StructureNBT/StructureLoot/Epic13.nbt,3,CHEST:5,./StructureNBT/StructureLoot/Epic14.nbt,3,CHEST:5,./StructureNBT/StructureLoot/Epic15.nbt,100)
Block(-8,25,3,bed:0)
Block(-8,25,4,bed:8)
Block(-8,25,5,planks:5)
Block(-8,25,7,planks)
Block(-8,26,-8,planks)
Block(-8,26,-7,planks)
Block(-8,26,-6,planks)
Block(-8,26,-5,planks)
Block(-8,26,-4,hay_block:4)
Block(-8,26,0,planks:5)
Block(-8,26,3,planks)
Block(-8,26,4,planks)
Block(-8,26,5,planks)
Block(-8,26,6,planks)
Block(-8,26,7,planks)
Block(-8,27,-7,oak_stairs:4)
Block(-8,27,-6,planks:5)
Block(-8,27,-5,planks:5)
Block(-8,27,-4,planks:5)
Block(-8,27,-3,planks:5)
Block(-8,27,-2,planks:5)
Block(-8,27,-1,planks:5)
Block(-8,27,0,planks:5)
Block(-8,27,1,planks:5)
Block(-8,27,2,planks:5)
Block(-8,27,3,planks:5)
Block(-8,27,4,planks:5)
Block(-8,27,5,oak_stairs:4)
Block(-8,27,6,oak_stairs:4)
Block(-8,27,7,oak_stairs:4)
Block(-8,28,-7,spruce_fence)
Block(-8,28,-6,spruce_fence)
Block(-8,28,-5,spruce_fence)
Block(-8,28,-4,spruce_fence)
Block(-8,28,5,spruce_fence)
Block(-8,28,6,spruce_fence)
Block(-8,28,7,spruce_fence)
Block(-8,29,-7,spruce_fence)
Block(-8,29,-6,spruce_fence)
Block(-8,29,-5,spruce_fence)
Block(-8,29,-4,spruce_fence)
Block(-8,29,1,fence)
Block(-8,29,2,fence)
Block(-8,29,5,spruce_fence)
Block(-8,29,6,spruce_fence)
Block(-8,29,7,spruce_fence)
Block(-8,30,-7,wooden_slab:13)
Block(-8,30,5,spruce_fence)
Block(-8,30,6,wooden_slab:13)
Block(-8,30,7,wooden_slab:13)
Block(-8,31,-7,wool)
Block(-8,31,6,wool)
Block(-8,31,7,fence)
Block(-8,32,-8,wool)
Block(-8,32,-7,wooden_slab:5)
Block(-8,32,4,wool:15)
Block(-8,32,5,wool:15)
Block(-8,32,6,wooden_slab:5)
Block(-8,32,7,wooden_slab:5)
Block(-8,33,4,wool:15)
Block(-8,34,4,wool:15)
Block(-8,35,3,wool:15)
Block(-8,36,3,wool)
Block(-8,37,3,wool)
Block(-8,38,3,wool)
Block(-8,39,3,wool)
Block(-8,40,4,wool)
Block(-8,41,4,wool)
Block(-8,41,5,fence)
Block(-8,42,5,log:5)
Block(-8,43,5,wooden_slab:5)
Block(-8,45,3,wool)
Block(-8,45,4,wool)
Block(-8,46,3,wool)
Block(-8,46,4,wooden_slab:5)
Block(-8,47,2,wool)
Block(-8,48,-8,fence)
Block(-8,48,2,wool:15)
Block(-8,49,-8,log:5)
Block(-8,49,2,wool:15)
Block(-8,50,-8,wooden_slab:5)
Block(-8,50,2,wool:15)
Block(-8,51,2,wool:15)
Block(-8,52,3,wool:15)
Block(-8,52,4,fence)
Block(-8,53,4,log:5)
Block(-8,54,4,wooden_slab:5)
Block(-8,63,4,wool:15)
Block(-8,65,-8,wool:15)
Block(-7,20,-8,planks)
Block(-7,20,-7,planks)
Block(-7,20,-6,planks)
Block(-7,20,-5,planks)
Block(-7,20,-4,planks)
Block(-7,20,-3,planks)
Block(-7,20,-2,planks)
Block(-7,20,-1,planks)
Block(-7,20,0,planks)
Block(-7,20,1,planks)
Block(-7,20,2,planks)
Block(-7,20,3,planks)
Block(-7,20,4,planks)
Block(-7,20,5,planks)
Block(-7,20,6,planks)
Block(-7,20,7,planks)
Block(-7,21,-8,hay_block)
Block(-7,21,-7,hay_block)
Block(-7,21,-6,crafting_table)
Block(-7,21,-5,planks:5)
Block(-7,21,-4,pumpkin:3)
Block(-7,21,-3,melon_block)
Block(-7,21,-2,air)
Block(-7,21,-1,air)
Block(-7,21,0,planks:5)
Block(-7,21,1,hay_block:8)
Block(-7,21,2,hay_block)
Block(-7,21,3,hay_block:4)
Block(-7,21,4,hay_block:8)
Block(-7,21,5,planks:5)
Block(-7,21,6,hay_block)
Block(-7,21,7,air)
Block(-7,22,-8,hay_block)
Block(-7,22,-7,hay_block)
Block(-7,22,-6,hay_block:8)
Block(-7,22,-5,dark_oak_stairs:1)
Block(-7,22,-4,crafting_table)
Block(-7,22,-3,crafting_table)
Block(-7,22,-2,hay_block:4)
Block(-7,22,-1,air)
Block(-7,22,0,dark_oak_stairs:1)
Block(-7,22,1,pumpkin:3)
Block(-7,22,2,hay_block:4)
Block(-7,22,3,melon_block)
Block(-7,22,4,hay_block:8)
Block(-7,22,5,dark_oak_stairs:1)
Block(-7,22,6,air)
Block(-7,22,7,air)
Block(-7,23,-6,melon_block)
Block(-7,23,4,hay_block)
Block(-7,24,-8,wooden_slab:8)
Block(-7,24,-7,wooden_slab:8)
Block(-7,24,-6,wooden_slab:8)
Block(-7,24,-5,wooden_slab:8)
Block(-7,24,5,wooden_slab:8)
Block(-7,24,6,wooden_slab:8)
Block(-7,24,7,wooden_slab:8)
Block(-7,25,-8,bed)
RandomBlock(-7,25,-7,CHEST:3,./StructureNBT/StructureLoot/JunkChest_1.nbt,20,CHEST:3,./StructureNBT/StructureLoot/JunkChest_2.nbt,15,CHEST:3,./StructureNBT/StructureLoot/JunkChest_3.nbt,15,CHEST:3,./StructureNBT/StructureLoot/JunkChest_4.nbt,15,CHEST:3,./StructureNBT/StructureLoot/JunkChest_5.nbt,15,CHEST:3,./StructureNBT/LoreStoryline/LoreGeneric_5.nbt,2,CHEST:3,./StructureNBT/LoreStoryline/LoreGeneric_4.nbt,2,CHEST:3,./StructureNBT/LoreStoryline/LoreGeneric_3.nbt,2,CHEST:3,./StructureNBT/LoreStoryline/LoreGeneric_2.nbt,2,CHEST:3,./StructureNBT/LoreStoryline/LoreGeneric_1.nbt,2,CHEST:3,./StructureNBT/LoreStoryline/LoreMedievalCity_5.nbt,3,CHEST:3,./StructureNBT/LoreStoryline/LoreMedievalCity_4.nbt,3,CHEST:3,./StructureNBT/LoreStoryline/LoreMedievalCity_3.nbt,3,CHEST:3,./StructureNBT/LoreStoryline/LoreMedievalCity_2.nbt,3,CHEST:3,./StructureNBT/LoreStoryline/LoreMedievalCity_1.nbt,3,CHEST:3,./StructureNBT/StructureLoot/Common1.nbt,3,CHEST:3,./StructureNBT/StructureLoot/Common2.nbt,3,CHEST:3,./StructureNBT/StructureLoot/Common3.nbt,3,CHEST:3,./StructureNBT/StructureLoot/Common4.nbt,3,CHEST:3,./StructureNBT/StructureLoot/Common5.nbt,3,CHEST:3,./StructureNBT/StructureLoot/Common5.nbt,3,CHEST:3,./StructureNBT/StructureLoot/Common6.nbt,3,CHEST:3,./StructureNBT/StructureLoot/Common7.nbt,3,CHEST:3,./StructureNBT/StructureLoot/Common8.nbt,3,CHEST:3,./StructureNBT/StructureLoot/Common9.nbt,3,CHEST:3,./StructureNBT/StructureLoot/Common10.nbt,3,CHEST:3,./StructureNBT/StructureLoot/Common11.nbt,3,CHEST:3,./StructureNBT/StructureLoot/Common12.nbt,3,CHEST:3,./StructureNBT/StructureLoot/Common13.nbt,3,CHEST:3,./StructureNBT/StructureLoot/Common14.nbt,3,CHEST:3,./StructureNBT/StructureLoot/Common15.nbt,3,CHEST:3,./StructureNBT/StructureLoot/Rare1.nbt,3,CHEST:3,./StructureNBT/StructureLoot/Rare2.nbt,3,CHEST:3,./StructureNBT/StructureLoot/Rare3.nbt,3,CHEST:3,./StructureNBT/StructureLoot/Rare4.nbt,3,CHEST:3,./StructureNBT/StructureLoot/Rare5.nbt,3,CHEST:3,./StructureNBT/StructureLoot/Rare6.nbt,3,CHEST:3,./StructureNBT/StructureLoot/Rare7.nbt,3,CHEST:3,./StructureNBT/StructureLoot/Rare8.nbt,3,CHEST:3,./StructureNBT/StructureLoot/Rare9.nbt,3,CHEST:3,./StructureNBT/StructureLoot/Rare10.nbt,3,CHEST:3,./StructureNBT/StructureLoot/Rare11.nbt,3,CHEST:3,./StructureNBT/StructureLoot/Rare12.nbt,3,CHEST:3,./StructureNBT/StructureLoot/Rare13.nbt,3,CHEST:3,./StructureNBT/StructureLoot/Rare14.nbt,3,CHEST:3,./StructureNBT/StructureLoot/Rare15.nbt,3,CHEST:3,./StructureNBT/StructureLoot/Epic1.nbt,3,CHEST:3,./StructureNBT/StructureLoot/Epic2.nbt,3,CHEST:3,./StructureNBT/StructureLoot/Epic3.nbt,3,CHEST:3,./StructureNBT/StructureLoot/Epic4.nbt,3,CHEST:3,./StructureNBT/StructureLoot/Epic5.nbt,3,CHEST:3,./StructureNBT/StructureLoot/Epic6.nbt,3,CHEST:3,./StructureNBT/StructureLoot/Epic7.nbt,3,CHEST:3,./StructureNBT/StructureLoot/Epic8.nbt,3,CHEST:3,./StructureNBT/StructureLoot/Epic9.nbt,3,CHEST:3,./StructureNBT/StructureLoot/Epic10.nbt,3,CHEST:3,./StructureNBT/StructureLoot/Epic11.nbt,3,CHEST:3,./StructureNBT/StructureLoot/Epic12.nbt,3,CHEST:3,./StructureNBT/StructureLoot/Epic13.nbt,3,CHEST:3,./StructureNBT/StructureLoot/Epic14.nbt,3,CHEST:3,./StructureNBT/StructureLoot/Epic15.nbt,100)
Block(-7,25,-5,dark_oak_stairs:5)
Block(-7,25,5,dark_oak_stairs:5)
Block(-7,25,6,hay_block)
Block(-7,25,7,hay_block)
Block(-7,26,-5,planks:5)
Block(-7,26,0,dark_oak_stairs:5)
Block(-7,26,5,planks:5)
RandomBlock(-7,26,7,CHEST:5,./StructureNBT/StructureLoot/JunkChest_1.nbt,20,CHEST:5,./StructureNBT/StructureLoot/JunkChest_2.nbt,15,CHEST:5,./StructureNBT/StructureLoot/JunkChest_3.nbt,15,CHEST:5,./StructureNBT/StructureLoot/JunkChest_4.nbt,15,CHEST:5,./StructureNBT/StructureLoot/JunkChest_5.nbt,15,CHEST:5,./StructureNBT/LoreStoryline/LoreGeneric_5.nbt,2,CHEST:5,./StructureNBT/LoreStoryline/LoreGeneric_4.nbt,2,CHEST:5,./StructureNBT/LoreStoryline/LoreGeneric_3.nbt,2,CHEST:5,./StructureNBT/LoreStoryline/LoreGeneric_2.nbt,2,CHEST:5,./StructureNBT/LoreStoryline/LoreGeneric_1.nbt,2,CHEST:5,./StructureNBT/LoreStoryline/LoreMedievalCity_5.nbt,3,CHEST:5,./StructureNBT/LoreStoryline/LoreMedievalCity_4.nbt,3,CHEST:5,./StructureNBT/LoreStoryline/LoreMedievalCity_3.nbt,3,CHEST:5,./StructureNBT/LoreStoryline/LoreMedievalCity_2.nbt,3,CHEST:5,./StructureNBT/LoreStoryline/LoreMedievalCity_1.nbt,3,CHEST:5,./StructureNBT/StructureLoot/Common1.nbt,3,CHEST:5,./StructureNBT/StructureLoot/Common2.nbt,3,CHEST:5,./StructureNBT/StructureLoot/Common3.nbt,3,CHEST:5,./StructureNBT/StructureLoot/Common4.nbt,3,CHEST:5,./StructureNBT/StructureLoot/Common5.nbt,3,CHEST:5,./StructureNBT/StructureLoot/Common5.nbt,3,CHEST:5,./StructureNBT/StructureLoot/Common6.nbt,3,CHEST:5,./StructureNBT/StructureLoot/Common7.nbt,3,CHEST:5,./StructureNBT/StructureLoot/Common8.nbt,3,CHEST:5,./StructureNBT/StructureLoot/Common9.nbt,3,CHEST:5,./StructureNBT/StructureLoot/Common10.nbt,3,CHEST:5,./StructureNBT/StructureLoot/Common11.nbt,3,CHEST:5,./StructureNBT/StructureLoot/Common12.nbt,3,CHEST:5,./StructureNBT/StructureLoot/Common13.nbt,3,CHEST:5,./StructureNBT/StructureLoot/Common14.nbt,3,CHEST:5,./StructureNBT/StructureLoot/Common15.nbt,3,CHEST:5,./StructureNBT/StructureLoot/Rare1.nbt,3,CHEST:5,./StructureNBT/StructureLoot/Rare2.nbt,3,CHEST:5,./StructureNBT/StructureLoot/Rare3.nbt,3,CHEST:5,./StructureNBT/StructureLoot/Rare4.nbt,3,CHEST:5,./StructureNBT/StructureLoot/Rare5.nbt,3,CHEST:5,./StructureNBT/StructureLoot/Rare6.nbt,3,CHEST:5,./StructureNBT/StructureLoot/Rare7.nbt,3,CHEST:5,./StructureNBT/StructureLoot/Rare8.nbt,3,CHEST:5,./StructureNBT/StructureLoot/Rare9.nbt,3,CHEST:5,./StructureNBT/StructureLoot/Rare10.nbt,3,CHEST:5,./StructureNBT/StructureLoot/Rare11.nbt,3,CHEST:5,./StructureNBT/StructureLoot/Rare12.nbt,3,CHEST:5,./StructureNBT/StructureLoot/Rare13.nbt,3,CHEST:5,./StructureNBT/StructureLoot/Rare14.nbt,3,CHEST:5,./StructureNBT/StructureLoot/Rare15.nbt,3,CHEST:5,./StructureNBT/StructureLoot/Epic1.nbt,3,CHEST:5,./StructureNBT/StructureLoot/Epic2.nbt,3,CHEST:5,./StructureNBT/StructureLoot/Epic3.nbt,3,CHEST:5,./StructureNBT/StructureLoot/Epic4.nbt,3,CHEST:5,./StructureNBT/StructureLoot/Epic5.nbt,3,CHEST:5,./StructureNBT/StructureLoot/Epic6.nbt,3,CHEST:5,./StructureNBT/StructureLoot/Epic7.nbt,3,CHEST:5,./StructureNBT/StructureLoot/Epic8.nbt,3,CHEST:5,./StructureNBT/StructureLoot/Epic9.nbt,3,CHEST:5,./StructureNBT/StructureLoot/Epic10.nbt,3,CHEST:5,./StructureNBT/StructureLoot/Epic11.nbt,3,CHEST:5,./StructureNBT/StructureLoot/Epic12.nbt,3,CHEST:5,./StructureNBT/StructureLoot/Epic13.nbt,3,CHEST:5,./StructureNBT/StructureLoot/Epic14.nbt,3,CHEST:5,./StructureNBT/StructureLoot/Epic15.nbt,100)
Block(-7,27,-8,planks:5)
Block(-7,27,-7,planks:5)
Block(-7,27,-6,wooden_slab:11)
Block(-7,27,-5,planks:5)
Block(-7,27,-4,wooden_slab:11)
Block(-7,27,-3,wooden_slab:11)
Block(-7,27,-2,wooden_slab:11)
Block(-7,27,-1,wooden_slab:11)
Block(-7,27,0,planks:5)
Block(-7,27,1,wooden_slab:11)
Block(-7,27,2,wooden_slab:11)
Block(-7,27,3,wooden_slab:11)
Block(-7,27,4,wooden_slab:11)
Block(-7,27,5,planks:5)
Block(-7,27,6,planks:5)
Block(-7,27,7,planks:5)
Block(-7,28,-7,planks:5)
Block(-7,28,-6,planks:5)
Block(-7,28,-5,planks:5)
Block(-7,28,-4,planks:5)
Block(-7,28,-3,planks:5)
Block(-7,28,-2,planks:5)
Block(-7,28,-1,planks:5)
Block(-7,28,0,planks:5)
Block(-7,28,1,planks:5)
Block(-7,28,2,planks:5)
Block(-7,28,3,planks:5)
Block(-7,28,4,planks:5)
Block(-7,28,5,planks:5)
Block(-7,28,6,planks:5)
Block(-7,28,7,planks:5)
Block(-7,29,-7,spruce_fence)
Block(-7,29,-6,spruce_fence)
Block(-7,29,-5,spruce_fence)
Block(-7,29,-4,spruce_fence)
Block(-7,29,2,fence)
Block(-7,29,5,spruce_fence)
Block(-7,29,6,spruce_fence)
Block(-7,29,7,spruce_fence)
Block(-7,30,-7,spruce_fence)
Block(-7,30,-6,spruce_fence)
Block(-7,30,-5,spruce_fence)
Block(-7,30,-4,spruce_fence)
Block(-7,30,5,spruce_fence)
Block(-7,30,6,spruce_fence)
Block(-7,30,7,spruce_fence)
Block(-7,31,-7,wool)
Block(-7,31,-6,spruce_fence)
Block(-7,31,-5,spruce_fence)
Block(-7,31,-4,spruce_fence)
Block(-7,31,5,spruce_fence)
Block(-7,31,6,wool)
Block(-7,31,7,spruce_fence)
Block(-7,32,-8,wool)
Block(-7,32,-7,wooden_slab:5)
Block(-7,32,-6,spruce_fence)
Block(-7,32,-5,spruce_fence)
Block(-7,32,4,wool:15)
Block(-7,32,5,wool)
Block(-7,32,6,wooden_slab:5)
Block(-7,32,7,spruce_fence)
Block(-7,33,4,wool:15)
Block(-7,34,3,wool:15)
Block(-7,35,3,wool:15)
Block(-7,36,2,wool)
Block(-7,37,2,wool)
Block(-7,38,3,wool:15)
Block(-7,39,3,wool:15)
Block(-7,40,3,wool:15)
Block(-7,41,4,wool)
Block(-7,41,5,fence)
Block(-7,42,5,log:5)
Block(-7,43,5,wooden_slab:5)
Block(-7,46,2,wool)
Block(-7,46,3,wool)
Block(-7,47,2,wool:15)
Block(-7,48,-8,fence)
Block(-7,48,1,wool:15)
Block(-7,49,-8,log:5)
Block(-7,49,1,wool)
Block(-7,50,-8,wooden_slab:5)
Block(-7,50,2,wool)
Block(-7,51,2,wool)
Block(-7,52,3,wool)
Block(-7,52,4,fence)
Block(-7,53,4,log:5)
Block(-7,54,4,wooden_slab:5)
Block(-7,64,3,wool:15)
Block(-7,65,-8,wool:14)
Block(-6,19,-8,planks)
Block(-6,19,-7,planks)
Block(-6,19,-6,planks)
Block(-6,19,-5,planks)
Block(-6,19,-4,planks)
Block(-6,19,-3,planks)
Block(-6,19,-2,planks)
Block(-6,19,-1,planks)
Block(-6,19,0,planks)
Block(-6,19,1,planks)
Block(-6,19,2,planks)
Block(-6,19,3,planks)
Block(-6,19,4,planks)
Block(-6,19,5,planks)
Block(-6,19,6,planks)
Block(-6,19,7,planks)
Block(-6,20,-8,hay_block:4)
Block(-6,20,-7,hay_block)
Block(-6,20,-6,hay_block)
Block(-6,20,-5,planks:5)
Block(-6,20,-4,hay_block)
Block(-6,20,-3,melon_block)
Block(-6,20,-2,hay_block)
Block(-6,20,-1,hay_block:8)
Block(-6,20,0,planks:5)
Block(-6,20,1,crafting_table)
Block(-6,20,2,hay_block:4)
Block(-6,20,3,hay_block)
Block(-6,20,4,hay_block:4)
Block(-6,20,5,planks:5)
Block(-6,20,6,hay_block:8)
Block(-6,20,7,hay_block)
RandomBlock(-6,21,-8,CHEST:3,./StructureNBT/StructureLoot/JunkChest_1.nbt,20,CHEST:3,./StructureNBT/StructureLoot/JunkChest_2.nbt,15,CHEST:3,./StructureNBT/StructureLoot/JunkChest_3.nbt,15,CHEST:3,./StructureNBT/StructureLoot/JunkChest_4.nbt,15,CHEST:3,./StructureNBT/StructureLoot/JunkChest_5.nbt,15,CHEST:3,./StructureNBT/LoreStoryline/LoreGeneric_5.nbt,2,CHEST:3,./StructureNBT/LoreStoryline/LoreGeneric_4.nbt,2,CHEST:3,./StructureNBT/LoreStoryline/LoreGeneric_3.nbt,2,CHEST:3,./StructureNBT/LoreStoryline/LoreGeneric_2.nbt,2,CHEST:3,./StructureNBT/LoreStoryline/LoreGeneric_1.nbt,2,CHEST:3,./StructureNBT/LoreStoryline/LoreMedievalCity_5.nbt,3,CHEST:3,./StructureNBT/LoreStoryline/LoreMedievalCity_4.nbt,3,CHEST:3,./StructureNBT/LoreStoryline/LoreMedievalCity_3.nbt,3,CHEST:3,./StructureNBT/LoreStoryline/LoreMedievalCity_2.nbt,3,CHEST:3,./StructureNBT/LoreStoryline/LoreMedievalCity_1.nbt,3,CHEST:3,./StructureNBT/StructureLoot/Common1.nbt,3,CHEST:3,./StructureNBT/StructureLoot/Common2.nbt,3,CHEST:3,./StructureNBT/StructureLoot/Common3.nbt,3,CHEST:3,./StructureNBT/StructureLoot/Common4.nbt,3,CHEST:3,./StructureNBT/StructureLoot/Common5.nbt,3,CHEST:3,./StructureNBT/StructureLoot/Common5.nbt,3,CHEST:3,./StructureNBT/StructureLoot/Common6.nbt,3,CHEST:3,./StructureNBT/StructureLoot/Common7.nbt,3,CHEST:3,./StructureNBT/StructureLoot/Common8.nbt,3,CHEST:3,./StructureNBT/StructureLoot/Common9.nbt,3,CHEST:3,./StructureNBT/StructureLoot/Common10.nbt,3,CHEST:3,./StructureNBT/StructureLoot/Common11.nbt,3,CHEST:3,./StructureNBT/StructureLoot/Common12.nbt,3,CHEST:3,./StructureNBT/StructureLoot/Common13.nbt,3,CHEST:3,./StructureNBT/StructureLoot/Common14.nbt,3,CHEST:3,./StructureNBT/StructureLoot/Common15.nbt,3,CHEST:3,./StructureNBT/StructureLoot/Rare1.nbt,3,CHEST:3,./StructureNBT/StructureLoot/Rare2.nbt,3,CHEST:3,./StructureNBT/StructureLoot/Rare3.nbt,3,CHEST:3,./StructureNBT/StructureLoot/Rare4.nbt,3,CHEST:3,./StructureNBT/StructureLoot/Rare5.nbt,3,CHEST:3,./StructureNBT/StructureLoot/Rare6.nbt,3,CHEST:3,./StructureNBT/StructureLoot/Rare7.nbt,3,CHEST:3,./StructureNBT/StructureLoot/Rare8.nbt,3,CHEST:3,./StructureNBT/StructureLoot/Rare9.nbt,3,CHEST:3,./StructureNBT/StructureLoot/Rare10.nbt,3,CHEST:3,./StructureNBT/StructureLoot/Rare11.nbt,3,CHEST:3,./StructureNBT/StructureLoot/Rare12.nbt,3,CHEST:3,./StructureNBT/StructureLoot/Rare13.nbt,3,CHEST:3,./StructureNBT/StructureLoot/Rare14.nbt,3,CHEST:3,./StructureNBT/StructureLoot/Rare15.nbt,3,CHEST:3,./StructureNBT/StructureLoot/Epic1.nbt,3,CHEST:3,./StructureNBT/StructureLoot/Epic2.nbt,3,CHEST:3,./StructureNBT/StructureLoot/Epic3.nbt,3,CHEST:3,./StructureNBT/StructureLoot/Epic4.nbt,3,CHEST:3,./StructureNBT/StructureLoot/Epic5.nbt,3,CHEST:3,./StructureNBT/StructureLoot/Epic6.nbt,3,CHEST:3,./StructureNBT/StructureLoot/Epic7.nbt,3,CHEST:3,./StructureNBT/StructureLoot/Epic8.nbt,3,CHEST:3,./StructureNBT/StructureLoot/Epic9.nbt,3,CHEST:3,./StructureNBT/StructureLoot/Epic10.nbt,3,CHEST:3,./StructureNBT/StructureLoot/Epic11.nbt,3,CHEST:3,./StructureNBT/StructureLoot/Epic12.nbt,3,CHEST:3,./StructureNBT/StructureLoot/Epic13.nbt,3,CHEST:3,./StructureNBT/StructureLoot/Epic14.nbt,3,CHEST:3,./StructureNBT/StructureLoot/Epic15.nbt,100)
Block(-6,21,-7,hay_block)
Block(-6,21,-6,air)
Block(-6,21,-5,dark_oak_stairs:1)
Block(-6,21,-4,hay_block)
Block(-6,21,-3,air)
Block(-6,21,-2,melon_block)
Block(-6,21,-1,hay_block)
Block(-6,21,0,dark_oak_stairs:1)
RandomBlock(-6,21,1,CHEST:5,./StructureNBT/StructureLoot/JunkChest_1.nbt,20,CHEST:5,./StructureNBT/StructureLoot/JunkChest_2.nbt,15,CHEST:5,./StructureNBT/StructureLoot/JunkChest_3.nbt,15,CHEST:5,./StructureNBT/StructureLoot/JunkChest_4.nbt,15,CHEST:5,./StructureNBT/StructureLoot/JunkChest_5.nbt,15,CHEST:5,./StructureNBT/LoreStoryline/LoreGeneric_5.nbt,2,CHEST:5,./StructureNBT/LoreStoryline/LoreGeneric_4.nbt,2,CHEST:5,./StructureNBT/LoreStoryline/LoreGeneric_3.nbt,2,CHEST:5,./StructureNBT/LoreStoryline/LoreGeneric_2.nbt,2,CHEST:5,./StructureNBT/LoreStoryline/LoreGeneric_1.nbt,2,CHEST:5,./StructureNBT/LoreStoryline/LoreMedievalCity_5.nbt,3,CHEST:5,./StructureNBT/LoreStoryline/LoreMedievalCity_4.nbt,3,CHEST:5,./StructureNBT/LoreStoryline/LoreMedievalCity_3.nbt,3,CHEST:5,./StructureNBT/LoreStoryline/LoreMedievalCity_2.nbt,3,CHEST:5,./StructureNBT/LoreStoryline/LoreMedievalCity_1.nbt,3,CHEST:5,./StructureNBT/StructureLoot/Common1.nbt,3,CHEST:5,./StructureNBT/StructureLoot/Common2.nbt,3,CHEST:5,./StructureNBT/StructureLoot/Common3.nbt,3,CHEST:5,./StructureNBT/StructureLoot/Common4.nbt,3,CHEST:5,./StructureNBT/StructureLoot/Common5.nbt,3,CHEST:5,./StructureNBT/StructureLoot/Common5.nbt,3,CHEST:5,./StructureNBT/StructureLoot/Common6.nbt,3,CHEST:5,./StructureNBT/StructureLoot/Common7.nbt,3,CHEST:5,./StructureNBT/StructureLoot/Common8.nbt,3,CHEST:5,./StructureNBT/StructureLoot/Common9.nbt,3,CHEST:5,./StructureNBT/StructureLoot/Common10.nbt,3,CHEST:5,./StructureNBT/StructureLoot/Common11.nbt,3,CHEST:5,./StructureNBT/StructureLoot/Common12.nbt,3,CHEST:5,./StructureNBT/StructureLoot/Common13.nbt,3,CHEST:5,./StructureNBT/StructureLoot/Common14.nbt,3,CHEST:5,./StructureNBT/StructureLoot/Common15.nbt,3,CHEST:5,./StructureNBT/StructureLoot/Rare1.nbt,3,CHEST:5,./StructureNBT/StructureLoot/Rare2.nbt,3,CHEST:5,./StructureNBT/StructureLoot/Rare3.nbt,3,CHEST:5,./StructureNBT/StructureLoot/Rare4.nbt,3,CHEST:5,./StructureNBT/StructureLoot/Rare5.nbt,3,CHEST:5,./StructureNBT/StructureLoot/Rare6.nbt,3,CHEST:5,./StructureNBT/StructureLoot/Rare7.nbt,3,CHEST:5,./StructureNBT/StructureLoot/Rare8.nbt,3,CHEST:5,./StructureNBT/StructureLoot/Rare9.nbt,3,CHEST:5,./StructureNBT/StructureLoot/Rare10.nbt,3,CHEST:5,./StructureNBT/StructureLoot/Rare11.nbt,3,CHEST:5,./StructureNBT/StructureLoot/Rare12.nbt,3,CHEST:5,./StructureNBT/StructureLoot/Rare13.nbt,3,CHEST:5,./StructureNBT/StructureLoot/Rare14.nbt,3,CHEST:5,./StructureNBT/StructureLoot/Rare15.nbt,3,CHEST:5,./StructureNBT/StructureLoot/Epic1.nbt,3,CHEST:5,./StructureNBT/StructureLoot/Epic2.nbt,3,CHEST:5,./StructureNBT/StructureLoot/Epic3.nbt,3,CHEST:5,./StructureNBT/StructureLoot/Epic4.nbt,3,CHEST:5,./StructureNBT/StructureLoot/Epic5.nbt,3,CHEST:5,./StructureNBT/StructureLoot/Epic6.nbt,3,CHEST:5,./StructureNBT/StructureLoot/Epic7.nbt,3,CHEST:5,./StructureNBT/StructureLoot/Epic8.nbt,3,CHEST:5,./StructureNBT/StructureLoot/Epic9.nbt,3,CHEST:5,./StructureNBT/StructureLoot/Epic10.nbt,3,CHEST:5,./StructureNBT/StructureLoot/Epic11.nbt,3,CHEST:5,./StructureNBT/StructureLoot/Epic12.nbt,3,CHEST:5,./StructureNBT/StructureLoot/Epic13.nbt,3,CHEST:5,./StructureNBT/StructureLoot/Epic14.nbt,3,CHEST:5,./StructureNBT/StructureLoot/Epic15.nbt,100)
Block(-6,21,2,hay_block)
Block(-6,21,3,pumpkin:3)
Block(-6,21,4,melon_block)
Block(-6,21,5,dark_oak_stairs:1)
Block(-6,21,6,hay_block:8)
Block(-6,21,7,crafting_table)
Block(-6,22,-8,air)
Block(-6,22,-7,hay_block)
Block(-6,22,-6,air)
Block(-6,22,-5,hay_block)
Block(-6,22,-4,crafting_table)
Block(-6,22,-3,air)
Block(-6,22,-2,hay_block:4)
Block(-6,22,-1,hay_block)
Block(-6,22,0,air)
Block(-6,22,1,air)
Block(-6,22,2,hay_block:4)
Block(-6,22,3,air)
Block(-6,22,4,air)
Block(-6,22,5,air)
Block(-6,22,6,hay_block)
Block(-6,22,7,air)
Block(-6,23,6,pumpkin:0)
Block(-6,24,-8,wooden_slab:8)
Block(-6,24,-7,wooden_slab:8)
Block(-6,24,-6,wooden_slab:8)
Block(-6,24,-5,wooden_slab:8)
Block(-6,24,5,wooden_slab:8)
Block(-6,24,6,wooden_slab:8)
Block(-6,24,7,wooden_slab:8)
Block(-6,25,5,crafting_table)
Block(-6,25,6,crafting_table)
Block(-6,27,-8,wooden_slab:11)
Block(-6,27,-7,wooden_slab:11)
Block(-6,27,-6,wooden_slab:11)
Block(-6,27,-5,wooden_slab:11)
Block(-6,27,-4,wooden_slab:11)
Block(-6,27,-3,wooden_slab:11)
Block(-6,27,-2,wooden_slab:11)
Block(-6,27,-1,wooden_slab:11)
Block(-6,27,0,wooden_slab:11)
Block(-6,27,1,wooden_slab:11)
Block(-6,27,2,wooden_slab:11)
Block(-6,27,3,wooden_slab:11)
Block(-6,27,4,wooden_slab:11)
Block(-6,27,5,wooden_slab:11)
Block(-6,27,6,wooden_slab:11)
Block(-6,28,-8,planks:5)
Block(-6,28,-7,planks:5)
RandomBlock(-6,28,-6,CHEST:5,./StructureNBT/StructureLoot/JunkChest_1.nbt,20,CHEST:5,./StructureNBT/StructureLoot/JunkChest_2.nbt,15,CHEST:5,./StructureNBT/StructureLoot/JunkChest_3.nbt,15,CHEST:5,./StructureNBT/StructureLoot/JunkChest_4.nbt,15,CHEST:5,./StructureNBT/StructureLoot/JunkChest_5.nbt,15,CHEST:5,./StructureNBT/LoreStoryline/LoreGeneric_5.nbt,2,CHEST:5,./StructureNBT/LoreStoryline/LoreGeneric_4.nbt,2,CHEST:5,./StructureNBT/LoreStoryline/LoreGeneric_3.nbt,2,CHEST:5,./StructureNBT/LoreStoryline/LoreGeneric_2.nbt,2,CHEST:5,./StructureNBT/LoreStoryline/LoreGeneric_1.nbt,2,CHEST:5,./StructureNBT/LoreStoryline/LoreMedievalCity_5.nbt,3,CHEST:5,./StructureNBT/LoreStoryline/LoreMedievalCity_4.nbt,3,CHEST:5,./StructureNBT/LoreStoryline/LoreMedievalCity_3.nbt,3,CHEST:5,./StructureNBT/LoreStoryline/LoreMedievalCity_2.nbt,3,CHEST:5,./StructureNBT/LoreStoryline/LoreMedievalCity_1.nbt,3,CHEST:5,./StructureNBT/StructureLoot/Common1.nbt,3,CHEST:5,./StructureNBT/StructureLoot/Common2.nbt,3,CHEST:5,./StructureNBT/StructureLoot/Common3.nbt,3,CHEST:5,./StructureNBT/StructureLoot/Common4.nbt,3,CHEST:5,./StructureNBT/StructureLoot/Common5.nbt,3,CHEST:5,./StructureNBT/StructureLoot/Common5.nbt,3,CHEST:5,./StructureNBT/StructureLoot/Common6.nbt,3,CHEST:5,./StructureNBT/StructureLoot/Common7.nbt,3,CHEST:5,./StructureNBT/StructureLoot/Common8.nbt,3,CHEST:5,./StructureNBT/StructureLoot/Common9.nbt,3,CHEST:5,./StructureNBT/StructureLoot/Common10.nbt,3,CHEST:5,./StructureNBT/StructureLoot/Common11.nbt,3,CHEST:5,./StructureNBT/StructureLoot/Common12.nbt,3,CHEST:5,./StructureNBT/StructureLoot/Common13.nbt,3,CHEST:5,./StructureNBT/StructureLoot/Common14.nbt,3,CHEST:5,./StructureNBT/StructureLoot/Common15.nbt,3,CHEST:5,./StructureNBT/StructureLoot/Rare1.nbt,3,CHEST:5,./StructureNBT/StructureLoot/Rare2.nbt,3,CHEST:5,./StructureNBT/StructureLoot/Rare3.nbt,3,CHEST:5,./StructureNBT/StructureLoot/Rare4.nbt,3,CHEST:5,./StructureNBT/StructureLoot/Rare5.nbt,3,CHEST:5,./StructureNBT/StructureLoot/Rare6.nbt,3,CHEST:5,./StructureNBT/StructureLoot/Rare7.nbt,3,CHEST:5,./StructureNBT/StructureLoot/Rare8.nbt,3,CHEST:5,./StructureNBT/StructureLoot/Rare9.nbt,3,CHEST:5,./StructureNBT/StructureLoot/Rare10.nbt,3,CHEST:5,./StructureNBT/StructureLoot/Rare11.nbt,3,CHEST:5,./StructureNBT/StructureLoot/Rare12.nbt,3,CHEST:5,./StructureNBT/StructureLoot/Rare13.nbt,3,CHEST:5,./StructureNBT/StructureLoot/Rare14.nbt,3,CHEST:5,./StructureNBT/StructureLoot/Rare15.nbt,3,CHEST:5,./StructureNBT/StructureLoot/Epic1.nbt,3,CHEST:5,./StructureNBT/StructureLoot/Epic2.nbt,3,CHEST:5,./StructureNBT/StructureLoot/Epic3.nbt,3,CHEST:5,./StructureNBT/StructureLoot/Epic4.nbt,3,CHEST:5,./StructureNBT/StructureLoot/Epic5.nbt,3,CHEST:5,./StructureNBT/StructureLoot/Epic6.nbt,3,CHEST:5,./StructureNBT/StructureLoot/Epic7.nbt,3,CHEST:5,./StructureNBT/StructureLoot/Epic8.nbt,3,CHEST:5,./StructureNBT/StructureLoot/Epic9.nbt,3,CHEST:5,./StructureNBT/StructureLoot/Epic10.nbt,3,CHEST:5,./StructureNBT/StructureLoot/Epic11.nbt,3,CHEST:5,./StructureNBT/StructureLoot/Epic12.nbt,3,CHEST:5,./StructureNBT/StructureLoot/Epic13.nbt,3,CHEST:5,./StructureNBT/StructureLoot/Epic14.nbt,3,CHEST:5,./StructureNBT/StructureLoot/Epic15.nbt,100)
Block(-6,28,-5,hay_block)
Block(-6,28,-4,hay_block)
Block(-6,28,-3,hay_block)
RandomBlock(-6,28,-2,CHEST:5,./StructureNBT/StructureLoot/JunkChest_1.nbt,20,CHEST:5,./StructureNBT/StructureLoot/JunkChest_2.nbt,15,CHEST:5,./StructureNBT/StructureLoot/JunkChest_3.nbt,15,CHEST:5,./StructureNBT/StructureLoot/JunkChest_4.nbt,15,CHEST:5,./StructureNBT/StructureLoot/JunkChest_5.nbt,15,CHEST:5,./StructureNBT/LoreStoryline/LoreGeneric_5.nbt,2,CHEST:5,./StructureNBT/LoreStoryline/LoreGeneric_4.nbt,2,CHEST:5,./StructureNBT/LoreStoryline/LoreGeneric_3.nbt,2,CHEST:5,./StructureNBT/LoreStoryline/LoreGeneric_2.nbt,2,CHEST:5,./StructureNBT/LoreStoryline/LoreGeneric_1.nbt,2,CHEST:5,./StructureNBT/LoreStoryline/LoreMedievalCity_5.nbt,3,CHEST:5,./StructureNBT/LoreStoryline/LoreMedievalCity_4.nbt,3,CHEST:5,./StructureNBT/LoreStoryline/LoreMedievalCity_3.nbt,3,CHEST:5,./StructureNBT/LoreStoryline/LoreMedievalCity_2.nbt,3,CHEST:5,./StructureNBT/LoreStoryline/LoreMedievalCity_1.nbt,3,CHEST:5,./StructureNBT/StructureLoot/Common1.nbt,3,CHEST:5,./StructureNBT/StructureLoot/Common2.nbt,3,CHEST:5,./StructureNBT/StructureLoot/Common3.nbt,3,CHEST:5,./StructureNBT/StructureLoot/Common4.nbt,3,CHEST:5,./StructureNBT/StructureLoot/Common5.nbt,3,CHEST:5,./StructureNBT/StructureLoot/Common5.nbt,3,CHEST:5,./StructureNBT/StructureLoot/Common6.nbt,3,CHEST:5,./StructureNBT/StructureLoot/Common7.nbt,3,CHEST:5,./StructureNBT/StructureLoot/Common8.nbt,3,CHEST:5,./StructureNBT/StructureLoot/Common9.nbt,3,CHEST:5,./StructureNBT/StructureLoot/Common10.nbt,3,CHEST:5,./StructureNBT/StructureLoot/Common11.nbt,3,CHEST:5,./StructureNBT/StructureLoot/Common12.nbt,3,CHEST:5,./StructureNBT/StructureLoot/Common13.nbt,3,CHEST:5,./StructureNBT/StructureLoot/Common14.nbt,3,CHEST:5,./StructureNBT/StructureLoot/Common15.nbt,3,CHEST:5,./StructureNBT/StructureLoot/Rare1.nbt,3,CHEST:5,./StructureNBT/StructureLoot/Rare2.nbt,3,CHEST:5,./StructureNBT/StructureLoot/Rare3.nbt,3,CHEST:5,./StructureNBT/StructureLoot/Rare4.nbt,3,CHEST:5,./StructureNBT/StructureLoot/Rare5.nbt,3,CHEST:5,./StructureNBT/StructureLoot/Rare6.nbt,3,CHEST:5,./StructureNBT/StructureLoot/Rare7.nbt,3,CHEST:5,./StructureNBT/StructureLoot/Rare8.nbt,3,CHEST:5,./StructureNBT/StructureLoot/Rare9.nbt,3,CHEST:5,./StructureNBT/StructureLoot/Rare10.nbt,3,CHEST:5,./StructureNBT/StructureLoot/Rare11.nbt,3,CHEST:5,./StructureNBT/StructureLoot/Rare12.nbt,3,CHEST:5,./StructureNBT/StructureLoot/Rare13.nbt,3,CHEST:5,./StructureNBT/StructureLoot/Rare14.nbt,3,CHEST:5,./StructureNBT/StructureLoot/Rare15.nbt,3,CHEST:5,./StructureNBT/StructureLoot/Epic1.nbt,3,CHEST:5,./StructureNBT/StructureLoot/Epic2.nbt,3,CHEST:5,./StructureNBT/StructureLoot/Epic3.nbt,3,CHEST:5,./StructureNBT/StructureLoot/Epic4.nbt,3,CHEST:5,./StructureNBT/StructureLoot/Epic5.nbt,3,CHEST:5,./StructureNBT/StructureLoot/Epic6.nbt,3,CHEST:5,./StructureNBT/StructureLoot/Epic7.nbt,3,CHEST:5,./StructureNBT/StructureLoot/Epic8.nbt,3,CHEST:5,./StructureNBT/StructureLoot/Epic9.nbt,3,CHEST:5,./StructureNBT/StructureLoot/Epic10.nbt,3,CHEST:5,./StructureNBT/StructureLoot/Epic11.nbt,3,CHEST:5,./StructureNBT/StructureLoot/Epic12.nbt,3,CHEST:5,./StructureNBT/StructureLoot/Epic13.nbt,3,CHEST:5,./StructureNBT/StructureLoot/Epic14.nbt,3,CHEST:5,./StructureNBT/StructureLoot/Epic15.nbt,100)
RandomBlock(-6,28,-1,CHEST:5,./StructureNBT/StructureLoot/JunkChest_1.nbt,20,CHEST:5,./StructureNBT/StructureLoot/JunkChest_2.nbt,15,CHEST:5,./StructureNBT/StructureLoot/JunkChest_3.nbt,15,CHEST:5,./StructureNBT/StructureLoot/JunkChest_4.nbt,15,CHEST:5,./StructureNBT/StructureLoot/JunkChest_5.nbt,15,CHEST:5,./StructureNBT/LoreStoryline/LoreGeneric_5.nbt,2,CHEST:5,./StructureNBT/LoreStoryline/LoreGeneric_4.nbt,2,CHEST:5,./StructureNBT/LoreStoryline/LoreGeneric_3.nbt,2,CHEST:5,./StructureNBT/LoreStoryline/LoreGeneric_2.nbt,2,CHEST:5,./StructureNBT/LoreStoryline/LoreGeneric_1.nbt,2,CHEST:5,./StructureNBT/LoreStoryline/LoreMedievalCity_5.nbt,3,CHEST:5,./StructureNBT/LoreStoryline/LoreMedievalCity_4.nbt,3,CHEST:5,./StructureNBT/LoreStoryline/LoreMedievalCity_3.nbt,3,CHEST:5,./StructureNBT/LoreStoryline/LoreMedievalCity_2.nbt,3,CHEST:5,./StructureNBT/LoreStoryline/LoreMedievalCity_1.nbt,3,CHEST:5,./StructureNBT/StructureLoot/Common1.nbt,3,CHEST:5,./StructureNBT/StructureLoot/Common2.nbt,3,CHEST:5,./StructureNBT/StructureLoot/Common3.nbt,3,CHEST:5,./StructureNBT/StructureLoot/Common4.nbt,3,CHEST:5,./StructureNBT/StructureLoot/Common5.nbt,3,CHEST:5,./StructureNBT/StructureLoot/Common5.nbt,3,CHEST:5,./StructureNBT/StructureLoot/Common6.nbt,3,CHEST:5,./StructureNBT/StructureLoot/Common7.nbt,3,CHEST:5,./StructureNBT/StructureLoot/Common8.nbt,3,CHEST:5,./StructureNBT/StructureLoot/Common9.nbt,3,CHEST:5,./StructureNBT/StructureLoot/Common10.nbt,3,CHEST:5,./StructureNBT/StructureLoot/Common11.nbt,3,CHEST:5,./StructureNBT/StructureLoot/Common12.nbt,3,CHEST:5,./StructureNBT/StructureLoot/Common13.nbt,3,CHEST:5,./StructureNBT/StructureLoot/Common14.nbt,3,CHEST:5,./StructureNBT/StructureLoot/Common15.nbt,3,CHEST:5,./StructureNBT/StructureLoot/Rare1.nbt,3,CHEST:5,./StructureNBT/StructureLoot/Rare2.nbt,3,CHEST:5,./StructureNBT/StructureLoot/Rare3.nbt,3,CHEST:5,./StructureNBT/StructureLoot/Rare4.nbt,3,CHEST:5,./StructureNBT/StructureLoot/Rare5.nbt,3,CHEST:5,./StructureNBT/StructureLoot/Rare6.nbt,3,CHEST:5,./StructureNBT/StructureLoot/Rare7.nbt,3,CHEST:5,./StructureNBT/StructureLoot/Rare8.nbt,3,CHEST:5,./StructureNBT/StructureLoot/Rare9.nbt,3,CHEST:5,./StructureNBT/StructureLoot/Rare10.nbt,3,CHEST:5,./StructureNBT/StructureLoot/Rare11.nbt,3,CHEST:5,./StructureNBT/StructureLoot/Rare12.nbt,3,CHEST:5,./StructureNBT/StructureLoot/Rare13.nbt,3,CHEST:5,./StructureNBT/StructureLoot/Rare14.nbt,3,CHEST:5,./StructureNBT/StructureLoot/Rare15.nbt,3,CHEST:5,./StructureNBT/StructureLoot/Epic1.nbt,3,CHEST:5,./StructureNBT/StructureLoot/Epic2.nbt,3,CHEST:5,./StructureNBT/StructureLoot/Epic3.nbt,3,CHEST:5,./StructureNBT/StructureLoot/Epic4.nbt,3,CHEST:5,./StructureNBT/StructureLoot/Epic5.nbt,3,CHEST:5,./StructureNBT/StructureLoot/Epic6.nbt,3,CHEST:5,./StructureNBT/StructureLoot/Epic7.nbt,3,CHEST:5,./StructureNBT/StructureLoot/Epic8.nbt,3,CHEST:5,./StructureNBT/StructureLoot/Epic9.nbt,3,CHEST:5,./StructureNBT/StructureLoot/Epic10.nbt,3,CHEST:5,./StructureNBT/StructureLoot/Epic11.nbt,3,CHEST:5,./StructureNBT/StructureLoot/Epic12.nbt,3,CHEST:5,./StructureNBT/StructureLoot/Epic13.nbt,3,CHEST:5,./StructureNBT/StructureLoot/Epic14.nbt,3,CHEST:5,./StructureNBT/StructureLoot/Epic15.nbt,100)
Block(-6,28,0,hay_block)
Block(-6,28,1,hay_block)
Block(-6,28,2,hay_block)
Block(-6,28,3,hay_block:4)
Block(-6,28,4,hay_block)
RandomBlock(-6,28,5,CHEST:5,./StructureNBT/StructureLoot/JunkChest_1.nbt,20,CHEST:5,./StructureNBT/StructureLoot/JunkChest_2.nbt,15,CHEST:5,./StructureNBT/StructureLoot/JunkChest_3.nbt,15,CHEST:5,./StructureNBT/StructureLoot/JunkChest_4.nbt,15,CHEST:5,./StructureNBT/StructureLoot/JunkChest_5.nbt,15,CHEST:5,./StructureNBT/LoreStoryline/LoreGeneric_5.nbt,2,CHEST:5,./StructureNBT/LoreStoryline/LoreGeneric_4.nbt,2,CHEST:5,./StructureNBT/LoreStoryline/LoreGeneric_3.nbt,2,CHEST:5,./StructureNBT/LoreStoryline/LoreGeneric_2.nbt,2,CHEST:5,./StructureNBT/LoreStoryline/LoreGeneric_1.nbt,2,CHEST:5,./StructureNBT/LoreStoryline/LoreMedievalCity_5.nbt,3,CHEST:5,./StructureNBT/LoreStoryline/LoreMedievalCity_4.nbt,3,CHEST:5,./StructureNBT/LoreStoryline/LoreMedievalCity_3.nbt,3,CHEST:5,./StructureNBT/LoreStoryline/LoreMedievalCity_2.nbt,3,CHEST:5,./StructureNBT/LoreStoryline/LoreMedievalCity_1.nbt,3,CHEST:5,./StructureNBT/StructureLoot/Common1.nbt,3,CHEST:5,./StructureNBT/StructureLoot/Common2.nbt,3,CHEST:5,./StructureNBT/StructureLoot/Common3.nbt,3,CHEST:5,./StructureNBT/StructureLoot/Common4.nbt,3,CHEST:5,./StructureNBT/StructureLoot/Common5.nbt,3,CHEST:5,./StructureNBT/StructureLoot/Common5.nbt,3,CHEST:5,./StructureNBT/StructureLoot/Common6.nbt,3,CHEST:5,./StructureNBT/StructureLoot/Common7.nbt,3,CHEST:5,./StructureNBT/StructureLoot/Common8.nbt,3,CHEST:5,./StructureNBT/StructureLoot/Common9.nbt,3,CHEST:5,./StructureNBT/StructureLoot/Common10.nbt,3,CHEST:5,./StructureNBT/StructureLoot/Common11.nbt,3,CHEST:5,./StructureNBT/StructureLoot/Common12.nbt,3,CHEST:5,./StructureNBT/StructureLoot/Common13.nbt,3,CHEST:5,./StructureNBT/StructureLoot/Common14.nbt,3,CHEST:5,./StructureNBT/StructureLoot/Common15.nbt,3,CHEST:5,./StructureNBT/StructureLoot/Rare1.nbt,3,CHEST:5,./StructureNBT/StructureLoot/Rare2.nbt,3,CHEST:5,./StructureNBT/StructureLoot/Rare3.nbt,3,CHEST:5,./StructureNBT/StructureLoot/Rare4.nbt,3,CHEST:5,./StructureNBT/StructureLoot/Rare5.nbt,3,CHEST:5,./StructureNBT/StructureLoot/Rare6.nbt,3,CHEST:5,./StructureNBT/StructureLoot/Rare7.nbt,3,CHEST:5,./StructureNBT/StructureLoot/Rare8.nbt,3,CHEST:5,./StructureNBT/StructureLoot/Rare9.nbt,3,CHEST:5,./StructureNBT/StructureLoot/Rare10.nbt,3,CHEST:5,./StructureNBT/StructureLoot/Rare11.nbt,3,CHEST:5,./StructureNBT/StructureLoot/Rare12.nbt,3,CHEST:5,./StructureNBT/StructureLoot/Rare13.nbt,3,CHEST:5,./StructureNBT/StructureLoot/Rare14.nbt,3,CHEST:5,./StructureNBT/StructureLoot/Rare15.nbt,3,CHEST:5,./StructureNBT/StructureLoot/Epic1.nbt,3,CHEST:5,./StructureNBT/StructureLoot/Epic2.nbt,3,CHEST:5,./StructureNBT/StructureLoot/Epic3.nbt,3,CHEST:5,./StructureNBT/StructureLoot/Epic4.nbt,3,CHEST:5,./StructureNBT/StructureLoot/Epic5.nbt,3,CHEST:5,./StructureNBT/StructureLoot/Epic6.nbt,3,CHEST:5,./StructureNBT/StructureLoot/Epic7.nbt,3,CHEST:5,./StructureNBT/StructureLoot/Epic8.nbt,3,CHEST:5,./StructureNBT/StructureLoot/Epic9.nbt,3,CHEST:5,./StructureNBT/StructureLoot/Epic10.nbt,3,CHEST:5,./StructureNBT/StructureLoot/Epic11.nbt,3,CHEST:5,./StructureNBT/StructureLoot/Epic12.nbt,3,CHEST:5,./StructureNBT/StructureLoot/Epic13.nbt,3,CHEST:5,./StructureNBT/StructureLoot/Epic14.nbt,3,CHEST:5,./StructureNBT/StructureLoot/Epic15.nbt,100)
RandomBlock(-6,28,6,CHEST:5,./StructureNBT/StructureLoot/JunkChest_1.nbt,20,CHEST:5,./StructureNBT/StructureLoot/JunkChest_2.nbt,15,CHEST:5,./StructureNBT/StructureLoot/JunkChest_3.nbt,15,CHEST:5,./StructureNBT/StructureLoot/JunkChest_4.nbt,15,CHEST:5,./StructureNBT/StructureLoot/JunkChest_5.nbt,15,CHEST:5,./StructureNBT/LoreStoryline/LoreGeneric_5.nbt,2,CHEST:5,./StructureNBT/LoreStoryline/LoreGeneric_4.nbt,2,CHEST:5,./StructureNBT/LoreStoryline/LoreGeneric_3.nbt,2,CHEST:5,./StructureNBT/LoreStoryline/LoreGeneric_2.nbt,2,CHEST:5,./StructureNBT/LoreStoryline/LoreGeneric_1.nbt,2,CHEST:5,./StructureNBT/LoreStoryline/LoreMedievalCity_5.nbt,3,CHEST:5,./StructureNBT/LoreStoryline/LoreMedievalCity_4.nbt,3,CHEST:5,./StructureNBT/LoreStoryline/LoreMedievalCity_3.nbt,3,CHEST:5,./StructureNBT/LoreStoryline/LoreMedievalCity_2.nbt,3,CHEST:5,./StructureNBT/LoreStoryline/LoreMedievalCity_1.nbt,3,CHEST:5,./StructureNBT/StructureLoot/Common1.nbt,3,CHEST:5,./StructureNBT/StructureLoot/Common2.nbt,3,CHEST:5,./StructureNBT/StructureLoot/Common3.nbt,3,CHEST:5,./StructureNBT/StructureLoot/Common4.nbt,3,CHEST:5,./StructureNBT/StructureLoot/Common5.nbt,3,CHEST:5,./StructureNBT/StructureLoot/Common5.nbt,3,CHEST:5,./StructureNBT/StructureLoot/Common6.nbt,3,CHEST:5,./StructureNBT/StructureLoot/Common7.nbt,3,CHEST:5,./StructureNBT/StructureLoot/Common8.nbt,3,CHEST:5,./StructureNBT/StructureLoot/Common9.nbt,3,CHEST:5,./StructureNBT/StructureLoot/Common10.nbt,3,CHEST:5,./StructureNBT/StructureLoot/Common11.nbt,3,CHEST:5,./StructureNBT/StructureLoot/Common12.nbt,3,CHEST:5,./StructureNBT/StructureLoot/Common13.nbt,3,CHEST:5,./StructureNBT/StructureLoot/Common14.nbt,3,CHEST:5,./StructureNBT/StructureLoot/Common15.nbt,3,CHEST:5,./StructureNBT/StructureLoot/Rare1.nbt,3,CHEST:5,./StructureNBT/StructureLoot/Rare2.nbt,3,CHEST:5,./StructureNBT/StructureLoot/Rare3.nbt,3,CHEST:5,./StructureNBT/StructureLoot/Rare4.nbt,3,CHEST:5,./StructureNBT/StructureLoot/Rare5.nbt,3,CHEST:5,./StructureNBT/StructureLoot/Rare6.nbt,3,CHEST:5,./StructureNBT/StructureLoot/Rare7.nbt,3,CHEST:5,./StructureNBT/StructureLoot/Rare8.nbt,3,CHEST:5,./StructureNBT/StructureLoot/Rare9.nbt,3,CHEST:5,./StructureNBT/StructureLoot/Rare10.nbt,3,CHEST:5,./StructureNBT/StructureLoot/Rare11.nbt,3,CHEST:5,./StructureNBT/StructureLoot/Rare12.nbt,3,CHEST:5,./StructureNBT/StructureLoot/Rare13.nbt,3,CHEST:5,./StructureNBT/StructureLoot/Rare14.nbt,3,CHEST:5,./StructureNBT/StructureLoot/Rare15.nbt,3,CHEST:5,./StructureNBT/StructureLoot/Epic1.nbt,3,CHEST:5,./StructureNBT/StructureLoot/Epic2.nbt,3,CHEST:5,./StructureNBT/StructureLoot/Epic3.nbt,3,CHEST:5,./StructureNBT/StructureLoot/Epic4.nbt,3,CHEST:5,./StructureNBT/StructureLoot/Epic5.nbt,3,CHEST:5,./StructureNBT/StructureLoot/Epic6.nbt,3,CHEST:5,./StructureNBT/StructureLoot/Epic7.nbt,3,CHEST:5,./StructureNBT/StructureLoot/Epic8.nbt,3,CHEST:5,./StructureNBT/StructureLoot/Epic9.nbt,3,CHEST:5,./StructureNBT/StructureLoot/Epic10.nbt,3,CHEST:5,./StructureNBT/StructureLoot/Epic11.nbt,3,CHEST:5,./StructureNBT/StructureLoot/Epic12.nbt,3,CHEST:5,./StructureNBT/StructureLoot/Epic13.nbt,3,CHEST:5,./StructureNBT/StructureLoot/Epic14.nbt,3,CHEST:5,./StructureNBT/StructureLoot/Epic15.nbt,100)
Block(-6,28,7,wooden_slab:3)
Block(-6,29,-4,hay_block)
Block(-6,29,2,hay_block)
RandomBlock(-6,29,4,CHEST:5,./StructureNBT/StructureLoot/JunkChest_1.nbt,20,CHEST:5,./StructureNBT/StructureLoot/JunkChest_2.nbt,15,CHEST:5,./StructureNBT/StructureLoot/JunkChest_3.nbt,15,CHEST:5,./StructureNBT/StructureLoot/JunkChest_4.nbt,15,CHEST:5,./StructureNBT/StructureLoot/JunkChest_5.nbt,15,CHEST:5,./StructureNBT/LoreStoryline/LoreGeneric_5.nbt,2,CHEST:5,./StructureNBT/LoreStoryline/LoreGeneric_4.nbt,2,CHEST:5,./StructureNBT/LoreStoryline/LoreGeneric_3.nbt,2,CHEST:5,./StructureNBT/LoreStoryline/LoreGeneric_2.nbt,2,CHEST:5,./StructureNBT/LoreStoryline/LoreGeneric_1.nbt,2,CHEST:5,./StructureNBT/LoreStoryline/LoreMedievalCity_5.nbt,3,CHEST:5,./StructureNBT/LoreStoryline/LoreMedievalCity_4.nbt,3,CHEST:5,./StructureNBT/LoreStoryline/LoreMedievalCity_3.nbt,3,CHEST:5,./StructureNBT/LoreStoryline/LoreMedievalCity_2.nbt,3,CHEST:5,./StructureNBT/LoreStoryline/LoreMedievalCity_1.nbt,3,CHEST:5,./StructureNBT/StructureLoot/Common1.nbt,3,CHEST:5,./StructureNBT/StructureLoot/Common2.nbt,3,CHEST:5,./StructureNBT/StructureLoot/Common3.nbt,3,CHEST:5,./StructureNBT/StructureLoot/Common4.nbt,3,CHEST:5,./StructureNBT/StructureLoot/Common5.nbt,3,CHEST:5,./StructureNBT/StructureLoot/Common5.nbt,3,CHEST:5,./StructureNBT/StructureLoot/Common6.nbt,3,CHEST:5,./StructureNBT/StructureLoot/Common7.nbt,3,CHEST:5,./StructureNBT/StructureLoot/Common8.nbt,3,CHEST:5,./StructureNBT/StructureLoot/Common9.nbt,3,CHEST:5,./StructureNBT/StructureLoot/Common10.nbt,3,CHEST:5,./StructureNBT/StructureLoot/Common11.nbt,3,CHEST:5,./StructureNBT/StructureLoot/Common12.nbt,3,CHEST:5,./StructureNBT/StructureLoot/Common13.nbt,3,CHEST:5,./StructureNBT/StructureLoot/Common14.nbt,3,CHEST:5,./StructureNBT/StructureLoot/Common15.nbt,3,CHEST:5,./StructureNBT/StructureLoot/Rare1.nbt,3,CHEST:5,./StructureNBT/StructureLoot/Rare2.nbt,3,CHEST:5,./StructureNBT/StructureLoot/Rare3.nbt,3,CHEST:5,./StructureNBT/StructureLoot/Rare4.nbt,3,CHEST:5,./StructureNBT/StructureLoot/Rare5.nbt,3,CHEST:5,./StructureNBT/StructureLoot/Rare6.nbt,3,CHEST:5,./StructureNBT/StructureLoot/Rare7.nbt,3,CHEST:5,./StructureNBT/StructureLoot/Rare8.nbt,3,CHEST:5,./StructureNBT/StructureLoot/Rare9.nbt,3,CHEST:5,./StructureNBT/StructureLoot/Rare10.nbt,3,CHEST:5,./StructureNBT/StructureLoot/Rare11.nbt,3,CHEST:5,./StructureNBT/StructureLoot/Rare12.nbt,3,CHEST:5,./StructureNBT/StructureLoot/Rare13.nbt,3,CHEST:5,./StructureNBT/StructureLoot/Rare14.nbt,3,CHEST:5,./StructureNBT/StructureLoot/Rare15.nbt,3,CHEST:5,./StructureNBT/StructureLoot/Epic1.nbt,3,CHEST:5,./StructureNBT/StructureLoot/Epic2.nbt,3,CHEST:5,./StructureNBT/StructureLoot/Epic3.nbt,3,CHEST:5,./StructureNBT/StructureLoot/Epic4.nbt,3,CHEST:5,./StructureNBT/StructureLoot/Epic5.nbt,3,CHEST:5,./StructureNBT/StructureLoot/Epic6.nbt,3,CHEST:5,./StructureNBT/StructureLoot/Epic7.nbt,3,CHEST:5,./StructureNBT/StructureLoot/Epic8.nbt,3,CHEST:5,./StructureNBT/StructureLoot/Epic9.nbt,3,CHEST:5,./StructureNBT/StructureLoot/Epic10.nbt,3,CHEST:5,./StructureNBT/StructureLoot/Epic11.nbt,3,CHEST:5,./StructureNBT/StructureLoot/Epic12.nbt,3,CHEST:5,./StructureNBT/StructureLoot/Epic13.nbt,3,CHEST:5,./StructureNBT/StructureLoot/Epic14.nbt,3,CHEST:5,./StructureNBT/StructureLoot/Epic15.nbt,100)
Block(-6,32,-7,spruce_fence)
Block(-6,32,-6,spruce_fence)
Block(-6,32,-5,spruce_fence)
Block(-6,32,4,wool)
Block(-6,32,5,spruce_fence)
Block(-6,32,6,spruce_fence)
Block(-6,32,7,spruce_fence)
Block(-6,33,-7,spruce_fence)
Block(-6,33,-6,spruce_fence)
Block(-6,33,-5,spruce_fence)
Block(-6,33,3,wool:15)
Block(-6,33,5,spruce_fence)
Block(-6,33,6,spruce_fence)
Block(-6,33,7,spruce_fence)
Block(-6,34,-7,spruce_fence)
Block(-6,34,-6,spruce_fence)
Block(-6,34,-5,spruce_fence)
Block(-6,34,3,wool:15)
Block(-6,34,5,spruce_fence)
Block(-6,34,6,spruce_fence)
Block(-6,34,7,spruce_fence)
Block(-6,35,-7,spruce_fence)
Block(-6,35,-6,spruce_fence)
Block(-6,35,-5,spruce_fence)
Block(-6,35,2,wool:15)
Block(-6,35,5,spruce_fence)
Block(-6,35,6,spruce_fence)
Block(-6,35,7,spruce_fence)
Block(-6,36,-7,spruce_fence)
Block(-6,36,-6,spruce_fence)
Block(-6,36,-5,spruce_fence)
Block(-6,36,2,wool)
Block(-6,36,5,spruce_fence)
Block(-6,36,6,spruce_fence)
Block(-6,36,7,spruce_fence)
Block(-6,37,2,wool)
Block(-6,38,2,wool:15)
Block(-6,39,3,wool:15)
Block(-6,40,3,wool:15)
Block(-6,41,4,wool:15)
Block(-6,42,4,log:5)
Block(-6,43,4,wooden_slab:5)
Block(-6,46,2,wool:15)
Block(-6,46,3,wool)
Block(-6,47,1,wool:15)
Block(-6,48,1,wool:15)
Block(-6,49,-8,oak_stairs:4)
Block(-6,49,-7,oak_stairs:4)
Block(-6,49,1,wool)
Block(-6,50,-8,double_wooden_slab:5)
Block(-6,50,-7,double_wooden_slab:5)
Block(-6,50,1,wool)
Block(-6,51,-8,spruce_fence)
Block(-6,51,-7,spruce_fence)
Block(-6,51,2,wool)
Block(-6,52,-8,spruce_fence)
Block(-6,52,-7,spruce_fence)
Block(-6,52,3,wool)
Block(-6,52,4,fence)
Block(-6,53,-8,spruce_fence)
Block(-6,53,-7,spruce_fence)
Block(-6,53,4,log:5)
Block(-6,54,4,wooden_slab:5)
Block(-6,65,3,wool:15)
Block(-5,18,-8,planks)
Block(-5,18,-7,planks)
Block(-5,18,-6,planks)
Block(-5,18,-5,planks)
Block(-5,18,-4,planks)
Block(-5,18,-3,planks)
Block(-5,18,-2,planks)
Block(-5,18,-1,planks)
Block(-5,18,0,planks)
Block(-5,18,1,planks)
Block(-5,18,2,planks)
Block(-5,18,3,planks)
Block(-5,18,4,planks)
Block(-5,18,5,planks)
Block(-5,18,6,planks)
Block(-5,18,7,planks)
Block(-5,19,-8,planks)
Block(-5,19,-7,planks)
Block(-5,19,-6,planks)
Block(-5,19,-5,planks)
Block(-5,19,-4,planks)
Block(-5,19,-3,planks)
Block(-5,19,-2,planks)
Block(-5,19,-1,planks)
Block(-5,19,0,planks)
Block(-5,19,1,planks)
Block(-5,19,2,planks)
Block(-5,19,3,planks)
Block(-5,19,4,planks)
Block(-5,19,5,planks)
Block(-5,19,6,planks)
Block(-5,19,7,planks)
Block(-5,20,-8,hay_block)
Block(-5,20,-7,hay_block)
Block(-5,20,-6,hay_block:4)
Block(-5,20,-5,dark_oak_stairs:1)
Block(-5,20,-4,hay_block:4)
Block(-5,20,-3,air)
Block(-5,20,-2,pumpkin:3)
Block(-5,20,-1,hay_block)
Block(-5,20,0,dark_oak_stairs:1)
Block(-5,20,1,hay_block)
Block(-5,20,2,hay_block)
Block(-5,20,3,hay_block)
Block(-5,20,4,hay_block)
Block(-5,20,5,dark_oak_stairs:1)
Block(-5,20,6,melon_block)
Block(-5,20,7,hay_block:4)
RandomBlock(-5,21,-8,CHEST:3,./StructureNBT/StructureLoot/JunkChest_1.nbt,20,CHEST:3,./StructureNBT/StructureLoot/JunkChest_2.nbt,15,CHEST:3,./StructureNBT/StructureLoot/JunkChest_3.nbt,15,CHEST:3,./StructureNBT/StructureLoot/JunkChest_4.nbt,15,CHEST:3,./StructureNBT/StructureLoot/JunkChest_5.nbt,15,CHEST:3,./StructureNBT/LoreStoryline/LoreGeneric_5.nbt,2,CHEST:3,./StructureNBT/LoreStoryline/LoreGeneric_4.nbt,2,CHEST:3,./StructureNBT/LoreStoryline/LoreGeneric_3.nbt,2,CHEST:3,./StructureNBT/LoreStoryline/LoreGeneric_2.nbt,2,CHEST:3,./StructureNBT/LoreStoryline/LoreGeneric_1.nbt,2,CHEST:3,./StructureNBT/LoreStoryline/LoreMedievalCity_5.nbt,3,CHEST:3,./StructureNBT/LoreStoryline/LoreMedievalCity_4.nbt,3,CHEST:3,./StructureNBT/LoreStoryline/LoreMedievalCity_3.nbt,3,CHEST:3,./StructureNBT/LoreStoryline/LoreMedievalCity_2.nbt,3,CHEST:3,./StructureNBT/LoreStoryline/LoreMedievalCity_1.nbt,3,CHEST:3,./StructureNBT/StructureLoot/Common1.nbt,3,CHEST:3,./StructureNBT/StructureLoot/Common2.nbt,3,CHEST:3,./StructureNBT/StructureLoot/Common3.nbt,3,CHEST:3,./StructureNBT/StructureLoot/Common4.nbt,3,CHEST:3,./StructureNBT/StructureLoot/Common5.nbt,3,CHEST:3,./StructureNBT/StructureLoot/Common5.nbt,3,CHEST:3,./StructureNBT/StructureLoot/Common6.nbt,3,CHEST:3,./StructureNBT/StructureLoot/Common7.nbt,3,CHEST:3,./StructureNBT/StructureLoot/Common8.nbt,3,CHEST:3,./StructureNBT/StructureLoot/Common9.nbt,3,CHEST:3,./StructureNBT/StructureLoot/Common10.nbt,3,CHEST:3,./StructureNBT/StructureLoot/Common11.nbt,3,CHEST:3,./StructureNBT/StructureLoot/Common12.nbt,3,CHEST:3,./StructureNBT/StructureLoot/Common13.nbt,3,CHEST:3,./StructureNBT/StructureLoot/Common14.nbt,3,CHEST:3,./StructureNBT/StructureLoot/Common15.nbt,3,CHEST:3,./StructureNBT/StructureLoot/Rare1.nbt,3,CHEST:3,./StructureNBT/StructureLoot/Rare2.nbt,3,CHEST:3,./StructureNBT/StructureLoot/Rare3.nbt,3,CHEST:3,./StructureNBT/StructureLoot/Rare4.nbt,3,CHEST:3,./StructureNBT/StructureLoot/Rare5.nbt,3,CHEST:3,./StructureNBT/StructureLoot/Rare6.nbt,3,CHEST:3,./StructureNBT/StructureLoot/Rare7.nbt,3,CHEST:3,./StructureNBT/StructureLoot/Rare8.nbt,3,CHEST:3,./StructureNBT/StructureLoot/Rare9.nbt,3,CHEST:3,./StructureNBT/StructureLoot/Rare10.nbt,3,CHEST:3,./StructureNBT/StructureLoot/Rare11.nbt,3,CHEST:3,./StructureNBT/StructureLoot/Rare12.nbt,3,CHEST:3,./StructureNBT/StructureLoot/Rare13.nbt,3,CHEST:3,./StructureNBT/StructureLoot/Rare14.nbt,3,CHEST:3,./StructureNBT/StructureLoot/Rare15.nbt,3,CHEST:3,./StructureNBT/StructureLoot/Epic1.nbt,3,CHEST:3,./StructureNBT/StructureLoot/Epic2.nbt,3,CHEST:3,./StructureNBT/StructureLoot/Epic3.nbt,3,CHEST:3,./StructureNBT/StructureLoot/Epic4.nbt,3,CHEST:3,./StructureNBT/StructureLoot/Epic5.nbt,3,CHEST:3,./StructureNBT/StructureLoot/Epic6.nbt,3,CHEST:3,./StructureNBT/StructureLoot/Epic7.nbt,3,CHEST:3,./StructureNBT/StructureLoot/Epic8.nbt,3,CHEST:3,./StructureNBT/StructureLoot/Epic9.nbt,3,CHEST:3,./StructureNBT/StructureLoot/Epic10.nbt,3,CHEST:3,./StructureNBT/StructureLoot/Epic11.nbt,3,CHEST:3,./StructureNBT/StructureLoot/Epic12.nbt,3,CHEST:3,./StructureNBT/StructureLoot/Epic13.nbt,3,CHEST:3,./StructureNBT/StructureLoot/Epic14.nbt,3,CHEST:3,./StructureNBT/StructureLoot/Epic15.nbt,100)
Block(-5,21,-7,hay_block)
RandomBlock(-5,21,-6,CHEST:3,./StructureNBT/StructureLoot/JunkChest_1.nbt,20,CHEST:3,./StructureNBT/StructureLoot/JunkChest_2.nbt,15,CHEST:3,./StructureNBT/StructureLoot/JunkChest_3.nbt,15,CHEST:3,./StructureNBT/StructureLoot/JunkChest_4.nbt,15,CHEST:3,./StructureNBT/StructureLoot/JunkChest_5.nbt,15,CHEST:3,./StructureNBT/LoreStoryline/LoreGeneric_5.nbt,2,CHEST:3,./StructureNBT/LoreStoryline/LoreGeneric_4.nbt,2,CHEST:3,./StructureNBT/LoreStoryline/LoreGeneric_3.nbt,2,CHEST:3,./StructureNBT/LoreStoryline/LoreGeneric_2.nbt,2,CHEST:3,./StructureNBT/LoreStoryline/LoreGeneric_1.nbt,2,CHEST:3,./StructureNBT/LoreStoryline/LoreMedievalCity_5.nbt,3,CHEST:3,./StructureNBT/LoreStoryline/LoreMedievalCity_4.nbt,3,CHEST:3,./StructureNBT/LoreStoryline/LoreMedievalCity_3.nbt,3,CHEST:3,./StructureNBT/LoreStoryline/LoreMedievalCity_2.nbt,3,CHEST:3,./StructureNBT/LoreStoryline/LoreMedievalCity_1.nbt,3,CHEST:3,./StructureNBT/StructureLoot/Common1.nbt,3,CHEST:3,./StructureNBT/StructureLoot/Common2.nbt,3,CHEST:3,./StructureNBT/StructureLoot/Common3.nbt,3,CHEST:3,./StructureNBT/StructureLoot/Common4.nbt,3,CHEST:3,./StructureNBT/StructureLoot/Common5.nbt,3,CHEST:3,./StructureNBT/StructureLoot/Common5.nbt,3,CHEST:3,./StructureNBT/StructureLoot/Common6.nbt,3,CHEST:3,./StructureNBT/StructureLoot/Common7.nbt,3,CHEST:3,./StructureNBT/StructureLoot/Common8.nbt,3,CHEST:3,./StructureNBT/StructureLoot/Common9.nbt,3,CHEST:3,./StructureNBT/StructureLoot/Common10.nbt,3,CHEST:3,./StructureNBT/StructureLoot/Common11.nbt,3,CHEST:3,./StructureNBT/StructureLoot/Common12.nbt,3,CHEST:3,./StructureNBT/StructureLoot/Common13.nbt,3,CHEST:3,./StructureNBT/StructureLoot/Common14.nbt,3,CHEST:3,./StructureNBT/StructureLoot/Common15.nbt,3,CHEST:3,./StructureNBT/StructureLoot/Rare1.nbt,3,CHEST:3,./StructureNBT/StructureLoot/Rare2.nbt,3,CHEST:3,./StructureNBT/StructureLoot/Rare3.nbt,3,CHEST:3,./StructureNBT/StructureLoot/Rare4.nbt,3,CHEST:3,./StructureNBT/StructureLoot/Rare5.nbt,3,CHEST:3,./StructureNBT/StructureLoot/Rare6.nbt,3,CHEST:3,./StructureNBT/StructureLoot/Rare7.nbt,3,CHEST:3,./StructureNBT/StructureLoot/Rare8.nbt,3,CHEST:3,./StructureNBT/StructureLoot/Rare9.nbt,3,CHEST:3,./StructureNBT/StructureLoot/Rare10.nbt,3,CHEST:3,./StructureNBT/StructureLoot/Rare11.nbt,3,CHEST:3,./StructureNBT/StructureLoot/Rare12.nbt,3,CHEST:3,./StructureNBT/StructureLoot/Rare13.nbt,3,CHEST:3,./StructureNBT/StructureLoot/Rare14.nbt,3,CHEST:3,./StructureNBT/StructureLoot/Rare15.nbt,3,CHEST:3,./StructureNBT/StructureLoot/Epic1.nbt,3,CHEST:3,./StructureNBT/StructureLoot/Epic2.nbt,3,CHEST:3,./StructureNBT/StructureLoot/Epic3.nbt,3,CHEST:3,./StructureNBT/StructureLoot/Epic4.nbt,3,CHEST:3,./StructureNBT/StructureLoot/Epic5.nbt,3,CHEST:3,./StructureNBT/StructureLoot/Epic6.nbt,3,CHEST:3,./StructureNBT/StructureLoot/Epic7.nbt,3,CHEST:3,./StructureNBT/StructureLoot/Epic8.nbt,3,CHEST:3,./StructureNBT/StructureLoot/Epic9.nbt,3,CHEST:3,./StructureNBT/StructureLoot/Epic10.nbt,3,CHEST:3,./StructureNBT/StructureLoot/Epic11.nbt,3,CHEST:3,./StructureNBT/StructureLoot/Epic12.nbt,3,CHEST:3,./StructureNBT/StructureLoot/Epic13.nbt,3,CHEST:3,./StructureNBT/StructureLoot/Epic14.nbt,3,CHEST:3,./StructureNBT/StructureLoot/Epic15.nbt,100)
Block(-5,21,-5,hay_block)
Block(-5,21,-4,air)
Block(-5,21,-3,air)
Block(-5,21,-2,melon_block)
Block(-5,21,-1,hay_block:4)
Block(-5,21,0,air)
Block(-5,21,1,air)
Block(-5,21,2,hay_block)
Block(-5,21,3,hay_block:8)
Block(-5,21,4,hay_block)
Block(-5,21,5,hay_block)
Block(-5,21,6,air)
Block(-5,21,7,air)
Block(-5,22,-8,air)
Block(-5,22,-7,hay_block)
Block(-5,22,-6,air)
Block(-5,22,-5,hay_block)
Block(-5,22,-4,air)
Block(-5,22,-3,air)
Block(-5,22,-2,air)
Block(-5,22,-1,air)
Block(-5,22,0,air)
Block(-5,22,1,air)
Block(-5,22,2,melon_block)
Block(-5,22,3,hay_block)
Block(-5,22,4,air)
Block(-5,22,5,air)
Block(-5,22,6,air)
Block(-5,22,7,air)
Block(-5,23,-7,hay_block)
Block(-5,24,-8,wooden_slab:8)
Block(-5,24,-7,wooden_slab:8)
Block(-5,24,-6,wooden_slab:8)
Block(-5,24,-5,wooden_slab:8)
Block(-5,24,-4,oak_stairs:4)
Block(-5,24,-3,oak_stairs:4)
Block(-5,24,-2,oak_stairs:4)
Block(-5,24,-1,oak_stairs:4)
Block(-5,24,0,oak_stairs:4)
Block(-5,24,1,oak_stairs:4)
Block(-5,24,2,oak_stairs:4)
Block(-5,24,3,oak_stairs:4)
Block(-5,24,4,oak_stairs:4)
Block(-5,24,5,wooden_slab:8)
Block(-5,24,6,wooden_slab:8)
Block(-5,24,7,wooden_slab:8)
Block(-5,25,-5,bed:10)
Block(-5,25,-4,bed)
RandomBlock(-5,25,-3,CHEST:3,./StructureNBT/StructureLoot/JunkChest_1.nbt,20,CHEST:3,./StructureNBT/StructureLoot/JunkChest_2.nbt,15,CHEST:3,./StructureNBT/StructureLoot/JunkChest_3.nbt,15,CHEST:3,./StructureNBT/StructureLoot/JunkChest_4.nbt,15,CHEST:3,./StructureNBT/StructureLoot/JunkChest_5.nbt,15,CHEST:3,./StructureNBT/LoreStoryline/LoreGeneric_5.nbt,2,CHEST:3,./StructureNBT/LoreStoryline/LoreGeneric_4.nbt,2,CHEST:3,./StructureNBT/LoreStoryline/LoreGeneric_3.nbt,2,CHEST:3,./StructureNBT/LoreStoryline/LoreGeneric_2.nbt,2,CHEST:3,./StructureNBT/LoreStoryline/LoreGeneric_1.nbt,2,CHEST:3,./StructureNBT/LoreStoryline/LoreMedievalCity_5.nbt,3,CHEST:3,./StructureNBT/LoreStoryline/LoreMedievalCity_4.nbt,3,CHEST:3,./StructureNBT/LoreStoryline/LoreMedievalCity_3.nbt,3,CHEST:3,./StructureNBT/LoreStoryline/LoreMedievalCity_2.nbt,3,CHEST:3,./StructureNBT/LoreStoryline/LoreMedievalCity_1.nbt,3,CHEST:3,./StructureNBT/StructureLoot/Common1.nbt,3,CHEST:3,./StructureNBT/StructureLoot/Common2.nbt,3,CHEST:3,./StructureNBT/StructureLoot/Common3.nbt,3,CHEST:3,./StructureNBT/StructureLoot/Common4.nbt,3,CHEST:3,./StructureNBT/StructureLoot/Common5.nbt,3,CHEST:3,./StructureNBT/StructureLoot/Common5.nbt,3,CHEST:3,./StructureNBT/StructureLoot/Common6.nbt,3,CHEST:3,./StructureNBT/StructureLoot/Common7.nbt,3,CHEST:3,./StructureNBT/StructureLoot/Common8.nbt,3,CHEST:3,./StructureNBT/StructureLoot/Common9.nbt,3,CHEST:3,./StructureNBT/StructureLoot/Common10.nbt,3,CHEST:3,./StructureNBT/StructureLoot/Common11.nbt,3,CHEST:3,./StructureNBT/StructureLoot/Common12.nbt,3,CHEST:3,./StructureNBT/StructureLoot/Common13.nbt,3,CHEST:3,./StructureNBT/StructureLoot/Common14.nbt,3,CHEST:3,./StructureNBT/StructureLoot/Common15.nbt,3,CHEST:3,./StructureNBT/StructureLoot/Rare1.nbt,3,CHEST:3,./StructureNBT/StructureLoot/Rare2.nbt,3,CHEST:3,./StructureNBT/StructureLoot/Rare3.nbt,3,CHEST:3,./StructureNBT/StructureLoot/Rare4.nbt,3,CHEST:3,./StructureNBT/StructureLoot/Rare5.nbt,3,CHEST:3,./StructureNBT/StructureLoot/Rare6.nbt,3,CHEST:3,./StructureNBT/StructureLoot/Rare7.nbt,3,CHEST:3,./StructureNBT/StructureLoot/Rare8.nbt,3,CHEST:3,./StructureNBT/StructureLoot/Rare9.nbt,3,CHEST:3,./StructureNBT/StructureLoot/Rare10.nbt,3,CHEST:3,./StructureNBT/StructureLoot/Rare11.nbt,3,CHEST:3,./StructureNBT/StructureLoot/Rare12.nbt,3,CHEST:3,./StructureNBT/StructureLoot/Rare13.nbt,3,CHEST:3,./StructureNBT/StructureLoot/Rare14.nbt,3,CHEST:3,./StructureNBT/StructureLoot/Rare15.nbt,3,CHEST:3,./StructureNBT/StructureLoot/Epic1.nbt,3,CHEST:3,./StructureNBT/StructureLoot/Epic2.nbt,3,CHEST:3,./StructureNBT/StructureLoot/Epic3.nbt,3,CHEST:3,./StructureNBT/StructureLoot/Epic4.nbt,3,CHEST:3,./StructureNBT/StructureLoot/Epic5.nbt,3,CHEST:3,./StructureNBT/StructureLoot/Epic6.nbt,3,CHEST:3,./StructureNBT/StructureLoot/Epic7.nbt,3,CHEST:3,./StructureNBT/StructureLoot/Epic8.nbt,3,CHEST:3,./StructureNBT/StructureLoot/Epic9.nbt,3,CHEST:3,./StructureNBT/StructureLoot/Epic10.nbt,3,CHEST:3,./StructureNBT/StructureLoot/Epic11.nbt,3,CHEST:3,./StructureNBT/StructureLoot/Epic12.nbt,3,CHEST:3,./StructureNBT/StructureLoot/Epic13.nbt,3,CHEST:3,./StructureNBT/StructureLoot/Epic14.nbt,3,CHEST:3,./StructureNBT/StructureLoot/Epic15.nbt,100)
Block(-5,27,-8,wooden_slab:11)
Block(-5,27,-7,wooden_slab:11)
Block(-5,27,-6,wooden_slab:11)
Block(-5,27,-5,wooden_slab:11)
Block(-5,27,-4,wooden_slab:11)
Block(-5,27,-3,wooden_slab:11)
Block(-5,27,-2,wooden_slab:11)
Block(-5,27,-1,wooden_slab:11)
Block(-5,27,0,wooden_slab:11)
Block(-5,27,1,wooden_slab:11)
Block(-5,27,2,wooden_slab:11)
Block(-5,27,3,wooden_slab:11)
Block(-5,27,4,wooden_slab:11)
Block(-5,27,5,wooden_slab:11)
Block(-5,27,6,wooden_slab:11)
Block(-5,28,-8,wooden_slab:3)
Block(-5,28,-3,hay_block)
Block(-5,28,0,hay_block:4)
Block(-5,28,1,hay_block)
Block(-5,28,2,crafting_table)
Block(-5,28,3,hay_block)
Block(-5,28,4,anvil:1)
Block(-5,28,7,wooden_slab:3)
Block(-5,32,3,wool)
Block(-5,32,4,wool)
Block(-5,33,3,wool:15)
Block(-5,33,6,dark_oak_stairs:6)
Block(-5,33,7,dark_oak_stairs:4)
Block(-5,34,2,wool:15)
Block(-5,34,6,fence)
Block(-5,34,7,fence)
Block(-5,35,2,wool:15)
Block(-5,36,-7,spruce_fence)
Block(-5,36,-6,spruce_fence)
Block(-5,36,2,wool)
Block(-5,36,5,spruce_fence)
Block(-5,36,6,spruce_fence)
Block(-5,37,-7,spruce_fence)
Block(-5,37,-6,spruce_fence)
Block(-5,37,2,wool)
Block(-5,37,5,spruce_fence)
Block(-5,37,6,spruce_fence)
Block(-5,38,-7,spruce_fence)
Block(-5,38,-6,spruce_fence)
Block(-5,38,2,wool:15)
Block(-5,38,5,spruce_fence)
Block(-5,38,6,spruce_fence)
Block(-5,39,-7,dark_oak_stairs:6)
Block(-5,39,-6,dark_oak_stairs:4)
Block(-5,39,-5,dark_oak_stairs:4)
Block(-5,39,-4,dark_oak_stairs:7)
Block(-5,39,2,wool:15)
Block(-5,39,5,spruce_fence)
Block(-5,39,6,spruce_fence)
Block(-5,40,-7,spruce_fence)
Block(-5,40,-6,spruce_fence)
Block(-5,40,-5,fence)
Block(-5,40,-4,fence)
Block(-5,40,3,wool:15)
Block(-5,40,5,spruce_fence)
Block(-5,40,6,spruce_fence)
Block(-5,41,-7,spruce_fence)
Block(-5,41,-6,spruce_fence)
Block(-5,41,3,wool:15)
Block(-5,41,4,fence)
Block(-5,41,5,spruce_fence)
Block(-5,41,6,spruce_fence)
Block(-5,42,-7,spruce_fence)
Block(-5,42,-6,spruce_fence)
Block(-5,42,4,log:5)
Block(-5,42,5,spruce_fence)
Block(-5,42,6,spruce_fence)
Block(-5,43,-7,spruce_fence)
Block(-5,43,-6,spruce_fence)
Block(-5,43,4,wooden_slab:5)
Block(-5,43,5,spruce_fence)
Block(-5,43,6,spruce_fence)
Block(-5,44,-7,spruce_fence)
Block(-5,44,-6,spruce_fence)
Block(-5,44,5,spruce_fence)
Block(-5,44,6,spruce_fence)
Block(-5,45,-7,spruce_fence)
Block(-5,45,-6,spruce_fence)
Block(-5,45,5,spruce_fence)
Block(-5,45,6,spruce_fence)
Block(-5,46,-7,spruce_fence)
Block(-5,46,-6,spruce_fence)
Block(-5,46,-5,fence)
Block(-5,46,1,wool:15)
Block(-5,46,2,wool)
Block(-5,46,4,dark_oak_stairs:6)
Block(-5,46,5,dark_oak_stairs:4)
Block(-5,46,6,dark_oak_stairs:4)
Block(-5,46,7,dark_oak_stairs:7)
Block(-5,47,-7,spruce_fence)
Block(-5,47,-6,spruce_fence)
Block(-5,47,1,wool:15)
Block(-5,47,4,fence)
Block(-5,47,5,spruce_fence)
Block(-5,47,6,spruce_fence)
Block(-5,47,7,fence)
Block(-5,48,-7,spruce_fence)
Block(-5,48,-6,wool:15)
Block(-5,48,0,wool:15)
Block(-5,48,5,spruce_fence)
Block(-5,48,6,spruce_fence)
Block(-5,49,-8,spruce_fence)
Block(-5,49,-7,spruce_fence)
Block(-5,49,-6,wool:15)
Block(-5,49,-5,wool:15)
Block(-5,49,1,wool)
Block(-5,49,4,spruce_fence)
Block(-5,49,5,spruce_fence)
Block(-5,49,6,spruce_fence)
Block(-5,50,-8,dark_oak_stairs:4)
Block(-5,50,-7,dark_oak_stairs:4)
Block(-5,50,-6,wool:15)
Block(-5,50,-5,wool:15)
Block(-5,50,-4,wool)
Block(-5,50,1,wool)
Block(-5,50,4,spruce_fence)
Block(-5,50,5,spruce_fence)
Block(-5,51,-6,wool:15)
Block(-5,51,-5,wool:15)
Block(-5,51,-4,wool)
Block(-5,51,-3,wool)
Block(-5,51,1,wool)
Block(-5,51,4,spruce_fence)
Block(-5,51,5,spruce_fence)
Block(-5,52,-6,wool:15)
Block(-5,52,-5,wool:15)
Block(-5,52,-4,wool)
Block(-5,52,-3,wool)
Block(-5,52,-2,wool)
Block(-5,52,2,wool)
Block(-5,52,3,fence)
Block(-5,52,4,spruce_fence)
Block(-5,52,5,spruce_fence)
Block(-5,53,-8,spruce_fence)
Block(-5,53,-7,spruce_fence)
Block(-5,53,-5,wool:15)
Block(-5,53,-4,wool:15)
Block(-5,53,-3,wool:15)
Block(-5,53,-2,wool:15)
Block(-5,53,-1,wool)
Block(-5,53,3,log:5)
Block(-5,53,4,spruce_fence)
Block(-5,53,5,spruce_fence)
Block(-5,54,-8,spruce_fence)
Block(-5,54,-7,spruce_fence)
Block(-5,54,-5,wool:15)
Block(-5,54,-4,wool:15)
Block(-5,54,-3,wool:15)
Block(-5,54,-2,wool:15)
Block(-5,54,-1,wool)
Block(-5,54,0,wool)
Block(-5,54,3,wooden_slab:5)
Block(-5,54,4,spruce_fence)
Block(-5,54,5,spruce_fence)
Block(-5,55,-8,spruce_fence)
Block(-5,55,-7,spruce_fence)
Block(-5,55,-6,fence)
Block(-5,55,-4,wool:15)
Block(-5,55,-3,wool:15)
Block(-5,55,-2,wool:15)
Block(-5,55,-1,wool:15)
Block(-5,55,0,wool:15)
Block(-5,55,1,wool)
Block(-5,55,4,spruce_fence)
Block(-5,55,5,spruce_fence)
Block(-5,56,-8,spruce_fence)
Block(-5,56,-7,spruce_fence)
Block(-5,56,-3,wool:15)
Block(-5,56,-2,wool:15)
Block(-5,56,-1,wool:15)
Block(-5,56,0,wool:15)
Block(-5,56,1,wool)
Block(-5,56,2,wool)
Block(-5,56,4,spruce_fence)
Block(-5,56,5,spruce_fence)
Block(-5,57,1,wool:15)
Block(-5,57,2,wool)
Block(-5,58,2,wool:15)
Block(-5,60,-8,dark_oak_stairs:7)
Block(-5,61,-8,fence)
Block(-5,61,-7,fence)
Block(-5,65,3,wool:14)
Block(-4,17,-8,planks:3)
Block(-4,17,-7,planks:3)
Block(-4,17,-6,planks:3)
Block(-4,17,-5,planks:3)
Block(-4,17,-4,planks:3)
Block(-4,17,-3,planks:3)
Block(-4,17,-2,planks:3)
Block(-4,17,-1,planks:3)
Block(-4,17,0,planks:3)
Block(-4,17,1,planks:3)
Block(-4,17,2,planks:3)
Block(-4,17,3,planks:3)
Block(-4,17,4,planks:3)
Block(-4,17,5,planks:3)
Block(-4,17,6,planks:3)
Block(-4,17,7,planks:3)
Block(-4,18,-8,planks:3)
Block(-4,18,-7,planks:3)
Block(-4,18,-6,planks:3)
Block(-4,18,-5,planks:3)
Block(-4,18,-4,planks:3)
Block(-4,18,-3,planks:3)
Block(-4,18,-2,planks:3)
Block(-4,18,-1,planks:3)
Block(-4,18,0,planks:3)
Block(-4,18,1,planks:3)
Block(-4,18,2,planks:3)
Block(-4,18,3,planks:3)
Block(-4,18,4,planks:3)
Block(-4,18,5,planks:3)
Block(-4,18,6,planks:3)
Block(-4,18,7,planks:3)
Block(-4,19,-8,planks:3)
Block(-4,19,-7,planks:3)
Block(-4,19,-6,planks:3)
Block(-4,19,-5,planks:3)
Block(-4,19,-4,planks:3)
Block(-4,19,-3,planks:3)
Block(-4,19,-2,planks:3)
Block(-4,19,-1,planks:3)
Block(-4,19,0,planks:3)
Block(-4,19,1,planks:3)
Block(-4,19,2,planks:3)
Block(-4,19,3,planks:3)
Block(-4,19,4,planks:3)
Block(-4,19,5,planks:3)
Block(-4,19,6,planks:3)
Block(-4,19,7,planks:3)
Block(-4,20,-8,hay_block)
Block(-4,20,-7,hay_block)
Block(-4,20,-6,hay_block:4)
Block(-4,20,-5,log:1)
Block(-4,20,-4,air)
Block(-4,20,-3,hay_block)
Block(-4,20,-2,air)
Block(-4,20,-1,hay_block)
Block(-4,20,0,wooden_slab:5)
Block(-4,20,1,hay_block:8)
Block(-4,20,2,hay_block)
Block(-4,20,3,air)
Block(-4,20,4,hay_block)
Block(-4,20,5,wooden_slab:5)
Block(-4,20,6,air)
Block(-4,20,7,log:1)
Block(-4,21,-8,hay_block:4)
Block(-4,21,-7,air)
Block(-4,21,-6,hay_block)
Block(-4,21,-5,log:1)
Block(-4,21,-4,dark_oak_fence)
Block(-4,21,-3,melon_block)
Block(-4,21,-2,air)
Block(-4,21,-1,hay_block)
Block(-4,21,0,crafting_table)
Block(-4,21,1,hay_block)
Block(-4,21,2,crafting_table)
Block(-4,21,3,hay_block:8)
Block(-4,21,4,hay_block)
Block(-4,21,5,melon_block)
Block(-4,21,6,dark_oak_fence)
Block(-4,21,7,log:1)
Block(-4,22,-8,hay_block)
Block(-4,22,-7,melon_block)
Block(-4,22,-6,hay_block)
Block(-4,22,-5,log:1)
Block(-4,22,-4,torch)
Block(-4,22,-3,air)
Block(-4,22,-2,air)
Block(-4,22,-1,hay_block)
Block(-4,22,0,air)
Block(-4,22,1,air)
Block(-4,22,2,air)
Block(-4,22,3,air)
RandomBlock(-4,22,4,CHEST:3,./StructureNBT/StructureLoot/JunkChest_1.nbt,20,CHEST:3,./StructureNBT/StructureLoot/JunkChest_2.nbt,15,CHEST:3,./StructureNBT/StructureLoot/JunkChest_3.nbt,15,CHEST:3,./StructureNBT/StructureLoot/JunkChest_4.nbt,15,CHEST:3,./StructureNBT/StructureLoot/JunkChest_5.nbt,15,CHEST:3,./StructureNBT/LoreStoryline/LoreGeneric_5.nbt,2,CHEST:3,./StructureNBT/LoreStoryline/LoreGeneric_4.nbt,2,CHEST:3,./StructureNBT/LoreStoryline/LoreGeneric_3.nbt,2,CHEST:3,./StructureNBT/LoreStoryline/LoreGeneric_2.nbt,2,CHEST:3,./StructureNBT/LoreStoryline/LoreGeneric_1.nbt,2,CHEST:3,./StructureNBT/LoreStoryline/LoreMedievalCity_5.nbt,3,CHEST:3,./StructureNBT/LoreStoryline/LoreMedievalCity_4.nbt,3,CHEST:3,./StructureNBT/LoreStoryline/LoreMedievalCity_3.nbt,3,CHEST:3,./StructureNBT/LoreStoryline/LoreMedievalCity_2.nbt,3,CHEST:3,./StructureNBT/LoreStoryline/LoreMedievalCity_1.nbt,3,CHEST:3,./StructureNBT/StructureLoot/Common1.nbt,3,CHEST:3,./StructureNBT/StructureLoot/Common2.nbt,3,CHEST:3,./StructureNBT/StructureLoot/Common3.nbt,3,CHEST:3,./StructureNBT/StructureLoot/Common4.nbt,3,CHEST:3,./StructureNBT/StructureLoot/Common5.nbt,3,CHEST:3,./StructureNBT/StructureLoot/Common5.nbt,3,CHEST:3,./StructureNBT/StructureLoot/Common6.nbt,3,CHEST:3,./StructureNBT/StructureLoot/Common7.nbt,3,CHEST:3,./StructureNBT/StructureLoot/Common8.nbt,3,CHEST:3,./StructureNBT/StructureLoot/Common9.nbt,3,CHEST:3,./StructureNBT/StructureLoot/Common10.nbt,3,CHEST:3,./StructureNBT/StructureLoot/Common11.nbt,3,CHEST:3,./StructureNBT/StructureLoot/Common12.nbt,3,CHEST:3,./StructureNBT/StructureLoot/Common13.nbt,3,CHEST:3,./StructureNBT/StructureLoot/Common14.nbt,3,CHEST:3,./StructureNBT/StructureLoot/Common15.nbt,3,CHEST:3,./StructureNBT/StructureLoot/Rare1.nbt,3,CHEST:3,./StructureNBT/StructureLoot/Rare2.nbt,3,CHEST:3,./StructureNBT/StructureLoot/Rare3.nbt,3,CHEST:3,./StructureNBT/StructureLoot/Rare4.nbt,3,CHEST:3,./StructureNBT/StructureLoot/Rare5.nbt,3,CHEST:3,./StructureNBT/StructureLoot/Rare6.nbt,3,CHEST:3,./StructureNBT/StructureLoot/Rare7.nbt,3,CHEST:3,./StructureNBT/StructureLoot/Rare8.nbt,3,CHEST:3,./StructureNBT/StructureLoot/Rare9.nbt,3,CHEST:3,./StructureNBT/StructureLoot/Rare10.nbt,3,CHEST:3,./StructureNBT/StructureLoot/Rare11.nbt,3,CHEST:3,./StructureNBT/StructureLoot/Rare12.nbt,3,CHEST:3,./StructureNBT/StructureLoot/Rare13.nbt,3,CHEST:3,./StructureNBT/StructureLoot/Rare14.nbt,3,CHEST:3,./StructureNBT/StructureLoot/Rare15.nbt,3,CHEST:3,./StructureNBT/StructureLoot/Epic1.nbt,3,CHEST:3,./StructureNBT/StructureLoot/Epic2.nbt,3,CHEST:3,./StructureNBT/StructureLoot/Epic3.nbt,3,CHEST:3,./StructureNBT/StructureLoot/Epic4.nbt,3,CHEST:3,./StructureNBT/StructureLoot/Epic5.nbt,3,CHEST:3,./StructureNBT/StructureLoot/Epic6.nbt,3,CHEST:3,./StructureNBT/StructureLoot/Epic7.nbt,3,CHEST:3,./StructureNBT/StructureLoot/Epic8.nbt,3,CHEST:3,./StructureNBT/StructureLoot/Epic9.nbt,3,CHEST:3,./StructureNBT/StructureLoot/Epic10.nbt,3,CHEST:3,./StructureNBT/StructureLoot/Epic11.nbt,3,CHEST:3,./StructureNBT/StructureLoot/Epic12.nbt,3,CHEST:3,./StructureNBT/StructureLoot/Epic13.nbt,3,CHEST:3,./StructureNBT/StructureLoot/Epic14.nbt,3,CHEST:3,./StructureNBT/StructureLoot/Epic15.nbt,100)
Block(-4,22,5,air)
Block(-4,22,6,torch)
Block(-4,22,7,log:1)
Block(-4,23,-8,crafting_table)
Block(-4,23,-5,log:1)
Block(-4,23,7,log:1)
Block(-4,24,-8,wooden_slab:8)
Block(-4,24,-7,wooden_slab:9)
Block(-4,24,-6,double_wooden_slab:1)
Block(-4,24,-5,log:1)
Block(-4,24,-4,log:9)
Block(-4,24,-3,log:9)
Block(-4,24,-2,log:9)
Block(-4,24,-1,log:9)
Block(-4,24,0,log:9)
Block(-4,24,1,log:9)
Block(-4,24,2,log:9)
Block(-4,24,3,log:9)
Block(-4,24,4,log:9)
Block(-4,24,5,log:9)
Block(-4,24,6,log:9)
Block(-4,24,7,log:1)
Block(-4,25,-8,double_wooden_slab:1)
Block(-4,25,-7,wooden_slab:1)
Block(-4,25,-6,ladder)
Block(-4,25,-5,log:1)
Block(-4,25,7,log:1)
Block(-4,26,-6,ladder)
Block(-4,26,-5,log:1)
Block(-4,26,7,log:1)
Block(-4,27,-7,wooden_slab:11)
Block(-4,27,-6,ladder)
Block(-4,27,-5,log:1)
Block(-4,27,-4,wooden_slab:13)
Block(-4,27,-3,wooden_slab:13)
Block(-4,27,-2,wooden_slab:13)
Block(-4,27,-1,wooden_slab:13)
Block(-4,27,0,wooden_slab:13)
Block(-4,27,1,wooden_slab:13)
Block(-4,27,2,wooden_slab:13)
Block(-4,27,3,wooden_slab:13)
Block(-4,27,4,wooden_slab:13)
Block(-4,27,5,wooden_slab:13)
Block(-4,27,6,wooden_slab:13)
Block(-4,27,7,log:1)
Block(-4,28,-8,wooden_slab:3)
Block(-4,28,-6,trapdoor)
Block(-4,28,-5,log:1)
Block(-4,28,-4,ladder:3)
Block(-4,28,7,log:1)
Block(-4,29,-8,ladder:3)
Block(-4,29,-5,log:1)
Block(-4,29,-4,ladder:3)
Block(-4,29,6,wall_sign,StructureNBT/SapphireCity/sap11/17-Sign.nbt)
Block(-4,29,7,log:1)
Block(-4,30,-6,dark_oak_fence)
Block(-4,30,-5,log:1)
Block(-4,30,-4,ladder:3)
Block(-4,30,6,dark_oak_fence)
Block(-4,30,7,log:1)
Block(-4,31,-6,torch)
Block(-4,31,-5,log:1)
Block(-4,31,-4,ladder:3)
Block(-4,31,6,torch)
Block(-4,31,7,log:1)
Block(-4,32,-5,log:1)
Block(-4,32,-4,ladder:3)
Block(-4,32,3,wool)
Block(-4,32,4,wool)
Block(-4,32,7,log:1)
Block(-4,33,-5,log:1)
Block(-4,33,-4,ladder:3)
Block(-4,33,3,wool:15)
Block(-4,33,6,dark_oak_stairs:6)
Block(-4,33,7,log:1)
Block(-4,34,-6,dark_oak_stairs:6)
Block(-4,34,-5,log:1)
Block(-4,34,-4,ladder:3)
Block(-4,34,2,wool:15)
Block(-4,34,6,dark_oak_stairs:6)
Block(-4,34,7,log:1)
Block(-4,35,-6,log:1)
Block(-4,35,-5,log:1)
Block(-4,35,-4,ladder:3)
Block(-4,35,2,wool:15)
Block(-4,35,6,log:1)
Block(-4,35,7,log:1)
Block(-4,36,-6,log:1)
Block(-4,36,-5,dark_oak_STAIRS:0)
Block(-4,36,2,wool)
Block(-4,36,6,log:1)
Block(-4,36,7,dark_oak_STAIRS:0)
Block(-4,37,-6,log:1)
Block(-4,37,-5,ladder:3)
Block(-4,37,2,wool)
Block(-4,37,6,log:1)
Block(-4,37,7,ladder:3)
Block(-4,38,-6,log:1)
Block(-4,38,-5,ladder:3)
Block(-4,38,2,wool:15)
Block(-4,38,6,log:1)
Block(-4,38,7,ladder:3)
Block(-4,39,-7,dark_oak_stairs:6)
Block(-4,39,-6,log:1)
Block(-4,39,-5,ladder:3)
Block(-4,39,-4,dark_oak_stairs:7)
Block(-4,39,2,wool:15)
Block(-4,39,6,log:1)
Block(-4,39,7,ladder:3)
Block(-4,40,-7,fence)
Block(-4,40,-6,log:1)
Block(-4,40,-5,ladder:3)
Block(-4,40,-4,fence)
Block(-4,40,-3,fence)
Block(-4,40,3,wool:15)
Block(-4,40,6,log:1)
Block(-4,40,7,ladder:3)
Block(-4,41,-7,dark_oak_stairs:6)
Block(-4,41,-6,log:1)
Block(-4,41,-5,ladder:3)
Block(-4,41,-3,fence)
Block(-4,41,-2,fence)
Block(-4,41,-1,fence)
Block(-4,41,3,wool)
Block(-4,41,4,fence)
Block(-4,41,5,dark_oak_stairs:6)
Block(-4,41,6,log:1)
Block(-4,41,7,ladder:3)
Block(-4,42,-7,log:1)
Block(-4,42,-6,log:1)
Block(-4,42,-5,ladder:3)
Block(-4,42,-1,fence)
Block(-4,42,0,fence)
Block(-4,42,1,fence)
Block(-4,42,4,log:5)
Block(-4,42,5,log:1)
Block(-4,42,6,log:1)
Block(-4,42,7,ladder:3)
Block(-4,43,-7,log:1)
Block(-4,43,-6,dark_oak_STAIRS:0)
Block(-4,43,1,fence)
Block(-4,43,2,fence)
Block(-4,43,3,fence)
Block(-4,43,4,wooden_slab:5)
Block(-4,43,5,log:1)
Block(-4,43,6,dark_oak_STAIRS:0)
Block(-4,44,-7,log:1)
Block(-4,44,-6,ladder:3)
Block(-4,44,3,fence)
Block(-4,44,4,fence)
Block(-4,44,5,log:1)
Block(-4,44,6,ladder:3)
Block(-4,45,-7,log:1)
Block(-4,45,-6,ladder:3)
Block(-4,45,5,log:1)
Block(-4,45,6,ladder:3)
Block(-4,46,-7,log:1)
Block(-4,46,-6,ladder:3)
Block(-4,46,-5,fence)
Block(-4,46,1,wool)
Block(-4,46,2,wool)
Block(-4,46,4,dark_oak_stairs:6)
Block(-4,46,5,log:1)
Block(-4,46,6,ladder:3)
Block(-4,46,7,dark_oak_stairs:7)
Block(-4,47,-7,log:1)
Block(-4,47,-6,ladder:3)
Block(-4,47,-5,fence)
Block(-4,47,-4,fence)
Block(-4,47,0,wool:15)
Block(-4,47,4,fence)
Block(-4,47,5,log:1)
Block(-4,47,6,ladder:3)
Block(-4,47,7,fence)
Block(-4,48,-8,dark_oak_stairs:6)
Block(-4,48,-7,log:1)
Block(-4,48,-6,ladder:3)
Block(-4,48,-5,wool)
Block(-4,48,-4,fence)
Block(-4,48,-3,fence)
Block(-4,48,0,wool:15)
Block(-4,48,4,dark_oak_stairs:6)
Block(-4,48,5,log:1)
Block(-4,48,6,ladder:3)
Block(-4,49,-8,log:1)
Block(-4,49,-7,log:1)
Block(-4,49,-6,ladder:3)
Block(-4,49,-4,wool)
Block(-4,49,-3,fence)
Block(-4,49,-2,fence)
Block(-4,49,0,wool:15)
Block(-4,49,4,log:1)
Block(-4,49,5,log:1)
Block(-4,49,6,ladder:3)
Block(-4,50,-8,log:1)
Block(-4,50,-7,dark_oak_STAIRS:0)
Block(-4,50,-3,wool)
Block(-4,50,-2,fence)
Block(-4,50,-1,fence)
Block(-4,50,1,wool)
Block(-4,50,4,log:1)
Block(-4,50,5,dark_oak_STAIRS:0)
Block(-4,51,-8,log:1)
Block(-4,51,-7,ladder:3)
Block(-4,51,-2,wool)
Block(-4,51,-1,fence)
Block(-4,51,0,fence)
Block(-4,51,1,wool)
Block(-4,51,4,log:1)
Block(-4,51,5,ladder:3)
Block(-4,52,-8,log:1)
Block(-4,52,-7,ladder:3)
Block(-4,52,-1,wool)
Block(-4,52,0,fence)
Block(-4,52,1,fence)
Block(-4,52,2,wool)
Block(-4,52,3,fence)
Block(-4,52,4,log:1)
Block(-4,52,5,ladder:3)
Block(-4,53,-8,log:1)
Block(-4,53,-7,ladder:3)
Block(-4,53,-6,wool:15)
Block(-4,53,0,wool)
Block(-4,53,1,fence)
Block(-4,53,2,fence)
Block(-4,53,3,log:5)
Block(-4,53,4,log:1)
Block(-4,53,5,ladder:3)
Block(-4,54,-8,log:1)
Block(-4,54,-7,ladder:3)
Block(-4,54,-6,wool)
Block(-4,54,1,wool)
Block(-4,54,2,fence)
Block(-4,54,3,fence)
Block(-4,54,4,log:1)
Block(-4,54,5,ladder:3)
Block(-4,55,-8,log:1)
Block(-4,55,-7,ladder:3)
Block(-4,55,-6,fence)
Block(-4,55,-5,wool)
Block(-4,55,2,wool)
Block(-4,55,3,dark_oak_stairs:6)
Block(-4,55,4,log:1)
Block(-4,55,5,ladder:3)
Block(-4,55,7,fence)
Block(-4,56,-8,log:1)
Block(-4,56,-7,ladder:3)
Block(-4,56,-6,fence)
Block(-4,56,-5,fence)
Block(-4,56,-4,wool)
Block(-4,56,3,log:1)
Block(-4,56,4,log:1)
Block(-4,56,5,spruce_fence)
Block(-4,56,6,fence)
Block(-4,56,7,fence)
Block(-4,57,-8,dark_oak_STAIRS:0)
Block(-4,57,-5,fence)
Block(-4,57,-4,fence)
Block(-4,57,-3,wool)
Block(-4,57,-2,wool:15)
Block(-4,57,-1,wool:15)
Block(-4,57,0,wool:15)
Block(-4,57,3,log:1)
Block(-4,57,4,dark_oak_STAIRS:0)
Block(-4,57,5,fence)
Block(-4,57,6,fence)
Block(-4,58,-8,ladder:3)
Block(-4,58,-4,fence)
Block(-4,58,-3,fence)
Block(-4,58,-2,fence)
Block(-4,58,-1,fence)
Block(-4,58,0,fence)
Block(-4,58,1,wool:15)
Block(-4,58,3,log:1)
Block(-4,58,4,fence)
Block(-4,58,5,fence)
Block(-4,59,-8,ladder:3)
Block(-4,59,-5,fence)
Block(-4,59,-4,fence)
Block(-4,59,-3,fence)
Block(-4,59,0,fence)
Block(-4,59,1,fence)
Block(-4,59,2,fence)
Block(-4,59,3,log:1)
Block(-4,60,-8,ladder:3)
Block(-4,60,-7,fence)
Block(-4,60,-6,fence)
Block(-4,60,-5,fence)
Block(-4,60,3,log:1)
Block(-4,61,-8,ladder:3)
Block(-4,61,-7,fence)
Block(-4,61,3,cobblestone_wall)
Block(-4,62,3,cobblestone_wall)
Block(-4,63,3,fence)
Block(-4,64,3,fence)
Block(-4,65,3,fence)
Block(-3,18,-8,planks)
Block(-3,18,-7,planks)
Block(-3,18,-6,planks)
Block(-3,18,-5,planks)
Block(-3,18,-4,planks)
Block(-3,18,-3,planks)
Block(-3,18,-2,planks)
Block(-3,18,-1,planks)
Block(-3,18,0,planks)
Block(-3,18,1,planks)
Block(-3,18,2,planks)
Block(-3,18,3,planks)
Block(-3,18,4,planks)
Block(-3,18,5,planks)
Block(-3,18,6,planks)
Block(-3,18,7,planks)
Block(-3,19,-8,planks)
Block(-3,19,-7,planks)
Block(-3,19,-6,planks)
Block(-3,19,-5,planks)
Block(-3,19,-4,planks)
Block(-3,19,-3,planks)
Block(-3,19,-2,planks)
Block(-3,19,-1,planks)
Block(-3,19,0,planks)
Block(-3,19,1,planks)
Block(-3,19,2,planks)
Block(-3,19,3,planks)
Block(-3,19,4,planks)
Block(-3,19,5,planks)
Block(-3,19,6,planks)
Block(-3,19,7,planks)
Block(-3,20,-8,hay_block:4)
Block(-3,20,-7,hay_block)
Block(-3,20,-6,hay_block)
Block(-3,20,-5,dark_oak_stairs:0)
Block(-3,20,-4,hay_block)
Block(-3,20,-3,hay_block)
Block(-3,20,-2,hay_block)
Block(-3,20,-1,melon_block)
Block(-3,20,0,dark_oak_stairs:0)
Block(-3,20,1,hay_block)
Block(-3,20,2,hay_block:8)
Block(-3,20,3,air)
Block(-3,20,4,hay_block)
Block(-3,20,5,dark_oak_stairs:0)
Block(-3,20,6,hay_block)
Block(-3,20,7,hay_block)
Block(-3,21,-8,hay_block)
Block(-3,21,-7,crafting_table)
Block(-3,21,-6,hay_block)
Block(-3,21,-5,air)
Block(-3,21,-4,crafting_table)
Block(-3,21,-3,hay_block)
Block(-3,21,-2,hay_block:8)
Block(-3,21,-1,hay_block:8)
Block(-3,21,0,hay_block)
Block(-3,21,1,air)
Block(-3,21,2,pumpkin:0)
Block(-3,21,3,hay_block:4)
Block(-3,21,4,hay_block)
Block(-3,21,5,crafting_table)
Block(-3,21,6,air)
Block(-3,21,7,hay_block)
Block(-3,22,-8,hay_block)
Block(-3,22,-7,air)
RandomBlock(-3,22,-6,CHEST:3,./StructureNBT/StructureLoot/JunkChest_1.nbt,20,CHEST:3,./StructureNBT/StructureLoot/JunkChest_2.nbt,15,CHEST:3,./StructureNBT/StructureLoot/JunkChest_3.nbt,15,CHEST:3,./StructureNBT/StructureLoot/JunkChest_4.nbt,15,CHEST:3,./StructureNBT/StructureLoot/JunkChest_5.nbt,15,CHEST:3,./StructureNBT/LoreStoryline/LoreGeneric_5.nbt,2,CHEST:3,./StructureNBT/LoreStoryline/LoreGeneric_4.nbt,2,CHEST:3,./StructureNBT/LoreStoryline/LoreGeneric_3.nbt,2,CHEST:3,./StructureNBT/LoreStoryline/LoreGeneric_2.nbt,2,CHEST:3,./StructureNBT/LoreStoryline/LoreGeneric_1.nbt,2,CHEST:3,./StructureNBT/LoreStoryline/LoreMedievalCity_5.nbt,3,CHEST:3,./StructureNBT/LoreStoryline/LoreMedievalCity_4.nbt,3,CHEST:3,./StructureNBT/LoreStoryline/LoreMedievalCity_3.nbt,3,CHEST:3,./StructureNBT/LoreStoryline/LoreMedievalCity_2.nbt,3,CHEST:3,./StructureNBT/LoreStoryline/LoreMedievalCity_1.nbt,3,CHEST:3,./StructureNBT/StructureLoot/Common1.nbt,3,CHEST:3,./StructureNBT/StructureLoot/Common2.nbt,3,CHEST:3,./StructureNBT/StructureLoot/Common3.nbt,3,CHEST:3,./StructureNBT/StructureLoot/Common4.nbt,3,CHEST:3,./StructureNBT/StructureLoot/Common5.nbt,3,CHEST:3,./StructureNBT/StructureLoot/Common5.nbt,3,CHEST:3,./StructureNBT/StructureLoot/Common6.nbt,3,CHEST:3,./StructureNBT/StructureLoot/Common7.nbt,3,CHEST:3,./StructureNBT/StructureLoot/Common8.nbt,3,CHEST:3,./StructureNBT/StructureLoot/Common9.nbt,3,CHEST:3,./StructureNBT/StructureLoot/Common10.nbt,3,CHEST:3,./StructureNBT/StructureLoot/Common11.nbt,3,CHEST:3,./StructureNBT/StructureLoot/Common12.nbt,3,CHEST:3,./StructureNBT/StructureLoot/Common13.nbt,3,CHEST:3,./StructureNBT/StructureLoot/Common14.nbt,3,CHEST:3,./StructureNBT/StructureLoot/Common15.nbt,3,CHEST:3,./StructureNBT/StructureLoot/Rare1.nbt,3,CHEST:3,./StructureNBT/StructureLoot/Rare2.nbt,3,CHEST:3,./StructureNBT/StructureLoot/Rare3.nbt,3,CHEST:3,./StructureNBT/StructureLoot/Rare4.nbt,3,CHEST:3,./StructureNBT/StructureLoot/Rare5.nbt,3,CHEST:3,./StructureNBT/StructureLoot/Rare6.nbt,3,CHEST:3,./StructureNBT/StructureLoot/Rare7.nbt,3,CHEST:3,./StructureNBT/StructureLoot/Rare8.nbt,3,CHEST:3,./StructureNBT/StructureLoot/Rare9.nbt,3,CHEST:3,./StructureNBT/StructureLoot/Rare10.nbt,3,CHEST:3,./StructureNBT/StructureLoot/Rare11.nbt,3,CHEST:3,./StructureNBT/StructureLoot/Rare12.nbt,3,CHEST:3,./StructureNBT/StructureLoot/Rare13.nbt,3,CHEST:3,./StructureNBT/StructureLoot/Rare14.nbt,3,CHEST:3,./StructureNBT/StructureLoot/Rare15.nbt,3,CHEST:3,./StructureNBT/StructureLoot/Epic1.nbt,3,CHEST:3,./StructureNBT/StructureLoot/Epic2.nbt,3,CHEST:3,./StructureNBT/StructureLoot/Epic3.nbt,3,CHEST:3,./StructureNBT/StructureLoot/Epic4.nbt,3,CHEST:3,./StructureNBT/StructureLoot/Epic5.nbt,3,CHEST:3,./StructureNBT/StructureLoot/Epic6.nbt,3,CHEST:3,./StructureNBT/StructureLoot/Epic7.nbt,3,CHEST:3,./StructureNBT/StructureLoot/Epic8.nbt,3,CHEST:3,./StructureNBT/StructureLoot/Epic9.nbt,3,CHEST:3,./StructureNBT/StructureLoot/Epic10.nbt,3,CHEST:3,./StructureNBT/StructureLoot/Epic11.nbt,3,CHEST:3,./StructureNBT/StructureLoot/Epic12.nbt,3,CHEST:3,./StructureNBT/StructureLoot/Epic13.nbt,3,CHEST:3,./StructureNBT/StructureLoot/Epic14.nbt,3,CHEST:3,./StructureNBT/StructureLoot/Epic15.nbt,100)
Block(-3,22,-5,air)
Block(-3,22,-4,air)
Block(-3,22,-3,hay_block)
Block(-3,22,-2,hay_block)
Block(-3,22,-1,air)
Block(-3,22,0,pumpkin:0)
Block(-3,22,1,air)
Block(-3,22,2,air)
Block(-3,22,3,hay_block)
Block(-3,22,4,air)
Block(-3,22,5,air)
Block(-3,22,6,air)
Block(-3,22,7,air)
Block(-3,24,-8,wooden_slab:8)
Block(-3,24,-7,wooden_slab:8)
Block(-3,24,-6,wooden_slab:8)
Block(-3,24,-5,wooden_slab:8)
Block(-3,24,-4,oak_stairs:5)
Block(-3,24,-3,oak_stairs:5)
Block(-3,24,-2,oak_stairs:5)
Block(-3,24,-1,oak_stairs:5)
Block(-3,24,0,oak_stairs:5)
Block(-3,24,1,oak_stairs:5)
Block(-3,24,2,oak_stairs:5)
Block(-3,24,3,oak_stairs:5)
Block(-3,24,4,oak_stairs:5)
Block(-3,24,5,wooden_slab:8)
Block(-3,24,6,wooden_slab:8)
Block(-3,24,7,wooden_slab:8)
Block(-3,25,0,bed:0)
Block(-3,25,1,bed:8)
RandomBlock(-3,25,2,CHEST:3,./StructureNBT/StructureLoot/JunkChest_1.nbt,20,CHEST:3,./StructureNBT/StructureLoot/JunkChest_2.nbt,15,CHEST:3,./StructureNBT/StructureLoot/JunkChest_3.nbt,15,CHEST:3,./StructureNBT/StructureLoot/JunkChest_4.nbt,15,CHEST:3,./StructureNBT/StructureLoot/JunkChest_5.nbt,15,CHEST:3,./StructureNBT/LoreStoryline/LoreGeneric_5.nbt,2,CHEST:3,./StructureNBT/LoreStoryline/LoreGeneric_4.nbt,2,CHEST:3,./StructureNBT/LoreStoryline/LoreGeneric_3.nbt,2,CHEST:3,./StructureNBT/LoreStoryline/LoreGeneric_2.nbt,2,CHEST:3,./StructureNBT/LoreStoryline/LoreGeneric_1.nbt,2,CHEST:3,./StructureNBT/LoreStoryline/LoreMedievalCity_5.nbt,3,CHEST:3,./StructureNBT/LoreStoryline/LoreMedievalCity_4.nbt,3,CHEST:3,./StructureNBT/LoreStoryline/LoreMedievalCity_3.nbt,3,CHEST:3,./StructureNBT/LoreStoryline/LoreMedievalCity_2.nbt,3,CHEST:3,./StructureNBT/LoreStoryline/LoreMedievalCity_1.nbt,3,CHEST:3,./StructureNBT/StructureLoot/Common1.nbt,3,CHEST:3,./StructureNBT/StructureLoot/Common2.nbt,3,CHEST:3,./StructureNBT/StructureLoot/Common3.nbt,3,CHEST:3,./StructureNBT/StructureLoot/Common4.nbt,3,CHEST:3,./StructureNBT/StructureLoot/Common5.nbt,3,CHEST:3,./StructureNBT/StructureLoot/Common5.nbt,3,CHEST:3,./StructureNBT/StructureLoot/Common6.nbt,3,CHEST:3,./StructureNBT/StructureLoot/Common7.nbt,3,CHEST:3,./StructureNBT/StructureLoot/Common8.nbt,3,CHEST:3,./StructureNBT/StructureLoot/Common9.nbt,3,CHEST:3,./StructureNBT/StructureLoot/Common10.nbt,3,CHEST:3,./StructureNBT/StructureLoot/Common11.nbt,3,CHEST:3,./StructureNBT/StructureLoot/Common12.nbt,3,CHEST:3,./StructureNBT/StructureLoot/Common13.nbt,3,CHEST:3,./StructureNBT/StructureLoot/Common14.nbt,3,CHEST:3,./StructureNBT/StructureLoot/Common15.nbt,3,CHEST:3,./StructureNBT/StructureLoot/Rare1.nbt,3,CHEST:3,./StructureNBT/StructureLoot/Rare2.nbt,3,CHEST:3,./StructureNBT/StructureLoot/Rare3.nbt,3,CHEST:3,./StructureNBT/StructureLoot/Rare4.nbt,3,CHEST:3,./StructureNBT/StructureLoot/Rare5.nbt,3,CHEST:3,./StructureNBT/StructureLoot/Rare6.nbt,3,CHEST:3,./StructureNBT/StructureLoot/Rare7.nbt,3,CHEST:3,./StructureNBT/StructureLoot/Rare8.nbt,3,CHEST:3,./StructureNBT/StructureLoot/Rare9.nbt,3,CHEST:3,./StructureNBT/StructureLoot/Rare10.nbt,3,CHEST:3,./StructureNBT/StructureLoot/Rare11.nbt,3,CHEST:3,./StructureNBT/StructureLoot/Rare12.nbt,3,CHEST:3,./StructureNBT/StructureLoot/Rare13.nbt,3,CHEST:3,./StructureNBT/StructureLoot/Rare14.nbt,3,CHEST:3,./StructureNBT/StructureLoot/Rare15.nbt,3,CHEST:3,./StructureNBT/StructureLoot/Epic1.nbt,3,CHEST:3,./StructureNBT/StructureLoot/Epic2.nbt,3,CHEST:3,./StructureNBT/StructureLoot/Epic3.nbt,3,CHEST:3,./StructureNBT/StructureLoot/Epic4.nbt,3,CHEST:3,./StructureNBT/StructureLoot/Epic5.nbt,3,CHEST:3,./StructureNBT/StructureLoot/Epic6.nbt,3,CHEST:3,./StructureNBT/StructureLoot/Epic7.nbt,3,CHEST:3,./StructureNBT/StructureLoot/Epic8.nbt,3,CHEST:3,./StructureNBT/StructureLoot/Epic9.nbt,3,CHEST:3,./StructureNBT/StructureLoot/Epic10.nbt,3,CHEST:3,./StructureNBT/StructureLoot/Epic11.nbt,3,CHEST:3,./StructureNBT/StructureLoot/Epic12.nbt,3,CHEST:3,./StructureNBT/StructureLoot/Epic13.nbt,3,CHEST:3,./StructureNBT/StructureLoot/Epic14.nbt,3,CHEST:3,./StructureNBT/StructureLoot/Epic15.nbt,100)
Block(-3,27,-8,wooden_slab:11)
Block(-3,27,-7,wooden_slab:11)
Block(-3,27,-6,wooden_slab:11)
Block(-3,27,-5,wooden_slab:11)
Block(-3,27,-4,wooden_slab:11)
Block(-3,27,-3,wooden_slab:11)
Block(-3,27,-2,wooden_slab:11)
Block(-3,27,-1,wooden_slab:11)
Block(-3,27,0,wooden_slab:11)
Block(-3,27,1,wooden_slab:11)
Block(-3,27,2,wooden_slab:11)
Block(-3,27,3,wooden_slab:11)
Block(-3,27,4,wooden_slab:11)
Block(-3,27,5,wooden_slab:11)
Block(-3,27,6,wooden_slab:11)
Block(-3,28,-8,wooden_slab:3)
Block(-3,28,-3,hay_block)
Block(-3,28,7,wooden_slab:3)
Block(-3,29,-3,hay_block)
Block(-3,32,3,wool)
Block(-3,32,4,wool)
Block(-3,33,2,wool:15)
Block(-3,33,6,dark_oak_stairs:6)
Block(-3,33,7,dark_oak_stairs:5)
Block(-3,34,2,wool:15)
Block(-3,34,6,fence)
Block(-3,34,7,fence)
Block(-3,35,2,wool:15)
Block(-3,36,-7,spruce_fence)
Block(-3,36,-6,spruce_fence)
Block(-3,36,2,wool)
Block(-3,36,5,spruce_fence)
Block(-3,36,6,spruce_fence)
Block(-3,37,-7,spruce_fence)
Block(-3,37,-6,spruce_fence)
Block(-3,37,2,wool)
Block(-3,37,5,spruce_fence)
Block(-3,37,6,spruce_fence)
Block(-3,38,-7,spruce_fence)
Block(-3,38,-6,spruce_fence)
Block(-3,38,2,wool)
Block(-3,38,5,spruce_fence)
Block(-3,38,6,spruce_fence)
Block(-3,39,-7,dark_oak_stairs:5)
Block(-3,39,-6,dark_oak_stairs:5)
Block(-3,39,-5,dark_oak_stairs:5)
Block(-3,39,-4,dark_oak_stairs:7)
Block(-3,39,2,wool:15)
Block(-3,39,5,spruce_fence)
Block(-3,39,6,spruce_fence)
Block(-3,40,-7,spruce_fence)
Block(-3,40,-6,spruce_fence)
Block(-3,40,-5,fence)
Block(-3,40,-4,fence)
Block(-3,40,2,wool:15)
Block(-3,40,5,spruce_fence)
Block(-3,40,6,spruce_fence)
Block(-3,41,-7,spruce_fence)
Block(-3,41,-6,spruce_fence)
Block(-3,41,3,wool:15)
Block(-3,41,4,fence)
Block(-3,41,5,spruce_fence)
Block(-3,41,6,spruce_fence)
Block(-3,42,-7,spruce_fence)
Block(-3,42,-6,spruce_fence)
Block(-3,42,4,log:5)
Block(-3,42,5,spruce_fence)
Block(-3,42,6,spruce_fence)
Block(-3,43,-7,spruce_fence)
Block(-3,43,-6,spruce_fence)
Block(-3,43,4,wooden_slab:5)
Block(-3,43,5,spruce_fence)
Block(-3,43,6,spruce_fence)
Block(-3,44,-7,spruce_fence)
Block(-3,44,-6,spruce_fence)
Block(-3,44,5,spruce_fence)
Block(-3,44,6,spruce_fence)
Block(-3,45,-7,spruce_fence)
Block(-3,45,-6,spruce_fence)
Block(-3,45,5,spruce_fence)
Block(-3,45,6,spruce_fence)
Block(-3,46,-7,spruce_fence)
Block(-3,46,-6,spruce_fence)
Block(-3,46,-5,fence)
Block(-3,46,1,wool)
Block(-3,46,2,wool)
Block(-3,46,4,dark_oak_stairs:6)
Block(-3,46,5,dark_oak_stairs:5)
Block(-3,46,6,dark_oak_stairs:5)
Block(-3,46,7,dark_oak_stairs:7)
Block(-3,47,-7,spruce_fence)
Block(-3,47,-6,spruce_fence)
Block(-3,47,0,wool:15)
Block(-3,47,4,fence)
Block(-3,47,5,spruce_fence)
Block(-3,47,6,spruce_fence)
Block(-3,47,7,fence)
Block(-3,48,-7,spruce_fence)
Block(-3,48,-6,spruce_fence)
Block(-3,48,0,wool:15)
Block(-3,48,5,spruce_fence)
Block(-3,48,6,spruce_fence)
Block(-3,49,-8,spruce_fence)
Block(-3,49,-7,spruce_fence)
Block(-3,49,-6,spruce_fence)
Block(-3,49,0,wool:15)
Block(-3,49,4,spruce_fence)
Block(-3,49,5,spruce_fence)
Block(-3,49,6,spruce_fence)
Block(-3,50,-8,dark_oak_stairs:5)
Block(-3,50,-7,dark_oak_stairs:5)
Block(-3,50,0,wool:15)
Block(-3,50,4,spruce_fence)
Block(-3,50,5,spruce_fence)
Block(-3,51,1,wool:15)
Block(-3,51,4,spruce_fence)
Block(-3,51,5,spruce_fence)
Block(-3,52,2,wool)
Block(-3,52,3,fence)
Block(-3,52,4,spruce_fence)
Block(-3,52,5,spruce_fence)
Block(-3,53,-8,spruce_fence)
Block(-3,53,-7,spruce_fence)
Block(-3,53,3,log:5)
Block(-3,53,4,spruce_fence)
Block(-3,53,5,spruce_fence)
Block(-3,54,-8,spruce_fence)
Block(-3,54,-7,spruce_fence)
Block(-3,54,3,wooden_slab:5)
Block(-3,54,4,spruce_fence)
Block(-3,54,5,spruce_fence)
Block(-3,55,-8,spruce_fence)
Block(-3,55,-7,spruce_fence)
Block(-3,55,-6,fence)
Block(-3,55,4,spruce_fence)
Block(-3,55,5,spruce_fence)
Block(-3,56,-8,spruce_fence)
Block(-3,56,-7,spruce_fence)
Block(-3,56,4,spruce_fence)
Block(-3,56,5,spruce_fence)
Block(-3,60,-8,dark_oak_stairs:7)
Block(-3,61,-8,fence)
Block(-3,61,-7,fence)
Block(-2,19,-8,planks)
Block(-2,19,-7,planks)
Block(-2,19,-6,planks)
Block(-2,19,-5,planks)
Block(-2,19,-4,planks)
Block(-2,19,-3,planks)
Block(-2,19,-2,planks)
Block(-2,19,-1,planks)
Block(-2,19,0,planks)
Block(-2,19,1,planks)
Block(-2,19,2,planks)
Block(-2,19,3,planks)
Block(-2,19,4,planks)
Block(-2,19,5,planks)
Block(-2,19,6,planks)
Block(-2,19,7,planks)
Block(-2,20,-8,hay_block:4)
Block(-2,20,-7,hay_block:4)
Block(-2,20,-6,hay_block)
Block(-2,20,-5,planks:5)
Block(-2,20,-4,hay_block)
Block(-2,20,-3,hay_block)
Block(-2,20,-2,pumpkin:1)
Block(-2,20,-1,hay_block)
Block(-2,20,0,planks:5)
Block(-2,20,1,hay_block:4)
Block(-2,20,2,hay_block:4)
Block(-2,20,3,hay_block)
Block(-2,20,4,hay_block)
Block(-2,20,5,planks:5)
Block(-2,20,6,hay_block:8)
Block(-2,20,7,hay_block:4)
Block(-2,21,-8,crafting_table)
Block(-2,21,-7,hay_block)
RandomBlock(-2,21,-6,CHEST:4,./StructureNBT/StructureLoot/JunkChest_1.nbt,20,CHEST:4,./StructureNBT/StructureLoot/JunkChest_2.nbt,15,CHEST:4,./StructureNBT/StructureLoot/JunkChest_3.nbt,15,CHEST:4,./StructureNBT/StructureLoot/JunkChest_4.nbt,15,CHEST:4,./StructureNBT/StructureLoot/JunkChest_5.nbt,15,CHEST:4,./StructureNBT/LoreStoryline/LoreGeneric_5.nbt,2,CHEST:4,./StructureNBT/LoreStoryline/LoreGeneric_4.nbt,2,CHEST:4,./StructureNBT/LoreStoryline/LoreGeneric_3.nbt,2,CHEST:4,./StructureNBT/LoreStoryline/LoreGeneric_2.nbt,2,CHEST:4,./StructureNBT/LoreStoryline/LoreGeneric_1.nbt,2,CHEST:4,./StructureNBT/LoreStoryline/LoreMedievalCity_5.nbt,3,CHEST:4,./StructureNBT/LoreStoryline/LoreMedievalCity_4.nbt,3,CHEST:4,./StructureNBT/LoreStoryline/LoreMedievalCity_3.nbt,3,CHEST:4,./StructureNBT/LoreStoryline/LoreMedievalCity_2.nbt,3,CHEST:4,./StructureNBT/LoreStoryline/LoreMedievalCity_1.nbt,3,CHEST:4,./StructureNBT/StructureLoot/Common1.nbt,3,CHEST:4,./StructureNBT/StructureLoot/Common2.nbt,3,CHEST:4,./StructureNBT/StructureLoot/Common3.nbt,3,CHEST:4,./StructureNBT/StructureLoot/Common4.nbt,3,CHEST:4,./StructureNBT/StructureLoot/Common5.nbt,3,CHEST:4,./StructureNBT/StructureLoot/Common5.nbt,3,CHEST:4,./StructureNBT/StructureLoot/Common6.nbt,3,CHEST:4,./StructureNBT/StructureLoot/Common7.nbt,3,CHEST:4,./StructureNBT/StructureLoot/Common8.nbt,3,CHEST:4,./StructureNBT/StructureLoot/Common9.nbt,3,CHEST:4,./StructureNBT/StructureLoot/Common10.nbt,3,CHEST:4,./StructureNBT/StructureLoot/Common11.nbt,3,CHEST:4,./StructureNBT/StructureLoot/Common12.nbt,3,CHEST:4,./StructureNBT/StructureLoot/Common13.nbt,3,CHEST:4,./StructureNBT/StructureLoot/Common14.nbt,3,CHEST:4,./StructureNBT/StructureLoot/Common15.nbt,3,CHEST:4,./StructureNBT/StructureLoot/Rare1.nbt,3,CHEST:4,./StructureNBT/StructureLoot/Rare2.nbt,3,CHEST:4,./StructureNBT/StructureLoot/Rare3.nbt,3,CHEST:4,./StructureNBT/StructureLoot/Rare4.nbt,3,CHEST:4,./StructureNBT/StructureLoot/Rare5.nbt,3,CHEST:4,./StructureNBT/StructureLoot/Rare6.nbt,3,CHEST:4,./StructureNBT/StructureLoot/Rare7.nbt,3,CHEST:4,./StructureNBT/StructureLoot/Rare8.nbt,3,CHEST:4,./StructureNBT/StructureLoot/Rare9.nbt,3,CHEST:4,./StructureNBT/StructureLoot/Rare10.nbt,3,CHEST:4,./StructureNBT/StructureLoot/Rare11.nbt,3,CHEST:4,./StructureNBT/StructureLoot/Rare12.nbt,3,CHEST:4,./StructureNBT/StructureLoot/Rare13.nbt,3,CHEST:4,./StructureNBT/StructureLoot/Rare14.nbt,3,CHEST:4,./StructureNBT/StructureLoot/Rare15.nbt,3,CHEST:4,./StructureNBT/StructureLoot/Epic1.nbt,3,CHEST:4,./StructureNBT/StructureLoot/Epic2.nbt,3,CHEST:4,./StructureNBT/StructureLoot/Epic3.nbt,3,CHEST:4,./StructureNBT/StructureLoot/Epic4.nbt,3,CHEST:4,./StructureNBT/StructureLoot/Epic5.nbt,3,CHEST:4,./StructureNBT/StructureLoot/Epic6.nbt,3,CHEST:4,./StructureNBT/StructureLoot/Epic7.nbt,3,CHEST:4,./StructureNBT/StructureLoot/Epic8.nbt,3,CHEST:4,./StructureNBT/StructureLoot/Epic9.nbt,3,CHEST:4,./StructureNBT/StructureLoot/Epic10.nbt,3,CHEST:4,./StructureNBT/StructureLoot/Epic11.nbt,3,CHEST:4,./StructureNBT/StructureLoot/Epic12.nbt,3,CHEST:4,./StructureNBT/StructureLoot/Epic13.nbt,3,CHEST:4,./StructureNBT/StructureLoot/Epic14.nbt,3,CHEST:4,./StructureNBT/StructureLoot/Epic15.nbt,100)
Block(-2,21,-5,dark_oak_stairs:0)
Block(-2,21,-4,hay_block)
Block(-2,21,-3,hay_block:4)
Block(-2,21,-2,hay_block:4)
Block(-2,21,-1,hay_block:4)
Block(-2,21,0,dark_oak_stairs:0)
Block(-2,21,1,hay_block)
Block(-2,21,2,hay_block:4)
Block(-2,21,3,hay_block)
Block(-2,21,4,hay_block:8)
Block(-2,21,5,dark_oak_stairs:0)
Block(-2,21,6,melon_block)
Block(-2,21,7,hay_block)
Block(-2,22,-8,melon_block)
Block(-2,22,-7,hay_block)
Block(-2,22,-6,air)
Block(-2,22,-5,air)
