
#######################################################################
# +-----------------------------------------------------------------+ #
# |                            BO3 object                           | #
# +-----------------------------------------------------------------+ #
#######################################################################

Author: NLBlackEagle

Description: No description given

Version: 3

SettingsMode: WriteDisable


#######################################################################
# +-----------------------------------------------------------------+ #
# |                          Main settings                          | #
# +-----------------------------------------------------------------+ #
#######################################################################

Tree: false

Frequency: 1

Rarity: 25.0

RotateRandomly: false

SpawnHeight: randomY

SpawnHeightOffset: 0

SpawnHeightVariance: 0

##############################
# Height Limits for the BO3. #
##############################

MinHeight: 47

MaxHeight: 47

######################
# Extrusion settings #
######################

ExtrudeMode: None

ExtrudeThroughBlocks: air

MaxBranchDepth: 60

ExcludedBiomes: All


#######################################################################
# +-----------------------------------------------------------------+ #
# |                      Source block settings                      | #
# +-----------------------------------------------------------------+ #
#######################################################################

SourceBlocks: air

MaxPercentageOutsideSourceBlock: 100

OutsideSourceBlock: placeAnyway


#######################################################################
# +-----------------------------------------------------------------+ #
# |                              Blocks                             | #
# +-----------------------------------------------------------------+ #
#######################################################################

Block(-1,1,4,cobblestone)
Block(-1,1,5,log)
Block(-1,1,6,cobblestone)
Block(-1,2,4,cobblestone)
Block(-1,2,5,log)
Block(-1,2,6,cobblestone)
Block(-1,3,4,cobblestone)
Block(-1,3,5,log)
Block(-1,3,6,cobblestone)
Block(-1,4,4,cobblestone)
Block(-1,4,5,log)
Block(-1,4,6,cobblestone)
Block(-1,5,4,cobblestone)
Block(-1,5,5,log)
Block(-1,5,6,cobblestone)
Block(-1,6,4,cobblestone)
Block(-1,6,5,log)
Block(-1,6,6,cobblestone)
Block(-1,7,4,cobblestone)
Block(-1,7,5,log)
Block(-1,7,6,cobblestone)
Block(-1,8,4,cobblestone)
Block(-1,8,5,log)
Block(-1,8,6,cobblestone)
Block(-1,9,4,cobblestone)
Block(-1,9,5,log)
Block(-1,9,6,cobblestone)
Block(-1,10,4,cobblestone)
Block(-1,10,5,log)
Block(-1,10,6,cobblestone)
Block(-1,11,4,cobblestone)
Block(-1,11,5,log)
Block(-1,11,6,cobblestone)
Block(-1,12,4,stone_stairs:2)
Block(-1,12,5,stone_brick_stairs:0)
Block(-1,12,6,stone_stairs:0)
Block(-1,38,5,wooden_slab:5)
Block(0,1,3,log)
Block(0,1,4,air)
Block(0,1,5,air)
Block(0,1,6,air)
Block(0,1,7,log)
Block(0,2,3,log)
Block(0,2,4,air)
Block(0,2,5,air)
Block(0,2,6,air)
Block(0,2,7,log)
Block(0,3,3,log)
Block(0,3,4,air)
Block(0,3,5,air)
Block(0,3,6,air)
Block(0,3,7,log)
Block(0,4,3,log)
Block(0,4,4,air)
Block(0,4,5,air)
Block(0,4,6,air)
Block(0,4,7,log)
Block(0,5,3,log)
Block(0,5,4,air)
Block(0,5,5,air)
Block(0,5,6,air)
Block(0,5,7,log)
Block(0,6,3,log)
Block(0,6,4,air)
Block(0,6,5,air)
Block(0,6,6,air)
Block(0,6,7,log)
Block(0,7,3,log)
Block(0,7,4,air)
Block(0,7,5,air)
Block(0,7,6,air)
Block(0,7,7,log)
Block(0,8,3,log)
Block(0,8,4,air)
Block(0,8,5,air)
Block(0,8,6,air)
Block(0,8,7,log)
Block(0,9,3,log)
Block(0,9,4,air)
Block(0,9,5,air)
Block(0,9,6,air)
Block(0,9,7,log)
Block(0,10,3,log)
Block(0,10,4,air)
Block(0,10,5,air)
Block(0,10,6,air)
Block(0,10,7,log)
Block(0,11,3,log)
Block(0,11,4,cobblestone)
Block(0,11,5,cobblestone)
Block(0,11,6,cobblestone)
Block(0,11,7,log)
Block(0,12,3,stone_brick_stairs:2)
Block(0,12,4,stone_stairs:0)
Block(0,12,5,log:4)
Block(0,12,6,stone_STAIRS:0)
Block(0,12,7,stone_brick_stairs:0)
Block(0,13,5,log)
Block(0,14,5,log)
Block(0,15,5,log)
Block(0,16,5,log)
Block(0,17,5,stone_stairs:0)
Block(0,37,5,dark_oak_stairs:4)
Block(0,38,5,wooden_slab:5)
Block(1,1,1,log)
Block(1,1,2,cobblestone)
Block(1,1,3,air)
Block(1,1,4,air)
Block(1,1,5,air)
Block(1,1,6,air)
Block(1,1,7,air)
Block(1,2,1,log)
Block(1,2,2,cobblestone)
Block(1,2,3,air)
Block(1,2,4,air)
Block(1,2,5,air)
Block(1,2,6,air)
Block(1,2,7,air)
Block(1,3,1,log)
Block(1,3,2,cobblestone)
Block(1,3,3,air)
Block(1,3,4,air)
Block(1,3,5,air)
Block(1,3,6,air)
Block(1,3,7,air)
Block(1,4,1,log)
Block(1,4,2,cobblestone)
Block(1,4,3,air)
Block(1,4,4,air)
Block(1,4,5,air)
Block(1,4,6,air)
Block(1,4,7,air)
Block(1,5,1,log)
Block(1,5,2,cobblestone)
Block(1,5,3,air)
Block(1,5,4,air)
Block(1,5,5,air)
Block(1,5,6,air)
Block(1,5,7,air)
Block(1,6,1,log)
Block(1,6,2,cobblestone)
Block(1,6,3,air)
Block(1,6,4,air)
Block(1,6,5,air)
Block(1,6,6,air)
Block(1,6,7,air)
Block(1,7,1,log)
Block(1,7,2,cobblestone)
Block(1,7,3,air)
Block(1,7,4,air)
Block(1,7,5,air)
Block(1,7,6,air)
Block(1,7,7,air)
Block(1,8,1,log)
Block(1,8,2,cobblestone)
Block(1,8,3,air)
Block(1,8,4,air)
Block(1,8,5,air)
Block(1,8,6,air)
Block(1,8,7,air)
Block(1,9,1,log)
Block(1,9,2,cobblestone)
Block(1,9,3,air)
Block(1,9,4,air)
Block(1,9,5,air)
Block(1,9,6,air)
Block(1,9,7,air)
Block(1,10,1,log)
Block(1,10,2,cobblestone)
Block(1,10,3,air)
Block(1,10,4,air)
Block(1,10,5,air)
Block(1,10,6,air)
Block(1,10,7,air)
Block(1,11,1,log)
Block(1,11,2,cobblestone)
Block(1,11,3,cobblestone)
Block(1,11,4,cobblestone)
Block(1,11,5,cobblestone)
Block(1,11,6,cobblestone)
Block(1,11,7,cobblestone)
Block(1,12,1,stone_brick_stairs:2)
Block(1,12,2,stone_stairs:0)
Block(1,12,3,stone_stairs:0)
Block(1,12,4,stone:6)
Block(1,12,5,log:4)
Block(1,12,6,stone:6)
Block(1,12,7,log:4)
Block(1,13,4,stone:6)
Block(1,13,5,air)
Block(1,13,6,stone:6)
Block(1,13,7,log)
Block(1,14,4,stone:6)
Block(1,14,5,air)
Block(1,14,6,stone:6)
Block(1,14,7,log)
Block(1,15,4,stone:6)
Block(1,15,5,air)
Block(1,15,6,stone:6)
Block(1,15,7,log)
Block(1,16,4,stone_stairs:0)
Block(1,16,5,air)
Block(1,16,6,stone_stairs:0)
Block(1,16,7,log)
Block(1,17,5,log:4)
Block(1,17,7,stone_stairs:0)
Block(1,30,4,dark_oak_stairs:6)
Block(1,30,5,dark_oak_stairs:4)
Block(1,30,6,dark_oak_stairs:7)
Block(1,31,3,dark_oak_stairs:6)
Block(1,31,4,dark_oak_STAIRS:0)
Block(1,31,5,cobblestone)
Block(1,31,6,dark_oak_stairs:2)
Block(1,31,7,dark_oak_stairs:7)
Block(1,32,5,log)
Block(1,33,2,wooden_slab:5)
Block(1,33,3,dark_oak_stairs:0)
Block(1,33,4,wooden_slab:5)
Block(1,33,5,log)
Block(1,33,6,wooden_slab:5)
Block(1,33,7,dark_oak_stairs:0)
Block(1,34,5,dark_oak_stairs:0)
Block(1,36,2,dark_oak_stairs:0)
Block(1,36,3,double_wooden_slab:5)
Block(1,36,4,wooden_slab:13)
Block(1,36,5,wooden_slab:13)
Block(1,36,6,wooden_slab:13)
Block(1,36,7,double_wooden_slab:5)
Block(1,37,4,dark_oak_stairs:0)
Block(1,37,5,double_wooden_slab:5)
Block(1,37,6,dark_oak_stairs:0)
Block(1,38,5,wooden_slab:5)
Block(1,43,3,stone_stairs:4)
Block(1,43,7,stone_stairs:4)
Block(1,44,3,stone_stairs:0)
Block(1,44,7,stone_stairs:0)
Block(1,45,3,stone_stairs:4)
Block(1,45,4,wooden_slab:13)
Block(1,45,5,stone_stairs:4)
Block(1,45,6,wooden_slab:13)
Block(1,45,7,stone_stairs:4)
Block(1,46,2,stone_brick_stairs:6)
Block(1,46,3,stone_brick_STAIRS:0)
Block(1,46,4,double_wooden_slab:5)
Block(1,46,5,wooden_slab:5)
Block(1,46,6,double_wooden_slab:5)
Block(1,46,7,stone_brick_stairs:2)
Block(1,47,4,stone_slab:3)
Block(1,47,6,stone_slab:3)
Block(2,1,0,cobblestone)
Block(2,1,4,cobblestone)
Block(2,1,5,log)
Block(2,1,6,cobblestone)
Block(2,2,0,cobblestone)
Block(2,2,4,cobblestone)
Block(2,2,5,log)
Block(2,2,6,cobblestone)
Block(2,3,0,cobblestone)
Block(2,3,4,cobblestone)
Block(2,3,5,log)
Block(2,3,6,cobblestone)
Block(2,4,0,cobblestone)
Block(2,4,4,cobblestone)
Block(2,4,5,log)
Block(2,4,6,cobblestone)
Block(2,5,0,cobblestone)
Block(2,5,4,cobblestone)
Block(2,5,5,log)
Block(2,5,6,cobblestone)
Block(2,6,0,cobblestone)
Block(2,6,4,cobblestone)
Block(2,6,5,log)
Block(2,6,6,cobblestone)
Block(2,7,0,cobblestone)
Block(2,7,4,cobblestone)
Block(2,7,5,log)
Block(2,7,6,cobblestone)
Block(2,8,0,cobblestone)
Block(2,8,4,cobblestone)
Block(2,8,5,log)
Block(2,8,6,cobblestone)
Block(2,9,0,cobblestone)
Block(2,9,4,cobblestone)
Block(2,9,5,log)
Block(2,9,6,cobblestone)
Block(2,10,0,cobblestone)
Block(2,10,4,cobblestone)
Block(2,10,5,log)
Block(2,10,6,cobblestone)
Block(2,11,0,cobblestone)
Block(2,11,1,cobblestone)
Block(2,11,2,cobblestone)
Block(2,11,3,cobblestone)
Block(2,11,4,cobblestone)
Block(2,11,5,log)
Block(2,11,6,cobblestone)
Block(2,11,7,cobblestone)
Block(2,12,0,stone_stairs:2)
Block(2,12,1,stone_stairs:0)
Block(2,12,2,stone:6)
Block(2,12,3,stone:6)
Block(2,12,4,cobblestone)
Block(2,12,5,log)
Block(2,12,6,cobblestone)
Block(2,12,7,log:4)
Block(2,13,2,stone:6)
Block(2,13,3,stone:6)
Block(2,13,4,stone:6)
Block(2,13,5,log)
Block(2,13,6,stone:6)
Block(2,14,2,stone:6)
Block(2,14,3,stone:6)
Block(2,14,4,stone:6)
Block(2,14,5,log)
Block(2,14,6,stone:6)
Block(2,15,2,stone:6)
Block(2,15,3,stone:6)
Block(2,15,4,stone:6)
Block(2,15,5,log)
Block(2,15,6,stone:6)
Block(2,16,2,stone_stairs:2)
Block(2,16,3,stone:6)
Block(2,16,4,stone:6)
Block(2,16,5,log)
Block(2,16,6,stone:6)
Block(2,17,4,stone:6)
Block(2,17,5,log)
Block(2,17,6,stone:6)
Block(2,17,7,log:4)
Block(2,18,4,stone:6)
Block(2,18,5,log)
Block(2,18,6,stone:6)
Block(2,19,4,stone:6)
Block(2,19,5,log)
Block(2,19,6,stone:6)
Block(2,20,4,stone:6)
Block(2,20,5,log)
Block(2,20,6,stone:6)
Block(2,21,4,stone:6)
Block(2,21,5,log)
Block(2,21,6,stone:6)
Block(2,22,4,stone:6)
Block(2,22,5,log)
Block(2,22,6,stone:6)
Block(2,23,4,stone:6)
Block(2,23,5,log)
Block(2,23,6,stone:6)
Block(2,24,4,stone:6)
Block(2,24,5,log)
Block(2,24,6,stone:6)
Block(2,25,4,stone:6)
Block(2,25,5,log)
Block(2,25,6,stone:6)
Block(2,26,4,stone:6)
Block(2,26,5,log)
Block(2,26,6,stone:6)
Block(2,27,4,stonebrick)
Block(2,27,5,log)
Block(2,27,6,stonebrick)
Block(2,28,3,stone_brick_stairs:6)
Block(2,28,4,log:8)
Block(2,28,5,log)
Block(2,28,6,log:8)
Block(2,28,7,stone_brick_stairs:7)
Block(2,29,3,stone_brick_STAIRS:0)
Block(2,29,4,wooden_slab:5)
Block(2,29,5,log)
Block(2,29,6,wooden_slab:5)
Block(2,29,7,stone_brick_stairs:2)
Block(2,30,2,stone_slab:13)
Block(2,30,3,stone_brick_stairs:6)
Block(2,30,4,log:8)
Block(2,30,5,log)
Block(2,30,6,log:8)
Block(2,30,7,stone_brick_stairs:7)
Block(2,31,2,stone:6)
Block(2,31,3,log)
Block(2,31,7,log)
Block(2,32,3,log)
Block(2,32,7,log)
Block(2,33,1,wooden_slab:5)
Block(2,33,2,double_wooden_slab:5)
Block(2,33,3,log)
Block(2,33,4,stone_stairs:7)
Block(2,33,5,wooden_slab:13)
Block(2,33,6,stone_stairs:6)
Block(2,33,7,log)
Block(2,34,3,log)
Block(2,34,4,log:8)
Block(2,34,5,log:8)
Block(2,34,6,log:8)
Block(2,34,7,log)
Block(2,35,3,log)
Block(2,35,4,stone_STAIRS:0)
Block(2,35,5,stone_stairs:0)
Block(2,35,6,stone_stairs:2)
Block(2,35,7,log)
Block(2,36,2,dark_oak_stairs:2)
Block(2,36,3,log)
Block(2,36,4,stone_stairs:4)
Block(2,36,5,stone_stairs:4)
Block(2,36,6,stone_stairs:4)
Block(2,36,7,log)
Block(2,37,3,stone_stairs:0)
Block(2,37,4,dark_oak_stairs:2)
Block(2,37,5,double_wooden_slab:5)
Block(2,37,6,dark_oak_STAIRS:0)
Block(2,37,7,stone_stairs:0)
Block(2,38,5,dark_oak_stairs:0)
Block(2,42,5,stone_stairs:4)
Block(2,43,3,dark_oak_stairs:4)
Block(2,43,5,log)
Block(2,43,7,dark_oak_stairs:4)
Block(2,44,1,wooden_slab:13)
Block(2,44,2,dark_oak_stairs:4)
Block(2,44,3,stone_stairs:1)
Block(2,44,5,log)
Block(2,44,7,stone_stairs:1)
Block(2,45,1,cobblestone)
Block(2,45,2,log:8)
Block(2,45,3,log:4)
Block(2,45,4,stonebrick:3)
Block(2,45,5,stone_stairs:1)
Block(2,45,6,stonebrick:3)
Block(2,45,7,log:4)
Block(2,46,1,stonebrick)
Block(2,47,1,wooden_slab:5)
Block(3,1,-1,log)
Block(3,1,3,log)
Block(3,1,7,log)
Block(3,2,-1,log)
Block(3,2,3,log)
Block(3,2,7,log)
Block(3,3,-1,log)
Block(3,3,3,log)
Block(3,3,7,log)
Block(3,4,-1,log)
Block(3,4,3,log)
Block(3,4,7,log)
Block(3,5,-1,log)
Block(3,5,3,log)
Block(3,5,7,log)
Block(3,6,-1,log)
Block(3,6,3,log)
Block(3,6,7,log)
Block(3,7,-1,log)
Block(3,7,3,log)
Block(3,7,7,log)
Block(3,8,-1,log)
Block(3,8,3,log)
Block(3,8,7,log)
Block(3,9,-1,log)
Block(3,9,3,log)
Block(3,9,7,log)
Block(3,10,-1,log)
Block(3,10,3,log)
Block(3,10,7,log)
Block(3,11,-1,log)
Block(3,11,0,cobblestone)
Block(3,11,1,cobblestone)
Block(3,11,2,cobblestone)
Block(3,11,3,log)
Block(3,11,7,log)
Block(3,12,-1,stone_brick_stairs:2)
Block(3,12,0,stone_stairs:0)
Block(3,12,1,log:8)
Block(3,12,2,log:8)
Block(3,12,3,log)
Block(3,12,7,log)
Block(3,13,1,log)
Block(3,13,3,log)
Block(3,13,7,log)
Block(3,14,1,log)
Block(3,14,3,log)
Block(3,14,7,log)
Block(3,15,1,log)
Block(3,15,3,log)
Block(3,15,7,log)
Block(3,16,1,log)
Block(3,16,3,log)
Block(3,16,7,log)
Block(3,17,1,stone_stairs:2)
Block(3,17,2,log:8)
Block(3,17,3,log)
Block(3,17,7,log)
Block(3,18,3,log)
Block(3,18,7,log)
Block(3,19,3,log)
Block(3,19,7,log)
Block(3,20,3,log)
Block(3,20,7,log)
Block(3,21,3,log)
Block(3,21,7,log)
Block(3,22,3,log)
Block(3,22,7,log)
Block(3,23,3,log)
Block(3,23,7,log)
Block(3,24,3,log)
Block(3,24,4,stonebrick)
Block(3,24,5,stonebrick)
Block(3,24,6,stonebrick)
Block(3,24,7,log)
Block(3,25,3,log)
Block(3,25,4,stonebrick)
Block(3,25,5,stonebrick)
Block(3,25,6,stonebrick)
Block(3,25,7,log)
Block(3,26,3,log)
Block(3,26,4,stonebrick)
Block(3,26,5,stonebrick)
Block(3,26,6,stonebrick)
Block(3,26,7,log)
Block(3,27,3,log)
Block(3,27,4,stonebrick)
Block(3,27,5,stonebrick)
Block(3,27,6,stonebrick)
Block(3,27,7,log)
Block(3,28,2,stone_brick_stairs:4)
Block(3,28,3,log)
Block(3,28,7,log)
Block(3,29,2,wooden_slab:5)
Block(3,29,3,log)
Block(3,29,7,log)
Block(3,30,1,double_stone_slab:5)
Block(3,30,2,double_wooden_slab:5)
Block(3,30,3,log)
Block(3,30,4,wooden_slab:13)
Block(3,30,5,wooden_slab:13)
Block(3,30,6,wooden_slab:13)
Block(3,30,7,log)
Block(3,31,1,log)
Block(3,31,3,log)
Block(3,31,7,log)
Block(3,32,1,cobblestone)
Block(3,32,3,log)
Block(3,32,7,log)
Block(3,33,0,wooden_slab:5)
Block(3,33,1,double_wooden_slab:5)
Block(3,33,2,log:8)
Block(3,33,3,log)
Block(3,33,4,wooden_slab:13)
Block(3,33,5,wooden_slab:13)
Block(3,33,6,wooden_slab:13)
Block(3,33,7,log)
Block(3,34,2,stone:6)
Block(3,34,3,log)
Block(3,34,4,anvil:1)
RandomBlock(3,34,5,CHEST:5,./StructureNBT/StructureLoot/JunkChest_1.nbt,20,CHEST:5,./StructureNBT/StructureLoot/JunkChest_2.nbt,15,CHEST:5,./StructureNBT/StructureLoot/JunkChest_3.nbt,15,CHEST:5,./StructureNBT/StructureLoot/JunkChest_4.nbt,15,CHEST:5,./StructureNBT/StructureLoot/JunkChest_5.nbt,15,CHEST:5,./StructureNBT/LoreStoryline/LoreGeneric_5.nbt,2,CHEST:5,./StructureNBT/LoreStoryline/LoreGeneric_4.nbt,2,CHEST:5,./StructureNBT/LoreStoryline/LoreGeneric_3.nbt,2,CHEST:5,./StructureNBT/LoreStoryline/LoreGeneric_2.nbt,2,CHEST:5,./StructureNBT/LoreStoryline/LoreGeneric_1.nbt,2,CHEST:5,./StructureNBT/LoreStoryline/LoreMedievalCity_5.nbt,3,CHEST:5,./StructureNBT/LoreStoryline/LoreMedievalCity_4.nbt,3,CHEST:5,./StructureNBT/LoreStoryline/LoreMedievalCity_3.nbt,3,CHEST:5,./StructureNBT/LoreStoryline/LoreMedievalCity_2.nbt,3,CHEST:5,./StructureNBT/LoreStoryline/LoreMedievalCity_1.nbt,3,CHEST:5,./StructureNBT/StructureLoot/Common1.nbt,3,CHEST:5,./StructureNBT/StructureLoot/Common2.nbt,3,CHEST:5,./StructureNBT/StructureLoot/Common3.nbt,3,CHEST:5,./StructureNBT/StructureLoot/Common4.nbt,3,CHEST:5,./StructureNBT/StructureLoot/Common5.nbt,3,CHEST:5,./StructureNBT/StructureLoot/Common5.nbt,3,CHEST:5,./StructureNBT/StructureLoot/Common6.nbt,3,CHEST:5,./StructureNBT/StructureLoot/Common7.nbt,3,CHEST:5,./StructureNBT/StructureLoot/Common8.nbt,3,CHEST:5,./StructureNBT/StructureLoot/Common9.nbt,3,CHEST:5,./StructureNBT/StructureLoot/Common10.nbt,3,CHEST:5,./StructureNBT/StructureLoot/Common11.nbt,3,CHEST:5,./StructureNBT/StructureLoot/Common12.nbt,3,CHEST:5,./StructureNBT/StructureLoot/Common13.nbt,3,CHEST:5,./StructureNBT/StructureLoot/Common14.nbt,3,CHEST:5,./StructureNBT/StructureLoot/Common15.nbt,3,CHEST:5,./StructureNBT/StructureLoot/Rare1.nbt,3,CHEST:5,./StructureNBT/StructureLoot/Rare2.nbt,3,CHEST:5,./StructureNBT/StructureLoot/Rare3.nbt,3,CHEST:5,./StructureNBT/StructureLoot/Rare4.nbt,3,CHEST:5,./StructureNBT/StructureLoot/Rare5.nbt,3,CHEST:5,./StructureNBT/StructureLoot/Rare6.nbt,3,CHEST:5,./StructureNBT/StructureLoot/Rare7.nbt,3,CHEST:5,./StructureNBT/StructureLoot/Rare8.nbt,3,CHEST:5,./StructureNBT/StructureLoot/Rare9.nbt,3,CHEST:5,./StructureNBT/StructureLoot/Rare10.nbt,3,CHEST:5,./StructureNBT/StructureLoot/Rare11.nbt,3,CHEST:5,./StructureNBT/StructureLoot/Rare12.nbt,3,CHEST:5,./StructureNBT/StructureLoot/Rare13.nbt,3,CHEST:5,./StructureNBT/StructureLoot/Rare14.nbt,3,CHEST:5,./StructureNBT/StructureLoot/Rare15.nbt,3,CHEST:5,./StructureNBT/StructureLoot/Epic1.nbt,3,CHEST:5,./StructureNBT/StructureLoot/Epic2.nbt,3,CHEST:5,./StructureNBT/StructureLoot/Epic3.nbt,3,CHEST:5,./StructureNBT/StructureLoot/Epic4.nbt,3,CHEST:5,./StructureNBT/StructureLoot/Epic5.nbt,3,CHEST:5,./StructureNBT/StructureLoot/Epic6.nbt,3,CHEST:5,./StructureNBT/StructureLoot/Epic7.nbt,3,CHEST:5,./StructureNBT/StructureLoot/Epic8.nbt,3,CHEST:5,./StructureNBT/StructureLoot/Epic9.nbt,3,CHEST:5,./StructureNBT/StructureLoot/Epic10.nbt,3,CHEST:5,./StructureNBT/StructureLoot/Epic11.nbt,3,CHEST:5,./StructureNBT/StructureLoot/Epic12.nbt,3,CHEST:5,./StructureNBT/StructureLoot/Epic13.nbt,3,CHEST:5,./StructureNBT/StructureLoot/Epic14.nbt,3,CHEST:5,./StructureNBT/StructureLoot/Epic15.nbt,100)
RandomBlock(3,34,6,CHEST:5,./StructureNBT/StructureLoot/JunkChest_1.nbt,20,CHEST:5,./StructureNBT/StructureLoot/JunkChest_2.nbt,15,CHEST:5,./StructureNBT/StructureLoot/JunkChest_3.nbt,15,CHEST:5,./StructureNBT/StructureLoot/JunkChest_4.nbt,15,CHEST:5,./StructureNBT/StructureLoot/JunkChest_5.nbt,15,CHEST:5,./StructureNBT/LoreStoryline/LoreGeneric_5.nbt,2,CHEST:5,./StructureNBT/LoreStoryline/LoreGeneric_4.nbt,2,CHEST:5,./StructureNBT/LoreStoryline/LoreGeneric_3.nbt,2,CHEST:5,./StructureNBT/LoreStoryline/LoreGeneric_2.nbt,2,CHEST:5,./StructureNBT/LoreStoryline/LoreGeneric_1.nbt,2,CHEST:5,./StructureNBT/LoreStoryline/LoreMedievalCity_5.nbt,3,CHEST:5,./StructureNBT/LoreStoryline/LoreMedievalCity_4.nbt,3,CHEST:5,./StructureNBT/LoreStoryline/LoreMedievalCity_3.nbt,3,CHEST:5,./StructureNBT/LoreStoryline/LoreMedievalCity_2.nbt,3,CHEST:5,./StructureNBT/LoreStoryline/LoreMedievalCity_1.nbt,3,CHEST:5,./StructureNBT/StructureLoot/Common1.nbt,3,CHEST:5,./StructureNBT/StructureLoot/Common2.nbt,3,CHEST:5,./StructureNBT/StructureLoot/Common3.nbt,3,CHEST:5,./StructureNBT/StructureLoot/Common4.nbt,3,CHEST:5,./StructureNBT/StructureLoot/Common5.nbt,3,CHEST:5,./StructureNBT/StructureLoot/Common5.nbt,3,CHEST:5,./StructureNBT/StructureLoot/Common6.nbt,3,CHEST:5,./StructureNBT/StructureLoot/Common7.nbt,3,CHEST:5,./StructureNBT/StructureLoot/Common8.nbt,3,CHEST:5,./StructureNBT/StructureLoot/Common9.nbt,3,CHEST:5,./StructureNBT/StructureLoot/Common10.nbt,3,CHEST:5,./StructureNBT/StructureLoot/Common11.nbt,3,CHEST:5,./StructureNBT/StructureLoot/Common12.nbt,3,CHEST:5,./StructureNBT/StructureLoot/Common13.nbt,3,CHEST:5,./StructureNBT/StructureLoot/Common14.nbt,3,CHEST:5,./StructureNBT/StructureLoot/Common15.nbt,3,CHEST:5,./StructureNBT/StructureLoot/Rare1.nbt,3,CHEST:5,./StructureNBT/StructureLoot/Rare2.nbt,3,CHEST:5,./StructureNBT/StructureLoot/Rare3.nbt,3,CHEST:5,./StructureNBT/StructureLoot/Rare4.nbt,3,CHEST:5,./StructureNBT/StructureLoot/Rare5.nbt,3,CHEST:5,./StructureNBT/StructureLoot/Rare6.nbt,3,CHEST:5,./StructureNBT/StructureLoot/Rare7.nbt,3,CHEST:5,./StructureNBT/StructureLoot/Rare8.nbt,3,CHEST:5,./StructureNBT/StructureLoot/Rare9.nbt,3,CHEST:5,./StructureNBT/StructureLoot/Rare10.nbt,3,CHEST:5,./StructureNBT/StructureLoot/Rare11.nbt,3,CHEST:5,./StructureNBT/StructureLoot/Rare12.nbt,3,CHEST:5,./StructureNBT/StructureLoot/Rare13.nbt,3,CHEST:5,./StructureNBT/StructureLoot/Rare14.nbt,3,CHEST:5,./StructureNBT/StructureLoot/Rare15.nbt,3,CHEST:5,./StructureNBT/StructureLoot/Epic1.nbt,3,CHEST:5,./StructureNBT/StructureLoot/Epic2.nbt,3,CHEST:5,./StructureNBT/StructureLoot/Epic3.nbt,3,CHEST:5,./StructureNBT/StructureLoot/Epic4.nbt,3,CHEST:5,./StructureNBT/StructureLoot/Epic5.nbt,3,CHEST:5,./StructureNBT/StructureLoot/Epic6.nbt,3,CHEST:5,./StructureNBT/StructureLoot/Epic7.nbt,3,CHEST:5,./StructureNBT/StructureLoot/Epic8.nbt,3,CHEST:5,./StructureNBT/StructureLoot/Epic9.nbt,3,CHEST:5,./StructureNBT/StructureLoot/Epic10.nbt,3,CHEST:5,./StructureNBT/StructureLoot/Epic11.nbt,3,CHEST:5,./StructureNBT/StructureLoot/Epic12.nbt,3,CHEST:5,./StructureNBT/StructureLoot/Epic13.nbt,3,CHEST:5,./StructureNBT/StructureLoot/Epic14.nbt,3,CHEST:5,./StructureNBT/StructureLoot/Epic15.nbt,100)
Block(3,34,7,log)
Block(3,35,2,wooden_slab:5)
Block(3,35,3,log)
Block(3,35,7,log)
Block(3,36,1,wooden_slab:5)
Block(3,36,2,double_wooden_slab:5)
Block(3,36,3,log)
Block(3,36,7,log)
Block(3,37,3,log)
Block(3,37,7,log)
Block(3,38,3,log)
Block(3,38,4,log:8)
Block(3,38,5,log:8)
Block(3,38,6,log:8)
Block(3,38,7,log)
Block(3,39,3,stone_stairs:0)
Block(3,39,4,dark_oak_fence)
Block(3,39,5,dark_oak_fence)
Block(3,39,6,dark_oak_fence)
Block(3,39,7,stone_stairs:0)
Block(3,40,2,dark_oak_fence)
Block(3,40,3,dark_oak_fence)
Block(3,40,4,dark_oak_fence)
Block(3,40,6,dark_oak_fence)
Block(3,40,7,dark_oak_fence)
Block(3,41,2,dark_oak_fence)
Block(3,41,3,stone_stairs:4)
Block(3,41,4,dark_oak_fence)
Block(3,41,5,dark_oak_fence)
Block(3,41,6,dark_oak_fence)
Block(3,41,7,stone_stairs:4)
Block(3,42,2,double_wooden_slab:5)
Block(3,42,3,log)
Block(3,42,4,log:8)
Block(3,42,5,log:8)
Block(3,42,6,log:8)
Block(3,42,7,log)
Block(3,43,2,cobblestone)
Block(3,43,3,log)
Block(3,43,4,dark_oak_stairs:2)
Block(3,43,5,stonebrick)
Block(3,43,6,dark_oak_STAIRS:0)
Block(3,43,7,log)
Block(3,44,0,wooden_slab:13)
Block(3,44,1,double_wooden_slab:5)
Block(3,44,2,cobblestone)
Block(3,44,3,log)
Block(3,44,4,dark_oak_stairs:6)
Block(3,44,5,stonebrick)
Block(3,44,6,dark_oak_stairs:7)
Block(3,44,7,log)
Block(3,45,0,cobblestone)
Block(3,45,1,cobblestone)
Block(3,45,2,cobblestone)
Block(3,45,3,log)
Block(3,45,4,cobblestone)
Block(3,45,5,cobblestone)
Block(3,45,6,cobblestone)
Block(3,45,7,log)
Block(3,46,0,stonebrick)
Block(3,46,1,dark_oak_fence)
Block(3,47,0,wooden_slab:5)
Block(3,47,1,torch)
Block(4,1,-1,cobblestone)
Block(4,1,2,cobblestone)
Block(4,2,-1,cobblestone)
Block(4,2,2,cobblestone)
Block(4,3,-1,cobblestone)
Block(4,3,2,cobblestone)
Block(4,4,-1,cobblestone)
Block(4,4,2,cobblestone)
Block(4,5,-1,cobblestone)
Block(4,5,2,cobblestone)
Block(4,6,-1,cobblestone)
Block(4,6,2,cobblestone)
Block(4,7,-1,cobblestone)
Block(4,7,2,cobblestone)
Block(4,8,-1,cobblestone)
Block(4,8,2,cobblestone)
Block(4,9,-1,cobblestone)
Block(4,9,2,cobblestone)
Block(4,10,-1,cobblestone)
Block(4,10,2,cobblestone)
Block(4,11,-1,cobblestone)
Block(4,11,0,cobblestone)
Block(4,11,1,cobblestone)
Block(4,11,2,cobblestone)
Block(4,12,-1,stone_stairs:2)
Block(4,12,0,stone:6)
Block(4,12,1,stone:6)
Block(4,12,2,cobblestone)
Block(4,13,0,stone:6)
Block(4,13,1,stone:6)
Block(4,13,2,stone:6)
Block(4,14,0,stone:6)
Block(4,14,1,stone:6)
Block(4,14,2,stone:6)
Block(4,15,0,stone:6)
Block(4,15,1,stone:6)
Block(4,15,2,stone:6)
Block(4,16,0,stone_stairs:2)
Block(4,16,1,stone:6)
Block(4,16,2,stone:6)
Block(4,17,2,stone:6)
Block(4,18,2,stone:6)
Block(4,19,2,stone:6)
Block(4,20,2,stone:6)
Block(4,21,2,stone:6)
Block(4,22,2,stone:6)
Block(4,23,2,stone:6)
Block(4,24,2,stone:6)
Block(4,24,3,stonebrick)
Block(4,24,4,stonebrick)
Block(4,24,5,stonebrick)
Block(4,24,6,stonebrick)
Block(4,24,7,stonebrick)
Block(4,25,2,stone:6)
Block(4,25,3,stonebrick)
Block(4,25,4,stonebrick)
Block(4,25,5,stonebrick)
Block(4,25,6,stonebrick)
Block(4,25,7,stonebrick)
Block(4,26,2,stone:6)
Block(4,26,3,stonebrick)
Block(4,26,4,stonebrick)
Block(4,26,5,stonebrick)
Block(4,26,6,stonebrick)
Block(4,26,7,stonebrick)
Block(4,27,2,stonebrick)
Block(4,27,3,stonebrick)
Block(4,27,4,stonebrick)
Block(4,27,5,stonebrick)
Block(4,27,6,stonebrick)
Block(4,27,7,stonebrick)
Block(4,28,1,stone_brick_stairs:6)
Block(4,28,2,stonebrick)
Block(4,29,1,wooden_slab:5)
Block(4,30,0,stone_slab:13)
Block(4,30,1,double_wooden_slab:5)
Block(4,30,2,wooden_slab:13)
Block(4,30,3,log:4)
Block(4,30,4,wooden_slab:13)
Block(4,30,5,wooden_slab:13)
Block(4,30,6,wooden_slab:13)
Block(4,30,7,log:4)
Block(4,31,0,stone:6)
Block(4,33,-1,wooden_slab:5)
Block(4,33,0,double_wooden_slab:5)
Block(4,33,1,log:4)
Block(4,33,2,wooden_slab:13)
Block(4,33,3,wooden_slab:13)
Block(4,33,4,wooden_slab:13)
Block(4,33,5,wooden_slab:13)
Block(4,33,6,wooden_slab:13)
Block(4,33,7,wooden_slab:13)
Block(4,34,1,stone:6)
Block(4,35,1,wooden_slab:5)
Block(4,36,-1,dark_oak_stairs:2)
Block(4,36,0,dark_oak_stairs:0)
Block(4,36,1,double_wooden_slab:5)
Block(4,36,2,wooden_slab:13)
Block(4,37,2,double_wooden_slab:5)
Block(4,38,2,stonebrick)
Block(4,38,3,wooden_slab:13)
Block(4,38,4,wooden_slab:13)
Block(4,38,5,wooden_slab:13)
Block(4,38,6,wooden_slab:13)
Block(4,38,7,wooden_slab:13)
Block(4,39,2,dark_oak_fence)
Block(4,39,3,cobblestone)
Block(4,39,4,cobblestone)
Block(4,39,5,cobblestone)
Block(4,39,6,cobblestone)
Block(4,39,7,cobblestone)
Block(4,40,1,dark_oak_fence)
Block(4,40,2,dark_oak_fence)
Block(4,40,3,cobblestone)
Block(4,40,4,cobblestone)
Block(4,40,5,stonebrick:3)
Block(4,40,6,cobblestone)
Block(4,40,7,cobblestone)
Block(4,41,1,dark_oak_fence)
Block(4,41,2,dark_oak_fence)
Block(4,41,3,cobblestone)
Block(4,41,4,cobblestone)
Block(4,41,5,cobblestone)
Block(4,41,6,cobblestone)
Block(4,41,7,cobblestone)
Block(4,42,1,double_wooden_slab:5)
Block(4,42,2,double_wooden_slab:5)
Block(4,42,3,crafting_table)
RandomBlock(4,42,5,CHEST:5,./StructureNBT/StructureLoot/JunkChest_1.nbt,20,CHEST:5,./StructureNBT/StructureLoot/JunkChest_2.nbt,15,CHEST:5,./StructureNBT/StructureLoot/JunkChest_3.nbt,15,CHEST:5,./StructureNBT/StructureLoot/JunkChest_4.nbt,15,CHEST:5,./StructureNBT/StructureLoot/JunkChest_5.nbt,15,CHEST:5,./StructureNBT/LoreStoryline/LoreGeneric_5.nbt,2,CHEST:5,./StructureNBT/LoreStoryline/LoreGeneric_4.nbt,2,CHEST:5,./StructureNBT/LoreStoryline/LoreGeneric_3.nbt,2,CHEST:5,./StructureNBT/LoreStoryline/LoreGeneric_2.nbt,2,CHEST:5,./StructureNBT/LoreStoryline/LoreGeneric_1.nbt,2,CHEST:5,./StructureNBT/LoreStoryline/LoreMedievalCity_5.nbt,3,CHEST:5,./StructureNBT/LoreStoryline/LoreMedievalCity_4.nbt,3,CHEST:5,./StructureNBT/LoreStoryline/LoreMedievalCity_3.nbt,3,CHEST:5,./StructureNBT/LoreStoryline/LoreMedievalCity_2.nbt,3,CHEST:5,./StructureNBT/LoreStoryline/LoreMedievalCity_1.nbt,3,CHEST:5,./StructureNBT/StructureLoot/Common1.nbt,3,CHEST:5,./StructureNBT/StructureLoot/Common2.nbt,3,CHEST:5,./StructureNBT/StructureLoot/Common3.nbt,3,CHEST:5,./StructureNBT/StructureLoot/Common4.nbt,3,CHEST:5,./StructureNBT/StructureLoot/Common5.nbt,3,CHEST:5,./StructureNBT/StructureLoot/Common5.nbt,3,CHEST:5,./StructureNBT/StructureLoot/Common6.nbt,3,CHEST:5,./StructureNBT/StructureLoot/Common7.nbt,3,CHEST:5,./StructureNBT/StructureLoot/Common8.nbt,3,CHEST:5,./StructureNBT/StructureLoot/Common9.nbt,3,CHEST:5,./StructureNBT/StructureLoot/Common10.nbt,3,CHEST:5,./StructureNBT/StructureLoot/Common11.nbt,3,CHEST:5,./StructureNBT/StructureLoot/Common12.nbt,3,CHEST:5,./StructureNBT/StructureLoot/Common13.nbt,3,CHEST:5,./StructureNBT/StructureLoot/Common14.nbt,3,CHEST:5,./StructureNBT/StructureLoot/Common15.nbt,3,CHEST:5,./StructureNBT/StructureLoot/Rare1.nbt,3,CHEST:5,./StructureNBT/StructureLoot/Rare2.nbt,3,CHEST:5,./StructureNBT/StructureLoot/Rare3.nbt,3,CHEST:5,./StructureNBT/StructureLoot/Rare4.nbt,3,CHEST:5,./StructureNBT/StructureLoot/Rare5.nbt,3,CHEST:5,./StructureNBT/StructureLoot/Rare6.nbt,3,CHEST:5,./StructureNBT/StructureLoot/Rare7.nbt,3,CHEST:5,./StructureNBT/StructureLoot/Rare8.nbt,3,CHEST:5,./StructureNBT/StructureLoot/Rare9.nbt,3,CHEST:5,./StructureNBT/StructureLoot/Rare10.nbt,3,CHEST:5,./StructureNBT/StructureLoot/Rare11.nbt,3,CHEST:5,./StructureNBT/StructureLoot/Rare12.nbt,3,CHEST:5,./StructureNBT/StructureLoot/Rare13.nbt,3,CHEST:5,./StructureNBT/StructureLoot/Rare14.nbt,3,CHEST:5,./StructureNBT/StructureLoot/Rare15.nbt,3,CHEST:5,./StructureNBT/StructureLoot/Epic1.nbt,3,CHEST:5,./StructureNBT/StructureLoot/Epic2.nbt,3,CHEST:5,./StructureNBT/StructureLoot/Epic3.nbt,3,CHEST:5,./StructureNBT/StructureLoot/Epic4.nbt,3,CHEST:5,./StructureNBT/StructureLoot/Epic5.nbt,3,CHEST:5,./StructureNBT/StructureLoot/Epic6.nbt,3,CHEST:5,./StructureNBT/StructureLoot/Epic7.nbt,3,CHEST:5,./StructureNBT/StructureLoot/Epic8.nbt,3,CHEST:5,./StructureNBT/StructureLoot/Epic9.nbt,3,CHEST:5,./StructureNBT/StructureLoot/Epic10.nbt,3,CHEST:5,./StructureNBT/StructureLoot/Epic11.nbt,3,CHEST:5,./StructureNBT/StructureLoot/Epic12.nbt,3,CHEST:5,./StructureNBT/StructureLoot/Epic13.nbt,3,CHEST:5,./StructureNBT/StructureLoot/Epic14.nbt,3,CHEST:5,./StructureNBT/StructureLoot/Epic15.nbt,100)
RandomBlock(4,42,6,CHEST:5,./StructureNBT/StructureLoot/JunkChest_1.nbt,20,CHEST:5,./StructureNBT/StructureLoot/JunkChest_2.nbt,15,CHEST:5,./StructureNBT/StructureLoot/JunkChest_3.nbt,15,CHEST:5,./StructureNBT/StructureLoot/JunkChest_4.nbt,15,CHEST:5,./StructureNBT/StructureLoot/JunkChest_5.nbt,15,CHEST:5,./StructureNBT/LoreStoryline/LoreGeneric_5.nbt,2,CHEST:5,./StructureNBT/LoreStoryline/LoreGeneric_4.nbt,2,CHEST:5,./StructureNBT/LoreStoryline/LoreGeneric_3.nbt,2,CHEST:5,./StructureNBT/LoreStoryline/LoreGeneric_2.nbt,2,CHEST:5,./StructureNBT/LoreStoryline/LoreGeneric_1.nbt,2,CHEST:5,./StructureNBT/LoreStoryline/LoreMedievalCity_5.nbt,3,CHEST:5,./StructureNBT/LoreStoryline/LoreMedievalCity_4.nbt,3,CHEST:5,./StructureNBT/LoreStoryline/LoreMedievalCity_3.nbt,3,CHEST:5,./StructureNBT/LoreStoryline/LoreMedievalCity_2.nbt,3,CHEST:5,./StructureNBT/LoreStoryline/LoreMedievalCity_1.nbt,3,CHEST:5,./StructureNBT/StructureLoot/Common1.nbt,3,CHEST:5,./StructureNBT/StructureLoot/Common2.nbt,3,CHEST:5,./StructureNBT/StructureLoot/Common3.nbt,3,CHEST:5,./StructureNBT/StructureLoot/Common4.nbt,3,CHEST:5,./StructureNBT/StructureLoot/Common5.nbt,3,CHEST:5,./StructureNBT/StructureLoot/Common5.nbt,3,CHEST:5,./StructureNBT/StructureLoot/Common6.nbt,3,CHEST:5,./StructureNBT/StructureLoot/Common7.nbt,3,CHEST:5,./StructureNBT/StructureLoot/Common8.nbt,3,CHEST:5,./StructureNBT/StructureLoot/Common9.nbt,3,CHEST:5,./StructureNBT/StructureLoot/Common10.nbt,3,CHEST:5,./StructureNBT/StructureLoot/Common11.nbt,3,CHEST:5,./StructureNBT/StructureLoot/Common12.nbt,3,CHEST:5,./StructureNBT/StructureLoot/Common13.nbt,3,CHEST:5,./StructureNBT/StructureLoot/Common14.nbt,3,CHEST:5,./StructureNBT/StructureLoot/Common15.nbt,3,CHEST:5,./StructureNBT/StructureLoot/Rare1.nbt,3,CHEST:5,./StructureNBT/StructureLoot/Rare2.nbt,3,CHEST:5,./StructureNBT/StructureLoot/Rare3.nbt,3,CHEST:5,./StructureNBT/StructureLoot/Rare4.nbt,3,CHEST:5,./StructureNBT/StructureLoot/Rare5.nbt,3,CHEST:5,./StructureNBT/StructureLoot/Rare6.nbt,3,CHEST:5,./StructureNBT/StructureLoot/Rare7.nbt,3,CHEST:5,./StructureNBT/StructureLoot/Rare8.nbt,3,CHEST:5,./StructureNBT/StructureLoot/Rare9.nbt,3,CHEST:5,./StructureNBT/StructureLoot/Rare10.nbt,3,CHEST:5,./StructureNBT/StructureLoot/Rare11.nbt,3,CHEST:5,./StructureNBT/StructureLoot/Rare12.nbt,3,CHEST:5,./StructureNBT/StructureLoot/Rare13.nbt,3,CHEST:5,./StructureNBT/StructureLoot/Rare14.nbt,3,CHEST:5,./StructureNBT/StructureLoot/Rare15.nbt,3,CHEST:5,./StructureNBT/StructureLoot/Epic1.nbt,3,CHEST:5,./StructureNBT/StructureLoot/Epic2.nbt,3,CHEST:5,./StructureNBT/StructureLoot/Epic3.nbt,3,CHEST:5,./StructureNBT/StructureLoot/Epic4.nbt,3,CHEST:5,./StructureNBT/StructureLoot/Epic5.nbt,3,CHEST:5,./StructureNBT/StructureLoot/Epic6.nbt,3,CHEST:5,./StructureNBT/StructureLoot/Epic7.nbt,3,CHEST:5,./StructureNBT/StructureLoot/Epic8.nbt,3,CHEST:5,./StructureNBT/StructureLoot/Epic9.nbt,3,CHEST:5,./StructureNBT/StructureLoot/Epic10.nbt,3,CHEST:5,./StructureNBT/StructureLoot/Epic11.nbt,3,CHEST:5,./StructureNBT/StructureLoot/Epic12.nbt,3,CHEST:5,./StructureNBT/StructureLoot/Epic13.nbt,3,CHEST:5,./StructureNBT/StructureLoot/Epic14.nbt,3,CHEST:5,./StructureNBT/StructureLoot/Epic15.nbt,100)
Block(4,42,7,crafting_table)
Block(4,43,1,cobblestone)
Block(4,43,2,log)
Block(4,44,0,dark_oak_stairs:6)
Block(4,44,1,cobblestone)
Block(4,44,2,log)
Block(4,45,0,log:4)
Block(4,45,1,cobblestone)
Block(4,45,2,log)
Block(4,45,3,log:4)
Block(4,45,4,wooden_slab:13)
Block(4,45,5,wooden_slab:13)
Block(4,45,6,wooden_slab:13)
Block(4,45,7,log:4)
Block(4,46,-1,stone_brick_stairs:4)
Block(5,1,-2,log)
Block(5,1,1,log)
Block(5,2,-2,log)
Block(5,2,1,log)
Block(5,3,-2,log)
Block(5,3,1,log)
Block(5,4,-2,log)
Block(5,4,1,log)
Block(5,5,-2,log)
Block(5,5,1,log)
Block(5,6,-2,log)
Block(5,6,1,log)
Block(5,7,-2,log)
Block(5,7,1,log)
Block(5,8,-2,log)
Block(5,8,1,log)
Block(5,9,-2,log)
Block(5,9,1,log)
Block(5,10,-2,log)
Block(5,10,1,log)
Block(5,11,-2,log)
Block(5,11,-1,cobblestone)
Block(5,11,0,cobblestone)
Block(5,11,1,log)
Block(5,12,-2,stone_brick_stairs:2)
Block(5,12,-1,log)
Block(5,12,0,log:8)
Block(5,12,1,log)
Block(5,13,-1,log)
Block(5,13,1,log)
Block(5,14,-1,log)
Block(5,14,1,log)
Block(5,15,-1,log)
Block(5,15,1,log)
Block(5,16,-1,log)
Block(5,16,1,log)
Block(5,17,-1,stone_stairs:2)
Block(5,17,0,log:8)
Block(5,17,1,log)
Block(5,18,1,log)
Block(5,19,1,log)
Block(5,20,1,log)
Block(5,21,1,log)
Block(5,22,1,log)
Block(5,23,1,log)
Block(5,24,1,log)
Block(5,24,2,stonebrick)
Block(5,24,3,stonebrick)
Block(5,24,4,stonebrick)
Block(5,24,5,stonebrick)
Block(5,24,6,stonebrick)
Block(5,24,7,stonebrick)
Block(5,25,1,log)
Block(5,25,2,stonebrick)
Block(5,25,3,stonebrick)
Block(5,25,4,stonebrick)
Block(5,25,5,stonebrick)
Block(5,25,6,stonebrick)
Block(5,25,7,stonebrick)
Block(5,26,1,log)
Block(5,26,2,stonebrick)
Block(5,26,3,stonebrick)
Block(5,26,4,stonebrick)
Block(5,26,5,stonebrick)
Block(5,26,6,stonebrick)
Block(5,26,7,stonebrick)
Block(5,27,1,log)
Block(5,27,2,stonebrick)
Block(5,27,3,stonebrick)
Block(5,27,4,stonebrick)
Block(5,27,5,stonebrick)
Block(5,27,6,stonebrick)
Block(5,27,7,stonebrick)
Block(5,28,0,stone_brick_stairs:4)
Block(5,28,1,log)
Block(5,29,0,stone_brick_stairs:1)
Block(5,29,1,log)
Block(5,30,0,stone_brick_stairs:4)
Block(5,30,1,log)
Block(5,30,2,log:8)
Block(5,30,3,log:4)
Block(5,30,4,wooden_slab:13)
Block(5,30,5,wooden_slab:13)
Block(5,30,6,wooden_slab:13)
Block(5,30,7,log:4)
Block(5,31,-1,dark_oak_stairs:4)
Block(5,31,0,log)
Block(5,31,1,log)
Block(5,32,0,log)
Block(5,32,1,log)
Block(5,33,-1,dark_oak_stairs:2)
Block(5,33,0,log)
Block(5,33,1,log)
Block(5,33,2,wooden_slab:13)
Block(5,33,3,wooden_slab:13)
Block(5,33,4,wooden_slab:13)
Block(5,33,5,wooden_slab:13)
Block(5,33,6,wooden_slab:13)
Block(5,33,7,wooden_slab:13)
Block(5,34,0,log)
Block(5,34,1,log)
Block(5,35,0,log)
Block(5,35,1,log)
Block(5,36,-1,double_wooden_slab:5)
Block(5,36,0,log)
Block(5,36,1,log)
Block(5,37,0,stone_stairs:2)
Block(5,37,1,log)
Block(5,38,1,log)
Block(5,38,2,wooden_slab:13)
Block(5,38,3,wooden_slab:13)
Block(5,38,4,wooden_slab:13)
Block(5,38,5,wooden_slab:13)
Block(5,38,6,wooden_slab:13)
Block(5,38,7,wooden_slab:13)
Block(5,39,1,stone_stairs:2)
Block(5,39,2,cobblestone)
Block(5,39,7,dark_oak_fence)
Block(5,40,1,dark_oak_fence)
Block(5,40,2,cobblestone)
Block(5,40,7,torch)
Block(5,41,1,stone_stairs:6)
Block(5,41,2,cobblestone)
Block(5,41,3,wooden_slab:13)
Block(5,41,4,wooden_slab:13)
Block(5,41,5,wooden_slab:13)
Block(5,41,6,wooden_slab:13)
Block(5,41,7,wooden_slab:13)
Block(5,42,1,log)
RandomBlock(5,42,2,CHEST:3,./StructureNBT/StructureLoot/JunkChest_1.nbt,20,CHEST:3,./StructureNBT/StructureLoot/JunkChest_2.nbt,15,CHEST:3,./StructureNBT/StructureLoot/JunkChest_3.nbt,15,CHEST:3,./StructureNBT/StructureLoot/JunkChest_4.nbt,15,CHEST:3,./StructureNBT/StructureLoot/JunkChest_5.nbt,15,CHEST:3,./StructureNBT/LoreStoryline/LoreGeneric_5.nbt,2,CHEST:3,./StructureNBT/LoreStoryline/LoreGeneric_4.nbt,2,CHEST:3,./StructureNBT/LoreStoryline/LoreGeneric_3.nbt,2,CHEST:3,./StructureNBT/LoreStoryline/LoreGeneric_2.nbt,2,CHEST:3,./StructureNBT/LoreStoryline/LoreGeneric_1.nbt,2,CHEST:3,./StructureNBT/LoreStoryline/LoreMedievalCity_5.nbt,3,CHEST:3,./StructureNBT/LoreStoryline/LoreMedievalCity_4.nbt,3,CHEST:3,./StructureNBT/LoreStoryline/LoreMedievalCity_3.nbt,3,CHEST:3,./StructureNBT/LoreStoryline/LoreMedievalCity_2.nbt,3,CHEST:3,./StructureNBT/LoreStoryline/LoreMedievalCity_1.nbt,3,CHEST:3,./StructureNBT/StructureLoot/Common1.nbt,3,CHEST:3,./StructureNBT/StructureLoot/Common2.nbt,3,CHEST:3,./StructureNBT/StructureLoot/Common3.nbt,3,CHEST:3,./StructureNBT/StructureLoot/Common4.nbt,3,CHEST:3,./StructureNBT/StructureLoot/Common5.nbt,3,CHEST:3,./StructureNBT/StructureLoot/Common5.nbt,3,CHEST:3,./StructureNBT/StructureLoot/Common6.nbt,3,CHEST:3,./StructureNBT/StructureLoot/Common7.nbt,3,CHEST:3,./StructureNBT/StructureLoot/Common8.nbt,3,CHEST:3,./StructureNBT/StructureLoot/Common9.nbt,3,CHEST:3,./StructureNBT/StructureLoot/Common10.nbt,3,CHEST:3,./StructureNBT/StructureLoot/Common11.nbt,3,CHEST:3,./StructureNBT/StructureLoot/Common12.nbt,3,CHEST:3,./StructureNBT/StructureLoot/Common13.nbt,3,CHEST:3,./StructureNBT/StructureLoot/Common14.nbt,3,CHEST:3,./StructureNBT/StructureLoot/Common15.nbt,3,CHEST:3,./StructureNBT/StructureLoot/Rare1.nbt,3,CHEST:3,./StructureNBT/StructureLoot/Rare2.nbt,3,CHEST:3,./StructureNBT/StructureLoot/Rare3.nbt,3,CHEST:3,./StructureNBT/StructureLoot/Rare4.nbt,3,CHEST:3,./StructureNBT/StructureLoot/Rare5.nbt,3,CHEST:3,./StructureNBT/StructureLoot/Rare6.nbt,3,CHEST:3,./StructureNBT/StructureLoot/Rare7.nbt,3,CHEST:3,./StructureNBT/StructureLoot/Rare8.nbt,3,CHEST:3,./StructureNBT/StructureLoot/Rare9.nbt,3,CHEST:3,./StructureNBT/StructureLoot/Rare10.nbt,3,CHEST:3,./StructureNBT/StructureLoot/Rare11.nbt,3,CHEST:3,./StructureNBT/StructureLoot/Rare12.nbt,3,CHEST:3,./StructureNBT/StructureLoot/Rare13.nbt,3,CHEST:3,./StructureNBT/StructureLoot/Rare14.nbt,3,CHEST:3,./StructureNBT/StructureLoot/Rare15.nbt,3,CHEST:3,./StructureNBT/StructureLoot/Epic1.nbt,3,CHEST:3,./StructureNBT/StructureLoot/Epic2.nbt,3,CHEST:3,./StructureNBT/StructureLoot/Epic3.nbt,3,CHEST:3,./StructureNBT/StructureLoot/Epic4.nbt,3,CHEST:3,./StructureNBT/StructureLoot/Epic5.nbt,3,CHEST:3,./StructureNBT/StructureLoot/Epic6.nbt,3,CHEST:3,./StructureNBT/StructureLoot/Epic7.nbt,3,CHEST:3,./StructureNBT/StructureLoot/Epic8.nbt,3,CHEST:3,./StructureNBT/StructureLoot/Epic9.nbt,3,CHEST:3,./StructureNBT/StructureLoot/Epic10.nbt,3,CHEST:3,./StructureNBT/StructureLoot/Epic11.nbt,3,CHEST:3,./StructureNBT/StructureLoot/Epic12.nbt,3,CHEST:3,./StructureNBT/StructureLoot/Epic13.nbt,3,CHEST:3,./StructureNBT/StructureLoot/Epic14.nbt,3,CHEST:3,./StructureNBT/StructureLoot/Epic15.nbt,100)
Block(5,43,-1,stone_stairs:6)
Block(5,43,0,dark_oak_stairs:6)
Block(5,43,1,log)
Block(5,44,-1,stone_stairs:2)
Block(5,44,0,stone_STAIRS:0)
Block(5,44,1,log)
Block(5,45,-1,stone_stairs:6)
Block(5,45,0,log:8)
Block(5,45,1,log)
Block(5,45,2,log:8)
Block(5,45,3,log:4)
Block(5,45,4,log:8)
Block(5,45,5,log:8)
Block(5,45,6,log:8)
Block(5,45,7,log:4)
Block(5,46,-1,stone_brick_stairs:1)
Block(6,1,-3,cobblestone)
Block(6,1,0,cobblestone)
Block(6,2,-3,cobblestone)
Block(6,2,0,cobblestone)
Block(6,3,-3,cobblestone)
Block(6,3,0,cobblestone)
Block(6,4,-3,cobblestone)
Block(6,4,0,cobblestone)
Block(6,5,-3,cobblestone)
Block(6,5,0,cobblestone)
Block(6,6,-3,cobblestone)
Block(6,6,0,cobblestone)
Block(6,7,-3,cobblestone)
Block(6,7,0,cobblestone)
Block(6,8,-3,cobblestone)
Block(6,8,0,cobblestone)
Block(6,9,-3,cobblestone)
Block(6,9,0,cobblestone)
Block(6,10,-3,cobblestone)
Block(6,10,0,cobblestone)
Block(6,11,-3,cobblestone)
Block(6,11,-2,cobblestone)
Block(6,11,-1,cobblestone)
Block(6,11,0,cobblestone)
Block(6,12,-3,stone_stairs:2)
Block(6,12,-2,stone_stairs:0)
Block(6,12,-1,stone:6)
Block(6,12,0,cobblestone)
Block(6,13,-1,stone:6)
Block(6,13,0,stone:6)
Block(6,14,-1,stone:6)
Block(6,14,0,stone:6)
Block(6,15,-1,stone:6)
Block(6,15,0,stone:6)
Block(6,16,-1,stone_stairs:2)
Block(6,16,0,stone:6)
Block(6,17,0,stone:6)
Block(6,18,0,stone:6)
Block(6,19,0,stone:6)
Block(6,20,0,stone:6)
Block(6,21,0,stone:6)
Block(6,22,0,stone:6)
Block(6,23,0,stone:6)
Block(6,24,0,stone:6)
Block(6,24,1,stonebrick)
Block(6,24,2,stonebrick)
Block(6,24,3,stonebrick)
Block(6,24,4,stonebrick)
Block(6,24,5,stonebrick)
Block(6,24,6,stonebrick)
Block(6,24,7,stonebrick)
Block(6,25,0,stone:6)
Block(6,25,1,stonebrick)
Block(6,25,2,stonebrick)
Block(6,25,3,stonebrick)
Block(6,25,4,stonebrick)
Block(6,25,5,stonebrick)
Block(6,25,6,stonebrick)
Block(6,25,7,stonebrick)
Block(6,26,0,stone:6)
Block(6,26,1,stonebrick)
Block(6,26,2,stonebrick)
Block(6,26,3,stonebrick)
Block(6,26,4,stonebrick)
Block(6,26,5,stonebrick)
Block(6,26,6,stonebrick)
Block(6,26,7,stonebrick)
Block(6,27,0,stonebrick)
Block(6,27,1,stonebrick)
Block(6,27,2,stonebrick)
Block(6,27,3,stonebrick)
Block(6,27,4,stonebrick)
Block(6,27,5,stonebrick)
Block(6,27,6,stonebrick)
Block(6,27,7,stonebrick)
Block(6,28,0,log:4)
Block(6,29,0,wooden_slab:5)
Block(6,30,-1,dark_oak_stairs:4)
Block(6,30,0,log:4)
Block(6,30,1,wooden_slab:13)
Block(6,30,2,wooden_slab:13)
Block(6,30,3,log:4)
Block(6,30,4,wooden_slab:13)
Block(6,30,5,wooden_slab:13)
Block(6,30,6,wooden_slab:13)
Block(6,30,7,log:4)
Block(6,31,-1,dark_oak_stairs:1)
Block(6,32,4,wooden_slab:5)
Block(6,32,5,wooden_slab:13)
Block(6,33,-1,wooden_slab:5)
Block(6,33,0,stone_stairs:5)
Block(6,33,1,wooden_slab:13)
Block(6,33,2,wooden_slab:13)
Block(6,33,3,wooden_slab:13)
Block(6,33,6,wooden_slab:5)
Block(6,33,7,wooden_slab:13)
Block(6,34,0,log:4)
Block(6,34,1,crafting_table)
Block(6,35,0,stone_stairs:1)
Block(6,35,1,crafting_table)
Block(6,36,-1,wooden_slab:13)
Block(6,36,0,stone_stairs:6)
Block(6,36,1,crafting_table)
Block(6,36,4,wooden_slab:5)
Block(6,36,5,wooden_slab:13)
Block(6,37,-1,dark_oak_stairs:2)
Block(6,37,0,dark_oak_stairs:0)
Block(6,37,1,crafting_table)
Block(6,37,6,wooden_slab:5)
Block(6,38,1,log:4)
Block(6,38,2,wooden_slab:13)
Block(6,38,3,wooden_slab:13)
Block(6,38,7,wooden_slab:13)
Block(6,39,1,dark_oak_fence)
Block(6,39,2,cobblestone)
Block(6,40,1,dark_oak_fence)
Block(6,40,2,cobblestone)
Block(6,40,4,wooden_slab:5)
Block(6,40,5,wooden_slab:13)
Block(6,41,1,dark_oak_fence)
Block(6,41,2,cobblestone)
Block(6,41,3,wooden_slab:13)
Block(6,41,6,wooden_slab:5)
Block(6,41,7,wooden_slab:13)
Block(6,42,1,log:4)
RandomBlock(6,42,2,CHEST:3,./StructureNBT/StructureLoot/JunkChest_1.nbt,20,CHEST:3,./StructureNBT/StructureLoot/JunkChest_2.nbt,15,CHEST:3,./StructureNBT/StructureLoot/JunkChest_3.nbt,15,CHEST:3,./StructureNBT/StructureLoot/JunkChest_4.nbt,15,CHEST:3,./StructureNBT/StructureLoot/JunkChest_5.nbt,15,CHEST:3,./StructureNBT/LoreStoryline/LoreGeneric_5.nbt,2,CHEST:3,./StructureNBT/LoreStoryline/LoreGeneric_4.nbt,2,CHEST:3,./StructureNBT/LoreStoryline/LoreGeneric_3.nbt,2,CHEST:3,./StructureNBT/LoreStoryline/LoreGeneric_2.nbt,2,CHEST:3,./StructureNBT/LoreStoryline/LoreGeneric_1.nbt,2,CHEST:3,./StructureNBT/LoreStoryline/LoreMedievalCity_5.nbt,3,CHEST:3,./StructureNBT/LoreStoryline/LoreMedievalCity_4.nbt,3,CHEST:3,./StructureNBT/LoreStoryline/LoreMedievalCity_3.nbt,3,CHEST:3,./StructureNBT/LoreStoryline/LoreMedievalCity_2.nbt,3,CHEST:3,./StructureNBT/LoreStoryline/LoreMedievalCity_1.nbt,3,CHEST:3,./StructureNBT/StructureLoot/Common1.nbt,3,CHEST:3,./StructureNBT/StructureLoot/Common2.nbt,3,CHEST:3,./StructureNBT/StructureLoot/Common3.nbt,3,CHEST:3,./StructureNBT/StructureLoot/Common4.nbt,3,CHEST:3,./StructureNBT/StructureLoot/Common5.nbt,3,CHEST:3,./StructureNBT/StructureLoot/Common5.nbt,3,CHEST:3,./StructureNBT/StructureLoot/Common6.nbt,3,CHEST:3,./StructureNBT/StructureLoot/Common7.nbt,3,CHEST:3,./StructureNBT/StructureLoot/Common8.nbt,3,CHEST:3,./StructureNBT/StructureLoot/Common9.nbt,3,CHEST:3,./StructureNBT/StructureLoot/Common10.nbt,3,CHEST:3,./StructureNBT/StructureLoot/Common11.nbt,3,CHEST:3,./StructureNBT/StructureLoot/Common12.nbt,3,CHEST:3,./StructureNBT/StructureLoot/Common13.nbt,3,CHEST:3,./StructureNBT/StructureLoot/Common14.nbt,3,CHEST:3,./StructureNBT/StructureLoot/Common15.nbt,3,CHEST:3,./StructureNBT/StructureLoot/Rare1.nbt,3,CHEST:3,./StructureNBT/StructureLoot/Rare2.nbt,3,CHEST:3,./StructureNBT/StructureLoot/Rare3.nbt,3,CHEST:3,./StructureNBT/StructureLoot/Rare4.nbt,3,CHEST:3,./StructureNBT/StructureLoot/Rare5.nbt,3,CHEST:3,./StructureNBT/StructureLoot/Rare6.nbt,3,CHEST:3,./StructureNBT/StructureLoot/Rare7.nbt,3,CHEST:3,./StructureNBT/StructureLoot/Rare8.nbt,3,CHEST:3,./StructureNBT/StructureLoot/Rare9.nbt,3,CHEST:3,./StructureNBT/StructureLoot/Rare10.nbt,3,CHEST:3,./StructureNBT/StructureLoot/Rare11.nbt,3,CHEST:3,./StructureNBT/StructureLoot/Rare12.nbt,3,CHEST:3,./StructureNBT/StructureLoot/Rare13.nbt,3,CHEST:3,./StructureNBT/StructureLoot/Rare14.nbt,3,CHEST:3,./StructureNBT/StructureLoot/Rare15.nbt,3,CHEST:3,./StructureNBT/StructureLoot/Epic1.nbt,3,CHEST:3,./StructureNBT/StructureLoot/Epic2.nbt,3,CHEST:3,./StructureNBT/StructureLoot/Epic3.nbt,3,CHEST:3,./StructureNBT/StructureLoot/Epic4.nbt,3,CHEST:3,./StructureNBT/StructureLoot/Epic5.nbt,3,CHEST:3,./StructureNBT/StructureLoot/Epic6.nbt,3,CHEST:3,./StructureNBT/StructureLoot/Epic7.nbt,3,CHEST:3,./StructureNBT/StructureLoot/Epic8.nbt,3,CHEST:3,./StructureNBT/StructureLoot/Epic9.nbt,3,CHEST:3,./StructureNBT/StructureLoot/Epic10.nbt,3,CHEST:3,./StructureNBT/StructureLoot/Epic11.nbt,3,CHEST:3,./StructureNBT/StructureLoot/Epic12.nbt,3,CHEST:3,./StructureNBT/StructureLoot/Epic13.nbt,3,CHEST:3,./StructureNBT/StructureLoot/Epic14.nbt,3,CHEST:3,./StructureNBT/StructureLoot/Epic15.nbt,100)
Block(6,43,1,dark_oak_stairs:0)
Block(6,44,1,dark_oak_stairs:4)
Block(6,44,4,wooden_slab:5)
Block(6,44,5,wooden_slab:13)
Block(6,45,-1,wooden_slab:13)
Block(6,45,0,stonebrick:3)
Block(6,45,1,cobblestone)
Block(6,45,2,wooden_slab:13)
Block(6,45,3,log:4)
Block(6,45,6,wooden_slab:5)
Block(6,45,7,log:4)
Block(6,46,-1,double_wooden_slab:5)
Block(6,47,-1,stone_slab:3)
Block(7,1,-3,log)
Block(7,1,0,log)
Block(7,2,-3,log)
Block(7,2,0,log)
Block(7,3,-3,log)
Block(7,3,0,log)
Block(7,4,-3,log)
Block(7,4,0,log)
Block(7,5,-3,log)
Block(7,5,0,log)
Block(7,6,-3,log)
Block(7,6,0,log)
Block(7,7,-3,log)
Block(7,7,0,log)
Block(7,8,-3,log)
Block(7,8,0,log)
Block(7,9,-3,log)
Block(7,9,0,log)
Block(7,10,-3,log)
Block(7,10,0,log)
Block(7,11,-3,log)
Block(7,11,-2,cobblestone)
Block(7,11,-1,cobblestone)
Block(7,11,0,log)
Block(7,12,-3,stone_brick_stairs:2)
Block(7,12,-2,log:8)
Block(7,12,-1,log:8)
Block(7,12,0,log)
Block(7,13,-2,log)
Block(7,13,0,log)
Block(7,14,-2,log)
Block(7,14,0,log)
Block(7,15,-2,log)
Block(7,15,0,log)
Block(7,16,-2,log)
Block(7,16,0,log)
Block(7,17,-2,stone_stairs:2)
Block(7,17,-1,log:8)
Block(7,17,0,log)
Block(7,18,0,log)
Block(7,19,0,log)
Block(7,20,0,log)
Block(7,21,0,log)
Block(7,22,0,log)
Block(7,23,0,log)
Block(7,24,0,log)
Block(7,24,1,stonebrick)
Block(7,24,2,stonebrick)
Block(7,24,3,stonebrick)
Block(7,24,4,stonebrick)
Block(7,24,5,stonebrick)
Block(7,24,6,stonebrick)
Block(7,24,7,stonebrick)
Block(7,25,0,log)
Block(7,25,1,stonebrick)
Block(7,25,2,stonebrick)
Block(7,25,3,stonebrick)
Block(7,25,4,stonebrick)
Block(7,25,5,stonebrick)
Block(7,25,6,stonebrick)
Block(7,25,7,stonebrick)
Block(7,26,0,log)
Block(7,26,1,stonebrick)
Block(7,26,2,stonebrick)
Block(7,26,3,stonebrick)
Block(7,26,4,stonebrick)
Block(7,26,5,stonebrick)
Block(7,26,6,stonebrick)
Block(7,26,7,stonebrick)
Block(7,27,0,log)
Block(7,27,1,stonebrick)
Block(7,27,2,stonebrick)
Block(7,27,3,stonebrick)
Block(7,27,4,stonebrick)
Block(7,27,5,stonebrick)
Block(7,27,6,stonebrick)
Block(7,27,7,stonebrick)
Block(7,28,0,log)
Block(7,29,0,log)
Block(7,30,-1,dark_oak_stairs:6)
Block(7,30,0,log)
Block(7,30,1,log:8)
Block(7,30,2,log:8)
Block(7,30,3,log:8)
Block(7,30,4,log:8)
Block(7,30,5,log:8)
Block(7,30,6,log:8)
Block(7,30,7,log:4)
Block(7,31,-1,cobblestone)
Block(7,31,4,wooden_slab:13)
Block(7,31,5,log)
Block(7,31,6,dark_oak_fence)
Block(7,32,-1,log)
Block(7,32,5,log)
Block(7,32,6,torch)
Block(7,33,-1,log)
Block(7,33,0,wooden_slab:13)
Block(7,33,1,wooden_slab:13)
Block(7,33,2,wooden_slab:13)
Block(7,33,3,wooden_slab:13)
Block(7,33,5,log)
Block(7,33,6,wooden_slab:13)
Block(7,33,7,wooden_slab:13)
Block(7,34,-1,dark_oak_stairs:2)
Block(7,34,0,log:4)
Block(7,34,1,crafting_table)
Block(7,34,5,log)
Block(7,35,0,stone_stairs:2)
Block(7,35,1,crafting_table)
Block(7,35,4,wooden_slab:13)
Block(7,35,5,log)
Block(7,36,-1,wooden_slab:13)
Block(7,36,0,stone_stairs:6)
Block(7,36,1,crafting_table)
Block(7,36,5,log)
Block(7,37,-2,dark_oak_stairs:6)
Block(7,37,-1,double_wooden_slab:5)
Block(7,37,0,double_wooden_slab:5)
Block(7,37,1,crafting_table)
Block(7,37,5,log)
Block(7,37,6,wooden_slab:13)
Block(7,38,-3,wooden_slab:5)
Block(7,38,-2,wooden_slab:5)
Block(7,38,-1,wooden_slab:5)
Block(7,38,0,dark_oak_stairs:2)
Block(7,38,1,log:4)
Block(7,38,2,wooden_slab:13)
Block(7,38,3,wooden_slab:13)
Block(7,38,5,log)
Block(7,38,7,wooden_slab:13)
Block(7,39,1,dark_oak_fence)
Block(7,39,2,cobblestone)
Block(7,39,4,wooden_slab:13)
Block(7,39,5,log)
Block(7,40,2,stonebrick:3)
Block(7,40,5,log)
Block(7,41,1,dark_oak_fence)
Block(7,41,2,cobblestone)
Block(7,41,3,wooden_slab:13)
Block(7,41,5,log)
Block(7,41,6,wooden_slab:13)
Block(7,41,7,wooden_slab:13)
Block(7,42,0,stone_stairs:6)
Block(7,42,1,log:4)
Block(7,42,2,crafting_table)
Block(7,42,5,log)
Block(7,43,0,log)
Block(7,43,1,stonebrick)
Block(7,43,4,wooden_slab:13)
Block(7,43,5,log)
Block(7,44,0,log)
Block(7,44,1,stonebrick)
Block(7,44,5,log)
Block(7,45,-1,stone_stairs:6)
Block(7,45,0,stone_STAIRS:0)
Block(7,45,1,cobblestone)
Block(7,45,2,wooden_slab:13)
Block(7,45,3,log:4)
Block(7,45,5,log)
Block(7,45,6,wooden_slab:13)
Block(7,45,7,log:4)
Block(7,46,-1,wooden_slab:5)
Block(7,46,5,wooden_slab:5)

#######################################################################
# +-----------------------------------------------------------------+ #
# |                            BO3 checks                           | #
# +-----------------------------------------------------------------+ #
#######################################################################


#######################################################################
# +-----------------------------------------------------------------+ #
# |                             Branches                            | #
# +-----------------------------------------------------------------+ #
#######################################################################

