
#######################################################################
# +-----------------------------------------------------------------+ #
# |                            BO3 object                           | #
# +-----------------------------------------------------------------+ #
#######################################################################

Author: NLBlackEagle

Description: No description given

Version: 3

SettingsMode: WriteDisable


#######################################################################
# +-----------------------------------------------------------------+ #
# |                          Main settings                          | #
# +-----------------------------------------------------------------+ #
#######################################################################

Tree: false

Frequency: 1

Rarity: 25.0

RotateRandomly: false

SpawnHeight: randomY

SpawnHeightOffset: 0

SpawnHeightVariance: 0

##############################
# Height Limits for the BO3. #
##############################

MinHeight: 47

MaxHeight: 47

######################
# Extrusion settings #
######################

ExtrudeMode: None

ExtrudeThroughBlocks: air

MaxBranchDepth: 60

ExcludedBiomes: All


#######################################################################
# +-----------------------------------------------------------------+ #
# |                      Source block settings                      | #
# +-----------------------------------------------------------------+ #
#######################################################################

SourceBlocks: air

MaxPercentageOutsideSourceBlock: 100

OutsideSourceBlock: placeAnyway


#######################################################################
# +-----------------------------------------------------------------+ #
# |                              Blocks                             | #
# +-----------------------------------------------------------------+ #
#######################################################################

Block(-8,35,-2,wooden_slab:13)
Block(-8,36,-2,double_wooden_slab:5)
Block(-8,37,-2,fence)
Block(-7,35,-2,double_wooden_slab:5)
Block(-7,36,-2,wooden_slab:5)
Block(-7,37,-2,fence)
Block(-7,38,-2,fence)
Block(-6,30,-4,wool)
Block(-6,30,-3,wool)
Block(-6,30,-1,wool)
Block(-6,30,0,wool)
Block(-6,30,1,wool)
Block(-6,31,-4,wool)
Block(-6,31,-3,wool)
Block(-6,31,-2,wool:15)
Block(-6,31,-1,wool:15)
Block(-6,31,0,wool:15)
Block(-6,32,-3,wool)
Block(-6,32,-2,wool:15)
Block(-6,32,-1,wool:15)
Block(-6,34,-2,wooden_slab:13)
Block(-6,35,-2,double_wooden_slab:5)
Block(-6,36,-2,fence)
Block(-6,37,-2,fence)
Block(-6,38,-2,fence)
Block(-6,39,-2,fence)
Block(-5,29,-4,wool)
Block(-5,29,1,wool:15)
Block(-5,30,-5,wool)
Block(-5,30,2,wool:15)
Block(-5,31,-6,wool:15)
Block(-5,31,-5,wool:15)
Block(-5,31,-4,wool:15)
Block(-5,31,0,wool)
Block(-5,31,1,wool)
Block(-5,32,-5,wool:15)
Block(-5,32,-4,wool:15)
Block(-5,32,0,wool:15)
Block(-5,32,1,wool)
Block(-5,33,-4,wool:15)
Block(-5,33,-3,wool)
Block(-5,33,-2,wool)
Block(-5,33,-1,wool:15)
Block(-5,33,0,wool)
Block(-5,34,-3,wool)
Block(-5,34,-2,double_wooden_slab:5)
Block(-5,34,-1,wool)
Block(-5,35,-2,wooden_slab:5)
Block(-5,36,-2,fence)
Block(-5,37,-2,wool)
Block(-5,38,-2,fence)
Block(-5,39,-2,fence)
Block(-5,40,-2,fence)
Block(-4,29,-5,wool:15)
Block(-4,29,2,wool:15)
Block(-4,30,-6,wool:15)
Block(-4,30,2,wool:15)
Block(-4,31,-6,wool)
Block(-4,31,2,wool)
Block(-4,32,-5,wool:15)
Block(-4,32,2,wool)
Block(-4,33,-5,wool:15)
Block(-4,33,-2,wooden_slab:13)
Block(-4,33,1,wool)
Block(-4,34,-4,wool)
Block(-4,34,-2,double_wooden_slab:5)
Block(-4,34,0,wool)
Block(-4,36,-2,fence)
Block(-4,37,-2,wool)
Block(-4,38,-2,fence)
Block(-4,39,-2,wool)
Block(-4,40,-2,fence)
Block(-4,41,-2,fence)
Block(-3,29,-6,wool:15)
Block(-3,29,3,wool:15)
Block(-3,30,-6,wool:15)
Block(-3,30,2,wool:15)
Block(-3,33,-5,wool)
Block(-3,33,-2,double_wooden_slab:5)
Block(-3,33,1,wool)
Block(-3,34,-5,log:9)
Block(-3,34,-4,log:9)
Block(-3,34,-3,log:9)
Block(-3,34,-2,log:9)
Block(-3,34,-1,log:9)
Block(-3,34,0,log:9)
Block(-3,34,1,log:9)
Block(-3,36,-2,fence)
Block(-3,37,-2,wool)
Block(-3,38,-2,fence)
Block(-3,39,-2,fence)
Block(-3,40,-2,wool)
Block(-3,41,-2,fence)
Block(-3,42,-2,fence)
Block(-2,28,-6,wool:15)
Block(-2,28,3,wool)
Block(-2,29,-6,wool:15)
Block(-2,32,-2,wooden_slab:13)
Block(-2,33,-2,double_wooden_slab:5)
Block(-2,36,-2,fence)
Block(-2,37,-2,wool)
Block(-2,38,-2,wool)
Block(-2,39,-2,fence)
Block(-2,40,-2,wool)
Block(-2,41,-2,wool)
Block(-2,42,-2,fence)
Block(-2,43,-2,fence)
Block(-1,28,-6,wool)
Block(-1,28,3,wool)
Block(-1,32,-2,double_wooden_slab:5)
Block(-1,33,-2,wooden_slab:5)
Block(-1,36,-2,wool)
Block(-1,37,-1,wool)
Block(-1,38,-2,wool)
Block(-1,39,-2,fence)
Block(-1,40,-2,fence)
Block(-1,40,-1,wool)
Block(-1,41,-2,wool)
Block(-1,42,-2,wool)
Block(-1,43,-2,fence)
Block(-1,44,-2,fence)
Block(0,28,-6,fence)
Block(0,28,3,fence)
Block(0,31,-2,double_wooden_slab:5)
Block(0,32,-2,double_wooden_slab:5)
Block(0,36,-2,wool)
Block(0,37,-1,wool)
Block(0,38,-1,wool)
Block(0,39,-2,wool)
Block(0,40,-2,fence)
Block(0,41,-2,wool)
Block(0,41,-1,wool)
Block(0,42,-2,wool)
Block(0,43,-2,wool)
Block(0,44,-2,fence)
Block(0,45,-2,fence)
Block(1,28,-6,fence)
Block(1,28,3,fence)
Block(1,29,-3,wooden_slab:13)
Block(1,29,-2,planks:5)
Block(1,29,-1,wooden_slab:13)
Block(1,30,-3,dark_oak_STAIRS:0)
Block(1,30,-1,dark_oak_stairs:2)
Block(1,31,-3,wooden_slab:5)
Block(1,31,-2,double_wooden_slab:5)
Block(1,31,-1,wooden_slab:5)
Block(1,32,-2,wooden_slab:5)
Block(1,36,-1,wool)
Block(1,37,-1,wool)
Block(1,38,-1,wool)
Block(1,39,-2,wool)
Block(1,40,-2,fence)
Block(1,41,-2,fence)
Block(1,42,-2,wool)
Block(1,42,-1,wool:15)
Block(1,43,-1,wool:15)
Block(1,44,-2,wool:15)
Block(1,45,-2,fence)
Block(1,46,-2,fence)
Block(2,28,-6,fence)
Block(2,28,-3,wooden_slab:13)
Block(2,28,-2,dark_oak_stairs:4)
Block(2,28,-1,wooden_slab:13)
Block(2,28,2,fence)
Block(2,28,3,fence)
Block(2,29,-3,double_wooden_slab:5)
Block(2,29,-2,planks)
Block(2,29,-1,double_wooden_slab:5)
Block(2,30,-4,wooden_slab:5)
Block(2,30,-3,oak_stairs:4)
Block(2,30,-2,wooden_slab:13)
Block(2,30,-1,oak_stairs:4)
Block(2,30,0,wooden_slab:5)
Block(2,31,-4,wooden_slab:5)
Block(2,31,-3,wooden_slab:5)
Block(2,31,-2,double_wooden_slab:5)
Block(2,31,-1,wooden_slab:5)
Block(2,31,0,wooden_slab:5)
Block(2,36,0,wool)
Block(2,37,-1,wool)
Block(2,38,-1,wool)
Block(2,39,-1,wool)
Block(2,40,-2,wool)
Block(2,41,-2,fence)
Block(2,42,-2,wool:15)
Block(2,43,-1,wool:15)
Block(2,44,-1,wool:15)
Block(2,45,-2,wool:15)
Block(2,46,-2,fence)
Block(2,47,-2,fence)
Block(3,27,-3,wooden_slab:13)
Block(3,27,-1,wooden_slab:13)
Block(3,28,-6,fence)
Block(3,28,-3,double_wooden_slab:5)
Block(3,28,-2,planks)
Block(3,28,-1,double_wooden_slab:5)
Block(3,28,2,fence)
Block(3,29,-4,wooden_slab:13)
Block(3,29,-3,planks)
Block(3,29,-2,planks)
Block(3,29,-1,planks)
Block(3,29,0,wooden_slab:13)
Block(3,30,-4,wooden_slab:13)
Block(3,30,-3,oak_stairs:1)
Block(3,30,-2,double_wooden_slab:5)
Block(3,30,-1,oak_stairs:1)
Block(3,30,0,wooden_slab:13)
Block(3,31,-2,wooden_slab:5)
Block(3,36,0,wool)
Block(3,37,0,wool:15)
Block(3,38,-1,wool:15)
Block(3,39,-1,wool)
Block(3,40,-2,wool)
Block(3,41,-2,fence)
Block(3,42,-2,fence)
Block(3,43,-2,wool:15)
Block(3,43,-1,wool:15)
Block(3,44,-1,wool:15)
Block(3,45,-1,wool:15)
Block(3,46,-2,wool)
Block(3,47,-2,fence)
Block(3,48,-2,fence)
Block(4,27,-3,wooden_slab:5)
Block(4,27,-2,planks)
Block(4,27,-1,wooden_slab:5)
Block(4,27,1,fence)
Block(4,28,-6,fence)
Block(4,28,-5,fence)
Block(4,28,-3,planks)
Block(4,28,-2,planks)
Block(4,28,-1,planks)
Block(4,28,1,fence)
Block(4,28,2,fence)
Block(4,29,-4,wooden_slab:13)
Block(4,29,-3,planks)
Block(4,29,-2,planks)
Block(4,29,-1,planks)
Block(4,29,0,wooden_slab:13)
Block(4,30,-2,double_wooden_slab:5)
Block(4,31,-4,wooden_slab:5)
Block(4,31,0,wooden_slab:5)
Block(4,37,0,wool:15)
Block(4,38,0,wool:15)
Block(4,39,-1,wool:15)
Block(4,40,-1,wool)
Block(4,41,-2,wool)
Block(4,42,-2,fence)
Block(4,43,-2,wool)
Block(4,44,-2,wool)
Block(4,44,-1,wool)
Block(4,45,-1,wool:15)
Block(4,46,-2,wool:15)
Block(4,47,-2,wool)
Block(4,48,-2,fence)
Block(4,49,-2,fence)
Block(5,26,-3,dark_oak_stairs:4)
Block(5,26,-2,planks)
Block(5,26,-1,dark_oak_stairs:4)
Block(5,27,-3,planks)
Block(5,27,-2,planks)
Block(5,27,-1,planks)
Block(5,27,1,fence)
Block(5,28,-5,fence)
Block(5,28,-4,dark_oak_stairs:6)
Block(5,28,-3,planks)
Block(5,28,-2,planks)
Block(5,28,-1,planks)
Block(5,28,0,dark_oak_stairs:7)
Block(5,29,-4,wooden_slab:5)
Block(5,29,-3,planks)
Block(5,29,-2,planks)
Block(5,29,-1,planks)
Block(5,29,0,wooden_slab:5)
Block(5,30,-4,wooden_slab:5)
Block(5,30,-2,wooden_slab:5)
Block(5,30,0,wooden_slab:5)
Block(5,31,-4,wooden_slab:5)
Block(5,31,0,wooden_slab:5)
Block(5,37,0,wool:15)
Block(5,38,0,wool:15)
Block(5,39,0,wool:15)
Block(5,40,-1,wool:15)
Block(5,41,-2,wool)
Block(5,42,-2,fence)
Block(5,43,-2,fence)
Block(5,44,-2,wool)
Block(5,44,-1,wool)
Block(5,45,-1,wool:15)
Block(5,46,-1,wool:15)
Block(5,47,-2,wool:15)
Block(5,48,-2,wool)
Block(5,49,-2,fence)
Block(5,50,-2,fence)
Block(6,24,-2,planks)
Block(6,25,-3,dark_oak_stairs:4)
Block(6,25,-2,planks)
Block(6,25,-1,dark_oak_stairs:4)
Block(6,26,-3,planks)
Block(6,26,-2,planks)
Block(6,26,-1,planks)
Block(6,27,-4,wooden_slab:13)
Block(6,27,-3,planks)
Block(6,27,-2,planks)
Block(6,27,-1,planks)
Block(6,27,0,wooden_slab:13)
Block(6,27,1,fence)
Block(6,28,-5,fence)
Block(6,28,-4,planks)
Block(6,28,-3,planks)
Block(6,28,-2,planks)
Block(6,28,-1,planks)
Block(6,28,0,planks)
Block(6,29,-4,wooden_slab:13)
Block(6,29,-3,planks)
Block(6,29,-2,double_wooden_slab:5)
Block(6,29,-1,planks)
Block(6,29,0,wooden_slab:13)
Block(6,30,-4,wooden_slab:13)
Block(6,30,0,wooden_slab:13)
Block(6,36,0,wool)
Block(6,37,0,wool)
Block(6,38,0,wool:15)
Block(6,39,0,wool:15)
Block(6,40,-1,wool:15)
Block(6,41,-1,wool)
Block(6,42,-2,wool)
Block(6,43,-2,fence)
Block(6,44,-2,wool)
Block(6,44,-1,wool)
Block(6,45,-1,wool:15)
Block(6,46,-1,wool:15)
Block(6,47,-1,wool:15)
Block(6,48,-2,wool:15)
Block(6,49,-2,wool)
Block(6,50,-2,fence)
Block(6,51,-2,fence)
Block(7,22,-2,planks)
Block(7,23,-3,wooden_slab:13)
Block(7,23,-2,planks)
Block(7,23,-1,wooden_slab:13)
Block(7,24,-3,planks)
Block(7,24,-2,planks)
Block(7,24,-1,planks)
Block(7,25,-3,planks)
Block(7,25,-2,planks)
Block(7,25,-1,planks)
Block(7,26,-4,wooden_slab:13)
Block(7,26,-3,planks)
Block(7,26,-2,planks)
Block(7,26,-1,planks)
Block(7,26,0,wooden_slab:13)
Block(7,27,-4,planks)
Block(7,27,-3,planks)
Block(7,27,-2,planks)
Block(7,27,-1,planks)
Block(7,27,0,planks)
Block(7,27,1,fence)
Block(7,28,-4,planks)
Block(7,28,-3,planks)
Block(7,28,-2,double_wooden_slab:5)
Block(7,28,-1,planks)
Block(7,28,0,planks)
Block(7,29,-4,wooden_slab:13)
Block(7,29,-3,planks)
Block(7,29,-2,wooden_slab:5)
Block(7,29,-1,planks)
Block(7,29,0,wooden_slab:13)
Block(7,30,-5,wooden_slab:5)
Block(7,30,1,wooden_slab:5)
Block(7,31,-4,wooden_slab:5)
Block(7,31,0,wooden_slab:5)
Block(7,36,1,wool:15)
Block(7,37,0,wool:15)
Block(7,38,0,wool)
Block(7,39,0,wool:15)
Block(7,40,0,wool:15)
Block(7,41,-1,wool:15)
Block(7,42,-2,wool)
Block(7,43,-2,fence)
Block(7,44,-2,fence)
Block(7,45,-2,wool)
Block(7,45,-1,wool)
Block(7,46,-1,wool)
Block(7,47,-1,wool:15)
Block(7,48,-1,wool:15)
Block(7,49,-2,wool:15)
Block(7,50,-2,wool)
Block(7,51,-2,fence)
Block(7,52,-2,fence)

#######################################################################
# +-----------------------------------------------------------------+ #
# |                            BO3 checks                           | #
# +-----------------------------------------------------------------+ #
#######################################################################


#######################################################################
# +-----------------------------------------------------------------+ #
# |                             Branches                            | #
# +-----------------------------------------------------------------+ #
#######################################################################

Branch(-16,0,0,sap27,NORTH,100.0)
