
#######################################################################
# +-----------------------------------------------------------------+ #
# |                            BO3 object                           | #
# +-----------------------------------------------------------------+ #
#######################################################################

Author: NLBlackEagle

Description: No description given

Version: 3

SettingsMode: WriteDisable


#######################################################################
# +-----------------------------------------------------------------+ #
# |                          Main settings                          | #
# +-----------------------------------------------------------------+ #
#######################################################################

Tree: false

Frequency: 1

Rarity: 25.0

RotateRandomly: false

SpawnHeight: randomY

SpawnHeightOffset: 0

SpawnHeightVariance: 0

##############################
# Height Limits for the BO3. #
##############################

MinHeight: 47

MaxHeight: 47

######################
# Extrusion settings #
######################

ExtrudeMode: None

ExtrudeThroughBlocks: air

MaxBranchDepth: 60

ExcludedBiomes: All


#######################################################################
# +-----------------------------------------------------------------+ #
# |                      Source block settings                      | #
# +-----------------------------------------------------------------+ #
#######################################################################

SourceBlocks: air

MaxPercentageOutsideSourceBlock: 100

OutsideSourceBlock: placeAnyway


#######################################################################
# +-----------------------------------------------------------------+ #
# |                              Blocks                             | #
# +-----------------------------------------------------------------+ #
#######################################################################
RandomBlock(-8,30,-3,CHEST:3,./StructureNBT/StructureLoot/JunkChest_1.nbt,20,CHEST:3,./StructureNBT/StructureLoot/JunkChest_2.nbt,15,CHEST:3,./StructureNBT/StructureLoot/JunkChest_3.nbt,15,CHEST:3,./StructureNBT/StructureLoot/JunkChest_4.nbt,15,CHEST:3,./StructureNBT/StructureLoot/JunkChest_5.nbt,15,CHEST:3,./StructureNBT/LoreStoryline/LoreGeneric_5.nbt,2,CHEST:3,./StructureNBT/LoreStoryline/LoreGeneric_4.nbt,2,CHEST:3,./StructureNBT/LoreStoryline/LoreGeneric_3.nbt,2,CHEST:3,./StructureNBT/LoreStoryline/LoreGeneric_2.nbt,2,CHEST:3,./StructureNBT/LoreStoryline/LoreGeneric_1.nbt,2,CHEST:3,./StructureNBT/LoreStoryline/LoreMedievalCity_5.nbt,3,CHEST:3,./StructureNBT/LoreStoryline/LoreMedievalCity_4.nbt,3,CHEST:3,./StructureNBT/LoreStoryline/LoreMedievalCity_3.nbt,3,CHEST:3,./StructureNBT/LoreStoryline/LoreMedievalCity_2.nbt,3,CHEST:3,./StructureNBT/LoreStoryline/LoreMedievalCity_1.nbt,3,CHEST:3,./StructureNBT/StructureLoot/Common1.nbt,3,CHEST:3,./StructureNBT/StructureLoot/Common2.nbt,3,CHEST:3,./StructureNBT/StructureLoot/Common3.nbt,3,CHEST:3,./StructureNBT/StructureLoot/Common4.nbt,3,CHEST:3,./StructureNBT/StructureLoot/Common5.nbt,3,CHEST:3,./StructureNBT/StructureLoot/Common5.nbt,3,CHEST:3,./StructureNBT/StructureLoot/Common6.nbt,3,CHEST:3,./StructureNBT/StructureLoot/Common7.nbt,3,CHEST:3,./StructureNBT/StructureLoot/Common8.nbt,3,CHEST:3,./StructureNBT/StructureLoot/Common9.nbt,3,CHEST:3,./StructureNBT/StructureLoot/Common10.nbt,3,CHEST:3,./StructureNBT/StructureLoot/Common11.nbt,3,CHEST:3,./StructureNBT/StructureLoot/Common12.nbt,3,CHEST:3,./StructureNBT/StructureLoot/Common13.nbt,3,CHEST:3,./StructureNBT/StructureLoot/Common14.nbt,3,CHEST:3,./StructureNBT/StructureLoot/Common15.nbt,3,CHEST:3,./StructureNBT/StructureLoot/Rare1.nbt,3,CHEST:3,./StructureNBT/StructureLoot/Rare2.nbt,3,CHEST:3,./StructureNBT/StructureLoot/Rare3.nbt,3,CHEST:3,./StructureNBT/StructureLoot/Rare4.nbt,3,CHEST:3,./StructureNBT/StructureLoot/Rare5.nbt,3,CHEST:3,./StructureNBT/StructureLoot/Rare6.nbt,3,CHEST:3,./StructureNBT/StructureLoot/Rare7.nbt,3,CHEST:3,./StructureNBT/StructureLoot/Rare8.nbt,3,CHEST:3,./StructureNBT/StructureLoot/Rare9.nbt,3,CHEST:3,./StructureNBT/StructureLoot/Rare10.nbt,3,CHEST:3,./StructureNBT/StructureLoot/Rare11.nbt,3,CHEST:3,./StructureNBT/StructureLoot/Rare12.nbt,3,CHEST:3,./StructureNBT/StructureLoot/Rare13.nbt,3,CHEST:3,./StructureNBT/StructureLoot/Rare14.nbt,3,CHEST:3,./StructureNBT/StructureLoot/Rare15.nbt,3,CHEST:3,./StructureNBT/StructureLoot/Epic1.nbt,3,CHEST:3,./StructureNBT/StructureLoot/Epic2.nbt,3,CHEST:3,./StructureNBT/StructureLoot/Epic3.nbt,3,CHEST:3,./StructureNBT/StructureLoot/Epic4.nbt,3,CHEST:3,./StructureNBT/StructureLoot/Epic5.nbt,3,CHEST:3,./StructureNBT/StructureLoot/Epic6.nbt,3,CHEST:3,./StructureNBT/StructureLoot/Epic7.nbt,3,CHEST:3,./StructureNBT/StructureLoot/Epic8.nbt,3,CHEST:3,./StructureNBT/StructureLoot/Epic9.nbt,3,CHEST:3,./StructureNBT/StructureLoot/Epic10.nbt,3,CHEST:3,./StructureNBT/StructureLoot/Epic11.nbt,3,CHEST:3,./StructureNBT/StructureLoot/Epic12.nbt,3,CHEST:3,./StructureNBT/StructureLoot/Epic13.nbt,3,CHEST:3,./StructureNBT/StructureLoot/Epic14.nbt,3,CHEST:3,./StructureNBT/StructureLoot/Epic15.nbt,100)
RandomBlock(-8,30,-1,CHEST,./StructureNBT/StructureLoot/JunkChest_1.nbt,20,CHEST,./StructureNBT/StructureLoot/JunkChest_2.nbt,15,CHEST,./StructureNBT/StructureLoot/JunkChest_3.nbt,15,CHEST,./StructureNBT/StructureLoot/JunkChest_4.nbt,15,CHEST,./StructureNBT/StructureLoot/JunkChest_5.nbt,15,CHEST,./StructureNBT/LoreStoryline/LoreGeneric_5.nbt,2,CHEST,./StructureNBT/LoreStoryline/LoreGeneric_4.nbt,2,CHEST,./StructureNBT/LoreStoryline/LoreGeneric_3.nbt,2,CHEST,./StructureNBT/LoreStoryline/LoreGeneric_2.nbt,2,CHEST,./StructureNBT/LoreStoryline/LoreGeneric_1.nbt,2,CHEST,./StructureNBT/LoreStoryline/LoreMedievalCity_5.nbt,3,CHEST,./StructureNBT/LoreStoryline/LoreMedievalCity_4.nbt,3,CHEST,./StructureNBT/LoreStoryline/LoreMedievalCity_3.nbt,3,CHEST,./StructureNBT/LoreStoryline/LoreMedievalCity_2.nbt,3,CHEST,./StructureNBT/LoreStoryline/LoreMedievalCity_1.nbt,3,CHEST,./StructureNBT/StructureLoot/Common1.nbt,3,CHEST,./StructureNBT/StructureLoot/Common2.nbt,3,CHEST,./StructureNBT/StructureLoot/Common3.nbt,3,CHEST,./StructureNBT/StructureLoot/Common4.nbt,3,CHEST,./StructureNBT/StructureLoot/Common5.nbt,3,CHEST,./StructureNBT/StructureLoot/Common5.nbt,3,CHEST,./StructureNBT/StructureLoot/Common6.nbt,3,CHEST,./StructureNBT/StructureLoot/Common7.nbt,3,CHEST,./StructureNBT/StructureLoot/Common8.nbt,3,CHEST,./StructureNBT/StructureLoot/Common9.nbt,3,CHEST,./StructureNBT/StructureLoot/Common10.nbt,3,CHEST,./StructureNBT/StructureLoot/Common11.nbt,3,CHEST,./StructureNBT/StructureLoot/Common12.nbt,3,CHEST,./StructureNBT/StructureLoot/Common13.nbt,3,CHEST,./StructureNBT/StructureLoot/Common14.nbt,3,CHEST,./StructureNBT/StructureLoot/Common15.nbt,3,CHEST,./StructureNBT/StructureLoot/Rare1.nbt,3,CHEST,./StructureNBT/StructureLoot/Rare2.nbt,3,CHEST,./StructureNBT/StructureLoot/Rare3.nbt,3,CHEST,./StructureNBT/StructureLoot/Rare4.nbt,3,CHEST,./StructureNBT/StructureLoot/Rare5.nbt,3,CHEST,./StructureNBT/StructureLoot/Rare6.nbt,3,CHEST,./StructureNBT/StructureLoot/Rare7.nbt,3,CHEST,./StructureNBT/StructureLoot/Rare8.nbt,3,CHEST,./StructureNBT/StructureLoot/Rare9.nbt,3,CHEST,./StructureNBT/StructureLoot/Rare10.nbt,3,CHEST,./StructureNBT/StructureLoot/Rare11.nbt,3,CHEST,./StructureNBT/StructureLoot/Rare12.nbt,3,CHEST,./StructureNBT/StructureLoot/Rare13.nbt,3,CHEST,./StructureNBT/StructureLoot/Rare14.nbt,3,CHEST,./StructureNBT/StructureLoot/Rare15.nbt,3,CHEST,./StructureNBT/StructureLoot/Epic1.nbt,3,CHEST,./StructureNBT/StructureLoot/Epic2.nbt,3,CHEST,./StructureNBT/StructureLoot/Epic3.nbt,3,CHEST,./StructureNBT/StructureLoot/Epic4.nbt,3,CHEST,./StructureNBT/StructureLoot/Epic5.nbt,3,CHEST,./StructureNBT/StructureLoot/Epic6.nbt,3,CHEST,./StructureNBT/StructureLoot/Epic7.nbt,3,CHEST,./StructureNBT/StructureLoot/Epic8.nbt,3,CHEST,./StructureNBT/StructureLoot/Epic9.nbt,3,CHEST,./StructureNBT/StructureLoot/Epic10.nbt,3,CHEST,./StructureNBT/StructureLoot/Epic11.nbt,3,CHEST,./StructureNBT/StructureLoot/Epic12.nbt,3,CHEST,./StructureNBT/StructureLoot/Epic13.nbt,3,CHEST,./StructureNBT/StructureLoot/Epic14.nbt,3,CHEST,./StructureNBT/StructureLoot/Epic15.nbt,100	)
RandomBlock(-7,30,-3,CHEST:3,./StructureNBT/StructureLoot/JunkChest_1.nbt,20,CHEST:3,./StructureNBT/StructureLoot/JunkChest_2.nbt,15,CHEST:3,./StructureNBT/StructureLoot/JunkChest_3.nbt,15,CHEST:3,./StructureNBT/StructureLoot/JunkChest_4.nbt,15,CHEST:3,./StructureNBT/StructureLoot/JunkChest_5.nbt,15,CHEST:3,./StructureNBT/LoreStoryline/LoreGeneric_5.nbt,2,CHEST:3,./StructureNBT/LoreStoryline/LoreGeneric_4.nbt,2,CHEST:3,./StructureNBT/LoreStoryline/LoreGeneric_3.nbt,2,CHEST:3,./StructureNBT/LoreStoryline/LoreGeneric_2.nbt,2,CHEST:3,./StructureNBT/LoreStoryline/LoreGeneric_1.nbt,2,CHEST:3,./StructureNBT/LoreStoryline/LoreMedievalCity_5.nbt,3,CHEST:3,./StructureNBT/LoreStoryline/LoreMedievalCity_4.nbt,3,CHEST:3,./StructureNBT/LoreStoryline/LoreMedievalCity_3.nbt,3,CHEST:3,./StructureNBT/LoreStoryline/LoreMedievalCity_2.nbt,3,CHEST:3,./StructureNBT/LoreStoryline/LoreMedievalCity_1.nbt,3,CHEST:3,./StructureNBT/StructureLoot/Common1.nbt,3,CHEST:3,./StructureNBT/StructureLoot/Common2.nbt,3,CHEST:3,./StructureNBT/StructureLoot/Common3.nbt,3,CHEST:3,./StructureNBT/StructureLoot/Common4.nbt,3,CHEST:3,./StructureNBT/StructureLoot/Common5.nbt,3,CHEST:3,./StructureNBT/StructureLoot/Common5.nbt,3,CHEST:3,./StructureNBT/StructureLoot/Common6.nbt,3,CHEST:3,./StructureNBT/StructureLoot/Common7.nbt,3,CHEST:3,./StructureNBT/StructureLoot/Common8.nbt,3,CHEST:3,./StructureNBT/StructureLoot/Common9.nbt,3,CHEST:3,./StructureNBT/StructureLoot/Common10.nbt,3,CHEST:3,./StructureNBT/StructureLoot/Common11.nbt,3,CHEST:3,./StructureNBT/StructureLoot/Common12.nbt,3,CHEST:3,./StructureNBT/StructureLoot/Common13.nbt,3,CHEST:3,./StructureNBT/StructureLoot/Common14.nbt,3,CHEST:3,./StructureNBT/StructureLoot/Common15.nbt,3,CHEST:3,./StructureNBT/StructureLoot/Rare1.nbt,3,CHEST:3,./StructureNBT/StructureLoot/Rare2.nbt,3,CHEST:3,./StructureNBT/StructureLoot/Rare3.nbt,3,CHEST:3,./StructureNBT/StructureLoot/Rare4.nbt,3,CHEST:3,./StructureNBT/StructureLoot/Rare5.nbt,3,CHEST:3,./StructureNBT/StructureLoot/Rare6.nbt,3,CHEST:3,./StructureNBT/StructureLoot/Rare7.nbt,3,CHEST:3,./StructureNBT/StructureLoot/Rare8.nbt,3,CHEST:3,./StructureNBT/StructureLoot/Rare9.nbt,3,CHEST:3,./StructureNBT/StructureLoot/Rare10.nbt,3,CHEST:3,./StructureNBT/StructureLoot/Rare11.nbt,3,CHEST:3,./StructureNBT/StructureLoot/Rare12.nbt,3,CHEST:3,./StructureNBT/StructureLoot/Rare13.nbt,3,CHEST:3,./StructureNBT/StructureLoot/Rare14.nbt,3,CHEST:3,./StructureNBT/StructureLoot/Rare15.nbt,3,CHEST:3,./StructureNBT/StructureLoot/Epic1.nbt,3,CHEST:3,./StructureNBT/StructureLoot/Epic2.nbt,3,CHEST:3,./StructureNBT/StructureLoot/Epic3.nbt,3,CHEST:3,./StructureNBT/StructureLoot/Epic4.nbt,3,CHEST:3,./StructureNBT/StructureLoot/Epic5.nbt,3,CHEST:3,./StructureNBT/StructureLoot/Epic6.nbt,3,CHEST:3,./StructureNBT/StructureLoot/Epic7.nbt,3,CHEST:3,./StructureNBT/StructureLoot/Epic8.nbt,3,CHEST:3,./StructureNBT/StructureLoot/Epic9.nbt,3,CHEST:3,./StructureNBT/StructureLoot/Epic10.nbt,3,CHEST:3,./StructureNBT/StructureLoot/Epic11.nbt,3,CHEST:3,./StructureNBT/StructureLoot/Epic12.nbt,3,CHEST:3,./StructureNBT/StructureLoot/Epic13.nbt,3,CHEST:3,./StructureNBT/StructureLoot/Epic14.nbt,3,CHEST:3,./StructureNBT/StructureLoot/Epic15.nbt,100)
RandomBlock(-7,30,-1,CHEST,./StructureNBT/StructureLoot/JunkChest_1.nbt,20,CHEST,./StructureNBT/StructureLoot/JunkChest_2.nbt,15,CHEST,./StructureNBT/StructureLoot/JunkChest_3.nbt,15,CHEST,./StructureNBT/StructureLoot/JunkChest_4.nbt,15,CHEST,./StructureNBT/StructureLoot/JunkChest_5.nbt,15,CHEST,./StructureNBT/LoreStoryline/LoreGeneric_5.nbt,2,CHEST,./StructureNBT/LoreStoryline/LoreGeneric_4.nbt,2,CHEST,./StructureNBT/LoreStoryline/LoreGeneric_3.nbt,2,CHEST,./StructureNBT/LoreStoryline/LoreGeneric_2.nbt,2,CHEST,./StructureNBT/LoreStoryline/LoreGeneric_1.nbt,2,CHEST,./StructureNBT/LoreStoryline/LoreMedievalCity_5.nbt,3,CHEST,./StructureNBT/LoreStoryline/LoreMedievalCity_4.nbt,3,CHEST,./StructureNBT/LoreStoryline/LoreMedievalCity_3.nbt,3,CHEST,./StructureNBT/LoreStoryline/LoreMedievalCity_2.nbt,3,CHEST,./StructureNBT/LoreStoryline/LoreMedievalCity_1.nbt,3,CHEST,./StructureNBT/StructureLoot/Common1.nbt,3,CHEST,./StructureNBT/StructureLoot/Common2.nbt,3,CHEST,./StructureNBT/StructureLoot/Common3.nbt,3,CHEST,./StructureNBT/StructureLoot/Common4.nbt,3,CHEST,./StructureNBT/StructureLoot/Common5.nbt,3,CHEST,./StructureNBT/StructureLoot/Common5.nbt,3,CHEST,./StructureNBT/StructureLoot/Common6.nbt,3,CHEST,./StructureNBT/StructureLoot/Common7.nbt,3,CHEST,./StructureNBT/StructureLoot/Common8.nbt,3,CHEST,./StructureNBT/StructureLoot/Common9.nbt,3,CHEST,./StructureNBT/StructureLoot/Common10.nbt,3,CHEST,./StructureNBT/StructureLoot/Common11.nbt,3,CHEST,./StructureNBT/StructureLoot/Common12.nbt,3,CHEST,./StructureNBT/StructureLoot/Common13.nbt,3,CHEST,./StructureNBT/StructureLoot/Common14.nbt,3,CHEST,./StructureNBT/StructureLoot/Common15.nbt,3,CHEST,./StructureNBT/StructureLoot/Rare1.nbt,3,CHEST,./StructureNBT/StructureLoot/Rare2.nbt,3,CHEST,./StructureNBT/StructureLoot/Rare3.nbt,3,CHEST,./StructureNBT/StructureLoot/Rare4.nbt,3,CHEST,./StructureNBT/StructureLoot/Rare5.nbt,3,CHEST,./StructureNBT/StructureLoot/Rare6.nbt,3,CHEST,./StructureNBT/StructureLoot/Rare7.nbt,3,CHEST,./StructureNBT/StructureLoot/Rare8.nbt,3,CHEST,./StructureNBT/StructureLoot/Rare9.nbt,3,CHEST,./StructureNBT/StructureLoot/Rare10.nbt,3,CHEST,./StructureNBT/StructureLoot/Rare11.nbt,3,CHEST,./StructureNBT/StructureLoot/Rare12.nbt,3,CHEST,./StructureNBT/StructureLoot/Rare13.nbt,3,CHEST,./StructureNBT/StructureLoot/Rare14.nbt,3,CHEST,./StructureNBT/StructureLoot/Rare15.nbt,3,CHEST,./StructureNBT/StructureLoot/Epic1.nbt,3,CHEST,./StructureNBT/StructureLoot/Epic2.nbt,3,CHEST,./StructureNBT/StructureLoot/Epic3.nbt,3,CHEST,./StructureNBT/StructureLoot/Epic4.nbt,3,CHEST,./StructureNBT/StructureLoot/Epic5.nbt,3,CHEST,./StructureNBT/StructureLoot/Epic6.nbt,3,CHEST,./StructureNBT/StructureLoot/Epic7.nbt,3,CHEST,./StructureNBT/StructureLoot/Epic8.nbt,3,CHEST,./StructureNBT/StructureLoot/Epic9.nbt,3,CHEST,./StructureNBT/StructureLoot/Epic10.nbt,3,CHEST,./StructureNBT/StructureLoot/Epic11.nbt,3,CHEST,./StructureNBT/StructureLoot/Epic12.nbt,3,CHEST,./StructureNBT/StructureLoot/Epic13.nbt,3,CHEST,./StructureNBT/StructureLoot/Epic14.nbt,3,CHEST,./StructureNBT/StructureLoot/Epic15.nbt,100	)

Block(-8,15,-2,planks)
Block(-8,16,-2,planks)
Block(-8,17,-2,planks)
Block(-8,18,-2,planks)
Block(-8,19,-2,planks)
Block(-8,20,-2,planks)
Block(-8,21,-2,planks)
Block(-8,22,-3,planks)
Block(-8,22,-2,planks)
Block(-8,22,-1,planks)
Block(-8,23,-3,planks)
Block(-8,23,-2,planks)
Block(-8,23,-1,planks)
Block(-8,24,-4,wooden_slab:13)
Block(-8,24,-3,planks)
Block(-8,24,-2,planks)
Block(-8,24,-1,planks)
Block(-8,24,0,wooden_slab:13)
Block(-8,25,-4,planks)
Block(-8,25,-3,planks)
Block(-8,25,-2,planks)
Block(-8,25,-1,planks)
Block(-8,25,0,planks)
Block(-8,26,-5,wooden_slab:13)
Block(-8,26,-4,planks)
Block(-8,26,-3,planks)
Block(-8,26,-2,double_wooden_slab:3)
Block(-8,26,-1,planks)
Block(-8,26,0,planks)
Block(-8,26,1,wooden_slab:13)
Block(-8,27,-5,planks)
Block(-8,27,-4,planks)
Block(-8,27,-3,wooden_slab:13)
Block(-8,27,-2,wooden_slab:13)
Block(-8,27,-1,wooden_slab:13)
Block(-8,27,0,planks)
Block(-8,27,1,planks)
Block(-8,28,-6,wooden_slab:13)
Block(-8,28,-5,planks)
Block(-8,28,-4,stone_STAIRS:0)
Block(-8,28,-3,iron_bars)
Block(-8,28,-1,iron_bars)
Block(-8,28,0,stone_stairs:2)
Block(-8,28,1,planks)
Block(-8,28,2,wooden_slab:13)
Block(-8,29,-6,planks)
Block(-8,29,-5,wooden_slab:13)
Block(-8,29,-4,wooden_slab:13)
Block(-8,29,-3,wooden_slab:13)
Block(-8,29,-2,wooden_slab:13)
Block(-8,29,-1,wooden_slab:13)
Block(-8,29,0,wooden_slab:13)
Block(-8,29,1,wooden_slab:13)
Block(-8,29,2,planks)
Block(-8,30,-6,planks)
Block(-8,30,-5,bed:10)
Block(-8,30,-4,bed)
Block(-8,30,-2,bookshelf)
Block(-8,30,0,bed:0)
Block(-8,30,1,bed:8)
Block(-8,30,2,planks)
Block(-8,31,-6,planks)
Block(-8,31,-2,bookshelf)
Block(-8,31,2,planks)
Block(-8,32,-7,oak_stairs:6)
Block(-8,32,-6,planks)
Block(-8,32,-2,bookshelf)
Block(-8,32,2,planks)
Block(-8,32,3,oak_stairs:7)
Block(-8,33,-7,spruce_fence)
Block(-8,33,-6,planks:5)
Block(-8,33,-5,wooden_slab:5)
Block(-8,33,-4,double_wooden_slab:3)
Block(-8,33,-3,double_wooden_slab:3)
Block(-8,33,-2,double_wooden_slab:3)
Block(-8,33,-1,double_wooden_slab:3)
Block(-8,33,0,double_wooden_slab:3)
Block(-8,33,1,wooden_slab:5)
Block(-8,33,2,planks:5)
Block(-8,33,3,spruce_fence)
Block(-8,34,-7,spruce_fence)
Block(-8,34,-6,spruce_fence)
Block(-8,34,2,spruce_fence)
Block(-8,34,3,spruce_fence)
Block(-8,35,-6,spruce_fence)
Block(-8,35,2,spruce_fence)
Block(-8,36,-6,spruce_fence)
Block(-8,36,-1,wooden_slab:13)
Block(-8,36,2,spruce_fence)
Block(-8,37,-6,spruce_fence)
Block(-8,37,-5,spruce_fence)
Block(-8,37,-1,log:5)
Block(-8,37,1,spruce_fence)
Block(-8,37,2,spruce_fence)
Block(-8,38,-5,spruce_fence)
Block(-8,38,-1,log:5)
Block(-8,38,1,spruce_fence)
Block(-8,39,-5,spruce_fence)
Block(-8,39,-1,wool)
Block(-8,39,1,spruce_fence)
Block(-8,40,-5,spruce_fence)
Block(-8,40,-4,spruce_fence)
Block(-8,40,-1,wool)
Block(-8,40,0,spruce_fence)
Block(-8,40,1,spruce_fence)
Block(-8,41,0,wool)
Block(-8,42,1,wool:15)
Block(-8,43,1,wool:15)
Block(-8,44,1,wool:15)
Block(-8,45,2,wool:15)
Block(-8,46,2,wool:15)
Block(-8,47,2,wool)
Block(-8,48,1,wool)
Block(-8,49,1,wool:15)
Block(-8,50,1,wool:15)
Block(-8,51,0,wool:15)
Block(-8,52,-1,fence)
Block(-8,52,0,wool)
Block(-8,53,-1,log:5)
Block(-8,53,0,wool)
Block(-8,54,-1,wooden_slab:5)
Block(-8,60,-1,fence)
Block(-7,15,-2,dark_oak_fence)
Block(-7,16,-2,dark_oak_fence)
Block(-7,17,-2,dark_oak_fence)
Block(-7,18,-2,dark_oak_fence)
Block(-7,19,-2,dark_oak_fence)
Block(-7,20,-2,dark_oak_fence)
Block(-7,21,-2,dark_oak_fence)
Block(-7,22,-2,planks)
Block(-7,23,-2,planks)
Block(-7,24,-2,planks)
Block(-7,25,-3,wooden_slab:13)
Block(-7,25,-2,planks)
Block(-7,25,-1,wooden_slab:13)
Block(-7,26,-4,wooden_slab:13)
Block(-7,26,-3,planks)
Block(-7,26,-2,planks)
Block(-7,26,-1,planks)
Block(-7,26,0,wooden_slab:13)
Block(-7,27,-4,planks)
Block(-7,27,-3,dispenser:5,StructureNBT/SapphireCity/sap68/3-Trap.nbt)
Block(-7,27,-2,planks)
Block(-7,27,-1,dispenser:5,StructureNBT/SapphireCity/sap68/4-Trap.nbt)
Block(-7,27,0,planks)
Block(-7,28,-5,wooden_slab:13)
Block(-7,28,-4,planks)
Block(-7,28,-3,dispenser:4,StructureNBT/SapphireCity/sap68/5-Trap.nbt)
Block(-7,28,-2,planks)
Block(-7,28,-1,dispenser:4,StructureNBT/SapphireCity/sap68/6-Trap.nbt)
Block(-7,28,0,planks)
Block(-7,28,1,wooden_slab:13)
Block(-7,29,-6,wooden_slab:13)
Block(-7,29,-5,planks)
Block(-7,29,-4,wooden_slab:13)
Block(-7,29,-3,wooden_slab:13)
Block(-7,29,-2,wooden_slab:13)
Block(-7,29,-1,wooden_slab:13)
Block(-7,29,0,wooden_slab:13)
Block(-7,29,1,planks)
Block(-7,29,2,wooden_slab:13)
Block(-7,30,-6,planks)
Block(-7,30,-5,bed:10)
Block(-7,30,-4,bed)
Block(-7,30,-2,bookshelf)
Block(-7,30,0,bed:0)
Block(-7,30,1,bed:8)
Block(-7,30,2,planks)
Block(-7,31,-6,planks)
Block(-7,31,-2,bookshelf)
Block(-7,31,2,planks)
Block(-7,32,-7,oak_stairs:6)
Block(-7,32,-6,planks)
Block(-7,32,-2,bookshelf)
Block(-7,32,2,planks)
Block(-7,32,3,oak_stairs:7)
Block(-7,33,-7,spruce_fence)
Block(-7,33,-6,planks:5)
Block(-7,33,-5,wooden_slab:5)
Block(-7,33,-4,double_wooden_slab:3)
Block(-7,33,-3,double_wooden_slab:3)
Block(-7,33,-2,double_wooden_slab:3)
Block(-7,33,-1,double_wooden_slab:3)
Block(-7,33,0,double_wooden_slab:3)
Block(-7,33,1,wooden_slab:5)
Block(-7,33,2,planks:5)
Block(-7,33,3,spruce_fence)
Block(-7,34,-7,spruce_fence)
Block(-7,34,-6,spruce_fence)
Block(-7,34,-1,hay_block)
Block(-7,34,2,spruce_fence)
Block(-7,34,3,spruce_fence)
Block(-7,35,-6,spruce_fence)
Block(-7,35,2,spruce_fence)
Block(-7,36,-6,spruce_fence)
Block(-7,36,2,spruce_fence)
Block(-7,37,-1,wooden_slab:13)
Block(-7,38,-1,log:5)
Block(-7,39,-1,wool)
Block(-7,40,-1,wool)
Block(-7,40,0,wool)
Block(-7,41,0,wool)
Block(-7,42,1,wool:15)
Block(-7,43,1,wool:15)
Block(-7,44,2,wool:15)
Block(-7,45,2,wool:15)
Block(-7,46,3,wool:15)
Block(-7,47,2,wool)
Block(-7,48,2,wool)
Block(-7,49,1,wool:15)
Block(-7,50,1,wool:15)
Block(-7,51,1,wool:15)
Block(-7,52,-1,fence)
Block(-7,52,0,wool)
Block(-7,53,-1,log:5)
Block(-7,53,0,wool)
Block(-7,54,-1,wooden_slab:5)
Block(-7,54,0,log:5)
Block(-7,55,0,wooden_slab:5)
Block(-7,60,-1,fence)
Block(-6,15,-2,planks:5)
Block(-6,16,-2,planks:5)
Block(-6,17,-2,planks:5)
Block(-6,18,-2,planks:5)
Block(-6,19,-2,planks:5)
Block(-6,20,-2,planks:5)
Block(-6,21,-2,planks:5)
Block(-6,22,-2,dark_oak_fence)
Block(-6,23,-2,dark_oak_fence)
Block(-6,24,-2,dark_oak_fence)
Block(-6,25,-2,dark_oak_fence)
Block(-6,26,-2,dark_oak_fence)
Block(-6,27,-3,iron_bars)
Block(-6,27,-2,dark_oak_fence)
Block(-6,27,-1,iron_bars)
Block(-6,28,-4,wooden_slab:13)
Block(-6,28,-3,wooden_slab:13)
Block(-6,28,-2,dark_oak_fence)
Block(-6,28,-1,wooden_slab:13)
Block(-6,28,0,wooden_slab:13)
Block(-6,29,-5,wooden_slab:13)
Block(-6,29,-4,planks)
Block(-6,29,-3,planks)
Block(-6,29,-2,planks)
Block(-6,29,-1,planks)
Block(-6,29,0,planks)
Block(-6,29,1,wooden_slab:13)
Block(-6,30,-5,planks)
Block(-6,30,-4,planks)
Block(-6,30,-3,planks)
Block(-6,30,-2,planks)
Block(-6,30,-1,planks)
Block(-6,30,0,planks)
Block(-6,30,1,planks)
Block(-6,31,-5,planks)
Block(-6,31,-4,wooden_slab:13)
Block(-6,31,-3,planks)
Block(-6,31,-2,planks)
Block(-6,31,-1,planks)
Block(-6,31,0,wooden_slab:13)
Block(-6,31,1,planks)
Block(-6,32,-5,planks)
Block(-6,32,-4,planks)
Block(-6,32,-3,planks)
Block(-6,32,-2,planks)
Block(-6,32,-1,planks)
Block(-6,32,0,planks)
Block(-6,32,1,planks)
Block(-6,33,-5,planks:5)
Block(-6,33,-4,wooden_slab:5)
Block(-6,33,-3,wooden_slab:5)
Block(-6,33,-2,wooden_slab:5)
Block(-6,33,-1,wooden_slab:5)
Block(-6,33,0,wooden_slab:5)
Block(-6,33,1,planks:5)
Block(-6,34,-5,wooden_slab:5)
Block(-6,34,1,wooden_slab:5)
Block(-6,37,-1,wooden_slab:13)
Block(-6,38,-1,log:5)
Block(-6,39,-1,wool)
Block(-6,40,-1,wool)
Block(-6,41,0,wool)
Block(-6,42,1,wool)
Block(-6,43,2,wool)
Block(-6,44,2,wool:15)
Block(-6,45,3,wool:15)
Block(-6,46,3,wool)
Block(-6,47,3,wool:15)
Block(-6,48,2,wool:15)
Block(-6,49,2,wool)
Block(-6,50,1,wool:15)
Block(-6,51,1,wool:15)
Block(-6,52,-1,fence)
Block(-6,52,0,fence)
Block(-6,52,1,wool:15)
Block(-6,53,-1,log:5)
Block(-6,53,0,wool)
Block(-6,54,-1,wooden_slab:5)
Block(-6,54,0,log:5)
Block(-6,55,0,wooden_slab:5)
Block(-6,60,-1,fence)
Block(-5,15,-2,planks:5)
Block(-5,16,-2,planks:5)
Block(-5,17,-2,planks:5)
Block(-5,18,-2,planks:5)
Block(-5,19,-2,planks:5)
Block(-5,20,-2,planks:5)
Block(-5,21,-2,planks:5)
Block(-5,22,-2,planks:5)
Block(-5,23,-2,planks:5)
Block(-5,24,-2,planks:5)
Block(-5,25,-2,planks:5)
Block(-5,26,-3,iron_bars)
Block(-5,26,-2,planks:5)
Block(-5,26,-1,iron_bars)
Block(-5,27,-3,iron_bars)
Block(-5,27,-2,planks:5)
Block(-5,27,-1,iron_bars)
Block(-5,28,-2,planks:5)
Block(-5,29,-2,wooden_slab:13)
Block(-5,30,-4,wall_banner:5,StructureNBT/SapphireCity/sap68/9-Banner.nbt)
Block(-5,30,-3,wooden_slab:13)
Block(-5,30,-2,planks)
Block(-5,30,-1,wooden_slab:13)
Block(-5,30,0,wall_banner:5,StructureNBT/SapphireCity/sap68/10-Banner.nbt)
Block(-5,31,-4,wooden_slab:13)
Block(-5,31,-3,planks)
Block(-5,31,-2,planks)
Block(-5,31,-1,planks)
Block(-5,31,0,wooden_slab:13)
Block(-5,32,-4,dark_oak_STAIRS:0)
Block(-5,32,-3,dark_oak_stairs:1)
Block(-5,32,-2,double_wooden_slab:5)
Block(-5,32,-1,dark_oak_stairs:1)
Block(-5,32,0,dark_oak_stairs:2)
Block(-5,33,-4,planks:5)
Block(-5,33,-3,wooden_slab:13)
Block(-5,33,-2,wooden_slab:13)
Block(-5,33,-1,wooden_slab:13)
Block(-5,33,0,planks:5)
Block(-5,34,-4,dark_oak_stairs:2)
Block(-5,34,-3,wooden_slab:13)
Block(-5,34,-2,double_wooden_slab:5)
Block(-5,34,-1,wooden_slab:13)
Block(-5,34,0,dark_oak_STAIRS:0)
Block(-5,35,-3,wooden_slab:5)
Block(-5,35,-2,double_wooden_slab:5)
Block(-5,35,-1,wooden_slab:5)
Block(-5,37,-1,wooden_slab:13)
Block(-5,38,-1,log:5)
Block(-5,39,-1,wool)
Block(-5,40,-1,wool)
Block(-5,41,0,wool)
Block(-5,42,1,wool)
Block(-5,43,2,wool)
Block(-5,44,3,wool:15)
Block(-5,45,4,wool:15)
Block(-5,46,4,wool:15)
Block(-5,47,3,wool:15)
Block(-5,48,3,wool:15)
Block(-5,49,2,wool:15)
Block(-5,50,2,wool:15)
Block(-5,51,2,wool:15)
Block(-5,52,1,wool:15)
Block(-5,53,0,fence)
Block(-5,53,1,wool)
Block(-5,54,0,log:5)
Block(-5,55,0,wooden_slab:5)
Block(-5,59,-1,fence)
Block(-5,59,0,fence)
Block(-5,60,-1,fence)
Block(-4,15,-2,planks:5)
Block(-4,16,-2,planks:5)
Block(-4,17,-2,planks:5)
Block(-4,18,-2,planks:5)
Block(-4,19,-2,planks:5)
Block(-4,20,-2,planks:5)
Block(-4,21,-2,planks:5)
Block(-4,22,-2,planks:5)
Block(-4,23,-2,planks:5)
Block(-4,24,-2,planks:5)
Block(-4,25,-3,iron_bars)
Block(-4,25,-2,planks:5)
Block(-4,25,-1,iron_bars)
Block(-4,26,-3,iron_bars)
Block(-4,26,-2,planks:5)
Block(-4,26,-1,iron_bars)
Block(-4,27,-2,planks:5)
Block(-4,28,-2,dark_oak_stairs:1)
Block(-4,37,-1,wooden_slab:13)
Block(-4,38,-1,log:5)
Block(-4,39,-1,wool)
Block(-4,40,0,wool)
Block(-4,41,0,wool)
Block(-4,42,1,wool)
Block(-4,43,2,wool:15)
Block(-4,44,2,wool:15)
Block(-4,45,3,wool:15)
Block(-4,46,4,wool:15)
Block(-4,47,4,wool)
Block(-4,48,3,wool:15)
Block(-4,49,3,wool:15)
Block(-4,50,3,wool:15)
Block(-4,51,2,wool:15)
Block(-4,52,2,wool:15)
Block(-4,53,0,fence)
Block(-4,53,1,wool)
Block(-4,54,0,log:5)
Block(-4,54,1,wool)
Block(-4,55,0,wooden_slab:5)
Block(-4,59,0,fence)
Block(-3,15,-2,planks:5)
Block(-3,16,-2,planks:5)
Block(-3,17,-2,planks:5)
Block(-3,18,-2,planks:5)
Block(-3,19,-2,planks:5)
Block(-3,20,-2,planks:5)
Block(-3,21,-2,planks:5)
Block(-3,22,-2,planks:5)
Block(-3,23,-2,planks:5)
Block(-3,24,-2,planks:5)
Block(-3,25,-3,iron_bars)
Block(-3,25,-2,planks:5)
Block(-3,25,-1,iron_bars)
Block(-3,26,-2,dark_oak_stairs:1)
Block(-3,37,-1,wooden_slab:13)
Block(-3,38,-1,log:5)
Block(-3,39,-1,wool)
Block(-3,40,0,wool)
Block(-3,41,0,wool)
Block(-3,42,1,wool)
Block(-3,43,2,wool:15)
Block(-3,44,2,wool:15)
Block(-3,45,3,wool:15)
Block(-3,46,4,wool)
Block(-3,47,4,wool)
Block(-3,48,4,wool)
Block(-3,49,4,wool)
Block(-3,50,3,wool:15)
Block(-3,51,3,wool:15)
Block(-3,52,2,wool:15)
Block(-3,53,0,fence)
Block(-3,53,1,wool)
Block(-3,54,0,log:5)
Block(-3,54,1,wool)
Block(-3,55,0,log:5)
Block(-3,56,0,wooden_slab:5)
Block(-3,59,0,fence)
Block(-2,15,-2,planks:5)
Block(-2,16,-2,planks:5)
Block(-2,17,-2,planks:5)
Block(-2,18,-2,planks:5)
Block(-2,19,-2,dark_oak_stairs:1)
Block(-2,37,-1,wooden_slab:13)
Block(-2,38,-1,log:5)
Block(-2,39,-1,fence)
Block(-2,39,0,wool)
Block(-2,40,0,wool)
Block(-2,41,0,wool)
Block(-2,42,1,wool)
Block(-2,43,2,wool:15)
Block(-2,44,2,wool:15)
Block(-2,45,3,wool)
Block(-2,46,4,wool)
Block(-2,47,4,wool)
Block(-2,48,5,wool)
Block(-2,49,4,wool)
Block(-2,50,4,wool)
Block(-2,51,3,wool:15)
Block(-2,52,2,wool)
Block(-2,53,2,wool)
Block(-2,54,0,fence)
Block(-2,54,1,wool)
Block(-2,55,0,log:5)
Block(-2,55,1,wool)
Block(-2,56,0,wooden_slab:5)
Block(-2,59,0,fence)
Block(-1,37,-1,wooden_slab:13)
Block(-1,38,-1,log:5)
Block(-1,38,0,wooden_slab:13)
Block(-1,39,-1,fence)
Block(-1,39,0,log:5)
Block(-1,40,0,wool)
Block(-1,41,1,wool)
Block(-1,42,1,wool:15)
Block(-1,43,2,wool:15)
Block(-1,44,3,wool:15)
Block(-1,45,4,wool:15)
Block(-1,46,4,wool:15)
Block(-1,47,4,wool:15)
Block(-1,48,5,wool:15)
Block(-1,49,5,wool:15)
Block(-1,50,4,wool)
Block(-1,51,3,wool:15)
Block(-1,52,2,wool:15)
Block(-1,53,2,wool)
Block(-1,54,0,fence)
Block(-1,54,1,wool)
Block(-1,55,0,log:5)
Block(-1,55,1,wool)
Block(-1,56,0,wooden_slab:5)
Block(-1,58,0,fence)
Block(-1,58,1,fence)
Block(-1,59,0,fence)
Block(0,38,0,wooden_slab:13)
Block(0,39,0,log:5)
Block(0,40,0,wool)
Block(0,41,1,wool:15)
Block(0,42,2,wool:15)
Block(0,43,2,wool:15)
Block(0,44,3,wool:15)
Block(0,45,4,wool:15)
Block(0,46,3,wool:15)
Block(0,47,4,wool:15)
Block(0,48,5,wool:15)
Block(0,49,5,wool:15)
Block(0,50,4,wool:15)
Block(0,51,3,wool:15)
Block(0,52,3,wool:15)
Block(0,53,2,wool:15)
Block(0,54,0,fence)
Block(0,54,1,wool)
Block(0,55,0,log:5)
Block(0,55,1,wool)
Block(0,56,0,wooden_slab:5)
Block(0,56,1,log:5)
Block(0,57,1,wooden_slab:5)
Block(0,58,1,fence)
Block(1,38,0,wooden_slab:13)
Block(1,39,0,log:5)
Block(1,40,0,wool:15)
Block(1,41,1,wool:15)
Block(1,42,2,wool:15)
Block(1,43,3,wool:15)
Block(1,44,3,wool:15)
Block(1,45,3,wool:15)
Block(1,46,3,wool)
Block(1,47,4,wool:15)
Block(1,48,4,wool:15)
Block(1,49,4,wool:15)
Block(1,50,4,wool:15)
Block(1,51,4,wool:15)
Block(1,52,3,wool:15)
Block(1,53,3,wool:15)
Block(1,54,2,wool:15)
Block(1,55,1,fence)
Block(1,55,2,wool)
Block(1,56,1,log:5)
Block(1,57,1,fence)
Block(1,58,1,fence)
Block(2,38,0,wooden_slab:13)
Block(2,39,0,log:5)
Block(2,40,0,wool:15)
Block(2,41,0,wool:15)
Block(2,42,1,wool:15)
Block(2,43,2,wool:15)
Block(2,44,2,wool)
Block(2,45,2,wool)
Block(2,46,3,wool)
Block(2,47,3,wool)
Block(2,48,3,wool)
Block(2,49,4,wool:15)
Block(2,50,4,wool:15)
Block(2,51,4,wool:15)
Block(2,52,3,wool:15)
Block(2,53,2,wool:15)
Block(2,54,2,wool)
Block(2,55,1,fence)
Block(2,55,2,wool)
Block(2,56,1,log:5)
Block(2,57,1,fence)
Block(3,38,0,wooden_slab:13)
Block(3,39,0,log:5)
Block(3,40,0,wool:15)
Block(3,41,0,wool:15)
Block(3,42,1,wool)
Block(3,43,1,wool)
Block(3,44,1,wool)
Block(3,45,2,wool)
Block(3,46,2,wool)
Block(3,47,2,wool)
Block(3,48,3,wool)
Block(3,49,3,wool)
Block(3,50,3,wool:15)
Block(3,51,4,wool:15)
Block(3,52,3,wool:15)
Block(3,53,2,wool)
Block(3,54,2,wool)
Block(3,55,1,wool)
Block(3,56,1,log:5)
Block(3,57,1,wooden_slab:5)
Block(4,38,0,wooden_slab:13)
Block(4,39,0,log:5)
Block(4,40,0,log:5)
Block(4,41,0,wool)
Block(4,42,0,wool)
Block(4,43,0,wool)
Block(4,44,1,wool)
Block(4,45,1,wool)
Block(4,46,1,wool)
Block(4,47,2,wool)
Block(4,48,2,wool)
Block(4,49,2,wool)
Block(4,50,3,wool)
Block(4,51,3,wool:15)
Block(4,52,2,wool)
Block(4,53,2,wool)
Block(4,54,1,wool)
Block(4,55,1,fence)
Block(4,56,1,fence)
Block(4,57,1,wooden_slab:5)
Block(5,39,0,wooden_slab:13)
Block(5,40,0,log:5)
Block(5,41,0,wool)
Block(5,42,0,wool)
Block(5,43,0,fence)
Block(5,43,1,fence)
Block(5,44,1,fence)
Block(5,45,1,fence)
Block(5,46,1,fence)
Block(5,46,2,fence)
Block(5,47,2,fence)
Block(5,48,2,fence)
Block(5,49,2,fence)
Block(5,49,3,fence)
Block(5,50,3,fence)
Block(5,51,3,fence)
Block(5,52,2,fence)
Block(5,52,3,fence)
Block(5,53,2,fence)
Block(5,54,1,fence)
Block(5,54,2,fence)
Block(6,39,0,wooden_slab:13)
Block(6,40,0,log:5)
Block(6,41,0,wool)
Block(6,42,0,fence)
Block(6,43,0,fence)
Block(7,39,0,wooden_slab:13)
Block(7,40,0,fence)
Block(7,41,0,fence)
Block(7,42,0,fence)

#######################################################################
# +-----------------------------------------------------------------+ #
# |                            BO3 checks                           | #
# +-----------------------------------------------------------------+ #
#######################################################################


#######################################################################
# +-----------------------------------------------------------------+ #
# |                             Branches                            | #
# +-----------------------------------------------------------------+ #
#######################################################################

