
#######################################################################
# +-----------------------------------------------------------------+ #
# |                            BO3 object                           | #
# +-----------------------------------------------------------------+ #
#######################################################################

Author: NLBlackEagle

Description: No description given

Version: 3

SettingsMode: WriteDisable


#######################################################################
# +-----------------------------------------------------------------+ #
# |                          Main settings                          | #
# +-----------------------------------------------------------------+ #
#######################################################################

Tree: false

Frequency: 1

Rarity: 25.0

RotateRandomly: false

SpawnHeight: randomY

SpawnHeightOffset: 0

SpawnHeightVariance: 0

##############################
# Height Limits for the BO3. #
##############################

MinHeight: 47

MaxHeight: 47

######################
# Extrusion settings #
######################

ExtrudeMode: None

ExtrudeThroughBlocks: air

MaxBranchDepth: 60

ExcludedBiomes: All


#######################################################################
# +-----------------------------------------------------------------+ #
# |                      Source block settings                      | #
# +-----------------------------------------------------------------+ #
#######################################################################

SourceBlocks: air

MaxPercentageOutsideSourceBlock: 100

OutsideSourceBlock: placeAnyway


#######################################################################
# +-----------------------------------------------------------------+ #
# |                              Blocks                             | #
# +-----------------------------------------------------------------+ #
#######################################################################

Block(-8,1,-8,cobblestone)
Block(-8,1,-7,cobblestone)
Block(-8,1,-6,cobblestone)
Block(-8,1,-5,cobblestone)
Block(-8,1,-4,cobblestone)
Block(-8,1,-1,air)
Block(-8,1,0,cobblestone)
Block(-8,2,-4,cobblestone)
Block(-8,2,-1,air)
Block(-8,2,0,cobblestone)
Block(-8,3,-4,cobblestone)
Block(-8,3,-1,air)
Block(-8,3,0,cobblestone)
Block(-8,4,-4,cobblestone)
Block(-8,4,-1,air)
Block(-8,4,0,cobblestone)
Block(-8,5,-4,cobblestone)
Block(-8,5,-1,air)
Block(-8,5,0,cobblestone)
Block(-8,6,-4,cobblestone)
Block(-8,6,-1,air)
Block(-8,6,0,cobblestone)
Block(-8,7,-4,cobblestone)
Block(-8,7,-1,air)
Block(-8,7,0,cobblestone)
Block(-8,8,-4,cobblestone)
Block(-8,8,-1,air)
Block(-8,8,0,cobblestone)
Block(-8,9,-4,cobblestone)
Block(-8,9,-1,air)
Block(-8,9,0,cobblestone)
Block(-8,10,-4,cobblestone)
Block(-8,10,-1,air)
Block(-8,10,0,cobblestone)
Block(-8,11,-4,cobblestone)
Block(-8,11,-3,cobblestone)
Block(-8,11,-2,cobblestone)
Block(-8,11,-1,cobblestone)
Block(-8,11,0,cobblestone)
Block(-8,12,-4,cobblestone)
Block(-8,12,-3,cobblestone)
Block(-8,12,-2,cobblestone)
Block(-8,12,-1,cobblestone)
Block(-8,12,0,stone_STAIRS:0)
Block(-8,13,-4,stone:6)
Block(-8,13,-3,stone:6)
Block(-8,13,-2,stone:6)
Block(-8,13,-1,stone:6)
Block(-8,14,-4,stone:6)
Block(-8,14,-3,stone:6)
Block(-8,14,-2,stone:6)
Block(-8,14,-1,stone:6)
Block(-8,15,-4,stone:6)
Block(-8,15,-3,stone:6)
Block(-8,15,-2,stone:6)
Block(-8,15,-1,stone:6)
Block(-8,16,-4,stone:6)
Block(-8,16,-3,stone:6)
Block(-8,16,-2,stone:6)
Block(-8,16,-1,stone_STAIRS:0)
Block(-8,17,-4,stone:6)
Block(-8,17,-3,stone:6)
Block(-8,17,-2,stone:6)
Block(-8,18,-4,stone:6)
Block(-8,18,-3,stone:6)
Block(-8,18,-2,stone:6)
Block(-8,19,-4,stone:6)
Block(-8,19,-3,stone:6)
Block(-8,19,-2,stone:6)
Block(-8,20,-4,stone:6)
Block(-8,20,-3,stone:6)
Block(-8,20,-2,stone_STAIRS:0)
Block(-8,21,-8,stone:6)
Block(-8,21,-7,stone:6)
Block(-8,21,-6,stone:6)
Block(-8,21,-5,stone:6)
Block(-8,21,-4,stone:6)
Block(-8,21,-3,stone:6)
Block(-8,22,-8,cobblestone)
Block(-8,22,-7,cobblestone)
Block(-8,22,-6,cobblestone)
Block(-8,22,-5,cobblestone)
Block(-8,22,-4,stone:6)
Block(-8,22,-3,stone:6)
Block(-8,23,-8,water:3)
Block(-8,23,-7,water:2)
Block(-8,23,-6,cobblestone)
Block(-8,23,-5,cobblestone)
Block(-8,23,-4,stone:6)
Block(-8,23,-3,stone:6)
Block(-8,24,-8,cobblestone)
Block(-8,24,-7,cobblestone)
Block(-8,24,-6,cobblestone)
Block(-8,24,-5,cobblestone)
Block(-8,24,-4,stone:6)
Block(-8,24,-3,stone_STAIRS:0)
Block(-8,25,-8,cobblestone)
Block(-8,25,-7,cobblestone)
Block(-8,25,-6,cobblestone)
Block(-8,25,-5,cobblestone)
Block(-8,25,-4,stone:6)
Block(-8,26,-8,cobblestone)
Block(-8,26,-7,cobblestone)
Block(-8,26,-6,stone:6)
Block(-8,26,-5,stone:6)
Block(-8,26,-4,stone:6)
Block(-8,27,-6,cobblestone)
Block(-8,27,-5,cobblestone)
Block(-8,27,-4,cobblestone)
Block(-8,28,-6,cobblestone)
Block(-8,28,-5,cobblestone)
Block(-8,28,-4,stone:6)
Block(-8,29,-8,wooden_slab:5)
Block(-8,29,-7,wooden_slab:5)
Block(-8,29,-6,cobblestone)
Block(-8,29,-5,stone_stairs:0)
Block(-8,29,-4,dark_oak_fence)
Block(-8,30,-6,cobblestone)
Block(-8,30,-5,stone_stairs:7)
Block(-8,31,-6,stonebrick)
Block(-8,31,-5,stonebrick)
Block(-8,32,-7,dark_oak_stairs:4)
Block(-8,32,-6,stonebrick)
Block(-8,32,-5,stonebrick)
Block(-8,32,-4,dark_oak_stairs:4)
Block(-8,33,-7,dark_oak_stairs:1)
Block(-8,33,-4,dark_oak_stairs:1)
Block(-8,36,-8,dark_oak_stairs:4)
Block(-8,37,-8,dark_oak_stairs:1)
Block(-7,1,-8,cobblestone)
Block(-7,1,-7,cobblestone)
Block(-7,1,-6,cobblestone)
Block(-7,1,-5,cobblestone)
Block(-7,1,-4,cobblestone)
Block(-7,1,-3,log)
Block(-7,1,-1,air)
Block(-7,1,0,log)
Block(-7,2,-4,cobblestone)
Block(-7,2,-3,log)
Block(-7,2,-1,air)
Block(-7,2,0,log)
Block(-7,3,-4,cobblestone)
Block(-7,3,-3,log)
Block(-7,3,-1,air)
Block(-7,3,0,log)
Block(-7,4,-4,cobblestone)
Block(-7,4,-3,log)
Block(-7,4,-1,air)
Block(-7,4,0,log)
Block(-7,5,-4,cobblestone)
Block(-7,5,-3,log)
Block(-7,5,-1,air)
Block(-7,5,0,log)
Block(-7,6,-4,cobblestone)
Block(-7,6,-3,log)
Block(-7,6,-1,air)
Block(-7,6,0,log)
Block(-7,7,-4,cobblestone)
Block(-7,7,-3,log)
Block(-7,7,-1,air)
Block(-7,7,0,log)
Block(-7,8,-4,cobblestone)
Block(-7,8,-3,log)
Block(-7,8,-1,air)
Block(-7,8,0,log)
Block(-7,9,-4,cobblestone)
Block(-7,9,-3,log)
Block(-7,9,-1,air)
Block(-7,9,0,log)
Block(-7,10,-4,cobblestone)
Block(-7,10,-3,log)
Block(-7,10,-1,air)
Block(-7,10,0,log)
Block(-7,11,-4,cobblestone)
Block(-7,11,-3,log)
Block(-7,11,-2,cobblestone)
Block(-7,11,-1,cobblestone)
Block(-7,11,0,log)
Block(-7,12,-4,cobblestone)
Block(-7,12,-3,log)
Block(-7,12,-2,log:8)
Block(-7,12,-1,log:8)
Block(-7,12,0,stone_brick_STAIRS:0)
Block(-7,13,-4,stone:6)
Block(-7,13,-3,log)
Block(-7,13,-1,log)
Block(-7,14,-4,stone:6)
Block(-7,14,-3,log)
Block(-7,14,-1,log)
Block(-7,15,-4,stone:6)
Block(-7,15,-3,log)
Block(-7,15,-1,log)
Block(-7,16,-4,stone:6)
Block(-7,16,-3,log)
Block(-7,16,-1,log)
Block(-7,17,-4,stone:6)
Block(-7,17,-3,log)
Block(-7,17,-2,log:8)
Block(-7,17,-1,stone_STAIRS:0)
Block(-7,18,-4,stone:6)
Block(-7,18,-3,log)
Block(-7,19,-4,stone:6)
Block(-7,19,-3,log)
Block(-7,20,-4,stone:6)
Block(-7,20,-3,log)
Block(-7,21,-8,stone:6)
Block(-7,21,-7,stone:6)
Block(-7,21,-6,stone:6)
Block(-7,21,-5,stone:6)
Block(-7,21,-4,stone:6)
Block(-7,21,-3,log)
Block(-7,22,-8,cobblestone)
Block(-7,22,-7,cobblestone)
Block(-7,22,-6,cobblestone)
Block(-7,22,-5,cobblestone)
Block(-7,22,-4,stone:6)
Block(-7,22,-3,log)
Block(-7,23,-8,double_stone_slab:3)
Block(-7,23,-7,double_stone_slab:3)
Block(-7,23,-6,log)
Block(-7,23,-5,cobblestone)
Block(-7,23,-4,stone:6)
Block(-7,23,-3,log)
Block(-7,24,-8,water:8)
Block(-7,24,-7,water:8)
Block(-7,24,-6,log)
Block(-7,24,-5,cobblestone)
Block(-7,24,-4,stone:6)
Block(-7,24,-3,log)
Block(-7,25,-8,water:8)
Block(-7,25,-7,water:8)
Block(-7,25,-6,log)
Block(-7,25,-5,cobblestone)
Block(-7,25,-4,stone:6)
Block(-7,25,-3,log)
Block(-7,26,-8,water)
Block(-7,26,-7,water)
Block(-7,26,-6,log)
Block(-7,26,-5,stone:6)
Block(-7,26,-4,stone:6)
Block(-7,26,-3,stone_brick_STAIRS:0)
Block(-7,27,-6,log)
Block(-7,27,-5,cobblestone)
Block(-7,27,-4,log)
Block(-7,28,-6,log)
Block(-7,28,-5,cobblestone)
Block(-7,28,-4,log)
Block(-7,29,-6,log)
Block(-7,29,-5,log:8)
Block(-7,29,-4,stone_brick_STAIRS:0)
Block(-7,30,-6,log)
Block(-7,30,-5,stone_stairs:7)
Block(-7,31,-6,stone:6)
Block(-7,31,-5,stone:6)
Block(-7,32,-7,dark_oak_stairs:6)
Block(-7,32,-6,stonebrick)
Block(-7,32,-5,stone:6)
Block(-7,32,-4,dark_oak_stairs:7)
Block(-7,33,-7,stonebrick)
Block(-7,33,-4,stonebrick)
Block(-7,34,-7,wooden_slab:5)
Block(-7,34,-4,wooden_slab:5)
Block(-7,35,-8,dark_oak_stairs:4)
Block(-7,36,-8,dark_oak_stairs:1)
Block(-6,1,-8,cobblestone)
Block(-6,1,-7,cobblestone)
Block(-6,1,-6,cobblestone)
Block(-6,1,-5,cobblestone)
Block(-6,1,-4,cobblestone)
Block(-6,1,-1,air)
Block(-6,1,0,cobblestone)
Block(-6,2,-4,cobblestone)
Block(-6,2,-1,air)
Block(-6,2,0,cobblestone)
Block(-6,3,-4,cobblestone)
Block(-6,3,-1,air)
Block(-6,3,0,cobblestone)
Block(-6,4,-4,cobblestone)
Block(-6,4,-1,air)
Block(-6,4,0,cobblestone)
Block(-6,5,-4,cobblestone)
Block(-6,5,-1,air)
Block(-6,5,0,cobblestone)
Block(-6,6,-4,cobblestone)
Block(-6,6,-1,air)
Block(-6,6,0,cobblestone)
Block(-6,7,-4,cobblestone)
Block(-6,7,-1,air)
Block(-6,7,0,cobblestone)
Block(-6,8,-4,cobblestone)
Block(-6,8,-1,air)
Block(-6,8,0,cobblestone)
Block(-6,9,-4,cobblestone)
Block(-6,9,-1,air)
Block(-6,9,0,cobblestone)
Block(-6,10,-4,cobblestone)
Block(-6,10,-1,air)
Block(-6,10,0,cobblestone)
Block(-6,11,-4,cobblestone)
Block(-6,11,-3,cobblestone)
Block(-6,11,-2,cobblestone)
Block(-6,11,-1,cobblestone)
Block(-6,11,0,cobblestone)
Block(-6,12,-4,cobblestone)
Block(-6,12,-3,cobblestone)
Block(-6,12,-2,cobblestone)
Block(-6,12,-1,cobblestone)
Block(-6,12,0,stone_STAIRS:0)
Block(-6,13,-4,stone:6)
Block(-6,13,-3,stone:6)
Block(-6,13,-2,stone:6)
Block(-6,13,-1,stone:6)
Block(-6,14,-4,stone:6)
Block(-6,14,-3,stone:6)
Block(-6,14,-2,stone:6)
Block(-6,14,-1,stone:6)
Block(-6,15,-4,stone:6)
Block(-6,15,-3,stone:6)
Block(-6,15,-2,stone:6)
Block(-6,15,-1,stone:6)
Block(-6,16,-4,stone:6)
Block(-6,16,-3,stone:6)
Block(-6,16,-2,stone:6)
Block(-6,16,-1,stone_STAIRS:0)
Block(-6,17,-4,stone:6)
Block(-6,17,-3,stone:6)
Block(-6,17,-2,stone:6)
Block(-6,18,-4,stone:6)
Block(-6,18,-3,stone:6)
Block(-6,18,-2,stone:6)
Block(-6,19,-4,stone:6)
Block(-6,19,-3,stone:6)
Block(-6,19,-2,stone:6)
Block(-6,20,-4,stone:6)
Block(-6,20,-3,stone:6)
Block(-6,20,-2,stone_STAIRS:0)
Block(-6,21,-8,stone:6)
Block(-6,21,-7,stone:6)
Block(-6,21,-6,stone:6)
Block(-6,21,-5,stone:6)
Block(-6,21,-4,stone:6)
Block(-6,21,-3,stone:6)
Block(-6,22,-8,cobblestone)
Block(-6,22,-7,cobblestone)
Block(-6,22,-6,cobblestone)
Block(-6,22,-5,cobblestone)
Block(-6,22,-4,stone:6)
Block(-6,22,-3,stone:6)
Block(-6,23,-8,double_stone_slab:3)
Block(-6,23,-7,cobblestone)
Block(-6,23,-6,cobblestone)
Block(-6,23,-5,cobblestone)
Block(-6,23,-4,stone:6)
Block(-6,23,-3,stone:6)
Block(-6,24,-8,water:8)
Block(-6,24,-7,water:8)
Block(-6,24,-6,cobblestone)
Block(-6,24,-5,cobblestone)
Block(-6,24,-4,stone:6)
Block(-6,24,-3,stone_STAIRS:0)
Block(-6,25,-8,water:8)
Block(-6,25,-7,water:8)
Block(-6,25,-6,cobblestone)
Block(-6,25,-5,cobblestone)
Block(-6,25,-4,stone:6)
Block(-6,26,-8,water)
Block(-6,26,-7,water)
Block(-6,26,-6,stone:6)
Block(-6,26,-5,stone:6)
Block(-6,26,-4,stone:6)
Block(-6,27,-6,cobblestone)
Block(-6,27,-5,cobblestone)
Block(-6,27,-4,cobblestone)
Block(-6,28,-6,cobblestone)
Block(-6,28,-5,cobblestone)
Block(-6,28,-4,stone:6)
Block(-6,29,-6,cobblestone)
Block(-6,29,-5,stone_stairs:1)
Block(-6,29,-4,dark_oak_fence)
Block(-6,30,-6,cobblestone)
Block(-6,30,-5,stone_stairs:7)
Block(-6,31,-6,stonebrick)
Block(-6,31,-5,stonebrick)
Block(-6,32,-7,dark_oak_stairs:5)
Block(-6,32,-6,stonebrick)
Block(-6,32,-5,stonebrick)
Block(-6,32,-4,dark_oak_stairs:5)
Block(-6,33,-7,dark_oak_stairs:0)
Block(-6,33,-4,dark_oak_stairs:0)
Block(-6,35,-8,dark_oak_STAIRS:0)
Block(-5,1,-8,cobblestone)
Block(-5,1,-7,cobblestone)
Block(-5,1,-6,cobblestone)
Block(-5,1,-5,cobblestone)
Block(-5,1,-4,cobblestone)
Block(-5,1,-1,air)
Block(-5,1,0,cobblestone)
Block(-5,2,-4,cobblestone)
Block(-5,2,-1,air)
Block(-5,2,0,cobblestone)
Block(-5,3,-4,cobblestone)
Block(-5,3,-1,air)
Block(-5,3,0,cobblestone)
Block(-5,4,-4,cobblestone)
Block(-5,4,-1,air)
Block(-5,4,0,cobblestone)
Block(-5,5,-4,cobblestone)
Block(-5,5,-1,air)
Block(-5,5,0,cobblestone)
Block(-5,6,-4,cobblestone)
Block(-5,6,-1,air)
Block(-5,6,0,cobblestone)
Block(-5,7,-4,cobblestone)
Block(-5,7,-1,air)
Block(-5,7,0,cobblestone)
Block(-5,8,-4,cobblestone)
Block(-5,8,-1,air)
Block(-5,8,0,cobblestone)
Block(-5,9,-4,cobblestone)
Block(-5,9,-1,air)
Block(-5,9,0,cobblestone)
Block(-5,10,-4,cobblestone)
Block(-5,10,-1,air)
Block(-5,10,0,cobblestone)
Block(-5,11,-4,cobblestone)
Block(-5,11,-3,cobblestone)
Block(-5,11,-2,cobblestone)
Block(-5,11,-1,cobblestone)
Block(-5,11,0,cobblestone)
Block(-5,12,-4,cobblestone)
Block(-5,12,-3,cobblestone)
Block(-5,12,-2,cobblestone)
Block(-5,12,-1,cobblestone)
Block(-5,12,0,stone_STAIRS:0)
Block(-5,13,-4,stone:6)
Block(-5,13,-3,stone:6)
Block(-5,13,-2,stone:6)
Block(-5,13,-1,stonebrick:3)
Block(-5,14,-4,stone:6)
Block(-5,14,-3,stone:6)
Block(-5,14,-2,stone:6)
Block(-5,14,-1,cobblestone)
Block(-5,15,-4,stone:6)
Block(-5,15,-3,stone:6)
Block(-5,15,-2,stone:6)
Block(-5,15,-1,stonebrick:3)
Block(-5,16,-4,stone:6)
Block(-5,16,-3,stone:6)
Block(-5,16,-2,stone:6)
Block(-5,16,-1,stone_STAIRS:0)
Block(-5,17,-4,stone:6)
Block(-5,17,-3,stone:6)
Block(-5,17,-2,stonebrick:3)
Block(-5,18,-4,stone:6)
Block(-5,18,-3,stone:6)
Block(-5,18,-2,cobblestone)
Block(-5,19,-4,stone:6)
Block(-5,19,-3,stone:6)
Block(-5,19,-2,stonebrick:3)
Block(-5,20,-4,stone:6)
Block(-5,20,-3,stone:6)
Block(-5,20,-2,stone_STAIRS:0)
Block(-5,21,-8,stone:6)
Block(-5,21,-7,stone:6)
Block(-5,21,-6,stone:6)
Block(-5,21,-5,stone:6)
Block(-5,21,-4,stone:6)
Block(-5,21,-3,stonebrick:3)
Block(-5,22,-8,cobblestone)
Block(-5,22,-7,cobblestone)
Block(-5,22,-6,cobblestone)
Block(-5,22,-5,cobblestone)
Block(-5,22,-4,stone:6)
Block(-5,22,-3,cobblestone)
Block(-5,23,-8,cobblestone)
Block(-5,23,-7,cobblestone)
Block(-5,23,-6,cobblestone)
Block(-5,23,-5,cobblestone)
Block(-5,23,-4,stone:6)
Block(-5,23,-3,stonebrick:3)
Block(-5,24,-8,cobblestone)
Block(-5,24,-7,cobblestone)
Block(-5,24,-6,cobblestone)
Block(-5,24,-5,cobblestone)
Block(-5,24,-4,stone:6)
Block(-5,24,-3,stone_STAIRS:0)
Block(-5,25,-8,cobblestone)
Block(-5,25,-7,cobblestone)
Block(-5,25,-6,cobblestone)
Block(-5,25,-5,cobblestone)
Block(-5,25,-4,cobblestone)
Block(-5,26,-8,stone:6)
Block(-5,26,-7,stone:6)
Block(-5,26,-6,stone:6)
Block(-5,26,-5,stone:6)
Block(-5,26,-4,stone:6)
Block(-5,27,-8,cobblestone)
Block(-5,27,-7,cobblestone)
Block(-5,27,-6,cobblestone)
Block(-5,27,-5,cobblestone)
Block(-5,27,-4,cobblestone)
Block(-5,28,-8,stained_glass_pane)
Block(-5,28,-7,stained_glass_pane)
Block(-5,28,-6,cobblestone)
Block(-5,28,-5,cobblestone)
Block(-5,28,-4,stone:6)
Block(-5,29,-8,wooden_slab:5)
Block(-5,29,-7,wooden_slab:5)
Block(-5,29,-6,cobblestone)
Block(-5,29,-5,stone_STAIRS:0)
Block(-5,29,-4,dark_oak_fence)
Block(-5,30,-6,cobblestone)
Block(-5,30,-5,stone_stairs:7)
Block(-5,31,-6,stonebrick)
Block(-5,31,-5,stonebrick)
Block(-5,32,-6,stonebrick)
Block(-5,32,-5,stonebrick)
Block(-5,33,-7,stone_brick_stairs:6)
Block(-5,33,-4,stone_brick_stairs:7)
Block(-5,34,-7,stone_slab:3)
Block(-5,34,-4,stone_slab:3)
Block(-5,35,-8,dark_oak_STAIRS:0)
Block(-4,1,-8,cobblestone)
Block(-4,1,-7,cobblestone)
Block(-4,1,-6,cobblestone)
Block(-4,1,-5,cobblestone)
Block(-4,1,-4,cobblestone)
Block(-4,1,0,cobblestone)
Block(-4,2,-4,cobblestone)
Block(-4,2,0,cobblestone)
Block(-4,3,-4,cobblestone)
Block(-4,3,0,cobblestone)
Block(-4,4,-4,cobblestone)
Block(-4,4,0,cobblestone)
Block(-4,5,-4,cobblestone)
Block(-4,5,0,cobblestone)
Block(-4,6,-4,cobblestone)
Block(-4,6,0,cobblestone)
Block(-4,7,-4,cobblestone)
Block(-4,7,0,cobblestone)
Block(-4,8,-4,cobblestone)
Block(-4,8,0,cobblestone)
Block(-4,9,-4,cobblestone)
Block(-4,9,0,cobblestone)
Block(-4,10,-4,cobblestone)
Block(-4,10,0,cobblestone)
Block(-4,11,-4,cobblestone)
Block(-4,11,-3,cobblestone)
Block(-4,11,-2,cobblestone)
Block(-4,11,-1,cobblestone)
Block(-4,11,0,cobblestone)
Block(-4,12,-4,cobblestone)
Block(-4,12,-3,cobblestone)
Block(-4,12,-2,cobblestone)
Block(-4,12,-1,cobblestone)
Block(-4,12,0,stone_STAIRS:0)
Block(-4,13,-4,stone:6)
Block(-4,13,-3,stone:6)
Block(-4,13,-2,stone:6)
Block(-4,13,-1,stone:6)
Block(-4,14,-4,stone:6)
Block(-4,14,-3,stone:6)
Block(-4,14,-2,stone:6)
Block(-4,14,-1,stone:6)
Block(-4,15,-4,stone:6)
Block(-4,15,-3,stone:6)
Block(-4,15,-2,stone:6)
Block(-4,15,-1,stone:6)
Block(-4,16,-4,stone:6)
Block(-4,16,-3,stone:6)
Block(-4,16,-2,stone:6)
Block(-4,16,-1,stone_STAIRS:0)
Block(-4,17,-4,stone:6)
Block(-4,17,-3,stone:6)
Block(-4,17,-2,stone:6)
Block(-4,18,-4,stone:6)
Block(-4,18,-3,stone:6)
Block(-4,18,-2,stone:6)
Block(-4,19,-4,stone:6)
Block(-4,19,-3,stone:6)
Block(-4,19,-2,stone:6)
Block(-4,20,-4,stone:6)
Block(-4,20,-3,stone:6)
Block(-4,20,-2,stone_STAIRS:0)
Block(-4,21,-8,stone:6)
Block(-4,21,-7,stone:6)
Block(-4,21,-6,stone:6)
Block(-4,21,-5,stone:6)
Block(-4,21,-4,stone:6)
Block(-4,21,-3,stone:6)
Block(-4,22,-8,cobblestone)
Block(-4,22,-7,cobblestone)
Block(-4,22,-6,cobblestone)
Block(-4,22,-5,cobblestone)
Block(-4,22,-4,stone:6)
Block(-4,22,-3,stone:6)
Block(-4,23,-8,cobblestone)
Block(-4,23,-7,cobblestone)
Block(-4,23,-6,cobblestone)
Block(-4,23,-5,cobblestone)
Block(-4,23,-4,stone:6)
Block(-4,23,-3,stone:6)
Block(-4,24,-8,cobblestone)
Block(-4,24,-7,cobblestone)
Block(-4,24,-6,cobblestone)
Block(-4,24,-5,cobblestone)
Block(-4,24,-4,stone:6)
Block(-4,24,-3,stone_STAIRS:0)
Block(-4,25,-8,planks)
Block(-4,25,-7,planks)
Block(-4,25,-6,cobblestone)
Block(-4,25,-5,cobblestone)
Block(-4,25,-4,stone:6)
Block(-4,26,-6,stone:6)
Block(-4,26,-5,stone:6)
Block(-4,26,-4,stone:6)
Block(-4,27,-6,cobblestone)
Block(-4,27,-5,cobblestone)
Block(-4,27,-4,cobblestone)
Block(-4,28,-6,cobblestone)
Block(-4,28,-5,cobblestone)
Block(-4,28,-4,stone:6)
Block(-4,29,-8,wooden_slab:13)
Block(-4,29,-7,wooden_slab:13)
Block(-4,29,-6,cobblestone)
Block(-4,29,-5,stone_stairs:0)
Block(-4,29,-4,dark_oak_fence)
Block(-4,30,-6,cobblestone)
Block(-4,30,-5,stone_stairs:7)
Block(-4,31,-6,stonebrick)
Block(-4,31,-5,stonebrick)
Block(-4,32,-7,dark_oak_stairs:4)
Block(-4,32,-6,stonebrick)
Block(-4,32,-5,stonebrick)
Block(-4,32,-4,dark_oak_stairs:4)
Block(-4,33,-7,dark_oak_stairs:1)
Block(-4,33,-4,dark_oak_stairs:1)
Block(-4,35,-8,dark_oak_STAIRS:0)
Block(-3,1,-8,cobblestone)
Block(-3,1,-7,cobblestone)
Block(-3,1,-6,cobblestone)
Block(-3,1,-5,cobblestone)
Block(-3,1,-4,cobblestone)
Block(-3,1,-3,log)
Block(-3,1,0,log)
Block(-3,2,-4,cobblestone)
Block(-3,2,-3,log)
Block(-3,2,0,log)
Block(-3,3,-4,cobblestone)
Block(-3,3,-3,log)
Block(-3,3,0,log)
Block(-3,4,-4,cobblestone)
Block(-3,4,-3,log)
Block(-3,4,0,log)
Block(-3,5,-4,cobblestone)
Block(-3,5,-3,log)
Block(-3,5,0,log)
Block(-3,6,-4,cobblestone)
Block(-3,6,-3,log)
Block(-3,6,0,log)
Block(-3,7,-4,cobblestone)
Block(-3,7,-3,log)
Block(-3,7,0,log)
Block(-3,8,-4,cobblestone)
Block(-3,8,-3,log)
Block(-3,8,0,log)
Block(-3,9,-4,cobblestone)
Block(-3,9,-3,log)
Block(-3,9,0,log)
Block(-3,10,-4,cobblestone)
Block(-3,10,-3,log)
Block(-3,10,0,log)
Block(-3,11,-4,cobblestone)
Block(-3,11,-3,log)
Block(-3,11,-2,cobblestone)
Block(-3,11,-1,cobblestone)
Block(-3,11,0,log)
Block(-3,12,-4,cobblestone)
Block(-3,12,-3,log)
Block(-3,12,-2,log:8)
Block(-3,12,-1,log:8)
Block(-3,12,0,stone_brick_STAIRS:0)
Block(-3,13,-4,stone:6)
Block(-3,13,-3,log)
Block(-3,13,-1,log)
Block(-3,14,-4,stone:6)
Block(-3,14,-3,log)
Block(-3,14,-1,log)
Block(-3,15,-4,stone:6)
Block(-3,15,-3,log)
Block(-3,15,-1,log)
Block(-3,16,-4,stone:6)
Block(-3,16,-3,log)
Block(-3,16,-1,log)
Block(-3,17,-4,stone:6)
Block(-3,17,-3,log)
Block(-3,17,-2,log:8)
Block(-3,17,-1,stone_STAIRS:0)
Block(-3,18,-4,stone:6)
Block(-3,18,-3,log)
Block(-3,19,-4,stone:6)
Block(-3,19,-3,log)
Block(-3,20,-4,stone:6)
Block(-3,20,-3,log)
Block(-3,21,-8,stone:6)
Block(-3,21,-7,stone:6)
Block(-3,21,-6,stone:6)
Block(-3,21,-5,stone:6)
Block(-3,21,-4,stone:6)
Block(-3,21,-3,log)
Block(-3,22,-8,cobblestone)
Block(-3,22,-7,cobblestone)
Block(-3,22,-6,cobblestone)
Block(-3,22,-5,cobblestone)
Block(-3,22,-4,stone:6)
Block(-3,22,-3,log)
Block(-3,23,-8,cobblestone)
Block(-3,23,-7,cobblestone)
Block(-3,23,-6,cobblestone)
Block(-3,23,-5,cobblestone)
Block(-3,23,-4,stone:6)
Block(-3,23,-3,log)
Block(-3,24,-8,cobblestone)
Block(-3,24,-7,cobblestone)
Block(-3,24,-6,cobblestone)
Block(-3,24,-5,cobblestone)
Block(-3,24,-4,stone:6)
Block(-3,24,-3,log)
Block(-3,25,-8,dark_oak_stairs:1)
Block(-3,25,-7,dark_oak_stairs:5)
Block(-3,25,-6,log)
Block(-3,25,-5,cobblestone)
Block(-3,25,-4,stone:6)
Block(-3,25,-3,log)
Block(-3,26,-7,dark_oak_stairs:0)
Block(-3,26,-6,log)
Block(-3,26,-5,stone:6)
Block(-3,26,-4,stone:6)
Block(-3,26,-3,stone_brick_STAIRS:0)
Block(-3,27,-6,log)
Block(-3,27,-5,cobblestone)
Block(-3,27,-4,log)
Block(-3,28,-6,log)
Block(-3,28,-5,cobblestone)
Block(-3,28,-4,log)
Block(-3,29,-6,log)
Block(-3,29,-5,log:8)
Block(-3,29,-4,stone_brick_STAIRS:0)
Block(-3,30,-8,wooden_slab:5)
Block(-3,30,-7,wooden_slab:5)
Block(-3,30,-6,log)
Block(-3,30,-5,stone_stairs:7)
Block(-3,31,-6,stone:6)
Block(-3,31,-5,stone:6)
Block(-3,32,-7,dark_oak_stairs:6)
Block(-3,32,-6,stonebrick)
Block(-3,32,-5,stone:6)
Block(-3,32,-4,dark_oak_stairs:7)
Block(-3,33,-7,stonebrick)
Block(-3,33,-4,stonebrick)
Block(-3,34,-7,wooden_slab:5)
Block(-3,34,-4,wooden_slab:5)
Block(-3,35,-8,dark_oak_STAIRS:0)
Block(-2,1,-8,cobblestone)
Block(-2,1,-7,cobblestone)
Block(-2,1,-6,cobblestone)
Block(-2,1,-5,cobblestone)
Block(-2,1,-4,cobblestone)
Block(-2,1,0,cobblestone)
Block(-2,2,-4,cobblestone)
Block(-2,2,0,cobblestone)
Block(-2,3,-4,cobblestone)
Block(-2,3,0,cobblestone)
Block(-2,4,-4,cobblestone)
Block(-2,4,0,cobblestone)
Block(-2,5,-4,cobblestone)
Block(-2,5,0,cobblestone)
Block(-2,6,-4,cobblestone)
Block(-2,6,0,cobblestone)
Block(-2,7,-4,cobblestone)
Block(-2,7,0,cobblestone)
Block(-2,8,-4,cobblestone)
Block(-2,8,0,cobblestone)
Block(-2,9,-4,cobblestone)
Block(-2,9,0,cobblestone)
Block(-2,10,-4,cobblestone)
Block(-2,10,0,cobblestone)
Block(-2,11,-4,cobblestone)
Block(-2,11,-3,cobblestone)
Block(-2,11,-2,cobblestone)
Block(-2,11,-1,cobblestone)
Block(-2,11,0,cobblestone)
Block(-2,12,-4,cobblestone)
Block(-2,12,-3,cobblestone)
Block(-2,12,-2,cobblestone)
Block(-2,12,-1,cobblestone)
Block(-2,12,0,stone_STAIRS:0)
Block(-2,13,-4,stone:6)
Block(-2,13,-3,stone:6)
Block(-2,13,-2,stone:6)
Block(-2,13,-1,stone:6)
Block(-2,14,-4,stone:6)
Block(-2,14,-3,stone:6)
Block(-2,14,-2,stone:6)
Block(-2,14,-1,stone:6)
Block(-2,15,-4,stone:6)
Block(-2,15,-3,stone:6)
Block(-2,15,-2,stone:6)
Block(-2,15,-1,stone:6)
Block(-2,16,-4,stone:6)
Block(-2,16,-3,stone:6)
Block(-2,16,-2,stone:6)
Block(-2,16,-1,stone_STAIRS:0)
Block(-2,17,-4,stone:6)
Block(-2,17,-3,stone:6)
Block(-2,17,-2,stone:6)
Block(-2,18,-4,stone:6)
Block(-2,18,-3,stone:6)
Block(-2,18,-2,stone:6)
Block(-2,19,-4,stone:6)
Block(-2,19,-3,stone:6)
Block(-2,19,-2,stone:6)
Block(-2,20,-4,stone:6)
Block(-2,20,-3,stone:6)
Block(-2,20,-2,stone_STAIRS:0)
Block(-2,21,-8,stone:6)
Block(-2,21,-7,stone:6)
Block(-2,21,-6,stone:6)
Block(-2,21,-5,stone:6)
Block(-2,21,-4,stone:6)
Block(-2,21,-3,stone:6)
Block(-2,22,-8,cobblestone)
Block(-2,22,-7,cobblestone)
Block(-2,22,-6,cobblestone)
Block(-2,22,-5,cobblestone)
Block(-2,22,-4,stone:6)
Block(-2,22,-3,stone:6)
Block(-2,23,-8,cobblestone)
Block(-2,23,-7,cobblestone)
Block(-2,23,-6,cobblestone)
Block(-2,23,-5,cobblestone)
Block(-2,23,-4,stone:6)
Block(-2,23,-3,stone:6)
Block(-2,24,-8,cobblestone)
Block(-2,24,-7,cobblestone)
Block(-2,24,-6,cobblestone)
Block(-2,24,-5,cobblestone)
Block(-2,24,-4,stone:6)
Block(-2,24,-3,stone_STAIRS:0)
Block(-2,25,-6,cobblestone)
Block(-2,25,-5,cobblestone)
Block(-2,25,-4,stone:6)
Block(-2,26,-7,dark_oak_stairs:5)
Block(-2,26,-6,stone:6)
Block(-2,26,-5,stone:6)
Block(-2,26,-4,stone:6)
Block(-2,27,-7,dark_oak_stairs:0)
Block(-2,27,-6,cobblestone)
Block(-2,27,-5,cobblestone)
Block(-2,27,-4,cobblestone)
Block(-2,28,-6,cobblestone)
Block(-2,28,-5,cobblestone)
Block(-2,28,-4,stone:6)
Block(-2,29,-6,cobblestone)
Block(-2,29,-5,stone_stairs:1)
Block(-2,29,-4,dark_oak_fence)
Block(-2,30,-8,double_wooden_slab:5)
Block(-2,30,-7,double_wooden_slab:5)
Block(-2,30,-6,cobblestone)
Block(-2,30,-5,stone_stairs:7)
Block(-2,31,-6,stonebrick)
Block(-2,31,-5,stonebrick)
Block(-2,32,-7,dark_oak_stairs:5)
Block(-2,32,-6,stonebrick)
Block(-2,32,-5,stonebrick)
Block(-2,32,-4,dark_oak_stairs:5)
Block(-2,33,-7,dark_oak_stairs:0)
Block(-2,33,-4,dark_oak_stairs:0)
Block(-2,35,-8,dark_oak_STAIRS:0)
Block(-1,1,-8,cobblestone)
Block(-1,1,-7,cobblestone)
Block(-1,1,-6,cobblestone)
Block(-1,1,-5,cobblestone)
Block(-1,1,-4,cobblestone)
Block(-1,1,0,cobblestone)
Block(-1,2,-4,cobblestone)
Block(-1,2,0,cobblestone)
Block(-1,3,-4,cobblestone)
Block(-1,3,0,cobblestone)
Block(-1,4,-4,cobblestone)
Block(-1,4,0,cobblestone)
Block(-1,5,-4,cobblestone)
Block(-1,5,0,cobblestone)
Block(-1,6,-4,cobblestone)
Block(-1,6,0,cobblestone)
Block(-1,7,-4,cobblestone)
Block(-1,7,0,cobblestone)
Block(-1,8,-4,cobblestone)
Block(-1,8,0,cobblestone)
Block(-1,9,-4,cobblestone)
Block(-1,9,0,cobblestone)
Block(-1,10,-4,cobblestone)
Block(-1,10,0,cobblestone)
Block(-1,11,-4,cobblestone)
Block(-1,11,-3,cobblestone)
Block(-1,11,-2,cobblestone)
Block(-1,11,-1,cobblestone)
Block(-1,11,0,cobblestone)
Block(-1,12,-4,cobblestone)
Block(-1,12,-3,cobblestone)
Block(-1,12,-2,cobblestone)
Block(-1,12,-1,cobblestone)
Block(-1,12,0,stone_STAIRS:0)
Block(-1,13,-4,stone:6)
Block(-1,13,-3,stone:6)
Block(-1,13,-2,stone:6)
Block(-1,13,-1,stonebrick:3)
Block(-1,14,-4,stone:6)
Block(-1,14,-3,stone:6)
Block(-1,14,-2,stone:6)
Block(-1,14,-1,cobblestone)
Block(-1,15,-4,stone:6)
Block(-1,15,-3,stone:6)
Block(-1,15,-2,stone:6)
Block(-1,15,-1,stonebrick:3)
Block(-1,16,-4,stone:6)
Block(-1,16,-3,stone:6)
Block(-1,16,-2,stone:6)
Block(-1,16,-1,stone_STAIRS:0)
Block(-1,17,-4,stone:6)
Block(-1,17,-3,stone:6)
Block(-1,17,-2,stonebrick:3)
Block(-1,18,-4,stone:6)
Block(-1,18,-3,stone:6)
Block(-1,18,-2,cobblestone)
Block(-1,19,-4,stone:6)
Block(-1,19,-3,stone:6)
Block(-1,19,-2,stonebrick:3)
Block(-1,20,-4,stone:6)
Block(-1,20,-3,stone:6)
Block(-1,20,-2,stone_STAIRS:0)
Block(-1,21,-8,stone:6)
Block(-1,21,-7,stone:6)
Block(-1,21,-6,stone:6)
Block(-1,21,-5,stone:6)
Block(-1,21,-4,stone:6)
Block(-1,21,-3,stonebrick:3)
Block(-1,22,-8,cobblestone)
Block(-1,22,-7,cobblestone)
Block(-1,22,-6,cobblestone)
Block(-1,22,-5,cobblestone)
Block(-1,22,-4,stone:6)
Block(-1,22,-3,cobblestone)
Block(-1,23,-8,cobblestone)
Block(-1,23,-7,cobblestone)
Block(-1,23,-6,cobblestone)
Block(-1,23,-5,cobblestone)
Block(-1,23,-4,stone:6)
Block(-1,23,-3,stonebrick:3)
Block(-1,24,-8,cobblestone)
Block(-1,24,-7,cobblestone)
Block(-1,24,-6,cobblestone)
Block(-1,24,-5,cobblestone)
Block(-1,24,-4,stone:6)
Block(-1,24,-3,stone_STAIRS:0)
Block(-1,25,-8,wall_sign,StructureNBT/SapphireCity/sap69/1-Sign.nbt)
Block(-1,25,-7,dark_oak_stairs:1)
Block(-1,25,-6,cobblestone)
Block(-1,25,-5,cobblestone)
Block(-1,25,-4,cobblestone)
Block(-1,26,-6,stone:6)
Block(-1,26,-5,stone:6)
Block(-1,26,-4,stone:6)
Block(-1,27,-8,log:9)
Block(-1,27,-7,log:9)
Block(-1,27,-6,cobblestone)
Block(-1,27,-5,cobblestone)
Block(-1,27,-4,cobblestone)
Block(-1,28,-8,birch_door:2)
Block(-1,28,-7,birch_door:2)
Block(-1,28,-6,cobblestone)
Block(-1,28,-5,cobblestone)
Block(-1,28,-4,stone:6)
Block(-1,29,-8,birch_door:9)
Block(-1,29,-7,birch_door:8)
Block(-1,29,-6,cobblestone)
Block(-1,29,-5,stone_STAIRS:0)
Block(-1,29,-4,dark_oak_fence)
Block(-1,30,-8,double_wooden_slab:5)
Block(-1,30,-7,double_wooden_slab:5)
Block(-1,30,-6,cobblestone)
Block(-1,30,-5,stone_stairs:7)
Block(-1,31,-8,wooden_slab:5)
Block(-1,31,-7,wooden_slab:5)
Block(-1,31,-6,stonebrick)
Block(-1,31,-5,stonebrick)
Block(-1,32,-6,stonebrick)
Block(-1,32,-5,stonebrick)
Block(-1,33,-7,stone_brick_stairs:6)
Block(-1,33,-4,stone_brick_stairs:7)
Block(-1,34,-7,stone_slab:3)
Block(-1,34,-4,stone_slab:3)
Block(-1,35,-8,dark_oak_STAIRS:0)
Block(0,1,-8,cobblestone)
Block(0,1,-7,cobblestone)
Block(0,1,-6,cobblestone)
Block(0,1,-5,cobblestone)
Block(0,1,-4,cobblestone)
Block(0,1,0,cobblestone)
Block(0,2,-4,cobblestone)
Block(0,2,0,cobblestone)
Block(0,3,-4,cobblestone)
Block(0,3,0,cobblestone)
Block(0,4,-4,cobblestone)
Block(0,4,0,cobblestone)
Block(0,5,-4,cobblestone)
Block(0,5,0,cobblestone)
Block(0,6,-4,cobblestone)
Block(0,6,0,cobblestone)
Block(0,7,-4,cobblestone)
Block(0,7,0,cobblestone)
Block(0,8,-4,cobblestone)
Block(0,8,0,cobblestone)
Block(0,9,-4,cobblestone)
Block(0,9,0,cobblestone)
Block(0,10,-4,cobblestone)
Block(0,10,0,cobblestone)
Block(0,11,-4,cobblestone)
Block(0,11,-3,cobblestone)
Block(0,11,-2,cobblestone)
Block(0,11,-1,cobblestone)
Block(0,11,0,cobblestone)
Block(0,12,-4,cobblestone)
Block(0,12,-3,cobblestone)
Block(0,12,-2,cobblestone)
Block(0,12,-1,cobblestone)
Block(0,12,0,stone_STAIRS:0)
Block(0,13,-4,stone:6)
Block(0,13,-3,stone:6)
Block(0,13,-2,stone:6)
Block(0,13,-1,stone:6)
Block(0,14,-4,stone:6)
Block(0,14,-3,stone:6)
Block(0,14,-2,stone:6)
Block(0,14,-1,stone:6)
Block(0,15,-4,stone:6)
Block(0,15,-3,stone:6)
Block(0,15,-2,stone:6)
Block(0,15,-1,stone:6)
Block(0,16,-4,stone:6)
Block(0,16,-3,stone:6)
Block(0,16,-2,stone:6)
Block(0,16,-1,stone_STAIRS:0)
Block(0,17,-4,stone:6)
Block(0,17,-3,stone:6)
Block(0,17,-2,stone:6)
Block(0,18,-4,stone:6)
Block(0,18,-3,stone:6)
Block(0,18,-2,stone:6)
Block(0,19,-4,stone:6)
Block(0,19,-3,stone:6)
Block(0,19,-2,stone:6)
Block(0,20,-4,stone:6)
Block(0,20,-3,stone:6)
Block(0,20,-2,stone_STAIRS:0)
Block(0,21,-8,stone:6)
Block(0,21,-7,stone:6)
Block(0,21,-6,stone:6)
Block(0,21,-5,stone:6)
Block(0,21,-4,stone:6)
Block(0,21,-3,stone:6)
Block(0,22,-8,cobblestone)
Block(0,22,-7,cobblestone)
Block(0,22,-6,cobblestone)
Block(0,22,-5,cobblestone)
Block(0,22,-4,stone:6)
Block(0,22,-3,stone:6)
Block(0,23,-8,cobblestone)
Block(0,23,-7,cobblestone)
Block(0,23,-6,cobblestone)
Block(0,23,-5,cobblestone)
Block(0,23,-4,stone:6)
Block(0,23,-3,stone:6)
Block(0,24,-8,cobblestone)
Block(0,24,-7,cobblestone)
Block(0,24,-6,cobblestone)
Block(0,24,-5,cobblestone)
Block(0,24,-4,stone:6)
Block(0,24,-3,stone_STAIRS:0)
Block(0,25,-7,fence)
Block(0,25,-6,cobblestone)
Block(0,25,-5,cobblestone)
Block(0,25,-4,stone:6)
Block(0,26,-7,carpet)
Block(0,26,-6,stone:6)
Block(0,26,-5,stone:6)
Block(0,26,-4,stone:6)
Block(0,27,-8,wooden_slab:13)
Block(0,27,-7,wooden_slab:13)
Block(0,27,-6,cobblestone)
Block(0,27,-5,cobblestone)
Block(0,27,-4,cobblestone)
Block(0,28,-8,bed:3)
Block(0,28,-7,bed:3)
Block(0,28,-6,cobblestone)
Block(0,28,-5,cobblestone)
Block(0,28,-4,stone:6)
Block(0,29,-6,cobblestone)
Block(0,29,-5,stone_stairs:0)
Block(0,29,-4,dark_oak_fence)
Block(0,30,-6,cobblestone)
Block(0,30,-5,stone_stairs:7)
Block(0,31,-8,wooden_slab:5)
Block(0,31,-7,wooden_slab:5)
Block(0,31,-6,stonebrick)
Block(0,31,-5,stonebrick)
Block(0,32,-7,dark_oak_stairs:4)
Block(0,32,-6,stonebrick)
Block(0,32,-5,stonebrick)
Block(0,32,-4,dark_oak_stairs:4)
Block(0,33,-7,dark_oak_stairs:1)
Block(0,33,-4,dark_oak_stairs:1)
Block(0,35,-8,dark_oak_STAIRS:0)
Block(1,1,-8,cobblestone)
Block(1,1,-7,cobblestone)
Block(1,1,-6,cobblestone)
Block(1,1,-5,cobblestone)
Block(1,1,-4,cobblestone)
Block(1,1,-3,log)
Block(1,1,0,log)
Block(1,2,-4,cobblestone)
Block(1,2,-3,log)
Block(1,2,0,log)
Block(1,3,-4,cobblestone)
Block(1,3,-3,log)
Block(1,3,0,log)
Block(1,4,-4,cobblestone)
Block(1,4,-3,log)
Block(1,4,0,log)
Block(1,5,-4,cobblestone)
Block(1,5,-3,log)
Block(1,5,0,log)
Block(1,6,-4,cobblestone)
Block(1,6,-3,log)
Block(1,6,0,log)
Block(1,7,-4,cobblestone)
Block(1,7,-3,log)
Block(1,7,0,log)
Block(1,8,-4,cobblestone)
Block(1,8,-3,log)
Block(1,8,0,log)
Block(1,9,-4,cobblestone)
Block(1,9,-3,log)
Block(1,9,0,log)
Block(1,10,-4,cobblestone)
Block(1,10,-3,log)
Block(1,10,0,log)
Block(1,11,-4,cobblestone)
Block(1,11,-3,log)
Block(1,11,-2,cobblestone)
Block(1,11,-1,cobblestone)
Block(1,11,0,log)
Block(1,12,-4,cobblestone)
Block(1,12,-3,log)
Block(1,12,-2,log:8)
Block(1,12,-1,log:8)
Block(1,12,0,stone_brick_STAIRS:0)
Block(1,13,-4,stone:6)
Block(1,13,-3,log)
Block(1,13,-1,log)
Block(1,14,-4,stone:6)
Block(1,14,-3,log)
Block(1,14,-1,log)
Block(1,15,-4,stone:6)
Block(1,15,-3,log)
Block(1,15,-1,log)
Block(1,16,-4,stone:6)
Block(1,16,-3,log)
Block(1,16,-1,log)
Block(1,17,-4,stone:6)
Block(1,17,-3,log)
Block(1,17,-2,log:8)
Block(1,17,-1,stone_STAIRS:0)
Block(1,18,-4,stone:6)
Block(1,18,-3,log)
Block(1,19,-4,stone:6)
Block(1,19,-3,log)
Block(1,20,-4,stone:6)
Block(1,20,-3,log)
Block(1,21,-8,stone:6)
Block(1,21,-7,stone:6)
Block(1,21,-6,stone:6)
Block(1,21,-5,stone:6)
Block(1,21,-4,stone:6)
Block(1,21,-3,log)
Block(1,22,-8,cobblestone)
Block(1,22,-7,cobblestone)
Block(1,22,-6,cobblestone)
Block(1,22,-5,cobblestone)
Block(1,22,-4,stone:6)
Block(1,22,-3,log)
Block(1,23,-8,cobblestone)
Block(1,23,-7,cobblestone)
Block(1,23,-6,cobblestone)
Block(1,23,-5,cobblestone)
Block(1,23,-4,stone:6)
Block(1,23,-3,log)
Block(1,24,-8,cobblestone)
Block(1,24,-7,cobblestone)
Block(1,24,-6,cobblestone)
Block(1,24,-5,cobblestone)
Block(1,24,-4,stone:6)
Block(1,24,-3,log)
Block(1,25,-8,wall_sign,StructureNBT/SapphireCity/sap69/2-Sign.nbt)
Block(1,25,-7,dark_oak_stairs:0)
Block(1,25,-6,log)
Block(1,25,-5,cobblestone)
Block(1,25,-4,stone:6)
Block(1,25,-3,log)
Block(1,26,-6,log)
Block(1,26,-5,stone:6)
Block(1,26,-4,stone:6)
Block(1,26,-3,stone_brick_STAIRS:0)
Block(1,27,-8,wooden_slab:13)
Block(1,27,-7,wooden_slab:13)
Block(1,27,-6,log)
Block(1,27,-5,cobblestone)
Block(1,27,-4,log)
Block(1,28,-8,bed:11)
Block(1,28,-7,bed:11)
Block(1,28,-6,log)
Block(1,28,-5,cobblestone)
Block(1,28,-4,log)
Block(1,29,-6,log)
Block(1,29,-5,log:8)
Block(1,29,-4,stone_brick_STAIRS:0)
Block(1,30,-6,log)
Block(1,30,-5,stone_stairs:7)
Block(1,31,-8,wooden_slab:5)
Block(1,31,-7,wooden_slab:5)
Block(1,31,-6,stone:6)
Block(1,31,-5,stone:6)
Block(1,32,-7,dark_oak_stairs:6)
Block(1,32,-6,stonebrick)
Block(1,32,-5,stone:6)
Block(1,32,-4,dark_oak_stairs:7)
Block(1,33,-7,stonebrick)
Block(1,33,-4,stonebrick)
Block(1,34,-7,wooden_slab:5)
Block(1,34,-4,wooden_slab:5)
Block(1,35,-8,dark_oak_STAIRS:0)
Block(2,1,-8,cobblestone)
Block(2,1,-7,cobblestone)
Block(2,1,-6,cobblestone)
Block(2,1,-5,cobblestone)
Block(2,1,-4,cobblestone)
Block(2,1,0,cobblestone)
Block(2,2,-4,cobblestone)
Block(2,2,0,cobblestone)
Block(2,3,-4,cobblestone)
Block(2,3,0,cobblestone)
Block(2,4,-4,cobblestone)
Block(2,4,0,cobblestone)
Block(2,5,-4,cobblestone)
Block(2,5,0,cobblestone)
Block(2,6,-4,cobblestone)
Block(2,6,0,cobblestone)
Block(2,7,-4,cobblestone)
Block(2,7,0,cobblestone)
Block(2,8,-4,cobblestone)
Block(2,8,0,cobblestone)
Block(2,9,-4,cobblestone)
Block(2,9,0,cobblestone)
Block(2,10,-4,cobblestone)
Block(2,10,0,cobblestone)
Block(2,11,-4,cobblestone)
Block(2,11,-3,cobblestone)
Block(2,11,-2,cobblestone)
Block(2,11,-1,cobblestone)
Block(2,11,0,cobblestone)
Block(2,12,-4,cobblestone)
Block(2,12,-3,cobblestone)
Block(2,12,-2,cobblestone)
Block(2,12,-1,cobblestone)
Block(2,12,0,stone_STAIRS:0)
Block(2,13,-4,stone:6)
Block(2,13,-3,stone:6)
Block(2,13,-2,stone:6)
Block(2,13,-1,stone:6)
Block(2,14,-4,stone:6)
Block(2,14,-3,stone:6)
Block(2,14,-2,stone:6)
Block(2,14,-1,stone:6)
Block(2,15,-4,stone:6)
Block(2,15,-3,stone:6)
Block(2,15,-2,stone:6)
Block(2,15,-1,stone:6)
Block(2,16,-4,stone:6)
Block(2,16,-3,stone:6)
Block(2,16,-2,stone:6)
Block(2,16,-1,stone_STAIRS:0)
Block(2,17,-4,stone:6)
Block(2,17,-3,stone:6)
Block(2,17,-2,stone:6)
Block(2,18,-4,stone:6)
Block(2,18,-3,stone:6)
Block(2,18,-2,stone:6)
Block(2,19,-4,stone:6)
Block(2,19,-3,stone:6)
Block(2,19,-2,stone:6)
Block(2,20,-4,stone:6)
Block(2,20,-3,stone:6)
Block(2,20,-2,stone_STAIRS:0)
Block(2,21,-8,stone:6)
Block(2,21,-7,stone:6)
Block(2,21,-6,stone:6)
Block(2,21,-5,stone:6)
Block(2,21,-4,stone:6)
Block(2,21,-3,stone:6)
Block(2,22,-8,cobblestone)
Block(2,22,-7,cobblestone)
Block(2,22,-6,cobblestone)
Block(2,22,-5,cobblestone)
Block(2,22,-4,stone:6)
Block(2,22,-3,stone:6)
Block(2,23,-8,cobblestone)
Block(2,23,-7,cobblestone)
Block(2,23,-6,cobblestone)
Block(2,23,-5,cobblestone)
Block(2,23,-4,stone:6)
Block(2,23,-3,stone:6)
Block(2,24,-8,cobblestone)
Block(2,24,-7,cobblestone)
Block(2,24,-6,cobblestone)
Block(2,24,-5,cobblestone)
Block(2,24,-4,stone:6)
Block(2,24,-3,stone_STAIRS:0)
Block(2,25,-8,cobblestone)
Block(2,25,-7,cobblestone)
Block(2,25,-6,cobblestone)
Block(2,25,-5,cobblestone)
Block(2,25,-4,stone:6)
Block(2,26,-8,stone:6)
Block(2,26,-7,stone:6)
Block(2,26,-6,stone:6)
Block(2,26,-5,stone:6)
Block(2,26,-4,stone:6)
Block(2,27,-8,wool)
Block(2,27,-7,wool)
Block(2,27,-6,cobblestone)
Block(2,27,-5,cobblestone)
Block(2,27,-4,cobblestone)
Block(2,28,-8,wool)
Block(2,28,-7,wool)
Block(2,28,-6,cobblestone)
Block(2,28,-5,cobblestone)
Block(2,28,-4,stone:6)
Block(2,29,-8,wool)
Block(2,29,-7,wool)
Block(2,29,-6,cobblestone)
Block(2,29,-5,stone_stairs:1)
Block(2,29,-4,dark_oak_fence)
Block(2,30,-8,wool)
Block(2,30,-7,wool)
Block(2,30,-6,cobblestone)
Block(2,30,-5,stone_stairs:7)
Block(2,31,-8,wooden_slab:5)
Block(2,31,-7,wooden_slab:5)
Block(2,31,-6,stonebrick)
Block(2,31,-5,stonebrick)
Block(2,32,-7,dark_oak_stairs:5)
Block(2,32,-6,stonebrick)
Block(2,32,-5,stonebrick)
Block(2,32,-4,dark_oak_stairs:5)
Block(2,33,-7,dark_oak_stairs:0)
Block(2,33,-4,dark_oak_stairs:0)
Block(2,35,-8,dark_oak_STAIRS:0)
Block(3,1,-8,cobblestone)
Block(3,1,-7,cobblestone)
Block(3,1,-6,cobblestone)
Block(3,1,-5,cobblestone)
Block(3,1,-4,cobblestone)
Block(3,1,0,cobblestone)
Block(3,2,-4,cobblestone)
Block(3,2,0,cobblestone)
Block(3,3,-4,cobblestone)
Block(3,3,0,cobblestone)
Block(3,4,-4,cobblestone)
Block(3,4,0,cobblestone)
Block(3,5,-4,cobblestone)
Block(3,5,0,cobblestone)
Block(3,6,-4,cobblestone)
Block(3,6,0,cobblestone)
Block(3,7,-4,cobblestone)
Block(3,7,0,cobblestone)
Block(3,8,-4,cobblestone)
Block(3,8,0,cobblestone)
Block(3,9,-4,cobblestone)
Block(3,9,0,cobblestone)
Block(3,10,-4,cobblestone)
Block(3,10,0,cobblestone)
Block(3,11,-4,cobblestone)
Block(3,11,-3,cobblestone)
Block(3,11,-2,cobblestone)
Block(3,11,-1,cobblestone)
Block(3,11,0,cobblestone)
Block(3,12,-4,cobblestone)
Block(3,12,-3,cobblestone)
Block(3,12,-2,cobblestone)
Block(3,12,-1,cobblestone)
Block(3,12,0,stone_STAIRS:0)
Block(3,13,-4,stone:6)
Block(3,13,-3,stone:6)
Block(3,13,-2,stone:6)
Block(3,13,-1,stonebrick:3)
Block(3,14,-4,stone:6)
Block(3,14,-3,stone:6)
Block(3,14,-2,stone:6)
Block(3,14,-1,cobblestone)
Block(3,15,-4,stone:6)
Block(3,15,-3,stone:6)
Block(3,15,-2,stone:6)
Block(3,15,-1,stonebrick:3)
Block(3,16,-4,stone:6)
Block(3,16,-3,stone:6)
Block(3,16,-2,stone:6)
Block(3,16,-1,stone_STAIRS:0)
Block(3,17,-4,stone:6)
Block(3,17,-3,stone:6)
Block(3,17,-2,stonebrick:3)
Block(3,18,-4,stone:6)
Block(3,18,-3,stone:6)
Block(3,18,-2,cobblestone)
Block(3,19,-4,stone:6)
Block(3,19,-3,stone:6)
Block(3,19,-2,stonebrick:3)
Block(3,20,-4,stone:6)
Block(3,20,-3,stone:6)
Block(3,20,-2,stone_STAIRS:0)
Block(3,21,-8,stone:6)
Block(3,21,-7,stone:6)
Block(3,21,-6,stone:6)
Block(3,21,-5,stone:6)
Block(3,21,-4,stone:6)
Block(3,21,-3,stonebrick:3)
Block(3,22,-8,cobblestone)
Block(3,22,-7,cobblestone)
Block(3,22,-6,cobblestone)
Block(3,22,-5,cobblestone)
Block(3,22,-4,stone:6)
Block(3,22,-3,cobblestone)
Block(3,23,-8,cobblestone)
Block(3,23,-7,cobblestone)
Block(3,23,-6,cobblestone)
Block(3,23,-5,cobblestone)
Block(3,23,-4,stone:6)
Block(3,23,-3,stonebrick:3)
Block(3,24,-8,cobblestone)
Block(3,24,-7,cobblestone)
Block(3,24,-6,cobblestone)
Block(3,24,-5,cobblestone)
Block(3,24,-4,stone:6)
Block(3,24,-3,stone_STAIRS:0)
Block(3,25,-8,cobblestone)
Block(3,25,-7,cobblestone)
Block(3,25,-6,cobblestone)
Block(3,25,-5,cobblestone)
Block(3,25,-4,cobblestone)
Block(3,26,-8,planks)
Block(3,26,-7,planks)
Block(3,26,-6,stone:6)
Block(3,26,-5,stone:6)
Block(3,26,-4,stone:6)
Block(3,27,-8,bookshelf)
Block(3,27,-7,bookshelf)
Block(3,27,-6,cobblestone)
Block(3,27,-5,cobblestone)
Block(3,27,-4,cobblestone)
Block(3,28,-8,bookshelf)
Block(3,28,-7,bookshelf)
Block(3,28,-6,cobblestone)
Block(3,28,-5,cobblestone)
Block(3,28,-4,stone:6)
Block(3,29,-6,cobblestone)
Block(3,29,-5,stone_STAIRS:0)
Block(3,29,-4,dark_oak_fence)
Block(3,30,-8,wooden_slab:13)
Block(3,30,-7,wooden_slab:13)
Block(3,30,-6,cobblestone)
Block(3,30,-5,stone_stairs:7)
Block(3,31,-8,wooden_slab:5)
Block(3,31,-7,wooden_slab:5)
Block(3,31,-6,stonebrick)
Block(3,31,-5,stonebrick)
Block(3,32,-6,stonebrick)
Block(3,32,-5,stonebrick)
Block(3,33,-7,stone_brick_stairs:6)
Block(3,33,-4,stone_brick_stairs:7)
Block(3,34,-7,stone_slab:3)
Block(3,34,-4,stone_slab:3)
Block(3,35,-8,dark_oak_STAIRS:0)
Block(4,1,-8,cobblestone)
Block(4,1,-7,cobblestone)
Block(4,1,-6,cobblestone)
Block(4,1,-5,cobblestone)
Block(4,1,-4,cobblestone)
Block(4,1,0,cobblestone)
Block(4,2,-4,cobblestone)
Block(4,2,0,cobblestone)
Block(4,3,-4,cobblestone)
Block(4,3,0,cobblestone)
Block(4,4,-4,cobblestone)
Block(4,4,0,cobblestone)
Block(4,5,-4,cobblestone)
Block(4,5,0,cobblestone)
Block(4,6,-4,cobblestone)
Block(4,6,0,cobblestone)
Block(4,7,-4,cobblestone)
Block(4,7,0,cobblestone)
Block(4,8,-4,cobblestone)
Block(4,8,0,cobblestone)
Block(4,9,-4,cobblestone)
Block(4,9,0,cobblestone)
Block(4,10,-4,cobblestone)
Block(4,10,0,cobblestone)
Block(4,11,-4,cobblestone)
Block(4,11,-3,cobblestone)
Block(4,11,-2,cobblestone)
Block(4,11,-1,cobblestone)
Block(4,11,0,cobblestone)
Block(4,12,-4,cobblestone)
Block(4,12,-3,cobblestone)
Block(4,12,-2,cobblestone)
Block(4,12,-1,cobblestone)
Block(4,12,0,stone_STAIRS:0)
Block(4,13,-4,stone:6)
Block(4,13,-3,stone:6)
Block(4,13,-2,stone:6)
Block(4,13,-1,stone:6)
Block(4,14,-4,stone:6)
Block(4,14,-3,stone:6)
Block(4,14,-2,stone:6)
Block(4,14,-1,stone:6)
Block(4,15,-4,stone:6)
Block(4,15,-3,stone:6)
Block(4,15,-2,stone:6)
Block(4,15,-1,stone:6)
Block(4,16,-4,stone:6)
Block(4,16,-3,stone:6)
Block(4,16,-2,stone:6)
Block(4,16,-1,stone_STAIRS:0)
Block(4,17,-4,stone:6)
Block(4,17,-3,stone:6)
Block(4,17,-2,stone:6)
Block(4,18,-4,stone:6)
Block(4,18,-3,stone:6)
Block(4,18,-2,stone:6)
Block(4,19,-4,stone:6)
Block(4,19,-3,stone:6)
Block(4,19,-2,stone:6)
Block(4,20,-4,stone:6)
Block(4,20,-3,stone:6)
Block(4,20,-2,stone_STAIRS:0)
Block(4,21,-8,stone:6)
Block(4,21,-7,stone:6)
Block(4,21,-6,stone:6)
Block(4,21,-5,stone:6)
Block(4,21,-4,stone:6)
Block(4,21,-3,stone:6)
Block(4,22,-8,cobblestone)
Block(4,22,-7,cobblestone)
Block(4,22,-6,cobblestone)
Block(4,22,-5,cobblestone)
Block(4,22,-4,stone:6)
Block(4,22,-3,stone:6)
Block(4,23,-8,cobblestone)
Block(4,23,-7,cobblestone)
Block(4,23,-6,cobblestone)
Block(4,23,-5,cobblestone)
Block(4,23,-4,stone:6)
Block(4,23,-3,stone:6)
Block(4,24,-8,cobblestone)
Block(4,24,-7,cobblestone)
Block(4,24,-6,cobblestone)
Block(4,24,-5,cobblestone)
Block(4,24,-4,stone:6)
Block(4,24,-3,stone_STAIRS:0)
Block(4,25,-8,cobblestone)
Block(4,25,-7,cobblestone)
Block(4,25,-6,cobblestone)
Block(4,25,-5,cobblestone)
Block(4,25,-4,stone:6)
Block(4,26,-8,planks)
Block(4,26,-7,planks)
Block(4,26,-6,stone:6)
Block(4,26,-5,stone:6)
Block(4,26,-4,stone:6)
Block(4,27,-6,cobblestone)
Block(4,27,-5,cobblestone)
Block(4,27,-4,cobblestone)
Block(4,28,-6,cobblestone)
Block(4,28,-5,cobblestone)
Block(4,28,-4,stone:6)
Block(4,29,-6,cobblestone)
Block(4,29,-5,stone_stairs:0)
Block(4,29,-4,dark_oak_fence)
Block(4,30,-8,wooden_slab:13)
Block(4,30,-7,wooden_slab:13)
Block(4,30,-6,cobblestone)
Block(4,30,-5,stone_stairs:7)
Block(4,31,-6,stonebrick)
Block(4,31,-5,stonebrick)
Block(4,32,-7,dark_oak_stairs:4)
Block(4,32,-6,stonebrick)
Block(4,32,-5,stonebrick)
Block(4,32,-4,dark_oak_stairs:4)
Block(4,33,-7,dark_oak_stairs:1)
Block(4,33,-4,dark_oak_stairs:1)
Block(4,35,-8,dark_oak_STAIRS:0)
Block(5,1,-8,cobblestone)
Block(5,1,-7,cobblestone)
Block(5,1,-6,cobblestone)
Block(5,1,-5,cobblestone)
Block(5,1,-4,cobblestone)
Block(5,1,-3,log)
Block(5,1,0,log)
Block(5,2,-4,cobblestone)
Block(5,2,-3,log)
Block(5,2,0,log)
Block(5,3,-4,cobblestone)
Block(5,3,-3,log)
Block(5,3,0,log)
Block(5,4,-4,cobblestone)
Block(5,4,-3,log)
Block(5,4,0,log)
Block(5,5,-4,cobblestone)
Block(5,5,-3,log)
Block(5,5,0,log)
Block(5,6,-4,cobblestone)
Block(5,6,-3,log)
Block(5,6,0,log)
Block(5,7,-4,cobblestone)
Block(5,7,-3,log)
Block(5,7,0,log)
Block(5,8,-4,cobblestone)
Block(5,8,-3,log)
Block(5,8,0,log)
Block(5,9,-4,cobblestone)
Block(5,9,-3,log)
Block(5,9,0,log)
Block(5,10,-4,cobblestone)
Block(5,10,-3,log)
Block(5,10,0,log)
Block(5,11,-4,cobblestone)
Block(5,11,-3,log)
Block(5,11,-2,cobblestone)
Block(5,11,-1,cobblestone)
Block(5,11,0,log)
Block(5,12,-4,cobblestone)
Block(5,12,-3,log)
Block(5,12,-2,log:8)
Block(5,12,-1,log:8)
Block(5,12,0,stone_brick_STAIRS:0)
Block(5,13,-4,stone:6)
Block(5,13,-3,log)
Block(5,13,-1,log)
Block(5,14,-4,stone:6)
Block(5,14,-3,log)
Block(5,14,-1,log)
Block(5,15,-4,stone:6)
Block(5,15,-3,log)
Block(5,15,-1,log)
Block(5,16,-4,stone:6)
Block(5,16,-3,log)
Block(5,16,-1,log)
Block(5,17,-4,stone:6)
Block(5,17,-3,log)
Block(5,17,-2,log:8)
Block(5,17,-1,stone_STAIRS:0)
Block(5,18,-4,stone:6)
Block(5,18,-3,log)
Block(5,19,-4,stone:6)
Block(5,19,-3,log)
Block(5,20,-4,stone:6)
Block(5,20,-3,log)
Block(5,21,-8,stone:6)
Block(5,21,-7,stone:6)
Block(5,21,-6,stone:6)
Block(5,21,-5,stone:6)
Block(5,21,-4,stone:6)
Block(5,21,-3,log)
Block(5,22,-8,cobblestone)
Block(5,22,-7,cobblestone)
Block(5,22,-6,cobblestone)
Block(5,22,-5,cobblestone)
Block(5,22,-4,stone:6)
Block(5,22,-3,log)
Block(5,23,-8,cobblestone)
Block(5,23,-7,cobblestone)
Block(5,23,-6,cobblestone)
Block(5,23,-5,cobblestone)
Block(5,23,-4,stone:6)
Block(5,23,-3,log)
Block(5,24,-8,cobblestone)
Block(5,24,-7,cobblestone)
Block(5,24,-6,cobblestone)
Block(5,24,-5,cobblestone)
Block(5,24,-4,stone:6)
Block(5,24,-3,log)
Block(5,25,-8,cobblestone)
Block(5,25,-7,cobblestone)
Block(5,25,-6,cobblestone)
Block(5,25,-5,cobblestone)
Block(5,25,-4,stone:6)
Block(5,25,-3,log)
Block(5,26,-8,planks)
Block(5,26,-7,planks)
Block(5,26,-6,log)
Block(5,26,-5,stone:6)
Block(5,26,-4,stone:6)
Block(5,26,-3,stone_brick_STAIRS:0)
Block(5,27,-8,wooden_slab:13)
Block(5,27,-7,wooden_slab:13)
Block(5,27,-6,log)
Block(5,27,-5,cobblestone)
Block(5,27,-4,log)
Block(5,28,-7,torch)
Block(5,28,-6,log)
Block(5,28,-5,cobblestone)
Block(5,28,-4,log)
Block(5,29,-6,log)
Block(5,29,-5,log:8)
Block(5,29,-4,stone_brick_STAIRS:0)
Block(5,30,-8,wooden_slab:13)
Block(5,30,-7,wooden_slab:13)
Block(5,30,-6,log)
Block(5,30,-5,stone_stairs:7)
Block(5,31,-6,stone:6)
Block(5,31,-5,stone:6)
Block(5,32,-7,dark_oak_stairs:6)
Block(5,32,-6,stonebrick)
Block(5,32,-5,stone:6)
Block(5,32,-4,dark_oak_stairs:7)
Block(5,33,-7,stonebrick)
Block(5,33,-4,stonebrick)
Block(5,34,-7,wooden_slab:5)
Block(5,34,-4,wooden_slab:5)
Block(5,35,-8,dark_oak_STAIRS:0)
Block(6,1,-8,cobblestone)
Block(6,1,-7,cobblestone)
Block(6,1,-6,cobblestone)
Block(6,1,-5,cobblestone)
Block(6,1,-4,cobblestone)
Block(6,1,0,cobblestone)
Block(6,2,-4,cobblestone)
Block(6,2,0,cobblestone)
Block(6,3,-4,cobblestone)
Block(6,3,0,cobblestone)
Block(6,4,-4,cobblestone)
Block(6,4,0,cobblestone)
Block(6,5,-4,cobblestone)
Block(6,5,0,cobblestone)
Block(6,6,-4,cobblestone)
Block(6,6,0,cobblestone)
Block(6,7,-4,cobblestone)
Block(6,7,0,cobblestone)
Block(6,8,-4,cobblestone)
Block(6,8,0,cobblestone)
Block(6,9,-4,cobblestone)
Block(6,9,0,cobblestone)
Block(6,10,-4,cobblestone)
Block(6,10,0,cobblestone)
Block(6,11,-4,cobblestone)
Block(6,11,-3,cobblestone)
Block(6,11,-2,cobblestone)
Block(6,11,-1,cobblestone)
Block(6,11,0,cobblestone)
Block(6,12,-4,cobblestone)
Block(6,12,-3,cobblestone)
Block(6,12,-2,cobblestone)
Block(6,12,-1,cobblestone)
Block(6,12,0,stone_STAIRS:0)
Block(6,13,-4,stone:6)
Block(6,13,-3,stone:6)
Block(6,13,-2,stone:6)
Block(6,13,-1,stone:6)
Block(6,14,-4,stone:6)
Block(6,14,-3,stone:6)
Block(6,14,-2,stone:6)
Block(6,14,-1,stone:6)
Block(6,15,-4,stone:6)
Block(6,15,-3,stone:6)
Block(6,15,-2,stone:6)
Block(6,15,-1,stone:6)
Block(6,16,-4,stone:6)
Block(6,16,-3,stone:6)
Block(6,16,-2,stone:6)
Block(6,16,-1,stone_STAIRS:0)
Block(6,17,-4,stone:6)
Block(6,17,-3,stone:6)
Block(6,17,-2,stone:6)
Block(6,18,-4,stone:6)
Block(6,18,-3,stone:6)
Block(6,18,-2,stone:6)
Block(6,19,-4,stone:6)
Block(6,19,-3,stone:6)
Block(6,19,-2,stone:6)
Block(6,20,-4,stone:6)
Block(6,20,-3,stone:6)
Block(6,20,-2,stone_STAIRS:0)
Block(6,21,-8,stone:6)
Block(6,21,-7,stone:6)
Block(6,21,-6,stone:6)
Block(6,21,-5,stone:6)
Block(6,21,-4,stone:6)
Block(6,21,-3,stone:6)
Block(6,22,-8,cobblestone)
Block(6,22,-7,cobblestone)
Block(6,22,-6,cobblestone)
Block(6,22,-5,cobblestone)
Block(6,22,-4,stone:6)
Block(6,22,-3,stone:6)
Block(6,23,-8,cobblestone)
Block(6,23,-7,cobblestone)
Block(6,23,-6,cobblestone)
Block(6,23,-5,cobblestone)
Block(6,23,-4,stone:6)
Block(6,23,-3,stone:6)
Block(6,24,-8,cobblestone)
Block(6,24,-7,cobblestone)
Block(6,24,-6,cobblestone)
Block(6,24,-5,cobblestone)
Block(6,24,-4,stone:6)
Block(6,24,-3,stone_STAIRS:0)
Block(6,25,-8,cobblestone)
Block(6,25,-7,cobblestone)
Block(6,25,-6,cobblestone)
Block(6,25,-5,cobblestone)
Block(6,25,-4,stone:6)
Block(6,26,-8,planks)
Block(6,26,-7,planks)
Block(6,26,-6,stone:6)
Block(6,26,-5,stone:6)
Block(6,26,-4,stone:6)
Block(6,27,-6,cobblestone)
Block(6,27,-5,cobblestone)
Block(6,27,-4,cobblestone)
Block(6,28,-6,cobblestone)
Block(6,28,-5,cobblestone)
Block(6,28,-4,stone:6)
Block(6,29,-6,cobblestone)
Block(6,29,-5,stone_stairs:1)
Block(6,29,-4,dark_oak_fence)
Block(6,30,-8,dark_oak_stairs:4)
Block(6,30,-7,dark_oak_stairs:4)
Block(6,30,-6,cobblestone)
Block(6,30,-5,stone_stairs:7)
Block(6,31,-6,stonebrick)
Block(6,31,-5,stonebrick)
Block(6,32,-7,dark_oak_stairs:5)
Block(6,32,-6,stonebrick)
Block(6,32,-5,stonebrick)
Block(6,32,-4,dark_oak_stairs:5)
Block(6,33,-7,dark_oak_stairs:0)
Block(6,33,-4,dark_oak_stairs:0)
Block(6,35,-8,dark_oak_STAIRS:0)
Block(7,1,-8,cobblestone)
Block(7,1,-7,cobblestone)
Block(7,1,-6,cobblestone)
Block(7,1,-5,cobblestone)
Block(7,1,-4,cobblestone)
Block(7,1,0,cobblestone)
Block(7,2,-4,cobblestone)
Block(7,2,0,cobblestone)
Block(7,3,-4,cobblestone)
Block(7,3,0,cobblestone)
Block(7,4,-4,cobblestone)
Block(7,4,0,cobblestone)
Block(7,5,-4,cobblestone)
Block(7,5,0,cobblestone)
Block(7,6,-4,cobblestone)
Block(7,6,0,cobblestone)
Block(7,7,-4,cobblestone)
Block(7,7,0,cobblestone)
Block(7,8,-4,cobblestone)
Block(7,8,0,cobblestone)
Block(7,9,-4,cobblestone)
Block(7,9,0,cobblestone)
Block(7,10,-4,cobblestone)
Block(7,10,0,cobblestone)
Block(7,11,-4,cobblestone)
Block(7,11,-3,cobblestone)
Block(7,11,-2,cobblestone)
Block(7,11,-1,cobblestone)
Block(7,11,0,cobblestone)
Block(7,12,-4,cobblestone)
Block(7,12,-3,cobblestone)
Block(7,12,-2,cobblestone)
Block(7,12,-1,cobblestone)
Block(7,12,0,stone_STAIRS:0)
Block(7,13,-4,stone:6)
Block(7,13,-3,stone:6)
Block(7,13,-2,stone:6)
Block(7,13,-1,stonebrick:3)
Block(7,14,-4,stone:6)
Block(7,14,-3,stone:6)
Block(7,14,-2,stone:6)
Block(7,14,-1,cobblestone)
Block(7,15,-4,stone:6)
Block(7,15,-3,stone:6)
Block(7,15,-2,stone:6)
Block(7,15,-1,stonebrick:3)
Block(7,16,-4,stone:6)
Block(7,16,-3,stone:6)
Block(7,16,-2,stone:6)
Block(7,16,-1,stone_STAIRS:0)
Block(7,17,-4,stone:6)
Block(7,17,-3,stone:6)
Block(7,17,-2,stonebrick:3)
Block(7,18,-4,stone:6)
Block(7,18,-3,stone:6)
Block(7,18,-2,cobblestone)
Block(7,19,-4,stone:6)
Block(7,19,-3,stone:6)
Block(7,19,-2,stonebrick:3)
Block(7,20,-4,stone:6)
Block(7,20,-3,stone:6)
Block(7,20,-2,stone_STAIRS:0)
Block(7,21,-8,stone:6)
Block(7,21,-7,stone:6)
Block(7,21,-6,stone:6)
Block(7,21,-5,stone:6)
Block(7,21,-4,stone:6)
Block(7,21,-3,stonebrick:3)
Block(7,22,-8,cobblestone)
Block(7,22,-7,cobblestone)
Block(7,22,-6,cobblestone)
Block(7,22,-5,cobblestone)
Block(7,22,-4,stone:6)
Block(7,22,-3,cobblestone)
Block(7,23,-8,cobblestone)
Block(7,23,-7,cobblestone)
Block(7,23,-6,cobblestone)
Block(7,23,-5,cobblestone)
Block(7,23,-4,stone:6)
Block(7,23,-3,stonebrick:3)
Block(7,24,-8,cobblestone)
Block(7,24,-7,cobblestone)
Block(7,24,-6,cobblestone)
Block(7,24,-5,cobblestone)
Block(7,24,-4,stone:6)
Block(7,24,-3,stone_STAIRS:0)
Block(7,25,-8,cobblestone)
Block(7,25,-7,cobblestone)
Block(7,25,-6,cobblestone)
Block(7,25,-5,cobblestone)
Block(7,25,-4,cobblestone)
Block(7,26,-8,stone:6)
Block(7,26,-7,stone:6)
Block(7,26,-6,stone:6)
Block(7,26,-5,stone:6)
Block(7,26,-4,stone:6)
Block(7,27,-8,cobblestone)
Block(7,27,-7,cobblestone)
Block(7,27,-6,cobblestone)
Block(7,27,-5,cobblestone)
Block(7,27,-4,cobblestone)
Block(7,28,-8,stained_glass_pane)
Block(7,28,-7,stained_glass_pane)
Block(7,28,-6,cobblestone)
Block(7,28,-5,cobblestone)
Block(7,28,-4,stone:6)
Block(7,29,-8,log:9)
Block(7,29,-7,log:9)
Block(7,29,-6,cobblestone)
Block(7,29,-5,stone_STAIRS:0)
Block(7,29,-4,dark_oak_fence)
Block(7,30,-8,dark_oak_stairs:1)
Block(7,30,-7,dark_oak_stairs:1)
Block(7,30,-6,cobblestone)
Block(7,30,-5,stone_stairs:7)
Block(7,31,-6,stonebrick)
Block(7,31,-5,stonebrick)
Block(7,32,-6,stonebrick)
Block(7,32,-5,stonebrick)
Block(7,33,-7,stone_brick_stairs:6)
Block(7,33,-4,stone_brick_stairs:7)
Block(7,34,-7,stone_slab:3)
Block(7,34,-4,stone_slab:3)
Block(7,35,-8,dark_oak_STAIRS:0)

#######################################################################
# +-----------------------------------------------------------------+ #
# |                            BO3 checks                           | #
# +-----------------------------------------------------------------+ #
#######################################################################


#######################################################################
# +-----------------------------------------------------------------+ #
# |                             Branches                            | #
# +-----------------------------------------------------------------+ #
#######################################################################

