
#######################################################################
# +-----------------------------------------------------------------+ #
# |                            BO3 object                           | #
# +-----------------------------------------------------------------+ #
#######################################################################

Author: NLBlackEagle

Description: No description given

Version: 3

SettingsMode: WriteDisable


#######################################################################
# +-----------------------------------------------------------------+ #
# |                          Main settings                          | #
# +-----------------------------------------------------------------+ #
#######################################################################

Tree: false

Frequency: 1

Rarity: 25.0

RotateRandomly: false

SpawnHeight: randomY

SpawnHeightOffset: 0

SpawnHeightVariance: 0

##############################
# Height Limits for the BO3. #
##############################

MinHeight: 47

MaxHeight: 47

######################
# Extrusion settings #
######################

ExtrudeMode: None

ExtrudeThroughBlocks: air

MaxBranchDepth: 60

ExcludedBiomes: All


#######################################################################
# +-----------------------------------------------------------------+ #
# |                      Source block settings                      | #
# +-----------------------------------------------------------------+ #
#######################################################################

SourceBlocks: air

MaxPercentageOutsideSourceBlock: 100

OutsideSourceBlock: placeAnyway


#######################################################################
# +-----------------------------------------------------------------+ #
# |                              Blocks                             | #
# +-----------------------------------------------------------------+ #
#######################################################################

Block(-8,1,-2,cobblestone)
Block(-8,1,7,cobblestone)
Block(-8,2,-2,cobblestone)
Block(-8,2,7,cobblestone)
Block(-8,3,-2,cobblestone)
Block(-8,3,7,cobblestone)
Block(-8,4,-2,cobblestone)
Block(-8,4,7,cobblestone)
Block(-8,5,-2,cobblestone)
Block(-8,5,7,cobblestone)
Block(-8,6,-2,cobblestone)
Block(-8,6,7,cobblestone)
Block(-8,7,-2,cobblestone)
Block(-8,7,7,cobblestone)
Block(-8,8,-2,cobblestone)
Block(-8,8,7,cobblestone)
Block(-8,9,-2,cobblestone)
Block(-8,9,7,cobblestone)
Block(-8,10,-2,cobblestone)
Block(-8,10,7,cobblestone)
Block(-8,11,-2,cobblestone)
Block(-8,11,-1,cobblestone)
Block(-8,11,0,cobblestone)
Block(-8,11,1,cobblestone)
Block(-8,11,2,cobblestone)
Block(-8,11,3,cobblestone)
Block(-8,11,4,cobblestone)
Block(-8,11,5,cobblestone)
Block(-8,11,6,cobblestone)
Block(-8,11,7,cobblestone)
Block(-8,12,-2,stone_stairs:2)
Block(-8,12,-1,stone_stairs:1)
Block(-8,12,0,stone:6)
Block(-8,12,1,log:4)
Block(-8,12,2,stone:6)
Block(-8,12,3,stone:6)
Block(-8,12,4,log:4)
Block(-8,12,5,stone:6)
Block(-8,12,6,log:4)
Block(-8,12,7,cobblestone)
Block(-8,13,0,stone:6)
Block(-8,13,2,stone:6)
Block(-8,13,3,stone:6)
Block(-8,13,5,stone:6)
Block(-8,13,7,stone:6)
Block(-8,14,0,stone:6)
Block(-8,14,2,stone:6)
Block(-8,14,3,stone:6)
Block(-8,14,5,stone:6)
Block(-8,14,7,stone:6)
Block(-8,15,0,stone:6)
Block(-8,15,2,stone:6)
Block(-8,15,3,stone:6)
Block(-8,15,5,stone:6)
Block(-8,15,7,stone:6)
Block(-8,16,0,stone_stairs:1)
Block(-8,16,2,stone:6)
Block(-8,16,3,stone:6)
Block(-8,16,5,stone:6)
Block(-8,16,7,stone:6)
Block(-8,17,1,log:4)
Block(-8,17,2,stone:6)
Block(-8,17,3,stone:6)
Block(-8,17,4,log:4)
Block(-8,17,6,log:4)
Block(-8,17,7,stone:6)
Block(-8,18,2,stone:6)
Block(-8,18,3,stone:6)
Block(-8,18,7,stone:6)
Block(-8,19,2,stone:6)
Block(-8,19,3,stone:6)
Block(-8,19,7,stone:6)
Block(-8,20,2,stone_stairs:1)
Block(-8,20,3,stone_stairs:1)
Block(-8,20,7,stone:6)
Block(-8,21,7,stone:6)
Block(-8,22,7,stone:6)
Block(-8,23,7,stone:6)
Block(-8,24,7,stone:6)
Block(-8,25,7,stone:6)
Block(-8,26,6,stone_brick_stairs:6)
Block(-8,26,7,stone:6)
Block(-8,27,6,stone:6)
Block(-8,27,7,stonebrick)
Block(-8,28,1,stone_brick_stairs:5)
Block(-8,28,4,stone_brick_stairs:5)
Block(-8,28,6,wooden_slab:5)
Block(-8,29,1,cobblestone_wall)
Block(-8,29,4,cobblestone_wall)
Block(-8,30,0,wooden_slab:5)
Block(-8,30,1,double_wooden_slab:5)
Block(-8,30,2,double_wooden_slab:5)
Block(-8,30,3,double_wooden_slab:5)
Block(-8,30,4,double_wooden_slab:5)
Block(-8,30,5,wooden_slab:5)
Block(-8,30,6,double_wooden_slab:5)
Block(-8,31,7,wooden_slab:5)
Block(-8,40,0,stone_brick_stairs:6)
Block(-8,40,1,stone_brick_stairs:5)
Block(-8,40,2,stone_slab:11)
Block(-8,40,3,stone_slab:11)
Block(-8,40,4,stone_brick_stairs:5)
Block(-8,40,5,stone_brick_stairs:7)
Block(-8,41,0,stone_brick_STAIRS:0)
Block(-8,41,1,double_wooden_slab:5)
Block(-8,41,2,stone_brick_stairs:2)
Block(-8,41,3,stone_brick_STAIRS:0)
Block(-8,41,4,double_wooden_slab:5)
Block(-8,41,5,stone_brick_stairs:2)
Block(-7,1,-1,log)
Block(-7,1,0,cobblestone)
Block(-7,2,-1,log)
Block(-7,2,0,cobblestone)
Block(-7,3,-1,log)
Block(-7,3,0,cobblestone)
Block(-7,4,-1,log)
Block(-7,4,0,cobblestone)
Block(-7,5,-1,log)
Block(-7,5,0,cobblestone)
Block(-7,6,-1,log)
Block(-7,6,0,cobblestone)
Block(-7,7,-1,log)
Block(-7,7,0,cobblestone)
Block(-7,8,-1,log)
Block(-7,8,0,cobblestone)
Block(-7,9,-1,log)
Block(-7,9,0,cobblestone)
Block(-7,10,-1,log)
Block(-7,10,0,cobblestone)
Block(-7,11,-1,log)
Block(-7,11,0,cobblestone)
Block(-7,11,1,cobblestone)
Block(-7,11,2,cobblestone)
Block(-7,11,3,cobblestone)
Block(-7,11,4,cobblestone)
Block(-7,11,5,cobblestone)
Block(-7,11,6,cobblestone)
Block(-7,11,7,cobblestone)
Block(-7,12,-1,stone_brick_stairs:2)
Block(-7,12,0,stone_stairs:1)
Block(-7,12,1,log)
Block(-7,12,2,stone:6)
Block(-7,12,3,stone:6)
Block(-7,12,4,log:4)
Block(-7,12,5,stone:6)
Block(-7,12,6,log:4)
Block(-7,12,7,stone:6)
Block(-7,13,1,log)
Block(-7,13,2,stone:6)
Block(-7,13,3,stone:6)
Block(-7,13,4,log)
Block(-7,13,5,stone:6)
Block(-7,13,6,log)
Block(-7,13,7,stone:6)
Block(-7,14,1,log)
Block(-7,14,2,stone:6)
Block(-7,14,3,stone:6)
Block(-7,14,4,log)
Block(-7,14,5,stone:6)
Block(-7,14,6,log)
Block(-7,14,7,stone:6)
Block(-7,15,1,log)
Block(-7,15,2,stone:6)
Block(-7,15,3,stone:6)
Block(-7,15,4,log)
Block(-7,15,5,stone:6)
Block(-7,15,6,log)
Block(-7,15,7,stone:6)
Block(-7,16,1,log)
Block(-7,16,2,stone_stairs:1)
Block(-7,16,3,stone_stairs:1)
Block(-7,16,4,log)
Block(-7,16,5,stone_stairs:1)
Block(-7,16,6,log)
Block(-7,16,7,stone:6)
Block(-7,17,1,stone_stairs:1)
Block(-7,17,4,stone_stairs:1)
Block(-7,17,6,stone_stairs:1)
Block(-7,26,7,stone_brick_stairs:5)
Block(-7,27,7,stone:6)
Block(-7,28,7,wooden_slab:5)
Block(-7,30,1,wooden_slab:5)
Block(-7,30,2,wooden_slab:5)
Block(-7,30,3,wooden_slab:5)
Block(-7,30,4,wooden_slab:5)
Block(-7,30,6,wooden_slab:5)
Block(-7,30,7,double_wooden_slab:5)
Block(-6,1,1,log)
Block(-6,1,2,cobblestone)
Block(-6,1,3,cobblestone)
Block(-6,1,4,log)
Block(-6,1,5,cobblestone)
Block(-6,2,1,log)
Block(-6,2,2,cobblestone)
Block(-6,2,3,cobblestone)
Block(-6,2,4,log)
Block(-6,2,5,cobblestone)
Block(-6,3,1,log)
Block(-6,3,2,cobblestone)
Block(-6,3,3,cobblestone)
Block(-6,3,4,log)
Block(-6,3,5,cobblestone)
Block(-6,4,1,log)
Block(-6,4,2,cobblestone)
Block(-6,4,3,cobblestone)
Block(-6,4,4,log)
Block(-6,4,5,cobblestone)
Block(-6,5,1,log)
Block(-6,5,2,cobblestone)
Block(-6,5,3,cobblestone)
Block(-6,5,4,log)
Block(-6,5,5,cobblestone)
Block(-6,6,1,log)
Block(-6,6,2,cobblestone)
Block(-6,6,3,cobblestone)
Block(-6,6,4,log)
Block(-6,6,5,cobblestone)
Block(-6,7,1,log)
Block(-6,7,2,cobblestone)
Block(-6,7,3,cobblestone)
Block(-6,7,4,log)
Block(-6,7,5,cobblestone)
Block(-6,8,1,log)
Block(-6,8,2,cobblestone)
Block(-6,8,3,cobblestone)
Block(-6,8,4,log)
Block(-6,8,5,cobblestone)
Block(-6,9,1,log)
Block(-6,9,2,cobblestone)
Block(-6,9,3,cobblestone)
Block(-6,9,4,log)
Block(-6,9,5,cobblestone)
Block(-6,10,1,log)
Block(-6,10,2,cobblestone)
Block(-6,10,3,cobblestone)
Block(-6,10,4,log)
Block(-6,10,5,cobblestone)
Block(-6,11,1,log)
Block(-6,11,2,cobblestone)
Block(-6,11,3,cobblestone)
Block(-6,11,4,log)
Block(-6,11,5,cobblestone)
Block(-6,11,6,cobblestone)
Block(-6,11,7,cobblestone)
Block(-6,12,1,stone_brick_stairs:1)
Block(-6,12,2,stone_stairs:1)
Block(-6,12,3,stone_stairs:1)
Block(-6,12,4,stone_brick_stairs:1)
Block(-6,12,5,stone_stairs:1)
Block(-6,12,6,stone_stairs:2)
Block(-6,12,7,stone:6)
Block(-6,13,7,stone:6)
Block(-6,14,7,stone:6)
Block(-6,15,7,stone:6)
Block(-6,16,7,stone_stairs:1)
Block(-6,30,7,wooden_slab:5)
Block(-5,1,6,log)
Block(-5,2,6,log)
Block(-5,3,6,log)
Block(-5,4,6,log)
Block(-5,5,6,log)
Block(-5,6,6,log)
Block(-5,7,6,log)
Block(-5,8,6,log)
Block(-5,9,6,log)
Block(-5,10,6,log)
Block(-5,11,6,log)
Block(-5,11,7,cobblestone)
Block(-5,12,6,stone_brick_stairs:1)
Block(-5,12,7,stone_stairs:2)
Block(-4,1,7,cobblestone)
Block(-4,2,7,cobblestone)
Block(-4,3,7,cobblestone)
Block(-4,4,7,cobblestone)
Block(-4,5,7,cobblestone)
Block(-4,6,7,cobblestone)
Block(-4,7,7,cobblestone)
Block(-4,8,7,cobblestone)
Block(-4,9,7,cobblestone)
Block(-4,10,7,cobblestone)
Block(-4,11,7,cobblestone)
Block(-4,12,7,stone_stairs:1)

#######################################################################
# +-----------------------------------------------------------------+ #
# |                            BO3 checks                           | #
# +-----------------------------------------------------------------+ #
#######################################################################


#######################################################################
# +-----------------------------------------------------------------+ #
# |                             Branches                            | #
# +-----------------------------------------------------------------+ #
#######################################################################

