
#######################################################################
# +-----------------------------------------------------------------+ #
# |                            BO3 object                           | #
# +-----------------------------------------------------------------+ #
#######################################################################

Author: NLBlackEagle

Description: No description given

Version: 3

SettingsMode: WriteDisable


#######################################################################
# +-----------------------------------------------------------------+ #
# |                          Main settings                          | #
# +-----------------------------------------------------------------+ #
#######################################################################

Tree: false

Frequency: 1

Rarity: 25.0

RotateRandomly: false

SpawnHeight: randomY

SpawnHeightOffset: 0

SpawnHeightVariance: 0

##############################
# Height Limits for the BO3. #
##############################

MinHeight: 47

MaxHeight: 47

######################
# Extrusion settings #
######################

ExtrudeMode: None

ExtrudeThroughBlocks: air

MaxBranchDepth: 60

ExcludedBiomes: All


#######################################################################
# +-----------------------------------------------------------------+ #
# |                      Source block settings                      | #
# +-----------------------------------------------------------------+ #
#######################################################################

SourceBlocks: air

MaxPercentageOutsideSourceBlock: 100

OutsideSourceBlock: placeAnyway


#######################################################################
# +-----------------------------------------------------------------+ #
# |                              Blocks                             | #
# +-----------------------------------------------------------------+ #
#######################################################################
RandomBlock(-2,30,-5,CHEST:5,./StructureNBT/StructureLoot/JunkChest_1.nbt,20,CHEST:5,./StructureNBT/StructureLoot/JunkChest_2.nbt,15,CHEST:5,./StructureNBT/StructureLoot/JunkChest_3.nbt,15,CHEST:5,./StructureNBT/StructureLoot/JunkChest_4.nbt,15,CHEST:5,./StructureNBT/StructureLoot/JunkChest_5.nbt,15,CHEST:5,./StructureNBT/LoreStoryline/LoreGeneric_5.nbt,2,CHEST:5,./StructureNBT/LoreStoryline/LoreGeneric_4.nbt,2,CHEST:5,./StructureNBT/LoreStoryline/LoreGeneric_3.nbt,2,CHEST:5,./StructureNBT/LoreStoryline/LoreGeneric_2.nbt,2,CHEST:5,./StructureNBT/LoreStoryline/LoreGeneric_1.nbt,2,CHEST:5,./StructureNBT/LoreStoryline/LoreMedievalCity_5.nbt,3,CHEST:5,./StructureNBT/LoreStoryline/LoreMedievalCity_4.nbt,3,CHEST:5,./StructureNBT/LoreStoryline/LoreMedievalCity_3.nbt,3,CHEST:5,./StructureNBT/LoreStoryline/LoreMedievalCity_2.nbt,3,CHEST:5,./StructureNBT/LoreStoryline/LoreMedievalCity_1.nbt,3,CHEST:5,./StructureNBT/StructureLoot/Common1.nbt,3,CHEST:5,./StructureNBT/StructureLoot/Common2.nbt,3,CHEST:5,./StructureNBT/StructureLoot/Common3.nbt,3,CHEST:5,./StructureNBT/StructureLoot/Common4.nbt,3,CHEST:5,./StructureNBT/StructureLoot/Common5.nbt,3,CHEST:5,./StructureNBT/StructureLoot/Common5.nbt,3,CHEST:5,./StructureNBT/StructureLoot/Common6.nbt,3,CHEST:5,./StructureNBT/StructureLoot/Common7.nbt,3,CHEST:5,./StructureNBT/StructureLoot/Common8.nbt,3,CHEST:5,./StructureNBT/StructureLoot/Common9.nbt,3,CHEST:5,./StructureNBT/StructureLoot/Common10.nbt,3,CHEST:5,./StructureNBT/StructureLoot/Common11.nbt,3,CHEST:5,./StructureNBT/StructureLoot/Common12.nbt,3,CHEST:5,./StructureNBT/StructureLoot/Common13.nbt,3,CHEST:5,./StructureNBT/StructureLoot/Common14.nbt,3,CHEST:5,./StructureNBT/StructureLoot/Common15.nbt,3,CHEST:5,./StructureNBT/StructureLoot/Rare1.nbt,3,CHEST:5,./StructureNBT/StructureLoot/Rare2.nbt,3,CHEST:5,./StructureNBT/StructureLoot/Rare3.nbt,3,CHEST:5,./StructureNBT/StructureLoot/Rare4.nbt,3,CHEST:5,./StructureNBT/StructureLoot/Rare5.nbt,3,CHEST:5,./StructureNBT/StructureLoot/Rare6.nbt,3,CHEST:5,./StructureNBT/StructureLoot/Rare7.nbt,3,CHEST:5,./StructureNBT/StructureLoot/Rare8.nbt,3,CHEST:5,./StructureNBT/StructureLoot/Rare9.nbt,3,CHEST:5,./StructureNBT/StructureLoot/Rare10.nbt,3,CHEST:5,./StructureNBT/StructureLoot/Rare11.nbt,3,CHEST:5,./StructureNBT/StructureLoot/Rare12.nbt,3,CHEST:5,./StructureNBT/StructureLoot/Rare13.nbt,3,CHEST:5,./StructureNBT/StructureLoot/Rare14.nbt,3,CHEST:5,./StructureNBT/StructureLoot/Rare15.nbt,3,CHEST:5,./StructureNBT/StructureLoot/Epic1.nbt,3,CHEST:5,./StructureNBT/StructureLoot/Epic2.nbt,3,CHEST:5,./StructureNBT/StructureLoot/Epic3.nbt,3,CHEST:5,./StructureNBT/StructureLoot/Epic4.nbt,3,CHEST:5,./StructureNBT/StructureLoot/Epic5.nbt,3,CHEST:5,./StructureNBT/StructureLoot/Epic6.nbt,3,CHEST:5,./StructureNBT/StructureLoot/Epic7.nbt,3,CHEST:5,./StructureNBT/StructureLoot/Epic8.nbt,3,CHEST:5,./StructureNBT/StructureLoot/Epic9.nbt,3,CHEST:5,./StructureNBT/StructureLoot/Epic10.nbt,3,CHEST:5,./StructureNBT/StructureLoot/Epic11.nbt,3,CHEST:5,./StructureNBT/StructureLoot/Epic12.nbt,3,CHEST:5,./StructureNBT/StructureLoot/Epic13.nbt,3,CHEST:5,./StructureNBT/StructureLoot/Epic14.nbt,3,CHEST:5,./StructureNBT/StructureLoot/Epic15.nbt,100)
RandomBlock(1,30,-2,CHEST,./StructureNBT/StructureLoot/JunkChest_1.nbt,20,CHEST,./StructureNBT/StructureLoot/JunkChest_2.nbt,15,CHEST,./StructureNBT/StructureLoot/JunkChest_3.nbt,15,CHEST,./StructureNBT/StructureLoot/JunkChest_4.nbt,15,CHEST,./StructureNBT/StructureLoot/JunkChest_5.nbt,15,CHEST,./StructureNBT/LoreStoryline/LoreGeneric_5.nbt,2,CHEST,./StructureNBT/LoreStoryline/LoreGeneric_4.nbt,2,CHEST,./StructureNBT/LoreStoryline/LoreGeneric_3.nbt,2,CHEST,./StructureNBT/LoreStoryline/LoreGeneric_2.nbt,2,CHEST,./StructureNBT/LoreStoryline/LoreGeneric_1.nbt,2,CHEST,./StructureNBT/LoreStoryline/LoreMedievalCity_5.nbt,3,CHEST,./StructureNBT/LoreStoryline/LoreMedievalCity_4.nbt,3,CHEST,./StructureNBT/LoreStoryline/LoreMedievalCity_3.nbt,3,CHEST,./StructureNBT/LoreStoryline/LoreMedievalCity_2.nbt,3,CHEST,./StructureNBT/LoreStoryline/LoreMedievalCity_1.nbt,3,CHEST,./StructureNBT/StructureLoot/Common1.nbt,3,CHEST,./StructureNBT/StructureLoot/Common2.nbt,3,CHEST,./StructureNBT/StructureLoot/Common3.nbt,3,CHEST,./StructureNBT/StructureLoot/Common4.nbt,3,CHEST,./StructureNBT/StructureLoot/Common5.nbt,3,CHEST,./StructureNBT/StructureLoot/Common5.nbt,3,CHEST,./StructureNBT/StructureLoot/Common6.nbt,3,CHEST,./StructureNBT/StructureLoot/Common7.nbt,3,CHEST,./StructureNBT/StructureLoot/Common8.nbt,3,CHEST,./StructureNBT/StructureLoot/Common9.nbt,3,CHEST,./StructureNBT/StructureLoot/Common10.nbt,3,CHEST,./StructureNBT/StructureLoot/Common11.nbt,3,CHEST,./StructureNBT/StructureLoot/Common12.nbt,3,CHEST,./StructureNBT/StructureLoot/Common13.nbt,3,CHEST,./StructureNBT/StructureLoot/Common14.nbt,3,CHEST,./StructureNBT/StructureLoot/Common15.nbt,3,CHEST,./StructureNBT/StructureLoot/Rare1.nbt,3,CHEST,./StructureNBT/StructureLoot/Rare2.nbt,3,CHEST,./StructureNBT/StructureLoot/Rare3.nbt,3,CHEST,./StructureNBT/StructureLoot/Rare4.nbt,3,CHEST,./StructureNBT/StructureLoot/Rare5.nbt,3,CHEST,./StructureNBT/StructureLoot/Rare6.nbt,3,CHEST,./StructureNBT/StructureLoot/Rare7.nbt,3,CHEST,./StructureNBT/StructureLoot/Rare8.nbt,3,CHEST,./StructureNBT/StructureLoot/Rare9.nbt,3,CHEST,./StructureNBT/StructureLoot/Rare10.nbt,3,CHEST,./StructureNBT/StructureLoot/Rare11.nbt,3,CHEST,./StructureNBT/StructureLoot/Rare12.nbt,3,CHEST,./StructureNBT/StructureLoot/Rare13.nbt,3,CHEST,./StructureNBT/StructureLoot/Rare14.nbt,3,CHEST,./StructureNBT/StructureLoot/Rare15.nbt,3,CHEST,./StructureNBT/StructureLoot/Epic1.nbt,3,CHEST,./StructureNBT/StructureLoot/Epic2.nbt,3,CHEST,./StructureNBT/StructureLoot/Epic3.nbt,3,CHEST,./StructureNBT/StructureLoot/Epic4.nbt,3,CHEST,./StructureNBT/StructureLoot/Epic5.nbt,3,CHEST,./StructureNBT/StructureLoot/Epic6.nbt,3,CHEST,./StructureNBT/StructureLoot/Epic7.nbt,3,CHEST,./StructureNBT/StructureLoot/Epic8.nbt,3,CHEST,./StructureNBT/StructureLoot/Epic9.nbt,3,CHEST,./StructureNBT/StructureLoot/Epic10.nbt,3,CHEST,./StructureNBT/StructureLoot/Epic11.nbt,3,CHEST,./StructureNBT/StructureLoot/Epic12.nbt,3,CHEST,./StructureNBT/StructureLoot/Epic13.nbt,3,CHEST,./StructureNBT/StructureLoot/Epic14.nbt,3,CHEST,./StructureNBT/StructureLoot/Epic15.nbt,100	)
RandomBlock(1,34,-5,CHEST:3,./StructureNBT/StructureLoot/JunkChest_1.nbt,20,CHEST:3,./StructureNBT/StructureLoot/JunkChest_2.nbt,15,CHEST:3,./StructureNBT/StructureLoot/JunkChest_3.nbt,15,CHEST:3,./StructureNBT/StructureLoot/JunkChest_4.nbt,15,CHEST:3,./StructureNBT/StructureLoot/JunkChest_5.nbt,15,CHEST:3,./StructureNBT/LoreStoryline/LoreGeneric_5.nbt,2,CHEST:3,./StructureNBT/LoreStoryline/LoreGeneric_4.nbt,2,CHEST:3,./StructureNBT/LoreStoryline/LoreGeneric_3.nbt,2,CHEST:3,./StructureNBT/LoreStoryline/LoreGeneric_2.nbt,2,CHEST:3,./StructureNBT/LoreStoryline/LoreGeneric_1.nbt,2,CHEST:3,./StructureNBT/LoreStoryline/LoreMedievalCity_5.nbt,3,CHEST:3,./StructureNBT/LoreStoryline/LoreMedievalCity_4.nbt,3,CHEST:3,./StructureNBT/LoreStoryline/LoreMedievalCity_3.nbt,3,CHEST:3,./StructureNBT/LoreStoryline/LoreMedievalCity_2.nbt,3,CHEST:3,./StructureNBT/LoreStoryline/LoreMedievalCity_1.nbt,3,CHEST:3,./StructureNBT/StructureLoot/Common1.nbt,3,CHEST:3,./StructureNBT/StructureLoot/Common2.nbt,3,CHEST:3,./StructureNBT/StructureLoot/Common3.nbt,3,CHEST:3,./StructureNBT/StructureLoot/Common4.nbt,3,CHEST:3,./StructureNBT/StructureLoot/Common5.nbt,3,CHEST:3,./StructureNBT/StructureLoot/Common5.nbt,3,CHEST:3,./StructureNBT/StructureLoot/Common6.nbt,3,CHEST:3,./StructureNBT/StructureLoot/Common7.nbt,3,CHEST:3,./StructureNBT/StructureLoot/Common8.nbt,3,CHEST:3,./StructureNBT/StructureLoot/Common9.nbt,3,CHEST:3,./StructureNBT/StructureLoot/Common10.nbt,3,CHEST:3,./StructureNBT/StructureLoot/Common11.nbt,3,CHEST:3,./StructureNBT/StructureLoot/Common12.nbt,3,CHEST:3,./StructureNBT/StructureLoot/Common13.nbt,3,CHEST:3,./StructureNBT/StructureLoot/Common14.nbt,3,CHEST:3,./StructureNBT/StructureLoot/Common15.nbt,3,CHEST:3,./StructureNBT/StructureLoot/Rare1.nbt,3,CHEST:3,./StructureNBT/StructureLoot/Rare2.nbt,3,CHEST:3,./StructureNBT/StructureLoot/Rare3.nbt,3,CHEST:3,./StructureNBT/StructureLoot/Rare4.nbt,3,CHEST:3,./StructureNBT/StructureLoot/Rare5.nbt,3,CHEST:3,./StructureNBT/StructureLoot/Rare6.nbt,3,CHEST:3,./StructureNBT/StructureLoot/Rare7.nbt,3,CHEST:3,./StructureNBT/StructureLoot/Rare8.nbt,3,CHEST:3,./StructureNBT/StructureLoot/Rare9.nbt,3,CHEST:3,./StructureNBT/StructureLoot/Rare10.nbt,3,CHEST:3,./StructureNBT/StructureLoot/Rare11.nbt,3,CHEST:3,./StructureNBT/StructureLoot/Rare12.nbt,3,CHEST:3,./StructureNBT/StructureLoot/Rare13.nbt,3,CHEST:3,./StructureNBT/StructureLoot/Rare14.nbt,3,CHEST:3,./StructureNBT/StructureLoot/Rare15.nbt,3,CHEST:3,./StructureNBT/StructureLoot/Epic1.nbt,3,CHEST:3,./StructureNBT/StructureLoot/Epic2.nbt,3,CHEST:3,./StructureNBT/StructureLoot/Epic3.nbt,3,CHEST:3,./StructureNBT/StructureLoot/Epic4.nbt,3,CHEST:3,./StructureNBT/StructureLoot/Epic5.nbt,3,CHEST:3,./StructureNBT/StructureLoot/Epic6.nbt,3,CHEST:3,./StructureNBT/StructureLoot/Epic7.nbt,3,CHEST:3,./StructureNBT/StructureLoot/Epic8.nbt,3,CHEST:3,./StructureNBT/StructureLoot/Epic9.nbt,3,CHEST:3,./StructureNBT/StructureLoot/Epic10.nbt,3,CHEST:3,./StructureNBT/StructureLoot/Epic11.nbt,3,CHEST:3,./StructureNBT/StructureLoot/Epic12.nbt,3,CHEST:3,./StructureNBT/StructureLoot/Epic13.nbt,3,CHEST:3,./StructureNBT/StructureLoot/Epic14.nbt,3,CHEST:3,./StructureNBT/StructureLoot/Epic15.nbt,100)

Block(-8,1,-8,cobblestone)
Block(-8,1,-7,cobblestone)
Block(-8,1,-6,cobblestone)
Block(-8,1,-5,cobblestone)
Block(-8,1,-4,cobblestone)
Block(-8,1,-3,cobblestone)
Block(-8,1,-2,cobblestone)
Block(-8,1,-1,cobblestone)
Block(-8,1,0,cobblestone)
Block(-8,1,1,cobblestone)
Block(-8,1,2,cobblestone)
Block(-8,1,3,cobblestone)
Block(-8,1,4,cobblestone)
Block(-8,2,4,cobblestone)
Block(-8,3,4,cobblestone)
Block(-8,4,4,cobblestone)
Block(-8,5,4,cobblestone)
Block(-8,6,4,cobblestone)
Block(-8,7,4,cobblestone)
Block(-8,8,4,cobblestone)
Block(-8,9,4,cobblestone)
Block(-8,10,4,cobblestone)
Block(-8,11,4,cobblestone)
Block(-8,11,5,cobblestone)
Block(-8,11,6,cobblestone)
Block(-8,11,7,cobblestone)
Block(-8,12,4,cobblestone)
Block(-8,12,5,stone:6)
Block(-8,12,6,log:4)
Block(-8,12,7,stone_stairs:1)
Block(-8,13,4,stone:6)
Block(-8,13,5,stone:6)
Block(-8,13,6,log)
Block(-8,14,4,stone:6)
Block(-8,14,5,stone:6)
Block(-8,14,6,log)
Block(-8,15,4,stone:6)
Block(-8,15,5,stone:6)
Block(-8,15,6,log)
Block(-8,16,4,stone:6)
Block(-8,16,5,stone_STAIRS:0)
Block(-8,16,6,log)
Block(-8,17,4,stone:6)
Block(-8,17,6,stone_stairs:1)
Block(-8,18,4,stone:6)
Block(-8,19,4,stone:6)
Block(-8,20,4,stone:6)
Block(-8,21,-8,stone:6)
Block(-8,21,-7,stone:6)
Block(-8,21,-6,stone:6)
Block(-8,21,-5,stone:6)
Block(-8,21,-4,stone:6)
Block(-8,21,-3,stone:6)
Block(-8,21,-2,stone:6)
Block(-8,21,-1,stone:6)
Block(-8,21,0,stone:6)
Block(-8,21,1,stone:6)
Block(-8,21,2,stone:6)
Block(-8,21,3,stone:6)
Block(-8,21,4,stone:6)
Block(-8,22,-8,cobblestone)
Block(-8,22,-7,cobblestone)
Block(-8,22,-6,cobblestone)
Block(-8,22,-5,cobblestone)
Block(-8,22,-4,cobblestone)
Block(-8,22,-3,cobblestone)
Block(-8,22,-2,cobblestone)
Block(-8,22,-1,cobblestone)
Block(-8,22,0,cobblestone)
Block(-8,22,1,cobblestone)
Block(-8,22,2,cobblestone)
Block(-8,22,3,cobblestone)
Block(-8,22,4,stone:6)
Block(-8,23,-8,cobblestone)
Block(-8,23,-7,cobblestone)
Block(-8,23,-6,cobblestone)
Block(-8,23,-5,cobblestone)
Block(-8,23,-4,cobblestone)
Block(-8,23,-3,cobblestone)
Block(-8,23,-2,cobblestone)
Block(-8,23,-1,cobblestone)
Block(-8,23,0,cobblestone)
Block(-8,23,1,cobblestone)
Block(-8,23,2,cobblestone)
Block(-8,23,3,cobblestone)
Block(-8,23,4,stone:6)
Block(-8,24,-8,cobblestone)
Block(-8,24,-7,cobblestone)
Block(-8,24,-6,cobblestone)
Block(-8,24,-5,cobblestone)
Block(-8,24,-4,cobblestone)
Block(-8,24,-3,cobblestone)
Block(-8,24,-2,cobblestone)
Block(-8,24,-1,cobblestone)
Block(-8,24,0,cobblestone)
Block(-8,24,1,cobblestone)
Block(-8,24,2,cobblestone)
Block(-8,24,3,cobblestone)
Block(-8,24,4,stone:6)
Block(-8,25,-8,cobblestone)
Block(-8,25,-7,cobblestone)
Block(-8,25,-6,cobblestone)
Block(-8,25,-5,cobblestone)
Block(-8,25,-4,cobblestone)
Block(-8,25,-3,cobblestone)
Block(-8,25,-2,cobblestone)
Block(-8,25,-1,cobblestone)
Block(-8,25,0,cobblestone)
Block(-8,25,1,cobblestone)
Block(-8,25,2,cobblestone)
Block(-8,25,3,cobblestone)
Block(-8,25,4,stone:6)
Block(-8,26,-2,stone_slab:3)
Block(-8,26,-1,stone:6)
Block(-8,26,0,log)
Block(-8,26,1,stone:6)
Block(-8,26,2,stone:6)
Block(-8,26,3,stone:6)
Block(-8,26,4,stone:6)
Block(-8,27,0,log)
Block(-8,27,1,stone:6)
Block(-8,27,2,stone:6)
Block(-8,27,3,stone:6)
Block(-8,27,4,stone:6)
Block(-8,27,5,dark_oak_stairs:5)
Block(-8,28,0,log)
Block(-8,28,5,double_stone_slab:3)
Block(-8,29,-1,wooden_slab:13)
Block(-8,29,0,log)
Block(-8,29,5,dark_oak_fence)
Block(-8,29,6,wooden_slab:13)
Block(-8,30,0,wooden_slab:5)
Block(-8,30,1,double_wooden_slab:5)
Block(-8,30,2,wooden_slab:13)
Block(-8,30,3,wooden_slab:13)
Block(-8,30,4,double_wooden_slab:5)
Block(-8,30,5,wooden_slab:5)
Block(-7,1,-8,cobblestone)
Block(-7,1,-7,cobblestone)
Block(-7,1,-6,cobblestone)
Block(-7,1,-5,cobblestone)
Block(-7,1,-4,cobblestone)
Block(-7,1,-3,cobblestone)
Block(-7,1,-2,cobblestone)
Block(-7,1,-1,cobblestone)
Block(-7,1,0,cobblestone)
Block(-7,1,1,cobblestone)
Block(-7,1,2,cobblestone)
Block(-7,1,3,cobblestone)
Block(-7,1,7,cobblestone)
Block(-7,2,3,cobblestone)
Block(-7,2,7,cobblestone)
Block(-7,3,3,cobblestone)
Block(-7,3,7,cobblestone)
Block(-7,4,3,cobblestone)
Block(-7,4,7,cobblestone)
Block(-7,5,3,cobblestone)
Block(-7,5,7,cobblestone)
Block(-7,6,3,cobblestone)
Block(-7,6,7,cobblestone)
Block(-7,7,3,cobblestone)
Block(-7,7,7,cobblestone)
Block(-7,8,3,cobblestone)
Block(-7,8,7,cobblestone)
Block(-7,9,3,cobblestone)
Block(-7,9,7,cobblestone)
Block(-7,10,3,cobblestone)
Block(-7,10,7,cobblestone)
Block(-7,11,3,cobblestone)
Block(-7,11,4,cobblestone)
Block(-7,11,5,cobblestone)
Block(-7,11,6,cobblestone)
Block(-7,11,7,cobblestone)
Block(-7,12,3,cobblestone)
Block(-7,12,4,stone:6)
Block(-7,12,5,stone:6)
Block(-7,12,6,stone_stairs:1)
Block(-7,12,7,stone_STAIRS:0)
Block(-7,13,3,stone:6)
Block(-7,13,4,stone:6)
Block(-7,13,5,stone:6)
Block(-7,14,3,stone:6)
Block(-7,14,4,stone:6)
Block(-7,14,5,stone:6)
Block(-7,15,3,stone:6)
Block(-7,15,4,stone:6)
Block(-7,15,5,stone:6)
Block(-7,16,3,stone:6)
Block(-7,16,4,stone:6)
Block(-7,16,5,stone_STAIRS:0)
Block(-7,17,3,stone:6)
Block(-7,18,3,stone:6)
Block(-7,19,3,stone:6)
Block(-7,20,3,stone:6)
Block(-7,21,-8,stone:6)
Block(-7,21,-7,stone:6)
Block(-7,21,-6,stone:6)
Block(-7,21,-5,stone:6)
Block(-7,21,-4,stone:6)
Block(-7,21,-3,stone:6)
Block(-7,21,-2,stone:6)
Block(-7,21,-1,stone:6)
Block(-7,21,0,stone:6)
Block(-7,21,1,stone:6)
Block(-7,21,2,stone:6)
Block(-7,21,3,stone:6)
Block(-7,22,-8,cobblestone)
Block(-7,22,-7,cobblestone)
Block(-7,22,-6,cobblestone)
Block(-7,22,-5,cobblestone)
Block(-7,22,-4,cobblestone)
Block(-7,22,-3,cobblestone)
Block(-7,22,-2,cobblestone)
Block(-7,22,-1,cobblestone)
Block(-7,22,0,cobblestone)
Block(-7,22,1,cobblestone)
Block(-7,22,2,cobblestone)
Block(-7,22,3,stone:6)
Block(-7,23,-8,cobblestone)
Block(-7,23,-7,cobblestone)
Block(-7,23,-6,cobblestone)
Block(-7,23,-5,cobblestone)
Block(-7,23,-4,cobblestone)
Block(-7,23,-3,cobblestone)
Block(-7,23,-2,cobblestone)
Block(-7,23,-1,cobblestone)
Block(-7,23,0,cobblestone)
Block(-7,23,1,cobblestone)
Block(-7,23,2,cobblestone)
Block(-7,23,3,stone:6)
Block(-7,24,-8,cobblestone)
Block(-7,24,-7,cobblestone)
Block(-7,24,-6,cobblestone)
Block(-7,24,-5,cobblestone)
Block(-7,24,-4,cobblestone)
Block(-7,24,-3,cobblestone)
Block(-7,24,-2,cobblestone)
Block(-7,24,-1,cobblestone)
Block(-7,24,0,cobblestone)
Block(-7,24,1,cobblestone)
Block(-7,24,2,cobblestone)
Block(-7,24,3,stone:6)
Block(-7,25,-8,cobblestone)
Block(-7,25,-7,cobblestone)
Block(-7,25,-6,cobblestone)
Block(-7,25,-5,cobblestone)
Block(-7,25,-4,cobblestone)
Block(-7,25,-3,cobblestone)
Block(-7,25,-2,cobblestone)
Block(-7,25,-1,cobblestone)
Block(-7,25,0,cobblestone)
Block(-7,25,1,cobblestone)
Block(-7,25,2,cobblestone)
Block(-7,25,3,stone:6)
Block(-7,26,-3,stone_slab:3)
Block(-7,26,-2,stone:6)
Block(-7,26,-1,stone:6)
Block(-7,26,0,stone:6)
Block(-7,26,1,stone:6)
Block(-7,26,2,stone:6)
Block(-7,26,3,stone:6)
Block(-7,27,-1,stone_slab:3)
Block(-7,27,0,stone:6)
Block(-7,27,1,stone:6)
Block(-7,27,2,stone:6)
Block(-7,27,3,stone:6)
Block(-7,27,4,dark_oak_stairs:7)
Block(-7,28,4,double_stone_slab:3)
Block(-7,29,-2,wooden_slab:13)
Block(-7,29,5,wooden_slab:13)
Block(-7,30,-1,wooden_slab:5)
Block(-7,30,0,double_wooden_slab:5)
Block(-7,30,1,wooden_slab:13)
Block(-7,30,2,wooden_slab:13)
Block(-7,30,3,double_wooden_slab:5)
Block(-7,30,4,wooden_slab:5)
Block(-6,1,-8,cobblestone)
Block(-6,1,-7,cobblestone)
Block(-6,1,-6,cobblestone)
Block(-6,1,-5,cobblestone)
Block(-6,1,-4,cobblestone)
Block(-6,1,-3,cobblestone)
Block(-6,1,-2,cobblestone)
Block(-6,1,-1,cobblestone)
Block(-6,1,0,cobblestone)
Block(-6,1,1,cobblestone)
Block(-6,1,2,log)
Block(-6,1,6,cobblestone)
Block(-6,2,2,log)
Block(-6,2,6,cobblestone)
Block(-6,3,2,log)
Block(-6,3,6,cobblestone)
Block(-6,4,2,log)
Block(-6,4,6,cobblestone)
Block(-6,5,2,log)
Block(-6,5,6,cobblestone)
Block(-6,6,2,log)
Block(-6,6,6,cobblestone)
Block(-6,7,2,log)
Block(-6,7,6,cobblestone)
Block(-6,8,2,log)
Block(-6,8,6,cobblestone)
Block(-6,9,2,log)
Block(-6,9,6,cobblestone)
Block(-6,10,2,log)
Block(-6,10,6,cobblestone)
Block(-6,11,2,log)
Block(-6,11,3,cobblestone)
Block(-6,11,4,cobblestone)
Block(-6,11,5,cobblestone)
Block(-6,11,6,cobblestone)
Block(-6,12,2,log)
Block(-6,12,3,log:8)
Block(-6,12,4,log:8)
Block(-6,12,5,stone_stairs:1)
Block(-6,12,6,stone_brick_STAIRS:0)
Block(-6,13,2,log)
Block(-6,13,4,log)
Block(-6,14,2,log)
Block(-6,14,4,log)
Block(-6,15,2,log)
Block(-6,15,4,log)
Block(-6,16,2,log)
Block(-6,16,4,log)
Block(-6,17,2,log)
Block(-6,17,3,log:8)
Block(-6,17,4,stone_STAIRS:0)
Block(-6,18,2,log)
Block(-6,19,2,log)
Block(-6,20,2,log)
Block(-6,21,-8,stone:6)
Block(-6,21,-7,stone:6)
Block(-6,21,-6,stone:6)
Block(-6,21,-5,stone:6)
Block(-6,21,-4,stone:6)
Block(-6,21,-3,stone:6)
Block(-6,21,-2,stone:6)
Block(-6,21,-1,stone:6)
Block(-6,21,0,stone:6)
Block(-6,21,1,stone:6)
Block(-6,21,2,log)
Block(-6,22,-8,cobblestone)
Block(-6,22,-7,cobblestone)
Block(-6,22,-6,cobblestone)
Block(-6,22,-5,cobblestone)
Block(-6,22,-4,cobblestone)
Block(-6,22,-3,cobblestone)
Block(-6,22,-2,cobblestone)
Block(-6,22,-1,cobblestone)
Block(-6,22,0,cobblestone)
Block(-6,22,1,cobblestone)
Block(-6,22,2,log)
Block(-6,23,-8,cobblestone)
Block(-6,23,-7,cobblestone)
Block(-6,23,-6,cobblestone)
Block(-6,23,-5,cobblestone)
Block(-6,23,-4,cobblestone)
Block(-6,23,-3,cobblestone)
Block(-6,23,-2,cobblestone)
Block(-6,23,-1,cobblestone)
Block(-6,23,0,cobblestone)
Block(-6,23,1,cobblestone)
Block(-6,23,2,log)
Block(-6,24,-8,cobblestone)
Block(-6,24,-7,cobblestone)
Block(-6,24,-6,cobblestone)
Block(-6,24,-5,cobblestone)
Block(-6,24,-4,cobblestone)
Block(-6,24,-3,cobblestone)
Block(-6,24,-2,cobblestone)
Block(-6,24,-1,cobblestone)
Block(-6,24,0,cobblestone)
Block(-6,24,1,cobblestone)
Block(-6,24,2,log)
Block(-6,25,-8,cobblestone)
Block(-6,25,-7,cobblestone)
Block(-6,25,-6,cobblestone)
Block(-6,25,-5,cobblestone)
Block(-6,25,-4,cobblestone)
Block(-6,25,-3,cobblestone)
Block(-6,25,-2,cobblestone)
Block(-6,25,-1,cobblestone)
Block(-6,25,0,cobblestone)
Block(-6,25,1,cobblestone)
Block(-6,25,2,log)
Block(-6,26,-4,stone_slab:3)
Block(-6,26,-3,stone:6)
Block(-6,26,-2,stone:6)
Block(-6,26,-1,stone:6)
Block(-6,26,0,stone:6)
Block(-6,26,1,stone:6)
Block(-6,26,2,log)
Block(-6,27,-2,stone_slab:3)
Block(-6,27,-1,stone:6)
Block(-6,27,0,stone:6)
Block(-6,27,1,stone:6)
Block(-6,27,2,log)
Block(-6,27,3,dark_oak_stairs:5)
Block(-6,28,2,log)
Block(-6,28,3,double_stone_slab:3)
Block(-6,29,-3,wooden_slab:13)
Block(-6,29,2,log)
Block(-6,29,3,dark_oak_fence)
Block(-6,29,4,wooden_slab:13)
Block(-6,30,-2,wooden_slab:5)
Block(-6,30,-1,double_wooden_slab:5)
Block(-6,30,0,wooden_slab:13)
Block(-6,30,1,wooden_slab:13)
Block(-6,30,2,double_wooden_slab:5)
Block(-6,30,3,wooden_slab:5)
Block(-5,1,-8,cobblestone)
Block(-5,1,-7,cobblestone)
Block(-5,1,-6,cobblestone)
Block(-5,1,-5,cobblestone)
Block(-5,1,-4,cobblestone)
Block(-5,1,-3,cobblestone)
Block(-5,1,-2,cobblestone)
Block(-5,1,-1,cobblestone)
Block(-5,1,0,cobblestone)
Block(-5,1,1,cobblestone)
Block(-5,1,5,cobblestone)
Block(-5,2,1,cobblestone)
Block(-5,2,5,cobblestone)
Block(-5,3,1,cobblestone)
Block(-5,3,5,cobblestone)
Block(-5,4,1,cobblestone)
Block(-5,4,5,cobblestone)
Block(-5,5,1,cobblestone)
Block(-5,5,5,cobblestone)
Block(-5,6,1,cobblestone)
Block(-5,6,5,cobblestone)
Block(-5,7,1,cobblestone)
Block(-5,7,5,cobblestone)
Block(-5,8,1,cobblestone)
Block(-5,8,5,cobblestone)
Block(-5,9,1,cobblestone)
Block(-5,9,5,cobblestone)
Block(-5,10,1,cobblestone)
Block(-5,10,5,cobblestone)
Block(-5,11,1,cobblestone)
Block(-5,11,2,cobblestone)
Block(-5,11,3,cobblestone)
Block(-5,11,4,cobblestone)
Block(-5,11,5,cobblestone)
Block(-5,12,1,cobblestone)
Block(-5,12,2,stone:6)
Block(-5,12,3,stone:6)
Block(-5,12,4,stone_stairs:1)
Block(-5,12,5,stone_STAIRS:0)
Block(-5,13,1,stone:6)
Block(-5,13,2,stone:6)
Block(-5,13,3,stone:6)
Block(-5,14,1,stone:6)
Block(-5,14,2,stone:6)
Block(-5,14,3,stone:6)
Block(-5,15,1,stone:6)
Block(-5,15,2,stone:6)
Block(-5,15,3,stone:6)
Block(-5,16,1,stone:6)
Block(-5,16,2,stone:6)
Block(-5,16,3,stone_STAIRS:0)
Block(-5,17,1,stone:6)
Block(-5,18,1,stone:6)
Block(-5,19,1,stone:6)
Block(-5,20,1,stone:6)
Block(-5,21,-8,stone:6)
Block(-5,21,-7,stone:6)
Block(-5,21,-6,stone:6)
Block(-5,21,-5,stone:6)
Block(-5,21,-4,stone:6)
Block(-5,21,-3,stone:6)
Block(-5,21,-2,stone:6)
Block(-5,21,-1,stone:6)
Block(-5,21,0,stone:6)
Block(-5,21,1,stone:6)
Block(-5,22,-8,cobblestone)
Block(-5,22,-7,cobblestone)
Block(-5,22,-6,cobblestone)
Block(-5,22,-5,cobblestone)
Block(-5,22,-4,cobblestone)
Block(-5,22,-3,cobblestone)
Block(-5,22,-2,cobblestone)
Block(-5,22,-1,cobblestone)
Block(-5,22,0,cobblestone)
Block(-5,22,1,stone:6)
Block(-5,23,-8,cobblestone)
Block(-5,23,-7,cobblestone)
Block(-5,23,-6,cobblestone)
Block(-5,23,-5,cobblestone)
Block(-5,23,-4,cobblestone)
Block(-5,23,-3,cobblestone)
Block(-5,23,-2,cobblestone)
Block(-5,23,-1,cobblestone)
Block(-5,23,0,cobblestone)
Block(-5,23,1,stone:6)
Block(-5,24,-8,cobblestone)
Block(-5,24,-7,cobblestone)
Block(-5,24,-6,cobblestone)
Block(-5,24,-5,cobblestone)
Block(-5,24,-4,cobblestone)
Block(-5,24,-3,cobblestone)
Block(-5,24,-2,cobblestone)
Block(-5,24,-1,cobblestone)
Block(-5,24,0,cobblestone)
Block(-5,24,1,stone:6)
Block(-5,25,-8,cobblestone)
Block(-5,25,-7,cobblestone)
Block(-5,25,-6,cobblestone)
Block(-5,25,-5,cobblestone)
Block(-5,25,-4,cobblestone)
Block(-5,25,-3,cobblestone)
Block(-5,25,-2,cobblestone)
Block(-5,25,-1,cobblestone)
Block(-5,25,0,cobblestone)
Block(-5,25,1,stone:6)
Block(-5,26,-5,stone_slab:3)
Block(-5,26,-4,stone:6)
Block(-5,26,-3,stone:6)
Block(-5,26,-2,stone:6)
Block(-5,26,-1,stone:6)
Block(-5,26,0,stone:6)
Block(-5,26,1,stone:6)
Block(-5,27,-3,stone_slab:3)
Block(-5,27,-2,stone:6)
Block(-5,27,-1,stone:6)
Block(-5,27,0,stone:6)
Block(-5,27,1,stone:6)
Block(-5,27,2,dark_oak_stairs:7)
Block(-5,28,2,double_stone_slab:3)
Block(-5,29,-4,wooden_slab:13)
Block(-5,29,3,wooden_slab:13)
Block(-5,30,-3,wooden_slab:5)
Block(-5,30,-2,double_wooden_slab:5)
Block(-5,30,-1,double_wooden_slab:5)
Block(-5,30,0,wooden_slab:13)
Block(-5,30,1,double_wooden_slab:5)
Block(-5,30,2,wooden_slab:5)
Block(-5,34,-5,stone_brick_stairs:4)
Block(-5,34,-4,wooden_slab:13)
Block(-5,34,-3,wooden_slab:13)
Block(-5,34,-2,stone_brick_stairs:4)
Block(-5,35,-6,stone_brick_stairs:6)
Block(-5,35,-5,stone_brick_STAIRS:0)
Block(-5,35,-4,stone_stairs:2)
Block(-5,35,-3,stone_STAIRS:0)
Block(-5,35,-2,stone_brick_stairs:2)
Block(-5,35,-1,stone_brick_stairs:7)
Block(-5,36,-6,wooden_slab:5)
Block(-5,36,-4,wooden_slab:5)
Block(-5,36,-3,wooden_slab:5)
Block(-5,36,-1,wooden_slab:5)
Block(-4,1,-8,cobblestone)
Block(-4,1,-7,cobblestone)
Block(-4,1,-6,cobblestone)
Block(-4,1,-5,log)
Block(-4,1,-4,cobblestone)
Block(-4,1,-3,cobblestone)
Block(-4,1,-2,log)
Block(-4,1,-1,cobblestone)
Block(-4,1,0,cobblestone)
Block(-4,1,4,log)
Block(-4,2,-5,log)
Block(-4,2,-4,cobblestone)
Block(-4,2,-3,cobblestone)
Block(-4,2,-2,log)
Block(-4,2,0,cobblestone)
Block(-4,2,4,log)
Block(-4,3,-5,log)
Block(-4,3,-4,cobblestone)
Block(-4,3,-3,cobblestone)
Block(-4,3,-2,log)
Block(-4,3,0,cobblestone)
Block(-4,3,4,log)
Block(-4,4,-5,log)
Block(-4,4,-4,cobblestone)
Block(-4,4,-3,cobblestone)
Block(-4,4,-2,log)
Block(-4,4,0,cobblestone)
Block(-4,4,4,log)
Block(-4,5,-5,log)
Block(-4,5,-4,cobblestone)
Block(-4,5,-3,cobblestone)
Block(-4,5,-2,log)
Block(-4,5,0,cobblestone)
Block(-4,5,4,log)
Block(-4,6,-5,log)
Block(-4,6,-4,cobblestone)
Block(-4,6,-3,cobblestone)
Block(-4,6,-2,log)
Block(-4,6,0,cobblestone)
Block(-4,6,4,log)
Block(-4,7,-5,log)
Block(-4,7,-4,cobblestone)
Block(-4,7,-3,cobblestone)
Block(-4,7,-2,log)
Block(-4,7,0,cobblestone)
Block(-4,7,4,log)
Block(-4,8,-5,log)
Block(-4,8,-4,cobblestone)
Block(-4,8,-3,cobblestone)
Block(-4,8,-2,log)
Block(-4,8,0,cobblestone)
Block(-4,8,4,log)
Block(-4,9,-5,log)
Block(-4,9,-4,cobblestone)
Block(-4,9,-3,cobblestone)
Block(-4,9,-2,log)
Block(-4,9,0,cobblestone)
Block(-4,9,4,log)
Block(-4,10,-5,log)
Block(-4,10,-4,cobblestone)
Block(-4,10,-3,cobblestone)
Block(-4,10,-2,log)
Block(-4,10,0,cobblestone)
Block(-4,10,4,log)
Block(-4,11,-5,log)
Block(-4,11,-4,cobblestone)
Block(-4,11,-3,cobblestone)
Block(-4,11,-2,log)
Block(-4,11,0,cobblestone)
Block(-4,11,1,cobblestone)
Block(-4,11,2,cobblestone)
Block(-4,11,3,cobblestone)
Block(-4,11,4,log)
Block(-4,12,-5,log)
Block(-4,12,-4,cobblestone)
Block(-4,12,-3,cobblestone)
Block(-4,12,-2,log)
Block(-4,12,0,cobblestone)
Block(-4,12,1,stone:6)
Block(-4,12,2,stone:6)
Block(-4,12,3,stone_stairs:1)
Block(-4,12,4,stone_brick_STAIRS:0)
Block(-4,13,-5,log)
Block(-4,13,-4,stone:6)
Block(-4,13,-3,stone:6)
Block(-4,13,-2,log)
Block(-4,13,0,stone:6)
Block(-4,13,1,stone:6)
Block(-4,13,2,stone:6)
Block(-4,14,-5,log)
Block(-4,14,-4,stone:6)
Block(-4,14,-3,stone:6)
Block(-4,14,-2,log)
Block(-4,14,0,stone:6)
Block(-4,14,1,stone:6)
Block(-4,14,2,stone:6)
Block(-4,15,-5,log)
Block(-4,15,-4,stone:6)
Block(-4,15,-3,stone:6)
Block(-4,15,-2,log)
Block(-4,15,0,stone:6)
Block(-4,15,1,stone:6)
Block(-4,15,2,stone:6)
Block(-4,16,-5,log)
Block(-4,16,-4,stone:6)
Block(-4,16,-3,stone:6)
Block(-4,16,-2,log)
Block(-4,16,0,stone:6)
Block(-4,16,1,stone:6)
Block(-4,16,2,stone_STAIRS:0)
Block(-4,17,-5,log)
Block(-4,17,-4,stone:6)
Block(-4,17,-3,stone:6)
Block(-4,17,-2,log)
Block(-4,17,0,stone:6)
Block(-4,18,-5,log)
Block(-4,18,-4,stone:6)
Block(-4,18,-3,stone:6)
Block(-4,18,-2,log)
Block(-4,18,0,stone:6)
Block(-4,19,-5,log)
Block(-4,19,-4,stone:6)
Block(-4,19,-3,stone:6)
Block(-4,19,-2,log)
Block(-4,19,0,stone:6)
Block(-4,20,-5,log)
Block(-4,20,-4,stone:6)
Block(-4,20,-3,stone:6)
Block(-4,20,-2,log)
Block(-4,20,0,stone:6)
Block(-4,21,-8,stone:6)
Block(-4,21,-7,stone:6)
Block(-4,21,-6,stone:6)
Block(-4,21,-5,log)
Block(-4,21,-4,stone:6)
Block(-4,21,-3,stone:6)
Block(-4,21,-2,log)
Block(-4,21,-1,stone:6)
Block(-4,21,0,stone:6)
Block(-4,22,-8,cobblestone)
Block(-4,22,-7,cobblestone)
Block(-4,22,-6,cobblestone)
Block(-4,22,-5,log)
Block(-4,22,-4,stone:6)
Block(-4,22,-3,stone:6)
Block(-4,22,-2,log)
Block(-4,22,-1,cobblestone)
Block(-4,22,0,stone:6)
Block(-4,23,-8,cobblestone)
Block(-4,23,-7,cobblestone)
Block(-4,23,-6,cobblestone)
Block(-4,23,-5,log)
Block(-4,23,-4,stone:6)
Block(-4,23,-3,stone:6)
Block(-4,23,-2,log)
Block(-4,23,-1,cobblestone)
Block(-4,23,0,stone:6)
Block(-4,24,-8,cobblestone)
Block(-4,24,-7,cobblestone)
Block(-4,24,-6,cobblestone)
Block(-4,24,-5,log)
Block(-4,24,-4,stone:6)
Block(-4,24,-3,stone:6)
Block(-4,24,-2,log)
Block(-4,24,-1,cobblestone)
Block(-4,24,0,stone:6)
Block(-4,25,-8,cobblestone)
Block(-4,25,-7,cobblestone)
Block(-4,25,-6,cobblestone)
Block(-4,25,-5,log)
Block(-4,25,-4,stone:6)
Block(-4,25,-3,stone:6)
Block(-4,25,-2,log)
Block(-4,25,-1,cobblestone)
Block(-4,25,0,stone:6)
Block(-4,26,-5,log)
Block(-4,26,-4,stone:6)
Block(-4,26,-3,stone:6)
Block(-4,26,-2,log)
Block(-4,26,-1,stone:6)
Block(-4,26,0,stone:6)
Block(-4,27,-5,log)
Block(-4,27,-4,stone:6)
Block(-4,27,-3,stone:6)
Block(-4,27,-2,log)
Block(-4,27,-1,stone:6)
Block(-4,27,0,stone:6)
Block(-4,27,1,dark_oak_stairs:5)
Block(-4,28,-5,log)
Block(-4,28,-4,stone:6)
Block(-4,28,-3,stone:6)
Block(-4,28,-2,log)
Block(-4,28,1,double_stone_slab:3)
Block(-4,29,-5,log)
Block(-4,29,-4,stone:6)
Block(-4,29,-3,stone:6)
Block(-4,29,-2,log)
Block(-4,29,1,dark_oak_fence)
Block(-4,29,2,wooden_slab:13)
Block(-4,30,-5,log)
Block(-4,30,-4,log:8)
Block(-4,30,-3,log:8)
Block(-4,30,-2,log)
Block(-4,30,-1,double_wooden_slab:5)
Block(-4,30,0,double_wooden_slab:5)
Block(-4,30,1,wooden_slab:5)
Block(-4,31,-5,stone_brick_stairs:0)
Block(-4,31,-4,dark_oak_stairs:7)
Block(-4,31,-3,dark_oak_stairs:6)
Block(-4,31,-2,stone_brick_stairs:0)
Block(-4,33,-7,stone_slab:11)
Block(-4,33,-5,stone_slab:11)
Block(-4,33,-2,stone_slab:11)
Block(-4,33,0,stone_slab:11)
Block(-4,34,-7,double_wooden_slab:5)
Block(-4,34,-6,stone_brick_stairs:6)
Block(-4,34,-5,log:4)
Block(-4,34,-4,stone_slab:3)
Block(-4,34,-3,stone_slab:3)
Block(-4,34,-2,log:4)
Block(-4,34,-1,stone_brick_stairs:7)
Block(-4,34,0,double_wooden_slab:5)
Block(-4,35,-7,stone_slab:3)
Block(-4,35,0,stone_slab:3)
Block(-3,1,-8,cobblestone)
Block(-3,1,-7,cobblestone)
Block(-3,1,-6,cobblestone)
Block(-3,1,-1,cobblestone)
Block(-3,1,3,cobblestone)
Block(-3,2,-6,cobblestone)
Block(-3,2,-1,cobblestone)
Block(-3,2,3,cobblestone)
Block(-3,3,-6,cobblestone)
Block(-3,3,-1,cobblestone)
Block(-3,3,3,cobblestone)
Block(-3,4,-6,cobblestone)
Block(-3,4,-1,cobblestone)
Block(-3,4,3,cobblestone)
Block(-3,5,-6,cobblestone)
Block(-3,5,-1,cobblestone)
Block(-3,5,3,cobblestone)
Block(-3,6,-6,cobblestone)
Block(-3,6,-1,cobblestone)
Block(-3,6,3,cobblestone)
Block(-3,7,-6,cobblestone)
Block(-3,7,-1,cobblestone)
Block(-3,7,3,cobblestone)
Block(-3,8,-6,cobblestone)
Block(-3,8,-1,cobblestone)
Block(-3,8,3,cobblestone)
Block(-3,9,-6,cobblestone)
Block(-3,9,-1,cobblestone)
Block(-3,9,3,cobblestone)
Block(-3,10,-6,cobblestone)
Block(-3,10,-1,cobblestone)
Block(-3,10,3,cobblestone)
Block(-3,11,-6,cobblestone)
Block(-3,11,-1,cobblestone)
Block(-3,11,0,cobblestone)
Block(-3,11,1,cobblestone)
Block(-3,11,2,cobblestone)
Block(-3,11,3,cobblestone)
Block(-3,12,-6,cobblestone)
Block(-3,12,-1,cobblestone)
Block(-3,12,0,stone:6)
Block(-3,12,1,stone:6)
Block(-3,12,2,stone:6)
Block(-3,12,3,stone_STAIRS:0)
Block(-3,13,-6,stone:6)
Block(-3,13,-1,stone:6)
Block(-3,13,0,stone:6)
Block(-3,13,1,stone:6)
Block(-3,13,2,stone:6)
Block(-3,14,-6,stone:6)
Block(-3,14,-1,stone:6)
Block(-3,14,0,stone:6)
Block(-3,14,1,stone:6)
Block(-3,14,2,stone:6)
Block(-3,15,-6,stone:6)
Block(-3,15,-1,stone:6)
Block(-3,15,0,stone:6)
Block(-3,15,1,stone:6)
Block(-3,15,2,stone:6)
Block(-3,16,-6,stone:6)
Block(-3,16,-1,stone:6)
Block(-3,16,0,stone:6)
Block(-3,16,1,stone:6)
Block(-3,16,2,stone_STAIRS:0)
Block(-3,17,-6,stone:6)
Block(-3,17,-1,stone:6)
Block(-3,18,-6,stone:6)
Block(-3,18,-1,stone:6)
Block(-3,19,-6,stone:6)
Block(-3,19,-1,stone:6)
Block(-3,20,-6,stone:6)
Block(-3,20,-1,stone:6)
Block(-3,21,-8,stone:6)
Block(-3,21,-7,stone:6)
Block(-3,21,-6,stone:6)
Block(-3,21,-1,stone:6)
Block(-3,22,-8,cobblestone)
Block(-3,22,-7,cobblestone)
Block(-3,22,-6,stone:6)
Block(-3,22,-1,stone:6)
Block(-3,23,-8,cobblestone)
Block(-3,23,-7,cobblestone)
Block(-3,23,-6,stone:6)
Block(-3,23,-1,stone:6)
Block(-3,24,-8,cobblestone)
Block(-3,24,-7,cobblestone)
Block(-3,24,-6,stone:6)
Block(-3,24,-5,stonebrick)
Block(-3,24,-4,stonebrick)
Block(-3,24,-3,stonebrick)
Block(-3,24,-2,stonebrick)
Block(-3,24,-1,stone:6)
Block(-3,25,-8,cobblestone)
Block(-3,25,-7,cobblestone)
Block(-3,25,-6,stone:6)
Block(-3,25,-5,stonebrick)
Block(-3,25,-4,stonebrick)
Block(-3,25,-3,stonebrick)
Block(-3,25,-2,stonebrick)
Block(-3,25,-1,stone:6)
Block(-3,26,-6,stone:6)
Block(-3,26,-5,stonebrick)
Block(-3,26,-4,stonebrick)
Block(-3,26,-3,stonebrick)
Block(-3,26,-2,stonebrick)
Block(-3,26,-1,stone:6)
Block(-3,27,-6,stone:6)
Block(-3,27,-5,stonebrick)
Block(-3,27,-4,stonebrick)
Block(-3,27,-3,stonebrick)
Block(-3,27,-2,stonebrick)
Block(-3,27,-1,stone:6)
Block(-3,27,0,dark_oak_stairs:7)
Block(-3,28,-6,stone:6)
Block(-3,28,-5,stonebrick)
Block(-3,28,-4,stonebrick)
Block(-3,28,-3,stonebrick)
Block(-3,28,-2,stonebrick)
Block(-3,28,-1,stone:6)
Block(-3,28,0,double_stone_slab:3)
Block(-3,29,-6,stone:6)
Block(-3,29,-5,stonebrick)
Block(-3,29,-4,stonebrick)
Block(-3,29,-3,stonebrick)
Block(-3,29,-2,stonebrick)
Block(-3,29,-1,stone:6)
Block(-3,29,0,wooden_slab:13)
Block(-3,29,1,wooden_slab:13)
Block(-3,30,-6,stone:6)
Block(-3,30,-5,stonebrick)
Block(-3,30,-2,stonebrick)
Block(-3,30,-1,stone:6)
Block(-3,30,0,wooden_slab:5)
Block(-3,31,-6,stone:6)
Block(-3,31,-5,log)
Block(-3,31,-2,log)
Block(-3,31,-1,stone:6)
Block(-3,32,-6,cobblestone_wall)
Block(-3,32,-5,log)
Block(-3,32,-4,dark_oak_stairs:0)
Block(-3,32,-3,dark_oak_stairs:0)
Block(-3,32,-2,log)
Block(-3,32,-1,cobblestone_wall)
Block(-3,33,-6,cobblestone_wall)
Block(-3,33,-5,log)
Block(-3,33,-4,dark_oak_stairs:4)
Block(-3,33,-3,dark_oak_stairs:4)
Block(-3,33,-2,log)
Block(-3,33,-1,cobblestone_wall)
Block(-3,34,-7,stone_brick_stairs:4)
Block(-3,34,-6,cobblestone_wall)
Block(-3,34,-5,log)
Block(-3,34,-2,log)
Block(-3,34,-1,cobblestone_wall)
Block(-3,34,0,stone_brick_stairs:4)
Block(-3,35,-8,stone_brick_stairs:4)
Block(-3,35,-5,wooden_slab:5)
Block(-3,35,-2,wooden_slab:5)
Block(-3,35,1,stone_brick_stairs:4)
Block(-3,36,-8,wooden_slab:5)
Block(-3,36,1,wooden_slab:5)
Block(-2,1,-8,cobblestone)
Block(-2,1,-7,log)
Block(-2,1,0,log)
Block(-2,1,3,log)
Block(-2,2,-7,log)
Block(-2,2,0,log)
Block(-2,2,3,log)
Block(-2,3,-7,log)
Block(-2,3,0,log)
Block(-2,3,3,log)
Block(-2,4,-7,log)
Block(-2,4,0,log)
Block(-2,4,3,log)
Block(-2,5,-7,log)
Block(-2,5,0,log)
Block(-2,5,3,log)
Block(-2,6,-7,log)
Block(-2,6,0,log)
Block(-2,6,3,log)
Block(-2,7,-7,log)
Block(-2,7,0,log)
Block(-2,7,3,log)
Block(-2,8,-7,log)
Block(-2,8,0,log)
Block(-2,8,3,log)
Block(-2,9,-7,log)
Block(-2,9,0,log)
Block(-2,9,3,log)
Block(-2,10,-7,log)
Block(-2,10,0,log)
Block(-2,10,3,log)
Block(-2,11,-7,log)
Block(-2,11,0,log)
Block(-2,11,1,cobblestone)
Block(-2,11,2,cobblestone)
Block(-2,11,3,log)
Block(-2,12,-7,log)
Block(-2,12,0,log)
Block(-2,12,1,log:8)
Block(-2,12,2,log:8)
Block(-2,12,3,stone_brick_STAIRS:0)
Block(-2,13,-7,log)
Block(-2,13,0,log)
Block(-2,13,2,log)
Block(-2,14,-7,log)
Block(-2,14,0,log)
Block(-2,14,2,log)
Block(-2,15,-7,log)
Block(-2,15,0,log)
Block(-2,15,2,log)
Block(-2,16,-7,log)
Block(-2,16,0,log)
Block(-2,16,2,log)
Block(-2,17,-7,log)
Block(-2,17,0,log)
Block(-2,17,1,log:8)
Block(-2,17,2,stone_STAIRS:0)
Block(-2,18,-7,log)
Block(-2,18,0,log)
Block(-2,19,-7,log)
Block(-2,19,0,log)
Block(-2,20,-7,log)
Block(-2,20,0,log)
Block(-2,21,-8,stone:6)
Block(-2,21,-7,log)
Block(-2,21,0,log)
Block(-2,22,-8,cobblestone)
Block(-2,22,-7,log)
Block(-2,22,0,log)
Block(-2,23,-8,cobblestone)
Block(-2,23,-7,log)
Block(-2,23,0,log)
Block(-2,24,-8,cobblestone)
Block(-2,24,-7,log)
Block(-2,24,-6,stonebrick)
Block(-2,24,-5,stonebrick)
Block(-2,24,-4,stonebrick)
Block(-2,24,-3,stonebrick)
Block(-2,24,-2,stonebrick)
Block(-2,24,-1,stonebrick)
Block(-2,24,0,log)
Block(-2,25,-8,cobblestone)
Block(-2,25,-7,log)
Block(-2,25,-6,stonebrick)
Block(-2,25,-5,stonebrick)
Block(-2,25,-4,stonebrick)
Block(-2,25,-3,stonebrick)
Block(-2,25,-2,stonebrick)
Block(-2,25,-1,stonebrick)
Block(-2,25,0,log)
Block(-2,26,-7,log)
Block(-2,26,-6,stonebrick)
Block(-2,26,-5,stonebrick)
Block(-2,26,-4,stonebrick)
Block(-2,26,-3,stonebrick)
Block(-2,26,-2,stonebrick)
Block(-2,26,-1,stonebrick)
Block(-2,26,0,log)
Block(-2,27,-7,log)
Block(-2,27,-6,stonebrick)
Block(-2,27,-5,stonebrick)
Block(-2,27,-4,stonebrick)
Block(-2,27,-3,stonebrick)
Block(-2,27,-2,stonebrick)
Block(-2,27,-1,stonebrick)
Block(-2,27,0,log)
Block(-2,28,-8,trapdoor:5)
Block(-2,28,-7,log)
Block(-2,28,-6,stonebrick)
Block(-2,28,-5,stonebrick)
Block(-2,28,-4,stonebrick)
Block(-2,28,-3,stonebrick)
Block(-2,28,-2,stonebrick)
Block(-2,28,-1,stonebrick)
Block(-2,28,0,log)
Block(-2,29,-7,log)
Block(-2,29,-6,stonebrick)
Block(-2,29,-5,stonebrick)
Block(-2,29,-4,stonebrick)
Block(-2,29,-3,stonebrick)
Block(-2,29,-2,stonebrick)
Block(-2,29,-1,stonebrick)
Block(-2,29,0,log)
Block(-2,30,-7,log)
Block(-2,30,-6,stonebrick)
Block(-2,30,-1,stonebrick)
Block(-2,30,0,log)
Block(-2,31,-7,stone_brick_stairs:2)
Block(-2,31,-6,log)
Block(-2,31,-3,dark_oak_stairs:6)
Block(-2,31,-2,dark_oak_stairs:4)
Block(-2,31,-1,log)
Block(-2,31,0,stone_brick_STAIRS:0)
Block(-2,32,-6,log)
Block(-2,32,-4,dark_oak_stairs:6)
Block(-2,32,-3,dark_oak_STAIRS:0)
Block(-2,32,-1,log)
Block(-2,33,-7,stone_slab:11)
Block(-2,33,-6,log)
Block(-2,33,-5,wooden_slab:13)
Block(-2,33,-4,dark_oak_STAIRS:0)
Block(-2,33,-1,log)
Block(-2,33,0,stone_slab:11)
Block(-2,34,-8,stone_brick_stairs:6)
Block(-2,34,-7,log:8)
Block(-2,34,-6,log)
Block(-2,34,-1,log)
Block(-2,34,0,log:8)
Block(-2,34,1,stone_brick_stairs:7)
Block(-2,35,-8,stone_brick_stairs:1)
Block(-2,35,-6,wooden_slab:5)
Block(-2,35,-1,wooden_slab:5)
Block(-2,35,1,stone_brick_stairs:1)
Block(-1,1,-8,cobblestone)
Block(-1,1,-7,cobblestone)
Block(-1,1,0,cobblestone)
Block(-1,1,3,cobblestone)
Block(-1,2,-7,cobblestone)
Block(-1,2,0,cobblestone)
Block(-1,2,3,cobblestone)
Block(-1,3,-7,cobblestone)
Block(-1,3,0,cobblestone)
Block(-1,3,3,cobblestone)
Block(-1,4,-7,cobblestone)
Block(-1,4,0,cobblestone)
Block(-1,4,3,cobblestone)
Block(-1,5,-7,cobblestone)
Block(-1,5,0,cobblestone)
Block(-1,5,3,cobblestone)
Block(-1,6,-7,cobblestone)
Block(-1,6,0,cobblestone)
Block(-1,6,3,cobblestone)
Block(-1,7,-7,cobblestone)
Block(-1,7,0,cobblestone)
Block(-1,7,3,cobblestone)
Block(-1,8,-7,cobblestone)
Block(-1,8,0,cobblestone)
Block(-1,8,3,cobblestone)
Block(-1,9,-7,cobblestone)
Block(-1,9,0,cobblestone)
Block(-1,9,3,cobblestone)
Block(-1,10,-7,cobblestone)
Block(-1,10,0,cobblestone)
Block(-1,10,3,cobblestone)
Block(-1,11,-7,cobblestone)
Block(-1,11,0,cobblestone)
Block(-1,11,1,cobblestone)
Block(-1,11,2,cobblestone)
Block(-1,11,3,cobblestone)
Block(-1,12,-7,cobblestone)
Block(-1,12,0,cobblestone)
Block(-1,12,1,stone:6)
Block(-1,12,2,stone:6)
Block(-1,12,3,stone_STAIRS:0)
Block(-1,13,-7,stone:6)
Block(-1,13,0,stone:6)
Block(-1,13,1,stone:6)
Block(-1,13,2,stone:6)
Block(-1,14,-7,stone:6)
Block(-1,14,0,stone:6)
Block(-1,14,1,stone:6)
Block(-1,14,2,stone:6)
Block(-1,15,-7,stone:6)
Block(-1,15,0,stone:6)
Block(-1,15,1,stone:6)
Block(-1,15,2,stone:6)
Block(-1,16,-7,stone:6)
Block(-1,16,0,stone:6)
Block(-1,16,1,stone:6)
Block(-1,16,2,stone_STAIRS:0)
Block(-1,17,-7,stone:6)
Block(-1,17,0,stone:6)
Block(-1,18,-7,stone:6)
Block(-1,18,0,stone:6)
Block(-1,19,-7,stone:6)
Block(-1,19,0,stone:6)
Block(-1,20,-7,stone:6)
Block(-1,20,0,stone:6)
Block(-1,21,-8,stone:6)
Block(-1,21,-7,stone:6)
Block(-1,21,0,stone:6)
Block(-1,22,-8,cobblestone)
Block(-1,22,-7,stone:6)
Block(-1,22,0,stone:6)
Block(-1,23,-8,cobblestone)
Block(-1,23,-7,stone:6)
Block(-1,23,0,stone:6)
Block(-1,24,-8,cobblestone)
Block(-1,24,-7,stone:6)
Block(-1,24,-6,stonebrick)
Block(-1,24,-5,stonebrick)
Block(-1,24,-4,stonebrick)
Block(-1,24,-3,stonebrick)
Block(-1,24,-2,stonebrick)
Block(-1,24,-1,stonebrick)
Block(-1,24,0,stone:6)
Block(-1,25,-8,cobblestone)
Block(-1,25,-7,stone:6)
Block(-1,25,-6,stonebrick)
Block(-1,25,-5,stonebrick)
Block(-1,25,-4,stonebrick)
Block(-1,25,-3,stonebrick)
Block(-1,25,-2,stonebrick)
Block(-1,25,-1,stonebrick)
Block(-1,25,0,stone:6)
Block(-1,26,-8,stonebrick)
Block(-1,26,-7,stonebrick)
Block(-1,26,-6,stonebrick)
Block(-1,26,-5,stonebrick)
Block(-1,26,-4,stonebrick)
Block(-1,26,-3,stonebrick)
Block(-1,26,-2,stonebrick)
Block(-1,26,-1,stonebrick)
Block(-1,26,0,stone:6)
Block(-1,27,-8,stonebrick)
Block(-1,27,-7,stonebrick)
Block(-1,27,-6,stonebrick)
Block(-1,27,-5,stonebrick)
Block(-1,27,-4,stonebrick)
Block(-1,27,-3,stonebrick)
Block(-1,27,-2,stonebrick)
Block(-1,27,-1,stonebrick)
Block(-1,27,0,stone:6)
Block(-1,28,-8,stonebrick)
Block(-1,28,-7,stonebrick)
Block(-1,28,-6,stonebrick)
Block(-1,28,-5,stonebrick)
Block(-1,28,-4,stonebrick)
Block(-1,28,-3,stonebrick)
Block(-1,28,-2,stonebrick)
Block(-1,28,-1,stonebrick)
Block(-1,28,0,stone:6)
Block(-1,29,-8,stonebrick)
Block(-1,29,-7,log:4)
Block(-1,29,-6,stonebrick)
Block(-1,29,-5,stonebrick)
Block(-1,29,-4,stonebrick)
Block(-1,29,-3,stonebrick)
Block(-1,29,-2,stonebrick)
Block(-1,29,-1,stonebrick)
Block(-1,29,0,stone:6)
Block(-1,30,-4,dark_oak_stairs:2)
Block(-1,30,-3,dark_oak_stairs:7)
Block(-1,30,0,log:4)
Block(-1,31,-3,dark_oak_stairs:2)
Block(-1,31,-2,dark_oak_stairs:7)
Block(-1,31,0,dark_oak_stairs:5)
Block(-1,32,-6,dark_oak_stairs:2)
Block(-1,32,-1,dark_oak_STAIRS:0)
Block(-1,33,-6,dark_oak_stairs:6)
Block(-1,33,-5,wooden_slab:13)
Block(-1,33,-1,dark_oak_stairs:7)
Block(-1,34,-8,wooden_slab:13)
Block(-1,34,-7,stone_slab:3)
Block(-1,34,0,stone_slab:3)
Block(-1,34,1,wooden_slab:13)
Block(-1,35,-8,stone_stairs:0)
Block(-1,35,1,stone_stairs:0)
Block(-1,36,-8,wooden_slab:5)
Block(-1,36,1,wooden_slab:5)
Block(0,1,-8,cobblestone)
Block(0,1,-7,cobblestone)
Block(0,1,0,cobblestone)
Block(0,1,3,cobblestone)
Block(0,2,-7,cobblestone)
Block(0,2,0,cobblestone)
Block(0,2,3,cobblestone)
Block(0,3,-7,cobblestone)
Block(0,3,0,cobblestone)
Block(0,3,3,cobblestone)
Block(0,4,-7,cobblestone)
Block(0,4,0,cobblestone)
Block(0,4,3,cobblestone)
Block(0,5,-7,cobblestone)
Block(0,5,0,cobblestone)
Block(0,5,3,cobblestone)
Block(0,6,-7,cobblestone)
Block(0,6,0,cobblestone)
Block(0,6,3,cobblestone)
Block(0,7,-7,cobblestone)
Block(0,7,0,cobblestone)
Block(0,7,3,cobblestone)
Block(0,8,-7,cobblestone)
Block(0,8,0,cobblestone)
Block(0,8,3,cobblestone)
Block(0,9,-7,cobblestone)
Block(0,9,0,cobblestone)
Block(0,9,3,cobblestone)
Block(0,10,-7,cobblestone)
Block(0,10,0,cobblestone)
Block(0,10,3,cobblestone)
Block(0,11,-7,cobblestone)
Block(0,11,0,cobblestone)
Block(0,11,1,cobblestone)
Block(0,11,2,cobblestone)
Block(0,11,3,cobblestone)
Block(0,12,-7,cobblestone)
Block(0,12,0,cobblestone)
Block(0,12,1,stone:6)
Block(0,12,2,stone:6)
Block(0,12,3,stone_STAIRS:0)
Block(0,13,-7,stone:6)
Block(0,13,0,stone:6)
Block(0,13,1,stone:6)
Block(0,13,2,stone:6)
Block(0,14,-7,stone:6)
Block(0,14,0,stone:6)
Block(0,14,1,stone:6)
Block(0,14,2,stone:6)
Block(0,15,-7,stone:6)
Block(0,15,0,stone:6)
Block(0,15,1,stone:6)
Block(0,15,2,stone:6)
Block(0,16,-7,stone:6)
Block(0,16,0,stone:6)
Block(0,16,1,stone:6)
Block(0,16,2,stone_STAIRS:0)
Block(0,17,-7,stone:6)
Block(0,17,0,stone:6)
Block(0,18,-7,stone:6)
Block(0,18,0,stone:6)
Block(0,19,-7,stone:6)
Block(0,19,0,stone:6)
Block(0,20,-7,stone:6)
Block(0,20,0,stone:6)
Block(0,21,-8,stone:6)
Block(0,21,-7,stone:6)
Block(0,21,0,stone:6)
Block(0,22,-8,cobblestone)
Block(0,22,-7,stone:6)
Block(0,22,0,stone:6)
Block(0,23,-8,cobblestone)
Block(0,23,-7,stone:6)
Block(0,23,0,stone:6)
Block(0,24,-8,cobblestone)
Block(0,24,-7,stone:6)
Block(0,24,-6,stonebrick)
Block(0,24,-5,stonebrick)
Block(0,24,-4,stonebrick)
Block(0,24,-3,stonebrick)
Block(0,24,-2,stonebrick)
Block(0,24,-1,stonebrick)
Block(0,24,0,stone:6)
Block(0,25,-8,cobblestone)
Block(0,25,-7,stone:6)
Block(0,25,-6,stonebrick)
Block(0,25,-5,stonebrick)
Block(0,25,-4,stonebrick)
Block(0,25,-3,stonebrick)
Block(0,25,-2,stonebrick)
Block(0,25,-1,stonebrick)
Block(0,25,0,stone:6)
Block(0,26,-8,stonebrick)
Block(0,26,-7,stone:6)
Block(0,26,-6,stonebrick)
Block(0,26,-5,stonebrick)
Block(0,26,-4,stonebrick)
Block(0,26,-3,stonebrick)
Block(0,26,-2,stonebrick)
Block(0,26,-1,stonebrick)
Block(0,26,0,stone:6)
Block(0,27,-8,stonebrick)
Block(0,27,-7,stone:6)
Block(0,27,-6,stonebrick)
Block(0,27,-5,stonebrick)
Block(0,27,-4,stonebrick)
Block(0,27,-3,stonebrick)
Block(0,27,-2,stonebrick)
Block(0,27,-1,stonebrick)
Block(0,27,0,stone:6)
Block(0,28,-8,stonebrick)
Block(0,28,-7,stone:6)
Block(0,28,-6,stonebrick)
Block(0,28,-5,stonebrick)
Block(0,28,-4,stonebrick)
Block(0,28,-3,stonebrick)
Block(0,28,-2,stonebrick)
Block(0,28,-1,stonebrick)
Block(0,28,0,stone:6)
Block(0,29,-8,stonebrick)
Block(0,29,-7,log:4)
Block(0,29,-6,stonebrick)
Block(0,29,-5,stonebrick)
Block(0,29,-4,stonebrick)
Block(0,29,-3,stonebrick)
Block(0,29,-2,stonebrick)
Block(0,29,-1,stonebrick)
Block(0,29,0,stone:6)
Block(0,30,0,log:4)
Block(0,31,0,dark_oak_stairs:4)
Block(0,32,-6,dark_oak_stairs:2)
Block(0,32,-1,dark_oak_STAIRS:0)
Block(0,33,-6,dark_oak_stairs:6)
Block(0,33,-5,wooden_slab:13)
Block(0,33,-4,wooden_slab:13)
Block(0,33,-3,wooden_slab:13)
Block(0,33,-2,wooden_slab:13)
Block(0,33,-1,dark_oak_stairs:7)
Block(0,34,-8,wooden_slab:13)
Block(0,34,-7,stone_slab:3)
Block(0,34,0,stone_slab:3)
Block(0,34,1,wooden_slab:13)
Block(0,35,-8,stone_stairs:1)
Block(0,35,1,stone_stairs:1)
Block(0,36,-8,wooden_slab:5)
Block(0,36,1,wooden_slab:5)
Block(1,1,-8,cobblestone)
Block(1,1,-7,log)
Block(1,1,0,log)
Block(1,1,3,log)
Block(1,2,-7,log)
Block(1,2,0,log)
Block(1,2,3,log)
Block(1,3,-7,log)
Block(1,3,0,log)
Block(1,3,3,log)
Block(1,4,-7,log)
Block(1,4,0,log)
Block(1,4,3,log)
Block(1,5,-7,log)
Block(1,5,0,log)
Block(1,5,3,log)
Block(1,6,-7,log)
Block(1,6,0,log)
Block(1,6,3,log)
Block(1,7,-7,log)
Block(1,7,0,log)
Block(1,7,3,log)
Block(1,8,-7,log)
Block(1,8,0,log)
Block(1,8,3,log)
Block(1,9,-7,log)
Block(1,9,0,log)
Block(1,9,3,log)
Block(1,10,-7,log)
Block(1,10,0,log)
Block(1,10,3,log)
Block(1,11,-7,log)
Block(1,11,0,log)
Block(1,11,1,cobblestone)
Block(1,11,2,cobblestone)
Block(1,11,3,log)
Block(1,12,-7,log)
Block(1,12,0,log)
Block(1,12,1,log:8)
Block(1,12,2,log:8)
Block(1,12,3,stone_brick_STAIRS:0)
Block(1,13,-7,log)
Block(1,13,0,log)
Block(1,13,2,log)
Block(1,14,-7,log)
Block(1,14,0,log)
Block(1,14,2,log)
Block(1,15,-7,log)
Block(1,15,0,log)
Block(1,15,2,log)
Block(1,16,-7,log)
Block(1,16,0,log)
Block(1,16,2,log)
Block(1,17,-7,log)
Block(1,17,0,log)
Block(1,17,1,log:8)
Block(1,17,2,stone_STAIRS:0)
Block(1,18,-7,log)
Block(1,18,0,log)
Block(1,19,-7,log)
Block(1,19,0,log)
Block(1,20,-7,log)
Block(1,20,0,log)
Block(1,21,-8,stone:6)
Block(1,21,-7,log)
Block(1,21,0,log)
Block(1,22,-8,cobblestone)
Block(1,22,-7,log)
Block(1,22,0,log)
Block(1,23,-8,cobblestone)
Block(1,23,-7,log)
Block(1,23,0,log)
Block(1,24,-8,cobblestone)
Block(1,24,-7,log)
Block(1,24,-6,stonebrick)
Block(1,24,-5,stonebrick)
Block(1,24,-4,stonebrick)
Block(1,24,-3,stonebrick)
Block(1,24,-2,stonebrick)
Block(1,24,-1,stonebrick)
Block(1,24,0,log)
Block(1,25,-8,cobblestone)
Block(1,25,-7,log)
Block(1,25,-6,stonebrick)
Block(1,25,-5,stonebrick)
Block(1,25,-4,stonebrick)
Block(1,25,-3,stonebrick)
Block(1,25,-2,stonebrick)
Block(1,25,-1,stonebrick)
Block(1,25,0,log)
Block(1,26,-8,log)
Block(1,26,-7,log)
Block(1,26,-6,stonebrick)
Block(1,26,-5,stonebrick)
Block(1,26,-4,stonebrick)
Block(1,26,-3,stonebrick)
Block(1,26,-2,stonebrick)
Block(1,26,-1,stonebrick)
Block(1,26,0,log)
Block(1,27,-8,log)
Block(1,27,-7,log)
Block(1,27,-6,stonebrick)
Block(1,27,-5,stonebrick)
Block(1,27,-4,stonebrick)
Block(1,27,-3,stonebrick)
Block(1,27,-2,stonebrick)
Block(1,27,-1,stonebrick)
Block(1,27,0,log)
Block(1,28,-8,log)
Block(1,28,-7,log)
Block(1,28,-6,stonebrick)
Block(1,28,-5,stonebrick)
Block(1,28,-4,stonebrick)
Block(1,28,-3,stonebrick)
Block(1,28,-2,stonebrick)
Block(1,28,-1,stonebrick)
Block(1,28,0,log)
Block(1,29,-8,stone:6)
Block(1,29,-7,log)
Block(1,29,-6,stonebrick)
Block(1,29,-5,stonebrick)
Block(1,29,-4,stonebrick)
Block(1,29,-3,stonebrick)
Block(1,29,-2,stonebrick)
Block(1,29,-1,stonebrick)
Block(1,29,0,log)
Block(1,30,-8,stone_brick_stairs:0)
Block(1,30,-7,log)
Block(1,30,-6,stonebrick)
Block(1,30,-5,dark_oak_fence)
Block(1,30,-1,stonebrick)
Block(1,30,0,log)
Block(1,31,-7,stone_brick_stairs:2)
Block(1,31,-6,log)
Block(1,31,-5,torch)
Block(1,31,-1,log)
Block(1,31,0,stone_brick_STAIRS:0)
Block(1,32,-6,log)
Block(1,32,-1,log)
Block(1,33,-7,stone_slab:11)
Block(1,33,-6,log)
Block(1,33,-5,wooden_slab:13)
Block(1,33,-4,wooden_slab:13)
Block(1,33,-3,wooden_slab:13)
Block(1,33,-2,wooden_slab:13)
Block(1,33,-1,log)
Block(1,33,0,stone_slab:11)
Block(1,34,-8,stone_brick_stairs:6)
Block(1,34,-7,log:8)
Block(1,34,-6,log)
Block(1,34,-2,dark_oak_fence)
Block(1,34,-1,log)
Block(1,34,0,log:8)
Block(1,34,1,stone_brick_stairs:7)
Block(1,35,-8,stone_brick_stairs:0)
Block(1,35,-6,wooden_slab:5)
Block(1,35,-2,torch)
Block(1,35,-1,wooden_slab:5)
Block(1,35,1,stone_brick_stairs:0)
Block(2,1,-8,cobblestone)
Block(2,1,-7,cobblestone)
Block(2,1,-6,cobblestone)
Block(2,1,-1,cobblestone)
Block(2,1,3,cobblestone)
Block(2,2,-7,cobblestone)
Block(2,2,-6,cobblestone)
Block(2,2,-1,cobblestone)
Block(2,2,3,cobblestone)
Block(2,3,-7,cobblestone)
Block(2,3,-6,cobblestone)
Block(2,3,-1,cobblestone)
Block(2,3,3,cobblestone)
Block(2,4,-7,cobblestone)
Block(2,4,-6,cobblestone)
Block(2,4,-1,cobblestone)
Block(2,4,3,cobblestone)
Block(2,5,-7,cobblestone)
Block(2,5,-6,cobblestone)
Block(2,5,-1,cobblestone)
Block(2,5,3,cobblestone)
Block(2,6,-7,cobblestone)
Block(2,6,-6,cobblestone)
Block(2,6,-1,cobblestone)
Block(2,6,3,cobblestone)
Block(2,7,-7,cobblestone)
Block(2,7,-6,cobblestone)
Block(2,7,-1,cobblestone)
Block(2,7,3,cobblestone)
Block(2,8,-7,cobblestone)
Block(2,8,-6,cobblestone)
Block(2,8,-1,cobblestone)
Block(2,8,3,cobblestone)
Block(2,9,-7,cobblestone)
Block(2,9,-6,cobblestone)
Block(2,9,-1,cobblestone)
Block(2,9,3,cobblestone)
Block(2,10,-7,cobblestone)
Block(2,10,-6,cobblestone)
Block(2,10,-1,cobblestone)
Block(2,10,3,cobblestone)
Block(2,11,-7,cobblestone)
Block(2,11,-6,cobblestone)
Block(2,11,-1,cobblestone)
Block(2,11,0,cobblestone)
Block(2,11,1,cobblestone)
Block(2,11,2,cobblestone)
Block(2,11,3,cobblestone)
Block(2,12,-7,cobblestone)
Block(2,12,-6,cobblestone)
Block(2,12,-1,cobblestone)
Block(2,12,0,stone:6)
Block(2,12,1,stone:6)
Block(2,12,2,stone_stairs:1)
Block(2,12,3,stone_STAIRS:0)
Block(2,13,-7,stone:6)
Block(2,13,-6,stone:6)
Block(2,13,-1,stone:6)
Block(2,13,0,stone:6)
Block(2,13,1,stone:6)
Block(2,14,-7,stone:6)
Block(2,14,-6,stone:6)
Block(2,14,-1,stone:6)
Block(2,14,0,stone:6)
Block(2,14,1,stone:6)
Block(2,15,-7,stone:6)
Block(2,15,-6,stone:6)
Block(2,15,-1,stone:6)
Block(2,15,0,stone:6)
Block(2,15,1,stone:6)
Block(2,16,-7,stone:6)
Block(2,16,-6,stone:6)
Block(2,16,-1,stone:6)
Block(2,16,0,stone:6)
Block(2,16,1,stone_STAIRS:0)
Block(2,17,-7,stone:6)
Block(2,17,-6,stone:6)
Block(2,17,-1,stone:6)
Block(2,18,-7,stone:6)
Block(2,18,-6,stone:6)
Block(2,18,-1,stone:6)
Block(2,19,-7,stone:6)
Block(2,19,-6,stone:6)
Block(2,19,-1,stone:6)
Block(2,20,-7,stone:6)
Block(2,20,-6,stone:6)
Block(2,20,-1,stone:6)
Block(2,21,-8,stone:6)
Block(2,21,-7,stone:6)
Block(2,21,-6,stone:6)
Block(2,21,-1,stone:6)
Block(2,22,-8,cobblestone)
Block(2,22,-7,stone:6)
Block(2,22,-6,stone:6)
Block(2,22,-1,stone:6)
Block(2,23,-8,cobblestone)
Block(2,23,-7,stone:6)
Block(2,23,-6,stone:6)
Block(2,23,-1,stone:6)
Block(2,24,-8,cobblestone)
Block(2,24,-7,stone:6)
Block(2,24,-6,stone:6)
Block(2,24,-5,stonebrick)
Block(2,24,-4,stonebrick)
Block(2,24,-3,stonebrick)
Block(2,24,-2,stonebrick)
Block(2,24,-1,stone:6)
Block(2,25,-8,cobblestone)
Block(2,25,-7,stone:6)
Block(2,25,-6,stone:6)
Block(2,25,-5,stonebrick)
Block(2,25,-4,stonebrick)
Block(2,25,-3,stonebrick)
Block(2,25,-2,stonebrick)
Block(2,25,-1,stone:6)
Block(2,26,-7,stone:6)
Block(2,26,-6,stone:6)
Block(2,26,-5,stonebrick)
Block(2,26,-4,stonebrick)
Block(2,26,-3,stonebrick)
Block(2,26,-2,stonebrick)
Block(2,26,-1,stone:6)
Block(2,27,-8,log:4)
Block(2,27,-7,dark_oak_fence)
Block(2,27,-6,stone:6)
Block(2,27,-5,stonebrick)
Block(2,27,-4,stonebrick)
Block(2,27,-3,stonebrick)
Block(2,27,-2,stonebrick)
Block(2,27,-1,stone:6)
Block(2,28,-8,stone_stairs:5)
Block(2,28,-7,stone_stairs:5)
Block(2,28,-6,stone:6)
Block(2,28,-5,stonebrick)
Block(2,28,-4,stonebrick)
Block(2,28,-3,stonebrick)
Block(2,28,-2,stonebrick)
Block(2,28,-1,stone:6)
Block(2,29,-8,stone:6)
Block(2,29,-7,stonebrick)
Block(2,29,-6,stone:6)
Block(2,29,-5,stonebrick)
Block(2,29,-4,stonebrick)
Block(2,29,-3,stonebrick)
Block(2,29,-2,stonebrick)
Block(2,29,-1,stone:6)
Block(2,30,-8,stone:6)
Block(2,30,-7,stonebrick)
Block(2,30,-6,stone:6)
Block(2,30,-5,stonebrick)
Block(2,30,-2,stonebrick)
Block(2,30,-1,stone:6)
Block(2,31,-6,stone:6)
Block(2,31,-5,log)
Block(2,31,-2,log)
Block(2,31,-1,stone:6)
Block(2,32,-6,cobblestone_wall)
Block(2,32,-5,log)
Block(2,32,-4,dark_oak_stairs:1)
Block(2,32,-3,dark_oak_stairs:1)
Block(2,32,-2,log)
Block(2,32,-1,cobblestone_wall)
Block(2,33,-6,cobblestone_wall)
Block(2,33,-5,log)
Block(2,33,-4,dark_oak_stairs:5)
Block(2,33,-3,dark_oak_stairs:5)
Block(2,33,-2,log)
Block(2,33,-1,cobblestone_wall)
Block(2,34,-7,stone_brick_stairs:5)
Block(2,34,-6,cobblestone_wall)
Block(2,34,-5,log)
Block(2,34,-2,log)
Block(2,34,-1,cobblestone_wall)
Block(2,34,0,stone_brick_stairs:5)
Block(2,35,-8,stone_brick_stairs:5)
Block(2,35,-5,wooden_slab:5)
Block(2,35,-2,wooden_slab:5)
Block(2,35,1,stone_brick_stairs:5)
Block(2,36,-8,wooden_slab:5)
Block(2,36,1,wooden_slab:5)
Block(3,1,-8,log)
Block(3,1,-5,log)
Block(3,1,-4,cobblestone)
Block(3,1,-3,cobblestone)
Block(3,1,-2,log)
Block(3,1,2,log)
Block(3,2,-8,log)
Block(3,2,-5,log)
Block(3,2,-4,cobblestone)
Block(3,2,-3,cobblestone)
Block(3,2,-2,log)
Block(3,2,2,log)
Block(3,3,-8,log)
Block(3,3,-5,log)
Block(3,3,-4,cobblestone)
Block(3,3,-3,cobblestone)
Block(3,3,-2,log)
Block(3,3,2,log)
Block(3,4,-8,log)
Block(3,4,-5,log)
Block(3,4,-4,cobblestone)
Block(3,4,-3,cobblestone)
Block(3,4,-2,log)
Block(3,4,2,log)
Block(3,5,-8,log)
Block(3,5,-5,log)
Block(3,5,-4,cobblestone)
Block(3,5,-3,cobblestone)
Block(3,5,-2,log)
Block(3,5,2,log)
Block(3,6,-8,log)
Block(3,6,-5,log)
Block(3,6,-4,cobblestone)
Block(3,6,-3,cobblestone)
Block(3,6,-2,log)
Block(3,6,2,log)
Block(3,7,-8,log)
Block(3,7,-5,log)
Block(3,7,-4,cobblestone)
Block(3,7,-3,cobblestone)
Block(3,7,-2,log)
Block(3,7,2,log)
Block(3,8,-8,log)
Block(3,8,-5,log)
Block(3,8,-4,cobblestone)
Block(3,8,-3,cobblestone)
Block(3,8,-2,log)
Block(3,8,2,log)
Block(3,9,-8,log)
Block(3,9,-5,log)
Block(3,9,-4,cobblestone)
Block(3,9,-3,cobblestone)
Block(3,9,-2,log)
Block(3,9,2,log)
Block(3,10,-8,log)
Block(3,10,-5,log)
Block(3,10,-4,cobblestone)
Block(3,10,-3,cobblestone)
Block(3,10,-2,log)
Block(3,10,2,log)
Block(3,11,-8,log)
Block(3,11,-7,cobblestone)
Block(3,11,-6,cobblestone)
Block(3,11,-5,log)
Block(3,11,-4,cobblestone)
Block(3,11,-3,cobblestone)
Block(3,11,-2,log)
Block(3,11,-1,cobblestone)
Block(3,11,0,cobblestone)
Block(3,11,1,cobblestone)
Block(3,11,2,log)
Block(3,12,-8,log)
Block(3,12,-7,stone:6)
Block(3,12,-6,stone:6)
Block(3,12,-5,log)
Block(3,12,-4,cobblestone)
Block(3,12,-3,cobblestone)
Block(3,12,-2,log)
Block(3,12,-1,stone:6)
Block(3,12,0,stone:6)
Block(3,12,1,stone_stairs:1)
Block(3,12,2,stone_STAIRS:0)
Block(3,13,-8,log)
Block(3,13,-7,stone:6)
Block(3,13,-6,stone:6)
Block(3,13,-5,log)
Block(3,13,-4,stone:6)
Block(3,13,-3,stone:6)
Block(3,13,-2,log)
Block(3,13,-1,stone:6)
Block(3,13,0,stone:6)
Block(3,14,-8,log)
Block(3,14,-7,stone:6)
Block(3,14,-6,stone:6)
Block(3,14,-5,log)
Block(3,14,-4,stone:6)
Block(3,14,-3,stone:6)
Block(3,14,-2,log)
Block(3,14,-1,stone:6)
Block(3,14,0,stone:6)
Block(3,15,-8,log)
Block(3,15,-7,stone:6)
Block(3,15,-6,stone:6)
Block(3,15,-5,log)
Block(3,15,-4,stone:6)
Block(3,15,-3,stone:6)
Block(3,15,-2,log)
Block(3,15,-1,stone:6)
Block(3,15,0,stone:6)
Block(3,16,-8,log)
Block(3,16,-7,stone:6)
Block(3,16,-6,stone:6)
Block(3,16,-5,log)
Block(3,16,-4,stone:6)
Block(3,16,-3,stone:6)
Block(3,16,-2,log)
Block(3,16,-1,stone:6)
Block(3,16,0,stone:6)
Block(3,17,-8,log)
Block(3,17,-7,stone:6)
Block(3,17,-6,stone:6)
Block(3,17,-5,log)
Block(3,17,-4,stone:6)
Block(3,17,-3,stone:6)
Block(3,17,-2,log)
Block(3,18,-8,log)
Block(3,18,-7,stone:6)
Block(3,18,-6,stone:6)
Block(3,18,-5,log)
Block(3,18,-4,stone:6)
Block(3,18,-3,stone:6)
Block(3,18,-2,log)
Block(3,19,-8,log)
Block(3,19,-7,stone:6)
Block(3,19,-6,stone:6)
Block(3,19,-5,log)
Block(3,19,-4,stone:6)
Block(3,19,-3,stone:6)
Block(3,19,-2,log)
Block(3,20,-8,log)
Block(3,20,-7,stone:6)
Block(3,20,-6,stone:6)
Block(3,20,-5,log)
Block(3,20,-4,stone:6)
Block(3,20,-3,stone:6)
Block(3,20,-2,log)
Block(3,21,-8,log)
Block(3,21,-7,stone:6)
Block(3,21,-6,stone:6)
Block(3,21,-5,log)
Block(3,21,-4,stone:6)
Block(3,21,-3,stone:6)
Block(3,21,-2,log)
Block(3,22,-8,log)
Block(3,22,-7,stone:6)
Block(3,22,-6,stone:6)
Block(3,22,-5,log)
Block(3,22,-4,stone:6)
Block(3,22,-3,stone:6)
Block(3,22,-2,log)
Block(3,23,-8,log)
Block(3,23,-7,stone:6)
Block(3,23,-6,stone:6)
Block(3,23,-5,log)
Block(3,23,-4,stone:6)
Block(3,23,-3,stone:6)
Block(3,23,-2,log)
Block(3,24,-8,log)
Block(3,24,-7,stone_stairs:1)
Block(3,24,-6,stone_stairs:1)
Block(3,24,-5,log)
Block(3,24,-4,stone:6)
Block(3,24,-3,stone:6)
Block(3,24,-2,log)
Block(3,25,-8,log)
Block(3,25,-5,log)
Block(3,25,-4,stone:6)
Block(3,25,-3,stone:6)
Block(3,25,-2,log)
Block(3,26,-8,log)
Block(3,26,-5,log)
Block(3,26,-4,stone:6)
Block(3,26,-3,stone:6)
Block(3,26,-2,log)
Block(3,27,-8,stone_brick_stairs:1)
Block(3,27,-5,log)
Block(3,27,-4,stone:6)
Block(3,27,-3,stone:6)
Block(3,27,-2,log)
Block(3,28,-5,log)
Block(3,28,-4,stone:6)
Block(3,28,-3,stone:6)
Block(3,28,-2,log)
Block(3,29,-5,log)
Block(3,29,-4,stone:6)
Block(3,29,-3,stone:6)
Block(3,29,-2,log)
Block(3,30,-8,dark_oak_stairs:5)
Block(3,30,-7,dark_oak_stairs:7)
Block(3,30,-5,log)
Block(3,30,-4,log:8)
Block(3,30,-3,log:8)
Block(3,30,-2,log)
Block(3,31,-8,stonebrick)
Block(3,31,-7,dark_oak_stairs:2)
Block(3,31,-5,stone_brick_stairs:1)
Block(3,31,-4,dark_oak_stairs:7)
Block(3,31,-3,dark_oak_stairs:6)
Block(3,31,-2,stone_brick_stairs:1)
Block(3,32,-8,wooden_slab:5)
Block(3,33,-7,stone_slab:11)
Block(3,33,-5,stone_slab:11)
Block(3,33,-2,stone_slab:11)
Block(3,33,0,stone_slab:11)
Block(3,34,-7,double_wooden_slab:5)
Block(3,34,-6,stone_brick_stairs:6)
Block(3,34,-5,log:4)
Block(3,34,-4,stone_slab:3)
Block(3,34,-3,stone_slab:3)
Block(3,34,-2,log:4)
Block(3,34,-1,stone_brick_stairs:7)
Block(3,34,0,double_wooden_slab:5)
Block(3,35,-7,stone_slab:3)
Block(3,35,0,stone_slab:3)
Block(4,1,1,cobblestone)
Block(4,2,1,cobblestone)
Block(4,3,1,cobblestone)
Block(4,4,1,cobblestone)
Block(4,5,1,cobblestone)
Block(4,6,1,cobblestone)
Block(4,7,1,cobblestone)
Block(4,8,1,cobblestone)
Block(4,9,1,cobblestone)
Block(4,10,1,cobblestone)
Block(4,11,-8,cobblestone)
Block(4,11,-7,cobblestone)
Block(4,11,-6,cobblestone)
Block(4,11,-5,cobblestone)
Block(4,11,-4,cobblestone)
Block(4,11,-3,cobblestone)
Block(4,11,-2,cobblestone)
Block(4,11,-1,cobblestone)
Block(4,11,0,cobblestone)
Block(4,11,1,cobblestone)
Block(4,12,-8,log:4)
Block(4,12,-7,stone:6)
Block(4,12,-6,stone:6)
Block(4,12,-5,log:4)
Block(4,12,-4,stone:6)
Block(4,12,-3,stone:6)
Block(4,12,-2,log:4)
Block(4,12,-1,stone:6)
Block(4,12,0,stone_stairs:1)
Block(4,12,1,stone_STAIRS:0)
Block(4,13,-7,stone:6)
Block(4,13,-6,stone:6)
Block(4,13,-4,stone:6)
Block(4,13,-3,stone:6)
Block(4,13,-1,stone:6)
Block(4,14,-7,stone:6)
Block(4,14,-6,stone:6)
Block(4,14,-4,stone:6)
Block(4,14,-3,stone:6)
Block(4,14,-1,stone:6)
Block(4,15,-7,stone:6)
Block(4,15,-6,stone:6)
Block(4,15,-4,stone:6)
Block(4,15,-3,stone:6)
Block(4,15,-1,stone:6)
Block(4,16,-7,stone:6)
Block(4,16,-6,stone:6)
Block(4,16,-4,stone:6)
Block(4,16,-3,stone:6)
Block(4,16,-1,stone_stairs:1)
Block(4,17,-8,log:4)
Block(4,17,-7,stone:6)
Block(4,17,-6,stone:6)
Block(4,17,-5,log:4)
Block(4,17,-4,stone:6)
Block(4,17,-3,stone:6)
Block(4,17,-2,log:4)
Block(4,18,-7,stone:6)
Block(4,18,-6,stone:6)
Block(4,18,-4,stone:6)
Block(4,18,-3,stone:6)
Block(4,19,-7,stone:6)
Block(4,19,-6,stone:6)
Block(4,19,-4,stone:6)
Block(4,19,-3,stone:6)
Block(4,20,-7,stone_stairs:1)
Block(4,20,-6,stone_stairs:1)
Block(4,20,-4,stone_stairs:1)
Block(4,20,-3,stone_stairs:1)
Block(4,34,-5,stone_brick_stairs:5)
Block(4,34,-4,wooden_slab:13)
Block(4,34,-3,wooden_slab:13)
Block(4,34,-2,stone_brick_stairs:5)
Block(4,35,-6,stone_brick_stairs:6)
Block(4,35,-5,stone_brick_STAIRS:0)
Block(4,35,-4,stone_stairs:2)
Block(4,35,-3,stone_STAIRS:0)
Block(4,35,-2,stone_brick_stairs:2)
Block(4,35,-1,stone_brick_stairs:7)
Block(4,36,-6,wooden_slab:5)
Block(4,36,-4,wooden_slab:5)
Block(4,36,-3,wooden_slab:5)
Block(4,36,-1,wooden_slab:5)
Block(5,1,-1,cobblestone)
Block(5,1,0,log)
Block(5,2,-1,cobblestone)
Block(5,2,0,log)
Block(5,3,-1,cobblestone)
Block(5,3,0,log)
Block(5,4,-1,cobblestone)
Block(5,4,0,log)
Block(5,5,-1,cobblestone)
Block(5,5,0,log)
Block(5,6,-1,cobblestone)
Block(5,6,0,log)
Block(5,7,-1,cobblestone)
Block(5,7,0,log)
Block(5,8,-1,cobblestone)
Block(5,8,0,log)
Block(5,9,-1,cobblestone)
Block(5,9,0,log)
Block(5,10,-1,cobblestone)
Block(5,10,0,log)
Block(5,11,-8,cobblestone)
Block(5,11,-7,cobblestone)
Block(5,11,-6,cobblestone)
Block(5,11,-5,cobblestone)
Block(5,11,-4,cobblestone)
Block(5,11,-3,cobblestone)
Block(5,11,-2,cobblestone)
Block(5,11,-1,cobblestone)
Block(5,11,0,log)
Block(5,12,-8,log:4)
Block(5,12,-7,stone:6)
Block(5,12,-6,stone:6)
Block(5,12,-5,log:4)
Block(5,12,-4,stone:6)
Block(5,12,-3,stone:6)
Block(5,12,-2,log)
Block(5,12,-1,stone_stairs:1)
Block(5,12,0,stone_STAIRS:0)
Block(5,13,-8,log)
Block(5,13,-7,stone:6)
Block(5,13,-6,stone:6)
Block(5,13,-5,log)
Block(5,13,-4,stone:6)
Block(5,13,-3,stone:6)
Block(5,13,-2,log)
Block(5,14,-8,log)
Block(5,14,-7,stone:6)
Block(5,14,-6,stone:6)
Block(5,14,-5,log)
Block(5,14,-4,stone:6)
Block(5,14,-3,stone:6)
Block(5,14,-2,log)
Block(5,15,-8,log)
Block(5,15,-7,stone:6)
Block(5,15,-6,stone:6)
Block(5,15,-5,log)
Block(5,15,-4,stone:6)
Block(5,15,-3,stone:6)
Block(5,15,-2,log)
Block(5,16,-8,log)
Block(5,16,-7,stone_stairs:1)
Block(5,16,-6,stone_stairs:1)
Block(5,16,-5,log)
Block(5,16,-4,stone_stairs:1)
Block(5,16,-3,stone_stairs:1)
Block(5,16,-2,log)
Block(5,17,-8,stone_stairs:1)
Block(5,17,-5,stone_stairs:1)
Block(5,17,-2,stone_stairs:1)
Block(6,1,-8,log)
Block(6,1,-7,cobblestone)
Block(6,1,-6,cobblestone)
Block(6,1,-5,log)
Block(6,1,-4,cobblestone)
Block(6,1,-3,cobblestone)
Block(6,1,-2,log)
Block(6,2,-8,log)
Block(6,2,-7,cobblestone)
Block(6,2,-6,cobblestone)
Block(6,2,-5,log)
Block(6,2,-4,cobblestone)
Block(6,2,-3,cobblestone)
Block(6,2,-2,log)
Block(6,3,-8,log)
Block(6,3,-7,cobblestone)
Block(6,3,-6,cobblestone)
Block(6,3,-5,log)
Block(6,3,-4,cobblestone)
Block(6,3,-3,cobblestone)
Block(6,3,-2,log)
Block(6,4,-8,log)
Block(6,4,-7,cobblestone)
Block(6,4,-6,cobblestone)
Block(6,4,-5,log)
Block(6,4,-4,cobblestone)
Block(6,4,-3,cobblestone)
Block(6,4,-2,log)
Block(6,5,-8,log)
Block(6,5,-7,cobblestone)
Block(6,5,-6,cobblestone)
Block(6,5,-5,log)
Block(6,5,-4,cobblestone)
Block(6,5,-3,cobblestone)
Block(6,5,-2,log)
Block(6,6,-8,log)
Block(6,6,-7,cobblestone)
Block(6,6,-6,cobblestone)
Block(6,6,-5,log)
Block(6,6,-4,cobblestone)
Block(6,6,-3,cobblestone)
Block(6,6,-2,log)
Block(6,7,-8,log)
Block(6,7,-7,cobblestone)
Block(6,7,-6,cobblestone)
Block(6,7,-5,log)
Block(6,7,-4,cobblestone)
Block(6,7,-3,cobblestone)
Block(6,7,-2,log)
Block(6,8,-8,log)
Block(6,8,-7,cobblestone)
Block(6,8,-6,cobblestone)
Block(6,8,-5,log)
Block(6,8,-4,cobblestone)
Block(6,8,-3,cobblestone)
Block(6,8,-2,log)
Block(6,9,-8,log)
Block(6,9,-7,cobblestone)
Block(6,9,-6,cobblestone)
Block(6,9,-5,log)
Block(6,9,-4,cobblestone)
Block(6,9,-3,cobblestone)
Block(6,9,-2,log)
Block(6,10,-8,log)
Block(6,10,-7,cobblestone)
Block(6,10,-6,cobblestone)
Block(6,10,-5,log)
Block(6,10,-4,cobblestone)
Block(6,10,-3,cobblestone)
Block(6,10,-2,log)
Block(6,11,-8,log)
Block(6,11,-7,cobblestone)
Block(6,11,-6,cobblestone)
Block(6,11,-5,log)
Block(6,11,-4,cobblestone)
Block(6,11,-3,cobblestone)
Block(6,11,-2,log)
Block(6,12,-8,stone_brick_stairs:1)
Block(6,12,-7,stone_stairs:1)
Block(6,12,-6,stone_stairs:1)
Block(6,12,-5,stone_brick_stairs:1)
Block(6,12,-4,stone_stairs:1)
Block(6,12,-3,stone_stairs:1)
Block(6,12,-2,stone_STAIRS:0)

#######################################################################
# +-----------------------------------------------------------------+ #
# |                            BO3 checks                           | #
# +-----------------------------------------------------------------+ #
#######################################################################


#######################################################################
# +-----------------------------------------------------------------+ #
# |                             Branches                            | #
# +-----------------------------------------------------------------+ #
#######################################################################

