#
# +-----------------------------------------------------------------+ #
# |                            BO3 object                           | #
# +-----------------------------------------------------------------+ #
#

# This is the config file of a custom object.
# If you add this object correctly to your BiomeConfigs, it will spawn in the world.

# This is the creator of this BO3 object
Author: BO3 BulkEdit (by LanToaster)

# A short description of this BO3 object
Description: This Object was Created with BO3_BulkEdit

# The BO3 version, don't change this! It can be used by external applications to do a version check.
Version: 3

# The settings mode, WriteAll, WriteWithoutComments or WriteDisable. See WorldConfig.
SettingsMode: WriteDisable


#
# +-----------------------------------------------------------------+ #
# |                          Main settings                          | #
# +-----------------------------------------------------------------+ #
#

# This needs to be set to true to spawn the object in the Tree and Sapling resources.
Tree: false

# The frequency of the BO3 from 1 to 200. Tries this many times to spawn this BO3 when using the CustomObject(...) resource.

Frequency: 1

# The rarity of the BO3 from 0 to 100. Each spawn attempt has rarity% chance to succeed when using the CustomObject(...) resource.

Rarity: 100.0

# If you set this to true, the BO3 will be placed with a random rotation.
RotateRandomly: false

# The spawn height of the BO3 - randomY, highestBlock or highestSolidBlock.
SpawnHeight: randomY

# The height limits for the BO3.
MinHeight: 68

MaxHeight: 78

# Objects can have other objects attacthed to it: branches. Branches can also
# have branches attached to it, which can also have branches, etc. This is the
# maximum branch depth for this objects.
MaxBranchDepth: 10

# When spawned with the UseWorld keyword, this BO3 should NOT spawn in the following biomes.
# If you writer.write the BO3 name directly in the BiomeConfigs, this will be ignored.
ExcludedBiomes: All


#
# +-----------------------------------------------------------------+ #
# |                      Source block settings                      | #
# +-----------------------------------------------------------------+ #
#

# The B(s) the BO3 should spawn in.
SourceBlocks: AIR

# The maximum percentage of the BO3 that can be outside the SourceBlock.
# The BO3 won't be placed on a location with more blocks outside the SourceBlock than this percentage.
MaxPercentageOutsideSourceBlock: 100

# What to do when a block is about to be placed outside the SourceBlock? (dontPlace, placeAnyway)
OutsideSourceBlock: placeAnyway


#
# +-----------------------------------------------------------------+ #
# |                              Blocks                             | #
# +-----------------------------------------------------------------+ #
#

# All the blocks used in the BO3 are listed here. Possible blocks:
# B(x,y,z,id[.data][,nbtfile.nbt)
# RandomBlock(x,y,z,id[:data][,nbtfile.nbt],chance[,id[:data][,nbtfile.nbt],chance[,...]])
# So RandomBlock(0,0,0,CHEST,chest.nbt,50,CHEST,anotherchest.nbt,100) will spawn a chest at
# the BO3 origin, and give it a 50% chance to have the contents of chest.nbt, or, if that
# fails, a 100% percent chance to have the contents of anotherchest.nbt.
B(-7,0,-7,STONE:0)
B(-6,0,-7,STONE:0)
B(-5,0,-7,STONE:0)
B(-4,0,-7,STONE:0)
B(-3,0,-7,STONE:0)
B(-2,0,-7,STONE:0)
B(-1,0,-7,STONE:0)
B(0,0,-7,STONE:0)
B(1,0,-7,STONE:0)
B(2,0,-7,STONE:0)
B(3,0,-7,STONE:0)
B(4,0,-7,STONE:0)
B(5,0,-7,STONE:0)
B(6,0,-7,STONE:0)
B(7,0,-7,STONE:0)
B(8,0,-7,STONE:0)
B(-7,0,-6,STONE:0)
B(-6,0,-6,STONE:0)
B(-5,0,-6,STONE:0)
B(-4,0,-6,STONE:0)
B(-3,0,-6,STONE:0)
B(-2,0,-6,STONE:0)
B(-1,0,-6,STONE:0)
B(0,0,-6,STONE:0)
B(1,0,-6,STONE:0)
B(2,0,-6,STONE:0)
B(3,0,-6,STONE:0)
B(4,0,-6,STONE:0)
B(5,0,-6,STONE:0)
B(6,0,-6,STONE:0)
B(7,0,-6,STONE:0)
B(8,0,-6,STONE:0)
B(-7,0,-5,STONE:0)
B(-6,0,-5,STONE:0)
B(-5,0,-5,STONE:0)
B(-4,0,-5,STONE:0)
B(-3,0,-5,STONE:0)
B(-2,0,-5,STONE:0)
B(-1,0,-5,STONE:0)
B(0,0,-5,STONE:0)
B(1,0,-5,STONE:0)
B(2,0,-5,STONE:0)
B(3,0,-5,STONE:0)
B(4,0,-5,STONE:0)
B(5,0,-5,STONE:0)
B(6,0,-5,STONE:0)
B(7,0,-5,STONE:0)
B(8,0,-5,STONE:0)
B(-7,0,-4,STONE:0)
B(-6,0,-4,STONE:0)
B(-5,0,-4,STONE:0)
B(-4,0,-4,STONE:0)
B(-3,0,-4,STONE:0)
B(-2,0,-4,STONE:0)
B(-1,0,-4,STONE:0)
B(0,0,-4,STONE:0)
B(1,0,-4,STONE:0)
B(2,0,-4,STONE:0)
B(3,0,-4,STONE:0)
B(4,0,-4,STONE:0)
B(5,0,-4,STONE:0)
B(6,0,-4,STONE:0)
B(7,0,-4,STONE:0)
B(8,0,-4,STONE:0)
B(-7,0,-3,STONE:0)
B(-6,0,-3,STONE:0)
B(-5,0,-3,STONE:0)
B(-4,0,-3,STONE:0)
B(-3,0,-3,STONE:0)
B(-2,0,-3,STONE:0)
B(-1,0,-3,STONE:0)
B(0,0,-3,STONE:0)
B(1,0,-3,STONE:0)
B(2,0,-3,STONE:0)
B(3,0,-3,STONE:0)
B(4,0,-3,STONE:0)
B(5,0,-3,STONE:0)
B(6,0,-3,STONE:0)
B(7,0,-3,STONE:0)
B(8,0,-3,STONE:0)
B(-7,0,-2,STONE:0)
B(-6,0,-2,STONE:0)
B(-5,0,-2,STONE:0)
B(-4,0,-2,STONE:0)
B(-3,0,-2,STONE:0)
B(-2,0,-2,STONE:0)
B(-1,0,-2,STONE:0)
B(0,0,-2,STONE:0)
B(1,0,-2,STONE:0)
B(2,0,-2,STONE:0)
B(3,0,-2,STONE:0)
B(4,0,-2,STONE:0)
B(5,0,-2,STONE:0)
B(6,0,-2,STONE:0)
B(7,0,-2,STONE:0)
B(8,0,-2,STONE:0)
B(-7,0,-1,STONE:0)
B(-6,0,-1,STONE:0)
B(-5,0,-1,STONE:0)
B(-4,0,-1,STONE:0)
B(-3,0,-1,STONE:0)
B(-2,0,-1,STONE:0)
B(-1,0,-1,STONE:0)
B(0,0,-1,STONE:0)
B(1,0,-1,STONE:0)
B(2,0,-1,STONE:0)
B(3,0,-1,STONE:0)
B(4,0,-1,STONE:0)
B(5,0,-1,STONE:0)
B(6,0,-1,STONE:0)
B(7,0,-1,STONE:0)
B(8,0,-1,STONE:0)
B(-7,0,0,STONE:0)
B(-6,0,0,STONE:0)
B(-5,0,0,STONE:0)
B(-4,0,0,STONE:0)
B(-3,0,0,STONE:0)
B(-2,0,0,STONE:0)
B(-1,0,0,STONE:0)
B(0,0,0,STONE:0)
B(1,0,0,STONE:0)
B(2,0,0,STONE:0)
B(3,0,0,STONE:0)
B(4,0,0,STONE:0)
B(5,0,0,STONE:0)
B(6,0,0,STONE:0)
B(7,0,0,STONE:0)
B(8,0,0,STONE:0)
B(-7,0,1,STONE:0)
B(-6,0,1,STONE:0)
B(-5,0,1,STONE:0)
B(-4,0,1,STONE:0)
B(-3,0,1,STONE:0)
B(-2,0,1,STONE:0)
B(-1,0,1,STONE:0)
B(0,0,1,STONE:0)
B(1,0,1,STONE:0)
B(2,0,1,STONE:0)
B(3,0,1,STONE:0)
B(4,0,1,STONE:0)
B(5,0,1,STONE:0)
B(6,0,1,STONE:0)
B(7,0,1,STONE:0)
B(8,0,1,STONE:0)
B(-7,0,2,STONE:0)
B(-6,0,2,STONE:0)
B(-5,0,2,STONE:0)
B(-4,0,2,STONE:0)
B(-3,0,2,STONE:0)
B(-2,0,2,STONE:0)
B(-1,0,2,STONE:0)
B(0,0,2,STONE:0)
B(1,0,2,STONE:0)
B(2,0,2,STONE:0)
B(3,0,2,STONE:0)
B(4,0,2,STONE:0)
B(5,0,2,STONE:0)
B(6,0,2,STONE:0)
B(7,0,2,STONE:0)
B(8,0,2,STONE:0)
B(-7,0,3,STONE:0)
B(-6,0,3,STONE:0)
B(-5,0,3,STONE:0)
B(-4,0,3,STONE:0)
B(-3,0,3,STONE:0)
B(-2,0,3,STONE:0)
B(-1,0,3,STONE:0)
B(0,0,3,STONE:0)
B(1,0,3,STONE:0)
B(2,0,3,STONE:0)
B(3,0,3,STONE:0)
B(4,0,3,STONE:0)
B(5,0,3,STONE:0)
B(6,0,3,STONE:0)
B(7,0,3,STONE:0)
B(8,0,3,STONE:0)
B(-7,0,4,STONE:0)
B(-6,0,4,STONE:0)
B(-5,0,4,STONE:0)
B(-4,0,4,STONE:0)
B(-3,0,4,STONE:0)
B(-2,0,4,STONE:0)
B(-1,0,4,STONE:0)
B(0,0,4,STONE:0)
B(1,0,4,STONE:0)
B(2,0,4,STONE:0)
B(3,0,4,STONE:0)
B(4,0,4,STONE:0)
B(5,0,4,STONE:0)
B(6,0,4,STONE:0)
B(7,0,4,STONE:0)
B(8,0,4,STONE:0)
B(-7,0,5,STONE:0)
B(-6,0,5,STONE:0)
B(-5,0,5,STONE:0)
B(-4,0,5,STONE:0)
B(-3,0,5,STONE:0)
B(-2,0,5,STONE:0)
B(-1,0,5,STONE:0)
B(0,0,5,STONE:0)
B(1,0,5,STONE:0)
B(2,0,5,STONE:0)
B(3,0,5,STONE:0)
B(4,0,5,STONE:0)
B(5,0,5,STONE:0)
B(6,0,5,STONE:0)
B(7,0,5,STONE:0)
B(8,0,5,STONE:0)
B(-7,0,6,STONE:0)
B(-6,0,6,STONE:0)
B(-5,0,6,STONE:0)
B(-4,0,6,STONE:0)
B(-3,0,6,STONE:0)
B(-2,0,6,STONE:0)
B(-1,0,6,STONE:0)
B(0,0,6,STONE:0)
B(1,0,6,STONE:0)
B(2,0,6,STONE:0)
B(3,0,6,STONE:0)
B(4,0,6,STONE:0)
B(5,0,6,STONE:0)
B(6,0,6,STONE:0)
B(7,0,6,STONE:0)
B(8,0,6,STONE:0)
B(-7,0,7,STONE:0)
B(-6,0,7,STONE:0)
B(-5,0,7,STONE:0)
B(-4,0,7,STONE:0)
B(-3,0,7,STONE:0)
B(-2,0,7,STONE:0)
B(-1,0,7,STONE:0)
B(0,0,7,STONE:0)
B(1,0,7,STONE:0)
B(2,0,7,STONE:0)
B(3,0,7,STONE:0)
B(4,0,7,STONE:0)
B(5,0,7,STONE:0)
B(6,0,7,STONE:0)
B(7,0,7,STONE:0)
B(8,0,7,STONE:0)
B(-7,0,8,STONE:0)
B(-6,0,8,STONE:0)
B(-5,0,8,STONE:0)
B(-4,0,8,STONE:0)
B(-3,0,8,STONE:0)
B(-2,0,8,STONE:0)
B(-1,0,8,STONE:0)
B(0,0,8,STONE:0)
B(1,0,8,STONE:0)
B(2,0,8,STONE:0)
B(3,0,8,STONE:0)
B(4,0,8,STONE:0)
B(5,0,8,STONE:0)
B(6,0,8,STONE:0)
B(7,0,8,STONE:0)
B(8,0,8,STONE:0)
B(-7,1,-7,STONE:0)
B(-6,1,-7,STONE:0)
B(-5,1,-7,STONE:0)
B(-4,1,-7,STONE:0)
B(-3,1,-7,STONE:0)
B(-2,1,-7,STONE:0)
B(-1,1,-7,STONE:0)
B(0,1,-7,STONE:0)
B(1,1,-7,STONE:0)
B(2,1,-7,STONE:0)
B(3,1,-7,STONE:0)
B(4,1,-7,STONE:0)
B(5,1,-7,STONE:0)
B(6,1,-7,STONE:0)
B(7,1,-7,STONE:0)
B(8,1,-7,STONE:0)
B(-7,1,-6,STONE:0)
B(-6,1,-6,STONE:0)
B(-5,1,-6,STONE:0)
B(-4,1,-6,STONE:0)
B(-3,1,-6,STONE:0)
B(-2,1,-6,STONE:0)
B(-1,1,-6,STONE:0)
B(0,1,-6,STONE:0)
B(1,1,-6,STONE:0)
B(2,1,-6,STONE:0)
B(3,1,-6,STONE:0)
B(4,1,-6,STONE:0)
B(5,1,-6,STONE:0)
B(6,1,-6,STONE:0)
B(7,1,-6,STONE:0)
B(8,1,-6,STONE:0)
B(-7,1,-5,STONE:0)
B(-6,1,-5,STONE:0)
B(-5,1,-5,STONE:0)
B(-4,1,-5,STONE:0)
B(-3,1,-5,STONE:0)
B(-2,1,-5,STONE:0)
B(-1,1,-5,STONE:0)
B(0,1,-5,STONE:0)
B(1,1,-5,STONE:0)
B(2,1,-5,STONE:0)
B(3,1,-5,STONE:0)
B(4,1,-5,STONE:0)
B(5,1,-5,STONE:0)
B(6,1,-5,STONE:0)
B(7,1,-5,STONE:0)
B(8,1,-5,STONE:0)
B(-7,1,-4,STONE:0)
B(-6,1,-4,STONE:0)
B(-5,1,-4,STONE:0)
B(-4,1,-4,STONE:0)
B(-3,1,-4,STONE:0)
B(-2,1,-4,STONE:0)
B(-1,1,-4,STONE:0)
B(0,1,-4,STONE:0)
B(1,1,-4,STONE:0)
B(2,1,-4,STONE:0)
B(3,1,-4,STONE:0)
B(4,1,-4,STONE:0)
B(5,1,-4,STONE:0)
B(6,1,-4,STONE:0)
B(7,1,-4,STONE:0)
B(8,1,-4,STONE:0)
B(-7,1,-3,STONE:0)
B(-6,1,-3,STONE:0)
B(-5,1,-3,STONE:0)
B(-4,1,-3,STONE:0)
B(-3,1,-3,STONE:0)
B(-2,1,-3,STONE:0)
B(-1,1,-3,STONE:0)
B(0,1,-3,STONE:0)
B(1,1,-3,STONE:0)
B(2,1,-3,STONE:0)
B(3,1,-3,STONE:0)
B(4,1,-3,STONE:0)
B(5,1,-3,STONE:0)
B(6,1,-3,STONE:0)
B(7,1,-3,STONE:0)
B(8,1,-3,STONE:0)
B(-7,1,-2,STONE:0)
B(-6,1,-2,STONE:0)
B(-5,1,-2,STONE:0)
B(-4,1,-2,STONE:0)
B(-3,1,-2,STONE:0)
B(-2,1,-2,STONE:0)
B(-1,1,-2,STONE:0)
B(0,1,-2,STONE:0)
B(1,1,-2,STONE:0)
B(2,1,-2,STONE:0)
B(3,1,-2,STONE:0)
B(4,1,-2,STONE:0)
B(5,1,-2,STONE:0)
B(6,1,-2,STONE:0)
B(7,1,-2,STONE:0)
B(8,1,-2,STONE:0)
B(-7,1,-1,STONE:0)
B(-6,1,-1,STONE:0)
B(-5,1,-1,STONE:0)
B(-4,1,-1,STONE:0)
B(-3,1,-1,STONE:0)
B(-2,1,-1,STONE:0)
B(-1,1,-1,STONE:0)
B(0,1,-1,STONE:0)
B(1,1,-1,STONE:0)
B(2,1,-1,STONE:0)
B(3,1,-1,STONE:0)
B(4,1,-1,STONE:0)
B(5,1,-1,STONE:0)
B(6,1,-1,STONE:0)
B(7,1,-1,STONE:0)
B(8,1,-1,STONE:0)
B(-7,1,0,STONE:0)
B(-6,1,0,STONE:0)
B(-5,1,0,STONE:0)
B(-4,1,0,STONE:0)
B(-3,1,0,STONE:0)
B(-2,1,0,STONE:0)
B(-1,1,0,STONE:0)
B(0,1,0,STONE:0)
B(1,1,0,STONE:0)
B(2,1,0,STONE:0)
B(3,1,0,STONE:0)
B(4,1,0,STONE:0)
B(5,1,0,STONE:0)
B(6,1,0,STONE:0)
B(7,1,0,STONE:0)
B(8,1,0,STONE:0)
B(-7,1,1,STONE:0)
B(-6,1,1,STONE:0)
B(-5,1,1,STONE:0)
B(-4,1,1,STONE:0)
B(-3,1,1,STONE:0)
B(-2,1,1,STONE:0)
B(-1,1,1,STONE:0)
B(0,1,1,STONE:0)
B(1,1,1,STONE:0)
B(2,1,1,STONE:0)
B(3,1,1,STONE:0)
B(4,1,1,STONE:0)
B(5,1,1,STONE:0)
B(6,1,1,STONE:0)
B(7,1,1,STONE:0)
B(8,1,1,STONE:0)
B(-7,1,2,STONE:0)
B(-6,1,2,STONE:0)
B(-5,1,2,STONE:0)
B(-4,1,2,STONE:0)
B(-3,1,2,STONE:0)
B(-2,1,2,STONE:0)
B(-1,1,2,STONE:0)
B(0,1,2,STONE:0)
B(1,1,2,STONE:0)
B(2,1,2,STONE:0)
B(3,1,2,STONE:0)
B(4,1,2,STONE:0)
B(5,1,2,STONE:0)
B(6,1,2,STONE:0)
B(7,1,2,STONE:0)
B(8,1,2,STONE:0)
B(-7,1,3,STONE:0)
B(-6,1,3,STONE:0)
B(-5,1,3,STONE:0)
B(-4,1,3,STONE:0)
B(-3,1,3,STONE:0)
B(-2,1,3,STONE:0)
B(-1,1,3,STONE:0)
B(0,1,3,STONE:0)
B(1,1,3,STONE:0)
B(2,1,3,STONE:0)
B(3,1,3,STONE:0)
B(4,1,3,STONE:0)
B(5,1,3,STONE:0)
B(6,1,3,STONE:0)
B(7,1,3,STONE:0)
B(8,1,3,STONE:0)
B(-7,1,4,STONE:0)
B(-6,1,4,STONE:0)
B(-5,1,4,STONE:0)
B(-4,1,4,STONE:0)
B(-3,1,4,STONE:0)
B(-2,1,4,STONE:0)
B(-1,1,4,STONE:0)
B(0,1,4,STONE:0)
B(1,1,4,STONE:0)
B(2,1,4,STONE:0)
B(3,1,4,STONE:0)
B(4,1,4,STONE:0)
B(5,1,4,STONE:0)
B(6,1,4,STONE:0)
B(7,1,4,STONE:0)
B(8,1,4,STONE:0)
B(-7,1,5,STONE:0)
B(-6,1,5,STONE:0)
B(-5,1,5,STONE:0)
B(-4,1,5,STONE:0)
B(-3,1,5,STONE:0)
B(-2,1,5,STONE:0)
B(-1,1,5,STONE:0)
B(0,1,5,STONE:0)
B(1,1,5,STONE:0)
B(2,1,5,STONE:0)
B(3,1,5,STONE:0)
B(4,1,5,STONE:0)
B(5,1,5,STONE:0)
B(6,1,5,STONE:0)
B(7,1,5,STONE:0)
B(8,1,5,STONE:0)
B(-7,1,6,STONE:0)
B(-6,1,6,STONE:0)
B(-5,1,6,STONE:0)
B(-4,1,6,STONE:0)
B(-3,1,6,STONE:0)
B(-2,1,6,STONE:0)
B(-1,1,6,STONE:0)
B(0,1,6,STONE:0)
B(1,1,6,STONE:0)
B(2,1,6,STONE:0)
B(3,1,6,STONE:0)
B(4,1,6,STONE:0)
B(5,1,6,STONE:0)
B(6,1,6,STONE:0)
B(7,1,6,STONE:0)
B(8,1,6,STONE:0)
B(-7,1,7,STONE:0)
B(-6,1,7,STONE:0)
B(-5,1,7,STONE:0)
B(-4,1,7,STONE:0)
B(-3,1,7,STONE:0)
B(-2,1,7,STONE:0)
B(-1,1,7,STONE:0)
B(0,1,7,STONE:0)
B(1,1,7,STONE:0)
B(2,1,7,STONE:0)
B(3,1,7,STONE:0)
B(4,1,7,STONE:0)
B(5,1,7,STONE:0)
B(6,1,7,STONE:0)
B(7,1,7,STONE:0)
B(8,1,7,STONE:0)
B(-7,1,8,STONE:0)
B(-6,1,8,STONE:0)
B(-5,1,8,STONE:0)
B(-4,1,8,STONE:0)
B(-3,1,8,STONE:0)
B(-2,1,8,STONE:0)
B(-1,1,8,STONE:0)
B(0,1,8,STONE:0)
B(1,1,8,STONE:0)
B(2,1,8,STONE:0)
B(3,1,8,STONE:0)
B(4,1,8,STONE:0)
B(5,1,8,STONE:0)
B(6,1,8,STONE:0)
B(7,1,8,STONE:0)
B(8,1,8,STONE:0)
B(-7,2,-7,STONE:0)
B(-6,2,-7,STONE:0)
B(-5,2,-7,STONE:0)
B(-4,2,-7,STONE:0)
B(-3,2,-7,STONE:0)
B(-2,2,-7,STONE:0)
B(-1,2,-7,STONE:0)
B(0,2,-7,STONE:0)
B(1,2,-7,STONE:0)
B(2,2,-7,STONE:0)
B(3,2,-7,STONE:0)
B(4,2,-7,STONE:0)
B(5,2,-7,STONE:0)
B(6,2,-7,STONE:0)
B(7,2,-7,STONE:0)
B(8,2,-7,STONE:0)
B(-7,2,-6,STONE:0)
B(-6,2,-6,STONE:0)
B(-5,2,-6,STONE:0)
B(-4,2,-6,STONE:0)
B(-3,2,-6,STONE:0)
B(-2,2,-6,STONE:0)
B(-1,2,-6,STONE:0)
B(0,2,-6,STONE:0)
B(1,2,-6,STONE:0)
B(2,2,-6,STONE:0)
B(3,2,-6,STONE:0)
B(4,2,-6,STONE:0)
B(5,2,-6,STONE:0)
B(6,2,-6,STONE:0)
B(7,2,-6,STONE:0)
B(8,2,-6,STONE:0)
B(-7,2,-5,STONE:0)
B(-6,2,-5,STONE:0)
B(-5,2,-5,STONE:0)
B(-4,2,-5,STONE:0)
B(-3,2,-5,STONE:0)
B(-2,2,-5,STONE:0)
B(-1,2,-5,STONE:0)
B(0,2,-5,STONE:0)
B(1,2,-5,STONE:0)
B(2,2,-5,STONE:0)
B(3,2,-5,STONE:0)
B(4,2,-5,STONE:0)
B(5,2,-5,STONE:0)
B(6,2,-5,STONE:0)
B(7,2,-5,STONE:0)
B(8,2,-5,STONE:0)
B(-7,2,-4,STONE:0)
B(-6,2,-4,STONE:0)
B(-5,2,-4,STONE:0)
B(-4,2,-4,STONE:0)
B(-3,2,-4,STONE:0)
B(-2,2,-4,STONE:0)
B(-1,2,-4,STONE:0)
B(0,2,-4,STONE:0)
B(1,2,-4,STONE:0)
B(2,2,-4,STONE:0)
B(3,2,-4,STONE:0)
B(4,2,-4,STONE:0)
B(5,2,-4,STONE:0)
B(6,2,-4,STONE:0)
B(7,2,-4,STONE:0)
B(8,2,-4,STONE:0)
B(-7,2,-3,STONE:0)
B(-6,2,-3,STONE:0)
B(-5,2,-3,STONE:0)
B(-4,2,-3,STONE:0)
B(-3,2,-3,STONE:0)
B(-2,2,-3,STONE:0)
B(-1,2,-3,STONE:0)
B(0,2,-3,STONE:0)
B(1,2,-3,STONE:0)
B(2,2,-3,STONE:0)
B(3,2,-3,STONE:0)
B(4,2,-3,STONE:0)
B(5,2,-3,STONE:0)
B(6,2,-3,STONE:0)
B(7,2,-3,STONE:0)
B(8,2,-3,STONE:0)
B(-7,2,-2,STONE:0)
B(-6,2,-2,STONE:0)
B(-5,2,-2,STONE:0)
B(-4,2,-2,STONE:0)
B(-3,2,-2,STONE:0)
B(-2,2,-2,STONE:0)
B(-1,2,-2,STONE:0)
B(0,2,-2,STONE:0)
B(1,2,-2,STONE:0)
B(2,2,-2,STONE:0)
B(3,2,-2,STONE:0)
B(4,2,-2,STONE:0)
B(5,2,-2,STONE:0)
B(6,2,-2,STONE:0)
B(7,2,-2,STONE:0)
B(8,2,-2,STONE:0)
B(-7,2,-1,STONE:0)
B(-6,2,-1,STONE:0)
B(-5,2,-1,STONE:0)
B(-4,2,-1,STONE:0)
B(-3,2,-1,STONE:0)
B(-2,2,-1,STONE:0)
B(-1,2,-1,STONE:0)
B(0,2,-1,STONE:0)
B(1,2,-1,STONE:0)
B(2,2,-1,STONE:0)
B(3,2,-1,STONE:0)
B(4,2,-1,STONE:0)
B(5,2,-1,STONE:0)
B(6,2,-1,STONE:0)
B(7,2,-1,STONE:0)
B(8,2,-1,STONE:0)
B(-7,2,0,STONE:0)
B(-6,2,0,STONE:0)
B(-5,2,0,STONE:0)
B(-4,2,0,STONE:0)
B(-3,2,0,STONE:0)
B(-2,2,0,STONE:0)
B(-1,2,0,STONE:0)
B(0,2,0,STONE:0)
B(1,2,0,STONE:0)
B(2,2,0,STONE:0)
B(3,2,0,STONE:0)
B(4,2,0,STONE:0)
B(5,2,0,STONE:0)
B(6,2,0,STONE:0)
B(7,2,0,STONE:0)
B(8,2,0,STONE:0)
B(-7,2,1,STONE:0)
B(-6,2,1,STONE:0)
B(-5,2,1,STONE:0)
B(-4,2,1,STONE:0)
B(-3,2,1,STONE:0)
B(-2,2,1,STONE:0)
B(-1,2,1,STONE:0)
B(0,2,1,STONE:0)
B(1,2,1,STONE:0)
B(2,2,1,STONE:0)
B(3,2,1,STONE:0)
B(4,2,1,STONE:0)
B(5,2,1,STONE:0)
B(6,2,1,STONE:0)
B(7,2,1,STONE:0)
B(8,2,1,STONE:0)
B(-7,2,2,STONE:0)
B(-6,2,2,STONE:0)
B(-5,2,2,STONE:0)
B(-4,2,2,STONE:0)
B(-3,2,2,STONE:0)
B(-2,2,2,STONE:0)
B(-1,2,2,STONE:0)
B(0,2,2,STONE:0)
B(1,2,2,STONE:0)
B(2,2,2,STONE:0)
B(3,2,2,STONE:0)
B(4,2,2,STONE:0)
B(5,2,2,STONE:0)
B(6,2,2,STONE:0)
B(7,2,2,STONE:0)
B(8,2,2,STONE:0)
B(-7,2,3,STONE:0)
B(-6,2,3,STONE:0)
B(-5,2,3,STONE:0)
B(-4,2,3,STONE:0)
B(-3,2,3,STONE:0)
B(-2,2,3,STONE:0)
B(-1,2,3,STONE:0)
B(0,2,3,STONE:0)
B(1,2,3,STONE:0)
B(2,2,3,STONE:0)
B(3,2,3,STONE:0)
B(4,2,3,STONE:0)
B(5,2,3,STONE:0)
B(6,2,3,STONE:0)
B(7,2,3,STONE:0)
B(8,2,3,STONE:0)
B(-7,2,4,STONE:0)
B(-6,2,4,STONE:0)
B(-5,2,4,STONE:0)
B(-4,2,4,STONE:0)
B(-3,2,4,STONE:0)
B(-2,2,4,STONE:0)
B(-1,2,4,STONE:0)
B(0,2,4,STONE:0)
B(1,2,4,STONE:0)
B(2,2,4,STONE:0)
B(3,2,4,STONE:0)
B(4,2,4,STONE:0)
B(5,2,4,STONE:0)
B(6,2,4,STONE:0)
B(7,2,4,STONE:0)
B(8,2,4,STONE:0)
B(-7,2,5,STONE:0)
B(-6,2,5,STONE:0)
B(-5,2,5,STONE:0)
B(-4,2,5,STONE:0)
B(-3,2,5,STONE:0)
B(-2,2,5,STONE:0)
B(-1,2,5,STONE:0)
B(0,2,5,STONE:0)
B(1,2,5,STONE:0)
B(2,2,5,STONE:0)
B(3,2,5,STONE:0)
B(4,2,5,STONE:0)
B(5,2,5,STONE:0)
B(6,2,5,STONE:0)
B(7,2,5,STONE:0)
B(8,2,5,STONE:0)
B(-7,2,6,STONE:0)
B(-6,2,6,STONE:0)
B(-5,2,6,STONE:0)
B(-4,2,6,STONE:0)
B(-3,2,6,STONE:0)
B(-2,2,6,STONE:0)
B(-1,2,6,STONE:0)
B(0,2,6,STONE:0)
B(1,2,6,STONE:0)
B(2,2,6,STONE:0)
B(3,2,6,STONE:0)
B(4,2,6,STONE:0)
B(5,2,6,STONE:0)
B(6,2,6,STONE:0)
B(7,2,6,STONE:0)
B(8,2,6,STONE:0)
B(-7,2,7,STONE:0)
B(-6,2,7,STONE:0)
B(-5,2,7,STONE:0)
B(-4,2,7,STONE:0)
B(-3,2,7,STONE:0)
B(-2,2,7,STONE:0)
B(-1,2,7,STONE:0)
B(0,2,7,STONE:0)
B(1,2,7,STONE:0)
B(2,2,7,STONE:0)
B(3,2,7,STONE:0)
B(4,2,7,STONE:0)
B(5,2,7,STONE:0)
B(6,2,7,STONE:0)
B(7,2,7,STONE:0)
B(8,2,7,STONE:0)
B(-7,2,8,STONE:0)
B(-6,2,8,STONE:0)
B(-5,2,8,STONE:0)
B(-4,2,8,STONE:0)
B(-3,2,8,STONE:0)
B(-2,2,8,STONE:0)
B(-1,2,8,STONE:0)
B(0,2,8,STONE:0)
B(1,2,8,STONE:0)
B(2,2,8,STONE:0)
B(3,2,8,STONE:0)
B(4,2,8,STONE:0)
B(5,2,8,STONE:0)
B(6,2,8,STONE:0)
B(7,2,8,STONE:0)
B(8,2,8,STONE:0)
B(-7,3,-7,STONE:0)
B(-6,3,-7,STONE:0)
B(-5,3,-7,STONE:0)
B(-4,3,-7,STONE:0)
B(-3,3,-7,STONE:0)
B(-2,3,-7,STONE:0)
B(-1,3,-7,STONE:0)
B(0,3,-7,STONE:0)
B(1,3,-7,STONE:0)
B(2,3,-7,STONE:0)
B(3,3,-7,STONE:0)
B(4,3,-7,STONE:0)
B(5,3,-7,STONE:0)
B(6,3,-7,STONE:0)
B(7,3,-7,STONE:0)
B(8,3,-7,STONE:0)
B(-7,3,-6,STONE:0)
B(-6,3,-6,STONE:0)
B(-5,3,-6,STONE:0)
B(-4,3,-6,STONE:0)
B(-3,3,-6,STONE:0)
B(-2,3,-6,STONE:0)
B(-1,3,-6,STONE:0)
B(0,3,-6,STONE:0)
B(1,3,-6,STONE:0)
B(2,3,-6,STONE:0)
B(3,3,-6,STONE:0)
B(4,3,-6,STONE:0)
B(5,3,-6,STONE:0)
B(6,3,-6,STONE:0)
B(7,3,-6,STONE:0)
B(8,3,-6,STONE:0)
B(-7,3,-5,STONE:0)
B(-6,3,-5,STONE:0)
B(-5,3,-5,STONE:0)
B(-4,3,-5,STONE:0)
B(-3,3,-5,STONE:0)
B(-2,3,-5,STONE:0)
B(-1,3,-5,STONE:0)
B(0,3,-5,STONE:0)
B(1,3,-5,STONE:0)
B(2,3,-5,STONE:0)
B(3,3,-5,STONE:0)
B(4,3,-5,STONE:0)
B(5,3,-5,STONE:0)
B(6,3,-5,STONE:0)
B(7,3,-5,STONE:0)
B(8,3,-5,STONE:0)
B(-7,3,-4,STONE:0)
B(-6,3,-4,STONE:0)
B(-5,3,-4,STONE:0)
B(-4,3,-4,STONE:0)
B(-3,3,-4,STONE:0)
B(-2,3,-4,STONE:0)
B(-1,3,-4,STONE:0)
B(0,3,-4,STONE:0)
B(1,3,-4,STONE:0)
B(2,3,-4,STONE:0)
B(3,3,-4,STONE:0)
B(4,3,-4,STONE:0)
B(5,3,-4,STONE:0)
B(6,3,-4,STONE:0)
B(7,3,-4,STONE:0)
B(8,3,-4,STONE:0)
B(-7,3,-3,STONE:0)
B(-6,3,-3,STONE:0)
B(-5,3,-3,STONE:0)
B(-4,3,-3,STONE:0)
B(-3,3,-3,STONE:0)
B(-2,3,-3,STONE:0)
B(-1,3,-3,STONE:0)
B(0,3,-3,STONE:0)
B(1,3,-3,STONE:0)
B(2,3,-3,STONE:0)
B(3,3,-3,STONE:0)
B(4,3,-3,STONE:0)
B(5,3,-3,STONE:0)
B(6,3,-3,STONE:0)
B(7,3,-3,STONE:0)
B(8,3,-3,STONE:0)
B(-7,3,-2,STONE:0)
B(-6,3,-2,STONE:0)
B(-5,3,-2,STONE:0)
B(-4,3,-2,STONE:0)
B(-3,3,-2,STONE:0)
B(-2,3,-2,STONE:0)
B(-1,3,-2,STONE:0)
B(0,3,-2,STONE:0)
B(1,3,-2,STONE:0)
B(2,3,-2,STONE:0)
B(3,3,-2,STONE:0)
B(4,3,-2,STONE:0)
B(5,3,-2,STONE:0)
B(6,3,-2,STONE:0)
B(7,3,-2,STONE:0)
B(8,3,-2,STONE:0)
B(-7,3,-1,STONE:0)
B(-6,3,-1,STONE:0)
B(-5,3,-1,STONE:0)
B(-4,3,-1,STONE:0)
B(-3,3,-1,STONE:0)
B(-2,3,-1,STONE:0)
B(-1,3,-1,STONE:0)
B(0,3,-1,STONE:0)
B(1,3,-1,STONE:0)
B(2,3,-1,STONE:0)
B(3,3,-1,STONE:0)
B(4,3,-1,STONE:0)
B(5,3,-1,STONE:0)
B(6,3,-1,STONE:0)
B(7,3,-1,STONE:0)
B(8,3,-1,STONE:0)
B(-7,3,0,STONE:0)
B(-6,3,0,STONE:0)
B(-5,3,0,STONE:0)
B(-4,3,0,STONE:0)
B(-3,3,0,STONE:0)
B(-2,3,0,STONE:0)
B(-1,3,0,STONE:0)
B(0,3,0,STONE:0)
B(1,3,0,STONE:0)
B(2,3,0,STONE:0)
B(3,3,0,STONE:0)
B(4,3,0,STONE:0)
B(5,3,0,STONE:0)
B(6,3,0,STONE:0)
B(7,3,0,STONE:0)
B(8,3,0,STONE:0)
B(-7,3,1,STONE:0)
B(-6,3,1,STONE:0)
B(-5,3,1,STONE:0)
B(-4,3,1,STONE:0)
B(-3,3,1,STONE:0)
B(-2,3,1,STONE:0)
B(-1,3,1,STONE:0)
B(0,3,1,STONE:0)
B(1,3,1,STONE:0)
B(2,3,1,STONE:0)
B(3,3,1,STONE:0)
B(4,3,1,STONE:0)
B(5,3,1,STONE:0)
B(6,3,1,STONE:0)
B(7,3,1,STONE:0)
B(8,3,1,STONE:0)
B(-7,3,2,STONE:0)
B(-6,3,2,STONE:0)
B(-5,3,2,STONE:0)
B(-4,3,2,STONE:0)
B(-3,3,2,STONE:0)
B(-2,3,2,STONE:0)
B(-1,3,2,STONE:0)
B(0,3,2,STONE:0)
B(1,3,2,STONE:0)
B(2,3,2,STONE:0)
B(3,3,2,STONE:0)
B(4,3,2,STONE:0)
B(5,3,2,STONE:0)
B(6,3,2,STONE:0)
B(7,3,2,STONE:0)
B(8,3,2,STONE:0)
B(-7,3,3,STONE:0)
B(-6,3,3,STONE:0)
B(-5,3,3,STONE:0)
B(-4,3,3,STONE:0)
B(-3,3,3,STONE:0)
B(-2,3,3,STONE:0)
B(-1,3,3,STONE:0)
B(0,3,3,STONE:0)
B(1,3,3,STONE:0)
B(2,3,3,STONE:0)
B(3,3,3,STONE:0)
B(4,3,3,STONE:0)
B(5,3,3,STONE:0)
B(6,3,3,STONE:0)
B(7,3,3,STONE:0)
B(8,3,3,STONE:0)
B(-7,3,4,STONE:0)
B(-6,3,4,STONE:0)
B(-5,3,4,STONE:0)
B(-4,3,4,STONE:0)
B(-3,3,4,STONE:0)
B(-2,3,4,STONE:0)
B(-1,3,4,STONE:0)
B(0,3,4,STONE:0)
B(1,3,4,STONE:0)
B(2,3,4,STONE:0)
B(3,3,4,STONE:0)
B(4,3,4,STONE:0)
B(5,3,4,STONE:0)
B(6,3,4,STONE:0)
B(7,3,4,STONE:0)
B(8,3,4,STONE:0)
B(-7,3,5,STONE:0)
B(-6,3,5,STONE:0)
B(-5,3,5,STONE:0)
B(-4,3,5,STONE:0)
B(-3,3,5,STONE:0)
B(-2,3,5,STONE:0)
B(-1,3,5,STONE:0)
B(0,3,5,STONE:0)
B(1,3,5,STONE:0)
B(2,3,5,STONE:0)
B(3,3,5,STONE:0)
B(4,3,5,STONE:0)
B(5,3,5,STONE:0)
B(6,3,5,STONE:0)
B(7,3,5,STONE:0)
B(8,3,5,STONE:0)
B(-7,3,6,STONE:0)
B(-6,3,6,STONE:0)
B(-5,3,6,STONE:0)
B(-4,3,6,STONE:0)
B(-3,3,6,STONE:0)
B(-2,3,6,STONE:0)
B(-1,3,6,STONE:0)
B(0,3,6,STONE:0)
B(1,3,6,STONE:0)
B(2,3,6,STONE:0)
B(3,3,6,STONE:0)
B(4,3,6,STONE:0)
B(5,3,6,STONE:0)
B(6,3,6,STONE:0)
B(7,3,6,STONE:0)
B(8,3,6,STONE:0)
B(-7,3,7,STONE:0)
B(-6,3,7,STONE:0)
B(-5,3,7,STONE:0)
B(-4,3,7,STONE:0)
B(-3,3,7,STONE:0)
B(-2,3,7,STONE:0)
B(-1,3,7,STONE:0)
B(0,3,7,STONE:0)
B(1,3,7,STONE:0)
B(2,3,7,STONE:0)
B(3,3,7,STONE:0)
B(4,3,7,STONE:0)
B(5,3,7,STONE:0)
B(6,3,7,STONE:0)
B(7,3,7,STONE:0)
B(8,3,7,STONE:0)
B(-7,3,8,STONE:0)
B(-6,3,8,STONE:0)
B(-5,3,8,STONE:0)
B(-4,3,8,STONE:0)
B(-3,3,8,STONE:0)
B(-2,3,8,STONE:0)
B(-1,3,8,STONE:0)
B(0,3,8,STONE:0)
B(1,3,8,STONE:0)
B(2,3,8,STONE:0)
B(3,3,8,STONE:0)
B(4,3,8,STONE:0)
B(5,3,8,STONE:0)
B(6,3,8,STONE:0)
B(7,3,8,STONE:0)
B(8,3,8,STONE:0)
B(-7,4,-7,STONE:0)
B(-6,4,-7,STONE:0)
B(-5,4,-7,STONE:0)
B(-4,4,-7,STONE:0)
B(-3,4,-7,STONE:0)
B(-2,4,-7,STONE:0)
B(-1,4,-7,STONE:0)
B(0,4,-7,STONE:0)
B(1,4,-7,STONE:0)
B(2,4,-7,STONE:0)
B(3,4,-7,STONE:0)
B(4,4,-7,STONE:0)
B(5,4,-7,STONE:0)
B(6,4,-7,STONE:0)
B(7,4,-7,STONE:0)
B(8,4,-7,STONE:0)
B(-7,4,-6,STONE:0)
B(-6,4,-6,STONE:0)
B(-5,4,-6,STONE:0)
B(-4,4,-6,STONE:0)
B(-3,4,-6,STONE:0)
B(-2,4,-6,STONE:0)
B(-1,4,-6,STONE:0)
B(0,4,-6,STONE:0)
B(1,4,-6,STONE:0)
B(2,4,-6,STONE:0)
B(3,4,-6,STONE:0)
B(4,4,-6,STONE:0)
B(5,4,-6,STONE:0)
B(6,4,-6,STONE:0)
B(7,4,-6,STONE:0)
B(8,4,-6,STONE:0)
B(-7,4,-5,STONE:0)
B(-6,4,-5,STONE:0)
B(-5,4,-5,STONE:0)
B(-4,4,-5,STONE:0)
B(-3,4,-5,STONE:0)
B(-2,4,-5,STONE:0)
B(-1,4,-5,STONE:0)
B(0,4,-5,STONE:0)
B(1,4,-5,STONE:0)
B(2,4,-5,STONE:0)
B(3,4,-5,STONE:0)
B(4,4,-5,STONE:0)
B(5,4,-5,STONE:0)
B(6,4,-5,STONE:0)
B(7,4,-5,STONE:0)
B(8,4,-5,STONE:0)
B(-7,4,-4,STONE:0)
B(-6,4,-4,STONE:0)
B(-5,4,-4,STONE:0)
B(-4,4,-4,STONE:0)
B(-3,4,-4,STONE:0)
B(-2,4,-4,STONE:0)
B(-1,4,-4,STONE:0)
B(0,4,-4,STONE:0)
B(1,4,-4,STONE:0)
B(2,4,-4,STONE:0)
B(3,4,-4,STONE:0)
B(4,4,-4,STONE:0)
B(5,4,-4,STONE:0)
B(6,4,-4,STONE:0)
B(7,4,-4,STONE:0)
B(8,4,-4,STONE:0)
B(-7,4,-3,STONE:0)
B(-6,4,-3,STONE:0)
B(-5,4,-3,STONE:0)
B(-4,4,-3,STONE:0)
B(-3,4,-3,STONE:0)
B(-2,4,-3,STONE:0)
B(-1,4,-3,STONE:0)
B(0,4,-3,STONE:0)
B(1,4,-3,STONE:0)
B(2,4,-3,STONE:0)
B(3,4,-3,STONE:0)
B(4,4,-3,STONE:0)
B(5,4,-3,STONE:0)
B(6,4,-3,STONE:0)
B(7,4,-3,STONE:0)
B(8,4,-3,STONE:0)
B(-7,4,-2,STONE:0)
B(-6,4,-2,STONE:0)
B(-5,4,-2,STONE:0)
B(-4,4,-2,STONE:0)
B(-3,4,-2,STONE:0)
B(-2,4,-2,STONE:0)
B(-1,4,-2,STONE:0)
B(0,4,-2,STONE:0)
B(1,4,-2,STONE:0)
B(2,4,-2,STONE:0)
B(3,4,-2,STONE:0)
B(4,4,-2,STONE:0)
B(5,4,-2,STONE:0)
B(6,4,-2,STONE:0)
B(7,4,-2,STONE:0)
B(8,4,-2,STONE:0)
B(-7,4,-1,STONE:0)
B(-6,4,-1,STONE:0)
B(-5,4,-1,STONE:0)
B(-4,4,-1,STONE:0)
B(-3,4,-1,STONE:0)
B(-2,4,-1,STONE:0)
B(-1,4,-1,STONE:0)
B(0,4,-1,STONE:0)
B(1,4,-1,STONE:0)
B(2,4,-1,STONE:0)
B(3,4,-1,STONE:0)
B(4,4,-1,STONE:0)
B(5,4,-1,STONE:0)
B(6,4,-1,STONE:0)
B(7,4,-1,STONE:0)
B(8,4,-1,STONE:0)
B(-7,4,0,STONE:0)
B(-6,4,0,STONE:0)
B(-5,4,0,STONE:0)
B(-4,4,0,STONE:0)
B(-3,4,0,STONE:0)
B(-2,4,0,STONE:0)
B(-1,4,0,STONE:0)
B(0,4,0,STONE:0)
B(1,4,0,STONE:0)
B(2,4,0,STONE:0)
B(3,4,0,STONE:0)
B(4,4,0,STONE:0)
B(5,4,0,STONE:0)
B(6,4,0,STONE:0)
B(7,4,0,STONE:0)
B(8,4,0,STONE:0)
B(-7,4,1,STONE:0)
B(-6,4,1,STONE:0)
B(-5,4,1,STONE:0)
B(-4,4,1,STONE:0)
B(-3,4,1,STONE:0)
B(-2,4,1,STONE:0)
B(-1,4,1,STONE:0)
B(0,4,1,STONE:0)
B(1,4,1,STONE:0)
B(2,4,1,STONE:0)
B(3,4,1,STONE:0)
B(4,4,1,STONE:0)
B(5,4,1,STONE:0)
B(6,4,1,STONE:0)
B(7,4,1,STONE:0)
B(8,4,1,STONE:0)
B(-7,4,2,STONE:0)
B(-6,4,2,STONE:0)
B(-5,4,2,STONE:0)
B(-4,4,2,STONE:0)
B(-3,4,2,STONE:0)
B(-2,4,2,STONE:0)
B(-1,4,2,STONE:0)
B(0,4,2,STONE:0)
B(1,4,2,STONE:0)
B(2,4,2,STONE:0)
B(3,4,2,STONE:0)
B(4,4,2,STONE:0)
B(5,4,2,STONE:0)
B(6,4,2,STONE:0)
B(7,4,2,STONE:0)
B(8,4,2,STONE:0)
B(-7,4,3,STONE:0)
B(-6,4,3,STONE:0)
B(-5,4,3,STONE:0)
B(-4,4,3,STONE:0)
B(-3,4,3,STONE:0)
B(-2,4,3,STONE:0)
B(-1,4,3,STONE:0)
B(0,4,3,STONE:0)
B(1,4,3,STONE:0)
B(2,4,3,STONE:0)
B(3,4,3,STONE:0)
B(4,4,3,STONE:0)
B(5,4,3,STONE:0)
B(6,4,3,STONE:0)
B(7,4,3,STONE:0)
B(8,4,3,STONE:0)
B(-7,4,4,STONE:0)
B(-6,4,4,STONE:0)
B(-5,4,4,STONE:0)
B(-4,4,4,STONE:0)
B(-3,4,4,STONE:0)
B(-2,4,4,STONE:0)
B(-1,4,4,STONE:0)
B(0,4,4,STONE:0)
B(1,4,4,STONE:0)
B(2,4,4,STONE:0)
B(3,4,4,STONE:0)
B(4,4,4,STONE:0)
B(5,4,4,STONE:0)
B(6,4,4,STONE:0)
B(7,4,4,STONE:0)
B(8,4,4,STONE:0)
B(-7,4,5,STONE:0)
B(-6,4,5,STONE:0)
B(-5,4,5,STONE:0)
B(-4,4,5,STONE:0)
B(-3,4,5,STONE:0)
B(-2,4,5,STONE:0)
B(-1,4,5,STONE:0)
B(0,4,5,STONE:0)
B(1,4,5,STONE:0)
B(2,4,5,STONE:0)
B(3,4,5,STONE:0)
B(4,4,5,STONE:0)
B(5,4,5,STONE:0)
B(6,4,5,STONE:0)
B(7,4,5,STONE:0)
B(8,4,5,STONE:0)
B(-7,4,6,STONE:0)
B(-6,4,6,STONE:0)
B(-5,4,6,STONE:0)
B(-4,4,6,STONE:0)
B(-3,4,6,STONE:0)
B(-2,4,6,STONE:0)
B(-1,4,6,STONE:0)
B(0,4,6,STONE:0)
B(1,4,6,STONE:0)
B(2,4,6,STONE:0)
B(3,4,6,STONE:0)
B(4,4,6,STONE:0)
B(5,4,6,STONE:0)
B(6,4,6,STONE:0)
B(7,4,6,STONE:0)
B(8,4,6,STONE:0)
B(-7,4,7,STONE:0)
B(-6,4,7,STONE:0)
B(-5,4,7,STONE:0)
B(-4,4,7,STONE:0)
B(-3,4,7,STONE:0)
B(-2,4,7,STONE:0)
B(-1,4,7,STONE:0)
B(0,4,7,STONE:0)
B(1,4,7,STONE:0)
B(2,4,7,STONE:0)
B(3,4,7,STONE:0)
B(4,4,7,STONE:0)
B(5,4,7,STONE:0)
B(6,4,7,STONE:0)
B(7,4,7,STONE:0)
B(8,4,7,STONE:0)
B(-7,4,8,STONE:0)
B(-6,4,8,STONE:0)
B(-5,4,8,STONE:0)
B(-4,4,8,STONE:0)
B(-3,4,8,STONE:0)
B(-2,4,8,STONE:0)
B(-1,4,8,STONE:0)
B(0,4,8,STONE:0)
B(1,4,8,STONE:0)
B(2,4,8,STONE:0)
B(3,4,8,STONE:0)
B(4,4,8,STONE:0)
B(5,4,8,STONE:0)
B(6,4,8,STONE:0)
B(7,4,8,STONE:0)
B(8,4,8,STONE:0)
B(-7,5,-7,STONE:0)
B(-6,5,-7,STONE:0)
B(-5,5,-7,STONE:0)
B(-4,5,-7,STONE:0)
B(-3,5,-7,STONE:0)
B(-2,5,-7,STONE:0)
B(-1,5,-7,STONE:0)
B(0,5,-7,STONE:0)
B(1,5,-7,STONE:0)
B(2,5,-7,STONE:0)
B(3,5,-7,STONE:0)
B(4,5,-7,STONE:0)
B(5,5,-7,STONE:0)
B(6,5,-7,STONE:0)
B(7,5,-7,STONE:0)
B(8,5,-7,STONE:0)
B(-7,5,-6,STONE:0)
B(-6,5,-6,STONE:0)
B(-5,5,-6,STONE:0)
B(-4,5,-6,STONE:0)
B(-3,5,-6,STONE:0)
B(-2,5,-6,STONE:0)
B(-1,5,-6,STONE:0)
B(0,5,-6,STONE:0)
B(1,5,-6,STONE:0)
B(2,5,-6,STONE:0)
B(3,5,-6,STONE:0)
B(4,5,-6,STONE:0)
B(5,5,-6,STONE:0)
B(6,5,-6,STONE:0)
B(7,5,-6,STONE:0)
B(8,5,-6,STONE:0)
B(-7,5,-5,STONE:0)
B(-6,5,-5,STONE:0)
B(-5,5,-5,STONE:0)
B(-4,5,-5,STONE:0)
B(-3,5,-5,STONE:0)
B(-2,5,-5,STONE:0)
B(-1,5,-5,STONE:0)
B(0,5,-5,STONE:0)
B(1,5,-5,STONE:0)
B(2,5,-5,STONE:0)
B(3,5,-5,STONE:0)
B(4,5,-5,STONE:0)
B(5,5,-5,STONE:0)
B(6,5,-5,STONE:0)
B(7,5,-5,STONE:0)
B(8,5,-5,STONE:0)
B(-7,5,-4,STONE:0)
B(-6,5,-4,STONE:0)
B(-5,5,-4,STONE:0)
B(-4,5,-4,STONE:0)
B(-3,5,-4,STONE:0)
B(-2,5,-4,STONE:0)
B(-1,5,-4,STONE:0)
B(0,5,-4,STONE:0)
B(1,5,-4,STONE:0)
B(2,5,-4,STONE:0)
B(3,5,-4,STONE:0)
B(4,5,-4,STONE:0)
B(5,5,-4,STONE:0)
B(6,5,-4,STONE:0)
B(7,5,-4,STONE:0)
B(8,5,-4,STONE:0)
B(-7,5,-3,STONE:0)
B(-6,5,-3,STONE:0)
B(-5,5,-3,STONE:0)
B(-4,5,-3,STONE:0)
B(-3,5,-3,STONE:0)
B(-2,5,-3,STONE:0)
B(-1,5,-3,STONE:0)
B(0,5,-3,STONE:0)
B(1,5,-3,STONE:0)
B(2,5,-3,STONE:0)
B(3,5,-3,STONE:0)
B(4,5,-3,STONE:0)
B(5,5,-3,STONE:0)
B(6,5,-3,STONE:0)
B(7,5,-3,STONE:0)
B(8,5,-3,STONE:0)
B(-7,5,-2,STONE:0)
B(-6,5,-2,STONE:0)
B(-5,5,-2,STONE:0)
B(-4,5,-2,STONE:0)
B(-3,5,-2,STONE:0)
B(-2,5,-2,STONE:0)
B(-1,5,-2,STONE:0)
B(0,5,-2,STONE:0)
B(1,5,-2,STONE:0)
B(2,5,-2,STONE:0)
B(3,5,-2,STONE:0)
B(4,5,-2,STONE:0)
B(5,5,-2,STONE:0)
B(6,5,-2,STONE:0)
B(7,5,-2,STONE:0)
B(8,5,-2,STONE:0)
B(-7,5,-1,STONE:0)
B(-6,5,-1,STONE:0)
B(-5,5,-1,STONE:0)
B(-4,5,-1,STONE:0)
B(-3,5,-1,STONE:0)
B(-2,5,-1,STONE:0)
B(-1,5,-1,STONE:0)
B(0,5,-1,STONE:0)
B(1,5,-1,STONE:0)
B(2,5,-1,STONE:0)
B(3,5,-1,STONE:0)
B(4,5,-1,STONE:0)
B(5,5,-1,STONE:0)
B(6,5,-1,STONE:0)
B(7,5,-1,STONE:0)
B(8,5,-1,STONE:0)
B(-7,5,0,STONE:0)
B(-6,5,0,STONE:0)
B(-5,5,0,STONE:0)
B(-4,5,0,STONE:0)
B(-3,5,0,STONE:0)
B(-2,5,0,STONE:0)
B(-1,5,0,STONE:0)
B(0,5,0,STONE:0)
B(1,5,0,STONE:0)
B(2,5,0,STONE:0)
B(3,5,0,STONE:0)
B(4,5,0,STONE:0)
B(5,5,0,STONE:0)
B(6,5,0,STONE:0)
B(7,5,0,STONE:0)
B(8,5,0,STONE:0)
B(-7,5,1,STONE:0)
B(-6,5,1,STONE:0)
B(-5,5,1,STONE:0)
B(-4,5,1,STONE:0)
B(-3,5,1,STONE:0)
B(-2,5,1,STONE:0)
B(-1,5,1,STONE:0)
B(0,5,1,STONE:0)
B(1,5,1,STONE:0)
B(2,5,1,STONE:0)
B(3,5,1,STONE:0)
B(4,5,1,STONE:0)
B(5,5,1,STONE:0)
B(6,5,1,STONE:0)
B(7,5,1,STONE:0)
B(8,5,1,STONE:0)
B(-7,5,2,STONE:0)
B(-6,5,2,STONE:0)
B(-5,5,2,STONE:0)
B(-4,5,2,STONE:0)
B(-3,5,2,STONE:0)
B(-2,5,2,STONE:0)
B(-1,5,2,STONE:0)
B(0,5,2,STONE:0)
B(1,5,2,STONE:0)
B(2,5,2,STONE:0)
B(3,5,2,STONE:0)
B(4,5,2,STONE:0)
B(5,5,2,STONE:0)
B(6,5,2,STONE:0)
B(7,5,2,STONE:0)
B(8,5,2,STONE:0)
B(-7,5,3,STONE:0)
B(-6,5,3,STONE:0)
B(-5,5,3,STONE:0)
B(-4,5,3,STONE:0)
B(-3,5,3,STONE:0)
B(-2,5,3,STONE:0)
B(-1,5,3,STONE:0)
B(0,5,3,STONE:0)
B(1,5,3,STONE:0)
B(2,5,3,STONE:0)
B(3,5,3,STONE:0)
B(4,5,3,STONE:0)
B(5,5,3,STONE:0)
B(6,5,3,STONE:0)
B(7,5,3,STONE:0)
B(8,5,3,STONE:0)
B(-7,5,4,STONE:0)
B(-6,5,4,STONE:0)
B(-5,5,4,STONE:0)
B(-4,5,4,STONE:0)
B(-3,5,4,STONE:0)
B(-2,5,4,STONE:0)
B(-1,5,4,STONE:0)
B(0,5,4,STONE:0)
B(1,5,4,STONE:0)
B(2,5,4,STONE:0)
B(3,5,4,STONE:0)
B(4,5,4,STONE:0)
B(5,5,4,STONE:0)
B(6,5,4,STONE:0)
B(7,5,4,STONE:0)
B(8,5,4,STONE:0)
B(-7,5,5,STONE:0)
B(-6,5,5,STONE:0)
B(-5,5,5,STONE:0)
B(-4,5,5,STONE:0)
B(-3,5,5,STONE:0)
B(-2,5,5,STONE:0)
B(-1,5,5,STONE:0)
B(0,5,5,STONE:0)
B(1,5,5,STONE:0)
B(2,5,5,STONE:0)
B(3,5,5,STONE:0)
B(4,5,5,STONE:0)
B(5,5,5,STONE:0)
B(6,5,5,STONE:0)
B(7,5,5,STONE:0)
B(8,5,5,STONE:0)
B(-7,5,6,STONE:0)
B(-6,5,6,STONE:0)
B(-5,5,6,STONE:0)
B(-4,5,6,STONE:0)
B(-3,5,6,STONE:0)
B(-2,5,6,STONE:0)
B(-1,5,6,STONE:0)
B(0,5,6,STONE:0)
B(1,5,6,STONE:0)
B(2,5,6,STONE:0)
B(3,5,6,STONE:0)
B(4,5,6,STONE:0)
B(5,5,6,STONE:0)
B(6,5,6,STONE:0)
B(7,5,6,STONE:0)
B(8,5,6,STONE:0)
B(-7,5,7,STONE:0)
B(-6,5,7,STONE:0)
B(-5,5,7,STONE:0)
B(-4,5,7,STONE:0)
B(-3,5,7,STONE:0)
B(-2,5,7,STONE:0)
B(-1,5,7,STONE:0)
B(0,5,7,STONE:0)
B(1,5,7,STONE:0)
B(2,5,7,STONE:0)
B(3,5,7,STONE:0)
B(4,5,7,STONE:0)
B(5,5,7,STONE:0)
B(6,5,7,STONE:0)
B(7,5,7,STONE:0)
B(8,5,7,STONE:0)
B(-7,5,8,STONE:0)
B(-6,5,8,STONE:0)
B(-5,5,8,STONE:0)
B(-4,5,8,STONE:0)
B(-3,5,8,STONE:0)
B(-2,5,8,STONE:0)
B(-1,5,8,STONE:0)
B(0,5,8,STONE:0)
B(1,5,8,STONE:0)
B(2,5,8,STONE:0)
B(3,5,8,STONE:0)
B(4,5,8,STONE:0)
B(5,5,8,STONE:0)
B(6,5,8,STONE:0)
B(7,5,8,STONE:0)
B(8,5,8,STONE:0)
B(-7,6,-7,STONE:0)
B(-6,6,-7,STONE:0)
B(-5,6,-7,STONE:0)
B(-4,6,-7,STONE:0)
B(-3,6,-7,STONE:0)
B(-2,6,-7,STONE:0)
B(-1,6,-7,STONE:0)
B(0,6,-7,STONE:0)
B(1,6,-7,STONE:0)
B(2,6,-7,STONE:0)
B(3,6,-7,STONE:0)
B(4,6,-7,STONE:0)
B(5,6,-7,STONE:0)
B(6,6,-7,STONE:0)
B(7,6,-7,STONE:0)
B(8,6,-7,STONE:0)
B(-7,6,-6,STONE:0)
B(-6,6,-6,STONE:0)
B(-5,6,-6,STONE:0)
B(-4,6,-6,STONE:0)
B(-3,6,-6,STONE:0)
B(-2,6,-6,STONE:0)
B(-1,6,-6,STONE:0)
B(0,6,-6,STONE:0)
B(1,6,-6,STONE:0)
B(2,6,-6,STONE:0)
B(3,6,-6,STONE:0)
B(4,6,-6,STONE:0)
B(5,6,-6,STONE:0)
B(6,6,-6,STONE:0)
B(7,6,-6,STONE:0)
B(8,6,-6,STONE:0)
B(-7,6,-5,STONE:0)
B(-6,6,-5,STONE:0)
B(-5,6,-5,STONE:0)
B(-4,6,-5,STONE:0)
B(-3,6,-5,STONE:0)
B(-2,6,-5,STONE:0)
B(-1,6,-5,STONE:0)
B(0,6,-5,STONE:0)
B(1,6,-5,STONE:0)
B(2,6,-5,STONE:0)
B(3,6,-5,STONE:0)
B(4,6,-5,STONE:0)
B(5,6,-5,STONE:0)
B(6,6,-5,STONE:0)
B(7,6,-5,STONE:0)
B(8,6,-5,STONE:0)
B(-7,6,-4,STONE:0)
B(-6,6,-4,STONE:0)
B(-5,6,-4,STONE:0)
B(-4,6,-4,STONE:0)
B(-3,6,-4,STONE:0)
B(-2,6,-4,STONE:0)
B(-1,6,-4,STONE:0)
B(0,6,-4,STONE:0)
B(1,6,-4,STONE:0)
B(2,6,-4,STONE:0)
B(3,6,-4,STONE:0)
B(4,6,-4,STONE:0)
B(5,6,-4,STONE:0)
B(6,6,-4,STONE:0)
B(7,6,-4,STONE:0)
B(8,6,-4,STONE:0)
B(-7,6,-3,STONE:0)
B(-6,6,-3,STONE:0)
B(-5,6,-3,STONE:0)
B(-4,6,-3,STONE:0)
B(-3,6,-3,STONE:0)
B(-2,6,-3,STONE:0)
B(-1,6,-3,STONE:0)
B(0,6,-3,STONE:0)
B(1,6,-3,STONE:0)
B(2,6,-3,STONE:0)
B(3,6,-3,STONE:0)
B(4,6,-3,STONE:0)
B(5,6,-3,STONE:0)
B(6,6,-3,STONE:0)
B(7,6,-3,STONE:0)
B(8,6,-3,STONE:0)
B(-7,6,-2,STONE:0)
B(-6,6,-2,STONE:0)
B(-5,6,-2,STONE:0)
B(-4,6,-2,STONE:0)
B(-3,6,-2,STONE:0)
B(-2,6,-2,STONE:0)
B(-1,6,-2,STONE:0)
B(0,6,-2,STONE:0)
B(1,6,-2,STONE:0)
B(2,6,-2,STONE:0)
B(3,6,-2,STONE:0)
B(4,6,-2,STONE:0)
B(5,6,-2,STONE:0)
B(6,6,-2,STONE:0)
B(7,6,-2,STONE:0)
B(8,6,-2,STONE:0)
B(-7,6,-1,STONE:0)
B(-6,6,-1,STONE:0)
B(-5,6,-1,STONE:0)
B(-4,6,-1,STONE:0)
B(-3,6,-1,STONE:0)
B(-2,6,-1,STONE:0)
B(-1,6,-1,STONE:0)
B(0,6,-1,STONE:0)
B(1,6,-1,STONE:0)
B(2,6,-1,STONE:0)
B(3,6,-1,STONE:0)
B(4,6,-1,STONE:0)
B(5,6,-1,STONE:0)
B(6,6,-1,STONE:0)
B(7,6,-1,STONE:0)
B(8,6,-1,STONE:0)
B(-7,6,0,STONE:0)
B(-6,6,0,STONE:0)
B(-5,6,0,STONE:0)
B(-4,6,0,STONE:0)
B(-3,6,0,STONE:0)
B(-2,6,0,STONE:0)
B(-1,6,0,STONE:0)
B(0,6,0,STONE:0)
B(1,6,0,STONE:0)
B(2,6,0,STONE:0)
B(3,6,0,STONE:0)
B(4,6,0,STONE:0)
B(5,6,0,STONE:0)
B(6,6,0,STONE:0)
B(7,6,0,STONE:0)
B(8,6,0,STONE:0)
B(-7,6,1,STONE:0)
B(-6,6,1,STONE:0)
B(-5,6,1,STONE:0)
B(-4,6,1,STONE:0)
B(-3,6,1,STONE:0)
B(-2,6,1,STONE:0)
B(-1,6,1,STONE:0)
B(0,6,1,STONE:0)
B(1,6,1,STONE:0)
B(2,6,1,STONE:0)
B(3,6,1,STONE:0)
B(4,6,1,STONE:0)
B(5,6,1,STONE:0)
B(6,6,1,STONE:0)
B(7,6,1,STONE:0)
B(8,6,1,STONE:0)
B(-7,6,2,STONE:0)
B(-6,6,2,STONE:0)
B(-5,6,2,STONE:0)
B(-4,6,2,STONE:0)
B(-3,6,2,STONE:0)
B(-2,6,2,STONE:0)
B(-1,6,2,STONE:0)
B(0,6,2,STONE:0)
B(1,6,2,STONE:0)
B(2,6,2,STONE:0)
B(3,6,2,STONE:0)
B(4,6,2,STONE:0)
B(5,6,2,STONE:0)
B(6,6,2,STONE:0)
B(7,6,2,STONE:0)
B(8,6,2,STONE:0)
B(-7,6,3,STONE:0)
B(-6,6,3,STONE:0)
B(-5,6,3,STONE:0)
B(-4,6,3,STONE:0)
B(-3,6,3,STONE:0)
B(-2,6,3,STONE:0)
B(-1,6,3,STONE:0)
B(0,6,3,STONE:0)
B(1,6,3,STONE:0)
B(2,6,3,STONE:0)
B(3,6,3,STONE:0)
B(4,6,3,STONE:0)
B(5,6,3,STONE:0)
B(6,6,3,STONE:0)
B(7,6,3,STONE:0)
B(8,6,3,STONE:0)
B(-7,6,4,STONE:0)
B(-6,6,4,STONE:0)
B(-5,6,4,STONE:0)
B(-4,6,4,STONE:0)
B(-3,6,4,STONE:0)
B(-2,6,4,STONE:0)
B(-1,6,4,STONE:0)
B(0,6,4,STONE:0)
B(1,6,4,STONE:0)
B(2,6,4,STONE:0)
B(3,6,4,STONE:0)
B(4,6,4,STONE:0)
B(5,6,4,STONE:0)
B(6,6,4,STONE:0)
B(7,6,4,STONE:0)
B(8,6,4,STONE:0)
B(-7,6,5,STONE:0)
B(-6,6,5,STONE:0)
B(-5,6,5,STONE:0)
B(-4,6,5,STONE:0)
B(-3,6,5,STONE:0)
B(-2,6,5,STONE:0)
B(-1,6,5,STONE:0)
B(0,6,5,STONE:0)
B(1,6,5,STONE:0)
B(2,6,5,STONE:0)
B(3,6,5,STONE:0)
B(4,6,5,STONE:0)
B(5,6,5,STONE:0)
B(6,6,5,STONE:0)
B(7,6,5,STONE:0)
B(8,6,5,STONE:0)
B(-7,6,6,STONE:0)
B(-6,6,6,STONE:0)
B(-5,6,6,STONE:0)
B(-4,6,6,STONE:0)
B(-3,6,6,STONE:0)
B(-2,6,6,STONE:0)
B(-1,6,6,STONE:0)
B(0,6,6,STONE:0)
B(1,6,6,STONE:0)
B(2,6,6,STONE:0)
B(3,6,6,STONE:0)
B(4,6,6,STONE:0)
B(5,6,6,STONE:0)
B(6,6,6,STONE:0)
B(7,6,6,STONE:0)
B(8,6,6,STONE:0)
B(-7,6,7,STONE:0)
B(-6,6,7,STONE:0)
B(-5,6,7,STONE:0)
B(-4,6,7,STONE:0)
B(-3,6,7,STONE:0)
B(-2,6,7,STONE:0)
B(-1,6,7,STONE:0)
B(0,6,7,STONE:0)
B(1,6,7,STONE:0)
B(2,6,7,STONE:0)
B(3,6,7,STONE:0)
B(4,6,7,STONE:0)
B(5,6,7,STONE:0)
B(6,6,7,STONE:0)
B(7,6,7,STONE:0)
B(8,6,7,STONE:0)
B(-7,6,8,STONE:0)
B(-6,6,8,STONE:0)
B(-5,6,8,STONE:0)
B(-4,6,8,STONE:0)
B(-3,6,8,STONE:0)
B(-2,6,8,STONE:0)
B(-1,6,8,STONE:0)
B(0,6,8,STONE:0)
B(1,6,8,STONE:0)
B(2,6,8,STONE:0)
B(3,6,8,STONE:0)
B(4,6,8,STONE:0)
B(5,6,8,STONE:0)
B(6,6,8,STONE:0)
B(7,6,8,STONE:0)
B(8,6,8,STONE:0)
B(-7,7,-7,STONE:0)
B(-6,7,-7,STONE:0)
B(-5,7,-7,STONE:0)
B(-4,7,-7,STONE:0)
B(-3,7,-7,STONE:0)
B(-2,7,-7,STONE:0)
B(-1,7,-7,STONE:0)
B(0,7,-7,STONE:0)
B(1,7,-7,STONE:0)
B(2,7,-7,STONE:0)
B(3,7,-7,STONE:0)
B(4,7,-7,STONE:0)
B(5,7,-7,STONE:0)
B(6,7,-7,STONE:0)
B(7,7,-7,STONE:0)
B(8,7,-7,STONE:0)
B(-7,7,-6,STONE:0)
B(-6,7,-6,STONE:0)
B(-5,7,-6,STONE:0)
B(-4,7,-6,STONE:0)
B(-3,7,-6,STONE:0)
B(-2,7,-6,STONE:0)
B(-1,7,-6,STONE:0)
B(0,7,-6,STONE:0)
B(1,7,-6,STONE:0)
B(2,7,-6,STONE:0)
B(3,7,-6,STONE:0)
B(4,7,-6,STONE:0)
B(5,7,-6,STONE:0)
B(6,7,-6,STONE:0)
B(7,7,-6,STONE:0)
B(8,7,-6,STONE:0)
B(-7,7,-5,STONE:0)
B(-6,7,-5,STONE:0)
B(-5,7,-5,STONE:0)
B(-4,7,-5,STONE:0)
B(-3,7,-5,STONE:0)
B(-2,7,-5,STONE:0)
B(-1,7,-5,STONE:0)
B(0,7,-5,STONE:0)
B(1,7,-5,STONE:0)
B(2,7,-5,STONE:0)
B(3,7,-5,STONE:0)
B(4,7,-5,STONE:0)
B(5,7,-5,STONE:0)
B(6,7,-5,STONE:0)
B(7,7,-5,STONE:0)
B(8,7,-5,STONE:0)
B(-7,7,-4,STONE:0)
B(-6,7,-4,STONE:0)
B(-5,7,-4,STONE:0)
B(-4,7,-4,STONE:0)
B(-3,7,-4,STONE:0)
B(-2,7,-4,STONE:0)
B(-1,7,-4,STONE:0)
B(0,7,-4,STONE:0)
B(1,7,-4,STONE:0)
B(2,7,-4,STONE:0)
B(3,7,-4,STONE:0)
B(4,7,-4,STONE:0)
B(5,7,-4,STONE:0)
B(6,7,-4,STONE:0)
B(7,7,-4,STONE:0)
B(8,7,-4,STONE:0)
B(-7,7,-3,STONE:0)
B(-6,7,-3,STONE:0)
B(-5,7,-3,STONE:0)
B(-4,7,-3,STONE:0)
B(-3,7,-3,STONE:0)
B(-2,7,-3,STONE:0)
B(-1,7,-3,STONE:0)
B(0,7,-3,STONE:0)
B(1,7,-3,STONE:0)
B(2,7,-3,STONE:0)
B(3,7,-3,STONE:0)
B(4,7,-3,STONE:0)
B(5,7,-3,STONE:0)
B(6,7,-3,STONE:0)
B(7,7,-3,STONE:0)
B(8,7,-3,STONE:0)
B(-7,7,-2,STONE:0)
B(-6,7,-2,STONE:0)
B(-5,7,-2,STONE:0)
B(-4,7,-2,STONE:0)
B(-3,7,-2,STONE:0)
B(-2,7,-2,STONE:0)
B(-1,7,-2,STONE:0)
B(0,7,-2,STONE:0)
B(1,7,-2,STONE:0)
B(2,7,-2,STONE:0)
B(3,7,-2,STONE:0)
B(4,7,-2,STONE:0)
B(5,7,-2,STONE:0)
B(6,7,-2,STONE:0)
B(7,7,-2,STONE:0)
B(8,7,-2,STONE:0)
B(-7,7,-1,STONE:0)
B(-6,7,-1,STONE:0)
B(-5,7,-1,STONE:0)
B(-4,7,-1,STONE:0)
B(-3,7,-1,STONE:0)
B(-2,7,-1,STONE:0)
B(-1,7,-1,STONE:0)
B(0,7,-1,STONE:0)
B(1,7,-1,STONE:0)
B(2,7,-1,STONE:0)
B(3,7,-1,STONE:0)
B(4,7,-1,STONE:0)
B(5,7,-1,STONE:0)
B(6,7,-1,STONE:0)
B(7,7,-1,STONE:0)
B(8,7,-1,STONE:0)
B(-7,7,0,STONE:0)
B(-6,7,0,STONE:0)
B(-5,7,0,STONE:0)
B(-4,7,0,STONE:0)
B(-3,7,0,STONE:0)
B(-2,7,0,STONE:0)
B(-1,7,0,STONE:0)
B(0,7,0,STONE:0)
B(1,7,0,STONE:0)
B(2,7,0,STONE:0)
B(3,7,0,STONE:0)
B(4,7,0,STONE:0)
B(5,7,0,STONE:0)
B(6,7,0,STONE:0)
B(7,7,0,STONE:0)
B(8,7,0,STONE:0)
B(-7,7,1,STONE:0)
B(-6,7,1,STONE:0)
B(-5,7,1,STONE:0)
B(-4,7,1,STONE:0)
B(-3,7,1,STONE:0)
B(-2,7,1,STONE:0)
B(-1,7,1,STONE:0)
B(0,7,1,STONE:0)
B(1,7,1,STONE:0)
B(2,7,1,STONE:0)
B(3,7,1,STONE:0)
B(4,7,1,STONE:0)
B(5,7,1,STONE:0)
B(6,7,1,STONE:0)
B(7,7,1,STONE:0)
B(8,7,1,STONE:0)
B(-7,7,2,STONE:0)
B(-6,7,2,STONE:0)
B(-5,7,2,STONE:0)
B(-4,7,2,STONE:0)
B(-3,7,2,STONE:0)
B(-2,7,2,STONE:0)
B(-1,7,2,STONE:0)
B(0,7,2,STONE:0)
B(1,7,2,STONE:0)
B(2,7,2,STONE:0)
B(3,7,2,STONE:0)
B(4,7,2,STONE:0)
B(5,7,2,STONE:0)
B(6,7,2,STONE:0)
B(7,7,2,STONE:0)
B(8,7,2,STONE:0)
B(-7,7,3,STONE:0)
B(-6,7,3,STONE:0)
B(-5,7,3,STONE:0)
B(-4,7,3,STONE:0)
B(-3,7,3,STONE:0)
B(-2,7,3,STONE:0)
B(-1,7,3,STONE:0)
B(0,7,3,STONE:0)
B(1,7,3,STONE:0)
B(2,7,3,STONE:0)
B(3,7,3,STONE:0)
B(4,7,3,STONE:0)
B(5,7,3,STONE:0)
B(6,7,3,STONE:0)
B(7,7,3,STONE:0)
B(8,7,3,STONE:0)
B(-7,7,4,STONE:0)
B(-6,7,4,STONE:0)
B(-5,7,4,STONE:0)
B(-4,7,4,STONE:0)
B(-3,7,4,STONE:0)
B(-2,7,4,STONE:0)
B(-1,7,4,STONE:0)
B(0,7,4,STONE:0)
B(1,7,4,STONE:0)
B(2,7,4,STONE:0)
B(3,7,4,STONE:0)
B(4,7,4,STONE:0)
B(5,7,4,STONE:0)
B(6,7,4,STONE:0)
B(7,7,4,STONE:0)
B(8,7,4,STONE:0)
B(-7,7,5,STONE:0)
B(-6,7,5,STONE:0)
B(-5,7,5,STONE:0)
B(-4,7,5,STONE:0)
B(-3,7,5,STONE:0)
B(-2,7,5,STONE:0)
B(-1,7,5,STONE:0)
B(0,7,5,STONE:0)
B(1,7,5,STONE:0)
B(2,7,5,STONE:0)
B(3,7,5,STONE:0)
B(4,7,5,STONE:0)
B(5,7,5,STONE:0)
B(6,7,5,STONE:0)
B(7,7,5,STONE:0)
B(8,7,5,STONE:0)
B(-7,7,6,STONE:0)
B(-6,7,6,STONE:0)
B(-5,7,6,STONE:0)
B(-4,7,6,STONE:0)
B(-3,7,6,STONE:0)
B(-2,7,6,STONE:0)
B(-1,7,6,STONE:0)
B(0,7,6,STONE:0)
B(1,7,6,STONE:0)
B(2,7,6,STONE:0)
B(3,7,6,STONE:0)
B(4,7,6,STONE:0)
B(5,7,6,STONE:0)
B(6,7,6,STONE:0)
B(7,7,6,STONE:0)
B(8,7,6,STONE:0)
B(-7,7,7,STONE:0)
B(-6,7,7,STONE:0)
B(-5,7,7,STONE:0)
B(-4,7,7,STONE:0)
B(-3,7,7,STONE:0)
B(-2,7,7,STONE:0)
B(-1,7,7,STONE:0)
B(0,7,7,STONE:0)
B(1,7,7,STONE:0)
B(2,7,7,STONE:0)
B(3,7,7,STONE:0)
B(4,7,7,STONE:0)
B(5,7,7,STONE:0)
B(6,7,7,STONE:0)
B(7,7,7,STONE:0)
B(8,7,7,STONE:0)
B(-7,7,8,STONE:0)
B(-6,7,8,STONE:0)
B(-5,7,8,STONE:0)
B(-4,7,8,STONE:0)
B(-3,7,8,STONE:0)
B(-2,7,8,STONE:0)
B(-1,7,8,STONE:0)
B(0,7,8,STONE:0)
B(1,7,8,STONE:0)
B(2,7,8,STONE:0)
B(3,7,8,STONE:0)
B(4,7,8,STONE:0)
B(5,7,8,STONE:0)
B(6,7,8,STONE:0)
B(7,7,8,STONE:0)
B(8,7,8,STONE:0)
B(-7,8,-7,STONE:0)
B(-6,8,-7,STONE:0)
B(-5,8,-7,STONE:0)
B(-4,8,-7,STONE:0)
B(-3,8,-7,STONE:0)
B(-2,8,-7,STONE:0)
B(-1,8,-7,STONE:0)
B(0,8,-7,STONE:0)
B(1,8,-7,STONE:0)
B(2,8,-7,STONE:0)
B(3,8,-7,STONE:0)
B(4,8,-7,STONE:0)
B(5,8,-7,STONE:0)
B(6,8,-7,STONE:0)
B(7,8,-7,STONE:0)
B(8,8,-7,STONE:0)
B(-7,8,-6,STONE:0)
B(-6,8,-6,STONE:0)
B(-5,8,-6,STONE:0)
B(-4,8,-6,STONE:0)
B(-3,8,-6,STONE:0)
B(-2,8,-6,STONE:0)
B(-1,8,-6,STONE:0)
B(0,8,-6,STONE:0)
B(1,8,-6,STONE:0)
B(2,8,-6,STONE:0)
B(3,8,-6,STONE:0)
B(4,8,-6,STONE:0)
B(5,8,-6,STONE:0)
B(6,8,-6,STONE:0)
B(7,8,-6,STONE:0)
B(8,8,-6,STONE:0)
B(-7,8,-5,STONE:0)
B(-6,8,-5,STONE:0)
B(-5,8,-5,STONE:0)
B(-4,8,-5,STONE:0)
B(-3,8,-5,STONE:0)
B(-2,8,-5,STONE:0)
B(-1,8,-5,STONE:0)
B(0,8,-5,STONE:0)
B(1,8,-5,STONE:0)
B(2,8,-5,STONE:0)
B(3,8,-5,STONE:0)
B(4,8,-5,STONE:0)
B(5,8,-5,STONE:0)
B(6,8,-5,STONE:0)
B(7,8,-5,STONE:0)
B(8,8,-5,STONE:0)
B(-7,8,-4,STONE:0)
B(-6,8,-4,STONE:0)
B(-5,8,-4,STONE:0)
B(-4,8,-4,STONE:0)
B(-3,8,-4,STONE:0)
B(-2,8,-4,STONE:0)
B(-1,8,-4,STONE:0)
B(0,8,-4,STONE:0)
B(1,8,-4,STONE:0)
B(2,8,-4,STONE:0)
B(3,8,-4,STONE:0)
B(4,8,-4,STONE:0)
B(5,8,-4,STONE:0)
B(6,8,-4,STONE:0)
B(7,8,-4,STONE:0)
B(8,8,-4,STONE:0)
B(-7,8,-3,STONE:0)
B(-6,8,-3,STONE:0)
B(-5,8,-3,STONE:0)
B(-4,8,-3,STONE:0)
B(-3,8,-3,STONE:0)
B(-2,8,-3,STONE:0)
B(-1,8,-3,STONE:0)
B(0,8,-3,STONE:0)
B(1,8,-3,STONE:0)
B(2,8,-3,STONE:0)
B(3,8,-3,STONE:0)
B(4,8,-3,STONE:0)
B(5,8,-3,STONE:0)
B(6,8,-3,STONE:0)
B(7,8,-3,STONE:0)
B(8,8,-3,STONE:0)
B(-7,8,-2,STONE:0)
B(-6,8,-2,STONE:0)
B(-5,8,-2,STONE:0)
B(-4,8,-2,STONE:0)
B(-3,8,-2,STONE:0)
B(-2,8,-2,STONE:0)
B(-1,8,-2,STONE:0)
B(0,8,-2,STONE:0)
B(1,8,-2,STONE:0)
B(2,8,-2,STONE:0)
B(3,8,-2,STONE:0)
B(4,8,-2,STONE:0)
B(5,8,-2,STONE:0)
B(6,8,-2,STONE:0)
B(7,8,-2,STONE:0)
B(8,8,-2,STONE:0)
B(-7,8,-1,STONE:0)
B(-6,8,-1,STONE:0)
B(-5,8,-1,STONE:0)
B(-4,8,-1,STONE:0)
B(-3,8,-1,STONE:0)
B(-2,8,-1,STONE:0)
B(-1,8,-1,STONE:0)
B(0,8,-1,STONE:0)
B(1,8,-1,STONE:0)
B(2,8,-1,STONE:0)
B(3,8,-1,STONE:0)
B(4,8,-1,STONE:0)
B(5,8,-1,STONE:0)
B(6,8,-1,STONE:0)
B(7,8,-1,STONE:0)
B(8,8,-1,STONE:0)
B(-7,8,0,STONE:0)
B(-6,8,0,STONE:0)
B(-5,8,0,STONE:0)
B(-4,8,0,STONE:0)
B(-3,8,0,STONE:0)
B(-2,8,0,STONE:0)
B(-1,8,0,STONE:0)
B(0,8,0,STONE:0)
B(1,8,0,STONE:0)
B(2,8,0,STONE:0)
B(3,8,0,STONE:0)
B(4,8,0,STONE:0)
B(5,8,0,STONE:0)
B(6,8,0,STONE:0)
B(7,8,0,STONE:0)
B(8,8,0,STONE:0)
B(-7,8,1,STONE:0)
B(-6,8,1,STONE:0)
B(-5,8,1,STONE:0)
B(-4,8,1,STONE:0)
B(-3,8,1,STONE:0)
B(-2,8,1,STONE:0)
B(-1,8,1,STONE:0)
B(0,8,1,STONE:0)
B(1,8,1,STONE:0)
B(2,8,1,STONE:0)
B(3,8,1,STONE:0)
B(4,8,1,STONE:0)
B(5,8,1,STONE:0)
B(6,8,1,STONE:0)
B(7,8,1,STONE:0)
B(8,8,1,STONE:0)
B(-7,8,2,STONE:0)
B(-6,8,2,STONE:0)
B(-5,8,2,STONE:0)
B(-4,8,2,STONE:0)
B(-3,8,2,STONE:0)
B(-2,8,2,STONE:0)
B(-1,8,2,STONE:0)
B(0,8,2,STONE:0)
B(1,8,2,STONE:0)
B(2,8,2,STONE:0)
B(3,8,2,STONE:0)
B(4,8,2,STONE:0)
B(5,8,2,STONE:0)
B(6,8,2,STONE:0)
B(7,8,2,STONE:0)
B(8,8,2,STONE:0)
B(-7,8,3,STONE:0)
B(-6,8,3,STONE:0)
B(-5,8,3,STONE:0)
B(-4,8,3,STONE:0)
B(-3,8,3,STONE:0)
B(-2,8,3,STONE:0)
B(-1,8,3,STONE:0)
B(0,8,3,STONE:0)
B(1,8,3,STONE:0)
B(2,8,3,STONE:0)
B(3,8,3,STONE:0)
B(4,8,3,STONE:0)
B(5,8,3,STONE:0)
B(6,8,3,STONE:0)
B(7,8,3,STONE:0)
B(8,8,3,STONE:0)
B(-7,8,4,STONE:0)
B(-6,8,4,STONE:0)
B(-5,8,4,STONE:0)
B(-4,8,4,STONE:0)
B(-3,8,4,STONE:0)
B(-2,8,4,STONE:0)
B(-1,8,4,STONE:0)
B(0,8,4,STONE:0)
B(1,8,4,STONE:0)
B(2,8,4,STONE:0)
B(3,8,4,STONE:0)
B(4,8,4,STONE:0)
B(5,8,4,STONE:0)
B(6,8,4,STONE:0)
B(7,8,4,STONE:0)
B(8,8,4,STONE:0)
B(-7,8,5,STONE:0)
B(-6,8,5,STONE:0)
B(-5,8,5,STONE:0)
B(-4,8,5,STONE:0)
B(-3,8,5,STONE:0)
B(-2,8,5,STONE:0)
B(-1,8,5,STONE:0)
B(0,8,5,STONE:0)
B(1,8,5,STONE:0)
B(2,8,5,STONE:0)
B(3,8,5,STONE:0)
B(4,8,5,STONE:0)
B(5,8,5,STONE:0)
B(6,8,5,STONE:0)
B(7,8,5,STONE:0)
B(8,8,5,STONE:0)
B(-7,8,6,STONE:0)
B(-6,8,6,STONE:0)
B(-5,8,6,STONE:0)
B(-4,8,6,STONE:0)
B(-3,8,6,STONE:0)
B(-2,8,6,STONE:0)
B(-1,8,6,STONE:0)
B(0,8,6,STONE:0)
B(1,8,6,STONE:0)
B(2,8,6,STONE:0)
B(3,8,6,STONE:0)
B(4,8,6,STONE:0)
B(5,8,6,STONE:0)
B(6,8,6,STONE:0)
B(7,8,6,STONE:0)
B(8,8,6,STONE:0)
B(-7,8,7,STONE:0)
B(-6,8,7,STONE:0)
B(-5,8,7,STONE:0)
B(-4,8,7,STONE:0)
B(-3,8,7,STONE:0)
B(-2,8,7,STONE:0)
B(-1,8,7,STONE:0)
B(0,8,7,STONE:0)
B(1,8,7,STONE:0)
B(2,8,7,STONE:0)
B(3,8,7,STONE:0)
B(4,8,7,STONE:0)
B(5,8,7,STONE:0)
B(6,8,7,STONE:0)
B(7,8,7,STONE:0)
B(8,8,7,STONE:0)
B(-7,8,8,STONE:0)
B(-6,8,8,STONE:0)
B(-5,8,8,STONE:0)
B(-4,8,8,STONE:0)
B(-3,8,8,STONE:0)
B(-2,8,8,STONE:0)
B(-1,8,8,STONE:0)
B(0,8,8,STONE:0)
B(1,8,8,STONE:0)
B(2,8,8,STONE:0)
B(3,8,8,STONE:0)
B(4,8,8,STONE:0)
B(5,8,8,STONE:0)
B(6,8,8,STONE:0)
B(7,8,8,STONE:0)
B(8,8,8,STONE:0)
B(-7,9,-7,STONE:0)
B(-6,9,-7,STONE:0)
B(-5,9,-7,STONE:0)
B(-4,9,-7,STONE:0)
B(-3,9,-7,STONE:0)
B(-2,9,-7,STONE:0)
B(-1,9,-7,STONE:0)
B(0,9,-7,STONE:0)
B(1,9,-7,STONE:0)
B(2,9,-7,STONE:0)
B(3,9,-7,STONE:0)
B(4,9,-7,STONE:0)
B(5,9,-7,STONE:0)
B(6,9,-7,STONE:0)
B(7,9,-7,STONE:0)
B(8,9,-7,STONE:0)
B(-7,9,-6,STONE:0)
B(-6,9,-6,STONE:0)
B(-5,9,-6,STONE:0)
B(-4,9,-6,STONE:0)
B(-3,9,-6,STONE:0)
B(-2,9,-6,STONE:0)
B(-1,9,-6,STONE:0)
B(0,9,-6,STONE:0)
B(1,9,-6,STONE:0)
B(2,9,-6,STONE:0)
B(3,9,-6,STONE:0)
B(4,9,-6,STONE:0)
B(5,9,-6,STONE:0)
B(6,9,-6,STONE:0)
B(7,9,-6,STONE:0)
B(8,9,-6,STONE:0)
B(-7,9,-5,STONE:0)
B(-6,9,-5,STONE:0)
B(-5,9,-5,STONE:0)
B(-4,9,-5,STONE:0)
B(-3,9,-5,STONE:0)
B(-2,9,-5,STONE:0)
B(-1,9,-5,STONE:0)
B(0,9,-5,STONE:0)
B(1,9,-5,STONE:0)
B(2,9,-5,STONE:0)
B(3,9,-5,STONE:0)
B(4,9,-5,STONE:0)
B(5,9,-5,STONE:0)
B(6,9,-5,STONE:0)
B(7,9,-5,STONE:0)
B(8,9,-5,STONE:0)
B(-7,9,-4,STONE:0)
B(-6,9,-4,STONE:0)
B(-5,9,-4,STONE:0)
B(-4,9,-4,STONE:0)
B(-3,9,-4,STONE:0)
B(-2,9,-4,STONE:0)
B(-1,9,-4,STONE:0)
B(0,9,-4,STONE:0)
B(1,9,-4,STONE:0)
B(2,9,-4,STONE:0)
B(3,9,-4,STONE:0)
B(4,9,-4,STONE:0)
B(5,9,-4,STONE:0)
B(6,9,-4,STONE:0)
B(7,9,-4,STONE:0)
B(8,9,-4,STONE:0)
B(-7,9,-3,STONE:0)
B(-6,9,-3,STONE:0)
B(-5,9,-3,STONE:0)
B(-4,9,-3,STONE:0)
B(-3,9,-3,STONE:0)
B(-2,9,-3,STONE:0)
B(-1,9,-3,STONE:0)
B(0,9,-3,STONE:0)
B(1,9,-3,STONE:0)
B(2,9,-3,STONE:0)
B(3,9,-3,STONE:0)
B(4,9,-3,STONE:0)
B(5,9,-3,STONE:0)
B(6,9,-3,STONE:0)
B(7,9,-3,STONE:0)
B(8,9,-3,STONE:0)
B(-7,9,-2,STONE:0)
B(-6,9,-2,STONE:0)
B(-5,9,-2,STONE:0)
B(-4,9,-2,STONE:0)
B(-3,9,-2,STONE:0)
B(-2,9,-2,STONE:0)
B(-1,9,-2,STONE:0)
B(0,9,-2,STONE:0)
B(1,9,-2,STONE:0)
B(2,9,-2,STONE:0)
B(3,9,-2,STONE:0)
B(4,9,-2,STONE:0)
B(5,9,-2,STONE:0)
B(6,9,-2,STONE:0)
B(7,9,-2,STONE:0)
B(8,9,-2,STONE:0)
B(-7,9,-1,STONE:0)
B(-6,9,-1,STONE:0)
B(-5,9,-1,STONE:0)
B(-4,9,-1,STONE:0)
B(-3,9,-1,STONE:0)
B(-2,9,-1,STONE:0)
B(-1,9,-1,STONE:0)
B(0,9,-1,STONE:0)
B(1,9,-1,STONE:0)
B(2,9,-1,STONE:0)
B(3,9,-1,STONE:0)
B(4,9,-1,STONE:0)
B(5,9,-1,STONE:0)
B(6,9,-1,STONE:0)
B(7,9,-1,STONE:0)
B(8,9,-1,STONE:0)
B(-7,9,0,STONE:0)
B(-6,9,0,STONE:0)
B(-5,9,0,STONE:0)
B(-4,9,0,STONE:0)
B(-3,9,0,STONE:0)
B(-2,9,0,STONE:0)
B(-1,9,0,STONE:0)
B(0,9,0,STONE:0)
B(1,9,0,STONE:0)
B(2,9,0,STONE:0)
B(3,9,0,STONE:0)
B(4,9,0,STONE:0)
B(5,9,0,STONE:0)
B(6,9,0,STONE:0)
B(7,9,0,STONE:0)
B(8,9,0,STONE:0)
B(-7,9,1,STONE:0)
B(-6,9,1,STONE:0)
B(-5,9,1,STONE:0)
B(-4,9,1,STONE:0)
B(-3,9,1,STONE:0)
B(-2,9,1,STONE:0)
B(-1,9,1,STONE:0)
B(0,9,1,STONE:0)
B(1,9,1,STONE:0)
B(2,9,1,STONE:0)
B(3,9,1,STONE:0)
B(4,9,1,STONE:0)
B(5,9,1,STONE:0)
B(6,9,1,STONE:0)
B(7,9,1,STONE:0)
B(8,9,1,STONE:0)
B(-7,9,2,STONE:0)
B(-6,9,2,STONE:0)
B(-5,9,2,STONE:0)
B(-4,9,2,STONE:0)
B(-3,9,2,STONE:0)
B(-2,9,2,STONE:0)
B(-1,9,2,STONE:0)
B(0,9,2,STONE:0)
B(1,9,2,STONE:0)
B(2,9,2,STONE:0)
B(3,9,2,STONE:0)
B(4,9,2,STONE:0)
B(5,9,2,STONE:0)
B(6,9,2,STONE:0)
B(7,9,2,STONE:0)
B(8,9,2,STONE:0)
B(-7,9,3,STONE:0)
B(-6,9,3,STONE:0)
B(-5,9,3,STONE:0)
B(-4,9,3,STONE:0)
B(-3,9,3,STONE:0)
B(-2,9,3,STONE:0)
B(-1,9,3,STONE:0)
B(0,9,3,STONE:0)
B(1,9,3,STONE:0)
B(2,9,3,STONE:0)
B(3,9,3,STONE:0)
B(4,9,3,STONE:0)
B(5,9,3,STONE:0)
B(6,9,3,STONE:0)
B(7,9,3,STONE:0)
B(8,9,3,STONE:0)
B(-7,9,4,STONE:0)
B(-6,9,4,STONE:0)
B(-5,9,4,STONE:0)
B(-4,9,4,STONE:0)
B(-3,9,4,STONE:0)
B(-2,9,4,STONE:0)
B(-1,9,4,STONE:0)
B(0,9,4,STONE:0)
B(1,9,4,STONE:0)
B(2,9,4,STONE:0)
B(3,9,4,STONE:0)
B(4,9,4,STONE:0)
B(5,9,4,STONE:0)
B(6,9,4,STONE:0)
B(7,9,4,STONE:0)
B(8,9,4,STONE:0)
B(-7,9,5,STONE:0)
B(-6,9,5,STONE:0)
B(-5,9,5,STONE:0)
B(-4,9,5,STONE:0)
B(-3,9,5,STONE:0)
B(-2,9,5,STONE:0)
B(-1,9,5,STONE:0)
B(0,9,5,STONE:0)
B(1,9,5,STONE:0)
B(2,9,5,STONE:0)
B(3,9,5,STONE:0)
B(4,9,5,STONE:0)
B(5,9,5,STONE:0)
B(6,9,5,STONE:0)
B(7,9,5,STONE:0)
B(8,9,5,STONE:0)
B(-7,9,6,STONE:0)
B(-6,9,6,STONE:0)
B(-5,9,6,STONE:0)
B(-4,9,6,STONE:0)
B(-3,9,6,STONE:0)
B(-2,9,6,STONE:0)
B(-1,9,6,STONE:0)
B(0,9,6,STONE:0)
B(1,9,6,STONE:0)
B(2,9,6,STONE:0)
B(3,9,6,STONE:0)
B(4,9,6,STONE:0)
B(5,9,6,STONE:0)
B(6,9,6,STONE:0)
B(7,9,6,STONE:0)
B(8,9,6,STONE:0)
B(-7,9,7,STONE:0)
B(-6,9,7,STONE:0)
B(-5,9,7,STONE:0)
B(-4,9,7,STONE:0)
B(-3,9,7,STONE:0)
B(-2,9,7,STONE:0)
B(-1,9,7,STONE:0)
B(0,9,7,STONE:0)
B(1,9,7,STONE:0)
B(2,9,7,STONE:0)
B(3,9,7,STONE:0)
B(4,9,7,STONE:0)
B(5,9,7,STONE:0)
B(6,9,7,STONE:0)
B(7,9,7,STONE:0)
B(8,9,7,STONE:0)
B(-7,9,8,STONE:0)
B(-6,9,8,STONE:0)
B(-5,9,8,STONE:0)
B(-4,9,8,STONE:0)
B(-3,9,8,STONE:0)
B(-2,9,8,STONE:0)
B(-1,9,8,STONE:0)
B(0,9,8,STONE:0)
B(1,9,8,STONE:0)
B(2,9,8,STONE:0)
B(3,9,8,STONE:0)
B(4,9,8,STONE:0)
B(5,9,8,STONE:0)
B(6,9,8,STONE:0)
B(7,9,8,STONE:0)
B(8,9,8,STONE:0)
B(-7,10,-7,DIRT:0)
B(-6,10,-7,DIRT:0)
B(-5,10,-7,DIRT:0)
B(-4,10,-7,DIRT:0)
B(-3,10,-7,DIRT:0)
B(-2,10,-7,DIRT:0)
B(-1,10,-7,DIRT:0)
B(0,10,-7,DIRT:0)
B(1,10,-7,DIRT:0)
B(2,10,-7,DIRT:0)
B(3,10,-7,DIRT:0)
B(4,10,-7,DIRT:0)
B(5,10,-7,DIRT:0)
B(6,10,-7,DIRT:0)
B(7,10,-7,DIRT:0)
B(8,10,-7,DIRT:0)
B(-7,10,-6,DIRT:0)
B(-6,10,-6,DIRT:0)
B(-5,10,-6,DIRT:0)
B(-4,10,-6,DIRT:0)
B(-3,10,-6,DIRT:0)
B(-2,10,-6,DIRT:0)
B(-1,10,-6,DIRT:0)
B(0,10,-6,DIRT:0)
B(1,10,-6,DIRT:0)
B(2,10,-6,DIRT:0)
B(3,10,-6,DIRT:0)
B(4,10,-6,DIRT:0)
B(5,10,-6,DIRT:0)
B(6,10,-6,DIRT:0)
B(7,10,-6,DIRT:0)
B(8,10,-6,DIRT:0)
B(-7,10,-5,DIRT:0)
B(-6,10,-5,DIRT:0)
B(-5,10,-5,DIRT:0)
B(-4,10,-5,DIRT:0)
B(-3,10,-5,DIRT:0)
B(-2,10,-5,DIRT:0)
B(-1,10,-5,DIRT:0)
B(0,10,-5,DIRT:0)
B(1,10,-5,DIRT:0)
B(2,10,-5,DIRT:0)
B(3,10,-5,DIRT:0)
B(4,10,-5,DIRT:0)
B(5,10,-5,DIRT:0)
B(6,10,-5,DIRT:0)
B(7,10,-5,DIRT:0)
B(8,10,-5,DIRT:0)
B(-7,10,-4,DIRT:0)
B(-6,10,-4,DIRT:0)
B(-5,10,-4,DIRT:0)
B(-4,10,-4,DIRT:0)
B(-3,10,-4,DIRT:0)
B(-2,10,-4,DIRT:0)
B(-1,10,-4,DIRT:0)
B(0,10,-4,DIRT:0)
B(1,10,-4,DIRT:0)
B(2,10,-4,DIRT:0)
B(3,10,-4,DIRT:0)
B(4,10,-4,DIRT:0)
B(5,10,-4,DIRT:0)
B(6,10,-4,DIRT:0)
B(7,10,-4,DIRT:0)
B(8,10,-4,DIRT:0)
B(-7,10,-3,DIRT:0)
B(-6,10,-3,DIRT:0)
B(-5,10,-3,DIRT:0)
B(-4,10,-3,DIRT:0)
B(-3,10,-3,DIRT:0)
B(-2,10,-3,DIRT:0)
B(-1,10,-3,DIRT:0)
B(0,10,-3,DIRT:0)
B(1,10,-3,DIRT:0)
B(2,10,-3,DIRT:0)
B(3,10,-3,DIRT:0)
B(4,10,-3,DIRT:0)
B(5,10,-3,DIRT:0)
B(6,10,-3,DIRT:0)
B(7,10,-3,DIRT:0)
B(8,10,-3,DIRT:0)
B(-7,10,-2,DIRT:0)
B(-6,10,-2,DIRT:0)
B(-5,10,-2,DIRT:0)
B(-4,10,-2,DIRT:0)
B(-3,10,-2,DIRT:0)
B(-2,10,-2,DIRT:0)
B(-1,10,-2,DIRT:0)
B(0,10,-2,DIRT:0)
B(1,10,-2,DIRT:0)
B(2,10,-2,DIRT:0)
B(3,10,-2,DIRT:0)
B(4,10,-2,DIRT:0)
B(5,10,-2,DIRT:0)
B(6,10,-2,DIRT:0)
B(7,10,-2,DIRT:0)
B(8,10,-2,DIRT:0)
B(-7,10,-1,DIRT:0)
B(-6,10,-1,DIRT:0)
B(-5,10,-1,DIRT:0)
B(-4,10,-1,DIRT:0)
B(-3,10,-1,DIRT:0)
B(-2,10,-1,DIRT:0)
B(-1,10,-1,DIRT:0)
B(0,10,-1,DIRT:0)
B(1,10,-1,DIRT:0)
B(2,10,-1,DIRT:0)
B(3,10,-1,DIRT:0)
B(4,10,-1,DIRT:0)
B(5,10,-1,DIRT:0)
B(6,10,-1,DIRT:0)
B(7,10,-1,DIRT:0)
B(8,10,-1,DIRT:0)
B(-7,10,0,DIRT:0)
B(-6,10,0,DIRT:0)
B(-5,10,0,DIRT:0)
B(-4,10,0,DIRT:0)
B(-3,10,0,DIRT:0)
B(-2,10,0,DIRT:0)
B(-1,10,0,DIRT:0)
B(0,10,0,DIRT:0)
B(1,10,0,DIRT:0)
B(2,10,0,DIRT:0)
B(3,10,0,DIRT:0)
B(4,10,0,DIRT:0)
B(5,10,0,DIRT:0)
B(6,10,0,DIRT:0)
B(7,10,0,DIRT:0)
B(8,10,0,DIRT:0)
B(-7,10,1,DIRT:0)
B(-6,10,1,DIRT:0)
B(-5,10,1,DIRT:0)
B(-4,10,1,DIRT:0)
B(-3,10,1,DIRT:0)
B(-2,10,1,DIRT:0)
B(-1,10,1,DIRT:0)
B(0,10,1,DIRT:0)
B(1,10,1,DIRT:0)
B(2,10,1,DIRT:0)
B(3,10,1,DIRT:0)
B(4,10,1,DIRT:0)
B(5,10,1,DIRT:0)
B(6,10,1,DIRT:0)
B(7,10,1,DIRT:0)
B(8,10,1,DIRT:0)
B(-7,10,2,DIRT:0)
B(-6,10,2,DIRT:0)
B(-5,10,2,DIRT:0)
B(-4,10,2,DIRT:0)
B(-3,10,2,DIRT:0)
B(-2,10,2,DIRT:0)
B(-1,10,2,DIRT:0)
B(0,10,2,DIRT:0)
B(1,10,2,DIRT:0)
B(2,10,2,DIRT:0)
B(3,10,2,DIRT:0)
B(4,10,2,DIRT:0)
B(5,10,2,DIRT:0)
B(6,10,2,DIRT:0)
B(7,10,2,DIRT:0)
B(8,10,2,DIRT:0)
B(-7,10,3,DIRT:0)
B(-6,10,3,DIRT:0)
B(-5,10,3,DIRT:0)
B(-4,10,3,DIRT:0)
B(-3,10,3,DIRT:0)
B(-2,10,3,DIRT:0)
B(-1,10,3,DIRT:0)
B(0,10,3,DIRT:0)
B(1,10,3,DIRT:0)
B(2,10,3,DIRT:0)
B(3,10,3,DIRT:0)
B(4,10,3,DIRT:0)
B(5,10,3,DIRT:0)
B(6,10,3,DIRT:0)
B(7,10,3,DIRT:0)
B(8,10,3,DIRT:0)
B(-7,10,4,DIRT:0)
B(-6,10,4,DIRT:0)
B(-5,10,4,DIRT:0)
B(-4,10,4,DIRT:0)
B(-3,10,4,DIRT:0)
B(-2,10,4,DIRT:0)
B(-1,10,4,DIRT:0)
B(0,10,4,DIRT:0)
B(1,10,4,DIRT:0)
B(2,10,4,DIRT:0)
B(3,10,4,DIRT:0)
B(4,10,4,DIRT:0)
B(5,10,4,DIRT:0)
B(6,10,4,DIRT:0)
B(7,10,4,DIRT:0)
B(8,10,4,DIRT:0)
B(-7,10,5,DIRT:0)
B(-6,10,5,DIRT:0)
B(-5,10,5,DIRT:0)
B(-4,10,5,DIRT:0)
B(-3,10,5,DIRT:0)
B(-2,10,5,DIRT:0)
B(-1,10,5,DIRT:0)
B(0,10,5,DIRT:0)
B(1,10,5,DIRT:0)
B(2,10,5,DIRT:0)
B(3,10,5,DIRT:0)
B(4,10,5,DIRT:0)
B(5,10,5,DIRT:0)
B(6,10,5,DIRT:0)
B(7,10,5,DIRT:0)
B(8,10,5,DIRT:0)
B(-7,10,6,DIRT:0)
B(-6,10,6,DIRT:0)
B(-5,10,6,DIRT:0)
B(-4,10,6,DIRT:0)
B(-3,10,6,DIRT:0)
B(-2,10,6,DIRT:0)
B(-1,10,6,DIRT:0)
B(0,10,6,DIRT:0)
B(1,10,6,DIRT:0)
B(2,10,6,DIRT:0)
B(3,10,6,DIRT:0)
B(4,10,6,DIRT:0)
B(5,10,6,DIRT:0)
B(6,10,6,DIRT:0)
B(7,10,6,DIRT:0)
B(8,10,6,DIRT:0)
B(-7,10,7,DIRT:0)
B(-6,10,7,DIRT:0)
B(-5,10,7,DIRT:0)
B(-4,10,7,DIRT:0)
B(-3,10,7,DIRT:0)
B(-2,10,7,DIRT:0)
B(-1,10,7,DIRT:0)
B(0,10,7,DIRT:0)
B(1,10,7,DIRT:0)
B(2,10,7,DIRT:0)
B(3,10,7,DIRT:0)
B(4,10,7,DIRT:0)
B(5,10,7,DIRT:0)
B(6,10,7,DIRT:0)
B(7,10,7,DIRT:0)
B(8,10,7,DIRT:0)
B(-7,10,8,DIRT:0)
B(-6,10,8,DIRT:0)
B(-5,10,8,DIRT:0)
B(-4,10,8,DIRT:0)
B(-3,10,8,DIRT:0)
B(-2,10,8,DIRT:0)
B(-1,10,8,DIRT:0)
B(0,10,8,DIRT:0)
B(1,10,8,DIRT:0)
B(2,10,8,DIRT:0)
B(3,10,8,DIRT:0)
B(4,10,8,DIRT:0)
B(5,10,8,DIRT:0)
B(6,10,8,DIRT:0)
B(7,10,8,DIRT:0)
B(8,10,8,DIRT:0)
B(-7,11,-7,DIRT:0)
B(-6,11,-7,DIRT:0)
B(-5,11,-7,DIRT:0)
B(-4,11,-7,DIRT:0)
B(-3,11,-7,DIRT:0)
B(-2,11,-7,DIRT:0)
B(-1,11,-7,DIRT:0)
B(0,11,-7,DIRT:0)
B(1,11,-7,DIRT:0)
B(2,11,-7,DIRT:0)
B(3,11,-7,DIRT:0)
B(4,11,-7,DIRT:0)
B(5,11,-7,DIRT:0)
B(6,11,-7,DIRT:0)
B(7,11,-7,DIRT:0)
B(8,11,-7,DIRT:0)
B(-7,11,-6,DIRT:0)
B(-6,11,-6,DIRT:0)
B(-5,11,-6,DIRT:0)
B(-4,11,-6,DIRT:0)
B(-3,11,-6,DIRT:0)
B(-2,11,-6,DIRT:0)
B(-1,11,-6,DIRT:0)
B(0,11,-6,DIRT:0)
B(1,11,-6,DIRT:0)
B(2,11,-6,DIRT:0)
B(3,11,-6,DIRT:0)
B(4,11,-6,DIRT:0)
B(5,11,-6,DIRT:0)
B(6,11,-6,DIRT:0)
B(7,11,-6,DIRT:0)
B(8,11,-6,DIRT:0)
B(-7,11,-5,DIRT:0)
B(-6,11,-5,DIRT:0)
B(-5,11,-5,DIRT:0)
B(-4,11,-5,DIRT:0)
B(-3,11,-5,DIRT:0)
B(-2,11,-5,DIRT:0)
B(-1,11,-5,DIRT:0)
B(0,11,-5,DIRT:0)
B(1,11,-5,DIRT:0)
B(2,11,-5,DIRT:0)
B(3,11,-5,DIRT:0)
B(4,11,-5,DIRT:0)
B(5,11,-5,DIRT:0)
B(6,11,-5,DIRT:0)
B(7,11,-5,DIRT:0)
B(8,11,-5,DIRT:0)
B(-7,11,-4,DIRT:0)
B(-6,11,-4,DIRT:0)
B(-5,11,-4,DIRT:0)
B(-4,11,-4,DIRT:0)
B(-3,11,-4,DIRT:0)
B(-2,11,-4,DIRT:0)
B(-1,11,-4,DIRT:0)
B(0,11,-4,DIRT:0)
B(1,11,-4,DIRT:0)
B(2,11,-4,DIRT:0)
B(3,11,-4,DIRT:0)
B(4,11,-4,DIRT:0)
B(5,11,-4,DIRT:0)
B(6,11,-4,DIRT:0)
B(7,11,-4,DIRT:0)
B(8,11,-4,DIRT:0)
B(-7,11,-3,DIRT:0)
B(-6,11,-3,DIRT:0)
B(-5,11,-3,DIRT:0)
B(-4,11,-3,DIRT:0)
B(-3,11,-3,DIRT:0)
B(-2,11,-3,DIRT:0)
B(-1,11,-3,DIRT:0)
B(0,11,-3,DIRT:0)
B(1,11,-3,DIRT:0)
B(2,11,-3,DIRT:0)
B(3,11,-3,DIRT:0)
B(4,11,-3,DIRT:0)
B(5,11,-3,DIRT:0)
B(6,11,-3,DIRT:0)
B(7,11,-3,DIRT:0)
B(8,11,-3,DIRT:0)
B(-7,11,-2,DIRT:0)
B(-6,11,-2,DIRT:0)
B(-5,11,-2,DIRT:0)
B(-4,11,-2,DIRT:0)
B(-3,11,-2,DIRT:0)
B(-2,11,-2,DIRT:0)
B(-1,11,-2,DIRT:0)
B(0,11,-2,DIRT:0)
B(1,11,-2,DIRT:0)
B(2,11,-2,DIRT:0)
B(3,11,-2,DIRT:0)
B(4,11,-2,DIRT:0)
B(5,11,-2,DIRT:0)
B(6,11,-2,DIRT:0)
B(7,11,-2,DIRT:0)
B(8,11,-2,DIRT:0)
B(-7,11,-1,DIRT:0)
B(-6,11,-1,DIRT:0)
B(-5,11,-1,DIRT:0)
B(-4,11,-1,DIRT:0)
B(-3,11,-1,DIRT:0)
B(-2,11,-1,DIRT:0)
B(-1,11,-1,DIRT:0)
B(0,11,-1,DIRT:0)
B(1,11,-1,DIRT:0)
B(2,11,-1,DIRT:0)
B(3,11,-1,DIRT:0)
B(4,11,-1,DIRT:0)
B(5,11,-1,DIRT:0)
B(6,11,-1,DIRT:0)
B(7,11,-1,DIRT:0)
B(8,11,-1,DIRT:0)
B(-7,11,0,DIRT:0)
B(-6,11,0,DIRT:0)
B(-5,11,0,DIRT:0)
B(-4,11,0,DIRT:0)
B(-3,11,0,DIRT:0)
B(-2,11,0,DIRT:0)
B(-1,11,0,DIRT:0)
B(0,11,0,DIRT:0)
B(1,11,0,DIRT:0)
B(2,11,0,DIRT:0)
B(3,11,0,DIRT:0)
B(4,11,0,DIRT:0)
B(5,11,0,DIRT:0)
B(6,11,0,DIRT:0)
B(7,11,0,DIRT:0)
B(8,11,0,DIRT:0)
B(-7,11,1,DIRT:0)
B(-6,11,1,DIRT:0)
B(-5,11,1,DIRT:0)
B(-4,11,1,DIRT:0)
B(-3,11,1,DIRT:0)
B(-2,11,1,DIRT:0)
B(-1,11,1,DIRT:0)
B(0,11,1,DIRT:0)
B(1,11,1,DIRT:0)
B(2,11,1,DIRT:0)
B(3,11,1,DIRT:0)
B(4,11,1,DIRT:0)
B(5,11,1,DIRT:0)
B(6,11,1,DIRT:0)
B(7,11,1,DIRT:0)
B(8,11,1,DIRT:0)
B(-7,11,2,DIRT:0)
B(-6,11,2,DIRT:0)
B(-5,11,2,DIRT:0)
B(-4,11,2,DIRT:0)
B(-3,11,2,DIRT:0)
B(-2,11,2,DIRT:0)
B(-1,11,2,DIRT:0)
B(0,11,2,DIRT:0)
B(1,11,2,DIRT:0)
B(2,11,2,DIRT:0)
B(3,11,2,DIRT:0)
B(4,11,2,DIRT:0)
B(5,11,2,DIRT:0)
B(6,11,2,DIRT:0)
B(7,11,2,DIRT:0)
B(8,11,2,DIRT:0)
B(-7,11,3,DIRT:0)
B(-6,11,3,DIRT:0)
B(-5,11,3,DIRT:0)
B(-4,11,3,DIRT:0)
B(-3,11,3,DIRT:0)
B(-2,11,3,DIRT:0)
B(-1,11,3,DIRT:0)
B(0,11,3,DIRT:0)
B(1,11,3,DIRT:0)
B(2,11,3,DIRT:0)
B(3,11,3,DIRT:0)
B(4,11,3,DIRT:0)
B(5,11,3,DIRT:0)
B(6,11,3,DIRT:0)
B(7,11,3,DIRT:0)
B(8,11,3,DIRT:0)
B(-7,11,4,DIRT:0)
B(-6,11,4,DIRT:0)
B(-5,11,4,DIRT:0)
B(-4,11,4,DIRT:0)
B(-3,11,4,DIRT:0)
B(-2,11,4,DIRT:0)
B(-1,11,4,DIRT:0)
B(0,11,4,DIRT:0)
B(1,11,4,DIRT:0)
B(2,11,4,DIRT:0)
B(3,11,4,DIRT:0)
B(4,11,4,DIRT:0)
B(5,11,4,DIRT:0)
B(6,11,4,DIRT:0)
B(7,11,4,DIRT:0)
B(8,11,4,DIRT:0)
B(-7,11,5,DIRT:0)
B(-6,11,5,DIRT:0)
B(-5,11,5,DIRT:0)
B(-4,11,5,DIRT:0)
B(-3,11,5,DIRT:0)
B(-2,11,5,DIRT:0)
B(-1,11,5,DIRT:0)
B(0,11,5,DIRT:0)
B(1,11,5,DIRT:0)
B(2,11,5,DIRT:0)
B(3,11,5,DIRT:0)
B(4,11,5,DIRT:0)
B(5,11,5,DIRT:0)
B(6,11,5,DIRT:0)
B(7,11,5,DIRT:0)
B(8,11,5,DIRT:0)
B(-7,11,6,DIRT:0)
B(-6,11,6,DIRT:0)
B(-5,11,6,DIRT:0)
B(-4,11,6,DIRT:0)
B(-3,11,6,DIRT:0)
B(-2,11,6,DIRT:0)
B(-1,11,6,DIRT:0)
B(0,11,6,DIRT:0)
B(1,11,6,DIRT:0)
B(2,11,6,DIRT:0)
B(3,11,6,DIRT:0)
B(4,11,6,DIRT:0)
B(5,11,6,DIRT:0)
B(6,11,6,DIRT:0)
B(7,11,6,DIRT:0)
B(8,11,6,DIRT:0)
B(-7,11,7,DIRT:0)
B(-6,11,7,DIRT:0)
B(-5,11,7,DIRT:0)
B(-4,11,7,DIRT:0)
B(-3,11,7,DIRT:0)
B(-2,11,7,DIRT:0)
B(-1,11,7,DIRT:0)
B(0,11,7,DIRT:0)
B(1,11,7,DIRT:0)
B(2,11,7,DIRT:0)
B(3,11,7,DIRT:0)
B(4,11,7,DIRT:0)
B(5,11,7,DIRT:0)
B(6,11,7,DIRT:0)
B(7,11,7,DIRT:0)
B(8,11,7,DIRT:0)
B(-7,11,8,DIRT:0)
B(-6,11,8,DIRT:0)
B(-5,11,8,DIRT:0)
B(-4,11,8,DIRT:0)
B(-3,11,8,DIRT:0)
B(-2,11,8,DIRT:0)
B(-1,11,8,DIRT:0)
B(0,11,8,DIRT:0)
B(1,11,8,DIRT:0)
B(2,11,8,DIRT:0)
B(3,11,8,DIRT:0)
B(4,11,8,DIRT:0)
B(5,11,8,DIRT:0)
B(6,11,8,DIRT:0)
B(7,11,8,DIRT:0)
B(8,11,8,DIRT:0)
B(-7,12,-7,DIRT:0)
B(-6,12,-7,DIRT:0)
B(-5,12,-7,DIRT:0)
B(-4,12,-7,DIRT:0)
B(-3,12,-7,DIRT:0)
B(-2,12,-7,DIRT:0)
B(-1,12,-7,FARMLAND:7)
B(0,12,-7,FARMLAND:7)
B(1,12,-7,DIRT:0)
B(2,12,-7,DIRT:0)
B(3,12,-7,DIRT:0)
B(4,12,-7,DIRT:0)
B(5,12,-7,DIRT:0)
B(6,12,-7,DIRT:0)
B(7,12,-7,DIRT:0)
B(8,12,-7,DIRT:0)
B(-7,12,-6,DIRT:0)
B(-6,12,-6,DIRT:0)
B(-5,12,-6,DIRT:0)
B(-4,12,-6,DIRT:0)
B(-3,12,-6,DIRT:0)
B(-2,12,-6,DIRT:0)
B(-1,12,-6,STONE:0)
B(0,12,-6,STONE:0)
B(1,12,-6,DIRT:0)
B(2,12,-6,DIRT:0)
B(3,12,-6,DIRT:0)
B(4,12,-6,DIRT:0)
B(5,12,-6,DIRT:0)
B(6,12,-6,DIRT:0)
B(7,12,-6,DIRT:0)
B(8,12,-6,DIRT:0)
B(-7,12,-5,DIRT:0)
B(-6,12,-5,DIRT:0)
B(-5,12,-5,DIRT:0)
B(-4,12,-5,DIRT:0)
B(-3,12,-5,DIRT:0)
B(-2,12,-5,DIRT:0)
B(-1,12,-5,DIRT:0)
B(0,12,-5,STONE:0)
B(1,12,-5,DIRT:0)
B(2,12,-5,DIRT:0)
B(3,12,-5,DIRT:0)
B(4,12,-5,DIRT:0)
B(5,12,-5,DIRT:0)
B(6,12,-5,DIRT:0)
B(7,12,-5,DIRT:0)
B(8,12,-5,DIRT:0)
B(-7,12,-4,DIRT:0)
B(-6,12,-4,DIRT:0)
B(-5,12,-4,DIRT:0)
B(-4,12,-4,DIRT:0)
B(-3,12,-4,DIRT:0)
B(-2,12,-4,DIRT:0)
B(-1,12,-4,DIRT:0)
B(0,12,-4,DIRT:0)
B(1,12,-4,DIRT:0)
B(2,12,-4,DIRT:0)
B(3,12,-4,DIRT:0)
B(4,12,-4,DIRT:0)
B(5,12,-4,DIRT:0)
B(6,12,-4,DIRT:0)
B(7,12,-4,DIRT:0)
B(8,12,-4,DIRT:0)
B(-7,12,-3,DIRT:0)
B(-6,12,-3,DIRT:0)
B(-5,12,-3,DIRT:0)
B(-4,12,-3,DIRT:0)
B(-3,12,-3,DIRT:0)
B(-2,12,-3,DIRT:0)
B(-1,12,-3,DIRT:0)
B(0,12,-3,DIRT:0)
B(1,12,-3,DIRT:0)
B(2,12,-3,STONE:0)
B(3,12,-3,DIRT:0)
B(4,12,-3,DIRT:0)
B(5,12,-3,DIRT:0)
B(6,12,-3,DIRT:0)
B(7,12,-3,DIRT:0)
B(8,12,-3,DIRT:0)
B(-7,12,-2,DIRT:0)
B(-6,12,-2,DIRT:0)
B(-5,12,-2,DIRT:0)
B(-4,12,-2,DIRT:0)
B(-3,12,-2,DIRT:0)
B(-2,12,-2,DIRT:0)
B(-1,12,-2,DIRT:0)
B(0,12,-2,DIRT:0)
B(1,12,-2,DIRT:0)
B(2,12,-2,DIRT:0)
B(3,12,-2,DIRT:0)
B(4,12,-2,DIRT:0)
B(5,12,-2,DIRT:0)
B(6,12,-2,DIRT:0)
B(7,12,-2,DIRT:0)
B(8,12,-2,DIRT:0)
B(-7,12,-1,DIRT:0)
B(-6,12,-1,DIRT:0)
B(-5,12,-1,DIRT:0)
B(-4,12,-1,DIRT:0)
B(-3,12,-1,DIRT:0)
B(-2,12,-1,DIRT:0)
B(-1,12,-1,DIRT:0)
B(0,12,-1,DIRT:0)
B(1,12,-1,DIRT:0)
B(2,12,-1,DIRT:0)
B(3,12,-1,DIRT:0)
B(4,12,-1,STONE:0)
B(5,12,-1,DIRT:0)
B(6,12,-1,DIRT:0)
B(7,12,-1,DIRT:0)
B(8,12,-1,DIRT:0)
B(-7,12,0,DIRT:0)
B(-6,12,0,DIRT:0)
B(-5,12,0,DIRT:0)
B(-4,12,0,DIRT:0)
B(-3,12,0,DIRT:0)
B(-2,12,0,DIRT:0)
B(-1,12,0,DIRT:0)
B(0,12,0,DIRT:0)
B(1,12,0,DIRT:0)
B(2,12,0,DIRT:0)
B(3,12,0,DIRT:0)
B(4,12,0,STONE:0)
B(5,12,0,DIRT:0)
B(6,12,0,DIRT:0)
B(7,12,0,DIRT:0)
B(8,12,0,DIRT:0)
B(-7,12,1,DIRT:0)
B(-6,12,1,DIRT:0)
B(-5,12,1,DIRT:0)
B(-4,12,1,DIRT:0)
B(-3,12,1,DIRT:0)
B(-2,12,1,DIRT:0)
B(-1,12,1,DIRT:0)
B(0,12,1,DIRT:0)
B(1,12,1,DIRT:0)
B(2,12,1,DIRT:0)
B(3,12,1,DIRT:0)
B(4,12,1,STONE:0)
B(5,12,1,DIRT:0)
B(6,12,1,DIRT:0)
B(7,12,1,DIRT:0)
B(8,12,1,DIRT:0)
B(-7,12,2,DIRT:0)
B(-6,12,2,DIRT:0)
B(-5,12,2,DIRT:0)
B(-4,12,2,DIRT:0)
B(-3,12,2,DIRT:0)
B(-2,12,2,DIRT:0)
B(-1,12,2,DIRT:0)
B(0,12,2,DIRT:0)
B(1,12,2,DIRT:0)
B(2,12,2,DIRT:0)
B(3,12,2,DIRT:0)
B(4,12,2,DIRT:0)
B(5,12,2,DIRT:0)
B(6,12,2,DIRT:0)
B(7,12,2,DIRT:0)
B(8,12,2,DIRT:0)
B(-7,12,3,DIRT:0)
B(-6,12,3,DIRT:0)
B(-5,12,3,DIRT:0)
B(-4,12,3,DIRT:0)
B(-3,12,3,DIRT:0)
B(-2,12,3,DIRT:0)
B(-1,12,3,DIRT:0)
B(0,12,3,DIRT:0)
B(1,12,3,DIRT:0)
B(2,12,3,DIRT:0)
B(3,12,3,DIRT:0)
B(4,12,3,DIRT:0)
B(5,12,3,DIRT:0)
B(6,12,3,DIRT:0)
B(7,12,3,DIRT:0)
B(8,12,3,DIRT:0)
B(-7,12,4,DIRT:0)
B(-6,12,4,DIRT:0)
B(-5,12,4,DIRT:0)
B(-4,12,4,DIRT:0)
B(-3,12,4,DIRT:0)
B(-2,12,4,DIRT:0)
B(-1,12,4,DIRT:0)
B(0,12,4,DIRT:0)
B(1,12,4,DIRT:0)
B(2,12,4,DIRT:0)
B(3,12,4,DIRT:0)
B(4,12,4,DIRT:0)
B(5,12,4,STONE:0)
B(6,12,4,STONE:0)
B(7,12,4,DIRT:0)
B(8,12,4,DIRT:0)
B(-7,12,5,DIRT:0)
B(-6,12,5,DIRT:0)
B(-5,12,5,DIRT:0)
B(-4,12,5,DIRT:0)
B(-3,12,5,DIRT:0)
B(-2,12,5,DIRT:0)
B(-1,12,5,DIRT:0)
B(0,12,5,DIRT:0)
B(1,12,5,DIRT:0)
B(2,12,5,DIRT:0)
B(3,12,5,DIRT:0)
B(4,12,5,DIRT:0)
B(5,12,5,DIRT:0)
B(6,12,5,STONE:0)
B(7,12,5,DIRT:0)
B(8,12,5,DIRT:0)
B(-7,12,6,DIRT:0)
B(-6,12,6,DIRT:0)
B(-5,12,6,DIRT:0)
B(-4,12,6,DIRT:0)
B(-3,12,6,DIRT:0)
B(-2,12,6,DIRT:0)
B(-1,12,6,DIRT:0)
B(0,12,6,DIRT:0)
B(1,12,6,DIRT:0)
B(2,12,6,DIRT:0)
B(3,12,6,DIRT:0)
B(4,12,6,DIRT:0)
B(5,12,6,DIRT:0)
B(6,12,6,STONE:0)
B(7,12,6,DIRT:0)
B(8,12,6,DIRT:0)
B(-7,12,7,DIRT:0)
B(-6,12,7,DIRT:0)
B(-5,12,7,DIRT:0)
B(-4,12,7,DIRT:0)
B(-3,12,7,DIRT:0)
B(-2,12,7,DIRT:0)
B(-1,12,7,DIRT:0)
B(0,12,7,DIRT:0)
B(1,12,7,DIRT:0)
B(2,12,7,DIRT:0)
B(3,12,7,DIRT:0)
B(4,12,7,DIRT:0)
B(5,12,7,DIRT:0)
B(6,12,7,DIRT:0)
B(7,12,7,DIRT:0)
B(8,12,7,STONE:0)
B(-7,12,8,DIRT:0)
B(-6,12,8,DIRT:0)
B(-5,12,8,DIRT:0)
B(-4,12,8,DIRT:0)
B(-3,12,8,DIRT:0)
B(-2,12,8,DIRT:0)
B(-1,12,8,DIRT:0)
B(0,12,8,DIRT:0)
B(1,12,8,DIRT:0)
B(2,12,8,DIRT:0)
B(3,12,8,DIRT:0)
B(4,12,8,DIRT:0)
B(5,12,8,DIRT:0)
B(6,12,8,DIRT:0)
B(7,12,8,DIRT:0)
B(8,12,8,DIRT:0)
B(-7,13,-7,STONE:0)
B(-6,13,-7,STONE:0)
B(-5,13,-7,STONE:0)
B(-4,13,-7,STONE:0)
B(-3,13,-7,STONE:0)
B(-2,13,-7,FARMLAND:7)
B(-1,13,-7,WHEAT:7)
B(0,13,-7,WHEAT:7)
B(1,13,-7,FARMLAND:7)
B(2,13,-7,WATER:2)
B(3,13,-7,WATER:1)
B(4,13,-7,DIRT:0)
B(5,13,-7,DIRT:0)
B(6,13,-7,DIRT:0)
B(7,13,-7,DIRT:0)
B(8,13,-7,FARMLAND:7)
B(-7,13,-6,STONE:0)
B(-6,13,-6,STONE:0)
B(-5,13,-6,STONE:0)
B(-4,13,-6,STONE:0)
B(-3,13,-6,STONE:0)
B(-2,13,-6,STONE:0)
B(-1,13,-6,FARMLAND:7)
B(0,13,-6,FARMLAND:7)
B(1,13,-6,FARMLAND:7)
B(2,13,-6,FARMLAND:7)
B(3,13,-6,WATER:15)
B(4,13,-6,DIRT:0)
B(5,13,-6,DIRT:0)
B(6,13,-6,DIRT:0)
B(7,13,-6,DIRT:0)
B(8,13,-6,DIRT:0)
B(-7,13,-5,STONE:0)
B(-6,13,-5,STONE:0)
B(-5,13,-5,STONE:0)
B(-4,13,-5,STONE:0)
B(-3,13,-5,STONE:0)
B(-2,13,-5,STONE:0)
B(-1,13,-5,STONE:0)
B(0,13,-5,FARMLAND:7)
B(1,13,-5,FARMLAND:7)
B(2,13,-5,DIRT:0)
B(3,13,-5,FARMLAND:7)
B(4,13,-5,DIRT:0)
B(5,13,-5,DIRT:0)
B(6,13,-5,DIRT:0)
B(7,13,-5,DIRT:0)
B(8,13,-5,DIRT:0)
B(-7,13,-4,STONE:0)
B(-6,13,-4,STONE:0)
B(-5,13,-4,STONE:0)
B(-4,13,-4,STONE:0)
B(-3,13,-4,STONE:0)
B(-2,13,-4,STONE:0)
B(-1,13,-4,STONE:0)
B(0,13,-4,FARMLAND:7)
B(1,13,-4,DIRT:0)
B(2,13,-4,DIRT:0)
B(3,13,-4,DIRT:0)
B(4,13,-4,DIRT:0)
B(5,13,-4,DIRT:0)
B(6,13,-4,DIRT:0)
B(7,13,-4,DIRT:0)
B(8,13,-4,DIRT:0)
B(-7,13,-3,STONE:0)
B(-6,13,-3,STONE:0)
B(-5,13,-3,STONE:0)
B(-4,13,-3,STONE:0)
B(-3,13,-3,STONE:0)
B(-2,13,-3,STONE:0)
B(-1,13,-3,STONE:0)
B(0,13,-3,STONE:0)
B(1,13,-3,DIRT:0)
B(2,13,-3,DIRT:0)
B(3,13,-3,DIRT:0)
B(4,13,-3,DIRT:0)
B(5,13,-3,DIRT:0)
B(6,13,-3,DIRT:0)
B(7,13,-3,DIRT:0)
B(8,13,-3,DIRT:0)
B(-7,13,-2,STONE:0)
B(-6,13,-2,STONE:0)
B(-5,13,-2,STONE:0)
B(-4,13,-2,STONE:0)
B(-3,13,-2,STONE:0)
B(-2,13,-2,STONE:0)
B(-1,13,-2,STONE:0)
B(0,13,-2,STONE:0)
B(1,13,-2,STONE:0)
B(2,13,-2,STONE:0)
B(3,13,-2,DIRT:0)
B(4,13,-2,DIRT:0)
B(5,13,-2,DIRT:0)
B(6,13,-2,DIRT:0)
B(7,13,-2,DIRT:0)
B(8,13,-2,DIRT:0)
B(-7,13,-1,STONE:0)
B(-6,13,-1,STONE:0)
B(-5,13,-1,STONE:0)
B(-4,13,-1,STONE:0)
B(-3,13,-1,STONE:0)
B(-2,13,-1,STONE:0)
B(-1,13,-1,STONE:0)
B(0,13,-1,STONE:0)
B(1,13,-1,STONE:0)
B(2,13,-1,STONE:0)
B(3,13,-1,STONE:0)
B(4,13,-1,DIRT:0)
B(5,13,-1,DIRT:0)
B(6,13,-1,DIRT:0)
B(7,13,-1,DIRT:0)
B(8,13,-1,DIRT:0)
B(-7,13,0,STONE:0)
B(-6,13,0,STONE:0)
B(-5,13,0,STONE:0)
B(-4,13,0,STONE:0)
B(-3,13,0,STONE:0)
B(-2,13,0,STONE:0)
B(-1,13,0,STONE:0)
B(0,13,0,STONE:0)
B(1,13,0,STONE:0)
B(2,13,0,STONE:0)
B(3,13,0,STONE:0)
B(4,13,0,DIRT:0)
B(5,13,0,DIRT:0)
B(6,13,0,DIRT:0)
B(7,13,0,DIRT:0)
B(8,13,0,DIRT:0)
B(-7,13,1,STONE:0)
B(-6,13,1,STONE:0)
B(-5,13,1,STONE:0)
B(-4,13,1,STONE:0)
B(-3,13,1,STONE:0)
B(-2,13,1,STONE:0)
B(-1,13,1,STONE:0)
B(0,13,1,STONE:0)
B(1,13,1,STONE:0)
B(2,13,1,STONE:0)
B(3,13,1,STONE:0)
B(4,13,1,DIRT:0)
B(5,13,1,DIRT:0)
B(6,13,1,DIRT:0)
B(7,13,1,DIRT:0)
B(8,13,1,DIRT:0)
B(-7,13,2,STONE:0)
B(-6,13,2,STONE:0)
B(-5,13,2,STONE:0)
B(-4,13,2,STONE:0)
B(-3,13,2,STONE:0)
B(-2,13,2,STONE:0)
B(-1,13,2,STONE:0)
B(0,13,2,STONE:0)
B(1,13,2,STONE:0)
B(2,13,2,STONE:0)
B(3,13,2,DIRT:0)
B(4,13,2,DIRT:0)
B(5,13,2,DIRT:0)
B(6,13,2,DIRT:0)
B(7,13,2,DIRT:0)
B(8,13,2,DIRT:0)
B(-7,13,3,STONE:0)
B(-6,13,3,STONE:0)
B(-5,13,3,STONE:0)
B(-4,13,3,STONE:0)
B(-3,13,3,STONE:0)
B(-2,13,3,STONE:0)
B(-1,13,3,STONE:0)
B(0,13,3,STONE:0)
B(1,13,3,STONE:0)
B(2,13,3,STONE:0)
B(3,13,3,STONE:0)
B(4,13,3,DIRT:0)
B(5,13,3,DIRT:0)
B(6,13,3,DIRT:0)
B(7,13,3,DIRT:0)
B(8,13,3,DIRT:0)
B(-7,13,4,STONE:0)
B(-6,13,4,STONE:0)
B(-5,13,4,STONE:0)
B(-4,13,4,STONE:0)
B(-3,13,4,STONE:0)
B(-2,13,4,STONE:0)
B(-1,13,4,STONE:0)
B(0,13,4,STONE:0)
B(1,13,4,STONE:0)
B(2,13,4,STONE:0)
B(3,13,4,STONE:0)
B(4,13,4,STONE:0)
B(5,13,4,DIRT:0)
B(6,13,4,DIRT:0)
B(7,13,4,DIRT:0)
B(8,13,4,DIRT:0)
B(-7,13,5,STONE:0)
B(-6,13,5,STONE:0)
B(-5,13,5,STONE:0)
B(-4,13,5,STONE:0)
B(-3,13,5,STONE:0)
B(-2,13,5,STONE:0)
B(-1,13,5,STONE:0)
B(0,13,5,STONE:0)
B(1,13,5,STONE:0)
B(2,13,5,STONE:0)
B(3,13,5,STONE:0)
B(4,13,5,STONE:0)
B(5,13,5,STONE:0)
B(6,13,5,DIRT:0)
B(7,13,5,DIRT:0)
B(8,13,5,DIRT:0)
B(-7,13,6,STONE:0)
B(-6,13,6,STONE:0)
B(-5,13,6,STONE:0)
B(-4,13,6,STONE:0)
B(-3,13,6,STONE:0)
B(-2,13,6,STONE:0)
B(-1,13,6,STONE:0)
B(0,13,6,STONE:0)
B(1,13,6,STONE:0)
B(2,13,6,STONE:0)
B(3,13,6,STONE:0)
B(4,13,6,STONE:0)
B(5,13,6,STONE:0)
B(6,13,6,DIRT:0)
B(7,13,6,DIRT:0)
B(8,13,6,DIRT:0)
B(-7,13,7,STONE:0)
B(-6,13,7,STONE:0)
B(-5,13,7,STONE:0)
B(-4,13,7,STONE:0)
B(-3,13,7,STONE:0)
B(-2,13,7,STONE:0)
B(-1,13,7,STONE:0)
B(0,13,7,STONE:0)
B(1,13,7,STONE:0)
B(2,13,7,STONE:0)
B(3,13,7,STONE:0)
B(4,13,7,STONE:0)
B(5,13,7,STONE:0)
B(6,13,7,STONE:0)
B(7,13,7,STONE:0)
B(8,13,7,DIRT:0)
B(-7,13,8,STONE:0)
B(-6,13,8,STONE:0)
B(-5,13,8,STONE:0)
B(-4,13,8,STONE:0)
B(-3,13,8,STONE:0)
B(-2,13,8,STONE:0)
B(-1,13,8,STONE:0)
B(0,13,8,STONE:0)
B(1,13,8,STONE:0)
B(2,13,8,STONE:0)
B(3,13,8,STONE:0)
B(4,13,8,STONE:0)
B(5,13,8,STONE:0)
B(6,13,8,STONE:0)
B(7,13,8,STONE:0)
B(8,13,8,STONE:0)
B(-7,14,-7,STONE:0)
B(-6,14,-7,STONE:0)
B(-5,14,-7,STONE:0)
B(-4,14,-7,STONE:0)
B(-3,14,-7,STONE:0)
B(-2,14,-7,WHEAT:7)
B(-1,14,-7,AIR:0)
B(0,14,-7,AIR:0)
B(1,14,-7,WHEAT:7)
B(2,14,-7,AIR:0)
B(3,14,-7,AIR:0)
B(4,14,-7,FARMLAND:7)
B(5,14,-7,FARMLAND:7)
B(6,14,-7,FARMLAND:7)
B(7,14,-7,FARMLAND:7)
B(8,14,-7,WATER:1)
B(-7,14,-6,STONE:0)
B(-6,14,-6,STONE:0)
B(-5,14,-6,STONE:0)
B(-4,14,-6,STONE:0)
B(-3,14,-6,STONE:0)
B(-2,14,-6,STONE:0)
B(-1,14,-6,WHEAT:7)
B(0,14,-6,WHEAT:7)
B(1,14,-6,WHEAT:7)
B(2,14,-6,WHEAT:7)
B(3,14,-6,WATER:7)
B(4,14,-6,WATER:6)
B(5,14,-6,FARMLAND:7)
B(6,14,-6,FARMLAND:7)
B(7,14,-6,FARMLAND:7)
B(8,14,-6,WATER:0)
B(-7,14,-5,STONE:0)
B(-6,14,-5,STONE:0)
B(-5,14,-5,STONE:0)
B(-4,14,-5,STONE:0)
B(-3,14,-5,STONE:0)
B(-2,14,-5,STONE:0)
B(-1,14,-5,STONE:0)
B(0,14,-5,WHEAT:7)
B(1,14,-5,WHEAT:7)
B(2,14,-5,FARMLAND:7)
B(3,14,-5,WATER:6)
B(4,14,-5,WATER:5)
B(5,14,-5,FARMLAND:7)
B(6,14,-5,FARMLAND:7)
B(7,14,-5,FARMLAND:7)
B(8,14,-5,FARMLAND:7)
B(-7,14,-4,STONE:0)
B(-6,14,-4,STONE:0)
B(-5,14,-4,STONE:0)
B(-4,14,-4,STONE:0)
B(-3,14,-4,STONE:0)
B(-2,14,-4,STONE:0)
B(-1,14,-4,STONE:0)
B(0,14,-4,WHEAT:7)
B(1,14,-4,FARMLAND:7)
B(2,14,-4,FARMLAND:7)
B(3,14,-4,FARMLAND:7)
B(4,14,-4,WATER:4)
B(5,14,-4,WATER:3)
B(6,14,-4,FARMLAND:7)
B(7,14,-4,FARMLAND:7)
B(8,14,-4,FARMLAND:7)
B(-7,14,-3,STONE:0)
B(-6,14,-3,STONE:0)
B(-5,14,-3,STONE:0)
B(-4,14,-3,STONE:0)
B(-3,14,-3,STONE:0)
B(-2,14,-3,STONE:0)
B(-1,14,-3,STONE:0)
B(0,14,-3,STONE:0)
B(1,14,-3,FARMLAND:7)
B(2,14,-3,FARMLAND:7)
B(3,14,-3,FARMLAND:7)
B(4,14,-3,FARMLAND:7)
B(5,14,-3,WATER:2)
B(6,14,-3,FARMLAND:7)
B(7,14,-3,FARMLAND:7)
B(8,14,-3,FARMLAND:7)
B(-7,14,-2,STONE:0)
B(-6,14,-2,STONE:0)
B(-5,14,-2,STONE:0)
B(-4,14,-2,STONE:0)
B(-3,14,-2,STONE:0)
B(-2,14,-2,STONE:0)
B(-1,14,-2,STONE:0)
B(0,14,-2,STONE:0)
B(1,14,-2,STONE:0)
B(2,14,-2,FARMLAND:7)
B(3,14,-2,FARMLAND:7)
B(4,14,-2,FARMLAND:7)
B(5,14,-2,WATER:1)
B(6,14,-2,FARMLAND:7)
B(7,14,-2,FARMLAND:7)
B(8,14,-2,FARMLAND:7)
B(-7,14,-1,STONE:0)
B(-6,14,-1,STONE:0)
B(-5,14,-1,STONE:0)
B(-4,14,-1,STONE:0)
B(-3,14,-1,STONE:0)
B(-2,14,-1,STONE:0)
B(-1,14,-1,STONE:0)
B(0,14,-1,STONE:0)
B(1,14,-1,STONE:0)
B(2,14,-1,STONE:0)
B(3,14,-1,FARMLAND:7)
B(4,14,-1,FARMLAND:7)
B(5,14,-1,WATER:0)
B(6,14,-1,WATER:0)
B(7,14,-1,FARMLAND:7)
B(8,14,-1,FARMLAND:7)
B(-7,14,0,STONE:0)
B(-6,14,0,STONE:0)
B(-5,14,0,STONE:0)
B(-4,14,0,STONE:0)
B(-3,14,0,STONE:0)
B(-2,14,0,STONE:0)
B(-1,14,0,STONE:0)
B(0,14,0,STONE:0)
B(1,14,0,STONE:0)
B(2,14,0,STONE:0)
B(3,14,0,STONE:0)
B(4,14,0,FARMLAND:7)
B(5,14,0,FARMLAND:7)
B(6,14,0,WATER:0)
B(7,14,0,WATER:0)
B(8,14,0,WATER:0)
B(-7,14,1,STONE:0)
B(-6,14,1,STONE:0)
B(-5,14,1,STONE:0)
B(-4,14,1,STONE:0)
B(-3,14,1,STONE:0)
B(-2,14,1,STONE:0)
B(-1,14,1,STONE:0)
B(0,14,1,STONE:0)
B(1,14,1,STONE:0)
B(2,14,1,STONE:0)
B(3,14,1,STONE:0)
B(4,14,1,FARMLAND:7)
B(5,14,1,FARMLAND:7)
B(6,14,1,FARMLAND:7)
B(7,14,1,FARMLAND:7)
B(8,14,1,WATER:0)
B(-7,14,2,STONE:0)
B(-6,14,2,STONE:0)
B(-5,14,2,STONE:0)
B(-4,14,2,STONE:0)
B(-3,14,2,STONE:0)
B(-2,14,2,STONE:0)
B(-1,14,2,STONE:0)
B(0,14,2,STONE:0)
B(1,14,2,STONE:0)
B(2,14,2,STONE:0)
B(3,14,2,DIRT:0)
B(4,14,2,FARMLAND:7)
B(5,14,2,FARMLAND:7)
B(6,14,2,FARMLAND:7)
B(7,14,2,FARMLAND:7)
B(8,14,2,FARMLAND:7)
B(-7,14,3,STONE:0)
B(-6,14,3,STONE:0)
B(-5,14,3,STONE:0)
B(-4,14,3,STONE:0)
B(-3,14,3,STONE:0)
B(-2,14,3,STONE:0)
B(-1,14,3,STONE:0)
B(0,14,3,STONE:0)
B(1,14,3,STONE:0)
B(2,14,3,STONE:0)
B(3,14,3,DIRT:0)
B(4,14,3,FARMLAND:7)
B(5,14,3,FARMLAND:7)
B(6,14,3,FARMLAND:7)
B(7,14,3,FARMLAND:7)
B(8,14,3,FARMLAND:7)
B(-7,14,4,STONE:0)
B(-6,14,4,STONE:0)
B(-5,14,4,STONE:0)
B(-4,14,4,STONE:0)
B(-3,14,4,STONE:0)
B(-2,14,4,STONE:0)
B(-1,14,4,STONE:0)
B(0,14,4,STONE:0)
B(1,14,4,STONE:0)
B(2,14,4,STONE:0)
B(3,14,4,STONE:0)
B(4,14,4,DIRT:0)
B(5,14,4,FARMLAND:7)
B(6,14,4,FARMLAND:7)
B(7,14,4,FARMLAND:7)
B(8,14,4,FARMLAND:7)
B(-7,14,5,STONE:0)
B(-6,14,5,STONE:0)
B(-5,14,5,STONE:0)
B(-4,14,5,STONE:0)
B(-3,14,5,STONE:0)
B(-2,14,5,STONE:0)
B(-1,14,5,STONE:0)
B(0,14,5,STONE:0)
B(1,14,5,STONE:0)
B(2,14,5,STONE:0)
B(3,14,5,STONE:0)
B(4,14,5,STONE:0)
B(5,14,5,DIRT:0)
B(6,14,5,FARMLAND:7)
B(7,14,5,FARMLAND:7)
B(8,14,5,FARMLAND:7)
B(-7,14,6,STONE:0)
B(-6,14,6,STONE:0)
B(-5,14,6,STONE:0)
B(-4,14,6,STONE:0)
B(-3,14,6,STONE:0)
B(-2,14,6,STONE:0)
B(-1,14,6,STONE:0)
B(0,14,6,STONE:0)
B(1,14,6,STONE:0)
B(2,14,6,STONE:0)
B(3,14,6,STONE:0)
B(4,14,6,STONE:0)
B(5,14,6,STONE:0)
B(6,14,6,DIRT:0)
B(7,14,6,FARMLAND:7)
B(8,14,6,FARMLAND:7)
B(-7,14,7,STONE:0)
B(-6,14,7,STONE:0)
B(-5,14,7,STONE:0)
B(-4,14,7,STONE:0)
B(-3,14,7,STONE:0)
B(-2,14,7,STONE:0)
B(-1,14,7,STONE:0)
B(0,14,7,STONE:0)
B(1,14,7,STONE:0)
B(2,14,7,STONE:0)
B(3,14,7,STONE:0)
B(4,14,7,STONE:0)
B(5,14,7,STONE:0)
B(6,14,7,STONE:0)
B(7,14,7,DIRT:0)
B(8,14,7,FARMLAND:7)
B(-7,14,8,STONE:0)
B(-6,14,8,STONE:0)
B(-5,14,8,STONE:0)
B(-4,14,8,STONE:0)
B(-3,14,8,STONE:0)
B(-2,14,8,STONE:0)
B(-1,14,8,STONE:0)
B(0,14,8,STONE:0)
B(1,14,8,STONE:0)
B(2,14,8,STONE:0)
B(3,14,8,STONE:0)
B(4,14,8,STONE:0)
B(5,14,8,STONE:0)
B(6,14,8,STONE:0)
B(7,14,8,STONE:0)
B(8,14,8,DIRT:0)
B(-7,15,-7,STONE:0)
B(-6,15,-7,STONE:0)
B(-5,15,-7,STONE:0)
B(-4,15,-7,STONE:0)
B(-3,15,-7,DIRT:0)
B(-2,15,-7,AIR:0)
B(-1,15,-7,AIR:0)
B(0,15,-7,AIR:0)
B(1,15,-7,AIR:0)
B(2,15,-7,AIR:0)
B(3,15,-7,AIR:0)
B(4,15,-7,WHEAT:7)
B(5,15,-7,WHEAT:7)
B(6,15,-7,WHEAT:7)
B(7,15,-7,WHEAT:7)
B(8,15,-7,AIR:0)
B(-7,15,-6,STONE:0)
B(-6,15,-6,STONE:0)
B(-5,15,-6,STONE:0)
B(-4,15,-6,STONE:0)
B(-3,15,-6,STONE:0)
B(-2,15,-6,STONE:0)
B(-1,15,-6,AIR:0)
B(0,15,-6,AIR:0)
B(1,15,-6,AIR:0)
B(2,15,-6,AIR:0)
B(3,15,-6,AIR:0)
B(4,15,-6,AIR:0)
B(5,15,-6,WHEAT:7)
B(6,15,-6,WHEAT:7)
B(7,15,-6,WHEAT:7)
B(8,15,-6,AIR:0)
B(-7,15,-5,STONE:0)
B(-6,15,-5,STONE:0)
B(-5,15,-5,STONE:0)
B(-4,15,-5,STONE:0)
B(-3,15,-5,STONE:0)
B(-2,15,-5,STONE:0)
B(-1,15,-5,STONE:0)
B(0,15,-5,AIR:0)
B(1,15,-5,AIR:0)
B(2,15,-5,WHEAT:7)
B(3,15,-5,AIR:0)
B(4,15,-5,AIR:0)
B(5,15,-5,WHEAT:7)
B(6,15,-5,WHEAT:7)
B(7,15,-5,WHEAT:7)
B(8,15,-5,WHEAT:7)
B(-7,15,-4,STONE:0)
B(-6,15,-4,STONE:0)
B(-5,15,-4,STONE:0)
B(-4,15,-4,STONE:0)
B(-3,15,-4,STONE:0)
B(-2,15,-4,STONE:0)
B(-1,15,-4,GRASS:0)
B(0,15,-4,AIR:0)
B(1,15,-4,WHEAT:7)
B(2,15,-4,WHEAT:7)
B(3,15,-4,WHEAT:7)
B(4,15,-4,AIR:0)
B(5,15,-4,AIR:0)
B(6,15,-4,WHEAT:7)
B(7,15,-4,WHEAT:7)
B(8,15,-4,WHEAT:7)
B(-7,15,-3,STONE:0)
B(-6,15,-3,STONE:0)
B(-5,15,-3,STONE:0)
B(-4,15,-3,STONE:0)
B(-3,15,-3,STONE:0)
B(-2,15,-3,STONE:0)
B(-1,15,-3,STONE:0)
B(0,15,-3,GRASS:0)
B(1,15,-3,WHEAT:7)
B(2,15,-3,WHEAT:7)
B(3,15,-3,WHEAT:7)
B(4,15,-3,WHEAT:7)
B(5,15,-3,AIR:0)
B(6,15,-3,WHEAT:7)
B(7,15,-3,WHEAT:7)
B(8,15,-3,WHEAT:7)
B(-7,15,-2,STONE:0)
B(-6,15,-2,STONE:0)
B(-5,15,-2,STONE:0)
B(-4,15,-2,STONE:0)
B(-3,15,-2,STONE:0)
B(-2,15,-2,STONE:0)
B(-1,15,-2,STONE:0)
B(0,15,-2,STONE:0)
B(1,15,-2,STONE:0)
B(2,15,-2,WHEAT:7)
B(3,15,-2,WHEAT:7)
B(4,15,-2,WHEAT:7)
B(5,15,-2,AIR:0)
B(6,15,-2,AIR:0)
B(7,15,-2,WHEAT:7)
B(8,15,-2,WHEAT:7)
B(-7,15,-1,STONE:0)
B(-6,15,-1,STONE:0)
B(-5,15,-1,STONE:0)
B(-4,15,-1,STONE:0)
B(-3,15,-1,STONE:0)
B(-2,15,-1,STONE:0)
B(-1,15,-1,STONE:0)
B(0,15,-1,STONE:0)
B(1,15,-1,STONE:0)
B(2,15,-1,STONE:0)
B(3,15,-1,WHEAT:7)
B(4,15,-1,WHEAT:7)
B(5,15,-1,AIR:0)
B(6,15,-1,AIR:0)
B(7,15,-1,WHEAT:7)
B(8,15,-1,WHEAT:7)
B(-7,15,0,STONE:0)
B(-6,15,0,STONE:0)
B(-5,15,0,STONE:0)
B(-4,15,0,STONE:0)
B(-3,15,0,STONE:0)
B(-2,15,0,STONE:0)
B(-1,15,0,STONE:0)
B(0,15,0,STONE:0)
B(1,15,0,STONE:0)
B(2,15,0,STONE:0)
B(3,15,0,STONE:0)
B(4,15,0,WHEAT:7)
B(5,15,0,WHEAT:7)
B(6,15,0,AIR:0)
B(7,15,0,AIR:0)
B(8,15,0,AIR:0)
B(-7,15,1,STONE:0)
B(-6,15,1,STONE:0)
B(-5,15,1,STONE:0)
B(-4,15,1,STONE:0)
B(-3,15,1,STONE:0)
B(-2,15,1,STONE:0)
B(-1,15,1,STONE:0)
B(0,15,1,STONE:0)
B(1,15,1,STONE:0)
B(2,15,1,STONE:0)
B(3,15,1,GRASS:0)
B(4,15,1,WHEAT:7)
B(5,15,1,WHEAT:7)
B(6,15,1,WHEAT:7)
B(7,15,1,WHEAT:7)
B(8,15,1,AIR:0)
B(-7,15,2,STONE:0)
B(-6,15,2,STONE:0)
B(-5,15,2,STONE:0)
B(-4,15,2,STONE:0)
B(-3,15,2,STONE:0)
B(-2,15,2,STONE:0)
B(-1,15,2,STONE:0)
B(0,15,2,STONE:0)
B(1,15,2,STONE:0)
B(2,15,2,DIRT:0)
B(3,15,2,HAY_BLOCK:0)
B(4,15,2,WHEAT:7)
B(5,15,2,WHEAT:7)
B(6,15,2,WHEAT:7)
B(7,15,2,WHEAT:7)
B(8,15,2,WHEAT:7)
B(-7,15,3,STONE:0)
B(-6,15,3,STONE:0)
B(-5,15,3,STONE:0)
B(-4,15,3,STONE:0)
B(-3,15,3,STONE:0)
B(-2,15,3,STONE:0)
B(-1,15,3,STONE:0)
B(0,15,3,STONE:0)
B(1,15,3,STONE:0)
B(2,15,3,STONE:0)
B(3,15,3,HAY_BLOCK:0)
B(4,15,3,WHEAT:7)
B(5,15,3,WHEAT:7)
B(6,15,3,WHEAT:7)
B(7,15,3,WHEAT:7)
B(8,15,3,WHEAT:7)
B(-7,15,4,STONE:0)
B(-6,15,4,STONE:0)
B(-5,15,4,STONE:0)
B(-4,15,4,STONE:0)
B(-3,15,4,STONE:0)
B(-2,15,4,STONE:0)
B(-1,15,4,STONE:0)
B(0,15,4,STONE:0)
B(1,15,4,STONE:0)
B(2,15,4,STONE:0)
B(3,15,4,STONE:0)
B(4,15,4,HAY_BLOCK:4)
B(5,15,4,WHEAT:7)
B(6,15,4,WHEAT:7)
B(7,15,4,WHEAT:7)
B(8,15,4,WHEAT:7)
B(-7,15,5,STONE:0)
B(-6,15,5,STONE:0)
B(-5,15,5,STONE:0)
B(-4,15,5,STONE:0)
B(-3,15,5,STONE:0)
B(-2,15,5,STONE:0)
B(-1,15,5,STONE:0)
B(0,15,5,STONE:0)
B(1,15,5,STONE:0)
B(2,15,5,STONE:0)
B(3,15,5,STONE:0)
B(4,15,5,STONE:0)
B(5,15,5,GRASS:0)
B(6,15,5,WHEAT:7)
B(7,15,5,WHEAT:7)
B(8,15,5,WHEAT:7)
B(-7,15,6,STONE:0)
B(-6,15,6,STONE:0)
B(-5,15,6,STONE:0)
B(-4,15,6,STONE:0)
B(-3,15,6,STONE:0)
B(-2,15,6,STONE:0)
B(-1,15,6,STONE:0)
B(0,15,6,STONE:0)
B(1,15,6,STONE:0)
B(2,15,6,STONE:0)
B(3,15,6,STONE:0)
B(4,15,6,STONE:0)
B(5,15,6,STONE:0)
B(6,15,6,HAY_BLOCK:4)
B(7,15,6,WHEAT:7)
B(8,15,6,WHEAT:7)
B(-7,15,7,STONE:0)
B(-6,15,7,STONE:0)
B(-5,15,7,STONE:0)
B(-4,15,7,STONE:0)
B(-3,15,7,STONE:0)
B(-2,15,7,STONE:0)
B(-1,15,7,STONE:0)
B(0,15,7,STONE:0)
B(1,15,7,STONE:0)
B(2,15,7,STONE:0)
B(3,15,7,STONE:0)
B(4,15,7,STONE:0)
B(5,15,7,STONE:0)
B(6,15,7,STONE:0)
B(7,15,7,HAY_BLOCK:8)
B(8,15,7,WHEAT:7)
B(-7,15,8,STONE:0)
B(-6,15,8,STONE:0)
B(-5,15,8,STONE:0)
B(-4,15,8,STONE:0)
B(-3,15,8,STONE:0)
B(-2,15,8,STONE:0)
B(-1,15,8,STONE:0)
B(0,15,8,STONE:0)
B(1,15,8,STONE:0)
B(2,15,8,STONE:0)
B(3,15,8,STONE:0)
B(4,15,8,STONE:0)
B(5,15,8,STONE:0)
B(6,15,8,STONE:0)
B(7,15,8,DIRT:0)
B(8,15,8,DIRT:0)
B(-7,16,-7,STONE:0)
B(-6,16,-7,STONE:0)
B(-5,16,-7,STONE:0)
B(-4,16,-7,GRASS:0)
B(-3,16,-7,GRASS:0)
B(-2,16,-7,AIR:0)
B(-1,16,-7,AIR:0)
B(0,16,-7,AIR:0)
B(1,16,-7,AIR:0)
B(2,16,-7,AIR:0)
B(3,16,-7,AIR:0)
B(4,16,-7,AIR:0)
B(5,16,-7,AIR:0)
B(6,16,-7,AIR:0)
B(7,16,-7,AIR:0)
B(8,16,-7,AIR:0)
B(-7,16,-6,STONE:0)
B(-6,16,-6,STONE:0)
B(-5,16,-6,STONE:0)
B(-4,16,-6,STONE:0)
B(-3,16,-6,STONE:0)
B(-2,16,-6,STONE:0)
B(-1,16,-6,AIR:0)
B(0,16,-6,AIR:0)
B(1,16,-6,AIR:0)
B(2,16,-6,AIR:0)
B(3,16,-6,AIR:0)
B(4,16,-6,AIR:0)
B(5,16,-6,AIR:0)
B(6,16,-6,AIR:0)
B(7,16,-6,AIR:0)
B(8,16,-6,AIR:0)
B(-7,16,-5,STONE:0)
B(-6,16,-5,STONE:0)
B(-5,16,-5,STONE:0)
B(-4,16,-5,STONE:0)
B(-3,16,-5,STONE:0)
B(-2,16,-5,STONE:0)
B(-1,16,-5,GRASS:0)
B(0,16,-5,AIR:0)
B(1,16,-5,AIR:0)
B(2,16,-5,AIR:0)
B(3,16,-5,AIR:0)
B(4,16,-5,AIR:0)
B(5,16,-5,AIR:0)
B(6,16,-5,AIR:0)
B(7,16,-5,AIR:0)
B(8,16,-5,AIR:0)
B(-7,16,-4,STONE:0)
B(-6,16,-4,STONE:0)
B(-5,16,-4,STONE:0)
B(-4,16,-4,STONE:0)
B(-3,16,-4,STONE:0)
B(-2,16,-4,STONE:0)
B(-1,16,-4,AIR:0)
B(0,16,-4,AIR:0)
B(1,16,-4,AIR:0)
B(2,16,-4,AIR:0)
B(3,16,-4,AIR:0)
B(4,16,-4,AIR:0)
B(5,16,-4,AIR:0)
B(6,16,-4,AIR:0)
B(7,16,-4,AIR:0)
B(8,16,-4,AIR:0)
B(-7,16,-3,STONE:0)
B(-6,16,-3,STONE:0)
B(-5,16,-3,STONE:0)
B(-4,16,-3,STONE:0)
B(-3,16,-3,STONE:0)
B(-2,16,-3,STONE:0)
B(-1,16,-3,STONE:0)
B(0,16,-3,AIR:0)
B(1,16,-3,AIR:0)
B(2,16,-3,AIR:0)
B(3,16,-3,AIR:0)
B(4,16,-3,AIR:0)
B(5,16,-3,AIR:0)
B(6,16,-3,AIR:0)
B(7,16,-3,AIR:0)
B(8,16,-3,AIR:0)
B(-7,16,-2,STONE:0)
B(-6,16,-2,STONE:0)
B(-5,16,-2,STONE:0)
B(-4,16,-2,STONE:0)
B(-3,16,-2,STONE:0)
B(-2,16,-2,STONE:0)
B(-1,16,-2,STONE:0)
B(0,16,-2,STONE:0)
B(1,16,-2,STONE:0)
B(2,16,-2,AIR:0)
B(3,16,-2,AIR:0)
B(4,16,-2,AIR:0)
B(5,16,-2,AIR:0)
B(6,16,-2,AIR:0)
B(7,16,-2,AIR:0)
B(8,16,-2,AIR:0)
B(-7,16,-1,STONE:0)
B(-6,16,-1,STONE:0)
B(-5,16,-1,STONE:0)
B(-4,16,-1,STONE:0)
B(-3,16,-1,STONE:0)
B(-2,16,-1,STONE:0)
B(-1,16,-1,STONE:0)
B(0,16,-1,STONE:0)
B(1,16,-1,STONE:0)
B(2,16,-1,GRASS:0)
B(3,16,-1,AIR:0)
B(4,16,-1,AIR:0)
B(5,16,-1,AIR:0)
B(6,16,-1,AIR:0)
B(7,16,-1,AIR:0)
B(8,16,-1,AIR:0)
B(-7,16,0,STONE:0)
B(-6,16,0,STONE:0)
B(-5,16,0,STONE:0)
B(-4,16,0,STONE:0)
B(-3,16,0,STONE:0)
B(-2,16,0,STONE:0)
B(-1,16,0,STONE:0)
B(0,16,0,STONE:0)
B(1,16,0,STONE:0)
B(2,16,0,STONE:0)
B(3,16,0,STONE:0)
B(4,16,0,AIR:0)
B(5,16,0,AIR:0)
B(6,16,0,AIR:0)
B(7,16,0,AIR:0)
B(8,16,0,AIR:0)
B(-7,16,1,STONE:0)
B(-6,16,1,STONE:0)
B(-5,16,1,STONE:0)
B(-4,16,1,STONE:0)
B(-3,16,1,STONE:0)
B(-2,16,1,STONE:0)
B(-1,16,1,STONE:0)
B(0,16,1,STONE:0)
B(1,16,1,STONE:0)
B(2,16,1,GRASS:0)
B(3,16,1,AIR:0)
B(4,16,1,AIR:0)
B(5,16,1,AIR:0)
B(6,16,1,AIR:0)
B(7,16,1,AIR:0)
B(8,16,1,AIR:0)
B(-7,16,2,STONE:0)
B(-6,16,2,STONE:0)
B(-5,16,2,STONE:0)
B(-4,16,2,STONE:0)
B(-3,16,2,STONE:0)
B(-2,16,2,STONE:0)
B(-1,16,2,STONE:0)
B(0,16,2,STONE:0)
B(1,16,2,STONE:0)
B(2,16,2,GRASS:0)
B(3,16,2,AIR:0)
B(4,16,2,AIR:0)
B(5,16,2,AIR:0)
B(6,16,2,AIR:0)
B(7,16,2,AIR:0)
B(8,16,2,AIR:0)
B(-7,16,3,STONE:0)
B(-6,16,3,STONE:0)
B(-5,16,3,STONE:0)
B(-4,16,3,STONE:0)
B(-3,16,3,STONE:0)
B(-2,16,3,STONE:0)
B(-1,16,3,STONE:0)
B(0,16,3,STONE:0)
B(1,16,3,STONE:0)
B(2,16,3,GRASS:0)
B(3,16,3,HAY_BLOCK:0)
B(4,16,3,AIR:0)
B(5,16,3,AIR:0)
B(6,16,3,AIR:0)
B(7,16,3,AIR:0)
B(8,16,3,AIR:0)
B(-7,16,4,STONE:0)
B(-6,16,4,STONE:0)
B(-5,16,4,STONE:0)
B(-4,16,4,STONE:0)
B(-3,16,4,STONE:0)
B(-2,16,4,STONE:0)
B(-1,16,4,STONE:0)
B(0,16,4,STONE:0)
B(1,16,4,DIRT:0)
B(2,16,4,STONE:0)
B(3,16,4,STONE:0)
B(4,16,4,AIR:0)
B(5,16,4,AIR:0)
B(6,16,4,AIR:0)
B(7,16,4,AIR:0)
B(8,16,4,AIR:0)
B(-7,16,5,STONE:0)
B(-6,16,5,STONE:0)
B(-5,16,5,STONE:0)
B(-4,16,5,STONE:0)
B(-3,16,5,STONE:0)
B(-2,16,5,STONE:0)
B(-1,16,5,STONE:0)
B(0,16,5,DIRT:0)
B(1,16,5,DIRT:0)
B(2,16,5,DIRT:0)
B(3,16,5,STONE:0)
B(4,16,5,GRASS:0)
B(5,16,5,AIR:0)
B(6,16,5,AIR:0)
B(7,16,5,AIR:0)
B(8,16,5,AIR:0)
B(-7,16,6,STONE:0)
B(-6,16,6,STONE:0)
B(-5,16,6,STONE:0)
B(-4,16,6,STONE:0)
B(-3,16,6,STONE:0)
B(-2,16,6,DIRT:0)
B(-1,16,6,DIRT:0)
B(0,16,6,DIRT:0)
B(1,16,6,DIRT:0)
B(2,16,6,STONE:0)
B(3,16,6,DIRT:0)
B(4,16,6,STONE:0)
B(5,16,6,DIRT:0)
B(6,16,6,AIR:0)
B(7,16,6,AIR:0)
B(8,16,6,AIR:0)
B(-7,16,7,STONE:0)
B(-6,16,7,STONE:0)
B(-5,16,7,STONE:0)
B(-4,16,7,STONE:0)
B(-3,16,7,DIRT:0)
B(-2,16,7,DIRT:0)
B(-1,16,7,DIRT:0)
B(0,16,7,DIRT:0)
B(1,16,7,STONE:0)
B(2,16,7,DIRT:0)
B(3,16,7,STONE:0)
B(4,16,7,DIRT:0)
B(5,16,7,STONE:0)
B(6,16,7,STONE:0)
B(7,16,7,AIR:0)
B(8,16,7,AIR:0)
B(-7,16,8,STONE:0)
B(-6,16,8,STONE:0)
B(-5,16,8,STONE:0)
B(-4,16,8,STONE:0)
B(-3,16,8,STONE:0)
B(-2,16,8,STONE:0)
B(-1,16,8,STONE:0)
B(0,16,8,STONE:0)
B(1,16,8,DIRT:0)
B(2,16,8,DIRT:0)
B(3,16,8,DIRT:0)
B(4,16,8,DIRT:0)
B(5,16,8,DIRT:0)
B(6,16,8,STONE:0)
B(7,16,8,HAY_BLOCK:0)
B(8,16,8,HAY_BLOCK:0)
B(-7,17,-7,AIR:0)
B(-6,17,-7,STONE:0)
B(-5,17,-7,STONE:0)
B(-4,17,-7,AIR:0)
B(-3,17,-7,AIR:0)
B(-2,17,-7,AIR:0)
B(-1,17,-7,AIR:0)
B(0,17,-7,AIR:0)
B(1,17,-7,AIR:0)
B(2,17,-7,AIR:0)
B(3,17,-7,AIR:0)
B(4,17,-7,AIR:0)
B(5,17,-7,AIR:0)
B(6,17,-7,AIR:0)
B(7,17,-7,AIR:0)
B(8,17,-7,AIR:0)
B(-7,17,-6,STONE:0)
B(-6,17,-6,STONE:0)
B(-5,17,-6,STONE:0)
B(-4,17,-6,STONE:0)
B(-3,17,-6,STONE:0)
B(-2,17,-6,GRASS:0)
B(-1,17,-6,AIR:0)
B(0,17,-6,AIR:0)
B(1,17,-6,AIR:0)
B(2,17,-6,AIR:0)
B(3,17,-6,AIR:0)
B(4,17,-6,AIR:0)
B(5,17,-6,AIR:0)
B(6,17,-6,AIR:0)
B(7,17,-6,AIR:0)
B(8,17,-6,AIR:0)
B(-7,17,-5,STONE:0)
B(-6,17,-5,STONE:0)
B(-5,17,-5,STONE:0)
B(-4,17,-5,STONE:0)
B(-3,17,-5,STONE:0)
B(-2,17,-5,STONE:0)
B(-1,17,-5,AIR:0)
B(0,17,-5,AIR:0)
B(1,17,-5,AIR:0)
B(2,17,-5,AIR:0)
B(3,17,-5,AIR:0)
B(4,17,-5,AIR:0)
B(5,17,-5,AIR:0)
B(6,17,-5,AIR:0)
B(7,17,-5,AIR:0)
B(8,17,-5,AIR:0)
B(-7,17,-4,STONE:0)
B(-6,17,-4,STONE:0)
B(-5,17,-4,STONE:0)
B(-4,17,-4,STONE:0)
B(-3,17,-4,STONE:0)
B(-2,17,-4,DIRT:0)
B(-1,17,-4,AIR:0)
B(0,17,-4,AIR:0)
B(1,17,-4,AIR:0)
B(2,17,-4,AIR:0)
B(3,17,-4,AIR:0)
B(4,17,-4,AIR:0)
B(5,17,-4,AIR:0)
B(6,17,-4,AIR:0)
B(7,17,-4,AIR:0)
B(8,17,-4,AIR:0)
B(-7,17,-3,STONE:0)
B(-6,17,-3,STONE:0)
B(-5,17,-3,STONE:0)
B(-4,17,-3,STONE:0)
B(-3,17,-3,STONE:0)
B(-2,17,-3,STONE:0)
B(-1,17,-3,STONE:0)
B(0,17,-3,AIR:0)
B(1,17,-3,AIR:0)
B(2,17,-3,AIR:0)
B(3,17,-3,AIR:0)
B(4,17,-3,AIR:0)
B(5,17,-3,AIR:0)
B(6,17,-3,AIR:0)
B(7,17,-3,AIR:0)
B(8,17,-3,AIR:0)
B(-7,17,-2,STONE:0)
B(-6,17,-2,STONE:0)
B(-5,17,-2,STONE:0)
B(-4,17,-2,STONE:0)
B(-3,17,-2,STONE:0)
B(-2,17,-2,STONE:0)
B(-1,17,-2,STONE:0)
B(0,17,-2,STONE:0)
B(1,17,-2,GRASS:0)
B(2,17,-2,AIR:0)
B(3,17,-2,AIR:0)
B(4,17,-2,AIR:0)
B(5,17,-2,AIR:0)
B(6,17,-2,AIR:0)
B(7,17,-2,AIR:0)
B(8,17,-2,AIR:0)
B(-7,17,-1,STONE:0)
B(-6,17,-1,STONE:0)
B(-5,17,-1,STONE:0)
B(-4,17,-1,STONE:0)
B(-3,17,-1,STONE:0)
B(-2,17,-1,STONE:0)
B(-1,17,-1,STONE:0)
B(0,17,-1,STONE:0)
B(1,17,-1,STONE:0)
B(2,17,-1,AIR:0)
B(3,17,-1,AIR:0)
B(4,17,-1,AIR:0)
B(5,17,-1,AIR:0)
B(6,17,-1,AIR:0)
B(7,17,-1,AIR:0)
B(8,17,-1,AIR:0)
B(-7,17,0,STONE:0)
B(-6,17,0,STONE:0)
B(-5,17,0,STONE:0)
B(-4,17,0,STONE:0)
B(-3,17,0,STONE:0)
B(-2,17,0,STONE:0)
B(-1,17,0,STONE:0)
B(0,17,0,STONE:0)
B(1,17,0,STONE:0)
B(2,17,0,STONE:0)
B(3,17,0,GRASS:0)
B(4,17,0,AIR:0)
B(5,17,0,AIR:0)
B(6,17,0,AIR:0)
B(7,17,0,AIR:0)
B(8,17,0,AIR:0)
B(-7,17,1,STONE:0)
B(-6,17,1,STONE:0)
B(-5,17,1,STONE:0)
B(-4,17,1,STONE:0)
B(-3,17,1,STONE:0)
B(-2,17,1,STONE:0)
B(-1,17,1,STONE:0)
B(0,17,1,STONE:0)
B(1,17,1,GRASS:0)
B(2,17,1,AIR:0)
B(3,17,1,AIR:0)
B(4,17,1,AIR:0)
B(5,17,1,AIR:0)
B(6,17,1,AIR:0)
B(7,17,1,AIR:0)
B(8,17,1,AIR:0)
B(-7,17,2,STONE:0)
B(-6,17,2,STONE:0)
B(-5,17,2,STONE:0)
B(-4,17,2,STONE:0)
B(-3,17,2,STONE:0)
B(-2,17,2,STONE:0)
B(-1,17,2,DIRT:0)
B(0,17,2,STONE:0)
B(1,17,2,STONE:0)
B(2,17,2,RED_FLOWER:8)
B(3,17,2,AIR:0)
B(4,17,2,AIR:0)
B(5,17,2,AIR:0)
B(6,17,2,AIR:0)
B(7,17,2,AIR:0)
B(8,17,2,AIR:0)
B(-7,17,3,STONE:0)
B(-6,17,3,STONE:0)
B(-5,17,3,STONE:0)
B(-4,17,3,STONE:0)
B(-3,17,3,DIRT:0)
B(-2,17,3,DIRT:0)
B(-1,17,3,DIRT:0)
B(0,17,3,DIRT:0)
B(1,17,3,STONE:0)
B(2,17,3,TALLGRASS:1)
B(3,17,3,AIR:0)
B(4,17,3,AIR:0)
B(5,17,3,AIR:0)
B(6,17,3,AIR:0)
B(7,17,3,AIR:0)
B(8,17,3,AIR:0)
B(-7,17,4,STONE:0)
B(-6,17,4,STONE:0)
B(-5,17,4,STONE:0)
B(-4,17,4,STONE:0)
B(-3,17,4,DIRT:0)
B(-2,17,4,DIRT:0)
B(-1,17,4,DIRT:0)
B(0,17,4,GRASS:0)
B(1,17,4,GRASS:0)
B(2,17,4,STONE:0)
B(3,17,4,GRASS:0)
B(4,17,4,AIR:0)
B(5,17,4,AIR:0)
B(6,17,4,AIR:0)
B(7,17,4,AIR:0)
B(8,17,4,AIR:0)
B(-7,17,5,STONE:0)
B(-6,17,5,STONE:0)
B(-5,17,5,STONE:0)
B(-4,17,5,STONE:0)
B(-3,17,5,STONE:0)
B(-2,17,5,GRASS:0)
B(-1,17,5,GRASS:0)
B(0,17,5,GRASS:0)
B(1,17,5,GRASS:0)
B(2,17,5,GRASS:0)
B(3,17,5,STONE:0)
B(4,17,5,AIR:0)
B(5,17,5,AIR:0)
B(6,17,5,AIR:0)
B(7,17,5,AIR:0)
B(8,17,5,AIR:0)
B(-7,17,6,STONE:0)
B(-6,17,6,STONE:0)
B(-5,17,6,STONE:0)
B(-4,17,6,STONE:0)
B(-3,17,6,DIRT:0)
B(-2,17,6,DIRT:0)
B(-1,17,6,GRASS:0)
B(0,17,6,GRASS:0)
B(1,17,6,GRASS:0)
B(2,17,6,GRASS:0)
B(3,17,6,GRASS:0)
B(4,17,6,GRASS:0)
B(5,17,6,GRASS:0)
B(6,17,6,AIR:0)
B(7,17,6,AIR:0)
B(8,17,6,AIR:0)
B(-7,17,7,STONE:0)
B(-6,17,7,STONE:0)
B(-5,17,7,STONE:0)
B(-4,17,7,STONE:0)
B(-3,17,7,STONE:0)
B(-2,17,7,STONE:0)
B(-1,17,7,STONE:0)
B(0,17,7,STONE:0)
B(1,17,7,GRASS:0)
B(2,17,7,GRASS:0)
B(3,17,7,GRASS:0)
B(4,17,7,GRASS:0)
B(5,17,7,STONE:0)
B(6,17,7,STONE:0)
B(7,17,7,AIR:0)
B(8,17,7,AIR:0)
B(-7,17,8,STONE:0)
B(-6,17,8,STONE:0)
B(-5,17,8,STONE:0)
B(-4,17,8,STONE:0)
B(-3,17,8,STONE:0)
B(-2,17,8,STONE:0)
B(-1,17,8,STONE:0)
B(0,17,8,STONE:0)
B(1,17,8,STONE:0)
B(2,17,8,GRASS:0)
B(3,17,8,GRASS:0)
B(4,17,8,GRASS:0)
B(5,17,8,GRASS:0)
B(6,17,8,GRASS:0)
B(7,17,8,AIR:0)
B(8,17,8,AIR:0)
B(-7,18,-7,AIR:0)
B(-6,18,-7,STONE:0)
B(-5,18,-7,STONE:0)
B(-4,18,-7,AIR:0)
B(-3,18,-7,AIR:0)
B(-2,18,-7,AIR:0)
B(-1,18,-7,AIR:0)
B(0,18,-7,AIR:0)
B(1,18,-7,AIR:0)
B(2,18,-7,AIR:0)
B(3,18,-7,AIR:0)
B(4,18,-7,AIR:0)
B(5,18,-7,AIR:0)
B(6,18,-7,AIR:0)
B(7,18,-7,AIR:0)
B(8,18,-7,AIR:0)
B(-7,18,-6,STONE:0)
B(-6,18,-6,STONE:0)
B(-5,18,-6,STONE:0)
B(-4,18,-6,STONE:0)
B(-3,18,-6,STONE:0)
B(-2,18,-6,AIR:0)
B(-1,18,-6,AIR:0)
B(0,18,-6,AIR:0)
B(1,18,-6,AIR:0)
B(2,18,-6,AIR:0)
B(3,18,-6,AIR:0)
B(4,18,-6,AIR:0)
B(5,18,-6,AIR:0)
B(6,18,-6,AIR:0)
B(7,18,-6,AIR:0)
B(8,18,-6,AIR:0)
B(-7,18,-5,STONE:0)
B(-6,18,-5,STONE:0)
B(-5,18,-5,STONE:0)
B(-4,18,-5,STONE:0)
B(-3,18,-5,STONE:0)
B(-2,18,-5,STONE:0)
B(-1,18,-5,AIR:0)
B(0,18,-5,AIR:0)
B(1,18,-5,AIR:0)
B(2,18,-5,AIR:0)
B(3,18,-5,AIR:0)
B(4,18,-5,AIR:0)
B(5,18,-5,AIR:0)
B(6,18,-5,AIR:0)
B(7,18,-5,AIR:0)
B(8,18,-5,AIR:0)
B(-7,18,-4,STONE:0)
B(-6,18,-4,STONE:0)
B(-5,18,-4,STONE:0)
B(-4,18,-4,STONE:0)
B(-3,18,-4,STONE:0)
B(-2,18,-4,GRASS:0)
B(-1,18,-4,AIR:0)
B(0,18,-4,AIR:0)
B(1,18,-4,AIR:0)
B(2,18,-4,AIR:0)
B(3,18,-4,AIR:0)
B(4,18,-4,AIR:0)
B(5,18,-4,AIR:0)
B(6,18,-4,AIR:0)
B(7,18,-4,AIR:0)
B(8,18,-4,AIR:0)
B(-7,18,-3,STONE:0)
B(-6,18,-3,STONE:0)
B(-5,18,-3,STONE:0)
B(-4,18,-3,STONE:0)
B(-3,18,-3,STONE:0)
B(-2,18,-3,STONE:0)
B(-1,18,-3,GRASS:0)
B(0,18,-3,AIR:0)
B(1,18,-3,AIR:0)
B(2,18,-3,AIR:0)
B(3,18,-3,AIR:0)
B(4,18,-3,AIR:0)
B(5,18,-3,AIR:0)
B(6,18,-3,AIR:0)
B(7,18,-3,AIR:0)
B(8,18,-3,AIR:0)
B(-7,18,-2,STONE:0)
B(-6,18,-2,STONE:0)
B(-5,18,-2,STONE:0)
B(-4,18,-2,STONE:0)
B(-3,18,-2,STONE:0)
B(-2,18,-2,STONE:0)
B(-1,18,-2,STONE:0)
B(0,18,-2,GRASS:0)
B(1,18,-2,AIR:0)
B(2,18,-2,AIR:0)
B(3,18,-2,AIR:0)
B(4,18,-2,AIR:0)
B(5,18,-2,AIR:0)
B(6,18,-2,AIR:0)
B(7,18,-2,AIR:0)
B(8,18,-2,AIR:0)
B(-7,18,-1,STONE:0)
B(-6,18,-1,STONE:0)
B(-5,18,-1,STONE:0)
B(-4,18,-1,STONE:0)
B(-3,18,-1,STONE:0)
B(-2,18,-1,STONE:0)
B(-1,18,-1,STONE:0)
B(0,18,-1,STONE:0)
B(1,18,-1,GRASS:0)
B(2,18,-1,AIR:0)
B(3,18,-1,AIR:0)
B(4,18,-1,AIR:0)
B(5,18,-1,AIR:0)
B(6,18,-1,AIR:0)
B(7,18,-1,AIR:0)
B(8,18,-1,AIR:0)
B(-7,18,0,STONE:0)
B(-6,18,0,STONE:0)
B(-5,18,0,STONE:0)
B(-4,18,0,STONE:0)
B(-3,18,0,STONE:0)
B(-2,18,0,STONE:0)
B(-1,18,0,STONE:0)
B(0,18,0,STONE:0)
B(1,18,0,GRASS:0)
B(2,18,0,STONE:0)
B(3,18,0,AIR:0)
B(4,18,0,AIR:0)
B(5,18,0,AIR:0)
B(6,18,0,AIR:0)
B(7,18,0,AIR:0)
B(8,18,0,AIR:0)
B(-7,18,1,STONE:0)
B(-6,18,1,STONE:0)
B(-5,18,1,STONE:0)
B(-4,18,1,STONE:0)
B(-3,18,1,DIRT:0)
B(-2,18,1,DIRT:0)
B(-1,18,1,DIRT:0)
B(0,18,1,STONE:0)
B(1,18,1,AIR:0)
B(2,18,1,AIR:0)
B(3,18,1,AIR:0)
B(4,18,1,AIR:0)
B(5,18,1,AIR:0)
B(6,18,1,AIR:0)
B(7,18,1,AIR:0)
B(8,18,1,AIR:0)
B(-7,18,2,STONE:0)
B(-6,18,2,STONE:0)
B(-5,18,2,STONE:0)
B(-4,18,2,STONE:0)
B(-3,18,2,DIRT:0)
B(-2,18,2,DIRT:0)
B(-1,18,2,DIRT:0)
B(0,18,2,STONE:0)
B(1,18,2,DIRT:0)
B(2,18,2,AIR:0)
B(3,18,2,AIR:0)
B(4,18,2,AIR:0)
B(5,18,2,AIR:0)
B(6,18,2,AIR:0)
B(7,18,2,AIR:0)
B(8,18,2,AIR:0)
B(-7,18,3,STONE:0)
B(-6,18,3,STONE:0)
B(-5,18,3,STONE:0)
B(-4,18,3,STONE:0)
B(-3,18,3,DIRT:0)
B(-2,18,3,DIRT:0)
B(-1,18,3,GRASS:0)
B(0,18,3,GRASS:0)
B(1,18,3,STONE:0)
B(2,18,3,AIR:0)
B(3,18,3,AIR:0)
B(4,18,3,AIR:0)
B(5,18,3,AIR:0)
B(6,18,3,AIR:0)
B(7,18,3,AIR:0)
B(8,18,3,AIR:0)
B(-7,18,4,STONE:0)
B(-6,18,4,STONE:0)
B(-5,18,4,STONE:0)
B(-4,18,4,STONE:0)
B(-3,18,4,DIRT:0)
B(-2,18,4,GRASS:0)
B(-1,18,4,GRASS:0)
B(0,18,4,TALLGRASS:1)
B(1,18,4,AIR:0)
B(2,18,4,GRASS:0)
B(3,18,4,TALLGRASS:1)
B(4,18,4,AIR:0)
B(5,18,4,AIR:0)
B(6,18,4,AIR:0)
B(7,18,4,AIR:0)
B(8,18,4,AIR:0)
B(-7,18,5,STONE:0)
B(-6,18,5,STONE:0)
B(-5,18,5,STONE:0)
B(-4,18,5,STONE:0)
B(-3,18,5,STONE:0)
B(-2,18,5,AIR:0)
B(-1,18,5,AIR:0)
B(0,18,5,YELLOW_FLOWER:0)
B(1,18,5,YELLOW_FLOWER:0)
B(2,18,5,TALLGRASS:1)
B(3,18,5,GRASS:0)
B(4,18,5,AIR:0)
B(5,18,5,AIR:0)
B(6,18,5,AIR:0)
B(7,18,5,AIR:0)
B(8,18,5,AIR:0)
B(-7,18,6,STONE:0)
B(-6,18,6,STONE:0)
B(-5,18,6,STONE:0)
B(-4,18,6,STONE:0)
B(-3,18,6,GRASS:0)
B(-2,18,6,GRASS:0)
B(-1,18,6,TALLGRASS:1)
B(0,18,6,TALLGRASS:1)
B(1,18,6,TALLGRASS:1)
B(2,18,6,TALLGRASS:1)
B(3,18,6,TALLGRASS:1)
B(4,18,6,TALLGRASS:1)
B(5,18,6,TALLGRASS:1)
B(6,18,6,AIR:0)
B(7,18,6,AIR:0)
B(8,18,6,AIR:0)
B(-7,18,7,STONE:0)
B(-6,18,7,STONE:0)
B(-5,18,7,STONE:0)
B(-4,18,7,STONE:0)
B(-3,18,7,STONE:0)
B(-2,18,7,STONE:0)
B(-1,18,7,DIRT:0)
B(0,18,7,GRASS:0)
B(1,18,7,TALLGRASS:1)
B(2,18,7,TALLGRASS:1)
B(3,18,7,TALLGRASS:1)
B(4,18,7,TALLGRASS:1)
B(5,18,7,STONE:0)
B(6,18,7,GRASS:0)
B(7,18,7,AIR:0)
B(8,18,7,AIR:0)
B(-7,18,8,STONE:0)
B(-6,18,8,STONE:0)
B(-5,18,8,STONE:0)
B(-4,18,8,STONE:0)
B(-3,18,8,STONE:0)
B(-2,18,8,STONE:0)
B(-1,18,8,STONE:0)
B(0,18,8,STONE:0)
B(1,18,8,DIRT:0)
B(2,18,8,TALLGRASS:1)
B(3,18,8,TALLGRASS:1)
B(4,18,8,TALLGRASS:1)
B(5,18,8,AIR:0)
B(6,18,8,TALLGRASS:1)
B(7,18,8,AIR:0)
B(8,18,8,AIR:0)
B(-7,19,-7,AIR:0)
B(-6,19,-7,STONE:0)
B(-5,19,-7,STONE:0)
B(-4,19,-7,AIR:0)
B(-3,19,-7,AIR:0)
B(-2,19,-7,AIR:0)
B(-1,19,-7,AIR:0)
B(0,19,-7,AIR:0)
B(1,19,-7,AIR:0)
B(2,19,-7,AIR:0)
B(3,19,-7,AIR:0)
B(4,19,-7,AIR:0)
B(5,19,-7,AIR:0)
B(6,19,-7,AIR:0)
B(7,19,-7,AIR:0)
B(8,19,-7,AIR:0)
B(-7,19,-6,STONE:0)
B(-6,19,-6,STONE:0)
B(-5,19,-6,STONE:0)
B(-4,19,-6,STONE:0)
B(-3,19,-6,DIRT:0)
B(-2,19,-6,AIR:0)
B(-1,19,-6,AIR:0)
B(0,19,-6,AIR:0)
B(1,19,-6,AIR:0)
B(2,19,-6,AIR:0)
B(3,19,-6,AIR:0)
B(4,19,-6,AIR:0)
B(5,19,-6,AIR:0)
B(6,19,-6,AIR:0)
B(7,19,-6,AIR:0)
B(8,19,-6,AIR:0)
B(-7,19,-5,STONE:0)
B(-6,19,-5,STONE:0)
B(-5,19,-5,STONE:0)
B(-4,19,-5,STONE:0)
B(-3,19,-5,STONE:0)
B(-2,19,-5,STONE:0)
B(-1,19,-5,AIR:0)
B(0,19,-5,AIR:0)
B(1,19,-5,AIR:0)
B(2,19,-5,AIR:0)
B(3,19,-5,AIR:0)
B(4,19,-5,AIR:0)
B(5,19,-5,AIR:0)
B(6,19,-5,AIR:0)
B(7,19,-5,AIR:0)
B(8,19,-5,AIR:0)
B(-7,19,-4,STONE:0)
B(-6,19,-4,STONE:0)
B(-5,19,-4,STONE:0)
B(-4,19,-4,STONE:0)
B(-3,19,-4,STONE:0)
B(-2,19,-4,AIR:0)
B(-1,19,-4,AIR:0)
B(0,19,-4,AIR:0)
B(1,19,-4,AIR:0)
B(2,19,-4,AIR:0)
B(3,19,-4,AIR:0)
B(4,19,-4,AIR:0)
B(5,19,-4,AIR:0)
B(6,19,-4,AIR:0)
B(7,19,-4,AIR:0)
B(8,19,-4,AIR:0)
B(-7,19,-3,STONE:0)
B(-6,19,-3,STONE:0)
B(-5,19,-3,DIRT:0)
B(-4,19,-3,DIRT:0)
B(-3,19,-3,DIRT:0)
B(-2,19,-3,STONE:0)
B(-1,19,-3,AIR:0)
B(0,19,-3,AIR:0)
B(1,19,-3,AIR:0)
B(2,19,-3,AIR:0)
B(3,19,-3,AIR:0)
B(4,19,-3,AIR:0)
B(5,19,-3,AIR:0)
B(6,19,-3,AIR:0)
B(7,19,-3,AIR:0)
B(8,19,-3,AIR:0)
B(-7,19,-2,STONE:0)
B(-6,19,-2,STONE:0)
B(-5,19,-2,AIR:0)
B(-4,19,-2,DIRT:0)
B(-3,19,-2,DIRT:0)
B(-2,19,-2,DIRT:0)
B(-1,19,-2,GRASS:0)
B(0,19,-2,TALLGRASS:1)
B(1,19,-2,AIR:0)
B(2,19,-2,AIR:0)
B(3,19,-2,AIR:0)
B(4,19,-2,AIR:0)
B(5,19,-2,AIR:0)
B(6,19,-2,AIR:0)
B(7,19,-2,AIR:0)
B(8,19,-2,AIR:0)
B(-7,19,-1,STONE:0)
B(-6,19,-1,STONE:0)
B(-5,19,-1,STONE:0)
B(-4,19,-1,DIRT:0)
B(-3,19,-1,DIRT:0)
B(-2,19,-1,DIRT:0)
B(-1,19,-1,STONE:0)
B(0,19,-1,STONE:0)
B(1,19,-1,TALLGRASS:1)
B(2,19,-1,AIR:0)
B(3,19,-1,AIR:0)
B(4,19,-1,AIR:0)
B(5,19,-1,AIR:0)
B(6,19,-1,AIR:0)
B(7,19,-1,AIR:0)
B(8,19,-1,AIR:0)
B(-7,19,0,STONE:0)
B(-6,19,0,STONE:0)
B(-5,19,0,STONE:0)
B(-4,19,0,STONE:0)
B(-3,19,0,DIRT:0)
B(-2,19,0,DIRT:0)
B(-1,19,0,STONE:0)
B(0,19,0,DIRT:0)
B(1,19,0,TALLGRASS:1)
B(2,19,0,GRASS:0)
B(3,19,0,AIR:0)
B(4,19,0,AIR:0)
B(5,19,0,AIR:0)
B(6,19,0,AIR:0)
B(7,19,0,AIR:0)
B(8,19,0,AIR:0)
B(-7,19,1,STONE:0)
B(-6,19,1,STONE:0)
B(-5,19,1,STONE:0)
B(-4,19,1,STONE:0)
B(-3,19,1,DIRT:0)
B(-2,19,1,DIRT:0)
B(-1,19,1,DIRT:0)
B(0,19,1,STONE:0)
B(1,19,1,AIR:0)
B(2,19,1,AIR:0)
B(3,19,1,AIR:0)
B(4,19,1,AIR:0)
B(5,19,1,AIR:0)
B(6,19,1,AIR:0)
B(7,19,1,AIR:0)
B(8,19,1,AIR:0)
B(-7,19,2,STONE:0)
B(-6,19,2,STONE:0)
B(-5,19,2,STONE:0)
B(-4,19,2,STONE:0)
B(-3,19,2,DIRT:0)
B(-2,19,2,GRASS:0)
B(-1,19,2,GRASS:0)
B(0,19,2,STONE:0)
B(1,19,2,GRASS:0)
B(2,19,2,AIR:0)
B(3,19,2,AIR:0)
B(4,19,2,AIR:0)
B(5,19,2,AIR:0)
B(6,19,2,AIR:0)
B(7,19,2,AIR:0)
B(8,19,2,AIR:0)
B(-7,19,3,STONE:0)
B(-6,19,3,STONE:0)
B(-5,19,3,STONE:0)
B(-4,19,3,STONE:0)
B(-3,19,3,GRASS:0)
B(-2,19,3,GRASS:0)
B(-1,19,3,TALLGRASS:1)
B(0,19,3,TALLGRASS:1)
B(1,19,3,GRASS:0)
B(2,19,3,AIR:0)
B(3,19,3,AIR:0)
B(4,19,3,AIR:0)
B(5,19,3,AIR:0)
B(6,19,3,AIR:0)
B(7,19,3,AIR:0)
B(8,19,3,AIR:0)
B(-7,19,4,STONE:0)
B(-6,19,4,STONE:0)
B(-5,19,4,STONE:0)
B(-4,19,4,STONE:0)
B(-3,19,4,GRASS:0)
B(-2,19,4,TALLGRASS:1)
B(-1,19,4,YELLOW_FLOWER:0)
B(0,19,4,AIR:0)
B(1,19,4,AIR:0)
B(2,19,4,AIR:0)
B(3,19,4,AIR:0)
B(4,19,4,AIR:0)
B(5,19,4,AIR:0)
B(6,19,4,AIR:0)
B(7,19,4,AIR:0)
B(8,19,4,AIR:0)
B(-7,19,5,STONE:0)
B(-6,19,5,STONE:0)
B(-5,19,5,STONE:0)
B(-4,19,5,STONE:0)
B(-3,19,5,GRASS:0)
B(-2,19,5,AIR:0)
B(-1,19,5,AIR:0)
B(0,19,5,AIR:0)
B(1,19,5,AIR:0)
B(2,19,5,AIR:0)
B(3,19,5,AIR:0)
B(4,19,5,AIR:0)
B(5,19,5,AIR:0)
B(6,19,5,AIR:0)
B(7,19,5,AIR:0)
B(8,19,5,AIR:0)
B(-7,19,6,STONE:0)
B(-6,19,6,STONE:0)
B(-5,19,6,STONE:0)
B(-4,19,6,STONE:0)
B(-3,19,6,AIR:0)
B(-2,19,6,TALLGRASS:1)
B(-1,19,6,AIR:0)
B(0,19,6,AIR:0)
B(1,19,6,AIR:0)
B(2,19,6,AIR:0)
B(3,19,6,AIR:0)
B(4,19,6,AIR:0)
B(5,19,6,AIR:0)
B(6,19,6,AIR:0)
B(7,19,6,AIR:0)
B(8,19,6,AIR:0)
B(-7,19,7,STONE:0)
B(-6,19,7,STONE:0)
B(-5,19,7,STONE:0)
B(-4,19,7,STONE:0)
B(-3,19,7,STONE:0)
B(-2,19,7,STONE:0)
B(-1,19,7,GRASS:0)
B(0,19,7,AIR:0)
B(1,19,7,AIR:0)
B(2,19,7,AIR:0)
B(3,19,7,AIR:0)
B(4,19,7,AIR:0)
B(5,19,7,STONE:0)
B(6,19,7,AIR:0)
B(7,19,7,AIR:0)
B(8,19,7,AIR:0)
B(-7,19,8,STONE:0)
B(-6,19,8,STONE:0)
B(-5,19,8,STONE:0)
B(-4,19,8,STONE:0)
B(-3,19,8,STONE:0)
B(-2,19,8,STONE:0)
B(-1,19,8,STONE:0)
B(0,19,8,STONE:0)
B(1,19,8,GRASS:0)
B(2,19,8,AIR:0)
B(3,19,8,AIR:0)
B(4,19,8,AIR:0)
B(5,19,8,AIR:0)
B(6,19,8,AIR:0)
B(7,19,8,AIR:0)
B(8,19,8,AIR:0)
B(-7,20,-7,DIRT:0)
B(-6,20,-7,STONE:0)
B(-5,20,-7,STONE:0)
B(-4,20,-7,AIR:0)
B(-3,20,-7,AIR:0)
B(-2,20,-7,AIR:0)
B(-1,20,-7,AIR:0)
B(0,20,-7,AIR:0)
B(1,20,-7,AIR:0)
B(2,20,-7,AIR:0)
B(3,20,-7,AIR:0)
B(4,20,-7,AIR:0)
B(5,20,-7,AIR:0)
B(6,20,-7,AIR:0)
B(7,20,-7,AIR:0)
B(8,20,-7,AIR:0)
B(-7,20,-6,STONE:0)
B(-6,20,-6,DIRT:0)
B(-5,20,-6,DIRT:0)
B(-4,20,-6,STONE:0)
B(-3,20,-6,GRASS:0)
B(-2,20,-6,AIR:0)
B(-1,20,-6,AIR:0)
B(0,20,-6,AIR:0)
B(1,20,-6,AIR:0)
B(2,20,-6,AIR:0)
B(3,20,-6,AIR:0)
B(4,20,-6,AIR:0)
B(5,20,-6,AIR:0)
B(6,20,-6,AIR:0)
B(7,20,-6,AIR:0)
B(8,20,-6,AIR:0)
B(-7,20,-5,STONE:0)
B(-6,20,-5,DIRT:0)
B(-5,20,-5,DIRT:0)
B(-4,20,-5,DIRT:0)
B(-3,20,-5,STONE:0)
B(-2,20,-5,GRASS:0)
B(-1,20,-5,AIR:0)
B(0,20,-5,AIR:0)
B(1,20,-5,AIR:0)
B(2,20,-5,AIR:0)
B(3,20,-5,AIR:0)
B(4,20,-5,AIR:0)
B(5,20,-5,AIR:0)
B(6,20,-5,AIR:0)
B(7,20,-5,AIR:0)
B(8,20,-5,AIR:0)
B(-7,20,-4,STONE:0)
B(-6,20,-4,DIRT:0)
B(-5,20,-4,DIRT:0)
B(-4,20,-4,DIRT:0)
B(-3,20,-4,STONE:0)
B(-2,20,-4,AIR:0)
B(-1,20,-4,AIR:0)
B(0,20,-4,AIR:0)
B(1,20,-4,AIR:0)
B(2,20,-4,AIR:0)
B(3,20,-4,AIR:0)
B(4,20,-4,AIR:0)
B(5,20,-4,AIR:0)
B(6,20,-4,AIR:0)
B(7,20,-4,AIR:0)
B(8,20,-4,AIR:0)
B(-7,20,-3,STONE:0)
B(-6,20,-3,STONE:0)
B(-5,20,-3,DIRT:0)
B(-4,20,-3,DIRT:0)
B(-3,20,-3,GRASS:0)
B(-2,20,-3,STONE:0)
B(-1,20,-3,AIR:0)
B(0,20,-3,AIR:0)
B(1,20,-3,AIR:0)
B(2,20,-3,AIR:0)
B(3,20,-3,AIR:0)
B(4,20,-3,AIR:0)
B(5,20,-3,AIR:0)
B(6,20,-3,AIR:0)
B(7,20,-3,AIR:0)
B(8,20,-3,AIR:0)
B(-7,20,-2,STONE:0)
B(-6,20,-2,STONE:0)
B(-5,20,-2,DIRT:0)
B(-4,20,-2,DIRT:0)
B(-3,20,-2,GRASS:0)
B(-2,20,-2,GRASS:0)
B(-1,20,-2,AIR:0)
B(0,20,-2,AIR:0)
B(1,20,-2,AIR:0)
B(2,20,-2,AIR:0)
B(3,20,-2,AIR:0)
B(4,20,-2,AIR:0)
B(5,20,-2,AIR:0)
B(6,20,-2,AIR:0)
B(7,20,-2,AIR:0)
B(8,20,-2,AIR:0)
B(-7,20,-1,STONE:0)
B(-6,20,-1,STONE:0)
B(-5,20,-1,STONE:0)
B(-4,20,-1,DIRT:0)
B(-3,20,-1,DIRT:0)
B(-2,20,-1,GRASS:0)
B(-1,20,-1,STONE:0)
B(0,20,-1,GRASS:0)
B(1,20,-1,AIR:0)
B(2,20,-1,AIR:0)
B(3,20,-1,AIR:0)
B(4,20,-1,AIR:0)
B(5,20,-1,AIR:0)
B(6,20,-1,AIR:0)
B(7,20,-1,AIR:0)
B(8,20,-1,AIR:0)
B(-7,20,0,STONE:0)
B(-6,20,0,STONE:0)
B(-5,20,0,STONE:0)
B(-4,20,0,STONE:0)
B(-3,20,0,DIRT:0)
B(-2,20,0,GRASS:0)
B(-1,20,0,STONE:0)
B(0,20,0,GRASS:0)
B(1,20,0,AIR:0)
B(2,20,0,AIR:0)
B(3,20,0,AIR:0)
B(4,20,0,AIR:0)
B(5,20,0,AIR:0)
B(6,20,0,AIR:0)
B(7,20,0,AIR:0)
B(8,20,0,AIR:0)
B(-7,20,1,STONE:0)
B(-6,20,1,STONE:0)
B(-5,20,1,STONE:0)
B(-4,20,1,STONE:0)
B(-3,20,1,GRASS:0)
B(-2,20,1,GRASS:0)
B(-1,20,1,GRASS:0)
B(0,20,1,GRASS:0)
B(1,20,1,AIR:0)
B(2,20,1,AIR:0)
B(3,20,1,AIR:0)
B(4,20,1,AIR:0)
B(5,20,1,AIR:0)
B(6,20,1,AIR:0)
B(7,20,1,AIR:0)
B(8,20,1,AIR:0)
B(-7,20,2,STONE:0)
B(-6,20,2,STONE:0)
B(-5,20,2,STONE:0)
B(-4,20,2,STONE:0)
B(-3,20,2,GRASS:0)
B(-2,20,2,AIR:0)
B(-1,20,2,TALLGRASS:1)
B(0,20,2,GRASS:0)
B(1,20,2,AIR:0)
B(2,20,2,AIR:0)
B(3,20,2,AIR:0)
B(4,20,2,AIR:0)
B(5,20,2,AIR:0)
B(6,20,2,AIR:0)
B(7,20,2,AIR:0)
B(8,20,2,AIR:0)
B(-7,20,3,STONE:0)
B(-6,20,3,STONE:0)
B(-5,20,3,STONE:0)
B(-4,20,3,STONE:0)
B(-3,20,3,TALLGRASS:1)
B(-2,20,3,AIR:0)
B(-1,20,3,AIR:0)
B(0,20,3,AIR:0)
B(1,20,3,DOUBLE_PLANT:2)
B(2,20,3,AIR:0)
B(3,20,3,AIR:0)
B(4,20,3,AIR:0)
B(5,20,3,AIR:0)
B(6,20,3,AIR:0)
B(7,20,3,AIR:0)
B(8,20,3,AIR:0)
B(-7,20,4,STONE:0)
B(-6,20,4,STONE:0)
B(-5,20,4,STONE:0)
B(-4,20,4,STONE:0)
B(-3,20,4,AIR:0)
B(-2,20,4,AIR:0)
B(-1,20,4,AIR:0)
B(0,20,4,AIR:0)
B(1,20,4,AIR:0)
B(2,20,4,AIR:0)
B(3,20,4,AIR:0)
B(4,20,4,AIR:0)
B(5,20,4,AIR:0)
B(6,20,4,AIR:0)
B(7,20,4,AIR:0)
B(8,20,4,AIR:0)
B(-7,20,5,STONE:0)
B(-6,20,5,STONE:0)
B(-5,20,5,STONE:0)
B(-4,20,5,STONE:0)
B(-3,20,5,AIR:0)
B(-2,20,5,AIR:0)
B(-1,20,5,AIR:0)
B(0,20,5,AIR:0)
B(1,20,5,AIR:0)
B(2,20,5,AIR:0)
B(3,20,5,AIR:0)
B(4,20,5,AIR:0)
B(5,20,5,AIR:0)
B(6,20,5,AIR:0)
B(7,20,5,AIR:0)
B(8,20,5,AIR:0)
B(-7,20,6,STONE:0)
B(-6,20,6,STONE:0)
B(-5,20,6,STONE:0)
B(-4,20,6,GRASS:0)
B(-3,20,6,AIR:0)
B(-2,20,6,AIR:0)
B(-1,20,6,AIR:0)
B(0,20,6,AIR:0)
B(1,20,6,AIR:0)
B(2,20,6,AIR:0)
B(3,20,6,AIR:0)
B(4,20,6,AIR:0)
B(5,20,6,AIR:0)
B(6,20,6,AIR:0)
B(7,20,6,AIR:0)
B(8,20,6,AIR:0)
B(-7,20,7,STONE:0)
B(-6,20,7,STONE:0)
B(-5,20,7,STONE:0)
B(-4,20,7,STONE:0)
B(-3,20,7,STONE:0)
B(-2,20,7,STONE:0)
B(-1,20,7,AIR:0)
B(0,20,7,AIR:0)
