#######################################################################
# +-----------------------------------------------------------------+ #
# |                            BO3 object                           | #
# +-----------------------------------------------------------------+ #
#######################################################################

Author: Bo3 BulkEdit

Description: Converted Schematic - Modified by Bo3BulkEdit

Version: 3

SettingsMode: WriteDisable

#######################################################################
# +-----------------------------------------------------------------+ #
# |                          Main settings                          | #
# +-----------------------------------------------------------------+ #
#######################################################################

IsOTGPlus: false
Tree: false
Frequency: 1
Rarity: 100
RotateRandomly: true
SpawnHeight: highestSolidBlock
SpawnHeightOffset: -1
SpawnHeightVariance: 0
MaxBranchDepth: 10
ExcludedBiomes: All

##############################
# Height Limits for the BO3. #
##############################

MinHeight: 0
MaxHeight: 255

#######################################################################
# +-----------------------------------------------------------------+ #
# |                      Source block settings                      | #
# +-----------------------------------------------------------------+ #
#######################################################################

SourceBlocks: AIR,STONE,GRASS,DIRT,SAND,GRAVEL
MaxPercentageOutsideSourceBlock: 0
OutsideSourceBlock: placeAnyway

ReplaceBelow: STONE
ReplaceWithBiomeBlocks: true
ReplaceWithGroundBlock: DIRT
ReplaceWithSurfaceBlock: GRASS
ReplaceWithStoneBlock: STONE
SmoothRadius: 0
SmoothHeightOffset: 0

#######################################################################
# +-----------------------------------------------------------------+ #
# |                              Blocks                             | #
# +-----------------------------------------------------------------+ #
#######################################################################

B(-1,-1,-7,GRASS)
B(0,-1,-7,GRASS)
B(1,-1,-7,GRASS)
B(2,-1,-7,GRASS)
B(3,-1,-7,GRASS)
B(4,-1,-7,GRASS)
B(5,-1,-7,GRASS)
B(-1,-1,-6,GRASS)
B(0,-1,-6,DIRT)
B(1,-1,-6,DIRT)
B(2,-1,-6,DIRT)
B(3,-1,-6,DIRT)
B(4,-1,-6,DIRT)
B(5,-1,-6,GRASS)
B(6,-1,-6,GRASS)
B(-2,-1,-5,GRASS)
B(-1,-1,-5,DIRT)
B(0,-1,-5,DIRT)
B(1,-1,-5,DIRT)
B(2,-1,-5,DIRT)
B(3,-1,-5,DIRT)
B(4,-1,-5,DIRT)
B(5,-1,-5,DIRT)
B(6,-1,-5,GRASS)
B(-4,-1,-4,GRASS)
B(-3,-1,-4,GRASS)
B(-2,-1,-4,DIRT)
B(-1,-1,-4,DIRT)
B(0,-1,-4,DIRT)
B(1,-1,-4,DIRT)
B(2,-1,-4,DIRT)
B(3,-1,-4,DIRT)
B(4,-1,-4,DIRT)
B(5,-1,-4,DIRT)
B(6,-1,-4,GRASS)
B(7,-1,-4,GRASS)
B(-4,-1,-3,GRASS)
B(-3,-1,-3,GRASS)
B(-2,-1,-3,DIRT)
B(-1,-1,-3,DIRT)
B(0,-1,-3,DIRT)
B(1,-1,-3,DIRT)
B(2,-1,-3,DIRT)
B(3,-1,-3,DIRT)
B(4,-1,-3,DIRT)
B(5,-1,-3,DIRT)
B(6,-1,-3,DIRT)
B(7,-1,-3,GRASS)
B(-5,-1,-2,GRASS)
B(-4,-1,-2,GRASS)
B(-3,-1,-2,DIRT)
B(-2,-1,-2,DIRT)
B(-1,-1,-2,DIRT)
B(0,-1,-2,DIRT)
B(1,-1,-2,DIRT)
B(2,-1,-2,DIRT)
B(3,-1,-2,GRASS)
B(4,-1,-2,DIRT)
B(5,-1,-2,DIRT)
B(6,-1,-2,DIRT)
B(7,-1,-2,GRASS)
B(-5,-1,-1,GRASS)
B(-4,-1,-1,DIRT)
B(-3,-1,-1,DIRT)
B(-2,-1,-1,DIRT)
B(-1,-1,-1,DIRT)
B(0,-1,-1,DIRT)
B(1,-1,-1,DIRT)
B(2,-1,-1,DIRT)
B(3,-1,-1,DIRT)
B(4,-1,-1,DIRT)
B(5,-1,-1,DIRT)
B(6,-1,-1,DIRT)
B(7,-1,-1,GRASS)
B(-5,-1,0,GRASS)
B(-4,-1,0,DIRT)
B(-3,-1,0,DIRT)
B(-2,-1,0,DIRT)
B(-1,-1,0,DIRT)
B(0,-1,0,DIRT)
B(1,-1,0,DIRT)
B(2,-1,0,DIRT)
B(3,-1,0,DIRT)
B(4,-1,0,DIRT)
B(5,-1,0,DIRT)
B(6,-1,0,DIRT)
B(7,-1,0,GRASS)
B(-5,-1,1,GRASS)
B(-4,-1,1,DIRT)
B(-3,-1,1,DIRT)
B(-2,-1,1,DIRT)
B(-1,-1,1,DIRT)
B(0,-1,1,DIRT)
B(1,-1,1,DIRT)
B(2,-1,1,DIRT)
B(3,-1,1,DIRT)
B(4,-1,1,DIRT)
B(5,-1,1,GRASS)
B(6,-1,1,GRASS)
B(7,-1,1,GRASS)
B(-5,-1,2,GRASS)
B(-4,-1,2,GRASS)
B(-3,-1,2,DIRT)
B(-2,-1,2,DIRT)
B(-1,-1,2,DIRT)
B(0,-1,2,DIRT)
B(1,-1,2,DIRT)
B(2,-1,2,DIRT)
B(3,-1,2,DIRT)
B(4,-1,2,GRASS)
B(5,-1,2,GRASS)
B(6,-1,2,GRASS)
B(-4,-1,3,GRASS)
B(-3,-1,3,DIRT)
B(-2,-1,3,DIRT)
B(-1,-1,3,DIRT)
B(0,-1,3,DIRT)
B(1,-1,3,DIRT)
B(2,-1,3,DIRT)
B(3,-1,3,GRASS)
B(4,-1,3,GRASS)
B(5,-1,3,GRASS)
B(-4,-1,4,GRASS)
B(-3,-1,4,GRASS)
B(-2,-1,4,GRASS)
B(-1,-1,4,DIRT)
B(0,-1,4,DIRT)
B(1,-1,4,DIRT)
B(2,-1,4,GRASS)
B(3,-1,4,GRASS)
B(4,-1,4,GRASS)
B(-3,-1,5,GRASS)
B(-2,-1,5,GRASS)
B(-1,-1,5,GRASS)
B(0,-1,5,GRASS)
B(1,-1,5,GRASS)
B(2,-1,5,GRASS)
B(3,-1,5,GRASS)
B(0,0,-6,GRASS)
B(1,0,-6,GRASS)
B(2,0,-6,GRASS)
B(3,0,-6,GRASS)
B(4,0,-6,GRASS)
B(-1,0,-5,GRASS)
B(0,0,-5,GRASS)
B(1,0,-5,GRASS)
B(2,0,-5,GRASS)
B(3,0,-5,GRASS)
B(4,0,-5,GRASS)
B(5,0,-5,GRASS)
B(-2,0,-4,GRASS)
B(-1,0,-4,GRASS)
B(0,0,-4,GRASS)
B(1,0,-4,FARMLAND:7)
B(2,0,-4,FARMLAND:7)
B(3,0,-4,FARMLAND:7)
B(4,0,-4,GRASS)
B(5,0,-4,GRASS)
B(-2,0,-3,GRASS)
B(-1,0,-3,FARMLAND:7)
B(0,0,-3,FARMLAND:7)
B(1,0,-3,WATER:1)
B(2,0,-3,WATER)
B(3,0,-3,WATER)
B(4,0,-3,FARMLAND:7)
B(5,0,-3,GRASS)
B(6,0,-3,GRASS)
B(-3,0,-2,GRASS)
B(-2,0,-2,GRASS)
B(-1,0,-2,FARMLAND:7)
B(0,0,-2,WATER:3)
B(1,0,-2,WATER:2)
B(2,0,-2,FARMLAND:7)
B(3,0,-2,WATER)
B(4,0,-2,FARMLAND:7)
B(5,0,-2,GRASS)
B(6,0,-2,GRASS)
B(-4,0,-1,GRASS)
B(-3,0,-1,GRASS)
B(-2,0,-1,FARMLAND:7)
B(-1,0,-1,WATER)
B(0,0,-1,FARMLAND:7)
B(1,0,-1,FARMLAND:7)
B(2,0,-1,FARMLAND:7)
B(3,0,-1,WATER)
B(4,0,-1,FARMLAND:7)
B(5,0,-1,GRASS)
B(6,0,-1,GRASS)
B(-4,0,0,GRASS)
B(-3,0,0,GRASS)
B(-2,0,0,FARMLAND:7)
B(-1,0,0,WATER)
B(0,0,0,FARMLAND:7)
B(1,0,0,WATER)
B(2,0,0,WATER)
B(3,0,0,WATER)
B(4,0,0,FARMLAND:7)
B(5,0,0,GRASS)
B(6,0,0,GRASS)
B(-4,0,1,GRASS)
B(-3,0,1,GRASS)
B(-2,0,1,FARMLAND:7)
B(-1,0,1,WATER)
B(0,0,1,WATER)
B(1,0,1,WATER)
B(2,0,1,FARMLAND:7)
B(3,0,1,GRASS)
B(4,0,1,GRASS)
B(-3,0,2,GRASS)
B(-2,0,2,GRASS)
B(-1,0,2,FARMLAND:7)
B(0,0,2,FARMLAND:7)
B(1,0,2,FARMLAND:7)
B(2,0,2,FARMLAND:7)
B(3,0,2,GRASS)
B(-3,0,3,GRASS)
B(-2,0,3,GRASS)
B(-1,0,3,GRASS)
B(0,0,3,GRASS)
B(1,0,3,GRASS)
B(2,0,3,GRASS)
B(-1,0,4,GRASS)
B(0,0,4,GRASS)
B(1,0,4,GRASS)
B(0,1,-5,SPRUCE_FENCE)
B(1,1,-5,SPRUCE_FENCE)
B(2,1,-5,SPRUCE_FENCE)
B(3,1,-5,SPRUCE_FENCE)
B(4,1,-5,SPRUCE_FENCE)
B(-1,1,-4,SPRUCE_FENCE)
B(0,1,-4,SPRUCE_FENCE)
B(1,1,-4,WHEAT:1)
B(2,1,-4,WHEAT:1)
B(3,1,-4,WHEAT:1)
B(4,1,-4,SPRUCE_FENCE)
B(-2,1,-3,SPRUCE_FENCE)
B(-1,1,-3,WHEAT:2)
B(0,1,-3,WHEAT:3)
B(4,1,-3,WHEAT:3)
B(5,1,-3,SPRUCE_FENCE)
B(-2,1,-2,SPRUCE_FENCE)
B(-1,1,-2,WHEAT:4)
B(2,1,-2,WHEAT:2)
B(4,1,-2,WHEAT:4)
B(5,1,-2,SPRUCE_FENCE)
B(-3,1,-1,SPRUCE_FENCE)
B(-2,1,-1,WHEAT:3)
B(0,1,-1,WHEAT:2)
B(1,1,-1,WHEAT:1)
B(2,1,-1,WHEAT:1)
B(4,1,-1,WHEAT:3)
B(5,1,-1,SPRUCE_FENCE)
B(-3,1,0,SPRUCE_FENCE)
B(-2,1,0,WHEAT:5)
B(0,1,0,WHEAT)
B(4,1,0,WHEAT:4)
B(5,1,0,SPRUCE_FENCE)
B(-3,1,1,SPRUCE_FENCE)
B(-2,1,1,WHEAT:1)
B(2,1,1,WHEAT)
B(3,1,1,SPRUCE_FENCE)
B(4,1,1,SPRUCE_FENCE)
B(-3,1,2,SPRUCE_FENCE)
B(-2,1,2,SPRUCE_FENCE)
B(-1,1,2,WHEAT)
B(0,1,2,WHEAT:4)
B(1,1,2,WHEAT:1)
B(2,1,2,WHEAT:2)
B(3,1,2,SPRUCE_FENCE)
B(-2,1,3,SPRUCE_FENCE)
B(-1,1,3,SPRUCE_FENCE)
B(0,1,3,SPRUCE_FENCE)
B(1,1,3,SPRUCE_FENCE)
B(2,1,3,SPRUCE_FENCE)

