#######################################################################
# +-----------------------------------------------------------------+ #
# |                            BO3 object                           | #
# +-----------------------------------------------------------------+ #
#######################################################################

Author: Bo3 BulkEdit

Description: Converted Schematic - Modified by Bo3BulkEdit

Version: 3

SettingsMode: WriteDisable

#######################################################################
# +-----------------------------------------------------------------+ #
# |                          Main settings                          | #
# +-----------------------------------------------------------------+ #
#######################################################################



Frequency: 0


SpawnHeight: randomY





##############################
# Height Limits for the BO3. #
##############################

MinHeight: 0
MaxHeight: 256

#######################################################################
# +-----------------------------------------------------------------+ #
# |                      Source block settings                      | #
# +-----------------------------------------------------------------+ #
#######################################################################

CanOverride: true
MaxPercentageOutsideSourceBlock: 100
OutsideSourceBlock: placeAnyway

#######################################################################
# +-----------------------------------------------------------------+ #
# |                               OTG+                              | #
# +-----------------------------------------------------------------+ #
#######################################################################

#######################################################################
# +-----------------------------------------------------------------+ #
# |                              Blocks                             | #
# +-----------------------------------------------------------------+ #
#######################################################################

B(0,750,0,AIR)
B(15,750,15,AIR)
B(9,-4,7,STAINED_GLASS:15)
B(10,-4,7,STAINED_GLASS:15)
B(9,-4,8,STAINED_GLASS:15)
B(10,-4,8,STAINED_GLASS:15)
B(7,-3,5,STAINED_GLASS:15)
B(8,-3,5,STAINED_GLASS:15)
B(9,-3,5,STAINED_GLASS:15)
B(10,-3,5,STAINED_GLASS:15)
B(7,-3,6,STAINED_GLASS:15)
B(8,-3,6,STAINED_GLASS:15)
B(9,-3,6,STAINED_GLASS:15)
B(10,-3,6,STAINED_GLASS:15)
B(8,-3,7,STAINED_GLASS:15)
B(9,-3,7,STAINED_GLASS:15)
B(10,-3,7,STAINED_GLASS:15)
B(8,-3,8,STAINED_GLASS:15)
B(9,-3,8,STAINED_GLASS:15)
B(10,-3,8,STAINED_GLASS:15)
B(7,-2,0,STAINED_GLASS:9)
B(7,-2,1,STAINED_GLASS:9)
B(7,-2,2,STAINED_GLASS:15)
B(8,-2,2,STAINED_GLASS:15)
B(9,-2,2,STAINED_GLASS:15)
B(10,-2,2,STAINED_GLASS:15)
B(6,-2,3,STAINED_GLASS:15)
B(7,-2,3,STAINED_GLASS:15)
B(8,-2,3,STAINED_GLASS:15)
B(9,-2,3,STAINED_GLASS:15)
B(10,-2,3,STAINED_GLASS:15)
B(6,-2,4,STAINED_GLASS:15)
B(7,-2,4,STAINED_GLASS:15)
B(8,-2,4,STAINED_GLASS:15)
B(9,-2,4,STAINED_GLASS:15)
B(10,-2,4,STAINED_GLASS:15)
B(11,-2,4,STAINED_GLASS:15)
B(6,-2,5,STAINED_GLASS:15)
B(7,-2,5,STAINED_GLASS:15)
B(8,-2,5,STAINED_GLASS:15)
B(9,-2,5,STAINED_GLASS:15)
B(10,-2,5,STAINED_GLASS:15)
B(11,-2,5,STAINED_GLASS:15)
B(6,-2,6,STAINED_GLASS:15)
B(7,-2,6,STAINED_GLASS:15)
B(8,-2,6,STAINED_GLASS:15)
B(9,-2,6,STAINED_GLASS:15)
B(10,-2,6,STAINED_GLASS:15)
B(11,-2,6,STAINED_GLASS:15)
B(6,-2,7,STAINED_GLASS:15)
B(7,-2,7,STAINED_GLASS:15)
B(8,-2,7,STAINED_GLASS:15)
B(9,-2,7,STAINED_GLASS:15)
B(10,-2,7,STAINED_GLASS:15)
B(11,-2,7,STAINED_GLASS:15)
B(6,-1,0,STAINED_GLASS:15)
B(7,-1,0,STAINED_GLASS:6)
B(8,-1,0,STAINED_GLASS:15)
B(9,-1,0,STAINED_GLASS:15)
B(4,-1,1,STAINED_GLASS:15)
B(5,-1,1,STAINED_GLASS:15)
B(6,-1,1,STAINED_GLASS:15)
B(7,-1,1,STAINED_GLASS:15)
B(8,-1,1,STAINED_GLASS:15)
B(9,-1,1,STAINED_GLASS:15)
B(4,-1,2,STAINED_GLASS:15)
B(5,-1,2,STAINED_GLASS:15)
B(6,-1,2,STAINED_GLASS:15)
B(7,-1,2,STAINED_GLASS:15)
B(8,-1,2,STAINED_GLASS:15)
B(9,-1,2,STAINED_GLASS:15)
B(10,-1,2,STAINED_GLASS:15)
B(4,-1,3,STAINED_GLASS:15)
B(5,-1,3,STAINED_GLASS:15)
B(6,-1,3,STAINED_GLASS:15)
B(7,-1,3,STAINED_GLASS:15)
B(8,-1,3,STAINED_GLASS:15)
B(9,-1,3,STAINED_GLASS:15)
B(10,-1,3,STAINED_GLASS:15)
B(11,-1,3,STAINED_GLASS:15)
B(4,-1,4,STAINED_GLASS:15)
B(5,-1,4,STAINED_GLASS:15)
B(6,-1,4,STAINED_GLASS:15)
B(7,-1,4,STAINED_GLASS:15)
B(8,-1,4,STAINED_GLASS:15)
B(9,-1,4,STAINED_GLASS:10)
B(10,-1,4,STAINED_GLASS:15)
B(11,-1,4,STAINED_GLASS:15)
B(5,-1,5,STAINED_GLASS:15)
B(6,-1,5,STAINED_GLASS:15)
B(7,-1,5,STAINED_GLASS:15)
B(8,-1,5,STAINED_GLASS:10)
B(9,-1,5,STAINED_GLASS:10)
B(10,-1,5,STAINED_GLASS:15)
B(11,-1,5,STAINED_GLASS:15)
B(5,-1,6,STAINED_GLASS:15)
B(6,-1,6,STAINED_GLASS:15)
B(7,-1,6,STAINED_GLASS:15)
B(8,-1,6,STAINED_GLASS:15)
B(9,-1,6,STAINED_GLASS:15)
B(10,-1,6,STAINED_GLASS:15)
B(11,-1,6,STAINED_GLASS:15)
B(5,-1,7,STAINED_GLASS:15)
B(6,-1,7,STAINED_GLASS:15)
B(7,-1,7,STAINED_GLASS:15)
B(8,-1,7,STAINED_GLASS:15)
B(9,-1,7,STAINED_GLASS:15)
B(3,0,0,STAINED_GLASS:15)
B(4,0,0,STAINED_GLASS:15)
B(5,0,0,STAINED_GLASS:15)
B(6,0,0,STAINED_GLASS:15)
B(7,0,0,STAINED_GLASS:15)
B(8,0,0,STAINED_GLASS:15)
B(9,0,0,STAINED_GLASS:15)
B(3,0,1,STAINED_GLASS:15)
B(4,0,1,STAINED_GLASS:15)
B(5,0,1,STAINED_GLASS:15)
B(6,0,1,STAINED_GLASS:15)
B(7,0,1,STAINED_GLASS:15)
B(8,0,1,STAINED_GLASS:15)
B(9,0,1,STAINED_GLASS:15)
B(10,0,1,STAINED_GLASS:15)
B(3,0,2,STAINED_GLASS:15)
B(4,0,2,STAINED_GLASS:15)
B(5,0,2,STAINED_GLASS:15)
B(6,0,2,STAINED_GLASS:15)
B(7,0,2,STAINED_GLASS:15)
B(8,0,2,SEA_LANTERN)
B(9,0,2,STAINED_GLASS:15)
B(10,0,2,STAINED_GLASS:15)
B(11,0,2,STAINED_GLASS:15)
B(3,0,3,STAINED_GLASS:15)
B(4,0,3,STAINED_GLASS:15)
B(5,0,3,STAINED_GLASS:15)
B(6,0,3,STAINED_GLASS:15)
B(7,0,3,STAINED_GLASS:15)
B(9,0,3,STAINED_GLASS:10)
B(10,0,3,STAINED_GLASS:15)
B(11,0,3,STAINED_GLASS:15)
B(4,0,4,STAINED_GLASS:15)
B(5,0,4,STAINED_GLASS:15)
B(6,0,4,STAINED_GLASS:10)
B(7,0,4,STAINED_GLASS:10)
B(8,0,4,STAINED_GLASS:10)
B(9,0,4,STAINED_GLASS:10)
B(10,0,4,STAINED_GLASS:6)
B(11,0,4,STAINED_GLASS:15)
B(4,0,5,STAINED_GLASS:15)
B(5,0,5,STAINED_GLASS:15)
B(6,0,5,STAINED_GLASS:15)
B(7,0,5,STAINED_GLASS:10)
B(8,0,5,STAINED_GLASS:10)
B(9,0,5,STAINED_GLASS:6)
B(10,0,5,STAINED_GLASS:15)
B(11,0,5,STAINED_GLASS:15)
B(4,0,6,STAINED_GLASS:15)
B(5,0,6,STAINED_GLASS:15)
B(6,0,6,STAINED_GLASS:15)
B(7,0,6,STAINED_GLASS:15)
B(8,0,6,STAINED_GLASS:6)
B(9,0,6,STAINED_GLASS:15)
B(8,0,7,STAINED_GLASS:15)
B(2,1,0,STAINED_GLASS:15)
B(3,1,0,STAINED_GLASS:15)
B(4,1,0,STAINED_GLASS:15)
B(5,1,0,STAINED_GLASS:15)
B(6,1,0,STAINED_GLASS:15)
B(7,1,0,STAINED_GLASS:6)
B(8,1,0,STAINED_GLASS:6)
B(9,1,0,STAINED_GLASS:15)
B(10,1,0,STAINED_GLASS:15)
B(11,1,0,STAINED_GLASS:15)
B(3,1,1,STAINED_GLASS:15)
B(4,1,1,STAINED_GLASS:15)
B(5,1,1,STAINED_GLASS:15)
B(6,1,1,STAINED_GLASS:15)
B(7,1,1,STAINED_GLASS:6)
B(8,1,1,SEA_LANTERN)
B(9,1,1,STAINED_GLASS:6)
B(10,1,1,STAINED_GLASS:15)
B(11,1,1,STAINED_GLASS:15)
B(3,1,2,STAINED_GLASS:15)
B(4,1,2,STAINED_GLASS:15)
B(5,1,2,STAINED_GLASS:15)
B(6,1,2,STAINED_GLASS:6)
B(7,1,2,SEA_LANTERN)
B(8,1,2,SEA_LANTERN)
B(9,1,2,STAINED_GLASS:6)
B(10,1,2,STAINED_GLASS:15)
B(11,1,2,STAINED_GLASS:15)
B(12,1,2,STAINED_GLASS:9)
B(3,1,3,STAINED_GLASS:15)
B(4,1,3,STAINED_GLASS:15)
B(5,1,3,STAINED_GLASS:6)
B(6,1,3,STAINED_GLASS:6)
B(7,1,3,SEA_LANTERN)
B(8,1,3,STAINED_GLASS:6)
B(9,1,3,STAINED_GLASS:6)
B(10,1,3,STAINED_GLASS:6)
B(11,1,3,STAINED_GLASS:15)
B(4,1,4,STAINED_GLASS:15)
B(5,1,4,STAINED_GLASS:15)
B(6,1,4,STAINED_GLASS:6)
B(7,1,4,STAINED_GLASS:6)
B(8,1,4,STAINED_GLASS:15)
B(9,1,4,STAINED_GLASS:15)
B(10,1,4,STAINED_GLASS:15)
B(11,1,4,STAINED_GLASS:15)
B(12,1,4,STAINED_GLASS:9)
B(4,1,5,STAINED_GLASS:15)
B(5,1,5,STAINED_GLASS:6)
B(6,1,5,STAINED_GLASS:9)
B(7,1,5,STAINED_GLASS:9)
B(8,1,5,STAINED_GLASS:15)
B(9,1,5,STAINED_GLASS:15)
B(10,1,5,STAINED_GLASS:15)
B(5,1,6,STAINED_GLASS:15)
B(6,1,6,STAINED_GLASS:15)
B(7,1,6,STAINED_GLASS:15)
B(8,1,6,STAINED_GLASS:15)
B(2,2,0,STAINED_GLASS:15)
B(3,2,0,STAINED_GLASS:15)
B(4,2,0,STAINED_GLASS:15)
B(5,2,0,STAINED_GLASS:15)
B(6,2,0,STAINED_GLASS:6)
B(7,2,0,SEA_LANTERN)
B(8,2,0,STAINED_GLASS:6)
B(9,2,0,STAINED_GLASS:6)
B(10,2,0,STAINED_GLASS:9)
B(11,2,0,STAINED_GLASS:9)
B(2,2,1,STAINED_GLASS:15)
B(3,2,1,STAINED_GLASS:15)
B(4,2,1,STAINED_GLASS:15)
B(5,2,1,STAINED_GLASS:6)
B(6,2,1,SEA_LANTERN)
B(7,2,1,SEA_LANTERN)
B(8,2,1,SEA_LANTERN)
B(9,2,1,STAINED_GLASS:6)
B(10,2,1,STAINED_GLASS:9)
B(11,2,1,STAINED_GLASS:9)
B(3,2,2,STAINED_GLASS:9)
B(4,2,2,STAINED_GLASS:9)
B(5,2,2,STAINED_GLASS:6)
B(6,2,2,STAINED_GLASS:6)
B(7,2,2,SEA_LANTERN)
B(8,2,2,STAINED_GLASS:6)
B(9,2,2,STAINED_GLASS:6)
B(10,2,2,STAINED_GLASS:15)
B(11,2,2,STAINED_GLASS:15)
B(12,2,2,STAINED_GLASS:9)
B(3,2,3,STAINED_GLASS:15)
B(4,2,3,STAINED_GLASS:9)
B(5,2,3,STAINED_GLASS:6)
B(6,2,3,STAINED_GLASS:6)
B(7,2,3,STAINED_GLASS:6)
B(8,2,3,STAINED_GLASS:6)
B(9,2,3,STAINED_GLASS:6)
B(10,2,3,STAINED_GLASS:15)
B(11,2,3,STAINED_GLASS:9)
B(4,2,4,STAINED_GLASS:15)
B(5,2,4,STAINED_GLASS:15)
B(6,2,4,STAINED_GLASS:9)
B(7,2,4,STAINED_GLASS:9)
B(8,2,4,STAINED_GLASS:9)
B(9,2,4,STAINED_GLASS:15)
B(11,2,4,STAINED_GLASS:9)
B(4,2,5,STAINED_GLASS:15)
B(5,2,5,STAINED_GLASS:15)
B(6,2,5,STAINED_GLASS:9)
B(7,2,5,STAINED_GLASS:9)
B(8,2,5,STAINED_GLASS:9)
B(9,2,5,STAINED_GLASS:15)
B(2,3,0,STAINED_GLASS:15)
B(3,3,0,STAINED_GLASS:15)
B(4,3,0,STAINED_GLASS:15)
B(5,3,0,STAINED_GLASS:6)
B(6,3,0,SEA_LANTERN)
B(7,3,0,SEA_LANTERN)
B(8,3,0,STAINED_GLASS:6)
B(9,3,0,STAINED_GLASS:6)
B(10,3,0,STAINED_GLASS:9)
B(11,3,0,STAINED_GLASS:9)
B(3,3,1,STAINED_GLASS:15)
B(4,3,1,STAINED_GLASS:9)
B(5,3,1,STAINED_GLASS:6)
B(6,3,1,SEA_LANTERN)
B(7,3,1,SEA_LANTERN)
B(8,3,1,SEA_LANTERN)
B(9,3,1,STAINED_GLASS:6)
B(10,3,1,STAINED_GLASS:9)
B(11,3,1,STAINED_GLASS:15)
B(3,3,2,STAINED_GLASS:15)
B(4,3,2,STAINED_GLASS:15)
B(5,3,2,STAINED_GLASS:6)
B(6,3,2,STAINED_GLASS:6)
B(7,3,2,STAINED_GLASS:6)
B(8,3,2,STAINED_GLASS:6)
B(9,3,2,STAINED_GLASS:6)
B(10,3,2,STAINED_GLASS:15)
B(11,3,2,STAINED_GLASS:15)
B(3,3,3,STAINED_GLASS:15)
B(4,3,3,STAINED_GLASS:15)
B(5,3,3,STAINED_GLASS:6)
B(6,3,3,STAINED_GLASS:9)
B(7,3,3,STAINED_GLASS:6)
B(8,3,3,STAINED_GLASS:9)
B(9,3,3,STAINED_GLASS:9)
B(10,3,3,STAINED_GLASS:15)
B(11,3,3,STAINED_GLASS:9)
B(5,3,4,STAINED_GLASS:9)
B(6,3,4,STAINED_GLASS:9)
B(7,3,4,STAINED_GLASS:9)
B(8,3,4,STAINED_GLASS:9)
B(9,3,4,STAINED_GLASS:15)
B(4,3,5,STAINED_GLASS:15)
B(6,3,5,STAINED_GLASS:9)
B(7,3,5,STAINED_GLASS:9)
B(8,3,5,STAINED_GLASS:9)
B(2,4,0,STAINED_GLASS:15)
B(3,4,0,STAINED_GLASS:15)
B(4,4,0,STAINED_GLASS:9)
B(5,4,0,STAINED_GLASS:6)
B(6,4,0,SEA_LANTERN)
B(7,4,0,SEA_LANTERN)
B(8,4,0,STAINED_GLASS:6)
B(9,4,0,STAINED_GLASS:6)
B(10,4,0,STAINED_GLASS:9)
B(11,4,0,STAINED_GLASS:9)
B(3,4,1,STAINED_GLASS:15)
B(4,4,1,STAINED_GLASS:15)
B(5,4,1,STAINED_GLASS:6)
B(6,4,1,STAINED_GLASS:6)
B(7,4,1,SEA_LANTERN)
B(8,4,1,STAINED_GLASS:6)
B(9,4,1,STAINED_GLASS:6)
B(10,4,1,STAINED_GLASS:9)
B(11,4,1,STAINED_GLASS:15)
B(3,4,2,STAINED_GLASS:15)
B(4,4,2,STAINED_GLASS:15)
B(5,4,2,STAINED_GLASS:6)
B(6,4,2,STAINED_GLASS:6)
B(7,4,2,STAINED_GLASS:6)
B(8,4,2,STAINED_GLASS:9)
B(9,4,2,STAINED_GLASS:9)
B(10,4,2,STAINED_GLASS:15)
B(11,4,2,STAINED_GLASS:15)
B(3,4,3,STAINED_GLASS:15)
B(4,4,3,STAINED_GLASS:15)
B(5,4,3,STAINED_GLASS:9)
B(6,4,3,STAINED_GLASS:9)
B(7,4,3,STAINED_GLASS:9)
B(8,4,3,STAINED_GLASS:9)
B(9,4,3,STAINED_GLASS:15)
B(5,4,4,STAINED_GLASS:9)
B(7,4,4,STAINED_GLASS:9)
B(2,5,0,STAINED_GLASS:15)
B(3,5,0,STAINED_GLASS:15)
B(4,5,0,STAINED_GLASS:9)
B(5,5,0,STAINED_GLASS:6)
B(6,5,0,SEA_LANTERN)
B(7,5,0,STAINED_GLASS:6)
B(8,5,0,STAINED_GLASS:6)
B(9,5,0,STAINED_GLASS:6)
B(10,5,0,STAINED_GLASS:15)
B(11,5,0,STAINED_GLASS:15)
B(3,5,1,STAINED_GLASS:15)
B(4,5,1,STAINED_GLASS:9)
B(5,5,1,STAINED_GLASS:6)
B(6,5,1,STAINED_GLASS:6)
B(7,5,1,STAINED_GLASS:6)
B(8,5,1,STAINED_GLASS:6)
B(9,5,1,STAINED_GLASS:6)
B(10,5,1,STAINED_GLASS:9)
B(3,5,2,STAINED_GLASS:15)
B(4,5,2,STAINED_GLASS:15)
B(5,5,2,STAINED_GLASS:6)
B(6,5,2,STAINED_GLASS:9)
B(7,5,2,STAINED_GLASS:9)
B(8,5,2,STAINED_GLASS:9)
B(9,5,2,STAINED_GLASS:15)
B(11,5,2,STAINED_GLASS:15)
B(4,5,3,STAINED_GLASS:15)
B(5,5,3,STAINED_GLASS:9)
B(6,5,3,STAINED_GLASS:9)
B(7,5,3,STAINED_GLASS:9)
B(8,5,3,STAINED_GLASS:9)
B(9,5,3,STAINED_GLASS:15)
B(2,6,0,STAINED_GLASS:15)
B(3,6,0,STAINED_GLASS:15)
B(4,6,0,STAINED_GLASS:15)
B(5,6,0,STAINED_GLASS:6)
B(6,6,0,STAINED_GLASS:6)
B(7,6,0,STAINED_GLASS:6)
B(8,6,0,STAINED_GLASS:6)
B(9,6,0,STAINED_GLASS:9)
B(10,6,0,STAINED_GLASS:15)
B(11,6,0,STAINED_GLASS:15)
B(3,6,1,STAINED_GLASS:15)
B(4,6,1,STAINED_GLASS:15)
B(5,6,1,STAINED_GLASS:6)
B(6,6,1,STAINED_GLASS:9)
B(7,6,1,STAINED_GLASS:6)
B(8,6,1,STAINED_GLASS:9)
B(9,6,1,STAINED_GLASS:9)
B(10,6,1,STAINED_GLASS:15)
B(3,6,2,STAINED_GLASS:15)
B(4,6,2,STAINED_GLASS:15)
B(5,6,2,STAINED_GLASS:9)
B(6,6,2,STAINED_GLASS:9)
B(7,6,2,STAINED_GLASS:9)
B(8,6,2,STAINED_GLASS:15)
B(7,6,3,STAINED_GLASS:9)
B(2,7,0,STAINED_GLASS:15)
B(3,7,0,STAINED_GLASS:15)
B(4,7,0,STAINED_GLASS:15)
B(5,7,0,STAINED_GLASS:6)
B(6,7,0,STAINED_GLASS:6)
B(7,7,0,STAINED_GLASS:9)
B(8,7,0,STAINED_GLASS:9)
B(9,7,0,STAINED_GLASS:15)
B(10,7,0,STAINED_GLASS:15)
B(11,7,0,STAINED_GLASS:15)
B(3,7,1,STAINED_GLASS:15)
B(4,7,1,STAINED_GLASS:15)
B(5,7,1,STAINED_GLASS:9)
B(6,7,1,STAINED_GLASS:9)
B(7,7,1,STAINED_GLASS:9)
B(8,7,1,STAINED_GLASS:9)
B(9,7,1,STAINED_GLASS:15)
B(4,7,2,STAINED_GLASS:15)
B(5,7,2,STAINED_GLASS:9)
B(6,7,2,STAINED_GLASS:9)
B(7,7,2,STAINED_GLASS:9)
B(2,8,0,STAINED_GLASS:15)
B(3,8,0,STAINED_GLASS:15)
B(4,8,0,STAINED_GLASS:9)
B(5,8,0,STAINED_GLASS:9)
B(6,8,0,STAINED_GLASS:9)
B(7,8,0,STAINED_GLASS:9)
B(8,8,0,STAINED_GLASS:15)
B(3,8,1,STAINED_GLASS:15)
B(4,8,1,STAINED_GLASS:15)
B(5,8,1,STAINED_GLASS:9)
B(6,8,1,STAINED_GLASS:9)
B(7,8,1,STAINED_GLASS:9)
B(8,8,1,STAINED_GLASS:9)
B(4,9,0,STAINED_GLASS:15)
B(5,9,0,STAINED_GLASS:9)
B(6,9,0,STAINED_GLASS:9)
B(7,9,0,STAINED_GLASS:9)
B(8,9,0,STAINED_GLASS:15)
B(3,9,1,STAINED_GLASS:15)
B(5,9,1,STAINED_GLASS:9)
B(7,9,1,STAINED_GLASS:9)
B(4,10,0,STAINED_GLASS:15)
B(6,10,0,STAINED_GLASS:9)

#######################################################################
# +-----------------------------------------------------------------+ #
# |                             Branches                            | #
# +-----------------------------------------------------------------+ #
#######################################################################

BR(0,0,-16,true,SPIKE-SET-FAT-MED-08_0x0,NORTH,100,0)
