
#######################################################################
# +-----------------------------------------------------------------+ #
# |                            BO3 object                           | #
# +-----------------------------------------------------------------+ #
#######################################################################

Author: NLBlackEagle

Description: No description given

Version: 3

SettingsMode: WriteDisable


#######################################################################
# +-----------------------------------------------------------------+ #
# |                          Main settings                          | #
# +-----------------------------------------------------------------+ #
#######################################################################

Tree: false

Frequency: 1

Rarity: 30.0

RotateRandomly: true

SpawnHeight: randomY

SpawnHeightOffset: 0

SpawnHeightVariance: 0

##############################
# Height Limits for the BO3. #
##############################

MinHeight: 15

MaxHeight: 20

######################
# Extrusion settings #
######################

ExtrudeMode: None

ExtrudeThroughBlocks: AIR

MaxBranchDepth: 10

ExcludedBiomes: All


#######################################################################
# +-----------------------------------------------------------------+ #
# |                      Source block settings                      | #
# +-----------------------------------------------------------------+ #
#######################################################################

SourceBlocks: AIR

MaxPercentageOutsideSourceBlock: 100

OutsideSourceBlock: placeAnyway

IsOTGPlus: false

InheritBO3: 

InheritBO3Rotation: NORTH

OverrideChildSettings: true

OverrideParentHeight: false

CanOverride: false

BranchFrequency: 0

BranchFrequencyGroup: 

MustBeBelowOther: false

MustBeInside: 

CannotBeInside: 

ReplacesBO3: 

CanSpawnOnWater: true

SpawnOnWaterOnly: false

SpawnUnderWater: false

SpawnAtWaterLevel: false

HeightOffset: 0

RemoveAir: true

ReplaceAbove: 

ReplaceBelow: 

ReplaceWithBiomeBlocks: true

ReplaceWithGroundBlock: DIRT

ReplaceWithSurfaceBlock: GRASS

SmoothRadius: 0

SmoothHeightOffset: 0

SmoothStartTop: false

SmoothStartWood: false

SmoothingSurfaceBlock: 

SmoothingGroundBlock: 

BO3Group: 

IsSpawnPoint: false


#######################################################################
# +-----------------------------------------------------------------+ #
# |                              Blocks                             | #
# +-----------------------------------------------------------------+ #
#######################################################################

Block(-7,11,0,STONE)
Block(-6,11,-2,STONE)
Block(-6,11,-1,STONE)
Block(-6,11,0,STONE)
Block(-6,11,1,STONE)
Block(-5,10,0,STONE)
Block(-5,10,1,STONE)
Block(-5,11,-3,STONE)
Block(-5,11,-2,STONE)
Block(-5,11,-1,STONE)
Block(-5,11,0,STONE)
Block(-5,11,1,STONE)
Block(-5,11,2,STONE)
Block(-5,11,3,STONE)
Block(-5,11,4,STONE)
Block(-5,11,5,STONE)
Block(-4,8,3,STONE)
Block(-4,9,0,STONE)
Block(-4,9,1,STONE)
Block(-4,9,3,STONE)
Block(-4,10,-2,STONE)
Block(-4,10,-1,STONE)
Block(-4,10,0,STONE)
Block(-4,10,1,STONE)
Block(-4,10,2,STONE)
Block(-4,10,3,STONE)
Block(-4,10,4,STONE)
Block(-4,11,-3,STONE)
Block(-4,11,-2,STONE)
Block(-4,11,-1,STONE)
Block(-4,11,0,STONE)
Block(-4,11,1,STONE)
Block(-4,11,2,STONE)
Block(-4,11,3,STONE)
Block(-4,11,4,STONE)
Block(-4,11,5,STONE)
Block(-4,11,6,STONE)
Block(-3,7,0,STONE)
Block(-3,8,0,STONE)
Block(-3,8,1,STONE)
Block(-3,9,0,STONE)
Block(-3,9,1,STONE)
Block(-3,9,2,STONE)
Block(-3,9,3,STONE)
Block(-3,10,-2,STONE)
Block(-3,10,-1,STONE)
Block(-3,10,0,STONE)
Block(-3,10,1,STONE)
Block(-3,10,2,STONE)
Block(-3,10,3,STONE)
Block(-3,10,4,STONE)
Block(-3,11,-4,STONE)
Block(-3,11,-3,STONE)
Block(-3,11,-2,STONE)
Block(-3,11,-1,STONE)
Block(-3,11,0,STONE)
Block(-3,11,1,STONE)
Block(-3,11,2,STONE)
Block(-3,11,3,STONE)
Block(-3,11,4,STONE)
Block(-3,11,5,STONE)
Block(-3,11,6,STONE)
Block(-2,8,-2,STONE)
Block(-2,9,-2,STONE)
Block(-2,9,0,STONE)
Block(-2,9,3,STONE)
Block(-2,10,-3,STONE)
Block(-2,10,-2,STONE)
Block(-2,10,-1,STONE)
Block(-2,10,0,STONE)
Block(-2,10,1,STONE)
Block(-2,10,2,STONE)
Block(-2,10,3,STONE)
Block(-2,10,4,STONE)
Block(-2,10,5,STONE)
Block(-2,11,-4,STONE)
Block(-2,11,-3,STONE)
Block(-2,11,-2,STONE)
Block(-2,11,-1,STONE)
Block(-2,11,0,STONE)
Block(-2,11,1,STONE)
Block(-2,11,2,STONE)
Block(-2,11,3,STONE)
Block(-2,11,4,STONE)
Block(-2,11,5,STONE)
Block(-2,11,6,STONE)
Block(-1,4,1,STONE)
Block(-1,5,1,STONE)
Block(-1,6,1,STONE)
Block(-1,7,1,STONE)
Block(-1,7,2,STONE)
Block(-1,8,1,STONE)
Block(-1,8,2,STONE)
Block(-1,8,4,STONE)
Block(-1,9,-2,STONE)
Block(-1,9,0,STONE)
Block(-1,9,1,STONE)
Block(-1,9,2,STONE)
Block(-1,9,3,STONE)
Block(-1,9,4,STONE)
Block(-1,9,5,STONE)
Block(-1,10,-3,STONE)
Block(-1,10,-2,STONE)
Block(-1,10,-1,STONE)
Block(-1,10,0,STONE)
Block(-1,10,1,STONE)
Block(-1,10,2,STONE)
Block(-1,10,3,STONE)
Block(-1,10,4,STONE)
Block(-1,10,5,STONE)
Block(-1,11,-4,STONE)
Block(-1,11,-3,STONE)
Block(-1,11,-2,STONE)
Block(-1,11,-1,STONE)
Block(-1,11,0,STONE)
Block(-1,11,1,STONE)
Block(-1,11,2,STONE)
Block(-1,11,3,STONE)
Block(-1,11,4,STONE)
Block(-1,11,5,STONE)
Block(-1,11,6,STONE)
B(0,8,1,STONE)
B(0,9,-2,STONE)
B(0,9,-1,STONE)
B(0,9,1,STONE)
B(0,9,2,STONE)
B(0,9,4,STONE)
B(0,10,-3,STONE)
B(0,10,-2,STONE)
B(0,10,-1,STONE)
B(0,10,0,STONE)
B(0,10,1,STONE)
B(0,10,2,STONE)
B(0,10,3,STONE)
B(0,10,4,STONE)
B(0,10,5,STONE)
B(0,11,-4,STONE)
B(0,11,-3,STONE)
B(0,11,-2,STONE)
B(0,11,-1,STONE)
B(0,11,0,STONE)
B(0,11,1,STONE)
B(0,11,2,STONE)
B(0,11,3,STONE)
B(0,11,4,STONE)
B(0,11,5,STONE)
B(0,11,6,STONE)
B(1,8,0,STONE)
B(1,9,-1,STONE)
B(1,9,0,STONE)
B(1,9,2,STONE)
B(1,9,3,STONE)
B(1,10,-4,STONE)
B(1,10,-3,STONE)
B(1,10,-2,STONE)
B(1,10,-1,STONE)
B(1,10,0,STONE)
B(1,10,1,STONE)
B(1,10,2,STONE)
B(1,10,3,STONE)
B(1,10,4,STONE)
B(1,11,-5,STONE)
B(1,11,-4,STONE)
B(1,11,-3,STONE)
B(1,11,-2,STONE)
B(1,11,-1,STONE)
B(1,11,0,STONE)
B(1,11,1,STONE)
B(1,11,2,STONE)
B(1,11,3,STONE)
B(1,11,4,STONE)
B(1,11,5,STONE)
B(1,11,6,STONE)
B(2,8,3,STONE)
B(2,9,-2,STONE)
B(2,9,0,STONE)
B(2,9,2,STONE)
B(2,9,3,STONE)
B(2,9,4,STONE)
B(2,10,-3,STONE)
B(2,10,-2,STONE)
B(2,10,-1,STONE)
B(2,10,0,STONE)
B(2,10,1,STONE)
B(2,10,2,STONE)
B(2,10,3,STONE)
B(2,10,4,STONE)
B(2,11,-5,STONE)
B(2,11,-4,STONE)
B(2,11,-3,STONE)
B(2,11,-2,STONE)
B(2,11,-1,STONE)
B(2,11,0,STONE)
B(2,11,1,STONE)
B(2,11,2,STONE)
B(2,11,3,STONE)
B(2,11,4,STONE)
B(2,11,5,STONE)
B(3,7,-1,STONE)
B(3,8,-1,STONE)
B(3,9,-1,STONE)
B(3,10,-3,STONE)
B(3,10,-2,STONE)
B(3,10,-1,STONE)
B(3,10,0,STONE)
B(3,10,1,STONE)
B(3,10,3,STONE)
B(3,11,-4,STONE)
B(3,11,-3,STONE)
B(3,11,-2,STONE)
B(3,11,-1,STONE)
B(3,11,0,STONE)
B(3,11,1,STONE)
B(3,11,2,STONE)
B(3,11,3,STONE)
B(3,11,4,STONE)
B(3,11,5,STONE)
B(3,11,6,STONE)
B(4,9,-1,STONE)
B(4,10,-1,STONE)
B(4,11,-3,STONE)
B(4,11,-2,STONE)
B(4,11,-1,STONE)
B(4,11,0,STONE)
B(4,11,3,STONE)
B(4,11,4,STONE)
B(5,11,-3,STONE)
B(5,11,-2,STONE)

#######################################################################
# +-----------------------------------------------------------------+ #
# |                            BO3 checks                           | #
# +-----------------------------------------------------------------+ #
#######################################################################

BlockCheck(-7,12,0,Solid)
BlockCheck(-6,12,-2,Solid)

#######################################################################
# +-----------------------------------------------------------------+ #
# |                             Branches                            | #
# +-----------------------------------------------------------------+ #
#######################################################################


#######################################################################
# +-----------------------------------------------------------------+ #
# |                             Entities                            | #
# +-----------------------------------------------------------------+ #
#######################################################################


#######################################################################
# +-----------------------------------------------------------------+ #
# |                            Particles                            | #
# +-----------------------------------------------------------------+ #
#######################################################################


#######################################################################
# +-----------------------------------------------------------------+ #
# |                             Spawners                            | #
# +-----------------------------------------------------------------+ #
#######################################################################


#######################################################################
# +-----------------------------------------------------------------+ #
# |                             ModData                             | #
# +-----------------------------------------------------------------+ #
#######################################################################

