
#
# +-----------------------------------------------------------------+ #
# |                            BO3 object                           | #
# +-----------------------------------------------------------------+ #
#

Author: NLBlackEagle

Description: No description given

Version: 3

SettingsMode: WriteDisable


#
# +-----------------------------------------------------------------+ #
# |                          Main settings                          | #
# +-----------------------------------------------------------------+ #
#

Tree: false

Frequency: 10

Rarity: 100.0

RotateRandomly: true

SpawnHeight: randomY

SpawnHeightOffset: 0

SpawnHeightVariance: 0


# Height Limits for the BO3. #


MinHeight: 5

MaxHeight: 5


# Extrusion settings #


ExtrudeMode: None

ExtrudeThroughBlocks: air

MaxBranchDepth: 10

ExcludedBiomes: All


#
# +-----------------------------------------------------------------+ #
# |                      Source block settings                      | #
# +-----------------------------------------------------------------+ #
#

SourceBlocks: air

MaxPercentageOutsideSourceBlock: 100

OutsideSourceBlock: placeAnyway


#
# +-----------------------------------------------------------------+ #
# |                              Blocks                             | #
# +-----------------------------------------------------------------+ #
#

B(-14,24,4,Leaves:7)
B(-13,0,-3,stone)
B(-13,0,-2,stone)
B(-13,0,-1,stone)
B(-13,0,0,stone)
B(-13,0,1,stone)
B(-13,0,2,stone)
B(-13,0,3,stone)
B(-13,0,4,stone)
B(-13,23,1,concrete:15)
B(-13,23,2,LOG:13)
B(-13,23,3,LOG:13)
B(-13,23,4,LOG:13)
B(-13,24,-6,stone)
B(-13,24,1,concrete:15)
B(-13,24,2,LOG:13)
B(-13,24,3,LOG:13)
B(-13,24,4,LOG:13)
B(-13,24,5,Leaves:7)
B(-13,25,-6,stone)
B(-13,25,-5,stone)
B(-13,25,-4,stone)
B(-13,25,-3,stone)
B(-13,25,-2,stone)
B(-13,25,-1,stone)
B(-13,25,0,concrete:15)
B(-13,25,1,concrete:15)
B(-13,25,2,concrete:15)
B(-13,25,3,LOG:13)
B(-13,25,4,LOG:13)
B(-13,25,5,LOG:13)
B(-13,25,6,concrete:15)
B(-13,26,-6,stone)
B(-13,26,-5,stone)
B(-13,26,-3,stone)
B(-13,26,-1,stone)
B(-13,26,0,stone)
B(-13,26,1,concrete:15)
B(-13,26,2,concrete:15)
B(-13,26,3,LOG:13)
B(-13,26,4,LOG:13)
B(-13,26,5,LOG:13)
B(-13,27,-5,stone)
B(-13,27,-3,stone)
B(-13,27,-1,stone)
B(-13,27,0,stone)
B(-13,27,1,concrete:15)
B(-13,27,3,LOG:13)
B(-13,27,4,LOG:13)
B(-12,0,-5,stone)
B(-12,0,-4,stone)
B(-12,0,-3,stone)
B(-12,0,-2,stone)
B(-12,0,-1,stone)
B(-12,0,0,stone)
B(-12,0,1,stone)
B(-12,0,2,stone)
B(-12,0,3,stone)
B(-12,0,4,stone)
B(-12,0,5,stone)
B(-12,0,6,stone)
B(-12,1,0,stone)
B(-12,1,1,stone)
B(-12,1,2,stone)
B(-12,1,3,stone)
B(-12,2,8,Leaves:7)
B(-12,22,0,concrete:15)
B(-12,22,1,LOG:13)
B(-12,22,2,LOG:13)
B(-12,22,3,LOG:13)
B(-12,22,4,LOG:13)
B(-12,23,-7,stone)
B(-12,23,-6,stone)
B(-12,23,-5,stone)
B(-12,23,-2,stone)
B(-12,23,0,concrete:15)
B(-12,23,1,concrete:15)
B(-12,23,2,LOG:13)
B(-12,23,3,LOG:13)
B(-12,23,4,LOG:13)
B(-12,23,6,concrete:15)
B(-12,24,-7,stone)
B(-12,24,-6,stone)
B(-12,24,-5,stone)
B(-12,24,-4,stone)
B(-12,24,-3,stone)
B(-12,24,-2,stone)
B(-12,24,-1,stone)
B(-12,24,0,concrete:15)
B(-12,24,1,concrete:15)
B(-12,24,2,concrete:15)
B(-12,24,3,LOG:13)
B(-12,24,4,LOG:13)
B(-12,24,5,LOG:13)
B(-12,24,6,concrete:15)
B(-12,24,7,concrete:15)
B(-12,24,8,stone)
B(-12,25,-6,stone)
B(-12,25,-5,stone)
B(-12,25,-4,stone)
B(-12,25,-3,stone)
B(-12,25,-2,stone)
B(-12,25,-1,stone)
B(-12,25,0,stone)
B(-12,25,1,concrete:15)
B(-12,25,2,concrete:15)
B(-12,25,3,stone)
B(-12,25,4,LOG:13)
B(-12,25,5,concrete:15)
B(-12,25,6,concrete:15)
B(-12,25,7,concrete:15)
B(-12,26,-7,stone)
B(-12,26,-6,stone)
B(-12,26,-5,stone)
B(-12,26,-4,stone)
B(-12,26,-3,stone)
B(-12,26,-2,stone)
B(-12,26,-1,stone)
B(-12,26,0,stone)
B(-12,26,1,concrete:15)
B(-12,26,2,concrete:15)
B(-12,26,3,LOG:13)
B(-12,26,4,LOG:13)
B(-12,26,5,LOG:13)
B(-12,26,6,concrete:15)
B(-12,26,7,stone)
B(-12,27,-6,stone)
B(-12,27,-5,stone)
B(-12,27,-4,stone)
B(-12,27,-3,stone)
B(-12,27,-2,stone)
B(-12,27,-1,stone)
B(-12,27,0,stone)
B(-12,27,1,stone)
B(-12,27,2,concrete:15)
B(-12,27,3,stone)
B(-12,27,4,LOG:13)
B(-12,27,5,stone)
B(-12,27,6,stone)
B(-11,0,-7,concrete:15)
B(-11,0,-6,stone)
B(-11,0,-5,stone)
B(-11,0,-4,stone)
B(-11,0,-3,stone)
B(-11,0,-2,stone)
B(-11,0,-1,stone)
B(-11,0,0,stone)
B(-11,0,1,stone)
B(-11,0,2,stone)
B(-11,0,3,stone)
B(-11,0,4,stone)
B(-11,0,5,stone)
B(-11,0,6,concrete:15)
B(-11,0,7,concrete:15)
B(-11,0,8,concrete:15)
B(-11,0,9,concrete:15)
B(-11,1,-4,stone)
B(-11,1,-3,stone)
B(-11,1,-2,stone)
B(-11,1,-1,stone)
B(-11,1,0,stone)
B(-11,1,1,stone)
B(-11,1,2,stone)
B(-11,1,3,stone)
B(-11,1,4,stone)
B(-11,1,5,stone)
B(-11,1,7,LOG:13)
B(-11,1,8,LOG:13)
B(-11,1,9,LOG:13)
B(-11,2,-4,stone)
B(-11,2,-3,stone)
B(-11,2,-1,stone)
B(-11,2,0,stone)
B(-11,2,1,stone)
B(-11,2,2,stone)
B(-11,2,3,stone)
B(-11,2,4,stone)
B(-11,2,7,Leaves:7)
B(-11,2,8,LOG:13)
B(-11,2,9,Leaves:7)
B(-11,3,0,stone)
B(-11,3,3,stone)
B(-11,3,8,Leaves:7)
B(-11,21,3,Leaves:7)
B(-11,21,4,Leaves:7)
B(-11,22,-4,stone)
B(-11,22,-1,concrete:15)
B(-11,22,0,concrete:15)
B(-11,22,1,LOG:13)
B(-11,22,2,LOG:13)
B(-11,22,3,LOG:13)
B(-11,22,4,LOG:13)
B(-11,22,5,concrete:15)
B(-11,23,-6,stone)
B(-11,23,-5,stone)
B(-11,23,-4,stone)
B(-11,23,-3,stone)
B(-11,23,-2,stone)
B(-11,23,-1,stone)
B(-11,23,0,concrete:15)
B(-11,23,1,LOG:13)
B(-11,23,2,LOG:13)
B(-11,23,3,LOG:13)
B(-11,23,4,concrete:15)
B(-11,23,5,concrete:15)
B(-11,23,6,concrete:15)
B(-11,23,7,concrete:15)
B(-11,24,-9,stone)
B(-11,24,-8,stone)
B(-11,24,-7,stone)
B(-11,24,-6,stone)
B(-11,24,-5,stone)
B(-11,24,-4,stone)
B(-11,24,-3,stone)
B(-11,24,-2,stone)
B(-11,24,-1,stone)
B(-11,24,0,stone)
B(-11,24,1,stone)
B(-11,24,2,stone)
B(-11,24,3,stone)
B(-11,24,4,concrete:15)
B(-11,24,5,stone)
B(-11,24,6,concrete:15)
B(-11,24,7,stone)
B(-11,24,8,stone)
B(-11,24,9,stone)
B(-11,25,-10,stone)
B(-11,25,-9,stone)
B(-11,25,-8,stone)
B(-11,25,-7,stone)
B(-11,25,-6,stone)
B(-11,25,-5,stone)
B(-11,25,-4,stone)
B(-11,25,-3,stone)
B(-11,25,-2,stone)
B(-11,25,-1,stone)
B(-11,25,0,stone)
B(-11,25,1,stone)
B(-11,25,2,stone)
B(-11,25,3,stone)
B(-11,25,4,stone)
B(-11,25,5,stone)
B(-11,25,6,stone)
B(-11,25,7,stone)
B(-11,25,8,stone)
B(-11,26,-10,stone)
B(-11,26,-9,stone)
B(-11,26,-8,stone)
B(-11,26,-7,stone)
B(-11,26,-6,stone)
B(-11,26,-5,stone)
B(-11,26,-4,stone)
B(-11,26,-3,stone)
B(-11,26,-2,stone)
B(-11,26,-1,stone)
B(-11,26,0,stone)
B(-11,26,1,stone)
B(-11,26,2,stone)
B(-11,26,3,stone)
B(-11,26,4,stone)
B(-11,26,5,stone)
B(-11,26,6,stone)
B(-11,26,7,stone)
B(-11,26,8,stone)
B(-11,27,-8,stone)
B(-11,27,-7,stone)
B(-11,27,-6,stone)
B(-11,27,-5,stone)
B(-11,27,-4,stone)
B(-11,27,-3,stone)
B(-11,27,-2,stone)
B(-11,27,-1,stone)
B(-11,27,0,stone)
B(-11,27,1,stone)
B(-11,27,2,stone)
B(-11,27,3,stone)
B(-11,27,4,stone)
B(-11,27,5,stone)
B(-11,27,6,stone)
B(-11,27,7,stone)
B(-11,27,8,stone)
B(-10,0,-9,Leaves:7)
B(-10,0,-8,LOG:13)
B(-10,0,-7,concrete:15)
B(-10,0,-6,concrete:15)
B(-10,0,-5,stone)
B(-10,0,-4,stone)
B(-10,0,-3,stone)
B(-10,0,-2,stone)
B(-10,0,-1,stone)
B(-10,0,0,stone)
B(-10,0,1,stone)
B(-10,0,2,stone)
B(-10,0,3,stone)
B(-10,0,4,stone)
B(-10,0,5,stone)
B(-10,0,6,stone)
B(-10,0,7,concrete:15)
B(-10,0,8,concrete:15)
B(-10,0,9,concrete:15)
B(-10,1,-7,concrete:15)
B(-10,1,-6,concrete:15)
B(-10,1,-5,stone)
B(-10,1,-4,stone)
B(-10,1,-3,stone)
B(-10,1,-2,stone)
B(-10,1,-1,stone)
B(-10,1,0,stone)
B(-10,1,1,stone)
B(-10,1,2,stone)
B(-10,1,3,stone)
B(-10,1,4,stone)
B(-10,1,5,stone)
B(-10,1,6,concrete:15)
B(-10,1,7,concrete:15)
B(-10,1,8,LOG:13)
B(-10,1,9,concrete:15)
B(-10,2,-6,concrete:15)
B(-10,2,-5,stone)
B(-10,2,-4,stone)
B(-10,2,-3,stone)
B(-10,2,-2,stone)
B(-10,2,-1,stone)
B(-10,2,0,stone)
B(-10,2,1,stone)
B(-10,2,2,stone)
B(-10,2,3,stone)
B(-10,2,4,stone)
B(-10,2,5,concrete:15)
B(-10,2,7,LOG:13)
B(-10,2,8,LOG:13)
B(-10,2,9,LOG:13)
B(-10,3,-4,stone)
B(-10,3,-3,stone)
B(-10,3,-2,stone)
B(-10,3,-1,stone)
B(-10,3,0,stone)
B(-10,3,1,stone)
B(-10,3,2,stone)
B(-10,3,3,stone)
B(-10,3,4,stone)
B(-10,3,5,concrete:15)
B(-10,3,6,concrete:15)
B(-10,3,7,concrete:15)
B(-10,3,8,LOG:13)
B(-10,4,-2,stone)
B(-10,4,-1,stone)
B(-10,4,0,stone)
B(-10,4,1,stone)
B(-10,4,2,stone)
B(-10,4,3,stone)
B(-10,4,7,LOG:13)
B(-10,4,8,Leaves:7)
B(-10,5,0,stone)
B(-10,5,1,stone)
B(-10,20,3,Leaves:7)
B(-10,21,-1,concrete:15)
B(-10,21,0,concrete:15)
B(-10,21,1,LOG:13)
B(-10,21,2,LOG:13)
B(-10,21,3,LOG:13)
B(-10,21,4,concrete:15)
B(-10,22,-5,stone)
B(-10,22,-4,stone)
B(-10,22,-2,stone)
B(-10,22,-1,concrete:15)
B(-10,22,0,concrete:15)
B(-10,22,1,LOG:13)
B(-10,22,2,LOG:13)
B(-10,22,3,LOG:13)
B(-10,22,4,concrete:15)
B(-10,23,-7,stone)
B(-10,23,-6,stone)
B(-10,23,-5,stone)
B(-10,23,-4,stone)
B(-10,23,-3,stone)
B(-10,23,-2,stone)
B(-10,23,-1,stone)
B(-10,23,0,stone)
B(-10,23,1,stone)
B(-10,23,2,LOG:13)
B(-10,23,3,concrete:15)
B(-10,23,4,stone)
B(-10,23,5,concrete:15)
B(-10,23,6,stone)
B(-10,23,7,stone)
B(-10,24,-11,stone)
B(-10,24,-10,stone)
B(-10,24,-9,stone)
B(-10,24,-8,stone)
B(-10,24,-7,stone)
B(-10,24,-6,stone)
B(-10,24,-5,stone)
B(-10,24,-4,stone)
B(-10,24,-3,stone)
B(-10,24,-2,stone)
B(-10,24,-1,stone)
B(-10,24,0,stone)
B(-10,24,1,stone)
B(-10,24,2,stone)
B(-10,24,3,stone)
B(-10,24,4,stone)
B(-10,24,5,stone)
B(-10,24,6,stone)
B(-10,24,7,stone)
B(-10,24,8,stone)
B(-10,24,9,stone)
B(-10,24,10,stone)
B(-10,25,-11,stone)
B(-10,25,-10,stone)
B(-10,25,-9,stone)
B(-10,25,-8,stone)
B(-10,25,-7,stone)
B(-10,25,-6,stone)
B(-10,25,-5,stone)
B(-10,25,-4,stone)
B(-10,25,-3,stone)
B(-10,25,-2,stone)
B(-10,25,-1,stone)
B(-10,25,0,stone)
B(-10,25,1,stone)
B(-10,25,2,stone)
B(-10,25,3,stone)
B(-10,25,4,stone)
B(-10,25,5,stone)
B(-10,25,6,stone)
B(-10,25,7,stone)
B(-10,25,8,stone)
B(-10,25,9,stone)
B(-10,26,-10,stone)
B(-10,26,-9,stone)
B(-10,26,-8,stone)
B(-10,26,-7,stone)
B(-10,26,-6,stone)
B(-10,26,-5,stone)
B(-10,26,-4,stone)
B(-10,26,-3,stone)
B(-10,26,-2,stone)
B(-10,26,-1,stone)
B(-10,26,0,stone)
B(-10,26,1,stone)
B(-10,26,2,stone)
B(-10,26,3,stone)
B(-10,26,4,stone)
B(-10,26,5,stone)
B(-10,26,6,stone)
B(-10,26,7,stone)
B(-10,26,8,stone)
B(-10,26,9,stone)
B(-10,27,-9,stone)
B(-10,27,-8,stone)
B(-10,27,-7,stone)
B(-10,27,-6,stone)
B(-10,27,-5,stone)
B(-10,27,-4,stone)
B(-10,27,-3,stone)
B(-10,27,-2,stone)
B(-10,27,-1,stone)
B(-10,27,0,stone)
B(-10,27,1,stone)
B(-10,27,2,stone)
B(-10,27,3,stone)
B(-10,27,4,stone)
B(-10,27,5,stone)
B(-10,27,6,stone)
B(-10,27,7,stone)
B(-10,27,8,stone)
B(-9,0,-9,LOG:13)
B(-9,0,-8,LOG:13)
B(-9,0,-7,concrete:15)
B(-9,0,-6,stone)
B(-9,0,-5,stone)
B(-9,0,-4,stone)
B(-9,0,-3,stone)
B(-9,0,-2,stone)
B(-9,0,-1,stone)
B(-9,0,0,stone)
B(-9,0,1,stone)
B(-9,0,2,stone)
B(-9,0,3,stone)
B(-9,0,4,stone)
B(-9,0,5,stone)
B(-9,0,6,stone)
B(-9,0,7,stone)
B(-9,0,8,concrete:15)
B(-9,0,9,concrete:15)
B(-9,0,10,concrete:15)
B(-9,1,-9,LOG:13)
B(-9,1,-8,LOG:13)
B(-9,1,-7,concrete:15)
B(-9,1,-6,concrete:15)
B(-9,1,-5,stone)
B(-9,1,-4,stone)
B(-9,1,-3,stone)
B(-9,1,-2,stone)
B(-9,1,-1,stone)
B(-9,1,0,stone)
B(-9,1,1,stone)
B(-9,1,2,stone)
B(-9,1,3,stone)
B(-9,1,4,stone)
B(-9,1,5,stone)
B(-9,1,6,stone)
B(-9,1,7,concrete:15)
B(-9,1,8,concrete:15)
B(-9,1,9,concrete:15)
B(-9,2,-9,Leaves:7)
B(-9,2,-8,LOG:13)
B(-9,2,-7,concrete:15)
B(-9,2,-6,stone)
B(-9,2,-5,stone)
B(-9,2,-4,stone)
B(-9,2,-3,stone)
B(-9,2,-2,stone)
B(-9,2,-1,stone)
B(-9,2,0,stone)
B(-9,2,1,stone)
B(-9,2,2,stone)
B(-9,2,3,stone)
B(-9,2,4,stone)
B(-9,2,5,stone)
B(-9,2,6,concrete:15)
B(-9,2,7,concrete:15)
B(-9,2,8,concrete:15)
B(-9,3,-9,Leaves:7)
B(-9,3,-8,Leaves:7)
B(-9,3,-6,concrete:15)
B(-9,3,-5,stone)
B(-9,3,-4,stone)
B(-9,3,-3,stone)
B(-9,3,-2,stone)
B(-9,3,-1,stone)
B(-9,3,0,stone)
B(-9,3,1,stone)
B(-9,3,2,stone)
B(-9,3,3,stone)
B(-9,3,4,stone)
B(-9,3,5,concrete:15)
B(-9,3,6,concrete:15)
B(-9,3,7,LOG:13)
B(-9,3,8,LOG:13)
B(-9,4,-4,stone)
B(-9,4,-3,stone)
B(-9,4,-2,stone)
B(-9,4,-1,stone)
B(-9,4,0,stone)
B(-9,4,1,stone)
B(-9,4,2,stone)
B(-9,4,3,stone)
B(-9,4,4,stone)
B(-9,4,6,LOG:13)
B(-9,4,7,LOG:13)
B(-9,4,8,LOG:13)
B(-9,4,9,Leaves:7)
B(-9,5,-4,stone)
B(-9,5,0,stone)
B(-9,5,1,stone)
B(-9,5,2,stone)
B(-9,5,3,stone)
B(-9,5,8,Leaves:7)
B(-9,6,0,stone)
B(-9,20,-2,stone)
B(-9,20,-1,stone)
B(-9,20,1,LOG:13)
B(-9,20,2,LOG:13)
B(-9,20,3,Leaves:7)
B(-9,21,-4,stone)
B(-9,21,-3,stone)
B(-9,21,-2,stone)
B(-9,21,-1,concrete:15)
B(-9,21,0,concrete:15)
B(-9,21,1,LOG:13)
B(-9,21,2,LOG:13)
B(-9,21,3,LOG:13)
B(-9,22,-5,stone)
B(-9,22,-4,stone)
B(-9,22,-3,stone)
B(-9,22,-2,stone)
B(-9,22,-1,stone)
B(-9,22,0,concrete:15)
B(-9,22,1,stone)
B(-9,22,2,LOG:13)
B(-9,22,3,concrete:15)
B(-9,22,4,concrete:15)
B(-9,23,-11,stone)
B(-9,23,-10,stone)
B(-9,23,-8,stone)
B(-9,23,-7,stone)
B(-9,23,-6,stone)
B(-9,23,-5,stone)
B(-9,23,-4,stone)
B(-9,23,-3,stone)
B(-9,23,-2,stone)
B(-9,23,-1,stone)
B(-9,23,0,stone)
B(-9,23,1,stone)
B(-9,23,2,stone)
B(-9,23,3,stone)
B(-9,23,4,stone)
B(-9,23,5,stone)
B(-9,23,6,stone)
B(-9,23,7,stone)
B(-9,23,8,stone)
B(-9,24,-11,stone)
B(-9,24,-10,stone)
B(-9,24,-9,stone)
B(-9,24,-8,stone)
B(-9,24,-7,stone)
B(-9,24,-6,stone)
B(-9,24,-5,stone)
B(-9,24,-4,stone)
B(-9,24,-3,stone)
B(-9,24,-2,stone)
B(-9,24,-1,stone)
B(-9,24,0,log2:1)
B(-9,24,1,stone)
B(-9,24,2,stone)
B(-9,24,3,stone)
B(-9,24,4,stone)
B(-9,24,5,stone)
B(-9,24,6,stone)
B(-9,24,7,stone)
B(-9,24,8,stone)
B(-9,24,9,stone)
B(-9,24,10,stone)
B(-9,25,-11,stone)
B(-9,25,-10,stone)
B(-9,25,-9,stone)
B(-9,25,-8,stone)
B(-9,25,-7,stone)
B(-9,25,-6,stone)
B(-9,25,-5,stone)
B(-9,25,-4,stone)
B(-9,25,-3,stone)
B(-9,25,-2,stone)
B(-9,25,-1,log:2)
B(-9,25,0,log:2)
B(-9,25,1,stone)
B(-9,25,2,stone)
B(-9,25,3,stone)
B(-9,25,4,stone)
B(-9,25,5,stone)
B(-9,25,6,stone)
B(-9,25,7,stone)
B(-9,25,8,stone)
B(-9,25,9,stone)
B(-9,25,10,stone)
B(-9,26,-11,stone)
B(-9,26,-10,stone)
B(-9,26,-9,stone)
B(-9,26,-8,stone)
B(-9,26,-7,stone)
B(-9,26,-6,stone)
B(-9,26,-5,stone)
B(-9,26,-3,log2:1)
B(-9,26,-2,stone)
B(-9,26,-1,log2)
B(-9,26,0,log)
B(-9,26,1,stone)
B(-9,26,2,stone)
B(-9,26,3,log2)
B(-9,26,4,stone)
B(-9,26,5,stone)
B(-9,26,6,stone)
B(-9,26,7,stone)
B(-9,26,8,stone)
B(-9,26,9,stone)
B(-9,26,10,stone)
B(-9,27,-11,stone)
B(-9,27,-10,stone)
B(-9,27,-9,stone)
B(-9,27,-8,stone)
B(-9,27,-7,stone)
B(-9,27,-6,stone)
B(-9,27,-5,stone)
B(-9,27,-4,stone)
B(-9,27,-3,log2:1)
B(-9,27,-2,log:2)
B(-9,27,-1,stone)
B(-9,27,0,log2:1)
B(-9,27,1,log:2)
B(-9,27,2,log:2)
B(-9,27,3,stone)
B(-9,27,4,stone)
B(-9,27,5,stone)
B(-9,27,6,stone)
B(-9,27,7,stone)
B(-9,27,8,stone)
B(-9,27,9,stone)
B(-8,0,-10,LOG:13)
B(-8,0,-9,LOG:13)
B(-8,0,-8,LOG:13)
B(-8,0,-7,stone)
B(-8,0,-6,stone)
B(-8,0,-5,stone)
B(-8,0,-4,stone)
B(-8,0,-3,stone)
B(-8,0,-2,stone)
B(-8,0,-1,stone)
B(-8,0,0,stone)
B(-8,0,1,stone)
B(-8,0,2,stone)
B(-8,0,3,stone)
B(-8,0,4,stone)
B(-8,0,5,stone)
B(-8,0,6,stone)
B(-8,0,7,stone)
B(-8,0,8,concrete:15)
B(-8,0,9,concrete:15)
B(-8,0,10,concrete:15)
B(-8,0,11,concrete:15)
B(-8,1,-9,LOG:13)
B(-8,1,-8,LOG:13)
B(-8,1,-7,stone)
B(-8,1,-6,stone)
B(-8,1,-5,stone)
B(-8,1,-4,stone)
B(-8,1,-3,stone)
B(-8,1,-2,stone)
B(-8,1,-1,stone)
B(-8,1,0,stone)
B(-8,1,1,stone)
B(-8,1,2,stone)
B(-8,1,3,stone)
B(-8,1,4,stone)
B(-8,1,5,stone)
B(-8,1,6,stone)
B(-8,1,7,stone)
B(-8,1,8,concrete:15)
B(-8,1,9,concrete:15)
B(-8,2,-9,LOG:13)
B(-8,2,-8,LOG:13)
B(-8,2,-7,concrete:15)
B(-8,2,-6,concrete:15)
B(-8,2,-5,stone)
B(-8,2,-4,stone)
B(-8,2,-3,stone)
B(-8,2,-2,stone)
B(-8,2,-1,stone)
B(-8,2,0,stone)
B(-8,2,1,stone)
B(-8,2,2,stone)
B(-8,2,3,stone)
B(-8,2,4,stone)
B(-8,2,5,stone)
B(-8,2,6,stone)
B(-8,2,7,concrete:15)
B(-8,2,8,concrete:15)
B(-8,3,-8,Leaves:7)
B(-8,3,-7,LOG:13)
B(-8,3,-6,concrete:15)
B(-8,3,-5,stone)
B(-8,3,-4,stone)
B(-8,3,-3,stone)
B(-8,3,-2,stone)
B(-8,3,-1,stone)
B(-8,3,0,stone)
B(-8,3,1,stone)
B(-8,3,2,stone)
B(-8,3,3,stone)
B(-8,3,4,stone)
B(-8,3,5,stone)
B(-8,3,6,LOG:13)
B(-8,3,7,LOG:13)
B(-8,3,8,LOG:13)
B(-8,4,-6,concrete:15)
B(-8,4,-5,concrete:15)
B(-8,4,-4,stone)
B(-8,4,-3,stone)
B(-8,4,-2,stone)
B(-8,4,-1,stone)
B(-8,4,0,stone)
B(-8,4,1,stone)
B(-8,4,2,stone)
B(-8,4,3,stone)
B(-8,4,4,stone)
B(-8,4,5,concrete:15)
B(-8,4,6,LOG:13)
B(-8,4,7,LOG:13)
B(-8,4,8,LOG:13)
B(-8,5,-5,stone)
B(-8,5,-4,stone)
B(-8,5,-3,stone)
B(-8,5,-2,stone)
B(-8,5,-1,stone)
B(-8,5,0,stone)
B(-8,5,1,stone)
B(-8,5,2,stone)
B(-8,5,3,stone)
B(-8,5,4,concrete:15)
B(-8,5,5,concrete:15)
B(-8,5,6,LOG:13)
B(-8,6,-4,stone)
B(-8,6,-3,stone)
B(-8,6,-2,stone)
B(-8,6,-1,stone)
B(-8,6,0,stone)
B(-8,6,1,stone)
B(-8,6,2,stone)
B(-8,6,3,stone)
B(-8,6,4,concrete:15)
B(-8,6,5,concrete:15)
B(-8,6,6,Leaves:7)
B(-8,7,-1,stone)
B(-8,7,0,stone)
B(-8,7,1,stone)
B(-8,7,3,stone)
B(-8,8,-2,Leaves:7)
B(-8,8,1,stone)
B(-8,9,1,concrete:15)
B(-8,19,0,concrete:15)
B(-8,19,3,Leaves:7)
B(-8,20,-5,stone)
B(-8,20,-4,stone)
B(-8,20,-3,stone)
B(-8,20,-2,stone)
B(-8,20,-1,stone)
B(-8,20,0,concrete:15)
B(-8,20,1,LOG:13)
B(-8,20,2,LOG:13)
B(-8,20,3,LOG:13)
B(-8,20,4,Leaves:7)
B(-8,21,-6,stone)
B(-8,21,-5,stone)
B(-8,21,-4,stone)
B(-8,21,-3,stone)
B(-8,21,-2,stone)
B(-8,21,-1,stone)
B(-8,21,0,concrete:15)
B(-8,21,1,concrete:15)
B(-8,21,2,LOG:13)
B(-8,21,3,LOG:13)
B(-8,21,4,LOG:13)
B(-8,22,-7,stone)
B(-8,22,-6,stone)
B(-8,22,-5,stone)
B(-8,22,-4,stone)
B(-8,22,-3,stone)
B(-8,22,-2,stone)
B(-8,22,-1,stone)
B(-8,22,0,stone)
B(-8,22,1,stone)
B(-8,22,2,stone)
B(-8,22,3,concrete:15)
B(-8,22,4,concrete:15)
B(-8,22,5,concrete:15)
B(-8,22,6,concrete:15)
B(-8,23,-10,stone)
B(-8,23,-9,stone)
B(-8,23,-8,stone)
B(-8,23,-7,stone)
B(-8,23,-6,stone)
B(-8,23,-5,stone)
B(-8,23,-4,stone)
B(-8,23,-3,stone)
B(-8,23,-2,stone)
B(-8,23,-1,stone)
B(-8,23,0,stone)
B(-8,23,1,stone)
B(-8,23,2,stone)
B(-8,23,3,stone)
B(-8,23,4,stone)
B(-8,23,5,stone)
B(-8,23,6,concrete:15)
B(-8,23,7,stone)
B(-8,24,-11,stone)
B(-8,24,-10,stone)
B(-8,24,-9,stone)
B(-8,24,-8,stone)
B(-8,24,-7,stone)
B(-8,24,-6,stone)
B(-8,24,-5,stone)
B(-8,24,-4,stone)
B(-8,24,-3,stone)
B(-8,24,-2,stone)
B(-8,24,-1,stone)
B(-8,24,0,stone)
B(-8,24,1,stone)
B(-8,24,2,stone)
B(-8,24,3,LOG:1)
B(-8,24,4,stone)
B(-8,24,5,stone)
B(-8,24,6,stone)
B(-8,24,7,stone)
B(-8,24,8,stone)
B(-8,24,9,stone)
B(-8,24,10,stone)
B(-8,25,-11,stone)
B(-8,25,-10,stone)
B(-8,25,-9,stone)
B(-8,25,-8,stone)
B(-8,25,-7,stone)
B(-8,25,-6,stone)
B(-8,25,-5,stone)
B(-8,25,-4,log)
B(-8,25,-3,stone)
B(-8,25,-2,stone)
B(-8,25,-1,stone)
B(-8,25,0,stone)
B(-8,25,1,LOG:1)
B(-8,25,2,stone)
B(-8,25,3,log2)
B(-8,25,4,log2:1)
B(-8,25,5,stone)
B(-8,25,6,stone)
B(-8,25,7,stone)
B(-8,25,8,stone)
B(-8,25,9,stone)
B(-8,25,10,stone)
B(-8,26,-12,stone)
B(-8,26,-11,stone)
B(-8,26,-10,stone)
B(-8,26,-9,stone)
B(-8,26,-8,stone)
B(-8,26,-7,stone)
B(-8,26,-6,stone)
B(-8,26,-5,stone)
B(-8,26,-4,stone)
B(-8,26,-3,log2)
B(-8,26,-2,log2)
B(-8,26,-1,stone)
B(-8,26,0,log)
B(-8,26,1,stone)
B(-8,26,2,log)
B(-8,26,3,log)
B(-8,26,4,LOG:1)
B(-8,26,5,stone)
B(-8,26,6,stone)
B(-8,26,7,stone)
B(-8,26,8,stone)
B(-8,26,9,stone)
B(-8,26,10,stone)
B(-8,27,-10,stone)
B(-8,27,-9,stone)
B(-8,27,-8,stone)
B(-8,27,-7,stone)
B(-8,27,-6,stone)
B(-8,27,-5,log)
B(-8,27,-4,stone)
B(-8,27,-3,stone)
B(-8,27,-2,stone)
B(-8,27,-1,stone)
B(-8,27,0,log:2)
B(-8,27,1,stone)
B(-8,27,2,log2)
B(-8,27,3,stone)
B(-8,27,4,stone)
B(-8,27,5,stone)
B(-8,27,6,stone)
B(-8,27,7,stone)
B(-8,27,8,stone)
B(-8,27,9,stone)
B(-8,27,10,stone)
B(-7,0,-10,concrete:15)
B(-7,0,-9,concrete:15)
B(-7,0,-8,stone)
B(-7,0,-7,stone)
B(-7,0,-6,stone)
B(-7,0,-5,stone)
B(-7,0,-4,stone)
B(-7,0,-3,stone)
B(-7,0,-2,stone)
B(-7,0,-1,stone)
B(-7,0,0,stone)
B(-7,0,1,stone)
B(-7,0,2,stone)
B(-7,0,3,stone)
B(-7,0,4,stone)
B(-7,0,5,stone)
B(-7,0,6,stone)
B(-7,0,7,stone)
B(-7,0,8,stone)
B(-7,0,9,concrete:15)
B(-7,0,10,stone)
B(-7,0,11,stone)
B(-7,1,-9,LOG:13)
B(-7,1,-8,concrete:15)
B(-7,1,-7,stone)
B(-7,1,-6,stone)
B(-7,1,-5,stone)
B(-7,1,-4,stone)
B(-7,1,-3,stone)
B(-7,1,-2,stone)
B(-7,1,-1,stone)
B(-7,1,0,stone)
B(-7,1,1,stone)
B(-7,1,2,stone)
B(-7,1,3,stone)
B(-7,1,4,stone)
B(-7,1,5,stone)
B(-7,1,6,stone)
B(-7,1,7,stone)
B(-7,1,8,concrete:15)
B(-7,1,9,concrete:15)
B(-7,1,10,concrete:15)
B(-7,2,-8,LOG:13)
B(-7,2,-7,LOG:13)
B(-7,2,-6,stone)
B(-7,2,-5,stone)
B(-7,2,-4,stone)
B(-7,2,-3,stone)
B(-7,2,-2,stone)
B(-7,2,-1,stone)
B(-7,2,0,stone)
B(-7,2,1,stone)
B(-7,2,2,stone)
B(-7,2,3,stone)
B(-7,2,4,stone)
B(-7,2,5,stone)
B(-7,2,6,stone)
B(-7,2,7,concrete:15)
B(-7,2,8,concrete:15)
B(-7,2,9,concrete:15)
B(-7,3,-9,Leaves:7)
B(-7,3,-8,LOG:13)
B(-7,3,-7,LOG:13)
B(-7,3,-6,concrete:15)
B(-7,3,-5,concrete:15)
B(-7,3,-4,stone)
B(-7,3,-3,stone)
B(-7,3,-2,stone)
B(-7,3,-1,stone)
B(-7,3,0,stone)
B(-7,3,1,stone)
B(-7,3,2,stone)
B(-7,3,3,stone)
B(-7,3,4,stone)
B(-7,3,5,stone)
B(-7,3,6,stone)
B(-7,3,7,LOG:13)
B(-7,3,8,concrete:15)
B(-7,4,-8,Leaves:7)
B(-7,4,-6,concrete:15)
B(-7,4,-5,concrete:15)
B(-7,4,-4,stone)
B(-7,4,-3,stone)
B(-7,4,-2,stone)
B(-7,4,-1,stone)
B(-7,4,0,stone)
B(-7,4,1,stone)
B(-7,4,2,stone)
B(-7,4,3,stone)
B(-7,4,4,stone)
B(-7,4,5,stone)
B(-7,4,6,LOG:13)
B(-7,4,7,LOG:13)
B(-7,5,-6,concrete:15)
B(-7,5,-5,concrete:15)
B(-7,5,-4,stone)
B(-7,5,-3,stone)
B(-7,5,-2,stone)
B(-7,5,-1,stone)
B(-7,5,0,stone)
B(-7,5,1,stone)
B(-7,5,2,stone)
B(-7,5,3,stone)
B(-7,5,4,stone)
B(-7,5,5,concrete:15)
B(-7,5,6,LOG:13)
B(-7,5,7,LOG:13)
B(-7,6,-5,concrete:15)
B(-7,6,-4,stone)
B(-7,6,-3,stone)
B(-7,6,-2,stone)
B(-7,6,-1,stone)
B(-7,6,0,stone)
B(-7,6,1,stone)
B(-7,6,2,stone)
B(-7,6,3,stone)
B(-7,6,4,concrete:15)
B(-7,6,5,LOG:13)
B(-7,6,6,LOG:13)
B(-7,6,7,Leaves:7)
B(-7,7,-3,concrete:15)
B(-7,7,-2,stone)
B(-7,7,-1,stone)
B(-7,7,0,stone)
B(-7,7,1,stone)
B(-7,7,2,stone)
B(-7,7,3,stone)
B(-7,7,4,concrete:15)
B(-7,7,6,Leaves:7)
B(-7,8,-3,Leaves:7)
B(-7,8,-2,concrete:15)
B(-7,8,-1,concrete:15)
B(-7,8,0,concrete:15)
B(-7,8,1,concrete:15)
B(-7,8,2,stone)
B(-7,8,3,concrete:15)
B(-7,9,-2,LOG:13)
B(-7,9,-1,LOG:13)
B(-7,9,0,concrete:15)
B(-7,9,1,concrete:15)
B(-7,9,2,concrete:15)
B(-7,10,-2,LOG:13)
B(-7,10,1,concrete:15)
B(-7,11,-1,Leaves:7)
B(-7,12,1,Leaves:7)
B(-7,17,-2,stone)
B(-7,17,-1,stone)
B(-7,18,-2,stone)
B(-7,18,-1,stone)
B(-7,18,0,stone)
B(-7,18,1,concrete:15)
B(-7,19,-3,stone)
B(-7,19,-2,stone)
B(-7,19,-1,stone)
B(-7,19,0,stone)
B(-7,19,1,concrete:15)
B(-7,20,-6,stone)
B(-7,20,-5,stone)
B(-7,20,-4,stone)
B(-7,20,-3,stone)
B(-7,20,-2,stone)
B(-7,20,-1,stone)
B(-7,20,0,concrete:15)
B(-7,20,1,concrete:15)
B(-7,20,2,LOG:13)
B(-7,20,3,LOG:13)
B(-7,20,4,LOG:13)
B(-7,21,-7,stone)
B(-7,21,-6,stone)
B(-7,21,-5,stone)
B(-7,21,-4,stone)
B(-7,21,-3,stone)
B(-7,21,-2,stone)
B(-7,21,-1,stone)
B(-7,21,0,stone)
B(-7,21,1,concrete:15)
B(-7,21,2,stone)
B(-7,21,3,LOG:13)
B(-7,21,4,LOG:13)
B(-7,21,5,LOG:13)
B(-7,22,-7,stone)
B(-7,22,-6,stone)
B(-7,22,-5,stone)
B(-7,22,-4,stone)
B(-7,22,-3,stone)
B(-7,22,-2,stone)
B(-7,22,-1,stone)
B(-7,22,0,stone)
B(-7,22,1,stone)
B(-7,22,2,stone)
B(-7,22,3,stone)
B(-7,22,4,concrete:15)
B(-7,22,5,concrete:15)
B(-7,22,6,concrete:15)
B(-7,22,7,concrete:15)
B(-7,23,-9,stone)
B(-7,23,-8,stone)
B(-7,23,-7,stone)
B(-7,23,-6,stone)
B(-7,23,-5,stone)
B(-7,23,-4,stone)
B(-7,23,-3,stone)
B(-7,23,-2,stone)
B(-7,23,-1,stone)
B(-7,23,0,stone)
B(-7,23,1,stone)
B(-7,23,2,stone)
B(-7,23,3,log2)
B(-7,23,4,stone)
B(-7,23,5,concrete:15)
B(-7,23,6,concrete:15)
B(-7,23,7,concrete:15)
B(-7,23,8,stone)
B(-7,24,-10,stone)
B(-7,24,-9,stone)
B(-7,24,-8,stone)
B(-7,24,-7,stone)
B(-7,24,-6,stone)
B(-7,24,-5,stone)
B(-7,24,-4,stone)
B(-7,24,-3,stone)
B(-7,24,-2,stone)
B(-7,24,-1,stone)
B(-7,24,0,stone)
B(-7,24,1,stone)
B(-7,24,2,log:2)
B(-7,24,3,stone)
B(-7,24,4,log)
B(-7,24,5,stone)
B(-7,24,6,stone)
B(-7,24,7,stone)
B(-7,24,8,stone)
B(-7,24,9,stone)
B(-7,24,10,stone)
B(-7,25,-12,stone)
B(-7,25,-11,stone)
B(-7,25,-10,stone)
B(-7,25,-9,stone)
B(-7,25,-8,stone)
B(-7,25,-7,stone)
B(-7,25,-6,stone)
B(-7,25,-5,stone)
B(-7,25,-4,stone)
B(-7,25,-3,stone)
B(-7,25,-2,log2:1)
B(-7,25,-1,log2)
B(-7,25,0,stone)
B(-7,25,1,stone)
B(-7,25,2,stone)
B(-7,25,3,stone)
B(-7,25,4,stone)
B(-7,25,5,stone)
B(-7,25,6,stone)
B(-7,25,7,stone)
B(-7,25,8,stone)
B(-7,25,9,stone)
B(-7,25,10,stone)
B(-7,25,11,stone)
B(-7,26,-12,stone)
B(-7,26,-11,stone)
B(-7,26,-10,stone)
B(-7,26,-9,stone)
B(-7,26,-8,stone)
B(-7,26,-7,stone)
B(-7,26,-6,stone)
B(-7,26,-5,log2)
B(-7,26,-4,log:2)
B(-7,26,-3,stone)
B(-7,26,-2,stone)
B(-7,26,-1,stone)
B(-7,26,0,stone)
B(-7,26,1,stone)
B(-7,26,2,stone)
B(-7,26,3,log2:1)
B(-7,26,4,stone)
B(-7,26,5,log)
B(-7,26,6,log2:1)
B(-7,26,7,stone)
B(-7,26,8,stone)
B(-7,26,9,stone)
B(-7,26,10,stone)
B(-7,27,-11,stone)
B(-7,27,-10,stone)
B(-7,27,-9,stone)
B(-7,27,-8,stone)
B(-7,27,-7,stone)
B(-7,27,-6,LOG:1)
B(-7,27,-5,log:2)
B(-7,27,-4,log2)
B(-7,27,-3,stone)
B(-7,27,-2,stone)
B(-7,27,-1,stone)
B(-7,27,0,log2:1)
B(-7,27,1,stone)
B(-7,27,2,log)
B(-7,27,3,log:2)
B(-7,27,4,stone)
B(-7,27,5,stone)
B(-7,27,6,log2:1)
B(-7,27,7,stone)
B(-7,27,8,stone)
B(-7,27,9,stone)
B(-7,27,10,stone)
B(-6,0,-11,concrete:15)
B(-6,0,-10,concrete:15)
B(-6,0,-9,concrete:15)
B(-6,0,-8,concrete:15)
B(-6,0,-7,stone)
B(-6,0,-6,stone)
B(-6,0,-5,stone)
B(-6,0,-4,stone)
B(-6,0,-3,stone)
B(-6,0,-2,stone)
B(-6,0,-1,stone)
B(-6,0,0,stone)
B(-6,0,1,stone)
B(-6,0,2,stone)
B(-6,0,3,stone)
B(-6,0,4,stone)
B(-6,0,5,stone)
B(-6,0,6,stone)
B(-6,0,7,stone)
B(-6,0,8,stone)
B(-6,0,9,stone)
B(-6,0,10,stone)
B(-6,0,11,stone)
B(-6,0,12,stone)
B(-6,1,-9,concrete:15)
B(-6,1,-8,concrete:15)
B(-6,1,-7,stone)
B(-6,1,-6,stone)
B(-6,1,-5,stone)
B(-6,1,-4,stone)
B(-6,1,-3,stone)
B(-6,1,-2,stone)
B(-6,1,-1,stone)
B(-6,1,0,stone)
B(-6,1,1,stone)
B(-6,1,2,stone)
B(-6,1,3,stone)
B(-6,1,4,stone)
B(-6,1,5,stone)
B(-6,1,6,stone)
B(-6,1,7,stone)
B(-6,1,8,stone)
B(-6,1,9,stone)
B(-6,1,10,stone)
B(-6,2,-9,LOG:13)
B(-6,2,-8,LOG:13)
B(-6,2,-7,stone)
B(-6,2,-6,stone)
B(-6,2,-5,stone)
B(-6,2,-4,stone)
B(-6,2,-3,stone)
B(-6,2,-2,stone)
B(-6,2,-1,stone)
B(-6,2,0,stone)
B(-6,2,1,stone)
B(-6,2,2,stone)
B(-6,2,3,stone)
B(-6,2,4,stone)
B(-6,2,5,stone)
B(-6,2,6,stone)
B(-6,2,7,stone)
B(-6,2,8,concrete:15)
B(-6,2,9,stone)
B(-6,2,10,stone)
B(-6,3,-9,LOG:13)
B(-6,3,-8,LOG:13)
B(-6,3,-7,LOG:13)
B(-6,3,-6,concrete:15)
B(-6,3,-5,stone)
B(-6,3,-4,stone)
B(-6,3,-3,stone)
B(-6,3,-2,stone)
B(-6,3,-1,stone)
B(-6,3,0,stone)
B(-6,3,1,stone)
B(-6,3,2,stone)
B(-6,3,3,stone)
B(-6,3,4,stone)
B(-6,3,5,stone)
B(-6,3,6,stone)
B(-6,3,7,concrete:15)
B(-6,3,8,concrete:15)
B(-6,4,-9,Leaves:7)
B(-6,4,-8,LOG:13)
B(-6,4,-7,concrete:15)
B(-6,4,-6,concrete:15)
B(-6,4,-5,concrete:15)
B(-6,4,-4,stone)
B(-6,4,-3,stone)
B(-6,4,-2,stone)
B(-6,4,-1,stone)
B(-6,4,0,stone)
B(-6,4,1,log:2)
B(-6,4,2,stone)
B(-6,4,3,stone)
B(-6,4,4,stone)
B(-6,4,5,stone)
B(-6,4,6,concrete:15)
B(-6,4,7,LOG:13)
B(-6,4,8,concrete:15)
B(-6,5,-8,Leaves:7)
B(-6,5,-7,concrete:15)
B(-6,5,-6,concrete:15)
B(-6,5,-5,concrete:15)
B(-6,5,-4,stone)
B(-6,5,-3,stone)
B(-6,5,-2,stone)
B(-6,5,-1,stone)
B(-6,5,0,stone)
B(-6,5,1,stone)
B(-6,5,2,stone)
B(-6,5,3,stone)
B(-6,5,4,stone)
B(-6,5,5,LOG:13)
B(-6,5,6,LOG:13)
B(-6,5,7,LOG:13)
B(-6,6,-7,Leaves:7)
B(-6,6,-6,LOG:13)
B(-6,6,-5,concrete:15)
B(-6,6,-4,stone)
B(-6,6,-3,stone)
B(-6,6,-2,stone)
B(-6,6,-1,stone)
B(-6,6,0,stone)
B(-6,6,1,stone)
B(-6,6,2,stone)
B(-6,6,3,stone)
B(-6,6,4,concrete:15)
B(-6,6,5,LOG:13)
B(-6,6,6,LOG:13)
B(-6,7,-5,Leaves:7)
B(-6,7,-4,concrete:15)
B(-6,7,-3,LOG:13)
B(-6,7,-2,concrete:15)
B(-6,7,-1,stone)
B(-6,7,0,stone)
B(-6,7,1,stone)
B(-6,7,2,stone)
B(-6,7,3,concrete:15)
B(-6,7,4,concrete:15)
B(-6,7,5,LOG:13)
B(-6,8,-3,LOG:13)
B(-6,8,-2,LOG:13)
B(-6,8,-1,concrete:15)
B(-6,8,0,concrete:15)
B(-6,8,1,stone)
B(-6,8,2,stone)
B(-6,8,3,concrete:15)
B(-6,8,4,concrete:15)
B(-6,8,5,LOG:13)
B(-6,8,6,LOG:13)
B(-6,9,-3,LOG:13)
B(-6,9,-2,LOG:13)
B(-6,9,-1,LOG:13)
B(-6,9,0,LOG:13)
B(-6,9,1,concrete:15)
B(-6,9,2,concrete:15)
B(-6,9,3,concrete:15)
B(-6,9,4,concrete:15)
B(-6,9,5,LOG:13)
B(-6,10,-2,LOG:13)
B(-6,10,-1,LOG:13)
B(-6,10,0,LOG:13)
B(-6,10,1,LOG:13)
B(-6,10,2,concrete:15)
B(-6,10,3,concrete:15)
B(-6,11,-2,LOG:13)
B(-6,11,-1,LOG:13)
B(-6,11,0,LOG:13)
B(-6,11,1,LOG:13)
B(-6,11,2,concrete:15)
B(-6,12,-1,LOG:13)
B(-6,12,0,LOG:13)
B(-6,12,1,LOG:13)
B(-6,12,2,Leaves:7)
B(-6,13,-2,concrete:15)
B(-6,13,-1,concrete:15)
B(-6,13,0,LOG:13)
B(-6,13,1,LOG:13)
B(-6,13,2,LOG:13)
B(-6,14,0,LOG:13)
B(-6,14,1,LOG:13)
B(-6,15,0,concrete:15)
B(-6,16,-2,stone)
B(-6,16,-1,stone)
B(-6,16,0,concrete:15)
B(-6,16,1,LOG:13)
B(-6,17,-3,stone)
B(-6,17,-2,stone)
B(-6,17,-1,stone)
B(-6,17,0,concrete:15)
B(-6,17,1,concrete:15)
B(-6,18,-3,stone)
B(-6,18,-2,stone)
B(-6,18,-1,stone)
B(-6,18,0,stone)
B(-6,18,1,concrete:15)
B(-6,18,2,concrete:15)
B(-6,18,4,Leaves:7)
B(-6,19,-3,stone)
B(-6,19,-2,stone)
B(-6,19,-1,stone)
B(-6,19,0,stone)
B(-6,19,1,concrete:15)
B(-6,19,2,LOG:13)
B(-6,19,4,Leaves:7)
B(-6,20,-6,stone)
B(-6,20,-5,stone)
B(-6,20,-4,stone)
B(-6,20,-3,stone)
B(-6,20,-2,stone)
B(-6,20,-1,stone)
B(-6,20,0,stone)
B(-6,20,1,concrete:15)
B(-6,20,2,concrete:15)
B(-6,20,3,LOG:13)
B(-6,20,4,LOG:13)
B(-6,20,5,Leaves:7)
B(-6,21,-7,stone)
B(-6,21,-6,stone)
B(-6,21,-5,stone)
B(-6,21,-4,stone)
B(-6,21,-3,stone)
B(-6,21,-2,stone)
B(-6,21,-1,stone)
B(-6,21,0,stone)
B(-6,21,1,stone)
B(-6,21,2,stone)
B(-6,21,3,stone)
B(-6,21,4,LOG:13)
B(-6,21,5,concrete:15)
B(-6,22,-7,stone)
B(-6,22,-6,stone)
B(-6,22,-5,stone)
B(-6,22,-4,stone)
B(-6,22,-3,stone)
B(-6,22,-2,stone)
B(-6,22,-1,stone)
B(-6,22,0,stone)
B(-6,22,1,stone)
B(-6,22,2,stone)
B(-6,22,3,stone)
B(-6,22,4,log)
B(-6,22,5,concrete:15)
B(-6,22,6,concrete:15)
B(-6,22,7,concrete:15)
B(-6,23,-9,stone)
B(-6,23,-8,stone)
B(-6,23,-7,stone)
B(-6,23,-6,stone)
B(-6,23,-5,stone)
B(-6,23,-4,stone)
B(-6,23,-3,stone)
B(-6,23,-2,stone)
B(-6,23,-1,stone)
B(-6,23,0,stone)
B(-6,23,1,stone)
B(-6,23,2,stone)
B(-6,23,3,stone)
B(-6,23,4,LOG:1)
B(-6,23,5,stone)
B(-6,23,6,concrete:15)
B(-6,23,7,concrete:15)
B(-6,23,8,stone)
B(-6,23,9,stone)
B(-6,23,10,stone)
B(-6,24,-10,stone)
B(-6,24,-9,stone)
B(-6,24,-8,stone)
B(-6,24,-7,stone)
B(-6,24,-6,stone)
B(-6,24,-5,stone)
B(-6,24,-4,stone)
B(-6,24,-3,stone)
B(-6,24,-2,stone)
B(-6,24,-1,stone)
B(-6,24,0,stone)
B(-6,24,1,stone)
B(-6,24,2,stone)
B(-6,24,3,stone)
B(-6,24,4,stone)
B(-6,24,5,stone)
B(-6,24,6,stone)
B(-6,24,7,stone)
B(-6,24,8,stone)
B(-6,24,9,stone)
B(-6,24,10,stone)
B(-6,25,-12,stone)
B(-6,25,-11,stone)
B(-6,25,-10,stone)
B(-6,25,-9,stone)
B(-6,25,-8,stone)
B(-6,25,-7,stone)
B(-6,25,-6,stone)
B(-6,25,-5,log2:1)
B(-6,25,-4,stone)
B(-6,25,-3,log2:1)
B(-6,25,-2,LOG:1)
B(-6,25,-1,LOG:1)
B(-6,25,0,stone)
B(-6,25,1,stone)
B(-6,25,2,LOG:1)
B(-6,25,3,stone)
B(-6,25,4,log)
B(-6,25,5,stone)
B(-6,25,6,stone)
B(-6,25,7,stone)
B(-6,25,8,stone)
B(-6,25,9,stone)
B(-6,25,10,stone)
B(-6,25,11,stone)
B(-6,26,-12,stone)
B(-6,26,-11,stone)
B(-6,26,-10,stone)
B(-6,26,-9,stone)
B(-6,26,-8,stone)
B(-6,26,-7,log:2)
B(-6,26,-6,log2:1)
B(-6,26,-5,stone)
B(-6,26,-4,LOG:1)
B(-6,26,-3,LOG:1)
B(-6,26,-2,stone)
B(-6,26,-1,stone)
B(-6,26,0,stone)
B(-6,26,1,stone)
B(-6,26,2,log)
B(-6,26,3,stone)
B(-6,26,4,log)
B(-6,26,5,log)
B(-6,26,6,stone)
B(-6,26,7,stone)
B(-6,26,8,stone)
B(-6,26,9,stone)
B(-6,26,10,stone)
B(-6,27,-11,stone)
B(-6,27,-10,stone)
B(-6,27,-9,stone)
B(-6,27,-8,stone)
B(-6,27,-7,log)
B(-6,27,-6,stone)
B(-6,27,-5,stone)
B(-6,27,-4,stone)
B(-6,27,-3,stone)
B(-6,27,-2,stone)
B(-6,27,-1,stone)
B(-6,27,0,stone)
B(-6,27,1,stone)
B(-6,27,2,stone)
B(-6,27,3,stone)
B(-6,27,4,stone)
B(-6,27,5,stone)
B(-6,27,6,stone)
B(-6,27,7,stone)
B(-6,27,8,stone)
B(-6,27,9,stone)
B(-6,27,10,stone)
B(-5,0,-11,concrete:15)
B(-5,0,-10,concrete:15)
B(-5,0,-9,concrete:15)
B(-5,0,-8,stone)
B(-5,0,-7,stone)
B(-5,0,-6,stone)
B(-5,0,-5,stone)
B(-5,0,-4,stone)
B(-5,0,-3,stone)
B(-5,0,-2,stone)
B(-5,0,-1,stone)
B(-5,0,0,stone)
B(-5,0,1,stone)
B(-5,0,2,stone)
B(-5,0,3,stone)
B(-5,0,4,stone)
B(-5,0,5,stone)
B(-5,0,6,stone)
B(-5,0,7,stone)
B(-5,0,8,stone)
B(-5,0,9,stone)
B(-5,0,10,stone)
B(-5,0,11,stone)
B(-5,0,12,concrete:15)
B(-5,1,-10,concrete:15)
B(-5,1,-9,concrete:15)
B(-5,1,-8,concrete:15)
B(-5,1,-7,stone)
B(-5,1,-6,stone)
B(-5,1,-5,stone)
B(-5,1,-4,stone)
B(-5,1,-3,stone)
B(-5,1,-2,stone)
B(-5,1,-1,stone)
B(-5,1,0,stone)
B(-5,1,1,stone)
B(-5,1,2,stone)
B(-5,1,3,stone)
B(-5,1,4,stone)
B(-5,1,5,stone)
B(-5,1,6,stone)
B(-5,1,7,stone)
B(-5,1,8,stone)
B(-5,1,9,stone)
B(-5,1,10,stone)
B(-5,2,-9,LOG:13)
B(-5,2,-8,LOG:13)
B(-5,2,-7,stone)
B(-5,2,-6,stone)
B(-5,2,-5,stone)
B(-5,2,-4,stone)
B(-5,2,-3,stone)
B(-5,2,-2,stone)
B(-5,2,-1,stone)
B(-5,2,0,stone)
B(-5,2,1,stone)
B(-5,2,2,stone)
B(-5,2,3,stone)
B(-5,2,4,stone)
B(-5,2,5,stone)
B(-5,2,6,stone)
B(-5,2,7,stone)
B(-5,2,8,stone)
B(-5,2,9,stone)
B(-5,3,-9,LOG:13)
B(-5,3,-8,LOG:13)
B(-5,3,-7,stone)
B(-5,3,-6,stone)
B(-5,3,-5,log2)
B(-5,3,-4,log2)
B(-5,3,-3,stone)
B(-5,3,-2,stone)
B(-5,3,-1,stone)
B(-5,3,0,log2)
B(-5,3,1,log)
B(-5,3,2,stone)
B(-5,3,3,stone)
B(-5,3,4,stone)
B(-5,3,5,stone)
B(-5,3,6,stone)
B(-5,3,7,stone)
B(-5,3,8,stone)
B(-5,4,-9,LOG:13)
B(-5,4,-8,LOG:13)
B(-5,4,-7,concrete:15)
B(-5,4,-6,stone)
B(-5,4,-5,stone)
B(-5,4,-4,stone)
B(-5,4,-3,stone)
B(-5,4,-2,stone)
B(-5,4,-1,stone)
B(-5,4,0,stone)
B(-5,4,1,stone)
B(-5,4,2,stone)
B(-5,4,3,stone)
B(-5,4,4,stone)
B(-5,4,5,stone)
B(-5,4,6,stone)
B(-5,4,7,concrete:15)
B(-5,4,8,stone)
B(-5,5,-8,LOG:13)
B(-5,5,-7,LOG:13)
B(-5,5,-6,concrete:15)
B(-5,5,-5,stone)
B(-5,5,-4,stone)
B(-5,5,-3,stone)
B(-5,5,-2,stone)
B(-5,5,-1,stone)
B(-5,5,0,stone)
B(-5,5,1,log2)
B(-5,5,2,stone)
B(-5,5,3,stone)
B(-5,5,4,stone)
B(-5,5,5,stone)
B(-5,5,6,LOG:13)
B(-5,5,7,concrete:15)
B(-5,5,8,concrete:15)
B(-5,6,-8,Leaves:7)
B(-5,6,-7,LOG:13)
B(-5,6,-6,LOG:13)
B(-5,6,-5,LOG:13)
B(-5,6,-4,concrete:15)
B(-5,6,-3,stone)
B(-5,6,-2,stone)
B(-5,6,-1,stone)
B(-5,6,0,stone)
B(-5,6,1,stone)
B(-5,6,2,stone)
B(-5,6,3,stone)
B(-5,6,4,stone)
B(-5,6,5,LOG:13)
B(-5,6,6,LOG:13)
B(-5,6,7,LOG:13)
B(-5,7,-7,LOG:13)
B(-5,7,-6,LOG:13)
B(-5,7,-5,LOG:13)
B(-5,7,-4,LOG:13)
B(-5,7,-3,LOG:13)
B(-5,7,-2,LOG:13)
B(-5,7,-1,stone)
B(-5,7,0,stone)
B(-5,7,1,stone)
B(-5,7,2,stone)
B(-5,7,3,stone)
B(-5,7,4,concrete:15)
B(-5,7,5,concrete:15)
B(-5,7,6,LOG:13)
B(-5,7,7,concrete:15)
B(-5,8,-5,Leaves:7)
B(-5,8,-3,LOG:13)
B(-5,8,-2,LOG:13)
B(-5,8,-1,stone)
B(-5,8,0,stone)
B(-5,8,1,log2:1)
B(-5,8,2,stone)
B(-5,8,3,concrete:15)
B(-5,8,4,concrete:15)
B(-5,8,5,LOG:13)
B(-5,8,6,LOG:13)
B(-5,8,7,LOG:13)
B(-5,9,-3,LOG:13)
B(-5,9,-2,LOG:13)
B(-5,9,-1,LOG:13)
B(-5,9,0,stone)
B(-5,9,1,stone)
B(-5,9,2,stone)
B(-5,9,3,concrete:15)
B(-5,9,4,LOG:13)
B(-5,9,5,LOG:13)
B(-5,9,6,LOG:13)
B(-5,10,-2,LOG:13)
B(-5,10,-1,LOG:13)
B(-5,10,0,LOG:13)
B(-5,10,1,stone)
B(-5,10,2,concrete:15)
B(-5,10,3,LOG:13)
B(-5,10,4,LOG:13)
B(-5,10,5,LOG:13)
B(-5,11,-2,concrete:15)
B(-5,11,-1,LOG:13)
B(-5,11,0,LOG:13)
B(-5,11,1,LOG:13)
B(-5,11,2,concrete:15)
B(-5,11,3,LOG:13)
B(-5,11,4,LOG:13)
B(-5,11,5,Leaves:7)
B(-5,12,-2,concrete:15)
B(-5,12,-1,concrete:15)
B(-5,12,0,LOG:13)
B(-5,12,1,LOG:13)
B(-5,12,2,concrete:15)
B(-5,12,3,LOG:13)
B(-5,12,4,LOG:13)
B(-5,13,-2,concrete:15)
B(-5,13,-1,concrete:15)
B(-5,13,0,LOG:13)
B(-5,13,1,LOG:13)
B(-5,13,2,LOG:13)
B(-5,13,3,LOG:13)
B(-5,14,-1,concrete:15)
B(-5,14,0,concrete:15)
B(-5,14,1,LOG:13)
B(-5,14,2,LOG:13)
B(-5,14,3,LOG:13)
B(-5,14,4,LOG:13)
B(-5,15,-2,stone)
B(-5,15,-1,stone)
B(-5,15,0,concrete:15)
B(-5,15,1,LOG:13)
B(-5,15,3,LOG:13)
B(-5,15,4,LOG:13)
B(-5,16,-3,stone)
B(-5,16,-2,stone)
B(-5,16,-1,stone)
B(-5,16,0,concrete:15)
B(-5,16,1,LOG:13)
B(-5,16,2,LOG:13)
B(-5,17,-3,stone)
B(-5,17,-2,stone)
B(-5,17,-1,stone)
B(-5,17,0,stone)
B(-5,17,1,LOG:13)
B(-5,17,2,LOG:13)
B(-5,17,3,LOG:13)
B(-5,17,4,Leaves:7)
B(-5,18,-4,stone)
B(-5,18,-3,stone)
B(-5,18,-2,stone)
B(-5,18,-1,stone)
B(-5,18,0,stone)
B(-5,18,1,concrete:15)
B(-5,18,2,LOG:13)
B(-5,18,3,LOG:13)
B(-5,18,4,LOG:13)
B(-5,18,5,Leaves:7)
B(-5,19,-5,stone)
B(-5,19,-4,stone)
B(-5,19,-3,stone)
B(-5,19,-2,stone)
B(-5,19,-1,stone)
B(-5,19,0,stone)
B(-5,19,1,concrete:15)
B(-5,19,2,LOG:13)
B(-5,19,3,LOG:13)
B(-5,19,4,LOG:13)
B(-5,20,-6,stone)
B(-5,20,-5,stone)
B(-5,20,-4,stone)
B(-5,20,-3,stone)
B(-5,20,-2,stone)
B(-5,20,-1,stone)
B(-5,20,0,stone)
B(-5,20,1,stone)
B(-5,20,2,LOG:13)
B(-5,20,3,LOG:13)
B(-5,20,4,LOG:13)
B(-5,21,-7,stone)
B(-5,21,-6,stone)
B(-5,21,-5,stone)
B(-5,21,-4,stone)
B(-5,21,-3,stone)
B(-5,21,-2,stone)
B(-5,21,-1,stone)
B(-5,21,0,stone)
B(-5,21,1,stone)
B(-5,21,2,stone)
B(-5,21,3,stone)
B(-5,21,4,stone)
B(-5,21,5,stone)
B(-5,22,-9,stone)
B(-5,22,-8,stone)
B(-5,22,-7,stone)
B(-5,22,-6,stone)
B(-5,22,-5,stone)
B(-5,22,-4,stone)
B(-5,22,-3,stone)
B(-5,22,-2,stone)
B(-5,22,-1,stone)
B(-5,22,0,stone)
B(-5,22,1,stone)
B(-5,22,2,log2:1)
B(-5,22,3,stone)
B(-5,22,4,stone)
B(-5,22,5,concrete:15)
B(-5,22,6,concrete:15)
B(-5,22,7,concrete:15)
B(-5,22,8,stone)
B(-5,23,-10,stone)
B(-5,23,-9,stone)
B(-5,23,-8,stone)
B(-5,23,-7,stone)
B(-5,23,-6,stone)
B(-5,23,-5,stone)
B(-5,23,-4,stone)
B(-5,23,-3,stone)
B(-5,23,-2,stone)
B(-5,23,-1,stone)
B(-5,23,0,stone)
B(-5,23,1,log2:1)
B(-5,23,2,stone)
B(-5,23,3,stone)
B(-5,23,4,stone)
B(-5,23,5,stone)
B(-5,23,6,log2)
B(-5,23,7,stone)
B(-5,23,8,stone)
B(-5,23,9,stone)
B(-5,23,10,stone)
B(-5,24,-10,stone)
B(-5,24,-9,stone)
B(-5,24,-8,stone)
B(-5,24,-7,stone)
B(-5,24,-6,stone)
B(-5,24,-5,stone)
B(-5,24,-4,stone)
B(-5,24,-3,stone)
B(-5,24,-2,stone)
B(-5,24,-1,log2:1)
B(-5,24,0,stone)
B(-5,24,1,stone)
B(-5,24,2,stone)
B(-5,24,3,stone)
B(-5,24,4,stone)
B(-5,24,5,stone)
B(-5,24,6,stone)
B(-5,24,7,stone)
B(-5,24,8,stone)
B(-5,24,9,stone)
B(-5,24,10,stone)
B(-5,24,11,concrete:15)
B(-5,25,-12,stone)
B(-5,25,-11,stone)
B(-5,25,-10,stone)
B(-5,25,-9,stone)
B(-5,25,-8,stone)
B(-5,25,-7,log:2)
B(-5,25,-6,stone)
B(-5,25,-5,log)
B(-5,25,-4,stone)
B(-5,25,-3,stone)
B(-5,25,-2,stone)
B(-5,25,-1,stone)
B(-5,25,0,LOG:1)
B(-5,25,1,stone)
B(-5,25,2,log)
B(-5,25,3,stone)
B(-5,25,4,LOG:1)
B(-5,25,5,stone)
B(-5,25,6,stone)
B(-5,25,7,stone)
B(-5,25,8,stone)
B(-5,25,9,stone)
B(-5,25,10,concrete:15)
B(-5,25,11,concrete:15)
B(-5,26,-12,stone)
B(-5,26,-11,stone)
B(-5,26,-10,stone)
B(-5,26,-9,stone)
B(-5,26,-8,stone)
B(-5,26,-7,log)
B(-5,26,-6,stone)
B(-5,26,-5,stone)
B(-5,26,-4,stone)
B(-5,26,-3,stone)
B(-5,26,-2,stone)
B(-5,26,-1,stone)
B(-5,26,0,stone)
B(-5,26,1,stone)
B(-5,26,2,stone)
B(-5,26,3,log)
B(-5,26,4,stone)
B(-5,26,5,stone)
B(-5,26,6,stone)
B(-5,26,7,stone)
B(-5,26,8,stone)
B(-5,26,9,stone)
B(-5,26,10,stone)
B(-5,26,11,concrete:15)
B(-5,27,-12,stone)
B(-5,27,-11,stone)
B(-5,27,-10,stone)
B(-5,27,-9,stone)
B(-5,27,-8,stone)
B(-5,27,-7,stone)
B(-5,27,-6,stone)
B(-5,27,-5,log2:1)
B(-5,27,-4,stone)
B(-5,27,-3,stone)
B(-5,27,-2,stone)
B(-5,27,-1,stone)
B(-5,27,0,stone)
B(-5,27,1,log)
B(-5,27,2,stone)
B(-5,27,3,log2)
B(-5,27,4,stone)
B(-5,27,5,log)
B(-5,27,6,stone)
B(-5,27,7,log:2)
B(-5,27,8,stone)
B(-5,27,9,stone)
B(-5,27,10,stone)
B(-5,27,11,stone)
B(-4,0,-12,stone)
B(-4,0,-11,stone)
B(-4,0,-10,concrete:15)
B(-4,0,-9,stone)
B(-4,0,-8,stone)
B(-4,0,-7,stone)
B(-4,0,-6,stone)
B(-4,0,-5,stone)
B(-4,0,-4,stone)
B(-4,0,-3,stone)
B(-4,0,-2,stone)
B(-4,0,-1,stone)
B(-4,0,0,stone)
B(-4,0,1,stone)
B(-4,0,2,stone)
B(-4,0,3,stone)
B(-4,0,4,stone)
B(-4,0,5,stone)
B(-4,0,6,stone)
B(-4,0,7,stone)
B(-4,0,8,stone)
B(-4,0,9,stone)
B(-4,0,10,stone)
B(-4,0,11,concrete:15)
B(-4,0,12,LOG:13)
B(-4,0,13,LOG:13)
B(-4,1,-10,concrete:15)
B(-4,1,-9,concrete:15)
B(-4,1,-8,stone)
B(-4,1,-7,stone)
B(-4,1,-6,stone)
B(-4,1,-5,stone)
B(-4,1,-4,stone)
B(-4,1,-3,stone)
B(-4,1,-2,stone)
B(-4,1,-1,stone)
B(-4,1,0,stone)
B(-4,1,1,stone)
B(-4,1,2,stone)
B(-4,1,3,stone)
B(-4,1,4,stone)
B(-4,1,5,stone)
B(-4,1,6,stone)
B(-4,1,7,stone)
B(-4,1,8,stone)
B(-4,1,9,stone)
B(-4,1,10,stone)
B(-4,1,11,concrete:15)
B(-4,2,-10,concrete:15)
B(-4,2,-9,LOG:13)
B(-4,2,-8,concrete:15)
B(-4,2,-7,stone)
B(-4,2,-6,stone)
B(-4,2,-5,stone)
B(-4,2,-4,stone)
B(-4,2,-3,stone)
B(-4,2,-2,stone)
B(-4,2,-1,log2:1)
B(-4,2,0,log:2)
B(-4,2,1,stone)
B(-4,2,2,stone)
B(-4,2,3,stone)
B(-4,2,4,stone)
B(-4,2,5,stone)
B(-4,2,6,stone)
B(-4,2,7,stone)
B(-4,2,8,stone)
B(-4,2,9,stone)
B(-4,2,10,concrete:15)
B(-4,2,11,concrete:15)
B(-4,3,-9,LOG:13)
B(-4,3,-8,LOG:13)
B(-4,3,-7,stone)
B(-4,3,-6,stone)
B(-4,3,-5,stone)
B(-4,3,-4,stone)
B(-4,3,-3,log2)
B(-4,3,-2,log2:1)
B(-4,3,-1,log2:1)
B(-4,3,0,stone)
B(-4,3,1,log)
B(-4,3,2,stone)
B(-4,3,3,log2)
B(-4,3,4,stone)
B(-4,3,5,LOG:1)
B(-4,3,6,stone)
B(-4,3,7,stone)
B(-4,3,8,stone)
B(-4,3,9,stone)
B(-4,4,-9,LOG:13)
B(-4,4,-8,LOG:13)
B(-4,4,-7,LOG:13)
B(-4,4,-6,stone)
B(-4,4,-5,log:2)
B(-4,4,-4,log)
B(-4,4,-3,stone)
B(-4,4,-2,stone)
B(-4,4,-1,stone)
B(-4,4,0,log2)
B(-4,4,1,log:2)
B(-4,4,2,stone)
B(-4,4,3,stone)
B(-4,4,4,stone)
B(-4,4,5,stone)
B(-4,4,6,stone)
B(-4,4,7,stone)
B(-4,4,8,stone)
B(-4,4,9,stone)
B(-4,5,-8,LOG:13)
B(-4,5,-7,LOG:13)
B(-4,5,-6,stone)
B(-4,5,-5,stone)
B(-4,5,-4,stone)
B(-4,5,-3,stone)
B(-4,5,-2,stone)
B(-4,5,-1,stone)
B(-4,5,0,stone)
B(-4,5,1,stone)
B(-4,5,2,stone)
B(-4,5,3,stone)
B(-4,5,4,stone)
B(-4,5,5,stone)
B(-4,5,6,stone)
B(-4,5,7,concrete:15)
B(-4,5,8,stone)
B(-4,6,-7,LOG:13)
B(-4,6,-6,LOG:13)
B(-4,6,-5,concrete:15)
B(-4,6,-4,stone)
B(-4,6,-3,stone)
B(-4,6,-2,log:2)
B(-4,6,-1,log2:1)
B(-4,6,0,log2)
B(-4,6,1,log2)
B(-4,6,2,stone)
B(-4,6,3,stone)
B(-4,6,4,stone)
B(-4,6,5,stone)
B(-4,6,6,concrete:15)
B(-4,6,7,concrete:15)
B(-4,6,8,concrete:15)
B(-4,7,-7,LOG:13)
B(-4,7,-6,LOG:13)
B(-4,7,-5,LOG:13)
B(-4,7,-4,concrete:15)
B(-4,7,-3,LOG:13)
B(-4,7,-2,stone)
B(-4,7,-1,stone)
B(-4,7,0,stone)
B(-4,7,1,stone)
B(-4,7,2,stone)
B(-4,7,3,stone)
B(-4,7,4,stone)
B(-4,7,5,stone)
B(-4,7,6,concrete:15)
B(-4,7,7,concrete:15)
B(-4,8,-6,LOG:13)
B(-4,8,-5,concrete:15)
B(-4,8,-4,LOG:13)
B(-4,8,-3,LOG:13)
B(-4,8,-2,LOG:13)
B(-4,8,-1,stone)
B(-4,8,0,stone)
B(-4,8,1,stone)
B(-4,8,2,stone)
B(-4,8,3,stone)
B(-4,8,4,stone)
B(-4,8,5,concrete:15)
B(-4,8,6,concrete:15)
B(-4,8,7,concrete:15)
B(-4,9,-6,concrete:15)
B(-4,9,-5,concrete:15)
B(-4,9,-4,concrete:15)
B(-4,9,-3,LOG:13)
B(-4,9,-2,concrete:15)
B(-4,9,-1,stone)
B(-4,9,0,stone)
B(-4,9,1,stone)
B(-4,9,2,stone)
B(-4,9,3,LOG:13)
B(-4,9,4,LOG:13)
B(-4,9,5,LOG:13)
B(-4,9,6,concrete:15)
B(-4,10,-5,concrete:15)
B(-4,10,-4,concrete:15)
B(-4,10,-3,concrete:15)
B(-4,10,-2,concrete:15)
B(-4,10,-1,log)
B(-4,10,0,stone)
B(-4,10,1,stone)
B(-4,10,2,stone)
B(-4,10,3,LOG:13)
B(-4,10,4,LOG:13)
B(-4,10,5,LOG:13)
B(-4,11,-5,concrete:15)
B(-4,11,-4,concrete:15)
B(-4,11,-3,concrete:15)
B(-4,11,-2,concrete:15)
B(-4,11,-1,concrete:15)
B(-4,11,0,stone)
B(-4,11,1,stone)
B(-4,11,2,concrete:15)
B(-4,11,3,LOG:13)
B(-4,11,4,LOG:13)
B(-4,11,5,LOG:13)
B(-4,11,6,Leaves:7)
B(-4,12,-2,concrete:15)
B(-4,12,-1,concrete:15)
B(-4,12,0,stone)
B(-4,12,1,concrete:15)
B(-4,12,2,concrete:15)
B(-4,12,3,LOG:13)
B(-4,12,4,LOG:13)
B(-4,12,5,LOG:13)
B(-4,13,-4,stone)
B(-4,13,-3,stone)
B(-4,13,-2,concrete:15)
B(-4,13,-1,stone)
B(-4,13,0,stone)
B(-4,13,1,stone)
B(-4,13,2,LOG:13)
B(-4,13,3,stone)
B(-4,13,4,LOG:13)
B(-4,14,-4,stone)
B(-4,14,-3,stone)
B(-4,14,-2,stone)
B(-4,14,-1,stone)
B(-4,14,0,stone)
B(-4,14,1,LOG:13)
B(-4,14,2,LOG:13)
B(-4,14,3,LOG:13)
B(-4,14,4,LOG:13)
B(-4,15,-4,stone)
B(-4,15,-3,stone)
B(-4,15,-2,stone)
B(-4,15,-1,stone)
B(-4,15,0,stone)
B(-4,15,1,stone)
B(-4,15,2,LOG:13)
B(-4,15,3,stone)
B(-4,15,4,LOG:13)
B(-4,15,5,Leaves:7)
B(-4,16,-3,stone)
B(-4,16,-2,stone)
B(-4,16,-1,stone)
B(-4,16,0,stone)
B(-4,16,1,LOG:13)
B(-4,16,2,LOG:13)
B(-4,16,3,LOG:13)
B(-4,16,4,concrete:15)
B(-4,17,-3,stone)
B(-4,17,-2,stone)
B(-4,17,-1,stone)
B(-4,17,0,stone)
B(-4,17,1,stone)
B(-4,17,2,LOG:13)
B(-4,17,3,LOG:13)
B(-4,17,4,LOG:13)
B(-4,18,-4,stone)
B(-4,18,-3,stone)
B(-4,18,-2,stone)
B(-4,18,-1,stone)
B(-4,18,0,stone)
B(-4,18,1,stone)
B(-4,18,2,stone)
B(-4,18,3,LOG:13)
B(-4,18,4,LOG:13)
B(-4,19,-5,stone)
B(-4,19,-4,stone)
B(-4,19,-3,log)
B(-4,19,-2,stone)
B(-4,19,-1,stone)
B(-4,19,0,stone)
B(-4,19,1,stone)
B(-4,19,2,LOG:13)
B(-4,19,3,LOG:13)
B(-4,19,4,LOG:13)
B(-4,19,5,LOG:13)
B(-4,20,-6,stone)
B(-4,20,-5,stone)
B(-4,20,-4,stone)
B(-4,20,-3,stone)
B(-4,20,-2,log2:1)
B(-4,20,-1,stone)
B(-4,20,0,stone)
B(-4,20,1,stone)
B(-4,20,2,stone)
B(-4,20,3,LOG:13)
B(-4,20,4,LOG:13)
B(-4,20,5,concrete:15)
B(-4,21,-7,stone)
B(-4,21,-6,stone)
B(-4,21,-5,stone)
B(-4,21,-4,log2:1)
B(-4,21,-3,stone)
B(-4,21,-2,log:2)
B(-4,21,-1,stone)
B(-4,21,0,stone)
B(-4,21,1,stone)
B(-4,21,2,stone)
B(-4,21,3,stone)
B(-4,21,4,stone)
B(-4,21,5,concrete:15)
B(-4,21,6,concrete:15)
B(-4,21,8,stone)
B(-4,22,-9,stone)
B(-4,22,-8,stone)
B(-4,22,-7,stone)
B(-4,22,-6,stone)
B(-4,22,-5,stone)
B(-4,22,-4,stone)
B(-4,22,-3,stone)
B(-4,22,-2,LOG:1)
B(-4,22,-1,stone)
B(-4,22,0,stone)
B(-4,22,1,log:2)
B(-4,22,2,LOG:1)
B(-4,22,3,stone)
B(-4,22,4,stone)
B(-4,22,5,stone)
B(-4,22,6,stone)
B(-4,22,7,stone)
B(-4,22,8,concrete:15)
B(-4,22,9,concrete:15)
B(-4,23,-9,stone)
B(-4,23,-8,stone)
B(-4,23,-7,stone)
B(-4,23,-6,stone)
B(-4,23,-5,stone)
B(-4,23,-4,log)
B(-4,23,-3,LOG:1)
B(-4,23,-2,log)
B(-4,23,-1,stone)
B(-4,23,0,stone)
B(-4,23,1,log2)
B(-4,23,2,stone)
B(-4,23,3,stone)
B(-4,23,4,stone)
B(-4,23,5,stone)
B(-4,23,6,stone)
B(-4,23,7,stone)
B(-4,23,8,stone)
B(-4,23,9,concrete:15)
B(-4,23,10,concrete:15)
B(-4,24,-11,stone)
B(-4,24,-10,stone)
B(-4,24,-9,stone)
B(-4,24,-8,stone)
B(-4,24,-7,stone)
B(-4,24,-6,stone)
B(-4,24,-5,stone)
B(-4,24,-4,stone)
B(-4,24,-3,LOG:1)
B(-4,24,-2,stone)
B(-4,24,-1,stone)
B(-4,24,0,stone)
B(-4,24,1,stone)
B(-4,24,2,stone)
B(-4,24,3,log:2)
B(-4,24,4,stone)
B(-4,24,5,stone)
B(-4,24,6,stone)
B(-4,24,7,stone)
B(-4,24,8,stone)
B(-4,24,9,stone)
B(-4,24,10,concrete:15)
B(-4,24,11,concrete:15)
B(-4,25,-13,stone)
B(-4,25,-12,stone)
B(-4,25,-11,stone)
B(-4,25,-10,stone)
B(-4,25,-9,stone)
B(-4,25,-8,stone)
B(-4,25,-7,stone)
B(-4,25,-6,stone)
B(-4,25,-5,stone)
B(-4,25,-4,stone)
B(-4,25,-3,stone)
B(-4,25,-2,log:2)
B(-4,25,-1,stone)
B(-4,25,0,stone)
B(-4,25,1,stone)
B(-4,25,2,log:2)
B(-4,25,3,stone)
B(-4,25,4,log)
B(-4,25,5,log2:1)
B(-4,25,6,stone)
B(-4,25,7,stone)
B(-4,25,8,stone)
B(-4,25,9,stone)
B(-4,25,10,concrete:15)
B(-4,25,11,concrete:15)
B(-4,26,-13,stone)
B(-4,26,-12,stone)
B(-4,26,-11,stone)
B(-4,26,-10,stone)
B(-4,26,-9,stone)
B(-4,26,-8,stone)
B(-4,26,-7,stone)
B(-4,26,-6,log2:1)
B(-4,26,-5,stone)
B(-4,26,-4,log2)
B(-4,26,-3,stone)
B(-4,26,-2,stone)
B(-4,26,-1,stone)
B(-4,26,0,log2)
B(-4,26,1,stone)
B(-4,26,2,stone)
B(-4,26,3,stone)
B(-4,26,4,stone)
B(-4,26,5,log2)
B(-4,26,6,stone)
B(-4,26,7,stone)
B(-4,26,8,stone)
B(-4,26,9,stone)
B(-4,26,10,concrete:15)
B(-4,26,11,concrete:15)
B(-4,27,-11,stone)
B(-4,27,-10,stone)
B(-4,27,-9,stone)
B(-4,27,-8,stone)
B(-4,27,-7,stone)
B(-4,27,-6,log2:1)
B(-4,27,-5,log:2)
B(-4,27,-4,LOG:1)
B(-4,27,-3,stone)
B(-4,27,-2,log2)
B(-4,27,-1,stone)
B(-4,27,0,stone)
B(-4,27,1,stone)
B(-4,27,2,stone)
B(-4,27,3,log)
B(-4,27,4,log)
B(-4,27,5,stone)
B(-4,27,6,log:2)
B(-4,27,7,stone)
B(-4,27,8,stone)
B(-4,27,9,stone)
B(-4,27,10,stone)
B(-4,27,11,stone)
B(-3,0,-12,stone)
B(-3,0,-11,stone)
B(-3,0,-10,stone)
B(-3,0,-9,stone)
B(-3,0,-8,stone)
B(-3,0,-7,stone)
B(-3,0,-6,stone)
B(-3,0,-5,stone)
B(-3,0,-4,stone)
B(-3,0,-3,stone)
B(-3,0,-2,stone)
B(-3,0,-1,stone)
B(-3,0,0,stone)
B(-3,0,1,stone)
B(-3,0,2,stone)
B(-3,0,3,stone)
B(-3,0,4,stone)
B(-3,0,5,stone)
B(-3,0,6,stone)
B(-3,0,7,stone)
B(-3,0,8,stone)
B(-3,0,9,stone)
B(-3,0,10,stone)
B(-3,0,11,concrete:15)
B(-3,0,12,LOG:13)
B(-3,0,13,LOG:13)
B(-3,0,14,Leaves:7)
B(-3,1,-11,stone)
B(-3,1,-10,stone)
B(-3,1,-9,stone)
B(-3,1,-8,stone)
B(-3,1,-7,stone)
B(-3,1,-6,stone)
B(-3,1,-5,stone)
B(-3,1,-4,stone)
B(-3,1,-3,stone)
B(-3,1,-2,stone)
B(-3,1,-1,stone)
B(-3,1,0,stone)
B(-3,1,1,stone)
B(-3,1,2,stone)
B(-3,1,3,stone)
B(-3,1,4,stone)
B(-3,1,5,stone)
B(-3,1,6,stone)
B(-3,1,7,stone)
B(-3,1,8,stone)
B(-3,1,9,stone)
B(-3,1,10,concrete:15)
B(-3,1,11,concrete:15)
B(-3,1,12,LOG:13)
B(-3,1,13,Leaves:7)
B(-3,2,-10,stone)
B(-3,2,-9,stone)
B(-3,2,-8,stone)
B(-3,2,-7,stone)
B(-3,2,-6,stone)
B(-3,2,-5,stone)
B(-3,2,-4,log)
B(-3,2,-3,stone)
B(-3,2,-2,log:2)
B(-3,2,-1,stone)
B(-3,2,0,stone)
B(-3,2,1,log)
B(-3,2,2,stone)
B(-3,2,3,stone)
B(-3,2,4,stone)
B(-3,2,5,log2)
B(-3,2,6,stone)
B(-3,2,7,stone)
B(-3,2,8,stone)
B(-3,2,9,stone)
B(-3,2,10,concrete:15)
B(-3,2,11,LOG:13)
B(-3,3,-10,concrete:15)
B(-3,3,-9,concrete:15)
B(-3,3,-8,concrete:15)
B(-3,3,-7,stone)
B(-3,3,-6,log:2)
B(-3,3,-5,stone)
B(-3,3,-4,log2)
B(-3,3,-3,stone)
B(-3,3,-2,log2:1)
B(-3,3,-1,log2)
B(-3,3,0,stone)
B(-3,3,1,log:2)
B(-3,3,2,stone)
B(-3,3,3,stone)
B(-3,3,4,log2:1)
B(-3,3,5,stone)
B(-3,3,6,stone)
B(-3,3,7,stone)
B(-3,3,8,stone)
B(-3,3,9,stone)
B(-3,3,10,concrete:15)
B(-3,4,-9,concrete:15)
B(-3,4,-8,LOG:13)
B(-3,4,-7,concrete:15)
B(-3,4,-6,stone)
B(-3,4,-5,stone)
B(-3,4,-4,stone)
B(-3,4,-3,stone)
B(-3,4,-2,stone)
B(-3,4,-1,log)
B(-3,4,0,stone)
B(-3,4,1,log:2)
B(-3,4,2,stone)
B(-3,4,3,stone)
B(-3,4,4,stone)
B(-3,4,5,log)
B(-3,4,6,stone)
B(-3,4,7,stone)
B(-3,4,8,stone)
B(-3,4,9,concrete:15)
B(-3,5,-8,LOG:13)
B(-3,5,-7,LOG:13)
B(-3,5,-6,stone)
B(-3,5,-5,stone)
B(-3,5,-4,stone)
B(-3,5,-3,log2:1)
B(-3,5,-2,stone)
B(-3,5,-1,log)
B(-3,5,0,stone)
B(-3,5,1,stone)
B(-3,5,2,stone)
B(-3,5,3,stone)
B(-3,5,4,stone)
B(-3,5,5,stone)
B(-3,5,6,stone)
B(-3,5,7,stone)
B(-3,5,8,stone)
B(-3,5,9,stone)
B(-3,6,-8,LOG:13)
B(-3,6,-7,LOG:13)
B(-3,6,-6,LOG:13)
B(-3,6,-5,stone)
B(-3,6,-4,stone)
B(-3,6,-3,log2:1)
B(-3,6,-2,log2)
B(-3,6,-1,log2:1)
B(-3,6,0,stone)
B(-3,6,1,stone)
B(-3,6,2,log:2)
B(-3,6,3,log2)
B(-3,6,4,stone)
B(-3,6,5,stone)
B(-3,6,6,stone)
B(-3,6,7,stone)
B(-3,6,8,stone)
B(-3,6,9,stone)
B(-3,7,-8,Leaves:7)
B(-3,7,-7,LOG:13)
B(-3,7,-6,LOG:13)
B(-3,7,-5,log2:1)
B(-3,7,-4,concrete:15)
B(-3,7,-3,log2:1)
B(-3,7,-2,stone)
B(-3,7,-1,stone)
B(-3,7,0,stone)
B(-3,7,1,stone)
B(-3,7,2,LOG:1)
B(-3,7,3,stone)
B(-3,7,4,stone)
B(-3,7,5,stone)
B(-3,7,6,stone)
B(-3,7,7,stone)
B(-3,8,-7,Leaves:7)
B(-3,8,-6,LOG:13)
B(-3,8,-5,concrete:15)
B(-3,8,-4,concrete:15)
B(-3,8,-3,concrete:15)
B(-3,8,-2,stone)
B(-3,8,-1,log:2)
B(-3,8,0,log:2)
B(-3,8,1,stone)
B(-3,8,2,stone)
B(-3,8,3,stone)
B(-3,8,4,stone)
B(-3,8,5,stone)
B(-3,8,6,concrete:15)
B(-3,8,7,stone)
B(-3,9,-6,concrete:15)
B(-3,9,-5,concrete:15)
B(-3,9,-4,concrete:15)
B(-3,9,-3,concrete:15)
B(-3,9,-2,stone)
B(-3,9,-1,stone)
B(-3,9,0,log2:1)
B(-3,9,1,log:2)
B(-3,9,2,stone)
B(-3,9,3,stone)
B(-3,9,4,LOG:13)
B(-3,9,5,concrete:15)
B(-3,9,6,concrete:15)
B(-3,10,-6,concrete:15)
B(-3,10,-5,concrete:15)
B(-3,10,-4,concrete:15)
B(-3,10,-3,concrete:15)
B(-3,10,-2,concrete:15)
B(-3,10,-1,log)
B(-3,10,0,stone)
B(-3,10,1,stone)
B(-3,10,2,stone)
B(-3,10,3,LOG:13)
B(-3,10,4,LOG:13)
B(-3,10,5,LOG:13)
B(-3,11,-5,concrete:15)
B(-3,11,-4,concrete:15)
B(-3,11,-3,concrete:15)
B(-3,11,-2,stone)
B(-3,11,-1,stone)
B(-3,11,0,stone)
B(-3,11,1,log:2)
B(-3,11,2,stone)
B(-3,11,3,stone)
B(-3,11,4,LOG:13)
B(-3,11,5,concrete:15)
B(-3,12,-5,concrete:15)
B(-3,12,-4,concrete:15)
B(-3,12,-3,stone)
B(-3,12,-2,stone)
B(-3,12,-1,stone)
B(-3,12,0,stone)
B(-3,12,1,log)
B(-3,12,2,stone)
B(-3,12,3,stone)
B(-3,12,4,concrete:15)
B(-3,12,5,concrete:15)
B(-3,13,-4,concrete:15)
B(-3,13,-3,concrete:15)
B(-3,13,-2,stone)
B(-3,13,-1,stone)
B(-3,13,0,stone)
B(-3,13,1,stone)
B(-3,13,2,stone)
B(-3,13,3,concrete:15)
B(-3,13,4,concrete:15)
B(-3,13,5,concrete:15)
B(-3,14,-4,concrete:15)
B(-3,14,-3,stone)
B(-3,14,-2,stone)
B(-3,14,-1,stone)
B(-3,14,0,stone)
B(-3,14,1,stone)
B(-3,14,2,stone)
B(-3,14,3,concrete:15)
B(-3,14,4,concrete:15)
B(-3,15,-4,concrete:15)
B(-3,15,-3,stone)
B(-3,15,-2,stone)
B(-3,15,-1,stone)
B(-3,15,0,stone)
B(-3,15,1,stone)
B(-3,15,2,stone)
B(-3,15,3,concrete:15)
B(-3,15,4,concrete:15)
B(-3,16,-4,stone)
B(-3,16,-3,stone)
B(-3,16,-2,stone)
B(-3,16,-1,stone)
B(-3,16,0,stone)
B(-3,16,1,stone)
B(-3,16,2,stone)
B(-3,16,3,concrete:15)
B(-3,16,4,concrete:15)
B(-3,16,5,concrete:15)
B(-3,17,-3,stone)
B(-3,17,-2,stone)
B(-3,17,-1,stone)
B(-3,17,0,stone)
B(-3,17,1,stone)
B(-3,17,2,stone)
B(-3,17,3,concrete:15)
B(-3,17,4,concrete:15)
B(-3,17,5,concrete:15)
B(-3,18,-3,stone)
B(-3,18,-2,log2)
B(-3,18,-1,stone)
B(-3,18,0,stone)
B(-3,18,1,stone)
B(-3,18,2,stone)
B(-3,18,3,stone)
B(-3,18,4,concrete:15)
B(-3,18,5,concrete:15)
B(-3,19,-5,stone)
B(-3,19,-4,stone)
B(-3,19,-3,stone)
B(-3,19,-2,stone)
B(-3,19,-1,log:2)
B(-3,19,0,stone)
B(-3,19,1,log:2)
B(-3,19,2,stone)
B(-3,19,3,stone)
B(-3,19,4,concrete:15)
B(-3,19,5,concrete:15)
B(-3,19,6,concrete:15)
B(-3,20,-5,stone)
B(-3,20,-4,stone)
B(-3,20,-3,LOG:1)
B(-3,20,-2,log)
B(-3,20,-1,stone)
B(-3,20,0,log:2)
B(-3,20,1,stone)
B(-3,20,2,stone)
B(-3,20,3,stone)
B(-3,20,4,concrete:15)
B(-3,20,5,concrete:15)
B(-3,20,6,concrete:15)
B(-3,21,-7,stone)
B(-3,21,-6,stone)
B(-3,21,-5,stone)
B(-3,21,-4,stone)
B(-3,21,-3,stone)
B(-3,21,-2,stone)
B(-3,21,-1,stone)
B(-3,21,0,stone)
B(-3,21,1,stone)
B(-3,21,2,stone)
B(-3,21,3,stone)
B(-3,21,4,stone)
B(-3,21,5,stone)
B(-3,21,6,concrete:15)
B(-3,22,-9,stone)
B(-3,22,-8,stone)
B(-3,22,-7,stone)
B(-3,22,-6,stone)
B(-3,22,-5,stone)
B(-3,22,-4,stone)
B(-3,22,-3,stone)
B(-3,22,-2,stone)
B(-3,22,-1,stone)
B(-3,22,0,stone)
B(-3,22,1,stone)
B(-3,22,2,stone)
B(-3,22,3,stone)
B(-3,22,4,log)
B(-3,22,5,stone)
B(-3,22,6,stone)
B(-3,22,7,stone)
B(-3,22,8,concrete:15)
B(-3,23,-10,stone)
B(-3,23,-9,stone)
B(-3,23,-8,stone)
B(-3,23,-7,stone)
B(-3,23,-6,stone)
B(-3,23,-5,stone)
B(-3,23,-4,stone)
B(-3,23,-3,stone)
B(-3,23,-2,stone)
B(-3,23,-1,stone)
B(-3,23,0,stone)
B(-3,23,1,stone)
B(-3,23,2,stone)
B(-3,23,3,log2:1)
B(-3,23,4,stone)
B(-3,23,5,stone)
B(-3,23,6,log)
B(-3,23,7,stone)
B(-3,23,8,concrete:15)
B(-3,23,9,concrete:15)
B(-3,23,10,concrete:15)
B(-3,24,-13,stone)
B(-3,24,-12,stone)
B(-3,24,-11,stone)
B(-3,24,-10,stone)
B(-3,24,-9,stone)
B(-3,24,-8,stone)
B(-3,24,-7,stone)
B(-3,24,-6,stone)
B(-3,24,-5,stone)
B(-3,24,-4,stone)
B(-3,24,-3,stone)
B(-3,24,-2,stone)
B(-3,24,-1,stone)
B(-3,24,0,log2)
B(-3,24,1,log:2)
B(-3,24,2,stone)
B(-3,24,3,log2:1)
B(-3,24,4,log2)
B(-3,24,5,stone)
B(-3,24,6,stone)
B(-3,24,7,stone)
B(-3,24,8,stone)
B(-3,24,9,concrete:15)
B(-3,24,10,concrete:15)
B(-3,24,11,LOG:13)
B(-3,25,-13,stone)
B(-3,25,-12,stone)
B(-3,25,-11,stone)
B(-3,25,-10,stone)
B(-3,25,-9,stone)
B(-3,25,-8,stone)
B(-3,25,-7,stone)
B(-3,25,-6,stone)
B(-3,25,-5,LOG:1)
B(-3,25,-4,stone)
B(-3,25,-3,stone)
B(-3,25,-2,LOG:1)
B(-3,25,-1,log2)
B(-3,25,0,LOG:1)
B(-3,25,1,stone)
B(-3,25,2,stone)
B(-3,25,3,stone)
B(-3,25,4,log)
B(-3,25,5,stone)
B(-3,25,6,stone)
B(-3,25,7,stone)
B(-3,25,8,stone)
B(-3,25,9,stone)
B(-3,25,10,LOG:13)
B(-3,25,11,LOG:13)
B(-3,26,-13,stone)
B(-3,26,-12,stone)
B(-3,26,-11,stone)
B(-3,26,-10,stone)
B(-3,26,-9,stone)
B(-3,26,-8,stone)
B(-3,26,-7,stone)
B(-3,26,-6,stone)
B(-3,26,-5,stone)
B(-3,26,-4,stone)
B(-3,26,-3,log)
B(-3,26,-2,stone)
B(-3,26,-1,stone)
B(-3,26,0,stone)
B(-3,26,1,stone)
B(-3,26,2,stone)
B(-3,26,3,stone)
B(-3,26,4,stone)
B(-3,26,5,stone)
B(-3,26,6,stone)
B(-3,26,7,stone)
B(-3,26,8,stone)
B(-3,26,9,stone)
B(-3,26,10,stone)
B(-3,26,11,LOG:13)
B(-3,27,-12,stone)
B(-3,27,-11,stone)
B(-3,27,-10,stone)
B(-3,27,-9,stone)
B(-3,27,-8,log2)
B(-3,27,-7,log2:1)
B(-3,27,-6,stone)
B(-3,27,-5,log)
B(-3,27,-4,stone)
B(-3,27,-3,stone)
B(-3,27,-2,stone)
B(-3,27,-1,stone)
B(-3,27,0,stone)
B(-3,27,1,LOG:1)
B(-3,27,2,stone)
B(-3,27,3,log2)
B(-3,27,4,log)
B(-3,27,5,stone)
B(-3,27,6,stone)
B(-3,27,7,log2:1)
B(-3,27,8,log)
B(-3,27,9,stone)
B(-3,27,10,stone)
B(-3,27,11,stone)
B(-2,0,-12,stone)
B(-2,0,-11,stone)
B(-2,0,-10,stone)
B(-2,0,-9,stone)
B(-2,0,-8,stone)
B(-2,0,-7,stone)
B(-2,0,-6,stone)
B(-2,0,-5,stone)
B(-2,0,-4,stone)
B(-2,0,-3,stone)
B(-2,0,-2,stone)
B(-2,0,-1,stone)
B(-2,0,0,stone)
B(-2,0,1,stone)
B(-2,0,2,stone)
B(-2,0,3,stone)
B(-2,0,4,stone)
B(-2,0,5,stone)
B(-2,0,6,stone)
B(-2,0,7,stone)
B(-2,0,8,stone)
B(-2,0,9,stone)
B(-2,0,10,stone)
B(-2,0,11,concrete:15)
B(-2,0,12,LOG:13)
B(-2,0,13,LOG:13)
B(-2,1,-12,stone)
B(-2,1,-11,stone)
B(-2,1,-10,stone)
B(-2,1,-9,stone)
B(-2,1,-8,stone)
B(-2,1,-7,stone)
B(-2,1,-6,stone)
B(-2,1,-5,stone)
B(-2,1,-4,stone)
B(-2,1,-3,stone)
B(-2,1,-2,stone)
B(-2,1,-1,stone)
B(-2,1,0,stone)
B(-2,1,1,stone)
B(-2,1,2,stone)
B(-2,1,3,stone)
B(-2,1,4,stone)
B(-2,1,5,stone)
B(-2,1,6,stone)
B(-2,1,7,stone)
B(-2,1,8,stone)
B(-2,1,9,stone)
B(-2,1,10,stone)
B(-2,1,11,LOG:13)
B(-2,1,12,LOG:13)
B(-2,2,-11,stone)
B(-2,2,-10,stone)
B(-2,2,-9,stone)
B(-2,2,-8,log)
B(-2,2,-7,stone)
B(-2,2,-6,stone)
B(-2,2,-5,log2:1)
B(-2,2,-4,stone)
B(-2,2,-3,stone)
B(-2,2,-2,stone)
B(-2,2,-1,LOG:1)
B(-2,2,0,LOG:1)
B(-2,2,1,stone)
B(-2,2,2,stone)
B(-2,2,3,stone)
B(-2,2,4,stone)
B(-2,2,5,stone)
B(-2,2,6,stone)
B(-2,2,7,stone)
B(-2,2,8,stone)
B(-2,2,9,stone)
B(-2,2,10,concrete:15)
B(-2,2,11,LOG:13)
B(-2,2,12,LOG:13)
B(-2,3,-10,stone)
B(-2,3,-9,concrete:15)
B(-2,3,-8,stone)
B(-2,3,-7,stone)
B(-2,3,-6,stone)
B(-2,3,-5,stone)
B(-2,3,-4,log2)
B(-2,3,-3,stone)
B(-2,3,-2,stone)
B(-2,3,-1,log)
B(-2,3,0,stone)
B(-2,3,1,stone)
B(-2,3,2,stone)
B(-2,3,3,log2:1)
B(-2,3,4,stone)
B(-2,3,5,stone)
B(-2,3,6,stone)
B(-2,3,7,stone)
B(-2,3,8,stone)
B(-2,3,9,concrete:15)
B(-2,3,10,concrete:15)
B(-2,3,11,LOG:13)
B(-2,4,-10,concrete:15)
B(-2,4,-9,concrete:15)
B(-2,4,-8,concrete:15)
B(-2,4,-7,concrete:15)
B(-2,4,-6,log:2)
B(-2,4,-5,stone)
B(-2,4,-4,stone)
B(-2,4,-3,stone)
B(-2,4,-2,stone)
B(-2,4,-1,stone)
B(-2,4,0,stone)
B(-2,4,1,stone)
B(-2,4,2,stone)
B(-2,4,3,log2)
B(-2,4,4,log2)
B(-2,4,5,stone)
B(-2,4,6,stone)
B(-2,4,7,stone)
B(-2,4,8,stone)
B(-2,4,9,concrete:15)
B(-2,4,10,concrete:15)
B(-2,5,-8,LOG:13)
B(-2,5,-7,concrete:15)
B(-2,5,-6,stone)
B(-2,5,-5,stone)
B(-2,5,-4,stone)
B(-2,5,-3,stone)
B(-2,5,-2,stone)
B(-2,5,-1,LOG:1)
B(-2,5,0,log2)
B(-2,5,1,stone)
B(-2,5,2,log:2)
B(-2,5,3,stone)
B(-2,5,4,stone)
B(-2,5,5,stone)
B(-2,5,6,stone)
B(-2,5,7,stone)
B(-2,5,8,stone)
B(-2,5,9,concrete:15)
B(-2,5,10,concrete:15)
B(-2,6,-8,LOG:13)
B(-2,6,-7,LOG:13)
B(-2,6,-6,stone)
B(-2,6,-5,stone)
B(-2,6,-4,stone)
B(-2,6,-3,log2)
B(-2,6,-2,stone)
B(-2,6,-1,log2:1)
B(-2,6,0,stone)
B(-2,6,1,stone)
B(-2,6,2,log)
B(-2,6,3,stone)
B(-2,6,4,stone)
B(-2,6,5,stone)
B(-2,6,6,stone)
B(-2,6,7,stone)
B(-2,6,8,stone)
B(-2,6,9,stone)
B(-2,7,-7,LOG:13)
B(-2,7,-6,LOG:13)
B(-2,7,-5,stone)
B(-2,7,-4,stone)
B(-2,7,-3,stone)
B(-2,7,-2,log)
B(-2,7,-1,stone)
B(-2,7,0,stone)
B(-2,7,1,stone)
B(-2,7,2,log2)
B(-2,7,3,stone)
B(-2,7,4,stone)
B(-2,7,5,stone)
B(-2,7,6,stone)
B(-2,7,7,stone)
B(-2,8,-7,LOG:13)
B(-2,8,-6,LOG:13)
B(-2,8,-5,stone)
B(-2,8,-4,stone)
B(-2,8,-3,stone)
B(-2,8,-2,stone)
B(-2,8,-1,log:2)
B(-2,8,0,log:2)
B(-2,8,1,stone)
B(-2,8,2,stone)
B(-2,8,3,stone)
B(-2,8,4,stone)
B(-2,8,5,stone)
B(-2,8,6,stone)
B(-2,8,7,stone)
B(-2,9,-7,Leaves:7)
B(-2,9,-6,LOG:13)
B(-2,9,-5,stone)
B(-2,9,-4,stone)
B(-2,9,-3,stone)
B(-2,9,-2,stone)
B(-2,9,-1,log2)
B(-2,9,0,stone)
B(-2,9,1,log:2)
B(-2,9,2,stone)
B(-2,9,3,stone)
B(-2,9,4,stone)
B(-2,9,5,stone)
B(-2,9,6,concrete:15)
B(-2,9,7,stone)
B(-2,10,-6,LOG:13)
B(-2,10,-5,LOG:13)
B(-2,10,-4,concrete:15)
B(-2,10,-3,stone)
B(-2,10,-2,log2:1)
B(-2,10,-1,stone)
B(-2,10,0,stone)
B(-2,10,1,stone)
B(-2,10,2,stone)
B(-2,10,3,stone)
B(-2,10,4,concrete:15)
B(-2,10,5,concrete:15)
B(-2,10,6,concrete:15)
B(-2,11,-6,LOG:13)
B(-2,11,-5,concrete:15)
B(-2,11,-4,concrete:15)
B(-2,11,-3,stone)
B(-2,11,-2,stone)
B(-2,11,-1,stone)
B(-2,11,0,log:2)
B(-2,11,1,stone)
B(-2,11,2,log2)
B(-2,11,3,stone)
B(-2,11,4,concrete:15)
B(-2,11,5,concrete:15)
B(-2,12,-5,concrete:15)
B(-2,12,-4,concrete:15)
B(-2,12,-3,concrete:15)
B(-2,12,-2,stone)
B(-2,12,-1,stone)
B(-2,12,0,log:2)
B(-2,12,1,stone)
B(-2,12,2,stone)
B(-2,12,3,stone)
B(-2,12,4,concrete:15)
B(-2,12,5,concrete:15)
B(-2,13,-4,concrete:15)
B(-2,13,-3,concrete:15)
B(-2,13,-2,stone)
B(-2,13,-1,stone)
B(-2,13,0,stone)
B(-2,13,1,log:2)
B(-2,13,2,stone)
B(-2,13,3,stone)
B(-2,13,4,concrete:15)
B(-2,13,5,concrete:15)
B(-2,14,-4,concrete:15)
B(-2,14,-3,concrete:15)
B(-2,14,-2,stone)
B(-2,14,-1,stone)
B(-2,14,0,stone)
B(-2,14,1,stone)
B(-2,14,2,stone)
B(-2,14,3,concrete:15)
B(-2,14,4,concrete:15)
B(-2,15,-5,concrete:15)
B(-2,15,-4,concrete:15)
B(-2,15,-3,stone)
B(-2,15,-2,stone)
B(-2,15,-1,stone)
B(-2,15,0,stone)
B(-2,15,1,stone)
B(-2,15,2,stone)
B(-2,15,3,stone)
B(-2,15,4,concrete:15)
B(-2,15,5,concrete:15)
B(-2,16,-5,concrete:15)
B(-2,16,-4,concrete:15)
B(-2,16,-3,stone)
B(-2,16,-2,stone)
B(-2,16,-1,stone)
B(-2,16,0,stone)
B(-2,16,1,stone)
B(-2,16,2,stone)
B(-2,16,3,concrete:15)
B(-2,16,4,concrete:15)
B(-2,16,5,concrete:15)
B(-2,17,-4,stone)
B(-2,17,-3,stone)
B(-2,17,-2,stone)
B(-2,17,-1,log2)
B(-2,17,0,stone)
B(-2,17,1,LOG:1)
B(-2,17,2,stone)
B(-2,17,3,stone)
B(-2,17,4,concrete:15)
B(-2,17,5,concrete:15)
B(-2,18,-5,stone)
B(-2,18,-4,stone)
B(-2,18,-3,stone)
B(-2,18,-2,log2)
B(-2,18,-1,stone)
B(-2,18,0,stone)
B(-2,18,1,stone)
B(-2,18,2,stone)
B(-2,18,3,stone)
B(-2,18,4,concrete:15)
B(-2,18,5,concrete:15)
B(-2,19,-5,stone)
B(-2,19,-4,stone)
B(-2,19,-3,stone)
B(-2,19,-2,stone)
B(-2,19,-1,stone)
B(-2,19,0,stone)
B(-2,19,1,stone)
B(-2,19,2,stone)
B(-2,19,3,stone)
B(-2,19,4,concrete:15)
B(-2,19,5,concrete:15)
B(-2,19,6,concrete:15)
B(-2,20,-7,stone)
B(-2,20,-6,stone)
B(-2,20,-5,stone)
B(-2,20,-4,log)
B(-2,20,-3,stone)
B(-2,20,-2,LOG:1)
B(-2,20,-1,stone)
B(-2,20,0,log2:1)
B(-2,20,1,stone)
B(-2,20,2,stone)
B(-2,20,3,stone)
B(-2,20,4,stone)
B(-2,20,5,concrete:15)
B(-2,20,6,stone)
B(-2,21,-8,stone)
B(-2,21,-7,stone)
B(-2,21,-6,stone)
B(-2,21,-5,log2)
B(-2,21,-4,stone)
B(-2,21,-3,stone)
B(-2,21,-2,log2)
B(-2,21,-1,stone)
B(-2,21,0,stone)
B(-2,21,1,log)
B(-2,21,2,stone)
B(-2,21,3,stone)
B(-2,21,4,stone)
B(-2,21,5,stone)
B(-2,21,6,stone)
B(-2,21,7,stone)
B(-2,22,-9,stone)
B(-2,22,-8,stone)
B(-2,22,-7,stone)
B(-2,22,-6,stone)
B(-2,22,-5,log2)
B(-2,22,-4,stone)
B(-2,22,-3,stone)
B(-2,22,-2,log2:1)
B(-2,22,-1,stone)
B(-2,22,0,stone)
B(-2,22,1,stone)
B(-2,22,2,log2:1)
B(-2,22,3,stone)
B(-2,22,4,stone)
B(-2,22,5,stone)
B(-2,22,6,stone)
B(-2,22,7,stone)
B(-2,22,8,concrete:15)
B(-2,23,-11,stone)
B(-2,23,-10,stone)
B(-2,23,-9,stone)
B(-2,23,-8,stone)
B(-2,23,-7,stone)
B(-2,23,-6,stone)
B(-2,23,-5,LOG:1)
B(-2,23,-4,log2:1)
B(-2,23,-3,stone)
B(-2,23,-2,stone)
B(-2,23,-1,stone)
B(-2,23,0,stone)
B(-2,23,1,stone)
B(-2,23,2,LOG:1)
B(-2,23,3,stone)
B(-2,23,4,stone)
B(-2,23,5,stone)
B(-2,23,6,stone)
B(-2,23,7,stone)
B(-2,23,8,concrete:15)
B(-2,23,9,concrete:15)
B(-2,23,10,LOG:13)
B(-2,24,-13,stone)
B(-2,24,-12,stone)
B(-2,24,-11,stone)
B(-2,24,-10,stone)
B(-2,24,-9,stone)
B(-2,24,-8,stone)
B(-2,24,-7,stone)
B(-2,24,-6,stone)
B(-2,24,-5,stone)
B(-2,24,-4,stone)
B(-2,24,-3,log2:1)
B(-2,24,-2,stone)
B(-2,24,-1,stone)
B(-2,24,0,stone)
B(-2,24,1,log2)
B(-2,24,2,stone)
B(-2,24,3,log2)
B(-2,24,4,stone)
B(-2,24,5,log2:1)
B(-2,24,6,log:2)
B(-2,24,7,stone)
B(-2,24,8,stone)
B(-2,24,9,LOG:13)
B(-2,24,10,LOG:13)
B(-2,24,11,Leaves:7)
B(-2,25,-13,stone)
B(-2,25,-12,stone)
B(-2,25,-11,stone)
B(-2,25,-10,stone)
B(-2,25,-9,stone)
B(-2,25,-8,stone)
B(-2,25,-7,stone)
B(-2,25,-6,stone)
B(-2,25,-5,stone)
B(-2,25,-4,stone)
B(-2,25,-3,stone)
B(-2,25,-2,stone)
B(-2,25,-1,log:2)
B(-2,25,0,stone)
B(-2,25,1,stone)
B(-2,25,2,stone)
B(-2,25,3,stone)
B(-2,25,4,log)
B(-2,25,5,LOG:1)
B(-2,25,6,log:2)
B(-2,25,7,stone)
B(-2,25,8,stone)
B(-2,25,9,stone)
B(-2,25,10,LOG:13)
B(-2,25,11,LOG:13)
B(-2,25,12,Leaves:7)
B(-2,26,-13,stone)
B(-2,26,-12,stone)
B(-2,26,-11,stone)
B(-2,26,-10,stone)
B(-2,26,-9,stone)
B(-2,26,-8,stone)
B(-2,26,-7,stone)
B(-2,26,-6,stone)
B(-2,26,-5,log:2)
B(-2,26,-4,stone)
B(-2,26,-3,log)
B(-2,26,-2,log:2)
B(-2,26,-1,log2)
B(-2,26,0,stone)
B(-2,26,1,stone)
B(-2,26,2,stone)
B(-2,26,3,stone)
B(-2,26,4,LOG:1)
B(-2,26,5,log2)
B(-2,26,6,stone)
B(-2,26,7,stone)
B(-2,26,8,stone)
B(-2,26,9,stone)
B(-2,26,10,LOG:13)
B(-2,26,11,LOG:13)
B(-2,27,-13,stone)
B(-2,27,-12,stone)
B(-2,27,-11,stone)
B(-2,27,-10,stone)
B(-2,27,-9,stone)
B(-2,27,-8,stone)
B(-2,27,-7,stone)
B(-2,27,-6,stone)
B(-2,27,-5,stone)
B(-2,27,-4,stone)
B(-2,27,-3,stone)
B(-2,27,-2,LOG:1)
B(-2,27,-1,stone)
B(-2,27,0,stone)
B(-2,27,1,log2:1)
B(-2,27,2,log:2)
B(-2,27,3,stone)
B(-2,27,4,stone)
B(-2,27,5,stone)
B(-2,27,6,stone)
B(-2,27,7,stone)
B(-2,27,8,stone)
B(-2,27,9,stone)
B(-2,27,10,stone)
B(-1,0,-12,stone)
B(-1,0,-11,stone)
B(-1,0,-10,stone)
B(-1,0,-9,stone)
B(-1,0,-8,stone)
B(-1,0,-7,stone)
B(-1,0,-6,stone)
B(-1,0,-5,stone)
B(-1,0,-4,stone)
B(-1,0,-3,stone)
B(-1,0,-2,stone)
B(-1,0,-1,stone)
B(-1,0,0,stone)
B(-1,0,1,stone)
B(-1,0,2,stone)
B(-1,0,3,stone)
B(-1,0,4,stone)
B(-1,0,5,stone)
B(-1,0,6,stone)
B(-1,0,7,stone)
B(-1,0,8,stone)
B(-1,0,9,stone)
B(-1,0,10,stone)
B(-1,0,11,stone)
B(-1,0,12,concrete:15)
B(-1,0,13,concrete:15)
B(-1,1,-11,stone)
B(-1,1,-10,stone)
B(-1,1,-9,stone)
B(-1,1,-8,stone)
B(-1,1,-7,stone)
B(-1,1,-6,stone)
B(-1,1,-5,stone)
B(-1,1,-4,stone)
B(-1,1,-3,stone)
B(-1,1,-2,stone)
B(-1,1,-1,stone)
B(-1,1,0,stone)
B(-1,1,1,log2)
B(-1,1,2,stone)
B(-1,1,3,stone)
B(-1,1,4,stone)
B(-1,1,5,stone)
B(-1,1,6,stone)
B(-1,1,7,stone)
B(-1,1,8,stone)
B(-1,1,9,stone)
B(-1,1,10,stone)
B(-1,1,11,stone)
B(-1,1,12,LOG:13)
B(-1,2,-10,stone)
B(-1,2,-9,stone)
B(-1,2,-8,stone)
B(-1,2,-7,stone)
B(-1,2,-6,stone)
B(-1,2,-5,stone)
B(-1,2,-4,stone)
B(-1,2,-3,stone)
B(-1,2,-2,stone)
B(-1,2,-1,stone)
B(-1,2,0,stone)
B(-1,2,1,stone)
B(-1,2,2,stone)
B(-1,2,3,stone)
B(-1,2,4,stone)
B(-1,2,5,stone)
B(-1,2,6,stone)
B(-1,2,7,stone)
B(-1,2,8,stone)
B(-1,2,9,stone)
B(-1,2,10,stone)
B(-1,2,11,LOG:13)
B(-1,2,12,LOG:13)
B(-1,2,13,Leaves:7)
B(-1,3,-10,stone)
B(-1,3,-9,stone)
B(-1,3,-8,stone)
B(-1,3,-7,log2)
B(-1,3,-6,stone)
B(-1,3,-5,stone)
B(-1,3,-4,stone)
B(-1,3,-3,stone)
B(-1,3,-2,stone)
B(-1,3,-1,stone)
B(-1,3,0,log2)
B(-1,3,1,stone)
B(-1,3,2,log)
B(-1,3,3,stone)
B(-1,3,4,stone)
B(-1,3,5,stone)
B(-1,3,6,stone)
B(-1,3,7,stone)
B(-1,3,8,stone)
B(-1,3,9,stone)
B(-1,3,10,LOG:13)
B(-1,3,11,LOG:13)
B(-1,3,12,Leaves:7)
B(-1,4,-10,stone)
B(-1,4,-9,stone)
B(-1,4,-8,concrete:15)
B(-1,4,-7,stone)
B(-1,4,-6,stone)
B(-1,4,-5,stone)
B(-1,4,-4,stone)
B(-1,4,-3,stone)
B(-1,4,-2,stone)
B(-1,4,-1,log:2)
B(-1,4,0,stone)
B(-1,4,1,stone)
B(-1,4,2,stone)
B(-1,4,3,log:2)
B(-1,4,4,stone)
B(-1,4,5,stone)
B(-1,4,6,stone)
B(-1,4,7,stone)
B(-1,4,8,stone)
B(-1,4,9,concrete:15)
B(-1,4,10,concrete:15)
B(-1,4,11,LOG:13)
B(-1,5,-9,concrete:15)
B(-1,5,-8,concrete:15)
B(-1,5,-7,concrete:15)
B(-1,5,-6,stone)
B(-1,5,-5,stone)
B(-1,5,-4,stone)
B(-1,5,-3,log2:1)
B(-1,5,-2,stone)
B(-1,5,-1,stone)
B(-1,5,0,stone)
B(-1,5,1,stone)
B(-1,5,2,stone)
B(-1,5,3,log2:1)
B(-1,5,4,stone)
B(-1,5,5,stone)
B(-1,5,6,stone)
B(-1,5,7,stone)
B(-1,5,8,concrete:15)
B(-1,5,9,concrete:15)
B(-1,5,10,concrete:15)
B(-1,5,11,concrete:15)
B(-1,6,-8,concrete:15)
B(-1,6,-7,concrete:15)
B(-1,6,-6,stone)
B(-1,6,-5,stone)
B(-1,6,-4,stone)
B(-1,6,-3,stone)
B(-1,6,-2,stone)
B(-1,6,-1,stone)
B(-1,6,0,stone)
B(-1,6,1,log2:1)
B(-1,6,2,log2)
B(-1,6,3,stone)
B(-1,6,4,stone)
B(-1,6,5,stone)
B(-1,6,6,stone)
B(-1,6,7,stone)
B(-1,6,8,stone)
B(-1,6,9,concrete:15)
B(-1,6,10,concrete:15)
B(-1,7,-8,concrete:15)
B(-1,7,-7,LOG:13)
B(-1,7,-6,concrete:15)
B(-1,7,-5,log2:1)
B(-1,7,-4,log2:1)
B(-1,7,-3,log)
B(-1,7,-2,stone)
B(-1,7,-1,stone)
B(-1,7,0,stone)
B(-1,7,1,stone)
B(-1,7,2,stone)
B(-1,7,3,log)
B(-1,7,4,stone)
B(-1,7,5,stone)
B(-1,7,6,stone)
B(-1,7,7,stone)
B(-1,7,8,stone)
B(-1,8,-8,LOG:13)
B(-1,8,-7,LOG:13)
B(-1,8,-6,LOG:13)
B(-1,8,-5,concrete:15)
B(-1,8,-4,stone)
B(-1,8,-3,log)
B(-1,8,-2,LOG:1)
B(-1,8,-1,log:2)
B(-1,8,0,stone)
B(-1,8,1,stone)
B(-1,8,2,log:2)
B(-1,8,3,stone)
B(-1,8,4,stone)
B(-1,8,5,stone)
B(-1,8,6,stone)
B(-1,8,7,stone)
B(-1,8,8,stone)
B(-1,9,-8,Leaves:7)
B(-1,9,-7,LOG:13)
B(-1,9,-6,LOG:13)
B(-1,9,-5,LOG:13)
B(-1,9,-4,stone)
B(-1,9,-3,stone)
B(-1,9,-2,LOG:1)
B(-1,9,-1,stone)
B(-1,9,0,stone)
B(-1,9,1,stone)
B(-1,9,2,stone)
B(-1,9,3,log)
B(-1,9,4,stone)
B(-1,9,5,concrete:15)
B(-1,9,6,concrete:15)
B(-1,9,7,concrete:15)
B(-1,10,-7,Leaves:7)
B(-1,10,-6,LOG:13)
B(-1,10,-5,LOG:13)
B(-1,10,-4,LOG:13)
B(-1,10,-3,stone)
B(-1,10,-2,log:2)
B(-1,10,-1,stone)
B(-1,10,0,stone)
B(-1,10,1,stone)
B(-1,10,2,LOG:1)
B(-1,10,3,log)
B(-1,10,4,stone)
B(-1,10,5,concrete:15)
B(-1,10,6,concrete:15)
B(-1,11,-5,LOG:13)
B(-1,11,-4,concrete:15)
B(-1,11,-3,stone)
B(-1,11,-2,stone)
B(-1,11,-1,stone)
B(-1,11,0,stone)
B(-1,11,1,stone)
B(-1,11,2,log)
B(-1,11,3,stone)
B(-1,11,4,concrete:15)
B(-1,11,5,LOG:13)
B(-1,12,-5,concrete:15)
B(-1,12,-4,concrete:15)
B(-1,12,-3,stone)
B(-1,12,-2,stone)
B(-1,12,-1,stone)
B(-1,12,0,stone)
B(-1,12,1,stone)
B(-1,12,2,log:2)
B(-1,12,3,stone)
B(-1,12,4,LOG:13)
B(-1,12,5,LOG:13)
B(-1,13,-5,LOG:13)
B(-1,13,-4,concrete:15)
B(-1,13,-3,concrete:15)
B(-1,13,-2,stone)
B(-1,13,-1,stone)
B(-1,13,0,stone)
B(-1,13,1,log)
B(-1,13,2,stone)
B(-1,13,3,stone)
B(-1,13,4,LOG:13)
B(-1,14,-5,LOG:13)
B(-1,14,-4,LOG:13)
B(-1,14,-3,stone)
B(-1,14,-2,stone)
B(-1,14,-1,log2:1)
B(-1,14,0,log2)
B(-1,14,1,log2:1)
B(-1,14,2,stone)
B(-1,14,3,stone)
B(-1,14,4,concrete:15)
B(-1,14,5,LOG:13)
B(-1,15,-5,LOG:13)
B(-1,15,-4,concrete:15)
B(-1,15,-3,stone)
B(-1,15,-2,stone)
B(-1,15,-1,stone)
B(-1,15,0,log2)
B(-1,15,1,stone)
B(-1,15,2,stone)
B(-1,15,3,stone)
B(-1,15,4,LOG:13)
B(-1,15,5,LOG:13)
B(-1,16,-5,concrete:15)
B(-1,16,-4,concrete:15)
B(-1,16,-3,stone)
B(-1,16,-2,log)
B(-1,16,-1,log2)
B(-1,16,0,stone)
B(-1,16,1,stone)
B(-1,16,2,stone)
B(-1,16,3,stone)
B(-1,16,4,LOG:13)
B(-1,16,5,LOG:13)
B(-1,17,-5,concrete:15)
B(-1,17,-4,concrete:15)
B(-1,17,-3,log)
B(-1,17,-2,stone)
B(-1,17,-1,stone)
B(-1,17,0,log2:1)
B(-1,17,1,stone)
B(-1,17,2,stone)
B(-1,17,3,LOG:13)
B(-1,17,4,LOG:13)
B(-1,17,5,LOG:13)
B(-1,17,6,concrete:15)
B(-1,18,-5,stone)
B(-1,18,-4,stone)
B(-1,18,-3,stone)
B(-1,18,-2,log)
B(-1,18,-1,stone)
B(-1,18,0,stone)
B(-1,18,1,stone)
B(-1,18,2,stone)
B(-1,18,3,stone)
B(-1,18,4,LOG:13)
B(-1,18,5,concrete:15)
B(-1,18,6,stone)
B(-1,19,-6,concrete:15)
B(-1,19,-5,stone)
B(-1,19,-4,log:2)
B(-1,19,-3,log2)
B(-1,19,-2,stone)
B(-1,19,-1,stone)
B(-1,19,0,stone)
B(-1,19,1,LOG:1)
B(-1,19,2,stone)
B(-1,19,3,stone)
B(-1,19,4,stone)
B(-1,19,5,stone)
B(-1,19,6,stone)
B(-1,19,7,stone)
B(-1,20,-8,stone)
B(-1,20,-7,concrete:15)
B(-1,20,-6,stone)
B(-1,20,-5,stone)
B(-1,20,-4,stone)
B(-1,20,-3,stone)
B(-1,20,-2,stone)
B(-1,20,-1,LOG:1)
B(-1,20,0,stone)
B(-1,20,1,LOG:1)
B(-1,20,2,stone)
B(-1,20,3,log2:1)
B(-1,20,4,stone)
B(-1,20,5,stone)
B(-1,20,6,stone)
B(-1,20,7,stone)
B(-1,20,8,concrete:15)
B(-1,21,-8,stone)
B(-1,21,-7,stone)
B(-1,21,-6,stone)
B(-1,21,-5,log)
B(-1,21,-4,stone)
B(-1,21,-3,stone)
B(-1,21,-2,LOG:1)
B(-1,21,-1,stone)
B(-1,21,0,stone)
B(-1,21,1,stone)
B(-1,21,2,LOG:1)
B(-1,21,3,stone)
B(-1,21,4,stone)
B(-1,21,5,stone)
B(-1,21,6,stone)
B(-1,21,7,concrete:15)
B(-1,21,8,concrete:15)
B(-1,22,-10,stone)
B(-1,22,-9,stone)
B(-1,22,-8,stone)
B(-1,22,-7,stone)
B(-1,22,-6,stone)
B(-1,22,-5,stone)
B(-1,22,-4,log2:1)
B(-1,22,-3,stone)
B(-1,22,-2,stone)
B(-1,22,-1,log)
B(-1,22,0,log2)
B(-1,22,1,stone)
B(-1,22,2,stone)
B(-1,22,3,log)
B(-1,22,4,stone)
B(-1,22,5,stone)
B(-1,22,6,stone)
B(-1,22,7,stone)
B(-1,22,8,LOG:13)
B(-1,23,-11,stone)
B(-1,23,-10,stone)
B(-1,23,-9,stone)
B(-1,23,-8,stone)
B(-1,23,-7,stone)
B(-1,23,-6,log2:1)
B(-1,23,-5,stone)
B(-1,23,-4,stone)
B(-1,23,-3,log2:1)
B(-1,23,-2,stone)
B(-1,23,-1,log:2)
B(-1,23,0,stone)
B(-1,23,1,log)
B(-1,23,2,log)
B(-1,23,3,log:2)
B(-1,23,4,stone)
B(-1,23,5,stone)
B(-1,23,6,stone)
B(-1,23,7,stone)
B(-1,23,8,stone)
B(-1,23,9,LOG:13)
B(-1,24,-13,stone)
B(-1,24,-12,stone)
B(-1,24,-11,stone)
B(-1,24,-10,stone)
B(-1,24,-9,stone)
B(-1,24,-8,stone)
B(-1,24,-7,stone)
B(-1,24,-6,log:2)
B(-1,24,-5,stone)
B(-1,24,-4,stone)
B(-1,24,-3,stone)
B(-1,24,-2,stone)
B(-1,24,-1,stone)
B(-1,24,0,stone)
B(-1,24,1,log:2)
B(-1,24,2,log2)
B(-1,24,3,log2:1)
B(-1,24,4,log2)
B(-1,24,5,log:2)
B(-1,24,6,stone)
B(-1,24,7,stone)
B(-1,24,8,stone)
B(-1,24,9,LOG:13)
B(-1,24,10,LOG:13)
B(-1,25,-13,stone)
B(-1,25,-12,stone)
B(-1,25,-11,stone)
B(-1,25,-10,stone)
B(-1,25,-9,stone)
B(-1,25,-8,stone)
B(-1,25,-7,stone)
B(-1,25,-6,stone)
B(-1,25,-5,stone)
B(-1,25,-4,stone)
B(-1,25,-3,stone)
B(-1,25,-2,stone)
B(-1,25,-1,log2)
B(-1,25,0,stone)
B(-1,25,1,stone)
B(-1,25,2,stone)
B(-1,25,3,stone)
B(-1,25,4,stone)
B(-1,25,5,log2:1)
B(-1,25,6,stone)
B(-1,25,7,stone)
B(-1,25,8,stone)
B(-1,25,9,LOG:13)
B(-1,25,10,LOG:13)
B(-1,25,11,LOG:13)
B(-1,26,-13,stone)
B(-1,26,-12,stone)
B(-1,26,-11,stone)
B(-1,26,-10,stone)
B(-1,26,-9,stone)
B(-1,26,-8,LOG:1)
B(-1,26,-7,stone)
B(-1,26,-6,stone)
B(-1,26,-5,stone)
B(-1,26,-4,stone)
B(-1,26,-3,log)
B(-1,26,-2,stone)
B(-1,26,-1,stone)
B(-1,26,0,stone)
B(-1,26,1,log:2)
B(-1,26,2,stone)
B(-1,26,3,stone)
B(-1,26,4,stone)
B(-1,26,5,stone)
B(-1,26,6,stone)
B(-1,26,7,stone)
B(-1,26,8,stone)
B(-1,26,9,stone)
B(-1,26,10,stone)
B(-1,26,11,LOG:13)
B(-1,26,12,concrete:15)
B(-1,27,-12,stone)
B(-1,27,-11,stone)
B(-1,27,-10,stone)
B(-1,27,-9,stone)
B(-1,27,-8,stone)
B(-1,27,-7,log)
B(-1,27,-6,stone)
B(-1,27,-5,stone)
B(-1,27,-4,log)
B(-1,27,-3,log2:1)
B(-1,27,-2,log2)
B(-1,27,-1,stone)
B(-1,27,0,stone)
B(-1,27,1,stone)
B(-1,27,2,stone)
B(-1,27,3,log2)
B(-1,27,4,log2)
B(-1,27,5,stone)
B(-1,27,6,stone)
B(-1,27,7,log2:1)
B(-1,27,8,stone)
B(-1,27,9,stone)
B(-1,27,10,stone)
B(-1,27,11,concrete:15)
B(0,0,-12,stone)
B(0,0,-11,stone)
B(0,0,-10,stone)
B(0,0,-9,stone)
B(0,0,-8,stone)
B(0,0,-7,stone)
B(0,0,-6,stone)
B(0,0,-5,stone)
B(0,0,-4,stone)
B(0,0,-3,stone)
B(0,0,-2,stone)
B(0,0,-1,stone)
B(0,0,0,stone)
B(0,0,1,stone)
B(0,0,2,stone)
B(0,0,3,stone)
B(0,0,4,stone)
B(0,0,5,stone)
B(0,0,6,stone)
B(0,0,7,stone)
B(0,0,8,stone)
B(0,0,9,stone)
B(0,0,10,stone)
B(0,0,11,stone)
B(0,0,12,concrete:15)
B(0,0,13,concrete:15)
B(0,1,-11,stone)
B(0,1,-10,stone)
B(0,1,-9,stone)
B(0,1,-8,stone)
B(0,1,-7,stone)
B(0,1,-6,stone)
B(0,1,-5,stone)
B(0,1,-4,stone)
B(0,1,-3,stone)
B(0,1,-2,log2)
B(0,1,-1,log2:1)
B(0,1,0,log2)
B(0,1,1,stone)
B(0,1,2,stone)
B(0,1,3,stone)
B(0,1,4,stone)
B(0,1,5,stone)
B(0,1,6,stone)
B(0,1,7,stone)
B(0,1,8,stone)
B(0,1,9,stone)
B(0,1,10,stone)
B(0,1,11,concrete:15)
B(0,1,12,concrete:15)
B(0,2,-10,stone)
B(0,2,-9,stone)
B(0,2,-8,stone)
B(0,2,-7,stone)
B(0,2,-6,stone)
B(0,2,-5,log2)
B(0,2,-4,log:2)
B(0,2,-3,stone)
B(0,2,-2,log2)
B(0,2,-1,stone)
B(0,2,0,stone)
B(0,2,1,stone)
B(0,2,2,log2:1)
B(0,2,3,log2)
B(0,2,4,stone)
B(0,2,5,stone)
B(0,2,6,stone)
B(0,2,7,stone)
B(0,2,8,stone)
B(0,2,9,stone)
B(0,2,10,LOG:13)
B(0,2,11,LOG:13)
B(0,2,12,Leaves:7)
B(0,3,-10,stone)
B(0,3,-9,stone)
B(0,3,-8,stone)
B(0,3,-7,stone)
B(0,3,-6,stone)
B(0,3,-5,log)
B(0,3,-4,stone)
B(0,3,-3,log:2)
B(0,3,-2,stone)
B(0,3,-1,stone)
B(0,3,0,stone)
B(0,3,1,stone)
B(0,3,2,stone)
B(0,3,3,stone)
B(0,3,4,stone)
B(0,3,5,stone)
B(0,3,6,stone)
B(0,3,7,stone)
B(0,3,8,stone)
B(0,3,9,LOG:13)
B(0,3,10,LOG:13)
B(0,3,11,LOG:13)
B(0,3,12,Leaves:7)
B(0,4,-10,stone)
B(0,4,-9,stone)
B(0,4,-8,stone)
B(0,4,-7,stone)
B(0,4,-6,stone)
B(0,4,-5,stone)
B(0,4,-4,stone)
B(0,4,-3,log:2)
B(0,4,-2,stone)
B(0,4,-1,stone)
B(0,4,0,log2:1)
B(0,4,1,log2)
B(0,4,2,stone)
B(0,4,3,LOG:1)
B(0,4,4,stone)
B(0,4,5,stone)
B(0,4,6,stone)
B(0,4,7,stone)
B(0,4,8,LOG:13)
B(0,4,9,LOG:13)
B(0,4,10,LOG:13)
B(0,4,11,Leaves:7)
B(0,5,-10,stone)
B(0,5,-9,stone)
B(0,5,-8,stone)
B(0,5,-7,stone)
B(0,5,-6,stone)
B(0,5,-5,stone)
B(0,5,-4,stone)
B(0,5,-3,log2)
B(0,5,-2,stone)
B(0,5,-1,log)
B(0,5,0,log)
B(0,5,1,stone)
B(0,5,2,stone)
B(0,5,3,stone)
B(0,5,4,stone)
B(0,5,5,stone)
B(0,5,6,stone)
B(0,5,7,stone)
B(0,5,8,concrete:15)
B(0,5,9,LOG:13)
B(0,5,10,concrete:15)
B(0,6,-8,concrete:15)
B(0,6,-7,stone)
B(0,6,-6,stone)
B(0,6,-5,stone)
B(0,6,-4,log2)
B(0,6,-3,stone)
B(0,6,-2,stone)
B(0,6,-1,stone)
B(0,6,0,stone)
B(0,6,1,stone)
B(0,6,2,stone)
B(0,6,3,log)
B(0,6,4,log)
B(0,6,5,stone)
B(0,6,6,stone)
B(0,6,7,stone)
B(0,6,8,concrete:15)
B(0,7,-7,concrete:15)
B(0,7,-6,concrete:15)
B(0,7,-5,concrete:15)
B(0,7,-4,stone)
B(0,7,-3,log2:1)
B(0,7,-2,log)
B(0,7,-1,stone)
B(0,7,0,log)
B(0,7,1,log2)
B(0,7,2,LOG:1)
B(0,7,3,stone)
B(0,7,4,stone)
B(0,7,5,stone)
B(0,7,6,stone)
B(0,7,7,concrete:15)
B(0,7,8,concrete:15)
B(0,8,-7,concrete:15)
B(0,8,-6,concrete:15)
B(0,8,-5,concrete:15)
B(0,8,-4,concrete:15)
B(0,8,-3,stone)
B(0,8,-2,log2:1)
B(0,8,-1,stone)
B(0,8,0,stone)
B(0,8,1,log)
B(0,8,2,log)
B(0,8,3,stone)
B(0,8,4,stone)
B(0,8,5,stone)
B(0,8,6,concrete:15)
B(0,8,7,concrete:15)
B(0,8,8,concrete:15)
B(0,9,-7,Leaves:7)
B(0,9,-6,LOG:13)
B(0,9,-5,LOG:13)
B(0,9,-4,LOG:13)
B(0,9,-3,stone)
B(0,9,-2,stone)
B(0,9,-1,LOG:1)
B(0,9,0,log:2)
B(0,9,1,stone)
B(0,9,2,stone)
B(0,9,3,stone)
B(0,9,4,stone)
B(0,9,5,LOG:13)
B(0,9,6,concrete:15)
B(0,9,7,concrete:15)
B(0,10,-5,LOG:13)
B(0,10,-4,LOG:13)
B(0,10,-3,LOG:1)
B(0,10,-2,stone)
B(0,10,-1,stone)
B(0,10,0,stone)
B(0,10,1,log:2)
B(0,10,2,stone)
B(0,10,3,log2)
B(0,10,4,LOG:13)
B(0,10,5,LOG:13)
B(0,11,-5,LOG:13)
B(0,11,-4,LOG:13)
B(0,11,-3,stone)
B(0,11,-2,log:2)
B(0,11,-1,log2)
B(0,11,0,stone)
B(0,11,1,stone)
B(0,11,2,log2)
B(0,11,3,stone)
B(0,11,4,LOG:13)
B(0,11,5,LOG:13)
B(0,12,-5,LOG:13)
B(0,12,-4,stone)
B(0,12,-3,stone)
B(0,12,-2,LOG:1)
B(0,12,-1,stone)
B(0,12,0,LOG:1)
B(0,12,1,log2)
B(0,12,2,stone)
B(0,12,3,stone)
B(0,12,4,LOG:13)
B(0,12,5,LOG:13)
B(0,12,6,Leaves:7)
B(0,13,-5,LOG:13)
B(0,13,-4,LOG:13)
B(0,13,-3,stone)
B(0,13,-2,stone)
B(0,13,-1,log2)
B(0,13,0,stone)
B(0,13,1,log2:1)
B(0,13,2,log)
B(0,13,3,stone)
B(0,13,4,LOG:13)
B(0,13,5,LOG:13)
B(0,14,-5,LOG:13)
B(0,14,-4,LOG:13)
B(0,14,-3,stone)
B(0,14,-2,stone)
B(0,14,-1,LOG:1)
B(0,14,0,stone)
B(0,14,1,stone)
B(0,14,2,stone)
B(0,14,3,concrete:15)
B(0,14,4,LOG:13)
B(0,14,5,LOG:13)
B(0,15,-5,LOG:13)
B(0,15,-4,LOG:13)
B(0,15,-3,stone)
B(0,15,-2,stone)
B(0,15,-1,stone)
B(0,15,0,log:2)
B(0,15,1,stone)
B(0,15,2,stone)
B(0,15,3,stone)
B(0,15,4,LOG:13)
B(0,15,5,LOG:13)
B(0,16,-5,LOG:13)
B(0,16,-4,LOG:13)
B(0,16,-3,stone)
B(0,16,-2,stone)
B(0,16,-1,log)
B(0,16,0,LOG:1)
B(0,16,1,stone)
B(0,16,2,log)
B(0,16,3,LOG:13)
B(0,16,4,LOG:13)
B(0,16,5,LOG:13)
B(0,16,6,Leaves:7)
B(0,17,-5,LOG:13)
B(0,17,-4,stone)
B(0,17,-3,stone)
B(0,17,-2,stone)
B(0,17,-1,stone)
B(0,17,0,log:2)
B(0,17,1,stone)
B(0,17,2,stone)
B(0,17,3,LOG:13)
B(0,17,4,LOG:13)
B(0,17,5,LOG:13)
B(0,18,-6,concrete:15)
B(0,18,-5,concrete:15)
B(0,18,-4,stone)
B(0,18,-3,stone)
B(0,18,-2,stone)
B(0,18,-1,stone)
B(0,18,0,stone)
B(0,18,1,stone)
B(0,18,2,stone)
B(0,18,3,LOG:13)
B(0,18,4,LOG:13)
B(0,18,5,LOG:13)
B(0,18,6,concrete:15)
B(0,19,-7,concrete:15)
B(0,19,-6,concrete:15)
B(0,19,-5,stone)
B(0,19,-4,log:2)
B(0,19,-3,log)
B(0,19,-2,stone)
B(0,19,-1,stone)
B(0,19,0,log2)
B(0,19,1,stone)
B(0,19,2,stone)
B(0,19,3,stone)
B(0,19,4,stone)
B(0,19,5,concrete:15)
B(0,19,6,concrete:15)
B(0,19,7,concrete:15)
B(0,20,-8,concrete:15)
B(0,20,-7,concrete:15)
B(0,20,-6,concrete:15)
B(0,20,-5,stone)
B(0,20,-4,stone)
B(0,20,-3,LOG:1)
B(0,20,-2,log)
B(0,20,-1,log)
B(0,20,0,stone)
B(0,20,1,stone)
B(0,20,2,stone)
B(0,20,3,log2:1)
B(0,20,4,stone)
B(0,20,5,concrete:15)
B(0,20,6,concrete:15)
B(0,20,7,concrete:15)
B(0,21,-9,stone)
B(0,21,-8,stone)
B(0,21,-7,stone)
B(0,21,-6,stone)
B(0,21,-5,log2)
B(0,21,-4,stone)
B(0,21,-3,log:2)
B(0,21,-2,LOG:1)
B(0,21,-1,stone)
B(0,21,0,log2)
B(0,21,1,stone)
B(0,21,2,stone)
B(0,21,3,stone)
B(0,21,4,stone)
B(0,21,5,stone)
B(0,21,6,concrete:15)
B(0,21,7,concrete:15)
B(0,22,-10,stone)
B(0,22,-9,stone)
B(0,22,-8,stone)
B(0,22,-7,stone)
B(0,22,-6,stone)
B(0,22,-5,LOG:1)
B(0,22,-4,stone)
B(0,22,-3,stone)
B(0,22,-2,log2)
B(0,22,-1,log)
B(0,22,0,stone)
B(0,22,1,log)
B(0,22,2,log:2)
B(0,22,3,log:2)
B(0,22,4,LOG:1)
B(0,22,5,stone)
B(0,22,6,stone)
B(0,22,7,concrete:15)
B(0,22,8,LOG:13)
B(0,23,-11,stone)
B(0,23,-10,stone)
B(0,23,-9,stone)
B(0,23,-8,stone)
B(0,23,-7,stone)
B(0,23,-6,stone)
B(0,23,-5,stone)
B(0,23,-4,log:2)
B(0,23,-3,stone)
B(0,23,-2,log:2)
B(0,23,-1,log2:1)
B(0,23,0,stone)
B(0,23,1,stone)
B(0,23,2,log)
B(0,23,3,stone)
B(0,23,4,stone)
B(0,23,5,log:2)
B(0,23,6,LOG:1)
B(0,23,7,stone)
B(0,23,8,LOG:13)
B(0,23,9,LOG:13)
B(0,23,10,Leaves:7)
B(0,24,-12,stone)
B(0,24,-11,stone)
B(0,24,-10,stone)
B(0,24,-9,stone)
B(0,24,-8,stone)
B(0,24,-7,stone)
B(0,24,-6,stone)
B(0,24,-5,stone)
B(0,24,-4,log2)
B(0,24,-3,stone)
B(0,24,-2,stone)
B(0,24,-1,stone)
B(0,24,0,stone)
B(0,24,1,stone)
B(0,24,2,stone)
B(0,24,3,stone)
B(0,24,4,stone)
B(0,24,5,stone)
B(0,24,6,log:2)
B(0,24,7,stone)
B(0,24,8,stone)
B(0,24,9,LOG:13)
B(0,24,10,LOG:13)
B(0,25,-13,stone)
B(0,25,-12,stone)
B(0,25,-11,stone)
B(0,25,-10,stone)
B(0,25,-9,stone)
B(0,25,-8,stone)
B(0,25,-7,stone)
B(0,25,-6,stone)
B(0,25,-5,LOG:1)
B(0,25,-4,log2:1)
B(0,25,-3,stone)
B(0,25,-2,stone)
B(0,25,-1,stone)
B(0,25,0,stone)
B(0,25,1,log)
B(0,25,2,stone)
B(0,25,3,stone)
B(0,25,4,LOG:1)
B(0,25,5,stone)
B(0,25,6,stone)
B(0,25,7,stone)
B(0,25,8,stone)
B(0,25,9,stone)
B(0,25,10,LOG:13)
B(0,25,11,concrete:15)
B(0,26,-13,stone)
B(0,26,-12,stone)
B(0,26,-11,stone)
B(0,26,-10,stone)
B(0,26,-9,stone)
B(0,26,-8,stone)
B(0,26,-7,log)
B(0,26,-6,stone)
B(0,26,-5,stone)
B(0,26,-4,log2)
B(0,26,-3,log)
B(0,26,-2,stone)
B(0,26,-1,log)
B(0,26,0,log)
B(0,26,1,stone)
B(0,26,2,stone)
B(0,26,3,log:2)
B(0,26,4,stone)
B(0,26,5,stone)
B(0,26,6,stone)
B(0,26,7,stone)
B(0,26,8,stone)
B(0,26,9,stone)
B(0,26,10,concrete:15)
B(0,26,11,concrete:15)
B(0,27,-12,stone)
B(0,27,-11,stone)
B(0,27,-10,stone)
B(0,27,-9,stone)
B(0,27,-8,stone)
B(0,27,-7,log2:1)
B(0,27,-6,log:2)
B(0,27,-5,LOG:1)
B(0,27,-4,stone)
B(0,27,-3,stone)
B(0,27,-2,stone)
B(0,27,-1,stone)
B(0,27,0,log:2)
B(0,27,1,stone)
B(0,27,2,stone)
B(0,27,3,stone)
B(0,27,4,stone)
B(0,27,5,stone)
B(0,27,6,log)
B(0,27,7,stone)
B(0,27,8,stone)
B(0,27,9,stone)
B(0,27,10,stone)
B(1,0,-12,stone)
B(1,0,-11,stone)
B(1,0,-10,stone)
B(1,0,-9,stone)
B(1,0,-8,stone)
B(1,0,-7,stone)
B(1,0,-6,stone)
B(1,0,-5,stone)
B(1,0,-4,stone)
B(1,0,-3,stone)
B(1,0,-2,stone)
B(1,0,-1,stone)
B(1,0,0,stone)
B(1,0,1,stone)
B(1,0,2,stone)
B(1,0,3,stone)
B(1,0,4,stone)
B(1,0,5,stone)
B(1,0,6,stone)
B(1,0,7,stone)
B(1,0,8,stone)
B(1,0,9,stone)
B(1,0,10,stone)
B(1,0,11,stone)
B(1,0,12,concrete:15)
B(1,0,13,concrete:15)
B(1,1,-11,stone)
B(1,1,-10,stone)
B(1,1,-9,stone)
B(1,1,-8,stone)
B(1,1,-7,stone)
B(1,1,-6,log2:1)
B(1,1,-5,stone)
B(1,1,-4,stone)
B(1,1,-3,stone)
B(1,1,-2,log:2)
B(1,1,-1,log)
B(1,1,0,stone)
B(1,1,1,log)
B(1,1,2,log2)
B(1,1,3,log2:1)
B(1,1,4,stone)
B(1,1,5,stone)
B(1,1,6,stone)
B(1,1,7,stone)
B(1,1,8,stone)
B(1,1,9,stone)
B(1,1,10,concrete:15)
B(1,1,11,concrete:15)
B(1,1,12,concrete:15)
B(1,2,-10,stone)
B(1,2,-9,stone)
B(1,2,-8,stone)
B(1,2,-7,stone)
B(1,2,-6,stone)
B(1,2,-5,stone)
B(1,2,-4,stone)
B(1,2,-3,log)
B(1,2,-2,log2:1)
B(1,2,-1,stone)
B(1,2,0,log2)
B(1,2,1,log:2)
B(1,2,2,stone)
B(1,2,3,stone)
B(1,2,4,LOG:1)
B(1,2,5,stone)
B(1,2,6,stone)
B(1,2,7,stone)
B(1,2,8,stone)
B(1,2,9,stone)
B(1,2,10,concrete:15)
B(1,2,11,LOG:13)
B(1,2,12,concrete:15)
B(1,3,-10,stone)
B(1,3,-9,stone)
B(1,3,-8,stone)
B(1,3,-7,LOG:1)
B(1,3,-6,log)
B(1,3,-5,stone)
B(1,3,-4,stone)
B(1,3,-3,stone)
B(1,3,-2,log2)
B(1,3,-1,stone)
B(1,3,0,stone)
B(1,3,1,log:2)
B(1,3,2,LOG:1)
B(1,3,3,log:2)
B(1,3,4,stone)
B(1,3,5,stone)
B(1,3,6,stone)
B(1,3,7,stone)
B(1,3,8,LOG:13)
B(1,3,9,LOG:13)
B(1,3,10,LOG:13)
B(1,3,11,Leaves:7)
B(1,4,-10,stone)
B(1,4,-9,stone)
B(1,4,-8,stone)
B(1,4,-7,stone)
B(1,4,-6,stone)
B(1,4,-5,stone)
B(1,4,-4,stone)
B(1,4,-3,log:2)
B(1,4,-2,stone)
B(1,4,-1,stone)
B(1,4,0,log)
B(1,4,1,stone)
B(1,4,2,stone)
B(1,4,3,stone)
B(1,4,4,stone)
B(1,4,5,stone)
B(1,4,6,stone)
B(1,4,7,stone)
B(1,4,8,LOG:13)
B(1,4,9,LOG:13)
B(1,5,-9,stone)
B(1,5,-8,stone)
B(1,5,-7,stone)
B(1,5,-6,stone)
B(1,5,-5,stone)
B(1,5,-4,stone)
B(1,5,-3,stone)
B(1,5,-2,log:2)
B(1,5,-1,stone)
B(1,5,0,stone)
B(1,5,1,stone)
B(1,5,2,stone)
B(1,5,3,stone)
B(1,5,4,stone)
B(1,5,5,stone)
B(1,5,6,stone)
B(1,5,7,LOG:13)
B(1,5,8,LOG:13)
B(1,5,9,LOG:13)
B(1,5,10,Leaves:7)
B(1,6,-7,concrete:15)
B(1,6,-6,stone)
B(1,6,-5,stone)
B(1,6,-4,stone)
B(1,6,-3,stone)
B(1,6,-2,LOG:1)
B(1,6,-1,stone)
B(1,6,0,log2:1)
B(1,6,1,stone)
B(1,6,2,stone)
B(1,6,3,log)
B(1,6,4,stone)
B(1,6,5,stone)
B(1,6,6,LOG:13)
B(1,6,7,LOG:13)
B(1,6,8,LOG:13)
B(1,6,9,Leaves:7)
B(1,7,-7,concrete:15)
B(1,7,-6,concrete:15)
B(1,7,-5,LOG:13)
B(1,7,-4,concrete:15)
B(1,7,-3,log2:1)
B(1,7,-2,stone)
B(1,7,-1,stone)
B(1,7,0,stone)
B(1,7,1,log:2)
B(1,7,2,stone)
B(1,7,3,stone)
B(1,7,4,log2)
B(1,7,5,stone)
B(1,7,6,LOG:13)
B(1,7,7,LOG:13)
B(1,7,8,concrete:15)
B(1,8,-5,LOG:13)
B(1,8,-4,LOG:13)
B(1,8,-3,stone)
B(1,8,-2,stone)
B(1,8,-1,stone)
B(1,8,0,LOG:1)
B(1,8,1,stone)
B(1,8,2,stone)
B(1,8,3,stone)
B(1,8,4,stone)
B(1,8,5,LOG:13)
B(1,8,6,LOG:13)
B(1,8,7,LOG:13)
B(1,8,8,concrete:15)
B(1,9,-5,LOG:13)
B(1,9,-4,concrete:15)
B(1,9,-3,stone)
B(1,9,-2,stone)
B(1,9,-1,stone)
B(1,9,0,stone)
B(1,9,1,stone)
B(1,9,2,log)
B(1,9,3,stone)
B(1,9,4,LOG:13)
B(1,9,5,LOG:13)
B(1,9,6,LOG:13)
B(1,9,7,concrete:15)
B(1,10,-6,Leaves:7)
B(1,10,-5,LOG:13)
B(1,10,-4,LOG:13)
B(1,10,-3,stone)
B(1,10,-2,stone)
B(1,10,-1,stone)
B(1,10,0,stone)
B(1,10,1,stone)
B(1,10,2,stone)
B(1,10,3,concrete:15)
B(1,10,4,LOG:13)
B(1,10,5,LOG:13)
B(1,10,6,Leaves:7)
B(1,11,-5,LOG:13)
B(1,11,-4,LOG:13)
B(1,11,-3,stone)
B(1,11,-2,log)
B(1,11,-1,log:2)
B(1,11,0,log)
B(1,11,1,stone)
B(1,11,2,log:2)
B(1,11,3,stone)
B(1,11,4,LOG:13)
B(1,11,5,LOG:13)
B(1,12,-5,LOG:13)
B(1,12,-4,LOG:13)
B(1,12,-3,stone)
B(1,12,-2,stone)
B(1,12,-1,log2)
B(1,12,0,log)
B(1,12,1,stone)
B(1,12,2,stone)
B(1,12,3,concrete:15)
B(1,12,4,LOG:13)
B(1,12,5,LOG:13)
B(1,13,-6,Leaves:7)
B(1,13,-5,LOG:13)
B(1,13,-4,LOG:13)
B(1,13,-3,concrete:15)
B(1,13,-2,stone)
B(1,13,-1,stone)
B(1,13,0,stone)
B(1,13,1,stone)
B(1,13,2,stone)
B(1,13,3,concrete:15)
B(1,13,4,LOG:13)
B(1,13,5,Leaves:7)
B(1,14,-5,LOG:13)
B(1,14,-4,LOG:13)
B(1,14,-3,stone)
B(1,14,-2,log:2)
B(1,14,-1,stone)
B(1,14,0,stone)
B(1,14,1,stone)
B(1,14,2,stone)
B(1,14,3,concrete:15)
B(1,14,4,concrete:15)
B(1,14,5,LOG:13)
B(1,14,6,Leaves:7)
B(1,15,-5,LOG:13)
B(1,15,-4,LOG:13)
B(1,15,-3,concrete:15)
B(1,15,-2,stone)
B(1,15,-1,stone)
B(1,15,0,LOG:1)
B(1,15,1,stone)
B(1,15,2,stone)
B(1,15,3,concrete:15)
B(1,15,4,LOG:13)
B(1,15,5,LOG:13)
B(1,15,6,Leaves:7)
B(1,16,-6,Leaves:7)
B(1,16,-5,LOG:13)
B(1,16,-4,LOG:13)
B(1,16,-3,concrete:15)
B(1,16,-2,stone)
B(1,16,-1,stone)
B(1,16,0,stone)
B(1,16,1,log)
B(1,16,2,log:2)
B(1,16,3,concrete:15)
B(1,16,4,LOG:13)
B(1,16,5,LOG:13)
B(1,16,6,Leaves:7)
B(1,16,7,Leaves:7)
B(1,17,-6,LOG:13)
B(1,17,-5,LOG:13)
B(1,17,-4,LOG:13)
B(1,17,-3,log:2)
B(1,17,-2,log)
B(1,17,-1,stone)
B(1,17,0,stone)
B(1,17,1,stone)
B(1,17,2,stone)
B(1,17,3,LOG:13)
B(1,17,4,LOG:13)
B(1,17,5,Leaves:7)
B(1,17,6,Leaves:7)
B(1,18,-7,concrete:15)
B(1,18,-6,concrete:15)
B(1,18,-5,LOG:13)
B(1,18,-4,concrete:15)
B(1,18,-3,stone)
B(1,18,-2,stone)
B(1,18,-1,stone)
B(1,18,0,LOG:1)
B(1,18,1,log2)
B(1,18,2,stone)
B(1,18,3,concrete:15)
B(1,18,4,LOG:13)
B(1,18,5,LOG:13)
B(1,18,6,Leaves:7)
B(1,19,-9,concrete:15)
B(1,19,-8,concrete:15)
B(1,19,-7,concrete:15)
B(1,19,-6,concrete:15)
B(1,19,-5,concrete:15)
B(1,19,-4,stone)
B(1,19,-3,log)
B(1,19,-2,log2)
B(1,19,-1,stone)
B(1,19,0,stone)
B(1,19,1,stone)
B(1,19,2,log2:1)
B(1,19,3,stone)
B(1,19,4,concrete:15)
B(1,19,5,concrete:15)
B(1,19,6,LOG:13)
B(1,20,-9,concrete:15)
B(1,20,-8,concrete:15)
B(1,20,-7,concrete:15)
B(1,20,-6,stone)
B(1,20,-5,stone)
B(1,20,-4,log2)
B(1,20,-3,stone)
B(1,20,-2,stone)
B(1,20,-1,LOG:1)
B(1,20,0,stone)
B(1,20,1,stone)
B(1,20,2,log2:1)
B(1,20,3,stone)
B(1,20,4,stone)
B(1,20,5,concrete:15)
B(1,20,6,LOG:13)
B(1,20,7,Leaves:7)
B(1,20,8,Leaves:7)
B(1,21,-10,stone)
B(1,21,-9,stone)
B(1,21,-8,stone)
B(1,21,-7,stone)
B(1,21,-6,stone)
B(1,21,-5,log:2)
B(1,21,-4,stone)
B(1,21,-3,stone)
B(1,21,-2,log2)
B(1,21,-1,log:2)
B(1,21,0,stone)
B(1,21,1,stone)
B(1,21,2,log)
B(1,21,3,log:2)
B(1,21,4,log2)
B(1,21,5,concrete:15)
B(1,21,6,concrete:15)
B(1,21,7,LOG:13)
B(1,21,8,LOG:13)
B(1,21,9,Leaves:7)
B(1,22,-10,stone)
B(1,22,-9,stone)
B(1,22,-8,stone)
B(1,22,-7,stone)
B(1,22,-6,stone)
B(1,22,-5,log)
B(1,22,-4,stone)
B(1,22,-3,stone)
B(1,22,-2,log2:1)
B(1,22,-1,stone)
B(1,22,0,stone)
B(1,22,1,log:2)
B(1,22,2,stone)
B(1,22,3,stone)
B(1,22,4,log)
B(1,22,5,stone)
B(1,22,6,stone)
B(1,22,7,stone)
B(1,22,8,LOG:13)
B(1,22,9,LOG:13)
B(1,23,-11,stone)
B(1,23,-10,stone)
B(1,23,-9,stone)
B(1,23,-8,stone)
B(1,23,-7,stone)
B(1,23,-6,stone)
B(1,23,-5,stone)
B(1,23,-4,stone)
B(1,23,-3,stone)
B(1,23,-2,stone)
B(1,23,-1,stone)
B(1,23,0,stone)
B(1,23,1,stone)
B(1,23,2,stone)
B(1,23,3,stone)
B(1,23,4,log)
B(1,23,5,stone)
B(1,23,6,stone)
B(1,23,7,stone)
B(1,23,8,LOG:13)
B(1,23,9,LOG:13)
B(1,24,-12,stone)
B(1,24,-11,stone)
B(1,24,-10,stone)
B(1,24,-9,stone)
B(1,24,-8,stone)
B(1,24,-7,stone)
B(1,24,-6,stone)
B(1,24,-5,stone)
B(1,24,-4,stone)
B(1,24,-3,stone)
B(1,24,-2,log:2)
B(1,24,-1,stone)
B(1,24,0,stone)
B(1,24,1,stone)
B(1,24,2,stone)
B(1,24,3,log2)
B(1,24,4,stone)
B(1,24,5,log2)
B(1,24,6,stone)
B(1,24,7,stone)
B(1,24,8,stone)
B(1,24,9,concrete:15)
B(1,25,-12,stone)
B(1,25,-11,stone)
B(1,25,-10,stone)
B(1,25,-9,stone)
B(1,25,-8,stone)
B(1,25,-7,log:2)
B(1,25,-6,stone)
B(1,25,-5,stone)
B(1,25,-4,stone)
B(1,25,-3,stone)
B(1,25,-2,log)
B(1,25,-1,log:2)
B(1,25,0,stone)
B(1,25,1,stone)
B(1,25,2,stone)
B(1,25,3,log:2)
B(1,25,4,log2)
B(1,25,5,LOG:1)
B(1,25,6,stone)
B(1,25,7,stone)
B(1,25,8,stone)
B(1,25,9,stone)
B(1,25,10,concrete:15)
B(1,25,11,concrete:15)
B(1,26,-12,stone)
B(1,26,-11,stone)
B(1,26,-10,stone)
B(1,26,-9,stone)
B(1,26,-8,stone)
B(1,26,-7,stone)
B(1,26,-6,log:2)
B(1,26,-5,LOG:1)
B(1,26,-4,LOG:1)
B(1,26,-3,stone)
B(1,26,-2,stone)
B(1,26,-1,stone)
B(1,26,0,stone)
B(1,26,1,stone)
B(1,26,2,LOG:1)
B(1,26,3,stone)
B(1,26,4,stone)
B(1,26,5,stone)
B(1,26,6,stone)
B(1,26,7,stone)
B(1,26,8,log2)
B(1,26,9,stone)
B(1,26,10,concrete:15)
B(1,26,11,concrete:15)
B(1,27,-11,stone)
B(1,27,-10,stone)
B(1,27,-9,stone)
B(1,27,-8,log2:1)
B(1,27,-7,LOG:1)
B(1,27,-6,stone)
B(1,27,-5,stone)
B(1,27,-4,stone)
B(1,27,-3,stone)
B(1,27,-2,log2)
B(1,27,-1,stone)
B(1,27,0,stone)
B(1,27,1,stone)
B(1,27,2,stone)
B(1,27,3,log2)
B(1,27,4,stone)
B(1,27,5,stone)
B(1,27,6,stone)
B(1,27,7,stone)
B(1,27,8,stone)
B(1,27,9,stone)
B(1,27,10,stone)
B(1,27,11,stone)
B(2,0,-12,stone)
B(2,0,-11,stone)
B(2,0,-10,stone)
B(2,0,-9,stone)
B(2,0,-8,stone)
B(2,0,-7,stone)
B(2,0,-6,stone)
B(2,0,-5,stone)
B(2,0,-4,stone)
B(2,0,-3,stone)
B(2,0,-2,stone)
B(2,0,-1,stone)
B(2,0,0,stone)
B(2,0,1,stone)
B(2,0,2,stone)
B(2,0,3,stone)
B(2,0,4,stone)
B(2,0,5,stone)
B(2,0,6,stone)
B(2,0,7,stone)
B(2,0,8,stone)
B(2,0,9,stone)
B(2,0,10,stone)
B(2,0,11,stone)
B(2,0,12,stone)
B(2,0,13,stone)
B(2,1,-11,stone)
B(2,1,-10,stone)
B(2,1,-9,stone)
B(2,1,-8,stone)
B(2,1,-7,stone)
B(2,1,-6,stone)
B(2,1,-5,stone)
B(2,1,-4,stone)
B(2,1,-3,stone)
B(2,1,-2,stone)
B(2,1,-1,LOG:1)
B(2,1,0,stone)
B(2,1,1,log:2)
B(2,1,2,stone)
B(2,1,3,stone)
B(2,1,4,stone)
B(2,1,5,stone)
B(2,1,6,stone)
B(2,1,7,stone)
B(2,1,8,stone)
B(2,1,9,stone)
B(2,1,10,stone)
B(2,1,11,concrete:15)
B(2,1,12,concrete:15)
B(2,2,-10,stone)
B(2,2,-9,stone)
B(2,2,-8,stone)
B(2,2,-7,log)
B(2,2,-6,stone)
B(2,2,-5,stone)
B(2,2,-4,stone)
B(2,2,-3,stone)
B(2,2,-2,stone)
B(2,2,-1,log)
B(2,2,0,log)
B(2,2,1,stone)
B(2,2,2,stone)
B(2,2,3,stone)
B(2,2,4,stone)
B(2,2,5,stone)
B(2,2,6,stone)
B(2,2,7,stone)
B(2,2,8,stone)
B(2,2,9,stone)
B(2,2,10,concrete:15)
B(2,2,11,concrete:15)
B(2,3,-10,stone)
B(2,3,-9,stone)
B(2,3,-8,stone)
B(2,3,-7,stone)
B(2,3,-6,stone)
B(2,3,-5,stone)
B(2,3,-4,log)
B(2,3,-3,stone)
B(2,3,-2,stone)
B(2,3,-1,stone)
B(2,3,0,stone)
B(2,3,1,stone)
B(2,3,2,log:2)
B(2,3,3,log:2)
B(2,3,4,stone)
B(2,3,5,stone)
B(2,3,6,stone)
B(2,3,7,stone)
B(2,3,8,concrete:15)
B(2,3,9,LOG:13)
B(2,3,10,concrete:15)
B(2,4,-10,stone)
B(2,4,-9,stone)
B(2,4,-8,stone)
B(2,4,-7,stone)
B(2,4,-6,stone)
B(2,4,-5,stone)
B(2,4,-4,log2)
B(2,4,-3,stone)
B(2,4,-2,log)
B(2,4,-1,log2:1)
B(2,4,0,stone)
B(2,4,1,stone)
B(2,4,2,stone)
B(2,4,3,log:2)
B(2,4,4,stone)
B(2,4,5,stone)
B(2,4,6,stone)
B(2,4,7,concrete:15)
B(2,4,8,LOG:13)
B(2,4,9,LOG:13)
B(2,4,10,LOG:13)
B(2,5,-9,stone)
B(2,5,-8,stone)
B(2,5,-7,stone)
B(2,5,-6,stone)
B(2,5,-5,stone)
B(2,5,-4,stone)
B(2,5,-3,stone)
B(2,5,-2,stone)
B(2,5,-1,stone)
B(2,5,0,log)
B(2,5,1,log:2)
B(2,5,2,log2:1)
B(2,5,3,stone)
B(2,5,4,stone)
B(2,5,5,stone)
B(2,5,6,LOG:13)
B(2,5,7,LOG:13)
B(2,5,8,LOG:13)
B(2,5,9,Leaves:7)
B(2,6,-8,concrete:15)
B(2,6,-7,concrete:15)
B(2,6,-6,LOG:13)
B(2,6,-5,stone)
B(2,6,-4,log)
B(2,6,-3,log2)
B(2,6,-2,log)
B(2,6,-1,stone)
B(2,6,0,stone)
B(2,6,1,stone)
B(2,6,2,log2:1)
B(2,6,3,log:2)
B(2,6,4,stone)
B(2,6,5,stone)
B(2,6,6,LOG:13)
B(2,6,7,LOG:13)
B(2,7,-7,LOG:13)
B(2,7,-6,LOG:13)
B(2,7,-5,LOG:13)
B(2,7,-4,LOG:13)
B(2,7,-3,log)
B(2,7,-2,log:2)
B(2,7,-1,stone)
B(2,7,0,stone)
B(2,7,1,stone)
B(2,7,2,log2:1)
B(2,7,3,stone)
B(2,7,4,stone)
B(2,7,5,LOG:13)
B(2,7,6,LOG:13)
B(2,7,7,LOG:13)
B(2,8,-5,LOG:13)
B(2,8,-4,LOG:13)
B(2,8,-3,stone)
B(2,8,-2,stone)
B(2,8,-1,stone)
B(2,8,0,stone)
B(2,8,1,stone)
B(2,8,2,stone)
B(2,8,3,stone)
B(2,8,4,stone)
B(2,8,5,LOG:13)
B(2,8,6,LOG:13)
B(2,8,7,LOG:13)
B(2,9,-5,LOG:13)
B(2,9,-4,LOG:13)
B(2,9,-3,stone)
B(2,9,-2,stone)
B(2,9,-1,stone)
B(2,9,0,log2:1)
B(2,9,1,LOG:1)
B(2,9,2,log)
B(2,9,3,concrete:15)
B(2,9,4,concrete:15)
B(2,9,5,LOG:13)
B(2,10,-5,Leaves:7)
B(2,10,-4,concrete:15)
B(2,10,-3,concrete:15)
B(2,10,-2,concrete:15)
B(2,10,-1,stone)
B(2,10,0,stone)
B(2,10,1,stone)
B(2,10,2,concrete:15)
B(2,10,3,concrete:15)
B(2,10,4,LOG:13)
B(2,10,5,LOG:13)
B(2,11,-4,LOG:13)
B(2,11,-3,concrete:15)
B(2,11,-2,concrete:15)
B(2,11,-1,concrete:15)
B(2,11,0,stone)
B(2,11,1,stone)
B(2,11,2,log2:1)
B(2,11,3,concrete:15)
B(2,11,4,concrete:15)
B(2,12,-5,LOG:13)
B(2,12,-4,concrete:15)
B(2,12,-3,concrete:15)
B(2,12,-2,concrete:15)
B(2,12,-1,log2:1)
B(2,12,0,log2:1)
B(2,12,1,stone)
B(2,12,2,log)
B(2,12,3,concrete:15)
B(2,12,4,concrete:15)
B(2,13,-5,LOG:13)
B(2,13,-4,LOG:13)
B(2,13,-3,concrete:15)
B(2,13,-2,log2:1)
B(2,13,-1,stone)
B(2,13,0,stone)
B(2,13,1,stone)
B(2,13,2,log2:1)
B(2,13,3,concrete:15)
B(2,13,4,concrete:15)
B(2,14,-4,concrete:15)
B(2,14,-3,concrete:15)
B(2,14,-2,stone)
B(2,14,-1,log:2)
B(2,14,0,log2)
B(2,14,1,stone)
B(2,14,2,stone)
B(2,14,3,concrete:15)
B(2,14,4,concrete:15)
B(2,14,5,Leaves:7)
B(2,15,-4,LOG:13)
B(2,15,-3,concrete:15)
B(2,15,-2,log2)
B(2,15,-1,stone)
B(2,15,0,stone)
B(2,15,1,log2)
B(2,15,2,stone)
B(2,15,3,stone)
B(2,15,4,concrete:15)
B(2,16,-6,Leaves:7)
B(2,16,-5,LOG:13)
B(2,16,-4,LOG:13)
B(2,16,-3,concrete:15)
B(2,16,-2,stone)
B(2,16,-1,stone)
B(2,16,0,stone)
B(2,16,1,log:2)
B(2,16,2,stone)
B(2,16,3,stone)
B(2,16,4,concrete:15)
B(2,16,5,concrete:15)
B(2,16,6,Leaves:7)
B(2,17,-7,Leaves:7)
B(2,17,-6,LOG:13)
B(2,17,-5,LOG:13)
B(2,17,-4,LOG:13)
B(2,17,-3,concrete:15)
B(2,17,-2,stone)
B(2,17,-1,stone)
B(2,17,0,log:2)
B(2,17,1,stone)
B(2,17,2,stone)
B(2,17,3,concrete:15)
B(2,17,4,concrete:15)
B(2,17,6,Leaves:7)
B(2,18,-6,LOG:13)
B(2,18,-5,LOG:13)
B(2,18,-4,LOG:13)
B(2,18,-3,concrete:15)
B(2,18,-2,log)
B(2,18,-1,stone)
B(2,18,0,LOG:1)
B(2,18,1,stone)
B(2,18,2,stone)
B(2,18,3,stone)
B(2,18,4,concrete:15)
B(2,18,5,LOG:13)
B(2,18,6,LOG:13)
B(2,18,7,Leaves:7)
B(2,19,-8,concrete:15)
B(2,19,-7,concrete:15)
B(2,19,-6,concrete:15)
B(2,19,-5,concrete:15)
B(2,19,-4,log:2)
B(2,19,-3,log2:1)
B(2,19,-2,log2)
B(2,19,-1,log)
B(2,19,0,stone)
B(2,19,1,stone)
B(2,19,2,stone)
B(2,19,3,log)
B(2,19,4,stone)
B(2,19,5,LOG:13)
B(2,19,6,LOG:13)
B(2,19,7,Leaves:7)
B(2,20,-8,concrete:15)
B(2,20,-7,concrete:15)
B(2,20,-6,stone)
B(2,20,-5,stone)
B(2,20,-4,log2:1)
B(2,20,-3,LOG:1)
B(2,20,-2,LOG:1)
B(2,20,-1,stone)
B(2,20,0,LOG:1)
B(2,20,1,log:2)
B(2,20,2,log2)
B(2,20,3,stone)
B(2,20,4,stone)
B(2,20,5,concrete:15)
B(2,20,6,LOG:13)
B(2,20,7,LOG:13)
B(2,20,8,Leaves:7)
B(2,21,-9,stone)
B(2,21,-8,concrete:15)
B(2,21,-7,stone)
B(2,21,-6,stone)
B(2,21,-5,stone)
B(2,21,-4,stone)
B(2,21,-3,stone)
B(2,21,-2,stone)
B(2,21,-1,stone)
B(2,21,0,stone)
B(2,21,1,stone)
B(2,21,2,log)
B(2,21,3,stone)
B(2,21,4,stone)
B(2,21,5,stone)
B(2,21,6,LOG:13)
B(2,21,7,LOG:13)
B(2,21,8,Leaves:7)
B(2,22,-10,stone)
B(2,22,-9,stone)
B(2,22,-8,stone)
B(2,22,-7,stone)
B(2,22,-6,stone)
B(2,22,-5,stone)
B(2,22,-4,log2:1)
B(2,22,-3,stone)
B(2,22,-2,stone)
B(2,22,-1,LOG:1)
B(2,22,0,stone)
B(2,22,1,log)
B(2,22,2,log2:1)
B(2,22,3,log:2)
B(2,22,4,LOG:1)
B(2,22,5,stone)
B(2,22,6,stone)
B(2,22,7,stone)
B(2,22,8,LOG:13)
B(2,22,9,LOG:13)
B(2,23,-11,stone)
B(2,23,-10,stone)
B(2,23,-9,stone)
B(2,23,-8,stone)
B(2,23,-7,stone)
B(2,23,-6,stone)
B(2,23,-5,log:2)
B(2,23,-4,log2:1)
B(2,23,-3,log2:1)
B(2,23,-2,stone)
B(2,23,-1,stone)
B(2,23,0,stone)
B(2,23,1,stone)
B(2,23,2,log)
B(2,23,3,log2)
B(2,23,4,stone)
B(2,23,5,stone)
B(2,23,6,log)
B(2,23,7,stone)
B(2,23,8,concrete:15)
B(2,23,9,LOG:13)
B(2,24,-11,stone)
B(2,24,-10,stone)
B(2,24,-9,stone)
B(2,24,-8,stone)
B(2,24,-7,stone)
B(2,24,-6,stone)
B(2,24,-5,log2)
B(2,24,-4,stone)
B(2,24,-3,stone)
B(2,24,-2,stone)
B(2,24,-1,stone)
B(2,24,0,stone)
B(2,24,1,log2:1)
B(2,24,2,stone)
B(2,24,3,stone)
B(2,24,4,stone)
B(2,24,5,stone)
B(2,24,6,stone)
B(2,24,7,stone)
B(2,24,8,stone)
B(2,24,9,concrete:15)
B(2,24,10,concrete:15)
B(2,25,-11,stone)
B(2,25,-10,stone)
B(2,25,-9,stone)
B(2,25,-8,stone)
B(2,25,-7,stone)
B(2,25,-6,stone)
B(2,25,-5,stone)
B(2,25,-4,stone)
B(2,25,-3,log:2)
B(2,25,-2,stone)
B(2,25,-1,LOG:1)
B(2,25,0,stone)
B(2,25,1,stone)
B(2,25,2,log)
B(2,25,3,LOG:1)
B(2,25,4,stone)
B(2,25,5,stone)
B(2,25,6,stone)
B(2,25,7,LOG:1)
B(2,25,8,stone)
B(2,25,9,concrete:15)
B(2,25,10,concrete:15)
B(2,25,11,concrete:15)
B(2,26,-11,stone)
B(2,26,-10,stone)
B(2,26,-9,stone)
B(2,26,-8,log2:1)
B(2,26,-7,stone)
B(2,26,-6,stone)
B(2,26,-5,log:2)
B(2,26,-4,log2)
B(2,26,-3,stone)
B(2,26,-2,stone)
B(2,26,-1,stone)
B(2,26,0,stone)
B(2,26,1,stone)
B(2,26,2,log2)
B(2,26,3,log)
B(2,26,4,stone)
B(2,26,5,stone)
B(2,26,6,stone)
B(2,26,7,stone)
B(2,26,8,stone)
B(2,26,9,stone)
B(2,26,10,stone)
B(2,26,11,concrete:15)
B(2,26,12,stone)
B(2,27,-11,stone)
B(2,27,-10,stone)
B(2,27,-9,stone)
B(2,27,-8,stone)
B(2,27,-7,stone)
B(2,27,-6,stone)
B(2,27,-5,stone)
B(2,27,-4,LOG:1)
B(2,27,-3,log2)
B(2,27,-2,log2)
B(2,27,-1,stone)
B(2,27,0,stone)
B(2,27,1,log)
B(2,27,2,stone)
B(2,27,3,log)
B(2,27,4,log:2)
B(2,27,5,stone)
B(2,27,6,stone)
B(2,27,7,LOG:1)
B(2,27,8,stone)
B(2,27,9,stone)
B(2,27,10,stone)
B(3,0,-12,stone)
B(3,0,-11,stone)
B(3,0,-10,stone)
B(3,0,-9,stone)
B(3,0,-8,stone)
B(3,0,-7,stone)
B(3,0,-6,stone)
B(3,0,-5,stone)
B(3,0,-4,stone)
B(3,0,-3,stone)
B(3,0,-2,stone)
B(3,0,-1,stone)
B(3,0,0,stone)
B(3,0,1,stone)
B(3,0,2,stone)
B(3,0,3,stone)
B(3,0,4,stone)
B(3,0,5,stone)
B(3,0,6,stone)
B(3,0,7,stone)
B(3,0,8,stone)
B(3,0,9,stone)
B(3,0,10,stone)
B(3,0,11,stone)
B(3,0,12,stone)
B(3,0,13,stone)
B(3,1,-10,stone)
B(3,1,-9,stone)
B(3,1,-8,stone)
B(3,1,-7,stone)
B(3,1,-6,stone)
B(3,1,-5,stone)
B(3,1,-4,stone)
B(3,1,-3,stone)
B(3,1,-2,stone)
B(3,1,-1,stone)
B(3,1,0,stone)
B(3,1,1,stone)
B(3,1,2,stone)
B(3,1,3,stone)
B(3,1,4,stone)
B(3,1,5,stone)
B(3,1,6,stone)
B(3,1,7,stone)
B(3,1,8,stone)
B(3,1,9,stone)
B(3,1,10,stone)
B(3,1,11,stone)
B(3,2,-10,stone)
B(3,2,-9,stone)
B(3,2,-8,stone)
B(3,2,-7,stone)
B(3,2,-6,log)
B(3,2,-5,stone)
B(3,2,-4,stone)
B(3,2,-3,stone)
B(3,2,-2,stone)
B(3,2,-1,stone)
B(3,2,0,log2)
B(3,2,1,stone)
B(3,2,2,log2:1)
B(3,2,3,stone)
B(3,2,4,stone)
B(3,2,5,stone)
B(3,2,6,stone)
B(3,2,7,stone)
B(3,2,8,stone)
B(3,2,9,stone)
B(3,2,10,stone)
B(3,3,-9,stone)
B(3,3,-8,concrete:15)
B(3,3,-7,stone)
B(3,3,-6,stone)
B(3,3,-5,log2:1)
B(3,3,-4,log:2)
B(3,3,-3,stone)
B(3,3,-2,stone)
B(3,3,-1,stone)
B(3,3,0,LOG:1)
B(3,3,1,log)
B(3,3,2,stone)
B(3,3,3,stone)
B(3,3,4,stone)
B(3,3,5,stone)
B(3,3,6,stone)
B(3,3,7,concrete:15)
B(3,3,8,concrete:15)
B(3,3,9,concrete:15)
B(3,3,10,concrete:15)
B(3,4,-8,concrete:15)
B(3,4,-7,concrete:15)
B(3,4,-6,stone)
B(3,4,-5,log2)
B(3,4,-4,log:2)
B(3,4,-3,stone)
B(3,4,-2,stone)
B(3,4,-1,stone)
B(3,4,0,stone)
B(3,4,1,stone)
B(3,4,2,stone)
B(3,4,3,stone)
B(3,4,4,stone)
B(3,4,5,stone)
B(3,4,6,stone)
B(3,4,7,concrete:15)
B(3,4,8,concrete:15)
B(3,4,9,concrete:15)
B(3,5,-8,concrete:15)
B(3,5,-7,LOG:13)
B(3,5,-6,stone)
B(3,5,-5,stone)
B(3,5,-4,stone)
B(3,5,-3,stone)
B(3,5,-2,stone)
B(3,5,-1,stone)
B(3,5,0,stone)
B(3,5,1,stone)
B(3,5,2,log2:1)
B(3,5,3,stone)
B(3,5,4,stone)
B(3,5,5,stone)
B(3,5,6,LOG:13)
B(3,5,7,LOG:13)
B(3,6,-7,LOG:13)
B(3,6,-6,LOG:13)
B(3,6,-5,LOG:13)
B(3,6,-4,stone)
B(3,6,-3,stone)
B(3,6,-2,log:2)
B(3,6,-1,LOG:1)
B(3,6,0,log)
B(3,6,1,stone)
B(3,6,2,log2)
B(3,6,3,stone)
B(3,6,4,log2)
B(3,6,5,LOG:13)
B(3,6,6,LOG:13)
B(3,7,-7,Leaves:7)
B(3,7,-6,LOG:13)
B(3,7,-5,LOG:13)
B(3,7,-4,concrete:15)
B(3,7,-3,stone)
B(3,7,-2,stone)
B(3,7,-1,stone)
B(3,7,0,log)
B(3,7,1,stone)
B(3,7,2,stone)
B(3,7,3,log:2)
B(3,7,4,LOG:13)
B(3,7,5,LOG:13)
B(3,7,6,LOG:13)
B(3,8,-6,Leaves:7)
B(3,8,-5,LOG:13)
B(3,8,-4,LOG:13)
B(3,8,-3,concrete:15)
B(3,8,-2,LOG:13)
B(3,8,-1,log2)
B(3,8,0,stone)
B(3,8,1,stone)
B(3,8,2,stone)
B(3,8,3,stone)
B(3,8,4,stone)
B(3,8,5,LOG:13)
B(3,8,6,LOG:13)
B(3,8,7,Leaves:7)
B(3,9,-4,concrete:15)
B(3,9,-3,LOG:13)
B(3,9,-2,LOG:13)
B(3,9,-1,LOG:13)
B(3,9,0,stone)
B(3,9,1,LOG:13)
B(3,9,2,LOG:13)
B(3,9,3,concrete:15)
B(3,9,4,concrete:15)
B(3,9,5,concrete:15)
B(3,9,6,Leaves:7)
B(3,10,-4,concrete:15)
B(3,10,-3,concrete:15)
B(3,10,-2,LOG:13)
B(3,10,-1,LOG:13)
B(3,10,0,LOG:13)
B(3,10,1,LOG:13)
B(3,10,2,LOG:13)
B(3,10,3,LOG:13)
B(3,10,4,concrete:15)
B(3,11,-2,concrete:15)
B(3,11,-1,LOG:13)
B(3,11,0,concrete:15)
B(3,11,1,LOG:13)
B(3,11,2,LOG:13)
B(3,11,3,concrete:15)
B(3,12,-1,concrete:15)
B(3,12,0,concrete:15)
B(3,12,1,concrete:15)
B(3,12,2,stone)
B(3,12,3,concrete:15)
B(3,12,4,concrete:15)
B(3,13,-2,stone)
B(3,13,-1,stone)
B(3,13,0,log2:1)
B(3,13,1,log2:1)
B(3,13,2,stone)
B(3,13,3,concrete:15)
B(3,14,-3,stone)
B(3,14,-2,stone)
B(3,14,-1,stone)
B(3,14,0,log2)
B(3,14,1,stone)
B(3,14,2,stone)
B(3,14,3,stone)
B(3,14,4,concrete:15)
B(3,15,-3,concrete:15)
B(3,15,-2,stone)
B(3,15,-1,stone)
B(3,15,0,log2)
B(3,15,1,stone)
B(3,15,2,stone)
B(3,15,3,stone)
B(3,15,4,stone)
B(3,15,5,concrete:15)
B(3,16,-3,concrete:15)
B(3,16,-2,stone)
