#######################################################################
# +-----------------------------------------------------------------+ #
# |                            BO3 object                           | #
# +-----------------------------------------------------------------+ #
#######################################################################

# This is the config file of a custom object.
# If you add this object correctly to your BiomeConfigs, it will spawn in the world.

# This is the creator of this BO3 object
Author: BO3 BulkEdit (by LanToaster)

# A short description of this BO3 object
Description: This Object was Created with BO3_BulkEdit

# The BO3 version, don't change this! It can be used by external applications to do a version check.
Version: 3

# The settings mode, WriteAll, WriteWithoutComments or WriteDisable. See WorldConfig.
SettingsMode: WriteDisable


#######################################################################
# +-----------------------------------------------------------------+ #
# |                          Main settings                          | #
# +-----------------------------------------------------------------+ #
#######################################################################

# This needs to be set to true to spawn the object in the Tree and Sapling resources.
Tree: false

# The frequency of the BO3 from 1 to 200. Tries this many times to spawn this BO3 when using the CustomObject(...) resource.

Frequency: 1

# The rarity of the BO3 from 0 to 100. Each spawn attempt has rarity% chance to succeed when using the CustomObject(...) resource.

Rarity: 100.0

# If you set this to true, the BO3 will be placed with a random rotation.
RotateRandomly: false

# The spawn height of the BO3 - randomY, highestBlock or highestSolidBlock.
SpawnHeight: highestBlock

# The height limits for the BO3.
MinHeight: 0

MaxHeight: 256

# Objects can have other objects attacthed to it: branches. Branches can also
# have branches attached to it, which can also have branches, etc. This is the
# maximum branch depth for this objects.
MaxBranchDepth: 10

# When spawned with the UseWorld keyword, this BO3 should NOT spawn in the following biomes.
# If you writer.write the BO3 name directly in the BiomeConfigs, this will be ignored.
ExcludedBiomes: All


#######################################################################
# +-----------------------------------------------------------------+ #
# |                      Source block settings                      | #
# +-----------------------------------------------------------------+ #
#######################################################################

# The block(s) the BO3 should spawn in.
SourceBlocks: AIR

# The maximum percentage of the BO3 that can be outside the SourceBlock.
# The BO3 won't be placed on a location with more blocks outside the SourceBlock than this percentage.
MaxPercentageOutsideSourceBlock: 100

# What to do when a block is about to be placed outside the SourceBlock? (dontPlace, placeAnyway)
OutsideSourceBlock: placeAnyway


#######################################################################
# +-----------------------------------------------------------------+ #
# |                              Blocks                             | #
# +-----------------------------------------------------------------+ #
#######################################################################

# All the blocks used in the BO3 are listed here. Possible blocks:
# Block(x,y,z,id[.data][,nbtfile.nbt)
# RandomBlock(x,y,z,id[:data][,nbtfile.nbt],chance[,id[:data][,nbtfile.nbt],chance[,...]])
# So RandomBlock(0,0,0,CHEST,chest.nbt,50,CHEST,anotherchest.nbt,100) will spawn a chest at
# the BO3 origin, and give it a 50% chance to have the contents of chest.nbt, or, if that
# fails, a 100% percent chance to have the contents of anotherchest.nbt.
Block(-4,30,8,STAINED_GLASS:9)
Block(-3,30,8,STAINED_GLASS:9)
Block(-1,30,8,STAINED_GLASS:9)
Block(0,30,8,STAINED_GLASS:9)
Block(1,30,8,STAINED_GLASS:15)
Block(2,30,8,STAINED_GLASS:15)
Block(-2,31,7,STAINED_GLASS:9)
Block(1,31,7,STAINED_GLASS:15)
Block(-5,31,8,STAINED_GLASS:9)
Block(-4,31,8,STAINED_GLASS:9)
Block(-3,31,8,STAINED_GLASS:9)
Block(-2,31,8,STAINED_GLASS:9)
Block(-1,31,8,STAINED_GLASS:9)
Block(0,31,8,STAINED_GLASS:9)
Block(1,31,8,STAINED_GLASS:15)
Block(2,31,8,STAINED_GLASS:15)
Block(0,32,6,STAINED_GLASS:15)
Block(-6,32,7,STAINED_GLASS:15)
Block(-5,32,7,STAINED_GLASS:15)
Block(-4,32,7,STAINED_GLASS:9)
Block(-3,32,7,STAINED_GLASS:9)
Block(-2,32,7,STAINED_GLASS:9)
Block(-1,32,7,STAINED_GLASS:15)
Block(0,32,7,STAINED_GLASS:15)
Block(1,32,7,STAINED_GLASS:9)
Block(-5,32,8,STAINED_GLASS:9)
Block(-4,32,8,STAINED_GLASS:9)
Block(-3,32,8,STAINED_GLASS:9)
Block(-2,32,8,STAINED_GLASS:9)
Block(-1,32,8,STAINED_GLASS:15)
Block(0,32,8,STAINED_GLASS:15)
Block(1,32,8,STAINED_GLASS:15)
Block(2,32,8,STAINED_GLASS:15)
Block(-5,33,6,STAINED_GLASS:15)
Block(-4,33,6,STAINED_GLASS:15)
Block(-2,33,6,STAINED_GLASS:15)
Block(-1,33,6,STAINED_GLASS:15)
Block(0,33,6,STAINED_GLASS:9)
Block(1,33,6,STAINED_GLASS:15)
Block(-6,33,7,STAINED_GLASS:9)
Block(-5,33,7,STAINED_GLASS:9)
Block(-4,33,7,STAINED_GLASS:9)
Block(-3,33,7,STAINED_GLASS:9)
Block(-2,33,7,STAINED_GLASS:15)
Block(-1,33,7,STAINED_GLASS:9)
Block(0,33,7,STAINED_GLASS:9)
Block(1,33,7,STAINED_GLASS:15)
Block(-5,33,8,STAINED_GLASS:15)
Block(-4,33,8,STAINED_GLASS:9)
Block(-3,33,8,STAINED_GLASS:9)
Block(-2,33,8,STAINED_GLASS:15)
Block(-1,33,8,STAINED_GLASS:9)
Block(0,33,8,STAINED_GLASS:9)
Block(1,33,8,STAINED_GLASS:15)
Block(2,33,8,STAINED_GLASS:15)
Block(-3,34,5,STAINED_GLASS:15)
Block(0,34,5,STAINED_GLASS:15)
Block(1,34,5,STAINED_GLASS:15)
Block(2,34,5,STAINED_GLASS:15)
Block(-6,34,6,STAINED_GLASS:15)
Block(-5,34,6,STAINED_GLASS:9)
Block(-4,34,6,STAINED_GLASS:9)
Block(-3,34,6,STAINED_GLASS:15)
Block(-2,34,6,STAINED_GLASS:9)
Block(-1,34,6,STAINED_GLASS:9)
Block(0,34,6,STAINED_GLASS:15)
Block(1,34,6,STAINED_GLASS:9)
Block(-6,34,7,STAINED_GLASS:15)
Block(-5,34,7,STAINED_GLASS:15)
Block(-4,34,7,STAINED_GLASS:15)
Block(-3,34,7,STAINED_GLASS:15)
Block(-2,34,7,STAINED_GLASS:9)
Block(-1,34,7,STAINED_GLASS:15)
Block(0,34,7,STAINED_GLASS:15)
Block(1,34,7,STAINED_GLASS:9)
Block(-5,34,8,STAINED_GLASS:9)
Block(-4,34,8,STAINED_GLASS:11)
Block(-3,34,8,STAINED_GLASS:11)
Block(-2,34,8,STAINED_GLASS:9)
Block(-1,34,8,STAINED_GLASS:11)
Block(0,34,8,STAINED_GLASS:11)
Block(1,34,8,STAINED_GLASS:15)
Block(2,34,8,STAINED_GLASS:15)
Block(-1,35,4,STAINED_GLASS:15)
Block(-5,35,5,STAINED_GLASS:15)
Block(-4,35,5,STAINED_GLASS:15)
Block(-3,35,5,STAINED_GLASS:9)
Block(-2,35,5,STAINED_GLASS:15)
Block(-1,35,5,STAINED_GLASS:15)
Block(0,35,5,STAINED_GLASS:9)
Block(1,35,5,STAINED_GLASS:15)
Block(2,35,5,STAINED_GLASS:15)
Block(-6,35,6,STAINED_GLASS:9)
Block(-5,35,6,STAINED_GLASS:15)
Block(-4,35,6,STAINED_GLASS:15)
Block(-3,35,6,STAINED_GLASS:9)
Block(-2,35,6,STAINED_GLASS:15)
Block(-1,35,6,STAINED_GLASS:15)
Block(0,35,6,STAINED_GLASS:9)
Block(1,35,6,STAINED_GLASS:15)
Block(-6,35,7,STAINED_GLASS:9)
Block(-5,35,7,STAINED_GLASS:9)
Block(-4,35,7,STAINED_GLASS:9)
Block(-3,35,7,STAINED_GLASS:9)
Block(-2,35,7,STAINED_GLASS:11)
Block(-1,35,7,STAINED_GLASS:9)
Block(0,35,7,STAINED_GLASS:9)
Block(1,35,7,STAINED_GLASS:9)
Block(2,35,7,STAINED_GLASS:9)
Block(-6,35,8,STAINED_GLASS:9)
Block(-5,35,8,STAINED_GLASS:9)
Block(-4,35,8,STAINED_GLASS:11)
Block(-3,35,8,STAINED_GLASS:11)
Block(-2,35,8,STAINED_GLASS:11)
Block(-1,35,8,STAINED_GLASS:11)
Block(0,35,8,STAINED_GLASS:11)
Block(1,35,8,STAINED_GLASS:9)
Block(2,35,8,STAINED_GLASS:9)
Block(-1,36,4,STAINED_GLASS:15)
Block(-5,36,5,STAINED_GLASS:15)
Block(-4,36,5,STAINED_GLASS:15)
Block(-3,36,5,STAINED_GLASS:9)
Block(-2,36,5,STAINED_GLASS:15)
Block(-1,36,5,STAINED_GLASS:15)
Block(0,36,5,STAINED_GLASS:9)
Block(1,36,5,STAINED_GLASS:15)
Block(2,36,5,STAINED_GLASS:15)
Block(-6,36,6,STAINED_GLASS:9)
Block(-5,36,6,STAINED_GLASS:15)
Block(-4,36,6,STAINED_GLASS:15)
Block(-3,36,6,STAINED_GLASS:9)
Block(-2,36,6,STAINED_GLASS:15)
Block(-1,36,6,STAINED_GLASS:15)
Block(0,36,6,STAINED_GLASS:9)
Block(1,36,6,STAINED_GLASS:15)
Block(-6,36,7,STAINED_GLASS:9)
Block(-5,36,7,STAINED_GLASS:9)
Block(-4,36,7,STAINED_GLASS:9)
Block(-3,36,7,STAINED_GLASS:9)
Block(-2,36,7,STAINED_GLASS:11)
Block(-1,36,7,STAINED_GLASS:9)
Block(0,36,7,STAINED_GLASS:9)
Block(1,36,7,STAINED_GLASS:9)
Block(2,36,7,STAINED_GLASS:9)
Block(-6,36,8,STAINED_GLASS:9)
Block(-5,36,8,STAINED_GLASS:9)
Block(-4,36,8,STAINED_GLASS:11)
Block(-3,36,8,SEA_LANTERN:0)
Block(-2,36,8,STAINED_GLASS:11)
Block(-1,36,8,SEA_LANTERN:0)
Block(0,36,8,STAINED_GLASS:11)
Block(1,36,8,STAINED_GLASS:9)
Block(2,36,8,STAINED_GLASS:9)
Block(-4,37,4,STAINED_GLASS:15)
Block(-3,37,4,STAINED_GLASS:15)
Block(-2,37,4,STAINED_GLASS:15)
Block(-1,37,4,STAINED_GLASS:9)
Block(0,37,4,STAINED_GLASS:15)
Block(-5,37,5,STAINED_GLASS:15)
Block(-4,37,5,STAINED_GLASS:9)
Block(-3,37,5,STAINED_GLASS:15)
Block(-2,37,5,STAINED_GLASS:9)
Block(-1,37,5,STAINED_GLASS:9)
Block(0,37,5,STAINED_GLASS:15)
Block(1,37,5,STAINED_GLASS:15)
Block(2,37,5,STAINED_GLASS:15)
Block(-6,37,6,STAINED_GLASS:15)
Block(-5,37,6,STAINED_GLASS:15)
Block(-4,37,6,STAINED_GLASS:9)
Block(-3,37,6,STAINED_GLASS:15)
Block(-2,37,6,STAINED_GLASS:9)
Block(-1,37,6,STAINED_GLASS:9)
Block(0,37,6,STAINED_GLASS:9)
Block(1,37,6,STAINED_GLASS:15)
Block(-6,37,7,STAINED_GLASS:15)
Block(-5,37,7,STAINED_GLASS:15)
Block(-4,37,7,STAINED_GLASS:9)
Block(-3,37,7,STAINED_GLASS:11)
Block(-2,37,7,SEA_LANTERN:0)
Block(-1,37,7,STAINED_GLASS:11)
Block(0,37,7,STAINED_GLASS:9)
Block(1,37,7,STAINED_GLASS:9)
Block(-5,37,8,STAINED_GLASS:9)
Block(-4,37,8,STAINED_GLASS:11)
Block(-3,37,8,SEA_LANTERN:0)
Block(-2,37,8,SEA_LANTERN:0)
Block(-1,37,8,SEA_LANTERN:0)
Block(0,37,8,STAINED_GLASS:11)
Block(1,37,8,STAINED_GLASS:9)
Block(2,37,8,STAINED_GLASS:9)
Block(-4,38,4,STAINED_GLASS:15)
Block(-3,38,4,STAINED_GLASS:15)
Block(-2,38,4,STAINED_GLASS:15)
Block(-1,38,4,STAINED_GLASS:9)
Block(0,38,4,STAINED_GLASS:15)
Block(-5,38,5,STAINED_GLASS:15)
Block(-4,38,5,STAINED_GLASS:9)
Block(-3,38,5,STAINED_GLASS:15)
Block(-2,38,5,STAINED_GLASS:9)
Block(-1,38,5,STAINED_GLASS:9)
Block(0,38,5,STAINED_GLASS:15)
Block(-5,38,6,STAINED_GLASS:15)
Block(-4,38,6,STAINED_GLASS:9)
Block(-3,38,6,STAINED_GLASS:15)
Block(-2,38,6,STAINED_GLASS:9)
Block(-1,38,6,STAINED_GLASS:9)
Block(0,38,6,STAINED_GLASS:9)
Block(1,38,6,STAINED_GLASS:15)
Block(-4,38,7,STAINED_GLASS:9)
Block(-3,38,7,STAINED_GLASS:11)
Block(-2,38,7,SEA_LANTERN:0)
Block(-1,38,7,STAINED_GLASS:11)
Block(0,38,7,STAINED_GLASS:9)
Block(1,38,7,STAINED_GLASS:9)
Block(-5,38,8,STAINED_GLASS:9)
Block(-4,38,8,STAINED_GLASS:9)
Block(-3,38,8,STAINED_GLASS:11)
Block(-2,38,8,SEA_LANTERN:0)
Block(-1,38,8,STAINED_GLASS:11)
Block(0,38,8,STAINED_GLASS:9)
Block(-4,39,3,STAINED_GLASS:15)
Block(-2,39,3,STAINED_GLASS:15)
Block(-1,39,3,STAINED_GLASS:15)
Block(-4,39,4,STAINED_GLASS:15)
Block(-3,39,4,STAINED_GLASS:9)
Block(-2,39,4,STAINED_GLASS:9)
Block(-1,39,4,STAINED_GLASS:15)
Block(0,39,4,STAINED_GLASS:15)
Block(-5,39,5,STAINED_GLASS:15)
Block(-4,39,5,STAINED_GLASS:15)
Block(-3,39,5,STAINED_GLASS:9)
Block(-2,39,5,STAINED_GLASS:15)
Block(-1,39,5,STAINED_GLASS:15)
Block(0,39,5,STAINED_GLASS:15)
Block(-5,39,6,STAINED_GLASS:15)
Block(-4,39,6,STAINED_GLASS:9)
Block(-3,39,6,STAINED_GLASS:9)
Block(-2,39,6,STAINED_GLASS:9)
Block(-1,39,6,STAINED_GLASS:9)
Block(0,39,6,STAINED_GLASS:9)
Block(1,39,6,STAINED_GLASS:9)
Block(-4,39,7,STAINED_GLASS:9)
Block(-3,39,7,STAINED_GLASS:11)
Block(-2,39,7,STAINED_GLASS:11)
Block(-1,39,7,STAINED_GLASS:11)
Block(0,39,7,STAINED_GLASS:9)
Block(1,39,7,STAINED_GLASS:9)
Block(-5,39,8,STAINED_GLASS:9)
Block(-4,39,8,STAINED_GLASS:9)
Block(-3,39,8,STAINED_GLASS:11)
Block(-2,39,8,STAINED_GLASS:11)
Block(-1,39,8,STAINED_GLASS:11)
Block(0,39,8,STAINED_GLASS:9)
Block(-4,40,3,STAINED_GLASS:15)
Block(-2,40,3,STAINED_GLASS:15)
Block(-1,40,3,STAINED_GLASS:15)
Block(-4,40,4,STAINED_GLASS:15)
Block(-3,40,4,STAINED_GLASS:9)
Block(-2,40,4,STAINED_GLASS:9)
Block(-1,40,4,STAINED_GLASS:15)
Block(0,40,4,STAINED_GLASS:15)
Block(-4,40,5,STAINED_GLASS:15)
Block(-3,40,5,STAINED_GLASS:9)
Block(-2,40,5,STAINED_GLASS:15)
Block(-1,40,5,STAINED_GLASS:15)
Block(0,40,5,STAINED_GLASS:15)
Block(-4,40,6,STAINED_GLASS:9)
Block(-3,40,6,STAINED_GLASS:9)
Block(-2,40,6,STAINED_GLASS:11)
Block(-1,40,6,STAINED_GLASS:9)
Block(0,40,6,STAINED_GLASS:9)
Block(-4,40,7,STAINED_GLASS:9)
Block(-3,40,7,STAINED_GLASS:9)
Block(-2,40,7,STAINED_GLASS:11)
Block(-1,40,7,STAINED_GLASS:9)
Block(0,40,7,STAINED_GLASS:9)
Block(-4,40,8,STAINED_GLASS:9)
Block(-3,40,8,STAINED_GLASS:9)
Block(-2,40,8,STAINED_GLASS:11)
Block(-1,40,8,STAINED_GLASS:9)
Block(0,40,8,STAINED_GLASS:9)
Block(-4,41,3,STAINED_GLASS:15)
Block(-2,41,3,STAINED_GLASS:15)
Block(-1,41,3,STAINED_GLASS:15)
Block(-4,41,4,STAINED_GLASS:15)
Block(-3,41,4,STAINED_GLASS:9)
Block(-2,41,4,STAINED_GLASS:9)
Block(-1,41,4,STAINED_GLASS:15)
Block(0,41,4,STAINED_GLASS:9)
Block(-4,41,5,STAINED_GLASS:15)
Block(-3,41,5,STAINED_GLASS:9)
Block(-2,41,5,STAINED_GLASS:15)
Block(-1,41,5,STAINED_GLASS:15)
Block(0,41,5,STAINED_GLASS:9)
Block(-4,41,6,STAINED_GLASS:9)
Block(-3,41,6,STAINED_GLASS:9)
Block(-2,41,6,STAINED_GLASS:11)
Block(-1,41,6,STAINED_GLASS:9)
Block(0,41,6,STAINED_GLASS:9)
Block(-4,41,7,STAINED_GLASS:9)
Block(-3,41,7,STAINED_GLASS:9)
Block(-2,41,7,STAINED_GLASS:9)
Block(-1,41,7,STAINED_GLASS:9)
Block(0,41,7,STAINED_GLASS:9)
Block(-3,41,8,STAINED_GLASS:9)
Block(-2,41,8,STAINED_GLASS:9)
Block(-1,41,8,STAINED_GLASS:9)
Block(-4,42,3,STAINED_GLASS:15)
Block(-3,42,3,STAINED_GLASS:15)
Block(-2,42,3,STAINED_GLASS:9)
Block(-1,42,3,STAINED_GLASS:15)
Block(-3,42,4,STAINED_GLASS:15)
Block(-2,42,4,STAINED_GLASS:15)
Block(-1,42,4,STAINED_GLASS:15)
Block(-4,42,5,STAINED_GLASS:15)
Block(-3,42,5,STAINED_GLASS:9)
Block(-2,42,5,STAINED_GLASS:9)
Block(-1,42,5,STAINED_GLASS:15)
Block(-4,42,6,STAINED_GLASS:9)
Block(-3,42,6,STAINED_GLASS:9)
Block(-2,42,6,STAINED_GLASS:9)
Block(-1,42,6,STAINED_GLASS:9)
Block(-3,42,7,STAINED_GLASS:9)
Block(-2,42,7,STAINED_GLASS:9)
Block(-1,42,7,STAINED_GLASS:9)
Block(-3,42,8,STAINED_GLASS:9)
Block(-2,42,8,STAINED_GLASS:9)
Block(-1,42,8,STAINED_GLASS:15)
Block(-4,43,3,STAINED_GLASS:15)
Block(-3,43,3,STAINED_GLASS:15)
Block(-2,43,3,STAINED_GLASS:9)
Block(-1,43,3,STAINED_GLASS:9)
Block(-3,43,4,STAINED_GLASS:15)
Block(-2,43,4,STAINED_GLASS:15)
Block(-1,43,4,STAINED_GLASS:9)
Block(-4,43,5,STAINED_GLASS:15)
Block(-3,43,5,STAINED_GLASS:9)
Block(-2,43,5,STAINED_GLASS:9)
Block(-1,43,5,STAINED_GLASS:9)
Block(-4,43,6,STAINED_GLASS:15)
Block(-3,43,6,STAINED_GLASS:9)
Block(-2,43,6,STAINED_GLASS:9)
Block(-1,43,6,STAINED_GLASS:9)
Block(-3,43,7,STAINED_GLASS:9)
Block(-1,43,7,STAINED_GLASS:9)
Block(-3,44,2,STAINED_GLASS:15)
Block(-2,44,2,STAINED_GLASS:15)
Block(-3,44,3,STAINED_GLASS:15)
Block(-2,44,3,STAINED_GLASS:15)
Block(-3,44,4,STAINED_GLASS:15)
Block(-2,44,4,STAINED_GLASS:15)
Block(-3,44,5,STAINED_GLASS:15)
Block(-2,44,5,STAINED_GLASS:9)
Block(-3,44,6,STAINED_GLASS:15)
Block(-3,45,2,STAINED_GLASS:15)
Block(-2,45,2,STAINED_GLASS:15)
Block(-3,45,3,STAINED_GLASS:15)
Block(-2,45,3,STAINED_GLASS:15)
Block(-3,45,4,STAINED_GLASS:15)
Block(-2,45,4,STAINED_GLASS:15)
Block(-2,45,5,STAINED_GLASS:15)
Block(-3,46,2,STAINED_GLASS:15)
Block(-2,46,2,STAINED_GLASS:15)
Block(-2,46,3,STAINED_GLASS:15)
