
#######################################################################
# +-----------------------------------------------------------------+ #
# |                            BO3 object                           | #
# +-----------------------------------------------------------------+ #
#######################################################################

Author: BO3 BulkEdit (by LanToaster)

Description: This Object was Created with BO3_BulkEdit

Version: 3

SettingsMode: WriteWithoutComments


#######################################################################
# +-----------------------------------------------------------------+ #
# |                          Main settings                          | #
# +-----------------------------------------------------------------+ #
#######################################################################

Tree: false

Frequency: 200

Rarity: 100.0

RotateRandomly: true

SpawnHeight: randomY

SpawnHeightOffset: 0

SpawnHeightVariance: 0

##############################
# Height Limits for the BO3. #
##############################

MinHeight: 165

MaxHeight: 165

######################
# Extrusion settings #
######################

ExtrudeMode: None

ExtrudeThroughBlocks: minecraft:air

MaxBranchDepth: 10


#######################################################################
# +-----------------------------------------------------------------+ #
# |                      Source block settings                      | #
# +-----------------------------------------------------------------+ #
#######################################################################

SourceBlocks: otg:air

MaxPercentageOutsideSourceBlock: 100

OutsideSourceBlock: placeAnyway

DoReplaceBlocks: true

IsOTGPlus: false


#######################################################################
# +-----------------------------------------------------------------+ #
# |                              Blocks                             | #
# +-----------------------------------------------------------------+ #
#######################################################################

B(-5,2,-3,minecraft:black_concrete)
B(-5,2,-2,minecraft:black_concrete)
B(-5,4,-2,minecraft:black_concrete)
B(-5,1,-1,minecraft:black_concrete)
B(-5,2,-1,minecraft:black_concrete)
B(-5,3,-1,minecraft:black_concrete)
B(-5,4,-1,minecraft:black_concrete)
B(-5,2,0,minecraft:black_concrete)
B(-5,3,0,minecraft:black_concrete)
B(-5,4,0,minecraft:black_concrete)
B(-5,2,1,minecraft:black_concrete)
B(-5,4,1,minecraft:black_concrete)
B(-4,2,-4,minecraft:black_concrete)
B(-4,1,-3,minecraft:black_concrete)
B(-4,2,-3,minecraft:black_concrete)
B(-4,3,-3,minecraft:magma_block)
B(-4,4,-3,minecraft:black_concrete)
B(-4,1,-2,minecraft:black_concrete)
B(-4,2,-2,minecraft:black_concrete)
B(-4,3,-2,minecraft:magma_block)
B(-4,4,-2,minecraft:black_concrete)
B(-4,0,-1,minecraft:black_concrete)
B(-4,1,-1,minecraft:black_concrete)
B(-4,2,-1,minecraft:black_concrete)
B(-4,3,-1,minecraft:magma_block)
B(-4,4,-1,minecraft:black_concrete)
B(-4,0,0,minecraft:black_concrete)
B(-4,1,0,minecraft:black_concrete)
B(-4,2,0,minecraft:black_concrete)
B(-4,3,0,minecraft:magma_block)
B(-4,4,0,minecraft:black_concrete)
B(-4,1,1,minecraft:black_concrete)
B(-4,2,1,minecraft:black_concrete)
B(-4,3,1,minecraft:magma_block)
B(-4,4,1,minecraft:black_concrete)
B(-4,1,2,minecraft:black_concrete)
B(-4,2,2,minecraft:black_concrete)
B(-4,4,2,minecraft:black_concrete)
B(-4,2,3,minecraft:black_concrete)
B(-3,1,-4,minecraft:black_concrete)
B(-3,2,-4,minecraft:black_concrete)
B(-3,3,-4,minecraft:black_concrete)
B(-3,1,-3,minecraft:black_concrete)
B(-3,2,-3,minecraft:black_concrete)
B(-3,3,-3,minecraft:magma_block)
B(-3,4,-3,minecraft:black_concrete)
B(-3,0,-2,minecraft:black_concrete)
B(-3,1,-2,minecraft:black_concrete)
B(-3,2,-2,minecraft:black_concrete)
B(-3,3,-2,minecraft:black_concrete)
B(-3,4,-2,minecraft:black_concrete)
B(-3,0,-1,minecraft:black_concrete)
B(-3,1,-1,minecraft:black_concrete)
B(-3,2,-1,minecraft:black_concrete)
B(-3,3,-1,minecraft:black_concrete)
B(-3,4,-1,minecraft:black_concrete)
B(-3,0,0,minecraft:black_concrete)
B(-3,1,0,minecraft:black_concrete)
B(-3,2,0,minecraft:black_concrete)
B(-3,3,0,minecraft:black_concrete)
B(-3,4,0,minecraft:black_concrete)
B(-3,0,1,minecraft:black_concrete)
B(-3,1,1,minecraft:black_concrete)
B(-3,2,1,minecraft:black_concrete)
B(-3,3,1,minecraft:magma_block)
B(-3,4,1,minecraft:black_concrete)
B(-3,1,2,minecraft:black_concrete)
B(-3,2,2,minecraft:black_concrete)
B(-3,3,2,minecraft:magma_block)
B(-3,4,2,minecraft:black_concrete)
B(-3,1,3,minecraft:black_concrete)
B(-3,2,3,minecraft:black_concrete)
B(-2,2,-5,minecraft:black_concrete)
B(-2,1,-4,minecraft:black_concrete)
B(-2,2,-4,minecraft:black_concrete)
B(-2,3,-4,minecraft:magma_block)
B(-2,4,-4,minecraft:black_concrete)
B(-2,0,-3,minecraft:black_concrete)
B(-2,1,-3,minecraft:black_concrete)
B(-2,2,-3,minecraft:black_concrete)
B(-2,3,-3,minecraft:magma_block)
B(-2,4,-3,minecraft:black_concrete)
B(-2,0,-2,minecraft:black_concrete)
B(-2,1,-2,minecraft:black_concrete)
B(-2,2,-2,minecraft:black_concrete)
B(-2,3,-2,minecraft:black_concrete)
B(-2,4,-2,minecraft:black_concrete)
B(-2,0,-1,minecraft:black_concrete)
B(-2,1,-1,minecraft:black_concrete)
B(-2,2,-1,minecraft:black_concrete)
B(-2,3,-1,minecraft:black_concrete)
B(-2,4,-1,minecraft:black_concrete)
B(-2,0,0,minecraft:black_concrete)
B(-2,1,0,minecraft:black_concrete)
B(-2,2,0,minecraft:black_concrete)
B(-2,3,0,minecraft:black_concrete)
B(-2,4,0,minecraft:black_concrete)
B(-2,0,1,minecraft:black_concrete)
B(-2,1,1,minecraft:black_concrete)
B(-2,2,1,minecraft:black_concrete)
B(-2,3,1,minecraft:black_concrete)
B(-2,4,1,minecraft:black_concrete)
B(-2,0,2,minecraft:black_concrete)
B(-2,1,2,minecraft:black_concrete)
B(-2,2,2,minecraft:black_concrete)
B(-2,3,2,minecraft:magma_block)
B(-2,4,2,minecraft:black_concrete)
B(-2,1,3,minecraft:black_concrete)
B(-2,2,3,minecraft:black_concrete)
B(-2,4,3,minecraft:black_concrete)
B(-2,2,4,minecraft:black_concrete)
B(-1,2,-5,minecraft:black_concrete)
B(-1,3,-5,minecraft:black_concrete)
B(-1,1,-4,minecraft:black_concrete)
B(-1,2,-4,minecraft:black_concrete)
B(-1,3,-4,minecraft:magma_block)
B(-1,4,-4,minecraft:black_concrete)
B(-1,0,-3,minecraft:black_concrete)
B(-1,1,-3,minecraft:black_concrete)
B(-1,2,-3,minecraft:black_concrete)
B(-1,3,-3,minecraft:black_concrete)
B(-1,4,-3,minecraft:black_concrete)
B(-1,0,-2,minecraft:black_concrete)
B(-1,1,-2,minecraft:black_concrete)
B(-1,2,-2,minecraft:black_concrete)
B(-1,3,-2,minecraft:black_concrete)
B(-1,4,-2,minecraft:black_concrete)
B(-1,0,-1,minecraft:black_concrete)
B(-1,1,-1,minecraft:black_concrete)
B(-1,2,-1,minecraft:black_concrete)
B(-1,3,-1,minecraft:black_concrete)
B(-1,4,-1,minecraft:black_concrete)
B(-1,0,0,minecraft:black_concrete)
B(-1,1,0,minecraft:black_concrete)
B(-1,2,0,minecraft:black_concrete)
B(-1,3,0,minecraft:black_concrete)
B(-1,4,0,minecraft:black_concrete)
B(-1,0,1,minecraft:black_concrete)
B(-1,1,1,minecraft:black_concrete)
B(-1,2,1,minecraft:black_concrete)
B(-1,3,1,minecraft:black_concrete)
B(-1,4,1,minecraft:black_concrete)
B(-1,0,2,minecraft:black_concrete)
B(-1,1,2,minecraft:black_concrete)
B(-1,2,2,minecraft:black_concrete)
B(-1,3,2,minecraft:black_concrete)
B(-1,4,2,minecraft:black_concrete)
B(-1,0,3,minecraft:black_concrete)
B(-1,1,3,minecraft:black_concrete)
B(-1,2,3,minecraft:black_concrete)
B(-1,3,3,minecraft:magma_block)
B(-1,4,3,minecraft:black_concrete)
B(-1,1,4,minecraft:black_concrete)
B(-1,2,4,minecraft:black_concrete)
B(0,2,-5,minecraft:black_concrete)
B(0,3,-5,minecraft:black_concrete)
B(0,4,-5,minecraft:black_concrete)
B(0,0,-4,minecraft:black_concrete)
B(0,1,-4,minecraft:black_concrete)
B(0,2,-4,minecraft:black_concrete)
B(0,3,-4,minecraft:magma_block)
B(0,4,-4,minecraft:black_concrete)
B(0,0,-3,minecraft:black_concrete)
B(0,1,-3,minecraft:black_concrete)
B(0,2,-3,minecraft:black_concrete)
B(0,3,-3,minecraft:black_concrete)
B(0,4,-3,minecraft:black_concrete)
B(0,0,-2,minecraft:black_concrete)
B(0,1,-2,minecraft:black_concrete)
B(0,2,-2,minecraft:black_concrete)
B(0,4,-2,minecraft:black_concrete)
B(0,0,-1,minecraft:black_concrete)
B(0,1,-1,minecraft:black_concrete)
B(0,2,-1,minecraft:black_concrete)
B(0,3,-1,minecraft:black_concrete)
B(0,4,-1,minecraft:black_concrete)
B(0,0,0,minecraft:black_concrete)
B(0,1,0,minecraft:black_concrete)
B(0,2,0,minecraft:black_concrete)
B(0,3,0,minecraft:black_concrete)
B(0,4,0,minecraft:black_concrete)
B(0,0,1,minecraft:black_concrete)
B(0,1,1,minecraft:black_concrete)
B(0,2,1,minecraft:black_concrete)
B(0,3,1,minecraft:black_concrete)
B(0,4,1,minecraft:black_concrete)
B(0,0,2,minecraft:black_concrete)
B(0,1,2,minecraft:black_concrete)
B(0,2,2,minecraft:black_concrete)
B(0,3,2,minecraft:black_concrete)
B(0,4,2,minecraft:black_concrete)
B(0,1,3,minecraft:black_concrete)
B(0,2,3,minecraft:black_concrete)
B(0,3,3,minecraft:magma_block)
B(0,4,3,minecraft:black_concrete)
B(0,1,4,minecraft:black_concrete)
B(0,2,4,minecraft:black_concrete)
B(0,3,4,minecraft:black_concrete)
B(0,4,4,minecraft:black_concrete)
B(1,1,-5,minecraft:black_concrete)
B(1,2,-5,minecraft:black_concrete)
B(1,4,-5,minecraft:black_concrete)
B(1,0,-4,minecraft:black_concrete)
B(1,1,-4,minecraft:black_concrete)
B(1,2,-4,minecraft:black_concrete)
B(1,3,-4,minecraft:magma_block)
B(1,4,-4,minecraft:black_concrete)
B(1,0,-3,minecraft:black_concrete)
B(1,1,-3,minecraft:black_concrete)
B(1,2,-3,minecraft:black_concrete)
B(1,3,-3,minecraft:black_concrete)
B(1,4,-3,minecraft:black_concrete)
B(1,0,-2,minecraft:black_concrete)
B(1,1,-2,minecraft:black_concrete)
B(1,2,-2,minecraft:black_concrete)
B(1,3,-2,minecraft:black_concrete)
B(1,4,-2,minecraft:black_concrete)
B(1,0,-1,minecraft:black_concrete)
B(1,1,-1,minecraft:black_concrete)
B(1,2,-1,minecraft:black_concrete)
B(1,3,-1,minecraft:black_concrete)
B(1,4,-1,minecraft:black_concrete)
B(1,0,0,minecraft:black_concrete)
B(1,1,0,minecraft:black_concrete)
B(1,2,0,minecraft:black_concrete)
B(1,3,0,minecraft:black_concrete)
B(1,4,0,minecraft:black_concrete)
B(1,0,1,minecraft:black_concrete)
B(1,1,1,minecraft:black_concrete)
B(1,2,1,minecraft:black_concrete)
B(1,3,1,minecraft:black_concrete)
B(1,4,1,minecraft:black_concrete)
B(1,0,2,minecraft:black_concrete)
B(1,1,2,minecraft:black_concrete)
B(1,2,2,minecraft:black_concrete)
B(1,3,2,minecraft:black_concrete)
B(1,4,2,minecraft:black_concrete)
B(1,1,3,minecraft:black_concrete)
B(1,2,3,minecraft:black_concrete)
B(1,3,3,minecraft:magma_block)
B(1,4,3,minecraft:black_concrete)
B(1,2,4,minecraft:black_concrete)
B(2,2,-5,minecraft:black_concrete)
B(2,4,-5,minecraft:black_concrete)
B(2,1,-4,minecraft:black_concrete)
B(2,2,-4,minecraft:black_concrete)
B(2,3,-4,minecraft:magma_block)
B(2,4,-4,minecraft:black_concrete)
B(2,0,-3,minecraft:black_concrete)
B(2,1,-3,minecraft:black_concrete)
B(2,2,-3,minecraft:black_concrete)
B(2,3,-3,minecraft:black_concrete)
B(2,4,-3,minecraft:black_concrete)
B(2,0,-2,minecraft:black_concrete)
B(2,1,-2,minecraft:black_concrete)
B(2,2,-2,minecraft:black_concrete)
B(2,3,-2,minecraft:black_concrete)
B(2,4,-2,minecraft:black_concrete)
B(2,0,-1,minecraft:black_concrete)
B(2,1,-1,minecraft:black_concrete)
B(2,2,-1,minecraft:black_concrete)
B(2,3,-1,minecraft:black_concrete)
B(2,4,-1,minecraft:black_concrete)
B(2,0,0,minecraft:black_concrete)
B(2,1,0,minecraft:black_concrete)
B(2,2,0,minecraft:black_concrete)
B(2,3,0,minecraft:black_concrete)
B(2,4,0,minecraft:black_concrete)
B(2,0,1,minecraft:black_concrete)
B(2,1,1,minecraft:black_concrete)
B(2,2,1,minecraft:black_concrete)
B(2,3,1,minecraft:black_concrete)
B(2,4,1,minecraft:black_concrete)
B(2,0,2,minecraft:black_concrete)
B(2,1,2,minecraft:black_concrete)
B(2,2,2,minecraft:black_concrete)
B(2,3,2,minecraft:magma_block)
B(2,4,2,minecraft:black_concrete)
B(2,1,3,minecraft:black_concrete)
B(2,2,3,minecraft:black_concrete)
B(2,3,3,minecraft:black_concrete)
B(2,2,4,minecraft:black_concrete)
B(3,2,-5,minecraft:black_concrete)
B(3,1,-4,minecraft:black_concrete)
B(3,2,-4,minecraft:black_concrete)
B(3,3,-4,minecraft:magma_block)
B(3,4,-4,minecraft:black_concrete)
B(3,1,-3,minecraft:black_concrete)
B(3,2,-3,minecraft:black_concrete)
B(3,3,-3,minecraft:magma_block)
B(3,4,-3,minecraft:black_concrete)
B(3,0,-2,minecraft:black_concrete)
B(3,1,-2,minecraft:black_concrete)
B(3,2,-2,minecraft:black_concrete)
B(3,3,-2,minecraft:magma_block)
B(3,4,-2,minecraft:black_concrete)
B(3,0,-1,minecraft:black_concrete)
B(3,1,-1,minecraft:black_concrete)
B(3,2,-1,minecraft:black_concrete)
B(3,3,-1,minecraft:black_concrete)
B(3,4,-1,minecraft:black_concrete)
B(3,0,0,minecraft:black_concrete)
B(3,1,0,minecraft:black_concrete)
B(3,2,0,minecraft:black_concrete)
B(3,3,0,minecraft:black_concrete)
B(3,4,0,minecraft:black_concrete)
B(3,0,1,minecraft:black_concrete)
B(3,1,1,minecraft:black_concrete)
B(3,2,1,minecraft:black_concrete)
B(3,3,1,minecraft:magma_block)
B(3,4,1,minecraft:black_concrete)
B(3,1,2,minecraft:black_concrete)
B(3,2,2,minecraft:black_concrete)
B(3,4,2,minecraft:black_concrete)
B(3,2,3,minecraft:black_concrete)
B(4,2,-4,minecraft:black_concrete)
B(4,1,-3,minecraft:black_concrete)
B(4,2,-3,minecraft:black_concrete)
B(4,1,-2,minecraft:black_concrete)
B(4,2,-2,minecraft:black_concrete)
B(4,3,-2,minecraft:magma_block)
B(4,4,-2,minecraft:black_concrete)
B(4,0,-1,minecraft:black_concrete)
B(4,1,-1,minecraft:black_concrete)
B(4,2,-1,minecraft:black_concrete)
B(4,3,-1,minecraft:magma_block)
B(4,4,-1,minecraft:black_concrete)
B(4,0,0,minecraft:black_concrete)
B(4,1,0,minecraft:black_concrete)
B(4,2,0,minecraft:black_concrete)
B(4,3,0,minecraft:magma_block)
B(4,4,0,minecraft:black_concrete)
B(4,0,1,minecraft:black_concrete)
B(4,1,1,minecraft:black_concrete)
B(4,2,1,minecraft:black_concrete)
B(4,3,1,minecraft:magma_block)
B(4,4,1,minecraft:black_concrete)
B(4,1,2,minecraft:black_concrete)
B(4,2,2,minecraft:black_concrete)
B(5,2,-2,minecraft:black_concrete)
B(5,2,-1,minecraft:black_concrete)
B(5,3,-1,minecraft:black_concrete)
B(5,1,0,minecraft:black_concrete)
B(5,2,0,minecraft:black_concrete)
B(5,1,1,minecraft:black_concrete)
B(5,2,1,minecraft:black_concrete)
B(5,3,1,minecraft:black_concrete)

#######################################################################
# +-----------------------------------------------------------------+ #
# |                            BO3 checks                           | #
# +-----------------------------------------------------------------+ #
#######################################################################

BlockCheck(0,3,-2,otg:stone,otg:dirt,minecraft:grass_block)

#######################################################################
# +-----------------------------------------------------------------+ #
# |                             Branches                            | #
# +-----------------------------------------------------------------+ #
#######################################################################


#######################################################################
# +-----------------------------------------------------------------+ #
# |                             Entities                            | #
# +-----------------------------------------------------------------+ #
#######################################################################

