
#######################################################################
# +-----------------------------------------------------------------+ #
# |                            BO3 object                           | #
# +-----------------------------------------------------------------+ #
#######################################################################

Author: NLBlackEagle

Description: No description given

Version: 3

SettingsMode: WriteDisable


#######################################################################
# +-----------------------------------------------------------------+ #
# |                          Main settings                          | #
# +-----------------------------------------------------------------+ #
#######################################################################

Tree: true

Frequency: 1

Rarity: 100.0

RotateRandomly: true

SpawnHeight: highestSolidBlock

SpawnHeightOffset: 0

SpawnHeightVariance: 0

##############################
# Height Limits for the BO3. #
##############################

MinHeight: 0

MaxHeight: 256

######################
# Extrusion settings #
######################

ExtrudeMode: None

ExtrudeThroughBlocks: AIR

MaxBranchDepth: 10

ExcludedBiomes: All


#######################################################################
# +-----------------------------------------------------------------+ #
# |                      Source block settings                      | #
# +-----------------------------------------------------------------+ #
#######################################################################

SourceBlocks: AIR

MaxPercentageOutsideSourceBlock: 100

OutsideSourceBlock: placeAnyway

IsOTGPlus: false

InheritBO3: 

InheritBO3Rotation: NORTH

OverrideChildSettings: true

OverrideParentHeight: false

CanOverride: false

BranchFrequency: 0

BranchFrequencyGroup: 

MustBeBelowOther: false

MustBeInside: 

CannotBeInside: 

ReplacesBO3: 

CanSpawnOnWater: true

SpawnOnWaterOnly: false

SpawnUnderWater: false

SpawnAtWaterLevel: false

HeightOffset: 0

RemoveAir: true

ReplaceAbove: 

ReplaceBelow: 

ReplaceWithBiomeBlocks: true

ReplaceWithGroundBlock: DIRT

ReplaceWithSurfaceBlock: GRASS

SmoothRadius: 0

SmoothHeightOffset: 0

SmoothStartTop: false

SmoothStartWood: false

SmoothingSurfaceBlock: 

SmoothingGroundBlock: 

BO3Group: 

IsSpawnPoint: false


#######################################################################
# +-----------------------------------------------------------------+ #
# |                              Blocks                             | #
# +-----------------------------------------------------------------+ #
#######################################################################

Block(-33,46,-1,STAINED_GLASS:10)
Block(-33,46,0,STAINED_GLASS:10)
Block(-33,47,-1,STAINED_GLASS:10)
Block(-33,47,0,STAINED_GLASS:14)
Block(-33,48,-1,STAINED_GLASS:14)
Block(-33,48,0,STAINED_GLASS:10)
Block(-32,42,-1,STAINED_GLASS:10)
Block(-32,42,0,STAINED_GLASS:10)
Block(-32,43,-1,STAINED_GLASS:10)
Block(-32,43,0,STAINED_GLASS:14)
Block(-32,44,-1,STAINED_GLASS:10)
Block(-32,44,0,STAINED_GLASS:14)
Block(-32,45,-1,STAINED_GLASS:10)
Block(-32,45,0,STAINED_GLASS:10)
Block(-32,46,-2,STAINED_GLASS:10)
Block(-32,46,-1,MAGMA)
Block(-32,46,0,MAGMA)
Block(-32,46,1,STAINED_GLASS:10)
Block(-32,47,-2,STAINED_GLASS:14)
Block(-32,47,-1,MAGMA)
Block(-32,47,0,MAGMA)
Block(-32,47,1,STAINED_GLASS:10)
Block(-32,48,-1,STAINED_GLASS:14)
Block(-32,48,0,STAINED_GLASS:14)
Block(-31,37,-1,STAINED_GLASS:10)
Block(-31,37,0,STAINED_GLASS:14)
Block(-31,38,-1,STAINED_GLASS:10)
Block(-31,38,0,STAINED_GLASS:10)
Block(-31,39,-2,STAINED_GLASS:10)
Block(-31,39,-1,STAINED_GLASS:10)
Block(-31,39,0,STAINED_GLASS:10)
Block(-31,39,1,STAINED_GLASS:10)
Block(-31,40,-2,STAINED_GLASS:10)
Block(-31,40,-1,STAINED_GLASS:10)
Block(-31,40,0,STAINED_GLASS:10)
Block(-31,40,1,STAINED_GLASS:14)
Block(-31,41,-2,STAINED_GLASS:14)
Block(-31,41,-1,STAINED_GLASS:14)
Block(-31,41,0,STAINED_GLASS:14)
Block(-31,41,1,STAINED_GLASS:14)
Block(-31,42,-2,STAINED_GLASS:14)
Block(-31,42,-1,STAINED_GLASS:10)
Block(-31,42,0,STAINED_GLASS:10)
Block(-31,42,1,STAINED_GLASS:10)
Block(-31,43,-2,STAINED_GLASS:10)
Block(-31,43,-1,MAGMA)
Block(-31,43,0,MAGMA)
Block(-31,43,1,STAINED_GLASS:10)
Block(-31,44,-2,STAINED_GLASS:10)
Block(-31,44,-1,MAGMA)
Block(-31,44,0,MAGMA)
Block(-31,44,1,STAINED_GLASS:10)
Block(-31,45,-2,STAINED_GLASS:14)
Block(-31,45,-1,MAGMA)
Block(-31,45,0,MAGMA)
Block(-31,45,1,STAINED_GLASS:14)
Block(-31,46,-2,STAINED_GLASS:14)
Block(-31,46,-1,MAGMA)
Block(-31,46,0,MAGMA)
Block(-31,46,1,STAINED_GLASS:10)
Block(-31,47,-1,STAINED_GLASS:14)
Block(-31,47,0,STAINED_GLASS:14)
Block(-30,36,-1,STAINED_GLASS:14)
Block(-30,36,0,STAINED_GLASS:10)
Block(-30,37,-2,STAINED_GLASS:10)
Block(-30,37,-1,STAINED_GLASS:14)
Block(-30,37,0,STAINED_GLASS:14)
Block(-30,37,1,STAINED_GLASS:10)
Block(-30,38,-3,STAINED_GLASS:10)
Block(-30,38,-2,STAINED_GLASS:10)
Block(-30,38,-1,STAINED_GLASS:10)
Block(-30,38,0,STAINED_GLASS:10)
Block(-30,38,1,STAINED_GLASS:10)
Block(-30,38,2,STAINED_GLASS:10)
Block(-30,39,-3,STAINED_GLASS:14)
Block(-30,39,-2,STAINED_GLASS:10)
Block(-30,39,-1,MAGMA)
Block(-30,39,0,MAGMA)
Block(-30,39,1,STAINED_GLASS:10)
Block(-30,39,2,STAINED_GLASS:14)
Block(-30,40,-3,STAINED_GLASS:14)
Block(-30,40,-2,STAINED_GLASS:10)
Block(-30,40,-1,MAGMA)
Block(-30,40,0,MAGMA)
Block(-30,40,1,STAINED_GLASS:10)
Block(-30,40,2,STAINED_GLASS:10)
Block(-30,41,-3,STAINED_GLASS:10)
Block(-30,41,-2,STAINED_GLASS:10)
Block(-30,41,-1,MAGMA)
Block(-30,41,0,MAGMA)
Block(-30,41,1,STAINED_GLASS:14)
Block(-30,41,2,STAINED_GLASS:10)
Block(-30,42,-3,STAINED_GLASS:14)
Block(-30,42,-2,STAINED_GLASS:10)
Block(-30,42,-1,MAGMA)
Block(-30,42,0,MAGMA)
Block(-30,42,1,STAINED_GLASS:14)
Block(-30,42,2,STAINED_GLASS:10)
Block(-30,43,-2,STAINED_GLASS:10)
Block(-30,43,-1,MAGMA)
Block(-30,43,0,MAGMA)
Block(-30,43,1,STAINED_GLASS:14)
Block(-30,44,-2,STAINED_GLASS:10)
Block(-30,44,-1,MAGMA)
Block(-30,44,0,MAGMA)
Block(-30,44,1,STAINED_GLASS:10)
Block(-30,45,-1,STAINED_GLASS:14)
Block(-30,45,0,STAINED_GLASS:10)
Block(-30,46,-1,STAINED_GLASS:10)
Block(-30,46,0,STAINED_GLASS:10)
Block(-29,32,-2,STAINED_GLASS:10)
Block(-29,32,-1,STAINED_GLASS:10)
Block(-29,32,0,STAINED_GLASS:10)
Block(-29,32,1,STAINED_GLASS:10)
Block(-29,33,-2,STAINED_GLASS:10)
Block(-29,33,-1,STAINED_GLASS:10)
Block(-29,33,0,STAINED_GLASS:10)
Block(-29,33,1,STAINED_GLASS:10)
Block(-29,34,-2,STAINED_GLASS:10)
Block(-29,34,-1,STAINED_GLASS:10)
Block(-29,34,0,STAINED_GLASS:10)
Block(-29,35,-2,STAINED_GLASS:10)
Block(-29,35,-1,STAINED_GLASS:14)
Block(-29,35,0,STAINED_GLASS:10)
Block(-29,35,1,STAINED_GLASS:10)
Block(-29,36,-3,STAINED_GLASS:10)
Block(-29,36,-2,STAINED_GLASS:10)
Block(-29,36,-1,STAINED_GLASS:14)
Block(-29,36,0,STAINED_GLASS:14)
Block(-29,36,1,STAINED_GLASS:10)
Block(-29,36,2,STAINED_GLASS:10)
Block(-29,37,-4,STAINED_GLASS:10)
Block(-29,37,-3,STAINED_GLASS:14)
Block(-29,37,-2,STAINED_GLASS:10)
Block(-29,37,-1,MAGMA)
Block(-29,37,0,MAGMA)
Block(-29,37,1,STAINED_GLASS:10)
Block(-29,37,2,STAINED_GLASS:10)
Block(-29,37,3,STAINED_GLASS:10)
Block(-29,38,-4,STAINED_GLASS:14)
Block(-29,38,-3,STAINED_GLASS:10)
Block(-29,38,-2,MAGMA)
Block(-29,38,-1,MAGMA)
Block(-29,38,0,MAGMA)
Block(-29,38,1,MAGMA)
Block(-29,38,2,STAINED_GLASS:10)
Block(-29,38,3,STAINED_GLASS:14)
Block(-29,39,-4,STAINED_GLASS:14)
Block(-29,39,-3,STAINED_GLASS:14)
Block(-29,39,-2,MAGMA)
Block(-29,39,-1,MAGMA)
Block(-29,39,0,MAGMA)
Block(-29,39,1,MAGMA)
Block(-29,39,2,STAINED_GLASS:14)
Block(-29,39,3,STAINED_GLASS:14)
Block(-29,40,-4,STAINED_GLASS:14)
Block(-29,40,-3,STAINED_GLASS:10)
Block(-29,40,-2,MAGMA)
Block(-29,40,-1,MAGMA)
Block(-29,40,0,MAGMA)
Block(-29,40,1,MAGMA)
Block(-29,40,2,STAINED_GLASS:10)
Block(-29,40,3,STAINED_GLASS:10)
Block(-29,41,-4,STAINED_GLASS:10)
Block(-29,41,-3,STAINED_GLASS:10)
Block(-29,41,-2,STAINED_GLASS:10)
Block(-29,41,-1,MAGMA)
Block(-29,41,0,MAGMA)
Block(-29,41,1,STAINED_GLASS:14)
Block(-29,41,2,STAINED_GLASS:14)
Block(-29,41,3,STAINED_GLASS:14)
Block(-29,42,-3,STAINED_GLASS:10)
Block(-29,42,-2,STAINED_GLASS:10)
Block(-29,42,-1,STAINED_GLASS:10)
Block(-29,42,0,STAINED_GLASS:14)
Block(-29,42,1,STAINED_GLASS:10)
Block(-29,42,2,STAINED_GLASS:14)
Block(-29,43,-2,STAINED_GLASS:14)
Block(-29,43,-1,STAINED_GLASS:10)
Block(-29,43,0,STAINED_GLASS:14)
Block(-29,43,1,STAINED_GLASS:14)
Block(-29,44,-1,STAINED_GLASS:10)
Block(-29,44,0,STAINED_GLASS:10)
Block(-28,30,-2,STAINED_GLASS:10)
Block(-28,30,-1,STAINED_GLASS:10)
Block(-28,30,0,STAINED_GLASS:10)
Block(-28,30,1,STAINED_GLASS:10)
Block(-28,31,-2,STAINED_GLASS:10)
Block(-28,31,-1,STAINED_GLASS:10)
Block(-28,31,0,STAINED_GLASS:10)
Block(-28,31,1,STAINED_GLASS:10)
Block(-28,32,-2,STAINED_GLASS:10)
Block(-28,32,-1,STAINED_GLASS:10)
Block(-28,32,0,STAINED_GLASS:10)
Block(-28,32,1,STAINED_GLASS:10)
Block(-28,33,-2,STAINED_GLASS:10)
Block(-28,33,-1,STAINED_GLASS:14)
Block(-28,33,0,STAINED_GLASS:14)
Block(-28,33,1,STAINED_GLASS:10)
Block(-28,34,-3,STAINED_GLASS:10)
Block(-28,34,-2,STAINED_GLASS:14)
Block(-28,34,-1,STAINED_GLASS:14)
Block(-28,34,0,STAINED_GLASS:14)
Block(-28,34,1,STAINED_GLASS:14)
Block(-28,34,2,STAINED_GLASS:10)
Block(-28,35,-4,STAINED_GLASS:10)
Block(-28,35,-3,STAINED_GLASS:14)
Block(-28,35,-2,STAINED_GLASS:14)
Block(-28,35,-1,MAGMA)
Block(-28,35,0,MAGMA)
Block(-28,35,1,STAINED_GLASS:10)
Block(-28,35,2,STAINED_GLASS:10)
Block(-28,35,3,STAINED_GLASS:14)
Block(-28,36,-4,STAINED_GLASS:14)
Block(-28,36,-3,STAINED_GLASS:14)
Block(-28,36,-2,MAGMA)
Block(-28,36,-1,MAGMA)
Block(-28,36,0,MAGMA)
Block(-28,36,1,MAGMA)
Block(-28,36,2,STAINED_GLASS:14)
Block(-28,36,3,STAINED_GLASS:14)
Block(-28,37,-4,STAINED_GLASS:14)
Block(-28,37,-3,STAINED_GLASS:10)
Block(-28,37,-2,MAGMA)
Block(-28,37,-1,MAGMA)
Block(-28,37,0,MAGMA)
Block(-28,37,1,MAGMA)
Block(-28,37,2,STAINED_GLASS:10)
Block(-28,37,3,STAINED_GLASS:14)
Block(-28,38,-4,STAINED_GLASS:10)
Block(-28,38,-3,STAINED_GLASS:14)
Block(-28,38,-2,MAGMA)
Block(-28,38,-1,MAGMA)
Block(-28,38,0,MAGMA)
Block(-28,38,1,MAGMA)
Block(-28,38,2,STAINED_GLASS:14)
Block(-28,38,3,STAINED_GLASS:14)
Block(-28,39,-4,STAINED_GLASS:10)
Block(-28,39,-3,STAINED_GLASS:10)
Block(-28,39,-2,STAINED_GLASS:14)
Block(-28,39,-1,MAGMA)
Block(-28,39,0,MAGMA)
Block(-28,39,1,STAINED_GLASS:14)
Block(-28,39,2,STAINED_GLASS:10)
Block(-28,39,3,STAINED_GLASS:14)
Block(-28,40,-3,STAINED_GLASS:10)
Block(-28,40,-2,STAINED_GLASS:10)
Block(-28,40,-1,STAINED_GLASS:10)
Block(-28,40,0,STAINED_GLASS:14)
Block(-28,40,1,STAINED_GLASS:10)
Block(-28,40,2,STAINED_GLASS:14)
Block(-28,41,-2,STAINED_GLASS:10)
Block(-28,41,-1,STAINED_GLASS:10)
Block(-28,41,0,STAINED_GLASS:14)
Block(-28,41,1,STAINED_GLASS:14)
Block(-28,42,-2,STAINED_GLASS:10)
Block(-28,42,-1,STAINED_GLASS:10)
Block(-28,42,0,STAINED_GLASS:14)
Block(-28,42,1,STAINED_GLASS:10)
Block(-28,43,-1,STAINED_GLASS:10)
Block(-28,43,0,STAINED_GLASS:14)
Block(-27,28,-2,STAINED_GLASS:10)
Block(-27,28,-1,STAINED_GLASS:10)
Block(-27,28,0,STAINED_GLASS:10)
Block(-27,28,1,STAINED_GLASS:10)
Block(-27,29,-2,STAINED_GLASS:10)
Block(-27,29,-1,STAINED_GLASS:10)
Block(-27,29,0,STAINED_GLASS:10)
Block(-27,29,1,STAINED_GLASS:14)
Block(-27,30,-2,STAINED_GLASS:10)
Block(-27,30,-1,STAINED_GLASS:10)
Block(-27,30,0,STAINED_GLASS:10)
Block(-27,30,1,STAINED_GLASS:14)
Block(-27,31,-2,STAINED_GLASS:10)
Block(-27,31,-1,STAINED_GLASS:14)
Block(-27,31,0,STAINED_GLASS:14)
Block(-27,31,1,STAINED_GLASS:10)
Block(-27,32,-3,STAINED_GLASS:10)
Block(-27,32,-2,STAINED_GLASS:14)
Block(-27,32,-1,STAINED_GLASS:10)
Block(-27,32,0,STAINED_GLASS:10)
Block(-27,32,1,STAINED_GLASS:14)
Block(-27,32,2,STAINED_GLASS:10)
Block(-27,33,-4,STAINED_GLASS:10)
Block(-27,33,-3,STAINED_GLASS:14)
Block(-27,33,-2,STAINED_GLASS:14)
Block(-27,33,-1,MAGMA)
Block(-27,33,0,MAGMA)
Block(-27,33,1,STAINED_GLASS:10)
Block(-27,33,2,STAINED_GLASS:14)
Block(-27,33,3,STAINED_GLASS:10)
Block(-27,34,-4,STAINED_GLASS:14)
Block(-27,34,-3,STAINED_GLASS:14)
Block(-27,34,-2,MAGMA)
Block(-27,34,-1,MAGMA)
Block(-27,34,0,MAGMA)
Block(-27,34,1,MAGMA)
Block(-27,34,2,STAINED_GLASS:14)
Block(-27,34,3,STAINED_GLASS:14)
Block(-27,35,-4,STAINED_GLASS:14)
Block(-27,35,-3,STAINED_GLASS:14)
Block(-27,35,-2,MAGMA)
Block(-27,35,-1,MAGMA)
Block(-27,35,0,MAGMA)
Block(-27,35,1,MAGMA)
Block(-27,35,2,STAINED_GLASS:10)
Block(-27,35,3,STAINED_GLASS:10)
Block(-27,36,-4,STAINED_GLASS:14)
Block(-27,36,-3,STAINED_GLASS:14)
Block(-27,36,-2,MAGMA)
Block(-27,36,-1,MAGMA)
Block(-27,36,0,MAGMA)
Block(-27,36,1,MAGMA)
Block(-27,36,2,STAINED_GLASS:10)
Block(-27,36,3,STAINED_GLASS:10)
Block(-27,37,-4,STAINED_GLASS:10)
Block(-27,37,-3,STAINED_GLASS:14)
Block(-27,37,-2,STAINED_GLASS:14)
Block(-27,37,-1,MAGMA)
Block(-27,37,0,MAGMA)
Block(-27,37,1,STAINED_GLASS:10)
Block(-27,37,2,STAINED_GLASS:10)
Block(-27,37,3,STAINED_GLASS:10)
Block(-27,38,-3,STAINED_GLASS:10)
Block(-27,38,-2,STAINED_GLASS:10)
Block(-27,38,-1,STAINED_GLASS:10)
Block(-27,38,0,STAINED_GLASS:14)
Block(-27,38,1,STAINED_GLASS:10)
Block(-27,38,2,STAINED_GLASS:10)
Block(-27,39,-2,STAINED_GLASS:14)
Block(-27,39,-1,STAINED_GLASS:10)
Block(-27,39,0,STAINED_GLASS:14)
Block(-27,39,1,STAINED_GLASS:10)
Block(-27,40,-2,STAINED_GLASS:10)
Block(-27,40,-1,STAINED_GLASS:10)
Block(-27,40,0,STAINED_GLASS:10)
Block(-27,40,1,STAINED_GLASS:10)
Block(-27,41,-1,STAINED_GLASS:10)
Block(-27,41,0,STAINED_GLASS:10)
Block(-26,26,-2,STAINED_GLASS:10)
Block(-26,26,-1,STAINED_GLASS:10)
Block(-26,26,0,STAINED_GLASS:10)
Block(-26,26,1,STAINED_GLASS:10)
Block(-26,27,-2,STAINED_GLASS:10)
Block(-26,27,-1,STAINED_GLASS:10)
Block(-26,27,0,STAINED_GLASS:10)
Block(-26,27,1,STAINED_GLASS:10)
Block(-26,28,-2,STAINED_GLASS:10)
Block(-26,28,-1,STAINED_GLASS:14)
Block(-26,28,0,STAINED_GLASS:10)
Block(-26,28,1,STAINED_GLASS:10)
Block(-26,29,-2,STAINED_GLASS:14)
Block(-26,29,-1,STAINED_GLASS:14)
Block(-26,29,0,STAINED_GLASS:10)
Block(-26,29,1,STAINED_GLASS:14)
Block(-26,30,-3,STAINED_GLASS:10)
Block(-26,30,-2,STAINED_GLASS:14)
Block(-26,30,-1,STAINED_GLASS:10)
Block(-26,30,0,STAINED_GLASS:14)
Block(-26,30,1,STAINED_GLASS:10)
Block(-26,30,2,STAINED_GLASS:10)
Block(-26,31,-4,STAINED_GLASS:10)
Block(-26,31,-3,STAINED_GLASS:14)
Block(-26,31,-2,STAINED_GLASS:10)
Block(-26,31,-1,MAGMA)
Block(-26,31,0,MAGMA)
Block(-26,31,1,STAINED_GLASS:10)
Block(-26,31,2,STAINED_GLASS:10)
Block(-26,31,3,STAINED_GLASS:10)
Block(-26,32,-4,STAINED_GLASS:14)
Block(-26,32,-3,STAINED_GLASS:14)
Block(-26,32,-2,MAGMA)
Block(-26,32,-1,MAGMA)
Block(-26,32,0,MAGMA)
Block(-26,32,1,MAGMA)
Block(-26,32,2,STAINED_GLASS:10)
Block(-26,32,3,STAINED_GLASS:14)
Block(-26,33,-4,STAINED_GLASS:14)
Block(-26,33,-3,STAINED_GLASS:14)
Block(-26,33,-2,MAGMA)
Block(-26,33,-1,MAGMA)
Block(-26,33,0,MAGMA)
Block(-26,33,1,MAGMA)
Block(-26,33,2,STAINED_GLASS:10)
Block(-26,33,3,STAINED_GLASS:10)
Block(-26,34,-4,STAINED_GLASS:14)
Block(-26,34,-3,STAINED_GLASS:14)
Block(-26,34,-2,MAGMA)
Block(-26,34,-1,MAGMA)
Block(-26,34,0,MAGMA)
Block(-26,34,1,MAGMA)
Block(-26,34,2,STAINED_GLASS:10)
Block(-26,34,3,STAINED_GLASS:14)
Block(-26,35,-4,STAINED_GLASS:10)
Block(-26,35,-3,STAINED_GLASS:14)
Block(-26,35,-2,STAINED_GLASS:14)
Block(-26,35,-1,MAGMA)
Block(-26,35,0,MAGMA)
Block(-26,35,1,STAINED_GLASS:14)
Block(-26,35,2,STAINED_GLASS:10)
Block(-26,35,3,STAINED_GLASS:14)
Block(-26,36,-3,STAINED_GLASS:10)
Block(-26,36,-2,STAINED_GLASS:14)
Block(-26,36,-1,STAINED_GLASS:10)
Block(-26,36,0,STAINED_GLASS:10)
Block(-26,36,1,STAINED_GLASS:10)
Block(-26,36,2,STAINED_GLASS:10)
Block(-26,37,-2,STAINED_GLASS:10)
Block(-26,37,-1,STAINED_GLASS:10)
Block(-26,37,0,STAINED_GLASS:10)
Block(-26,37,1,STAINED_GLASS:10)
Block(-26,38,-2,STAINED_GLASS:10)
Block(-26,38,-1,STAINED_GLASS:10)
Block(-26,38,0,STAINED_GLASS:10)
Block(-26,38,1,STAINED_GLASS:10)
Block(-26,39,-2,STAINED_GLASS:10)
Block(-26,39,-1,STAINED_GLASS:14)
Block(-26,39,0,STAINED_GLASS:14)
Block(-26,39,1,STAINED_GLASS:10)
Block(-26,40,-1,STAINED_GLASS:10)
Block(-26,40,0,STAINED_GLASS:14)
Block(-25,23,-2,STAINED_GLASS:10)
Block(-25,24,-2,STAINED_GLASS:10)
Block(-25,24,-1,STAINED_GLASS:10)
Block(-25,24,0,STAINED_GLASS:10)
Block(-25,24,1,STAINED_GLASS:10)
Block(-25,25,-2,STAINED_GLASS:10)
Block(-25,25,-1,STAINED_GLASS:10)
Block(-25,25,0,STAINED_GLASS:10)
Block(-25,25,1,STAINED_GLASS:10)
Block(-25,26,-2,STAINED_GLASS:10)
Block(-25,26,-1,STAINED_GLASS:10)
Block(-25,26,0,STAINED_GLASS:10)
Block(-25,26,1,STAINED_GLASS:10)
Block(-25,27,-2,STAINED_GLASS:10)
Block(-25,27,-1,STAINED_GLASS:10)
Block(-25,27,0,STAINED_GLASS:10)
Block(-25,27,1,STAINED_GLASS:10)
Block(-25,28,-3,STAINED_GLASS:10)
Block(-25,28,-2,STAINED_GLASS:10)
Block(-25,28,-1,STAINED_GLASS:10)
Block(-25,28,0,STAINED_GLASS:10)
Block(-25,28,1,STAINED_GLASS:10)
Block(-25,28,2,STAINED_GLASS:10)
Block(-25,29,-4,STAINED_GLASS:10)
Block(-25,29,-3,STAINED_GLASS:10)
Block(-25,29,-2,STAINED_GLASS:10)
Block(-25,29,-1,MAGMA)
Block(-25,29,0,MAGMA)
Block(-25,29,1,STAINED_GLASS:10)
Block(-25,29,2,STAINED_GLASS:10)
Block(-25,29,3,STAINED_GLASS:10)
Block(-25,30,-4,STAINED_GLASS:14)
Block(-25,30,-3,STAINED_GLASS:10)
Block(-25,30,-2,MAGMA)
Block(-25,30,-1,MAGMA)
Block(-25,30,0,MAGMA)
Block(-25,30,1,MAGMA)
Block(-25,30,2,STAINED_GLASS:10)
Block(-25,30,3,STAINED_GLASS:14)
Block(-25,31,-4,STAINED_GLASS:14)
Block(-25,31,-3,STAINED_GLASS:10)
Block(-25,31,-2,MAGMA)
Block(-25,31,-1,MAGMA)
Block(-25,31,0,MAGMA)
Block(-25,31,1,MAGMA)
Block(-25,31,2,STAINED_GLASS:10)
Block(-25,31,3,STAINED_GLASS:10)
Block(-25,32,-4,STAINED_GLASS:14)
Block(-25,32,-3,STAINED_GLASS:10)
Block(-25,32,-2,MAGMA)
Block(-25,32,-1,MAGMA)
Block(-25,32,0,MAGMA)
Block(-25,32,1,MAGMA)
Block(-25,32,2,STAINED_GLASS:10)
Block(-25,32,3,STAINED_GLASS:10)
Block(-25,33,-4,STAINED_GLASS:10)
Block(-25,33,-3,STAINED_GLASS:10)
Block(-25,33,-2,STAINED_GLASS:10)
Block(-25,33,-1,MAGMA)
Block(-25,33,0,MAGMA)
Block(-25,33,1,STAINED_GLASS:10)
Block(-25,33,2,STAINED_GLASS:10)
Block(-25,33,3,STAINED_GLASS:10)
Block(-25,34,-3,STAINED_GLASS:10)
Block(-25,34,-2,STAINED_GLASS:10)
Block(-25,34,-1,STAINED_GLASS:14)
Block(-25,34,0,STAINED_GLASS:10)
Block(-25,34,1,STAINED_GLASS:10)
Block(-25,34,2,STAINED_GLASS:14)
Block(-25,35,-2,STAINED_GLASS:10)
Block(-25,35,-1,STAINED_GLASS:10)
Block(-25,35,0,STAINED_GLASS:10)
Block(-25,35,1,STAINED_GLASS:14)
Block(-25,36,-2,STAINED_GLASS:10)
Block(-25,36,-1,STAINED_GLASS:10)
Block(-25,36,0,STAINED_GLASS:10)
Block(-25,36,1,STAINED_GLASS:10)
Block(-25,37,-2,STAINED_GLASS:10)
Block(-25,37,-1,STAINED_GLASS:10)
Block(-25,37,0,STAINED_GLASS:14)
Block(-25,37,1,STAINED_GLASS:10)
Block(-25,38,-1,STAINED_GLASS:14)
Block(-25,38,0,STAINED_GLASS:14)
Block(-24,22,-2,STAINED_GLASS:10)
Block(-24,22,-1,STAINED_GLASS:10)
Block(-24,22,0,STAINED_GLASS:10)
Block(-24,22,1,STAINED_GLASS:10)
Block(-24,23,-2,STAINED_GLASS:10)
Block(-24,23,-1,STAINED_GLASS:10)
Block(-24,23,0,STAINED_GLASS:10)
Block(-24,23,1,STAINED_GLASS:10)
Block(-24,24,-2,STAINED_GLASS:10)
Block(-24,24,-1,STAINED_GLASS:10)
Block(-24,24,0,STAINED_GLASS:10)
Block(-24,24,1,STAINED_GLASS:10)
Block(-24,25,-2,STAINED_GLASS:10)
Block(-24,25,-1,STAINED_GLASS:10)
Block(-24,25,0,STAINED_GLASS:10)
Block(-24,25,1,STAINED_GLASS:10)
Block(-24,26,-3,STAINED_GLASS:10)
Block(-24,26,-2,STAINED_GLASS:14)
Block(-24,26,-1,STAINED_GLASS:10)
Block(-24,26,0,STAINED_GLASS:10)
Block(-24,26,1,STAINED_GLASS:10)
Block(-24,26,2,STAINED_GLASS:10)
Block(-24,27,-4,STAINED_GLASS:10)
Block(-24,27,-3,STAINED_GLASS:14)
Block(-24,27,-2,STAINED_GLASS:10)
Block(-24,27,-1,MAGMA)
Block(-24,27,0,MAGMA)
Block(-24,27,1,STAINED_GLASS:14)
Block(-24,27,2,STAINED_GLASS:10)
Block(-24,27,3,STAINED_GLASS:10)
Block(-24,28,-4,STAINED_GLASS:14)
Block(-24,28,-3,STAINED_GLASS:10)
Block(-24,28,-2,MAGMA)
Block(-24,28,-1,MAGMA)
Block(-24,28,0,MAGMA)
Block(-24,28,1,MAGMA)
Block(-24,28,2,STAINED_GLASS:10)
Block(-24,28,3,STAINED_GLASS:14)
Block(-24,29,-4,STAINED_GLASS:14)
Block(-24,29,-3,STAINED_GLASS:10)
Block(-24,29,-2,MAGMA)
Block(-24,29,-1,MAGMA)
Block(-24,29,0,MAGMA)
Block(-24,29,1,MAGMA)
Block(-24,29,2,STAINED_GLASS:10)
Block(-24,29,3,STAINED_GLASS:10)
Block(-24,30,-4,STAINED_GLASS:14)
Block(-24,30,-3,STAINED_GLASS:10)
Block(-24,30,-2,MAGMA)
Block(-24,30,-1,MAGMA)
Block(-24,30,0,MAGMA)
Block(-24,30,1,MAGMA)
Block(-24,30,2,STAINED_GLASS:14)
Block(-24,30,3,STAINED_GLASS:10)
Block(-24,31,-4,STAINED_GLASS:14)
Block(-24,31,-3,STAINED_GLASS:10)
Block(-24,31,-2,STAINED_GLASS:14)
Block(-24,31,-1,MAGMA)
Block(-24,31,0,MAGMA)
Block(-24,31,1,STAINED_GLASS:10)
Block(-24,31,2,STAINED_GLASS:10)
Block(-24,31,3,STAINED_GLASS:10)
Block(-24,32,-3,STAINED_GLASS:10)
Block(-24,32,-2,STAINED_GLASS:14)
Block(-24,32,-1,STAINED_GLASS:14)
Block(-24,32,0,STAINED_GLASS:14)
Block(-24,32,1,STAINED_GLASS:14)
Block(-24,32,2,STAINED_GLASS:14)
Block(-24,33,-2,STAINED_GLASS:14)
Block(-24,33,-1,STAINED_GLASS:10)
Block(-24,33,0,STAINED_GLASS:10)
Block(-24,33,1,STAINED_GLASS:10)
Block(-24,34,-2,STAINED_GLASS:10)
Block(-24,34,-1,STAINED_GLASS:14)
Block(-24,34,0,STAINED_GLASS:10)
Block(-24,34,1,STAINED_GLASS:10)
Block(-24,35,-2,STAINED_GLASS:14)
Block(-24,35,-1,STAINED_GLASS:10)
Block(-24,35,0,STAINED_GLASS:14)
Block(-24,35,1,STAINED_GLASS:10)
Block(-24,36,-1,STAINED_GLASS:10)
Block(-24,36,0,STAINED_GLASS:10)
Block(-23,20,-2,STAINED_GLASS:10)
Block(-23,20,-1,STAINED_GLASS:10)
Block(-23,20,0,STAINED_GLASS:10)
Block(-23,20,1,STAINED_GLASS:10)
Block(-23,21,-2,STAINED_GLASS:10)
Block(-23,21,-1,STAINED_GLASS:10)
Block(-23,21,0,STAINED_GLASS:10)
Block(-23,21,1,STAINED_GLASS:10)
Block(-23,22,-2,STAINED_GLASS:10)
Block(-23,22,-1,STAINED_GLASS:10)
Block(-23,22,0,STAINED_GLASS:10)
Block(-23,22,1,STAINED_GLASS:10)
Block(-23,23,-2,STAINED_GLASS:10)
Block(-23,23,-1,STAINED_GLASS:14)
Block(-23,23,0,STAINED_GLASS:14)
Block(-23,23,1,STAINED_GLASS:10)
Block(-23,24,-3,STAINED_GLASS:10)
Block(-23,24,-2,STAINED_GLASS:10)
Block(-23,24,-1,STAINED_GLASS:14)
Block(-23,24,0,STAINED_GLASS:10)
Block(-23,24,1,STAINED_GLASS:10)
Block(-23,24,2,STAINED_GLASS:10)
Block(-23,25,-4,STAINED_GLASS:10)
Block(-23,25,-3,STAINED_GLASS:14)
Block(-23,25,-2,STAINED_GLASS:10)
Block(-23,25,-1,MAGMA)
Block(-23,25,0,MAGMA)
Block(-23,25,1,STAINED_GLASS:10)
Block(-23,25,2,STAINED_GLASS:10)
Block(-23,25,3,STAINED_GLASS:10)
Block(-23,26,-4,STAINED_GLASS:14)
Block(-23,26,-3,STAINED_GLASS:14)
Block(-23,26,-2,MAGMA)
Block(-23,26,-1,MAGMA)
Block(-23,26,0,MAGMA)
Block(-23,26,1,MAGMA)
Block(-23,26,2,STAINED_GLASS:10)
Block(-23,26,3,STAINED_GLASS:10)
Block(-23,27,-4,STAINED_GLASS:14)
Block(-23,27,-3,STAINED_GLASS:14)
Block(-23,27,-2,MAGMA)
Block(-23,27,-1,MAGMA)
Block(-23,27,0,MAGMA)
Block(-23,27,1,MAGMA)
Block(-23,27,2,STAINED_GLASS:14)
Block(-23,27,3,STAINED_GLASS:10)
Block(-23,28,-4,STAINED_GLASS:14)
Block(-23,28,-3,STAINED_GLASS:10)
Block(-23,28,-2,MAGMA)
Block(-23,28,-1,MAGMA)
Block(-23,28,0,MAGMA)
Block(-23,28,1,MAGMA)
Block(-23,28,2,STAINED_GLASS:14)
Block(-23,28,3,STAINED_GLASS:10)
Block(-23,29,-4,STAINED_GLASS:10)
Block(-23,29,-3,STAINED_GLASS:10)
Block(-23,29,-2,STAINED_GLASS:10)
Block(-23,29,-1,MAGMA)
Block(-23,29,0,MAGMA)
Block(-23,29,1,STAINED_GLASS:10)
Block(-23,29,2,STAINED_GLASS:10)
Block(-23,29,3,STAINED_GLASS:14)
Block(-23,30,-3,STAINED_GLASS:10)
Block(-23,30,-2,STAINED_GLASS:10)
Block(-23,30,-1,STAINED_GLASS:10)
Block(-23,30,0,STAINED_GLASS:14)
Block(-23,30,1,STAINED_GLASS:10)
Block(-23,30,2,STAINED_GLASS:14)
Block(-23,31,-2,STAINED_GLASS:14)
Block(-23,31,-1,STAINED_GLASS:10)
Block(-23,31,0,STAINED_GLASS:14)
Block(-23,31,1,STAINED_GLASS:14)
Block(-23,32,-2,STAINED_GLASS:10)
Block(-23,32,-1,STAINED_GLASS:14)
Block(-23,32,0,STAINED_GLASS:10)
Block(-23,32,1,STAINED_GLASS:10)
Block(-23,33,-2,STAINED_GLASS:10)
Block(-23,33,-1,STAINED_GLASS:10)
Block(-23,33,0,STAINED_GLASS:14)
Block(-23,33,1,STAINED_GLASS:10)
Block(-23,34,-1,STAINED_GLASS:14)
Block(-23,34,0,STAINED_GLASS:10)
Block(-22,18,-2,STAINED_GLASS:10)
Block(-22,18,-1,STAINED_GLASS:10)
Block(-22,18,0,STAINED_GLASS:10)
Block(-22,18,1,STAINED_GLASS:10)
Block(-22,19,-2,STAINED_GLASS:10)
Block(-22,19,-1,STAINED_GLASS:10)
Block(-22,19,0,STAINED_GLASS:10)
Block(-22,19,1,STAINED_GLASS:10)
Block(-22,20,-2,STAINED_GLASS:10)
Block(-22,20,-1,STAINED_GLASS:10)
Block(-22,20,0,STAINED_GLASS:10)
Block(-22,20,1,STAINED_GLASS:10)
Block(-22,21,-2,STAINED_GLASS:10)
Block(-22,21,-1,STAINED_GLASS:10)
Block(-22,21,0,STAINED_GLASS:14)
Block(-22,21,1,STAINED_GLASS:10)
Block(-22,22,-3,STAINED_GLASS:10)
Block(-22,22,-2,STAINED_GLASS:10)
Block(-22,22,-1,STAINED_GLASS:10)
Block(-22,22,0,STAINED_GLASS:10)
Block(-22,22,1,STAINED_GLASS:10)
Block(-22,22,2,STAINED_GLASS:10)
Block(-22,23,-4,STAINED_GLASS:10)
Block(-22,23,-3,STAINED_GLASS:14)
Block(-22,23,-2,STAINED_GLASS:10)
Block(-22,23,-1,MAGMA)
Block(-22,23,0,MAGMA)
Block(-22,23,1,STAINED_GLASS:10)
Block(-22,23,2,STAINED_GLASS:10)
Block(-22,23,3,STAINED_GLASS:10)
Block(-22,24,-4,STAINED_GLASS:14)
Block(-22,24,-3,STAINED_GLASS:10)
Block(-22,24,-2,MAGMA)
Block(-22,24,-1,MAGMA)
Block(-22,24,0,MAGMA)
Block(-22,24,1,MAGMA)
Block(-22,24,2,STAINED_GLASS:10)
Block(-22,24,3,STAINED_GLASS:10)
Block(-22,25,-4,STAINED_GLASS:14)
Block(-22,25,-3,STAINED_GLASS:14)
Block(-22,25,-2,MAGMA)
Block(-22,25,-1,MAGMA)
Block(-22,25,0,MAGMA)
Block(-22,25,1,MAGMA)
Block(-22,25,2,STAINED_GLASS:10)
Block(-22,25,3,STAINED_GLASS:10)
Block(-22,26,-4,STAINED_GLASS:14)
Block(-22,26,-3,STAINED_GLASS:10)
Block(-22,26,-2,MAGMA)
Block(-22,26,-1,MAGMA)
Block(-22,26,0,MAGMA)
Block(-22,26,1,MAGMA)
Block(-22,26,2,STAINED_GLASS:10)
Block(-22,26,3,STAINED_GLASS:14)
Block(-22,27,-4,STAINED_GLASS:10)
Block(-22,27,-3,STAINED_GLASS:14)
Block(-22,27,-2,STAINED_GLASS:10)
Block(-22,27,-1,MAGMA)
Block(-22,27,0,MAGMA)
Block(-22,27,1,STAINED_GLASS:14)
Block(-22,27,2,STAINED_GLASS:10)
Block(-22,27,3,STAINED_GLASS:10)
Block(-22,28,-3,STAINED_GLASS:10)
Block(-22,28,-2,STAINED_GLASS:10)
Block(-22,28,-1,STAINED_GLASS:14)
Block(-22,28,0,STAINED_GLASS:10)
Block(-22,28,1,STAINED_GLASS:10)
Block(-22,28,2,STAINED_GLASS:10)
Block(-22,29,-2,STAINED_GLASS:10)
Block(-22,29,-1,STAINED_GLASS:14)
Block(-22,29,0,STAINED_GLASS:10)
Block(-22,29,1,STAINED_GLASS:14)
Block(-22,30,-2,STAINED_GLASS:10)
Block(-22,30,-1,STAINED_GLASS:10)
Block(-22,30,0,STAINED_GLASS:10)
Block(-22,30,1,STAINED_GLASS:10)
Block(-22,31,-2,STAINED_GLASS:10)
Block(-22,31,-1,STAINED_GLASS:10)
Block(-22,31,0,STAINED_GLASS:10)
Block(-22,31,1,STAINED_GLASS:10)
Block(-22,32,-1,STAINED_GLASS:14)
Block(-22,32,0,STAINED_GLASS:10)
Block(-21,16,-2,STAINED_GLASS:10)
Block(-21,16,-1,STAINED_GLASS:10)
Block(-21,16,0,STAINED_GLASS:10)
Block(-21,16,1,STAINED_GLASS:10)
Block(-21,17,-2,STAINED_GLASS:10)
Block(-21,17,-1,STAINED_GLASS:10)
Block(-21,17,0,STAINED_GLASS:10)
Block(-21,17,1,STAINED_GLASS:10)
Block(-21,18,-2,STAINED_GLASS:10)
Block(-21,18,-1,STAINED_GLASS:10)
Block(-21,18,0,STAINED_GLASS:10)
Block(-21,18,1,STAINED_GLASS:10)
Block(-21,19,-2,STAINED_GLASS:10)
Block(-21,19,-1,STAINED_GLASS:14)
Block(-21,19,0,STAINED_GLASS:14)
Block(-21,19,1,STAINED_GLASS:10)
Block(-21,20,-3,STAINED_GLASS:10)
Block(-21,20,-2,STAINED_GLASS:14)
Block(-21,20,-1,STAINED_GLASS:14)
Block(-21,20,0,STAINED_GLASS:10)
Block(-21,20,1,STAINED_GLASS:10)
Block(-21,20,2,STAINED_GLASS:10)
Block(-21,21,-4,STAINED_GLASS:10)
Block(-21,21,-3,STAINED_GLASS:14)
Block(-21,21,-2,STAINED_GLASS:10)
Block(-21,21,-1,MAGMA)
Block(-21,21,0,MAGMA)
Block(-21,21,1,STAINED_GLASS:10)
Block(-21,21,2,STAINED_GLASS:10)
Block(-21,21,3,STAINED_GLASS:10)
Block(-21,22,-4,STAINED_GLASS:14)
Block(-21,22,-3,STAINED_GLASS:10)
Block(-21,22,-2,MAGMA)
Block(-21,22,-1,MAGMA)
Block(-21,22,0,MAGMA)
Block(-21,22,1,MAGMA)
Block(-21,22,2,STAINED_GLASS:10)
Block(-21,22,3,STAINED_GLASS:10)
Block(-21,23,-4,STAINED_GLASS:14)
Block(-21,23,-3,STAINED_GLASS:14)
Block(-21,23,-2,MAGMA)
Block(-21,23,-1,MAGMA)
Block(-21,23,0,MAGMA)
Block(-21,23,1,MAGMA)
Block(-21,23,2,STAINED_GLASS:10)
Block(-21,23,3,STAINED_GLASS:10)
Block(-21,24,-4,STAINED_GLASS:10)
Block(-21,24,-3,STAINED_GLASS:10)
Block(-21,24,-2,MAGMA)
Block(-21,24,-1,MAGMA)
Block(-21,24,0,MAGMA)
Block(-21,24,1,MAGMA)
Block(-21,24,2,STAINED_GLASS:10)
Block(-21,24,3,STAINED_GLASS:10)
Block(-21,25,-4,STAINED_GLASS:14)
Block(-21,25,-3,STAINED_GLASS:14)
Block(-21,25,-2,STAINED_GLASS:10)
Block(-21,25,-1,MAGMA)
Block(-21,25,0,MAGMA)
Block(-21,25,1,STAINED_GLASS:10)
Block(-21,25,2,STAINED_GLASS:10)
Block(-21,25,3,STAINED_GLASS:10)
Block(-21,26,-3,STAINED_GLASS:10)
Block(-21,26,-2,STAINED_GLASS:14)
Block(-21,26,-1,STAINED_GLASS:10)
Block(-21,26,0,STAINED_GLASS:14)
Block(-21,26,1,STAINED_GLASS:14)
Block(-21,26,2,STAINED_GLASS:10)
Block(-21,27,-2,STAINED_GLASS:10)
Block(-21,27,-1,STAINED_GLASS:10)
Block(-21,27,0,STAINED_GLASS:10)
Block(-21,27,1,STAINED_GLASS:10)
Block(-21,28,-2,STAINED_GLASS:10)
Block(-21,28,-1,STAINED_GLASS:10)
Block(-21,28,0,STAINED_GLASS:10)
Block(-21,28,1,STAINED_GLASS:14)
Block(-21,29,-2,STAINED_GLASS:10)
Block(-21,29,-1,STAINED_GLASS:10)
Block(-21,29,0,STAINED_GLASS:10)
Block(-21,29,1,STAINED_GLASS:10)
Block(-21,30,-1,STAINED_GLASS:14)
Block(-21,30,0,STAINED_GLASS:10)
Block(-20,14,-2,STAINED_GLASS:10)
Block(-20,14,-1,STAINED_GLASS:10)
Block(-20,14,0,STAINED_GLASS:10)
Block(-20,14,1,STAINED_GLASS:10)
Block(-20,15,-2,STAINED_GLASS:10)
Block(-20,15,-1,STAINED_GLASS:10)
Block(-20,15,0,STAINED_GLASS:10)
Block(-20,15,1,STAINED_GLASS:10)
Block(-20,16,-2,STAINED_GLASS:10)
Block(-20,16,-1,STAINED_GLASS:10)
Block(-20,16,0,STAINED_GLASS:10)
Block(-20,16,1,STAINED_GLASS:10)
Block(-20,17,-2,STAINED_GLASS:10)
Block(-20,17,-1,STAINED_GLASS:10)
Block(-20,17,0,STAINED_GLASS:14)
Block(-20,17,1,STAINED_GLASS:10)
Block(-20,18,-3,STAINED_GLASS:10)
Block(-20,18,-2,STAINED_GLASS:14)
Block(-20,18,-1,STAINED_GLASS:10)
Block(-20,18,0,STAINED_GLASS:10)
Block(-20,18,1,STAINED_GLASS:10)
Block(-20,18,2,STAINED_GLASS:10)
Block(-20,19,-4,STAINED_GLASS:10)
Block(-20,19,-3,STAINED_GLASS:14)
Block(-20,19,-2,STAINED_GLASS:14)
Block(-20,19,-1,MAGMA)
Block(-20,19,0,MAGMA)
Block(-20,19,1,STAINED_GLASS:10)
Block(-20,19,2,STAINED_GLASS:10)
Block(-20,19,3,STAINED_GLASS:10)
Block(-20,20,-4,STAINED_GLASS:14)
Block(-20,20,-3,STAINED_GLASS:14)
Block(-20,20,-2,MAGMA)
Block(-20,20,-1,MAGMA)
Block(-20,20,0,MAGMA)
Block(-20,20,1,MAGMA)
Block(-20,20,2,STAINED_GLASS:14)
Block(-20,20,3,STAINED_GLASS:10)
Block(-20,21,-4,STAINED_GLASS:14)
Block(-20,21,-3,STAINED_GLASS:14)
Block(-20,21,-2,MAGMA)
Block(-20,21,-1,MAGMA)
Block(-20,21,0,MAGMA)
Block(-20,21,1,MAGMA)
Block(-20,21,2,STAINED_GLASS:10)
Block(-20,21,3,STAINED_GLASS:14)
Block(-20,22,-4,STAINED_GLASS:14)
Block(-20,22,-3,STAINED_GLASS:10)
Block(-20,22,-2,MAGMA)
Block(-20,22,-1,MAGMA)
Block(-20,22,0,MAGMA)
Block(-20,22,1,MAGMA)
Block(-20,22,2,STAINED_GLASS:14)
Block(-20,22,3,STAINED_GLASS:14)
Block(-20,23,-4,STAINED_GLASS:14)
Block(-20,23,-3,STAINED_GLASS:10)
Block(-20,23,-2,STAINED_GLASS:14)
Block(-20,23,-1,MAGMA)
Block(-20,23,0,MAGMA)
Block(-20,23,1,STAINED_GLASS:10)
Block(-20,23,2,STAINED_GLASS:14)
Block(-20,23,3,STAINED_GLASS:14)
Block(-20,24,-3,STAINED_GLASS:10)
Block(-20,24,-2,STAINED_GLASS:10)
Block(-20,24,-1,STAINED_GLASS:10)
Block(-20,24,0,STAINED_GLASS:10)
Block(-20,24,1,STAINED_GLASS:10)
Block(-20,24,2,STAINED_GLASS:10)
Block(-20,25,-2,STAINED_GLASS:14)
Block(-20,25,-1,STAINED_GLASS:10)
Block(-20,25,0,STAINED_GLASS:10)
Block(-20,25,1,STAINED_GLASS:14)
Block(-20,26,-2,STAINED_GLASS:10)
Block(-20,26,-1,STAINED_GLASS:10)
Block(-20,26,0,STAINED_GLASS:14)
Block(-20,26,1,STAINED_GLASS:10)
Block(-20,27,-2,STAINED_GLASS:14)
Block(-20,27,-1,STAINED_GLASS:10)
Block(-20,27,0,STAINED_GLASS:10)
Block(-20,27,1,STAINED_GLASS:10)
Block(-20,28,-1,STAINED_GLASS:10)
Block(-20,28,0,STAINED_GLASS:10)
Block(-19,12,-1,STAINED_GLASS:10)
Block(-19,12,0,STAINED_GLASS:10)
Block(-19,12,1,STAINED_GLASS:10)
Block(-19,13,-2,STAINED_GLASS:10)
Block(-19,13,-1,STAINED_GLASS:10)
Block(-19,13,0,STAINED_GLASS:10)
Block(-19,13,1,STAINED_GLASS:10)
Block(-19,14,-2,STAINED_GLASS:10)
Block(-19,14,-1,STAINED_GLASS:10)
Block(-19,14,0,STAINED_GLASS:10)
Block(-19,14,1,STAINED_GLASS:10)
Block(-19,15,-2,STAINED_GLASS:10)
Block(-19,15,-1,STAINED_GLASS:10)
Block(-19,15,0,STAINED_GLASS:14)
Block(-19,15,1,STAINED_GLASS:10)
Block(-19,16,-3,STAINED_GLASS:10)
Block(-19,16,-2,STAINED_GLASS:10)
Block(-19,16,-1,STAINED_GLASS:10)
Block(-19,16,0,STAINED_GLASS:14)
Block(-19,16,1,STAINED_GLASS:10)
Block(-19,16,2,STAINED_GLASS:10)
Block(-19,17,-4,STAINED_GLASS:10)
Block(-19,17,-3,STAINED_GLASS:14)
Block(-19,17,-2,STAINED_GLASS:10)
Block(-19,17,-1,MAGMA)
Block(-19,17,0,MAGMA)
Block(-19,17,1,STAINED_GLASS:10)
Block(-19,17,2,STAINED_GLASS:10)
Block(-19,17,3,STAINED_GLASS:10)
Block(-19,18,-4,STAINED_GLASS:14)
Block(-19,18,-3,STAINED_GLASS:14)
Block(-19,18,-2,MAGMA)
Block(-19,18,-1,MAGMA)
Block(-19,18,0,MAGMA)
Block(-19,18,1,MAGMA)
Block(-19,18,2,STAINED_GLASS:10)
Block(-19,18,3,STAINED_GLASS:14)
Block(-19,19,-4,STAINED_GLASS:14)
Block(-19,19,-3,STAINED_GLASS:14)
Block(-19,19,-2,MAGMA)
Block(-19,19,-1,MAGMA)
Block(-19,19,0,MAGMA)
Block(-19,19,1,MAGMA)
Block(-19,19,2,STAINED_GLASS:10)
Block(-19,19,3,STAINED_GLASS:10)
Block(-19,20,-4,STAINED_GLASS:14)
Block(-19,20,-3,STAINED_GLASS:14)
Block(-19,20,-2,MAGMA)
Block(-19,20,-1,MAGMA)
Block(-19,20,0,MAGMA)
Block(-19,20,1,MAGMA)
Block(-19,20,2,STAINED_GLASS:10)
Block(-19,20,3,STAINED_GLASS:14)
Block(-19,21,-4,STAINED_GLASS:10)
Block(-19,21,-3,STAINED_GLASS:14)
Block(-19,21,-2,STAINED_GLASS:10)
Block(-19,21,-1,MAGMA)
Block(-19,21,0,MAGMA)
Block(-19,21,1,STAINED_GLASS:10)
Block(-19,21,2,STAINED_GLASS:10)
Block(-19,21,3,STAINED_GLASS:10)
Block(-19,22,-3,STAINED_GLASS:14)
Block(-19,22,-2,STAINED_GLASS:10)
Block(-19,22,-1,STAINED_GLASS:10)
Block(-19,22,0,STAINED_GLASS:10)
Block(-19,22,1,STAINED_GLASS:14)
Block(-19,22,2,STAINED_GLASS:10)
Block(-19,23,-2,STAINED_GLASS:10)
Block(-19,23,-1,STAINED_GLASS:10)
Block(-19,23,0,STAINED_GLASS:10)
Block(-19,23,1,STAINED_GLASS:14)
Block(-19,24,-2,STAINED_GLASS:10)
Block(-19,24,-1,STAINED_GLASS:10)
Block(-19,24,0,STAINED_GLASS:14)
Block(-19,24,1,STAINED_GLASS:10)
Block(-19,25,-2,STAINED_GLASS:10)
Block(-19,25,-1,STAINED_GLASS:10)
Block(-19,25,0,STAINED_GLASS:14)
Block(-19,25,1,STAINED_GLASS:10)
Block(-19,26,-1,STAINED_GLASS:10)
Block(-19,26,0,STAINED_GLASS:10)
Block(-18,10,-1,STAINED_GLASS:10)
Block(-18,10,0,STAINED_GLASS:10)
Block(-18,10,1,STAINED_GLASS:10)
Block(-18,11,-2,STAINED_GLASS:10)
Block(-18,11,-1,STAINED_GLASS:10)
Block(-18,11,0,STAINED_GLASS:10)
Block(-18,11,1,STAINED_GLASS:10)
Block(-18,12,-2,STAINED_GLASS:10)
Block(-18,12,-1,STAINED_GLASS:10)
Block(-18,12,0,STAINED_GLASS:10)
Block(-18,12,1,STAINED_GLASS:10)
Block(-18,13,-2,STAINED_GLASS:10)
Block(-18,13,-1,STAINED_GLASS:14)
Block(-18,13,0,STAINED_GLASS:14)
Block(-18,13,1,STAINED_GLASS:10)
Block(-18,14,-3,STAINED_GLASS:10)
Block(-18,14,-2,STAINED_GLASS:14)
Block(-18,14,-1,STAINED_GLASS:10)
Block(-18,14,0,STAINED_GLASS:10)
Block(-18,14,1,STAINED_GLASS:14)
Block(-18,14,2,STAINED_GLASS:10)
Block(-18,15,-4,STAINED_GLASS:10)
Block(-18,15,-3,STAINED_GLASS:14)
Block(-18,15,-2,STAINED_GLASS:14)
Block(-18,15,-1,MAGMA)
Block(-18,15,0,MAGMA)
Block(-18,15,1,STAINED_GLASS:10)
Block(-18,15,2,STAINED_GLASS:10)
Block(-18,15,3,STAINED_GLASS:10)
Block(-18,16,-4,STAINED_GLASS:14)
Block(-18,16,-3,STAINED_GLASS:10)
Block(-18,16,-2,MAGMA)
Block(-18,16,-1,MAGMA)
Block(-18,16,0,MAGMA)
Block(-18,16,1,MAGMA)
Block(-18,16,2,STAINED_GLASS:10)
Block(-18,16,3,STAINED_GLASS:10)
Block(-18,17,-4,STAINED_GLASS:14)
Block(-18,17,-3,STAINED_GLASS:14)
Block(-18,17,-2,MAGMA)
Block(-18,17,-1,MAGMA)
Block(-18,17,0,MAGMA)
Block(-18,17,1,MAGMA)
Block(-18,17,2,STAINED_GLASS:10)
Block(-18,17,3,STAINED_GLASS:10)
Block(-18,18,-4,STAINED_GLASS:14)
Block(-18,18,-3,STAINED_GLASS:14)
Block(-18,18,-2,MAGMA)
Block(-18,18,-1,MAGMA)
Block(-18,18,0,MAGMA)
Block(-18,18,1,MAGMA)
Block(-18,18,2,STAINED_GLASS:14)
Block(-18,18,3,STAINED_GLASS:10)
Block(-18,19,-4,STAINED_GLASS:10)
Block(-18,19,-3,STAINED_GLASS:14)
Block(-18,19,-2,STAINED_GLASS:10)
Block(-18,19,-1,MAGMA)
Block(-18,19,0,MAGMA)
Block(-18,19,1,STAINED_GLASS:14)
Block(-18,19,2,STAINED_GLASS:10)
Block(-18,19,3,STAINED_GLASS:10)
Block(-18,20,-3,STAINED_GLASS:10)
Block(-18,20,-2,STAINED_GLASS:10)
Block(-18,20,-1,STAINED_GLASS:10)
Block(-18,20,0,STAINED_GLASS:14)
Block(-18,20,1,STAINED_GLASS:14)
Block(-18,20,2,STAINED_GLASS:10)
Block(-18,21,-2,STAINED_GLASS:10)
Block(-18,21,-1,STAINED_GLASS:10)
Block(-18,21,0,STAINED_GLASS:14)
Block(-18,21,1,STAINED_GLASS:10)
Block(-18,22,-2,STAINED_GLASS:10)
Block(-18,22,-1,STAINED_GLASS:10)
Block(-18,22,0,STAINED_GLASS:10)
Block(-18,22,1,STAINED_GLASS:10)
Block(-18,23,-2,STAINED_GLASS:10)
Block(-18,23,-1,STAINED_GLASS:14)
Block(-18,23,0,STAINED_GLASS:14)
Block(-18,23,1,STAINED_GLASS:10)
Block(-18,24,-1,STAINED_GLASS:14)
Block(-18,24,0,STAINED_GLASS:10)
Block(-17,8,-2,STAINED_GLASS:10)
Block(-17,8,-1,STAINED_GLASS:10)
Block(-17,8,0,STAINED_GLASS:10)
Block(-17,8,1,STAINED_GLASS:10)
Block(-17,9,-2,STAINED_GLASS:10)
Block(-17,9,-1,STAINED_GLASS:10)
Block(-17,9,0,STAINED_GLASS:14)
Block(-17,9,1,STAINED_GLASS:10)
Block(-17,10,-2,STAINED_GLASS:10)
Block(-17,10,-1,STAINED_GLASS:14)
Block(-17,10,0,STAINED_GLASS:14)
Block(-17,10,1,STAINED_GLASS:10)
Block(-17,11,-2,STAINED_GLASS:10)
Block(-17,11,-1,STAINED_GLASS:10)
Block(-17,11,0,STAINED_GLASS:10)
Block(-17,11,1,STAINED_GLASS:10)
Block(-17,12,-3,STAINED_GLASS:10)
Block(-17,12,-2,STAINED_GLASS:14)
Block(-17,12,-1,STAINED_GLASS:14)
Block(-17,12,0,STAINED_GLASS:14)
Block(-17,12,1,STAINED_GLASS:10)
Block(-17,12,2,STAINED_GLASS:10)
Block(-17,13,-4,STAINED_GLASS:10)
Block(-17,13,-3,STAINED_GLASS:14)
Block(-17,13,-2,STAINED_GLASS:14)
Block(-17,13,-1,MAGMA)
Block(-17,13,0,MAGMA)
Block(-17,13,1,STAINED_GLASS:14)
Block(-17,13,2,STAINED_GLASS:10)
Block(-17,13,3,STAINED_GLASS:10)
Block(-17,14,-4,STAINED_GLASS:14)
Block(-17,14,-3,STAINED_GLASS:14)
Block(-17,14,-2,MAGMA)
Block(-17,14,-1,MAGMA)
Block(-17,14,0,MAGMA)
Block(-17,14,1,MAGMA)
Block(-17,14,2,STAINED_GLASS:10)
Block(-17,14,3,STAINED_GLASS:10)
Block(-17,15,-4,STAINED_GLASS:14)
Block(-17,15,-3,STAINED_GLASS:14)
Block(-17,15,-2,MAGMA)
Block(-17,15,-1,MAGMA)
Block(-17,15,0,MAGMA)
Block(-17,15,1,MAGMA)
Block(-17,15,2,STAINED_GLASS:10)
Block(-17,15,3,STAINED_GLASS:14)
Block(-17,16,-4,STAINED_GLASS:14)
Block(-17,16,-3,STAINED_GLASS:10)
Block(-17,16,-2,MAGMA)
Block(-17,16,-1,MAGMA)
Block(-17,16,0,MAGMA)
Block(-17,16,1,MAGMA)
Block(-17,16,2,STAINED_GLASS:10)
Block(-17,16,3,STAINED_GLASS:10)
Block(-17,17,-4,STAINED_GLASS:14)
Block(-17,17,-3,STAINED_GLASS:10)
Block(-17,17,-2,STAINED_GLASS:10)
Block(-17,17,-1,MAGMA)
Block(-17,17,0,MAGMA)
Block(-17,17,1,STAINED_GLASS:14)
Block(-17,17,2,STAINED_GLASS:10)
Block(-17,17,3,STAINED_GLASS:10)
Block(-17,18,-3,STAINED_GLASS:14)
Block(-17,18,-2,STAINED_GLASS:10)
Block(-17,18,-1,STAINED_GLASS:10)
Block(-17,18,0,STAINED_GLASS:10)
Block(-17,18,1,STAINED_GLASS:14)
Block(-17,18,2,STAINED_GLASS:10)
Block(-17,19,-2,STAINED_GLASS:14)
Block(-17,19,-1,STAINED_GLASS:10)
Block(-17,19,0,STAINED_GLASS:10)
Block(-17,19,1,STAINED_GLASS:10)
Block(-17,20,-2,STAINED_GLASS:10)
Block(-17,20,-1,STAINED_GLASS:14)
Block(-17,20,0,STAINED_GLASS:10)
Block(-17,20,1,STAINED_GLASS:10)
Block(-17,21,-2,STAINED_GLASS:10)
Block(-17,21,-1,STAINED_GLASS:10)
Block(-17,21,0,STAINED_GLASS:14)
Block(-17,21,1,STAINED_GLASS:10)
Block(-17,22,-1,STAINED_GLASS:14)
Block(-17,22,0,STAINED_GLASS:10)
Block(-16,5,-2,STAINED_GLASS:10)
Block(-16,6,-2,STAINED_GLASS:10)
Block(-16,6,-1,STAINED_GLASS:10)
Block(-16,6,0,STAINED_GLASS:10)
Block(-16,6,1,STAINED_GLASS:10)
Block(-16,7,-2,STAINED_GLASS:10)
Block(-16,7,-1,STAINED_GLASS:10)
Block(-16,7,0,STAINED_GLASS:10)
Block(-16,7,1,STAINED_GLASS:10)
Block(-16,8,-2,STAINED_GLASS:10)
Block(-16,8,-1,STAINED_GLASS:14)
Block(-16,8,0,STAINED_GLASS:14)
Block(-16,8,1,STAINED_GLASS:10)
Block(-16,9,-2,STAINED_GLASS:10)
Block(-16,9,-1,STAINED_GLASS:10)
Block(-16,9,0,STAINED_GLASS:10)
Block(-16,9,1,STAINED_GLASS:10)
Block(-16,10,-3,STAINED_GLASS:10)
Block(-16,10,-2,STAINED_GLASS:10)
Block(-16,10,-1,STAINED_GLASS:14)
Block(-16,10,0,STAINED_GLASS:10)
Block(-16,10,1,STAINED_GLASS:14)
Block(-16,10,2,STAINED_GLASS:14)
Block(-16,11,-4,STAINED_GLASS:10)
Block(-16,11,-3,STAINED_GLASS:14)
Block(-16,11,-2,STAINED_GLASS:10)
Block(-16,11,-1,MAGMA)
Block(-16,11,0,MAGMA)
Block(-16,11,1,STAINED_GLASS:14)
Block(-16,11,2,STAINED_GLASS:14)
Block(-16,11,3,STAINED_GLASS:10)
Block(-16,12,-4,STAINED_GLASS:14)
Block(-16,12,-3,STAINED_GLASS:14)
Block(-16,12,-2,MAGMA)
Block(-16,12,-1,MAGMA)
Block(-16,12,0,MAGMA)
Block(-16,12,1,MAGMA)
Block(-16,12,2,STAINED_GLASS:14)
Block(-16,12,3,STAINED_GLASS:14)
Block(-16,13,-4,STAINED_GLASS:14)
Block(-16,13,-3,STAINED_GLASS:14)
Block(-16,13,-2,MAGMA)
Block(-16,13,-1,MAGMA)
Block(-16,13,0,MAGMA)
Block(-16,13,1,MAGMA)
Block(-16,13,2,STAINED_GLASS:10)
Block(-16,13,3,STAINED_GLASS:10)
Block(-16,14,-4,STAINED_GLASS:14)
Block(-16,14,-3,STAINED_GLASS:14)
Block(-16,14,-2,MAGMA)
Block(-16,14,-1,MAGMA)
Block(-16,14,0,MAGMA)
Block(-16,14,1,MAGMA)
Block(-16,14,2,STAINED_GLASS:14)
Block(-16,14,3,STAINED_GLASS:10)
Block(-16,15,-4,STAINED_GLASS:10)
Block(-16,15,-3,STAINED_GLASS:10)
Block(-16,15,-2,STAINED_GLASS:10)
Block(-16,15,-1,MAGMA)
Block(-16,15,0,MAGMA)
Block(-16,15,1,STAINED_GLASS:14)
Block(-16,15,2,STAINED_GLASS:14)
Block(-16,15,3,STAINED_GLASS:10)
Block(-16,16,-3,STAINED_GLASS:10)
Block(-16,16,-2,STAINED_GLASS:10)
Block(-16,16,-1,STAINED_GLASS:10)
Block(-16,16,0,STAINED_GLASS:10)
Block(-16,16,1,STAINED_GLASS:14)
Block(-16,16,2,STAINED_GLASS:10)
Block(-16,17,-2,STAINED_GLASS:10)
Block(-16,17,-1,STAINED_GLASS:10)
Block(-16,17,0,STAINED_GLASS:10)
Block(-16,17,1,STAINED_GLASS:10)
Block(-16,18,-2,STAINED_GLASS:10)
Block(-16,18,-1,STAINED_GLASS:10)
Block(-16,18,0,STAINED_GLASS:14)
Block(-16,18,1,STAINED_GLASS:14)
Block(-16,19,-2,STAINED_GLASS:10)
Block(-16,19,-1,STAINED_GLASS:10)
Block(-16,19,0,STAINED_GLASS:10)
Block(-16,19,1,STAINED_GLASS:10)
Block(-16,20,-1,STAINED_GLASS:14)
Block(-16,20,0,STAINED_GLASS:14)
Block(-15,3,-2,STAINED_GLASS:10)
Block(-15,4,-2,STAINED_GLASS:10)
Block(-15,4,-1,STAINED_GLASS:10)
Block(-15,4,0,STAINED_GLASS:10)
Block(-15,4,1,STAINED_GLASS:10)
Block(-15,5,-2,STAINED_GLASS:10)
Block(-15,5,-1,STAINED_GLASS:10)
Block(-15,5,0,STAINED_GLASS:14)
Block(-15,5,1,STAINED_GLASS:10)
Block(-15,6,-2,STAINED_GLASS:10)
Block(-15,6,-1,STAINED_GLASS:14)
Block(-15,6,0,STAINED_GLASS:10)
Block(-15,6,1,STAINED_GLASS:10)
Block(-15,7,-2,STAINED_GLASS:10)
Block(-15,7,-1,STAINED_GLASS:10)
Block(-15,7,0,STAINED_GLASS:14)
Block(-15,7,1,STAINED_GLASS:10)
Block(-15,8,-3,STAINED_GLASS:10)
Block(-15,8,-2,STAINED_GLASS:10)
Block(-15,8,-1,STAINED_GLASS:10)
Block(-15,8,0,STAINED_GLASS:14)
Block(-15,8,1,STAINED_GLASS:10)
Block(-15,8,2,STAINED_GLASS:10)
Block(-15,9,-4,STAINED_GLASS:10)
Block(-15,9,-3,STAINED_GLASS:10)
Block(-15,9,-2,STAINED_GLASS:10)
Block(-15,9,-1,MAGMA)
Block(-15,9,0,MAGMA)
Block(-15,9,1,STAINED_GLASS:10)
Block(-15,9,2,STAINED_GLASS:10)
Block(-15,9,3,STAINED_GLASS:10)
Block(-15,10,-4,STAINED_GLASS:14)
Block(-15,10,-3,STAINED_GLASS:10)
Block(-15,10,-2,MAGMA)
Block(-15,10,-1,MAGMA)
Block(-15,10,0,MAGMA)
Block(-15,10,1,MAGMA)
Block(-15,10,2,STAINED_GLASS:14)
Block(-15,10,3,STAINED_GLASS:10)
Block(-15,11,-4,STAINED_GLASS:14)
Block(-15,11,-3,STAINED_GLASS:10)
Block(-15,11,-2,MAGMA)
Block(-15,11,-1,MAGMA)
Block(-15,11,0,MAGMA)
Block(-15,11,1,MAGMA)
Block(-15,11,2,STAINED_GLASS:10)
Block(-15,11,3,STAINED_GLASS:14)
Block(-15,12,-4,STAINED_GLASS:14)
Block(-15,12,-3,STAINED_GLASS:14)
Block(-15,12,-2,MAGMA)
Block(-15,12,-1,MAGMA)
Block(-15,12,0,MAGMA)
Block(-15,12,1,MAGMA)
Block(-15,12,2,STAINED_GLASS:10)
Block(-15,12,3,STAINED_GLASS:10)
Block(-15,13,-4,STAINED_GLASS:10)
Block(-15,13,-3,STAINED_GLASS:10)
Block(-15,13,-2,STAINED_GLASS:14)
Block(-15,13,-1,MAGMA)
Block(-15,13,0,MAGMA)
Block(-15,13,1,STAINED_GLASS:10)
Block(-15,13,2,STAINED_GLASS:10)
Block(-15,13,3,STAINED_GLASS:10)
Block(-15,14,-3,STAINED_GLASS:10)
Block(-15,14,-2,STAINED_GLASS:10)
Block(-15,14,-1,STAINED_GLASS:14)
Block(-15,14,0,STAINED_GLASS:10)
Block(-15,14,1,STAINED_GLASS:10)
Block(-15,14,2,STAINED_GLASS:10)
Block(-15,15,-2,STAINED_GLASS:10)
Block(-15,15,-1,STAINED_GLASS:14)
Block(-15,15,0,STAINED_GLASS:10)
Block(-15,15,1,STAINED_GLASS:10)
Block(-15,16,-2,STAINED_GLASS:10)
Block(-15,16,-1,STAINED_GLASS:10)
Block(-15,16,0,STAINED_GLASS:10)
Block(-15,16,1,STAINED_GLASS:14)
Block(-15,17,-2,STAINED_GLASS:10)
Block(-15,17,-1,STAINED_GLASS:10)
Block(-15,17,0,STAINED_GLASS:10)
Block(-15,18,-1,STAINED_GLASS:10)
Block(-15,18,0,STAINED_GLASS:10)
Block(-15,18,1,STAINED_GLASS:14)
Block(-14,1,-2,STAINED_GLASS:10)
Block(-14,2,-2,STAINED_GLASS:10)
Block(-14,2,-1,STAINED_GLASS:10)
Block(-14,2,0,STAINED_GLASS:10)
Block(-14,2,1,STAINED_GLASS:10)
Block(-14,3,-2,STAINED_GLASS:10)
Block(-14,3,-1,STAINED_GLASS:10)
Block(-14,3,0,STAINED_GLASS:10)
Block(-14,3,1,STAINED_GLASS:14)
Block(-14,4,-2,STAINED_GLASS:14)
Block(-14,4,-1,STAINED_GLASS:10)
Block(-14,4,0,STAINED_GLASS:14)
Block(-14,4,1,STAINED_GLASS:10)
Block(-14,5,-2,STAINED_GLASS:14)
Block(-14,5,-1,STAINED_GLASS:10)
Block(-14,5,0,STAINED_GLASS:10)
Block(-14,5,1,STAINED_GLASS:10)
Block(-14,6,-3,STAINED_GLASS:10)
Block(-14,6,-2,STAINED_GLASS:10)
Block(-14,6,-1,STAINED_GLASS:10)
Block(-14,6,0,STAINED_GLASS:14)
Block(-14,6,1,STAINED_GLASS:10)
Block(-14,6,2,STAINED_GLASS:10)
Block(-14,7,-4,STAINED_GLASS:10)
Block(-14,7,-3,STAINED_GLASS:14)
Block(-14,7,-2,STAINED_GLASS:10)
Block(-14,7,-1,MAGMA)
Block(-14,7,0,MAGMA)
Block(-14,7,1,STAINED_GLASS:10)
Block(-14,7,2,STAINED_GLASS:10)
Block(-14,7,3,STAINED_GLASS:14)
Block(-14,8,-4,STAINED_GLASS:14)
Block(-14,8,-3,STAINED_GLASS:10)
Block(-14,8,-2,MAGMA)
Block(-14,8,-1,MAGMA)
Block(-14,8,0,MAGMA)
Block(-14,8,1,MAGMA)
Block(-14,8,2,STAINED_GLASS:10)
Block(-14,8,3,STAINED_GLASS:10)
Block(-14,9,-4,STAINED_GLASS:14)
Block(-14,9,-3,STAINED_GLASS:10)
Block(-14,9,-2,MAGMA)
Block(-14,9,-1,MAGMA)
Block(-14,9,0,MAGMA)
Block(-14,9,1,MAGMA)
Block(-14,9,2,STAINED_GLASS:10)
Block(-14,9,3,STAINED_GLASS:14)
Block(-14,10,-4,STAINED_GLASS:10)
Block(-14,10,-3,STAINED_GLASS:10)
Block(-14,10,-2,MAGMA)
Block(-14,10,-1,MAGMA)
Block(-14,10,0,MAGMA)
Block(-14,10,1,MAGMA)
Block(-14,10,2,STAINED_GLASS:14)
Block(-14,10,3,STAINED_GLASS:10)
Block(-14,11,-4,STAINED_GLASS:10)
Block(-14,11,-3,STAINED_GLASS:10)
Block(-14,11,-2,STAINED_GLASS:14)
Block(-14,11,-1,MAGMA)
Block(-14,11,0,MAGMA)
Block(-14,11,1,STAINED_GLASS:10)
Block(-14,11,2,STAINED_GLASS:10)
Block(-14,11,3,STAINED_GLASS:14)
Block(-14,12,-3,STAINED_GLASS:10)
Block(-14,12,-2,STAINED_GLASS:10)
Block(-14,12,-1,STAINED_GLASS:14)
Block(-14,12,0,STAINED_GLASS:14)
Block(-14,12,1,STAINED_GLASS:10)
Block(-14,12,2,STAINED_GLASS:10)
Block(-14,13,-2,STAINED_GLASS:10)
Block(-14,13,-1,STAINED_GLASS:10)
Block(-14,13,0,STAINED_GLASS:10)
Block(-14,13,1,STAINED_GLASS:10)
Block(-14,14,-2,STAINED_GLASS:10)
Block(-14,14,-1,STAINED_GLASS:10)
Block(-14,14,0,STAINED_GLASS:10)
Block(-14,14,1,STAINED_GLASS:10)
Block(-14,15,-2,STAINED_GLASS:10)
Block(-14,15,-1,STAINED_GLASS:10)
Block(-14,15,0,STAINED_GLASS:10)
Block(-14,15,1,STAINED_GLASS:10)
Block(-14,16,-1,STAINED_GLASS:14)
Block(-14,16,0,STAINED_GLASS:10)
Block(-13,-1,-2,STAINED_GLASS:10)
Block(-13,-1,-1,STAINED_GLASS:10)
Block(-13,-1,0,STAINED_GLASS:10)
Block(-13,-1,1,STAINED_GLASS:14)
Block(-13,0,-2,STAINED_GLASS:10)
Block(-13,0,-1,STAINED_GLASS:10)
Block(-13,0,0,STAINED_GLASS:10)
Block(-13,0,1,STAINED_GLASS:10)
Block(-13,1,-2,STAINED_GLASS:10)
Block(-13,1,-1,STAINED_GLASS:10)
Block(-13,1,0,STAINED_GLASS:10)
Block(-13,1,1,STAINED_GLASS:10)
Block(-13,2,-2,STAINED_GLASS:10)
Block(-13,2,-1,STAINED_GLASS:10)
Block(-13,2,0,STAINED_GLASS:14)
Block(-13,2,1,STAINED_GLASS:14)
Block(-13,3,-2,STAINED_GLASS:14)
Block(-13,3,-1,STAINED_GLASS:10)
Block(-13,3,0,STAINED_GLASS:10)
Block(-13,3,1,STAINED_GLASS:10)
Block(-13,4,-3,STAINED_GLASS:14)
Block(-13,4,-2,STAINED_GLASS:10)
Block(-13,4,-1,STAINED_GLASS:10)
Block(-13,4,0,STAINED_GLASS:10)
Block(-13,4,1,STAINED_GLASS:10)
Block(-13,4,2,STAINED_GLASS:10)
Block(-13,5,-4,STAINED_GLASS:10)
Block(-13,5,-3,STAINED_GLASS:10)
Block(-13,5,-2,STAINED_GLASS:10)
Block(-13,5,-1,MAGMA)
Block(-13,5,0,MAGMA)
Block(-13,5,1,STAINED_GLASS:10)
Block(-13,5,2,STAINED_GLASS:10)
Block(-13,5,3,STAINED_GLASS:10)
Block(-13,6,-4,STAINED_GLASS:14)
Block(-13,6,-3,STAINED_GLASS:14)
Block(-13,6,-2,MAGMA)
Block(-13,6,-1,MAGMA)
Block(-13,6,0,MAGMA)
Block(-13,6,1,MAGMA)
Block(-13,6,2,STAINED_GLASS:10)
Block(-13,6,3,STAINED_GLASS:10)
Block(-13,7,-4,STAINED_GLASS:14)
Block(-13,7,-3,STAINED_GLASS:14)
Block(-13,7,-2,MAGMA)
Block(-13,7,-1,MAGMA)
Block(-13,7,0,MAGMA)
Block(-13,7,1,MAGMA)
Block(-13,7,2,STAINED_GLASS:10)
Block(-13,7,3,STAINED_GLASS:14)
Block(-13,8,-4,STAINED_GLASS:14)
Block(-13,8,-3,STAINED_GLASS:10)
Block(-13,8,-2,MAGMA)
Block(-13,8,-1,MAGMA)
Block(-13,8,0,MAGMA)
Block(-13,8,1,MAGMA)
Block(-13,8,2,STAINED_GLASS:10)
Block(-13,8,3,STAINED_GLASS:10)
Block(-13,9,-4,STAINED_GLASS:14)
Block(-13,9,-3,STAINED_GLASS:10)
Block(-13,9,-2,STAINED_GLASS:10)
Block(-13,9,-1,MAGMA)
Block(-13,9,0,MAGMA)
Block(-13,9,1,STAINED_GLASS:10)
Block(-13,9,2,STAINED_GLASS:14)
Block(-13,9,3,STAINED_GLASS:10)
Block(-13,10,-3,STAINED_GLASS:10)
Block(-13,10,-2,STAINED_GLASS:10)
Block(-13,10,-1,STAINED_GLASS:10)
Block(-13,10,0,STAINED_GLASS:10)
Block(-13,10,1,STAINED_GLASS:10)
Block(-13,10,2,STAINED_GLASS:10)
Block(-13,11,-2,STAINED_GLASS:10)
Block(-13,11,-1,STAINED_GLASS:10)
Block(-13,11,0,STAINED_GLASS:10)
Block(-13,11,1,STAINED_GLASS:10)
Block(-13,12,-2,STAINED_GLASS:14)
Block(-13,12,-1,STAINED_GLASS:10)
Block(-13,12,0,STAINED_GLASS:14)
Block(-13,12,1,STAINED_GLASS:10)
Block(-13,13,-2,STAINED_GLASS:10)
Block(-13,13,-1,STAINED_GLASS:14)
Block(-13,13,0,STAINED_GLASS:14)
Block(-13,13,1,STAINED_GLASS:10)
Block(-13,14,-1,STAINED_GLASS:10)
Block(-13,14,0,STAINED_GLASS:14)
Block(-12,-3,-2,STAINED_GLASS:10)
Block(-12,-3,-1,STAINED_GLASS:10)
Block(-12,-3,0,STAINED_GLASS:10)
Block(-12,-2,-2,STAINED_GLASS:10)
Block(-12,-2,-1,STAINED_GLASS:10)
Block(-12,-2,0,STAINED_GLASS:10)
Block(-12,-1,-2,STAINED_GLASS:10)
Block(-12,-1,-1,STAINED_GLASS:10)
Block(-12,-1,0,STAINED_GLASS:10)
Block(-12,-1,1,STAINED_GLASS:14)
Block(-12,0,-2,STAINED_GLASS:10)
Block(-12,0,-1,STAINED_GLASS:10)
Block(-12,0,0,STAINED_GLASS:14)
Block(-12,0,1,STAINED_GLASS:10)
Block(-12,1,-2,STAINED_GLASS:10)
Block(-12,1,-1,STAINED_GLASS:10)
Block(-12,1,0,STAINED_GLASS:10)
Block(-12,1,1,STAINED_GLASS:14)
Block(-12,2,-3,STAINED_GLASS:10)
Block(-12,2,-2,STAINED_GLASS:10)
Block(-12,2,-1,STAINED_GLASS:14)
Block(-12,2,0,STAINED_GLASS:10)
Block(-12,2,1,STAINED_GLASS:14)
Block(-12,2,2,STAINED_GLASS:10)
Block(-12,3,-4,STAINED_GLASS:10)
Block(-12,3,-3,STAINED_GLASS:10)
Block(-12,3,-2,STAINED_GLASS:10)
Block(-12,3,-1,MAGMA)
Block(-12,3,0,MAGMA)
Block(-12,3,1,STAINED_GLASS:10)
Block(-12,3,2,STAINED_GLASS:14)
Block(-12,3,3,STAINED_GLASS:14)
Block(-12,4,-4,STAINED_GLASS:10)
Block(-12,4,-3,STAINED_GLASS:14)
Block(-12,4,-2,MAGMA)
Block(-12,4,-1,MAGMA)
Block(-12,4,0,MAGMA)
Block(-12,4,1,MAGMA)
Block(-12,4,2,STAINED_GLASS:10)
Block(-12,4,3,STAINED_GLASS:10)
Block(-12,5,-4,STAINED_GLASS:10)
Block(-12,5,-3,STAINED_GLASS:10)
Block(-12,5,-2,MAGMA)
Block(-12,5,-1,MAGMA)
Block(-12,5,0,MAGMA)
Block(-12,5,1,MAGMA)
Block(-12,5,2,STAINED_GLASS:10)
Block(-12,5,3,STAINED_GLASS:14)
Block(-12,6,-4,STAINED_GLASS:10)
Block(-12,6,-3,STAINED_GLASS:10)
Block(-12,6,-2,MAGMA)
Block(-12,6,-1,MAGMA)
Block(-12,6,0,MAGMA)
Block(-12,6,1,MAGMA)
Block(-12,6,2,STAINED_GLASS:10)
Block(-12,6,3,STAINED_GLASS:10)
Block(-12,7,-4,STAINED_GLASS:10)
Block(-12,7,-3,STAINED_GLASS:14)
Block(-12,7,-2,STAINED_GLASS:10)
Block(-12,7,-1,MAGMA)
Block(-12,7,0,MAGMA)
Block(-12,7,1,STAINED_GLASS:14)
Block(-12,7,2,STAINED_GLASS:14)
Block(-12,7,3,STAINED_GLASS:14)
Block(-12,8,-3,STAINED_GLASS:10)
Block(-12,8,-2,STAINED_GLASS:14)
Block(-12,8,-1,STAINED_GLASS:10)
Block(-12,8,0,STAINED_GLASS:14)
Block(-12,8,1,STAINED_GLASS:14)
Block(-12,8,2,STAINED_GLASS:10)
Block(-12,9,-2,STAINED_GLASS:14)
Block(-12,9,-1,STAINED_GLASS:10)
Block(-12,9,0,STAINED_GLASS:10)
Block(-12,9,1,STAINED_GLASS:10)
Block(-12,10,-2,STAINED_GLASS:14)
Block(-12,10,-1,STAINED_GLASS:10)
Block(-12,10,0,STAINED_GLASS:14)
Block(-12,10,1,STAINED_GLASS:14)
Block(-12,11,-2,STAINED_GLASS:14)
Block(-12,11,-1,STAINED_GLASS:10)
Block(-12,11,0,STAINED_GLASS:10)
Block(-12,11,1,STAINED_GLASS:10)
Block(-12,12,-1,STAINED_GLASS:10)
Block(-12,12,0,STAINED_GLASS:14)
Block(-11,-5,-2,STAINED_GLASS:10)
Block(-11,-5,-1,STAINED_GLASS:10)
Block(-11,-5,0,STAINED_GLASS:10)
Block(-11,-4,-2,STAINED_GLASS:10)
Block(-11,-4,-1,STAINED_GLASS:10)
Block(-11,-4,0,STAINED_GLASS:10)
Block(-11,-3,-2,STAINED_GLASS:10)
Block(-11,-3,-1,STAINED_GLASS:10)
Block(-11,-3,0,STAINED_GLASS:10)
Block(-11,-2,-2,STAINED_GLASS:10)
Block(-11,-2,-1,STAINED_GLASS:10)
Block(-11,-2,0,STAINED_GLASS:14)
Block(-11,-1,-2,STAINED_GLASS:10)
Block(-11,-1,-1,STAINED_GLASS:14)
Block(-11,-1,0,STAINED_GLASS:10)
Block(-11,-1,1,STAINED_GLASS:14)
Block(-11,0,-3,STAINED_GLASS:10)
Block(-11,0,-2,STAINED_GLASS:14)
Block(-11,0,-1,STAINED_GLASS:10)
Block(-11,0,0,STAINED_GLASS:14)
Block(-11,0,1,STAINED_GLASS:10)
Block(-11,0,2,STAINED_GLASS:10)
Block(-11,1,-4,STAINED_GLASS:10)
Block(-11,1,-3,STAINED_GLASS:14)
Block(-11,1,-2,STAINED_GLASS:10)
Block(-11,1,-1,MAGMA)
Block(-11,1,0,MAGMA)
Block(-11,1,1,STAINED_GLASS:14)
Block(-11,1,2,STAINED_GLASS:10)
Block(-11,1,3,STAINED_GLASS:10)
Block(-11,2,-4,STAINED_GLASS:14)
Block(-11,2,-3,STAINED_GLASS:14)
Block(-11,2,-2,MAGMA)
Block(-11,2,-1,MAGMA)
Block(-11,2,0,MAGMA)
Block(-11,2,1,MAGMA)
Block(-11,2,2,STAINED_GLASS:14)
Block(-11,2,3,STAINED_GLASS:10)
Block(-11,3,-4,STAINED_GLASS:14)
Block(-11,3,-3,STAINED_GLASS:10)
Block(-11,3,-2,MAGMA)
Block(-11,3,-1,MAGMA)
Block(-11,3,0,MAGMA)
Block(-11,3,1,MAGMA)
Block(-11,3,2,STAINED_GLASS:10)
Block(-11,3,3,STAINED_GLASS:10)
Block(-11,4,-4,STAINED_GLASS:10)
Block(-11,4,-3,STAINED_GLASS:14)
Block(-11,4,-2,MAGMA)
Block(-11,4,-1,MAGMA)
Block(-11,4,0,MAGMA)
Block(-11,4,1,MAGMA)
Block(-11,4,2,STAINED_GLASS:10)
Block(-11,4,3,STAINED_GLASS:10)
Block(-11,5,-4,STAINED_GLASS:14)
Block(-11,5,-3,STAINED_GLASS:10)
Block(-11,5,-2,STAINED_GLASS:10)
Block(-11,5,-1,MAGMA)
Block(-11,5,0,MAGMA)
Block(-11,5,1,STAINED_GLASS:10)
Block(-11,5,2,STAINED_GLASS:10)
Block(-11,5,3,STAINED_GLASS:14)
Block(-11,6,-3,STAINED_GLASS:14)
Block(-11,6,-2,STAINED_GLASS:10)
Block(-11,6,-1,STAINED_GLASS:10)
Block(-11,6,0,STAINED_GLASS:10)
Block(-11,6,1,STAINED_GLASS:10)
Block(-11,6,2,STAINED_GLASS:10)
Block(-11,7,-2,STAINED_GLASS:10)
Block(-11,7,-1,STAINED_GLASS:10)
Block(-11,7,0,STAINED_GLASS:10)
Block(-11,7,1,STAINED_GLASS:10)
Block(-11,8,-2,STAINED_GLASS:14)
Block(-11,8,-1,STAINED_GLASS:14)
Block(-11,8,0,STAINED_GLASS:14)
Block(-11,8,1,STAINED_GLASS:10)
Block(-11,9,-2,STAINED_GLASS:14)
Block(-11,9,-1,STAINED_GLASS:14)
Block(-11,9,0,STAINED_GLASS:10)
Block(-11,9,1,STAINED_GLASS:10)
Block(-11,10,-1,STAINED_GLASS:14)
Block(-11,10,0,STAINED_GLASS:14)
Block(-10,-6,-2,STAINED_GLASS:10)
Block(-10,-6,-1,STAINED_GLASS:10)
Block(-10,-6,0,STAINED_GLASS:14)
Block(-10,-5,-2,STAINED_GLASS:10)
Block(-10,-5,-1,STAINED_GLASS:10)
Block(-10,-5,0,STAINED_GLASS:14)
Block(-10,-4,-2,STAINED_GLASS:10)
Block(-10,-4,-1,STAINED_GLASS:10)
Block(-10,-4,0,STAINED_GLASS:10)
Block(-10,-3,-2,STAINED_GLASS:14)
Block(-10,-3,-1,STAINED_GLASS:14)
Block(-10,-3,0,STAINED_GLASS:10)
Block(-10,-3,1,STAINED_GLASS:10)
Block(-10,-2,-3,STAINED_GLASS:10)
Block(-10,-2,-2,STAINED_GLASS:10)
Block(-10,-2,-1,STAINED_GLASS:10)
Block(-10,-2,0,STAINED_GLASS:14)
Block(-10,-2,1,STAINED_GLASS:10)
Block(-10,-2,2,STAINED_GLASS:14)
Block(-10,-1,-4,STAINED_GLASS:10)
Block(-10,-1,-3,STAINED_GLASS:14)
Block(-10,-1,-2,STAINED_GLASS:10)
Block(-10,-1,-1,MAGMA)
Block(-10,-1,0,MAGMA)
Block(-10,-1,1,STAINED_GLASS:10)
Block(-10,-1,2,STAINED_GLASS:14)
Block(-10,-1,3,STAINED_GLASS:10)
Block(-10,0,-4,STAINED_GLASS:14)
Block(-10,0,-3,STAINED_GLASS:14)
Block(-10,0,-2,MAGMA)
Block(-10,0,-1,MAGMA)
Block(-10,0,0,MAGMA)
Block(-10,0,1,MAGMA)
Block(-10,0,2,STAINED_GLASS:10)
Block(-10,0,3,STAINED_GLASS:14)
Block(-10,1,-4,STAINED_GLASS:14)
Block(-10,1,-3,STAINED_GLASS:14)
Block(-10,1,-2,MAGMA)
Block(-10,1,-1,MAGMA)
Block(-10,1,0,MAGMA)
Block(-10,1,1,MAGMA)
Block(-10,1,2,STAINED_GLASS:10)
Block(-10,1,3,STAINED_GLASS:14)
Block(-10,2,-4,STAINED_GLASS:14)
Block(-10,2,-3,STAINED_GLASS:14)
Block(-10,2,-2,MAGMA)
Block(-10,2,-1,MAGMA)
Block(-10,2,0,MAGMA)
Block(-10,2,1,MAGMA)
Block(-10,2,2,STAINED_GLASS:10)
Block(-10,2,3,STAINED_GLASS:10)
Block(-10,3,-4,STAINED_GLASS:14)
Block(-10,3,-3,STAINED_GLASS:10)
Block(-10,3,-2,STAINED_GLASS:10)
Block(-10,3,-1,MAGMA)
Block(-10,3,0,MAGMA)
Block(-10,3,1,STAINED_GLASS:10)
Block(-10,3,2,STAINED_GLASS:10)
Block(-10,3,3,STAINED_GLASS:10)
Block(-10,4,-3,STAINED_GLASS:10)
Block(-10,4,-2,STAINED_GLASS:10)
Block(-10,4,-1,STAINED_GLASS:10)
Block(-10,4,0,STAINED_GLASS:10)
Block(-10,4,1,STAINED_GLASS:14)
Block(-10,4,2,STAINED_GLASS:10)
Block(-10,5,-2,STAINED_GLASS:10)
Block(-10,5,-1,STAINED_GLASS:10)
Block(-10,5,0,STAINED_GLASS:10)
Block(-10,5,1,STAINED_GLASS:10)
Block(-10,6,-2,STAINED_GLASS:10)
Block(-10,6,-1,STAINED_GLASS:10)
Block(-10,6,0,STAINED_GLASS:10)
Block(-10,6,1,STAINED_GLASS:10)
Block(-10,7,-2,STAINED_GLASS:10)
Block(-10,7,-1,STAINED_GLASS:14)
Block(-10,7,0,STAINED_GLASS:10)
Block(-10,7,1,STAINED_GLASS:10)
Block(-10,8,-1,STAINED_GLASS:14)
Block(-10,8,0,STAINED_GLASS:10)
Block(-9,-7,-2,STAINED_GLASS:10)
Block(-9,-7,-1,STAINED_GLASS:14)
Block(-9,-7,0,STAINED_GLASS:10)
Block(-9,-6,-2,STAINED_GLASS:14)
Block(-9,-6,-1,STAINED_GLASS:10)
Block(-9,-6,0,STAINED_GLASS:10)
Block(-9,-5,-2,STAINED_GLASS:10)
Block(-9,-5,-1,STAINED_GLASS:14)
Block(-9,-5,0,STAINED_GLASS:14)
Block(-9,-5,1,STAINED_GLASS:10)
Block(-9,-4,-3,STAINED_GLASS:10)
Block(-9,-4,-2,STAINED_GLASS:10)
Block(-9,-4,-1,STAINED_GLASS:14)
Block(-9,-4,0,STAINED_GLASS:14)
Block(-9,-4,1,STAINED_GLASS:14)
Block(-9,-4,2,STAINED_GLASS:10)
Block(-9,-3,-4,STAINED_GLASS:10)
Block(-9,-3,-3,STAINED_GLASS:10)
Block(-9,-3,-2,STAINED_GLASS:14)
Block(-9,-3,-1,MAGMA)
Block(-9,-3,0,MAGMA)
Block(-9,-3,1,STAINED_GLASS:10)
Block(-9,-3,2,STAINED_GLASS:14)
Block(-9,-3,3,STAINED_GLASS:14)
Block(-9,-2,-4,STAINED_GLASS:10)
Block(-9,-2,-3,STAINED_GLASS:14)
Block(-9,-2,-2,MAGMA)
Block(-9,-2,-1,MAGMA)
Block(-9,-2,0,MAGMA)
Block(-9,-2,1,MAGMA)
Block(-9,-2,2,STAINED_GLASS:14)
Block(-9,-2,3,STAINED_GLASS:10)
Block(-9,-1,-4,STAINED_GLASS:10)
Block(-9,-1,-3,STAINED_GLASS:10)
Block(-9,-1,-2,MAGMA)
Block(-9,-1,-1,MAGMA)
Block(-9,-1,0,MAGMA)
Block(-9,-1,1,MAGMA)
Block(-9,-1,2,STAINED_GLASS:10)
Block(-9,-1,3,STAINED_GLASS:14)
Block(-9,0,-3,STAINED_GLASS:14)
Block(-9,0,-2,MAGMA)
Block(-9,0,-1,MAGMA)
Block(-9,0,0,MAGMA)
Block(-9,0,1,MAGMA)
Block(-9,0,2,STAINED_GLASS:10)
Block(-9,0,3,STAINED_GLASS:10)
Block(-9,1,-3,STAINED_GLASS:14)
Block(-9,1,-2,STAINED_GLASS:14)
Block(-9,1,-1,MAGMA)
Block(-9,1,0,MAGMA)
Block(-9,1,1,STAINED_GLASS:14)
Block(-9,1,2,STAINED_GLASS:10)
Block(-9,1,3,STAINED_GLASS:10)
Block(-9,2,-3,STAINED_GLASS:10)
Block(-9,2,-2,STAINED_GLASS:10)
Block(-9,2,-1,STAINED_GLASS:10)
Block(-9,2,0,STAINED_GLASS:10)
Block(-9,2,1,STAINED_GLASS:10)
Block(-9,2,2,STAINED_GLASS:14)
Block(-9,3,-2,STAINED_GLASS:10)
Block(-9,3,-1,STAINED_GLASS:14)
Block(-9,3,0,STAINED_GLASS:10)
Block(-9,3,1,STAINED_GLASS:10)
Block(-9,3,2,STAINED_GLASS:10)
Block(-9,4,-2,STAINED_GLASS:10)
Block(-9,4,-1,STAINED_GLASS:10)
Block(-9,4,0,STAINED_GLASS:14)
Block(-9,4,1,STAINED_GLASS:10)
Block(-9,5,-2,STAINED_GLASS:10)
Block(-9,5,-1,STAINED_GLASS:14)
Block(-9,5,0,STAINED_GLASS:10)
Block(-9,5,1,STAINED_GLASS:14)
Block(-9,6,-1,STAINED_GLASS:10)
Block(-9,6,0,STAINED_GLASS:14)
Block(-8,-8,-2,STAINED_GLASS:10)
Block(-8,-8,-1,STAINED_GLASS:10)
Block(-8,-8,0,STAINED_GLASS:10)
Block(-8,-7,-2,STAINED_GLASS:10)
Block(-8,-7,-1,STAINED_GLASS:10)
Block(-8,-7,0,STAINED_GLASS:10)
Block(-8,-7,1,STAINED_GLASS:10)
Block(-8,-6,-3,STAINED_GLASS:14)
Block(-8,-6,-2,STAINED_GLASS:10)
Block(-8,-6,-1,STAINED_GLASS:10)
Block(-8,-6,0,STAINED_GLASS:14)
Block(-8,-6,1,STAINED_GLASS:10)
Block(-8,-6,2,STAINED_GLASS:10)
Block(-8,-5,-4,STAINED_GLASS:10)
Block(-8,-5,-3,STAINED_GLASS:10)
Block(-8,-5,-2,STAINED_GLASS:14)
Block(-8,-5,-1,MAGMA)
Block(-8,-5,0,MAGMA)
Block(-8,-5,1,STAINED_GLASS:14)
Block(-8,-5,2,STAINED_GLASS:10)
Block(-8,-5,3,STAINED_GLASS:10)
Block(-8,-4,-4,STAINED_GLASS:10)
Block(-8,-4,-3,STAINED_GLASS:14)
Block(-8,-4,-2,MAGMA)
Block(-8,-4,-1,MAGMA)
Block(-8,-4,0,MAGMA)
Block(-8,-4,1,MAGMA)
Block(-8,-4,2,STAINED_GLASS:10)
Block(-8,-4,3,STAINED_GLASS:10)
Block(-8,-3,-4,STAINED_GLASS:10)
Block(-8,-3,-3,STAINED_GLASS:10)
Block(-8,-3,-2,MAGMA)
Block(-8,-3,-1,MAGMA)
Block(-8,-3,0,MAGMA)
Block(-8,-3,1,MAGMA)
Block(-8,-3,2,STAINED_GLASS:10)
Block(-8,-3,3,STAINED_GLASS:10)
Block(-8,-2,-4,STAINED_GLASS:10)
Block(-8,-2,-3,STAINED_GLASS:10)
Block(-8,-2,-2,MAGMA)
Block(-8,-2,-1,MAGMA)
Block(-8,-2,0,MAGMA)
Block(-8,-2,1,MAGMA)
Block(-8,-2,2,STAINED_GLASS:10)
Block(-8,-2,3,STAINED_GLASS:10)
Block(-8,-1,-4,STAINED_GLASS:10)
Block(-8,-1,-3,STAINED_GLASS:10)
Block(-8,-1,-2,STAINED_GLASS:14)
Block(-8,-1,-1,MAGMA)
Block(-8,-1,0,MAGMA)
Block(-8,-1,1,STAINED_GLASS:10)
Block(-8,-1,2,STAINED_GLASS:10)
Block(-8,-1,3,STAINED_GLASS:10)
Block(-8,0,-3,STAINED_GLASS:10)
Block(-8,0,-2,STAINED_GLASS:14)
Block(-8,0,-1,STAINED_GLASS:10)
Block(-8,0,0,STAINED_GLASS:14)
Block(-8,0,1,STAINED_GLASS:10)
Block(-8,0,2,STAINED_GLASS:10)
Block(-8,1,-2,STAINED_GLASS:10)
Block(-8,1,-1,STAINED_GLASS:10)
Block(-8,1,0,STAINED_GLASS:10)
Block(-8,1,1,STAINED_GLASS:14)
Block(-8,1,2,STAINED_GLASS:14)
Block(-8,2,-2,STAINED_GLASS:10)
Block(-8,2,-1,STAINED_GLASS:10)
Block(-8,2,0,STAINED_GLASS:10)
Block(-8,2,1,STAINED_GLASS:10)
Block(-8,3,-2,STAINED_GLASS:10)
Block(-8,3,-1,STAINED_GLASS:14)
Block(-8,3,0,STAINED_GLASS:10)
Block(-8,3,1,STAINED_GLASS:10)
Block(-8,4,-1,STAINED_GLASS:10)
Block(-8,4,0,STAINED_GLASS:14)
Block(-7,-9,-1,STAINED_GLASS:10)
Block(-7,-9,0,STAINED_GLASS:10)
Block(-7,-8,-2,STAINED_GLASS:10)
Block(-7,-8,-1,STAINED_GLASS:10)
Block(-7,-8,0,STAINED_GLASS:10)
Block(-7,-8,1,STAINED_GLASS:14)
Block(-7,-7,-4,STAINED_GLASS:10)
Block(-7,-7,-3,STAINED_GLASS:14)
Block(-7,-7,-2,STAINED_GLASS:10)
Block(-7,-7,-1,MAGMA)
Block(-7,-7,0,MAGMA)
Block(-7,-7,1,STAINED_GLASS:10)
Block(-7,-7,2,STAINED_GLASS:10)
Block(-7,-7,3,STAINED_GLASS:10)
Block(-7,-6,-4,STAINED_GLASS:10)
Block(-7,-6,-3,STAINED_GLASS:10)
Block(-7,-6,-2,MAGMA)
Block(-7,-6,-1,MAGMA)
Block(-7,-6,0,MAGMA)
Block(-7,-6,1,MAGMA)
Block(-7,-6,2,STAINED_GLASS:10)
Block(-7,-6,3,STAINED_GLASS:14)
Block(-7,-5,-4,STAINED_GLASS:10)
Block(-7,-5,-3,STAINED_GLASS:10)
Block(-7,-5,-2,MAGMA)
Block(-7,-5,-1,MAGMA)
Block(-7,-5,0,MAGMA)
Block(-7,-5,1,MAGMA)
Block(-7,-5,2,STAINED_GLASS:10)
Block(-7,-5,3,STAINED_GLASS:10)
Block(-7,-4,-4,STAINED_GLASS:10)
Block(-7,-4,-3,STAINED_GLASS:14)
Block(-7,-4,-2,MAGMA)
Block(-7,-4,-1,MAGMA)
Block(-7,-4,0,MAGMA)
Block(-7,-4,1,MAGMA)
Block(-7,-4,2,STAINED_GLASS:14)
Block(-7,-4,3,STAINED_GLASS:14)
Block(-7,-3,-3,STAINED_GLASS:10)
Block(-7,-3,-2,STAINED_GLASS:14)
Block(-7,-3,-1,MAGMA)
Block(-7,-3,0,MAGMA)
Block(-7,-3,1,STAINED_GLASS:14)
Block(-7,-3,2,STAINED_GLASS:10)
Block(-7,-3,3,STAINED_GLASS:14)
Block(-7,-2,-3,STAINED_GLASS:10)
Block(-7,-2,-2,STAINED_GLASS:14)
Block(-7,-2,-1,STAINED_GLASS:10)
Block(-7,-2,0,STAINED_GLASS:10)
Block(-7,-2,1,STAINED_GLASS:14)
Block(-7,-2,2,STAINED_GLASS:10)
Block(-7,-1,-2,STAINED_GLASS:14)
Block(-7,-1,-1,STAINED_GLASS:10)
Block(-7,-1,0,STAINED_GLASS:10)
Block(-7,-1,1,STAINED_GLASS:10)
Block(-7,0,-2,STAINED_GLASS:14)
Block(-7,0,-1,STAINED_GLASS:10)
Block(-7,0,0,STAINED_GLASS:10)
Block(-7,0,1,STAINED_GLASS:10)
Block(-7,1,-2,STAINED_GLASS:14)
Block(-7,1,-1,STAINED_GLASS:10)
Block(-7,1,0,STAINED_GLASS:10)
Block(-7,1,1,STAINED_GLASS:10)
Block(-7,2,-1,STAINED_GLASS:10)
Block(-7,2,0,STAINED_GLASS:10)
Block(-6,-9,-2,STAINED_GLASS:10)
Block(-6,-9,-1,STAINED_GLASS:10)
Block(-6,-9,0,STAINED_GLASS:10)
Block(-6,-9,1,STAINED_GLASS:10)
Block(-6,-8,-2,STAINED_GLASS:14)
Block(-6,-8,-1,STAINED_GLASS:14)
Block(-6,-8,0,STAINED_GLASS:10)
Block(-6,-8,1,STAINED_GLASS:14)
Block(-6,-8,2,STAINED_GLASS:10)
Block(-6,-7,-3,STAINED_GLASS:14)
Block(-6,-7,-2,MAGMA)
Block(-6,-7,-1,MAGMA)
Block(-6,-7,0,MAGMA)
Block(-6,-7,1,MAGMA)
Block(-6,-7,2,STAINED_GLASS:10)
Block(-6,-7,3,STAINED_GLASS:10)
Block(-6,-6,-3,STAINED_GLASS:10)
Block(-6,-6,-2,MAGMA)
Block(-6,-6,-1,MAGMA)
Block(-6,-6,0,MAGMA)
Block(-6,-6,1,MAGMA)
Block(-6,-6,2,STAINED_GLASS:14)
Block(-6,-6,3,STAINED_GLASS:10)
Block(-6,-5,-4,STAINED_GLASS:10)
Block(-6,-5,-3,STAINED_GLASS:10)
Block(-6,-5,-2,STAINED_GLASS:10)
Block(-6,-5,-1,STAINED_GLASS:10)
Block(-6,-5,0,STAINED_GLASS:10)
Block(-6,-5,1,STAINED_GLASS:10)
Block(-6,-5,2,STAINED_GLASS:10)
Block(-6,-5,3,STAINED_GLASS:14)
Block(-6,-4,-4,STAINED_GLASS:10)
Block(-6,-4,-3,STAINED_GLASS:10)
Block(-6,-4,-2,STAINED_GLASS:14)
Block(-6,-4,-1,STAINED_GLASS:14)
Block(-6,-4,0,STAINED_GLASS:14)
Block(-6,-4,1,STAINED_GLASS:10)
Block(-6,-4,2,STAINED_GLASS:10)
Block(-6,-3,-2,STAINED_GLASS:10)
Block(-6,-3,-1,STAINED_GLASS:10)
Block(-6,-3,0,STAINED_GLASS:10)
Block(-6,-3,1,STAINED_GLASS:14)
Block(-6,-2,-2,STAINED_GLASS:10)
Block(-6,-2,-1,STAINED_GLASS:10)
Block(-6,-2,0,STAINED_GLASS:10)
Block(-6,-2,1,STAINED_GLASS:10)
Block(-6,-1,-1,STAINED_GLASS:10)
Block(-6,-1,0,STAINED_GLASS:10)
Block(-6,0,-1,STAINED_GLASS:10)
Block(-6,0,0,STAINED_GLASS:14)
Block(-5,-8,-2,STAINED_GLASS:10)
Block(-5,-8,-1,STAINED_GLASS:14)
Block(-5,-8,0,STAINED_GLASS:14)
Block(-5,-8,1,STAINED_GLASS:14)
Block(-5,-7,-3,STAINED_GLASS:10)
Block(-5,-7,-2,STAINED_GLASS:10)
Block(-5,-7,-1,STAINED_GLASS:10)
Block(-5,-7,0,STAINED_GLASS:10)
Block(-5,-7,1,STAINED_GLASS:10)
Block(-5,-7,2,STAINED_GLASS:10)
Block(-5,-6,-3,STAINED_GLASS:10)
Block(-5,-6,-2,STAINED_GLASS:10)
Block(-5,-6,-1,STAINED_GLASS:14)
Block(-5,-6,0,STAINED_GLASS:14)
Block(-5,-6,1,STAINED_GLASS:10)
Block(-5,-6,2,STAINED_GLASS:10)
Block(-5,-5,-2,STAINED_GLASS:10)
Block(-5,-5,-1,STAINED_GLASS:10)
Block(-5,-5,0,STAINED_GLASS:14)
Block(-5,-5,1,STAINED_GLASS:10)
Block(-5,-4,-2,STAINED_GLASS:14)
Block(-5,-4,-1,STAINED_GLASS:14)
Block(-5,-4,0,STAINED_GLASS:14)
Block(-5,-4,1,STAINED_GLASS:10)
Block(-5,-3,-1,STAINED_GLASS:10)
Block(-5,-3,0,STAINED_GLASS:10)
Block(-5,-2,-1,STAINED_GLASS:10)
Block(-5,-2,0,STAINED_GLASS:10)

#######################################################################
# +-----------------------------------------------------------------+ #
# |                            BO3 checks                           | #
# +-----------------------------------------------------------------+ #
#######################################################################

BlockCheck(-14,-1,-2,concrete,MAGMA,concrete_powder,STAINED_GLASS:1)
BlockCheck(-14,-1,-1,concrete,MAGMA,concrete_powder,STAINED_GLASS:1)
BlockCheck(-14,-1,0,concrete,MAGMA,concrete_powder,STAINED_GLASS:1)
BlockCheck(-14,-1,1,concrete,MAGMA,concrete_powder,STAINED_GLASS:1)
BlockCheck(-13,-1,-3,concrete,MAGMA,concrete_powder,STAINED_GLASS:1)
BlockCheck(-13,-1,2,concrete,MAGMA,concrete_powder,STAINED_GLASS:1)
BlockCheck(-12,-1,-3,concrete,MAGMA,concrete_powder,STAINED_GLASS:1)
BlockCheck(-12,-1,2,concrete,MAGMA,concrete_powder,STAINED_GLASS:1)
BlockCheck(-11,-1,-4,concrete,MAGMA,concrete_powder,STAINED_GLASS:1)
BlockCheck(-11,-1,-3,concrete,MAGMA,concrete_powder,STAINED_GLASS:1)
BlockCheck(-11,-1,2,concrete,MAGMA,concrete_powder,STAINED_GLASS:1)
BlockCheck(-11,-1,3,concrete,MAGMA,concrete_powder,STAINED_GLASS:1)
BlockCheck(-10,-1,-5,concrete,MAGMA,concrete_powder,STAINED_GLASS:1)
BlockCheck(-10,-1,4,concrete,MAGMA,concrete_powder,STAINED_GLASS:1)
BlockCheck(-9,-1,-5,concrete,MAGMA,concrete_powder,STAINED_GLASS:1)
BlockCheck(-9,-1,4,concrete,MAGMA,concrete_powder,STAINED_GLASS:1)
BlockCheck(-8,-1,-5,concrete,MAGMA,concrete_powder,STAINED_GLASS:1)
BlockCheck(-8,-1,4,concrete,MAGMA,concrete_powder,STAINED_GLASS:1)
BlockCheck(-7,-1,-4,concrete,MAGMA,concrete_powder,STAINED_GLASS:1)
BlockCheck(-7,-1,-3,concrete,MAGMA,concrete_powder,STAINED_GLASS:1)
BlockCheck(-7,-1,2,concrete,MAGMA,concrete_powder,STAINED_GLASS:1)
BlockCheck(-7,-1,3,concrete,MAGMA,concrete_powder,STAINED_GLASS:1)
BlockCheck(-6,-1,-2,concrete,MAGMA,concrete_powder,STAINED_GLASS:1)
BlockCheck(-6,-1,1,concrete,MAGMA,concrete_powder,STAINED_GLASS:1)
BlockCheck(-5,-1,-1,concrete,MAGMA,concrete_powder,STAINED_GLASS:1)
BlockCheck(-5,-1,0,concrete,MAGMA,concrete_powder,STAINED_GLASS:1)

#######################################################################
# +-----------------------------------------------------------------+ #
# |                             Branches                            | #
# +-----------------------------------------------------------------+ #
#######################################################################


#######################################################################
# +-----------------------------------------------------------------+ #
# |                             Entities                            | #
# +-----------------------------------------------------------------+ #
#######################################################################


#######################################################################
# +-----------------------------------------------------------------+ #
# |                            Particles                            | #
# +-----------------------------------------------------------------+ #
#######################################################################


#######################################################################
# +-----------------------------------------------------------------+ #
# |                             Spawners                            | #
# +-----------------------------------------------------------------+ #
#######################################################################


#######################################################################
# +-----------------------------------------------------------------+ #
# |                             ModData                             | #
# +-----------------------------------------------------------------+ #
#######################################################################

