#######################################################################
# +-----------------------------------------------------------------+ #
# |                            BO3 object                           | #
# +-----------------------------------------------------------------+ #
#######################################################################

Author: Bo3 BulkEdit

Description: Converted Schematic - Modified by Bo3BulkEdit

Version: 3

SettingsMode: WriteDisable

#######################################################################
# +-----------------------------------------------------------------+ #
# |                          Main settings                          | #
# +-----------------------------------------------------------------+ #
#######################################################################

Frequency: 1
SpawnHeight: HighestSolidBlock

##############################
# Height Limits for the BO3. #
##############################

MinHeight: 60
MaxHeight: 100


#######################################################################
# +-----------------------------------------------------------------+ #
# |                               OTG+                              | #
# +-----------------------------------------------------------------+ #
#######################################################################

InheritBO3: 
InheritBO3Rotation: NORTH
OverrideChildSettings: true
OverrideParentHeight: false
CanOverride: false
BranchFrequency: 0
BranchFrequencyGroup: 
MustBeBelowOther: false
MustBeInside: 
CannotBeInside: 
ReplacesBO3: 
MustBeInsideWorldBorders: false
CanSpawnOnWater: true
SpawnOnWaterOnly: false
SpawnUnderWater: false
SpawnAtWaterLevel: false
HeightOffset: -1
RemoveAir: true
ReplaceAbove: 
ReplaceBelow: COBBLESTONE
ReplaceWithBiomeBlocks: true
ReplaceWithSurfaceBlock: GRASS
ReplaceWithGroundBlock: DIRT
ReplaceWithStoneBlock: STONE
SmoothRadius: 0
SmoothHeightOffset: 0
SmoothStartTop: false
SmoothStartWood: false
SmoothingSurfaceBlock: GRASS
SmoothingGroundBlock:  DIRT
BO3Group: FarmStead:1
IsSpawnPoint: false
DoReplaceBlocks: true

#######################################################################
# +-----------------------------------------------------------------+ #
# |                              Blocks                             | #
# +-----------------------------------------------------------------+ #
#######################################################################

B(-6,0,-6,GRASS)
B(-5,0,-6,STONE:6)
B(-4,0,-6,GRASS)
B(-3,0,-6,GRASS)
B(-2,0,-6,GRASS)
B(-1,0,-6,GRASS)
B(0,0,-6,GRASS)
B(1,0,-6,GRASS)
B(2,0,-6,GRASS)
B(3,0,-6,GRASS)
B(4,0,-6,GRASS)
B(5,0,-6,GRASS)
B(6,0,-6,STONE:6)
B(7,0,-6,GRASS)
B(-6,0,-5,GRASS_PATH)
B(-5,0,-5,DIRT)
B(-4,0,-5,DIRT)
B(-3,0,-5,DIRT)
B(-2,0,-5,DIRT)
B(-1,0,-5,DIRT)
B(0,0,-5,DIRT)
B(1,0,-5,DIRT)
B(2,0,-5,DIRT)
B(3,0,-5,DIRT)
B(4,0,-5,DIRT)
B(5,0,-5,DIRT)
B(6,0,-5,DIRT)
B(7,0,-5,GRASS)
B(-6,0,-4,GRASS)
B(-5,0,-4,DIRT)
B(-4,0,-4,DIRT)
B(-3,0,-4,GRAVEL)
B(-2,0,-4,GRASS_PATH)
B(-1,0,-4,DIRT)
B(0,0,-4,GRASS_PATH)
B(1,0,-4,DIRT)
B(2,0,-4,GRASS)
B(3,0,-4,DIRT)
B(4,0,-4,GRASS)
B(5,0,-4,DIRT)
B(6,0,-4,DIRT)
B(7,0,-4,GRASS)
B(-6,0,-3,GRAVEL)
B(-5,0,-3,DIRT)
B(-4,0,-3,DIRT)
B(-3,0,-3,GRAVEL)
B(-2,0,-3,GRASS)
B(-1,0,-3,DIRT)
B(0,0,-3,GRASS_PATH)
B(1,0,-3,GRASS_PATH)
B(2,0,-3,GRASS_PATH)
B(3,0,-3,GRAVEL)
B(4,0,-3,GRAVEL)
B(5,0,-3,GRASS)
B(6,0,-3,GRASS)
B(7,0,-3,GRASS)
B(-6,0,-2,GRASS)
B(-5,0,-2,DIRT)
B(-4,0,-2,GRASS_PATH)
B(-3,0,-2,GRAVEL)
B(-2,0,-2,GRAVEL)
B(-1,0,-2,GRAVEL)
B(0,0,-2,GRASS)
B(1,0,-2,GRAVEL)
B(2,0,-2,GRASS)
B(3,0,-2,GRASS)
B(4,0,-2,GRAVEL)
B(5,0,-2,GRASS)
B(6,0,-2,GRASS)
B(7,0,-2,GRAVEL)
B(-6,0,-1,GRASS_PATH)
B(-5,0,-1,DIRT)
B(-4,0,-1,GRASS_PATH)
B(-3,0,-1,GRASS_PATH)
B(-2,0,-1,GRASS)
B(-1,0,-1,GRASS)
B(0,0,-1,GRAVEL)
B(1,0,-1,GRAVEL)
B(2,0,-1,GRAVEL)
B(3,0,-1,GRAVEL)
B(4,0,-1,GRASS_PATH)
B(5,0,-1,GRASS)
B(6,0,-1,GRAVEL)
B(7,0,-1,GRASS)
B(-6,0,0,GRASS)
B(-5,0,0,DIRT)
B(-4,0,0,GRAVEL)
B(-3,0,0,GRAVEL)
B(-2,0,0,GRAVEL)
B(-1,0,0,GRASS_PATH)
B(0,0,0,GRASS)
B(1,0,0,GRASS_PATH)
B(2,0,0,GRAVEL)
B(3,0,0,GRASS)
B(4,0,0,GRAVEL)
B(5,0,0,GRASS)
B(6,0,0,GRAVEL)
B(7,0,0,GRASS)
B(-6,0,1,GRASS)
B(-5,0,1,DIRT)
B(-4,0,1,GRASS)
B(-3,0,1,GRASS_PATH)
B(-2,0,1,GRASS_PATH)
B(-1,0,1,GRASS)
B(0,0,1,GRAVEL)
B(1,0,1,DIRT)
B(2,0,1,GRAVEL)
B(3,0,1,GRASS)
B(4,0,1,DIRT)
B(5,0,1,DIRT)
B(6,0,1,DIRT)
B(7,0,1,GRASS)
B(-6,0,2,GRASS_PATH)
B(-5,0,2,DIRT)
B(-4,0,2,STONE:6)
B(-3,0,2,STONE:6)
B(-2,0,2,STONE:6)
B(-1,0,2,DIRT)
B(0,0,2,DIRT)
B(1,0,2,DIRT)
B(2,0,2,DIRT)
B(3,0,2,DIRT)
B(4,0,2,DIRT)
B(5,0,2,DIRT)
B(6,0,2,DIRT)
B(7,0,2,GRASS)
B(-6,0,3,GRASS)
B(-5,0,3,STONE:6)
B(-4,0,3,GRASS)
B(-3,0,3,GRASS)
B(-2,0,3,GRASS)
B(-1,0,3,STONE:6)
B(0,0,3,GRASS)
B(1,0,3,GRASS_PATH)
B(2,0,3,GRASS_PATH)
B(3,0,3,GRASS)
B(4,0,3,GRASS)
B(5,0,3,GRASS)
B(6,0,3,STONE:6)
B(7,0,3,GRASS)
B(-6,0,4,GRAVEL)
B(-5,0,4,GRASS)
B(-4,0,4,GRASS_PATH)
B(-3,0,4,GRASS)
B(-2,0,4,GRAVEL)
B(-1,0,4,GRASS)
B(0,0,4,GRASS_PATH)
B(1,0,4,GRASS)
B(2,0,4,GRAVEL)
B(3,0,4,GRASS)
B(4,0,4,GRASS)
B(5,0,4,GRASS)
B(6,0,4,GRASS)
B(7,0,4,GRASS)
B(-6,0,5,GRAVEL)
B(-5,0,5,GRASS_PATH)
B(-4,0,5,GRASS)
B(-3,0,5,GRAVEL)
B(-2,0,5,GRAVEL)
B(-1,0,5,GRASS_PATH)
B(0,0,5,GRAVEL)
B(1,0,5,GRASS)
B(2,0,5,GRAVEL)
B(3,0,5,GRASS)
B(4,0,5,GRASS_PATH)
B(5,0,5,GRAVEL)
B(6,0,5,GRAVEL)
B(7,0,5,GRASS)
B(-6,0,6,GRASS)
B(-5,0,6,GRAVEL)
B(-4,0,6,GRAVEL)
B(-3,0,6,GRASS)
B(-2,0,6,GRAVEL)
B(-1,0,6,GRASS)
B(0,0,6,GRAVEL)
B(1,0,6,GRASS)
B(2,0,6,GRASS)
B(3,0,6,GRAVEL)
B(4,0,6,GRAVEL)
B(5,0,6,GRASS_PATH)
B(6,0,6,GRASS_PATH)
B(7,0,6,GRASS)
B(-6,0,7,GRASS)
B(-5,0,7,GRASS_PATH)
B(-4,0,7,GRASS_PATH)
B(-3,0,7,GRASS)
B(-2,0,7,GRASS)
B(-1,0,7,GRAVEL)
B(0,0,7,GRASS)
B(1,0,7,GRASS)
B(2,0,7,GRASS)
B(3,0,7,GRASS)
B(4,0,7,GRASS)
B(5,0,7,GRASS)
B(6,0,7,GRASS)
B(7,0,7,GRASS)
B(-5,1,-6,FENCE)
B(6,1,-6,FENCE)
B(-5,1,-5,LOG)
B(6,1,-5,LOG)
B(-4,1,-4,HAY_BLOCK)
B(-3,1,-4,CHEST:3,./NBT/chest.nbt)
B(-1,1,-4,HAY_BLOCK)
B(1,1,-4,HAY_BLOCK)
B(2,1,-4,CHEST:3,./NBT/chest.nbt)
B(3,1,-4,HAY_BLOCK:8)
B(4,1,-4,CHEST:3,./NBT/chest.nbt)
B(5,1,-4,HAY_BLOCK)
B(-5,1,-3,PLANKS:1)
B(-4,1,-3,HAY_BLOCK:4)
B(-1,1,-3,HAY_BLOCK)
B(-5,1,-2,PLANKS:1)
B(-5,1,-1,PLANKS:1)
B(-5,1,0,PLANKS:1)
B(1,1,1,HAY_BLOCK)
B(2,1,1,CAULDRON:3)
B(3,1,1,CAULDRON:3)
B(4,1,1,HAY_BLOCK)
B(5,1,1,HAY_BLOCK:8)
B(-5,1,2,LOG)
B(-1,1,2,LOG)
B(6,1,2,LOG)
B(-5,1,3,FENCE)
B(-1,1,3,FENCE)
B(6,1,3,FENCE)
B(-5,2,-6,FENCE)
B(6,2,-6,FENCE)
B(-5,2,-5,LOG)
B(-4,2,-5,FENCE)
B(-2,2,-5,FENCE)
B(0,2,-5,FENCE)
B(2,2,-5,FENCE)
B(4,2,-5,FENCE)
B(6,2,-5,LOG)
B(-4,2,-4,HAY_BLOCK:4)
B(3,2,-4,HAY_BLOCK:8)
B(-5,2,-3,FENCE)
B(-5,2,-2,FENCE)
B(-5,2,-1,FENCE)
B(-5,2,0,FENCE)
B(5,2,1,HAY_BLOCK:4)
B(-5,2,2,LOG)
B(-1,2,2,LOG)
B(0,2,2,FENCE)
B(2,2,2,FENCE)
B(4,2,2,FENCE)
B(6,2,2,LOG)
B(-5,2,3,FENCE)
B(-1,2,3,FENCE)
B(6,2,3,FENCE)
B(-6,3,-6,WOODEN_SLAB:9)
B(-5,3,-6,DOUBLE_WOODEN_SLAB:1)
B(-4,3,-6,WOODEN_SLAB:9)
B(-3,3,-6,WOODEN_SLAB:9)
B(-2,3,-6,WOODEN_SLAB:9)
B(-1,3,-6,WOODEN_SLAB:9)
B(0,3,-6,WOODEN_SLAB:9)
B(1,3,-6,WOODEN_SLAB:9)
B(2,3,-6,WOODEN_SLAB:9)
B(3,3,-6,WOODEN_SLAB:9)
B(4,3,-6,WOODEN_SLAB:9)
B(5,3,-6,WOODEN_SLAB:9)
B(6,3,-6,DOUBLE_WOODEN_SLAB:1)
B(7,3,-6,WOODEN_SLAB:9)
B(-6,3,-5,WOODEN_SLAB:9)
B(-5,3,-5,LOG)
B(-4,3,-5,FENCE)
B(-2,3,-5,FENCE)
B(0,3,-5,FENCE)
B(2,3,-5,FENCE)
B(4,3,-5,FENCE)
B(6,3,-5,LOG)
B(7,3,-5,WOODEN_SLAB:9)
B(-5,3,-3,FENCE)
B(6,3,-3,FENCE)
B(-5,3,-2,FENCE)
B(6,3,-2,FENCE)
B(-5,3,-1,FENCE)
B(6,3,-1,FENCE)
B(-5,3,0,FENCE)
B(6,3,0,FENCE)
B(-6,3,2,WOODEN_SLAB:9)
B(-5,3,2,LOG)
B(-1,3,2,LOG)
B(0,3,2,FENCE)
B(2,3,2,FENCE)
B(4,3,2,FENCE)
B(6,3,2,LOG)
B(7,3,2,WOODEN_SLAB:9)
B(-6,3,3,WOODEN_SLAB:9)
B(-5,3,3,DOUBLE_WOODEN_SLAB:1)
B(-4,3,3,WOODEN_SLAB:9)
B(-3,3,3,WOODEN_SLAB:9)
B(-2,3,3,WOODEN_SLAB:9)
B(-1,3,3,DOUBLE_WOODEN_SLAB:1)
B(0,3,3,WOODEN_SLAB:9)
B(1,3,3,WOODEN_SLAB:9)
B(2,3,3,WOODEN_SLAB:9)
B(3,3,3,WOODEN_SLAB:9)
B(4,3,3,WOODEN_SLAB:9)
B(5,3,3,WOODEN_SLAB:9)
B(6,3,3,DOUBLE_WOODEN_SLAB:1)
B(7,3,3,WOODEN_SLAB:9)
B(-6,4,-5,WOODEN_SLAB:1)
B(-5,4,-5,WOODEN_SLAB:1)
B(-4,4,-5,WOODEN_SLAB:1)
B(-3,4,-5,WOODEN_SLAB:1)
B(-2,4,-5,WOODEN_SLAB:1)
B(-1,4,-5,WOODEN_SLAB:1)
B(0,4,-5,WOODEN_SLAB:1)
B(1,4,-5,WOODEN_SLAB:1)
B(2,4,-5,WOODEN_SLAB:1)
B(3,4,-5,WOODEN_SLAB:1)
B(4,4,-5,WOODEN_SLAB:1)
B(5,4,-5,WOODEN_SLAB:1)
B(6,4,-5,WOODEN_SLAB:1)
B(7,4,-5,WOODEN_SLAB:1)
B(-6,4,-4,DOUBLE_WOODEN_SLAB:1)
B(-5,4,-4,DOUBLE_WOODEN_SLAB:1)
B(-4,4,-4,WOODEN_SLAB:9)
B(-3,4,-4,WOODEN_SLAB:9)
B(-2,4,-4,WOODEN_SLAB:9)
B(-1,4,-4,WOODEN_SLAB:9)
B(0,4,-4,WOODEN_SLAB:9)
B(1,4,-4,WOODEN_SLAB:9)
B(2,4,-4,WOODEN_SLAB:9)
B(3,4,-4,WOODEN_SLAB:9)
B(4,4,-4,WOODEN_SLAB:9)
B(5,4,-4,WOODEN_SLAB:9)
B(6,4,-4,DOUBLE_WOODEN_SLAB:1)
B(7,4,-4,DOUBLE_WOODEN_SLAB:1)
B(-6,4,-3,WOODEN_SLAB:9)
B(-5,4,-3,DOUBLE_WOODEN_SLAB:1)
B(-4,4,-3,WOODEN_SLAB:9)
B(-3,4,-3,WOODEN_SLAB:9)
B(-2,4,-3,WOODEN_SLAB:9)
B(-1,4,-3,WOODEN_SLAB:9)
B(0,4,-3,WOODEN_SLAB:9)
B(1,4,-3,WOODEN_SLAB:9)
B(2,4,-3,WOODEN_SLAB:9)
B(3,4,-3,WOODEN_SLAB:9)
B(4,4,-3,WOODEN_SLAB:9)
B(5,4,-3,WOODEN_SLAB:9)
B(6,4,-3,DOUBLE_WOODEN_SLAB:1)
B(7,4,-3,WOODEN_SLAB:9)
B(-6,4,-2,WOODEN_SLAB:9)
B(7,4,-2,WOODEN_SLAB:9)
B(-6,4,-1,WOODEN_SLAB:9)
B(7,4,-1,WOODEN_SLAB:9)
B(-6,4,0,WOODEN_SLAB:9)
B(-5,4,0,DOUBLE_WOODEN_SLAB:1)
B(-4,4,0,WOODEN_SLAB:9)
B(-3,4,0,WOODEN_SLAB:9)
B(-2,4,0,WOODEN_SLAB:9)
B(-1,4,0,WOODEN_SLAB:9)
B(0,4,0,WOODEN_SLAB:9)
B(1,4,0,WOODEN_SLAB:9)
B(2,4,0,WOODEN_SLAB:9)
B(3,4,0,WOODEN_SLAB:9)
B(4,4,0,WOODEN_SLAB:9)
B(5,4,0,WOODEN_SLAB:9)
B(6,4,0,DOUBLE_WOODEN_SLAB:1)
B(7,4,0,WOODEN_SLAB:9)
B(-6,4,1,DOUBLE_WOODEN_SLAB:1)
B(-5,4,1,DOUBLE_WOODEN_SLAB:1)
B(-4,4,1,WOODEN_SLAB:9)
B(-3,4,1,WOODEN_SLAB:9)
B(-2,4,1,WOODEN_SLAB:9)
B(-1,4,1,WOODEN_SLAB:9)
B(0,4,1,WOODEN_SLAB:9)
B(1,4,1,WOODEN_SLAB:9)
B(2,4,1,WOODEN_SLAB:9)
B(3,4,1,WOODEN_SLAB:9)
B(4,4,1,WOODEN_SLAB:9)
B(5,4,1,WOODEN_SLAB:9)
B(6,4,1,DOUBLE_WOODEN_SLAB:1)
B(7,4,1,DOUBLE_WOODEN_SLAB:1)
B(-6,4,2,WOODEN_SLAB:1)
B(-5,4,2,WOODEN_SLAB:1)
B(-4,4,2,WOODEN_SLAB:1)
B(-3,4,2,WOODEN_SLAB:1)
B(-2,4,2,WOODEN_SLAB:1)
B(-1,4,2,WOODEN_SLAB:1)
B(0,4,2,WOODEN_SLAB:1)
B(1,4,2,WOODEN_SLAB:1)
B(2,4,2,WOODEN_SLAB:1)
B(3,4,2,WOODEN_SLAB:1)
B(4,4,2,WOODEN_SLAB:1)
B(5,4,2,WOODEN_SLAB:1)
B(6,4,2,WOODEN_SLAB:1)
B(7,4,2,WOODEN_SLAB:1)
B(-6,5,-2,WOODEN_SLAB:1)
B(-5,5,-2,WOODEN_SLAB:1)
B(-4,5,-2,WOODEN_SLAB:1)
B(-3,5,-2,WOODEN_SLAB:1)
B(-2,5,-2,WOODEN_SLAB:1)
B(-1,5,-2,WOODEN_SLAB:1)
B(0,5,-2,WOODEN_SLAB:1)
B(1,5,-2,WOODEN_SLAB:1)
B(2,5,-2,WOODEN_SLAB:1)
B(3,5,-2,WOODEN_SLAB:1)
B(4,5,-2,WOODEN_SLAB:1)
B(5,5,-2,WOODEN_SLAB:1)
B(6,5,-2,WOODEN_SLAB:1)
B(7,5,-2,WOODEN_SLAB:1)
B(-6,5,-1,WOODEN_SLAB:1)
B(-5,5,-1,WOODEN_SLAB:1)
B(-4,5,-1,WOODEN_SLAB:1)
B(-3,5,-1,WOODEN_SLAB:1)
B(-2,5,-1,WOODEN_SLAB:1)
B(-1,5,-1,WOODEN_SLAB:1)
B(0,5,-1,WOODEN_SLAB:1)
B(1,5,-1,WOODEN_SLAB:1)
B(2,5,-1,WOODEN_SLAB:1)
B(3,5,-1,WOODEN_SLAB:1)
B(4,5,-1,WOODEN_SLAB:1)
B(5,5,-1,WOODEN_SLAB:1)
B(6,5,-1,WOODEN_SLAB:1)
B(7,5,-1,WOODEN_SLAB:1)

RB(-4,1,-5,CONCRETE,90,BRICK_BLOCK,100)
RB(-3,1,-5,CONCRETE,90,BRICK_BLOCK,100)
RB(-2,1,-5,CONCRETE,90,BRICK_BLOCK,100)
RB(-1,1,-5,CONCRETE,90,BRICK_BLOCK,100)
RB(0,1,-5,CONCRETE,90,BRICK_BLOCK,100)
RB(1,1,-5,CONCRETE,90,BRICK_BLOCK,100)
RB(2,1,-5,CONCRETE,90,BRICK_BLOCK,100)
RB(3,1,-5,CONCRETE,90,BRICK_BLOCK,100)
RB(4,1,-5,CONCRETE,90,BRICK_BLOCK,100)
RB(5,1,-5,CONCRETE,90,BRICK_BLOCK,100)
RB(-5,1,-4,CONCRETE,90,BRICK_BLOCK,100)
RB(6,1,-4,CONCRETE,90,BRICK_BLOCK,100)
RB(-5,1,1,CONCRETE,90,BRICK_BLOCK,100)
RB(6,1,1,CONCRETE,90,BRICK_BLOCK,100)
RB(0,1,2,CONCRETE,90,BRICK_BLOCK,100)
RB(1,1,2,CONCRETE,90,BRICK_BLOCK,100)
RB(2,1,2,CONCRETE,90,BRICK_BLOCK,100)
RB(3,1,2,CONCRETE,90,BRICK_BLOCK,100)
RB(4,1,2,CONCRETE,90,BRICK_BLOCK,100)
RB(5,1,2,CONCRETE,90,BRICK_BLOCK,100)
RB(-3,2,-5,CONCRETE,90,BRICK_BLOCK,100)
RB(-1,2,-5,CONCRETE,90,BRICK_BLOCK,100)
RB(1,2,-5,CONCRETE,90,BRICK_BLOCK,100)
RB(3,2,-5,CONCRETE,90,BRICK_BLOCK,100)
RB(5,2,-5,CONCRETE,90,BRICK_BLOCK,100)
RB(-5,2,-4,CONCRETE,90,BRICK_BLOCK,100)
RB(6,2,-4,CONCRETE,90,BRICK_BLOCK,100)
RB(-5,2,1,CONCRETE,90,BRICK_BLOCK,100)
RB(6,2,1,CONCRETE,90,BRICK_BLOCK,100)
RB(1,2,2,CONCRETE,90,BRICK_BLOCK,100)
RB(3,2,2,CONCRETE,90,BRICK_BLOCK,100)
RB(5,2,2,CONCRETE,90,BRICK_BLOCK,100)
RB(-3,3,-5,CONCRETE,90,BRICK_BLOCK,100)
RB(-1,3,-5,CONCRETE,90,BRICK_BLOCK,100)
RB(1,3,-5,CONCRETE,90,BRICK_BLOCK,100)
RB(3,3,-5,CONCRETE,90,BRICK_BLOCK,100)
RB(5,3,-5,CONCRETE,90,BRICK_BLOCK,100)
RB(-5,3,-4,CONCRETE,90,BRICK_BLOCK,100)
RB(6,3,-4,CONCRETE,90,BRICK_BLOCK,100)
RB(-5,3,1,CONCRETE,90,BRICK_BLOCK,100)
RB(6,3,1,CONCRETE,90,BRICK_BLOCK,100)
RB(1,3,2,CONCRETE,90,BRICK_BLOCK,100)
RB(3,3,2,CONCRETE,90,BRICK_BLOCK,100)
RB(5,3,2,CONCRETE,90,BRICK_BLOCK,100)
RB(-5,4,-2,CONCRETE,90,BRICK_BLOCK,100)
RB(6,4,-2,CONCRETE,90,BRICK_BLOCK,100)
RB(-5,4,-1,CONCRETE,90,BRICK_BLOCK,100)
RB(6,4,-1,CONCRETE,90,BRICK_BLOCK,100)


#######################################################################
# +-----------------------------------------------------------------+ #
# |                             Entities                            | #
# +-----------------------------------------------------------------+ #
#######################################################################

E(0,1,-2,cow,1)
E(3,1,-2,cow,1)
E(-2,1,-1,cow,1)
E(5,1,-1,cow,1)
E(3,1,0,cow,1)
