
#######################################################################
# +-----------------------------------------------------------------+ #
# |                            BO4 object                           | #
# +-----------------------------------------------------------------+ #
#######################################################################

Author: NLBlackEagle

Description: No description given

SettingsMode: WriteWithoutComments


#######################################################################
# +-----------------------------------------------------------------+ #
# |                          Main settings                          | #
# +-----------------------------------------------------------------+ #
#######################################################################

FixedRotation: 

Frequency: 1

SpawnHeight: highestBlock

UseCenterForHighestBlock: true

##############################
# Height Limits for the BO4. #
##############################

MinHeight: 0

MaxHeight: 255

InheritBO3: 

InheritBO3Rotation: NORTH

OverrideChildSettings: true

OverrideParentHeight: false

CanOverride: false

BranchFrequency: 0

BranchFrequencyGroup: 

MustBeBelowOther: false

MustBeInside: 

CannotBeInside: 

ReplacesBO3: 

MustBeInsideWorldBorders: false

CanSpawnOnWater: true

SpawnOnWaterOnly: false

SpawnUnderWater: false

SpawnAtWaterLevel: false

HeightOffset: 0

RemoveAir: true

ReplaceAbove: 

ReplaceBelow: 

ReplaceWithBiomeBlocks: true

ReplaceWithSurfaceBlock: GRASS

ReplaceWithGroundBlock: DIRT

ReplaceWithStoneBlock: STONE

SmoothRadius: 0

SmoothHeightOffset: 0

SmoothStartTop: false

SmoothStartWood: false

SmoothingSurfaceBlock: 

SmoothingGroundBlock: 

BO3Group: 

IsSpawnPoint: false

DoReplaceBlocks: true


#######################################################################
# +-----------------------------------------------------------------+ #
# |                              Blocks                             | #
# +-----------------------------------------------------------------+ #
#######################################################################

RandomBlock(0,2,1,minecraft:chest,./StructureNBT/StructureLoot/JunkChest_1.nbt,20,minecraft:chest,./StructureNBT/StructureLoot/JunkChest_2.nbt,15,minecraft:chest,./StructureNBT/StructureLoot/JunkChest_3.nbt,15,minecraft:chest,./StructureNBT/StructureLoot/JunkChest_4.nbt,15,minecraft:chest,./StructureNBT/StructureLoot/JunkChest_5.nbt,15,minecraft:chest,./StructureNBT/LoreStoryline/LoreGeneric_5.nbt,2,minecraft:chest,./StructureNBT/LoreStoryline/LoreGeneric_4.nbt,2,minecraft:chest,./StructureNBT/LoreStoryline/LoreGeneric_3.nbt,2,minecraft:chest,./StructureNBT/LoreStoryline/LoreGeneric_2.nbt,2,minecraft:chest,./StructureNBT/LoreStoryline/LoreGeneric_1.nbt,2,minecraft:chest,./StructureNBT/LoreStoryline/LoreSmallRuin_5.nbt,3,minecraft:chest,./StructureNBT/LoreStoryline/LoreSmallRuin_4.nbt,3,minecraft:chest,./StructureNBT/LoreStoryline/LoreSmallRuin_3.nbt,3,minecraft:chest,./StructureNBT/LoreStoryline/LoreSmallRuin_2.nbt,3,minecraft:chest,./StructureNBT/LoreStoryline/LoreSmallRuin_1.nbt,3,minecraft:chest,./StructureNBT/StructureLoot/Common1.nbt,3,minecraft:chest,./StructureNBT/StructureLoot/Common2.nbt,3,minecraft:chest,./StructureNBT/StructureLoot/Common3.nbt,3,minecraft:chest,./StructureNBT/StructureLoot/Common4.nbt,3,minecraft:chest,./StructureNBT/StructureLoot/Common5.nbt,3,minecraft:chest,./StructureNBT/StructureLoot/Common5.nbt,3,minecraft:chest,./StructureNBT/StructureLoot/Common6.nbt,3,minecraft:chest,./StructureNBT/StructureLoot/Common7.nbt,3,minecraft:chest,./StructureNBT/StructureLoot/Common8.nbt,3,minecraft:chest,./StructureNBT/StructureLoot/Common9.nbt,3,minecraft:chest,./StructureNBT/StructureLoot/Common10.nbt,3,minecraft:chest,./StructureNBT/StructureLoot/Common11.nbt,3,minecraft:chest,./StructureNBT/StructureLoot/Common12.nbt,3,minecraft:chest,./StructureNBT/StructureLoot/Common13.nbt,3,minecraft:chest,./StructureNBT/StructureLoot/Common14.nbt,3,minecraft:chest,./StructureNBT/StructureLoot/Common15.nbt,3,minecraft:chest,./StructureNBT/StructureLoot/Rare1.nbt,3,minecraft:chest,./StructureNBT/StructureLoot/Rare2.nbt,3,minecraft:chest,./StructureNBT/StructureLoot/Rare3.nbt,3,minecraft:chest,./StructureNBT/StructureLoot/Rare4.nbt,3,minecraft:chest,./StructureNBT/StructureLoot/Rare5.nbt,3,minecraft:chest,./StructureNBT/StructureLoot/Rare6.nbt,3,minecraft:chest,./StructureNBT/StructureLoot/Rare7.nbt,3,minecraft:chest,./StructureNBT/StructureLoot/Rare8.nbt,3,minecraft:chest,./StructureNBT/StructureLoot/Rare9.nbt,3,minecraft:chest,./StructureNBT/StructureLoot/Rare10.nbt,3,minecraft:chest,./StructureNBT/StructureLoot/Rare11.nbt,3,minecraft:chest,./StructureNBT/StructureLoot/Rare12.nbt,3,minecraft:chest,./StructureNBT/StructureLoot/Rare13.nbt,3,minecraft:chest,./StructureNBT/StructureLoot/Rare14.nbt,3,minecraft:chest,./StructureNBT/StructureLoot/Rare15.nbt,3,minecraft:chest,./StructureNBT/StructureLoot/Epic1.nbt,3,minecraft:chest,./StructureNBT/StructureLoot/Epic2.nbt,3,minecraft:chest,./StructureNBT/StructureLoot/Epic3.nbt,3,minecraft:chest,./StructureNBT/StructureLoot/Epic4.nbt,3,minecraft:chest,./StructureNBT/StructureLoot/Epic5.nbt,3,minecraft:chest,./StructureNBT/StructureLoot/Epic6.nbt,3,minecraft:chest,./StructureNBT/StructureLoot/Epic7.nbt,3,minecraft:chest,./StructureNBT/StructureLoot/Epic8.nbt,3,minecraft:chest,./StructureNBT/StructureLoot/Epic9.nbt,3,minecraft:chest,./StructureNBT/StructureLoot/Epic10.nbt,3,minecraft:chest,./StructureNBT/StructureLoot/Epic11.nbt,3,minecraft:chest,./StructureNBT/StructureLoot/Epic12.nbt,3,minecraft:chest,./StructureNBT/StructureLoot/Epic13.nbt,3,minecraft:chest,./StructureNBT/StructureLoot/Epic14.nbt,3,minecraft:chest,./StructureNBT/StructureLoot/Epic15.nbt,1,minecraft:chest,./StructureNBT/StructureLoot/Common15.nbt,100)
B(-3,0,-4,minecraft:oak_leaves)
B(-3,0,-3,minecraft:oak_leaves)
B(-3,0,0,minecraft:cobblestone_slab)
B(-3,0,3,minecraft:oak_leaves)
B(-3,0,4,minecraft:oak_leaves)
B(-3,0,5,minecraft:cobblestone_slab)
B(-2,0,-5,minecraft:cobblestone_slab)
B(-2,0,-4,minecraft:oak_leaves)
B(-2,0,-3,minecraft:cobblestone_slab)
B(-2,0,-2,minecraft:mossy_stone_bricks)
B(-2,0,-1,minecraft:oak_leaves)
B(-2,0,0,minecraft:mossy_stone_bricks)
B(-2,0,1,minecraft:mossy_stone_bricks)
B(-2,0,2,minecraft:mossy_stone_bricks)
B(-2,0,3,minecraft:cobblestone_slab)
B(-2,0,4,minecraft:mossy_stone_bricks)
B(-2,0,5,minecraft:oak_leaves)
B(-2,1,-3,minecraft:vine[east=true,north=false,south=false,up=false,west=false])
B(-2,1,-2,minecraft:mossy_stone_bricks)
B(-2,1,-1,minecraft:vine[east=true,north=false,south=false,up=false,west=false])
B(-2,1,0,minecraft:cobblestone_stairs[facing=south,half=bottom,shape=straight,waterlogged=false])
B(-2,1,1,minecraft:mossy_stone_bricks)
B(-2,1,2,minecraft:cobblestone_stairs[facing=east,half=bottom,shape=straight,waterlogged=false])
B(-2,1,4,minecraft:mossy_stone_bricks)
B(-2,1,5,minecraft:vine[east=true,north=false,south=false,up=false,west=false])
B(-2,2,-3,minecraft:vine[east=true,north=false,south=false,up=false,west=false])
B(-2,2,-2,minecraft:cobblestone_stairs[facing=east,half=bottom,shape=straight,waterlogged=false])
B(-2,2,4,minecraft:vine[east=true,north=false,south=false,up=false,west=false])
B(-2,2,5,minecraft:vine[east=true,north=false,south=false,up=false,west=false])
B(-2,3,-3,minecraft:vine[east=true,north=false,south=false,up=false,west=false])
B(-2,3,5,minecraft:vine[east=true,north=false,south=false,up=false,west=false])
B(-2,4,-3,minecraft:vine[east=true,north=false,south=false,up=false,west=false])
B(-1,0,-4,minecraft:oak_leaves)
B(-1,0,-3,minecraft:mossy_stone_bricks)
B(-1,0,-2,minecraft:mossy_stone_bricks)
B(-1,0,-1,minecraft:mossy_stone_bricks)
B(-1,0,0,minecraft:mossy_stone_bricks)
B(-1,0,1,minecraft:mossy_stone_bricks)
B(-1,0,2,minecraft:mossy_stone_bricks)
B(-1,0,3,minecraft:mossy_stone_bricks)
B(-1,0,4,minecraft:mossy_stone_bricks)
B(-1,0,5,minecraft:mossy_stone_bricks)
B(-1,0,6,minecraft:cobblestone_slab)
B(-1,1,-4,minecraft:vine[east=false,north=false,south=true,up=false,west=false])
B(-1,1,-3,minecraft:mossy_stone_bricks)
B(-1,1,-2,minecraft:chiseled_stone_bricks)
B(-1,1,-1,minecraft:mossy_stone_bricks)
B(-1,1,0,minecraft:cobblestone_stairs[facing=east,half=bottom,shape=straight,waterlogged=false])
B(-1,1,1,minecraft:mossy_stone_bricks)
B(-1,1,2,minecraft:cobblestone_stairs[facing=south,half=bottom,shape=straight,waterlogged=false])
B(-1,1,3,minecraft:mossy_stone_bricks)
B(-1,1,4,minecraft:chiseled_stone_bricks)
B(-1,1,5,minecraft:mossy_stone_bricks)
B(-1,1,6,minecraft:vine[east=false,north=true,south=false,up=false,west=false])
B(-1,2,-4,minecraft:vine[east=false,north=false,south=true,up=false,west=false])
B(-1,2,-3,minecraft:mossy_stone_bricks)
B(-1,2,-2,minecraft:cracked_stone_bricks)
B(-1,2,-1,minecraft:iron_bars)
B(-1,2,0,minecraft:cobblestone_wall)
B(-1,2,1,minecraft:chiseled_stone_bricks)
B(-1,2,2,minecraft:cobblestone_wall)
B(-1,2,3,minecraft:spruce_slab)
B(-1,2,4,minecraft:mossy_stone_bricks)
B(-1,2,5,minecraft:mossy_stone_bricks)
B(-1,2,6,minecraft:vine[east=false,north=true,south=false,up=false,west=false])
B(-1,3,-4,minecraft:vine[east=false,north=false,south=true,up=false,west=false])
B(-1,3,-3,minecraft:mossy_stone_bricks)
B(-1,3,-2,minecraft:cobblestone_wall)
B(-1,3,1,minecraft:cobblestone_slab)
B(-1,3,4,minecraft:cobblestone_wall)
B(-1,3,5,minecraft:mossy_stone_bricks)
B(-1,3,6,minecraft:vine[east=false,north=true,south=false,up=false,west=false])
B(-1,4,-4,minecraft:cobblestone_wall)
B(-1,4,-3,minecraft:chiseled_stone_bricks)
B(-1,4,-2,minecraft:vine[east=false,north=true,south=false,up=false,west=false])
B(-1,4,4,minecraft:cobblestone_wall)
B(-1,4,5,minecraft:chiseled_stone_bricks)
B(-1,4,6,minecraft:cobblestone_wall)
B(-1,5,5,minecraft:cobblestone_wall)
B(0,0,-4,minecraft:cobblestone_slab)
B(0,0,-3,minecraft:mossy_stone_bricks)
B(0,0,-2,minecraft:mossy_stone_bricks)
B(0,0,-1,minecraft:oak_leaves)
B(0,0,0,minecraft:mossy_stone_bricks)
B(0,0,1,minecraft:cracked_stone_bricks)
B(0,0,2,minecraft:mossy_stone_bricks)
B(0,0,3,minecraft:fern)
B(0,0,4,minecraft:mossy_stone_bricks)
B(0,0,5,minecraft:mossy_stone_bricks)
B(0,0,6,minecraft:cobblestone_slab)
B(0,1,-3,minecraft:chiseled_stone_bricks)
B(0,1,-2,minecraft:spruce_slab)
B(0,1,-1,minecraft:oak_leaves)
B(0,1,0,minecraft:cobblestone_stairs[facing=south,half=bottom,shape=straight,waterlogged=false])
B(0,1,1,minecraft:chiseled_stone_bricks)
B(0,1,2,minecraft:cobblestone_slab)
B(0,1,4,minecraft:vine[east=false,north=false,south=false,up=false,west=true])
B(0,1,5,minecraft:chiseled_stone_bricks)
B(0,2,-3,minecraft:mossy_stone_bricks)
B(0,2,4,minecraft:vine[east=false,north=false,south=false,up=false,west=true])
B(0,2,5,minecraft:mossy_stone_bricks)
B(0,3,-3,minecraft:cobblestone_wall)
B(0,3,5,minecraft:cobblestone_wall)
B(0,4,-3,minecraft:vine[east=false,north=false,south=false,up=false,west=true])
B(1,0,-4,minecraft:vine[east=false,north=false,south=true,up=false,west=false])
B(1,0,-3,minecraft:mossy_stone_bricks)
B(1,0,-2,minecraft:grass)
B(1,0,-1,minecraft:mossy_stone_bricks)
B(1,0,0,minecraft:cracked_stone_bricks)
B(1,0,1,minecraft:mossy_stone_bricks)
B(1,0,2,minecraft:mossy_stone_bricks)
B(1,0,3,minecraft:mossy_stone_bricks)
B(1,0,4,minecraft:cracked_stone_bricks)
B(1,0,5,minecraft:mossy_stone_bricks)
B(1,0,6,minecraft:vine[east=false,north=true,south=false,up=false,west=false])
B(1,1,-4,minecraft:vine[east=false,north=false,south=true,up=false,west=false])
B(1,1,-3,minecraft:mossy_stone_bricks)
B(1,1,-2,minecraft:vine[east=false,north=true,south=false,up=false,west=false])
B(1,1,0,minecraft:cobblestone_stairs[facing=west,half=bottom,shape=straight,waterlogged=false])
B(1,1,1,minecraft:cobblestone_stairs[facing=west,half=bottom,shape=straight,waterlogged=false])
B(1,1,2,minecraft:cobblestone_stairs[facing=east,half=bottom,shape=straight,waterlogged=false])
B(1,1,4,minecraft:vine[east=false,north=false,south=true,up=false,west=false])
B(1,1,5,minecraft:cracked_stone_bricks)
B(1,1,6,minecraft:vine[east=false,north=true,south=false,up=false,west=false])
B(1,2,-3,minecraft:vine[east=false,north=false,south=false,up=false,west=true])
B(1,2,5,minecraft:iron_bars)
B(2,0,-4,minecraft:cobblestone_slab)
B(2,0,-3,minecraft:mossy_stone_bricks)
B(2,0,-2,minecraft:mossy_stone_bricks)
B(2,0,-1,minecraft:cracked_stone_bricks)
B(2,0,0,minecraft:cobblestone_stairs[facing=east,half=bottom,shape=straight,waterlogged=false])
B(2,0,1,minecraft:oak_leaves)
B(2,0,2,minecraft:cobblestone_slab)
B(2,0,3,minecraft:cracked_stone_bricks)
B(2,0,4,minecraft:cobblestone_stairs[facing=south,half=bottom,shape=straight,waterlogged=false])
B(2,0,5,minecraft:mossy_stone_bricks)
B(2,0,6,minecraft:cobblestone_slab)
B(2,1,-3,minecraft:cobblestone_stairs[facing=west,half=bottom,shape=straight,waterlogged=false])
B(2,1,5,minecraft:cobblestone_stairs[facing=west,half=bottom,shape=straight,waterlogged=false])
B(3,0,-4,minecraft:cobblestone_slab)
B(3,0,-3,minecraft:mossy_stone_bricks)
B(3,0,-2,minecraft:cobblestone_stairs[facing=west,half=bottom,shape=straight,waterlogged=false])
B(3,0,-1,minecraft:cobblestone_stairs[facing=west,half=bottom,shape=straight,waterlogged=false])
B(3,0,0,minecraft:oak_leaves)
B(3,0,2,minecraft:stone_brick_slab)
B(3,0,3,minecraft:cobblestone_slab)
B(3,0,4,minecraft:cobblestone_slab)
B(3,0,5,minecraft:mossy_stone_bricks)
B(3,1,-3,minecraft:cobblestone_wall)
B(3,1,5,minecraft:cobblestone_wall)

#######################################################################
# +-----------------------------------------------------------------+ #
# |                             Branches                            | #
# +-----------------------------------------------------------------+ #
#######################################################################


#######################################################################
# +-----------------------------------------------------------------+ #
# |                             Entities                            | #
# +-----------------------------------------------------------------+ #
#######################################################################

