#######################################################################
# +-----------------------------------------------------------------+ #
# |                            BO3 object                           | #
# +-----------------------------------------------------------------+ #
#######################################################################

Author: Bo3 BulkEdit

Description: Converted Schematic - Modified by Bo3BulkEdit

Version: 3

SettingsMode: WriteDisable

#######################################################################
# +-----------------------------------------------------------------+ #
# |                          Main settings                          | #
# +-----------------------------------------------------------------+ #
#######################################################################



Frequency: 0


SpawnHeight: randomY





##############################
# Height Limits for the BO3. #
##############################

MinHeight: 0
MaxHeight: 256

#######################################################################
# +-----------------------------------------------------------------+ #
# |                      Source block settings                      | #
# +-----------------------------------------------------------------+ #
#######################################################################

CanOverride: true
MaxPercentageOutsideSourceBlock: 100
OutsideSourceBlock: placeAnyway

#######################################################################
# +-----------------------------------------------------------------+ #
# |                               OTG+                              | #
# +-----------------------------------------------------------------+ #
#######################################################################

#######################################################################
# +-----------------------------------------------------------------+ #
# |                              Blocks                             | #
# +-----------------------------------------------------------------+ #
#######################################################################

B(0,750,0,AIR)
B(15,750,15,AIR)
B(8,10,15,STAINED_GLASS:15)
B(2,11,15,STAINED_GLASS:15)
B(3,11,15,STAINED_GLASS:9)
B(4,11,15,STAINED_GLASS:9)
B(5,11,15,STAINED_GLASS:9)
B(6,11,15,STAINED_GLASS:9)
B(7,11,15,STAINED_GLASS:15)
B(8,11,15,STAINED_GLASS:6)
B(2,12,14,STAINED_GLASS:15)
B(4,12,14,STAINED_GLASS:9)
B(5,12,14,STAINED_GLASS:9)
B(6,12,14,STAINED_GLASS:9)
B(7,12,14,STAINED_GLASS:9)
B(8,12,14,STAINED_GLASS:15)
B(2,12,15,STAINED_GLASS:15)
B(3,12,15,STAINED_GLASS:6)
B(4,12,15,STAINED_GLASS:11)
B(5,12,15,STAINED_GLASS:11)
B(6,12,15,STAINED_GLASS:11)
B(7,12,15,STAINED_GLASS:11)
B(8,12,15,STAINED_GLASS:15)
B(6,13,13,STAINED_GLASS:9)
B(7,13,13,STAINED_GLASS:9)
B(9,13,13,STAINED_GLASS:15)
B(2,13,14,STAINED_GLASS:11)
B(3,13,14,STAINED_GLASS:15)
B(4,13,14,STAINED_GLASS:11)
B(5,13,14,STAINED_GLASS:11)
B(6,13,14,STAINED_GLASS:11)
B(7,13,14,STAINED_GLASS:11)
B(8,13,14,STAINED_GLASS:11)
B(2,13,15,STAINED_GLASS:15)
B(3,13,15,STAINED_GLASS:15)
B(4,13,15,STAINED_GLASS:9)
B(5,13,15,STAINED_GLASS:9)
B(6,13,15,STAINED_GLASS:9)
B(7,13,15,STAINED_GLASS:15)
B(8,13,15,STAINED_GLASS:6)
B(2,14,13,STAINED_GLASS:15)
B(3,14,13,STAINED_GLASS:15)
B(4,14,13,STAINED_GLASS:15)
B(5,14,13,STAINED_GLASS:9)
B(6,14,13,STAINED_GLASS:11)
B(7,14,13,STAINED_GLASS:11)
B(8,14,13,STAINED_GLASS:9)
B(9,14,13,STAINED_GLASS:15)
B(2,14,14,STAINED_GLASS:15)
B(3,14,14,STAINED_GLASS:11)
B(4,14,14,STAINED_GLASS:15)
B(5,14,14,STAINED_GLASS:9)
B(6,14,14,STAINED_GLASS:9)
B(7,14,14,STAINED_GLASS:9)
B(8,14,14,STAINED_GLASS:15)
B(2,14,15,STAINED_GLASS:9)
B(3,14,15,STAINED_GLASS:11)
B(4,14,15,STAINED_GLASS:11)
B(5,14,15,STAINED_GLASS:11)
B(6,14,15,STAINED_GLASS:11)
B(7,14,15,STAINED_GLASS:11)
B(8,14,15,STAINED_GLASS:6)
B(9,14,15,STAINED_GLASS:15)
B(3,15,12,STAINED_GLASS:15)
B(4,15,12,STAINED_GLASS:15)
B(5,15,12,STAINED_GLASS:9)
B(6,15,12,STAINED_GLASS:9)
B(7,15,12,STAINED_GLASS:9)
B(8,15,12,STAINED_GLASS:9)
B(2,15,13,STAINED_GLASS:11)
B(3,15,13,STAINED_GLASS:11)
B(4,15,13,STAINED_GLASS:11)
B(5,15,13,STAINED_GLASS:11)
B(6,15,13,STAINED_GLASS:9)
B(7,15,13,STAINED_GLASS:9)
B(8,15,13,STAINED_GLASS:6)
B(9,15,13,STAINED_GLASS:15)
B(2,15,14,STAINED_GLASS:11)
B(3,15,14,STAINED_GLASS:9)
B(4,15,14,STAINED_GLASS:11)
B(5,15,14,STAINED_GLASS:11)
B(6,15,14,STAINED_GLASS:11)
B(7,15,14,STAINED_GLASS:11)
B(8,15,14,STAINED_GLASS:6)
B(2,15,15,STAINED_GLASS:15)
B(3,15,15,STAINED_GLASS:10)
B(4,15,15,STAINED_GLASS:10)
B(5,15,15,STAINED_GLASS:10)
B(6,15,15,STAINED_GLASS:10)
B(7,15,15,STAINED_GLASS:10)
B(8,15,15,STAINED_GLASS:11)
B(9,15,15,STAINED_GLASS:15)
B(2,16,11,STAINED_GLASS:15)
B(5,16,11,STAINED_GLASS:9)
B(6,16,11,STAINED_GLASS:9)
B(8,16,11,STAINED_GLASS:9)
B(2,16,12,STAINED_GLASS:15)
B(3,16,12,STAINED_GLASS:11)
B(4,16,12,STAINED_GLASS:11)
B(5,16,12,STAINED_GLASS:6)
B(6,16,12,STAINED_GLASS:6)
B(7,16,12,STAINED_GLASS:6)
B(8,16,12,STAINED_GLASS:15)
B(2,16,13,STAINED_GLASS:15)
B(3,16,13,STAINED_GLASS:9)
B(4,16,13,STAINED_GLASS:9)
B(5,16,13,STAINED_GLASS:9)
B(6,16,13,STAINED_GLASS:6)
B(7,16,13,STAINED_GLASS:6)
B(8,16,13,STAINED_GLASS:9)
B(9,16,13,STAINED_GLASS:15)
B(1,16,14,STAINED_GLASS:15)
B(2,16,14,STAINED_GLASS:11)
B(3,16,14,STAINED_GLASS:11)
B(4,16,14,STAINED_GLASS:10)
B(5,16,14,STAINED_GLASS:10)
B(6,16,14,STAINED_GLASS:10)
B(7,16,14,STAINED_GLASS:10)
B(8,16,14,STAINED_GLASS:11)
B(9,16,14,STAINED_GLASS:15)
B(1,16,15,STAINED_GLASS:15)
B(2,16,15,STAINED_GLASS:15)
B(3,16,15,STAINED_GLASS:10)
B(4,16,15,STAINED_GLASS:10)
B(5,16,15,STAINED_GLASS:10)
B(6,16,15,STAINED_GLASS:10)
B(7,16,15,STAINED_GLASS:10)
B(8,16,15,STAINED_GLASS:11)
B(9,16,15,STAINED_GLASS:15)
B(7,17,10,STAINED_GLASS:9)
B(8,17,10,STAINED_GLASS:15)
B(1,17,11,STAINED_GLASS:15)
B(2,17,11,STAINED_GLASS:15)
B(3,17,11,STAINED_GLASS:15)
B(4,17,11,STAINED_GLASS:9)
B(5,17,11,STAINED_GLASS:9)
B(6,17,11,STAINED_GLASS:9)
B(7,17,11,STAINED_GLASS:9)
B(8,17,11,STAINED_GLASS:9)
B(2,17,12,STAINED_GLASS:15)
B(3,17,12,STAINED_GLASS:15)
B(4,17,12,STAINED_GLASS:15)
B(5,17,12,STAINED_GLASS:9)
B(6,17,12,STAINED_GLASS:9)
B(7,17,12,STAINED_GLASS:9)
B(8,17,12,STAINED_GLASS:15)
B(2,17,13,STAINED_GLASS:9)
B(3,17,13,STAINED_GLASS:9)
B(4,17,13,STAINED_GLASS:9)
B(5,17,13,STAINED_GLASS:9)
B(6,17,13,STAINED_GLASS:6)
B(7,17,13,STAINED_GLASS:6)
B(8,17,13,STAINED_GLASS:9)
B(9,17,13,STAINED_GLASS:15)
B(1,17,14,STAINED_GLASS:9)
B(2,17,14,STAINED_GLASS:9)
B(3,17,14,STAINED_GLASS:11)
B(4,17,14,STAINED_GLASS:6)
B(5,17,14,STAINED_GLASS:6)
B(6,17,14,STAINED_GLASS:6)
B(7,17,14,STAINED_GLASS:6)
B(8,17,14,STAINED_GLASS:9)
B(9,17,14,STAINED_GLASS:15)
B(1,17,15,STAINED_GLASS:9)
B(2,17,15,STAINED_GLASS:15)
B(3,17,15,STAINED_GLASS:6)
B(4,17,15,SEA_LANTERN)
B(5,17,15,SEA_LANTERN)
B(6,17,15,SEA_LANTERN)
B(7,17,15,STAINED_GLASS:11)
B(8,17,15,STAINED_GLASS:9)
B(9,17,15,STAINED_GLASS:15)
B(2,18,10,STAINED_GLASS:15)
B(3,18,10,STAINED_GLASS:15)
B(4,18,10,STAINED_GLASS:15)
B(5,18,10,STAINED_GLASS:9)
B(6,18,10,STAINED_GLASS:9)
B(7,18,10,STAINED_GLASS:9)
B(8,18,10,STAINED_GLASS:15)
B(1,18,11,STAINED_GLASS:15)
B(2,18,11,STAINED_GLASS:15)
B(3,18,11,STAINED_GLASS:9)
B(4,18,11,STAINED_GLASS:9)
B(5,18,11,STAINED_GLASS:9)
B(6,18,11,STAINED_GLASS:9)
B(7,18,11,STAINED_GLASS:9)
B(8,18,11,STAINED_GLASS:9)
B(2,18,12,STAINED_GLASS:15)
B(3,18,12,STAINED_GLASS:9)
B(4,18,12,STAINED_GLASS:9)
B(5,18,12,STAINED_GLASS:9)
B(6,18,12,STAINED_GLASS:9)
B(7,18,12,STAINED_GLASS:9)
B(8,18,12,STAINED_GLASS:15)
B(9,18,12,STAINED_GLASS:15)
B(1,18,13,STAINED_GLASS:9)
B(2,18,13,STAINED_GLASS:9)
B(3,18,13,STAINED_GLASS:6)
B(4,18,13,STAINED_GLASS:6)
B(5,18,13,STAINED_GLASS:6)
B(6,18,13,STAINED_GLASS:6)
B(7,18,13,STAINED_GLASS:6)
B(8,18,13,STAINED_GLASS:9)
B(9,18,13,STAINED_GLASS:15)
B(1,18,14,STAINED_GLASS:15)
B(2,18,14,STAINED_GLASS:9)
B(3,18,14,STAINED_GLASS:6)
B(4,18,14,STAINED_GLASS:6)
B(5,18,14,SEA_LANTERN)
B(6,18,14,STAINED_GLASS:6)
B(7,18,14,STAINED_GLASS:6)
B(8,18,14,STAINED_GLASS:15)
B(9,18,14,STAINED_GLASS:15)
B(1,18,15,STAINED_GLASS:15)
B(2,18,15,STAINED_GLASS:15)
B(3,18,15,STAINED_GLASS:6)
B(4,18,15,SEA_LANTERN)
B(5,18,15,SEA_LANTERN)
B(6,18,15,SEA_LANTERN)
B(7,18,15,STAINED_GLASS:11)
B(8,18,15,STAINED_GLASS:9)
B(9,18,15,STAINED_GLASS:15)
B(1,19,9,STAINED_GLASS:15)
B(4,19,9,STAINED_GLASS:15)
B(5,19,9,STAINED_GLASS:9)
B(7,19,9,STAINED_GLASS:9)
B(8,19,9,STAINED_GLASS:9)
B(1,19,10,STAINED_GLASS:15)
B(2,19,10,STAINED_GLASS:15)
B(3,19,10,STAINED_GLASS:9)
B(4,19,10,STAINED_GLASS:9)
B(5,19,10,STAINED_GLASS:9)
B(6,19,10,STAINED_GLASS:9)
B(7,19,10,STAINED_GLASS:9)
B(8,19,10,STAINED_GLASS:9)
B(1,19,11,STAINED_GLASS:15)
B(2,19,11,STAINED_GLASS:9)
B(3,19,11,STAINED_GLASS:15)
B(4,19,11,STAINED_GLASS:15)
B(5,19,11,STAINED_GLASS:9)
B(6,19,11,STAINED_GLASS:9)
B(7,19,11,STAINED_GLASS:9)
B(8,19,11,STAINED_GLASS:9)
B(2,19,12,STAINED_GLASS:9)
B(3,19,12,STAINED_GLASS:6)
B(4,19,12,STAINED_GLASS:6)
B(5,19,12,STAINED_GLASS:6)
B(6,19,12,STAINED_GLASS:6)
B(7,19,12,STAINED_GLASS:6)
B(8,19,12,STAINED_GLASS:15)
B(9,19,12,STAINED_GLASS:15)
B(1,19,13,STAINED_GLASS:15)
B(2,19,13,STAINED_GLASS:9)
B(3,19,13,STAINED_GLASS:6)
B(4,19,13,STAINED_GLASS:6)
B(5,19,13,STAINED_GLASS:6)
B(6,19,13,SEA_LANTERN)
B(7,19,13,STAINED_GLASS:6)
B(8,19,13,STAINED_GLASS:9)
B(9,19,13,STAINED_GLASS:15)
B(1,19,14,STAINED_GLASS:15)
B(2,19,14,STAINED_GLASS:15)
B(3,19,14,STAINED_GLASS:6)
B(4,19,14,STAINED_GLASS:6)
B(5,19,14,SEA_LANTERN)
B(6,19,14,STAINED_GLASS:6)
B(7,19,14,STAINED_GLASS:6)
B(8,19,14,STAINED_GLASS:9)
B(9,19,14,STAINED_GLASS:15)
B(1,19,15,STAINED_GLASS:15)
B(2,19,15,STAINED_GLASS:15)
B(3,19,15,STAINED_GLASS:6)
B(4,19,15,SEA_LANTERN)
B(5,19,15,SEA_LANTERN)
B(6,19,15,SEA_LANTERN)
B(7,19,15,STAINED_GLASS:6)
B(8,19,15,STAINED_GLASS:9)
B(9,19,15,STAINED_GLASS:15)
B(6,20,8,STAINED_GLASS:9)
B(7,20,8,STAINED_GLASS:9)
B(1,20,9,STAINED_GLASS:15)
B(2,20,9,STAINED_GLASS:15)
B(3,20,9,STAINED_GLASS:15)
B(4,20,9,STAINED_GLASS:9)
B(5,20,9,STAINED_GLASS:9)
B(6,20,9,STAINED_GLASS:9)
B(7,20,9,STAINED_GLASS:9)
B(8,20,9,STAINED_GLASS:9)
B(1,20,10,STAINED_GLASS:15)
B(2,20,10,STAINED_GLASS:15)
B(3,20,10,STAINED_GLASS:15)
B(4,20,10,STAINED_GLASS:15)
B(5,20,10,STAINED_GLASS:15)
B(6,20,10,STAINED_GLASS:9)
B(7,20,10,STAINED_GLASS:9)
B(8,20,10,STAINED_GLASS:15)
B(1,20,11,STAINED_GLASS:15)
B(2,20,11,STAINED_GLASS:9)
B(3,20,11,STAINED_GLASS:9)
B(4,20,11,STAINED_GLASS:9)
B(5,20,11,STAINED_GLASS:6)
B(6,20,11,STAINED_GLASS:6)
B(7,20,11,STAINED_GLASS:9)
B(8,20,11,STAINED_GLASS:9)
B(9,20,11,STAINED_GLASS:15)
B(1,20,12,STAINED_GLASS:15)
B(2,20,12,STAINED_GLASS:9)
B(3,20,12,STAINED_GLASS:6)
B(4,20,12,STAINED_GLASS:6)
B(5,20,12,STAINED_GLASS:6)
B(6,20,12,STAINED_GLASS:6)
B(7,20,12,STAINED_GLASS:6)
B(8,20,12,STAINED_GLASS:15)
B(9,20,12,STAINED_GLASS:15)
B(1,20,13,STAINED_GLASS:15)
B(2,20,13,STAINED_GLASS:9)
B(3,20,13,STAINED_GLASS:6)
B(4,20,13,STAINED_GLASS:6)
B(5,20,13,SEA_LANTERN)
B(6,20,13,SEA_LANTERN)
B(7,20,13,STAINED_GLASS:6)
B(8,20,13,STAINED_GLASS:15)
B(9,20,13,STAINED_GLASS:15)
B(1,20,14,STAINED_GLASS:15)
B(2,20,14,STAINED_GLASS:9)
B(3,20,14,STAINED_GLASS:6)
B(4,20,14,STAINED_GLASS:6)
B(5,20,14,SEA_LANTERN)
B(6,20,14,STAINED_GLASS:6)
B(7,20,14,STAINED_GLASS:6)
B(8,20,14,STAINED_GLASS:9)
B(9,20,14,STAINED_GLASS:15)
B(1,20,15,STAINED_GLASS:15)
B(2,20,15,STAINED_GLASS:15)
B(3,20,15,STAINED_GLASS:6)
B(4,20,15,STAINED_GLASS:6)
B(5,20,15,STAINED_GLASS:6)
B(6,20,15,STAINED_GLASS:6)
B(7,20,15,STAINED_GLASS:6)
B(8,20,15,STAINED_GLASS:15)
B(9,20,15,STAINED_GLASS:15)
B(8,21,7,STAINED_GLASS:9)
B(1,21,8,STAINED_GLASS:15)
B(2,21,8,STAINED_GLASS:15)
B(3,21,8,STAINED_GLASS:15)
B(4,21,8,STAINED_GLASS:15)
B(5,21,8,STAINED_GLASS:9)
B(6,21,8,STAINED_GLASS:9)
B(7,21,8,STAINED_GLASS:9)
B(8,21,8,STAINED_GLASS:9)
B(1,21,9,STAINED_GLASS:15)
B(2,21,9,STAINED_GLASS:9)
B(3,21,9,STAINED_GLASS:9)
B(4,21,9,STAINED_GLASS:15)
B(5,21,9,STAINED_GLASS:9)
B(6,21,9,STAINED_GLASS:9)
B(7,21,9,STAINED_GLASS:9)
B(8,21,9,STAINED_GLASS:9)
B(1,21,10,STAINED_GLASS:15)
B(2,21,10,STAINED_GLASS:9)
B(3,21,10,STAINED_GLASS:9)
B(4,21,10,STAINED_GLASS:9)
B(5,21,10,STAINED_GLASS:9)
B(6,21,10,STAINED_GLASS:9)
B(7,21,10,STAINED_GLASS:6)
B(8,21,10,STAINED_GLASS:9)
B(1,21,11,STAINED_GLASS:15)
B(2,21,11,STAINED_GLASS:9)
B(3,21,11,STAINED_GLASS:6)
B(4,21,11,STAINED_GLASS:6)
B(5,21,11,STAINED_GLASS:6)
B(6,21,11,STAINED_GLASS:6)
B(7,21,11,STAINED_GLASS:6)
B(8,21,11,STAINED_GLASS:9)
B(9,21,11,STAINED_GLASS:9)
B(1,21,12,STAINED_GLASS:15)
B(2,21,12,STAINED_GLASS:9)
B(3,21,12,STAINED_GLASS:6)
B(4,21,12,SEA_LANTERN)
B(5,21,12,SEA_LANTERN)
B(6,21,12,SEA_LANTERN)
B(7,21,12,STAINED_GLASS:6)
B(8,21,12,STAINED_GLASS:15)
B(9,21,12,STAINED_GLASS:15)
B(1,21,13,STAINED_GLASS:15)
B(2,21,13,STAINED_GLASS:9)
B(3,21,13,STAINED_GLASS:6)
B(4,21,13,STAINED_GLASS:6)
B(5,21,13,SEA_LANTERN)
B(6,21,13,SEA_LANTERN)
B(7,21,13,STAINED_GLASS:6)
B(8,21,13,STAINED_GLASS:9)
B(9,21,13,STAINED_GLASS:15)
B(1,21,14,STAINED_GLASS:15)
B(2,21,14,STAINED_GLASS:9)
B(3,21,14,STAINED_GLASS:6)
B(4,21,14,STAINED_GLASS:6)
B(5,21,14,STAINED_GLASS:6)
B(6,21,14,STAINED_GLASS:6)
B(7,21,14,STAINED_GLASS:6)
B(8,21,14,STAINED_GLASS:9)
B(9,21,14,STAINED_GLASS:15)
B(1,21,15,STAINED_GLASS:15)
B(2,21,15,STAINED_GLASS:15)
B(3,21,15,STAINED_GLASS:6)
B(4,21,15,STAINED_GLASS:6)
B(5,21,15,STAINED_GLASS:6)
B(6,21,15,STAINED_GLASS:6)
B(7,21,15,STAINED_GLASS:6)
B(8,21,15,STAINED_GLASS:15)
B(3,22,7,STAINED_GLASS:9)
B(4,22,7,STAINED_GLASS:9)
B(5,22,7,STAINED_GLASS:9)
B(6,22,7,STAINED_GLASS:9)
B(7,22,7,STAINED_GLASS:9)
B(8,22,7,STAINED_GLASS:9)
B(1,22,8,STAINED_GLASS:15)
B(2,22,8,STAINED_GLASS:9)
B(3,22,8,STAINED_GLASS:9)
B(4,22,8,STAINED_GLASS:9)
B(5,22,8,STAINED_GLASS:9)
B(6,22,8,STAINED_GLASS:9)
B(7,22,8,STAINED_GLASS:9)
B(8,22,8,STAINED_GLASS:9)
B(1,22,9,STAINED_GLASS:15)
B(2,22,9,STAINED_GLASS:15)
B(3,22,9,STAINED_GLASS:9)
B(4,22,9,STAINED_GLASS:9)
B(5,22,9,STAINED_GLASS:9)
B(6,22,9,STAINED_GLASS:9)
B(7,22,9,STAINED_GLASS:9)
B(8,22,9,STAINED_GLASS:9)
B(9,22,9,STAINED_GLASS:9)
B(1,22,10,STAINED_GLASS:15)
B(2,22,10,STAINED_GLASS:9)
B(3,22,10,STAINED_GLASS:6)
B(4,22,10,STAINED_GLASS:6)
B(5,22,10,STAINED_GLASS:6)
B(6,22,10,STAINED_GLASS:6)
B(7,22,10,STAINED_GLASS:6)
B(8,22,10,STAINED_GLASS:9)
B(9,22,10,STAINED_GLASS:9)
B(1,22,11,STAINED_GLASS:15)
B(2,22,11,STAINED_GLASS:9)
B(3,22,11,STAINED_GLASS:6)
B(4,22,11,STAINED_GLASS:6)
B(5,22,11,SEA_LANTERN)
B(6,22,11,STAINED_GLASS:6)
B(7,22,11,STAINED_GLASS:6)
B(8,22,11,STAINED_GLASS:9)
B(9,22,11,STAINED_GLASS:9)
B(1,22,12,STAINED_GLASS:15)
B(2,22,12,STAINED_GLASS:9)
B(3,22,12,STAINED_GLASS:6)
B(4,22,12,SEA_LANTERN)
B(5,22,12,SEA_LANTERN)
B(6,22,12,SEA_LANTERN)
B(7,22,12,STAINED_GLASS:6)
B(8,22,12,STAINED_GLASS:9)
B(9,22,12,STAINED_GLASS:15)
B(1,22,13,STAINED_GLASS:15)
B(2,22,13,STAINED_GLASS:9)
B(3,22,13,STAINED_GLASS:6)
B(4,22,13,STAINED_GLASS:6)
B(5,22,13,SEA_LANTERN)
B(6,22,13,STAINED_GLASS:6)
B(7,22,13,STAINED_GLASS:6)
B(8,22,13,STAINED_GLASS:9)
B(9,22,13,STAINED_GLASS:9)
B(1,22,14,STAINED_GLASS:15)
B(2,22,14,STAINED_GLASS:15)
B(3,22,14,STAINED_GLASS:6)
B(4,22,14,STAINED_GLASS:6)
B(5,22,14,STAINED_GLASS:6)
B(6,22,14,STAINED_GLASS:6)
B(7,22,14,STAINED_GLASS:6)
B(8,22,14,STAINED_GLASS:9)
B(9,22,14,STAINED_GLASS:15)
B(1,22,15,STAINED_GLASS:15)
B(2,22,15,STAINED_GLASS:15)
B(3,22,15,STAINED_GLASS:15)
B(4,22,15,STAINED_GLASS:9)
B(5,22,15,STAINED_GLASS:9)
B(6,22,15,STAINED_GLASS:15)
B(7,22,15,STAINED_GLASS:9)
B(8,22,15,STAINED_GLASS:15)
B(5,23,6,STAINED_GLASS:9)
B(7,23,6,STAINED_GLASS:9)
B(8,23,6,STAINED_GLASS:15)
B(1,23,7,STAINED_GLASS:9)
B(2,23,7,STAINED_GLASS:9)
B(3,23,7,STAINED_GLASS:9)
B(4,23,7,STAINED_GLASS:9)
B(5,23,7,STAINED_GLASS:9)
B(6,23,7,STAINED_GLASS:9)
B(7,23,7,STAINED_GLASS:9)
B(8,23,7,STAINED_GLASS:9)
B(1,23,8,STAINED_GLASS:9)
B(2,23,8,STAINED_GLASS:9)
B(3,23,8,STAINED_GLASS:9)
B(4,23,8,STAINED_GLASS:9)
B(5,23,8,STAINED_GLASS:9)
B(6,23,8,STAINED_GLASS:9)
B(7,23,8,STAINED_GLASS:9)
B(8,23,8,STAINED_GLASS:9)
B(1,23,9,STAINED_GLASS:15)
B(2,23,9,STAINED_GLASS:9)
B(3,23,9,STAINED_GLASS:9)
B(4,23,9,STAINED_GLASS:6)
B(5,23,9,STAINED_GLASS:6)
B(6,23,9,STAINED_GLASS:9)
B(7,23,9,STAINED_GLASS:6)
B(8,23,9,STAINED_GLASS:9)
B(9,23,9,STAINED_GLASS:9)
B(1,23,10,STAINED_GLASS:15)
B(2,23,10,STAINED_GLASS:9)
B(3,23,10,STAINED_GLASS:6)
B(4,23,10,STAINED_GLASS:6)
B(5,23,10,STAINED_GLASS:6)
B(6,23,10,STAINED_GLASS:6)
B(7,23,10,STAINED_GLASS:6)
B(8,23,10,STAINED_GLASS:9)
B(9,23,10,STAINED_GLASS:9)
B(1,23,11,STAINED_GLASS:15)
B(2,23,11,STAINED_GLASS:15)
B(3,23,11,STAINED_GLASS:6)
B(4,23,11,SEA_LANTERN)
B(5,23,11,SEA_LANTERN)
B(6,23,11,STAINED_GLASS:6)
B(7,23,11,STAINED_GLASS:6)
B(8,23,11,STAINED_GLASS:9)
B(9,23,11,STAINED_GLASS:9)
B(1,23,12,STAINED_GLASS:15)
B(2,23,12,STAINED_GLASS:15)
B(3,23,12,STAINED_GLASS:6)
B(4,23,12,SEA_LANTERN)
B(5,23,12,SEA_LANTERN)
B(6,23,12,SEA_LANTERN)
B(7,23,12,STAINED_GLASS:6)
B(8,23,12,STAINED_GLASS:9)
B(9,23,12,STAINED_GLASS:15)
B(1,23,13,STAINED_GLASS:15)
B(2,23,13,STAINED_GLASS:9)
B(3,23,13,STAINED_GLASS:6)
B(4,23,13,STAINED_GLASS:6)
B(5,23,13,STAINED_GLASS:6)
B(6,23,13,STAINED_GLASS:6)
B(7,23,13,STAINED_GLASS:6)
B(8,23,13,STAINED_GLASS:9)
B(9,23,13,STAINED_GLASS:15)
B(2,23,14,STAINED_GLASS:15)
B(3,23,14,STAINED_GLASS:6)
B(4,23,14,STAINED_GLASS:15)
B(5,23,14,STAINED_GLASS:9)
B(6,23,14,STAINED_GLASS:9)
B(7,23,14,STAINED_GLASS:9)
B(8,23,14,STAINED_GLASS:9)
B(2,23,15,STAINED_GLASS:15)
B(3,23,15,STAINED_GLASS:15)
B(4,23,15,STAINED_GLASS:15)
B(5,23,15,STAINED_GLASS:15)
B(6,23,15,STAINED_GLASS:9)
B(7,23,15,STAINED_GLASS:15)
B(7,24,5,STAINED_GLASS:15)
B(1,24,6,STAINED_GLASS:9)
B(2,24,6,STAINED_GLASS:9)
B(3,24,6,STAINED_GLASS:9)
B(4,24,6,STAINED_GLASS:9)
B(5,24,6,STAINED_GLASS:9)
B(6,24,6,STAINED_GLASS:15)
B(7,24,6,STAINED_GLASS:9)
B(8,24,6,STAINED_GLASS:15)
B(1,24,7,STAINED_GLASS:9)
B(2,24,7,STAINED_GLASS:9)
B(3,24,7,STAINED_GLASS:9)
B(4,24,7,STAINED_GLASS:9)
B(5,24,7,STAINED_GLASS:9)
B(6,24,7,STAINED_GLASS:15)
B(7,24,7,STAINED_GLASS:15)
B(8,24,7,STAINED_GLASS:9)
B(1,24,8,STAINED_GLASS:9)
B(2,24,8,STAINED_GLASS:9)
B(3,24,8,STAINED_GLASS:9)
B(4,24,8,STAINED_GLASS:9)
B(5,24,8,STAINED_GLASS:9)
B(6,24,8,STAINED_GLASS:6)
B(7,24,8,STAINED_GLASS:9)
B(8,24,8,STAINED_GLASS:9)
B(9,24,8,STAINED_GLASS:9)
B(0,24,9,STAINED_GLASS:15)
B(1,24,9,STAINED_GLASS:9)
B(2,24,9,STAINED_GLASS:9)
B(3,24,9,STAINED_GLASS:6)
B(4,24,9,STAINED_GLASS:6)
B(5,24,9,STAINED_GLASS:6)
B(6,24,9,STAINED_GLASS:6)
B(7,24,9,STAINED_GLASS:6)
B(8,24,9,STAINED_GLASS:9)
B(9,24,9,STAINED_GLASS:9)
B(1,24,10,STAINED_GLASS:9)
B(2,24,10,STAINED_GLASS:9)
B(3,24,10,STAINED_GLASS:6)
B(4,24,10,STAINED_GLASS:6)
B(5,24,10,SEA_LANTERN)
B(6,24,10,STAINED_GLASS:6)
B(7,24,10,STAINED_GLASS:6)
B(8,24,10,STAINED_GLASS:9)
B(9,24,10,STAINED_GLASS:9)
B(1,24,11,STAINED_GLASS:15)
B(2,24,11,STAINED_GLASS:9)
B(3,24,11,STAINED_GLASS:6)
B(4,24,11,SEA_LANTERN)
B(5,24,11,SEA_LANTERN)
B(6,24,11,STAINED_GLASS:6)
B(7,24,11,STAINED_GLASS:6)
B(8,24,11,STAINED_GLASS:9)
B(9,24,11,STAINED_GLASS:9)
B(1,24,12,STAINED_GLASS:15)
B(2,24,12,STAINED_GLASS:9)
B(3,24,12,STAINED_GLASS:6)
B(4,24,12,STAINED_GLASS:6)
B(5,24,12,STAINED_GLASS:6)
B(6,24,12,STAINED_GLASS:6)
B(7,24,12,STAINED_GLASS:6)
B(8,24,12,STAINED_GLASS:9)
B(9,24,12,STAINED_GLASS:15)
B(1,24,13,STAINED_GLASS:15)
B(2,24,13,STAINED_GLASS:15)
B(3,24,13,STAINED_GLASS:6)
B(4,24,13,STAINED_GLASS:6)
B(5,24,13,STAINED_GLASS:6)
B(6,24,13,STAINED_GLASS:9)
B(7,24,13,STAINED_GLASS:9)
B(8,24,13,STAINED_GLASS:9)
B(9,24,13,STAINED_GLASS:15)
B(2,24,14,STAINED_GLASS:15)
B(3,24,14,STAINED_GLASS:15)
B(4,24,14,STAINED_GLASS:15)
B(5,24,14,STAINED_GLASS:9)
B(6,24,14,STAINED_GLASS:9)
B(7,24,14,STAINED_GLASS:9)
B(8,24,14,STAINED_GLASS:15)
B(4,24,15,STAINED_GLASS:9)
B(5,24,15,STAINED_GLASS:9)
B(6,24,15,STAINED_GLASS:9)
B(1,25,5,STAINED_GLASS:15)
B(2,25,5,STAINED_GLASS:9)
B(3,25,5,STAINED_GLASS:9)
B(4,25,5,STAINED_GLASS:9)
B(5,25,5,STAINED_GLASS:15)
B(6,25,5,STAINED_GLASS:15)
B(7,25,5,STAINED_GLASS:9)
B(8,25,5,STAINED_GLASS:15)
B(1,25,6,STAINED_GLASS:9)
B(2,25,6,STAINED_GLASS:9)
B(3,25,6,STAINED_GLASS:9)
B(4,25,6,STAINED_GLASS:9)
B(5,25,6,STAINED_GLASS:15)
B(6,25,6,STAINED_GLASS:9)
B(7,25,6,STAINED_GLASS:15)
B(8,25,6,STAINED_GLASS:15)
B(1,25,7,STAINED_GLASS:15)
B(2,25,7,STAINED_GLASS:9)
B(3,25,7,STAINED_GLASS:9)
B(4,25,7,STAINED_GLASS:9)
B(5,25,7,STAINED_GLASS:9)
B(6,25,7,STAINED_GLASS:9)
B(7,25,7,STAINED_GLASS:9)
B(8,25,7,STAINED_GLASS:9)
B(1,25,8,STAINED_GLASS:9)
B(2,25,8,STAINED_GLASS:6)
B(3,25,8,STAINED_GLASS:6)
B(4,25,8,STAINED_GLASS:6)
B(5,25,8,STAINED_GLASS:6)
B(6,25,8,STAINED_GLASS:6)
B(7,25,8,STAINED_GLASS:9)
B(8,25,8,STAINED_GLASS:9)
B(9,25,8,STAINED_GLASS:9)
B(0,25,9,STAINED_GLASS:15)
B(1,25,9,STAINED_GLASS:15)
B(2,25,9,STAINED_GLASS:9)
B(3,25,9,STAINED_GLASS:6)
B(4,25,9,SEA_LANTERN)
B(5,25,9,SEA_LANTERN)
B(6,25,9,STAINED_GLASS:6)
B(7,25,9,STAINED_GLASS:6)
B(8,25,9,STAINED_GLASS:9)
B(9,25,9,STAINED_GLASS:9)
B(1,25,10,STAINED_GLASS:15)
B(2,25,10,STAINED_GLASS:9)
B(3,25,10,STAINED_GLASS:6)
B(4,25,10,STAINED_GLASS:6)
B(5,25,10,SEA_LANTERN)
B(6,25,10,STAINED_GLASS:6)
B(7,25,10,STAINED_GLASS:6)
B(8,25,10,STAINED_GLASS:9)
B(9,25,10,STAINED_GLASS:9)
B(1,25,11,STAINED_GLASS:9)
B(2,25,11,STAINED_GLASS:9)
B(3,25,11,STAINED_GLASS:6)
B(4,25,11,SEA_LANTERN)
B(5,25,11,STAINED_GLASS:6)
B(6,25,11,STAINED_GLASS:6)
B(7,25,11,STAINED_GLASS:6)
B(8,25,11,STAINED_GLASS:9)
B(9,25,11,STAINED_GLASS:9)
B(1,25,12,STAINED_GLASS:15)
B(2,25,12,STAINED_GLASS:9)
B(3,25,12,STAINED_GLASS:6)
B(4,25,12,STAINED_GLASS:6)
B(5,25,12,STAINED_GLASS:6)
B(6,25,12,STAINED_GLASS:6)
B(7,25,12,STAINED_GLASS:6)
B(8,25,12,STAINED_GLASS:15)
B(2,25,13,STAINED_GLASS:9)
B(3,25,13,STAINED_GLASS:9)
B(4,25,13,STAINED_GLASS:9)
B(5,25,13,STAINED_GLASS:9)
B(6,25,13,STAINED_GLASS:9)
B(7,25,13,STAINED_GLASS:9)
B(8,25,13,STAINED_GLASS:9)
B(9,25,13,STAINED_GLASS:15)
B(3,25,14,STAINED_GLASS:15)
B(4,25,14,STAINED_GLASS:15)
B(5,25,14,STAINED_GLASS:9)
B(6,25,14,STAINED_GLASS:9)
B(7,25,14,STAINED_GLASS:9)
B(3,26,4,STAINED_GLASS:15)
B(4,26,4,STAINED_GLASS:15)
B(6,26,4,STAINED_GLASS:15)
B(7,26,4,STAINED_GLASS:15)
B(1,26,5,STAINED_GLASS:9)
B(2,26,5,STAINED_GLASS:9)
B(3,26,5,STAINED_GLASS:9)
B(4,26,5,STAINED_GLASS:9)
B(5,26,5,STAINED_GLASS:9)
B(6,26,5,STAINED_GLASS:9)
B(7,26,5,STAINED_GLASS:15)
B(8,26,5,STAINED_GLASS:15)
B(1,26,6,STAINED_GLASS:15)
B(2,26,6,STAINED_GLASS:15)
B(3,26,6,STAINED_GLASS:15)
B(4,26,6,STAINED_GLASS:15)
B(5,26,6,STAINED_GLASS:9)
B(6,26,6,STAINED_GLASS:15)
B(7,26,6,STAINED_GLASS:9)
B(8,26,6,STAINED_GLASS:15)
B(1,26,7,STAINED_GLASS:9)
B(2,26,7,STAINED_GLASS:9)
B(3,26,7,STAINED_GLASS:6)
B(4,26,7,STAINED_GLASS:6)
B(5,26,7,STAINED_GLASS:6)
B(6,26,7,STAINED_GLASS:6)
B(7,26,7,STAINED_GLASS:9)
B(8,26,7,STAINED_GLASS:9)
B(9,26,7,STAINED_GLASS:9)
B(1,26,8,STAINED_GLASS:9)
B(2,26,8,STAINED_GLASS:6)
B(3,26,8,STAINED_GLASS:6)
B(4,26,8,STAINED_GLASS:6)
B(5,26,8,STAINED_GLASS:6)
B(6,26,8,STAINED_GLASS:6)
B(7,26,8,STAINED_GLASS:9)
B(8,26,8,STAINED_GLASS:9)
B(9,26,8,STAINED_GLASS:9)
B(0,26,9,STAINED_GLASS:9)
B(1,26,9,STAINED_GLASS:9)
B(2,26,9,STAINED_GLASS:9)
B(3,26,9,STAINED_GLASS:6)
B(4,26,9,SEA_LANTERN)
B(5,26,9,SEA_LANTERN)
B(6,26,9,STAINED_GLASS:6)
B(7,26,9,STAINED_GLASS:6)
B(8,26,9,STAINED_GLASS:9)
B(9,26,9,STAINED_GLASS:9)
B(1,26,10,STAINED_GLASS:9)
B(2,26,10,STAINED_GLASS:15)
B(3,26,10,STAINED_GLASS:6)
B(4,26,10,STAINED_GLASS:6)
B(5,26,10,SEA_LANTERN)
B(6,26,10,STAINED_GLASS:6)
B(7,26,10,STAINED_GLASS:6)
B(8,26,10,STAINED_GLASS:9)
B(9,26,10,STAINED_GLASS:9)
B(1,26,11,STAINED_GLASS:15)
B(2,26,11,STAINED_GLASS:15)
B(3,26,11,STAINED_GLASS:6)
B(4,26,11,STAINED_GLASS:6)
B(5,26,11,STAINED_GLASS:6)
B(6,26,11,STAINED_GLASS:6)
B(7,26,11,STAINED_GLASS:6)
B(8,26,11,STAINED_GLASS:9)
B(9,26,11,STAINED_GLASS:15)
B(1,26,12,STAINED_GLASS:15)
B(2,26,12,STAINED_GLASS:15)
B(3,26,12,STAINED_GLASS:9)
B(4,26,12,STAINED_GLASS:9)
B(5,26,12,STAINED_GLASS:9)
B(6,26,12,STAINED_GLASS:9)
B(7,26,12,STAINED_GLASS:9)
B(8,26,12,STAINED_GLASS:15)
B(2,26,13,STAINED_GLASS:15)
B(3,26,13,STAINED_GLASS:15)
B(4,26,13,STAINED_GLASS:15)
B(5,26,13,STAINED_GLASS:9)
B(6,26,13,STAINED_GLASS:9)
B(8,26,13,STAINED_GLASS:9)
B(5,27,3,STAINED_GLASS:15)
B(6,27,3,STAINED_GLASS:15)
B(8,27,3,STAINED_GLASS:15)
B(0,27,4,STAINED_GLASS:15)
B(1,27,4,STAINED_GLASS:15)
B(2,27,4,STAINED_GLASS:15)
B(3,27,4,STAINED_GLASS:9)
B(4,27,4,STAINED_GLASS:9)
B(5,27,4,STAINED_GLASS:15)
B(6,27,4,STAINED_GLASS:9)
B(7,27,4,STAINED_GLASS:9)
B(1,27,5,STAINED_GLASS:15)
B(2,27,5,STAINED_GLASS:15)
B(3,27,5,STAINED_GLASS:15)
B(4,27,5,STAINED_GLASS:15)
B(5,27,5,STAINED_GLASS:15)
B(6,27,5,STAINED_GLASS:15)
B(7,27,5,STAINED_GLASS:9)
B(8,27,5,STAINED_GLASS:15)
B(1,27,6,STAINED_GLASS:9)
B(2,27,6,STAINED_GLASS:9)
B(3,27,6,STAINED_GLASS:9)
B(4,27,6,STAINED_GLASS:9)
B(5,27,6,STAINED_GLASS:6)
B(6,27,6,STAINED_GLASS:9)
B(7,27,6,STAINED_GLASS:6)
B(8,27,6,STAINED_GLASS:15)
B(1,27,7,STAINED_GLASS:9)
B(2,27,7,STAINED_GLASS:6)
B(3,27,7,STAINED_GLASS:6)
B(4,27,7,STAINED_GLASS:6)
B(5,27,7,STAINED_GLASS:6)
B(6,27,7,STAINED_GLASS:6)
B(7,27,7,STAINED_GLASS:9)
B(8,27,7,STAINED_GLASS:9)
B(9,27,7,STAINED_GLASS:9)
B(1,27,8,STAINED_GLASS:9)
B(2,27,8,STAINED_GLASS:6)
B(3,27,8,STAINED_GLASS:6)
B(4,27,8,SEA_LANTERN)
B(5,27,8,SEA_LANTERN)
B(6,27,8,STAINED_GLASS:6)
B(7,27,8,STAINED_GLASS:9)
B(8,27,8,STAINED_GLASS:9)
B(9,27,8,STAINED_GLASS:9)
B(0,27,9,STAINED_GLASS:9)
B(1,27,9,STAINED_GLASS:15)
B(2,27,9,STAINED_GLASS:9)
B(3,27,9,STAINED_GLASS:6)
B(4,27,9,SEA_LANTERN)
B(5,27,9,SEA_LANTERN)
B(6,27,9,STAINED_GLASS:6)
B(7,27,9,STAINED_GLASS:6)
B(8,27,9,STAINED_GLASS:9)
B(9,27,9,STAINED_GLASS:9)
B(1,27,10,STAINED_GLASS:15)
B(2,27,10,STAINED_GLASS:15)
B(3,27,10,STAINED_GLASS:6)
B(4,27,10,STAINED_GLASS:6)
B(5,27,10,STAINED_GLASS:6)
B(6,27,10,STAINED_GLASS:6)
B(7,27,10,STAINED_GLASS:6)
B(8,27,10,STAINED_GLASS:15)
B(9,27,10,STAINED_GLASS:9)
B(1,27,11,STAINED_GLASS:15)
B(2,27,11,STAINED_GLASS:15)
B(3,27,11,STAINED_GLASS:6)
B(4,27,11,STAINED_GLASS:6)
B(5,27,11,STAINED_GLASS:9)
B(6,27,11,STAINED_GLASS:9)
B(7,27,11,STAINED_GLASS:6)
B(8,27,11,STAINED_GLASS:9)
B(2,27,12,STAINED_GLASS:15)
B(3,27,12,STAINED_GLASS:15)
B(4,27,12,STAINED_GLASS:9)
B(5,27,12,STAINED_GLASS:9)
B(6,27,12,STAINED_GLASS:9)
B(7,27,12,STAINED_GLASS:9)
B(8,27,12,STAINED_GLASS:9)
B(3,27,13,STAINED_GLASS:15)
B(4,27,13,STAINED_GLASS:15)
B(5,27,13,STAINED_GLASS:9)
B(1,28,3,STAINED_GLASS:15)
B(3,28,3,STAINED_GLASS:15)
B(4,28,3,STAINED_GLASS:15)
B(5,28,3,STAINED_GLASS:9)
B(6,28,3,STAINED_GLASS:9)
B(7,28,3,STAINED_GLASS:15)
B(8,28,3,STAINED_GLASS:15)
B(0,28,4,STAINED_GLASS:9)
B(1,28,4,STAINED_GLASS:9)
B(2,28,4,STAINED_GLASS:9)
B(3,28,4,STAINED_GLASS:15)
B(4,28,4,STAINED_GLASS:15)
B(5,28,4,STAINED_GLASS:9)
B(6,28,4,STAINED_GLASS:15)
B(7,28,4,STAINED_GLASS:15)
B(1,28,5,STAINED_GLASS:9)
B(2,28,5,STAINED_GLASS:9)
B(3,28,5,STAINED_GLASS:9)
B(4,28,5,STAINED_GLASS:9)
B(5,28,5,STAINED_GLASS:9)
B(6,28,5,STAINED_GLASS:9)
B(7,28,5,STAINED_GLASS:9)
B(8,28,5,STAINED_GLASS:15)
B(0,28,6,STAINED_GLASS:9)
B(1,28,6,STAINED_GLASS:9)
B(2,28,6,STAINED_GLASS:9)
B(3,28,6,STAINED_GLASS:6)
B(4,28,6,STAINED_GLASS:6)
B(5,28,6,STAINED_GLASS:6)
B(6,28,6,STAINED_GLASS:6)
B(7,28,6,STAINED_GLASS:6)
B(8,28,6,STAINED_GLASS:9)
B(1,28,7,STAINED_GLASS:15)
B(2,28,7,STAINED_GLASS:6)
B(3,28,7,STAINED_GLASS:6)
B(4,28,7,SEA_LANTERN)
B(5,28,7,SEA_LANTERN)
B(6,28,7,STAINED_GLASS:6)
B(7,28,7,STAINED_GLASS:9)
B(8,28,7,STAINED_GLASS:9)
B(9,28,7,STAINED_GLASS:9)
B(1,28,8,STAINED_GLASS:15)
B(2,28,8,STAINED_GLASS:6)
B(3,28,8,STAINED_GLASS:6)
B(4,28,8,SEA_LANTERN)
B(5,28,8,SEA_LANTERN)
B(6,28,8,STAINED_GLASS:6)
B(7,28,8,STAINED_GLASS:9)
B(8,28,8,STAINED_GLASS:9)
B(9,28,8,STAINED_GLASS:9)
B(0,28,9,STAINED_GLASS:15)
B(1,28,9,STAINED_GLASS:15)
B(2,28,9,STAINED_GLASS:9)
B(3,28,9,STAINED_GLASS:6)
B(4,28,9,STAINED_GLASS:6)
B(5,28,9,STAINED_GLASS:6)
B(6,28,9,STAINED_GLASS:6)
B(7,28,9,STAINED_GLASS:6)
B(8,28,9,STAINED_GLASS:9)
B(9,28,9,STAINED_GLASS:9)
B(1,28,10,STAINED_GLASS:15)
B(2,28,10,STAINED_GLASS:15)
B(3,28,10,STAINED_GLASS:6)
B(4,28,10,STAINED_GLASS:6)
B(5,28,10,STAINED_GLASS:6)
B(6,28,10,STAINED_GLASS:6)
B(7,28,10,STAINED_GLASS:15)
B(8,28,10,STAINED_GLASS:15)
B(9,28,10,STAINED_GLASS:9)
B(1,28,11,STAINED_GLASS:15)
B(2,28,11,STAINED_GLASS:15)
B(3,28,11,STAINED_GLASS:9)
B(4,28,11,STAINED_GLASS:9)
B(5,28,11,STAINED_GLASS:15)
B(6,28,11,STAINED_GLASS:9)
B(7,28,11,STAINED_GLASS:15)
B(8,28,11,STAINED_GLASS:9)
B(2,28,12,STAINED_GLASS:15)
B(4,28,12,STAINED_GLASS:15)
B(5,28,12,STAINED_GLASS:15)
B(6,28,12,STAINED_GLASS:15)
B(1,29,3,STAINED_GLASS:15)
B(3,29,3,STAINED_GLASS:15)
B(4,29,3,STAINED_GLASS:15)
B(5,29,3,STAINED_GLASS:9)
B(6,29,3,STAINED_GLASS:9)
B(7,29,3,STAINED_GLASS:15)
B(8,29,3,STAINED_GLASS:15)
B(0,29,4,STAINED_GLASS:9)
B(1,29,4,STAINED_GLASS:9)
B(2,29,4,STAINED_GLASS:9)
B(3,29,4,STAINED_GLASS:15)
B(4,29,4,STAINED_GLASS:15)
B(5,29,4,STAINED_GLASS:9)
B(6,29,4,STAINED_GLASS:15)
B(7,29,4,STAINED_GLASS:15)
B(1,29,5,STAINED_GLASS:9)
B(2,29,5,STAINED_GLASS:9)
B(3,29,5,STAINED_GLASS:9)
B(4,29,5,STAINED_GLASS:9)
B(5,29,5,STAINED_GLASS:9)
B(6,29,5,STAINED_GLASS:9)
B(7,29,5,STAINED_GLASS:9)
B(8,29,5,STAINED_GLASS:15)
B(0,29,6,STAINED_GLASS:15)
B(1,29,6,STAINED_GLASS:9)
B(2,29,6,STAINED_GLASS:9)
B(3,29,6,STAINED_GLASS:6)
B(4,29,6,STAINED_GLASS:6)
B(5,29,6,SEA_LANTERN)
B(6,29,6,STAINED_GLASS:6)
B(7,29,6,STAINED_GLASS:6)
B(8,29,6,STAINED_GLASS:9)
B(1,29,7,STAINED_GLASS:15)
B(2,29,7,STAINED_GLASS:6)
B(3,29,7,STAINED_GLASS:6)
B(4,29,7,SEA_LANTERN)
B(5,29,7,SEA_LANTERN)
B(6,29,7,STAINED_GLASS:6)
B(7,29,7,STAINED_GLASS:9)
B(8,29,7,STAINED_GLASS:9)
B(9,29,7,STAINED_GLASS:9)
B(1,29,8,STAINED_GLASS:15)
B(2,29,8,STAINED_GLASS:6)
B(3,29,8,STAINED_GLASS:6)
B(4,29,8,SEA_LANTERN)
B(5,29,8,SEA_LANTERN)
B(6,29,8,STAINED_GLASS:6)
B(7,29,8,STAINED_GLASS:9)
B(8,29,8,STAINED_GLASS:9)
B(9,29,8,STAINED_GLASS:9)
B(0,29,9,STAINED_GLASS:15)
B(1,29,9,STAINED_GLASS:15)
B(2,29,9,STAINED_GLASS:15)
B(3,29,9,STAINED_GLASS:6)
B(4,29,9,STAINED_GLASS:6)
B(5,29,9,STAINED_GLASS:6)
B(6,29,9,STAINED_GLASS:6)
B(7,29,9,STAINED_GLASS:6)
B(8,29,9,STAINED_GLASS:9)
B(1,29,10,STAINED_GLASS:15)
B(2,29,10,STAINED_GLASS:9)
B(3,29,10,STAINED_GLASS:9)
B(4,29,10,STAINED_GLASS:9)
B(5,29,10,STAINED_GLASS:15)
B(6,29,10,STAINED_GLASS:9)
B(7,29,10,STAINED_GLASS:15)
B(8,29,10,STAINED_GLASS:15)
B(1,29,11,STAINED_GLASS:15)
B(3,29,11,STAINED_GLASS:15)
B(4,29,11,STAINED_GLASS:9)
B(5,29,11,STAINED_GLASS:15)
B(6,29,11,STAINED_GLASS:15)
B(7,29,11,STAINED_GLASS:15)
B(2,30,2,STAINED_GLASS:15)
B(3,30,2,STAINED_GLASS:15)
B(5,30,2,STAINED_GLASS:15)
B(6,30,2,STAINED_GLASS:15)
B(1,30,3,STAINED_GLASS:15)
B(2,30,3,STAINED_GLASS:15)
B(3,30,3,STAINED_GLASS:9)
B(4,30,3,STAINED_GLASS:9)
B(5,30,3,STAINED_GLASS:15)
B(6,30,3,STAINED_GLASS:15)
B(7,30,3,STAINED_GLASS:15)
B(8,30,3,STAINED_GLASS:15)
B(0,30,4,STAINED_GLASS:15)
B(1,30,4,STAINED_GLASS:15)
B(2,30,4,STAINED_GLASS:15)
B(3,30,4,STAINED_GLASS:9)
B(4,30,4,STAINED_GLASS:9)
B(5,30,4,STAINED_GLASS:15)
B(6,30,4,STAINED_GLASS:9)
B(7,30,4,STAINED_GLASS:15)
B(1,30,5,STAINED_GLASS:15)
B(2,30,5,STAINED_GLASS:9)
B(3,30,5,STAINED_GLASS:6)
B(4,30,5,STAINED_GLASS:6)
B(5,30,5,STAINED_GLASS:6)
B(6,30,5,STAINED_GLASS:9)
B(7,30,5,STAINED_GLASS:9)
B(8,30,5,STAINED_GLASS:15)
B(1,30,6,STAINED_GLASS:9)
B(2,30,6,STAINED_GLASS:9)
B(3,30,6,STAINED_GLASS:6)
B(4,30,6,SEA_LANTERN)
B(5,30,6,SEA_LANTERN)
B(6,30,6,STAINED_GLASS:6)
B(7,30,6,STAINED_GLASS:6)
B(8,30,6,STAINED_GLASS:9)
B(1,30,7,STAINED_GLASS:15)
B(2,30,7,STAINED_GLASS:6)
B(3,30,7,STAINED_GLASS:6)
B(4,30,7,SEA_LANTERN)
B(5,30,7,SEA_LANTERN)
B(6,30,7,STAINED_GLASS:6)
B(7,30,7,STAINED_GLASS:9)
B(8,30,7,STAINED_GLASS:9)
B(1,30,8,STAINED_GLASS:15)
B(2,30,8,STAINED_GLASS:6)
B(3,30,8,STAINED_GLASS:6)
B(4,30,8,STAINED_GLASS:6)
B(5,30,8,STAINED_GLASS:6)
B(6,30,8,STAINED_GLASS:6)
B(7,30,8,STAINED_GLASS:9)
B(8,30,8,STAINED_GLASS:9)
B(1,30,9,STAINED_GLASS:15)
B(2,30,9,STAINED_GLASS:15)
B(3,30,9,STAINED_GLASS:6)
B(4,30,9,STAINED_GLASS:9)
B(5,30,9,STAINED_GLASS:9)
B(6,30,9,STAINED_GLASS:6)
B(7,30,9,STAINED_GLASS:9)
B(8,30,9,STAINED_GLASS:9)
B(1,30,10,STAINED_GLASS:15)
B(2,30,10,STAINED_GLASS:15)
B(3,30,10,STAINED_GLASS:15)
B(4,30,10,STAINED_GLASS:15)
B(5,30,10,STAINED_GLASS:15)
B(6,30,10,STAINED_GLASS:9)
B(4,30,11,STAINED_GLASS:15)
B(2,31,2,STAINED_GLASS:15)
B(3,31,2,STAINED_GLASS:15)
B(5,31,2,STAINED_GLASS:15)
B(6,31,2,STAINED_GLASS:15)
B(1,31,3,STAINED_GLASS:15)
B(2,31,3,STAINED_GLASS:15)
B(3,31,3,STAINED_GLASS:9)
B(4,31,3,STAINED_GLASS:9)
B(5,31,3,STAINED_GLASS:15)
B(6,31,3,STAINED_GLASS:15)
B(7,31,3,STAINED_GLASS:15)
B(2,31,4,STAINED_GLASS:15)
B(3,31,4,STAINED_GLASS:9)
B(4,31,4,STAINED_GLASS:9)
B(5,31,4,STAINED_GLASS:15)
B(6,31,4,STAINED_GLASS:9)
B(7,31,4,STAINED_GLASS:15)
B(2,31,5,STAINED_GLASS:9)
B(3,31,5,STAINED_GLASS:6)
B(4,31,5,STAINED_GLASS:6)
B(5,31,5,STAINED_GLASS:6)
B(6,31,5,STAINED_GLASS:9)
B(7,31,5,STAINED_GLASS:9)
B(1,31,6,STAINED_GLASS:15)
B(2,31,6,STAINED_GLASS:15)
B(3,31,6,STAINED_GLASS:6)
B(4,31,6,SEA_LANTERN)
B(5,31,6,STAINED_GLASS:6)
B(6,31,6,STAINED_GLASS:6)
B(7,31,6,STAINED_GLASS:9)
B(2,31,7,STAINED_GLASS:15)
B(3,31,7,STAINED_GLASS:6)
B(4,31,7,STAINED_GLASS:6)
B(5,31,7,STAINED_GLASS:6)
B(6,31,7,STAINED_GLASS:6)
B(7,31,7,STAINED_GLASS:9)
B(2,31,8,STAINED_GLASS:15)
B(3,31,8,STAINED_GLASS:15)
B(4,31,8,STAINED_GLASS:6)
B(5,31,8,STAINED_GLASS:6)
B(6,31,8,STAINED_GLASS:9)
B(7,31,8,STAINED_GLASS:9)
B(2,31,9,STAINED_GLASS:15)
B(3,31,9,STAINED_GLASS:15)
B(4,31,9,STAINED_GLASS:9)
B(5,31,9,STAINED_GLASS:9)
B(6,31,9,STAINED_GLASS:9)
B(7,31,9,STAINED_GLASS:9)
B(3,31,10,STAINED_GLASS:15)
B(4,31,10,STAINED_GLASS:15)
B(5,31,10,STAINED_GLASS:15)
B(6,31,10,STAINED_GLASS:9)
B(4,32,1,STAINED_GLASS:15)
B(2,32,2,STAINED_GLASS:15)
B(3,32,2,STAINED_GLASS:9)
B(4,32,2,STAINED_GLASS:15)
B(5,32,2,STAINED_GLASS:9)
B(6,32,2,STAINED_GLASS:15)
B(1,32,3,STAINED_GLASS:15)
B(2,32,3,STAINED_GLASS:15)
B(3,32,3,STAINED_GLASS:15)
B(4,32,3,STAINED_GLASS:15)
B(5,32,3,STAINED_GLASS:9)
B(6,32,3,STAINED_GLASS:15)
B(7,32,3,STAINED_GLASS:9)
B(2,32,4,STAINED_GLASS:15)
B(3,32,4,STAINED_GLASS:9)
B(4,32,4,STAINED_GLASS:9)
B(5,32,4,STAINED_GLASS:9)
B(6,32,4,STAINED_GLASS:9)
B(7,32,4,STAINED_GLASS:9)
B(2,32,5,STAINED_GLASS:9)
B(3,32,5,STAINED_GLASS:6)
B(4,32,5,STAINED_GLASS:6)
B(5,32,5,STAINED_GLASS:6)
B(6,32,5,STAINED_GLASS:9)
B(7,32,5,STAINED_GLASS:9)
B(1,32,6,STAINED_GLASS:9)
B(2,32,6,STAINED_GLASS:9)
B(3,32,6,STAINED_GLASS:9)
B(4,32,6,STAINED_GLASS:6)
B(5,32,6,STAINED_GLASS:6)
B(6,32,6,STAINED_GLASS:9)
B(7,32,6,STAINED_GLASS:9)
B(2,32,7,STAINED_GLASS:15)
B(3,32,7,STAINED_GLASS:15)
B(4,32,7,STAINED_GLASS:6)
B(5,32,7,STAINED_GLASS:6)
B(6,32,7,STAINED_GLASS:9)
B(7,32,7,STAINED_GLASS:9)
B(2,32,8,STAINED_GLASS:15)
B(3,32,8,STAINED_GLASS:15)
B(4,32,8,STAINED_GLASS:15)
B(5,32,8,STAINED_GLASS:9)
B(6,32,8,STAINED_GLASS:9)
B(3,32,9,STAINED_GLASS:15)
B(4,32,9,STAINED_GLASS:15)
B(5,32,9,STAINED_GLASS:9)
B(6,32,9,STAINED_GLASS:9)
B(4,33,1,STAINED_GLASS:15)
B(2,33,2,STAINED_GLASS:15)
B(3,33,2,STAINED_GLASS:9)
B(4,33,2,STAINED_GLASS:15)
B(5,33,2,STAINED_GLASS:9)
B(6,33,2,STAINED_GLASS:15)
B(2,33,3,STAINED_GLASS:15)
B(3,33,3,STAINED_GLASS:15)
B(4,33,3,STAINED_GLASS:15)
B(5,33,3,STAINED_GLASS:9)
B(6,33,3,STAINED_GLASS:15)
B(2,33,4,STAINED_GLASS:15)
B(3,33,4,STAINED_GLASS:15)
B(4,33,4,STAINED_GLASS:6)
B(5,33,4,STAINED_GLASS:9)
B(6,33,4,STAINED_GLASS:9)
B(2,33,5,STAINED_GLASS:15)
B(3,33,5,STAINED_GLASS:9)
B(4,33,5,STAINED_GLASS:9)
B(5,33,5,STAINED_GLASS:9)
B(6,33,5,STAINED_GLASS:9)
B(3,33,6,STAINED_GLASS:15)
B(4,33,6,SEA_LANTERN)
B(5,33,6,STAINED_GLASS:9)
B(6,33,6,STAINED_GLASS:9)
B(7,33,6,STAINED_GLASS:9)
B(2,33,7,STAINED_GLASS:15)
B(3,33,7,STAINED_GLASS:15)
B(4,33,7,STAINED_GLASS:9)
B(5,33,7,STAINED_GLASS:9)
B(6,33,7,STAINED_GLASS:9)
B(4,33,8,STAINED_GLASS:9)
B(5,33,8,STAINED_GLASS:9)
B(6,33,8,STAINED_GLASS:9)
B(3,33,9,STAINED_GLASS:15)
B(6,33,9,STAINED_GLASS:9)
B(4,34,1,STAINED_GLASS:15)
B(2,34,2,STAINED_GLASS:9)
B(3,34,2,STAINED_GLASS:9)
B(4,34,2,STAINED_GLASS:15)
B(5,34,2,STAINED_GLASS:9)
B(6,34,2,STAINED_GLASS:9)
B(2,34,3,STAINED_GLASS:9)
B(3,34,3,STAINED_GLASS:9)
B(4,34,3,STAINED_GLASS:15)
B(5,34,3,STAINED_GLASS:9)
B(6,34,3,STAINED_GLASS:9)
B(2,34,4,STAINED_GLASS:9)
B(3,34,4,STAINED_GLASS:15)
B(4,34,4,STAINED_GLASS:6)
B(5,34,4,STAINED_GLASS:9)
B(6,34,4,STAINED_GLASS:9)
B(2,34,5,STAINED_GLASS:15)
B(3,34,5,STAINED_GLASS:15)
B(4,34,5,STAINED_GLASS:15)
B(5,34,5,STAINED_GLASS:9)
B(6,34,5,STAINED_GLASS:9)
B(3,34,6,STAINED_GLASS:9)
B(4,34,6,STAINED_GLASS:9)
B(5,34,6,STAINED_GLASS:9)
B(6,34,6,STAINED_GLASS:9)
B(3,34,7,STAINED_GLASS:9)
B(4,34,7,STAINED_GLASS:9)
B(5,34,7,STAINED_GLASS:9)
B(6,34,7,STAINED_GLASS:9)
B(4,34,8,STAINED_GLASS:9)
B(5,34,8,STAINED_GLASS:9)
B(3,35,1,STAINED_GLASS:15)
B(4,35,1,STAINED_GLASS:9)
B(5,35,1,STAINED_GLASS:15)
B(3,35,2,STAINED_GLASS:9)
B(4,35,2,STAINED_GLASS:9)
B(5,35,2,STAINED_GLASS:15)
B(3,35,3,STAINED_GLASS:9)
B(4,35,3,STAINED_GLASS:9)
B(5,35,3,STAINED_GLASS:9)
B(3,35,4,STAINED_GLASS:9)
B(4,35,4,STAINED_GLASS:9)
B(5,35,4,STAINED_GLASS:9)
B(6,35,4,STAINED_GLASS:9)
B(3,35,5,STAINED_GLASS:9)
B(4,35,5,STAINED_GLASS:9)
B(5,35,5,STAINED_GLASS:9)
B(3,35,6,STAINED_GLASS:9)
B(4,35,6,STAINED_GLASS:9)
B(5,35,6,STAINED_GLASS:9)
B(6,35,6,STAINED_GLASS:9)
B(3,36,1,STAINED_GLASS:15)
B(4,36,1,STAINED_GLASS:9)
B(5,36,1,STAINED_GLASS:15)
B(3,36,2,STAINED_GLASS:9)
B(4,36,2,STAINED_GLASS:9)
B(5,36,2,STAINED_GLASS:15)
B(3,36,3,STAINED_GLASS:9)
B(4,36,3,STAINED_GLASS:9)
B(5,36,3,STAINED_GLASS:9)
B(3,36,4,STAINED_GLASS:9)
B(4,36,4,STAINED_GLASS:9)
B(5,36,4,STAINED_GLASS:9)
B(6,36,4,STAINED_GLASS:9)
B(3,36,5,STAINED_GLASS:9)
B(4,36,5,STAINED_GLASS:9)
B(5,36,5,STAINED_GLASS:9)
B(4,37,0,STAINED_GLASS:15)
B(3,37,1,STAINED_GLASS:15)
B(4,37,1,STAINED_GLASS:15)
B(5,37,1,STAINED_GLASS:15)
B(3,37,2,STAINED_GLASS:15)
B(4,37,2,STAINED_GLASS:15)
B(5,37,2,STAINED_GLASS:15)
B(4,37,3,STAINED_GLASS:9)
B(5,37,3,STAINED_GLASS:9)
B(5,37,4,STAINED_GLASS:9)
B(4,38,0,STAINED_GLASS:15)
B(3,38,1,STAINED_GLASS:15)
B(4,38,1,STAINED_GLASS:15)
B(5,38,1,STAINED_GLASS:15)
B(3,38,2,STAINED_GLASS:15)
B(4,38,2,STAINED_GLASS:15)
B(5,38,2,STAINED_GLASS:15)
B(4,38,3,STAINED_GLASS:15)
B(4,39,0,STAINED_GLASS:15)
B(4,39,1,STAINED_GLASS:15)
B(4,39,2,STAINED_GLASS:15)

