#######################################################################
# +-----------------------------------------------------------------+ #
# |                            BO3 object                           | #
# +-----------------------------------------------------------------+ #
#######################################################################

# This is the config file of a custom object.
# If you add this object correctly to your BiomeConfigs, it will spawn in the world.

# This is the creator of this BO3 object
Author: BO3 BulkEdit (by LanToaster)

# A short description of this BO3 object
Description: Bo3 spikes created by NLBlackEagle

# The BO3 version, don't change this! It can be used by external applications to do a version check.
Version: 3

# The settings mode, WriteAll, WriteWithoutComments or WriteDisable. See WorldConfig.
SettingsMode: WriteDisable


#######################################################################
# +-----------------------------------------------------------------+ #
# |                          Main settings                          | #
# +-----------------------------------------------------------------+ #
#######################################################################

# This needs to be set to true to spawn the object in the Tree and Sapling resources.
Tree: false

# The frequency of the BO3 from 1 to 200. Tries this many times to spawn this BO3 when using the CustomObject(...) resource.

Frequency: 100

# The rarity of the BO3 from 0 to 100. Each spawn attempt has rarity% chance to succeed when using the CustomObject(...) resource.

Rarity: 100

# If you set this to true, the BO3 will be placed with a random rotation.
RotateRandomly: true

# The spawn height of the BO3 - randomY, highestBlock or highestSolidBlock.
SpawnHeight: randomY

# The height limits for the BO3.
MinHeight: 0

MaxHeight: 256

# Objects can have other objects attacthed to it: branches. Branches can also
# have branches attached to it, which can also have branches, etc. This is the
# maximum branch depth for this objects.
MaxBranchDepth: 10

# When spawned with the UseWorld keyword, this BO3 should NOT spawn in the following biomes.
# If you writer.write the BO3 name directly in the BiomeConfigs, this will be ignored.
ExcludedBiomes: All


#######################################################################
# +-----------------------------------------------------------------+ #
# |                      Source block settings                      | #
# +-----------------------------------------------------------------+ #
#######################################################################

# The block(s) the BO3 should spawn in.
SourceBlocks: AIR

# The maximum percentage of the BO3 that can be outside the SourceBlock.
# The BO3 won't be placed on a location with more blocks outside the SourceBlock than this percentage.
MaxPercentageOutsideSourceBlock: 100

# What to do when a block is about to be placed outside the SourceBlock? (dontPlace, placeAnyway)
OutsideSourceBlock: placeAnyway


#######################################################################
# +-----------------------------------------------------------------+ #
# |                              Blocks                             | #
# +-----------------------------------------------------------------+ #
#######################################################################

# All the blocks used in the BO3 are listed here. Possible blocks:
# Block(x,y,z,id[.data][,nbtfile.nbt)
# RandomBlock(x,y,z,id[:data][,nbtfile.nbt],chance[,id[:data][,nbtfile.nbt],chance[,...]])
# So RandomBlock(0,0,0,CHEST,chest.nbt,50,CHEST,anotherchest.nbt,100) will spawn a chest at
# the BO3 origin, and give it a 50% chance to have the contents of chest.nbt, or, if that
# fails, a 100% percent chance to have the contents of anotherchest.nbt.
Block(-1,-1,0,STAINED_GLASS:15)
Block(0,-1,0,STAINED_GLASS:15)
Block(1,-1,0,STAINED_GLASS:10)
Block(2,-1,0,STAINED_GLASS:15)
Block(-2,-1,1,STAINED_GLASS:15)
Block(-1,-1,1,STAINED_GLASS:10)
Block(0,-1,1,STAINED_GLASS:10)
Block(1,-1,1,STAINED_GLASS:10)
Block(2,-1,1,STAINED_GLASS:10)
Block(3,-1,1,STAINED_GLASS:15)
Block(-2,-1,2,STAINED_GLASS:10)
Block(-1,-1,2,STAINED_GLASS:10)
Block(0,-1,2,STAINED_GLASS:10)
Block(1,-1,2,STAINED_GLASS:10)
Block(2,-1,2,STAINED_GLASS:10)
Block(3,-1,2,STAINED_GLASS:15)
Block(-3,-1,3,STAINED_GLASS:15)
Block(-2,-1,3,STAINED_GLASS:15)
Block(-1,-1,3,STAINED_GLASS:10)
Block(0,-1,3,SEA_LANTERN:0)
Block(1,-1,3,SEA_LANTERN:0)
Block(2,-1,3,STAINED_GLASS:10)
Block(3,-1,3,STAINED_GLASS:10)
Block(4,-1,3,STAINED_GLASS:15)
Block(-3,-1,4,STAINED_GLASS:15)
Block(-2,-1,4,STAINED_GLASS:15)
Block(-1,-1,4,STAINED_GLASS:10)
Block(0,-1,4,SEA_LANTERN:0)
Block(1,-1,4,SEA_LANTERN:0)
Block(2,-1,4,STAINED_GLASS:10)
Block(3,-1,4,STAINED_GLASS:15)
Block(4,-1,4,STAINED_GLASS:15)
Block(-3,-1,5,STAINED_GLASS:15)
Block(-2,-1,5,STAINED_GLASS:10)
Block(-1,-1,5,STAINED_GLASS:10)
Block(0,-1,5,STAINED_GLASS:10)
Block(1,-1,5,STAINED_GLASS:10)
Block(2,-1,5,STAINED_GLASS:10)
Block(3,-1,5,STAINED_GLASS:10)
Block(4,-1,5,STAINED_GLASS:15)
Block(-2,-1,6,STAINED_GLASS:15)
Block(-1,-1,6,STAINED_GLASS:10)
Block(0,-1,6,STAINED_GLASS:15)
Block(1,-1,6,STAINED_GLASS:15)
Block(2,-1,6,STAINED_GLASS:15)
Block(3,-1,6,STAINED_GLASS:15)
Block(3,0,-1,STAINED_GLASS:15)
Block(-3,0,0,STAINED_GLASS:15)
Block(-2,0,0,STAINED_GLASS:15)
Block(-1,0,0,STAINED_GLASS:15)
Block(1,0,0,STAINED_GLASS:10)
Block(2,0,0,STAINED_GLASS:15)
Block(3,0,0,STAINED_GLASS:15)
Block(-2,0,1,STAINED_GLASS:10)
Block(-1,0,1,STAINED_GLASS:10)
Block(0,0,1,STAINED_GLASS:10)
Block(1,0,1,STAINED_GLASS:10)
Block(2,0,1,STAINED_GLASS:10)
Block(3,0,1,STAINED_GLASS:15)
Block(-2,0,2,STAINED_GLASS:10)
Block(-1,0,2,STAINED_GLASS:10)
Block(0,0,2,SEA_LANTERN:0)
Block(1,0,2,SEA_LANTERN:0)
Block(2,0,2,STAINED_GLASS:10)
Block(3,0,2,STAINED_GLASS:15)
Block(-3,0,3,STAINED_GLASS:15)
Block(-2,0,3,STAINED_GLASS:15)
Block(-1,0,3,STAINED_GLASS:10)
Block(0,0,3,SEA_LANTERN:0)
Block(1,0,3,SEA_LANTERN:0)
Block(2,0,3,STAINED_GLASS:10)
Block(3,0,3,STAINED_GLASS:10)
Block(4,0,3,STAINED_GLASS:15)
Block(-3,0,4,STAINED_GLASS:15)
Block(-2,0,4,STAINED_GLASS:15)
Block(-1,0,4,STAINED_GLASS:10)
Block(0,0,4,STAINED_GLASS:10)
Block(1,0,4,STAINED_GLASS:10)
Block(2,0,4,STAINED_GLASS:10)
Block(3,0,4,STAINED_GLASS:15)
Block(-2,0,5,STAINED_GLASS:10)
Block(-1,0,5,STAINED_GLASS:10)
Block(0,0,5,STAINED_GLASS:10)
Block(1,0,5,STAINED_GLASS:10)
Block(2,0,5,STAINED_GLASS:15)
Block(3,0,5,STAINED_GLASS:10)
Block(4,0,5,STAINED_GLASS:15)
Block(-2,0,6,STAINED_GLASS:15)
Block(-1,0,6,STAINED_GLASS:15)
Block(-2,1,-1,STAINED_GLASS:15)
Block(-1,1,-1,STAINED_GLASS:15)
Block(1,1,-1,STAINED_GLASS:15)
Block(2,1,-1,STAINED_GLASS:15)
Block(3,1,-1,STAINED_GLASS:15)
Block(-3,1,0,STAINED_GLASS:15)
Block(-2,1,0,STAINED_GLASS:15)
Block(-1,1,0,STAINED_GLASS:10)
Block(0,1,0,STAINED_GLASS:10)
Block(1,1,0,STAINED_GLASS:10)
Block(2,1,0,STAINED_GLASS:10)
Block(3,1,0,STAINED_GLASS:15)
Block(-2,1,1,STAINED_GLASS:10)
Block(-1,1,1,STAINED_GLASS:10)
Block(0,1,1,SEA_LANTERN:0)
Block(1,1,1,STAINED_GLASS:10)
Block(2,1,1,STAINED_GLASS:10)
Block(3,1,1,STAINED_GLASS:15)
Block(-3,1,2,STAINED_GLASS:15)
Block(-2,1,2,STAINED_GLASS:10)
Block(-1,1,2,STAINED_GLASS:10)
Block(0,1,2,SEA_LANTERN:0)
Block(1,1,2,SEA_LANTERN:0)
Block(2,1,2,STAINED_GLASS:10)
Block(3,1,2,STAINED_GLASS:15)
Block(4,1,2,STAINED_GLASS:15)
Block(-3,1,3,STAINED_GLASS:15)
Block(-2,1,3,STAINED_GLASS:15)
Block(-1,1,3,STAINED_GLASS:10)
Block(0,1,3,STAINED_GLASS:10)
Block(1,1,3,STAINED_GLASS:10)
Block(2,1,3,STAINED_GLASS:10)
Block(3,1,3,STAINED_GLASS:10)
Block(4,1,3,STAINED_GLASS:15)
Block(-3,1,4,STAINED_GLASS:15)
Block(-2,1,4,STAINED_GLASS:15)
Block(-1,1,4,PURPLE_GLAZED_TERRACOTTA:2)
Block(0,1,4,STAINED_GLASS:10)
Block(1,1,4,STAINED_GLASS:10)
Block(2,1,4,STAINED_GLASS:10)
Block(3,1,4,STAINED_GLASS:15)
Block(-2,1,5,STAINED_GLASS:15)
Block(-1,1,5,STAINED_GLASS:15)
Block(0,1,5,STAINED_GLASS:15)
Block(1,1,5,STAINED_GLASS:15)
Block(3,1,5,STAINED_GLASS:15)
Block(0,2,-2,STAINED_GLASS:15)
Block(3,2,-2,STAINED_GLASS:15)
Block(-3,2,-1,STAINED_GLASS:15)
Block(-2,2,-1,STAINED_GLASS:10)
Block(-1,2,-1,STAINED_GLASS:10)
Block(0,2,-1,STAINED_GLASS:15)
Block(1,2,-1,STAINED_GLASS:10)
Block(2,2,-1,STAINED_GLASS:10)
Block(3,2,-1,STAINED_GLASS:15)
Block(-3,2,0,STAINED_GLASS:15)
Block(-2,2,0,STAINED_GLASS:15)
Block(-1,2,0,STAINED_GLASS:10)
Block(0,2,0,STAINED_GLASS:10)
Block(1,2,0,SEA_LANTERN:0)
Block(2,2,0,STAINED_GLASS:10)
Block(3,2,0,STAINED_GLASS:15)
Block(-2,2,1,STAINED_GLASS:10)
Block(-1,2,1,STAINED_GLASS:10)
Block(0,2,1,SEA_LANTERN:0)
Block(1,2,1,SEA_LANTERN:0)
Block(2,2,1,STAINED_GLASS:10)
Block(3,2,1,STAINED_GLASS:15)
Block(-3,2,2,STAINED_GLASS:15)
Block(-2,2,2,STAINED_GLASS:10)
Block(-1,2,2,STAINED_GLASS:10)
Block(0,2,2,SEA_LANTERN:0)
Block(1,2,2,SEA_LANTERN:0)
Block(2,2,2,STAINED_GLASS:14)
Block(3,2,2,STAINED_GLASS:15)
Block(4,2,2,STAINED_GLASS:15)
Block(-3,2,3,STAINED_GLASS:15)
Block(-2,2,3,STAINED_GLASS:15)
Block(-1,2,3,PURPLE_GLAZED_TERRACOTTA:2)
Block(0,2,3,STAINED_GLASS:10)
Block(1,2,3,STAINED_GLASS:14)
Block(2,2,3,STAINED_GLASS:14)
Block(3,2,3,STAINED_GLASS:14)
Block(-2,2,4,STAINED_GLASS:15)
Block(-1,2,4,STAINED_GLASS:15)
Block(0,2,4,STAINED_GLASS:15)
Block(1,2,4,STAINED_GLASS:15)
Block(2,2,4,STAINED_GLASS:15)
Block(3,2,4,STAINED_GLASS:15)
Block(2,3,-3,STAINED_GLASS:15)
Block(-2,3,-2,STAINED_GLASS:15)
Block(-1,3,-2,STAINED_GLASS:15)
Block(0,3,-2,STAINED_GLASS:10)
Block(1,3,-2,STAINED_GLASS:15)
Block(2,3,-2,STAINED_GLASS:15)
Block(3,3,-2,STAINED_GLASS:15)
Block(-3,3,-1,STAINED_GLASS:15)
Block(-2,3,-1,STAINED_GLASS:10)
Block(-1,3,-1,STAINED_GLASS:10)
Block(0,3,-1,STAINED_GLASS:10)
Block(1,3,-1,STAINED_GLASS:10)
Block(2,3,-1,STAINED_GLASS:10)
Block(3,3,-1,STAINED_GLASS:15)
Block(-3,3,0,STAINED_GLASS:15)
Block(-2,3,0,STAINED_GLASS:15)
Block(-1,3,0,STAINED_GLASS:10)
Block(0,3,0,SEA_LANTERN:0)
Block(1,3,0,SEA_LANTERN:0)
Block(2,3,0,STAINED_GLASS:10)
Block(3,3,0,STAINED_GLASS:15)
Block(4,3,0,STAINED_GLASS:15)
Block(-3,3,1,STAINED_GLASS:15)
Block(-2,3,1,STAINED_GLASS:10)
Block(-1,3,1,STAINED_GLASS:10)
Block(0,3,1,SEA_LANTERN:0)
Block(1,3,1,SEA_LANTERN:0)
Block(2,3,1,STAINED_GLASS:10)
Block(3,3,1,STAINED_GLASS:15)
Block(-3,3,2,STAINED_GLASS:15)
Block(-2,3,2,STAINED_GLASS:10)
Block(-1,3,2,STAINED_GLASS:10)
Block(0,3,2,PURPLE_GLAZED_TERRACOTTA:2)
Block(1,3,2,STAINED_GLASS:10)
Block(2,3,2,STAINED_GLASS:14)
Block(3,3,2,STAINED_GLASS:15)
Block(4,3,2,STAINED_GLASS:15)
Block(-3,3,3,STAINED_GLASS:15)
Block(-2,3,3,STAINED_GLASS:15)
Block(-1,3,3,STAINED_GLASS:10)
Block(0,3,3,STAINED_GLASS:15)
Block(1,3,3,STAINED_GLASS:15)
Block(2,3,3,STAINED_GLASS:14)
Block(3,3,3,STAINED_GLASS:15)
Block(0,3,4,STAINED_GLASS:15)
Block(1,3,4,STAINED_GLASS:15)
Block(-3,4,-3,STAINED_GLASS:15)
Block(-1,4,-3,STAINED_GLASS:15)
Block(0,4,-3,STAINED_GLASS:15)
Block(1,4,-3,STAINED_GLASS:15)
Block(2,4,-3,STAINED_GLASS:10)
Block(3,4,-3,STAINED_GLASS:15)
Block(-2,4,-2,STAINED_GLASS:10)
Block(-1,4,-2,STAINED_GLASS:10)
Block(0,4,-2,STAINED_GLASS:10)
Block(1,4,-2,STAINED_GLASS:10)
Block(2,4,-2,STAINED_GLASS:10)
Block(3,4,-2,STAINED_GLASS:15)
Block(-3,4,-1,STAINED_GLASS:15)
Block(-2,4,-1,STAINED_GLASS:10)
Block(-1,4,-1,SEA_LANTERN:0)
Block(0,4,-1,STAINED_GLASS:10)
Block(1,4,-1,SEA_LANTERN:0)
Block(2,4,-1,STAINED_GLASS:10)
Block(3,4,-1,STAINED_GLASS:15)
Block(-3,4,0,STAINED_GLASS:15)
Block(-2,4,0,STAINED_GLASS:15)
Block(-1,4,0,STAINED_GLASS:10)
Block(0,4,0,SEA_LANTERN:0)
Block(1,4,0,SEA_LANTERN:0)
Block(2,4,0,STAINED_GLASS:10)
Block(3,4,0,STAINED_GLASS:15)
Block(4,4,0,STAINED_GLASS:15)
Block(-3,4,1,STAINED_GLASS:15)
Block(-2,4,1,STAINED_GLASS:10)
Block(-1,4,1,PURPLE_GLAZED_TERRACOTTA:2)
Block(0,4,1,PURPLE_GLAZED_TERRACOTTA:2)
Block(1,4,1,SEA_LANTERN:0)
Block(2,4,1,STAINED_GLASS:10)
Block(3,4,1,STAINED_GLASS:15)
Block(-2,4,2,PURPLE_GLAZED_TERRACOTTA:2)
Block(-1,4,2,PURPLE_GLAZED_TERRACOTTA:2)
Block(0,4,2,PURPLE_GLAZED_TERRACOTTA:2)
Block(1,4,2,PURPLE_GLAZED_TERRACOTTA:2)
Block(2,4,2,STAINED_GLASS:14)
Block(3,4,2,STAINED_GLASS:15)
Block(-3,4,3,STAINED_GLASS:15)
Block(-2,4,3,STAINED_GLASS:15)
Block(-1,4,3,STAINED_GLASS:15)
Block(0,4,3,STAINED_GLASS:15)
Block(1,4,3,STAINED_GLASS:15)
Block(2,4,3,STAINED_GLASS:15)
Block(-1,5,-4,STAINED_GLASS:15)
Block(1,5,-4,STAINED_GLASS:15)
Block(2,5,-4,STAINED_GLASS:15)
Block(-3,5,-3,STAINED_GLASS:15)
Block(-2,5,-3,STAINED_GLASS:15)
Block(-1,5,-3,STAINED_GLASS:10)
Block(0,5,-3,STAINED_GLASS:10)
Block(1,5,-3,STAINED_GLASS:10)
Block(2,5,-3,STAINED_GLASS:10)
Block(3,5,-3,STAINED_GLASS:15)
Block(-2,5,-2,STAINED_GLASS:10)
Block(-1,5,-2,STAINED_GLASS:10)
Block(0,5,-2,SEA_LANTERN:0)
Block(1,5,-2,STAINED_GLASS:10)
Block(2,5,-2,STAINED_GLASS:10)
Block(3,5,-2,STAINED_GLASS:15)
Block(-3,5,-1,STAINED_GLASS:15)
Block(-2,5,-1,STAINED_GLASS:10)
Block(-1,5,-1,SEA_LANTERN:0)
Block(0,5,-1,SEA_LANTERN:0)
Block(1,5,-1,SEA_LANTERN:0)
Block(2,5,-1,STAINED_GLASS:10)
Block(3,5,-1,STAINED_GLASS:15)
Block(4,5,-1,STAINED_GLASS:15)
Block(-3,5,0,STAINED_GLASS:15)
Block(-2,5,0,STAINED_GLASS:15)
Block(-1,5,0,STAINED_GLASS:10)
Block(0,5,0,SEA_LANTERN:0)
Block(1,5,0,PURPLE_GLAZED_TERRACOTTA:2)
Block(2,5,0,STAINED_GLASS:10)
Block(3,5,0,STAINED_GLASS:15)
Block(4,5,0,STAINED_GLASS:15)
Block(-3,5,1,STAINED_GLASS:15)
Block(-2,5,1,PURPLE_GLAZED_TERRACOTTA:2)
Block(-1,5,1,PURPLE_GLAZED_TERRACOTTA:2)
Block(0,5,1,PURPLE_GLAZED_TERRACOTTA:2)
Block(1,5,1,PURPLE_GLAZED_TERRACOTTA:2)
Block(2,5,1,STAINED_GLASS:14)
Block(3,5,1,STAINED_GLASS:15)
Block(-2,5,2,STAINED_GLASS:15)
Block(-1,5,2,PURPLE_GLAZED_TERRACOTTA:2)
Block(0,5,2,STAINED_GLASS:15)
Block(1,5,2,STAINED_GLASS:15)
Block(2,5,2,STAINED_GLASS:15)
Block(1,6,-5,STAINED_GLASS:15)
Block(-3,6,-4,STAINED_GLASS:15)
Block(-2,6,-4,STAINED_GLASS:15)
Block(-1,6,-4,STAINED_GLASS:10)
Block(0,6,-4,STAINED_GLASS:15)
Block(1,6,-4,STAINED_GLASS:10)
Block(2,6,-4,STAINED_GLASS:10)
Block(-3,6,-3,STAINED_GLASS:15)
Block(-2,6,-3,STAINED_GLASS:10)
Block(-1,6,-3,STAINED_GLASS:10)
Block(0,6,-3,STAINED_GLASS:10)
Block(1,6,-3,STAINED_GLASS:10)
Block(2,6,-3,STAINED_GLASS:10)
Block(3,6,-3,STAINED_GLASS:15)
Block(-2,6,-2,STAINED_GLASS:10)
Block(-1,6,-2,SEA_LANTERN:0)
Block(0,6,-2,SEA_LANTERN:0)
Block(1,6,-2,SEA_LANTERN:0)
Block(2,6,-2,STAINED_GLASS:10)
Block(3,6,-2,STAINED_GLASS:15)
Block(-3,6,-1,STAINED_GLASS:15)
Block(-2,6,-1,STAINED_GLASS:10)
Block(-1,6,-1,SEA_LANTERN:0)
Block(0,6,-1,SEA_LANTERN:0)
Block(1,6,-1,SEA_LANTERN:0)
Block(2,6,-1,STAINED_GLASS:10)
Block(3,6,-1,STAINED_GLASS:15)
Block(4,6,-1,STAINED_GLASS:15)
Block(-3,6,0,STAINED_GLASS:15)
Block(-2,6,0,STAINED_GLASS:15)
Block(-1,6,0,STAINED_GLASS:10)
Block(0,6,0,STAINED_GLASS:10)
Block(1,6,0,STAINED_GLASS:10)
Block(2,6,0,STAINED_GLASS:10)
Block(3,6,0,STAINED_GLASS:15)
Block(-2,6,1,STAINED_GLASS:10)
Block(-1,6,1,STAINED_GLASS:15)
Block(0,6,1,STAINED_GLASS:15)
Block(1,6,1,STAINED_GLASS:10)
Block(2,6,1,STAINED_GLASS:15)
Block(3,6,1,STAINED_GLASS:15)
Block(-1,6,2,STAINED_GLASS:15)
Block(0,6,2,STAINED_GLASS:15)
Block(1,6,2,STAINED_GLASS:15)
Block(-2,7,-5,STAINED_GLASS:15)
Block(-1,7,-5,STAINED_GLASS:15)
Block(0,7,-5,STAINED_GLASS:15)
Block(1,7,-5,STAINED_GLASS:10)
Block(2,7,-5,STAINED_GLASS:15)
Block(-3,7,-4,STAINED_GLASS:15)
Block(-2,7,-4,STAINED_GLASS:10)
Block(-1,7,-4,STAINED_GLASS:10)
Block(0,7,-4,STAINED_GLASS:10)
Block(1,7,-4,STAINED_GLASS:10)
Block(2,7,-4,STAINED_GLASS:10)
Block(-3,7,-3,STAINED_GLASS:15)
Block(-2,7,-3,STAINED_GLASS:10)
Block(-1,7,-3,STAINED_GLASS:10)
Block(0,7,-3,SEA_LANTERN:0)
Block(1,7,-3,STAINED_GLASS:10)
Block(2,7,-3,STAINED_GLASS:10)
Block(3,7,-3,STAINED_GLASS:15)
Block(-4,7,-2,STAINED_GLASS:15)
Block(-3,7,-2,STAINED_GLASS:15)
Block(-2,7,-2,STAINED_GLASS:10)
Block(-1,7,-2,SEA_LANTERN:0)
Block(0,7,-2,SEA_LANTERN:0)
Block(1,7,-2,SEA_LANTERN:0)
Block(2,7,-2,STAINED_GLASS:10)
Block(3,7,-2,STAINED_GLASS:15)
Block(-3,7,-1,STAINED_GLASS:15)
Block(-2,7,-1,STAINED_GLASS:10)
Block(-1,7,-1,PURPLE_GLAZED_TERRACOTTA:2)
Block(0,7,-1,SEA_LANTERN:0)
Block(1,7,-1,STAINED_GLASS:10)
Block(2,7,-1,STAINED_GLASS:14)
Block(3,7,-1,STAINED_GLASS:15)
Block(4,7,-1,STAINED_GLASS:15)
Block(-3,7,0,STAINED_GLASS:15)
Block(-2,7,0,STAINED_GLASS:15)
Block(-1,7,0,PURPLE_GLAZED_TERRACOTTA:2)
Block(0,7,0,PURPLE_GLAZED_TERRACOTTA:2)
Block(1,7,0,STAINED_GLASS:15)
Block(2,7,0,STAINED_GLASS:14)
Block(3,7,0,STAINED_GLASS:15)
Block(-2,7,1,STAINED_GLASS:15)
Block(0,7,1,STAINED_GLASS:15)
Block(1,7,1,STAINED_GLASS:15)
Block(-3,8,-6,STAINED_GLASS:15)
Block(-2,8,-6,STAINED_GLASS:15)
Block(0,8,-6,STAINED_GLASS:15)
Block(1,8,-6,STAINED_GLASS:15)
Block(2,8,-6,STAINED_GLASS:15)
Block(3,8,-6,STAINED_GLASS:15)
Block(-3,8,-5,STAINED_GLASS:15)
Block(-2,8,-5,STAINED_GLASS:10)
Block(-1,8,-5,STAINED_GLASS:10)
Block(0,8,-5,STAINED_GLASS:10)
Block(1,8,-5,STAINED_GLASS:10)
Block(2,8,-5,STAINED_GLASS:10)
Block(-3,8,-4,STAINED_GLASS:15)
Block(-2,8,-4,STAINED_GLASS:10)
Block(-1,8,-4,SEA_LANTERN:0)
Block(0,8,-4,STAINED_GLASS:10)
Block(1,8,-4,SEA_LANTERN:0)
Block(2,8,-4,STAINED_GLASS:10)
Block(-3,8,-3,STAINED_GLASS:15)
Block(-2,8,-3,STAINED_GLASS:10)
Block(-1,8,-3,STAINED_GLASS:10)
Block(0,8,-3,SEA_LANTERN:0)
Block(1,8,-3,STAINED_GLASS:10)
Block(2,8,-3,STAINED_GLASS:10)
Block(3,8,-3,STAINED_GLASS:15)
Block(-4,8,-2,STAINED_GLASS:15)
Block(-3,8,-2,STAINED_GLASS:15)
Block(-2,8,-2,STAINED_GLASS:10)
Block(-1,8,-2,SEA_LANTERN:0)
Block(0,8,-2,STAINED_GLASS:10)
Block(1,8,-2,SEA_LANTERN:0)
Block(2,8,-2,STAINED_GLASS:10)
Block(3,8,-2,STAINED_GLASS:15)
Block(-3,8,-1,STAINED_GLASS:15)
Block(-2,8,-1,PURPLE_GLAZED_TERRACOTTA:2)
Block(-1,8,-1,PURPLE_GLAZED_TERRACOTTA:2)
Block(0,8,-1,STAINED_GLASS:10)
Block(1,8,-1,PURPLE_GLAZED_TERRACOTTA:2)
Block(2,8,-1,STAINED_GLASS:14)
Block(3,8,-1,STAINED_GLASS:15)
Block(-3,8,0,STAINED_GLASS:15)
Block(-2,8,0,STAINED_GLASS:15)
Block(-1,8,0,STAINED_GLASS:15)
Block(0,8,0,STAINED_GLASS:15)
Block(1,8,0,STAINED_GLASS:15)
Block(2,8,0,STAINED_GLASS:15)
Block(3,8,0,STAINED_GLASS:15)
Block(1,8,1,STAINED_GLASS:15)
Block(-1,9,-7,STAINED_GLASS:15)
Block(2,9,-7,STAINED_GLASS:15)
Block(-3,9,-6,STAINED_GLASS:15)
Block(-2,9,-6,STAINED_GLASS:10)
Block(-1,9,-6,STAINED_GLASS:15)
Block(0,9,-6,STAINED_GLASS:10)
Block(1,9,-6,STAINED_GLASS:10)
Block(2,9,-6,STAINED_GLASS:15)
Block(3,9,-6,STAINED_GLASS:15)
Block(-3,9,-5,STAINED_GLASS:15)
Block(-2,9,-5,STAINED_GLASS:10)
Block(-1,9,-5,STAINED_GLASS:10)
Block(0,9,-5,STAINED_GLASS:10)
Block(1,9,-5,STAINED_GLASS:10)
Block(2,9,-5,STAINED_GLASS:10)
Block(-3,9,-4,STAINED_GLASS:15)
Block(-2,9,-4,STAINED_GLASS:10)
Block(-1,9,-4,SEA_LANTERN:0)
Block(0,9,-4,SEA_LANTERN:0)
Block(1,9,-4,SEA_LANTERN:0)
Block(2,9,-4,STAINED_GLASS:10)
Block(3,9,-4,STAINED_GLASS:15)
Block(4,9,-4,STAINED_GLASS:15)
Block(-3,9,-3,STAINED_GLASS:15)
Block(-2,9,-3,STAINED_GLASS:10)
Block(-1,9,-3,STAINED_GLASS:10)
Block(0,9,-3,SEA_LANTERN:0)
Block(1,9,-3,STAINED_GLASS:10)
Block(2,9,-3,STAINED_GLASS:14)
Block(3,9,-3,STAINED_GLASS:15)
Block(-4,9,-2,STAINED_GLASS:15)
Block(-3,9,-2,STAINED_GLASS:15)
Block(-2,9,-2,STAINED_GLASS:10)
Block(-1,9,-2,STAINED_GLASS:10)
Block(0,9,-2,PURPLE_GLAZED_TERRACOTTA:2)
Block(1,9,-2,PURPLE_GLAZED_TERRACOTTA:2)
Block(2,9,-2,STAINED_GLASS:14)
Block(3,9,-2,STAINED_GLASS:15)
Block(-3,9,-1,STAINED_GLASS:15)
Block(-2,9,-1,STAINED_GLASS:15)
Block(-1,9,-1,STAINED_GLASS:15)
Block(0,9,-1,PURPLE_GLAZED_TERRACOTTA:2)
Block(1,9,-1,STAINED_GLASS:15)
Block(2,9,-1,STAINED_GLASS:15)
Block(0,9,0,STAINED_GLASS:15)
Block(-3,10,-7,STAINED_GLASS:15)
Block(-2,10,-7,STAINED_GLASS:15)
Block(-1,10,-7,STAINED_GLASS:10)
Block(0,10,-7,STAINED_GLASS:15)
Block(1,10,-7,STAINED_GLASS:15)
Block(2,10,-7,STAINED_GLASS:10)
Block(-3,10,-6,STAINED_GLASS:15)
Block(-2,10,-6,STAINED_GLASS:10)
Block(-1,10,-6,STAINED_GLASS:10)
Block(0,10,-6,STAINED_GLASS:10)
Block(1,10,-6,STAINED_GLASS:10)
Block(2,10,-6,STAINED_GLASS:15)
Block(3,10,-6,STAINED_GLASS:15)
Block(-3,10,-5,STAINED_GLASS:15)
Block(-2,10,-5,STAINED_GLASS:10)
Block(-1,10,-5,SEA_LANTERN:0)
Block(0,10,-5,SEA_LANTERN:0)
Block(1,10,-5,STAINED_GLASS:10)
Block(2,10,-5,STAINED_GLASS:10)
Block(-3,10,-4,STAINED_GLASS:15)
Block(-2,10,-4,STAINED_GLASS:10)
Block(-1,10,-4,SEA_LANTERN:0)
Block(0,10,-4,SEA_LANTERN:0)
Block(1,10,-4,SEA_LANTERN:0)
Block(2,10,-4,STAINED_GLASS:14)
Block(3,10,-4,STAINED_GLASS:15)
Block(4,10,-4,STAINED_GLASS:15)
Block(-3,10,-3,STAINED_GLASS:15)
Block(-2,10,-3,STAINED_GLASS:10)
Block(-1,10,-3,STAINED_GLASS:10)
Block(0,10,-3,STAINED_GLASS:10)
Block(1,10,-3,STAINED_GLASS:14)
Block(2,10,-3,PURPLE_GLAZED_TERRACOTTA:2)
Block(3,10,-3,STAINED_GLASS:15)
Block(-2,10,-2,STAINED_GLASS:10)
Block(-1,10,-2,PURPLE_GLAZED_TERRACOTTA:2)
Block(0,10,-2,STAINED_GLASS:15)
Block(1,10,-2,PURPLE_GLAZED_TERRACOTTA:2)
Block(2,10,-2,PURPLE_GLAZED_TERRACOTTA:2)
Block(3,10,-2,STAINED_GLASS:15)
Block(-3,10,-1,STAINED_GLASS:15)
Block(-1,10,-1,STAINED_GLASS:15)
Block(0,10,-1,STAINED_GLASS:15)
Block(1,10,-1,STAINED_GLASS:15)
Block(-3,11,-8,STAINED_GLASS:15)
Block(-1,11,-8,STAINED_GLASS:15)
Block(0,11,-8,STAINED_GLASS:15)
Block(1,11,-8,STAINED_GLASS:15)
Block(2,11,-8,STAINED_GLASS:15)
Block(-3,11,-7,STAINED_GLASS:15)
Block(-2,11,-7,STAINED_GLASS:10)
Block(-1,11,-7,STAINED_GLASS:10)
Block(0,11,-7,STAINED_GLASS:10)
Block(1,11,-7,STAINED_GLASS:10)
Block(2,11,-7,STAINED_GLASS:10)
Block(-3,11,-6,STAINED_GLASS:15)
Block(-2,11,-6,STAINED_GLASS:10)
Block(-1,11,-6,STAINED_GLASS:10)
Block(0,11,-6,SEA_LANTERN:0)
Block(1,11,-6,STAINED_GLASS:10)
Block(2,11,-6,STAINED_GLASS:15)
Block(3,11,-6,STAINED_GLASS:15)
Block(-4,11,-5,STAINED_GLASS:15)
Block(-3,11,-5,STAINED_GLASS:15)
Block(-2,11,-5,STAINED_GLASS:10)
Block(-1,11,-5,SEA_LANTERN:0)
Block(0,11,-5,SEA_LANTERN:0)
Block(1,11,-5,STAINED_GLASS:10)
Block(2,11,-5,STAINED_GLASS:10)
Block(3,11,-5,STAINED_GLASS:15)
Block(-3,11,-4,STAINED_GLASS:15)
Block(-2,11,-4,STAINED_GLASS:10)
Block(-1,11,-4,STAINED_GLASS:10)
Block(0,11,-4,SEA_LANTERN:0)
Block(1,11,-4,STAINED_GLASS:10)
Block(2,11,-4,STAINED_GLASS:14)
Block(3,11,-4,STAINED_GLASS:15)
Block(4,11,-4,STAINED_GLASS:15)
Block(-3,11,-3,STAINED_GLASS:15)
Block(-2,11,-3,STAINED_GLASS:10)
Block(-1,11,-3,STAINED_GLASS:10)
Block(0,11,-3,STAINED_GLASS:10)
Block(1,11,-3,STAINED_GLASS:14)
Block(2,11,-3,STAINED_GLASS:15)
Block(3,11,-3,STAINED_GLASS:15)
Block(-2,11,-2,STAINED_GLASS:15)
Block(-1,11,-2,STAINED_GLASS:15)
Block(0,11,-2,STAINED_GLASS:15)
Block(1,11,-2,STAINED_GLASS:15)
Block(2,11,-2,STAINED_GLASS:15)
Block(0,11,-1,STAINED_GLASS:15)
Block(-2,12,-9,STAINED_GLASS:15)
Block(1,12,-9,STAINED_GLASS:15)
Block(2,12,-9,STAINED_GLASS:15)
Block(-3,12,-8,STAINED_GLASS:10)
Block(-2,12,-8,STAINED_GLASS:15)
Block(-1,12,-8,STAINED_GLASS:10)
Block(0,12,-8,STAINED_GLASS:10)
Block(1,12,-8,STAINED_GLASS:10)
Block(2,12,-8,STAINED_GLASS:10)
Block(-3,12,-7,STAINED_GLASS:15)
Block(-2,12,-7,STAINED_GLASS:10)
Block(-1,12,-7,SEA_LANTERN:0)
Block(0,12,-7,STAINED_GLASS:10)
Block(1,12,-7,STAINED_GLASS:10)
Block(2,12,-7,STAINED_GLASS:10)
Block(-3,12,-6,STAINED_GLASS:15)
Block(-2,12,-6,STAINED_GLASS:10)
Block(-1,12,-6,SEA_LANTERN:0)
Block(0,12,-6,SEA_LANTERN:0)
Block(1,12,-6,STAINED_GLASS:14)
Block(2,12,-6,STAINED_GLASS:15)
Block(3,12,-6,STAINED_GLASS:15)
Block(-4,12,-5,STAINED_GLASS:15)
Block(-3,12,-5,STAINED_GLASS:15)
Block(-2,12,-5,STAINED_GLASS:10)
Block(-1,12,-5,SEA_LANTERN:0)
Block(0,12,-5,SEA_LANTERN:0)
Block(1,12,-5,STAINED_GLASS:14)
Block(2,12,-5,STAINED_GLASS:14)
Block(3,12,-5,STAINED_GLASS:15)
Block(-3,12,-4,STAINED_GLASS:15)
Block(-2,12,-4,STAINED_GLASS:10)
Block(-1,12,-4,STAINED_GLASS:10)
Block(0,12,-4,STAINED_GLASS:14)
Block(1,12,-4,STAINED_GLASS:14)
Block(2,12,-4,STAINED_GLASS:14)
Block(-3,12,-3,STAINED_GLASS:15)
Block(-2,12,-3,STAINED_GLASS:10)
Block(-1,12,-3,STAINED_GLASS:15)
Block(0,12,-3,STAINED_GLASS:15)
Block(1,12,-3,STAINED_GLASS:15)
Block(3,12,-3,STAINED_GLASS:15)
Block(-1,12,-2,STAINED_GLASS:15)
Block(1,12,-2,STAINED_GLASS:15)
Block(0,13,-10,STAINED_GLASS:15)
Block(-3,13,-9,STAINED_GLASS:15)
Block(-2,13,-9,STAINED_GLASS:10)
Block(-1,13,-9,STAINED_GLASS:15)
Block(0,13,-9,STAINED_GLASS:15)
Block(1,13,-9,STAINED_GLASS:10)
Block(2,13,-9,STAINED_GLASS:15)
Block(-3,13,-8,STAINED_GLASS:10)
Block(-2,13,-8,STAINED_GLASS:10)
Block(-1,13,-8,STAINED_GLASS:10)
Block(0,13,-8,STAINED_GLASS:10)
Block(1,13,-8,STAINED_GLASS:10)
Block(2,13,-8,STAINED_GLASS:10)
Block(-3,13,-7,STAINED_GLASS:15)
Block(-2,13,-7,STAINED_GLASS:10)
Block(-1,13,-7,SEA_LANTERN:0)
Block(0,13,-7,SEA_LANTERN:0)
Block(1,13,-7,STAINED_GLASS:10)
Block(2,13,-7,STAINED_GLASS:10)
Block(3,13,-7,STAINED_GLASS:15)
Block(-4,13,-6,STAINED_GLASS:15)
Block(-3,13,-6,STAINED_GLASS:15)
Block(-2,13,-6,STAINED_GLASS:10)
Block(-1,13,-6,SEA_LANTERN:0)
Block(0,13,-6,SEA_LANTERN:0)
Block(1,13,-6,STAINED_GLASS:14)
Block(2,13,-6,STAINED_GLASS:15)
Block(3,13,-6,STAINED_GLASS:15)
Block(-4,13,-5,STAINED_GLASS:15)
Block(-3,13,-5,STAINED_GLASS:15)
Block(-2,13,-5,STAINED_GLASS:10)
Block(-1,13,-5,STAINED_GLASS:10)
Block(0,13,-5,STAINED_GLASS:14)
Block(1,13,-5,STAINED_GLASS:14)
Block(2,13,-5,STAINED_GLASS:14)
Block(3,13,-5,STAINED_GLASS:15)
Block(-3,13,-4,STAINED_GLASS:15)
Block(-2,13,-4,STAINED_GLASS:10)
Block(-1,13,-4,STAINED_GLASS:15)
Block(0,13,-4,STAINED_GLASS:14)
Block(1,13,-4,STAINED_GLASS:15)
Block(2,13,-4,STAINED_GLASS:15)
Block(-2,13,-3,STAINED_GLASS:15)
Block(0,13,-3,STAINED_GLASS:15)
Block(-3,14,-10,STAINED_GLASS:15)
Block(-2,14,-10,STAINED_GLASS:15)
Block(-1,14,-10,STAINED_GLASS:15)
Block(0,14,-10,STAINED_GLASS:10)
Block(1,14,-10,STAINED_GLASS:15)
Block(2,14,-10,STAINED_GLASS:15)
Block(-3,14,-9,STAINED_GLASS:10)
Block(-2,14,-9,STAINED_GLASS:10)
Block(-1,14,-9,STAINED_GLASS:10)
Block(0,14,-9,STAINED_GLASS:10)
Block(1,14,-9,STAINED_GLASS:10)
Block(2,14,-9,STAINED_GLASS:15)
Block(-3,14,-8,STAINED_GLASS:10)
Block(-2,14,-8,STAINED_GLASS:10)
Block(-1,14,-8,SEA_LANTERN:0)
Block(0,14,-8,SEA_LANTERN:0)
Block(1,14,-8,STAINED_GLASS:10)
Block(2,14,-8,STAINED_GLASS:10)
Block(-3,14,-7,STAINED_GLASS:15)
Block(-2,14,-7,STAINED_GLASS:10)
Block(-1,14,-7,SEA_LANTERN:0)
Block(0,14,-7,SEA_LANTERN:0)
Block(1,14,-7,STAINED_GLASS:10)
Block(2,14,-7,STAINED_GLASS:14)
Block(3,14,-7,STAINED_GLASS:15)
Block(-4,14,-6,STAINED_GLASS:15)
Block(-3,14,-6,STAINED_GLASS:15)
Block(-2,14,-6,STAINED_GLASS:14)
Block(-1,14,-6,SEA_LANTERN:0)
Block(0,14,-6,STAINED_GLASS:14)
Block(1,14,-6,STAINED_GLASS:14)
Block(2,14,-6,STAINED_GLASS:15)
Block(3,14,-6,STAINED_GLASS:15)
Block(-3,14,-5,STAINED_GLASS:15)
Block(-2,14,-5,STAINED_GLASS:14)
Block(-1,14,-5,STAINED_GLASS:14)
Block(0,14,-5,STAINED_GLASS:14)
Block(1,14,-5,STAINED_GLASS:15)
Block(2,14,-5,STAINED_GLASS:14)
Block(-3,14,-4,STAINED_GLASS:15)
Block(-2,14,-4,STAINED_GLASS:15)
Block(-1,14,-4,STAINED_GLASS:15)
Block(0,14,-4,STAINED_GLASS:15)
Block(1,14,-4,STAINED_GLASS:15)
Block(-3,15,-11,STAINED_GLASS:15)
Block(0,15,-11,STAINED_GLASS:15)
Block(1,15,-11,STAINED_GLASS:15)
Block(2,15,-11,STAINED_GLASS:15)
Block(-3,15,-10,STAINED_GLASS:15)
Block(-2,15,-10,STAINED_GLASS:10)
Block(-1,15,-10,STAINED_GLASS:10)
Block(0,15,-10,STAINED_GLASS:10)
Block(1,15,-10,STAINED_GLASS:10)
Block(2,15,-10,STAINED_GLASS:15)
Block(-3,15,-9,STAINED_GLASS:10)
Block(-2,15,-9,STAINED_GLASS:10)
Block(-1,15,-9,STAINED_GLASS:10)
Block(0,15,-9,STAINED_GLASS:10)
Block(1,15,-9,STAINED_GLASS:10)
Block(2,15,-9,STAINED_GLASS:15)
Block(-4,15,-8,STAINED_GLASS:15)
Block(-3,15,-8,STAINED_GLASS:10)
Block(-2,15,-8,STAINED_GLASS:10)
Block(-1,15,-8,SEA_LANTERN:0)
Block(0,15,-8,SEA_LANTERN:0)
Block(1,15,-8,STAINED_GLASS:10)
Block(2,15,-8,STAINED_GLASS:10)
Block(3,15,-8,STAINED_GLASS:15)
Block(-4,15,-7,STAINED_GLASS:15)
Block(-3,15,-7,STAINED_GLASS:15)
Block(-2,15,-7,STAINED_GLASS:14)
Block(-1,15,-7,STAINED_GLASS:14)
Block(0,15,-7,SEA_LANTERN:0)
Block(1,15,-7,STAINED_GLASS:10)
Block(2,15,-7,STAINED_GLASS:14)
Block(3,15,-7,STAINED_GLASS:15)
Block(-4,15,-6,STAINED_GLASS:15)
Block(-3,15,-6,STAINED_GLASS:15)
Block(-2,15,-6,STAINED_GLASS:14)
Block(-1,15,-6,STAINED_GLASS:14)
Block(0,15,-6,STAINED_GLASS:14)
Block(1,15,-6,STAINED_GLASS:14)
Block(2,15,-6,STAINED_GLASS:15)
Block(3,15,-6,STAINED_GLASS:15)
Block(-3,15,-5,STAINED_GLASS:15)
Block(-2,15,-5,STAINED_GLASS:15)
Block(-1,15,-5,STAINED_GLASS:15)
Block(0,15,-5,STAINED_GLASS:15)
Block(2,15,-5,STAINED_GLASS:15)
Block(0,15,-4,STAINED_GLASS:15)
Block(2,16,-12,STAINED_GLASS:15)
Block(-4,16,-11,STAINED_GLASS:15)
Block(-3,16,-11,STAINED_GLASS:10)
Block(-2,16,-11,STAINED_GLASS:15)
Block(-1,16,-11,STAINED_GLASS:15)
Block(0,16,-11,STAINED_GLASS:10)
Block(1,16,-11,STAINED_GLASS:10)
Block(2,16,-11,STAINED_GLASS:10)
Block(-3,16,-10,STAINED_GLASS:15)
Block(-2,16,-10,STAINED_GLASS:10)
Block(-1,16,-10,STAINED_GLASS:10)
Block(0,16,-10,SEA_LANTERN:0)
Block(1,16,-10,STAINED_GLASS:10)
Block(2,16,-10,STAINED_GLASS:15)
Block(-3,16,-9,STAINED_GLASS:10)
Block(-2,16,-9,STAINED_GLASS:10)
Block(-1,16,-9,SEA_LANTERN:0)
Block(0,16,-9,SEA_LANTERN:0)
Block(1,16,-9,STAINED_GLASS:10)
Block(2,16,-9,STAINED_GLASS:15)
Block(-4,16,-8,STAINED_GLASS:15)
Block(-3,16,-8,STAINED_GLASS:14)
Block(-2,16,-8,STAINED_GLASS:10)
Block(-1,16,-8,SEA_LANTERN:0)
Block(0,16,-8,SEA_LANTERN:0)
Block(1,16,-8,STAINED_GLASS:14)
Block(2,16,-8,STAINED_GLASS:14)
Block(3,16,-8,STAINED_GLASS:15)
Block(-4,16,-7,STAINED_GLASS:15)
Block(-3,16,-7,STAINED_GLASS:15)
Block(-2,16,-7,STAINED_GLASS:14)
Block(-1,16,-7,PURPLE_GLAZED_TERRACOTTA:2)
Block(0,16,-7,PURPLE_GLAZED_TERRACOTTA:2)
Block(1,16,-7,PURPLE_GLAZED_TERRACOTTA:2)
Block(2,16,-7,PURPLE_GLAZED_TERRACOTTA:2)
Block(-3,16,-6,STAINED_GLASS:15)
Block(-2,16,-6,STAINED_GLASS:15)
Block(-1,16,-6,PURPLE_GLAZED_TERRACOTTA:2)
Block(0,16,-6,STAINED_GLASS:15)
Block(1,16,-6,STAINED_GLASS:15)
Block(2,16,-6,STAINED_GLASS:15)
Block(3,16,-6,STAINED_GLASS:15)
Block(-3,16,-5,STAINED_GLASS:15)
Block(-1,16,-5,STAINED_GLASS:15)
Block(0,16,-5,STAINED_GLASS:15)
Block(-3,17,-12,STAINED_GLASS:15)
Block(-2,17,-12,STAINED_GLASS:15)
Block(-1,17,-12,STAINED_GLASS:15)
Block(0,17,-12,STAINED_GLASS:15)
Block(1,17,-12,STAINED_GLASS:15)
Block(2,17,-12,STAINED_GLASS:15)
Block(-4,17,-11,STAINED_GLASS:15)
Block(-3,17,-11,STAINED_GLASS:10)
Block(-2,17,-11,STAINED_GLASS:10)
Block(-1,17,-11,STAINED_GLASS:10)
Block(0,17,-11,STAINED_GLASS:10)
Block(1,17,-11,STAINED_GLASS:10)
Block(2,17,-11,STAINED_GLASS:10)
Block(-3,17,-10,STAINED_GLASS:15)
Block(-2,17,-10,STAINED_GLASS:10)
Block(-1,17,-10,SEA_LANTERN:0)
Block(0,17,-10,SEA_LANTERN:0)
Block(1,17,-10,STAINED_GLASS:10)
Block(2,17,-10,STAINED_GLASS:15)
Block(3,17,-10,STAINED_GLASS:15)
Block(-4,17,-9,STAINED_GLASS:15)
Block(-3,17,-9,STAINED_GLASS:10)
Block(-2,17,-9,STAINED_GLASS:10)
Block(-1,17,-9,SEA_LANTERN:0)
Block(0,17,-9,SEA_LANTERN:0)
Block(1,17,-9,STAINED_GLASS:10)
Block(2,17,-9,STAINED_GLASS:15)
Block(3,17,-9,STAINED_GLASS:15)
Block(-4,17,-8,STAINED_GLASS:15)
Block(-3,17,-8,STAINED_GLASS:14)
Block(-2,17,-8,STAINED_GLASS:10)
Block(-1,17,-8,PURPLE_GLAZED_TERRACOTTA:2)
Block(0,17,-8,PURPLE_GLAZED_TERRACOTTA:2)
Block(1,17,-8,PURPLE_GLAZED_TERRACOTTA:2)
Block(2,17,-8,PURPLE_GLAZED_TERRACOTTA:2)
Block(3,17,-8,STAINED_GLASS:15)
Block(-4,17,-7,STAINED_GLASS:15)
Block(-3,17,-7,STAINED_GLASS:15)
Block(-2,17,-7,STAINED_GLASS:14)
Block(-1,17,-7,STAINED_GLASS:15)
Block(0,17,-7,PURPLE_GLAZED_TERRACOTTA:2)
Block(1,17,-7,PURPLE_GLAZED_TERRACOTTA:2)
Block(2,17,-7,STAINED_GLASS:15)
Block(-1,17,-6,STAINED_GLASS:15)
Block(0,17,-6,STAINED_GLASS:15)
Block(-4,18,-13,STAINED_GLASS:15)
Block(-2,18,-13,STAINED_GLASS:15)
Block(-1,18,-13,STAINED_GLASS:15)
Block(0,18,-13,STAINED_GLASS:15)
Block(1,18,-13,STAINED_GLASS:15)
Block(2,18,-13,STAINED_GLASS:15)
Block(-3,18,-12,STAINED_GLASS:10)
Block(-2,18,-12,STAINED_GLASS:10)
Block(-1,18,-12,STAINED_GLASS:10)
Block(0,18,-12,STAINED_GLASS:10)
Block(1,18,-12,STAINED_GLASS:10)
Block(2,18,-12,STAINED_GLASS:15)
Block(-4,18,-11,STAINED_GLASS:15)
Block(-3,18,-11,STAINED_GLASS:10)
Block(-2,18,-11,STAINED_GLASS:10)
Block(-1,18,-11,STAINED_GLASS:10)
Block(0,18,-11,SEA_LANTERN:0)
Block(1,18,-11,STAINED_GLASS:10)
Block(2,18,-11,STAINED_GLASS:10)
Block(-3,18,-10,STAINED_GLASS:15)
Block(-2,18,-10,STAINED_GLASS:10)
Block(-1,18,-10,SEA_LANTERN:0)
Block(0,18,-10,SEA_LANTERN:0)
Block(1,18,-10,STAINED_GLASS:10)
Block(2,18,-10,STAINED_GLASS:15)
Block(3,18,-10,STAINED_GLASS:15)
Block(-4,18,-9,STAINED_GLASS:15)
Block(-3,18,-9,STAINED_GLASS:14)
Block(-2,18,-9,STAINED_GLASS:14)
Block(-1,18,-9,SEA_LANTERN:0)
Block(0,18,-9,SEA_LANTERN:0)
Block(1,18,-9,STAINED_GLASS:10)
Block(2,18,-9,STAINED_GLASS:15)
Block(3,18,-9,STAINED_GLASS:15)
Block(-3,18,-8,STAINED_GLASS:14)
Block(-2,18,-8,STAINED_GLASS:14)
Block(-1,18,-8,STAINED_GLASS:14)
Block(0,18,-8,PURPLE_GLAZED_TERRACOTTA:2)
Block(1,18,-8,STAINED_GLASS:14)
Block(2,18,-8,STAINED_GLASS:14)
Block(-3,18,-7,STAINED_GLASS:15)
Block(-2,18,-7,STAINED_GLASS:15)
Block(-1,18,-7,STAINED_GLASS:15)
Block(0,18,-7,STAINED_GLASS:15)
Block(1,18,-7,STAINED_GLASS:15)
Block(-1,18,-6,STAINED_GLASS:15)
Block(0,19,-14,STAINED_GLASS:15)
Block(1,19,-14,STAINED_GLASS:15)
Block(-4,19,-13,STAINED_GLASS:15)
Block(-3,19,-13,STAINED_GLASS:15)
Block(-2,19,-13,STAINED_GLASS:10)
Block(-1,19,-13,STAINED_GLASS:10)
Block(0,19,-13,STAINED_GLASS:10)
Block(1,19,-13,STAINED_GLASS:10)
Block(2,19,-13,STAINED_GLASS:15)
Block(-3,19,-12,STAINED_GLASS:10)
Block(-2,19,-12,STAINED_GLASS:10)
Block(-1,19,-12,STAINED_GLASS:10)
Block(0,19,-12,STAINED_GLASS:10)
Block(1,19,-12,STAINED_GLASS:10)
Block(2,19,-12,STAINED_GLASS:15)
Block(-4,19,-11,STAINED_GLASS:15)
Block(-3,19,-11,STAINED_GLASS:10)
Block(-2,19,-11,STAINED_GLASS:10)
Block(-1,19,-11,SEA_LANTERN:0)
Block(0,19,-11,SEA_LANTERN:0)
Block(1,19,-11,STAINED_GLASS:10)
Block(2,19,-11,STAINED_GLASS:10)
Block(3,19,-11,STAINED_GLASS:15)
Block(-4,19,-10,STAINED_GLASS:15)
Block(-3,19,-10,STAINED_GLASS:15)
Block(-2,19,-10,PURPLE_GLAZED_TERRACOTTA:2)
Block(-1,19,-10,SEA_LANTERN:0)
Block(0,19,-10,STAINED_GLASS:10)
Block(1,19,-10,STAINED_GLASS:10)
Block(2,19,-10,STAINED_GLASS:15)
Block(3,19,-10,STAINED_GLASS:15)
Block(-4,19,-9,STAINED_GLASS:15)
Block(-3,19,-9,STAINED_GLASS:14)
Block(-2,19,-9,STAINED_GLASS:14)
Block(-1,19,-9,STAINED_GLASS:10)
Block(0,19,-9,STAINED_GLASS:10)
Block(1,19,-9,STAINED_GLASS:10)
Block(2,19,-9,STAINED_GLASS:15)
Block(3,19,-9,STAINED_GLASS:15)
Block(-3,19,-8,STAINED_GLASS:15)
Block(-2,19,-8,STAINED_GLASS:14)
Block(-1,19,-8,STAINED_GLASS:15)
Block(0,19,-8,STAINED_GLASS:15)
Block(1,19,-8,STAINED_GLASS:15)
Block(2,19,-8,STAINED_GLASS:15)
Block(0,19,-7,STAINED_GLASS:15)
Block(-4,20,-14,STAINED_GLASS:15)
Block(-3,20,-14,STAINED_GLASS:15)
Block(-2,20,-14,STAINED_GLASS:15)
Block(-1,20,-14,STAINED_GLASS:15)
Block(0,20,-14,STAINED_GLASS:10)
Block(1,20,-14,STAINED_GLASS:10)
Block(2,20,-14,STAINED_GLASS:15)
Block(-4,20,-13,STAINED_GLASS:15)
Block(-3,20,-13,STAINED_GLASS:10)
Block(-2,20,-13,STAINED_GLASS:10)
Block(-1,20,-13,STAINED_GLASS:10)
Block(0,20,-13,STAINED_GLASS:10)
Block(1,20,-13,STAINED_GLASS:10)
Block(2,20,-13,STAINED_GLASS:15)
Block(-3,20,-12,STAINED_GLASS:10)
Block(-2,20,-12,SEA_LANTERN:0)
Block(-1,20,-12,SEA_LANTERN:0)
Block(0,20,-12,SEA_LANTERN:0)
Block(1,20,-12,STAINED_GLASS:10)
Block(2,20,-12,STAINED_GLASS:15)
Block(-4,20,-11,STAINED_GLASS:15)
Block(-3,20,-11,PURPLE_GLAZED_TERRACOTTA:2)
Block(-2,20,-11,PURPLE_GLAZED_TERRACOTTA:2)
Block(-1,20,-11,SEA_LANTERN:0)
Block(0,20,-11,SEA_LANTERN:0)
Block(1,20,-11,STAINED_GLASS:10)
Block(2,20,-11,STAINED_GLASS:10)
Block(3,20,-11,STAINED_GLASS:15)
Block(-4,20,-10,STAINED_GLASS:15)
Block(-3,20,-10,STAINED_GLASS:15)
Block(-2,20,-10,PURPLE_GLAZED_TERRACOTTA:2)
Block(-1,20,-10,PURPLE_GLAZED_TERRACOTTA:2)
Block(0,20,-10,STAINED_GLASS:10)
Block(1,20,-10,STAINED_GLASS:10)
Block(2,20,-10,STAINED_GLASS:15)
Block(-3,20,-9,PURPLE_GLAZED_TERRACOTTA:2)
Block(-2,20,-9,STAINED_GLASS:15)
Block(-1,20,-9,PURPLE_GLAZED_TERRACOTTA:2)
Block(0,20,-9,STAINED_GLASS:10)
Block(1,20,-9,STAINED_GLASS:15)
Block(2,20,-9,STAINED_GLASS:15)
Block(-2,20,-8,STAINED_GLASS:15)
Block(-1,20,-8,STAINED_GLASS:15)
Block(0,20,-8,STAINED_GLASS:15)
Block(-3,21,-15,STAINED_GLASS:15)
Block(-2,21,-15,STAINED_GLASS:15)
Block(-1,21,-15,STAINED_GLASS:15)
Block(0,21,-15,STAINED_GLASS:15)
Block(1,21,-15,STAINED_GLASS:15)
Block(-4,21,-14,STAINED_GLASS:15)
Block(-3,21,-14,STAINED_GLASS:10)
Block(-2,21,-14,STAINED_GLASS:10)
Block(-1,21,-14,STAINED_GLASS:10)
Block(0,21,-14,STAINED_GLASS:10)
Block(1,21,-14,STAINED_GLASS:10)
Block(2,21,-14,STAINED_GLASS:15)
Block(-4,21,-13,STAINED_GLASS:15)
Block(-3,21,-13,STAINED_GLASS:10)
Block(-2,21,-13,STAINED_GLASS:10)
Block(-1,21,-13,SEA_LANTERN:0)
Block(0,21,-13,STAINED_GLASS:10)
Block(1,21,-13,STAINED_GLASS:10)
Block(2,21,-13,STAINED_GLASS:15)
Block(-4,21,-12,STAINED_GLASS:15)
Block(-3,21,-12,STAINED_GLASS:10)
Block(-2,21,-12,SEA_LANTERN:0)
Block(-1,21,-12,SEA_LANTERN:0)
Block(0,21,-12,SEA_LANTERN:0)
Block(1,21,-12,STAINED_GLASS:10)
Block(2,21,-12,STAINED_GLASS:15)
Block(-4,21,-11,STAINED_GLASS:15)
Block(-3,21,-11,PURPLE_GLAZED_TERRACOTTA:2)
Block(-2,21,-11,PURPLE_GLAZED_TERRACOTTA:2)
Block(-1,21,-11,SEA_LANTERN:0)
Block(0,21,-11,STAINED_GLASS:10)
Block(1,21,-11,STAINED_GLASS:10)
Block(2,21,-11,STAINED_GLASS:10)
Block(3,21,-11,STAINED_GLASS:15)
Block(-4,21,-10,STAINED_GLASS:15)
Block(-3,21,-10,STAINED_GLASS:15)
Block(-2,21,-10,PURPLE_GLAZED_TERRACOTTA:2)
Block(-1,21,-10,PURPLE_GLAZED_TERRACOTTA:2)
Block(0,21,-10,STAINED_GLASS:15)
Block(1,21,-10,STAINED_GLASS:10)
Block(2,21,-10,STAINED_GLASS:15)
Block(-3,21,-9,STAINED_GLASS:15)
Block(-1,21,-9,STAINED_GLASS:15)
Block(0,21,-9,STAINED_GLASS:15)
Block(-3,22,-15,STAINED_GLASS:15)
Block(-2,22,-15,STAINED_GLASS:15)
Block(-1,22,-15,STAINED_GLASS:15)
Block(0,22,-15,STAINED_GLASS:15)
Block(1,22,-15,STAINED_GLASS:15)
Block(-4,22,-14,STAINED_GLASS:15)
Block(-3,22,-14,STAINED_GLASS:10)
Block(-2,22,-14,STAINED_GLASS:10)
Block(-1,22,-14,STAINED_GLASS:10)
Block(0,22,-14,SEA_LANTERN:0)
Block(1,22,-14,STAINED_GLASS:10)
Block(2,22,-14,STAINED_GLASS:15)
Block(-4,22,-13,STAINED_GLASS:15)
Block(-3,22,-13,STAINED_GLASS:10)
Block(-2,22,-13,STAINED_GLASS:10)
Block(-1,22,-13,SEA_LANTERN:0)
Block(0,22,-13,STAINED_GLASS:10)
Block(1,22,-13,STAINED_GLASS:10)
Block(2,22,-13,STAINED_GLASS:15)
Block(-4,22,-12,STAINED_GLASS:15)
Block(-3,22,-12,STAINED_GLASS:14)
Block(-2,22,-12,SEA_LANTERN:0)
Block(-1,22,-12,SEA_LANTERN:0)
Block(0,22,-12,SEA_LANTERN:0)
Block(1,22,-12,STAINED_GLASS:10)
Block(2,22,-12,STAINED_GLASS:15)
Block(-4,22,-11,STAINED_GLASS:15)
Block(-3,22,-11,PURPLE_GLAZED_TERRACOTTA:2)
Block(-2,22,-11,PURPLE_GLAZED_TERRACOTTA:2)
Block(-1,22,-11,PURPLE_GLAZED_TERRACOTTA:2)
Block(0,22,-11,PURPLE_GLAZED_TERRACOTTA:2)
Block(1,22,-11,STAINED_GLASS:10)
Block(2,22,-11,STAINED_GLASS:10)
Block(-3,22,-10,STAINED_GLASS:15)
Block(-2,22,-10,STAINED_GLASS:15)
Block(-1,22,-10,STAINED_GLASS:15)
Block(0,22,-10,STAINED_GLASS:15)
Block(1,22,-10,STAINED_GLASS:15)
Block(2,22,-10,STAINED_GLASS:15)
Block(-1,22,-9,STAINED_GLASS:15)
Block(0,22,-9,STAINED_GLASS:15)
Block(-1,23,-16,STAINED_GLASS:15)
Block(0,23,-16,STAINED_GLASS:15)
Block(-3,23,-15,STAINED_GLASS:15)
Block(-2,23,-15,STAINED_GLASS:10)
Block(-1,23,-15,STAINED_GLASS:10)
Block(0,23,-15,STAINED_GLASS:10)
Block(1,23,-15,STAINED_GLASS:15)
Block(-4,23,-14,STAINED_GLASS:15)
Block(-3,23,-14,STAINED_GLASS:10)
Block(-2,23,-14,STAINED_GLASS:10)
Block(-1,23,-14,SEA_LANTERN:0)
Block(0,23,-14,SEA_LANTERN:0)
Block(1,23,-14,STAINED_GLASS:10)
Block(2,23,-14,STAINED_GLASS:15)
Block(-4,23,-13,STAINED_GLASS:15)
Block(-3,23,-13,STAINED_GLASS:10)
Block(-2,23,-13,STAINED_GLASS:10)
Block(-1,23,-13,SEA_LANTERN:0)
Block(0,23,-13,STAINED_GLASS:10)
Block(1,23,-13,STAINED_GLASS:10)
Block(2,23,-13,STAINED_GLASS:15)
Block(-3,23,-12,PURPLE_GLAZED_TERRACOTTA:2)
Block(-2,23,-12,PURPLE_GLAZED_TERRACOTTA:2)
Block(-1,23,-12,PURPLE_GLAZED_TERRACOTTA:2)
Block(0,23,-12,PURPLE_GLAZED_TERRACOTTA:2)
Block(1,23,-12,STAINED_GLASS:10)
Block(2,23,-12,STAINED_GLASS:15)
Block(-4,23,-11,STAINED_GLASS:15)
Block(-3,23,-11,STAINED_GLASS:15)
Block(-2,23,-11,PURPLE_GLAZED_TERRACOTTA:2)
Block(-1,23,-11,PURPLE_GLAZED_TERRACOTTA:2)
Block(0,23,-11,STAINED_GLASS:15)
Block(1,23,-11,STAINED_GLASS:15)
Block(2,23,-11,STAINED_GLASS:15)
Block(-1,23,-10,STAINED_GLASS:15)
Block(-1,24,-16,STAINED_GLASS:15)
Block(0,24,-16,STAINED_GLASS:15)
Block(-3,24,-15,STAINED_GLASS:15)
Block(-2,24,-15,STAINED_GLASS:10)
Block(-1,24,-15,STAINED_GLASS:10)
Block(0,24,-15,STAINED_GLASS:10)
Block(1,24,-15,STAINED_GLASS:15)
Block(-3,24,-14,STAINED_GLASS:10)
Block(-2,24,-14,STAINED_GLASS:10)
Block(-1,24,-14,SEA_LANTERN:0)
Block(0,24,-14,STAINED_GLASS:10)
Block(1,24,-14,STAINED_GLASS:15)
Block(-3,24,-13,STAINED_GLASS:15)
Block(-2,24,-13,PURPLE_GLAZED_TERRACOTTA:2)
Block(-1,24,-13,PURPLE_GLAZED_TERRACOTTA:2)
Block(0,24,-13,STAINED_GLASS:10)
Block(1,24,-13,STAINED_GLASS:10)
Block(-3,24,-12,STAINED_GLASS:15)
Block(-2,24,-12,PURPLE_GLAZED_TERRACOTTA:2)
Block(-1,24,-12,PURPLE_GLAZED_TERRACOTTA:2)
Block(0,24,-12,PURPLE_GLAZED_TERRACOTTA:2)
Block(1,24,-12,STAINED_GLASS:15)
Block(-2,24,-11,STAINED_GLASS:15)
Block(-1,24,-11,STAINED_GLASS:15)
Block(0,24,-11,STAINED_GLASS:15)
Block(-2,25,-16,STAINED_GLASS:15)
Block(-1,25,-16,STAINED_GLASS:15)
Block(0,25,-16,STAINED_GLASS:15)
Block(-3,25,-15,STAINED_GLASS:15)
Block(-2,25,-15,STAINED_GLASS:10)
Block(-1,25,-15,STAINED_GLASS:10)
Block(0,25,-15,STAINED_GLASS:10)
Block(1,25,-15,STAINED_GLASS:15)
Block(-3,25,-14,STAINED_GLASS:15)
Block(-2,25,-14,STAINED_GLASS:15)
Block(-1,25,-14,STAINED_GLASS:10)
Block(0,25,-14,PURPLE_GLAZED_TERRACOTTA:2)
Block(1,25,-14,STAINED_GLASS:15)
Block(-3,25,-13,STAINED_GLASS:15)
Block(-2,25,-13,STAINED_GLASS:15)
Block(-1,25,-13,PURPLE_GLAZED_TERRACOTTA:2)
Block(0,25,-13,STAINED_GLASS:15)
Block(1,25,-13,STAINED_GLASS:15)
Block(-2,25,-12,STAINED_GLASS:15)
Block(-1,25,-12,STAINED_GLASS:15)
Block(0,25,-12,STAINED_GLASS:15)
Block(-1,25,-11,STAINED_GLASS:15)
Block(-2,26,-16,STAINED_GLASS:15)
Block(-1,26,-16,STAINED_GLASS:10)
Block(0,26,-16,STAINED_GLASS:15)
Block(-2,26,-15,STAINED_GLASS:15)
Block(-1,26,-15,STAINED_GLASS:15)
Block(0,26,-15,STAINED_GLASS:15)
Block(-3,26,-14,STAINED_GLASS:15)
Block(-2,26,-14,STAINED_GLASS:15)
Block(-1,26,-14,STAINED_GLASS:10)
Block(0,26,-14,STAINED_GLASS:15)
Block(-1,26,-13,STAINED_GLASS:15)
Block(-2,26,-12,STAINED_GLASS:15)
Block(-1,26,-12,STAINED_GLASS:15)
Block(0,26,-12,STAINED_GLASS:15)
Block(-2,27,-16,STAINED_GLASS:15)
Block(-1,27,-16,STAINED_GLASS:10)
Block(0,27,-16,STAINED_GLASS:15)
Block(-2,27,-15,STAINED_GLASS:15)
Block(-1,27,-15,STAINED_GLASS:15)
Block(0,27,-15,STAINED_GLASS:15)
Block(-1,27,-14,STAINED_GLASS:15)
Block(0,27,-14,STAINED_GLASS:15)
Block(-1,28,-17,STAINED_GLASS:15)
Block(-2,28,-16,STAINED_GLASS:15)
Block(-1,28,-16,STAINED_GLASS:15)
Block(-2,28,-15,STAINED_GLASS:15)
Block(-1,28,-15,STAINED_GLASS:15)
Block(0,28,-15,STAINED_GLASS:15)
Block(-1,29,-17,STAINED_GLASS:15)
Block(-2,29,-16,STAINED_GLASS:15)
Block(-1,30,-17,STAINED_GLASS:15)

#######################################################################
# +-----------------------------------------------------------------+ #
# |                            BO3 checks                           | #
# +-----------------------------------------------------------------+ #
#######################################################################

# Require a condition at a certain location in order for the BO3 to be spawned.
# BlockCheck(x,y,z,BlockName[,BlockName[,...]]) - one of the blocks must be at the location
# BlockCheckNot(x,y,z,BlockName[,BlockName[,...]]) - all the blocks must not be at the location
# LightCheck(x,y,z,minLightLevel,maxLightLevel) - light must be between min and max (inclusive)

# You can use "Solid" as a BlockName for matching all solid blocks or "All" to match all blocks that aren't air.

# Examples:
#   BlockCheck(0,-1,0,GRASS,DIRT)  Require grass or dirt just below the object
#   BlockCheck(0,-1,0,Solid)       Require any solid block just below the object
#   BlockCheck(0,-1,0,WOOL)        Require any type of wool just below the object
#   BlockCheck(0,-1,0,WOOL:0)      Require white wool just below the object
#   BlockCheckNot(0,-1,0,WOOL:0)   Require that there is no white wool below the object
#   LightCheck(0,0,0,0,1)          Require almost complete darkness just below the object

#######################################################################
# +-----------------------------------------------------------------+ #
# |                             Branches                            | #
# +-----------------------------------------------------------------+ #
#######################################################################

# Branches are objects that will spawn when this object spawns when it is used in
# the CustomStructure resource. Branches can also have branches, making complex
# structures possible. See the wiki for more details.

# Regular Branches spawn each branch with an independent chance of spawning.
# Branch(x,y,z,branchName,rotation,chance[,anotherBranchName,rotation,chance[,...]][IndividualChance])
# branchName - name of the object to spawn.
# rotation - NORTH, SOUTH, EAST or WEST.
# IndividualChance - The chance each branch has to spawn, assumed to be 100 when left blank

# Weighted Branches spawn branches with a dependent chance of spawning.
# WeightedBranch(x,y,z,branchName,rotation,chance[,anotherBranchName,rotation,chance[,...]][MaxChanceOutOf])
# MaxChanceOutOf - The chance all branches have to spawn out of, assumed to be 100 when left blank
