#######################################################################
# +-----------------------------------------------------------------+ #
# |                            BO3 object                           | #
# +-----------------------------------------------------------------+ #
#######################################################################

# This is the config file of a custom object.
# If you add this object correctly to your BiomeConfigs, it will spawn in the world.

# This is the creator of this BO3 object
Author: BO3 BulkEdit (by LanToaster)

# A short description of this BO3 object
Description: Bo3 spikes created by NLBlackEagle

# The BO3 version, don't change this! It can be used by external applications to do a version check.
Version: 3

# The settings mode, WriteAll, WriteWithoutComments or WriteDisable. See WorldConfig.
SettingsMode: WriteDisable


#######################################################################
# +-----------------------------------------------------------------+ #
# |                          Main settings                          | #
# +-----------------------------------------------------------------+ #
#######################################################################

# This needs to be set to true to spawn the object in the Tree and Sapling resources.
Tree: false

# The frequency of the BO3 from 1 to 200. Tries this many times to spawn this BO3 when using the CustomObject(...) resource.

Frequency: 100

# The rarity of the BO3 from 0 to 100. Each spawn attempt has rarity% chance to succeed when using the CustomObject(...) resource.

Rarity: 100

# If you set this to true, the BO3 will be placed with a random rotation.
RotateRandomly: true

# The spawn height of the BO3 - randomY, highestBlock or highestSolidBlock.
SpawnHeight: randomY

# The height limits for the BO3.
MinHeight: 0

MaxHeight: 256

# Objects can have other objects attacthed to it: branches. Branches can also
# have branches attached to it, which can also have branches, etc. This is the
# maximum branch depth for this objects.
MaxBranchDepth: 10

# When spawned with the UseWorld keyword, this BO3 should NOT spawn in the following biomes.
# If you writer.write the BO3 name directly in the BiomeConfigs, this will be ignored.
ExcludedBiomes: All


#######################################################################
# +-----------------------------------------------------------------+ #
# |                      Source block settings                      | #
# +-----------------------------------------------------------------+ #
#######################################################################

# The block(s) the BO3 should spawn in.
SourceBlocks: AIR

# The maximum percentage of the BO3 that can be outside the SourceBlock.
# The BO3 won't be placed on a location with more blocks outside the SourceBlock than this percentage.
MaxPercentageOutsideSourceBlock: 100

# What to do when a block is about to be placed outside the SourceBlock? (dontPlace, placeAnyway)
OutsideSourceBlock: placeAnyway


#######################################################################
# +-----------------------------------------------------------------+ #
# |                              Blocks                             | #
# +-----------------------------------------------------------------+ #
#######################################################################

# All the blocks used in the BO3 are listed here. Possible blocks:
# Block(x,y,z,id[.data][,nbtfile.nbt)
# RandomBlock(x,y,z,id[:data][,nbtfile.nbt],chance[,id[:data][,nbtfile.nbt],chance[,...]])
# So RandomBlock(0,0,0,CHEST,chest.nbt,50,CHEST,anotherchest.nbt,100) will spawn a chest at
# the BO3 origin, and give it a 50% chance to have the contents of chest.nbt, or, if that
# fails, a 100% percent chance to have the contents of anotherchest.nbt.
Block(1,0,-2,STAINED_GLASS:15)
Block(2,0,-2,STAINED_GLASS:15)
Block(-1,0,-1,STAINED_GLASS:15)
Block(0,0,-1,STAINED_GLASS:15)
Block(1,0,-1,STAINED_GLASS:15)
Block(-2,0,0,STAINED_GLASS:15)
Block(0,1,-3,STAINED_GLASS:15)
Block(1,1,-3,STAINED_GLASS:15)
Block(2,1,-3,STAINED_GLASS:15)
Block(-1,1,-2,STAINED_GLASS:15)
Block(0,1,-2,STAINED_GLASS:15)
Block(1,1,-2,STAINED_GLASS:11)
Block(2,1,-2,STAINED_GLASS:11)
Block(-2,1,-1,STAINED_GLASS:15)
Block(-1,1,-1,STAINED_GLASS:15)
Block(0,1,-1,STAINED_GLASS:15)
Block(1,1,-1,SEA_LANTERN:0)
Block(2,1,-1,STAINED_GLASS:6)
Block(-2,1,0,STAINED_GLASS:15)
Block(-1,1,0,STAINED_GLASS:15)
Block(0,1,0,SEA_LANTERN:0)
Block(1,1,0,SEA_LANTERN:0)
Block(2,1,0,SEA_LANTERN:0)
Block(3,1,0,STAINED_GLASS:15)
Block(-1,1,1,STAINED_GLASS:15)
Block(0,1,1,SEA_LANTERN:0)
Block(-1,2,-3,STAINED_GLASS:15)
Block(0,2,-3,STAINED_GLASS:15)
Block(1,2,-3,STAINED_GLASS:11)
Block(2,2,-3,STAINED_GLASS:11)
Block(-2,2,-2,STAINED_GLASS:15)
Block(-1,2,-2,STAINED_GLASS:15)
Block(0,2,-2,STAINED_GLASS:15)
Block(1,2,-2,STAINED_GLASS:6)
Block(2,2,-2,STAINED_GLASS:11)
Block(-2,2,-1,STAINED_GLASS:15)
Block(-1,2,-1,STAINED_GLASS:15)
Block(0,2,-1,SEA_LANTERN:0)
Block(1,2,-1,SEA_LANTERN:0)
Block(2,2,-1,SEA_LANTERN:0)
Block(-2,2,0,STAINED_GLASS:15)
Block(-1,2,0,STAINED_GLASS:15)
Block(0,2,0,SEA_LANTERN:0)
Block(1,2,0,SEA_LANTERN:0)
Block(2,2,0,SEA_LANTERN:0)
Block(3,2,0,STAINED_GLASS:11)
Block(-1,2,1,STAINED_GLASS:15)
Block(0,2,1,SEA_LANTERN:0)
Block(1,2,1,SEA_LANTERN:0)
Block(2,2,1,STAINED_GLASS:15)
Block(3,2,1,STAINED_GLASS:15)
Block(0,2,2,STAINED_GLASS:15)
Block(1,2,2,STAINED_GLASS:15)
Block(2,2,2,STAINED_GLASS:15)
Block(3,2,2,STAINED_GLASS:15)
Block(0,2,3,STAINED_GLASS:15)
Block(0,3,-4,STAINED_GLASS:15)
Block(1,3,-4,STAINED_GLASS:15)
Block(-3,3,-3,STAINED_GLASS:15)
Block(-2,3,-3,STAINED_GLASS:15)
Block(-1,3,-3,STAINED_GLASS:15)
Block(0,3,-3,SEA_LANTERN:0)
Block(1,3,-3,STAINED_GLASS:11)
Block(2,3,-3,STAINED_GLASS:11)
Block(-2,3,-2,STAINED_GLASS:15)
Block(-1,3,-2,STAINED_GLASS:6)
Block(0,3,-2,SEA_LANTERN:0)
Block(1,3,-2,STAINED_GLASS:6)
Block(2,3,-2,STAINED_GLASS:11)
Block(-2,3,-1,STAINED_GLASS:15)
Block(-1,3,-1,STAINED_GLASS:15)
Block(0,3,-1,SEA_LANTERN:0)
Block(1,3,-1,SEA_LANTERN:0)
Block(2,3,-1,SEA_LANTERN:0)
Block(-2,3,0,STAINED_GLASS:15)
Block(-1,3,0,STAINED_GLASS:15)
Block(0,3,0,SEA_LANTERN:0)
Block(1,3,0,SEA_LANTERN:0)
Block(2,3,0,SEA_LANTERN:0)
Block(3,3,0,STAINED_GLASS:11)
Block(-1,3,1,STAINED_GLASS:15)
Block(0,3,1,STAINED_GLASS:6)
Block(1,3,1,STAINED_GLASS:15)
Block(2,3,1,STAINED_GLASS:15)
Block(0,3,2,STAINED_GLASS:15)
Block(1,3,2,STAINED_GLASS:15)
Block(0,4,-5,STAINED_GLASS:15)
Block(-1,4,-4,STAINED_GLASS:15)
Block(0,4,-4,STAINED_GLASS:15)
Block(1,4,-4,STAINED_GLASS:15)
Block(-3,4,-3,STAINED_GLASS:11)
Block(-2,4,-3,STAINED_GLASS:15)
Block(-1,4,-3,SEA_LANTERN:0)
Block(0,4,-3,SEA_LANTERN:0)
Block(1,4,-3,STAINED_GLASS:15)
Block(2,4,-3,STAINED_GLASS:15)
Block(-2,4,-2,STAINED_GLASS:11)
Block(-1,4,-2,STAINED_GLASS:6)
Block(0,4,-2,SEA_LANTERN:0)
Block(1,4,-2,SEA_LANTERN:0)
Block(2,4,-2,STAINED_GLASS:11)
Block(-2,4,-1,STAINED_GLASS:15)
Block(-1,4,-1,STAINED_GLASS:11)
Block(0,4,-1,SEA_LANTERN:0)
Block(1,4,-1,SEA_LANTERN:0)
Block(2,4,-1,STAINED_GLASS:6)
Block(-2,4,0,STAINED_GLASS:11)
Block(-1,4,0,STAINED_GLASS:11)
Block(0,4,0,SEA_LANTERN:0)
Block(1,4,0,STAINED_GLASS:15)
Block(2,4,0,STAINED_GLASS:15)
Block(3,4,0,STAINED_GLASS:15)
Block(-1,4,1,STAINED_GLASS:15)
Block(0,4,1,STAINED_GLASS:15)
Block(1,4,1,STAINED_GLASS:15)
Block(0,4,2,STAINED_GLASS:15)
Block(0,5,-6,STAINED_GLASS:15)
Block(-1,5,-5,STAINED_GLASS:15)
Block(0,5,-5,STAINED_GLASS:15)
Block(-3,5,-4,STAINED_GLASS:11)
Block(-2,5,-4,STAINED_GLASS:11)
Block(-1,5,-4,STAINED_GLASS:15)
Block(0,5,-4,SEA_LANTERN:0)
Block(1,5,-4,STAINED_GLASS:15)
Block(-3,5,-3,STAINED_GLASS:11)
Block(-2,5,-3,STAINED_GLASS:6)
Block(-1,5,-3,SEA_LANTERN:0)
Block(0,5,-3,SEA_LANTERN:0)
Block(1,5,-3,STAINED_GLASS:11)
Block(2,5,-3,STAINED_GLASS:11)
Block(-2,5,-2,STAINED_GLASS:11)
Block(-1,5,-2,SEA_LANTERN:0)
Block(0,5,-2,SEA_LANTERN:0)
Block(1,5,-2,SEA_LANTERN:0)
Block(2,5,-2,STAINED_GLASS:11)
Block(-2,5,-1,STAINED_GLASS:11)
Block(-1,5,-1,STAINED_GLASS:11)
Block(0,5,-1,SEA_LANTERN:0)
Block(1,5,-1,SEA_LANTERN:0)
Block(2,5,-1,STAINED_GLASS:11)
Block(-2,5,0,STAINED_GLASS:11)
Block(-1,5,0,STAINED_GLASS:11)
Block(0,5,0,STAINED_GLASS:15)
Block(1,5,0,STAINED_GLASS:15)
Block(2,5,0,STAINED_GLASS:15)
Block(0,5,1,STAINED_GLASS:15)
Block(-1,6,-6,STAINED_GLASS:15)
Block(0,6,-6,STAINED_GLASS:15)
Block(-3,6,-5,STAINED_GLASS:11)
Block(-2,6,-5,STAINED_GLASS:15)
Block(-1,6,-5,STAINED_GLASS:15)
Block(0,6,-5,STAINED_GLASS:6)
Block(-3,6,-4,STAINED_GLASS:11)
Block(-2,6,-4,STAINED_GLASS:15)
Block(-1,6,-4,SEA_LANTERN:0)
Block(0,6,-4,SEA_LANTERN:0)
Block(1,6,-4,STAINED_GLASS:15)
Block(-3,6,-3,STAINED_GLASS:11)
Block(-2,6,-3,STAINED_GLASS:6)
Block(-1,6,-3,SEA_LANTERN:0)
Block(0,6,-3,SEA_LANTERN:0)
Block(1,6,-3,STAINED_GLASS:11)
Block(2,6,-3,STAINED_GLASS:11)
Block(-2,6,-2,STAINED_GLASS:11)
Block(-1,6,-2,SEA_LANTERN:0)
Block(0,6,-2,SEA_LANTERN:0)
Block(1,6,-2,STAINED_GLASS:6)
Block(2,6,-2,STAINED_GLASS:11)
Block(-2,6,-1,STAINED_GLASS:15)
Block(-1,6,-1,STAINED_GLASS:11)
Block(0,6,-1,SEA_LANTERN:0)
Block(1,6,-1,STAINED_GLASS:11)
Block(2,6,-1,STAINED_GLASS:11)
Block(-2,6,0,STAINED_GLASS:11)
Block(-1,6,0,STAINED_GLASS:11)
Block(0,6,0,STAINED_GLASS:15)
Block(0,7,-7,STAINED_GLASS:15)
Block(-3,7,-6,STAINED_GLASS:11)
Block(-2,7,-6,STAINED_GLASS:15)
Block(-1,7,-6,STAINED_GLASS:15)
Block(0,7,-6,STAINED_GLASS:15)
Block(-4,7,-5,STAINED_GLASS:11)
Block(-3,7,-5,STAINED_GLASS:11)
Block(-2,7,-5,STAINED_GLASS:15)
Block(-1,7,-5,SEA_LANTERN:0)
Block(0,7,-5,STAINED_GLASS:6)
Block(-3,7,-4,STAINED_GLASS:11)
Block(-2,7,-4,STAINED_GLASS:6)
Block(-1,7,-4,SEA_LANTERN:0)
Block(0,7,-4,SEA_LANTERN:0)
Block(1,7,-4,STAINED_GLASS:15)
Block(-3,7,-3,STAINED_GLASS:15)
Block(-2,7,-3,SEA_LANTERN:0)
Block(-1,7,-3,SEA_LANTERN:0)
Block(0,7,-3,SEA_LANTERN:0)
Block(1,7,-3,STAINED_GLASS:11)
Block(2,7,-3,STAINED_GLASS:11)
Block(-2,7,-2,STAINED_GLASS:15)
Block(-1,7,-2,STAINED_GLASS:6)
Block(0,7,-2,SEA_LANTERN:0)
Block(1,7,-2,STAINED_GLASS:11)
Block(-2,7,-1,STAINED_GLASS:15)
Block(-1,7,-1,STAINED_GLASS:15)
Block(0,7,-1,STAINED_GLASS:15)
Block(1,7,-1,STAINED_GLASS:11)
Block(-1,8,-7,STAINED_GLASS:15)
Block(0,8,-7,STAINED_GLASS:15)
Block(-4,8,-6,STAINED_GLASS:11)
Block(-3,8,-6,STAINED_GLASS:11)
Block(-2,8,-6,STAINED_GLASS:15)
Block(-1,8,-6,STAINED_GLASS:6)
Block(0,8,-6,STAINED_GLASS:15)
Block(-4,8,-5,STAINED_GLASS:11)
Block(-3,8,-5,STAINED_GLASS:11)
Block(-2,8,-5,SEA_LANTERN:0)
Block(-1,8,-5,SEA_LANTERN:0)
Block(0,8,-5,SEA_LANTERN:0)
Block(-3,8,-4,STAINED_GLASS:15)
Block(-2,8,-4,STAINED_GLASS:6)
Block(-1,8,-4,SEA_LANTERN:0)
Block(0,8,-4,SEA_LANTERN:0)
Block(1,8,-4,STAINED_GLASS:15)
Block(-3,8,-3,STAINED_GLASS:15)
Block(-2,8,-3,SEA_LANTERN:0)
Block(-1,8,-3,SEA_LANTERN:0)
Block(0,8,-3,STAINED_GLASS:11)
Block(1,8,-3,STAINED_GLASS:11)
Block(2,8,-3,STAINED_GLASS:11)
Block(-2,8,-2,STAINED_GLASS:15)
Block(-1,8,-2,STAINED_GLASS:15)
Block(0,8,-2,STAINED_GLASS:11)
Block(1,8,-2,STAINED_GLASS:11)
Block(-2,8,-1,STAINED_GLASS:15)
Block(-1,8,-1,STAINED_GLASS:15)
Block(0,8,-1,STAINED_GLASS:11)
Block(-2,9,-8,STAINED_GLASS:11)
Block(-1,9,-8,STAINED_GLASS:11)
Block(-3,9,-7,STAINED_GLASS:11)
Block(-2,9,-7,STAINED_GLASS:11)
Block(-1,9,-7,STAINED_GLASS:15)
Block(0,9,-7,STAINED_GLASS:15)
Block(-5,9,-6,STAINED_GLASS:11)
Block(-4,9,-6,STAINED_GLASS:11)
Block(-3,9,-6,STAINED_GLASS:6)
Block(-2,9,-6,SEA_LANTERN:0)
Block(-1,9,-6,STAINED_GLASS:6)
Block(0,9,-6,STAINED_GLASS:15)
Block(-4,9,-5,STAINED_GLASS:11)
Block(-3,9,-5,STAINED_GLASS:15)
Block(-2,9,-5,SEA_LANTERN:0)
Block(-1,9,-5,SEA_LANTERN:0)
Block(0,9,-5,SEA_LANTERN:0)
Block(-3,9,-4,STAINED_GLASS:15)
Block(-2,9,-4,SEA_LANTERN:0)
Block(-1,9,-4,SEA_LANTERN:0)
Block(0,9,-4,SEA_LANTERN:0)
Block(1,9,-4,STAINED_GLASS:15)
Block(-3,9,-3,STAINED_GLASS:15)
Block(-2,9,-3,STAINED_GLASS:6)
Block(-1,9,-3,STAINED_GLASS:11)
Block(0,9,-3,STAINED_GLASS:11)
Block(-2,9,-2,STAINED_GLASS:15)
Block(-1,9,-2,STAINED_GLASS:11)
Block(0,9,-2,STAINED_GLASS:11)
Block(-2,10,-9,STAINED_GLASS:11)
Block(-3,10,-8,STAINED_GLASS:11)
Block(-2,10,-8,STAINED_GLASS:11)
Block(-1,10,-8,STAINED_GLASS:11)
Block(-5,10,-7,STAINED_GLASS:11)
Block(-4,10,-7,STAINED_GLASS:11)
Block(-3,10,-7,STAINED_GLASS:11)
Block(-2,10,-7,STAINED_GLASS:11)
Block(-1,10,-7,STAINED_GLASS:6)
Block(0,10,-7,STAINED_GLASS:15)
Block(-5,10,-6,STAINED_GLASS:11)
Block(-4,10,-6,STAINED_GLASS:11)
Block(-3,10,-6,STAINED_GLASS:6)
Block(-2,10,-6,SEA_LANTERN:0)
Block(-1,10,-6,SEA_LANTERN:0)
Block(0,10,-6,STAINED_GLASS:15)
Block(-4,10,-5,STAINED_GLASS:15)
Block(-3,10,-5,STAINED_GLASS:15)
Block(-2,10,-5,SEA_LANTERN:0)
Block(-1,10,-5,SEA_LANTERN:0)
Block(0,10,-5,STAINED_GLASS:6)
Block(-3,10,-4,STAINED_GLASS:15)
Block(-2,10,-4,SEA_LANTERN:0)
Block(-1,10,-4,SEA_LANTERN:0)
Block(0,10,-4,STAINED_GLASS:11)
Block(1,10,-4,STAINED_GLASS:15)
Block(-3,10,-3,STAINED_GLASS:15)
Block(-2,10,-3,STAINED_GLASS:11)
Block(-1,10,-3,STAINED_GLASS:11)
Block(-2,10,-2,STAINED_GLASS:11)
Block(-3,11,-9,STAINED_GLASS:11)
Block(-2,11,-9,STAINED_GLASS:11)
Block(-5,11,-8,STAINED_GLASS:15)
Block(-4,11,-8,STAINED_GLASS:11)
Block(-3,11,-8,STAINED_GLASS:11)
Block(-2,11,-8,SEA_LANTERN:0)
Block(-1,11,-8,STAINED_GLASS:11)
Block(-5,11,-7,STAINED_GLASS:15)
Block(-4,11,-7,STAINED_GLASS:15)
Block(-3,11,-7,STAINED_GLASS:6)
Block(-2,11,-7,SEA_LANTERN:0)
Block(-1,11,-7,STAINED_GLASS:6)
Block(0,11,-7,STAINED_GLASS:15)
Block(-5,11,-6,STAINED_GLASS:15)
Block(-4,11,-6,STAINED_GLASS:15)
Block(-3,11,-6,SEA_LANTERN:0)
Block(-2,11,-6,SEA_LANTERN:0)
Block(-1,11,-6,SEA_LANTERN:0)
Block(0,11,-6,STAINED_GLASS:15)
Block(-4,11,-5,STAINED_GLASS:15)
Block(-3,11,-5,STAINED_GLASS:15)
Block(-2,11,-5,SEA_LANTERN:0)
Block(-1,11,-5,SEA_LANTERN:0)
Block(0,11,-5,STAINED_GLASS:11)
Block(-3,11,-4,STAINED_GLASS:15)
Block(-2,11,-4,STAINED_GLASS:6)
Block(-1,11,-4,STAINED_GLASS:11)
Block(0,11,-4,STAINED_GLASS:11)
Block(-2,11,-3,STAINED_GLASS:11)
Block(-2,12,-10,STAINED_GLASS:11)
Block(-5,12,-9,STAINED_GLASS:15)
Block(-4,12,-9,STAINED_GLASS:11)
Block(-3,12,-9,STAINED_GLASS:11)
Block(-2,12,-9,STAINED_GLASS:6)
Block(-5,12,-8,STAINED_GLASS:15)
Block(-4,12,-8,STAINED_GLASS:15)
Block(-3,12,-8,SEA_LANTERN:0)
Block(-2,12,-8,SEA_LANTERN:0)
Block(-1,12,-8,STAINED_GLASS:15)
Block(-5,12,-7,STAINED_GLASS:15)
Block(-4,12,-7,STAINED_GLASS:15)
Block(-3,12,-7,STAINED_GLASS:6)
Block(-2,12,-7,SEA_LANTERN:0)
Block(-1,12,-7,SEA_LANTERN:0)
Block(0,12,-7,STAINED_GLASS:15)
Block(-5,12,-6,STAINED_GLASS:15)
Block(-4,12,-6,STAINED_GLASS:15)
Block(-3,12,-6,SEA_LANTERN:0)
Block(-2,12,-6,SEA_LANTERN:0)
Block(-1,12,-6,STAINED_GLASS:6)
Block(0,12,-6,STAINED_GLASS:15)
Block(-4,12,-5,STAINED_GLASS:15)
Block(-3,12,-5,STAINED_GLASS:11)
Block(-2,12,-5,SEA_LANTERN:0)
Block(-1,12,-5,STAINED_GLASS:11)
Block(0,12,-5,STAINED_GLASS:11)
Block(-3,12,-4,STAINED_GLASS:15)
Block(-2,12,-4,STAINED_GLASS:11)
Block(-1,12,-4,STAINED_GLASS:11)
Block(-2,13,-11,STAINED_GLASS:11)
Block(-3,13,-10,STAINED_GLASS:11)
Block(-2,13,-10,STAINED_GLASS:15)
Block(-6,13,-9,STAINED_GLASS:15)
Block(-5,13,-9,STAINED_GLASS:15)
Block(-4,13,-9,STAINED_GLASS:15)
Block(-3,13,-9,SEA_LANTERN:0)
Block(-2,13,-9,STAINED_GLASS:6)
Block(-5,13,-8,STAINED_GLASS:15)
Block(-4,13,-8,STAINED_GLASS:6)
Block(-3,13,-8,SEA_LANTERN:0)
Block(-2,13,-8,SEA_LANTERN:0)
Block(-1,13,-8,STAINED_GLASS:15)
Block(-5,13,-7,STAINED_GLASS:15)
Block(-4,13,-7,STAINED_GLASS:15)
Block(-3,13,-7,SEA_LANTERN:0)
Block(-2,13,-7,SEA_LANTERN:0)
Block(-1,13,-7,SEA_LANTERN:0)
Block(0,13,-7,STAINED_GLASS:15)
Block(-5,13,-6,STAINED_GLASS:15)
Block(-4,13,-6,STAINED_GLASS:15)
Block(-3,13,-6,STAINED_GLASS:6)
Block(-2,13,-6,SEA_LANTERN:0)
Block(-1,13,-6,STAINED_GLASS:15)
Block(-4,13,-5,STAINED_GLASS:11)
Block(-3,13,-5,STAINED_GLASS:11)
Block(-2,13,-5,STAINED_GLASS:11)
Block(-1,13,-5,STAINED_GLASS:11)
Block(-2,13,-4,STAINED_GLASS:11)
Block(-3,14,-11,STAINED_GLASS:11)
Block(-2,14,-11,STAINED_GLASS:11)
Block(-6,14,-10,STAINED_GLASS:15)
Block(-5,14,-10,STAINED_GLASS:15)
Block(-4,14,-10,STAINED_GLASS:11)
Block(-3,14,-10,STAINED_GLASS:11)
Block(-2,14,-10,STAINED_GLASS:6)
Block(-6,14,-9,STAINED_GLASS:15)
Block(-5,14,-9,STAINED_GLASS:15)
Block(-4,14,-9,SEA_LANTERN:0)
Block(-3,14,-9,SEA_LANTERN:0)
Block(-2,14,-9,SEA_LANTERN:0)
Block(-5,14,-8,STAINED_GLASS:15)
Block(-4,14,-8,STAINED_GLASS:6)
Block(-3,14,-8,SEA_LANTERN:0)
Block(-2,14,-8,SEA_LANTERN:0)
Block(-1,14,-8,STAINED_GLASS:15)
Block(-5,14,-7,STAINED_GLASS:15)
Block(-4,14,-7,STAINED_GLASS:15)
Block(-3,14,-7,SEA_LANTERN:0)
Block(-2,14,-7,SEA_LANTERN:0)
Block(-1,14,-7,STAINED_GLASS:6)
Block(0,14,-7,STAINED_GLASS:15)
Block(-5,14,-6,STAINED_GLASS:11)
Block(-4,14,-6,STAINED_GLASS:11)
Block(-3,14,-6,STAINED_GLASS:11)
Block(-2,14,-6,STAINED_GLASS:15)
Block(-1,14,-6,STAINED_GLASS:15)
Block(-4,14,-5,STAINED_GLASS:11)
Block(-3,14,-5,STAINED_GLASS:11)
Block(-2,14,-5,STAINED_GLASS:11)
Block(-3,15,-12,STAINED_GLASS:11)
Block(-5,15,-11,STAINED_GLASS:15)
Block(-4,15,-11,STAINED_GLASS:11)
Block(-3,15,-11,STAINED_GLASS:11)
Block(-2,15,-11,STAINED_GLASS:11)
Block(-7,15,-10,STAINED_GLASS:15)
Block(-6,15,-10,STAINED_GLASS:15)
Block(-5,15,-10,STAINED_GLASS:15)
Block(-4,15,-10,STAINED_GLASS:15)
Block(-3,15,-10,SEA_LANTERN:0)
Block(-2,15,-10,STAINED_GLASS:6)
Block(-6,15,-9,STAINED_GLASS:15)
Block(-5,15,-9,STAINED_GLASS:11)
Block(-4,15,-9,SEA_LANTERN:0)
Block(-3,15,-9,SEA_LANTERN:0)
Block(-2,15,-9,SEA_LANTERN:0)
Block(-5,15,-8,STAINED_GLASS:11)
Block(-4,15,-8,SEA_LANTERN:0)
Block(-3,15,-8,SEA_LANTERN:0)
Block(-2,15,-8,SEA_LANTERN:0)
Block(-1,15,-8,STAINED_GLASS:15)
Block(-5,15,-7,STAINED_GLASS:11)
Block(-4,15,-7,STAINED_GLASS:11)
Block(-3,15,-7,STAINED_GLASS:6)
Block(-2,15,-7,SEA_LANTERN:0)
Block(-1,15,-7,STAINED_GLASS:15)
Block(-5,15,-6,STAINED_GLASS:11)
Block(-4,15,-6,STAINED_GLASS:11)
Block(-3,15,-6,STAINED_GLASS:11)
Block(-2,15,-6,STAINED_GLASS:15)
Block(-5,16,-12,STAINED_GLASS:15)
Block(-4,16,-12,STAINED_GLASS:11)
Block(-3,16,-12,STAINED_GLASS:11)
Block(-6,16,-11,STAINED_GLASS:11)
Block(-5,16,-11,STAINED_GLASS:15)
Block(-4,16,-11,STAINED_GLASS:15)
Block(-3,16,-11,STAINED_GLASS:6)
Block(-2,16,-11,STAINED_GLASS:11)
Block(-7,16,-10,STAINED_GLASS:11)
Block(-6,16,-10,STAINED_GLASS:11)
Block(-5,16,-10,STAINED_GLASS:11)
Block(-4,16,-10,SEA_LANTERN:0)
Block(-3,16,-10,SEA_LANTERN:0)
Block(-2,16,-10,SEA_LANTERN:0)
Block(-6,16,-9,STAINED_GLASS:11)
Block(-5,16,-9,STAINED_GLASS:11)
Block(-4,16,-9,SEA_LANTERN:0)
Block(-3,16,-9,SEA_LANTERN:0)
Block(-2,16,-9,STAINED_GLASS:6)
Block(-5,16,-8,STAINED_GLASS:11)
Block(-4,16,-8,SEA_LANTERN:0)
Block(-3,16,-8,SEA_LANTERN:0)
Block(-2,16,-8,STAINED_GLASS:15)
Block(-1,16,-8,STAINED_GLASS:15)
Block(-5,16,-7,STAINED_GLASS:11)
Block(-4,16,-7,STAINED_GLASS:11)
Block(-3,16,-7,STAINED_GLASS:11)
Block(-2,16,-7,STAINED_GLASS:15)
Block(-1,16,-7,STAINED_GLASS:15)
Block(-5,16,-6,STAINED_GLASS:11)
Block(-4,16,-6,STAINED_GLASS:11)
Block(-4,17,-13,STAINED_GLASS:15)
Block(-3,17,-13,STAINED_GLASS:15)
Block(-6,17,-12,STAINED_GLASS:15)
Block(-5,17,-12,STAINED_GLASS:15)
Block(-4,17,-12,STAINED_GLASS:15)
Block(-3,17,-12,STAINED_GLASS:11)
Block(-7,17,-11,STAINED_GLASS:11)
Block(-6,17,-11,STAINED_GLASS:11)
Block(-5,17,-11,STAINED_GLASS:6)
Block(-4,17,-11,SEA_LANTERN:0)
Block(-3,17,-11,STAINED_GLASS:6)
Block(-2,17,-11,STAINED_GLASS:11)
Block(-7,17,-10,STAINED_GLASS:11)
Block(-6,17,-10,STAINED_GLASS:11)
Block(-5,17,-10,STAINED_GLASS:11)
Block(-4,17,-10,SEA_LANTERN:0)
Block(-3,17,-10,SEA_LANTERN:0)
Block(-2,17,-10,SEA_LANTERN:0)
Block(-6,17,-9,STAINED_GLASS:11)
Block(-5,17,-9,STAINED_GLASS:11)
Block(-4,17,-9,SEA_LANTERN:0)
Block(-3,17,-9,SEA_LANTERN:0)
Block(-2,17,-9,STAINED_GLASS:15)
Block(-5,17,-8,STAINED_GLASS:11)
Block(-4,17,-8,STAINED_GLASS:6)
Block(-3,17,-8,STAINED_GLASS:15)
Block(-2,17,-8,STAINED_GLASS:15)
Block(-5,17,-7,STAINED_GLASS:11)
Block(-4,17,-7,STAINED_GLASS:11)
Block(-3,17,-7,STAINED_GLASS:15)
Block(-2,17,-7,STAINED_GLASS:15)
Block(-4,18,-14,STAINED_GLASS:15)
Block(-7,18,-13,STAINED_GLASS:11)
Block(-6,18,-13,STAINED_GLASS:15)
Block(-5,18,-13,STAINED_GLASS:15)
Block(-4,18,-13,STAINED_GLASS:15)
Block(-3,18,-13,STAINED_GLASS:15)
Block(-7,18,-12,STAINED_GLASS:11)
Block(-6,18,-12,STAINED_GLASS:15)
Block(-5,18,-12,SEA_LANTERN:0)
Block(-4,18,-12,STAINED_GLASS:6)
Block(-3,18,-12,STAINED_GLASS:11)
Block(-7,18,-11,STAINED_GLASS:11)
Block(-6,18,-11,STAINED_GLASS:11)
Block(-5,18,-11,STAINED_GLASS:6)
Block(-4,18,-11,SEA_LANTERN:0)
Block(-3,18,-11,SEA_LANTERN:0)
Block(-2,18,-11,STAINED_GLASS:11)
Block(-7,18,-10,STAINED_GLASS:11)
Block(-6,18,-10,STAINED_GLASS:11)
Block(-5,18,-10,STAINED_GLASS:11)
Block(-4,18,-10,SEA_LANTERN:0)
Block(-3,18,-10,SEA_LANTERN:0)
Block(-2,18,-10,STAINED_GLASS:6)
Block(-6,18,-9,STAINED_GLASS:11)
Block(-5,18,-9,STAINED_GLASS:11)
Block(-4,18,-9,SEA_LANTERN:0)
Block(-3,18,-9,STAINED_GLASS:15)
Block(-2,18,-9,STAINED_GLASS:15)
Block(-5,18,-8,STAINED_GLASS:11)
Block(-4,18,-8,STAINED_GLASS:15)
Block(-3,18,-8,STAINED_GLASS:15)
Block(-5,18,-7,STAINED_GLASS:11)
Block(-4,18,-7,STAINED_GLASS:11)
Block(-4,19,-15,STAINED_GLASS:15)
Block(-5,19,-14,STAINED_GLASS:15)
Block(-4,19,-14,STAINED_GLASS:11)
Block(-8,19,-13,STAINED_GLASS:11)
Block(-7,19,-13,STAINED_GLASS:11)
Block(-6,19,-13,STAINED_GLASS:15)
Block(-5,19,-13,STAINED_GLASS:15)
Block(-4,19,-13,SEA_LANTERN:0)
Block(-3,19,-13,STAINED_GLASS:11)
Block(-7,19,-12,STAINED_GLASS:11)
Block(-6,19,-12,STAINED_GLASS:6)
Block(-5,19,-12,SEA_LANTERN:0)
Block(-4,19,-12,STAINED_GLASS:6)
Block(-3,19,-12,STAINED_GLASS:11)
Block(-7,19,-11,STAINED_GLASS:11)
Block(-6,19,-11,STAINED_GLASS:11)
Block(-5,19,-11,SEA_LANTERN:0)
Block(-4,19,-11,SEA_LANTERN:0)
Block(-3,19,-11,SEA_LANTERN:0)
Block(-2,19,-11,STAINED_GLASS:11)
Block(-7,19,-10,STAINED_GLASS:11)
Block(-6,19,-10,STAINED_GLASS:11)
Block(-5,19,-10,STAINED_GLASS:11)
Block(-4,19,-10,SEA_LANTERN:0)
Block(-3,19,-10,SEA_LANTERN:0)
Block(-2,19,-10,STAINED_GLASS:15)
Block(-6,19,-9,STAINED_GLASS:11)
Block(-5,19,-9,STAINED_GLASS:15)
Block(-4,19,-9,STAINED_GLASS:15)
Block(-3,19,-9,STAINED_GLASS:15)
Block(-4,19,-8,STAINED_GLASS:15)
Block(-5,20,-15,STAINED_GLASS:15)
Block(-4,20,-15,STAINED_GLASS:11)
Block(-7,20,-14,STAINED_GLASS:15)
Block(-6,20,-14,STAINED_GLASS:15)
Block(-5,20,-14,STAINED_GLASS:15)
Block(-4,20,-14,STAINED_GLASS:6)
Block(-8,20,-13,STAINED_GLASS:15)
Block(-7,20,-13,STAINED_GLASS:11)
Block(-6,20,-13,SEA_LANTERN:0)
Block(-5,20,-13,SEA_LANTERN:0)
Block(-4,20,-13,SEA_LANTERN:0)
Block(-3,20,-13,STAINED_GLASS:11)
Block(-7,20,-12,STAINED_GLASS:11)
Block(-6,20,-12,STAINED_GLASS:6)
Block(-5,20,-12,SEA_LANTERN:0)
Block(-4,20,-12,SEA_LANTERN:0)
Block(-3,20,-12,STAINED_GLASS:11)
Block(-7,20,-11,STAINED_GLASS:11)
Block(-6,20,-11,STAINED_GLASS:11)
Block(-5,20,-11,SEA_LANTERN:0)
Block(-4,20,-11,SEA_LANTERN:0)
Block(-3,20,-11,STAINED_GLASS:6)
Block(-2,20,-11,STAINED_GLASS:11)
Block(-7,20,-10,STAINED_GLASS:11)
Block(-6,20,-10,STAINED_GLASS:11)
Block(-5,20,-10,STAINED_GLASS:11)
Block(-4,20,-10,SEA_LANTERN:0)
Block(-3,20,-10,STAINED_GLASS:15)
Block(-2,20,-10,STAINED_GLASS:15)
Block(-6,20,-9,STAINED_GLASS:15)
Block(-5,20,-9,STAINED_GLASS:15)
Block(-4,20,-9,STAINED_GLASS:15)
Block(-4,21,-16,STAINED_GLASS:15)
Block(-7,21,-15,STAINED_GLASS:11)
Block(-6,21,-15,STAINED_GLASS:11)
Block(-5,21,-15,STAINED_GLASS:15)
Block(-4,21,-15,STAINED_GLASS:15)
Block(-8,21,-14,STAINED_GLASS:15)
Block(-7,21,-14,STAINED_GLASS:11)
Block(-6,21,-14,STAINED_GLASS:15)
Block(-5,21,-14,SEA_LANTERN:0)
Block(-4,21,-14,STAINED_GLASS:6)
Block(-8,21,-13,STAINED_GLASS:11)
Block(-7,21,-13,STAINED_GLASS:11)
Block(-6,21,-13,SEA_LANTERN:0)
Block(-5,21,-13,SEA_LANTERN:0)
Block(-4,21,-13,SEA_LANTERN:0)
Block(-3,21,-13,STAINED_GLASS:11)
Block(-7,21,-12,STAINED_GLASS:11)
Block(-6,21,-12,SEA_LANTERN:0)
Block(-5,21,-12,SEA_LANTERN:0)
Block(-4,21,-12,SEA_LANTERN:0)
Block(-3,21,-12,STAINED_GLASS:11)
Block(-7,21,-11,STAINED_GLASS:11)
Block(-6,21,-11,STAINED_GLASS:11)
Block(-5,21,-11,STAINED_GLASS:6)
Block(-4,21,-11,SEA_LANTERN:0)
Block(-3,21,-11,STAINED_GLASS:11)
Block(-7,21,-10,STAINED_GLASS:11)
Block(-6,21,-10,STAINED_GLASS:11)
Block(-5,21,-10,STAINED_GLASS:11)
Block(-4,21,-10,STAINED_GLASS:15)
Block(-3,21,-10,STAINED_GLASS:15)
Block(-7,22,-16,STAINED_GLASS:11)
Block(-5,22,-16,STAINED_GLASS:11)
Block(-4,22,-16,STAINED_GLASS:15)
Block(-8,22,-15,STAINED_GLASS:11)
Block(-7,22,-15,STAINED_GLASS:11)
Block(-6,22,-15,STAINED_GLASS:11)
Block(-5,22,-15,STAINED_GLASS:6)
Block(-4,22,-15,STAINED_GLASS:15)
Block(-8,22,-14,STAINED_GLASS:11)
Block(-7,22,-14,STAINED_GLASS:11)
Block(-6,22,-14,SEA_LANTERN:0)
Block(-5,22,-14,SEA_LANTERN:0)
Block(-4,22,-14,SEA_LANTERN:0)
Block(-8,22,-13,STAINED_GLASS:11)
Block(-7,22,-13,STAINED_GLASS:11)
Block(-6,22,-13,SEA_LANTERN:0)
Block(-5,22,-13,SEA_LANTERN:0)
Block(-4,22,-13,SEA_LANTERN:0)
Block(-3,22,-13,STAINED_GLASS:11)
Block(-7,22,-12,STAINED_GLASS:11)
Block(-6,22,-12,SEA_LANTERN:0)
Block(-5,22,-12,SEA_LANTERN:0)
Block(-4,22,-12,STAINED_GLASS:6)
Block(-3,22,-12,STAINED_GLASS:11)
Block(-7,22,-11,STAINED_GLASS:11)
Block(-6,22,-11,STAINED_GLASS:11)
Block(-5,22,-11,STAINED_GLASS:15)
Block(-4,22,-11,STAINED_GLASS:11)
Block(-3,22,-11,STAINED_GLASS:11)
Block(-7,22,-10,STAINED_GLASS:11)
Block(-6,22,-10,STAINED_GLASS:11)
Block(-5,22,-10,STAINED_GLASS:11)
Block(-4,22,-10,STAINED_GLASS:11)
Block(-5,23,-17,STAINED_GLASS:15)
Block(-8,23,-16,STAINED_GLASS:11)
Block(-7,23,-16,STAINED_GLASS:11)
Block(-6,23,-16,STAINED_GLASS:11)
Block(-5,23,-16,STAINED_GLASS:15)
Block(-4,23,-16,STAINED_GLASS:15)
Block(-9,23,-15,STAINED_GLASS:11)
Block(-8,23,-15,STAINED_GLASS:11)
Block(-7,23,-15,STAINED_GLASS:6)
Block(-6,23,-15,SEA_LANTERN:0)
Block(-5,23,-15,STAINED_GLASS:6)
Block(-4,23,-15,STAINED_GLASS:15)
Block(-8,23,-14,STAINED_GLASS:15)
Block(-7,23,-14,STAINED_GLASS:11)
Block(-6,23,-14,SEA_LANTERN:0)
Block(-5,23,-14,SEA_LANTERN:0)
Block(-4,23,-14,SEA_LANTERN:0)
Block(-8,23,-13,STAINED_GLASS:11)
Block(-7,23,-13,STAINED_GLASS:11)
Block(-6,23,-13,SEA_LANTERN:0)
Block(-5,23,-13,SEA_LANTERN:0)
Block(-4,23,-13,SEA_LANTERN:0)
Block(-3,23,-13,STAINED_GLASS:11)
Block(-7,23,-12,STAINED_GLASS:11)
Block(-6,23,-12,STAINED_GLASS:6)
Block(-5,23,-12,STAINED_GLASS:11)
Block(-4,23,-12,STAINED_GLASS:11)
Block(-7,23,-11,STAINED_GLASS:15)
Block(-6,23,-11,STAINED_GLASS:15)
Block(-5,23,-11,STAINED_GLASS:11)
Block(-4,23,-11,STAINED_GLASS:11)
Block(-6,24,-18,STAINED_GLASS:11)
Block(-7,24,-17,STAINED_GLASS:11)
Block(-6,24,-17,STAINED_GLASS:11)
Block(-5,24,-17,STAINED_GLASS:15)
Block(-9,24,-16,STAINED_GLASS:11)
Block(-8,24,-16,STAINED_GLASS:11)
Block(-7,24,-16,SEA_LANTERN:0)
Block(-6,24,-16,STAINED_GLASS:15)
Block(-5,24,-16,STAINED_GLASS:6)
Block(-4,24,-16,STAINED_GLASS:15)
Block(-9,24,-15,STAINED_GLASS:15)
Block(-8,24,-15,STAINED_GLASS:11)
Block(-7,24,-15,STAINED_GLASS:6)
Block(-6,24,-15,SEA_LANTERN:0)
Block(-5,24,-15,SEA_LANTERN:0)
Block(-4,24,-15,STAINED_GLASS:15)
Block(-8,24,-14,STAINED_GLASS:15)
Block(-7,24,-14,STAINED_GLASS:15)
Block(-6,24,-14,SEA_LANTERN:0)
Block(-5,24,-14,SEA_LANTERN:0)
Block(-4,24,-14,STAINED_GLASS:6)
Block(-8,24,-13,STAINED_GLASS:15)
Block(-7,24,-13,STAINED_GLASS:11)
Block(-6,24,-13,SEA_LANTERN:0)
Block(-5,24,-13,SEA_LANTERN:0)
Block(-4,24,-13,STAINED_GLASS:11)
Block(-3,24,-13,STAINED_GLASS:11)
Block(-7,24,-12,STAINED_GLASS:11)
Block(-6,24,-12,STAINED_GLASS:11)
Block(-5,24,-12,STAINED_GLASS:11)
Block(-4,24,-12,STAINED_GLASS:11)
Block(-7,24,-11,STAINED_GLASS:15)
Block(-6,24,-11,STAINED_GLASS:11)
Block(-7,25,-18,STAINED_GLASS:11)
Block(-6,25,-18,STAINED_GLASS:11)
Block(-8,25,-17,STAINED_GLASS:11)
Block(-7,25,-17,STAINED_GLASS:11)
Block(-6,25,-17,STAINED_GLASS:11)
Block(-5,25,-17,STAINED_GLASS:15)
Block(-9,25,-16,STAINED_GLASS:11)
Block(-8,25,-16,STAINED_GLASS:6)
Block(-7,25,-16,SEA_LANTERN:0)
Block(-6,25,-16,SEA_LANTERN:0)
Block(-5,25,-16,STAINED_GLASS:6)
Block(-4,25,-16,STAINED_GLASS:15)
Block(-9,25,-15,STAINED_GLASS:15)
Block(-8,25,-15,STAINED_GLASS:15)
Block(-7,25,-15,SEA_LANTERN:0)
Block(-6,25,-15,SEA_LANTERN:0)
Block(-5,25,-15,SEA_LANTERN:0)
Block(-4,25,-15,STAINED_GLASS:15)
Block(-8,25,-14,STAINED_GLASS:15)
Block(-7,25,-14,STAINED_GLASS:15)
Block(-6,25,-14,SEA_LANTERN:0)
Block(-5,25,-14,SEA_LANTERN:0)
Block(-4,25,-14,STAINED_GLASS:11)
Block(-8,25,-13,STAINED_GLASS:15)
Block(-7,25,-13,STAINED_GLASS:11)
Block(-6,25,-13,STAINED_GLASS:11)
Block(-5,25,-13,STAINED_GLASS:11)
Block(-4,25,-13,STAINED_GLASS:11)
Block(-7,25,-12,STAINED_GLASS:11)
Block(-6,25,-12,STAINED_GLASS:11)
Block(-7,26,-19,STAINED_GLASS:11)
Block(-6,26,-19,STAINED_GLASS:11)
Block(-9,26,-18,STAINED_GLASS:11)
Block(-8,26,-18,STAINED_GLASS:11)
Block(-7,26,-18,STAINED_GLASS:11)
Block(-6,26,-18,STAINED_GLASS:6)
Block(-9,26,-17,STAINED_GLASS:11)
Block(-8,26,-17,STAINED_GLASS:11)
Block(-7,26,-17,SEA_LANTERN:0)
Block(-6,26,-17,STAINED_GLASS:6)
Block(-5,26,-17,STAINED_GLASS:15)
Block(-9,26,-16,STAINED_GLASS:11)
Block(-8,26,-16,STAINED_GLASS:6)
Block(-7,26,-16,SEA_LANTERN:0)
Block(-6,26,-16,SEA_LANTERN:0)
Block(-5,26,-16,SEA_LANTERN:0)
Block(-4,26,-16,STAINED_GLASS:15)
Block(-9,26,-15,STAINED_GLASS:15)
Block(-8,26,-15,STAINED_GLASS:15)
Block(-7,26,-15,SEA_LANTERN:0)
Block(-6,26,-15,SEA_LANTERN:0)
Block(-5,26,-15,STAINED_GLASS:6)
Block(-4,26,-15,STAINED_GLASS:15)
Block(-8,26,-14,STAINED_GLASS:11)
Block(-7,26,-14,STAINED_GLASS:11)
Block(-6,26,-14,SEA_LANTERN:0)
Block(-5,26,-14,STAINED_GLASS:11)
Block(-4,26,-14,STAINED_GLASS:11)
Block(-8,26,-13,STAINED_GLASS:11)
Block(-7,26,-13,STAINED_GLASS:11)
Block(-6,26,-13,STAINED_GLASS:11)
Block(-5,26,-13,STAINED_GLASS:11)
Block(-7,26,-12,STAINED_GLASS:11)
Block(-6,27,-20,STAINED_GLASS:11)
Block(-9,27,-19,STAINED_GLASS:11)
Block(-8,27,-19,STAINED_GLASS:11)
Block(-7,27,-19,STAINED_GLASS:11)
Block(-6,27,-19,STAINED_GLASS:11)
Block(-10,27,-18,STAINED_GLASS:15)
Block(-9,27,-18,STAINED_GLASS:15)
Block(-8,27,-18,STAINED_GLASS:11)
Block(-7,27,-18,SEA_LANTERN:0)
Block(-6,27,-18,STAINED_GLASS:6)
Block(-9,27,-17,STAINED_GLASS:15)
Block(-8,27,-17,STAINED_GLASS:6)
Block(-7,27,-17,SEA_LANTERN:0)
Block(-6,27,-17,STAINED_GLASS:6)
Block(-5,27,-17,STAINED_GLASS:15)
Block(-9,27,-16,STAINED_GLASS:15)
Block(-8,27,-16,SEA_LANTERN:0)
Block(-7,27,-16,SEA_LANTERN:0)
Block(-6,27,-16,SEA_LANTERN:0)
Block(-5,27,-16,SEA_LANTERN:0)
Block(-4,27,-16,STAINED_GLASS:15)
Block(-9,27,-15,STAINED_GLASS:15)
Block(-8,27,-15,STAINED_GLASS:11)
Block(-7,27,-15,STAINED_GLASS:6)
Block(-6,27,-15,SEA_LANTERN:0)
Block(-5,27,-15,STAINED_GLASS:15)
Block(-8,27,-14,STAINED_GLASS:11)
Block(-7,27,-14,STAINED_GLASS:11)
Block(-6,27,-14,STAINED_GLASS:11)
Block(-5,27,-14,STAINED_GLASS:11)
Block(-7,28,-20,STAINED_GLASS:11)
Block(-6,28,-20,STAINED_GLASS:15)
Block(-10,28,-19,STAINED_GLASS:11)
Block(-9,28,-19,STAINED_GLASS:11)
Block(-8,28,-19,STAINED_GLASS:11)
Block(-7,28,-19,STAINED_GLASS:6)
Block(-6,28,-19,STAINED_GLASS:6)
Block(-10,28,-18,STAINED_GLASS:15)
Block(-9,28,-18,STAINED_GLASS:15)
Block(-8,28,-18,SEA_LANTERN:0)
Block(-7,28,-18,SEA_LANTERN:0)
Block(-6,28,-18,SEA_LANTERN:0)
Block(-9,28,-17,STAINED_GLASS:15)
Block(-8,28,-17,STAINED_GLASS:6)
Block(-7,28,-17,SEA_LANTERN:0)
Block(-6,28,-17,SEA_LANTERN:0)
Block(-5,28,-17,STAINED_GLASS:15)
Block(-9,28,-16,STAINED_GLASS:11)
Block(-8,28,-16,SEA_LANTERN:0)
Block(-7,28,-16,SEA_LANTERN:0)
Block(-6,28,-16,SEA_LANTERN:0)
Block(-5,28,-16,STAINED_GLASS:6)
Block(-4,28,-16,STAINED_GLASS:15)
Block(-9,28,-15,STAINED_GLASS:11)
Block(-8,28,-15,STAINED_GLASS:11)
Block(-7,28,-15,STAINED_GLASS:11)
Block(-6,28,-15,STAINED_GLASS:15)
Block(-5,28,-15,STAINED_GLASS:15)
Block(-8,28,-14,STAINED_GLASS:11)
Block(-7,28,-14,STAINED_GLASS:11)
Block(-6,28,-14,STAINED_GLASS:11)
Block(-7,29,-21,STAINED_GLASS:15)
Block(-9,29,-20,STAINED_GLASS:11)
Block(-8,29,-20,STAINED_GLASS:11)
Block(-7,29,-20,STAINED_GLASS:15)
Block(-6,29,-20,STAINED_GLASS:15)
Block(-11,29,-19,STAINED_GLASS:11)
Block(-10,29,-19,STAINED_GLASS:11)
Block(-9,29,-19,STAINED_GLASS:6)
Block(-8,29,-19,SEA_LANTERN:0)
Block(-7,29,-19,STAINED_GLASS:6)
Block(-6,29,-19,STAINED_GLASS:6)
Block(-10,29,-18,STAINED_GLASS:11)
Block(-9,29,-18,STAINED_GLASS:11)
Block(-8,29,-18,SEA_LANTERN:0)
Block(-7,29,-18,SEA_LANTERN:0)
Block(-6,29,-18,SEA_LANTERN:0)
Block(-9,29,-17,STAINED_GLASS:11)
Block(-8,29,-17,SEA_LANTERN:0)
Block(-7,29,-17,SEA_LANTERN:0)
Block(-6,29,-17,SEA_LANTERN:0)
Block(-5,29,-17,STAINED_GLASS:15)
Block(-9,29,-16,STAINED_GLASS:11)
Block(-8,29,-16,STAINED_GLASS:6)
Block(-7,29,-16,STAINED_GLASS:11)
Block(-6,29,-16,SEA_LANTERN:0)
Block(-5,29,-16,STAINED_GLASS:15)
Block(-9,29,-15,STAINED_GLASS:11)
Block(-8,29,-15,STAINED_GLASS:11)
Block(-7,29,-15,STAINED_GLASS:11)
Block(-6,29,-15,STAINED_GLASS:11)
Block(-9,30,-21,STAINED_GLASS:11)
Block(-8,30,-21,STAINED_GLASS:11)
Block(-7,30,-21,STAINED_GLASS:15)
Block(-10,30,-20,STAINED_GLASS:11)
Block(-9,30,-20,STAINED_GLASS:11)
Block(-8,30,-20,STAINED_GLASS:11)
Block(-7,30,-20,STAINED_GLASS:6)
Block(-6,30,-20,STAINED_GLASS:15)
Block(-11,30,-19,STAINED_GLASS:11)
Block(-10,30,-19,STAINED_GLASS:11)
Block(-9,30,-19,STAINED_GLASS:6)
Block(-8,30,-19,SEA_LANTERN:0)
Block(-7,30,-19,SEA_LANTERN:0)
Block(-6,30,-19,SEA_LANTERN:0)
Block(-10,30,-18,STAINED_GLASS:11)
Block(-9,30,-18,STAINED_GLASS:11)
Block(-8,30,-18,SEA_LANTERN:0)
Block(-7,30,-18,SEA_LANTERN:0)
Block(-6,30,-18,STAINED_GLASS:6)
Block(-9,30,-17,STAINED_GLASS:11)
Block(-8,30,-17,SEA_LANTERN:0)
Block(-7,30,-17,SEA_LANTERN:0)
Block(-6,30,-17,STAINED_GLASS:6)
Block(-5,30,-17,STAINED_GLASS:15)
Block(-9,30,-16,STAINED_GLASS:11)
Block(-8,30,-16,STAINED_GLASS:6)
Block(-7,30,-16,STAINED_GLASS:11)
Block(-6,30,-16,SEA_LANTERN:0)
Block(-5,30,-16,STAINED_GLASS:15)
Block(-9,30,-15,STAINED_GLASS:11)
Block(-8,30,-15,STAINED_GLASS:11)
Block(-9,31,-22,STAINED_GLASS:11)
Block(-8,31,-22,STAINED_GLASS:11)
Block(-7,31,-22,STAINED_GLASS:11)
Block(-10,31,-21,STAINED_GLASS:11)
Block(-9,31,-21,STAINED_GLASS:11)
Block(-8,31,-21,STAINED_GLASS:11)
Block(-7,31,-21,STAINED_GLASS:11)
Block(-11,31,-20,STAINED_GLASS:11)
Block(-10,31,-20,STAINED_GLASS:11)
Block(-9,31,-20,STAINED_GLASS:6)
Block(-8,31,-20,SEA_LANTERN:0)
Block(-7,31,-20,STAINED_GLASS:6)
Block(-6,31,-20,STAINED_GLASS:15)
Block(-11,31,-19,STAINED_GLASS:11)
Block(-10,31,-19,STAINED_GLASS:11)
Block(-9,31,-19,SEA_LANTERN:0)
Block(-8,31,-19,SEA_LANTERN:0)
Block(-7,31,-19,SEA_LANTERN:0)
Block(-6,31,-19,SEA_LANTERN:0)
Block(-10,31,-18,STAINED_GLASS:11)
Block(-9,31,-18,STAINED_GLASS:11)
Block(-8,31,-18,SEA_LANTERN:0)
Block(-7,31,-18,SEA_LANTERN:0)
Block(-6,31,-18,STAINED_GLASS:15)
Block(-9,31,-17,STAINED_GLASS:11)
Block(-8,31,-17,STAINED_GLASS:6)
Block(-7,31,-17,SEA_LANTERN:0)
Block(-6,31,-17,STAINED_GLASS:15)
Block(-9,31,-16,STAINED_GLASS:11)
Block(-8,31,-16,STAINED_GLASS:15)
Block(-6,31,-16,STAINED_GLASS:15)
Block(-10,32,-22,STAINED_GLASS:11)
Block(-9,32,-22,STAINED_GLASS:11)
Block(-8,32,-22,STAINED_GLASS:11)
Block(-7,32,-22,STAINED_GLASS:11)
Block(-11,32,-21,STAINED_GLASS:11)
Block(-10,32,-21,STAINED_GLASS:11)
Block(-9,32,-21,SEA_LANTERN:0)
Block(-8,32,-21,STAINED_GLASS:6)
Block(-7,32,-21,STAINED_GLASS:15)
Block(-11,32,-20,STAINED_GLASS:11)
Block(-10,32,-20,STAINED_GLASS:11)
Block(-9,32,-20,STAINED_GLASS:6)
Block(-8,32,-20,SEA_LANTERN:0)
Block(-7,32,-20,SEA_LANTERN:0)
Block(-6,32,-20,STAINED_GLASS:15)
Block(-11,32,-19,STAINED_GLASS:11)
Block(-10,32,-19,STAINED_GLASS:11)
Block(-9,32,-19,SEA_LANTERN:0)
Block(-8,32,-19,SEA_LANTERN:0)
Block(-7,32,-19,STAINED_GLASS:6)
Block(-6,32,-19,STAINED_GLASS:6)
Block(-10,32,-18,STAINED_GLASS:11)
Block(-9,32,-18,STAINED_GLASS:11)
Block(-8,32,-18,SEA_LANTERN:0)
Block(-7,32,-18,SEA_LANTERN:0)
Block(-6,32,-18,STAINED_GLASS:15)
Block(-9,32,-17,STAINED_GLASS:11)
Block(-8,32,-17,STAINED_GLASS:6)
Block(-7,32,-17,STAINED_GLASS:15)
Block(-6,32,-17,STAINED_GLASS:15)
Block(-9,32,-16,STAINED_GLASS:15)
Block(-8,33,-24,STAINED_GLASS:11)
Block(-9,33,-23,STAINED_GLASS:15)
Block(-8,33,-23,STAINED_GLASS:11)
Block(-12,33,-22,STAINED_GLASS:11)
Block(-11,33,-22,STAINED_GLASS:11)
Block(-10,33,-22,STAINED_GLASS:15)
Block(-9,33,-22,SEA_LANTERN:0)
Block(-8,33,-22,STAINED_GLASS:11)
Block(-7,33,-22,STAINED_GLASS:11)
Block(-11,33,-21,STAINED_GLASS:11)
Block(-10,33,-21,STAINED_GLASS:6)
Block(-9,33,-21,SEA_LANTERN:0)
Block(-8,33,-21,STAINED_GLASS:6)
Block(-7,33,-21,STAINED_GLASS:11)
Block(-11,33,-20,STAINED_GLASS:11)
Block(-10,33,-20,STAINED_GLASS:11)
Block(-9,33,-20,SEA_LANTERN:0)
Block(-8,33,-20,SEA_LANTERN:0)
Block(-7,33,-20,SEA_LANTERN:0)
Block(-6,33,-20,STAINED_GLASS:15)
Block(-11,33,-19,STAINED_GLASS:11)
Block(-10,33,-19,STAINED_GLASS:11)
Block(-9,33,-19,STAINED_GLASS:6)
Block(-8,33,-19,SEA_LANTERN:0)
Block(-7,33,-19,STAINED_GLASS:15)
Block(-6,33,-19,STAINED_GLASS:15)
Block(-10,33,-18,STAINED_GLASS:15)
Block(-9,33,-18,STAINED_GLASS:15)
Block(-8,33,-18,SEA_LANTERN:0)
Block(-7,33,-18,STAINED_GLASS:15)
Block(-9,33,-17,STAINED_GLASS:15)
Block(-8,33,-17,STAINED_GLASS:15)
Block(-9,34,-24,STAINED_GLASS:15)
Block(-8,34,-24,STAINED_GLASS:15)
Block(-11,34,-23,STAINED_GLASS:11)
Block(-10,34,-23,STAINED_GLASS:11)
Block(-9,34,-23,STAINED_GLASS:15)
Block(-8,34,-23,STAINED_GLASS:15)
Block(-12,34,-22,STAINED_GLASS:11)
Block(-11,34,-22,STAINED_GLASS:11)
Block(-10,34,-22,SEA_LANTERN:0)
Block(-9,34,-22,SEA_LANTERN:0)
Block(-8,34,-22,STAINED_GLASS:11)
Block(-7,34,-22,STAINED_GLASS:11)
Block(-11,34,-21,STAINED_GLASS:11)
Block(-10,34,-21,STAINED_GLASS:6)
Block(-9,34,-21,SEA_LANTERN:0)
Block(-8,34,-21,SEA_LANTERN:0)
Block(-7,34,-21,STAINED_GLASS:11)
Block(-11,34,-20,STAINED_GLASS:15)
Block(-10,34,-20,STAINED_GLASS:15)
Block(-9,34,-20,SEA_LANTERN:0)
Block(-8,34,-20,SEA_LANTERN:0)
Block(-7,34,-20,STAINED_GLASS:6)
Block(-6,34,-20,STAINED_GLASS:15)
Block(-11,34,-19,STAINED_GLASS:15)
Block(-10,34,-19,STAINED_GLASS:15)
Block(-9,34,-19,STAINED_GLASS:6)
Block(-8,34,-19,SEA_LANTERN:0)
Block(-7,34,-19,STAINED_GLASS:15)
Block(-6,34,-19,STAINED_GLASS:15)
Block(-10,34,-18,STAINED_GLASS:15)
Block(-9,34,-18,STAINED_GLASS:15)
Block(-8,34,-18,STAINED_GLASS:15)
Block(-9,34,-17,STAINED_GLASS:15)
Block(-9,35,-25,STAINED_GLASS:15)
Block(-11,35,-24,STAINED_GLASS:11)
Block(-10,35,-24,STAINED_GLASS:11)
Block(-9,35,-24,STAINED_GLASS:15)
Block(-8,35,-24,STAINED_GLASS:15)
Block(-13,35,-23,STAINED_GLASS:11)
Block(-12,35,-23,STAINED_GLASS:11)
Block(-11,35,-23,STAINED_GLASS:11)
Block(-10,35,-23,STAINED_GLASS:11)
Block(-9,35,-23,SEA_LANTERN:0)
Block(-8,35,-23,STAINED_GLASS:15)
Block(-12,35,-22,STAINED_GLASS:11)
Block(-11,35,-22,STAINED_GLASS:6)
Block(-10,35,-22,SEA_LANTERN:0)
Block(-9,35,-22,SEA_LANTERN:0)
Block(-8,35,-22,STAINED_GLASS:11)
Block(-7,35,-22,STAINED_GLASS:11)
Block(-11,35,-21,STAINED_GLASS:15)
Block(-10,35,-21,SEA_LANTERN:0)
Block(-9,35,-21,SEA_LANTERN:0)
Block(-8,35,-21,SEA_LANTERN:0)
Block(-7,35,-21,STAINED_GLASS:11)
Block(-11,35,-20,STAINED_GLASS:15)
Block(-10,35,-20,STAINED_GLASS:15)
Block(-9,35,-20,STAINED_GLASS:6)
Block(-8,35,-20,SEA_LANTERN:0)
Block(-7,35,-20,STAINED_GLASS:11)
Block(-11,35,-19,STAINED_GLASS:15)
Block(-10,35,-19,STAINED_GLASS:15)
Block(-9,35,-19,STAINED_GLASS:15)
Block(-8,35,-19,STAINED_GLASS:15)
Block(-11,36,-25,STAINED_GLASS:11)
Block(-10,36,-25,STAINED_GLASS:15)
Block(-9,36,-25,STAINED_GLASS:15)
Block(-12,36,-24,STAINED_GLASS:11)
Block(-11,36,-24,STAINED_GLASS:11)
Block(-10,36,-24,STAINED_GLASS:15)
Block(-9,36,-24,STAINED_GLASS:6)
Block(-8,36,-24,STAINED_GLASS:15)
Block(-13,36,-23,STAINED_GLASS:11)
Block(-12,36,-23,STAINED_GLASS:11)
Block(-11,36,-23,STAINED_GLASS:11)
Block(-10,36,-23,SEA_LANTERN:0)
Block(-9,36,-23,SEA_LANTERN:0)
Block(-8,36,-23,STAINED_GLASS:15)
Block(-12,36,-22,STAINED_GLASS:15)
Block(-11,36,-22,STAINED_GLASS:6)
Block(-10,36,-22,SEA_LANTERN:0)
Block(-9,36,-22,SEA_LANTERN:0)
Block(-8,36,-22,STAINED_GLASS:11)
Block(-7,36,-22,STAINED_GLASS:11)
Block(-11,36,-21,STAINED_GLASS:15)
Block(-10,36,-21,SEA_LANTERN:0)
Block(-9,36,-21,SEA_LANTERN:0)
Block(-8,36,-21,STAINED_GLASS:6)
Block(-7,36,-21,STAINED_GLASS:11)
Block(-11,36,-20,STAINED_GLASS:15)
Block(-10,36,-20,STAINED_GLASS:15)
Block(-9,36,-20,STAINED_GLASS:6)
Block(-8,36,-20,SEA_LANTERN:0)
Block(-7,36,-20,STAINED_GLASS:11)
Block(-11,36,-19,STAINED_GLASS:15)
Block(-10,36,-19,STAINED_GLASS:15)
Block(-11,37,-25,STAINED_GLASS:15)
Block(-10,37,-25,STAINED_GLASS:15)
Block(-9,37,-25,STAINED_GLASS:15)
Block(-12,37,-24,STAINED_GLASS:11)
Block(-11,37,-24,STAINED_GLASS:6)
Block(-10,37,-24,SEA_LANTERN:0)
Block(-9,37,-24,STAINED_GLASS:6)
Block(-8,37,-24,STAINED_GLASS:15)
Block(-13,37,-23,STAINED_GLASS:11)
Block(-12,37,-23,STAINED_GLASS:11)
Block(-11,37,-23,STAINED_GLASS:15)
Block(-10,37,-23,SEA_LANTERN:0)
Block(-9,37,-23,SEA_LANTERN:0)
Block(-8,37,-23,STAINED_GLASS:15)
Block(-12,37,-22,STAINED_GLASS:15)
Block(-11,37,-22,SEA_LANTERN:0)
Block(-10,37,-22,SEA_LANTERN:0)
Block(-9,37,-22,SEA_LANTERN:0)
Block(-8,37,-22,STAINED_GLASS:11)
Block(-7,37,-22,STAINED_GLASS:11)
Block(-11,37,-21,STAINED_GLASS:15)
Block(-10,37,-21,STAINED_GLASS:6)
Block(-9,37,-21,SEA_LANTERN:0)
Block(-8,37,-21,STAINED_GLASS:11)
Block(-11,37,-20,STAINED_GLASS:15)
Block(-10,37,-20,STAINED_GLASS:15)
Block(-9,37,-20,STAINED_GLASS:15)
Block(-8,37,-20,STAINED_GLASS:11)
Block(-12,38,-25,STAINED_GLASS:11)
Block(-11,38,-25,STAINED_GLASS:11)
Block(-10,38,-25,STAINED_GLASS:15)
Block(-9,38,-25,STAINED_GLASS:11)
Block(-12,38,-24,STAINED_GLASS:11)
Block(-11,38,-24,STAINED_GLASS:11)
Block(-10,38,-24,STAINED_GLASS:11)
Block(-9,38,-24,SEA_LANTERN:0)
Block(-8,38,-24,STAINED_GLASS:11)
Block(-13,38,-23,STAINED_GLASS:11)
Block(-12,38,-23,STAINED_GLASS:11)
Block(-11,38,-23,STAINED_GLASS:11)
Block(-10,38,-23,SEA_LANTERN:0)
Block(-9,38,-23,SEA_LANTERN:0)
Block(-8,38,-23,STAINED_GLASS:11)
Block(-12,38,-22,STAINED_GLASS:15)
Block(-11,38,-22,SEA_LANTERN:0)
Block(-10,38,-22,SEA_LANTERN:0)
Block(-9,38,-22,SEA_LANTERN:0)
Block(-8,38,-22,STAINED_GLASS:11)
Block(-7,38,-22,STAINED_GLASS:11)
Block(-11,38,-21,STAINED_GLASS:15)
Block(-10,38,-21,STAINED_GLASS:6)
Block(-9,38,-21,STAINED_GLASS:15)
Block(-8,38,-21,STAINED_GLASS:11)
Block(-11,38,-20,STAINED_GLASS:15)
Block(-10,38,-20,STAINED_GLASS:15)
Block(-12,39,-25,STAINED_GLASS:11)
Block(-11,39,-25,STAINED_GLASS:15)
Block(-10,39,-25,STAINED_GLASS:11)
Block(-12,39,-24,STAINED_GLASS:11)
Block(-11,39,-24,STAINED_GLASS:11)
Block(-10,39,-24,SEA_LANTERN:0)
Block(-9,39,-24,STAINED_GLASS:11)
Block(-11,39,-23,STAINED_GLASS:15)
Block(-10,39,-23,SEA_LANTERN:0)
Block(-9,39,-23,STAINED_GLASS:11)
Block(-11,39,-22,STAINED_GLASS:15)
Block(-10,39,-22,STAINED_GLASS:15)
Block(-9,39,-22,STAINED_GLASS:15)
Block(-11,39,-21,STAINED_GLASS:15)
Block(-10,39,-21,STAINED_GLASS:15)
Block(-11,40,-26,STAINED_GLASS:15)
Block(-12,40,-25,STAINED_GLASS:15)
Block(-11,40,-25,STAINED_GLASS:11)
Block(-10,40,-25,STAINED_GLASS:11)
Block(-12,40,-24,STAINED_GLASS:15)
Block(-11,40,-24,STAINED_GLASS:15)
Block(-10,40,-24,SEA_LANTERN:0)
Block(-9,40,-24,STAINED_GLASS:11)
Block(-11,40,-23,STAINED_GLASS:15)
Block(-10,40,-23,STAINED_GLASS:11)
Block(-9,40,-23,STAINED_GLASS:11)
Block(-11,40,-22,STAINED_GLASS:15)
Block(-11,41,-26,STAINED_GLASS:11)
Block(-12,41,-25,STAINED_GLASS:11)
Block(-11,41,-25,STAINED_GLASS:11)
Block(-10,41,-25,STAINED_GLASS:11)
Block(-12,41,-24,STAINED_GLASS:11)
Block(-11,41,-24,STAINED_GLASS:15)
Block(-10,41,-24,STAINED_GLASS:11)
Block(-9,41,-24,STAINED_GLASS:11)
Block(-11,41,-23,STAINED_GLASS:15)
Block(-10,41,-23,STAINED_GLASS:15)
Block(-11,42,-26,STAINED_GLASS:11)
Block(-12,42,-25,STAINED_GLASS:11)
Block(-11,42,-25,STAINED_GLASS:11)
Block(-11,43,-26,STAINED_GLASS:11)

#######################################################################
# +-----------------------------------------------------------------+ #
# |                            BO3 checks                           | #
# +-----------------------------------------------------------------+ #
#######################################################################

# Require a condition at a certain location in order for the BO3 to be spawned.
# BlockCheck(x,y,z,BlockName[,BlockName[,...]]) - one of the blocks must be at the location
# BlockCheckNot(x,y,z,BlockName[,BlockName[,...]]) - all the blocks must not be at the location
# LightCheck(x,y,z,minLightLevel,maxLightLevel) - light must be between min and max (inclusive)

# You can use "Solid" as a BlockName for matching all solid blocks or "All" to match all blocks that aren't air.

# Examples:
#   BlockCheck(0,-1,0,GRASS,DIRT)  Require grass or dirt just below the object
#   BlockCheck(0,-1,0,Solid)       Require any solid block just below the object
#   BlockCheck(0,-1,0,WOOL)        Require any type of wool just below the object
#   BlockCheck(0,-1,0,WOOL:0)      Require white wool just below the object
#   BlockCheckNot(0,-1,0,WOOL:0)   Require that there is no white wool below the object
#   LightCheck(0,0,0,0,1)          Require almost complete darkness just below the object

#######################################################################
# +-----------------------------------------------------------------+ #
# |                             Branches                            | #
# +-----------------------------------------------------------------+ #
#######################################################################

# Branches are objects that will spawn when this object spawns when it is used in
# the CustomStructure resource. Branches can also have branches, making complex
# structures possible. See the wiki for more details.

# Regular Branches spawn each branch with an independent chance of spawning.
# Branch(x,y,z,branchName,rotation,chance[,anotherBranchName,rotation,chance[,...]][IndividualChance])
# branchName - name of the object to spawn.
# rotation - NORTH, SOUTH, EAST or WEST.
# IndividualChance - The chance each branch has to spawn, assumed to be 100 when left blank

# Weighted Branches spawn branches with a dependent chance of spawning.
# WeightedBranch(x,y,z,branchName,rotation,chance[,anotherBranchName,rotation,chance[,...]][MaxChanceOutOf])
# MaxChanceOutOf - The chance all branches have to spawn out of, assumed to be 100 when left blank
