#######################################################################
# +-----------------------------------------------------------------+ #
# |                            BO3 object                           | #
# +-----------------------------------------------------------------+ #
#######################################################################

# This is the config file of a custom object.
# If you add this object correctly to your BiomeConfigs, it will spawn in the world.

# This is the creator of this BO3 object
Author: BO3 BulkEdit (by LanToaster)

# A short description of this BO3 object
Description: Bo3 spikes created by NLBlackEagle

# The BO3 version, don't change this! It can be used by external applications to do a version check.
Version: 3

# The settings mode, WriteAll, WriteWithoutComments or WriteDisable. See WorldConfig.
SettingsMode: WriteDisable


#######################################################################
# +-----------------------------------------------------------------+ #
# |                          Main settings                          | #
# +-----------------------------------------------------------------+ #
#######################################################################

# This needs to be set to true to spawn the object in the Tree and Sapling resources.
Tree: false

# The frequency of the BO3 from 1 to 200. Tries this many times to spawn this BO3 when using the CustomObject(...) resource.

Frequency: 100

# The rarity of the BO3 from 0 to 100. Each spawn attempt has rarity% chance to succeed when using the CustomObject(...) resource.

Rarity: 100

# If you set this to true, the BO3 will be placed with a random rotation.
RotateRandomly: true

# The spawn height of the BO3 - randomY, highestBlock or highestSolidBlock.
SpawnHeight: randomY

# The height limits for the BO3.
MinHeight: 0

MaxHeight: 256

# Objects can have other objects attacthed to it: branches. Branches can also
# have branches attached to it, which can also have branches, etc. This is the
# maximum branch depth for this objects.
MaxBranchDepth: 10

# When spawned with the UseWorld keyword, this BO3 should NOT spawn in the following biomes.
# If you writer.write the BO3 name directly in the BiomeConfigs, this will be ignored.
ExcludedBiomes: All


#######################################################################
# +-----------------------------------------------------------------+ #
# |                      Source block settings                      | #
# +-----------------------------------------------------------------+ #
#######################################################################

# The block(s) the BO3 should spawn in.
SourceBlocks: AIR

# The maximum percentage of the BO3 that can be outside the SourceBlock.
# The BO3 won't be placed on a location with more blocks outside the SourceBlock than this percentage.
MaxPercentageOutsideSourceBlock: 100

# What to do when a block is about to be placed outside the SourceBlock? (dontPlace, placeAnyway)
OutsideSourceBlock: placeAnyway


#######################################################################
# +-----------------------------------------------------------------+ #
# |                              Blocks                             | #
# +-----------------------------------------------------------------+ #
#######################################################################

# All the blocks used in the BO3 are listed here. Possible blocks:
# Block(x,y,z,id[.data][,nbtfile.nbt)
# RandomBlock(x,y,z,id[:data][,nbtfile.nbt],chance[,id[:data][,nbtfile.nbt],chance[,...]])
# So RandomBlock(0,0,0,CHEST,chest.nbt,50,CHEST,anotherchest.nbt,100) will spawn a chest at
# the BO3 origin, and give it a 50% chance to have the contents of chest.nbt, or, if that
# fails, a 100% percent chance to have the contents of anotherchest.nbt.
Block(0,0,-3,STAINED_GLASS:15)
Block(1,0,-3,STAINED_GLASS:15)
Block(-1,0,-2,STAINED_GLASS:15)
Block(0,0,-2,STAINED_GLASS:15)
Block(0,0,-1,STAINED_GLASS:15)
Block(1,0,-1,STAINED_GLASS:15)
Block(0,1,-3,STAINED_GLASS:15)
Block(1,1,-3,STAINED_GLASS:15)
Block(2,1,-3,STAINED_GLASS:15)
Block(-2,1,-2,STAINED_GLASS:15)
Block(-1,1,-2,STAINED_GLASS:6)
Block(0,1,-2,SEA_LANTERN:0)
Block(1,1,-2,STAINED_GLASS:15)
Block(2,1,-2,STAINED_GLASS:15)
Block(-2,1,-1,STAINED_GLASS:15)
Block(-1,1,-1,STAINED_GLASS:15)
Block(0,1,-1,SEA_LANTERN:0)
Block(1,1,-1,SEA_LANTERN:0)
Block(2,1,-1,STAINED_GLASS:15)
Block(-2,1,0,STAINED_GLASS:15)
Block(-1,1,0,STAINED_GLASS:15)
Block(0,1,0,STAINED_GLASS:15)
Block(2,1,0,STAINED_GLASS:15)
Block(0,2,-4,STAINED_GLASS:15)
Block(1,2,-4,STAINED_GLASS:15)
Block(2,2,-4,STAINED_GLASS:15)
Block(-3,2,-3,STAINED_GLASS:15)
Block(-2,2,-3,STAINED_GLASS:15)
Block(-1,2,-3,STAINED_GLASS:15)
Block(0,2,-3,STAINED_GLASS:15)
Block(1,2,-3,STAINED_GLASS:11)
Block(2,2,-3,STAINED_GLASS:11)
Block(-2,2,-2,STAINED_GLASS:15)
Block(-1,2,-2,STAINED_GLASS:6)
Block(0,2,-2,SEA_LANTERN:0)
Block(1,2,-2,SEA_LANTERN:0)
Block(2,2,-2,SEA_LANTERN:0)
Block(-2,2,-1,STAINED_GLASS:15)
Block(-1,2,-1,STAINED_GLASS:11)
Block(0,2,-1,SEA_LANTERN:0)
Block(1,2,-1,SEA_LANTERN:0)
Block(2,2,-1,STAINED_GLASS:15)
Block(-2,2,0,STAINED_GLASS:11)
Block(-1,2,0,STAINED_GLASS:11)
Block(0,2,0,SEA_LANTERN:0)
Block(1,2,0,STAINED_GLASS:15)
Block(2,2,0,STAINED_GLASS:6)
Block(3,2,0,STAINED_GLASS:15)
Block(-1,2,1,STAINED_GLASS:15)
Block(0,2,1,STAINED_GLASS:15)
Block(1,2,1,STAINED_GLASS:15)
Block(2,2,1,STAINED_GLASS:15)
Block(-2,3,-4,STAINED_GLASS:15)
Block(-1,3,-4,STAINED_GLASS:15)
Block(0,3,-4,STAINED_GLASS:15)
Block(1,3,-4,STAINED_GLASS:11)
Block(2,3,-4,STAINED_GLASS:11)
Block(-3,3,-3,STAINED_GLASS:15)
Block(-2,3,-3,STAINED_GLASS:15)
Block(-1,3,-3,STAINED_GLASS:15)
Block(0,3,-3,SEA_LANTERN:0)
Block(1,3,-3,STAINED_GLASS:6)
Block(2,3,-3,STAINED_GLASS:11)
Block(-2,3,-2,STAINED_GLASS:11)
Block(-1,3,-2,STAINED_GLASS:6)
Block(0,3,-2,SEA_LANTERN:0)
Block(1,3,-2,SEA_LANTERN:0)
Block(2,3,-2,SEA_LANTERN:0)
Block(-2,3,-1,STAINED_GLASS:11)
Block(-1,3,-1,STAINED_GLASS:11)
Block(0,3,-1,SEA_LANTERN:0)
Block(1,3,-1,SEA_LANTERN:0)
Block(2,3,-1,STAINED_GLASS:11)
Block(-2,3,0,STAINED_GLASS:11)
Block(-1,3,0,STAINED_GLASS:11)
Block(0,3,0,SEA_LANTERN:0)
Block(1,3,0,STAINED_GLASS:15)
Block(2,3,0,STAINED_GLASS:6)
Block(3,3,0,STAINED_GLASS:15)
Block(-1,3,1,STAINED_GLASS:11)
Block(0,3,1,STAINED_GLASS:15)
Block(-2,4,-4,STAINED_GLASS:15)
Block(-1,4,-4,STAINED_GLASS:15)
Block(0,4,-4,SEA_LANTERN:0)
Block(1,4,-4,STAINED_GLASS:11)
Block(2,4,-4,STAINED_GLASS:11)
Block(-3,4,-3,STAINED_GLASS:15)
Block(-2,4,-3,STAINED_GLASS:15)
Block(-1,4,-3,STAINED_GLASS:6)
Block(0,4,-3,SEA_LANTERN:0)
Block(1,4,-3,STAINED_GLASS:6)
Block(2,4,-3,STAINED_GLASS:11)
Block(-2,4,-2,STAINED_GLASS:11)
Block(-1,4,-2,SEA_LANTERN:0)
Block(0,4,-2,SEA_LANTERN:0)
Block(1,4,-2,SEA_LANTERN:0)
Block(2,4,-2,SEA_LANTERN:0)
Block(-2,4,-1,STAINED_GLASS:11)
Block(-1,4,-1,STAINED_GLASS:11)
Block(0,4,-1,SEA_LANTERN:0)
Block(1,4,-1,SEA_LANTERN:0)
Block(2,4,-1,STAINED_GLASS:11)
Block(-2,4,0,STAINED_GLASS:11)
Block(-1,4,0,STAINED_GLASS:11)
Block(0,4,0,STAINED_GLASS:15)
Block(1,4,0,STAINED_GLASS:15)
Block(2,4,0,STAINED_GLASS:15)
Block(0,4,1,STAINED_GLASS:15)
Block(1,5,-6,STAINED_GLASS:15)
Block(0,5,-5,STAINED_GLASS:15)
Block(1,5,-5,STAINED_GLASS:15)
Block(-3,5,-4,STAINED_GLASS:15)
Block(-2,5,-4,STAINED_GLASS:15)
Block(-1,5,-4,STAINED_GLASS:15)
Block(0,5,-4,SEA_LANTERN:0)
Block(1,5,-4,STAINED_GLASS:11)
Block(2,5,-4,STAINED_GLASS:11)
Block(-3,5,-3,STAINED_GLASS:15)
Block(-2,5,-3,STAINED_GLASS:15)
Block(-1,5,-3,STAINED_GLASS:6)
Block(0,5,-3,SEA_LANTERN:0)
Block(1,5,-3,SEA_LANTERN:0)
Block(2,5,-3,STAINED_GLASS:11)
Block(-2,5,-2,STAINED_GLASS:11)
Block(-1,5,-2,SEA_LANTERN:0)
Block(0,5,-2,SEA_LANTERN:0)
Block(1,5,-2,STAINED_GLASS:6)
Block(2,5,-2,STAINED_GLASS:6)
Block(-2,5,-1,STAINED_GLASS:11)
Block(-1,5,-1,STAINED_GLASS:11)
Block(0,5,-1,SEA_LANTERN:0)
Block(1,5,-1,STAINED_GLASS:15)
Block(2,5,-1,STAINED_GLASS:15)
Block(-2,5,0,STAINED_GLASS:11)
Block(-1,5,0,STAINED_GLASS:11)
Block(0,5,0,STAINED_GLASS:15)
Block(2,5,0,STAINED_GLASS:15)
Block(1,6,-6,STAINED_GLASS:11)
Block(0,6,-5,STAINED_GLASS:15)
Block(1,6,-5,STAINED_GLASS:11)
Block(-3,6,-4,STAINED_GLASS:15)
Block(-2,6,-4,STAINED_GLASS:11)
Block(-1,6,-4,SEA_LANTERN:0)
Block(0,6,-4,SEA_LANTERN:0)
Block(1,6,-4,STAINED_GLASS:11)
Block(2,6,-4,STAINED_GLASS:11)
Block(-3,6,-3,STAINED_GLASS:11)
Block(-2,6,-3,STAINED_GLASS:11)
Block(-1,6,-3,STAINED_GLASS:6)
Block(0,6,-3,SEA_LANTERN:0)
Block(1,6,-3,SEA_LANTERN:0)
Block(2,6,-3,STAINED_GLASS:11)
Block(-2,6,-2,STAINED_GLASS:11)
Block(-1,6,-2,STAINED_GLASS:6)
Block(0,6,-2,SEA_LANTERN:0)
Block(1,6,-2,STAINED_GLASS:6)
Block(2,6,-2,STAINED_GLASS:6)
Block(-2,6,-1,STAINED_GLASS:11)
Block(-1,6,-1,STAINED_GLASS:11)
Block(0,6,-1,SEA_LANTERN:0)
Block(1,6,-1,STAINED_GLASS:15)
Block(2,6,-1,STAINED_GLASS:15)
Block(-2,6,0,STAINED_GLASS:11)
Block(-1,7,-6,STAINED_GLASS:15)
Block(0,7,-6,STAINED_GLASS:15)
Block(1,7,-6,STAINED_GLASS:15)
Block(-3,7,-5,STAINED_GLASS:15)
Block(-2,7,-5,STAINED_GLASS:15)
Block(-1,7,-5,STAINED_GLASS:15)
Block(0,7,-5,SEA_LANTERN:0)
Block(1,7,-5,STAINED_GLASS:15)
Block(-3,7,-4,STAINED_GLASS:11)
Block(-2,7,-4,STAINED_GLASS:11)
Block(-1,7,-4,SEA_LANTERN:0)
Block(0,7,-4,SEA_LANTERN:0)
Block(1,7,-4,STAINED_GLASS:11)
Block(2,7,-4,STAINED_GLASS:11)
Block(-3,7,-3,STAINED_GLASS:11)
Block(-2,7,-3,STAINED_GLASS:11)
Block(-1,7,-3,SEA_LANTERN:0)
Block(0,7,-3,SEA_LANTERN:0)
Block(1,7,-3,SEA_LANTERN:0)
Block(2,7,-3,STAINED_GLASS:15)
Block(-2,7,-2,STAINED_GLASS:11)
Block(-1,7,-2,STAINED_GLASS:6)
Block(0,7,-2,STAINED_GLASS:15)
Block(1,7,-2,STAINED_GLASS:15)
Block(2,7,-2,STAINED_GLASS:15)
Block(-2,7,-1,STAINED_GLASS:11)
Block(-1,7,-1,STAINED_GLASS:11)
Block(0,7,-1,STAINED_GLASS:15)
Block(1,7,-1,STAINED_GLASS:15)
Block(1,8,-7,STAINED_GLASS:15)
Block(-3,8,-6,STAINED_GLASS:15)
Block(-2,8,-6,STAINED_GLASS:15)
Block(-1,8,-6,STAINED_GLASS:15)
Block(0,8,-6,STAINED_GLASS:11)
Block(1,8,-6,STAINED_GLASS:11)
Block(-3,8,-5,STAINED_GLASS:15)
Block(-2,8,-5,STAINED_GLASS:15)
Block(-1,8,-5,STAINED_GLASS:15)
Block(0,8,-5,SEA_LANTERN:0)
Block(1,8,-5,STAINED_GLASS:11)
Block(-3,8,-4,STAINED_GLASS:15)
Block(-2,8,-4,STAINED_GLASS:11)
Block(-1,8,-4,SEA_LANTERN:0)
Block(0,8,-4,SEA_LANTERN:0)
Block(1,8,-4,STAINED_GLASS:15)
Block(2,8,-4,STAINED_GLASS:15)
Block(-3,8,-3,STAINED_GLASS:11)
Block(-2,8,-3,STAINED_GLASS:11)
Block(-1,8,-3,SEA_LANTERN:0)
Block(0,8,-3,SEA_LANTERN:0)
Block(1,8,-3,STAINED_GLASS:6)
Block(2,8,-3,STAINED_GLASS:15)
Block(-2,8,-2,STAINED_GLASS:15)
Block(-1,8,-2,STAINED_GLASS:15)
Block(0,8,-2,STAINED_GLASS:15)
Block(1,8,-2,STAINED_GLASS:15)
Block(2,8,-2,STAINED_GLASS:15)
Block(-2,8,-1,STAINED_GLASS:15)
Block(-1,8,-1,STAINED_GLASS:15)
Block(0,8,-1,STAINED_GLASS:15)
Block(1,9,-7,STAINED_GLASS:11)
Block(-3,9,-6,STAINED_GLASS:11)
Block(-2,9,-6,STAINED_GLASS:15)
Block(-1,9,-6,SEA_LANTERN:0)
Block(0,9,-6,STAINED_GLASS:6)
Block(1,9,-6,STAINED_GLASS:11)
Block(-3,9,-5,STAINED_GLASS:11)
Block(-2,9,-5,STAINED_GLASS:11)
Block(-1,9,-5,SEA_LANTERN:0)
Block(0,9,-5,SEA_LANTERN:0)
Block(1,9,-5,STAINED_GLASS:11)
Block(-3,9,-4,STAINED_GLASS:15)
Block(-2,9,-4,STAINED_GLASS:15)
Block(-1,9,-4,SEA_LANTERN:0)
Block(0,9,-4,SEA_LANTERN:0)
Block(1,9,-4,STAINED_GLASS:11)
Block(2,9,-4,STAINED_GLASS:11)
Block(-3,9,-3,STAINED_GLASS:15)
Block(-2,9,-3,STAINED_GLASS:15)
Block(-1,9,-3,STAINED_GLASS:6)
Block(0,9,-3,SEA_LANTERN:0)
Block(1,9,-3,STAINED_GLASS:6)
Block(2,9,-3,STAINED_GLASS:15)
Block(-2,9,-2,STAINED_GLASS:15)
Block(-1,9,-2,STAINED_GLASS:15)
Block(-2,9,-1,STAINED_GLASS:15)
Block(-3,10,-7,STAINED_GLASS:11)
Block(-1,10,-7,STAINED_GLASS:15)
Block(0,10,-7,STAINED_GLASS:15)
Block(1,10,-7,STAINED_GLASS:15)
Block(-3,10,-6,STAINED_GLASS:11)
Block(-2,10,-6,STAINED_GLASS:6)
Block(-1,10,-6,SEA_LANTERN:0)
Block(0,10,-6,STAINED_GLASS:6)
Block(1,10,-6,STAINED_GLASS:11)
Block(-3,10,-5,STAINED_GLASS:11)
Block(-2,10,-5,STAINED_GLASS:11)
Block(-1,10,-5,SEA_LANTERN:0)
Block(0,10,-5,SEA_LANTERN:0)
Block(1,10,-5,STAINED_GLASS:11)
Block(-3,10,-4,STAINED_GLASS:11)
Block(-2,10,-4,STAINED_GLASS:15)
Block(-1,10,-4,SEA_LANTERN:0)
Block(0,10,-4,SEA_LANTERN:0)
Block(1,10,-4,STAINED_GLASS:15)
Block(2,10,-4,STAINED_GLASS:15)
Block(-3,10,-3,STAINED_GLASS:15)
Block(-2,10,-3,STAINED_GLASS:15)
Block(-1,10,-3,STAINED_GLASS:6)
Block(0,10,-3,STAINED_GLASS:15)
Block(1,10,-3,STAINED_GLASS:15)
Block(-1,10,-2,STAINED_GLASS:15)
Block(-1,11,-8,STAINED_GLASS:15)
Block(0,11,-8,STAINED_GLASS:15)
Block(-4,11,-7,STAINED_GLASS:11)
Block(-3,11,-7,STAINED_GLASS:11)
Block(-2,11,-7,STAINED_GLASS:11)
Block(-1,11,-7,STAINED_GLASS:11)
Block(0,11,-7,STAINED_GLASS:15)
Block(1,11,-7,STAINED_GLASS:11)
Block(-3,11,-6,STAINED_GLASS:11)
Block(-2,11,-6,STAINED_GLASS:6)
Block(-1,11,-6,SEA_LANTERN:0)
Block(0,11,-6,SEA_LANTERN:0)
Block(1,11,-6,STAINED_GLASS:11)
Block(-3,11,-5,STAINED_GLASS:11)
Block(-2,11,-5,STAINED_GLASS:11)
Block(-1,11,-5,SEA_LANTERN:0)
Block(0,11,-5,SEA_LANTERN:0)
Block(1,11,-5,STAINED_GLASS:11)
Block(-3,11,-4,STAINED_GLASS:15)
Block(-2,11,-4,STAINED_GLASS:15)
Block(-1,11,-4,SEA_LANTERN:0)
Block(0,11,-4,STAINED_GLASS:15)
Block(1,11,-4,STAINED_GLASS:11)
Block(2,11,-4,STAINED_GLASS:11)
Block(-3,11,-3,STAINED_GLASS:15)
Block(-2,11,-3,STAINED_GLASS:15)
Block(-1,11,-3,STAINED_GLASS:15)
Block(0,11,-3,STAINED_GLASS:15)
Block(1,11,-3,STAINED_GLASS:15)
Block(-1,12,-8,STAINED_GLASS:15)
Block(0,12,-8,STAINED_GLASS:11)
Block(-4,12,-7,STAINED_GLASS:11)
Block(-3,12,-7,STAINED_GLASS:11)
Block(-2,12,-7,STAINED_GLASS:11)
Block(-1,12,-7,SEA_LANTERN:0)
Block(0,12,-7,STAINED_GLASS:6)
Block(1,12,-7,STAINED_GLASS:15)
Block(-3,12,-6,STAINED_GLASS:11)
Block(-2,12,-6,STAINED_GLASS:6)
Block(-1,12,-6,SEA_LANTERN:0)
Block(0,12,-6,SEA_LANTERN:0)
Block(1,12,-6,STAINED_GLASS:11)
Block(-3,12,-5,STAINED_GLASS:15)
Block(-2,12,-5,STAINED_GLASS:15)
Block(-1,12,-5,SEA_LANTERN:0)
Block(0,12,-5,SEA_LANTERN:0)
Block(1,12,-5,STAINED_GLASS:11)
Block(-3,12,-4,STAINED_GLASS:15)
Block(-2,12,-4,STAINED_GLASS:15)
Block(-1,12,-4,SEA_LANTERN:0)
Block(0,12,-4,STAINED_GLASS:15)
Block(1,12,-4,STAINED_GLASS:15)
Block(2,12,-4,STAINED_GLASS:15)
Block(-3,12,-3,STAINED_GLASS:15)
Block(-2,12,-3,STAINED_GLASS:15)
Block(-1,12,-3,STAINED_GLASS:15)
Block(-3,13,-8,STAINED_GLASS:11)
Block(-2,13,-8,STAINED_GLASS:11)
Block(-1,13,-8,SEA_LANTERN:0)
Block(0,13,-8,STAINED_GLASS:11)
Block(-4,13,-7,STAINED_GLASS:11)
Block(-3,13,-7,STAINED_GLASS:11)
Block(-2,13,-7,STAINED_GLASS:6)
Block(-1,13,-7,SEA_LANTERN:0)
Block(0,13,-7,STAINED_GLASS:6)
Block(1,13,-7,STAINED_GLASS:11)
Block(-3,13,-6,STAINED_GLASS:15)
Block(-2,13,-6,SEA_LANTERN:0)
Block(-1,13,-6,SEA_LANTERN:0)
Block(0,13,-6,SEA_LANTERN:0)
Block(1,13,-6,STAINED_GLASS:15)
Block(-3,13,-5,STAINED_GLASS:15)
Block(-2,13,-5,STAINED_GLASS:15)
Block(-1,13,-5,SEA_LANTERN:0)
Block(0,13,-5,SEA_LANTERN:0)
Block(1,13,-5,STAINED_GLASS:15)
Block(-3,13,-4,STAINED_GLASS:15)
Block(-2,13,-4,STAINED_GLASS:15)
Block(-1,13,-4,STAINED_GLASS:15)
Block(0,13,-4,STAINED_GLASS:15)
Block(-1,13,-3,STAINED_GLASS:15)
Block(0,14,-10,STAINED_GLASS:15)
Block(-3,14,-9,STAINED_GLASS:11)
Block(-1,14,-9,STAINED_GLASS:15)
Block(0,14,-9,STAINED_GLASS:15)
Block(-4,14,-8,STAINED_GLASS:11)
Block(-3,14,-8,STAINED_GLASS:11)
Block(-2,14,-8,STAINED_GLASS:15)
Block(-1,14,-8,SEA_LANTERN:0)
Block(0,14,-8,STAINED_GLASS:11)
Block(-4,14,-7,STAINED_GLASS:11)
Block(-3,14,-7,STAINED_GLASS:15)
Block(-2,14,-7,STAINED_GLASS:6)
Block(-1,14,-7,SEA_LANTERN:0)
Block(0,14,-7,SEA_LANTERN:0)
Block(1,14,-7,STAINED_GLASS:15)
Block(-3,14,-6,STAINED_GLASS:15)
Block(-2,14,-6,SEA_LANTERN:0)
Block(-1,14,-6,SEA_LANTERN:0)
Block(0,14,-6,STAINED_GLASS:6)
Block(1,14,-6,STAINED_GLASS:15)
Block(-3,14,-5,STAINED_GLASS:15)
Block(-2,14,-5,STAINED_GLASS:15)
Block(-1,14,-5,SEA_LANTERN:0)
Block(0,14,-5,STAINED_GLASS:15)
Block(1,14,-5,STAINED_GLASS:15)
Block(-3,14,-4,STAINED_GLASS:15)
Block(-2,14,-4,STAINED_GLASS:15)
Block(-1,14,-4,STAINED_GLASS:15)
Block(0,15,-10,STAINED_GLASS:15)
Block(-3,15,-9,STAINED_GLASS:15)
Block(-1,15,-9,STAINED_GLASS:11)
Block(0,15,-9,STAINED_GLASS:15)
Block(-4,15,-8,STAINED_GLASS:15)
Block(-3,15,-8,STAINED_GLASS:15)
Block(-2,15,-8,SEA_LANTERN:0)
Block(-1,15,-8,SEA_LANTERN:0)
Block(0,15,-8,STAINED_GLASS:15)
Block(-4,15,-7,STAINED_GLASS:15)
Block(-3,15,-7,STAINED_GLASS:15)
Block(-2,15,-7,STAINED_GLASS:6)
Block(-1,15,-7,SEA_LANTERN:0)
Block(0,15,-7,SEA_LANTERN:0)
Block(1,15,-7,STAINED_GLASS:15)
Block(-3,15,-6,STAINED_GLASS:15)
Block(-2,15,-6,STAINED_GLASS:6)
Block(-1,15,-6,SEA_LANTERN:0)
Block(0,15,-6,STAINED_GLASS:6)
Block(1,15,-6,STAINED_GLASS:15)
Block(-3,15,-5,STAINED_GLASS:15)
Block(-2,15,-5,STAINED_GLASS:15)
Block(-1,15,-5,SEA_LANTERN:0)
Block(0,15,-5,STAINED_GLASS:15)
Block(1,15,-5,STAINED_GLASS:15)
Block(-3,15,-4,STAINED_GLASS:15)
Block(-2,16,-10,STAINED_GLASS:11)
Block(-1,16,-10,STAINED_GLASS:11)
Block(0,16,-10,STAINED_GLASS:11)
Block(-4,16,-9,STAINED_GLASS:11)
Block(-3,16,-9,STAINED_GLASS:6)
Block(-2,16,-9,STAINED_GLASS:11)
Block(-1,16,-9,SEA_LANTERN:0)
Block(0,16,-9,STAINED_GLASS:11)
Block(-4,16,-8,STAINED_GLASS:15)
Block(-3,16,-8,STAINED_GLASS:15)
Block(-2,16,-8,SEA_LANTERN:0)
Block(-1,16,-8,SEA_LANTERN:0)
Block(0,16,-8,STAINED_GLASS:11)
Block(-4,16,-7,STAINED_GLASS:15)
Block(-3,16,-7,STAINED_GLASS:15)
Block(-2,16,-7,SEA_LANTERN:0)
Block(-1,16,-7,SEA_LANTERN:0)
Block(0,16,-7,SEA_LANTERN:0)
Block(1,16,-7,STAINED_GLASS:15)
Block(-3,16,-6,STAINED_GLASS:15)
Block(-2,16,-6,STAINED_GLASS:6)
Block(-1,16,-6,STAINED_GLASS:15)
Block(0,16,-6,STAINED_GLASS:15)
Block(-3,16,-5,STAINED_GLASS:15)
Block(-2,16,-5,STAINED_GLASS:15)
Block(-1,16,-5,STAINED_GLASS:15)
Block(0,16,-5,STAINED_GLASS:15)
Block(0,17,-11,STAINED_GLASS:11)
Block(-4,17,-10,STAINED_GLASS:11)
Block(-3,17,-10,STAINED_GLASS:11)
Block(-2,17,-10,STAINED_GLASS:11)
Block(-1,17,-10,STAINED_GLASS:11)
Block(0,17,-10,STAINED_GLASS:11)
Block(-4,17,-9,STAINED_GLASS:11)
Block(-3,17,-9,STAINED_GLASS:6)
Block(-2,17,-9,STAINED_GLASS:11)
Block(-1,17,-9,SEA_LANTERN:0)
Block(0,17,-9,STAINED_GLASS:11)
Block(-4,17,-8,STAINED_GLASS:11)
Block(-3,17,-8,STAINED_GLASS:15)
Block(-2,17,-8,SEA_LANTERN:0)
Block(-1,17,-8,SEA_LANTERN:0)
Block(0,17,-8,STAINED_GLASS:11)
Block(-4,17,-7,STAINED_GLASS:15)
Block(-3,17,-7,STAINED_GLASS:15)
Block(-2,17,-7,SEA_LANTERN:0)
Block(-1,17,-7,SEA_LANTERN:0)
Block(0,17,-7,STAINED_GLASS:6)
Block(1,17,-7,STAINED_GLASS:11)
Block(-3,17,-6,STAINED_GLASS:15)
Block(-2,17,-6,STAINED_GLASS:6)
Block(-1,17,-6,STAINED_GLASS:15)
Block(0,17,-6,STAINED_GLASS:15)
Block(-3,17,-5,STAINED_GLASS:15)
Block(-2,17,-5,STAINED_GLASS:15)
Block(-1,17,-5,STAINED_GLASS:15)
Block(0,18,-11,STAINED_GLASS:15)
Block(-4,18,-10,STAINED_GLASS:11)
Block(-3,18,-10,STAINED_GLASS:15)
Block(-2,18,-10,SEA_LANTERN:0)
Block(-1,18,-10,STAINED_GLASS:6)
Block(0,18,-10,STAINED_GLASS:11)
Block(-4,18,-9,STAINED_GLASS:11)
Block(-3,18,-9,STAINED_GLASS:6)
Block(-2,18,-9,SEA_LANTERN:0)
Block(-1,18,-9,SEA_LANTERN:0)
Block(0,18,-9,STAINED_GLASS:11)
Block(-4,18,-8,STAINED_GLASS:15)
Block(-3,18,-8,STAINED_GLASS:15)
Block(-2,18,-8,SEA_LANTERN:0)
Block(-1,18,-8,SEA_LANTERN:0)
Block(0,18,-8,STAINED_GLASS:11)
Block(-4,18,-7,STAINED_GLASS:15)
Block(-3,18,-7,STAINED_GLASS:15)
Block(-2,18,-7,STAINED_GLASS:6)
Block(-1,18,-7,SEA_LANTERN:0)
Block(0,18,-7,STAINED_GLASS:6)
Block(1,18,-7,STAINED_GLASS:15)
Block(-3,18,-6,STAINED_GLASS:15)
Block(-2,18,-6,STAINED_GLASS:15)
Block(-4,19,-11,STAINED_GLASS:11)
Block(-3,19,-11,STAINED_GLASS:15)
Block(-2,19,-11,STAINED_GLASS:15)
Block(-1,19,-11,STAINED_GLASS:15)
Block(0,19,-11,STAINED_GLASS:15)
Block(-4,19,-10,STAINED_GLASS:15)
Block(-3,19,-10,STAINED_GLASS:15)
Block(-2,19,-10,SEA_LANTERN:0)
Block(-1,19,-10,STAINED_GLASS:6)
Block(0,19,-10,STAINED_GLASS:11)
Block(-4,19,-9,STAINED_GLASS:15)
Block(-3,19,-9,SEA_LANTERN:0)
Block(-2,19,-9,SEA_LANTERN:0)
Block(-1,19,-9,SEA_LANTERN:0)
Block(0,19,-9,STAINED_GLASS:11)
Block(-4,19,-8,STAINED_GLASS:15)
Block(-3,19,-8,STAINED_GLASS:15)
Block(-2,19,-8,SEA_LANTERN:0)
Block(-1,19,-8,SEA_LANTERN:0)
Block(0,19,-8,STAINED_GLASS:11)
Block(-4,19,-7,STAINED_GLASS:15)
Block(-3,19,-7,STAINED_GLASS:15)
Block(-2,19,-7,STAINED_GLASS:6)
Block(-1,19,-7,STAINED_GLASS:15)
Block(0,19,-7,STAINED_GLASS:11)
Block(-2,19,-6,STAINED_GLASS:15)
Block(-2,20,-12,STAINED_GLASS:15)
Block(-1,20,-12,STAINED_GLASS:15)
Block(-5,20,-11,STAINED_GLASS:11)
Block(-4,20,-11,STAINED_GLASS:11)
Block(-3,20,-11,STAINED_GLASS:15)
Block(-2,20,-11,STAINED_GLASS:15)
Block(-1,20,-11,STAINED_GLASS:15)
Block(0,20,-11,STAINED_GLASS:11)
Block(-4,20,-10,STAINED_GLASS:11)
Block(-3,20,-10,STAINED_GLASS:6)
Block(-2,20,-10,SEA_LANTERN:0)
Block(-1,20,-10,SEA_LANTERN:0)
Block(0,20,-10,STAINED_GLASS:11)
Block(-4,20,-9,STAINED_GLASS:15)
Block(-3,20,-9,SEA_LANTERN:0)
Block(-2,20,-9,SEA_LANTERN:0)
Block(-1,20,-9,SEA_LANTERN:0)
Block(0,20,-9,STAINED_GLASS:11)
Block(-4,20,-8,STAINED_GLASS:15)
Block(-3,20,-8,STAINED_GLASS:15)
Block(-2,20,-8,SEA_LANTERN:0)
Block(-1,20,-8,SEA_LANTERN:0)
Block(0,20,-8,STAINED_GLASS:11)
Block(-4,20,-7,STAINED_GLASS:15)
Block(-3,20,-7,STAINED_GLASS:15)
Block(-2,20,-7,STAINED_GLASS:6)
Block(-1,20,-7,STAINED_GLASS:15)
Block(0,20,-7,STAINED_GLASS:11)
Block(-2,21,-12,STAINED_GLASS:15)
Block(-1,21,-12,STAINED_GLASS:15)
Block(-5,21,-11,STAINED_GLASS:11)
Block(-4,21,-11,STAINED_GLASS:11)
Block(-3,21,-11,SEA_LANTERN:0)
Block(-2,21,-11,SEA_LANTERN:0)
Block(-1,21,-11,STAINED_GLASS:6)
Block(0,21,-11,STAINED_GLASS:15)
Block(-4,21,-10,STAINED_GLASS:15)
Block(-3,21,-10,STAINED_GLASS:6)
Block(-2,21,-10,SEA_LANTERN:0)
Block(-1,21,-10,SEA_LANTERN:0)
Block(0,21,-10,STAINED_GLASS:11)
Block(-4,21,-9,STAINED_GLASS:15)
Block(-3,21,-9,STAINED_GLASS:6)
Block(-2,21,-9,SEA_LANTERN:0)
Block(-1,21,-9,SEA_LANTERN:0)
Block(0,21,-9,STAINED_GLASS:11)
Block(-4,21,-8,STAINED_GLASS:15)
Block(-3,21,-8,STAINED_GLASS:15)
Block(-2,21,-8,SEA_LANTERN:0)
Block(-1,21,-8,STAINED_GLASS:15)
Block(0,21,-8,STAINED_GLASS:15)
Block(-4,21,-7,STAINED_GLASS:15)
Block(-2,21,-7,STAINED_GLASS:15)
Block(-3,22,-13,STAINED_GLASS:15)
Block(-1,22,-13,STAINED_GLASS:15)
Block(-4,22,-12,STAINED_GLASS:15)
Block(-3,22,-12,STAINED_GLASS:15)
Block(-2,22,-12,STAINED_GLASS:15)
Block(-1,22,-12,STAINED_GLASS:15)
Block(-5,22,-11,STAINED_GLASS:15)
Block(-4,22,-11,STAINED_GLASS:15)
Block(-3,22,-11,SEA_LANTERN:0)
Block(-2,22,-11,SEA_LANTERN:0)
Block(-1,22,-11,STAINED_GLASS:6)
Block(0,22,-11,STAINED_GLASS:11)
Block(-4,22,-10,STAINED_GLASS:15)
Block(-3,22,-10,SEA_LANTERN:0)
Block(-2,22,-10,SEA_LANTERN:0)
Block(-1,22,-10,SEA_LANTERN:0)
Block(0,22,-10,STAINED_GLASS:15)
Block(-4,22,-9,STAINED_GLASS:15)
Block(-3,22,-9,STAINED_GLASS:6)
Block(-2,22,-9,SEA_LANTERN:0)
Block(-1,22,-9,SEA_LANTERN:0)
Block(0,22,-9,STAINED_GLASS:15)
Block(-4,22,-8,STAINED_GLASS:15)
Block(-3,22,-8,STAINED_GLASS:15)
Block(-2,22,-8,STAINED_GLASS:15)
Block(-1,22,-8,STAINED_GLASS:15)
Block(-2,22,-7,STAINED_GLASS:15)
Block(-1,23,-14,STAINED_GLASS:15)
Block(-5,23,-13,STAINED_GLASS:11)
Block(-4,23,-13,STAINED_GLASS:15)
Block(-3,23,-13,STAINED_GLASS:15)
Block(-2,23,-13,STAINED_GLASS:15)
Block(-1,23,-13,STAINED_GLASS:15)
Block(-5,23,-12,STAINED_GLASS:11)
Block(-4,23,-12,STAINED_GLASS:11)
Block(-3,23,-12,STAINED_GLASS:15)
Block(-2,23,-12,SEA_LANTERN:0)
Block(-1,23,-12,STAINED_GLASS:11)
Block(-5,23,-11,STAINED_GLASS:15)
Block(-4,23,-11,STAINED_GLASS:15)
Block(-3,23,-11,SEA_LANTERN:0)
Block(-2,23,-11,SEA_LANTERN:0)
Block(-1,23,-11,SEA_LANTERN:0)
Block(0,23,-11,STAINED_GLASS:11)
Block(-4,23,-10,STAINED_GLASS:15)
Block(-3,23,-10,SEA_LANTERN:0)
Block(-2,23,-10,SEA_LANTERN:0)
Block(-1,23,-10,STAINED_GLASS:6)
Block(0,23,-10,STAINED_GLASS:11)
Block(-4,23,-9,STAINED_GLASS:15)
Block(-3,23,-9,STAINED_GLASS:6)
Block(-2,23,-9,SEA_LANTERN:0)
Block(-1,23,-9,SEA_LANTERN:0)
Block(0,23,-9,STAINED_GLASS:11)
Block(-4,23,-8,STAINED_GLASS:15)
Block(-3,23,-8,STAINED_GLASS:15)
Block(-2,23,-8,STAINED_GLASS:15)
Block(-1,24,-14,STAINED_GLASS:15)
Block(-5,24,-13,STAINED_GLASS:11)
Block(-4,24,-13,STAINED_GLASS:11)
Block(-3,24,-13,SEA_LANTERN:0)
Block(-2,24,-13,STAINED_GLASS:15)
Block(-1,24,-13,STAINED_GLASS:6)
Block(-5,24,-12,STAINED_GLASS:11)
Block(-4,24,-12,STAINED_GLASS:11)
Block(-3,24,-12,SEA_LANTERN:0)
Block(-2,24,-12,SEA_LANTERN:0)
Block(-1,24,-12,STAINED_GLASS:15)
Block(-5,24,-11,STAINED_GLASS:11)
Block(-4,24,-11,STAINED_GLASS:15)
Block(-3,24,-11,SEA_LANTERN:0)
Block(-2,24,-11,SEA_LANTERN:0)
Block(-1,24,-11,SEA_LANTERN:0)
Block(0,24,-11,STAINED_GLASS:11)
Block(-4,24,-10,STAINED_GLASS:15)
Block(-3,24,-10,STAINED_GLASS:6)
Block(-2,24,-10,SEA_LANTERN:0)
Block(-1,24,-10,STAINED_GLASS:6)
Block(0,24,-10,STAINED_GLASS:15)
Block(-4,24,-9,STAINED_GLASS:15)
Block(-3,24,-9,STAINED_GLASS:15)
Block(-2,24,-9,SEA_LANTERN:0)
Block(-1,24,-9,STAINED_GLASS:15)
Block(0,24,-9,STAINED_GLASS:15)
Block(-4,24,-8,STAINED_GLASS:15)
Block(-3,25,-14,STAINED_GLASS:15)
Block(-2,25,-14,STAINED_GLASS:15)
Block(-1,25,-14,STAINED_GLASS:15)
Block(-5,25,-13,STAINED_GLASS:11)
Block(-4,25,-13,STAINED_GLASS:15)
Block(-3,25,-13,SEA_LANTERN:0)
Block(-2,25,-13,STAINED_GLASS:15)
Block(-1,25,-13,STAINED_GLASS:6)
Block(-5,25,-12,STAINED_GLASS:11)
Block(-4,25,-12,STAINED_GLASS:11)
Block(-3,25,-12,SEA_LANTERN:0)
Block(-2,25,-12,SEA_LANTERN:0)
Block(-1,25,-12,STAINED_GLASS:15)
Block(-5,25,-11,STAINED_GLASS:15)
Block(-4,25,-11,STAINED_GLASS:15)
Block(-3,25,-11,SEA_LANTERN:0)
Block(-2,25,-11,SEA_LANTERN:0)
Block(-1,25,-11,SEA_LANTERN:0)
Block(0,25,-11,STAINED_GLASS:15)
Block(-4,25,-10,STAINED_GLASS:15)
Block(-3,25,-10,STAINED_GLASS:6)
Block(-2,25,-10,STAINED_GLASS:15)
Block(-1,25,-10,STAINED_GLASS:15)
Block(-4,25,-9,STAINED_GLASS:15)
Block(-3,25,-9,STAINED_GLASS:15)
Block(-2,25,-9,STAINED_GLASS:15)
Block(-1,25,-9,STAINED_GLASS:15)
Block(-3,26,-15,STAINED_GLASS:15)
Block(-1,26,-15,STAINED_GLASS:15)
Block(-5,26,-14,STAINED_GLASS:15)
Block(-4,26,-14,STAINED_GLASS:15)
Block(-3,26,-14,STAINED_GLASS:15)
Block(-2,26,-14,STAINED_GLASS:15)
Block(-1,26,-14,STAINED_GLASS:15)
Block(-5,26,-13,STAINED_GLASS:11)
Block(-4,26,-13,STAINED_GLASS:6)
Block(-3,26,-13,SEA_LANTERN:0)
Block(-2,26,-13,SEA_LANTERN:0)
Block(-1,26,-13,SEA_LANTERN:0)
Block(-5,26,-12,STAINED_GLASS:11)
Block(-4,26,-12,STAINED_GLASS:11)
Block(-3,26,-12,SEA_LANTERN:0)
Block(-2,26,-12,SEA_LANTERN:0)
Block(-1,26,-12,STAINED_GLASS:11)
Block(-5,26,-11,STAINED_GLASS:15)
Block(-4,26,-11,STAINED_GLASS:15)
Block(-3,26,-11,SEA_LANTERN:0)
Block(-2,26,-11,SEA_LANTERN:0)
Block(-1,26,-11,STAINED_GLASS:6)
Block(0,26,-11,STAINED_GLASS:15)
Block(-4,26,-10,STAINED_GLASS:15)
Block(-3,26,-10,STAINED_GLASS:6)
Block(-2,26,-10,STAINED_GLASS:15)
Block(-1,26,-10,STAINED_GLASS:15)
Block(-4,26,-9,STAINED_GLASS:15)
Block(-2,26,-9,STAINED_GLASS:15)
Block(-3,27,-15,STAINED_GLASS:15)
Block(-1,27,-15,STAINED_GLASS:15)
Block(-5,27,-14,STAINED_GLASS:11)
Block(-4,27,-14,STAINED_GLASS:15)
Block(-3,27,-14,SEA_LANTERN:0)
Block(-2,27,-14,STAINED_GLASS:6)
Block(-1,27,-14,STAINED_GLASS:11)
Block(-5,27,-13,STAINED_GLASS:11)
Block(-4,27,-13,STAINED_GLASS:6)
Block(-3,27,-13,SEA_LANTERN:0)
Block(-2,27,-13,SEA_LANTERN:0)
Block(-1,27,-13,SEA_LANTERN:0)
Block(-5,27,-12,STAINED_GLASS:11)
Block(-4,27,-12,STAINED_GLASS:11)
Block(-3,27,-12,SEA_LANTERN:0)
Block(-2,27,-12,SEA_LANTERN:0)
Block(-1,27,-12,STAINED_GLASS:11)
Block(-5,27,-11,STAINED_GLASS:11)
Block(-4,27,-11,STAINED_GLASS:15)
Block(-3,27,-11,SEA_LANTERN:0)
Block(-2,27,-11,SEA_LANTERN:0)
Block(-1,27,-11,STAINED_GLASS:6)
Block(0,27,-11,STAINED_GLASS:11)
Block(-4,27,-10,STAINED_GLASS:15)
Block(-3,27,-10,STAINED_GLASS:15)
Block(-5,28,-15,STAINED_GLASS:15)
Block(-4,28,-15,STAINED_GLASS:15)
Block(-3,28,-15,STAINED_GLASS:15)
Block(-2,28,-15,STAINED_GLASS:15)
Block(-1,28,-15,STAINED_GLASS:15)
Block(-5,28,-14,STAINED_GLASS:15)
Block(-4,28,-14,STAINED_GLASS:15)
Block(-3,28,-14,SEA_LANTERN:0)
Block(-2,28,-14,STAINED_GLASS:6)
Block(-1,28,-14,STAINED_GLASS:15)
Block(-5,28,-13,STAINED_GLASS:11)
Block(-4,28,-13,SEA_LANTERN:0)
Block(-3,28,-13,SEA_LANTERN:0)
Block(-2,28,-13,SEA_LANTERN:0)
Block(-1,28,-13,SEA_LANTERN:0)
Block(-5,28,-12,STAINED_GLASS:11)
Block(-4,28,-12,STAINED_GLASS:11)
Block(-3,28,-12,SEA_LANTERN:0)
Block(-2,28,-12,SEA_LANTERN:0)
Block(-1,28,-12,STAINED_GLASS:11)
Block(-5,28,-11,STAINED_GLASS:15)
Block(-4,28,-11,STAINED_GLASS:15)
Block(-3,28,-11,STAINED_GLASS:15)
Block(-2,28,-11,STAINED_GLASS:15)
Block(-1,28,-11,STAINED_GLASS:11)
Block(-3,28,-10,STAINED_GLASS:15)
Block(-3,29,-16,STAINED_GLASS:15)
Block(-2,29,-16,STAINED_GLASS:15)
Block(-6,29,-15,STAINED_GLASS:15)
Block(-5,29,-15,STAINED_GLASS:15)
Block(-4,29,-15,STAINED_GLASS:15)
Block(-3,29,-15,SEA_LANTERN:0)
Block(-2,29,-15,STAINED_GLASS:15)
Block(-1,29,-15,STAINED_GLASS:15)
Block(-5,29,-14,STAINED_GLASS:15)
Block(-4,29,-14,STAINED_GLASS:6)
Block(-3,29,-14,SEA_LANTERN:0)
Block(-2,29,-14,SEA_LANTERN:0)
Block(-1,29,-14,STAINED_GLASS:15)
Block(-5,29,-13,STAINED_GLASS:15)
Block(-4,29,-13,SEA_LANTERN:0)
Block(-3,29,-13,SEA_LANTERN:0)
Block(-2,29,-13,SEA_LANTERN:0)
Block(-1,29,-13,STAINED_GLASS:6)
Block(-5,29,-12,STAINED_GLASS:15)
Block(-4,29,-12,STAINED_GLASS:15)
Block(-3,29,-12,SEA_LANTERN:0)
Block(-2,29,-12,SEA_LANTERN:0)
Block(-1,29,-12,STAINED_GLASS:15)
Block(-5,29,-11,STAINED_GLASS:15)
Block(-4,29,-11,STAINED_GLASS:15)
Block(-3,29,-11,STAINED_GLASS:15)
Block(-2,29,-11,STAINED_GLASS:15)
Block(-1,29,-11,STAINED_GLASS:15)
Block(-3,30,-16,STAINED_GLASS:15)
Block(-2,30,-16,STAINED_GLASS:15)
Block(-6,30,-15,STAINED_GLASS:15)
Block(-5,30,-15,STAINED_GLASS:15)
Block(-4,30,-15,SEA_LANTERN:0)
Block(-3,30,-15,SEA_LANTERN:0)
Block(-2,30,-15,STAINED_GLASS:6)
Block(-1,30,-15,STAINED_GLASS:15)
Block(-5,30,-14,STAINED_GLASS:11)
Block(-4,30,-14,STAINED_GLASS:6)
Block(-3,30,-14,SEA_LANTERN:0)
Block(-2,30,-14,SEA_LANTERN:0)
Block(-1,30,-14,STAINED_GLASS:15)
Block(-5,30,-13,STAINED_GLASS:11)
Block(-4,30,-13,STAINED_GLASS:6)
Block(-3,30,-13,SEA_LANTERN:0)
Block(-2,30,-13,SEA_LANTERN:0)
Block(-1,30,-13,STAINED_GLASS:6)
Block(-5,30,-12,STAINED_GLASS:11)
Block(-4,30,-12,STAINED_GLASS:15)
Block(-3,30,-12,SEA_LANTERN:0)
Block(-2,30,-12,STAINED_GLASS:11)
Block(-1,30,-12,STAINED_GLASS:15)
Block(-5,30,-11,STAINED_GLASS:15)
Block(-4,31,-17,STAINED_GLASS:15)
Block(-3,31,-17,STAINED_GLASS:15)
Block(-2,31,-17,STAINED_GLASS:15)
Block(-5,31,-16,STAINED_GLASS:11)
Block(-4,31,-16,STAINED_GLASS:15)
Block(-3,31,-16,STAINED_GLASS:15)
Block(-2,31,-16,STAINED_GLASS:15)
Block(-6,31,-15,STAINED_GLASS:11)
Block(-5,31,-15,STAINED_GLASS:11)
Block(-4,31,-15,SEA_LANTERN:0)
Block(-3,31,-15,SEA_LANTERN:0)
Block(-2,31,-15,STAINED_GLASS:6)
Block(-1,31,-15,STAINED_GLASS:15)
Block(-5,31,-14,STAINED_GLASS:11)
Block(-4,31,-14,SEA_LANTERN:0)
Block(-3,31,-14,SEA_LANTERN:0)
Block(-2,31,-14,SEA_LANTERN:0)
Block(-1,31,-14,STAINED_GLASS:15)
Block(-5,31,-13,STAINED_GLASS:11)
Block(-4,31,-13,STAINED_GLASS:6)
Block(-3,31,-13,STAINED_GLASS:11)
Block(-2,31,-13,SEA_LANTERN:0)
Block(-1,31,-13,STAINED_GLASS:11)
Block(-5,31,-12,STAINED_GLASS:11)
Block(-4,31,-12,STAINED_GLASS:11)
Block(-3,31,-12,STAINED_GLASS:11)
Block(-2,31,-12,STAINED_GLASS:11)
Block(-2,32,-18,STAINED_GLASS:15)
Block(-6,32,-17,STAINED_GLASS:11)
Block(-5,32,-17,STAINED_GLASS:15)
Block(-4,32,-17,STAINED_GLASS:15)
Block(-3,32,-17,STAINED_GLASS:15)
Block(-2,32,-17,STAINED_GLASS:15)
Block(-6,32,-16,STAINED_GLASS:11)
Block(-5,32,-16,STAINED_GLASS:11)
Block(-4,32,-16,STAINED_GLASS:15)
Block(-3,32,-16,SEA_LANTERN:0)
Block(-2,32,-16,STAINED_GLASS:15)
Block(-6,32,-15,STAINED_GLASS:11)
Block(-5,32,-15,STAINED_GLASS:11)
Block(-4,32,-15,SEA_LANTERN:0)
Block(-3,32,-15,SEA_LANTERN:0)
Block(-2,32,-15,SEA_LANTERN:0)
Block(-1,32,-15,STAINED_GLASS:15)
Block(-5,32,-14,STAINED_GLASS:11)
Block(-4,32,-14,SEA_LANTERN:0)
Block(-3,32,-14,SEA_LANTERN:0)
Block(-2,32,-14,STAINED_GLASS:6)
Block(-1,32,-14,STAINED_GLASS:15)
Block(-5,32,-13,STAINED_GLASS:11)
Block(-4,32,-13,STAINED_GLASS:6)
Block(-3,32,-13,STAINED_GLASS:11)
Block(-2,32,-13,SEA_LANTERN:0)
Block(-1,32,-13,STAINED_GLASS:11)
Block(-5,32,-12,STAINED_GLASS:11)
Block(-4,32,-12,STAINED_GLASS:15)
Block(-3,32,-12,STAINED_GLASS:11)
Block(-2,33,-18,STAINED_GLASS:15)
Block(-6,33,-17,STAINED_GLASS:15)
Block(-5,33,-17,STAINED_GLASS:15)
Block(-4,33,-17,SEA_LANTERN:0)
Block(-3,33,-17,STAINED_GLASS:6)
Block(-2,33,-17,STAINED_GLASS:6)
Block(-6,33,-16,STAINED_GLASS:15)
Block(-5,33,-16,STAINED_GLASS:11)
Block(-4,33,-16,SEA_LANTERN:0)
Block(-3,33,-16,SEA_LANTERN:0)
Block(-2,33,-16,STAINED_GLASS:15)
Block(-6,33,-15,STAINED_GLASS:11)
Block(-5,33,-15,STAINED_GLASS:11)
Block(-4,33,-15,SEA_LANTERN:0)
Block(-3,33,-15,SEA_LANTERN:0)
Block(-2,33,-15,SEA_LANTERN:0)
Block(-1,33,-15,STAINED_GLASS:15)
Block(-5,33,-14,STAINED_GLASS:15)
Block(-4,33,-14,STAINED_GLASS:6)
Block(-3,33,-14,SEA_LANTERN:0)
Block(-2,33,-14,STAINED_GLASS:6)
Block(-1,33,-14,STAINED_GLASS:15)
Block(-5,33,-13,STAINED_GLASS:15)
Block(-4,33,-13,STAINED_GLASS:15)
Block(-3,33,-13,STAINED_GLASS:15)
Block(-2,33,-13,STAINED_GLASS:15)
Block(-5,33,-12,STAINED_GLASS:15)
Block(-3,33,-12,STAINED_GLASS:15)
Block(-4,34,-18,STAINED_GLASS:15)
Block(-3,34,-18,STAINED_GLASS:15)
Block(-2,34,-18,STAINED_GLASS:15)
Block(-6,34,-17,STAINED_GLASS:15)
Block(-5,34,-17,STAINED_GLASS:15)
Block(-4,34,-17,SEA_LANTERN:0)
Block(-3,34,-17,STAINED_GLASS:6)
Block(-2,34,-17,STAINED_GLASS:6)
Block(-6,34,-16,STAINED_GLASS:15)
Block(-5,34,-16,STAINED_GLASS:11)
Block(-4,34,-16,SEA_LANTERN:0)
Block(-3,34,-16,SEA_LANTERN:0)
Block(-2,34,-16,STAINED_GLASS:15)
Block(-6,34,-15,STAINED_GLASS:11)
Block(-5,34,-15,STAINED_GLASS:11)
Block(-4,34,-15,SEA_LANTERN:0)
Block(-3,34,-15,SEA_LANTERN:0)
Block(-2,34,-15,SEA_LANTERN:0)
Block(-1,34,-15,STAINED_GLASS:15)
Block(-5,34,-14,STAINED_GLASS:15)
Block(-4,34,-14,STAINED_GLASS:6)
Block(-3,34,-14,STAINED_GLASS:15)
Block(-2,34,-14,STAINED_GLASS:15)
Block(-4,34,-13,STAINED_GLASS:15)
Block(-2,34,-13,STAINED_GLASS:15)
Block(-4,35,-19,STAINED_GLASS:15)
Block(-3,35,-19,STAINED_GLASS:15)
Block(-2,35,-19,STAINED_GLASS:15)
Block(-7,35,-18,STAINED_GLASS:15)
Block(-6,35,-18,STAINED_GLASS:15)
Block(-5,35,-18,STAINED_GLASS:15)
Block(-4,35,-18,STAINED_GLASS:15)
Block(-3,35,-18,STAINED_GLASS:15)
Block(-2,35,-18,STAINED_GLASS:15)
Block(-6,35,-17,STAINED_GLASS:11)
Block(-5,35,-17,STAINED_GLASS:6)
Block(-4,35,-17,SEA_LANTERN:0)
Block(-3,35,-17,STAINED_GLASS:6)
Block(-2,35,-17,STAINED_GLASS:6)
Block(-6,35,-16,STAINED_GLASS:11)
Block(-5,35,-16,STAINED_GLASS:11)
Block(-4,35,-16,SEA_LANTERN:0)
Block(-3,35,-16,SEA_LANTERN:0)
Block(-2,35,-16,STAINED_GLASS:15)
Block(-6,35,-15,STAINED_GLASS:11)
Block(-5,35,-15,STAINED_GLASS:11)
Block(-4,35,-15,SEA_LANTERN:0)
Block(-3,35,-15,SEA_LANTERN:0)
Block(-2,35,-15,STAINED_GLASS:6)
Block(-1,35,-15,STAINED_GLASS:15)
Block(-5,35,-14,STAINED_GLASS:11)
Block(-4,35,-14,STAINED_GLASS:6)
Block(-3,35,-14,STAINED_GLASS:15)
Block(-2,35,-14,STAINED_GLASS:15)
Block(-4,36,-19,STAINED_GLASS:15)
Block(-3,36,-19,STAINED_GLASS:15)
Block(-2,36,-19,STAINED_GLASS:15)
Block(-7,36,-18,STAINED_GLASS:15)
Block(-6,36,-18,STAINED_GLASS:15)
Block(-5,36,-18,STAINED_GLASS:15)
Block(-4,36,-18,SEA_LANTERN:0)
Block(-3,36,-18,STAINED_GLASS:6)
Block(-2,36,-18,STAINED_GLASS:15)
Block(-6,36,-17,STAINED_GLASS:15)
Block(-5,36,-17,STAINED_GLASS:6)
Block(-4,36,-17,SEA_LANTERN:0)
Block(-3,36,-17,SEA_LANTERN:0)
Block(-2,36,-17,SEA_LANTERN:0)
Block(-6,36,-16,STAINED_GLASS:15)
Block(-5,36,-16,STAINED_GLASS:11)
Block(-4,36,-16,SEA_LANTERN:0)
Block(-3,36,-16,SEA_LANTERN:0)
Block(-2,36,-16,STAINED_GLASS:15)
Block(-6,36,-15,STAINED_GLASS:11)
Block(-5,36,-15,STAINED_GLASS:11)
Block(-4,36,-15,SEA_LANTERN:0)
Block(-3,36,-15,STAINED_GLASS:15)
Block(-2,36,-15,STAINED_GLASS:6)
Block(-1,36,-15,STAINED_GLASS:15)
Block(-5,36,-14,STAINED_GLASS:15)
Block(-4,36,-14,STAINED_GLASS:15)
Block(-3,36,-14,STAINED_GLASS:15)
Block(-6,37,-19,STAINED_GLASS:15)
Block(-5,37,-19,STAINED_GLASS:15)
Block(-4,37,-19,STAINED_GLASS:15)
Block(-3,37,-19,STAINED_GLASS:15)
Block(-2,37,-19,STAINED_GLASS:15)
Block(-7,37,-18,STAINED_GLASS:15)
Block(-6,37,-18,STAINED_GLASS:15)
Block(-5,37,-18,STAINED_GLASS:15)
Block(-4,37,-18,SEA_LANTERN:0)
Block(-3,37,-18,STAINED_GLASS:6)
Block(-2,37,-18,STAINED_GLASS:15)
Block(-6,37,-17,STAINED_GLASS:15)
Block(-5,37,-17,SEA_LANTERN:0)
Block(-4,37,-17,SEA_LANTERN:0)
Block(-3,37,-17,SEA_LANTERN:0)
Block(-2,37,-17,SEA_LANTERN:0)
Block(-6,37,-16,STAINED_GLASS:15)
Block(-5,37,-16,STAINED_GLASS:15)
Block(-4,37,-16,SEA_LANTERN:0)
Block(-3,37,-16,SEA_LANTERN:0)
Block(-2,37,-16,STAINED_GLASS:15)
Block(-6,37,-15,STAINED_GLASS:15)
Block(-5,37,-15,STAINED_GLASS:15)
Block(-4,37,-15,STAINED_GLASS:15)
Block(-3,37,-15,STAINED_GLASS:15)
Block(-2,37,-15,STAINED_GLASS:15)
Block(-4,37,-14,STAINED_GLASS:15)
Block(-3,38,-21,STAINED_GLASS:15)
Block(-4,38,-20,STAINED_GLASS:15)
Block(-3,38,-20,STAINED_GLASS:15)
Block(-7,38,-19,STAINED_GLASS:15)
Block(-6,38,-19,STAINED_GLASS:15)
Block(-5,38,-19,STAINED_GLASS:15)
Block(-4,38,-19,SEA_LANTERN:0)
Block(-3,38,-19,STAINED_GLASS:15)
Block(-2,38,-19,STAINED_GLASS:15)
Block(-7,38,-18,STAINED_GLASS:15)
Block(-6,38,-18,STAINED_GLASS:15)
Block(-5,38,-18,STAINED_GLASS:6)
Block(-4,38,-18,SEA_LANTERN:0)
Block(-3,38,-18,STAINED_GLASS:6)
Block(-2,38,-18,STAINED_GLASS:15)
Block(-6,38,-17,STAINED_GLASS:15)
Block(-5,38,-17,SEA_LANTERN:0)
Block(-4,38,-17,SEA_LANTERN:0)
Block(-3,38,-17,STAINED_GLASS:6)
Block(-2,38,-17,STAINED_GLASS:6)
Block(-6,38,-16,STAINED_GLASS:15)
Block(-5,38,-16,STAINED_GLASS:11)
Block(-4,38,-16,SEA_LANTERN:0)
Block(-3,38,-16,SEA_LANTERN:0)
Block(-2,38,-16,STAINED_GLASS:15)
Block(-6,38,-15,STAINED_GLASS:11)
Block(-5,38,-15,STAINED_GLASS:11)
Block(-4,38,-15,STAINED_GLASS:15)
Block(-2,38,-15,STAINED_GLASS:15)
Block(-3,39,-21,STAINED_GLASS:15)
Block(-4,39,-20,STAINED_GLASS:15)
Block(-3,39,-20,STAINED_GLASS:15)
Block(-7,39,-19,STAINED_GLASS:15)
Block(-6,39,-19,STAINED_GLASS:15)
Block(-5,39,-19,SEA_LANTERN:0)
Block(-4,39,-19,SEA_LANTERN:0)
Block(-3,39,-19,STAINED_GLASS:15)
Block(-2,39,-19,STAINED_GLASS:15)
Block(-7,39,-18,STAINED_GLASS:15)
Block(-6,39,-18,STAINED_GLASS:15)
Block(-5,39,-18,STAINED_GLASS:6)
Block(-4,39,-18,SEA_LANTERN:0)
Block(-3,39,-18,SEA_LANTERN:0)
Block(-2,39,-18,STAINED_GLASS:15)
Block(-6,39,-17,STAINED_GLASS:11)
Block(-5,39,-17,STAINED_GLASS:6)
Block(-4,39,-17,SEA_LANTERN:0)
Block(-3,39,-17,STAINED_GLASS:6)
Block(-2,39,-17,STAINED_GLASS:6)
Block(-6,39,-16,STAINED_GLASS:11)
Block(-5,39,-16,STAINED_GLASS:11)
Block(-4,39,-16,SEA_LANTERN:0)
Block(-3,39,-16,STAINED_GLASS:15)
Block(-2,39,-16,STAINED_GLASS:15)
Block(-6,39,-15,STAINED_GLASS:11)
Block(-4,39,-15,STAINED_GLASS:11)
Block(-5,40,-21,STAINED_GLASS:15)
Block(-4,40,-21,STAINED_GLASS:15)
Block(-3,40,-21,STAINED_GLASS:15)
Block(-7,40,-20,STAINED_GLASS:15)
Block(-6,40,-20,STAINED_GLASS:15)
Block(-5,40,-20,STAINED_GLASS:15)
Block(-4,40,-20,STAINED_GLASS:15)
Block(-3,40,-20,STAINED_GLASS:15)
Block(-7,40,-19,STAINED_GLASS:15)
Block(-6,40,-19,STAINED_GLASS:15)
Block(-5,40,-19,SEA_LANTERN:0)
Block(-4,40,-19,SEA_LANTERN:0)
Block(-3,40,-19,STAINED_GLASS:15)
Block(-2,40,-19,STAINED_GLASS:15)
Block(-7,40,-18,STAINED_GLASS:15)
Block(-6,40,-18,STAINED_GLASS:15)
Block(-5,40,-18,SEA_LANTERN:0)
Block(-4,40,-18,SEA_LANTERN:0)
Block(-3,40,-18,SEA_LANTERN:0)
Block(-2,40,-18,STAINED_GLASS:15)
Block(-6,40,-17,STAINED_GLASS:15)
Block(-5,40,-17,STAINED_GLASS:6)
Block(-4,40,-17,STAINED_GLASS:11)
Block(-3,40,-17,STAINED_GLASS:15)
Block(-2,40,-17,STAINED_GLASS:15)
Block(-6,40,-16,STAINED_GLASS:15)
Block(-5,40,-16,STAINED_GLASS:11)
Block(-4,40,-16,STAINED_GLASS:11)
Block(-3,40,-16,STAINED_GLASS:11)
Block(-6,41,-21,STAINED_GLASS:15)
Block(-5,41,-21,STAINED_GLASS:15)
Block(-4,41,-21,STAINED_GLASS:15)
Block(-3,41,-21,STAINED_GLASS:15)
Block(-7,41,-20,STAINED_GLASS:15)
Block(-6,41,-20,STAINED_GLASS:15)
Block(-5,41,-20,STAINED_GLASS:15)
Block(-4,41,-20,SEA_LANTERN:0)
Block(-3,41,-20,STAINED_GLASS:15)
Block(-7,41,-19,STAINED_GLASS:15)
Block(-6,41,-19,STAINED_GLASS:15)
Block(-5,41,-19,SEA_LANTERN:0)
Block(-4,41,-19,SEA_LANTERN:0)
Block(-3,41,-19,STAINED_GLASS:15)
Block(-2,41,-19,STAINED_GLASS:15)
Block(-7,41,-18,STAINED_GLASS:15)
Block(-6,41,-18,STAINED_GLASS:15)
Block(-5,41,-18,SEA_LANTERN:0)
Block(-4,41,-18,SEA_LANTERN:0)
Block(-3,41,-18,STAINED_GLASS:6)
Block(-2,41,-18,STAINED_GLASS:15)
Block(-6,41,-17,STAINED_GLASS:15)
Block(-5,41,-17,STAINED_GLASS:6)
Block(-4,41,-17,STAINED_GLASS:11)
Block(-3,41,-17,STAINED_GLASS:15)
Block(-2,41,-17,STAINED_GLASS:15)
Block(-6,41,-16,STAINED_GLASS:15)
Block(-5,41,-16,STAINED_GLASS:11)
Block(-4,41,-16,STAINED_GLASS:11)
Block(-6,42,-21,STAINED_GLASS:15)
Block(-5,42,-21,STAINED_GLASS:15)
Block(-4,42,-21,STAINED_GLASS:15)
Block(-3,42,-21,STAINED_GLASS:15)
Block(-7,42,-20,STAINED_GLASS:15)
Block(-6,42,-20,STAINED_GLASS:15)
Block(-5,42,-20,STAINED_GLASS:15)
Block(-4,42,-20,SEA_LANTERN:0)
Block(-3,42,-20,STAINED_GLASS:15)
Block(-7,42,-19,STAINED_GLASS:15)
Block(-6,42,-19,STAINED_GLASS:15)
Block(-5,42,-19,SEA_LANTERN:0)
Block(-4,42,-19,SEA_LANTERN:0)
Block(-3,42,-19,STAINED_GLASS:15)
Block(-2,42,-19,STAINED_GLASS:15)
Block(-7,42,-18,STAINED_GLASS:15)
Block(-6,42,-18,STAINED_GLASS:15)
Block(-5,42,-18,STAINED_GLASS:6)
Block(-4,42,-18,SEA_LANTERN:0)
Block(-3,42,-18,STAINED_GLASS:6)
Block(-2,42,-18,STAINED_GLASS:15)
Block(-6,42,-17,STAINED_GLASS:15)
Block(-5,42,-17,STAINED_GLASS:11)
Block(-4,42,-17,STAINED_GLASS:11)
Block(-6,42,-16,STAINED_GLASS:15)
Block(-4,42,-16,STAINED_GLASS:11)
Block(-6,43,-21,STAINED_GLASS:15)
Block(-5,43,-21,STAINED_GLASS:15)
Block(-4,43,-21,STAINED_GLASS:15)
Block(-7,43,-20,STAINED_GLASS:15)
Block(-6,43,-20,STAINED_GLASS:15)
Block(-5,43,-20,STAINED_GLASS:15)
Block(-4,43,-20,SEA_LANTERN:0)
Block(-6,43,-19,STAINED_GLASS:15)
Block(-5,43,-19,SEA_LANTERN:0)
Block(-4,43,-19,STAINED_GLASS:11)
Block(-5,43,-18,STAINED_GLASS:15)
Block(-4,43,-18,STAINED_GLASS:11)
Block(-3,43,-18,STAINED_GLASS:11)
Block(-5,43,-17,STAINED_GLASS:11)
Block(-6,44,-21,STAINED_GLASS:15)
Block(-5,44,-21,STAINED_GLASS:11)
Block(-4,44,-21,STAINED_GLASS:11)
Block(-7,44,-20,STAINED_GLASS:15)
Block(-6,44,-20,STAINED_GLASS:15)
Block(-5,44,-20,STAINED_GLASS:11)
Block(-4,44,-20,SEA_LANTERN:0)
Block(-6,44,-19,STAINED_GLASS:15)
Block(-5,44,-19,STAINED_GLASS:11)
Block(-4,44,-19,STAINED_GLASS:11)
Block(-5,44,-18,STAINED_GLASS:11)
Block(-5,45,-22,STAINED_GLASS:15)
Block(-6,45,-21,STAINED_GLASS:15)
Block(-5,45,-21,STAINED_GLASS:11)
Block(-4,45,-21,STAINED_GLASS:11)
Block(-7,45,-20,STAINED_GLASS:15)
Block(-6,45,-20,STAINED_GLASS:15)
Block(-5,45,-20,STAINED_GLASS:11)
Block(-4,45,-20,STAINED_GLASS:11)
Block(-6,45,-19,STAINED_GLASS:15)
Block(-5,45,-19,STAINED_GLASS:11)
Block(-5,46,-22,STAINED_GLASS:15)
Block(-6,46,-21,STAINED_GLASS:15)
Block(-5,46,-21,STAINED_GLASS:11)
Block(-5,46,-20,STAINED_GLASS:11)
Block(-4,46,-20,STAINED_GLASS:11)
Block(-5,47,-22,STAINED_GLASS:15)
Block(-5,47,-21,STAINED_GLASS:15)
Block(-5,47,-20,STAINED_GLASS:15)
Block(-5,48,-22,STAINED_GLASS:15)

#######################################################################
# +-----------------------------------------------------------------+ #
# |                            BO3 checks                           | #
# +-----------------------------------------------------------------+ #
#######################################################################

# Require a condition at a certain location in order for the BO3 to be spawned.
# BlockCheck(x,y,z,BlockName[,BlockName[,...]]) - one of the blocks must be at the location
# BlockCheckNot(x,y,z,BlockName[,BlockName[,...]]) - all the blocks must not be at the location
# LightCheck(x,y,z,minLightLevel,maxLightLevel) - light must be between min and max (inclusive)

# You can use "Solid" as a BlockName for matching all solid blocks or "All" to match all blocks that aren't air.

# Examples:
#   BlockCheck(0,-1,0,GRASS,DIRT)  Require grass or dirt just below the object
#   BlockCheck(0,-1,0,Solid)       Require any solid block just below the object
#   BlockCheck(0,-1,0,WOOL)        Require any type of wool just below the object
#   BlockCheck(0,-1,0,WOOL:0)      Require white wool just below the object
#   BlockCheckNot(0,-1,0,WOOL:0)   Require that there is no white wool below the object
#   LightCheck(0,0,0,0,1)          Require almost complete darkness just below the object

#######################################################################
# +-----------------------------------------------------------------+ #
# |                             Branches                            | #
# +-----------------------------------------------------------------+ #
#######################################################################

# Branches are objects that will spawn when this object spawns when it is used in
# the CustomStructure resource. Branches can also have branches, making complex
# structures possible. See the wiki for more details.

# Regular Branches spawn each branch with an independent chance of spawning.
# Branch(x,y,z,branchName,rotation,chance[,anotherBranchName,rotation,chance[,...]][IndividualChance])
# branchName - name of the object to spawn.
# rotation - NORTH, SOUTH, EAST or WEST.
# IndividualChance - The chance each branch has to spawn, assumed to be 100 when left blank

# Weighted Branches spawn branches with a dependent chance of spawning.
# WeightedBranch(x,y,z,branchName,rotation,chance[,anotherBranchName,rotation,chance[,...]][MaxChanceOutOf])
# MaxChanceOutOf - The chance all branches have to spawn out of, assumed to be 100 when left blank
