#######################################################################
# +-----------------------------------------------------------------+ #
# |                            BO3 object                           | #
# +-----------------------------------------------------------------+ #
#######################################################################

Author: Bo3 BulkEdit

Description: Converted Schematic - Modified by Bo3BulkEdit

Version: 3

SettingsMode: WriteDisable

#######################################################################
# +-----------------------------------------------------------------+ #
# |                          Main settings                          | #
# +-----------------------------------------------------------------+ #
#######################################################################

IsOTGPlus: true
Tree: false
Frequency: 1
Rarity: 100.0
RotateRandomly: false
SpawnHeight: randomY
MaxBranchDepth: 10
ExcludedBiomes: All

##############################
# Height Limits for the BO3. #
##############################

MinHeight: 0
MaxHeight: 255

#######################################################################
# +-----------------------------------------------------------------+ #
# |                      Source block settings                      | #
# +-----------------------------------------------------------------+ #
#######################################################################

CanOverride: true
MaxPercentageOutsideSourceBlock: 100
OutsideSourceBlock: placeAnyway

#######################################################################
# +-----------------------------------------------------------------+ #
# |                               OTG+                              | #
# +-----------------------------------------------------------------+ #
#######################################################################

BO3Group: CeilingCrystals:0

#######################################################################
# +-----------------------------------------------------------------+ #
# |                              Blocks                             | #
# +-----------------------------------------------------------------+ #
#######################################################################

B(0,750,0,AIR)
B(15,750,15,AIR)
B(9,-19,15,STAINED_GLASS:15)
B(7,-18,13,STAINED_GLASS:15)
B(6,-18,14,STAINED_GLASS:15)
B(7,-18,14,STAINED_GLASS:15)
B(8,-18,14,STAINED_GLASS:15)
B(5,-18,15,STAINED_GLASS:6)
B(6,-18,15,STAINED_GLASS:15)
B(7,-18,15,STAINED_GLASS:15)
B(8,-18,15,STAINED_GLASS:15)
B(9,-18,15,STAINED_GLASS:15)
B(6,-17,11,STAINED_GLASS:15)
B(7,-17,11,STAINED_GLASS:15)
B(5,-17,12,STAINED_GLASS:15)
B(6,-17,12,STAINED_GLASS:15)
B(7,-17,12,STAINED_GLASS:15)
B(4,-17,13,STAINED_GLASS:6)
B(5,-17,13,STAINED_GLASS:15)
B(6,-17,13,STAINED_GLASS:15)
B(7,-17,13,STAINED_GLASS:15)
B(3,-17,14,STAINED_GLASS:6)
B(4,-17,14,STAINED_GLASS:6)
B(5,-17,14,STAINED_GLASS:6)
B(6,-17,14,STAINED_GLASS:15)
B(7,-17,14,STAINED_GLASS:11)
B(8,-17,14,STAINED_GLASS:15)
B(4,-17,15,STAINED_GLASS:6)
B(5,-17,15,STAINED_GLASS:6)
B(6,-17,15,SEA_LANTERN)
B(7,-17,15,STAINED_GLASS:11)
B(8,-17,15,STAINED_GLASS:6)
B(9,-17,15,STAINED_GLASS:6)
B(5,-16,10,STAINED_GLASS:15)
B(6,-16,10,STAINED_GLASS:15)
B(3,-16,11,STAINED_GLASS:6)
B(4,-16,11,STAINED_GLASS:15)
B(5,-16,11,STAINED_GLASS:15)
B(6,-16,11,STAINED_GLASS:15)
B(7,-16,11,STAINED_GLASS:15)
B(2,-16,12,STAINED_GLASS:6)
B(3,-16,12,STAINED_GLASS:6)
B(4,-16,12,STAINED_GLASS:6)
B(5,-16,12,STAINED_GLASS:15)
B(6,-16,12,STAINED_GLASS:15)
B(7,-16,12,STAINED_GLASS:15)
B(2,-16,13,STAINED_GLASS:6)
B(3,-16,13,STAINED_GLASS:6)
B(4,-16,13,STAINED_GLASS:6)
B(5,-16,13,SEA_LANTERN)
B(6,-16,13,STAINED_GLASS:14)
B(7,-16,13,STAINED_GLASS:6)
B(3,-16,14,STAINED_GLASS:6)
B(4,-16,14,STAINED_GLASS:11)
B(5,-16,14,STAINED_GLASS:11)
B(6,-16,14,SEA_LANTERN)
B(7,-16,14,SEA_LANTERN)
B(8,-16,14,STAINED_GLASS:6)
B(4,-16,15,STAINED_GLASS:6)
B(5,-16,15,STAINED_GLASS:11)
B(6,-16,15,STAINED_GLASS:15)
B(7,-16,15,SEA_LANTERN)
B(8,-16,15,STAINED_GLASS:6)
B(9,-16,15,STAINED_GLASS:6)
B(4,-15,8,STAINED_GLASS:6)
B(3,-15,9,STAINED_GLASS:6)
B(4,-15,9,STAINED_GLASS:6)
B(5,-15,9,STAINED_GLASS:15)
B(1,-15,10,STAINED_GLASS:15)
B(2,-15,10,STAINED_GLASS:6)
B(3,-15,10,STAINED_GLASS:6)
B(4,-15,10,STAINED_GLASS:6)
B(5,-15,10,STAINED_GLASS:15)
B(6,-15,10,STAINED_GLASS:15)
B(1,-15,11,STAINED_GLASS:6)
B(2,-15,11,STAINED_GLASS:6)
B(3,-15,11,STAINED_GLASS:6)
B(4,-15,11,STAINED_GLASS:11)
B(5,-15,11,STAINED_GLASS:15)
B(6,-15,11,STAINED_GLASS:15)
B(7,-15,11,STAINED_GLASS:15)
B(2,-15,12,STAINED_GLASS:6)
B(3,-15,12,STAINED_GLASS:11)
B(4,-15,12,SEA_LANTERN)
B(5,-15,12,STAINED_GLASS:14)
B(6,-15,12,STAINED_GLASS:15)
B(7,-15,12,STAINED_GLASS:6)
B(2,-15,13,STAINED_GLASS:6)
B(3,-15,13,STAINED_GLASS:11)
B(4,-15,13,STAINED_GLASS:11)
B(5,-15,13,SEA_LANTERN)
B(6,-15,13,SEA_LANTERN)
B(7,-15,13,STAINED_GLASS:6)
B(3,-15,14,STAINED_GLASS:6)
B(4,-15,14,STAINED_GLASS:6)
B(5,-15,14,STAINED_GLASS:15)
B(6,-15,14,STAINED_GLASS:15)
B(7,-15,14,STAINED_GLASS:14)
B(8,-15,14,STAINED_GLASS:6)
B(4,-15,15,STAINED_GLASS:15)
B(5,-15,15,STAINED_GLASS:15)
B(6,-15,15,STAINED_GLASS:15)
B(7,-15,15,STAINED_GLASS:14)
B(8,-15,15,STAINED_GLASS:6)
B(9,-15,15,STAINED_GLASS:6)
B(1,-14,7,STAINED_GLASS:15)
B(2,-14,7,STAINED_GLASS:6)
B(3,-14,7,STAINED_GLASS:6)
B(0,-14,8,STAINED_GLASS:15)
B(1,-14,8,STAINED_GLASS:15)
B(2,-14,8,STAINED_GLASS:6)
B(3,-14,8,STAINED_GLASS:6)
B(4,-14,8,STAINED_GLASS:6)
B(0,-14,9,STAINED_GLASS:15)
B(1,-14,9,STAINED_GLASS:15)
B(2,-14,9,STAINED_GLASS:6)
B(3,-14,9,STAINED_GLASS:6)
B(4,-14,9,STAINED_GLASS:6)
B(5,-14,9,STAINED_GLASS:15)
B(1,-14,10,STAINED_GLASS:15)
B(2,-14,10,STAINED_GLASS:15)
B(3,-14,10,SEA_LANTERN)
B(4,-14,10,STAINED_GLASS:11)
B(5,-14,10,STAINED_GLASS:15)
B(6,-14,10,STAINED_GLASS:15)
B(1,-14,11,STAINED_GLASS:15)
B(2,-14,11,STAINED_GLASS:11)
B(3,-14,11,SEA_LANTERN)
B(4,-14,11,STAINED_GLASS:15)
B(5,-14,11,STAINED_GLASS:15)
B(6,-14,11,STAINED_GLASS:15)
B(7,-14,11,STAINED_GLASS:15)
B(2,-14,12,STAINED_GLASS:11)
B(3,-14,12,STAINED_GLASS:15)
B(4,-14,12,STAINED_GLASS:15)
B(5,-14,12,STAINED_GLASS:15)
B(6,-14,12,STAINED_GLASS:15)
B(7,-14,12,STAINED_GLASS:6)
B(2,-14,13,STAINED_GLASS:15)
B(3,-14,13,STAINED_GLASS:15)
B(4,-14,13,STAINED_GLASS:15)
B(5,-14,13,SEA_LANTERN)
B(6,-14,13,STAINED_GLASS:14)
B(7,-14,13,STAINED_GLASS:6)
B(3,-14,14,STAINED_GLASS:15)
B(4,-14,14,STAINED_GLASS:14)
B(5,-14,14,STAINED_GLASS:14)
B(6,-14,14,STAINED_GLASS:6)
B(7,-14,14,STAINED_GLASS:14)
B(8,-14,14,STAINED_GLASS:6)
B(4,-14,15,STAINED_GLASS:15)
B(5,-14,15,STAINED_GLASS:14)
B(6,-14,15,STAINED_GLASS:15)
B(7,-14,15,STAINED_GLASS:14)
B(8,-14,15,STAINED_GLASS:6)
B(9,-14,15,STAINED_GLASS:15)
B(2,-13,4,STAINED_GLASS:6)
B(0,-13,5,STAINED_GLASS:15)
B(1,-13,5,STAINED_GLASS:6)
B(2,-13,5,STAINED_GLASS:6)
B(0,-13,6,STAINED_GLASS:15)
B(1,-13,6,STAINED_GLASS:6)
B(2,-13,6,STAINED_GLASS:6)
B(0,-13,7,STAINED_GLASS:15)
B(1,-13,7,STAINED_GLASS:15)
B(2,-13,7,STAINED_GLASS:6)
B(3,-13,7,STAINED_GLASS:6)
B(0,-13,8,STAINED_GLASS:15)
B(1,-13,8,STAINED_GLASS:11)
B(2,-13,8,STAINED_GLASS:11)
B(3,-13,8,STAINED_GLASS:6)
B(4,-13,8,STAINED_GLASS:6)
B(0,-13,9,STAINED_GLASS:15)
B(1,-13,9,STAINED_GLASS:11)
B(2,-13,9,SEA_LANTERN)
B(3,-13,9,STAINED_GLASS:11)
B(4,-13,9,STAINED_GLASS:15)
B(5,-13,9,STAINED_GLASS:15)
B(1,-13,10,STAINED_GLASS:15)
B(2,-13,10,STAINED_GLASS:11)
B(3,-13,10,SEA_LANTERN)
B(4,-13,10,STAINED_GLASS:15)
B(5,-13,10,STAINED_GLASS:15)
B(6,-13,10,STAINED_GLASS:15)
B(1,-13,11,STAINED_GLASS:15)
B(2,-13,11,SEA_LANTERN)
B(3,-13,11,SEA_LANTERN)
B(4,-13,11,STAINED_GLASS:14)
B(5,-13,11,STAINED_GLASS:6)
B(6,-13,11,STAINED_GLASS:15)
B(7,-13,11,STAINED_GLASS:15)
B(2,-13,12,STAINED_GLASS:15)
B(3,-13,12,STAINED_GLASS:14)
B(4,-13,12,STAINED_GLASS:6)
B(5,-13,12,STAINED_GLASS:14)
B(6,-13,12,STAINED_GLASS:6)
B(7,-13,12,STAINED_GLASS:6)
B(2,-13,13,STAINED_GLASS:15)
B(3,-13,13,STAINED_GLASS:14)
B(4,-13,13,STAINED_GLASS:14)
B(5,-13,13,STAINED_GLASS:6)
B(6,-13,13,STAINED_GLASS:6)
B(7,-13,13,STAINED_GLASS:6)
B(3,-13,14,STAINED_GLASS:15)
B(4,-13,14,STAINED_GLASS:14)
B(5,-13,14,STAINED_GLASS:6)
B(6,-13,14,STAINED_GLASS:6)
B(7,-13,14,STAINED_GLASS:6)
B(8,-13,14,STAINED_GLASS:6)
B(4,-13,15,STAINED_GLASS:15)
B(5,-13,15,STAINED_GLASS:15)
B(6,-13,15,STAINED_GLASS:6)
B(7,-13,15,STAINED_GLASS:6)
B(0,-12,3,STAINED_GLASS:15)
B(1,-12,3,STAINED_GLASS:6)
B(0,-12,4,STAINED_GLASS:15)
B(1,-12,4,STAINED_GLASS:15)
B(2,-12,4,STAINED_GLASS:15)
B(0,-12,5,STAINED_GLASS:15)
B(1,-12,5,STAINED_GLASS:11)
B(2,-12,5,STAINED_GLASS:6)
B(0,-12,6,SEA_LANTERN)
B(1,-12,6,STAINED_GLASS:11)
B(2,-12,6,STAINED_GLASS:6)
B(0,-12,7,STAINED_GLASS:11)
B(1,-12,7,SEA_LANTERN)
B(2,-12,7,STAINED_GLASS:14)
B(3,-12,7,STAINED_GLASS:6)
B(0,-12,8,STAINED_GLASS:11)
B(1,-12,8,SEA_LANTERN)
B(2,-12,8,SEA_LANTERN)
B(3,-12,8,STAINED_GLASS:6)
B(4,-12,8,STAINED_GLASS:15)
B(0,-12,9,STAINED_GLASS:15)
B(1,-12,9,STAINED_GLASS:15)
B(2,-12,9,SEA_LANTERN)
B(3,-12,9,STAINED_GLASS:15)
B(4,-12,9,STAINED_GLASS:15)
B(5,-12,9,STAINED_GLASS:15)
B(1,-12,10,STAINED_GLASS:15)
B(2,-12,10,STAINED_GLASS:15)
B(3,-12,10,STAINED_GLASS:15)
B(4,-12,10,STAINED_GLASS:14)
B(5,-12,10,STAINED_GLASS:6)
B(6,-12,10,STAINED_GLASS:6)
B(1,-12,11,STAINED_GLASS:15)
B(2,-12,11,STAINED_GLASS:14)
B(3,-12,11,STAINED_GLASS:6)
B(4,-12,11,STAINED_GLASS:14)
B(5,-12,11,STAINED_GLASS:6)
B(6,-12,11,STAINED_GLASS:6)
B(7,-12,11,STAINED_GLASS:6)
B(2,-12,12,STAINED_GLASS:11)
B(3,-12,12,STAINED_GLASS:14)
B(4,-12,12,STAINED_GLASS:6)
B(5,-12,12,STAINED_GLASS:6)
B(6,-12,12,STAINED_GLASS:6)
B(2,-12,13,STAINED_GLASS:15)
B(3,-12,13,STAINED_GLASS:6)
B(4,-12,13,STAINED_GLASS:6)
B(5,-12,13,STAINED_GLASS:6)
B(3,-12,14,STAINED_GLASS:15)
B(4,-12,14,STAINED_GLASS:6)
B(0,-11,2,STAINED_GLASS:6)
B(0,-11,3,STAINED_GLASS:6)
B(1,-11,3,STAINED_GLASS:6)
B(0,-11,4,STAINED_GLASS:14)
B(1,-11,4,STAINED_GLASS:14)
B(2,-11,4,STAINED_GLASS:6)
B(0,-11,5,STAINED_GLASS:11)
B(1,-11,5,STAINED_GLASS:15)
B(2,-11,5,STAINED_GLASS:6)
B(0,-11,6,SEA_LANTERN)
B(1,-11,6,STAINED_GLASS:15)
B(2,-11,6,STAINED_GLASS:6)
B(0,-11,7,STAINED_GLASS:15)
B(1,-11,7,SEA_LANTERN)
B(2,-11,7,STAINED_GLASS:15)
B(3,-11,7,STAINED_GLASS:6)
B(0,-11,8,STAINED_GLASS:15)
B(1,-11,8,STAINED_GLASS:14)
B(2,-11,8,STAINED_GLASS:14)
B(3,-11,8,STAINED_GLASS:6)
B(4,-11,8,STAINED_GLASS:6)
B(0,-11,9,STAINED_GLASS:15)
B(1,-11,9,STAINED_GLASS:14)
B(2,-11,9,STAINED_GLASS:15)
B(3,-11,9,STAINED_GLASS:14)
B(4,-11,9,STAINED_GLASS:6)
B(5,-11,9,STAINED_GLASS:6)
B(1,-11,10,STAINED_GLASS:15)
B(2,-11,10,STAINED_GLASS:14)
B(3,-11,10,STAINED_GLASS:15)
B(4,-11,10,STAINED_GLASS:6)
B(5,-11,10,STAINED_GLASS:6)
B(6,-11,10,STAINED_GLASS:6)
B(1,-11,11,STAINED_GLASS:15)
B(2,-11,11,STAINED_GLASS:6)
B(3,-11,11,STAINED_GLASS:6)
B(4,-11,11,STAINED_GLASS:6)
B(2,-11,12,STAINED_GLASS:6)
B(3,-11,12,STAINED_GLASS:6)
B(2,-11,13,STAINED_GLASS:6)
B(0,-10,2,STAINED_GLASS:6)
B(0,-10,3,STAINED_GLASS:14)
B(1,-10,3,STAINED_GLASS:6)
B(0,-10,4,STAINED_GLASS:15)
B(1,-10,4,STAINED_GLASS:6)
B(2,-10,4,STAINED_GLASS:6)
B(0,-10,5,SEA_LANTERN)
B(1,-10,5,STAINED_GLASS:14)
B(2,-10,5,STAINED_GLASS:6)
B(0,-10,6,SEA_LANTERN)
B(1,-10,6,STAINED_GLASS:14)
B(2,-10,6,STAINED_GLASS:6)
B(0,-10,7,STAINED_GLASS:14)
B(1,-10,7,STAINED_GLASS:15)
B(2,-10,7,STAINED_GLASS:14)
B(3,-10,7,STAINED_GLASS:6)
B(0,-10,8,STAINED_GLASS:14)
B(1,-10,8,STAINED_GLASS:15)
B(2,-10,8,STAINED_GLASS:14)
B(3,-10,8,STAINED_GLASS:6)
B(4,-10,8,STAINED_GLASS:6)
B(0,-10,9,STAINED_GLASS:15)
B(1,-10,9,STAINED_GLASS:15)
B(2,-10,9,STAINED_GLASS:6)
B(3,-10,9,STAINED_GLASS:6)
B(4,-10,9,STAINED_GLASS:6)
B(1,-10,10,STAINED_GLASS:15)
B(2,-10,10,STAINED_GLASS:15)
B(3,-10,10,STAINED_GLASS:6)
B(0,-9,2,STAINED_GLASS:6)
B(0,-9,3,STAINED_GLASS:6)
B(1,-9,3,STAINED_GLASS:6)
B(0,-9,4,STAINED_GLASS:14)
B(1,-9,4,STAINED_GLASS:14)
B(2,-9,4,STAINED_GLASS:6)
B(0,-9,5,STAINED_GLASS:14)
B(1,-9,5,STAINED_GLASS:6)
B(2,-9,5,STAINED_GLASS:6)
B(0,-9,6,STAINED_GLASS:15)
B(1,-9,6,STAINED_GLASS:6)
B(2,-9,6,STAINED_GLASS:6)
B(0,-9,7,STAINED_GLASS:15)
B(1,-9,7,STAINED_GLASS:15)
B(2,-9,7,STAINED_GLASS:6)
B(3,-9,7,STAINED_GLASS:6)
B(0,-9,8,STAINED_GLASS:15)
B(1,-9,8,STAINED_GLASS:15)
B(2,-9,8,STAINED_GLASS:6)
B(0,-9,9,STAINED_GLASS:15)
B(0,-8,2,STAINED_GLASS:6)
B(0,-8,3,STAINED_GLASS:14)
B(1,-8,3,STAINED_GLASS:6)
B(0,-8,4,STAINED_GLASS:6)
B(1,-8,4,STAINED_GLASS:6)
B(2,-8,4,STAINED_GLASS:6)
B(0,-8,5,STAINED_GLASS:6)
B(1,-8,5,STAINED_GLASS:6)
B(0,-8,6,STAINED_GLASS:15)
B(0,-7,2,STAINED_GLASS:6)
B(0,-7,3,STAINED_GLASS:6)
B(1,-7,3,STAINED_GLASS:6)
B(0,-7,4,STAINED_GLASS:6)

