#######################################################################
# +-----------------------------------------------------------------+ #
# |                            BO3 object                           | #
# +-----------------------------------------------------------------+ #
#######################################################################

Author: Bo3 BulkEdit

Description: Converted Schematic - Modified by Bo3BulkEdit

Version: 3

SettingsMode: WriteDisable

#######################################################################
# +-----------------------------------------------------------------+ #
# |                          Main settings                          | #
# +-----------------------------------------------------------------+ #
#######################################################################

IsOTGPlus: true
Tree: false
Frequency: 1
Rarity: 100.0
RotateRandomly: false
SpawnHeight: randomY
MaxBranchDepth: 10
ExcludedBiomes: All

##############################
# Height Limits for the BO3. #
##############################

MinHeight: 0
MaxHeight: 255

#######################################################################
# +-----------------------------------------------------------------+ #
# |                      Source block settings                      | #
# +-----------------------------------------------------------------+ #
#######################################################################

CanOverride: true
MaxPercentageOutsideSourceBlock: 100
OutsideSourceBlock: placeAnyway

#######################################################################
# +-----------------------------------------------------------------+ #
# |                               OTG+                              | #
# +-----------------------------------------------------------------+ #
#######################################################################

BO3Group: CeilingCrystals:0

#######################################################################
# +-----------------------------------------------------------------+ #
# |                              Blocks                             | #
# +-----------------------------------------------------------------+ #
#######################################################################

B(0,750,0,AIR)
B(15,750,15,AIR)
B(9,-20,1,STAINED_GLASS:15)
B(10,-20,1,STAINED_GLASS:15)
B(11,-20,1,STAINED_GLASS:15)
B(8,-20,2,STAINED_GLASS:15)
B(9,-20,2,STAINED_GLASS:15)
B(10,-20,2,STAINED_GLASS:15)
B(11,-20,2,STAINED_GLASS:15)
B(8,-20,3,STAINED_GLASS:6)
B(9,-20,3,STAINED_GLASS:15)
B(10,-20,3,STAINED_GLASS:15)
B(8,-20,4,STAINED_GLASS:6)
B(9,-20,4,STAINED_GLASS:6)
B(10,-20,4,STAINED_GLASS:15)
B(10,-20,5,STAINED_GLASS:6)
B(11,-20,5,STAINED_GLASS:6)
B(8,-19,0,STAINED_GLASS:15)
B(9,-19,0,STAINED_GLASS:15)
B(10,-19,0,STAINED_GLASS:15)
B(5,-19,1,STAINED_GLASS:6)
B(6,-19,1,STAINED_GLASS:6)
B(7,-19,1,STAINED_GLASS:15)
B(8,-19,1,STAINED_GLASS:15)
B(9,-19,1,STAINED_GLASS:15)
B(10,-19,1,STAINED_GLASS:15)
B(11,-19,1,STAINED_GLASS:15)
B(6,-19,2,STAINED_GLASS:6)
B(7,-19,2,STAINED_GLASS:6)
B(8,-19,2,STAINED_GLASS:15)
B(9,-19,2,STAINED_GLASS:11)
B(10,-19,2,STAINED_GLASS:6)
B(11,-19,2,STAINED_GLASS:6)
B(7,-19,3,STAINED_GLASS:6)
B(8,-19,3,SEA_LANTERN)
B(9,-19,3,SEA_LANTERN)
B(10,-19,3,STAINED_GLASS:11)
B(11,-19,3,STAINED_GLASS:6)
B(12,-19,3,STAINED_GLASS:6)
B(7,-19,4,STAINED_GLASS:6)
B(8,-19,4,STAINED_GLASS:11)
B(9,-19,4,SEA_LANTERN)
B(10,-19,4,SEA_LANTERN)
B(11,-19,4,STAINED_GLASS:6)
B(8,-19,5,STAINED_GLASS:6)
B(9,-19,5,STAINED_GLASS:6)
B(10,-19,5,STAINED_GLASS:15)
B(11,-19,5,STAINED_GLASS:15)
B(9,-19,6,STAINED_GLASS:6)
B(5,-18,0,STAINED_GLASS:6)
B(6,-18,0,STAINED_GLASS:6)
B(7,-18,0,STAINED_GLASS:15)
B(8,-18,0,STAINED_GLASS:15)
B(9,-18,0,STAINED_GLASS:15)
B(10,-18,0,STAINED_GLASS:15)
B(5,-18,1,STAINED_GLASS:6)
B(6,-18,1,STAINED_GLASS:11)
B(7,-18,1,SEA_LANTERN)
B(8,-18,1,STAINED_GLASS:11)
B(9,-18,1,STAINED_GLASS:15)
B(10,-18,1,STAINED_GLASS:15)
B(11,-18,1,STAINED_GLASS:6)
B(6,-18,2,STAINED_GLASS:6)
B(7,-18,2,SEA_LANTERN)
B(8,-18,2,SEA_LANTERN)
B(9,-18,2,STAINED_GLASS:15)
B(10,-18,2,STAINED_GLASS:6)
B(11,-18,2,STAINED_GLASS:6)
B(7,-18,3,STAINED_GLASS:11)
B(8,-18,3,SEA_LANTERN)
B(9,-18,3,SEA_LANTERN)
B(10,-18,3,STAINED_GLASS:6)
B(11,-18,3,STAINED_GLASS:6)
B(12,-18,3,STAINED_GLASS:6)
B(7,-18,4,STAINED_GLASS:6)
B(8,-18,4,STAINED_GLASS:6)
B(9,-18,4,SEA_LANTERN)
B(10,-18,4,STAINED_GLASS:15)
B(11,-18,4,STAINED_GLASS:11)
B(12,-18,4,STAINED_GLASS:6)
B(8,-18,5,STAINED_GLASS:15)
B(9,-18,5,STAINED_GLASS:11)
B(10,-18,5,STAINED_GLASS:15)
B(11,-18,5,STAINED_GLASS:15)
B(9,-18,6,STAINED_GLASS:15)
B(5,-17,0,STAINED_GLASS:6)
B(6,-17,0,STAINED_GLASS:11)
B(7,-17,0,SEA_LANTERN)
B(8,-17,0,STAINED_GLASS:11)
B(9,-17,0,STAINED_GLASS:6)
B(10,-17,0,STAINED_GLASS:6)
B(5,-17,1,STAINED_GLASS:6)
B(6,-17,1,STAINED_GLASS:6)
B(7,-17,1,SEA_LANTERN)
B(8,-17,1,SEA_LANTERN)
B(9,-17,1,STAINED_GLASS:6)
B(10,-17,1,STAINED_GLASS:6)
B(11,-17,1,STAINED_GLASS:6)
B(6,-17,2,STAINED_GLASS:6)
B(7,-17,2,SEA_LANTERN)
B(8,-17,2,SEA_LANTERN)
B(9,-17,2,STAINED_GLASS:11)
B(10,-17,2,STAINED_GLASS:6)
B(11,-17,2,STAINED_GLASS:6)
B(7,-17,3,STAINED_GLASS:15)
B(8,-17,3,STAINED_GLASS:15)
B(9,-17,3,STAINED_GLASS:15)
B(10,-17,3,STAINED_GLASS:11)
B(11,-17,3,STAINED_GLASS:6)
B(12,-17,3,STAINED_GLASS:6)
B(7,-17,4,STAINED_GLASS:15)
B(8,-17,4,STAINED_GLASS:11)
B(9,-17,4,STAINED_GLASS:15)
B(10,-17,4,STAINED_GLASS:15)
B(11,-17,4,STAINED_GLASS:15)
B(8,-17,5,STAINED_GLASS:15)
B(9,-17,5,STAINED_GLASS:11)
B(5,-16,0,STAINED_GLASS:6)
B(6,-16,0,STAINED_GLASS:6)
B(7,-16,0,SEA_LANTERN)
B(8,-16,0,STAINED_GLASS:6)
B(9,-16,0,STAINED_GLASS:6)
B(10,-16,0,STAINED_GLASS:6)
B(5,-16,1,STAINED_GLASS:6)
B(6,-16,1,STAINED_GLASS:14)
B(7,-16,1,SEA_LANTERN)
B(8,-16,1,STAINED_GLASS:11)
B(9,-16,1,STAINED_GLASS:6)
B(10,-16,1,STAINED_GLASS:6)
B(11,-16,1,STAINED_GLASS:6)
B(6,-16,2,STAINED_GLASS:15)
B(7,-16,2,STAINED_GLASS:15)
B(8,-16,2,STAINED_GLASS:15)
B(9,-16,2,STAINED_GLASS:11)
B(10,-16,2,STAINED_GLASS:6)
B(11,-16,2,STAINED_GLASS:6)
B(7,-16,3,STAINED_GLASS:14)
B(8,-16,3,STAINED_GLASS:15)
B(9,-16,3,STAINED_GLASS:6)
B(10,-16,3,STAINED_GLASS:6)
B(7,-16,4,STAINED_GLASS:15)
B(8,-16,4,STAINED_GLASS:15)
B(9,-16,4,STAINED_GLASS:15)
B(5,-15,0,STAINED_GLASS:15)
B(6,-15,0,STAINED_GLASS:14)
B(7,-15,0,STAINED_GLASS:15)
B(8,-15,0,STAINED_GLASS:14)
B(9,-15,0,STAINED_GLASS:6)
B(10,-15,0,STAINED_GLASS:6)
B(5,-15,1,STAINED_GLASS:15)
B(6,-15,1,STAINED_GLASS:14)
B(7,-15,1,STAINED_GLASS:15)
B(8,-15,1,STAINED_GLASS:6)
B(9,-15,1,STAINED_GLASS:6)
B(10,-15,1,STAINED_GLASS:6)
B(11,-15,1,STAINED_GLASS:6)
B(6,-15,2,STAINED_GLASS:15)
B(7,-15,2,STAINED_GLASS:15)
B(8,-15,2,STAINED_GLASS:6)
B(9,-15,2,STAINED_GLASS:6)
B(7,-15,3,STAINED_GLASS:15)
B(8,-15,3,STAINED_GLASS:15)
B(5,-14,0,STAINED_GLASS:15)
B(6,-14,0,STAINED_GLASS:15)
B(7,-14,0,STAINED_GLASS:6)
B(8,-14,0,STAINED_GLASS:15)
B(9,-14,0,STAINED_GLASS:15)
B(5,-14,1,STAINED_GLASS:15)
B(6,-14,1,STAINED_GLASS:15)
B(7,-14,1,STAINED_GLASS:15)
B(5,-13,0,STAINED_GLASS:15)

