#######################################################################
# +-----------------------------------------------------------------+ #
# |                            BO3 object                           | #
# +-----------------------------------------------------------------+ #
#######################################################################

Author: Bo3 BulkEdit

Description: Converted Schematic - Modified by Bo3BulkEdit

Version: 3

SettingsMode: WriteDisable

#######################################################################
# +-----------------------------------------------------------------+ #
# |                          Main settings                          | #
# +-----------------------------------------------------------------+ #
#######################################################################



Frequency: 0


SpawnHeight: randomY





##############################
# Height Limits for the BO3. #
##############################

MinHeight: 0
MaxHeight: 256

#######################################################################
# +-----------------------------------------------------------------+ #
# |                      Source block settings                      | #
# +-----------------------------------------------------------------+ #
#######################################################################

CanOverride: true
MaxPercentageOutsideSourceBlock: 100
OutsideSourceBlock: placeAnyway

#######################################################################
# +-----------------------------------------------------------------+ #
# |                               OTG+                              | #
# +-----------------------------------------------------------------+ #
#######################################################################

#######################################################################
# +-----------------------------------------------------------------+ #
# |                              Blocks                             | #
# +-----------------------------------------------------------------+ #
#######################################################################

B(0,750,0,AIR)
B(15,750,15,AIR)
B(13,13,15,STAINED_GLASS:15)
B(10,14,15,STAINED_GLASS:9)
B(11,14,15,STAINED_GLASS:9)
B(12,14,15,STAINED_GLASS:15)
B(13,14,15,STAINED_GLASS:15)
B(11,15,14,STAINED_GLASS:9)
B(12,15,14,STAINED_GLASS:15)
B(8,15,15,STAINED_GLASS:9)
B(9,15,15,STAINED_GLASS:9)
B(10,15,15,STAINED_GLASS:11)
B(11,15,15,STAINED_GLASS:11)
B(12,15,15,STAINED_GLASS:11)
B(13,15,15,STAINED_GLASS:9)
B(11,16,13,STAINED_GLASS:9)
B(10,16,14,STAINED_GLASS:9)
B(11,16,14,STAINED_GLASS:11)
B(12,16,14,STAINED_GLASS:15)
B(7,16,15,STAINED_GLASS:9)
B(8,16,15,STAINED_GLASS:11)
B(9,16,15,STAINED_GLASS:11)
B(10,16,15,STAINED_GLASS:9)
B(11,16,15,STAINED_GLASS:9)
B(12,16,15,STAINED_GLASS:15)
B(13,16,15,STAINED_GLASS:9)
B(14,16,15,STAINED_GLASS:9)
B(10,17,13,STAINED_GLASS:9)
B(11,17,13,STAINED_GLASS:11)
B(8,17,14,STAINED_GLASS:9)
B(9,17,14,STAINED_GLASS:9)
B(10,17,14,STAINED_GLASS:11)
B(11,17,14,STAINED_GLASS:15)
B(12,17,14,STAINED_GLASS:9)
B(5,17,15,STAINED_GLASS:15)
B(6,17,15,STAINED_GLASS:15)
B(7,17,15,STAINED_GLASS:11)
B(8,17,15,STAINED_GLASS:9)
B(9,17,15,STAINED_GLASS:9)
B(10,17,15,STAINED_GLASS:11)
B(11,17,15,STAINED_GLASS:11)
B(12,17,15,STAINED_GLASS:11)
B(13,17,15,STAINED_GLASS:9)
B(14,17,15,STAINED_GLASS:9)
B(11,18,12,STAINED_GLASS:9)
B(8,18,13,STAINED_GLASS:9)
B(9,18,13,STAINED_GLASS:9)
B(10,18,13,STAINED_GLASS:9)
B(11,18,13,STAINED_GLASS:9)
B(7,18,14,STAINED_GLASS:9)
B(8,18,14,STAINED_GLASS:9)
B(9,18,14,STAINED_GLASS:9)
B(10,18,14,STAINED_GLASS:15)
B(11,18,14,STAINED_GLASS:9)
B(12,18,14,STAINED_GLASS:9)
B(13,18,14,STAINED_GLASS:9)
B(5,18,15,STAINED_GLASS:15)
B(6,18,15,STAINED_GLASS:15)
B(7,18,15,STAINED_GLASS:15)
B(8,18,15,STAINED_GLASS:9)
B(9,18,15,STAINED_GLASS:9)
B(10,18,15,STAINED_GLASS:11)
B(11,18,15,STAINED_GLASS:11)
B(12,18,15,STAINED_GLASS:9)
B(13,18,15,STAINED_GLASS:9)
B(14,18,15,STAINED_GLASS:9)
B(11,19,11,STAINED_GLASS:15)
B(8,19,12,STAINED_GLASS:9)
B(9,19,12,STAINED_GLASS:9)
B(10,19,12,STAINED_GLASS:9)
B(11,19,12,STAINED_GLASS:9)
B(7,19,13,STAINED_GLASS:9)
B(8,19,13,STAINED_GLASS:9)
B(9,19,13,STAINED_GLASS:9)
B(10,19,13,STAINED_GLASS:15)
B(11,19,13,STAINED_GLASS:9)
B(4,19,14,STAINED_GLASS:15)
B(5,19,14,STAINED_GLASS:15)
B(6,19,14,STAINED_GLASS:15)
B(7,19,14,STAINED_GLASS:15)
B(8,19,14,STAINED_GLASS:9)
B(9,19,14,STAINED_GLASS:9)
B(10,19,14,STAINED_GLASS:9)
B(11,19,14,STAINED_GLASS:11)
B(12,19,14,STAINED_GLASS:9)
B(13,19,14,STAINED_GLASS:9)
B(5,19,15,STAINED_GLASS:9)
B(6,19,15,STAINED_GLASS:15)
B(7,19,15,STAINED_GLASS:9)
B(8,19,15,STAINED_GLASS:11)
B(9,19,15,STAINED_GLASS:11)
B(10,19,15,STAINED_GLASS:11)
B(11,19,15,STAINED_GLASS:11)
B(12,19,15,STAINED_GLASS:9)
B(13,19,15,STAINED_GLASS:9)
B(14,19,15,STAINED_GLASS:9)
B(10,20,11,STAINED_GLASS:9)
B(11,20,11,STAINED_GLASS:15)
B(7,20,12,STAINED_GLASS:9)
B(8,20,12,STAINED_GLASS:9)
B(9,20,12,STAINED_GLASS:9)
B(10,20,12,STAINED_GLASS:9)
B(11,20,12,STAINED_GLASS:15)
B(5,20,13,STAINED_GLASS:15)
B(6,20,13,STAINED_GLASS:15)
B(7,20,13,STAINED_GLASS:9)
B(8,20,13,STAINED_GLASS:9)
B(9,20,13,STAINED_GLASS:9)
B(10,20,13,STAINED_GLASS:9)
B(11,20,13,STAINED_GLASS:9)
B(12,20,13,STAINED_GLASS:15)
B(4,20,14,STAINED_GLASS:9)
B(5,20,14,STAINED_GLASS:9)
B(6,20,14,STAINED_GLASS:15)
B(7,20,14,STAINED_GLASS:15)
B(8,20,14,STAINED_GLASS:9)
B(9,20,14,STAINED_GLASS:9)
B(10,20,14,STAINED_GLASS:11)
B(11,20,14,STAINED_GLASS:11)
B(12,20,14,STAINED_GLASS:15)
B(13,20,14,STAINED_GLASS:9)
B(5,20,15,STAINED_GLASS:9)
B(6,20,15,STAINED_GLASS:9)
B(7,20,15,STAINED_GLASS:11)
B(8,20,15,STAINED_GLASS:11)
B(9,20,15,STAINED_GLASS:11)
B(10,20,15,STAINED_GLASS:11)
B(11,20,15,STAINED_GLASS:11)
B(12,20,15,STAINED_GLASS:9)
B(13,20,15,STAINED_GLASS:9)
B(14,20,15,STAINED_GLASS:9)
B(9,21,10,STAINED_GLASS:9)
B(10,21,10,STAINED_GLASS:15)
B(8,21,11,STAINED_GLASS:9)
B(9,21,11,STAINED_GLASS:9)
B(10,21,11,STAINED_GLASS:9)
B(11,21,11,STAINED_GLASS:15)
B(5,21,12,STAINED_GLASS:15)
B(6,21,12,STAINED_GLASS:15)
B(7,21,12,STAINED_GLASS:9)
B(8,21,12,STAINED_GLASS:9)
B(9,21,12,STAINED_GLASS:9)
B(10,21,12,STAINED_GLASS:9)
B(11,21,12,STAINED_GLASS:9)
B(4,21,13,STAINED_GLASS:15)
B(5,21,13,STAINED_GLASS:9)
B(6,21,13,STAINED_GLASS:9)
B(7,21,13,STAINED_GLASS:15)
B(8,21,13,STAINED_GLASS:9)
B(9,21,13,STAINED_GLASS:9)
B(10,21,13,STAINED_GLASS:11)
B(11,21,13,STAINED_GLASS:15)
B(12,21,13,STAINED_GLASS:15)
B(4,21,14,STAINED_GLASS:15)
B(5,21,14,STAINED_GLASS:15)
B(6,21,14,STAINED_GLASS:15)
B(7,21,14,STAINED_GLASS:9)
B(8,21,14,STAINED_GLASS:11)
B(9,21,14,STAINED_GLASS:11)
B(10,21,14,STAINED_GLASS:11)
B(11,21,14,STAINED_GLASS:11)
B(12,21,14,STAINED_GLASS:15)
B(13,21,14,STAINED_GLASS:15)
B(5,21,15,STAINED_GLASS:9)
B(6,21,15,STAINED_GLASS:11)
B(7,21,15,STAINED_GLASS:11)
B(8,21,15,SEA_LANTERN)
B(9,21,15,SEA_LANTERN)
B(10,21,15,STAINED_GLASS:11)
B(11,21,15,STAINED_GLASS:11)
B(12,21,15,STAINED_GLASS:9)
B(13,21,15,STAINED_GLASS:9)
B(14,21,15,STAINED_GLASS:15)
B(9,22,9,STAINED_GLASS:9)
B(8,22,10,STAINED_GLASS:9)
B(9,22,10,STAINED_GLASS:9)
B(10,22,10,STAINED_GLASS:9)
B(6,22,11,STAINED_GLASS:15)
B(7,22,11,STAINED_GLASS:9)
B(8,22,11,STAINED_GLASS:9)
B(9,22,11,STAINED_GLASS:9)
B(10,22,11,STAINED_GLASS:15)
B(11,22,11,STAINED_GLASS:9)
B(4,22,12,STAINED_GLASS:15)
B(5,22,12,STAINED_GLASS:9)
B(6,22,12,STAINED_GLASS:9)
B(7,22,12,STAINED_GLASS:15)
B(8,22,12,STAINED_GLASS:9)
B(9,22,12,STAINED_GLASS:9)
B(10,22,12,STAINED_GLASS:9)
B(11,22,12,STAINED_GLASS:9)
B(12,22,12,STAINED_GLASS:15)
B(4,22,13,STAINED_GLASS:15)
B(5,22,13,STAINED_GLASS:15)
B(6,22,13,STAINED_GLASS:15)
B(7,22,13,STAINED_GLASS:9)
B(8,22,13,STAINED_GLASS:11)
B(9,22,13,STAINED_GLASS:11)
B(10,22,13,STAINED_GLASS:11)
B(11,22,13,STAINED_GLASS:15)
B(12,22,13,STAINED_GLASS:15)
B(4,22,14,STAINED_GLASS:15)
B(5,22,14,STAINED_GLASS:15)
B(6,22,14,STAINED_GLASS:9)
B(7,22,14,STAINED_GLASS:11)
B(8,22,14,STAINED_GLASS:11)
B(9,22,14,STAINED_GLASS:11)
B(10,22,14,STAINED_GLASS:11)
B(11,22,14,STAINED_GLASS:11)
B(12,22,14,STAINED_GLASS:15)
B(13,22,14,STAINED_GLASS:15)
B(5,22,15,STAINED_GLASS:9)
B(6,22,15,STAINED_GLASS:11)
B(7,22,15,STAINED_GLASS:11)
B(8,22,15,SEA_LANTERN)
B(9,22,15,SEA_LANTERN)
B(10,22,15,STAINED_GLASS:11)
B(11,22,15,STAINED_GLASS:11)
B(12,22,15,STAINED_GLASS:9)
B(13,22,15,STAINED_GLASS:9)
B(14,22,15,STAINED_GLASS:15)
B(8,23,9,STAINED_GLASS:9)
B(9,23,9,STAINED_GLASS:9)
B(10,23,9,STAINED_GLASS:9)
B(6,23,10,STAINED_GLASS:15)
B(7,23,10,STAINED_GLASS:9)
B(8,23,10,STAINED_GLASS:9)
B(9,23,10,STAINED_GLASS:9)
B(10,23,10,STAINED_GLASS:15)
B(3,23,11,STAINED_GLASS:15)
B(4,23,11,STAINED_GLASS:15)
B(5,23,11,STAINED_GLASS:15)
B(6,23,11,STAINED_GLASS:9)
B(7,23,11,STAINED_GLASS:9)
B(8,23,11,STAINED_GLASS:9)
B(9,23,11,STAINED_GLASS:9)
B(10,23,11,STAINED_GLASS:9)
B(11,23,11,STAINED_GLASS:15)
B(3,23,12,STAINED_GLASS:15)
B(4,23,12,STAINED_GLASS:15)
B(5,23,12,STAINED_GLASS:15)
B(6,23,12,STAINED_GLASS:15)
B(7,23,12,STAINED_GLASS:9)
B(8,23,12,STAINED_GLASS:11)
B(9,23,12,STAINED_GLASS:11)
B(10,23,12,STAINED_GLASS:11)
B(11,23,12,STAINED_GLASS:9)
B(12,23,12,STAINED_GLASS:15)
B(4,23,13,STAINED_GLASS:15)
B(5,23,13,STAINED_GLASS:9)
B(6,23,13,STAINED_GLASS:9)
B(7,23,13,STAINED_GLASS:11)
B(8,23,13,STAINED_GLASS:11)
B(9,23,13,STAINED_GLASS:11)
B(10,23,13,STAINED_GLASS:11)
B(11,23,13,STAINED_GLASS:9)
B(12,23,13,STAINED_GLASS:15)
B(4,23,14,STAINED_GLASS:15)
B(5,23,14,STAINED_GLASS:15)
B(6,23,14,STAINED_GLASS:11)
B(7,23,14,STAINED_GLASS:11)
B(8,23,14,SEA_LANTERN)
B(9,23,14,SEA_LANTERN)
B(10,23,14,STAINED_GLASS:11)
B(11,23,14,STAINED_GLASS:11)
B(12,23,14,STAINED_GLASS:15)
B(13,23,14,STAINED_GLASS:15)
B(5,23,15,STAINED_GLASS:9)
B(6,23,15,STAINED_GLASS:11)
B(7,23,15,STAINED_GLASS:11)
B(8,23,15,SEA_LANTERN)
B(9,23,15,SEA_LANTERN)
B(10,23,15,STAINED_GLASS:11)
B(11,23,15,STAINED_GLASS:11)
B(12,23,15,STAINED_GLASS:9)
B(13,23,15,STAINED_GLASS:15)
B(9,24,8,STAINED_GLASS:9)
B(6,24,9,STAINED_GLASS:15)
B(7,24,9,STAINED_GLASS:9)
B(8,24,9,STAINED_GLASS:9)
B(9,24,9,STAINED_GLASS:9)
B(10,24,9,STAINED_GLASS:15)
B(5,24,10,STAINED_GLASS:15)
B(6,24,10,STAINED_GLASS:9)
B(7,24,10,STAINED_GLASS:9)
B(8,24,10,STAINED_GLASS:9)
B(9,24,10,STAINED_GLASS:9)
B(10,24,10,STAINED_GLASS:15)
B(11,24,10,STAINED_GLASS:15)
B(3,24,11,STAINED_GLASS:15)
B(4,24,11,STAINED_GLASS:9)
B(5,24,11,STAINED_GLASS:9)
B(6,24,11,STAINED_GLASS:15)
B(7,24,11,STAINED_GLASS:15)
B(8,24,11,STAINED_GLASS:9)
B(9,24,11,STAINED_GLASS:9)
B(10,24,11,STAINED_GLASS:9)
B(11,24,11,STAINED_GLASS:15)
B(3,24,12,STAINED_GLASS:15)
B(4,24,12,STAINED_GLASS:15)
B(5,24,12,STAINED_GLASS:9)
B(6,24,12,STAINED_GLASS:9)
B(7,24,12,STAINED_GLASS:11)
B(8,24,12,STAINED_GLASS:11)
B(9,24,12,STAINED_GLASS:11)
B(10,24,12,STAINED_GLASS:11)
B(11,24,12,STAINED_GLASS:15)
B(12,24,12,STAINED_GLASS:15)
B(4,24,13,STAINED_GLASS:15)
B(5,24,13,STAINED_GLASS:9)
B(6,24,13,STAINED_GLASS:11)
B(7,24,13,STAINED_GLASS:11)
B(8,24,13,SEA_LANTERN)
B(9,24,13,STAINED_GLASS:11)
B(10,24,13,STAINED_GLASS:11)
B(11,24,13,STAINED_GLASS:9)
B(12,24,13,STAINED_GLASS:15)
B(4,24,14,STAINED_GLASS:15)
B(5,24,14,STAINED_GLASS:15)
B(6,24,14,STAINED_GLASS:11)
B(7,24,14,STAINED_GLASS:11)
B(8,24,14,SEA_LANTERN)
B(9,24,14,SEA_LANTERN)
B(10,24,14,STAINED_GLASS:11)
B(11,24,14,STAINED_GLASS:11)
B(12,24,14,STAINED_GLASS:9)
B(13,24,14,STAINED_GLASS:15)
B(5,24,15,STAINED_GLASS:9)
B(6,24,15,STAINED_GLASS:11)
B(7,24,15,STAINED_GLASS:11)
B(8,24,15,STAINED_GLASS:11)
B(9,24,15,STAINED_GLASS:11)
B(10,24,15,STAINED_GLASS:11)
B(11,24,15,STAINED_GLASS:11)
B(12,24,15,STAINED_GLASS:9)
B(13,24,15,STAINED_GLASS:15)
B(9,25,7,STAINED_GLASS:9)
B(8,25,8,STAINED_GLASS:9)
B(9,25,8,STAINED_GLASS:9)
B(5,25,9,STAINED_GLASS:15)
B(6,25,9,STAINED_GLASS:9)
B(7,25,9,STAINED_GLASS:9)
B(8,25,9,STAINED_GLASS:9)
B(9,25,9,STAINED_GLASS:9)
B(10,25,9,STAINED_GLASS:9)
B(3,25,10,STAINED_GLASS:15)
B(4,25,10,STAINED_GLASS:15)
B(5,25,10,STAINED_GLASS:9)
B(6,25,10,STAINED_GLASS:15)
B(7,25,10,STAINED_GLASS:9)
B(8,25,10,STAINED_GLASS:9)
B(9,25,10,STAINED_GLASS:11)
B(10,25,10,STAINED_GLASS:15)
B(11,25,10,STAINED_GLASS:15)
B(3,25,11,STAINED_GLASS:15)
B(4,25,11,STAINED_GLASS:15)
B(5,25,11,STAINED_GLASS:15)
B(6,25,11,STAINED_GLASS:9)
B(7,25,11,STAINED_GLASS:9)
B(8,25,11,STAINED_GLASS:11)
B(9,25,11,STAINED_GLASS:11)
B(10,25,11,STAINED_GLASS:9)
B(11,25,11,STAINED_GLASS:15)
B(3,25,12,STAINED_GLASS:15)
B(4,25,12,STAINED_GLASS:9)
B(5,25,12,STAINED_GLASS:11)
B(6,25,12,STAINED_GLASS:11)
B(7,25,12,STAINED_GLASS:11)
B(8,25,12,SEA_LANTERN)
B(9,25,12,STAINED_GLASS:11)
B(10,25,12,STAINED_GLASS:11)
B(11,25,12,STAINED_GLASS:9)
B(12,25,12,STAINED_GLASS:15)
B(4,25,13,STAINED_GLASS:15)
B(5,25,13,STAINED_GLASS:9)
B(6,25,13,STAINED_GLASS:11)
B(7,25,13,SEA_LANTERN)
B(8,25,13,SEA_LANTERN)
B(9,25,13,STAINED_GLASS:11)
B(10,25,13,STAINED_GLASS:11)
B(11,25,13,STAINED_GLASS:9)
B(12,25,13,STAINED_GLASS:15)
B(4,25,14,STAINED_GLASS:15)
B(5,25,14,STAINED_GLASS:15)
B(6,25,14,STAINED_GLASS:11)
B(7,25,14,STAINED_GLASS:11)
B(8,25,14,SEA_LANTERN)
B(9,25,14,SEA_LANTERN)
B(10,25,14,STAINED_GLASS:11)
B(11,25,14,STAINED_GLASS:11)
B(12,25,14,STAINED_GLASS:15)
B(5,25,15,STAINED_GLASS:9)
B(6,25,15,STAINED_GLASS:11)
B(7,25,15,STAINED_GLASS:11)
B(8,25,15,STAINED_GLASS:11)
B(9,25,15,STAINED_GLASS:11)
B(10,25,15,STAINED_GLASS:9)
B(11,25,15,STAINED_GLASS:9)
B(12,25,15,STAINED_GLASS:9)
B(13,25,15,STAINED_GLASS:15)
B(8,26,7,STAINED_GLASS:9)
B(9,26,7,STAINED_GLASS:9)
B(6,26,8,STAINED_GLASS:15)
B(7,26,8,STAINED_GLASS:9)
B(8,26,8,STAINED_GLASS:9)
B(9,26,8,STAINED_GLASS:9)
B(3,26,9,STAINED_GLASS:15)
B(4,26,9,STAINED_GLASS:15)
B(5,26,9,STAINED_GLASS:9)
B(6,26,9,STAINED_GLASS:15)
B(7,26,9,STAINED_GLASS:9)
B(8,26,9,STAINED_GLASS:9)
B(9,26,9,STAINED_GLASS:9)
B(10,26,9,STAINED_GLASS:15)
B(11,26,9,STAINED_GLASS:15)
B(3,26,10,STAINED_GLASS:15)
B(4,26,10,STAINED_GLASS:9)
B(5,26,10,STAINED_GLASS:15)
B(6,26,10,STAINED_GLASS:9)
B(7,26,10,STAINED_GLASS:9)
B(8,26,10,STAINED_GLASS:11)
B(9,26,10,STAINED_GLASS:11)
B(10,26,10,STAINED_GLASS:15)
B(11,26,10,STAINED_GLASS:15)
B(3,26,11,STAINED_GLASS:15)
B(4,26,11,STAINED_GLASS:9)
B(5,26,11,STAINED_GLASS:9)
B(6,26,11,STAINED_GLASS:11)
B(7,26,11,STAINED_GLASS:11)
B(8,26,11,STAINED_GLASS:11)
B(9,26,11,STAINED_GLASS:11)
B(10,26,11,STAINED_GLASS:15)
B(11,26,11,STAINED_GLASS:15)
B(3,26,12,STAINED_GLASS:15)
B(4,26,12,STAINED_GLASS:9)
B(5,26,12,STAINED_GLASS:11)
B(6,26,12,STAINED_GLASS:11)
B(7,26,12,SEA_LANTERN)
B(8,26,12,SEA_LANTERN)
B(9,26,12,STAINED_GLASS:11)
B(10,26,12,STAINED_GLASS:11)
B(11,26,12,STAINED_GLASS:9)
B(12,26,12,STAINED_GLASS:15)
B(3,26,13,STAINED_GLASS:15)
B(4,26,13,STAINED_GLASS:15)
B(5,26,13,STAINED_GLASS:9)
B(6,26,13,STAINED_GLASS:11)
B(7,26,13,SEA_LANTERN)
B(8,26,13,SEA_LANTERN)
B(9,26,13,STAINED_GLASS:11)
B(10,26,13,STAINED_GLASS:11)
B(11,26,13,STAINED_GLASS:15)
B(12,26,13,STAINED_GLASS:15)
B(4,26,14,STAINED_GLASS:15)
B(5,26,14,STAINED_GLASS:15)
B(6,26,14,STAINED_GLASS:11)
B(7,26,14,STAINED_GLASS:11)
B(8,26,14,STAINED_GLASS:11)
B(9,26,14,STAINED_GLASS:11)
B(10,26,14,STAINED_GLASS:11)
B(11,26,14,STAINED_GLASS:9)
B(12,26,14,STAINED_GLASS:15)
B(5,26,15,STAINED_GLASS:9)
B(6,26,15,STAINED_GLASS:11)
B(7,26,15,STAINED_GLASS:11)
B(8,26,15,STAINED_GLASS:9)
B(9,26,15,STAINED_GLASS:9)
B(10,26,15,STAINED_GLASS:15)
B(11,26,15,STAINED_GLASS:15)
B(12,26,15,STAINED_GLASS:15)
B(8,27,6,STAINED_GLASS:9)
B(6,27,7,STAINED_GLASS:9)
B(7,27,7,STAINED_GLASS:9)
B(8,27,7,STAINED_GLASS:9)
B(9,27,7,STAINED_GLASS:9)
B(3,27,8,STAINED_GLASS:15)
B(5,27,8,STAINED_GLASS:15)
B(6,27,8,STAINED_GLASS:9)
B(7,27,8,STAINED_GLASS:9)
B(8,27,8,STAINED_GLASS:9)
B(9,27,8,STAINED_GLASS:9)
B(2,27,9,STAINED_GLASS:15)
B(3,27,9,STAINED_GLASS:9)
B(4,27,9,STAINED_GLASS:9)
B(5,27,9,STAINED_GLASS:15)
B(6,27,9,STAINED_GLASS:9)
B(7,27,9,STAINED_GLASS:9)
B(8,27,9,STAINED_GLASS:11)
B(9,27,9,STAINED_GLASS:9)
B(10,27,9,STAINED_GLASS:9)
B(11,27,9,STAINED_GLASS:9)
B(3,27,10,STAINED_GLASS:15)
B(4,27,10,STAINED_GLASS:15)
B(5,27,10,STAINED_GLASS:9)
B(6,27,10,STAINED_GLASS:11)
B(7,27,10,STAINED_GLASS:11)
B(8,27,10,STAINED_GLASS:11)
B(9,27,10,STAINED_GLASS:11)
B(10,27,10,STAINED_GLASS:15)
B(11,27,10,STAINED_GLASS:15)
B(3,27,11,STAINED_GLASS:15)
B(4,27,11,STAINED_GLASS:11)
B(5,27,11,STAINED_GLASS:11)
B(6,27,11,STAINED_GLASS:11)
B(7,27,11,STAINED_GLASS:11)
B(8,27,11,SEA_LANTERN)
B(9,27,11,STAINED_GLASS:11)
B(10,27,11,STAINED_GLASS:9)
B(11,27,11,STAINED_GLASS:15)
B(3,27,12,STAINED_GLASS:15)
B(4,27,12,STAINED_GLASS:9)
B(5,27,12,STAINED_GLASS:11)
B(6,27,12,SEA_LANTERN)
B(7,27,12,SEA_LANTERN)
B(8,27,12,SEA_LANTERN)
B(9,27,12,STAINED_GLASS:11)
B(10,27,12,STAINED_GLASS:11)
B(11,27,12,STAINED_GLASS:9)
B(12,27,12,STAINED_GLASS:15)
B(3,27,13,STAINED_GLASS:15)
B(4,27,13,STAINED_GLASS:15)
B(5,27,13,STAINED_GLASS:9)
B(6,27,13,STAINED_GLASS:11)
B(7,27,13,SEA_LANTERN)
B(8,27,13,STAINED_GLASS:11)
B(9,27,13,STAINED_GLASS:11)
B(10,27,13,STAINED_GLASS:11)
B(11,27,13,STAINED_GLASS:15)
B(4,27,14,STAINED_GLASS:9)
B(5,27,14,STAINED_GLASS:9)
B(6,27,14,STAINED_GLASS:11)
B(7,27,14,STAINED_GLASS:11)
B(8,27,14,STAINED_GLASS:11)
B(9,27,14,STAINED_GLASS:11)
B(10,27,14,STAINED_GLASS:9)
B(11,27,14,STAINED_GLASS:15)
B(12,27,14,STAINED_GLASS:15)
B(5,27,15,STAINED_GLASS:9)
B(6,27,15,STAINED_GLASS:11)
B(7,27,15,STAINED_GLASS:15)
B(8,27,15,STAINED_GLASS:9)
B(9,27,15,STAINED_GLASS:9)
B(10,27,15,STAINED_GLASS:15)
B(11,27,15,STAINED_GLASS:15)
B(6,28,6,STAINED_GLASS:9)
B(7,28,6,STAINED_GLASS:9)
B(8,28,6,STAINED_GLASS:9)
B(5,28,7,STAINED_GLASS:9)
B(6,28,7,STAINED_GLASS:9)
B(7,28,7,STAINED_GLASS:9)
B(8,28,7,STAINED_GLASS:9)
B(9,28,7,STAINED_GLASS:9)
B(2,28,8,STAINED_GLASS:15)
B(3,28,8,STAINED_GLASS:9)
B(4,28,8,STAINED_GLASS:9)
B(5,28,8,STAINED_GLASS:9)
B(6,28,8,STAINED_GLASS:9)
B(7,28,8,STAINED_GLASS:9)
B(8,28,8,STAINED_GLASS:9)
B(9,28,8,STAINED_GLASS:9)
B(10,28,8,STAINED_GLASS:9)
B(2,28,9,STAINED_GLASS:15)
B(3,28,9,STAINED_GLASS:15)
B(4,28,9,STAINED_GLASS:9)
B(5,28,9,STAINED_GLASS:9)
B(6,28,9,STAINED_GLASS:11)
B(7,28,9,STAINED_GLASS:11)
B(8,28,9,STAINED_GLASS:11)
B(9,28,9,STAINED_GLASS:9)
B(10,28,9,STAINED_GLASS:9)
B(11,28,9,STAINED_GLASS:9)
B(3,28,10,STAINED_GLASS:15)
B(4,28,10,STAINED_GLASS:9)
B(5,28,10,STAINED_GLASS:11)
B(6,28,10,STAINED_GLASS:11)
B(7,28,10,STAINED_GLASS:11)
B(8,28,10,STAINED_GLASS:11)
B(9,28,10,STAINED_GLASS:11)
B(10,28,10,STAINED_GLASS:9)
B(11,28,10,STAINED_GLASS:15)
B(2,28,11,STAINED_GLASS:15)
B(3,28,11,STAINED_GLASS:15)
B(4,28,11,STAINED_GLASS:11)
B(5,28,11,STAINED_GLASS:11)
B(6,28,11,STAINED_GLASS:11)
B(7,28,11,SEA_LANTERN)
B(8,28,11,SEA_LANTERN)
B(9,28,11,STAINED_GLASS:11)
B(10,28,11,STAINED_GLASS:9)
B(11,28,11,STAINED_GLASS:9)
B(3,28,12,STAINED_GLASS:15)
B(4,28,12,STAINED_GLASS:9)
B(5,28,12,STAINED_GLASS:11)
B(6,28,12,SEA_LANTERN)
B(7,28,12,SEA_LANTERN)
B(8,28,12,STAINED_GLASS:11)
B(9,28,12,STAINED_GLASS:11)
B(10,28,12,STAINED_GLASS:11)
B(11,28,12,STAINED_GLASS:9)
B(12,28,12,STAINED_GLASS:15)
B(3,28,13,STAINED_GLASS:15)
B(4,28,13,STAINED_GLASS:15)
B(5,28,13,STAINED_GLASS:9)
B(6,28,13,STAINED_GLASS:11)
B(7,28,13,STAINED_GLASS:11)
B(8,28,13,STAINED_GLASS:11)
B(9,28,13,STAINED_GLASS:11)
B(10,28,13,STAINED_GLASS:9)
B(11,28,13,STAINED_GLASS:15)
B(4,28,14,STAINED_GLASS:9)
B(5,28,14,STAINED_GLASS:9)
B(6,28,14,STAINED_GLASS:11)
B(7,28,14,STAINED_GLASS:11)
B(8,28,14,STAINED_GLASS:15)
B(9,28,14,STAINED_GLASS:15)
B(10,28,14,STAINED_GLASS:15)
B(5,28,15,STAINED_GLASS:9)
B(6,28,15,STAINED_GLASS:9)
B(7,28,15,STAINED_GLASS:15)
B(8,28,15,STAINED_GLASS:15)
B(9,28,15,STAINED_GLASS:15)
B(7,29,5,STAINED_GLASS:9)
B(8,29,5,STAINED_GLASS:9)
B(5,29,6,STAINED_GLASS:9)
B(6,29,6,STAINED_GLASS:9)
B(7,29,6,STAINED_GLASS:9)
B(8,29,6,STAINED_GLASS:9)
B(3,29,7,STAINED_GLASS:9)
B(4,29,7,STAINED_GLASS:9)
B(5,29,7,STAINED_GLASS:9)
B(6,29,7,STAINED_GLASS:9)
B(7,29,7,STAINED_GLASS:9)
B(8,29,7,STAINED_GLASS:9)
B(9,29,7,STAINED_GLASS:9)
B(1,29,8,STAINED_GLASS:9)
B(2,29,8,STAINED_GLASS:9)
B(3,29,8,STAINED_GLASS:9)
B(4,29,8,STAINED_GLASS:9)
B(5,29,8,STAINED_GLASS:9)
B(6,29,8,STAINED_GLASS:9)
B(7,29,8,STAINED_GLASS:9)
B(8,29,8,STAINED_GLASS:11)
B(9,29,8,STAINED_GLASS:9)
B(10,29,8,STAINED_GLASS:9)
B(2,29,9,STAINED_GLASS:9)
B(3,29,9,STAINED_GLASS:9)
B(4,29,9,STAINED_GLASS:9)
B(5,29,9,STAINED_GLASS:11)
B(6,29,9,STAINED_GLASS:11)
B(7,29,9,STAINED_GLASS:11)
B(8,29,9,STAINED_GLASS:11)
B(9,29,9,STAINED_GLASS:9)
B(10,29,9,STAINED_GLASS:9)
B(11,29,9,STAINED_GLASS:9)
B(3,29,10,STAINED_GLASS:15)
B(4,29,10,STAINED_GLASS:11)
B(5,29,10,STAINED_GLASS:11)
B(6,29,10,SEA_LANTERN)
B(7,29,10,SEA_LANTERN)
B(8,29,10,STAINED_GLASS:11)
B(9,29,10,STAINED_GLASS:11)
B(10,29,10,STAINED_GLASS:9)
B(11,29,10,STAINED_GLASS:15)
B(2,29,11,STAINED_GLASS:15)
B(3,29,11,STAINED_GLASS:15)
B(4,29,11,STAINED_GLASS:11)
B(5,29,11,STAINED_GLASS:11)
B(6,29,11,STAINED_GLASS:11)
B(7,29,11,SEA_LANTERN)
B(8,29,11,SEA_LANTERN)
B(9,29,11,STAINED_GLASS:11)
B(10,29,11,STAINED_GLASS:9)
B(11,29,11,STAINED_GLASS:15)
B(3,29,12,STAINED_GLASS:15)
B(4,29,12,STAINED_GLASS:15)
B(5,29,12,STAINED_GLASS:11)
B(6,29,12,SEA_LANTERN)
B(7,29,12,STAINED_GLASS:11)
B(8,29,12,STAINED_GLASS:11)
B(9,29,12,STAINED_GLASS:11)
B(10,29,12,STAINED_GLASS:11)
B(11,29,12,STAINED_GLASS:9)
B(3,29,13,STAINED_GLASS:15)
B(4,29,13,STAINED_GLASS:15)
B(5,29,13,STAINED_GLASS:9)
B(6,29,13,STAINED_GLASS:11)
B(7,29,13,STAINED_GLASS:11)
B(8,29,13,STAINED_GLASS:15)
B(9,29,13,STAINED_GLASS:15)
B(10,29,13,STAINED_GLASS:15)
B(4,29,14,STAINED_GLASS:9)
B(5,29,14,STAINED_GLASS:9)
B(6,29,14,STAINED_GLASS:11)
B(7,29,14,STAINED_GLASS:15)
B(8,29,14,STAINED_GLASS:15)
B(9,29,14,STAINED_GLASS:15)
B(10,29,14,STAINED_GLASS:15)
B(5,29,15,STAINED_GLASS:9)
B(6,29,15,STAINED_GLASS:9)
B(7,29,15,STAINED_GLASS:15)
B(7,30,4,STAINED_GLASS:9)
B(6,30,5,STAINED_GLASS:9)
B(7,30,5,STAINED_GLASS:9)
B(8,30,5,STAINED_GLASS:9)
B(3,30,6,STAINED_GLASS:9)
B(4,30,6,STAINED_GLASS:9)
B(5,30,6,STAINED_GLASS:9)
B(6,30,6,STAINED_GLASS:9)
B(7,30,6,STAINED_GLASS:9)
B(8,30,6,STAINED_GLASS:15)
B(9,30,6,STAINED_GLASS:9)
B(2,30,7,STAINED_GLASS:9)
B(3,30,7,STAINED_GLASS:9)
B(4,30,7,STAINED_GLASS:9)
B(5,30,7,STAINED_GLASS:9)
B(6,30,7,STAINED_GLASS:9)
B(7,30,7,STAINED_GLASS:9)
B(8,30,7,STAINED_GLASS:9)
B(9,30,7,STAINED_GLASS:9)
B(1,30,8,STAINED_GLASS:9)
B(2,30,8,STAINED_GLASS:9)
B(3,30,8,STAINED_GLASS:9)
B(4,30,8,STAINED_GLASS:9)
B(5,30,8,STAINED_GLASS:9)
B(6,30,8,STAINED_GLASS:11)
B(7,30,8,STAINED_GLASS:11)
B(8,30,8,STAINED_GLASS:11)
B(9,30,8,STAINED_GLASS:9)
B(10,30,8,STAINED_GLASS:9)
B(2,30,9,STAINED_GLASS:9)
B(3,30,9,STAINED_GLASS:9)
B(4,30,9,STAINED_GLASS:11)
B(5,30,9,STAINED_GLASS:11)
B(6,30,9,SEA_LANTERN)
B(7,30,9,STAINED_GLASS:11)
B(8,30,9,STAINED_GLASS:11)
B(9,30,9,STAINED_GLASS:9)
B(10,30,9,STAINED_GLASS:9)
B(11,30,9,STAINED_GLASS:9)
B(2,30,10,STAINED_GLASS:15)
B(3,30,10,STAINED_GLASS:9)
B(4,30,10,STAINED_GLASS:11)
B(5,30,10,STAINED_GLASS:11)
B(6,30,10,SEA_LANTERN)
B(7,30,10,SEA_LANTERN)
B(8,30,10,STAINED_GLASS:11)
B(9,30,10,STAINED_GLASS:11)
B(10,30,10,STAINED_GLASS:9)
B(11,30,10,STAINED_GLASS:15)
B(2,30,11,STAINED_GLASS:15)
B(3,30,11,STAINED_GLASS:15)
B(4,30,11,STAINED_GLASS:11)
B(5,30,11,STAINED_GLASS:11)
B(6,30,11,STAINED_GLASS:11)
B(7,30,11,SEA_LANTERN)
B(8,30,11,STAINED_GLASS:11)
B(9,30,11,STAINED_GLASS:11)
B(10,30,11,STAINED_GLASS:9)
B(11,30,11,STAINED_GLASS:15)
B(3,30,12,STAINED_GLASS:15)
B(4,30,12,STAINED_GLASS:9)
B(5,30,12,STAINED_GLASS:11)
B(6,30,12,STAINED_GLASS:11)
B(7,30,12,STAINED_GLASS:11)
B(8,30,12,STAINED_GLASS:15)
B(9,30,12,STAINED_GLASS:9)
B(10,30,12,STAINED_GLASS:9)
B(11,30,12,STAINED_GLASS:15)
B(3,30,13,STAINED_GLASS:15)
B(4,30,13,STAINED_GLASS:15)
B(5,30,13,STAINED_GLASS:9)
B(6,30,13,STAINED_GLASS:11)
B(7,30,13,STAINED_GLASS:15)
B(8,30,13,STAINED_GLASS:15)
B(9,30,13,STAINED_GLASS:15)
B(4,30,14,STAINED_GLASS:9)
B(5,30,14,STAINED_GLASS:9)
B(6,30,14,STAINED_GLASS:15)
B(7,30,14,STAINED_GLASS:15)
B(8,30,14,STAINED_GLASS:15)
B(9,30,14,STAINED_GLASS:15)
B(7,31,3,STAINED_GLASS:9)
B(6,31,4,STAINED_GLASS:9)
B(7,31,4,STAINED_GLASS:9)
B(3,31,5,STAINED_GLASS:9)
B(4,31,5,STAINED_GLASS:9)
B(5,31,5,STAINED_GLASS:15)
B(6,31,5,STAINED_GLASS:9)
B(7,31,5,STAINED_GLASS:9)
B(8,31,5,STAINED_GLASS:9)
B(1,31,6,STAINED_GLASS:15)
B(2,31,6,STAINED_GLASS:9)
B(3,31,6,STAINED_GLASS:9)
B(4,31,6,STAINED_GLASS:9)
B(5,31,6,STAINED_GLASS:15)
B(6,31,6,STAINED_GLASS:9)
B(7,31,6,STAINED_GLASS:9)
B(8,31,6,STAINED_GLASS:15)
B(9,31,6,STAINED_GLASS:9)
B(1,31,7,STAINED_GLASS:15)
B(2,31,7,STAINED_GLASS:9)
B(3,31,7,STAINED_GLASS:9)
B(4,31,7,STAINED_GLASS:9)
B(5,31,7,STAINED_GLASS:9)
B(6,31,7,STAINED_GLASS:11)
B(7,31,7,STAINED_GLASS:11)
B(8,31,7,STAINED_GLASS:9)
B(9,31,7,STAINED_GLASS:9)
B(1,31,8,STAINED_GLASS:15)
B(2,31,8,STAINED_GLASS:9)
B(3,31,8,STAINED_GLASS:11)
B(4,31,8,STAINED_GLASS:9)
B(5,31,8,STAINED_GLASS:11)
B(6,31,8,STAINED_GLASS:11)
B(7,31,8,STAINED_GLASS:11)
B(8,31,8,STAINED_GLASS:11)
B(9,31,8,STAINED_GLASS:9)
B(10,31,8,STAINED_GLASS:9)
B(2,31,9,STAINED_GLASS:9)
B(3,31,9,STAINED_GLASS:9)
B(4,31,9,STAINED_GLASS:11)
B(5,31,9,SEA_LANTERN)
B(6,31,9,SEA_LANTERN)
B(7,31,9,STAINED_GLASS:11)
B(8,31,9,STAINED_GLASS:11)
B(9,31,9,STAINED_GLASS:9)
B(10,31,9,STAINED_GLASS:9)
B(11,31,9,STAINED_GLASS:9)
B(2,31,10,STAINED_GLASS:15)
B(3,31,10,STAINED_GLASS:15)
B(4,31,10,STAINED_GLASS:11)
B(5,31,10,STAINED_GLASS:11)
B(6,31,10,SEA_LANTERN)
B(7,31,10,SEA_LANTERN)
B(8,31,10,STAINED_GLASS:11)
B(9,31,10,STAINED_GLASS:11)
B(10,31,10,STAINED_GLASS:15)
B(2,31,11,STAINED_GLASS:15)
B(3,31,11,STAINED_GLASS:9)
B(4,31,11,STAINED_GLASS:11)
B(5,31,11,STAINED_GLASS:11)
B(6,31,11,STAINED_GLASS:11)
B(7,31,11,STAINED_GLASS:11)
B(8,31,11,STAINED_GLASS:11)
B(9,31,11,STAINED_GLASS:11)
B(10,31,11,STAINED_GLASS:9)
B(11,31,11,STAINED_GLASS:15)
B(3,31,12,STAINED_GLASS:9)
B(4,31,12,STAINED_GLASS:9)
B(5,31,12,STAINED_GLASS:11)
B(6,31,12,STAINED_GLASS:11)
B(7,31,12,STAINED_GLASS:15)
B(8,31,12,STAINED_GLASS:15)
B(9,31,12,STAINED_GLASS:9)
B(10,31,12,STAINED_GLASS:9)
B(3,31,13,STAINED_GLASS:9)
B(4,31,13,STAINED_GLASS:9)
B(5,31,13,STAINED_GLASS:9)
B(6,31,13,STAINED_GLASS:9)
B(7,31,13,STAINED_GLASS:15)
B(8,31,13,STAINED_GLASS:15)
B(9,31,13,STAINED_GLASS:15)
B(4,31,14,STAINED_GLASS:9)
B(5,31,14,STAINED_GLASS:9)
B(6,31,14,STAINED_GLASS:9)
B(7,31,14,STAINED_GLASS:15)
B(6,32,3,STAINED_GLASS:9)
B(7,32,3,STAINED_GLASS:9)
B(4,32,4,STAINED_GLASS:15)
B(5,32,4,STAINED_GLASS:9)
B(6,32,4,STAINED_GLASS:9)
B(7,32,4,STAINED_GLASS:9)
B(1,32,5,STAINED_GLASS:15)
B(2,32,5,STAINED_GLASS:15)
B(3,32,5,STAINED_GLASS:9)
B(4,32,5,STAINED_GLASS:9)
B(5,32,5,STAINED_GLASS:9)
B(6,32,5,STAINED_GLASS:15)
B(7,32,5,STAINED_GLASS:9)
B(8,32,5,STAINED_GLASS:15)
B(9,32,5,STAINED_GLASS:9)
B(1,32,6,STAINED_GLASS:9)
B(2,32,6,STAINED_GLASS:9)
B(3,32,6,STAINED_GLASS:15)
B(4,32,6,STAINED_GLASS:15)
B(5,32,6,STAINED_GLASS:9)
B(6,32,6,STAINED_GLASS:11)
B(7,32,6,STAINED_GLASS:9)
B(8,32,6,STAINED_GLASS:9)
B(9,32,6,STAINED_GLASS:9)
B(1,32,7,STAINED_GLASS:9)
B(2,32,7,STAINED_GLASS:15)
B(3,32,7,STAINED_GLASS:9)
B(4,32,7,STAINED_GLASS:9)
B(5,32,7,STAINED_GLASS:11)
B(6,32,7,STAINED_GLASS:11)
B(7,32,7,STAINED_GLASS:11)
B(8,32,7,STAINED_GLASS:9)
B(9,32,7,STAINED_GLASS:9)
B(1,32,8,STAINED_GLASS:9)
B(2,32,8,STAINED_GLASS:9)
B(3,32,8,STAINED_GLASS:11)
B(4,32,8,STAINED_GLASS:11)
B(5,32,8,STAINED_GLASS:11)
B(6,32,8,SEA_LANTERN)
B(7,32,8,STAINED_GLASS:11)
B(8,32,8,STAINED_GLASS:11)
B(9,32,8,STAINED_GLASS:9)
B(10,32,8,STAINED_GLASS:9)
B(1,32,9,STAINED_GLASS:9)
B(2,32,9,STAINED_GLASS:9)
B(3,32,9,STAINED_GLASS:9)
B(4,32,9,STAINED_GLASS:11)
B(5,32,9,SEA_LANTERN)
B(6,32,9,SEA_LANTERN)
B(7,32,9,STAINED_GLASS:11)
B(8,32,9,STAINED_GLASS:11)
B(9,32,9,STAINED_GLASS:9)
B(10,32,9,STAINED_GLASS:9)
B(11,32,9,STAINED_GLASS:15)
B(2,32,10,STAINED_GLASS:9)
B(3,32,10,STAINED_GLASS:9)
B(4,32,10,STAINED_GLASS:11)
B(5,32,10,STAINED_GLASS:11)
B(6,32,10,STAINED_GLASS:11)
B(7,32,10,STAINED_GLASS:11)
B(8,32,10,STAINED_GLASS:11)
B(9,32,10,STAINED_GLASS:15)
B(10,32,10,STAINED_GLASS:15)
B(2,32,11,STAINED_GLASS:15)
B(3,32,11,STAINED_GLASS:9)
B(4,32,11,STAINED_GLASS:11)
B(5,32,11,STAINED_GLASS:11)
B(6,32,11,STAINED_GLASS:11)
B(7,32,11,STAINED_GLASS:11)
B(8,32,11,STAINED_GLASS:15)
B(9,32,11,STAINED_GLASS:15)
B(10,32,11,STAINED_GLASS:15)
B(3,32,12,STAINED_GLASS:9)
B(4,32,12,STAINED_GLASS:9)
B(5,32,12,STAINED_GLASS:9)
B(6,32,12,STAINED_GLASS:9)
B(7,32,12,STAINED_GLASS:15)
B(8,32,12,STAINED_GLASS:15)
B(3,32,13,STAINED_GLASS:9)
B(4,32,13,STAINED_GLASS:9)
B(5,32,13,STAINED_GLASS:9)
B(6,32,13,STAINED_GLASS:15)
B(7,32,13,STAINED_GLASS:15)
B(7,33,2,STAINED_GLASS:9)
B(4,33,3,STAINED_GLASS:15)
B(5,33,3,STAINED_GLASS:9)
B(6,33,3,STAINED_GLASS:9)
B(7,33,3,STAINED_GLASS:9)
B(3,33,4,STAINED_GLASS:15)
B(4,33,4,STAINED_GLASS:9)
B(5,33,4,STAINED_GLASS:9)
B(6,33,4,STAINED_GLASS:9)
B(7,33,4,STAINED_GLASS:9)
B(0,33,5,STAINED_GLASS:15)
B(1,33,5,STAINED_GLASS:9)
B(2,33,5,STAINED_GLASS:9)
B(3,33,5,STAINED_GLASS:15)
B(4,33,5,STAINED_GLASS:15)
B(5,33,5,STAINED_GLASS:15)
B(6,33,5,STAINED_GLASS:9)
B(7,33,5,STAINED_GLASS:11)
B(8,33,5,STAINED_GLASS:15)
B(9,33,5,STAINED_GLASS:9)
B(1,33,6,STAINED_GLASS:15)
B(2,33,6,STAINED_GLASS:15)
B(3,33,6,STAINED_GLASS:9)
B(4,33,6,STAINED_GLASS:9)
B(5,33,6,STAINED_GLASS:11)
B(6,33,6,STAINED_GLASS:11)
B(7,33,6,STAINED_GLASS:9)
B(8,33,6,STAINED_GLASS:9)
B(9,33,6,STAINED_GLASS:9)
B(1,33,7,STAINED_GLASS:15)
B(2,33,7,STAINED_GLASS:9)
B(3,33,7,STAINED_GLASS:11)
B(4,33,7,STAINED_GLASS:11)
B(5,33,7,STAINED_GLASS:11)
B(6,33,7,SEA_LANTERN)
B(7,33,7,STAINED_GLASS:11)
B(8,33,7,STAINED_GLASS:9)
B(9,33,7,STAINED_GLASS:9)
B(1,33,8,STAINED_GLASS:9)
B(2,33,8,STAINED_GLASS:9)
B(3,33,8,STAINED_GLASS:11)
B(4,33,8,STAINED_GLASS:11)
B(5,33,8,SEA_LANTERN)
B(6,33,8,SEA_LANTERN)
B(7,33,8,STAINED_GLASS:11)
B(8,33,8,STAINED_GLASS:11)
B(9,33,8,STAINED_GLASS:9)
B(10,33,8,STAINED_GLASS:9)
B(1,33,9,STAINED_GLASS:9)
B(2,33,9,STAINED_GLASS:9)
B(3,33,9,STAINED_GLASS:9)
B(4,33,9,STAINED_GLASS:11)
B(5,33,9,SEA_LANTERN)
B(6,33,9,STAINED_GLASS:11)
B(7,33,9,STAINED_GLASS:11)
B(8,33,9,STAINED_GLASS:11)
B(9,33,9,STAINED_GLASS:9)
B(10,33,9,STAINED_GLASS:15)
B(2,33,10,STAINED_GLASS:9)
B(3,33,10,STAINED_GLASS:15)
B(4,33,10,STAINED_GLASS:11)
B(5,33,10,STAINED_GLASS:11)
B(6,33,10,STAINED_GLASS:11)
B(7,33,10,STAINED_GLASS:11)
B(8,33,10,STAINED_GLASS:15)
B(9,33,10,STAINED_GLASS:15)
B(10,33,10,STAINED_GLASS:15)
B(2,33,11,STAINED_GLASS:15)
B(3,33,11,STAINED_GLASS:9)
B(4,33,11,STAINED_GLASS:11)
B(5,33,11,STAINED_GLASS:11)
B(6,33,11,STAINED_GLASS:9)
B(7,33,11,STAINED_GLASS:9)
B(8,33,11,STAINED_GLASS:15)
B(9,33,11,STAINED_GLASS:15)
B(3,33,12,STAINED_GLASS:9)
B(4,33,12,STAINED_GLASS:9)
B(5,33,12,STAINED_GLASS:9)
B(6,33,12,STAINED_GLASS:9)
B(7,33,12,STAINED_GLASS:15)
B(4,33,13,STAINED_GLASS:9)
B(6,33,13,STAINED_GLASS:15)
B(6,34,2,STAINED_GLASS:15)
B(7,34,2,STAINED_GLASS:15)
B(3,34,3,STAINED_GLASS:15)
B(4,34,3,STAINED_GLASS:9)
B(5,34,3,STAINED_GLASS:9)
B(6,34,3,STAINED_GLASS:15)
B(7,34,3,STAINED_GLASS:15)
B(1,34,4,STAINED_GLASS:15)
B(2,34,4,STAINED_GLASS:15)
B(3,34,4,STAINED_GLASS:9)
B(4,34,4,STAINED_GLASS:15)
B(5,34,4,STAINED_GLASS:15)
B(6,34,4,STAINED_GLASS:9)
B(7,34,4,STAINED_GLASS:9)
B(8,34,4,STAINED_GLASS:9)
B(0,34,5,STAINED_GLASS:9)
B(1,34,5,STAINED_GLASS:15)
B(2,34,5,STAINED_GLASS:15)
B(3,34,5,STAINED_GLASS:9)
B(4,34,5,STAINED_GLASS:9)
B(5,34,5,STAINED_GLASS:9)
B(6,34,5,STAINED_GLASS:11)
B(7,34,5,STAINED_GLASS:11)
B(8,34,5,STAINED_GLASS:9)
B(9,34,5,STAINED_GLASS:9)
B(1,34,6,STAINED_GLASS:9)
B(2,34,6,STAINED_GLASS:9)
B(3,34,6,STAINED_GLASS:11)
B(4,34,6,STAINED_GLASS:11)
B(5,34,6,STAINED_GLASS:11)
B(6,34,6,STAINED_GLASS:11)
B(7,34,6,STAINED_GLASS:9)
B(8,34,6,STAINED_GLASS:9)
B(9,34,6,STAINED_GLASS:9)
B(1,34,7,STAINED_GLASS:9)
B(2,34,7,STAINED_GLASS:9)
B(3,34,7,STAINED_GLASS:11)
B(4,34,7,STAINED_GLASS:11)
B(5,34,7,SEA_LANTERN)
B(6,34,7,SEA_LANTERN)
B(7,34,7,STAINED_GLASS:11)
B(8,34,7,STAINED_GLASS:9)
B(9,34,7,STAINED_GLASS:9)
B(1,34,8,STAINED_GLASS:15)
B(2,34,8,STAINED_GLASS:9)
B(3,34,8,STAINED_GLASS:11)
B(4,34,8,STAINED_GLASS:11)
B(5,34,8,SEA_LANTERN)
B(6,34,8,SEA_LANTERN)
B(7,34,8,STAINED_GLASS:11)
B(8,34,8,STAINED_GLASS:11)
B(9,34,8,STAINED_GLASS:9)
B(10,34,8,STAINED_GLASS:15)
B(1,34,9,STAINED_GLASS:15)
B(2,34,9,STAINED_GLASS:15)
B(3,34,9,STAINED_GLASS:9)
B(4,34,9,STAINED_GLASS:11)
B(5,34,9,STAINED_GLASS:11)
B(6,34,9,STAINED_GLASS:11)
B(7,34,9,STAINED_GLASS:11)
B(8,34,9,STAINED_GLASS:15)
B(9,34,9,STAINED_GLASS:15)
B(10,34,9,STAINED_GLASS:15)
B(2,34,10,STAINED_GLASS:15)
B(3,34,10,STAINED_GLASS:15)
B(4,34,10,STAINED_GLASS:11)
B(5,34,10,STAINED_GLASS:11)
B(6,34,10,STAINED_GLASS:9)
B(7,34,10,STAINED_GLASS:15)
B(8,34,10,STAINED_GLASS:15)
B(2,34,11,STAINED_GLASS:15)
B(3,34,11,STAINED_GLASS:9)
B(4,34,11,STAINED_GLASS:9)
B(5,34,11,STAINED_GLASS:9)
B(6,34,11,STAINED_GLASS:9)
B(7,34,11,STAINED_GLASS:15)
B(8,34,11,STAINED_GLASS:15)
B(3,34,12,STAINED_GLASS:9)
B(4,34,12,STAINED_GLASS:9)
B(6,34,12,STAINED_GLASS:9)
B(6,35,2,STAINED_GLASS:15)
B(7,35,2,STAINED_GLASS:15)
B(3,35,3,STAINED_GLASS:15)
B(4,35,3,STAINED_GLASS:9)
B(5,35,3,STAINED_GLASS:9)
B(6,35,3,STAINED_GLASS:15)
B(7,35,3,STAINED_GLASS:15)
B(1,35,4,STAINED_GLASS:15)
B(2,35,4,STAINED_GLASS:15)
B(3,35,4,STAINED_GLASS:9)
B(4,35,4,STAINED_GLASS:15)
B(5,35,4,STAINED_GLASS:15)
B(6,35,4,STAINED_GLASS:9)
B(7,35,4,STAINED_GLASS:9)
B(8,35,4,STAINED_GLASS:9)
B(0,35,5,STAINED_GLASS:9)
B(1,35,5,STAINED_GLASS:15)
B(2,35,5,STAINED_GLASS:15)
B(3,35,5,STAINED_GLASS:9)
B(4,35,5,STAINED_GLASS:9)
B(5,35,5,STAINED_GLASS:9)
B(6,35,5,STAINED_GLASS:11)
B(7,35,5,STAINED_GLASS:11)
B(8,35,5,STAINED_GLASS:9)
B(9,35,5,STAINED_GLASS:9)
B(1,35,6,STAINED_GLASS:9)
B(2,35,6,STAINED_GLASS:9)
B(3,35,6,STAINED_GLASS:11)
B(4,35,6,STAINED_GLASS:11)
B(5,35,6,SEA_LANTERN)
B(6,35,6,STAINED_GLASS:11)
B(7,35,6,STAINED_GLASS:9)
B(8,35,6,STAINED_GLASS:9)
B(9,35,6,STAINED_GLASS:9)
B(1,35,7,STAINED_GLASS:9)
B(2,35,7,STAINED_GLASS:9)
B(3,35,7,STAINED_GLASS:11)
B(4,35,7,SEA_LANTERN)
B(5,35,7,SEA_LANTERN)
B(6,35,7,SEA_LANTERN)
B(7,35,7,STAINED_GLASS:11)
B(8,35,7,STAINED_GLASS:9)
B(9,35,7,STAINED_GLASS:15)
B(1,35,8,STAINED_GLASS:15)
B(2,35,8,STAINED_GLASS:15)
B(3,35,8,STAINED_GLASS:11)
B(4,35,8,STAINED_GLASS:11)
B(5,35,8,SEA_LANTERN)
B(6,35,8,STAINED_GLASS:11)
B(7,35,8,STAINED_GLASS:11)
B(8,35,8,STAINED_GLASS:11)
B(9,35,8,STAINED_GLASS:9)
B(1,35,9,STAINED_GLASS:15)
B(2,35,9,STAINED_GLASS:15)
B(3,35,9,STAINED_GLASS:15)
B(4,35,9,STAINED_GLASS:11)
B(5,35,9,STAINED_GLASS:11)
B(6,35,9,STAINED_GLASS:9)
B(7,35,9,STAINED_GLASS:15)
B(8,35,9,STAINED_GLASS:15)
B(10,35,9,STAINED_GLASS:15)
B(2,35,10,STAINED_GLASS:15)
B(3,35,10,STAINED_GLASS:15)
B(4,35,10,STAINED_GLASS:11)
B(5,35,10,STAINED_GLASS:9)
B(6,35,10,STAINED_GLASS:9)
B(7,35,10,STAINED_GLASS:15)
B(8,35,10,STAINED_GLASS:15)
B(3,35,11,STAINED_GLASS:9)
B(4,35,11,STAINED_GLASS:9)
B(5,35,11,STAINED_GLASS:9)
B(6,35,11,STAINED_GLASS:9)
B(7,35,11,STAINED_GLASS:9)
B(3,35,12,STAINED_GLASS:9)
B(4,36,2,STAINED_GLASS:15)
B(5,36,2,STAINED_GLASS:15)
B(6,36,2,STAINED_GLASS:15)
B(7,36,2,STAINED_GLASS:15)
B(1,36,3,STAINED_GLASS:15)
B(2,36,3,STAINED_GLASS:15)
B(3,36,3,STAINED_GLASS:9)
B(4,36,3,STAINED_GLASS:15)
B(5,36,3,STAINED_GLASS:15)
B(6,36,3,STAINED_GLASS:15)
B(7,36,3,STAINED_GLASS:15)
B(1,36,4,STAINED_GLASS:15)
B(2,36,4,STAINED_GLASS:9)
B(3,36,4,STAINED_GLASS:15)
B(4,36,4,STAINED_GLASS:9)
B(5,36,4,STAINED_GLASS:9)
B(6,36,4,STAINED_GLASS:9)
B(7,36,4,STAINED_GLASS:9)
B(0,36,5,STAINED_GLASS:15)
B(1,36,5,STAINED_GLASS:15)
B(2,36,5,STAINED_GLASS:9)
B(3,36,5,STAINED_GLASS:11)
B(4,36,5,STAINED_GLASS:11)
B(5,36,5,STAINED_GLASS:11)
B(6,36,5,STAINED_GLASS:11)
B(7,36,5,STAINED_GLASS:11)
B(8,36,5,STAINED_GLASS:9)
B(1,36,6,STAINED_GLASS:15)
B(2,36,6,STAINED_GLASS:9)
B(3,36,6,STAINED_GLASS:11)
B(4,36,6,SEA_LANTERN)
B(5,36,6,SEA_LANTERN)
B(6,36,6,STAINED_GLASS:11)
B(7,36,6,STAINED_GLASS:9)
B(8,36,6,STAINED_GLASS:9)
B(1,36,7,STAINED_GLASS:15)
B(2,36,7,STAINED_GLASS:9)
B(3,36,7,STAINED_GLASS:11)
B(4,36,7,SEA_LANTERN)
B(5,36,7,SEA_LANTERN)
B(6,36,7,STAINED_GLASS:11)
B(7,36,7,STAINED_GLASS:11)
B(8,36,7,STAINED_GLASS:9)
B(9,36,7,STAINED_GLASS:15)
B(1,36,8,STAINED_GLASS:15)
B(2,36,8,STAINED_GLASS:15)
B(3,36,8,STAINED_GLASS:11)
B(4,36,8,STAINED_GLASS:11)
B(5,36,8,STAINED_GLASS:11)
B(6,36,8,STAINED_GLASS:11)
B(7,36,8,STAINED_GLASS:11)
B(8,36,8,STAINED_GLASS:9)
B(9,36,8,STAINED_GLASS:9)
B(2,36,9,STAINED_GLASS:15)
B(3,36,9,STAINED_GLASS:15)
B(4,36,9,STAINED_GLASS:11)
B(5,36,9,STAINED_GLASS:9)
B(6,36,9,STAINED_GLASS:9)
B(7,36,9,STAINED_GLASS:15)
B(3,36,10,STAINED_GLASS:15)
B(4,36,10,STAINED_GLASS:15)
B(5,36,10,STAINED_GLASS:9)
B(6,36,10,STAINED_GLASS:9)
B(7,36,10,STAINED_GLASS:9)
B(4,37,2,STAINED_GLASS:15)
B(5,37,2,STAINED_GLASS:15)
B(6,37,2,STAINED_GLASS:15)
B(1,37,3,STAINED_GLASS:15)
B(2,37,3,STAINED_GLASS:15)
B(3,37,3,STAINED_GLASS:9)
B(4,37,3,STAINED_GLASS:15)
B(5,37,3,STAINED_GLASS:15)
B(6,37,3,STAINED_GLASS:15)
B(1,37,4,STAINED_GLASS:15)
B(2,37,4,STAINED_GLASS:9)
B(3,37,4,STAINED_GLASS:15)
B(4,37,4,STAINED_GLASS:9)
B(5,37,4,STAINED_GLASS:9)
B(6,37,4,STAINED_GLASS:9)
B(7,37,4,STAINED_GLASS:9)
B(1,37,5,STAINED_GLASS:15)
B(2,37,5,STAINED_GLASS:9)
B(3,37,5,STAINED_GLASS:11)
B(4,37,5,STAINED_GLASS:11)
B(5,37,5,STAINED_GLASS:11)
B(6,37,5,STAINED_GLASS:11)
B(7,37,5,STAINED_GLASS:9)
B(2,37,6,STAINED_GLASS:9)
B(3,37,6,STAINED_GLASS:11)
B(4,37,6,SEA_LANTERN)
B(5,37,6,STAINED_GLASS:11)
B(6,37,6,STAINED_GLASS:11)
B(7,37,6,STAINED_GLASS:9)
B(2,37,7,STAINED_GLASS:15)
B(3,37,7,STAINED_GLASS:15)
B(4,37,7,STAINED_GLASS:11)
B(5,37,7,STAINED_GLASS:11)
B(6,37,7,STAINED_GLASS:11)
B(7,37,7,STAINED_GLASS:9)
B(8,37,7,STAINED_GLASS:9)
B(2,37,8,STAINED_GLASS:15)
B(3,37,8,STAINED_GLASS:15)
B(4,37,8,STAINED_GLASS:11)
B(5,37,8,STAINED_GLASS:11)
B(6,37,8,STAINED_GLASS:9)
B(7,37,8,STAINED_GLASS:9)
B(8,37,8,STAINED_GLASS:9)
B(3,37,9,STAINED_GLASS:15)
B(4,37,9,STAINED_GLASS:9)
B(5,37,9,STAINED_GLASS:9)
B(6,37,9,STAINED_GLASS:9)
B(7,37,9,STAINED_GLASS:15)
B(4,37,10,STAINED_GLASS:15)
B(5,37,10,STAINED_GLASS:9)
B(4,38,1,STAINED_GLASS:15)
B(1,38,2,STAINED_GLASS:15)
B(2,38,2,STAINED_GLASS:15)
B(3,38,2,STAINED_GLASS:15)
B(4,38,2,STAINED_GLASS:9)
B(5,38,2,STAINED_GLASS:15)
B(6,38,2,STAINED_GLASS:9)
B(1,38,3,STAINED_GLASS:15)
B(2,38,3,STAINED_GLASS:9)
B(3,38,3,STAINED_GLASS:15)
B(4,38,3,STAINED_GLASS:9)
B(5,38,3,STAINED_GLASS:15)
B(6,38,3,STAINED_GLASS:9)
B(1,38,4,STAINED_GLASS:15)
B(2,38,4,STAINED_GLASS:15)
B(3,38,4,STAINED_GLASS:9)
B(4,38,4,STAINED_GLASS:9)
B(5,38,4,STAINED_GLASS:9)
B(6,38,4,STAINED_GLASS:9)
B(7,38,4,STAINED_GLASS:9)
B(1,38,5,STAINED_GLASS:15)
B(2,38,5,STAINED_GLASS:9)
B(3,38,5,STAINED_GLASS:11)
B(4,38,5,STAINED_GLASS:11)
B(5,38,5,STAINED_GLASS:11)
B(6,38,5,STAINED_GLASS:9)
B(7,38,5,STAINED_GLASS:9)
B(2,38,6,STAINED_GLASS:9)
B(3,38,6,STAINED_GLASS:9)
B(4,38,6,STAINED_GLASS:11)
B(5,38,6,STAINED_GLASS:11)
B(6,38,6,STAINED_GLASS:9)
B(7,38,6,STAINED_GLASS:9)
B(2,38,7,STAINED_GLASS:9)
B(3,38,7,STAINED_GLASS:15)
B(4,38,7,STAINED_GLASS:11)
B(5,38,7,STAINED_GLASS:11)
B(6,38,7,STAINED_GLASS:9)
B(7,38,7,STAINED_GLASS:9)
B(2,38,8,STAINED_GLASS:15)
B(3,38,8,STAINED_GLASS:15)
B(4,38,8,STAINED_GLASS:15)
B(5,38,8,STAINED_GLASS:9)
B(6,38,8,STAINED_GLASS:9)
B(7,38,8,STAINED_GLASS:9)
B(4,38,9,STAINED_GLASS:9)
B(5,38,9,STAINED_GLASS:9)
B(4,39,1,STAINED_GLASS:15)
B(1,39,2,STAINED_GLASS:15)
B(2,39,2,STAINED_GLASS:15)
B(3,39,2,STAINED_GLASS:15)
B(4,39,2,STAINED_GLASS:9)
B(5,39,2,STAINED_GLASS:15)
B(1,39,3,STAINED_GLASS:15)
B(2,39,3,STAINED_GLASS:9)
B(3,39,3,STAINED_GLASS:15)
B(4,39,3,STAINED_GLASS:9)
B(5,39,3,STAINED_GLASS:15)
B(2,39,4,STAINED_GLASS:15)
B(3,39,4,STAINED_GLASS:9)
B(4,39,4,STAINED_GLASS:11)
B(5,39,4,STAINED_GLASS:9)
B(6,39,4,STAINED_GLASS:9)
B(2,39,5,STAINED_GLASS:15)
B(3,39,5,STAINED_GLASS:9)
B(4,39,5,STAINED_GLASS:9)
B(5,39,5,STAINED_GLASS:9)
B(6,39,5,STAINED_GLASS:9)
B(7,39,5,STAINED_GLASS:9)
B(2,39,6,STAINED_GLASS:15)
B(3,39,6,STAINED_GLASS:15)
B(4,39,6,STAINED_GLASS:11)
B(5,39,6,SEA_LANTERN)
B(6,39,6,STAINED_GLASS:15)
B(3,39,7,STAINED_GLASS:15)
B(4,39,7,STAINED_GLASS:15)
B(5,39,7,STAINED_GLASS:9)
B(6,39,7,STAINED_GLASS:9)
B(4,39,8,STAINED_GLASS:9)
B(5,39,8,STAINED_GLASS:9)
B(6,39,8,STAINED_GLASS:9)
B(7,39,8,STAINED_GLASS:9)
B(4,39,9,STAINED_GLASS:9)
B(4,40,1,STAINED_GLASS:15)
B(1,40,2,STAINED_GLASS:15)
B(2,40,2,STAINED_GLASS:15)
B(3,40,2,STAINED_GLASS:15)
B(4,40,2,STAINED_GLASS:9)
B(5,40,2,STAINED_GLASS:9)
B(1,40,3,STAINED_GLASS:15)
B(2,40,3,STAINED_GLASS:9)
B(3,40,3,STAINED_GLASS:15)
B(4,40,3,STAINED_GLASS:9)
B(5,40,3,STAINED_GLASS:9)
B(2,40,4,STAINED_GLASS:15)
B(3,40,4,STAINED_GLASS:9)
B(4,40,4,STAINED_GLASS:11)
B(5,40,4,STAINED_GLASS:9)
B(6,40,4,STAINED_GLASS:9)
B(2,40,5,STAINED_GLASS:15)
B(3,40,5,STAINED_GLASS:15)
B(4,40,5,STAINED_GLASS:15)
B(5,40,5,STAINED_GLASS:9)
B(6,40,5,STAINED_GLASS:9)
B(2,40,6,STAINED_GLASS:15)
B(3,40,6,STAINED_GLASS:9)
B(4,40,6,STAINED_GLASS:9)
B(5,40,6,STAINED_GLASS:9)
B(6,40,6,STAINED_GLASS:15)
B(4,40,7,STAINED_GLASS:9)
B(5,40,7,STAINED_GLASS:9)
B(6,40,7,STAINED_GLASS:9)
B(4,40,8,STAINED_GLASS:9)
B(5,40,8,STAINED_GLASS:9)
B(3,41,1,STAINED_GLASS:15)
B(4,41,1,STAINED_GLASS:15)
B(1,41,2,STAINED_GLASS:15)
B(2,41,2,STAINED_GLASS:9)
B(3,41,2,STAINED_GLASS:9)
B(4,41,2,STAINED_GLASS:15)
B(2,41,3,STAINED_GLASS:15)
B(3,41,3,STAINED_GLASS:9)
B(4,41,3,STAINED_GLASS:9)
B(2,41,4,STAINED_GLASS:15)
B(3,41,4,STAINED_GLASS:9)
B(4,41,4,STAINED_GLASS:9)
B(5,41,4,STAINED_GLASS:9)
B(2,41,5,STAINED_GLASS:9)
B(3,41,5,STAINED_GLASS:9)
B(4,41,5,STAINED_GLASS:9)
B(5,41,5,STAINED_GLASS:9)
B(6,41,5,STAINED_GLASS:9)
B(3,41,6,STAINED_GLASS:9)
B(4,41,6,STAINED_GLASS:9)
B(5,41,6,STAINED_GLASS:9)
B(4,41,7,STAINED_GLASS:9)
B(3,42,1,STAINED_GLASS:15)
B(4,42,1,STAINED_GLASS:9)
B(1,42,2,STAINED_GLASS:15)
B(2,42,2,STAINED_GLASS:9)
B(3,42,2,STAINED_GLASS:9)
B(4,42,2,STAINED_GLASS:15)
B(2,42,3,STAINED_GLASS:15)
B(3,42,3,STAINED_GLASS:9)
B(4,42,3,STAINED_GLASS:9)
B(2,42,4,STAINED_GLASS:15)
B(3,42,4,STAINED_GLASS:9)
B(4,42,4,STAINED_GLASS:9)
B(5,42,4,STAINED_GLASS:9)
B(2,42,5,STAINED_GLASS:9)
B(3,42,5,STAINED_GLASS:9)
B(4,42,5,STAINED_GLASS:9)
B(5,42,5,STAINED_GLASS:9)
B(2,43,0,STAINED_GLASS:15)
B(2,43,1,STAINED_GLASS:15)
B(3,43,1,STAINED_GLASS:15)
B(2,43,2,STAINED_GLASS:15)
B(3,43,2,STAINED_GLASS:15)
B(4,43,2,STAINED_GLASS:15)
B(2,43,3,STAINED_GLASS:15)
B(3,43,3,STAINED_GLASS:9)
B(4,43,3,STAINED_GLASS:9)
B(3,43,4,STAINED_GLASS:15)
B(2,44,0,STAINED_GLASS:15)
B(2,44,1,STAINED_GLASS:15)
B(3,44,1,STAINED_GLASS:15)
B(2,44,2,STAINED_GLASS:15)
B(3,44,2,STAINED_GLASS:15)
B(4,44,2,STAINED_GLASS:15)
B(2,44,3,STAINED_GLASS:15)
B(3,44,3,STAINED_GLASS:15)
B(2,45,0,STAINED_GLASS:15)
B(2,45,1,STAINED_GLASS:15)
B(2,45,2,STAINED_GLASS:15)
B(3,45,2,STAINED_GLASS:15)

