
#######################################################################
# +-----------------------------------------------------------------+ #
# |                            BO3 object                           | #
# +-----------------------------------------------------------------+ #
#######################################################################

Author: BO3 BulkEdit (by LanToaster)

Description: This Object was Created with BO3_BulkEdit

Version: 3

SettingsMode: WriteWithoutComments


#######################################################################
# +-----------------------------------------------------------------+ #
# |                          Main settings                          | #
# +-----------------------------------------------------------------+ #
#######################################################################

Tree: false

Frequency: 100

Rarity: 100.0

RotateRandomly: true

SpawnHeight: randomY

SpawnHeightOffset: 0

SpawnHeightVariance: 0

##############################
# Height Limits for the BO3. #
##############################

MinHeight: 87

MaxHeight: 87

######################
# Extrusion settings #
######################

ExtrudeMode: None

ExtrudeThroughBlocks: minecraft:air

MaxBranchDepth: 50


#######################################################################
# +-----------------------------------------------------------------+ #
# |                      Source block settings                      | #
# +-----------------------------------------------------------------+ #
#######################################################################

SourceBlocks: otg:air

MaxPercentageOutsideSourceBlock: 100

OutsideSourceBlock: placeAnyway

DoReplaceBlocks: true

IsOTGPlus: false


#######################################################################
# +-----------------------------------------------------------------+ #
# |                              Blocks                             | #
# +-----------------------------------------------------------------+ #
#######################################################################

B(-7,-1,-7,minecraft:jungle_log)
B(-7,0,-7,minecraft:jungle_log)
B(-7,1,-7,minecraft:jungle_log)
B(-7,2,-7,minecraft:jungle_fence)
B(-7,3,-7,minecraft:torch)
B(-7,0,-6,minecraft:jungle_log[axis=z])
B(-7,1,-6,minecraft:jungle_slab)
B(-7,0,-5,minecraft:jungle_log[axis=z])
B(-7,1,-5,minecraft:jungle_slab)
B(-7,0,-4,minecraft:jungle_log[axis=z])
B(-7,1,-4,minecraft:jungle_slab)
B(-7,10,-4,minecraft:jungle_stairs[facing=south,half=top,shape=straight,waterlogged=false])
B(-7,11,-4,minecraft:birch_slab)
B(-7,-1,-3,minecraft:jungle_log)
B(-7,0,-3,minecraft:jungle_log)
B(-7,1,-3,minecraft:jungle_log)
B(-7,2,-3,minecraft:jungle_fence)
B(-7,3,-3,minecraft:jungle_fence)
B(-7,4,-3,minecraft:jungle_fence)
B(-7,5,-3,minecraft:jungle_fence)
B(-7,6,-3,minecraft:jungle_fence)
B(-7,7,-3,minecraft:jungle_fence)
B(-7,8,-3,minecraft:jungle_planks)
B(-7,9,-3,minecraft:jungle_planks)
B(-7,10,-3,minecraft:jungle_planks)
B(-7,11,-3,minecraft:birch_slab)
B(-7,0,-2,minecraft:jungle_log[axis=z])
B(-7,1,-2,minecraft:jungle_slab)
B(-7,10,-2,minecraft:jungle_stairs[facing=east,half=top,shape=straight,waterlogged=false])
B(-7,11,-2,minecraft:birch_slab)
B(-7,0,-1,minecraft:jungle_log[axis=z])
B(-7,1,-1,minecraft:jungle_slab)
B(-7,10,-1,minecraft:jungle_stairs[facing=east,half=top,shape=straight,waterlogged=false])
B(-7,11,-1,minecraft:birch_slab)
B(-7,-1,0,minecraft:jungle_log)
B(-7,0,0,minecraft:jungle_log)
B(-7,1,0,minecraft:jungle_log)
B(-7,2,0,minecraft:jungle_fence)
B(-7,3,0,minecraft:jungle_fence)
B(-7,4,0,minecraft:jungle_fence)
B(-7,5,0,minecraft:jungle_fence)
B(-7,6,0,minecraft:jungle_fence)
B(-7,7,0,minecraft:jungle_fence)
B(-7,8,0,minecraft:jungle_planks)
B(-7,9,0,minecraft:jungle_planks)
B(-7,10,0,minecraft:jungle_planks)
B(-7,11,0,minecraft:birch_slab)
B(-7,0,1,minecraft:jungle_log[axis=z])
B(-7,1,1,minecraft:jungle_slab)
B(-7,10,1,minecraft:jungle_stairs[facing=north,half=top,shape=straight,waterlogged=false])
B(-7,11,1,minecraft:birch_slab)
B(-7,0,2,minecraft:jungle_log[axis=z])
B(-7,1,2,minecraft:jungle_slab)
B(-7,0,3,minecraft:jungle_log[axis=z])
B(-7,1,3,minecraft:jungle_slab)
B(-7,-1,4,minecraft:jungle_log)
B(-7,0,4,minecraft:jungle_log)
B(-7,1,4,minecraft:jungle_log)
B(-7,2,4,minecraft:jungle_fence)
B(-7,3,4,minecraft:torch)
B(-6,0,-7,minecraft:jungle_log[axis=x])
B(-6,1,-7,minecraft:jungle_slab)
B(-6,0,-6,minecraft:jungle_slab[type=top,waterlogged=false])
B(-6,1,-6,minecraft:farmland[moisture=7])
B(-6,2,-6,minecraft:wheat)
B(-6,0,-5,minecraft:jungle_slab[type=top,waterlogged=false])
B(-6,1,-5,minecraft:farmland[moisture=7])
B(-6,2,-5,minecraft:wheat[age=1])
B(-6,0,-4,minecraft:jungle_slab[type=top,waterlogged=false])
B(-6,1,-4,minecraft:farmland[moisture=7])
B(-6,2,-4,minecraft:wheat[age=3])
B(-6,10,-4,minecraft:jungle_stairs[facing=south,half=top,shape=straight,waterlogged=false])
B(-6,11,-4,minecraft:birch_slab)
B(-6,0,-3,minecraft:jungle_slab[type=top,waterlogged=false])
B(-6,1,-3,minecraft:farmland[moisture=7])
B(-6,2,-3,minecraft:wheat[age=6])
B(-6,8,-3,minecraft:jungle_slab)
B(-6,9,-3,minecraft:jungle_planks)
B(-6,10,-3,minecraft:water)
B(-6,0,-2,minecraft:jungle_slab[type=top,waterlogged=false])
B(-6,1,-2,minecraft:farmland[moisture=7])
B(-6,2,-2,minecraft:wheat[age=2])
B(-6,9,-2,minecraft:jungle_slab[type=top,waterlogged=false])
B(-6,10,-2,minecraft:water)
B(-6,0,-1,minecraft:jungle_slab[type=top,waterlogged=false])
B(-6,1,-1,minecraft:farmland[moisture=7])
B(-6,2,-1,minecraft:wheat[age=2])
B(-6,9,-1,minecraft:jungle_slab[type=top,waterlogged=false])
B(-6,10,-1,minecraft:water)
B(-6,0,0,minecraft:jungle_slab[type=top,waterlogged=false])
B(-6,1,0,minecraft:farmland[moisture=7])
B(-6,2,0,minecraft:wheat[age=5])
B(-6,8,0,minecraft:jungle_slab)
B(-6,9,0,minecraft:jungle_planks)
B(-6,10,0,minecraft:water)
B(-6,0,1,minecraft:jungle_slab[type=top,waterlogged=false])
B(-6,1,1,minecraft:farmland[moisture=7])
B(-6,2,1,minecraft:wheat[age=2])
B(-6,10,1,minecraft:jungle_stairs[facing=north,half=top,shape=straight,waterlogged=false])
B(-6,11,1,minecraft:birch_slab)
B(-6,0,2,minecraft:jungle_slab[type=top,waterlogged=false])
B(-6,1,2,minecraft:farmland[moisture=7])
B(-6,2,2,minecraft:wheat)
B(-6,0,3,minecraft:jungle_slab[type=top,waterlogged=false])
B(-6,1,3,minecraft:farmland[moisture=7])
B(-6,2,3,minecraft:wheat[age=2])
B(-6,0,4,minecraft:jungle_log[axis=x])
B(-6,1,4,minecraft:jungle_slab)
B(-5,0,-7,minecraft:jungle_log[axis=x])
B(-5,1,-7,minecraft:jungle_slab)
B(-5,0,-6,minecraft:jungle_slab[type=top,waterlogged=false])
B(-5,1,-6,minecraft:farmland[moisture=7])
B(-5,2,-6,minecraft:wheat[age=1])
B(-5,0,-5,minecraft:jungle_slab[type=top,waterlogged=false])
B(-5,1,-5,minecraft:water)
B(-5,0,-4,minecraft:jungle_slab[type=top,waterlogged=false])
B(-5,1,-4,minecraft:water)
B(-5,10,-4,minecraft:jungle_stairs[facing=south,half=top,shape=straight,waterlogged=false])
B(-5,11,-4,minecraft:birch_slab)
B(-5,0,-3,minecraft:jungle_slab[type=top,waterlogged=false])
B(-5,1,-3,minecraft:water)
B(-5,8,-3,minecraft:jungle_slab)
B(-5,9,-3,minecraft:jungle_planks)
B(-5,10,-3,minecraft:water)
B(-5,0,-2,minecraft:jungle_slab[type=top,waterlogged=false])
B(-5,1,-2,minecraft:water)
B(-5,9,-2,minecraft:jungle_slab[type=top,waterlogged=false])
B(-5,10,-2,minecraft:water)
B(-5,0,-1,minecraft:jungle_slab[type=top,waterlogged=false])
B(-5,1,-1,minecraft:water)
B(-5,9,-1,minecraft:jungle_slab[type=top,waterlogged=false])
B(-5,10,-1,minecraft:water)
B(-5,0,0,minecraft:jungle_slab[type=top,waterlogged=false])
B(-5,1,0,minecraft:water)
B(-5,8,0,minecraft:jungle_slab)
B(-5,9,0,minecraft:jungle_planks)
B(-5,10,0,minecraft:water)
B(-5,0,1,minecraft:jungle_slab[type=top,waterlogged=false])
B(-5,1,1,minecraft:water)
B(-5,10,1,minecraft:jungle_stairs[facing=north,half=top,shape=straight,waterlogged=false])
B(-5,11,1,minecraft:birch_slab)
B(-5,0,2,minecraft:jungle_slab[type=top,waterlogged=false])
B(-5,1,2,minecraft:water)
B(-5,0,3,minecraft:jungle_slab[type=top,waterlogged=false])
B(-5,1,3,minecraft:farmland[moisture=7])
B(-5,2,3,minecraft:wheat[age=2])
B(-5,0,4,minecraft:jungle_log[axis=x])
B(-5,1,4,minecraft:jungle_slab)
B(-4,0,-7,minecraft:jungle_log[axis=x])
B(-4,1,-7,minecraft:jungle_slab)
B(-4,10,-7,minecraft:jungle_stairs[facing=east,half=top,shape=straight,waterlogged=false])
B(-4,11,-7,minecraft:birch_slab)
B(-4,0,-6,minecraft:jungle_slab[type=top,waterlogged=false])
B(-4,1,-6,minecraft:farmland[moisture=7])
B(-4,2,-6,minecraft:wheat[age=4])
B(-4,10,-6,minecraft:jungle_stairs[facing=east,half=top,shape=straight,waterlogged=false])
B(-4,11,-6,minecraft:birch_slab)
B(-4,0,-5,minecraft:jungle_slab[type=top,waterlogged=false])
B(-4,1,-5,minecraft:water)
B(-4,10,-5,minecraft:jungle_stairs[facing=east,half=top,shape=straight,waterlogged=false])
B(-4,11,-5,minecraft:birch_slab)
B(-4,0,-4,minecraft:jungle_slab[type=top,waterlogged=false])
B(-4,1,-4,minecraft:farmland[moisture=7])
B(-4,2,-4,minecraft:melon_stem)
B(-4,10,-4,minecraft:jungle_stairs[facing=east,half=top,shape=inner_right,waterlogged=false])
B(-4,11,-4,minecraft:birch_slab)
B(-4,0,-3,minecraft:jungle_slab[type=top,waterlogged=false])
B(-4,1,-3,minecraft:farmland[moisture=7])
B(-4,2,-3,minecraft:melon_stem[age=2])
B(-4,5,-3,minecraft:jungle_fence[east=true,north=false,south=false,waterlogged=false,west=false])
B(-4,6,-3,minecraft:torch)
B(-4,7,-3,minecraft:jungle_stairs[facing=east,half=top,shape=straight,waterlogged=false])
B(-4,8,-3,minecraft:jungle_slab)
B(-4,9,-3,minecraft:jungle_planks)
B(-4,10,-3,minecraft:water)
B(-4,0,-2,minecraft:jungle_slab[type=top,waterlogged=false])
B(-4,1,-2,minecraft:farmland[moisture=7])
B(-4,2,-2,minecraft:melon_stem[age=2])
B(-4,9,-2,minecraft:jungle_stairs[facing=east,half=top,shape=straight,waterlogged=false])
B(-4,10,-2,minecraft:water)
B(-4,0,-1,minecraft:jungle_slab[type=top,waterlogged=false])
B(-4,1,-1,minecraft:farmland[moisture=7])
B(-4,2,-1,minecraft:melon_stem[age=7])
B(-4,9,-1,minecraft:jungle_stairs[facing=east,half=top,shape=straight,waterlogged=false])
B(-4,10,-1,minecraft:water)
B(-4,0,0,minecraft:jungle_slab[type=top,waterlogged=false])
B(-4,1,0,minecraft:farmland[moisture=7])
B(-4,2,0,minecraft:melon_stem)
B(-4,5,0,minecraft:jungle_fence[east=true,north=false,south=false,waterlogged=false,west=false])
B(-4,6,0,minecraft:torch)
B(-4,7,0,minecraft:jungle_stairs[facing=east,half=top,shape=straight,waterlogged=false])
B(-4,8,0,minecraft:jungle_slab)
B(-4,9,0,minecraft:jungle_planks)
B(-4,10,0,minecraft:water)
B(-4,0,1,minecraft:jungle_slab[type=top,waterlogged=false])
B(-4,1,1,minecraft:farmland[moisture=7])
B(-4,2,1,minecraft:melon_stem[age=7])
B(-4,10,1,minecraft:jungle_stairs[facing=north,half=top,shape=inner_right,waterlogged=false])
B(-4,11,1,minecraft:birch_slab)
B(-4,0,2,minecraft:jungle_slab[type=top,waterlogged=false])
B(-4,1,2,minecraft:water)
B(-4,10,2,minecraft:jungle_stairs[facing=east,half=top,shape=straight,waterlogged=false])
B(-4,11,2,minecraft:birch_slab)
B(-4,0,3,minecraft:jungle_slab[type=top,waterlogged=false])
B(-4,1,3,minecraft:farmland[moisture=7])
B(-4,2,3,minecraft:wheat[age=1])
B(-4,10,3,minecraft:jungle_stairs[facing=east,half=top,shape=straight,waterlogged=false])
B(-4,11,3,minecraft:birch_slab)
B(-4,0,4,minecraft:jungle_log[axis=x])
B(-4,1,4,minecraft:jungle_slab)
B(-4,10,4,minecraft:jungle_stairs[facing=east,half=top,shape=straight,waterlogged=false])
B(-4,11,4,minecraft:birch_slab)
B(-3,-1,-7,minecraft:jungle_log)
B(-3,0,-7,minecraft:jungle_log)
B(-3,1,-7,minecraft:jungle_log)
B(-3,2,-7,minecraft:jungle_fence)
B(-3,3,-7,minecraft:jungle_fence)
B(-3,4,-7,minecraft:jungle_fence)
B(-3,5,-7,minecraft:jungle_fence)
B(-3,6,-7,minecraft:jungle_fence)
B(-3,7,-7,minecraft:jungle_fence)
B(-3,8,-7,minecraft:jungle_slab[type=double,waterlogged=false])
B(-3,9,-7,minecraft:jungle_planks)
B(-3,10,-7,minecraft:jungle_planks)
B(-3,11,-7,minecraft:birch_slab)
B(-3,0,-6,minecraft:jungle_slab[type=top,waterlogged=false])
B(-3,1,-6,minecraft:farmland[moisture=7])
B(-3,2,-6,minecraft:wheat)
B(-3,8,-6,minecraft:jungle_slab)
B(-3,9,-6,minecraft:jungle_planks)
B(-3,10,-6,minecraft:water)
B(-3,0,-5,minecraft:jungle_slab[type=top,waterlogged=false])
B(-3,1,-5,minecraft:water)
B(-3,8,-5,minecraft:jungle_slab)
B(-3,9,-5,minecraft:jungle_planks)
B(-3,10,-5,minecraft:water)
B(-3,0,-4,minecraft:jungle_slab[type=top,waterlogged=false])
B(-3,1,-4,minecraft:farmland[moisture=7])
B(-3,2,-4,minecraft:melon_stem[age=1])
B(-3,5,-4,minecraft:jungle_fence[east=false,north=false,south=true,waterlogged=false,west=false])
B(-3,6,-4,minecraft:torch)
B(-3,7,-4,minecraft:jungle_stairs[facing=south,half=top,shape=straight,waterlogged=false])
B(-3,8,-4,minecraft:jungle_slab)
B(-3,9,-4,minecraft:jungle_planks)
B(-3,10,-4,minecraft:water)
B(-3,-1,-3,minecraft:jungle_log)
B(-3,0,-3,minecraft:jungle_log)
B(-3,1,-3,minecraft:jungle_log)
B(-3,2,-3,minecraft:jungle_log)
B(-3,3,-3,minecraft:jungle_log)
B(-3,4,-3,minecraft:jungle_log)
B(-3,5,-3,minecraft:jungle_log)
B(-3,6,-3,minecraft:jungle_log)
B(-3,7,-3,minecraft:jungle_log)
B(-3,8,-3,minecraft:jungle_slab[type=double,waterlogged=false])
B(-3,9,-3,minecraft:water)
B(-3,10,-3,minecraft:water)
B(-3,0,-2,minecraft:jungle_slab[type=top,waterlogged=false])
B(-3,1,-2,minecraft:water)
B(-3,2,-2,minecraft:jungle_stairs[facing=east,half=bottom,shape=straight,waterlogged=false])
B(-3,3,-2,minecraft:jungle_stairs[facing=east,half=top,shape=straight,waterlogged=false])
B(-3,4,-2,minecraft:jungle_stairs[facing=east,half=bottom,shape=straight,waterlogged=false])
B(-3,5,-2,minecraft:jungle_stairs[facing=east,half=top,shape=straight,waterlogged=false])
B(-3,6,-2,minecraft:jungle_stairs[facing=east,half=bottom,shape=straight,waterlogged=false])
B(-3,7,-2,minecraft:jungle_stairs[facing=east,half=top,shape=straight,waterlogged=false])
B(-3,8,-2,minecraft:jungle_slab[type=double,waterlogged=false])
B(-3,9,-2,minecraft:water)
B(-3,10,-2,minecraft:water)
B(-3,0,-1,minecraft:jungle_slab[type=top,waterlogged=false])
B(-3,1,-1,minecraft:water)
B(-3,2,-1,minecraft:jungle_stairs[facing=east,half=bottom,shape=straight,waterlogged=false])
B(-3,3,-1,minecraft:jungle_stairs[facing=east,half=top,shape=straight,waterlogged=false])
B(-3,4,-1,minecraft:jungle_stairs[facing=east,half=bottom,shape=straight,waterlogged=false])
B(-3,5,-1,minecraft:jungle_stairs[facing=east,half=top,shape=straight,waterlogged=false])
B(-3,6,-1,minecraft:jungle_stairs[facing=east,half=bottom,shape=straight,waterlogged=false])
B(-3,7,-1,minecraft:jungle_stairs[facing=east,half=top,shape=straight,waterlogged=false])
B(-3,8,-1,minecraft:jungle_slab[type=double,waterlogged=false])
B(-3,9,-1,minecraft:water)
B(-3,10,-1,minecraft:water)
B(-3,-1,0,minecraft:jungle_log)
B(-3,0,0,minecraft:jungle_log)
B(-3,1,0,minecraft:jungle_log)
B(-3,2,0,minecraft:jungle_log)
B(-3,3,0,minecraft:jungle_log)
B(-3,4,0,minecraft:jungle_log)
B(-3,5,0,minecraft:jungle_log)
B(-3,6,0,minecraft:jungle_log)
B(-3,7,0,minecraft:jungle_log)
B(-3,8,0,minecraft:jungle_slab[type=double,waterlogged=false])
B(-3,9,0,minecraft:water)
B(-3,10,0,minecraft:water)
B(-3,0,1,minecraft:jungle_slab[type=top,waterlogged=false])
B(-3,1,1,minecraft:farmland[moisture=7])
B(-3,2,1,minecraft:melon_stem[age=1])
B(-3,5,1,minecraft:jungle_fence[east=false,north=true,south=false,waterlogged=false,west=false])
B(-3,6,1,minecraft:torch)
B(-3,7,1,minecraft:jungle_stairs[facing=north,half=top,shape=straight,waterlogged=false])
B(-3,8,1,minecraft:jungle_slab)
B(-3,9,1,minecraft:jungle_planks)
B(-3,10,1,minecraft:water)
B(-3,0,2,minecraft:jungle_slab[type=top,waterlogged=false])
B(-3,1,2,minecraft:water)
B(-3,8,2,minecraft:jungle_slab)
B(-3,9,2,minecraft:jungle_planks)
B(-3,10,2,minecraft:water)
B(-3,0,3,minecraft:jungle_slab[type=top,waterlogged=false])
B(-3,1,3,minecraft:farmland[moisture=7])
B(-3,2,3,minecraft:wheat[age=2])
B(-3,8,3,minecraft:jungle_slab)
B(-3,9,3,minecraft:jungle_planks)
B(-3,10,3,minecraft:water)
B(-3,-1,4,minecraft:jungle_log)
B(-3,0,4,minecraft:jungle_log)
B(-3,1,4,minecraft:jungle_log)
B(-3,2,4,minecraft:jungle_fence)
B(-3,3,4,minecraft:jungle_fence)
B(-3,4,4,minecraft:jungle_fence)
B(-3,5,4,minecraft:jungle_fence)
B(-3,6,4,minecraft:jungle_fence)
B(-3,7,4,minecraft:jungle_fence)
B(-3,8,4,minecraft:jungle_planks)
B(-3,9,4,minecraft:jungle_planks)
B(-3,10,4,minecraft:jungle_planks)
B(-3,11,4,minecraft:birch_slab)
B(-3,-1,5,minecraft:birch_stairs[facing=east,half=bottom,shape=straight,waterlogged=false])
B(-2,0,-7,minecraft:jungle_log[axis=x])
B(-2,1,-7,minecraft:jungle_slab)
B(-2,10,-7,minecraft:jungle_stairs[facing=south,half=top,shape=straight,waterlogged=false])
B(-2,11,-7,minecraft:birch_slab)
B(-2,0,-6,minecraft:jungle_slab[type=top,waterlogged=false])
B(-2,1,-6,minecraft:farmland[moisture=7])
B(-2,2,-6,minecraft:wheat[age=4])
B(-2,9,-6,minecraft:jungle_slab[type=top,waterlogged=false])
B(-2,10,-6,minecraft:water)
B(-2,0,-5,minecraft:jungle_slab[type=top,waterlogged=false])
B(-2,1,-5,minecraft:water)
B(-2,9,-5,minecraft:jungle_slab[type=top,waterlogged=false])
B(-2,10,-5,minecraft:water)
B(-2,0,-4,minecraft:jungle_slab[type=top,waterlogged=false])
B(-2,1,-4,minecraft:farmland[moisture=7])
B(-2,2,-4,minecraft:melon_stem[age=2])
B(-2,9,-4,minecraft:jungle_stairs[facing=south,half=top,shape=straight,waterlogged=false])
B(-2,10,-4,minecraft:water)
B(-2,0,-3,minecraft:jungle_slab[type=top,waterlogged=false])
B(-2,1,-3,minecraft:water)
B(-2,2,-3,minecraft:jungle_stairs[facing=south,half=bottom,shape=straight,waterlogged=false])
B(-2,3,-3,minecraft:jungle_stairs[facing=south,half=top,shape=straight,waterlogged=false])
B(-2,4,-3,minecraft:jungle_stairs[facing=south,half=bottom,shape=straight,waterlogged=false])
B(-2,5,-3,minecraft:jungle_stairs[facing=south,half=top,shape=straight,waterlogged=false])
B(-2,6,-3,minecraft:jungle_stairs[facing=south,half=bottom,shape=straight,waterlogged=false])
B(-2,7,-3,minecraft:jungle_stairs[facing=south,half=top,shape=straight,waterlogged=false])
B(-2,8,-3,minecraft:jungle_slab[type=double,waterlogged=false])
B(-2,9,-3,minecraft:water)
B(-2,10,-3,minecraft:water)
B(-2,0,-2,minecraft:jungle_slab[type=top,waterlogged=false])
B(-2,1,-2,minecraft:water)
B(-2,2,-2,minecraft:cauldron)
B(-2,3,-2,minecraft:cauldron)
B(-2,4,-2,minecraft:cauldron)
B(-2,5,-2,minecraft:cauldron)
B(-2,6,-2,minecraft:cauldron)
B(-2,7,-2,minecraft:cauldron)
B(-2,8,-2,minecraft:cauldron[level=3])
B(-2,9,-2,minecraft:water)
B(-2,0,-1,minecraft:jungle_slab[type=top,waterlogged=false])
B(-2,1,-1,minecraft:water)
B(-2,2,-1,minecraft:cauldron)
B(-2,3,-1,minecraft:cauldron)
B(-2,4,-1,minecraft:cauldron)
B(-2,5,-1,minecraft:cauldron)
B(-2,6,-1,minecraft:cauldron)
B(-2,7,-1,minecraft:cauldron)
B(-2,8,-1,minecraft:cauldron[level=3])
B(-2,9,-1,minecraft:water)
B(-2,0,0,minecraft:jungle_slab[type=top,waterlogged=false])
B(-2,1,0,minecraft:water)
B(-2,2,0,minecraft:jungle_stairs)
B(-2,3,0,minecraft:jungle_stairs[facing=north,half=top,shape=straight,waterlogged=false])
B(-2,4,0,minecraft:jungle_stairs)
B(-2,5,0,minecraft:jungle_stairs[facing=north,half=top,shape=straight,waterlogged=false])
B(-2,6,0,minecraft:jungle_stairs)
B(-2,7,0,minecraft:jungle_stairs[facing=north,half=top,shape=straight,waterlogged=false])
B(-2,8,0,minecraft:jungle_slab[type=double,waterlogged=false])
B(-2,9,0,minecraft:water)
B(-2,10,0,minecraft:water)
B(-2,0,1,minecraft:jungle_slab[type=top,waterlogged=false])
B(-2,1,1,minecraft:farmland[moisture=7])
B(-2,2,1,minecraft:melon_stem[age=2])
B(-2,9,1,minecraft:jungle_stairs[facing=north,half=top,shape=straight,waterlogged=false])
B(-2,10,1,minecraft:water)
B(-2,0,2,minecraft:jungle_slab[type=top,waterlogged=false])
B(-2,1,2,minecraft:water)
B(-2,9,2,minecraft:jungle_slab[type=top,waterlogged=false])
B(-2,10,2,minecraft:water)
B(-2,0,3,minecraft:jungle_slab[type=top,waterlogged=false])
B(-2,1,3,minecraft:farmland[moisture=7])
B(-2,2,3,minecraft:wheat[age=1])
B(-2,9,3,minecraft:jungle_slab[type=top,waterlogged=false])
B(-2,10,3,minecraft:water)
B(-2,0,4,minecraft:jungle_log[axis=x])
B(-2,1,4,minecraft:jungle_slab)
B(-2,10,4,minecraft:jungle_stairs[facing=north,half=top,shape=straight,waterlogged=false])
B(-2,11,4,minecraft:birch_slab)
B(-2,-1,5,minecraft:birch_stairs[facing=west,half=top,shape=straight,waterlogged=false])
B(-2,0,5,minecraft:birch_stairs[facing=east,half=bottom,shape=straight,waterlogged=false])
B(-1,0,-7,minecraft:jungle_log[axis=x])
B(-1,1,-7,minecraft:jungle_slab)
B(-1,10,-7,minecraft:jungle_stairs[facing=south,half=top,shape=straight,waterlogged=false])
B(-1,11,-7,minecraft:birch_slab)
B(-1,0,-6,minecraft:jungle_slab[type=top,waterlogged=false])
B(-1,1,-6,minecraft:farmland[moisture=7])
B(-1,2,-6,minecraft:wheat[age=3])
B(-1,9,-6,minecraft:jungle_slab[type=top,waterlogged=false])
B(-1,10,-6,minecraft:water)
B(-1,0,-5,minecraft:jungle_slab[type=top,waterlogged=false])
B(-1,1,-5,minecraft:water)
B(-1,9,-5,minecraft:jungle_slab[type=top,waterlogged=false])
B(-1,10,-5,minecraft:water)
B(-1,0,-4,minecraft:jungle_slab[type=top,waterlogged=false])
B(-1,1,-4,minecraft:farmland[moisture=7])
B(-1,2,-4,minecraft:melon_stem[age=3])
B(-1,9,-4,minecraft:jungle_stairs[facing=south,half=top,shape=straight,waterlogged=false])
B(-1,10,-4,minecraft:water)
B(-1,0,-3,minecraft:jungle_slab[type=top,waterlogged=false])
B(-1,1,-3,minecraft:water)
B(-1,2,-3,minecraft:jungle_stairs[facing=south,half=bottom,shape=straight,waterlogged=false])
B(-1,3,-3,minecraft:jungle_stairs[facing=south,half=top,shape=straight,waterlogged=false])
B(-1,4,-3,minecraft:jungle_stairs[facing=south,half=bottom,shape=straight,waterlogged=false])
B(-1,5,-3,minecraft:jungle_stairs[facing=south,half=top,shape=straight,waterlogged=false])
B(-1,6,-3,minecraft:jungle_stairs[facing=south,half=bottom,shape=straight,waterlogged=false])
B(-1,7,-3,minecraft:jungle_stairs[facing=south,half=top,shape=straight,waterlogged=false])
B(-1,8,-3,minecraft:jungle_slab[type=double,waterlogged=false])
B(-1,9,-3,minecraft:water)
B(-1,10,-3,minecraft:water)
B(-1,0,-2,minecraft:jungle_slab[type=top,waterlogged=false])
B(-1,1,-2,minecraft:water)
B(-1,2,-2,minecraft:cauldron)
B(-1,3,-2,minecraft:cauldron)
B(-1,4,-2,minecraft:cauldron)
B(-1,5,-2,minecraft:cauldron)
B(-1,6,-2,minecraft:cauldron)
B(-1,7,-2,minecraft:cauldron)
B(-1,8,-2,minecraft:cauldron[level=3])
B(-1,9,-2,minecraft:water)
B(-1,0,-1,minecraft:jungle_slab[type=top,waterlogged=false])
B(-1,1,-1,minecraft:water)
B(-1,2,-1,minecraft:cauldron)
B(-1,3,-1,minecraft:cauldron)
B(-1,4,-1,minecraft:cauldron)
B(-1,5,-1,minecraft:cauldron)
B(-1,6,-1,minecraft:cauldron)
B(-1,7,-1,minecraft:cauldron)
B(-1,8,-1,minecraft:cauldron[level=3])
B(-1,9,-1,minecraft:water)
B(-1,0,0,minecraft:jungle_slab[type=top,waterlogged=false])
B(-1,1,0,minecraft:water)
B(-1,2,0,minecraft:jungle_stairs)
B(-1,3,0,minecraft:jungle_stairs[facing=north,half=top,shape=straight,waterlogged=false])
B(-1,4,0,minecraft:jungle_stairs)
B(-1,5,0,minecraft:jungle_stairs[facing=north,half=top,shape=straight,waterlogged=false])
B(-1,6,0,minecraft:jungle_stairs)
B(-1,7,0,minecraft:jungle_stairs[facing=north,half=top,shape=straight,waterlogged=false])
B(-1,8,0,minecraft:jungle_slab[type=double,waterlogged=false])
B(-1,9,0,minecraft:water)
B(-1,10,0,minecraft:water)
B(-1,0,1,minecraft:jungle_slab[type=top,waterlogged=false])
B(-1,1,1,minecraft:farmland[moisture=7])
B(-1,2,1,minecraft:melon_stem[age=3])
B(-1,9,1,minecraft:jungle_stairs[facing=north,half=top,shape=straight,waterlogged=false])
B(-1,10,1,minecraft:water)
B(-1,0,2,minecraft:jungle_slab[type=top,waterlogged=false])
B(-1,1,2,minecraft:water)
B(-1,9,2,minecraft:jungle_slab[type=top,waterlogged=false])
B(-1,10,2,minecraft:water)
B(-1,0,3,minecraft:jungle_slab[type=top,waterlogged=false])
B(-1,1,3,minecraft:farmland[moisture=7])
B(-1,2,3,minecraft:wheat[age=2])
B(-1,9,3,minecraft:jungle_slab[type=top,waterlogged=false])
B(-1,10,3,minecraft:water)
B(-1,0,4,minecraft:jungle_log[axis=x])
B(-1,1,4,minecraft:jungle_slab)
B(-1,10,4,minecraft:jungle_stairs[facing=north,half=top,shape=straight,waterlogged=false])
B(-1,11,4,minecraft:birch_slab)
B(-1,0,5,minecraft:birch_stairs[facing=west,half=top,shape=straight,waterlogged=false])
B(-1,1,5,minecraft:birch_slab)
B(0,-1,-7,minecraft:jungle_log)
B(0,0,-7,minecraft:jungle_log)
B(0,1,-7,minecraft:jungle_log)
B(0,2,-7,minecraft:jungle_fence)
B(0,3,-7,minecraft:jungle_fence)
B(0,4,-7,minecraft:jungle_fence)
B(0,5,-7,minecraft:jungle_fence)
B(0,6,-7,minecraft:jungle_fence)
B(0,7,-7,minecraft:jungle_fence)
B(0,8,-7,minecraft:jungle_planks)
B(0,9,-7,minecraft:jungle_planks)
B(0,10,-7,minecraft:jungle_planks)
B(0,11,-7,minecraft:birch_slab)
B(0,0,-6,minecraft:jungle_slab[type=top,waterlogged=false])
B(0,1,-6,minecraft:farmland[moisture=7])
B(0,2,-6,minecraft:wheat[age=7])
B(0,8,-6,minecraft:jungle_slab)
B(0,9,-6,minecraft:jungle_planks)
B(0,10,-6,minecraft:water)
B(0,0,-5,minecraft:jungle_slab[type=top,waterlogged=false])
B(0,1,-5,minecraft:water)
B(0,8,-5,minecraft:jungle_slab)
B(0,9,-5,minecraft:jungle_planks)
B(0,10,-5,minecraft:water)
B(0,0,-4,minecraft:jungle_slab[type=top,waterlogged=false])
B(0,1,-4,minecraft:farmland[moisture=7])
B(0,2,-4,minecraft:melon_stem)
B(0,5,-4,minecraft:jungle_fence[east=false,north=false,south=true,waterlogged=false,west=false])
B(0,6,-4,minecraft:torch)
B(0,7,-4,minecraft:jungle_stairs[facing=south,half=top,shape=straight,waterlogged=false])
B(0,8,-4,minecraft:jungle_slab)
B(0,9,-4,minecraft:jungle_planks)
B(0,10,-4,minecraft:water)
B(0,-1,-3,minecraft:jungle_log)
B(0,0,-3,minecraft:jungle_log)
B(0,1,-3,minecraft:jungle_log)
B(0,2,-3,minecraft:jungle_log)
B(0,3,-3,minecraft:jungle_log)
B(0,4,-3,minecraft:jungle_log)
B(0,5,-3,minecraft:jungle_log)
B(0,6,-3,minecraft:jungle_log)
B(0,7,-3,minecraft:jungle_log)
B(0,8,-3,minecraft:jungle_slab[type=double,waterlogged=false])
B(0,9,-3,minecraft:water)
B(0,10,-3,minecraft:water)
B(0,0,-2,minecraft:jungle_slab[type=top,waterlogged=false])
B(0,1,-2,minecraft:water)
B(0,2,-2,minecraft:jungle_stairs[facing=west,half=bottom,shape=straight,waterlogged=false])
B(0,3,-2,minecraft:jungle_stairs[facing=west,half=top,shape=straight,waterlogged=false])
B(0,4,-2,minecraft:jungle_stairs[facing=west,half=bottom,shape=straight,waterlogged=false])
B(0,5,-2,minecraft:jungle_stairs[facing=west,half=top,shape=straight,waterlogged=false])
B(0,6,-2,minecraft:jungle_stairs[facing=west,half=bottom,shape=straight,waterlogged=false])
B(0,7,-2,minecraft:jungle_stairs[facing=west,half=top,shape=straight,waterlogged=false])
B(0,8,-2,minecraft:jungle_slab[type=double,waterlogged=false])
B(0,9,-2,minecraft:water)
B(0,10,-2,minecraft:water)
B(0,0,-1,minecraft:jungle_slab[type=top,waterlogged=false])
B(0,1,-1,minecraft:water)
B(0,2,-1,minecraft:jungle_stairs[facing=west,half=bottom,shape=straight,waterlogged=false])
B(0,3,-1,minecraft:jungle_stairs[facing=west,half=top,shape=straight,waterlogged=false])
B(0,4,-1,minecraft:jungle_stairs[facing=west,half=bottom,shape=straight,waterlogged=false])
B(0,5,-1,minecraft:jungle_stairs[facing=west,half=top,shape=straight,waterlogged=false])
B(0,6,-1,minecraft:jungle_stairs[facing=west,half=bottom,shape=straight,waterlogged=false])
B(0,7,-1,minecraft:jungle_stairs[facing=west,half=top,shape=straight,waterlogged=false])
B(0,8,-1,minecraft:jungle_slab[type=double,waterlogged=false])
B(0,9,-1,minecraft:water)
B(0,10,-1,minecraft:water)
B(0,-1,0,minecraft:jungle_log)
B(0,0,0,minecraft:jungle_log)
B(0,1,0,minecraft:jungle_log)
B(0,2,0,minecraft:jungle_log)
B(0,3,0,minecraft:jungle_log)
B(0,4,0,minecraft:jungle_log)
B(0,5,0,minecraft:jungle_log)
B(0,6,0,minecraft:jungle_log)
B(0,7,0,minecraft:jungle_log)
B(0,8,0,minecraft:jungle_slab[type=double,waterlogged=false])
B(0,9,0,minecraft:water)
B(0,10,0,minecraft:water)
B(0,0,1,minecraft:jungle_slab[type=top,waterlogged=false])
B(0,1,1,minecraft:farmland[moisture=7])
B(0,2,1,minecraft:melon_stem[age=7])
B(0,5,1,minecraft:jungle_fence[east=false,north=true,south=false,waterlogged=false,west=false])
B(0,6,1,minecraft:torch)
B(0,7,1,minecraft:jungle_stairs[facing=north,half=top,shape=straight,waterlogged=false])
B(0,8,1,minecraft:jungle_slab)
B(0,9,1,minecraft:jungle_planks)
B(0,10,1,minecraft:water)
B(0,0,2,minecraft:jungle_slab[type=top,waterlogged=false])
B(0,1,2,minecraft:water)
B(0,8,2,minecraft:jungle_slab)
B(0,9,2,minecraft:jungle_planks)
B(0,10,2,minecraft:water)
B(0,0,3,minecraft:jungle_slab[type=top,waterlogged=false])
B(0,1,3,minecraft:farmland[moisture=7])
B(0,2,3,minecraft:wheat[age=3])
B(0,8,3,minecraft:jungle_slab)
B(0,9,3,minecraft:jungle_planks)
B(0,10,3,minecraft:water)
B(0,-1,4,minecraft:jungle_log)
B(0,0,4,minecraft:jungle_log)
B(0,1,4,minecraft:jungle_log)
B(0,2,4,minecraft:jungle_fence)
B(0,3,4,minecraft:jungle_fence)
B(0,4,4,minecraft:jungle_fence)
B(0,5,4,minecraft:jungle_fence)
B(0,6,4,minecraft:jungle_fence)
B(0,7,4,minecraft:jungle_fence)
B(0,8,4,minecraft:jungle_planks)
B(0,9,4,minecraft:jungle_planks)
B(0,10,4,minecraft:jungle_planks)
B(0,11,4,minecraft:birch_slab)
B(1,0,-7,minecraft:jungle_log[axis=x])
B(1,1,-7,minecraft:jungle_slab)
B(1,10,-7,minecraft:jungle_stairs[facing=west,half=top,shape=straight,waterlogged=false])
B(1,11,-7,minecraft:birch_slab)
B(1,0,-6,minecraft:jungle_slab[type=top,waterlogged=false])
B(1,1,-6,minecraft:farmland[moisture=7])
B(1,2,-6,minecraft:wheat)
B(1,10,-6,minecraft:jungle_stairs[facing=west,half=top,shape=straight,waterlogged=false])
B(1,11,-6,minecraft:birch_slab)
B(1,0,-5,minecraft:jungle_slab[type=top,waterlogged=false])
B(1,1,-5,minecraft:water)
B(1,10,-5,minecraft:jungle_stairs[facing=west,half=top,shape=straight,waterlogged=false])
B(1,11,-5,minecraft:birch_slab)
B(1,0,-4,minecraft:jungle_slab[type=top,waterlogged=false])
B(1,1,-4,minecraft:farmland[moisture=7])
B(1,2,-4,minecraft:melon_stem[age=7])
B(1,10,-4,minecraft:jungle_stairs[facing=south,half=top,shape=inner_right,waterlogged=false])
B(1,11,-4,minecraft:birch_slab)
B(1,0,-3,minecraft:jungle_slab[type=top,waterlogged=false])
B(1,1,-3,minecraft:farmland[moisture=7])
B(1,2,-3,minecraft:melon_stem[age=1])
B(1,5,-3,minecraft:jungle_fence[east=false,north=false,south=false,waterlogged=false,west=true])
B(1,6,-3,minecraft:torch)
B(1,7,-3,minecraft:jungle_stairs[facing=west,half=top,shape=straight,waterlogged=false])
B(1,8,-3,minecraft:jungle_slab)
B(1,9,-3,minecraft:jungle_planks)
B(1,10,-3,minecraft:water)
B(1,0,-2,minecraft:jungle_slab[type=top,waterlogged=false])
B(1,1,-2,minecraft:water)
B(1,9,-2,minecraft:jungle_stairs[facing=west,half=top,shape=straight,waterlogged=false])
B(1,10,-2,minecraft:water)
B(1,0,-1,minecraft:jungle_slab[type=top,waterlogged=false])
B(1,1,-1,minecraft:water)
B(1,9,-1,minecraft:jungle_stairs[facing=west,half=top,shape=straight,waterlogged=false])
B(1,10,-1,minecraft:water)
B(1,0,0,minecraft:jungle_slab[type=top,waterlogged=false])
B(1,1,0,minecraft:farmland[moisture=7])
B(1,2,0,minecraft:melon_stem[age=1])
B(1,5,0,minecraft:jungle_fence[east=false,north=false,south=false,waterlogged=false,west=true])
B(1,6,0,minecraft:torch)
B(1,7,0,minecraft:jungle_stairs[facing=west,half=top,shape=straight,waterlogged=false])
B(1,8,0,minecraft:jungle_slab)
B(1,9,0,minecraft:jungle_planks)
B(1,10,0,minecraft:water)
B(1,0,1,minecraft:jungle_slab[type=top,waterlogged=false])
B(1,1,1,minecraft:farmland[moisture=7])
B(1,2,1,minecraft:melon_stem[age=2])
B(1,10,1,minecraft:jungle_stairs[facing=west,half=top,shape=inner_right,waterlogged=false])
B(1,11,1,minecraft:birch_slab)
B(1,0,2,minecraft:jungle_slab[type=top,waterlogged=false])
B(1,1,2,minecraft:water)
B(1,10,2,minecraft:jungle_stairs[facing=west,half=top,shape=straight,waterlogged=false])
B(1,11,2,minecraft:birch_slab)
B(1,0,3,minecraft:jungle_slab[type=top,waterlogged=false])
B(1,1,3,minecraft:farmland[moisture=7])
B(1,2,3,minecraft:wheat[age=4])
B(1,10,3,minecraft:jungle_stairs[facing=west,half=top,shape=straight,waterlogged=false])
B(1,11,3,minecraft:birch_slab)
B(1,0,4,minecraft:jungle_log[axis=x])
B(1,1,4,minecraft:jungle_slab)
B(1,10,4,minecraft:jungle_stairs[facing=west,half=top,shape=straight,waterlogged=false])
B(1,11,4,minecraft:birch_slab)
B(2,0,-7,minecraft:jungle_log[axis=x])
B(2,1,-7,minecraft:jungle_slab)
B(2,0,-6,minecraft:jungle_slab[type=top,waterlogged=false])
B(2,1,-6,minecraft:farmland[moisture=7])
B(2,2,-6,minecraft:wheat[age=1])
B(2,0,-5,minecraft:jungle_slab[type=top,waterlogged=false])
B(2,1,-5,minecraft:water)
B(2,0,-4,minecraft:jungle_slab[type=top,waterlogged=false])
B(2,1,-4,minecraft:farmland[moisture=7])
B(2,2,-4,minecraft:melon_stem[age=7])
B(2,10,-4,minecraft:jungle_stairs[facing=south,half=top,shape=straight,waterlogged=false])
B(2,11,-4,minecraft:birch_slab)
B(2,0,-3,minecraft:jungle_slab[type=top,waterlogged=false])
B(2,1,-3,minecraft:farmland[moisture=7])
B(2,2,-3,minecraft:melon_stem[age=2])
B(2,8,-3,minecraft:jungle_slab)
B(2,9,-3,minecraft:jungle_planks)
B(2,10,-3,minecraft:water)
B(2,0,-2,minecraft:jungle_slab[type=top,waterlogged=false])
B(2,1,-2,minecraft:water)
B(2,9,-2,minecraft:jungle_slab[type=top,waterlogged=false])
B(2,10,-2,minecraft:water)
B(2,0,-1,minecraft:jungle_slab[type=top,waterlogged=false])
B(2,1,-1,minecraft:water)
B(2,9,-1,minecraft:jungle_slab[type=top,waterlogged=false])
B(2,10,-1,minecraft:water)
B(2,0,0,minecraft:jungle_slab[type=top,waterlogged=false])
B(2,1,0,minecraft:farmland[moisture=7])
B(2,2,0,minecraft:melon_stem[age=1])
B(2,8,0,minecraft:jungle_slab)
B(2,9,0,minecraft:jungle_planks)
B(2,10,0,minecraft:water)
B(2,0,1,minecraft:jungle_slab[type=top,waterlogged=false])
B(2,1,1,minecraft:farmland[moisture=7])
B(2,2,1,minecraft:melon_stem[age=7])
B(2,10,1,minecraft:jungle_stairs[facing=north,half=top,shape=straight,waterlogged=false])
B(2,11,1,minecraft:birch_slab)
B(2,0,2,minecraft:jungle_slab[type=top,waterlogged=false])
B(2,1,2,minecraft:water)
B(2,0,3,minecraft:jungle_slab[type=top,waterlogged=false])
B(2,1,3,minecraft:farmland[moisture=7])
B(2,2,3,minecraft:wheat[age=2])
B(2,0,4,minecraft:jungle_log[axis=x])
B(2,1,4,minecraft:jungle_slab)
B(3,0,-7,minecraft:jungle_log[axis=x])
B(3,1,-7,minecraft:jungle_slab)
B(3,0,-6,minecraft:jungle_slab[type=top,waterlogged=false])
B(3,1,-6,minecraft:farmland[moisture=7])
B(3,2,-6,minecraft:wheat[age=3])
B(3,0,-5,minecraft:jungle_slab[type=top,waterlogged=false])
B(3,1,-5,minecraft:water)
B(3,0,-4,minecraft:jungle_slab[type=top,waterlogged=false])
B(3,1,-4,minecraft:water)
B(3,10,-4,minecraft:jungle_stairs[facing=south,half=top,shape=straight,waterlogged=false])
B(3,11,-4,minecraft:birch_slab)
B(3,0,-3,minecraft:jungle_slab[type=top,waterlogged=false])
B(3,1,-3,minecraft:water)
B(3,8,-3,minecraft:jungle_slab)
B(3,9,-3,minecraft:jungle_planks)
B(3,10,-3,minecraft:water)
B(3,0,-2,minecraft:jungle_slab[type=top,waterlogged=false])
B(3,1,-2,minecraft:water)
B(3,9,-2,minecraft:jungle_slab[type=top,waterlogged=false])
B(3,10,-2,minecraft:water)
B(3,0,-1,minecraft:jungle_slab[type=top,waterlogged=false])
B(3,1,-1,minecraft:water)
B(3,9,-1,minecraft:jungle_slab[type=top,waterlogged=false])
B(3,10,-1,minecraft:water)
B(3,0,0,minecraft:jungle_slab[type=top,waterlogged=false])
B(3,1,0,minecraft:water)
B(3,8,0,minecraft:jungle_slab)
B(3,9,0,minecraft:jungle_planks)
B(3,10,0,minecraft:water)
B(3,0,1,minecraft:jungle_slab[type=top,waterlogged=false])
B(3,1,1,minecraft:water)
B(3,10,1,minecraft:jungle_stairs[facing=north,half=top,shape=straight,waterlogged=false])
B(3,11,1,minecraft:birch_slab)
B(3,0,2,minecraft:jungle_slab[type=top,waterlogged=false])
B(3,1,2,minecraft:water)
B(3,0,3,minecraft:jungle_slab[type=top,waterlogged=false])
B(3,1,3,minecraft:farmland[moisture=7])
B(3,2,3,minecraft:wheat[age=1])
B(3,0,4,minecraft:jungle_log[axis=x])
B(3,1,4,minecraft:jungle_slab)
B(4,0,-7,minecraft:jungle_log[axis=x])
B(4,1,-7,minecraft:jungle_slab)
B(4,0,-6,minecraft:jungle_slab[type=top,waterlogged=false])
B(4,1,-6,minecraft:farmland[moisture=7])
B(4,2,-6,minecraft:wheat)
B(4,0,-5,minecraft:jungle_slab[type=top,waterlogged=false])
B(4,1,-5,minecraft:farmland[moisture=7])
B(4,2,-5,minecraft:wheat[age=2])
B(4,0,-4,minecraft:jungle_slab[type=top,waterlogged=false])
B(4,1,-4,minecraft:farmland[moisture=7])
B(4,2,-4,minecraft:wheat)
B(4,10,-4,minecraft:jungle_stairs[facing=south,half=top,shape=straight,waterlogged=false])
B(4,11,-4,minecraft:birch_slab)
B(4,0,-3,minecraft:jungle_slab[type=top,waterlogged=false])
B(4,1,-3,minecraft:farmland[moisture=7])
B(4,2,-3,minecraft:wheat[age=2])
B(4,8,-3,minecraft:jungle_slab)
B(4,9,-3,minecraft:jungle_planks)
B(4,10,-3,minecraft:water)
B(4,0,-2,minecraft:jungle_slab[type=top,waterlogged=false])
B(4,1,-2,minecraft:farmland[moisture=7])
B(4,2,-2,minecraft:wheat[age=3])
B(4,9,-2,minecraft:jungle_slab[type=top,waterlogged=false])
B(4,10,-2,minecraft:water)
B(4,0,-1,minecraft:jungle_slab[type=top,waterlogged=false])
B(4,1,-1,minecraft:farmland[moisture=7])
B(4,2,-1,minecraft:wheat)
B(4,9,-1,minecraft:jungle_slab[type=top,waterlogged=false])
B(4,10,-1,minecraft:water)
B(4,0,0,minecraft:jungle_slab[type=top,waterlogged=false])
B(4,1,0,minecraft:farmland[moisture=7])
B(4,2,0,minecraft:wheat[age=4])
B(4,8,0,minecraft:jungle_slab)
B(4,9,0,minecraft:jungle_planks)
B(4,10,0,minecraft:water)
B(4,0,1,minecraft:jungle_slab[type=top,waterlogged=false])
B(4,1,1,minecraft:farmland[moisture=7])
B(4,2,1,minecraft:wheat[age=1])
B(4,10,1,minecraft:jungle_stairs[facing=north,half=top,shape=straight,waterlogged=false])
B(4,11,1,minecraft:birch_slab)
B(4,0,2,minecraft:jungle_slab[type=top,waterlogged=false])
B(4,1,2,minecraft:farmland[moisture=7])
B(4,2,2,minecraft:wheat[age=4])
B(4,0,3,minecraft:jungle_slab[type=top,waterlogged=false])
B(4,1,3,minecraft:farmland[moisture=7])
B(4,2,3,minecraft:wheat[age=3])
B(4,0,4,minecraft:jungle_log[axis=x])
B(4,1,4,minecraft:jungle_slab)
B(5,-1,-7,minecraft:jungle_log)
B(5,0,-7,minecraft:jungle_log)
B(5,1,-7,minecraft:jungle_log)
B(5,2,-7,minecraft:jungle_fence)
B(5,3,-7,minecraft:torch)
B(5,0,-6,minecraft:jungle_log[axis=z])
B(5,1,-6,minecraft:jungle_slab)
B(5,0,-5,minecraft:jungle_log[axis=z])
B(5,1,-5,minecraft:jungle_slab)
B(5,0,-4,minecraft:jungle_log[axis=z])
B(5,1,-4,minecraft:jungle_slab)
B(5,10,-4,minecraft:jungle_stairs[facing=south,half=top,shape=straight,waterlogged=false])
B(5,11,-4,minecraft:birch_slab)
B(5,-1,-3,minecraft:jungle_log)
B(5,0,-3,minecraft:jungle_log)
B(5,1,-3,minecraft:jungle_log)
B(5,2,-3,minecraft:jungle_fence)
B(5,3,-3,minecraft:jungle_fence)
B(5,4,-3,minecraft:jungle_fence)
B(5,5,-3,minecraft:jungle_fence)
B(5,6,-3,minecraft:jungle_fence)
B(5,7,-3,minecraft:jungle_fence)
B(5,8,-3,minecraft:jungle_planks)
B(5,9,-3,minecraft:jungle_planks)
B(5,10,-3,minecraft:jungle_planks)
B(5,11,-3,minecraft:birch_slab)
B(5,0,-2,minecraft:jungle_log[axis=z])
B(5,1,-2,minecraft:jungle_slab)
B(5,10,-2,minecraft:jungle_stairs[facing=west,half=top,shape=straight,waterlogged=false])
B(5,11,-2,minecraft:birch_slab)
B(5,0,-1,minecraft:jungle_log[axis=z])
B(5,1,-1,minecraft:jungle_slab)
B(5,10,-1,minecraft:jungle_stairs[facing=west,half=top,shape=straight,waterlogged=false])
B(5,11,-1,minecraft:birch_slab)
B(5,-1,0,minecraft:jungle_log)
B(5,0,0,minecraft:jungle_log)
B(5,1,0,minecraft:jungle_log)
B(5,2,0,minecraft:jungle_fence)
B(5,3,0,minecraft:jungle_fence)
B(5,4,0,minecraft:jungle_fence)
B(5,5,0,minecraft:jungle_fence)
B(5,6,0,minecraft:jungle_fence)
B(5,7,0,minecraft:jungle_fence)
B(5,8,0,minecraft:jungle_planks)
B(5,9,0,minecraft:jungle_planks)
B(5,10,0,minecraft:jungle_planks)
B(5,11,0,minecraft:birch_slab)
B(5,0,1,minecraft:jungle_log[axis=z])
B(5,1,1,minecraft:jungle_slab)
B(5,10,1,minecraft:jungle_stairs[facing=north,half=top,shape=straight,waterlogged=false])
B(5,11,1,minecraft:birch_slab)
B(5,0,2,minecraft:jungle_log[axis=z])
B(5,1,2,minecraft:jungle_slab)
B(5,0,3,minecraft:jungle_log[axis=z])
B(5,1,3,minecraft:jungle_slab)
B(5,-1,4,minecraft:jungle_log)
B(5,0,4,minecraft:jungle_log)
B(5,1,4,minecraft:jungle_log)
B(5,2,4,minecraft:jungle_fence)
B(5,3,4,minecraft:torch)

#######################################################################
# +-----------------------------------------------------------------+ #
# |                            BO3 checks                           | #
# +-----------------------------------------------------------------+ #
#######################################################################


#######################################################################
# +-----------------------------------------------------------------+ #
# |                             Branches                            | #
# +-----------------------------------------------------------------+ #
#######################################################################


#######################################################################
# +-----------------------------------------------------------------+ #
# |                             Entities                            | #
# +-----------------------------------------------------------------+ #
#######################################################################

Entity(-1,2,4,minecraft:villager,1,../JungleNBT/entities/tribalfarmer.txt)
