
#######################################################################
# +-----------------------------------------------------------------+ #
# |                            BO3 object                           | #
# +-----------------------------------------------------------------+ #
#######################################################################

Author: BO3 BulkEdit (by LanToaster)

Description: This Object was Created with BO3_BulkEdit

Version: 3

SettingsMode: WriteWithoutComments


#######################################################################
# +-----------------------------------------------------------------+ #
# |                          Main settings                          | #
# +-----------------------------------------------------------------+ #
#######################################################################

Tree: false

Frequency: 100

Rarity: 100.0

RotateRandomly: true

SpawnHeight: randomY

SpawnHeightOffset: 0

SpawnHeightVariance: 0

##############################
# Height Limits for the BO3. #
##############################

MinHeight: 87

MaxHeight: 87

######################
# Extrusion settings #
######################

ExtrudeMode: None

ExtrudeThroughBlocks: minecraft:air

MaxBranchDepth: 50


#######################################################################
# +-----------------------------------------------------------------+ #
# |                      Source block settings                      | #
# +-----------------------------------------------------------------+ #
#######################################################################

SourceBlocks: otg:air

MaxPercentageOutsideSourceBlock: 100

OutsideSourceBlock: placeAnyway

DoReplaceBlocks: true

IsOTGPlus: false


#######################################################################
# +-----------------------------------------------------------------+ #
# |                              Blocks                             | #
# +-----------------------------------------------------------------+ #
#######################################################################

B(-7,-1,-7,minecraft:cobblestone)
B(-7,0,-7,minecraft:cobblestone)
B(-7,1,-7,minecraft:cobblestone_wall)
B(-7,2,-7,minecraft:oak_fence)
B(-7,3,-7,minecraft:torch)
B(-7,-1,-3,minecraft:cobblestone)
B(-7,0,-3,minecraft:cobblestone)
B(-7,1,-3,minecraft:cobblestone_wall)
B(-7,2,-3,minecraft:oak_fence)
B(-7,-1,2,minecraft:cobblestone)
B(-7,0,2,minecraft:cobblestone)
B(-7,1,2,minecraft:cobblestone_wall)
B(-7,2,2,minecraft:oak_fence)
B(-7,-1,6,minecraft:cobblestone)
B(-7,0,6,minecraft:cobblestone)
B(-7,1,6,minecraft:cobblestone_wall)
B(-7,2,6,minecraft:oak_fence)
B(-7,3,6,minecraft:torch)
B(-6,-1,-6,minecraft:cobblestone)
B(-6,0,-6,minecraft:cobblestone_stairs[facing=east,half=bottom,shape=outer_right,waterlogged=false])
B(-6,-1,-5,minecraft:cobblestone)
B(-6,0,-5,minecraft:cobblestone_stairs[facing=east,half=bottom,shape=straight,waterlogged=false])
B(-6,-1,-4,minecraft:cobblestone)
B(-6,0,-4,minecraft:cobblestone_wall)
B(-6,-1,-3,minecraft:grass_path)
B(-6,-1,-2,minecraft:cobblestone)
B(-6,0,-2,minecraft:cobblestone_slab)
B(-6,-1,-1,minecraft:cobblestone)
B(-6,0,-1,minecraft:cobblestone_stairs[facing=south,half=bottom,shape=outer_left,waterlogged=false])
B(-6,-1,0,minecraft:cobblestone)
B(-6,0,0,minecraft:cobblestone_stairs[facing=east,half=bottom,shape=straight,waterlogged=false])
B(-6,-1,1,minecraft:cobblestone)
B(-6,0,1,minecraft:cobblestone_stairs[facing=east,half=bottom,shape=outer_left,waterlogged=false])
B(-6,-1,2,minecraft:grass_path)
B(-6,-1,3,minecraft:cobblestone)
B(-6,0,3,minecraft:cobblestone_slab)
B(-6,-1,4,minecraft:cobblestone)
B(-6,0,4,minecraft:cobblestone_stairs[facing=east,half=bottom,shape=straight,waterlogged=false])
B(-6,-1,5,minecraft:cobblestone)
B(-6,0,5,minecraft:cobblestone_stairs[facing=north,half=bottom,shape=outer_right,waterlogged=false])
B(-5,-1,-6,minecraft:cobblestone)
B(-5,0,-6,minecraft:cobblestone_stairs[facing=south,half=bottom,shape=straight,waterlogged=false])
B(-5,-1,-5,minecraft:dirt)
B(-5,0,-5,minecraft:podzol)
B(-5,1,-5,minecraft:oak_fence)
B(-5,2,-5,minecraft:oak_fence)
B(-5,3,-5,minecraft:oak_fence[east=true,north=false,south=true,waterlogged=false,west=false])
B(-5,-1,-4,minecraft:cobblestone)
B(-5,0,-4,minecraft:cobblestone_stairs)
B(-5,3,-4,minecraft:oak_fence[east=false,north=true,south=true,waterlogged=false,west=false])
B(-5,-1,-3,minecraft:grass_path)
B(-5,3,-3,minecraft:oak_fence[east=true,north=true,south=true,waterlogged=false,west=false])
B(-5,-1,-2,minecraft:cobblestone)
B(-5,0,-2,minecraft:cobblestone_stairs[facing=south,half=bottom,shape=straight,waterlogged=false])
B(-5,3,-2,minecraft:oak_fence[east=false,north=true,south=true,waterlogged=false,west=false])
B(-5,-1,-1,minecraft:dirt)
B(-5,0,-1,minecraft:podzol)
B(-5,1,-1,minecraft:oak_fence)
B(-5,2,-1,minecraft:oak_fence)
B(-5,3,-1,minecraft:oak_fence[east=true,north=true,south=true,waterlogged=false,west=false])
B(-5,-1,0,minecraft:dirt)
B(-5,0,0,minecraft:podzol)
B(-5,3,0,minecraft:oak_fence[east=false,north=true,south=true,waterlogged=false,west=false])
B(-5,-1,1,minecraft:cobblestone)
B(-5,0,1,minecraft:cobblestone_stairs)
B(-5,3,1,minecraft:oak_fence[east=false,north=true,south=true,waterlogged=false,west=false])
B(-5,-1,2,minecraft:grass_path)
B(-5,3,2,minecraft:oak_fence[east=false,north=true,south=true,waterlogged=false,west=false])
B(-5,-1,3,minecraft:cobblestone)
B(-5,0,3,minecraft:cobblestone_stairs[facing=south,half=bottom,shape=straight,waterlogged=false])
B(-5,3,3,minecraft:oak_fence[east=false,north=true,south=true,waterlogged=false,west=false])
B(-5,-1,4,minecraft:dirt)
B(-5,0,4,minecraft:podzol)
B(-5,1,4,minecraft:oak_fence)
B(-5,2,4,minecraft:oak_fence)
B(-5,3,4,minecraft:oak_fence[east=true,north=true,south=false,waterlogged=false,west=false])
B(-5,-1,5,minecraft:cobblestone)
B(-5,0,5,minecraft:cobblestone_slab)
B(-4,-1,-6,minecraft:cobblestone)
B(-4,-1,-5,minecraft:cobblestone)
B(-4,0,-5,minecraft:cobblestone_slab)
B(-4,3,-5,minecraft:oak_fence[east=true,north=false,south=false,waterlogged=false,west=true])
B(-4,-1,-4,minecraft:cobblestone)
B(-4,0,-4,minecraft:cobblestone_stairs[facing=west,half=bottom,shape=outer_right,waterlogged=false])
B(-4,3,-3,minecraft:oak_fence[east=true,north=false,south=false,waterlogged=false,west=true])
B(-4,-1,-2,minecraft:cobblestone)
B(-4,0,-2,minecraft:cobblestone_stairs[facing=west,half=bottom,shape=outer_left,waterlogged=false])
B(-4,-1,-1,minecraft:cobblestone)
B(-4,0,-1,minecraft:cobblestone_slab)
B(-4,3,-1,minecraft:oak_fence[east=true,north=false,south=false,waterlogged=false,west=true])
B(-4,-1,0,minecraft:cobblestone)
B(-4,0,0,minecraft:cobblestone)
B(-4,-1,1,minecraft:cobblestone)
B(-4,0,1,minecraft:cobblestone_slab)
B(-4,-1,3,minecraft:cobblestone)
B(-4,0,3,minecraft:cobblestone_stairs[facing=west,half=bottom,shape=outer_left,waterlogged=false])
B(-4,-1,4,minecraft:cobblestone)
B(-4,0,4,minecraft:cobblestone_stairs[facing=south,half=bottom,shape=inner_right,waterlogged=false])
B(-4,3,4,minecraft:oak_fence[east=true,north=false,south=false,waterlogged=false,west=true])
B(-4,-1,5,minecraft:cobblestone)
B(-4,0,5,minecraft:cobblestone)
B(-3,-1,-7,minecraft:cobblestone)
B(-3,0,-7,minecraft:cobblestone)
B(-3,1,-7,minecraft:cobblestone_wall)
B(-3,2,-7,minecraft:oak_fence)
B(-3,-1,-5,minecraft:grass_path)
B(-3,3,-5,minecraft:oak_fence[east=true,north=false,south=false,waterlogged=false,west=true])
B(-3,-1,-3,minecraft:cobblestone)
B(-3,0,-3,minecraft:cobblestone)
B(-3,1,-3,minecraft:cobblestone_wall)
B(-3,2,-3,minecraft:oak_fence)
B(-3,3,-3,minecraft:oak_fence[east=false,north=false,south=false,waterlogged=false,west=true])
B(-3,-1,-2,minecraft:cauldron[level=3])
B(-3,-1,-1,minecraft:grass_path)
B(-3,3,-1,minecraft:oak_fence[east=true,north=false,south=false,waterlogged=false,west=true])
B(-3,-1,0,minecraft:grass_path)
B(-3,-1,1,minecraft:cauldron[level=2])
B(-3,-1,2,minecraft:cobblestone)
B(-3,0,2,minecraft:cobblestone)
B(-3,1,2,minecraft:cobblestone_wall)
B(-3,2,2,minecraft:oak_fence)
B(-3,3,2,minecraft:oak_fence[east=false,north=false,south=true,waterlogged=false,west=false])
B(-3,3,3,minecraft:oak_fence[east=false,north=true,south=true,waterlogged=false,west=false])
B(-3,-1,4,minecraft:grass_path)
B(-3,3,4,minecraft:oak_fence[east=true,north=true,south=false,waterlogged=false,west=true])
B(-3,-1,5,minecraft:grass_path)
B(-3,-1,6,minecraft:cobblestone)
B(-3,0,6,minecraft:cobblestone)
B(-3,1,6,minecraft:cobblestone_wall)
B(-3,2,6,minecraft:oak_fence)
B(-2,-1,-6,minecraft:cobblestone)
B(-2,-1,-5,minecraft:cobblestone)
B(-2,0,-5,minecraft:cobblestone_stairs[facing=east,half=bottom,shape=straight,waterlogged=false])
B(-2,3,-5,minecraft:oak_fence[east=true,north=false,south=false,waterlogged=false,west=true])
B(-2,-1,-4,minecraft:cobblestone)
B(-2,0,-4,minecraft:cobblestone_stairs[facing=north,half=bottom,shape=outer_right,waterlogged=false])
B(-2,-1,-3,minecraft:cauldron[level=2])
B(-2,-1,-2,minecraft:cobblestone)
B(-2,0,-2,minecraft:cobblestone_wall)
B(-2,-1,-1,minecraft:cobblestone)
B(-2,0,-1,minecraft:cobblestone_stairs[facing=east,half=bottom,shape=straight,waterlogged=false])
B(-2,3,-1,minecraft:oak_fence[east=true,north=false,south=false,waterlogged=false,west=true])
B(-2,-1,0,minecraft:cobblestone)
B(-2,0,0,minecraft:cobblestone)
B(-2,-1,1,minecraft:cobblestone)
B(-2,-1,2,minecraft:cauldron[level=3])
B(-2,-1,3,minecraft:cobblestone)
B(-2,0,3,minecraft:cobblestone)
B(-2,-1,4,minecraft:cobblestone)
B(-2,0,4,minecraft:cobblestone_stairs[facing=east,half=bottom,shape=straight,waterlogged=false])
B(-2,3,4,minecraft:oak_fence[east=true,north=false,south=false,waterlogged=false,west=true])
B(-2,-1,5,minecraft:cobblestone)
B(-2,0,5,minecraft:cobblestone_stairs[facing=north,half=bottom,shape=outer_right,waterlogged=false])
B(-1,-1,-6,minecraft:cobblestone)
B(-1,0,-6,minecraft:cobblestone_stairs[facing=east,half=bottom,shape=outer_right,waterlogged=false])
B(-1,-1,-5,minecraft:dirt)
B(-1,0,-5,minecraft:podzol)
B(-1,1,-5,minecraft:oak_fence)
B(-1,2,-5,minecraft:oak_fence)
B(-1,3,-5,minecraft:oak_fence[east=true,north=false,south=true,waterlogged=false,west=true])
B(-1,-1,-4,minecraft:cobblestone)
B(-1,0,-4,minecraft:cobblestone_stairs)
B(-1,3,-4,minecraft:oak_fence[east=false,north=true,south=true,waterlogged=false,west=false])
B(-1,-1,-3,minecraft:grass_path)
B(-1,3,-3,minecraft:oak_fence[east=false,north=true,south=true,waterlogged=false,west=false])
B(-1,-1,-2,minecraft:cobblestone)
B(-1,0,-2,minecraft:cobblestone_slab)
B(-1,3,-2,minecraft:oak_fence[east=false,north=true,south=true,waterlogged=false,west=false])
B(-1,-1,-1,minecraft:dirt)
B(-1,0,-1,minecraft:podzol)
B(-1,1,-1,minecraft:oak_fence)
B(-1,2,-1,minecraft:oak_fence)
B(-1,3,-1,minecraft:oak_fence[east=false,north=true,south=false,waterlogged=false,west=true])
B(-1,4,-1,minecraft:torch)
B(-1,-1,0,minecraft:dirt)
B(-1,0,0,minecraft:podzol)
B(-1,-1,1,minecraft:cobblestone)
B(-1,0,1,minecraft:cobblestone_slab)
B(-1,-1,2,minecraft:grass_path)
B(-1,-1,3,minecraft:cobblestone)
B(-1,0,3,minecraft:cobblestone_slab)
B(-1,-1,4,minecraft:dirt)
B(-1,0,4,minecraft:podzol)
B(-1,3,4,minecraft:oak_fence[east=true,north=false,south=false,waterlogged=false,west=true])
B(-1,-1,5,minecraft:cobblestone)
B(-1,0,5,minecraft:cobblestone_slab)
B(0,-1,-6,minecraft:cobblestone)
B(0,0,-6,minecraft:cobblestone_stairs[facing=south,half=bottom,shape=straight,waterlogged=false])
B(0,-1,-5,minecraft:dirt)
B(0,0,-5,minecraft:podzol)
B(0,3,-5,minecraft:oak_fence[east=true,north=false,south=false,waterlogged=false,west=true])
B(0,-1,-4,minecraft:cobblestone)
B(0,0,-4,minecraft:cobblestone_slab)
B(0,-1,-3,minecraft:grass_path)
B(0,-1,-2,minecraft:cobblestone)
B(0,0,-2,minecraft:cobblestone_stairs[facing=south,half=bottom,shape=straight,waterlogged=false])
B(0,-1,-1,minecraft:dirt)
B(0,0,-1,minecraft:podzol)
B(0,-1,0,minecraft:dirt)
B(0,0,0,minecraft:podzol)
B(0,1,0,minecraft:oak_fence)
B(0,2,0,minecraft:oak_fence)
B(0,3,0,minecraft:oak_fence[east=true,north=false,south=true,waterlogged=false,west=false])
B(0,4,0,minecraft:torch)
B(0,-1,1,minecraft:cobblestone)
B(0,0,1,minecraft:cobblestone)
B(0,3,1,minecraft:oak_fence[east=false,north=true,south=true,waterlogged=false,west=false])
B(0,3,2,minecraft:oak_fence[east=false,north=true,south=true,waterlogged=false,west=false])
B(0,-1,3,minecraft:cobblestone)
B(0,0,3,minecraft:cobblestone_stairs[facing=east,half=bottom,shape=outer_right,waterlogged=false])
B(0,3,3,minecraft:oak_fence[east=false,north=true,south=true,waterlogged=false,west=false])
B(0,-1,4,minecraft:dirt)
B(0,0,4,minecraft:podzol)
B(0,1,4,minecraft:oak_fence)
B(0,2,4,minecraft:oak_fence)
B(0,3,4,minecraft:oak_fence[east=true,north=true,south=false,waterlogged=false,west=true])
B(0,-1,5,minecraft:cobblestone)
B(0,0,5,minecraft:cobblestone)
B(1,-1,-6,minecraft:cobblestone)
B(1,0,-6,minecraft:cobblestone_slab)
B(1,-1,-5,minecraft:cobblestone)
B(1,0,-5,minecraft:cobblestone_slab)
B(1,3,-5,minecraft:oak_fence[east=true,north=false,south=false,waterlogged=false,west=true])
B(1,-1,-4,minecraft:cobblestone)
B(1,-1,-3,minecraft:cauldron[level=3])
B(1,-1,-2,minecraft:cobblestone)
B(1,0,-2,minecraft:cobblestone_stairs[facing=west,half=bottom,shape=outer_left,waterlogged=false])
B(1,-1,-1,minecraft:cobblestone)
B(1,0,-1,minecraft:cobblestone_stairs[facing=west,half=bottom,shape=straight,waterlogged=false])
B(1,-1,0,minecraft:cobblestone)
B(1,0,0,minecraft:cobblestone_stairs[facing=north,half=bottom,shape=outer_left,waterlogged=false])
B(1,3,0,minecraft:oak_fence[east=true,north=false,south=false,waterlogged=false,west=true])
B(1,-1,1,minecraft:cobblestone)
B(1,0,1,minecraft:cobblestone)
B(1,-1,2,minecraft:cauldron[level=3])
B(1,-1,3,minecraft:cobblestone)
B(1,0,3,minecraft:cobblestone_stairs[facing=south,half=bottom,shape=outer_right,waterlogged=false])
B(1,-1,4,minecraft:cobblestone)
B(1,0,4,minecraft:cobblestone_stairs[facing=west,half=bottom,shape=straight,waterlogged=false])
B(1,3,4,minecraft:oak_fence[east=true,north=false,south=false,waterlogged=false,west=true])
B(1,-1,5,minecraft:cobblestone)
B(1,0,5,minecraft:cobblestone_wall[east=none,north=none,south=none,up=true,waterlogged=false,west=low])
B(2,-1,-7,minecraft:cobblestone)
B(2,0,-7,minecraft:cobblestone)
B(2,1,-7,minecraft:cobblestone_wall)
B(2,2,-7,minecraft:oak_fence)
B(2,-1,-6,minecraft:grass_path)
B(2,-1,-5,minecraft:grass_path)
B(2,3,-5,minecraft:oak_fence[east=true,north=false,south=true,waterlogged=false,west=true])
B(2,3,-4,minecraft:oak_fence[east=false,north=true,south=true,waterlogged=false,west=false])
B(2,-1,-3,minecraft:cobblestone)
B(2,0,-3,minecraft:cobblestone)
B(2,1,-3,minecraft:cobblestone_wall)
B(2,2,-3,minecraft:oak_fence)
B(2,3,-3,minecraft:oak_fence[east=false,north=true,south=false,waterlogged=false,west=false])
B(2,-1,-2,minecraft:cauldron[level=2])
B(2,-1,0,minecraft:grass_path)
B(2,3,0,minecraft:oak_fence[east=true,north=false,south=false,waterlogged=false,west=true])
B(2,-1,1,minecraft:cauldron[level=3])
B(2,-1,2,minecraft:cobblestone)
B(2,0,2,minecraft:cobblestone)
B(2,1,2,minecraft:cobblestone_wall)
B(2,2,2,minecraft:oak_fence)
B(2,3,2,minecraft:oak_fence[east=true,north=false,south=false,waterlogged=false,west=false])
B(2,3,4,minecraft:oak_fence[east=true,north=false,south=false,waterlogged=false,west=true])
B(2,-1,5,minecraft:grass_path)
B(2,-1,6,minecraft:cobblestone)
B(2,0,6,minecraft:cobblestone)
B(2,1,6,minecraft:cobblestone_wall)
B(2,2,6,minecraft:oak_fence)
B(3,-1,-6,minecraft:cobblestone)
B(3,0,-6,minecraft:cobblestone_stairs[facing=south,half=bottom,shape=outer_left,waterlogged=false])
B(3,-1,-5,minecraft:cobblestone)
B(3,0,-5,minecraft:cobblestone_stairs[facing=east,half=bottom,shape=straight,waterlogged=false])
B(3,3,-5,minecraft:oak_fence[east=true,north=false,south=false,waterlogged=false,west=true])
B(3,-1,-4,minecraft:cobblestone)
B(3,0,-4,minecraft:cobblestone_slab)
B(3,-1,-2,minecraft:cobblestone)
B(3,0,-2,minecraft:cobblestone)
B(3,-1,-1,minecraft:cobblestone)
B(3,0,-1,minecraft:cobblestone_slab)
B(3,-1,0,minecraft:cobblestone)
B(3,0,0,minecraft:cobblestone_slab)
B(3,3,0,minecraft:oak_fence[east=true,north=false,south=false,waterlogged=false,west=true])
B(3,-1,1,minecraft:cobblestone)
B(3,3,2,minecraft:oak_fence[east=true,north=false,south=false,waterlogged=false,west=true])
B(3,-1,3,minecraft:cobblestone)
B(3,0,3,minecraft:cobblestone_stairs[facing=south,half=bottom,shape=outer_left,waterlogged=false])
B(3,-1,4,minecraft:cobblestone)
B(3,0,4,minecraft:cobblestone_stairs[facing=east,half=bottom,shape=straight,waterlogged=false])
B(3,3,4,minecraft:oak_fence[east=true,north=false,south=false,waterlogged=false,west=true])
B(3,-1,5,minecraft:cobblestone)
B(4,-1,-6,minecraft:cobblestone)
B(4,0,-6,minecraft:cobblestone_slab)
B(4,-1,-5,minecraft:dirt)
B(4,0,-5,minecraft:podzol)
B(4,1,-5,minecraft:oak_fence)
B(4,2,-5,minecraft:oak_fence)
B(4,3,-5,minecraft:oak_fence[east=false,north=false,south=true,waterlogged=false,west=true])
B(4,-1,-4,minecraft:cobblestone)
B(4,0,-4,minecraft:cobblestone_stairs)
B(4,3,-4,minecraft:oak_fence[east=false,north=true,south=true,waterlogged=false,west=false])
B(4,3,-3,minecraft:oak_fence[east=false,north=true,south=true,waterlogged=false,west=false])
B(4,-1,-2,minecraft:cobblestone)
B(4,0,-2,minecraft:cobblestone_slab)
B(4,3,-2,minecraft:oak_fence[east=false,north=true,south=true,waterlogged=false,west=false])
B(4,-1,-1,minecraft:dirt)
B(4,0,-1,minecraft:podzol)
B(4,1,-1,minecraft:oak_fence)
B(4,2,-1,minecraft:oak_fence)
B(4,3,-1,minecraft:oak_fence[east=false,north=true,south=true,waterlogged=false,west=false])
B(4,-1,0,minecraft:dirt)
B(4,0,0,minecraft:podzol)
B(4,3,0,minecraft:oak_fence[east=false,north=true,south=true,waterlogged=false,west=true])
B(4,-1,1,minecraft:cobblestone)
B(4,0,1,minecraft:cobblestone_stairs)
B(4,3,1,minecraft:oak_fence[east=false,north=true,south=true,waterlogged=false,west=false])
B(4,-1,2,minecraft:grass_path)
B(4,3,2,minecraft:oak_fence[east=false,north=true,south=true,waterlogged=false,west=true])
B(4,-1,3,minecraft:cobblestone)
B(4,0,3,minecraft:cobblestone_stairs[facing=west,half=bottom,shape=outer_left,waterlogged=false])
B(4,3,3,minecraft:oak_fence[east=false,north=true,south=true,waterlogged=false,west=false])
B(4,-1,4,minecraft:dirt)
B(4,0,4,minecraft:podzol)
B(4,1,4,minecraft:oak_fence)
B(4,2,4,minecraft:oak_fence)
B(4,3,4,minecraft:oak_fence[east=false,north=true,south=false,waterlogged=false,west=true])
B(4,-1,5,minecraft:cobblestone)
B(4,0,5,minecraft:cobblestone)
B(5,-1,-6,minecraft:cobblestone)
B(5,0,-6,minecraft:cobblestone)
B(5,-1,-5,minecraft:cobblestone)
B(5,0,-5,minecraft:cobblestone_stairs[facing=west,half=bottom,shape=straight,waterlogged=false])
B(5,-1,-4,minecraft:cobblestone)
B(5,0,-4,minecraft:cobblestone_stairs[facing=west,half=bottom,shape=outer_right,waterlogged=false])
B(5,-1,-3,minecraft:grass_path)
B(5,-1,-2,minecraft:cobblestone)
B(5,0,-2,minecraft:cobblestone)
B(5,-1,-1,minecraft:cobblestone)
B(5,0,-1,minecraft:cobblestone)
B(5,-1,0,minecraft:cobblestone)
B(5,0,0,minecraft:cobblestone_slab)
B(5,-1,1,minecraft:cobblestone)
B(5,0,1,minecraft:cobblestone_stairs[facing=west,half=bottom,shape=outer_right,waterlogged=false])
B(5,-1,2,minecraft:grass_path)
B(5,-1,3,minecraft:cobblestone)
B(5,0,3,minecraft:cobblestone_wall)
B(5,-1,4,minecraft:cobblestone)
B(5,0,4,minecraft:cobblestone_slab)
B(5,-1,5,minecraft:cobblestone)
B(5,0,5,minecraft:cobblestone_slab)
B(6,-1,-7,minecraft:cobblestone)
B(6,0,-7,minecraft:cobblestone)
B(6,1,-7,minecraft:cobblestone_wall)
B(6,2,-7,minecraft:oak_fence)
B(6,3,-7,minecraft:torch)
B(6,-1,-3,minecraft:cobblestone)
B(6,0,-3,minecraft:cobblestone)
B(6,1,-3,minecraft:cobblestone_wall)
B(6,2,-3,minecraft:oak_fence)
B(6,-1,2,minecraft:cobblestone)
B(6,0,2,minecraft:cobblestone)
B(6,1,2,minecraft:cobblestone_wall)
B(6,2,2,minecraft:oak_fence)
B(6,-1,6,minecraft:cobblestone)
B(6,0,6,minecraft:cobblestone)
B(6,1,6,minecraft:cobblestone_wall)
B(6,2,6,minecraft:oak_fence)
B(6,3,6,minecraft:torch)
RB(5,1,-6,minecraft:air,../JungleNBT/pots/JunglePot01.nbt,10,minecraft:air,../JungleNBT/pots/JunglePot02.nbt,10,minecraft:air,../JungleNBT/pots/JunglePot03.nbt,10,minecraft:air,../JungleNBT/pots/JunglePot04.nbt,10,minecraft:air,../JungleNBT/pots/JunglePot05.nbt,10,minecraft:air,../JungleNBT/pots/JunglePot06.nbt,10,minecraft:air,../JungleNBT/pots/JunglePot07.nbt,10,minecraft:air,../JungleNBT/pots/JunglePot08.nbt,100)
RB(3,1,-2,minecraft:air,../JungleNBT/pots/JunglePot01.nbt,10,minecraft:air,../JungleNBT/pots/JunglePot02.nbt,10,minecraft:air,../JungleNBT/pots/JunglePot03.nbt,10,minecraft:air,../JungleNBT/pots/JunglePot04.nbt,10,minecraft:air,../JungleNBT/pots/JunglePot05.nbt,10,minecraft:air,../JungleNBT/pots/JunglePot06.nbt,10,minecraft:air,../JungleNBT/pots/JunglePot07.nbt,10,minecraft:air,../JungleNBT/pots/JunglePot08.nbt,100)
RB(-4,1,0,minecraft:air,../JungleNBT/pots/JunglePot01.nbt,10,minecraft:air,../JungleNBT/pots/JunglePot02.nbt,10,minecraft:air,../JungleNBT/pots/JunglePot03.nbt,10,minecraft:air,../JungleNBT/pots/JunglePot04.nbt,10,minecraft:air,../JungleNBT/pots/JunglePot05.nbt,10,minecraft:air,../JungleNBT/pots/JunglePot06.nbt,10,minecraft:air,../JungleNBT/pots/JunglePot07.nbt,10,minecraft:air,../JungleNBT/pots/JunglePot08.nbt,100)
RB(-2,1,3,minecraft:air,../JungleNBT/pots/JunglePot01.nbt,10,minecraft:air,../JungleNBT/pots/JunglePot02.nbt,10,minecraft:air,../JungleNBT/pots/JunglePot03.nbt,10,minecraft:air,../JungleNBT/pots/JunglePot04.nbt,10,minecraft:air,../JungleNBT/pots/JunglePot05.nbt,10,minecraft:air,../JungleNBT/pots/JunglePot06.nbt,10,minecraft:air,../JungleNBT/pots/JunglePot07.nbt,10,minecraft:air,../JungleNBT/pots/JunglePot08.nbt,100)
RB(4,1,5,minecraft:air,../JungleNBT/pots/JunglePot01.nbt,10,minecraft:air,../JungleNBT/pots/JunglePot02.nbt,10,minecraft:air,../JungleNBT/pots/JunglePot03.nbt,10,minecraft:air,../JungleNBT/pots/JunglePot04.nbt,10,minecraft:air,../JungleNBT/pots/JunglePot05.nbt,10,minecraft:air,../JungleNBT/pots/JunglePot06.nbt,10,minecraft:air,../JungleNBT/pots/JunglePot07.nbt,10,minecraft:air,../JungleNBT/pots/JunglePot08.nbt,100)

#######################################################################
# +-----------------------------------------------------------------+ #
# |                            BO3 checks                           | #
# +-----------------------------------------------------------------+ #
#######################################################################


#######################################################################
# +-----------------------------------------------------------------+ #
# |                             Branches                            | #
# +-----------------------------------------------------------------+ #
#######################################################################


#######################################################################
# +-----------------------------------------------------------------+ #
# |                             Entities                            | #
# +-----------------------------------------------------------------+ #
#######################################################################

Entity(0,1,-1,minecraft:villager,1,../JungleNBT/entities/tribalfarmer.txt)
