
#######################################################################
# +-----------------------------------------------------------------+ #
# |                            BO3 object                           | #
# +-----------------------------------------------------------------+ #
#######################################################################

Author: NLBlackEagle

Description: No description given

Version: 3

SettingsMode: WriteDisable


#######################################################################
# +-----------------------------------------------------------------+ #
# |                          Main settings                          | #
# +-----------------------------------------------------------------+ #
#######################################################################

Tree: false

Frequency: 1

Rarity: 90.0

RotateRandomly: true

SpawnHeight: randomY

SpawnHeightOffset: 0

SpawnHeightVariance: 0

##############################
# Height Limits for the BO3. #
##############################

MinHeight: 65

MaxHeight: 90

######################
# Extrusion settings #
######################

ExtrudeMode: None

ExtrudeThroughBlocks: AIR

MaxBranchDepth: 10

ExcludedBiomes: All


#######################################################################
# +-----------------------------------------------------------------+ #
# |                      Source block settings                      | #
# +-----------------------------------------------------------------+ #
#######################################################################

SourceBlocks: STONE,DIRT,GRASS,SAND,SANDSTONE,OBSIDIAN,STAINED_CLAY,AIR,COAL_ORE,IRON_ORE,GRAVEL,TALLGRASS,175,38,98,144,31,139

MaxPercentageOutsideSourceBlock: 0

OutsideSourceBlock: placeAnyway

DoReplaceBlocks: false

IsOTGPlus: false


#######################################################################
# +-----------------------------------------------------------------+ #
# |                              Blocks                             | #
# +-----------------------------------------------------------------+ #
#######################################################################

Block(-9,6,-2,STONE:6)
Block(-9,6,0,STONE:6)
Block(-9,6,1,STONE:6)
Block(-9,6,3,STONE:6)
Block(-9,7,-2,STONE:6)
Block(-9,7,0,STONE:6)
Block(-9,7,1,STONE:6)
Block(-9,7,3,STONE:6)
Block(-9,8,-2,STONE:6)
Block(-9,8,0,STONE:6)
Block(-9,8,1,STONE:6)
Block(-9,8,3,STONE:6)
Block(-9,9,-2,STONE:6)
Block(-9,9,0,STONE:6)
Block(-9,9,1,STONE:6)
Block(-9,9,3,STONE:6)
Block(-9,10,-2,STONE:6)
Block(-9,10,-1,STEP:0)
Block(-9,10,2,STEP:0)
Block(-9,10,3,STONE:6)
Block(-9,11,-2,minecraft:black_glazed_terracotta:1)
Block(-9,11,3,minecraft:black_glazed_terracotta:1)
Block(-8,6,0,STONE:6)
Block(-8,6,1,STONE:6)
Block(-8,7,0,STONE:6)
Block(-8,7,1,STONE:6)
Block(-8,8,0,STONE:6)
Block(-8,8,1,STONE:6)
Block(-8,9,0,SMOOTH_STAIRS:1)
Block(-8,9,1,SMOOTH_STAIRS:1)
Block(-8,10,-1,STEP:0)
Block(-8,10,2,STEP:0)
Block(-7,0,-2,COBBLESTONE:0)
Block(-7,0,-1,COBBLESTONE:0)
Block(-7,0,0,COBBLESTONE:0)
Block(-7,0,1,COBBLESTONE:0)
Block(-7,0,2,COBBLESTONE:0)
Block(-7,0,3,COBBLESTONE:0)
Block(-7,1,-2,COBBLESTONE:0)
Block(-7,1,-1,COBBLESTONE:0)
Block(-7,1,0,COBBLESTONE:0)
Block(-7,1,1,COBBLESTONE:0)
Block(-7,1,2,COBBLESTONE:0)
Block(-7,1,3,COBBLESTONE:0)
Block(-7,2,-2,COBBLESTONE:0)
Block(-7,2,-1,COBBLESTONE:0)
Block(-7,2,0,COBBLESTONE:0)
Block(-7,2,1,COBBLESTONE:0)
Block(-7,2,2,COBBLESTONE:0)
Block(-7,2,3,COBBLESTONE:0)
Block(-7,3,-2,COBBLESTONE:0)
Block(-7,3,-1,COBBLESTONE:0)
Block(-7,3,0,COBBLESTONE:0)
Block(-7,3,1,COBBLESTONE:0)
Block(-7,3,2,COBBLESTONE:0)
Block(-7,3,3,COBBLESTONE:0)
Block(-7,4,-2,COBBLESTONE:0)
Block(-7,4,-1,COBBLESTONE:0)
Block(-7,4,0,COBBLESTONE:0)
Block(-7,4,1,COBBLESTONE:0)
Block(-7,4,2,COBBLESTONE:0)
Block(-7,4,3,COBBLESTONE:0)
Block(-7,6,0,STONE:6)
Block(-7,6,1,STONE:6)
Block(-7,7,0,STONE:6)
Block(-7,7,1,STONE:6)
Block(-7,8,0,SMOOTH_STAIRS:1)
Block(-7,8,1,SMOOTH_STAIRS:1)
Block(-7,10,-1,STEP:0)
Block(-7,10,2,STEP:0)
Block(-6,0,-2,COBBLESTONE:0)
Block(-6,0,-1,COBBLESTONE:0)
Block(-6,0,0,COBBLESTONE:0)
Block(-6,0,1,COBBLESTONE:0)
Block(-6,0,2,COBBLESTONE:0)
Block(-6,0,3,COBBLESTONE:0)
Block(-6,1,-2,COBBLESTONE:0)
Block(-6,1,-1,COBBLESTONE_STAIRS:1)
Block(-6,1,1,COBBLESTONE_STAIRS:1)
Block(-6,1,3,COBBLESTONE:0)
Block(-6,2,-2,COBBLESTONE:0)
Block(-6,2,0,COBBLESTONE_STAIRS:1)
Block(-6,2,2,COBBLESTONE_STAIRS:1)
Block(-6,2,3,COBBLESTONE:0)
Block(-6,3,-2,COBBLESTONE:0)
Block(-6,3,-1,COBBLESTONE_STAIRS:5)
Block(-6,3,1,COBBLESTONE_STAIRS:5)
Block(-6,3,3,COBBLESTONE:0)
Block(-6,4,-2,COBBLESTONE:0)
Block(-6,4,-1,COBBLESTONE:0)
Block(-6,4,0,COBBLESTONE_STAIRS:1)
Block(-6,4,1,COBBLESTONE:0)
Block(-6,4,2,COBBLESTONE_STAIRS:1)
Block(-6,4,3,COBBLESTONE:0)
Block(-6,6,0,STONE:6)
Block(-6,6,1,STONE:6)
Block(-6,7,0,SMOOTH_STAIRS:1)
Block(-6,7,1,SMOOTH_STAIRS:1)
Block(-6,10,-4,STEP:0)
Block(-6,10,-3,STEP:0)
Block(-6,10,-2,STEP:0)
Block(-6,10,-1,STEP:0)
Block(-6,10,2,STEP:0)
Block(-6,10,3,STEP:0)
Block(-6,10,4,STEP:0)
Block(-6,10,5,STEP:0)
Block(-5,0,-2,COBBLESTONE:0)
Block(-5,0,-1,COBBLESTONE:0)
Block(-5,0,0,COBBLESTONE:0)
Block(-5,0,1,COBBLESTONE:0)
Block(-5,0,2,COBBLESTONE:0)
Block(-5,0,3,COBBLESTONE:0)
Block(-5,1,-2,COBBLESTONE:0)
Block(-5,1,-1,COBBLESTONE:0)
Block(-5,1,1,COBBLESTONE:0)
Block(-5,1,3,COBBLESTONE:0)
Block(-5,2,-2,COBBLESTONE:0)
Block(-5,2,0,COBBLESTONE:0)
Block(-5,2,2,COBBLESTONE:0)
Block(-5,2,3,COBBLESTONE:0)
Block(-5,3,-2,COBBLESTONE:0)
Block(-5,3,-1,COBBLESTONE:0)
Block(-5,3,1,COBBLESTONE:0)
Block(-5,3,3,COBBLESTONE:0)
Block(-5,4,-2,COBBLESTONE:0)
Block(-5,4,-1,COBBLESTONE:0)
Block(-5,4,0,COBBLESTONE:0)
Block(-5,4,1,COBBLESTONE:0)
Block(-5,4,2,COBBLESTONE:0)
Block(-5,4,3,COBBLESTONE:0)
Block(-5,6,-3,STONE:6)
Block(-5,6,-2,SMOOTH_STAIRS:0)
Block(-5,6,-1,SMOOTH_STAIRS:0)
Block(-5,6,0,STONE:6)
Block(-5,6,1,STONE:6)
Block(-5,6,2,SMOOTH_STAIRS:0)
Block(-5,6,3,SMOOTH_STAIRS:0)
Block(-5,6,4,STONE:6)
Block(-5,7,-3,STONE:6)
Block(-5,7,4,STONE:6)
Block(-5,8,-3,STONE:6)
Block(-5,8,4,STONE:6)
Block(-5,9,-3,STONE:6)
Block(-5,9,4,STONE:6)
Block(-5,10,-4,STEP:0)
Block(-5,10,-3,STONE:6)
Block(-5,10,4,STONE:6)
Block(-5,10,5,STEP:0)
Block(-5,11,-3,minecraft:black_glazed_terracotta:3)
Block(-5,11,4,minecraft:black_glazed_terracotta)
Block(-4,0,-5,COBBLESTONE:0)
Block(-4,0,-4,COBBLESTONE:0)
Block(-4,0,-3,COBBLESTONE:0)
Block(-4,0,-2,STONE:6)
Block(-4,0,-1,STONE:6)
Block(-4,0,0,STONE:6)
Block(-4,0,1,STONE:6)
Block(-4,0,2,STONE:6)
Block(-4,0,3,STONE:6)
Block(-4,0,4,COBBLESTONE:0)
Block(-4,0,5,COBBLESTONE:0)
Block(-4,0,6,COBBLESTONE:0)
Block(-4,1,-5,COBBLESTONE:0)
Block(-4,1,-4,COBBLESTONE:0)
Block(-4,1,-3,COBBLESTONE:0)
Block(-4,1,-2,STONE:6)
Block(-4,1,-1,STONE:6)
Block(-4,1,0,IRON_FENCE:0)
Block(-4,1,1,STONE:6)
Block(-4,1,2,IRON_FENCE:0)
Block(-4,1,3,STONE:6)
Block(-4,1,4,COBBLESTONE:0)
Block(-4,1,5,COBBLESTONE:0)
Block(-4,1,6,COBBLESTONE:0)
Block(-4,2,-5,COBBLESTONE:0)
Block(-4,2,-4,COBBLESTONE:0)
Block(-4,2,-3,COBBLESTONE:0)
Block(-4,2,-2,STONE:6)
Block(-4,2,-1,IRON_FENCE:0)
Block(-4,2,0,STONE:6)
Block(-4,2,1,IRON_FENCE:0)
Block(-4,2,2,STONE:6)
Block(-4,2,3,STONE:6)
Block(-4,2,4,COBBLESTONE:0)
Block(-4,2,5,COBBLESTONE:0)
Block(-4,2,6,COBBLESTONE:0)
Block(-4,3,-5,COBBLESTONE:0)
Block(-4,3,-4,COBBLESTONE:0)
Block(-4,3,-3,COBBLESTONE:0)
Block(-4,3,-2,STONE:6)
Block(-4,3,-1,STONE:6)
Block(-4,3,0,IRON_FENCE:0)
Block(-4,3,1,STONE:6)
Block(-4,3,2,IRON_FENCE:0)
Block(-4,3,3,STONE:6)
Block(-4,3,4,COBBLESTONE:0)
Block(-4,3,5,COBBLESTONE:0)
Block(-4,3,6,COBBLESTONE:0)
Block(-4,4,-5,COBBLESTONE:0)
Block(-4,4,-4,COBBLESTONE:0)
Block(-4,4,-3,COBBLESTONE:0)
Block(-4,4,-2,STONE:6)
Block(-4,4,-1,SMOOTH_BRICK:0)
Block(-4,4,0,SMOOTH_BRICK:0)
Block(-4,4,1,SMOOTH_BRICK:0)
Block(-4,4,2,SMOOTH_BRICK:0)
Block(-4,4,3,STONE:6)
Block(-4,4,4,COBBLESTONE:0)
Block(-4,4,5,COBBLESTONE:0)
Block(-4,4,6,COBBLESTONE:0)
Block(-4,5,-2,STONE:6)
Block(-4,5,-1,SMOOTH_BRICK:0)
Block(-4,5,0,SMOOTH_BRICK:0)
Block(-4,5,1,SMOOTH_BRICK:0)
Block(-4,5,2,SMOOTH_BRICK:0)
Block(-4,5,3,STONE:6)
Block(-4,6,-3,SMOOTH_STAIRS:2)
Block(-4,6,-2,STONE:6)
Block(-4,6,-1,STONE:6)
Block(-4,6,0,STONE:6)
Block(-4,6,1,STONE:6)
Block(-4,6,2,STONE:6)
Block(-4,6,3,STONE:6)
Block(-4,6,4,SMOOTH_STAIRS:3)
Block(-4,7,-2,REDSTONE_WIRE:0)
Block(-4,10,-4,STEP:0)
Block(-4,10,5,STEP:0)
Block(-3,0,-5,COBBLESTONE:0)
Block(-3,0,-4,COBBLESTONE:0)
Block(-3,0,-3,COBBLESTONE:0)
Block(-3,0,-2,STONE:6)
Block(-3,0,-1,COBBLESTONE:0)
Block(-3,0,0,COBBLESTONE:0)
Block(-3,0,1,COBBLESTONE:0)
Block(-3,0,2,COBBLESTONE:0)
Block(-3,0,3,STONE:6)
Block(-3,0,4,COBBLESTONE:0)
Block(-3,0,5,COBBLESTONE:0)
Block(-3,0,6,COBBLESTONE:0)
Block(-3,1,-5,COBBLESTONE:0)
Block(-3,1,-4,COBBLESTONE:0)
Block(-3,1,-3,COBBLESTONE:0)
Block(-3,1,-2,STONE:6)
Block(-3,1,-1,WEB:0)
Block(-3,1,2,WEB:0)
Block(-3,1,3,IRON_FENCE:0)
Block(-3,1,6,COBBLESTONE:0)
Block(-3,2,-5,COBBLESTONE:0)
Block(-3,2,-2,IRON_FENCE:0)
Block(-3,2,1,WEB:0)
Block(-3,2,2,WEB:0)
Block(-3,2,3,STONE:6)
Block(-3,2,4,COBBLESTONE:0)
Block(-3,2,5,COBBLESTONE_STAIRS:2)
Block(-3,2,6,COBBLESTONE:0)
Block(-3,3,-5,COBBLESTONE:0)
Block(-3,3,-4,COBBLESTONE_STAIRS:3)
Block(-3,3,-3,COBBLESTONE:0)
Block(-3,3,-2,STONE:6)
Block(-3,3,1,WEB:0)
Block(-3,3,3,IRON_FENCE:0)
Block(-3,3,6,COBBLESTONE:0)
Block(-3,4,-5,COBBLESTONE:0)
Block(-3,4,-4,COBBLESTONE:0)
Block(-3,4,-3,COBBLESTONE:0)
Block(-3,4,-2,SMOOTH_BRICK:0)
Block(-3,4,-1,WEB:0)
Block(-3,4,0,WEB:0)
Block(-3,4,1,WEB:0)
Block(-3,4,2,WEB:0)
Block(-3,4,3,SMOOTH_BRICK:0)
Block(-3,4,4,COBBLESTONE:0)
Block(-3,4,5,COBBLESTONE_STAIRS:2)
Block(-3,4,6,COBBLESTONE:0)
Block(-3,5,-2,SMOOTH_BRICK:0)
Block(-3,5,-1,CONCRETE:6)
Block(-3,5,0,STAINED_CLAY:15)
Block(-3,5,1,STAINED_CLAY:14)
Block(-3,5,2,CONCRETE:6)
Block(-3,5,3,SMOOTH_BRICK:0)
Block(-3,6,-3,SMOOTH_STAIRS:2)
Block(-3,6,-2,STONE:6)
Block(-3,6,-1,STATIONARY_WATER:0)
Block(-3,6,0,STATIONARY_WATER:0)
Block(-3,6,1,STATIONARY_WATER:0)
Block(-3,6,2,STATIONARY_WATER:0)
Block(-3,6,3,STONE:6)
Block(-3,6,4,SMOOTH_STAIRS:3)
Block(-3,10,-4,STEP:0)
Block(-3,10,5,STEP:0)
Block(-2,0,-5,COBBLESTONE:0)
Block(-2,0,-4,COBBLESTONE:0)
Block(-2,0,-3,COBBLESTONE:0)
Block(-2,0,-2,STONE:6)
Block(-2,0,-1,COBBLESTONE:0)
Block(-2,0,0,COBBLESTONE:0)
Block(-2,0,1,COBBLESTONE:0)
Block(-2,0,2,COBBLESTONE:0)
Block(-2,0,3,STONE:6)
Block(-2,0,4,COBBLESTONE:0)
Block(-2,0,5,COBBLESTONE:0)
Block(-2,0,6,COBBLESTONE:0)
Block(-2,1,-5,COBBLESTONE:0)
Block(-2,1,-2,IRON_FENCE:0)
Block(-2,1,3,STONE:6)
Block(-2,1,4,COBBLESTONE:0)
Block(-2,1,5,COBBLESTONE_STAIRS:6)
Block(-2,1,6,COBBLESTONE:0)
Block(-2,2,-5,COBBLESTONE:0)
Block(-2,2,-4,COBBLESTONE_STAIRS:3)
Block(-2,2,-3,COBBLESTONE:0)
Block(-2,2,-2,STONE:6)
Block(-2,2,-1,WEB:0)
Block(-2,2,6,COBBLESTONE:0)
Block(-2,3,-5,COBBLESTONE:0)
Block(-2,3,-2,IRON_FENCE:0)
Block(-2,3,3,STONE:6)
Block(-2,3,4,COBBLESTONE:0)
Block(-2,3,5,COBBLESTONE_STAIRS:6)
Block(-2,3,6,COBBLESTONE:0)
Block(-2,4,-5,COBBLESTONE:0)
Block(-2,4,-4,COBBLESTONE_STAIRS:3)
Block(-2,4,-3,COBBLESTONE:0)
Block(-2,4,-2,SMOOTH_BRICK:0)
Block(-2,4,2,WEB:0)
Block(-2,4,3,SMOOTH_BRICK:0)
Block(-2,4,4,COBBLESTONE:0)
Block(-2,4,5,COBBLESTONE:0)
Block(-2,4,6,COBBLESTONE:0)
Block(-2,5,-2,SMOOTH_BRICK:0)
Block(-2,5,-1,STAINED_CLAY:14)
Block(-2,5,0,STAINED_CLAY:15)
Block(-2,5,1,minecraft:red_glazed_terracotta:3)
Block(-2,5,2,STAINED_CLAY:15)
Block(-2,5,3,SMOOTH_BRICK:0)
Block(-2,6,-3,SMOOTH_STAIRS:2)
Block(-2,6,-2,STONE:6)
Block(-2,6,-1,STATIONARY_WATER:0)
Block(-2,6,0,STONE:6)
Block(-2,6,1,STONE:6)
Block(-2,6,2,STATIONARY_WATER:0)
Block(-2,6,3,STONE:6)
Block(-2,6,4,SMOOTH_STAIRS:3)
Block(-2,7,0,COBBLESTONE_STAIRS:2)
Block(-2,7,1,COBBLESTONE_STAIRS:0)
Block(-2,8,0,STEP:0)
Block(-2,8,1,STEP:0)
Block(-2,10,-4,STEP:0)
Block(-2,10,5,STEP:0)
Block(-1,0,-5,COBBLESTONE:0)
Block(-1,0,-4,COBBLESTONE:0)
Block(-1,0,-3,COBBLESTONE:0)
Block(-1,0,-2,STONE:6)
Block(-1,0,-1,COBBLESTONE:0)
Block(-1,0,0,COBBLESTONE:0)
Block(-1,0,1,COBBLESTONE:0)
Block(-1,0,2,COBBLESTONE:0)
Block(-1,0,3,STONE:6)
Block(-1,0,4,COBBLESTONE:0)
Block(-1,0,5,COBBLESTONE:0)
Block(-1,0,6,COBBLESTONE:0)
Block(-1,1,-5,COBBLESTONE:0)
Block(-1,1,-4,COBBLESTONE:0)
Block(-1,1,-3,COBBLESTONE:0)
Block(-1,1,-2,STONE:6)
Block(-1,1,-1,WEB:0)
Block(-1,1,0,WEB:0)
Block(-1,1,3,IRON_FENCE:0)
Block(-1,1,6,COBBLESTONE:0)
Block(-1,2,-5,COBBLESTONE:0)
Block(-1,2,-2,IRON_FENCE:0)
Block(-1,2,3,STONE:6)
Block(-1,2,4,COBBLESTONE:0)
Block(-1,2,5,COBBLESTONE_STAIRS:2)
Block(-1,2,6,COBBLESTONE:0)
Block(-1,3,-5,COBBLESTONE:0)
Block(-1,3,-4,COBBLESTONE_STAIRS:7)
Block(-1,3,-3,COBBLESTONE:0)
Block(-1,3,-2,STONE:6)
Block(-1,3,-1,WEB:0)
Block(-1,3,3,IRON_FENCE:0)
Block(-1,3,6,COBBLESTONE:0)
Block(-1,4,-5,COBBLESTONE:0)
Block(-1,4,-4,COBBLESTONE:0)
Block(-1,4,-3,COBBLESTONE:0)
Block(-1,4,-2,SMOOTH_BRICK:0)
Block(-1,4,-1,WEB:0)
Block(-1,4,2,WEB:0)
Block(-1,4,3,SMOOTH_BRICK:0)
Block(-1,4,4,COBBLESTONE:0)
Block(-1,4,5,COBBLESTONE_STAIRS:2)
Block(-1,4,6,COBBLESTONE:0)
Block(-1,5,-2,SMOOTH_BRICK:0)
Block(-1,5,-1,STAINED_CLAY:14)
Block(-1,5,0,STAINED_CLAY:15)
Block(-1,5,1,STAINED_CLAY:15)
Block(-1,5,2,minecraft:red_glazed_terracotta:3)
Block(-1,5,3,SMOOTH_BRICK:0)
Block(-1,6,-3,SMOOTH_STAIRS:2)
Block(-1,6,-2,STONE:6)
Block(-1,6,-1,STATIONARY_WATER:0)
Block(-1,6,0,STONE:6)
Block(-1,6,1,STONE:6)
Block(-1,6,2,STATIONARY_WATER:0)
Block(-1,6,3,STONE:6)
Block(-1,6,4,SMOOTH_STAIRS:3)
Block(-1,7,0,COBBLESTONE_STAIRS:2)
Block(-1,7,1,COBBLESTONE_STAIRS:3)
Block(-1,7,3,REDSTONE_WIRE:0)
Block(-1,8,0,STEP:0)
Block(-1,8,1,STEP:0)
Block(-1,10,-4,STEP:0)
Block(-1,10,5,STEP:0)
Block(0,0,-5,COBBLESTONE:0)
Block(0,0,-4,COBBLESTONE:0)
Block(0,0,-3,COBBLESTONE:0)
Block(0,0,-2,STONE:6)
Block(0,0,-1,COBBLESTONE:0)
Block(0,0,0,COBBLESTONE:0)
Block(0,0,1,COBBLESTONE:0)
Block(0,0,2,COBBLESTONE:0)
Block(0,0,3,STONE:6)
Block(0,0,4,COBBLESTONE:0)
Block(0,0,5,COBBLESTONE:0)
Block(0,0,6,COBBLESTONE:0)
Block(0,1,-5,COBBLESTONE:0)
Block(0,1,-2,IRON_FENCE:0)
Block(0,1,1,WEB:0)
Block(0,1,3,STONE:6)
Block(0,1,4,COBBLESTONE:0)
Block(0,1,5,COBBLESTONE_STAIRS:6)
Block(0,1,6,COBBLESTONE:0)
Block(0,2,-5,COBBLESTONE:0)
Block(0,2,-4,COBBLESTONE_STAIRS:3)
Block(0,2,-3,COBBLESTONE:0)
Block(0,2,-2,STONE:6)
Block(0,2,3,IRON_FENCE:0)
Block(0,2,6,COBBLESTONE:0)
Block(0,3,-5,COBBLESTONE:0)
Block(0,3,-2,IRON_FENCE:0)
Block(0,3,3,STONE:6)
Block(0,3,4,COBBLESTONE:0)
Block(0,3,5,COBBLESTONE_STAIRS:6)
Block(0,3,6,COBBLESTONE:0)
Block(0,4,-5,COBBLESTONE:0)
Block(0,4,-4,COBBLESTONE_STAIRS:3)
Block(0,4,-3,COBBLESTONE:0)
Block(0,4,-2,SMOOTH_BRICK:0)
Block(0,4,2,WEB:0)
Block(0,4,3,SMOOTH_BRICK:0)
Block(0,4,4,COBBLESTONE:0)
Block(0,4,5,COBBLESTONE:0)
Block(0,4,6,COBBLESTONE:0)
Block(0,5,-2,SMOOTH_BRICK:0)
Block(0,5,-1,STAINED_CLAY:15)
Block(0,5,0,CONCRETE:6)
Block(0,5,1,STAINED_CLAY:15)
Block(0,5,2,STAINED_CLAY:15)
Block(0,5,3,SMOOTH_BRICK:0)
Block(0,6,-3,SMOOTH_STAIRS:2)
Block(0,6,-2,STONE:6)
Block(0,6,-1,STATIONARY_WATER:0)
Block(0,6,0,STONE:6)
Block(0,6,1,STONE:6)
Block(0,6,2,STATIONARY_WATER:0)
Block(0,6,3,STONE:6)
Block(0,6,4,SMOOTH_STAIRS:3)
Block(0,7,-2,REDSTONE_WIRE:0)
Block(0,7,0,COBBLESTONE_STAIRS:2)
Block(0,7,1,COBBLESTONE_STAIRS:3)
Block(0,8,0,STEP:0)
Block(0,8,1,STEP:0)
Block(0,10,-4,STEP:0)
Block(0,10,5,STEP:0)
Block(1,0,-5,COBBLESTONE:0)
Block(1,0,-4,COBBLESTONE:0)
Block(1,0,-3,COBBLESTONE:0)
Block(1,0,-2,STONE:6)
Block(1,0,-1,COBBLESTONE:0)
Block(1,0,0,COBBLESTONE:0)
Block(1,0,1,COBBLESTONE:0)
Block(1,0,2,COBBLESTONE:0)
Block(1,0,3,STONE:6)
Block(1,0,4,COBBLESTONE:0)
Block(1,0,5,COBBLESTONE:0)
Block(1,0,6,COBBLESTONE:0)
Block(1,1,-5,COBBLESTONE:0)
Block(1,1,-4,COBBLESTONE:0)
Block(1,1,-3,COBBLESTONE:0)
Block(1,1,-2,STONE:6)
Block(1,1,-1,WEB:0)
Block(1,1,0,WEB:0)
Block(1,1,1,WEB:0)
Block(1,1,3,IRON_FENCE:0)
Block(1,1,6,COBBLESTONE:0)
Block(1,2,-5,COBBLESTONE:0)
Block(1,2,-2,IRON_FENCE:0)
Block(1,2,2,WEB:0)
Block(1,2,3,STONE:6)
Block(1,2,4,COBBLESTONE:0)
Block(1,2,5,COBBLESTONE_STAIRS:2)
Block(1,2,6,COBBLESTONE:0)
Block(1,3,-5,COBBLESTONE:0)
Block(1,3,-4,COBBLESTONE_STAIRS:7)
Block(1,3,-3,COBBLESTONE:0)
Block(1,3,-2,STONE:6)
Block(1,3,-1,WEB:0)
Block(1,3,3,IRON_FENCE:0)
Block(1,3,6,COBBLESTONE:0)
Block(1,4,-5,COBBLESTONE:0)
Block(1,4,-4,COBBLESTONE:0)
Block(1,4,-3,COBBLESTONE:0)
Block(1,4,-2,SMOOTH_BRICK:0)
Block(1,4,-1,WEB:0)
Block(1,4,0,WEB:0)
Block(1,4,1,WEB:0)
Block(1,4,3,SMOOTH_BRICK:0)
Block(1,4,4,COBBLESTONE:0)
Block(1,4,5,COBBLESTONE_STAIRS:2)
Block(1,4,6,COBBLESTONE:0)
Block(1,5,-2,SMOOTH_BRICK:0)
Block(1,5,-1,STAINED_CLAY:15)
Block(1,5,0,CONCRETE:6)
Block(1,5,1,minecraft:red_glazed_terracotta:3)
Block(1,5,2,STAINED_CLAY:14)
Block(1,5,3,SMOOTH_BRICK:0)
Block(1,6,-3,SMOOTH_STAIRS:2)
Block(1,6,-2,STONE:6)
Block(1,6,-1,STATIONARY_WATER:0)
Block(1,6,0,STONE:6)
Block(1,6,1,STONE:6)
Block(1,6,2,STATIONARY_WATER:0)
Block(1,6,3,STONE:6)
Block(1,6,4,SMOOTH_STAIRS:3)
Block(1,7,0,COBBLESTONE_STAIRS:1)
Block(1,7,1,COBBLESTONE_STAIRS:3)
Block(1,8,0,STEP:0)
Block(1,8,1,STEP:0)
Block(1,10,-4,STEP:0)
Block(1,10,5,STEP:0)
Block(2,0,-5,COBBLESTONE:0)
Block(2,0,-4,COBBLESTONE:0)
Block(2,0,-3,COBBLESTONE:0)
Block(2,0,-2,STONE:6)
Block(2,0,-1,COBBLESTONE:0)
Block(2,0,0,COBBLESTONE:0)
Block(2,0,1,COBBLESTONE:0)
Block(2,0,2,COBBLESTONE:0)
Block(2,0,3,STONE:6)
Block(2,0,4,COBBLESTONE:0)
Block(2,0,5,COBBLESTONE:0)
Block(2,0,6,COBBLESTONE:0)
Block(2,1,-5,COBBLESTONE:0)
Block(2,1,-2,IRON_FENCE:0)
Block(2,1,-1,WEB:0)
Block(2,1,0,WEB:0)
Block(2,1,1,WEB:0)
Block(2,1,2,WEB:0)
Block(2,1,3,STONE:6)
Block(2,1,4,COBBLESTONE:0)
Block(2,1,5,COBBLESTONE_STAIRS:6)
Block(2,1,6,COBBLESTONE:0)
Block(2,2,-5,COBBLESTONE:0)
Block(2,2,-4,COBBLESTONE_STAIRS:3)
Block(2,2,-3,COBBLESTONE:0)
Block(2,2,-2,STONE:6)
Block(2,2,-1,WEB:0)
Block(2,2,3,IRON_FENCE:0)
Block(2,2,6,COBBLESTONE:0)
Block(2,3,-5,COBBLESTONE:0)
Block(2,3,-2,IRON_FENCE:0)
Block(2,3,2,WEB:0)
Block(2,3,3,STONE:6)
Block(2,3,4,COBBLESTONE:0)
Block(2,3,5,COBBLESTONE_STAIRS:6)
Block(2,3,6,COBBLESTONE:0)
Block(2,4,-5,COBBLESTONE:0)
Block(2,4,-4,COBBLESTONE_STAIRS:3)
Block(2,4,-3,COBBLESTONE:0)
Block(2,4,-2,SMOOTH_BRICK:0)
Block(2,4,-1,WEB:0)
Block(2,4,0,WEB:0)
Block(2,4,2,WEB:0)
Block(2,4,3,SMOOTH_BRICK:0)
Block(2,4,4,COBBLESTONE:0)
Block(2,4,5,COBBLESTONE:0)
Block(2,4,6,COBBLESTONE:0)
Block(2,5,-2,SMOOTH_BRICK:0)
Block(2,5,-1,minecraft:red_glazed_terracotta:0)
Block(2,5,0,STAINED_CLAY:15)
Block(2,5,1,STAINED_CLAY:15)
Block(2,5,2,STAINED_CLAY:15)
Block(2,5,3,SMOOTH_BRICK:0)
Block(2,6,-3,SMOOTH_STAIRS:2)
Block(2,6,-2,STONE:6)
Block(2,6,-1,STATIONARY_WATER:0)
Block(2,6,0,STATIONARY_WATER:0)
Block(2,6,1,STATIONARY_WATER:0)
Block(2,6,2,STATIONARY_WATER:0)
Block(2,6,3,STONE:6)
Block(2,6,4,SMOOTH_STAIRS:3)
Block(2,10,-4,STEP:0)
Block(2,10,5,STEP:0)
Block(3,0,-5,COBBLESTONE:0)
Block(3,0,-4,COBBLESTONE:0)
Block(3,0,-3,COBBLESTONE:0)
Block(3,0,-2,STONE:6)
Block(3,0,-1,COBBLESTONE:0)
Block(3,0,0,COBBLESTONE:0)
Block(3,0,1,COBBLESTONE:0)
Block(3,0,2,COBBLESTONE:0)
Block(3,0,3,STONE:6)
Block(3,0,4,COBBLESTONE:0)
Block(3,0,5,COBBLESTONE:0)
Block(3,0,6,COBBLESTONE:0)
Block(3,1,-5,COBBLESTONE:0)
Block(3,1,-4,COBBLESTONE:0)
Block(3,1,-3,COBBLESTONE:0)
Block(3,1,-2,STONE:6)
Block(3,1,-1,STONE:6)
Block(3,1,2,STONE:6)
Block(3,1,3,STONE:6)
Block(3,1,4,COBBLESTONE:0)
Block(3,1,5,COBBLESTONE:0)
Block(3,1,6,COBBLESTONE:0)
Block(3,2,-5,COBBLESTONE:0)
Block(3,2,-4,COBBLESTONE:0)
Block(3,2,-3,COBBLESTONE:0)
Block(3,2,-2,STONE:6)
Block(3,2,-1,STONE:6)
Block(3,2,1,WEB:0)
Block(3,2,2,STONE:6)
Block(3,2,3,STONE:6)
Block(3,2,4,COBBLESTONE:0)
Block(3,2,5,COBBLESTONE:0)
Block(3,2,6,COBBLESTONE:0)
Block(3,3,-5,COBBLESTONE:0)
Block(3,3,-4,COBBLESTONE:0)
Block(3,3,-3,COBBLESTONE:0)
Block(3,3,-2,STONE:6)
Block(3,3,-1,STONE:6)
Block(3,3,2,STONE:6)
Block(3,3,3,STONE:6)
Block(3,3,4,COBBLESTONE:0)
Block(3,3,5,COBBLESTONE:0)
Block(3,3,6,COBBLESTONE:0)
Block(3,4,-5,COBBLESTONE:0)
Block(3,4,-4,COBBLESTONE:0)
Block(3,4,-3,COBBLESTONE:0)
Block(3,4,-2,STONE:6)
Block(3,4,-1,SMOOTH_BRICK:0)
Block(3,4,0,SMOOTH_BRICK:0)
Block(3,4,1,SMOOTH_BRICK:0)
Block(3,4,2,SMOOTH_BRICK:0)
Block(3,4,3,STONE:6)
Block(3,4,4,COBBLESTONE:0)
Block(3,4,5,COBBLESTONE:0)
Block(3,4,6,COBBLESTONE:0)
Block(3,5,-2,STONE:6)
Block(3,5,-1,SMOOTH_BRICK:0)
Block(3,5,0,SMOOTH_BRICK:0)
Block(3,5,1,SMOOTH_BRICK:0)
Block(3,5,2,SMOOTH_BRICK:0)
Block(3,5,3,STONE:6)
Block(3,6,-3,SMOOTH_STAIRS:2)
Block(3,6,-2,STONE:6)
Block(3,6,-1,STONE:6)
Block(3,6,0,STONE:6)
Block(3,6,1,STONE:6)
Block(3,6,2,STONE:6)
Block(3,6,3,STONE:6)
Block(3,6,4,SMOOTH_STAIRS:3)
Block(3,7,0,REDSTONE_WIRE:0)
Block(3,7,3,REDSTONE_WIRE:0)
Block(3,10,-4,STEP:0)
Block(3,10,5,STEP:0)
Block(4,0,-1,STONE:6)
Block(4,0,0,COBBLESTONE:0)
Block(4,0,1,COBBLESTONE:0)
Block(4,0,2,STONE:6)
Block(4,1,-1,STONE:6)
Block(4,1,1,WEB:0)
Block(4,1,2,STONE:6)
Block(4,2,-1,STONE:6)
Block(4,2,2,STONE:6)
Block(4,3,-1,STONE:6)
Block(4,3,0,WEB:0)
Block(4,3,1,WEB:0)
Block(4,3,2,STONE:6)
Block(4,4,-1,STONE:6)
Block(4,4,0,COBBLESTONE_STAIRS:5)
Block(4,4,1,COBBLESTONE_STAIRS:5)
Block(4,4,2,STONE:6)
Block(4,5,-1,STONE:6)
Block(4,5,0,STONE:6)
Block(4,5,1,STONE:6)
Block(4,5,2,STONE:6)
Block(4,6,-3,STONE:6)
Block(4,6,-2,SMOOTH_STAIRS:1)
Block(4,6,-1,SMOOTH_STAIRS:1)
Block(4,6,0,SMOOTH_STAIRS:1)
Block(4,6,1,SMOOTH_STAIRS:1)
Block(4,6,2,SMOOTH_STAIRS:1)
Block(4,6,3,SMOOTH_STAIRS:1)
Block(4,6,4,STONE:6)
Block(4,7,-3,STONE:6)
Block(4,7,4,STONE:6)
Block(4,8,-3,STONE:6)
Block(4,8,4,STONE:6)
Block(4,9,-3,STONE:6)
Block(4,9,4,STONE:6)
Block(4,10,-4,STEP:0)
Block(4,10,-3,STONE:6)
Block(4,10,4,STONE:6)
Block(4,10,5,STEP:0)
Block(4,11,-3,minecraft:black_glazed_terracotta:0)
Block(4,11,4,minecraft:black_glazed_terracotta:0)
Block(5,0,-1,STONE:6)
Block(5,0,0,COBBLESTONE:0)
Block(5,0,1,COBBLESTONE:0)
Block(5,0,2,STONE:6)
Block(5,1,-1,STONE:6)
Block(5,1,0,COBBLESTONE_STAIRS:0)
Block(5,1,1,COBBLESTONE_STAIRS:0)
Block(5,1,2,STONE:6)
Block(5,2,-1,STONE:6)
Block(5,2,2,STONE:6)
Block(5,3,-1,STONE:6)
Block(5,3,0,WEB:0)
Block(5,3,1,WEB:0)
Block(5,3,2,STONE:6)
Block(5,4,-1,STONE:6)
Block(5,4,0,STEP:13)
Block(5,4,1,STEP:13)
Block(5,4,2,STONE:6)
Block(5,5,-1,STONE:6)
Block(5,5,0,STONE:6)
Block(5,5,1,STONE:6)
Block(5,5,2,STONE:6)
Block(5,6,-2,STEP:5)
Block(5,6,-1,SMOOTH_STAIRS:2)
Block(5,6,0,SMOOTH_STAIRS:0)
Block(5,6,1,SMOOTH_STAIRS:0)
Block(5,6,2,SMOOTH_STAIRS:3)
Block(5,6,3,STEP:5)
Block(5,7,-1,STEP:0)
Block(5,7,0,STEP:0)
Block(5,7,1,STEP:0)
Block(5,7,2,STEP:0)
Block(5,10,-4,STEP:0)
Block(5,10,-3,STEP:0)
Block(5,10,4,STEP:0)
Block(5,10,5,STEP:0)
Block(6,0,-1,STONE:6)
Block(6,0,0,STONE:6)
Block(6,0,1,STONE:6)
Block(6,0,2,STONE:6)
Block(6,1,-1,STONE:6)
Block(6,1,0,STONE:6)
Block(6,1,1,STONE:6)
Block(6,1,2,STONE:6)
Block(6,2,-1,COBBLESTONE_STAIRS:3)
Block(6,2,2,COBBLESTONE_STAIRS:2)
Block(6,3,-1,COBBLESTONE_STAIRS:7)
Block(6,3,2,COBBLESTONE_STAIRS:6)
Block(6,4,-1,COBBLESTONE:0)
Block(6,4,2,COBBLESTONE:0)
Block(6,5,-1,STONE:6)
Block(6,5,0,minecraft:red_glazed_terracotta:3)
Block(6,5,1,STAINED_CLAY:15)
Block(6,5,2,STONE:6)
Block(6,6,-2,STEP:5)
Block(6,6,-1,SMOOTH_STAIRS:2)
Block(6,6,2,SMOOTH_STAIRS:3)
Block(6,6,3,STEP:5)
Block(6,7,-1,STEP:0)
Block(6,7,2,STEP:0)
Block(6,10,-3,STEP:0)
Block(6,10,4,STEP:0)
Block(7,0,-1,STONE:6)
Block(7,0,0,STONE:6)
Block(7,0,1,STONE:6)
Block(7,0,2,STONE:6)
Block(7,1,-1,STONE:6)
Block(7,1,0,STONE:6)
Block(7,1,1,STONE:6)
Block(7,1,2,STONE:6)
Block(7,2,-1,COBBLESTONE_STAIRS:3)
Block(7,2,2,COBBLESTONE_STAIRS:2)
Block(7,3,-1,COBBLESTONE_STAIRS:7)
Block(7,3,2,COBBLESTONE_STAIRS:6)
Block(7,4,-1,COBBLESTONE:0)
Block(7,4,2,COBBLESTONE:0)
Block(7,5,-1,STONE:6)
Block(7,5,0,STAINED_CLAY:15)
Block(7,5,1,minecraft:red_glazed_terracotta)
Block(7,5,2,STONE:6)
Block(7,6,-2,STEP:5)
Block(7,6,-1,SMOOTH_STAIRS:2)
Block(7,6,2,SMOOTH_STAIRS:3)
Block(7,6,3,STEP:5)
Block(7,7,-1,STEP:0)
Block(7,7,2,STEP:0)
Block(7,10,-3,STEP:0)
Block(7,10,4,STEP:0)
Block(8,0,-1,STONE:6)
Block(8,0,0,STONE:6)
Block(8,0,1,STONE:6)
Block(8,0,2,STONE:6)
Block(8,1,-1,STONE:6)
Block(8,1,0,STONE:6)
Block(8,1,1,STONE:6)
Block(8,1,2,STONE:6)
Block(8,2,-1,STONE:6)
Block(8,2,0,COBBLESTONE_STAIRS:0)
Block(8,2,1,COBBLESTONE_STAIRS:0)
Block(8,2,2,STONE:6)
Block(8,3,-1,STONE:6)
Block(8,3,0,COBBLESTONE_STAIRS:4)
Block(8,3,1,COBBLESTONE_STAIRS:4)
Block(8,3,2,STONE:6)
Block(8,4,-1,STONE:6)
Block(8,4,0,COBBLESTONE:0)
Block(8,4,1,COBBLESTONE:0)
Block(8,4,2,STONE:6)
Block(8,5,-1,STONE:6)
Block(8,5,0,STONE:6)
Block(8,5,1,STONE:6)
Block(8,5,2,STONE:6)
Block(8,6,-2,STEP:5)
Block(8,6,-1,SMOOTH_STAIRS:1)
Block(8,6,0,SMOOTH_STAIRS:1)
Block(8,6,1,SMOOTH_STAIRS:1)
Block(8,6,2,SMOOTH_STAIRS:3)
Block(8,6,3,STEP:5)
Block(8,7,-1,STEP:0)
Block(8,7,0,STEP:0)
Block(8,7,1,STEP:0)
Block(8,7,2,STEP:0)
Block(8,10,-3,STEP:0)
Block(8,10,4,STEP:0)
Block(9,6,-2,STEP:5)
Block(9,6,-1,STEP:5)
Block(9,6,0,STEP:5)
Block(9,6,1,STEP:5)
Block(9,6,2,STEP:5)
Block(9,6,3,STEP:5)
Block(9,10,-3,STEP:0)
Block(9,10,4,STEP:0)
Block(10,10,-3,STEP:0)
Block(10,10,-2,STEP:0)
Block(10,10,-1,STEP:0)
Block(10,10,0,STEP:0)
Block(10,10,1,STEP:0)
Block(10,10,2,STEP:0)
Block(10,10,3,STEP:0)
Block(10,10,4,STEP:0)


Block(-5,7,-2,AIR:0)
Block(-5,7,-1,AIR:0)
Block(-5,7,0,AIR:0)
Block(-5,7,1,AIR:0)
Block(-5,7,2,AIR:0)
Block(-5,7,3,AIR:0)
Block(-5,8,-2,AIR:0)
Block(-5,8,-1,AIR:0)
Block(-5,8,0,AIR:0)
Block(-5,8,1,AIR:0)
Block(-5,8,2,AIR:0)
Block(-5,8,3,AIR:0)
Block(-5,9,-2,AIR:0)
Block(-5,9,-1,AIR:0)
Block(-5,9,0,AIR:0)
Block(-5,9,1,AIR:0)
Block(-5,9,2,AIR:0)
Block(-5,9,3,AIR:0)
Block(-5,10,-1,AIR:0)
Block(-5,10,0,AIR:0)
Block(-5,10,1,AIR:0)
Block(-5,10,2,AIR:0)
Block(-4,7,-3,AIR:0)
Block(-4,7,-1,AIR:0)
Block(-4,7,0,AIR:0)
Block(-4,7,1,AIR:0)
Block(-4,7,2,AIR:0)
Block(-4,7,3,AIR:0)
Block(-4,7,4,AIR:0)
Block(-4,8,-3,AIR:0)
Block(-4,8,-2,AIR:0)
Block(-4,8,-1,AIR:0)
Block(-4,8,0,AIR:0)
Block(-4,8,1,AIR:0)
Block(-4,8,2,AIR:0)
Block(-4,8,3,AIR:0)
Block(-4,8,4,AIR:0)
Block(-4,9,-3,AIR:0)
Block(-4,9,-2,AIR:0)
Block(-4,9,-1,AIR:0)
Block(-4,9,0,AIR:0)
Block(-4,9,1,AIR:0)
Block(-4,9,2,AIR:0)
Block(-4,9,3,AIR:0)
Block(-4,9,4,AIR:0)
Block(-4,10,-2,AIR:0)
Block(-4,10,-1,AIR:0)
Block(-4,10,0,AIR:0)
Block(-4,10,1,AIR:0)
Block(-4,10,2,AIR:0)
Block(-4,10,3,AIR:0)
Block(-3,1,0,AIR:0)
Block(-3,1,1,AIR:0)
Block(-3,2,-1,AIR:0)
Block(-3,2,0,AIR:0)
Block(-3,3,-1,AIR:0)
Block(-3,3,0,AIR:0)
Block(-3,3,2,AIR:0)
Block(-3,7,-3,AIR:0)
Block(-3,7,-2,AIR:0)
Block(-3,7,-1,AIR:0)
Block(-3,7,0,AIR:0)
Block(-3,7,1,AIR:0)
Block(-3,7,2,AIR:0)
Block(-3,7,3,AIR:0)
Block(-3,7,4,AIR:0)
Block(-3,8,-3,AIR:0)
Block(-3,8,-2,AIR:0)
Block(-3,8,-1,AIR:0)
Block(-3,8,0,AIR:0)
Block(-3,8,1,AIR:0)
Block(-3,8,2,AIR:0)
Block(-3,8,3,AIR:0)
Block(-3,8,4,AIR:0)
Block(-3,9,-3,AIR:0)
Block(-3,9,-2,AIR:0)
Block(-3,9,-1,AIR:0)
Block(-3,9,0,AIR:0)
Block(-3,9,1,AIR:0)
Block(-3,9,2,AIR:0)
Block(-3,9,3,AIR:0)
Block(-3,9,4,AIR:0)
Block(-3,10,-3,AIR:0)
Block(-3,10,-2,AIR:0)
Block(-3,10,-1,AIR:0)
Block(-3,10,0,AIR:0)
Block(-3,10,1,AIR:0)
Block(-3,10,2,AIR:0)
Block(-3,10,3,AIR:0)
Block(-3,10,4,AIR:0)
Block(-2,1,-1,AIR:0)
Block(-2,1,0,AIR:0)
Block(-2,1,1,AIR:0)
Block(-2,1,2,AIR:0)
Block(-2,2,0,AIR:0)
Block(-2,2,1,AIR:0)
Block(-2,2,2,AIR:0)
Block(-2,2,3,AIR:0)
Block(-2,2,4,AIR:0)
Block(-2,3,-1,AIR:0)
Block(-2,3,0,AIR:0)
Block(-2,3,1,AIR:0)
Block(-2,3,2,AIR:0)
Block(-2,4,-1,AIR:0)
Block(-2,4,0,AIR:0)
Block(-2,4,1,AIR:0)
Block(-2,7,-3,AIR:0)
Block(-2,7,-2,AIR:0)
Block(-2,7,-1,AIR:0)
Block(-2,7,2,AIR:0)
Block(-2,7,3,AIR:0)
Block(-2,7,4,AIR:0)
Block(-2,8,-3,AIR:0)
Block(-2,8,-2,AIR:0)
Block(-2,8,-1,AIR:0)
Block(-2,8,2,AIR:0)
Block(-2,8,3,AIR:0)
Block(-2,8,4,AIR:0)
Block(-2,9,-3,AIR:0)
Block(-2,9,-2,AIR:0)
Block(-2,9,-1,AIR:0)
Block(-2,9,0,AIR:0)
Block(-2,9,1,AIR:0)
Block(-2,9,2,AIR:0)
Block(-2,9,3,AIR:0)
Block(-2,9,4,AIR:0)
Block(-2,10,-3,AIR:0)
Block(-2,10,-2,AIR:0)
Block(-2,10,-1,AIR:0)
Block(-2,10,0,AIR:0)
Block(-2,10,1,AIR:0)
Block(-2,10,2,AIR:0)
Block(-2,10,3,AIR:0)
Block(-2,10,4,AIR:0)
Block(-1,1,1,AIR:0)
Block(-1,1,2,AIR:0)
Block(-1,2,-1,AIR:0)
Block(-1,2,0,AIR:0)
Block(-1,2,1,AIR:0)
Block(-1,2,2,AIR:0)
Block(-1,3,0,AIR:0)
Block(-1,3,1,AIR:0)
Block(-1,3,2,AIR:0)
Block(-1,4,0,AIR:0)
Block(-1,4,1,AIR:0)
Block(-1,7,-3,AIR:0)
Block(-1,7,-2,AIR:0)
Block(-1,7,-1,AIR:0)
Block(-1,7,2,AIR:0)
Block(-1,7,4,AIR:0)
Block(-1,8,-3,AIR:0)
Block(-1,8,-2,AIR:0)
Block(-1,8,-1,AIR:0)
Block(-1,8,2,AIR:0)
Block(-1,8,3,AIR:0)
Block(-1,8,4,AIR:0)
Block(-1,9,-3,AIR:0)
Block(-1,9,-2,AIR:0)
Block(-1,9,-1,AIR:0)
Block(-1,9,0,AIR:0)
Block(-1,9,1,AIR:0)
Block(-1,9,2,AIR:0)
Block(-1,9,3,AIR:0)
Block(-1,9,4,AIR:0)
Block(-1,10,-3,AIR:0)
Block(-1,10,-2,AIR:0)
Block(-1,10,-1,AIR:0)
Block(-1,10,0,AIR:0)
Block(-1,10,1,AIR:0)
Block(-1,10,2,AIR:0)
Block(-1,10,3,AIR:0)
Block(-1,10,4,AIR:0)
Block(0,1,-1,AIR:0)
Block(0,1,0,AIR:0)
Block(0,1,2,AIR:0)
Block(0,2,-1,AIR:0)
Block(0,2,0,AIR:0)
Block(0,2,1,AIR:0)
Block(0,2,2,AIR:0)
Block(0,3,-1,AIR:0)
Block(0,3,0,AIR:0)
Block(0,3,1,AIR:0)
Block(0,3,2,AIR:0)
Block(0,4,-1,AIR:0)
Block(0,4,0,AIR:0)
Block(0,4,1,AIR:0)
Block(0,7,-3,AIR:0)
Block(0,7,-1,AIR:0)
Block(0,7,2,AIR:0)
Block(0,7,3,AIR:0)
Block(0,7,4,AIR:0)
Block(0,8,-3,AIR:0)
Block(0,8,-2,AIR:0)
Block(0,8,-1,AIR:0)
Block(0,8,2,AIR:0)
Block(0,8,3,AIR:0)
Block(0,8,4,AIR:0)
Block(0,9,-3,AIR:0)
Block(0,9,-2,AIR:0)
Block(0,9,-1,AIR:0)
Block(0,9,0,AIR:0)
Block(0,9,1,AIR:0)
Block(0,9,2,AIR:0)
Block(0,9,3,AIR:0)
Block(0,9,4,AIR:0)
Block(0,10,-3,AIR:0)
Block(0,10,-2,AIR:0)
Block(0,10,-1,AIR:0)
Block(0,10,0,AIR:0)
Block(0,10,1,AIR:0)
Block(0,10,2,AIR:0)
Block(0,10,3,AIR:0)
Block(0,10,4,AIR:0)
Block(1,1,2,AIR:0)
Block(1,2,-1,AIR:0)
Block(1,2,0,AIR:0)
Block(1,2,1,AIR:0)
Block(1,3,0,AIR:0)
Block(1,3,1,AIR:0)
Block(1,3,2,AIR:0)
Block(1,4,2,AIR:0)
Block(1,7,-3,AIR:0)
Block(1,7,-2,AIR:0)
Block(1,7,-1,AIR:0)
Block(1,7,2,AIR:0)
Block(1,7,3,AIR:0)
Block(1,7,4,AIR:0)
Block(1,8,-3,AIR:0)
Block(1,8,-2,AIR:0)
Block(1,8,-1,AIR:0)
Block(1,8,2,AIR:0)
Block(1,8,3,AIR:0)
Block(1,8,4,AIR:0)
Block(1,9,-3,AIR:0)
Block(1,9,-2,AIR:0)
Block(1,9,-1,AIR:0)
Block(1,9,0,AIR:0)
Block(1,9,1,AIR:0)
Block(1,9,2,AIR:0)
Block(1,9,3,AIR:0)
Block(1,9,4,AIR:0)
Block(1,10,-3,AIR:0)
Block(1,10,-2,AIR:0)
Block(1,10,-1,AIR:0)
Block(1,10,0,AIR:0)
Block(1,10,1,AIR:0)
Block(1,10,2,AIR:0)
Block(1,10,3,AIR:0)
Block(1,10,4,AIR:0)
Block(2,2,0,AIR:0)
Block(2,2,1,AIR:0)
Block(2,2,2,AIR:0)
Block(2,3,-1,AIR:0)
Block(2,3,0,AIR:0)
Block(2,3,1,AIR:0)
Block(2,4,1,AIR:0)
Block(2,7,-3,AIR:0)
Block(2,7,-2,AIR:0)
Block(2,7,-1,AIR:0)
Block(2,7,0,AIR:0)
Block(2,7,1,AIR:0)
Block(2,7,2,AIR:0)
Block(2,7,3,AIR:0)
Block(2,7,4,AIR:0)
Block(2,8,-3,AIR:0)
Block(2,8,-2,AIR:0)
Block(2,8,-1,AIR:0)
Block(2,8,0,AIR:0)
Block(2,8,1,AIR:0)
Block(2,8,2,AIR:0)
Block(2,8,3,AIR:0)
Block(2,8,4,AIR:0)
Block(2,9,-3,AIR:0)
Block(2,9,-2,AIR:0)
Block(2,9,-1,AIR:0)
Block(2,9,0,AIR:0)
Block(2,9,1,AIR:0)
Block(2,9,2,AIR:0)
Block(2,9,3,AIR:0)
Block(2,9,4,AIR:0)
Block(2,10,-3,AIR:0)
Block(2,10,-2,AIR:0)
Block(2,10,-1,AIR:0)
Block(2,10,0,AIR:0)
Block(2,10,1,AIR:0)
Block(2,10,2,AIR:0)
Block(2,10,3,AIR:0)
Block(2,10,4,AIR:0)
Block(3,1,0,AIR:0)
Block(3,1,1,AIR:0)
Block(3,2,0,AIR:0)
Block(3,3,0,AIR:0)
Block(3,3,1,AIR:0)
Block(3,7,-3,AIR:0)
Block(3,7,-2,AIR:0)
Block(3,7,-1,AIR:0)
Block(3,7,1,AIR:0)
Block(3,7,2,AIR:0)
Block(3,7,4,AIR:0)
Block(3,8,-3,AIR:0)
Block(3,8,-2,AIR:0)
Block(3,8,-1,AIR:0)
Block(3,8,0,AIR:0)
Block(3,8,1,AIR:0)
Block(3,8,2,AIR:0)
Block(3,8,3,AIR:0)
Block(3,8,4,AIR:0)
Block(3,9,-3,AIR:0)
Block(3,9,-2,AIR:0)
Block(3,9,-1,AIR:0)
Block(3,9,0,AIR:0)
Block(3,9,1,AIR:0)
Block(3,9,2,AIR:0)
Block(3,9,3,AIR:0)
Block(3,9,4,AIR:0)
Block(3,10,-2,AIR:0)
Block(3,10,-1,AIR:0)
Block(3,10,0,AIR:0)
Block(3,10,1,AIR:0)
Block(3,10,2,AIR:0)
Block(3,10,3,AIR:0)
Block(4,1,0,AIR:0)
Block(4,2,0,AIR:0)
Block(4,2,1,AIR:0)
Block(4,7,-2,AIR:0)
Block(4,7,-1,AIR:0)
Block(4,7,0,AIR:0)
Block(4,7,1,AIR:0)
Block(4,7,2,AIR:0)
Block(4,7,3,AIR:0)
Block(4,8,-2,AIR:0)
Block(4,8,-1,AIR:0)
Block(4,8,0,AIR:0)
Block(4,8,1,AIR:0)
Block(4,8,2,AIR:0)
Block(4,8,3,AIR:0)
Block(4,9,-2,AIR:0)
Block(4,9,-1,AIR:0)
Block(4,9,0,AIR:0)
Block(4,9,1,AIR:0)
Block(4,9,2,AIR:0)
Block(4,9,3,AIR:0)
Block(4,10,-1,AIR:0)
Block(4,10,0,AIR:0)
Block(4,10,1,AIR:0)
Block(4,10,2,AIR:0)
Block(5,2,0,AIR:0)
Block(5,2,1,AIR:0)
Block(5,7,-2,AIR:0)
Block(5,7,3,AIR:0)
Block(5,8,-2,AIR:0)
Block(5,8,-1,AIR:0)
Block(5,8,0,AIR:0)
Block(5,8,1,AIR:0)
Block(5,8,2,AIR:0)
Block(5,8,3,AIR:0)
Block(5,9,-2,AIR:0)
Block(5,9,-1,AIR:0)
Block(5,9,0,AIR:0)
Block(5,9,1,AIR:0)
Block(5,9,2,AIR:0)
Block(5,9,3,AIR:0)
Block(5,10,-2,AIR:0)
Block(5,10,-1,AIR:0)
Block(5,10,0,AIR:0)
Block(5,10,1,AIR:0)
Block(5,10,2,AIR:0)
Block(5,10,3,AIR:0)
Block(6,2,0,AIR:0)
Block(6,2,1,AIR:0)
Block(6,3,0,AIR:0)
Block(6,3,1,AIR:0)
Block(6,4,0,AIR:0)
Block(6,4,1,AIR:0)
Block(6,6,0,AIR:0)
Block(6,6,1,AIR:0)
Block(6,7,-2,AIR:0)
Block(6,7,0,AIR:0)
Block(6,7,1,AIR:0)
Block(6,7,3,AIR:0)
Block(6,8,-2,AIR:0)
Block(6,8,-1,AIR:0)
Block(6,8,0,AIR:0)
Block(6,8,1,AIR:0)
Block(6,8,2,AIR:0)
Block(6,8,3,AIR:0)
Block(6,9,-2,AIR:0)
Block(6,9,-1,AIR:0)
Block(6,9,0,AIR:0)
Block(6,9,1,AIR:0)
Block(6,9,2,AIR:0)
Block(6,9,3,AIR:0)
Block(6,10,-2,AIR:0)
Block(6,10,-1,AIR:0)
Block(6,10,0,AIR:0)
Block(6,10,1,AIR:0)
Block(6,10,2,AIR:0)
Block(6,10,3,AIR:0)
Block(7,2,0,AIR:0)
Block(7,2,1,AIR:0)
Block(7,3,0,AIR:0)
Block(7,3,1,AIR:0)
Block(7,4,0,AIR:0)
Block(7,4,1,AIR:0)
Block(7,6,0,AIR:0)
Block(7,6,1,AIR:0)
Block(7,7,-2,AIR:0)
Block(7,7,0,AIR:0)
Block(7,7,1,AIR:0)
Block(7,7,3,AIR:0)
Block(7,8,-2,AIR:0)
Block(7,8,-1,AIR:0)
Block(7,8,0,AIR:0)
Block(7,8,1,AIR:0)
Block(7,8,2,AIR:0)
Block(7,8,3,AIR:0)
Block(7,9,-2,AIR:0)
Block(7,9,-1,AIR:0)
Block(7,9,0,AIR:0)
Block(7,9,1,AIR:0)
Block(7,9,2,AIR:0)
Block(7,9,3,AIR:0)
Block(7,10,-2,AIR:0)
Block(7,10,-1,AIR:0)
Block(7,10,0,AIR:0)
Block(7,10,1,AIR:0)
Block(7,10,2,AIR:0)
Block(7,10,3,AIR:0)
Block(8,7,-2,AIR:0)
Block(8,7,3,AIR:0)
Block(8,8,-2,AIR:0)
Block(8,8,-1,AIR:0)
Block(8,8,0,AIR:0)
Block(8,8,1,AIR:0)
Block(8,8,2,AIR:0)
Block(8,8,3,AIR:0)
Block(8,9,-2,AIR:0)
Block(8,9,-1,AIR:0)
Block(8,9,0,AIR:0)
Block(8,9,1,AIR:0)
Block(8,9,2,AIR:0)
Block(8,9,3,AIR:0)
Block(8,10,-2,AIR:0)
Block(8,10,-1,AIR:0)
Block(8,10,0,AIR:0)
Block(8,10,1,AIR:0)
Block(8,10,2,AIR:0)
Block(8,10,3,AIR:0)
Block(9,7,-2,AIR:0)
Block(9,7,-1,AIR:0)
Block(9,7,0,AIR:0)
Block(9,7,1,AIR:0)
Block(9,7,2,AIR:0)
Block(9,7,3,AIR:0)
Block(9,8,-2,AIR:0)
Block(9,8,-1,AIR:0)
Block(9,8,0,AIR:0)
Block(9,8,1,AIR:0)
Block(9,8,2,AIR:0)
Block(9,8,3,AIR:0)
Block(9,9,-2,AIR:0)
Block(9,9,-1,AIR:0)
Block(9,9,0,AIR:0)
Block(9,9,1,AIR:0)
Block(9,9,2,AIR:0)
Block(9,9,3,AIR:0)
Block(9,10,-2,AIR:0)
Block(9,10,-1,AIR:0)
Block(9,10,0,AIR:0)
Block(9,10,1,AIR:0)
Block(9,10,2,AIR:0)
Block(9,10,3,AIR:0)
Block(-8,10,0,AIR:0)
Block(-8,10,1,AIR:0)
Block(-7,9,0,AIR:0)
Block(-7,9,1,AIR:0)
Block(-7,10,0,AIR:0)
Block(-7,10,1,AIR:0)
Block(-6,9,0,AIR:0)
Block(-6,9,1,AIR:0)
Block(-6,10,0,AIR:0)
Block(-6,10,1,AIR:0)
Block(-6,8,0,AIR:0)
Block(-6,8,1,AIR:0)

Block(-5,11,-1,AIR:0)
Block(-5,11,0,AIR:0)
Block(-5,11,1,AIR:0)
Block(-5,11,2,AIR:0)
Block(-4,11,-2,AIR:0)
Block(-4,11,-1,AIR:0)
Block(-4,11,0,AIR:0)
Block(-4,11,1,AIR:0)
Block(-4,11,2,AIR:0)
Block(-4,11,3,AIR:0)
Block(-3,11,-3,AIR:0)
Block(-3,11,-2,AIR:0)
Block(-3,11,-1,AIR:0)
Block(-3,11,0,AIR:0)
Block(-3,11,1,AIR:0)
Block(-3,11,2,AIR:0)
Block(-3,11,3,AIR:0)
Block(-3,11,4,AIR:0)
Block(-2,11,-3,AIR:0)
Block(-2,11,-2,AIR:0)
Block(-2,11,-1,AIR:0)
Block(-2,11,0,AIR:0)
Block(-2,11,1,AIR:0)
Block(-2,11,2,AIR:0)
Block(-2,11,3,AIR:0)
Block(-2,11,4,AIR:0)
Block(-1,11,-3,AIR:0)
Block(-1,11,-2,AIR:0)
Block(-1,11,-1,AIR:0)
Block(-1,11,0,AIR:0)
Block(-1,11,1,AIR:0)
Block(-1,11,2,AIR:0)
Block(-1,11,3,AIR:0)
Block(-1,11,4,AIR:0)
Block(0,11,-3,AIR:0)
Block(0,11,-2,AIR:0)
Block(0,11,-1,AIR:0)
Block(0,11,0,AIR:0)
Block(0,11,1,AIR:0)
Block(0,11,2,AIR:0)
Block(0,11,3,AIR:0)
Block(0,11,4,AIR:0)
Block(1,11,-3,AIR:0)
Block(1,11,-2,AIR:0)
Block(1,11,-1,AIR:0)
Block(1,11,0,AIR:0)
Block(1,11,1,AIR:0)
Block(1,11,2,AIR:0)
Block(1,11,3,AIR:0)
Block(1,11,4,AIR:0)
Block(2,11,-3,AIR:0)
Block(2,11,-2,AIR:0)
Block(2,11,-1,AIR:0)
Block(2,11,0,AIR:0)
Block(2,11,1,AIR:0)
Block(2,11,2,AIR:0)
Block(2,11,3,AIR:0)
Block(2,11,4,AIR:0)
Block(3,11,-2,AIR:0)
Block(3,11,-1,AIR:0)
Block(3,11,0,AIR:0)
Block(3,11,1,AIR:0)
Block(3,11,2,AIR:0)
Block(3,11,3,AIR:0)
Block(4,11,-1,AIR:0)
Block(4,11,0,AIR:0)
Block(4,11,1,AIR:0)
Block(4,11,2,AIR:0)
Block(5,11,-2,AIR:0)
Block(5,11,-1,AIR:0)
Block(5,11,0,AIR:0)
Block(5,11,1,AIR:0)
Block(5,11,2,AIR:0)
Block(5,11,3,AIR:0)
Block(6,11,-2,AIR:0)
Block(6,11,-1,AIR:0)
Block(6,11,0,AIR:0)
Block(6,11,1,AIR:0)
Block(6,11,2,AIR:0)
Block(6,11,3,AIR:0)
Block(7,11,-2,AIR:0)
Block(7,11,-1,AIR:0)
Block(7,11,0,AIR:0)
Block(7,11,1,AIR:0)
Block(7,11,2,AIR:0)
Block(7,11,3,AIR:0)
Block(8,11,-2,AIR:0)
Block(8,11,-1,AIR:0)
Block(8,11,0,AIR:0)
Block(8,11,1,AIR:0)
Block(8,11,2,AIR:0)
Block(8,11,3,AIR:0)
Block(9,11,-2,AIR:0)
Block(9,11,-1,AIR:0)
Block(9,11,0,AIR:0)
Block(9,11,1,AIR:0)
Block(9,11,2,AIR:0)
Block(9,11,3,AIR:0)
Block(-8,11,0,AIR:0)
Block(-8,11,1,AIR:0)
Block(-7,11,0,AIR:0)
Block(-7,11,1,AIR:0)
Block(-6,11,0,AIR:0)
Block(-6,11,1,AIR:0)
Block(-5,12,-1,AIR:0)
Block(-5,12,0,AIR:0)
Block(-5,12,1,AIR:0)
Block(-5,12,2,AIR:0)
Block(-4,12,-2,AIR:0)
Block(-4,12,-1,AIR:0)
Block(-4,12,0,AIR:0)
Block(-4,12,1,AIR:0)
Block(-4,12,2,AIR:0)
Block(-4,12,3,AIR:0)
Block(-3,12,-3,AIR:0)
Block(-3,12,-2,AIR:0)
Block(-3,12,-1,AIR:0)
Block(-3,12,0,AIR:0)
Block(-3,12,1,AIR:0)
Block(-3,12,2,AIR:0)
Block(-3,12,3,AIR:0)
Block(-3,12,4,AIR:0)
Block(-2,12,-3,AIR:0)
Block(-2,12,-2,AIR:0)
Block(-2,12,-1,AIR:0)
Block(-2,12,0,AIR:0)
Block(-2,12,1,AIR:0)
Block(-2,12,2,AIR:0)
Block(-2,12,3,AIR:0)
Block(-2,12,4,AIR:0)
Block(-1,12,-3,AIR:0)
Block(-1,12,-2,AIR:0)
Block(-1,12,-1,AIR:0)
Block(-1,12,0,AIR:0)
Block(-1,12,1,AIR:0)
Block(-1,12,2,AIR:0)
Block(-1,12,3,AIR:0)
Block(-1,12,4,AIR:0)
Block(0,12,-3,AIR:0)
Block(0,12,-2,AIR:0)
Block(0,12,-1,AIR:0)
Block(0,12,0,AIR:0)
Block(0,12,1,AIR:0)
Block(0,12,2,AIR:0)
Block(0,12,3,AIR:0)
Block(0,12,4,AIR:0)
Block(1,12,-3,AIR:0)
Block(1,12,-2,AIR:0)
Block(1,12,-1,AIR:0)
Block(1,12,0,AIR:0)
Block(1,12,1,AIR:0)
Block(1,12,2,AIR:0)
Block(1,12,3,AIR:0)
Block(1,12,4,AIR:0)
Block(2,12,-3,AIR:0)
Block(2,12,-2,AIR:0)
Block(2,12,-1,AIR:0)
Block(2,12,0,AIR:0)
Block(2,12,1,AIR:0)
Block(2,12,2,AIR:0)
Block(2,12,3,AIR:0)
Block(2,12,4,AIR:0)
Block(3,12,-2,AIR:0)
Block(3,12,-1,AIR:0)
Block(3,12,0,AIR:0)
Block(3,12,1,AIR:0)
Block(3,12,2,AIR:0)
Block(3,12,3,AIR:0)
Block(4,12,-1,AIR:0)
Block(4,12,0,AIR:0)
Block(4,12,1,AIR:0)
Block(4,12,2,AIR:0)
Block(5,12,-2,AIR:0)
Block(5,12,-1,AIR:0)
Block(5,12,0,AIR:0)
Block(5,12,1,AIR:0)
Block(5,12,2,AIR:0)
Block(5,12,3,AIR:0)
Block(6,12,-2,AIR:0)
Block(6,12,-1,AIR:0)
Block(6,12,0,AIR:0)
Block(6,12,1,AIR:0)
Block(6,12,2,AIR:0)
Block(6,12,3,AIR:0)
Block(7,12,-2,AIR:0)
Block(7,12,-1,AIR:0)
Block(7,12,0,AIR:0)
Block(7,12,1,AIR:0)
Block(7,12,2,AIR:0)
Block(7,12,3,AIR:0)
Block(8,12,-2,AIR:0)
Block(8,12,-1,AIR:0)
Block(8,12,0,AIR:0)
Block(8,12,1,AIR:0)
Block(8,12,2,AIR:0)
Block(8,12,3,AIR:0)
Block(9,12,-2,AIR:0)
Block(9,12,-1,AIR:0)
Block(9,12,0,AIR:0)
Block(9,12,1,AIR:0)
Block(9,12,2,AIR:0)
Block(9,12,3,AIR:0)
Block(-8,12,0,AIR:0)
Block(-8,12,1,AIR:0)
Block(-7,12,0,AIR:0)
Block(-7,12,1,AIR:0)
Block(-6,12,0,AIR:0)
Block(-6,12,1,AIR:0)

Block(-9,11,-1,AIR:0)
Block(-9,11,2,AIR:0)
Block(-8,11,-1,AIR:0)
Block(-8,11,2,AIR:0)
Block(-7,11,-1,AIR:0)
Block(-7,11,2,AIR:0)
Block(-6,11,-4,AIR:0)
Block(-6,11,-3,AIR:0)
Block(-6,11,-2,AIR:0)
Block(-6,11,-1,AIR:0)
Block(-6,11,2,AIR:0)
Block(-6,11,3,AIR:0)
Block(-6,11,4,AIR:0)
Block(-6,11,5,AIR:0)
Block(-5,11,-4,AIR:0)
Block(-5,11,5,AIR:0)
Block(-4,11,-4,AIR:0)
Block(-4,11,5,AIR:0)
Block(-3,11,-4,AIR:0)
Block(-3,11,5,AIR:0)
Block(-2,11,-4,AIR:0)
Block(-2,11,5,AIR:0)
Block(-1,11,-4,AIR:0)
Block(-1,11,5,AIR:0)
Block(0,11,-4,AIR:0)
Block(0,11,5,AIR:0)
Block(1,11,-4,AIR:0)
Block(1,11,5,AIR:0)
Block(2,11,-4,AIR:0)
Block(2,11,5,AIR:0)
Block(3,11,-4,AIR:0)
Block(3,11,5,AIR:0)
Block(4,11,-4,AIR:0)
Block(4,11,5,AIR:0)
Block(5,11,-4,AIR:0)
Block(5,11,-3,AIR:0)
Block(5,11,4,AIR:0)
Block(5,11,5,AIR:0)
Block(6,11,-3,AIR:0)
Block(6,11,4,AIR:0)
Block(7,11,-3,AIR:0)
Block(7,11,4,AIR:0)
Block(8,11,-3,AIR:0)
Block(8,11,4,AIR:0)
Block(9,11,-3,AIR:0)
Block(9,11,4,AIR:0)
Block(10,11,-3,AIR:0)
Block(10,11,-2,AIR:0)
Block(10,11,-1,AIR:0)
Block(10,11,0,AIR:0)
Block(10,11,1,AIR:0)
Block(10,11,2,AIR:0)
Block(10,11,3,AIR:0)
Block(10,11,4,AIR:0)


RandomBlock(-9,6,-1,STAINED_GLASS:14,15,CONCRETE:6,25,CONCRETE:14,25,minecraft:red_glazed_terracotta:0,30,STAINED_CLAY:15,50,STAINED_CLAY:15,100)
RandomBlock(-9,6,2,STAINED_GLASS:14,15,CONCRETE:6,25,CONCRETE:14,25,minecraft:red_glazed_terracotta:0,30,STAINED_CLAY:15,50,STAINED_CLAY:15,100)
RandomBlock(-9,7,-1,STAINED_GLASS:14,15,CONCRETE:6,25,CONCRETE:14,25,minecraft:red_glazed_terracotta:0,30,STAINED_CLAY:15,50,STAINED_CLAY:15,100)
RandomBlock(-9,7,2,STAINED_GLASS:14,15,CONCRETE:6,25,CONCRETE:14,25,minecraft:red_glazed_terracotta:0,30,STAINED_CLAY:15,50,STAINED_CLAY:15,100)
RandomBlock(-9,8,-1,STAINED_GLASS:14,15,CONCRETE:6,25,CONCRETE:14,25,minecraft:red_glazed_terracotta:0,30,STAINED_CLAY:15,50,STAINED_CLAY:15,100)
RandomBlock(-9,8,2,STAINED_GLASS:14,15,CONCRETE:6,25,CONCRETE:14,25,minecraft:red_glazed_terracotta:0,30,STAINED_CLAY:15,50,STAINED_CLAY:15,100)
RandomBlock(-9,9,-1,STAINED_GLASS:14,15,CONCRETE:6,25,CONCRETE:14,25,minecraft:red_glazed_terracotta:0,30,STAINED_CLAY:15,50,STAINED_CLAY:15,100)
RandomBlock(-9,9,2,STAINED_GLASS:14,15,CONCRETE:6,25,CONCRETE:14,25,minecraft:red_glazed_terracotta:0,30,STAINED_CLAY:15,50,STAINED_CLAY:15,100)
RandomBlock(-8,6,-1,STAINED_GLASS:14,15,CONCRETE:6,25,CONCRETE:14,25,minecraft:red_glazed_terracotta:0,30,STAINED_CLAY:15,50,STAINED_CLAY:15,100)
RandomBlock(-8,6,2,STAINED_GLASS:14,15,CONCRETE:6,25,CONCRETE:14,25,minecraft:red_glazed_terracotta:0,30,STAINED_CLAY:15,50,STAINED_CLAY:15,100)
RandomBlock(-8,7,-1,STAINED_GLASS:14,15,CONCRETE:6,25,CONCRETE:14,25,minecraft:red_glazed_terracotta:0,30,STAINED_CLAY:15,50,STAINED_CLAY:15,100)
RandomBlock(-8,7,2,STAINED_GLASS:14,15,CONCRETE:6,25,CONCRETE:14,25,minecraft:red_glazed_terracotta:0,30,STAINED_CLAY:15,50,STAINED_CLAY:15,100)
RandomBlock(-8,8,-1,STAINED_GLASS:14,15,CONCRETE:6,25,CONCRETE:14,25,minecraft:red_glazed_terracotta:0,30,STAINED_CLAY:15,50,STAINED_CLAY:15,100)
RandomBlock(-8,8,2,STAINED_GLASS:14,15,CONCRETE:6,25,CONCRETE:14,25,minecraft:red_glazed_terracotta:0,30,STAINED_CLAY:15,50,STAINED_CLAY:15,100)
RandomBlock(-8,9,-1,STAINED_GLASS:14,15,CONCRETE:6,25,CONCRETE:14,25,minecraft:red_glazed_terracotta:0,30,STAINED_CLAY:15,50,STAINED_CLAY:15,100)
RandomBlock(-8,9,2,STAINED_GLASS:14,15,CONCRETE:6,25,CONCRETE:14,25,minecraft:red_glazed_terracotta:0,30,STAINED_CLAY:15,50,STAINED_CLAY:15,100)
RandomBlock(-7,6,-1,STAINED_GLASS:14,15,CONCRETE:6,25,CONCRETE:14,25,minecraft:red_glazed_terracotta:0,30,STAINED_CLAY:15,50,STAINED_CLAY:15,100)
RandomBlock(-7,6,2,STAINED_GLASS:14,15,CONCRETE:6,25,CONCRETE:14,25,minecraft:red_glazed_terracotta:0,30,STAINED_CLAY:15,50,STAINED_CLAY:15,100)
RandomBlock(-7,7,-1,STAINED_GLASS:14,15,CONCRETE:6,25,CONCRETE:14,25,minecraft:red_glazed_terracotta:0,30,STAINED_CLAY:15,50,STAINED_CLAY:15,100)
RandomBlock(-7,7,2,STAINED_GLASS:14,15,CONCRETE:6,25,CONCRETE:14,25,minecraft:red_glazed_terracotta:0,30,STAINED_CLAY:15,50,STAINED_CLAY:15,100)
RandomBlock(-7,8,-1,STAINED_GLASS:14,15,CONCRETE:6,25,CONCRETE:14,25,minecraft:red_glazed_terracotta:0,30,STAINED_CLAY:15,50,STAINED_CLAY:15,100)
RandomBlock(-7,8,2,STAINED_GLASS:14,15,CONCRETE:6,25,CONCRETE:14,25,minecraft:red_glazed_terracotta:0,30,STAINED_CLAY:15,50,STAINED_CLAY:15,100)
RandomBlock(-7,9,-1,STAINED_GLASS:14,15,CONCRETE:6,25,CONCRETE:14,25,minecraft:red_glazed_terracotta:0,30,STAINED_CLAY:15,50,STAINED_CLAY:15,100)
RandomBlock(-7,9,2,STAINED_GLASS:14,15,CONCRETE:6,25,CONCRETE:14,25,minecraft:red_glazed_terracotta:0,30,STAINED_CLAY:15,50,STAINED_CLAY:15,100)
RandomBlock(-6,6,-4,STAINED_GLASS:14,15,CONCRETE:6,25,CONCRETE:14,25,minecraft:red_glazed_terracotta:0,30,STAINED_CLAY:15,50,STAINED_CLAY:15,100)
RandomBlock(-6,6,-3,STAINED_GLASS:14,15,CONCRETE:6,25,CONCRETE:14,25,minecraft:red_glazed_terracotta:0,30,STAINED_CLAY:15,50,STAINED_CLAY:15,100)
RandomBlock(-6,6,-2,STAINED_GLASS:14,15,CONCRETE:6,25,CONCRETE:14,25,minecraft:red_glazed_terracotta:0,30,STAINED_CLAY:15,50,STAINED_CLAY:15,100)
RandomBlock(-6,6,-1,STAINED_GLASS:14,15,CONCRETE:6,25,CONCRETE:14,25,minecraft:red_glazed_terracotta:0,30,STAINED_CLAY:15,50,STAINED_CLAY:15,100)
RandomBlock(-6,6,2,STAINED_GLASS:14,15,CONCRETE:6,25,CONCRETE:14,25,minecraft:red_glazed_terracotta:0,30,STAINED_CLAY:15,50,STAINED_CLAY:15,100)
RandomBlock(-6,6,3,STAINED_GLASS:14,15,CONCRETE:6,25,CONCRETE:14,25,minecraft:red_glazed_terracotta:0,30,STAINED_CLAY:15,50,STAINED_CLAY:15,100)
RandomBlock(-6,6,4,STAINED_GLASS:14,15,CONCRETE:6,25,CONCRETE:14,25,minecraft:red_glazed_terracotta:0,30,STAINED_CLAY:15,50,STAINED_CLAY:15,100)
RandomBlock(-6,6,5,STAINED_GLASS:14,15,CONCRETE:6,25,CONCRETE:14,25,minecraft:red_glazed_terracotta:0,30,STAINED_CLAY:15,50,STAINED_CLAY:15,100)
RandomBlock(-6,7,-4,STAINED_GLASS:14,15,CONCRETE:6,25,CONCRETE:14,25,minecraft:red_glazed_terracotta:0,30,STAINED_CLAY:15,50,STAINED_CLAY:15,100)
RandomBlock(-6,7,-3,STAINED_GLASS:14,15,CONCRETE:6,25,CONCRETE:14,25,minecraft:red_glazed_terracotta:0,30,STAINED_CLAY:15,50,STAINED_CLAY:15,100)
RandomBlock(-6,7,-2,STAINED_GLASS:14,15,CONCRETE:6,25,CONCRETE:14,25,minecraft:red_glazed_terracotta:0,30,STAINED_CLAY:15,50,STAINED_CLAY:15,100)
RandomBlock(-6,7,-1,STAINED_GLASS:14,15,CONCRETE:6,25,CONCRETE:14,25,minecraft:red_glazed_terracotta:0,30,STAINED_CLAY:15,50,STAINED_CLAY:15,100)
RandomBlock(-6,7,2,STAINED_GLASS:14,15,CONCRETE:6,25,CONCRETE:14,25,minecraft:red_glazed_terracotta:0,30,STAINED_CLAY:15,50,STAINED_CLAY:15,100)
RandomBlock(-6,7,3,STAINED_GLASS:14,15,CONCRETE:6,25,CONCRETE:14,25,minecraft:red_glazed_terracotta:0,30,STAINED_CLAY:15,50,STAINED_CLAY:15,100)
RandomBlock(-6,7,4,STAINED_GLASS:14,15,CONCRETE:6,25,CONCRETE:14,25,minecraft:red_glazed_terracotta:0,30,STAINED_CLAY:15,50,STAINED_CLAY:15,100)
RandomBlock(-6,7,5,STAINED_GLASS:14,15,CONCRETE:6,25,CONCRETE:14,25,minecraft:red_glazed_terracotta:0,30,STAINED_CLAY:15,50,STAINED_CLAY:15,100)
RandomBlock(-6,8,-4,STAINED_GLASS:14,15,CONCRETE:6,25,CONCRETE:14,25,minecraft:red_glazed_terracotta:0,30,STAINED_CLAY:15,50,STAINED_CLAY:15,100)
RandomBlock(-6,8,-3,STAINED_GLASS:14,15,CONCRETE:6,25,CONCRETE:14,25,minecraft:red_glazed_terracotta:0,30,STAINED_CLAY:15,50,STAINED_CLAY:15,100)
RandomBlock(-6,8,-2,STAINED_GLASS:14,15,CONCRETE:6,25,CONCRETE:14,25,minecraft:red_glazed_terracotta:0,30,STAINED_CLAY:15,50,STAINED_CLAY:15,100)
RandomBlock(-6,8,-1,STAINED_GLASS:14,15,CONCRETE:6,25,CONCRETE:14,25,minecraft:red_glazed_terracotta:0,30,STAINED_CLAY:15,50,STAINED_CLAY:15,100)
RandomBlock(-6,8,2,STAINED_GLASS:14,15,CONCRETE:6,25,CONCRETE:14,25,minecraft:red_glazed_terracotta:0,30,STAINED_CLAY:15,50,STAINED_CLAY:15,100)
RandomBlock(-6,8,3,STAINED_GLASS:14,15,CONCRETE:6,25,CONCRETE:14,25,minecraft:red_glazed_terracotta:0,30,STAINED_CLAY:15,50,STAINED_CLAY:15,100)
RandomBlock(-6,8,4,STAINED_GLASS:14,15,CONCRETE:6,25,CONCRETE:14,25,minecraft:red_glazed_terracotta:0,30,STAINED_CLAY:15,50,STAINED_CLAY:15,100)
RandomBlock(-6,8,5,STAINED_GLASS:14,15,CONCRETE:6,25,CONCRETE:14,25,minecraft:red_glazed_terracotta:0,30,STAINED_CLAY:15,50,STAINED_CLAY:15,100)
RandomBlock(-6,9,-4,STAINED_GLASS:14,15,CONCRETE:6,25,CONCRETE:14,25,minecraft:red_glazed_terracotta:0,30,STAINED_CLAY:15,50,STAINED_CLAY:15,100)
RandomBlock(-6,9,-3,STAINED_GLASS:14,15,CONCRETE:6,25,CONCRETE:14,25,minecraft:red_glazed_terracotta:0,30,STAINED_CLAY:15,50,STAINED_CLAY:15,100)
RandomBlock(-6,9,-2,STAINED_GLASS:14,15,CONCRETE:6,25,CONCRETE:14,25,minecraft:red_glazed_terracotta:0,30,STAINED_CLAY:15,50,STAINED_CLAY:15,100)
RandomBlock(-6,9,-1,STAINED_GLASS:14,15,CONCRETE:6,25,CONCRETE:14,25,minecraft:red_glazed_terracotta:0,30,STAINED_CLAY:15,50,STAINED_CLAY:15,100)
RandomBlock(-6,9,2,STAINED_GLASS:14,15,CONCRETE:6,25,CONCRETE:14,25,minecraft:red_glazed_terracotta:0,30,STAINED_CLAY:15,50,STAINED_CLAY:15,100)
RandomBlock(-6,9,3,STAINED_GLASS:14,15,CONCRETE:6,25,CONCRETE:14,25,minecraft:red_glazed_terracotta:0,30,STAINED_CLAY:15,50,STAINED_CLAY:15,100)
RandomBlock(-6,9,4,STAINED_GLASS:14,15,CONCRETE:6,25,CONCRETE:14,25,minecraft:red_glazed_terracotta:0,30,STAINED_CLAY:15,50,STAINED_CLAY:15,100)
RandomBlock(-6,9,5,STAINED_GLASS:14,15,CONCRETE:6,25,CONCRETE:14,25,minecraft:red_glazed_terracotta:0,30,STAINED_CLAY:15,50,STAINED_CLAY:15,100)
RandomBlock(-5,6,-4,STAINED_GLASS:14,15,CONCRETE:6,25,CONCRETE:14,25,minecraft:red_glazed_terracotta:0,30,STAINED_CLAY:15,50,STAINED_CLAY:15,100)
RandomBlock(-5,6,5,STAINED_GLASS:14,15,CONCRETE:6,25,CONCRETE:14,25,minecraft:red_glazed_terracotta:0,30,STAINED_CLAY:15,50,STAINED_CLAY:15,100)
RandomBlock(-5,7,-4,STAINED_GLASS:14,15,CONCRETE:6,25,CONCRETE:14,25,minecraft:red_glazed_terracotta:0,30,STAINED_CLAY:15,50,STAINED_CLAY:15,100)
RandomBlock(-5,7,5,STAINED_GLASS:14,15,CONCRETE:6,25,CONCRETE:14,25,minecraft:red_glazed_terracotta:0,30,STAINED_CLAY:15,50,STAINED_CLAY:15,100)
RandomBlock(-5,8,-4,STAINED_GLASS:14,15,CONCRETE:6,25,CONCRETE:14,25,minecraft:red_glazed_terracotta:0,30,STAINED_CLAY:15,50,STAINED_CLAY:15,100)
RandomBlock(-5,8,5,STAINED_GLASS:14,15,CONCRETE:6,25,CONCRETE:14,25,minecraft:red_glazed_terracotta:0,30,STAINED_CLAY:15,50,STAINED_CLAY:15,100)
RandomBlock(-5,9,-4,STAINED_GLASS:14,15,CONCRETE:6,25,CONCRETE:14,25,minecraft:red_glazed_terracotta:0,30,STAINED_CLAY:15,50,STAINED_CLAY:15,100)
RandomBlock(-5,9,5,STAINED_GLASS:14,15,CONCRETE:6,25,CONCRETE:14,25,minecraft:red_glazed_terracotta:0,30,STAINED_CLAY:15,50,STAINED_CLAY:15,100)
RandomBlock(-4,6,-4,STAINED_GLASS:14,15,CONCRETE:6,25,CONCRETE:14,25,minecraft:red_glazed_terracotta:0,30,STAINED_CLAY:15,50,STAINED_CLAY:15,100)
RandomBlock(-4,6,5,STAINED_GLASS:14,15,CONCRETE:6,25,CONCRETE:14,25,minecraft:red_glazed_terracotta:0,30,STAINED_CLAY:15,50,STAINED_CLAY:15,100)
RandomBlock(-4,7,-4,STAINED_GLASS:14,15,CONCRETE:6,25,CONCRETE:14,25,minecraft:red_glazed_terracotta:0,30,STAINED_CLAY:15,50,STAINED_CLAY:15,100)
RandomBlock(-4,7,5,STAINED_GLASS:14,15,CONCRETE:6,25,CONCRETE:14,25,minecraft:red_glazed_terracotta:0,30,STAINED_CLAY:15,50,STAINED_CLAY:15,100)
RandomBlock(-4,8,-4,STAINED_GLASS:14,15,CONCRETE:6,25,CONCRETE:14,25,minecraft:red_glazed_terracotta:0,30,STAINED_CLAY:15,50,STAINED_CLAY:15,100)
RandomBlock(-4,8,5,STAINED_GLASS:14,15,CONCRETE:6,25,CONCRETE:14,25,minecraft:red_glazed_terracotta:0,30,STAINED_CLAY:15,50,STAINED_CLAY:15,100)
RandomBlock(-4,9,-4,STAINED_GLASS:14,15,CONCRETE:6,25,CONCRETE:14,25,minecraft:red_glazed_terracotta:0,30,STAINED_CLAY:15,50,STAINED_CLAY:15,100)
RandomBlock(-4,9,5,STAINED_GLASS:14,15,CONCRETE:6,25,CONCRETE:14,25,minecraft:red_glazed_terracotta:0,30,STAINED_CLAY:15,50,STAINED_CLAY:15,100)
RandomBlock(-3,6,-4,STAINED_GLASS:14,15,CONCRETE:6,25,CONCRETE:14,25,minecraft:red_glazed_terracotta:0,30,STAINED_CLAY:15,50,STAINED_CLAY:15,100)
RandomBlock(-3,6,5,STAINED_GLASS:14,15,CONCRETE:6,25,CONCRETE:14,25,minecraft:red_glazed_terracotta:0,30,STAINED_CLAY:15,50,STAINED_CLAY:15,100)
RandomBlock(-3,7,-4,STAINED_GLASS:14,15,CONCRETE:6,25,CONCRETE:14,25,minecraft:red_glazed_terracotta:0,30,STAINED_CLAY:15,50,STAINED_CLAY:15,100)
RandomBlock(-3,7,5,STAINED_GLASS:14,15,CONCRETE:6,25,CONCRETE:14,25,minecraft:red_glazed_terracotta:0,30,STAINED_CLAY:15,50,STAINED_CLAY:15,100)
RandomBlock(-3,8,-4,STAINED_GLASS:14,15,CONCRETE:6,25,CONCRETE:14,25,minecraft:red_glazed_terracotta:0,30,STAINED_CLAY:15,50,STAINED_CLAY:15,100)
RandomBlock(-3,8,5,STAINED_GLASS:14,15,CONCRETE:6,25,CONCRETE:14,25,minecraft:red_glazed_terracotta:0,30,STAINED_CLAY:15,50,STAINED_CLAY:15,100)
RandomBlock(-3,9,-4,STAINED_GLASS:14,15,CONCRETE:6,25,CONCRETE:14,25,minecraft:red_glazed_terracotta:0,30,STAINED_CLAY:15,50,STAINED_CLAY:15,100)
RandomBlock(-3,9,5,STAINED_GLASS:14,15,CONCRETE:6,25,CONCRETE:14,25,minecraft:red_glazed_terracotta:0,30,STAINED_CLAY:15,50,STAINED_CLAY:15,100)
RandomBlock(-2,6,-4,STAINED_GLASS:14,15,CONCRETE:6,25,CONCRETE:14,25,minecraft:red_glazed_terracotta:0,30,STAINED_CLAY:15,50,STAINED_CLAY:15,100)
RandomBlock(-2,6,5,STAINED_GLASS:14,15,CONCRETE:6,25,CONCRETE:14,25,minecraft:red_glazed_terracotta:0,30,STAINED_CLAY:15,50,STAINED_CLAY:15,100)
RandomBlock(-2,7,-4,STAINED_GLASS:14,15,CONCRETE:6,25,CONCRETE:14,25,minecraft:red_glazed_terracotta:0,30,STAINED_CLAY:15,50,STAINED_CLAY:15,100)
RandomBlock(-2,7,5,STAINED_GLASS:14,15,CONCRETE:6,25,CONCRETE:14,25,minecraft:red_glazed_terracotta:0,30,STAINED_CLAY:15,50,STAINED_CLAY:15,100)
RandomBlock(-2,8,-4,STAINED_GLASS:14,15,CONCRETE:6,25,CONCRETE:14,25,minecraft:red_glazed_terracotta:0,30,STAINED_CLAY:15,50,STAINED_CLAY:15,100)
RandomBlock(-2,8,5,STAINED_GLASS:14,15,CONCRETE:6,25,CONCRETE:14,25,minecraft:red_glazed_terracotta:0,30,STAINED_CLAY:15,50,STAINED_CLAY:15,100)
RandomBlock(-2,9,-4,STAINED_GLASS:14,15,CONCRETE:6,25,CONCRETE:14,25,minecraft:red_glazed_terracotta:0,30,STAINED_CLAY:15,50,STAINED_CLAY:15,100)
RandomBlock(-2,9,5,STAINED_GLASS:14,15,CONCRETE:6,25,CONCRETE:14,25,minecraft:red_glazed_terracotta:0,30,STAINED_CLAY:15,50,STAINED_CLAY:15,100)
RandomBlock(-1,6,-4,STAINED_GLASS:14,15,CONCRETE:6,25,CONCRETE:14,25,minecraft:red_glazed_terracotta:0,30,STAINED_CLAY:15,50,STAINED_CLAY:15,100)
RandomBlock(-1,6,5,STAINED_GLASS:14,15,CONCRETE:6,25,CONCRETE:14,25,minecraft:red_glazed_terracotta:0,30,STAINED_CLAY:15,50,STAINED_CLAY:15,100)
RandomBlock(-1,7,-4,STAINED_GLASS:14,15,CONCRETE:6,25,CONCRETE:14,25,minecraft:red_glazed_terracotta:0,30,STAINED_CLAY:15,50,STAINED_CLAY:15,100)
RandomBlock(-1,7,5,STAINED_GLASS:14,15,CONCRETE:6,25,CONCRETE:14,25,minecraft:red_glazed_terracotta:0,30,STAINED_CLAY:15,50,STAINED_CLAY:15,100)
RandomBlock(-1,8,-4,STAINED_GLASS:14,15,CONCRETE:6,25,CONCRETE:14,25,minecraft:red_glazed_terracotta:0,30,STAINED_CLAY:15,50,STAINED_CLAY:15,100)
RandomBlock(-1,8,5,STAINED_GLASS:14,15,CONCRETE:6,25,CONCRETE:14,25,minecraft:red_glazed_terracotta:0,30,STAINED_CLAY:15,50,STAINED_CLAY:15,100)
RandomBlock(-1,9,-4,STAINED_GLASS:14,15,CONCRETE:6,25,CONCRETE:14,25,minecraft:red_glazed_terracotta:0,30,STAINED_CLAY:15,50,STAINED_CLAY:15,100)
RandomBlock(-1,9,5,STAINED_GLASS:14,15,CONCRETE:6,25,CONCRETE:14,25,minecraft:red_glazed_terracotta:0,30,STAINED_CLAY:15,50,STAINED_CLAY:15,100)
RandomBlock(0,6,-4,STAINED_GLASS:14,15,CONCRETE:6,25,CONCRETE:14,25,minecraft:red_glazed_terracotta:0,30,STAINED_CLAY:15,50,STAINED_CLAY:15,100)
RandomBlock(0,6,5,STAINED_GLASS:14,15,CONCRETE:6,25,CONCRETE:14,25,minecraft:red_glazed_terracotta:0,30,STAINED_CLAY:15,50,STAINED_CLAY:15,100)
RandomBlock(0,7,-4,STAINED_GLASS:14,15,CONCRETE:6,25,CONCRETE:14,25,minecraft:red_glazed_terracotta:0,30,STAINED_CLAY:15,50,STAINED_CLAY:15,100)
RandomBlock(0,7,5,STAINED_GLASS:14,15,CONCRETE:6,25,CONCRETE:14,25,minecraft:red_glazed_terracotta:0,30,STAINED_CLAY:15,50,STAINED_CLAY:15,100)
RandomBlock(0,8,-4,STAINED_GLASS:14,15,CONCRETE:6,25,CONCRETE:14,25,minecraft:red_glazed_terracotta:0,30,STAINED_CLAY:15,50,STAINED_CLAY:15,100)
RandomBlock(0,8,5,STAINED_GLASS:14,15,CONCRETE:6,25,CONCRETE:14,25,minecraft:red_glazed_terracotta:0,30,STAINED_CLAY:15,50,STAINED_CLAY:15,100)
RandomBlock(0,9,-4,STAINED_GLASS:14,15,CONCRETE:6,25,CONCRETE:14,25,minecraft:red_glazed_terracotta:0,30,STAINED_CLAY:15,50,STAINED_CLAY:15,100)
RandomBlock(0,9,5,STAINED_GLASS:14,15,CONCRETE:6,25,CONCRETE:14,25,minecraft:red_glazed_terracotta:0,30,STAINED_CLAY:15,50,STAINED_CLAY:15,100)
RandomBlock(1,6,-4,STAINED_GLASS:14,15,CONCRETE:6,25,CONCRETE:14,25,minecraft:red_glazed_terracotta:0,30,STAINED_CLAY:15,50,STAINED_CLAY:15,100)
RandomBlock(1,6,5,STAINED_GLASS:14,15,CONCRETE:6,25,CONCRETE:14,25,minecraft:red_glazed_terracotta:0,30,STAINED_CLAY:15,50,STAINED_CLAY:15,100)
RandomBlock(1,7,-4,STAINED_GLASS:14,15,CONCRETE:6,25,CONCRETE:14,25,minecraft:red_glazed_terracotta:0,30,STAINED_CLAY:15,50,STAINED_CLAY:15,100)
RandomBlock(1,7,5,STAINED_GLASS:14,15,CONCRETE:6,25,CONCRETE:14,25,minecraft:red_glazed_terracotta:0,30,STAINED_CLAY:15,50,STAINED_CLAY:15,100)
RandomBlock(1,8,-4,STAINED_GLASS:14,15,CONCRETE:6,25,CONCRETE:14,25,minecraft:red_glazed_terracotta:0,30,STAINED_CLAY:15,50,STAINED_CLAY:15,100)
RandomBlock(1,8,5,STAINED_GLASS:14,15,CONCRETE:6,25,CONCRETE:14,25,minecraft:red_glazed_terracotta:0,30,STAINED_CLAY:15,50,STAINED_CLAY:15,100)
RandomBlock(1,9,-4,STAINED_GLASS:14,15,CONCRETE:6,25,CONCRETE:14,25,minecraft:red_glazed_terracotta:0,30,STAINED_CLAY:15,50,STAINED_CLAY:15,100)
RandomBlock(1,9,5,STAINED_GLASS:14,15,CONCRETE:6,25,CONCRETE:14,25,minecraft:red_glazed_terracotta:0,30,STAINED_CLAY:15,50,STAINED_CLAY:15,100)
RandomBlock(2,6,-4,STAINED_GLASS:14,15,CONCRETE:6,25,CONCRETE:14,25,minecraft:red_glazed_terracotta:0,30,STAINED_CLAY:15,50,STAINED_CLAY:15,100)
RandomBlock(2,6,5,STAINED_GLASS:14,15,CONCRETE:6,25,CONCRETE:14,25,minecraft:red_glazed_terracotta:0,30,STAINED_CLAY:15,50,STAINED_CLAY:15,100)
RandomBlock(2,7,-4,STAINED_GLASS:14,15,CONCRETE:6,25,CONCRETE:14,25,minecraft:red_glazed_terracotta:0,30,STAINED_CLAY:15,50,STAINED_CLAY:15,100)
RandomBlock(2,7,5,STAINED_GLASS:14,15,CONCRETE:6,25,CONCRETE:14,25,minecraft:red_glazed_terracotta:0,30,STAINED_CLAY:15,50,STAINED_CLAY:15,100)
RandomBlock(2,8,-4,STAINED_GLASS:14,15,CONCRETE:6,25,CONCRETE:14,25,minecraft:red_glazed_terracotta:0,30,STAINED_CLAY:15,50,STAINED_CLAY:15,100)
RandomBlock(2,8,5,STAINED_GLASS:14,15,CONCRETE:6,25,CONCRETE:14,25,minecraft:red_glazed_terracotta:0,30,STAINED_CLAY:15,50,STAINED_CLAY:15,100)
RandomBlock(2,9,-4,STAINED_GLASS:14,15,CONCRETE:6,25,CONCRETE:14,25,minecraft:red_glazed_terracotta:0,30,STAINED_CLAY:15,50,STAINED_CLAY:15,100)
RandomBlock(2,9,5,STAINED_GLASS:14,15,CONCRETE:6,25,CONCRETE:14,25,minecraft:red_glazed_terracotta:0,30,STAINED_CLAY:15,50,STAINED_CLAY:15,100)
RandomBlock(3,6,-4,STAINED_GLASS:14,15,CONCRETE:6,25,CONCRETE:14,25,minecraft:red_glazed_terracotta:0,30,STAINED_CLAY:15,50,STAINED_CLAY:15,100)
RandomBlock(3,6,5,STAINED_GLASS:14,15,CONCRETE:6,25,CONCRETE:14,25,minecraft:red_glazed_terracotta:0,30,STAINED_CLAY:15,50,STAINED_CLAY:15,100)
RandomBlock(3,7,-4,STAINED_GLASS:14,15,CONCRETE:6,25,CONCRETE:14,25,minecraft:red_glazed_terracotta:0,30,STAINED_CLAY:15,50,STAINED_CLAY:15,100)
RandomBlock(3,7,5,STAINED_GLASS:14,15,CONCRETE:6,25,CONCRETE:14,25,minecraft:red_glazed_terracotta:0,30,STAINED_CLAY:15,50,STAINED_CLAY:15,100)
RandomBlock(3,8,-4,STAINED_GLASS:14,15,CONCRETE:6,25,CONCRETE:14,25,minecraft:red_glazed_terracotta:0,30,STAINED_CLAY:15,50,STAINED_CLAY:15,100)
RandomBlock(3,8,5,STAINED_GLASS:14,15,CONCRETE:6,25,CONCRETE:14,25,minecraft:red_glazed_terracotta:0,30,STAINED_CLAY:15,50,STAINED_CLAY:15,100)
RandomBlock(3,9,-4,STAINED_GLASS:14,15,CONCRETE:6,25,CONCRETE:14,25,minecraft:red_glazed_terracotta:0,30,STAINED_CLAY:15,50,STAINED_CLAY:15,100)
RandomBlock(3,9,5,STAINED_GLASS:14,15,CONCRETE:6,25,CONCRETE:14,25,minecraft:red_glazed_terracotta:0,30,STAINED_CLAY:15,50,STAINED_CLAY:15,100)
RandomBlock(4,6,-4,STAINED_GLASS:14,15,CONCRETE:6,25,CONCRETE:14,25,minecraft:red_glazed_terracotta:0,30,STAINED_CLAY:15,50,STAINED_CLAY:15,100)
RandomBlock(4,6,5,STAINED_GLASS:14,15,CONCRETE:6,25,CONCRETE:14,25,minecraft:red_glazed_terracotta:0,30,STAINED_CLAY:15,50,STAINED_CLAY:15,100)
RandomBlock(4,7,-4,STAINED_GLASS:14,15,CONCRETE:6,25,CONCRETE:14,25,minecraft:red_glazed_terracotta:0,30,STAINED_CLAY:15,50,STAINED_CLAY:15,100)
RandomBlock(4,7,5,STAINED_GLASS:14,15,CONCRETE:6,25,CONCRETE:14,25,minecraft:red_glazed_terracotta:0,30,STAINED_CLAY:15,50,STAINED_CLAY:15,100)
RandomBlock(4,8,-4,STAINED_GLASS:14,15,CONCRETE:6,25,CONCRETE:14,25,minecraft:red_glazed_terracotta:0,30,STAINED_CLAY:15,50,STAINED_CLAY:15,100)
RandomBlock(4,8,5,STAINED_GLASS:14,15,CONCRETE:6,25,CONCRETE:14,25,minecraft:red_glazed_terracotta:0,30,STAINED_CLAY:15,50,STAINED_CLAY:15,100)
RandomBlock(4,9,-4,STAINED_GLASS:14,15,CONCRETE:6,25,CONCRETE:14,25,minecraft:red_glazed_terracotta:0,30,STAINED_CLAY:15,50,STAINED_CLAY:15,100)
RandomBlock(4,9,5,STAINED_GLASS:14,15,CONCRETE:6,25,CONCRETE:14,25,minecraft:red_glazed_terracotta:0,30,STAINED_CLAY:15,50,STAINED_CLAY:15,100)
RandomBlock(5,6,-4,STAINED_GLASS:14,15,CONCRETE:6,25,CONCRETE:14,25,minecraft:red_glazed_terracotta:0,30,STAINED_CLAY:15,50,STAINED_CLAY:15,100)
RandomBlock(5,6,-3,STAINED_GLASS:14,15,CONCRETE:6,25,CONCRETE:14,25,minecraft:red_glazed_terracotta:0,30,STAINED_CLAY:15,50,STAINED_CLAY:15,100)
RandomBlock(5,6,4,STAINED_GLASS:14,15,CONCRETE:6,25,CONCRETE:14,25,minecraft:red_glazed_terracotta:0,30,STAINED_CLAY:15,50,STAINED_CLAY:15,100)
RandomBlock(5,6,5,STAINED_GLASS:14,15,CONCRETE:6,25,CONCRETE:14,25,minecraft:red_glazed_terracotta:0,30,STAINED_CLAY:15,50,STAINED_CLAY:15,100)
RandomBlock(5,7,-4,STAINED_GLASS:14,15,CONCRETE:6,25,CONCRETE:14,25,minecraft:red_glazed_terracotta:0,30,STAINED_CLAY:15,50,STAINED_CLAY:15,100)
RandomBlock(5,7,-3,STAINED_GLASS:14,15,CONCRETE:6,25,CONCRETE:14,25,minecraft:red_glazed_terracotta:0,30,STAINED_CLAY:15,50,STAINED_CLAY:15,100)
RandomBlock(5,7,4,STAINED_GLASS:14,15,CONCRETE:6,25,CONCRETE:14,25,minecraft:red_glazed_terracotta:0,30,STAINED_CLAY:15,50,STAINED_CLAY:15,100)
RandomBlock(5,7,5,STAINED_GLASS:14,15,CONCRETE:6,25,CONCRETE:14,25,minecraft:red_glazed_terracotta:0,30,STAINED_CLAY:15,50,STAINED_CLAY:15,100)
RandomBlock(5,8,-4,STAINED_GLASS:14,15,CONCRETE:6,25,CONCRETE:14,25,minecraft:red_glazed_terracotta:0,30,STAINED_CLAY:15,50,STAINED_CLAY:15,100)
RandomBlock(5,8,-3,STAINED_GLASS:14,15,CONCRETE:6,25,CONCRETE:14,25,minecraft:red_glazed_terracotta:0,30,STAINED_CLAY:15,50,STAINED_CLAY:15,100)
RandomBlock(5,8,4,STAINED_GLASS:14,15,CONCRETE:6,25,CONCRETE:14,25,minecraft:red_glazed_terracotta:0,30,STAINED_CLAY:15,50,STAINED_CLAY:15,100)
RandomBlock(5,8,5,STAINED_GLASS:14,15,CONCRETE:6,25,CONCRETE:14,25,minecraft:red_glazed_terracotta:0,30,STAINED_CLAY:15,50,STAINED_CLAY:15,100)
RandomBlock(5,9,-4,STAINED_GLASS:14,15,CONCRETE:6,25,CONCRETE:14,25,minecraft:red_glazed_terracotta:0,30,STAINED_CLAY:15,50,STAINED_CLAY:15,100)
RandomBlock(5,9,-3,STAINED_GLASS:14,15,CONCRETE:6,25,CONCRETE:14,25,minecraft:red_glazed_terracotta:0,30,STAINED_CLAY:15,50,STAINED_CLAY:15,100)
RandomBlock(5,9,4,STAINED_GLASS:14,15,CONCRETE:6,25,CONCRETE:14,25,minecraft:red_glazed_terracotta:0,30,STAINED_CLAY:15,50,STAINED_CLAY:15,100)
RandomBlock(5,9,5,STAINED_GLASS:14,15,CONCRETE:6,25,CONCRETE:14,25,minecraft:red_glazed_terracotta:0,30,STAINED_CLAY:15,50,STAINED_CLAY:15,100)
RandomBlock(6,6,-3,STAINED_GLASS:14,15,CONCRETE:6,25,CONCRETE:14,25,minecraft:red_glazed_terracotta:0,30,STAINED_CLAY:15,50,STAINED_CLAY:15,100)
RandomBlock(6,6,4,STAINED_GLASS:14,15,CONCRETE:6,25,CONCRETE:14,25,minecraft:red_glazed_terracotta:0,30,STAINED_CLAY:15,50,STAINED_CLAY:15,100)
RandomBlock(6,7,-3,STAINED_GLASS:14,15,CONCRETE:6,25,CONCRETE:14,25,minecraft:red_glazed_terracotta:0,30,STAINED_CLAY:15,50,STAINED_CLAY:15,100)
RandomBlock(6,7,4,STAINED_GLASS:14,15,CONCRETE:6,25,CONCRETE:14,25,minecraft:red_glazed_terracotta:0,30,STAINED_CLAY:15,50,STAINED_CLAY:15,100)
RandomBlock(6,8,-3,STAINED_GLASS:14,15,CONCRETE:6,25,CONCRETE:14,25,minecraft:red_glazed_terracotta:0,30,STAINED_CLAY:15,50,STAINED_CLAY:15,100)
RandomBlock(6,8,4,STAINED_GLASS:14,15,CONCRETE:6,25,CONCRETE:14,25,minecraft:red_glazed_terracotta:0,30,STAINED_CLAY:15,50,STAINED_CLAY:15,100)
RandomBlock(6,9,-3,STAINED_GLASS:14,15,CONCRETE:6,25,CONCRETE:14,25,minecraft:red_glazed_terracotta:0,30,STAINED_CLAY:15,50,STAINED_CLAY:15,100)
RandomBlock(6,9,4,STAINED_GLASS:14,15,CONCRETE:6,25,CONCRETE:14,25,minecraft:red_glazed_terracotta:0,30,STAINED_CLAY:15,50,STAINED_CLAY:15,100)
RandomBlock(7,6,-3,STAINED_GLASS:14,15,CONCRETE:6,25,CONCRETE:14,25,minecraft:red_glazed_terracotta:0,30,STAINED_CLAY:15,50,STAINED_CLAY:15,100)
RandomBlock(7,6,4,STAINED_GLASS:14,15,CONCRETE:6,25,CONCRETE:14,25,minecraft:red_glazed_terracotta:0,30,STAINED_CLAY:15,50,STAINED_CLAY:15,100)
RandomBlock(7,7,-3,STAINED_GLASS:14,15,CONCRETE:6,25,CONCRETE:14,25,minecraft:red_glazed_terracotta:0,30,STAINED_CLAY:15,50,STAINED_CLAY:15,100)
RandomBlock(7,7,4,STAINED_GLASS:14,15,CONCRETE:6,25,CONCRETE:14,25,minecraft:red_glazed_terracotta:0,30,STAINED_CLAY:15,50,STAINED_CLAY:15,100)
RandomBlock(7,8,-3,STAINED_GLASS:14,15,CONCRETE:6,25,CONCRETE:14,25,minecraft:red_glazed_terracotta:0,30,STAINED_CLAY:15,50,STAINED_CLAY:15,100)
RandomBlock(7,8,4,STAINED_GLASS:14,15,CONCRETE:6,25,CONCRETE:14,25,minecraft:red_glazed_terracotta:0,30,STAINED_CLAY:15,50,STAINED_CLAY:15,100)
RandomBlock(7,9,-3,STAINED_GLASS:14,15,CONCRETE:6,25,CONCRETE:14,25,minecraft:red_glazed_terracotta:0,30,STAINED_CLAY:15,50,STAINED_CLAY:15,100)
RandomBlock(7,9,4,STAINED_GLASS:14,15,CONCRETE:6,25,CONCRETE:14,25,minecraft:red_glazed_terracotta:0,30,STAINED_CLAY:15,50,STAINED_CLAY:15,100)
RandomBlock(8,6,-3,STAINED_GLASS:14,15,CONCRETE:6,25,CONCRETE:14,25,minecraft:red_glazed_terracotta:0,30,STAINED_CLAY:15,50,STAINED_CLAY:15,100)
RandomBlock(8,6,4,STAINED_GLASS:14,15,CONCRETE:6,25,CONCRETE:14,25,minecraft:red_glazed_terracotta:0,30,STAINED_CLAY:15,50,STAINED_CLAY:15,100)
RandomBlock(8,7,-3,STAINED_GLASS:14,15,CONCRETE:6,25,CONCRETE:14,25,minecraft:red_glazed_terracotta:0,30,STAINED_CLAY:15,50,STAINED_CLAY:15,100)
RandomBlock(8,7,4,STAINED_GLASS:14,15,CONCRETE:6,25,CONCRETE:14,25,minecraft:red_glazed_terracotta:0,30,STAINED_CLAY:15,50,STAINED_CLAY:15,100)
RandomBlock(8,8,-3,STAINED_GLASS:14,15,CONCRETE:6,25,CONCRETE:14,25,minecraft:red_glazed_terracotta:0,30,STAINED_CLAY:15,50,STAINED_CLAY:15,100)
RandomBlock(8,8,4,STAINED_GLASS:14,15,CONCRETE:6,25,CONCRETE:14,25,minecraft:red_glazed_terracotta:0,30,STAINED_CLAY:15,50,STAINED_CLAY:15,100)
RandomBlock(8,9,-3,STAINED_GLASS:14,15,CONCRETE:6,25,CONCRETE:14,25,minecraft:red_glazed_terracotta:0,30,STAINED_CLAY:15,50,STAINED_CLAY:15,100)
RandomBlock(8,9,4,STAINED_GLASS:14,15,CONCRETE:6,25,CONCRETE:14,25,minecraft:red_glazed_terracotta:0,30,STAINED_CLAY:15,50,STAINED_CLAY:15,100)
RandomBlock(9,6,-3,STAINED_GLASS:14,15,CONCRETE:6,25,CONCRETE:14,25,minecraft:red_glazed_terracotta:0,30,STAINED_CLAY:15,50,STAINED_CLAY:15,100)
RandomBlock(9,6,4,STAINED_GLASS:14,15,CONCRETE:6,25,CONCRETE:14,25,minecraft:red_glazed_terracotta:0,30,STAINED_CLAY:15,50,STAINED_CLAY:15,100)
RandomBlock(9,7,-3,STAINED_GLASS:14,15,CONCRETE:6,25,CONCRETE:14,25,minecraft:red_glazed_terracotta:0,30,STAINED_CLAY:15,50,STAINED_CLAY:15,100)
RandomBlock(9,7,4,STAINED_GLASS:14,15,CONCRETE:6,25,CONCRETE:14,25,minecraft:red_glazed_terracotta:0,30,STAINED_CLAY:15,50,STAINED_CLAY:15,100)
RandomBlock(9,8,-3,STAINED_GLASS:14,15,CONCRETE:6,25,CONCRETE:14,25,minecraft:red_glazed_terracotta:0,30,STAINED_CLAY:15,50,STAINED_CLAY:15,100)
RandomBlock(9,8,4,STAINED_GLASS:14,15,CONCRETE:6,25,CONCRETE:14,25,minecraft:red_glazed_terracotta:0,30,STAINED_CLAY:15,50,STAINED_CLAY:15,100)
RandomBlock(9,9,-3,STAINED_GLASS:14,15,CONCRETE:6,25,CONCRETE:14,25,minecraft:red_glazed_terracotta:0,30,STAINED_CLAY:15,50,STAINED_CLAY:15,100)
RandomBlock(9,9,4,STAINED_GLASS:14,15,CONCRETE:6,25,CONCRETE:14,25,minecraft:red_glazed_terracotta:0,30,STAINED_CLAY:15,50,STAINED_CLAY:15,100)
RandomBlock(10,6,-3,STAINED_GLASS:14,15,CONCRETE:6,25,CONCRETE:14,25,minecraft:red_glazed_terracotta:0,30,STAINED_CLAY:15,50,STAINED_CLAY:15,100)
RandomBlock(10,6,-2,STAINED_GLASS:14,15,CONCRETE:6,25,CONCRETE:14,25,minecraft:red_glazed_terracotta:0,30,STAINED_CLAY:15,50,STAINED_CLAY:15,100)
RandomBlock(10,6,-1,STAINED_GLASS:14,15,CONCRETE:6,25,CONCRETE:14,25,minecraft:red_glazed_terracotta:0,30,STAINED_CLAY:15,50,STAINED_CLAY:15,100)
RandomBlock(10,6,0,STAINED_GLASS:14,15,CONCRETE:6,25,CONCRETE:14,25,minecraft:red_glazed_terracotta:0,30,STAINED_CLAY:15,50,STAINED_CLAY:15,100)
RandomBlock(10,6,1,STAINED_GLASS:14,15,CONCRETE:6,25,CONCRETE:14,25,minecraft:red_glazed_terracotta:0,30,STAINED_CLAY:15,50,STAINED_CLAY:15,100)
RandomBlock(10,6,2,STAINED_GLASS:14,15,CONCRETE:6,25,CONCRETE:14,25,minecraft:red_glazed_terracotta:0,30,STAINED_CLAY:15,50,STAINED_CLAY:15,100)
RandomBlock(10,6,3,STAINED_GLASS:14,15,CONCRETE:6,25,CONCRETE:14,25,minecraft:red_glazed_terracotta:0,30,STAINED_CLAY:15,50,STAINED_CLAY:15,100)
RandomBlock(10,6,4,STAINED_GLASS:14,15,CONCRETE:6,25,CONCRETE:14,25,minecraft:red_glazed_terracotta:0,30,STAINED_CLAY:15,50,STAINED_CLAY:15,100)
RandomBlock(10,7,-3,STAINED_GLASS:14,15,CONCRETE:6,25,CONCRETE:14,25,minecraft:red_glazed_terracotta:0,30,STAINED_CLAY:15,50,STAINED_CLAY:15,100)
RandomBlock(10,7,-2,STAINED_GLASS:14,15,CONCRETE:6,25,CONCRETE:14,25,minecraft:red_glazed_terracotta:0,30,STAINED_CLAY:15,50,STAINED_CLAY:15,100)
RandomBlock(10,7,-1,STAINED_GLASS:14,15,CONCRETE:6,25,CONCRETE:14,25,minecraft:red_glazed_terracotta:0,30,STAINED_CLAY:15,50,STAINED_CLAY:15,100)
RandomBlock(10,7,0,STAINED_GLASS:14,15,CONCRETE:6,25,CONCRETE:14,25,minecraft:red_glazed_terracotta:0,30,STAINED_CLAY:15,50,STAINED_CLAY:15,100)
RandomBlock(10,7,1,STAINED_GLASS:14,15,CONCRETE:6,25,CONCRETE:14,25,minecraft:red_glazed_terracotta:0,30,STAINED_CLAY:15,50,STAINED_CLAY:15,100)
RandomBlock(10,7,2,STAINED_GLASS:14,15,CONCRETE:6,25,CONCRETE:14,25,minecraft:red_glazed_terracotta:0,30,STAINED_CLAY:15,50,STAINED_CLAY:15,100)
RandomBlock(10,7,3,STAINED_GLASS:14,15,CONCRETE:6,25,CONCRETE:14,25,minecraft:red_glazed_terracotta:0,30,STAINED_CLAY:15,50,STAINED_CLAY:15,100)
RandomBlock(10,7,4,STAINED_GLASS:14,15,CONCRETE:6,25,CONCRETE:14,25,minecraft:red_glazed_terracotta:0,30,STAINED_CLAY:15,50,STAINED_CLAY:15,100)
RandomBlock(10,8,-3,STAINED_GLASS:14,15,CONCRETE:6,25,CONCRETE:14,25,minecraft:red_glazed_terracotta:0,30,STAINED_CLAY:15,50,STAINED_CLAY:15,100)
RandomBlock(10,8,-2,STAINED_GLASS:14,15,CONCRETE:6,25,CONCRETE:14,25,minecraft:red_glazed_terracotta:0,30,STAINED_CLAY:15,50,STAINED_CLAY:15,100)
RandomBlock(10,8,-1,STAINED_GLASS:14,15,CONCRETE:6,25,CONCRETE:14,25,minecraft:red_glazed_terracotta:0,30,STAINED_CLAY:15,50,STAINED_CLAY:15,100)
RandomBlock(10,8,0,STAINED_GLASS:14,15,CONCRETE:6,25,CONCRETE:14,25,minecraft:red_glazed_terracotta:0,30,STAINED_CLAY:15,50,STAINED_CLAY:15,100)
RandomBlock(10,8,1,STAINED_GLASS:14,15,CONCRETE:6,25,CONCRETE:14,25,minecraft:red_glazed_terracotta:0,30,STAINED_CLAY:15,50,STAINED_CLAY:15,100)
RandomBlock(10,8,2,STAINED_GLASS:14,15,CONCRETE:6,25,CONCRETE:14,25,minecraft:red_glazed_terracotta:0,30,STAINED_CLAY:15,50,STAINED_CLAY:15,100)
RandomBlock(10,8,3,STAINED_GLASS:14,15,CONCRETE:6,25,CONCRETE:14,25,minecraft:red_glazed_terracotta:0,30,STAINED_CLAY:15,50,STAINED_CLAY:15,100)
RandomBlock(10,8,4,STAINED_GLASS:14,15,CONCRETE:6,25,CONCRETE:14,25,minecraft:red_glazed_terracotta:0,30,STAINED_CLAY:15,50,STAINED_CLAY:15,100)
RandomBlock(10,9,-3,STAINED_GLASS:14,15,CONCRETE:6,25,CONCRETE:14,25,minecraft:red_glazed_terracotta:0,30,STAINED_CLAY:15,50,STAINED_CLAY:15,100)
RandomBlock(10,9,-2,STAINED_GLASS:14,15,CONCRETE:6,25,CONCRETE:14,25,minecraft:red_glazed_terracotta:0,30,STAINED_CLAY:15,50,STAINED_CLAY:15,100)
RandomBlock(10,9,-1,STAINED_GLASS:14,15,CONCRETE:6,25,CONCRETE:14,25,minecraft:red_glazed_terracotta:0,30,STAINED_CLAY:15,50,STAINED_CLAY:15,100)
RandomBlock(10,9,0,STAINED_GLASS:14,15,CONCRETE:6,25,CONCRETE:14,25,minecraft:red_glazed_terracotta:0,30,STAINED_CLAY:15,50,STAINED_CLAY:15,100)
RandomBlock(10,9,1,STAINED_GLASS:14,15,CONCRETE:6,25,CONCRETE:14,25,minecraft:red_glazed_terracotta:0,30,STAINED_CLAY:15,50,STAINED_CLAY:15,100)
RandomBlock(10,9,2,STAINED_GLASS:14,15,CONCRETE:6,25,CONCRETE:14,25,minecraft:red_glazed_terracotta:0,30,STAINED_CLAY:15,50,STAINED_CLAY:15,100)
RandomBlock(10,9,3,STAINED_GLASS:14,15,CONCRETE:6,25,CONCRETE:14,25,minecraft:red_glazed_terracotta:0,30,STAINED_CLAY:15,50,STAINED_CLAY:15,100)
RandomBlock(10,9,4,STAINED_GLASS:14,15,CONCRETE:6,25,CONCRETE:14,25,minecraft:red_glazed_terracotta:0,30,STAINED_CLAY:15,50,STAINED_CLAY:15,100)

RandomBlock(-5,1,0,SKULL:1,NBT/Skulls/dungeon_skull_01.nbt,6,AIR,9,SKULL:1,NBT/Skulls/dungeon_skull_02.nbt,12,AIR,15,SKULL:1,NBT/Skulls/dungeon_skull_03.nbt,18,AIR,21,SKULL:1,NBT/Skulls/dungeon_skull_04.nbt,24,AIR,27,SKULL:1,NBT/Skulls/dungeon_skull_05.nbt,30,AIR,33,SKULL:1,NBT/Skulls/dungeon_skull_06.nbt,36,AIR,39,SKULL:1,NBT/Skulls/dungeon_skull_07.nbt,42,AIR,45,SKULL:1,NBT/Skulls/dungeon_skull_08.nbt,48,AIR,51,SKULL:1,NBT/Skulls/dungeon_skull_09.nbt,54,AIR,57,SKULL:1,NBT/Skulls/dungeon_skull_10.nbt,60,AIR,63,SKULL:1,NBT/Skulls/dungeon_skull_11.nbt,66,AIR,69,SKULL:1,NBT/Skulls/dungeon_skull_12.nbt,72,AIR,75,SKULL:1,NBT/Skulls/dungeon_skull_13.nbt,78,AIR,81,SKULL:1,NBT/Skulls/dungeon_skull_14.nbt,84,AIR,87,SKULL:1,NBT/Skulls/dungeon_skull_15.nbt,90,AIR,93,SKULL:1,NBT/Skulls/dungeon_skull_16.nbt,96,AIR,100)
RandomBlock(-5,1,2,SKULL:1,NBT/Skulls/dungeon_skull_01.nbt,6,AIR,9,SKULL:1,NBT/Skulls/dungeon_skull_02.nbt,12,AIR,15,SKULL:1,NBT/Skulls/dungeon_skull_03.nbt,18,AIR,21,SKULL:1,NBT/Skulls/dungeon_skull_04.nbt,24,AIR,27,SKULL:1,NBT/Skulls/dungeon_skull_05.nbt,30,AIR,33,SKULL:1,NBT/Skulls/dungeon_skull_06.nbt,36,AIR,39,SKULL:1,NBT/Skulls/dungeon_skull_07.nbt,42,AIR,45,SKULL:1,NBT/Skulls/dungeon_skull_08.nbt,48,AIR,51,SKULL:1,NBT/Skulls/dungeon_skull_09.nbt,54,AIR,57,SKULL:1,NBT/Skulls/dungeon_skull_10.nbt,60,AIR,63,SKULL:1,NBT/Skulls/dungeon_skull_11.nbt,66,AIR,69,SKULL:1,NBT/Skulls/dungeon_skull_12.nbt,72,AIR,75,SKULL:1,NBT/Skulls/dungeon_skull_13.nbt,78,AIR,81,SKULL:1,NBT/Skulls/dungeon_skull_14.nbt,84,AIR,87,SKULL:1,NBT/Skulls/dungeon_skull_15.nbt,90,AIR,93,SKULL:1,NBT/Skulls/dungeon_skull_16.nbt,96,AIR,100)
RandomBlock(-5,2,-1,SKULL:1,NBT/Skulls/dungeon_skull_01.nbt,6,AIR,9,SKULL:1,NBT/Skulls/dungeon_skull_02.nbt,12,AIR,15,SKULL:1,NBT/Skulls/dungeon_skull_03.nbt,18,AIR,21,SKULL:1,NBT/Skulls/dungeon_skull_04.nbt,24,AIR,27,SKULL:1,NBT/Skulls/dungeon_skull_05.nbt,30,AIR,33,SKULL:1,NBT/Skulls/dungeon_skull_06.nbt,36,AIR,39,SKULL:1,NBT/Skulls/dungeon_skull_07.nbt,42,AIR,45,SKULL:1,NBT/Skulls/dungeon_skull_08.nbt,48,AIR,51,SKULL:1,NBT/Skulls/dungeon_skull_09.nbt,54,AIR,57,SKULL:1,NBT/Skulls/dungeon_skull_10.nbt,60,AIR,63,SKULL:1,NBT/Skulls/dungeon_skull_11.nbt,66,AIR,69,SKULL:1,NBT/Skulls/dungeon_skull_12.nbt,72,AIR,75,SKULL:1,NBT/Skulls/dungeon_skull_13.nbt,78,AIR,81,SKULL:1,NBT/Skulls/dungeon_skull_14.nbt,84,AIR,87,SKULL:1,NBT/Skulls/dungeon_skull_15.nbt,90,AIR,93,SKULL:1,NBT/Skulls/dungeon_skull_16.nbt,96,AIR,100)
RandomBlock(-5,2,1,SKULL:1,NBT/Skulls/dungeon_skull_01.nbt,6,AIR,9,SKULL:1,NBT/Skulls/dungeon_skull_02.nbt,12,AIR,15,SKULL:1,NBT/Skulls/dungeon_skull_03.nbt,18,AIR,21,SKULL:1,NBT/Skulls/dungeon_skull_04.nbt,24,AIR,27,SKULL:1,NBT/Skulls/dungeon_skull_05.nbt,30,AIR,33,SKULL:1,NBT/Skulls/dungeon_skull_06.nbt,36,AIR,39,SKULL:1,NBT/Skulls/dungeon_skull_07.nbt,42,AIR,45,SKULL:1,NBT/Skulls/dungeon_skull_08.nbt,48,AIR,51,SKULL:1,NBT/Skulls/dungeon_skull_09.nbt,54,AIR,57,SKULL:1,NBT/Skulls/dungeon_skull_10.nbt,60,AIR,63,SKULL:1,NBT/Skulls/dungeon_skull_11.nbt,66,AIR,69,SKULL:1,NBT/Skulls/dungeon_skull_12.nbt,72,AIR,75,SKULL:1,NBT/Skulls/dungeon_skull_13.nbt,78,AIR,81,SKULL:1,NBT/Skulls/dungeon_skull_14.nbt,84,AIR,87,SKULL:1,NBT/Skulls/dungeon_skull_15.nbt,90,AIR,93,SKULL:1,NBT/Skulls/dungeon_skull_16.nbt,96,AIR,100)
RandomBlock(-5,3,0,SKULL:1,NBT/Skulls/dungeon_skull_01.nbt,6,AIR,9,SKULL:1,NBT/Skulls/dungeon_skull_02.nbt,12,AIR,15,SKULL:1,NBT/Skulls/dungeon_skull_03.nbt,18,AIR,21,SKULL:1,NBT/Skulls/dungeon_skull_04.nbt,24,AIR,27,SKULL:1,NBT/Skulls/dungeon_skull_05.nbt,30,AIR,33,SKULL:1,NBT/Skulls/dungeon_skull_06.nbt,36,AIR,39,SKULL:1,NBT/Skulls/dungeon_skull_07.nbt,42,AIR,45,SKULL:1,NBT/Skulls/dungeon_skull_08.nbt,48,AIR,51,SKULL:1,NBT/Skulls/dungeon_skull_09.nbt,54,AIR,57,SKULL:1,NBT/Skulls/dungeon_skull_10.nbt,60,AIR,63,SKULL:1,NBT/Skulls/dungeon_skull_11.nbt,66,AIR,69,SKULL:1,NBT/Skulls/dungeon_skull_12.nbt,72,AIR,75,SKULL:1,NBT/Skulls/dungeon_skull_13.nbt,78,AIR,81,SKULL:1,NBT/Skulls/dungeon_skull_14.nbt,84,AIR,87,SKULL:1,NBT/Skulls/dungeon_skull_15.nbt,90,AIR,93,SKULL:1,NBT/Skulls/dungeon_skull_16.nbt,96,AIR,100)
RandomBlock(-5,3,2,SKULL:1,NBT/Skulls/dungeon_skull_01.nbt,6,AIR,9,SKULL:1,NBT/Skulls/dungeon_skull_02.nbt,12,AIR,15,SKULL:1,NBT/Skulls/dungeon_skull_03.nbt,18,AIR,21,SKULL:1,NBT/Skulls/dungeon_skull_04.nbt,24,AIR,27,SKULL:1,NBT/Skulls/dungeon_skull_05.nbt,30,AIR,33,SKULL:1,NBT/Skulls/dungeon_skull_06.nbt,36,AIR,39,SKULL:1,NBT/Skulls/dungeon_skull_07.nbt,42,AIR,45,SKULL:1,NBT/Skulls/dungeon_skull_08.nbt,48,AIR,51,SKULL:1,NBT/Skulls/dungeon_skull_09.nbt,54,AIR,57,SKULL:1,NBT/Skulls/dungeon_skull_10.nbt,60,AIR,63,SKULL:1,NBT/Skulls/dungeon_skull_11.nbt,66,AIR,69,SKULL:1,NBT/Skulls/dungeon_skull_12.nbt,72,AIR,75,SKULL:1,NBT/Skulls/dungeon_skull_13.nbt,78,AIR,81,SKULL:1,NBT/Skulls/dungeon_skull_14.nbt,84,AIR,87,SKULL:1,NBT/Skulls/dungeon_skull_15.nbt,90,AIR,93,SKULL:1,NBT/Skulls/dungeon_skull_16.nbt,96,AIR,100)
RandomBlock(-3,1,4,SKULL:1,NBT/Skulls/dungeon_skull_01.nbt,6,AIR,9,SKULL:1,NBT/Skulls/dungeon_skull_02.nbt,12,AIR,15,SKULL:1,NBT/Skulls/dungeon_skull_03.nbt,18,AIR,21,SKULL:1,NBT/Skulls/dungeon_skull_04.nbt,24,AIR,27,SKULL:1,NBT/Skulls/dungeon_skull_05.nbt,30,AIR,33,SKULL:1,NBT/Skulls/dungeon_skull_06.nbt,36,AIR,39,SKULL:1,NBT/Skulls/dungeon_skull_07.nbt,42,AIR,45,SKULL:1,NBT/Skulls/dungeon_skull_08.nbt,48,AIR,51,SKULL:1,NBT/Skulls/dungeon_skull_09.nbt,54,AIR,57,SKULL:1,NBT/Skulls/dungeon_skull_10.nbt,60,AIR,63,SKULL:1,NBT/Skulls/dungeon_skull_11.nbt,66,AIR,69,SKULL:1,NBT/Skulls/dungeon_skull_12.nbt,72,AIR,75,SKULL:1,NBT/Skulls/dungeon_skull_13.nbt,78,AIR,81,SKULL:1,NBT/Skulls/dungeon_skull_14.nbt,84,AIR,87,SKULL:1,NBT/Skulls/dungeon_skull_15.nbt,90,AIR,93,SKULL:1,NBT/Skulls/dungeon_skull_16.nbt,96,AIR,100)
RandomBlock(-3,2,-3,SKULL:1,NBT/Skulls/dungeon_skull_01.nbt,6,AIR,9,SKULL:1,NBT/Skulls/dungeon_skull_02.nbt,12,AIR,15,SKULL:1,NBT/Skulls/dungeon_skull_03.nbt,18,AIR,21,SKULL:1,NBT/Skulls/dungeon_skull_04.nbt,24,AIR,27,SKULL:1,NBT/Skulls/dungeon_skull_05.nbt,30,AIR,33,SKULL:1,NBT/Skulls/dungeon_skull_06.nbt,36,AIR,39,SKULL:1,NBT/Skulls/dungeon_skull_07.nbt,42,AIR,45,SKULL:1,NBT/Skulls/dungeon_skull_08.nbt,48,AIR,51,SKULL:1,NBT/Skulls/dungeon_skull_09.nbt,54,AIR,57,SKULL:1,NBT/Skulls/dungeon_skull_10.nbt,60,AIR,63,SKULL:1,NBT/Skulls/dungeon_skull_11.nbt,66,AIR,69,SKULL:1,NBT/Skulls/dungeon_skull_12.nbt,72,AIR,75,SKULL:1,NBT/Skulls/dungeon_skull_13.nbt,78,AIR,81,SKULL:1,NBT/Skulls/dungeon_skull_14.nbt,84,AIR,87,SKULL:1,NBT/Skulls/dungeon_skull_15.nbt,90,AIR,93,SKULL:1,NBT/Skulls/dungeon_skull_16.nbt,96,AIR,100)
RandomBlock(-3,3,4,SKULL:1,NBT/Skulls/dungeon_skull_01.nbt,6,AIR,9,SKULL:1,NBT/Skulls/dungeon_skull_02.nbt,12,AIR,15,SKULL:1,NBT/Skulls/dungeon_skull_03.nbt,18,AIR,21,SKULL:1,NBT/Skulls/dungeon_skull_04.nbt,24,AIR,27,SKULL:1,NBT/Skulls/dungeon_skull_05.nbt,30,AIR,33,SKULL:1,NBT/Skulls/dungeon_skull_06.nbt,36,AIR,39,SKULL:1,NBT/Skulls/dungeon_skull_07.nbt,42,AIR,45,SKULL:1,NBT/Skulls/dungeon_skull_08.nbt,48,AIR,51,SKULL:1,NBT/Skulls/dungeon_skull_09.nbt,54,AIR,57,SKULL:1,NBT/Skulls/dungeon_skull_10.nbt,60,AIR,63,SKULL:1,NBT/Skulls/dungeon_skull_11.nbt,66,AIR,69,SKULL:1,NBT/Skulls/dungeon_skull_12.nbt,72,AIR,75,SKULL:1,NBT/Skulls/dungeon_skull_13.nbt,78,AIR,81,SKULL:1,NBT/Skulls/dungeon_skull_14.nbt,84,AIR,87,SKULL:1,NBT/Skulls/dungeon_skull_15.nbt,90,AIR,93,SKULL:1,NBT/Skulls/dungeon_skull_16.nbt,96,AIR,100)
RandomBlock(-2,1,-3,SKULL:1,NBT/Skulls/dungeon_skull_01.nbt,6,AIR,9,SKULL:1,NBT/Skulls/dungeon_skull_02.nbt,12,AIR,15,SKULL:1,NBT/Skulls/dungeon_skull_03.nbt,18,AIR,21,SKULL:1,NBT/Skulls/dungeon_skull_04.nbt,24,AIR,27,SKULL:1,NBT/Skulls/dungeon_skull_05.nbt,30,AIR,33,SKULL:1,NBT/Skulls/dungeon_skull_06.nbt,36,AIR,39,SKULL:1,NBT/Skulls/dungeon_skull_07.nbt,42,AIR,45,SKULL:1,NBT/Skulls/dungeon_skull_08.nbt,48,AIR,51,SKULL:1,NBT/Skulls/dungeon_skull_09.nbt,54,AIR,57,SKULL:1,NBT/Skulls/dungeon_skull_10.nbt,60,AIR,63,SKULL:1,NBT/Skulls/dungeon_skull_11.nbt,66,AIR,69,SKULL:1,NBT/Skulls/dungeon_skull_12.nbt,72,AIR,75,SKULL:1,NBT/Skulls/dungeon_skull_13.nbt,78,AIR,81,SKULL:1,NBT/Skulls/dungeon_skull_14.nbt,84,AIR,87,SKULL:1,NBT/Skulls/dungeon_skull_15.nbt,90,AIR,93,SKULL:1,NBT/Skulls/dungeon_skull_16.nbt,96,AIR,100)
RandomBlock(-2,3,-3,SKULL:1,NBT/Skulls/dungeon_skull_01.nbt,6,AIR,9,SKULL:1,NBT/Skulls/dungeon_skull_02.nbt,12,AIR,15,SKULL:1,NBT/Skulls/dungeon_skull_03.nbt,18,AIR,21,SKULL:1,NBT/Skulls/dungeon_skull_04.nbt,24,AIR,27,SKULL:1,NBT/Skulls/dungeon_skull_05.nbt,30,AIR,33,SKULL:1,NBT/Skulls/dungeon_skull_06.nbt,36,AIR,39,SKULL:1,NBT/Skulls/dungeon_skull_07.nbt,42,AIR,45,SKULL:1,NBT/Skulls/dungeon_skull_08.nbt,48,AIR,51,SKULL:1,NBT/Skulls/dungeon_skull_09.nbt,54,AIR,57,SKULL:1,NBT/Skulls/dungeon_skull_10.nbt,60,AIR,63,SKULL:1,NBT/Skulls/dungeon_skull_11.nbt,66,AIR,69,SKULL:1,NBT/Skulls/dungeon_skull_12.nbt,72,AIR,75,SKULL:1,NBT/Skulls/dungeon_skull_13.nbt,78,AIR,81,SKULL:1,NBT/Skulls/dungeon_skull_14.nbt,84,AIR,87,SKULL:1,NBT/Skulls/dungeon_skull_15.nbt,90,AIR,93,SKULL:1,NBT/Skulls/dungeon_skull_16.nbt,96,AIR,100)
RandomBlock(-1,1,4,SKULL:1,NBT/Skulls/dungeon_skull_01.nbt,6,AIR,9,SKULL:1,NBT/Skulls/dungeon_skull_02.nbt,12,AIR,15,SKULL:1,NBT/Skulls/dungeon_skull_03.nbt,18,AIR,21,SKULL:1,NBT/Skulls/dungeon_skull_04.nbt,24,AIR,27,SKULL:1,NBT/Skulls/dungeon_skull_05.nbt,30,AIR,33,SKULL:1,NBT/Skulls/dungeon_skull_06.nbt,36,AIR,39,SKULL:1,NBT/Skulls/dungeon_skull_07.nbt,42,AIR,45,SKULL:1,NBT/Skulls/dungeon_skull_08.nbt,48,AIR,51,SKULL:1,NBT/Skulls/dungeon_skull_09.nbt,54,AIR,57,SKULL:1,NBT/Skulls/dungeon_skull_10.nbt,60,AIR,63,SKULL:1,NBT/Skulls/dungeon_skull_11.nbt,66,AIR,69,SKULL:1,NBT/Skulls/dungeon_skull_12.nbt,72,AIR,75,SKULL:1,NBT/Skulls/dungeon_skull_13.nbt,78,AIR,81,SKULL:1,NBT/Skulls/dungeon_skull_14.nbt,84,AIR,87,SKULL:1,NBT/Skulls/dungeon_skull_15.nbt,90,AIR,93,SKULL:1,NBT/Skulls/dungeon_skull_16.nbt,96,AIR,100)
RandomBlock(-1,2,-3,SKULL:1,NBT/Skulls/dungeon_skull_01.nbt,6,AIR,9,SKULL:1,NBT/Skulls/dungeon_skull_02.nbt,12,AIR,15,SKULL:1,NBT/Skulls/dungeon_skull_03.nbt,18,AIR,21,SKULL:1,NBT/Skulls/dungeon_skull_04.nbt,24,AIR,27,SKULL:1,NBT/Skulls/dungeon_skull_05.nbt,30,AIR,33,SKULL:1,NBT/Skulls/dungeon_skull_06.nbt,36,AIR,39,SKULL:1,NBT/Skulls/dungeon_skull_07.nbt,42,AIR,45,SKULL:1,NBT/Skulls/dungeon_skull_08.nbt,48,AIR,51,SKULL:1,NBT/Skulls/dungeon_skull_09.nbt,54,AIR,57,SKULL:1,NBT/Skulls/dungeon_skull_10.nbt,60,AIR,63,SKULL:1,NBT/Skulls/dungeon_skull_11.nbt,66,AIR,69,SKULL:1,NBT/Skulls/dungeon_skull_12.nbt,72,AIR,75,SKULL:1,NBT/Skulls/dungeon_skull_13.nbt,78,AIR,81,SKULL:1,NBT/Skulls/dungeon_skull_14.nbt,84,AIR,87,SKULL:1,NBT/Skulls/dungeon_skull_15.nbt,90,AIR,93,SKULL:1,NBT/Skulls/dungeon_skull_16.nbt,96,AIR,100)
RandomBlock(-1,3,4,SKULL:1,NBT/Skulls/dungeon_skull_01.nbt,6,AIR,9,SKULL:1,NBT/Skulls/dungeon_skull_02.nbt,12,AIR,15,SKULL:1,NBT/Skulls/dungeon_skull_03.nbt,18,AIR,21,SKULL:1,NBT/Skulls/dungeon_skull_04.nbt,24,AIR,27,SKULL:1,NBT/Skulls/dungeon_skull_05.nbt,30,AIR,33,SKULL:1,NBT/Skulls/dungeon_skull_06.nbt,36,AIR,39,SKULL:1,NBT/Skulls/dungeon_skull_07.nbt,42,AIR,45,SKULL:1,NBT/Skulls/dungeon_skull_08.nbt,48,AIR,51,SKULL:1,NBT/Skulls/dungeon_skull_09.nbt,54,AIR,57,SKULL:1,NBT/Skulls/dungeon_skull_10.nbt,60,AIR,63,SKULL:1,NBT/Skulls/dungeon_skull_11.nbt,66,AIR,69,SKULL:1,NBT/Skulls/dungeon_skull_12.nbt,72,AIR,75,SKULL:1,NBT/Skulls/dungeon_skull_13.nbt,78,AIR,81,SKULL:1,NBT/Skulls/dungeon_skull_14.nbt,84,AIR,87,SKULL:1,NBT/Skulls/dungeon_skull_15.nbt,90,AIR,93,SKULL:1,NBT/Skulls/dungeon_skull_16.nbt,96,AIR,100)
RandomBlock(0,1,-3,SKULL:1,NBT/Skulls/dungeon_skull_01.nbt,6,AIR,9,SKULL:1,NBT/Skulls/dungeon_skull_02.nbt,12,AIR,15,SKULL:1,NBT/Skulls/dungeon_skull_03.nbt,18,AIR,21,SKULL:1,NBT/Skulls/dungeon_skull_04.nbt,24,AIR,27,SKULL:1,NBT/Skulls/dungeon_skull_05.nbt,30,AIR,33,SKULL:1,NBT/Skulls/dungeon_skull_06.nbt,36,AIR,39,SKULL:1,NBT/Skulls/dungeon_skull_07.nbt,42,AIR,45,SKULL:1,NBT/Skulls/dungeon_skull_08.nbt,48,AIR,51,SKULL:1,NBT/Skulls/dungeon_skull_09.nbt,54,AIR,57,SKULL:1,NBT/Skulls/dungeon_skull_10.nbt,60,AIR,63,SKULL:1,NBT/Skulls/dungeon_skull_11.nbt,66,AIR,69,SKULL:1,NBT/Skulls/dungeon_skull_12.nbt,72,AIR,75,SKULL:1,NBT/Skulls/dungeon_skull_13.nbt,78,AIR,81,SKULL:1,NBT/Skulls/dungeon_skull_14.nbt,84,AIR,87,SKULL:1,NBT/Skulls/dungeon_skull_15.nbt,90,AIR,93,SKULL:1,NBT/Skulls/dungeon_skull_16.nbt,96,AIR,100)
RandomBlock(0,2,4,SKULL:1,NBT/Skulls/dungeon_skull_01.nbt,6,AIR,9,SKULL:1,NBT/Skulls/dungeon_skull_02.nbt,12,AIR,15,SKULL:1,NBT/Skulls/dungeon_skull_03.nbt,18,AIR,21,SKULL:1,NBT/Skulls/dungeon_skull_04.nbt,24,AIR,27,SKULL:1,NBT/Skulls/dungeon_skull_05.nbt,30,AIR,33,SKULL:1,NBT/Skulls/dungeon_skull_06.nbt,36,AIR,39,SKULL:1,NBT/Skulls/dungeon_skull_07.nbt,42,AIR,45,SKULL:1,NBT/Skulls/dungeon_skull_08.nbt,48,AIR,51,SKULL:1,NBT/Skulls/dungeon_skull_09.nbt,54,AIR,57,SKULL:1,NBT/Skulls/dungeon_skull_10.nbt,60,AIR,63,SKULL:1,NBT/Skulls/dungeon_skull_11.nbt,66,AIR,69,SKULL:1,NBT/Skulls/dungeon_skull_12.nbt,72,AIR,75,SKULL:1,NBT/Skulls/dungeon_skull_13.nbt,78,AIR,81,SKULL:1,NBT/Skulls/dungeon_skull_14.nbt,84,AIR,87,SKULL:1,NBT/Skulls/dungeon_skull_15.nbt,90,AIR,93,SKULL:1,NBT/Skulls/dungeon_skull_16.nbt,96,AIR,100)
RandomBlock(0,3,-3,SKULL:1,NBT/Skulls/dungeon_skull_01.nbt,6,AIR,9,SKULL:1,NBT/Skulls/dungeon_skull_02.nbt,12,AIR,15,SKULL:1,NBT/Skulls/dungeon_skull_03.nbt,18,AIR,21,SKULL:1,NBT/Skulls/dungeon_skull_04.nbt,24,AIR,27,SKULL:1,NBT/Skulls/dungeon_skull_05.nbt,30,AIR,33,SKULL:1,NBT/Skulls/dungeon_skull_06.nbt,36,AIR,39,SKULL:1,NBT/Skulls/dungeon_skull_07.nbt,42,AIR,45,SKULL:1,NBT/Skulls/dungeon_skull_08.nbt,48,AIR,51,SKULL:1,NBT/Skulls/dungeon_skull_09.nbt,54,AIR,57,SKULL:1,NBT/Skulls/dungeon_skull_10.nbt,60,AIR,63,SKULL:1,NBT/Skulls/dungeon_skull_11.nbt,66,AIR,69,SKULL:1,NBT/Skulls/dungeon_skull_12.nbt,72,AIR,75,SKULL:1,NBT/Skulls/dungeon_skull_13.nbt,78,AIR,81,SKULL:1,NBT/Skulls/dungeon_skull_14.nbt,84,AIR,87,SKULL:1,NBT/Skulls/dungeon_skull_15.nbt,90,AIR,93,SKULL:1,NBT/Skulls/dungeon_skull_16.nbt,96,AIR,100)
RandomBlock(1,1,4,SKULL:1,NBT/Skulls/dungeon_skull_01.nbt,6,AIR,9,SKULL:1,NBT/Skulls/dungeon_skull_02.nbt,12,AIR,15,SKULL:1,NBT/Skulls/dungeon_skull_03.nbt,18,AIR,21,SKULL:1,NBT/Skulls/dungeon_skull_04.nbt,24,AIR,27,SKULL:1,NBT/Skulls/dungeon_skull_05.nbt,30,AIR,33,SKULL:1,NBT/Skulls/dungeon_skull_06.nbt,36,AIR,39,SKULL:1,NBT/Skulls/dungeon_skull_07.nbt,42,AIR,45,SKULL:1,NBT/Skulls/dungeon_skull_08.nbt,48,AIR,51,SKULL:1,NBT/Skulls/dungeon_skull_09.nbt,54,AIR,57,SKULL:1,NBT/Skulls/dungeon_skull_10.nbt,60,AIR,63,SKULL:1,NBT/Skulls/dungeon_skull_11.nbt,66,AIR,69,SKULL:1,NBT/Skulls/dungeon_skull_12.nbt,72,AIR,75,SKULL:1,NBT/Skulls/dungeon_skull_13.nbt,78,AIR,81,SKULL:1,NBT/Skulls/dungeon_skull_14.nbt,84,AIR,87,SKULL:1,NBT/Skulls/dungeon_skull_15.nbt,90,AIR,93,SKULL:1,NBT/Skulls/dungeon_skull_16.nbt,96,AIR,100)
RandomBlock(1,2,-3,SKULL:1,NBT/Skulls/dungeon_skull_01.nbt,6,AIR,9,SKULL:1,NBT/Skulls/dungeon_skull_02.nbt,12,AIR,15,SKULL:1,NBT/Skulls/dungeon_skull_03.nbt,18,AIR,21,SKULL:1,NBT/Skulls/dungeon_skull_04.nbt,24,AIR,27,SKULL:1,NBT/Skulls/dungeon_skull_05.nbt,30,AIR,33,SKULL:1,NBT/Skulls/dungeon_skull_06.nbt,36,AIR,39,SKULL:1,NBT/Skulls/dungeon_skull_07.nbt,42,AIR,45,SKULL:1,NBT/Skulls/dungeon_skull_08.nbt,48,AIR,51,SKULL:1,NBT/Skulls/dungeon_skull_09.nbt,54,AIR,57,SKULL:1,NBT/Skulls/dungeon_skull_10.nbt,60,AIR,63,SKULL:1,NBT/Skulls/dungeon_skull_11.nbt,66,AIR,69,SKULL:1,NBT/Skulls/dungeon_skull_12.nbt,72,AIR,75,SKULL:1,NBT/Skulls/dungeon_skull_13.nbt,78,AIR,81,SKULL:1,NBT/Skulls/dungeon_skull_14.nbt,84,AIR,87,SKULL:1,NBT/Skulls/dungeon_skull_15.nbt,90,AIR,93,SKULL:1,NBT/Skulls/dungeon_skull_16.nbt,96,AIR,100)
RandomBlock(1,3,4,SKULL:1,NBT/Skulls/dungeon_skull_01.nbt,6,AIR,9,SKULL:1,NBT/Skulls/dungeon_skull_02.nbt,12,AIR,15,SKULL:1,NBT/Skulls/dungeon_skull_03.nbt,18,AIR,21,SKULL:1,NBT/Skulls/dungeon_skull_04.nbt,24,AIR,27,SKULL:1,NBT/Skulls/dungeon_skull_05.nbt,30,AIR,33,SKULL:1,NBT/Skulls/dungeon_skull_06.nbt,36,AIR,39,SKULL:1,NBT/Skulls/dungeon_skull_07.nbt,42,AIR,45,SKULL:1,NBT/Skulls/dungeon_skull_08.nbt,48,AIR,51,SKULL:1,NBT/Skulls/dungeon_skull_09.nbt,54,AIR,57,SKULL:1,NBT/Skulls/dungeon_skull_10.nbt,60,AIR,63,SKULL:1,NBT/Skulls/dungeon_skull_11.nbt,66,AIR,69,SKULL:1,NBT/Skulls/dungeon_skull_12.nbt,72,AIR,75,SKULL:1,NBT/Skulls/dungeon_skull_13.nbt,78,AIR,81,SKULL:1,NBT/Skulls/dungeon_skull_14.nbt,84,AIR,87,SKULL:1,NBT/Skulls/dungeon_skull_15.nbt,90,AIR,93,SKULL:1,NBT/Skulls/dungeon_skull_16.nbt,96,AIR,100)
RandomBlock(2,1,-3,SKULL:1,NBT/Skulls/dungeon_skull_01.nbt,6,AIR,9,SKULL:1,NBT/Skulls/dungeon_skull_02.nbt,12,AIR,15,SKULL:1,NBT/Skulls/dungeon_skull_03.nbt,18,AIR,21,SKULL:1,NBT/Skulls/dungeon_skull_04.nbt,24,AIR,27,SKULL:1,NBT/Skulls/dungeon_skull_05.nbt,30,AIR,33,SKULL:1,NBT/Skulls/dungeon_skull_06.nbt,36,AIR,39,SKULL:1,NBT/Skulls/dungeon_skull_07.nbt,42,AIR,45,SKULL:1,NBT/Skulls/dungeon_skull_08.nbt,48,AIR,51,SKULL:1,NBT/Skulls/dungeon_skull_09.nbt,54,AIR,57,SKULL:1,NBT/Skulls/dungeon_skull_10.nbt,60,AIR,63,SKULL:1,NBT/Skulls/dungeon_skull_11.nbt,66,AIR,69,SKULL:1,NBT/Skulls/dungeon_skull_12.nbt,72,AIR,75,SKULL:1,NBT/Skulls/dungeon_skull_13.nbt,78,AIR,81,SKULL:1,NBT/Skulls/dungeon_skull_14.nbt,84,AIR,87,SKULL:1,NBT/Skulls/dungeon_skull_15.nbt,90,AIR,93,SKULL:1,NBT/Skulls/dungeon_skull_16.nbt,96,AIR,100)
RandomBlock(2,2,4,SKULL:1,NBT/Skulls/dungeon_skull_01.nbt,6,AIR,9,SKULL:1,NBT/Skulls/dungeon_skull_02.nbt,12,AIR,15,SKULL:1,NBT/Skulls/dungeon_skull_03.nbt,18,AIR,21,SKULL:1,NBT/Skulls/dungeon_skull_04.nbt,24,AIR,27,SKULL:1,NBT/Skulls/dungeon_skull_05.nbt,30,AIR,33,SKULL:1,NBT/Skulls/dungeon_skull_06.nbt,36,AIR,39,SKULL:1,NBT/Skulls/dungeon_skull_07.nbt,42,AIR,45,SKULL:1,NBT/Skulls/dungeon_skull_08.nbt,48,AIR,51,SKULL:1,NBT/Skulls/dungeon_skull_09.nbt,54,AIR,57,SKULL:1,NBT/Skulls/dungeon_skull_10.nbt,60,AIR,63,SKULL:1,NBT/Skulls/dungeon_skull_11.nbt,66,AIR,69,SKULL:1,NBT/Skulls/dungeon_skull_12.nbt,72,AIR,75,SKULL:1,NBT/Skulls/dungeon_skull_13.nbt,78,AIR,81,SKULL:1,NBT/Skulls/dungeon_skull_14.nbt,84,AIR,87,SKULL:1,NBT/Skulls/dungeon_skull_15.nbt,90,AIR,93,SKULL:1,NBT/Skulls/dungeon_skull_16.nbt,96,AIR,100)
RandomBlock(2,3,-3,SKULL:1,NBT/Skulls/dungeon_skull_01.nbt,6,AIR,9,SKULL:1,NBT/Skulls/dungeon_skull_02.nbt,12,AIR,15,SKULL:1,NBT/Skulls/dungeon_skull_03.nbt,18,AIR,21,SKULL:1,NBT/Skulls/dungeon_skull_04.nbt,24,AIR,27,SKULL:1,NBT/Skulls/dungeon_skull_05.nbt,30,AIR,33,SKULL:1,NBT/Skulls/dungeon_skull_06.nbt,36,AIR,39,SKULL:1,NBT/Skulls/dungeon_skull_07.nbt,42,AIR,45,SKULL:1,NBT/Skulls/dungeon_skull_08.nbt,48,AIR,51,SKULL:1,NBT/Skulls/dungeon_skull_09.nbt,54,AIR,57,SKULL:1,NBT/Skulls/dungeon_skull_10.nbt,60,AIR,63,SKULL:1,NBT/Skulls/dungeon_skull_11.nbt,66,AIR,69,SKULL:1,NBT/Skulls/dungeon_skull_12.nbt,72,AIR,75,SKULL:1,NBT/Skulls/dungeon_skull_13.nbt,78,AIR,81,SKULL:1,NBT/Skulls/dungeon_skull_14.nbt,84,AIR,87,SKULL:1,NBT/Skulls/dungeon_skull_15.nbt,90,AIR,93,SKULL:1,NBT/Skulls/dungeon_skull_16.nbt,96,AIR,100)



RandomBlock(-6,2,1,AIR,30,CHEST:3,NBT/LoreStoryLine/LoreSpooky_2.nbt,5,CHEST:3,NBT/StructureLoot/Common1.nbt,10,CHEST:3,NBT/StructureLoot/Common2.nbt,10,CHEST:3,NBT/StructureLoot/Common3.nbt,10,CHEST:3,NBT/StructureLoot/Common4.nbt,10,CHEST:3,NBT/StructureLoot/Common5.nbt,10,CHEST:3,NBT/StructureLoot/Common6.nbt,10,CHEST:3,NBT/StructureLoot/Common7.nbt,10,CHEST:3,NBT/StructureLoot/Common8.nbt,10,CHEST:3,NBT/StructureLoot/Common9.nbt,10,CHEST:3,NBT/StructureLoot/Common10.nbt,10,CHEST:3,NBT/StructureLoot/Common11.nbt,10,CHEST:3,NBT/StructureLoot/Common12.nbt,10,CHEST:3,NBT/StructureLoot/Common13.nbt,10,CHEST:3,NBT/StructureLoot/Common14.nbt,10,CHEST:3,NBT/StructureLoot/Common15.nbt,100)
RandomBlock(0,2,5,AIR,30,CHEST:5,NBT/LoreStoryLine/LoreSpooky_2.nbt,5,CHEST:5,NBT/StructureLoot/Common1.nbt,10,CHEST:5,NBT/StructureLoot/Common2.nbt,10,CHEST:5,NBT/StructureLoot/Common3.nbt,10,CHEST:5,NBT/StructureLoot/Common4.nbt,10,CHEST:5,NBT/StructureLoot/Common5.nbt,10,CHEST:5,NBT/StructureLoot/Common6.nbt,10,CHEST:5,NBT/StructureLoot/Common7.nbt,10,CHEST:5,NBT/StructureLoot/Common8.nbt,10,CHEST:5,NBT/StructureLoot/Common9.nbt,10,CHEST:5,NBT/StructureLoot/Common10.nbt,10,CHEST:5,NBT/StructureLoot/Common11.nbt,10,CHEST:5,NBT/StructureLoot/Common12.nbt,10,CHEST:5,NBT/StructureLoot/Common13.nbt,10,CHEST:5,NBT/StructureLoot/Common14.nbt,10,CHEST:5,NBT/StructureLoot/Common15.nbt,100)
RandomBlock(0,3,-4,AIR,30,CHEST:5,NBT/LoreStoryLine/LoreSpooky_2.nbt,5,CHEST:5,NBT/StructureLoot/Common1.nbt,10,CHEST:5,NBT/StructureLoot/Common2.nbt,10,CHEST:5,NBT/StructureLoot/Common3.nbt,10,CHEST:5,NBT/StructureLoot/Common4.nbt,10,CHEST:5,NBT/StructureLoot/Common5.nbt,10,CHEST:5,NBT/StructureLoot/Common6.nbt,10,CHEST:5,NBT/StructureLoot/Common7.nbt,10,CHEST:5,NBT/StructureLoot/Common8.nbt,10,CHEST:5,NBT/StructureLoot/Common9.nbt,10,CHEST:5,NBT/StructureLoot/Common10.nbt,10,CHEST:5,NBT/StructureLoot/Common11.nbt,10,CHEST:5,NBT/StructureLoot/Common12.nbt,10,CHEST:5,NBT/StructureLoot/Common13.nbt,10,CHEST:5,NBT/StructureLoot/Common14.nbt,10,CHEST:5,NBT/StructureLoot/Common15.nbt,100)

RandomBlock(-6,1,0,TRAPPED_CHEST:3,NBT/StructureLoot/BoneChest.nbt,50,AIR,100)
RandomBlock(-6,1,2,TRAPPED_CHEST:3,NBT/StructureLoot/BoneChest.nbt,50,AIR,100)
RandomBlock(-6,2,-1,TRAPPED_CHEST:3,NBT/StructureLoot/BoneChest.nbt,50,AIR,100)
RandomBlock(-6,3,0,TRAPPED_CHEST:3,NBT/StructureLoot/BoneChest.nbt,50,AIR,100)
RandomBlock(-6,3,2,TRAPPED_CHEST:3,NBT/StructureLoot/BoneChest.nbt,50,AIR,100)
RandomBlock(-3,1,5,TRAPPED_CHEST:5,NBT/StructureLoot/BoneChest.nbt,50,AIR,100)
RandomBlock(-3,2,-4,TRAPPED_CHEST:5,NBT/StructureLoot/BoneChest.nbt,50,AIR,100)
RandomBlock(-3,3,5,TRAPPED_CHEST:5,NBT/StructureLoot/BoneChest.nbt,50,AIR,100)
RandomBlock(-2,1,-4,TRAPPED_CHEST:5,NBT/StructureLoot/BoneChest.nbt,50,AIR,100)
RandomBlock(-2,3,-4,TRAPPED_CHEST:5,NBT/StructureLoot/BoneChest.nbt,50,AIR,100)
RandomBlock(-1,1,5,TRAPPED_CHEST:5,NBT/StructureLoot/BoneChest.nbt,50,AIR,100)
RandomBlock(-1,2,-4,TRAPPED_CHEST:3,NBT/StructureLoot/BoneChest.nbt,50,AIR,100)
RandomBlock(-1,3,5,TRAPPED_CHEST:5,NBT/StructureLoot/BoneChest.nbt,50,AIR,100)
RandomBlock(0,1,-4,TRAPPED_CHEST:5,NBT/StructureLoot/BoneChest.nbt,50,AIR,100)
RandomBlock(1,1,5,TRAPPED_CHEST:5,NBT/StructureLoot/BoneChest.nbt,50,AIR,100)
RandomBlock(1,2,-4,TRAPPED_CHEST:5,NBT/StructureLoot/BoneChest.nbt,50,AIR,100)
RandomBlock(1,3,5,TRAPPED_CHEST:5,NBT/StructureLoot/BoneChest.nbt,50,AIR,100)
RandomBlock(2,1,-4,TRAPPED_CHEST:5,NBT/StructureLoot/BoneChest.nbt,50,AIR,100)
RandomBlock(2,2,5,TRAPPED_CHEST:5,NBT/StructureLoot/BoneChest.nbt,50,AIR,100)
RandomBlock(2,3,-4,TRAPPED_CHEST:5,NBT/StructureLoot/BoneChest.nbt,50,AIR,100)


Block(-5,10,-2,WALL_BANNER:3,NBT/SpookyDungeons/SpookyDungeon_Easy_Banner.nbt)
Block(-5,10,3,WALL_BANNER:2,NBT/SpookyDungeons/SpookyDungeon_Easy_Banner.nbt)
Block(-4,10,-3,WALL_BANNER:5,NBT/SpookyDungeons/SpookyDungeon_Easy_Banner.nbt)
Block(-4,10,4,WALL_BANNER:5,NBT/SpookyDungeons/SpookyDungeon_Easy_Banner.nbt)
Block(3,10,-3,WALL_BANNER:4,NBT/SpookyDungeons/SpookyDungeon_Easy_Banner.nbt)
Block(3,10,4,WALL_BANNER:4,NBT/SpookyDungeons/SpookyDungeon_Easy_Banner.nbt)
Block(4,10,-2,WALL_BANNER:3,NBT/SpookyDungeons/SpookyDungeon_Easy_Banner.nbt)
Block(4,10,3,WALL_BANNER:2,NBT/SpookyDungeons/SpookyDungeon_Easy_Banner.nbt)


Block(-2,2,5,MOB_SPAWNER:0,NBT/SpookyDungeons/SpookyDungeon_Easy_SpiderSpawn.nbt)

#######################################################################
# +-----------------------------------------------------------------+ #
# |                            BO3 checks                           | #
# +-----------------------------------------------------------------+ #
#######################################################################


BlockCheck(-9,10,0,AIR)
BlockCheck(-9,10,1,AIR)

BlockCheck(-7,10,-2,AIR)
BlockCheck(-7,10,3,AIR)
BlockCheck(-1,10,-5,AIR)
BlockCheck(-1,10,6,AIR)
BlockCheck(10,10,-4,AIR)
BlockCheck(10,10,5,AIR)

BlockCheck(-7,9,-2,Solid)
BlockCheck(-7,9,3,Solid)
BlockCheck(-1,9,-5,Solid)
BlockCheck(-1,9,6,Solid)
BlockCheck(10,9,-4,Solid)
BlockCheck(10,9,5,Solid)


#######################################################################
# +-----------------------------------------------------------------+ #
# |                             Branches                            | #
# +-----------------------------------------------------------------+ #
#######################################################################


#######################################################################
# +-----------------------------------------------------------------+ #
# |                             Entities                            | #
# +-----------------------------------------------------------------+ #
#######################################################################


#######################################################################
# +-----------------------------------------------------------------+ #
# |                            Particles                            | #
# +-----------------------------------------------------------------+ #
#######################################################################


#######################################################################
# +-----------------------------------------------------------------+ #
# |                             Spawners                            | #
# +-----------------------------------------------------------------+ #
#######################################################################


#######################################################################
# +-----------------------------------------------------------------+ #
# |                             ModData                             | #
# +-----------------------------------------------------------------+ #
#######################################################################

