
#######################################################################
# +-----------------------------------------------------------------+ #
# |                            BO3 object                           | #
# +-----------------------------------------------------------------+ #
#######################################################################

Author: NLBlackEagle

Description: No description given

Version: 3

SettingsMode: WriteWithoutComments


#######################################################################
# +-----------------------------------------------------------------+ #
# |                          Main settings                          | #
# +-----------------------------------------------------------------+ #
#######################################################################

Tree: true

Frequency: 0

Rarity: 100.0

RotateRandomly: false

SpawnHeight: randomY

SpawnHeightOffset: 0

SpawnHeightVariance: 0

##############################
# Height Limits for the BO3. #
##############################

MinHeight: 0

MaxHeight: 70

######################
# Extrusion settings #
######################

ExtrudeMode: None

ExtrudeThroughBlocks: otg:air

MaxBranchDepth: 10


#######################################################################
# +-----------------------------------------------------------------+ #
# |                      Source block settings                      | #
# +-----------------------------------------------------------------+ #
#######################################################################

SourceBlocks: otg:air

MaxPercentageOutsideSourceBlock: 100

OutsideSourceBlock: placeAnyway

DoReplaceBlocks: true

IsOTGPlus: false


#######################################################################
# +-----------------------------------------------------------------+ #
# |                              Blocks                             | #
# +-----------------------------------------------------------------+ #
#######################################################################

B(-6,0,1,minecraft:black_terracotta)
B(-6,0,2,minecraft:black_terracotta)
B(-6,0,3,minecraft:black_terracotta)
B(-6,1,1,minecraft:pink_concrete)
B(-6,1,2,minecraft:black_terracotta)
B(-6,1,3,minecraft:black_terracotta)
B(-6,2,2,minecraft:red_stained_glass)
B(-5,0,0,minecraft:black_terracotta)
B(-5,0,1,minecraft:black_terracotta)
B(-5,0,3,minecraft:black_terracotta)
B(-5,1,0,minecraft:red_stained_glass)
B(-5,1,1,minecraft:black_terracotta)
B(-5,1,2,minecraft:black_terracotta)
B(-5,1,3,minecraft:black_terracotta)
B(-5,2,1,minecraft:black_glazed_terracotta)
B(-5,2,2,minecraft:black_terracotta)
B(-5,2,3,minecraft:black_glazed_terracotta[facing=west])
B(-4,0,0,minecraft:black_terracotta)
B(-4,0,1,minecraft:black_terracotta)
B(-4,0,2,minecraft:black_terracotta)
B(-4,0,3,minecraft:black_terracotta)
B(-4,1,0,minecraft:black_terracotta)
B(-4,1,1,minecraft:black_terracotta)
B(-4,1,2,minecraft:black_terracotta)
B(-4,1,3,minecraft:black_terracotta)
B(-4,2,0,minecraft:red_stained_glass)
B(-4,2,1,minecraft:black_terracotta)
B(-4,2,2,minecraft:black_terracotta)
B(-4,2,3,minecraft:black_terracotta)
B(-4,3,1,minecraft:black_glazed_terracotta)
B(-4,3,2,minecraft:black_terracotta)
B(-4,3,3,minecraft:red_stained_glass)
B(-3,0,1,minecraft:black_terracotta)
B(-3,0,2,minecraft:black_terracotta)
B(-3,1,1,minecraft:black_terracotta)
B(-3,1,2,minecraft:black_terracotta)
B(-3,2,0,minecraft:red_stained_glass)
B(-3,2,1,minecraft:black_terracotta)
B(-3,2,2,minecraft:black_terracotta)
B(-3,2,3,minecraft:black_glazed_terracotta[facing=south])
B(-3,3,0,minecraft:red_stained_glass)
B(-3,3,1,minecraft:black_glazed_terracotta)
B(-3,3,2,minecraft:red_stained_glass)
B(-3,3,3,minecraft:red_stained_glass)
B(-3,4,1,minecraft:red_concrete)
B(-3,4,2,minecraft:pink_concrete)
B(-2,2,1,minecraft:red_stained_glass)
B(-2,3,0,minecraft:red_stained_glass)
B(-2,3,1,minecraft:black_terracotta)
B(-2,3,2,minecraft:black_glazed_terracotta[facing=south])
B(-2,4,0,minecraft:black_glazed_terracotta)
B(-2,4,1,minecraft:black_terracotta)
B(-2,4,2,minecraft:black_glazed_terracotta[facing=south])
B(-2,5,0,minecraft:pink_concrete)
B(-2,5,1,minecraft:red_glazed_terracotta[facing=west])
B(-2,5,2,minecraft:red_stained_glass)
B(-1,3,1,minecraft:red_stained_glass)
B(-1,4,0,minecraft:red_glazed_terracotta[facing=east])
B(-1,4,1,minecraft:red_glazed_terracotta)
B(-1,4,2,minecraft:black_terracotta)
B(-1,5,0,minecraft:black_terracotta)
B(-1,5,1,minecraft:black_terracotta)
B(-1,5,2,minecraft:red_stained_glass)
B(-1,6,0,minecraft:red_concrete)
B(-1,6,1,minecraft:red_stained_glass)
B(0,5,0,minecraft:black_terracotta)
B(0,5,1,minecraft:black_terracotta)
B(0,6,-1,minecraft:pink_concrete)
B(0,6,0,minecraft:black_terracotta)
B(0,6,1,minecraft:red_stained_glass)
B(0,7,-1,minecraft:red_stained_glass)
B(0,7,0,minecraft:red_stained_glass)
B(1,5,0,minecraft:red_stained_glass)
B(1,5,1,minecraft:red_stained_glass)
B(1,6,-1,minecraft:red_glazed_terracotta)
B(1,6,0,minecraft:black_terracotta)
B(1,7,-1,minecraft:black_terracotta)
B(1,7,0,minecraft:black_glazed_terracotta[facing=west])
B(2,7,-2,minecraft:red_stained_glass)
B(2,7,-1,minecraft:red_glazed_terracotta)
B(2,7,0,minecraft:black_terracotta)
B(2,8,-2,minecraft:black_glazed_terracotta)
B(2,8,-1,minecraft:red_concrete)
B(2,9,-2,minecraft:red_stained_glass)
B(3,8,-2,minecraft:black_terracotta)
B(3,8,-1,minecraft:black_terracotta)
B(3,9,-2,minecraft:black_glazed_terracotta[facing=west])
B(3,9,-1,minecraft:pink_concrete)
B(4,8,-2,minecraft:red_stained_glass)
B(4,9,-2,minecraft:red_glazed_terracotta)
B(4,9,-1,minecraft:red_concrete)
B(4,10,-3,minecraft:red_stained_glass)
B(4,10,-2,minecraft:pink_concrete)
B(5,9,-3,minecraft:red_stained_glass)
B(5,10,-3,minecraft:red_concrete)
B(5,10,-2,minecraft:black_glazed_terracotta[facing=south])
B(5,11,-3,minecraft:black_glazed_terracotta[facing=west])
B(6,11,-3,minecraft:black_terracotta)

#######################################################################
# +-----------------------------------------------------------------+ #
# |                            BO3 checks                           | #
# +-----------------------------------------------------------------+ #
#######################################################################

BlockCheck(0,1,0,otg:air,minecraft:water)
BlockCheck(-5,0,2,Solid)

#######################################################################
# +-----------------------------------------------------------------+ #
# |                             Branches                            | #
# +-----------------------------------------------------------------+ #
#######################################################################


#######################################################################
# +-----------------------------------------------------------------+ #
# |                             Entities                            | #
# +-----------------------------------------------------------------+ #
#######################################################################

