#######################################################################
# +-----------------------------------------------------------------+ #
# |                            BO3 object                           | #
# +-----------------------------------------------------------------+ #
#######################################################################

Author: Bo3 BulkEdit

Description: Converted Schematic - Modified by Bo3BulkEdit

Version: 3

SettingsMode: WriteDisable

#######################################################################
# +-----------------------------------------------------------------+ #
# |                          Main settings                          | #
# +-----------------------------------------------------------------+ #
#######################################################################

IsOTGPlus: true
Tree: false
Frequency: 1
Rarity: 100.0
RotateRandomly: false
SpawnHeight: randomY
MaxBranchDepth: 10
ExcludedBiomes: All

##############################
# Height Limits for the BO3. #
##############################

MinHeight: 0
MaxHeight: 255

#######################################################################
# +-----------------------------------------------------------------+ #
# |                      Source block settings                      | #
# +-----------------------------------------------------------------+ #
#######################################################################

CanOverride: true
MaxPercentageOutsideSourceBlock: 100
OutsideSourceBlock: placeAnyway

#######################################################################
# +-----------------------------------------------------------------+ #
# |                               OTG+                              | #
# +-----------------------------------------------------------------+ #
#######################################################################

BO3Group: CeilingCrystals:0

#######################################################################
# +-----------------------------------------------------------------+ #
# |                              Blocks                             | #
# +-----------------------------------------------------------------+ #
#######################################################################

B(0,750,0,AIR)
B(15,750,15,AIR)
B(14,-33,11,STAINED_GLASS:15)
B(15,-33,11,STAINED_GLASS:15)
B(14,-33,12,STAINED_GLASS:15)
B(15,-33,12,STAINED_GLASS:15)
B(14,-32,8,STAINED_GLASS:15)
B(15,-32,8,STAINED_GLASS:15)
B(13,-32,9,STAINED_GLASS:15)
B(14,-32,9,STAINED_GLASS:15)
B(15,-32,9,STAINED_GLASS:15)
B(13,-32,10,STAINED_GLASS:15)
B(14,-32,10,STAINED_GLASS:15)
B(15,-32,10,STAINED_GLASS:15)
B(13,-32,11,STAINED_GLASS:15)
B(14,-32,11,STAINED_GLASS:15)
B(15,-32,11,STAINED_GLASS:15)
B(14,-32,12,STAINED_GLASS:15)
B(15,-32,12,STAINED_GLASS:15)
B(13,-31,6,STAINED_GLASS:15)
B(14,-31,6,STAINED_GLASS:15)
B(12,-31,7,STAINED_GLASS:15)
B(13,-31,7,STAINED_GLASS:15)
B(14,-31,7,STAINED_GLASS:15)
B(15,-31,7,STAINED_GLASS:15)
B(11,-31,8,STAINED_GLASS:15)
B(12,-31,8,STAINED_GLASS:15)
B(13,-31,8,STAINED_GLASS:15)
B(14,-31,8,STAINED_GLASS:15)
B(15,-31,8,STAINED_GLASS:15)
B(11,-31,9,STAINED_GLASS:15)
B(12,-31,9,STAINED_GLASS:15)
B(13,-31,9,STAINED_GLASS:15)
B(14,-31,9,STAINED_GLASS:15)
B(15,-31,9,STAINED_GLASS:15)
B(12,-31,10,STAINED_GLASS:15)
B(13,-31,10,STAINED_GLASS:15)
B(14,-31,10,PURPLE_GLAZED_TERRACOTTA:3)
B(15,-31,10,STAINED_GLASS:15)
B(12,-31,11,STAINED_GLASS:15)
B(13,-31,11,STAINED_GLASS:15)
B(14,-31,11,STAINED_GLASS:15)
B(15,-31,11,STAINED_GLASS:15)
B(14,-30,3,STAINED_GLASS:15)
B(15,-30,3,STAINED_GLASS:15)
B(12,-30,4,STAINED_GLASS:15)
B(13,-30,4,STAINED_GLASS:15)
B(14,-30,4,STAINED_GLASS:15)
B(10,-30,5,STAINED_GLASS:15)
B(12,-30,5,STAINED_GLASS:15)
B(13,-30,5,STAINED_GLASS:15)
B(14,-30,5,STAINED_GLASS:15)
B(15,-30,5,STAINED_GLASS:15)
B(9,-30,6,STAINED_GLASS:15)
B(10,-30,6,STAINED_GLASS:15)
B(11,-30,6,STAINED_GLASS:15)
B(12,-30,6,STAINED_GLASS:15)
B(13,-30,6,STAINED_GLASS:15)
B(14,-30,6,STAINED_GLASS:15)
B(15,-30,6,STAINED_GLASS:15)
B(9,-30,7,STAINED_GLASS:15)
B(10,-30,7,STAINED_GLASS:15)
B(11,-30,7,STAINED_GLASS:15)
B(12,-30,7,STAINED_GLASS:15)
B(13,-30,7,SEA_LANTERN)
B(14,-30,7,PURPLE_GLAZED_TERRACOTTA:3)
B(15,-30,7,STAINED_GLASS:15)
B(10,-30,8,STAINED_GLASS:15)
B(11,-30,8,STAINED_GLASS:15)
B(12,-30,8,SEA_LANTERN)
B(13,-30,8,STAINED_GLASS:15)
B(14,-30,8,PURPLE_GLAZED_TERRACOTTA:3)
B(15,-30,8,PURPLE_GLAZED_TERRACOTTA:3)
B(10,-30,9,STAINED_GLASS:15)
B(11,-30,9,STAINED_GLASS:15)
B(12,-30,9,STAINED_GLASS:15)
B(13,-30,9,STAINED_GLASS:11)
B(14,-30,9,STAINED_GLASS:10)
B(11,-30,10,STAINED_GLASS:15)
B(12,-30,10,STAINED_GLASS:15)
B(13,-30,10,STAINED_GLASS:15)
B(14,-30,10,STAINED_GLASS:15)
B(12,-30,11,STAINED_GLASS:15)
B(13,-30,11,STAINED_GLASS:15)
B(14,-30,11,STAINED_GLASS:15)
B(12,-29,1,STAINED_GLASS:15)
B(11,-29,2,STAINED_GLASS:15)
B(12,-29,2,STAINED_GLASS:15)
B(13,-29,2,STAINED_GLASS:15)
B(14,-29,2,STAINED_GLASS:15)
B(9,-29,3,STAINED_GLASS:15)
B(11,-29,3,STAINED_GLASS:15)
B(12,-29,3,STAINED_GLASS:15)
B(13,-29,3,STAINED_GLASS:15)
B(14,-29,3,STAINED_GLASS:15)
B(15,-29,3,STAINED_GLASS:15)
B(8,-29,4,STAINED_GLASS:15)
B(9,-29,4,STAINED_GLASS:15)
B(10,-29,4,STAINED_GLASS:15)
B(11,-29,4,STAINED_GLASS:15)
B(12,-29,4,STAINED_GLASS:15)
B(13,-29,4,STAINED_GLASS:15)
B(14,-29,4,STAINED_GLASS:15)
B(15,-29,4,STAINED_GLASS:15)
B(8,-29,5,STAINED_GLASS:15)
B(9,-29,5,STAINED_GLASS:15)
B(10,-29,5,STAINED_GLASS:15)
B(11,-29,5,STAINED_GLASS:15)
B(12,-29,5,STAINED_GLASS:15)
B(13,-29,5,STAINED_GLASS:15)
B(14,-29,5,STAINED_GLASS:11)
B(15,-29,5,STAINED_GLASS:15)
B(8,-29,6,STAINED_GLASS:15)
B(9,-29,6,STAINED_GLASS:15)
B(10,-29,6,PURPLE_GLAZED_TERRACOTTA:3)
B(11,-29,6,SEA_LANTERN)
B(12,-29,6,STAINED_GLASS:15)
B(13,-29,6,STAINED_GLASS:15)
B(14,-29,6,PURPLE_GLAZED_TERRACOTTA:3)
B(15,-29,6,STAINED_GLASS:10)
B(9,-29,7,STAINED_GLASS:15)
B(10,-29,7,STAINED_GLASS:15)
B(11,-29,7,STAINED_GLASS:11)
B(12,-29,7,SEA_LANTERN)
B(13,-29,7,SEA_LANTERN)
B(14,-29,7,PURPLE_GLAZED_TERRACOTTA:3)
B(15,-29,7,STAINED_GLASS:10)
B(9,-29,8,STAINED_GLASS:15)
B(10,-29,8,STAINED_GLASS:15)
B(11,-29,8,STAINED_GLASS:15)
B(12,-29,8,SEA_LANTERN)
B(13,-29,8,STAINED_GLASS:11)
B(14,-29,8,STAINED_GLASS:11)
B(15,-29,8,PURPLE_GLAZED_TERRACOTTA:3)
B(9,-29,9,STAINED_GLASS:15)
B(10,-29,9,STAINED_GLASS:15)
B(11,-29,9,STAINED_GLASS:15)
B(12,-29,9,STAINED_GLASS:11)
B(13,-29,9,STAINED_GLASS:10)
B(14,-29,9,STAINED_GLASS:15)
B(15,-29,9,STAINED_GLASS:15)
B(11,-29,10,STAINED_GLASS:15)
B(12,-29,10,STAINED_GLASS:15)
B(13,-29,10,STAINED_GLASS:15)
B(14,-29,10,STAINED_GLASS:15)
B(12,-29,11,STAINED_GLASS:15)
B(12,-28,0,STAINED_GLASS:15)
B(11,-28,1,STAINED_GLASS:15)
B(12,-28,1,STAINED_GLASS:15)
B(13,-28,1,STAINED_GLASS:15)
B(8,-28,2,STAINED_GLASS:15)
B(9,-28,2,STAINED_GLASS:15)
B(10,-28,2,STAINED_GLASS:15)
B(11,-28,2,STAINED_GLASS:15)
B(12,-28,2,STAINED_GLASS:15)
B(13,-28,2,STAINED_GLASS:15)
B(14,-28,2,STAINED_GLASS:15)
B(15,-28,2,STAINED_GLASS:15)
B(7,-28,3,STAINED_GLASS:15)
B(8,-28,3,STAINED_GLASS:15)
B(9,-28,3,STAINED_GLASS:15)
B(10,-28,3,STAINED_GLASS:15)
B(11,-28,3,STAINED_GLASS:15)
B(12,-28,3,STAINED_GLASS:15)
B(13,-28,3,STAINED_GLASS:10)
B(14,-28,3,STAINED_GLASS:15)
B(15,-28,3,STAINED_GLASS:15)
B(7,-28,4,STAINED_GLASS:15)
B(8,-28,4,STAINED_GLASS:15)
B(9,-28,4,STAINED_GLASS:10)
B(10,-28,4,STAINED_GLASS:10)
B(11,-28,4,STAINED_GLASS:15)
B(12,-28,4,STAINED_GLASS:15)
B(13,-28,4,STAINED_GLASS:11)
B(14,-28,4,STAINED_GLASS:10)
B(15,-28,4,STAINED_GLASS:10)
B(7,-28,5,STAINED_GLASS:15)
B(8,-28,5,STAINED_GLASS:15)
B(9,-28,5,PURPLE_GLAZED_TERRACOTTA:3)
B(10,-28,5,PURPLE_GLAZED_TERRACOTTA:3)
B(11,-28,5,PURPLE_GLAZED_TERRACOTTA:3)
B(12,-28,5,PURPLE_GLAZED_TERRACOTTA:3)
B(13,-28,5,STAINED_GLASS:11)
B(14,-28,5,STAINED_GLASS:11)
B(15,-28,5,STAINED_GLASS:10)
B(7,-28,6,STAINED_GLASS:15)
B(8,-28,6,STAINED_GLASS:15)
B(9,-28,6,STAINED_GLASS:15)
B(10,-28,6,STAINED_GLASS:11)
B(11,-28,6,SEA_LANTERN)
B(12,-28,6,SEA_LANTERN)
B(13,-28,6,STAINED_GLASS:11)
B(14,-28,6,STAINED_GLASS:11)
B(15,-28,6,STAINED_GLASS:10)
B(8,-28,7,STAINED_GLASS:15)
B(9,-28,7,STAINED_GLASS:15)
B(10,-28,7,STAINED_GLASS:11)
B(11,-28,7,STAINED_GLASS:11)
B(12,-28,7,SEA_LANTERN)
B(13,-28,7,STAINED_GLASS:11)
B(14,-28,7,STAINED_GLASS:11)
B(15,-28,7,STAINED_GLASS:10)
B(8,-28,8,STAINED_GLASS:15)
B(9,-28,8,STAINED_GLASS:15)
B(10,-28,8,STAINED_GLASS:10)
B(11,-28,8,STAINED_GLASS:11)
B(12,-28,8,STAINED_GLASS:11)
B(13,-28,8,STAINED_GLASS:11)
B(14,-28,8,STAINED_GLASS:10)
B(15,-28,8,STAINED_GLASS:10)
B(9,-28,9,STAINED_GLASS:10)
B(10,-28,9,STAINED_GLASS:10)
B(11,-28,9,STAINED_GLASS:10)
B(12,-28,9,STAINED_GLASS:10)
B(13,-28,9,STAINED_GLASS:10)
B(14,-28,9,STAINED_GLASS:15)
B(11,-28,10,STAINED_GLASS:15)
B(12,-28,10,STAINED_GLASS:3)
B(13,-28,10,STAINED_GLASS:15)
B(14,-28,10,STAINED_GLASS:15)
B(11,-27,0,STAINED_GLASS:15)
B(12,-27,0,STAINED_GLASS:10)
B(9,-27,1,STAINED_GLASS:15)
B(10,-27,1,STAINED_GLASS:15)
B(11,-27,1,STAINED_GLASS:15)
B(12,-27,1,STAINED_GLASS:15)
B(13,-27,1,STAINED_GLASS:15)
B(6,-27,2,STAINED_GLASS:15)
B(7,-27,2,STAINED_GLASS:15)
B(8,-27,2,STAINED_GLASS:10)
B(9,-27,2,STAINED_GLASS:10)
B(10,-27,2,STAINED_GLASS:15)
B(11,-27,2,STAINED_GLASS:15)
B(12,-27,2,STAINED_GLASS:10)
B(13,-27,2,STAINED_GLASS:10)
B(14,-27,2,STAINED_GLASS:15)
B(15,-27,2,STAINED_GLASS:15)
B(7,-27,3,STAINED_GLASS:10)
B(8,-27,3,STAINED_GLASS:3)
B(9,-27,3,STAINED_GLASS:10)
B(10,-27,3,STAINED_GLASS:15)
B(11,-27,3,PURPLE_GLAZED_TERRACOTTA:3)
B(12,-27,3,STAINED_GLASS:11)
B(13,-27,3,STAINED_GLASS:10)
B(14,-27,3,STAINED_GLASS:15)
B(15,-27,3,STAINED_GLASS:15)
B(7,-27,4,STAINED_GLASS:15)
B(8,-27,4,STAINED_GLASS:10)
B(9,-27,4,PURPLE_GLAZED_TERRACOTTA:3)
B(10,-27,4,PURPLE_GLAZED_TERRACOTTA:3)
B(11,-27,4,PURPLE_GLAZED_TERRACOTTA:3)
B(12,-27,4,SEA_LANTERN)
B(13,-27,4,STAINED_GLASS:11)
B(14,-27,4,STAINED_GLASS:10)
B(15,-27,4,STAINED_GLASS:10)
B(7,-27,5,STAINED_GLASS:15)
B(8,-27,5,STAINED_GLASS:10)
B(9,-27,5,PURPLE_GLAZED_TERRACOTTA:3)
B(10,-27,5,PURPLE_GLAZED_TERRACOTTA:3)
B(11,-27,5,SEA_LANTERN)
B(12,-27,5,SEA_LANTERN)
B(13,-27,5,STAINED_GLASS:11)
B(14,-27,5,STAINED_GLASS:11)
B(15,-27,5,STAINED_GLASS:10)
B(7,-27,6,STAINED_GLASS:15)
B(8,-27,6,STAINED_GLASS:15)
B(9,-27,6,PURPLE_GLAZED_TERRACOTTA:3)
B(10,-27,6,STAINED_GLASS:11)
B(11,-27,6,SEA_LANTERN)
B(12,-27,6,SEA_LANTERN)
B(13,-27,6,STAINED_GLASS:11)
B(14,-27,6,STAINED_GLASS:11)
B(15,-27,6,STAINED_GLASS:10)
B(8,-27,7,STAINED_GLASS:15)
B(9,-27,7,STAINED_GLASS:10)
B(10,-27,7,STAINED_GLASS:11)
B(11,-27,7,STAINED_GLASS:11)
B(12,-27,7,STAINED_GLASS:11)
B(13,-27,7,STAINED_GLASS:11)
B(14,-27,7,STAINED_GLASS:10)
B(15,-27,7,STAINED_GLASS:10)
B(8,-27,8,STAINED_GLASS:15)
B(9,-27,8,STAINED_GLASS:10)
B(10,-27,8,STAINED_GLASS:10)
B(11,-27,8,STAINED_GLASS:11)
B(12,-27,8,STAINED_GLASS:11)
B(13,-27,8,STAINED_GLASS:10)
B(14,-27,8,STAINED_GLASS:10)
B(15,-27,8,STAINED_GLASS:15)
B(9,-27,9,STAINED_GLASS:15)
B(10,-27,9,STAINED_GLASS:10)
B(11,-27,9,STAINED_GLASS:3)
B(12,-27,9,STAINED_GLASS:10)
B(13,-27,9,STAINED_GLASS:15)
B(10,-27,10,STAINED_GLASS:3)
B(12,-27,10,STAINED_GLASS:3)
B(9,-26,0,STAINED_GLASS:15)
B(10,-26,0,STAINED_GLASS:15)
B(11,-26,0,STAINED_GLASS:10)
B(12,-26,0,STAINED_GLASS:15)
B(8,-26,1,STAINED_GLASS:15)
B(9,-26,1,STAINED_GLASS:15)
B(10,-26,1,STAINED_GLASS:10)
B(11,-26,1,STAINED_GLASS:15)
B(12,-26,1,STAINED_GLASS:10)
B(13,-26,1,STAINED_GLASS:15)
B(14,-26,1,STAINED_GLASS:15)
B(6,-26,2,STAINED_GLASS:15)
B(7,-26,2,STAINED_GLASS:10)
B(8,-26,2,STAINED_GLASS:15)
B(9,-26,2,STAINED_GLASS:15)
B(10,-26,2,STAINED_GLASS:15)
B(11,-26,2,STAINED_GLASS:10)
B(12,-26,2,STAINED_GLASS:11)
B(13,-26,2,STAINED_GLASS:10)
B(14,-26,2,STAINED_GLASS:15)
B(15,-26,2,STAINED_GLASS:15)
B(7,-26,3,STAINED_GLASS:15)
B(8,-26,3,STAINED_GLASS:10)
B(9,-26,3,PURPLE_GLAZED_TERRACOTTA:3)
B(10,-26,3,PURPLE_GLAZED_TERRACOTTA:3)
B(11,-26,3,PURPLE_GLAZED_TERRACOTTA:3)
B(12,-26,3,STAINED_GLASS:11)
B(13,-26,3,STAINED_GLASS:10)
B(14,-26,3,STAINED_GLASS:10)
B(15,-26,3,STAINED_GLASS:10)
B(7,-26,4,STAINED_GLASS:15)
B(8,-26,4,STAINED_GLASS:10)
B(9,-26,4,PURPLE_GLAZED_TERRACOTTA:3)
B(10,-26,4,PURPLE_GLAZED_TERRACOTTA:3)
B(11,-26,4,SEA_LANTERN)
B(12,-26,4,SEA_LANTERN)
B(13,-26,4,STAINED_GLASS:11)
B(14,-26,4,STAINED_GLASS:10)
B(15,-26,4,STAINED_GLASS:10)
B(7,-26,5,STAINED_GLASS:15)
B(8,-26,5,STAINED_GLASS:10)
B(9,-26,5,STAINED_GLASS:11)
B(10,-26,5,STAINED_GLASS:11)
B(11,-26,5,SEA_LANTERN)
B(12,-26,5,SEA_LANTERN)
B(13,-26,5,STAINED_GLASS:11)
B(14,-26,5,STAINED_GLASS:11)
B(15,-26,5,STAINED_GLASS:10)
B(7,-26,6,STAINED_GLASS:15)
B(8,-26,6,STAINED_GLASS:10)
B(9,-26,6,STAINED_GLASS:11)
B(10,-26,6,STAINED_GLASS:11)
B(11,-26,6,STAINED_GLASS:11)
B(12,-26,6,STAINED_GLASS:11)
B(13,-26,6,STAINED_GLASS:11)
B(14,-26,6,STAINED_GLASS:10)
B(15,-26,6,STAINED_GLASS:10)
B(8,-26,7,STAINED_GLASS:15)
B(9,-26,7,STAINED_GLASS:10)
B(10,-26,7,STAINED_GLASS:11)
B(11,-26,7,STAINED_GLASS:11)
B(12,-26,7,STAINED_GLASS:11)
B(13,-26,7,STAINED_GLASS:10)
B(14,-26,7,STAINED_GLASS:15)
B(15,-26,7,STAINED_GLASS:15)
B(8,-26,8,STAINED_GLASS:15)
B(9,-26,8,STAINED_GLASS:10)
B(10,-26,8,STAINED_GLASS:10)
B(11,-26,8,STAINED_GLASS:10)
B(12,-26,8,STAINED_GLASS:10)
B(13,-26,8,STAINED_GLASS:10)
B(14,-26,8,STAINED_GLASS:15)
B(9,-26,9,STAINED_GLASS:15)
B(10,-26,9,STAINED_GLASS:3)
B(12,-26,9,STAINED_GLASS:15)
B(8,-25,0,STAINED_GLASS:15)
B(9,-25,0,STAINED_GLASS:10)
B(10,-25,0,STAINED_GLASS:10)
B(11,-25,0,STAINED_GLASS:15)
B(12,-25,0,STAINED_GLASS:10)
B(6,-25,1,STAINED_GLASS:15)
B(7,-25,1,STAINED_GLASS:15)
B(8,-25,1,STAINED_GLASS:10)
B(9,-25,1,STAINED_GLASS:3)
B(10,-25,1,STAINED_GLASS:15)
B(11,-25,1,STAINED_GLASS:10)
B(12,-25,1,STAINED_GLASS:11)
B(13,-25,1,STAINED_GLASS:15)
B(14,-25,1,STAINED_GLASS:15)
B(6,-25,2,STAINED_GLASS:15)
B(7,-25,2,STAINED_GLASS:15)
B(8,-25,2,STAINED_GLASS:10)
B(9,-25,2,STAINED_GLASS:10)
B(10,-25,2,STAINED_GLASS:10)
B(11,-25,2,STAINED_GLASS:11)
B(12,-25,2,STAINED_GLASS:11)
B(13,-25,2,STAINED_GLASS:10)
B(14,-25,2,STAINED_GLASS:15)
B(15,-25,2,STAINED_GLASS:15)
B(7,-25,3,STAINED_GLASS:10)
B(8,-25,3,PURPLE_GLAZED_TERRACOTTA:3)
B(9,-25,3,PURPLE_GLAZED_TERRACOTTA:3)
B(10,-25,3,PURPLE_GLAZED_TERRACOTTA:3)
B(11,-25,3,SEA_LANTERN)
B(12,-25,3,STAINED_GLASS:11)
B(13,-25,3,STAINED_GLASS:10)
B(14,-25,3,STAINED_GLASS:10)
B(15,-25,3,STAINED_GLASS:10)
B(7,-25,4,STAINED_GLASS:15)
B(8,-25,4,STAINED_GLASS:10)
B(9,-25,4,STAINED_GLASS:11)
B(10,-25,4,SEA_LANTERN)
B(11,-25,4,SEA_LANTERN)
B(12,-25,4,SEA_LANTERN)
B(13,-25,4,STAINED_GLASS:11)
B(14,-25,4,STAINED_GLASS:10)
B(15,-25,4,STAINED_GLASS:15)
B(7,-25,5,STAINED_GLASS:15)
B(8,-25,5,STAINED_GLASS:10)
B(9,-25,5,STAINED_GLASS:11)
B(10,-25,5,STAINED_GLASS:11)
B(11,-25,5,SEA_LANTERN)
B(12,-25,5,SEA_LANTERN)
B(13,-25,5,STAINED_GLASS:11)
B(14,-25,5,STAINED_GLASS:11)
B(15,-25,5,STAINED_GLASS:15)
B(7,-25,6,STAINED_GLASS:15)
B(8,-25,6,STAINED_GLASS:10)
B(9,-25,6,STAINED_GLASS:11)
B(10,-25,6,STAINED_GLASS:11)
B(11,-25,6,STAINED_GLASS:11)
B(12,-25,6,STAINED_GLASS:11)
B(13,-25,6,STAINED_GLASS:10)
B(14,-25,6,STAINED_GLASS:15)
B(15,-25,6,STAINED_GLASS:10)
B(8,-25,7,STAINED_GLASS:15)
B(9,-25,7,STAINED_GLASS:10)
B(10,-25,7,STAINED_GLASS:11)
B(11,-25,7,STAINED_GLASS:10)
B(12,-25,7,STAINED_GLASS:10)
B(13,-25,7,STAINED_GLASS:10)
B(14,-25,7,STAINED_GLASS:15)
B(9,-25,8,STAINED_GLASS:10)
B(10,-25,8,STAINED_GLASS:10)
B(11,-25,8,STAINED_GLASS:15)
B(12,-25,8,STAINED_GLASS:10)
B(13,-25,8,STAINED_GLASS:3)
B(9,-25,9,STAINED_GLASS:15)
B(6,-24,0,STAINED_GLASS:15)
B(7,-24,0,STAINED_GLASS:15)
B(8,-24,0,STAINED_GLASS:10)
B(9,-24,0,STAINED_GLASS:3)
B(10,-24,0,STAINED_GLASS:15)
B(11,-24,0,STAINED_GLASS:10)
B(12,-24,0,STAINED_GLASS:10)
B(13,-24,0,STAINED_GLASS:15)
B(14,-24,0,STAINED_GLASS:15)
B(6,-24,1,STAINED_GLASS:15)
B(7,-24,1,STAINED_GLASS:10)
B(8,-24,1,STAINED_GLASS:15)
B(9,-24,1,STAINED_GLASS:10)
B(10,-24,1,STAINED_GLASS:10)
B(11,-24,1,STAINED_GLASS:11)
B(12,-24,1,STAINED_GLASS:11)
B(13,-24,1,STAINED_GLASS:15)
B(14,-24,1,STAINED_GLASS:15)
B(6,-24,2,STAINED_GLASS:15)
B(7,-24,2,STAINED_GLASS:10)
B(8,-24,2,STAINED_GLASS:11)
B(9,-24,2,STAINED_GLASS:11)
B(10,-24,2,STAINED_GLASS:11)
B(11,-24,2,PURPLE_GLAZED_TERRACOTTA:3)
B(12,-24,2,STAINED_GLASS:11)
B(13,-24,2,STAINED_GLASS:10)
B(14,-24,2,STAINED_GLASS:10)
B(15,-24,2,STAINED_GLASS:15)
B(6,-24,3,STAINED_GLASS:15)
B(7,-24,3,STAINED_GLASS:10)
B(8,-24,3,STAINED_GLASS:11)
B(9,-24,3,STAINED_GLASS:11)
B(10,-24,3,SEA_LANTERN)
B(11,-24,3,SEA_LANTERN)
B(12,-24,3,STAINED_GLASS:11)
B(13,-24,3,STAINED_GLASS:10)
B(14,-24,3,STAINED_GLASS:10)
B(15,-24,3,STAINED_GLASS:10)
B(7,-24,4,STAINED_GLASS:15)
B(8,-24,4,STAINED_GLASS:10)
B(9,-24,4,STAINED_GLASS:11)
B(10,-24,4,SEA_LANTERN)
B(11,-24,4,SEA_LANTERN)
B(12,-24,4,STAINED_GLASS:11)
B(13,-24,4,STAINED_GLASS:11)
B(14,-24,4,STAINED_GLASS:10)
B(15,-24,4,STAINED_GLASS:15)
B(7,-24,5,STAINED_GLASS:10)
B(8,-24,5,STAINED_GLASS:10)
B(9,-24,5,STAINED_GLASS:11)
B(10,-24,5,STAINED_GLASS:11)
B(11,-24,5,STAINED_GLASS:11)
B(12,-24,5,STAINED_GLASS:11)
B(13,-24,5,STAINED_GLASS:11)
B(14,-24,5,STAINED_GLASS:10)
B(15,-24,5,STAINED_GLASS:15)
B(7,-24,6,STAINED_GLASS:15)
B(8,-24,6,STAINED_GLASS:10)
B(9,-24,6,STAINED_GLASS:11)
B(10,-24,6,STAINED_GLASS:11)
B(11,-24,6,STAINED_GLASS:10)
B(12,-24,6,STAINED_GLASS:10)
B(13,-24,6,STAINED_GLASS:15)
B(15,-24,6,STAINED_GLASS:15)
B(8,-24,7,STAINED_GLASS:15)
B(9,-24,7,STAINED_GLASS:10)
B(10,-24,7,STAINED_GLASS:10)
B(11,-24,7,STAINED_GLASS:3)
B(12,-24,7,STAINED_GLASS:10)
B(13,-24,7,STAINED_GLASS:3)
B(9,-24,8,STAINED_GLASS:15)
B(10,-24,8,STAINED_GLASS:15)
B(12,-24,8,STAINED_GLASS:3)
B(5,-23,0,STAINED_GLASS:15)
B(6,-23,0,STAINED_GLASS:10)
B(7,-23,0,STAINED_GLASS:10)
B(8,-23,0,STAINED_GLASS:3)
B(9,-23,0,STAINED_GLASS:10)
B(10,-23,0,STAINED_GLASS:10)
B(11,-23,0,STAINED_GLASS:11)
B(12,-23,0,STAINED_GLASS:10)
B(13,-23,0,STAINED_GLASS:15)
B(14,-23,0,STAINED_GLASS:15)
B(6,-23,1,STAINED_GLASS:15)
B(7,-23,1,STAINED_GLASS:15)
B(8,-23,1,STAINED_GLASS:10)
B(9,-23,1,STAINED_GLASS:11)
B(10,-23,1,STAINED_GLASS:11)
B(11,-23,1,STAINED_GLASS:11)
B(12,-23,1,STAINED_GLASS:11)
B(13,-23,1,STAINED_GLASS:15)
B(14,-23,1,STAINED_GLASS:15)
B(6,-23,2,STAINED_GLASS:15)
B(7,-23,2,STAINED_GLASS:11)
B(8,-23,2,STAINED_GLASS:11)
B(9,-23,2,STAINED_GLASS:11)
B(10,-23,2,STAINED_GLASS:11)
B(11,-23,2,SEA_LANTERN)
B(12,-23,2,STAINED_GLASS:11)
B(13,-23,2,STAINED_GLASS:10)
B(14,-23,2,STAINED_GLASS:10)
B(15,-23,2,STAINED_GLASS:15)
B(6,-23,3,STAINED_GLASS:15)
B(7,-23,3,STAINED_GLASS:10)
B(8,-23,3,STAINED_GLASS:11)
B(9,-23,3,STAINED_GLASS:11)
B(10,-23,3,SEA_LANTERN)
B(11,-23,3,SEA_LANTERN)
B(12,-23,3,STAINED_GLASS:11)
B(13,-23,3,STAINED_GLASS:10)
B(14,-23,3,STAINED_GLASS:15)
B(15,-23,3,STAINED_GLASS:15)
B(7,-23,4,STAINED_GLASS:15)
B(8,-23,4,STAINED_GLASS:10)
B(9,-23,4,STAINED_GLASS:11)
B(10,-23,4,SEA_LANTERN)
B(11,-23,4,STAINED_GLASS:11)
B(12,-23,4,STAINED_GLASS:11)
B(13,-23,4,STAINED_GLASS:11)
B(14,-23,4,STAINED_GLASS:10)
B(15,-23,4,STAINED_GLASS:15)
B(7,-23,5,STAINED_GLASS:10)
B(8,-23,5,STAINED_GLASS:10)
B(9,-23,5,STAINED_GLASS:11)
B(10,-23,5,STAINED_GLASS:11)
B(11,-23,5,STAINED_GLASS:11)
B(12,-23,5,STAINED_GLASS:11)
B(13,-23,5,STAINED_GLASS:10)
B(14,-23,5,STAINED_GLASS:15)
B(15,-23,5,STAINED_GLASS:15)
B(7,-23,6,STAINED_GLASS:15)
B(8,-23,6,STAINED_GLASS:15)
B(9,-23,6,STAINED_GLASS:11)
B(10,-23,6,STAINED_GLASS:10)
B(11,-23,6,STAINED_GLASS:10)
B(12,-23,6,STAINED_GLASS:10)
B(13,-23,6,STAINED_GLASS:3)
B(9,-23,7,STAINED_GLASS:10)
B(10,-23,7,STAINED_GLASS:15)
B(11,-23,7,STAINED_GLASS:3)
B(12,-23,7,STAINED_GLASS:3)
B(5,-22,0,STAINED_GLASS:15)
B(6,-22,0,STAINED_GLASS:15)
B(7,-22,0,STAINED_GLASS:15)
B(8,-22,0,STAINED_GLASS:10)
B(9,-22,0,STAINED_GLASS:11)
B(10,-22,0,STAINED_GLASS:11)
B(11,-22,0,STAINED_GLASS:11)
B(12,-22,0,STAINED_GLASS:10)
B(13,-22,0,STAINED_GLASS:15)
B(14,-22,0,STAINED_GLASS:15)
B(6,-22,1,STAINED_GLASS:15)
B(7,-22,1,STAINED_GLASS:10)
B(8,-22,1,STAINED_GLASS:11)
B(9,-22,1,STAINED_GLASS:11)
B(10,-22,1,STAINED_GLASS:11)
B(11,-22,1,STAINED_GLASS:11)
B(12,-22,1,STAINED_GLASS:11)
B(13,-22,1,STAINED_GLASS:10)
B(14,-22,1,STAINED_GLASS:15)
B(5,-22,2,STAINED_GLASS:15)
B(6,-22,2,STAINED_GLASS:15)
B(7,-22,2,STAINED_GLASS:11)
B(8,-22,2,STAINED_GLASS:11)
B(9,-22,2,STAINED_GLASS:11)
B(10,-22,2,SEA_LANTERN)
B(11,-22,2,SEA_LANTERN)
B(12,-22,2,STAINED_GLASS:11)
B(13,-22,2,STAINED_GLASS:10)
B(14,-22,2,STAINED_GLASS:10)
B(15,-22,2,STAINED_GLASS:15)
B(6,-22,3,STAINED_GLASS:15)
B(7,-22,3,STAINED_GLASS:10)
B(8,-22,3,STAINED_GLASS:11)
B(9,-22,3,STAINED_GLASS:11)
B(10,-22,3,SEA_LANTERN)
B(11,-22,3,STAINED_GLASS:11)
B(12,-22,3,STAINED_GLASS:11)
B(13,-22,3,STAINED_GLASS:10)
B(14,-22,3,STAINED_GLASS:3)
B(15,-22,3,STAINED_GLASS:3)
B(7,-22,4,STAINED_GLASS:10)
B(8,-22,4,STAINED_GLASS:10)
B(9,-22,4,STAINED_GLASS:11)
B(10,-22,4,STAINED_GLASS:11)
B(11,-22,4,STAINED_GLASS:11)
B(12,-22,4,STAINED_GLASS:10)
B(13,-22,4,STAINED_GLASS:10)
B(14,-22,4,STAINED_GLASS:3)
B(7,-22,5,STAINED_GLASS:10)
B(8,-22,5,STAINED_GLASS:10)
B(9,-22,5,STAINED_GLASS:11)
B(10,-22,5,STAINED_GLASS:11)
B(11,-22,5,STAINED_GLASS:10)
B(12,-22,5,STAINED_GLASS:10)
B(13,-22,5,STAINED_GLASS:3)
B(7,-22,6,STAINED_GLASS:15)
B(8,-22,6,STAINED_GLASS:15)
B(9,-22,6,STAINED_GLASS:10)
B(10,-22,6,STAINED_GLASS:15)
B(11,-22,6,STAINED_GLASS:3)
B(12,-22,6,STAINED_GLASS:3)
B(9,-22,7,STAINED_GLASS:15)
B(5,-21,0,STAINED_GLASS:15)
B(6,-21,0,STAINED_GLASS:10)
B(7,-21,0,STAINED_GLASS:10)
B(8,-21,0,STAINED_GLASS:11)
B(9,-21,0,STAINED_GLASS:11)
B(10,-21,0,STAINED_GLASS:11)
B(11,-21,0,STAINED_GLASS:11)
B(12,-21,0,STAINED_GLASS:10)
B(13,-21,0,STAINED_GLASS:3)
B(14,-21,0,STAINED_GLASS:3)
B(6,-21,1,STAINED_GLASS:15)
B(7,-21,1,STAINED_GLASS:11)
B(8,-21,1,STAINED_GLASS:11)
B(9,-21,1,SEA_LANTERN)
B(10,-21,1,SEA_LANTERN)
B(11,-21,1,STAINED_GLASS:11)
B(12,-21,1,STAINED_GLASS:11)
B(13,-21,1,STAINED_GLASS:10)
B(14,-21,1,STAINED_GLASS:3)
B(5,-21,2,STAINED_GLASS:15)
B(6,-21,2,STAINED_GLASS:15)
B(7,-21,2,STAINED_GLASS:11)
B(8,-21,2,STAINED_GLASS:11)
B(9,-21,2,STAINED_GLASS:11)
B(10,-21,2,SEA_LANTERN)
B(11,-21,2,SEA_LANTERN)
B(12,-21,2,STAINED_GLASS:11)
B(13,-21,2,STAINED_GLASS:10)
B(14,-21,2,STAINED_GLASS:3)
B(6,-21,3,STAINED_GLASS:15)
B(7,-21,3,STAINED_GLASS:10)
B(8,-21,3,STAINED_GLASS:11)
B(9,-21,3,STAINED_GLASS:11)
B(10,-21,3,STAINED_GLASS:11)
B(11,-21,3,STAINED_GLASS:11)
B(12,-21,3,STAINED_GLASS:10)
B(13,-21,3,STAINED_GLASS:10)
B(14,-21,3,STAINED_GLASS:3)
B(15,-21,3,STAINED_GLASS:3)
B(7,-21,4,STAINED_GLASS:10)
B(8,-21,4,STAINED_GLASS:10)
B(9,-21,4,STAINED_GLASS:11)
B(10,-21,4,STAINED_GLASS:11)
B(11,-21,4,STAINED_GLASS:10)
B(12,-21,4,STAINED_GLASS:10)
B(13,-21,4,STAINED_GLASS:3)
B(7,-21,5,STAINED_GLASS:15)
B(8,-21,5,STAINED_GLASS:10)
B(9,-21,5,STAINED_GLASS:10)
B(10,-21,5,STAINED_GLASS:10)
B(11,-21,5,STAINED_GLASS:10)
B(12,-21,5,STAINED_GLASS:10)
B(13,-21,5,STAINED_GLASS:3)
B(8,-21,6,STAINED_GLASS:15)
B(9,-21,6,STAINED_GLASS:15)
B(5,-20,0,STAINED_GLASS:15)
B(6,-20,0,STAINED_GLASS:10)
B(7,-20,0,STAINED_GLASS:11)
B(8,-20,0,STAINED_GLASS:11)
B(9,-20,0,SEA_LANTERN)
B(10,-20,0,STAINED_GLASS:11)
B(11,-20,0,STAINED_GLASS:11)
B(12,-20,0,STAINED_GLASS:10)
B(13,-20,0,STAINED_GLASS:3)
B(14,-20,0,STAINED_GLASS:3)
B(5,-20,1,STAINED_GLASS:15)
B(6,-20,1,STAINED_GLASS:15)
B(7,-20,1,STAINED_GLASS:11)
B(8,-20,1,STAINED_GLASS:11)
B(9,-20,1,SEA_LANTERN)
B(10,-20,1,SEA_LANTERN)
B(11,-20,1,PURPLE_GLAZED_TERRACOTTA:3)
B(12,-20,1,PURPLE_GLAZED_TERRACOTTA:3)
B(13,-20,1,STAINED_GLASS:10)
B(14,-20,1,STAINED_GLASS:3)
B(5,-20,2,STAINED_GLASS:15)
B(6,-20,2,STAINED_GLASS:10)
B(7,-20,2,STAINED_GLASS:11)
B(8,-20,2,STAINED_GLASS:11)
B(9,-20,2,STAINED_GLASS:11)
B(10,-20,2,SEA_LANTERN)
B(11,-20,2,PURPLE_GLAZED_TERRACOTTA:3)
B(12,-20,2,PURPLE_GLAZED_TERRACOTTA:3)
B(13,-20,2,STAINED_GLASS:10)
B(14,-20,2,STAINED_GLASS:3)
B(6,-20,3,STAINED_GLASS:15)
B(7,-20,3,STAINED_GLASS:10)
B(8,-20,3,STAINED_GLASS:11)
B(9,-20,3,STAINED_GLASS:11)
B(10,-20,3,STAINED_GLASS:11)
B(11,-20,3,STAINED_GLASS:10)
B(12,-20,3,STAINED_GLASS:3)
B(13,-20,3,STAINED_GLASS:3)
B(7,-20,4,STAINED_GLASS:10)
B(8,-20,4,STAINED_GLASS:10)
B(9,-20,4,STAINED_GLASS:10)
B(10,-20,4,STAINED_GLASS:10)
B(11,-20,4,STAINED_GLASS:10)
B(12,-20,4,STAINED_GLASS:15)
B(7,-20,5,STAINED_GLASS:15)
B(8,-20,5,STAINED_GLASS:15)
B(9,-20,5,STAINED_GLASS:15)
B(10,-20,5,STAINED_GLASS:15)
B(11,-20,5,STAINED_GLASS:15)
B(12,-20,5,STAINED_GLASS:15)
B(5,-19,0,STAINED_GLASS:15)
B(6,-19,0,STAINED_GLASS:10)
B(7,-19,0,STAINED_GLASS:11)
B(8,-19,0,SEA_LANTERN)
B(9,-19,0,SEA_LANTERN)
B(10,-19,0,PURPLE_GLAZED_TERRACOTTA:3)
B(11,-19,0,PURPLE_GLAZED_TERRACOTTA:3)
B(12,-19,0,STAINED_GLASS:10)
B(13,-19,0,STAINED_GLASS:3)
B(14,-19,0,STAINED_GLASS:3)
B(5,-19,1,STAINED_GLASS:15)
B(6,-19,1,STAINED_GLASS:15)
B(7,-19,1,STAINED_GLASS:11)
B(8,-19,1,STAINED_GLASS:11)
B(9,-19,1,SEA_LANTERN)
B(10,-19,1,SEA_LANTERN)
B(11,-19,1,PURPLE_GLAZED_TERRACOTTA:3)
B(12,-19,1,PURPLE_GLAZED_TERRACOTTA:3)
B(13,-19,1,STAINED_GLASS:3)
B(5,-19,2,STAINED_GLASS:15)
B(6,-19,2,STAINED_GLASS:10)
B(7,-19,2,STAINED_GLASS:11)
B(8,-19,2,STAINED_GLASS:11)
B(9,-19,2,STAINED_GLASS:11)
B(10,-19,2,STAINED_GLASS:11)
B(11,-19,2,STAINED_GLASS:11)
B(12,-19,2,STAINED_GLASS:10)
B(13,-19,2,STAINED_GLASS:10)
B(14,-19,2,STAINED_GLASS:3)
B(6,-19,3,STAINED_GLASS:15)
B(7,-19,3,STAINED_GLASS:10)
B(8,-19,3,STAINED_GLASS:11)
B(9,-19,3,STAINED_GLASS:10)
B(10,-19,3,STAINED_GLASS:10)
B(11,-19,3,STAINED_GLASS:10)
B(12,-19,3,STAINED_GLASS:3)
B(7,-19,4,STAINED_GLASS:15)
B(8,-19,4,STAINED_GLASS:10)
B(9,-19,4,STAINED_GLASS:15)
B(10,-19,4,STAINED_GLASS:10)
B(11,-19,4,STAINED_GLASS:15)
B(7,-19,5,STAINED_GLASS:15)
B(9,-19,5,STAINED_GLASS:15)
B(10,-19,5,STAINED_GLASS:15)
B(5,-18,0,STAINED_GLASS:15)
B(6,-18,0,STAINED_GLASS:10)
B(7,-18,0,STAINED_GLASS:11)
B(8,-18,0,SEA_LANTERN)
B(9,-18,0,SEA_LANTERN)
B(10,-18,0,PURPLE_GLAZED_TERRACOTTA:3)
B(11,-18,0,PURPLE_GLAZED_TERRACOTTA:3)
B(12,-18,0,STAINED_GLASS:10)
B(13,-18,0,STAINED_GLASS:15)
B(14,-18,0,STAINED_GLASS:15)
B(5,-18,1,STAINED_GLASS:15)
B(6,-18,1,STAINED_GLASS:10)
B(7,-18,1,STAINED_GLASS:11)
B(8,-18,1,STAINED_GLASS:11)
B(9,-18,1,STAINED_GLASS:11)
B(10,-18,1,STAINED_GLASS:11)
B(11,-18,1,STAINED_GLASS:11)
B(12,-18,1,STAINED_GLASS:10)
B(13,-18,1,STAINED_GLASS:15)
B(5,-18,2,STAINED_GLASS:15)
B(6,-18,2,STAINED_GLASS:10)
B(7,-18,2,STAINED_GLASS:11)
B(8,-18,2,STAINED_GLASS:11)
B(9,-18,2,STAINED_GLASS:11)
B(10,-18,2,STAINED_GLASS:11)
B(11,-18,2,STAINED_GLASS:10)
B(12,-18,2,STAINED_GLASS:3)
B(13,-18,2,STAINED_GLASS:3)
B(6,-18,3,STAINED_GLASS:15)
B(7,-18,3,STAINED_GLASS:10)
B(8,-18,3,STAINED_GLASS:10)
B(9,-18,3,STAINED_GLASS:15)
B(10,-18,3,STAINED_GLASS:10)
B(11,-18,3,STAINED_GLASS:15)
B(7,-18,4,STAINED_GLASS:15)
B(8,-18,4,STAINED_GLASS:15)
B(10,-18,4,STAINED_GLASS:15)
B(5,-17,0,STAINED_GLASS:15)
B(6,-17,0,STAINED_GLASS:10)
B(7,-17,0,STAINED_GLASS:11)
B(8,-17,0,SEA_LANTERN)
B(9,-17,0,STAINED_GLASS:11)
B(10,-17,0,STAINED_GLASS:11)
B(11,-17,0,STAINED_GLASS:11)
B(12,-17,0,STAINED_GLASS:10)
B(5,-17,1,STAINED_GLASS:15)
B(6,-17,1,STAINED_GLASS:10)
B(7,-17,1,STAINED_GLASS:11)
B(8,-17,1,STAINED_GLASS:11)
B(9,-17,1,STAINED_GLASS:11)
B(10,-17,1,STAINED_GLASS:11)
B(11,-17,1,STAINED_GLASS:10)
B(12,-17,1,STAINED_GLASS:3)
B(13,-17,1,STAINED_GLASS:3)
B(5,-17,2,STAINED_GLASS:15)
B(6,-17,2,STAINED_GLASS:15)
B(7,-17,2,STAINED_GLASS:11)
B(8,-17,2,STAINED_GLASS:10)
B(9,-17,2,STAINED_GLASS:10)
B(10,-17,2,STAINED_GLASS:10)
B(11,-17,2,STAINED_GLASS:10)
B(12,-17,2,STAINED_GLASS:3)
B(7,-17,3,STAINED_GLASS:10)
B(8,-17,3,STAINED_GLASS:15)
B(9,-17,3,STAINED_GLASS:15)
B(10,-17,3,STAINED_GLASS:15)
B(7,-17,4,STAINED_GLASS:15)
B(5,-16,0,STAINED_GLASS:10)
B(6,-16,0,STAINED_GLASS:10)
B(7,-16,0,STAINED_GLASS:11)
B(8,-16,0,STAINED_GLASS:11)
B(9,-16,0,STAINED_GLASS:11)
B(10,-16,0,STAINED_GLASS:11)
B(11,-16,0,STAINED_GLASS:10)
B(12,-16,0,STAINED_GLASS:3)
B(5,-16,1,STAINED_GLASS:15)
B(6,-16,1,STAINED_GLASS:10)
B(7,-16,1,STAINED_GLASS:11)
B(8,-16,1,STAINED_GLASS:11)
B(9,-16,1,STAINED_GLASS:10)
B(10,-16,1,STAINED_GLASS:10)
B(11,-16,1,STAINED_GLASS:3)
B(5,-16,2,STAINED_GLASS:15)
B(6,-16,2,STAINED_GLASS:15)
B(7,-16,2,STAINED_GLASS:10)
B(8,-16,2,STAINED_GLASS:15)
B(9,-16,2,STAINED_GLASS:15)
B(10,-16,2,STAINED_GLASS:10)
B(11,-16,2,STAINED_GLASS:3)
B(7,-16,3,STAINED_GLASS:15)
B(5,-15,0,STAINED_GLASS:15)
B(6,-15,0,STAINED_GLASS:3)
B(7,-15,0,STAINED_GLASS:10)
B(8,-15,0,STAINED_GLASS:10)
B(9,-15,0,STAINED_GLASS:3)
B(10,-15,0,STAINED_GLASS:3)
B(11,-15,0,STAINED_GLASS:3)
B(5,-15,1,STAINED_GLASS:3)
B(6,-15,1,STAINED_GLASS:3)
B(7,-15,1,STAINED_GLASS:10)
B(8,-15,1,STAINED_GLASS:15)
B(9,-15,1,STAINED_GLASS:3)
B(10,-15,1,STAINED_GLASS:3)
B(11,-15,1,STAINED_GLASS:3)
B(6,-15,2,STAINED_GLASS:15)
B(7,-15,2,STAINED_GLASS:15)
B(8,-15,2,STAINED_GLASS:15)
B(9,-15,2,STAINED_GLASS:15)
B(10,-15,2,STAINED_GLASS:3)
B(5,-14,0,STAINED_GLASS:15)
B(6,-14,0,STAINED_GLASS:15)
B(7,-14,0,STAINED_GLASS:10)
B(8,-14,0,STAINED_GLASS:3)
B(9,-14,0,STAINED_GLASS:3)
B(10,-14,0,STAINED_GLASS:3)
B(5,-14,1,STAINED_GLASS:3)
B(6,-14,1,STAINED_GLASS:3)
B(7,-14,1,STAINED_GLASS:15)
B(8,-14,1,STAINED_GLASS:15)
B(9,-14,1,STAINED_GLASS:3)
B(10,-14,1,STAINED_GLASS:3)
B(5,-13,0,STAINED_GLASS:15)
B(6,-13,0,STAINED_GLASS:15)
B(7,-13,0,STAINED_GLASS:15)
B(8,-13,0,STAINED_GLASS:15)
B(9,-13,0,STAINED_GLASS:15)
B(10,-13,0,STAINED_GLASS:3)
B(6,-13,1,STAINED_GLASS:3)
B(7,-13,1,STAINED_GLASS:15)
B(8,-13,1,STAINED_GLASS:15)
B(5,-12,0,STAINED_GLASS:15)
B(6,-12,0,STAINED_GLASS:15)
B(7,-12,0,STAINED_GLASS:15)
B(8,-12,0,STAINED_GLASS:15)
B(5,-11,0,STAINED_GLASS:15)
B(7,-11,0,STAINED_GLASS:15)

#######################################################################
# +-----------------------------------------------------------------+ #
# |                             Branches                            | #
# +-----------------------------------------------------------------+ #
#######################################################################

BR(16,0,0,true,CEILING_SPIKE-SET-FAT-MED-05_1x1,NORTH,100,0)
