
#######################################################################
# +-----------------------------------------------------------------+ #
# |                            BO3 object                           | #
# +-----------------------------------------------------------------+ #
#######################################################################

Author: BO3 BulkEdit (by LanToaster)

Description: This Object was Created with BO3_BulkEdit

Version: 3

SettingsMode: WriteWithoutComments


#######################################################################
# +-----------------------------------------------------------------+ #
# |                          Main settings                          | #
# +-----------------------------------------------------------------+ #
#######################################################################

Tree: false

Frequency: 1

Rarity: 100.0

RotateRandomly: false

SpawnHeight: randomY

SpawnHeightOffset: 0

SpawnHeightVariance: 0

##############################
# Height Limits for the BO3. #
##############################

MinHeight: 82

MaxHeight: 82

######################
# Extrusion settings #
######################

ExtrudeMode: None

ExtrudeThroughBlocks: minecraft:air

MaxBranchDepth: 10


#######################################################################
# +-----------------------------------------------------------------+ #
# |                      Source block settings                      | #
# +-----------------------------------------------------------------+ #
#######################################################################

SourceBlocks: otg:air

MaxPercentageOutsideSourceBlock: 100

OutsideSourceBlock: placeAnyway

DoReplaceBlocks: true

IsOTGPlus: false


#######################################################################
# +-----------------------------------------------------------------+ #
# |                              Blocks                             | #
# +-----------------------------------------------------------------+ #
#######################################################################

B(-7,-1,0,minecraft:jungle_leaves[distance=7,persistent=true])
B(-7,0,1,minecraft:jungle_leaves[distance=7,persistent=true])
B(-7,0,2,minecraft:stone_brick_stairs)
B(-7,1,2,minecraft:jungle_leaves[distance=7,persistent=true])
B(-7,2,2,minecraft:vine[east=false,north=false,south=true,up=false,west=false])
B(-7,3,2,minecraft:vine[east=false,north=false,south=true,up=false,west=false])
B(-7,1,3,minecraft:jungle_leaves[distance=7,persistent=true])
B(-7,2,3,minecraft:jungle_leaves[distance=7,persistent=true])
B(-7,3,3,minecraft:jungle_leaves[distance=7,persistent=true])
B(-7,3,4,minecraft:jungle_leaves[distance=7,persistent=true])
B(-7,3,6,minecraft:grass_block)
B(-7,3,7,minecraft:grass_block)
B(-7,3,8,minecraft:grass_block)
B(-6,0,1,minecraft:stone_brick_stairs[facing=south,half=bottom,shape=straight,waterlogged=false])
B(-6,0,2,minecraft:stone_brick_stairs)
B(-6,1,2,minecraft:stone_brick_stairs[facing=south,half=bottom,shape=straight,waterlogged=false])
B(-6,2,2,minecraft:vine[east=false,north=false,south=true,up=false,west=false])
B(-6,2,3,minecraft:chiseled_stone_bricks)
B(-6,3,3,minecraft:stone_brick_stairs[facing=south,half=bottom,shape=straight,waterlogged=false])
B(-5,0,1,minecraft:stone_brick_stairs[facing=south,half=bottom,shape=straight,waterlogged=false])
B(-5,0,2,minecraft:stone_brick_stairs)
B(-5,0,3,minecraft:jungle_leaves[distance=7,persistent=true])
B(-5,1,3,minecraft:jungle_leaves[distance=7,persistent=true])
B(-5,2,3,minecraft:jungle_leaves[distance=7,persistent=true])
B(-5,3,4,minecraft:jungle_leaves[distance=7,persistent=true])
B(-5,3,6,minecraft:stone_brick_slab[type=double,waterlogged=false])
B(-4,-1,0,minecraft:jungle_leaves[distance=7,persistent=true])
B(-4,0,1,minecraft:jungle_leaves[distance=7,persistent=true])
B(-4,0,2,minecraft:jungle_leaves[distance=7,persistent=true])
B(-4,0,3,minecraft:jungle_leaves[distance=7,persistent=true])
B(-4,1,4,minecraft:jungle_leaves[distance=7,persistent=true])
B(-4,2,5,minecraft:chiseled_stone_bricks)
B(-4,3,5,minecraft:stone_brick_stairs[facing=west,half=bottom,shape=straight,waterlogged=false])
B(-4,1,6,minecraft:jungle_leaves[distance=7,persistent=true])
B(-4,1,7,minecraft:jungle_leaves[distance=7,persistent=true])
B(-4,2,7,minecraft:vine[east=false,north=false,south=true,up=false,west=false])
B(-4,2,8,minecraft:chiseled_stone_bricks)
B(-4,3,8,minecraft:stone_brick_stairs[facing=west,half=bottom,shape=straight,waterlogged=false])
B(-3,-1,0,minecraft:jungle_leaves[distance=7,persistent=true])
B(-3,0,1,minecraft:stone_brick_stairs[facing=south,half=bottom,shape=straight,waterlogged=false])
B(-3,0,2,minecraft:stone_brick_stairs)
B(-3,0,3,minecraft:jungle_leaves[distance=7,persistent=true])
B(-3,0,4,minecraft:stone_brick_stairs[facing=east,half=bottom,shape=straight,waterlogged=false])
B(-3,0,5,minecraft:stone_brick_stairs[facing=east,half=bottom,shape=straight,waterlogged=false])
B(-3,1,5,minecraft:stone_brick_stairs[facing=west,half=bottom,shape=straight,waterlogged=false])
B(-3,0,6,minecraft:stone_brick_stairs[facing=east,half=bottom,shape=straight,waterlogged=false])
B(-3,1,6,minecraft:jungle_leaves[distance=7,persistent=true])
B(-3,0,7,minecraft:jungle_leaves[distance=7,persistent=true])
B(-3,0,8,minecraft:stone_brick_stairs[facing=east,half=bottom,shape=straight,waterlogged=false])
B(-3,1,8,minecraft:stone_brick_stairs[facing=west,half=bottom,shape=straight,waterlogged=false])
B(-3,2,8,minecraft:vine[east=false,north=false,south=false,up=false,west=true])
B(-2,0,1,minecraft:stone_brick_stairs[facing=south,half=bottom,shape=outer_right,waterlogged=false])
B(-2,0,2,minecraft:stone_brick_stairs[facing=west,half=bottom,shape=outer_right,waterlogged=false])
B(-2,0,3,minecraft:jungle_leaves[distance=7,persistent=true])
B(-2,0,4,minecraft:jungle_leaves[distance=7,persistent=true])
B(-2,0,5,minecraft:jungle_leaves[distance=7,persistent=true])
B(-2,-1,6,minecraft:jungle_leaves[distance=7,persistent=true])
B(-2,0,6,minecraft:jungle_leaves[distance=7,persistent=true])
B(-2,0,7,minecraft:stone_brick_stairs[facing=west,half=bottom,shape=straight,waterlogged=false])
B(-2,0,8,minecraft:stone_brick_stairs[facing=west,half=bottom,shape=straight,waterlogged=false])
RB(-7,-1,1,minecraft:mossy_stone_bricks,10,minecraft:cracked_stone_bricks,10,minecraft:cobblestone,10,minecraft:mossy_cobblestone,10,minecraft:stone_bricks,100)
RB(-6,-1,1,minecraft:mossy_stone_bricks,10,minecraft:cracked_stone_bricks,10,minecraft:cobblestone,10,minecraft:mossy_cobblestone,10,minecraft:stone_bricks,100)
RB(-5,-1,1,minecraft:mossy_stone_bricks,10,minecraft:cracked_stone_bricks,10,minecraft:cobblestone,10,minecraft:mossy_cobblestone,10,minecraft:stone_bricks,100)
RB(-4,-1,1,minecraft:mossy_stone_bricks,10,minecraft:cracked_stone_bricks,10,minecraft:cobblestone,10,minecraft:mossy_cobblestone,10,minecraft:stone_bricks,100)
RB(-3,-1,1,minecraft:mossy_stone_bricks,10,minecraft:cracked_stone_bricks,10,minecraft:cobblestone,10,minecraft:mossy_cobblestone,10,minecraft:stone_bricks,100)
RB(-2,-1,1,minecraft:mossy_stone_bricks,10,minecraft:cracked_stone_bricks,10,minecraft:cobblestone,10,minecraft:mossy_cobblestone,10,minecraft:stone_bricks,100)
RB(-7,-1,2,minecraft:mossy_stone_bricks,10,minecraft:cracked_stone_bricks,10,minecraft:cobblestone,10,minecraft:mossy_cobblestone,10,minecraft:stone_bricks,100)
RB(-6,-1,2,minecraft:mossy_stone_bricks,10,minecraft:cracked_stone_bricks,10,minecraft:cobblestone,10,minecraft:mossy_cobblestone,10,minecraft:stone_bricks,100)
RB(-5,-1,2,minecraft:mossy_stone_bricks,10,minecraft:cracked_stone_bricks,10,minecraft:cobblestone,10,minecraft:mossy_cobblestone,10,minecraft:stone_bricks,100)
RB(-4,-1,2,minecraft:mossy_stone_bricks,10,minecraft:cracked_stone_bricks,10,minecraft:cobblestone,10,minecraft:mossy_cobblestone,10,minecraft:stone_bricks,100)
RB(-3,-1,2,minecraft:mossy_stone_bricks,10,minecraft:cracked_stone_bricks,10,minecraft:cobblestone,10,minecraft:mossy_cobblestone,10,minecraft:stone_bricks,100)
RB(-2,-1,2,minecraft:mossy_stone_bricks,10,minecraft:cracked_stone_bricks,10,minecraft:cobblestone,10,minecraft:mossy_cobblestone,10,minecraft:stone_bricks,100)
RB(-7,-1,3,minecraft:mossy_stone_bricks,10,minecraft:cracked_stone_bricks,10,minecraft:cobblestone,10,minecraft:mossy_cobblestone,10,minecraft:stone_bricks,100)
RB(-6,-1,3,minecraft:mossy_stone_bricks,10,minecraft:cracked_stone_bricks,10,minecraft:cobblestone,10,minecraft:mossy_cobblestone,10,minecraft:stone_bricks,100)
RB(-5,-1,3,minecraft:mossy_stone_bricks,10,minecraft:cracked_stone_bricks,10,minecraft:cobblestone,10,minecraft:mossy_cobblestone,10,minecraft:stone_bricks,100)
RB(-4,-1,3,minecraft:mossy_stone_bricks,10,minecraft:cracked_stone_bricks,10,minecraft:cobblestone,10,minecraft:mossy_cobblestone,10,minecraft:stone_bricks,100)
RB(-3,-1,3,minecraft:mossy_stone_bricks,10,minecraft:cracked_stone_bricks,10,minecraft:cobblestone,10,minecraft:mossy_cobblestone,10,minecraft:stone_bricks,100)
RB(-2,-1,3,minecraft:mossy_stone_bricks,10,minecraft:cracked_stone_bricks,10,minecraft:cobblestone,10,minecraft:mossy_cobblestone,10,minecraft:stone_bricks,100)
RB(-7,-1,4,minecraft:mossy_stone_bricks,10,minecraft:cracked_stone_bricks,10,minecraft:cobblestone,10,minecraft:mossy_cobblestone,10,minecraft:stone_bricks,100)
RB(-6,-1,4,minecraft:mossy_stone_bricks,10,minecraft:cracked_stone_bricks,10,minecraft:cobblestone,10,minecraft:mossy_cobblestone,10,minecraft:stone_bricks,100)
RB(-5,-1,4,minecraft:mossy_stone_bricks,10,minecraft:cracked_stone_bricks,10,minecraft:cobblestone,10,minecraft:mossy_cobblestone,10,minecraft:stone_bricks,100)
RB(-4,-1,4,minecraft:mossy_stone_bricks,10,minecraft:cracked_stone_bricks,10,minecraft:cobblestone,10,minecraft:mossy_cobblestone,10,minecraft:stone_bricks,100)
RB(-3,-1,4,minecraft:mossy_stone_bricks,10,minecraft:cracked_stone_bricks,10,minecraft:cobblestone,10,minecraft:mossy_cobblestone,10,minecraft:stone_bricks,100)
RB(-2,-1,4,minecraft:mossy_stone_bricks,10,minecraft:cracked_stone_bricks,10,minecraft:cobblestone,10,minecraft:mossy_cobblestone,10,minecraft:stone_bricks,100)
RB(-7,-1,5,minecraft:mossy_stone_bricks,10,minecraft:cracked_stone_bricks,10,minecraft:cobblestone,10,minecraft:mossy_cobblestone,10,minecraft:stone_bricks,100)
RB(-6,-1,5,minecraft:mossy_stone_bricks,10,minecraft:cracked_stone_bricks,10,minecraft:cobblestone,10,minecraft:mossy_cobblestone,10,minecraft:stone_bricks,100)
RB(-5,-1,5,minecraft:mossy_stone_bricks,10,minecraft:cracked_stone_bricks,10,minecraft:cobblestone,10,minecraft:mossy_cobblestone,10,minecraft:stone_bricks,100)
RB(-4,-1,5,minecraft:mossy_stone_bricks,10,minecraft:cracked_stone_bricks,10,minecraft:cobblestone,10,minecraft:mossy_cobblestone,10,minecraft:stone_bricks,100)
RB(-3,-1,5,minecraft:mossy_stone_bricks,10,minecraft:cracked_stone_bricks,10,minecraft:cobblestone,10,minecraft:mossy_cobblestone,10,minecraft:stone_bricks,100)
RB(-2,-1,5,minecraft:mossy_stone_bricks,10,minecraft:cracked_stone_bricks,10,minecraft:cobblestone,10,minecraft:mossy_cobblestone,10,minecraft:stone_bricks,100)
RB(-7,-1,6,minecraft:mossy_stone_bricks,10,minecraft:cracked_stone_bricks,10,minecraft:cobblestone,10,minecraft:mossy_cobblestone,10,minecraft:stone_bricks,100)
RB(-6,-1,6,minecraft:mossy_stone_bricks,10,minecraft:cracked_stone_bricks,10,minecraft:cobblestone,10,minecraft:mossy_cobblestone,10,minecraft:stone_bricks,100)
RB(-5,-1,6,minecraft:mossy_stone_bricks,10,minecraft:cracked_stone_bricks,10,minecraft:cobblestone,10,minecraft:mossy_cobblestone,10,minecraft:stone_bricks,100)
RB(-4,-1,6,minecraft:mossy_stone_bricks,10,minecraft:cracked_stone_bricks,10,minecraft:cobblestone,10,minecraft:mossy_cobblestone,10,minecraft:stone_bricks,100)
RB(-3,-1,6,minecraft:mossy_stone_bricks,10,minecraft:cracked_stone_bricks,10,minecraft:cobblestone,10,minecraft:mossy_cobblestone,10,minecraft:stone_bricks,100)
RB(-7,-1,7,minecraft:mossy_stone_bricks,10,minecraft:cracked_stone_bricks,10,minecraft:cobblestone,10,minecraft:mossy_cobblestone,10,minecraft:stone_bricks,100)
RB(-6,-1,7,minecraft:mossy_stone_bricks,10,minecraft:cracked_stone_bricks,10,minecraft:cobblestone,10,minecraft:mossy_cobblestone,10,minecraft:stone_bricks,100)
RB(-5,-1,7,minecraft:mossy_stone_bricks,10,minecraft:cracked_stone_bricks,10,minecraft:cobblestone,10,minecraft:mossy_cobblestone,10,minecraft:stone_bricks,100)
RB(-4,-1,7,minecraft:mossy_stone_bricks,10,minecraft:cracked_stone_bricks,10,minecraft:cobblestone,10,minecraft:mossy_cobblestone,10,minecraft:stone_bricks,100)
RB(-3,-1,7,minecraft:mossy_stone_bricks,10,minecraft:cracked_stone_bricks,10,minecraft:cobblestone,10,minecraft:mossy_cobblestone,10,minecraft:stone_bricks,100)
RB(-2,-1,7,minecraft:mossy_stone_bricks,10,minecraft:cracked_stone_bricks,10,minecraft:cobblestone,10,minecraft:mossy_cobblestone,10,minecraft:stone_bricks,100)
RB(-7,-1,8,minecraft:mossy_stone_bricks,10,minecraft:cracked_stone_bricks,10,minecraft:cobblestone,10,minecraft:mossy_cobblestone,10,minecraft:stone_bricks,100)
RB(-6,-1,8,minecraft:mossy_stone_bricks,10,minecraft:cracked_stone_bricks,10,minecraft:cobblestone,10,minecraft:mossy_cobblestone,10,minecraft:stone_bricks,100)
RB(-5,-1,8,minecraft:mossy_stone_bricks,10,minecraft:cracked_stone_bricks,10,minecraft:cobblestone,10,minecraft:mossy_cobblestone,10,minecraft:stone_bricks,100)
RB(-4,-1,8,minecraft:mossy_stone_bricks,10,minecraft:cracked_stone_bricks,10,minecraft:cobblestone,10,minecraft:mossy_cobblestone,10,minecraft:stone_bricks,100)
RB(-3,-1,8,minecraft:mossy_stone_bricks,10,minecraft:cracked_stone_bricks,10,minecraft:cobblestone,10,minecraft:mossy_cobblestone,10,minecraft:stone_bricks,100)
RB(-2,-1,8,minecraft:mossy_stone_bricks,10,minecraft:cracked_stone_bricks,10,minecraft:cobblestone,10,minecraft:mossy_cobblestone,10,minecraft:stone_bricks,100)
RB(-7,0,3,minecraft:mossy_stone_bricks,10,minecraft:cracked_stone_bricks,10,minecraft:cobblestone,10,minecraft:mossy_cobblestone,10,minecraft:stone_bricks,100)
RB(-6,0,3,minecraft:mossy_stone_bricks,10,minecraft:cracked_stone_bricks,10,minecraft:cobblestone,10,minecraft:mossy_cobblestone,10,minecraft:stone_bricks,100)
RB(-7,0,4,minecraft:mossy_stone_bricks,10,minecraft:cracked_stone_bricks,10,minecraft:cobblestone,10,minecraft:mossy_cobblestone,10,minecraft:stone_bricks,100)
RB(-6,0,4,minecraft:mossy_stone_bricks,10,minecraft:cracked_stone_bricks,10,minecraft:cobblestone,10,minecraft:mossy_cobblestone,10,minecraft:stone_bricks,100)
RB(-5,0,4,minecraft:mossy_stone_bricks,10,minecraft:cracked_stone_bricks,10,minecraft:cobblestone,10,minecraft:mossy_cobblestone,10,minecraft:stone_bricks,100)
RB(-4,0,4,minecraft:mossy_stone_bricks,10,minecraft:cracked_stone_bricks,10,minecraft:cobblestone,10,minecraft:mossy_cobblestone,10,minecraft:stone_bricks,100)
RB(-7,0,5,minecraft:mossy_stone_bricks,10,minecraft:cracked_stone_bricks,10,minecraft:cobblestone,10,minecraft:mossy_cobblestone,10,minecraft:stone_bricks,100)
RB(-6,0,5,minecraft:mossy_stone_bricks,10,minecraft:cracked_stone_bricks,10,minecraft:cobblestone,10,minecraft:mossy_cobblestone,10,minecraft:stone_bricks,100)
RB(-5,0,5,minecraft:mossy_stone_bricks,10,minecraft:cracked_stone_bricks,10,minecraft:cobblestone,10,minecraft:mossy_cobblestone,10,minecraft:stone_bricks,100)
RB(-4,0,5,minecraft:mossy_stone_bricks,10,minecraft:cracked_stone_bricks,10,minecraft:cobblestone,10,minecraft:mossy_cobblestone,10,minecraft:stone_bricks,100)
RB(-7,0,6,minecraft:mossy_stone_bricks,10,minecraft:cracked_stone_bricks,10,minecraft:cobblestone,10,minecraft:mossy_cobblestone,10,minecraft:stone_bricks,100)
RB(-6,0,6,minecraft:mossy_stone_bricks,10,minecraft:cracked_stone_bricks,10,minecraft:cobblestone,10,minecraft:mossy_cobblestone,10,minecraft:stone_bricks,100)
RB(-5,0,6,minecraft:mossy_stone_bricks,10,minecraft:cracked_stone_bricks,10,minecraft:cobblestone,10,minecraft:mossy_cobblestone,10,minecraft:stone_bricks,100)
RB(-4,0,6,minecraft:mossy_stone_bricks,10,minecraft:cracked_stone_bricks,10,minecraft:cobblestone,10,minecraft:mossy_cobblestone,10,minecraft:stone_bricks,100)
RB(-7,0,7,minecraft:mossy_stone_bricks,10,minecraft:cracked_stone_bricks,10,minecraft:cobblestone,10,minecraft:mossy_cobblestone,10,minecraft:stone_bricks,100)
RB(-6,0,7,minecraft:mossy_stone_bricks,10,minecraft:cracked_stone_bricks,10,minecraft:cobblestone,10,minecraft:mossy_cobblestone,10,minecraft:stone_bricks,100)
RB(-5,0,7,minecraft:mossy_stone_bricks,10,minecraft:cracked_stone_bricks,10,minecraft:cobblestone,10,minecraft:mossy_cobblestone,10,minecraft:stone_bricks,100)
RB(-4,0,7,minecraft:mossy_stone_bricks,10,minecraft:cracked_stone_bricks,10,minecraft:cobblestone,10,minecraft:mossy_cobblestone,10,minecraft:stone_bricks,100)
RB(-7,0,8,minecraft:mossy_stone_bricks,10,minecraft:cracked_stone_bricks,10,minecraft:cobblestone,10,minecraft:mossy_cobblestone,10,minecraft:stone_bricks,100)
RB(-6,0,8,minecraft:mossy_stone_bricks,10,minecraft:cracked_stone_bricks,10,minecraft:cobblestone,10,minecraft:mossy_cobblestone,10,minecraft:stone_bricks,100)
RB(-5,0,8,minecraft:mossy_stone_bricks,10,minecraft:cracked_stone_bricks,10,minecraft:cobblestone,10,minecraft:mossy_cobblestone,10,minecraft:stone_bricks,100)
RB(-4,0,8,minecraft:mossy_stone_bricks,10,minecraft:cracked_stone_bricks,10,minecraft:cobblestone,10,minecraft:mossy_cobblestone,10,minecraft:stone_bricks,100)
RB(-6,1,3,minecraft:mossy_stone_bricks,10,minecraft:cracked_stone_bricks,10,minecraft:cobblestone,10,minecraft:mossy_cobblestone,10,minecraft:stone_bricks,100)
RB(-7,1,4,minecraft:mossy_stone_bricks,10,minecraft:cracked_stone_bricks,10,minecraft:cobblestone,10,minecraft:mossy_cobblestone,10,minecraft:stone_bricks,100)
RB(-6,1,4,minecraft:mossy_stone_bricks,10,minecraft:cracked_stone_bricks,10,minecraft:cobblestone,10,minecraft:mossy_cobblestone,10,minecraft:stone_bricks,100)
RB(-5,1,4,minecraft:mossy_stone_bricks,10,minecraft:cracked_stone_bricks,10,minecraft:cobblestone,10,minecraft:mossy_cobblestone,10,minecraft:stone_bricks,100)
RB(-7,1,5,minecraft:mossy_stone_bricks,10,minecraft:cracked_stone_bricks,10,minecraft:cobblestone,10,minecraft:mossy_cobblestone,10,minecraft:stone_bricks,100)
RB(-6,1,5,minecraft:mossy_stone_bricks,10,minecraft:cracked_stone_bricks,10,minecraft:cobblestone,10,minecraft:mossy_cobblestone,10,minecraft:stone_bricks,100)
RB(-5,1,5,minecraft:mossy_stone_bricks,10,minecraft:cracked_stone_bricks,10,minecraft:cobblestone,10,minecraft:mossy_cobblestone,10,minecraft:stone_bricks,100)
RB(-4,1,5,minecraft:mossy_stone_bricks,10,minecraft:cracked_stone_bricks,10,minecraft:cobblestone,10,minecraft:mossy_cobblestone,10,minecraft:stone_bricks,100)
RB(-7,1,6,minecraft:mossy_stone_bricks,10,minecraft:cracked_stone_bricks,10,minecraft:cobblestone,10,minecraft:mossy_cobblestone,10,minecraft:stone_bricks,100)
RB(-6,1,6,minecraft:mossy_stone_bricks,10,minecraft:cracked_stone_bricks,10,minecraft:cobblestone,10,minecraft:mossy_cobblestone,10,minecraft:stone_bricks,100)
RB(-5,1,6,minecraft:mossy_stone_bricks,10,minecraft:cracked_stone_bricks,10,minecraft:cobblestone,10,minecraft:mossy_cobblestone,10,minecraft:stone_bricks,100)
RB(-7,1,7,minecraft:mossy_stone_bricks,10,minecraft:cracked_stone_bricks,10,minecraft:cobblestone,10,minecraft:mossy_cobblestone,10,minecraft:stone_bricks,100)
RB(-6,1,7,minecraft:mossy_stone_bricks,10,minecraft:cracked_stone_bricks,10,minecraft:cobblestone,10,minecraft:mossy_cobblestone,10,minecraft:stone_bricks,100)
RB(-5,1,7,minecraft:mossy_stone_bricks,10,minecraft:cracked_stone_bricks,10,minecraft:cobblestone,10,minecraft:mossy_cobblestone,10,minecraft:stone_bricks,100)
RB(-7,1,8,minecraft:mossy_stone_bricks,10,minecraft:cracked_stone_bricks,10,minecraft:cobblestone,10,minecraft:mossy_cobblestone,10,minecraft:stone_bricks,100)
RB(-6,1,8,minecraft:mossy_stone_bricks,10,minecraft:cracked_stone_bricks,10,minecraft:cobblestone,10,minecraft:mossy_cobblestone,10,minecraft:stone_bricks,100)
RB(-5,1,8,minecraft:mossy_stone_bricks,10,minecraft:cracked_stone_bricks,10,minecraft:cobblestone,10,minecraft:mossy_cobblestone,10,minecraft:stone_bricks,100)
RB(-4,1,8,minecraft:mossy_stone_bricks,10,minecraft:cracked_stone_bricks,10,minecraft:cobblestone,10,minecraft:mossy_cobblestone,10,minecraft:stone_bricks,100)
RB(-7,2,4,minecraft:mossy_stone_bricks,10,minecraft:cracked_stone_bricks,10,minecraft:cobblestone,10,minecraft:mossy_cobblestone,10,minecraft:stone_bricks,100)
RB(-6,2,4,minecraft:mossy_stone_bricks,10,minecraft:cracked_stone_bricks,10,minecraft:cobblestone,10,minecraft:mossy_cobblestone,10,minecraft:stone_bricks,100)
RB(-5,2,4,minecraft:mossy_stone_bricks,10,minecraft:cracked_stone_bricks,10,minecraft:cobblestone,10,minecraft:mossy_cobblestone,10,minecraft:stone_bricks,100)
RB(-7,2,5,minecraft:mossy_stone_bricks,10,minecraft:cracked_stone_bricks,10,minecraft:cobblestone,10,minecraft:mossy_cobblestone,10,minecraft:stone_bricks,100)
RB(-6,2,5,minecraft:mossy_stone_bricks,10,minecraft:cracked_stone_bricks,10,minecraft:cobblestone,10,minecraft:mossy_cobblestone,10,minecraft:stone_bricks,100)
RB(-5,2,5,minecraft:mossy_stone_bricks,10,minecraft:cracked_stone_bricks,10,minecraft:cobblestone,10,minecraft:mossy_cobblestone,10,minecraft:stone_bricks,100)
RB(-7,2,6,minecraft:mossy_stone_bricks,10,minecraft:cracked_stone_bricks,10,minecraft:cobblestone,10,minecraft:mossy_cobblestone,10,minecraft:stone_bricks,100)
RB(-6,2,6,minecraft:mossy_stone_bricks,10,minecraft:cracked_stone_bricks,10,minecraft:cobblestone,10,minecraft:mossy_cobblestone,10,minecraft:stone_bricks,100)
RB(-5,2,6,minecraft:mossy_stone_bricks,10,minecraft:cracked_stone_bricks,10,minecraft:cobblestone,10,minecraft:mossy_cobblestone,10,minecraft:stone_bricks,100)
RB(-7,2,7,minecraft:mossy_stone_bricks,10,minecraft:cracked_stone_bricks,10,minecraft:cobblestone,10,minecraft:mossy_cobblestone,10,minecraft:stone_bricks,100)
RB(-6,2,7,minecraft:mossy_stone_bricks,10,minecraft:cracked_stone_bricks,10,minecraft:cobblestone,10,minecraft:mossy_cobblestone,10,minecraft:stone_bricks,100)
RB(-5,2,7,minecraft:mossy_stone_bricks,10,minecraft:cracked_stone_bricks,10,minecraft:cobblestone,10,minecraft:mossy_cobblestone,10,minecraft:stone_bricks,100)
RB(-7,2,8,minecraft:mossy_stone_bricks,10,minecraft:cracked_stone_bricks,10,minecraft:cobblestone,10,minecraft:mossy_cobblestone,10,minecraft:stone_bricks,100)
RB(-6,2,8,minecraft:mossy_stone_bricks,10,minecraft:cracked_stone_bricks,10,minecraft:cobblestone,10,minecraft:mossy_cobblestone,10,minecraft:stone_bricks,100)
RB(-5,2,8,minecraft:mossy_stone_bricks,10,minecraft:cracked_stone_bricks,10,minecraft:cobblestone,10,minecraft:mossy_cobblestone,10,minecraft:stone_bricks,100)
RB(-6,3,4,minecraft:mossy_stone_bricks,10,minecraft:cracked_stone_bricks,10,minecraft:cobblestone,10,minecraft:mossy_cobblestone,10,minecraft:stone_bricks,100)
RB(-7,3,5,minecraft:mossy_stone_bricks,10,minecraft:cracked_stone_bricks,10,minecraft:cobblestone,10,minecraft:mossy_cobblestone,10,minecraft:stone_bricks,100)
RB(-6,3,5,minecraft:mossy_stone_bricks,10,minecraft:cracked_stone_bricks,10,minecraft:cobblestone,10,minecraft:mossy_cobblestone,10,minecraft:stone_bricks,100)
RB(-5,3,5,minecraft:mossy_stone_bricks,10,minecraft:cracked_stone_bricks,10,minecraft:cobblestone,10,minecraft:mossy_cobblestone,10,minecraft:stone_bricks,100)
RB(-6,3,6,minecraft:mossy_stone_bricks,10,minecraft:cracked_stone_bricks,10,minecraft:cobblestone,10,minecraft:mossy_cobblestone,10,minecraft:stone_bricks,100)
RB(-6,3,7,minecraft:mossy_stone_bricks,10,minecraft:cracked_stone_bricks,10,minecraft:cobblestone,10,minecraft:mossy_cobblestone,10,minecraft:stone_bricks,100)
RB(-6,3,8,minecraft:mossy_stone_bricks,10,minecraft:cracked_stone_bricks,10,minecraft:cobblestone,10,minecraft:mossy_cobblestone,10,minecraft:stone_bricks,100)
RB(-5,3,8,minecraft:mossy_stone_bricks,10,minecraft:cracked_stone_bricks,10,minecraft:cobblestone,10,minecraft:mossy_cobblestone,10,minecraft:stone_bricks,100)

#######################################################################
# +-----------------------------------------------------------------+ #
# |                            BO3 checks                           | #
# +-----------------------------------------------------------------+ #
#######################################################################


#######################################################################
# +-----------------------------------------------------------------+ #
# |                             Branches                            | #
# +-----------------------------------------------------------------+ #
#######################################################################


#######################################################################
# +-----------------------------------------------------------------+ #
# |                             Entities                            | #
# +-----------------------------------------------------------------+ #
#######################################################################

