#######################################################################
# +-----------------------------------------------------------------+ #
# |                            BO3 object                           | #
# +-----------------------------------------------------------------+ #
#######################################################################

Author: Bo3 BulkEdit

Description: Converted Schematic - Modified by Bo3BulkEdit

Version: 3

SettingsMode: WriteDisable

#######################################################################
# +-----------------------------------------------------------------+ #
# |                          Main settings                          | #
# +-----------------------------------------------------------------+ #
#######################################################################



Frequency: 0


SpawnHeight: randomY





##############################
# Height Limits for the BO3. #
##############################

MinHeight: 0
MaxHeight: 256

#######################################################################
# +-----------------------------------------------------------------+ #
# |                      Source block settings                      | #
# +-----------------------------------------------------------------+ #
#######################################################################

CanOverride: true
MaxPercentageOutsideSourceBlock: 100
OutsideSourceBlock: placeAnyway

#######################################################################
# +-----------------------------------------------------------------+ #
# |                               OTG+                              | #
# +-----------------------------------------------------------------+ #
#######################################################################

#######################################################################
# +-----------------------------------------------------------------+ #
# |                              Blocks                             | #
# +-----------------------------------------------------------------+ #
#######################################################################

B(0,750,0,AIR)
B(15,750,15,AIR)
B(8,-3,6,STAINED_GLASS:15)
B(8,-3,7,STAINED_GLASS:15)
B(7,-2,5,STAINED_GLASS:15)
B(8,-2,5,STAINED_GLASS:15)
B(7,-2,6,STAINED_GLASS:15)
B(8,-2,6,STAINED_GLASS:15)
B(7,-2,7,STAINED_GLASS:15)
B(8,-2,7,STAINED_GLASS:15)
B(7,-1,4,STAINED_GLASS:15)
B(8,-1,4,STAINED_GLASS:15)
B(6,-1,5,STAINED_GLASS:15)
B(7,-1,5,STAINED_GLASS:15)
B(8,-1,5,STAINED_GLASS:15)
B(9,-1,5,STAINED_GLASS:15)
B(6,-1,6,STAINED_GLASS:15)
B(7,-1,6,STAINED_GLASS:15)
B(8,-1,6,STAINED_GLASS:15)
B(9,-1,6,STAINED_GLASS:15)
B(7,-1,7,STAINED_GLASS:15)
B(8,-1,7,STAINED_GLASS:15)
B(6,0,2,STAINED_GLASS:15)
B(6,0,3,STAINED_GLASS:15)
B(7,0,3,STAINED_GLASS:15)
B(8,0,3,STAINED_GLASS:15)
B(6,0,4,STAINED_GLASS:15)
B(8,0,4,STAINED_GLASS:15)
B(9,0,4,STAINED_GLASS:15)
B(6,0,5,STAINED_GLASS:15)
B(7,0,5,STAINED_GLASS:15)
B(8,0,5,STAINED_GLASS:15)
B(9,0,5,STAINED_GLASS:15)
B(6,0,6,STAINED_GLASS:15)
B(7,0,6,STAINED_GLASS:15)
B(8,0,6,STAINED_GLASS:15)
B(9,0,6,STAINED_GLASS:15)
B(5,1,1,STAINED_GLASS:15)
B(6,1,1,STAINED_GLASS:15)
B(6,1,2,STAINED_GLASS:15)
B(7,1,2,STAINED_GLASS:15)
B(8,1,2,STAINED_GLASS:15)
B(5,1,3,STAINED_GLASS:15)
B(6,1,3,STAINED_GLASS:15)
B(7,1,3,STAINED_GLASS:15)
B(8,1,3,STAINED_GLASS:15)
B(9,1,3,STAINED_GLASS:15)
B(5,1,4,STAINED_GLASS:15)
B(6,1,4,STAINED_GLASS:15)
B(7,1,4,SEA_LANTERN)
B(8,1,4,STAINED_GLASS:15)
B(9,1,4,STAINED_GLASS:15)
B(5,1,5,STAINED_GLASS:15)
B(6,1,5,STAINED_GLASS:15)
B(7,1,5,STAINED_GLASS:15)
B(8,1,5,STAINED_GLASS:15)
B(9,1,5,STAINED_GLASS:15)
B(6,1,6,STAINED_GLASS:15)
B(7,1,6,STAINED_GLASS:15)
B(5,2,0,STAINED_GLASS:15)
B(5,2,1,STAINED_GLASS:15)
B(6,2,1,STAINED_GLASS:15)
B(7,2,1,STAINED_GLASS:15)
B(8,2,1,STAINED_GLASS:15)
B(4,2,2,STAINED_GLASS:15)
B(5,2,2,STAINED_GLASS:15)
B(6,2,2,STAINED_GLASS:15)
B(7,2,2,STAINED_GLASS:15)
B(8,2,2,STAINED_GLASS:15)
B(9,2,2,STAINED_GLASS:15)
B(10,2,2,STAINED_GLASS:15)
B(4,2,3,STAINED_GLASS:15)
B(5,2,3,STAINED_GLASS:15)
B(6,2,3,STAINED_GLASS:15)
B(7,2,3,SEA_LANTERN)
B(8,2,3,STAINED_GLASS:15)
B(9,2,3,STAINED_GLASS:15)
B(5,2,4,STAINED_GLASS:15)
B(6,2,4,STAINED_GLASS:15)
B(7,2,4,PURPLE_GLAZED_TERRACOTTA:2)
B(8,2,4,STAINED_GLASS:15)
B(9,2,4,STAINED_GLASS:15)
B(10,2,4,STAINED_GLASS:15)
B(5,2,5,STAINED_GLASS:15)
B(6,2,5,STAINED_GLASS:15)
B(7,2,5,STAINED_GLASS:15)
B(8,2,5,STAINED_GLASS:15)
B(6,2,6,STAINED_GLASS:15)
B(7,2,6,STAINED_GLASS:15)
B(4,3,0,PURPLE_GLAZED_TERRACOTTA:2)
B(5,3,0,PURPLE_GLAZED_TERRACOTTA:2)
B(6,3,0,STAINED_GLASS:15)
B(7,3,0,STAINED_GLASS:15)
B(8,3,0,STAINED_GLASS:15)
B(4,3,1,STAINED_GLASS:15)
B(6,3,1,STAINED_GLASS:15)
B(7,3,1,STAINED_GLASS:15)
B(8,3,1,STAINED_GLASS:15)
B(9,3,1,STAINED_GLASS:15)
B(10,3,1,STAINED_GLASS:15)
B(4,3,2,STAINED_GLASS:15)
B(5,3,2,STAINED_GLASS:15)
B(6,3,2,STAINED_GLASS:10)
B(7,3,2,SEA_LANTERN)
B(8,3,2,STAINED_GLASS:15)
B(9,3,2,STAINED_GLASS:15)
B(10,3,2,STAINED_GLASS:15)
B(4,3,3,STAINED_GLASS:15)
B(5,3,3,STAINED_GLASS:15)
B(6,3,3,PURPLE_GLAZED_TERRACOTTA:2)
B(7,3,3,PURPLE_GLAZED_TERRACOTTA:2)
B(8,3,3,PURPLE_GLAZED_TERRACOTTA:2)
B(10,3,3,STAINED_GLASS:15)
B(4,3,4,STAINED_GLASS:15)
B(5,3,4,STAINED_GLASS:15)
B(6,3,4,STAINED_GLASS:15)
B(7,3,4,PURPLE_GLAZED_TERRACOTTA:2)
B(8,3,4,STAINED_GLASS:15)
B(10,3,4,STAINED_GLASS:15)
B(5,3,5,STAINED_GLASS:15)
B(7,3,5,STAINED_GLASS:15)
B(4,4,0,PURPLE_GLAZED_TERRACOTTA:2)
B(5,4,0,PURPLE_GLAZED_TERRACOTTA:2)
B(6,4,0,PURPLE_GLAZED_TERRACOTTA:2)
B(7,4,0,SEA_LANTERN)
B(8,4,0,STAINED_GLASS:15)
B(9,4,0,STAINED_GLASS:15)
B(10,4,0,STAINED_GLASS:15)
B(4,4,1,STAINED_GLASS:15)
B(5,4,1,STAINED_GLASS:10)
B(6,4,1,SEA_LANTERN)
B(7,4,1,SEA_LANTERN)
B(8,4,1,STAINED_GLASS:10)
B(9,4,1,STAINED_GLASS:15)
B(10,4,1,STAINED_GLASS:15)
B(3,4,2,STAINED_GLASS:15)
B(4,4,2,STAINED_GLASS:15)
B(5,4,2,STAINED_GLASS:10)
B(6,4,2,STAINED_GLASS:10)
B(7,4,2,SEA_LANTERN)
B(8,4,2,PURPLE_GLAZED_TERRACOTTA:2)
B(9,4,2,STAINED_GLASS:10)
B(10,4,2,STAINED_GLASS:15)
B(4,4,3,STAINED_GLASS:15)
B(5,4,3,PURPLE_GLAZED_TERRACOTTA:2)
B(6,4,3,PURPLE_GLAZED_TERRACOTTA:2)
B(7,4,3,PURPLE_GLAZED_TERRACOTTA:2)
B(8,4,3,STAINED_GLASS:15)
B(9,4,3,STAINED_GLASS:15)
B(10,4,3,STAINED_GLASS:15)
B(5,4,4,STAINED_GLASS:15)
B(6,4,4,STAINED_GLASS:15)
B(7,4,4,STAINED_GLASS:15)
B(8,4,4,STAINED_GLASS:15)
B(4,5,0,STAINED_GLASS:10)
B(5,5,0,STAINED_GLASS:10)
B(6,5,0,SEA_LANTERN)
B(7,5,0,SEA_LANTERN)
B(8,5,0,STAINED_GLASS:10)
B(9,5,0,STAINED_GLASS:10)
B(10,5,0,STAINED_GLASS:15)
B(4,5,1,STAINED_GLASS:15)
B(5,5,1,STAINED_GLASS:10)
B(6,5,1,SEA_LANTERN)
B(7,5,1,STAINED_GLASS:10)
B(8,5,1,STAINED_GLASS:10)
B(9,5,1,STAINED_GLASS:10)
B(10,5,1,STAINED_GLASS:15)
B(3,5,2,STAINED_GLASS:15)
B(4,5,2,STAINED_GLASS:15)
B(5,5,2,STAINED_GLASS:10)
B(6,5,2,STAINED_GLASS:10)
B(7,5,2,STAINED_GLASS:10)
B(8,5,2,STAINED_GLASS:14)
B(9,5,2,STAINED_GLASS:10)
B(10,5,2,STAINED_GLASS:15)
B(5,5,3,STAINED_GLASS:10)
B(6,5,3,STAINED_GLASS:15)
B(7,5,3,STAINED_GLASS:15)
B(8,5,3,STAINED_GLASS:15)
B(7,5,4,STAINED_GLASS:15)
B(3,6,0,STAINED_GLASS:15)
B(4,6,0,STAINED_GLASS:10)
B(5,6,0,STAINED_GLASS:10)
B(6,6,0,SEA_LANTERN)
B(7,6,0,SEA_LANTERN)
B(8,6,0,STAINED_GLASS:10)
B(9,6,0,STAINED_GLASS:10)
B(10,6,0,STAINED_GLASS:15)
B(4,6,1,STAINED_GLASS:15)
B(5,6,1,STAINED_GLASS:10)
B(6,6,1,PURPLE_GLAZED_TERRACOTTA:2)
B(7,6,1,PURPLE_GLAZED_TERRACOTTA:2)
B(8,6,1,STAINED_GLASS:10)
B(9,6,1,STAINED_GLASS:15)
B(10,6,1,STAINED_GLASS:15)
B(3,6,2,STAINED_GLASS:15)
B(4,6,2,STAINED_GLASS:15)
B(5,6,2,PURPLE_GLAZED_TERRACOTTA:2)
B(6,6,2,PURPLE_GLAZED_TERRACOTTA:2)
B(7,6,2,PURPLE_GLAZED_TERRACOTTA:2)
B(8,6,2,STAINED_GLASS:15)
B(9,6,2,STAINED_GLASS:15)
B(5,6,3,STAINED_GLASS:15)
B(7,6,3,STAINED_GLASS:15)
B(3,7,0,STAINED_GLASS:15)
B(4,7,0,STAINED_GLASS:10)
B(5,7,0,STAINED_GLASS:10)
B(6,7,0,SEA_LANTERN)
B(7,7,0,STAINED_GLASS:10)
B(8,7,0,STAINED_GLASS:10)
B(9,7,0,STAINED_GLASS:10)
B(4,7,1,STAINED_GLASS:15)
B(5,7,1,PURPLE_GLAZED_TERRACOTTA:2)
B(6,7,1,PURPLE_GLAZED_TERRACOTTA:2)
B(7,7,1,STAINED_GLASS:15)
B(8,7,1,STAINED_GLASS:15)
B(10,7,1,STAINED_GLASS:15)
B(4,7,2,STAINED_GLASS:15)
B(5,7,2,STAINED_GLASS:15)
B(6,7,2,STAINED_GLASS:15)
B(7,7,2,STAINED_GLASS:15)
B(8,7,2,STAINED_GLASS:15)
B(3,8,0,STAINED_GLASS:15)
B(4,8,0,STAINED_GLASS:10)
B(5,8,0,PURPLE_GLAZED_TERRACOTTA:2)
B(6,8,0,PURPLE_GLAZED_TERRACOTTA:2)
B(7,8,0,PURPLE_GLAZED_TERRACOTTA:2)
B(8,8,0,STAINED_GLASS:14)
B(9,8,0,STAINED_GLASS:15)
B(4,8,1,STAINED_GLASS:15)
B(5,8,1,STAINED_GLASS:15)
B(6,8,1,STAINED_GLASS:15)
B(7,8,1,STAINED_GLASS:15)
B(7,8,2,STAINED_GLASS:15)
B(4,9,0,PURPLE_GLAZED_TERRACOTTA:2)
B(5,9,0,STAINED_GLASS:15)
B(6,9,0,PURPLE_GLAZED_TERRACOTTA:2)
B(7,9,0,STAINED_GLASS:15)
B(8,9,0,STAINED_GLASS:15)
B(4,9,1,STAINED_GLASS:15)
B(6,9,1,STAINED_GLASS:15)
B(4,10,0,STAINED_GLASS:15)
B(6,10,0,STAINED_GLASS:15)
B(7,10,0,STAINED_GLASS:15)
B(6,11,0,STAINED_GLASS:15)

#######################################################################
# +-----------------------------------------------------------------+ #
# |                             Branches                            | #
# +-----------------------------------------------------------------+ #
#######################################################################

BR(0,0,-16,true,SPIKE-SET-MED-SMALL-04_0x0,NORTH,100,0)
