
#
# +-----------------------------------------------------------------+ #
# |                            BO3 object                           | #
# +-----------------------------------------------------------------+ #
#

Author: NLBlackEagle

Description: Converted version of the BO2 90

Version: 3

SettingsMode: WriteDisable


#
# +-----------------------------------------------------------------+ #
# |                          Main settings                          | #
# +-----------------------------------------------------------------+ #
#

Tree: true

Frequency: 1

Rarity: 5.0

RotateRandomly: true

SpawnHeight: highestSolidBlock

SpawnHeightOffset: 0

SpawnHeightVariance: 0


# Height Limits for the BO3. #


MinHeight: 0

MaxHeight: 199


# Extrusion settings #


ExtrudeMode: None

ExtrudeThroughBlocks: air

MaxBranchDepth: 10

ExcludedBiomes: 


#
# +-----------------------------------------------------------------+ #
# |                      Source block settings                      | #
# +-----------------------------------------------------------------+ #
#

SourceBlocks: AIR,GRASS,DIRT,SAND

MaxPercentageOutsideSourceBlock: 0

OutsideSourceBlock: placeAnyway


#
# +-----------------------------------------------------------------+ #
# |                              Blocks                             | #
# +-----------------------------------------------------------------+ #
#

B(-5,-3,2,LOG:12)
B(4,7,-15,leaves:0)
B(-1,1,0,LOG:12)
B(-1,0,0,LOG:12)
B(-1,3,0,LOG:12)
B(-1,2,0,LOG:12)
B(-16,5,-10,leaves:0)
B(-16,7,-10,leaves:0)
B(-16,6,-10,leaves:0)
B(-1,4,0,LOG:12)
B(-2,-2,4,LOG:12)
B(-1,5,0,LOG:12)
B(-2,-3,4,LOG:12)
B(-1,6,0,LOG:12)
B(-2,-4,4,LOG:12)
B(-2,-5,4,LOG:12)
B(-1,7,0,LOG:12)
B(14,11,-4,leaves:0)
B(-7,14,-14,leaves:0)
B(-7,13,-14,leaves:0)
B(-7,16,-14,leaves:0)
B(-15,10,12,leaves:0)
B(6,7,-10,leaves:0)
B(6,6,-10,leaves:0)
B(6,8,-10,leaves:0)
B(-6,14,15,leaves:0)
B(-6,9,-11,leaves:0)
B(3,18,-5,leaves:0)
B(3,19,-5,leaves:0)
B(3,16,-5,leaves:0)
B(-6,12,15,leaves:0)
B(-6,13,15,leaves:0)
B(-6,10,15,leaves:0)
B(-6,11,15,leaves:0)
B(3,11,-5,leaves:0)
B(3,10,-5,LOG:12)
B(3,15,-5,leaves:0)
B(3,14,-5,leaves:0)
B(3,13,-5,leaves:0)
B(3,12,-5,leaves:0)
B(5,16,8,leaves:0)
B(5,17,8,leaves:0)
B(5,18,8,leaves:0)
B(5,19,8,leaves:0)
B(-18,12,-7,leaves:0)
B(-18,11,-7,leaves:0)
B(-10,-5,-8,LOG:12)
B(-10,-4,-8,LOG:12)
B(-10,-3,-8,LOG:12)
B(5,15,8,leaves:0)
B(5,14,8,leaves:0)
B(-8,9,9,leaves:0)
B(7,10,-6,leaves:0)
B(7,12,-6,leaves:0)
B(7,17,-6,leaves:0)
B(-7,12,-14,leaves:0)
B(7,13,-6,leaves:0)
B(-7,11,-14,leaves:0)
B(-7,10,-14,leaves:0)
B(-1,18,-7,leaves:0)
B(-10,9,11,leaves:0)
B(3,-4,-5,LOG:12)
B(3,-2,-5,LOG:12)
B(-5,9,3,leaves:0)
B(5,20,8,leaves:0)
B(-1,16,-7,leaves:0)
B(-1,15,-7,leaves:0)
B(-1,14,-7,leaves:0)
B(-10,14,-8,leaves:0)
B(-10,15,-8,leaves:0)
B(-10,16,-8,leaves:0)
B(-10,12,-8,leaves:0)
B(-10,13,-8,leaves:0)
B(5,-4,8,LOG:12)
B(12,10,-3,leaves:0)
B(12,11,-3,leaves:0)
B(-2,17,14,leaves:0)
B(-8,11,2,leaves:0)
B(-2,15,14,leaves:0)
B(-5,22,0,leaves:0)
B(-8,10,2,leaves:0)
B(0,8,-15,leaves:0)
B(-2,16,14,leaves:0)
B(-2,13,14,leaves:0)
B(-2,14,14,leaves:0)
B(-2,11,14,leaves:0)
B(-2,12,14,leaves:0)
B(-2,10,14,leaves:0)
B(-1,11,-13,leaves:0)
B(-1,10,-13,leaves:0)
B(-1,13,-13,leaves:0)
B(-1,12,-13,leaves:0)
B(-11,20,5,leaves:0)
B(-15,10,1,leaves:0)
B(-15,12,1,leaves:0)
B(-15,11,1,leaves:0)
B(-5,19,0,leaves:0)
B(-3,11,7,LOG:12)
B(-15,5,-9,leaves:0)
B(-5,18,0,leaves:0)
B(-3,10,7,leaves:0)
B(-15,6,-9,leaves:0)
B(-5,17,0,leaves:0)
B(-15,7,-9,leaves:0)
B(-5,16,0,leaves:0)
B(-15,8,-9,leaves:0)
B(-8,20,2,leaves:0)
B(-15,9,-9,leaves:0)
B(-5,13,0,leaves:0)
B(-5,12,0,leaves:0)
B(-3,13,7,leaves:0)
B(-5,11,0,leaves:0)
B(-5,20,0,leaves:0)
B(-11,15,5,leaves:0)
B(-5,21,0,leaves:0)
B(-11,16,5,leaves:0)
B(-11,13,5,leaves:0)
B(-11,14,5,leaves:0)
B(-11,19,5,leaves:0)
B(-8,16,2,leaves:0)
B(-15,4,-9,leaves:0)
B(-11,17,5,leaves:0)
B(-8,18,2,leaves:0)
B(-11,18,5,leaves:0)
B(-8,19,2,leaves:0)
B(-11,12,5,leaves:0)
B(-11,10,5,leaves:0)
B(-4,14,16,leaves:0)
B(-4,13,16,leaves:0)
B(-4,11,16,leaves:0)
B(-5,10,0,leaves:0)
B(-9,-4,-9,LOG:12)
B(-5,21,2,leaves:0)
B(-5,20,2,leaves:0)
B(-11,11,-13,leaves:0)
B(-11,12,-13,leaves:0)
B(-5,14,2,leaves:0)
B(-11,13,-13,leaves:0)
B(-5,15,2,leaves:0)
B(-5,16,2,leaves:0)
B(-5,17,2,leaves:0)
B(-5,19,2,LOG:12)
B(-11,10,-13,leaves:0)
B(3,6,-12,leaves:0)
B(3,7,-12,leaves:0)
B(3,8,-12,leaves:0)
B(3,9,-12,leaves:0)
B(-5,11,2,leaves:0)
B(-5,10,2,leaves:0)
B(-5,-3,0,LOG:12)
B(-10,-4,10,LOG:12)
B(-5,-1,0,LOG:12)
B(-5,-2,0,LOG:12)
B(-14,10,-3,leaves:0)
B(-14,12,-3,leaves:0)
B(-14,11,-3,leaves:0)
B(-14,14,-3,leaves:0)
B(-14,13,-3,leaves:0)
B(-6,16,-10,leaves:0)
B(-6,10,-10,leaves:0)
B(-6,11,-10,leaves:0)
B(4,10,15,leaves:0)
B(-6,15,-10,leaves:0)
B(4,13,15,leaves:0)
B(4,14,15,leaves:0)
B(4,11,15,leaves:0)
B(4,12,15,leaves:0)
B(10,19,6,leaves:0)
B(10,18,6,leaves:0)
B(4,15,15,leaves:0)
B(10,17,6,leaves:0)
B(10,16,6,leaves:0)
B(4,16,15,leaves:0)
B(10,15,6,leaves:0)
B(10,14,6,leaves:0)
B(4,19,15,leaves:0)
B(10,13,6,leaves:0)
B(10,12,6,leaves:0)
B(10,11,6,leaves:0)
B(2,6,-11,leaves:0)
B(-1,-1,-2,LOG:12)
B(2,7,-11,leaves:0)
B(-1,-4,-2,LOG:12)
B(-1,-2,-2,LOG:12)
B(-1,-3,-2,LOG:12)
B(1,14,19,leaves:0)
B(5,11,-8,leaves:0)
B(5,12,-8,leaves:0)
B(5,10,-8,leaves:0)
B(5,13,-8,leaves:0)
B(5,18,-8,leaves:0)
B(-6,-3,1,LOG:12)
B(-6,-4,1,LOG:12)
B(-6,-5,1,LOG:12)
B(-6,-2,1,LOG:12)
B(5,9,-14,leaves:0)
B(5,8,-14,leaves:0)
B(5,7,-14,leaves:0)
B(-9,19,-9,leaves:0)
B(5,13,-10,leaves:0)
B(5,12,-10,leaves:0)
B(5,11,-10,leaves:0)
B(5,10,-10,leaves:0)
B(-9,14,-9,leaves:0)
B(-9,16,-9,leaves:0)
B(-9,15,-9,leaves:0)
B(2,9,-11,leaves:0)
B(-9,18,-9,leaves:0)
B(-9,17,-9,leaves:0)
B(5,17,3,leaves:0)
B(5,18,3,leaves:0)
B(5,15,3,leaves:0)
B(5,16,3,leaves:0)
B(5,14,3,leaves:0)
B(-12,15,-5,leaves:0)
B(5,11,3,LOG:12)
B(-12,14,-5,leaves:0)
B(5,12,3,LOG:12)
B(-12,13,-5,leaves:0)
B(-12,12,-5,leaves:0)
B(-12,9,1,leaves:0)
B(-12,11,-5,leaves:0)
B(-12,10,-5,leaves:0)
B(5,19,3,leaves:0)
B(-17,11,-7,leaves:0)
B(5,10,3,LOG:12)
B(-10,12,10,leaves:0)
B(-10,11,10,leaves:0)
B(-10,10,10,leaves:0)
B(-16,9,9,leaves:0)
B(-16,8,9,leaves:0)
B(12,11,-6,leaves:0)
B(9,19,8,leaves:0)
B(-10,16,10,leaves:0)
B(13,9,8,leaves:0)
B(-10,17,10,leaves:0)
B(9,18,8,leaves:0)
B(-1,11,-2,leaves:0)
B(-10,14,10,leaves:0)
B(9,17,8,leaves:0)
B(-10,15,10,leaves:0)
B(9,16,8,leaves:0)
B(9,15,8,leaves:0)
B(12,10,-6,leaves:0)
B(9,14,8,leaves:0)
B(9,13,8,leaves:0)
B(-10,18,10,leaves:0)
B(-10,19,10,leaves:0)
B(9,12,8,leaves:0)
B(3,13,17,leaves:0)
B(-1,15,-2,LOG:12)
B(-1,14,-2,LOG:12)
B(10,15,12,leaves:0)
B(-1,13,-2,leaves:0)
B(-1,12,-2,leaves:0)
B(10,13,12,leaves:0)
B(-1,19,-2,leaves:0)
B(-1,18,-2,leaves:0)
B(-1,17,-2,leaves:0)
B(-6,11,1,leaves:0)
B(-6,12,1,leaves:0)
B(-6,10,1,leaves:0)
B(-1,21,-2,leaves:0)
B(-9,17,-6,leaves:0)
B(-9,16,-6,leaves:0)
B(-1,20,-2,leaves:0)
B(-9,18,-6,leaves:0)
B(13,14,7,leaves:0)
B(13,13,7,leaves:0)
B(13,12,7,leaves:0)
B(-9,14,-6,leaves:0)
B(3,14,17,leaves:0)
B(-6,18,1,LOG:12)
B(-6,19,1,leaves:0)
B(-6,13,1,leaves:0)
B(-14,9,-4,leaves:0)
B(-6,15,1,leaves:0)
B(-6,20,1,leaves:0)
B(-6,21,1,leaves:0)
B(-6,22,1,leaves:0)
B(-2,0,3,LOG:12)
B(-2,7,3,LOG:12)
B(-2,6,3,LOG:12)
B(-12,-5,-5,LOG:12)
B(-12,-3,-5,LOG:12)
B(-12,-4,-5,LOG:12)
B(-12,-2,-5,LOG:12)
B(0,9,-14,leaves:0)
B(0,8,-14,leaves:0)
B(-12,15,11,leaves:0)
B(5,16,13,leaves:0)
B(-12,16,11,leaves:0)
B(5,17,13,leaves:0)
B(5,18,13,leaves:0)
B(5,19,13,leaves:0)
B(-12,14,11,leaves:0)
B(5,13,13,leaves:0)
B(5,14,13,leaves:0)
B(0,5,-14,leaves:0)
B(0,6,-14,leaves:0)
B(0,7,-14,leaves:0)
B(11,15,8,leaves:0)
B(11,16,8,leaves:0)
B(10,11,12,leaves:0)
B(11,17,8,leaves:0)
B(10,12,12,leaves:0)
B(11,11,8,leaves:0)
B(11,12,8,leaves:0)
B(11,13,8,leaves:0)
B(11,14,8,leaves:0)
B(-12,12,11,leaves:0)
B(-15,6,-10,leaves:0)
B(-12,11,11,leaves:0)
B(-15,8,-10,leaves:0)
B(-15,7,-10,leaves:0)
B(-9,-4,-6,LOG:12)
B(-9,-5,-6,LOG:12)
B(4,20,3,leaves:0)
B(-9,-3,-6,LOG:12)
B(4,21,3,leaves:0)
B(-7,-1,8,LOG:12)
B(-7,-2,8,LOG:12)
B(-11,15,-10,leaves:0)
B(-11,13,-10,leaves:0)
B(-11,12,-10,leaves:0)
B(12,12,0,leaves:0)
B(12,13,0,leaves:0)
B(12,14,0,leaves:0)
B(-13,12,-9,leaves:0)
B(-8,8,-12,leaves:0)
B(-13,13,-9,leaves:0)
B(-13,14,-9,leaves:0)
B(-13,15,-9,leaves:0)
B(12,10,0,leaves:0)
B(-13,10,-9,leaves:0)
B(12,11,0,leaves:0)
B(-11,10,12,leaves:0)
B(-11,12,12,leaves:0)
B(-11,11,12,leaves:0)
B(-11,13,12,leaves:0)
B(-3,13,17,leaves:0)
B(-3,14,17,leaves:0)
B(-3,11,17,leaves:0)
B(-3,12,17,leaves:0)
B(-11,11,-10,leaves:0)
B(9,11,-3,leaves:0)
B(9,10,-3,leaves:0)
B(-3,12,16,leaves:0)
B(-3,13,16,leaves:0)
B(-3,14,16,leaves:0)
B(9,15,-3,leaves:0)
B(9,14,-3,leaves:0)
B(9,13,-3,leaves:0)
B(9,12,-3,leaves:0)
B(9,16,-3,leaves:0)
B(4,17,3,leaves:0)
B(4,16,3,leaves:0)
B(4,15,3,leaves:0)
B(4,12,3,leaves:0)
B(4,11,3,LOG:12)
B(4,10,3,LOG:12)
B(13,11,7,leaves:0)
B(13,10,7,leaves:0)
B(4,19,3,leaves:0)
B(4,18,3,leaves:0)
B(-7,21,8,leaves:0)
B(-3,7,-13,leaves:0)
B(-2,15,4,leaves:0)
B(-3,8,-13,leaves:0)
B(-3,9,-13,leaves:0)
B(-2,19,4,leaves:0)
B(-2,18,4,leaves:0)
B(-2,17,4,leaves:0)
B(-2,16,4,leaves:0)
B(-11,9,14,leaves:0)
B(-2,20,4,leaves:0)
B(-7,12,8,leaves:0)
B(-7,11,8,leaves:0)
B(-7,10,8,leaves:0)
B(-14,8,6,leaves:0)
B(-14,9,6,leaves:0)
B(-14,6,6,leaves:0)
B(-14,7,6,leaves:0)
B(-7,19,8,leaves:0)
B(-7,18,8,leaves:0)
B(3,20,-5,leaves:0)
B(-7,17,8,leaves:0)
B(-7,16,8,leaves:0)
B(-7,15,8,leaves:0)
B(-7,14,8,leaves:0)
B(-7,13,8,leaves:0)
B(-13,10,-6,leaves:0)
B(4,-4,3,LOG:12)
B(8,19,9,leaves:0)
B(7,17,14,leaves:0)
B(8,18,9,leaves:0)
B(7,16,14,leaves:0)
B(8,17,9,leaves:0)
B(8,16,9,leaves:0)
B(-5,23,1,leaves:0)
B(8,15,9,leaves:0)
B(-6,17,5,leaves:0)
B(8,14,9,leaves:0)
B(8,12,9,leaves:0)
B(8,11,9,leaves:0)
B(7,10,14,leaves:0)
B(7,14,14,leaves:0)
B(7,13,14,leaves:0)
B(7,12,14,leaves:0)
B(7,11,14,leaves:0)
B(6,9,-6,leaves:0)
B(-6,21,5,leaves:0)
B(0,20,6,leaves:0)
B(-7,-3,-5,LOG:12)
B(-6,20,5,leaves:0)
B(-6,23,5,leaves:0)
B(-5,18,1,leaves:0)
B(-5,19,1,leaves:0)
B(-5,17,1,leaves:0)
B(-11,11,6,leaves:0)
B(-5,14,1,leaves:0)
B(-11,10,6,leaves:0)
B(-11,9,15,leaves:0)
B(-5,15,1,leaves:0)
B(-11,13,6,leaves:0)
B(-11,12,6,leaves:0)
B(-11,15,6,leaves:0)
B(-11,14,6,leaves:0)
B(-9,9,10,leaves:0)
B(-11,17,6,leaves:0)
B(-11,16,6,leaves:0)
B(-11,19,6,leaves:0)
B(-11,18,6,leaves:0)
B(0,19,6,leaves:0)
B(0,17,6,leaves:0)
B(-15,15,2,leaves:0)
B(0,18,6,leaves:0)
B(0,15,6,leaves:0)
B(-6,16,5,leaves:0)
B(-5,21,1,leaves:0)
B(-6,15,5,leaves:0)
B(0,16,6,leaves:0)
B(-5,20,1,leaves:0)
B(-15,10,2,leaves:0)
B(-6,14,5,leaves:0)
B(-6,13,5,leaves:0)
B(-6,12,5,leaves:0)
B(0,11,6,leaves:0)
B(0,12,6,leaves:0)
B(-6,10,5,leaves:0)
B(0,10,6,LOG:12)
B(-13,-5,-6,LOG:12)
B(-13,-4,-6,LOG:12)
B(-13,-3,-6,LOG:12)
B(-14,8,4,leaves:0)
B(-8,12,3,leaves:0)
B(-8,13,3,leaves:0)
B(-14,7,4,leaves:0)
B(-8,16,3,leaves:0)
B(-10,9,10,leaves:0)
B(-17,9,3,leaves:0)
B(-17,8,3,leaves:0)
B(-17,7,3,leaves:0)
B(-8,19,3,leaves:0)
B(-8,18,3,LOG:12)
B(-8,20,3,leaves:0)
B(-14,14,2,leaves:0)
B(-14,13,2,leaves:0)
B(-12,14,-11,leaves:0)
B(-14,16,2,leaves:0)
B(-14,15,2,leaves:0)
B(-14,12,2,leaves:0)
B(-14,11,2,leaves:0)
B(-7,9,5,leaves:0)
B(6,14,4,leaves:0)
B(6,13,4,leaves:0)
B(6,16,4,leaves:0)
B(6,15,4,leaves:0)
B(-12,13,-11,leaves:0)
B(6,18,4,leaves:0)
B(-12,12,-11,leaves:0)
B(-8,7,-11,leaves:0)
B(6,17,4,leaves:0)
B(-12,11,-11,leaves:0)
B(6,19,4,leaves:0)
B(-12,10,-11,leaves:0)
B(-8,8,-11,leaves:0)
B(-8,9,-11,leaves:0)
B(-7,8,5,leaves:0)
B(-8,9,8,leaves:0)
B(-2,10,15,leaves:0)
B(-2,11,15,leaves:0)
B(-2,12,15,leaves:0)
B(-2,13,15,leaves:0)
B(-2,14,15,leaves:0)
B(-2,15,15,leaves:0)
B(6,20,-2,leaves:0)
B(-2,16,15,leaves:0)
B(6,12,4,leaves:0)
B(6,16,-2,leaves:0)
B(6,17,-2,leaves:0)
B(6,14,-2,LOG:12)
B(6,15,-2,leaves:0)
B(6,18,-2,leaves:0)
B(6,19,-2,leaves:0)
B(8,16,-1,leaves:0)
B(8,15,-1,leaves:0)
B(8,17,-1,leaves:0)
B(8,12,-1,leaves:0)
B(8,11,-1,leaves:0)
B(8,14,-1,leaves:0)
B(8,13,-1,leaves:0)
B(-1,-4,0,LOG:12)
B(-1,-3,0,LOG:12)
B(-1,-2,0,LOG:12)
B(-1,-1,0,LOG:12)
B(-6,7,-12,leaves:0)
B(-6,6,-12,leaves:0)
B(8,20,9,leaves:0)
B(-6,9,-12,leaves:0)
B(2,-4,4,LOG:12)
B(2,-3,4,LOG:12)
B(2,-5,4,LOG:12)
B(1,-5,0,LOG:12)
B(1,-4,0,LOG:12)
B(1,-3,0,LOG:12)
B(1,-2,0,LOG:12)
B(1,-1,0,LOG:12)
B(-9,18,-12,leaves:0)
B(-9,17,-12,leaves:0)
B(-9,14,-12,leaves:0)
B(-9,13,-12,leaves:0)
B(-9,16,-12,leaves:0)
B(-9,15,-12,leaves:0)
B(-10,17,-7,leaves:0)
B(-10,14,-7,leaves:0)
B(-10,13,-7,leaves:0)
B(-15,10,13,leaves:0)
B(-10,16,-7,leaves:0)
B(-15,11,13,leaves:0)
B(-10,15,-7,leaves:0)
B(12,12,1,leaves:0)
B(12,14,1,leaves:0)
B(12,13,1,leaves:0)
B(12,15,1,leaves:0)
B(13,11,-2,leaves:0)
B(12,18,1,leaves:0)
B(13,10,-2,leaves:0)
B(12,17,1,leaves:0)
B(13,13,-2,leaves:0)
B(13,12,-2,leaves:0)
B(-11,10,11,leaves:0)
B(-11,11,11,leaves:0)
B(-11,12,11,leaves:0)
B(3,13,10,leaves:0)
B(-11,13,11,leaves:0)
B(3,14,10,leaves:0)
B(3,15,10,leaves:0)
B(3,16,10,leaves:0)
B(3,17,10,leaves:0)
B(-11,9,-12,leaves:0)
B(3,18,10,leaves:0)
B(3,19,10,leaves:0)
B(-2,7,5,LOG:12)
B(-2,8,5,LOG:12)
B(-2,9,5,LOG:12)
B(-11,15,11,leaves:0)
B(-11,14,11,leaves:0)
B(-11,16,11,leaves:0)
B(3,20,10,leaves:0)
B(-5,9,2,leaves:0)
B(1,18,0,leaves:0)
B(2,14,4,leaves:0)
B(1,19,0,leaves:0)
B(1,16,0,leaves:0)
B(7,14,-7,leaves:0)
B(1,17,0,leaves:0)
B(2,10,4,leaves:0)
B(2,11,4,leaves:0)
B(2,10,-7,LOG:12)
B(2,12,4,leaves:0)
B(2,12,-7,leaves:0)
B(-9,10,-15,leaves:0)
B(2,11,-7,LOG:12)
B(2,14,-7,leaves:0)
B(-16,9,10,leaves:0)
B(2,13,-7,leaves:0)
B(2,16,-7,leaves:0)
B(2,15,-7,leaves:0)
B(2,18,4,leaves:0)
B(2,19,4,leaves:0)
B(13,9,-3,leaves:0)
B(2,18,-7,leaves:0)
B(13,8,-3,leaves:0)
B(2,17,-7,leaves:0)
B(10,16,3,leaves:0)
B(2,19,-7,leaves:0)
B(10,15,3,leaves:0)
B(10,14,3,leaves:0)
B(10,13,3,leaves:0)
B(10,19,3,leaves:0)
B(10,18,3,leaves:0)
B(10,17,3,leaves:0)
B(10,12,3,leaves:0)
B(7,12,-7,leaves:0)
B(7,13,-7,leaves:0)
B(7,10,-7,leaves:0)
B(-6,-4,5,LOG:12)
B(7,11,-7,leaves:0)
B(-6,-3,5,LOG:12)
B(-6,-1,5,LOG:12)
B(-6,-2,5,LOG:12)
B(2,20,4,leaves:0)
B(-10,-3,-7,LOG:12)
B(-10,-4,-7,LOG:12)
B(-2,15,16,leaves:0)
B(-2,12,16,leaves:0)
B(3,7,-13,leaves:0)
B(-2,14,16,leaves:0)
B(3,9,-13,leaves:0)
B(-2,13,16,leaves:0)
B(-5,-3,1,LOG:12)
B(-7,15,-8,leaves:0)
B(-5,-2,1,LOG:12)
B(-7,14,-8,leaves:0)
B(-7,13,-8,LOG:12)
B(-5,-4,1,LOG:12)
B(-7,18,-8,leaves:0)
B(-7,16,-8,leaves:0)
B(-5,10,1,leaves:0)
B(-5,11,1,leaves:0)
B(6,10,-4,leaves:0)
B(6,11,-4,LOG:12)
B(6,17,-4,leaves:0)
B(-6,17,14,leaves:0)
B(6,16,-4,leaves:0)
B(6,19,-4,leaves:0)
B(-16,10,-4,leaves:0)
B(6,13,-4,leaves:0)
B(-6,13,14,leaves:0)
B(6,12,-4,LOG:12)
B(-2,10,16,leaves:0)
B(6,15,-4,leaves:0)
B(-6,15,14,leaves:0)
B(6,14,-4,leaves:0)
B(-6,11,14,leaves:0)
B(-6,12,14,leaves:0)
B(-1,15,11,LOG:12)
B(-1,16,11,leaves:0)
B(-1,17,11,leaves:0)
B(-9,12,-12,leaves:0)
B(-5,11,16,leaves:0)
B(6,20,-4,leaves:0)
B(1,20,0,leaves:0)
B(-1,12,11,leaves:0)
B(1,21,0,leaves:0)
B(-1,13,11,LOG:12)
B(-1,14,11,LOG:12)
B(2,7,-12,leaves:0)
B(2,6,-12,leaves:0)
B(-3,12,15,leaves:0)
B(-7,-1,9,LOG:12)
B(4,-2,-6,LOG:12)
B(-3,11,15,leaves:0)
B(4,-3,-6,LOG:12)
B(-7,-3,9,LOG:12)
B(4,-4,-6,LOG:12)
B(-7,-2,9,LOG:12)
B(-3,16,15,leaves:0)
B(-7,-4,9,LOG:12)
B(-3,15,15,leaves:0)
B(-3,14,15,leaves:0)
B(-3,13,15,leaves:0)
B(5,9,-15,leaves:0)
B(5,7,-15,leaves:0)
B(-10,10,-14,leaves:0)
B(-10,14,-14,leaves:0)
B(-10,13,-14,leaves:0)
B(-10,12,-14,leaves:0)
B(-10,11,-14,leaves:0)
B(0,12,-9,leaves:0)
B(-13,-4,-7,LOG:12)
B(0,13,-9,leaves:0)
B(0,14,-9,leaves:0)
B(3,16,7,leaves:0)
B(3,17,7,leaves:0)
B(3,18,7,leaves:0)
B(3,19,7,leaves:0)
B(0,10,-9,leaves:0)
B(-3,13,-14,leaves:0)
B(-3,10,-14,leaves:0)
B(-3,12,-14,leaves:0)
B(3,20,7,leaves:0)
B(-9,11,16,leaves:0)
B(7,7,-8,leaves:0)
B(7,8,-8,leaves:0)
B(7,9,-8,leaves:0)
B(5,11,16,leaves:0)
B(5,12,16,leaves:0)
B(5,14,16,leaves:0)
B(4,12,-6,LOG:12)
B(-9,14,16,leaves:0)
B(4,13,-6,leaves:0)
B(4,14,-6,leaves:0)
B(4,15,-6,leaves:0)
B(-4,17,-2,leaves:0)
B(4,16,-6,leaves:0)
B(-4,18,-2,leaves:0)
B(4,19,-6,leaves:0)
B(-4,19,-2,leaves:0)
B(4,18,-6,leaves:0)
B(5,10,16,leaves:0)
B(-4,11,-2,leaves:0)
B(-4,12,-2,leaves:0)
B(-4,13,-2,leaves:0)
B(-4,14,-2,leaves:0)
B(-3,1,-2,LOG:12)
B(-3,3,-2,LOG:12)
B(-3,4,-2,LOG:12)
B(-3,5,-2,LOG:12)
B(-3,6,-2,LOG:12)
B(-2,9,4,LOG:12)
B(-3,0,-2,LOG:12)
B(-2,8,4,LOG:12)
B(-2,7,4,LOG:12)
B(-4,22,-2,leaves:0)
B(5,14,-9,leaves:0)
B(-5,18,-7,leaves:0)
B(-5,17,-7,leaves:0)
B(-4,20,-2,leaves:0)
B(-4,21,-2,leaves:0)
B(-5,19,-7,leaves:0)
B(5,10,-9,leaves:0)
B(5,11,-9,leaves:0)
B(5,12,-9,leaves:0)
B(-5,16,-7,leaves:0)
B(5,13,-9,leaves:0)
B(-5,15,-7,leaves:0)
B(14,11,-3,leaves:0)
B(14,10,-3,leaves:0)
B(3,-4,7,LOG:12)
B(-13,17,-7,leaves:0)
B(-13,16,-7,leaves:0)
B(-13,15,-7,leaves:0)
B(-13,14,-7,leaves:0)
B(-13,12,-7,leaves:0)
B(-13,11,-7,leaves:0)
B(-13,10,-7,leaves:0)
B(-7,17,-2,leaves:0)
B(-7,16,-2,leaves:0)
B(-7,15,-2,leaves:0)
B(-7,14,-2,leaves:0)
B(-7,19,-2,leaves:0)
B(-7,18,-2,leaves:0)
B(-7,13,-2,leaves:0)
B(-7,12,-2,leaves:0)
B(-7,11,-2,leaves:0)
B(-7,10,-2,leaves:0)
B(-15,9,-8,leaves:0)
B(-15,8,-8,leaves:0)
B(-7,20,-2,leaves:0)
B(-15,7,-8,leaves:0)
B(-15,6,-8,leaves:0)
B(-10,16,11,leaves:0)
B(-10,15,11,leaves:0)
B(-10,17,11,leaves:0)
B(-4,-2,-2,LOG:12)
B(-4,-1,-2,LOG:12)
B(-17,9,-2,leaves:0)
B(-4,-4,-2,LOG:12)
B(-4,-3,-2,LOG:12)
B(-10,11,11,leaves:0)
B(-10,12,11,leaves:0)
B(-10,13,11,leaves:0)
B(-10,14,11,leaves:0)
B(6,-5,4,LOG:12)
B(6,-3,4,LOG:12)
B(6,-4,4,LOG:12)
B(9,11,11,leaves:0)
B(9,13,11,leaves:0)
B(9,12,11,leaves:0)
B(9,15,11,leaves:0)
B(9,14,11,leaves:0)
B(9,17,11,leaves:0)
B(-7,-2,-2,LOG:12)
B(-7,-3,-2,LOG:12)
B(-7,-4,-2,LOG:12)
B(-15,6,-11,leaves:0)
B(-15,5,-11,leaves:0)
B(5,11,-7,leaves:0)
B(5,10,-7,leaves:0)
B(5,13,-7,leaves:0)
B(5,12,-7,leaves:0)
B(-7,16,9,leaves:0)
B(-7,17,9,leaves:0)
B(-7,14,9,leaves:0)
B(-7,15,9,leaves:0)
B(-7,18,9,leaves:0)
B(-7,19,9,leaves:0)
B(12,13,13,leaves:0)
B(-10,-3,11,LOG:12)
B(-10,-4,11,LOG:12)
B(-7,12,9,leaves:0)
B(-3,6,-14,leaves:0)
B(-3,7,-14,leaves:0)
B(-7,13,9,leaves:0)
B(-7,10,9,leaves:0)
B(-7,11,9,leaves:0)
B(-3,9,-14,leaves:0)
B(-3,15,9,leaves:0)
B(-3,14,9,leaves:0)
B(-3,17,9,leaves:0)
B(-3,16,9,leaves:0)
B(-7,17,-5,leaves:0)
B(-3,11,9,leaves:0)
B(-3,13,9,leaves:0)
B(-3,12,9,leaves:0)
B(-7,12,-5,leaves:0)
B(-7,11,-5,LOG:12)
B(-7,10,-5,LOG:12)
B(-14,8,5,leaves:0)
B(-8,16,-15,leaves:0)
B(-7,16,-5,leaves:0)
B(-14,6,5,leaves:0)
B(-7,15,-5,leaves:0)
B(-7,14,-5,leaves:0)
B(-7,13,-5,leaves:0)
B(-8,17,-15,leaves:0)
B(12,11,13,leaves:0)
B(-4,15,6,leaves:0)
B(-4,14,6,leaves:0)
B(-4,13,6,leaves:0)
B(-4,12,6,leaves:0)
B(-4,11,6,LOG:12)
B(-4,10,6,LOG:12)
B(-4,15,-9,leaves:0)
B(-4,16,6,leaves:0)
B(-4,14,-9,leaves:0)
B(-4,17,6,leaves:0)
B(-4,18,6,leaves:0)
B(-3,20,9,leaves:0)
B(10,11,11,leaves:0)
B(-8,10,-15,leaves:0)
B(-8,13,-15,leaves:0)
B(-4,20,6,leaves:0)
B(-4,22,6,leaves:0)
B(-3,18,9,leaves:0)
B(-4,21,6,leaves:0)
B(-3,19,9,leaves:0)
B(-12,9,-11,leaves:0)
B(-12,7,-11,leaves:0)
B(-7,21,9,leaves:0)
B(-7,20,9,leaves:0)
B(10,12,11,leaves:0)
B(10,13,11,leaves:0)
B(10,14,11,leaves:0)
B(10,15,11,leaves:0)
B(-4,16,-9,leaves:0)
B(-4,17,-9,leaves:0)
B(0,20,2,leaves:0)
B(-13,9,16,leaves:0)
B(0,19,2,leaves:0)
B(0,18,2,leaves:0)
B(0,15,2,leaves:0)
B(-11,11,-12,leaves:0)
B(-11,13,-12,leaves:0)
B(-11,12,-12,leaves:0)
B(-13,7,-1,leaves:0)
B(-8,10,9,leaves:0)
B(-8,11,9,leaves:0)
B(-8,12,9,LOG:12)
B(-8,13,9,leaves:0)
B(-13,6,-1,leaves:0)
B(-8,14,9,leaves:0)
B(-8,15,9,leaves:0)
B(-8,16,9,LOG:12)
B(-8,17,9,leaves:0)
B(-8,18,9,leaves:0)
B(-8,19,9,leaves:0)
B(-13,10,17,leaves:0)
B(5,-2,-6,LOG:12)
B(5,-3,-6,LOG:12)
B(5,-4,-6,LOG:12)
B(-8,21,9,leaves:0)
B(-6,8,-13,leaves:0)
B(-6,9,-13,leaves:0)
B(-7,11,-11,leaves:0)
B(-7,12,-11,leaves:0)
B(-7,13,-11,leaves:0)
B(-6,6,-13,leaves:0)
B(-17,9,6,leaves:0)
B(4,20,1,leaves:0)
B(-6,7,-13,leaves:0)
B(-7,15,-11,LOG:12)
B(-7,16,-11,leaves:0)
B(-7,17,-11,leaves:0)
B(-15,11,9,leaves:0)
B(-15,10,9,leaves:0)
B(-15,15,9,leaves:0)
B(-15,14,9,leaves:0)
B(-16,10,11,leaves:0)
B(0,-3,2,LOG:12)
B(0,-4,2,LOG:12)
B(0,-1,2,LOG:12)
B(0,-2,2,LOG:12)
B(-9,6,-13,leaves:0)
B(-9,7,-13,leaves:0)
B(-9,8,-13,leaves:0)
B(-9,9,-13,leaves:0)
B(-8,-2,9,LOG:12)
B(-8,-1,9,LOG:12)
B(-8,-4,9,LOG:12)
B(-8,-3,9,LOG:12)
B(0,12,-8,leaves:0)
B(-8,-5,9,LOG:12)
B(-11,-5,-8,LOG:12)
B(-2,11,18,leaves:0)
B(-11,-3,-8,LOG:12)
B(0,15,-8,leaves:0)
B(-11,-4,-8,LOG:12)
B(0,14,-8,leaves:0)
B(-14,17,4,leaves:0)
B(-14,16,4,leaves:0)
B(-14,15,4,leaves:0)
B(5,16,-6,leaves:0)
B(-15,10,-7,leaves:0)
B(5,17,-6,leaves:0)
B(-15,12,-7,leaves:0)
B(-15,13,-7,leaves:0)
B(-15,14,-7,leaves:0)
B(-14,14,4,leaves:0)
B(-14,12,4,leaves:0)
B(-14,11,4,leaves:0)
B(-5,9,5,leaves:0)
B(5,11,-6,leaves:0)
B(5,12,-6,leaves:0)
B(5,13,-6,leaves:0)
B(5,14,-6,leaves:0)
B(5,10,-6,leaves:0)
B(-16,7,-9,leaves:0)
B(-16,6,-9,leaves:0)
B(-16,8,-9,leaves:0)
B(2,15,-9,leaves:0)
B(2,14,-9,leaves:0)
B(-2,22,-2,leaves:0)
B(2,13,-9,leaves:0)
B(-16,7,11,leaves:0)
B(-16,9,11,leaves:0)
B(-16,5,-9,leaves:0)
B(-16,8,11,leaves:0)
B(4,9,-13,leaves:0)
B(2,12,-9,leaves:0)
B(2,11,-9,leaves:0)
B(4,7,-13,leaves:0)
B(2,10,-9,LOG:12)
B(-2,20,-2,leaves:0)
B(5,-4,5,LOG:12)
B(-2,21,-2,leaves:0)
B(-2,14,-2,LOG:12)
B(-2,17,-2,leaves:0)
B(-15,6,0,leaves:0)
B(-9,13,15,leaves:0)
B(-9,12,15,leaves:0)
B(-9,10,15,leaves:0)
B(-4,17,13,leaves:0)
B(0,0,-1,LOG:12)
B(-4,14,13,leaves:0)
B(0,9,-1,leaves:0)
B(0,8,-1,leaves:0)
B(0,7,-1,leaves:0)
B(-4,13,13,leaves:0)
B(-4,12,13,leaves:0)
B(0,6,-1,leaves:0)
B(-11,8,-13,leaves:0)
B(-11,9,-13,leaves:0)
B(7,14,1,leaves:0)
B(7,16,1,leaves:0)
B(7,15,1,leaves:0)
B(7,18,1,leaves:0)
B(7,17,1,leaves:0)
B(1,14,17,leaves:0)
B(1,15,17,leaves:0)
B(7,19,1,leaves:0)
B(1,13,17,leaves:0)
B(-1,-2,-4,LOG:12)
B(-15,-3,-7,LOG:12)
B(-15,8,0,leaves:0)
B(-15,7,0,leaves:0)
B(-15,9,0,leaves:0)
B(3,19,-8,leaves:0)
B(-4,19,10,leaves:0)
B(8,9,6,leaves:0)
B(-3,14,14,leaves:0)
B(-3,15,14,leaves:0)
B(-3,12,14,leaves:0)
B(-3,13,14,leaves:0)
B(3,10,-8,leaves:0)
B(3,11,-8,leaves:0)
B(-4,18,10,leaves:0)
B(3,12,-8,leaves:0)
B(-4,17,10,leaves:0)
B(-4,16,10,leaves:0)
B(-4,15,10,leaves:0)
B(-4,14,10,leaves:0)
B(-4,13,10,leaves:0)
B(3,16,-8,leaves:0)
B(-4,12,10,leaves:0)
B(-3,16,14,leaves:0)
B(3,18,-8,leaves:0)
B(-3,0,0,LOG:12)
B(-3,1,0,LOG:12)
B(-3,3,0,LOG:12)
B(-3,2,0,LOG:12)
B(-4,21,10,leaves:0)
B(-3,5,0,LOG:12)
B(-4,20,10,leaves:0)
B(-3,4,0,LOG:12)
B(3,20,-8,leaves:0)
B(-3,7,0,LOG:12)
B(-3,6,0,LOG:12)
B(-2,15,-9,leaves:0)
B(-2,-1,-2,LOG:12)
B(-2,13,-9,leaves:0)
B(-4,22,10,leaves:0)
B(-2,-2,-2,LOG:12)
B(-2,-3,-2,LOG:12)
B(-2,-4,-2,LOG:12)
B(-6,10,16,leaves:0)
B(-6,12,16,leaves:0)
B(-6,11,16,leaves:0)
B(5,-4,6,LOG:12)
B(15,17,4,leaves:0)
B(-1,11,14,leaves:0)
B(-1,12,14,leaves:0)
B(-2,8,6,LOG:12)
B(-1,13,14,leaves:0)
B(-2,9,6,leaves:0)
B(-1,14,14,leaves:0)
B(-1,15,14,leaves:0)
B(-1,16,14,leaves:0)
B(-1,17,14,leaves:0)
B(-14,14,5,leaves:0)
B(-11,14,-12,leaves:0)
B(-14,12,5,leaves:0)
B(-14,13,5,leaves:0)
B(-14,10,5,leaves:0)
B(-14,11,5,leaves:0)
B(1,20,-3,leaves:0)
B(1,21,-3,leaves:0)
B(-4,23,2,leaves:0)
B(-2,8,-15,leaves:0)
B(-2,7,-15,leaves:0)
B(-3,12,5,leaves:0)
B(-13,14,5,leaves:0)
B(9,12,14,leaves:0)
B(-13,13,5,leaves:0)
B(-3,13,5,leaves:0)
B(-13,12,5,leaves:0)
B(-3,10,5,leaves:0)
B(-13,11,5,leaves:0)
B(-13,10,5,leaves:0)
B(-4,17,2,leaves:0)
B(-4,16,2,leaves:0)
B(-4,19,2,leaves:0)
B(-4,18,2,leaves:0)
B(-4,13,2,leaves:0)
B(-13,18,5,leaves:0)
B(-4,12,2,leaves:0)
B(-13,17,5,leaves:0)
B(9,13,14,leaves:0)
B(-13,16,5,leaves:0)
B(9,14,14,leaves:0)
B(-13,15,5,leaves:0)
B(-11,14,7,leaves:0)
B(-4,20,2,leaves:0)
B(-11,13,7,leaves:0)
B(-4,21,2,leaves:0)
B(-11,12,7,leaves:0)
B(-4,22,2,leaves:0)
B(-8,13,-16,leaves:0)
B(-8,12,-16,leaves:0)
B(-11,17,7,leaves:0)
B(-3,20,5,leaves:0)
B(-3,21,5,leaves:0)
B(-12,10,15,leaves:0)
B(-12,11,15,leaves:0)
B(-12,12,15,leaves:0)
B(-12,13,15,leaves:0)
B(-9,14,1,leaves:0)
B(-12,9,3,leaves:0)
B(-4,11,2,leaves:0)
B(-16,10,-3,leaves:0)
B(-3,14,5,leaves:0)
B(-3,17,5,leaves:0)
B(-12,10,-12,leaves:0)
B(-3,19,5,leaves:0)
B(-12,11,-12,leaves:0)
B(-12,12,-12,leaves:0)
B(-3,18,5,leaves:0)
B(-16,12,-3,leaves:0)
B(-2,-3,1,LOG:12)
B(3,18,14,leaves:0)
B(1,10,-3,leaves:0)
B(-2,-4,1,LOG:12)
B(3,17,14,leaves:0)
B(3,14,14,leaves:0)
B(1,15,-3,leaves:0)
B(3,13,14,leaves:0)
B(1,14,-3,leaves:0)
B(3,12,14,leaves:0)
B(-15,8,-7,leaves:0)
B(1,13,-3,leaves:0)
B(3,11,14,leaves:0)
B(5,13,6,leaves:0)
B(-12,6,3,leaves:0)
B(-2,-1,1,LOG:12)
B(3,19,14,leaves:0)
B(-2,-2,1,LOG:12)
B(5,16,6,leaves:0)
B(5,17,6,leaves:0)
B(5,14,6,leaves:0)
B(5,15,6,leaves:0)
B(5,18,6,leaves:0)
B(5,19,6,leaves:0)
B(1,18,-3,leaves:0)
B(3,10,14,leaves:0)
B(1,19,-3,leaves:0)
B(1,16,-3,leaves:0)
B(1,17,-3,leaves:0)
B(-1,11,-5,leaves:0)
B(-6,17,-12,leaves:0)
B(-1,12,-5,leaves:0)
B(-6,16,-12,leaves:0)
B(13,18,5,leaves:0)
B(-1,13,-5,leaves:0)
B(-6,15,-12,leaves:0)
B(-6,14,-12,leaves:0)
B(-1,14,-5,leaves:0)
B(-6,13,-12,leaves:0)
B(-6,12,-12,leaves:0)
B(-6,11,-12,leaves:0)
B(-6,10,-12,leaves:0)
B(13,11,5,leaves:0)
B(-14,17,-2,leaves:0)
B(13,10,5,leaves:0)
B(-14,16,-2,leaves:0)
B(5,-4,-4,LOG:12)
B(13,12,5,leaves:0)
B(3,9,-14,leaves:0)
B(3,8,-14,leaves:0)
B(3,7,-14,leaves:0)
B(13,17,5,leaves:0)
B(-6,18,-12,leaves:0)
B(5,17,5,leaves:0)
B(5,18,5,leaves:0)
B(5,19,5,leaves:0)
B(-14,10,-2,leaves:0)
B(5,13,5,leaves:0)
B(-14,13,-2,leaves:0)
B(5,14,5,leaves:0)
B(-14,14,-2,leaves:0)
B(5,15,5,leaves:0)
B(-14,15,-2,leaves:0)
B(5,16,5,leaves:0)
B(-4,-2,2,LOG:12)
B(-4,-3,2,LOG:12)
B(-4,-4,2,LOG:12)
B(-14,-3,-5,LOG:12)
B(-14,-4,-5,LOG:12)
B(-1,20,-5,leaves:0)
B(-1,21,-5,leaves:0)
B(-4,-1,2,LOG:12)
B(-1,13,-4,leaves:0)
B(-1,12,-4,leaves:0)
B(5,20,5,leaves:0)
B(-4,12,8,LOG:12)
B(-5,16,-11,leaves:0)
B(-4,13,8,leaves:0)
B(-5,17,-11,leaves:0)
B(-4,10,8,LOG:12)
B(-4,11,8,LOG:12)
B(-14,9,-6,leaves:0)
B(-4,16,8,leaves:0)
B(-4,17,8,leaves:0)
B(-5,10,-11,leaves:0)
B(-5,11,-11,leaves:0)
B(-5,12,-11,leaves:0)
B(-1,18,-5,leaves:0)
B(-5,13,-11,leaves:0)
B(-1,17,-5,leaves:0)
B(-5,14,-11,leaves:0)
B(-9,18,1,leaves:0)
B(-5,15,-11,leaves:0)
B(-1,15,-5,leaves:0)
B(-9,19,1,leaves:0)
B(-1,21,-4,leaves:0)
B(-1,14,-4,leaves:0)
B(-1,15,-4,leaves:0)
B(-1,16,-4,leaves:0)
B(-1,17,-4,leaves:0)
B(-1,18,-4,leaves:0)
B(-1,19,-4,leaves:0)
B(1,-4,-3,LOG:12)
B(1,-3,-3,LOG:12)
B(1,-2,-3,LOG:12)
B(0,9,-12,leaves:0)
B(0,8,-12,leaves:0)
B(5,10,-12,leaves:0)
B(5,11,-12,leaves:0)
B(-6,11,13,leaves:0)
B(9,19,2,leaves:0)
B(9,18,2,leaves:0)
B(9,17,2,leaves:0)
B(9,16,2,leaves:0)
B(9,15,2,leaves:0)
B(9,14,2,leaves:0)
B(2,5,-13,leaves:0)
B(2,6,-13,leaves:0)
B(-6,17,13,leaves:0)
B(-6,16,13,leaves:0)
B(-6,15,13,leaves:0)
B(-6,14,13,leaves:0)
B(-16,6,-12,leaves:0)
B(9,13,2,leaves:0)
B(-14,10,-5,leaves:0)
B(2,8,-13,leaves:0)
B(-3,-4,4,LOG:12)
B(-3,-3,4,LOG:12)
B(6,13,15,leaves:0)
B(-15,10,14,leaves:0)
B(6,14,15,leaves:0)
B(6,11,15,leaves:0)
B(6,12,15,leaves:0)
B(-9,-4,12,LOG:12)
B(-14,12,-5,leaves:0)
B(-3,-2,4,LOG:12)
B(-9,-3,12,LOG:12)
B(-14,11,-5,leaves:0)
B(-4,20,8,leaves:0)
B(-8,10,16,leaves:0)
B(-8,11,16,leaves:0)
B(-8,12,16,leaves:0)
B(-8,13,16,leaves:0)
B(-4,21,8,leaves:0)
B(2,14,-8,leaves:0)
B(2,15,-8,leaves:0)
B(2,12,-8,leaves:0)
B(2,13,-8,leaves:0)
B(2,19,-8,leaves:0)
B(2,16,-8,leaves:0)
B(-4,18,8,leaves:0)
B(-4,19,8,leaves:0)
B(2,10,-8,leaves:0)
B(2,11,-8,LOG:12)
B(-13,15,9,leaves:0)
B(-13,16,9,leaves:0)
B(-13,17,9,leaves:0)
B(-13,11,9,leaves:0)
B(-13,12,9,leaves:0)
B(7,7,-14,leaves:0)
B(-13,13,9,leaves:0)
B(7,8,-14,leaves:0)
B(-13,14,9,leaves:0)
B(-11,14,-8,leaves:0)
B(-11,13,-8,leaves:0)
B(-11,15,-8,leaves:0)
B(-11,12,-8,leaves:0)
B(14,12,3,leaves:0)
B(-6,9,9,leaves:0)
B(14,16,3,leaves:0)
B(-13,10,9,leaves:0)
B(14,17,3,leaves:0)
B(-11,11,3,leaves:0)
B(-12,11,1,leaves:0)
B(-11,12,3,leaves:0)
B(-12,10,1,leaves:0)
B(-12,13,1,leaves:0)
B(-11,14,3,leaves:0)
B(-12,15,1,leaves:0)
B(-11,15,3,leaves:0)
B(-12,14,1,leaves:0)
B(-11,16,3,leaves:0)
B(-12,17,1,leaves:0)
B(-11,17,3,leaves:0)
B(-12,16,1,leaves:0)
B(-3,12,4,leaves:0)
B(-10,14,-10,leaves:0)
B(-10,15,-10,leaves:0)
B(-10,16,-10,leaves:0)
B(-10,17,-10,leaves:0)
B(-11,10,3,leaves:0)
B(-10,18,-10,leaves:0)
B(-11,9,12,leaves:0)
B(-2,21,1,leaves:0)
B(-2,20,1,leaves:0)
B(-3,9,-11,leaves:0)
B(-3,8,-11,leaves:0)
B(-17,9,-3,leaves:0)
B(-3,7,-11,leaves:0)
B(6,19,8,leaves:0)
B(-1,12,0,leaves:0)
B(-1,13,0,leaves:0)
B(6,17,8,leaves:0)
B(-8,4,-3,leaves:0)
B(-1,14,0,leaves:0)
B(6,18,8,leaves:0)
B(-3,21,4,leaves:0)
B(-1,15,0,leaves:0)
B(-9,15,12,leaves:0)
B(-3,20,4,leaves:0)
B(-9,14,12,leaves:0)
B(-1,16,0,leaves:0)
B(-9,13,12,leaves:0)
B(-1,17,0,leaves:0)
B(-9,12,12,leaves:0)
B(-1,18,0,leaves:0)
B(-9,11,12,leaves:0)
B(-1,19,0,leaves:0)
B(-9,10,12,leaves:0)
B(-3,17,4,leaves:0)
B(-3,18,4,leaves:0)
B(-3,19,4,leaves:0)
B(-14,9,8,leaves:0)
B(-14,8,8,leaves:0)
B(13,17,4,leaves:0)
B(-3,14,4,leaves:0)
B(13,18,4,leaves:0)
B(-9,16,12,leaves:0)
B(-3,16,4,leaves:0)
B(-9,17,12,leaves:0)
B(-8,6,-3,leaves:0)
B(-8,5,-3,leaves:0)
B(6,15,8,leaves:0)
B(-8,8,-3,leaves:0)
B(6,14,8,leaves:0)
B(-12,18,1,leaves:0)
B(-8,7,-3,leaves:0)
B(-12,19,1,leaves:0)
B(13,10,4,leaves:0)
B(-8,9,-3,leaves:0)
B(13,11,4,leaves:0)
B(13,12,4,leaves:0)
B(-1,21,0,leaves:0)
B(-10,18,-1,leaves:0)
B(-10,17,-1,leaves:0)
B(-10,14,-1,leaves:0)
B(-10,13,-1,LOG:12)
B(8,14,13,leaves:0)
B(-10,19,-1,leaves:0)
B(8,13,13,leaves:0)
B(8,16,13,leaves:0)
B(8,10,13,leaves:0)
B(8,12,13,leaves:0)
B(8,11,13,leaves:0)
B(-10,20,-1,leaves:0)
B(2,8,-15,leaves:0)
B(-10,9,13,leaves:0)
B(-2,15,1,leaves:0)
B(-2,14,1,leaves:0)
B(-2,19,1,leaves:0)
B(-2,18,1,leaves:0)
B(-2,17,1,leaves:0)
B(-12,11,14,leaves:0)
B(6,9,-8,leaves:0)
B(-12,10,14,leaves:0)
B(6,8,-8,leaves:0)
B(-12,14,14,leaves:0)
B(-12,13,14,leaves:0)
B(-12,12,14,leaves:0)
B(8,19,5,leaves:0)
B(8,18,5,leaves:0)
B(-14,15,8,leaves:0)
B(8,17,5,leaves:0)
B(8,16,5,leaves:0)
B(-14,16,8,leaves:0)
B(-14,13,8,leaves:0)
B(-14,14,8,leaves:0)
B(-14,11,8,leaves:0)
B(-14,12,8,leaves:0)
B(-14,10,8,leaves:0)
B(8,14,5,leaves:0)
B(8,15,5,leaves:0)
B(8,12,5,leaves:0)
B(11,17,9,leaves:0)
B(-8,-3,-9,LOG:12)
B(-8,-5,-9,LOG:12)
B(11,13,9,leaves:0)
B(11,12,9,leaves:0)
B(-8,-4,-9,LOG:12)
B(-4,20,12,leaves:0)
B(4,-4,7,LOG:12)
B(-3,19,-7,leaves:0)
B(4,-5,7,LOG:12)
B(-12,10,-13,leaves:0)
B(-12,13,-13,leaves:0)
B(-3,17,-7,leaves:0)
B(4,-3,7,LOG:12)
B(-3,18,-7,leaves:0)
B(-3,15,-7,leaves:0)
B(-3,16,-7,leaves:0)
B(-12,-4,-8,LOG:12)
B(-4,12,12,leaves:0)
B(-4,17,12,leaves:0)
B(-17,9,-14,leaves:0)
B(-4,18,12,leaves:0)
B(-4,19,12,leaves:0)
B(-3,14,-7,leaves:0)
B(-4,13,12,leaves:0)
B(-4,14,12,leaves:0)
B(-4,15,12,leaves:0)
B(-4,16,12,leaves:0)
B(-9,10,14,leaves:0)
B(-9,11,14,leaves:0)
B(-9,12,14,leaves:0)
B(-9,13,14,leaves:0)
B(-17,7,5,leaves:0)
B(-9,16,14,leaves:0)
B(8,-4,5,LOG:12)
B(9,9,-6,leaves:0)
B(6,13,-8,leaves:0)
B(6,12,-8,leaves:0)
B(6,11,-8,leaves:0)
B(6,10,-8,leaves:0)
B(6,20,1,leaves:0)
B(-7,9,3,leaves:0)
B(0,12,18,leaves:0)
B(0,13,18,leaves:0)
B(-8,15,-9,leaves:0)
B(-8,16,-9,leaves:0)
B(-8,17,-9,leaves:0)
B(-16,6,-11,leaves:0)
B(-16,5,-11,leaves:0)
B(-16,7,-11,leaves:0)
B(-6,20,8,leaves:0)
B(-6,21,8,leaves:0)
B(0,18,9,leaves:0)
B(0,15,9,leaves:0)
B(-6,11,8,LOG:12)
B(-6,10,8,leaves:0)
B(-12,17,-8,leaves:0)
B(-12,16,-8,leaves:0)
B(-12,11,-8,leaves:0)
B(-6,18,8,leaves:0)
B(-12,15,-8,leaves:0)
B(-6,15,8,leaves:0)
B(15,11,-1,leaves:0)
B(-12,14,-8,leaves:0)
B(-12,13,-8,leaves:0)
B(-6,12,8,LOG:12)
B(-12,12,-8,leaves:0)
B(-2,10,-11,leaves:0)
B(6,15,1,leaves:0)
B(-2,12,-11,leaves:0)
B(6,17,1,leaves:0)
B(-2,11,-11,leaves:0)
B(-2,14,-11,leaves:0)
B(6,19,1,leaves:0)
B(-2,13,-11,leaves:0)
B(6,18,1,leaves:0)
B(-2,16,-11,leaves:0)
B(-2,15,-11,leaves:0)
B(-14,11,12,leaves:0)
B(-16,8,-8,leaves:0)
B(-16,7,-8,leaves:0)
B(-14,8,-7,leaves:0)
B(-16,9,-8,leaves:0)
B(-5,22,12,leaves:0)
B(4,7,-14,leaves:0)
B(4,6,-14,leaves:0)
B(-1,10,7,leaves:0)
B(-1,11,7,leaves:0)
B(-1,12,7,leaves:0)
B(4,8,-14,leaves:0)
B(-5,17,5,leaves:0)
B(1,18,-1,leaves:0)
B(-5,16,5,leaves:0)
B(1,19,-1,leaves:0)
B(1,16,-1,leaves:0)
B(1,17,-1,leaves:0)
B(-5,17,12,leaves:0)
B(-5,20,5,leaves:0)
B(-5,16,12,leaves:0)
B(-5,18,12,leaves:0)
B(-5,13,12,leaves:0)
B(-5,12,12,leaves:0)
B(-5,15,12,leaves:0)
B(-5,14,12,leaves:0)
B(2,18,-3,leaves:0)
B(2,15,-3,leaves:0)
B(2,19,-3,leaves:0)
B(-11,9,-14,leaves:0)
B(2,14,-3,leaves:0)
B(2,13,-3,leaves:0)
B(2,12,-3,leaves:0)
B(-1,19,7,leaves:0)
B(-1,18,7,leaves:0)
B(-1,17,7,leaves:0)
B(-1,21,7,leaves:0)
B(-1,20,7,leaves:0)
B(-5,-3,-1,LOG:12)
B(-5,-4,-1,LOG:12)
B(-5,-1,-1,LOG:12)
B(-5,-2,-1,LOG:12)
B(10,10,-7,leaves:0)
B(10,11,-7,leaves:0)
B(11,9,0,leaves:0)
B(-11,12,-11,leaves:0)
B(-11,11,-11,leaves:0)
B(-11,10,-11,leaves:0)
B(0,-1,3,LOG:12)
B(0,-3,3,LOG:12)
B(0,-2,3,LOG:12)
B(0,-4,3,LOG:12)
B(-5,-2,5,LOG:12)
B(1,-4,-1,LOG:12)
B(-5,-3,5,LOG:12)
B(-5,-4,5,LOG:12)
B(-5,-5,5,LOG:12)
B(1,-1,-1,LOG:12)
B(1,-3,-1,LOG:12)
B(1,-2,-1,LOG:12)
B(-11,13,-11,leaves:0)
B(-11,14,-11,leaves:0)
B(-11,15,-11,leaves:0)
B(1,-4,1,LOG:12)
B(1,-3,1,LOG:12)
B(1,-2,1,LOG:12)
B(-4,21,9,leaves:0)
B(-4,20,9,leaves:0)
B(2,-4,-3,LOG:12)
B(2,-3,-3,LOG:12)
B(-17,11,6,leaves:0)
B(-17,10,6,leaves:0)
B(-4,19,9,leaves:0)
B(-14,10,3,leaves:0)
B(-5,15,5,leaves:0)
B(-14,11,3,leaves:0)
B(-5,14,5,leaves:0)
B(-14,12,3,leaves:0)
B(-5,13,5,leaves:0)
B(-5,12,5,leaves:0)
B(-14,13,3,leaves:0)
B(-5,11,5,leaves:0)
B(-5,10,5,leaves:0)
B(-14,18,3,leaves:0)
B(-14,14,3,leaves:0)
B(-14,15,3,leaves:0)
B(-14,17,3,leaves:0)
B(-6,8,-14,leaves:0)
B(-6,7,-14,leaves:0)
B(-6,9,-14,leaves:0)
B(-4,14,9,leaves:0)
B(-4,13,9,leaves:0)
B(-6,6,-14,leaves:0)
B(-4,11,9,leaves:0)
B(-4,18,9,leaves:0)
B(-4,17,9,leaves:0)
B(-4,16,9,leaves:0)
B(-15,6,1,leaves:0)
B(-15,7,1,leaves:0)
B(-15,8,1,leaves:0)
B(-15,9,1,leaves:0)
B(14,18,4,leaves:0)
B(1,16,1,leaves:0)
B(1,17,1,leaves:0)
B(1,18,1,leaves:0)
B(1,19,1,leaves:0)
B(8,19,6,leaves:0)
B(3,13,9,leaves:0)
B(3,14,9,leaves:0)
B(14,16,4,leaves:0)
B(8,17,6,leaves:0)
B(14,17,4,leaves:0)
B(8,18,6,leaves:0)
B(8,16,6,leaves:0)
B(3,18,9,leaves:0)
B(8,15,6,leaves:0)
B(3,17,9,leaves:0)
B(8,14,6,leaves:0)
B(3,16,9,LOG:12)
B(8,13,6,leaves:0)
B(3,15,9,leaves:0)
B(8,12,6,leaves:0)
B(8,10,6,leaves:0)
B(3,19,9,leaves:0)
B(-2,9,-14,leaves:0)
B(-2,7,-14,leaves:0)
B(-2,8,-14,leaves:0)
B(-2,6,-14,leaves:0)
B(0,11,3,leaves:0)
B(3,20,9,leaves:0)
B(0,18,3,leaves:0)
B(0,19,3,leaves:0)
B(0,16,3,LOG:12)
B(-8,7,-4,leaves:0)
B(0,17,3,leaves:0)
B(1,20,1,leaves:0)
B(1,21,1,leaves:0)
B(-8,5,-4,leaves:0)
B(0,15,3,leaves:0)
B(8,20,6,leaves:0)
B(0,20,3,leaves:0)
B(0,21,3,leaves:0)
B(-3,21,7,leaves:0)
B(-3,20,7,leaves:0)
B(0,9,-13,leaves:0)
B(-3,19,7,leaves:0)
B(-3,18,7,leaves:0)
B(-3,17,7,LOG:12)
B(13,9,5,leaves:0)
B(0,5,-13,leaves:0)
B(0,6,-13,leaves:0)
B(0,7,-13,leaves:0)
B(0,8,-13,leaves:0)
B(-15,11,8,leaves:0)
B(-15,10,8,leaves:0)
B(-15,14,8,leaves:0)
B(-15,12,8,leaves:0)
B(-15,13,8,leaves:0)
B(-16,8,12,leaves:0)
B(-5,21,-1,leaves:0)
B(-5,20,-1,leaves:0)
B(-5,23,-1,leaves:0)
B(-5,22,-1,leaves:0)
B(3,11,-7,LOG:12)
B(-9,10,5,leaves:0)
B(-9,11,5,leaves:0)
B(3,10,-7,leaves:0)
B(-5,19,-1,leaves:0)
B(3,13,-7,leaves:0)
B(3,12,-7,leaves:0)
B(-5,16,-1,leaves:0)
B(3,14,-7,leaves:0)
B(-5,15,-1,leaves:0)
B(-5,18,-1,leaves:0)
B(3,16,-7,leaves:0)
B(-5,17,-1,leaves:0)
B(-5,12,-1,leaves:0)
B(-9,18,5,LOG:12)
B(-9,19,5,LOG:12)
B(-5,11,-1,leaves:0)
B(-5,14,-1,leaves:0)
B(-9,16,5,leaves:0)
B(4,18,-8,leaves:0)
B(-5,13,-1,leaves:0)
B(-9,17,5,leaves:0)
B(4,19,-8,leaves:0)
B(-9,14,5,leaves:0)
B(-9,15,5,leaves:0)
B(-9,12,5,leaves:0)
B(-5,10,-1,leaves:0)
B(-9,13,5,leaves:0)
B(4,13,-8,leaves:0)
B(4,12,-8,leaves:0)
B(4,11,-8,leaves:0)
B(4,10,-8,leaves:0)
B(-12,9,2,leaves:0)
B(3,18,-7,leaves:0)
B(-13,8,-15,leaves:0)
B(3,19,-7,leaves:0)
B(-15,8,-6,leaves:0)
B(-15,9,-6,leaves:0)
B(0,7,-2,LOG:12)
B(0,8,-2,LOG:12)
B(0,9,-2,leaves:0)
B(0,6,-2,LOG:12)
B(13,12,2,leaves:0)
B(13,11,2,leaves:0)
B(7,8,-13,leaves:0)
B(13,14,2,leaves:0)
B(13,13,2,leaves:0)
B(13,10,2,leaves:0)
B(2,10,-11,leaves:0)
B(2,11,-11,leaves:0)
B(4,20,-8,leaves:0)
B(2,12,-11,leaves:0)
B(2,13,-11,leaves:0)
B(-11,9,13,leaves:0)
B(-11,8,13,leaves:0)
B(-17,9,-4,leaves:0)
B(12,17,4,leaves:0)
B(12,16,4,leaves:0)
B(-16,10,-2,leaves:0)
B(-16,13,-2,leaves:0)
B(12,11,4,leaves:0)
B(12,10,4,leaves:0)
B(12,12,4,leaves:0)
B(12,15,4,leaves:0)
B(12,14,4,leaves:0)
B(-11,11,15,leaves:0)
B(-5,10,3,leaves:0)
B(-5,11,3,leaves:0)
B(-11,10,15,leaves:0)
B(-5,12,3,leaves:0)
B(-11,12,15,leaves:0)
B(-5,13,3,leaves:0)
B(2,7,-14,leaves:0)
B(-16,15,-2,leaves:0)
B(2,8,-14,leaves:0)
B(-9,22,5,leaves:0)
B(-9,21,5,leaves:0)
B(-9,20,5,leaves:0)
B(-5,17,3,leaves:0)
B(-5,16,3,leaves:0)
B(-5,15,3,leaves:0)
B(-5,14,3,leaves:0)
B(-5,18,3,leaves:0)
B(-5,20,3,leaves:0)
B(-13,16,6,leaves:0)
B(-13,17,6,leaves:0)
B(-13,18,6,leaves:0)
B(-13,19,6,leaves:0)
B(-3,12,6,leaves:0)
B(-13,12,6,leaves:0)
B(-3,11,6,leaves:0)
B(-13,13,6,leaves:0)
B(-13,14,6,leaves:0)
B(-3,14,6,leaves:0)
B(-3,13,6,leaves:0)
B(-13,15,6,leaves:0)
B(-3,10,6,leaves:0)
B(-13,11,6,leaves:0)
B(-3,19,6,leaves:0)
B(-6,-2,8,LOG:12)
B(-3,17,6,leaves:0)
B(-3,18,6,leaves:0)
B(-3,15,6,leaves:0)
B(-3,16,6,leaves:0)
B(7,10,-5,leaves:0)
B(7,11,-5,leaves:0)
B(7,17,-5,leaves:0)
B(7,18,-5,leaves:0)
B(7,13,-5,leaves:0)
B(7,12,-5,leaves:0)
B(7,14,-5,leaves:0)
B(-3,21,6,leaves:0)
B(-5,14,-10,leaves:0)
B(-5,13,-10,leaves:0)
B(-5,10,-10,leaves:0)
B(13,10,6,leaves:0)
B(-5,16,-10,leaves:0)
B(-5,15,-10,leaves:0)
B(1,20,-7,leaves:0)
B(-3,7,-12,leaves:0)
B(-3,9,-12,leaves:0)
B(4,20,7,leaves:0)
B(-3,8,-12,leaves:0)
B(-17,8,11,leaves:0)
B(8,10,-10,leaves:0)
B(13,11,6,leaves:0)
B(13,12,6,leaves:0)
B(-14,9,7,leaves:0)
B(-5,-2,3,LOG:12)
B(-5,-3,3,LOG:12)
B(-9,19,0,leaves:0)
B(-9,18,0,leaves:0)
B(-5,-4,3,LOG:12)
B(4,17,1,leaves:0)
B(4,16,1,leaves:0)
B(4,19,1,leaves:0)
B(4,18,1,leaves:0)
B(4,14,7,leaves:0)
B(4,17,7,leaves:0)
B(4,16,7,leaves:0)
B(4,19,7,leaves:0)
B(4,18,7,leaves:0)
B(11,15,11,leaves:0)
B(11,11,11,leaves:0)
B(1,10,-7,leaves:0)
B(11,12,11,leaves:0)
B(1,11,-7,leaves:0)
B(11,13,11,leaves:0)
B(11,14,11,leaves:0)
B(6,7,-9,leaves:0)
B(1,14,-7,leaves:0)
B(1,15,-7,leaves:0)
B(1,12,-7,leaves:0)
B(6,8,-9,leaves:0)
B(1,13,-7,leaves:0)
B(1,16,-7,leaves:0)
B(1,17,-7,leaves:0)
B(0,20,-2,leaves:0)
B(0,21,-2,leaves:0)
B(-1,9,4,LOG:12)
B(-3,11,18,leaves:0)
B(-2,10,9,leaves:0)
B(-2,15,9,leaves:0)
B(-2,16,9,leaves:0)
B(-14,12,-12,leaves:0)
B(0,14,-2,leaves:0)
B(4,9,-11,leaves:0)
B(0,15,-2,leaves:0)
B(0,12,-2,leaves:0)
B(4,8,-11,leaves:0)
B(4,7,-11,leaves:0)
B(0,13,-2,leaves:0)
B(-2,18,9,leaves:0)
B(-2,17,9,leaves:0)
B(-2,19,9,leaves:0)
B(-2,20,9,leaves:0)
B(8,14,-4,leaves:0)
B(0,19,-2,leaves:0)
B(8,15,-4,leaves:0)
B(8,16,-4,leaves:0)
B(0,17,-2,leaves:0)
B(8,17,-4,leaves:0)
B(8,10,-4,leaves:0)
B(8,11,-4,leaves:0)
B(8,12,-4,leaves:0)
B(8,13,-4,leaves:0)
B(1,20,10,leaves:0)
B(-7,9,8,leaves:0)
B(-7,13,2,leaves:0)
B(1,21,10,leaves:0)
B(-7,11,2,leaves:0)
B(-7,12,2,leaves:0)
B(-12,9,13,leaves:0)
B(-7,10,2,leaves:0)
B(-17,9,0,leaves:0)
B(-6,7,-15,leaves:0)
B(-6,8,-15,leaves:0)
B(10,9,5,leaves:0)
B(-17,6,0,leaves:0)
B(1,15,10,leaves:0)
B(1,16,10,leaves:0)
B(-7,20,2,leaves:0)
B(-7,21,2,leaves:0)
B(1,19,10,leaves:0)
B(-5,12,-13,leaves:0)
B(-5,13,-13,leaves:0)
B(1,17,10,leaves:0)
B(-5,16,-13,leaves:0)
B(-5,17,-13,leaves:0)
B(-5,14,-13,leaves:0)
B(-15,10,10,leaves:0)
B(-15,12,10,leaves:0)
B(-15,11,10,leaves:0)
B(-16,7,5,leaves:0)
B(-3,12,18,leaves:0)
B(-7,19,2,leaves:0)
B(-7,16,2,leaves:0)
B(-7,18,2,leaves:0)
B(-7,17,2,leaves:0)
B(-1,8,-15,leaves:0)
B(1,9,-4,LOG:12)
B(1,8,-4,LOG:12)
B(-11,6,4,leaves:0)
B(-6,12,10,LOG:12)
B(-6,15,10,leaves:0)
B(-6,16,10,leaves:0)
B(-6,13,10,leaves:0)
B(-6,14,10,leaves:0)
B(-6,18,10,leaves:0)
B(-6,17,10,leaves:0)
B(-13,9,8,leaves:0)
B(-14,7,-8,leaves:0)
B(-13,7,8,leaves:0)
B(-14,8,-8,leaves:0)
B(-13,8,8,leaves:0)
B(2,20,7,leaves:0)
B(-10,8,-13,leaves:0)
B(-14,12,1,leaves:0)
B(-13,7,-11,leaves:0)
B(-14,13,1,leaves:0)
B(-13,8,-11,leaves:0)
B(-10,9,-13,leaves:0)
B(-14,10,1,leaves:0)
B(-14,11,1,leaves:0)
B(2,-4,-1,LOG:12)
B(2,-3,-1,LOG:12)
B(2,-2,-1,LOG:12)
B(15,11,0,leaves:0)
B(-6,19,4,leaves:0)
B(-6,20,4,leaves:0)
B(-6,7,-3,leaves:0)
B(-6,8,-3,leaves:0)
B(-6,9,-3,leaves:0)
B(-6,21,4,leaves:0)
B(-6,5,-3,LOG:12)
B(-6,6,-3,leaves:0)
B(-5,14,6,leaves:0)
B(-5,13,6,leaves:0)
B(-5,16,6,leaves:0)
B(-5,15,6,leaves:0)
B(-5,10,6,leaves:0)
B(-5,12,6,leaves:0)
B(-5,11,6,leaves:0)
B(-5,17,6,leaves:0)
B(4,16,-7,leaves:0)
B(4,15,-7,leaves:0)
B(4,14,-7,leaves:0)
B(4,12,-7,leaves:0)
B(1,6,-11,leaves:0)
B(4,11,-7,leaves:0)
B(1,8,-11,leaves:0)
B(1,9,-11,leaves:0)
B(2,17,7,leaves:0)
B(2,16,7,leaves:0)
B(2,19,7,leaves:0)
B(-3,19,12,leaves:0)
B(2,18,7,leaves:0)
B(-3,16,12,leaves:0)
B(4,19,-7,leaves:0)
B(-3,17,12,leaves:0)
B(-3,14,12,leaves:0)
B(2,14,7,leaves:0)
B(-3,15,12,leaves:0)
B(-3,12,12,leaves:0)
B(-3,13,12,leaves:0)
B(-5,22,6,leaves:0)
B(-5,20,6,leaves:0)
B(3,-4,4,LOG:12)
B(1,16,-10,leaves:0)
B(-9,18,-11,leaves:0)
B(-9,17,-11,leaves:0)
B(-9,16,-11,leaves:0)
B(-9,15,-11,leaves:0)
B(6,20,0,leaves:0)
B(-9,12,-11,leaves:0)
B(2,-4,1,LOG:12)
B(-9,22,8,leaves:0)
B(-9,21,8,leaves:0)
B(2,-3,1,LOG:12)
B(6,18,0,leaves:0)
B(6,17,0,leaves:0)
B(6,19,0,leaves:0)
B(2,19,-1,leaves:0)
B(2,17,-1,leaves:0)
B(2,18,-1,leaves:0)
B(2,12,-1,leaves:0)
B(-9,11,8,leaves:0)
B(-6,15,4,leaves:0)
B(-6,14,4,leaves:0)
B(-9,10,-11,leaves:0)
B(-6,13,4,leaves:0)
B(-6,12,4,leaves:0)
B(-6,11,4,leaves:0)
B(-9,10,8,leaves:0)
B(-9,19,8,leaves:0)
B(1,11,-10,leaves:0)
B(1,10,-10,leaves:0)
B(1,15,-10,leaves:0)
B(-9,15,8,leaves:0)
B(1,14,-10,leaves:0)
B(-9,16,8,leaves:0)
B(1,13,-10,leaves:0)
B(-9,17,8,leaves:0)
B(1,12,-10,leaves:0)
B(-9,18,8,leaves:0)
B(-6,-2,4,LOG:12)
B(-6,-4,4,LOG:12)
B(2,9,-9,leaves:0)
B(-6,15,2,leaves:0)
B(-6,14,2,leaves:0)
B(-6,16,2,leaves:0)
B(-6,19,2,LOG:12)
B(-6,18,2,LOG:12)
B(-6,20,2,LOG:12)
B(-5,-2,6,LOG:12)
B(-6,21,2,leaves:0)
B(-6,22,2,leaves:0)
B(0,-2,-2,LOG:12)
B(0,-3,-2,LOG:12)
B(0,-4,-2,LOG:12)
B(0,-5,-2,LOG:12)
B(-5,-4,6,LOG:12)
B(2,20,1,leaves:0)
B(2,22,1,leaves:0)
B(2,21,1,leaves:0)
B(1,-3,2,LOG:12)
B(1,-4,2,LOG:12)
B(13,11,-8,leaves:0)
B(10,16,-1,leaves:0)
B(-14,6,1,leaves:0)
B(-12,10,3,leaves:0)
B(-12,11,3,leaves:0)
B(-14,12,-8,leaves:0)
B(-12,14,3,leaves:0)
B(2,19,1,leaves:0)
B(-12,15,3,leaves:0)
B(2,18,1,leaves:0)
B(-12,12,3,leaves:0)
B(-14,10,-8,leaves:0)
B(-14,11,-8,leaves:0)
B(-12,13,3,leaves:0)
B(-12,18,3,leaves:0)
B(-12,19,3,leaves:0)
B(-12,16,3,leaves:0)
B(2,17,1,leaves:0)
B(2,16,1,leaves:0)
B(-12,17,3,leaves:0)
B(-2,18,-5,leaves:0)
B(-2,19,-5,leaves:0)
B(-2,14,-5,leaves:0)
B(-2,15,-5,leaves:0)
B(-2,16,-5,leaves:0)
B(-2,17,-5,leaves:0)
B(3,19,8,leaves:0)
B(3,18,8,leaves:0)
B(-12,-4,-4,LOG:12)
B(3,17,8,leaves:0)
B(3,16,8,LOG:12)
B(-12,-2,-4,LOG:12)
B(-12,-3,-4,LOG:12)
B(-14,8,1,leaves:0)
B(-14,7,1,leaves:0)
B(12,13,14,leaves:0)
B(-14,9,1,leaves:0)
B(-10,18,9,leaves:0)
B(-10,17,9,leaves:0)
B(-10,16,9,leaves:0)
B(11,10,-7,leaves:0)
B(10,14,-1,leaves:0)
B(-10,15,9,leaves:0)
B(-2,21,-5,leaves:0)
B(-10,14,9,leaves:0)
B(10,15,-1,leaves:0)
B(10,12,-1,leaves:0)
B(-10,12,9,leaves:0)
B(10,13,-1,leaves:0)
B(-10,11,9,leaves:0)
B(10,10,-1,leaves:0)
B(10,11,-1,leaves:0)
B(-2,20,-5,leaves:0)
B(1,19,2,leaves:0)
B(1,18,2,leaves:0)
B(1,17,2,leaves:0)
B(1,16,2,leaves:0)
B(1,15,2,leaves:0)
B(-9,9,9,leaves:0)
B(5,7,-10,leaves:0)
B(5,8,-10,leaves:0)
B(5,9,-10,leaves:0)
B(4,20,9,leaves:0)
B(8,20,5,leaves:0)
B(7,17,8,leaves:0)
B(7,16,8,leaves:0)
B(7,15,8,leaves:0)
B(7,14,8,leaves:0)
B(7,12,17,leaves:0)
B(7,18,8,leaves:0)
B(7,19,8,leaves:0)
B(-5,-3,-3,LOG:12)
B(1,14,15,leaves:0)
B(-5,-4,-3,LOG:12)
B(1,15,15,leaves:0)
B(-5,-5,-3,LOG:12)
B(1,16,15,leaves:0)
B(1,18,15,leaves:0)
B(-5,-2,-3,LOG:12)
B(1,13,15,leaves:0)
B(1,12,15,leaves:0)
B(-4,9,5,LOG:12)
B(-4,8,5,LOG:12)
B(7,9,13,leaves:0)
B(7,20,8,leaves:0)
B(11,12,14,leaves:0)
B(1,8,-12,leaves:0)
B(11,10,14,leaves:0)
B(1,6,-12,leaves:0)
B(11,11,14,leaves:0)
B(-15,9,10,leaves:0)
B(-5,12,-3,leaves:0)
B(1,20,2,leaves:0)
B(-5,11,-3,leaves:0)
B(-5,14,-3,leaves:0)
B(-5,13,-3,leaves:0)
B(-5,16,-3,leaves:0)
B(-5,15,-3,leaves:0)
B(1,9,-12,leaves:0)
B(-5,18,-3,leaves:0)
B(-11,12,14,leaves:0)
B(-6,9,-2,leaves:0)
B(-11,11,14,leaves:0)
B(-6,8,-2,LOG:12)
B(-5,19,-3,leaves:0)
B(-6,7,-2,LOG:12)
B(-11,14,14,leaves:0)
B(-6,6,-2,leaves:0)
B(-11,13,14,leaves:0)
B(-6,5,-2,leaves:0)
B(-4,-1,-3,LOG:12)
B(-4,-2,-3,LOG:12)
B(-4,-3,-3,LOG:12)
B(-8,11,13,leaves:0)
B(-4,-4,-3,LOG:12)
B(-8,17,5,leaves:0)
B(-8,18,5,LOG:12)
B(-8,13,13,leaves:0)
B(-8,15,5,leaves:0)
B(-8,12,13,leaves:0)
B(-8,16,5,leaves:0)
B(-8,14,5,leaves:0)
B(-8,14,13,leaves:0)
B(-8,12,5,leaves:0)
B(-8,16,13,leaves:0)
B(-9,19,6,leaves:0)
B(-9,22,7,leaves:0)
B(-9,17,6,leaves:0)
B(-9,21,7,leaves:0)
B(-9,18,6,leaves:0)
B(-9,20,7,leaves:0)
B(-9,15,6,leaves:0)
B(-9,16,6,leaves:0)
B(-9,13,6,leaves:0)
B(-9,11,6,leaves:0)
B(-9,12,6,leaves:0)
B(-14,-3,-7,LOG:12)
B(-9,10,6,leaves:0)
B(-14,-4,-7,LOG:12)
B(-5,20,-3,leaves:0)
B(-5,21,-3,leaves:0)
B(-5,22,-3,leaves:0)
B(-8,20,5,leaves:0)
B(-8,21,5,leaves:0)
B(-8,22,5,leaves:0)
B(-9,24,6,leaves:0)
B(-8,19,5,leaves:0)
B(3,-4,5,LOG:12)
B(14,12,6,leaves:0)
B(-9,21,6,leaves:0)
B(-9,22,6,leaves:0)
B(3,-5,5,LOG:12)
B(14,10,6,leaves:0)
B(-17,10,-4,leaves:0)
B(7,19,-3,leaves:0)
B(8,20,2,leaves:0)
B(4,20,-4,leaves:0)
B(7,13,-3,leaves:0)
B(7,12,-3,leaves:0)
B(7,15,-3,leaves:0)
B(4,21,-4,leaves:0)
B(7,14,-3,leaves:0)
B(7,17,-3,leaves:0)
B(7,16,-3,leaves:0)
B(13,15,1,leaves:0)
B(4,16,-4,leaves:0)
B(4,17,-4,leaves:0)
B(4,14,-4,leaves:0)
B(4,18,-4,leaves:0)
B(4,19,-4,leaves:0)
B(8,15,2,leaves:0)
B(8,16,2,leaves:0)
B(8,14,2,leaves:0)
B(13,11,1,leaves:0)
B(8,19,2,leaves:0)
B(-10,15,2,leaves:0)
B(13,13,1,leaves:0)
B(-10,14,2,leaves:0)
B(8,17,2,leaves:0)
B(13,12,1,leaves:0)
B(8,18,2,leaves:0)
B(-9,12,7,leaves:0)
B(-9,17,7,leaves:0)
B(-9,19,7,leaves:0)
B(4,13,-4,leaves:0)
B(4,12,-4,LOG:12)
B(-9,18,7,leaves:0)
B(4,11,-4,leaves:0)
B(-4,19,-3,leaves:0)
B(-4,18,-3,leaves:0)
B(5,13,17,leaves:0)
B(3,20,5,leaves:0)
B(5,14,17,leaves:0)
B(3,21,5,leaves:0)
B(-5,9,-5,LOG:12)
B(-4,13,-3,leaves:0)
B(-4,14,-3,leaves:0)
B(-4,16,-3,leaves:0)
B(-13,18,3,leaves:0)
B(-13,17,3,leaves:0)
B(-14,17,-7,leaves:0)
B(-13,19,3,leaves:0)
B(-13,14,3,leaves:0)
B(-14,16,-7,leaves:0)
B(-13,13,3,leaves:0)
B(-14,15,-7,leaves:0)
B(-13,16,3,leaves:0)
B(-4,20,-3,leaves:0)
B(-14,13,-7,leaves:0)
B(-13,15,3,leaves:0)
B(-14,12,-7,leaves:0)
B(-13,10,3,leaves:0)
B(-14,11,-7,leaves:0)
B(5,20,1,leaves:0)
B(-13,12,3,leaves:0)
B(-14,10,-7,leaves:0)
B(-13,11,3,leaves:0)
B(-10,18,2,leaves:0)
B(6,20,-1,leaves:0)
B(5,17,1,leaves:0)
B(5,18,1,leaves:0)
B(-16,10,8,leaves:0)
B(5,19,1,leaves:0)
B(3,19,5,leaves:0)
B(3,14,5,leaves:0)
B(3,12,5,leaves:0)
B(3,11,5,leaves:0)
B(3,18,5,leaves:0)
B(3,17,5,leaves:0)
B(3,16,5,leaves:0)
B(3,15,5,leaves:0)
B(5,16,1,leaves:0)
B(6,17,-1,leaves:0)
B(6,18,-1,leaves:0)
B(4,8,-9,leaves:0)
B(6,19,-1,leaves:0)
B(4,17,9,leaves:0)
B(4,16,9,LOG:12)
B(4,19,9,leaves:0)
B(4,18,9,leaves:0)
B(6,13,-1,leaves:0)
B(6,14,-1,leaves:0)
B(6,15,-1,leaves:0)
B(6,16,-1,leaves:0)
B(4,12,9,leaves:0)
B(4,13,9,leaves:0)
B(4,14,9,leaves:0)
B(4,7,-9,leaves:0)
B(-12,9,-14,leaves:0)
B(-12,8,-14,leaves:0)
B(11,12,15,leaves:0)
B(-16,8,-14,leaves:0)
B(11,11,15,leaves:0)
B(-16,9,-14,leaves:0)
B(11,10,15,leaves:0)
B(-4,22,-3,leaves:0)
B(-4,21,-3,leaves:0)
B(4,-4,-4,LOG:12)
B(7,12,9,leaves:0)
B(7,13,9,leaves:0)
B(7,14,9,leaves:0)
B(7,15,9,leaves:0)
B(7,16,9,leaves:0)
B(7,17,9,leaves:0)
B(7,18,9,leaves:0)
B(-9,-3,-4,LOG:12)
B(-9,-4,-4,LOG:12)
B(-1,0,3,LOG:12)
B(-11,7,5,leaves:0)
B(-11,6,5,leaves:0)
B(4,9,-12,leaves:0)
B(4,8,-12,leaves:0)
B(4,7,-12,leaves:0)
B(7,20,9,leaves:0)
B(-14,9,-9,leaves:0)
B(-14,8,-9,leaves:0)
B(-14,7,-9,leaves:0)
B(-14,6,-9,leaves:0)
B(-8,12,-10,leaves:0)
B(-8,11,-10,leaves:0)
B(-15,15,-1,leaves:0)
B(-15,14,-1,leaves:0)
B(-8,17,-10,leaves:0)
B(-8,16,-10,leaves:0)
B(-8,15,-10,leaves:0)
B(-12,9,12,leaves:0)
B(-7,9,9,leaves:0)
B(-8,18,-10,leaves:0)
B(-7,8,9,leaves:0)
B(-12,7,12,leaves:0)
B(-14,7,0,leaves:0)
B(-14,6,0,leaves:0)
B(-15,13,-1,leaves:0)
B(-15,10,-1,leaves:0)
B(-12,10,4,leaves:0)
B(15,9,0,leaves:0)
B(-12,11,4,leaves:0)
B(-12,12,4,leaves:0)
B(-14,8,0,leaves:0)
B(-14,9,0,leaves:0)
B(2,-4,0,LOG:12)
B(-12,17,4,leaves:0)
B(2,-3,0,LOG:12)
B(-12,18,4,leaves:0)
B(-12,19,4,leaves:0)
B(-12,13,4,leaves:0)
B(-12,14,4,leaves:0)
B(-4,-4,5,LOG:12)
B(-12,15,4,leaves:0)
B(13,9,3,leaves:0)
B(-12,16,4,leaves:0)
B(-16,8,6,leaves:0)
B(-16,7,6,leaves:0)
B(12,9,7,leaves:0)
B(-12,20,4,leaves:0)
B(1,9,-3,leaves:0)
B(1,8,-3,leaves:0)
B(-2,18,-6,leaves:0)
B(-2,17,-6,leaves:0)
B(-2,19,-6,leaves:0)
B(-2,15,-3,leaves:0)
B(7,16,10,leaves:0)
B(-2,20,-3,leaves:0)
B(7,15,10,leaves:0)
B(-2,21,-3,leaves:0)
B(7,18,10,leaves:0)
B(-2,22,-3,leaves:0)
B(7,17,10,leaves:0)
B(7,12,10,leaves:0)
B(7,11,10,leaves:0)
B(-13,8,7,leaves:0)
B(7,14,10,leaves:0)
B(-13,9,7,leaves:0)
B(7,13,10,leaves:0)
B(-8,-4,-10,LOG:12)
B(5,14,-4,leaves:0)
B(5,13,-4,leaves:0)
B(5,16,-4,leaves:0)
B(5,15,-4,leaves:0)
B(3,9,-9,leaves:0)
B(5,18,-4,leaves:0)
B(5,17,-4,leaves:0)
B(3,8,-9,leaves:0)
B(5,19,-4,leaves:0)
B(5,12,-4,leaves:0)
B(-4,14,5,leaves:0)
B(-4,13,5,leaves:0)
B(-4,12,5,leaves:0)
B(-4,11,5,leaves:0)
B(-4,10,5,leaves:0)
B(-11,-4,-7,LOG:12)
B(-4,2,-1,LOG:12)
B(-4,1,-1,LOG:12)
B(-4,0,-1,LOG:12)
B(-4,16,5,leaves:0)
B(-13,9,-12,leaves:0)
B(-10,9,-12,leaves:0)
B(10,12,7,leaves:0)
B(10,11,7,leaves:0)
B(13,11,-7,leaves:0)
B(10,10,7,leaves:0)
B(10,16,7,leaves:0)
B(10,15,7,leaves:0)
B(5,20,-4,leaves:0)
B(10,14,7,leaves:0)
B(10,13,7,leaves:0)
B(-4,22,5,leaves:0)
B(10,19,7,leaves:0)
B(-4,7,-1,LOG:12)
B(10,18,7,leaves:0)
B(10,17,7,leaves:0)
B(-4,5,-1,LOG:12)
B(-4,6,-1,LOG:12)
B(-4,21,5,leaves:0)
B(-4,3,-1,LOG:12)
B(-4,20,5,leaves:0)
B(-4,4,-1,LOG:12)
B(-1,20,9,leaves:0)
B(-8,10,-11,leaves:0)
B(-1,12,-3,leaves:0)
B(-1,17,9,leaves:0)
B(-1,18,9,leaves:0)
B(-1,19,9,leaves:0)
B(-1,17,-3,leaves:0)
B(-1,18,-3,leaves:0)
B(-1,19,-3,leaves:0)
B(-1,14,-3,leaves:0)
B(-1,15,-3,leaves:0)
B(-1,21,-3,leaves:0)
B(-2,-2,-3,LOG:12)
B(-2,-3,-3,LOG:12)
B(-6,14,-15,leaves:0)
B(-6,13,-15,leaves:0)
B(-6,15,-15,leaves:0)
B(8,16,-3,leaves:0)
B(8,15,-3,leaves:0)
B(8,14,-3,leaves:0)
B(8,13,-3,leaves:0)
B(8,12,-3,leaves:0)
B(8,11,-3,leaves:0)
B(1,-4,-2,LOG:12)
B(1,-3,-2,LOG:12)
B(1,-2,-2,LOG:12)
B(8,17,-3,leaves:0)
B(7,13,-2,LOG:12)
B(7,14,-2,LOG:12)
B(7,15,-2,leaves:0)
B(7,16,-2,leaves:0)
B(7,17,-2,leaves:0)
B(7,19,-2,leaves:0)
B(10,13,14,leaves:0)
B(-13,15,12,leaves:0)
B(10,14,14,leaves:0)
B(10,11,14,leaves:0)
B(10,12,14,leaves:0)
B(-13,14,12,leaves:0)
B(5,12,4,leaves:0)
B(5,13,4,leaves:0)
B(-12,-3,-6,LOG:12)
B(5,14,4,leaves:0)
B(5,15,4,leaves:0)
B(-12,-4,-6,LOG:12)
B(5,17,4,leaves:0)
B(5,18,4,leaves:0)
B(5,19,4,leaves:0)
B(-8,17,-11,leaves:0)
B(-8,18,-11,leaves:0)
B(7,20,-2,leaves:0)
B(-8,15,-11,leaves:0)
B(-8,16,-11,leaves:0)
B(-8,13,-11,leaves:0)
B(5,11,4,LOG:12)
B(-8,11,-11,leaves:0)
B(-8,12,-11,leaves:0)
B(-13,11,12,leaves:0)
B(-17,-4,-8,LOG:12)
B(-13,10,12,leaves:0)
B(-11,10,-14,leaves:0)
B(-11,11,-14,leaves:0)
B(-11,12,-14,leaves:0)
B(-11,13,-14,leaves:0)
B(-3,9,-10,leaves:0)
B(-3,8,-10,leaves:0)
B(-1,-3,-3,LOG:12)
B(7,19,0,leaves:0)
B(7,18,0,leaves:0)
B(-1,-2,-3,LOG:12)
B(-1,-1,-3,LOG:12)
B(7,13,0,leaves:0)
B(7,17,0,leaves:0)
B(7,15,0,leaves:0)
B(7,14,0,leaves:0)
B(-12,10,-15,leaves:0)
B(-12,14,-6,leaves:0)
B(-12,15,-6,leaves:0)
B(-1,15,9,leaves:0)
B(-1,10,9,leaves:0)
B(5,-4,4,LOG:12)
B(-12,11,-6,leaves:0)
B(-12,12,-6,leaves:0)
B(-12,13,-6,leaves:0)
B(-17,10,-8,leaves:0)
B(-6,11,2,leaves:0)
B(-6,10,2,leaves:0)
B(-6,13,2,leaves:0)
B(-6,12,2,leaves:0)
B(13,17,8,leaves:0)
B(13,14,8,leaves:0)
B(8,15,1,leaves:0)
B(8,14,1,leaves:0)
B(5,6,-11,leaves:0)
B(8,17,1,leaves:0)
B(5,7,-11,leaves:0)
B(5,8,-11,leaves:0)
B(8,19,1,leaves:0)
B(5,9,-11,leaves:0)
B(8,18,1,leaves:0)
B(9,13,15,leaves:0)
B(9,12,15,leaves:0)
B(9,14,15,leaves:0)
B(13,11,8,leaves:0)
B(13,10,8,leaves:0)
B(5,-4,7,LOG:12)
B(5,-3,7,LOG:12)
B(5,-5,7,LOG:12)
B(-10,9,14,leaves:0)
B(-12,10,0,leaves:0)
B(-12,11,0,leaves:0)
B(-12,14,0,leaves:0)
B(-12,13,0,leaves:0)
B(-12,16,0,leaves:0)
B(-12,15,0,leaves:0)
B(-15,10,-14,leaves:0)
B(-11,8,-4,leaves:0)
B(-11,9,-4,leaves:0)
B(-6,-4,2,LOG:12)
B(-6,-3,2,LOG:12)
B(-9,12,-1,leaves:0)
B(-5,18,-4,leaves:0)
B(5,20,7,leaves:0)
B(-9,11,-1,leaves:0)
B(-5,19,-4,leaves:0)
B(-9,13,-1,leaves:0)
B(-1,15,-6,leaves:0)
B(-1,14,-6,leaves:0)
B(-1,13,-6,leaves:0)
B(-9,18,-1,leaves:0)
B(-9,17,-1,leaves:0)
B(-5,10,-4,LOG:12)
B(-2,7,0,LOG:12)
B(-5,11,-4,LOG:12)
B(-2,8,0,LOG:12)
B(-2,3,0,LOG:12)
B(-14,17,-1,leaves:0)
B(-2,4,0,LOG:12)
B(-2,5,0,LOG:12)
B(-14,15,-1,leaves:0)
B(-5,16,-4,leaves:0)
B(-2,6,0,LOG:12)
B(-14,16,-1,leaves:0)
B(-5,17,-4,leaves:0)
B(-2,0,0,LOG:12)
B(-14,14,-1,leaves:0)
B(-14,13,-1,leaves:0)
B(-14,12,-1,leaves:0)
B(-2,2,0,LOG:12)
B(-14,11,-1,leaves:0)
B(-2,1,0,LOG:12)
B(-14,10,-1,leaves:0)
B(-9,19,-1,leaves:0)
B(5,14,7,leaves:0)
B(-5,22,-4,leaves:0)
B(5,15,7,leaves:0)
B(5,16,7,leaves:0)
B(5,17,7,leaves:0)
B(5,18,7,leaves:0)
B(5,19,7,leaves:0)
B(5,16,-3,leaves:0)
B(5,17,-3,leaves:0)
B(5,19,-3,leaves:0)
B(1,20,-2,leaves:0)
B(5,13,-3,leaves:0)
B(5,14,-3,leaves:0)
B(5,15,-3,leaves:0)
B(1,6,-13,leaves:0)
B(-17,10,-3,leaves:0)
B(1,14,-2,LOG:12)
B(1,13,-2,leaves:0)
B(1,19,-2,leaves:0)
B(1,17,-2,leaves:0)
B(1,18,-2,leaves:0)
B(-4,7,4,LOG:12)
B(-4,8,4,LOG:12)
B(-6,11,-14,leaves:0)
B(-6,10,-14,leaves:0)
B(-13,9,-13,leaves:0)
B(-3,20,11,leaves:0)
B(-13,8,-13,leaves:0)
B(-5,-3,-4,LOG:12)
B(-5,-4,-4,LOG:12)
B(-6,12,-14,leaves:0)
B(-6,13,-14,leaves:0)
B(-6,14,-14,leaves:0)
B(-6,15,-14,leaves:0)
B(-6,16,-14,leaves:0)
B(-13,8,6,leaves:0)
B(-13,7,6,leaves:0)
B(-2,-3,3,LOG:12)
B(-2,-4,3,LOG:12)
B(-2,-2,3,LOG:12)
B(-9,-3,-5,LOG:12)
B(-9,-4,-5,LOG:12)
B(-8,11,14,leaves:0)
B(-8,12,14,leaves:0)
B(-6,-4,-2,LOG:12)
B(-8,13,14,leaves:0)
B(-8,14,14,leaves:0)
B(-1,19,-6,leaves:0)
B(-1,18,-6,leaves:0)
B(-11,11,-7,leaves:0)
B(-11,14,-7,leaves:0)
B(-11,15,-7,leaves:0)
B(-11,12,-7,leaves:0)
B(-8,10,14,leaves:0)
B(-11,13,-7,leaves:0)
B(-3,12,11,leaves:0)
B(-3,16,11,leaves:0)
B(-3,15,11,leaves:0)
B(-3,14,11,leaves:0)
B(-3,13,11,leaves:0)
B(-3,19,11,leaves:0)
B(-3,18,11,leaves:0)
B(-3,17,11,leaves:0)
B(-11,11,9,leaves:0)
B(-11,12,9,leaves:0)
B(-11,13,9,leaves:0)
B(-11,14,9,leaves:0)
B(-11,15,9,leaves:0)
B(-5,9,-4,LOG:12)
B(-11,16,9,leaves:0)
B(-5,8,-4,LOG:12)
B(-11,17,9,leaves:0)
B(-11,18,9,leaves:0)
B(-5,6,-4,LOG:12)
B(-6,18,-9,leaves:0)
B(-6,19,-9,leaves:0)
B(-6,16,-9,leaves:0)
B(-6,17,-9,leaves:0)
B(-6,14,-9,leaves:0)
B(-6,15,-9,leaves:0)
B(-8,20,-1,leaves:0)
B(-12,20,0,leaves:0)
B(-12,9,-15,leaves:0)
B(-7,13,-16,leaves:0)
B(-12,18,0,leaves:0)
B(-12,19,0,leaves:0)
B(-2,20,3,leaves:0)
B(-6,21,-2,leaves:0)
B(-6,20,-2,leaves:0)
B(-3,10,-10,leaves:0)
B(-3,12,-10,leaves:0)
B(-3,11,-10,leaves:0)
B(-3,14,-10,leaves:0)
B(-3,13,-10,leaves:0)
B(3,12,18,leaves:0)
B(-3,15,-10,leaves:0)
B(-9,12,-5,LOG:12)
B(-12,8,-15,leaves:0)
B(-9,11,-5,leaves:0)
B(2,16,0,leaves:0)
B(-9,14,-5,leaves:0)
B(-9,13,-5,leaves:0)
B(2,19,0,leaves:0)
B(2,17,0,leaves:0)
B(2,18,0,leaves:0)
B(-2,19,3,leaves:0)
B(-2,18,3,leaves:0)
B(-2,17,3,leaves:0)
B(-2,16,3,leaves:0)
B(-2,15,3,leaves:0)
B(-2,14,3,leaves:0)
B(-9,16,-5,leaves:0)
B(-9,15,-5,leaves:0)
B(-9,18,-5,leaves:0)
B(-9,17,-5,leaves:0)
B(-6,10,-2,leaves:0)
B(-6,14,-2,leaves:0)
B(-6,13,-2,leaves:0)
B(-6,12,-2,leaves:0)
B(-6,11,-2,leaves:0)
B(-6,18,-2,leaves:0)
B(-6,17,-2,leaves:0)
B(-6,15,-2,leaves:0)
B(-16,7,-13,leaves:0)
B(8,8,-11,leaves:0)
B(-6,19,-2,leaves:0)
B(-1,2,-1,LOG:12)
B(-1,3,-1,LOG:12)
B(-1,0,-1,LOG:12)
B(-1,1,-1,LOG:12)
B(-1,6,-1,LOG:12)
B(-1,7,-1,LOG:12)
B(-1,5,-1,LOG:12)
B(1,14,-11,leaves:0)
B(1,13,-11,leaves:0)
B(-1,8,-1,leaves:0)
B(2,20,0,leaves:0)
B(1,10,-11,leaves:0)
B(2,21,0,leaves:0)
B(2,22,0,leaves:0)
B(1,12,-11,leaves:0)
B(1,11,-11,leaves:0)
B(-11,10,16,leaves:0)
B(-8,-4,-1,LOG:12)
B(-5,18,-5,leaves:0)
B(-5,17,-5,leaves:0)
B(-5,16,-5,leaves:0)
B(1,9,5,LOG:12)
B(-5,15,-5,leaves:0)
B(-5,13,-5,leaves:0)
B(-5,11,-5,LOG:12)
B(-14,8,-10,leaves:0)
B(-11,13,16,leaves:0)
B(-11,12,16,leaves:0)
B(-14,6,-10,leaves:0)
B(-11,11,16,leaves:0)
B(-14,7,-10,leaves:0)
B(-5,19,-5,leaves:0)
B(-5,10,-5,LOG:12)
B(-8,17,-8,leaves:0)
B(-8,16,-8,leaves:0)
B(-8,15,-8,leaves:0)
B(-8,14,-8,leaves:0)
B(-8,13,-8,leaves:0)
B(-17,8,2,leaves:0)
B(-17,7,2,leaves:0)
B(-2,10,-14,leaves:0)
B(-2,11,-14,leaves:0)
B(-17,9,2,leaves:0)
B(-2,12,-14,leaves:0)
B(-2,13,-14,leaves:0)
B(-17,6,2,leaves:0)
B(-2,14,-14,leaves:0)
B(1,-4,5,LOG:12)
B(-1,20,10,leaves:0)
B(-8,16,-5,leaves:0)
B(-8,17,-5,leaves:0)
B(8,10,-7,leaves:0)
B(-4,14,-14,leaves:0)
B(-8,14,-5,leaves:0)
B(-8,15,-5,leaves:0)
B(-8,12,-5,LOG:12)
B(8,12,-7,leaves:0)
B(-12,8,11,leaves:0)
B(8,11,-7,leaves:0)
B(-12,9,11,leaves:0)
B(-8,11,-5,LOG:12)
B(-4,11,-14,leaves:0)
B(-4,12,-14,leaves:0)
B(-4,13,-14,leaves:0)
B(-16,7,7,leaves:0)
B(-1,18,10,leaves:0)
B(-1,19,10,leaves:0)
B(-1,15,10,leaves:0)
B(-1,16,10,leaves:0)
B(-1,17,10,leaves:0)
B(-16,12,10,leaves:0)
B(1,8,-2,leaves:0)
B(1,9,-2,leaves:0)
B(-16,10,10,leaves:0)
B(-16,11,10,leaves:0)
B(1,7,-2,LOG:12)
B(-16,-4,-7,LOG:12)
B(-8,11,-1,leaves:0)
B(-1,9,-13,leaves:0)
B(-1,6,-13,leaves:0)
B(-1,8,-13,leaves:0)
B(-1,7,-13,leaves:0)
B(3,9,-10,leaves:0)
B(-8,19,-1,leaves:0)
B(6,17,10,leaves:0)
B(-8,18,-1,leaves:0)
B(-8,17,-1,leaves:0)
B(6,18,10,leaves:0)
B(6,12,10,leaves:0)
B(-9,-3,9,LOG:12)
B(-8,13,-1,leaves:0)
B(6,14,10,leaves:0)
B(-8,12,-1,leaves:0)
B(-9,-4,9,LOG:12)
B(6,15,10,leaves:0)
B(3,8,-10,leaves:0)
B(0,20,-5,leaves:0)
B(-8,-4,-8,LOG:12)
B(0,19,-5,leaves:0)
B(7,10,13,leaves:0)
B(7,13,13,leaves:0)
B(7,12,13,leaves:0)
B(-15,12,-3,leaves:0)
B(-5,0,1,LOG:12)
B(7,14,13,leaves:0)
B(7,17,13,leaves:0)
B(7,16,13,leaves:0)
B(7,18,13,leaves:0)
B(-15,10,-3,leaves:0)
B(-15,11,-3,leaves:0)
B(1,11,5,LOG:12)
B(1,12,5,leaves:0)
B(1,10,5,LOG:12)
B(0,10,-5,LOG:12)
B(1,16,5,leaves:0)
B(1,13,5,leaves:0)
B(1,14,5,leaves:0)
B(1,19,5,leaves:0)
B(0,13,-5,leaves:0)
B(-8,9,3,leaves:0)
B(0,14,-5,leaves:0)
B(0,12,-5,LOG:12)
B(1,18,5,leaves:0)
B(0,18,-5,leaves:0)
B(0,15,-5,leaves:0)
B(2,-4,3,LOG:12)
B(1,20,5,leaves:0)
B(1,21,5,leaves:0)
B(1,22,5,leaves:0)
B(-1,0,2,LOG:12)
B(4,13,12,leaves:0)
B(4,12,12,leaves:0)
B(4,11,12,leaves:0)
B(4,18,12,leaves:0)
B(9,15,4,leaves:0)
B(9,16,4,leaves:0)
B(-7,17,-9,leaves:0)
B(9,17,4,leaves:0)
B(9,18,4,leaves:0)
B(9,19,4,leaves:0)
B(-7,14,-9,LOG:12)
B(-7,16,-9,LOG:12)
B(-7,15,-9,LOG:12)
B(-9,21,4,leaves:0)
B(2,18,3,leaves:0)
B(-9,20,4,leaves:0)
B(2,19,3,leaves:0)
B(2,17,3,leaves:0)
B(-7,8,6,leaves:0)
B(-7,9,6,leaves:0)
B(2,11,3,leaves:0)
B(11,11,5,leaves:0)
B(-9,19,4,leaves:0)
B(11,10,5,leaves:0)
B(-2,12,12,leaves:0)
B(11,13,5,leaves:0)
B(11,12,5,leaves:0)
B(-2,11,12,leaves:0)
B(-2,14,12,leaves:0)
B(-2,13,12,leaves:0)
B(2,-4,-2,LOG:12)
B(-2,16,12,leaves:0)
B(2,-5,-2,LOG:12)
B(-17,8,-8,leaves:0)
B(-2,15,12,leaves:0)
B(11,19,5,leaves:0)
B(-2,18,12,leaves:0)
B(-2,17,12,leaves:0)
B(11,18,5,leaves:0)
B(2,-1,-2,LOG:12)
B(2,-2,-2,LOG:12)
B(2,-3,-2,LOG:12)
B(-9,12,4,leaves:0)
B(-13,11,16,leaves:0)
B(-13,12,16,leaves:0)
B(-9,11,4,leaves:0)
B(-13,10,16,leaves:0)
B(-9,13,4,leaves:0)
B(-9,16,4,leaves:0)
B(-9,15,4,leaves:0)
B(-9,18,4,leaves:0)
B(-9,17,4,LOG:12)
B(-10,9,-4,leaves:0)
B(0,14,15,leaves:0)
B(0,13,15,leaves:0)
B(0,12,15,leaves:0)
B(0,15,15,leaves:0)
B(0,16,15,leaves:0)
B(2,20,3,leaves:0)
B(-8,9,7,leaves:0)
B(-7,-4,-9,LOG:12)
B(2,12,-2,leaves:0)
B(2,13,-2,leaves:0)
B(-8,-3,-5,LOG:12)
B(-8,-4,-5,LOG:12)
B(-3,13,-11,leaves:0)
B(2,19,-2,leaves:0)
B(-3,12,-11,leaves:0)
B(2,18,-2,leaves:0)
B(-3,11,-11,leaves:0)
B(-8,20,7,leaves:0)
B(2,17,-2,leaves:0)
B(-8,21,7,leaves:0)
B(-3,15,-11,leaves:0)
B(-3,14,-11,leaves:0)
B(6,11,11,leaves:0)
B(-4,0,-2,LOG:12)
B(-4,1,-2,LOG:12)
B(6,18,11,leaves:0)
B(-14,6,3,leaves:0)
B(6,17,11,leaves:0)
B(2,21,-2,leaves:0)
B(-14,7,3,leaves:0)
B(6,19,11,leaves:0)
B(-14,9,3,leaves:0)
B(6,14,11,leaves:0)
B(2,20,-2,leaves:0)
B(6,13,11,leaves:0)
B(6,16,11,leaves:0)
B(-8,10,7,leaves:0)
B(-8,11,7,leaves:0)
B(-4,3,-2,LOG:12)
B(-4,2,-2,LOG:12)
B(-4,5,-2,LOG:12)
B(-8,15,7,leaves:0)
B(-4,4,-2,LOG:12)
B(-8,16,7,leaves:0)
B(-4,7,-2,LOG:12)
B(-8,17,7,leaves:0)
B(-4,6,-2,LOG:12)
B(-8,18,7,leaves:0)
B(-5,-4,-2,LOG:12)
B(-5,-2,-2,LOG:12)
B(-5,-3,-2,LOG:12)
B(-5,-1,-2,LOG:12)
B(-7,21,11,leaves:0)
B(-7,22,11,leaves:0)
B(1,19,11,leaves:0)
B(1,18,11,leaves:0)
B(1,15,11,leaves:0)
B(1,14,11,LOG:12)
B(1,17,11,leaves:0)
B(1,16,11,leaves:0)
B(-7,12,11,leaves:0)
B(-7,15,11,leaves:0)
B(-7,16,11,leaves:0)
B(-7,13,11,LOG:12)
B(-7,14,11,leaves:0)
B(-7,19,11,leaves:0)
B(-7,17,11,leaves:0)
B(11,8,-8,leaves:0)
B(-5,17,-8,leaves:0)
B(-5,16,-8,leaves:0)
B(-5,15,-8,leaves:0)
B(-5,14,-8,leaves:0)
B(-5,5,-3,LOG:12)
B(-5,6,-3,LOG:12)
B(-5,7,-3,LOG:12)
B(-5,8,-3,leaves:0)
B(-5,9,-3,leaves:0)
B(-4,9,7,LOG:12)
B(-5,15,-2,leaves:0)
B(-5,14,-2,leaves:0)
B(-5,13,-2,leaves:0)
B(-5,12,-2,leaves:0)
B(-5,11,-2,leaves:0)
B(-5,10,-2,leaves:0)
B(-5,19,-2,leaves:0)
B(-5,18,-2,leaves:0)
B(-5,17,-2,leaves:0)
B(7,14,11,leaves:0)
B(7,18,11,leaves:0)
B(7,17,11,leaves:0)
B(7,16,11,leaves:0)
B(-5,20,-2,leaves:0)
B(-5,22,-2,leaves:0)
B(-5,21,-2,leaves:0)
B(-4,20,-1,leaves:0)
B(-4,21,-1,leaves:0)
B(7,11,-10,leaves:0)
B(3,21,1,leaves:0)
B(-14,12,-10,leaves:0)
B(-14,11,-10,leaves:0)
B(-14,13,-10,leaves:0)
B(-11,9,-3,leaves:0)
B(-14,15,-10,leaves:0)
B(3,15,1,leaves:0)
B(3,16,1,leaves:0)
B(3,17,1,leaves:0)
B(3,19,1,leaves:0)
B(-3,0,-1,LOG:12)
B(-3,1,-1,LOG:12)
B(5,8,-12,leaves:0)
B(-3,6,-1,LOG:12)
B(5,7,-12,leaves:0)
B(-8,12,17,leaves:0)
B(5,6,-12,leaves:0)
B(5,5,-12,leaves:0)
B(-3,3,-1,LOG:12)
B(-3,2,-1,LOG:12)
B(-3,5,-1,LOG:12)
B(-3,4,-1,LOG:12)
B(5,9,-12,leaves:0)
B(-16,12,-7,leaves:0)
B(-16,11,-7,leaves:0)
B(-16,10,-7,leaves:0)
B(-13,16,1,leaves:0)
B(-4,11,-1,leaves:0)
B(-13,15,1,leaves:0)
B(-4,12,-1,leaves:0)
B(-13,14,1,leaves:0)
B(-4,13,-1,leaves:0)
B(-13,13,1,leaves:0)
B(-13,12,1,leaves:0)
B(-4,14,-1,leaves:0)
B(-13,11,1,leaves:0)
B(-13,10,1,leaves:0)
B(-4,17,-1,leaves:0)
B(-4,18,-1,leaves:0)
B(-4,19,-1,leaves:0)
B(9,13,3,leaves:0)
B(9,14,3,leaves:0)
B(9,16,3,leaves:0)
B(9,15,3,leaves:0)
B(9,18,3,leaves:0)
B(9,17,3,leaves:0)
B(9,19,3,leaves:0)
B(7,17,3,leaves:0)
B(7,18,3,leaves:0)
B(7,15,3,leaves:0)
B(7,16,3,leaves:0)
B(7,13,3,leaves:0)
B(7,14,3,leaves:0)
B(-2,5,1,LOG:12)
B(-2,4,1,LOG:12)
B(-6,10,-6,LOG:12)
B(-2,3,1,LOG:12)
B(-2,2,1,LOG:12)
B(-2,7,1,LOG:12)
B(-2,6,1,LOG:12)
B(8,11,10,leaves:0)
B(8,12,10,leaves:0)
B(8,13,10,leaves:0)
B(6,19,2,leaves:0)
B(-2,0,1,LOG:12)
B(8,14,10,leaves:0)
B(-2,1,1,LOG:12)
B(8,15,10,leaves:0)
B(8,16,10,leaves:0)
B(8,17,10,leaves:0)
B(12,11,7,leaves:0)
B(6,14,2,leaves:0)
B(12,12,7,leaves:0)
B(6,13,2,leaves:0)
B(12,14,7,leaves:0)
B(6,18,2,leaves:0)
B(6,17,2,leaves:0)
B(6,16,2,leaves:0)
B(6,15,2,leaves:0)
B(12,10,7,leaves:0)
B(6,20,2,leaves:0)
B(6,21,2,leaves:0)
B(8,19,10,leaves:0)
B(-11,6,2,leaves:0)
B(-3,13,-13,leaves:0)
B(-3,12,-13,leaves:0)
B(8,20,10,leaves:0)
B(-3,10,-13,leaves:0)
B(-4,-3,-1,LOG:12)
B(2,14,14,leaves:0)
B(-4,-2,-1,LOG:12)
B(2,15,14,leaves:0)
B(2,12,14,leaves:0)
B(-4,-5,-1,LOG:12)
B(-4,-4,-1,LOG:12)
B(2,13,14,leaves:0)
B(2,18,14,leaves:0)
B(2,19,14,leaves:0)
B(2,16,14,leaves:0)
B(-16,10,7,leaves:0)
B(-4,-1,-1,LOG:12)
B(-4,15,-7,leaves:0)
B(-4,16,-7,leaves:0)
B(-4,17,-7,leaves:0)
B(-4,18,-7,leaves:0)
B(-4,19,-7,leaves:0)
B(2,11,14,leaves:0)
B(-6,13,-6,LOG:12)
B(-6,14,-6,leaves:0)
B(-6,11,-6,LOG:12)
B(-6,12,-6,LOG:12)
B(-6,17,-6,leaves:0)
B(-6,16,-6,leaves:0)
B(1,19,-4,leaves:0)
B(1,17,-4,leaves:0)
B(1,18,-4,leaves:0)
B(-11,7,3,leaves:0)
B(-11,6,3,leaves:0)
B(1,12,-4,LOG:12)
B(1,11,-4,leaves:0)
B(1,10,-4,leaves:0)
B(1,9,4,LOG:12)
B(1,14,-4,leaves:0)
B(1,13,-4,LOG:12)
B(-15,10,-11,leaves:0)
B(-15,11,-11,leaves:0)
B(-15,12,-11,leaves:0)
B(1,21,-4,leaves:0)
B(1,20,-4,leaves:0)
B(-5,9,0,leaves:0)
B(0,18,0,leaves:0)
B(-5,5,0,LOG:12)
B(-7,17,-15,leaves:0)
B(0,17,0,leaves:0)
B(-5,6,0,LOG:12)
B(-7,14,-15,leaves:0)
B(0,16,0,leaves:0)
B(0,15,0,leaves:0)
B(-5,0,0,LOG:12)
B(0,14,0,LOG:12)
B(-5,1,0,LOG:12)
B(4,18,11,leaves:0)
B(3,20,-4,leaves:0)
B(3,21,-4,leaves:0)
B(-12,8,10,leaves:0)
B(4,19,11,leaves:0)
B(-12,9,10,leaves:0)
B(4,14,11,leaves:0)
B(4,11,11,leaves:0)
B(4,12,11,leaves:0)
B(0,21,0,leaves:0)
B(0,20,0,leaves:0)
B(4,18,14,leaves:0)
B(4,16,14,leaves:0)
B(4,17,14,leaves:0)
B(3,19,-4,leaves:0)
B(4,14,14,leaves:0)
B(4,15,14,leaves:0)
B(4,12,14,leaves:0)
B(3,16,-4,leaves:0)
B(-16,9,8,leaves:0)
B(4,13,14,leaves:0)
B(4,10,14,leaves:0)
B(4,11,14,leaves:0)
B(3,11,-4,leaves:0)
B(3,12,-4,leaves:0)
B(3,13,-4,leaves:0)
B(3,14,-4,leaves:0)
B(-7,11,-15,leaves:0)
B(0,19,0,leaves:0)
B(-7,10,-15,leaves:0)
B(-7,13,-15,leaves:0)
B(-7,12,-15,leaves:0)
B(1,7,-1,leaves:0)
B(1,8,-1,leaves:0)
B(3,8,-11,leaves:0)
B(6,16,12,leaves:0)
B(3,9,-11,leaves:0)
B(6,17,12,leaves:0)
B(6,14,12,leaves:0)
B(6,15,12,leaves:0)
B(6,12,12,leaves:0)
B(6,13,12,leaves:0)
B(6,10,12,leaves:0)
B(-1,7,-14,leaves:0)
B(8,20,3,leaves:0)
B(-1,9,-14,leaves:0)
B(-1,8,-14,leaves:0)
B(-13,9,9,leaves:0)
B(-7,0,7,LOG:12)
B(3,7,-11,leaves:0)
B(3,6,-11,leaves:0)
B(3,-5,-4,LOG:12)
B(8,18,3,leaves:0)
B(8,17,3,leaves:0)
B(8,16,3,leaves:0)
B(3,-3,-4,LOG:12)
B(8,15,3,leaves:0)
B(3,-4,-4,LOG:12)
B(8,14,3,leaves:0)
B(11,15,-3,leaves:0)
B(-13,9,-10,leaves:0)
B(11,11,-3,leaves:0)
B(-13,6,-10,leaves:0)
B(11,12,-3,leaves:0)
B(-13,8,-10,leaves:0)
B(11,10,-3,leaves:0)
B(-13,7,-10,leaves:0)
B(-13,10,2,leaves:0)
B(-13,11,2,leaves:0)
B(-13,14,2,leaves:0)
B(-1,8,1,leaves:0)
B(-13,15,2,leaves:0)
B(-13,12,2,leaves:0)
B(-13,13,2,leaves:0)
B(-13,18,2,leaves:0)
B(-13,19,2,leaves:0)
B(-13,16,2,leaves:0)
B(-1,6,1,LOG:12)
B(-18,11,-8,leaves:0)
B(-1,0,1,LOG:12)
B(-1,1,1,LOG:12)
B(-6,11,-11,leaves:0)
B(-6,12,-11,leaves:0)
B(-6,13,-11,leaves:0)
B(-6,15,-11,leaves:0)
B(-6,16,-11,leaves:0)
B(-6,17,-11,leaves:0)
B(-14,16,-4,leaves:0)
B(-14,14,-4,leaves:0)
B(-14,13,-4,leaves:0)
B(-14,12,-4,leaves:0)
B(-7,8,7,leaves:0)
B(-14,11,-4,leaves:0)
B(-7,9,7,leaves:0)
B(-14,10,-4,leaves:0)
B(-14,7,2,leaves:0)
B(-14,6,2,leaves:0)
B(-14,8,2,leaves:0)
B(8,-4,3,LOG:12)
B(-16,12,-6,leaves:0)
B(-16,10,-6,leaves:0)
B(-16,11,-6,leaves:0)
B(1,-2,-4,LOG:12)
B(-16,10,6,leaves:0)
B(-8,19,12,leaves:0)
B(0,20,-6,leaves:0)
B(-8,18,12,leaves:0)
B(-8,17,12,leaves:0)
B(-8,13,6,leaves:0)
B(-8,15,12,leaves:0)
B(-8,12,6,leaves:0)
B(2,9,-8,leaves:0)
B(-8,16,12,leaves:0)
B(2,8,-8,leaves:0)
B(-8,15,6,leaves:0)
B(-8,14,6,leaves:0)
B(-8,14,12,leaves:0)
B(-16,12,6,leaves:0)
B(-8,17,6,leaves:0)
B(-8,12,12,leaves:0)
B(-16,11,6,leaves:0)
B(-8,16,6,leaves:0)
B(-8,19,6,leaves:0)
B(14,10,7,leaves:0)
B(-8,18,6,leaves:0)
B(1,-4,-4,LOG:12)
B(1,-3,-4,LOG:12)
B(-8,11,6,leaves:0)
B(-8,10,6,leaves:0)
B(0,13,-6,LOG:12)
B(0,19,-6,leaves:0)
B(0,18,-6,leaves:0)
B(1,21,11,leaves:0)
B(14,14,7,leaves:0)
B(0,11,-6,LOG:12)
B(0,10,-6,LOG:12)
B(1,8,-10,leaves:0)
B(1,9,-10,leaves:0)
B(1,20,11,leaves:0)
B(0,-1,0,LOG:12)
B(0,-2,0,LOG:12)
B(0,-3,0,LOG:12)
B(0,-4,0,LOG:12)
B(-6,13,17,leaves:0)
B(-6,11,17,leaves:0)
B(-4,12,-13,leaves:0)
B(-4,10,-13,leaves:0)
B(-4,13,-13,leaves:0)
B(-16,-4,-6,LOG:12)
B(-16,-5,-6,LOG:12)
B(-4,6,-3,LOG:12)
B(-16,-3,-6,LOG:12)
B(-8,24,6,leaves:0)
B(-8,23,6,leaves:0)
B(-8,22,6,leaves:0)
B(-8,21,6,leaves:0)
B(-8,20,6,leaves:0)
B(1,14,18,leaves:0)
B(-4,8,6,LOG:12)
B(-4,9,6,LOG:12)
B(7,-4,4,LOG:12)
B(-15,12,-4,leaves:0)
B(-15,10,-4,leaves:0)
B(11,8,-7,leaves:0)
B(8,18,0,leaves:0)
B(11,9,-7,leaves:0)
B(8,17,0,leaves:0)
B(8,16,0,leaves:0)
B(11,7,-7,leaves:0)
B(8,15,0,leaves:0)
B(8,14,0,leaves:0)
B(8,13,0,leaves:0)
B(8,12,0,leaves:0)
B(-5,7,-2,LOG:12)
B(-12,11,-4,leaves:0)
B(-5,4,-2,LOG:12)
B(-5,5,-2,LOG:12)
B(-5,6,-2,LOG:12)
B(-9,9,8,leaves:0)
B(-12,13,-4,leaves:0)
B(-12,12,-4,leaves:0)
B(-12,15,-4,leaves:0)
B(-12,14,-4,leaves:0)
B(8,9,-9,leaves:0)
B(-5,0,-2,LOG:12)
B(12,11,8,leaves:0)
B(8,17,11,leaves:0)
B(8,16,11,leaves:0)
B(8,15,11,leaves:0)
B(8,14,11,leaves:0)
B(8,13,11,leaves:0)
B(8,12,11,leaves:0)
B(9,-4,4,LOG:12)
B(7,14,4,leaves:0)
B(7,15,4,leaves:0)
B(7,16,4,leaves:0)
B(7,17,4,leaves:0)
B(7,18,4,leaves:0)
B(7,13,4,leaves:0)
B(7,12,4,leaves:0)
B(-12,14,12,leaves:0)
B(12,12,8,leaves:0)
B(-12,16,12,leaves:0)
B(12,17,8,leaves:0)
B(-14,12,-11,leaves:0)
B(-12,10,12,leaves:0)
B(-12,11,12,leaves:0)
B(-14,10,-11,leaves:0)
B(-14,11,-11,leaves:0)
B(4,8,-10,leaves:0)
B(4,9,-10,leaves:0)
B(-2,18,5,leaves:0)
B(-2,17,5,leaves:0)
B(-2,19,5,leaves:0)
B(-2,14,5,leaves:0)
B(-2,13,5,leaves:0)
B(-2,16,5,leaves:0)
B(-2,20,5,leaves:0)
B(-2,21,5,leaves:0)
B(-8,14,15,leaves:0)
B(-8,12,15,leaves:0)
B(-8,13,15,leaves:0)
B(-8,10,15,leaves:0)
B(-8,11,15,leaves:0)
B(5,9,-13,leaves:0)
B(5,7,-13,leaves:0)
B(-3,14,3,leaves:0)
B(-3,12,3,leaves:0)
B(-3,19,3,leaves:0)
B(-3,18,3,leaves:0)
B(-3,17,3,leaves:0)
B(-3,16,3,leaves:0)
B(-2,11,5,leaves:0)
B(-2,12,5,leaves:0)
B(-2,10,5,leaves:0)
B(2,9,-10,leaves:0)
B(4,7,-10,leaves:0)
B(-9,10,13,leaves:0)
B(-9,11,13,leaves:0)
B(-3,21,3,leaves:0)
B(-9,13,13,leaves:0)
B(-9,14,13,leaves:0)
B(-3,20,3,leaves:0)
B(8,14,12,leaves:0)
B(8,12,12,leaves:0)
B(8,13,12,leaves:0)
B(8,16,12,leaves:0)
B(8,17,12,leaves:0)
B(6,12,16,leaves:0)
B(-9,10,9,leaves:0)
B(9,12,5,leaves:0)
B(-9,11,9,leaves:0)
B(6,13,16,leaves:0)
B(6,11,16,leaves:0)
B(9,15,5,leaves:0)
B(-9,15,9,leaves:0)
B(9,16,5,leaves:0)
B(9,13,5,leaves:0)
B(6,14,16,leaves:0)
B(-9,18,9,leaves:0)
B(-9,19,9,leaves:0)
B(-9,16,9,leaves:0)
B(-9,17,9,leaves:0)
B(9,18,5,leaves:0)
B(9,17,5,leaves:0)
B(-2,-4,5,LOG:12)
B(-2,7,2,LOG:12)
B(-2,6,2,LOG:12)
B(-2,5,2,LOG:12)
B(-2,2,2,LOG:12)
B(-2,1,2,LOG:12)
B(-9,20,9,leaves:0)
B(9,12,1,leaves:0)
B(9,11,1,leaves:0)
B(9,13,1,leaves:0)
B(9,14,1,leaves:0)
B(9,15,1,leaves:0)
B(9,16,1,leaves:0)
B(9,17,1,leaves:0)
B(9,18,1,leaves:0)
B(9,19,1,leaves:0)
B(-2,0,2,LOG:12)
B(-3,-1,3,LOG:12)
B(-3,-4,3,LOG:12)
B(-3,-2,3,LOG:12)
B(-3,-3,3,LOG:12)
B(-12,9,-13,leaves:0)
B(-12,8,-13,leaves:0)
B(4,20,2,leaves:0)
B(4,18,2,leaves:0)
B(4,17,2,leaves:0)
B(4,19,2,leaves:0)
B(4,11,2,LOG:12)
B(4,14,2,leaves:0)
B(4,16,2,leaves:0)
B(4,15,2,leaves:0)
B(11,9,-6,leaves:0)
B(11,8,-6,leaves:0)
B(0,15,-12,leaves:0)
B(0,12,-12,leaves:0)
B(0,11,-12,leaves:0)
B(0,10,-12,leaves:0)
B(-13,13,4,leaves:0)
B(-13,12,4,leaves:0)
B(-13,11,4,leaves:0)
B(-13,10,4,leaves:0)
B(-7,12,16,leaves:0)
B(-13,16,4,leaves:0)
B(-7,11,16,leaves:0)
B(-13,15,4,leaves:0)
B(-7,10,16,leaves:0)
B(-13,14,4,leaves:0)
B(-13,18,4,leaves:0)
B(3,20,4,leaves:0)
B(3,21,4,leaves:0)
B(1,9,-7,leaves:0)
B(4,-4,5,LOG:12)
B(4,-5,5,LOG:12)
B(16,8,-2,leaves:0)
B(16,9,-2,leaves:0)
B(-16,12,4,leaves:0)
B(-13,4,3,leaves:0)
B(-13,5,3,leaves:0)
B(-7,11,-7,LOG:12)
B(-7,12,-7,LOG:12)
B(-7,13,-7,LOG:12)
B(-7,14,-7,LOG:12)
B(-7,15,-7,leaves:0)
B(-7,16,-7,leaves:0)
B(15,9,-3,leaves:0)
B(-7,17,-7,leaves:0)
B(-7,18,-7,leaves:0)
B(-7,19,-7,leaves:0)
B(-13,6,3,leaves:0)
B(-5,14,9,LOG:12)
B(-5,12,9,LOG:12)
B(-5,13,9,LOG:12)
B(-5,18,9,leaves:0)
B(3,19,4,leaves:0)
B(-16,13,-11,leaves:0)
B(-16,12,-11,leaves:0)
B(-5,17,9,leaves:0)
B(3,18,4,leaves:0)
B(3,17,4,leaves:0)
B(3,14,4,leaves:0)
B(3,12,4,leaves:0)
B(-5,11,9,LOG:12)
B(3,11,4,leaves:0)
B(3,10,4,LOG:12)
B(-7,12,-13,leaves:0)
B(-11,-4,-5,LOG:12)
B(-7,13,-13,leaves:0)
B(-11,-5,-5,LOG:12)
B(11,12,3,leaves:0)
B(-7,14,-13,leaves:0)
B(11,13,3,leaves:0)
B(-7,15,-13,leaves:0)
B(-11,-2,-5,LOG:12)
B(-11,-3,-5,LOG:12)
B(11,18,3,leaves:0)
B(11,19,3,leaves:0)
B(11,14,3,leaves:0)
B(11,15,3,leaves:0)
B(11,16,3,leaves:0)
B(12,9,4,leaves:0)
B(-4,0,1,LOG:12)
B(-4,1,1,LOG:12)
B(-4,2,1,LOG:12)
B(-4,3,1,LOG:12)
B(-4,4,1,LOG:12)
B(-4,5,1,LOG:12)
B(-4,6,1,LOG:12)
B(-4,15,-11,leaves:0)
B(-4,10,-11,leaves:0)
B(-7,11,-13,leaves:0)
B(-4,14,-11,leaves:0)
B(-7,10,-13,leaves:0)
B(-4,13,-11,leaves:0)
B(-4,12,-11,leaves:0)
B(-4,11,-11,leaves:0)
B(-16,9,-1,leaves:0)
B(-15,9,-1,leaves:0)
B(-15,8,-1,leaves:0)
B(-15,7,-1,leaves:0)
B(-6,-4,-3,LOG:12)
B(-6,-5,-3,LOG:12)
B(-6,-2,-3,LOG:12)
B(-6,-3,-3,LOG:12)
B(9,15,-2,LOG:12)
B(9,16,-2,leaves:0)
B(2,-4,5,LOG:12)
B(9,13,-2,leaves:0)
B(9,14,-2,leaves:0)
B(9,11,-2,leaves:0)
B(9,12,-2,leaves:0)
B(-7,19,12,leaves:0)
B(-7,18,12,leaves:0)
B(-11,13,-5,leaves:0)
B(-11,12,-5,leaves:0)
B(-7,15,12,leaves:0)
B(-11,11,-5,leaves:0)
B(-7,16,12,leaves:0)
B(-7,17,12,leaves:0)
B(-7,12,12,leaves:0)
B(6,10,-10,leaves:0)
B(-11,16,-5,leaves:0)
B(6,12,-10,leaves:0)
B(-11,15,-5,leaves:0)
B(-11,14,-5,leaves:0)
B(4,11,-12,leaves:0)
B(-7,20,12,leaves:0)
B(-5,14,14,leaves:0)
B(-5,15,14,leaves:0)
B(-5,17,14,leaves:0)
B(-5,10,14,leaves:0)
B(-5,11,14,leaves:0)
B(-5,13,14,leaves:0)
B(-13,12,-12,leaves:0)
B(11,11,13,leaves:0)
B(11,12,13,leaves:0)
B(-13,10,-12,leaves:0)
B(11,10,13,leaves:0)
B(11,14,13,leaves:0)
B(11,13,13,leaves:0)
B(2,20,11,leaves:0)
B(7,12,-9,leaves:0)
B(7,11,-9,leaves:0)
B(2,18,11,leaves:0)
B(2,17,11,leaves:0)
B(2,19,11,leaves:0)
B(-12,18,7,leaves:0)
B(-12,19,7,leaves:0)
B(-16,5,0,leaves:0)
B(-12,16,7,leaves:0)
B(-12,17,7,leaves:0)
B(-12,14,7,leaves:0)
B(-12,15,7,leaves:0)
B(-12,12,7,leaves:0)
B(-12,13,7,leaves:0)
B(2,9,-5,LOG:12)
B(2,13,11,leaves:0)
B(2,16,11,leaves:0)
B(2,15,11,leaves:0)
B(4,11,5,leaves:0)
B(-1,13,12,leaves:0)
B(-1,12,12,leaves:0)
B(-1,15,12,LOG:12)
B(-1,14,12,LOG:12)
B(-7,8,-2,leaves:0)
B(-7,7,-2,leaves:0)
B(-1,16,12,leaves:0)
B(-7,6,-2,leaves:0)
B(-7,9,-2,leaves:0)
B(-16,7,0,leaves:0)
B(4,17,5,leaves:0)
B(-16,6,0,leaves:0)
B(4,19,5,leaves:0)
B(-16,9,0,leaves:0)
B(-16,8,0,leaves:0)
B(4,18,5,leaves:0)
B(4,15,5,leaves:0)
B(4,14,5,leaves:0)
B(-1,-1,2,LOG:12)
B(-16,7,1,leaves:0)
B(-1,-2,2,LOG:12)
B(-16,8,1,leaves:0)
B(-16,6,1,leaves:0)
B(-16,9,1,leaves:0)
B(-6,19,3,leaves:0)
B(-14,9,-13,leaves:0)
B(-1,-5,2,LOG:12)
B(-6,15,3,leaves:0)
B(-6,16,3,leaves:0)
B(-1,-3,2,LOG:12)
B(-6,17,3,leaves:0)
B(-1,-4,2,LOG:12)
B(-6,18,3,leaves:0)
B(-6,23,3,leaves:0)
B(-6,22,3,leaves:0)
B(1,11,6,leaves:0)
B(1,10,6,LOG:12)
B(-6,21,3,leaves:0)
B(13,8,0,leaves:0)
B(-6,20,3,leaves:0)
B(13,9,0,leaves:0)
B(1,19,6,leaves:0)
B(1,18,6,leaves:0)
B(0,-4,-3,LOG:12)
B(0,-3,-3,LOG:12)
B(0,16,13,leaves:0)
B(0,15,13,leaves:0)
B(0,14,13,leaves:0)
B(0,19,13,leaves:0)
B(0,18,13,leaves:0)
B(0,17,13,leaves:0)
B(-6,14,3,leaves:0)
B(-6,12,3,leaves:0)
B(-9,-3,11,LOG:12)
B(-6,11,3,leaves:0)
B(-9,-4,11,LOG:12)
B(-6,10,3,leaves:0)
B(-9,-5,11,LOG:12)
B(0,-2,-3,LOG:12)
B(-2,13,-8,leaves:0)
B(-2,15,-8,leaves:0)
B(-2,16,-8,leaves:0)
B(-8,18,-13,leaves:0)
B(-8,17,-13,leaves:0)
B(-8,16,-13,leaves:0)
B(-8,13,-13,leaves:0)
B(-15,12,-12,leaves:0)
B(-14,6,-13,leaves:0)
B(-7,12,-12,leaves:0)
B(-6,17,-3,leaves:0)
B(-7,11,-12,leaves:0)
B(-6,16,-3,leaves:0)
B(-7,14,-12,leaves:0)
B(-6,19,-3,leaves:0)
B(-7,13,-12,leaves:0)
B(-6,18,-3,leaves:0)
B(-7,16,-12,leaves:0)
B(-7,15,-12,leaves:0)
B(-1,19,2,leaves:0)
B(-7,18,-12,leaves:0)
B(-1,18,2,leaves:0)
B(-7,17,-12,leaves:0)
B(-1,17,2,leaves:0)
B(-1,16,2,LOG:12)
B(-1,15,2,LOG:12)
B(-6,11,-3,leaves:0)
B(-1,14,2,LOG:12)
B(-6,10,-3,leaves:0)
B(-6,13,-3,leaves:0)
B(-6,12,-3,leaves:0)
B(-6,15,-3,leaves:0)
B(-6,14,-3,leaves:0)
B(-8,-3,-4,LOG:12)
B(-8,-4,-4,LOG:12)
B(-9,4,-3,leaves:0)
B(10,15,-2,leaves:0)
B(10,16,-2,leaves:0)
B(10,13,-2,leaves:0)
B(10,14,-2,leaves:0)
B(10,11,-2,leaves:0)
B(10,12,-2,leaves:0)
B(3,12,12,leaves:0)
B(5,15,-1,leaves:0)
B(5,14,-1,leaves:0)
B(5,17,-1,leaves:0)
B(5,11,-1,leaves:0)
B(3,16,12,leaves:0)
B(5,13,-1,leaves:0)
B(5,12,-1,leaves:0)
B(-13,10,14,leaves:0)
B(3,19,12,leaves:0)
B(3,18,12,leaves:0)
B(3,17,12,leaves:0)
B(5,19,-1,leaves:0)
B(5,18,-1,leaves:0)
B(-13,11,14,leaves:0)
B(-4,19,-4,leaves:0)
B(-4,18,-4,leaves:0)
B(-4,17,-4,leaves:0)
B(-4,16,-4,leaves:0)
B(-4,14,-4,leaves:0)
B(-4,13,-4,leaves:0)
B(-6,20,-3,leaves:0)
B(-4,21,-4,leaves:0)
B(-7,10,-12,leaves:0)
B(11,11,-6,leaves:0)
B(11,10,-6,leaves:0)
B(-1,9,-11,leaves:0)
B(-8,13,-4,LOG:12)
B(-8,12,-4,LOG:12)
B(-8,11,-4,leaves:0)
B(-8,10,-4,LOG:12)
B(-9,12,-17,leaves:0)
B(-4,0,0,LOG:12)
B(-8,17,-4,leaves:0)
B(-8,16,-4,leaves:0)
B(-8,15,-4,leaves:0)
B(-4,4,0,LOG:12)
B(-4,3,0,LOG:12)
B(-4,2,0,LOG:12)
B(-4,1,0,LOG:12)
B(-4,6,0,LOG:12)
B(-4,5,0,LOG:12)
B(1,20,7,leaves:0)
B(1,17,7,leaves:0)
B(1,18,7,leaves:0)
B(1,11,7,leaves:0)
B(2,20,-5,leaves:0)
B(1,19,7,leaves:0)
B(5,20,-1,leaves:0)
B(-16,-4,-9,LOG:12)
B(9,17,-1,leaves:0)
B(9,15,-1,leaves:0)
B(9,14,-1,leaves:0)
B(0,20,-3,leaves:0)
B(2,16,-5,leaves:0)
B(0,21,-3,leaves:0)
B(2,15,-5,leaves:0)
B(0,22,-3,leaves:0)
B(2,14,-5,leaves:0)
B(2,13,-5,leaves:0)
B(2,12,-5,LOG:12)
B(9,13,-1,leaves:0)
B(9,12,-1,leaves:0)
B(2,11,-5,LOG:12)
B(9,11,-1,leaves:0)
B(2,10,-5,leaves:0)
B(-12,13,-2,leaves:0)
B(-12,12,-2,leaves:0)
B(-12,17,-2,leaves:0)
B(-12,16,-2,leaves:0)
B(-12,15,-2,leaves:0)
B(2,17,-5,leaves:0)
B(-12,14,-2,leaves:0)
B(2,18,-5,leaves:0)
B(15,9,-4,leaves:0)
B(-5,21,9,leaves:0)
B(-1,20,2,leaves:0)
B(-1,21,2,leaves:0)
B(13,10,-4,leaves:0)
B(-10,12,5,leaves:0)
B(-10,15,5,leaves:0)
B(-10,14,5,leaves:0)
B(-10,17,5,leaves:0)
B(-10,16,5,leaves:0)
B(-10,18,5,leaves:0)
B(-10,11,5,leaves:0)
B(-10,10,5,leaves:0)
B(0,15,-3,leaves:0)
B(0,14,-3,leaves:0)
B(0,13,-3,LOG:12)
B(0,10,-3,LOG:12)
B(-9,17,11,leaves:0)
B(-9,16,11,leaves:0)
B(-9,15,11,leaves:0)
B(-7,7,-12,leaves:0)
B(-9,13,11,leaves:0)
B(-9,14,11,leaves:0)
B(-11,14,1,LOG:12)
B(-7,9,-12,leaves:0)
B(-7,8,-12,leaves:0)
B(-10,22,5,leaves:0)
B(-8,12,-13,leaves:0)
B(0,19,-3,leaves:0)
B(-10,21,5,leaves:0)
B(-8,11,-13,leaves:0)
B(-8,10,-13,leaves:0)
B(0,17,-3,leaves:0)
B(0,18,-3,leaves:0)
B(-11,19,1,leaves:0)
B(2,16,6,leaves:0)
B(2,17,6,leaves:0)
B(2,11,6,leaves:0)
B(2,14,6,leaves:0)
B(2,-4,-5,LOG:12)
B(2,-3,-5,LOG:12)
B(-10,16,8,LOG:12)
B(-10,15,8,leaves:0)
B(-10,18,8,leaves:0)
B(-10,17,8,leaves:0)
B(-2,8,-1,LOG:12)
B(-2,7,-1,LOG:12)
B(-2,6,-1,LOG:12)
B(-2,5,-1,LOG:12)
B(-2,4,-1,LOG:12)
B(-2,3,-1,LOG:12)
B(-2,2,-1,LOG:12)
B(-10,14,8,leaves:0)
B(-2,1,-1,LOG:12)
B(-2,0,-1,LOG:12)
B(0,10,8,leaves:0)
B(11,9,-5,leaves:0)
B(0,18,8,leaves:0)
B(0,15,8,leaves:0)
B(0,13,8,leaves:0)
B(0,11,8,leaves:0)
B(0,12,8,leaves:0)
B(-3,22,0,leaves:0)
B(-3,21,0,leaves:0)
B(11,15,12,leaves:0)
B(11,13,12,leaves:0)
B(0,21,8,leaves:0)
B(0,20,8,leaves:0)
B(3,16,2,leaves:0)
B(3,17,2,leaves:0)
B(3,18,2,leaves:0)
B(-15,11,-13,leaves:0)
B(3,14,2,leaves:0)
B(-15,12,-13,leaves:0)
B(3,15,2,leaves:0)
B(14,11,5,leaves:0)
B(3,11,2,LOG:12)
B(-1,16,5,leaves:0)
B(-1,17,5,leaves:0)
B(-1,18,5,leaves:0)
B(7,11,15,leaves:0)
B(7,15,15,leaves:0)
B(7,14,15,leaves:0)
B(7,13,15,leaves:0)
B(7,12,15,leaves:0)
B(-15,8,9,leaves:0)
B(-15,9,9,leaves:0)
B(1,9,-8,leaves:0)
B(1,8,-8,leaves:0)
B(-1,20,5,leaves:0)
B(-2,13,6,leaves:0)
B(-2,12,6,leaves:0)
B(-2,11,6,leaves:0)
B(-2,10,6,leaves:0)
B(-12,17,8,leaves:0)
B(-12,18,8,leaves:0)
B(-12,11,8,leaves:0)
B(-12,12,8,leaves:0)
B(-12,13,8,leaves:0)
B(-12,14,8,leaves:0)
B(-12,15,8,leaves:0)
B(-12,16,8,leaves:0)
B(-7,-4,1,LOG:12)
B(-7,-3,1,LOG:12)
B(-14,8,10,leaves:0)
B(-14,7,10,leaves:0)
B(15,8,-2,leaves:0)
B(15,7,-2,leaves:0)
B(15,9,-2,leaves:0)
B(-14,9,10,leaves:0)
B(13,12,11,leaves:0)
B(-15,9,13,leaves:0)
B(2,16,12,leaves:0)
B(2,17,12,leaves:0)
B(2,14,12,leaves:0)
B(2,15,12,leaves:0)
B(2,18,12,leaves:0)
B(3,-3,2,LOG:12)
B(-6,11,-15,leaves:0)
B(-6,12,-15,leaves:0)
B(-6,10,-15,leaves:0)
B(12,9,3,leaves:0)
B(-16,12,-12,leaves:0)
B(12,17,5,leaves:0)
B(12,10,5,leaves:0)
B(12,11,5,leaves:0)
B(-5,9,-14,leaves:0)
B(12,14,5,leaves:0)
B(12,16,5,leaves:0)
B(-3,14,0,leaves:0)
B(-3,13,0,leaves:0)
B(-3,15,0,leaves:0)
B(-3,12,0,leaves:0)
B(-3,11,0,leaves:0)
B(-3,18,0,leaves:0)
B(-3,17,0,leaves:0)
B(-3,19,0,leaves:0)
B(-5,15,8,leaves:0)
B(3,18,3,leaves:0)
B(3,17,3,leaves:0)
B(3,19,3,leaves:0)
B(-5,11,8,LOG:12)
B(-5,12,8,LOG:12)
B(-13,6,2,leaves:0)
B(-5,13,8,LOG:12)
B(3,10,3,LOG:12)
B(3,12,3,LOG:12)
B(3,11,3,LOG:12)
B(-5,10,8,LOG:12)
B(3,16,3,leaves:0)
B(-5,20,8,leaves:0)
B(-5,21,8,leaves:0)
B(3,21,3,leaves:0)
B(3,20,3,leaves:0)
B(-8,17,11,leaves:0)
B(-8,16,11,leaves:0)
B(-8,18,11,leaves:0)
B(-8,14,11,leaves:0)
B(-11,17,-4,leaves:0)
B(-8,15,11,leaves:0)
B(-11,15,-4,leaves:0)
B(-11,16,-4,leaves:0)
B(-8,10,11,leaves:0)
B(-11,13,-4,leaves:0)
B(-11,14,-4,leaves:0)
B(-11,11,-4,leaves:0)
B(-11,12,-4,leaves:0)
B(-13,7,2,leaves:0)
B(-11,10,-4,leaves:0)
B(-13,8,2,leaves:0)
B(-5,19,8,leaves:0)
B(12,12,11,leaves:0)
B(-12,15,9,leaves:0)
B(-12,14,9,leaves:0)
B(-12,17,9,leaves:0)
B(-12,16,9,leaves:0)
B(-12,11,9,leaves:0)
B(-12,13,9,leaves:0)
B(-12,12,9,leaves:0)
B(6,-4,3,LOG:12)
B(-7,11,15,leaves:0)
B(-7,12,15,leaves:0)
B(12,9,-1,leaves:0)
B(-3,-3,0,LOG:12)
B(-3,-4,0,LOG:12)
B(-3,-1,0,LOG:12)
B(-3,-2,0,LOG:12)
B(-7,13,15,leaves:0)
B(-7,14,15,leaves:0)
B(-2,17,6,leaves:0)
B(-2,16,6,leaves:0)
B(-2,19,6,leaves:0)
B(-2,18,6,leaves:0)
B(-2,20,6,leaves:0)
B(-8,-3,11,LOG:12)
B(-8,-4,11,LOG:12)
B(-16,9,-2,leaves:0)
B(-16,8,-2,leaves:0)
B(10,10,-9,leaves:0)
B(-6,-3,3,LOG:12)
B(2,20,13,leaves:0)
B(0,11,-11,leaves:0)
B(-11,-4,-4,LOG:12)
B(0,10,-11,leaves:0)
B(-11,-3,-4,LOG:12)
B(0,12,-11,leaves:0)
B(0,15,-11,leaves:0)
B(6,11,3,LOG:12)
B(2,-4,-4,LOG:12)
B(2,-2,-4,LOG:12)
B(2,-3,-4,LOG:12)
B(6,18,3,leaves:0)
B(6,19,3,leaves:0)
B(6,16,3,leaves:0)
B(6,17,3,leaves:0)
B(6,14,3,leaves:0)
B(6,15,3,leaves:0)
B(6,12,3,leaves:0)
B(2,9,-6,LOG:12)
B(6,13,3,leaves:0)
B(-8,18,4,LOG:12)
B(-8,19,4,leaves:0)
B(-7,8,-1,leaves:0)
B(-7,7,-1,leaves:0)
B(-8,20,4,leaves:0)
B(-8,21,4,leaves:0)
B(-9,14,-10,leaves:0)
B(11,11,12,leaves:0)
B(-9,15,-10,leaves:0)
B(-9,16,-10,leaves:0)
B(-9,17,-10,leaves:0)
B(16,9,-3,leaves:0)
B(-9,18,-10,leaves:0)
B(-14,9,-14,leaves:0)
B(6,12,-11,leaves:0)
B(-16,8,2,leaves:0)
B(-16,9,2,leaves:0)
B(-8,10,-12,leaves:0)
B(-16,6,2,leaves:0)
B(-16,7,2,leaves:0)
B(-1,21,8,leaves:0)
B(-1,20,8,leaves:0)
B(-1,19,8,leaves:0)
B(4,12,10,leaves:0)
B(-1,15,8,leaves:0)
B(4,13,10,leaves:0)
B(4,11,10,leaves:0)
B(-1,18,8,leaves:0)
B(4,16,10,LOG:12)
B(4,17,10,LOG:12)
B(6,20,3,leaves:0)
B(1,16,8,leaves:0)
B(1,19,8,leaves:0)
B(4,18,10,leaves:0)
B(4,19,10,leaves:0)
B(1,18,8,leaves:0)
B(-8,12,4,leaves:0)
B(-8,14,4,leaves:0)
B(-8,16,4,leaves:0)
B(-12,10,-3,leaves:0)
B(-8,17,4,LOG:12)
B(-12,11,-3,leaves:0)
B(-12,12,-3,leaves:0)
B(-12,13,-3,leaves:0)
B(-1,11,8,leaves:0)
B(-12,14,-3,leaves:0)
B(-1,10,8,leaves:0)
B(-12,15,-3,leaves:0)
B(-12,16,-3,leaves:0)
B(-8,16,-12,leaves:0)
B(4,20,10,leaves:0)
B(-8,17,-12,leaves:0)
B(-8,15,-12,leaves:0)
B(-8,12,-12,leaves:0)
B(-8,13,-12,leaves:0)
B(-15,12,-2,leaves:0)
B(-15,13,-2,leaves:0)
B(-15,14,-2,leaves:0)
B(-15,10,-2,leaves:0)
B(2,21,-4,leaves:0)
B(7,14,-1,leaves:0)
B(2,20,-4,leaves:0)
B(7,15,-1,leaves:0)
B(7,11,-1,leaves:0)
B(-15,16,-2,leaves:0)
B(7,16,-1,leaves:0)
B(-15,15,-2,leaves:0)
B(7,17,-1,leaves:0)
B(7,19,-1,leaves:0)
B(3,-2,-3,LOG:12)
B(3,-4,-3,LOG:12)
B(2,17,-4,leaves:0)
B(2,16,-4,leaves:0)
B(2,19,-4,leaves:0)
B(2,18,-4,leaves:0)
B(2,10,-4,leaves:0)
B(2,11,-4,leaves:0)
B(2,12,-4,leaves:0)
B(2,13,-4,leaves:0)
B(2,14,-4,leaves:0)
B(-1,13,-9,leaves:0)
B(-1,14,-9,leaves:0)
B(-1,11,-9,leaves:0)
B(11,14,2,leaves:0)
B(11,13,2,leaves:0)
B(11,15,2,leaves:0)
B(-15,14,7,leaves:0)
B(-15,13,7,leaves:0)
B(11,17,2,leaves:0)
B(-15,12,7,leaves:0)
B(-15,11,7,leaves:0)
B(11,12,2,leaves:0)
B(-7,11,3,leaves:0)
B(-7,10,3,leaves:0)
B(-7,15,3,leaves:0)
B(-7,14,3,leaves:0)
B(-7,13,3,leaves:0)
B(-7,12,3,leaves:0)
B(-15,10,7,leaves:0)
B(16,10,-2,leaves:0)
B(2,17,5,leaves:0)
B(2,15,5,leaves:0)
B(2,14,5,leaves:0)
B(2,11,5,leaves:0)
B(2,10,5,leaves:0)
B(2,19,5,leaves:0)
B(2,18,5,leaves:0)
B(2,20,5,leaves:0)
B(1,18,12,leaves:0)
B(1,17,12,leaves:0)
B(1,16,12,leaves:0)
B(1,15,12,LOG:12)
B(1,19,12,leaves:0)
B(16,12,-2,leaves:0)
B(16,11,-2,leaves:0)
B(1,20,12,leaves:0)
B(-8,21,11,leaves:0)
B(-1,6,-12,leaves:0)
B(-1,9,-12,leaves:0)
B(-1,8,-12,leaves:0)
B(15,11,-3,leaves:0)
B(-6,9,-6,LOG:12)
B(-6,14,-16,leaves:0)
B(-9,-5,10,LOG:12)
B(-9,-4,10,LOG:12)
B(-9,-3,10,LOG:12)
B(7,21,6,leaves:0)
B(7,20,6,leaves:0)
B(-7,9,-13,leaves:0)
B(-7,7,-13,leaves:0)
B(-7,8,-13,leaves:0)
B(7,12,6,leaves:0)
B(7,15,6,leaves:0)
B(11,11,-5,leaves:0)
B(11,10,-5,leaves:0)
B(7,17,6,leaves:0)
B(7,16,6,leaves:0)
B(7,19,6,leaves:0)
B(7,18,6,leaves:0)
B(4,11,13,leaves:0)
B(4,13,13,leaves:0)
B(4,14,13,leaves:0)
B(4,19,13,leaves:0)
B(-13,11,13,leaves:0)
B(-13,10,13,leaves:0)
B(4,17,13,leaves:0)
B(-13,12,13,leaves:0)
B(4,18,13,leaves:0)
B(-7,21,3,leaves:0)
B(-7,20,3,leaves:0)
B(-7,19,3,leaves:0)
B(-7,18,3,LOG:12)
B(-7,17,3,leaves:0)
B(-7,16,3,leaves:0)
B(14,9,-1,leaves:0)
B(-9,18,10,leaves:0)
B(-9,19,10,leaves:0)
B(-9,16,10,leaves:0)
B(-9,17,10,leaves:0)
B(-1,10,5,LOG:12)
B(-9,14,10,LOG:12)
B(-1,11,5,leaves:0)
B(-9,15,10,leaves:0)
B(-9,13,10,leaves:0)
B(0,17,12,leaves:0)
B(-9,12,10,leaves:0)
B(0,16,12,leaves:0)
B(0,18,12,leaves:0)
B(0,15,12,leaves:0)
B(0,14,12,leaves:0)
B(10,10,-8,leaves:0)
B(1,21,9,leaves:0)
B(1,20,9,leaves:0)
B(-2,15,11,leaves:0)
B(-2,14,11,leaves:0)
B(-2,17,11,leaves:0)
B(-2,16,11,leaves:0)
B(-2,18,11,leaves:0)
B(7,-4,6,LOG:12)
B(-2,16,-7,leaves:0)
B(-2,19,-7,leaves:0)
B(-2,18,-7,leaves:0)
B(-2,13,11,leaves:0)
B(-12,10,10,leaves:0)
B(-12,11,10,leaves:0)
B(3,11,-3,leaves:0)
B(-2,15,-7,leaves:0)
B(3,12,-3,leaves:0)
B(-14,6,-14,leaves:0)
B(3,13,-3,leaves:0)
B(1,17,9,leaves:0)
B(1,18,9,leaves:0)
B(1,19,9,leaves:0)
B(-7,7,-11,leaves:0)
B(1,16,9,LOG:12)
B(-12,17,10,leaves:0)
B(3,14,-3,leaves:0)
B(-12,16,10,leaves:0)
B(3,17,-3,leaves:0)
B(-7,9,-11,leaves:0)
B(3,16,-3,leaves:0)
B(-12,18,10,leaves:0)
B(-12,13,10,leaves:0)
B(3,19,-3,leaves:0)
B(-12,12,10,leaves:0)
B(3,18,-3,leaves:0)
B(-12,15,10,leaves:0)
B(-12,14,10,leaves:0)
B(-15,11,-10,leaves:0)
B(-15,14,-10,leaves:0)
B(-15,15,-10,leaves:0)
B(-15,12,-10,leaves:0)
B(-9,11,-2,leaves:0)
B(-15,13,-10,leaves:0)
B(-9,13,-2,leaves:0)
B(-9,12,-2,leaves:0)
B(-9,15,-2,leaves:0)
B(-9,17,-2,leaves:0)
B(-9,16,-2,leaves:0)
B(-9,18,-2,leaves:0)
B(14,7,-3,leaves:0)
B(14,8,-3,leaves:0)
B(14,9,-3,leaves:0)
B(11,9,-4,leaves:0)
B(-13,9,-9,leaves:0)
B(-8,20,1,leaves:0)
B(1,9,-5,LOG:12)
B(-4,10,-10,leaves:0)
B(-15,9,8,leaves:0)
B(-15,8,8,leaves:0)
B(-15,7,8,leaves:0)
B(-4,13,-10,leaves:0)
B(-4,14,-10,leaves:0)
B(-4,15,-10,leaves:0)
B(-4,16,-10,leaves:0)
B(3,20,-2,leaves:0)
B(-4,17,-10,leaves:0)
B(-8,18,1,leaves:0)
B(-8,17,1,leaves:0)
B(-8,19,1,leaves:0)
B(-8,10,1,leaves:0)
B(-8,11,1,leaves:0)
B(-6,13,6,leaves:0)
B(-6,12,6,leaves:0)
B(3,12,-2,leaves:0)
B(-6,11,6,leaves:0)
B(-6,10,6,leaves:0)
B(-6,17,6,leaves:0)
B(-6,16,6,leaves:0)
B(-6,15,6,leaves:0)
B(-6,14,6,leaves:0)
B(3,17,-2,leaves:0)
B(3,18,-2,leaves:0)
B(3,19,-2,leaves:0)
B(3,13,-2,leaves:0)
B(3,16,-2,leaves:0)
B(8,17,15,leaves:0)
B(-6,22,6,leaves:0)
B(-1,9,7,leaves:0)
B(7,12,7,leaves:0)
B(7,15,7,leaves:0)
B(7,16,7,leaves:0)
B(7,13,7,leaves:0)
B(8,14,15,leaves:0)
B(8,13,15,leaves:0)
B(7,14,7,leaves:0)
B(7,19,7,leaves:0)
B(7,17,7,leaves:0)
B(-6,19,6,leaves:0)
B(3,17,0,leaves:0)
B(3,18,0,leaves:0)
B(3,19,0,leaves:0)
B(3,12,0,leaves:0)
B(-3,10,-12,leaves:0)
B(-3,12,-12,leaves:0)
B(-3,11,-12,leaves:0)
B(-13,6,5,leaves:0)
B(-3,14,-12,leaves:0)
B(-13,7,5,leaves:0)
B(-3,13,-12,leaves:0)
B(9,13,7,leaves:0)
B(3,15,15,leaves:0)
B(9,14,7,leaves:0)
B(3,14,15,leaves:0)
B(9,11,7,leaves:0)
B(3,13,15,leaves:0)
B(-3,20,-2,leaves:0)
B(3,12,15,leaves:0)
B(9,12,7,leaves:0)
B(9,17,7,leaves:0)
B(9,18,7,leaves:0)
B(3,18,15,leaves:0)
B(9,15,7,leaves:0)
B(3,17,15,leaves:0)
B(9,16,7,leaves:0)
B(-3,19,-2,leaves:0)
B(-3,18,-2,leaves:0)
B(-3,12,-9,leaves:0)
B(-3,17,-2,leaves:0)
B(9,19,7,leaves:0)
B(-3,11,-2,leaves:0)
B(3,10,15,leaves:0)
B(-3,14,-9,leaves:0)
B(3,11,15,leaves:0)
B(-3,13,-9,leaves:0)
B(-3,16,-9,leaves:0)
B(-3,15,-9,leaves:0)
B(-3,17,-9,leaves:0)
B(-3,18,-9,leaves:0)
B(-10,21,6,leaves:0)
B(-10,13,-16,leaves:0)
B(-10,12,-16,leaves:0)
B(-10,11,-16,leaves:0)
B(13,13,0,leaves:0)
B(3,-4,-2,LOG:12)
B(-4,7,3,LOG:12)
B(3,-3,-2,LOG:12)
B(-4,6,3,LOG:12)
B(13,11,0,leaves:0)
B(-3,22,-2,leaves:0)
B(3,-2,-2,LOG:12)
B(-3,21,-2,leaves:0)
B(10,20,5,leaves:0)
B(-2,-3,2,LOG:12)
B(-3,8,6,LOG:12)
B(-2,-2,2,LOG:12)
B(-3,9,6,leaves:0)
B(-2,-1,2,LOG:12)
B(1,8,-15,leaves:0)
B(-2,-5,2,LOG:12)
B(-2,-4,2,LOG:12)
B(1,7,-15,leaves:0)
B(0,9,-9,leaves:0)
B(-11,12,-1,LOG:12)
B(-11,13,-1,leaves:0)
B(-11,11,-1,leaves:0)
B(-11,16,-1,leaves:0)
B(-11,17,-1,leaves:0)
B(-11,14,-1,leaves:0)
B(-11,15,-1,leaves:0)
B(3,22,0,leaves:0)
B(-11,19,-1,leaves:0)
B(3,21,0,leaves:0)
B(-2,21,-1,leaves:0)
B(-11,18,-1,leaves:0)
B(3,20,0,leaves:0)
B(-7,11,4,leaves:0)
B(-7,12,4,leaves:0)
B(-7,10,4,leaves:0)
B(-7,15,4,leaves:0)
B(-10,18,3,leaves:0)
B(-7,16,4,leaves:0)
B(-10,19,3,leaves:0)
B(-7,18,4,LOG:12)
B(-10,16,3,leaves:0)
B(-7,17,4,leaves:0)
B(-10,15,3,leaves:0)
B(-7,19,4,leaves:0)
B(-10,13,3,leaves:0)
B(-10,12,3,leaves:0)
B(-10,11,3,leaves:0)
B(-10,10,3,leaves:0)
B(4,19,-3,leaves:0)
B(4,17,-3,leaves:0)
B(4,18,-3,leaves:0)
B(4,16,-3,leaves:0)
B(4,13,-3,leaves:0)
B(4,14,-3,leaves:0)
B(4,12,-3,leaves:0)
B(-11,11,17,leaves:0)
B(-11,10,17,leaves:0)
B(-7,20,4,leaves:0)
B(-7,21,4,leaves:0)
B(-11,12,17,leaves:0)
B(-7,22,4,leaves:0)
B(-9,12,-13,leaves:0)
B(-9,11,-13,leaves:0)
B(-4,15,-6,leaves:0)
B(-4,16,-6,leaves:0)
B(-2,20,2,leaves:0)
B(-4,19,-6,leaves:0)
B(-4,17,-6,leaves:0)
B(-4,18,-6,leaves:0)
B(-1,5,-2,LOG:12)
B(-1,6,-2,LOG:12)
B(-2,18,2,leaves:0)
B(-2,19,2,leaves:0)
B(-2,12,2,leaves:0)
B(-2,13,2,leaves:0)
B(4,20,-3,leaves:0)
B(-1,7,-2,LOG:12)
B(-2,14,2,leaves:0)
B(-1,8,-2,LOG:12)
B(-2,15,2,leaves:0)
B(-13,6,10,leaves:0)
B(12,14,2,leaves:0)
B(-13,7,10,leaves:0)
B(12,15,2,leaves:0)
B(-2,20,-1,leaves:0)
B(12,16,2,leaves:0)
B(12,17,2,leaves:0)
B(-15,9,12,leaves:0)
B(-14,8,11,leaves:0)
B(-14,9,11,leaves:0)
B(-13,8,10,leaves:0)
B(-13,9,10,leaves:0)
B(12,13,2,leaves:0)
B(-11,10,13,leaves:0)
B(-11,11,13,leaves:0)
B(-11,12,13,leaves:0)
B(-11,13,13,leaves:0)
B(-2,19,-1,leaves:0)
B(-2,21,2,leaves:0)
B(-2,14,-1,leaves:0)
B(-2,17,-1,leaves:0)
B(-2,11,-1,leaves:0)
B(-2,12,-1,leaves:0)
B(-11,13,10,leaves:0)
B(-11,14,10,leaves:0)
B(-11,16,10,leaves:0)
B(-11,17,10,leaves:0)
B(-13,11,-1,leaves:0)
B(5,7,-9,leaves:0)
B(-13,13,-1,leaves:0)
B(-13,14,-1,leaves:0)
B(-13,15,-1,leaves:0)
B(-13,16,-1,leaves:0)
B(2,9,-3,LOG:12)
B(-8,20,-2,leaves:0)
B(-11,10,10,leaves:0)
B(-11,12,10,leaves:0)
B(-11,11,10,leaves:0)
B(-6,14,-5,leaves:0)
B(10,10,5,leaves:0)
B(-6,15,-5,leaves:0)
B(-6,16,-5,leaves:0)
B(-6,17,-5,leaves:0)
B(-6,10,-5,LOG:12)
B(-6,11,-5,LOG:12)
B(-6,12,-5,LOG:12)
B(10,11,5,leaves:0)
B(10,17,5,leaves:0)
B(10,18,5,leaves:0)
B(10,15,5,leaves:0)
B(-6,18,-5,leaves:0)
B(-6,19,-5,leaves:0)
B(10,19,5,leaves:0)
B(-7,5,-4,leaves:0)
B(-7,9,-4,leaves:0)
B(-6,-1,6,LOG:12)
B(-8,12,-2,leaves:0)
B(-6,-2,6,LOG:12)
B(-8,11,-2,leaves:0)
B(-6,-3,6,LOG:12)
B(-7,8,-4,LOG:12)
B(-8,14,-2,leaves:0)
B(-6,20,-5,leaves:0)
B(-8,16,-2,leaves:0)
B(-8,15,-2,leaves:0)
B(-8,18,-2,leaves:0)
B(-8,17,-2,leaves:0)
B(-8,19,-2,leaves:0)
B(8,10,-8,leaves:0)
B(1,-3,4,LOG:12)
B(-7,5,-5,leaves:0)
B(1,-5,4,LOG:12)
B(1,-4,4,LOG:12)
B(-7,9,-5,LOG:12)
B(-14,14,10,leaves:0)
B(-9,18,3,leaves:0)
B(-9,19,3,leaves:0)
B(4,11,-10,leaves:0)
B(4,12,-10,leaves:0)
B(-14,13,10,leaves:0)
B(-14,10,10,leaves:0)
B(4,13,-10,leaves:0)
B(-14,11,10,leaves:0)
B(-16,6,3,leaves:0)
B(4,10,-10,leaves:0)
B(-16,8,3,leaves:0)
B(-16,7,3,leaves:0)
B(-12,9,15,leaves:0)
B(-8,15,8,leaves:0)
B(-8,17,8,leaves:0)
B(8,20,7,leaves:0)
B(-8,16,8,leaves:0)
B(-8,19,8,leaves:0)
B(-7,11,14,leaves:0)
B(-7,13,14,leaves:0)
B(-7,12,14,leaves:0)
B(-7,14,14,leaves:0)
B(-8,11,8,leaves:0)
B(-7,17,14,leaves:0)
B(-8,10,8,leaves:0)
B(-8,13,8,leaves:0)
B(-8,12,8,LOG:12)
B(8,19,7,leaves:0)
B(8,18,7,leaves:0)
B(8,12,7,leaves:0)
B(8,13,7,leaves:0)
B(8,10,7,leaves:0)
B(8,11,7,leaves:0)
B(8,16,7,leaves:0)
B(8,17,7,leaves:0)
B(8,14,7,leaves:0)
B(8,15,7,leaves:0)
B(-6,9,-5,LOG:12)
B(-6,7,-5,leaves:0)
B(-6,8,-5,LOG:12)
B(-14,9,-11,leaves:0)
B(-6,5,-5,leaves:0)
B(-14,8,-11,leaves:0)
B(-14,7,-11,leaves:0)
B(-14,6,-11,leaves:0)
B(-9,13,3,leaves:0)
B(11,15,1,leaves:0)
B(11,14,1,leaves:0)
B(11,13,1,leaves:0)
B(11,12,1,leaves:0)
B(11,19,1,leaves:0)
B(11,18,1,leaves:0)
B(11,17,1,leaves:0)
B(11,16,1,leaves:0)
B(3,14,-10,leaves:0)
B(3,11,-10,leaves:0)
B(3,10,-10,leaves:0)
B(3,13,-10,leaves:0)
B(3,12,-10,leaves:0)
B(0,14,1,LOG:12)
B(0,15,1,leaves:0)
B(0,18,1,leaves:0)
B(0,19,1,leaves:0)
B(2,15,13,leaves:0)
B(2,16,13,leaves:0)
B(2,17,13,leaves:0)
B(2,18,13,leaves:0)
B(2,11,13,leaves:0)
B(2,12,13,leaves:0)
B(12,12,-2,leaves:0)
B(12,11,-2,leaves:0)
B(2,14,13,leaves:0)
B(11,13,-4,leaves:0)
B(11,11,-4,leaves:0)
B(2,19,13,leaves:0)
B(0,14,11,LOG:12)
B(0,15,11,LOG:12)
B(0,16,11,leaves:0)
B(0,17,11,leaves:0)
B(0,19,11,leaves:0)
B(2,18,2,leaves:0)
B(2,16,2,leaves:0)
B(2,15,2,leaves:0)
B(3,13,16,leaves:0)
B(3,14,16,leaves:0)
B(2,19,2,leaves:0)
B(-8,21,8,leaves:0)
B(-8,20,8,leaves:0)
B(3,12,16,leaves:0)
B(-15,12,0,leaves:0)
B(-13,16,0,leaves:0)
B(-13,15,0,leaves:0)
B(2,20,2,leaves:0)
B(-13,14,0,leaves:0)
B(-15,10,0,leaves:0)
B(-13,13,0,leaves:0)
B(-13,12,0,leaves:0)
B(-15,11,0,leaves:0)
B(-13,11,0,leaves:0)
B(3,-2,-1,LOG:12)
B(3,-3,-1,LOG:12)
B(0,-1,1,LOG:12)
B(0,-3,1,LOG:12)
B(0,-2,1,LOG:12)
B(0,-5,1,LOG:12)
B(0,-4,1,LOG:12)
B(0,0,0,LOG:12)
B(6,15,-6,leaves:0)
B(6,14,-6,leaves:0)
B(6,17,-6,leaves:0)
B(6,10,-6,leaves:0)
B(6,11,-6,leaves:0)
B(6,12,-6,leaves:0)
B(6,13,-6,leaves:0)
B(5,12,14,leaves:0)
B(-4,9,-11,leaves:0)
B(-4,8,-11,leaves:0)
B(-4,7,-11,leaves:0)
B(5,16,14,leaves:0)
B(5,15,14,leaves:0)
B(5,14,14,leaves:0)
B(5,13,14,leaves:0)
B(5,19,14,leaves:0)
B(5,18,14,leaves:0)
B(5,17,14,leaves:0)
B(-10,16,6,leaves:0)
B(-9,-5,-8,LOG:12)
B(-9,-4,-8,LOG:12)
B(-10,13,6,leaves:0)
B(-10,19,6,leaves:0)
B(-10,18,6,leaves:0)
B(-10,17,6,leaves:0)
B(3,10,-13,leaves:0)
B(-10,12,6,leaves:0)
B(-9,-3,-8,LOG:12)
B(-10,11,6,leaves:0)
B(-15,11,-6,leaves:0)
B(-10,12,12,leaves:0)
B(-15,10,-6,leaves:0)
B(-10,13,12,leaves:0)
B(-10,14,12,leaves:0)
B(-10,15,12,leaves:0)
B(-10,10,12,leaves:0)
B(-10,17,12,leaves:0)
B(-10,16,12,leaves:0)
B(2,-3,2,LOG:12)
B(2,-4,2,LOG:12)
B(9,13,-5,leaves:0)
B(9,11,-5,leaves:0)
B(10,14,8,leaves:0)
B(10,15,8,leaves:0)
B(10,16,8,leaves:0)
B(10,17,8,leaves:0)
B(10,11,8,leaves:0)
B(10,12,8,leaves:0)
B(10,13,8,leaves:0)
B(-10,-4,-9,LOG:12)
B(0,8,0,leaves:0)
B(-1,9,6,LOG:12)
B(2,20,8,leaves:0)
B(8,12,-6,leaves:0)
B(8,14,-6,leaves:0)
B(1,18,4,leaves:0)
B(1,19,4,leaves:0)
B(8,10,-6,leaves:0)
B(8,11,-6,leaves:0)
B(1,17,4,leaves:0)
B(1,10,4,LOG:12)
B(1,11,4,LOG:12)
B(1,12,4,LOG:12)
B(-7,8,-14,leaves:0)
B(-5,18,7,leaves:0)
B(-5,19,7,leaves:0)
B(-7,9,-14,leaves:0)
B(-7,6,-14,leaves:0)
B(-7,7,-14,leaves:0)
B(10,12,10,leaves:0)
B(10,13,10,leaves:0)
B(10,14,10,leaves:0)
B(-8,-2,8,LOG:12)
B(-8,-3,8,LOG:12)
B(-8,-1,8,LOG:12)
B(-8,-4,8,LOG:12)
B(9,13,13,leaves:0)
B(2,16,8,leaves:0)
B(9,12,13,leaves:0)
B(-9,13,-8,leaves:0)
B(2,14,8,leaves:0)
B(-9,16,-8,leaves:0)
B(2,19,8,leaves:0)
B(-9,17,-8,leaves:0)
B(-5,20,7,leaves:0)
B(-9,14,-8,leaves:0)
B(2,18,8,leaves:0)
B(-9,15,-8,leaves:0)
B(2,17,8,leaves:0)
B(-5,22,7,leaves:0)
B(9,11,13,leaves:0)
B(9,10,13,leaves:0)
B(-15,-3,-6,LOG:12)
B(-15,-4,-6,LOG:12)
B(-15,-2,-6,LOG:12)
B(-5,15,7,leaves:0)
B(-5,12,7,LOG:12)
B(-5,11,7,LOG:12)
B(-5,10,7,leaves:0)
B(-13,10,-14,leaves:0)
B(-2,6,-3,LOG:12)
B(-10,16,-9,leaves:0)
B(-10,15,-9,leaves:0)
B(-10,18,-9,leaves:0)
B(-10,17,-9,leaves:0)
B(1,20,4,leaves:0)
B(-10,11,-9,leaves:0)
B(1,21,4,leaves:0)
B(-7,23,5,leaves:0)
B(-7,22,5,leaves:0)
B(-7,21,5,leaves:0)
B(-13,11,15,leaves:0)
B(-13,12,15,leaves:0)
B(-7,20,5,leaves:0)
B(-7,8,-15,leaves:0)
B(-7,7,-15,leaves:0)
B(-7,9,-15,leaves:0)
B(-7,19,5,leaves:0)
B(-3,18,2,leaves:0)
B(1,18,14,leaves:0)
B(-3,17,2,leaves:0)
B(1,17,14,leaves:0)
B(1,19,14,leaves:0)
B(1,14,14,leaves:0)
B(1,13,14,leaves:0)
B(-3,12,2,leaves:0)
B(1,16,14,leaves:0)
B(-3,11,2,leaves:0)
B(1,15,14,leaves:0)
B(-3,19,2,leaves:0)
B(-13,6,4,leaves:0)
B(-13,8,4,leaves:0)
B(-13,7,4,leaves:0)
B(-3,20,2,leaves:0)
B(-3,21,2,leaves:0)
B(1,11,14,leaves:0)
B(-3,23,2,leaves:0)
B(-3,24,2,leaves:0)
B(-15,6,7,leaves:0)
B(-15,9,7,leaves:0)
B(-15,8,7,leaves:0)
B(1,9,-6,leaves:0)
B(-6,11,-4,LOG:12)
B(-6,12,-4,leaves:0)
B(10,11,4,leaves:0)
B(-6,10,-4,leaves:0)
B(-6,15,-4,leaves:0)
B(-6,16,-4,leaves:0)
B(-6,13,-4,leaves:0)
B(10,18,4,leaves:0)
B(-6,19,-4,leaves:0)
B(10,19,4,leaves:0)
B(-6,17,-4,leaves:0)
B(-6,18,-4,leaves:0)
B(10,14,4,leaves:0)
B(10,15,4,leaves:0)
B(10,16,4,leaves:0)
B(10,17,4,leaves:0)
B(-7,15,5,leaves:0)
B(-5,1,-1,LOG:12)
B(-7,17,5,leaves:0)
B(-5,0,-1,LOG:12)
B(-7,16,5,leaves:0)
B(-7,11,5,leaves:0)
B(-13,19,7,leaves:0)
B(-7,10,5,leaves:0)
B(-7,13,5,leaves:0)
B(-13,18,7,leaves:0)
B(-7,12,5,leaves:0)
B(-13,17,7,leaves:0)
B(-13,16,7,leaves:0)
B(-13,15,7,leaves:0)
B(-13,14,7,leaves:0)
B(-13,13,7,leaves:0)
B(-13,11,7,leaves:0)
B(-13,10,7,leaves:0)
B(-4,5,2,LOG:12)
B(-4,6,2,LOG:12)
B(-4,0,2,LOG:12)
B(-5,6,-1,LOG:12)
B(-4,7,2,LOG:12)
B(-5,7,-1,LOG:12)
B(-5,4,-1,LOG:12)
B(-5,5,-1,LOG:12)
B(2,21,10,leaves:0)
B(-3,9,7,leaves:0)
B(2,20,10,leaves:0)
B(-9,12,-4,LOG:12)
B(-9,13,-4,leaves:0)
B(-9,11,-4,LOG:12)
B(-9,16,-4,leaves:0)
B(-9,17,-4,leaves:0)
B(-7,-1,7,LOG:12)
B(-9,14,-4,LOG:12)
B(-9,15,-4,leaves:0)
B(-1,12,-11,leaves:0)
B(-1,13,-11,leaves:0)
B(14,9,-4,leaves:0)
B(-1,10,-11,leaves:0)
B(-1,11,-11,leaves:0)
B(-10,7,-14,leaves:0)
B(-10,8,-14,leaves:0)
B(2,14,10,leaves:0)
B(-10,9,-14,leaves:0)
B(2,15,10,leaves:0)
B(9,13,6,leaves:0)
B(2,16,10,leaves:0)
B(9,12,6,leaves:0)
B(2,17,10,LOG:12)
B(9,11,6,leaves:0)
B(2,18,10,leaves:0)
B(2,19,10,leaves:0)
B(9,10,6,leaves:0)
B(9,17,6,leaves:0)
B(9,16,6,leaves:0)
B(9,15,6,leaves:0)
B(9,14,6,leaves:0)
B(9,18,6,leaves:0)
B(9,19,6,leaves:0)
B(0,0,1,LOG:12)
B(7,16,12,leaves:0)
B(7,14,12,leaves:0)
B(7,13,12,leaves:0)
B(7,18,12,leaves:0)
B(7,17,12,leaves:0)
B(14,11,2,leaves:0)
B(14,17,2,leaves:0)
B(12,9,5,leaves:0)
B(-6,-4,-4,LOG:12)
B(-6,-3,-4,LOG:12)
B(1,13,-12,leaves:0)
B(1,10,-12,leaves:0)
B(-4,21,-5,leaves:0)
B(-7,-2,5,LOG:12)
B(0,13,14,leaves:0)
B(0,14,14,leaves:0)
B(0,16,14,leaves:0)
B(0,17,14,leaves:0)
B(-4,13,-5,leaves:0)
B(-4,12,-5,leaves:0)
B(-4,15,-5,leaves:0)
B(-4,14,-5,leaves:0)
B(-4,17,-5,leaves:0)
B(-4,16,-5,leaves:0)
B(6,-4,-6,LOG:12)
B(-4,18,-5,leaves:0)
B(3,19,-1,leaves:0)
B(3,18,-1,leaves:0)
B(4,-4,8,LOG:12)
B(1,20,6,leaves:0)
B(3,15,-1,leaves:0)
B(-5,18,10,leaves:0)
B(-5,19,10,leaves:0)
B(3,14,-1,leaves:0)
B(3,13,-1,leaves:0)
B(3,12,-1,leaves:0)
B(-6,11,7,leaves:0)
B(-5,15,10,leaves:0)
B(-6,12,7,LOG:12)
B(-5,14,10,LOG:12)
B(-6,15,7,leaves:0)
B(5,19,-2,leaves:0)
B(1,7,-14,leaves:0)
B(-5,13,10,leaves:0)
B(-5,12,10,leaves:0)
B(1,8,-14,leaves:0)
B(-6,18,7,leaves:0)
B(5,15,-2,leaves:0)
B(5,16,-2,leaves:0)
B(5,17,-2,leaves:0)
B(5,18,-2,leaves:0)
B(5,13,-2,leaves:0)
B(-6,10,7,leaves:0)
B(5,21,-2,leaves:0)
B(5,20,-2,leaves:0)
B(9,14,16,leaves:0)
B(6,13,13,leaves:0)
B(6,14,13,leaves:0)
B(6,12,13,leaves:0)
B(-10,15,-6,leaves:0)
B(6,10,13,leaves:0)
B(-5,22,10,leaves:0)
B(-5,21,10,leaves:0)
B(-10,11,-6,leaves:0)
B(5,15,0,leaves:0)
B(-5,20,10,leaves:0)
B(5,16,0,leaves:0)
B(5,17,0,leaves:0)
B(6,19,13,leaves:0)
B(5,18,0,leaves:0)
B(-13,10,-11,leaves:0)
B(5,19,0,leaves:0)
B(-10,16,-6,leaves:0)
B(6,17,13,leaves:0)
B(-13,12,-11,leaves:0)
B(-10,17,-6,leaves:0)
B(6,18,13,leaves:0)
B(6,15,13,leaves:0)
B(6,16,13,leaves:0)
B(-11,12,-3,leaves:0)
B(-12,14,-1,leaves:0)
B(-11,13,-3,leaves:0)
B(-12,13,-1,leaves:0)
B(-11,14,-3,leaves:0)
B(-12,16,-1,leaves:0)
B(-11,15,-3,leaves:0)
B(-12,15,-1,leaves:0)
B(-11,16,-3,leaves:0)
B(-11,17,-3,leaves:0)
B(-12,12,-1,leaves:0)
B(-11,10,-3,leaves:0)
B(-11,11,-3,leaves:0)
B(5,20,0,leaves:0)
B(9,20,6,leaves:0)
B(-12,17,-1,leaves:0)
B(-12,18,-1,leaves:0)
B(-12,19,-1,leaves:0)
B(-12,20,-1,leaves:0)
B(4,16,8,LOG:12)
B(4,17,8,leaves:0)
B(4,18,8,leaves:0)
B(4,19,8,leaves:0)
B(-4,-2,-4,LOG:12)
B(-4,-3,-4,LOG:12)
B(-1,8,-3,LOG:12)
B(-1,9,-3,LOG:12)
B(-1,6,-3,LOG:12)
B(-1,7,-3,LOG:12)
B(4,20,-1,leaves:0)
B(-12,20,6,leaves:0)
B(-6,-2,7,LOG:12)
B(-6,-1,7,LOG:12)
B(4,14,8,leaves:0)
B(4,13,8,leaves:0)
B(-14,7,12,leaves:0)
B(-14,8,12,leaves:0)
B(-14,9,12,leaves:0)
B(-3,15,-8,leaves:0)
B(-15,9,11,leaves:0)
B(-14,6,12,leaves:0)
B(4,20,8,leaves:0)
B(-15,-3,-5,LOG:12)
B(2,12,16,leaves:0)
B(2,13,16,leaves:0)
B(2,9,-4,LOG:12)
B(-10,9,4,leaves:0)
B(2,14,16,leaves:0)
B(-3,17,-8,leaves:0)
B(-3,16,-8,leaves:0)
B(-3,18,-8,leaves:0)
B(4,19,-1,leaves:0)
B(4,16,-1,leaves:0)
B(4,15,-1,leaves:0)
B(4,18,-1,leaves:0)
B(4,14,-1,leaves:0)
B(4,13,-1,leaves:0)
B(-5,17,-6,leaves:0)
B(-5,16,-6,leaves:0)
B(-12,10,6,leaves:0)
B(-5,19,-6,leaves:0)
B(-5,18,-6,leaves:0)
B(-12,12,6,leaves:0)
B(-12,11,6,leaves:0)
B(-12,14,6,leaves:0)
B(-12,13,6,leaves:0)
B(-12,16,6,leaves:0)
B(-12,15,6,leaves:0)
B(-7,8,-3,leaves:0)
B(-12,18,6,leaves:0)
B(-7,9,-3,leaves:0)
B(-12,17,6,leaves:0)
B(3,20,-1,leaves:0)
B(-7,6,-3,leaves:0)
B(-12,19,6,leaves:0)
B(-7,7,-3,leaves:0)
B(-7,5,-3,leaves:0)
B(-9,-4,-3,LOG:12)
B(12,11,-8,leaves:0)
B(-6,11,0,leaves:0)
B(-6,10,0,leaves:0)
B(-8,-4,-2,LOG:12)
B(-7,12,17,leaves:0)
B(-7,13,17,leaves:0)
B(-16,9,4,leaves:0)
B(-16,6,4,leaves:0)
B(-12,8,14,leaves:0)
B(-12,9,14,leaves:0)
B(0,11,-10,leaves:0)
B(0,12,-10,leaves:0)
B(0,13,-10,leaves:0)
B(0,14,-10,leaves:0)
B(0,10,-10,leaves:0)
B(11,20,4,leaves:0)
B(-2,-5,-1,LOG:12)
B(-2,-4,-1,LOG:12)
B(0,16,-10,leaves:0)
B(0,15,-10,leaves:0)
B(-2,-3,-1,LOG:12)
B(-2,-2,-1,LOG:12)
B(-2,-1,-1,LOG:12)
B(1,-3,-5,LOG:12)
B(1,-2,-5,LOG:12)
B(11,18,4,leaves:0)
B(11,17,4,leaves:0)
B(11,16,4,leaves:0)
B(11,14,4,leaves:0)
B(11,13,4,leaves:0)
B(11,12,4,leaves:0)
B(11,11,4,leaves:0)
B(5,20,15,leaves:0)
B(8,13,4,leaves:0)
B(8,14,4,leaves:0)
B(8,12,4,leaves:0)
B(-6,20,0,leaves:0)
B(-6,22,0,leaves:0)
B(-6,21,0,leaves:0)
B(-6,12,0,leaves:0)
B(-6,13,0,leaves:0)
B(-6,14,0,leaves:0)
B(-6,15,0,leaves:0)
B(-6,16,0,leaves:0)
B(-6,17,0,leaves:0)
B(-6,18,0,leaves:0)
B(-6,19,0,leaves:0)
B(-15,10,-5,leaves:0)
B(8,18,4,leaves:0)
B(8,17,4,leaves:0)
B(8,16,4,leaves:0)
B(8,15,4,leaves:0)
B(8,19,4,leaves:0)
B(-9,12,-3,LOG:12)
B(-9,11,-3,leaves:0)
B(-10,-4,-6,LOG:12)
B(-10,-3,-6,LOG:12)
