
#
# +-----------------------------------------------------------------+ #
# |                            BO3 object                           | #
# +-----------------------------------------------------------------+ #
#

Author: NLBlackEagle

Description: Converted version of the BO2 26

Version: 3

SettingsMode: WriteDisable


#
# +-----------------------------------------------------------------+ #
# |                          Main settings                          | #
# +-----------------------------------------------------------------+ #
#

Tree: true

Frequency: 1

Rarity: 100.0

RotateRandomly: true

SpawnHeight: highestSolidBlock

SpawnHeightOffset: 0

SpawnHeightVariance: 0


# Height Limits for the BO3. #


MinHeight: 0

MaxHeight: 85


# Extrusion settings #


ExtrudeMode: None

ExtrudeThroughBlocks: air

MaxBranchDepth: 10

ExcludedBiomes: 


#
# +-----------------------------------------------------------------+ #
# |                      Source block settings                      | #
# +-----------------------------------------------------------------+ #
#

SourceBlocks: AIR,GRASS,DIRT,SAND

MaxPercentageOutsideSourceBlock: 0

OutsideSourceBlock: placeAnyway


#
# +-----------------------------------------------------------------+ #
# |                              Blocks                             | #
# +-----------------------------------------------------------------+ #
#

B(1,19,-4,Leaves:4)
B(0,20,-2,Leaves:4)
B(0,22,-2,Leaves:4)
B(1,18,-4,Leaves:4)
B(0,21,2,Leaves:4)
B(0,22,2,Leaves:4)
B(3,19,-6,Leaves:4)
B(-3,22,0,Leaves:4)
B(4,18,-5,Leaves:4)
B(-3,22,1,Leaves:4)
B(-3,21,1,Leaves:4)
B(-3,20,1,LOG:13)
B(0,16,2,Leaves:4)
B(0,15,-2,Leaves:4)
B(0,12,2,Leaves:4)
B(3,-5,0,LOG:13)
B(3,20,-6,Leaves:4)
B(3,-4,0,LOG:13)
B(3,16,2,Leaves:4)
B(3,17,2,Leaves:4)
B(3,18,2,Leaves:4)
B(0,17,6,leaves:4)
B(3,19,2,Leaves:4)
B(0,19,-2,Leaves:4)
B(0,15,6,leaves:4)
B(0,16,6,leaves:4)
B(1,23,-4,Leaves:4)
B(3,14,2,Leaves:4)
B(0,17,-2,Leaves:4)
B(3,15,2,Leaves:4)
B(0,16,-2,LOG:13)
B(1,25,-4,Leaves:4)
B(1,24,-4,Leaves:4)
B(0,12,6,leaves:4)
B(1,26,-4,Leaves:4)
B(-1,12,5,Leaves:4)
B(3,23,-2,LOG:13)
B(0,18,0,Leaves:4)
B(3,22,-2,LOG:13)
B(3,21,-2,LOG:13)
B(0,16,0,Leaves:4)
B(3,20,-2,LOG:13)
B(3,28,-4,Leaves:4)
B(0,13,0,Leaves:4)
B(3,20,4,leaves:4)
B(0,12,0,Leaves:4)
B(3,26,-4,Leaves:4)
B(-3,16,-3,Leaves:4)
B(3,25,-4,Leaves:4)
B(3,28,-2,LOG:13)
B(3,22,-4,Leaves:4)
B(3,29,-2,LOG:13)
B(3,23,-4,Leaves:4)
B(3,26,-2,Leaves:4)
B(3,20,-4,Leaves:4)
B(3,27,-2,LOG:13)
B(3,24,-2,LOG:13)
B(3,25,-2,LOG:13)
B(3,25,2,Leaves:4)
B(0,21,0,Leaves:4)
B(0,20,0,Leaves:4)
B(4,20,-5,Leaves:4)
B(2,-4,0,LOG:13)
B(3,18,-5,Leaves:4)
B(3,19,-4,Leaves:4)
B(3,19,-5,Leaves:4)
B(2,-3,0,LOG:13)
B(3,11,-2,LOG:13)
B(0,23,0,Leaves:4)
B(0,22,0,Leaves:4)
B(3,18,-4,Leaves:4)
B(0,24,0,Leaves:4)
B(3,17,-2,LOG:13)
B(3,18,-2,LOG:13)
B(3,19,-2,LOG:13)
B(0,19,0,Leaves:4)
B(3,14,-2,LOG:13)
B(3,15,-2,LOG:13)
B(3,16,-2,LOG:13)
B(4,22,1,Leaves:4)
B(6,21,-2,Leaves:4)
B(6,22,-2,Leaves:4)
B(1,0,-1,LOG:13)
B(1,8,-2,LOG:13)
B(-2,21,-6,Leaves:4)
B(1,9,-2,LOG:13)
B(1,3,-1,LOG:13)
B(1,6,-2,LOG:13)
B(1,4,-1,LOG:13)
B(1,7,-2,LOG:13)
B(1,1,-1,LOG:13)
B(1,4,-2,LOG:13)
B(1,2,-1,LOG:13)
B(1,5,-2,LOG:13)
B(1,2,-2,LOG:13)
B(1,7,-1,LOG:13)
B(-2,21,0,Leaves:4)
B(6,20,1,Leaves:4)
B(1,3,-2,LOG:13)
B(1,8,-1,LOG:13)
B(-2,20,0,Leaves:4)
B(1,0,-2,LOG:13)
B(1,5,-1,LOG:13)
B(1,1,-2,LOG:13)
B(1,6,-1,LOG:13)
B(1,9,-1,LOG:13)
B(4,22,0,Leaves:4)
B(4,21,0,Leaves:4)
B(6,21,1,Leaves:4)
B(4,27,0,Leaves:4)
B(3,16,0,Leaves:4)
B(3,17,0,Leaves:4)
B(-2,19,0,Leaves:4)
B(3,15,0,Leaves:4)
B(-2,18,0,Leaves:4)
B(6,16,-2,Leaves:4)
B(5,21,2,Leaves:4)
B(6,14,-2,LOG:13)
B(3,18,0,Leaves:4)
B(6,15,-2,Leaves:4)
B(-2,17,-3,Leaves:4)
B(-2,16,-3,Leaves:4)
B(3,13,0,Leaves:4)
B(-2,15,-3,Leaves:4)
B(0,20,-5,Leaves:4)
B(4,19,0,Leaves:4)
B(3,17,4,Leaves:4)
B(3,16,4,Leaves:4)
B(5,20,2,Leaves:4)
B(3,-8,2,LOG:13)
B(4,16,0,Leaves:4)
B(0,24,-5,Leaves:4)
B(4,17,0,Leaves:4)
B(0,25,-5,Leaves:4)
B(4,18,0,Leaves:4)
B(-3,18,-1,Leaves:4)
B(-3,17,-1,Leaves:4)
B(0,19,-5,Leaves:4)
B(3,16,6,leaves:4)
B(3,17,6,leaves:4)
B(5,16,-4,Leaves:4)
B(5,15,-4,Leaves:4)
B(5,18,-4,Leaves:4)
B(5,17,-4,Leaves:4)
B(1,12,5,Leaves:4)
B(1,15,5,Leaves:4)
B(1,16,5,Leaves:4)
B(-1,20,-7,Leaves:4)
B(-3,17,-2,Leaves:4)
B(8,22,-1,Leaves:4)
B(1,18,5,Leaves:4)
B(-3,16,-2,Leaves:4)
B(3,-8,-4,LOG:13)
B(5,18,-6,Leaves:4)
B(2,-3,-1,LOG:13)
B(0,20,-8,Leaves:4)
B(0,21,-8,Leaves:4)
B(-3,16,-4,Leaves:4)
B(2,-2,-1,LOG:13)
B(2,-1,-1,LOG:13)
B(3,19,3,Leaves:4)
B(2,24,-1,LOG:13)
B(3,19,-1,Leaves:4)
B(2,25,-1,Leaves:4)
B(3,18,-1,Leaves:4)
B(2,26,-1,Leaves:4)
B(3,17,-1,Leaves:4)
B(3,16,-1,Leaves:4)
B(2,28,-1,Leaves:4)
B(3,14,3,Leaves:4)
B(3,15,-1,Leaves:4)
B(2,29,-1,Leaves:4)
B(3,13,-1,Leaves:4)
B(3,16,3,Leaves:4)
B(3,15,3,Leaves:4)
B(2,21,-1,Leaves:4)
B(5,19,-2,Leaves:4)
B(2,20,-1,LOG:13)
B(2,23,-1,Leaves:4)
B(2,22,-1,Leaves:4)
B(5,15,-2,Leaves:4)
B(5,18,-2,Leaves:4)
B(5,14,-2,Leaves:4)
B(5,21,-2,Leaves:4)
B(1,18,-1,LOG:13)
B(1,19,-1,Leaves:4)
B(1,14,-1,LOG:13)
B(1,15,-1,Leaves:4)
B(1,16,-1,Leaves:4)
B(0,12,4,Leaves:4)
B(1,17,-1,Leaves:4)
B(-1,17,-3,Leaves:4)
B(3,20,3,Leaves:4)
B(0,16,4,Leaves:4)
B(-2,20,-2,Leaves:4)
B(-2,21,-2,Leaves:4)
B(-1,16,-3,Leaves:4)
B(2,30,-1,Leaves:4)
B(-1,21,-3,Leaves:4)
B(-1,20,-3,Leaves:4)
B(2,16,7,leaves:4)
B(-2,16,-2,Leaves:4)
B(-2,15,-2,Leaves:4)
B(5,28,-2,Leaves:4)
B(1,11,-1,Leaves:4)
B(5,29,-2,Leaves:4)
B(1,10,-1,LOG:13)
B(5,26,-2,Leaves:4)
B(1,13,-1,Leaves:4)
B(5,27,-2,LOG:13)
B(5,19,0,Leaves:4)
B(1,12,-1,Leaves:4)
B(5,22,-2,Leaves:4)
B(2,17,-3,LOG:13)
B(2,18,-3,Leaves:4)
B(7,22,1,Leaves:4)
B(7,21,0,Leaves:4)
B(2,16,3,Leaves:4)
B(2,17,3,Leaves:4)
B(2,15,3,Leaves:4)
B(2,12,3,Leaves:4)
B(1,-2,-2,LOG:13)
B(2,13,3,Leaves:4)
B(1,-1,-2,LOG:13)
B(6,21,0,Leaves:4)
B(6,20,0,Leaves:4)
B(5,18,2,Leaves:4)
B(5,19,2,Leaves:4)
B(5,21,0,Leaves:4)
B(5,20,0,Leaves:4)
B(7,16,-2,Leaves:4)
B(2,-4,-2,LOG:13)
B(2,-5,-2,LOG:13)
B(7,20,0,Leaves:4)
B(3,27,0,Leaves:4)
B(7,21,1,Leaves:4)
B(1,21,-8,Leaves:4)
B(2,13,-3,LOG:13)
B(2,-1,-2,LOG:13)
B(3,26,0,Leaves:4)
B(2,-2,-2,LOG:13)
B(3,25,0,Leaves:4)
B(2,-3,-2,LOG:13)
B(0,4,-1,LOG:13)
B(2,19,-1,LOG:13)
B(2,21,-7,Leaves:4)
B(4,17,-3,LOG:13)
B(2,17,-1,LOG:13)
B(2,18,-1,LOG:13)
B(4,15,-3,Leaves:4)
B(2,15,-1,LOG:13)
B(4,16,-3,Leaves:4)
B(2,16,-1,LOG:13)
B(-1,16,7,leaves:4)
B(5,17,4,Leaves:4)
B(5,18,4,Leaves:4)
B(2,13,-1,LOG:13)
B(2,14,-1,LOG:13)
B(2,12,-1,Leaves:4)
B(2,11,-1,LOG:13)
B(2,10,-1,LOG:13)
B(2,13,4,Leaves:4)
B(1,18,0,Leaves:4)
B(0,25,-6,Leaves:4)
B(4,27,-3,Leaves:4)
B(0,24,-6,Leaves:4)
B(2,15,4,Leaves:4)
B(1,16,0,Leaves:4)
B(2,16,4,Leaves:4)
B(1,17,0,Leaves:4)
B(-2,20,2,Leaves:4)
B(4,28,-3,Leaves:4)
B(1,15,0,Leaves:4)
B(1,12,0,Leaves:4)
B(-1,19,-1,Leaves:4)
B(1,13,0,Leaves:4)
B(2,12,4,Leaves:4)
B(-1,18,-1,Leaves:4)
B(1,11,0,Leaves:4)
B(-1,17,-1,Leaves:4)
B(4,22,-1,Leaves:4)
B(2,17,4,Leaves:4)
B(4,28,-1,Leaves:4)
B(2,18,4,Leaves:4)
B(4,27,-1,Leaves:4)
B(0,20,-6,Leaves:4)
B(4,26,-1,Leaves:4)
B(-1,20,-1,Leaves:4)
B(-2,19,2,Leaves:4)
B(4,20,-1,LOG:13)
B(4,21,-1,Leaves:4)
B(-2,12,2,Leaves:4)
B(4,20,-3,Leaves:4)
B(4,21,-3,Leaves:4)
B(4,22,-3,Leaves:4)
B(4,23,-3,Leaves:4)
B(-2,20,-1,Leaves:4)
B(0,19,-6,Leaves:4)
B(0,18,-6,Leaves:4)
B(1,-5,-1,LOG:13)
B(1,-6,-1,LOG:13)
B(1,-1,-1,LOG:13)
B(1,-2,-1,LOG:13)
B(3,30,-2,LOG:13)
B(-1,10,-1,LOG:13)
B(2,24,1,Leaves:4)
B(-2,21,2,Leaves:4)
B(-2,15,-1,Leaves:4)
B(2,26,1,Leaves:4)
B(2,25,1,Leaves:4)
B(-2,17,-1,Leaves:4)
B(4,20,4,leaves:4)
B(2,10,-2,LOG:13)
B(2,11,-2,LOG:13)
B(2,12,-2,LOG:13)
B(2,-2,-3,LOG:13)
B(2,13,-2,LOG:13)
B(2,-6,-3,LOG:13)
B(2,19,-2,LOG:13)
B(2,11,1,Leaves:4)
B(2,7,-3,LOG:13)
B(6,16,-4,Leaves:4)
B(2,18,-2,LOG:13)
B(6,19,-4,Leaves:4)
B(2,13,1,Leaves:4)
B(2,12,1,Leaves:4)
B(2,15,-2,LOG:13)
B(2,14,-2,LOG:13)
B(6,15,-4,Leaves:4)
B(2,17,-2,LOG:13)
B(2,16,-2,LOG:13)
B(2,18,1,Leaves:4)
B(2,15,1,Leaves:4)
B(2,14,1,Leaves:4)
B(2,17,1,Leaves:4)
B(1,23,0,Leaves:4)
B(3,24,-1,Leaves:4)
B(3,25,-1,Leaves:4)
B(1,26,0,Leaves:4)
B(3,26,-1,Leaves:4)
B(1,27,0,Leaves:4)
B(3,28,-1,Leaves:4)
B(4,19,-1,Leaves:4)
B(3,29,-1,Leaves:4)
B(2,23,-2,LOG:13)
B(4,16,-1,Leaves:4)
B(2,24,-2,LOG:13)
B(4,15,-1,Leaves:4)
B(2,21,-2,LOG:13)
B(4,18,-1,Leaves:4)
B(2,22,-2,LOG:13)
B(0,-8,0,LOG:13)
B(1,20,0,Leaves:4)
B(2,20,-2,LOG:13)
B(4,11,-1,LOG:13)
B(1,21,0,Leaves:4)
B(1,22,0,Leaves:4)
B(2,9,-2,LOG:13)
B(2,1,-1,LOG:13)
B(2,29,-2,Leaves:4)
B(2,0,-1,LOG:13)
B(2,28,-2,Leaves:4)
B(2,3,-1,LOG:13)
B(2,6,-2,LOG:13)
B(2,27,-2,LOG:13)
B(2,2,-1,LOG:13)
B(2,5,-2,LOG:13)
B(2,26,-2,LOG:13)
B(2,5,-1,LOG:13)
B(2,8,-2,LOG:13)
B(2,25,-2,Leaves:4)
B(2,4,-1,LOG:13)
B(2,7,-2,LOG:13)
B(2,2,-2,LOG:13)
B(2,7,-1,LOG:13)
B(4,17,5,leaves:4)
B(-2,21,-5,Leaves:4)
B(2,1,-2,LOG:13)
B(2,6,-1,LOG:13)
B(4,16,5,leaves:4)
B(2,4,-2,LOG:13)
B(2,9,-1,LOG:13)
B(2,3,-2,LOG:13)
B(2,8,-1,LOG:13)
B(3,20,-1,LOG:13)
B(4,17,4,Leaves:4)
B(7,21,2,Leaves:4)
B(2,0,-2,LOG:13)
B(3,21,-1,Leaves:4)
B(4,16,4,Leaves:4)
B(1,24,-3,Leaves:4)
B(1,23,-3,Leaves:4)
B(1,26,-3,Leaves:4)
B(1,19,2,Leaves:4)
B(1,11,3,Leaves:4)
B(1,15,1,Leaves:4)
B(1,25,-3,Leaves:4)
B(1,12,3,Leaves:4)
B(1,16,1,Leaves:4)
B(1,16,2,Leaves:4)
B(1,18,1,Leaves:4)
B(1,22,-3,Leaves:4)
B(1,19,1,Leaves:4)
B(1,21,-3,Leaves:4)
B(1,12,2,Leaves:4)
B(1,11,2,Leaves:4)
B(1,17,3,Leaves:4)
B(1,18,3,Leaves:4)
B(1,11,1,LOG:13)
B(1,12,1,Leaves:4)
B(1,16,6,leaves:4)
B(1,15,6,leaves:4)
B(1,14,6,leaves:4)
B(6,20,3,Leaves:4)
B(0,20,-7,Leaves:4)
B(0,12,3,Leaves:4)
B(0,-8,-3,LOG:13)
B(1,30,-2,Leaves:4)
B(1,27,1,Leaves:4)
B(0,13,3,Leaves:4)
B(1,24,1,Leaves:4)
B(1,21,1,Leaves:4)
B(5,17,3,Leaves:4)
B(5,18,3,Leaves:4)
B(8,22,0,Leaves:4)
B(3,17,7,leaves:4)
B(5,19,3,Leaves:4)
B(2,21,-4,Leaves:4)
B(2,22,-4,Leaves:4)
B(2,25,-4,Leaves:4)
B(2,26,-4,Leaves:4)
B(2,23,-4,Leaves:4)
B(8,21,0,Leaves:4)
B(6,14,-3,Leaves:4)
B(6,13,-3,Leaves:4)
B(3,-7,-3,LOG:13)
B(6,15,-3,Leaves:4)
B(2,17,-4,Leaves:4)
B(2,18,-4,Leaves:4)
B(5,16,6,leaves:4)
B(5,17,6,leaves:4)
B(5,15,6,leaves:4)
B(0,20,1,Leaves:4)
B(1,18,-3,Leaves:4)
B(1,19,-3,Leaves:4)
B(0,22,1,Leaves:4)
B(0,21,1,Leaves:4)
B(2,21,-3,LOG:13)
B(2,24,-3,LOG:13)
B(2,25,-3,Leaves:4)
B(2,22,-3,Leaves:4)
B(-1,15,-2,Leaves:4)
B(-1,12,2,Leaves:4)
B(-1,11,2,Leaves:4)
B(3,6,-2,LOG:13)
B(-1,17,-2,Leaves:4)
B(-1,16,-2,Leaves:4)
B(-4,17,-2,Leaves:4)
B(5,17,5,leaves:4)
B(5,18,5,leaves:4)
B(4,19,-6,Leaves:4)
B(4,18,-6,Leaves:4)
B(4,16,6,leaves:4)
B(0,11,1,Leaves:4)
B(4,15,6,leaves:4)
B(-1,20,-2,Leaves:4)
B(5,16,5,leaves:4)
B(2,29,-3,Leaves:4)
B(2,28,-3,Leaves:4)
B(2,27,-3,Leaves:4)
B(0,12,1,Leaves:4)
B(0,13,1,Leaves:4)
B(0,19,1,Leaves:4)
B(0,16,1,Leaves:4)
B(0,17,1,Leaves:4)
B(-1,20,-5,Leaves:4)
B(5,26,-3,Leaves:4)
B(5,27,-3,Leaves:4)
B(5,28,-3,Leaves:4)
B(2,17,5,leaves:4)
B(2,16,5,leaves:4)
B(2,15,5,Leaves:4)
B(2,13,5,Leaves:4)
B(2,12,5,Leaves:4)
B(7,22,-1,Leaves:4)
B(7,21,-1,Leaves:4)
B(2,18,2,Leaves:4)
B(2,16,2,Leaves:4)
B(2,15,2,Leaves:4)
B(1,30,-1,Leaves:4)
B(2,19,2,Leaves:4)
B(5,16,-3,Leaves:4)
B(-1,20,-4,Leaves:4)
B(5,18,-3,Leaves:4)
B(1,22,-2,Leaves:4)
B(4,14,-2,LOG:13)
B(1,21,-2,Leaves:4)
B(2,14,2,Leaves:4)
B(2,13,2,Leaves:4)
B(2,12,2,Leaves:4)
B(5,15,-3,Leaves:4)
B(5,15,-1,Leaves:4)
B(-1,17,-4,Leaves:4)
B(1,28,-2,Leaves:4)
B(1,29,-2,Leaves:4)
B(1,26,-2,Leaves:4)
B(5,13,-1,Leaves:4)
B(3,26,1,Leaves:4)
B(3,27,1,Leaves:4)
B(5,19,-1,Leaves:4)
B(1,21,-1,Leaves:4)
B(2,26,2,Leaves:4)
B(1,22,-1,Leaves:4)
B(1,20,-1,LOG:13)
B(1,12,-2,LOG:13)
B(1,11,-2,LOG:13)
B(1,14,-2,LOG:13)
B(1,13,-2,LOG:13)
B(1,10,-2,LOG:13)
B(1,19,-2,Leaves:4)
B(1,15,-2,LOG:13)
B(1,16,-2,LOG:13)
B(1,-7,-3,LOG:13)
B(1,17,-2,LOG:13)
B(1,18,-2,LOG:13)
B(1,29,-1,Leaves:4)
B(3,16,1,Leaves:4)
B(5,18,-5,Leaves:4)
B(3,17,1,Leaves:4)
B(3,18,1,Leaves:4)
B(1,26,-1,Leaves:4)
B(1,28,-1,Leaves:4)
B(5,17,-5,Leaves:4)
B(5,16,-5,Leaves:4)
B(6,19,-6,Leaves:4)
B(6,18,-5,Leaves:4)
B(6,19,-5,Leaves:4)
B(1,16,7,leaves:4)
B(5,21,-1,Leaves:4)
B(5,22,-1,Leaves:4)
B(2,23,-5,Leaves:4)
B(2,22,-5,Leaves:4)
B(2,24,-5,Leaves:4)
B(2,27,-5,Leaves:4)
B(0,-7,-1,LOG:13)
B(0,16,7,leaves:4)
B(5,20,-1,Leaves:4)
B(0,15,7,leaves:4)
B(1,27,-5,Leaves:4)
B(1,22,-5,Leaves:4)
B(1,24,-5,Leaves:4)
B(1,23,-5,Leaves:4)
B(0,20,-4,Leaves:4)
B(4,28,-4,Leaves:4)
B(4,29,-4,Leaves:4)
B(2,19,-6,Leaves:4)
B(2,18,-6,Leaves:4)
B(0,20,-3,Leaves:4)
B(0,27,-4,Leaves:4)
B(-4,17,-1,Leaves:4)
B(0,26,-4,Leaves:4)
B(0,22,-3,Leaves:4)
B(-4,18,-1,Leaves:4)
B(0,25,-4,Leaves:4)
B(0,24,-4,Leaves:4)
B(0,27,-3,Leaves:4)
B(2,19,-5,Leaves:4)
B(-1,12,3,Leaves:4)
B(2,17,-5,Leaves:4)
B(2,18,-5,Leaves:4)
B(4,20,-4,Leaves:4)
B(2,17,-6,Leaves:4)
B(7,15,-3,Leaves:4)
B(4,24,-4,Leaves:4)
B(4,23,-4,Leaves:4)
B(4,16,-4,Leaves:4)
B(4,17,-4,Leaves:4)
B(3,-7,1,LOG:13)
B(3,-6,1,LOG:13)
B(4,18,-4,Leaves:4)
B(4,17,3,Leaves:4)
B(2,20,-6,Leaves:4)
B(-1,21,2,Leaves:4)
B(-1,22,3,Leaves:4)
B(0,19,-4,Leaves:4)
B(2,25,-6,Leaves:4)
B(2,23,-6,LOG:13)
B(2,24,-6,Leaves:4)
B(4,19,3,Leaves:4)
B(-1,20,-6,Leaves:4)
B(4,18,3,Leaves:4)
B(4,6,-1,LOG:13)
B(-4,18,-3,Leaves:4)
B(3,21,-3,Leaves:4)
B(3,22,-3,Leaves:4)
B(-1,11,5,Leaves:4)
B(1,18,-6,Leaves:4)
B(1,20,-7,Leaves:4)
B(1,19,-6,Leaves:4)
B(1,21,-7,Leaves:4)
B(1,16,4,Leaves:4)
B(-2,21,1,Leaves:4)
B(-2,20,1,Leaves:4)
B(5,22,1,Leaves:4)
B(5,20,1,Leaves:4)
B(5,21,1,Leaves:4)
B(3,28,-3,Leaves:4)
B(1,14,4,Leaves:4)
B(3,27,-3,Leaves:4)
B(1,15,4,Leaves:4)
B(3,26,-3,Leaves:4)
B(1,25,-7,Leaves:4)
B(1,12,4,Leaves:4)
B(3,25,-3,Leaves:4)
B(0,12,5,Leaves:4)
B(0,16,-1,Leaves:4)
B(0,13,5,Leaves:4)
B(-2,16,-4,Leaves:4)
B(0,18,-1,Leaves:4)
B(-2,15,-4,Leaves:4)
B(0,15,5,Leaves:4)
B(0,17,-1,Leaves:4)
B(1,20,-6,Leaves:4)
B(0,19,-1,Leaves:4)
B(-2,17,-4,Leaves:4)
B(6,20,2,Leaves:4)
B(-1,13,0,Leaves:4)
B(1,24,-6,Leaves:4)
B(6,16,6,leaves:4)
B(1,22,-6,Leaves:4)
B(1,23,-6,Leaves:4)
B(3,20,-5,Leaves:4)
B(-1,18,0,Leaves:4)
B(3,25,-5,Leaves:4)
B(-1,19,0,Leaves:4)
B(0,16,5,Leaves:4)
B(0,17,5,Leaves:4)
B(3,23,-5,Leaves:4)
B(6,20,-1,Leaves:4)
B(3,24,-5,Leaves:4)
B(6,21,-1,Leaves:4)
B(5,19,1,Leaves:4)
B(0,10,-1,LOG:13)
B(-1,12,4,Leaves:4)
B(3,17,5,leaves:4)
B(3,16,5,leaves:4)
B(0,17,-3,Leaves:4)
B(6,19,-1,Leaves:4)
B(-1,20,0,Leaves:4)
B(2,16,6,leaves:4)
B(1,19,-5,Leaves:4)
B(2,17,6,leaves:4)
B(2,18,6,leaves:4)
B(1,18,-5,Leaves:4)
B(2,15,0,Leaves:4)
B(2,16,0,Leaves:4)
B(2,13,0,Leaves:4)
B(2,14,0,LOG:13)
B(0,18,-7,Leaves:4)
B(2,17,0,Leaves:4)
B(0,19,-7,Leaves:4)
B(0,24,-1,Leaves:4)
B(0,22,-1,Leaves:4)
B(0,23,-1,Leaves:4)
B(2,11,0,Leaves:4)
B(0,21,-1,Leaves:4)
B(2,12,0,Leaves:4)
B(4,17,1,Leaves:4)
B(4,19,1,Leaves:4)
B(4,18,1,Leaves:4)
B(4,16,7,leaves:4)
B(2,24,0,Leaves:4)
B(4,18,2,Leaves:4)
B(-2,12,1,Leaves:4)
B(2,25,0,Leaves:4)
B(4,17,2,Leaves:4)
B(2,26,0,Leaves:4)
B(4,19,2,Leaves:4)
B(-2,13,1,Leaves:4)
B(-2,19,1,Leaves:4)
B(3,17,-3,Leaves:4)
B(3,19,-3,Leaves:4)
B(1,19,-7,LOG:13)
B(3,18,-3,Leaves:4)
B(4,16,2,Leaves:4)
B(2,23,0,Leaves:4)

#
# +-----------------------------------------------------------------+ #
# |                            BO3 checks                           | #
# +-----------------------------------------------------------------+ #
#

BlockCheck(0,-2,0,Solid)
BlockCheck(0,-1,0,grass,dirt)
BlockCheck(0,-1,0,Solid)
BlockCheckNot(0,-1,0,air)

#
# +-----------------------------------------------------------------+ #
# |                             Branches                            | #
# +-----------------------------------------------------------------+ #
#

