
#
# +-----------------------------------------------------------------+ #
# |                            BO3 object                           | #
# +-----------------------------------------------------------------+ #
#

Author: NLBlackEagle

Description: Converted version of the BO2 37

Version: 3

SettingsMode: WriteDisable


#
# +-----------------------------------------------------------------+ #
# |                          Main settings                          | #
# +-----------------------------------------------------------------+ #
#

Tree: true

Frequency: 1

Rarity: 100.0

RotateRandomly: true

SpawnHeight: highestSolidBlock

SpawnHeightOffset: 0

SpawnHeightVariance: 0


# Height Limits for the BO3. #


MinHeight: 0

MaxHeight: 199


# Extrusion settings #


ExtrudeMode: None

ExtrudeThroughBlocks: air

MaxBranchDepth: 10

ExcludedBiomes: 


#
# +-----------------------------------------------------------------+ #
# |                      Source block settings                      | #
# +-----------------------------------------------------------------+ #
#

SourceBlocks: AIR,GRASS,DIRT,SAND

MaxPercentageOutsideSourceBlock: 0

OutsideSourceBlock: placeAnyway


#
# +-----------------------------------------------------------------+ #
# |                              Blocks                             | #
# +-----------------------------------------------------------------+ #
#

B(8,20,-4,leaves:1)
B(0,20,-2,leaves:1)
B(0,21,-2,leaves:1)
B(0,52,-4,leaves:1)
B(0,53,-4,leaves:1)
B(0,50,-4,leaves:1)
B(0,51,-4,leaves:1)
B(0,16,-12,leaves:1)
B(0,15,-12,leaves:1)
B(0,14,-12,leaves:1)
B(1,32,-13,leaves:1)
B(-1,-1,-1,LOG:12)
B(1,31,-13,leaves:1)
B(-1,-2,-1,LOG:12)
B(1,30,-13,leaves:1)
B(1,36,-13,leaves:1)
B(1,35,-13,leaves:1)
B(1,34,-13,leaves:1)
B(8,21,-4,leaves:1)
B(1,33,-13,leaves:1)
B(-1,1,0,leaves:2)
B(-1,2,0,leaves:2)
B(3,27,-6,leaves:1)
B(7,54,-6,leaves:1)
B(3,26,-6,leaves:1)
B(7,55,-6,leaves:1)
B(3,25,-6,leaves:1)
B(7,56,-6,leaves:1)
B(3,24,-6,leaves:1)
B(-1,29,-7,leaves:1)
B(-1,28,-7,leaves:1)
B(-1,35,-7,leaves:1)
B(7,58,-6,leaves:1)
B(-1,33,-7,leaves:1)
B(7,57,-6,leaves:1)
B(-1,34,-7,leaves:1)
B(8,19,-4,leaves:1)
B(-1,31,-7,leaves:1)
B(3,28,-6,leaves:1)
B(7,59,-6,leaves:1)
B(-1,32,-7,leaves:1)
B(3,29,-6,leaves:1)
B(0,19,-2,leaves:1)
B(-1,30,-7,leaves:1)
B(0,18,-2,leaves:1)
B(0,17,-2,leaves:1)
B(0,16,-2,leaves:1)
B(1,60,-5,leaves:1)
B(-12,13,2,leaves:1)
B(-3,58,-5,leaves:1)
B(-3,57,-5,leaves:1)
B(1,61,-5,leaves:1)
B(-3,59,-5,leaves:1)
B(0,40,-4,leaves:1)
B(0,41,-4,leaves:1)
B(0,42,-4,leaves:1)
B(3,18,-5,leaves:1)
B(-3,56,-5,leaves:1)
B(3,19,-5,leaves:1)
B(3,16,-5,leaves:1)
B(3,17,-5,leaves:1)
B(3,15,-5,leaves:1)
B(6,46,0,leaves:1)
B(6,47,0,leaves:1)
B(6,48,0,leaves:1)
B(6,49,0,leaves:1)
B(1,9,-4,leaves:1)
B(-7,10,-7,leaves:1)
B(-7,11,-7,leaves:1)
B(-3,26,-5,leaves:1)
B(-3,24,-5,leaves:1)
B(-3,25,-5,leaves:1)
B(-3,28,-5,leaves:1)
B(-1,17,-7,leaves:1)
B(-1,18,-7,leaves:1)
B(-1,19,-7,leaves:1)
B(-3,23,-5,leaves:1)
B(-3,22,-5,leaves:1)
B(3,2,1,leaves:2)
B(3,0,1,LOG:12)
B(3,1,1,leaves:2)
B(15,15,-5,leaves:1)
B(-1,16,-17,leaves:1)
B(-1,21,-7,leaves:1)
B(-1,20,-7,leaves:1)
B(-1,23,-7,leaves:1)
B(-1,22,-7,leaves:1)
B(-1,25,-7,leaves:1)
B(-1,24,-7,leaves:1)
B(-1,27,-7,leaves:1)
B(-1,26,-7,leaves:1)
B(1,50,-8,leaves:1)
B(3,44,-6,leaves:1)
B(3,45,-6,leaves:1)
B(1,52,-8,leaves:1)
B(3,42,-6,leaves:1)
B(-3,10,-5,leaves:1)
B(1,51,-8,leaves:1)
B(3,43,-6,leaves:1)
B(1,53,-8,leaves:1)
B(6,52,0,leaves:1)
B(6,51,0,leaves:1)
B(6,50,0,leaves:1)
B(3,40,-6,leaves:1)
B(3,41,-6,leaves:1)
B(15,14,-5,leaves:1)
B(2,-4,-1,LOG:12)
B(15,13,-5,leaves:1)
B(2,-3,-1,LOG:12)
B(15,12,-5,leaves:1)
B(2,-6,-1,LOG:12)
B(2,-5,-1,LOG:12)
B(2,-2,-1,LOG:12)
B(2,-1,-1,LOG:12)
B(0,18,-12,leaves:1)
B(0,17,-12,leaves:1)
B(0,19,-12,leaves:1)
B(2,-7,-1,LOG:12)
B(5,40,-3,leaves:1)
B(2,6,0,LOG:12)
B(5,41,-3,leaves:1)
B(5,42,-3,leaves:1)
B(5,43,-3,leaves:1)
B(5,44,-3,leaves:1)
B(2,29,-1,leaves:1)
B(5,25,-11,leaves:1)
B(5,24,-11,leaves:1)
B(5,26,-11,leaves:1)
B(0,9,-3,leaves:1)
B(1,47,-8,leaves:1)
B(1,48,-8,leaves:1)
B(1,49,-8,leaves:1)
B(4,28,5,leaves:1)
B(5,45,-3,leaves:1)
B(-3,0,-3,LOG:12)
B(0,1,-3,LOG:12)
B(0,0,-3,LOG:12)
B(5,23,-11,leaves:1)
B(5,22,-11,leaves:1)
B(7,45,2,leaves:1)
B(1,7,-11,leaves:1)
B(7,47,2,leaves:1)
B(1,8,-11,leaves:1)
B(4,32,5,leaves:1)
B(1,9,-11,leaves:1)
B(2,30,-1,leaves:1)
B(2,34,-1,leaves:1)
B(2,33,-1,leaves:1)
B(2,32,-1,leaves:1)
B(5,39,-11,leaves:1)
B(2,31,-1,leaves:1)
B(0,9,-7,leaves:1)
B(1,32,-10,leaves:1)
B(1,16,-10,leaves:1)
B(-3,-6,-5,LOG:12)
B(1,17,-10,leaves:1)
B(-3,-4,-5,LOG:12)
B(1,18,-10,leaves:1)
B(-3,-3,-5,LOG:12)
B(1,19,-10,leaves:1)
B(10,34,-5,leaves:1)
B(-10,33,-2,leaves:1)
B(-3,-2,-5,LOG:12)
B(-10,32,-2,leaves:1)
B(-10,31,-2,leaves:1)
B(-10,30,-2,leaves:1)
B(10,30,-5,leaves:1)
B(10,31,-5,leaves:1)
B(10,32,-5,leaves:1)
B(-10,34,-2,leaves:1)
B(10,33,-5,leaves:1)
B(2,-4,1,LOG:12)
B(2,-5,1,LOG:12)
B(2,-6,1,LOG:12)
B(2,-1,1,LOG:12)
B(2,-2,1,LOG:12)
B(2,-3,1,LOG:12)
B(5,43,-11,leaves:1)
B(1,20,-10,leaves:1)
B(5,42,-11,leaves:1)
B(1,20,-8,leaves:1)
B(1,21,-8,leaves:1)
B(5,41,-11,leaves:1)
B(5,40,-11,leaves:1)
B(-7,42,-7,leaves:1)
B(-7,40,-7,leaves:1)
B(-7,41,-7,leaves:1)
B(-2,-5,-5,LOG:12)
B(-2,-4,-5,LOG:12)
B(2,17,-1,leaves:1)
B(2,15,-1,LOG:12)
B(-2,-1,-5,LOG:12)
B(2,16,-1,LOG:12)
B(2,13,-1,LOG:12)
B(-2,-3,-5,LOG:12)
B(2,14,-1,LOG:12)
B(1,15,-8,leaves:1)
B(2,12,-1,LOG:12)
B(1,16,-8,leaves:1)
B(2,11,-1,LOG:12)
B(2,10,-1,LOG:12)
B(1,19,-8,leaves:1)
B(5,1,-2,Leaves:4)
B(1,17,-8,leaves:1)
B(1,18,-8,leaves:1)
B(2,2,0,LOG:12)
B(-7,39,-7,leaves:1)
B(1,10,-10,leaves:1)
B(2,3,0,LOG:12)
B(2,4,0,LOG:12)
B(2,5,0,LOG:12)
B(1,15,-10,leaves:1)
B(1,14,-10,leaves:1)
B(5,9,-2,leaves:1)
B(2,1,0,leaves:2)
B(-1,9,-4,LOG:12)
B(-1,8,-4,LOG:12)
B(-1,7,-4,LOG:12)
B(-1,6,-4,LOG:12)
B(-1,5,-4,LOG:12)
B(-1,4,-4,LOG:12)
B(-1,3,-4,LOG:12)
B(-1,2,-4,LOG:12)
B(-1,16,-1,leaves:1)
B(-1,15,-1,leaves:1)
B(-5,20,2,leaves:1)
B(0,-4,-2,LOG:12)
B(2,20,1,leaves:1)
B(1,34,-17,leaves:1)
B(2,21,1,leaves:1)
B(1,-1,2,LOG:12)
B(0,-1,-2,LOG:12)
B(-10,15,1,leaves:1)
B(-10,14,1,leaves:1)
B(-10,13,1,leaves:1)
B(-2,13,-5,LOG:12)
B(2,19,1,leaves:1)
B(-2,12,-5,leaves:1)
B(2,18,1,leaves:1)
B(-2,11,-5,LOG:12)
B(-2,10,-5,leaves:1)
B(2,15,1,leaves:1)
B(2,17,1,leaves:1)
B(2,41,-1,leaves:1)
B(2,16,1,leaves:1)
B(-2,18,-5,LOG:12)
B(-2,14,-5,LOG:12)
B(-2,15,-5,leaves:1)
B(-2,16,-5,leaves:1)
B(-2,17,-5,LOG:12)
B(3,19,8,leaves:1)
B(3,18,8,leaves:1)
B(4,-1,-3,LOG:12)
B(3,17,8,leaves:1)
B(-1,27,-1,leaves:1)
B(4,-2,-3,LOG:12)
B(3,16,8,leaves:1)
B(-1,29,-1,leaves:1)
B(-1,28,-1,leaves:1)
B(-10,16,1,leaves:1)
B(-10,17,1,leaves:1)
B(-10,18,1,leaves:1)
B(2,7,-1,LOG:12)
B(2,6,-1,LOG:12)
B(2,9,-1,LOG:12)
B(-2,24,-5,leaves:1)
B(2,8,-1,LOG:12)
B(-2,23,-5,leaves:1)
B(-4,21,0,leaves:1)
B(-1,-2,-2,LOG:12)
B(-1,-3,-2,LOG:12)
B(-1,-6,-2,LOG:12)
B(3,7,-3,LOG:12)
B(3,8,-3,LOG:12)
B(3,5,-3,LOG:12)
B(3,6,-3,LOG:12)
B(5,24,-10,leaves:1)
B(5,23,-10,leaves:1)
B(3,9,-3,LOG:12)
B(5,26,-10,leaves:1)
B(5,25,-10,leaves:1)
B(3,0,-3,LOG:12)
B(5,22,-10,leaves:1)
B(3,3,-3,LOG:12)
B(3,4,-3,LOG:12)
B(3,1,-3,LOG:12)
B(3,2,-3,LOG:12)
B(-2,32,-5,leaves:1)
B(-2,33,-5,leaves:1)
B(-2,34,-5,leaves:1)
B(0,-3,-3,LOG:12)
B(0,-6,-3,LOG:12)
B(0,-5,-3,LOG:12)
B(-4,19,0,leaves:1)
B(-4,18,0,leaves:1)
B(11,32,-6,leaves:1)
B(11,33,-6,leaves:1)
B(12,35,-6,leaves:1)
B(12,36,-6,leaves:1)
B(12,33,-6,leaves:1)
B(12,34,-6,leaves:1)
B(12,31,-6,leaves:1)
B(12,32,-6,leaves:1)
B(0,-1,-3,LOG:12)
B(12,30,-6,leaves:1)
B(0,-2,-3,LOG:12)
B(11,34,-6,leaves:1)
B(-2,26,-5,leaves:1)
B(11,35,-6,leaves:1)
B(-4,20,0,leaves:1)
B(-2,25,-5,leaves:1)
B(11,36,-6,leaves:1)
B(11,37,-6,leaves:1)
B(15,32,-6,leaves:1)
B(15,30,-6,leaves:1)
B(7,49,-7,leaves:1)
B(7,47,-7,leaves:1)
B(7,48,-7,leaves:1)
B(5,-1,-1,LOG:12)
B(-2,59,-5,leaves:1)
B(5,40,-10,leaves:1)
B(-2,58,-5,leaves:1)
B(-2,2,-5,LOG:12)
B(-2,1,-5,LOG:12)
B(-2,4,-5,LOG:12)
B(-2,3,-5,LOG:12)
B(-2,56,-5,leaves:1)
B(-2,0,-5,LOG:12)
B(-2,57,-5,leaves:1)
B(-2,9,-5,LOG:12)
B(-2,6,-5,LOG:12)
B(-2,5,-5,LOG:12)
B(-2,8,-5,LOG:12)
B(-2,7,-5,LOG:12)
B(5,39,-10,leaves:1)
B(4,45,-4,leaves:1)
B(-8,24,-6,leaves:1)
B(4,43,-4,leaves:1)
B(4,44,-4,leaves:1)
B(4,41,-4,leaves:1)
B(-8,21,-6,leaves:1)
B(4,42,-4,leaves:1)
B(-8,22,-6,leaves:1)
B(-1,15,-2,leaves:1)
B(-1,19,-2,leaves:1)
B(-1,18,-2,leaves:1)
B(-1,17,-2,leaves:1)
B(-1,16,-2,leaves:1)
B(-1,21,-2,leaves:1)
B(-1,20,-2,leaves:1)
B(2,61,-7,leaves:1)
B(2,60,-7,leaves:1)
B(2,62,-7,leaves:1)
B(1,43,2,leaves:1)
B(4,32,-4,leaves:1)
B(1,44,2,leaves:1)
B(4,33,-4,leaves:1)
B(1,45,2,leaves:1)
B(4,34,-4,leaves:1)
B(9,24,-1,leaves:1)
B(4,35,-4,leaves:1)
B(9,23,-1,leaves:1)
B(1,41,2,leaves:1)
B(4,30,-4,leaves:1)
B(1,42,2,leaves:1)
B(4,31,-4,leaves:1)
B(4,46,-1,leaves:1)
B(-1,28,-2,leaves:1)
B(9,26,-1,leaves:1)
B(9,25,-1,leaves:1)
B(-1,27,-2,leaves:1)
B(9,28,-1,leaves:1)
B(-1,29,-2,leaves:1)
B(9,27,-1,leaves:1)
B(2,66,-5,log)
B(4,44,-7,leaves:1)
B(4,45,-7,leaves:1)
B(2,64,-5,log)
B(4,42,-7,leaves:1)
B(2,65,-5,log)
B(4,43,-7,leaves:1)
B(2,62,-5,log)
B(4,40,-7,leaves:1)
B(4,37,-4,leaves:1)
B(2,63,-5,log)
B(4,41,-7,leaves:1)
B(4,36,-4,leaves:1)
B(2,60,-5,leaves:1)
B(2,61,-5,leaves:1)
B(4,38,-4,leaves:1)
B(9,46,-9,leaves:1)
B(-6,34,-3,leaves:1)
B(-6,37,-3,leaves:1)
B(-6,36,-3,leaves:1)
B(-6,31,-3,leaves:1)
B(-4,23,-4,leaves:1)
B(-6,33,-3,leaves:1)
B(-4,25,-4,leaves:1)
B(-6,32,-3,leaves:1)
B(-4,24,-4,leaves:1)
B(2,57,-5,leaves:1)
B(5,15,-1,leaves:1)
B(2,58,-5,leaves:1)
B(2,59,-5,log)
B(5,17,-1,leaves:1)
B(5,16,-1,leaves:1)
B(2,53,-5,log)
B(1,8,-12,leaves:1)
B(2,54,-5,log)
B(1,7,-12,leaves:1)
B(2,55,-5,log)
B(2,56,-5,log)
B(9,48,-9,leaves:1)
B(2,50,-5,leaves:1)
B(9,47,-9,leaves:1)
B(2,51,-5,leaves:1)
B(2,52,-5,leaves:1)
B(9,49,-9,leaves:1)
B(9,40,-1,leaves:1)
B(9,50,-9,leaves:1)
B(9,42,-1,leaves:1)
B(9,41,-1,leaves:1)
B(9,44,-1,leaves:1)
B(9,43,-1,leaves:1)
B(1,9,-12,leaves:1)
B(4,29,-7,leaves:1)
B(4,28,-7,leaves:1)
B(2,48,-5,leaves:1)
B(4,26,-7,leaves:1)
B(2,49,-5,leaves:1)
B(4,27,-7,leaves:1)
B(2,46,-5,log)
B(4,24,-7,leaves:1)
B(2,47,-5,leaves:1)
B(4,25,-7,leaves:1)
B(2,44,-5,log)
B(4,22,-7,leaves:1)
B(2,45,-5,log)
B(4,23,-7,leaves:1)
B(2,42,-5,log)
B(2,43,-5,log)
B(2,40,-5,log)
B(2,41,-5,log)
B(-5,30,-3,leaves:1)
B(2,30,-5,leaves:1)
B(0,46,-3,leaves:1)
B(2,34,-5,leaves:1)
B(-4,-4,-3,LOG:12)
B(0,47,-3,leaves:1)
B(2,33,-5,leaves:1)
B(0,48,-3,leaves:1)
B(2,32,-5,leaves:1)
B(-4,-6,-3,LOG:12)
B(0,49,-3,leaves:1)
B(2,31,-5,leaves:1)
B(2,38,-5,leaves:1)
B(-1,26,-10,leaves:1)
B(2,37,-5,leaves:1)
B(-1,27,-10,leaves:1)
B(2,36,-5,leaves:1)
B(-1,28,-10,leaves:1)
B(2,35,-5,leaves:1)
B(-1,29,-10,leaves:1)
B(12,26,0,leaves:1)
B(2,39,-5,log)
B(12,24,0,leaves:1)
B(2,30,-6,leaves:1)
B(5,40,-14,leaves:1)
B(2,31,-6,leaves:1)
B(2,32,-6,leaves:1)
B(-5,24,-3,leaves:1)
B(2,33,-6,leaves:1)
B(2,34,-6,leaves:1)
B(2,35,-6,leaves:1)
B(2,36,-6,leaves:1)
B(2,37,-6,leaves:1)
B(2,38,-6,leaves:1)
B(2,39,-6,leaves:1)
B(-5,23,-3,leaves:1)
B(0,51,-3,leaves:1)
B(0,52,-3,leaves:1)
B(7,20,-3,leaves:1)
B(5,39,-14,leaves:1)
B(0,50,-3,leaves:1)
B(5,38,-14,leaves:1)
B(-3,-5,-3,LOG:12)
B(-3,-2,-3,LOG:12)
B(2,21,-5,leaves:1)
B(2,20,-5,leaves:1)
B(-3,-3,-3,LOG:12)
B(3,61,-5,leaves:1)
B(3,60,-5,leaves:1)
B(0,53,-3,leaves:1)
B(2,29,-5,leaves:1)
B(4,32,3,leaves:1)
B(2,41,-6,leaves:1)
B(1,33,-14,leaves:1)
B(2,42,-6,leaves:1)
B(1,32,-14,leaves:1)
B(1,31,-14,leaves:1)
B(2,40,-6,leaves:1)
B(1,30,-14,leaves:1)
B(2,46,-6,leaves:1)
B(-5,38,-3,leaves:1)
B(2,43,-6,leaves:1)
B(-5,35,-3,leaves:1)
B(2,44,-6,leaves:1)
B(-5,36,-3,leaves:1)
B(1,34,-14,leaves:1)
B(2,49,-6,leaves:1)
B(-5,33,-3,leaves:1)
B(-5,34,-3,leaves:1)
B(2,47,-6,leaves:1)
B(-5,31,-3,leaves:1)
B(2,48,-6,leaves:1)
B(-5,32,-3,leaves:1)
B(7,21,-3,leaves:1)
B(4,29,-4,leaves:1)
B(2,19,-6,leaves:1)
B(2,18,-6,leaves:1)
B(2,16,-5,leaves:1)
B(0,20,-3,leaves:1)
B(2,15,-5,leaves:1)
B(0,21,-3,leaves:1)
B(0,22,-3,leaves:1)
B(0,23,-3,leaves:1)
B(0,24,-3,leaves:1)
B(5,53,-1,leaves:1)
B(0,29,-3,leaves:1)
B(7,19,-3,leaves:1)
B(7,18,-3,leaves:1)
B(5,51,-1,leaves:1)
B(5,50,-1,leaves:1)
B(2,19,-5,leaves:1)
B(2,17,-5,leaves:1)
B(2,18,-5,leaves:1)
B(3,13,-9,leaves:1)
B(2,15,-6,leaves:1)
B(2,16,-6,leaves:1)
B(3,15,-9,leaves:1)
B(4,20,-4,leaves:1)
B(3,14,-9,leaves:1)
B(2,17,-6,leaves:1)
B(7,15,-3,leaves:1)
B(4,21,-4,leaves:1)
B(7,17,-3,leaves:1)
B(7,16,-3,leaves:1)
B(4,16,-4,leaves:1)
B(4,17,-4,leaves:1)
B(4,15,-4,leaves:1)
B(9,15,-3,leaves:1)
B(0,30,-3,leaves:1)
B(9,14,-3,leaves:1)
B(4,18,-4,leaves:1)
B(2,29,-6,leaves:1)
B(4,19,-4,leaves:1)
B(5,47,-1,leaves:1)
B(0,33,-3,leaves:1)
B(5,48,-1,leaves:1)
B(0,34,-3,leaves:1)
B(5,49,-1,leaves:1)
B(0,31,-3,leaves:1)
B(0,32,-3,leaves:1)
B(9,16,-3,leaves:1)
B(0,37,-3,leaves:1)
B(0,38,-3,leaves:1)
B(0,35,-3,leaves:1)
B(5,46,-1,leaves:1)
B(0,36,-3,leaves:1)
B(-6,9,-7,leaves:1)
B(2,20,-6,leaves:1)
B(4,1,-1,LOG:12)
B(4,0,-1,LOG:12)
B(4,3,-1,LOG:12)
B(4,2,-1,LOG:12)
B(2,26,-6,leaves:1)
B(2,21,-6,leaves:1)
B(3,20,5,leaves:1)
B(3,21,5,leaves:1)
B(-2,34,-8,leaves:1)
B(-2,33,-8,leaves:1)
B(-2,32,-8,leaves:1)
B(-4,13,-3,leaves:1)
B(-4,15,-3,leaves:1)
B(-4,14,-3,leaves:1)
B(-2,35,-8,leaves:1)
B(-4,16,-3,leaves:1)
B(-12,30,-2,leaves:1)
B(-12,36,-2,leaves:1)
B(-12,34,-2,leaves:1)
B(0,16,-3,leaves:1)
B(0,15,-3,leaves:1)
B(0,14,-3,leaves:1)
B(0,13,-3,leaves:1)
B(0,12,-3,leaves:1)
B(0,11,-3,leaves:1)
B(3,21,-5,leaves:1)
B(3,22,-5,leaves:1)
B(-2,23,-8,leaves:1)
B(3,20,-5,leaves:1)
B(-2,25,-8,leaves:1)
B(3,25,-5,leaves:1)
B(-2,24,-8,leaves:1)
B(3,26,-5,leaves:1)
B(3,23,-5,leaves:1)
B(3,24,-5,leaves:1)
B(3,29,-5,leaves:1)
B(3,28,-5,leaves:1)
B(3,19,5,leaves:1)
B(3,27,-5,leaves:1)
B(3,23,-9,leaves:1)
B(3,24,-9,leaves:1)
B(-11,14,1,leaves:1)
B(-11,13,1,leaves:1)
B(-11,16,1,leaves:1)
B(-11,15,1,leaves:1)
B(3,18,5,leaves:1)
B(0,19,-3,leaves:1)
B(3,17,5,leaves:1)
B(3,16,5,leaves:1)
B(0,17,-3,leaves:1)
B(3,15,5,leaves:1)
B(0,18,-3,leaves:1)
B(2,-2,-5,LOG:12)
B(3,50,-5,leaves:1)
B(-11,17,1,leaves:1)
B(3,51,-5,leaves:1)
B(3,56,-5,leaves:1)
B(-4,37,-3,leaves:1)
B(3,57,-5,leaves:1)
B(-4,36,-3,leaves:1)
B(3,58,-5,leaves:1)
B(3,59,-5,leaves:1)
B(-4,38,-3,leaves:1)
B(3,52,-5,leaves:1)
B(-4,33,-3,leaves:1)
B(3,53,-5,leaves:1)
B(-4,32,-3,leaves:1)
B(3,54,-5,leaves:1)
B(-4,35,-3,leaves:1)
B(3,55,-5,leaves:1)
B(-4,34,-3,leaves:1)
B(2,59,-6,leaves:1)
B(2,58,-6,leaves:1)
B(2,55,-6,leaves:1)
B(2,57,-6,leaves:1)
B(2,56,-6,leaves:1)
B(2,51,-6,leaves:1)
B(2,50,-6,leaves:1)
B(2,53,-6,leaves:1)
B(2,52,-6,leaves:1)
B(2,-4,-5,LOG:12)
B(2,-3,-5,LOG:12)
B(-1,19,6,leaves:1)
B(-1,18,6,leaves:1)
B(3,47,-5,leaves:1)
B(3,48,-5,leaves:1)
B(3,46,-5,leaves:1)
B(-4,25,-3,leaves:1)
B(-4,24,-3,leaves:1)
B(-4,23,-3,leaves:1)
B(-2,1,-1,leaves:2)
B(-4,30,-3,leaves:1)
B(-4,31,-3,leaves:1)
B(3,49,-5,leaves:1)
B(2,62,-6,leaves:1)
B(-1,20,6,leaves:1)
B(2,61,-6,leaves:1)
B(-1,21,6,leaves:1)
B(2,60,-6,leaves:1)
B(-2,49,-3,leaves:1)
B(-2,61,-6,leaves:1)
B(0,17,-14,leaves:1)
B(0,15,-14,leaves:1)
B(0,16,-14,leaves:1)
B(0,14,-14,leaves:1)
B(-6,30,-2,leaves:1)
B(-2,53,-3,leaves:1)
B(-2,52,-3,leaves:1)
B(-2,51,-3,leaves:1)
B(-2,50,-3,leaves:1)
B(9,57,-6,leaves:1)
B(9,56,-6,leaves:1)
B(9,53,-6,leaves:1)
B(9,54,-6,leaves:1)
B(4,-1,0,LOG:12)
B(4,-4,0,LOG:12)
B(4,-3,0,LOG:12)
B(3,19,2,leaves:1)
B(3,4,0,LOG:12)
B(3,3,0,LOG:12)
B(3,2,0,LOG:12)
B(-1,17,-15,leaves:1)
B(-1,16,-15,leaves:1)
B(3,1,0,leaves:2)
B(-1,19,5,leaves:1)
B(-2,45,-6,leaves:1)
B(-2,44,-6,leaves:1)
B(-2,41,-6,leaves:1)
B(-2,40,-6,leaves:1)
B(-1,14,-15,leaves:1)
B(-2,43,-6,leaves:1)
B(-1,13,-15,leaves:1)
B(-2,42,-6,leaves:1)
B(3,29,2,leaves:1)
B(2,-7,0,LOG:12)
B(-1,17,-16,leaves:1)
B(-1,16,-16,leaves:1)
B(3,21,2,leaves:1)
B(3,22,2,leaves:1)
B(-1,14,-16,leaves:1)
B(-1,13,-16,leaves:1)
B(3,20,2,leaves:1)
B(-1,20,5,leaves:1)
B(-1,21,5,leaves:1)
B(2,-4,0,LOG:12)
B(2,-3,0,LOG:12)
B(2,-1,0,LOG:12)
B(-3,-6,-4,LOG:12)
B(3,30,2,leaves:1)
B(3,31,2,leaves:1)
B(3,33,2,leaves:1)
B(-3,-1,-4,LOG:12)
B(3,35,2,leaves:1)
B(-3,-3,-4,LOG:12)
B(3,36,2,leaves:1)
B(-3,-5,-4,LOG:12)
B(6,22,-2,leaves:1)
B(-2,20,-6,leaves:1)
B(6,23,-2,leaves:1)
B(-2,21,-6,leaves:1)
B(6,24,-2,leaves:1)
B(-2,22,-6,leaves:1)
B(6,25,-2,leaves:1)
B(-2,23,-6,leaves:1)
B(6,26,-2,leaves:1)
B(-2,24,-6,leaves:1)
B(6,27,-2,leaves:1)
B(6,28,-2,leaves:1)
B(-2,25,-6,leaves:1)
B(6,29,-2,leaves:1)
B(5,36,-4,leaves:1)
B(5,35,-4,leaves:1)
B(5,37,-4,leaves:1)
B(5,31,-4,leaves:1)
B(-2,10,-3,leaves:1)
B(1,6,-3,LOG:12)
B(5,32,-4,leaves:1)
B(-2,11,-3,leaves:1)
B(1,5,-3,LOG:12)
B(5,33,-4,leaves:1)
B(1,4,-3,LOG:12)
B(5,34,-4,leaves:1)
B(1,3,-3,LOG:12)
B(1,9,-3,leaves:1)
B(1,8,-3,LOG:12)
B(1,7,-3,LOG:12)
B(-2,16,-6,leaves:1)
B(-2,15,-6,leaves:1)
B(-2,18,-6,leaves:1)
B(-2,17,-6,leaves:1)
B(1,2,-3,LOG:12)
B(1,1,-3,LOG:12)
B(-2,19,-6,leaves:1)
B(1,0,-3,LOG:12)
B(-2,32,-6,leaves:1)
B(6,16,-2,leaves:1)
B(6,17,-2,leaves:1)
B(-2,33,-6,leaves:1)
B(-2,34,-6,leaves:1)
B(6,15,-2,leaves:1)
B(-2,17,-3,leaves:1)
B(-2,19,-3,leaves:1)
B(-2,18,-3,leaves:1)
B(-2,12,-3,leaves:1)
B(-8,10,-7,leaves:1)
B(-2,20,-3,leaves:1)
B(-2,21,-3,leaves:1)
B(4,42,-9,leaves:1)
B(4,43,-9,leaves:1)
B(5,41,-4,leaves:1)
B(4,40,-9,leaves:1)
B(4,41,-9,leaves:1)
B(4,44,-9,leaves:1)
B(-2,26,-6,leaves:1)
B(4,15,0,leaves:1)
B(4,16,0,leaves:1)
B(4,17,0,leaves:1)
B(4,18,0,leaves:1)
B(6,43,-2,leaves:1)
B(6,44,-2,leaves:1)
B(6,45,-2,leaves:1)
B(-3,32,-4,leaves:1)
B(-3,33,-4,leaves:1)
B(-2,29,-3,leaves:1)
B(0,40,6,leaves:1)
B(0,41,6,leaves:1)
B(-1,-1,0,LOG:12)
B(0,42,6,leaves:1)
B(-3,25,-4,leaves:1)
B(-3,24,-4,leaves:1)
B(-3,23,-4,leaves:1)
B(-2,32,-3,leaves:1)
B(8,29,-1,leaves:1)
B(-2,33,-3,leaves:1)
B(8,28,-1,leaves:1)
B(-2,30,-3,leaves:1)
B(8,27,-1,leaves:1)
B(-2,31,-3,leaves:1)
B(8,26,-1,leaves:1)
B(6,40,-2,leaves:1)
B(8,25,-1,leaves:1)
B(8,24,-1,leaves:1)
B(6,42,-2,leaves:1)
B(8,23,-1,leaves:1)
B(6,41,-2,leaves:1)
B(8,22,-1,leaves:1)
B(-2,13,-6,leaves:1)
B(-2,14,-6,leaves:1)
B(-2,11,-6,leaves:1)
B(-2,12,-6,leaves:1)
B(-2,10,-6,leaves:1)
B(-2,35,-3,leaves:1)
B(2,0,1,LOG:12)
B(-2,34,-3,leaves:1)
B(-2,37,-3,leaves:1)
B(-2,39,-3,leaves:1)
B(-2,38,-3,leaves:1)
B(5,29,-4,leaves:1)
B(-3,21,-4,leaves:1)
B(2,1,1,LOG:12)
B(-3,22,-4,leaves:1)
B(-3,13,-4,leaves:1)
B(-3,15,-4,leaves:1)
B(-3,14,-4,leaves:1)
B(-3,10,0,leaves:1)
B(-3,16,-4,leaves:1)
B(-8,40,-7,leaves:1)
B(-3,12,0,leaves:1)
B(-3,11,0,leaves:1)
B(0,39,6,leaves:1)
B(2,55,-7,leaves:1)
B(8,40,-1,leaves:1)
B(3,18,3,leaves:1)
B(2,56,-7,leaves:1)
B(8,41,-1,leaves:1)
B(3,17,3,leaves:1)
B(10,20,-4,leaves:1)
B(2,57,-7,leaves:1)
B(8,42,-1,leaves:1)
B(2,58,-7,leaves:1)
B(8,43,-1,leaves:1)
B(3,19,3,leaves:1)
B(2,59,-7,leaves:1)
B(8,44,-1,leaves:1)
B(6,31,-4,leaves:1)
B(6,33,-4,leaves:1)
B(6,32,-4,leaves:1)
B(1,-5,0,LOG:12)
B(1,-2,0,LOG:12)
B(1,-1,0,LOG:12)
B(3,16,3,leaves:1)
B(-1,10,-3,leaves:1)
B(2,56,-8,leaves:1)
B(2,57,-8,leaves:1)
B(2,58,-8,leaves:1)
B(10,19,-4,leaves:1)
B(2,59,-8,leaves:1)
B(3,29,3,leaves:1)
B(10,50,-9,leaves:1)
B(-1,17,-3,leaves:1)
B(-1,18,-3,leaves:1)
B(3,22,3,leaves:1)
B(-1,19,-3,leaves:1)
B(3,21,3,leaves:1)
B(3,20,3,leaves:1)
B(-1,15,-3,leaves:1)
B(-1,16,-3,leaves:1)
B(-2,-4,-3,LOG:12)
B(-2,-5,-3,LOG:12)
B(13,31,-6,leaves:1)
B(-2,-2,-3,LOG:12)
B(13,30,-6,leaves:1)
B(-2,-1,-3,LOG:12)
B(4,53,-6,leaves:1)
B(4,52,-6,leaves:1)
B(4,51,-6,leaves:1)
B(4,50,-6,leaves:1)
B(2,61,-8,leaves:1)
B(13,33,-6,leaves:1)
B(2,62,-8,leaves:1)
B(13,32,-6,leaves:1)
B(-2,-6,-3,LOG:12)
B(2,60,-8,leaves:1)
B(13,34,-6,leaves:1)
B(-2,-7,-3,LOG:12)
B(2,37,-7,leaves:1)
B(8,16,-3,leaves:1)
B(4,39,-9,leaves:1)
B(2,38,-7,leaves:1)
B(8,15,-3,leaves:1)
B(2,39,-7,leaves:1)
B(8,14,-3,leaves:1)
B(2,33,-7,leaves:1)
B(2,34,-7,leaves:1)
B(2,35,-7,leaves:1)
B(2,36,-7,leaves:1)
B(3,15,10,leaves:1)
B(1,-4,-2,LOG:12)
B(2,30,-7,leaves:1)
B(1,-3,-2,LOG:12)
B(2,31,-7,leaves:1)
B(1,-2,-2,LOG:12)
B(2,32,-7,leaves:1)
B(1,-1,-2,LOG:12)
B(3,18,10,leaves:1)
B(3,32,3,leaves:1)
B(3,19,10,leaves:1)
B(3,31,3,leaves:1)
B(1,-7,-2,LOG:12)
B(8,19,-3,leaves:1)
B(8,18,-3,leaves:1)
B(1,-5,-2,LOG:12)
B(8,17,-3,leaves:1)
B(2,34,-8,leaves:1)
B(2,35,-8,leaves:1)
B(2,36,-8,leaves:1)
B(-6,18,-1,leaves:1)
B(2,37,-8,leaves:1)
B(3,30,3,leaves:1)
B(-6,19,-1,leaves:1)
B(2,38,-8,leaves:1)
B(-6,16,-1,leaves:1)
B(-6,17,-1,leaves:1)
B(-6,14,-1,leaves:1)
B(-6,15,-1,leaves:1)
B(10,48,-9,leaves:1)
B(2,30,-8,leaves:1)
B(4,1,1,leaves:2)
B(2,31,-8,leaves:1)
B(4,2,1,leaves:2)
B(2,32,-8,leaves:1)
B(2,33,-8,leaves:1)
B(2,28,-7,leaves:1)
B(5,26,-9,leaves:1)
B(4,27,-9,leaves:1)
B(2,29,-7,leaves:1)
B(2,26,-7,leaves:1)
B(2,27,-7,leaves:1)
B(5,22,-9,leaves:1)
B(4,23,-9,leaves:1)
B(5,24,-9,leaves:1)
B(5,23,-9,leaves:1)
B(4,24,-9,leaves:1)
B(2,20,-7,leaves:1)
B(2,21,-7,leaves:1)
B(7,26,-2,leaves:1)
B(7,27,-2,leaves:1)
B(7,25,-2,leaves:1)
B(7,28,-2,leaves:1)
B(7,29,-2,leaves:1)
B(1,18,0,leaves:1)
B(1,19,0,leaves:1)
B(0,16,-11,leaves:1)
B(1,16,0,leaves:1)
B(0,17,-11,leaves:1)
B(1,17,0,leaves:1)
B(-1,3,-5,LOG:12)
B(1,15,0,leaves:1)
B(-1,2,-5,LOG:12)
B(-1,1,-5,LOG:12)
B(-1,0,-5,LOG:12)
B(-1,7,-5,LOG:12)
B(-1,6,-5,LOG:12)
B(-1,5,-5,LOG:12)
B(-1,4,-5,LOG:12)
B(2,16,-7,leaves:1)
B(2,15,-7,leaves:1)
B(-1,9,-5,LOG:12)
B(2,18,-7,leaves:1)
B(0,9,-4,leaves:1)
B(-1,8,-5,LOG:12)
B(2,17,-7,leaves:1)
B(2,19,-7,leaves:1)
B(0,1,-4,LOG:12)
B(0,0,-4,LOG:12)
B(-1,-4,-3,LOG:12)
B(-1,-3,-3,LOG:12)
B(-1,-2,-3,LOG:12)
B(-7,20,-8,leaves:1)
B(8,20,-3,leaves:1)
B(-1,-7,-3,LOG:12)
B(-6,20,-1,leaves:1)
B(0,9,-8,leaves:1)
B(-7,19,-8,leaves:1)
B(-7,18,-8,leaves:1)
B(-7,17,-8,leaves:1)
B(0,8,-8,leaves:1)
B(2,-1,-4,LOG:12)
B(0,50,-9,leaves:1)
B(2,-4,-4,LOG:12)
B(0,47,-9,leaves:1)
B(-6,50,-1,leaves:1)
B(2,-3,-4,LOG:12)
B(0,49,-9,leaves:1)
B(0,48,-9,leaves:1)
B(1,23,0,leaves:1)
B(1,24,0,leaves:1)
B(1,25,0,leaves:1)
B(10,14,-4,leaves:1)
B(1,26,0,leaves:1)
B(10,15,-4,leaves:1)
B(1,27,0,leaves:1)
B(10,16,-4,leaves:1)
B(10,17,-4,leaves:1)
B(10,18,-4,leaves:1)
B(1,20,0,leaves:1)
B(1,21,0,leaves:1)
B(1,22,0,leaves:1)
B(0,52,-9,leaves:1)
B(-6,48,-1,leaves:1)
B(-7,9,-7,leaves:1)
B(-6,49,-1,leaves:1)
B(1,42,-2,leaves:1)
B(1,20,-11,leaves:1)
B(1,43,-2,leaves:1)
B(1,40,-2,leaves:1)
B(1,20,-9,leaves:1)
B(1,41,-2,leaves:1)
B(1,21,-9,leaves:1)
B(1,44,-2,leaves:1)
B(1,45,-2,leaves:1)
B(0,30,-9,leaves:1)
B(0,31,-9,leaves:1)
B(0,32,-9,leaves:1)
B(0,33,-9,leaves:1)
B(1,40,0,leaves:1)
B(1,44,0,leaves:1)
B(1,43,0,leaves:1)
B(1,42,0,leaves:1)
B(1,41,0,leaves:1)
B(1,18,-11,leaves:1)
B(1,17,-11,leaves:1)
B(1,45,0,leaves:1)
B(1,19,-11,leaves:1)
B(1,34,-11,leaves:1)
B(1,31,-11,leaves:1)
B(1,32,-11,leaves:1)
B(1,36,-11,leaves:1)
B(0,20,-9,leaves:1)
B(0,21,-9,leaves:1)
B(1,30,-11,leaves:1)
B(0,19,-9,leaves:1)
B(0,17,-9,leaves:1)
B(0,18,-9,leaves:1)
B(0,11,-9,leaves:1)
B(2,29,-4,LOG:12)
B(2,28,-4,LOG:12)
B(3,16,7,leaves:1)
B(2,27,-4,LOG:12)
B(3,17,7,leaves:1)
B(3,18,7,leaves:1)
B(3,19,7,leaves:1)
B(0,10,-9,leaves:1)
B(2,21,-4,LOG:12)
B(2,22,-4,LOG:12)
B(-5,27,-7,leaves:1)
B(2,20,-4,LOG:12)
B(2,25,-4,LOG:12)
B(2,26,-4,LOG:12)
B(-5,28,-7,leaves:1)
B(2,23,-4,LOG:12)
B(2,24,-4,LOG:12)
B(-1,26,-9,leaves:1)
B(-1,27,-9,leaves:1)
B(-1,28,-9,leaves:1)
B(-1,29,-9,leaves:1)
B(3,-2,-3,LOG:12)
B(3,-3,-3,LOG:12)
B(3,-1,-3,LOG:12)
B(3,-4,-3,LOG:12)
B(-4,51,-2,leaves:1)
B(2,17,-4,leaves:1)
B(-4,52,-2,leaves:1)
B(2,16,-4,leaves:1)
B(2,19,-4,leaves:1)
B(2,18,-4,leaves:1)
B(-4,49,-2,leaves:1)
B(-4,48,-2,leaves:1)
B(-1,9,-6,leaves:1)
B(3,20,7,leaves:1)
B(-1,11,-6,leaves:1)
B(-1,10,-6,leaves:1)
B(-1,15,-6,leaves:1)
B(-1,14,-6,leaves:1)
B(2,49,-4,leaves:1)
B(-1,13,-6,leaves:1)
B(-1,12,-6,leaves:1)
B(7,43,-2,leaves:1)
B(7,42,-2,leaves:1)
B(7,45,-2,leaves:1)
B(7,44,-2,leaves:1)
B(2,40,-4,log)
B(-2,2,0,leaves:2)
B(7,41,-2,leaves:1)
B(2,48,-4,leaves:1)
B(2,47,-4,leaves:1)
B(2,46,-4,leaves:1)
B(2,45,-4,log)
B(-7,32,-2,leaves:1)
B(3,0,-4,LOG:12)
B(2,44,-4,log)
B(-7,31,-2,leaves:1)
B(16,16,-6,leaves:1)
B(-4,13,-2,leaves:1)
B(2,43,-4,log)
B(-7,30,-2,leaves:1)
B(16,15,-6,leaves:1)
B(2,42,-4,log)
B(2,41,-4,log)
B(2,38,-4,log)
B(4,1,0,leaves:2)
B(2,39,-4,log)
B(4,0,0,LOG:12)
B(4,2,0,leaves:2)
B(4,21,-6,leaves:1)
B(-1,50,-3,leaves:1)
B(4,22,-6,leaves:1)
B(-1,51,-3,leaves:1)
B(-1,52,-3,leaves:1)
B(-1,53,-3,leaves:1)
B(4,25,-6,leaves:1)
B(4,26,-6,leaves:1)
B(4,23,-6,leaves:1)
B(4,24,-6,leaves:1)
B(-1,47,-3,leaves:1)
B(-1,46,-3,leaves:1)
B(-1,49,-3,leaves:1)
B(-1,48,-3,leaves:1)
B(5,21,-3,leaves:1)
B(5,20,-3,leaves:1)
B(2,35,-4,log)
B(-5,18,-7,leaves:1)
B(7,22,-1,leaves:1)
B(2,34,-4,LOG:12)
B(-5,17,-7,leaves:1)
B(2,37,-4,log)
B(2,36,-4,log)
B(-5,19,-7,leaves:1)
B(2,31,-4,LOG:12)
B(2,30,-4,LOG:12)
B(7,25,-1,leaves:1)
B(2,33,-4,LOG:12)
B(7,24,-1,leaves:1)
B(2,32,-4,LOG:12)
B(7,23,-1,leaves:1)
B(5,16,-3,leaves:1)
B(1,25,-2,leaves:1)
B(5,17,-3,leaves:1)
B(1,24,-2,leaves:1)
B(5,18,-3,leaves:1)
B(1,23,-2,leaves:1)
B(5,19,-3,leaves:1)
B(1,22,-2,leaves:1)
B(1,21,-2,leaves:1)
B(1,20,-2,LOG:12)
B(5,15,-3,leaves:1)
B(-1,38,-3,leaves:1)
B(1,28,-2,leaves:1)
B(-1,37,-3,leaves:1)
B(-1,36,-3,leaves:1)
B(1,26,-2,leaves:1)
B(-1,35,-3,leaves:1)
B(1,27,-2,leaves:1)
B(4,40,-6,leaves:1)
B(16,13,-6,leaves:1)
B(16,14,-6,leaves:1)
B(4,47,-6,leaves:1)
B(1,12,-2,LOG:12)
B(4,48,-6,leaves:1)
B(-1,32,-3,leaves:1)
B(1,11,-2,LOG:12)
B(4,45,-6,leaves:1)
B(-1,33,-3,leaves:1)
B(1,14,-2,LOG:12)
B(4,46,-6,leaves:1)
B(-1,34,-3,leaves:1)
B(1,13,-2,LOG:12)
B(4,43,-6,leaves:1)
B(4,44,-6,leaves:1)
B(4,41,-6,leaves:1)
B(1,10,-2,LOG:12)
B(4,42,-6,leaves:1)
B(-1,30,-3,leaves:1)
B(-1,29,-3,leaves:1)
B(1,19,-2,LOG:12)
B(-1,28,-3,leaves:1)
B(-3,9,-6,leaves:1)
B(1,15,-2,LOG:12)
B(1,16,-2,LOG:12)
B(2,51,-4,leaves:1)
B(1,17,-2,leaves:1)
B(-1,27,-3,leaves:1)
B(2,50,-4,leaves:1)
B(4,49,-6,leaves:1)
B(1,18,-2,LOG:12)
B(-1,26,-3,leaves:1)
B(2,53,-4,log)
B(-1,-6,-6,LOG:12)
B(2,52,-4,leaves:1)
B(2,55,-4,leaves:1)
B(2,54,-4,leaves:1)
B(-6,9,-6,leaves:1)
B(-1,-3,-6,LOG:12)
B(7,41,-1,leaves:1)
B(-1,-5,-6,LOG:12)
B(3,60,-3,leaves:1)
B(6,54,-5,leaves:1)
B(6,55,-5,leaves:1)
B(6,56,-5,leaves:1)
B(11,32,-5,leaves:1)
B(11,31,-5,leaves:1)
B(11,30,-5,leaves:1)
B(3,61,-3,leaves:1)
B(-2,-6,-6,LOG:12)
B(5,39,-13,leaves:1)
B(5,38,-13,leaves:1)
B(-1,28,-6,leaves:1)
B(-1,27,-6,leaves:1)
B(-1,29,-6,leaves:1)
B(3,41,-3,log)
B(3,40,-3,log)
B(3,46,-3,leaves:1)
B(3,45,-3,leaves:1)
B(3,44,-3,leaves:1)
B(3,49,-3,leaves:1)
B(3,47,-3,leaves:1)
B(3,48,-3,leaves:1)
B(-1,34,-6,leaves:1)
B(-1,35,-6,leaves:1)
B(-1,30,-6,LOG:12)
B(-1,31,-6,leaves:1)
B(-1,32,-6,leaves:1)
B(-1,33,-6,leaves:1)
B(-1,19,-6,LOG:12)
B(-1,18,-6,LOG:12)
B(-1,17,-6,leaves:1)
B(-1,16,-6,leaves:1)
B(3,51,-3,leaves:1)
B(3,50,-3,leaves:1)
B(3,53,-3,leaves:1)
B(3,52,-3,leaves:1)
B(3,55,-3,leaves:1)
B(3,54,-3,leaves:1)
B(3,57,-3,leaves:1)
B(3,56,-3,leaves:1)
B(3,58,-3,leaves:1)
B(3,59,-3,leaves:1)
B(-1,25,-6,LOG:12)
B(-1,26,-6,LOG:12)
B(-1,23,-6,LOG:12)
B(-1,24,-6,LOG:12)
B(-1,21,-6,LOG:12)
B(-1,22,-6,LOG:12)
B(-1,20,-6,LOG:12)
B(3,23,-3,leaves:1)
B(3,24,-3,leaves:1)
B(3,21,-3,LOG:12)
B(3,22,-3,leaves:1)
B(3,20,-3,LOG:12)
B(3,29,-3,LOG:12)
B(3,28,-3,leaves:1)
B(3,27,-3,leaves:1)
B(3,26,-3,LOG:12)
B(3,25,-3,leaves:1)
B(3,32,-3,LOG:12)
B(3,33,-3,LOG:12)
B(3,34,-3,log)
B(3,35,-3,log)
B(-2,32,-7,leaves:1)
B(-2,33,-7,leaves:1)
B(3,30,-3,LOG:12)
B(-2,30,-7,leaves:1)
B(3,31,-3,LOG:12)
B(-2,31,-7,leaves:1)
B(3,37,-3,log)
B(3,36,-3,log)
B(-2,29,-7,leaves:1)
B(3,39,-3,log)
B(-2,28,-7,leaves:1)
B(3,38,-3,log)
B(-2,27,-7,leaves:1)
B(-4,15,-9,leaves:1)
B(-4,14,-9,leaves:1)
B(-4,13,-9,leaves:1)
B(5,49,-7,leaves:1)
B(-2,23,-7,leaves:1)
B(-2,24,-7,leaves:1)
B(5,40,-13,leaves:1)
B(2,16,0,leaves:1)
B(2,19,0,leaves:1)
B(2,17,0,leaves:1)
B(2,18,0,leaves:1)
B(-2,17,-7,leaves:1)
B(-2,16,-7,leaves:1)
B(-4,24,-9,leaves:1)
B(-4,23,-9,leaves:1)
B(-2,14,-7,leaves:1)
B(3,10,-3,leaves:1)
B(-2,15,-7,leaves:1)
B(3,11,-3,leaves:1)
B(3,12,-3,leaves:1)
B(-4,22,-9,leaves:1)
B(3,13,-3,LOG:12)
B(-2,13,-7,leaves:1)
B(-1,2,-1,leaves:2)
B(1,18,-9,leaves:1)
B(-2,1,-4,LOG:12)
B(-1,3,-1,leaves:2)
B(1,19,-9,leaves:1)
B(1,14,-9,leaves:1)
B(-2,4,-4,LOG:12)
B(1,15,-9,leaves:1)
B(-2,5,-4,LOG:12)
B(5,50,-7,leaves:1)
B(1,16,-9,leaves:1)
B(-2,2,-4,LOG:12)
B(5,51,-7,leaves:1)
B(-2,3,-4,LOG:12)
B(1,17,-9,leaves:1)
B(-1,62,-6,leaves:1)
B(3,15,-3,LOG:12)
B(-2,8,-4,LOG:12)
B(-1,61,-6,leaves:1)
B(5,53,-7,leaves:1)
B(3,14,-3,LOG:12)
B(-2,9,-4,LOG:12)
B(1,16,-11,leaves:1)
B(-2,6,-4,LOG:12)
B(3,17,-3,leaves:1)
B(3,16,-3,LOG:12)
B(1,15,-11,leaves:1)
B(-2,7,-4,LOG:12)
B(1,10,-11,leaves:1)
B(3,19,-3,LOG:12)
B(2,20,0,leaves:1)
B(3,18,-3,LOG:12)
B(2,21,0,leaves:1)
B(12,18,-5,leaves:1)
B(0,25,2,leaves:1)
B(0,24,2,leaves:1)
B(0,21,2,leaves:1)
B(0,20,2,leaves:1)
B(-5,21,-5,leaves:1)
B(0,23,2,leaves:1)
B(0,22,2,leaves:1)
B(0,34,-8,leaves:1)
B(-6,22,-5,leaves:1)
B(-6,21,-5,leaves:1)
B(0,32,-8,leaves:1)
B(0,33,-8,leaves:1)
B(-6,23,-5,leaves:1)
B(0,30,-8,leaves:1)
B(0,31,-8,leaves:1)
B(3,-6,0,LOG:12)
B(3,-5,0,LOG:12)
B(12,16,-5,leaves:1)
B(-3,11,1,leaves:1)
B(0,60,-5,leaves:1)
B(-3,10,1,leaves:1)
B(-4,42,-6,leaves:1)
B(-9,31,-2,leaves:1)
B(-4,43,-6,leaves:1)
B(-9,30,-2,leaves:1)
B(-4,44,-6,leaves:1)
B(-9,33,-2,leaves:1)
B(-9,32,-2,leaves:1)
B(-4,40,-6,leaves:1)
B(-4,41,-6,leaves:1)
B(3,23,-2,leaves:1)
B(3,22,-2,LOG:12)
B(3,21,-2,LOG:12)
B(3,20,-2,LOG:12)
B(-9,34,-2,leaves:1)
B(0,58,-5,leaves:1)
B(-7,32,-3,leaves:1)
B(0,57,-5,leaves:1)
B(0,56,-5,leaves:1)
B(3,28,-2,LOG:12)
B(0,55,-5,leaves:1)
B(3,29,-2,LOG:12)
B(-7,36,-3,leaves:1)
B(3,26,-2,LOG:12)
B(3,27,-2,LOG:12)
B(-7,34,-3,leaves:1)
B(3,24,-2,leaves:1)
B(0,59,-5,leaves:1)
B(3,25,-2,LOG:12)
B(-7,37,-3,leaves:1)
B(3,10,-2,LOG:12)
B(3,12,-2,LOG:12)
B(3,11,-2,LOG:12)
B(0,45,-5,leaves:1)
B(3,17,-2,leaves:1)
B(-5,23,-5,leaves:1)
B(0,44,-5,leaves:1)
B(3,18,-2,LOG:12)
B(-5,22,-5,leaves:1)
B(3,19,-2,LOG:12)
B(-5,25,-5,leaves:1)
B(3,13,-2,LOG:12)
B(3,14,-2,LOG:12)
B(-5,26,-5,leaves:1)
B(3,15,-2,LOG:12)
B(3,16,-2,LOG:12)
B(0,41,-5,leaves:1)
B(0,40,-5,leaves:1)
B(0,43,-5,leaves:1)
B(0,42,-5,leaves:1)
B(4,9,-2,leaves:1)
B(1,8,-2,LOG:12)
B(1,9,-2,LOG:12)
B(1,6,-2,LOG:12)
B(1,7,-2,LOG:12)
B(1,4,-2,LOG:12)
B(1,5,-2,LOG:12)
B(1,2,-2,LOG:12)
B(4,2,-2,LOG:12)
B(4,1,-2,LOG:12)
B(1,3,-2,LOG:12)
B(4,54,-5,leaves:1)
B(4,0,-2,LOG:12)
B(4,53,-5,leaves:1)
B(4,56,-5,leaves:1)
B(4,55,-5,leaves:1)
B(4,58,-5,leaves:1)
B(4,4,-2,LOG:12)
B(4,57,-5,leaves:1)
B(4,3,-2,LOG:12)
B(4,59,-5,leaves:1)
B(3,16,0,leaves:1)
B(3,17,0,leaves:1)
B(-3,52,-2,leaves:1)
B(-3,53,-2,leaves:1)
B(-3,50,-2,leaves:1)
B(3,18,0,leaves:1)
B(-3,51,-2,leaves:1)
B(3,19,0,leaves:1)
B(4,43,-5,leaves:1)
B(4,42,-5,leaves:1)
B(-4,23,-10,leaves:1)
B(4,41,-5,leaves:1)
B(-4,22,-10,leaves:1)
B(4,40,-5,leaves:1)
B(4,46,-5,leaves:1)
B(6,25,-12,leaves:1)
B(4,45,-5,leaves:1)
B(6,22,-12,leaves:1)
B(4,44,-5,leaves:1)
B(6,23,-12,leaves:1)
B(0,20,-5,leaves:1)
B(0,21,-5,leaves:1)
B(-3,46,-2,leaves:1)
B(3,21,6,leaves:1)
B(3,20,6,leaves:1)
B(0,22,-5,leaves:1)
B(-3,49,-2,leaves:1)
B(0,23,-5,leaves:1)
B(-3,48,-2,leaves:1)
B(0,24,-5,leaves:1)
B(-3,47,-2,leaves:1)
B(0,25,-5,leaves:1)
B(-7,18,0,leaves:1)
B(-7,17,0,leaves:1)
B(0,19,-5,leaves:1)
B(-7,19,0,leaves:1)
B(-3,20,-2,leaves:1)
B(-7,14,0,leaves:1)
B(3,16,6,leaves:1)
B(3,17,6,leaves:1)
B(-7,16,0,leaves:1)
B(3,18,6,leaves:1)
B(-7,15,0,leaves:1)
B(-2,48,-2,leaves:1)
B(-2,49,-2,leaves:1)
B(-2,46,-2,leaves:1)
B(-2,47,-2,leaves:1)
B(-2,51,-2,leaves:1)
B(-3,19,-2,leaves:1)
B(0,12,-8,leaves:1)
B(0,10,-5,leaves:1)
B(-3,18,-2,leaves:1)
B(-2,50,-2,leaves:1)
B(0,11,-8,leaves:1)
B(0,10,-8,leaves:1)
B(-3,15,-2,leaves:1)
B(0,17,-8,leaves:1)
B(0,11,-5,leaves:1)
B(-3,17,-2,leaves:1)
B(-3,16,-2,leaves:1)
B(0,12,-5,leaves:1)
B(0,17,-5,leaves:1)
B(0,18,-5,leaves:1)
B(0,19,-8,leaves:1)
B(0,16,-5,leaves:1)
B(0,18,-8,leaves:1)
B(4,61,-5,leaves:1)
B(4,60,-5,leaves:1)
B(0,20,-8,leaves:1)
B(0,21,-8,leaves:1)
B(3,-4,-2,LOG:12)
B(-3,23,-9,leaves:1)
B(-3,22,-9,leaves:1)
B(3,-6,-2,LOG:12)
B(3,-5,-2,LOG:12)
B(-4,8,3,leaves:1)
B(3,-2,-2,LOG:12)
B(-3,22,-2,leaves:1)
B(-3,21,-2,leaves:1)
B(-3,24,-9,leaves:1)
B(-3,0,-5,LOG:12)
B(5,47,-6,leaves:1)
B(-3,9,-5,leaves:1)
B(0,0,-5,LOG:12)
B(0,9,-5,leaves:1)
B(5,48,-6,leaves:1)
B(5,49,-6,leaves:1)
B(-1,1,2,leaves:2)
B(0,8,-9,leaves:1)
B(0,9,-9,leaves:1)
B(-2,20,-2,leaves:1)
B(-2,21,-2,leaves:1)
B(-2,12,-2,leaves:1)
B(-2,11,-2,leaves:1)
B(-2,13,-2,leaves:1)
B(3,55,0,leaves:1)
B(-2,16,-2,leaves:1)
B(3,54,0,leaves:1)
B(-2,15,-2,leaves:1)
B(3,57,0,leaves:1)
B(-2,18,-2,leaves:1)
B(3,56,0,leaves:1)
B(-2,17,-2,leaves:1)
B(-8,31,-2,leaves:1)
B(4,-4,-2,LOG:12)
B(3,58,0,leaves:1)
B(-8,32,-2,leaves:1)
B(4,-5,-2,LOG:12)
B(-2,19,-2,leaves:1)
B(4,-2,-2,LOG:12)
B(4,-1,-2,LOG:12)
B(-8,30,-2,leaves:1)
B(2,16,3,leaves:1)
B(2,15,3,leaves:1)
B(-4,13,-8,leaves:1)
B(-2,10,-2,leaves:1)
B(5,60,-6,leaves:1)
B(-11,31,-2,leaves:1)
B(0,3,-1,LOG:12)
B(-11,32,-2,leaves:1)
B(0,2,-1,LOG:12)
B(0,1,-1,LOG:12)
B(-11,30,-2,leaves:1)
B(0,0,-1,LOG:12)
B(3,21,0,leaves:1)
B(2,38,-9,leaves:1)
B(3,20,0,leaves:1)
B(2,37,-9,leaves:1)
B(2,36,-9,leaves:1)
B(2,35,-9,leaves:1)
B(2,34,-9,leaves:1)
B(2,-4,-2,LOG:12)
B(2,33,-9,leaves:1)
B(2,-5,-2,LOG:12)
B(2,32,-9,leaves:1)
B(2,31,-9,leaves:1)
B(3,29,0,leaves:1)
B(2,-7,-2,LOG:12)
B(-11,35,-2,leaves:1)
B(2,30,-9,leaves:1)
B(-11,34,-2,leaves:1)
B(2,-3,-2,LOG:12)
B(5,52,-6,leaves:1)
B(5,51,-6,leaves:1)
B(5,50,-6,leaves:1)
B(-1,-7,-4,LOG:12)
B(4,19,-3,leaves:1)
B(-1,-6,-4,LOG:12)
B(-1,-5,-4,LOG:12)
B(-1,-4,-4,LOG:12)
B(-1,-3,-4,LOG:12)
B(4,16,-3,leaves:1)
B(-1,-2,-4,LOG:12)
B(-14,34,-2,leaves:1)
B(3,33,0,leaves:1)
B(3,32,0,leaves:1)
B(3,35,0,leaves:1)
B(3,34,0,leaves:1)
B(3,31,0,leaves:1)
B(3,30,0,leaves:1)
B(-11,29,-2,leaves:1)
B(3,37,0,leaves:1)
B(3,36,0,leaves:1)
B(5,59,-6,leaves:1)
B(-4,31,-8,leaves:1)
B(4,25,-3,leaves:1)
B(-6,40,-7,leaves:1)
B(-4,32,-8,leaves:1)
B(4,24,-3,leaves:1)
B(4,27,-3,leaves:1)
B(4,26,-3,leaves:1)
B(-6,43,-7,leaves:1)
B(4,29,-3,leaves:1)
B(4,28,-3,leaves:1)
B(-6,41,-7,leaves:1)
B(-4,33,-8,leaves:1)
B(-6,42,-7,leaves:1)
B(2,30,-2,LOG:12)
B(2,31,-2,leaves:1)
B(2,32,-2,leaves:1)
B(2,33,-2,leaves:1)
B(2,34,-2,leaves:1)
B(2,35,-2,leaves:1)
B(2,37,-2,leaves:1)
B(10,23,0,leaves:1)
B(2,36,-2,leaves:1)
B(10,24,0,leaves:1)
B(3,40,-2,leaves:1)
B(3,41,-2,leaves:1)
B(2,38,-2,leaves:1)
B(3,42,-2,leaves:1)
B(2,56,-9,leaves:1)
B(3,43,-2,leaves:1)
B(-1,2,-2,leaves:2)
B(3,44,-2,leaves:1)
B(10,25,0,leaves:1)
B(-1,0,-2,LOG:12)
B(10,26,0,leaves:1)
B(2,59,-9,leaves:1)
B(2,57,-9,leaves:1)
B(3,13,-8,leaves:1)
B(2,58,-9,leaves:1)
B(3,14,-8,leaves:1)
B(4,20,-3,leaves:1)
B(4,21,-3,leaves:1)
B(2,41,-2,leaves:1)
B(2,42,-2,leaves:1)
B(2,45,-2,leaves:1)
B(2,43,-2,leaves:1)
B(2,44,-2,leaves:1)
B(-3,9,0,leaves:1)
B(3,23,-8,leaves:1)
B(-2,-1,-2,LOG:12)
B(-2,11,-1,leaves:1)
B(-2,-2,-2,LOG:12)
B(-2,12,-1,leaves:1)
B(-8,9,-7,leaves:1)
B(-8,8,-7,leaves:1)
B(2,7,-3,LOG:12)
B(2,19,-2,LOG:12)
B(2,6,-3,LOG:12)
B(2,18,-2,LOG:12)
B(2,5,-3,LOG:12)
B(2,4,-3,LOG:12)
B(3,60,-2,leaves:1)
B(2,15,-2,LOG:12)
B(3,61,-2,leaves:1)
B(2,9,-3,LOG:12)
B(2,17,-2,leaves:1)
B(2,16,-2,LOG:12)
B(2,8,-3,LOG:12)
B(4,42,-3,leaves:1)
B(10,41,0,leaves:1)
B(4,43,-3,leaves:1)
B(10,42,0,leaves:1)
B(4,44,-3,leaves:1)
B(4,45,-3,leaves:1)
B(10,40,0,leaves:1)
B(2,3,-3,LOG:12)
B(2,2,-3,LOG:12)
B(2,1,-3,LOG:12)
B(2,0,-3,LOG:12)
B(-6,10,-7,leaves:1)
B(-6,11,-7,leaves:1)
B(2,23,-2,LOG:12)
B(2,24,-2,LOG:12)
B(2,21,-2,LOG:12)
B(2,22,-2,LOG:12)
B(3,59,-2,leaves:1)
B(2,20,-2,LOG:12)
B(3,58,-2,leaves:1)
B(3,57,-2,leaves:1)
B(3,55,-2,leaves:1)
B(3,56,-2,leaves:1)
B(3,54,-2,leaves:1)
B(2,29,-2,leaves:1)
B(2,60,-9,leaves:1)
B(2,28,-2,LOG:12)
B(2,61,-9,leaves:1)
B(2,27,-2,LOG:12)
B(2,62,-9,leaves:1)
B(2,26,-2,LOG:12)
B(2,25,-2,LOG:12)
B(-4,10,-6,leaves:1)
B(4,53,-3,leaves:1)
B(-4,12,-6,leaves:1)
B(-4,11,-6,leaves:1)
B(4,51,-3,leaves:1)
B(4,52,-3,leaves:1)
B(4,50,-3,leaves:1)
B(1,24,-3,leaves:1)
B(1,23,-3,leaves:1)
B(1,26,-3,leaves:1)
B(0,40,5,leaves:1)
B(1,25,-3,leaves:1)
B(1,20,-3,LOG:12)
B(1,22,-3,leaves:1)
B(1,21,-3,LOG:12)
B(8,55,-6,leaves:1)
B(8,54,-6,leaves:1)
B(8,53,-6,leaves:1)
B(8,56,-6,leaves:1)
B(8,57,-6,leaves:1)
B(0,42,5,leaves:1)
B(1,27,-3,LOG:12)
B(0,41,5,leaves:1)
B(1,28,-3,LOG:12)
B(1,29,-3,LOG:12)
B(0,43,5,leaves:1)
B(1,37,-3,leaves:1)
B(1,36,-3,leaves:1)
B(1,35,-3,leaves:1)
B(1,34,-3,leaves:1)
B(1,33,-3,leaves:1)
B(1,32,-3,leaves:1)
B(1,31,-3,leaves:1)
B(1,30,-3,LOG:12)
B(-1,-7,-5,LOG:12)
B(-1,-5,-5,LOG:12)
B(-1,-3,-5,LOG:12)
B(-1,-4,-5,LOG:12)
B(-1,-1,-5,LOG:12)
B(-1,-2,-5,LOG:12)
B(3,33,1,leaves:1)
B(3,36,1,leaves:1)
B(3,35,1,leaves:1)
B(3,30,1,leaves:1)
B(3,32,1,leaves:1)
B(3,31,1,leaves:1)
B(18,14,-6,leaves:1)
B(14,15,-5,leaves:1)
B(14,14,-5,leaves:1)
B(14,13,-5,leaves:1)
B(-9,14,1,leaves:1)
B(-9,15,1,leaves:1)
B(1,11,-3,LOG:12)
B(1,10,-3,LOG:12)
B(1,15,-3,LOG:12)
B(1,14,-3,LOG:12)
B(1,13,-3,LOG:12)
B(1,12,-3,LOG:12)
B(-1,50,-12,leaves:1)
B(-5,21,-8,leaves:1)
B(-5,20,-8,leaves:1)
B(-5,19,-8,leaves:1)
B(-5,18,-8,leaves:1)
B(14,16,-5,leaves:1)
B(0,24,1,leaves:1)
B(0,23,1,leaves:1)
B(0,25,1,leaves:1)
B(1,18,-3,LOG:12)
B(0,20,1,leaves:1)
B(1,19,-3,LOG:12)
B(3,54,1,leaves:1)
B(1,16,-3,LOG:12)
B(-5,11,-6,leaves:1)
B(0,22,1,leaves:1)
B(-5,10,-6,leaves:1)
B(1,17,-3,leaves:1)
B(0,21,1,leaves:1)
B(3,56,1,leaves:1)
B(3,55,1,leaves:1)
B(3,58,1,leaves:1)
B(3,57,1,leaves:1)
B(-1,11,-5,LOG:12)
B(-1,12,-5,LOG:12)
B(-1,13,-5,LOG:12)
B(-1,14,-5,LOG:12)
B(-1,10,-5,leaves:1)
B(8,50,-8,leaves:1)
B(8,51,-8,leaves:1)
B(-5,15,-2,leaves:1)
B(1,1,0,LOG:12)
B(-5,14,-2,leaves:1)
B(1,2,0,LOG:12)
B(-5,13,-2,leaves:1)
B(1,0,0,LOG:12)
B(1,3,0,LOG:12)
B(1,4,0,LOG:12)
B(0,19,1,leaves:1)
B(-1,24,-5,leaves:1)
B(-1,25,-5,leaves:1)
B(-1,22,-5,LOG:12)
B(-1,23,-5,leaves:1)
B(-1,20,-5,leaves:1)
B(-1,21,-5,leaves:1)
B(-1,13,-4,leaves:1)
B(-1,12,-4,leaves:1)
B(-1,11,-4,leaves:1)
B(-1,10,-4,leaves:1)
B(11,16,-4,leaves:1)
B(11,17,-4,leaves:1)
B(11,14,-4,leaves:1)
B(11,15,-4,leaves:1)
B(4,43,-10,leaves:1)
B(-5,24,-2,leaves:1)
B(4,42,-10,leaves:1)
B(-5,23,-2,leaves:1)
B(4,41,-10,leaves:1)
B(4,40,-10,leaves:1)
B(-1,19,-5,leaves:1)
B(-1,18,-5,leaves:1)
B(-4,20,-1,leaves:1)
B(7,49,1,leaves:1)
B(-1,17,-5,LOG:12)
B(-1,16,-5,LOG:12)
B(-1,15,-5,LOG:12)
B(-4,21,-1,leaves:1)
B(-1,30,-5,leaves:1)
B(7,50,1,leaves:1)
B(-1,20,-4,leaves:1)
B(-1,21,-4,leaves:1)
B(-1,24,-4,leaves:1)
B(-1,23,-4,leaves:1)
B(-1,14,-4,leaves:1)
B(-1,26,-8,leaves:1)
B(-1,15,-4,leaves:1)
B(-1,28,-8,leaves:1)
B(-1,27,-8,leaves:1)
B(11,18,-4,leaves:1)
B(-1,27,-5,leaves:1)
B(3,29,1,leaves:1)
B(-1,26,-5,leaves:1)
B(-1,29,-5,leaves:1)
B(-1,28,-5,leaves:1)
B(-1,42,-5,leaves:1)
B(-1,43,-5,leaves:1)
B(-1,40,-5,leaves:1)
B(-1,41,-5,leaves:1)
B(-4,50,-1,leaves:1)
B(-1,44,-5,leaves:1)
B(-1,45,-5,leaves:1)
B(-1,30,-4,leaves:1)
B(2,61,-10,leaves:1)
B(1,-1,-3,LOG:12)
B(-1,29,-8,leaves:1)
B(8,48,-8,leaves:1)
B(1,-5,-3,LOG:12)
B(-1,27,-4,leaves:1)
B(8,47,-8,leaves:1)
B(-1,28,-4,leaves:1)
B(3,-7,-1,LOG:12)
B(1,-4,-3,LOG:12)
B(1,-3,-3,LOG:12)
B(-1,25,-4,leaves:1)
B(8,49,-8,leaves:1)
B(1,-2,-3,LOG:12)
B(-1,26,-4,leaves:1)
B(-1,29,-4,leaves:1)
B(1,-6,-3,LOG:12)
B(3,15,1,leaves:1)
B(3,16,1,leaves:1)
B(3,17,1,leaves:1)
B(3,-1,-1,LOG:12)
B(3,18,1,leaves:1)
B(-4,48,-1,leaves:1)
B(3,-4,-1,LOG:12)
B(-4,47,-1,leaves:1)
B(3,-5,-1,LOG:12)
B(0,-1,1,LOG:12)
B(5,42,-12,leaves:1)
B(5,41,-12,leaves:1)
B(5,40,-12,leaves:1)
B(-4,-6,-5,LOG:12)
B(-4,-4,-5,LOG:12)
B(0,2,0,leaves:2)
B(-4,-5,-5,LOG:12)
B(0,0,0,LOG:12)
B(0,1,0,leaves:2)
B(-1,58,-5,leaves:1)
B(-1,57,-5,leaves:1)
B(-1,56,-5,leaves:1)
B(-6,40,-6,leaves:1)
B(-6,41,-6,leaves:1)
B(-1,59,-5,leaves:1)
B(5,39,-12,leaves:1)
B(16,33,-7,leaves:1)
B(6,33,-5,leaves:1)
B(6,34,-5,leaves:1)
B(-3,9,1,leaves:1)
B(-4,14,-1,leaves:1)
B(-4,15,-1,leaves:1)
B(-4,16,-1,leaves:1)
B(-4,17,-1,leaves:1)
B(-4,18,-1,leaves:1)
B(-4,19,-1,leaves:1)
B(2,14,-8,leaves:1)
B(2,15,-8,leaves:1)
B(2,13,-8,leaves:1)
B(2,16,-8,leaves:1)
B(2,17,-8,leaves:1)
B(3,55,2,leaves:1)
B(2,-1,2,LOG:12)
B(3,54,2,leaves:1)
B(6,36,-5,leaves:1)
B(6,35,-5,leaves:1)
B(3,57,2,leaves:1)
B(6,38,-5,leaves:1)
B(6,37,-5,leaves:1)
B(3,-4,1,LOG:12)
B(3,-2,1,LOG:12)
B(3,-1,1,LOG:12)
B(2,23,-8,leaves:1)
B(2,24,-8,leaves:1)
B(2,25,-8,leaves:1)
B(1,34,-16,leaves:1)
B(6,58,-6,leaves:1)
B(6,59,-6,leaves:1)
B(1,30,-16,leaves:1)
B(-12,16,1,leaves:1)
B(-6,10,-6,leaves:1)
B(-2,2,1,leaves:2)
B(9,30,-5,leaves:1)
B(9,31,-5,leaves:1)
B(1,36,-16,leaves:1)
B(9,34,-5,leaves:1)
B(9,33,-5,leaves:1)
B(9,32,-5,leaves:1)
B(9,38,-5,leaves:1)
B(-2,1,1,leaves:2)
B(9,36,-5,leaves:1)
B(6,55,-6,leaves:1)
B(6,57,-6,leaves:1)
B(6,56,-6,leaves:1)
B(-1,21,4,leaves:1)
B(-1,20,4,leaves:1)
B(1,26,-6,leaves:1)
B(1,27,-6,leaves:1)
B(6,60,-6,leaves:1)
B(-4,29,-7,leaves:1)
B(-4,27,-7,leaves:1)
B(-4,28,-7,leaves:1)
B(-12,18,1,leaves:1)
B(-6,20,-8,leaves:1)
B(-4,20,-7,leaves:1)
B(-4,21,-7,leaves:1)
B(-6,22,-6,leaves:1)
B(-6,23,-6,leaves:1)
B(-6,24,-6,leaves:1)
B(-4,17,-7,leaves:1)
B(-6,25,-6,leaves:1)
B(-4,18,-7,leaves:1)
B(-4,19,-7,leaves:1)
B(1,43,-3,leaves:1)
B(1,44,-3,leaves:1)
B(1,41,-3,leaves:1)
B(-1,22,4,leaves:1)
B(1,42,-3,leaves:1)
B(-1,23,4,leaves:1)
B(-6,19,-8,leaves:1)
B(1,45,-3,leaves:1)
B(-6,17,-8,leaves:1)
B(-6,18,-8,leaves:1)
B(-4,9,-6,leaves:1)
B(-2,3,-3,LOG:12)
B(0,40,2,leaves:1)
B(-2,1,-3,LOG:12)
B(0,41,2,leaves:1)
B(-2,2,-3,LOG:12)
B(-2,0,-3,LOG:12)
B(-2,9,-3,leaves:1)
B(1,19,-4,leaves:1)
B(1,17,-4,leaves:1)
B(1,18,-4,leaves:1)
B(3,49,-4,leaves:1)
B(3,48,-4,log)
B(-1,51,-11,leaves:1)
B(3,42,-4,log)
B(-1,50,-11,leaves:1)
B(3,43,-4,log)
B(0,61,-6,leaves:1)
B(3,40,-4,log)
B(-4,27,-5,leaves:1)
B(0,62,-6,leaves:1)
B(3,41,-4,log)
B(-4,28,-5,leaves:1)
B(3,46,-4,log)
B(3,47,-4,log)
B(-4,26,-5,leaves:1)
B(3,44,-4,log)
B(-4,23,-5,leaves:1)
B(3,45,-4,log)
B(-4,24,-5,leaves:1)
B(1,12,-4,leaves:1)
B(1,11,-4,leaves:1)
B(1,10,-4,leaves:1)
B(-3,10,2,leaves:1)
B(1,16,-4,leaves:1)
B(1,15,-4,leaves:1)
B(1,13,-4,leaves:1)
B(1,30,-12,leaves:1)
B(1,28,-4,leaves:1)
B(1,31,-12,leaves:1)
B(1,29,-4,LOG:12)
B(-3,11,2,leaves:1)
B(3,38,-4,log)
B(3,37,-4,log)
B(1,36,-12,leaves:1)
B(-4,20,1,leaves:1)
B(3,39,-4,log)
B(-4,21,1,leaves:1)
B(1,34,-12,leaves:1)
B(1,35,-12,leaves:1)
B(1,32,-12,leaves:1)
B(3,30,-4,LOG:12)
B(3,31,-4,leaves:1)
B(-4,18,1,leaves:1)
B(3,32,-4,leaves:1)
B(3,33,-4,leaves:1)
B(1,32,-6,leaves:1)
B(3,34,-4,leaves:1)
B(1,31,-6,leaves:1)
B(3,35,-4,log)
B(1,30,-6,leaves:1)
B(3,36,-4,leaves:1)
B(1,21,-4,leaves:1)
B(1,20,-4,leaves:1)
B(-1,48,-11,leaves:1)
B(1,34,-6,leaves:1)
B(1,23,-4,leaves:1)
B(-1,47,-11,leaves:1)
B(1,33,-6,leaves:1)
B(1,25,-4,leaves:1)
B(-4,19,1,leaves:1)
B(1,24,-4,leaves:1)
B(1,27,-4,LOG:12)
B(1,26,-4,leaves:1)
B(-3,13,-3,leaves:1)
B(-3,14,-3,leaves:1)
B(0,16,0,leaves:1)
B(0,15,0,leaves:1)
B(-3,12,-3,leaves:1)
B(-3,22,-7,leaves:1)
B(3,29,-4,leaves:1)
B(-3,21,-7,leaves:1)
B(3,28,-4,leaves:1)
B(-3,20,-7,leaves:1)
B(-3,15,-3,leaves:1)
B(3,27,-4,leaves:1)
B(3,26,-4,leaves:1)
B(1,30,-4,LOG:12)
B(3,24,-4,leaves:1)
B(1,62,-6,leaves:1)
B(4,18,11,leaves:1)
B(3,25,-4,leaves:1)
B(-3,19,-7,leaves:1)
B(3,22,-4,leaves:1)
B(3,23,-4,leaves:1)
B(3,20,-4,leaves:1)
B(-3,18,-7,leaves:1)
B(3,21,-4,leaves:1)
B(1,61,-6,leaves:1)
B(-3,15,-7,leaves:1)
B(6,45,1,leaves:1)
B(1,38,-4,leaves:1)
B(6,46,1,leaves:1)
B(1,37,-4,leaves:1)
B(1,35,-4,log)
B(6,49,1,leaves:1)
B(1,34,-4,LOG:12)
B(1,33,-4,LOG:12)
B(6,47,1,leaves:1)
B(1,32,-4,LOG:12)
B(6,48,1,leaves:1)
B(1,31,-4,LOG:12)
B(3,61,-1,leaves:1)
B(3,19,-4,leaves:1)
B(-3,14,-7,leaves:1)
B(-3,13,-7,leaves:1)
B(3,16,-4,leaves:1)
B(3,18,-4,leaves:1)
B(3,17,-4,leaves:1)
B(1,47,-4,leaves:1)
B(1,46,-4,leaves:1)
B(1,49,-4,leaves:1)
B(1,48,-4,leaves:1)
B(1,43,-4,leaves:1)
B(1,42,-4,leaves:1)
B(1,45,-4,leaves:1)
B(1,44,-4,leaves:1)
B(-7,25,-6,leaves:1)
B(-3,38,-3,leaves:1)
B(-3,37,-3,leaves:1)
B(5,-1,-2,LOG:12)
B(-3,36,-3,leaves:1)
B(1,3,-1,LOG:12)
B(-7,22,-6,leaves:1)
B(-3,35,-3,leaves:1)
B(4,0,-3,LOG:12)
B(1,4,-1,LOG:12)
B(-7,21,-6,leaves:1)
B(-3,34,-3,leaves:1)
B(0,9,-6,leaves:1)
B(-7,24,-6,leaves:1)
B(-3,33,-3,leaves:1)
B(1,2,-1,LOG:12)
B(-7,23,-6,leaves:1)
B(1,7,-1,LOG:12)
B(1,8,-1,LOG:12)
B(1,5,-1,LOG:12)
B(1,6,-1,LOG:12)
B(1,9,-1,LOG:12)
B(1,53,-4,leaves:1)
B(1,51,-4,leaves:1)
B(1,52,-4,leaves:1)
B(1,50,-4,leaves:1)
B(-3,29,-3,leaves:1)
B(-8,50,0,leaves:1)
B(-3,30,-3,leaves:1)
B(-7,20,-6,leaves:1)
B(-3,31,-3,leaves:1)
B(0,2,1,leaves:2)
B(-3,32,-3,leaves:1)
B(0,1,1,leaves:2)
B(-8,19,0,leaves:1)
B(-8,14,0,leaves:1)
B(-8,15,0,leaves:1)
B(-8,16,0,leaves:1)
B(-8,17,0,leaves:1)
B(1,18,-12,leaves:1)
B(1,19,-12,leaves:1)
B(9,20,-4,leaves:1)
B(6,25,-13,leaves:1)
B(3,-1,-4,LOG:12)
B(1,17,-12,leaves:1)
B(-4,21,-5,leaves:1)
B(3,-4,-4,LOG:12)
B(-4,22,-5,leaves:1)
B(9,18,-4,leaves:1)
B(-1,27,-11,leaves:1)
B(-1,28,-11,leaves:1)
B(9,17,-4,leaves:1)
B(9,19,-4,leaves:1)
B(-1,26,-11,leaves:1)
B(9,16,-4,leaves:1)
B(5,10,-2,leaves:1)
B(0,20,4,leaves:1)
B(0,21,4,leaves:1)
B(0,22,4,leaves:1)
B(3,17,-1,leaves:1)
B(-13,13,2,leaves:1)
B(3,16,-1,leaves:1)
B(3,13,-1,LOG:12)
B(-13,16,2,leaves:1)
B(3,12,-1,LOG:12)
B(3,10,-1,LOG:12)
B(2,59,-12,leaves:1)
B(3,11,-1,LOG:12)
B(-1,2,1,leaves:2)
B(-1,1,1,leaves:2)
B(5,19,-2,leaves:1)
B(5,15,-2,leaves:1)
B(5,16,-2,leaves:1)
B(5,17,-2,leaves:1)
B(5,18,-2,leaves:1)
B(5,11,-2,leaves:1)
B(1,18,-1,leaves:1)
B(5,21,-2,leaves:1)
B(1,19,-1,leaves:1)
B(5,20,-2,leaves:1)
B(1,16,-1,leaves:1)
B(1,17,-1,leaves:1)
B(0,19,4,leaves:1)
B(2,36,-10,leaves:1)
B(2,38,-10,leaves:1)
B(2,37,-10,leaves:1)
B(2,32,-10,leaves:1)
B(7,50,-8,leaves:1)
B(2,31,-10,leaves:1)
B(2,34,-10,leaves:1)
B(2,33,-10,leaves:1)
B(5,28,-2,leaves:1)
B(1,11,-1,LOG:12)
B(5,29,-2,leaves:1)
B(1,10,-1,LOG:12)
B(7,51,-8,leaves:1)
B(2,30,-10,leaves:1)
B(5,26,-2,leaves:1)
B(7,52,-8,leaves:1)
B(5,27,-2,leaves:1)
B(5,24,-2,leaves:1)
B(5,25,-2,leaves:1)
B(5,22,-2,leaves:1)
B(0,44,4,leaves:1)
B(2,17,-3,leaves:1)
B(2,18,-3,LOG:12)
B(2,15,-3,LOG:12)
B(2,16,-3,LOG:12)
B(0,40,4,leaves:1)
B(0,41,4,leaves:1)
B(0,42,4,leaves:1)
B(2,19,-3,LOG:12)
B(0,43,4,leaves:1)
B(2,10,-3,LOG:12)
B(2,14,-3,LOG:12)
B(2,13,-3,LOG:12)
B(2,12,-3,LOG:12)
B(2,11,-3,LOG:12)
B(4,-1,-1,LOG:12)
B(4,-2,-1,LOG:12)
B(2,56,-10,leaves:1)
B(2,58,-10,leaves:1)
B(3,8,-1,LOG:12)
B(2,57,-10,leaves:1)
B(3,7,-1,LOG:12)
B(2,59,-10,leaves:1)
B(3,9,-1,LOG:12)
B(3,4,-1,LOG:12)
B(3,1,2,leaves:2)
B(3,3,-1,LOG:12)
B(3,6,-1,LOG:12)
B(3,5,-1,LOG:12)
B(-4,-5,-4,LOG:12)
B(0,26,-6,leaves:1)
B(0,25,-6,leaves:1)
B(0,24,-6,leaves:1)
B(0,23,-6,leaves:1)
B(0,50,-10,leaves:1)
B(3,59,-1,leaves:1)
B(-3,1,-4,LOG:12)
B(3,56,-1,leaves:1)
B(0,28,-6,leaves:1)
B(1,-1,-4,LOG:12)
B(-3,0,-4,LOG:12)
B(3,57,-1,leaves:1)
B(0,27,-6,leaves:1)
B(-3,9,-4,leaves:1)
B(-13,34,-2,leaves:1)
B(-1,9,-3,leaves:1)
B(0,48,-10,leaves:1)
B(5,49,0,leaves:1)
B(0,49,-10,leaves:1)
B(4,20,-1,leaves:1)
B(4,21,-1,leaves:1)
B(3,55,-1,leaves:1)
B(1,-4,-4,LOG:12)
B(-1,0,-3,LOG:12)
B(3,54,-1,leaves:1)
B(1,-3,-4,LOG:12)
B(-1,1,-3,LOG:12)
B(1,-5,-4,LOG:12)
B(5,47,0,leaves:1)
B(-13,30,-2,leaves:1)
B(5,46,0,leaves:1)
B(-1,2,-3,leaves:2)
B(4,32,4,leaves:1)
B(0,13,-6,leaves:1)
B(4,31,4,leaves:1)
B(0,12,-6,leaves:1)
B(4,30,4,leaves:1)
B(0,15,-6,leaves:1)
B(0,14,-6,leaves:1)
B(-3,14,-8,leaves:1)
B(0,17,-6,leaves:1)
B(0,16,-6,leaves:1)
B(-3,15,-8,leaves:1)
B(-3,13,-8,leaves:1)
B(1,-5,-1,LOG:12)
B(1,-4,-1,LOG:12)
B(1,-7,-1,LOG:12)
B(-5,40,-6,leaves:1)
B(1,-6,-1,LOG:12)
B(-5,41,-6,leaves:1)
B(1,-1,-1,LOG:12)
B(-5,42,-6,leaves:1)
B(-3,60,-6,leaves:1)
B(0,47,-10,leaves:1)
B(-5,43,-6,leaves:1)
B(0,11,-6,leaves:1)
B(1,-3,-1,LOG:12)
B(-5,44,-6,leaves:1)
B(0,10,-6,leaves:1)
B(1,-2,-1,LOG:12)
B(1,8,-10,leaves:1)
B(1,9,-10,leaves:1)
B(-3,59,-6,leaves:1)
B(1,-4,1,LOG:12)
B(1,-1,1,LOG:12)
B(4,33,4,leaves:1)
B(4,34,4,leaves:1)
B(3,36,-1,leaves:1)
B(-3,23,-8,leaves:1)
B(3,37,-1,leaves:1)
B(-3,24,-8,leaves:1)
B(3,34,-1,leaves:1)
B(3,35,-1,leaves:1)
B(2,-4,-3,LOG:12)
B(2,-3,-3,LOG:12)
B(2,-2,-3,LOG:12)
B(2,-1,-3,LOG:12)
B(7,48,-8,leaves:1)
B(7,49,-8,leaves:1)
B(2,-5,-3,LOG:12)
B(0,-1,0,LOG:12)
B(0,-2,0,LOG:12)
B(7,47,-8,leaves:1)
B(0,-3,0,LOG:12)
B(2,0,-4,LOG:12)
B(3,33,-1,leaves:1)
B(3,32,-1,leaves:1)
B(-3,16,-8,leaves:1)
B(4,28,4,leaves:1)
B(-3,34,-8,leaves:1)
B(-3,32,-8,leaves:1)
B(-3,33,-8,leaves:1)
B(4,19,-1,leaves:1)
B(-3,31,-8,leaves:1)
B(0,31,-6,leaves:1)
B(4,16,-1,leaves:1)
B(0,30,-6,leaves:1)
B(4,18,-1,leaves:1)
B(0,32,-6,leaves:1)
B(4,17,-1,leaves:1)
B(5,42,-2,leaves:1)
B(5,43,-2,leaves:1)
B(5,41,-2,leaves:1)
B(-5,12,-6,leaves:1)
B(3,20,-1,leaves:1)
B(3,21,-1,leaves:1)
B(0,33,-7,leaves:1)
B(0,34,-7,leaves:1)
B(0,31,-7,leaves:1)
B(-3,19,-6,leaves:1)
B(0,32,-7,leaves:1)
B(1,16,1,leaves:1)
B(-3,18,-6,leaves:1)
B(-3,17,-6,leaves:1)
B(0,30,-7,leaves:1)
B(3,18,9,leaves:1)
B(3,17,9,leaves:1)
B(3,16,9,leaves:1)
B(3,15,9,leaves:1)
B(1,1,1,leaves:2)
B(1,0,1,LOG:12)
B(3,19,9,leaves:1)
B(0,23,-7,leaves:1)
B(1,25,1,leaves:1)
B(0,29,-7,leaves:1)
B(0,19,3,leaves:1)
B(0,24,-7,leaves:1)
B(1,23,1,leaves:1)
B(0,25,-7,leaves:1)
B(4,40,-8,leaves:1)
B(5,37,-5,leaves:1)
B(4,41,-8,leaves:1)
B(5,38,-5,leaves:1)
B(4,42,-8,leaves:1)
B(5,39,-5,leaves:1)
B(4,43,-8,leaves:1)
B(4,44,-8,leaves:1)
B(0,20,3,leaves:1)
B(-5,51,-1,leaves:1)
B(0,21,3,leaves:1)
B(-5,52,-1,leaves:1)
B(0,22,3,leaves:1)
B(-5,53,-1,leaves:1)
B(0,23,3,leaves:1)
B(0,24,3,leaves:1)
B(0,18,-10,leaves:1)
B(0,17,-10,leaves:1)
B(11,27,0,leaves:1)
B(11,26,0,leaves:1)
B(11,25,0,leaves:1)
B(11,24,0,leaves:1)
B(1,-3,-5,LOG:12)
B(11,23,0,leaves:1)
B(1,-2,-5,LOG:12)
B(0,19,-10,leaves:1)
B(11,22,0,leaves:1)
B(0,20,-10,leaves:1)
B(-3,41,-6,leaves:1)
B(-3,42,-6,leaves:1)
B(4,51,-2,leaves:1)
B(4,50,-2,leaves:1)
B(-3,40,-6,leaves:1)
B(4,52,-2,leaves:1)
B(-3,43,-6,leaves:1)
B(-3,44,-6,leaves:1)
B(-5,47,-1,leaves:1)
B(6,18,-3,leaves:1)
B(6,17,-3,leaves:1)
B(6,16,-3,leaves:1)
B(6,15,-3,leaves:1)
B(5,55,-5,leaves:1)
B(1,44,1,leaves:1)
B(5,54,-5,leaves:1)
B(1,45,1,leaves:1)
B(5,57,-5,leaves:1)
B(1,42,1,leaves:1)
B(5,56,-5,leaves:1)
B(1,43,1,leaves:1)
B(6,19,-3,leaves:1)
B(1,40,1,leaves:1)
B(1,41,1,leaves:1)
B(5,53,-5,leaves:1)
B(-5,48,-1,leaves:1)
B(-5,49,-1,leaves:1)
B(0,30,-10,leaves:1)
B(0,31,-10,leaves:1)
B(-6,14,0,leaves:1)
B(-6,15,0,leaves:1)
B(5,58,-5,leaves:1)
B(-6,16,0,leaves:1)
B(-6,17,0,leaves:1)
B(14,30,-6,leaves:1)
B(-5,50,-1,leaves:1)
B(14,32,-6,leaves:1)
B(14,34,-6,leaves:1)
B(14,33,-6,leaves:1)
B(14,35,-6,leaves:1)
B(3,4,-2,LOG:12)
B(2,20,-3,LOG:12)
B(3,5,-2,LOG:12)
B(2,21,-3,leaves:1)
B(3,2,-2,LOG:12)
B(3,3,-2,LOG:12)
B(2,24,-3,leaves:1)
B(2,25,-3,leaves:1)
B(2,22,-3,leaves:1)
B(2,23,-3,leaves:1)
B(0,43,3,leaves:1)
B(0,45,3,leaves:1)
B(11,42,0,leaves:1)
B(0,40,3,leaves:1)
B(3,8,-2,LOG:12)
B(11,43,0,leaves:1)
B(3,9,-2,LOG:12)
B(0,42,3,leaves:1)
B(11,40,0,leaves:1)
B(3,6,-2,LOG:12)
B(0,41,3,leaves:1)
B(11,41,0,leaves:1)
B(3,7,-2,LOG:12)
B(-8,36,-3,leaves:1)
B(2,29,-3,leaves:1)
B(2,28,-3,leaves:1)
B(2,27,-3,leaves:1)
B(2,26,-3,leaves:1)
B(-6,48,0,leaves:1)
B(-8,35,-3,leaves:1)
B(-6,47,0,leaves:1)
B(-8,34,-3,leaves:1)
B(3,28,-7,leaves:1)
B(1,40,-1,leaves:1)
B(2,30,-3,leaves:1)
B(3,27,-7,leaves:1)
B(1,41,-1,leaves:1)
B(2,31,-3,leaves:1)
B(3,26,-7,leaves:1)
B(1,42,-1,leaves:1)
B(2,32,-3,LOG:12)
B(3,25,-7,leaves:1)
B(1,43,-1,leaves:1)
B(2,33,-3,LOG:12)
B(1,44,-1,leaves:1)
B(2,34,-3,LOG:12)
B(1,45,-1,leaves:1)
B(2,35,-3,log)
B(2,36,-3,log)
B(7,36,-5,leaves:1)
B(-5,21,-1,leaves:1)
B(7,37,-5,leaves:1)
B(-5,20,-1,leaves:1)
B(7,34,-5,leaves:1)
B(4,49,-2,leaves:1)
B(7,35,-5,leaves:1)
B(4,48,-2,leaves:1)
B(4,47,-2,leaves:1)
B(4,46,-2,leaves:1)
B(7,38,-5,leaves:1)
B(4,45,-2,leaves:1)
B(4,43,-2,leaves:1)
B(4,41,-2,leaves:1)
B(4,42,-2,leaves:1)
B(7,33,-5,leaves:1)
B(4,40,-2,leaves:1)
B(7,32,-5,leaves:1)
B(7,31,-5,leaves:1)
B(7,30,-5,leaves:1)
B(2,38,-3,log)
B(2,37,-3,log)
B(2,39,-3,log)
B(-5,9,-6,leaves:1)
B(-5,19,-1,leaves:1)
B(2,42,-3,log)
B(-5,16,-1,leaves:1)
B(2,43,-3,log)
B(-5,15,-1,leaves:1)
B(2,40,-3,log)
B(-5,18,-1,leaves:1)
B(2,41,-3,log)
B(-5,17,-1,leaves:1)
B(-5,14,-1,leaves:1)
B(4,17,-2,leaves:1)
B(4,16,-2,leaves:1)
B(0,14,-13,leaves:1)
B(0,15,-13,leaves:1)
B(0,16,-13,leaves:1)
B(0,17,-13,leaves:1)
B(4,10,-2,leaves:1)
B(4,11,-2,leaves:1)
B(1,21,-1,leaves:1)
B(0,0,-2,LOG:12)
B(1,22,-1,leaves:1)
B(0,1,-2,LOG:12)
B(1,23,-1,leaves:1)
B(0,2,-2,leaves:2)
B(1,24,-1,leaves:1)
B(1,20,-1,leaves:1)
B(4,29,-8,leaves:1)
B(4,26,-2,leaves:1)
B(4,25,-2,leaves:1)
B(4,24,-2,leaves:1)
B(4,23,-2,leaves:1)
B(0,19,-13,leaves:1)
B(0,18,-13,leaves:1)
B(4,22,-8,leaves:1)
B(4,24,-8,leaves:1)
B(4,23,-8,leaves:1)
B(-3,11,-6,leaves:1)
B(-2,9,-6,leaves:1)
B(4,21,-2,leaves:1)
B(-3,10,-6,leaves:1)
B(4,22,-2,leaves:1)
B(4,25,-8,leaves:1)
B(-3,12,-6,leaves:1)
B(4,20,-2,leaves:1)
B(4,27,-8,leaves:1)
B(1,26,-1,leaves:1)
B(1,25,-1,leaves:1)
B(1,27,-1,leaves:1)
B(6,50,-7,leaves:1)
B(-7,50,0,leaves:1)
B(6,51,-7,leaves:1)
B(6,52,-7,leaves:1)
B(-7,51,0,leaves:1)
B(-7,47,0,leaves:1)
B(-7,48,0,leaves:1)
B(-7,49,0,leaves:1)
B(-3,-6,-2,LOG:12)
B(-2,-7,-4,LOG:12)
B(0,-1,-1,LOG:12)
B(0,-2,-5,LOG:12)
B(0,-2,-1,LOG:12)
B(0,-3,-1,LOG:12)
B(0,-3,-5,LOG:12)
B(0,-4,-1,LOG:12)
B(-2,-3,-4,LOG:12)
B(0,-5,-1,LOG:12)
B(-2,-4,-4,LOG:12)
B(-2,-5,-4,LOG:12)
B(6,47,-7,leaves:1)
B(-2,-6,-4,LOG:12)
B(6,49,-7,leaves:1)
B(6,48,-7,leaves:1)
B(1,20,-5,leaves:1)
B(0,-5,-5,LOG:12)
B(1,21,-5,leaves:1)
B(0,28,-4,leaves:1)
B(0,27,-4,leaves:1)
B(0,26,-4,leaves:1)
B(0,25,-4,leaves:1)
B(0,24,-4,leaves:1)
B(0,23,-4,leaves:1)
B(-3,9,2,leaves:1)
B(1,46,-7,leaves:1)
B(-2,12,-4,leaves:1)
B(-2,11,-4,leaves:1)
B(1,48,-7,leaves:1)
B(-2,10,-4,leaves:1)
B(1,47,-7,leaves:1)
B(1,49,-7,leaves:1)
B(1,57,-5,leaves:1)
B(1,56,-5,leaves:1)
B(1,55,-5,leaves:1)
B(1,59,-5,leaves:1)
B(1,58,-5,leaves:1)
B(4,-1,1,LOG:12)
B(12,16,-4,leaves:1)
B(12,15,-4,leaves:1)
B(12,14,-4,leaves:1)
B(12,13,-4,leaves:1)
B(0,15,-4,leaves:1)
B(0,14,-4,leaves:1)
B(0,17,-4,leaves:1)
B(0,16,-4,leaves:1)
B(0,11,-4,leaves:1)
B(0,10,-4,leaves:1)
B(0,13,-4,leaves:1)
B(0,12,-4,leaves:1)
B(-2,3,-2,leaves:2)
B(-2,2,-2,leaves:2)
B(-2,0,-2,LOG:12)
B(1,40,-5,leaves:1)
B(0,18,-4,leaves:1)
B(0,19,-4,leaves:1)
B(1,42,-5,leaves:1)
B(1,41,-5,leaves:1)
B(1,51,-7,leaves:1)
B(1,44,-5,leaves:1)
B(1,50,-7,leaves:1)
B(1,43,-5,leaves:1)
B(-2,9,-2,leaves:1)
B(1,45,-5,leaves:1)
B(1,53,-7,leaves:1)
B(1,52,-7,leaves:1)
B(13,17,-5,leaves:1)
B(6,21,-3,leaves:1)
B(-2,27,-4,leaves:1)
B(6,20,-3,leaves:1)
B(-2,26,-4,leaves:1)
B(-2,25,-4,leaves:1)
B(-2,24,-4,leaves:1)
B(-2,28,-4,leaves:1)
B(8,31,-5,leaves:1)
B(-3,29,-7,leaves:1)
B(8,32,-5,leaves:1)
B(-3,28,-7,leaves:1)
B(-3,27,-7,leaves:1)
B(8,30,-5,leaves:1)
B(-3,26,-7,leaves:1)
B(8,36,-5,leaves:1)
B(8,34,-5,leaves:1)
B(8,33,-5,leaves:1)
B(8,38,-5,leaves:1)
B(-3,30,-7,leaves:1)
B(1,27,-7,leaves:1)
B(1,28,-7,leaves:1)
B(1,29,-7,leaves:1)
B(1,23,-7,leaves:1)
B(1,24,-7,leaves:1)
B(1,25,-7,leaves:1)
B(-2,14,-4,leaves:1)
B(0,16,-1,leaves:1)
B(0,15,-1,leaves:1)
B(-2,13,-4,leaves:1)
B(-5,22,-10,leaves:1)
B(-2,16,-4,leaves:1)
B(0,18,-1,leaves:1)
B(-2,15,-4,leaves:1)
B(0,17,-1,leaves:1)
B(-2,18,-4,leaves:1)
B(-2,17,-4,leaves:1)
B(0,19,-1,leaves:1)
B(-2,19,-4,leaves:1)
B(13,16,-5,leaves:1)
B(-2,20,-4,leaves:1)
B(13,15,-5,leaves:1)
B(-2,21,-4,leaves:1)
B(13,14,-5,leaves:1)
B(-2,22,-4,leaves:1)
B(13,13,-5,leaves:1)
B(-2,23,-4,leaves:1)
B(3,50,-4,leaves:1)
B(-9,17,0,leaves:1)
B(-9,15,0,leaves:1)
B(3,54,-4,leaves:1)
B(3,53,-4,leaves:1)
B(3,52,-4,leaves:1)
B(1,19,-5,leaves:1)
B(3,51,-4,leaves:1)
B(1,18,-5,leaves:1)
B(3,58,-4,leaves:1)
B(3,57,-4,leaves:1)
B(3,56,-4,leaves:1)
B(3,55,-4,leaves:1)
B(3,59,-4,leaves:1)
B(0,16,-7,leaves:1)
B(1,16,-5,leaves:1)
B(0,17,-7,leaves:1)
B(1,17,-5,leaves:1)
B(1,15,-5,leaves:1)
B(0,10,-7,leaves:1)
B(0,20,-1,leaves:1)
B(-9,20,0,leaves:1)
B(0,12,-7,leaves:1)
B(0,11,-7,leaves:1)
B(0,-1,-4,LOG:12)
B(0,-2,-4,LOG:12)
B(0,-3,-4,LOG:12)
B(3,61,-4,leaves:1)
B(1,35,-15,leaves:1)
B(3,60,-4,leaves:1)
B(1,34,-15,leaves:1)
B(1,31,-15,leaves:1)
B(1,32,-15,leaves:1)
B(1,30,-15,leaves:1)
B(1,14,-7,leaves:1)
B(1,15,-7,leaves:1)
B(1,13,-7,leaves:1)
B(0,-5,-4,LOG:12)
B(0,-4,-4,LOG:12)
B(1,16,-7,leaves:1)
B(0,-6,-4,LOG:12)

#
# +-----------------------------------------------------------------+ #
# |                            BO3 checks                           | #
# +-----------------------------------------------------------------+ #
#

BlockCheck(0,-1,0,grass,dirt)

#
# +-----------------------------------------------------------------+ #
# |                             Branches                            | #
# +-----------------------------------------------------------------+ #
#

