
#
# +-----------------------------------------------------------------+ #
# |                            BO3 object                           | #
# +-----------------------------------------------------------------+ #
#

Author: NLBlackEagle

Description: Converted version of the BO2 40

Version: 3

SettingsMode: WriteDisable


#
# +-----------------------------------------------------------------+ #
# |                          Main settings                          | #
# +-----------------------------------------------------------------+ #
#

Tree: true

Frequency: 1

Rarity: 100.0

RotateRandomly: true

SpawnHeight: highestSolidBlock

SpawnHeightOffset: 0

SpawnHeightVariance: 0


# Height Limits for the BO3. #


MinHeight: 0

MaxHeight: 199


# Extrusion settings #


ExtrudeMode: None

ExtrudeThroughBlocks: air

MaxBranchDepth: 10

ExcludedBiomes: 


#
# +-----------------------------------------------------------------+ #
# |                      Source block settings                      | #
# +-----------------------------------------------------------------+ #
#

SourceBlocks: AIR,GRASS,DIRT,SAND

MaxPercentageOutsideSourceBlock: 0

OutsideSourceBlock: placeAnyway


#
# +-----------------------------------------------------------------+ #
# |                              Blocks                             | #
# +-----------------------------------------------------------------+ #
#

B(6,9,-8,leaves:1)
B(6,7,-8,leaves:1)
B(6,8,-8,leaves:1)
B(6,5,-8,leaves:1)
B(6,6,-8,leaves:1)
B(6,3,-8,LOG:12)
B(9,7,-7,leaves:1)
B(11,7,-6,leaves:1)
B(6,4,-8,LOG:12)
B(9,8,-7,leaves:1)
B(9,17,-7,leaves:1)
B(9,5,-7,leaves:1)
B(6,1,-8,LOG:12)
B(9,16,-7,leaves:1)
B(9,6,-7,leaves:1)
B(6,2,-8,LOG:12)
B(6,-1,-8,leaves:2)
B(9,18,-7,leaves:1)
B(9,4,-7,leaves:1)
B(6,0,-8,LOG:12)
B(9,13,-7,leaves:1)
B(9,12,-7,leaves:1)
B(9,15,-7,leaves:1)
B(9,14,-7,leaves:1)
B(9,8,-5,leaves:1)
B(6,-8,-8,LOG:12)
B(6,-7,-8,LOG:12)
B(6,-6,-8,LOG:12)
B(9,11,-7,leaves:1)
B(6,0,-6,leaves:2)
B(6,-5,-8,LOG:12)
B(6,-4,-8,LOG:12)
B(6,-3,-8,LOG:12)
B(6,-2,-8,LOG:12)
B(6,7,-6,leaves:1)
B(6,6,-6,leaves:1)
B(9,9,-5,leaves:1)
B(9,9,-10,leaves:1)
B(9,7,-10,leaves:1)
B(9,8,-10,leaves:1)
B(8,17,-7,leaves:1)
B(8,18,-7,leaves:1)
B(8,19,-7,leaves:1)
B(8,16,-7,leaves:1)
B(10,7,-7,leaves:1)
B(10,6,-7,leaves:1)
B(10,5,-7,leaves:1)
B(6,7,-10,leaves:1)
B(6,9,-10,leaves:1)
B(6,8,-10,leaves:1)
B(8,10,-7,leaves:1)
B(8,11,-7,leaves:1)
B(5,-6,-6,LOG:12)
B(5,-7,-6,LOG:12)
B(5,-1,-6,leaves:2)
B(10,4,-7,leaves:1)
B(6,0,-5,leaves:2)
B(7,23,-6,leaves:1)
B(4,5,-3,leaves:1)
B(7,22,-6,leaves:1)
B(4,4,-3,leaves:1)
B(9,9,-6,leaves:1)
B(9,8,-6,leaves:1)
B(6,11,-8,leaves:1)
B(6,10,-8,leaves:1)
B(4,4,-2,leaves:1)
B(6,0,-7,leaves:2)
B(6,1,-7,leaves:2)
B(6,6,-7,leaves:1)
B(10,15,-5,leaves:1)
B(6,7,-7,leaves:1)
B(6,5,-7,leaves:1)
B(6,18,-8,leaves:1)
B(6,19,-8,leaves:1)
B(7,24,-6,leaves:1)
B(6,8,-7,leaves:1)
B(6,16,-8,leaves:1)
B(6,17,-8,leaves:1)
B(10,16,-5,leaves:1)
B(6,9,-7,leaves:1)
B(6,22,-10,leaves:1)
B(6,23,-10,leaves:1)
B(6,20,-8,leaves:1)
B(3,6,-10,leaves:1)
B(6,21,-8,leaves:1)
B(3,7,-11,leaves:1)
B(3,6,-11,leaves:1)
B(3,5,-11,leaves:1)
B(6,24,-10,leaves:1)
B(7,14,-6,leaves:1)
B(7,15,-6,leaves:1)
B(9,19,-8,leaves:1)
B(8,-7,-7,LOG:12)
B(9,15,-8,leaves:1)
B(9,14,-8,leaves:1)
B(9,13,-8,leaves:1)
B(5,13,-4,leaves:1)
B(8,-6,-7,LOG:12)
B(8,-1,-7,leaves:2)
B(5,12,-4,leaves:1)
B(9,25,-8,leaves:1)
B(7,7,-7,leaves:1)
B(9,24,-8,leaves:1)
B(7,5,-7,leaves:1)
B(7,6,-7,leaves:1)
B(10,4,-6,leaves:1)
B(10,5,-6,leaves:1)
B(5,8,-7,leaves:1)
B(5,9,-7,leaves:1)
B(5,0,-8,leaves:2)
B(9,20,-8,leaves:1)
B(6,-6,-7,LOG:12)
B(5,0,-7,leaves:2)
B(9,21,-8,leaves:1)
B(9,22,-8,leaves:1)
B(9,23,-8,leaves:1)
B(5,1,-7,leaves:2)
B(6,-7,-7,LOG:12)
B(6,-1,-6,leaves:2)
B(6,-2,-7,LOG:12)
B(6,-1,-7,leaves:2)
B(6,-4,-7,LOG:12)
B(6,-3,-7,LOG:12)
B(7,-2,-7,LOG:12)
B(7,-1,-7,leaves:2)
B(5,-1,-5,leaves:2)
B(7,6,-10,leaves:1)
B(7,5,-10,leaves:1)
B(7,-5,-6,LOG:12)
B(7,-1,-6,leaves:2)
B(4,16,-7,leaves:1)
B(6,-7,-10,LOG:12)
B(7,-7,-6,LOG:12)
B(4,17,-7,leaves:1)
B(6,16,-10,leaves:1)
B(6,17,-10,leaves:1)
B(7,22,-9,leaves:1)
B(7,21,-9,leaves:1)
B(7,20,-9,leaves:1)
B(7,25,-9,leaves:1)
B(7,24,-9,leaves:1)
B(7,23,-9,leaves:1)
B(4,-1,-8,leaves:2)
B(4,-6,-8,LOG:12)
B(9,20,-11,leaves:1)
B(7,15,-7,leaves:1)
B(9,21,-11,leaves:1)
B(7,14,-7,leaves:1)
B(10,12,-7,leaves:1)
B(10,13,-7,leaves:1)
B(9,8,-4,leaves:1)
B(10,11,-7,leaves:1)
B(10,14,-7,leaves:1)
B(5,-1,-10,leaves:2)
B(10,15,-7,leaves:1)
B(4,-1,-9,leaves:2)
B(10,24,-8,leaves:1)
B(10,25,-8,leaves:1)
B(10,23,-8,leaves:1)
B(9,20,-13,leaves:1)
B(10,20,-8,leaves:1)
B(10,21,-8,leaves:1)
B(7,12,-7,leaves:1)
B(13,4,-6,leaves:1)
B(7,13,-7,leaves:1)
B(7,11,-7,leaves:1)
B(4,-1,-7,leaves:2)
B(8,20,-7,leaves:1)
B(8,21,-7,leaves:1)
B(10,23,-7,leaves:1)
B(8,22,-7,leaves:1)
B(8,23,-7,leaves:1)
B(7,17,-8,leaves:1)
B(7,18,-8,leaves:1)
B(7,15,-8,leaves:1)
B(7,16,-8,leaves:1)
B(7,17,-9,leaves:1)
B(7,16,-9,leaves:1)
B(7,19,-9,leaves:1)
B(7,18,-9,leaves:1)
B(7,10,-8,leaves:1)
B(7,12,-9,leaves:1)
B(7,13,-9,leaves:1)
B(5,-7,-10,LOG:12)
B(7,14,-9,leaves:1)
B(7,15,-9,leaves:1)
B(7,14,-8,leaves:1)
B(7,13,-8,leaves:1)
B(7,10,-9,leaves:1)
B(7,12,-8,leaves:1)
B(7,11,-9,leaves:1)
B(7,11,-8,leaves:1)
B(8,24,-7,leaves:1)
B(5,6,-9,leaves:1)
B(5,5,-9,leaves:1)
B(5,7,-9,leaves:1)
B(6,13,-4,leaves:1)
B(11,24,-7,leaves:1)
B(6,14,-4,leaves:1)
B(11,23,-7,leaves:1)
B(6,-5,-10,LOG:12)
B(6,-6,-10,LOG:12)
B(9,19,-13,leaves:1)
B(11,5,-6,leaves:1)
B(11,6,-6,leaves:1)
B(11,4,-6,leaves:1)
B(7,22,-7,leaves:1)
B(2,6,-11,leaves:1)
B(8,13,-8,leaves:1)
B(2,5,-11,leaves:1)
B(8,12,-8,leaves:1)
B(8,11,-8,leaves:1)
B(8,10,-8,leaves:1)
B(4,-1,-6,leaves:2)
B(6,16,-11,leaves:1)
B(6,17,-11,leaves:1)
B(6,18,-11,leaves:1)
B(5,19,-8,leaves:1)
B(5,18,-8,leaves:1)
B(4,11,-10,leaves:1)
B(5,7,-11,leaves:1)
B(4,12,-10,leaves:1)
B(5,8,-11,leaves:1)
B(4,13,-10,leaves:1)
B(5,7,-10,leaves:1)
B(5,8,-10,leaves:1)
B(8,18,-8,leaves:1)
B(11,5,-7,leaves:1)
B(8,19,-8,leaves:1)
B(8,16,-8,leaves:1)
B(8,17,-8,leaves:1)
B(8,14,-8,leaves:1)
B(8,15,-8,leaves:1)
B(8,22,-8,leaves:1)
B(8,21,-8,leaves:1)
B(8,24,-8,leaves:1)
B(8,23,-8,leaves:1)
B(10,8,-11,leaves:1)
B(5,6,-10,leaves:1)
B(10,7,-11,leaves:1)
B(5,5,-10,leaves:1)
B(8,20,-8,leaves:1)
B(5,20,-8,leaves:1)
B(5,-1,-9,leaves:2)
B(5,-2,-9,LOG:12)
B(5,14,-10,leaves:1)
B(5,13,-10,leaves:1)
B(5,12,-10,leaves:1)
B(5,11,-10,leaves:1)
B(8,25,-8,leaves:1)
B(9,4,-14,leaves:1)
B(10,12,-12,leaves:1)
B(10,13,-12,leaves:1)
B(10,14,-12,leaves:1)
B(9,5,-14,leaves:1)
B(7,-6,-10,LOG:12)
B(7,-1,-9,LOG:12)
B(3,-1,-7,leaves:2)
B(9,19,-11,leaves:1)
B(9,12,-11,leaves:1)
B(7,-5,-9,LOG:12)
B(9,11,-11,leaves:1)
B(7,-2,-9,LOG:12)
B(7,-3,-9,LOG:12)
B(9,15,-11,leaves:1)
B(9,14,-11,leaves:1)
B(9,13,-11,leaves:1)
B(11,11,-14,leaves:1)
B(11,12,-14,leaves:1)
B(11,13,-14,leaves:1)
B(12,13,-6,leaves:1)
B(8,19,-11,leaves:1)
B(12,14,-6,leaves:1)
B(12,11,-6,leaves:1)
B(12,12,-6,leaves:1)
B(8,6,-10,leaves:1)
B(8,7,-10,leaves:1)
B(8,4,-10,leaves:1)
B(7,6,-8,LOG:12)
B(8,5,-7,leaves:1)
B(7,1,-9,LOG:12)
B(7,2,-9,LOG:12)
B(7,7,-8,LOG:12)
B(8,9,-6,leaves:1)
B(9,23,-9,leaves:1)
B(6,19,-9,leaves:1)
B(7,4,-8,LOG:12)
B(8,8,-6,leaves:1)
B(9,24,-9,leaves:1)
B(7,5,-8,LOG:12)
B(7,0,-9,LOG:12)
B(5,-2,-8,LOG:12)
B(5,-1,-8,leaves:2)
B(7,8,-8,LOG:12)
B(7,9,-8,leaves:1)
B(7,9,-9,leaves:1)
B(10,10,-10,leaves:1)
B(7,7,-9,leaves:1)
B(8,10,-9,leaves:1)
B(4,10,-6,leaves:1)
B(11,19,-8,leaves:1)
B(7,8,-9,leaves:1)
B(7,5,-9,LOG:12)
B(7,2,-8,LOG:12)
B(8,9,-7,leaves:1)
B(8,12,-9,leaves:1)
B(7,6,-9,leaves:1)
B(7,3,-8,LOG:12)
B(8,8,-7,leaves:1)
B(8,11,-9,leaves:1)
B(7,3,-9,LOG:12)
B(7,0,-8,LOG:12)
B(8,7,-7,leaves:1)
B(8,14,-9,leaves:1)
B(8,6,-7,leaves:1)
B(7,4,-9,LOG:12)
B(7,1,-8,LOG:12)
B(8,13,-9,leaves:1)
B(8,15,-9,leaves:1)
B(10,18,-10,leaves:1)
B(8,16,-9,leaves:1)
B(8,17,-9,leaves:1)
B(8,8,-9,leaves:1)
B(8,18,-9,leaves:1)
B(8,9,-9,leaves:1)
B(8,19,-9,leaves:1)
B(8,6,-9,leaves:1)
B(8,7,-9,leaves:1)
B(10,17,-10,leaves:1)
B(8,5,-9,leaves:1)
B(10,16,-10,leaves:1)
B(8,7,-8,leaves:1)
B(5,-6,-8,LOG:12)
B(8,8,-8,leaves:1)
B(8,5,-8,leaves:1)
B(5,-3,-8,LOG:12)
B(6,12,-9,leaves:1)
B(8,6,-8,leaves:1)
B(5,-4,-8,LOG:12)
B(6,11,-9,leaves:1)
B(9,26,-9,leaves:1)
B(6,14,-9,leaves:1)
B(9,25,-9,leaves:1)
B(6,13,-9,leaves:1)
B(5,-8,-8,LOG:12)
B(6,15,-9,leaves:1)
B(9,4,-13,leaves:1)
B(9,5,-13,leaves:1)
B(9,6,-13,leaves:1)
B(3,9,-6,leaves:1)
B(5,11,-9,leaves:1)
B(7,18,-10,leaves:1)
B(7,-2,-8,LOG:12)
B(5,12,-3,leaves:1)
B(7,16,-10,leaves:1)
B(7,17,-10,leaves:1)
B(7,-1,-8,LOG:12)
B(5,13,-3,leaves:1)
B(7,-4,-8,LOG:12)
B(7,-3,-8,LOG:12)
B(4,0,-7,leaves:2)
B(11,20,-8,leaves:1)
B(11,21,-8,leaves:1)
B(8,25,-9,leaves:1)
B(8,24,-9,leaves:1)
B(8,23,-9,leaves:1)
B(8,22,-9,leaves:1)
B(8,21,-9,leaves:1)
B(8,20,-9,leaves:1)
B(5,-5,-7,LOG:12)
B(11,13,-6,leaves:1)
B(5,16,-12,leaves:1)
B(5,17,-12,leaves:1)
B(11,12,-6,leaves:1)
B(5,-3,-7,LOG:12)
B(5,-2,-7,LOG:12)
B(11,14,-6,leaves:1)
B(5,-8,-7,LOG:12)
B(5,-6,-7,LOG:12)
B(11,11,-6,leaves:1)
B(5,0,-6,leaves:2)
B(6,-1,-9,LOG:12)
B(4,8,-10,leaves:1)
B(6,-2,-9,LOG:12)
B(11,16,-11,leaves:1)
B(11,17,-11,leaves:1)
B(6,12,-5,leaves:1)
B(5,6,-6,leaves:1)
B(6,14,-6,leaves:1)
B(5,5,-6,leaves:1)
B(5,7,-12,leaves:1)
B(10,17,-6,leaves:1)
B(6,12,-6,leaves:1)
B(6,13,-6,leaves:1)
B(10,16,-6,leaves:1)
B(5,7,-4,leaves:1)
B(5,6,-4,leaves:1)
B(5,5,-4,leaves:1)
B(6,-6,-9,LOG:12)
B(6,14,-5,leaves:1)
B(11,15,-11,leaves:1)
B(5,4,-4,leaves:1)
B(6,13,-5,leaves:1)
B(6,-4,-9,LOG:12)
B(6,-3,-9,LOG:12)
B(6,15,-5,leaves:1)
B(6,-7,-9,LOG:12)
B(6,8,-11,leaves:1)
B(6,9,-11,leaves:1)
B(4,7,-10,leaves:1)
B(11,8,-11,leaves:1)
B(10,11,-13,leaves:1)
B(4,6,-10,leaves:1)
B(10,12,-13,leaves:1)
B(4,5,-10,leaves:1)
B(10,13,-13,leaves:1)
B(4,0,-8,leaves:2)
B(9,10,-5,leaves:1)
B(4,0,-6,leaves:2)
B(9,16,-9,leaves:1)
B(9,17,-9,leaves:1)
B(9,18,-9,leaves:1)
B(10,25,-10,leaves:1)
B(5,16,-7,leaves:1)
B(5,17,-7,leaves:1)
B(5,18,-7,leaves:1)
B(4,9,-6,leaves:1)
B(8,7,-12,leaves:1)
B(8,6,-12,leaves:1)
B(5,11,-7,leaves:1)
B(5,10,-7,leaves:1)
B(10,24,-10,leaves:1)
B(8,5,-12,leaves:1)
B(10,23,-10,leaves:1)
B(8,4,-12,leaves:1)
B(12,4,-6,leaves:1)
B(12,5,-6,leaves:1)
B(6,10,-7,leaves:1)
B(8,-6,-8,LOG:12)
B(8,-1,-8,leaves:2)
B(6,11,-7,leaves:1)
B(9,20,-12,leaves:1)
B(8,19,-6,leaves:1)
B(9,10,-6,leaves:1)
B(5,7,-5,leaves:1)
B(9,16,-6,leaves:1)
B(9,17,-6,leaves:1)
B(5,5,-5,leaves:1)
B(6,-1,-5,leaves:2)
B(8,10,-6,leaves:1)
B(5,6,-5,leaves:1)
B(9,21,-12,leaves:1)
B(9,11,-6,leaves:1)
B(6,17,-7,leaves:1)
B(10,7,-10,leaves:1)
B(6,18,-7,leaves:1)
B(10,8,-10,leaves:1)
B(10,9,-10,leaves:1)
B(8,13,-10,leaves:1)
B(8,14,-10,leaves:1)
B(8,11,-10,leaves:1)
B(8,12,-10,leaves:1)
B(8,15,-10,leaves:1)
B(8,20,-5,leaves:1)
B(8,19,-10,leaves:1)
B(8,21,-6,leaves:1)
B(8,20,-6,leaves:1)
B(3,-1,-6,leaves:2)
B(9,12,-12,leaves:1)
B(9,11,-12,leaves:1)
B(10,19,-8,leaves:1)
B(9,19,-12,leaves:1)
B(8,20,-10,leaves:1)
B(8,21,-10,leaves:1)
B(9,23,-10,leaves:1)
B(9,21,-10,leaves:1)
B(8,19,-5,leaves:1)
B(8,4,-11,leaves:1)
B(9,13,-10,leaves:1)
B(8,6,-11,leaves:1)
B(9,15,-10,leaves:1)
B(8,5,-11,leaves:1)
B(9,14,-10,leaves:1)
B(8,7,-11,leaves:1)
B(9,10,-10,leaves:1)
B(6,1,-9,LOG:12)
B(6,0,-9,LOG:12)
B(6,7,-9,leaves:1)
B(6,6,-9,leaves:1)
B(6,8,-9,leaves:1)
B(6,3,-9,LOG:12)
B(6,2,-9,LOG:12)
B(6,5,-9,leaves:1)
B(6,4,-9,LOG:12)

#
# +-----------------------------------------------------------------+ #
# |                            BO3 checks                           | #
# +-----------------------------------------------------------------+ #
#

BlockCheck(0,-2,0,Solid)
BlockCheck(0,-1,0,grass,dirt)
BlockCheck(0,-1,2,grass,dirt)
BlockCheck(2,-1,0,grass,dirt)
BlockCheck(-2,-1,0,grass,dirt)
BlockCheck(0,-1,-2,grass,dirt)
BlockCheck(0,-1,0,Solid)
BlockCheckNot(0,-1,0,air)

#
# +-----------------------------------------------------------------+ #
# |                             Branches                            | #
# +-----------------------------------------------------------------+ #
#

