
#
# +-----------------------------------------------------------------+ #
# |                            BO3 object                           | #
# +-----------------------------------------------------------------+ #
#

Author: NLBlackEagle

Description: Converted version of the BO2 49

Version: 3

SettingsMode: WriteDisable


#
# +-----------------------------------------------------------------+ #
# |                          Main settings                          | #
# +-----------------------------------------------------------------+ #
#

Tree: true

Frequency: 2

Rarity: 10.0

RotateRandomly: true

SpawnHeight: highestSolidBlock

SpawnHeightOffset: 0

SpawnHeightVariance: 0


# Height Limits for the BO3. #


MinHeight: 0

MaxHeight: 199


# Extrusion settings #


ExtrudeMode: None

ExtrudeThroughBlocks: air

MaxBranchDepth: 10

ExcludedBiomes: 


#
# +-----------------------------------------------------------------+ #
# |                      Source block settings                      | #
# +-----------------------------------------------------------------+ #
#

SourceBlocks: AIR,GRASS,DIRT,SAND

MaxPercentageOutsideSourceBlock: 0

OutsideSourceBlock: placeAnyway


#
# +-----------------------------------------------------------------+ #
# |                              Blocks                             | #
# +-----------------------------------------------------------------+ #
#

B(-5,-2,2,LOG:12)
B(-5,-1,2,LOG:12)
B(-5,-6,2,LOG:12)
B(-5,-5,2,LOG:12)
B(-1,39,-7,leaves:1)
B(-5,-4,2,LOG:12)
B(-5,-3,2,LOG:12)
B(-1,42,-7,leaves:1)
B(-5,74,3,leaves:1)
B(-5,73,3,leaves:1)
B(-5,72,3,leaves:1)
B(-5,71,3,leaves:1)
B(-5,70,3,leaves:1)
B(-1,40,-7,leaves:1)
B(-1,41,-7,leaves:1)
B(-1,3,0,LOG:12)
B(-1,2,0,LOG:12)
B(-5,58,3,log)
B(-5,59,3,log)
B(-5,66,3,leaves:1)
B(-5,65,3,leaves:1)
B(-1,35,-7,leaves:1)
B(-5,67,3,leaves:1)
B(-1,36,-7,leaves:1)
B(-5,62,3,log)
B(-2,-6,4,LOG:12)
B(-5,61,3,log)
B(-5,64,3,log)
B(-5,63,3,log)
B(-1,4,0,LOG:12)
B(-2,-2,4,LOG:12)
B(-2,-3,4,LOG:12)
B(-1,5,0,LOG:12)
B(5,40,8,leaves:1)
B(-5,60,3,log)
B(-1,6,0,LOG:12)
B(-2,-5,4,LOG:12)
B(-1,7,0,LOG:12)
B(-1,8,0,LOG:12)
B(-1,9,0,LOG:12)
B(-2,-1,4,LOG:12)
B(-5,56,3,leaves:1)
B(-5,55,3,leaves:1)
B(-5,54,3,leaves:1)
B(-5,40,3,leaves:1)
B(-5,42,3,leaves:1)
B(-5,41,3,leaves:1)
B(-5,44,3,leaves:1)
B(-5,43,3,leaves:1)
B(-18,25,-7,leaves:1)
B(-18,24,-7,leaves:1)
B(-18,23,-7,leaves:1)
B(-18,22,-7,leaves:1)
B(-18,21,-7,leaves:1)
B(-8,-1,2,LOG:12)
B(-1,21,-13,leaves:1)
B(-4,9,-4,leaves:2)
B(-1,22,-13,leaves:1)
B(-1,23,-13,leaves:1)
B(-8,-5,2,LOG:12)
B(-8,-3,2,LOG:12)
B(-1,20,-13,leaves:1)
B(-5,56,0,leaves:1)
B(-5,57,0,leaves:1)
B(-5,58,0,leaves:1)
B(-1,21,-7,leaves:2)
B(-1,20,-7,leaves:2)
B(-1,23,-7,leaves:2)
B(-1,22,-7,leaves:2)
B(-1,25,-7,leaves:1)
B(-1,24,-7,leaves:1)
B(-5,51,0,leaves:1)
B(-5,50,0,leaves:1)
B(-5,48,0,leaves:1)
B(-5,49,0,leaves:1)
B(-5,44,0,LOG:12)
B(-5,61,2,leaves:1)
B(-5,62,2,leaves:1)
B(-14,37,-3,leaves:1)
B(-5,63,2,leaves:1)
B(-14,38,-3,leaves:1)
B(-5,64,2,leaves:1)
B(-5,39,0,LOG:12)
B(-5,38,0,LOG:12)
B(-11,39,5,leaves:1)
B(-5,42,0,LOG:12)
B(-11,38,5,leaves:1)
B(-5,43,0,LOG:12)
B(-5,40,0,leaves:1)
B(-5,41,0,leaves:1)
B(-5,58,2,log)
B(-5,57,2,log)
B(-10,20,-8,leaves:1)
B(-14,39,-3,leaves:1)
B(-5,51,2,LOG:12)
B(-5,52,2,LOG:12)
B(-5,55,2,log)
B(-15,23,1,leaves:1)
B(-5,56,2,log)
B(-15,22,1,leaves:1)
B(-15,21,1,leaves:1)
B(-14,42,-3,leaves:1)
B(-5,53,2,leaves:1)
B(-5,54,2,leaves:1)
B(-14,40,-3,leaves:1)
B(-14,41,-3,leaves:1)
B(-15,25,1,leaves:1)
B(-15,24,1,leaves:1)
B(-11,24,5,leaves:1)
B(-11,25,5,leaves:1)
B(-11,26,5,leaves:1)
B(-11,23,5,leaves:1)
B(-11,26,-13,leaves:1)
B(-5,42,2,leaves:1)
B(-11,27,-13,leaves:1)
B(-5,43,2,leaves:1)
B(-5,44,2,leaves:1)
B(-10,37,-8,leaves:1)
B(-10,38,-8,leaves:1)
B(-10,39,-8,leaves:1)
B(-1,-6,-7,LOG:12)
B(-1,-4,-7,LOG:12)
B(-1,-3,-7,LOG:12)
B(-10,40,-8,leaves:1)
B(-5,38,2,leaves:1)
B(-5,37,2,leaves:1)
B(-10,21,-8,leaves:1)
B(-10,22,-8,leaves:1)
B(-1,-1,-7,LOG:12)
B(-1,-2,-7,LOG:12)
B(-8,37,2,leaves:1)
B(-8,36,2,leaves:1)
B(-8,35,2,leaves:1)
B(2,0,0,LOG:12)
B(-6,27,-10,leaves:1)
B(-8,46,2,leaves:1)
B(-8,47,2,leaves:1)
B(-8,48,2,leaves:1)
B(-6,25,-10,leaves:1)
B(-6,26,-10,leaves:1)
B(-6,21,-10,leaves:1)
B(-6,22,-10,leaves:1)
B(-5,13,2,LOG:12)
B(-5,14,2,LOG:12)
B(-18,19,4,leaves:1)
B(-5,15,2,LOG:12)
B(-5,16,2,LOG:12)
B(-8,39,2,leaves:1)
B(-8,38,2,leaves:1)
B(-18,18,4,leaves:1)
B(-8,54,2,leaves:1)
B(-8,55,2,leaves:1)
B(-8,52,2,leaves:1)
B(-8,53,2,leaves:1)
B(-8,58,2,leaves:1)
B(-8,59,2,leaves:1)
B(-8,57,2,leaves:1)
B(-5,12,2,LOG:12)
B(-8,50,2,leaves:1)
B(-5,11,2,LOG:12)
B(-8,51,2,leaves:1)
B(-5,10,2,LOG:12)
B(-11,24,-13,leaves:1)
B(-11,25,-13,leaves:1)
B(-8,49,2,leaves:1)
B(-5,-3,0,LOG:12)
B(-5,-4,0,LOG:12)
B(-8,63,2,leaves:1)
B(-8,64,2,leaves:1)
B(-8,65,2,leaves:1)
B(-8,60,2,leaves:1)
B(-8,61,2,leaves:1)
B(-5,-7,0,LOG:12)
B(-5,-5,0,LOG:12)
B(-5,-6,0,LOG:12)
B(10,20,6,leaves:1)
B(-18,20,4,leaves:1)
B(-11,40,5,leaves:1)
B(10,19,6,leaves:1)
B(10,18,6,leaves:1)
B(-11,47,5,leaves:1)
B(-11,49,5,leaves:1)
B(-11,48,5,leaves:1)
B(-1,-4,-2,LOG:12)
B(-1,-5,-2,LOG:12)
B(-1,-2,-2,LOG:12)
B(-1,-3,-2,LOG:12)
B(-1,-6,-2,LOG:12)
B(-1,-7,-2,LOG:12)
B(-7,68,8,leaves:1)
B(-7,69,8,leaves:1)
B(-7,62,8,leaves:1)
B(-7,63,8,leaves:1)
B(-7,60,8,leaves:1)
B(-7,61,8,leaves:1)
B(-6,-4,1,LOG:12)
B(-6,-5,1,LOG:12)
B(-6,-6,1,LOG:12)
B(-9,20,-9,leaves:1)
B(-9,21,-9,leaves:1)
B(-6,-2,1,LOG:12)
B(-7,58,8,leaves:1)
B(-7,59,8,leaves:1)
B(-7,50,8,leaves:1)
B(-7,51,8,leaves:1)
B(-7,52,8,leaves:1)
B(-7,48,8,leaves:1)
B(-7,49,8,leaves:1)
B(5,23,3,leaves:1)
B(5,24,3,leaves:1)
B(-12,23,-5,leaves:1)
B(-12,22,-5,leaves:1)
B(-7,35,8,leaves:1)
B(-7,36,8,leaves:1)
B(-7,37,8,leaves:1)
B(-7,38,8,leaves:1)
B(-7,39,8,leaves:1)
B(-1,11,-2,LOG:12)
B(-1,10,-2,LOG:12)
B(-9,34,-9,leaves:1)
B(-9,33,-9,leaves:1)
B(-9,35,-9,leaves:1)
B(-1,15,-2,LOG:12)
B(-1,14,-2,LOG:12)
B(-1,13,-2,LOG:12)
B(-1,12,-2,LOG:12)
B(5,31,3,leaves:1)
B(5,32,3,leaves:1)
B(5,30,3,leaves:1)
B(3,17,17,leaves:1)
B(-8,1,-5,LOG:12)
B(-8,0,-5,LOG:12)
B(-2,0,3,LOG:12)
B(-1,32,-2,leaves:1)
B(-1,33,-2,leaves:1)
B(-9,26,-6,leaves:1)
B(-9,25,-6,leaves:1)
B(-9,40,-6,leaves:1)
B(-1,39,-2,leaves:1)
B(-1,38,-2,leaves:1)
B(-9,39,-6,leaves:1)
B(-6,30,1,leaves:1)
B(4,41,3,leaves:1)
B(4,40,3,leaves:1)
B(-6,33,1,leaves:1)
B(-6,34,1,leaves:1)
B(-1,40,-2,leaves:1)
B(-6,31,1,leaves:1)
B(-6,32,1,leaves:1)
B(-6,36,1,leaves:1)
B(-6,35,1,leaves:1)
B(-6,38,1,LOG:12)
B(-6,39,1,leaves:1)
B(-7,70,8,leaves:1)
B(-1,52,-2,leaves:1)
B(-7,71,8,leaves:1)
B(11,16,8,leaves:1)
B(-1,53,-2,leaves:1)
B(11,17,8,leaves:1)
B(-6,40,1,leaves:1)
B(-1,54,-2,leaves:1)
B(11,18,8,leaves:1)
B(-6,41,1,LOG:12)
B(-1,55,-2,leaves:1)
B(-6,42,1,LOG:12)
B(-6,43,1,LOG:12)
B(-6,44,1,LOG:12)
B(-1,50,-2,leaves:1)
B(-6,45,1,LOG:12)
B(-1,51,-2,leaves:1)
B(-9,44,-6,leaves:1)
B(-9,43,-6,leaves:1)
B(-9,45,-6,leaves:1)
B(9,23,-3,leaves:1)
B(9,22,-3,leaves:1)
B(9,21,-3,leaves:1)
B(-2,58,4,leaves:1)
B(-2,59,4,leaves:1)
B(-2,57,4,leaves:1)
B(-2,61,4,leaves:1)
B(-2,60,4,leaves:1)
B(4,24,3,leaves:1)
B(4,26,3,leaves:1)
B(4,25,3,leaves:1)
B(-2,68,4,leaves:1)
B(-2,69,4,leaves:1)
B(4,31,3,leaves:1)
B(-2,71,4,leaves:1)
B(-2,73,4,leaves:1)
B(4,33,3,leaves:1)
B(-2,72,4,leaves:1)
B(4,32,3,leaves:1)
B(4,39,3,leaves:1)
B(-2,74,4,leaves:1)
B(4,38,3,leaves:1)
B(-2,36,4,leaves:1)
B(-2,37,4,leaves:1)
B(-2,35,4,leaves:1)
B(-2,44,4,leaves:1)
B(-2,43,4,leaves:1)
B(-2,42,4,leaves:1)
B(-2,49,4,leaves:1)
B(-2,45,4,leaves:1)
B(-2,46,4,leaves:1)
B(-2,47,4,leaves:1)
B(-2,48,4,leaves:1)
B(-2,53,4,leaves:1)
B(-2,52,4,leaves:1)
B(-2,54,4,leaves:1)
B(-7,23,8,leaves:1)
B(-7,22,8,leaves:1)
B(-7,25,8,leaves:1)
B(-7,24,8,leaves:1)
B(-2,24,4,leaves:1)
B(-2,26,4,leaves:1)
B(-2,25,4,leaves:1)
B(-2,28,4,leaves:1)
B(-2,27,4,leaves:1)
B(-2,29,4,leaves:1)
B(3,22,-5,leaves:1)
B(3,23,-5,leaves:1)
B(-13,19,-6,leaves:1)
B(-2,30,4,leaves:1)
B(-2,31,4,leaves:1)
B(-2,32,4,leaves:1)
B(-2,33,4,leaves:1)
B(-13,20,-6,leaves:1)
B(-11,24,6,leaves:1)
B(-11,23,6,leaves:1)
B(-11,22,6,leaves:1)
B(-11,21,6,leaves:1)
B(-8,35,3,leaves:1)
B(-8,36,3,leaves:1)
B(-7,-2,-5,LOG:12)
B(0,28,6,leaves:1)
B(-15,25,2,leaves:1)
B(-15,26,2,leaves:1)
B(0,29,6,leaves:1)
B(-15,27,2,leaves:1)
B(-8,33,3,leaves:1)
B(-8,34,3,leaves:1)
B(0,24,6,leaves:1)
B(0,25,6,leaves:1)
B(0,26,6,leaves:1)
B(0,27,6,leaves:1)
B(0,20,6,leaves:1)
B(0,21,6,leaves:1)
B(0,22,6,leaves:1)
B(-7,-5,-5,LOG:12)
B(0,23,6,leaves:1)
B(-7,-6,-5,LOG:12)
B(-7,-2,-8,LOG:12)
B(-4,27,-9,leaves:1)
B(11,22,-9,leaves:1)
B(11,23,-9,leaves:1)
B(11,20,-9,leaves:1)
B(11,21,-9,leaves:1)
B(-8,39,3,leaves:1)
B(-8,48,3,leaves:1)
B(-8,49,3,leaves:1)
B(-8,46,3,leaves:1)
B(-8,47,3,leaves:1)
B(-8,40,3,leaves:1)
B(-8,41,3,leaves:1)
B(-6,39,5,leaves:1)
B(-5,45,1,LOG:12)
B(-5,46,1,LOG:12)
B(-5,47,1,LOG:12)
B(-5,48,1,LOG:12)
B(-5,49,1,LOG:12)
B(-11,41,6,leaves:1)
B(-11,40,6,leaves:1)
B(-11,49,6,leaves:1)
B(6,32,4,leaves:1)
B(6,31,4,leaves:1)
B(6,30,4,leaves:1)
B(-6,41,5,leaves:1)
B(-6,40,5,leaves:1)
B(-6,43,5,leaves:1)
B(-6,42,5,leaves:1)
B(-6,45,5,leaves:1)
B(-5,51,1,leaves:1)
B(-6,44,5,leaves:1)
B(-5,50,1,LOG:12)
B(-6,47,5,leaves:1)
B(-5,53,1,leaves:1)
B(-6,46,5,leaves:1)
B(-5,52,1,leaves:1)
B(-6,49,5,leaves:1)
B(-6,48,5,leaves:1)
B(-5,36,1,leaves:1)
B(-5,35,1,leaves:1)
B(-6,34,5,leaves:1)
B(-6,33,5,leaves:1)
B(-5,44,1,leaves:1)
B(-5,43,1,leaves:1)
B(-5,42,1,leaves:1)
B(-6,35,5,leaves:1)
B(-5,41,1,leaves:1)
B(-6,68,5,leaves:1)
B(-6,69,5,leaves:1)
B(0,65,6,leaves:1)
B(-6,64,5,leaves:1)
B(-6,65,5,leaves:1)
B(-6,66,5,leaves:1)
B(-6,67,5,leaves:1)
B(-6,60,5,log)
B(-6,61,5,log)
B(-6,62,5,log)
B(-6,63,5,log)
B(-5,59,1,leaves:1)
B(-6,59,5,log)
B(-6,57,5,log)
B(-6,58,5,log)
B(-5,61,1,leaves:1)
B(-6,55,5,leaves:1)
B(-6,56,5,leaves:1)
B(-5,60,1,leaves:1)
B(-6,54,5,leaves:1)
B(-6,50,5,leaves:1)
B(-4,8,-5,LOG:12)
B(-4,7,-5,LOG:12)
B(-4,9,-5,LOG:12)
B(-4,4,-5,LOG:12)
B(-1,-6,0,LOG:12)
B(-4,6,-5,LOG:12)
B(-1,-5,0,LOG:12)
B(-4,5,-5,LOG:12)
B(-1,-4,0,LOG:12)
B(-10,42,-7,leaves:1)
B(8,24,-1,leaves:1)
B(-6,80,5,leaves:1)
B(8,23,-1,leaves:1)
B(-6,81,5,leaves:1)
B(8,22,-1,leaves:1)
B(8,21,-1,leaves:1)
B(-8,-2,3,LOG:12)
B(-8,-3,3,LOG:12)
B(6,34,-2,leaves:1)
B(6,32,-2,leaves:1)
B(6,33,-2,leaves:1)
B(-10,41,-7,leaves:1)
B(0,30,6,leaves:1)
B(-6,77,5,leaves:1)
B(-6,78,5,leaves:1)
B(-6,75,5,leaves:1)
B(-6,76,5,leaves:1)
B(-6,79,5,leaves:1)
B(6,31,-2,leaves:1)
B(-6,70,5,leaves:1)
B(6,30,-2,leaves:1)
B(-6,73,5,log)
B(-6,71,5,leaves:1)
B(-6,72,5,log)
B(-10,23,-7,leaves:1)
B(-10,22,-7,leaves:1)
B(1,-4,0,LOG:12)
B(1,-3,0,LOG:12)
B(1,-2,0,LOG:12)
B(1,-1,0,LOG:12)
B(-10,24,-7,leaves:1)
B(6,34,-4,leaves:1)
B(6,35,-4,leaves:1)
B(6,36,-4,leaves:1)
B(6,37,-4,leaves:1)
B(-9,27,-12,leaves:1)
B(-9,26,-12,leaves:1)
B(-9,25,-12,leaves:1)
B(-9,24,-12,leaves:1)
B(-1,41,11,leaves:1)
B(-1,40,11,leaves:1)
B(-1,54,11,leaves:1)
B(-1,53,11,leaves:1)
B(-1,55,11,leaves:1)
B(2,22,-7,leaves:1)
B(2,20,-7,leaves:1)
B(2,21,-7,leaves:1)
B(-5,2,2,LOG:12)
B(1,-6,0,LOG:12)
B(-5,3,2,LOG:12)
B(-5,4,2,LOG:12)
B(-5,5,2,LOG:12)
B(-7,37,-8,leaves:1)
B(-5,0,2,LOG:12)
B(-5,1,2,LOG:12)
B(-5,6,2,LOG:12)
B(-5,7,2,LOG:12)
B(-5,8,2,LOG:12)
B(-5,9,2,LOG:12)
B(-1,29,11,leaves:1)
B(-7,31,-8,leaves:1)
B(-14,22,2,leaves:1)
B(-7,32,-8,leaves:1)
B(-14,23,2,leaves:1)
B(-7,33,-8,leaves:1)
B(-14,27,2,leaves:1)
B(-14,28,2,leaves:1)
B(-14,29,2,leaves:1)
B(2,19,-7,leaves:1)
B(-16,30,-4,leaves:1)
B(-16,31,-4,leaves:1)
B(-7,24,-8,leaves:1)
B(-7,23,-8,leaves:1)
B(-5,0,-8,LOG:12)
B(-5,1,-8,LOG:12)
B(2,27,4,leaves:1)
B(-1,37,11,leaves:1)
B(-1,38,11,leaves:1)
B(-1,39,11,leaves:1)
B(-16,28,-4,leaves:1)
B(-1,33,11,leaves:1)
B(-16,27,-4,leaves:1)
B(-1,34,11,leaves:1)
B(-16,29,-4,leaves:1)
B(-1,36,11,leaves:1)
B(-1,30,11,leaves:1)
B(2,28,4,leaves:1)
B(-1,31,11,leaves:1)
B(2,29,4,leaves:1)
B(-1,32,11,leaves:1)
B(-11,58,6,leaves:1)
B(-9,19,-15,leaves:1)
B(-5,-7,1,LOG:12)
B(-5,-6,1,LOG:12)
B(-5,-3,1,LOG:12)
B(-11,52,6,leaves:1)
B(-11,53,6,leaves:1)
B(-5,-5,1,LOG:12)
B(-11,50,6,leaves:1)
B(-5,-4,1,LOG:12)
B(-11,51,6,leaves:1)
B(-11,56,6,leaves:1)
B(-11,57,6,leaves:1)
B(-11,54,6,leaves:1)
B(-11,55,6,leaves:1)
B(1,36,0,leaves:1)
B(1,37,0,leaves:1)
B(1,38,0,leaves:1)
B(1,39,0,leaves:1)
B(1,32,0,leaves:1)
B(1,33,0,leaves:1)
B(1,31,0,leaves:1)
B(3,55,7,leaves:1)
B(3,53,7,leaves:1)
B(3,54,7,leaves:1)
B(0,37,-9,leaves:1)
B(1,40,0,leaves:1)
B(-3,42,9,leaves:1)
B(1,41,0,leaves:1)
B(-3,47,9,leaves:1)
B(-10,21,-14,leaves:1)
B(-10,20,-14,leaves:1)
B(-10,23,-14,leaves:1)
B(-3,43,9,leaves:1)
B(-10,22,-14,leaves:1)
B(-3,44,9,leaves:1)
B(-3,45,9,leaves:1)
B(-3,46,9,leaves:1)
B(0,20,-9,leaves:1)
B(0,21,-9,leaves:2)
B(1,51,0,leaves:1)
B(1,50,0,leaves:1)
B(1,53,0,leaves:1)
B(1,52,0,leaves:1)
B(1,55,0,leaves:1)
B(1,54,0,leaves:1)
B(1,56,0,leaves:1)
B(0,19,-9,leaves:2)
B(0,18,-9,leaves:2)
B(-5,30,-7,leaves:1)
B(-5,26,-7,leaves:1)
B(-4,36,-2,leaves:1)
B(-7,52,-2,leaves:1)
B(-5,27,-7,leaves:1)
B(-4,35,-2,leaves:1)
B(-7,53,-2,leaves:1)
B(-4,38,-2,leaves:1)
B(-7,50,-2,leaves:1)
B(-4,37,-2,leaves:1)
B(-7,51,-2,leaves:1)
B(-5,28,-7,leaves:1)
B(-3,64,9,leaves:1)
B(-5,29,-7,leaves:1)
B(-3,65,9,leaves:1)
B(-3,69,9,leaves:1)
B(-4,39,-2,leaves:1)
B(-4,52,-2,leaves:1)
B(-3,70,9,leaves:1)
B(-4,49,-2,leaves:1)
B(-3,71,9,leaves:1)
B(-7,62,-2,leaves:1)
B(-4,48,-2,leaves:1)
B(-5,37,-7,leaves:1)
B(-4,47,-2,leaves:1)
B(-5,38,-7,leaves:1)
B(-4,46,-2,leaves:1)
B(3,23,7,leaves:1)
B(-4,45,-2,leaves:1)
B(3,22,7,leaves:1)
B(-4,44,-2,leaves:1)
B(3,21,7,leaves:1)
B(-4,43,-2,leaves:1)
B(-4,81,6,leaves:1)
B(-4,80,6,leaves:1)
B(-5,69,2,leaves:1)
B(-5,71,2,leaves:1)
B(-7,35,-2,leaves:1)
B(-7,34,-2,leaves:1)
B(-7,33,-2,leaves:1)
B(-5,70,2,leaves:1)
B(4,20,-6,leaves:1)
B(-4,28,-2,LOG:12)
B(-4,29,-2,LOG:12)
B(-4,23,-2,LOG:12)
B(-7,43,-2,leaves:1)
B(-4,26,-2,LOG:12)
B(-7,40,-2,leaves:1)
B(-4,27,-2,LOG:12)
B(-4,24,-2,LOG:12)
B(-7,42,-2,leaves:1)
B(-4,25,-2,LOG:12)
B(-7,41,-2,leaves:1)
B(-13,19,-7,leaves:1)
B(-7,17,-2,LOG:12)
B(-7,16,-2,LOG:12)
B(-7,15,-2,LOG:12)
B(-7,14,-2,LOG:12)
B(-7,19,-2,LOG:12)
B(-7,18,-2,LOG:12)
B(-7,13,-2,LOG:12)
B(-7,12,-2,LOG:12)
B(-7,20,-2,LOG:12)
B(-7,21,-2,LOG:12)
B(-7,44,-5,leaves:1)
B(-7,45,-5,leaves:1)
B(-7,57,9,leaves:1)
B(-4,-2,-2,LOG:12)
B(-7,46,-5,leaves:1)
B(-7,56,9,leaves:1)
B(-7,47,-5,leaves:1)
B(-4,-6,-2,LOG:12)
B(-4,-5,-2,LOG:12)
B(-7,59,9,leaves:1)
B(-4,-4,-2,LOG:12)
B(-7,58,9,leaves:1)
B(-4,-3,-2,LOG:12)
B(-4,-8,-2,LOG:12)
B(-4,-7,-2,LOG:12)
B(-4,45,6,leaves:1)
B(-4,46,6,leaves:1)
B(-4,47,6,leaves:1)
B(-4,48,6,leaves:1)
B(-4,44,6,leaves:1)
B(-7,59,-5,leaves:1)
B(-7,46,9,leaves:1)
B(-7,58,-5,leaves:1)
B(-7,45,9,leaves:1)
B(-7,48,9,leaves:1)
B(-7,47,9,leaves:1)
B(-7,49,9,leaves:1)
B(-4,49,6,leaves:1)
B(-4,52,6,leaves:1)
B(-4,53,6,leaves:1)
B(-4,50,6,leaves:1)
B(-4,51,6,leaves:1)
B(-10,39,11,leaves:1)
B(-7,-2,-2,LOG:12)
B(-7,-3,-2,LOG:12)
B(-7,-4,-2,LOG:12)
B(-7,-5,-2,LOG:12)
B(-7,-6,-2,LOG:12)
B(-4,63,6,leaves:1)
B(-4,64,6,leaves:1)
B(-4,65,6,leaves:1)
B(-4,66,6,leaves:1)
B(-4,67,6,leaves:1)
B(-4,68,6,leaves:1)
B(-4,69,6,leaves:1)
B(-4,61,6,leaves:1)
B(-4,62,6,leaves:1)
B(-7,62,9,leaves:1)
B(-7,61,9,leaves:1)
B(-7,63,9,leaves:1)
B(-4,76,6,leaves:1)
B(-4,77,6,leaves:1)
B(-4,75,6,leaves:1)
B(-4,-3,-9,LOG:12)
B(-4,78,6,leaves:1)
B(-4,79,6,leaves:1)
B(-4,-4,-9,LOG:12)
B(-7,60,9,leaves:1)
B(-4,70,6,leaves:1)
B(-10,40,11,leaves:1)
B(-10,41,11,leaves:1)
B(-20,17,-8,leaves:1)
B(-8,70,3,leaves:1)
B(-8,72,3,leaves:1)
B(-8,71,3,leaves:1)
B(-3,24,9,leaves:1)
B(-8,60,3,leaves:1)
B(-3,23,9,leaves:1)
B(-3,22,9,leaves:1)
B(-7,29,-5,leaves:1)
B(-3,28,9,leaves:1)
B(-7,28,-5,leaves:1)
B(-3,27,9,leaves:1)
B(-7,36,9,leaves:1)
B(-3,25,9,leaves:1)
B(-7,34,9,leaves:1)
B(-8,68,3,leaves:1)
B(-7,35,9,leaves:1)
B(-7,32,9,leaves:1)
B(-7,33,9,leaves:1)
B(-8,67,3,leaves:1)
B(-8,66,3,leaves:1)
B(-7,30,-5,leaves:1)
B(-6,-1,-8,LOG:12)
B(-4,24,-9,leaves:1)
B(-4,23,-9,leaves:1)
B(-3,32,9,leaves:1)
B(-8,51,3,leaves:1)
B(-4,26,-9,leaves:1)
B(-8,50,3,leaves:1)
B(-4,25,-9,leaves:1)
B(-7,21,9,leaves:1)
B(-7,38,-5,leaves:1)
B(-8,59,3,leaves:1)
B(-7,22,9,leaves:1)
B(-7,37,-5,leaves:1)
B(-8,58,3,leaves:1)
B(-7,36,-5,leaves:1)
B(-8,57,3,leaves:1)
B(-8,56,3,leaves:1)
B(-3,31,9,leaves:1)
B(-7,20,9,leaves:1)
B(-3,30,9,leaves:1)
B(-3,29,9,leaves:1)
B(-4,33,6,leaves:1)
B(-4,32,6,leaves:1)
B(-4,37,6,leaves:1)
B(-4,36,6,leaves:1)
B(-4,35,6,leaves:1)
B(-4,34,6,leaves:1)
B(0,38,-8,leaves:1)
B(0,39,-8,leaves:1)
B(0,37,-8,leaves:1)
B(4,40,1,leaves:1)
B(4,41,1,leaves:1)
B(0,40,-8,leaves:1)
B(4,39,1,leaves:1)
B(-8,19,9,leaves:1)
B(-8,20,9,leaves:1)
B(-8,21,9,leaves:1)
B(4,27,1,leaves:1)
B(4,28,1,leaves:1)
B(4,29,1,leaves:1)
B(4,26,1,leaves:1)
B(-3,62,6,leaves:1)
B(-3,63,6,leaves:1)
B(-3,64,6,leaves:1)
B(-3,65,6,leaves:1)
B(-3,66,6,leaves:1)
B(-3,67,6,leaves:1)
B(-3,68,6,leaves:1)
B(-3,69,6,leaves:1)
B(-7,27,-11,leaves:1)
B(-7,26,-11,leaves:1)
B(-7,25,-11,leaves:1)
B(0,-7,2,LOG:12)
B(-14,38,4,leaves:1)
B(-14,37,4,leaves:1)
B(-2,57,-2,leaves:1)
B(0,-5,2,LOG:12)
B(-3,53,6,leaves:1)
B(-2,58,-2,leaves:1)
B(-3,54,6,leaves:1)
B(-2,55,-2,leaves:1)
B(-2,56,-2,leaves:1)
B(-14,33,4,leaves:1)
B(-13,52,6,leaves:1)
B(-3,52,6,leaves:1)
B(-14,32,4,leaves:1)
B(0,-2,2,LOG:12)
B(-14,31,4,leaves:1)
B(-2,59,-2,leaves:1)
B(-3,55,6,leaves:1)
B(-3,56,6,leaves:1)
B(-13,50,6,leaves:1)
B(-13,51,6,leaves:1)
B(-13,49,6,leaves:1)
B(-13,48,6,leaves:1)
B(-13,42,6,leaves:1)
B(-13,41,6,leaves:1)
B(-13,44,6,leaves:1)
B(-13,43,6,leaves:1)
B(-2,51,-2,leaves:1)
B(-13,40,6,leaves:1)
B(0,19,-8,leaves:2)
B(0,18,-8,leaves:2)
B(-3,71,6,leaves:1)
B(-3,72,6,leaves:1)
B(-3,70,6,leaves:1)
B(-13,39,6,leaves:1)
B(-13,38,6,leaves:1)
B(-13,37,6,leaves:1)
B(-3,75,6,leaves:1)
B(-2,35,-2,leaves:1)
B(-3,73,6,leaves:1)
B(-2,33,-2,leaves:1)
B(-3,74,6,leaves:1)
B(-2,34,-2,leaves:1)
B(-2,43,-2,leaves:1)
B(-2,42,-2,leaves:1)
B(-2,41,-2,leaves:1)
B(-2,40,-2,leaves:1)
B(0,22,-8,leaves:1)
B(0,21,-8,leaves:1)
B(-14,40,-2,leaves:1)
B(-16,23,0,leaves:1)
B(-3,4,-5,LOG:12)
B(-16,22,0,leaves:1)
B(-3,5,-5,LOG:12)
B(-16,21,0,leaves:1)
B(-3,2,-5,LOG:12)
B(-3,3,-5,LOG:12)
B(-16,20,0,leaves:1)
B(-3,8,-5,LOG:12)
B(-3,6,-5,LOG:12)
B(-3,7,-5,LOG:12)
B(-2,31,-2,leaves:1)
B(-14,41,-2,leaves:1)
B(-2,30,-2,leaves:1)
B(-2,25,-2,LOG:12)
B(-2,24,-2,LOG:12)
B(-2,23,-2,LOG:12)
B(-2,22,-2,LOG:12)
B(-9,61,1,leaves:1)
B(-2,29,-2,leaves:1)
B(-9,62,1,leaves:1)
B(-2,28,-2,leaves:1)
B(-2,27,-2,leaves:1)
B(-9,60,1,leaves:1)
B(-2,26,-2,leaves:1)
B(-9,63,1,leaves:1)
B(-2,20,-2,LOG:12)
B(-2,21,-2,LOG:12)
B(-2,16,-2,LOG:12)
B(-2,15,-2,LOG:12)
B(-2,18,-2,LOG:12)
B(-2,17,-2,LOG:12)
B(-2,19,-2,LOG:12)
B(7,25,1,leaves:1)
B(7,24,1,leaves:1)
B(7,23,1,leaves:1)
B(7,22,1,leaves:1)
B(0,-4,-8,LOG:12)
B(0,3,-1,LOG:12)
B(0,2,-1,LOG:12)
B(7,21,1,leaves:1)
B(0,6,-1,LOG:12)
B(0,5,-1,LOG:12)
B(0,4,-1,LOG:12)
B(-14,33,-2,leaves:1)
B(-1,-6,-4,LOG:12)
B(-14,32,-2,leaves:1)
B(-1,-5,-4,LOG:12)
B(-2,29,-9,leaves:1)
B(-1,-4,-4,LOG:12)
B(-1,-3,-4,LOG:12)
B(-14,37,-2,leaves:1)
B(-1,-2,-4,LOG:12)
B(-14,36,-2,leaves:1)
B(-14,35,-2,leaves:1)
B(-14,34,-2,leaves:1)
B(-2,32,-9,leaves:1)
B(-14,38,-2,leaves:1)
B(-14,39,-2,leaves:1)
B(-2,30,-9,leaves:1)
B(-2,31,-9,leaves:1)
B(3,19,-8,leaves:2)
B(-2,20,-9,leaves:2)
B(-14,38,5,leaves:1)
B(-14,39,5,leaves:1)
B(-14,33,5,leaves:1)
B(-2,22,-9,leaves:1)
B(-14,36,5,leaves:1)
B(-2,21,-9,leaves:1)
B(-14,37,5,leaves:1)
B(-14,34,5,leaves:1)
B(-2,23,-9,leaves:2)
B(-14,35,5,leaves:1)
B(-2,-5,-2,LOG:12)
B(-2,-6,-2,LOG:12)
B(-4,21,10,leaves:1)
B(-2,-7,-2,LOG:12)
B(-4,20,10,leaves:1)
B(3,20,-8,leaves:1)
B(-12,28,-12,leaves:1)
B(-4,23,10,leaves:1)
B(-4,22,10,leaves:1)
B(-2,-2,-2,LOG:12)
B(-4,25,10,leaves:1)
B(-2,-3,-2,LOG:12)
B(-4,24,10,leaves:1)
B(-2,-4,-2,LOG:12)
B(-1,18,14,leaves:1)
B(-4,36,10,leaves:1)
B(-1,19,14,leaves:1)
B(-4,39,10,leaves:1)
B(-4,38,10,leaves:1)
B(-4,37,10,leaves:1)
B(-16,19,0,leaves:1)
B(-11,28,-12,leaves:1)
B(-11,27,-12,leaves:1)
B(-11,29,-12,leaves:1)
B(12,17,-9,leaves:1)
B(12,18,-9,leaves:1)
B(12,19,-9,leaves:1)
B(-3,47,4,LOG:12)
B(-3,46,4,LOG:12)
B(-3,49,4,leaves:1)
B(-3,48,4,leaves:1)
B(-4,32,2,leaves:1)
B(-3,53,4,leaves:1)
B(-4,33,2,leaves:1)
B(-3,54,4,leaves:1)
B(-3,55,4,leaves:1)
B(-3,56,4,log)
B(-4,31,2,leaves:1)
B(-3,50,4,leaves:1)
B(-3,51,4,leaves:1)
B(-3,52,4,LOG:12)
B(1,27,-3,leaves:1)
B(1,28,-3,leaves:1)
B(1,29,-3,leaves:1)
B(-1,50,-4,leaves:1)
B(-1,51,-4,leaves:1)
B(-13,19,5,leaves:1)
B(-13,18,5,leaves:1)
B(-4,12,2,LOG:12)
B(-3,57,4,log)
B(-1,-7,-5,LOG:12)
B(-3,67,4,leaves:1)
B(-1,-8,-5,LOG:12)
B(-3,64,4,leaves:1)
B(-1,-5,-5,LOG:12)
B(-3,65,4,leaves:1)
B(-1,-6,-5,LOG:12)
B(-3,62,4,leaves:1)
B(-1,-3,-5,LOG:12)
B(-3,63,4,leaves:1)
B(-9,-2,1,LOG:12)
B(-1,-4,-5,LOG:12)
B(-9,-5,1,LOG:12)
B(-3,61,4,leaves:1)
B(-9,-4,1,LOG:12)
B(-3,27,4,leaves:1)
B(-3,26,4,leaves:1)
B(-3,28,4,leaves:1)
B(-12,16,15,leaves:1)
B(-12,18,15,leaves:1)
B(-12,17,15,leaves:1)
B(-12,19,15,leaves:1)
B(-10,57,-1,leaves:1)
B(-4,10,2,LOG:12)
B(-4,11,2,LOG:12)
B(-10,55,-1,leaves:1)
B(-10,56,-1,leaves:1)
B(-16,26,-3,leaves:1)
B(-16,27,-3,leaves:1)
B(-2,-4,1,LOG:12)
B(-16,28,-3,leaves:1)
B(-16,29,-3,leaves:1)
B(-2,-7,1,LOG:12)
B(-3,34,5,leaves:1)
B(-3,35,5,leaves:1)
B(-3,38,4,leaves:1)
B(-3,37,4,leaves:1)
B(-3,36,4,leaves:1)
B(-3,39,4,leaves:1)
B(-3,44,4,leaves:1)
B(-3,45,4,LOG:12)
B(-3,42,4,leaves:1)
B(5,19,6,leaves:1)
B(-3,43,4,leaves:1)
B(-9,37,1,leaves:1)
B(2,47,4,leaves:1)
B(-9,36,1,leaves:1)
B(2,46,4,leaves:1)
B(-9,35,1,leaves:1)
B(-9,34,1,leaves:1)
B(-9,32,1,leaves:1)
B(-9,31,1,leaves:1)
B(2,45,4,leaves:1)
B(5,20,6,leaves:1)
B(-9,30,1,leaves:1)
B(-3,44,5,leaves:1)
B(-3,43,5,leaves:1)
B(-3,46,5,leaves:1)
B(-3,45,5,leaves:1)
B(-13,40,5,leaves:1)
B(-3,40,5,leaves:1)
B(-13,41,5,leaves:1)
B(-13,42,5,leaves:1)
B(-3,42,5,leaves:1)
B(-3,41,5,leaves:1)
B(-13,43,5,leaves:1)
B(-3,36,5,leaves:1)
B(-9,29,1,leaves:1)
B(-9,28,1,leaves:1)
B(2,38,4,leaves:1)
B(-4,-3,2,LOG:12)
B(2,37,4,leaves:1)
B(-4,-4,2,LOG:12)
B(2,36,4,leaves:1)
B(-4,-5,2,LOG:12)
B(-3,56,5,leaves:1)
B(-3,55,5,leaves:1)
B(5,21,5,leaves:1)
B(-1,11,-4,LOG:12)
B(-1,10,-4,LOG:12)
B(5,20,5,leaves:1)
B(-4,-6,2,LOG:12)
B(-4,-7,2,LOG:12)
B(-13,54,5,leaves:1)
B(-5,19,-11,leaves:1)
B(-3,49,5,leaves:1)
B(-3,47,5,leaves:1)
B(-3,48,5,leaves:1)
B(-5,1,-7,LOG:12)
B(5,39,6,leaves:1)
B(5,38,6,leaves:1)
B(-5,3,-7,LOG:12)
B(5,37,6,leaves:1)
B(-5,2,-7,LOG:12)
B(5,36,6,leaves:1)
B(-3,68,4,leaves:1)
B(-9,55,1,leaves:1)
B(-3,69,4,leaves:1)
B(5,40,6,leaves:1)
B(-9,54,1,leaves:1)
B(-9,53,1,leaves:1)
B(-9,52,1,leaves:1)
B(-9,57,1,leaves:1)
B(-9,56,1,leaves:1)
B(-3,62,5,leaves:1)
B(-3,64,5,leaves:1)
B(-13,20,5,leaves:1)
B(-3,63,5,leaves:1)
B(-13,21,5,leaves:1)
B(-9,51,1,leaves:1)
B(-3,65,5,leaves:1)
B(-1,24,-4,leaves:1)
B(5,34,5,leaves:1)
B(-1,23,-4,leaves:1)
B(5,35,5,leaves:1)
B(5,36,5,leaves:1)
B(5,37,5,leaves:1)
B(5,38,5,leaves:1)
B(2,23,-13,leaves:1)
B(5,39,5,leaves:1)
B(2,24,-13,leaves:1)
B(-3,70,4,leaves:1)
B(2,25,-13,leaves:1)
B(2,26,-13,leaves:1)
B(-3,72,4,leaves:1)
B(-1,27,-5,leaves:1)
B(-3,71,4,leaves:1)
B(-3,74,4,leaves:1)
B(-1,29,-5,leaves:1)
B(-5,23,-11,leaves:1)
B(-3,73,4,leaves:1)
B(-1,28,-5,leaves:1)
B(-3,76,4,leaves:1)
B(-5,21,-11,leaves:1)
B(-3,75,4,leaves:1)
B(-5,22,-11,leaves:1)
B(-5,20,-11,leaves:1)
B(-13,39,5,leaves:1)
B(-9,42,1,leaves:1)
B(-13,37,5,leaves:1)
B(-1,40,-5,leaves:1)
B(-9,44,1,leaves:1)
B(-9,43,1,leaves:1)
B(-3,71,5,leaves:1)
B(-1,46,-5,leaves:1)
B(-3,70,5,leaves:1)
B(-9,45,1,leaves:1)
B(-3,75,5,leaves:1)
B(-3,74,5,leaves:1)
B(-1,30,-4,leaves:1)
B(-3,73,5,leaves:1)
B(-3,72,5,leaves:1)
B(-13,35,5,leaves:1)
B(1,-1,-3,LOG:12)
B(-13,36,5,leaves:1)
B(-3,77,5,leaves:1)
B(-3,76,5,leaves:1)
B(1,-5,-3,LOG:12)
B(1,-4,-3,LOG:12)
B(-3,69,5,leaves:1)
B(-1,25,-4,leaves:1)
B(1,-3,-3,LOG:12)
B(1,-2,-3,LOG:12)
B(-1,29,-4,leaves:1)
B(-9,38,1,leaves:1)
B(-1,39,-5,leaves:1)
B(-9,39,1,leaves:1)
B(9,19,2,leaves:1)
B(-4,42,8,leaves:1)
B(-4,41,8,leaves:1)
B(-4,40,8,leaves:1)
B(-1,43,0,leaves:1)
B(-4,46,8,leaves:1)
B(-6,18,13,leaves:1)
B(-1,42,0,leaves:1)
B(-4,45,8,leaves:1)
B(-6,17,13,leaves:1)
B(-1,41,0,leaves:1)
B(-4,44,8,leaves:1)
B(-12,57,1,leaves:1)
B(-4,43,8,leaves:1)
B(-12,58,1,leaves:1)
B(-12,59,1,leaves:1)
B(-1,44,0,leaves:1)
B(-7,4,2,LOG:12)
B(-12,60,1,leaves:1)
B(-7,7,2,LOG:12)
B(-7,8,2,LOG:12)
B(-11,43,3,leaves:1)
B(-4,51,8,leaves:1)
B(-7,9,2,LOG:12)
B(-11,42,3,leaves:1)
B(-11,41,3,leaves:1)
B(-4,53,8,leaves:1)
B(-11,40,3,leaves:1)
B(-4,52,8,leaves:1)
B(-1,52,0,leaves:1)
B(-11,45,3,leaves:1)
B(-1,54,0,leaves:1)
B(-11,44,3,leaves:1)
B(-1,53,0,leaves:1)
B(-1,56,0,leaves:1)
B(-7,0,2,LOG:12)
B(-1,55,0,leaves:1)
B(-7,1,2,LOG:12)
B(-7,2,2,LOG:12)
B(-1,57,0,leaves:1)
B(-7,3,2,LOG:12)
B(-3,-7,4,LOG:12)
B(-3,-3,4,LOG:12)
B(-3,-6,4,LOG:12)
B(-3,-5,4,LOG:12)
B(-3,-2,4,LOG:12)
B(-3,-1,4,LOG:12)
B(-10,-2,-1,LOG:12)
B(-12,30,1,leaves:1)
B(-10,-4,-1,LOG:12)
B(-12,31,1,leaves:1)
B(-4,28,8,leaves:1)
B(-4,27,8,leaves:1)
B(-4,26,8,leaves:1)
B(-12,38,1,leaves:1)
B(-12,39,1,leaves:1)
B(-11,34,3,leaves:1)
B(-11,36,3,leaves:1)
B(-11,35,3,leaves:1)
B(2,18,-8,leaves:2)
B(2,19,-8,leaves:2)
B(-12,29,1,leaves:1)
B(-2,42,1,leaves:1)
B(-2,43,1,leaves:1)
B(-10,-6,-1,LOG:12)
B(-2,46,1,leaves:1)
B(-10,-5,-1,LOG:12)
B(-2,47,1,leaves:1)
B(-2,48,1,leaves:1)
B(-12,41,1,leaves:1)
B(-12,42,1,leaves:1)
B(-4,31,8,leaves:1)
B(-4,30,8,leaves:1)
B(-2,60,1,leaves:1)
B(-11,19,-8,leaves:1)
B(-11,29,3,leaves:1)
B(-11,28,3,leaves:1)
B(-11,27,3,leaves:1)
B(-4,39,8,leaves:1)
B(-11,26,3,leaves:1)
B(-12,45,1,leaves:1)
B(-12,46,1,leaves:1)
B(-12,43,1,leaves:1)
B(-12,44,1,leaves:1)
B(-4,29,8,leaves:1)
B(-2,55,1,leaves:1)
B(-6,23,-12,leaves:1)
B(-10,31,-10,leaves:1)
B(-2,56,1,leaves:1)
B(-6,21,-12,leaves:1)
B(-6,22,-12,leaves:1)
B(-2,59,1,leaves:1)
B(2,20,-8,leaves:1)
B(-2,57,1,leaves:1)
B(2,21,-8,leaves:1)
B(-2,58,1,leaves:1)
B(-11,20,-8,leaves:1)
B(-11,21,-8,leaves:1)
B(-10,30,-1,leaves:1)
B(-16,30,-3,leaves:1)
B(-16,31,-3,leaves:1)
B(-11,48,7,leaves:1)
B(-10,31,-1,leaves:1)
B(-4,74,2,leaves:1)
B(-9,26,12,leaves:1)
B(-2,30,1,LOG:12)
B(-4,71,2,leaves:1)
B(-10,38,-1,leaves:1)
B(-4,70,2,leaves:1)
B(-10,37,-1,leaves:1)
B(-4,73,2,leaves:1)
B(-4,72,2,leaves:1)
B(-10,18,-10,leaves:1)
B(-10,39,-1,leaves:1)
B(-2,25,1,LOG:12)
B(-2,24,1,LOG:12)
B(0,50,2,leaves:1)
B(-2,27,1,LOG:12)
B(0,51,2,leaves:1)
B(-2,26,1,LOG:12)
B(0,52,2,leaves:1)
B(-4,67,2,leaves:1)
B(-9,27,12,leaves:1)
B(-2,21,1,LOG:12)
B(-4,68,2,leaves:1)
B(-9,28,12,leaves:1)
B(-2,20,1,LOG:12)
B(-4,69,2,leaves:1)
B(-2,23,1,LOG:12)
B(-9,29,12,leaves:1)
B(-2,22,1,LOG:12)
B(-2,29,1,LOG:12)
B(-2,28,1,LOG:12)
B(-1,10,0,LOG:12)
B(-12,28,1,leaves:1)
B(-1,11,0,LOG:12)
B(-12,27,1,leaves:1)
B(-8,2,-3,LOG:12)
B(-1,12,0,LOG:12)
B(-10,42,-1,leaves:1)
B(-12,26,1,leaves:1)
B(-8,3,-3,LOG:12)
B(-1,13,0,LOG:12)
B(-10,41,-1,leaves:1)
B(-8,4,-3,LOG:12)
B(-1,14,0,LOG:12)
B(-10,40,-1,leaves:1)
B(-4,66,2,leaves:1)
B(-1,15,0,LOG:12)
B(-2,40,1,leaves:1)
B(-4,65,2,leaves:1)
B(-1,16,0,LOG:12)
B(-2,41,1,leaves:1)
B(-4,64,2,leaves:1)
B(-1,17,0,LOG:12)
B(-4,63,2,leaves:1)
B(-1,18,0,LOG:12)
B(-4,62,2,leaves:1)
B(-1,19,0,LOG:12)
B(-11,51,7,leaves:1)
B(-4,61,2,leaves:1)
B(-11,52,7,leaves:1)
B(0,62,2,leaves:1)
B(-2,38,1,leaves:1)
B(-2,37,1,leaves:1)
B(-2,36,1,LOG:12)
B(-11,50,7,leaves:1)
B(-2,35,1,LOG:12)
B(-2,34,1,LOG:12)
B(-2,33,1,LOG:12)
B(-4,56,2,leaves:1)
B(-2,32,1,LOG:12)
B(-4,57,2,log)
B(-2,31,1,LOG:12)
B(-8,6,-3,LOG:12)
B(-8,5,-3,LOG:12)
B(-8,8,-3,LOG:12)
B(-8,7,-3,LOG:12)
B(-8,9,-3,LOG:12)
B(-2,39,1,leaves:1)
B(-4,69,8,leaves:1)
B(-4,67,8,leaves:1)
B(-1,20,0,LOG:12)
B(-4,68,8,leaves:1)
B(-1,21,0,LOG:12)
B(-11,20,7,leaves:1)
B(-18,19,7,leaves:1)
B(-11,21,7,leaves:1)
B(-18,18,7,leaves:1)
B(-4,51,2,LOG:12)
B(-4,50,2,LOG:12)
B(-4,53,2,LOG:12)
B(-4,52,2,leaves:1)
B(-4,55,2,leaves:1)
B(-11,22,7,leaves:1)
B(-4,54,2,LOG:12)
B(0,34,2,leaves:1)
B(-9,-1,1,LOG:12)
B(0,35,2,leaves:1)
B(0,36,2,leaves:1)
B(0,37,2,leaves:1)
B(-1,34,0,leaves:1)
B(-1,35,0,leaves:1)
B(-1,36,0,leaves:1)
B(-4,76,8,leaves:1)
B(-4,77,8,leaves:1)
B(-4,4,-6,LOG:12)
B(-4,73,8,leaves:1)
B(-4,74,8,leaves:1)
B(-4,2,-6,LOG:12)
B(-4,75,8,leaves:1)
B(-4,3,-6,LOG:12)
B(-9,37,12,leaves:1)
B(-4,44,2,leaves:1)
B(-4,1,-6,LOG:12)
B(-9,36,12,leaves:1)
B(-4,43,2,leaves:1)
B(-4,42,2,leaves:1)
B(-2,12,1,LOG:12)
B(-4,36,2,leaves:1)
B(0,44,2,leaves:1)
B(-2,11,1,LOG:12)
B(-4,37,2,leaves:1)
B(0,45,2,leaves:1)
B(-18,21,7,leaves:1)
B(-2,10,1,LOG:12)
B(9,20,2,leaves:1)
B(-4,34,2,leaves:1)
B(-18,22,7,leaves:1)
B(-4,35,2,leaves:1)
B(-2,16,1,LOG:12)
B(9,21,2,leaves:1)
B(-18,20,7,leaves:1)
B(-2,15,1,LOG:12)
B(-2,14,1,LOG:12)
B(-4,38,2,leaves:1)
B(-2,13,1,LOG:12)
B(-2,19,1,LOG:12)
B(-2,18,1,LOG:12)
B(-2,17,1,LOG:12)
B(0,48,2,leaves:1)
B(0,49,2,leaves:1)
B(0,46,2,leaves:1)
B(0,47,2,leaves:1)
B(-12,27,-13,leaves:1)
B(-6,72,8,leaves:1)
B(-6,73,8,leaves:1)
B(-12,19,14,leaves:1)
B(-6,70,8,leaves:1)
B(-6,71,8,leaves:1)
B(-6,76,8,leaves:1)
B(-6,74,8,leaves:1)
B(-6,75,8,leaves:1)
B(3,18,-15,leaves:1)
B(3,19,-15,leaves:1)
B(-6,67,8,leaves:1)
B(-12,26,-13,leaves:1)
B(-6,68,8,leaves:1)
B(-12,25,-13,leaves:1)
B(-6,69,8,leaves:1)
B(0,20,9,leaves:1)
B(0,21,9,leaves:1)
B(0,22,9,leaves:1)
B(-6,64,8,leaves:1)
B(-6,65,8,leaves:1)
B(-6,66,8,leaves:1)
B(3,21,-15,leaves:1)
B(3,20,-15,leaves:1)
B(-3,25,-7,leaves:1)
B(0,54,9,leaves:1)
B(0,53,9,leaves:1)
B(-6,50,8,leaves:1)
B(-6,51,8,leaves:1)
B(-12,24,14,leaves:1)
B(-9,19,14,leaves:1)
B(-12,23,14,leaves:1)
B(-9,18,14,leaves:1)
B(-12,25,14,leaves:1)
B(-12,22,14,leaves:1)
B(-12,21,14,leaves:1)
B(-4,17,12,leaves:1)
B(-4,18,12,leaves:1)
B(-4,19,12,leaves:1)
B(-4,16,12,leaves:1)
B(-6,49,8,leaves:1)
B(-6,45,8,leaves:1)
B(-6,46,8,leaves:1)
B(-6,47,8,leaves:1)
B(-6,48,8,leaves:1)
B(-6,44,8,leaves:1)
B(-9,17,14,leaves:1)
B(-5,75,5,log)
B(-5,74,5,log)
B(-5,77,5,log)
B(-5,76,5,log)
B(-5,79,5,leaves:1)
B(-5,78,5,leaves:1)
B(-5,71,5,leaves:1)
B(-1,57,7,leaves:1)
B(-5,70,5,leaves:1)
B(-1,56,7,leaves:1)
B(-5,73,5,log)
B(-1,55,7,leaves:1)
B(-5,72,5,log)
B(6,26,1,leaves:1)
B(6,25,1,leaves:1)
B(6,24,1,leaves:1)
B(-6,33,8,leaves:1)
B(6,23,1,leaves:1)
B(-6,32,8,leaves:1)
B(6,22,1,leaves:1)
B(-6,31,8,leaves:1)
B(-6,36,8,leaves:1)
B(-6,35,8,leaves:1)
B(-6,34,8,leaves:1)
B(-6,39,8,leaves:1)
B(-6,38,8,leaves:1)
B(-5,66,5,log)
B(-5,65,5,log)
B(-5,64,5,log)
B(-5,63,5,log)
B(-5,69,5,leaves:1)
B(-5,68,5,leaves:1)
B(-5,67,5,log)
B(-1,42,7,leaves:1)
B(-1,41,7,leaves:1)
B(-5,62,5,log)
B(-1,44,7,leaves:1)
B(-5,61,5,log)
B(-1,43,7,leaves:1)
B(-5,60,5,log)
B(-6,24,8,leaves:1)
B(-6,26,8,leaves:1)
B(-6,25,8,leaves:1)
B(-8,20,-9,leaves:1)
B(-12,20,-8,leaves:1)
B(-6,27,8,leaves:1)
B(-8,22,-9,leaves:1)
B(-8,21,-9,leaves:1)
B(-1,71,7,leaves:1)
B(-1,70,7,leaves:1)
B(-12,19,-8,leaves:1)
B(-18,20,-4,leaves:1)
B(-18,22,-4,leaves:1)
B(-18,21,-4,leaves:1)
B(-2,27,-11,leaves:1)
B(-2,26,-11,leaves:1)
B(-2,25,-11,leaves:1)
B(-3,-4,-7,LOG:12)
B(-3,-3,-7,LOG:12)
B(-3,-2,-7,LOG:12)
B(-3,-1,-7,LOG:12)
B(-1,60,7,leaves:1)
B(-5,81,5,leaves:1)
B(-5,80,5,leaves:1)
B(-1,62,7,leaves:1)
B(-1,61,7,leaves:1)
B(-1,64,7,leaves:1)
B(-1,63,7,leaves:1)
B(-1,58,7,leaves:1)
B(-1,59,7,leaves:1)
B(-4,40,9,leaves:1)
B(-4,41,9,leaves:1)
B(-4,42,9,leaves:1)
B(-4,43,9,leaves:1)
B(-5,21,12,leaves:1)
B(-5,20,12,leaves:1)
B(-14,31,3,leaves:1)
B(-14,30,3,leaves:1)
B(-5,36,5,leaves:1)
B(-5,37,5,leaves:1)
B(-5,34,5,leaves:1)
B(-5,35,5,leaves:1)
B(-4,39,9,leaves:1)
B(-4,37,9,leaves:1)
B(-4,38,9,leaves:1)
B(-4,36,9,leaves:1)
B(-5,17,12,leaves:1)
B(-5,19,12,leaves:1)
B(-5,18,12,leaves:1)
B(-17,19,3,leaves:1)
B(-8,31,-9,leaves:1)
B(-8,32,-9,leaves:1)
B(-8,33,-9,leaves:1)
B(-5,49,5,leaves:1)
B(-1,29,7,leaves:1)
B(-1,26,7,leaves:1)
B(-1,28,7,leaves:1)
B(-1,27,7,leaves:1)
B(-17,22,3,leaves:1)
B(-5,50,5,leaves:1)
B(-17,23,3,leaves:1)
B(-5,51,5,leaves:1)
B(-17,20,3,leaves:1)
B(-17,21,3,leaves:1)
B(-5,58,5,log)
B(-5,59,5,log)
B(-5,56,5,log)
B(-5,57,5,log)
B(-5,54,5,leaves:1)
B(-5,55,5,log)
B(-5,52,5,leaves:1)
B(-5,53,5,leaves:1)
B(-15,35,8,leaves:1)
B(-5,39,5,leaves:1)
B(-5,38,5,leaves:1)
B(-5,40,5,leaves:1)
B(-5,-3,-1,LOG:12)
B(-5,-4,-1,LOG:12)
B(-5,48,5,leaves:1)
B(-5,-7,-1,LOG:12)
B(-5,-5,-1,LOG:12)
B(-8,34,-9,leaves:1)
B(-3,9,-4,LOG:12)
B(0,-4,3,LOG:12)
B(10,21,-7,leaves:1)
B(10,22,-7,leaves:1)
B(10,23,-7,leaves:1)
B(10,24,-7,leaves:1)
B(10,25,-7,leaves:1)
B(1,-4,-1,LOG:12)
B(-6,68,1,leaves:1)
B(1,-3,-1,LOG:12)
B(1,-2,-1,LOG:12)
B(-6,72,1,leaves:1)
B(1,-4,1,LOG:12)
B(1,-2,1,LOG:12)
B(-6,59,1,leaves:1)
B(-4,23,9,leaves:1)
B(2,-3,-3,LOG:12)
B(-4,25,9,leaves:1)
B(-4,24,9,leaves:1)
B(-4,27,9,leaves:1)
B(-11,30,-11,leaves:1)
B(-4,26,9,leaves:1)
B(-4,28,9,leaves:1)
B(-6,62,1,leaves:1)
B(-6,61,1,leaves:1)
B(-6,60,1,leaves:1)
B(-6,67,1,leaves:1)
B(-17,22,6,leaves:1)
B(-6,46,1,LOG:12)
B(-6,47,1,LOG:12)
B(-6,48,1,leaves:1)
B(-6,49,1,leaves:1)
B(-6,50,1,leaves:1)
B(-17,25,6,leaves:1)
B(-6,54,1,leaves:1)
B(-17,26,6,leaves:1)
B(-6,53,1,leaves:1)
B(-6,56,1,leaves:1)
B(-17,23,6,leaves:1)
B(-6,55,1,leaves:1)
B(-17,24,6,leaves:1)
B(-14,29,3,leaves:1)
B(-3,40,7,leaves:1)
B(-3,41,7,leaves:1)
B(-3,42,7,leaves:1)
B(3,18,9,leaves:1)
B(-3,39,7,leaves:1)
B(3,19,9,leaves:1)
B(-3,38,7,leaves:1)
B(-3,50,7,leaves:1)
B(-14,22,-15,leaves:1)
B(-3,51,7,leaves:1)
B(-3,56,7,leaves:1)
B(-3,57,7,leaves:1)
B(-3,58,7,leaves:1)
B(-3,59,7,leaves:1)
B(8,28,6,leaves:1)
B(-14,23,-15,leaves:1)
B(-3,52,7,leaves:1)
B(-14,24,-15,leaves:1)
B(-3,53,7,leaves:1)
B(-14,25,-15,leaves:1)
B(-3,54,7,leaves:1)
B(-3,55,7,leaves:1)
B(8,25,6,leaves:1)
B(-8,3,-4,LOG:12)
B(8,24,6,leaves:1)
B(-8,2,-4,LOG:12)
B(8,27,6,leaves:1)
B(-8,1,-4,LOG:12)
B(8,26,6,leaves:1)
B(-8,0,-4,LOG:12)
B(-3,49,7,leaves:1)
B(-5,55,-1,leaves:1)
B(1,35,1,leaves:1)
B(1,36,1,leaves:1)
B(-5,53,-1,leaves:1)
B(-5,54,-1,leaves:1)
B(1,32,1,leaves:1)
B(1,33,1,leaves:1)
B(1,34,1,leaves:1)
B(-9,-1,0,LOG:12)
B(-9,-2,0,LOG:12)
B(-9,-3,0,LOG:12)
B(-9,-4,0,LOG:12)
B(-5,46,-1,leaves:1)
B(-5,47,-1,leaves:1)
B(0,34,3,leaves:1)
B(1,48,1,leaves:1)
B(1,49,1,leaves:1)
B(0,32,3,leaves:1)
B(-5,40,-1,leaves:1)
B(0,33,3,leaves:1)
B(1,47,1,leaves:1)
B(-3,30,7,leaves:1)
B(0,38,3,leaves:1)
B(0,39,3,leaves:1)
B(1,42,1,leaves:1)
B(-3,33,7,leaves:1)
B(0,37,3,leaves:1)
B(1,43,1,leaves:1)
B(-3,34,7,leaves:1)
B(-3,35,7,leaves:1)
B(1,41,1,leaves:1)
B(-3,36,7,leaves:1)
B(-5,48,-1,leaves:1)
B(-3,37,7,leaves:1)
B(-5,49,-1,leaves:1)
B(-3,28,7,leaves:1)
B(-3,29,7,leaves:1)
B(-5,38,-1,leaves:1)
B(1,50,1,leaves:1)
B(1,52,-1,leaves:1)
B(-5,37,-1,LOG:12)
B(1,53,-1,leaves:1)
B(1,50,-1,leaves:1)
B(-5,39,-1,leaves:1)
B(1,51,-1,leaves:1)
B(1,51,1,leaves:1)
B(0,48,3,leaves:1)
B(0,47,3,leaves:1)
B(1,56,1,leaves:1)
B(1,58,1,leaves:1)
B(0,44,3,leaves:1)
B(1,57,1,leaves:1)
B(0,43,3,leaves:1)
B(-5,32,-1,LOG:12)
B(0,46,3,leaves:1)
B(1,59,1,leaves:1)
B(-5,31,-1,LOG:12)
B(0,45,3,leaves:1)
B(-5,34,-1,LOG:12)
B(-5,33,-1,LOG:12)
B(-5,36,-1,LOG:12)
B(-5,35,-1,LOG:12)
B(-4,72,9,leaves:1)
B(-4,71,9,leaves:1)
B(2,27,-3,leaves:1)
B(2,26,-3,leaves:1)
B(1,40,-1,leaves:1)
B(1,41,-1,leaves:1)
B(1,42,-1,leaves:1)
B(3,21,-7,leaves:1)
B(3,20,-7,leaves:1)
B(0,52,3,leaves:1)
B(0,51,3,leaves:1)
B(-5,5,-6,LOG:12)
B(-5,4,-6,LOG:12)
B(-5,3,-6,LOG:12)
B(1,49,-1,leaves:1)
B(-3,66,7,leaves:1)
B(-3,65,7,leaves:1)
B(-3,64,7,leaves:1)
B(-3,63,7,leaves:1)
B(1,30,-1,leaves:1)
B(1,31,-1,leaves:1)
B(3,17,-7,leaves:2)
B(-3,62,7,leaves:1)
B(-3,61,7,leaves:1)
B(-3,60,7,leaves:1)
B(3,18,-7,leaves:2)
B(1,39,-1,leaves:1)
B(1,38,-1,leaves:1)
B(-3,75,7,leaves:1)
B(-3,74,7,leaves:1)
B(-3,77,7,leaves:1)
B(0,1,-2,LOG:12)
B(-3,76,7,leaves:1)
B(0,2,-2,LOG:12)
B(-3,71,7,leaves:1)
B(0,3,-2,LOG:12)
B(-3,70,7,leaves:1)
B(0,4,-2,LOG:12)
B(-3,73,7,leaves:1)
B(-3,72,7,leaves:1)
B(-9,37,5,leaves:1)
B(-9,39,5,leaves:1)
B(-9,38,5,leaves:1)
B(-3,32,6,leaves:1)
B(-3,31,6,leaves:1)
B(-9,30,5,leaves:1)
B(-3,33,6,leaves:1)
B(-3,39,6,leaves:1)
B(-3,37,6,leaves:1)
B(-3,38,6,leaves:1)
B(-9,29,5,leaves:1)
B(-9,28,5,leaves:1)
B(-11,17,15,leaves:1)
B(-11,16,15,leaves:1)
B(-3,43,6,leaves:1)
B(-3,42,6,leaves:1)
B(-3,41,6,leaves:1)
B(-3,40,6,leaves:1)
B(-3,46,6,leaves:1)
B(-3,45,6,leaves:1)
B(-3,44,6,leaves:1)
B(-5,17,3,LOG:12)
B(-5,16,3,LOG:12)
B(-5,15,3,LOG:12)
B(-9,59,0,leaves:1)
B(-5,19,3,LOG:12)
B(-5,18,3,LOG:12)
B(-5,20,3,LOG:12)
B(-5,23,3,LOG:12)
B(-5,24,3,LOG:12)
B(-5,21,3,LOG:12)
B(-5,22,3,LOG:12)
B(-13,19,6,leaves:1)
B(4,42,7,leaves:1)
B(-9,53,5,leaves:1)
B(-9,60,0,leaves:1)
B(4,41,7,leaves:1)
B(-9,52,5,leaves:1)
B(-9,54,5,leaves:1)
B(1,42,-7,leaves:1)
B(-9,51,5,leaves:1)
B(4,43,7,leaves:1)
B(-9,50,5,leaves:1)
B(-5,26,3,LOG:12)
B(-5,25,3,LOG:12)
B(-5,28,3,LOG:12)
B(-5,27,3,LOG:12)
B(-5,29,3,LOG:12)
B(-9,56,0,leaves:1)
B(-9,58,0,leaves:1)
B(-5,30,3,LOG:12)
B(-9,57,0,leaves:1)
B(-5,31,3,LOG:12)
B(-5,32,3,LOG:12)
B(-5,33,3,LOG:12)
B(-5,34,3,LOG:12)
B(-9,43,5,leaves:1)
B(-9,42,5,leaves:1)
B(-9,41,5,leaves:1)
B(-9,40,5,leaves:1)
B(-9,39,0,leaves:1)
B(-9,38,0,leaves:1)
B(-3,27,-7,leaves:1)
B(-3,26,-7,leaves:1)
B(4,21,7,leaves:1)
B(-3,33,-7,leaves:1)
B(1,22,-7,leaves:1)
B(-3,31,-7,leaves:1)
B(4,20,7,leaves:1)
B(-3,32,-7,leaves:1)
B(-3,30,-7,leaves:1)
B(-9,42,0,leaves:1)
B(-9,43,0,leaves:1)
B(-9,40,0,leaves:1)
B(-9,41,0,leaves:1)
B(1,23,-7,leaves:1)
B(-9,27,0,leaves:1)
B(-5,23,-10,leaves:1)
B(-8,57,9,leaves:1)
B(-9,26,0,leaves:1)
B(-5,22,-10,leaves:1)
B(-8,56,9,leaves:1)
B(-5,25,-10,leaves:1)
B(-8,55,9,leaves:1)
B(-5,24,-10,leaves:1)
B(-8,54,9,leaves:1)
B(-8,53,9,leaves:1)
B(-10,60,0,leaves:1)
B(-5,21,-10,leaves:1)
B(-8,52,9,leaves:1)
B(-8,51,9,leaves:1)
B(-3,38,-7,leaves:1)
B(-3,37,-7,leaves:1)
B(-3,39,-7,leaves:1)
B(-10,59,0,leaves:1)
B(-3,40,-7,leaves:1)
B(-8,50,9,leaves:1)
B(-9,33,0,leaves:1)
B(-9,34,0,leaves:1)
B(-5,-2,3,LOG:12)
B(-5,-3,3,LOG:12)
B(-10,57,0,leaves:1)
B(-16,24,-2,leaves:1)
B(-8,49,9,leaves:1)
B(-10,58,0,leaves:1)
B(-8,48,9,leaves:1)
B(-16,29,-2,leaves:1)
B(-16,27,-2,leaves:1)
B(-16,28,-2,leaves:1)
B(-16,25,-2,leaves:1)
B(-16,26,-2,leaves:1)
B(-9,24,0,leaves:1)
B(-9,25,0,leaves:1)
B(-4,0,-7,LOG:12)
B(-8,36,9,leaves:1)
B(-4,1,-7,LOG:12)
B(-4,2,-7,LOG:12)
B(-8,39,9,leaves:1)
B(-8,38,9,leaves:1)
B(-8,37,9,leaves:1)
B(4,19,7,leaves:1)
B(-10,40,0,leaves:1)
B(-10,41,0,leaves:1)
B(-10,38,0,leaves:1)
B(-10,37,0,leaves:1)
B(-10,39,0,leaves:1)
B(-7,31,2,LOG:12)
B(-7,32,2,LOG:12)
B(-7,30,2,LOG:12)
B(-7,35,2,LOG:12)
B(-7,36,2,LOG:12)
B(-7,33,2,LOG:12)
B(-7,34,2,LOG:12)
B(8,29,-4,leaves:1)
B(8,27,-4,leaves:1)
B(-7,29,2,LOG:12)
B(-7,28,2,LOG:12)
B(8,28,-4,leaves:1)
B(-7,27,2,LOG:12)
B(8,25,-4,leaves:1)
B(-7,26,2,LOG:12)
B(8,26,-4,leaves:1)
B(-7,40,2,leaves:1)
B(-7,41,2,LOG:12)
B(-7,42,2,LOG:12)
B(-7,43,2,LOG:12)
B(-7,44,2,LOG:12)
B(-7,45,2,LOG:12)
B(-7,46,2,LOG:12)
B(-2,21,9,leaves:1)
B(-2,22,9,leaves:1)
B(-2,23,9,leaves:1)
B(-2,24,9,leaves:1)
B(-7,38,2,leaves:1)
B(-7,37,2,LOG:12)
B(-7,39,2,leaves:1)
B(-5,70,6,leaves:1)
B(-7,13,2,LOG:12)
B(-7,14,2,LOG:12)
B(-7,11,2,LOG:12)
B(-7,12,2,LOG:12)
B(-5,74,6,log)
B(-5,73,6,log)
B(-7,10,2,LOG:12)
B(-5,72,6,log)
B(-5,71,6,leaves:1)
B(-5,78,6,log)
B(2,56,1,leaves:1)
B(-5,77,6,log)
B(2,57,1,leaves:1)
B(-5,76,6,log)
B(2,54,1,leaves:1)
B(-5,75,6,log)
B(2,55,1,leaves:1)
B(-5,79,6,log)
B(-2,35,9,leaves:1)
B(-2,36,9,leaves:1)
B(-2,33,9,leaves:1)
B(-2,34,9,leaves:1)
B(-2,31,9,leaves:1)
B(-2,32,9,leaves:1)
B(0,49,-2,leaves:1)
B(-7,22,2,LOG:12)
B(-7,23,2,LOG:12)
B(-5,81,6,log)
B(-7,24,2,LOG:12)
B(-5,80,6,log)
B(-7,25,2,LOG:12)
B(-5,83,6,leaves:1)
B(0,32,-2,leaves:1)
B(2,47,1,leaves:1)
B(-5,82,6,leaves:1)
B(2,48,1,leaves:1)
B(-7,20,2,LOG:12)
B(0,30,-2,leaves:1)
B(-5,84,6,leaves:1)
B(-7,21,2,LOG:12)
B(0,31,-2,leaves:1)
B(2,44,1,leaves:1)
B(1,17,10,leaves:1)
B(2,45,1,leaves:1)
B(1,18,10,leaves:1)
B(2,46,1,leaves:1)
B(2,40,1,leaves:1)
B(2,41,1,leaves:1)
B(-2,46,9,leaves:1)
B(-2,47,9,leaves:1)
B(-2,48,9,leaves:1)
B(-2,49,9,leaves:1)
B(-6,-1,-9,LOG:12)
B(-7,19,2,LOG:12)
B(-6,-2,-9,LOG:12)
B(-7,16,2,LOG:12)
B(-6,-4,-9,LOG:12)
B(-7,15,2,LOG:12)
B(-7,18,2,LOG:12)
B(0,39,-2,leaves:1)
B(-7,17,2,LOG:12)
B(0,38,-2,leaves:1)
B(-6,61,4,log)
B(-6,62,4,log)
B(-6,60,4,log)
B(-6,65,4,leaves:1)
B(-6,20,10,leaves:1)
B(-5,51,6,leaves:1)
B(-6,66,4,leaves:1)
B(-6,21,10,leaves:1)
B(-5,52,6,leaves:1)
B(-6,63,4,log)
B(-6,64,4,log)
B(-5,50,6,leaves:1)
B(-6,69,4,leaves:1)
B(-6,67,4,leaves:1)
B(-6,26,10,leaves:1)
B(-6,68,4,leaves:1)
B(-6,27,10,leaves:1)
B(-6,29,10,leaves:1)
B(-6,28,10,leaves:1)
B(-2,51,9,leaves:1)
B(-2,50,9,leaves:1)
B(-2,59,9,leaves:1)
B(-5,68,6,leaves:1)
B(-5,69,6,leaves:1)
B(-6,70,4,leaves:1)
B(-5,64,6,leaves:1)
B(0,51,-2,leaves:1)
B(-5,65,6,leaves:1)
B(0,50,-2,leaves:1)
B(-5,66,6,leaves:1)
B(-5,67,6,leaves:1)
B(-6,74,4,leaves:1)
B(-5,60,6,leaves:1)
B(-6,75,4,leaves:1)
B(-5,61,6,leaves:1)
B(-6,76,4,leaves:1)
B(-5,62,6,leaves:1)
B(-6,77,4,leaves:1)
B(-5,63,6,leaves:1)
B(-6,78,4,leaves:1)
B(2,58,7,leaves:1)
B(-6,79,4,leaves:1)
B(2,59,7,leaves:1)
B(2,56,7,leaves:1)
B(2,57,7,leaves:1)
B(2,55,7,leaves:1)
B(-6,19,10,leaves:1)
B(2,54,7,leaves:1)
B(-2,61,9,leaves:1)
B(-2,60,9,leaves:1)
B(-2,63,9,leaves:1)
B(-2,62,9,leaves:1)
B(-14,23,1,leaves:1)
B(-5,33,6,leaves:1)
B(-14,24,1,leaves:1)
B(-5,34,6,leaves:1)
B(-6,40,4,LOG:12)
B(-14,25,1,leaves:1)
B(-5,31,6,leaves:1)
B(-6,40,10,leaves:1)
B(-14,26,1,leaves:1)
B(-5,32,6,leaves:1)
B(-6,41,10,leaves:1)
B(-14,27,1,leaves:1)
B(-5,37,6,leaves:1)
B(-5,35,6,leaves:1)
B(-5,36,6,leaves:1)
B(2,23,7,leaves:1)
B(-8,3,1,LOG:12)
B(-6,47,4,LOG:12)
B(2,24,7,leaves:1)
B(-8,2,1,LOG:12)
B(-6,48,4,LOG:12)
B(2,25,7,leaves:1)
B(-8,1,1,LOG:12)
B(-6,45,4,LOG:12)
B(-8,0,1,LOG:12)
B(-6,46,4,LOG:12)
B(-6,42,10,leaves:1)
B(-6,43,4,leaves:1)
B(-6,43,10,leaves:1)
B(-6,44,4,leaves:1)
B(-6,41,4,LOG:12)
B(-14,22,1,leaves:1)
B(-6,42,4,LOG:12)
B(2,20,7,leaves:1)
B(2,22,7,leaves:1)
B(-6,39,4,LOG:12)
B(2,21,7,leaves:1)
B(-6,38,4,leaves:1)
B(-6,30,10,leaves:1)
B(-6,50,4,LOG:12)
B(-5,45,6,leaves:1)
B(-6,51,4,leaves:1)
B(-5,46,6,leaves:1)
B(-5,47,6,leaves:1)
B(-5,48,6,leaves:1)
B(-5,49,6,leaves:1)
B(-6,56,4,log)
B(-6,37,10,leaves:1)
B(-6,57,4,log)
B(-6,38,10,leaves:1)
B(-6,58,4,log)
B(-6,59,4,log)
B(-6,36,10,leaves:1)
B(-6,52,4,LOG:12)
B(-6,53,4,LOG:12)
B(-6,54,4,LOG:12)
B(-6,55,4,leaves:1)
B(4,26,-13,leaves:1)
B(-7,-5,2,LOG:12)
B(2,-4,-1,LOG:12)
B(-7,-1,2,LOG:12)
B(-6,49,4,LOG:12)
B(2,-2,-1,LOG:12)
B(-7,-3,2,LOG:12)
B(2,-1,-1,LOG:12)
B(-7,-4,2,LOG:12)
B(-6,39,10,leaves:1)
B(5,40,-3,leaves:1)
B(5,41,-3,leaves:1)
B(2,28,-1,leaves:1)
B(2,29,-1,leaves:1)
B(-6,62,2,leaves:1)
B(-3,21,12,leaves:1)
B(-3,22,12,leaves:1)
B(-6,64,2,leaves:1)
B(-3,23,12,leaves:1)
B(-6,63,2,leaves:1)
B(-9,49,8,leaves:1)
B(-6,66,2,leaves:1)
B(-6,68,2,leaves:1)
B(-6,67,2,leaves:1)
B(-3,20,12,leaves:1)
B(-6,69,2,leaves:1)
B(2,37,-1,leaves:1)
B(2,38,-1,leaves:1)
B(2,36,-1,leaves:1)
B(-9,28,-11,leaves:1)
B(-9,27,-11,leaves:1)
B(2,39,-1,leaves:1)
B(-9,29,-11,leaves:1)
B(2,30,-1,leaves:1)
B(-3,18,12,leaves:1)
B(2,19,7,leaves:1)
B(-3,19,12,leaves:1)
B(-9,30,-11,leaves:1)
B(-6,37,4,leaves:1)
B(-6,70,2,leaves:1)
B(-6,36,4,leaves:1)
B(4,18,-7,leaves:2)
B(-6,75,2,leaves:1)
B(-6,74,2,leaves:1)
B(-6,73,2,leaves:1)
B(1,31,-10,leaves:1)
B(1,18,-10,leaves:1)
B(1,19,-10,leaves:2)
B(6,27,0,leaves:1)
B(6,26,0,leaves:1)
B(6,25,0,leaves:1)
B(6,24,0,leaves:1)
B(6,23,0,leaves:1)
B(-5,37,10,leaves:1)
B(-5,36,10,leaves:1)
B(-9,22,8,leaves:1)
B(-5,39,10,leaves:1)
B(-5,38,10,leaves:1)
B(-9,20,8,leaves:1)
B(-9,21,8,leaves:1)
B(-5,35,10,leaves:1)
B(-2,-8,-5,LOG:12)
B(-2,-5,-5,LOG:12)
B(-2,-4,-5,LOG:12)
B(-2,-6,-5,LOG:12)
B(-2,-2,-5,LOG:12)
B(-14,55,1,leaves:1)
B(-14,54,1,leaves:1)
B(-6,15,2,LOG:12)
B(-11,38,-1,leaves:1)
B(-6,14,2,LOG:12)
B(-11,39,-1,leaves:1)
B(-6,17,2,LOG:12)
B(-6,16,2,LOG:12)
B(-11,37,-1,leaves:1)
B(-6,19,2,LOG:12)
B(-6,18,2,LOG:12)
B(-12,32,3,leaves:1)
B(-12,33,3,leaves:1)
B(2,31,1,leaves:1)
B(-6,20,2,LOG:12)
B(2,30,1,leaves:1)
B(-7,70,2,leaves:1)
B(-6,21,2,LOG:12)
B(2,33,1,leaves:1)
B(2,32,1,leaves:1)
B(-7,72,2,leaves:1)
B(-7,71,2,leaves:1)
B(2,34,1,leaves:1)
B(-7,73,2,leaves:1)
B(-12,34,3,leaves:1)
B(0,-2,-2,LOG:12)
B(0,-3,-2,LOG:12)
B(-11,40,-1,leaves:1)
B(0,-4,-2,LOG:12)
B(0,-6,-2,LOG:12)
B(-12,41,3,leaves:1)
B(-12,42,3,leaves:1)
B(-12,43,3,leaves:1)
B(1,-3,2,LOG:12)
B(-7,48,2,leaves:1)
B(-7,49,2,leaves:1)
B(2,49,-1,leaves:1)
B(-11,56,-1,leaves:1)
B(-11,55,-1,leaves:1)
B(-6,37,2,leaves:1)
B(-6,36,2,leaves:1)
B(-6,43,2,leaves:1)
B(-6,44,2,LOG:12)
B(-6,45,2,LOG:12)
B(-7,50,2,leaves:1)
B(-6,46,2,LOG:12)
B(-6,40,2,leaves:1)
B(-6,41,2,leaves:1)
B(-6,42,2,leaves:1)
B(-7,56,2,leaves:1)
B(-7,55,2,leaves:1)
B(11,21,-7,leaves:1)
B(11,20,-7,leaves:1)
B(2,40,-1,leaves:1)
B(-7,54,2,leaves:1)
B(2,41,-1,leaves:1)
B(-7,53,2,leaves:1)
B(-9,50,8,leaves:1)
B(3,19,8,leaves:1)
B(3,18,8,leaves:1)
B(-6,49,2,LOG:12)
B(-6,48,2,LOG:12)
B(-6,47,2,LOG:12)
B(-6,56,2,leaves:1)
B(11,18,-7,leaves:1)
B(-6,54,2,LOG:12)
B(-6,55,2,leaves:1)
B(11,19,-7,leaves:1)
B(-6,52,2,LOG:12)
B(-10,18,9,leaves:1)
B(-6,53,2,LOG:12)
B(-10,17,9,leaves:1)
B(-6,50,2,LOG:12)
B(-6,51,2,leaves:1)
B(-12,24,3,leaves:1)
B(-12,25,3,leaves:1)
B(-7,66,2,leaves:1)
B(-12,26,3,leaves:1)
B(-7,65,2,leaves:1)
B(2,51,-1,leaves:1)
B(-9,52,8,leaves:1)
B(-7,64,2,leaves:1)
B(-9,51,8,leaves:1)
B(-7,63,2,leaves:1)
B(-7,62,2,leaves:1)
B(2,50,-1,leaves:1)
B(-2,45,-5,leaves:1)
B(-2,46,-5,leaves:1)
B(-2,44,-5,leaves:1)
B(-10,63,2,leaves:1)
B(-2,39,-5,leaves:1)
B(-2,38,-5,leaves:1)
B(-10,65,2,leaves:1)
B(-2,37,-5,leaves:1)
B(-10,64,2,leaves:1)
B(-2,36,-5,leaves:1)
B(-13,40,3,leaves:1)
B(-13,41,3,leaves:1)
B(3,22,8,leaves:1)
B(8,27,5,leaves:1)
B(3,21,8,leaves:1)
B(3,20,8,leaves:1)
B(8,25,5,leaves:1)
B(8,26,5,leaves:1)
B(8,24,5,leaves:1)
B(-2,29,-5,leaves:1)
B(-2,28,-5,leaves:1)
B(3,46,5,leaves:1)
B(3,44,5,leaves:1)
B(3,45,5,leaves:1)
B(-8,76,5,leaves:1)
B(3,43,5,leaves:1)
B(-5,-3,-3,LOG:12)
B(3,37,5,leaves:1)
B(-2,50,-5,leaves:1)
B(-5,-4,-3,LOG:12)
B(3,38,5,leaves:1)
B(-2,51,-5,leaves:1)
B(-5,-5,-3,LOG:12)
B(-2,52,-5,leaves:1)
B(-5,-6,-3,LOG:12)
B(1,17,15,leaves:1)
B(-2,53,-5,leaves:1)
B(1,18,15,leaves:1)
B(1,19,15,leaves:1)
B(-8,8,-1,LOG:12)
B(-8,7,-1,LOG:12)
B(-8,9,-1,LOG:12)
B(1,21,15,leaves:1)
B(1,20,15,leaves:1)
B(-8,1,-1,LOG:12)
B(-8,2,-1,LOG:12)
B(-8,3,-1,LOG:12)
B(-8,4,-1,LOG:12)
B(-8,5,-1,LOG:12)
B(-8,6,-1,LOG:12)
B(1,43,2,leaves:1)
B(1,44,2,leaves:1)
B(1,45,2,leaves:1)
B(1,46,2,leaves:1)
B(1,47,2,leaves:1)
B(1,48,2,leaves:1)
B(1,31,2,leaves:1)
B(1,34,2,leaves:1)
B(1,35,2,leaves:1)
B(1,32,2,leaves:1)
B(1,33,2,leaves:1)
B(1,36,2,leaves:1)
B(-19,16,9,leaves:1)
B(-14,26,-14,leaves:1)
B(-14,25,-14,leaves:1)
B(-5,18,-3,LOG:12)
B(-5,17,-3,LOG:12)
B(-5,19,-3,LOG:12)
B(-11,17,14,leaves:1)
B(-11,18,14,leaves:1)
B(-11,19,14,leaves:1)
B(7,30,-3,leaves:1)
B(7,31,-3,leaves:1)
B(-4,-2,-3,LOG:12)
B(-4,-3,-3,LOG:12)
B(-4,-4,-3,LOG:12)
B(-4,-5,-3,LOG:12)
B(-4,-6,-3,LOG:12)
B(-4,-7,-3,LOG:12)
B(-11,24,14,leaves:1)
B(-9,24,7,leaves:1)
B(-8,18,13,leaves:1)
B(-9,23,7,leaves:1)
B(-8,19,13,leaves:1)
B(-11,20,14,leaves:1)
B(-11,21,14,leaves:1)
B(-11,22,14,leaves:1)
B(-11,23,14,leaves:1)
B(-5,24,-3,LOG:12)
B(-5,20,-3,LOG:12)
B(-5,21,-3,LOG:12)
B(7,32,-3,leaves:1)
B(-5,22,-3,LOG:12)
B(-9,25,7,leaves:1)
B(-5,23,-3,LOG:12)
B(-16,29,5,leaves:1)
B(-16,25,5,leaves:1)
B(-16,26,5,leaves:1)
B(-16,27,5,leaves:1)
B(-16,28,5,leaves:1)
B(-9,28,6,leaves:1)
B(-15,25,-15,leaves:1)
B(-9,25,6,leaves:1)
B(-9,26,6,leaves:1)
B(-9,27,6,leaves:1)
B(7,29,-3,leaves:1)
B(7,28,-3,leaves:1)
B(-5,37,-3,leaves:1)
B(-5,35,-3,leaves:1)
B(-5,36,-3,leaves:1)
B(-5,33,-3,leaves:1)
B(-5,34,-3,leaves:1)
B(8,24,2,leaves:1)
B(8,21,2,leaves:1)
B(8,23,2,leaves:1)
B(8,22,2,leaves:1)
B(-5,42,-3,leaves:1)
B(-5,43,-3,leaves:1)
B(-5,44,-3,leaves:1)
B(-5,45,-3,leaves:1)
B(4,22,-4,leaves:1)
B(-5,46,-3,leaves:1)
B(4,21,-4,leaves:1)
B(4,23,-4,leaves:1)
B(-8,20,13,leaves:1)
B(-8,24,13,leaves:1)
B(-8,23,13,leaves:1)
B(-8,22,13,leaves:1)
B(-8,21,13,leaves:1)
B(5,18,18,leaves:1)
B(5,17,18,leaves:1)
B(-4,19,-3,LOG:12)
B(5,17,17,leaves:1)
B(-4,18,-3,LOG:12)
B(5,18,17,leaves:1)
B(5,19,17,leaves:1)
B(-8,58,5,leaves:1)
B(-5,7,-5,LOG:12)
B(-8,57,5,leaves:1)
B(-5,6,-5,LOG:12)
B(-8,56,5,leaves:1)
B(-5,5,-5,LOG:12)
B(-8,55,5,leaves:1)
B(-8,54,5,leaves:1)
B(-8,53,5,leaves:1)
B(-5,9,-5,LOG:12)
B(-8,52,5,leaves:1)
B(-5,8,-5,LOG:12)
B(-4,17,-3,LOG:12)
B(-4,16,-3,LOG:12)
B(5,28,1,leaves:1)
B(6,30,-1,leaves:1)
B(-9,54,6,leaves:1)
B(-9,53,6,leaves:1)
B(-9,52,6,leaves:1)
B(-9,51,6,leaves:1)
B(-9,50,6,leaves:1)
B(-4,20,-3,LOG:12)
B(3,25,5,leaves:1)
B(3,24,5,leaves:1)
B(5,26,1,leaves:1)
B(-9,59,6,leaves:1)
B(5,27,1,leaves:1)
B(3,26,5,leaves:1)
B(5,24,1,leaves:1)
B(5,25,1,leaves:1)
B(-10,35,2,leaves:1)
B(-10,36,2,leaves:1)
B(-17,27,-4,leaves:1)
B(-10,33,2,leaves:1)
B(-17,26,-4,leaves:1)
B(-10,34,2,leaves:1)
B(6,28,-1,leaves:1)
B(-10,31,2,leaves:1)
B(6,29,-1,leaves:1)
B(-10,32,2,leaves:1)
B(6,26,-1,leaves:1)
B(6,27,-1,leaves:1)
B(-10,30,2,leaves:1)
B(6,22,-1,leaves:1)
B(6,23,-1,leaves:1)
B(-9,64,6,leaves:1)
B(-9,61,6,leaves:1)
B(-9,60,6,leaves:1)
B(-9,63,6,leaves:1)
B(-9,62,6,leaves:1)
B(-17,22,-4,leaves:1)
B(-17,23,-4,leaves:1)
B(-17,24,-4,leaves:1)
B(-17,25,-4,leaves:1)
B(-9,69,6,leaves:1)
B(-9,68,6,leaves:1)
B(-10,42,2,leaves:1)
B(-10,43,2,leaves:1)
B(-10,44,2,leaves:1)
B(-8,33,5,leaves:1)
B(-10,45,2,leaves:1)
B(-10,46,2,leaves:1)
B(-8,39,5,leaves:1)
B(-10,47,2,leaves:1)
B(-10,48,2,leaves:1)
B(-4,37,-3,leaves:1)
B(-4,36,-3,leaves:1)
B(-8,31,-10,leaves:1)
B(-8,32,5,leaves:1)
B(-4,33,-3,leaves:1)
B(-8,30,-10,leaves:1)
B(-8,31,5,leaves:1)
B(-8,30,5,leaves:1)
B(-4,35,-3,leaves:1)
B(-4,34,-3,leaves:1)
B(-13,38,3,leaves:1)
B(-4,42,-3,leaves:1)
B(-13,39,3,leaves:1)
B(-9,37,6,leaves:1)
B(-8,29,-10,leaves:1)
B(-13,30,3,leaves:1)
B(-13,32,3,leaves:1)
B(-13,31,3,leaves:1)
B(-13,33,3,leaves:1)
B(-8,44,5,leaves:1)
B(-8,41,5,leaves:1)
B(-4,23,-3,LOG:12)
B(-8,40,5,leaves:1)
B(-4,22,-3,LOG:12)
B(-8,43,5,leaves:1)
B(-4,21,-3,LOG:12)
B(-8,42,5,leaves:1)
B(-13,24,3,leaves:1)
B(-9,43,6,leaves:1)
B(-9,44,6,leaves:1)
B(-13,23,3,leaves:1)
B(-13,22,3,leaves:1)
B(5,20,17,leaves:1)
B(-2,49,-3,leaves:1)
B(-9,-3,-4,LOG:12)
B(-9,-1,-4,LOG:12)
B(-9,-4,-4,LOG:12)
B(-12,22,-6,leaves:1)
B(-12,21,-6,leaves:1)
B(-6,38,-2,leaves:1)
B(-6,39,-2,leaves:1)
B(-2,55,-3,leaves:1)
B(-2,54,-3,leaves:1)
B(-2,53,-3,leaves:1)
B(-6,34,-2,leaves:1)
B(-2,50,-3,leaves:1)
B(-6,35,-2,leaves:1)
B(-6,36,-2,leaves:1)
B(-2,37,3,leaves:1)
B(-2,38,3,leaves:1)
B(-2,39,3,leaves:1)
B(-2,56,-3,leaves:1)
B(-6,50,-2,leaves:1)
B(-2,57,-3,leaves:1)
B(-6,48,-2,leaves:1)
B(-6,49,-2,leaves:1)
B(-2,41,3,leaves:1)
B(-6,42,-2,leaves:1)
B(-2,40,3,leaves:1)
B(-6,43,-2,leaves:1)
B(-6,40,-2,leaves:1)
B(-6,41,-2,leaves:1)
B(-2,42,3,leaves:1)
B(-6,47,-2,leaves:1)
B(-6,44,-2,leaves:1)
B(-2,48,3,leaves:1)
B(-12,20,-15,leaves:1)
B(-2,49,3,leaves:1)
B(-12,21,-15,leaves:1)
B(-12,22,-15,leaves:1)
B(-2,44,-6,leaves:1)
B(-2,41,-6,leaves:1)
B(-2,43,-6,leaves:1)
B(-2,42,-6,leaves:1)
B(-2,37,-6,leaves:1)
B(-4,47,-3,leaves:1)
B(-2,50,3,leaves:1)
B(-4,43,-3,leaves:1)
B(-4,44,-3,leaves:1)
B(-6,52,-2,leaves:1)
B(-2,53,3,leaves:1)
B(-4,45,-3,leaves:1)
B(-2,52,3,leaves:1)
B(-6,53,-2,leaves:1)
B(-4,46,-3,leaves:1)
B(-2,51,3,leaves:1)
B(-15,26,-1,leaves:1)
B(-2,50,-6,leaves:1)
B(-15,25,-1,leaves:1)
B(-2,57,3,leaves:1)
B(-15,28,-1,leaves:1)
B(-2,58,3,leaves:1)
B(-15,27,-1,leaves:1)
B(-2,59,3,leaves:1)
B(-15,29,-1,leaves:1)
B(0,19,-14,leaves:1)
B(2,-2,0,LOG:12)
B(2,-1,0,LOG:12)
B(-2,51,-6,leaves:1)
B(-2,60,3,leaves:1)
B(-15,21,-1,leaves:1)
B(-15,22,-1,leaves:1)
B(-2,65,3,leaves:1)
B(0,20,-14,leaves:1)
B(-2,64,3,leaves:1)
B(0,21,-14,leaves:1)
B(-9,56,7,leaves:1)
B(-9,57,7,leaves:1)
B(-12,25,4,leaves:1)
B(-9,54,7,leaves:1)
B(-9,55,7,leaves:1)
B(-12,24,4,leaves:1)
B(-9,52,7,leaves:1)
B(-9,53,7,leaves:1)
B(-9,50,7,leaves:1)
B(-9,51,7,leaves:1)
B(5,39,-4,leaves:1)
B(-2,69,3,leaves:1)
B(-12,23,4,leaves:1)
B(-2,68,3,leaves:1)
B(-12,22,4,leaves:1)
B(-2,67,3,leaves:1)
B(-9,58,7,leaves:1)
B(5,38,-4,leaves:1)
B(-2,66,3,leaves:1)
B(-9,59,7,leaves:1)
B(5,37,-4,leaves:1)
B(-2,71,3,leaves:1)
B(10,21,7,leaves:1)
B(10,20,7,leaves:1)
B(-2,70,3,leaves:1)
B(1,0,-3,LOG:12)
B(-12,36,4,leaves:1)
B(-12,35,4,leaves:1)
B(-2,35,-6,leaves:1)
B(-2,36,-6,leaves:1)
B(-2,34,-6,leaves:1)
B(-2,17,-3,LOG:12)
B(-2,16,-3,LOG:12)
B(-2,19,-3,LOG:12)
B(-2,18,-3,LOG:12)
B(-2,13,-3,LOG:12)
B(-2,12,-3,LOG:12)
B(-9,48,7,leaves:1)
B(-2,15,-3,LOG:12)
B(-12,34,4,leaves:1)
B(-9,49,7,leaves:1)
B(-2,14,-3,LOG:12)
B(-2,20,-3,LOG:12)
B(5,40,-4,leaves:1)
B(-2,28,-6,leaves:1)
B(-2,27,-6,leaves:1)
B(-2,26,-6,leaves:1)
B(-15,19,-17,leaves:1)
B(-12,45,4,leaves:1)
B(-12,44,4,leaves:1)
B(-12,43,4,leaves:1)
B(-2,32,-3,leaves:1)
B(-2,33,-3,leaves:1)
B(-2,31,-3,leaves:1)
B(-15,20,-17,leaves:1)
B(-2,39,-3,leaves:1)
B(-15,21,-17,leaves:1)
B(-2,38,-3,leaves:1)
B(-2,40,-3,leaves:1)
B(-2,41,-3,leaves:1)
B(-2,42,-3,leaves:1)
B(10,19,7,leaves:1)
B(10,18,7,leaves:1)
B(-16,21,1,leaves:1)
B(-16,22,1,leaves:1)
B(-16,23,1,leaves:1)
B(-16,20,1,leaves:1)
B(-1,22,9,leaves:1)
B(-1,21,9,leaves:1)
B(-1,23,9,leaves:1)
B(5,23,4,leaves:1)
B(5,22,4,leaves:1)
B(-1,12,-3,LOG:12)
B(5,21,4,leaves:1)
B(-1,11,-3,LOG:12)
B(-1,10,-3,LOG:12)
B(5,38,4,leaves:1)
B(-1,13,-3,LOG:12)
B(5,34,4,leaves:1)
B(-1,37,9,leaves:1)
B(-1,36,9,leaves:1)
B(-1,35,9,leaves:1)
B(5,37,4,leaves:1)
B(-2,-4,-3,LOG:12)
B(-2,-5,-3,LOG:12)
B(5,33,4,leaves:1)
B(-2,-3,-3,LOG:12)
B(5,32,4,leaves:1)
B(-2,-8,-3,LOG:12)
B(-2,-6,-3,LOG:12)
B(-2,-7,-3,LOG:12)
B(-13,24,-15,leaves:1)
B(-13,22,-15,leaves:1)
B(-13,23,-15,leaves:1)
B(7,21,0,leaves:1)
B(7,22,0,leaves:1)
B(7,23,0,leaves:1)
B(7,24,0,leaves:1)
B(1,-4,-2,LOG:12)
B(1,-2,-2,LOG:12)
B(1,-1,-2,LOG:12)
B(-13,21,-15,leaves:1)
B(1,-6,-2,LOG:12)
B(-8,26,-11,leaves:1)
B(-8,27,-11,leaves:1)
B(-8,28,-11,leaves:1)
B(-8,29,-11,leaves:1)
B(-1,38,9,leaves:1)
B(-1,39,9,leaves:1)
B(-1,59,9,leaves:1)
B(-1,58,9,leaves:1)
B(-1,57,9,leaves:1)
B(-1,56,9,leaves:1)
B(-1,55,9,leaves:1)
B(-1,54,9,leaves:1)
B(7,26,-2,leaves:1)
B(7,27,-2,leaves:1)
B(7,28,-2,leaves:1)
B(7,29,-2,leaves:1)
B(-15,30,-1,leaves:1)
B(-1,-4,-3,LOG:12)
B(-1,-3,-3,LOG:12)
B(-1,-6,-3,LOG:12)
B(-1,-5,-3,LOG:12)
B(-1,-2,-3,LOG:12)
B(8,23,-3,leaves:1)
B(8,24,-3,leaves:1)
B(-1,-8,-3,LOG:12)
B(8,25,-3,leaves:1)
B(8,26,-3,leaves:1)
B(8,27,-3,leaves:1)
B(-11,23,-14,leaves:1)
B(-11,24,-14,leaves:1)
B(-11,21,-14,leaves:1)
B(-11,22,-14,leaves:1)
B(1,42,-2,leaves:1)
B(-8,6,-2,LOG:12)
B(-6,11,2,LOG:12)
B(-8,7,-2,LOG:12)
B(-6,10,2,LOG:12)
B(-8,8,-2,LOG:12)
B(-6,13,2,LOG:12)
B(-8,9,-2,LOG:12)
B(-6,12,2,LOG:12)
B(-9,55,-1,leaves:1)
B(-9,56,-1,leaves:1)
B(-9,57,-1,leaves:1)
B(-9,58,-1,leaves:1)
B(-9,59,-1,leaves:1)
B(-8,3,-2,LOG:12)
B(-8,2,-2,LOG:12)
B(-8,5,-2,LOG:12)
B(-8,4,-2,LOG:12)
B(1,30,-2,leaves:1)
B(-9,42,-1,leaves:1)
B(-9,40,-1,leaves:1)
B(-9,41,-1,leaves:1)
B(1,30,-11,leaves:1)
B(1,29,-11,leaves:1)
B(1,28,-11,leaves:1)
B(-5,33,-4,leaves:1)
B(-5,32,-4,leaves:1)
B(-5,35,-4,leaves:1)
B(-5,34,-4,leaves:1)
B(-5,40,-4,leaves:1)
B(-5,41,-4,leaves:1)
B(-5,42,-4,leaves:1)
B(-5,44,-4,leaves:1)
B(-5,43,-4,leaves:1)
B(-9,40,-5,leaves:1)
B(-6,-6,2,LOG:12)
B(-6,-4,2,LOG:12)
B(-6,-2,2,LOG:12)
B(-6,-3,2,LOG:12)
B(-6,-1,2,LOG:12)
B(-5,11,-4,LOG:12)
B(-5,12,-4,LOG:12)
B(5,36,-3,leaves:1)
B(-5,13,-4,LOG:12)
B(5,37,-3,leaves:1)
B(-5,14,-4,LOG:12)
B(5,38,-3,leaves:1)
B(-5,15,-4,LOG:12)
B(5,39,-3,leaves:1)
B(-5,16,-4,LOG:12)
B(-5,17,-4,LOG:12)
B(-1,50,-3,leaves:1)
B(-1,51,-3,leaves:1)
B(-1,52,-3,leaves:1)
B(-1,53,-3,leaves:1)
B(-14,28,-1,leaves:1)
B(-14,29,-1,leaves:1)
B(-14,23,-1,leaves:1)
B(-14,22,-1,leaves:1)
B(-14,24,-1,leaves:1)
B(7,30,-2,leaves:1)
B(-17,24,-3,leaves:1)
B(-17,23,-3,leaves:1)
B(-17,22,-3,leaves:1)
B(-17,21,-3,leaves:1)
B(-9,39,-1,leaves:1)
B(12,19,-10,leaves:1)
B(-17,20,-3,leaves:1)
B(12,18,-10,leaves:1)
B(-9,33,-1,leaves:1)
B(-14,39,-1,leaves:1)
B(-9,32,-1,leaves:1)
B(-14,38,-1,leaves:1)
B(-3,23,-11,leaves:1)
B(-14,32,-1,leaves:1)
B(-3,24,-11,leaves:1)
B(-14,31,-1,leaves:1)
B(-14,30,-1,leaves:1)
B(-1,39,-3,leaves:1)
B(-1,38,-3,leaves:1)
B(-3,20,-11,leaves:1)
B(1,29,-2,leaves:1)
B(-14,33,-1,leaves:1)
B(-17,25,-3,leaves:1)
B(-3,25,-11,leaves:1)
B(-3,26,-11,leaves:1)
B(8,22,1,leaves:1)
B(8,21,1,leaves:1)
B(8,20,1,leaves:1)
B(-1,31,-3,leaves:1)
B(-1,32,-3,leaves:1)
B(-1,30,-3,leaves:1)
B(-1,29,-3,leaves:1)
B(-1,28,-3,leaves:1)
B(-14,40,-1,leaves:1)
B(-1,25,-3,leaves:1)
B(-1,24,-3,leaves:1)
B(-1,27,-3,leaves:1)
B(-1,26,-3,leaves:1)
B(-1,-2,-6,LOG:12)
B(-1,-3,-6,LOG:12)
B(8,23,1,leaves:1)
B(-1,-4,-6,LOG:12)
B(-1,-5,-6,LOG:12)
B(-9,-6,-1,LOG:12)
B(-9,-5,-1,LOG:12)
B(-3,21,11,leaves:1)
B(2,34,0,leaves:1)
B(2,33,0,leaves:1)
B(-3,23,11,leaves:1)
B(-3,22,11,leaves:1)
B(2,31,0,leaves:1)
B(-5,-3,-4,LOG:12)
B(2,30,0,leaves:1)
B(-5,-2,-4,LOG:12)
B(-5,-7,-4,LOG:12)
B(-5,-6,-4,LOG:12)
B(-5,-5,-4,LOG:12)
B(-8,63,-1,leaves:1)
B(-5,-4,-4,LOG:12)
B(-8,62,-1,leaves:1)
B(-3,25,11,leaves:1)
B(-9,-3,-1,LOG:12)
B(-8,61,-1,leaves:1)
B(-3,24,11,leaves:1)
B(-9,-4,-1,LOG:12)
B(2,37,0,leaves:1)
B(-8,60,-1,leaves:1)
B(-9,-1,-1,LOG:12)
B(2,36,0,leaves:1)
B(-3,26,11,leaves:1)
B(-9,-2,-1,LOG:12)
B(2,35,0,leaves:1)
B(-2,-5,-6,LOG:12)
B(-2,-6,-6,LOG:12)
B(-1,38,-6,leaves:1)
B(-2,-3,-6,LOG:12)
B(-2,-4,-6,LOG:12)
B(-2,-2,-6,LOG:12)
B(-18,22,8,leaves:1)
B(-1,43,-6,leaves:1)
B(-18,23,8,leaves:1)
B(-1,44,-6,leaves:1)
B(-1,42,-6,leaves:1)
B(-18,20,8,leaves:1)
B(-1,45,-6,leaves:1)
B(2,49,0,leaves:1)
B(-18,21,8,leaves:1)
B(2,48,0,leaves:1)
B(-1,27,-6,leaves:1)
B(-18,19,8,leaves:1)
B(-11,21,-7,leaves:1)
B(-11,22,-7,leaves:1)
B(-11,23,-7,leaves:1)
B(-9,-5,-5,LOG:12)
B(2,52,0,leaves:1)
B(2,51,0,leaves:1)
B(-2,-1,3,LOG:12)
B(2,50,0,leaves:1)
B(-2,-2,3,LOG:12)
B(-9,-1,-5,LOG:12)
B(-9,-2,-5,LOG:12)
B(-9,-3,-5,LOG:12)
B(2,54,0,leaves:1)
B(-9,-4,-5,LOG:12)
B(2,53,0,leaves:1)
B(-1,37,-6,leaves:1)
B(5,40,7,leaves:1)
B(5,41,7,leaves:1)
B(-2,-5,3,LOG:12)
B(-2,-6,3,LOG:12)
B(-6,26,-9,leaves:1)
B(-6,-3,-2,LOG:12)
B(-6,-4,-2,LOG:12)
B(-6,28,-9,leaves:1)
B(-6,27,-9,leaves:1)
B(-6,-2,-2,LOG:12)
B(-6,29,-9,leaves:1)
B(5,39,7,leaves:1)
B(-6,-5,-2,LOG:12)
B(5,38,7,leaves:1)
B(-6,-6,-2,LOG:12)
B(5,37,7,leaves:1)
B(-8,9,0,LOG:12)
B(-8,5,0,LOG:12)
B(-8,6,0,LOG:12)
B(-8,7,0,LOG:12)
B(-8,8,0,LOG:12)
B(-1,25,-6,leaves:1)
B(-8,1,0,LOG:12)
B(-1,26,-6,leaves:1)
B(-8,2,0,LOG:12)
B(-8,3,0,LOG:12)
B(-8,4,0,LOG:12)
B(-3,19,11,leaves:1)
B(-3,18,11,leaves:1)
B(-8,0,0,leaves:2)
B(-12,33,0,leaves:1)
B(-12,34,0,leaves:1)
B(-12,31,0,leaves:1)
B(-12,32,0,leaves:1)
B(-12,30,0,leaves:1)
B(-6,24,-9,leaves:1)
B(-8,21,-1,LOG:12)
B(-6,23,-9,leaves:1)
B(-6,22,-9,leaves:1)
B(-8,20,-1,LOG:12)
B(-12,29,0,leaves:1)
B(-12,28,0,leaves:1)
B(-12,24,0,leaves:1)
B(-12,25,0,leaves:1)
B(-12,26,0,leaves:1)
B(-12,27,0,leaves:1)
B(-12,20,0,leaves:1)
B(-12,21,0,leaves:1)
B(-12,22,0,leaves:1)
B(-12,23,0,leaves:1)
B(-17,24,-2,leaves:1)
B(-17,22,-2,leaves:1)
B(-17,23,-2,leaves:1)
B(-17,20,-2,leaves:1)
B(-17,21,-2,leaves:1)
B(-8,33,-1,leaves:1)
B(-9,28,-5,leaves:1)
B(-9,27,-5,leaves:1)
B(-9,26,-5,leaves:1)
B(-8,34,-1,leaves:1)
B(-8,35,-1,leaves:1)
B(-12,55,0,leaves:1)
B(-12,56,0,leaves:1)
B(-6,21,-2,LOG:12)
B(-6,20,-2,LOG:12)
B(-12,54,0,leaves:1)
B(-6,23,-2,LOG:12)
B(-6,22,-2,LOG:12)
B(-12,57,0,leaves:1)
B(-6,25,-2,LOG:12)
B(-6,24,-2,LOG:12)
B(-6,27,-2,LOG:12)
B(-6,26,-2,LOG:12)
B(-6,28,-2,LOG:12)
B(2,19,-15,leaves:1)
B(-17,19,-2,leaves:1)
B(-8,40,-1,leaves:1)
B(-8,43,-1,leaves:1)
B(-8,41,-1,leaves:1)
B(-8,42,-1,leaves:1)
B(2,20,-15,leaves:1)
B(-12,44,0,leaves:1)
B(-12,45,0,leaves:1)
B(-12,46,0,leaves:1)
B(-3,22,-10,leaves:1)
B(-12,47,0,leaves:1)
B(-3,21,-10,leaves:1)
B(-12,48,0,leaves:1)
B(-3,20,-10,leaves:1)
B(-3,27,-10,leaves:1)
B(-6,18,-2,LOG:12)
B(-3,26,-10,leaves:1)
B(-3,25,-10,leaves:1)
B(-6,19,-2,LOG:12)
B(-1,6,-1,LOG:12)
B(-1,7,-1,LOG:12)
B(2,29,0,leaves:1)
B(-8,55,-1,leaves:1)
B(-8,56,-1,leaves:1)
B(-8,57,-1,leaves:1)
B(-1,8,-1,LOG:12)
B(-8,59,-1,leaves:1)
B(-1,9,-1,LOG:12)
B(-8,-6,-1,LOG:12)
B(-8,-4,-1,LOG:12)
B(-8,-5,-1,LOG:12)
B(-8,-3,-1,LOG:12)
B(-8,23,-8,leaves:1)
B(-8,22,-8,leaves:1)
B(-8,24,-8,leaves:1)
B(-5,11,-5,LOG:12)
B(-17,21,2,leaves:1)
B(-17,22,2,leaves:1)
B(-17,20,2,leaves:1)
B(-5,42,-5,leaves:1)
B(-5,40,-5,leaves:1)
B(-5,41,-5,leaves:1)
B(-5,33,-5,leaves:1)
B(-1,20,10,leaves:1)
B(-5,39,-5,leaves:1)
B(-5,38,-5,leaves:1)
B(-5,30,-5,leaves:1)
B(-5,31,-5,leaves:1)
B(-5,32,-5,leaves:1)
B(-8,35,-8,leaves:1)
B(-8,34,-8,leaves:1)
B(-8,33,-8,leaves:1)
B(-8,38,-8,leaves:1)
B(-8,37,-8,leaves:1)
B(1,30,5,leaves:1)
B(1,0,-2,LOG:12)
B(1,1,-2,LOG:12)
B(-8,40,-5,leaves:1)
B(-15,36,-3,leaves:1)
B(-15,37,-3,leaves:1)
B(-8,11,-1,LOG:12)
B(1,37,5,leaves:1)
B(-8,10,-1,LOG:12)
B(1,38,5,leaves:1)
B(-5,-5,-5,LOG:12)
B(-5,-6,-5,LOG:12)
B(-13,28,1,leaves:1)
B(-5,-3,-5,LOG:12)
B(-8,19,-1,LOG:12)
B(-5,-4,-5,LOG:12)
B(-8,18,-1,LOG:12)
B(-13,26,1,leaves:1)
B(-8,17,-1,LOG:12)
B(-8,39,-5,leaves:1)
B(-13,27,1,leaves:1)
B(-5,-2,-5,LOG:12)
B(-8,16,-1,LOG:12)
B(-8,38,-5,leaves:1)
B(-8,15,-1,LOG:12)
B(-13,25,1,leaves:1)
B(-8,14,-1,LOG:12)
B(-8,13,-1,LOG:12)
B(-8,12,-1,LOG:12)
B(1,41,5,leaves:1)
B(1,40,5,leaves:1)
B(0,21,-5,leaves:1)
B(1,49,5,leaves:1)
B(1,42,5,leaves:1)
B(-8,28,-5,leaves:1)
B(0,26,-5,leaves:1)
B(0,27,-5,leaves:1)
B(-8,27,-5,leaves:1)
B(-13,38,1,leaves:1)
B(-9,73,4,leaves:1)
B(0,28,-5,leaves:1)
B(-13,39,1,leaves:1)
B(-8,29,-5,leaves:1)
B(-9,71,4,leaves:1)
B(0,22,-5,leaves:1)
B(-9,72,4,leaves:1)
B(0,23,-5,leaves:1)
B(0,24,-5,leaves:1)
B(0,25,-5,leaves:1)
B(-2,53,12,leaves:1)
B(-2,54,12,leaves:1)
B(-2,57,12,leaves:1)
B(-2,55,12,leaves:1)
B(-2,56,12,leaves:1)
B(-8,57,-5,leaves:1)
B(-8,56,-5,leaves:1)
B(-13,42,1,leaves:1)
B(-8,55,-5,leaves:1)
B(-13,40,1,leaves:1)
B(-13,41,1,leaves:1)
B(-8,46,-5,leaves:1)
B(-8,45,-5,leaves:1)
B(-8,48,-5,leaves:1)
B(-8,47,-5,leaves:1)
B(-13,55,1,leaves:1)
B(1,28,5,leaves:1)
B(-13,56,1,leaves:1)
B(1,29,5,leaves:1)
B(-9,50,4,leaves:1)
B(-13,57,1,leaves:1)
B(-13,58,1,leaves:1)
B(-5,-6,-7,LOG:12)
B(-9,53,4,leaves:1)
B(-5,-5,-7,LOG:12)
B(-9,54,4,leaves:1)
B(-5,-4,-7,LOG:12)
B(-9,51,4,leaves:1)
B(-5,-3,-7,LOG:12)
B(-9,52,4,leaves:1)
B(-9,43,4,leaves:1)
B(-9,42,4,leaves:1)
B(-9,41,4,leaves:1)
B(-9,40,4,leaves:1)
B(-9,49,4,leaves:1)
B(-9,48,4,leaves:1)
B(-9,44,4,leaves:1)
B(-9,30,4,leaves:1)
B(-9,32,4,leaves:1)
B(-8,70,7,leaves:1)
B(-9,31,4,leaves:1)
B(-7,21,-9,leaves:1)
B(-7,22,-9,leaves:1)
B(-7,23,-9,leaves:1)
B(-9,39,4,leaves:1)
B(-8,72,7,leaves:1)
B(-8,71,7,leaves:1)
B(-7,30,-9,leaves:1)
B(9,22,4,leaves:1)
B(-9,29,4,leaves:1)
B(9,21,4,leaves:1)
B(9,20,4,leaves:1)
B(-7,31,-9,leaves:1)
B(-8,69,7,leaves:1)
B(-8,68,7,leaves:1)
B(-7,29,-9,leaves:1)
B(2,-4,-2,LOG:12)
B(2,-1,-2,LOG:12)
B(2,-2,-2,LOG:12)
B(2,-3,-2,LOG:12)
B(-10,0,-4,LOG:12)
B(-8,58,7,leaves:1)
B(-2,21,12,leaves:1)
B(-8,57,7,leaves:1)
B(-2,25,12,leaves:1)
B(-2,24,12,leaves:1)
B(-2,23,12,leaves:1)
B(-2,22,12,leaves:1)
B(-8,50,7,leaves:1)
B(-2,27,12,leaves:1)
B(-8,52,7,leaves:1)
B(-2,26,12,leaves:1)
B(-8,51,7,leaves:1)
B(-8,54,7,leaves:1)
B(-8,53,7,leaves:1)
B(-8,56,7,leaves:1)
B(-8,55,7,leaves:1)
B(-1,48,10,leaves:1)
B(-1,47,10,leaves:1)
B(2,30,3,leaves:1)
B(2,36,3,leaves:1)
B(2,35,3,leaves:1)
B(2,34,3,leaves:1)
B(-1,42,10,leaves:1)
B(-1,41,10,leaves:1)
B(-1,44,10,leaves:1)
B(-1,43,10,leaves:1)
B(-1,45,10,leaves:1)
B(-8,41,7,leaves:1)
B(0,17,15,leaves:1)
B(-1,37,10,leaves:1)
B(-1,36,10,leaves:1)
B(2,28,3,leaves:1)
B(2,41,-2,leaves:1)
B(2,42,-2,leaves:1)
B(2,29,3,leaves:1)
B(2,40,-2,leaves:1)
B(-1,35,10,leaves:1)
B(-1,34,10,leaves:1)
B(-1,33,10,leaves:1)
B(-1,32,10,leaves:1)
B(-8,36,7,leaves:1)
B(-8,37,7,leaves:1)
B(-8,-1,-5,LOG:12)
B(-8,-3,-5,LOG:12)
B(-8,-5,-5,LOG:12)
B(-8,-4,-5,LOG:12)
B(-17,20,0,leaves:1)
B(-8,26,7,leaves:1)
B(-8,27,7,leaves:1)
B(-8,24,7,leaves:1)
B(-3,19,-11,leaves:1)
B(-8,25,7,leaves:1)
B(2,45,3,leaves:1)
B(2,42,3,leaves:1)
B(2,41,3,leaves:1)
B(2,44,3,leaves:1)
B(2,43,3,leaves:1)
B(-1,57,10,leaves:1)
B(-1,56,10,leaves:1)
B(-1,55,10,leaves:1)
B(-1,54,10,leaves:1)
B(-1,53,10,leaves:1)
B(2,29,-2,leaves:1)
B(2,28,-2,leaves:1)
B(2,27,-2,leaves:1)
B(-17,19,0,leaves:1)
B(2,40,3,leaves:1)
B(-7,30,11,leaves:1)
B(-7,37,11,leaves:1)
B(-7,38,11,leaves:1)
B(-7,31,11,leaves:1)
B(-5,-8,-2,LOG:12)
B(-5,-6,-2,LOG:12)
B(-5,-7,-2,LOG:12)
B(-5,-4,-2,LOG:12)
B(-5,-5,-2,LOG:12)
B(-5,-2,-2,LOG:12)
B(-5,-3,-2,LOG:12)
B(-7,39,11,leaves:1)
B(3,46,1,leaves:1)
B(3,45,1,leaves:1)
B(3,44,1,leaves:1)
B(3,43,1,leaves:1)
B(3,42,1,leaves:1)
B(3,41,1,leaves:1)
B(3,40,1,leaves:1)
B(-7,27,11,leaves:1)
B(-7,29,11,leaves:1)
B(-7,28,11,leaves:1)
B(3,30,1,leaves:1)
B(3,31,1,leaves:1)
B(-4,-2,-7,LOG:12)
B(-4,-1,-7,LOG:12)
B(-4,-6,-7,LOG:12)
B(-4,-5,-7,LOG:12)
B(-5,26,-8,leaves:1)
B(-5,25,-8,leaves:1)
B(-5,28,-8,leaves:1)
B(-5,27,-8,leaves:1)
B(-6,-6,-6,LOG:12)
B(-6,-5,-6,LOG:12)
B(-6,-2,-6,LOG:12)
B(-6,-4,-6,LOG:12)
B(-6,-3,-6,LOG:12)
B(3,54,1,leaves:1)
B(3,53,1,leaves:1)
B(3,56,1,leaves:1)
B(3,55,1,leaves:1)
B(-4,40,-1,leaves:1)
B(-4,39,-1,leaves:1)
B(-4,38,-1,leaves:1)
B(-4,37,-1,leaves:1)
B(-4,36,-1,LOG:12)
B(-4,35,-1,LOG:12)
B(-4,34,-1,LOG:12)
B(-4,33,-1,LOG:12)
B(-4,32,-1,LOG:12)
B(-4,31,-1,LOG:12)
B(-4,30,-1,LOG:12)
B(-5,24,-2,LOG:12)
B(-5,26,-2,LOG:12)
B(-5,25,-2,LOG:12)
B(-5,28,-2,LOG:12)
B(-5,27,-2,LOG:12)
B(-5,29,-2,LOG:12)
B(-5,31,-2,LOG:12)
B(-5,30,-2,LOG:12)
B(-5,37,-2,leaves:1)
B(-5,36,-2,leaves:1)
B(-5,35,-2,leaves:1)
B(3,28,1,leaves:1)
B(-4,55,-1,leaves:1)
B(3,29,1,leaves:1)
B(-4,54,-1,leaves:1)
B(-5,39,-2,leaves:1)
B(-4,53,-1,leaves:1)
B(-5,38,-2,leaves:1)
B(-4,52,-1,leaves:1)
B(-4,50,-1,leaves:1)
B(-4,51,-1,leaves:1)
B(-4,49,-1,leaves:1)
B(-5,44,-2,leaves:1)
B(-5,46,-2,leaves:1)
B(-5,45,-2,leaves:1)
B(-5,48,-2,leaves:1)
B(-5,47,-2,leaves:1)
B(-4,41,-1,leaves:1)
B(-5,-4,-8,LOG:12)
B(-5,-5,-8,LOG:12)
B(-5,-2,-8,LOG:12)
B(-4,46,-1,leaves:1)
B(-5,-3,-8,LOG:12)
B(-4,45,-1,leaves:1)
B(-4,48,-1,leaves:1)
B(-5,-1,-8,LOG:12)
B(-4,47,-1,leaves:1)
B(-5,52,-2,leaves:1)
B(-6,42,-6,leaves:1)
B(-6,40,-6,leaves:1)
B(-6,41,-6,leaves:1)
B(-3,64,-1,leaves:1)
B(-6,39,-6,leaves:1)
B(-6,34,-6,leaves:1)
B(-6,33,-6,leaves:1)
B(9,20,3,leaves:1)
B(9,21,3,leaves:1)
B(-3,61,-1,leaves:1)
B(-3,63,-1,leaves:1)
B(-3,62,-1,leaves:1)
B(-3,53,-1,leaves:1)
B(-3,54,-1,leaves:1)
B(7,28,3,leaves:1)
B(7,29,3,leaves:1)
B(-4,80,5,leaves:1)
B(7,26,3,leaves:1)
B(7,27,3,leaves:1)
B(-3,52,-1,leaves:1)
B(-3,51,-1,leaves:1)
B(-4,78,5,leaves:1)
B(-3,44,-1,leaves:1)
B(-4,77,5,leaves:1)
B(-3,45,-1,leaves:1)
B(-3,42,-1,leaves:1)
B(-4,79,5,leaves:1)
B(-3,43,-1,leaves:1)
B(-4,73,5,log)
B(9,19,3,leaves:1)
B(-4,76,5,leaves:1)
B(-3,46,-1,leaves:1)
B(-4,75,5,leaves:1)
B(-4,70,5,leaves:1)
B(-4,72,5,log)
B(-4,71,5,leaves:1)
B(-4,59,5,log)
B(-2,5,1,LOG:12)
B(-2,4,1,LOG:12)
B(-2,3,1,LOG:12)
B(-2,2,1,LOG:12)
B(-2,9,1,LOG:12)
B(-2,8,1,LOG:12)
B(-2,7,1,LOG:12)
B(-2,6,1,LOG:12)
B(-4,60,5,log)
B(-4,36,-7,leaves:1)
B(-4,61,5,log)
B(-2,1,1,LOG:12)
B(-4,37,-7,leaves:1)
B(-4,38,-7,leaves:1)
B(-4,64,5,log)
B(-4,65,5,log)
B(-4,62,5,log)
B(-4,63,5,log)
B(-4,68,5,leaves:1)
B(-4,69,5,leaves:1)
B(-4,66,5,log)
B(-4,67,5,log)
B(-4,49,5,leaves:1)
B(-4,48,5,leaves:1)
B(-4,30,-7,leaves:1)
B(-4,29,-7,leaves:1)
B(-4,27,-7,leaves:1)
B(-4,28,-7,leaves:1)
B(-3,19,-13,leaves:1)
B(-4,26,-7,leaves:1)
B(-3,18,-13,leaves:1)
B(-4,50,5,leaves:1)
B(6,23,2,leaves:1)
B(-4,51,5,leaves:1)
B(-4,52,5,leaves:1)
B(-4,53,5,leaves:1)
B(-4,54,5,leaves:1)
B(-4,55,5,leaves:1)
B(6,27,2,leaves:1)
B(-4,56,5,log)
B(6,26,2,leaves:1)
B(-4,57,5,log)
B(-4,58,5,log)
B(6,28,2,leaves:1)
B(-4,-3,-1,LOG:12)
B(-4,-5,-1,LOG:12)
B(-4,-4,-1,LOG:12)
B(-4,-6,-1,LOG:12)
B(-4,39,5,leaves:1)
B(-4,38,5,leaves:1)
B(-4,37,5,leaves:1)
B(-6,32,-6,leaves:1)
B(-7,54,11,leaves:1)
B(-7,53,11,leaves:1)
B(-7,55,11,leaves:1)
B(-6,27,-6,leaves:1)
B(-6,28,-6,leaves:1)
B(-6,29,-6,leaves:1)
B(-4,47,5,leaves:1)
B(-3,20,-13,leaves:1)
B(-7,50,11,leaves:1)
B(-4,40,5,leaves:1)
B(-7,52,11,leaves:1)
B(-4,41,5,leaves:1)
B(-7,51,11,leaves:1)
B(2,23,14,leaves:1)
B(2,24,14,leaves:1)
B(2,25,14,leaves:1)
B(2,26,14,leaves:1)
B(2,27,14,leaves:1)
B(-7,49,11,leaves:1)
B(-7,48,11,leaves:1)
B(-4,34,5,leaves:1)
B(-4,35,5,leaves:1)
B(-4,36,5,leaves:1)
B(-16,27,7,leaves:1)
B(-16,28,7,leaves:1)
B(-8,54,6,leaves:1)
B(-8,55,6,leaves:1)
B(-8,53,6,leaves:1)
B(-8,58,6,leaves:1)
B(-8,59,6,leaves:1)
B(-8,56,6,leaves:1)
B(0,34,0,leaves:1)
B(-8,57,6,leaves:1)
B(0,33,0,leaves:1)
B(0,39,0,leaves:1)
B(0,38,0,leaves:1)
B(1,28,-4,leaves:1)
B(-8,40,6,leaves:1)
B(0,41,0,leaves:1)
B(0,40,0,leaves:1)
B(0,43,0,leaves:1)
B(0,42,0,leaves:1)
B(1,27,-4,leaves:1)
B(1,26,-4,leaves:1)
B(-8,74,6,leaves:1)
B(-8,75,6,leaves:1)
B(-8,72,6,leaves:1)
B(-8,73,6,leaves:1)
B(-8,70,6,leaves:1)
B(-8,71,6,leaves:1)
B(3,24,-4,leaves:1)
B(3,23,-4,leaves:1)
B(-18,21,6,leaves:1)
B(-8,2,2,LOG:12)
B(-8,1,2,LOG:12)
B(-18,20,6,leaves:1)
B(-8,0,2,LOG:12)
B(-8,3,2,LOG:12)
B(-8,63,6,leaves:1)
B(-8,64,6,leaves:1)
B(-8,65,6,leaves:1)
B(-8,66,6,leaves:1)
B(-8,60,6,leaves:1)
B(-8,61,6,leaves:1)
B(-8,62,6,leaves:1)
B(-8,67,6,leaves:1)
B(-8,68,6,leaves:1)
B(-8,69,6,leaves:1)
B(8,25,3,leaves:1)
B(1,0,-1,LOG:12)
B(1,3,-1,LOG:12)
B(1,1,-1,LOG:12)
B(1,2,-1,LOG:12)
B(8,22,3,leaves:1)
B(8,23,3,leaves:1)
B(8,24,3,leaves:1)
B(-9,70,6,leaves:1)
B(-17,20,1,leaves:1)
B(-17,21,1,leaves:1)
B(0,57,0,leaves:1)
B(0,55,0,leaves:1)
B(0,56,0,leaves:1)
B(0,54,0,leaves:1)
B(-9,21,13,leaves:1)
B(-9,20,13,leaves:1)
B(-9,23,13,leaves:1)
B(-9,22,13,leaves:1)
B(-9,25,13,leaves:1)
B(-9,24,13,leaves:1)
B(-9,26,13,leaves:1)
B(-18,22,9,leaves:1)
B(-14,41,-4,leaves:1)
B(-6,23,-11,leaves:1)
B(-6,20,-11,leaves:1)
B(-6,26,-11,leaves:1)
B(-6,24,-11,leaves:1)
B(-6,25,-11,leaves:1)
B(-1,7,1,LOG:12)
B(-1,8,1,LOG:12)
B(-1,9,1,LOG:12)
B(-1,3,1,LOG:12)
B(-1,4,1,LOG:12)
B(-1,6,1,LOG:12)
B(-1,0,1,LOG:12)
B(-1,2,1,LOG:12)
B(-1,1,1,LOG:12)
B(-13,23,2,leaves:1)
B(-13,24,2,leaves:1)
B(-13,25,2,leaves:1)
B(-6,19,-11,leaves:1)
B(-13,26,2,leaves:1)
B(0,-1,-6,LOG:12)
B(-13,28,2,leaves:1)
B(0,-3,-6,LOG:12)
B(0,-4,-6,LOG:12)
B(-13,29,2,leaves:1)
B(0,-5,-6,LOG:12)
B(-18,24,-8,leaves:1)
B(-18,23,-8,leaves:1)
B(0,26,-6,leaves:1)
B(0,25,-6,leaves:1)
B(0,24,-6,leaves:1)
B(1,-1,-4,LOG:12)
B(1,-2,-4,LOG:12)
B(1,38,11,leaves:1)
B(1,39,11,leaves:1)
B(0,20,-6,leaves:2)
B(1,-4,-4,LOG:12)
B(1,-3,-4,LOG:12)
B(1,-6,-4,LOG:12)
B(1,-5,-4,LOG:12)
B(1,-7,-4,LOG:12)
B(-8,29,12,leaves:1)
B(-8,28,12,leaves:1)
B(-8,24,12,leaves:1)
B(-18,18,6,leaves:1)
B(-8,25,12,leaves:1)
B(-18,17,6,leaves:1)
B(-8,26,12,leaves:1)
B(-8,27,12,leaves:1)
B(-18,19,6,leaves:1)
B(-15,36,-4,leaves:1)
B(-8,23,12,leaves:1)
B(-15,37,-4,leaves:1)
B(-13,39,2,leaves:1)
B(-13,38,2,leaves:1)
B(0,44,-6,leaves:1)
B(-13,31,2,leaves:1)
B(-13,30,2,leaves:1)
B(-16,30,6,leaves:1)
B(-8,39,6,leaves:1)
B(-8,38,6,leaves:1)
B(0,-3,0,LOG:12)
B(0,-4,0,LOG:12)
B(-8,37,6,leaves:1)
B(-8,30,6,leaves:1)
B(-4,19,-13,leaves:1)
B(-4,18,-13,leaves:1)
B(0,-6,0,LOG:12)
B(0,-5,0,LOG:12)
B(1,40,11,leaves:1)
B(-8,29,6,leaves:1)
B(-8,28,6,leaves:1)
B(-8,27,6,leaves:1)
B(1,41,11,leaves:1)
B(-16,29,6,leaves:1)
B(-16,28,6,leaves:1)
B(-16,27,6,leaves:1)
B(-16,26,6,leaves:1)
B(2,28,-12,leaves:1)
B(2,26,-12,leaves:1)
B(2,27,-12,leaves:1)
B(8,22,0,leaves:1)
B(8,20,0,leaves:1)
B(8,21,0,leaves:1)
B(-3,73,3,leaves:1)
B(-3,72,3,leaves:1)
B(-3,71,3,leaves:1)
B(-3,70,3,leaves:1)
B(-2,61,5,leaves:1)
B(-2,60,5,leaves:1)
B(-2,59,5,leaves:1)
B(-2,58,5,leaves:1)
B(-3,69,3,leaves:1)
B(-3,67,3,leaves:1)
B(-3,62,3,leaves:1)
B(-3,61,3,leaves:1)
B(-3,64,3,leaves:1)
B(-3,63,3,leaves:1)
B(-3,66,3,leaves:1)
B(-3,65,3,leaves:1)
B(-2,54,5,leaves:1)
B(-2,53,5,leaves:1)
B(-2,55,5,leaves:1)
B(-2,46,5,leaves:1)
B(-2,71,5,leaves:1)
B(-12,24,-4,leaves:1)
B(-12,23,-4,leaves:1)
B(-3,24,3,LOG:12)
B(-3,23,3,LOG:12)
B(-3,26,3,LOG:12)
B(-3,25,3,LOG:12)
B(-3,28,3,LOG:12)
B(-3,27,3,LOG:12)
B(-3,29,3,LOG:12)
B(4,40,2,leaves:1)
B(7,30,4,leaves:1)
B(-3,30,3,LOG:12)
B(-3,31,3,LOG:12)
B(-3,32,3,LOG:12)
B(-3,33,3,LOG:12)
B(-3,15,3,LOG:12)
B(-3,14,3,LOG:12)
B(-3,13,3,LOG:12)
B(-3,12,3,LOG:12)
B(-9,19,13,leaves:1)
B(-3,19,3,LOG:12)
B(-3,18,3,LOG:12)
B(-3,17,3,LOG:12)
B(-3,16,3,LOG:12)
B(0,-1,-5,LOG:12)
B(0,-4,-5,LOG:12)
B(4,30,2,leaves:1)
B(7,29,4,leaves:1)
B(4,38,2,leaves:1)
B(7,26,4,leaves:1)
B(4,31,2,leaves:1)
B(7,28,4,leaves:1)
B(7,27,4,leaves:1)
B(0,-8,-5,LOG:12)
B(1,50,5,leaves:1)
B(1,51,5,leaves:1)
B(-3,21,3,LOG:12)
B(4,39,2,leaves:1)
B(-3,22,3,LOG:12)
B(-3,20,3,LOG:12)
B(9,20,5,leaves:1)
B(9,21,5,leaves:1)
B(-3,49,3,LOG:12)
B(9,22,5,leaves:1)
B(9,23,5,leaves:1)
B(-3,46,3,LOG:12)
B(-3,45,3,LOG:12)
B(-3,48,3,LOG:12)
B(-3,47,3,LOG:12)
B(-2,35,5,leaves:1)
B(-2,42,5,leaves:1)
B(-2,43,5,leaves:1)
B(-2,44,5,leaves:1)
B(-2,45,5,leaves:1)
B(-3,52,3,leaves:1)
B(-3,53,3,leaves:1)
B(-3,54,3,leaves:1)
B(-3,55,3,leaves:1)
B(-3,50,3,LOG:12)
B(-3,51,3,LOG:12)
B(-3,39,3,LOG:12)
B(-3,38,3,LOG:12)
B(-3,37,3,LOG:12)
B(-3,36,3,LOG:12)
B(-3,35,3,LOG:12)
B(-3,34,3,LOG:12)
B(-9,18,9,leaves:1)
B(-9,19,9,leaves:1)
B(-9,17,9,leaves:1)
B(-2,33,5,leaves:1)
B(-2,34,5,leaves:1)
B(-3,43,3,leaves:1)
B(-3,44,3,LOG:12)
B(-3,41,3,LOG:12)
B(-3,42,3,LOG:12)
B(-3,40,3,leaves:1)
B(-2,-3,5,LOG:12)
B(-2,8,2,LOG:12)
B(-2,7,2,LOG:12)
B(-2,6,2,LOG:12)
B(-2,5,2,LOG:12)
B(-2,4,2,LOG:12)
B(-2,3,2,LOG:12)
B(-2,2,2,LOG:12)
B(-2,1,2,LOG:12)
B(-9,20,9,leaves:1)
B(-2,9,2,LOG:12)
B(-2,0,2,LOG:12)
B(-16,24,-1,leaves:1)
B(-16,25,-1,leaves:1)
B(-16,26,-1,leaves:1)
B(-16,27,-1,leaves:1)
B(-3,-1,3,LOG:12)
B(-3,-4,3,LOG:12)
B(-3,-5,3,LOG:12)
B(-16,20,-1,leaves:1)
B(-16,23,-1,leaves:1)
B(-16,22,-1,leaves:1)
B(-3,11,3,LOG:12)
B(4,29,2,leaves:1)
B(-3,10,3,LOG:12)
B(4,27,2,leaves:1)
B(4,26,2,leaves:1)
B(4,25,2,leaves:1)
B(3,43,4,leaves:1)
B(3,44,4,leaves:1)
B(3,45,4,leaves:1)
B(-7,-5,-7,LOG:12)
B(-10,50,5,leaves:1)
B(-10,51,5,leaves:1)
B(-7,-2,-7,LOG:12)
B(-7,-4,-7,LOG:12)
B(-13,20,4,leaves:1)
B(-13,22,4,leaves:1)
B(-13,21,4,leaves:1)
B(1,23,-13,leaves:1)
B(1,22,-13,leaves:1)
B(1,25,-13,leaves:1)
B(1,24,-13,leaves:1)
B(-13,35,4,leaves:1)
B(-13,34,4,leaves:1)
B(-13,33,4,leaves:1)
B(-13,32,4,leaves:1)
B(3,25,4,leaves:1)
B(3,26,4,leaves:1)
B(3,27,4,leaves:1)
B(-13,39,4,leaves:1)
B(-13,38,4,leaves:1)
B(-17,27,-5,leaves:1)
B(-17,28,-5,leaves:1)
B(-17,24,-5,leaves:1)
B(-17,23,-5,leaves:1)
B(3,35,4,leaves:1)
B(-17,26,-5,leaves:1)
B(-17,25,-5,leaves:1)
B(-13,40,4,leaves:1)
B(3,36,4,leaves:1)
B(-13,42,4,leaves:1)
B(3,37,4,leaves:1)
B(-13,41,4,leaves:1)
B(-7,19,-13,leaves:1)
B(-4,21,-11,leaves:1)
B(-4,20,-11,leaves:1)
B(-4,23,-11,leaves:1)
B(-7,20,-13,leaves:1)
B(-4,22,-11,leaves:1)
B(-7,22,-13,leaves:1)
B(-7,21,-13,leaves:1)
B(0,24,-12,leaves:1)
B(0,25,-12,leaves:1)
B(0,26,-12,leaves:1)
B(0,27,-12,leaves:1)
B(4,22,5,leaves:1)
B(4,23,5,leaves:1)
B(0,0,-7,LOG:12)
B(4,35,5,leaves:1)
B(4,36,5,leaves:1)
B(4,37,5,leaves:1)
B(-7,49,12,leaves:1)
B(4,39,5,leaves:1)
B(-7,48,12,leaves:1)
B(-6,-6,-3,LOG:12)
B(-6,-4,-3,LOG:12)
B(-6,-5,-3,LOG:12)
B(-6,-2,-3,LOG:12)
B(-6,-3,-3,LOG:12)
B(-7,32,-7,leaves:1)
B(4,43,5,leaves:1)
B(4,42,5,leaves:1)
B(4,41,5,leaves:1)
B(4,40,5,leaves:1)
B(-7,26,-7,leaves:1)
B(-7,25,-7,leaves:1)
B(-7,40,-7,leaves:1)
B(9,22,-2,leaves:1)
B(9,21,-2,leaves:1)
B(-7,27,12,leaves:1)
B(-7,28,12,leaves:1)
B(-16,28,4,leaves:1)
B(-7,25,12,leaves:1)
B(-11,24,-5,leaves:1)
B(-7,26,12,leaves:1)
B(-7,23,12,leaves:1)
B(-7,24,12,leaves:1)
B(-7,21,12,leaves:1)
B(-7,22,12,leaves:1)
B(-7,39,-7,leaves:1)
B(-7,38,-7,leaves:1)
B(-7,37,-7,leaves:1)
B(-16,25,4,leaves:1)
B(-11,25,-5,leaves:1)
B(-16,24,4,leaves:1)
B(-7,35,-7,leaves:1)
B(-16,27,4,leaves:1)
B(-7,34,-7,leaves:1)
B(-16,26,4,leaves:1)
B(-7,33,-7,leaves:1)
B(-1,9,-4,LOG:12)
B(-1,8,-4,LOG:12)
B(-1,7,-4,LOG:12)
B(-1,6,-4,LOG:12)
B(-1,5,-4,LOG:12)
B(-1,4,-4,LOG:12)
B(-1,3,-4,LOG:12)
B(-1,2,-4,LOG:12)
B(-17,24,4,leaves:1)
B(-17,23,4,leaves:1)
B(-17,22,4,leaves:1)
B(-17,21,4,leaves:1)
B(-17,20,4,leaves:1)
B(-1,30,12,leaves:1)
B(-1,26,12,leaves:1)
B(-12,18,7,leaves:1)
B(-1,25,12,leaves:1)
B(-12,19,7,leaves:1)
B(-1,24,12,leaves:1)
B(-1,29,12,leaves:1)
B(-1,28,12,leaves:1)
B(-1,27,12,leaves:1)
B(-7,51,12,leaves:1)
B(-7,50,12,leaves:1)
B(-7,53,12,leaves:1)
B(-12,20,7,leaves:1)
B(-1,-1,2,LOG:12)
B(-11,46,1,leaves:1)
B(-1,-2,2,LOG:12)
B(-11,47,1,leaves:1)
B(-11,48,1,leaves:1)
B(-11,49,1,leaves:1)
B(-11,44,1,leaves:1)
B(-11,45,1,leaves:1)
B(-1,-7,2,LOG:12)
B(-11,40,1,leaves:1)
B(-1,-8,2,LOG:12)
B(-11,41,1,leaves:1)
B(-1,-5,2,LOG:12)
B(-1,-6,2,LOG:12)
B(-1,-3,2,LOG:12)
B(-1,-4,2,LOG:12)
B(-6,23,3,LOG:12)
B(-6,22,3,LOG:12)
B(-6,25,3,LOG:12)
B(-6,24,3,LOG:12)
B(-6,21,3,LOG:12)
B(-6,20,3,LOG:12)
B(1,19,6,leaves:1)
B(-11,39,1,leaves:1)
B(-11,59,1,leaves:1)
B(0,-8,-3,LOG:12)
B(-6,41,-3,leaves:1)
B(-11,58,1,leaves:1)
B(-6,42,-3,leaves:1)
B(0,-4,-3,LOG:12)
B(-6,47,-3,leaves:1)
B(-6,48,-3,leaves:1)
B(0,-6,-3,LOG:12)
B(-6,45,-3,leaves:1)
B(-6,46,-3,leaves:1)
B(-2,-5,-8,LOG:12)
B(0,-2,-3,LOG:12)
B(-15,22,-16,leaves:1)
B(-15,21,-16,leaves:1)
B(-8,22,-13,leaves:1)
B(-8,23,-13,leaves:1)
B(-8,20,-13,leaves:1)
B(-8,21,-13,leaves:1)
B(-11,60,1,leaves:1)
B(-11,61,1,leaves:1)
B(2,59,6,leaves:1)
B(2,58,6,leaves:1)
B(-2,2,-5,LOG:12)
B(-2,4,-5,LOG:12)
B(-2,3,-5,LOG:12)
B(-2,6,-5,LOG:12)
B(-2,5,-5,LOG:12)
B(2,60,6,leaves:1)
B(-2,7,-5,LOG:12)
B(-6,17,-3,LOG:12)
B(-6,16,-3,LOG:12)
B(-6,19,-3,LOG:12)
B(-6,18,-3,LOG:12)
B(-6,59,3,log)
B(-4,45,-4,leaves:1)
B(-4,44,-4,leaves:1)
B(-6,13,-3,LOG:12)
B(-6,12,-3,LOG:12)
B(-6,15,-3,LOG:12)
B(-6,14,-3,LOG:12)
B(-8,-5,-4,LOG:12)
B(-6,60,3,log)
B(-6,61,3,log)
B(-8,-3,-4,LOG:12)
B(-6,66,3,leaves:1)
B(-6,67,3,leaves:1)
B(-6,68,3,leaves:1)
B(-6,69,3,leaves:1)
B(-6,65,3,leaves:1)
B(-7,25,-12,leaves:1)
B(-7,24,-12,leaves:1)
B(-7,23,-12,leaves:1)
B(-9,0,-3,LOG:12)
B(-7,22,-12,leaves:1)
B(-9,1,-3,LOG:12)
B(-9,2,-3,LOG:12)
B(-6,49,3,LOG:12)
B(-6,48,3,LOG:12)
B(-4,36,-4,leaves:1)
B(4,44,-1,leaves:1)
B(-4,35,-4,leaves:1)
B(-4,34,-4,leaves:1)
B(-4,33,-4,leaves:1)
B(-6,50,3,LOG:12)
B(4,41,-1,leaves:1)
B(-4,42,-4,leaves:1)
B(4,40,-1,leaves:1)
B(-4,43,-4,leaves:1)
B(-4,40,-4,leaves:1)
B(4,43,-1,leaves:1)
B(-4,41,-4,leaves:1)
B(4,42,-1,leaves:1)
B(-6,57,3,log)
B(-6,58,3,log)
B(-6,55,3,leaves:1)
B(-6,56,3,log)
B(-6,53,3,leaves:1)
B(-6,54,3,leaves:1)
B(-6,51,3,LOG:12)
B(-6,52,3,leaves:1)
B(0,28,13,leaves:1)
B(-6,38,3,LOG:12)
B(-6,37,3,LOG:12)
B(-6,39,3,leaves:1)
B(0,24,13,leaves:1)
B(-6,39,-3,leaves:1)
B(0,25,13,leaves:1)
B(-6,38,-3,leaves:1)
B(0,26,13,leaves:1)
B(0,27,13,leaves:1)
B(-6,34,-3,leaves:1)
B(-6,37,-3,leaves:1)
B(-6,33,-3,leaves:1)
B(-4,32,-4,leaves:1)
B(-6,40,-3,leaves:1)
B(-6,40,3,leaves:1)
B(-6,41,3,LOG:12)
B(0,23,13,leaves:1)
B(-6,42,3,LOG:12)
B(0,22,13,leaves:1)
B(-6,43,3,leaves:1)
B(-6,44,3,LOG:12)
B(-6,45,3,LOG:12)
B(-6,46,3,LOG:12)
B(-6,47,3,LOG:12)
B(-6,29,3,LOG:12)
B(-6,28,3,LOG:12)
B(-6,27,3,LOG:12)
B(-6,26,3,LOG:12)
B(-4,16,-4,LOG:12)
B(-4,15,-4,LOG:12)
B(-4,14,-4,LOG:12)
B(-6,21,-3,LOG:12)
B(-4,13,-4,LOG:12)
B(-4,12,-4,LOG:12)
B(-6,20,-3,LOG:12)
B(-4,11,-4,LOG:12)
B(11,19,-6,leaves:1)
B(-6,31,3,LOG:12)
B(-6,32,3,LOG:12)
B(-6,30,3,LOG:12)
B(-6,35,3,LOG:12)
B(-6,36,3,LOG:12)
B(-6,33,3,LOG:12)
B(-6,34,3,LOG:12)
B(1,26,7,leaves:1)
B(1,27,7,leaves:1)
B(1,22,7,leaves:1)
B(1,23,7,leaves:1)
B(1,24,7,leaves:1)
B(1,25,7,leaves:1)
B(-1,61,2,leaves:1)
B(-1,63,2,leaves:1)
B(5,32,-1,leaves:1)
B(-1,62,2,leaves:1)
B(5,33,-1,leaves:1)
B(5,38,-1,leaves:1)
B(5,39,-1,leaves:1)
B(5,31,-1,leaves:1)
B(-1,53,2,leaves:1)
B(5,30,-1,leaves:1)
B(-1,54,2,leaves:1)
B(-1,55,2,leaves:1)
B(-1,56,2,leaves:1)
B(-9,41,11,leaves:1)
B(-9,40,11,leaves:1)
B(1,21,7,leaves:1)
B(1,20,7,leaves:1)
B(-9,42,11,leaves:1)
B(5,29,-1,leaves:1)
B(-5,42,9,leaves:1)
B(-5,41,9,leaves:1)
B(-5,40,9,leaves:1)
B(-1,52,2,leaves:1)
B(-1,51,2,leaves:1)
B(2,23,-5,leaves:1)
B(-1,50,2,leaves:1)
B(5,24,-1,leaves:1)
B(2,25,-5,leaves:1)
B(2,24,-5,leaves:1)
B(1,19,7,leaves:1)
B(-8,29,-4,leaves:1)
B(-1,48,2,leaves:1)
B(-1,49,2,leaves:1)
B(-1,46,2,leaves:1)
B(-1,47,2,leaves:1)
B(-8,31,-4,leaves:1)
B(-8,30,-4,leaves:1)
B(-5,37,9,leaves:1)
B(-5,36,9,leaves:1)
B(-5,39,9,leaves:1)
B(-5,38,9,leaves:1)
B(0,29,-3,leaves:1)
B(-1,36,2,leaves:1)
B(-1,37,2,leaves:1)
B(-1,38,2,leaves:1)
B(-1,39,2,leaves:1)
B(-6,74,3,leaves:1)
B(-8,41,-4,leaves:1)
B(-6,73,3,leaves:1)
B(-6,3,-7,LOG:12)
B(-8,40,-4,leaves:1)
B(-6,76,3,leaves:1)
B(-6,75,3,leaves:1)
B(-8,42,-4,leaves:1)
B(-5,22,9,leaves:1)
B(-6,77,3,leaves:1)
B(0,30,-3,leaves:1)
B(-5,26,9,leaves:1)
B(-8,49,-4,leaves:1)
B(-5,25,9,leaves:1)
B(-8,48,-4,leaves:1)
B(-5,24,9,leaves:1)
B(0,31,-3,leaves:1)
B(-5,23,9,leaves:1)
B(-6,70,3,leaves:1)
B(-5,29,9,leaves:1)
B(-6,72,3,leaves:1)
B(-5,28,9,leaves:1)
B(-6,71,3,leaves:1)
B(-5,27,9,leaves:1)
B(-8,59,-4,leaves:1)
B(-8,57,-4,leaves:1)
B(-2,34,-8,leaves:1)
B(-8,58,-4,leaves:1)
B(-2,33,-8,leaves:1)
B(-2,32,-8,leaves:1)
B(-8,55,-4,leaves:1)
B(-8,56,-4,leaves:1)
B(-2,31,-8,leaves:1)
B(-10,21,8,leaves:1)
B(-2,38,-8,leaves:1)
B(-10,20,8,leaves:1)
B(1,62,7,leaves:1)
B(1,60,7,leaves:1)
B(1,61,7,leaves:1)
B(-12,38,-2,leaves:1)
B(-12,39,-2,leaves:1)
B(-2,21,-8,leaves:2)
B(-2,20,-8,leaves:2)
B(-2,23,-8,leaves:1)
B(1,59,7,leaves:1)
B(-2,22,-8,leaves:2)
B(1,58,7,leaves:1)
B(1,57,7,leaves:1)
B(-2,24,-8,leaves:1)
B(1,56,7,leaves:1)
B(1,55,7,leaves:1)
B(-10,26,5,leaves:1)
B(-10,25,5,leaves:1)
B(1,54,7,leaves:1)
B(-2,19,-8,leaves:2)
B(-10,28,5,leaves:1)
B(-10,27,5,leaves:1)
B(-12,25,-2,leaves:1)
B(-12,26,-2,leaves:1)
B(-1,24,13,leaves:1)
B(-1,25,13,leaves:1)
B(-1,22,13,leaves:1)
B(-1,23,13,leaves:1)
B(-1,20,13,leaves:1)
B(-1,21,13,leaves:1)
B(-18,21,5,leaves:1)
B(-18,20,5,leaves:1)
B(-10,39,5,leaves:1)
B(-10,38,5,leaves:1)
B(-10,37,5,leaves:1)
B(-11,27,1,leaves:1)
B(-11,28,1,leaves:1)
B(-11,29,1,leaves:1)
B(-10,18,8,leaves:1)
B(-10,19,8,leaves:1)
B(2,26,6,leaves:1)
B(2,25,6,leaves:1)
B(-9,39,11,leaves:1)
B(-9,38,11,leaves:1)
B(-9,37,11,leaves:1)
B(-9,36,11,leaves:1)
B(-10,49,5,leaves:1)
B(-18,17,5,leaves:1)
B(-18,18,5,leaves:1)
B(-11,30,1,leaves:1)
B(-18,19,5,leaves:1)
B(-11,32,1,leaves:1)
B(-11,31,1,leaves:1)
B(-10,42,5,leaves:1)
B(-1,64,2,leaves:1)
B(-11,33,1,leaves:1)
B(-10,41,5,leaves:1)
B(-10,40,5,leaves:1)
B(-1,39,5,leaves:1)
B(-3,30,0,leaves:1)
B(-1,34,5,leaves:1)
B(-1,42,5,leaves:1)
B(-1,41,5,leaves:1)
B(-1,44,5,leaves:1)
B(-1,43,5,leaves:1)
B(-1,40,5,leaves:1)
B(-3,41,0,LOG:12)
B(-9,33,-10,leaves:1)
B(-3,40,0,LOG:12)
B(-3,39,0,LOG:12)
B(0,22,8,leaves:1)
B(0,23,8,leaves:1)
B(0,24,8,leaves:1)
B(0,25,8,leaves:1)
B(-1,55,5,leaves:1)
B(-3,31,0,leaves:1)
B(-3,32,0,leaves:1)
B(-1,54,5,leaves:1)
B(-3,33,0,leaves:1)
B(-1,53,5,leaves:1)
B(-3,34,0,leaves:1)
B(-1,52,5,leaves:1)
B(-3,35,0,LOG:12)
B(-3,36,0,LOG:12)
B(-3,37,0,LOG:12)
B(-3,38,0,leaves:1)
B(3,29,2,leaves:1)
B(3,27,2,leaves:1)
B(3,28,2,leaves:1)
B(-3,48,0,leaves:1)
B(-3,46,0,leaves:1)
B(-3,47,0,leaves:1)
B(-3,44,0,leaves:1)
B(-3,45,0,leaves:1)
B(-1,22,5,leaves:1)
B(-3,42,0,LOG:12)
B(-3,43,0,leaves:1)
B(-3,61,0,leaves:1)
B(-1,25,5,leaves:1)
B(-1,26,5,leaves:1)
B(-3,63,0,leaves:1)
B(-1,23,5,leaves:1)
B(-3,62,0,leaves:1)
B(-1,24,5,leaves:1)
B(-1,29,5,leaves:1)
B(-1,27,5,leaves:1)
B(-1,28,5,leaves:1)
B(-18,22,-6,leaves:1)
B(-18,21,-6,leaves:1)
B(-18,20,-6,leaves:1)
B(-18,25,-6,leaves:1)
B(-18,24,-6,leaves:1)
B(-18,23,-6,leaves:1)
B(-12,18,8,leaves:1)
B(3,39,2,leaves:1)
B(-3,57,0,leaves:1)
B(3,31,2,leaves:1)
B(3,32,2,leaves:1)
B(3,33,2,leaves:1)
B(-1,33,5,leaves:1)
B(-3,53,0,leaves:1)
B(-1,32,5,leaves:1)
B(-3,54,0,leaves:1)
B(-3,55,0,leaves:1)
B(-3,56,0,leaves:1)
B(-1,30,5,leaves:1)
B(-7,-6,1,LOG:12)
B(0,53,8,leaves:1)
B(0,54,8,leaves:1)
B(-7,-4,1,LOG:12)
B(-7,-5,1,LOG:12)
B(-7,-2,1,LOG:12)
B(-7,-3,1,LOG:12)
B(0,57,8,leaves:1)
B(0,56,8,leaves:1)
B(0,55,8,leaves:1)
B(-1,57,5,leaves:1)
B(-1,56,5,leaves:1)
B(-11,26,-4,leaves:1)
B(-11,25,-4,leaves:1)
B(2,36,12,leaves:1)
B(-2,58,6,leaves:1)
B(-2,59,6,leaves:1)
B(-2,60,6,leaves:1)
B(-2,64,6,leaves:1)
B(-2,63,6,leaves:1)
B(-2,62,6,leaves:1)
B(-2,61,6,leaves:1)
B(-2,68,6,leaves:1)
B(-2,67,6,leaves:1)
B(-2,66,6,leaves:1)
B(-2,65,6,leaves:1)
B(-2,69,6,leaves:1)
B(-5,28,8,leaves:1)
B(-5,29,8,leaves:1)
B(-5,26,8,leaves:1)
B(3,28,3,leaves:1)
B(-5,27,8,leaves:1)
B(-5,25,8,leaves:1)
B(3,27,3,leaves:1)
B(3,26,3,leaves:1)
B(-2,70,6,leaves:1)
B(-2,75,6,leaves:1)
B(-2,74,6,leaves:1)
B(-2,76,6,leaves:1)
B(-5,38,8,leaves:1)
B(-5,39,8,leaves:1)
B(3,35,3,leaves:1)
B(-5,30,8,leaves:1)
B(-5,31,8,leaves:1)
B(3,34,3,leaves:1)
B(-5,32,8,leaves:1)
B(3,33,3,leaves:1)
B(-8,70,4,leaves:1)
B(-8,74,4,leaves:1)
B(-8,75,4,leaves:1)
B(-8,72,4,leaves:1)
B(-8,73,4,leaves:1)
B(-5,46,8,leaves:1)
B(-5,44,8,leaves:1)
B(-5,45,8,leaves:1)
B(-3,-5,0,LOG:12)
B(-3,-6,0,LOG:12)
B(-3,-4,0,LOG:12)
B(-5,42,8,leaves:1)
B(-5,43,8,leaves:1)
B(-5,40,8,leaves:1)
B(3,43,3,leaves:1)
B(-5,41,8,leaves:1)
B(3,42,3,leaves:1)
B(3,41,3,leaves:1)
B(-8,68,4,leaves:1)
B(-8,69,4,leaves:1)
B(-1,3,-5,LOG:12)
B(-1,2,-5,LOG:12)
B(-16,19,-17,leaves:1)
B(-1,6,-5,LOG:12)
B(-1,5,-5,LOG:12)
B(-1,4,-5,LOG:12)
B(-8,53,4,leaves:1)
B(-8,52,4,leaves:1)
B(-8,51,4,leaves:1)
B(-8,50,4,leaves:1)
B(10,24,-9,leaves:1)
B(-8,59,4,leaves:1)
B(-8,58,4,leaves:1)
B(-8,57,4,leaves:1)
B(-8,56,4,leaves:1)
B(-8,55,4,leaves:1)
B(-2,30,6,leaves:1)
B(-8,42,4,leaves:1)
B(-2,31,6,leaves:1)
B(-8,41,4,leaves:1)
B(-6,-4,3,LOG:12)
B(-2,32,6,leaves:1)
B(-6,-3,3,LOG:12)
B(-6,-2,3,LOG:12)
B(-11,-5,-4,LOG:12)
B(-8,47,4,leaves:1)
B(-11,-4,-4,LOG:12)
B(-11,-2,-4,LOG:12)
B(-8,44,4,leaves:1)
B(-11,-1,-4,LOG:12)
B(-8,43,4,leaves:1)
B(-8,46,4,leaves:1)
B(-8,45,4,leaves:1)
B(-9,32,-10,leaves:1)
B(-9,31,-10,leaves:1)
B(-9,30,-10,leaves:1)
B(-2,39,6,leaves:1)
B(-2,43,6,leaves:1)
B(-2,44,6,leaves:1)
B(-2,41,6,leaves:1)
B(-2,42,6,leaves:1)
B(-2,40,6,leaves:1)
B(-8,34,4,leaves:1)
B(-8,33,4,leaves:1)
B(-8,32,4,leaves:1)
B(0,27,-11,leaves:1)
B(0,28,-11,leaves:1)
B(0,29,-11,leaves:1)
B(-16,20,-17,leaves:1)
B(-9,19,-10,leaves:1)
B(0,30,-11,leaves:1)
B(-9,18,-10,leaves:1)
B(1,32,12,leaves:1)
B(2,40,5,leaves:1)
B(6,29,3,leaves:1)
B(-15,30,-2,leaves:1)
B(6,28,3,leaves:1)
B(-15,31,-2,leaves:1)
B(-15,32,-2,leaves:1)
B(-15,33,-2,leaves:1)
B(-15,34,-2,leaves:1)
B(-12,24,-3,leaves:1)
B(-1,23,8,leaves:1)
B(-12,25,-3,leaves:1)
B(-1,25,8,leaves:1)
B(-1,24,8,leaves:1)
B(2,47,5,leaves:1)
B(2,48,5,leaves:1)
B(1,37,12,leaves:1)
B(2,49,5,leaves:1)
B(1,38,12,leaves:1)
B(1,35,12,leaves:1)
B(-7,-1,3,LOG:12)
B(1,36,12,leaves:1)
B(1,33,12,leaves:1)
B(1,34,12,leaves:1)
B(-9,1,-4,LOG:12)
B(-9,0,-4,LOG:12)
B(-1,32,-9,leaves:1)
B(-15,29,-2,leaves:1)
B(6,30,3,leaves:1)
B(-1,33,-9,leaves:1)
B(-1,34,-9,leaves:1)
B(-15,35,7,leaves:1)
B(-1,41,8,leaves:1)
B(-15,36,7,leaves:1)
B(-1,40,8,leaves:1)
B(-15,34,7,leaves:1)
B(-8,23,-12,leaves:1)
B(-8,24,-12,leaves:1)
B(-1,38,8,leaves:1)
B(-8,25,-12,leaves:1)
B(-1,39,8,leaves:1)
B(-8,26,-12,leaves:1)
B(2,25,-4,leaves:1)
B(2,26,-4,leaves:1)
B(-1,20,-9,leaves:1)
B(2,24,-4,leaves:1)
B(-1,21,-9,leaves:1)
B(-1,22,-9,leaves:1)
B(-6,1,2,LOG:12)
B(1,22,8,leaves:1)
B(-6,2,2,LOG:12)
B(-6,3,2,LOG:12)
B(-6,4,2,LOG:12)
B(-6,0,2,LOG:12)
B(-6,9,2,LOG:12)
B(-6,5,2,LOG:12)
B(-6,6,2,LOG:12)
B(-6,7,2,LOG:12)
B(-6,8,2,LOG:12)
B(-1,26,8,leaves:1)
B(-1,0,-6,LOG:12)
B(-1,18,-9,leaves:2)
B(1,24,8,leaves:1)
B(-1,1,-6,LOG:12)
B(1,23,8,leaves:1)
B(-1,2,-6,LOG:12)
B(-10,0,-3,LOG:12)
B(-1,59,8,leaves:1)
B(-1,57,8,leaves:1)
B(-1,58,8,leaves:1)
B(-1,55,8,leaves:1)
B(-1,56,8,leaves:1)
B(-1,53,8,leaves:1)
B(-1,54,8,leaves:1)
B(-8,40,11,leaves:1)
B(-8,42,11,leaves:1)
B(-8,41,11,leaves:1)
B(-8,48,11,leaves:1)
B(-5,50,8,leaves:1)
B(7,28,-1,leaves:1)
B(7,27,-1,leaves:1)
B(-5,52,8,leaves:1)
B(-5,51,8,leaves:1)
B(7,26,-1,leaves:1)
B(7,25,-1,leaves:1)
B(7,24,-1,leaves:1)
B(-8,37,11,leaves:1)
B(-8,36,11,leaves:1)
B(-8,33,11,leaves:1)
B(-8,32,11,leaves:1)
B(-8,31,11,leaves:1)
B(-8,30,11,leaves:1)
B(2,26,5,leaves:1)
B(2,28,5,leaves:1)
B(-8,38,11,leaves:1)
B(2,27,5,leaves:1)
B(-8,39,11,leaves:1)
B(-7,-2,3,LOG:12)
B(-7,-3,3,LOG:12)
B(-6,2,-6,LOG:12)
B(-6,3,-6,LOG:12)
B(2,39,5,leaves:1)
B(2,38,5,leaves:1)
B(-5,70,8,leaves:1)
B(-6,4,-6,LOG:12)
B(7,30,6,leaves:1)
B(7,31,6,leaves:1)
B(-7,50,3,leaves:1)
B(-7,51,3,leaves:1)
B(-7,52,3,leaves:1)
B(-7,53,3,leaves:1)
B(-7,54,3,leaves:1)
B(-7,49,3,leaves:1)
B(-2,30,11,leaves:1)
B(-2,36,11,leaves:1)
B(-2,37,11,leaves:1)
B(-2,38,11,leaves:1)
B(-7,40,3,leaves:1)
B(-7,43,3,leaves:1)
B(-7,41,3,leaves:1)
B(-7,42,3,leaves:1)
B(-7,38,3,leaves:1)
B(7,29,6,leaves:1)
B(7,28,6,leaves:1)
B(-2,29,11,leaves:1)
B(-2,27,11,leaves:1)
B(-2,28,11,leaves:1)
B(-2,25,11,leaves:1)
B(-2,26,11,leaves:1)
B(-7,36,3,leaves:1)
B(-7,37,3,leaves:1)
B(-2,-2,-7,LOG:12)
B(-2,-4,-7,LOG:12)
B(-7,28,3,LOG:12)
B(-2,-6,-7,LOG:12)
B(-2,55,11,leaves:1)
B(-7,27,3,LOG:12)
B(-2,56,11,leaves:1)
B(-2,57,11,leaves:1)
B(-2,58,11,leaves:1)
B(-2,59,11,leaves:1)
B(-9,55,-2,leaves:1)
B(-19,17,6,leaves:1)
B(-19,16,6,leaves:1)
B(-9,58,-2,leaves:1)
B(-2,-1,-7,LOG:12)
B(-9,56,-2,leaves:1)
B(-9,57,-2,leaves:1)
B(3,24,-3,leaves:1)
B(-2,41,-7,leaves:1)
B(-2,40,-7,leaves:1)
B(1,55,8,leaves:1)
B(-2,39,-7,leaves:1)
B(-2,38,-7,leaves:1)
B(1,54,8,leaves:1)
B(3,26,-3,leaves:1)
B(3,25,-3,leaves:1)
B(-2,34,-7,leaves:1)
B(-2,35,-7,leaves:1)
B(-3,65,0,leaves:1)
B(-3,64,0,leaves:1)
B(-2,33,-7,leaves:1)
B(0,29,12,leaves:1)
B(0,28,12,leaves:1)
B(0,27,12,leaves:1)
B(-17,24,5,leaves:1)
B(-17,25,5,leaves:1)
B(-2,20,-7,leaves:2)
B(-17,22,5,leaves:1)
B(-2,21,-7,leaves:2)
B(-17,23,5,leaves:1)
B(0,30,12,leaves:1)
B(-7,74,3,leaves:1)
B(0,31,12,leaves:1)
B(-2,25,-7,leaves:1)
B(0,32,12,leaves:1)
B(-2,26,-7,leaves:1)
B(0,33,12,leaves:1)
B(-7,71,3,leaves:1)
B(-7,73,3,leaves:1)
B(1,21,9,leaves:1)
B(-7,72,3,leaves:1)
B(1,20,9,leaves:1)
B(-2,18,11,leaves:1)
B(0,34,12,leaves:1)
B(-2,19,-7,leaves:2)
B(-17,21,5,leaves:1)
B(-7,68,3,leaves:1)
B(-7,67,3,leaves:1)
B(-7,66,3,leaves:1)
B(-7,65,3,leaves:1)
B(-7,64,3,leaves:1)
B(-7,63,3,leaves:1)
B(-7,62,3,leaves:1)
B(-7,61,3,leaves:1)
B(1,19,9,leaves:1)
B(-2,8,-4,LOG:12)
B(-2,9,-4,LOG:12)
B(-2,7,-4,LOG:12)
B(-6,30,-5,leaves:1)
B(-6,31,-5,leaves:1)
B(-6,29,-5,leaves:1)
B(-6,42,-5,leaves:1)
B(3,-2,0,LOG:12)
B(-6,35,-5,leaves:1)
B(-6,34,-5,leaves:1)
B(-6,33,-5,leaves:1)
B(-6,36,-5,leaves:1)
B(-9,31,-2,leaves:1)
B(-9,30,-2,leaves:1)
B(-9,32,-2,leaves:1)
B(-4,40,-6,leaves:1)
B(-4,41,-6,leaves:1)
B(-9,39,-2,leaves:1)
B(-9,38,-2,leaves:1)
B(-9,35,-8,leaves:1)
B(-9,37,-8,leaves:1)
B(-9,36,-8,leaves:1)
B(-3,60,-2,leaves:1)
B(-9,37,-2,leaves:1)
B(-9,39,-8,leaves:1)
B(-9,38,-8,leaves:1)
B(-3,59,-2,leaves:1)
B(3,26,-2,leaves:1)
B(3,27,-2,leaves:1)
B(3,25,-2,leaves:1)
B(-4,39,-6,leaves:1)
B(-6,44,-5,leaves:1)
B(-6,43,-5,leaves:1)
B(-4,38,-6,leaves:1)
B(-4,37,-6,leaves:1)
B(-10,56,6,leaves:1)
B(-9,-1,-2,LOG:12)
B(-3,28,-9,leaves:1)
B(-9,-2,-2,LOG:12)
B(-3,29,-9,leaves:1)
B(-3,40,-2,leaves:1)
B(-9,-4,-2,LOG:12)
B(-3,41,-2,leaves:1)
B(-10,51,6,leaves:1)
B(-9,-5,-2,LOG:12)
B(-3,42,-2,leaves:1)
B(-10,52,6,leaves:1)
B(-10,57,6,leaves:1)
B(-10,58,6,leaves:1)
B(-3,21,-12,leaves:1)
B(-3,20,-12,leaves:1)
B(-10,41,3,leaves:1)
B(-10,42,3,leaves:1)
B(-3,23,-12,leaves:1)
B(-3,22,-12,leaves:1)
B(-10,40,3,leaves:1)
B(-10,45,3,leaves:1)
B(-9,-6,-2,LOG:12)
B(-10,46,3,leaves:1)
B(-3,35,-2,leaves:1)
B(-10,43,3,leaves:1)
B(-3,34,-2,leaves:1)
B(-10,44,3,leaves:1)
B(-3,36,-2,leaves:1)
B(-3,39,-2,leaves:1)
B(-10,47,3,leaves:1)
B(-6,38,6,leaves:1)
B(-10,29,3,leaves:1)
B(-6,39,6,leaves:1)
B(-6,37,6,leaves:1)
B(-10,43,6,leaves:1)
B(-3,52,-2,leaves:1)
B(-6,32,6,leaves:1)
B(-3,50,-2,leaves:1)
B(-4,25,-10,leaves:1)
B(-6,33,6,leaves:1)
B(-3,51,-2,leaves:1)
B(-4,24,-10,leaves:1)
B(-6,30,6,leaves:1)
B(-4,23,-10,leaves:1)
B(-6,31,6,leaves:1)
B(-4,22,-10,leaves:1)
B(-4,21,-10,leaves:1)
B(-10,30,3,leaves:1)
B(-10,31,3,leaves:1)
B(-3,44,-2,leaves:1)
B(-10,35,3,leaves:1)
B(-3,43,-2,leaves:1)
B(-10,36,3,leaves:1)
B(-10,37,3,leaves:1)
B(-3,49,-2,leaves:1)
B(-10,38,3,leaves:1)
B(-5,82,7,leaves:1)
B(-6,43,6,leaves:1)
B(-5,81,7,leaves:1)
B(-6,44,6,leaves:1)
B(-5,80,7,leaves:1)
B(-6,45,6,leaves:1)
B(-6,46,6,leaves:1)
B(-6,40,6,leaves:1)
B(-6,41,6,leaves:1)
B(-6,42,6,leaves:1)
B(-2,74,7,leaves:1)
B(-8,-3,1,LOG:12)
B(-2,73,7,leaves:1)
B(-2,70,7,leaves:1)
B(-2,72,7,leaves:1)
B(-2,71,7,leaves:1)
B(9,22,7,leaves:1)
B(9,23,7,leaves:1)
B(9,24,7,leaves:1)
B(-6,54,6,leaves:1)
B(-6,55,6,leaves:1)
B(9,25,7,leaves:1)
B(-6,59,6,leaves:1)
B(-10,26,6,leaves:1)
B(-10,24,6,leaves:1)
B(-10,25,6,leaves:1)
B(-6,52,6,leaves:1)
B(-6,53,6,leaves:1)
B(-6,51,6,leaves:1)
B(-4,0,3,LOG:12)
B(-3,28,-2,LOG:12)
B(-3,23,-9,leaves:1)
B(-3,27,-2,LOG:12)
B(-3,22,-9,leaves:1)
B(-3,26,-2,LOG:12)
B(-3,21,-9,leaves:2)
B(-3,25,-2,LOG:12)
B(-3,20,-9,leaves:2)
B(-3,27,-9,leaves:1)
B(-3,24,-2,LOG:12)
B(-3,26,-9,leaves:1)
B(-3,23,-2,LOG:12)
B(-3,22,-2,LOG:12)
B(-3,24,-9,leaves:1)
B(-3,21,-2,LOG:12)
B(-13,35,-1,leaves:1)
B(-13,34,-1,leaves:1)
B(-17,19,-1,leaves:1)
B(-13,36,-1,leaves:1)
B(-13,31,-1,leaves:1)
B(-13,33,-1,leaves:1)
B(-13,32,-1,leaves:1)
B(-4,-2,-6,LOG:12)
B(-2,53,-1,leaves:1)
B(-4,-6,-6,LOG:12)
B(-4,-5,-6,LOG:12)
B(-4,-4,-6,LOG:12)
B(-4,-3,-6,LOG:12)
B(3,46,0,leaves:1)
B(3,45,0,leaves:1)
B(-2,-1,2,LOG:12)
B(-2,44,-1,leaves:1)
B(3,44,0,leaves:1)
B(-2,43,-1,leaves:1)
B(3,43,0,leaves:1)
B(-2,-7,2,LOG:12)
B(-8,44,-2,leaves:1)
B(-2,-6,2,LOG:12)
B(-8,45,-2,leaves:1)
B(-2,-5,2,LOG:12)
B(3,48,0,leaves:1)
B(-2,-4,2,LOG:12)
B(-9,29,-3,leaves:1)
B(-8,43,-2,leaves:1)
B(3,47,0,leaves:1)
B(-8,40,-2,leaves:1)
B(-8,41,-2,leaves:1)
B(-13,45,-1,leaves:1)
B(-13,44,-1,leaves:1)
B(-13,43,-1,leaves:1)
B(-13,42,-1,leaves:1)
B(-13,41,-1,leaves:1)
B(-2,61,-1,leaves:1)
B(-13,40,-1,leaves:1)
B(-2,60,-1,leaves:1)
B(-2,59,-1,leaves:1)
B(-9,31,-3,leaves:1)
B(-8,39,-2,leaves:1)
B(3,51,0,leaves:1)
B(-2,58,-1,leaves:1)
B(3,50,0,leaves:1)
B(3,53,0,leaves:1)
B(3,52,0,leaves:1)
B(-2,54,-1,leaves:1)
B(-2,57,-1,leaves:1)
B(-2,56,-1,leaves:1)
B(-9,30,-3,leaves:1)
B(-8,38,-2,leaves:1)
B(-17,21,-1,leaves:1)
B(-17,22,-1,leaves:1)
B(-8,32,-2,leaves:1)
B(-8,33,-2,leaves:1)
B(-17,20,-1,leaves:1)
B(-8,34,-2,leaves:1)
B(-2,30,-1,leaves:1)
B(-2,31,-1,leaves:1)
B(-2,24,-1,LOG:12)
B(-13,54,0,leaves:1)
B(-13,55,0,leaves:1)
B(-2,23,-1,LOG:12)
B(-2,22,-1,LOG:12)
B(-2,21,-1,LOG:12)
B(-2,28,-1,LOG:12)
B(-2,27,-1,LOG:12)
B(-2,26,-1,LOG:12)
B(-2,25,-1,LOG:12)
B(-8,62,-2,leaves:1)
B(-8,60,-2,leaves:1)
B(-8,61,-2,leaves:1)
B(-2,29,-1,LOG:12)
B(3,29,0,leaves:1)
B(3,28,0,leaves:1)
B(-9,22,-13,leaves:1)
B(-9,23,-13,leaves:1)
B(-9,24,-13,leaves:1)
B(-6,-5,-5,LOG:12)
B(-6,-4,-5,LOG:12)
B(-6,-3,-5,LOG:12)
B(-6,-2,-5,LOG:12)
B(-11,28,-1,leaves:1)
B(-2,42,-1,leaves:1)
B(-2,33,-1,leaves:1)
B(3,33,0,leaves:1)
B(-8,58,-2,leaves:1)
B(-11,29,-1,leaves:1)
B(-2,32,-1,leaves:1)
B(3,32,0,leaves:1)
B(-8,59,-2,leaves:1)
B(-2,35,-1,leaves:1)
B(3,35,0,leaves:1)
B(3,34,0,leaves:1)
B(-2,36,-1,leaves:1)
B(3,31,0,leaves:1)
B(-9,55,-3,leaves:1)
B(-9,56,-3,leaves:1)
B(3,30,0,leaves:1)
B(-8,52,-2,leaves:1)
B(4,24,-3,leaves:1)
B(-2,20,2,LOG:12)
B(-9,0,-1,LOG:12)
B(-1,5,-2,LOG:12)
B(-1,6,-2,LOG:12)
B(-7,37,4,leaves:1)
B(-2,18,2,LOG:12)
B(-7,36,4,leaves:1)
B(3,40,-2,leaves:1)
B(-1,4,-2,LOG:12)
B(-2,19,2,LOG:12)
B(-7,35,4,leaves:1)
B(3,41,-2,leaves:1)
B(-11,25,13,leaves:1)
B(-7,34,4,leaves:1)
B(-11,26,13,leaves:1)
B(-11,24,13,leaves:1)
B(-2,12,2,LOG:12)
B(-2,13,2,LOG:12)
B(-2,10,2,LOG:12)
B(-2,11,2,LOG:12)
B(-1,9,-2,LOG:12)
B(-2,16,2,LOG:12)
B(-2,17,2,LOG:12)
B(4,22,-3,leaves:1)
B(-1,7,-2,LOG:12)
B(-2,14,2,LOG:12)
B(4,23,-3,leaves:1)
B(-1,8,-2,LOG:12)
B(-2,15,2,LOG:12)
B(-2,20,-1,LOG:12)
B(-4,28,-6,leaves:1)
B(-4,29,-6,leaves:1)
B(-2,31,2,LOG:12)
B(-2,30,2,LOG:12)
B(3,38,-2,leaves:1)
B(3,39,-2,leaves:1)
B(-2,29,2,LOG:12)
B(-7,47,4,leaves:1)
B(-7,46,4,leaves:1)
B(-7,49,4,leaves:1)
B(-7,48,4,leaves:1)
B(-2,18,-1,LOG:12)
B(-7,43,4,leaves:1)
B(-2,19,-1,LOG:12)
B(-7,42,4,leaves:1)
B(-2,21,2,LOG:12)
B(-2,22,2,LOG:12)
B(-2,23,2,LOG:12)
B(-4,30,-6,leaves:1)
B(-2,24,2,LOG:12)
B(-2,17,-1,LOG:12)
B(-2,25,2,LOG:12)
B(-4,32,-6,leaves:1)
B(-2,26,2,LOG:12)
B(-4,31,-6,leaves:1)
B(-2,27,2,LOG:12)
B(-2,28,2,LOG:12)
B(0,61,1,leaves:1)
B(-2,41,2,leaves:1)
B(-2,40,2,leaves:1)
B(0,60,1,leaves:1)
B(-7,54,4,leaves:1)
B(-7,53,4,leaves:1)
B(-9,-3,3,LOG:12)
B(-2,38,2,leaves:1)
B(4,42,-3,leaves:1)
B(-2,39,2,leaves:1)
B(-2,36,2,LOG:12)
B(-2,37,2,LOG:12)
B(-2,34,2,LOG:12)
B(-7,52,4,leaves:1)
B(-2,35,2,LOG:12)
B(-2,32,2,LOG:12)
B(-7,50,4,leaves:1)
B(-2,33,2,LOG:12)
B(4,41,-3,leaves:1)
B(-2,50,2,leaves:1)
B(-2,53,2,leaves:1)
B(-2,52,2,leaves:1)
B(10,18,5,leaves:1)
B(-13,25,-1,leaves:1)
B(-13,26,-1,leaves:1)
B(10,19,5,leaves:1)
B(-13,24,-1,leaves:1)
B(-7,5,-4,LOG:12)
B(-7,64,4,leaves:1)
B(-7,6,-4,LOG:12)
B(-7,3,-4,LOG:12)
B(-7,4,-4,LOG:12)
B(-7,69,4,leaves:1)
B(-7,9,-4,LOG:12)
B(-8,10,-2,LOG:12)
B(-7,68,4,leaves:1)
B(-7,7,-4,LOG:12)
B(-8,12,-2,LOG:12)
B(-7,8,-4,LOG:12)
B(-8,11,-2,LOG:12)
B(-8,14,-2,LOG:12)
B(-8,13,-2,LOG:12)
B(-2,48,2,leaves:1)
B(-2,49,2,leaves:1)
B(-8,15,-2,LOG:12)
B(-7,61,4,leaves:1)
B(-7,60,4,leaves:1)
B(-7,63,4,leaves:1)
B(-7,62,4,leaves:1)
B(-12,20,-16,leaves:1)
B(-2,68,2,leaves:1)
B(-5,-5,-6,LOG:12)
B(-5,-2,-6,LOG:12)
B(-5,-3,-6,LOG:12)
B(-7,3,-5,LOG:12)
B(-7,2,-5,LOG:12)
B(-7,4,-5,LOG:12)
B(0,59,1,leaves:1)
B(0,58,1,leaves:1)
B(-12,19,-16,leaves:1)
B(-7,0,-5,LOG:12)
B(-7,1,-5,LOG:12)
B(0,51,1,leaves:1)
B(0,50,1,leaves:1)
B(0,54,1,leaves:1)
B(0,53,1,leaves:1)
B(0,52,1,leaves:1)
B(-2,59,2,leaves:1)
B(-2,58,2,leaves:1)
B(-7,70,4,leaves:1)
B(-7,71,4,leaves:1)
B(-2,55,2,leaves:1)
B(-7,72,4,leaves:1)
B(-2,54,2,leaves:1)
B(-7,73,4,leaves:1)
B(-2,57,2,leaves:1)
B(-9,31,3,leaves:1)
B(-7,74,4,leaves:1)
B(-2,56,2,leaves:1)
B(-7,75,4,leaves:1)
B(-9,33,3,leaves:1)
B(-7,76,4,leaves:1)
B(-9,32,3,leaves:1)
B(-7,77,4,leaves:1)
B(-9,34,3,leaves:1)
B(-9,37,3,leaves:1)
B(-9,39,3,leaves:1)
B(-9,38,3,leaves:1)
B(0,45,1,leaves:1)
B(-2,61,2,leaves:1)
B(8,25,7,leaves:1)
B(-2,62,2,leaves:1)
B(8,26,7,leaves:1)
B(-2,63,2,leaves:1)
B(8,27,7,leaves:1)
B(-2,64,2,leaves:1)
B(0,42,1,leaves:1)
B(0,44,1,leaves:1)
B(-2,60,2,leaves:1)
B(0,43,1,leaves:1)
B(4,20,17,leaves:1)
B(0,39,1,leaves:1)
B(0,38,1,leaves:1)
B(0,37,1,leaves:1)
B(0,36,1,leaves:1)
B(0,35,1,leaves:1)
B(0,34,1,leaves:1)
B(-6,9,-5,LOG:12)
B(-6,7,-5,LOG:12)
B(-6,8,-5,LOG:12)
B(-6,5,-5,LOG:12)
B(-6,6,-5,LOG:12)
B(-6,3,-5,LOG:12)
B(-6,4,-5,LOG:12)
B(-2,1,-7,LOG:12)
B(-2,2,-7,LOG:12)
B(-9,67,3,leaves:1)
B(-9,68,3,leaves:1)
B(-9,66,3,leaves:1)
B(-13,40,0,leaves:1)
B(-13,42,0,leaves:1)
B(-13,41,0,leaves:1)
B(-13,44,0,leaves:1)
B(-13,43,0,leaves:1)
B(2,34,2,leaves:1)
B(2,33,2,leaves:1)
B(2,32,2,leaves:1)
B(2,31,2,leaves:1)
B(2,30,2,leaves:1)
B(1,1,0,LOG:12)
B(1,2,0,LOG:12)
B(1,0,0,LOG:12)
B(-8,40,8,leaves:1)
B(-10,37,12,leaves:1)
B(-10,36,12,leaves:1)
B(-10,35,12,leaves:1)
B(-13,31,0,leaves:1)
B(-13,30,0,leaves:1)
B(2,45,2,leaves:1)
B(2,44,2,leaves:1)
B(-9,70,3,leaves:1)
B(-10,29,12,leaves:1)
B(-9,71,3,leaves:1)
B(-13,32,0,leaves:1)
B(-13,39,0,leaves:1)
B(2,41,2,leaves:1)
B(-13,38,0,leaves:1)
B(2,43,2,leaves:1)
B(2,42,2,leaves:1)
B(-13,29,0,leaves:1)
B(-8,52,8,leaves:1)
B(-8,53,8,leaves:1)
B(-8,54,8,leaves:1)
B(-8,55,8,leaves:1)
B(-8,56,8,leaves:1)
B(-8,57,8,leaves:1)
B(-8,58,8,leaves:1)
B(-15,23,0,leaves:1)
B(3,19,16,leaves:1)
B(-9,49,3,leaves:1)
B(-15,24,0,leaves:1)
B(-15,25,0,leaves:1)
B(3,17,16,leaves:1)
B(-13,20,0,leaves:1)
B(-9,47,3,leaves:1)
B(-15,26,0,leaves:1)
B(3,18,16,leaves:1)
B(-9,48,3,leaves:1)
B(-9,45,3,leaves:1)
B(-9,46,3,leaves:1)
B(-9,43,3,leaves:1)
B(-9,44,3,leaves:1)
B(-13,26,0,leaves:1)
B(-13,25,0,leaves:1)
B(-13,28,0,leaves:1)
B(-13,27,0,leaves:1)
B(-13,22,0,leaves:1)
B(-13,21,0,leaves:1)
B(-15,20,0,leaves:1)
B(-13,24,0,leaves:1)
B(-15,21,0,leaves:1)
B(-13,23,0,leaves:1)
B(-15,22,0,leaves:1)
B(-8,23,8,leaves:1)
B(-8,24,8,leaves:1)
B(-8,21,8,leaves:1)
B(-8,22,8,leaves:1)
B(2,29,2,leaves:1)
B(-9,54,3,leaves:1)
B(-9,55,3,leaves:1)
B(-15,19,0,leaves:1)
B(-9,51,3,leaves:1)
B(-9,52,3,leaves:1)
B(-9,53,3,leaves:1)
B(0,37,11,leaves:1)
B(0,38,11,leaves:1)
B(0,39,11,leaves:1)
B(0,33,11,leaves:1)
B(0,34,11,leaves:1)
B(0,35,11,leaves:1)
B(0,36,11,leaves:1)
B(3,21,16,leaves:1)
B(3,20,16,leaves:1)
B(3,22,16,leaves:1)
B(3,-2,-1,LOG:12)
B(-8,38,8,leaves:1)
B(-13,26,-14,leaves:1)
B(0,-1,1,LOG:12)
B(-13,25,-14,leaves:1)
B(-13,24,-14,leaves:1)
B(0,-3,1,LOG:12)
B(0,-2,1,LOG:12)
B(0,-4,1,LOG:12)
B(0,2,0,LOG:12)
B(-4,-4,-5,LOG:12)
B(0,3,0,LOG:12)
B(-4,-5,-5,LOG:12)
B(0,0,0,LOG:12)
B(-4,-2,-5,LOG:12)
B(0,1,0,LOG:12)
B(-4,-3,-5,LOG:12)
B(0,4,0,LOG:12)
B(-5,78,7,leaves:1)
B(-5,79,7,leaves:1)
B(-5,76,7,leaves:1)
B(-5,77,7,leaves:1)
B(0,40,11,leaves:1)
B(0,41,11,leaves:1)
B(-6,75,6,leaves:1)
B(0,42,11,leaves:1)
B(-6,77,6,leaves:1)
B(-5,70,7,leaves:1)
B(-6,76,6,leaves:1)
B(-5,71,7,leaves:1)
B(-6,79,6,leaves:1)
B(-6,78,6,leaves:1)
B(-5,74,7,leaves:1)
B(-5,75,7,leaves:1)
B(-5,72,7,leaves:1)
B(-5,73,7,leaves:1)
B(1,40,4,leaves:1)
B(-6,60,6,leaves:1)
B(1,41,4,leaves:1)
B(-5,69,7,leaves:1)
B(-6,64,6,leaves:1)
B(-6,63,6,leaves:1)
B(-6,62,6,leaves:1)
B(1,48,4,leaves:1)
B(-6,61,6,leaves:1)
B(1,47,4,leaves:1)
B(-6,68,6,leaves:1)
B(-6,67,6,leaves:1)
B(1,49,4,leaves:1)
B(-6,66,6,leaves:1)
B(-6,65,6,leaves:1)
B(-5,60,7,leaves:1)
B(10,21,8,leaves:1)
B(10,22,8,leaves:1)
B(-5,58,7,leaves:1)
B(-5,59,7,leaves:1)
B(-5,56,7,leaves:1)
B(-5,57,7,leaves:1)
B(-5,54,7,leaves:1)
B(-5,55,7,leaves:1)
B(-5,52,7,leaves:1)
B(-5,53,7,leaves:1)
B(3,40,2,leaves:1)
B(10,19,8,leaves:1)
B(-5,47,7,leaves:1)
B(-5,48,7,leaves:1)
B(-5,49,7,leaves:1)
B(-6,82,6,leaves:1)
B(-5,43,7,leaves:1)
B(-6,81,6,leaves:1)
B(-5,44,7,leaves:1)
B(-6,80,6,leaves:1)
B(-5,45,7,leaves:1)
B(-5,46,7,leaves:1)
B(3,42,2,leaves:1)
B(3,41,2,leaves:1)
B(-5,41,7,leaves:1)
B(-5,42,7,leaves:1)
B(-5,29,7,leaves:1)
B(2,20,8,leaves:1)
B(2,21,8,leaves:1)
B(2,22,8,leaves:1)
B(2,23,8,leaves:1)
B(-9,21,-8,leaves:1)
B(-9,22,-8,leaves:1)
B(-9,23,-8,leaves:1)
B(-5,31,7,leaves:1)
B(-5,30,7,leaves:1)
B(-5,35,7,leaves:1)
B(-5,34,7,leaves:1)
B(-5,33,7,leaves:1)
B(-5,32,7,leaves:1)
B(8,29,-6,leaves:1)
B(8,28,-6,leaves:1)
B(9,22,-5,leaves:1)
B(9,24,-5,leaves:1)
B(9,23,-5,leaves:1)
