
#
# +-----------------------------------------------------------------+ #
# |                            BO3 object                           | #
# +-----------------------------------------------------------------+ #
#

Author: NLBlackEagle

Description: Converted version of the BO2 52

Version: 3

SettingsMode: WriteDisable


#
# +-----------------------------------------------------------------+ #
# |                          Main settings                          | #
# +-----------------------------------------------------------------+ #
#

Tree: true

Frequency: 3

Rarity: 10.0

RotateRandomly: true

SpawnHeight: highestSolidBlock

SpawnHeightOffset: 0

SpawnHeightVariance: 0


# Height Limits for the BO3. #


MinHeight: 0

MaxHeight: 95


# Extrusion settings #


ExtrudeMode: None

ExtrudeThroughBlocks: air

MaxBranchDepth: 10

ExcludedBiomes: 


#
# +-----------------------------------------------------------------+ #
# |                      Source block settings                      | #
# +-----------------------------------------------------------------+ #
#

SourceBlocks: AIR,GRASS,DIRT,SAND

MaxPercentageOutsideSourceBlock: 0

OutsideSourceBlock: placeAnyway


#
# +-----------------------------------------------------------------+ #
# |                              Blocks                             | #
# +-----------------------------------------------------------------+ #
#

B(-7,1,4,leaves:2)
B(-1,6,3,leaves:2)
B(-4,2,6,leaves:2)
B(-1,8,4,leaves:2)
B(-1,2,3,leaves:2)
B(-1,3,4,leaves:2)
B(-4,7,6,leaves:2)
B(-1,2,4,leaves:2)
B(-1,1,4,leaves:2)
B(-7,5,4,leaves:2)
B(-1,6,4,leaves:2)
B(-4,3,6,leaves:2)
B(-1,5,4,leaves:2)
B(-4,5,6,leaves:2)
B(-7,2,4,leaves:2)
B(1,1,1,leaves:2)
B(-3,3,8,leaves:2)
B(-3,10,2,leaves:2)
B(-3,2,8,leaves:2)
B(-3,13,5,leaves:2)
B(0,2,2,leaves:2)
B(0,5,2,leaves:2)
B(-3,0,4,LOG:12)
B(-3,1,4,LOG:12)
B(-1,1,0,leaves:2)
B(-3,2,4,LOG:12)
B(-1,0,0,leaves:2)
B(-3,3,4,LOG:12)
B(-3,12,2,leaves:2)
B(0,1,2,leaves:2)
B(-3,4,4,leaves:2)
B(-3,5,4,LOG:12)
B(-3,6,4,leaves:2)
B(-3,7,4,leaves:2)
B(-3,8,4,leaves:2)
B(-3,9,4,leaves:2)
B(-4,12,2,leaves:2)
B(-4,14,4,leaves:2)
B(-2,-4,4,LOG:12)
B(-5,2,7,leaves:2)
B(-5,7,7,leaves:2)
B(-3,10,1,leaves:2)
B(-5,4,0,leaves:2)
B(-5,1,0,leaves:2)
B(-5,10,4,leaves:2)
B(-7,1,0,leaves:2)
B(-4,10,2,leaves:2)
B(-8,2,2,leaves:2)
B(-5,11,4,leaves:2)
B(0,6,3,leaves:2)
B(-6,2,2,leaves:2)
B(-6,3,2,leaves:2)
B(0,1,7,leaves:2)
B(-6,9,2,leaves:2)
B(-6,5,2,leaves:2)
B(-6,8,2,leaves:2)
B(-4,3,2,leaves:2)
B(-5,9,4,leaves:2)
B(-4,5,2,leaves:2)
B(-4,6,2,leaves:2)
B(-5,7,4,leaves:2)
B(-5,6,4,leaves:2)
B(-4,2,2,leaves:2)
B(-5,3,4,leaves:2)
B(-5,2,4,leaves:2)
B(-6,2,6,leaves:2)
B(-4,8,2,leaves:2)
B(-4,9,2,leaves:2)
B(-5,4,-1,leaves:2)
B(-6,5,6,leaves:2)
B(-4,2,9,leaves:2)
B(-2,7,0,leaves:2)
B(-4,2,7,leaves:2)
B(-4,3,7,leaves:2)
B(-7,1,5,leaves:2)
B(-1,10,2,leaves:2)
B(-7,5,5,leaves:2)
B(-1,1,7,leaves:2)
B(-7,6,5,leaves:2)
B(-1,2,7,leaves:2)
B(1,1,0,leaves:2)
B(-2,0,0,leaves:2)
B(-7,5,3,leaves:2)
B(-4,7,5,leaves:2)
B(-4,6,5,leaves:2)
B(-2,1,0,leaves:2)
B(-4,9,5,leaves:2)
B(-4,8,5,leaves:2)
B(-7,2,3,leaves:2)
B(-4,3,5,leaves:2)
B(-3,2,9,leaves:2)
B(-4,-4,2,LOG:12)
B(-3,4,5,leaves:2)
B(-3,3,5,leaves:2)
B(0,1,3,leaves:2)
B(-3,9,5,leaves:2)
B(-3,6,5,leaves:2)
B(-3,7,5,leaves:2)
B(-2,3,3,leaves:2)
B(-2,2,3,leaves:2)
B(-2,2,9,leaves:2)
B(-2,7,3,leaves:2)
B(-3,7,3,leaves:2)
B(-2,9,4,leaves:2)
B(-3,8,3,LOG:12)
B(-2,6,3,leaves:2)
B(-3,9,3,leaves:2)
B(-2,7,4,leaves:2)
B(-2,6,4,leaves:2)
B(-3,3,3,LOG:12)
B(-3,4,3,LOG:12)
B(-2,9,3,leaves:2)
B(-3,5,3,LOG:12)
B(-4,-7,4,LOG:12)
B(0,2,1,leaves:2)
B(-2,8,3,leaves:2)
B(-3,6,3,LOG:12)
B(0,1,1,leaves:2)
B(-2,3,4,leaves:2)
B(-4,-1,4,LOG:12)
B(-2,2,4,leaves:2)
B(-3,0,3,LOG:12)
B(-3,1,3,LOG:12)
B(-4,-3,4,LOG:12)
B(-4,-2,4,LOG:12)
B(-3,2,3,LOG:12)
B(0,5,1,leaves:2)
B(-5,8,1,leaves:2)
B(-4,12,4,leaves:2)
B(-4,13,4,leaves:2)
B(-4,10,4,leaves:2)
B(-4,11,4,leaves:2)
B(-8,1,1,leaves:2)
B(-5,2,1,leaves:2)
B(-5,1,1,leaves:2)
B(-5,4,1,leaves:2)
B(-4,-3,3,LOG:12)
B(-8,1,3,leaves:2)
B(-4,-4,3,LOG:12)
B(-4,-5,3,LOG:12)
B(-7,1,1,leaves:2)
B(-4,-6,3,LOG:12)
B(-4,-1,3,LOG:12)
B(-4,-2,3,LOG:12)
B(-8,1,4,leaves:2)
B(-4,-7,3,LOG:12)
B(-8,2,3,leaves:2)
B(-4,8,1,leaves:2)
B(-6,6,5,leaves:2)
B(-6,5,5,leaves:2)
B(-5,4,3,leaves:2)
B(-5,3,3,leaves:2)
B(-6,3,3,leaves:2)
B(-6,2,3,leaves:2)
B(-6,2,5,leaves:2)
B(-6,5,3,leaves:2)
B(-6,1,5,leaves:2)
B(-5,7,3,leaves:2)
B(-4,1,1,leaves:2)
B(-5,6,3,leaves:2)
B(-4,2,1,leaves:2)
B(-6,6,3,leaves:2)
B(-6,9,3,leaves:2)
B(-4,4,1,leaves:2)
B(-4,5,1,leaves:2)
B(-5,9,3,leaves:2)
B(-4,7,1,leaves:2)
B(-5,6,5,leaves:2)
B(-4,1,3,LOG:12)
B(-5,3,5,leaves:2)
B(-4,0,3,LOG:12)
B(-4,3,3,leaves:2)
B(-4,2,3,LOG:12)
B(-5,7,5,leaves:2)
B(-4,5,3,leaves:2)
B(-4,4,3,LOG:12)
B(-4,7,3,leaves:2)
B(-4,6,3,LOG:12)
B(-4,9,3,leaves:2)
B(-4,8,3,leaves:2)
B(-6,1,1,leaves:2)
B(-6,2,1,leaves:2)
B(-5,2,5,leaves:2)
B(-6,3,1,leaves:2)
B(1,1,3,leaves:2)
B(1,0,3,leaves:2)
B(-1,2,2,leaves:2)
B(-4,9,4,leaves:2)
B(-1,5,2,leaves:2)
B(-4,7,4,leaves:2)
B(-1,6,2,leaves:2)
B(-4,8,4,leaves:2)
B(-1,7,2,leaves:2)
B(-4,6,4,leaves:2)
B(-1,7,1,leaves:2)
B(-4,3,4,leaves:2)
B(-4,4,4,leaves:2)
B(0,1,0,leaves:2)
B(-2,13,5,leaves:2)
B(-4,0,4,LOG:12)
B(-1,5,1,leaves:2)
B(-4,4,0,leaves:2)
B(-3,6,6,leaves:2)
B(-1,2,1,leaves:2)
B(-3,7,6,leaves:2)
B(-1,1,1,leaves:2)
B(-3,8,6,leaves:2)
B(-4,7,0,leaves:2)
B(0,1,4,leaves:2)
B(-2,-4,2,LOG:12)
B(1,5,3,leaves:2)
B(-3,3,6,leaves:2)
B(-3,15,3,leaves:2)
B(-3,14,3,LOG:12)
B(-3,13,3,leaves:2)
B(-3,12,3,leaves:2)
B(-7,9,2,leaves:2)
B(-3,17,3,LOG:12)
B(-3,16,3,LOG:12)
B(-2,2,8,leaves:2)
B(-7,2,2,leaves:2)
B(-5,10,3,leaves:2)
B(-5,11,3,leaves:2)
B(-5,12,3,leaves:2)
B(-3,-8,4,LOG:12)
B(-4,2,8,leaves:2)
B(-3,-7,4,LOG:12)
B(-4,1,8,leaves:2)
B(-3,-4,4,LOG:12)
B(-3,-3,4,LOG:12)
B(-3,-6,4,LOG:12)
B(-3,-5,4,LOG:12)
B(-3,-2,4,LOG:12)
B(-3,-1,4,LOG:12)
B(-2,2,5,leaves:2)
B(-3,6,2,leaves:2)
B(-2,3,5,leaves:2)
B(-3,5,2,leaves:2)
B(-2,5,5,leaves:2)
B(-3,4,2,leaves:2)
B(-3,2,2,leaves:2)
B(-8,5,5,leaves:2)
B(-3,4,1,leaves:2)
B(-3,2,1,leaves:2)
B(-3,1,1,leaves:2)
B(-3,8,1,leaves:2)
B(-2,6,5,leaves:2)
B(-8,1,5,leaves:2)
B(-4,14,3,leaves:2)
B(-3,9,2,leaves:2)
B(-2,9,5,leaves:2)
B(-3,8,2,leaves:2)
B(-2,-3,3,LOG:12)
B(-6,8,4,leaves:2)
B(-1,10,3,leaves:2)
B(-6,6,4,leaves:2)
B(-2,3,7,leaves:2)
B(-6,2,4,leaves:2)
B(-2,2,7,leaves:2)
B(-2,-7,3,LOG:12)
B(-2,-8,3,LOG:12)
B(-2,-5,3,LOG:12)
B(0,5,4,leaves:2)
B(1,1,2,leaves:2)
B(0,5,5,leaves:2)
B(-6,1,0,leaves:2)
B(-5,2,2,leaves:2)
B(-4,10,3,leaves:2)
B(-5,3,2,leaves:2)
B(-4,11,3,leaves:2)
B(-5,4,2,leaves:2)
B(-4,12,3,leaves:2)
B(-1,8,5,leaves:2)
B(-1,2,6,leaves:2)
B(-1,9,5,leaves:2)
B(-1,9,6,leaves:2)
B(-1,8,6,leaves:2)
B(-1,5,5,leaves:2)
B(-5,6,2,leaves:2)
B(-5,8,2,leaves:2)
B(-1,2,5,leaves:2)
B(-5,9,2,leaves:2)
B(-1,1,5,leaves:2)
B(-1,10,4,leaves:2)
B(-2,8,2,leaves:2)
B(-2,7,2,leaves:2)
B(-2,13,4,leaves:2)
B(-2,6,2,leaves:2)
B(-2,4,2,leaves:2)
B(-2,2,2,leaves:2)
B(-3,11,4,leaves:2)
B(-5,2,6,leaves:2)
B(-2,4,1,leaves:2)
B(-3,10,4,leaves:2)
B(-5,5,6,leaves:2)
B(-2,2,1,leaves:2)
B(-5,7,6,leaves:2)
B(-2,8,1,leaves:2)
B(-2,7,1,leaves:2)
B(-3,-7,2,LOG:12)
B(-3,-8,2,LOG:12)
B(-2,1,1,leaves:2)
B(0,1,8,leaves:2)
B(-2,10,2,leaves:2)
B(-3,-3,2,LOG:12)
B(-3,-4,2,LOG:12)
B(-3,-6,3,LOG:12)
B(-3,-7,3,LOG:12)
B(-3,-1,3,LOG:12)
B(-5,12,2,leaves:2)
B(-3,-4,3,LOG:12)
B(-3,-5,3,LOG:12)
B(-5,10,2,leaves:2)
B(-3,-2,3,LOG:12)
B(-3,-3,3,LOG:12)
B(-3,3,0,leaves:2)
B(-3,4,0,leaves:2)
B(-3,13,4,leaves:2)
B(-3,7,0,leaves:2)
B(-3,14,4,leaves:2)
B(-3,8,0,leaves:2)
B(-3,11,3,leaves:2)
B(-3,10,3,leaves:2)
B(-2,8,6,leaves:2)
B(-2,13,3,leaves:2)
B(-2,2,6,leaves:2)
B(-2,3,6,leaves:2)
B(-2,11,3,leaves:2)
B(-2,10,3,leaves:2)
B(-1,0,-1,leaves:2)
B(-2,10,4,leaves:2)
B(-2,11,4,leaves:2)

#
# +-----------------------------------------------------------------+ #
# |                            BO3 checks                           | #
# +-----------------------------------------------------------------+ #
#

BlockCheck(0,-2,0,Solid)
BlockCheck(0,-1,0,grass,dirt)
BlockCheck(0,-1,2,grass,dirt)
BlockCheck(2,-1,0,grass,dirt)
BlockCheck(-2,-1,0,grass,dirt)
BlockCheck(0,-1,-2,grass,dirt)
BlockCheck(0,-1,0,Solid)
BlockCheckNot(0,-1,0,air)

#
# +-----------------------------------------------------------------+ #
# |                             Branches                            | #
# +-----------------------------------------------------------------+ #
#

