
#
# +-----------------------------------------------------------------+ #
# |                            BO3 object                           | #
# +-----------------------------------------------------------------+ #
#

Author: NLBlackEagle

Description: Converted version of the BO2 86

Version: 3

SettingsMode: WriteDisable


#
# +-----------------------------------------------------------------+ #
# |                          Main settings                          | #
# +-----------------------------------------------------------------+ #
#

Tree: true

Frequency: 1

Rarity: 5.0

RotateRandomly: true

SpawnHeight: highestSolidBlock

SpawnHeightOffset: 0

SpawnHeightVariance: 0


# Height Limits for the BO3. #


MinHeight: 0

MaxHeight: 199


# Extrusion settings #


ExtrudeMode: None

ExtrudeThroughBlocks: air

MaxBranchDepth: 10

ExcludedBiomes: 


#
# +-----------------------------------------------------------------+ #
# |                      Source block settings                      | #
# +-----------------------------------------------------------------+ #
#

SourceBlocks: AIR,GRASS,DIRT,SAND

MaxPercentageOutsideSourceBlock: 0

OutsideSourceBlock: placeAnyway


#
# +-----------------------------------------------------------------+ #
# |                              Blocks                             | #
# +-----------------------------------------------------------------+ #
#

B(-7,9,4,Leaves:4)
B(0,12,-12,Leaves:4)
B(-5,-5,2,LOG:12)
B(-5,-4,2,LOG:12)
B(9,8,-5,Leaves:4)
B(9,7,-5,Leaves:4)
B(9,5,-5,Leaves:4)
B(-13,12,4,Leaves:4)
B(-13,11,4,Leaves:4)
B(-13,10,4,Leaves:4)
B(-3,9,8,Leaves:4)
B(-3,8,8,Leaves:4)
B(-3,7,8,Leaves:4)
B(-3,6,8,Leaves:4)
B(9,9,-5,Leaves:4)
B(0,5,2,LOG:12)
B(-1,3,0,LOG:12)
B(-1,2,0,LOG:12)
B(-1,4,0,LOG:12)
B(-1,7,0,Leaves:4)
B(-1,8,0,Leaves:4)
B(-1,9,0,Leaves:4)
B(6,7,-10,Leaves:4)
B(-1,9,10,Leaves:4)
B(1,10,-13,Leaves:4)
B(6,9,-10,Leaves:4)
B(6,8,-10,Leaves:4)
B(0,8,2,LOG:12)
B(0,9,2,Leaves:4)
B(1,8,-7,Leaves:4)
B(0,6,2,LOG:12)
B(0,7,2,Leaves:4)
B(-5,5,-15,Leaves:4)
B(-5,6,-15,Leaves:4)
B(-5,4,-15,Leaves:4)
B(-6,9,-11,Leaves:4)
B(-6,8,-11,Leaves:4)
B(-6,7,-11,Leaves:4)
B(3,16,-5,Leaves:4)
B(3,17,-5,Leaves:4)
B(-5,7,-15,Leaves:4)
B(-5,8,-15,Leaves:4)
B(3,11,-5,Leaves:4)
B(3,10,-5,Leaves:4)
B(3,15,-5,Leaves:4)
B(3,14,-5,Leaves:4)
B(3,12,-5,Leaves:4)
B(-4,6,9,Leaves:4)
B(-4,7,9,Leaves:4)
B(-4,5,9,Leaves:4)
B(-11,8,8,Leaves:4)
B(-11,7,8,Leaves:4)
B(-11,9,8,Leaves:4)
B(-11,6,8,Leaves:4)
B(-11,5,8,Leaves:4)
B(5,13,8,Leaves:4)
B(-8,6,9,Leaves:4)
B(5,12,8,Leaves:4)
B(-8,7,9,Leaves:4)
B(-1,9,9,Leaves:4)
B(-8,8,9,Leaves:4)
B(5,11,8,Leaves:4)
B(6,9,-7,Leaves:4)
B(-8,9,9,Leaves:4)
B(5,10,8,Leaves:4)
B(7,10,-6,Leaves:4)
B(-7,11,-7,Leaves:4)
B(-7,12,-7,Leaves:4)
B(-7,13,-7,Leaves:4)
B(7,12,-6,Leaves:4)
B(-7,14,-7,Leaves:4)
B(7,11,-6,Leaves:4)
B(-7,15,-7,Leaves:4)
B(-13,7,3,Leaves:4)
B(-13,6,3,Leaves:4)
B(-13,9,3,Leaves:4)
B(-13,8,3,Leaves:4)
B(-5,14,9,Leaves:4)
B(-5,12,9,Leaves:4)
B(-5,13,9,Leaves:4)
B(3,14,4,Leaves:4)
B(3,13,4,Leaves:4)
B(7,13,-6,Leaves:4)
B(-5,10,9,Leaves:4)
B(3,12,4,Leaves:4)
B(-5,11,9,Leaves:4)
B(3,11,4,Leaves:4)
B(3,10,4,Leaves:4)
B(-1,17,-7,Leaves:4)
B(-4,5,-4,LOG:12)
B(-4,4,-4,LOG:12)
B(-4,7,-4,LOG:12)
B(10,9,0,Leaves:4)
B(-4,6,-4,LOG:12)
B(-4,9,-4,LOG:12)
B(-4,8,-4,LOG:12)
B(-8,-5,2,LOG:12)
B(-11,8,0,Leaves:4)
B(6,8,1,Leaves:4)
B(6,6,1,Leaves:4)
B(10,8,0,Leaves:4)
B(6,9,1,Leaves:4)
B(-8,9,13,Leaves:4)
B(-10,5,11,Leaves:4)
B(-10,4,11,Leaves:4)
B(-10,7,11,Leaves:4)
B(-4,9,1,Leaves:4)
B(-5,8,3,Leaves:4)
B(-5,9,3,Leaves:4)
B(-4,15,-11,Leaves:4)
B(-4,10,-11,Leaves:4)
B(-1,11,-7,LOG:12)
B(-1,10,-7,Leaves:4)
B(-1,16,-7,Leaves:4)
B(-4,14,-11,Leaves:4)
B(-7,11,-13,Leaves:4)
B(-1,15,-7,Leaves:4)
B(-4,13,-11,Leaves:4)
B(-1,14,-7,Leaves:4)
B(-4,12,-11,Leaves:4)
B(-1,13,-7,Leaves:4)
B(-4,11,-11,Leaves:4)
B(-10,14,-8,Leaves:4)
B(2,8,0,Leaves:4)
B(2,7,0,Leaves:4)
B(2,6,0,Leaves:4)
B(-10,10,-8,Leaves:4)
B(-10,11,-8,Leaves:4)
B(-10,12,-8,Leaves:4)
B(-10,13,-8,Leaves:4)
B(4,8,6,LOG:12)
B(-3,9,-3,Leaves:4)
B(-3,8,-3,Leaves:4)
B(4,7,6,Leaves:4)
B(-3,3,-3,LOG:12)
B(-3,2,-3,LOG:12)
B(-3,1,-3,LOG:12)
B(-3,0,-3,LOG:12)
B(-12,7,8,Leaves:4)
B(-3,6,-3,LOG:12)
B(-12,6,8,Leaves:4)
B(-3,5,-3,LOG:12)
B(-12,9,8,Leaves:4)
B(-12,8,8,Leaves:4)
B(-3,4,-3,LOG:12)
B(-13,8,-7,Leaves:4)
B(1,8,7,Leaves:4)
B(-13,9,-7,Leaves:4)
B(1,9,7,Leaves:4)
B(-16,8,-1,Leaves:4)
B(-8,11,2,Leaves:4)
B(-16,9,-1,Leaves:4)
B(-8,10,2,Leaves:4)
B(1,6,7,Leaves:4)
B(1,7,7,Leaves:4)
B(-16,7,-1,Leaves:4)
B(-8,15,2,Leaves:4)
B(-8,14,2,Leaves:4)
B(2,9,9,Leaves:4)
B(-8,13,2,Leaves:4)
B(-8,12,2,Leaves:4)
B(-15,9,-1,Leaves:4)
B(-15,8,-1,Leaves:4)
B(-1,11,-13,Leaves:4)
B(-15,7,-1,Leaves:4)
B(-1,10,-13,Leaves:4)
B(-1,13,-13,Leaves:4)
B(-1,12,-13,Leaves:4)
B(0,8,-7,Leaves:4)
B(-6,-4,-3,LOG:12)
B(-6,-5,-3,LOG:12)
B(-15,10,1,Leaves:4)
B(-11,8,-11,Leaves:4)
B(-11,7,-11,Leaves:4)
B(-15,11,1,Leaves:4)
B(-3,11,7,LOG:12)
B(-5,17,0,Leaves:4)
B(-3,10,7,Leaves:4)
B(-5,16,0,Leaves:4)
B(-15,7,-9,Leaves:4)
B(9,11,-2,Leaves:4)
B(-5,15,0,Leaves:4)
B(9,12,-2,Leaves:4)
B(-3,15,7,Leaves:4)
B(-5,14,0,LOG:12)
B(-3,14,7,Leaves:4)
B(9,10,-2,Leaves:4)
B(-3,13,7,Leaves:4)
B(-3,12,7,Leaves:4)
B(-5,11,0,Leaves:4)
B(-11,13,-5,Leaves:4)
B(7,9,5,Leaves:4)
B(-11,12,-5,Leaves:4)
B(-11,13,5,Leaves:4)
B(-11,11,-5,Leaves:4)
B(-11,14,5,Leaves:4)
B(-11,10,-5,Leaves:4)
B(-8,16,2,Leaves:4)
B(-7,10,12,Leaves:4)
B(-7,11,12,Leaves:4)
B(7,6,5,Leaves:4)
B(7,7,5,Leaves:4)
B(6,10,-10,Leaves:4)
B(-11,11,5,Leaves:4)
B(-11,12,5,Leaves:4)
B(6,12,-10,Leaves:4)
B(-11,14,-5,Leaves:4)
B(-11,10,5,Leaves:4)
B(6,11,-10,Leaves:4)
B(5,7,-2,Leaves:4)
B(-5,10,0,Leaves:4)
B(4,12,-12,Leaves:4)
B(4,14,-12,Leaves:4)
B(4,13,-12,Leaves:4)
B(-1,9,-4,Leaves:4)
B(-1,8,-4,Leaves:4)
B(-5,14,2,Leaves:4)
B(-5,15,2,Leaves:4)
B(-5,16,2,Leaves:4)
B(9,7,-11,Leaves:4)
B(-5,9,-9,Leaves:4)
B(-5,5,-9,Leaves:4)
B(-5,6,-9,Leaves:4)
B(3,9,-12,Leaves:4)
B(-5,12,2,Leaves:4)
B(-5,11,2,Leaves:4)
B(7,12,-9,Leaves:4)
B(-9,6,-11,Leaves:4)
B(-9,5,-11,Leaves:4)
B(7,10,-9,Leaves:4)
B(7,11,-9,Leaves:4)
B(-9,9,-11,Leaves:4)
B(-9,8,-11,Leaves:4)
B(-9,7,-11,Leaves:4)
B(-5,-3,0,LOG:12)
B(-5,-4,0,LOG:12)
B(-5,-1,0,LOG:12)
B(-14,10,-3,Leaves:4)
B(-14,12,-3,Leaves:4)
B(-14,11,-3,Leaves:4)
B(2,8,-5,Leaves:4)
B(-12,10,7,Leaves:4)
B(2,9,-5,Leaves:4)
B(-5,-5,0,LOG:12)
B(4,10,5,Leaves:4)
B(-1,11,12,Leaves:4)
B(-1,10,12,Leaves:4)
B(4,11,5,Leaves:4)
B(-1,13,12,Leaves:4)
B(-1,12,12,Leaves:4)
B(6,9,-4,Leaves:4)
B(-6,10,-10,Leaves:4)
B(-7,7,-2,Leaves:4)
B(-6,11,-10,Leaves:4)
B(6,8,-4,Leaves:4)
B(-6,14,-10,Leaves:4)
B(-6,12,-10,Leaves:4)
B(-6,13,-10,Leaves:4)
B(-7,9,-2,LOG:12)
B(8,8,0,Leaves:4)
B(9,9,3,Leaves:4)
B(9,8,3,Leaves:4)
B(8,9,0,Leaves:4)
B(-16,7,0,Leaves:4)
B(-16,9,0,Leaves:4)
B(-16,8,0,Leaves:4)
B(4,12,5,Leaves:4)
B(4,15,5,Leaves:4)
B(8,6,0,Leaves:4)
B(4,14,5,Leaves:4)
B(8,7,0,Leaves:4)
B(5,8,5,Leaves:4)
B(-16,7,1,Leaves:4)
B(-16,8,1,Leaves:4)
B(5,9,5,LOG:12)
B(2,8,-11,Leaves:4)
B(5,6,5,Leaves:4)
B(5,7,5,Leaves:4)
B(2,7,-11,Leaves:4)
B(-1,-4,-2,LOG:12)
B(-9,10,-9,Leaves:4)
B(-16,9,1,Leaves:4)
B(5,11,-8,Leaves:4)
B(-10,9,-2,Leaves:4)
B(5,12,-8,Leaves:4)
B(-10,8,-2,Leaves:4)
B(-10,7,-2,Leaves:4)
B(5,10,-8,Leaves:4)
B(-1,-5,2,LOG:12)
B(5,13,-8,Leaves:4)
B(-1,-4,2,LOG:12)
B(1,13,6,Leaves:4)
B(1,12,6,Leaves:4)
B(1,11,6,Leaves:4)
B(1,10,6,Leaves:4)
B(1,16,6,Leaves:4)
B(-10,6,-2,Leaves:4)
B(1,15,6,Leaves:4)
B(13,9,0,Leaves:4)
B(-6,-5,1,LOG:12)
B(0,-4,-3,LOG:12)
B(3,8,-7,Leaves:4)
B(-6,14,3,Leaves:4)
B(-6,13,3,Leaves:4)
B(-6,12,3,Leaves:4)
B(-6,11,3,Leaves:4)
B(-6,10,3,Leaves:4)
B(5,13,-10,Leaves:4)
B(5,12,-10,Leaves:4)
B(5,11,-10,Leaves:4)
B(5,10,-10,Leaves:4)
B(-9,14,-9,Leaves:4)
B(-9,16,-9,Leaves:4)
B(-9,15,-9,Leaves:4)
B(2,9,-11,Leaves:4)
B(5,13,3,Leaves:4)
B(5,14,3,Leaves:4)
B(-12,14,-5,Leaves:4)
B(5,11,3,Leaves:4)
B(-12,13,-5,Leaves:4)
B(5,12,3,Leaves:4)
B(-12,9,1,Leaves:4)
B(-12,12,-5,Leaves:4)
B(-12,10,-5,Leaves:4)
B(-2,13,-8,Leaves:4)
B(-2,14,-8,Leaves:4)
B(-2,15,-8,Leaves:4)
B(-2,16,-8,Leaves:4)
B(-2,10,-8,Leaves:4)
B(-2,12,-8,LOG:12)
B(5,10,3,Leaves:4)
B(-7,7,-10,Leaves:4)
B(-7,8,-10,Leaves:4)
B(-7,9,-10,Leaves:4)
B(-10,10,10,Leaves:4)
B(-2,9,-5,LOG:12)
B(-2,6,-5,LOG:12)
B(-2,8,-5,Leaves:4)
B(-2,7,-5,LOG:12)
B(-12,4,1,Leaves:4)
B(-10,6,7,Leaves:4)
B(-10,5,7,Leaves:4)
B(-10,8,7,Leaves:4)
B(-10,7,7,Leaves:4)
B(-12,7,1,Leaves:4)
B(-10,9,7,Leaves:4)
B(-12,5,1,Leaves:4)
B(-1,10,-2,Leaves:4)
B(-9,5,4,Leaves:4)
B(-6,17,-3,Leaves:4)
B(-7,12,-12,Leaves:4)
B(-6,16,-3,Leaves:4)
B(-7,13,-12,Leaves:4)
B(-1,16,2,Leaves:4)
B(-1,15,2,Leaves:4)
B(-1,14,-2,Leaves:4)
B(7,7,-9,Leaves:4)
B(-6,11,-3,Leaves:4)
B(7,8,-9,Leaves:4)
B(-1,12,2,Leaves:4)
B(-1,11,2,LOG:12)
B(-1,17,-2,Leaves:4)
B(-6,15,-3,Leaves:4)
B(-1,10,2,LOG:12)
B(-1,16,-2,Leaves:4)
B(-6,14,-3,Leaves:4)
B(-6,11,1,Leaves:4)
B(-17,7,-1,Leaves:4)
B(-6,12,1,Leaves:4)
B(-6,10,1,Leaves:4)
B(-9,13,-6,Leaves:4)
B(-9,12,-6,Leaves:4)
B(-9,15,-6,Leaves:4)
B(4,8,10,Leaves:4)
B(-9,10,-6,LOG:12)
B(-6,16,1,Leaves:4)
B(-6,15,1,Leaves:4)
B(-14,9,-4,Leaves:4)
B(-14,8,-4,Leaves:4)
B(-8,6,-5,Leaves:4)
B(-2,7,3,Leaves:4)
B(-8,9,-5,Leaves:4)
B(-8,8,-5,Leaves:4)
B(-9,6,-3,Leaves:4)
B(-9,9,-3,Leaves:4)
B(-2,9,3,LOG:12)
B(-9,8,-3,Leaves:4)
B(10,10,-2,Leaves:4)
B(-11,9,-1,Leaves:4)
B(5,15,-1,Leaves:4)
B(-11,6,-1,Leaves:4)
B(1,6,8,Leaves:4)
B(5,14,-1,Leaves:4)
B(-11,5,-1,Leaves:4)
B(5,11,-1,Leaves:4)
B(5,13,-1,Leaves:4)
B(5,12,-1,Leaves:4)
B(1,9,8,Leaves:4)
B(-1,5,-11,Leaves:4)
B(-1,6,-11,Leaves:4)
B(7,6,-1,leaves:4)
B(-12,7,9,Leaves:4)
B(7,7,-1,leaves:4)
B(3,9,6,Leaves:4)
B(-12,8,9,Leaves:4)
B(7,8,-1,Leaves:4)
B(7,9,-1,Leaves:4)
B(3,8,6,Leaves:4)
B(-12,6,9,Leaves:4)
B(-4,17,-4,Leaves:4)
B(-4,16,-4,Leaves:4)
B(-12,9,9,Leaves:4)
B(-4,15,-4,Leaves:4)
B(-6,9,3,Leaves:4)
B(0,5,-14,Leaves:4)
B(0,6,-14,Leaves:4)
B(-7,10,-12,Leaves:4)
B(-8,14,-4,Leaves:4)
B(-8,13,-4,Leaves:4)
B(-8,10,-4,Leaves:4)
B(-4,6,11,Leaves:4)
B(-4,0,0,LOG:12)
B(-8,16,-4,Leaves:4)
B(-8,15,-4,Leaves:4)
B(10,7,-4,Leaves:4)
B(-4,7,11,Leaves:4)
B(-4,8,11,Leaves:4)
B(1,13,7,Leaves:4)
B(1,14,7,Leaves:4)
B(1,11,7,Leaves:4)
B(1,12,7,Leaves:4)
B(10,9,-4,Leaves:4)
B(-8,6,-12,Leaves:4)
B(-8,5,-12,Leaves:4)
B(-8,8,-12,Leaves:4)
B(-8,7,-12,Leaves:4)
B(-8,9,-12,Leaves:4)
B(2,16,-5,Leaves:4)
B(2,14,-5,Leaves:4)
B(2,13,-5,Leaves:4)
B(2,12,-5,Leaves:4)
B(2,11,-5,Leaves:4)
B(2,10,-5,Leaves:4)
B(9,11,-1,Leaves:4)
B(9,10,-1,Leaves:4)
B(-12,12,-2,Leaves:4)
B(-12,11,-2,Leaves:4)
B(-12,10,-2,Leaves:4)
B(2,17,-5,Leaves:4)
B(-11,10,-10,Leaves:4)
B(-12,14,-2,Leaves:4)
B(2,9,10,Leaves:4)
B(2,7,10,Leaves:4)
B(2,8,10,Leaves:4)
B(9,11,-3,Leaves:4)
B(9,10,-3,Leaves:4)
B(-6,6,-7,Leaves:4)
B(9,12,-3,Leaves:4)
B(-6,8,-7,Leaves:4)
B(-6,7,-7,Leaves:4)
B(-6,9,-7,Leaves:4)
B(4,15,3,Leaves:4)
B(-12,8,-3,Leaves:4)
B(4,14,3,Leaves:4)
B(-12,9,-3,Leaves:4)
B(4,13,3,Leaves:4)
B(4,12,3,Leaves:4)
B(4,11,3,Leaves:4)
B(4,10,3,Leaves:4)
B(-3,7,-13,Leaves:4)
B(-2,14,4,Leaves:4)
B(-3,8,-13,Leaves:4)
B(-3,9,-13,Leaves:4)
B(-2,12,4,Leaves:4)
B(-3,4,-13,Leaves:4)
B(-3,5,-13,Leaves:4)
B(-3,6,-13,Leaves:4)
B(-10,13,5,Leaves:4)
B(-10,12,5,Leaves:4)
B(-10,11,5,Leaves:4)
B(-10,10,5,Leaves:4)
B(0,16,-3,Leaves:4)
B(-7,12,8,Leaves:4)
B(0,15,-3,Leaves:4)
B(-7,11,8,Leaves:4)
B(0,14,-3,Leaves:4)
B(-7,10,8,Leaves:4)
B(0,13,-3,Leaves:4)
B(-14,8,6,Leaves:4)
B(0,12,-3,Leaves:4)
B(-14,9,6,Leaves:4)
B(0,11,-3,Leaves:4)
B(0,10,-3,Leaves:4)
B(-14,7,6,Leaves:4)
B(-7,14,8,Leaves:4)
B(-7,13,8,Leaves:4)
B(-13,10,-6,Leaves:4)
B(-7,7,-12,Leaves:4)
B(-7,6,-12,Leaves:4)
B(-11,14,1,Leaves:4)
B(-11,13,1,Leaves:4)
B(-7,9,-12,Leaves:4)
B(-11,15,1,Leaves:4)
B(-7,8,-12,Leaves:4)
B(-11,10,1,Leaves:4)
B(-8,12,-13,Leaves:4)
B(-8,11,-13,Leaves:4)
B(0,17,-3,Leaves:4)
B(0,18,-3,Leaves:4)
B(2,16,6,Leaves:4)
B(2,11,6,Leaves:4)
B(2,13,6,Leaves:4)
B(2,14,6,Leaves:4)
B(2,10,6,Leaves:4)
B(-12,5,-10,Leaves:4)
B(-2,9,-1,Leaves:4)
B(-12,6,-10,Leaves:4)
B(-12,8,-10,Leaves:4)
B(-10,10,8,Leaves:4)
B(-12,9,-10,Leaves:4)
B(4,8,-5,Leaves:4)
B(-2,4,-1,LOG:12)
B(-2,3,-1,LOG:12)
B(4,9,-5,Leaves:4)
B(-10,11,8,Leaves:4)
B(-10,14,8,Leaves:4)
B(-2,2,-1,LOG:12)
B(-10,13,8,Leaves:4)
B(-2,1,-1,LOG:12)
B(-2,0,-1,LOG:12)
B(-2,10,4,Leaves:4)
B(-2,11,4,Leaves:4)
B(0,10,8,Leaves:4)
B(0,13,8,Leaves:4)
B(0,14,8,Leaves:4)
B(-11,8,9,Leaves:4)
B(0,12,8,Leaves:4)
B(-11,9,9,Leaves:4)
B(-1,8,8,Leaves:4)
B(6,9,-6,Leaves:4)
B(-1,9,8,Leaves:4)
B(6,8,-6,Leaves:4)
B(-1,7,8,Leaves:4)
B(-7,-5,-5,LOG:12)
B(6,5,-6,Leaves:4)
B(-9,4,10,Leaves:4)
B(-5,16,1,Leaves:4)
B(-5,14,1,Leaves:4)
B(-11,11,6,Leaves:4)
B(-11,10,6,Leaves:4)
B(-11,13,6,Leaves:4)
B(-5,12,1,Leaves:4)
B(-5,13,1,LOG:12)
B(-11,12,6,Leaves:4)
B(-9,9,10,Leaves:4)
B(-9,7,10,Leaves:4)
B(-9,8,10,Leaves:4)
B(-9,5,10,Leaves:4)
B(0,15,6,Leaves:4)
B(3,12,2,Leaves:4)
B(-6,14,5,Leaves:4)
B(3,14,2,Leaves:4)
B(3,15,2,Leaves:4)
B(0,14,6,Leaves:4)
B(-6,13,5,Leaves:4)
B(-15,11,2,Leaves:4)
B(-6,12,5,Leaves:4)
B(0,11,6,Leaves:4)
B(0,12,6,Leaves:4)
B(-6,11,5,Leaves:4)
B(3,10,2,Leaves:4)
B(-6,10,5,Leaves:4)
B(0,10,6,Leaves:4)
B(3,11,2,Leaves:4)
B(-1,12,5,Leaves:4)
B(-1,13,5,Leaves:4)
B(-1,14,5,Leaves:4)
B(10,9,1,Leaves:4)
B(-1,15,5,Leaves:4)
B(-1,16,5,Leaves:4)
B(-11,9,1,Leaves:4)
B(-11,5,1,Leaves:4)
B(-14,8,4,Leaves:4)
B(-8,10,3,Leaves:4)
B(0,9,3,LOG:12)
B(-8,12,3,Leaves:4)
B(-15,7,9,Leaves:4)
B(-8,13,3,Leaves:4)
B(-8,14,3,Leaves:4)
B(0,8,3,Leaves:4)
B(-8,15,3,Leaves:4)
B(-14,7,4,Leaves:4)
B(-8,16,3,Leaves:4)
B(-1,8,11,Leaves:4)
B(-10,5,10,Leaves:4)
B(-1,9,11,Leaves:4)
B(-10,7,10,Leaves:4)
B(-10,8,10,Leaves:4)
B(-10,9,10,Leaves:4)
B(-1,7,11,Leaves:4)
B(9,9,4,Leaves:4)
B(-2,13,6,Leaves:4)
B(-2,12,6,Leaves:4)
B(-2,11,6,Leaves:4)
B(-2,10,6,Leaves:4)
B(-14,10,2,Leaves:4)
B(-12,10,8,Leaves:4)
B(-12,11,8,Leaves:4)
B(-7,9,5,Leaves:4)
B(6,9,-5,Leaves:4)
B(6,13,4,Leaves:4)
B(-7,-5,1,LOG:12)
B(4,8,5,Leaves:4)
B(-8,6,-11,Leaves:4)
B(4,7,5,Leaves:4)
B(-8,7,-11,Leaves:4)
B(-8,5,-11,Leaves:4)
B(4,9,5,Leaves:4)
B(-12,10,-11,Leaves:4)
B(-2,11,-15,Leaves:4)
B(-8,8,-11,Leaves:4)
B(4,6,5,Leaves:4)
B(-8,9,-11,Leaves:4)
B(4,5,5,Leaves:4)
B(-7,8,5,Leaves:4)
B(-7,6,5,Leaves:4)
B(-8,9,8,Leaves:4)
B(-8,7,8,Leaves:4)
B(-8,8,8,Leaves:4)
B(8,8,-3,Leaves:4)
B(-8,6,8,Leaves:4)
B(8,9,-3,Leaves:4)
B(-3,6,9,Leaves:4)
B(6,10,4,Leaves:4)
B(6,11,4,Leaves:4)
B(6,12,-2,Leaves:4)
B(6,13,-2,Leaves:4)
B(6,11,-2,Leaves:4)
B(-14,7,10,Leaves:4)
B(6,14,-2,Leaves:4)
B(8,10,-1,Leaves:4)
B(8,12,-1,Leaves:4)
B(8,11,-1,Leaves:4)
B(8,14,-1,Leaves:4)
B(8,13,-1,Leaves:4)
B(-4,8,-5,Leaves:4)
B(-4,9,-5,LOG:12)
B(-4,6,-5,LOG:12)
B(-1,-5,0,LOG:12)
B(-1,-4,0,LOG:12)
B(-1,-3,0,LOG:12)
B(12,8,3,Leaves:4)
B(12,9,3,Leaves:4)
B(9,10,-8,Leaves:4)
B(-6,8,-12,Leaves:4)
B(-5,7,-14,Leaves:4)
B(5,9,-3,Leaves:4)
B(-6,9,-12,Leaves:4)
B(-3,14,0,Leaves:4)
B(-3,13,0,LOG:12)
B(-3,16,0,Leaves:4)
B(-3,15,0,Leaves:4)
B(-3,12,0,Leaves:4)
B(-3,11,0,Leaves:4)
B(-3,17,0,Leaves:4)
B(-5,11,8,Leaves:4)
B(-5,12,8,Leaves:4)
B(-5,13,8,Leaves:4)
B(-5,14,8,Leaves:4)
B(1,-5,0,LOG:12)
B(3,10,3,Leaves:4)
B(3,12,3,Leaves:4)
B(-5,10,8,Leaves:4)
B(3,11,3,Leaves:4)
B(3,14,3,Leaves:4)
B(2,8,1,Leaves:4)
B(3,13,3,Leaves:4)
B(2,7,1,Leaves:4)
B(2,6,1,Leaves:4)
B(3,15,3,Leaves:4)
B(8,8,7,Leaves:4)
B(-9,13,-12,Leaves:4)
B(1,7,6,Leaves:4)
B(1,8,6,Leaves:4)
B(1,9,6,Leaves:4)
B(-10,10,-7,Leaves:4)
B(-10,12,-7,Leaves:4)
B(-10,11,-7,Leaves:4)
B(-10,14,-7,Leaves:4)
B(-10,13,-7,Leaves:4)
B(-13,7,-6,Leaves:4)
B(-13,8,-6,Leaves:4)
B(-13,9,-6,Leaves:4)
B(-9,6,-10,Leaves:4)
B(-9,7,-10,Leaves:4)
B(-9,5,-10,Leaves:4)
B(-11,13,-4,Leaves:4)
B(-8,10,11,Leaves:4)
B(-11,14,-4,Leaves:4)
B(-8,11,11,Leaves:4)
B(-13,9,2,Leaves:4)
B(-11,11,-4,Leaves:4)
B(-11,12,-4,Leaves:4)
B(-13,7,2,Leaves:4)
B(-13,8,2,Leaves:4)
B(-11,10,-4,Leaves:4)
B(-9,8,-10,Leaves:4)
B(-9,9,-10,Leaves:4)
B(6,5,2,Leaves:4)
B(-11,4,-12,Leaves:4)
B(6,7,2,Leaves:4)
B(6,6,2,Leaves:4)
B(-12,14,9,Leaves:4)
B(-11,8,-12,Leaves:4)
B(-2,6,5,Leaves:4)
B(6,9,2,Leaves:4)
B(6,8,2,Leaves:4)
B(-11,7,-12,Leaves:4)
B(-2,8,5,Leaves:4)
B(-11,6,-12,Leaves:4)
B(-11,5,-12,Leaves:4)
B(-2,9,5,Leaves:4)
B(12,8,-1,Leaves:4)
B(-3,-5,0,LOG:12)
B(-3,-3,0,LOG:12)
B(-3,-4,0,LOG:12)
B(-3,-1,0,LOG:12)
B(-3,-2,0,LOG:12)
B(-5,9,2,Leaves:4)
B(2,13,4,Leaves:4)
B(-9,10,-10,Leaves:4)
B(2,14,4,Leaves:4)
B(1,16,0,Leaves:4)
B(2,15,4,Leaves:4)
B(1,14,0,Leaves:4)
B(1,15,0,Leaves:4)
B(9,7,-4,Leaves:4)
B(2,10,4,Leaves:4)
B(9,8,-4,Leaves:4)
B(2,11,4,Leaves:4)
B(1,12,0,Leaves:4)
B(1,13,0,Leaves:4)
B(2,12,4,Leaves:4)
B(9,9,-4,Leaves:4)
B(2,12,-7,Leaves:4)
B(2,11,-7,Leaves:4)
B(-2,15,6,Leaves:4)
B(2,14,-7,Leaves:4)
B(-2,14,6,Leaves:4)
B(2,13,-7,Leaves:4)
B(2,16,-7,Leaves:4)
B(2,15,-7,Leaves:4)
B(-1,9,-5,Leaves:4)
B(-5,7,-8,Leaves:4)
B(-5,8,-8,LOG:12)
B(-5,9,-8,Leaves:4)
B(10,12,3,Leaves:4)
B(7,12,-7,Leaves:4)
B(7,13,-7,Leaves:4)
B(10,11,3,Leaves:4)
B(7,10,-7,Leaves:4)
B(10,10,3,Leaves:4)
B(7,11,-7,Leaves:4)
B(-16,8,-2,Leaves:4)
B(-16,7,-2,Leaves:4)
B(-6,-5,3,LOG:12)
B(-7,15,-8,Leaves:4)
B(0,9,-8,LOG:12)
B(-7,13,-8,LOG:12)
B(-5,-5,1,LOG:12)
B(0,11,-11,Leaves:4)
B(-5,-4,1,LOG:12)
B(0,10,-11,Leaves:4)
B(-7,12,-8,Leaves:4)
B(0,13,-11,Leaves:4)
B(0,12,-11,Leaves:4)
B(0,8,-8,LOG:12)
B(6,11,3,Leaves:4)
B(2,8,-6,Leaves:4)
B(6,10,3,Leaves:4)
B(-12,5,0,Leaves:4)
B(-7,11,-8,Leaves:4)
B(-12,6,0,Leaves:4)
B(-5,10,1,Leaves:4)
B(-12,7,0,Leaves:4)
B(-5,11,1,Leaves:4)
B(-12,8,0,Leaves:4)
B(-12,9,0,Leaves:4)
B(6,10,-4,Leaves:4)
B(6,11,-4,Leaves:4)
B(6,13,-4,Leaves:4)
B(7,8,6,Leaves:4)
B(-16,11,-4,Leaves:4)
B(6,12,-4,Leaves:4)
B(6,15,-4,Leaves:4)
B(6,14,-4,Leaves:4)
B(7,9,6,Leaves:4)
B(6,14,3,Leaves:4)
B(6,12,3,Leaves:4)
B(6,13,3,Leaves:4)
B(2,9,-6,Leaves:4)
B(-7,7,-1,Leaves:4)
B(-9,10,-12,Leaves:4)
B(-7,6,-1,Leaves:4)
B(-1,10,11,Leaves:4)
B(-1,11,11,Leaves:4)
B(-1,12,11,Leaves:4)
B(-1,13,11,Leaves:4)
B(-1,14,11,Leaves:4)
B(-9,11,-10,Leaves:4)
B(-9,12,-10,Leaves:4)
B(-9,13,-10,Leaves:4)
B(-9,15,-10,Leaves:4)
B(1,10,8,Leaves:4)
B(-9,9,5,Leaves:4)
B(-8,11,-12,Leaves:4)
B(-16,9,2,Leaves:4)
B(-8,10,-12,Leaves:4)
B(2,5,-12,Leaves:4)
B(2,7,-12,Leaves:4)
B(2,6,-12,Leaves:4)
B(4,11,10,Leaves:4)
B(1,13,8,Leaves:4)
B(1,12,8,Leaves:4)
B(1,15,8,Leaves:4)
B(1,14,8,Leaves:4)
B(-8,10,4,Leaves:4)
B(-8,11,4,Leaves:4)
B(-8,12,4,Leaves:4)
B(-8,13,4,Leaves:4)
B(-8,14,4,Leaves:4)
B(-12,10,-3,Leaves:4)
B(-1,14,8,Leaves:4)
B(-12,11,-3,Leaves:4)
B(-1,13,8,Leaves:4)
B(-12,12,-3,Leaves:4)
B(-1,12,8,Leaves:4)
B(-14,8,-5,Leaves:4)
B(-14,9,-5,Leaves:4)
B(-1,11,8,Leaves:4)
B(-1,10,8,Leaves:4)
B(-8,9,-6,LOG:12)
B(-8,8,-6,LOG:12)
B(-18,7,-2,Leaves:4)
B(2,8,-12,Leaves:4)
B(2,9,-12,Leaves:4)
B(-14,7,-5,Leaves:4)
B(-8,12,-12,Leaves:4)
B(-8,13,-12,Leaves:4)
B(-9,9,-4,Leaves:4)
B(-9,5,-4,Leaves:4)
B(-9,6,-4,Leaves:4)
B(-9,7,-4,Leaves:4)
B(-9,8,-4,Leaves:4)
B(-15,11,-2,Leaves:4)
B(-15,12,-2,Leaves:4)
B(-15,10,-2,Leaves:4)
B(3,13,7,Leaves:4)
B(3,14,7,Leaves:4)
B(3,15,7,Leaves:4)
B(0,13,-9,Leaves:4)
B(0,14,-9,Leaves:4)
B(0,10,-9,Leaves:4)
B(7,12,-1,Leaves:4)
B(7,13,-1,Leaves:4)
B(7,14,-1,Leaves:4)
B(7,15,-1,Leaves:4)
B(3,10,7,Leaves:4)
B(3,12,7,Leaves:4)
B(7,10,-1,Leaves:4)
B(7,11,-1,Leaves:4)
B(3,11,7,Leaves:4)
B(3,8,5,Leaves:4)
B(-3,12,-14,Leaves:4)
B(-3,11,-14,Leaves:4)
B(2,17,-4,Leaves:4)
B(2,16,-4,Leaves:4)
B(11,9,3,Leaves:4)
B(2,11,-4,Leaves:4)
B(2,12,-4,Leaves:4)
B(-1,9,-6,Leaves:4)
B(-1,13,-9,Leaves:4)
B(-1,14,-9,Leaves:4)
B(-1,15,-9,Leaves:4)
B(7,6,-8,Leaves:4)
B(7,7,-8,Leaves:4)
B(-5,12,-7,Leaves:4)
B(5,9,6,Leaves:4)
B(5,8,6,Leaves:4)
B(5,7,6,Leaves:4)
B(10,8,-3,Leaves:4)
B(7,8,-8,Leaves:4)
B(10,7,-3,Leaves:4)
B(7,9,-8,Leaves:4)
B(4,10,-6,Leaves:4)
B(4,11,-6,Leaves:4)
B(-10,8,-3,Leaves:4)
B(11,10,2,Leaves:4)
B(4,12,-6,Leaves:4)
B(4,13,-6,Leaves:4)
B(-10,9,-3,Leaves:4)
B(4,14,-6,Leaves:4)
B(4,15,-6,Leaves:4)
B(-10,7,-3,Leaves:4)
B(11,11,2,Leaves:4)
B(-4,17,-2,Leaves:4)
B(-7,11,3,Leaves:4)
B(-4,18,-2,Leaves:4)
B(-7,14,3,Leaves:4)
B(-7,13,3,Leaves:4)
B(-7,12,3,Leaves:4)
B(-4,10,-2,Leaves:4)
B(-4,11,-2,Leaves:4)
B(-4,14,-2,LOG:12)
B(-4,15,-2,Leaves:4)
B(-4,16,-2,Leaves:4)
B(-3,9,-2,Leaves:4)
B(-3,1,-2,LOG:12)
B(-3,2,-2,LOG:12)
B(-3,3,-2,LOG:12)
B(-3,4,-2,LOG:12)
B(2,16,5,Leaves:4)
B(2,15,5,Leaves:4)
B(2,14,5,Leaves:4)
B(2,13,5,Leaves:4)
B(2,12,5,Leaves:4)
B(-2,9,4,Leaves:4)
B(-2,8,4,Leaves:4)
B(-3,0,-2,LOG:12)
B(2,11,5,Leaves:4)
B(2,10,5,Leaves:4)
B(-5,17,-7,Leaves:4)
B(-5,14,-7,Leaves:4)
B(3,9,-8,Leaves:4)
B(5,10,-9,Leaves:4)
B(-5,13,-7,Leaves:4)
B(3,8,-8,Leaves:4)
B(5,11,-9,Leaves:4)
B(-5,16,-7,Leaves:4)
B(5,12,-9,Leaves:4)
B(-5,15,-7,Leaves:4)
B(5,13,-9,Leaves:4)
B(-10,5,6,Leaves:4)
B(-7,17,-2,Leaves:4)
B(-7,16,-2,Leaves:4)
B(-7,15,-2,Leaves:4)
B(1,12,12,Leaves:4)
B(-7,14,-2,Leaves:4)
B(1,11,12,Leaves:4)
B(-7,13,-2,Leaves:4)
B(-7,12,-2,Leaves:4)
B(-7,11,-2,Leaves:4)
B(-7,10,-2,Leaves:4)
B(-1,5,-12,Leaves:4)
B(-1,7,-12,Leaves:4)
B(-1,6,-12,Leaves:4)
B(-1,8,-12,Leaves:4)
B(-6,6,-6,Leaves:4)
B(-10,6,6,Leaves:4)
B(-10,7,6,Leaves:4)
B(-6,7,-6,Leaves:4)
B(-10,8,6,Leaves:4)
B(-9,5,5,Leaves:4)
B(-6,8,-6,Leaves:4)
B(-6,9,-6,Leaves:4)
B(-4,-2,-2,LOG:12)
B(-4,-1,-2,LOG:12)
B(-17,7,-2,Leaves:4)
B(-4,-5,-2,LOG:12)
B(-4,-4,-2,LOG:12)
B(-4,-3,-2,LOG:12)
B(-4,6,8,Leaves:4)
B(-7,6,-13,Leaves:4)
B(-4,7,8,Leaves:4)
B(-7,9,-13,Leaves:4)
B(-7,7,-13,Leaves:4)
B(7,12,6,Leaves:4)
B(7,13,6,Leaves:4)
B(11,13,-5,Leaves:4)
B(7,10,6,Leaves:4)
B(7,11,6,Leaves:4)
B(-4,9,8,Leaves:4)
B(-2,-5,-7,LOG:12)
B(-12,8,-2,Leaves:4)
B(4,8,-6,Leaves:4)
B(4,7,-6,Leaves:4)
B(-15,7,-11,Leaves:4)
B(4,9,-6,Leaves:4)
B(4,6,-6,Leaves:4)
B(5,11,-7,Leaves:4)
B(5,10,-7,Leaves:4)
B(5,13,-7,Leaves:4)
B(5,12,-7,Leaves:4)
B(-7,16,3,Leaves:4)
B(5,14,-7,Leaves:4)
B(-12,9,-2,Leaves:4)
B(-7,14,9,Leaves:4)
B(-7,15,9,Leaves:4)
B(-1,10,5,Leaves:4)
B(-1,11,5,Leaves:4)
B(-3,4,-14,Leaves:4)
B(-7,12,9,Leaves:4)
B(-3,6,-14,Leaves:4)
B(-7,13,9,Leaves:4)
B(-3,7,-14,Leaves:4)
B(-3,8,-14,Leaves:4)
B(-7,10,9,Leaves:4)
B(-7,11,9,Leaves:4)
B(-4,9,12,Leaves:4)
B(-3,15,9,Leaves:4)
B(-3,14,9,Leaves:4)
B(-7,17,-5,Leaves:4)
B(-3,11,9,Leaves:4)
B(-3,10,9,Leaves:4)
B(-3,13,9,Leaves:4)
B(-3,12,9,Leaves:4)
B(-14,9,5,Leaves:4)
B(-7,12,-5,Leaves:4)
B(-14,7,5,Leaves:4)
B(-14,8,5,Leaves:4)
B(-7,16,-5,Leaves:4)
B(-7,15,-5,Leaves:4)
B(-14,6,5,Leaves:4)
B(-7,14,-5,Leaves:4)
B(-7,13,-5,Leaves:4)
B(-4,15,6,Leaves:4)
B(-4,14,6,Leaves:4)
B(-4,13,6,Leaves:4)
B(-4,12,6,Leaves:4)
B(-4,11,6,Leaves:4)
B(-4,10,6,Leaves:4)
B(-4,15,-9,Leaves:4)
B(-4,14,-9,Leaves:4)
B(-4,13,-9,Leaves:4)
B(-4,12,-9,Leaves:4)
B(-4,11,-9,Leaves:4)
B(-4,10,-9,Leaves:4)
B(-2,14,11,Leaves:4)
B(-2,17,-7,Leaves:4)
B(-2,16,-7,Leaves:4)
B(-2,11,11,Leaves:4)
B(-2,10,11,Leaves:4)
B(-2,12,11,Leaves:4)
B(-12,9,-11,Leaves:4)
B(-2,10,-7,Leaves:4)
B(-2,11,-7,Leaves:4)
B(-12,10,10,Leaves:4)
B(-2,14,-7,Leaves:4)
B(-12,5,-11,Leaves:4)
B(3,10,-3,Leaves:4)
B(-2,15,-7,Leaves:4)
B(-14,4,-14,Leaves:4)
B(-12,6,-11,Leaves:4)
B(3,11,-3,Leaves:4)
B(-12,7,-11,Leaves:4)
B(-2,12,-7,LOG:12)
B(3,12,-3,Leaves:4)
B(3,13,-3,Leaves:4)
B(-12,8,-11,Leaves:4)
B(1,10,9,Leaves:4)
B(-12,4,-11,Leaves:4)
B(1,11,9,Leaves:4)
B(1,13,9,Leaves:4)
B(-7,8,-11,Leaves:4)
B(-2,4,-4,LOG:12)
B(1,14,9,Leaves:4)
B(-2,5,-4,LOG:12)
B(-7,7,-11,Leaves:4)
B(-7,6,-11,Leaves:4)
B(3,15,-3,Leaves:4)
B(-2,8,-4,Leaves:4)
B(3,14,-3,Leaves:4)
B(-2,9,-4,Leaves:4)
B(3,17,-3,Leaves:4)
B(-2,6,-4,LOG:12)
B(3,16,-3,Leaves:4)
B(-7,9,-11,Leaves:4)
B(9,9,-7,Leaves:4)
B(9,7,-7,Leaves:4)
B(-9,11,-2,Leaves:4)
B(9,8,-7,Leaves:4)
B(-9,10,-2,Leaves:4)
B(-9,13,-2,Leaves:4)
B(2,5,2,LOG:12)
B(-9,12,-2,Leaves:4)
B(-9,15,-2,Leaves:4)
B(2,6,2,LOG:12)
B(-9,14,-2,Leaves:4)
B(2,7,2,Leaves:4)
B(2,8,2,Leaves:4)
B(-9,16,-2,Leaves:4)
B(2,9,2,LOG:12)
B(-8,9,-10,Leaves:4)
B(-8,7,-10,Leaves:4)
B(-8,8,-10,Leaves:4)
B(-8,6,-10,Leaves:4)
B(0,16,2,Leaves:4)
B(0,15,2,Leaves:4)
B(0,14,2,Leaves:4)
B(0,13,2,Leaves:4)
B(0,12,2,Leaves:4)
B(-13,6,-9,Leaves:4)
B(0,11,2,Leaves:4)
B(0,10,2,LOG:12)
B(3,-5,0,LOG:12)
B(-13,7,-9,Leaves:4)
B(-12,9,-9,Leaves:4)
B(-12,8,-9,Leaves:4)
B(-12,7,-9,Leaves:4)
B(-12,6,-1,Leaves:4)
B(-12,8,-1,Leaves:4)
B(1,9,-5,Leaves:4)
B(-12,9,-1,Leaves:4)
B(-4,10,-10,Leaves:4)
B(-4,11,-10,Leaves:4)
B(-4,12,-10,Leaves:4)
B(-4,13,-10,Leaves:4)
B(-15,7,8,Leaves:4)
B(-4,14,-10,Leaves:4)
B(-4,15,-10,Leaves:4)
B(-4,16,-10,Leaves:4)
B(-13,7,-1,Leaves:4)
B(-13,8,-1,Leaves:4)
B(-13,9,-1,Leaves:4)
B(-8,10,9,Leaves:4)
B(-8,11,9,Leaves:4)
B(-8,14,9,Leaves:4)
B(-8,16,1,Leaves:4)
B(-8,15,1,Leaves:4)
B(1,8,-5,Leaves:4)
B(-8,10,1,Leaves:4)
B(-8,12,1,Leaves:4)
B(-8,13,1,Leaves:4)
B(-8,14,1,Leaves:4)
B(-6,13,6,Leaves:4)
B(3,10,-2,Leaves:4)
B(-6,12,6,Leaves:4)
B(3,12,-2,Leaves:4)
B(-6,10,6,Leaves:4)
B(3,11,-2,Leaves:4)
B(3,17,-2,Leaves:4)
B(-6,8,-13,Leaves:4)
B(-6,9,-13,Leaves:4)
B(3,13,-2,Leaves:4)
B(3,14,-2,Leaves:4)
B(3,15,-2,Leaves:4)
B(3,16,-2,Leaves:4)
B(-7,11,-11,Leaves:4)
B(-7,12,-11,Leaves:4)
B(-7,13,-11,Leaves:4)
B(-7,14,-11,Leaves:4)
B(8,5,-4,Leaves:4)
B(4,8,-2,Leaves:4)
B(8,8,-4,Leaves:4)
B(4,7,-2,Leaves:4)
B(-1,6,7,Leaves:4)
B(-1,9,7,Leaves:4)
B(7,11,7,Leaves:4)
B(7,12,7,Leaves:4)
B(7,10,7,Leaves:4)
B(8,9,-4,Leaves:4)
B(7,13,7,Leaves:4)
B(3,14,0,Leaves:4)
B(3,15,0,Leaves:4)
B(0,-5,2,LOG:12)
B(0,-4,2,LOG:12)
B(3,12,0,Leaves:4)
B(3,13,0,Leaves:4)
B(3,11,0,Leaves:4)
B(-13,8,5,Leaves:4)
B(-9,5,-13,Leaves:4)
B(-9,6,-13,Leaves:4)
B(-13,9,5,Leaves:4)
B(-9,7,-13,Leaves:4)
B(-9,8,-13,Leaves:4)
B(-9,9,-13,Leaves:4)
B(-3,12,-12,Leaves:4)
B(-13,6,5,Leaves:4)
B(-13,7,5,Leaves:4)
B(-3,15,-12,Leaves:4)
B(0,13,-8,Leaves:4)
B(-3,18,-2,Leaves:4)
B(0,12,-8,Leaves:4)
B(0,17,-8,Leaves:4)
B(-3,15,-2,Leaves:4)
B(-3,10,-9,Leaves:4)
B(0,16,-8,Leaves:4)
B(0,15,-8,Leaves:4)
B(-3,12,-9,Leaves:4)
B(-3,16,-2,Leaves:4)
B(0,14,-8,Leaves:4)
B(-3,11,-9,Leaves:4)
B(-3,14,-9,Leaves:4)
B(-3,11,-2,Leaves:4)
B(-3,13,-9,Leaves:4)
B(-3,10,-2,Leaves:4)
B(-3,12,-2,Leaves:4)
B(5,15,-6,Leaves:4)
B(-14,10,4,Leaves:4)
B(-3,6,10,Leaves:4)
B(-3,9,10,Leaves:4)
B(-3,8,10,Leaves:4)
B(-5,9,5,Leaves:4)
B(-5,8,5,Leaves:4)
B(5,11,-6,Leaves:4)
B(5,12,-6,Leaves:4)
B(5,13,-6,Leaves:4)
B(-4,9,3,LOG:12)
B(5,14,-6,Leaves:4)
B(3,-5,-2,LOG:12)
B(5,10,-6,Leaves:4)
B(-3,4,-5,LOG:12)
B(-3,5,-5,LOG:12)
B(-3,8,-5,LOG:12)
B(4,7,8,Leaves:4)
B(3,6,3,Leaves:4)
B(3,7,3,Leaves:4)
B(-3,9,-5,LOG:12)
B(3,8,3,Leaves:4)
B(-3,6,-5,LOG:12)
B(-3,7,-5,LOG:12)
B(3,9,3,Leaves:4)
B(4,9,8,Leaves:4)
B(4,8,8,Leaves:4)
B(2,15,-9,Leaves:4)
B(2,14,-9,Leaves:4)
B(-3,6,6,Leaves:4)
B(2,13,-9,Leaves:4)
B(-3,8,6,Leaves:4)
B(-16,6,11,Leaves:4)
B(-3,9,6,Leaves:4)
B(4,9,-13,Leaves:4)
B(-2,-4,2,LOG:12)
B(-17,11,-1,Leaves:4)
B(2,12,-9,Leaves:4)
B(2,11,-9,Leaves:4)
B(0,7,-9,Leaves:4)
B(0,8,-9,Leaves:4)
B(0,9,-9,Leaves:4)
B(-2,12,-2,Leaves:4)
B(-2,13,-2,Leaves:4)
B(-2,16,-2,Leaves:4)
B(-2,15,-2,Leaves:4)
B(-2,17,-2,Leaves:4)
B(-11,12,-1,Leaves:4)
B(-11,13,-1,Leaves:4)
B(-2,10,-2,Leaves:4)
B(-11,10,-1,Leaves:4)
B(-11,11,-1,Leaves:4)
B(-11,14,-1,Leaves:4)
B(-11,15,-1,Leaves:4)
B(0,3,-1,LOG:12)
B(-11,6,-13,Leaves:4)
B(-7,11,4,Leaves:4)
B(-7,12,4,Leaves:4)
B(-11,7,-13,Leaves:4)
B(-7,10,4,Leaves:4)
B(-7,16,4,Leaves:4)
B(-7,13,4,Leaves:4)
B(0,5,-1,LOG:12)
B(0,4,-1,LOG:12)
B(7,12,1,Leaves:4)
B(7,11,1,Leaves:4)
B(7,14,1,Leaves:4)
B(7,13,1,Leaves:4)
B(-6,-5,-5,LOG:12)
B(-10,12,3,Leaves:4)
B(-6,-4,-5,LOG:12)
B(-10,11,3,Leaves:4)
B(-10,10,3,Leaves:4)
B(3,8,10,Leaves:4)
B(-1,-5,-4,LOG:12)
B(-1,-4,-4,LOG:12)
B(4,15,-3,Leaves:4)
B(4,16,-3,Leaves:4)
B(3,7,10,Leaves:4)
B(3,6,10,Leaves:4)
B(4,12,-3,Leaves:4)
B(4,10,-3,Leaves:4)
B(-15,7,0,Leaves:4)
B(7,10,1,Leaves:4)
B(-9,11,-13,Leaves:4)
B(-4,15,-6,Leaves:4)
B(-4,17,-6,Leaves:4)
B(-9,7,-1,Leaves:4)
B(8,9,6,Leaves:4)
B(-1,3,-2,LOG:12)
B(-9,8,-1,Leaves:4)
B(-9,9,-1,Leaves:4)
B(3,10,-8,Leaves:4)
B(-2,12,2,Leaves:4)
B(3,11,-8,Leaves:4)
B(-2,13,2,Leaves:4)
B(3,12,-8,Leaves:4)
B(3,13,-8,Leaves:4)
B(-11,9,6,Leaves:4)
B(-2,10,2,Leaves:4)
B(3,14,-8,Leaves:4)
B(-2,11,2,LOG:12)
B(-2,16,2,Leaves:4)
B(-4,14,10,Leaves:4)
B(-11,7,6,Leaves:4)
B(-1,9,-2,Leaves:4)
B(-4,13,10,Leaves:4)
B(-11,8,6,Leaves:4)
B(-4,12,10,Leaves:4)
B(-11,5,6,Leaves:4)
B(-2,15,2,Leaves:4)
B(-11,6,6,Leaves:4)
B(-4,11,10,Leaves:4)
B(-13,7,10,Leaves:4)
B(-14,6,11,Leaves:4)
B(-14,7,11,Leaves:4)
B(-15,6,12,Leaves:4)
B(-3,1,0,LOG:12)
B(-3,3,0,LOG:12)
B(-2,-5,-2,LOG:12)
B(-3,2,0,LOG:12)
B(-2,14,-1,Leaves:4)
B(-2,16,-9,Leaves:4)
B(-2,15,-1,Leaves:4)
B(-2,15,-9,Leaves:4)
B(-2,14,-9,Leaves:4)
B(-2,13,-9,Leaves:4)
B(-2,-1,-2,LOG:12)
B(-2,10,-1,Leaves:4)
B(-2,-2,-2,LOG:12)
B(-2,11,-1,Leaves:4)
B(-2,12,-9,Leaves:4)
B(-2,-3,-2,LOG:12)
B(-2,11,-9,Leaves:4)
B(-2,12,-1,Leaves:4)
B(-2,13,-1,Leaves:4)
B(-2,-4,-2,LOG:12)
B(-2,10,-9,Leaves:4)
B(5,8,-9,Leaves:4)
B(-13,10,-1,Leaves:4)
B(-13,11,-1,Leaves:4)
B(-13,12,-1,Leaves:4)
B(-13,13,-1,Leaves:4)
B(-13,14,-1,Leaves:4)
B(6,8,3,Leaves:4)
B(2,7,-3,Leaves:4)
B(6,7,3,Leaves:4)
B(2,6,-3,Leaves:4)
B(-2,8,6,Leaves:4)
B(6,9,3,Leaves:4)
B(-2,9,6,Leaves:4)
B(2,9,-3,Leaves:4)
B(-11,10,10,Leaves:4)
B(6,6,3,Leaves:4)
B(6,5,3,Leaves:4)
B(-6,14,-5,Leaves:4)
B(-6,15,-5,Leaves:4)
B(10,10,5,Leaves:4)
B(-6,16,-5,Leaves:4)
B(-6,17,-5,Leaves:4)
B(-6,10,-5,Leaves:4)
B(-6,11,-5,LOG:12)
B(-6,12,-5,Leaves:4)
B(-16,10,0,Leaves:4)
B(6,9,-2,Leaves:4)
B(-8,12,-2,Leaves:4)
B(-8,11,-2,Leaves:4)
B(-8,14,-2,Leaves:4)
B(-8,16,-2,Leaves:4)
B(-8,15,-2,Leaves:4)
B(-4,11,-6,LOG:12)
B(8,12,-8,Leaves:4)
B(8,11,-8,Leaves:4)
B(8,10,-8,Leaves:4)
B(-7,8,-5,Leaves:4)
B(-2,5,-15,Leaves:4)
B(4,11,-10,Leaves:4)
B(4,13,-10,Leaves:4)
B(10,7,-2,Leaves:4)
B(10,9,-2,Leaves:4)
B(10,8,-2,Leaves:4)
B(4,10,-10,Leaves:4)
B(-3,12,5,Leaves:4)
B(-3,13,5,Leaves:4)
B(-3,10,5,Leaves:4)
B(-13,11,5,Leaves:4)
B(-3,11,5,LOG:12)
B(-13,10,5,Leaves:4)
B(-4,16,2,Leaves:4)
B(-4,13,2,LOG:12)
B(-4,12,2,LOG:12)
B(-4,15,2,Leaves:4)
B(-4,14,2,Leaves:4)
B(-8,14,8,Leaves:4)
B(-11,13,7,Leaves:4)
B(-11,12,7,Leaves:4)
B(-11,11,7,Leaves:4)
B(-11,10,7,Leaves:4)
B(-7,11,14,Leaves:4)
B(-7,10,14,Leaves:4)
B(-8,11,8,Leaves:4)
B(-8,10,8,Leaves:4)
B(-8,13,8,Leaves:4)
B(-8,12,8,Leaves:4)
B(-9,10,1,Leaves:4)
B(-9,11,1,Leaves:4)
B(-9,14,1,Leaves:4)
B(-9,15,1,Leaves:4)
B(-9,12,1,Leaves:4)
B(-9,13,1,Leaves:4)
B(-12,7,3,Leaves:4)
B(-12,9,3,Leaves:4)
B(-10,6,5,Leaves:4)
B(-4,10,2,LOG:12)
B(-10,5,5,Leaves:4)
B(-4,11,2,Leaves:4)
B(-10,4,5,Leaves:4)
B(8,12,7,Leaves:4)
B(-16,10,-3,Leaves:4)
B(8,10,7,Leaves:4)
B(8,11,7,Leaves:4)
B(-2,-3,1,LOG:12)
B(1,11,-3,Leaves:4)
B(-2,-4,1,LOG:12)
B(1,10,-3,Leaves:4)
B(-2,-5,1,LOG:12)
B(1,15,-3,Leaves:4)
B(1,14,-3,Leaves:4)
B(-6,9,-5,Leaves:4)
B(1,12,-3,Leaves:4)
B(-10,7,5,Leaves:4)
B(-6,7,-5,Leaves:4)
B(-9,14,3,Leaves:4)
B(-6,8,-5,Leaves:4)
B(-10,9,5,Leaves:4)
B(-14,7,-11,Leaves:4)
B(5,13,6,Leaves:4)
B(-9,11,3,Leaves:4)
B(5,12,6,Leaves:4)
B(-14,5,-11,Leaves:4)
B(-9,10,3,Leaves:4)
B(-9,13,3,Leaves:4)
B(5,11,6,Leaves:4)
B(-9,12,3,Leaves:4)
B(5,10,6,Leaves:4)
B(-2,7,-7,LOG:12)
B(-2,8,-7,LOG:12)
B(7,5,3,Leaves:4)
B(7,9,3,Leaves:4)
B(7,8,3,Leaves:4)
B(1,16,-3,Leaves:4)
B(7,7,3,Leaves:4)
B(-5,11,-6,Leaves:4)
B(1,17,-3,Leaves:4)
B(7,6,3,Leaves:4)
B(11,10,1,Leaves:4)
B(11,9,2,Leaves:4)
B(11,8,2,Leaves:4)
B(-1,11,-5,Leaves:4)
B(3,14,-10,Leaves:4)
B(-6,13,-12,Leaves:4)
B(3,11,-10,Leaves:4)
B(3,10,-10,Leaves:4)
B(-6,12,-12,Leaves:4)
B(-6,11,-12,Leaves:4)
B(-6,10,-12,Leaves:4)
B(-1,10,-5,Leaves:4)
B(3,12,-10,Leaves:4)
B(5,12,5,Leaves:4)
B(5,11,5,Leaves:4)
B(-14,10,-2,Leaves:4)
B(-14,11,-2,Leaves:4)
B(5,13,5,Leaves:4)
B(1,5,0,LOG:12)
B(-14,12,-2,Leaves:4)
B(5,14,5,Leaves:4)
B(1,6,0,LOG:12)
B(5,15,5,Leaves:4)
B(1,4,0,LOG:12)
B(0,15,1,Leaves:4)
B(0,16,1,Leaves:4)
B(0,17,1,Leaves:4)
B(-4,-4,2,LOG:12)
B(-4,-5,2,LOG:12)
B(-14,6,-6,Leaves:4)
B(-13,4,-14,Leaves:4)
B(-1,10,-4,Leaves:4)
B(11,11,-4,Leaves:4)
B(-13,7,-14,Leaves:4)
B(-13,5,-14,Leaves:4)
B(-13,6,-14,Leaves:4)
B(-4,12,8,Leaves:4)
B(-10,9,-9,Leaves:4)
B(-5,9,-7,LOG:12)
B(0,11,11,Leaves:4)
B(-4,13,8,LOG:12)
B(0,12,11,Leaves:4)
B(-5,8,-7,Leaves:4)
B(-10,8,-9,Leaves:4)
B(0,13,11,Leaves:4)
B(-5,7,-7,LOG:12)
B(-4,10,8,Leaves:4)
B(-5,6,-7,Leaves:4)
B(-4,11,8,Leaves:4)
B(-14,9,-6,Leaves:4)
B(-4,14,8,Leaves:4)
B(-14,7,-6,Leaves:4)
B(-14,8,-6,Leaves:4)
B(-5,10,-11,Leaves:4)
B(-5,11,-11,Leaves:4)
B(-5,12,-11,Leaves:4)
B(-1,17,-5,Leaves:4)
B(-5,13,-11,Leaves:4)
B(-1,16,-5,Leaves:4)
B(-5,14,-11,Leaves:4)
B(-10,7,-9,Leaves:4)
B(-1,15,-5,Leaves:4)
B(-10,6,-9,Leaves:4)
B(2,16,2,Leaves:4)
B(2,15,2,Leaves:4)
B(2,10,2,Leaves:4)
B(2,14,2,Leaves:4)
B(2,13,2,Leaves:4)
B(2,12,2,Leaves:4)
B(2,11,2,Leaves:4)
B(-1,15,-4,Leaves:4)
B(-1,16,-4,Leaves:4)
B(-1,17,-4,Leaves:4)
B(-15,12,0,Leaves:4)
B(-15,13,0,Leaves:4)
B(-15,10,0,Leaves:4)
B(-15,11,0,Leaves:4)
B(-13,12,0,Leaves:4)
B(-13,11,0,Leaves:4)
B(3,8,4,Leaves:4)
B(-6,7,1,Leaves:4)
B(7,9,-3,Leaves:4)
B(0,5,-12,Leaves:4)
B(3,6,4,Leaves:4)
B(2,14,-13,Leaves:4)
B(0,7,-12,Leaves:4)
B(2,15,-13,Leaves:4)
B(0,6,-12,Leaves:4)
B(0,9,-12,Leaves:4)
B(2,13,-13,Leaves:4)
B(0,8,-12,Leaves:4)
B(2,10,-13,Leaves:4)
B(7,8,-3,Leaves:4)
B(3,-4,-1,LOG:12)
B(3,-5,-1,LOG:12)
B(3,9,4,Leaves:4)
B(-6,11,13,Leaves:4)
B(-6,10,13,Leaves:4)
B(5,5,3,Leaves:4)
B(5,4,3,Leaves:4)
B(5,7,3,Leaves:4)
B(0,-5,1,LOG:12)
B(0,-4,1,LOG:12)
B(5,6,3,Leaves:4)
B(-3,7,11,Leaves:4)
B(5,8,3,Leaves:4)
B(-4,-5,-5,LOG:12)
B(-3,6,11,Leaves:4)
B(-3,9,11,Leaves:4)
B(-3,8,11,Leaves:4)
B(0,6,0,Leaves:4)
B(-10,10,-9,Leaves:4)
B(6,14,-6,Leaves:4)
B(0,4,0,LOG:12)
B(-6,12,13,Leaves:4)
B(0,5,0,LOG:12)
B(6,10,-6,Leaves:4)
B(6,11,-6,Leaves:4)
B(6,12,-6,Leaves:4)
B(6,13,-6,Leaves:4)
B(-3,5,11,Leaves:4)
B(9,12,2,Leaves:4)
B(9,11,2,Leaves:4)
B(-4,9,-11,Leaves:4)
B(-4,8,-11,Leaves:4)
B(-7,8,2,Leaves:4)
B(-4,7,-11,Leaves:4)
B(-4,6,-11,Leaves:4)
B(3,9,-5,Leaves:4)
B(3,8,-5,Leaves:4)
B(-14,10,-5,Leaves:4)
B(2,9,-13,Leaves:4)
B(-3,-4,4,LOG:12)
B(3,10,-13,Leaves:4)
B(-10,12,6,Leaves:4)
B(-10,11,6,Leaves:4)
B(-10,10,6,Leaves:4)
B(2,14,-8,Leaves:4)
B(2,15,-8,Leaves:4)
B(2,12,-8,Leaves:4)
B(2,13,-8,Leaves:4)
B(2,16,-8,Leaves:4)
B(2,-5,2,LOG:12)
B(9,12,-5,Leaves:4)
B(2,11,-8,Leaves:4)
B(-11,14,-8,Leaves:4)
B(-11,15,-8,Leaves:4)
B(-11,10,-8,Leaves:4)
B(-11,11,-8,Leaves:4)
B(-6,8,9,Leaves:4)
B(-6,9,9,Leaves:4)
B(-6,6,9,Leaves:4)
B(-6,7,9,Leaves:4)
B(-9,9,2,Leaves:4)
B(-1,9,6,Leaves:4)
B(-11,11,3,Leaves:4)
B(-11,12,3,Leaves:4)
B(-11,13,3,Leaves:4)
B(-3,4,-11,Leaves:4)
B(-12,12,1,Leaves:4)
B(-3,12,4,Leaves:4)
B(-10,11,-10,Leaves:4)
B(-3,11,4,Leaves:4)
B(-3,10,4,Leaves:4)
B(8,13,-6,Leaves:4)
B(8,12,-6,Leaves:4)
B(-11,10,3,Leaves:4)
B(0,9,9,Leaves:4)
B(1,16,4,Leaves:4)
B(8,10,-6,Leaves:4)
B(8,11,-6,Leaves:4)
B(-11,6,12,Leaves:4)
B(-17,7,-3,Leaves:4)
B(1,10,4,Leaves:4)
B(-3,9,-11,Leaves:4)
B(1,11,4,Leaves:4)
B(1,14,4,Leaves:4)
B(-3,6,-11,Leaves:4)
B(1,15,4,Leaves:4)
B(-3,5,-11,Leaves:4)
B(1,12,4,Leaves:4)
B(-3,8,-11,Leaves:4)
B(1,13,4,Leaves:4)
B(-3,7,-11,Leaves:4)
B(-7,8,-14,Leaves:4)
B(-7,9,-14,Leaves:4)
B(-7,7,-14,Leaves:4)
B(-1,10,0,Leaves:4)
B(-1,11,0,Leaves:4)
B(-1,12,0,Leaves:4)
B(-1,15,0,Leaves:4)
B(-1,16,0,Leaves:4)
B(-1,17,0,Leaves:4)
B(2,11,8,Leaves:4)
B(2,12,8,Leaves:4)
B(-9,10,12,Leaves:4)
B(2,10,8,Leaves:4)
B(-9,12,-8,Leaves:4)
B(2,15,8,Leaves:4)
B(-9,13,-8,Leaves:4)
B(2,14,8,Leaves:4)
B(-9,10,-8,Leaves:4)
B(2,13,8,Leaves:4)
B(-14,8,8,Leaves:4)
B(-9,11,-8,Leaves:4)
B(-3,13,4,Leaves:4)
B(-10,10,-10,Leaves:4)
B(-3,14,4,Leaves:4)
B(-3,15,4,Leaves:4)
B(-9,14,-8,Leaves:4)
B(-3,16,4,Leaves:4)
B(-9,15,-8,Leaves:4)
B(-8,6,-3,Leaves:4)
B(6,13,8,Leaves:4)
B(6,12,8,Leaves:4)
B(-14,7,8,Leaves:4)
B(-8,9,-3,Leaves:4)
B(-10,10,-1,Leaves:4)
B(-10,15,-1,Leaves:4)
B(-10,12,-1,Leaves:4)
B(-10,11,-1,Leaves:4)
B(-10,14,-1,Leaves:4)
B(-10,13,-1,Leaves:4)
B(-5,14,7,Leaves:4)
B(-5,13,7,Leaves:4)
B(-5,12,7,Leaves:4)
B(-5,11,7,Leaves:4)
B(-4,8,-6,Leaves:4)
B(-4,9,-6,Leaves:4)
B(-4,7,-6,Leaves:4)
B(-2,5,-3,LOG:12)
B(-2,12,1,Leaves:4)
B(-2,11,1,Leaves:4)
B(-2,3,-3,LOG:12)
B(-2,10,1,Leaves:4)
B(-2,4,-3,LOG:12)
B(-2,16,1,Leaves:4)
B(-2,15,1,Leaves:4)
B(-10,16,-9,Leaves:4)
B(-10,15,-9,Leaves:4)
B(-10,12,-9,Leaves:4)
B(-10,11,-9,Leaves:4)
B(-10,13,-9,Leaves:4)
B(2,7,3,Leaves:4)
B(6,9,-8,Leaves:4)
B(2,8,3,Leaves:4)
B(2,6,3,LOG:12)
B(-11,5,7,Leaves:4)
B(-7,9,-15,Leaves:4)
B(8,6,5,Leaves:4)
B(-3,10,2,Leaves:4)
B(8,8,5,Leaves:4)
B(8,9,5,Leaves:4)
B(-3,16,2,Leaves:4)
B(-13,9,-8,Leaves:4)
B(-3,15,2,Leaves:4)
B(-3,13,2,LOG:12)
B(-3,12,2,LOG:12)
B(-3,11,2,LOG:12)
B(-13,6,4,Leaves:4)
B(-5,6,11,Leaves:4)
B(-5,7,11,Leaves:4)
B(-12,9,-8,Leaves:4)
B(-13,8,4,Leaves:4)
B(-12,8,-8,Leaves:4)
B(-13,7,4,Leaves:4)
B(-5,5,11,Leaves:4)
B(-15,7,7,Leaves:4)
B(-15,9,7,Leaves:4)
B(-15,8,7,Leaves:4)
B(1,8,-6,Leaves:4)
B(1,9,-6,Leaves:4)
B(1,7,-6,Leaves:4)
B(10,10,4,Leaves:4)
B(10,12,4,Leaves:4)
B(10,13,4,Leaves:4)
B(-6,10,-4,Leaves:4)
B(-6,15,-4,Leaves:4)
B(-6,16,-4,Leaves:4)
B(-3,15,-7,Leaves:4)
B(-6,14,-4,Leaves:4)
B(-6,17,-4,Leaves:4)
B(-7,14,5,Leaves:4)
B(-4,10,12,Leaves:4)
B(-4,12,12,Leaves:4)
B(-7,11,5,Leaves:4)
B(-7,10,5,Leaves:4)
B(-7,13,5,Leaves:4)
B(-7,12,5,Leaves:4)
B(-3,12,-7,Leaves:4)
B(-3,11,-7,Leaves:4)
B(-3,14,-7,Leaves:4)
B(11,8,-3,Leaves:4)
B(-3,10,-7,Leaves:4)
B(-13,10,7,Leaves:4)
B(-5,9,4,Leaves:4)
B(-5,8,4,Leaves:4)
B(-5,8,-1,Leaves:4)
B(-5,9,-1,Leaves:4)
B(-5,6,-1,Leaves:4)
B(-5,7,-1,Leaves:4)
B(-4,9,2,Leaves:4)
B(8,9,-5,Leaves:4)
B(8,8,-5,Leaves:4)
B(-3,9,7,Leaves:4)
B(6,13,-8,Leaves:4)
B(-3,8,7,Leaves:4)
B(9,8,-6,Leaves:4)
B(-3,7,7,Leaves:4)
B(6,12,-8,Leaves:4)
B(-3,6,7,Leaves:4)
B(6,11,-8,Leaves:4)
B(-9,13,-4,Leaves:4)
B(6,10,-8,Leaves:4)
B(-9,10,-4,Leaves:4)
B(-9,11,-4,Leaves:4)
B(-9,14,-4,Leaves:4)
B(-9,15,-4,Leaves:4)
B(9,7,-6,Leaves:4)
B(8,5,-5,Leaves:4)
B(4,9,-3,Leaves:4)
B(4,7,-3,Leaves:4)
B(8,7,-5,Leaves:4)
B(9,5,-6,Leaves:4)
B(8,6,-5,Leaves:4)
B(-1,14,-11,Leaves:4)
B(-1,13,-11,Leaves:4)
B(-7,9,3,Leaves:4)
B(-1,10,-11,Leaves:4)
B(-8,11,-9,Leaves:4)
B(-1,11,-11,Leaves:4)
B(-8,12,-9,Leaves:4)
B(-8,14,-9,Leaves:4)
B(-8,15,-9,Leaves:4)
B(2,11,10,Leaves:4)
B(2,12,10,Leaves:4)
B(0,4,1,LOG:12)
B(0,6,1,Leaves:4)
B(0,5,1,Leaves:4)
B(-4,10,-5,LOG:12)
B(-4,11,-5,LOG:12)
B(0,12,9,Leaves:4)
B(0,13,9,Leaves:4)
B(-6,11,8,Leaves:4)
B(-6,-5,-4,LOG:12)
B(-6,10,8,Leaves:4)
B(-12,11,-8,Leaves:4)
B(0,11,9,Leaves:4)
B(-12,10,-8,Leaves:4)
B(0,10,9,Leaves:4)
B(-6,14,8,Leaves:4)
B(-6,12,8,Leaves:4)
B(-12,12,-8,Leaves:4)
B(1,13,-12,Leaves:4)
B(1,12,-12,Leaves:4)
B(1,10,-12,Leaves:4)
B(1,14,-12,Leaves:4)
B(6,13,1,Leaves:4)
B(-5,6,-16,Leaves:4)
B(6,12,1,Leaves:4)
B(-2,10,-11,Leaves:4)
B(6,14,1,Leaves:4)
B(-2,12,-11,Leaves:4)
B(-2,11,-11,Leaves:4)
B(-2,13,-11,Leaves:4)
B(-4,12,-5,LOG:12)
B(-4,15,-5,Leaves:4)
B(-4,14,-5,Leaves:4)
B(-4,16,-5,Leaves:4)
B(3,5,2,Leaves:4)
B(3,6,2,Leaves:4)
B(3,7,2,Leaves:4)
B(3,8,2,Leaves:4)
B(-14,9,-7,Leaves:4)
B(3,9,2,Leaves:4)
B(3,15,-1,Leaves:4)
B(3,14,-1,Leaves:4)
B(3,13,-1,Leaves:4)
B(-6,11,7,Leaves:4)
B(-6,12,7,Leaves:4)
B(3,11,-1,Leaves:4)
B(-1,10,7,Leaves:4)
B(-5,11,10,Leaves:4)
B(-5,10,10,Leaves:4)
B(-1,11,7,Leaves:4)
B(-5,13,10,Leaves:4)
B(-1,12,7,Leaves:4)
B(-1,13,7,Leaves:4)
B(-5,12,10,Leaves:4)
B(5,13,-2,Leaves:4)
B(5,14,-2,Leaves:4)
B(1,14,-1,Leaves:4)
B(1,15,-1,Leaves:4)
B(-9,8,-12,Leaves:4)
B(-9,7,-12,Leaves:4)
B(1,17,-1,Leaves:4)
B(-9,6,-12,Leaves:4)
B(-9,5,-12,Leaves:4)
B(-10,12,-6,Leaves:4)
B(-10,13,-6,Leaves:4)
B(-10,14,-6,Leaves:4)
B(-5,10,12,Leaves:4)
B(5,11,0,Leaves:4)
B(5,12,0,Leaves:4)
B(5,13,0,Leaves:4)
B(5,14,0,Leaves:4)
B(-10,10,-6,Leaves:4)
B(5,15,0,Leaves:4)
B(-10,11,-6,Leaves:4)
B(1,11,-1,Leaves:4)
B(1,10,-1,Leaves:4)
B(1,13,-1,Leaves:4)
B(1,12,-1,Leaves:4)
B(2,17,-3,Leaves:4)
B(-11,12,-3,Leaves:4)
B(-12,13,-1,Leaves:4)
B(-11,13,-3,Leaves:4)
B(2,15,-3,Leaves:4)
B(-11,14,-3,Leaves:4)
B(2,16,-3,Leaves:4)
B(-11,15,-3,Leaves:4)
B(-12,10,-1,Leaves:4)
B(-12,12,-1,Leaves:4)
B(-12,11,-1,Leaves:4)
B(-11,10,-3,Leaves:4)
B(-11,11,-3,Leaves:4)
B(-2,9,7,Leaves:4)
B(-2,8,7,Leaves:4)
B(6,6,4,Leaves:4)
B(6,7,4,Leaves:4)
B(6,8,4,Leaves:4)
B(-2,7,7,Leaves:4)
B(-2,6,7,Leaves:4)
B(2,10,-3,Leaves:4)
B(6,5,4,Leaves:4)
B(2,14,-3,Leaves:4)
B(2,13,-3,Leaves:4)
B(2,12,-3,Leaves:4)
B(2,11,-3,Leaves:4)
B(4,-5,-1,LOG:12)
B(-1,15,7,Leaves:4)
B(-1,14,7,Leaves:4)
B(6,9,-3,Leaves:4)
B(-5,-4,-1,LOG:12)
B(-5,-1,-1,LOG:12)
B(-5,-5,-1,LOG:12)
B(4,15,8,Leaves:4)
B(-4,-5,-4,LOG:12)
B(-3,6,-4,LOG:12)
B(-3,5,-4,LOG:12)
B(-3,4,-4,LOG:12)
B(-3,3,-4,LOG:12)
B(11,8,0,Leaves:4)
B(4,9,7,Leaves:4)
B(11,9,0,Leaves:4)
B(-3,9,-4,Leaves:4)
B(-3,8,-4,LOG:12)
B(-3,7,-4,LOG:12)
B(-4,-4,-4,LOG:12)
B(-1,8,-3,Leaves:4)
B(-1,9,-3,Leaves:4)
B(-1,7,-3,Leaves:4)
B(11,7,0,Leaves:4)
B(0,-5,3,LOG:12)
B(4,10,8,Leaves:4)
B(4,12,8,Leaves:4)
B(-1,4,-3,LOG:12)
B(4,11,8,Leaves:4)
B(4,14,8,Leaves:4)
B(4,13,8,Leaves:4)
B(-3,11,-8,Leaves:4)
B(-3,14,-8,Leaves:4)
B(-3,12,-8,Leaves:4)
B(-3,13,-8,Leaves:4)
B(-15,7,11,Leaves:4)
B(-14,6,12,Leaves:4)
B(1,-5,1,LOG:12)
B(1,-4,1,LOG:12)
B(7,6,4,Leaves:4)
B(7,9,4,Leaves:4)
B(-14,10,3,Leaves:4)
B(-5,14,5,Leaves:4)
B(-14,11,3,Leaves:4)
B(-5,13,5,Leaves:4)
B(-5,12,5,Leaves:4)
B(-5,11,5,Leaves:4)
B(-5,10,5,Leaves:4)
B(2,9,-4,Leaves:4)
B(2,8,-4,Leaves:4)
B(-10,9,4,Leaves:4)
B(-10,8,4,Leaves:4)
B(2,7,-4,Leaves:4)
B(-3,16,-8,Leaves:4)
B(5,9,-1,Leaves:4)
B(-6,8,-14,Leaves:4)
B(-4,10,9,Leaves:4)
B(-10,7,4,Leaves:4)
B(-4,14,9,Leaves:4)
B(4,15,-1,Leaves:4)
B(-4,13,9,Leaves:4)
B(-4,12,9,LOG:12)
B(-4,11,9,Leaves:4)
B(5,7,-1,Leaves:4)
B(4,14,-1,Leaves:4)
B(-4,15,9,Leaves:4)
B(4,13,-1,Leaves:4)
B(-5,17,-6,Leaves:4)
B(-4,10,-4,LOG:12)
B(-12,10,6,Leaves:4)
B(-5,13,-6,LOG:12)
B(-5,12,-6,LOG:12)
B(-5,15,-6,Leaves:4)
B(-5,14,-6,Leaves:4)
B(-15,6,1,Leaves:4)
B(-15,7,1,Leaves:4)
B(-15,8,1,Leaves:4)
B(-7,9,-3,Leaves:4)
B(-15,9,1,Leaves:4)
B(1,13,1,Leaves:4)
B(1,15,1,Leaves:4)
B(1,16,1,Leaves:4)
B(-6,11,0,Leaves:4)
B(-6,10,0,Leaves:4)
B(3,10,9,Leaves:4)
B(3,13,9,Leaves:4)
B(1,10,1,LOG:12)
B(1,11,1,Leaves:4)
B(3,11,9,Leaves:4)
B(3,12,9,Leaves:4)
B(1,12,1,Leaves:4)
B(-16,7,4,Leaves:4)
B(0,12,3,Leaves:4)
B(0,10,3,Leaves:4)
B(-9,8,-2,Leaves:4)
B(-9,9,-2,Leaves:4)
B(-8,9,-4,Leaves:4)
B(0,16,3,Leaves:4)
B(-8,6,-4,Leaves:4)
B(0,15,3,Leaves:4)
B(0,11,-10,Leaves:4)
B(0,12,-10,Leaves:4)
B(0,13,-10,Leaves:4)
B(0,14,-10,Leaves:4)
B(0,10,-10,Leaves:4)
B(-9,6,-2,Leaves:4)
B(1,9,9,Leaves:4)
B(-2,-5,-1,LOG:12)
B(-2,-4,-1,LOG:12)
B(-2,-3,-1,LOG:12)
B(-2,-2,-1,LOG:12)
B(-2,-1,-1,LOG:12)
B(0,9,-13,Leaves:4)
B(1,-5,-5,LOG:12)
B(8,11,4,Leaves:4)
B(8,12,4,Leaves:4)
B(11,8,1,Leaves:4)
B(0,5,-13,Leaves:4)
B(-6,12,0,Leaves:4)
B(0,6,-13,Leaves:4)
B(-6,14,0,Leaves:4)
B(-6,15,0,Leaves:4)
B(11,9,1,Leaves:4)
B(-6,16,0,Leaves:4)
B(-15,11,-5,Leaves:4)
B(-15,12,-5,Leaves:4)
B(-9,12,-3,Leaves:4)
B(-9,11,-3,Leaves:4)
B(-9,10,-3,Leaves:4)
B(-9,16,-3,Leaves:4)
B(-9,15,-3,Leaves:4)
B(5,5,4,Leaves:4)
B(5,6,4,Leaves:4)
B(10,7,-1,Leaves:4)
B(5,9,4,Leaves:4)
B(10,8,-1,Leaves:4)
B(5,7,4,Leaves:4)
B(10,9,-1,Leaves:4)
B(5,8,4,Leaves:4)
B(3,7,-6,Leaves:4)
B(3,8,-6,Leaves:4)
B(-5,9,-6,LOG:12)
B(-5,8,-6,Leaves:4)
B(-5,7,-6,LOG:12)
B(-9,10,5,Leaves:4)
B(3,11,-7,Leaves:4)
B(-9,11,5,Leaves:4)
B(3,13,-7,Leaves:4)
B(3,12,-7,Leaves:4)
B(-5,16,-1,Leaves:4)
B(3,15,-7,Leaves:4)
B(-5,15,-1,Leaves:4)
B(3,14,-7,LOG:12)
B(-5,18,-1,Leaves:4)
B(-5,17,-1,Leaves:4)
B(3,16,-7,Leaves:4)
B(-5,12,-1,Leaves:4)
B(-5,11,-1,Leaves:4)
B(-5,14,-1,LOG:12)
B(-9,12,-7,Leaves:4)
B(-5,13,-1,Leaves:4)
B(-9,11,-7,Leaves:4)
B(-9,14,-7,Leaves:4)
B(-9,13,-7,Leaves:4)
B(-9,12,5,Leaves:4)
B(-5,10,-1,Leaves:4)
B(-9,15,-7,Leaves:4)
B(-9,13,5,Leaves:4)
B(4,13,-8,Leaves:4)
B(4,12,-8,Leaves:4)
B(4,11,-8,Leaves:4)
B(4,10,-8,Leaves:4)
B(0,11,-13,Leaves:4)
B(4,14,-8,Leaves:4)
B(1,7,1,Leaves:4)
B(-15,8,-6,Leaves:4)
B(1,9,1,LOG:12)
B(1,8,1,Leaves:4)
B(-15,9,-6,Leaves:4)
B(-1,8,-10,Leaves:4)
B(-12,7,2,Leaves:4)
B(-1,9,-10,Leaves:4)
B(-12,6,2,Leaves:4)
B(-12,5,2,Leaves:4)
B(-2,7,-6,LOG:12)
B(7,9,-2,Leaves:4)
B(7,8,-2,Leaves:4)
B(-12,12,-7,Leaves:4)
B(-2,9,-6,LOG:12)
B(-12,10,-7,Leaves:4)
B(-1,7,-10,Leaves:4)
B(2,14,-11,Leaves:4)
B(2,15,-11,Leaves:4)
B(-15,7,-6,Leaves:4)
B(2,10,-11,Leaves:4)
B(2,11,-11,Leaves:4)
B(-9,9,3,Leaves:4)
B(-6,4,8,Leaves:4)
B(-6,6,8,Leaves:4)
B(-6,5,8,Leaves:4)
B(-3,-4,-2,LOG:12)
B(-3,-5,-2,LOG:12)
B(-16,10,-2,Leaves:4)
B(-16,11,-2,Leaves:4)
B(-4,8,-10,Leaves:4)
B(-4,7,-10,Leaves:4)
B(-4,6,-10,Leaves:4)
B(0,-4,-1,LOG:12)
B(-3,-2,-2,LOG:12)
B(-3,-3,-2,LOG:12)
B(-2,-5,-4,LOG:12)
B(-4,9,-10,Leaves:4)
B(-3,-1,-2,LOG:12)
B(-5,10,3,LOG:12)
B(-5,11,3,Leaves:4)
B(-5,12,3,Leaves:4)
B(-7,13,7,Leaves:4)
B(-7,11,7,Leaves:4)
B(-5,16,3,Leaves:4)
B(-5,14,3,Leaves:4)
B(-5,12,11,Leaves:4)
B(-3,12,6,Leaves:4)
B(-3,11,6,Leaves:4)
B(-3,14,6,Leaves:4)
B(-3,13,6,Leaves:4)
B(-5,10,11,Leaves:4)
B(-13,10,6,Leaves:4)
B(-3,10,6,Leaves:4)
B(4,10,-11,Leaves:4)
B(-6,7,0,Leaves:4)
B(-6,6,0,Leaves:4)
B(7,10,-5,Leaves:4)
B(7,11,-5,Leaves:4)
B(-2,3,-2,LOG:12)
B(4,9,-4,Leaves:4)
B(-2,2,-2,LOG:12)
B(-2,1,-2,LOG:12)
B(-2,0,-2,LOG:12)
B(7,13,-5,Leaves:4)
B(-1,8,5,Leaves:4)
B(-1,7,5,Leaves:4)
B(-2,6,-2,LOG:12)
B(7,12,-5,Leaves:4)
B(-2,4,-2,LOG:12)
B(-1,9,5,Leaves:4)
B(0,8,1,Leaves:4)
B(0,7,1,Leaves:4)
B(-1,6,5,Leaves:4)
B(-2,9,-2,Leaves:4)
B(0,9,1,LOG:12)
B(-6,9,8,Leaves:4)
B(-6,7,8,Leaves:4)
B(-5,14,-10,Leaves:4)
B(-5,13,-10,Leaves:4)
B(-5,12,-10,Leaves:4)
B(-5,11,-10,Leaves:4)
B(-5,10,-10,Leaves:4)
B(-4,9,10,Leaves:4)
B(-3,-5,2,LOG:12)
B(0,6,8,Leaves:4)
B(-3,7,-12,Leaves:4)
B(-3,6,-12,Leaves:4)
B(-3,9,-12,Leaves:4)
B(-4,7,10,Leaves:4)
B(-3,8,-12,Leaves:4)
B(-4,6,10,Leaves:4)
B(0,9,8,Leaves:4)
B(-3,-4,2,LOG:12)
B(0,16,-1,Leaves:4)
B(0,15,-1,Leaves:4)
B(-2,16,-4,Leaves:4)
B(0,17,-1,Leaves:4)
B(-2,17,-4,Leaves:4)
B(8,11,-10,Leaves:4)
B(-14,8,7,Leaves:4)
B(-14,7,7,Leaves:4)
B(0,10,-1,Leaves:4)
B(0,11,-1,Leaves:4)
B(0,12,-1,Leaves:4)
B(0,13,-1,Leaves:4)
B(-9,15,0,Leaves:4)
B(-11,10,-6,Leaves:4)
B(-11,11,-6,Leaves:4)
B(-11,12,-6,Leaves:4)
B(-11,13,-6,Leaves:4)
B(-11,14,-6,Leaves:4)
B(1,12,-5,Leaves:4)
B(1,13,-5,Leaves:4)
B(1,11,-5,Leaves:4)
B(1,17,-5,Leaves:4)
B(1,15,-5,Leaves:4)
B(-4,7,-7,Leaves:4)
B(4,14,7,Leaves:4)
B(-4,8,-7,LOG:12)
B(4,12,1,Leaves:4)
B(4,15,1,Leaves:4)
B(4,14,1,Leaves:4)
B(-6,-5,0,LOG:12)
B(-6,-4,0,LOG:12)
B(4,11,1,Leaves:4)
B(4,10,1,LOG:12)
B(4,10,7,Leaves:4)
B(1,11,-7,Leaves:4)
B(4,11,7,Leaves:4)
B(4,12,7,Leaves:4)
B(4,13,7,Leaves:4)
B(1,14,-7,Leaves:4)
B(6,7,-9,Leaves:4)
B(-9,11,0,Leaves:4)
B(1,15,-7,Leaves:4)
B(6,6,-9,Leaves:4)
B(-9,12,0,Leaves:4)
B(-9,13,0,Leaves:4)
B(6,9,-9,Leaves:4)
B(1,12,-7,Leaves:4)
B(-9,14,0,Leaves:4)
B(1,13,-7,Leaves:4)
B(6,8,-9,Leaves:4)
B(1,16,-7,Leaves:4)
B(1,17,-7,Leaves:4)
B(-9,10,0,Leaves:4)
B(-1,9,4,Leaves:4)
B(3,14,-6,Leaves:4)
B(3,13,-6,Leaves:4)
B(-6,9,7,Leaves:4)
B(3,16,-6,Leaves:4)
B(3,15,-6,Leaves:4)
B(-1,7,4,Leaves:4)
B(3,10,-6,Leaves:4)
B(-1,6,4,Leaves:4)
B(3,12,-6,Leaves:4)
B(3,11,-6,Leaves:4)
B(-1,-1,-1,LOG:12)
B(-2,11,9,Leaves:4)
B(-2,12,9,Leaves:4)
B(-1,-2,-1,LOG:12)
B(-4,9,-9,Leaves:4)
B(-1,-3,-1,LOG:12)
B(5,9,9,Leaves:4)
B(5,8,9,Leaves:4)
B(-1,-4,-1,LOG:12)
B(-7,8,11,Leaves:4)
B(-7,9,11,Leaves:4)
B(-2,13,9,Leaves:4)
B(-7,6,11,Leaves:4)
B(-7,7,11,Leaves:4)
B(-1,-5,-1,LOG:12)
B(0,11,-2,Leaves:4)
B(0,14,-2,Leaves:4)
B(0,15,-2,Leaves:4)
B(4,9,-11,Leaves:4)
B(4,8,-11,Leaves:4)
B(0,12,-2,Leaves:4)
B(0,13,-2,LOG:12)
B(-2,-1,0,LOG:12)
B(4,7,-11,Leaves:4)
B(-2,-2,0,LOG:12)
B(-2,-3,0,LOG:12)
B(-2,-4,0,LOG:12)
B(-2,-5,0,LOG:12)
B(-3,9,4,Leaves:4)
B(3,8,1,Leaves:4)
B(3,7,1,Leaves:4)
B(0,18,-2,Leaves:4)
B(0,17,-2,Leaves:4)
B(0,16,-2,Leaves:4)
B(8,10,-4,Leaves:4)
B(8,11,-4,Leaves:4)
B(8,12,-4,Leaves:4)
B(-7,13,2,Leaves:4)
B(-7,9,8,Leaves:4)
B(-7,14,2,Leaves:4)
B(-7,8,8,Leaves:4)
B(-7,7,8,Leaves:4)
B(-7,12,2,Leaves:4)
B(-7,6,8,Leaves:4)
B(10,9,-7,Leaves:4)
B(10,8,-7,Leaves:4)
B(10,7,-7,Leaves:4)
B(-12,12,2,Leaves:4)
B(-12,14,2,Leaves:4)
B(-12,13,2,Leaves:4)
B(-6,7,-15,Leaves:4)
B(-7,9,0,Leaves:4)
B(-10,8,3,Leaves:4)
B(-7,7,0,Leaves:4)
B(10,9,5,Leaves:4)
B(-17,7,0,Leaves:4)
B(-15,6,6,Leaves:4)
B(-11,11,-9,Leaves:4)
B(1,11,10,Leaves:4)
B(1,12,10,Leaves:4)
B(-11,10,-9,Leaves:4)
B(-15,7,6,Leaves:4)
B(1,10,10,Leaves:4)
B(1,15,10,Leaves:4)
B(1,13,10,Leaves:4)
B(-10,9,3,Leaves:4)
B(1,14,10,Leaves:4)
B(-5,10,-13,Leaves:4)
B(-5,11,-13,Leaves:4)
B(0,7,6,Leaves:4)
B(-15,9,6,Leaves:4)
B(0,9,6,Leaves:4)
B(-2,13,10,Leaves:4)
B(-2,14,10,Leaves:4)
B(-6,9,10,Leaves:4)
B(-2,11,10,Leaves:4)
B(-2,12,10,Leaves:4)
B(-6,8,10,Leaves:4)
B(-6,7,10,Leaves:4)
B(-6,6,10,Leaves:4)
B(-7,15,2,Leaves:4)
B(5,6,1,leaves:4)
B(-1,5,-15,Leaves:4)
B(-10,16,-2,Leaves:4)
B(-10,12,-2,Leaves:4)
B(-10,13,-2,Leaves:4)
B(-10,14,-2,Leaves:4)
B(-10,15,-2,Leaves:4)
B(3,8,7,Leaves:4)
B(1,9,-4,Leaves:4)
B(1,8,-4,Leaves:4)
B(10,13,-5,Leaves:4)
B(-10,10,-2,Leaves:4)
B(-10,11,-2,Leaves:4)
B(10,12,-5,Leaves:4)
B(-2,16,0,Leaves:4)
B(-11,9,4,Leaves:4)
B(-13,10,8,Leaves:4)
B(-8,9,5,Leaves:4)
B(-6,11,10,Leaves:4)
B(-6,12,10,Leaves:4)
B(-2,11,0,Leaves:4)
B(-2,10,0,Leaves:4)
B(-6,10,10,Leaves:4)
B(-6,15,10,Leaves:4)
B(-2,12,0,Leaves:4)
B(-2,15,0,Leaves:4)
B(-6,13,10,Leaves:4)
B(-6,14,10,Leaves:4)
B(-13,6,8,Leaves:4)
B(-13,7,8,Leaves:4)
B(-14,7,-8,Leaves:4)
B(-13,8,8,Leaves:4)
B(-14,8,-8,Leaves:4)
B(-3,17,-5,Leaves:4)
B(-3,14,-5,Leaves:4)
B(-3,15,-5,Leaves:4)
B(-3,16,-5,Leaves:4)
B(-13,5,-11,Leaves:4)
B(-3,11,-5,LOG:12)
B(-13,6,-11,Leaves:4)
B(-3,10,-5,LOG:12)
B(-14,12,1,Leaves:4)
B(-14,13,1,Leaves:4)
B(-10,6,-13,Leaves:4)
B(-13,8,-11,Leaves:4)
B(-11,6,11,Leaves:4)
B(-14,10,1,Leaves:4)
B(12,9,0,Leaves:4)
B(-11,7,11,Leaves:4)
B(-7,-5,2,LOG:12)
B(7,5,-5,Leaves:4)
B(2,-5,-1,LOG:12)
B(-6,6,7,Leaves:4)
B(-6,7,7,Leaves:4)
B(-6,5,7,Leaves:4)
B(7,9,-5,Leaves:4)
B(7,8,-5,Leaves:4)
B(-15,7,-5,Leaves:4)
B(-15,8,-5,Leaves:4)
B(-6,8,-3,LOG:12)
B(0,9,-3,Leaves:4)
B(-5,14,6,Leaves:4)
B(-5,13,6,Leaves:4)
B(1,9,3,Leaves:4)
B(1,7,3,LOG:12)
B(-5,10,6,Leaves:4)
B(1,6,3,LOG:12)
B(-5,12,6,Leaves:4)
B(-5,11,6,Leaves:4)
B(-11,12,4,Leaves:4)
B(-11,13,4,Leaves:4)
B(-11,14,4,Leaves:4)
B(-12,8,4,Leaves:4)
B(4,15,-7,Leaves:4)
B(-12,9,4,Leaves:4)
B(4,14,-7,Leaves:4)
B(-11,10,4,Leaves:4)
B(2,10,7,Leaves:4)
B(4,13,-7,Leaves:4)
B(-11,11,4,Leaves:4)
B(2,11,7,Leaves:4)
B(4,7,2,Leaves:4)
B(4,12,-7,Leaves:4)
B(1,7,-11,Leaves:4)
B(4,11,-7,Leaves:4)
B(4,9,2,Leaves:4)
B(1,9,-11,Leaves:4)
B(4,8,2,Leaves:4)
B(2,13,7,Leaves:4)
B(2,12,7,Leaves:4)
B(2,15,7,Leaves:4)
B(2,14,7,Leaves:4)
B(-3,12,12,Leaves:4)
B(-3,10,12,Leaves:4)
B(-3,11,12,Leaves:4)
B(-3,-5,-5,LOG:12)
B(-3,-4,-5,LOG:12)
B(-8,5,5,Leaves:4)
B(-8,4,5,Leaves:4)
B(-9,13,-11,Leaves:4)
B(-9,12,-11,Leaves:4)
B(2,-4,1,LOG:12)
B(2,-5,1,LOG:12)
B(-17,7,-6,Leaves:4)
B(-11,9,-7,Leaves:4)
B(-11,7,-7,Leaves:4)
B(-11,8,-7,Leaves:4)
B(-12,10,-9,Leaves:4)
B(-11,6,-7,Leaves:4)
B(-12,11,-9,Leaves:4)
B(6,14,0,Leaves:4)
B(-2,-5,-5,LOG:12)
B(6,13,0,Leaves:4)
B(6,15,0,Leaves:4)
B(2,16,-1,Leaves:4)
B(2,13,-1,Leaves:4)
B(6,12,0,Leaves:4)
B(2,14,-1,Leaves:4)
B(6,11,0,Leaves:4)
B(1,15,-8,Leaves:4)
B(-9,11,8,Leaves:4)
B(2,12,-1,Leaves:4)
B(-6,14,4,Leaves:4)
B(2,11,-1,Leaves:4)
B(-9,13,8,Leaves:4)
B(-6,13,4,Leaves:4)
B(1,13,-8,Leaves:4)
B(-9,10,-11,Leaves:4)
B(2,10,-1,Leaves:4)
B(1,14,-8,Leaves:4)
B(-6,12,4,Leaves:4)
B(-9,11,-11,Leaves:4)
B(-6,11,4,Leaves:4)
B(-7,8,-6,LOG:12)
B(-6,10,4,Leaves:4)
B(-9,10,8,Leaves:4)
B(1,11,-10,Leaves:4)
B(1,10,-10,Leaves:4)
B(-7,9,-6,LOG:12)
B(1,11,-8,Leaves:4)
B(1,13,-10,Leaves:4)
B(2,8,-9,Leaves:4)
B(7,14,2,Leaves:4)
B(7,13,2,Leaves:4)
B(7,12,2,Leaves:4)
B(2,7,-9,Leaves:4)
B(-6,15,2,Leaves:4)
B(-1,17,-1,Leaves:4)
B(-6,14,2,Leaves:4)
B(-1,16,-1,Leaves:4)
B(-6,16,2,Leaves:4)
B(-1,15,-1,Leaves:4)
B(-5,6,10,Leaves:4)
B(-5,9,10,Leaves:4)
B(-4,-4,0,LOG:12)
B(-4,-5,0,LOG:12)
B(6,8,6,Leaves:4)
B(7,10,2,Leaves:4)
B(-4,-1,0,LOG:12)
B(6,9,6,Leaves:4)
B(7,11,2,Leaves:4)
B(-4,-2,0,LOG:12)
B(-4,-3,0,LOG:12)
B(6,6,6,Leaves:4)
B(6,7,6,Leaves:4)
B(8,9,4,Leaves:4)
B(8,8,4,Leaves:4)
B(0,-4,-2,LOG:12)
B(-1,10,-1,Leaves:4)
B(1,-4,2,LOG:12)
B(1,-5,2,LOG:12)
B(-13,10,-4,Leaves:4)
B(-10,15,1,Leaves:4)
B(-13,12,-4,Leaves:4)
B(-10,14,1,Leaves:4)
B(-13,11,-4,Leaves:4)
B(-10,13,1,Leaves:4)
B(-10,11,1,Leaves:4)
B(-10,10,1,Leaves:4)
B(2,11,1,Leaves:4)
B(2,10,1,LOG:12)
B(2,13,1,Leaves:4)
B(2,12,1,Leaves:4)
B(11,8,-2,Leaves:4)
B(-12,10,3,Leaves:4)
B(-12,11,3,Leaves:4)
B(-12,12,3,Leaves:4)
B(-2,11,-5,LOG:12)
B(-12,13,3,Leaves:4)
B(-2,10,-5,LOG:12)
B(2,15,1,Leaves:4)
B(2,14,1,Leaves:4)
B(2,16,1,Leaves:4)
B(-2,14,-5,Leaves:4)
B(-2,15,-5,Leaves:4)
B(-2,16,-5,Leaves:4)
B(-2,17,-5,Leaves:4)
B(3,14,8,Leaves:4)
B(3,12,8,Leaves:4)
B(-14,8,1,Leaves:4)
B(3,13,8,Leaves:4)
B(-14,7,1,Leaves:4)
B(5,12,-11,Leaves:4)
B(3,10,8,Leaves:4)
B(-14,9,1,Leaves:4)
B(3,11,8,Leaves:4)
B(-10,16,1,Leaves:4)
B(2,7,-1,Leaves:4)
B(-10,14,9,Leaves:4)
B(2,9,-1,Leaves:4)
B(2,8,-1,Leaves:4)
B(5,13,-11,Leaves:4)
B(5,14,-11,Leaves:4)
B(1,15,2,Leaves:4)
B(1,14,2,Leaves:4)
B(1,13,2,Leaves:4)
B(1,12,2,Leaves:4)
B(1,11,2,Leaves:4)
B(9,8,-9,Leaves:4)
B(1,10,2,LOG:12)
B(9,9,-9,Leaves:4)
B(-9,8,9,Leaves:4)
B(3,8,-3,Leaves:4)
B(-9,7,9,Leaves:4)
B(-9,6,9,Leaves:4)
B(3,9,-3,Leaves:4)
B(-9,5,9,Leaves:4)
B(5,7,-10,Leaves:4)
B(5,8,-10,Leaves:4)
B(5,9,-10,Leaves:4)
B(-4,12,0,Leaves:4)
B(-4,11,0,Leaves:4)
B(-4,10,0,Leaves:4)
B(-4,16,0,Leaves:4)
B(-4,15,0,Leaves:4)
B(-4,14,0,Leaves:4)
B(-2,11,13,Leaves:4)
B(-4,18,0,Leaves:4)
B(-9,9,-9,Leaves:4)
B(7,13,8,Leaves:4)
B(-9,7,-9,Leaves:4)
B(7,12,8,Leaves:4)
B(-9,6,-9,Leaves:4)
B(-9,9,0,Leaves:4)
B(-2,8,-13,Leaves:4)
B(-2,6,-13,Leaves:4)
B(1,9,10,Leaves:4)
B(1,8,10,Leaves:4)
B(-2,7,-13,Leaves:4)
B(1,7,10,Leaves:4)
B(-5,-3,-3,LOG:12)
B(-5,-4,-3,LOG:12)
B(-5,-5,-3,LOG:12)
B(8,8,-10,Leaves:4)
B(8,9,-10,Leaves:4)
B(8,6,-10,Leaves:4)
B(8,7,-10,Leaves:4)
B(-8,7,-1,Leaves:4)
B(8,9,-6,Leaves:4)
B(8,8,-6,Leaves:4)
B(8,7,-6,Leaves:4)
B(-9,8,-7,Leaves:4)
B(8,5,-6,Leaves:4)
B(-9,9,-7,Leaves:4)
B(8,4,-6,Leaves:4)
B(-9,7,-7,Leaves:4)
B(8,3,-6,Leaves:4)
B(-10,9,-7,Leaves:4)
B(-4,8,5,Leaves:4)
B(-10,8,-7,Leaves:4)
B(-10,7,-7,Leaves:4)
B(-10,6,-7,Leaves:4)
B(-11,9,-6,Leaves:4)
B(-11,8,-6,Leaves:4)
B(-11,7,-6,Leaves:4)
B(-8,6,-1,Leaves:4)
B(-8,16,-6,Leaves:4)
B(-8,15,-6,Leaves:4)
B(-8,14,-6,Leaves:4)
B(-8,13,-6,Leaves:4)
B(-8,12,-6,Leaves:4)
B(-8,10,-6,LOG:12)
B(11,10,-1,Leaves:4)
B(-8,17,-6,Leaves:4)
B(-5,8,-10,Leaves:4)
B(-5,9,-10,Leaves:4)
B(-5,6,-10,Leaves:4)
B(1,4,-12,Leaves:4)
B(1,7,-12,Leaves:4)
B(4,7,1,Leaves:4)
B(1,6,-12,Leaves:4)
B(1,5,-12,Leaves:4)
B(-2,7,12,Leaves:4)
B(-6,13,11,Leaves:4)
B(-2,6,12,Leaves:4)
B(-6,10,11,Leaves:4)
B(-6,11,11,Leaves:4)
B(-2,9,12,Leaves:4)
B(-5,10,-3,LOG:12)
B(-5,16,-3,Leaves:4)
B(-5,15,-3,Leaves:4)
B(-5,18,-3,Leaves:4)
B(1,9,-12,Leaves:4)
B(-5,17,-3,Leaves:4)
B(-6,9,-2,Leaves:4)
B(-6,8,-2,Leaves:4)
B(-6,7,-2,Leaves:4)
B(-11,9,-5,Leaves:4)
B(-11,8,-5,Leaves:4)
B(-11,7,-5,Leaves:4)
B(-11,6,-5,Leaves:4)
B(-8,10,5,Leaves:4)
B(-4,-1,-3,LOG:12)
B(-4,-2,-3,LOG:12)
B(-4,-3,-3,LOG:12)
B(-4,-4,-3,LOG:12)
B(-4,7,-13,Leaves:4)
B(-4,-5,-3,LOG:12)
B(-4,6,-13,Leaves:4)
B(-4,9,-13,Leaves:4)
B(-4,8,-13,Leaves:4)
B(5,9,-6,Leaves:4)
B(-8,13,5,Leaves:4)
B(-4,5,-13,Leaves:4)
B(-8,11,5,Leaves:4)
B(-8,12,5,Leaves:4)
B(-9,11,6,Leaves:4)
B(-9,12,6,Leaves:4)
B(-9,10,6,Leaves:4)
B(-3,-5,-3,LOG:12)
B(-1,13,-10,Leaves:4)
B(-1,14,-10,Leaves:4)
B(-3,-4,-3,LOG:12)
B(-1,11,-10,Leaves:4)
B(-3,-3,-3,LOG:12)
B(-1,12,-10,Leaves:4)
B(-1,15,-10,Leaves:4)
B(-13,9,-3,Leaves:4)
B(-12,7,-7,Leaves:4)
B(-12,9,-7,Leaves:4)
B(-12,8,-7,Leaves:4)
B(3,11,-9,Leaves:4)
B(3,10,-9,Leaves:4)
B(-17,11,-4,Leaves:4)
B(2,14,-6,Leaves:4)
B(3,13,-9,Leaves:4)
B(7,11,-3,Leaves:4)
B(7,10,-3,Leaves:4)
B(3,12,-9,Leaves:4)
B(2,16,-6,Leaves:4)
B(7,13,-3,Leaves:4)
B(2,17,-6,Leaves:4)
B(3,14,-9,Leaves:4)
B(7,12,-3,Leaves:4)
B(2,10,-6,Leaves:4)
B(7,14,-3,Leaves:4)
B(2,11,-6,Leaves:4)
B(2,12,-6,Leaves:4)
B(2,13,-6,Leaves:4)
B(7,12,5,Leaves:4)
B(-2,12,8,Leaves:4)
B(4,14,-4,Leaves:4)
B(4,15,-4,Leaves:4)
B(-2,14,8,Leaves:4)
B(-3,8,-7,LOG:12)
B(-2,11,8,Leaves:4)
B(-10,12,2,Leaves:4)
B(-10,11,2,Leaves:4)
B(8,13,2,Leaves:4)
B(-10,10,2,Leaves:4)
B(-10,15,2,Leaves:4)
B(-10,14,2,Leaves:4)
B(-10,13,2,Leaves:4)
B(4,8,-1,Leaves:4)
B(9,8,-2,Leaves:4)
B(9,9,-2,Leaves:4)
B(8,12,2,Leaves:4)
B(9,6,-2,Leaves:4)
B(-9,11,7,Leaves:4)
B(9,7,-2,Leaves:4)
B(-9,10,7,Leaves:4)
B(8,11,2,Leaves:4)
B(-9,13,7,Leaves:4)
B(8,10,2,Leaves:4)
B(-9,12,7,Leaves:4)
B(-9,14,7,Leaves:4)
B(4,13,-4,Leaves:4)
B(4,5,-1,Leaves:4)
B(9,10,-9,Leaves:4)
B(4,7,-1,Leaves:4)
B(4,11,-4,Leaves:4)
B(4,6,-1,Leaves:4)
B(4,10,-4,Leaves:4)
B(-4,18,-3,Leaves:4)
B(-5,9,-5,LOG:12)
B(-5,8,-5,LOG:12)
B(-4,15,-3,Leaves:4)
B(-5,7,6,Leaves:4)
B(-5,6,6,Leaves:4)
B(-4,17,-3,Leaves:4)
B(-5,9,6,Leaves:4)
B(-4,16,-3,Leaves:4)
B(-5,8,6,Leaves:4)
B(-13,13,3,Leaves:4)
B(-13,10,3,Leaves:4)
B(5,10,9,Leaves:4)
B(5,12,9,Leaves:4)
B(-13,12,3,Leaves:4)
B(-13,11,3,Leaves:4)
B(3,10,5,Leaves:4)
B(-1,9,-9,Leaves:4)
B(-1,8,-9,Leaves:4)
B(6,10,6,Leaves:4)
B(-10,15,0,Leaves:4)
B(6,11,6,Leaves:4)
B(6,13,6,Leaves:4)
B(3,14,5,Leaves:4)
B(3,13,5,Leaves:4)
B(3,12,5,Leaves:4)
B(3,11,5,Leaves:4)
B(5,13,1,Leaves:4)
B(5,14,1,Leaves:4)
B(5,15,1,Leaves:4)
B(3,15,5,Leaves:4)
B(10,11,2,Leaves:4)
B(10,10,2,Leaves:4)
B(4,8,-9,Leaves:4)
B(4,9,-9,Leaves:4)
B(-10,10,0,Leaves:4)
B(6,11,-1,Leaves:4)
B(6,12,-1,Leaves:4)
B(-10,13,0,Leaves:4)
B(6,13,-1,Leaves:4)
B(-10,14,0,Leaves:4)
B(6,14,-1,Leaves:4)
B(-10,11,0,Leaves:4)
B(10,12,2,Leaves:4)
B(-10,12,0,Leaves:4)
B(-1,7,-9,Leaves:4)
B(4,12,9,Leaves:4)
B(4,13,9,Leaves:4)
B(-1,10,6,Leaves:4)
B(-1,11,6,Leaves:4)
B(-1,12,6,Leaves:4)
B(4,7,-9,Leaves:4)
B(4,10,9,Leaves:4)
B(4,11,9,Leaves:4)
B(-1,15,6,Leaves:4)
B(-1,14,6,Leaves:4)
B(-1,13,6,Leaves:4)
B(-16,7,-6,Leaves:4)
B(-1,8,3,Leaves:4)
B(-1,7,3,Leaves:4)
B(-6,9,6,Leaves:4)
B(-7,-5,-1,LOG:12)
B(-7,9,12,Leaves:4)
B(-2,9,-9,Leaves:4)
B(-1,9,3,LOG:12)
B(-13,7,11,Leaves:4)
B(0,11,-14,Leaves:4)
B(-7,7,12,Leaves:4)
B(-7,8,12,Leaves:4)
B(-4,5,-8,Leaves:4)
B(-4,6,-8,Leaves:4)
B(-4,7,-8,Leaves:4)
B(-4,8,-8,Leaves:4)
B(-13,6,11,Leaves:4)
B(-4,9,-8,Leaves:4)
B(-11,5,5,Leaves:4)
B(-11,9,5,Leaves:4)
B(-11,7,5,Leaves:4)
B(-11,6,5,Leaves:4)
B(4,9,-12,Leaves:4)
B(4,7,-12,Leaves:4)
B(-13,10,-8,Leaves:4)
B(-14,8,-9,Leaves:4)
B(3,8,0,Leaves:4)
B(-5,7,7,Leaves:4)
B(3,9,0,Leaves:4)
B(-14,7,-9,Leaves:4)
B(-5,6,7,Leaves:4)
B(-8,13,-10,Leaves:4)
B(6,9,-1,Leaves:4)
B(-8,12,-10,Leaves:4)
B(-8,11,-10,Leaves:4)
B(6,7,-1,leaves:4)
B(-8,10,-10,Leaves:4)
B(-8,15,-10,Leaves:4)
B(-8,14,-10,Leaves:4)
B(-7,9,9,Leaves:4)
B(-12,6,12,Leaves:4)
B(-12,5,12,Leaves:4)
B(-7,6,9,Leaves:4)
B(-12,7,12,Leaves:4)
B(-14,7,0,Leaves:4)
B(-15,12,-1,Leaves:4)
B(-15,13,-1,Leaves:4)
B(-15,10,-1,Leaves:4)
B(-15,11,-1,Leaves:4)
B(0,6,7,Leaves:4)
B(-12,10,4,Leaves:4)
B(0,8,7,Leaves:4)
B(-12,11,4,Leaves:4)
B(-12,12,4,Leaves:4)
B(0,7,7,Leaves:4)
B(-14,8,0,Leaves:4)
B(-14,9,0,Leaves:4)
B(2,-5,0,LOG:12)
B(0,9,7,Leaves:4)
B(-6,7,6,Leaves:4)
B(-13,12,-3,Leaves:4)
B(-13,11,-3,Leaves:4)
B(-3,-5,-4,LOG:12)
B(-13,10,-3,Leaves:4)
B(2,7,6,Leaves:4)
B(-7,10,-1,Leaves:4)
B(-7,12,-1,Leaves:4)
B(-7,11,-1,Leaves:4)
B(-7,14,-1,Leaves:4)
B(-3,10,-4,LOG:12)
B(-7,13,-1,Leaves:4)
B(-7,15,-1,Leaves:4)
B(2,9,6,Leaves:4)
B(-7,17,-1,Leaves:4)
B(2,8,6,Leaves:4)
B(-2,10,-3,Leaves:4)
B(1,9,-3,Leaves:4)
B(-2,16,-6,Leaves:4)
B(-2,15,-6,Leaves:4)
B(-2,17,-6,Leaves:4)
B(-8,9,4,Leaves:4)
B(-2,17,-3,Leaves:4)
B(-2,16,-3,Leaves:4)
B(-3,9,5,Leaves:4)
B(-8,14,-7,Leaves:4)
B(-3,12,8,Leaves:4)
B(-2,18,-3,Leaves:4)
B(-8,15,-7,Leaves:4)
B(-3,11,8,Leaves:4)
B(-3,14,8,Leaves:4)
B(-8,12,-7,Leaves:4)
B(-3,13,8,LOG:12)
B(-8,13,-7,Leaves:4)
B(-2,15,-3,Leaves:4)
B(-3,8,5,Leaves:4)
B(-8,11,-7,Leaves:4)
B(4,11,0,Leaves:4)
B(4,12,0,Leaves:4)
B(4,13,0,Leaves:4)
B(4,14,0,Leaves:4)
B(2,13,-14,Leaves:4)
B(-13,6,7,Leaves:4)
B(-13,7,7,Leaves:4)
B(-13,8,7,Leaves:4)
B(-13,9,7,Leaves:4)
B(4,10,0,Leaves:4)
B(-12,9,5,Leaves:4)
B(4,15,0,Leaves:4)
B(-12,6,5,Leaves:4)
B(2,11,-14,Leaves:4)
B(2,10,-14,Leaves:4)
B(-12,7,5,Leaves:4)
B(-10,12,7,Leaves:4)
B(-10,11,7,Leaves:4)
B(-10,10,7,Leaves:4)
B(5,14,-4,Leaves:4)
B(-6,-5,-1,LOG:12)
B(-6,-4,-1,LOG:12)
B(5,15,-4,Leaves:4)
B(3,9,-9,Leaves:4)
B(3,7,-9,Leaves:4)
B(-10,14,7,Leaves:4)
B(3,8,-9,Leaves:4)
B(5,11,-4,Leaves:4)
B(-7,6,10,Leaves:4)
B(-4,13,5,Leaves:4)
B(-4,12,5,Leaves:4)
B(-4,10,5,LOG:12)
B(-8,8,4,Leaves:4)
B(-7,7,1,Leaves:4)
B(-7,9,10,Leaves:4)
B(-4,2,-1,LOG:12)
B(-2,14,-6,Leaves:4)
B(-4,1,-1,LOG:12)
B(-4,0,-1,LOG:12)
B(-2,11,-6,LOG:12)
B(-2,12,-6,LOG:12)
B(-4,16,5,Leaves:4)
B(-2,10,-6,Leaves:4)
B(-13,5,-12,Leaves:4)
B(-10,6,-12,Leaves:4)
B(-13,6,-12,Leaves:4)
B(-10,7,-12,Leaves:4)
B(-4,15,7,Leaves:4)
B(-3,15,-4,Leaves:4)
B(-4,14,7,Leaves:4)
B(7,9,-4,Leaves:4)
B(-3,9,12,Leaves:4)
B(-3,14,-4,Leaves:4)
B(-4,13,7,LOG:12)
B(7,8,-4,Leaves:4)
B(-3,17,-4,Leaves:4)
B(-4,12,7,Leaves:4)
B(-3,7,12,Leaves:4)
B(-3,16,-4,Leaves:4)
B(-3,8,12,Leaves:4)
B(-4,11,7,Leaves:4)
B(-4,10,7,Leaves:4)
B(-3,6,12,Leaves:4)
B(5,8,2,Leaves:4)
B(5,6,2,LOG:12)
B(-4,3,-1,LOG:12)
B(4,14,-9,Leaves:4)
B(3,8,8,Leaves:4)
B(4,12,-9,Leaves:4)
B(4,11,-9,Leaves:4)
B(3,9,8,Leaves:4)
B(4,10,-9,Leaves:4)
B(-8,10,-11,Leaves:4)
B(1,8,2,LOG:12)
B(1,7,2,Leaves:4)
B(1,6,2,LOG:12)
B(1,5,2,LOG:12)
B(1,9,2,LOG:12)
B(-6,12,-13,Leaves:4)
B(-6,11,-13,Leaves:4)
B(-1,16,1,Leaves:4)
B(8,7,3,Leaves:4)
B(-16,10,1,Leaves:4)
B(8,8,3,Leaves:4)
B(-16,11,1,Leaves:4)
B(8,9,3,Leaves:4)
B(-1,17,-3,Leaves:4)
B(-1,10,1,LOG:12)
B(-1,13,-3,Leaves:4)
B(-1,14,-3,Leaves:4)
B(-1,15,-3,Leaves:4)
B(-1,16,-3,Leaves:4)
B(-1,15,1,Leaves:4)
B(-2,-4,-3,LOG:12)
B(-2,-5,-3,LOG:12)
B(8,12,-3,Leaves:4)
B(8,11,-3,Leaves:4)
B(8,10,-3,Leaves:4)
B(7,10,-2,Leaves:4)
B(7,11,-2,Leaves:4)
B(7,12,-2,Leaves:4)
B(-6,16,-1,Leaves:4)
B(7,13,-2,Leaves:4)
B(-13,10,10,Leaves:4)
B(-6,17,-1,Leaves:4)
B(7,14,-2,Leaves:4)
B(-6,14,-1,Leaves:4)
B(-6,15,-1,Leaves:4)
B(-6,12,-1,Leaves:4)
B(-6,13,-1,Leaves:4)
B(-6,10,-1,Leaves:4)
B(-6,11,-1,Leaves:4)
B(9,7,0,Leaves:4)
B(9,9,0,Leaves:4)
B(-6,10,-13,Leaves:4)
B(5,12,4,Leaves:4)
B(5,13,4,Leaves:4)
B(5,14,4,Leaves:4)
B(-11,8,-8,Leaves:4)
B(-11,9,-8,Leaves:4)
B(-8,13,-11,Leaves:4)
B(-8,14,-11,Leaves:4)
B(-8,11,-11,Leaves:4)
B(5,11,4,Leaves:4)
B(5,10,4,Leaves:4)
B(-8,12,-11,Leaves:4)
B(-11,8,10,Leaves:4)
B(-11,9,10,Leaves:4)
B(-11,6,10,Leaves:4)
B(-11,7,10,Leaves:4)
B(7,9,-11,Leaves:4)
B(0,9,-4,Leaves:4)
B(0,8,-4,Leaves:4)
B(-3,9,-10,Leaves:4)
B(-3,8,-10,Leaves:4)
B(-3,7,-10,Leaves:4)
B(-1,-4,-3,LOG:12)
B(-1,-5,-3,LOG:12)
B(7,13,0,Leaves:4)
B(7,12,0,Leaves:4)
B(-1,-5,1,LOG:12)
B(7,11,0,Leaves:4)
B(-1,-4,1,LOG:12)
B(7,14,0,Leaves:4)
B(9,9,-8,Leaves:4)
B(9,8,-8,Leaves:4)
B(-11,15,2,Leaves:4)
B(-11,14,2,Leaves:4)
B(-11,11,2,Leaves:4)
B(-11,10,2,Leaves:4)
B(-11,13,2,Leaves:4)
B(-11,12,2,Leaves:4)
B(10,11,-3,Leaves:4)
B(-1,14,9,Leaves:4)
B(10,11,-4,Leaves:4)
B(10,12,-4,Leaves:4)
B(-1,12,9,Leaves:4)
B(-1,13,9,Leaves:4)
B(-4,9,13,Leaves:4)
B(-1,10,9,Leaves:4)
B(-12,10,-6,Leaves:4)
B(-12,11,-6,Leaves:4)
B(-4,15,-12,Leaves:4)
B(-7,7,-7,Leaves:4)
B(-4,14,-12,Leaves:4)
B(-7,6,-7,Leaves:4)
B(2,9,-2,Leaves:4)
B(-4,13,-12,Leaves:4)
B(-4,12,-12,Leaves:4)
B(2,7,-2,Leaves:4)
B(-7,9,-7,Leaves:4)
B(1,13,3,Leaves:4)
B(1,11,3,Leaves:4)
B(1,12,3,Leaves:4)
B(-8,6,-2,Leaves:4)
B(3,10,-11,Leaves:4)
B(-6,11,2,Leaves:4)
B(-8,7,-2,Leaves:4)
B(-6,10,2,Leaves:4)
B(1,10,3,Leaves:4)
B(-8,8,-2,Leaves:4)
B(-9,9,-8,Leaves:4)
B(-8,9,-2,Leaves:4)
B(-9,7,-8,Leaves:4)
B(3,11,-11,Leaves:4)
B(1,15,3,Leaves:4)
B(8,10,1,Leaves:4)
B(1,16,3,Leaves:4)
B(8,11,1,Leaves:4)
B(8,13,1,Leaves:4)
B(8,12,1,Leaves:4)
B(8,14,1,Leaves:4)
B(5,8,-11,Leaves:4)
B(5,9,-11,Leaves:4)
B(6,9,5,Leaves:4)
B(6,8,5,Leaves:4)
B(6,7,5,Leaves:4)
B(6,6,5,Leaves:4)
B(-8,9,10,Leaves:4)
B(-8,8,10,Leaves:4)
B(-8,7,10,Leaves:4)
B(-8,5,10,Leaves:4)
B(-2,7,-12,Leaves:4)
B(-2,8,-12,Leaves:4)
B(-2,6,-12,Leaves:4)
B(-2,9,-12,Leaves:4)
B(-12,10,0,Leaves:4)
B(-2,10,7,Leaves:4)
B(-12,12,0,Leaves:4)
B(-12,11,0,Leaves:4)
B(-12,14,0,Leaves:4)
B(-2,13,7,Leaves:4)
B(-2,14,7,Leaves:4)
B(-2,11,7,Leaves:4)
B(-2,12,7,Leaves:4)
B(11,7,-1,Leaves:4)
B(11,8,-1,Leaves:4)
B(11,9,-1,Leaves:4)
B(-2,11,-10,Leaves:4)
B(-2,10,-10,Leaves:4)
B(-11,9,-4,Leaves:4)
B(-6,-4,2,LOG:12)
B(-6,-5,2,LOG:12)
B(-2,15,-10,Leaves:4)
B(-2,14,-10,Leaves:4)
B(-2,13,-10,Leaves:4)
B(-2,12,-10,Leaves:4)
B(8,5,-7,Leaves:4)
B(9,10,0,Leaves:4)
B(-1,11,-6,LOG:12)
B(-9,12,-1,Leaves:4)
B(8,4,-7,Leaves:4)
B(-1,10,-6,Leaves:4)
B(-9,11,-1,Leaves:4)
B(9,11,0,Leaves:4)
B(-9,14,-1,Leaves:4)
B(-9,13,-1,Leaves:4)
B(1,-5,3,LOG:12)
B(-9,16,-1,Leaves:4)
B(-1,15,-6,Leaves:4)
B(-9,15,-1,Leaves:4)
B(-1,14,-6,Leaves:4)
B(-1,13,-6,Leaves:4)
B(-1,12,-6,LOG:12)
B(-5,10,-4,LOG:12)
B(4,11,6,Leaves:4)
B(4,12,6,Leaves:4)
B(-2,8,0,Leaves:4)
B(-2,9,0,Leaves:4)
B(8,10,-9,Leaves:4)
B(-5,12,-4,LOG:12)
B(4,10,6,Leaves:4)
B(-2,3,0,LOG:12)
B(8,9,-7,Leaves:4)
B(-5,15,-4,Leaves:4)
B(8,8,-7,Leaves:4)
B(-2,4,0,LOG:12)
B(8,11,-9,Leaves:4)
B(-5,16,-4,Leaves:4)
B(8,7,-7,Leaves:4)
B(-9,10,-1,Leaves:4)
B(-5,17,-4,Leaves:4)
B(8,6,-7,Leaves:4)
B(-2,0,0,LOG:12)
B(-2,2,0,LOG:12)
B(-14,12,-1,Leaves:4)
B(3,8,-4,Leaves:4)
B(-14,11,-1,Leaves:4)
B(4,14,6,Leaves:4)
B(4,13,6,Leaves:4)
B(-10,9,-8,Leaves:4)
B(-10,8,-8,Leaves:4)
B(5,10,7,Leaves:4)
B(5,12,7,Leaves:4)
B(5,11,7,Leaves:4)
B(5,14,7,Leaves:4)
B(5,13,7,Leaves:4)
B(5,12,-3,Leaves:4)
B(5,13,-3,Leaves:4)
B(5,14,-3,Leaves:4)
B(5,15,-3,Leaves:4)
B(5,11,-3,Leaves:4)
B(1,9,11,Leaves:4)
B(1,7,11,Leaves:4)
B(1,7,-13,Leaves:4)
B(1,8,11,Leaves:4)
B(1,6,-13,Leaves:4)
B(4,8,0,Leaves:4)
B(1,5,-13,Leaves:4)
B(1,4,-13,Leaves:4)
B(4,7,0,Leaves:4)
B(-6,8,-1,Leaves:4)
B(-17,11,-3,Leaves:4)
B(-6,7,-1,Leaves:4)
B(-17,10,-3,Leaves:4)
B(1,9,-13,Leaves:4)
B(-6,9,-1,Leaves:4)
B(1,12,-2,Leaves:4)
B(1,11,-2,Leaves:4)
B(1,14,-2,Leaves:4)
B(1,13,-2,Leaves:4)
B(4,8,9,Leaves:4)
B(-3,9,-6,LOG:12)
B(4,9,9,Leaves:4)
B(1,15,-2,Leaves:4)
B(-3,6,-6,LOG:12)
B(1,16,-2,Leaves:4)
B(1,17,-2,Leaves:4)
B(-3,8,-6,LOG:12)
B(-7,10,13,Leaves:4)
B(-4,6,-12,Leaves:4)
B(-4,9,4,Leaves:4)
B(-4,5,-12,Leaves:4)
B(-4,8,-12,Leaves:4)
B(-4,7,-12,Leaves:4)
B(-4,9,-12,Leaves:4)
B(-6,10,-14,Leaves:4)
B(-13,7,-13,Leaves:4)
B(-13,6,-13,Leaves:4)
B(-13,5,-13,Leaves:4)
B(-13,4,-13,Leaves:4)
B(-5,-5,-4,LOG:12)
B(-5,-4,-4,LOG:12)
B(2,11,9,Leaves:4)
B(2,12,9,Leaves:4)
B(2,13,9,Leaves:4)
B(-13,8,-2,Leaves:4)
B(-13,9,-2,Leaves:4)
B(3,14,-12,Leaves:4)
B(0,12,7,Leaves:4)
B(0,13,7,Leaves:4)
B(8,13,-2,Leaves:4)
B(0,10,7,Leaves:4)
B(3,13,-12,Leaves:4)
B(0,11,7,Leaves:4)
B(8,12,-2,Leaves:4)
B(8,11,-2,Leaves:4)
B(8,10,-2,Leaves:4)
B(0,14,7,Leaves:4)
B(0,15,7,Leaves:4)
B(3,10,-12,Leaves:4)
B(2,14,9,Leaves:4)
B(-13,6,6,Leaves:4)
B(-12,9,-6,Leaves:4)
B(-13,9,6,Leaves:4)
B(-13,8,6,Leaves:4)
B(-12,8,-6,Leaves:4)
B(-13,7,6,Leaves:4)
B(-12,7,-6,Leaves:4)
B(-2,-4,3,LOG:12)
B(-6,-4,-2,LOG:12)
B(-1,17,-6,Leaves:4)
B(-11,10,-7,Leaves:4)
B(-11,12,-7,Leaves:4)
B(-11,13,-7,Leaves:4)
B(-8,10,14,Leaves:4)
B(-8,9,0,Leaves:4)
B(-3,12,11,Leaves:4)
B(-3,11,11,Leaves:4)
B(2,9,5,Leaves:4)
B(-3,10,11,Leaves:4)
B(2,7,5,Leaves:4)
B(2,8,5,Leaves:4)
B(-11,10,9,Leaves:4)
B(-11,13,9,Leaves:4)
B(-11,14,9,Leaves:4)
B(-5,9,-4,LOG:12)
B(6,12,9,Leaves:4)
B(-6,14,-9,Leaves:4)
B(-6,15,-9,Leaves:4)
B(0,8,10,Leaves:4)
B(0,7,10,Leaves:4)
B(9,12,-6,Leaves:4)
B(9,13,-6,Leaves:4)
B(0,9,10,Leaves:4)
B(-6,11,12,Leaves:4)
B(-6,10,12,Leaves:4)
B(-6,11,-9,Leaves:4)
B(-6,13,-9,Leaves:4)
B(-6,12,-9,Leaves:4)
B(10,8,-9,Leaves:4)
B(-3,10,-10,Leaves:4)
B(7,7,2,Leaves:4)
B(-3,12,-10,Leaves:4)
B(-3,11,-10,Leaves:4)
B(-3,14,-10,Leaves:4)
B(-3,13,-10,Leaves:4)
B(-3,15,-10,Leaves:4)
B(-2,9,-8,Leaves:4)
B(2,15,0,Leaves:4)
B(-9,12,-5,Leaves:4)
B(2,16,0,Leaves:4)
B(-9,11,-5,Leaves:4)
B(-9,14,-5,Leaves:4)
B(2,13,0,Leaves:4)
B(2,14,0,Leaves:4)
B(-9,13,-5,Leaves:4)
B(-17,10,-2,Leaves:4)
B(-17,11,-2,Leaves:4)
B(-17,12,-2,Leaves:4)
B(-2,16,3,Leaves:4)
B(-2,14,3,Leaves:4)
B(6,10,5,Leaves:4)
B(-9,15,-5,Leaves:4)
B(-2,13,3,Leaves:4)
B(6,11,5,Leaves:4)
B(2,12,0,Leaves:4)
B(6,12,5,Leaves:4)
B(-2,12,3,Leaves:4)
B(-2,11,3,Leaves:4)
B(-6,10,-2,Leaves:4)
B(-2,10,3,Leaves:4)
B(-6,14,-2,Leaves:4)
B(-6,13,-2,Leaves:4)
B(-6,12,-2,Leaves:4)
B(-6,11,-2,Leaves:4)
B(-6,18,-2,Leaves:4)
B(-6,17,-2,Leaves:4)
B(-13,7,12,Leaves:4)
B(-6,16,-2,Leaves:4)
B(-6,15,-2,Leaves:4)
B(8,7,-11,Leaves:4)
B(-1,2,-1,LOG:12)
B(-1,3,-1,LOG:12)
B(-1,0,-1,LOG:12)
B(-15,10,3,Leaves:4)
B(9,9,-3,Leaves:4)
B(9,8,-3,Leaves:4)
B(-1,4,-1,LOG:12)
B(9,7,-3,Leaves:4)
B(1,14,-11,Leaves:4)
B(1,10,-9,Leaves:4)
B(1,13,-11,Leaves:4)
B(1,11,-9,Leaves:4)
B(-5,9,7,Leaves:4)
B(1,13,-9,Leaves:4)
B(-1,9,-1,Leaves:4)
B(1,10,-11,Leaves:4)
B(4,11,-5,Leaves:4)
B(4,12,-5,Leaves:4)
B(4,13,-5,Leaves:4)
B(4,14,-5,Leaves:4)
B(9,12,-7,Leaves:4)
B(2,8,7,Leaves:4)
B(-5,17,-5,Leaves:4)
B(2,7,7,Leaves:4)
B(1,7,5,Leaves:4)
B(-5,16,-5,Leaves:4)
B(1,8,5,Leaves:4)
B(9,10,-7,Leaves:4)
B(-5,15,-5,Leaves:4)
B(1,9,5,Leaves:4)
B(9,11,-7,Leaves:4)
B(-5,14,-5,Leaves:4)
B(-5,13,-5,LOG:12)
B(-5,12,-5,LOG:12)
B(-5,11,-5,LOG:12)
B(-14,8,-10,Leaves:4)
B(4,15,-5,Leaves:4)
B(-13,8,-5,Leaves:4)
B(-13,9,-5,Leaves:4)
B(-10,5,9,Leaves:4)
B(-14,7,-10,Leaves:4)
B(-10,9,9,Leaves:4)
B(-12,5,6,Leaves:4)
B(-12,7,6,Leaves:4)
B(-12,6,6,Leaves:4)
B(-12,9,6,Leaves:4)
B(-5,10,-5,Leaves:4)
B(-8,15,-8,Leaves:4)
B(-8,14,-8,Leaves:4)
B(-8,13,-8,Leaves:4)
B(-8,12,-8,Leaves:4)
B(-3,17,1,Leaves:4)
B(-3,16,1,Leaves:4)
B(-3,15,1,Leaves:4)
B(-3,14,1,Leaves:4)
B(-3,13,1,LOG:12)
B(-3,12,1,Leaves:4)
B(-3,11,1,Leaves:4)
B(-3,10,1,Leaves:4)
B(-8,8,-13,Leaves:4)
B(-8,9,-13,Leaves:4)
B(-8,6,-13,Leaves:4)
B(-8,7,-13,Leaves:4)
B(-2,11,-14,Leaves:4)
B(10,9,3,Leaves:4)
B(10,8,3,Leaves:4)
B(10,7,3,Leaves:4)
B(-3,-1,-1,LOG:12)
B(-3,-2,-1,LOG:12)
B(-3,-3,-1,LOG:12)
B(-3,-4,-1,LOG:12)
B(-7,-4,0,LOG:12)
B(-7,-5,0,LOG:12)
B(-3,-5,-1,LOG:12)
B(-8,5,-13,Leaves:4)
B(-14,6,9,Leaves:4)
B(-8,16,-5,Leaves:4)
B(10,7,-5,Leaves:4)
B(-8,17,-5,Leaves:4)
B(10,8,-5,Leaves:4)
B(-8,14,-5,Leaves:4)
B(-12,6,11,Leaves:4)
B(-8,15,-5,Leaves:4)
B(8,12,-7,Leaves:4)
B(-8,13,-5,Leaves:4)
B(-14,7,9,Leaves:4)
B(8,11,-7,Leaves:4)
B(-4,12,-14,Leaves:4)
B(-4,13,-14,Leaves:4)
B(-7,14,10,Leaves:4)
B(-16,7,7,Leaves:4)
B(-7,12,10,Leaves:4)
B(-7,11,10,Leaves:4)
B(-7,10,10,Leaves:4)
B(-16,6,7,Leaves:4)
B(-1,12,10,Leaves:4)
B(1,8,-9,Leaves:4)
B(-1,13,10,Leaves:4)
B(1,9,-9,Leaves:4)
B(-15,7,4,Leaves:4)
B(0,6,-11,Leaves:4)
B(1,9,-2,Leaves:4)
B(0,7,-11,Leaves:4)
B(-13,9,1,Leaves:4)
B(-13,8,1,Leaves:4)
B(0,8,-11,Leaves:4)
B(-8,11,-1,Leaves:4)
B(-8,10,-1,Leaves:4)
B(-7,17,-3,Leaves:4)
B(-1,6,-13,Leaves:4)
B(-1,5,-13,Leaves:4)
B(-7,15,-3,Leaves:4)
B(-5,-5,-5,LOG:12)
B(-1,7,-13,Leaves:4)
B(-7,13,-3,Leaves:4)
B(3,9,-10,Leaves:4)
B(-7,11,-3,Leaves:4)
B(-7,12,-3,Leaves:4)
B(-8,15,-1,Leaves:4)
B(6,12,10,Leaves:4)
B(-8,14,-1,Leaves:4)
B(6,13,10,Leaves:4)
B(-7,10,-3,Leaves:4)
B(-8,13,-1,Leaves:4)
B(-8,12,-1,Leaves:4)
B(-5,6,8,Leaves:4)
B(-5,7,8,Leaves:4)
B(-5,5,8,Leaves:4)
B(3,8,-10,Leaves:4)
B(3,7,-10,Leaves:4)
B(-3,-3,1,LOG:12)
B(-13,5,1,Leaves:4)
B(-3,-4,1,LOG:12)
B(-3,-5,1,LOG:12)
B(3,12,6,Leaves:4)
B(-7,17,0,Leaves:4)
B(-3,17,-1,Leaves:4)
B(3,13,6,Leaves:4)
B(3,14,6,Leaves:4)
B(3,15,6,Leaves:4)
B(-5,9,1,Leaves:4)
B(-7,14,0,Leaves:4)
B(-7,13,0,Leaves:4)
B(-7,16,0,Leaves:4)
B(-8,10,-8,Leaves:4)
B(-7,15,0,Leaves:4)
B(-3,10,-1,Leaves:4)
B(-15,12,-3,Leaves:4)
B(-3,11,-1,Leaves:4)
B(-3,14,-1,Leaves:4)
B(-3,13,-1,Leaves:4)
B(-3,16,-1,Leaves:4)
B(-15,10,-3,Leaves:4)
B(-3,15,-1,Leaves:4)
B(-15,11,-3,Leaves:4)
B(1,11,5,Leaves:4)
B(1,12,5,Leaves:4)
B(1,10,5,Leaves:4)
B(1,15,5,Leaves:4)
B(1,16,5,Leaves:4)
B(0,10,-5,Leaves:4)
B(1,13,5,Leaves:4)
B(1,14,5,Leaves:4)
B(-8,8,3,Leaves:4)
B(-5,9,8,Leaves:4)
B(-5,8,8,Leaves:4)
B(-8,9,3,Leaves:4)
B(0,11,-5,Leaves:4)
B(0,12,-5,LOG:12)
B(0,17,-5,Leaves:4)
B(0,15,-5,Leaves:4)
B(3,11,6,Leaves:4)
B(0,16,-5,Leaves:4)
B(3,10,6,Leaves:4)
B(-6,8,5,Leaves:4)
B(-6,6,5,Leaves:4)
B(7,7,-7,Leaves:4)
B(7,8,-7,Leaves:4)
B(-4,7,-16,Leaves:4)
B(-4,6,-16,Leaves:4)
B(-4,5,-16,Leaves:4)
B(-14,10,0,Leaves:4)
B(12,9,2,Leaves:4)
B(-10,6,-11,Leaves:4)
B(-7,11,0,Leaves:4)
B(-10,9,-11,Leaves:4)
B(-12,10,5,Leaves:4)
B(-10,8,-11,Leaves:4)
B(-10,7,-11,Leaves:4)
B(-7,10,0,Leaves:4)
B(-14,13,0,Leaves:4)
B(-14,12,0,Leaves:4)
B(-14,11,0,Leaves:4)
B(-1,7,2,Leaves:4)
B(-1,8,2,LOG:12)
B(-9,5,6,Leaves:4)
B(-1,9,2,Leaves:4)
B(-7,11,-9,Leaves:4)
B(-7,12,-9,Leaves:4)
B(7,8,-10,Leaves:4)
B(0,9,-5,Leaves:4)
B(0,8,-5,Leaves:4)
B(7,7,-10,Leaves:4)
B(7,9,-10,Leaves:4)
B(-11,10,-2,Leaves:4)
B(-11,13,-2,Leaves:4)
B(-11,14,-2,Leaves:4)
B(-11,11,-2,Leaves:4)
B(-11,12,-2,Leaves:4)
B(9,11,4,Leaves:4)
B(-7,7,6,Leaves:4)
B(-8,10,10,Leaves:4)
B(-7,6,6,Leaves:4)
B(-7,14,-9,Leaves:4)
B(-7,13,-9,Leaves:4)
B(4,6,4,Leaves:4)
B(4,7,4,Leaves:4)
B(2,6,12,Leaves:4)
B(-8,11,10,Leaves:4)
B(4,8,4,Leaves:4)
B(4,9,4,Leaves:4)
B(2,14,3,Leaves:4)
B(-4,14,-8,Leaves:4)
B(2,15,3,Leaves:4)
B(-4,13,-8,Leaves:4)
B(-7,9,6,Leaves:4)
B(2,12,3,Leaves:4)
B(-4,12,-8,LOG:12)
B(2,13,3,Leaves:4)
B(-4,11,-8,Leaves:4)
B(-4,16,3,Leaves:4)
B(-4,10,-8,Leaves:4)
B(2,10,3,Leaves:4)
B(-4,15,3,Leaves:4)
B(2,11,3,Leaves:4)
B(-4,14,3,Leaves:4)
B(-4,13,3,Leaves:4)
B(-2,10,12,Leaves:4)
B(-2,12,12,Leaves:4)
B(-2,11,12,Leaves:4)
B(-5,9,-13,Leaves:4)
B(-5,7,-13,Leaves:4)
B(-5,8,-13,Leaves:4)
B(5,12,2,Leaves:4)
B(5,13,2,Leaves:4)
B(5,14,2,Leaves:4)
B(0,6,4,Leaves:4)
B(0,7,4,Leaves:4)
B(-7,9,-8,Leaves:4)
B(-7,8,-8,Leaves:4)
B(-7,7,-8,Leaves:4)
B(0,8,4,Leaves:4)
B(-9,10,4,Leaves:4)
B(0,9,4,Leaves:4)
B(-9,12,4,Leaves:4)
B(-9,11,4,Leaves:4)
B(-9,14,4,Leaves:4)
B(-9,13,4,Leaves:4)
B(-1,7,12,Leaves:4)
B(-7,6,-8,Leaves:4)
B(-1,9,12,Leaves:4)
B(-10,6,-4,Leaves:4)
B(-4,10,3,Leaves:4)
B(-10,8,-4,Leaves:4)
B(-4,11,3,LOG:12)
B(-4,12,3,Leaves:4)
B(-10,7,-4,Leaves:4)
B(-10,9,-4,Leaves:4)
B(-11,9,-9,Leaves:4)
B(-11,8,-9,Leaves:4)
B(-11,7,-9,Leaves:4)
B(-9,8,6,Leaves:4)
B(-9,9,6,Leaves:4)
B(-9,6,6,Leaves:4)
B(-9,7,6,Leaves:4)
B(6,8,8,Leaves:4)
B(-9,5,11,Leaves:4)
B(3,8,9,Leaves:4)
B(3,9,9,Leaves:4)
B(-8,8,7,Leaves:4)
B(-10,10,-5,Leaves:4)
B(7,11,-4,Leaves:4)
B(-8,9,7,Leaves:4)
B(7,12,-4,Leaves:4)
B(7,13,-4,Leaves:4)
B(-8,6,7,Leaves:4)
B(-8,7,7,Leaves:4)
B(-10,13,-5,Leaves:4)
B(-10,12,-5,Leaves:4)
B(-10,11,-5,Leaves:4)
B(-10,15,-5,Leaves:4)
B(10,11,0,Leaves:4)
B(8,6,2,Leaves:4)
B(8,7,2,Leaves:4)
B(8,8,2,Leaves:4)
B(7,10,-4,Leaves:4)
B(8,9,2,Leaves:4)
B(-8,9,-7,Leaves:4)
B(2,10,-2,Leaves:4)
B(2,11,-2,Leaves:4)
B(2,12,-2,Leaves:4)
B(2,13,-2,Leaves:4)
B(-8,6,-7,Leaves:4)
B(-8,7,-7,Leaves:4)
B(-8,8,-7,Leaves:4)
B(-3,13,-11,Leaves:4)
B(-3,12,-11,Leaves:4)
B(-3,11,-11,Leaves:4)
B(-3,10,-11,Leaves:4)
B(2,15,-2,Leaves:4)
B(2,14,-2,Leaves:4)
B(2,16,-2,Leaves:4)
B(-6,16,-7,Leaves:4)
B(-6,14,-7,Leaves:4)
B(-3,15,-11,Leaves:4)
B(-6,13,-7,Leaves:4)
B(-3,14,-11,Leaves:4)
B(-6,12,-7,Leaves:4)
B(-6,11,-7,Leaves:4)
B(-4,0,-2,LOG:12)
B(-4,1,-2,LOG:12)
B(-3,5,-15,Leaves:4)
B(-3,6,-15,Leaves:4)
B(-14,7,3,Leaves:4)
B(-14,8,3,Leaves:4)
B(-14,9,3,Leaves:4)
B(-3,4,-15,Leaves:4)
B(-8,10,7,Leaves:4)
B(-8,11,7,Leaves:4)
B(-8,12,7,Leaves:4)
B(-4,3,-2,LOG:12)
B(-8,14,7,Leaves:4)
B(-8,15,7,Leaves:4)
B(9,7,1,Leaves:4)
B(9,9,1,Leaves:4)
B(9,8,1,Leaves:4)
B(-5,10,-8,Leaves:4)
B(-5,13,-8,Leaves:4)
B(-5,-4,-2,LOG:12)
B(-5,-5,-2,LOG:12)
B(-5,-2,-2,LOG:12)
B(-5,-3,-2,LOG:12)
B(-5,-1,-2,LOG:12)
B(7,8,7,Leaves:4)
B(7,9,7,Leaves:4)
B(-8,7,-8,Leaves:4)
B(-8,6,-8,Leaves:4)
B(1,11,11,Leaves:4)
B(1,10,11,Leaves:4)
B(1,13,11,Leaves:4)
B(-8,9,-8,Leaves:4)
B(1,12,11,Leaves:4)
B(-8,8,-8,Leaves:4)
B(-2,9,-11,Leaves:4)
B(1,6,12,Leaves:4)
B(-2,8,-11,Leaves:4)
B(1,7,12,Leaves:4)
B(-2,7,-11,Leaves:4)
B(-12,8,-5,Leaves:4)
B(-7,11,11,Leaves:4)
B(-12,9,-5,Leaves:4)
B(1,8,12,Leaves:4)
B(-7,10,11,Leaves:4)
B(-4,-5,-7,LOG:12)
B(-6,9,-9,Leaves:4)
B(-6,6,-9,Leaves:4)
B(-6,5,-9,Leaves:4)
B(-6,8,-9,Leaves:4)
B(-6,7,-9,Leaves:4)
B(-6,4,-9,Leaves:4)
B(-6,-5,-6,LOG:12)
B(-10,14,-4,Leaves:4)
B(-10,12,-4,Leaves:4)
B(-10,10,-4,Leaves:4)
B(-10,11,-4,Leaves:4)
B(-5,15,-8,Leaves:4)
B(-5,14,-8,Leaves:4)
B(-1,10,-14,Leaves:4)
B(-10,6,-5,Leaves:4)
B(-5,11,-12,Leaves:4)
B(-10,7,-5,Leaves:4)
B(-10,4,-5,Leaves:4)
B(-10,5,-5,Leaves:4)
B(-5,10,-12,Leaves:4)
B(-4,6,7,Leaves:4)
B(-4,7,7,Leaves:4)
B(-4,8,7,Leaves:4)
B(-5,8,-3,LOG:12)
B(-10,8,-5,Leaves:4)
B(-10,9,-5,Leaves:4)
B(-5,9,-3,Leaves:4)
B(-4,9,7,Leaves:4)
B(-5,15,-2,Leaves:4)
B(-5,14,-2,LOG:12)
B(-5,12,-2,Leaves:4)
B(-10,3,-5,Leaves:4)
B(-5,11,-2,Leaves:4)
B(8,4,-8,Leaves:4)
B(-5,10,-2,Leaves:4)
B(8,7,-8,Leaves:4)
B(8,8,-8,Leaves:4)
B(8,5,-8,Leaves:4)
B(-5,17,-2,Leaves:4)
B(8,9,-8,Leaves:4)
B(-5,16,-2,Leaves:4)
B(-5,7,-12,Leaves:4)
B(-5,6,-12,Leaves:4)
B(-5,9,-12,Leaves:4)
B(-5,8,-12,Leaves:4)
B(-8,9,11,Leaves:4)
B(-8,8,11,Leaves:4)
B(-1,13,-8,Leaves:4)
B(-1,12,-8,Leaves:4)
B(-1,17,-8,Leaves:4)
B(-2,7,9,Leaves:4)
B(-1,16,-8,Leaves:4)
B(-1,15,-8,Leaves:4)
B(-2,9,9,Leaves:4)
B(-1,14,-8,Leaves:4)
B(-2,8,9,Leaves:4)
B(-7,13,1,Leaves:4)
B(-7,12,1,Leaves:4)
B(-7,11,1,Leaves:4)
B(7,12,-10,Leaves:4)
B(-7,15,1,Leaves:4)
B(-9,6,-14,Leaves:4)
B(-7,16,1,Leaves:4)
B(-2,6,10,Leaves:4)
B(-2,7,10,Leaves:4)
B(7,11,-10,Leaves:4)
B(-9,9,-14,Leaves:4)
B(-9,8,-14,Leaves:4)
B(-11,9,-3,Leaves:4)
B(-11,7,-3,Leaves:4)
B(-11,8,-3,Leaves:4)
B(3,10,1,LOG:12)
B(3,11,1,Leaves:4)
B(3,12,1,Leaves:4)
B(3,13,1,Leaves:4)
B(3,14,1,Leaves:4)
B(3,15,1,Leaves:4)
B(3,16,1,Leaves:4)
B(0,8,11,Leaves:4)
B(6,10,-5,Leaves:4)
B(6,11,-5,Leaves:4)
B(6,12,-5,Leaves:4)
B(-3,0,-1,LOG:12)
B(-3,1,-1,LOG:12)
B(0,7,11,Leaves:4)
B(0,6,11,Leaves:4)
B(5,8,-12,Leaves:4)
B(-4,5,-15,Leaves:4)
B(-4,6,-15,Leaves:4)
B(-4,7,-15,Leaves:4)
B(-3,3,-1,LOG:12)
B(5,9,-4,Leaves:4)
B(-3,2,-1,LOG:12)
B(5,9,-12,Leaves:4)
B(-3,4,-1,LOG:12)
B(6,14,-5,Leaves:4)
B(1,-5,-6,LOG:12)
B(6,13,-5,Leaves:4)
B(-4,8,-15,Leaves:4)
B(-6,8,-10,Leaves:4)
B(-6,9,-10,Leaves:4)
B(-7,9,13,Leaves:4)
B(5,8,7,Leaves:4)
B(-3,9,1,Leaves:4)
B(-4,11,-1,Leaves:4)
B(-4,13,-1,LOG:12)
B(-4,14,-1,Leaves:4)
B(-13,12,1,Leaves:4)
B(-4,15,-1,Leaves:4)
B(-4,16,-1,Leaves:4)
B(-6,9,12,Leaves:4)
B(-13,10,1,Leaves:4)
B(-4,17,-1,Leaves:4)
B(7,12,3,Leaves:4)
B(7,11,3,Leaves:4)
B(7,10,3,Leaves:4)
B(13,8,-1,Leaves:4)
B(3,-5,1,LOG:12)
B(9,10,3,Leaves:4)
B(9,11,3,Leaves:4)
B(9,12,3,Leaves:4)
B(-2,11,-13,Leaves:4)
B(-3,9,-9,Leaves:4)
B(7,14,3,Leaves:4)
B(-9,5,-5,Leaves:4)
B(-1,10,4,Leaves:4)
B(-9,7,-5,Leaves:4)
B(-9,6,-5,Leaves:4)
B(-9,9,-5,Leaves:4)
B(-9,8,-5,Leaves:4)
B(1,11,-6,LOG:12)
B(-11,9,2,Leaves:4)
B(1,12,-6,Leaves:4)
B(1,13,-6,Leaves:4)
B(-6,10,-6,Leaves:4)
B(1,14,-6,Leaves:4)
B(1,15,-6,Leaves:4)
B(1,16,-6,Leaves:4)
B(1,17,-6,Leaves:4)
B(6,14,2,Leaves:4)
B(6,13,2,Leaves:4)
B(6,12,2,Leaves:4)
B(6,11,2,Leaves:4)
B(-7,12,6,Leaves:4)
B(0,12,5,Leaves:4)
B(0,13,5,Leaves:4)
B(-7,11,6,Leaves:4)
B(0,14,5,Leaves:4)
B(0,15,5,Leaves:4)
B(-7,13,6,Leaves:4)
B(-3,12,10,Leaves:4)
B(0,10,5,Leaves:4)
B(-3,13,10,Leaves:4)
B(0,11,5,Leaves:4)
B(-3,10,10,Leaves:4)
B(-3,11,10,Leaves:4)
B(-11,8,2,Leaves:4)
B(-11,5,2,Leaves:4)
B(-11,6,2,Leaves:4)
B(-1,16,4,Leaves:4)
B(-1,11,4,Leaves:4)
B(-1,12,4,Leaves:4)
B(-1,13,4,Leaves:4)
B(-3,11,-13,Leaves:4)
B(-1,14,4,Leaves:4)
B(-4,-3,-1,LOG:12)
B(-12,6,-12,Leaves:4)
B(-4,-2,-1,LOG:12)
B(-12,7,-12,Leaves:4)
B(-12,4,-12,Leaves:4)
B(-4,-5,-1,LOG:12)
B(-12,5,-12,Leaves:4)
B(-4,-4,-1,LOG:12)
B(-1,7,-7,LOG:12)
B(-1,9,-7,Leaves:4)
B(-1,8,-7,LOG:12)
B(-12,3,-12,Leaves:4)
B(-4,-1,-1,LOG:12)
B(-4,14,-7,Leaves:4)
B(-4,15,-7,Leaves:4)
B(-6,13,-8,Leaves:4)
B(-6,14,-8,Leaves:4)
B(-4,12,-7,LOG:12)
B(-4,11,-7,LOG:12)
B(-6,13,-6,Leaves:4)
B(-6,14,-6,Leaves:4)
B(-6,11,-6,Leaves:4)
B(-6,12,-6,Leaves:4)
B(-6,15,-6,Leaves:4)
B(-1,11,-12,Leaves:4)
B(-6,16,-6,Leaves:4)
B(-1,12,-12,Leaves:4)
B(-1,13,-12,Leaves:4)
B(1,17,-4,Leaves:4)
B(-13,9,0,Leaves:4)
B(-11,7,3,Leaves:4)
B(10,11,1,Leaves:4)
B(10,10,1,Leaves:4)
B(-13,8,-4,Leaves:4)
B(-13,9,-4,Leaves:4)
B(1,12,-4,Leaves:4)
B(1,11,-4,Leaves:4)
B(1,10,-4,Leaves:4)
B(1,16,-4,Leaves:4)
B(1,7,4,Leaves:4)
B(1,15,-4,Leaves:4)
B(1,9,4,Leaves:4)
B(-5,6,9,Leaves:4)
B(-5,5,9,Leaves:4)
B(9,9,-10,Leaves:4)
B(9,7,-10,Leaves:4)
B(9,8,-10,Leaves:4)
B(-4,16,1,Leaves:4)
B(-4,15,1,Leaves:4)
B(-4,17,1,Leaves:4)
B(-4,12,1,Leaves:4)
B(-4,15,4,Leaves:4)
B(-4,11,1,Leaves:4)
B(-4,16,4,Leaves:4)
B(-4,14,1,Leaves:4)
B(-4,13,1,LOG:12)
B(-11,8,3,Leaves:4)
B(-11,9,3,Leaves:4)
B(-13,6,0,Leaves:4)
B(-8,12,0,Leaves:4)
B(-8,13,0,Leaves:4)
B(-13,8,0,Leaves:4)
B(-13,7,0,Leaves:4)
B(-8,11,0,Leaves:4)
B(-8,-5,0,LOG:12)
B(-5,8,0,Leaves:4)
B(-5,9,0,Leaves:4)
B(0,16,0,Leaves:4)
B(-3,11,-3,Leaves:4)
B(0,15,0,Leaves:4)
B(-3,17,-3,Leaves:4)
B(0,14,0,Leaves:4)
B(0,13,0,Leaves:4)
B(-3,15,-3,Leaves:4)
B(0,12,0,Leaves:4)
B(-3,16,-3,Leaves:4)
B(10,9,4,Leaves:4)
B(3,13,-14,Leaves:4)
B(-12,7,10,Leaves:4)
B(-12,9,10,Leaves:4)
B(-12,6,10,Leaves:4)
B(-8,8,2,Leaves:4)
B(4,11,11,Leaves:4)
B(-8,7,2,Leaves:4)
B(3,16,-4,Leaves:4)
B(3,15,-4,Leaves:4)
B(-16,6,8,Leaves:4)
B(3,17,-4,Leaves:4)
B(-16,7,8,Leaves:4)
B(3,11,-4,Leaves:4)
B(3,12,-4,Leaves:4)
B(3,13,-4,Leaves:4)
B(3,14,-4,Leaves:4)
B(-15,7,3,Leaves:4)
B(-15,8,3,Leaves:4)
B(13,9,1,Leaves:4)
B(-3,10,-3,Leaves:4)
B(3,10,-4,Leaves:4)
B(0,8,-6,Leaves:4)
B(0,9,-6,Leaves:4)
B(5,8,8,Leaves:4)
B(1,9,-1,Leaves:4)
B(-15,9,-2,Leaves:4)
B(5,9,8,Leaves:4)
B(3,8,-11,Leaves:4)
B(3,9,-11,Leaves:4)
B(2,7,8,Leaves:4)
B(2,8,8,Leaves:4)
B(-1,5,-14,Leaves:4)
B(-1,4,-14,Leaves:4)
B(-1,6,-14,Leaves:4)
B(-12,7,7,Leaves:4)
B(-7,16,-6,Leaves:4)
B(-13,8,9,Leaves:4)
B(-12,8,7,Leaves:4)
B(-7,15,-6,Leaves:4)
B(-7,14,-6,Leaves:4)
B(-7,13,-6,Leaves:4)
B(-7,12,-6,Leaves:4)
B(-7,11,-6,Leaves:4)
B(-7,6,7,Leaves:4)
B(-7,10,-6,LOG:12)
B(-13,7,9,Leaves:4)
B(-13,6,9,Leaves:4)
B(-3,9,3,Leaves:4)
B(-8,9,-14,Leaves:4)
B(-4,12,4,Leaves:4)
B(-8,8,-14,Leaves:4)
B(-4,13,4,Leaves:4)
B(-4,10,4,LOG:12)
B(-4,11,4,Leaves:4)
B(-8,14,0,Leaves:4)
B(-8,15,0,Leaves:4)
B(-8,16,0,Leaves:4)
B(10,8,-6,Leaves:4)
B(10,7,-6,Leaves:4)
B(-5,8,9,Leaves:4)
B(-5,9,9,Leaves:4)
B(5,7,0,Leaves:4)
B(7,4,-6,Leaves:4)
B(5,6,0,Leaves:4)
B(7,5,-6,Leaves:4)
B(7,8,-6,Leaves:4)
B(7,9,-6,Leaves:4)
B(-13,6,-10,Leaves:4)
B(-13,5,-10,Leaves:4)
B(-7,7,-9,Leaves:4)
B(-10,9,-10,Leaves:4)
B(-7,8,-9,Leaves:4)
B(-13,8,-10,Leaves:4)
B(-7,9,-9,Leaves:4)
B(-10,8,-10,Leaves:4)
B(-13,7,-10,Leaves:4)
B(8,12,3,Leaves:4)
B(12,8,1,Leaves:4)
B(-10,7,-10,Leaves:4)
B(9,10,-4,Leaves:4)
B(-10,6,-10,Leaves:4)
B(12,9,1,Leaves:4)
B(-10,5,-10,Leaves:4)
B(9,12,-4,Leaves:4)
B(9,11,-4,Leaves:4)
B(8,11,3,Leaves:4)
B(6,7,7,Leaves:4)
B(-13,10,2,Leaves:4)
B(6,8,7,Leaves:4)
B(-13,11,2,Leaves:4)
B(6,9,7,Leaves:4)
B(-1,7,1,Leaves:4)
B(-1,8,1,Leaves:4)
B(-1,9,1,LOG:12)
B(-13,12,2,Leaves:4)
B(-13,13,2,Leaves:4)
B(-1,3,1,LOG:12)
B(-1,6,1,LOG:12)
B(0,8,-10,Leaves:4)
B(-9,7,12,Leaves:4)
B(0,7,-10,Leaves:4)
B(-6,10,-11,Leaves:4)
B(0,10,4,Leaves:4)
B(-6,12,-11,Leaves:4)
B(0,13,4,Leaves:4)
B(-6,13,-11,Leaves:4)
B(0,14,4,Leaves:4)
B(0,11,4,Leaves:4)
B(0,12,4,Leaves:4)
B(-11,13,8,Leaves:4)
B(-11,12,8,Leaves:4)
B(-11,14,8,Leaves:4)
B(-11,11,8,Leaves:4)
B(-11,10,8,Leaves:4)
B(-9,14,2,Leaves:4)
B(-9,13,2,Leaves:4)
B(-9,15,2,Leaves:4)
B(-7,7,7,Leaves:4)
B(-9,10,2,Leaves:4)
B(-14,12,-4,Leaves:4)
B(-7,9,7,Leaves:4)
B(-14,11,-4,Leaves:4)
B(-9,12,2,Leaves:4)
B(-9,11,2,Leaves:4)
B(0,9,5,Leaves:4)
B(0,7,5,Leaves:4)
B(0,8,5,Leaves:4)
B(6,6,0,leaves:4)
B(-14,7,2,Leaves:4)
B(6,5,0,leaves:4)
B(6,4,0,leaves:4)
B(-14,6,2,Leaves:4)
B(0,6,5,Leaves:4)
B(-14,9,2,Leaves:4)
B(-14,8,2,Leaves:4)
B(-9,7,7,Leaves:4)
B(-9,8,7,Leaves:4)
B(-9,6,7,Leaves:4)
B(3,7,-1,Leaves:4)
B(-9,9,7,Leaves:4)
B(9,6,2,Leaves:4)
B(3,6,-1,Leaves:4)
B(9,8,2,Leaves:4)
B(9,9,2,Leaves:4)
B(-10,8,8,Leaves:4)
B(-10,9,8,Leaves:4)
B(-10,6,8,Leaves:4)
B(-10,7,8,Leaves:4)
B(-10,5,8,Leaves:4)
B(-8,13,6,Leaves:4)
B(-8,12,6,Leaves:4)
B(2,10,-12,Leaves:4)
B(-8,11,12,Leaves:4)
B(-8,10,12,Leaves:4)
B(1,-5,-4,LOG:12)
B(2,12,-12,Leaves:4)
B(2,13,-12,Leaves:4)
B(-8,11,6,Leaves:4)
B(2,14,-12,Leaves:4)
B(-8,10,6,Leaves:4)
B(6,15,7,Leaves:4)
B(0,13,-6,Leaves:4)
B(6,14,7,Leaves:4)
B(0,15,-6,Leaves:4)
B(6,13,7,Leaves:4)
B(0,14,-6,Leaves:4)
B(6,12,7,Leaves:4)
B(0,17,-6,Leaves:4)
B(0,16,-6,Leaves:4)
B(-8,9,6,Leaves:4)
B(0,11,-6,LOG:12)
B(0,10,-6,Leaves:4)
B(4,6,3,Leaves:4)
B(7,10,-8,Leaves:4)
B(1,8,-10,Leaves:4)
B(4,5,3,Leaves:4)
B(1,9,-10,Leaves:4)
B(4,8,3,Leaves:4)
B(4,7,3,Leaves:4)
B(7,13,-8,Leaves:4)
B(7,12,-8,Leaves:4)
B(7,11,-8,Leaves:4)
B(4,9,3,Leaves:4)
B(-13,13,-2,Leaves:4)
B(-13,14,-2,Leaves:4)
B(0,-4,0,LOG:12)
B(-13,11,-2,Leaves:4)
B(-13,12,-2,Leaves:4)
B(-8,6,6,Leaves:4)
B(-13,10,-2,Leaves:4)
B(-3,4,-16,Leaves:4)
B(4,10,4,Leaves:4)
B(-1,10,13,Leaves:4)
B(-4,12,-13,Leaves:4)
B(-4,0,-3,LOG:12)
B(-4,13,-13,Leaves:4)
B(-4,8,-3,LOG:12)
B(-4,4,-3,LOG:12)
B(-4,3,-3,LOG:12)
B(4,13,4,Leaves:4)
B(4,14,4,Leaves:4)
B(2,10,-10,Leaves:4)
B(2,11,-10,Leaves:4)
B(4,11,4,Leaves:4)
B(4,12,4,Leaves:4)
B(2,12,-10,Leaves:4)
B(2,13,-10,Leaves:4)
B(-4,9,-3,LOG:12)
B(4,15,4,Leaves:4)
B(8,6,1,Leaves:4)
B(-3,15,-6,Leaves:4)
B(-3,14,-6,Leaves:4)
B(-4,8,6,Leaves:4)
B(-4,7,6,Leaves:4)
B(-2,10,-12,Leaves:4)
B(8,9,1,Leaves:4)
B(-2,11,-12,Leaves:4)
B(8,8,1,Leaves:4)
B(-4,6,6,Leaves:4)
B(-2,12,-12,Leaves:4)
B(8,7,1,Leaves:4)
B(-4,5,6,Leaves:4)
B(-9,9,-6,LOG:12)
B(-9,7,-6,Leaves:4)
B(-9,8,-6,Leaves:4)
B(-9,5,-6,Leaves:4)
B(11,10,0,Leaves:4)
B(-8,9,-9,Leaves:4)
B(-8,8,-9,Leaves:4)
B(-8,7,-9,Leaves:4)
B(-6,15,9,Leaves:4)
B(-6,14,9,Leaves:4)
B(-6,13,9,Leaves:4)
B(-2,9,11,Leaves:4)
B(-2,8,11,Leaves:4)
B(-12,9,-4,Leaves:4)
B(-2,7,11,Leaves:4)
B(-2,6,11,Leaves:4)
B(-12,8,-4,Leaves:4)
B(-15,11,-4,Leaves:4)
B(-2,9,-10,Leaves:4)
B(-15,12,-4,Leaves:4)
B(-2,8,-10,Leaves:4)
B(-2,7,-10,Leaves:4)
B(-15,10,-4,Leaves:4)
B(-6,12,9,Leaves:4)
B(-6,11,9,Leaves:4)
B(-15,13,-4,Leaves:4)
B(-6,10,9,Leaves:4)
B(-5,10,4,Leaves:4)
B(-5,13,4,Leaves:4)
B(-5,14,4,Leaves:4)
B(-2,6,-10,Leaves:4)
B(-5,11,4,Leaves:4)
B(-5,12,4,Leaves:4)
B(6,14,-3,Leaves:4)
B(11,8,-7,Leaves:4)
B(6,13,-3,Leaves:4)
B(6,12,-3,Leaves:4)
B(6,11,-3,Leaves:4)
B(8,13,0,Leaves:4)
B(6,15,-3,Leaves:4)
B(8,11,0,Leaves:4)
B(-5,16,4,Leaves:4)
B(-5,17,4,Leaves:4)
B(8,10,0,Leaves:4)
B(6,10,-3,Leaves:4)
B(-5,7,-2,Leaves:4)
B(-10,9,-6,Leaves:4)
B(-5,8,-2,Leaves:4)
B(-10,7,-6,Leaves:4)
B(-5,9,-2,Leaves:4)
B(-12,11,-4,Leaves:4)
B(-10,8,-6,Leaves:4)
B(-10,6,-6,Leaves:4)
B(-9,5,8,Leaves:4)
B(-9,7,8,Leaves:4)
B(-3,-5,-6,LOG:12)
B(-9,6,8,Leaves:4)
B(-12,13,-4,Leaves:4)
B(3,8,-2,Leaves:4)
B(-9,8,8,Leaves:4)
B(3,9,-2,Leaves:4)
B(-12,12,-4,Leaves:4)
B(8,8,-9,Leaves:4)
B(8,9,-9,Leaves:4)
B(8,7,-9,Leaves:4)
B(8,4,-9,Leaves:4)
B(-5,0,-2,LOG:12)
B(6,10,-9,Leaves:4)
B(6,12,-9,Leaves:4)
B(6,11,-9,Leaves:4)
B(6,13,-9,Leaves:4)
B(-7,14,-10,Leaves:4)
B(-7,13,-10,Leaves:4)
B(0,14,10,Leaves:4)
B(-5,6,-11,Leaves:4)
B(0,12,10,Leaves:4)
B(-5,8,-11,Leaves:4)
B(-7,10,-10,Leaves:4)
B(0,13,10,Leaves:4)
B(-5,7,-11,Leaves:4)
B(0,10,10,Leaves:4)
B(-7,12,-10,Leaves:4)
B(-7,11,-10,Leaves:4)
B(0,11,10,Leaves:4)
B(4,13,-2,Leaves:4)
B(4,12,-2,Leaves:4)
B(4,15,-2,Leaves:4)
B(4,14,-2,Leaves:4)
B(4,16,-2,Leaves:4)
B(-6,7,-8,Leaves:4)
B(-7,12,-4,Leaves:4)
B(-7,15,-4,Leaves:4)
B(-6,8,-8,LOG:12)
B(-7,14,-4,Leaves:4)
B(-6,9,-8,Leaves:4)
B(-8,16,-3,Leaves:4)
B(7,10,4,Leaves:4)
B(-8,15,-3,Leaves:4)
B(7,13,4,Leaves:4)
B(-8,14,-3,Leaves:4)
B(7,12,4,Leaves:4)
B(-8,11,-3,Leaves:4)
B(-8,10,-3,LOG:12)
B(5,10,-5,Leaves:4)
B(5,11,-5,Leaves:4)
B(5,12,-5,Leaves:4)
B(5,13,-5,Leaves:4)
B(-3,11,-6,LOG:12)
B(-3,10,-6,LOG:12)
B(-3,12,-6,LOG:12)
B(8,7,-1,Leaves:4)
B(8,8,-1,Leaves:4)
B(5,14,-5,Leaves:4)
B(8,9,-1,Leaves:4)
B(4,8,-10,Leaves:4)
B(4,9,-10,Leaves:4)
B(-2,14,5,Leaves:4)
B(-2,13,5,Leaves:4)
B(-2,15,5,Leaves:4)
B(-5,10,-9,Leaves:4)
B(-13,12,-5,Leaves:4)
B(-5,14,-9,Leaves:4)
B(-5,13,-9,Leaves:4)
B(-5,12,-9,Leaves:4)
B(-5,11,-9,Leaves:4)
B(-4,4,-14,Leaves:4)
B(-4,5,-14,Leaves:4)
B(-13,10,-5,Leaves:4)
B(-4,6,-14,Leaves:4)
B(-4,7,-14,Leaves:4)
B(-4,8,-14,Leaves:4)
B(-3,15,3,Leaves:4)
B(6,8,-11,Leaves:4)
B(-2,9,8,Leaves:4)
B(-3,13,3,Leaves:4)
B(-2,7,8,Leaves:4)
B(-3,12,3,LOG:12)
B(-2,8,8,Leaves:4)
B(-2,6,8,Leaves:4)
B(-3,16,3,Leaves:4)
B(-5,15,-9,Leaves:4)
B(-5,16,-9,Leaves:4)
B(-2,11,5,Leaves:4)
B(-2,12,5,Leaves:4)
B(-11,10,0,Leaves:4)
B(-2,10,5,Leaves:4)
B(-11,15,0,Leaves:4)
B(0,-5,-5,LOG:12)
B(-11,14,0,Leaves:4)
B(-11,13,0,Leaves:4)
B(2,9,-10,Leaves:4)
B(2,8,-10,Leaves:4)
B(-11,12,0,Leaves:4)
B(4,7,-10,Leaves:4)
B(-8,7,12,Leaves:4)
B(-8,9,12,Leaves:4)
B(-11,8,-10,Leaves:4)
B(-11,7,-10,Leaves:4)
B(-11,9,-10,Leaves:4)
B(-4,10,11,Leaves:4)
B(-6,9,11,Leaves:4)
B(-4,11,11,Leaves:4)
B(-4,14,11,Leaves:4)
B(-4,15,11,Leaves:4)
B(-4,12,11,Leaves:4)
B(-4,13,11,Leaves:4)
B(-11,6,-10,Leaves:4)
B(-1,7,-8,LOG:12)
B(-3,9,2,LOG:12)
B(-1,8,-8,Leaves:4)
B(-11,5,-10,Leaves:4)
B(-10,10,-3,Leaves:4)
B(-1,16,3,Leaves:4)
B(-1,15,3,Leaves:4)
B(-6,9,4,Leaves:4)
B(-10,11,-3,LOG:12)
B(-1,13,3,Leaves:4)
B(-10,10,4,Leaves:4)
B(-1,12,3,Leaves:4)
B(-1,11,3,Leaves:4)
B(-1,10,3,Leaves:4)
B(-10,14,4,Leaves:4)
B(-10,13,4,Leaves:4)
B(-10,12,4,Leaves:4)
B(-10,11,4,Leaves:4)
B(-10,14,-3,Leaves:4)
B(-10,13,-3,Leaves:4)
B(-10,15,-3,Leaves:4)
B(-9,11,9,Leaves:4)
B(0,15,-4,Leaves:4)
B(0,17,-4,Leaves:4)
B(0,16,-4,Leaves:4)
B(0,11,-4,Leaves:4)
B(0,10,-4,Leaves:4)
B(-11,6,-2,Leaves:4)
B(-11,7,-2,Leaves:4)
B(-11,9,-2,Leaves:4)
B(-11,8,-2,Leaves:4)
B(6,10,-7,Leaves:4)
B(-4,-5,1,LOG:12)
B(0,7,12,Leaves:4)
B(6,13,-7,Leaves:4)
B(6,12,-7,Leaves:4)
B(6,11,-7,Leaves:4)
B(-15,8,2,Leaves:4)
B(-15,7,2,Leaves:4)
B(-4,-3,1,LOG:12)
B(9,10,1,Leaves:4)
B(-4,-4,1,LOG:12)
B(9,12,1,Leaves:4)
B(-15,9,2,Leaves:4)
B(-2,9,2,Leaves:4)
B(9,11,1,Leaves:4)
B(5,9,-5,Leaves:4)
B(10,8,-10,Leaves:4)
B(-16,11,-1,Leaves:4)
B(-16,10,-1,Leaves:4)
B(-3,-4,3,LOG:12)
B(-1,9,-8,LOG:12)
B(8,10,-5,Leaves:4)
B(-12,5,-13,Leaves:4)
B(0,14,-7,Leaves:4)
B(7,8,0,Leaves:4)
B(0,13,-7,Leaves:4)
B(7,7,0,leaves:4)
B(0,16,-7,Leaves:4)
B(-3,11,3,LOG:12)
B(0,15,-7,Leaves:4)
B(-3,10,3,Leaves:4)
B(8,13,-5,Leaves:4)
B(8,12,-5,Leaves:4)
B(8,11,-5,Leaves:4)
B(0,10,-7,Leaves:4)
B(0,12,-7,Leaves:4)
B(7,9,0,Leaves:4)
B(0,11,-7,LOG:12)
B(9,7,-1,Leaves:4)
B(9,5,-1,Leaves:4)
B(9,6,-1,Leaves:4)
B(9,9,-1,Leaves:4)
B(-3,9,-8,Leaves:4)
B(4,10,2,Leaves:4)
B(4,12,2,Leaves:4)
B(-3,7,-8,Leaves:4)
B(4,11,2,Leaves:4)
B(4,14,2,Leaves:4)
B(0,-5,-4,LOG:12)
B(4,13,2,Leaves:4)

#
# +-----------------------------------------------------------------+ #
# |                            BO3 checks                           | #
# +-----------------------------------------------------------------+ #
#

BlockCheck(0,-1,0,grass,dirt)
BlockCheck(0,-2,0,dirt)

#
# +-----------------------------------------------------------------+ #
# |                             Branches                            | #
# +-----------------------------------------------------------------+ #
#

