
#
# +-----------------------------------------------------------------+ #
# |                            BO3 object                           | #
# +-----------------------------------------------------------------+ #
#

Author: NLBlackEagle

Description: Converted version of the BO2 91

Version: 3

SettingsMode: WriteDisable


#
# +-----------------------------------------------------------------+ #
# |                          Main settings                          | #
# +-----------------------------------------------------------------+ #
#

Tree: true

Frequency: 1

Rarity: 2.0

RotateRandomly: true

SpawnHeight: highestSolidBlock

SpawnHeightOffset: 0

SpawnHeightVariance: 0


# Height Limits for the BO3. #


MinHeight: 0

MaxHeight: 199


# Extrusion settings #


ExtrudeMode: None

ExtrudeThroughBlocks: air

MaxBranchDepth: 10

ExcludedBiomes: 


#
# +-----------------------------------------------------------------+ #
# |                      Source block settings                      | #
# +-----------------------------------------------------------------+ #
#

SourceBlocks: AIR,GRASS,DIRT,SAND

MaxPercentageOutsideSourceBlock: 0

OutsideSourceBlock: placeAnyway


#
# +-----------------------------------------------------------------+ #
# |                              Blocks                             | #
# +-----------------------------------------------------------------+ #
#

B(10,43,6,Leaves:4)
B(10,44,6,Leaves:4)
B(10,41,6,Leaves:4)
B(10,42,6,Leaves:4)
B(10,47,6,Leaves:4)
B(10,45,6,Leaves:4)
B(10,46,6,Leaves:4)
B(17,35,-32,Leaves:4)
B(17,34,-32,Leaves:4)
B(17,33,-32,Leaves:4)
B(17,32,-32,Leaves:4)
B(17,31,-32,Leaves:4)
B(10,45,18,Leaves:4)
B(10,30,6,LOG:12)
B(23,47,-17,Leaves:4)
B(10,46,18,Leaves:4)
B(23,40,-17,Leaves:4)
B(10,48,18,Leaves:4)
B(23,41,-17,Leaves:4)
B(10,36,6,Leaves:4)
B(10,37,6,Leaves:4)
B(10,38,6,Leaves:4)
B(10,39,6,Leaves:4)
B(10,41,18,Leaves:4)
B(10,40,18,Leaves:4)
B(10,42,18,Leaves:4)
B(5,47,8,Leaves:4)
B(5,45,8,Leaves:4)
B(5,46,8,Leaves:4)
B(5,43,8,Leaves:4)
B(5,44,8,Leaves:4)
B(5,40,8,Leaves:4)
B(9,34,-24,Leaves:4)
B(14,-2,-4,LOG:12)
B(9,36,-24,Leaves:4)
B(14,-3,-4,LOG:12)
B(10,40,6,Leaves:4)
B(9,35,-24,Leaves:4)
B(14,-4,-4,LOG:12)
B(10,36,18,LOG:12)
B(-5,49,3,Leaves:4)
B(-5,47,3,Leaves:4)
B(-5,48,3,Leaves:4)
B(27,38,-10,Leaves:4)
B(27,39,-10,Leaves:4)
B(-5,50,3,Leaves:4)
B(27,40,-10,Leaves:4)
B(27,44,-10,Leaves:4)
B(27,41,-10,Leaves:4)
B(27,42,-10,Leaves:4)
B(-5,36,3,Leaves:4)
B(-5,37,3,Leaves:4)
B(-5,38,3,Leaves:4)
B(27,46,-10,Leaves:4)
B(40,38,-7,Leaves:4)
B(-5,42,3,Leaves:4)
B(40,37,-7,Leaves:4)
B(-5,41,3,Leaves:4)
B(-5,44,3,Leaves:4)
B(-5,43,3,Leaves:4)
B(-5,46,3,Leaves:4)
B(-5,45,3,Leaves:4)
B(14,35,-4,Leaves:4)
B(14,36,-4,Leaves:4)
B(14,33,-4,Leaves:4)
B(14,34,-4,Leaves:4)
B(-23,39,13,Leaves:4)
B(13,44,13,Leaves:4)
B(13,46,13,Leaves:4)
B(13,47,13,Leaves:4)
B(13,48,13,Leaves:4)
B(13,50,13,Leaves:4)
B(5,38,8,Leaves:4)
B(13,39,13,Leaves:4)
B(23,39,-17,Leaves:4)
B(5,39,8,Leaves:4)
B(13,37,13,Leaves:4)
B(23,38,-17,Leaves:4)
B(23,37,-17,Leaves:4)
B(13,38,13,Leaves:4)
B(18,34,-30,Leaves:4)
B(14,50,-4,Leaves:4)
B(18,36,-30,Leaves:4)
B(14,53,-4,Leaves:4)
B(23,32,-17,Leaves:4)
B(14,54,-4,Leaves:4)
B(23,31,-17,Leaves:4)
B(14,51,-4,Leaves:4)
B(18,32,-30,Leaves:4)
B(14,52,-4,Leaves:4)
B(18,33,-30,Leaves:4)
B(14,57,-4,Leaves:4)
B(23,36,-17,Leaves:4)
B(23,35,-17,Leaves:4)
B(14,55,-4,Leaves:4)
B(23,34,-17,Leaves:4)
B(14,56,-4,Leaves:4)
B(23,33,-17,Leaves:4)
B(-24,45,2,Leaves:4)
B(-24,46,2,Leaves:4)
B(14,49,-4,Leaves:4)
B(13,41,13,Leaves:4)
B(13,40,13,Leaves:4)
B(-24,41,2,Leaves:4)
B(-24,42,2,Leaves:4)
B(-24,43,2,Leaves:4)
B(3,-5,-5,LOG:12)
B(-23,44,13,Leaves:4)
B(3,-3,-5,LOG:12)
B(3,-2,-5,LOG:12)
B(13,22,13,Leaves:4)
B(-23,42,13,Leaves:4)
B(-23,43,13,Leaves:4)
B(-23,40,13,Leaves:4)
B(3,-6,-5,LOG:12)
B(-23,41,13,Leaves:4)
B(14,40,-4,Leaves:4)
B(14,41,-4,Leaves:4)
B(14,42,-4,Leaves:4)
B(14,43,-4,Leaves:4)
B(14,46,-4,Leaves:4)
B(14,47,-4,Leaves:4)
B(14,38,-4,Leaves:4)
B(14,37,-4,Leaves:4)
B(14,39,-4,Leaves:4)
B(24,19,7,Leaves:4)
B(3,-1,-5,LOG:12)
B(-22,37,10,Leaves:4)
B(12,39,18,Leaves:4)
B(-22,39,10,Leaves:4)
B(12,40,18,Leaves:4)
B(12,41,18,Leaves:4)
B(12,44,18,Leaves:4)
B(5,-9,8,LOG:12)
B(5,-8,8,LOG:12)
B(5,-7,8,LOG:12)
B(12,42,18,Leaves:4)
B(5,-6,8,LOG:12)
B(12,43,18,Leaves:4)
B(5,-5,8,LOG:12)
B(5,-4,8,LOG:12)
B(12,46,18,Leaves:4)
B(5,-3,8,LOG:12)
B(12,47,18,Leaves:4)
B(5,-2,8,LOG:12)
B(-22,47,10,Leaves:4)
B(-22,48,10,Leaves:4)
B(-22,49,10,Leaves:4)
B(24,39,7,Leaves:4)
B(24,38,7,Leaves:4)
B(24,37,7,Leaves:4)
B(24,36,7,Leaves:4)
B(24,34,7,Leaves:4)
B(24,44,7,Leaves:4)
B(24,41,7,Leaves:4)
B(-22,41,10,Leaves:4)
B(-22,40,10,Leaves:4)
B(-22,43,10,Leaves:4)
B(-22,42,10,Leaves:4)
B(23,39,-4,Leaves:4)
B(12,17,18,Leaves:4)
B(24,50,7,Leaves:4)
B(24,51,7,Leaves:4)
B(23,41,-4,Leaves:4)
B(23,40,-4,Leaves:4)
B(23,45,-4,Leaves:4)
B(23,44,-4,Leaves:4)
B(23,43,-4,Leaves:4)
B(23,42,-4,Leaves:4)
B(-28,42,4,Leaves:4)
B(23,49,-4,Leaves:4)
B(23,48,-4,Leaves:4)
B(23,47,-4,Leaves:4)
B(23,46,-4,Leaves:4)
B(-26,39,4,Leaves:4)
B(5,44,13,Leaves:4)
B(5,43,13,Leaves:4)
B(5,45,13,Leaves:4)
B(5,48,13,Leaves:4)
B(5,47,13,Leaves:4)
B(23,34,-4,Leaves:4)
B(12,38,18,Leaves:4)
B(23,36,-4,Leaves:4)
B(23,38,-4,Leaves:4)
B(23,37,-4,Leaves:4)
B(-26,41,4,Leaves:4)
B(35,40,-15,Leaves:4)
B(-26,40,4,Leaves:4)
B(4,-8,2,LOG:12)
B(4,-7,2,LOG:12)
B(4,-6,2,LOG:12)
B(4,-5,2,LOG:12)
B(4,-4,2,LOG:12)
B(4,-3,2,LOG:12)
B(4,-2,2,LOG:12)
B(4,-1,2,LOG:12)
B(10,29,6,LOG:12)
B(10,20,6,Leaves:4)
B(10,21,6,Leaves:4)
B(9,45,8,Leaves:4)
B(9,46,8,Leaves:4)
B(9,40,8,Leaves:4)
B(9,43,8,Leaves:4)
B(9,41,8,Leaves:4)
B(9,42,8,Leaves:4)
B(10,19,6,Leaves:4)
B(10,18,6,Leaves:4)
B(10,17,6,Leaves:4)
B(10,16,6,Leaves:4)
B(10,15,6,Leaves:4)
B(17,28,-16,LOG:12)
B(17,29,-16,LOG:12)
B(-17,32,-7,Leaves:4)
B(-17,33,-7,Leaves:4)
B(-17,34,-7,Leaves:4)
B(-17,35,-7,Leaves:4)
B(-17,36,-7,Leaves:4)
B(-17,37,-7,Leaves:4)
B(17,30,-16,LOG:12)
B(17,31,-16,LOG:12)
B(9,29,8,LOG:12)
B(-17,31,-7,Leaves:4)
B(-10,35,10,LOG:12)
B(-10,34,10,LOG:12)
B(9,33,8,LOG:12)
B(9,32,8,LOG:12)
B(9,31,8,LOG:12)
B(9,30,8,LOG:12)
B(9,37,8,Leaves:4)
B(-10,38,10,Leaves:4)
B(-10,39,10,Leaves:4)
B(9,39,8,Leaves:4)
B(-10,37,10,Leaves:4)
B(9,38,8,Leaves:4)
B(7,46,-7,Leaves:4)
B(5,36,-8,Leaves:4)
B(-9,29,-9,LOG:12)
B(-9,28,-9,LOG:12)
B(-9,27,-9,LOG:12)
B(6,39,25,Leaves:4)
B(-9,26,-9,LOG:12)
B(-9,25,-9,LOG:12)
B(-9,40,-9,Leaves:4)
B(-9,41,-9,Leaves:4)
B(5,40,-8,Leaves:4)
B(-9,42,-9,Leaves:4)
B(5,41,-8,Leaves:4)
B(-9,43,-9,Leaves:4)
B(5,-7,13,LOG:12)
B(5,-6,13,LOG:12)
B(5,42,-8,Leaves:4)
B(5,-5,13,LOG:12)
B(5,-4,13,LOG:12)
B(9,19,8,Leaves:4)
B(-9,38,-9,Leaves:4)
B(-9,37,-9,Leaves:4)
B(9,17,8,Leaves:4)
B(9,16,8,Leaves:4)
B(-9,39,-9,Leaves:4)
B(13,21,7,Leaves:4)
B(13,22,7,Leaves:4)
B(13,20,7,Leaves:4)
B(-9,50,-9,Leaves:4)
B(-1,15,-2,LOG:12)
B(-1,19,-2,LOG:12)
B(-1,18,-2,LOG:12)
B(-1,17,-2,LOG:12)
B(-9,51,-9,Leaves:4)
B(-9,46,-9,Leaves:4)
B(10,19,-10,LOG:12)
B(-9,47,-9,Leaves:4)
B(-9,44,-9,Leaves:4)
B(-9,45,-9,Leaves:4)
B(-1,21,-2,LOG:12)
B(-1,22,-2,LOG:12)
B(-9,48,-9,Leaves:4)
B(-1,20,-2,LOG:12)
B(-12,41,11,Leaves:4)
B(-12,40,11,Leaves:4)
B(13,19,7,Leaves:4)
B(-12,43,11,Leaves:4)
B(13,18,7,Leaves:4)
B(-12,42,11,Leaves:4)
B(13,17,7,Leaves:4)
B(-12,44,11,Leaves:4)
B(13,16,7,Leaves:4)
B(-12,37,11,Leaves:4)
B(-12,38,11,Leaves:4)
B(6,40,25,Leaves:4)
B(-12,36,11,Leaves:4)
B(5,39,21,Leaves:4)
B(5,38,21,Leaves:4)
B(-12,39,11,Leaves:4)
B(5,34,13,Leaves:4)
B(5,35,13,Leaves:4)
B(10,34,12,LOG:12)
B(6,45,25,Leaves:4)
B(6,46,25,Leaves:4)
B(6,47,25,Leaves:4)
B(6,48,25,Leaves:4)
B(6,41,25,Leaves:4)
B(6,42,25,Leaves:4)
B(6,43,25,Leaves:4)
B(6,44,25,Leaves:4)
B(5,47,21,Leaves:4)
B(-19,41,-14,Leaves:4)
B(5,46,21,Leaves:4)
B(5,49,21,Leaves:4)
B(13,41,7,Leaves:4)
B(5,48,21,Leaves:4)
B(13,42,7,Leaves:4)
B(3,34,17,Leaves:4)
B(3,35,17,Leaves:4)
B(13,40,7,Leaves:4)
B(3,32,17,Leaves:4)
B(3,33,17,Leaves:4)
B(-10,40,10,Leaves:4)
B(-10,41,10,Leaves:4)
B(5,41,21,Leaves:4)
B(17,46,-16,Leaves:4)
B(-1,38,-2,Leaves:4)
B(5,40,21,Leaves:4)
B(5,43,21,Leaves:4)
B(-1,36,-2,Leaves:4)
B(5,42,21,Leaves:4)
B(5,45,21,Leaves:4)
B(-1,35,-2,Leaves:4)
B(3,37,17,Leaves:4)
B(3,36,17,Leaves:4)
B(-19,40,-14,Leaves:4)
B(13,53,7,Leaves:4)
B(16,21,17,Leaves:4)
B(13,51,7,Leaves:4)
B(5,52,21,Leaves:4)
B(17,36,-16,Leaves:4)
B(5,51,21,Leaves:4)
B(5,50,21,Leaves:4)
B(17,39,-16,Leaves:4)
B(17,38,-16,Leaves:4)
B(17,37,-16,Leaves:4)
B(-19,31,-12,Leaves:4)
B(-19,32,-12,Leaves:4)
B(17,42,-16,Leaves:4)
B(17,43,-16,Leaves:4)
B(17,40,-16,Leaves:4)
B(-19,35,-12,Leaves:4)
B(16,18,17,Leaves:4)
B(16,19,17,Leaves:4)
B(8,34,-27,Leaves:4)
B(8,33,-27,Leaves:4)
B(8,32,-27,Leaves:4)
B(8,39,-27,Leaves:4)
B(-13,42,-6,Leaves:4)
B(8,37,-27,Leaves:4)
B(-13,41,-6,Leaves:4)
B(3,50,17,Leaves:4)
B(8,38,-27,Leaves:4)
B(8,35,-27,Leaves:4)
B(8,36,-27,Leaves:4)
B(13,21,13,Leaves:4)
B(25,40,2,Leaves:4)
B(3,47,17,Leaves:4)
B(3,48,17,Leaves:4)
B(10,47,-10,Leaves:4)
B(-22,38,-8,Leaves:4)
B(-22,35,-8,Leaves:4)
B(10,44,-10,Leaves:4)
B(10,43,-10,Leaves:4)
B(10,46,-10,Leaves:4)
B(10,45,-10,Leaves:4)
B(10,40,-10,Leaves:4)
B(13,19,13,Leaves:4)
B(10,42,-10,Leaves:4)
B(10,41,-10,Leaves:4)
B(3,46,17,Leaves:4)
B(13,16,13,Leaves:4)
B(3,45,17,Leaves:4)
B(13,18,13,Leaves:4)
B(13,17,13,Leaves:4)
B(25,35,2,LOG:12)
B(25,34,2,LOG:12)
B(10,39,-10,Leaves:4)
B(10,36,-10,Leaves:4)
B(10,37,-10,Leaves:4)
B(10,35,-10,Leaves:4)
B(10,34,-10,Leaves:4)
B(10,33,-10,Leaves:4)
B(10,32,-10,Leaves:4)
B(10,20,-10,LOG:12)
B(10,22,-10,LOG:12)
B(10,21,-10,LOG:12)
B(5,44,-23,Leaves:4)
B(0,33,-34,Leaves:4)
B(3,36,-5,Leaves:4)
B(23,36,-34,Leaves:4)
B(6,36,17,Leaves:4)
B(27,-7,-10,LOG:12)
B(33,37,0,Leaves:4)
B(33,34,0,Leaves:4)
B(33,36,0,Leaves:4)
B(33,32,0,Leaves:4)
B(10,-8,18,LOG:12)
B(-6,41,-23,Leaves:4)
B(10,-7,18,LOG:12)
B(-6,42,-23,Leaves:4)
B(10,-6,18,LOG:12)
B(10,-5,18,LOG:12)
B(-6,40,-23,Leaves:4)
B(32,39,0,Leaves:4)
B(6,48,17,Leaves:4)
B(6,49,17,Leaves:4)
B(6,46,17,Leaves:4)
B(6,47,17,Leaves:4)
B(25,32,-35,Leaves:4)
B(25,33,-35,Leaves:4)
B(6,45,17,Leaves:4)
B(25,34,-35,Leaves:4)
B(33,47,0,Leaves:4)
B(33,45,0,Leaves:4)
B(6,41,17,Leaves:4)
B(6,40,17,Leaves:4)
B(33,48,0,Leaves:4)
B(-6,38,-23,Leaves:4)
B(-6,36,-23,Leaves:4)
B(-6,35,-23,Leaves:4)
B(33,43,0,Leaves:4)
B(-6,34,-23,Leaves:4)
B(-6,33,-23,Leaves:4)
B(32,46,0,Leaves:4)
B(32,45,0,Leaves:4)
B(32,44,0,Leaves:4)
B(32,43,0,Leaves:4)
B(4,0,-5,Leaves:4)
B(32,49,0,Leaves:4)
B(4,1,-5,Leaves:4)
B(32,48,0,Leaves:4)
B(3,47,-5,Leaves:4)
B(3,46,-5,Leaves:4)
B(32,40,0,Leaves:4)
B(-13,33,-6,Leaves:4)
B(-13,34,-6,Leaves:4)
B(-13,35,-6,Leaves:4)
B(-6,47,-23,Leaves:4)
B(-13,36,-6,Leaves:4)
B(-13,37,-6,Leaves:4)
B(-13,38,-6,Leaves:4)
B(-6,44,-23,Leaves:4)
B(-6,43,-23,Leaves:4)
B(-6,46,-23,Leaves:4)
B(-6,45,-23,Leaves:4)
B(8,17,9,Leaves:4)
B(16,21,10,Leaves:4)
B(16,20,10,Leaves:4)
B(-5,31,1,Leaves:4)
B(21,29,-19,Leaves:4)
B(-5,32,1,Leaves:4)
B(4,35,-20,Leaves:4)
B(4,36,-20,Leaves:4)
B(4,37,-20,Leaves:4)
B(21,31,-19,Leaves:4)
B(27,39,-13,Leaves:4)
B(21,32,-19,Leaves:4)
B(21,33,-19,Leaves:4)
B(21,34,-19,Leaves:4)
B(21,35,-19,Leaves:4)
B(21,36,-19,Leaves:4)
B(21,37,-19,Leaves:4)
B(21,38,-19,Leaves:4)
B(21,39,-19,Leaves:4)
B(16,19,10,Leaves:4)
B(-5,47,1,Leaves:4)
B(-7,39,-29,Leaves:4)
B(-5,49,1,Leaves:4)
B(-8,46,-15,Leaves:4)
B(-8,45,-15,Leaves:4)
B(-8,44,-15,Leaves:4)
B(26,40,7,Leaves:4)
B(-8,43,-15,Leaves:4)
B(-8,42,-15,Leaves:4)
B(-8,41,-15,Leaves:4)
B(26,42,7,Leaves:4)
B(26,41,7,Leaves:4)
B(16,43,10,Leaves:4)
B(16,44,10,Leaves:4)
B(26,36,7,Leaves:4)
B(-7,40,-29,Leaves:4)
B(26,37,7,Leaves:4)
B(-7,41,-29,Leaves:4)
B(-8,37,-15,Leaves:4)
B(26,38,7,Leaves:4)
B(16,41,10,Leaves:4)
B(26,39,7,Leaves:4)
B(16,40,10,Leaves:4)
B(-7,42,-29,Leaves:4)
B(-7,43,-29,Leaves:4)
B(16,47,10,Leaves:4)
B(16,49,10,Leaves:4)
B(16,48,10,Leaves:4)
B(-5,36,1,Leaves:4)
B(-5,37,1,Leaves:4)
B(-5,34,1,Leaves:4)
B(7,48,14,Leaves:4)
B(-5,39,1,Leaves:4)
B(7,45,14,Leaves:4)
B(26,35,7,Leaves:4)
B(7,44,14,Leaves:4)
B(26,34,7,Leaves:4)
B(7,47,14,Leaves:4)
B(26,33,7,Leaves:4)
B(7,46,14,Leaves:4)
B(26,32,7,Leaves:4)
B(14,51,10,Leaves:4)
B(14,52,10,Leaves:4)
B(14,54,10,Leaves:4)
B(-8,48,-15,Leaves:4)
B(-11,41,22,Leaves:4)
B(-5,40,1,Leaves:4)
B(16,39,10,Leaves:4)
B(16,38,10,Leaves:4)
B(-5,44,1,Leaves:4)
B(-27,38,9,Leaves:4)
B(-5,42,1,Leaves:4)
B(-7,38,-29,Leaves:4)
B(-27,39,9,Leaves:4)
B(-5,41,1,Leaves:4)
B(14,50,10,Leaves:4)
B(7,-7,14,LOG:12)
B(7,-8,14,LOG:12)
B(7,-5,14,Leaves:4)
B(7,-6,14,LOG:12)
B(3,36,-23,Leaves:4)
B(3,37,-23,Leaves:4)
B(3,38,-23,Leaves:4)
B(14,48,10,Leaves:4)
B(3,39,-23,Leaves:4)
B(14,45,10,Leaves:4)
B(14,44,10,Leaves:4)
B(14,43,10,Leaves:4)
B(14,42,10,Leaves:4)
B(14,41,10,Leaves:4)
B(14,40,10,Leaves:4)
B(26,52,7,Leaves:4)
B(26,53,7,Leaves:4)
B(8,42,9,Leaves:4)
B(25,49,2,Leaves:4)
B(8,43,9,Leaves:4)
B(16,31,-17,Leaves:4)
B(25,43,2,Leaves:4)
B(25,44,2,Leaves:4)
B(25,41,2,Leaves:4)
B(16,30,-17,Leaves:4)
B(25,42,2,Leaves:4)
B(25,47,2,Leaves:4)
B(8,45,9,Leaves:4)
B(25,48,2,Leaves:4)
B(8,46,9,Leaves:4)
B(25,45,2,Leaves:4)
B(8,48,9,Leaves:4)
B(25,46,2,Leaves:4)
B(14,38,10,Leaves:4)
B(25,50,2,Leaves:4)
B(14,37,10,Leaves:4)
B(14,39,10,Leaves:4)
B(20,-9,-9,LOG:12)
B(20,-8,-9,LOG:12)
B(20,-7,-9,LOG:12)
B(8,32,9,LOG:12)
B(20,-6,-9,LOG:12)
B(8,33,9,LOG:12)
B(20,-5,-9,LOG:12)
B(20,-4,-9,LOG:12)
B(20,-3,-9,LOG:12)
B(8,31,9,LOG:12)
B(8,36,9,Leaves:4)
B(20,-2,-9,LOG:12)
B(20,-1,-9,LOG:12)
B(8,34,9,LOG:12)
B(27,47,-13,Leaves:4)
B(27,46,-13,Leaves:4)
B(27,45,-13,Leaves:4)
B(27,44,-13,Leaves:4)
B(-10,42,-7,Leaves:4)
B(27,43,-13,Leaves:4)
B(27,42,-13,Leaves:4)
B(27,41,-13,Leaves:4)
B(-10,44,-7,Leaves:4)
B(27,40,-13,Leaves:4)
B(14,21,10,Leaves:4)
B(14,20,10,Leaves:4)
B(21,44,-19,Leaves:4)
B(21,43,-19,Leaves:4)
B(21,42,-19,Leaves:4)
B(21,41,-19,Leaves:4)
B(21,40,-19,Leaves:4)
B(-10,41,-7,Leaves:4)
B(-10,40,-7,Leaves:4)
B(-10,37,-7,Leaves:4)
B(14,16,10,Leaves:4)
B(-10,38,-7,Leaves:4)
B(14,18,10,Leaves:4)
B(-10,36,-7,Leaves:4)
B(14,17,10,Leaves:4)
B(-10,33,-7,Leaves:4)
B(14,19,10,Leaves:4)
B(-10,31,-7,LOG:12)
B(3,41,-23,Leaves:4)
B(3,42,-23,Leaves:4)
B(-10,39,-7,Leaves:4)
B(3,40,-23,Leaves:4)
B(3,34,10,Leaves:4)
B(-10,29,-7,LOG:12)
B(-10,28,-7,LOG:12)
B(-4,34,-18,Leaves:4)
B(-4,35,-18,Leaves:4)
B(-23,40,7,Leaves:4)
B(13,19,-6,LOG:12)
B(1,-3,0,LOG:12)
B(-10,27,-7,LOG:12)
B(3,37,10,Leaves:4)
B(3,38,10,Leaves:4)
B(3,39,10,Leaves:4)
B(-20,34,-11,Leaves:4)
B(-20,33,-11,Leaves:4)
B(-20,36,-11,Leaves:4)
B(-20,37,-11,Leaves:4)
B(-10,30,-7,LOG:12)
B(20,38,-9,Leaves:4)
B(10,48,12,Leaves:4)
B(20,39,-9,Leaves:4)
B(10,46,12,Leaves:4)
B(-23,42,7,Leaves:4)
B(10,47,12,Leaves:4)
B(3,46,10,Leaves:4)
B(-4,40,-18,Leaves:4)
B(3,44,10,Leaves:4)
B(-4,41,-18,Leaves:4)
B(3,45,10,Leaves:4)
B(-4,42,-18,Leaves:4)
B(3,42,10,Leaves:4)
B(-4,43,-18,Leaves:4)
B(3,43,10,Leaves:4)
B(-4,45,-18,Leaves:4)
B(3,40,10,Leaves:4)
B(3,41,10,Leaves:4)
B(20,27,-9,LOG:12)
B(13,37,-6,Leaves:4)
B(-4,37,-18,Leaves:4)
B(10,35,12,LOG:12)
B(-4,36,-18,Leaves:4)
B(20,28,-9,LOG:12)
B(-4,39,-18,Leaves:4)
B(-4,38,-18,Leaves:4)
B(13,38,-6,Leaves:4)
B(12,17,1,Leaves:4)
B(-1,43,11,Leaves:4)
B(-1,42,11,Leaves:4)
B(-14,43,-26,Leaves:4)
B(-14,40,-26,Leaves:4)
B(-1,45,11,Leaves:4)
B(-1,44,11,Leaves:4)
B(16,35,-17,Leaves:4)
B(-15,43,13,Leaves:4)
B(-15,44,13,Leaves:4)
B(16,36,-17,Leaves:4)
B(16,33,-17,Leaves:4)
B(-9,40,-12,Leaves:4)
B(-15,41,13,Leaves:4)
B(16,34,-17,Leaves:4)
B(-15,42,13,Leaves:4)
B(16,39,-17,Leaves:4)
B(-9,42,-12,Leaves:4)
B(-9,43,-12,Leaves:4)
B(16,37,-17,Leaves:4)
B(-9,45,-12,Leaves:4)
B(16,38,-17,Leaves:4)
B(-15,48,13,Leaves:4)
B(-7,45,-8,Leaves:4)
B(13,42,-6,Leaves:4)
B(16,43,-17,Leaves:4)
B(-15,47,13,Leaves:4)
B(-7,46,-8,Leaves:4)
B(16,42,-17,Leaves:4)
B(-7,47,-8,Leaves:4)
B(-15,46,13,Leaves:4)
B(16,41,-17,Leaves:4)
B(-15,45,13,Leaves:4)
B(16,40,-17,Leaves:4)
B(13,48,-6,Leaves:4)
B(13,47,-6,Leaves:4)
B(-4,47,-18,Leaves:4)
B(27,32,-38,Leaves:4)
B(-9,51,-12,Leaves:4)
B(16,44,-17,Leaves:4)
B(-7,44,-8,Leaves:4)
B(-9,52,-12,Leaves:4)
B(16,45,-17,Leaves:4)
B(-14,38,-26,Leaves:4)
B(-7,43,-8,Leaves:4)
B(16,46,-17,Leaves:4)
B(-7,42,-8,Leaves:4)
B(16,47,-17,Leaves:4)
B(-7,41,-8,Leaves:4)
B(-7,40,-8,Leaves:4)
B(-9,49,-12,Leaves:4)
B(12,32,1,Leaves:4)
B(-9,48,-12,Leaves:4)
B(-15,38,13,Leaves:4)
B(-9,47,-12,Leaves:4)
B(12,34,1,Leaves:4)
B(-7,38,-8,Leaves:4)
B(-9,46,-12,Leaves:4)
B(12,33,1,Leaves:4)
B(-7,39,-8,Leaves:4)
B(-23,39,7,Leaves:4)
B(-7,37,-8,Leaves:4)
B(-23,38,7,Leaves:4)
B(13,55,-6,Leaves:4)
B(-23,35,7,Leaves:4)
B(-23,34,7,Leaves:4)
B(12,39,1,Leaves:4)
B(-23,37,7,Leaves:4)
B(-23,36,7,Leaves:4)
B(12,38,1,Leaves:4)
B(12,37,1,Leaves:4)
B(1,18,0,LOG:12)
B(1,19,0,LOG:12)
B(1,16,0,LOG:12)
B(1,17,0,LOG:12)
B(1,14,0,LOG:12)
B(8,-6,9,LOG:12)
B(1,15,0,LOG:12)
B(1,12,0,LOG:12)
B(1,13,0,LOG:12)
B(-6,37,14,Leaves:4)
B(12,47,1,Leaves:4)
B(-6,39,14,Leaves:4)
B(-7,24,-8,LOG:12)
B(12,40,1,Leaves:4)
B(8,-3,9,Leaves:4)
B(-27,40,9,Leaves:4)
B(12,41,1,Leaves:4)
B(8,-4,9,Leaves:4)
B(-7,26,-8,LOG:12)
B(-27,41,9,Leaves:4)
B(-7,25,-8,LOG:12)
B(-27,42,9,Leaves:4)
B(-6,31,14,LOG:12)
B(12,44,1,Leaves:4)
B(12,45,1,Leaves:4)
B(-6,32,14,LOG:12)
B(-7,27,-8,LOG:12)
B(12,42,1,Leaves:4)
B(12,43,1,Leaves:4)
B(-1,37,11,Leaves:4)
B(-1,33,11,Leaves:4)
B(16,50,10,Leaves:4)
B(16,51,10,Leaves:4)
B(16,52,10,Leaves:4)
B(-1,36,11,Leaves:4)
B(16,53,10,Leaves:4)
B(-1,32,11,Leaves:4)
B(-6,40,14,Leaves:4)
B(-6,41,14,Leaves:4)
B(-6,44,14,Leaves:4)
B(-6,42,14,Leaves:4)
B(-6,43,14,Leaves:4)
B(1,36,0,Leaves:4)
B(1,37,0,Leaves:4)
B(1,34,0,Leaves:4)
B(1,35,0,Leaves:4)
B(7,38,-7,Leaves:4)
B(7,37,-7,Leaves:4)
B(7,36,-7,Leaves:4)
B(-20,38,-7,Leaves:4)
B(-20,39,-7,Leaves:4)
B(-20,36,-7,Leaves:4)
B(-20,37,-7,Leaves:4)
B(-20,34,-7,Leaves:4)
B(-20,35,-7,Leaves:4)
B(-20,32,-7,Leaves:4)
B(-20,33,-7,Leaves:4)
B(-20,40,-7,Leaves:4)
B(4,46,-20,Leaves:4)
B(7,35,-7,Leaves:4)
B(7,32,-7,LOG:12)
B(7,30,-7,LOG:12)
B(7,31,-7,LOG:12)
B(1,23,0,LOG:12)
B(7,29,-7,LOG:12)
B(20,41,-9,Leaves:4)
B(1,20,0,LOG:12)
B(1,21,0,LOG:12)
B(1,22,0,LOG:12)
B(20,48,-9,Leaves:4)
B(20,46,-9,Leaves:4)
B(20,45,-9,Leaves:4)
B(20,44,-9,Leaves:4)
B(20,43,-9,Leaves:4)
B(20,42,-9,Leaves:4)
B(18,43,-25,Leaves:4)
B(29,56,-5,Leaves:4)
B(1,42,0,Leaves:4)
B(1,41,0,Leaves:4)
B(1,48,0,Leaves:4)
B(1,47,0,Leaves:4)
B(1,49,0,Leaves:4)
B(18,35,-25,Leaves:4)
B(18,34,-25,Leaves:4)
B(18,33,-25,Leaves:4)
B(2,34,-26,Leaves:4)
B(18,39,-25,Leaves:4)
B(18,38,-25,Leaves:4)
B(18,37,-25,Leaves:4)
B(31,38,7,Leaves:4)
B(18,36,-25,Leaves:4)
B(31,39,7,Leaves:4)
B(31,36,7,Leaves:4)
B(2,37,-26,Leaves:4)
B(31,40,7,Leaves:4)
B(1,51,0,Leaves:4)
B(1,50,0,Leaves:4)
B(-3,40,15,Leaves:4)
B(-4,40,-2,Leaves:4)
B(-4,41,-2,Leaves:4)
B(-4,36,-2,Leaves:4)
B(-4,35,-2,Leaves:4)
B(-4,38,-2,Leaves:4)
B(-4,37,-2,Leaves:4)
B(-4,32,-2,Leaves:4)
B(-4,34,-2,Leaves:4)
B(-4,33,-2,Leaves:4)
B(-3,39,15,Leaves:4)
B(39,38,-5,Leaves:4)
B(-4,39,-2,Leaves:4)
B(-4,43,-2,Leaves:4)
B(-4,42,-2,Leaves:4)
B(12,-5,1,LOG:12)
B(12,-6,1,LOG:12)
B(12,-3,1,LOG:12)
B(12,-4,1,LOG:12)
B(12,-2,1,LOG:12)
B(33,36,-5,Leaves:4)
B(33,39,-5,Leaves:4)
B(-7,39,-2,Leaves:4)
B(-7,38,-2,Leaves:4)
B(-7,37,-2,Leaves:4)
B(33,37,-5,Leaves:4)
B(-7,36,-2,Leaves:4)
B(33,38,-5,Leaves:4)
B(-7,35,-2,Leaves:4)
B(-7,34,-2,Leaves:4)
B(-7,33,-2,Leaves:4)
B(-7,32,-2,Leaves:4)
B(-7,31,-2,Leaves:4)
B(12,-7,1,LOG:12)
B(-3,43,15,Leaves:4)
B(-3,44,15,Leaves:4)
B(-3,45,15,Leaves:4)
B(-7,44,-2,Leaves:4)
B(-7,43,-2,Leaves:4)
B(-7,45,-2,Leaves:4)
B(33,40,-5,Leaves:4)
B(22,29,-19,Leaves:4)
B(33,41,-5,Leaves:4)
B(33,42,-5,Leaves:4)
B(-7,42,-2,Leaves:4)
B(-7,41,-2,Leaves:4)
B(29,42,-5,Leaves:4)
B(29,41,-5,Leaves:4)
B(29,40,-5,Leaves:4)
B(3,-9,10,LOG:12)
B(2,40,-26,Leaves:4)
B(22,40,-19,Leaves:4)
B(22,31,-19,Leaves:4)
B(22,33,-19,Leaves:4)
B(22,32,-19,Leaves:4)
B(22,35,-19,Leaves:4)
B(22,34,-19,Leaves:4)
B(22,37,-19,Leaves:4)
B(22,36,-19,Leaves:4)
B(22,39,-19,Leaves:4)
B(22,38,-19,Leaves:4)
B(29,39,-5,Leaves:4)
B(29,55,-5,Leaves:4)
B(29,54,-5,Leaves:4)
B(29,50,-5,Leaves:4)
B(-19,36,-10,Leaves:4)
B(3,-8,10,LOG:12)
B(-19,37,-10,Leaves:4)
B(3,-7,10,LOG:12)
B(-19,34,-10,Leaves:4)
B(3,-6,10,LOG:12)
B(22,42,-19,Leaves:4)
B(-19,35,-10,Leaves:4)
B(3,-5,10,LOG:12)
B(22,41,-19,Leaves:4)
B(29,49,-5,Leaves:4)
B(29,45,-5,Leaves:4)
B(-19,32,-10,Leaves:4)
B(-19,33,-10,Leaves:4)
B(29,48,-5,Leaves:4)
B(16,37,8,Leaves:4)
B(16,20,8,Leaves:4)
B(16,21,8,Leaves:4)
B(16,23,8,Leaves:4)
B(16,24,8,Leaves:4)
B(-10,39,-29,Leaves:4)
B(16,16,8,Leaves:4)
B(16,19,8,Leaves:4)
B(16,15,8,Leaves:4)
B(35,34,0,Leaves:4)
B(35,39,0,Leaves:4)
B(35,35,0,Leaves:4)
B(35,36,0,Leaves:4)
B(35,37,0,Leaves:4)
B(35,38,0,Leaves:4)
B(4,0,-6,Leaves:4)
B(-8,35,-15,Leaves:4)
B(-8,36,-15,Leaves:4)
B(-8,33,-15,Leaves:4)
B(-8,34,-15,Leaves:4)
B(12,49,-16,Leaves:4)
B(12,47,-16,Leaves:4)
B(12,48,-16,Leaves:4)
B(12,45,-16,Leaves:4)
B(12,46,-16,Leaves:4)
B(12,44,-16,Leaves:4)
B(12,41,-16,Leaves:4)
B(12,40,-16,Leaves:4)
B(-11,35,22,Leaves:4)
B(-11,38,22,Leaves:4)
B(-11,37,22,Leaves:4)
B(-11,36,22,Leaves:4)
B(35,40,0,Leaves:4)
B(12,50,-16,Leaves:4)
B(-10,46,-29,Leaves:4)
B(-10,44,-29,Leaves:4)
B(16,51,8,Leaves:4)
B(16,50,8,Leaves:4)
B(-10,43,-29,Leaves:4)
B(-10,40,-29,Leaves:4)
B(-10,41,-29,Leaves:4)
B(16,46,8,Leaves:4)
B(16,45,8,Leaves:4)
B(16,47,8,Leaves:4)
B(16,44,8,Leaves:4)
B(16,43,8,Leaves:4)
B(16,40,8,Leaves:4)
B(12,36,-16,Leaves:4)
B(12,37,-16,Leaves:4)
B(12,38,-16,Leaves:4)
B(12,39,-16,Leaves:4)
B(16,38,8,Leaves:4)
B(12,33,-16,Leaves:4)
B(16,39,8,Leaves:4)
B(12,34,-16,Leaves:4)
B(12,35,-16,Leaves:4)
B(-24,43,0,Leaves:4)
B(0,24,2,LOG:12)
B(0,21,2,LOG:12)
B(0,20,2,LOG:12)
B(0,23,2,LOG:12)
B(0,22,2,LOG:12)
B(-20,43,21,Leaves:4)
B(-20,45,21,Leaves:4)
B(7,43,28,Leaves:4)
B(-20,44,21,Leaves:4)
B(7,45,28,Leaves:4)
B(7,46,28,Leaves:4)
B(-20,46,21,Leaves:4)
B(0,19,2,LOG:12)
B(0,18,2,LOG:12)
B(-15,41,9,Leaves:4)
B(0,17,2,LOG:12)
B(0,16,2,LOG:12)
B(-15,43,9,Leaves:4)
B(0,15,2,LOG:12)
B(-21,40,-15,Leaves:4)
B(-15,42,9,Leaves:4)
B(-15,45,9,Leaves:4)
B(-15,44,9,Leaves:4)
B(-21,39,-15,Leaves:4)
B(-21,38,-15,Leaves:4)
B(21,19,13,Leaves:4)
B(-17,43,22,Leaves:4)
B(-20,39,21,Leaves:4)
B(-20,37,21,Leaves:4)
B(-20,38,21,Leaves:4)
B(21,41,13,Leaves:4)
B(4,9,-2,LOG:12)
B(4,8,-2,LOG:12)
B(5,39,-25,Leaves:4)
B(4,7,-2,LOG:12)
B(12,29,-21,Leaves:4)
B(21,40,13,Leaves:4)
B(5,33,-25,Leaves:4)
B(4,2,-2,LOG:12)
B(4,1,-2,LOG:12)
B(5,32,-25,Leaves:4)
B(-17,37,22,Leaves:4)
B(-17,34,22,Leaves:4)
B(4,0,-2,LOG:12)
B(13,36,-12,Leaves:4)
B(-17,35,22,Leaves:4)
B(4,6,-2,LOG:12)
B(4,5,-2,LOG:12)
B(13,38,-12,Leaves:4)
B(5,35,-25,Leaves:4)
B(4,4,-2,LOG:12)
B(13,39,-12,Leaves:4)
B(5,34,-25,Leaves:4)
B(4,3,-2,LOG:12)
B(0,-7,2,LOG:12)
B(-11,38,-28,Leaves:4)
B(-11,39,-28,Leaves:4)
B(6,45,15,Leaves:4)
B(4,44,23,Leaves:4)
B(4,42,23,Leaves:4)
B(4,41,23,Leaves:4)
B(13,42,-12,Leaves:4)
B(13,43,-12,Leaves:4)
B(6,47,15,Leaves:4)
B(4,46,23,Leaves:4)
B(13,40,-12,Leaves:4)
B(6,46,15,Leaves:4)
B(4,45,23,Leaves:4)
B(13,41,-12,Leaves:4)
B(13,46,-12,Leaves:4)
B(13,47,-12,Leaves:4)
B(0,-3,2,LOG:12)
B(13,44,-12,Leaves:4)
B(13,45,-12,Leaves:4)
B(0,-4,2,LOG:12)
B(13,48,-12,Leaves:4)
B(13,49,-12,Leaves:4)
B(24,39,-18,Leaves:4)
B(24,34,-18,Leaves:4)
B(24,32,-18,Leaves:4)
B(24,37,-18,Leaves:4)
B(24,38,-18,Leaves:4)
B(24,35,-18,Leaves:4)
B(24,36,-18,Leaves:4)
B(4,34,23,Leaves:4)
B(4,32,23,Leaves:4)
B(-15,34,9,leaves:4)
B(22,-10,-8,LOG:12)
B(-15,39,9,Leaves:4)
B(-15,38,9,Leaves:4)
B(-15,37,9,Leaves:4)
B(-15,36,9,Leaves:4)
B(-15,35,9,LOG:12)
B(12,46,-21,Leaves:4)
B(11,33,-27,Leaves:4)
B(11,34,-27,Leaves:4)
B(11,32,-27,Leaves:4)
B(11,37,-27,Leaves:4)
B(12,36,-21,Leaves:4)
B(11,35,-27,Leaves:4)
B(12,34,-21,Leaves:4)
B(11,36,-27,Leaves:4)
B(12,35,-21,Leaves:4)
B(12,32,-21,Leaves:4)
B(12,30,-21,Leaves:4)
B(12,31,-21,Leaves:4)
B(5,41,-6,Leaves:4)
B(5,40,-6,Leaves:4)
B(5,43,-6,Leaves:4)
B(-6,39,16,Leaves:4)
B(-13,35,10,Leaves:4)
B(-13,36,10,Leaves:4)
B(-13,33,10,Leaves:4)
B(-13,34,10,Leaves:4)
B(-13,39,10,Leaves:4)
B(-13,37,10,Leaves:4)
B(-13,38,10,Leaves:4)
B(5,36,-6,Leaves:4)
B(5,35,-6,Leaves:4)
B(-6,44,16,Leaves:4)
B(-6,41,16,Leaves:4)
B(-6,42,16,Leaves:4)
B(-6,43,16,Leaves:4)
B(7,50,22,Leaves:4)
B(7,51,22,Leaves:4)
B(5,39,-6,Leaves:4)
B(5,38,-6,Leaves:4)
B(23,36,-20,Leaves:4)
B(23,35,-20,Leaves:4)
B(23,34,-20,Leaves:4)
B(23,33,-20,Leaves:4)
B(23,32,-20,Leaves:4)
B(23,31,-20,Leaves:4)
B(23,30,-20,Leaves:4)
B(7,41,22,Leaves:4)
B(7,42,22,Leaves:4)
B(7,43,22,Leaves:4)
B(7,44,22,Leaves:4)
B(7,40,22,Leaves:4)
B(7,49,22,Leaves:4)
B(7,45,22,Leaves:4)
B(23,39,-20,Leaves:4)
B(7,46,22,Leaves:4)
B(7,47,22,Leaves:4)
B(23,37,-20,Leaves:4)
B(23,38,-20,Leaves:4)
B(23,41,-20,Leaves:4)
B(23,40,-20,Leaves:4)
B(23,43,-20,Leaves:4)
B(-1,-8,-4,LOG:12)
B(23,42,-20,Leaves:4)
B(-1,-7,-4,LOG:12)
B(-1,-6,-4,LOG:12)
B(-1,-5,-4,LOG:12)
B(-1,-4,-4,LOG:12)
B(-13,44,10,Leaves:4)
B(-1,-3,-4,LOG:12)
B(-11,41,-28,Leaves:4)
B(-13,45,10,Leaves:4)
B(-11,40,-28,Leaves:4)
B(-13,46,10,Leaves:4)
B(-11,43,-28,Leaves:4)
B(-13,41,10,Leaves:4)
B(-13,40,10,Leaves:4)
B(27,33,-36,Leaves:4)
B(21,38,-26,Leaves:4)
B(-13,43,10,Leaves:4)
B(21,37,-26,Leaves:4)
B(-13,42,10,Leaves:4)
B(21,36,-26,Leaves:4)
B(21,35,-26,Leaves:4)
B(21,34,-26,Leaves:4)
B(21,33,-26,Leaves:4)
B(-2,47,-18,Leaves:4)
B(-2,46,-18,Leaves:4)
B(-2,45,-18,Leaves:4)
B(23,41,-6,Leaves:4)
B(23,40,-6,Leaves:4)
B(23,43,-6,Leaves:4)
B(23,42,-6,Leaves:4)
B(23,45,-6,Leaves:4)
B(23,44,-6,Leaves:4)
B(23,46,-6,Leaves:4)
B(16,33,-26,Leaves:4)
B(16,34,-26,Leaves:4)
B(16,37,-26,Leaves:4)
B(16,38,-26,Leaves:4)
B(16,35,-26,Leaves:4)
B(16,36,-26,Leaves:4)
B(16,39,-26,Leaves:4)
B(23,36,-6,Leaves:4)
B(23,35,-6,Leaves:4)
B(23,34,-6,Leaves:4)
B(23,33,-6,Leaves:4)
B(23,38,-6,Leaves:4)
B(23,37,-6,Leaves:4)
B(5,-9,6,LOG:12)
B(5,-8,6,LOG:12)
B(5,-5,6,LOG:12)
B(5,-4,6,LOG:12)
B(18,32,-34,Leaves:4)
B(5,-7,6,LOG:12)
B(18,31,-34,Leaves:4)
B(5,-6,6,LOG:12)
B(5,-1,6,LOG:12)
B(18,36,-34,Leaves:4)
B(18,35,-34,Leaves:4)
B(5,-3,6,LOG:12)
B(18,34,-34,Leaves:4)
B(5,-2,6,LOG:12)
B(11,33,-31,Leaves:4)
B(11,32,-31,Leaves:4)
B(23,52,-6,Leaves:4)
B(11,31,-31,Leaves:4)
B(11,30,-31,Leaves:4)
B(26,35,-26,Leaves:4)
B(26,34,-26,Leaves:4)
B(12,17,-9,LOG:12)
B(1,42,-18,Leaves:4)
B(-17,39,17,Leaves:4)
B(1,41,-18,Leaves:4)
B(30,50,-10,Leaves:4)
B(-17,36,17,Leaves:4)
B(12,18,-9,LOG:12)
B(12,19,-9,LOG:12)
B(-17,37,17,Leaves:4)
B(-1,42,-4,Leaves:4)
B(1,43,-18,Leaves:4)
B(-3,47,4,Leaves:4)
B(-3,49,4,Leaves:4)
B(-3,48,4,Leaves:4)
B(-17,35,17,Leaves:4)
B(1,40,-18,Leaves:4)
B(-1,37,-4,Leaves:4)
B(7,46,-23,Leaves:4)
B(-1,36,-4,Leaves:4)
B(-1,38,-4,Leaves:4)
B(1,37,-18,Leaves:4)
B(30,41,-10,Leaves:4)
B(30,42,-10,Leaves:4)
B(1,33,-18,Leaves:4)
B(30,40,-10,Leaves:4)
B(12,20,-9,LOG:12)
B(12,21,-9,LOG:12)
B(12,22,-9,LOG:12)
B(1,39,-18,Leaves:4)
B(1,38,-18,Leaves:4)
B(-17,44,17,Leaves:4)
B(-17,43,17,Leaves:4)
B(30,49,-10,Leaves:4)
B(-17,45,17,Leaves:4)
B(-17,40,17,Leaves:4)
B(30,47,-10,Leaves:4)
B(-17,42,17,Leaves:4)
B(-17,41,17,Leaves:4)
B(-2,40,-18,Leaves:4)
B(9,44,14,Leaves:4)
B(9,45,14,Leaves:4)
B(-2,41,-18,Leaves:4)
B(9,46,14,Leaves:4)
B(-3,25,4,LOG:12)
B(1,28,-18,LOG:12)
B(9,47,14,Leaves:4)
B(-3,24,4,LOG:12)
B(9,48,14,Leaves:4)
B(9,49,14,Leaves:4)
B(1,29,-18,LOG:12)
B(13,50,15,Leaves:4)
B(13,48,15,Leaves:4)
B(13,46,15,Leaves:4)
B(13,47,15,Leaves:4)
B(-2,36,-18,Leaves:4)
B(-2,37,-18,Leaves:4)
B(-2,34,-18,Leaves:4)
B(-2,38,-18,Leaves:4)
B(-2,39,-18,Leaves:4)
B(9,34,14,LOG:12)
B(-2,33,-18,Leaves:4)
B(-2,32,-18,Leaves:4)
B(-3,38,4,Leaves:4)
B(-3,37,4,Leaves:4)
B(-3,36,4,Leaves:4)
B(9,35,14,LOG:12)
B(9,36,14,LOG:12)
B(-3,35,4,Leaves:4)
B(12,39,16,Leaves:4)
B(12,37,16,Leaves:4)
B(12,38,16,Leaves:4)
B(-3,39,4,Leaves:4)
B(12,47,16,Leaves:4)
B(-3,40,4,Leaves:4)
B(12,46,16,Leaves:4)
B(-3,41,4,Leaves:4)
B(12,45,16,Leaves:4)
B(12,44,16,Leaves:4)
B(12,43,16,Leaves:4)
B(-3,44,4,Leaves:4)
B(-3,45,4,Leaves:4)
B(12,42,16,Leaves:4)
B(12,41,16,Leaves:4)
B(-3,42,4,Leaves:4)
B(12,40,16,Leaves:4)
B(-3,43,4,Leaves:4)
B(29,55,-3,Leaves:4)
B(29,54,-3,Leaves:4)
B(5,-7,-4,Leaves:4)
B(-13,44,5,Leaves:4)
B(-13,45,5,Leaves:4)
B(5,-5,-4,Leaves:4)
B(5,-4,-4,Leaves:4)
B(5,-3,-4,Leaves:4)
B(5,-2,-4,LOG:12)
B(-13,40,5,Leaves:4)
B(5,-1,-4,LOG:12)
B(-13,41,5,Leaves:4)
B(-13,42,5,Leaves:4)
B(-13,43,5,Leaves:4)
B(9,-8,2,LOG:12)
B(9,-9,2,LOG:12)
B(9,-4,2,LOG:12)
B(32,38,-2,Leaves:4)
B(32,37,-2,Leaves:4)
B(9,-5,2,LOG:12)
B(32,36,-2,Leaves:4)
B(9,-6,2,LOG:12)
B(32,35,-2,Leaves:4)
B(9,-7,2,LOG:12)
B(32,34,-2,Leaves:4)
B(9,-1,2,LOG:12)
B(9,-2,2,LOG:12)
B(5,28,6,LOG:12)
B(9,-3,2,LOG:12)
B(5,27,6,LOG:12)
B(5,39,6,Leaves:4)
B(5,38,6,Leaves:4)
B(5,37,6,Leaves:4)
B(-17,36,-9,Leaves:4)
B(-17,37,-9,Leaves:4)
B(5,40,6,Leaves:4)
B(29,35,-3,Leaves:4)
B(-17,34,-9,Leaves:4)
B(-17,35,-9,Leaves:4)
B(5,42,6,Leaves:4)
B(29,37,-3,Leaves:4)
B(5,43,6,Leaves:4)
B(29,36,-3,Leaves:4)
B(5,44,6,Leaves:4)
B(5,45,6,Leaves:4)
B(-17,38,-9,Leaves:4)
B(29,39,-3,Leaves:4)
B(5,46,6,Leaves:4)
B(29,38,-3,Leaves:4)
B(-17,32,-9,Leaves:4)
B(-1,22,-4,LOG:12)
B(-17,33,-9,Leaves:4)
B(-17,31,-9,Leaves:4)
B(0,38,19,Leaves:4)
B(0,37,19,Leaves:4)
B(0,39,19,Leaves:4)
B(32,52,-2,Leaves:4)
B(0,34,19,Leaves:4)
B(0,36,19,Leaves:4)
B(0,35,19,Leaves:4)
B(5,47,6,Leaves:4)
B(32,53,-2,Leaves:4)
B(29,40,-3,Leaves:4)
B(23,-4,-6,LOG:12)
B(29,41,-3,Leaves:4)
B(23,-3,-6,LOG:12)
B(29,42,-3,Leaves:4)
B(23,-7,-6,LOG:12)
B(32,39,-2,Leaves:4)
B(-13,39,5,Leaves:4)
B(29,45,-3,Leaves:4)
B(23,-8,-6,LOG:12)
B(23,-5,-6,LOG:12)
B(29,44,-3,Leaves:4)
B(23,-6,-6,LOG:12)
B(-13,38,5,Leaves:4)
B(29,49,-3,Leaves:4)
B(29,48,-3,Leaves:4)
B(23,-9,-6,LOG:12)
B(29,47,-3,Leaves:4)
B(-13,35,5,Leaves:4)
B(-1,35,-4,Leaves:4)
B(-13,36,5,Leaves:4)
B(32,41,-2,Leaves:4)
B(32,40,-2,Leaves:4)
B(32,45,-2,Leaves:4)
B(32,44,-2,Leaves:4)
B(29,52,-3,Leaves:4)
B(29,53,-3,Leaves:4)
B(32,46,-2,Leaves:4)
B(29,50,-3,Leaves:4)
B(29,51,-3,Leaves:4)
B(9,19,2,Leaves:4)
B(-18,38,7,Leaves:4)
B(34,38,-11,Leaves:4)
B(15,50,-12,Leaves:4)
B(34,41,-11,Leaves:4)
B(34,40,-11,Leaves:4)
B(-3,-8,4,LOG:12)
B(-3,-7,4,LOG:12)
B(-3,-4,4,LOG:12)
B(-18,42,7,Leaves:4)
B(-3,-3,4,LOG:12)
B(-18,41,7,Leaves:4)
B(-3,-6,4,LOG:12)
B(-3,-5,4,LOG:12)
B(34,42,-11,Leaves:4)
B(-2,50,1,Leaves:4)
B(-2,51,1,Leaves:4)
B(-12,39,-27,Leaves:4)
B(-12,38,-27,Leaves:4)
B(-7,45,-30,Leaves:4)
B(-7,41,-30,Leaves:4)
B(-7,42,-30,Leaves:4)
B(-7,43,-30,Leaves:4)
B(-2,46,1,Leaves:4)
B(-2,47,1,Leaves:4)
B(-2,48,1,Leaves:4)
B(-2,49,1,Leaves:4)
B(17,30,-34,Leaves:4)
B(-7,39,-30,Leaves:4)
B(-16,34,-3,Leaves:4)
B(15,23,-12,LOG:12)
B(-16,35,-3,Leaves:4)
B(-16,36,-3,Leaves:4)
B(15,26,-12,LOG:12)
B(9,-7,14,LOG:12)
B(15,24,-12,LOG:12)
B(9,-8,14,LOG:12)
B(15,25,-12,LOG:12)
B(0,51,2,Leaves:4)
B(-2,21,1,LOG:12)
B(-2,20,1,LOG:12)
B(-16,38,-3,Leaves:4)
B(-16,37,-3,Leaves:4)
B(-16,39,-3,Leaves:4)
B(-16,46,-3,Leaves:4)
B(-16,47,-3,Leaves:4)
B(18,31,-32,Leaves:4)
B(18,33,-32,Leaves:4)
B(-16,42,-3,Leaves:4)
B(18,32,-32,Leaves:4)
B(-16,43,-3,Leaves:4)
B(-16,40,-3,Leaves:4)
B(18,34,-32,Leaves:4)
B(13,38,15,Leaves:4)
B(-2,40,1,Leaves:4)
B(-12,41,-27,Leaves:4)
B(-12,40,-27,Leaves:4)
B(-2,41,1,Leaves:4)
B(-3,23,4,LOG:12)
B(-12,43,-27,Leaves:4)
B(-3,22,4,LOG:12)
B(-12,42,-27,Leaves:4)
B(9,47,2,Leaves:4)
B(35,49,2,Leaves:4)
B(9,48,2,Leaves:4)
B(9,49,2,Leaves:4)
B(13,39,15,Leaves:4)
B(-2,38,1,Leaves:4)
B(13,40,15,Leaves:4)
B(9,44,2,Leaves:4)
B(-2,37,1,Leaves:4)
B(-13,-6,5,LOG:12)
B(13,41,15,Leaves:4)
B(9,46,2,Leaves:4)
B(-13,-7,5,LOG:12)
B(9,-6,14,LOG:12)
B(9,45,2,Leaves:4)
B(9,40,2,Leaves:4)
B(13,45,15,Leaves:4)
B(9,42,2,Leaves:4)
B(13,42,15,Leaves:4)
B(9,41,2,Leaves:4)
B(13,43,15,Leaves:4)
B(6,-7,15,LOG:12)
B(6,-6,15,LOG:12)
B(26,33,-34,Leaves:4)
B(-16,49,-3,Leaves:4)
B(26,32,-34,Leaves:4)
B(-2,39,1,Leaves:4)
B(15,40,-12,Leaves:4)
B(-16,52,-3,Leaves:4)
B(15,41,-12,Leaves:4)
B(-16,53,-3,Leaves:4)
B(-16,54,-3,Leaves:4)
B(15,45,-12,Leaves:4)
B(35,36,2,Leaves:4)
B(-9,40,12,Leaves:4)
B(15,42,-12,Leaves:4)
B(15,43,-12,Leaves:4)
B(9,38,2,Leaves:4)
B(-9,42,12,Leaves:4)
B(15,49,-12,Leaves:4)
B(9,39,2,Leaves:4)
B(-9,41,12,Leaves:4)
B(15,46,-12,Leaves:4)
B(9,36,2,Leaves:4)
B(-9,43,12,Leaves:4)
B(-9,46,12,Leaves:4)
B(-4,48,2,Leaves:4)
B(-4,49,2,Leaves:4)
B(0,39,2,Leaves:4)
B(12,37,-9,Leaves:4)
B(0,36,2,Leaves:4)
B(12,36,-9,Leaves:4)
B(0,37,2,Leaves:4)
B(12,39,-9,Leaves:4)
B(12,38,-9,Leaves:4)
B(0,38,2,Leaves:4)
B(-9,33,12,LOG:12)
B(-4,40,2,Leaves:4)
B(15,36,-12,Leaves:4)
B(13,19,15,Leaves:4)
B(13,18,15,Leaves:4)
B(13,17,15,Leaves:4)
B(15,38,-12,Leaves:4)
B(15,39,-12,Leaves:4)
B(-4,44,2,Leaves:4)
B(-9,34,12,LOG:12)
B(-4,41,2,Leaves:4)
B(-4,36,2,Leaves:4)
B(13,22,15,Leaves:4)
B(-4,37,2,Leaves:4)
B(13,23,15,Leaves:4)
B(9,20,2,Leaves:4)
B(13,20,15,Leaves:4)
B(-9,38,12,Leaves:4)
B(13,21,15,Leaves:4)
B(-9,39,12,Leaves:4)
B(12,43,-9,Leaves:4)
B(0,40,2,Leaves:4)
B(12,42,-9,Leaves:4)
B(12,41,-9,Leaves:4)
B(0,41,2,Leaves:4)
B(-4,38,2,Leaves:4)
B(12,40,-9,Leaves:4)
B(-4,39,2,Leaves:4)
B(-2,19,1,LOG:12)
B(-2,18,1,LOG:12)
B(0,48,2,Leaves:4)
B(12,48,-9,Leaves:4)
B(0,46,2,Leaves:4)
B(0,47,2,Leaves:4)
B(0,37,9,Leaves:4)
B(8,19,5,Leaves:4)
B(0,36,9,Leaves:4)
B(8,18,5,Leaves:4)
B(0,35,9,Leaves:4)
B(8,17,5,Leaves:4)
B(8,16,5,LOG:12)
B(0,39,9,Leaves:4)
B(-20,40,-15,Leaves:4)
B(-20,39,-15,Leaves:4)
B(-19,41,19,Leaves:4)
B(-19,42,19,Leaves:4)
B(-19,43,19,Leaves:4)
B(-19,44,19,Leaves:4)
B(-19,38,19,Leaves:4)
B(-19,37,19,Leaves:4)
B(-19,36,19,Leaves:4)
B(-19,34,19,Leaves:4)
B(-19,35,19,Leaves:4)
B(-12,37,14,Leaves:4)
B(31,40,9,Leaves:4)
B(-12,38,14,Leaves:4)
B(-12,39,14,Leaves:4)
B(0,49,9,Leaves:4)
B(0,46,9,Leaves:4)
B(0,45,9,Leaves:4)
B(0,41,9,Leaves:4)
B(0,43,9,Leaves:4)
B(0,44,9,Leaves:4)
B(0,40,9,Leaves:4)
B(4,5,-3,LOG:12)
B(8,-4,5,Leaves:4)
B(4,4,-3,LOG:12)
B(8,-5,5,Leaves:4)
B(4,3,-3,LOG:12)
B(4,2,-3,Leaves:4)
B(8,-3,5,Leaves:4)
B(4,1,-3,Leaves:4)
B(4,0,-3,LOG:12)
B(8,-7,5,LOG:12)
B(4,9,-3,LOG:12)
B(4,8,-3,LOG:12)
B(4,7,-3,LOG:12)
B(4,6,-3,LOG:12)
B(-17,-8,3,LOG:12)
B(-17,-7,3,LOG:12)
B(-17,-6,3,LOG:12)
B(-12,40,14,Leaves:4)
B(-12,41,14,Leaves:4)
B(-12,42,14,Leaves:4)
B(-12,43,14,Leaves:4)
B(-12,44,14,Leaves:4)
B(-12,47,14,Leaves:4)
B(-2,32,-11,Leaves:4)
B(-2,34,-11,Leaves:4)
B(-2,33,-11,Leaves:4)
B(-2,39,-11,Leaves:4)
B(-2,36,-11,Leaves:4)
B(-2,35,-11,Leaves:4)
B(6,29,-8,LOG:12)
B(-2,38,-11,Leaves:4)
B(-2,37,-11,Leaves:4)
B(-7,38,23,Leaves:4)
B(-3,37,-25,Leaves:4)
B(-3,38,-25,Leaves:4)
B(-3,35,-25,Leaves:4)
B(-4,44,9,Leaves:4)
B(-3,33,-25,Leaves:4)
B(-4,45,9,Leaves:4)
B(-3,34,-25,Leaves:4)
B(-4,46,9,Leaves:4)
B(20,39,-5,Leaves:4)
B(-4,43,9,Leaves:4)
B(20,36,-5,Leaves:4)
B(20,35,-5,Leaves:4)
B(20,38,-5,Leaves:4)
B(-3,39,-25,Leaves:4)
B(20,37,-5,Leaves:4)
B(-3,41,-25,Leaves:4)
B(-5,36,5,Leaves:4)
B(1,18,-1,LOG:12)
B(1,19,-1,LOG:12)
B(27,40,-17,Leaves:4)
B(27,41,-17,Leaves:4)
B(1,14,-1,LOG:12)
B(1,15,-1,LOG:12)
B(1,16,-1,LOG:12)
B(1,17,-1,LOG:12)
B(20,29,-5,LOG:12)
B(20,28,-5,LOG:12)
B(20,27,-5,LOG:12)
B(1,13,-1,LOG:12)
B(27,38,-17,Leaves:4)
B(1,12,-1,LOG:12)
B(0,48,19,Leaves:4)
B(-22,38,-24,Leaves:4)
B(6,39,-8,Leaves:4)
B(-22,37,-24,Leaves:4)
B(0,46,19,Leaves:4)
B(0,40,19,Leaves:4)
B(0,41,19,Leaves:4)
B(0,42,19,Leaves:4)
B(0,43,19,Leaves:4)
B(-5,50,5,Leaves:4)
B(6,30,-8,LOG:12)
B(6,36,-8,Leaves:4)
B(6,37,-8,Leaves:4)
B(-3,42,-25,Leaves:4)
B(-3,43,-25,Leaves:4)
B(-3,44,-25,Leaves:4)
B(-3,45,-25,Leaves:4)
B(-3,46,-25,Leaves:4)
B(-3,47,-25,Leaves:4)
B(-17,37,3,Leaves:4)
B(-17,38,3,Leaves:4)
B(-5,45,5,Leaves:4)
B(-17,39,3,Leaves:4)
B(-5,46,5,Leaves:4)
B(-5,47,5,Leaves:4)
B(-5,48,5,Leaves:4)
B(6,42,-8,Leaves:4)
B(-5,41,5,Leaves:4)
B(-22,36,-24,Leaves:4)
B(-5,42,5,Leaves:4)
B(-5,43,5,Leaves:4)
B(-5,44,5,Leaves:4)
B(-17,40,3,Leaves:4)
B(-17,41,3,Leaves:4)
B(1,-7,1,LOG:12)
B(1,-8,1,LOG:12)
B(10,16,-7,LOG:12)
B(10,17,-7,LOG:12)
B(10,14,-7,LOG:12)
B(10,15,-7,LOG:12)
B(32,38,7,Leaves:4)
B(10,18,-7,LOG:12)
B(10,19,-7,LOG:12)
B(-17,49,3,Leaves:4)
B(-17,48,3,Leaves:4)
B(-17,47,3,Leaves:4)
B(-17,46,3,Leaves:4)
B(38,36,2,Leaves:4)
B(-17,44,3,Leaves:4)
B(-17,43,3,Leaves:4)
B(-17,42,3,Leaves:4)
B(10,20,-7,LOG:12)
B(10,21,-7,LOG:12)
B(1,-4,-1,LOG:12)
B(-5,-5,5,LOG:12)
B(-5,-6,5,LOG:12)
B(-5,-7,5,LOG:12)
B(1,-3,-1,LOG:12)
B(-5,-8,5,LOG:12)
B(1,-2,-1,LOG:12)
B(23,40,0,Leaves:4)
B(23,43,0,Leaves:4)
B(23,44,0,Leaves:4)
B(23,41,0,Leaves:4)
B(23,42,0,Leaves:4)
B(1,-6,1,LOG:12)
B(23,48,0,Leaves:4)
B(1,-5,1,LOG:12)
B(23,45,0,Leaves:4)
B(1,-4,1,LOG:12)
B(23,46,0,Leaves:4)
B(22,36,-35,Leaves:4)
B(1,-3,1,LOG:12)
B(22,35,-35,Leaves:4)
B(1,-2,1,LOG:12)
B(22,34,-35,Leaves:4)
B(23,49,0,Leaves:4)
B(10,34,-7,Leaves:4)
B(10,35,-7,Leaves:4)
B(20,-1,-5,LOG:12)
B(20,-2,-5,LOG:12)
B(20,-3,-5,LOG:12)
B(20,-4,-5,LOG:12)
B(20,-5,-5,LOG:12)
B(12,21,16,Leaves:4)
B(10,38,-7,Leaves:4)
B(10,39,-7,Leaves:4)
B(28,39,2,Leaves:4)
B(10,36,-7,Leaves:4)
B(-4,29,9,LOG:12)
B(28,38,2,Leaves:4)
B(28,37,2,Leaves:4)
B(10,37,-7,Leaves:4)
B(-4,28,9,LOG:12)
B(28,42,2,Leaves:4)
B(28,43,2,Leaves:4)
B(28,40,2,Leaves:4)
B(28,41,2,Leaves:4)
B(12,36,16,Leaves:4)
B(10,44,-7,Leaves:4)
B(10,45,-7,Leaves:4)
B(10,46,-7,Leaves:4)
B(10,40,-7,Leaves:4)
B(28,45,2,Leaves:4)
B(28,44,2,Leaves:4)
B(28,47,2,Leaves:4)
B(28,46,2,Leaves:4)
B(28,49,2,Leaves:4)
B(10,47,-7,Leaves:4)
B(28,48,2,Leaves:4)
B(28,51,2,Leaves:4)
B(1,13,1,LOG:12)
B(1,14,1,LOG:12)
B(1,15,1,LOG:12)
B(1,16,1,LOG:12)
B(1,17,1,LOG:12)
B(1,18,1,LOG:12)
B(1,19,1,LOG:12)
B(23,19,0,Leaves:4)
B(1,24,1,LOG:12)
B(1,22,1,LOG:12)
B(1,23,1,LOG:12)
B(1,20,1,LOG:12)
B(1,21,1,LOG:12)
B(4,32,-30,Leaves:4)
B(4,31,-30,Leaves:4)
B(-4,45,-16,Leaves:4)
B(4,34,-30,Leaves:4)
B(-4,46,-16,Leaves:4)
B(4,33,-30,Leaves:4)
B(4,36,-30,Leaves:4)
B(4,35,-30,Leaves:4)
B(4,38,-30,Leaves:4)
B(4,37,-30,Leaves:4)
B(1,39,1,Leaves:4)
B(1,35,1,Leaves:4)
B(1,36,1,Leaves:4)
B(1,37,1,Leaves:4)
B(1,38,1,Leaves:4)
B(23,37,0,Leaves:4)
B(23,36,0,Leaves:4)
B(23,35,0,Leaves:4)
B(1,49,1,Leaves:4)
B(1,46,1,Leaves:4)
B(23,39,0,Leaves:4)
B(23,38,0,Leaves:4)
B(1,45,1,Leaves:4)
B(23,33,0,Leaves:4)
B(1,40,1,Leaves:4)
B(23,32,0,Leaves:4)
B(1,41,1,Leaves:4)
B(-5,46,-25,Leaves:4)
B(-5,44,-25,Leaves:4)
B(-5,45,-25,Leaves:4)
B(1,52,1,Leaves:4)
B(1,50,-1,Leaves:4)
B(39,38,-3,Leaves:4)
B(39,37,-3,Leaves:4)
B(26,34,9,Leaves:4)
B(26,37,9,Leaves:4)
B(26,38,9,Leaves:4)
B(1,41,-1,Leaves:4)
B(26,39,9,Leaves:4)
B(1,42,-1,Leaves:4)
B(7,37,-5,Leaves:4)
B(7,35,-5,Leaves:4)
B(7,38,-5,Leaves:4)
B(7,39,-5,Leaves:4)
B(26,40,9,Leaves:4)
B(1,48,-1,Leaves:4)
B(26,42,9,Leaves:4)
B(1,49,-1,Leaves:4)
B(26,41,9,Leaves:4)
B(1,34,-1,Leaves:4)
B(1,35,-1,Leaves:4)
B(7,49,-5,Leaves:4)
B(7,46,-5,Leaves:4)
B(7,47,-5,Leaves:4)
B(34,46,0,Leaves:4)
B(34,45,0,Leaves:4)
B(28,35,8,Leaves:4)
B(7,42,-5,Leaves:4)
B(7,41,-5,Leaves:4)
B(28,37,8,Leaves:4)
B(7,44,-5,Leaves:4)
B(28,38,8,Leaves:4)
B(7,43,-5,Leaves:4)
B(28,34,8,Leaves:4)
B(1,38,-1,Leaves:4)
B(1,37,-1,Leaves:4)
B(1,36,-1,Leaves:4)
B(1,21,-1,LOG:12)
B(34,31,0,Leaves:4)
B(1,22,-1,LOG:12)
B(34,32,0,Leaves:4)
B(1,20,-1,LOG:12)
B(34,38,0,Leaves:4)
B(34,35,0,Leaves:4)
B(34,34,0,Leaves:4)
B(34,37,0,Leaves:4)
B(34,36,0,Leaves:4)
B(7,50,-5,Leaves:4)
B(8,45,-21,Leaves:4)
B(-8,44,-17,Leaves:4)
B(-8,42,-17,Leaves:4)
B(-8,43,-17,Leaves:4)
B(-8,46,-17,Leaves:4)
B(-8,47,-17,Leaves:4)
B(-8,41,-17,Leaves:4)
B(-8,35,-17,Leaves:4)
B(-8,36,-17,Leaves:4)
B(-8,37,-17,Leaves:4)
B(-8,38,-17,Leaves:4)
B(-8,32,-17,Leaves:4)
B(-8,33,-17,Leaves:4)
B(-8,34,-17,Leaves:4)
B(1,46,-7,Leaves:4)
B(1,45,-7,Leaves:4)
B(1,47,-7,Leaves:4)
B(1,40,-7,Leaves:4)
B(1,42,-7,Leaves:4)
B(1,41,-7,Leaves:4)
B(1,44,-7,Leaves:4)
B(1,43,-7,Leaves:4)
B(7,11,-5,Leaves:4)
B(-9,48,0,Leaves:4)
B(4,9,-4,LOG:12)
B(7,17,-5,LOG:12)
B(7,16,-5,LOG:12)
B(7,13,-5,Leaves:4)
B(7,12,-5,Leaves:4)
B(-5,34,3,Leaves:4)
B(4,7,-4,LOG:12)
B(7,15,-5,LOG:12)
B(7,14,-5,LOG:12)
B(4,8,-4,LOG:12)
B(4,1,-4,Leaves:4)
B(4,2,-4,Leaves:4)
B(4,0,-4,Leaves:4)
B(-5,39,-25,Leaves:4)
B(2,35,-32,Leaves:4)
B(-5,38,-25,Leaves:4)
B(2,36,-32,Leaves:4)
B(2,33,-32,Leaves:4)
B(2,34,-32,Leaves:4)
B(2,31,-32,Leaves:4)
B(-5,33,-25,Leaves:4)
B(2,32,-32,Leaves:4)
B(16,48,-15,Leaves:4)
B(-5,42,-25,Leaves:4)
B(-9,42,0,Leaves:4)
B(16,49,-15,Leaves:4)
B(-5,43,-25,Leaves:4)
B(-9,43,0,Leaves:4)
B(16,46,-15,Leaves:4)
B(-5,40,-25,Leaves:4)
B(-9,40,0,Leaves:4)
B(16,47,-15,Leaves:4)
B(-5,41,-25,Leaves:4)
B(-9,41,0,Leaves:4)
B(-9,46,0,Leaves:4)
B(16,44,-15,Leaves:4)
B(-9,47,0,Leaves:4)
B(16,42,-15,Leaves:4)
B(-9,44,0,Leaves:4)
B(-9,45,0,Leaves:4)
B(16,43,-15,Leaves:4)
B(16,41,-15,Leaves:4)
B(1,33,-7,Leaves:4)
B(16,39,-15,Leaves:4)
B(16,35,-15,Leaves:4)
B(16,36,-15,Leaves:4)
B(16,37,-15,Leaves:4)
B(1,38,-7,Leaves:4)
B(16,38,-15,Leaves:4)
B(1,39,-7,Leaves:4)
B(1,35,-7,Leaves:4)
B(37,41,-5,Leaves:4)
B(37,40,-5,Leaves:4)
B(37,42,-5,Leaves:4)
B(-4,39,-16,Leaves:4)
B(-4,38,-16,Leaves:4)
B(-4,37,-16,Leaves:4)
B(-29,41,12,Leaves:4)
B(-4,36,-16,Leaves:4)
B(-29,42,12,Leaves:4)
B(-4,35,-16,Leaves:4)
B(-4,44,-16,Leaves:4)
B(16,28,-15,LOG:12)
B(-4,41,-16,Leaves:4)
B(16,29,-15,LOG:12)
B(-4,42,-16,Leaves:4)
B(-4,40,-16,Leaves:4)
B(37,37,-5,Leaves:4)
B(16,26,-15,LOG:12)
B(37,38,-5,Leaves:4)
B(37,39,-5,Leaves:4)
B(37,36,-5,Leaves:4)
B(37,35,-5,Leaves:4)
B(1,46,10,Leaves:4)
B(1,47,10,Leaves:4)
B(-10,51,-17,Leaves:4)
B(1,42,10,Leaves:4)
B(1,43,10,Leaves:4)
B(1,44,10,Leaves:4)
B(1,45,10,Leaves:4)
B(14,43,16,Leaves:4)
B(16,31,-1,Leaves:4)
B(14,40,16,Leaves:4)
B(14,41,16,Leaves:4)
B(14,39,16,Leaves:4)
B(1,41,10,Leaves:4)
B(1,40,10,Leaves:4)
B(1,37,10,Leaves:4)
B(1,38,10,Leaves:4)
B(1,36,10,Leaves:4)
B(-10,42,-17,Leaves:4)
B(1,34,10,Leaves:4)
B(-10,41,-17,Leaves:4)
B(-10,40,-17,Leaves:4)
B(-10,46,-17,Leaves:4)
B(14,51,16,Leaves:4)
B(16,42,-1,Leaves:4)
B(1,39,10,Leaves:4)
B(16,40,-1,Leaves:4)
B(14,50,16,Leaves:4)
B(16,35,-1,Leaves:4)
B(16,33,-1,Leaves:4)
B(14,49,16,Leaves:4)
B(8,18,-4,LOG:12)
B(16,38,-1,Leaves:4)
B(14,48,16,Leaves:4)
B(16,39,-1,Leaves:4)
B(14,47,16,Leaves:4)
B(16,36,-1,Leaves:4)
B(-2,27,9,LOG:12)
B(8,14,-4,LOG:12)
B(8,15,-4,LOG:12)
B(8,16,-4,LOG:12)
B(8,17,-4,LOG:12)
B(8,10,-4,LOG:12)
B(8,11,-4,LOG:12)
B(8,12,-4,LOG:12)
B(8,13,-4,LOG:12)
B(18,50,-4,Leaves:4)
B(16,51,-1,Leaves:4)
B(-10,37,-17,Leaves:4)
B(16,50,-1,Leaves:4)
B(-10,36,-17,Leaves:4)
B(16,53,-1,Leaves:4)
B(-10,39,-17,Leaves:4)
B(16,52,-1,Leaves:4)
B(-10,38,-17,Leaves:4)
B(-10,35,-17,Leaves:4)
B(-2,29,9,LOG:12)
B(-10,34,-17,Leaves:4)
B(-2,28,9,LOG:12)
B(16,48,-1,Leaves:4)
B(16,49,-1,Leaves:4)
B(-2,35,9,Leaves:4)
B(-2,36,9,Leaves:4)
B(16,43,-1,Leaves:4)
B(16,44,-1,Leaves:4)
B(16,45,-1,Leaves:4)
B(16,46,-1,Leaves:4)
B(18,41,-4,Leaves:4)
B(18,40,-4,Leaves:4)
B(-14,36,-12,Leaves:4)
B(18,42,-4,Leaves:4)
B(-2,39,9,Leaves:4)
B(-2,46,9,Leaves:4)
B(-2,47,9,Leaves:4)
B(-6,-8,-9,LOG:12)
B(-2,42,9,Leaves:4)
B(-2,43,9,Leaves:4)
B(16,54,-1,Leaves:4)
B(-2,44,9,Leaves:4)
B(-2,45,9,Leaves:4)
B(18,37,-4,Leaves:4)
B(18,38,-4,Leaves:4)
B(-6,-7,-9,LOG:12)
B(18,39,-4,Leaves:4)
B(-6,-6,-9,LOG:12)
B(2,49,7,Leaves:4)
B(-8,-7,5,LOG:12)
B(16,28,-22,Leaves:4)
B(-13,39,20,Leaves:4)
B(-8,-8,5,LOG:12)
B(16,29,-22,Leaves:4)
B(-13,38,20,Leaves:4)
B(-8,-5,5,LOG:12)
B(-13,37,20,Leaves:4)
B(-13,36,20,Leaves:4)
B(-8,-6,5,LOG:12)
B(2,45,7,Leaves:4)
B(2,46,7,Leaves:4)
B(2,47,7,Leaves:4)
B(2,48,7,Leaves:4)
B(16,27,-22,Leaves:4)
B(2,42,7,Leaves:4)
B(25,53,8,Leaves:4)
B(2,41,7,Leaves:4)
B(2,44,7,Leaves:4)
B(2,43,7,Leaves:4)
B(2,40,7,Leaves:4)
B(-1,31,25,Leaves:4)
B(-1,34,25,Leaves:4)
B(16,33,-22,Leaves:4)
B(-1,35,25,Leaves:4)
B(16,34,-22,Leaves:4)
B(-1,32,25,Leaves:4)
B(16,31,-22,Leaves:4)
B(-1,33,25,Leaves:4)
B(16,32,-22,Leaves:4)
B(-1,38,25,Leaves:4)
B(16,30,-22,Leaves:4)
B(-1,39,25,Leaves:4)
B(-1,36,25,Leaves:4)
B(-1,37,25,Leaves:4)
B(16,39,-22,Leaves:4)
B(16,37,-22,Leaves:4)
B(16,38,-22,Leaves:4)
B(22,39,-3,Leaves:4)
B(16,35,-22,Leaves:4)
B(16,36,-22,Leaves:4)
B(18,-2,-4,LOG:12)
B(22,47,-3,Leaves:4)
B(18,-1,-4,LOG:12)
B(18,-4,-4,LOG:12)
B(18,-3,-4,LOG:12)
B(22,43,-3,Leaves:4)
B(22,40,-3,Leaves:4)
B(22,41,-3,Leaves:4)
B(-1,41,25,Leaves:4)
B(-1,40,25,Leaves:4)
B(-6,40,4,Leaves:4)
B(16,40,-22,Leaves:4)
B(16,41,-22,Leaves:4)
B(14,21,16,Leaves:4)
B(16,42,-22,Leaves:4)
B(14,20,16,Leaves:4)
B(16,43,-22,Leaves:4)
B(-6,47,4,Leaves:4)
B(-6,48,4,Leaves:4)
B(16,47,-22,Leaves:4)
B(-6,45,4,Leaves:4)
B(22,29,-3,LOG:12)
B(-6,46,4,Leaves:4)
B(-6,43,4,Leaves:4)
B(-6,44,4,Leaves:4)
B(-6,41,4,Leaves:4)
B(-6,42,4,Leaves:4)
B(25,34,8,Leaves:4)
B(25,35,8,Leaves:4)
B(22,31,-3,LOG:12)
B(22,32,-3,LOG:12)
B(22,37,-3,Leaves:4)
B(22,38,-3,Leaves:4)
B(22,35,-3,Leaves:4)
B(22,36,-3,Leaves:4)
B(14,18,16,Leaves:4)
B(22,30,-3,LOG:12)
B(14,19,16,Leaves:4)
B(7,-2,-3,LOG:12)
B(7,-3,-3,LOG:12)
B(19,-5,-7,LOG:12)
B(-6,50,4,Leaves:4)
B(19,-4,-7,LOG:12)
B(-6,51,4,Leaves:4)
B(7,-1,-3,LOG:12)
B(19,-3,-7,LOG:12)
B(19,-2,-7,LOG:12)
B(19,-1,-7,LOG:12)
B(2,36,7,Leaves:4)
B(22,18,-3,Leaves:4)
B(2,37,7,Leaves:4)
B(22,17,-3,Leaves:4)
B(-13,43,20,Leaves:4)
B(22,19,-3,Leaves:4)
B(25,37,8,Leaves:4)
B(7,-6,-3,LOG:12)
B(25,36,8,Leaves:4)
B(7,-4,-3,LOG:12)
B(2,38,7,Leaves:4)
B(25,39,8,Leaves:4)
B(7,-5,-3,LOG:12)
B(25,38,8,Leaves:4)
B(2,39,7,Leaves:4)
B(25,43,8,Leaves:4)
B(25,44,8,Leaves:4)
B(-6,49,4,Leaves:4)
B(15,34,-29,Leaves:4)
B(25,40,8,Leaves:4)
B(-13,40,20,Leaves:4)
B(25,41,8,Leaves:4)
B(-13,41,20,Leaves:4)
B(25,42,8,Leaves:4)
B(-13,42,20,Leaves:4)
B(5,42,19,Leaves:4)
B(-25,43,6,Leaves:4)
B(-25,42,6,Leaves:4)
B(5,45,19,Leaves:4)
B(5,47,19,Leaves:4)
B(5,48,19,Leaves:4)
B(5,49,19,Leaves:4)
B(-19,38,-22,Leaves:4)
B(-25,40,6,Leaves:4)
B(-19,37,-22,Leaves:4)
B(-25,41,6,Leaves:4)
B(5,50,19,Leaves:4)
B(-25,38,6,Leaves:4)
B(-25,37,6,Leaves:4)
B(4,43,-24,Leaves:4)
B(-25,39,6,Leaves:4)
B(3,-3,4,LOG:12)
B(3,-2,4,LOG:12)
B(3,-1,4,LOG:12)
B(5,-1,0,LOG:12)
B(-6,36,4,Leaves:4)
B(-6,35,4,Leaves:4)
B(5,-6,0,LOG:12)
B(5,-7,0,LOG:12)
B(5,-8,0,LOG:12)
B(5,-9,0,LOG:12)
B(5,-2,0,LOG:12)
B(5,-3,0,LOG:12)
B(3,-6,4,LOG:12)
B(5,-4,0,LOG:12)
B(3,-5,4,LOG:12)
B(3,-4,4,LOG:12)
B(5,-5,0,LOG:12)
B(9,42,21,Leaves:4)
B(9,43,21,Leaves:4)
B(23,39,-13,Leaves:4)
B(16,-2,-1,LOG:12)
B(23,38,-13,Leaves:4)
B(23,37,-13,Leaves:4)
B(16,-3,-1,LOG:12)
B(-5,41,-32,Leaves:4)
B(23,36,-13,Leaves:4)
B(-2,-9,-5,LOG:12)
B(-2,-8,-5,LOG:12)
B(16,-8,-1,LOG:12)
B(-2,-5,-5,LOG:12)
B(-2,-4,-5,LOG:12)
B(-2,-7,-5,LOG:12)
B(-2,-6,-5,LOG:12)
B(16,-4,-1,LOG:12)
B(16,-5,-1,LOG:12)
B(-2,-3,-5,LOG:12)
B(16,-6,-1,LOG:12)
B(16,-7,-1,LOG:12)
B(17,33,-30,Leaves:4)
B(17,34,-30,Leaves:4)
B(-19,41,-22,Leaves:4)
B(-19,40,-22,Leaves:4)
B(17,38,-30,Leaves:4)
B(5,39,19,Leaves:4)
B(17,32,-30,Leaves:4)
B(5,37,19,Leaves:4)
B(-6,-5,4,LOG:12)
B(-6,-4,4,LOG:12)
B(-6,-7,4,LOG:12)
B(-6,-6,4,LOG:12)
B(13,48,-16,Leaves:4)
B(13,49,-16,Leaves:4)
B(13,46,-16,Leaves:4)
B(19,54,1,Leaves:4)
B(13,47,-16,Leaves:4)
B(9,-6,21,LOG:12)
B(19,53,1,Leaves:4)
B(-19,33,17,Leaves:4)
B(19,52,1,Leaves:4)
B(13,45,-16,Leaves:4)
B(12,51,14,Leaves:4)
B(19,51,1,Leaves:4)
B(12,52,14,Leaves:4)
B(19,50,1,Leaves:4)
B(13,43,-16,Leaves:4)
B(9,-7,21,LOG:12)
B(13,40,-16,Leaves:4)
B(12,50,14,Leaves:4)
B(9,-8,21,LOG:12)
B(13,41,-16,Leaves:4)
B(19,27,-7,LOG:12)
B(-19,38,17,Leaves:4)
B(19,26,-7,LOG:12)
B(-19,39,17,Leaves:4)
B(19,49,1,Leaves:4)
B(19,25,-7,LOG:12)
B(12,49,14,Leaves:4)
B(19,47,1,Leaves:4)
B(-19,34,17,Leaves:4)
B(12,48,14,Leaves:4)
B(19,48,1,Leaves:4)
B(-19,35,17,Leaves:4)
B(12,47,14,Leaves:4)
B(19,45,1,Leaves:4)
B(-19,36,17,Leaves:4)
B(19,46,1,Leaves:4)
B(19,28,-7,LOG:12)
B(13,37,-16,Leaves:4)
B(13,38,-16,Leaves:4)
B(13,39,-16,Leaves:4)
B(-19,44,17,Leaves:4)
B(8,1,4,Leaves:4)
B(19,42,1,Leaves:4)
B(13,34,-16,Leaves:4)
B(19,41,1,Leaves:4)
B(12,43,14,Leaves:4)
B(-19,43,17,Leaves:4)
B(12,44,14,Leaves:4)
B(13,35,-16,Leaves:4)
B(-19,42,17,Leaves:4)
B(19,44,1,Leaves:4)
B(13,36,-16,Leaves:4)
B(8,2,4,Leaves:4)
B(-19,41,17,Leaves:4)
B(19,43,1,Leaves:4)
B(-19,40,17,Leaves:4)
B(19,38,1,Leaves:4)
B(19,39,1,Leaves:4)
B(12,39,14,Leaves:4)
B(12,36,14,Leaves:4)
B(2,-6,7,LOG:12)
B(19,35,1,Leaves:4)
B(2,-7,7,LOG:12)
B(-19,45,17,Leaves:4)
B(19,36,1,Leaves:4)
B(2,-8,7,LOG:12)
B(12,38,14,Leaves:4)
B(19,37,1,Leaves:4)
B(2,-9,7,LOG:12)
B(12,37,14,Leaves:4)
B(2,-5,7,LOG:12)
B(4,39,-24,Leaves:4)
B(7,49,17,Leaves:4)
B(7,48,17,Leaves:4)
B(7,45,17,Leaves:4)
B(7,40,17,Leaves:4)
B(19,20,1,Leaves:4)
B(19,22,1,Leaves:4)
B(19,21,1,Leaves:4)
B(12,23,14,Leaves:4)
B(19,17,1,Leaves:4)
B(19,18,1,Leaves:4)
B(19,19,1,Leaves:4)
B(12,19,14,Leaves:4)
B(-2,23,-5,LOG:12)
B(8,40,-11,Leaves:4)
B(8,39,5,Leaves:4)
B(8,38,5,Leaves:4)
B(-14,36,-14,Leaves:4)
B(-14,35,-14,Leaves:4)
B(-14,39,-14,Leaves:4)
B(8,30,5,LOG:12)
B(7,38,17,Leaves:4)
B(8,31,5,LOG:12)
B(7,39,17,Leaves:4)
B(7,37,17,Leaves:4)
B(8,34,5,Leaves:4)
B(3,37,21,Leaves:4)
B(8,35,5,Leaves:4)
B(3,38,21,Leaves:4)
B(8,36,5,Leaves:4)
B(3,39,21,Leaves:4)
B(8,37,5,Leaves:4)
B(8,45,-11,Leaves:4)
B(8,46,-11,Leaves:4)
B(3,34,21,Leaves:4)
B(8,47,-11,Leaves:4)
B(3,35,21,Leaves:4)
B(8,48,-11,Leaves:4)
B(3,36,21,Leaves:4)
B(8,41,-11,Leaves:4)
B(-2,38,-5,Leaves:4)
B(8,42,-11,Leaves:4)
B(-2,37,-5,Leaves:4)
B(-2,36,-5,Leaves:4)
B(8,44,-11,Leaves:4)
B(-2,32,-5,Leaves:4)
B(-2,33,-5,Leaves:4)
B(-2,34,-5,Leaves:4)
B(-2,35,-5,Leaves:4)
B(-14,40,-14,Leaves:4)
B(8,29,5,LOG:12)
B(8,28,5,LOG:12)
B(8,21,5,Leaves:4)
B(8,20,5,Leaves:4)
B(8,38,-11,Leaves:4)
B(8,39,-11,Leaves:4)
B(8,36,-11,Leaves:4)
B(8,37,-11,Leaves:4)
B(8,35,-11,Leaves:4)
B(8,33,-11,Leaves:4)
B(7,17,8,Leaves:4)
B(7,16,8,Leaves:4)
B(8,27,-11,LOG:12)
B(8,28,-11,LOG:12)
B(8,29,-11,LOG:12)
B(8,20,-11,LOG:12)
B(8,50,5,Leaves:4)
B(8,21,-11,LOG:12)
B(8,22,-11,LOG:12)
B(8,23,-11,LOG:12)
B(8,24,-11,LOG:12)
B(8,25,-11,LOG:12)
B(37,38,-3,Leaves:4)
B(37,36,-3,Leaves:4)
B(8,49,5,Leaves:4)
B(8,47,5,Leaves:4)
B(8,45,5,Leaves:4)
B(8,46,5,Leaves:4)
B(8,43,5,Leaves:4)
B(8,44,5,Leaves:4)
B(8,41,5,Leaves:4)
B(8,42,5,Leaves:4)
B(8,40,5,Leaves:4)
B(4,46,-4,Leaves:4)
B(7,39,8,Leaves:4)
B(4,43,-4,Leaves:4)
B(4,41,-4,Leaves:4)
B(4,42,-4,Leaves:4)
B(4,40,-4,Leaves:4)
B(24,36,-11,Leaves:4)
B(13,43,1,Leaves:4)
B(24,37,-11,Leaves:4)
B(11,35,14,LOG:12)
B(13,44,1,Leaves:4)
B(13,45,1,Leaves:4)
B(24,38,-11,Leaves:4)
B(13,46,1,Leaves:4)
B(24,39,-11,Leaves:4)
B(13,40,1,Leaves:4)
B(13,41,1,Leaves:4)
B(24,35,-11,Leaves:4)
B(13,42,1,Leaves:4)
B(13,34,1,Leaves:4)
B(13,35,1,Leaves:4)
B(13,32,1,Leaves:4)
B(13,33,1,Leaves:4)
B(24,45,-11,Leaves:4)
B(13,30,1,Leaves:4)
B(24,46,-11,Leaves:4)
B(13,31,1,Leaves:4)
B(24,43,-11,Leaves:4)
B(24,44,-11,Leaves:4)
B(24,41,-11,Leaves:4)
B(24,42,-11,Leaves:4)
B(24,40,-11,Leaves:4)
B(13,38,1,Leaves:4)
B(4,36,-4,Leaves:4)
B(13,39,1,Leaves:4)
B(13,36,1,Leaves:4)
B(7,43,8,Leaves:4)
B(7,44,8,Leaves:4)
B(7,45,8,Leaves:4)
B(7,46,8,Leaves:4)
B(7,47,8,Leaves:4)
B(7,48,8,Leaves:4)
B(38,39,-8,Leaves:4)
B(7,40,8,Leaves:4)
B(7,41,8,Leaves:4)
B(7,42,8,Leaves:4)
B(38,40,-8,Leaves:4)
B(38,41,-8,Leaves:4)
B(31,37,3,Leaves:4)
B(31,36,3,Leaves:4)
B(31,34,3,Leaves:4)
B(31,39,3,Leaves:4)
B(31,38,3,Leaves:4)
B(-9,41,-21,Leaves:4)
B(7,37,-3,Leaves:4)
B(7,39,-3,Leaves:4)
B(7,38,-3,Leaves:4)
B(31,46,3,Leaves:4)
B(31,49,3,Leaves:4)
B(31,40,3,Leaves:4)
B(31,42,3,Leaves:4)
B(-11,39,14,Leaves:4)
B(-11,38,14,Leaves:4)
B(13,29,1,Leaves:4)
B(13,21,1,Leaves:4)
B(-11,42,14,Leaves:4)
B(-11,43,14,Leaves:4)
B(-11,47,14,Leaves:4)
B(7,11,-3,LOG:12)
B(7,10,-3,LOG:12)
B(7,13,-3,LOG:12)
B(7,12,-3,LOG:12)
B(7,15,-3,LOG:12)
B(7,14,-3,LOG:12)
B(7,17,-3,LOG:12)
B(-11,40,14,Leaves:4)
B(7,16,-3,LOG:12)
B(-11,41,14,Leaves:4)
B(-25,41,4,Leaves:4)
B(-25,43,4,Leaves:4)
B(-25,42,4,Leaves:4)
B(-25,44,4,Leaves:4)
B(-25,47,4,Leaves:4)
B(-25,46,4,Leaves:4)
B(4,11,-4,LOG:12)
B(4,10,-4,LOG:12)
B(-21,34,17,Leaves:4)
B(-21,33,17,Leaves:4)
B(2,39,-22,Leaves:4)
B(2,38,-22,Leaves:4)
B(2,37,-22,Leaves:4)
B(-21,36,17,Leaves:4)
B(8,39,-4,Leaves:4)
B(8,38,-4,Leaves:4)
B(8,33,-4,LOG:12)
B(-8,45,5,Leaves:4)
B(-21,43,17,Leaves:4)
B(-21,42,17,Leaves:4)
B(-8,44,5,Leaves:4)
B(-8,47,5,Leaves:4)
B(8,49,-4,Leaves:4)
B(8,43,-4,Leaves:4)
B(-21,40,17,Leaves:4)
B(4,-3,-4,LOG:12)
B(4,-2,-4,LOG:12)
B(4,-1,-4,Leaves:4)
B(13,-3,1,LOG:12)
B(13,-4,1,LOG:12)
B(4,-7,-4,LOG:12)
B(7,42,-3,Leaves:4)
B(4,-6,-4,LOG:12)
B(13,-5,1,LOG:12)
B(7,41,-3,Leaves:4)
B(13,-6,1,LOG:12)
B(4,-5,-4,LOG:12)
B(7,40,-3,Leaves:4)
B(-8,43,5,Leaves:4)
B(13,-7,1,LOG:12)
B(4,-4,-4,Leaves:4)
B(7,45,-3,Leaves:4)
B(7,46,-3,Leaves:4)
B(7,43,-3,Leaves:4)
B(7,47,-3,Leaves:4)
B(7,48,-3,Leaves:4)
B(8,40,-4,Leaves:4)
B(8,41,-4,Leaves:4)
B(8,42,-4,Leaves:4)
B(-2,24,3,LOG:12)
B(-2,25,3,LOG:12)
B(-2,22,3,LOG:12)
B(-2,23,3,LOG:12)
B(36,42,-3,Leaves:4)
B(36,41,-3,Leaves:4)
B(36,38,-3,Leaves:4)
B(2,41,-22,Leaves:4)
B(36,39,-3,Leaves:4)
B(2,42,-22,Leaves:4)
B(-22,50,1,Leaves:4)
B(36,37,-3,Leaves:4)
B(2,40,-22,Leaves:4)
B(2,42,25,Leaves:4)
B(2,44,25,Leaves:4)
B(21,0,-6,LOG:12)
B(2,43,25,Leaves:4)
B(13,46,-7,Leaves:4)
B(13,47,-7,Leaves:4)
B(2,43,-22,Leaves:4)
B(2,44,-22,Leaves:4)
B(-2,37,3,Leaves:4)
B(-2,38,3,Leaves:4)
B(-2,39,3,Leaves:4)
B(-2,35,3,Leaves:4)
B(-2,36,3,Leaves:4)
B(-12,35,-6,Leaves:4)
B(-12,34,-6,Leaves:4)
B(-12,33,-6,Leaves:4)
B(7,-1,0,LOG:12)
B(7,-2,0,LOG:12)
B(7,-3,0,LOG:12)
B(13,37,-7,Leaves:4)
B(7,-4,0,LOG:12)
B(7,-5,0,LOG:12)
B(13,38,-7,Leaves:4)
B(-2,40,3,Leaves:4)
B(7,-6,0,LOG:12)
B(13,39,-7,Leaves:4)
B(7,-7,0,LOG:12)
B(7,-8,0,LOG:12)
B(-12,39,-6,Leaves:4)
B(7,-9,0,LOG:12)
B(-12,38,-6,Leaves:4)
B(-12,37,-6,Leaves:4)
B(-12,36,-6,Leaves:4)
B(-2,46,3,Leaves:4)
B(-2,47,3,Leaves:4)
B(-20,36,16,Leaves:4)
B(-20,37,16,Leaves:4)
B(-2,44,3,Leaves:4)
B(-20,38,16,Leaves:4)
B(-20,39,16,Leaves:4)
B(-2,48,3,Leaves:4)
B(-2,49,3,Leaves:4)
B(-4,-6,-10,LOG:12)
B(-4,-7,-10,LOG:12)
B(-20,34,16,Leaves:4)
B(-12,40,-6,Leaves:4)
B(12,34,-26,Leaves:4)
B(12,33,-26,Leaves:4)
B(-12,41,-6,Leaves:4)
B(-4,-8,-10,LOG:12)
B(-12,43,-6,Leaves:4)
B(2,-7,0,LOG:12)
B(12,30,-26,Leaves:4)
B(12,36,-26,Leaves:4)
B(12,35,-26,Leaves:4)
B(-2,52,3,Leaves:4)
B(-2,51,3,Leaves:4)
B(12,37,-26,Leaves:4)
B(-4,-9,5,LOG:12)
B(2,-4,0,LOG:12)
B(-4,-6,5,LOG:12)
B(-20,40,16,Leaves:4)
B(2,-3,0,LOG:12)
B(-4,-5,5,LOG:12)
B(-20,41,16,Leaves:4)
B(-4,-8,5,LOG:12)
B(-4,-7,5,LOG:12)
B(-20,45,16,Leaves:4)
B(2,-2,0,LOG:12)
B(-4,-4,5,LOG:12)
B(-20,42,16,Leaves:4)
B(2,-1,0,LOG:12)
B(-20,43,16,Leaves:4)
B(13,52,-7,Leaves:4)
B(5,39,-4,Leaves:4)
B(5,36,-4,Leaves:4)
B(5,35,-4,Leaves:4)
B(32,39,-10,Leaves:4)
B(32,37,-10,Leaves:4)
B(5,46,-4,Leaves:4)
B(5,44,-4,Leaves:4)
B(5,45,-4,Leaves:4)
B(-28,40,8,Leaves:4)
B(-28,41,8,Leaves:4)
B(-28,42,8,Leaves:4)
B(5,43,-4,Leaves:4)
B(5,40,-4,Leaves:4)
B(-32,41,6,Leaves:4)
B(-13,40,12,Leaves:4)
B(-13,41,12,Leaves:4)
B(-13,44,12,Leaves:4)
B(-13,45,12,Leaves:4)
B(-13,42,12,Leaves:4)
B(-13,43,12,Leaves:4)
B(5,14,-4,Leaves:4)
B(5,13,-4,Leaves:4)
B(13,19,-7,LOG:12)
B(-28,39,8,Leaves:4)
B(-28,38,8,Leaves:4)
B(7,46,10,Leaves:4)
B(7,45,10,Leaves:4)
B(7,44,10,Leaves:4)
B(5,10,-4,LOG:12)
B(5,11,-4,LOG:12)
B(5,12,-4,LOG:12)
B(-13,49,12,Leaves:4)
B(-13,48,12,Leaves:4)
B(-13,47,12,Leaves:4)
B(-13,46,12,Leaves:4)
B(13,21,-7,LOG:12)
B(7,43,10,Leaves:4)
B(13,20,-7,LOG:12)
B(7,42,10,Leaves:4)
B(7,41,10,Leaves:4)
B(7,40,10,Leaves:4)
B(2,36,25,Leaves:4)
B(2,35,25,Leaves:4)
B(2,34,25,Leaves:4)
B(4,34,25,Leaves:4)
B(7,34,10,LOG:12)
B(7,33,10,LOG:12)
B(7,38,10,Leaves:4)
B(7,37,10,Leaves:4)
B(13,18,-7,LOG:12)
B(13,17,-7,LOG:12)
B(2,32,25,Leaves:4)
B(2,33,25,Leaves:4)
B(21,35,-33,Leaves:4)
B(7,43,0,Leaves:4)
B(21,36,-33,Leaves:4)
B(7,44,0,Leaves:4)
B(7,45,0,Leaves:4)
B(21,33,-33,Leaves:4)
B(7,46,0,Leaves:4)
B(7,47,0,Leaves:4)
B(7,48,0,Leaves:4)
B(5,29,4,LOG:12)
B(28,43,-20,Leaves:4)
B(5,27,4,LOG:12)
B(28,41,-20,Leaves:4)
B(4,42,25,Leaves:4)
B(5,28,4,LOG:12)
B(4,41,25,Leaves:4)
B(5,25,4,LOG:12)
B(5,26,4,LOG:12)
B(4,47,25,Leaves:4)
B(7,-9,10,LOG:12)
B(7,-6,10,LOG:12)
B(4,43,25,Leaves:4)
B(7,-5,10,Leaves:4)
B(7,-8,10,LOG:12)
B(4,46,25,Leaves:4)
B(7,-7,10,LOG:12)
B(7,40,0,Leaves:4)
B(10,-8,14,LOG:12)
B(7,42,0,Leaves:4)
B(10,-7,14,LOG:12)
B(7,41,0,Leaves:4)
B(-13,39,12,Leaves:4)
B(-13,35,12,Leaves:4)
B(7,-3,10,LOG:12)
B(7,-4,10,Leaves:4)
B(8,0,3,LOG:12)
B(-1,37,9,Leaves:4)
B(8,1,3,Leaves:4)
B(22,37,10,Leaves:4)
B(-1,36,9,Leaves:4)
B(8,2,3,LOG:12)
B(-1,35,9,Leaves:4)
B(22,38,10,Leaves:4)
B(22,40,10,Leaves:4)
B(22,41,10,Leaves:4)
B(22,42,10,Leaves:4)
B(-6,38,21,Leaves:4)
B(-1,40,9,Leaves:4)
B(-1,46,9,Leaves:4)
B(-1,45,9,Leaves:4)
B(23,-2,-8,LOG:12)
B(-1,48,9,Leaves:4)
B(23,-5,-8,LOG:12)
B(-1,42,9,Leaves:4)
B(23,-6,-8,LOG:12)
B(-1,41,9,Leaves:4)
B(-1,44,9,Leaves:4)
B(23,-3,-8,LOG:12)
B(23,-4,-8,LOG:12)
B(-1,43,9,Leaves:4)
B(-6,41,21,Leaves:4)
B(-1,38,9,Leaves:4)
B(-1,39,9,Leaves:4)
B(-6,44,21,Leaves:4)
B(-6,42,21,Leaves:4)
B(28,35,-20,Leaves:4)
B(7,39,0,Leaves:4)
B(28,36,-20,Leaves:4)
B(38,38,-8,Leaves:4)
B(38,37,-8,Leaves:4)
B(28,38,-20,Leaves:4)
B(5,14,4,LOG:12)
B(5,15,4,LOG:12)
B(23,-8,-8,LOG:12)
B(23,-7,-8,LOG:12)
B(32,41,-10,Leaves:4)
B(23,-9,-8,LOG:12)
B(-8,50,-11,Leaves:4)
B(23,39,-8,Leaves:4)
B(-8,51,-11,Leaves:4)
B(22,33,-31,Leaves:4)
B(22,32,-31,Leaves:4)
B(22,35,-31,Leaves:4)
B(23,35,-8,Leaves:4)
B(23,34,-8,Leaves:4)
B(23,33,-8,Leaves:4)
B(23,32,-8,Leaves:4)
B(-12,41,18,Leaves:4)
B(-12,42,18,Leaves:4)
B(-12,43,18,Leaves:4)
B(-12,40,18,Leaves:4)
B(-8,45,-11,Leaves:4)
B(22,36,-31,Leaves:4)
B(22,37,-31,Leaves:4)
B(-8,44,-11,Leaves:4)
B(-8,47,-11,Leaves:4)
B(-8,46,-11,Leaves:4)
B(22,39,-31,Leaves:4)
B(-8,49,-11,Leaves:4)
B(-8,48,-11,Leaves:4)
B(7,-8,8,LOG:12)
B(23,47,-8,Leaves:4)
B(8,-8,1,LOG:12)
B(7,-5,8,LOG:12)
B(-8,42,-11,Leaves:4)
B(23,46,-8,Leaves:4)
B(7,-4,8,Leaves:4)
B(8,-9,1,LOG:12)
B(-8,43,-11,Leaves:4)
B(7,-7,8,LOG:12)
B(8,-6,1,LOG:12)
B(-8,40,-11,Leaves:4)
B(8,-7,1,LOG:12)
B(7,-6,8,LOG:12)
B(-8,41,-11,Leaves:4)
B(7,13,0,LOG:12)
B(8,-4,1,LOG:12)
B(23,43,-8,Leaves:4)
B(7,12,0,LOG:12)
B(8,-5,1,LOG:12)
B(23,42,-8,Leaves:4)
B(23,45,-8,Leaves:4)
B(7,11,0,LOG:12)
B(8,-2,1,LOG:12)
B(7,10,0,LOG:12)
B(8,-3,1,LOG:12)
B(23,44,-8,Leaves:4)
B(10,36,14,LOG:12)
B(10,35,14,LOG:12)
B(8,-1,1,LOG:12)
B(10,34,14,LOG:12)
B(7,14,0,LOG:12)
B(23,40,-8,Leaves:4)
B(7,-1,8,LOG:12)
B(7,-2,8,LOG:12)
B(7,-3,8,Leaves:4)
B(-8,39,-11,Leaves:4)
B(10,44,14,Leaves:4)
B(10,47,14,Leaves:4)
B(10,46,14,Leaves:4)
B(-10,38,22,Leaves:4)
B(-10,37,22,Leaves:4)
B(11,29,-21,Leaves:4)
B(10,38,14,Leaves:4)
B(-22,44,1,Leaves:4)
B(5,-1,4,LOG:12)
B(-22,43,1,Leaves:4)
B(-22,42,1,Leaves:4)
B(5,-3,4,LOG:12)
B(5,-2,4,LOG:12)
B(5,-5,4,LOG:12)
B(5,-4,4,LOG:12)
B(11,33,-21,Leaves:4)
B(11,34,-21,Leaves:4)
B(5,-6,4,LOG:12)
B(11,35,-21,Leaves:4)
B(11,36,-21,Leaves:4)
B(-22,41,1,Leaves:4)
B(11,30,-21,Leaves:4)
B(11,31,-21,Leaves:4)
B(10,51,14,Leaves:4)
B(11,32,-21,Leaves:4)
B(11,37,-21,Leaves:4)
B(-3,41,22,Leaves:4)
B(-3,40,22,Leaves:4)
B(-3,43,22,Leaves:4)
B(-3,42,22,Leaves:4)
B(8,10,1,LOG:12)
B(8,11,1,LOG:12)
B(-31,40,8,Leaves:4)
B(-31,42,8,Leaves:4)
B(27,41,13,Leaves:4)
B(-19,41,-18,Leaves:4)
B(1,37,-11,Leaves:4)
B(-19,40,-18,Leaves:4)
B(1,38,-11,Leaves:4)
B(11,-8,16,LOG:12)
B(11,-6,16,LOG:12)
B(11,-7,16,LOG:12)
B(-31,39,8,Leaves:4)
B(34,42,-4,Leaves:4)
B(34,40,-4,Leaves:4)
B(34,41,-4,Leaves:4)
B(25,36,-27,Leaves:4)
B(1,42,-11,Leaves:4)
B(25,35,-27,Leaves:4)
B(1,40,-11,Leaves:4)
B(1,41,-11,Leaves:4)
B(15,36,-14,Leaves:4)
B(15,35,-14,Leaves:4)
B(15,34,-14,Leaves:4)
B(15,39,-14,Leaves:4)
B(1,39,-11,Leaves:4)
B(15,38,-14,Leaves:4)
B(15,37,-14,Leaves:4)
B(-9,44,-5,Leaves:4)
B(-9,45,-5,Leaves:4)
B(-9,47,-5,Leaves:4)
B(-9,40,-5,Leaves:4)
B(-9,41,-5,Leaves:4)
B(-9,43,-5,Leaves:4)
B(15,45,-14,Leaves:4)
B(15,44,-14,Leaves:4)
B(15,46,-14,Leaves:4)
B(15,41,-14,Leaves:4)
B(15,40,-14,Leaves:4)
B(15,43,-14,Leaves:4)
B(15,42,-14,Leaves:4)
B(15,49,-14,Leaves:4)
B(15,48,-14,Leaves:4)
B(42,37,-8,Leaves:4)
B(-3,43,-11,Leaves:4)
B(11,36,16,Leaves:4)
B(11,37,16,Leaves:4)
B(8,40,1,Leaves:4)
B(8,42,1,Leaves:4)
B(8,47,1,Leaves:4)
B(8,48,1,Leaves:4)
B(-19,37,-18,Leaves:4)
B(-19,36,-18,Leaves:4)
B(-19,38,-18,Leaves:4)
B(34,36,-4,Leaves:4)
B(8,39,1,Leaves:4)
B(34,38,-4,Leaves:4)
B(34,37,-4,Leaves:4)
B(11,39,16,Leaves:4)
B(11,38,16,Leaves:4)
B(5,41,4,Leaves:4)
B(5,42,4,Leaves:4)
B(5,43,4,Leaves:4)
B(5,44,4,Leaves:4)
B(5,40,4,Leaves:4)
B(-3,32,-11,Leaves:4)
B(5,49,4,Leaves:4)
B(-3,33,-11,Leaves:4)
B(-3,34,-11,Leaves:4)
B(-3,35,-11,Leaves:4)
B(5,46,4,Leaves:4)
B(23,46,-13,Leaves:4)
B(5,45,4,Leaves:4)
B(11,40,16,Leaves:4)
B(5,48,4,Leaves:4)
B(23,44,-13,Leaves:4)
B(5,47,4,Leaves:4)
B(23,45,-13,Leaves:4)
B(-1,-6,-6,LOG:12)
B(23,42,-13,Leaves:4)
B(11,43,16,Leaves:4)
B(11,44,16,Leaves:4)
B(-1,-7,-6,LOG:12)
B(23,43,-13,Leaves:4)
B(-1,-8,-6,LOG:12)
B(23,40,-13,Leaves:4)
B(11,41,16,Leaves:4)
B(23,41,-13,Leaves:4)
B(11,42,16,Leaves:4)
B(11,47,16,Leaves:4)
B(-3,36,-11,Leaves:4)
B(-1,-3,-6,LOG:12)
B(11,45,16,Leaves:4)
B(-1,-4,-6,LOG:12)
B(11,46,16,Leaves:4)
B(-1,-5,-6,LOG:12)
B(7,45,-13,Leaves:4)
B(19,18,8,Leaves:4)
B(7,44,-13,Leaves:4)
B(7,43,-13,Leaves:4)
B(7,42,-13,Leaves:4)
B(7,40,-13,Leaves:4)
B(2,37,0,Leaves:4)
B(7,41,-13,Leaves:4)
B(2,36,0,Leaves:4)
B(23,36,-29,Leaves:4)
B(23,37,-29,Leaves:4)
B(23,34,-29,Leaves:4)
B(-1,39,-6,Leaves:4)
B(23,35,-29,Leaves:4)
B(-1,38,-6,Leaves:4)
B(19,20,8,Leaves:4)
B(23,38,-29,Leaves:4)
B(23,39,-29,Leaves:4)
B(2,42,0,Leaves:4)
B(2,45,0,Leaves:4)
B(2,44,0,Leaves:4)
B(-1,40,-6,Leaves:4)
B(23,40,-29,Leaves:4)
B(-1,43,-6,Leaves:4)
B(2,47,0,Leaves:4)
B(-1,47,-6,Leaves:4)
B(2,46,0,Leaves:4)
B(19,19,8,Leaves:4)
B(2,49,0,Leaves:4)
B(2,48,0,Leaves:4)
B(-1,46,-6,Leaves:4)
B(-6,39,-9,Leaves:4)
B(7,25,-13,LOG:12)
B(7,24,-13,LOG:12)
B(7,23,-13,LOG:12)
B(19,39,8,Leaves:4)
B(7,22,-13,LOG:12)
B(19,37,8,Leaves:4)
B(19,38,8,Leaves:4)
B(2,51,0,Leaves:4)
B(-2,-4,3,LOG:12)
B(2,50,0,Leaves:4)
B(-1,34,-6,Leaves:4)
B(-6,42,-9,Leaves:4)
B(-1,36,-6,Leaves:4)
B(-1,37,-6,Leaves:4)
B(-6,40,-9,Leaves:4)
B(-6,45,-9,Leaves:4)
B(-2,-7,3,LOG:12)
B(-6,46,-9,Leaves:4)
B(-2,-8,3,LOG:12)
B(-1,32,-6,Leaves:4)
B(-2,-5,3,LOG:12)
B(-2,-6,3,LOG:12)
B(-6,44,-9,Leaves:4)
B(7,36,-13,Leaves:4)
B(19,45,8,Leaves:4)
B(7,35,-13,Leaves:4)
B(-6,25,-9,LOG:12)
B(19,46,8,Leaves:4)
B(7,37,-13,Leaves:4)
B(-32,39,6,Leaves:4)
B(20,40,14,Leaves:4)
B(20,41,14,Leaves:4)
B(20,42,14,Leaves:4)
B(20,43,14,Leaves:4)
B(19,40,8,Leaves:4)
B(19,41,8,Leaves:4)
B(19,42,8,Leaves:4)
B(20,39,14,Leaves:4)
B(-6,34,-9,Leaves:4)
B(19,53,8,Leaves:4)
B(19,52,8,Leaves:4)
B(19,51,8,Leaves:4)
B(-9,36,-5,Leaves:4)
B(-9,38,-5,Leaves:4)
B(-9,39,-5,Leaves:4)
B(15,28,-14,LOG:12)
B(15,29,-14,LOG:12)
B(15,26,-14,LOG:12)
B(15,27,-14,LOG:12)
B(20,20,14,Leaves:4)
B(15,25,-14,LOG:12)
B(20,19,14,Leaves:4)
B(-2,20,3,LOG:12)
B(-2,21,3,LOG:12)
B(2,15,0,LOG:12)
B(2,16,0,LOG:12)
B(2,13,0,LOG:12)
B(2,14,0,LOG:12)
B(2,19,0,LOG:12)
B(2,17,0,LOG:12)
B(2,18,0,LOG:12)
B(2,11,0,LOG:12)
B(2,12,0,LOG:12)
B(2,10,0,LOG:12)
B(33,40,-15,Leaves:4)
B(21,0,-7,LOG:12)
B(2,20,0,LOG:12)
B(2,21,0,LOG:12)
B(-25,44,2,Leaves:4)
B(-25,45,2,Leaves:4)
B(8,-4,10,Leaves:4)
B(-30,39,9,Leaves:4)
B(8,-5,10,LOG:12)
B(8,-6,10,LOG:12)
B(8,-7,10,LOG:12)
B(-24,44,8,Leaves:4)
B(-24,45,8,Leaves:4)
B(-21,33,-8,Leaves:4)
B(-21,34,-8,Leaves:4)
B(-21,35,-8,Leaves:4)
B(-21,36,-8,Leaves:4)
B(-21,37,-8,Leaves:4)
B(-21,38,-8,Leaves:4)
B(-21,39,-8,Leaves:4)
B(-30,40,9,Leaves:4)
B(-24,40,8,Leaves:4)
B(-24,41,8,Leaves:4)
B(-30,42,9,Leaves:4)
B(-30,41,9,Leaves:4)
B(-24,39,8,Leaves:4)
B(-24,38,8,Leaves:4)
B(-24,37,8,Leaves:4)
B(-24,36,8,Leaves:4)
B(-24,35,8,Leaves:4)
B(1,-5,5,LOG:12)
B(1,-4,5,LOG:12)
B(1,-3,5,LOG:12)
B(-8,-7,7,LOG:12)
B(-8,-8,7,LOG:12)
B(1,-2,5,LOG:12)
B(1,-1,5,LOG:12)
B(-11,39,16,Leaves:4)
B(-11,38,16,Leaves:4)
B(-8,-6,7,LOG:12)
B(-8,-5,7,LOG:12)
B(0,45,-5,Leaves:4)
B(0,46,-5,Leaves:4)
B(0,41,-5,Leaves:4)
B(0,40,-5,Leaves:4)
B(0,43,-5,Leaves:4)
B(-31,39,6,Leaves:4)
B(1,38,5,Leaves:4)
B(1,34,5,Leaves:4)
B(0,39,-5,Leaves:4)
B(0,38,-5,Leaves:4)
B(2,39,-20,Leaves:4)
B(0,36,-5,Leaves:4)
B(1,39,5,Leaves:4)
B(1,40,5,Leaves:4)
B(1,46,5,Leaves:4)
B(1,47,5,Leaves:4)
B(1,48,5,Leaves:4)
B(1,49,5,Leaves:4)
B(1,42,5,Leaves:4)
B(1,43,5,Leaves:4)
B(1,44,5,Leaves:4)
B(1,45,5,Leaves:4)
B(-2,40,20,Leaves:4)
B(-2,41,20,Leaves:4)
B(-2,42,20,Leaves:4)
B(-2,43,20,Leaves:4)
B(-2,47,20,Leaves:4)
B(8,47,-13,Leaves:4)
B(-2,48,20,Leaves:4)
B(8,45,-13,Leaves:4)
B(8,46,-13,Leaves:4)
B(8,43,-13,Leaves:4)
B(8,44,-13,Leaves:4)
B(-20,39,14,Leaves:4)
B(8,42,-13,Leaves:4)
B(8,41,-13,Leaves:4)
B(8,40,-13,Leaves:4)
B(-20,38,14,Leaves:4)
B(2,36,-20,Leaves:4)
B(2,37,-20,Leaves:4)
B(8,36,-13,Leaves:4)
B(8,37,-13,Leaves:4)
B(8,38,-13,Leaves:4)
B(8,39,-13,Leaves:4)
B(8,35,-13,Leaves:4)
B(-2,39,20,Leaves:4)
B(36,35,0,Leaves:4)
B(1,22,5,LOG:12)
B(36,34,0,Leaves:4)
B(1,23,5,LOG:12)
B(1,24,5,LOG:12)
B(1,25,5,LOG:12)
B(-20,40,14,Leaves:4)
B(36,37,0,Leaves:4)
B(36,36,0,Leaves:4)
B(36,39,0,Leaves:4)
B(36,38,0,Leaves:4)
B(1,36,-24,Leaves:4)
B(37,37,-1,Leaves:4)
B(16,27,-19,Leaves:4)
B(37,35,-1,Leaves:4)
B(16,28,-19,Leaves:4)
B(1,39,-24,Leaves:4)
B(37,36,-1,Leaves:4)
B(16,29,-19,Leaves:4)
B(1,37,-24,Leaves:4)
B(1,38,-24,Leaves:4)
B(20,18,16,Leaves:4)
B(20,19,16,Leaves:4)
B(17,20,12,Leaves:4)
B(16,30,-19,Leaves:4)
B(28,32,-34,Leaves:4)
B(16,32,-19,Leaves:4)
B(28,33,-34,Leaves:4)
B(16,31,-19,Leaves:4)
B(16,34,-19,Leaves:4)
B(16,33,-19,Leaves:4)
B(1,44,-24,Leaves:4)
B(-5,39,17,Leaves:4)
B(-5,38,17,Leaves:4)
B(1,40,-24,Leaves:4)
B(1,41,-24,Leaves:4)
B(-5,40,17,Leaves:4)
B(-5,41,17,Leaves:4)
B(17,13,12,Leaves:4)
B(17,17,12,Leaves:4)
B(17,14,12,Leaves:4)
B(17,15,12,Leaves:4)
B(17,18,12,Leaves:4)
B(17,19,12,Leaves:4)
B(16,46,-19,Leaves:4)
B(16,47,-19,Leaves:4)
B(6,46,11,Leaves:4)
B(6,47,11,Leaves:4)
B(6,44,11,Leaves:4)
B(6,45,11,Leaves:4)
B(6,42,11,Leaves:4)
B(-5,43,17,Leaves:4)
B(-5,42,17,Leaves:4)
B(6,40,11,Leaves:4)
B(6,41,11,Leaves:4)
B(17,43,12,Leaves:4)
B(17,44,12,Leaves:4)
B(17,45,12,Leaves:4)
B(17,46,12,Leaves:4)
B(17,40,12,Leaves:4)
B(17,41,12,Leaves:4)
B(17,42,12,Leaves:4)
B(2,-4,-2,LOG:12)
B(2,-5,-2,LOG:12)
B(2,-6,-2,LOG:12)
B(2,-7,-2,LOG:12)
B(17,47,12,Leaves:4)
B(2,-1,-2,LOG:12)
B(2,-2,-2,LOG:12)
B(2,-3,-2,LOG:12)
B(19,36,-34,Leaves:4)
B(16,39,-19,Leaves:4)
B(19,35,-34,Leaves:4)
B(16,37,-19,Leaves:4)
B(19,33,-34,Leaves:4)
B(16,38,-19,Leaves:4)
B(16,35,-19,Leaves:4)
B(16,36,-19,Leaves:4)
B(19,31,-34,Leaves:4)
B(16,45,-19,Leaves:4)
B(-21,37,15,Leaves:4)
B(16,44,-19,Leaves:4)
B(16,43,-19,Leaves:4)
B(-21,39,15,Leaves:4)
B(16,42,-19,Leaves:4)
B(17,38,12,Leaves:4)
B(17,39,12,Leaves:4)
B(16,40,-19,Leaves:4)
B(29,34,3,Leaves:4)
B(29,33,3,Leaves:4)
B(21,36,-31,Leaves:4)
B(21,35,-31,Leaves:4)
B(21,38,-31,Leaves:4)
B(21,37,-31,Leaves:4)
B(2,35,-2,Leaves:4)
B(-8,44,7,Leaves:4)
B(2,37,-2,Leaves:4)
B(-8,45,7,Leaves:4)
B(2,36,-2,Leaves:4)
B(-18,40,-19,Leaves:4)
B(-21,44,15,Leaves:4)
B(2,39,-2,Leaves:4)
B(-8,42,7,Leaves:4)
B(-21,45,15,Leaves:4)
B(21,30,-31,Leaves:4)
B(2,38,-2,Leaves:4)
B(-8,43,7,Leaves:4)
B(21,31,-31,Leaves:4)
B(21,32,-31,Leaves:4)
B(-8,41,7,Leaves:4)
B(21,33,-31,Leaves:4)
B(19,30,-34,Leaves:4)
B(21,34,-31,Leaves:4)
B(-21,42,15,Leaves:4)
B(-8,46,7,Leaves:4)
B(-21,40,15,Leaves:4)
B(-8,47,7,Leaves:4)
B(-21,41,15,Leaves:4)
B(2,41,-2,Leaves:4)
B(6,38,11,Leaves:4)
B(2,40,-2,Leaves:4)
B(6,39,11,Leaves:4)
B(2,43,-2,Leaves:4)
B(8,2,2,LOG:12)
B(8,3,2,LOG:12)
B(2,48,-2,Leaves:4)
B(8,0,2,LOG:12)
B(8,1,2,LOG:12)
B(29,50,3,Leaves:4)
B(2,10,-2,LOG:12)
B(2,11,-2,LOG:12)
B(2,12,-2,LOG:12)
B(2,13,-2,LOG:12)
B(-10,39,24,Leaves:4)
B(2,18,-2,LOG:12)
B(-10,38,24,Leaves:4)
B(2,15,-2,LOG:12)
B(2,14,-2,LOG:12)
B(2,17,-2,LOG:12)
B(2,16,-2,LOG:12)
B(29,46,3,Leaves:4)
B(29,47,3,Leaves:4)
B(29,48,3,Leaves:4)
B(29,49,3,Leaves:4)
B(29,45,3,Leaves:4)
B(29,44,3,Leaves:4)
B(29,43,3,Leaves:4)
B(29,42,3,Leaves:4)
B(29,41,3,Leaves:4)
B(29,40,3,Leaves:4)
B(-6,43,-30,Leaves:4)
B(-6,44,-30,Leaves:4)
B(29,37,3,Leaves:4)
B(-6,41,-30,Leaves:4)
B(29,36,3,Leaves:4)
B(-3,45,-13,Leaves:4)
B(-3,41,-13,Leaves:4)
B(-3,42,-13,Leaves:4)
B(-7,33,11,LOG:12)
B(-7,34,11,LOG:12)
B(-7,32,11,LOG:12)
B(3,36,-32,Leaves:4)
B(3,35,-32,Leaves:4)
B(3,34,-32,Leaves:4)
B(3,33,-32,Leaves:4)
B(-4,44,-22,Leaves:4)
B(-4,42,-22,Leaves:4)
B(-4,43,-22,Leaves:4)
B(-4,40,-22,Leaves:4)
B(-4,41,-22,Leaves:4)
B(-13,36,-15,Leaves:4)
B(-13,39,-15,Leaves:4)
B(-13,38,-15,Leaves:4)
B(-13,37,-15,Leaves:4)
B(-18,37,-19,Leaves:4)
B(-18,38,-19,Leaves:4)
B(9,-10,1,LOG:12)
B(-18,39,-19,Leaves:4)
B(-16,36,19,Leaves:4)
B(-16,37,19,Leaves:4)
B(-16,34,19,Leaves:4)
B(-13,44,-15,Leaves:4)
B(18,27,-6,LOG:12)
B(18,26,-6,LOG:12)
B(-13,41,-15,Leaves:4)
B(-13,40,-15,Leaves:4)
B(-13,43,-15,Leaves:4)
B(26,33,-33,Leaves:4)
B(-16,41,19,Leaves:4)
B(26,32,-33,Leaves:4)
B(26,36,-33,Leaves:4)
B(26,35,-33,Leaves:4)
B(-16,43,19,Leaves:4)
B(26,34,-33,Leaves:4)
B(-16,42,19,Leaves:4)
B(18,37,-6,Leaves:4)
B(18,38,-6,Leaves:4)
B(18,36,-6,Leaves:4)
B(18,44,-6,Leaves:4)
B(18,43,-6,Leaves:4)
B(18,42,-6,Leaves:4)
B(18,41,-6,Leaves:4)
B(18,40,-6,Leaves:4)
B(-12,39,18,Leaves:4)
B(-12,38,18,Leaves:4)
B(-12,35,18,Leaves:4)
B(-12,37,18,Leaves:4)
B(-12,36,18,Leaves:4)
B(4,41,-16,Leaves:4)
B(18,46,-6,Leaves:4)
B(18,48,-6,Leaves:4)
B(4,44,-16,Leaves:4)
B(4,33,-16,Leaves:4)
B(-10,42,-19,Leaves:4)
B(4,34,-16,Leaves:4)
B(-10,41,-19,Leaves:4)
B(4,32,-16,Leaves:4)
B(4,37,-16,Leaves:4)
B(4,38,-16,Leaves:4)
B(4,35,-16,Leaves:4)
B(-10,40,-19,Leaves:4)
B(18,0,-3,LOG:12)
B(-10,45,-19,Leaves:4)
B(4,27,-16,LOG:12)
B(12,19,21,Leaves:4)
B(12,18,21,Leaves:4)
B(12,17,21,Leaves:4)
B(-14,35,-10,Leaves:4)
B(-14,36,-10,Leaves:4)
B(-14,34,-10,Leaves:4)
B(19,38,-29,Leaves:4)
B(19,40,-29,Leaves:4)
B(-22,43,21,Leaves:4)
B(-10,37,-19,Leaves:4)
B(-10,38,-19,Leaves:4)
B(-10,39,-19,Leaves:4)
B(12,50,7,Leaves:4)
B(12,51,7,Leaves:4)
B(12,52,7,Leaves:4)
B(19,36,-29,Leaves:4)
B(12,45,7,Leaves:4)
B(12,44,7,Leaves:4)
B(8,22,-13,LOG:12)
B(12,49,7,Leaves:4)
B(8,24,-13,LOG:12)
B(8,23,-13,LOG:12)
B(12,40,7,Leaves:4)
B(12,41,7,Leaves:4)
B(12,42,7,Leaves:4)
B(12,43,7,Leaves:4)
B(12,37,7,Leaves:4)
B(8,31,10,LOG:12)
B(8,33,10,LOG:12)
B(8,32,10,LOG:12)
B(8,35,10,LOG:12)
B(8,34,10,LOG:12)
B(-3,52,-1,Leaves:4)
B(8,42,10,Leaves:4)
B(8,41,10,Leaves:4)
B(8,40,10,Leaves:4)
B(-3,42,-1,Leaves:4)
B(-3,48,-1,Leaves:4)
B(12,22,7,Leaves:4)
B(8,47,10,Leaves:4)
B(8,46,10,Leaves:4)
B(12,21,7,Leaves:4)
B(12,20,7,Leaves:4)
B(12,19,7,Leaves:4)
B(12,16,7,Leaves:4)
B(12,18,7,Leaves:4)
B(-4,49,5,Leaves:4)
B(30,38,-2,Leaves:4)
B(12,42,21,Leaves:4)
B(-4,48,5,Leaves:4)
B(12,44,21,Leaves:4)
B(12,45,21,Leaves:4)
B(30,39,-2,Leaves:4)
B(15,43,19,Leaves:4)
B(15,41,19,Leaves:4)
B(15,40,19,Leaves:4)
B(-4,50,5,Leaves:4)
B(30,47,-2,Leaves:4)
B(27,34,-29,Leaves:4)
B(30,46,-2,Leaves:4)
B(27,35,-29,Leaves:4)
B(-4,39,-22,Leaves:4)
B(30,45,-2,Leaves:4)
B(-4,38,-22,Leaves:4)
B(-4,37,-22,Leaves:4)
B(30,44,-2,Leaves:4)
B(-4,39,5,Leaves:4)
B(30,48,-2,Leaves:4)
B(-4,32,-22,Leaves:4)
B(-4,31,-22,Leaves:4)
B(-4,30,-22,Leaves:4)
B(-4,35,-22,Leaves:4)
B(30,42,-2,Leaves:4)
B(-4,34,-22,Leaves:4)
B(12,39,21,Leaves:4)
B(-4,33,-22,Leaves:4)
B(-4,46,5,Leaves:4)
B(12,41,21,Leaves:4)
B(-4,47,5,Leaves:4)
B(12,40,21,Leaves:4)
B(18,-1,-6,LOG:12)
B(-4,44,5,Leaves:4)
B(-4,45,5,Leaves:4)
B(18,-2,-6,LOG:12)
B(18,-3,-6,LOG:12)
B(-4,42,5,Leaves:4)
B(18,-4,-6,LOG:12)
B(-4,43,5,Leaves:4)
B(-4,41,5,Leaves:4)
B(12,20,21,Leaves:4)
B(-3,40,-13,Leaves:4)
B(15,21,19,Leaves:4)
B(30,50,-2,Leaves:4)
B(30,52,-2,Leaves:4)
B(30,54,-2,Leaves:4)
B(30,53,-2,Leaves:4)
B(-7,45,11,Leaves:4)
B(-3,39,-13,Leaves:4)
B(-7,44,11,Leaves:4)
B(-3,38,-13,Leaves:4)
B(-21,46,-2,Leaves:4)
B(-7,48,11,Leaves:4)
B(-7,47,11,Leaves:4)
B(-7,46,11,Leaves:4)
B(-4,35,5,Leaves:4)
B(-3,33,-13,Leaves:4)
B(-4,36,5,Leaves:4)
B(-7,41,11,Leaves:4)
B(-3,34,-13,Leaves:4)
B(-21,43,-2,Leaves:4)
B(-21,42,-2,Leaves:4)
B(-3,36,-13,Leaves:4)
B(-21,41,-2,Leaves:4)
B(17,34,-22,Leaves:4)
B(11,39,-3,Leaves:4)
B(17,30,-22,Leaves:4)
B(3,28,-18,LOG:12)
B(17,31,-22,Leaves:4)
B(-2,34,27,Leaves:4)
B(3,29,-18,LOG:12)
B(17,38,-22,Leaves:4)
B(17,39,-22,Leaves:4)
B(17,36,-22,Leaves:4)
B(17,37,-22,Leaves:4)
B(4,39,11,Leaves:4)
B(4,37,11,Leaves:4)
B(11,41,-3,Leaves:4)
B(11,40,-3,Leaves:4)
B(-17,36,14,Leaves:4)
B(11,43,-3,Leaves:4)
B(11,42,-3,Leaves:4)
B(11,47,-3,Leaves:4)
B(11,46,-3,Leaves:4)
B(-17,39,14,Leaves:4)
B(11,49,-3,Leaves:4)
B(-17,38,14,Leaves:4)
B(11,48,-3,Leaves:4)
B(-17,37,14,Leaves:4)
B(17,43,-22,Leaves:4)
B(17,44,-22,Leaves:4)
B(17,45,-22,Leaves:4)
B(17,40,-22,Leaves:4)
B(17,41,-22,Leaves:4)
B(17,42,-22,Leaves:4)
B(25,36,-29,Leaves:4)
B(11,33,-3,Leaves:4)
B(25,33,-29,Leaves:4)
B(11,38,-3,Leaves:4)
B(11,37,-3,Leaves:4)
B(11,36,-3,Leaves:4)
B(25,35,-29,Leaves:4)
B(11,35,-3,LOG:12)
B(25,34,-29,Leaves:4)
B(-18,50,9,Leaves:4)
B(8,48,3,Leaves:4)
B(8,49,3,Leaves:4)
B(0,33,26,Leaves:4)
B(8,44,3,Leaves:4)
B(0,34,26,Leaves:4)
B(8,43,3,Leaves:4)
B(8,46,3,Leaves:4)
B(0,35,26,Leaves:4)
B(8,45,3,Leaves:4)
B(0,32,26,Leaves:4)
B(-17,40,14,Leaves:4)
B(-17,41,14,Leaves:4)
B(-17,42,14,Leaves:4)
B(-17,43,14,Leaves:4)
B(0,45,26,Leaves:4)
B(0,42,26,Leaves:4)
B(8,51,3,Leaves:4)
B(8,50,3,Leaves:4)
B(0,41,26,Leaves:4)
B(11,55,-3,Leaves:4)
B(11,54,-3,Leaves:4)
B(13,45,-18,Leaves:4)
B(13,44,-18,Leaves:4)
B(13,42,-18,Leaves:4)
B(-17,39,1,Leaves:4)
B(13,48,-18,Leaves:4)
B(-17,37,1,Leaves:4)
B(13,46,-18,Leaves:4)
B(-17,38,1,Leaves:4)
B(-18,36,9,LOG:12)
B(-18,38,9,Leaves:4)
B(9,37,-21,Leaves:4)
B(-18,39,9,Leaves:4)
B(18,41,-20,Leaves:4)
B(18,40,-20,Leaves:4)
B(13,33,-18,Leaves:4)
B(18,45,-20,Leaves:4)
B(13,36,-18,Leaves:4)
B(4,-9,11,LOG:12)
B(34,36,-2,Leaves:4)
B(13,35,-18,Leaves:4)
B(-18,40,9,Leaves:4)
B(13,37,-18,Leaves:4)
B(18,42,-20,Leaves:4)
B(13,39,-18,Leaves:4)
B(-18,41,9,Leaves:4)
B(18,47,-20,Leaves:4)
B(18,46,-20,Leaves:4)
B(-18,48,9,Leaves:4)
B(-18,47,9,Leaves:4)
B(13,40,-18,Leaves:4)
B(13,41,-18,Leaves:4)
B(18,32,-20,Leaves:4)
B(18,31,-20,Leaves:4)
B(34,46,-2,Leaves:4)
B(18,34,-20,Leaves:4)
B(34,47,-2,Leaves:4)
B(18,33,-20,Leaves:4)
B(34,41,-2,Leaves:4)
B(18,30,-20,Leaves:4)
B(34,42,-2,Leaves:4)
B(-17,53,1,Leaves:4)
B(-17,54,1,Leaves:4)
B(18,39,-20,Leaves:4)
B(-17,51,1,Leaves:4)
B(18,36,-20,Leaves:4)
B(3,45,-18,Leaves:4)
B(18,35,-20,Leaves:4)
B(18,38,-20,Leaves:4)
B(18,37,-20,Leaves:4)
B(-17,50,1,Leaves:4)
B(4,-4,11,LOG:12)
B(4,-8,11,LOG:12)
B(34,38,-2,Leaves:4)
B(34,37,-2,Leaves:4)
B(4,-7,11,LOG:12)
B(4,-6,11,LOG:12)
B(4,-5,11,LOG:12)
B(-17,48,1,Leaves:4)
B(-17,49,1,Leaves:4)
B(17,28,-22,Leaves:4)
B(8,16,3,LOG:12)
B(17,29,-22,Leaves:4)
B(8,15,3,LOG:12)
B(-17,40,1,Leaves:4)
B(-17,41,1,Leaves:4)
B(-17,42,1,Leaves:4)
B(-17,43,1,Leaves:4)
B(3,33,-18,Leaves:4)
B(-17,45,1,Leaves:4)
B(-14,41,-4,Leaves:4)
B(-14,42,-4,Leaves:4)
B(-14,40,-4,Leaves:4)
B(-14,47,-4,Leaves:4)
B(-14,46,-4,Leaves:4)
B(-14,43,-4,Leaves:4)
B(-14,44,-4,Leaves:4)
B(-14,35,-4,Leaves:4)
B(-14,34,-4,Leaves:4)
B(-14,39,-4,Leaves:4)
B(-14,37,-4,Leaves:4)
B(-14,36,-4,Leaves:4)
B(1,34,-26,Leaves:4)
B(1,35,-26,Leaves:4)
B(1,36,-26,Leaves:4)
B(1,37,-26,Leaves:4)
B(1,38,-26,Leaves:4)
B(1,39,-26,Leaves:4)
B(6,34,-16,Leaves:4)
B(6,33,-16,Leaves:4)
B(6,36,-16,Leaves:4)
B(6,35,-16,Leaves:4)
B(6,38,-16,Leaves:4)
B(6,37,-16,Leaves:4)
B(6,39,-16,Leaves:4)
B(15,42,-16,Leaves:4)
B(15,43,-16,Leaves:4)
B(15,45,-16,Leaves:4)
B(9,41,-19,Leaves:4)
B(15,41,-16,Leaves:4)
B(15,40,-16,Leaves:4)
B(9,45,-19,Leaves:4)
B(9,44,-19,Leaves:4)
B(9,43,-19,Leaves:4)
B(9,46,-19,Leaves:4)
B(15,39,-16,Leaves:4)
B(2,44,-12,Leaves:4)
B(15,34,-16,Leaves:4)
B(2,42,-12,Leaves:4)
B(2,41,-12,Leaves:4)
B(2,40,-12,Leaves:4)
B(15,37,-16,Leaves:4)
B(15,38,-16,Leaves:4)
B(15,35,-16,Leaves:4)
B(15,36,-16,Leaves:4)
B(9,38,-19,Leaves:4)
B(0,35,21,Leaves:4)
B(-18,42,-22,Leaves:4)
B(0,34,21,Leaves:4)
B(-18,41,-22,Leaves:4)
B(0,33,21,Leaves:4)
B(-18,43,-22,Leaves:4)
B(11,-5,-3,LOG:12)
B(9,39,-19,Leaves:4)
B(0,39,21,Leaves:4)
B(0,38,21,Leaves:4)
B(11,-3,-3,LOG:12)
B(0,37,21,Leaves:4)
B(0,36,21,Leaves:4)
B(11,-4,-3,LOG:12)
B(11,-2,-3,LOG:12)
B(11,-1,-3,LOG:12)
B(8,-8,3,LOG:12)
B(8,-9,3,LOG:12)
B(8,-4,3,LOG:12)
B(7,44,-11,Leaves:4)
B(7,45,-11,Leaves:4)
B(8,-5,3,LOG:12)
B(7,46,-11,Leaves:4)
B(8,-6,3,LOG:12)
B(-18,39,-22,Leaves:4)
B(7,47,-11,Leaves:4)
B(8,-7,3,LOG:12)
B(-18,37,-22,Leaves:4)
B(7,40,-11,Leaves:4)
B(-18,36,-22,Leaves:4)
B(8,-1,3,LOG:12)
B(-18,35,-22,Leaves:4)
B(8,-2,3,LOG:12)
B(8,-3,3,Leaves:4)
B(-7,43,-15,Leaves:4)
B(-7,44,-15,Leaves:4)
B(-7,45,-15,Leaves:4)
B(-7,46,-15,Leaves:4)
B(11,39,14,Leaves:4)
B(-7,40,-15,Leaves:4)
B(-7,41,-15,Leaves:4)
B(-7,42,-15,Leaves:4)
B(11,46,14,Leaves:4)
B(23,41,-15,Leaves:4)
B(11,45,14,Leaves:4)
B(23,40,-15,Leaves:4)
B(11,44,14,Leaves:4)
B(11,43,14,Leaves:4)
B(-7,37,-15,Leaves:4)
B(7,36,-11,Leaves:4)
B(11,42,14,Leaves:4)
B(-7,36,-15,Leaves:4)
B(23,44,-15,Leaves:4)
B(23,43,-15,Leaves:4)
B(23,42,-15,Leaves:4)
B(7,38,-11,Leaves:4)
B(7,37,-11,Leaves:4)
B(0,40,21,Leaves:4)
B(0,41,21,Leaves:4)
B(-7,34,-15,Leaves:4)
B(-7,35,-15,Leaves:4)
B(-7,32,-15,Leaves:4)
B(-7,33,-15,Leaves:4)
B(11,47,14,Leaves:4)
B(11,48,14,Leaves:4)
B(7,21,-11,LOG:12)
B(11,51,14,Leaves:4)
B(7,23,-11,LOG:12)
B(7,22,-11,LOG:12)
B(7,25,-11,LOG:12)
B(7,24,-11,LOG:12)
B(7,27,-11,LOG:12)
B(7,26,-11,LOG:12)
B(7,29,-11,LOG:12)
B(7,28,-11,LOG:12)
B(2,37,-12,Leaves:4)
B(2,38,-12,Leaves:4)
B(2,39,-12,Leaves:4)
B(6,43,-16,Leaves:4)
B(6,41,-16,Leaves:4)
B(6,40,-16,Leaves:4)
B(-7,49,-15,Leaves:4)
B(23,39,-15,Leaves:4)
B(6,48,-16,Leaves:4)
B(-17,41,-24,Leaves:4)
B(6,49,-16,Leaves:4)
B(-17,40,-24,Leaves:4)
B(6,46,-16,Leaves:4)
B(23,38,-15,Leaves:4)
B(6,44,-16,Leaves:4)
B(6,45,-16,Leaves:4)
B(27,49,1,Leaves:4)
B(27,48,1,Leaves:4)
B(27,47,1,Leaves:4)
B(8,4,1,LOG:12)
B(27,46,1,Leaves:4)
B(8,3,1,LOG:12)
B(27,45,1,Leaves:4)
B(8,2,1,LOG:12)
B(8,1,1,LOG:12)
B(27,44,1,Leaves:4)
B(8,0,1,LOG:12)
B(27,43,1,Leaves:4)
B(-14,38,18,Leaves:4)
B(-14,35,18,Leaves:4)
B(8,9,1,LOG:12)
B(8,8,1,LOG:12)
B(8,7,1,LOG:12)
B(27,51,1,Leaves:4)
B(27,52,1,Leaves:4)
B(27,50,1,Leaves:4)
B(6,-5,11,LOG:12)
B(25,19,6,Leaves:4)
B(6,-6,11,LOG:12)
B(6,-3,11,LOG:12)
B(4,34,27,Leaves:4)
B(6,-4,11,Leaves:4)
B(27,38,1,Leaves:4)
B(27,37,1,Leaves:4)
B(-12,47,-4,Leaves:4)
B(-12,48,-4,Leaves:4)
B(-12,45,-4,Leaves:4)
B(-12,46,-4,Leaves:4)
B(-12,43,-4,Leaves:4)
B(-12,44,-4,Leaves:4)
B(-12,41,-4,Leaves:4)
B(-12,42,-4,Leaves:4)
B(27,39,1,Leaves:4)
B(-12,40,-4,Leaves:4)
B(27,40,1,Leaves:4)
B(27,41,1,Leaves:4)
B(25,41,6,Leaves:4)
B(25,40,6,Leaves:4)
B(-16,39,-18,Leaves:4)
B(-16,38,-18,Leaves:4)
B(25,39,6,Leaves:4)
B(25,37,6,Leaves:4)
B(25,36,6,Leaves:4)
B(25,35,6,Leaves:4)
B(6,40,19,Leaves:4)
B(-16,41,-18,Leaves:4)
B(25,33,6,Leaves:4)
B(-16,40,-18,Leaves:4)
B(6,41,19,Leaves:4)
B(6,-8,11,LOG:12)
B(4,41,27,Leaves:4)
B(6,42,19,Leaves:4)
B(6,-7,11,LOG:12)
B(4,42,27,Leaves:4)
B(6,43,19,Leaves:4)
B(6,44,19,Leaves:4)
B(4,43,27,Leaves:4)
B(6,45,19,Leaves:4)
B(4,44,27,Leaves:4)
B(6,-9,11,LOG:12)
B(10,-7,16,LOG:12)
B(10,-8,16,LOG:12)
B(15,19,13,Leaves:4)
B(15,18,13,Leaves:4)
B(15,17,13,Leaves:4)
B(10,-6,16,LOG:12)
B(6,47,19,Leaves:4)
B(6,46,19,Leaves:4)
B(4,45,27,Leaves:4)
B(6,49,19,Leaves:4)
B(6,48,19,Leaves:4)
B(4,47,27,Leaves:4)
B(15,16,13,Leaves:4)
B(14,49,14,Leaves:4)
B(14,48,14,Leaves:4)
B(12,29,-24,Leaves:4)
B(14,45,14,Leaves:4)
B(14,47,14,Leaves:4)
B(14,46,14,Leaves:4)
B(-13,38,-23,Leaves:4)
B(-13,39,-23,Leaves:4)
B(6,39,19,Leaves:4)
B(15,20,13,Leaves:4)
B(15,21,13,Leaves:4)
B(14,51,14,Leaves:4)
B(-13,40,-23,Leaves:4)
B(14,50,14,Leaves:4)
B(14,39,14,Leaves:4)
B(14,38,14,Leaves:4)
B(12,37,-24,Leaves:4)
B(12,35,-24,Leaves:4)
B(12,34,-24,Leaves:4)
B(12,33,-24,Leaves:4)
B(12,32,-24,Leaves:4)
B(15,41,13,Leaves:4)
B(12,31,-24,Leaves:4)
B(15,40,13,Leaves:4)
B(25,51,6,Leaves:4)
B(12,30,-24,Leaves:4)
B(-2,50,5,Leaves:4)
B(25,52,6,Leaves:4)
B(-2,46,5,Leaves:4)
B(-2,47,5,Leaves:4)
B(-2,48,5,Leaves:4)
B(-2,49,5,Leaves:4)
B(14,42,14,Leaves:4)
B(14,40,14,Leaves:4)
B(14,41,14,Leaves:4)
B(15,39,13,Leaves:4)
B(-12,33,-4,Leaves:4)
B(-12,32,-4,Leaves:4)
B(-12,35,-4,Leaves:4)
B(-12,34,-4,Leaves:4)
B(-12,37,-4,Leaves:4)
B(-12,36,-4,Leaves:4)
B(-12,39,-4,Leaves:4)
B(-12,38,-4,Leaves:4)
B(15,52,13,Leaves:4)
B(15,43,13,Leaves:4)
B(15,44,13,Leaves:4)
B(15,45,13,Leaves:4)
B(18,0,-2,LOG:12)
B(15,48,13,Leaves:4)
B(15,49,13,Leaves:4)
B(36,33,-1,Leaves:4)
B(36,32,-1,Leaves:4)
B(36,39,-1,Leaves:4)
B(-14,43,18,Leaves:4)
B(36,34,-1,Leaves:4)
B(14,18,14,Leaves:4)
B(36,35,-1,Leaves:4)
B(14,17,14,Leaves:4)
B(36,36,-1,Leaves:4)
B(14,16,14,Leaves:4)
B(36,37,-1,Leaves:4)
B(-14,42,18,Leaves:4)
B(-14,41,18,Leaves:4)
B(14,20,14,Leaves:4)
B(36,40,-1,Leaves:4)
B(4,41,2,Leaves:4)
B(4,40,2,Leaves:4)
B(4,48,2,Leaves:4)
B(4,49,2,Leaves:4)
B(4,46,2,Leaves:4)
B(-6,34,-18,Leaves:4)
B(-2,22,5,LOG:12)
B(23,38,11,Leaves:4)
B(4,47,2,Leaves:4)
B(-6,35,-18,Leaves:4)
B(-2,23,5,LOG:12)
B(23,39,11,Leaves:4)
B(4,45,2,Leaves:4)
B(-6,33,-18,Leaves:4)
B(4,42,2,Leaves:4)
B(4,43,2,Leaves:4)
B(10,39,16,Leaves:4)
B(0,-2,-5,LOG:12)
B(0,-4,-5,LOG:12)
B(0,-3,-5,LOG:12)
B(-6,45,-18,Leaves:4)
B(-6,46,-18,Leaves:4)
B(4,37,2,Leaves:4)
B(4,38,2,Leaves:4)
B(0,-5,-5,LOG:12)
B(-6,41,-18,Leaves:4)
B(10,41,16,Leaves:4)
B(0,-6,-5,LOG:12)
B(10,40,16,Leaves:4)
B(-6,42,-18,Leaves:4)
B(0,-7,-5,LOG:12)
B(-6,43,-18,Leaves:4)
B(0,-8,-5,LOG:12)
B(-6,44,-18,Leaves:4)
B(1,50,5,Leaves:4)
B(10,43,16,Leaves:4)
B(-6,40,-18,Leaves:4)
B(4,39,2,Leaves:4)
B(10,48,16,Leaves:4)
B(10,47,16,Leaves:4)
B(-7,33,-19,Leaves:4)
B(4,-6,27,LOG:12)
B(-7,34,-19,Leaves:4)
B(-7,37,-19,Leaves:4)
B(-2,36,5,Leaves:4)
B(-2,38,5,Leaves:4)
B(-2,37,5,Leaves:4)
B(-2,39,5,Leaves:4)
B(4,-5,27,LOG:12)
B(-2,40,5,Leaves:4)
B(-2,41,5,Leaves:4)
B(-2,42,5,Leaves:4)
B(-2,43,5,Leaves:4)
B(-2,44,5,Leaves:4)
B(-2,45,5,Leaves:4)
B(-7,45,-19,Leaves:4)
B(-7,46,-19,Leaves:4)
B(-7,43,-19,Leaves:4)
B(-7,44,-19,Leaves:4)
B(-7,47,-19,Leaves:4)
B(18,43,13,Leaves:4)
B(18,44,13,Leaves:4)
B(-2,26,5,LOG:12)
B(-2,25,5,LOG:12)
B(-2,24,5,LOG:12)
B(-7,41,-19,Leaves:4)
B(18,40,13,Leaves:4)
B(-7,42,-19,Leaves:4)
B(18,41,13,Leaves:4)
B(18,42,13,Leaves:4)
B(-2,-3,5,LOG:12)
B(-2,-4,5,LOG:12)
B(-2,-5,5,LOG:12)
B(-2,-6,5,LOG:12)
B(-2,-2,5,LOG:12)
B(18,39,13,Leaves:4)
B(-2,-7,5,LOG:12)
B(-2,-8,5,LOG:12)
B(23,38,-24,Leaves:4)
B(23,37,-24,Leaves:4)
B(23,39,-24,Leaves:4)
B(23,34,-24,Leaves:4)
B(23,33,-24,Leaves:4)
B(23,36,-24,Leaves:4)
B(23,35,-24,Leaves:4)
B(18,20,13,Leaves:4)
B(18,21,13,Leaves:4)
B(0,37,-29,Leaves:4)
B(0,38,-29,Leaves:4)
B(23,41,-24,Leaves:4)
B(23,40,-24,Leaves:4)
B(0,35,-29,Leaves:4)
B(0,36,-29,Leaves:4)
B(4,46,11,Leaves:4)
B(4,45,11,Leaves:4)
B(4,44,11,Leaves:4)
B(4,43,11,Leaves:4)
B(4,42,11,Leaves:4)
B(-11,40,16,Leaves:4)
B(4,41,11,Leaves:4)
B(4,40,11,Leaves:4)
B(-11,41,16,Leaves:4)
B(18,19,13,Leaves:4)
B(18,18,13,Leaves:4)
B(18,17,13,Leaves:4)
B(18,16,13,Leaves:4)
B(18,15,13,Leaves:4)
B(10,35,16,LOG:12)
B(10,36,16,LOG:12)
B(10,37,16,Leaves:4)
B(10,38,16,Leaves:4)
B(4,27,2,LOG:12)
B(4,26,2,LOG:12)
B(4,25,2,LOG:12)
B(4,24,2,LOG:12)
B(4,10,2,LOG:12)
B(27,53,1,Leaves:4)
B(4,12,2,LOG:12)
B(4,11,2,LOG:12)
B(4,14,2,LOG:12)
B(4,13,2,LOG:12)
B(4,15,2,LOG:12)
B(21,40,9,Leaves:4)
B(-16,-7,4,LOG:12)
B(21,41,9,Leaves:4)
B(21,42,9,Leaves:4)
B(-16,-6,4,LOG:12)
B(21,38,9,Leaves:4)
B(21,37,9,Leaves:4)
B(-5,42,22,Leaves:4)
B(-5,41,22,Leaves:4)
B(21,39,9,Leaves:4)
B(21,53,9,Leaves:4)
B(21,52,9,Leaves:4)
B(7,36,-18,Leaves:4)
B(-21,41,-4,Leaves:4)
B(7,37,-18,Leaves:4)
B(7,38,-18,Leaves:4)
B(7,39,-18,Leaves:4)
B(-21,40,-4,Leaves:4)
B(7,35,-18,Leaves:4)
B(7,34,-18,Leaves:4)
B(21,34,-24,Leaves:4)
B(21,35,-24,Leaves:4)
B(21,36,-24,Leaves:4)
B(21,37,-24,Leaves:4)
B(21,38,-24,Leaves:4)
B(7,47,-18,Leaves:4)
B(7,48,-18,Leaves:4)
B(7,46,-18,Leaves:4)
B(7,45,-18,Leaves:4)
B(21,41,-24,Leaves:4)
B(7,44,-18,Leaves:4)
B(7,43,-18,Leaves:4)
B(21,44,-24,Leaves:4)
B(21,43,-24,Leaves:4)
B(19,20,11,Leaves:4)
B(19,21,11,Leaves:4)
B(0,47,-12,Leaves:4)
B(3,43,19,Leaves:4)
B(3,41,19,Leaves:4)
B(3,40,19,Leaves:4)
B(0,40,-12,Leaves:4)
B(0,41,-12,Leaves:4)
B(-26,39,8,Leaves:4)
B(19,39,11,Leaves:4)
B(-26,38,8,Leaves:4)
B(19,37,11,Leaves:4)
B(19,38,11,Leaves:4)
B(19,36,11,Leaves:4)
B(0,39,-12,Leaves:4)
B(0,34,-12,Leaves:4)
B(3,33,19,Leaves:4)
B(3,32,19,Leaves:4)
B(0,37,-12,Leaves:4)
B(3,35,19,Leaves:4)
B(3,34,19,Leaves:4)
B(0,38,-12,Leaves:4)
B(0,35,-12,Leaves:4)
B(3,37,19,Leaves:4)
B(3,36,19,Leaves:4)
B(3,38,19,Leaves:4)
B(3,39,19,Leaves:4)
B(19,17,11,Leaves:4)
B(24,45,-8,Leaves:4)
B(24,46,-8,Leaves:4)
B(24,47,-8,Leaves:4)
B(24,48,-8,Leaves:4)
B(24,41,-8,Leaves:4)
B(24,42,-8,Leaves:4)
B(24,43,-8,Leaves:4)
B(24,44,-8,Leaves:4)
B(24,40,-8,Leaves:4)
B(-16,40,4,Leaves:4)
B(-16,41,4,Leaves:4)
B(24,39,-8,Leaves:4)
B(24,34,-8,Leaves:4)
B(24,35,-8,Leaves:4)
B(-16,47,4,Leaves:4)
B(-16,46,4,Leaves:4)
B(24,33,-8,Leaves:4)
B(-16,48,4,Leaves:4)
B(-1,34,18,Leaves:4)
B(-16,43,4,Leaves:4)
B(-1,35,18,Leaves:4)
B(-16,42,4,Leaves:4)
B(-16,45,4,Leaves:4)
B(19,46,11,Leaves:4)
B(19,45,11,Leaves:4)
B(-5,32,14,LOG:12)
B(-5,38,14,Leaves:4)
B(19,43,11,Leaves:4)
B(19,42,11,Leaves:4)
B(19,41,11,Leaves:4)
B(19,40,11,Leaves:4)
B(-16,39,4,Leaves:4)
B(-8,38,18,Leaves:4)
B(-8,39,18,Leaves:4)
B(-16,38,4,Leaves:4)
B(-5,42,14,Leaves:4)
B(-5,41,14,Leaves:4)
B(-5,40,14,Leaves:4)
B(-5,43,14,Leaves:4)
B(21,50,-16,Leaves:4)
B(19,52,11,Leaves:4)
B(19,51,11,Leaves:4)
B(19,53,11,Leaves:4)
B(24,51,-8,Leaves:4)
B(-8,42,18,Leaves:4)
B(-8,43,18,Leaves:4)
B(24,52,-8,Leaves:4)
B(-8,40,18,Leaves:4)
B(-8,41,18,Leaves:4)
B(21,44,-16,Leaves:4)
B(-12,38,7,Leaves:4)
B(-12,39,7,Leaves:4)
B(21,41,-16,Leaves:4)
B(21,40,-16,Leaves:4)
B(-17,33,-5,Leaves:4)
B(21,48,-16,Leaves:4)
B(-17,34,-5,Leaves:4)
B(21,47,-16,Leaves:4)
B(-17,35,-5,Leaves:4)
B(21,46,-16,Leaves:4)
B(-17,36,-5,Leaves:4)
B(21,45,-16,Leaves:4)
B(-17,37,-5,Leaves:4)
B(-12,35,7,Leaves:4)
B(-11,38,-5,Leaves:4)
B(-17,39,-5,Leaves:4)
B(-17,38,-5,Leaves:4)
B(-11,39,-5,Leaves:4)
B(36,37,-12,Leaves:4)
B(-11,37,-5,Leaves:4)
B(36,36,-12,Leaves:4)
B(36,39,-12,Leaves:4)
B(36,38,-12,Leaves:4)
B(-11,34,-5,Leaves:4)
B(8,-8,26,LOG:12)
B(-19,39,11,Leaves:4)
B(8,-7,26,LOG:12)
B(-19,38,11,Leaves:4)
B(8,-6,26,LOG:12)
B(-11,33,-5,Leaves:4)
B(-21,35,-6,Leaves:4)
B(-21,36,-6,Leaves:4)
B(-21,32,-6,Leaves:4)
B(-26,43,2,Leaves:4)
B(21,39,-16,Leaves:4)
B(21,38,-16,Leaves:4)
B(-12,42,7,Leaves:4)
B(-17,41,-5,Leaves:4)
B(-12,43,7,Leaves:4)
B(-12,44,7,Leaves:4)
B(-17,47,-5,Leaves:4)
B(-12,45,7,Leaves:4)
B(21,37,-16,Leaves:4)
B(-17,46,-5,Leaves:4)
B(21,36,-16,Leaves:4)
B(-11,47,-5,Leaves:4)
B(-11,48,-5,Leaves:4)
B(-19,43,11,Leaves:4)
B(-19,45,11,Leaves:4)
B(-19,40,11,Leaves:4)
B(-12,40,7,Leaves:4)
B(-19,42,11,Leaves:4)
B(-11,40,-5,Leaves:4)
B(-11,42,-5,Leaves:4)
B(-19,48,11,Leaves:4)
B(-11,43,-5,Leaves:4)
B(-19,47,11,Leaves:4)
B(-11,44,-5,Leaves:4)
B(-11,45,-5,Leaves:4)
B(-19,49,11,Leaves:4)
B(-11,46,-5,Leaves:4)
B(-17,50,-5,Leaves:4)
B(2,0,-5,Leaves:4)
B(-17,52,-5,Leaves:4)
B(-17,53,-5,Leaves:4)
B(21,29,-16,Leaves:4)
B(8,8,0,LOG:12)
B(8,9,0,LOG:12)
B(8,0,0,LOG:12)
B(8,1,0,LOG:12)
B(8,2,0,LOG:12)
B(8,3,0,LOG:12)
B(8,4,0,LOG:12)
B(8,5,0,LOG:12)
B(8,6,0,LOG:12)
B(8,7,0,LOG:12)
B(27,45,-15,Leaves:4)
B(-12,35,-19,Leaves:4)
B(27,42,-15,Leaves:4)
B(-12,38,-19,Leaves:4)
B(-12,39,-19,Leaves:4)
B(-12,36,-19,Leaves:4)
B(-12,37,-19,Leaves:4)
B(34,40,-13,Leaves:4)
B(-18,41,-17,Leaves:4)
B(-18,40,-17,Leaves:4)
B(3,0,-7,Leaves:4)
B(34,38,-13,Leaves:4)
B(34,39,-13,Leaves:4)
B(-4,42,-24,Leaves:4)
B(-4,43,-24,Leaves:4)
B(-4,44,-24,Leaves:4)
B(-4,45,-24,Leaves:4)
B(-4,46,-24,Leaves:4)
B(-4,47,-24,Leaves:4)
B(-4,48,-24,Leaves:4)
B(-4,49,-24,Leaves:4)
B(-4,41,-24,Leaves:4)
B(24,-3,-8,LOG:12)
B(-4,40,-24,Leaves:4)
B(24,-4,-8,LOG:12)
B(24,-5,-8,LOG:12)
B(-4,37,-24,Leaves:4)
B(-18,36,-17,Leaves:4)
B(-18,37,-17,Leaves:4)
B(-4,35,-24,Leaves:4)
B(-18,38,-17,Leaves:4)
B(-4,36,-24,Leaves:4)
B(-18,39,-17,Leaves:4)
B(-4,33,-24,Leaves:4)
B(-18,34,-17,Leaves:4)
B(-18,35,-17,Leaves:4)
B(-4,32,-24,Leaves:4)
B(19,53,-2,Leaves:4)
B(19,55,-2,Leaves:4)
B(27,41,-15,Leaves:4)
B(27,40,-15,Leaves:4)
B(-12,40,-19,Leaves:4)
B(-12,41,-19,Leaves:4)
B(27,38,-15,Leaves:4)
B(-12,42,-19,Leaves:4)
B(27,39,-15,Leaves:4)
B(24,-9,-8,LOG:12)
B(24,-8,-8,LOG:12)
B(24,-7,-8,LOG:12)
B(24,-6,-8,LOG:12)
B(4,37,-12,Leaves:4)
B(28,36,0,Leaves:4)
B(4,38,-12,Leaves:4)
B(28,37,0,Leaves:4)
B(4,35,-12,Leaves:4)
B(19,41,-2,Leaves:4)
B(4,36,-12,Leaves:4)
B(28,38,0,Leaves:4)
B(19,47,-2,Leaves:4)
B(-17,42,19,Leaves:4)
B(-17,41,19,Leaves:4)
B(-17,44,19,Leaves:4)
B(4,39,-12,Leaves:4)
B(19,46,-2,Leaves:4)
B(-17,43,19,Leaves:4)
B(20,-8,-7,LOG:12)
B(20,-7,-7,LOG:12)
B(-4,44,-4,Leaves:4)
B(19,49,-2,Leaves:4)
B(20,-6,-7,LOG:12)
B(20,-5,-7,LOG:12)
B(20,-4,-7,LOG:12)
B(28,39,0,Leaves:4)
B(4,34,-12,Leaves:4)
B(20,-3,-7,LOG:12)
B(20,-2,-7,LOG:12)
B(20,-1,-7,LOG:12)
B(28,40,0,Leaves:4)
B(19,51,-2,Leaves:4)
B(19,50,-2,Leaves:4)
B(4,24,-12,LOG:12)
B(-17,37,19,Leaves:4)
B(28,49,0,Leaves:4)
B(-17,36,19,Leaves:4)
B(4,25,-12,LOG:12)
B(28,46,0,Leaves:4)
B(-17,35,19,Leaves:4)
B(4,26,-12,LOG:12)
B(28,47,0,Leaves:4)
B(28,44,0,Leaves:4)
B(28,45,0,Leaves:4)
B(19,36,-2,Leaves:4)
B(28,42,0,Leaves:4)
B(28,43,0,Leaves:4)
B(-4,36,-4,Leaves:4)
B(19,38,-2,Leaves:4)
B(-4,35,-4,Leaves:4)
B(19,39,-2,Leaves:4)
B(-4,34,-4,Leaves:4)
B(-4,39,-4,Leaves:4)
B(-4,38,-4,Leaves:4)
B(-4,37,-4,Leaves:4)
B(-4,42,-4,Leaves:4)
B(-4,43,-4,Leaves:4)
B(-4,40,-4,Leaves:4)
B(-4,41,-4,Leaves:4)
B(28,52,0,Leaves:4)
B(28,51,0,Leaves:4)
B(28,50,0,Leaves:4)
B(19,40,-2,Leaves:4)
B(28,53,0,Leaves:4)
B(-4,23,-4,LOG:12)
B(-4,22,-4,LOG:12)
B(-4,25,-4,LOG:12)
B(-4,24,-4,LOG:12)
B(-1,42,18,Leaves:4)
B(-1,41,18,Leaves:4)
B(-1,40,18,Leaves:4)
B(-1,46,18,Leaves:4)
B(-1,44,18,Leaves:4)
B(-1,43,18,Leaves:4)
B(4,42,-12,Leaves:4)
B(4,43,-12,Leaves:4)
B(4,44,-12,Leaves:4)
B(4,45,-12,Leaves:4)
B(4,40,-12,Leaves:4)
B(4,41,-12,Leaves:4)
B(-1,38,18,Leaves:4)
B(-1,36,18,Leaves:4)
B(-1,37,18,Leaves:4)
B(1,43,29,Leaves:4)
B(1,44,29,Leaves:4)
B(38,37,-13,Leaves:4)
B(38,36,-13,Leaves:4)
B(17,29,-24,Leaves:4)
B(-1,40,20,Leaves:4)
B(-1,41,20,Leaves:4)
B(-1,42,20,Leaves:4)
B(-1,43,20,Leaves:4)
B(5,32,-19,Leaves:4)
B(5,34,-19,Leaves:4)
B(5,33,-19,Leaves:4)
B(14,25,-13,LOG:12)
B(-1,37,20,Leaves:4)
B(5,39,-19,Leaves:4)
B(-1,38,20,Leaves:4)
B(-1,35,20,Leaves:4)
B(-1,36,20,Leaves:4)
B(-21,41,7,Leaves:4)
B(5,36,-19,Leaves:4)
B(-21,42,7,Leaves:4)
B(5,37,-19,Leaves:4)
B(-1,39,20,Leaves:4)
B(5,38,-19,Leaves:4)
B(-21,40,7,Leaves:4)
B(12,42,5,Leaves:4)
B(12,45,5,Leaves:4)
B(-8,36,-4,Leaves:4)
B(14,34,-13,Leaves:4)
B(14,33,-13,Leaves:4)
B(14,36,-13,Leaves:4)
B(14,35,-13,Leaves:4)
B(-8,39,-4,Leaves:4)
B(14,38,-13,Leaves:4)
B(14,37,-13,Leaves:4)
B(14,39,-13,Leaves:4)
B(5,44,-19,Leaves:4)
B(5,48,-19,Leaves:4)
B(5,46,-19,Leaves:4)
B(5,47,-19,Leaves:4)
B(17,41,-24,Leaves:4)
B(17,42,-24,Leaves:4)
B(17,43,-24,Leaves:4)
B(14,41,-13,Leaves:4)
B(-8,41,-4,Leaves:4)
B(14,40,-13,Leaves:4)
B(-8,40,-4,Leaves:4)
B(-8,42,-4,Leaves:4)
B(-26,45,8,Leaves:4)
B(14,45,-13,Leaves:4)
B(14,44,-13,Leaves:4)
B(-8,44,-4,Leaves:4)
B(14,43,-13,Leaves:4)
B(-8,46,-4,Leaves:4)
B(14,42,-13,Leaves:4)
B(17,40,-24,Leaves:4)
B(14,46,-13,Leaves:4)
B(17,36,-24,Leaves:4)
B(-18,-7,5,LOG:12)
B(17,37,-24,Leaves:4)
B(17,35,-24,Leaves:4)
B(17,30,-24,Leaves:4)
B(19,-2,-2,LOG:12)
B(19,-1,-2,LOG:12)
B(-26,42,8,Leaves:4)
B(-26,41,8,Leaves:4)
B(17,38,-24,Leaves:4)
B(-26,40,8,Leaves:4)
B(17,39,-24,Leaves:4)
B(-1,44,13,Leaves:4)
B(-1,45,13,Leaves:4)
B(-1,43,13,Leaves:4)
B(-1,46,13,Leaves:4)
B(-1,47,13,Leaves:4)
B(-18,44,5,Leaves:4)
B(-18,43,5,Leaves:4)
B(-18,42,5,Leaves:4)
B(-18,41,5,Leaves:4)
B(-18,40,5,Leaves:4)
B(-15,42,19,Leaves:4)
B(-15,41,19,Leaves:4)
B(-18,46,5,Leaves:4)
B(-12,38,-2,Leaves:4)
B(-15,45,19,Leaves:4)
B(-12,39,-2,Leaves:4)
B(-15,44,19,Leaves:4)
B(-12,37,-2,Leaves:4)
B(-15,43,19,Leaves:4)
B(-12,34,-2,Leaves:4)
B(-12,32,-2,Leaves:4)
B(-12,33,-2,Leaves:4)
B(-18,38,5,Leaves:4)
B(-15,37,19,Leaves:4)
B(-15,39,19,Leaves:4)
B(-15,38,19,Leaves:4)
B(22,38,-25,Leaves:4)
B(22,37,-25,Leaves:4)
B(22,36,-25,Leaves:4)
B(22,35,-25,Leaves:4)
B(22,34,-25,Leaves:4)
B(22,33,-25,Leaves:4)
B(22,32,-25,Leaves:4)
B(24,38,-2,Leaves:4)
B(24,39,-2,Leaves:4)
B(24,36,-2,Leaves:4)
B(24,37,-2,Leaves:4)
B(-21,37,7,Leaves:4)
B(-21,36,7,Leaves:4)
B(-21,39,7,Leaves:4)
B(24,40,-2,Leaves:4)
B(-21,38,7,Leaves:4)
B(24,46,-2,Leaves:4)
B(24,45,-2,Leaves:4)
B(24,44,-2,Leaves:4)
B(24,43,-2,Leaves:4)
B(-13,40,-29,Leaves:4)
B(-13,42,-29,Leaves:4)
B(-13,41,-29,Leaves:4)
B(-21,35,7,Leaves:4)
B(-21,34,7,Leaves:4)
B(-1,35,13,Leaves:4)
B(-1,36,13,Leaves:4)
B(-1,37,13,Leaves:4)
B(-1,38,13,Leaves:4)
B(-1,31,13,LOG:12)
B(-1,32,13,LOG:12)
B(-1,33,13,Leaves:4)
B(-1,34,13,Leaves:4)
B(22,43,-25,Leaves:4)
B(-13,39,-29,Leaves:4)
B(24,32,-2,LOG:12)
B(-12,40,-2,Leaves:4)
B(-12,41,-2,Leaves:4)
B(24,34,-2,Leaves:4)
B(-12,42,-2,Leaves:4)
B(-12,43,-2,Leaves:4)
B(-12,44,-2,Leaves:4)
B(-12,45,-2,Leaves:4)
B(-12,46,-2,Leaves:4)
B(-12,47,-2,Leaves:4)
B(21,40,7,Leaves:4)
B(21,38,7,Leaves:4)
B(24,42,1,Leaves:4)
B(21,37,7,Leaves:4)
B(24,40,1,Leaves:4)
B(24,46,1,Leaves:4)
B(24,45,1,Leaves:4)
B(24,44,1,Leaves:4)
B(24,43,1,Leaves:4)
B(24,49,1,Leaves:4)
B(24,48,1,Leaves:4)
B(24,47,1,Leaves:4)
B(21,39,7,Leaves:4)
B(7,35,-25,Leaves:4)
B(7,34,-25,Leaves:4)
B(21,52,7,Leaves:4)
B(24,50,1,Leaves:4)
B(21,46,7,Leaves:4)
B(21,45,7,Leaves:4)
B(-17,40,12,Leaves:4)
B(-17,41,12,Leaves:4)
B(-17,42,12,Leaves:4)
B(-17,48,12,Leaves:4)
B(-17,47,12,Leaves:4)
B(-18,42,13,Leaves:4)
B(-18,47,13,Leaves:4)
B(-18,48,13,Leaves:4)
B(12,29,5,Leaves:4)
B(12,20,5,Leaves:4)
B(12,21,5,Leaves:4)
B(12,30,5,Leaves:4)
B(-17,-7,5,LOG:12)
B(-18,40,13,Leaves:4)
B(-18,41,13,Leaves:4)
B(-18,38,13,Leaves:4)
B(12,39,5,Leaves:4)
B(-18,37,13,Leaves:4)
B(-18,36,13,Leaves:4)
B(-18,35,13,Leaves:4)
B(12,35,5,Leaves:4)
B(12,36,5,Leaves:4)
B(-23,39,3,Leaves:4)
B(12,38,5,Leaves:4)
B(-18,39,13,Leaves:4)
B(-23,37,3,Leaves:4)
B(12,41,5,Leaves:4)
B(31,41,-15,Leaves:4)
B(31,40,-15,Leaves:4)
B(-23,40,3,Leaves:4)
B(-18,41,-24,Leaves:4)
B(-23,43,3,Leaves:4)
B(-23,44,3,Leaves:4)
B(-23,41,3,Leaves:4)
B(-23,42,3,Leaves:4)
B(-23,45,3,Leaves:4)
B(-23,46,3,Leaves:4)
B(4,-7,13,Leaves:4)
B(4,-6,13,LOG:12)
B(4,-5,13,LOG:12)
B(12,17,5,Leaves:4)
B(12,18,5,Leaves:4)
B(12,19,5,Leaves:4)
B(12,16,5,Leaves:4)
B(8,35,-30,Leaves:4)
B(8,31,-30,Leaves:4)
B(8,32,-30,Leaves:4)
B(8,33,-30,Leaves:4)
B(8,34,-30,Leaves:4)
B(8,30,-30,Leaves:4)
B(-14,45,-19,Leaves:4)
B(-14,43,-19,Leaves:4)
B(-14,44,-19,Leaves:4)
B(-14,41,-19,Leaves:4)
B(-14,40,-19,Leaves:4)
B(40,36,1,Leaves:4)
B(-7,38,15,Leaves:4)
B(-7,39,15,Leaves:4)
B(32,39,5,Leaves:4)
B(32,36,5,Leaves:4)
B(20,38,-16,Leaves:4)
B(10,40,-9,Leaves:4)
B(12,15,11,Leaves:4)
B(12,16,11,Leaves:4)
B(12,17,11,Leaves:4)
B(12,18,11,Leaves:4)
B(12,19,11,Leaves:4)
B(10,45,-9,Leaves:4)
B(-3,45,-23,Leaves:4)
B(10,46,-9,Leaves:4)
B(-3,44,-23,Leaves:4)
B(10,47,-9,Leaves:4)
B(-3,47,-23,Leaves:4)
B(-3,46,-23,Leaves:4)
B(-3,41,-23,Leaves:4)
B(10,41,-9,Leaves:4)
B(-3,40,-23,Leaves:4)
B(10,42,-9,Leaves:4)
B(-3,43,-23,Leaves:4)
B(10,43,-9,Leaves:4)
B(-3,42,-23,Leaves:4)
B(10,44,-9,Leaves:4)
B(25,42,-15,Leaves:4)
B(25,43,-15,Leaves:4)
B(25,40,-15,Leaves:4)
B(25,41,-15,Leaves:4)
B(25,44,-15,Leaves:4)
B(25,45,-15,Leaves:4)
B(10,38,-9,Leaves:4)
B(10,39,-9,Leaves:4)
B(10,36,-9,Leaves:4)
B(10,37,-9,Leaves:4)
B(10,35,-9,Leaves:4)
B(-12,33,9,Leaves:4)
B(-12,34,9,Leaves:4)
B(20,50,-16,Leaves:4)
B(-12,35,9,Leaves:4)
B(-12,36,9,Leaves:4)
B(-12,37,9,Leaves:4)
B(-12,38,9,Leaves:4)
B(14,30,-31,Leaves:4)
B(25,39,-15,Leaves:4)
B(-12,39,9,Leaves:4)
B(-15,43,-26,Leaves:4)
B(14,33,-31,Leaves:4)
B(-3,43,23,Leaves:4)
B(14,34,-31,Leaves:4)
B(-3,41,23,Leaves:4)
B(-3,42,23,Leaves:4)
B(-3,40,23,Leaves:4)
B(10,20,-9,LOG:12)
B(10,22,-9,LOG:12)
B(10,21,-9,LOG:12)
B(-12,45,9,Leaves:4)
B(-12,43,9,Leaves:4)
B(-12,44,9,Leaves:4)
B(20,42,-16,Leaves:4)
B(20,40,-16,Leaves:4)
B(20,41,-16,Leaves:4)
B(20,46,-16,Leaves:4)
B(20,47,-16,Leaves:4)
B(20,44,-16,Leaves:4)
B(20,45,-16,Leaves:4)
B(20,48,-16,Leaves:4)
B(20,49,-16,Leaves:4)
B(-3,31,-23,Leaves:4)
B(-3,32,-23,Leaves:4)
B(-3,33,-23,Leaves:4)
B(-3,34,-23,Leaves:4)
B(10,19,-9,LOG:12)
B(-3,39,-23,Leaves:4)
B(10,18,-9,LOG:12)
B(10,17,-9,LOG:12)
B(-3,38,-23,Leaves:4)
B(-12,42,9,Leaves:4)
B(-12,41,9,Leaves:4)
B(-12,40,9,Leaves:4)
B(0,34,28,Leaves:4)
B(-7,44,15,Leaves:4)
B(-7,43,15,Leaves:4)
B(-7,42,15,Leaves:4)
B(-7,41,15,Leaves:4)
B(-7,40,15,Leaves:4)
B(32,41,5,Leaves:4)
B(32,40,5,Leaves:4)
B(-15,38,-26,Leaves:4)
B(0,44,28,Leaves:4)
B(-15,37,-26,Leaves:4)
B(24,39,1,Leaves:4)
B(-14,37,-19,Leaves:4)
B(24,37,1,Leaves:4)
B(24,34,1,Leaves:4)
B(23,31,-31,Leaves:4)
B(-14,39,-19,Leaves:4)
B(23,32,-31,Leaves:4)
B(-14,38,-19,Leaves:4)
B(24,33,1,LOG:12)
B(-3,31,23,Leaves:4)
B(23,35,-31,Leaves:4)
B(23,36,-31,Leaves:4)
B(23,33,-31,Leaves:4)
B(23,34,-31,Leaves:4)
B(23,38,-31,Leaves:4)
B(23,37,-31,Leaves:4)
B(1,32,12,Leaves:4)
B(30,50,-7,Leaves:4)
B(13,19,18,Leaves:4)
B(30,51,-7,Leaves:4)
B(13,18,18,Leaves:4)
B(18,40,15,Leaves:4)
B(-6,34,-16,Leaves:4)
B(-6,35,-16,Leaves:4)
B(-6,32,-16,Leaves:4)
B(-6,33,-16,Leaves:4)
B(1,39,12,Leaves:4)
B(13,20,18,Leaves:4)
B(1,37,12,Leaves:4)
B(1,38,12,Leaves:4)
B(1,35,12,Leaves:4)
B(-1,44,-9,Leaves:4)
B(1,33,12,Leaves:4)
B(-1,47,-9,Leaves:4)
B(1,34,12,Leaves:4)
B(1,41,12,Leaves:4)
B(21,43,-21,Leaves:4)
B(1,43,12,Leaves:4)
B(1,42,12,Leaves:4)
B(21,44,-21,Leaves:4)
B(21,41,-21,Leaves:4)
B(21,42,-21,Leaves:4)
B(21,40,-21,Leaves:4)
B(-6,41,-16,Leaves:4)
B(-6,42,-16,Leaves:4)
B(13,42,22,Leaves:4)
B(-6,44,-16,Leaves:4)
B(-6,45,-16,Leaves:4)
B(-6,46,-16,Leaves:4)
B(-6,37,-16,Leaves:4)
B(-1,31,-9,Leaves:4)
B(-6,36,-16,Leaves:4)
B(18,20,15,Leaves:4)
B(18,21,15,Leaves:4)
B(1,48,12,Leaves:4)
B(1,49,12,Leaves:4)
B(-1,37,-9,Leaves:4)
B(1,44,12,Leaves:4)
B(-1,35,-9,Leaves:4)
B(1,45,12,Leaves:4)
B(-1,36,-9,Leaves:4)
B(-1,34,-9,Leaves:4)
B(-21,39,11,Leaves:4)
B(10,41,-15,Leaves:4)
B(10,40,-15,Leaves:4)
B(13,17,22,Leaves:4)
B(10,42,-15,Leaves:4)
B(10,45,-15,Leaves:4)
B(10,44,-15,Leaves:4)
B(10,46,-15,Leaves:4)
B(30,39,-7,Leaves:4)
B(-6,47,-16,Leaves:4)
B(30,37,-7,Leaves:4)
B(30,36,-7,Leaves:4)
B(30,40,-7,Leaves:4)
B(10,39,-15,Leaves:4)
B(10,38,-15,Leaves:4)
B(10,37,-15,Leaves:4)
B(10,36,-15,Leaves:4)
B(10,35,-15,Leaves:4)
B(10,34,-15,Leaves:4)
B(18,41,15,Leaves:4)
B(18,42,15,Leaves:4)
B(39,38,-10,Leaves:4)
B(30,49,-7,Leaves:4)
B(30,42,-7,Leaves:4)
B(30,41,-7,Leaves:4)
B(30,47,-7,Leaves:4)
B(-8,33,-23,Leaves:4)
B(18,32,3,Leaves:4)
B(18,34,3,Leaves:4)
B(18,33,3,Leaves:4)
B(12,41,11,Leaves:4)
B(12,42,11,Leaves:4)
B(12,40,11,Leaves:4)
B(18,37,3,Leaves:4)
B(18,38,3,Leaves:4)
B(-8,41,11,Leaves:4)
B(-8,44,11,Leaves:4)
B(18,35,3,Leaves:4)
B(18,36,3,Leaves:4)
B(-8,43,11,Leaves:4)
B(-8,46,11,Leaves:4)
B(-8,45,11,Leaves:4)
B(-8,48,11,Leaves:4)
B(-8,47,11,Leaves:4)
B(18,41,3,Leaves:4)
B(18,44,3,Leaves:4)
B(18,43,3,Leaves:4)
B(18,42,3,Leaves:4)
B(12,39,11,Leaves:4)
B(12,38,11,Leaves:4)
B(12,37,11,Leaves:4)
B(29,46,-14,Leaves:4)
B(29,45,-14,Leaves:4)
B(29,47,-14,Leaves:4)
B(-8,34,11,LOG:12)
B(-8,33,11,LOG:12)
B(-8,39,11,Leaves:4)
B(12,48,11,Leaves:4)
B(12,47,11,Leaves:4)
B(12,43,11,Leaves:4)
B(12,46,11,Leaves:4)
B(12,45,11,Leaves:4)
B(-8,41,-23,Leaves:4)
B(29,39,-14,Leaves:4)
B(29,38,-14,Leaves:4)
B(29,37,-14,Leaves:4)
B(29,36,-14,Leaves:4)
B(18,17,3,Leaves:4)
B(18,16,3,Leaves:4)
B(18,21,3,Leaves:4)
B(18,20,3,Leaves:4)
B(-8,38,-23,Leaves:4)
B(29,41,-14,Leaves:4)
B(-8,37,-23,Leaves:4)
B(29,40,-14,Leaves:4)
B(11,36,-5,Leaves:4)
B(11,39,-5,Leaves:4)
B(11,38,-5,Leaves:4)
B(11,37,-5,Leaves:4)
B(-19,40,6,Leaves:4)
B(-19,41,6,Leaves:4)
B(-19,43,6,Leaves:4)
B(-19,39,6,Leaves:4)
B(-19,38,6,Leaves:4)
B(11,47,-5,Leaves:4)
B(11,46,-5,Leaves:4)
B(11,48,-5,Leaves:4)
B(11,41,-5,Leaves:4)
B(11,40,-5,Leaves:4)
B(11,43,-5,Leaves:4)
B(11,42,-5,Leaves:4)
B(2,35,-34,Leaves:4)
B(2,33,-34,Leaves:4)
B(11,18,-5,LOG:12)
B(11,17,-5,LOG:12)
B(11,16,-5,LOG:12)
B(11,15,-5,LOG:12)
B(18,53,3,Leaves:4)
B(18,51,3,Leaves:4)
B(18,52,3,Leaves:4)
B(18,50,3,Leaves:4)
B(18,49,3,Leaves:4)
B(18,48,3,Leaves:4)
B(31,39,-15,Leaves:4)
B(31,37,-15,Leaves:4)
B(-17,46,5,Leaves:4)
B(-17,47,5,Leaves:4)
B(1,41,9,Leaves:4)
B(1,40,9,Leaves:4)
B(1,48,9,Leaves:4)
B(12,33,-31,Leaves:4)
B(1,49,9,Leaves:4)
B(12,34,-31,Leaves:4)
B(1,46,9,Leaves:4)
B(12,35,-31,Leaves:4)
B(1,47,9,Leaves:4)
B(12,30,-31,Leaves:4)
B(12,31,-31,Leaves:4)
B(0,40,-27,Leaves:4)
B(12,32,-31,Leaves:4)
B(0,41,-27,Leaves:4)
B(-17,42,5,Leaves:4)
B(-17,41,5,Leaves:4)
B(-17,40,5,Leaves:4)
B(-21,46,11,Leaves:4)
B(-17,39,12,Leaves:4)
B(-21,45,11,Leaves:4)
B(-21,42,11,Leaves:4)
B(-21,40,11,Leaves:4)
B(-21,41,11,Leaves:4)
B(4,37,13,Leaves:4)
B(-20,37,-21,Leaves:4)
B(-20,36,-21,Leaves:4)
B(1,34,9,Leaves:4)
B(-20,39,-21,Leaves:4)
B(-20,38,-21,Leaves:4)
B(1,35,9,Leaves:4)
B(1,36,9,Leaves:4)
B(0,34,-27,Leaves:4)
B(1,37,9,Leaves:4)
B(1,38,9,Leaves:4)
B(1,39,9,Leaves:4)
B(-20,40,-21,Leaves:4)
B(-20,41,-21,Leaves:4)
B(-20,42,-21,Leaves:4)
B(0,37,-27,Leaves:4)
B(0,38,-27,Leaves:4)
B(0,35,-27,Leaves:4)
B(-21,48,11,Leaves:4)
B(0,36,-27,Leaves:4)
B(21,38,-21,Leaves:4)
B(21,39,-21,Leaves:4)
B(21,36,-21,Leaves:4)
B(18,19,15,Leaves:4)
B(11,52,-5,Leaves:4)
B(21,37,-21,Leaves:4)
B(18,18,15,Leaves:4)
B(-5,37,-17,Leaves:4)
B(-5,36,-17,Leaves:4)
B(0,31,12,Leaves:4)
B(0,32,12,Leaves:4)
B(-5,39,-17,Leaves:4)
B(0,33,12,Leaves:4)
B(-5,38,-17,Leaves:4)
B(4,43,13,Leaves:4)
B(4,42,13,Leaves:4)
B(4,45,13,Leaves:4)
B(4,44,13,Leaves:4)
B(4,47,13,Leaves:4)
B(4,46,13,Leaves:4)
B(11,55,-5,Leaves:4)
B(4,48,13,Leaves:4)
B(0,35,12,Leaves:4)
B(21,31,-21,Leaves:4)
B(-5,43,-17,Leaves:4)
B(0,34,12,Leaves:4)
B(-5,44,-17,Leaves:4)
B(-5,45,-17,Leaves:4)
B(0,37,12,Leaves:4)
B(-5,46,-17,Leaves:4)
B(0,36,12,Leaves:4)
B(21,35,-21,Leaves:4)
B(0,38,12,Leaves:4)
B(-5,40,-17,Leaves:4)
B(21,33,-21,Leaves:4)
B(-5,41,-17,Leaves:4)
B(21,32,-21,Leaves:4)
B(-5,42,-17,Leaves:4)
B(0,43,12,Leaves:4)
B(0,44,12,Leaves:4)
B(0,41,12,Leaves:4)
B(0,42,12,Leaves:4)
B(12,29,-31,Leaves:4)
B(0,48,12,Leaves:4)
B(-5,34,-17,Leaves:4)
B(0,47,12,Leaves:4)
B(-5,35,-17,Leaves:4)
B(0,46,12,Leaves:4)
B(0,45,12,Leaves:4)
B(0,49,12,Leaves:4)
B(20,41,4,Leaves:4)
B(20,40,4,Leaves:4)
B(20,45,4,Leaves:4)
B(20,44,4,Leaves:4)
B(20,43,4,Leaves:4)
B(20,42,4,Leaves:4)
B(20,49,4,Leaves:4)
B(20,48,4,Leaves:4)
