
#
# +-----------------------------------------------------------------+ #
# |                            BO3 object                           | #
# +-----------------------------------------------------------------+ #
#

Author: NLBlackEagle

Description: Converted version of the BO2 AFR11L

Version: 3

SettingsMode: WriteDisable


#
# +-----------------------------------------------------------------+ #
# |                          Main settings                          | #
# +-----------------------------------------------------------------+ #
#

Tree: true

Frequency: 1

Rarity: 100.0

RotateRandomly: true

SpawnHeight: highestSolidBlock

SpawnHeightOffset: -1

SpawnHeightVariance: 0


# Height Limits for the BO3. #


MinHeight: 0

MaxHeight: 199


# Extrusion settings #


ExtrudeMode: None

ExtrudeThroughBlocks: air

MaxBranchDepth: 10

ExcludedBiomes: 


#
# +-----------------------------------------------------------------+ #
# |                      Source block settings                      | #
# +-----------------------------------------------------------------+ #
#

SourceBlocks: AIR,GRASS,DIRT,SAND,MYCELIUM

MaxPercentageOutsideSourceBlock: 0

OutsideSourceBlock: placeAnyway


#
# +-----------------------------------------------------------------+ #
# |                              Blocks                             | #
# +-----------------------------------------------------------------+ #
#

B(1,17,-4,Leaves:4)
B(7,14,9,leaves:4)
B(10,13,1,Leaves:4)
B(4,12,-5,Leaves:4)
B(-9,13,-2,Leaves:4)
B(9,13,-7,Leaves:4)
B(9,15,-7,Leaves:4)
B(-1,-1,-1,LOG:12)
B(-1,-2,-1,LOG:12)
B(-2,12,9,Leaves:4)
B(0,15,8,Leaves:4)
B(-1,-3,-1,LOG:12)
B(-5,15,-5,Leaves:4)
B(3,17,-6,Leaves:4)
B(-2,15,9,Leaves:4)
B(-5,13,-5,LOG:12)
B(0,12,8,Leaves:4)
B(8,13,5,Leaves:4)
B(4,15,-5,Leaves:4)
B(0,11,-2,LOG:12)
B(-3,16,2,Leaves:4)
B(-3,14,2,Leaves:4)
B(-5,14,1,Leaves:4)
B(-3,13,2,Leaves:4)
B(-5,12,1,Leaves:4)
B(0,12,-2,LOG:12)
B(-1,3,0,LOG:12)
B(-5,13,1,Leaves:4)
B(0,13,2,Leaves:4)
B(-11,15,6,Leaves:4)
B(0,12,2,Leaves:4)
B(11,15,-10,Leaves:4)
B(3,9,1,LOG:12)
B(-4,14,4,Leaves:4)
B(3,17,2,Leaves:4)
B(-4,16,4,Leaves:4)
B(-4,13,1,Leaves:4)
B(-6,16,5,Leaves:4)
B(-1,4,0,LOG:12)
B(-3,16,1,Leaves:4)
B(-1,5,0,LOG:12)
B(-3,15,1,Leaves:4)
B(0,13,6,Leaves:4)
B(-6,12,5,LOG:12)
B(-3,12,1,Leaves:4)
B(-8,13,0,Leaves:4)
B(8,12,-4,Leaves:4)
B(8,13,-7,Leaves:4)
B(8,14,-7,Leaves:4)
B(8,15,-7,Leaves:4)
B(13,14,-12,Leaves:4)
B(-4,13,-10,Leaves:4)
B(-3,13,-3,Leaves:4)
B(0,17,0,Leaves:4)
B(0,16,0,Leaves:4)
B(0,12,0,Leaves:4)
B(-8,13,3,Leaves:4)
B(-6,16,-4,Leaves:4)
B(-8,14,3,Leaves:4)
B(-8,15,3,Leaves:4)
B(-6,13,-4,Leaves:4)
B(-3,16,-7,Leaves:4)
B(-6,14,-4,Leaves:4)
B(-8,15,-5,Leaves:4)
B(-6,17,-4,Leaves:4)
B(-8,12,-5,Leaves:4)
B(8,12,-7,Leaves:4)
B(10,14,4,Leaves:4)
B(-7,15,10,Leaves:4)
B(-7,14,5,Leaves:4)
B(-7,13,5,Leaves:4)
B(1,14,10,Leaves:4)
B(-7,12,5,Leaves:4)
B(-6,13,6,Leaves:4)
B(-13,14,7,leaves:4)
B(3,17,-5,Leaves:4)
B(-6,16,6,Leaves:4)
B(-6,15,6,Leaves:4)
B(-12,15,4,Leaves:4)
B(3,13,-2,Leaves:4)
B(-2,13,10,Leaves:4)
B(-12,14,8,Leaves:4)
B(6,14,4,LOG:12)
B(1,0,-1,LOG:12)
B(6,14,-8,Leaves:4)
B(-9,12,-4,Leaves:4)
B(1,3,-1,LOG:12)
B(1,4,-1,LOG:12)
B(1,1,-1,LOG:12)
B(1,4,-2,LOG:12)
B(1,2,-1,LOG:12)
B(-7,14,-1,LOG:12)
B(1,2,-2,LOG:12)
B(1,3,-2,LOG:12)
B(-7,13,-1,Leaves:4)
B(1,0,-2,LOG:12)
B(1,5,-1,LOG:12)
B(-9,14,-4,Leaves:4)
B(1,1,-2,LOG:12)
B(1,6,-1,LOG:12)
B(1,9,-1,LOG:12)
B(-10,13,-2,Leaves:4)
B(-7,15,-3,Leaves:4)
B(-2,15,-6,Leaves:4)
B(10,13,-5,Leaves:4)
B(-7,12,-3,Leaves:4)
B(-8,14,-1,Leaves:4)
B(-8,12,-1,Leaves:4)
B(3,16,0,Leaves:4)
B(3,17,0,Leaves:4)
B(-2,16,0,Leaves:4)
B(-7,14,-6,Leaves:4)
B(-7,13,-6,Leaves:4)
B(9,13,6,Leaves:4)
B(-2,16,-3,Leaves:4)
B(-2,12,-3,Leaves:4)
B(-8,13,-7,Leaves:4)
B(-3,13,8,Leaves:4)
B(-6,13,10,Leaves:4)
B(9,14,6,Leaves:4)
B(-2,14,0,Leaves:4)
B(-5,14,9,Leaves:4)
B(-5,15,9,Leaves:4)
B(4,14,0,Leaves:4)
B(-5,13,9,Leaves:4)
B(3,17,4,Leaves:4)
B(3,16,4,Leaves:4)
B(7,13,-6,Leaves:4)
B(3,13,4,Leaves:4)
B(4,16,0,Leaves:4)
B(7,15,-6,Leaves:4)
B(9,14,7,Leaves:4)
B(9,15,-8,Leaves:4)
B(-4,13,4,Leaves:4)
B(-7,16,0,Leaves:4)
B(0,13,9,Leaves:4)
B(6,13,-12,Leaves:4)
B(5,15,-4,Leaves:4)
B(1,12,5,Leaves:4)
B(1,15,5,Leaves:4)
B(0,13,-5,Leaves:4)
B(0,16,-8,Leaves:4)
B(0,14,-5,Leaves:4)
B(-3,14,-2,Leaves:4)
B(0,15,-8,Leaves:4)
B(-4,12,5,Leaves:4)
B(-6,15,8,Leaves:4)
B(-3,13,-5,Leaves:4)
B(-3,14,-9,Leaves:4)
B(-3,10,-2,LOG:12)
B(-3,14,-5,Leaves:4)
B(0,15,-5,Leaves:4)
B(-6,13,8,Leaves:4)
B(0,16,-5,Leaves:4)
B(-3,16,-5,Leaves:4)
B(-6,12,8,Leaves:4)
B(-3,12,-2,Leaves:4)
B(5,15,-6,Leaves:4)
B(8,14,3,Leaves:4)
B(-4,15,7,Leaves:4)
B(-3,13,0,Leaves:4)
B(-3,16,0,Leaves:4)
B(-4,14,7,Leaves:4)
B(-3,15,0,Leaves:4)
B(-4,12,7,Leaves:4)
B(-3,16,-4,Leaves:4)
B(-3,12,0,Leaves:4)
B(2,-1,-1,LOG:12)
B(-7,12,0,Leaves:4)
B(8,13,3,Leaves:4)
B(9,12,-4,Leaves:4)
B(-1,16,-7,Leaves:4)
B(-3,17,0,Leaves:4)
B(5,10,-6,LOG:12)
B(2,8,0,LOG:12)
B(4,13,-9,Leaves:4)
B(2,7,0,LOG:12)
B(-5,12,8,Leaves:4)
B(4,15,-9,Leaves:4)
B(3,16,-1,Leaves:4)
B(1,-1,0,LOG:12)
B(3,13,-1,Leaves:4)
B(-6,15,7,Leaves:4)
B(-1,12,7,Leaves:4)
B(-5,14,6,Leaves:4)
B(-11,13,-2,Leaves:4)
B(5,16,-2,Leaves:4)
B(7,12,-12,Leaves:4)
B(0,0,-3,LOG:12)
B(-5,12,6,Leaves:4)
B(-1,16,1,Leaves:4)
B(8,12,-12,Leaves:4)
B(-1,17,1,Leaves:4)
B(0,13,4,Leaves:4)
B(8,15,-12,Leaves:4)
B(0,14,4,Leaves:4)
B(-11,14,4,Leaves:4)
B(8,13,-12,Leaves:4)
B(0,17,4,Leaves:4)
B(-1,17,-3,Leaves:4)
B(4,15,-7,Leaves:4)
B(-8,15,10,Leaves:4)
B(-1,13,-3,LOG:12)
B(-1,14,-3,LOG:12)
B(-8,13,2,Leaves:4)
B(-1,16,-3,Leaves:4)
B(-1,15,1,Leaves:4)
B(9,14,4,Leaves:4)
B(-8,14,11,Leaves:4)
B(-10,14,-6,Leaves:4)
B(-8,15,11,Leaves:4)
B(-2,16,-2,Leaves:4)
B(2,13,7,Leaves:4)
B(-7,14,-9,Leaves:4)
B(-2,15,-2,Leaves:4)
B(2,12,7,Leaves:4)
B(-3,15,12,leaves:4)
B(5,16,0,Leaves:4)
B(5,17,0,Leaves:4)
B(1,10,-1,LOG:12)
B(1,13,-1,LOG:12)
B(-12,14,-1,leaves:4)
B(8,12,-3,Leaves:4)
B(2,17,3,Leaves:4)
B(2,15,3,Leaves:4)
B(-5,16,0,Leaves:4)
B(2,12,3,Leaves:4)
B(1,-1,-2,LOG:12)
B(-4,15,3,Leaves:4)
B(-3,14,7,Leaves:4)
B(-5,13,0,Leaves:4)
B(-4,14,3,Leaves:4)
B(-11,14,-1,Leaves:4)
B(-5,12,0,Leaves:4)
B(-3,12,7,Leaves:4)
B(0,3,-1,LOG:12)
B(0,2,-1,LOG:12)
B(0,1,-1,LOG:12)
B(0,0,-1,LOG:12)
B(-6,16,-1,Leaves:4)
B(-6,17,-1,Leaves:4)
B(-6,14,-1,Leaves:4)
B(7,16,-2,Leaves:4)
B(11,14,5,leaves:4)
B(-7,12,4,Leaves:4)
B(-6,13,-1,Leaves:4)
B(5,13,2,Leaves:4)
B(-7,15,4,Leaves:4)
B(-7,16,4,Leaves:4)
B(5,15,2,Leaves:4)
B(0,4,-1,LOG:12)
B(7,16,1,Leaves:4)
B(6,14,0,Leaves:4)
B(6,13,0,Leaves:4)
B(-9,16,4,Leaves:4)
B(4,15,-3,Leaves:4)
B(4,16,-3,Leaves:4)
B(-1,14,7,Leaves:4)
B(-6,15,4,Leaves:4)
B(1,15,-8,Leaves:4)
B(-6,14,4,Leaves:4)
B(-4,10,3,LOG:12)
B(4,12,-12,Leaves:4)
B(4,13,-12,Leaves:4)
B(4,15,-12,Leaves:4)
B(2,14,4,Leaves:4)
B(1,17,0,Leaves:4)
B(2,16,4,Leaves:4)
B(-4,14,-6,Leaves:4)
B(1,15,0,Leaves:4)
B(-1,17,-1,Leaves:4)
B(-6,16,2,Leaves:4)
B(-1,15,-1,Leaves:4)
B(-1,13,-1,Leaves:4)
B(-8,15,12,leaves:4)
B(10,14,3,Leaves:4)
B(-8,14,6,Leaves:4)
B(10,13,3,Leaves:4)
B(-8,16,6,Leaves:4)
B(3,12,-8,Leaves:4)
B(-4,15,10,Leaves:4)
B(7,12,-7,Leaves:4)
B(-4,13,10,Leaves:4)
B(-2,14,2,Leaves:4)
B(-4,12,10,Leaves:4)
B(0,-2,-2,LOG:12)
B(0,15,-6,Leaves:4)
B(0,16,-6,Leaves:4)
B(7,13,-14,Leaves:4)
B(7,15,-8,Leaves:4)
B(-10,15,-5,Leaves:4)
B(-5,12,2,Leaves:4)
B(1,-1,-1,LOG:12)
B(1,-3,-1,LOG:12)
B(1,-2,-1,LOG:12)
B(7,12,-9,Leaves:4)
B(7,12,-8,LOG:12)
B(10,12,-9,Leaves:4)
B(-2,14,-1,Leaves:4)
B(-2,16,-9,Leaves:4)
B(-4,15,-8,Leaves:4)
B(-2,16,-1,Leaves:4)
B(-2,15,-9,Leaves:4)
B(1,-2,1,LOG:12)
B(-2,13,-9,Leaves:4)
B(1,-1,1,LOG:12)
B(12,13,-14,Leaves:4)
B(0,-1,-2,LOG:12)
B(-2,13,-1,Leaves:4)
B(-11,14,2,Leaves:4)
B(-11,15,10,Leaves:4)
B(12,12,-11,Leaves:4)
B(2,-2,-3,LOG:12)
B(-10,13,1,Leaves:4)
B(2,-1,-3,LOG:12)
B(13,12,-8,Leaves:4)
B(-5,15,5,Leaves:4)
B(0,-1,0,LOG:12)
B(0,-2,0,LOG:12)
B(2,6,-3,LOG:12)
B(2,5,-3,LOG:12)
B(2,17,-2,Leaves:4)
B(6,15,-4,Leaves:4)
B(2,16,-2,Leaves:4)
B(-2,13,-5,Leaves:4)
B(6,15,3,Leaves:4)
B(2,16,1,Leaves:4)
B(-6,12,-7,Leaves:4)
B(2,0,-3,LOG:12)
B(-3,14,-11,leaves:4)
B(-1,14,9,Leaves:4)
B(-6,14,-5,Leaves:4)
B(-6,16,-5,Leaves:4)
B(-6,17,-5,Leaves:4)
B(10,13,5,Leaves:4)
B(-6,13,-5,Leaves:4)
B(9,13,-13,Leaves:4)
B(4,17,-1,Leaves:4)
B(9,12,-13,Leaves:4)
B(-6,14,-10,Leaves:4)
B(4,13,-1,Leaves:4)
B(12,14,-13,Leaves:4)
B(5,12,-11,Leaves:4)
B(2,0,-1,LOG:12)
B(-10,16,1,Leaves:4)
B(11,14,-7,Leaves:4)
B(-5,15,-6,LOG:12)
B(-5,14,-6,LOG:12)
B(4,13,4,Leaves:4)
B(-8,14,-2,Leaves:4)
B(4,16,5,Leaves:4)
B(-8,14,7,LOG:12)
B(10,14,6,Leaves:4)
B(-8,13,-2,Leaves:4)
B(-8,15,7,LOG:12)
B(2,12,-10,Leaves:4)
B(4,17,4,Leaves:4)
B(2,15,-10,Leaves:4)
B(1,13,1,Leaves:4)
B(1,13,3,Leaves:4)
B(1,14,3,Leaves:4)
B(8,12,-8,Leaves:4)
B(1,17,2,Leaves:4)
B(-3,16,-6,Leaves:4)
B(-3,15,-6,Leaves:4)
B(6,14,-11,Leaves:4)
B(6,15,-11,Leaves:4)
B(5,12,-8,Leaves:4)
B(3,12,-11,Leaves:4)
B(1,17,3,Leaves:4)
B(-6,15,3,Leaves:4)
B(12,12,-9,Leaves:4)
B(-6,16,3,Leaves:4)
B(12,13,-9,Leaves:4)
B(14,14,-10,Leaves:4)
B(4,15,-10,Leaves:4)
B(1,13,6,Leaves:4)
B(8,14,1,Leaves:4)
B(8,13,6,Leaves:4)
B(1,0,1,LOG:12)
B(1,14,6,Leaves:4)
B(1,13,8,Leaves:4)
B(-3,12,5,LOG:12)
B(0,13,3,Leaves:4)
B(-8,14,4,Leaves:4)
B(-4,14,0,Leaves:4)
B(-12,14,-3,leaves:4)
B(-4,12,2,Leaves:4)
B(0,14,3,Leaves:4)
B(-4,14,2,Leaves:4)
B(-8,15,8,Leaves:4)
B(-6,14,3,Leaves:4)
B(-8,14,8,Leaves:4)
B(-6,13,3,Leaves:4)
B(5,15,-10,Leaves:4)
B(0,-1,-3,LOG:12)
B(1,15,11,Leaves:4)
B(10,13,-12,Leaves:4)
B(-11,15,7,Leaves:4)
B(-6,14,9,Leaves:4)
B(5,13,3,LOG:12)
B(3,13,7,Leaves:4)
B(7,13,8,Leaves:4)
B(3,15,7,Leaves:4)
B(-6,12,9,Leaves:4)
B(7,14,8,Leaves:4)
B(7,13,-1,Leaves:4)
B(-2,16,-8,Leaves:4)
B(-5,14,4,Leaves:4)
B(-5,11,4,LOG:12)
B(-12,14,0,leaves:4)
B(-2,13,7,Leaves:4)
B(-2,14,7,LOG:12)
B(9,14,-11,Leaves:4)
B(-2,12,7,Leaves:4)
B(9,13,-11,Leaves:4)
B(-2,16,7,Leaves:4)
B(-2,15,7,LOG:12)
B(6,12,-3,Leaves:4)
B(-10,15,-4,Leaves:4)
B(8,13,0,Leaves:4)
B(6,15,-3,Leaves:4)
B(11,14,-14,Leaves:4)
B(2,17,-4,Leaves:4)
B(-5,15,4,Leaves:4)
B(-9,14,3,Leaves:4)
B(-9,16,3,Leaves:4)
B(5,13,6,Leaves:4)
B(13,12,-9,Leaves:4)
B(-6,13,0,Leaves:4)
B(-6,14,0,Leaves:4)
B(-6,16,0,Leaves:4)
B(2,15,-4,Leaves:4)
B(-10,14,10,Leaves:4)
B(-2,15,-10,Leaves:4)
B(8,14,-11,Leaves:4)
B(-1,15,-9,Leaves:4)
B(-1,16,-9,Leaves:4)
B(11,14,2,leaves:4)
B(-9,12,-3,Leaves:4)
B(-5,12,-7,Leaves:4)
B(13,12,-10,Leaves:4)
B(-1,15,-2,Leaves:4)
B(-2,8,0,LOG:12)
B(-5,12,-4,Leaves:4)
B(4,12,-6,Leaves:4)
B(8,12,-9,LOG:12)
B(11,14,-8,Leaves:4)
B(-5,17,-4,Leaves:4)
B(4,15,-6,Leaves:4)
B(11,15,-8,Leaves:4)
B(8,13,-9,Leaves:4)
B(-9,13,-3,Leaves:4)
B(-6,14,-3,Leaves:4)
B(-4,17,-2,Leaves:4)
B(-5,15,-2,Leaves:4)
B(1,1,0,LOG:12)
B(1,2,0,LOG:12)
B(-5,14,-2,Leaves:4)
B(-5,13,-2,Leaves:4)
B(-5,12,-2,LOG:12)
B(1,0,0,LOG:12)
B(3,8,-4,LOG:12)
B(3,7,-4,LOG:12)
B(5,13,5,Leaves:4)
B(10,14,-10,Leaves:4)
B(-7,12,3,Leaves:4)
B(-9,13,-6,Leaves:4)
B(-4,12,-2,Leaves:4)
B(0,13,1,Leaves:4)
B(-9,14,-6,Leaves:4)
B(-4,13,-2,Leaves:4)
B(-4,14,-2,Leaves:4)
B(0,16,1,Leaves:4)
B(-4,15,-2,Leaves:4)
B(9,13,0,Leaves:4)
B(0,17,1,Leaves:4)
B(-5,16,-2,Leaves:4)
B(6,15,-9,Leaves:4)
B(-8,15,-6,Leaves:4)
B(-8,14,-6,Leaves:4)
B(-8,13,-6,Leaves:4)
B(5,13,7,Leaves:4)
B(-6,16,1,Leaves:4)
B(2,17,5,Leaves:4)
B(2,15,5,Leaves:4)
B(2,14,5,Leaves:4)
B(0,15,11,Leaves:4)
B(2,13,5,Leaves:4)
B(-4,14,8,Leaves:4)
B(-4,15,8,Leaves:4)
B(-7,13,1,Leaves:4)
B(-7,12,1,Leaves:4)
B(7,12,-13,Leaves:4)
B(-1,17,-5,Leaves:4)
B(-5,13,-7,Leaves:4)
B(-5,16,-7,Leaves:4)
B(-1,15,-5,Leaves:4)
B(5,13,-9,Leaves:4)
B(7,14,-13,Leaves:4)
B(2,17,2,Leaves:4)
B(7,13,-10,Leaves:4)
B(2,15,2,Leaves:4)
B(-5,17,-1,Leaves:4)
B(4,13,-2,Leaves:4)
B(4,15,-2,Leaves:4)
B(-5,14,-1,Leaves:4)
B(7,15,-10,Leaves:4)
B(-7,17,-2,Leaves:4)
B(5,15,-1,Leaves:4)
B(-7,16,-2,Leaves:4)
B(-1,15,-4,Leaves:4)
B(-1,16,-4,Leaves:4)
B(-7,15,-4,Leaves:4)
B(5,16,-1,Leaves:4)
B(-8,15,-3,Leaves:4)
B(4,15,-8,Leaves:4)
B(-8,14,-3,Leaves:4)
B(-7,13,-2,Leaves:4)
B(-6,15,11,Leaves:4)
B(0,0,-2,LOG:12)
B(-5,12,-3,Leaves:4)
B(5,12,-5,Leaves:4)
B(0,1,-2,LOG:12)
B(0,2,-2,LOG:12)
B(-5,14,-3,Leaves:4)
B(-5,13,-3,Leaves:4)
B(-5,15,-3,Leaves:4)
B(-4,13,-4,Leaves:4)
B(-4,12,-4,LOG:12)
B(11,13,-6,Leaves:4)
B(11,12,-6,Leaves:4)
B(5,14,-12,Leaves:4)
B(3,10,1,LOG:12)
B(10,14,-11,LOG:12)
B(-10,15,11,Leaves:4)
B(0,2,0,LOG:12)
B(0,3,0,LOG:12)
B(0,0,0,LOG:12)
B(-8,16,5,Leaves:4)
B(6,15,-6,Leaves:4)
B(-2,14,5,Leaves:4)
B(-8,14,5,Leaves:4)
B(-8,15,-4,Leaves:4)
B(-8,12,5,Leaves:4)
B(6,12,-6,Leaves:4)
B(-3,9,-1,LOG:12)
B(-9,15,6,Leaves:4)
B(10,15,-6,Leaves:4)
B(8,13,-13,Leaves:4)
B(-9,14,6,Leaves:4)
B(10,14,-6,Leaves:4)
B(11,14,-11,Leaves:4)
B(-3,15,3,Leaves:4)
B(1,14,7,Leaves:4)
B(-10,15,6,Leaves:4)
B(-5,13,3,Leaves:4)
B(-7,15,7,Leaves:4)
B(0,14,7,Leaves:4)
B(-11,13,0,Leaves:4)
B(13,14,-11,Leaves:4)
B(-4,14,-1,Leaves:4)
B(11,12,-5,Leaves:4)
B(2,16,-5,Leaves:4)
B(2,15,-5,Leaves:4)
B(-5,14,3,Leaves:4)
B(-3,9,2,LOG:12)
B(-3,8,2,LOG:12)
B(-5,15,11,Leaves:4)
B(-1,15,3,Leaves:4)
B(2,12,-8,Leaves:4)
B(-3,12,6,Leaves:4)
B(-13,14,6,leaves:4)
B(2,17,-6,Leaves:4)
B(-3,13,6,LOG:12)
B(9,12,-5,Leaves:4)
B(7,13,5,Leaves:4)
B(9,13,-5,Leaves:4)
B(-10,16,4,Leaves:4)
B(4,16,-4,Leaves:4)
B(-2,13,8,Leaves:4)
B(12,14,-12,Leaves:4)
B(-2,15,8,Leaves:4)
B(5,12,-13,Leaves:4)
B(12,12,-12,Leaves:4)
B(-13,14,9,leaves:4)
B(9,14,5,Leaves:4)
B(0,15,-4,Leaves:4)
B(0,14,-4,Leaves:4)
B(0,16,-4,Leaves:4)
B(-10,15,2,Leaves:4)
B(5,15,-13,Leaves:4)
B(-10,14,2,Leaves:4)
B(4,15,3,Leaves:4)
B(7,13,-5,Leaves:4)
B(7,12,-5,Leaves:4)
B(5,12,-7,Leaves:4)
B(-9,15,7,Leaves:4)
B(-9,14,7,Leaves:4)
B(7,13,3,Leaves:4)
B(7,14,3,Leaves:4)
B(9,12,-9,Leaves:4)
B(-2,15,4,Leaves:4)
B(8,14,8,Leaves:4)
B(-2,14,4,Leaves:4)
B(-5,13,-10,Leaves:4)
B(-11,15,3,Leaves:4)
B(-12,14,1,leaves:4)
B(-2,16,4,Leaves:4)
B(6,11,-7,LOG:12)
B(-4,11,-3,LOG:12)
B(-3,11,4,LOG:12)
B(-4,13,-3,Leaves:4)
B(6,14,9,leaves:4)
B(1,17,-6,Leaves:4)
B(8,15,-6,Leaves:4)
B(-2,7,1,LOG:12)
B(-2,6,1,LOG:12)
B(8,14,-6,Leaves:4)
B(-10,15,5,Leaves:4)
B(-10,14,5,Leaves:4)
B(9,12,-6,Leaves:4)
B(9,14,-6,Leaves:4)
B(1,14,4,Leaves:4)
B(0,12,5,Leaves:4)
B(0,15,-3,Leaves:4)
B(0,13,5,Leaves:4)
B(-2,15,-4,LOG:12)
B(-7,13,6,LOG:12)
B(8,13,-10,Leaves:4)
B(-3,15,10,Leaves:4)
B(-1,12,0,Leaves:4)
B(-3,13,9,Leaves:4)
B(8,12,-10,Leaves:4)
B(-9,15,12,leaves:4)
B(-7,12,-5,Leaves:4)
B(-1,16,0,Leaves:4)
B(0,16,5,Leaves:4)
B(-7,16,-5,Leaves:4)
B(-7,14,8,Leaves:4)
B(-7,14,-5,Leaves:4)
B(-7,13,-5,Leaves:4)
B(10,13,-8,Leaves:4)
B(10,14,-8,Leaves:4)
B(9,12,-12,Leaves:4)
B(9,13,-12,Leaves:4)
B(6,13,6,Leaves:4)
B(11,14,-13,Leaves:4)
B(-4,14,6,Leaves:4)
B(-1,17,4,Leaves:4)
B(-4,12,6,Leaves:4)
B(3,17,5,Leaves:4)
B(10,15,-8,Leaves:4)
B(-4,16,6,Leaves:4)
B(-4,13,-9,Leaves:4)
B(-3,13,-10,Leaves:4)
B(-10,14,0,Leaves:4)
B(10,13,2,Leaves:4)
B(2,15,0,LOG:12)
B(-4,15,-7,Leaves:4)
B(-2,14,11,Leaves:4)
B(0,15,-7,Leaves:4)
B(2,14,0,LOG:12)
B(-9,13,-5,Leaves:4)
B(1,16,-5,Leaves:4)
B(0,17,-7,Leaves:4)
B(8,12,-5,Leaves:4)
B(1,15,-5,Leaves:4)
B(-5,15,7,Leaves:4)
B(-2,14,3,Leaves:4)
B(6,13,5,Leaves:4)
B(-10,15,8,Leaves:4)
B(-6,14,-2,Leaves:4)
B(4,16,1,Leaves:4)
B(-6,13,-2,LOG:12)
B(-6,12,-2,Leaves:4)
B(-2,13,-7,Leaves:4)
B(9,13,-10,LOG:12)
B(-6,17,-2,Leaves:4)
B(-4,13,-7,Leaves:4)
B(4,9,-5,LOG:12)
B(-10,14,8,Leaves:4)
B(-2,12,1,Leaves:4)
B(-1,2,-1,LOG:12)
B(-1,3,-1,LOG:12)
B(-6,14,-6,Leaves:4)
B(-1,0,-1,LOG:12)
B(-6,12,-6,Leaves:4)
B(-2,16,1,Leaves:4)
B(1,13,9,Leaves:4)
B(-2,15,1,Leaves:4)
B(-2,13,1,Leaves:4)
B(1,15,-7,Leaves:4)
B(3,17,-3,Leaves:4)
B(4,12,2,LOG:12)
B(-2,17,1,Leaves:4)
B(-9,14,0,Leaves:4)
B(4,11,2,LOG:12)
B(4,14,2,Leaves:4)
B(-4,17,-9,Leaves:4)
B(4,13,2,Leaves:4)

#
# +-----------------------------------------------------------------+ #
# |                            BO3 checks                           | #
# +-----------------------------------------------------------------+ #
#

BlockCheck(0,-1,0,GRASS,DIRT,MYCELIUM)

#
# +-----------------------------------------------------------------+ #
# |                             Branches                            | #
# +-----------------------------------------------------------------+ #
#

