
#
# +-----------------------------------------------------------------+ #
# |                            BO3 object                           | #
# +-----------------------------------------------------------------+ #
#

Author: NLBlackEagle

Description: Converted version of the BO2 AFR11S

Version: 3

SettingsMode: WriteDisable


#
# +-----------------------------------------------------------------+ #
# |                          Main settings                          | #
# +-----------------------------------------------------------------+ #
#

Tree: true

Frequency: 1

Rarity: 100.0

RotateRandomly: true

SpawnHeight: highestSolidBlock

SpawnHeightOffset: -3

SpawnHeightVariance: 0


# Height Limits for the BO3. #


MinHeight: 0

MaxHeight: 199


# Extrusion settings #


ExtrudeMode: None

ExtrudeThroughBlocks: air

MaxBranchDepth: 10

ExcludedBiomes: 


#
# +-----------------------------------------------------------------+ #
# |                      Source block settings                      | #
# +-----------------------------------------------------------------+ #
#

SourceBlocks: AIR,GRASS,DIRT,SAND

MaxPercentageOutsideSourceBlock: 0

OutsideSourceBlock: placeAnyway


#
# +-----------------------------------------------------------------+ #
# |                              Blocks                             | #
# +-----------------------------------------------------------------+ #
#

B(5,8,5,leaves:4)
B(-1,8,4,leaves:4)
B(1,10,3,leaves:4)
B(2,6,3,LOG:12)
B(-7,8,4,leaves:4)
B(2,7,2,LOG:12)
B(-1,7,4,leaves:4)
B(-7,9,-5,leaves:4)
B(8,8,1,leaves:4)
B(2,7,7,leaves:4)
B(3,8,-3,leaves:4)
B(1,8,5,leaves:4)
B(-3,10,2,leaves:4)
B(-4,9,-8,leaves:4)
B(1,8,4,leaves:4)
B(0,10,-2,leaves:4)
B(-4,10,0,leaves:4)
B(-2,-1,0,LOG:12)
B(-2,-2,0,LOG:12)
B(-2,-3,0,LOG:12)
B(-3,7,4,leaves:4)
B(0,10,2,leaves:4)
B(-3,8,4,leaves:4)
B(-8,9,-4,leaves:4)
B(3,8,1,LOG:12)
B(3,9,1,leaves:4)
B(-6,10,3,leaves:4)
B(-1,8,0,leaves:4)
B(-1,9,0,leaves:4)
B(-5,8,0,leaves:4)
B(-5,6,0,leaves:4)
B(-5,7,0,leaves:4)
B(1,9,-6,leaves:4)
B(0,9,3,leaves:4)
B(-4,10,2,leaves:4)
B(0,7,3,leaves:4)
B(0,8,3,leaves:4)
B(0,7,2,leaves:4)
B(-7,7,0,leaves:4)
B(1,8,-5,leaves:4)
B(3,8,5,leaves:4)
B(-6,9,-5,LOG:12)
B(3,10,-2,leaves:4)
B(-2,10,6,leaves:4)
B(0,8,6,leaves:4)
B(-4,6,2,leaves:4)
B(-5,8,4,log:4)
B(-1,9,-6,leaves:4)
B(-5,8,-1,leaves:4)
B(-1,10,-2,leaves:4)
B(-5,9,-1,leaves:4)
B(-9,7,4,leaves:4)
B(5,7,1,leaves:4)
B(-5,7,-2,leaves:4)
B(-5,9,-2,leaves:4)
B(-3,8,7,leaves:4)
B(1,8,-2,leaves:4)
B(4,8,-2,leaves:4)
B(4,7,-2,leaves:4)
B(4,8,5,LOG:12)
B(5,7,6,leaves:4)
B(0,9,-6,leaves:4)
B(-3,10,-4,leaves:4)
B(1,7,-1,leaves:4)
B(1,8,-1,LOG:12)
B(-2,8,0,leaves:4)
B(4,9,-3,leaves:4)
B(-7,7,5,leaves:4)
B(3,9,-2,leaves:4)
B(-10,9,-3,leaves:4)
B(-9,9,-7,Leaves:4)
B(-5,7,-3,leaves:4)
B(4,8,-3,leaves:4)
B(1,9,-1,leaves:4)
B(-5,9,-3,leaves:4)
B(-2,10,-3,leaves:4)
B(-2,0,0,LOG:12)
B(-2,2,0,LOG:12)
B(-4,7,5,leaves:4)
B(-6,10,1,leaves:4)
B(-2,1,0,LOG:12)
B(3,8,-4,leaves:4)
B(1,9,-3,leaves:4)
B(1,8,-3,leaves:4)
B(1,9,-4,leaves:4)
B(1,7,-4,leaves:4)
B(0,6,-6,leaves:4)
B(-3,9,-2,leaves:4)
B(-1,10,-4,leaves:4)
B(-3,5,-2,LOG:12)
B(-3,6,-2,LOG:12)
B(-3,7,-2,leaves:4)
B(-3,8,5,leaves:4)
B(-5,9,-7,leaves:4)
B(-8,9,-5,leaves:4)
B(-3,7,3,leaves:4)
B(-2,7,3,leaves:4)
B(2,10,5,leaves:4)
B(-2,7,4,leaves:4)
B(-2,9,3,leaves:4)
B(-9,9,-3,leaves:4)
B(0,2,1,LOG:12)
B(3,8,-6,leaves:4)
B(-2,8,3,leaves:4)
B(3,9,-8,leaves:4)
B(-5,9,-6,leaves:4)
B(0,3,1,LOG:12)
B(0,6,1,leaves:4)
B(-5,7,1,leaves:4)
B(-8,8,1,leaves:4)
B(-4,9,-5,leaves:4)
B(2,10,2,leaves:4)
B(-4,9,-4,leaves:4)
B(-9,8,1,leaves:4)
B(4,9,1,leaves:4)
B(-5,8,9,leaves:4)
B(6,7,1,leaves:4)
B(6,8,1,leaves:4)
B(4,7,1,leaves:4)
B(4,8,1,leaves:4)
B(4,8,0,leaves:4)
B(-7,9,1,leaves:4)
B(-4,10,5,leaves:4)
B(-3,10,-2,leaves:4)
B(4,7,0,leaves:4)
B(1,7,1,leaves:4)
B(-6,8,-1,leaves:4)
B(-4,8,1,leaves:4)
B(-9,8,3,leaves:4)
B(-9,7,3,leaves:4)
B(-6,8,5,leaves:4)
B(1,9,1,leaves:4)
B(5,8,0,leaves:4)
B(1,8,1,leaves:4)
B(7,8,-1,leaves:4)
B(3,7,6,leaves:4)
B(0,7,-2,leaves:4)
B(-5,7,3,leaves:4)
B(5,8,-3,leaves:4)
B(-6,7,-2,leaves:4)
B(1,7,0,leaves:4)
B(-5,9,3,leaves:4)
B(-3,9,-6,leaves:4)
B(4,8,9,leaves:4)
B(3,7,4,LOG:12)
B(-2,7,-6,leaves:4)
B(-2,6,-6,leaves:4)
B(-3,6,-6,leaves:4)
B(-5,7,5,leaves:4)
B(-4,9,-1,leaves:4)
B(-4,7,3,LOG:12)
B(5,8,2,leaves:4)
B(-4,8,-1,leaves:4)
B(3,8,8,leaves:4)
B(2,8,0,leaves:4)
B(-4,9,4,leaves:4)
B(2,7,0,leaves:4)
B(3,6,2,leaves:4)
B(2,6,0,leaves:4)
B(-1,6,2,leaves:4)
B(3,7,2,leaves:4)
B(-4,7,4,leaves:4)
B(-1,7,2,leaves:4)
B(3,8,2,leaves:4)
B(-1,9,2,leaves:4)
B(-1,9,1,leaves:4)
B(5,9,-6,leaves:4)
B(-3,7,-5,leaves:4)
B(2,7,1,leaves:4)
B(0,7,0,leaves:4)
B(-1,4,1,LOG:12)
B(-1,6,1,leaves:4)
B(4,8,6,leaves:4)
B(-3,7,-1,leaves:4)
B(-1,0,1,LOG:12)
B(1,7,2,leaves:4)
B(-1,10,-3,leaves:4)
B(-3,9,-1,leaves:4)
B(-3,9,-3,leaves:4)
B(-6,9,-3,leaves:4)
B(0,9,-5,leaves:4)
B(-1,1,1,LOG:12)
B(1,5,2,LOG:12)
B(4,7,6,leaves:4)
B(0,8,-5,leaves:4)
B(-3,8,-1,leaves:4)
B(5,9,-4,leaves:4)
B(-4,8,0,leaves:4)
B(5,8,-4,leaves:4)
B(0,8,-3,leaves:4)
B(0,7,-3,leaves:4)
B(-4,6,0,leaves:4)
B(1,9,2,leaves:4)
B(1,9,3,leaves:4)
B(1,8,3,leaves:4)
B(1,8,7,leaves:4)
B(0,9,-9,leaves:4)
B(1,9,6,leaves:4)
B(3,9,-5,leaves:4)
B(4,9,2,leaves:4)
B(4,8,2,leaves:4)
B(-4,8,8,leaves:4)
B(4,8,4,leaves:4)
B(1,10,-1,leaves:4)
B(5,8,7,leaves:4)
B(-3,7,2,leaves:4)
B(-3,6,2,LOG:12)
B(-4,10,-1,leaves:4)
B(6,7,2,leaves:4)
B(-7,8,7,leaves:4)
B(-3,8,2,leaves:4)
B(7,8,5,leaves:4)
B(-2,10,-4,leaves:4)
B(2,10,-3,leaves:4)
B(0,8,-1,leaves:4)
B(0,7,-1,LOG:12)
B(0,6,-1,leaves:4)
B(2,8,10,leaves:4)
B(-7,9,-8,leaves:4)
B(0,7,4,leaves:4)
B(0,8,4,leaves:4)
B(6,7,0,leaves:4)
B(0,7,5,leaves:4)
B(1,4,2,LOG:12)
B(0,8,5,leaves:4)
B(-4,10,3,leaves:4)
B(2,10,-1,leaves:4)
B(0,9,0,leaves:4)
B(-2,7,-2,leaves:4)
B(3,8,-1,leaves:4)
B(2,8,4,leaves:4)
B(-1,8,5,leaves:4)
B(2,9,4,leaves:4)
B(-10,9,-4,Leaves:4)
B(-1,7,5,leaves:4)
B(4,10,3,leaves:4)
B(3,9,-1,leaves:4)
B(4,8,-4,leaves:4)
B(2,7,5,leaves:4)
B(0,8,1,leaves:4)
B(2,8,5,leaves:4)
B(-1,9,6,leaves:4)
B(0,9,1,leaves:4)
B(-3,6,-4,leaves:4)
B(-1,9,-4,leaves:4)
B(-2,5,2,LOG:12)
B(-1,10,5,leaves:4)
B(-1,6,-4,leaves:4)
B(-5,8,-4,LOG:12)
B(-1,6,-5,leaves:4)
B(-5,9,-5,leaves:4)
B(-5,7,6,leaves:4)
B(-1,9,-5,leaves:4)
B(-2,7,1,leaves:4)
B(0,9,-4,LOG:12)
B(-5,8,6,leaves:4)
B(-1,8,-3,LOG:12)
B(-5,9,-8,leaves:4)
B(-9,9,-1,leaves:4)
B(6,8,6,leaves:4)
B(-5,9,-9,leaves:4)
B(-2,10,2,leaves:4)
B(-1,9,-2,leaves:4)
B(0,10,5,leaves:4)
B(-1,-1,1,LOG:12)
B(-1,-2,1,LOG:12)
B(-5,10,2,leaves:4)
B(-1,10,-1,leaves:4)
B(4,7,3,leaves:4)
B(-3,7,0,leaves:4)
B(-3,9,0,leaves:4)
B(0,10,-1,leaves:4)
B(-2,10,-1,leaves:4)
B(-8,9,-3,leaves:4)
B(7,7,2,leaves:4)
B(7,8,2,leaves:4)
B(-1,9,-7,leaves:4)
B(-2,9,-8,leaves:4)
B(2,7,-3,leaves:4)
B(6,8,3,leaves:4)
B(2,10,1,leaves:4)
B(7,7,0,leaves:4)
B(6,7,3,leaves:4)
B(2,9,-3,leaves:4)
B(-1,10,6,leaves:4)
B(2,9,-4,leaves:4)
B(-2,10,3,leaves:4)
B(-7,9,-1,leaves:4)
B(-4,9,-6,leaves:4)
B(-2,9,-1,leaves:4)
B(-2,8,-1,leaves:4)
B(-2,7,-1,leaves:4)
B(-2,4,-1,LOG:12)
B(-2,3,-1,LOG:12)
B(-4,9,-7,leaves:4)
B(4,10,1,leaves:4)
B(-4,7,-3,LOG:12)
B(-1,6,-1,LOG:12)
B(2,8,-2,leaves:4)
B(-1,5,-1,LOG:12)
B(2,7,-1,leaves:4)
B(-2,8,-4,leaves:4)
B(-2,10,4,leaves:4)
B(-7,9,-3,leaves:4)
B(-2,7,-4,leaves:4)
B(2,8,-1,leaves:4)
B(-4,9,-3,leaves:4)
B(-4,9,-2,leaves:4)
B(-7,9,-7,leaves:4)
B(-2,7,-3,LOG:12)
B(-4,8,-2,leaves:4)

#
# +-----------------------------------------------------------------+ #
# |                            BO3 checks                           | #
# +-----------------------------------------------------------------+ #
#

BlockCheck(0,-1,0,grass,dirt)

#
# +-----------------------------------------------------------------+ #
# |                             Branches                            | #
# +-----------------------------------------------------------------+ #
#

