
#
# +-----------------------------------------------------------------+ #
# |                            BO3 object                           | #
# +-----------------------------------------------------------------+ #
#

Author: NLBlackEagle

Description: Converted version of the BO2 AFR6L

Version: 3

SettingsMode: WriteDisable


#
# +-----------------------------------------------------------------+ #
# |                          Main settings                          | #
# +-----------------------------------------------------------------+ #
#

Tree: true

Frequency: 1

Rarity: 100.0

RotateRandomly: true

SpawnHeight: highestSolidBlock

SpawnHeightOffset: -3

SpawnHeightVariance: 0


# Height Limits for the BO3. #


MinHeight: 0

MaxHeight: 199


# Extrusion settings #


ExtrudeMode: None

ExtrudeThroughBlocks: air

MaxBranchDepth: 10

ExcludedBiomes: 


#
# +-----------------------------------------------------------------+ #
# |                      Source block settings                      | #
# +-----------------------------------------------------------------+ #
#

SourceBlocks: AIR,GRASS,DIRT,SAND

MaxPercentageOutsideSourceBlock: 0

OutsideSourceBlock: placeAnyway


#
# +-----------------------------------------------------------------+ #
# |                              Blocks                             | #
# +-----------------------------------------------------------------+ #
#

B(1,17,-4,Leaves:4)
B(4,12,-5,Leaves:4)
B(3,14,-6,Leaves:4)
B(3,13,-6,Leaves:4)
B(-5,17,-5,leaves:4)
B(9,7,-5,leaves:4)
B(-5,16,-5,leaves:4)
B(4,16,-5,Leaves:4)
B(4,15,-5,Leaves:4)
B(1,15,-4,Leaves:4)
B(1,14,-4,Leaves:4)
B(0,14,-2,Leaves:4)
B(-3,13,2,Leaves:4)
B(0,13,-2,Leaves:4)
B(0,12,2,Leaves:4)
B(-3,8,4,leaves:4)
B(-4,12,1,Leaves:4)
B(-4,14,4,leaves:4)
B(-4,11,1,Leaves:4)
B(3,6,0,LOG:12)
B(0,17,-2,Leaves:4)
B(3,7,0,LOG:12)
B(3,14,2,Leaves:4)
B(3,8,0,LOG:12)
B(0,11,6,leaves:4)
B(0,12,6,leaves:4)
B(3,10,2,LOG:12)
B(8,12,-4,leaves:4)
B(0,10,6,leaves:4)
B(-1,12,5,leaves:4)
B(6,7,-1,LOG:12)
B(-7,12,2,leaves:4)
B(-3,13,-3,Leaves:4)
B(-3,14,-3,LOG:12)
B(0,15,0,Leaves:4)
B(-3,17,-3,Leaves:4)
B(-3,18,-3,Leaves:4)
B(-3,15,-3,LOG:12)
B(-6,16,-4,leaves:4)
B(10,8,-5,leaves:4)
B(-8,10,-5,leaves:4)
B(3,16,-5,Leaves:4)
B(3,17,-5,Leaves:4)
B(11,9,-3,leaves:4)
B(3,11,-5,Leaves:4)
B(3,12,-4,Leaves:4)
B(-5,9,4,leaves:4)
B(3,13,-2,Leaves:4)
B(3,14,-2,Leaves:4)
B(3,15,-2,Leaves:4)
B(3,13,-5,Leaves:4)
B(-4,8,2,Leaves:4)
B(-4,9,2,LOG:12)
B(6,8,-5,Leaves:4)
B(1,0,-1,LOG:12)
B(8,7,-4,leaves:4)
B(9,8,-6,leaves:4)
B(1,1,-1,LOG:12)
B(0,9,-6,LOG:12)
B(-9,11,-4,leaves:4)
B(1,2,-1,LOG:12)
B(1,0,-2,LOG:12)
B(1,1,-2,LOG:12)
B(8,7,-3,leaves:4)
B(8,9,-3,LOG:12)
B(8,7,-2,leaves:4)
B(-2,15,-6,Leaves:4)
B(-2,17,-6,Leaves:4)
B(-7,12,-3,leaves:4)
B(7,10,-6,Leaves:4)
B(-2,16,0,Leaves:4)
B(-7,13,-6,leaves:4)
B(-7,10,-6,leaves:4)
B(-2,17,-3,Leaves:4)
B(3,12,0,Leaves:4)
B(-2,13,-3,Leaves:4)
B(-2,12,-3,Leaves:4)
B(3,13,0,Leaves:4)
B(-2,15,-3,Leaves:4)
B(-8,10,-7,leaves:4)
B(3,11,0,Leaves:4)
B(-2,14,-3,Leaves:4)
B(-2,14,0,Leaves:4)
B(4,11,0,LOG:12)
B(4,13,0,Leaves:4)
B(-3,8,3,leaves:4)
B(4,10,0,LOG:12)
B(3,13,4,leaves:4)
B(-5,9,1,leaves:4)
B(-4,10,-5,leaves:4)
B(-4,13,4,leaves:4)
B(-4,10,4,leaves:4)
B(-4,11,4,leaves:4)
B(5,13,-4,Leaves:4)
B(1,11,5,leaves:4)
B(1,12,5,LOG:12)
B(1,10,5,leaves:4)
B(0,13,-8,log)
B(0,12,-8,LOG:12)
B(1,13,5,leaves:4)
B(0,17,-8,Leaves:4)
B(0,16,-8,Leaves:4)
B(0,14,-5,Leaves:4)
B(0,15,-8,log)
B(-3,16,-2,Leaves:4)
B(0,14,-8,log)
B(0,15,-5,Leaves:4)
B(-3,12,-2,Leaves:4)
B(-4,9,1,Leaves:4)
B(-5,8,3,leaves:4)
B(5,9,-3,Leaves:4)
B(-3,13,-4,Leaves:4)
B(-3,14,0,Leaves:4)
B(-3,12,-4,Leaves:4)
B(6,13,1,leaves:4)
B(-3,17,-4,Leaves:4)
B(-3,18,-4,Leaves:4)
B(-1,12,-7,Leaves:4)
B(-4,8,3,leaves:4)
B(7,9,-5,leaves:4)
B(7,7,-5,leaves:4)
B(3,15,-1,Leaves:4)
B(3,14,-1,Leaves:4)
B(3,12,-1,Leaves:4)
B(0,5,-3,LOG:12)
B(0,8,-5,LOG:12)
B(0,6,-3,LOG:12)
B(5,13,-2,Leaves:4)
B(0,14,4,leaves:4)
B(1,17,-1,Leaves:4)
B(-1,17,-3,Leaves:4)
B(1,9,6,leaves:4)
B(2,11,7,leaves:4)
B(4,13,-7,Leaves:4)
B(-1,15,-3,Leaves:4)
B(-1,16,-3,Leaves:4)
B(-1,15,1,Leaves:4)
B(-2,12,-2,LOG:12)
B(-2,11,-2,LOG:12)
B(5,10,0,leaves:4)
B(-2,14,-2,Leaves:4)
B(-2,13,-2,LOG:12)
B(5,12,0,LOG:12)
B(5,13,0,LOG:12)
B(-2,18,-2,Leaves:4)
B(-2,17,-2,Leaves:4)
B(5,16,0,leaves:4)
B(2,17,-3,Leaves:4)
B(2,15,-3,Leaves:4)
B(8,12,-3,leaves:4)
B(1,-2,-2,LOG:12)
B(2,12,3,leaves:4)
B(1,-1,-2,LOG:12)
B(2,11,3,LOG:12)
B(-5,11,0,leaves:4)
B(-4,13,3,leaves:4)
B(0,1,-1,LOG:12)
B(0,0,-1,LOG:12)
B(7,13,-2,Leaves:4)
B(5,13,2,leaves:4)
B(2,14,-3,Leaves:4)
B(5,15,2,leaves:4)
B(0,9,4,leaves:4)
B(6,13,0,leaves:4)
B(6,12,0,leaves:4)
B(4,13,-3,Leaves:4)
B(2,13,-1,Leaves:4)
B(4,14,-3,Leaves:4)
B(1,15,-8,Leaves:4)
B(-4,10,3,LOG:12)
B(-4,11,3,LOG:12)
B(1,13,-8,Leaves:4)
B(-5,10,0,leaves:4)
B(-4,12,3,leaves:4)
B(1,14,-8,Leaves:4)
B(-7,7,-6,leaves:4)
B(-6,11,4,leaves:4)
B(-6,10,4,leaves:4)
B(6,9,-3,Leaves:4)
B(7,15,2,leaves:4)
B(1,14,0,Leaves:4)
B(9,7,-4,leaves:4)
B(9,8,-4,leaves:4)
B(2,11,4,LOG:12)
B(7,13,2,leaves:4)
B(9,9,-4,leaves:4)
B(2,12,4,leaves:4)
B(-1,17,-1,Leaves:4)
B(2,13,-7,Leaves:4)
B(-1,13,-1,Leaves:4)
B(0,7,-4,LOG:12)
B(-5,14,2,leaves:4)
B(-1,4,-2,LOG:12)
B(7,11,2,leaves:4)
B(-2,11,2,Leaves:4)
B(-1,9,-2,LOG:12)
B(3,15,-8,Leaves:4)
B(-1,7,-2,LOG:12)
B(-1,8,-2,LOG:12)
B(-10,10,-5,leaves:4)
B(0,14,-6,Leaves:4)
B(0,16,-6,Leaves:4)
B(-3,15,-8,Leaves:4)
B(7,13,0,leaves:4)
B(7,12,0,leaves:4)
B(7,11,0,leaves:4)
B(1,-1,-1,LOG:12)
B(-5,12,2,leaves:4)
B(-2,17,-9,Leaves:4)
B(-2,14,-1,Leaves:4)
B(-2,15,-1,Leaves:4)
B(-2,16,-1,Leaves:4)
B(0,-1,-2,LOG:12)
B(0,15,-11,leaves:4)
B(-7,10,-8,leaves:4)
B(-7,11,-8,leaves:4)
B(2,13,-2,Leaves:4)
B(10,10,-3,leaves:4)
B(-5,11,5,leaves:4)
B(6,13,-4,Leaves:4)
B(2,17,-2,Leaves:4)
B(-2,13,-5,Leaves:4)
B(-6,10,-7,leaves:4)
B(-6,10,-5,leaves:4)
B(-6,11,-5,leaves:4)
B(6,9,-4,Leaves:4)
B(6,7,-4,Leaves:4)
B(4,11,-1,Leaves:4)
B(5,7,-1,LOG:12)
B(-7,9,-2,leaves:4)
B(4,13,-1,Leaves:4)
B(8,8,0,leaves:4)
B(8,9,0,leaves:4)
B(6,9,-2,Leaves:4)
B(2,3,-1,LOG:12)
B(2,5,-1,LOG:12)
B(2,4,-1,LOG:12)
B(-7,8,-3,leaves:4)
B(-7,9,-3,leaves:4)
B(-4,6,-2,LOG:12)
B(-7,9,-7,leaves:4)
B(-7,8,-7,leaves:4)
B(-3,15,-6,Leaves:4)
B(-7,7,-5,leaves:4)
B(-7,9,-5,LOG:12)
B(-7,8,-5,leaves:4)
B(8,13,1,leaves:4)
B(1,12,6,leaves:4)
B(1,11,6,leaves:4)
B(1,14,6,leaves:4)
B(1,13,8,leaves:4)
B(1,12,8,leaves:4)
B(10,9,-2,leaves:4)
B(-4,12,0,Leaves:4)
B(-3,13,5,leaves:4)
B(-4,10,0,leaves:4)
B(0,11,3,leaves:4)
B(0,14,3,leaves:4)
B(-6,13,3,leaves:4)
B(0,13,-10,leaves:4)
B(-6,11,3,leaves:4)
B(5,13,3,leaves:4)
B(5,14,3,leaves:4)
B(0,14,-9,Leaves:4)
B(-2,15,-8,Leaves:4)
B(7,10,-1,Leaves:4)
B(8,14,0,leaves:4)
B(8,13,0,leaves:4)
B(8,12,0,leaves:4)
B(2,17,-4,Leaves:4)
B(-6,7,-5,leaves:4)
B(2,11,-4,Leaves:4)
B(2,13,-4,Leaves:4)
B(-2,16,-10,leaves:4)
B(-1,10,-2,LOG:12)
B(-1,12,-9,Leaves:4)
B(8,9,-6,leaves:4)
B(-1,13,-5,Leaves:4)
B(-1,13,-6,Leaves:4)
B(10,7,-3,leaves:4)
B(-5,10,-4,leaves:4)
B(-2,9,0,LOG:12)
B(-5,6,-3,LOG:12)
B(4,12,-6,Leaves:4)
B(-5,14,-4,leaves:4)
B(-1,18,-2,Leaves:4)
B(-5,15,-4,leaves:4)
B(-5,9,-3,leaves:4)
B(-10,9,-5,leaves:4)
B(-7,11,3,leaves:4)
B(-4,18,-2,Leaves:4)
B(-7,10,3,leaves:4)
B(-4,9,5,leaves:4)
B(0,15,1,Leaves:4)
B(-5,17,-2,leaves:4)
B(0,16,1,Leaves:4)
B(-9,11,-6,leaves:4)
B(-1,13,-4,Leaves:4)
B(-3,5,-2,LOG:12)
B(-6,13,1,leaves:4)
B(-5,8,-7,leaves:4)
B(2,15,5,leaves:4)
B(-1,17,-8,Leaves:4)
B(-8,9,-5,leaves:4)
B(-2,9,4,leaves:4)
B(2,12,5,leaves:4)
B(10,9,-3,leaves:4)
B(-9,9,-3,leaves:4)
B(-1,16,-5,Leaves:4)
B(3,14,-7,Leaves:4)
B(-5,17,-1,leaves:4)
B(4,13,-2,Leaves:4)
B(-9,11,-7,leaves:4)
B(5,14,-3,Leaves:4)
B(5,15,-1,Leaves:4)
B(4,13,-8,Leaves:4)
B(5,14,-1,Leaves:4)
B(-1,16,-4,Leaves:4)
B(5,10,-3,Leaves:4)
B(5,11,-1,Leaves:4)
B(5,13,-1,Leaves:4)
B(4,14,-8,Leaves:4)
B(-8,10,-3,leaves:4)
B(4,9,0,LOG:12)
B(4,6,0,LOG:12)
B(-7,11,-2,leaves:4)
B(-7,10,-2,leaves:4)
B(0,0,-2,LOG:12)
B(0,1,-2,LOG:12)
B(5,12,-5,Leaves:4)
B(-5,12,-3,leaves:4)
B(0,2,-2,LOG:12)
B(7,8,-1,leaves:4)
B(-5,13,-3,leaves:4)
B(7,9,-1,leaves:4)
B(-5,17,-3,leaves:4)
B(-6,9,-2,leaves:4)
B(1,14,-2,Leaves:4)
B(0,3,-2,LOG:12)
B(-4,14,-4,Leaves:4)
B(0,4,-2,LOG:12)
B(-6,8,-4,LOG:12)
B(-6,7,-4,LOG:12)
B(3,10,1,LOG:12)
B(7,8,-2,LOG:12)
B(8,7,-1,leaves:4)
B(7,6,-3,leaves:4)
B(5,15,-5,Leaves:4)
B(5,16,-5,Leaves:4)
B(-4,8,4,leaves:4)
B(-2,13,5,leaves:4)
B(6,13,-6,Leaves:4)
B(6,13,-5,Leaves:4)
B(-3,14,3,leaves:4)
B(-3,12,3,leaves:4)
B(1,13,7,leaves:4)
B(0,-1,-1,LOG:12)
B(0,-2,-1,LOG:12)
B(0,-3,-1,LOG:12)
B(-5,10,3,leaves:4)
B(-2,11,5,leaves:4)
B(-5,11,3,leaves:4)
B(0,13,7,leaves:4)
B(0,10,7,leaves:4)
B(1,10,7,leaves:4)
B(-3,9,1,LOG:12)
B(2,16,-5,Leaves:4)
B(-6,9,4,leaves:4)
B(2,13,-8,Leaves:4)
B(-1,14,3,leaves:4)
B(-1,10,3,leaves:4)
B(7,11,-3,Leaves:4)
B(2,14,-6,Leaves:4)
B(9,11,-3,leaves:4)
B(4,17,-4,Leaves:4)
B(-1,16,-6,Leaves:4)
B(0,15,-4,Leaves:4)
B(0,14,-4,Leaves:4)
B(0,16,-4,Leaves:4)
B(9,9,-2,leaves:4)
B(-2,5,-2,LOG:12)
B(5,14,-7,Leaves:4)
B(-1,10,4,leaves:4)
B(-4,18,-3,Leaves:4)
B(-9,8,-5,leaves:4)
B(-5,9,-4,leaves:4)
B(1,12,-6,Leaves:4)
B(9,10,-6,leaves:4)
B(1,15,-6,Leaves:4)
B(-4,15,-3,Leaves:4)
B(1,10,4,leaves:4)
B(1,13,4,leaves:4)
B(0,16,-1,Leaves:4)
B(0,16,-3,Leaves:4)
B(0,15,-3,Leaves:4)
B(0,17,-1,Leaves:4)
B(0,10,5,leaves:4)
B(-1,15,0,Leaves:4)
B(-7,11,-5,leaves:4)
B(-7,10,-5,LOG:12)
B(5,10,1,leaves:4)
B(3,12,5,leaves:4)
B(3,11,5,leaves:4)
B(5,13,1,leaves:4)
B(-1,12,4,leaves:4)
B(5,14,1,leaves:4)
B(0,18,-3,Leaves:4)
B(0,14,-1,Leaves:4)
B(2,15,6,leaves:4)
B(6,10,-1,Leaves:4)
B(8,10,-5,leaves:4)
B(6,13,-1,Leaves:4)
B(6,14,-1,Leaves:4)
B(0,14,-7,Leaves:4)
B(1,13,-5,Leaves:4)
B(2,13,0,Leaves:4)
B(2,14,0,Leaves:4)
B(0,15,-7,Leaves:4)
B(0,17,-7,Leaves:4)
B(1,15,-5,Leaves:4)
B(-2,16,-7,Leaves:4)
B(0,10,-7,LOG:12)
B(2,12,0,Leaves:4)
B(0,11,-7,LOG:12)
B(-2,15,-7,Leaves:4)
B(-6,11,-2,leaves:4)
B(1,18,-9,Leaves:4)
B(9,6,-3,leaves:4)
B(-2,11,1,Leaves:4)
B(-2,10,1,leaves:4)
B(9,9,-3,leaves:4)
B(9,7,-3,leaves:4)
B(3,15,-3,Leaves:4)
B(3,14,-3,Leaves:4)
B(1,15,-7,Leaves:4)
B(-2,10,4,leaves:4)
B(-1,8,-1,LOG:12)
B(1,15,-11,leaves:4)
B(4,13,2,Leaves:4)

#
# +-----------------------------------------------------------------+ #
# |                            BO3 checks                           | #
# +-----------------------------------------------------------------+ #
#

BlockCheck(0,-1,0,grass,dirt)

#
# +-----------------------------------------------------------------+ #
# |                             Branches                            | #
# +-----------------------------------------------------------------+ #
#

