
#
# +-----------------------------------------------------------------+ #
# |                            BO3 object                           | #
# +-----------------------------------------------------------------+ #
#

Author: NLBlackEagle

Description: Converted version of the BO2 AFR7S

Version: 3

SettingsMode: WriteDisable


#
# +-----------------------------------------------------------------+ #
# |                          Main settings                          | #
# +-----------------------------------------------------------------+ #
#

Tree: true

Frequency: 1

Rarity: 100.0

RotateRandomly: true

SpawnHeight: highestSolidBlock

SpawnHeightOffset: -3

SpawnHeightVariance: 0


# Height Limits for the BO3. #


MinHeight: 0

MaxHeight: 199


# Extrusion settings #


ExtrudeMode: None

ExtrudeThroughBlocks: air

MaxBranchDepth: 10

ExcludedBiomes: 


#
# +-----------------------------------------------------------------+ #
# |                      Source block settings                      | #
# +-----------------------------------------------------------------+ #
#

SourceBlocks: AIR,GRASS,DIRT,SAND

MaxPercentageOutsideSourceBlock: 0

OutsideSourceBlock: placeAnyway


#
# +-----------------------------------------------------------------+ #
# |                              Blocks                             | #
# +-----------------------------------------------------------------+ #
#

B(-1,6,3,leaves:4)
B(-1,5,2,leaves:4)
B(-3,4,-5,leaves:4)
B(-3,5,-5,leaves:4)
B(2,4,3,leaves:4)
B(-1,3,3,leaves:4)
B(-4,5,4,leaves:4)
B(-1,2,4,leaves:4)
B(0,3,-5,leaves:4)
B(-1,4,1,leaves:4)
B(-1,5,4,leaves:4)
B(0,5,-5,leaves:4)
B(-1,4,4,LOG:13)
B(0,5,-3,leaves:4)
B(0,4,-3,leaves:4)
B(0,3,-3,leaves:4)
B(-6,3,-3,leaves:4)
B(-4,7,0,leaves:4)
B(-6,4,-3,leaves:4)
B(0,6,-3,leaves:4)
B(-3,3,-3,leaves:4)
B(1,3,4,leaves:4)
B(1,4,4,leaves:4)
B(-3,1,-3,leaves:4)
B(0,3,4,leaves:4)
B(0,2,4,leaves:4)
B(3,4,-3,leaves:4)
B(1,5,3,leaves:4)
B(-3,3,6,leaves:4)
B(1,5,6,leaves:4)
B(-1,1,0,LOG:13)
B(1,6,6,leaves:4)
B(-1,3,0,leaves:4)
B(-1,2,0,LOG:13)
B(-2,-1,0,LOG:13)
B(-3,6,4,leaves:4)
B(-2,-2,0,LOG:13)
B(3,6,-5,leaves:4)
B(-2,-3,0,LOG:13)
B(3,3,-5,leaves:4)
B(3,4,0,leaves:4)
B(-3,6,2,leaves:4)
B(-2,3,5,leaves:4)
B(-3,2,1,LOG:13)
B(-3,1,1,LOG:13)
B(-2,7,5,leaves:4)
B(-5,1,0,leaves:4)
B(-5,2,0,leaves:4)
B(0,3,-1,LOG:13)
B(1,4,-6,leaves:4)
B(1,6,-5,leaves:4)
B(0,5,-1,leaves:4)
B(0,4,-1,leaves:4)
B(-5,3,-1,leaves:4)
B(-2,4,-5,leaves:4)
B(0,5,4,leaves:4)
B(-6,4,0,leaves:4)
B(-6,3,0,leaves:4)
B(0,4,5,leaves:4)
B(-5,4,2,leaves:4)
B(2,3,4,leaves:4)
B(-1,7,5,leaves:4)
B(-1,5,6,leaves:4)
B(-5,4,4,leaves:4)
B(-2,4,-2,leaves:4)
B(-1,4,5,leaves:4)
B(3,4,-1,leaves:4)
B(-1,6,5,leaves:4)
B(2,4,0,leaves:4)
B(4,4,-4,leaves:4)
B(-5,6,-1,leaves:4)
B(-5,7,2,leaves:4)
B(-1,2,5,leaves:4)
B(-5,5,-1,leaves:4)
B(3,2,-2,leaves:4)
B(-3,4,-4,leaves:4)
B(-2,5,2,leaves:4)
B(4,2,-3,leaves:4)
B(1,6,-2,leaves:4)
B(-2,4,2,leaves:4)
B(-5,3,-2,leaves:4)
B(-2,3,2,LOG:13)
B(-5,4,-2,leaves:4)
B(-2,2,2,leaves:4)
B(1,4,-2,LOG:13)
B(1,2,-2,leaves:4)
B(-2,4,1,leaves:4)
B(-5,6,-3,leaves:4)
B(-5,4,-4,leaves:4)
B(-1,4,7,leaves:4)
B(4,4,-2,leaves:4)
B(-4,5,5,leaves:4)
B(-2,0,0,LOG:13)
B(-1,4,-2,leaves:4)
B(1,5,0,leaves:4)
B(1,4,0,leaves:4)
B(3,2,-4,leaves:4)
B(-5,2,-2,leaves:4)
B(-1,5,-3,leaves:4)
B(-3,4,-2,LOG:13)
B(-3,7,-2,leaves:4)
B(-2,2,3,leaves:4)
B(-3,2,0,leaves:4)
B(-3,5,0,leaves:4)
B(-3,4,0,leaves:4)
B(-3,6,0,leaves:4)
B(-2,4,3,LOG:13)
B(-2,5,4,leaves:4)
B(-3,5,3,leaves:4)
B(-2,4,4,leaves:4)
B(-2,3,4,leaves:4)
B(-2,1,4,leaves:4)
B(-3,2,3,leaves:4)
B(-5,7,1,leaves:4)
B(-4,3,-4,leaves:4)
B(-4,2,-4,leaves:4)
B(2,4,-5,leaves:4)
B(2,2,-5,leaves:4)
B(-5,4,1,LOG:13)
B(-5,6,1,leaves:4)
B(-5,5,1,leaves:4)
B(-7,4,1,leaves:4)
B(2,2,-4,leaves:4)
B(2,1,-4,leaves:4)
B(2,5,-3,leaves:4)
B(-7,2,1,leaves:4)
B(2,4,-3,LOG:13)
B(2,3,-3,leaves:4)
B(-2,2,6,leaves:4)
B(-7,6,1,leaves:4)
B(-4,1,-1,leaves:4)
B(-5,4,3,leaves:4)
B(5,3,-3,leaves:4)
B(-4,1,-2,leaves:4)
B(-4,1,1,leaves:4)
B(-5,5,3,leaves:4)
B(-4,3,1,LOG:13)
B(-4,4,1,leaves:4)
B(-2,4,-1,leaves:4)
B(-4,5,1,leaves:4)
B(-2,3,-1,LOG:13)
B(0,4,-2,leaves:4)
B(-4,7,1,leaves:4)
B(-4,5,-3,leaves:4)
B(-6,3,-2,leaves:4)
B(-1,3,-1,leaves:4)
B(-2,4,-3,leaves:4)
B(2,5,-2,leaves:4)
B(-2,5,-4,leaves:4)
B(-4,5,3,leaves:4)
B(2,7,-2,leaves:4)
B(-7,4,-1,leaves:4)
B(2,6,-1,leaves:4)
B(-4,6,-1,leaves:4)
B(-4,6,-2,leaves:4)
B(-6,4,-1,leaves:4)
B(-6,3,1,leaves:4)
B(-6,4,1,leaves:4)
B(-4,3,-1,leaves:4)
B(-6,5,1,leaves:4)
B(-4,4,-1,leaves:4)

#
# +-----------------------------------------------------------------+ #
# |                            BO3 checks                           | #
# +-----------------------------------------------------------------+ #
#

BlockCheck(0,-1,0,grass,dirt)

#
# +-----------------------------------------------------------------+ #
# |                             Branches                            | #
# +-----------------------------------------------------------------+ #
#

