
#
# +-----------------------------------------------------------------+ #
# |                            BO3 object                           | #
# +-----------------------------------------------------------------+ #
#

Author: NLBlackEagle

Description: No description given

Version: 3

SettingsMode: WriteDisable


#
# +-----------------------------------------------------------------+ #
# |                          Main settings                          | #
# +-----------------------------------------------------------------+ #
#

Tree: true

Frequency: 1

Rarity: 100.0

RotateRandomly: true

SpawnHeight: highestSolidBlock

SpawnHeightOffset: 0

SpawnHeightVariance: 0


# Height Limits for the BO3. #


MinHeight: 0

MaxHeight: 256


# Extrusion settings #


ExtrudeMode: None

ExtrudeThroughBlocks: air

MaxBranchDepth: 10

ExcludedBiomes: All


#
# +-----------------------------------------------------------------+ #
# |                      Source block settings                      | #
# +-----------------------------------------------------------------+ #
#

SourceBlocks: AIR,GRASS,DIRT,SAND

MaxPercentageOutsideSourceBlock: 0

OutsideSourceBlock: placeAnyway


#
# +-----------------------------------------------------------------+ #
# |                              Blocks                             | #
# +-----------------------------------------------------------------+ #
#

B(-8,9,-5,wool)
B(-8,9,-4,wool)
B(-8,10,-4,wool)
B(-8,11,-2,wool:14)
B(-8,13,-4,wool)
B(-7,6,-2,wool:6)
B(-7,6,-1,wool:14)
B(-7,7,-2,wool:6)
B(-7,8,-2,wool:14)
B(-7,9,-4,wool:6)
B(-7,9,-2,wool:6)
B(-7,9,0,wool:6)
B(-7,9,1,wool)
B(-7,10,-6,wool:6)
B(-7,10,-4,wool)
B(-7,10,-3,LOG:13)
B(-7,10,-2,wool:14)
B(-7,11,-5,wool)
B(-7,11,-4,wool)
B(-7,12,-3,wool:14)
B(-7,13,-4,wool)
B(-6,6,-8,wool)
B(-6,6,-7,wool)
B(-6,6,-6,wool)
B(-6,6,-2,wool)
B(-6,7,-8,wool:14)
B(-6,7,-3,LOG:13)
B(-6,7,-2,LOG:13)
B(-6,7,-1,wool:6)
B(-6,8,-8,wool:6)
B(-6,8,-6,wool:14)
B(-6,8,-4,wool)
B(-6,8,-3,wool:6)
B(-6,8,-2,LOG:13)
B(-6,8,-1,LOG:13)
B(-6,8,0,wool)
B(-6,8,1,wool:6)
B(-6,8,2,wool:14)
B(-6,9,-5,wool:6)
B(-6,9,-4,wool:14)
B(-6,9,-3,wool:6)
B(-6,9,-2,LOG:13)
B(-6,9,-1,wool:6)
B(-6,9,0,wool:14)
B(-6,9,4,wool:6)
B(-6,10,-6,wool:6)
B(-6,10,-4,LOG:13)
B(-6,10,-3,wool)
B(-6,10,-2,LOG:13)
B(-6,10,0,wool:14)
B(-6,10,1,wool)
B(-6,10,2,wool)
B(-6,10,4,wool)
B(-6,11,-4,wool:6)
B(-6,11,-2,wool)
B(-6,11,-1,wool:6)
B(-6,12,-4,wool)
B(-6,12,-3,wool:6)
B(-6,12,-1,wool:14)
B(-6,13,-4,wool:14)
B(-6,14,-3,wool:6)
B(-5,5,-9,LOG:13)
B(-5,6,-9,LOG:13)
B(-5,6,-8,LOG:13)
B(-5,6,-4,LOG:13)
B(-5,6,-3,LOG:13)
B(-5,6,-1,wool:6)
B(-5,7,-9,wool:14)
B(-5,7,-7,wool:14)
B(-5,7,-6,wool:14)
B(-5,7,-3,LOG:13)
B(-5,7,-2,wool:6)
B(-5,8,-4,wool)
B(-5,8,-3,wool:6)
B(-5,8,0,wool)
B(-5,8,1,wool:6)
B(-5,8,2,wool:14)
B(-5,8,4,wool)
B(-5,9,-8,wool)
B(-5,9,-7,wool:14)
B(-5,9,-6,wool:6)
B(-5,9,-5,wool:6)
B(-5,9,-4,wool:6)
B(-5,9,-3,wool:14)
B(-5,9,-2,wool)
B(-5,9,-1,wool:14)
B(-5,9,1,wool:6)
B(-5,9,3,wool)
B(-5,9,4,wool:14)
B(-5,9,5,wool:6)
B(-5,10,-8,wool)
B(-5,10,-6,wool:6)
B(-5,10,-5,wool:14)
B(-5,10,-3,wool:14)
B(-5,10,-1,wool)
B(-5,10,0,wool)
B(-5,10,1,wool)
B(-5,10,2,wool:6)
B(-5,10,3,wool)
B(-5,10,5,wool:14)
B(-5,10,6,wool:14)
B(-5,11,-6,wool)
B(-5,11,-5,wool)
B(-5,11,6,wool:6)
B(-5,12,-6,wool:6)
B(-5,12,-5,wool:6)
B(-5,12,-3,wool)
B(-5,12,-2,wool:6)
B(-5,12,0,wool:6)
B(-5,12,4,wool:14)
B(-5,13,-5,wool:14)
B(-5,13,-1,wool:14)
B(-4,5,-7,wool)
B(-4,6,-9,wool:6)
B(-4,6,-7,wool)
B(-4,6,-4,LOG:13)
B(-4,6,-3,LOG:13)
B(-4,6,1,wool:6)
B(-4,7,-8,LOG:13)
B(-4,7,-7,LOG:13)
B(-4,7,-6,wool:14)
B(-4,7,-5,wool:6)
B(-4,7,-1,wool:6)
B(-4,8,-9,wool)
B(-4,8,-8,wool:6)
B(-4,8,-2,wool:14)
B(-4,8,0,wool:14)
B(-4,8,2,wool:14)
B(-4,8,3,wool:6)
B(-4,8,4,wool)
B(-4,8,5,wool:14)
B(-4,9,-7,wool:14)
B(-4,9,-6,wool:6)
B(-4,9,-3,wool)
B(-4,9,-1,wool:14)
B(-4,9,1,wool:6)
B(-4,9,2,wool:14)
B(-4,9,3,wool:6)
B(-4,9,4,wool:14)
B(-4,9,5,wool)
B(-4,10,-7,wool)
B(-4,10,-6,wool)
B(-4,10,-5,wool:6)
B(-4,10,-4,wool:14)
B(-4,10,-3,wool:14)
B(-4,10,-2,wool:14)
B(-4,10,-1,wool:14)
B(-4,10,0,wool:14)
B(-4,10,1,wool:14)
B(-4,10,2,wool:14)
B(-4,10,3,wool)
B(-4,10,4,LOG:13)
B(-4,10,5,LOG:13)
B(-4,11,-7,wool:6)
B(-4,11,-5,wool:6)
B(-4,11,-2,wool:14)
B(-4,11,1,wool:6)
B(-4,11,3,wool:14)
B(-4,11,5,wool:6)
B(-4,12,-3,wool:14)
B(-4,12,0,wool:14)
B(-4,12,1,wool:6)
B(-4,13,-7,wool:6)
B(-3,5,-8,wool:6)
B(-3,5,-7,wool)
B(-3,5,-4,LOG:13)
B(-3,5,-3,LOG:13)
B(-3,6,-4,LOG:13)
B(-3,6,-3,LOG:13)
B(-3,7,-9,wool:14)
B(-3,7,-7,LOG:13)
B(-3,7,-6,LOG:13)
B(-3,7,0,wool:14)
B(-3,7,1,wool:6)
B(-3,7,2,wool:14)
B(-3,7,3,wool)
B(-3,8,-7,wool)
B(-3,8,0,wool:14)
B(-3,8,1,wool:14)
B(-3,8,2,LOG:13)
B(-3,9,-9,wool)
B(-3,9,-7,wool:6)
B(-3,9,-6,wool)
B(-3,9,-5,wool:14)
B(-3,9,0,wool)
B(-3,9,2,LOG:13)
B(-3,9,3,LOG:13)
B(-3,9,5,wool:14)
B(-3,10,-8,wool:6)
B(-3,10,-7,wool:14)
B(-3,10,-6,wool)
B(-3,10,-5,wool)
B(-3,10,-1,wool:6)
B(-3,10,0,wool:6)
B(-3,10,1,wool)
B(-3,10,2,wool)
B(-3,10,3,wool)
B(-3,10,5,wool:6)
B(-3,11,-7,wool)
B(-3,11,-6,wool:14)
B(-3,11,0,wool)
B(-3,11,2,wool)
B(-3,11,3,wool:14)
B(-3,11,4,wool:14)
B(-3,12,-8,wool:14)
B(-3,12,-6,wool:6)
B(-3,12,1,wool:14)
B(-3,13,-8,wool:14)
B(-3,13,-7,wool:14)
B(-3,13,-6,wool:14)
B(-2,4,-3,LOG:13)
B(-2,5,-5,LOG:13)
B(-2,5,-4,LOG:13)
B(-2,5,-3,LOG:13)
B(-2,6,-6,LOG:13)
B(-2,6,-5,LOG:13)
B(-2,6,-4,LOG:13)
B(-2,7,-9,wool:14)
B(-2,7,-7,wool:14)
B(-2,7,-6,LOG:13)
B(-2,7,-5,LOG:13)
B(-2,7,-1,wool:6)
B(-2,7,0,wool)
B(-2,7,2,LOG:13)
B(-2,8,-8,wool:6)
B(-2,8,-6,LOG:13)
B(-2,8,0,wool:14)
B(-2,8,1,wool:6)
B(-2,8,2,LOG:13)
B(-2,9,-9,wool)
B(-2,9,-7,wool:14)
B(-2,9,0,wool:14)
B(-2,9,1,wool:14)
B(-2,9,2,wool)
B(-2,9,4,wool)
B(-2,9,6,wool:14)
B(-2,10,-6,wool)
B(-2,10,0,wool:6)
B(-2,10,1,wool)
B(-2,10,2,wool:14)
B(-2,10,4,wool)
B(-2,11,-11,wool:14)
B(-2,11,-10,wool:14)
B(-2,11,-9,wool:6)
B(-2,11,-7,wool:14)
B(-2,11,1,wool:6)
B(-2,11,2,wool:14)
B(-2,11,4,wool)
B(-2,12,-4,wool)
B(-2,12,1,wool:14)
B(-2,13,-6,wool:14)
B(-1,-3,1,LOG:1)
B(-1,0,-1,LOG:13)
B(-1,1,-1,LOG:13)
B(-1,2,-2,LOG:13)
B(-1,2,-1,LOG:13)
B(-1,3,-3,LOG:13)
B(-1,3,-2,LOG:13)
B(-1,4,-4,LOG:13)
B(-1,4,-3,LOG:13)
B(-1,4,-2,LOG:13)
B(-1,6,2,LOG:13)
B(-1,6,3,LOG:13)
B(-1,7,-8,wool)
B(-1,7,2,LOG:13)
B(-1,8,-7,LOG:13)
B(-1,8,1,wool)
B(-1,8,2,wool:6)
B(-1,8,5,wool)
B(-1,9,-9,wool)
B(-1,9,-8,LOG:13)
B(-1,9,-5,wool:6)
B(-1,9,-1,wool:14)
B(-1,9,0,wool:6)
B(-1,9,1,wool:14)
B(-1,9,2,wool:14)
B(-1,9,3,wool:14)
B(-1,10,-9,wool:14)
B(-1,10,-8,LOG:13)
B(-1,10,-6,wool:6)
B(-1,10,-4,wool:6)
B(-1,10,-1,wool:6)
B(-1,10,1,wool)
B(-1,10,2,wool:6)
B(-1,10,4,wool)
B(-1,11,-10,LOG:13)
B(-1,11,-9,LOG:13)
B(-1,11,-8,wool:6)
B(-1,11,-7,wool)
B(-1,11,-4,wool)
B(-1,11,1,wool:6)
B(-1,11,2,wool:14)
B(-1,12,-9,wool)
B(-1,12,-8,wool:14)
B(-1,12,-5,wool:14)
B(-1,12,-1,wool)
B(-1,12,2,wool)
B(-1,12,5,wool:6)
B(-1,13,-9,wool:14)
B(-1,13,-5,wool)
B(-1,13,-4,wool:6)
B(0,-4,1,LOG:1)
B(0,-4,3,LOG:1)
B(0,-3,0,LOG:1)
B(0,-3,1,LOG:13)
B(0,-3,2,LOG:13)
B(0,-3,3,LOG:13)
B(0,-2,0,LOG:13)
B(0,-2,1,LOG:13)
B(0,-1,-2,LOG:13)
B(0,-1,-1,LOG:13)
B(0,-1,0,LOG:13)
B(0,0,-2,LOG:13)
B(0,0,-1,LOG:13)
B(0,0,0,LOG:13)
B(0,1,-2,LOG:13)
B(0,1,-1,LOG:13)
B(0,2,-2,LOG:13)
B(0,2,-1,LOG:13)
B(0,3,-3,LOG:13)
B(0,3,-2,LOG:13)
B(0,3,-1,LOG:13)
B(0,4,-1,LOG:13)
B(0,5,1,LOG:13)
B(0,6,1,LOG:13)
B(0,6,2,LOG:13)
B(0,8,-8,wool:6)
B(0,8,-7,wool:14)
B(0,8,1,wool:14)
B(0,8,2,wool)
B(0,9,-9,LOG:13)
B(0,9,-8,LOG:13)
B(0,9,-7,wool:6)
B(0,9,-6,wool:14)
B(0,9,-4,wool:6)
B(0,9,0,LOG:13)
B(0,9,1,wool:14)
B(0,9,3,wool:6)
B(0,9,5,wool)
B(0,10,-11,wool)
B(0,10,-9,wool:14)
B(0,10,-5,wool:14)
B(0,10,-4,wool)
B(0,10,-3,wool)
B(0,10,-2,wool:14)
B(0,10,0,LOG:13)
B(0,10,1,LOG:13)
B(0,10,3,wool:6)
B(0,10,4,wool:14)
B(0,10,5,wool)
B(0,11,-7,wool:14)
B(0,11,-5,wool:6)
B(0,11,-4,LOG:13)
B(0,11,-2,wool:6)
B(0,11,1,wool:6)
B(0,11,2,wool:6)
B(0,11,3,wool:6)
B(0,12,-8,wool:14)
B(0,12,-7,wool)
B(0,12,-4,wool:6)
B(0,12,-3,wool:6)
B(0,12,-2,wool:14)
B(0,12,0,wool:6)
B(0,12,4,wool:6)
B(0,13,2,wool)
B(1,-5,3,LOG:1)
B(1,-4,-5,LOG:1)
B(1,-4,3,LOG:1)
B(1,-4,4,LOG:1)
B(1,-3,-5,LOG:1)
B(1,-3,-4,LOG:13)
B(1,-3,-3,LOG:13)
B(1,-3,1,LOG:1)
B(1,-3,3,LOG:13)
B(1,-3,4,LOG:13)
B(1,-2,-4,LOG:1)
B(1,-2,-3,LOG:13)
B(1,-2,-2,LOG:13)
B(1,-1,-2,LOG:13)
B(1,-1,-1,LOG:13)
B(1,-1,0,LOG:1)
B(1,0,-2,LOG:13)
B(1,0,-1,LOG:13)
B(1,0,0,LOG:13)
B(1,0,1,LOG:13)
B(1,1,-2,LOG:1)
B(1,1,-1,LOG:13)
B(1,2,-1,LOG:13)
B(1,3,-2,LOG:13)
B(1,3,-1,LOG:13)
B(1,3,0,LOG:13)
B(1,4,-2,LOG:13)
B(1,4,-1,LOG:13)
B(1,4,0,LOG:13)
B(1,4,1,LOG:13)
B(1,5,0,LOG:13)
B(1,5,1,LOG:13)
B(1,6,1,LOG:13)
B(1,7,5,wool:6)
B(1,8,1,wool:14)
B(1,8,5,wool:14)
B(1,9,-9,wool)
B(1,9,-8,wool:14)
B(1,9,-1,LOG:13)
B(1,9,0,LOG:13)
B(1,9,3,wool:6)
B(1,9,4,wool:14)
B(1,10,-8,wool:14)
B(1,10,-5,wool)
B(1,10,-4,wool:6)
B(1,10,-3,LOG:13)
B(1,10,-2,wool)
B(1,10,-1,wool:6)
B(1,10,2,wool:14)
B(1,10,3,wool:14)
B(1,10,4,wool:14)
B(1,10,5,wool:14)
B(1,10,6,wool:6)
B(1,11,-9,wool:6)
B(1,11,-8,wool:6)
B(1,11,-6,wool)
B(1,11,-4,LOG:13)
B(1,11,-3,wool:6)
B(1,11,-2,wool:6)
B(1,11,-1,wool)
B(1,11,0,wool)
B(1,11,1,wool:6)
B(1,11,2,LOG:13)
B(1,11,4,wool:6)
B(1,12,-9,wool:14)
B(1,12,-4,wool)
B(1,12,-3,wool)
B(1,12,-2,wool)
B(1,12,1,wool:6)
B(1,12,2,wool:6)
B(1,13,-5,wool:14)
B(1,13,-4,wool:14)
B(1,13,-3,wool:6)
B(1,13,-2,wool:14)
B(1,13,2,wool:14)
B(1,13,3,wool:6)
B(1,14,-4,wool:14)
B(2,-5,-5,LOG:1)
B(2,-4,-5,LOG:13)
B(2,-3,-4,LOG:13)
B(2,-3,3,LOG:1)
B(2,-2,-2,LOG:13)
B(2,-2,-1,LOG:13)
B(2,-1,-2,LOG:13)
B(2,-1,-1,LOG:13)
B(2,0,-2,LOG:1)
B(2,0,0,LOG:1)
B(2,4,-1,LOG:13)
B(2,5,-1,LOG:13)
B(2,6,-1,LOG:13)
B(2,6,5,wool:6)
B(2,7,-2,wool)
B(2,7,-1,LOG:13)
B(2,7,1,wool:14)
B(2,7,6,wool:14)
B(2,8,-4,wool:6)
B(2,8,-1,LOG:13)
B(2,8,4,wool:14)
B(2,8,5,wool)
B(2,9,-1,LOG:13)
B(2,9,2,wool:14)
B(2,9,3,wool)
B(2,9,4,wool:6)
B(2,10,-7,wool:14)
B(2,10,-3,LOG:13)
B(2,10,-2,LOG:13)
B(2,10,0,wool)
B(2,10,1,wool)
B(2,10,3,wool:6)
B(2,10,4,wool:6)
B(2,10,5,wool)
B(2,10,6,wool)
B(2,11,-4,wool)
B(2,11,-2,wool:14)
B(2,12,-5,wool)
B(2,12,-2,wool)
B(2,12,3,wool:14)
B(2,12,6,wool)
B(2,13,3,wool:6)
B(2,14,-4,wool:6)
B(3,-7,-3,LOG:1)
B(3,-6,-3,LOG:13)
B(3,-6,-2,LOG:1)
B(3,-5,-6,LOG:1)
B(3,-5,-2,LOG:13)
B(3,-4,-6,LOG:13)
B(3,-4,-2,LOG:13)
B(3,-3,-2,LOG:13)
B(3,-3,-1,LOG:1)
B(3,-2,-3,LOG:1)
B(3,-2,-2,LOG:13)
B(3,-2,-1,LOG:13)
B(3,-1,-2,LOG:13)
B(3,5,-1,LOG:13)
B(3,5,0,LOG:13)
B(3,6,-1,wool)
B(3,6,1,wool:14)
B(3,6,2,wool:6)
B(3,6,5,wool:6)
B(3,7,-1,LOG:13)
B(3,7,0,wool:14)
B(3,7,1,wool)
B(3,7,2,wool)
B(3,7,4,wool:14)
B(3,7,5,wool:14)
B(3,7,6,wool:6)
B(3,8,-3,wool)
B(3,8,-2,wool)
B(3,8,-1,wool:14)
B(3,8,0,wool:14)
B(3,8,1,wool)
B(3,8,3,wool)
B(3,8,4,LOG:13)
B(3,8,5,LOG:13)
B(3,9,3,wool)
B(3,9,4,wool:6)
B(3,9,5,wool:6)
B(3,10,-4,wool)
B(3,10,5,wool:6)
B(3,11,-4,wool:14)
B(3,11,7,wool:6)
B(3,12,-4,wool:14)
B(3,13,-3,wool:14)
B(4,-3,-2,LOG:13)
B(4,-2,-2,LOG:13)
B(4,-2,-1,LOG:1)
B(4,5,0,LOG:13)
B(4,5,1,LOG:13)
B(4,6,0,wool:14)
B(4,6,1,LOG:13)
B(4,6,2,LOG:13)
B(4,7,1,wool:6)
B(4,7,2,LOG:13)
B(4,7,3,LOG:13)
B(4,7,5,wool)
B(4,8,-1,LOG:13)
B(4,8,1,wool:6)
B(4,8,3,LOG:13)
B(4,8,5,wool:14)
B(4,8,7,wool:6)
B(4,9,-3,wool:6)
B(4,9,0,wool)
B(4,9,2,wool:6)
B(4,9,4,wool)
B(4,9,5,wool:6)
B(4,10,-2,wool:6)
B(4,10,-1,wool:14)
B(4,10,1,wool)
B(4,10,2,wool)
B(4,10,4,wool:14)
B(4,10,6,wool)
B(4,11,6,wool:6)
B(5,-6,-2,LOG:1)
B(5,-5,-2,LOG:1)
B(5,-5,-1,LOG:1)
B(5,-4,-2,LOG:13)
B(5,-3,-2,LOG:13)
B(5,6,-2,wool)
B(5,6,-1,wool:6)
B(5,7,1,wool:14)
B(5,7,3,wool)
B(5,7,5,wool)
B(5,8,-1,wool:14)
B(5,8,0,wool:14)
B(5,8,3,wool)
B(5,8,5,wool:6)
B(5,9,1,wool)
B(5,9,2,wool)
B(5,9,4,wool:6)
B(5,10,3,wool:6)
B(5,11,3,wool)
B(6,-6,-2,LOG:1)
B(6,-5,-2,LOG:13)
B(6,-3,-2,LOG:13)
B(6,-3,-1,LOG:13)
B(6,-3,0,LOG:1)
B(6,7,-2,wool:6)
B(6,7,3,wool:6)
B(6,8,-2,wool:6)
B(6,8,3,wool)
B(6,8,4,wool:6)
B(6,9,-2,wool:6)
B(6,9,0,wool)
B(6,9,3,wool)
B(6,10,3,wool)
B(7,-4,-1,LOG:13)
B(7,-3,-1,LOG:1)

#
# +-----------------------------------------------------------------+ #
# |                            BO3 checks                           | #
# +-----------------------------------------------------------------+ #
#

BlockCheck(0,-1,0,grass,dirt)

#
# +-----------------------------------------------------------------+ #
# |                             Branches                            | #
# +-----------------------------------------------------------------+ #
#

