
#
# +-----------------------------------------------------------------+ #
# |                            BO3 object                           | #
# +-----------------------------------------------------------------+ #
#

Author: NLBlackEagle

Description: No description given

Version: 3

SettingsMode: WriteDisable


#
# +-----------------------------------------------------------------+ #
# |                          Main settings                          | #
# +-----------------------------------------------------------------+ #
#

Tree: true

Frequency: 1

Rarity: 100.0

RotateRandomly: true

SpawnHeight: highestSolidBlock

SpawnHeightOffset: 0

SpawnHeightVariance: 0


# Height Limits for the BO3. #


MinHeight: 0

MaxHeight: 256


# Extrusion settings #


ExtrudeMode: None

ExtrudeThroughBlocks: air

MaxBranchDepth: 10

ExcludedBiomes: All


#
# +-----------------------------------------------------------------+ #
# |                      Source block settings                      | #
# +-----------------------------------------------------------------+ #
#

SourceBlocks: AIR,GRASS,DIRT,SAND

MaxPercentageOutsideSourceBlock: 0

OutsideSourceBlock: placeAnyway


#
# +-----------------------------------------------------------------+ #
# |                              Blocks                             | #
# +-----------------------------------------------------------------+ #
#

B(-13,8,0,wool:14)
B(-12,1,-1,wool:14)
B(-12,2,-2,wool:6)
B(-12,6,1,wool)
B(-12,8,1,wool)
B(-12,9,-4,wool:14)
B(-12,9,-3,wool)
B(-12,9,-2,wool:6)
B(-12,9,1,wool)
B(-12,10,-1,wool:14)
B(-12,10,0,wool:6)
B(-11,2,-1,wool)
B(-11,4,-1,wool:14)
B(-11,4,1,wool:14)
B(-11,5,0,wool:6)
B(-11,6,0,wool)
B(-11,7,-5,wool)
B(-11,7,1,wool:14)
B(-11,8,-4,wool:6)
B(-11,9,-6,wool)
B(-11,9,-3,wool)
B(-11,9,-2,wool:6)
B(-11,9,3,wool:6)
B(-11,10,-6,wool)
B(-11,10,-5,wool:6)
B(-11,10,-4,wool:14)
B(-11,10,-2,wool:14)
B(-10,-1,-1,wool:14)
B(-10,-1,0,wool)
B(-10,0,-3,wool)
B(-10,3,-4,wool)
B(-10,4,-1,wool)
B(-10,5,1,wool:6)
B(-10,6,-5,wool:14)
B(-10,6,-4,wool:6)
B(-10,6,2,wool:6)
B(-10,7,-5,wool:6)
B(-10,7,-4,wool)
B(-10,8,-7,wool:14)
B(-10,8,-6,wool)
B(-10,8,-4,wool:6)
B(-10,8,-2,LOG:13)
B(-10,8,-1,wool:6)
B(-10,8,0,LOG:13)
B(-10,9,-5,wool:6)
B(-10,9,-3,LOG:13)
B(-10,9,-1,wool:6)
B(-10,9,1,wool:6)
B(-10,10,-7,wool:6)
B(-10,10,-5,wool)
B(-10,10,-4,wool:6)
B(-10,10,1,wool:14)
B(-10,11,-4,wool)
B(-10,11,-3,wool)
B(-10,11,-1,wool)
B(-10,11,1,wool:14)
B(-10,12,-4,wool:6)
B(-9,0,0,wool)
B(-9,1,0,wool)
B(-9,2,-1,LOG:13)
B(-9,2,0,wool:6)
B(-9,2,1,wool:14)
B(-9,2,2,wool:6)
B(-9,3,-1,wool:6)
B(-9,3,0,wool)
B(-9,3,1,wool:14)
B(-9,5,-7,wool:6)
B(-9,5,-5,wool:6)
B(-9,5,-2,wool)
B(-9,5,0,wool)
B(-9,6,-6,wool:14)
B(-9,6,-5,wool:14)
B(-9,6,-3,LOG:13)
B(-9,6,-2,LOG:13)
B(-9,6,-1,wool:6)
B(-9,6,1,wool:6)
B(-9,7,-9,wool)
B(-9,7,-8,wool)
B(-9,7,-6,wool)
B(-9,7,-5,wool:6)
B(-9,7,-4,wool)
B(-9,7,-3,wool:6)
B(-9,7,-2,LOG:13)
B(-9,7,-1,LOG:13)
B(-9,7,2,wool:14)
B(-9,8,-7,wool)
B(-9,8,-3,wool)
B(-9,8,-2,wool)
B(-9,8,2,wool)
B(-9,9,-7,wool:6)
B(-9,9,-5,LOG:13)
B(-9,9,-4,LOG:13)
B(-9,9,-3,wool)
B(-9,9,-2,wool:6)
B(-9,9,2,wool:6)
B(-9,9,3,wool)
B(-9,10,-3,wool)
B(-9,10,-2,wool)
B(-9,10,0,wool)
B(-9,10,2,wool)
B(-9,11,-3,wool:6)
B(-9,12,-6,wool:14)
B(-9,12,-5,wool:6)
B(-9,12,-4,wool:14)
B(-9,13,-5,wool)
B(-8,-1,0,wool)
B(-8,1,2,wool:6)
B(-8,2,-1,wool:14)
B(-8,2,1,wool:14)
B(-8,3,-2,LOG:13)
B(-8,3,-1,wool:14)
B(-8,4,-3,LOG:13)
B(-8,5,-4,LOG:13)
B(-8,5,-3,LOG:13)
B(-8,6,-5,wool:14)
B(-8,6,-3,LOG:13)
B(-8,7,-10,wool:14)
B(-8,7,-8,wool)
B(-8,7,-4,wool:6)
B(-8,8,-7,wool)
B(-8,8,-4,wool)
B(-8,8,-2,wool:6)
B(-8,8,-1,wool)
B(-8,8,2,wool:6)
B(-8,9,-6,wool:14)
B(-8,9,-5,wool)
B(-8,9,-4,wool)
B(-8,9,-2,wool:6)
B(-8,9,1,wool:6)
B(-8,9,5,wool:6)
B(-8,10,-7,wool)
B(-8,10,0,wool:14)
B(-8,11,-7,wool:14)
B(-8,11,-6,wool)
B(-8,11,-3,wool:14)
B(-8,11,2,wool)
B(-8,12,-9,wool)
B(-8,12,-5,wool:6)
B(-8,12,-3,wool:6)
B(-8,14,-2,wool:14)
B(-7,0,1,wool:6)
B(-7,2,1,wool:14)
B(-7,4,-1,wool:14)
B(-7,5,-5,LOG:13)
B(-7,5,-4,LOG:13)
B(-7,6,-9,wool)
B(-7,6,-6,wool)
B(-7,6,3,wool:6)
B(-7,7,-7,wool)
B(-7,7,-6,wool)
B(-7,7,-5,wool)
B(-7,7,-4,wool)
B(-7,7,8,wool:14)
B(-7,8,-5,wool:6)
B(-7,8,3,wool)
B(-7,8,6,wool)
B(-7,8,8,wool:6)
B(-7,8,9,wool:6)
B(-7,8,10,wool:6)
B(-7,9,-6,wool:14)
B(-7,9,-5,wool:14)
B(-7,9,-4,wool:14)
B(-7,9,4,wool:6)
B(-7,10,-7,wool:14)
B(-7,10,-6,wool)
B(-7,10,-3,wool)
B(-7,10,-1,wool:6)
B(-7,10,7,wool)
B(-7,11,-10,wool:6)
B(-7,11,-8,wool)
B(-7,11,-6,wool:6)
B(-7,11,-5,wool:6)
B(-7,11,-4,wool)
B(-7,11,-3,wool)
B(-7,11,-1,wool:6)
B(-7,11,3,wool:14)
B(-7,11,8,wool)
B(-7,12,-6,wool:14)
B(-7,12,-2,wool:6)
B(-7,12,3,wool:14)
B(-7,13,-9,wool:14)
B(-7,13,-8,wool:14)
B(-7,13,-5,wool:6)
B(-7,13,-3,wool:14)
B(-6,1,-2,wool)
B(-6,1,-1,wool)
B(-6,2,-2,wool)
B(-6,5,-5,LOG:13)
B(-6,6,-6,wool:14)
B(-6,6,2,wool:14)
B(-6,6,7,wool:6)
B(-6,6,9,wool:14)
B(-6,7,-4,wool)
B(-6,7,1,wool)
B(-6,7,8,wool:6)
B(-6,7,11,wool)
B(-6,8,-10,wool)
B(-6,8,-3,wool:6)
B(-6,8,2,wool:6)
B(-6,8,3,wool)
B(-6,8,4,wool)
B(-6,8,7,wool:6)
B(-6,8,10,wool:6)
B(-6,9,-8,wool:14)
B(-6,9,-7,wool:14)
B(-6,9,-3,wool)
B(-6,9,2,wool:14)
B(-6,9,3,LOG:13)
B(-6,9,4,wool)
B(-6,9,5,wool:14)
B(-6,9,6,wool)
B(-6,9,9,wool:14)
B(-6,10,-10,wool:6)
B(-6,10,-5,wool)
B(-6,10,-3,wool)
B(-6,10,-2,wool:14)
B(-6,10,1,wool)
B(-6,10,3,wool:14)
B(-6,10,5,wool:6)
B(-6,10,6,wool)
B(-6,11,-7,wool)
B(-6,11,-6,wool:6)
B(-6,11,-2,wool:6)
B(-6,11,2,wool:6)
B(-6,12,-8,wool:6)
B(-6,13,-8,wool)
B(-6,13,-4,wool:6)
B(-6,13,0,wool)
B(-6,13,1,wool)
B(-5,-6,-1,LOG:13)
B(-5,5,-5,LOG:13)
B(-5,5,-4,LOG:13)
B(-5,6,-6,wool:14)
B(-5,6,-5,LOG:13)
B(-5,6,-4,LOG:13)
B(-5,6,3,wool:6)
B(-5,6,6,wool)
B(-5,6,10,wool:6)
B(-5,6,11,wool:6)
B(-5,7,-11,wool)
B(-5,7,-8,wool)
B(-5,7,-7,wool)
B(-5,7,11,wool)
B(-5,8,-8,wool:14)
B(-5,8,1,wool)
B(-5,8,9,wool:14)
B(-5,8,11,wool:6)
B(-5,8,12,wool)
B(-5,9,-11,wool)
B(-5,9,-10,wool)
B(-5,9,-9,wool)
B(-5,9,-8,wool:14)
B(-5,9,-7,wool:6)
B(-5,9,-3,wool:14)
B(-5,9,3,LOG:13)
B(-5,9,5,wool)
B(-5,9,7,wool:6)
B(-5,9,10,wool:6)
B(-5,10,-9,wool:6)
B(-5,10,-4,wool)
B(-5,10,7,wool:6)
B(-5,11,-11,wool:6)
B(-5,11,-10,wool)
B(-5,11,-8,wool)
B(-5,11,-5,wool)
B(-5,11,-3,wool)
B(-5,11,5,wool)
B(-5,12,-6,wool)
B(-5,12,-1,wool:6)
B(-5,12,2,wool)
B(-5,12,7,wool:6)
B(-5,12,8,wool:6)
B(-5,13,-4,wool)
B(-5,13,-2,wool:6)
B(-5,13,-1,wool)
B(-4,-5,0,LOG:13)
B(-4,5,-4,LOG:13)
B(-4,5,9,wool)
B(-4,6,10,wool:6)
B(-4,6,11,wool:14)
B(-4,7,-10,wool)
B(-4,7,-8,wool)
B(-4,7,3,wool)
B(-4,7,5,wool:6)
B(-4,7,10,wool)
B(-4,8,-12,wool:14)
B(-4,8,-10,wool:6)
B(-4,8,-9,wool)
B(-4,8,5,LOG:13)
B(-4,8,7,wool:6)
B(-4,8,9,wool:6)
B(-4,8,10,wool)
B(-4,8,11,wool:14)
B(-4,8,12,wool)
B(-4,9,-12,wool:6)
B(-4,9,-11,wool:14)
B(-4,9,-10,wool)
B(-4,9,-9,wool)
B(-4,9,-8,wool:14)
B(-4,9,-7,wool:6)
B(-4,9,3,wool:6)
B(-4,9,4,LOG:13)
B(-4,9,7,wool)
B(-4,9,9,wool:14)
B(-4,9,12,wool:6)
B(-4,10,-8,wool:6)
B(-4,10,-3,wool)
B(-4,10,-1,wool:6)
B(-4,10,0,wool)
B(-4,10,4,wool:14)
B(-4,10,6,wool:14)
B(-4,10,7,wool:14)
B(-4,11,-10,wool)
B(-4,11,-9,wool:14)
B(-4,11,-2,wool:14)
B(-4,11,1,wool:14)
B(-4,11,5,wool:6)
B(-4,11,8,wool:14)
B(-4,12,-10,wool)
B(-4,12,-6,wool:14)
B(-4,12,-5,wool:6)
B(-4,12,-4,wool)
B(-4,12,-3,wool)
B(-4,12,-2,wool)
B(-4,12,-1,wool)
B(-4,12,7,wool:14)
B(-4,13,-4,wool:6)
B(-4,13,-3,wool:14)
B(-4,13,-2,wool:14)
B(-4,13,2,wool:14)
B(-4,14,-2,wool:14)
B(-4,14,-1,wool)
B(-4,14,4,wool:6)
B(-3,-5,0,LOG:13)
B(-3,3,-2,LOG:13)
B(-3,3,-1,LOG:13)
B(-3,4,-3,LOG:13)
B(-3,4,-2,LOG:13)
B(-3,4,-1,LOG:13)
B(-3,5,-4,LOG:13)
B(-3,5,-3,LOG:13)
B(-3,5,8,wool:6)
B(-3,5,9,wool)
B(-3,6,-10,wool:6)
B(-3,6,-9,wool:14)
B(-3,6,-8,wool:14)
B(-3,6,13,wool:6)
B(-3,7,-12,wool:14)
B(-3,7,7,wool:14)
B(-3,7,12,wool:6)
B(-3,8,-11,wool:6)
B(-3,8,-10,wool:6)
B(-3,8,-9,wool)
B(-3,8,-8,wool:6)
B(-3,8,-7,wool:6)
B(-3,8,-1,wool)
B(-3,8,5,LOG:13)
B(-3,8,7,wool:6)
B(-3,8,9,wool:14)
B(-3,8,12,wool:14)
B(-3,9,-13,wool:6)
B(-3,9,-12,wool:14)
B(-3,9,-11,wool)
B(-3,9,-10,LOG:13)
B(-3,9,-9,LOG:13)
B(-3,9,-8,wool:14)
B(-3,9,-7,wool:6)
B(-3,9,2,wool:6)
B(-3,9,4,wool:6)
B(-3,9,6,wool:6)
B(-3,9,8,wool:6)
B(-3,10,-13,wool:6)
B(-3,10,-10,wool:14)
B(-3,10,-6,wool)
B(-3,10,6,wool:14)
B(-3,10,8,wool)
B(-3,10,9,wool:14)
B(-3,11,-10,wool:14)
B(-3,11,-9,wool:6)
B(-3,11,-8,wool:6)
B(-3,11,-7,wool:6)
B(-3,11,-6,wool:14)
B(-3,11,-3,wool:6)
B(-3,11,-2,wool:6)
B(-3,11,-1,wool)
B(-3,11,0,wool:6)
B(-3,11,1,wool:14)
B(-3,11,9,wool:14)
B(-3,12,-10,wool)
B(-3,12,0,wool)
B(-3,13,-9,wool:6)
B(-3,13,1,wool:14)
B(-3,13,2,wool:6)
B(-3,14,-1,wool)
B(-3,14,0,wool)
B(-3,14,1,wool:6)
B(-3,15,1,wool:14)
B(-3,15,2,wool)
B(-2,-5,0,LOG:13)
B(-2,-4,0,LOG:13)
B(-2,0,0,LOG:13)
B(-2,1,0,LOG:13)
B(-2,2,-1,LOG:13)
B(-2,2,0,LOG:13)
B(-2,2,1,LOG:13)
B(-2,3,-2,LOG:13)
B(-2,3,-1,LOG:13)
B(-2,3,0,LOG:13)
B(-2,4,-3,LOG:13)
B(-2,4,-2,LOG:13)
B(-2,5,-4,LOG:13)
B(-2,5,-3,LOG:13)
B(-2,5,10,wool:14)
B(-2,5,11,LOG:13)
B(-2,6,-9,wool:6)
B(-2,6,-8,wool)
B(-2,6,-4,LOG:13)
B(-2,6,10,wool)
B(-2,6,11,LOG:13)
B(-2,7,5,LOG:13)
B(-2,7,8,wool:14)
B(-2,7,9,wool:6)
B(-2,7,14,wool:6)
B(-2,8,-12,wool:6)
B(-2,8,-3,wool)
B(-2,8,5,LOG:13)
B(-2,8,7,wool)
B(-2,8,8,wool:14)
B(-2,8,9,wool:14)
B(-2,8,10,wool:6)
B(-2,9,-10,wool:6)
B(-2,9,-9,LOG:13)
B(-2,9,-8,LOG:13)
B(-2,9,7,wool:14)
B(-2,9,10,wool)
B(-2,9,11,wool)
B(-2,10,-10,wool:6)
B(-2,10,-9,wool:6)
B(-2,10,-8,wool)
B(-2,10,-7,wool:14)
B(-2,10,-3,wool)
B(-2,10,-2,wool:14)
B(-2,10,-1,LOG:13)
B(-2,10,2,wool)
B(-2,10,7,wool:14)
B(-2,10,11,wool)
B(-2,11,-12,wool:6)
B(-2,11,-9,wool:6)
B(-2,11,-7,wool:6)
B(-2,11,-3,wool:14)
B(-2,11,-2,wool:14)
B(-2,11,-1,LOG:13)
B(-2,11,0,LOG:13)
B(-2,12,-9,wool)
B(-2,12,-2,LOG:13)
B(-2,13,-6,wool)
B(-2,13,-5,wool:6)
B(-2,13,-2,wool:6)
B(-2,13,3,wool)
B(-2,13,4,wool:6)
B(-2,14,-2,wool:14)
B(-2,14,1,wool:6)
B(-2,15,-4,wool:6)
B(-2,15,-3,wool)
B(-2,15,-2,wool:14)
B(-2,15,1,wool:14)
B(-2,15,3,wool)
B(-1,-4,-5,LOG:13)
B(-1,-4,-1,LOG:13)
B(-1,-4,0,LOG:13)
B(-1,-3,-4,LOG:13)
B(-1,-3,-3,LOG:13)
B(-1,-3,-2,LOG:13)
B(-1,-3,-1,LOG:13)
B(-1,-3,0,LOG:13)
B(-1,-2,-3,LOG:13)
B(-1,-2,-2,LOG:13)
B(-1,-1,0,LOG:13)
B(-1,0,-1,LOG:13)
B(-1,0,0,LOG:13)
B(-1,1,-1,LOG:13)
B(-1,1,0,LOG:13)
B(-1,1,1,LOG:13)
B(-1,2,0,LOG:13)
B(-1,2,1,LOG:13)
B(-1,3,0,LOG:13)
B(-1,3,1,LOG:13)
B(-1,3,2,LOG:13)
B(-1,3,10,wool)
B(-1,4,1,LOG:13)
B(-1,4,2,LOG:13)
B(-1,4,9,LOG:13)
B(-1,4,10,LOG:13)
B(-1,4,11,LOG:13)
B(-1,5,-5,LOG:13)
B(-1,5,-4,LOG:13)
B(-1,5,4,LOG:13)
B(-1,5,13,wool)
B(-1,6,-5,LOG:13)
B(-1,6,4,LOG:13)
B(-1,6,5,LOG:13)
B(-1,6,9,wool:6)
B(-1,6,10,wool:6)
B(-1,6,11,wool:6)
B(-1,6,14,wool:6)
B(-1,7,-10,wool:6)
B(-1,7,-9,wool:6)
B(-1,7,5,LOG:13)
B(-1,7,9,wool)
B(-1,7,10,wool:6)
B(-1,8,-10,wool)
B(-1,8,-9,wool:14)
B(-1,8,-8,LOG:13)
B(-1,8,8,wool)
B(-1,8,9,wool:6)
B(-1,8,10,wool:14)
B(-1,9,-12,wool)
B(-1,9,-11,wool)
B(-1,9,-8,LOG:13)
B(-1,9,-2,wool)
B(-1,9,10,wool:6)
B(-1,9,11,wool:6)
B(-1,10,-11,wool:14)
B(-1,10,-9,wool)
B(-1,10,-8,wool:14)
B(-1,10,-5,wool:6)
B(-1,10,-4,wool:14)
B(-1,10,-2,wool)
B(-1,10,-1,LOG:13)
B(-1,11,-12,wool)
B(-1,11,-9,wool)
B(-1,11,2,wool:6)
B(-1,11,11,wool:14)
B(-1,11,13,wool)
B(-1,12,-5,wool:14)
B(-1,12,-4,wool:14)
B(-1,12,-3,LOG:13)
B(-1,12,-2,wool)
B(-1,12,0,wool)
B(-1,12,1,wool:6)
B(-1,12,3,wool)
B(-1,13,-7,wool:6)
B(-1,13,-6,wool:14)
B(-1,13,-4,LOG:13)
B(-1,13,-2,wool:14)
B(-1,13,-1,wool:6)
B(-1,14,2,wool:14)
B(-1,15,-2,wool)
B(-1,15,1,wool:6)
B(-1,16,-3,wool:14)
B(0,-4,-5,LOG:13)
B(0,-3,-2,LOG:13)
B(0,-3,-1,LOG:13)
B(0,-2,-3,LOG:13)
B(0,-2,-2,LOG:13)
B(0,-2,-1,LOG:13)
B(0,-1,-2,LOG:13)
B(0,-1,-1,LOG:13)
B(0,-1,0,LOG:13)
B(0,0,-1,LOG:13)
B(0,0,0,LOG:13)
B(0,1,0,LOG:13)
B(0,3,1,LOG:13)
B(0,3,2,LOG:13)
B(0,4,1,LOG:13)
B(0,4,2,LOG:13)
B(0,4,3,LOG:13)
B(0,4,8,LOG:13)
B(0,4,9,LOG:13)
B(0,4,10,wool:14)
B(0,4,12,wool:14)
B(0,5,-5,LOG:13)
B(0,5,3,LOG:13)
B(0,5,4,LOG:13)
B(0,5,8,LOG:13)
B(0,6,-6,LOG:13)
B(0,6,-5,LOG:13)
B(0,6,4,LOG:13)
B(0,6,5,LOG:13)
B(0,6,6,LOG:13)
B(0,6,9,wool)
B(0,6,10,wool:6)
B(0,6,11,wool)
B(0,7,-10,wool:6)
B(0,7,-9,wool:14)
B(0,7,-7,LOG:13)
B(0,7,-6,LOG:13)
B(0,7,-1,wool)
B(0,8,-9,wool)
B(0,8,-8,LOG:13)
B(0,8,-7,LOG:13)
B(0,8,13,wool:14)
B(0,9,-10,wool:14)
B(0,9,-9,wool:14)
B(0,9,-1,wool)
B(0,9,9,wool)
B(0,9,10,wool:6)
B(0,9,14,wool:14)
B(0,10,-11,wool:6)
B(0,10,-10,wool)
B(0,10,-7,wool:14)
B(0,10,-3,wool)
B(0,10,-1,LOG:13)
B(0,10,11,wool)
B(0,11,0,wool:14)
B(0,11,2,wool)
B(0,11,12,wool:6)
B(0,12,-11,wool:14)
B(0,12,-7,wool:6)
B(0,12,-2,wool:14)
B(0,12,-1,wool:14)
B(0,12,2,wool)
B(0,13,-7,wool:6)
B(0,13,-4,wool:6)
B(0,13,-2,wool:6)
B(0,13,0,wool)
B(0,14,0,wool:6)
B(1,-5,-6,LOG:13)
B(1,-3,-2,LOG:13)
B(1,-2,-2,LOG:13)
B(1,-2,-1,LOG:13)
B(1,-1,-2,LOG:13)
B(1,-1,-1,LOG:13)
B(1,4,2,LOG:13)
B(1,4,3,LOG:13)
B(1,5,2,LOG:13)
B(1,5,3,LOG:13)
B(1,5,4,LOG:13)
B(1,5,7,LOG:13)
B(1,5,8,LOG:13)
B(1,5,10,wool:14)
B(1,5,11,wool)
B(1,5,12,wool:14)
B(1,6,-6,LOG:13)
B(1,6,4,LOG:13)
B(1,6,6,LOG:13)
B(1,6,7,LOG:13)
B(1,6,11,wool:14)
B(1,7,-10,wool:14)
B(1,7,-6,LOG:13)
B(1,7,7,LOG:13)
B(1,7,9,wool:6)
B(1,8,-9,wool:14)
B(1,8,-8,wool:14)
B(1,8,-7,LOG:13)
B(1,8,-1,wool)
B(1,8,1,wool:14)
B(1,8,2,wool:6)
B(1,8,4,wool)
B(1,8,7,LOG:13)
B(1,8,8,LOG:13)
B(1,8,9,wool)
B(1,8,10,wool)
B(1,9,-9,wool:6)
B(1,9,-2,wool:6)
B(1,9,-1,LOG:13)
B(1,9,0,LOG:13)
B(1,9,7,wool:14)
B(1,9,8,wool:14)
B(1,9,9,wool:6)
B(1,9,11,wool)
B(1,9,12,wool:6)
B(1,10,-11,wool:14)
B(1,10,-7,wool)
B(1,10,-2,wool)
B(1,10,-1,LOG:13)
B(1,10,7,wool:6)
B(1,10,10,wool:6)
B(1,10,14,wool:6)
B(1,11,-10,wool:6)
B(1,11,-3,wool:6)
B(1,11,-2,wool:14)
B(1,11,0,wool)
B(1,11,9,wool:6)
B(1,11,11,wool)
B(1,12,-5,wool:6)
B(1,12,-1,wool:14)
B(1,12,9,wool:6)
B(1,12,10,wool:14)
B(1,15,-3,wool)
B(2,-4,-2,LOG:13)
B(2,-4,-1,LOG:13)
B(2,-3,-2,LOG:13)
B(2,5,2,LOG:13)
B(2,5,3,LOG:13)
B(2,6,-7,LOG:13)
B(2,6,-6,LOG:13)
B(2,6,2,LOG:13)
B(2,6,3,LOG:13)
B(2,6,8,wool)
B(2,6,10,wool:14)
B(2,7,3,wool)
B(2,7,5,wool)
B(2,8,-10,wool:14)
B(2,8,1,LOG:13)
B(2,8,7,wool:6)
B(2,8,11,wool:6)
B(2,9,-12,wool)
B(2,9,0,LOG:13)
B(2,9,1,LOG:13)
B(2,9,9,LOG:13)
B(2,9,11,wool)
B(2,10,-12,wool)
B(2,10,-11,wool:6)
B(2,10,-10,wool:6)
B(2,10,-7,wool)
B(2,10,-3,wool:6)
B(2,10,-1,LOG:13)
B(2,10,8,wool)
B(2,11,-11,wool:6)
B(2,11,-5,wool:6)
B(2,11,-4,wool:14)
B(2,11,12,wool)
B(2,12,-4,wool:14)
B(2,14,-4,wool:6)
B(2,14,-3,wool:6)
B(3,-5,0,LOG:13)
B(3,-4,-3,LOG:13)
B(3,-4,-2,LOG:13)
B(3,-3,-2,LOG:13)
B(3,5,-7,LOG:13)
B(3,6,-8,wool:14)
B(3,6,-7,LOG:13)
B(3,6,2,LOG:13)
B(3,6,3,LOG:13)
B(3,7,-9,wool)
B(3,7,1,LOG:13)
B(3,7,2,LOG:13)
B(3,7,3,LOG:13)
B(3,7,5,wool:6)
B(3,8,1,LOG:13)
B(3,8,2,wool)
B(3,8,3,wool)
B(3,8,12,wool:6)
B(3,9,-11,wool)
B(3,9,-5,wool:6)
B(3,9,-4,wool:14)
B(3,9,-2,wool:14)
B(3,9,2,wool:14)
B(3,9,3,wool)
B(3,9,7,wool:14)
B(3,9,8,wool:14)
B(3,9,9,wool:6)
B(3,10,-10,wool:6)
B(3,10,-6,wool:6)
B(3,10,-3,wool)
B(3,10,4,wool:14)
B(3,10,5,wool)
B(3,10,9,wool:6)
B(3,11,-5,wool:6)
B(3,11,-4,wool:14)
B(3,11,-2,LOG:13)
B(3,11,-1,wool:6)
B(3,12,-8,wool:6)
B(3,12,-3,wool)
B(3,12,-2,wool:14)
B(3,12,1,wool)
B(3,12,9,wool:14)
B(3,13,0,wool:6)
B(3,14,-2,wool:14)
B(4,-5,1,LOG:13)
B(4,-4,-3,LOG:13)
B(4,5,-9,LOG:13)
B(4,5,-8,LOG:13)
B(4,5,-7,LOG:13)
B(4,6,-9,LOG:13)
B(4,6,1,wool:6)
B(4,7,-12,wool)
B(4,7,-9,wool:6)
B(4,7,-6,wool)
B(4,7,-1,wool:6)
B(4,7,3,LOG:13)
B(4,7,6,wool:6)
B(4,8,-12,wool:14)
B(4,8,-10,wool)
B(4,8,-9,wool)
B(4,8,-6,wool)
B(4,8,-1,wool:14)
B(4,8,1,wool:14)
B(4,8,3,LOG:13)
B(4,8,4,LOG:13)
B(4,8,5,LOG:13)
B(4,8,6,wool:14)
B(4,8,9,wool:14)
B(4,9,-5,wool:6)
B(4,9,0,wool:6)
B(4,9,1,wool)
B(4,9,7,wool:6)
B(4,9,9,wool)
B(4,9,11,wool)
B(4,10,-7,wool:14)
B(4,10,-5,wool)
B(4,10,-1,wool)
B(4,10,3,wool:14)
B(4,11,-8,wool:6)
B(4,11,-2,wool)
B(4,11,3,wool:14)
B(4,11,9,wool:14)
B(4,12,-5,wool)
B(4,12,-4,wool)
B(4,12,-3,wool:14)
B(4,12,-2,LOG:13)
B(4,12,0,wool)
B(4,12,1,wool:14)
B(4,13,-3,wool:6)
B(4,13,-1,wool)
B(4,14,-4,wool:6)
B(4,14,-1,wool)
B(4,15,-5,wool:14)
B(5,-5,-3,LOG:13)
B(5,4,-8,LOG:13)
B(5,4,4,wool:6)
B(5,5,2,wool)
B(5,5,3,wool:6)
B(5,6,-10,wool:14)
B(5,6,-9,LOG:13)
B(5,6,1,LOG:13)
B(5,6,2,LOG:13)
B(5,7,-12,wool)
B(5,7,-9,LOG:13)
B(5,7,-6,wool:6)
B(5,7,-1,wool:6)
B(5,7,3,LOG:13)
B(5,8,-11,wool)
B(5,8,-8,wool:14)
B(5,8,-6,wool:6)
B(5,8,-1,wool:6)
B(5,8,0,wool)
B(5,8,1,wool)
B(5,8,4,wool:14)
B(5,8,6,wool:14)
B(5,9,-10,wool:14)
B(5,9,-9,wool:6)
B(5,9,-7,wool:14)
B(5,9,-5,wool:14)
B(5,9,-4,wool:14)
B(5,9,-2,wool:14)
B(5,9,5,LOG:13)
B(5,10,-11,wool)
B(5,10,-6,wool)
B(5,10,-4,wool:14)
B(5,10,-3,wool:14)
B(5,10,-1,wool:6)
B(5,10,9,wool)
B(5,11,3,wool:6)
B(5,12,-8,wool:6)
B(5,12,-5,wool)
B(5,12,-4,wool:14)
B(5,12,-1,wool:6)
B(5,14,-5,wool:14)
B(5,15,-4,wool)
B(6,3,1,wool:6)
B(6,4,-7,LOG:13)
B(6,4,-6,LOG:13)
B(6,5,-9,wool)
B(6,5,-1,wool:6)
B(6,5,1,LOG:13)
B(6,5,4,wool)
B(6,5,5,wool)
B(6,6,-10,wool)
B(6,6,-9,wool:14)
B(6,6,1,LOG:13)
B(6,6,3,wool)
B(6,6,4,wool)
B(6,7,-12,wool:6)
B(6,7,-10,LOG:13)
B(6,7,-9,wool:6)
B(6,7,-6,wool)
B(6,7,0,LOG:13)
B(6,8,-9,wool:6)
B(6,8,-6,wool:6)
B(6,8,-2,wool)
B(6,8,-1,wool:6)
B(6,8,1,wool)
B(6,8,3,wool:14)
B(6,8,4,wool:14)
B(6,9,-11,wool:14)
B(6,9,-9,wool:14)
B(6,9,-7,wool)
B(6,9,-1,wool:6)
B(6,9,1,wool)
B(6,9,3,wool:14)
B(6,9,4,wool:6)
B(6,9,5,wool)
B(6,10,-10,wool:6)
B(6,10,-8,wool:6)
B(6,10,-3,wool:14)
B(6,10,-2,wool:6)
B(6,11,-1,wool:14)
B(6,12,-2,wool:6)
B(6,13,-7,wool:6)
B(6,13,-5,wool:6)
B(6,14,-4,wool:14)
B(6,14,-2,wool)
B(6,14,-1,wool:14)
B(7,2,4,wool:14)
B(7,3,6,wool:6)
B(7,4,1,LOG:13)
B(7,4,2,LOG:13)
B(7,5,-10,wool:14)
B(7,5,-8,wool:6)
B(7,5,0,wool:6)
B(7,5,2,wool:6)
B(7,5,3,wool)
B(7,6,-2,wool:6)
B(7,6,-1,wool)
B(7,6,1,wool:6)
B(7,7,-11,wool:14)
B(7,7,-10,wool)
B(7,7,-9,wool:6)
B(7,7,-3,wool:6)
B(7,7,-1,wool:14)
B(7,7,1,wool)
B(7,7,2,wool:14)
B(7,7,3,wool:14)
B(7,8,-10,wool:14)
B(7,8,-9,LOG:13)
B(7,8,-6,wool)
B(7,8,-4,wool:6)
B(7,8,-3,wool:6)
B(7,8,-2,wool:6)
B(7,8,-1,LOG:13)
B(7,8,0,wool:14)
B(7,8,2,wool)
B(7,9,-9,wool:14)
B(7,9,-8,wool)
B(7,9,-6,wool)
B(7,9,-4,wool:14)
B(7,9,-3,wool:14)
B(7,9,0,wool:14)
B(7,10,-8,wool)
B(7,11,-3,wool:14)
B(7,12,-6,wool:6)
B(7,12,-1,wool:6)
B(7,13,-5,wool:14)
B(8,1,2,wool)
B(8,1,3,wool:6)
B(8,3,1,wool)
B(8,4,1,wool:6)
B(8,4,2,wool:14)
B(8,4,3,LOG:13)
B(8,4,5,wool:14)
B(8,5,-1,wool:14)
B(8,5,1,wool)
B(8,5,2,wool:14)
B(8,5,4,wool:14)
B(8,6,-8,wool:6)
B(8,6,-5,wool)
B(8,6,-4,wool:6)
B(8,6,1,wool:6)
B(8,6,4,wool:14)
B(8,6,5,wool)
B(8,7,-11,wool:14)
B(8,7,-9,wool:14)
B(8,7,-7,wool:14)
B(8,7,-3,wool:14)
B(8,7,2,wool)
B(8,7,3,wool:6)
B(8,7,4,wool:6)
B(8,7,5,wool)
B(8,8,-7,wool:6)
B(8,8,-5,wool:14)
B(8,8,-3,wool)
B(8,8,-2,wool)
B(8,8,-1,wool)
B(8,8,1,wool:6)
B(8,8,3,wool:6)
B(8,9,-9,wool:14)
B(8,9,-8,wool:14)
B(8,9,-6,wool:6)
B(8,9,-5,wool)
B(8,9,-4,wool:6)
B(8,9,-3,wool:6)
B(8,9,2,wool:14)
B(8,10,-7,wool:6)
B(8,10,-1,wool:6)
B(8,11,-1,wool:14)
B(8,12,-7,wool:14)
B(8,12,-5,wool:6)
B(9,2,3,wool:14)
B(9,3,1,wool:6)
B(9,4,2,wool)
B(9,4,3,wool:14)
B(9,5,3,wool:6)
B(9,5,5,wool:6)
B(9,6,-11,wool:6)
B(9,6,-10,wool:14)
B(9,6,-6,wool:14)
B(9,7,-7,wool)
B(9,8,-7,wool)
B(9,8,-6,wool)
B(9,8,-5,wool:14)
B(9,8,1,wool:14)
B(9,9,-10,wool:6)
B(9,9,-7,wool)
B(9,9,-6,wool)
B(9,9,-3,wool:6)
B(9,9,-2,wool:14)
B(9,9,-1,wool)
B(9,9,1,wool:14)
B(9,10,-11,wool)
B(9,10,-9,wool:6)
B(9,10,-8,wool:14)
B(9,10,-7,wool)
B(9,10,-6,wool:6)
B(9,10,-5,wool:6)
B(9,10,3,wool:6)
B(9,11,-8,wool:6)
B(9,11,-7,wool)
B(9,12,-7,wool:14)
B(9,12,-6,wool)
B(10,2,3,wool:6)
B(10,4,1,wool)
B(10,4,5,wool)
B(10,7,-8,wool)
B(10,7,-7,wool)
B(10,7,-4,wool:6)
B(10,8,0,wool:14)
B(10,9,-9,wool)
B(10,9,-6,wool)
B(10,11,-5,wool)
B(11,7,3,wool:6)
B(11,8,-5,wool:14)
B(11,8,3,wool)
B(11,9,-8,wool)
B(11,9,-5,wool:6)
B(11,10,-9,wool:14)

#
# +-----------------------------------------------------------------+ #
# |                            BO3 checks                           | #
# +-----------------------------------------------------------------+ #
#

BlockCheck(0,-1,0,grass,dirt)

#
# +-----------------------------------------------------------------+ #
# |                             Branches                            | #
# +-----------------------------------------------------------------+ #
#

