
#
# +-----------------------------------------------------------------+ #
# |                            BO3 object                           | #
# +-----------------------------------------------------------------+ #
#

Author: NLBlackEagle

Description: No description given

Version: 3

SettingsMode: WriteDisable


#
# +-----------------------------------------------------------------+ #
# |                          Main settings                          | #
# +-----------------------------------------------------------------+ #
#

Tree: true

Frequency: 1

Rarity: 100.0

RotateRandomly: true

SpawnHeight: highestSolidBlock

SpawnHeightOffset: 0

SpawnHeightVariance: 0


# Height Limits for the BO3. #


MinHeight: 0

MaxHeight: 256


# Extrusion settings #


ExtrudeMode: None

ExtrudeThroughBlocks: air

MaxBranchDepth: 10

ExcludedBiomes: All


#
# +-----------------------------------------------------------------+ #
# |                      Source block settings                      | #
# +-----------------------------------------------------------------+ #
#

SourceBlocks: AIR,GRASS,DIRT,SAND

MaxPercentageOutsideSourceBlock: 0

OutsideSourceBlock: placeAnyway


#
# +-----------------------------------------------------------------+ #
# |                              Blocks                             | #
# +-----------------------------------------------------------------+ #
#

B(-14,4,-3,Leaves:4)
B(-14,6,0,Leaves:4)
B(-14,7,1,Leaves:4)
B(-14,9,0,Leaves:4)
B(-14,9,1,Leaves:4)
B(-14,12,8,Leaves:4)
B(-14,12,12,Leaves:4)
B(-14,13,4,Leaves:4)
B(-14,13,9,Leaves:4)
B(-14,13,12,Leaves:4)
B(-13,3,-3,Leaves:4)
B(-13,4,-3,Leaves:4)
B(-13,4,-1,Leaves:4)
B(-13,5,-5,Leaves:4)
B(-13,5,-3,Leaves:4)
B(-13,5,-2,Leaves:4)
B(-13,6,-3,Leaves:4)
B(-13,6,-2,Leaves:4)
B(-13,7,0,Leaves:4)
B(-13,8,-1,Leaves:4)
B(-13,8,0,Leaves:4)
B(-13,9,-4,Leaves:4)
B(-13,9,-2,Leaves:4)
B(-13,9,0,Leaves:4)
B(-13,9,2,Leaves:4)
B(-13,9,11,Leaves:4)
B(-13,10,-2,Leaves:4)
B(-13,10,3,Leaves:4)
B(-13,11,7,Leaves:4)
B(-13,11,11,Leaves:4)
B(-13,11,12,Leaves:4)
B(-13,12,-1,Leaves:4)
B(-13,12,11,Leaves:4)
B(-13,13,4,Leaves:4)
B(-13,14,9,Leaves:4)
B(-13,14,11,Leaves:4)
B(-13,15,11,Leaves:4)
B(-12,2,-4,Leaves:4)
B(-12,3,-4,Leaves:4)
B(-12,3,0,Leaves:4)
B(-12,4,-5,Leaves:4)
B(-12,7,-4,Leaves:4)
B(-12,7,-2,Leaves:4)
B(-12,7,3,Leaves:4)
B(-12,8,-6,Leaves:4)
B(-12,8,-5,Leaves:4)
B(-12,8,-3,Leaves:4)
B(-12,8,0,Leaves:4)
B(-12,9,-5,Leaves:4)
B(-12,9,0,Leaves:4)
B(-12,9,1,Leaves:4)
B(-12,9,2,Leaves:4)
B(-12,9,3,Leaves:4)
B(-12,9,11,Leaves:4)
B(-12,10,0,Leaves:4)
B(-12,10,2,Leaves:4)
B(-12,10,9,Leaves:4)
B(-12,10,12,Leaves:4)
B(-12,11,-8,Leaves:4)
B(-12,11,0,Leaves:4)
B(-12,12,-8,Leaves:4)
B(-12,12,1,Leaves:4)
B(-12,12,8,Leaves:4)
B(-12,12,10,LOG_2:13)
B(-12,12,12,Leaves:4)
B(-12,13,1,Leaves:4)
B(-12,13,4,Leaves:4)
B(-12,13,5,Leaves:4)
B(-12,14,3,Leaves:4)
B(-12,14,9,Leaves:4)
B(-12,14,10,Leaves:4)
B(-12,15,2,Leaves:4)
B(-12,15,10,Leaves:4)
B(-11,2,-4,Leaves:4)
B(-11,2,-3,Leaves:4)
B(-11,3,1,Leaves:4)
B(-11,4,-5,Leaves:4)
B(-11,4,-2,LOG_2:13)
B(-11,4,0,Leaves:4)
B(-11,4,2,Leaves:4)
B(-11,5,-6,Leaves:4)
B(-11,5,-3,LOG_2:13)
B(-11,5,-1,LOG_2:13)
B(-11,5,3,Leaves:4)
B(-11,5,7,Leaves:4)
B(-11,5,8,Leaves:4)
B(-11,6,-5,Leaves:4)
B(-11,6,-1,Leaves:4)
B(-11,6,0,Leaves:4)
B(-11,6,1,Leaves:4)
B(-11,6,9,Leaves:4)
B(-11,7,-1,Leaves:4)
B(-11,7,1,Leaves:4)
B(-11,7,10,Leaves:4)
B(-11,7,11,Leaves:4)
B(-11,8,2,Leaves:4)
B(-11,8,3,Leaves:4)
B(-11,9,0,Leaves:4)
B(-11,10,-3,Leaves:4)
B(-11,10,0,Leaves:4)
B(-11,10,1,Leaves:4)
B(-11,10,2,Leaves:4)
B(-11,10,4,Leaves:4)
B(-11,11,-9,Leaves:4)
B(-11,11,-8,Leaves:4)
B(-11,11,-7,Leaves:4)
B(-11,11,2,Leaves:4)
B(-11,11,3,Leaves:4)
B(-11,11,5,Leaves:4)
B(-11,11,9,LOG_2:13)
B(-11,11,11,Leaves:4)
B(-11,12,3,Leaves:4)
B(-11,12,7,Leaves:4)
B(-11,12,9,LOG_2:13)
B(-11,12,10,LOG_2:13)
B(-11,12,13,Leaves:4)
B(-11,13,1,Leaves:4)
B(-11,13,3,Leaves:4)
B(-11,13,6,Leaves:4)
B(-11,13,7,Leaves:4)
B(-11,13,10,Leaves:4)
B(-11,14,3,Leaves:4)
B(-11,14,4,Leaves:4)
B(-11,14,5,Leaves:4)
B(-11,14,6,Leaves:4)
B(-11,14,10,Leaves:4)
B(-11,14,11,Leaves:4)
B(-11,15,-10,Leaves:4)
B(-11,15,3,Leaves:4)
B(-10,2,-2,Leaves:4)
B(-10,3,0,Leaves:4)
B(-10,3,8,Leaves:4)
B(-10,4,0,Leaves:4)
B(-10,5,-3,Leaves:4)
B(-10,5,-1,LOG_2:13)
B(-10,5,0,LOG_2:13)
B(-10,5,8,Leaves:4)
B(-10,7,-6,Leaves:4)
B(-10,7,-3,Leaves:4)
B(-10,7,2,Leaves:4)
B(-10,7,10,Leaves:4)
B(-10,8,-5,Leaves:4)
B(-10,8,1,Leaves:4)
B(-10,8,2,Leaves:4)
B(-10,9,-6,Leaves:4)
B(-10,9,-5,LOG_2:13)
B(-10,9,2,Leaves:4)
B(-10,9,3,Leaves:4)
B(-10,9,12,Leaves:4)
B(-10,10,-7,Leaves:4)
B(-10,10,-1,Leaves:4)
B(-10,10,2,LOG_2:13)
B(-10,10,5,Leaves:4)
B(-10,10,6,LOG_2:13)
B(-10,10,7,LOG_2:13)
B(-10,10,8,LOG_2:13)
B(-10,11,-8,Leaves:4)
B(-10,11,-5,Leaves:4)
B(-10,11,3,Leaves:4)
B(-10,11,8,LOG_2:13)
B(-10,11,9,LOG_2:13)
B(-10,11,12,Leaves:4)
B(-10,12,-11,Leaves:4)
B(-10,12,-10,Leaves:4)
B(-10,12,-9,Leaves:4)
B(-10,12,-6,Leaves:4)
B(-10,12,4,Leaves:4)
B(-10,12,8,Leaves:4)
B(-10,13,-10,Leaves:4)
B(-10,13,-8,Leaves:4)
B(-10,13,-1,Leaves:4)
B(-10,13,3,Leaves:4)
B(-10,13,6,Leaves:4)
B(-10,13,10,Leaves:4)
B(-10,13,12,Leaves:4)
B(-10,14,-9,Leaves:4)
B(-10,14,-7,Leaves:4)
B(-10,15,-11,Leaves:4)
B(-10,15,-9,Leaves:4)
B(-10,15,1,Leaves:4)
B(-10,15,2,Leaves:4)
B(-10,15,3,Leaves:4)
B(-10,16,3,Leaves:4)
B(-10,16,5,Leaves:4)
B(-10,16,6,Leaves:4)
B(-10,17,4,Leaves:4)
B(-9,4,-2,Leaves:4)
B(-9,4,0,Leaves:4)
B(-9,4,1,Leaves:4)
B(-9,4,2,Leaves:4)
B(-9,4,6,Leaves:4)
B(-9,4,10,Leaves:4)
B(-9,5,-2,Leaves:4)
B(-9,5,0,LOG_2:13)
B(-9,5,5,Leaves:4)
B(-9,5,9,Leaves:4)
B(-9,5,10,Leaves:4)
B(-9,6,-4,Leaves:4)
B(-9,6,0,LOG_2:13)
B(-9,6,1,LOG_2:13)
B(-9,6,2,Leaves:4)
B(-9,6,10,Leaves:4)
B(-9,6,13,Leaves:4)
B(-9,7,-5,Leaves:4)
B(-9,7,-3,Leaves:4)
B(-9,7,-2,LOG_2:13)
B(-9,7,-1,LOG_2:13)
B(-9,7,0,LOG_2:13)
B(-9,7,7,Leaves:4)
B(-9,7,11,Leaves:4)
B(-9,7,12,Leaves:4)
B(-9,8,-8,Leaves:4)
B(-9,8,4,Leaves:4)
B(-9,8,11,Leaves:4)
B(-9,9,-10,Leaves:4)
B(-9,9,-9,Leaves:4)
B(-9,9,-8,Leaves:4)
B(-9,9,-6,Leaves:4)
B(-9,9,-5,LOG_2:13)
B(-9,9,-3,Leaves:4)
B(-9,9,5,LOG_2:13)
B(-9,9,6,LOG_2:13)
B(-9,9,11,Leaves:4)
B(-9,10,2,LOG_2:13)
B(-9,10,3,LOG_2:13)
B(-9,10,6,LOG_2:13)
B(-9,10,11,Leaves:4)
B(-9,11,-8,LOG_2:13)
B(-9,11,-6,Leaves:4)
B(-9,11,-5,Leaves:4)
B(-9,11,0,Leaves:4)
B(-9,11,8,Leaves:4)
B(-9,11,9,Leaves:4)
B(-9,11,10,Leaves:4)
B(-9,11,11,Leaves:4)
B(-9,12,-9,Leaves:4)
B(-9,12,2,Leaves:4)
B(-9,12,10,Leaves:4)
B(-9,12,12,Leaves:4)
B(-9,13,-7,Leaves:4)
B(-9,13,1,Leaves:4)
B(-9,13,2,Leaves:4)
B(-9,13,3,Leaves:4)
B(-9,13,5,Leaves:4)
B(-9,13,9,Leaves:4)
B(-9,14,-7,Leaves:4)
B(-9,14,1,Leaves:4)
B(-9,14,8,Leaves:4)
B(-9,14,10,Leaves:4)
B(-9,15,-10,Leaves:4)
B(-9,17,-9,Leaves:4)
B(-8,2,7,Leaves:4)
B(-8,2,8,Leaves:4)
B(-8,4,-4,Leaves:4)
B(-8,4,-3,Leaves:4)
B(-8,4,5,Leaves:4)
B(-8,5,-3,Leaves:4)
B(-8,5,8,LOG_2:13)
B(-8,5,9,Leaves:4)
B(-8,5,10,Leaves:4)
B(-8,6,-2,Leaves:4)
B(-8,6,1,LOG_2:13)
B(-8,6,2,LOG_2:13)
B(-8,6,8,Leaves:4)
B(-8,7,-5,Leaves:4)
B(-8,7,10,Leaves:4)
B(-8,7,11,Leaves:4)
B(-8,7,12,Leaves:4)
B(-8,8,-6,Leaves:4)
B(-8,8,-5,Leaves:4)
B(-8,8,-3,LOG_2:13)
B(-8,8,-2,LOG_2:13)
B(-8,8,2,Leaves:4)
B(-8,8,4,LOG_2:13)
B(-8,8,7,Leaves:4)
B(-8,8,11,Leaves:4)
B(-8,9,-9,Leaves:4)
B(-8,9,-6,Leaves:4)
B(-8,9,-5,LOG_2:13)
B(-8,9,-4,LOG_2:13)
B(-8,9,-3,LOG_2:13)
B(-8,9,3,LOG_2:13)
B(-8,9,4,LOG_2:13)
B(-8,9,5,LOG_2:13)
B(-8,9,8,Leaves:4)
B(-8,9,10,Leaves:4)
B(-8,10,-8,Leaves:4)
B(-8,10,-7,LOG_2:13)
B(-8,10,-6,LOG_2:13)
B(-8,10,0,Leaves:4)
B(-8,10,2,Leaves:4)
B(-8,10,3,LOG_2:13)
B(-8,10,4,Leaves:4)
B(-8,10,9,Leaves:4)
B(-8,10,11,Leaves:4)
B(-8,11,-10,Leaves:4)
B(-8,11,-5,Leaves:4)
B(-8,11,2,Leaves:4)
B(-8,11,7,Leaves:4)
B(-8,11,10,Leaves:4)
B(-8,12,-11,Leaves:4)
B(-8,12,-8,Leaves:4)
B(-8,12,5,Leaves:4)
B(-8,12,11,Leaves:4)
B(-8,12,12,Leaves:4)
B(-8,13,-12,Leaves:4)
B(-8,13,-6,Leaves:4)
B(-8,13,-3,Leaves:4)
B(-8,13,2,Leaves:4)
B(-8,13,3,Leaves:4)
B(-8,13,8,Leaves:4)
B(-8,13,10,Leaves:4)
B(-8,14,-9,Leaves:4)
B(-8,14,-7,Leaves:4)
B(-8,14,-6,Leaves:4)
B(-8,14,3,Leaves:4)
B(-8,14,6,Leaves:4)
B(-8,15,-13,Leaves:4)
B(-8,15,-9,Leaves:4)
B(-8,15,-8,Leaves:4)
B(-8,15,0,Leaves:4)
B(-8,15,2,Leaves:4)
B(-8,15,5,Leaves:4)
B(-8,16,-8,Leaves:4)
B(-8,16,5,Leaves:4)
B(-8,16,7,Leaves:4)
B(-8,16,8,Leaves:4)
B(-8,17,-12,Leaves:4)
B(-8,17,5,Leaves:4)
B(-8,18,-11,Leaves:4)
B(-8,18,5,Leaves:4)
B(-7,2,9,Leaves:4)
B(-7,5,5,Leaves:4)
B(-7,5,9,Leaves:4)
B(-7,6,2,LOG_2:13)
B(-7,6,3,LOG_2:13)
B(-7,6,6,LOG_2:13)
B(-7,6,7,LOG_2:13)
B(-7,6,9,Leaves:4)
B(-7,6,11,Leaves:4)
B(-7,7,3,LOG_2:13)
B(-7,8,4,LOG_2:13)
B(-7,8,5,LOG_2:13)
B(-7,8,10,Leaves:4)
B(-7,9,-5,Leaves:4)
B(-7,9,-4,Leaves:4)
B(-7,9,3,LOG_2:13)
B(-7,9,4,LOG_2:13)
B(-7,9,5,LOG_2:13)
B(-7,9,9,Leaves:4)
B(-7,9,11,Leaves:4)
B(-7,9,13,Leaves:4)
B(-7,10,-9,Leaves:4)
B(-7,10,0,Leaves:4)
B(-7,10,1,Leaves:4)
B(-7,10,3,LOG_2:13)
B(-7,10,8,Leaves:4)
B(-7,10,10,Leaves:4)
B(-7,10,11,Leaves:4)
B(-7,11,-8,Leaves:4)
B(-7,11,-7,Leaves:4)
B(-7,11,-6,Leaves:4)
B(-7,11,-1,Leaves:4)
B(-7,11,1,Leaves:4)
B(-7,11,3,Leaves:4)
B(-7,11,8,Leaves:4)
B(-7,11,9,Leaves:4)
B(-7,11,10,Leaves:4)
B(-7,11,11,Leaves:4)
B(-7,12,-10,Leaves:4)
B(-7,12,-8,Leaves:4)
B(-7,12,0,Leaves:4)
B(-7,12,3,Leaves:4)
B(-7,12,6,Leaves:4)
B(-7,12,10,Leaves:4)
B(-7,12,11,Leaves:4)
B(-7,12,12,Leaves:4)
B(-7,13,-11,Leaves:4)
B(-7,13,-10,Leaves:4)
B(-7,13,-9,Leaves:4)
B(-7,13,-3,Leaves:4)
B(-7,13,-2,Leaves:4)
B(-7,13,0,LOG_2:13)
B(-7,13,1,Leaves:4)
B(-7,13,3,Leaves:4)
B(-7,13,9,Leaves:4)
B(-7,13,10,Leaves:4)
B(-7,13,12,Leaves:4)
B(-7,14,-10,Leaves:4)
B(-7,14,-7,Leaves:4)
B(-7,14,0,Leaves:4)
B(-7,14,2,Leaves:4)
B(-7,14,8,Leaves:4)
B(-7,14,10,Leaves:4)
B(-7,15,-11,Leaves:4)
B(-7,15,-10,LOG_2:13)
B(-7,15,-9,Leaves:4)
B(-7,15,-8,Leaves:4)
B(-7,15,-6,Leaves:4)
B(-7,15,-2,Leaves:4)
B(-7,15,0,Leaves:4)
B(-7,15,2,Leaves:4)
B(-7,15,5,Leaves:4)
B(-7,15,6,Leaves:4)
B(-7,15,8,Leaves:4)
B(-7,16,-8,Leaves:4)
B(-7,16,0,Leaves:4)
B(-7,16,2,Leaves:4)
B(-7,17,-10,Leaves:4)
B(-7,17,-8,Leaves:4)
B(-7,17,0,Leaves:4)
B(-7,17,6,Leaves:4)
B(-7,17,7,Leaves:4)
B(-7,18,-11,Leaves:4)
B(-7,18,-9,Leaves:4)
B(-6,5,7,Leaves:4)
B(-6,5,8,Leaves:4)
B(-6,6,7,Leaves:4)
B(-6,6,8,Leaves:4)
B(-6,6,11,Leaves:4)
B(-6,7,3,LOG_2:13)
B(-6,7,4,LOG_2:13)
B(-6,7,5,LOG_2:13)
B(-6,7,11,Leaves:4)
B(-6,8,4,LOG_2:13)
B(-6,8,5,LOG_2:13)
B(-6,8,10,Leaves:4)
B(-6,8,11,Leaves:4)
B(-6,9,5,LOG_2:13)
B(-6,9,9,Leaves:4)
B(-6,9,12,Leaves:4)
B(-6,9,14,Leaves:4)
B(-6,10,-9,Leaves:4)
B(-6,10,-8,Leaves:4)
B(-6,10,2,LOG_2:13)
B(-6,10,3,LOG_2:13)
B(-6,10,9,Leaves:4)
B(-6,11,8,Leaves:4)
B(-6,11,13,Leaves:4)
B(-6,12,-11,Leaves:4)
B(-6,12,-10,Leaves:4)
B(-6,12,1,LOG_2:13)
B(-6,12,2,LOG_2:13)
B(-6,12,5,Leaves:4)
B(-6,12,6,Leaves:4)
B(-6,12,7,Leaves:4)
B(-6,12,8,Leaves:4)
B(-6,12,10,Leaves:4)
B(-6,12,11,Leaves:4)
B(-6,13,-10,Leaves:4)
B(-6,13,-9,Leaves:4)
B(-6,13,3,Leaves:4)
B(-6,13,4,Leaves:4)
B(-6,13,8,Leaves:4)
B(-6,13,9,Leaves:4)
B(-6,14,-13,Leaves:4)
B(-6,14,-12,Leaves:4)
B(-6,14,-11,Leaves:4)
B(-6,14,-10,Leaves:4)
B(-6,14,0,Leaves:4)
B(-6,14,2,Leaves:4)
B(-6,14,4,Leaves:4)
B(-6,14,5,Leaves:4)
B(-6,14,7,Leaves:4)
B(-6,14,8,Leaves:4)
B(-6,14,9,Leaves:4)
B(-6,15,-11,LOG_2:13)
B(-6,15,-10,LOG_2:13)
B(-6,15,-8,Leaves:4)
B(-6,15,0,Leaves:4)
B(-6,15,3,Leaves:4)
B(-6,15,5,Leaves:4)
B(-6,15,8,Leaves:4)
B(-6,15,9,Leaves:4)
B(-6,15,10,Leaves:4)
B(-6,16,-13,Leaves:4)
B(-6,16,-10,Leaves:4)
B(-6,16,-8,Leaves:4)
B(-6,16,3,Leaves:4)
B(-6,16,4,Leaves:4)
B(-6,16,7,Leaves:4)
B(-6,16,8,Leaves:4)
B(-6,17,-12,Leaves:4)
B(-6,17,-11,Leaves:4)
B(-6,17,-10,Leaves:4)
B(-6,17,2,Leaves:4)
B(-6,17,5,Leaves:4)
B(-6,17,8,Leaves:4)
B(-6,18,-11,Leaves:4)
B(-5,5,8,Leaves:4)
B(-5,6,4,LOG_2:13)
B(-5,6,5,LOG_2:13)
B(-5,6,8,Leaves:4)
B(-5,6,11,Leaves:4)
B(-5,7,4,LOG_2:13)
B(-5,7,5,LOG_2:13)
B(-5,9,12,Leaves:4)
B(-5,10,-6,LOG_2:13)
B(-5,10,2,LOG_2:13)
B(-5,10,8,Leaves:4)
B(-5,10,10,Leaves:4)
B(-5,11,-5,LOG_2:13)
B(-5,11,1,Leaves:4)
B(-5,11,2,LOG_2:13)
B(-5,12,2,LOG_2:13)
B(-5,12,4,Leaves:4)
B(-5,12,9,Leaves:4)
B(-5,12,10,Leaves:4)
B(-5,13,-10,Leaves:4)
B(-5,13,-1,Leaves:4)
B(-5,13,0,Leaves:4)
B(-5,13,2,Leaves:4)
B(-5,13,4,Leaves:4)
B(-5,13,6,Leaves:4)
B(-5,13,10,Leaves:4)
B(-5,14,-11,LOG_2:13)
B(-5,14,-8,Leaves:4)
B(-5,14,0,Leaves:4)
B(-5,14,6,Leaves:4)
B(-5,14,7,Leaves:4)
B(-5,14,9,Leaves:4)
B(-5,15,-11,LOG_2:13)
B(-5,15,-10,Leaves:4)
B(-5,15,-9,Leaves:4)
B(-5,15,-8,Leaves:4)
B(-5,15,1,Leaves:4)
B(-5,15,2,Leaves:4)
B(-5,15,3,Leaves:4)
B(-5,15,4,Leaves:4)
B(-5,15,7,Leaves:4)
B(-5,16,2,Leaves:4)
B(-5,16,5,Leaves:4)
B(-5,16,9,Leaves:4)
B(-5,17,2,Leaves:4)
B(-5,18,-10,Leaves:4)
B(-5,18,3,Leaves:4)
B(-4,5,3,LOG_2:13)
B(-4,5,4,LOG_2:13)
B(-4,5,5,LOG_2:13)
B(-4,6,3,LOG_2:13)
B(-4,6,4,LOG_2:13)
B(-4,6,5,LOG_2:13)
B(-4,11,2,LOG_2:13)
B(-4,12,-5,LOG_2:13)
B(-4,12,2,Leaves:4)
B(-4,12,10,Leaves:4)
B(-4,13,-10,Leaves:4)
B(-4,13,0,Leaves:4)
B(-4,13,1,Leaves:4)
B(-4,13,2,Leaves:4)
B(-4,13,4,Leaves:4)
B(-4,13,8,Leaves:4)
B(-4,13,10,Leaves:4)
B(-4,13,11,Leaves:4)
B(-4,14,-11,LOG_2:13)
B(-4,14,-10,Leaves:4)
B(-4,14,0,Leaves:4)
B(-4,14,4,Leaves:4)
B(-4,14,8,Leaves:4)
B(-4,15,-11,Leaves:4)
B(-4,15,-10,Leaves:4)
B(-4,15,-8,Leaves:4)
B(-4,15,-1,Leaves:4)
B(-4,15,2,Leaves:4)
B(-4,15,4,Leaves:4)
B(-4,15,5,Leaves:4)
B(-4,15,6,Leaves:4)
B(-4,15,8,Leaves:4)
B(-4,16,-2,Leaves:4)
B(-4,16,6,Leaves:4)
B(-4,16,8,Leaves:4)
B(-4,17,-3,Leaves:4)
B(-4,17,-2,Leaves:4)
B(-4,17,-1,Leaves:4)
B(-4,17,1,Leaves:4)
B(-4,17,2,Leaves:4)
B(-4,17,4,Leaves:4)
B(-4,17,5,Leaves:4)
B(-4,17,9,Leaves:4)
B(-4,18,1,Leaves:4)
B(-4,18,2,Leaves:4)
B(-4,18,3,Leaves:4)
B(-3,2,0,LOG_2:13)
B(-3,2,1,LOG_2:13)
B(-3,3,0,LOG_2:13)
B(-3,3,1,LOG_2:13)
B(-3,4,-1,LOG_2:13)
B(-3,4,0,LOG_2:13)
B(-3,4,2,LOG_2:13)
B(-3,4,3,LOG_2:13)
B(-3,5,-1,LOG_2:13)
B(-3,5,2,LOG_2:13)
B(-3,5,3,LOG_2:13)
B(-3,5,4,LOG_2:13)
B(-3,6,4,LOG_2:13)
B(-3,11,1,Leaves:4)
B(-3,11,2,LOG_2:13)
B(-3,11,3,LOG_2:13)
B(-3,11,7,Leaves:4)
B(-3,11,9,Leaves:4)
B(-3,12,2,Leaves:4)
B(-3,12,3,LOG_2:13)
B(-3,12,4,LOG_2:13)
B(-3,12,8,Leaves:4)
B(-3,13,-11,LOG_2:13)
B(-3,13,-10,LOG_2:13)
B(-3,13,-5,LOG_2:13)
B(-3,13,1,Leaves:4)
B(-3,13,4,Leaves:4)
B(-3,13,7,LOG_2:13)
B(-3,13,8,Leaves:4)
B(-3,14,-14,Leaves:4)
B(-3,14,-11,LOG_2:13)
B(-3,14,-10,Leaves:4)
B(-3,14,-5,LOG_2:13)
B(-3,14,-4,LOG_2:13)
B(-3,14,-3,LOG_2:13)
B(-3,14,0,Leaves:4)
B(-3,14,1,Leaves:4)
B(-3,14,2,Leaves:4)
B(-3,14,5,Leaves:4)
B(-3,14,7,LOG_2:13)
B(-3,14,8,LOG_2:13)
B(-3,14,9,Leaves:4)
B(-3,15,-13,Leaves:4)
B(-3,15,-11,Leaves:4)
B(-3,15,-10,Leaves:4)
B(-3,15,-3,LOG_2:13)
B(-3,15,-2,LOG_2:13)
B(-3,15,0,Leaves:4)
B(-3,15,3,Leaves:4)
B(-3,15,4,Leaves:4)
B(-3,15,5,Leaves:4)
B(-3,15,7,Leaves:4)
B(-3,15,9,Leaves:4)
B(-3,15,11,Leaves:4)
B(-3,16,-12,Leaves:4)
B(-3,16,-4,Leaves:4)
B(-3,16,-3,Leaves:4)
B(-3,16,0,Leaves:4)
B(-3,16,7,Leaves:4)
B(-3,16,8,Leaves:4)
B(-3,17,-12,Leaves:4)
B(-3,17,1,Leaves:4)
B(-3,17,2,Leaves:4)
B(-3,18,-11,Leaves:4)
B(-3,18,5,Leaves:4)
B(-2,-6,2,LOG_2:13)
B(-2,2,0,LOG_2:13)
B(-2,2,1,LOG_2:13)
B(-2,3,0,LOG_2:13)
B(-2,3,1,LOG_2:13)
B(-2,3,2,LOG_2:13)
B(-2,4,-1,LOG_2:13)
B(-2,4,0,LOG_2:13)
B(-2,4,1,LOG_2:13)
B(-2,4,2,LOG_2:13)
B(-2,5,-1,LOG_2:13)
B(-2,5,0,LOG_2:13)
B(-2,5,2,LOG_2:13)
B(-2,6,-1,LOG_2:13)
B(-2,11,-8,LOG_2:13)
B(-2,11,8,Leaves:4)
B(-2,12,-9,LOG_2:13)
B(-2,12,-6,LOG_2:13)
B(-2,12,4,LOG_2:13)
B(-2,12,5,LOG_2:13)
B(-2,12,6,Leaves:4)
B(-2,12,7,Leaves:4)
B(-2,13,-10,LOG_2:13)
B(-2,13,-9,LOG_2:13)
B(-2,13,-6,LOG_2:13)
B(-2,13,-5,LOG_2:13)
B(-2,13,1,Leaves:4)
B(-2,13,3,Leaves:4)
B(-2,13,5,LOG_2:13)
B(-2,13,6,LOG_2:13)
B(-2,13,7,LOG_2:13)
B(-2,13,8,Leaves:4)
B(-2,14,1,Leaves:4)
B(-2,14,2,Leaves:4)
B(-2,14,4,Leaves:4)
B(-2,14,5,Leaves:4)
B(-2,14,6,Leaves:4)
B(-2,14,7,Leaves:4)
B(-2,14,9,Leaves:4)
B(-2,14,10,Leaves:4)
B(-2,14,11,Leaves:4)
B(-2,15,-14,Leaves:4)
B(-2,15,-11,LOG_2:13)
B(-2,15,-4,Leaves:4)
B(-2,15,-2,LOG_2:13)
B(-2,15,1,Leaves:4)
B(-2,15,4,Leaves:4)
B(-2,15,5,Leaves:4)
B(-2,15,6,Leaves:4)
B(-2,15,7,Leaves:4)
B(-2,16,-14,Leaves:4)
B(-2,16,-13,Leaves:4)
B(-2,16,-12,Leaves:4)
B(-2,16,-1,Leaves:4)
B(-2,16,5,Leaves:4)
B(-2,16,7,Leaves:4)
B(-2,16,10,Leaves:4)
B(-2,17,-13,Leaves:4)
B(-2,17,-11,Leaves:4)
B(-2,17,-10,Leaves:4)
B(-2,17,-5,Leaves:4)
B(-2,17,0,Leaves:4)
B(-2,17,7,Leaves:4)
B(-2,18,0,Leaves:4)
B(-2,18,5,Leaves:4)
B(-1,-6,2,LOG_2:13)
B(-1,-5,-3,LOG:1)
B(-1,-4,-4,LOG_2:13)
B(-1,-4,-3,LOG_2:13)
B(-1,-4,-1,LOG:1)
B(-1,-4,2,LOG:1)
B(-1,-3,-3,LOG_2:13)
B(-1,-3,-2,LOG_2:13)
B(-1,-3,-1,LOG_2:13)
B(-1,-3,1,LOG:1)
B(-1,-2,-2,LOG:1)
B(-1,-2,-1,LOG:1)
B(-1,-2,0,LOG:1)
B(-1,1,0,LOG_2:13)
B(-1,2,0,LOG_2:13)
B(-1,2,1,LOG_2:13)
B(-1,3,0,LOG_2:13)
B(-1,3,1,LOG_2:13)
B(-1,4,-1,LOG_2:13)
B(-1,5,-1,LOG_2:13)
B(-1,5,0,LOG_2:13)
B(-1,6,-2,LOG_2:13)
B(-1,6,-1,LOG_2:13)
B(-1,10,-8,LOG_2:13)
B(-1,10,-7,LOG_2:13)
B(-1,10,-6,LOG_2:13)
B(-1,11,-9,LOG_2:13)
B(-1,11,-8,LOG_2:13)
B(-1,11,-7,LOG_2:13)
B(-1,11,-6,LOG_2:13)
B(-1,12,-9,LOG_2:13)
B(-1,12,-7,LOG_2:13)
B(-1,12,-6,LOG_2:13)
B(-1,12,-3,Leaves:4)
B(-1,12,-2,Leaves:4)
B(-1,12,3,LOG_2:13)
B(-1,12,4,LOG_2:13)
B(-1,12,9,Leaves:4)
B(-1,13,-13,Leaves:4)
B(-1,13,-11,Leaves:4)
B(-1,13,-4,Leaves:4)
B(-1,13,3,LOG_2:13)
B(-1,13,9,Leaves:4)
B(-1,13,10,Leaves:4)
B(-1,14,-12,Leaves:4)
B(-1,14,-5,Leaves:4)
B(-1,14,-4,Leaves:4)
B(-1,14,-1,Leaves:4)
B(-1,14,0,Leaves:4)
B(-1,14,2,Leaves:4)
B(-1,15,-4,Leaves:4)
B(-1,15,-3,Leaves:4)
B(-1,15,-2,LOG_2:13)
B(-1,15,-1,Leaves:4)
B(-1,15,0,Leaves:4)
B(-1,15,2,Leaves:4)
B(-1,15,4,Leaves:4)
B(-1,15,6,Leaves:4)
B(-1,15,10,Leaves:4)
B(-1,16,-14,Leaves:4)
B(-1,16,-13,Leaves:4)
B(-1,16,-12,LOG_2:13)
B(-1,16,-11,Leaves:4)
B(-1,16,-10,Leaves:4)
B(-1,16,-5,Leaves:4)
B(-1,16,-2,Leaves:4)
B(-1,16,0,Leaves:4)
B(-1,16,5,Leaves:4)
B(-1,16,7,Leaves:4)
B(-1,16,9,Leaves:4)
B(-1,17,-12,Leaves:4)
B(-1,17,-11,Leaves:4)
B(-1,17,-10,Leaves:4)
B(-1,17,-4,Leaves:4)
B(-1,17,-2,Leaves:4)
B(-1,17,-1,Leaves:4)
B(-1,17,1,Leaves:4)
B(-1,17,7,Leaves:4)
B(-1,18,-12,Leaves:4)
B(-1,18,-5,Leaves:4)
B(-1,18,-2,Leaves:4)
B(-1,19,-3,Leaves:4)
B(-1,19,-1,Leaves:4)
B(-1,20,-2,Leaves:4)
B(0,-6,-3,LOG:1)
B(0,-6,-2,LOG:1)
B(0,-5,-4,LOG_2:13)
B(0,-5,-3,LOG:1)
B(0,-5,2,LOG_2:13)
B(0,-4,-4,LOG_2:13)
B(0,-4,-3,LOG_2:13)
B(0,-4,1,LOG_2:13)
B(0,-4,2,LOG_2:13)
B(0,-3,-2,LOG_2:13)
B(0,-3,-1,LOG_2:13)
B(0,-3,0,LOG_2:13)
B(0,-3,1,LOG_2:13)
B(0,-2,-2,LOG:1)
B(0,-2,0,LOG_2:13)
B(0,-2,1,LOG_2:13)
B(0,-2,2,LOG_2:13)
B(0,-1,0,LOG_2:13)
B(0,-1,1,LOG_2:13)
B(0,-1,2,LOG_2:13)
B(0,0,0,LOG_2:13)
B(0,0,1,LOG_2:13)
B(0,0,2,LOG_2:13)
B(0,0,3,LOG:1)
B(0,1,0,LOG_2:13)
B(0,1,1,LOG_2:13)
B(0,1,2,LOG_2:13)
B(0,2,0,LOG_2:13)
B(0,6,-2,LOG_2:13)
B(0,6,-1,LOG_2:13)
B(0,6,0,LOG_2:13)
B(0,7,-2,LOG_2:13)
B(0,7,-1,LOG_2:13)
B(0,9,-6,LOG_2:13)
B(0,9,-5,LOG_2:13)
B(0,10,-6,LOG_2:13)
B(0,10,-5,LOG_2:13)
B(0,12,5,Leaves:4)
B(0,12,9,Leaves:4)
B(0,13,-13,Leaves:4)
B(0,13,-12,Leaves:4)
B(0,13,-11,Leaves:4)
B(0,13,-2,Leaves:4)
B(0,13,1,Leaves:4)
B(0,13,2,LOG_2:13)
B(0,13,11,Leaves:4)
B(0,14,-14,Leaves:4)
B(0,14,0,Leaves:4)
B(0,14,1,Leaves:4)
B(0,14,2,LOG_2:13)
B(0,14,3,Leaves:4)
B(0,14,6,Leaves:4)
B(0,14,7,Leaves:4)
B(0,15,-12,Leaves:4)
B(0,15,-2,Leaves:4)
B(0,15,-1,Leaves:4)
B(0,15,2,Leaves:4)
B(0,15,3,Leaves:4)
B(0,15,6,Leaves:4)
B(0,15,7,Leaves:4)
B(0,15,9,Leaves:4)
B(0,15,12,Leaves:4)
B(0,16,-14,Leaves:4)
B(0,16,-13,Leaves:4)
B(0,16,-12,LOG_2:13)
B(0,16,-5,Leaves:4)
B(0,16,-1,Leaves:4)
B(0,16,2,Leaves:4)
B(0,16,3,Leaves:4)
B(0,16,6,Leaves:4)
B(0,16,9,Leaves:4)
B(0,16,10,Leaves:4)
B(0,16,11,Leaves:4)
B(0,17,-14,Leaves:4)
B(0,17,-13,Leaves:4)
B(0,17,-12,Leaves:4)
B(0,17,-11,Leaves:4)
B(0,17,8,Leaves:4)
B(0,18,-14,Leaves:4)
B(0,18,-12,Leaves:4)
B(0,18,-10,Leaves:4)
B(0,18,-5,Leaves:4)
B(0,18,9,Leaves:4)
B(0,19,-4,Leaves:4)
B(1,-6,-5,LOG:1)
B(1,-6,5,LOG_2:13)
B(1,-6,6,LOG:1)
B(1,-5,-5,LOG_2:13)
B(1,-5,-4,LOG_2:13)
B(1,-5,5,LOG:1)
B(1,-5,6,LOG:1)
B(1,-4,0,LOG:1)
B(1,-4,1,LOG_2:13)
B(1,-4,2,LOG_2:13)
B(1,-3,-1,LOG:1)
B(1,-3,0,LOG_2:13)
B(1,-3,1,LOG_2:13)
B(1,-3,2,LOG_2:13)
B(1,-2,0,LOG:1)
B(1,-2,1,LOG_2:13)
B(1,-2,2,LOG_2:13)
B(1,-1,0,LOG_2:13)
B(1,-1,1,LOG_2:13)
B(1,-1,2,LOG_2:13)
B(1,0,0,LOG_2:13)
B(1,0,1,LOG_2:13)
B(1,1,1,LOG_2:13)
B(1,6,-2,LOG_2:13)
B(1,6,-1,LOG_2:13)
B(1,7,-3,LOG_2:13)
B(1,7,-2,LOG_2:13)
B(1,8,-3,LOG_2:13)
B(1,8,-2,LOG_2:13)
B(1,9,-6,LOG_2:13)
B(1,9,-5,LOG_2:13)
B(1,9,-4,LOG_2:13)
B(1,9,-3,LOG_2:13)
B(1,10,7,Leaves:4)
B(1,11,6,Leaves:4)
B(1,11,8,Leaves:4)
B(1,12,6,Leaves:4)
B(1,12,7,Leaves:4)
B(1,13,-13,Leaves:4)
B(1,13,-3,Leaves:4)
B(1,13,3,Leaves:4)
B(1,13,8,Leaves:4)
B(1,14,-13,Leaves:4)
B(1,14,-12,Leaves:4)
B(1,14,0,Leaves:4)
B(1,14,2,LOG_2:13)
B(1,14,4,Leaves:4)
B(1,14,7,Leaves:4)
B(1,15,-13,Leaves:4)
B(1,15,-3,Leaves:4)
B(1,15,-2,Leaves:4)
B(1,15,2,Leaves:4)
B(1,15,4,Leaves:4)
B(1,15,6,Leaves:4)
B(1,15,7,Leaves:4)
B(1,16,-13,Leaves:4)
B(1,16,-12,Leaves:4)
B(1,16,-11,Leaves:4)
B(1,16,-10,Leaves:4)
B(1,16,-9,Leaves:4)
B(1,16,-4,Leaves:4)
B(1,16,-2,Leaves:4)
B(1,16,-1,Leaves:4)
B(1,16,0,Leaves:4)
B(1,17,-12,Leaves:4)
B(1,17,-9,Leaves:4)
B(1,17,-2,Leaves:4)
B(1,17,0,Leaves:4)
B(1,17,4,Leaves:4)
B(1,17,7,Leaves:4)
B(1,18,-12,Leaves:4)
B(1,18,-11,Leaves:4)
B(1,18,-2,Leaves:4)
B(1,18,1,Leaves:4)
B(1,18,2,Leaves:4)
B(1,19,-4,Leaves:4)
B(2,-5,-5,LOG_2:13)
B(2,-5,5,LOG_2:13)
B(2,-5,6,LOG_2:13)
B(2,-4,0,LOG:1)
B(2,-3,0,LOG_2:13)
B(2,-3,1,LOG_2:13)
B(2,-3,2,LOG_2:13)
B(2,-2,1,LOG_2:13)
B(2,-2,2,LOG_2:13)
B(2,-1,0,LOG:1)
B(2,-1,1,LOG:1)
B(2,6,-2,LOG_2:13)
B(2,6,-1,LOG_2:13)
B(2,7,-2,LOG_2:13)
B(2,8,-4,LOG_2:13)
B(2,8,-3,LOG_2:13)
B(2,9,-5,LOG_2:13)
B(2,9,-4,LOG_2:13)
B(2,9,6,Leaves:4)
B(2,11,6,Leaves:4)
B(2,11,7,Leaves:4)
B(2,11,8,Leaves:4)
B(2,12,3,Leaves:4)
B(2,12,6,Leaves:4)
B(2,13,2,Leaves:4)
B(2,13,3,Leaves:4)
B(2,14,-10,Leaves:4)
B(2,14,-3,Leaves:4)
B(2,14,-2,Leaves:4)
B(2,14,2,LOG_2:13)
B(2,14,8,Leaves:4)
B(2,15,-10,Leaves:4)
B(2,15,-2,Leaves:4)
B(2,15,1,Leaves:4)
B(2,15,3,Leaves:4)
B(2,15,5,Leaves:4)
B(2,16,-10,Leaves:4)
B(2,16,-3,Leaves:4)
B(2,16,3,Leaves:4)
B(2,16,7,Leaves:4)
B(2,16,8,Leaves:4)
B(2,17,-12,Leaves:4)
B(2,17,-3,Leaves:4)
B(2,17,-2,Leaves:4)
B(2,17,-1,Leaves:4)
B(2,17,0,Leaves:4)
B(2,17,3,Leaves:4)
B(2,17,10,Leaves:4)
B(2,18,-2,Leaves:4)
B(2,18,-1,Leaves:4)
B(2,18,3,Leaves:4)
B(3,-6,5,LOG:1)
B(3,-5,4,LOG_2:13)
B(3,-5,5,LOG_2:13)
B(3,-4,1,LOG:1)
B(3,-4,4,LOG_2:13)
B(3,-3,0,LOG_2:13)
B(3,-3,1,LOG_2:13)
B(3,-3,2,LOG_2:13)
B(3,-3,3,LOG_2:13)
B(3,-2,1,LOG:1)
B(3,-2,3,LOG:1)
B(3,5,0,LOG_2:13)
B(3,6,-1,LOG_2:13)
B(3,6,0,LOG_2:13)
B(3,8,6,Leaves:4)
B(3,9,-4,LOG_2:13)
B(3,10,-5,LOG_2:13)
B(3,10,-4,LOG_2:13)
B(3,10,4,Leaves:4)
B(3,10,8,Leaves:4)
B(3,11,-5,LOG_2:13)
B(3,11,6,Leaves:4)
B(3,11,7,Leaves:4)
B(3,11,8,Leaves:4)
B(3,12,-11,Leaves:4)
B(3,12,-9,Leaves:4)
B(3,12,-1,Leaves:4)
B(3,12,1,Leaves:4)
B(3,12,3,Leaves:4)
B(3,12,6,Leaves:4)
B(3,12,8,Leaves:4)
B(3,12,10,Leaves:4)
B(3,13,-10,Leaves:4)
B(3,13,-8,Leaves:4)
B(3,13,0,Leaves:4)
B(3,13,3,Leaves:4)
B(3,13,5,Leaves:4)
B(3,13,6,Leaves:4)
B(3,13,7,Leaves:4)
B(3,13,8,Leaves:4)
B(3,13,9,Leaves:4)
B(3,14,-13,Leaves:4)
B(3,14,-12,Leaves:4)
B(3,14,-10,Leaves:4)
B(3,14,-9,Leaves:4)
B(3,14,-8,Leaves:4)
B(3,14,1,Leaves:4)
B(3,14,3,Leaves:4)
B(3,14,7,Leaves:4)
B(3,14,8,Leaves:4)
B(3,14,9,Leaves:4)
B(3,15,-12,Leaves:4)
B(3,15,-11,Leaves:4)
B(3,15,-8,Leaves:4)
B(3,15,-4,Leaves:4)
B(3,15,-1,Leaves:4)
B(3,15,1,Leaves:4)
B(3,15,3,LOG_2:13)
B(3,15,4,Leaves:4)
B(3,15,5,Leaves:4)
B(3,15,6,Leaves:4)
B(3,15,7,Leaves:4)
B(3,15,8,Leaves:4)
B(3,16,-13,Leaves:4)
B(3,16,-12,Leaves:4)
B(3,16,-11,Leaves:4)
B(3,16,-9,Leaves:4)
B(3,16,5,Leaves:4)
B(3,16,6,Leaves:4)
B(3,16,7,Leaves:4)
B(3,16,8,Leaves:4)
B(3,16,9,Leaves:4)
B(3,17,-13,Leaves:4)
B(3,17,-11,Leaves:4)
B(3,17,-2,Leaves:4)
B(3,19,-12,Leaves:4)
B(4,-5,2,LOG:1)
B(4,-5,5,LOG:1)
B(4,-4,2,LOG_2:13)
B(4,-4,3,LOG_2:13)
B(4,-4,4,LOG_2:13)
B(4,-4,5,LOG:1)
B(4,-3,2,LOG_2:13)
B(4,-3,3,LOG_2:13)
B(4,5,0,LOG_2:13)
B(4,5,1,LOG_2:13)
B(4,8,5,LOG_2:13)
B(4,8,7,Leaves:4)
B(4,9,5,LOG_2:13)
B(4,9,8,Leaves:4)
B(4,9,9,Leaves:4)
B(4,10,3,Leaves:4)
B(4,10,4,Leaves:4)
B(4,10,6,LOG_2:13)
B(4,10,7,Leaves:4)
B(4,10,9,Leaves:4)
B(4,11,-6,LOG_2:13)
B(4,11,-5,LOG_2:13)
B(4,11,3,Leaves:4)
B(4,11,4,Leaves:4)
B(4,12,-8,Leaves:4)
B(4,12,-7,LOG_2:13)
B(4,12,-6,LOG_2:13)
B(4,12,4,Leaves:4)
B(4,12,8,Leaves:4)
B(4,12,9,Leaves:4)
B(4,13,-11,Leaves:4)
B(4,13,-8,LOG_2:13)
B(4,13,-3,Leaves:4)
B(4,13,-1,Leaves:4)
B(4,13,0,Leaves:4)
B(4,13,7,Leaves:4)
B(4,14,-10,Leaves:4)
B(4,14,-9,LOG_2:13)
B(4,14,-4,Leaves:4)
B(4,14,2,Leaves:4)
B(4,14,3,Leaves:4)
B(4,14,9,Leaves:4)
B(4,15,-12,Leaves:4)
B(4,15,-1,Leaves:4)
B(4,15,2,Leaves:4)
B(4,15,3,Leaves:4)
B(4,15,6,Leaves:4)
B(4,15,8,Leaves:4)
B(4,16,-11,Leaves:4)
B(4,16,-10,Leaves:4)
B(4,16,-4,Leaves:4)
B(4,16,-1,Leaves:4)
B(4,16,2,Leaves:4)
B(4,16,3,Leaves:4)
B(4,17,-11,Leaves:4)
B(4,17,-10,Leaves:4)
B(4,17,-9,Leaves:4)
B(4,17,0,Leaves:4)
B(4,17,1,Leaves:4)
B(4,17,3,Leaves:4)
B(5,-5,4,LOG_2:13)
B(5,-5,5,LOG:1)
B(5,-4,4,LOG_2:13)
B(5,-4,5,LOG_2:13)
B(5,-3,2,LOG:1)
B(5,5,1,LOG_2:13)
B(5,5,2,LOG_2:13)
B(5,6,2,LOG_2:13)
B(5,6,3,LOG_2:13)
B(5,8,4,LOG_2:13)
B(5,8,5,Leaves:4)
B(5,8,6,Leaves:4)
B(5,9,7,Leaves:4)
B(5,10,2,Leaves:4)
B(5,10,3,Leaves:4)
B(5,10,4,Leaves:4)
B(5,10,6,Leaves:4)
B(5,10,7,Leaves:4)
B(5,11,5,Leaves:4)
B(5,11,7,Leaves:4)
B(5,12,-12,Leaves:4)
B(5,12,-11,Leaves:4)
B(5,12,-10,Leaves:4)
B(5,12,-9,Leaves:4)
B(5,12,-8,Leaves:4)
B(5,12,-6,LOG_2:13)
B(5,12,4,Leaves:4)
B(5,12,6,Leaves:4)
B(5,12,7,Leaves:4)
B(5,13,-12,Leaves:4)
B(5,13,-10,Leaves:4)
B(5,13,-9,Leaves:4)
B(5,13,-2,Leaves:4)
B(5,13,3,Leaves:4)
B(5,13,5,Leaves:4)
B(5,13,6,Leaves:4)
B(5,13,9,Leaves:4)
B(5,14,-13,Leaves:4)
B(5,14,-12,Leaves:4)
B(5,14,-10,LOG_2:13)
B(5,14,-9,Leaves:4)
B(5,14,-7,Leaves:4)
B(5,14,-4,Leaves:4)
B(5,14,-3,Leaves:4)
B(5,14,-2,Leaves:4)
B(5,14,1,Leaves:4)
B(5,14,3,Leaves:4)
B(5,15,-13,Leaves:4)
B(5,15,-12,Leaves:4)
B(5,15,-11,Leaves:4)
B(5,15,-9,Leaves:4)
B(5,15,-8,Leaves:4)
B(5,15,-7,Leaves:4)
B(5,15,-3,Leaves:4)
B(5,15,0,Leaves:4)
B(5,15,2,Leaves:4)
B(5,15,3,Leaves:4)
B(5,15,6,Leaves:4)
B(5,16,-14,Leaves:4)
B(5,16,-10,Leaves:4)
B(5,16,-9,Leaves:4)
B(5,16,-2,Leaves:4)
B(5,16,1,Leaves:4)
B(5,16,2,Leaves:4)
B(5,16,3,Leaves:4)
B(5,17,-11,Leaves:4)
B(5,17,-10,Leaves:4)
B(5,18,-1,Leaves:4)
B(6,6,3,LOG_2:13)
B(6,7,3,LOG_2:13)
B(6,7,4,LOG_2:13)
B(6,8,6,Leaves:4)
B(6,9,-5,Leaves:4)
B(6,9,4,Leaves:4)
B(6,10,1,Leaves:4)
B(6,10,4,Leaves:4)
B(6,10,5,Leaves:4)
B(6,10,6,Leaves:4)
B(6,11,-9,Leaves:4)
B(6,11,-7,LOG_2:13)
B(6,12,-10,Leaves:4)
B(6,12,-9,Leaves:4)
B(6,12,-7,Leaves:4)
B(6,12,-6,LOG_2:13)
B(6,12,-5,Leaves:4)
B(6,12,7,Leaves:4)
B(6,13,-12,Leaves:4)
B(6,13,-10,Leaves:4)
B(6,13,-9,Leaves:4)
B(6,13,-8,Leaves:4)
B(6,13,-6,LOG_2:13)
B(6,13,-5,Leaves:4)
B(6,13,6,Leaves:4)
B(6,13,8,Leaves:4)
B(6,14,-13,Leaves:4)
B(6,14,-10,Leaves:4)
B(6,14,-8,Leaves:4)
B(6,14,-6,LOG_2:13)
B(6,14,-5,LOG_2:13)
B(6,14,-4,Leaves:4)
B(6,14,-3,Leaves:4)
B(6,14,-1,Leaves:4)
B(6,15,-11,Leaves:4)
B(6,15,-3,Leaves:4)
B(6,15,0,Leaves:4)
B(6,15,1,Leaves:4)
B(6,15,2,Leaves:4)
B(6,16,-9,Leaves:4)
B(6,16,-7,Leaves:4)
B(6,16,-4,Leaves:4)
B(6,16,-3,Leaves:4)
B(6,17,-10,Leaves:4)
B(6,17,1,Leaves:4)
B(7,5,-1,Leaves:4)
B(7,6,-1,Leaves:4)
B(7,7,-7,Leaves:4)
B(7,7,-1,Leaves:4)
B(7,7,0,Leaves:4)
B(7,7,3,LOG_2:13)
B(7,7,5,Leaves:4)
B(7,8,-6,Leaves:4)
B(7,9,-5,Leaves:4)
B(7,9,1,Leaves:4)
B(7,9,7,Leaves:4)
B(7,10,-4,Leaves:4)
B(7,10,2,Leaves:4)
B(7,10,4,Leaves:4)
B(7,10,7,Leaves:4)
B(7,11,-9,Leaves:4)
B(7,11,-8,Leaves:4)
B(7,11,-7,LOG_2:13)
B(7,11,-5,Leaves:4)
B(7,11,1,Leaves:4)
B(7,11,3,Leaves:4)
B(7,11,5,Leaves:4)
B(7,12,-10,Leaves:4)
B(7,12,-3,Leaves:4)
B(7,12,-2,Leaves:4)
B(7,12,2,Leaves:4)
B(7,12,4,Leaves:4)
B(7,13,-10,Leaves:4)
B(7,13,-8,Leaves:4)
B(7,13,4,Leaves:4)
B(7,14,-10,Leaves:4)
B(7,14,-9,Leaves:4)
B(7,14,-8,Leaves:4)
B(7,14,-5,LOG_2:13)
B(7,14,-4,LOG_2:13)
B(7,14,-3,LOG_2:13)
B(7,15,-10,Leaves:4)
B(7,15,-9,Leaves:4)
B(7,15,-1,Leaves:4)
B(7,16,-8,Leaves:4)
B(7,16,-5,Leaves:4)
B(7,17,-8,Leaves:4)
B(7,17,-4,Leaves:4)
B(8,4,0,Leaves:4)
B(8,6,-6,Leaves:4)
B(8,6,-5,Leaves:4)
B(8,7,-4,Leaves:4)
B(8,7,3,LOG_2:13)
B(8,8,1,LOG_2:13)
B(8,8,2,LOG_2:13)
B(8,8,3,LOG_2:13)
B(8,8,4,Leaves:4)
B(8,8,5,Leaves:4)
B(8,8,6,Leaves:4)
B(8,9,-6,Leaves:4)
B(8,9,-4,Leaves:4)
B(8,9,1,LOG_2:13)
B(8,9,4,Leaves:4)
B(8,10,-7,LOG_2:13)
B(8,10,4,Leaves:4)
B(8,10,5,Leaves:4)
B(8,10,6,Leaves:4)
B(8,11,-9,Leaves:4)
B(8,11,-8,Leaves:4)
B(8,11,-4,Leaves:4)
B(8,11,-3,Leaves:4)
B(8,11,3,Leaves:4)
B(8,12,-7,Leaves:4)
B(8,12,-5,Leaves:4)
B(8,12,-4,Leaves:4)
B(8,12,5,Leaves:4)
B(8,13,-11,Leaves:4)
B(8,13,-10,Leaves:4)
B(8,13,-9,Leaves:4)
B(8,13,-8,Leaves:4)
B(8,13,-6,Leaves:4)
B(8,13,-5,Leaves:4)
B(8,13,-3,Leaves:4)
B(8,13,-2,Leaves:4)
B(8,13,-1,Leaves:4)
B(8,13,0,Leaves:4)
B(8,13,5,Leaves:4)
B(8,14,-11,Leaves:4)
B(8,14,-10,Leaves:4)
B(8,14,-9,Leaves:4)
B(8,14,-8,Leaves:4)
B(8,14,-6,Leaves:4)
B(8,14,-5,Leaves:4)
B(8,14,-3,LOG_2:13)
B(8,14,-2,Leaves:4)
B(8,14,-1,Leaves:4)
B(8,14,0,Leaves:4)
B(8,15,-11,Leaves:4)
B(8,15,-10,Leaves:4)
B(8,15,-8,Leaves:4)
B(8,15,-4,Leaves:4)
B(8,15,-3,Leaves:4)
B(8,15,-1,Leaves:4)
B(8,15,0,Leaves:4)
B(8,16,-10,Leaves:4)
B(8,16,-5,Leaves:4)
B(8,16,-3,Leaves:4)
B(8,16,-1,Leaves:4)
B(8,17,-9,Leaves:4)
B(8,17,-8,Leaves:4)
B(9,4,-1,Leaves:4)
B(9,5,-4,Leaves:4)
B(9,5,2,Leaves:4)
B(9,6,-7,Leaves:4)
B(9,6,-6,Leaves:4)
B(9,6,-4,Leaves:4)
B(9,7,-1,LOG_2:13)
B(9,8,-7,Leaves:4)
B(9,8,-4,Leaves:4)
B(9,8,-1,LOG_2:13)
B(9,9,-6,LOG_2:13)
B(9,9,-3,Leaves:4)
B(9,9,-1,Leaves:4)
B(9,9,0,LOG_2:13)
B(9,9,1,LOG_2:13)
B(9,9,4,LOG_2:13)
B(9,9,8,Leaves:4)
B(9,10,-4,Leaves:4)
B(9,10,3,Leaves:4)
B(9,10,6,Leaves:4)
B(9,11,-10,Leaves:4)
B(9,11,-4,Leaves:4)
B(9,11,5,Leaves:4)
B(9,12,-8,Leaves:4)
B(9,12,-3,Leaves:4)
B(9,13,-8,Leaves:4)
B(9,13,-5,Leaves:4)
B(9,13,-3,Leaves:4)
B(9,13,-2,Leaves:4)
B(9,13,5,Leaves:4)
B(9,13,6,Leaves:4)
B(9,14,-12,Leaves:4)
B(9,14,-8,Leaves:4)
B(9,14,-5,Leaves:4)
B(9,15,-10,Leaves:4)
B(9,15,-8,Leaves:4)
B(9,15,-7,Leaves:4)
B(9,15,-6,Leaves:4)
B(9,15,-2,LOG_2:13)
B(9,15,0,Leaves:4)
B(9,15,2,Leaves:4)
B(9,16,-10,Leaves:4)
B(9,16,-5,Leaves:4)
B(9,16,1,Leaves:4)
B(9,17,-9,Leaves:4)
B(9,17,-7,Leaves:4)
B(9,17,-1,Leaves:4)
B(9,17,0,Leaves:4)
B(10,3,-1,Leaves:4)
B(10,4,0,Leaves:4)
B(10,5,-3,Leaves:4)
B(10,5,-2,Leaves:4)
B(10,5,1,Leaves:4)
B(10,5,2,Leaves:4)
B(10,6,-4,Leaves:4)
B(10,6,-1,LOG_2:13)
B(10,7,-6,Leaves:4)
B(10,7,-1,Leaves:4)
B(10,7,1,Leaves:4)
B(10,7,6,Leaves:4)
B(10,8,-2,Leaves:4)
B(10,8,0,Leaves:4)
B(10,8,5,Leaves:4)
B(10,9,-9,Leaves:4)
B(10,9,-5,Leaves:4)
B(10,9,1,LOG_2:13)
B(10,9,3,Leaves:4)
B(10,9,4,Leaves:4)
B(10,9,8,Leaves:4)
B(10,10,1,Leaves:4)
B(10,10,3,Leaves:4)
B(10,10,5,LOG_2:13)
B(10,12,-1,Leaves:4)
B(10,12,3,Leaves:4)
B(10,12,5,Leaves:4)
B(10,13,-9,Leaves:4)
B(10,13,-3,Leaves:4)
B(10,13,-2,Leaves:4)
B(10,13,-1,Leaves:4)
B(10,13,0,Leaves:4)
B(10,13,6,Leaves:4)
B(10,14,-11,Leaves:4)
B(10,14,-9,Leaves:4)
B(10,14,-8,Leaves:4)
B(10,14,-7,Leaves:4)
B(10,14,-4,Leaves:4)
B(10,14,-3,Leaves:4)
B(10,14,-1,Leaves:4)
B(10,14,0,Leaves:4)
B(10,15,-5,Leaves:4)
B(10,15,-3,Leaves:4)
B(10,15,-1,LOG_2:13)
B(10,16,-2,Leaves:4)
B(10,17,-1,Leaves:4)
B(10,17,0,Leaves:4)
B(11,3,-2,Leaves:4)
B(11,4,-1,Leaves:4)
B(11,6,-3,Leaves:4)
B(11,6,0,Leaves:4)
B(11,7,-7,Leaves:4)
B(11,7,-1,Leaves:4)
B(11,7,5,Leaves:4)
B(11,8,-1,Leaves:4)
B(11,8,1,Leaves:4)
B(11,8,3,Leaves:4)
B(11,9,-8,Leaves:4)
B(11,9,-7,Leaves:4)
B(11,9,1,LOG_2:13)
B(11,9,8,Leaves:4)
B(11,10,-5,Leaves:4)
B(11,10,2,Leaves:4)
B(11,10,3,Leaves:4)
B(11,11,-6,Leaves:4)
B(11,11,7,Leaves:4)
B(11,12,-2,Leaves:4)
B(11,12,5,Leaves:4)
B(11,13,-9,Leaves:4)
B(11,13,-4,Leaves:4)
B(11,13,5,Leaves:4)
B(11,14,-7,Leaves:4)
B(11,14,-6,Leaves:4)
B(11,14,-4,Leaves:4)
B(11,14,-1,Leaves:4)
B(11,14,1,Leaves:4)
B(11,15,-9,Leaves:4)
B(11,15,-8,Leaves:4)
B(11,15,-5,Leaves:4)
B(11,15,-4,Leaves:4)
B(11,15,-2,Leaves:4)
B(11,15,0,Leaves:4)
B(11,15,2,Leaves:4)
B(11,16,-2,Leaves:4)
B(12,5,0,Leaves:4)
B(12,6,-2,Leaves:4)
B(12,7,-1,Leaves:4)
B(12,7,0,Leaves:4)
B(12,8,-1,Leaves:4)
B(12,8,1,Leaves:4)
B(12,9,-7,Leaves:4)
B(12,9,-5,Leaves:4)
B(12,9,-1,Leaves:4)
B(12,9,4,Leaves:4)
B(12,9,5,Leaves:4)
B(12,10,-6,Leaves:4)
B(12,10,5,Leaves:4)
B(12,11,6,Leaves:4)
B(12,12,5,Leaves:4)
B(12,15,-2,Leaves:4)
B(12,15,-1,Leaves:4)
B(12,17,-1,Leaves:4)
B(13,6,0,Leaves:4)
B(13,7,3,Leaves:4)
B(13,9,0,Leaves:4)
B(13,16,-1,Leaves:4)

#
# +-----------------------------------------------------------------+ #
# |                            BO3 checks                           | #
# +-----------------------------------------------------------------+ #
#

BlockCheck(0,-1,0,grass,dirt)

#
# +-----------------------------------------------------------------+ #
# |                             Branches                            | #
# +-----------------------------------------------------------------+ #
#

