
#
# +-----------------------------------------------------------------+ #
# |                            BO3 object                           | #
# +-----------------------------------------------------------------+ #
#

Author: NLBlackEagle

Description: No description given

Version: 3

SettingsMode: WriteDisable


#
# +-----------------------------------------------------------------+ #
# |                          Main settings                          | #
# +-----------------------------------------------------------------+ #
#

Tree: true

Frequency: 1

Rarity: 100.0

RotateRandomly: true

SpawnHeight: highestSolidBlock

SpawnHeightOffset: 0

SpawnHeightVariance: 0


# Height Limits for the BO3. #


MinHeight: 0

MaxHeight: 256


# Extrusion settings #


ExtrudeMode: None

ExtrudeThroughBlocks: air

MaxBranchDepth: 10

ExcludedBiomes: All


#
# +-----------------------------------------------------------------+ #
# |                      Source block settings                      | #
# +-----------------------------------------------------------------+ #
#

SourceBlocks: AIR,GRASS,DIRT,SAND

MaxPercentageOutsideSourceBlock: 0

OutsideSourceBlock: placeAnyway


#
# +-----------------------------------------------------------------+ #
# |                              Blocks                             | #
# +-----------------------------------------------------------------+ #
#

B(-11,5,-3,leaves:1)
B(-11,6,-1,Leaves:4)
B(-11,7,-2,Leaves:4)
B(-10,5,-4,leaves:1)
B(-10,5,-3,Leaves:4)
B(-10,5,-2,leaves:1)
B(-10,5,2,leaves:1)
B(-10,6,-4,leaves:1)
B(-10,6,-1,leaves:1)
B(-10,6,1,leaves:1)
B(-10,6,2,Leaves:4)
B(-10,7,-5,leaves:1)
B(-10,7,-4,Leaves:4)
B(-10,7,-3,LOG_2:13)
B(-10,8,-5,Leaves:4)
B(-10,8,-4,leaves:1)
B(-10,8,-3,Leaves:4)
B(-10,8,-2,leaves:1)
B(-10,9,1,Leaves:4)
B(-10,11,-1,Leaves:4)
B(-10,12,-2,Leaves:4)
B(-9,3,2,Leaves:4)
B(-9,4,-2,Leaves:4)
B(-9,4,-1,leaves:1)
B(-9,5,-4,leaves:1)
B(-9,5,-2,leaves:1)
B(-9,5,-1,leaves:1)
B(-9,5,1,Leaves:4)
B(-9,6,-4,Leaves:4)
B(-9,6,-3,Leaves:4)
B(-9,6,-2,LOG:13)
B(-9,6,-1,leaves:1)
B(-9,7,-2,leaves:1)
B(-9,7,3,leaves:1)
B(-9,8,-2,leaves:1)
B(-9,9,-1,Leaves:4)
B(-9,9,0,Leaves:4)
B(-9,10,-5,leaves:1)
B(-9,10,-2,leaves:1)
B(-9,11,-2,Leaves:4)
B(-9,11,-1,leaves:1)
B(-9,11,0,Leaves:4)
B(-9,12,-6,Leaves:4)
B(-9,12,-3,leaves:1)
B(-8,2,-1,Leaves:4)
B(-8,2,1,Leaves:4)
B(-8,2,3,leaves:1)
B(-8,3,-1,leaves:1)
B(-8,3,2,Leaves:4)
B(-8,4,1,Leaves:4)
B(-8,4,2,leaves:1)
B(-8,5,-1,Leaves:4)
B(-8,5,1,leaves:1)
B(-8,6,-3,Leaves:4)
B(-8,6,-1,LOG_2:13)
B(-8,6,0,Leaves:4)
B(-8,6,1,Leaves:4)
B(-8,7,-5,Leaves:4)
B(-8,7,-3,Leaves:4)
B(-8,7,-2,Leaves:4)
B(-8,7,-1,Leaves:4)
B(-8,7,2,leaves:1)
B(-8,8,-5,leaves:1)
B(-8,8,-1,Leaves:4)
B(-8,8,0,Leaves:4)
B(-8,9,-5,Leaves:4)
B(-8,9,2,leaves:1)
B(-8,10,-4,leaves:1)
B(-8,10,-3,Leaves:4)
B(-8,10,-2,Leaves:4)
B(-8,10,-1,leaves:1)
B(-8,10,0,LOG_2:13)
B(-8,10,1,Leaves:4)
B(-8,11,-4,Leaves:4)
B(-8,11,-3,leaves:1)
B(-8,11,-1,LOG_2:13)
B(-8,11,0,leaves:1)
B(-8,11,1,leaves:1)
B(-8,11,2,Leaves:4)
B(-8,12,-3,Leaves:4)
B(-8,12,-1,leaves:1)
B(-8,12,0,Leaves:4)
B(-8,12,1,leaves:1)
B(-8,13,-4,Leaves:4)
B(-8,13,0,leaves:1)
B(-7,2,0,Leaves:4)
B(-7,2,1,leaves:1)
B(-7,2,3,leaves:1)
B(-7,3,-1,leaves:1)
B(-7,3,0,leaves:1)
B(-7,3,1,LOG_2:13)
B(-7,3,3,leaves:1)
B(-7,4,2,leaves:1)
B(-7,6,-4,leaves:1)
B(-7,6,-3,leaves:1)
B(-7,6,-1,LOG_2:13)
B(-7,6,1,leaves:1)
B(-7,6,2,leaves:1)
B(-7,6,3,leaves:1)
B(-7,7,-1,LOG:13)
B(-7,8,-4,leaves:1)
B(-7,8,-1,Leaves:4)
B(-7,8,0,leaves:1)
B(-7,8,2,leaves:1)
B(-7,9,-5,Leaves:4)
B(-7,9,-2,leaves:1)
B(-7,9,0,leaves:1)
B(-7,9,1,LOG:13)
B(-7,10,-7,Leaves:4)
B(-7,10,-6,Leaves:4)
B(-7,10,-4,leaves:1)
B(-7,10,-2,leaves:1)
B(-7,10,-1,leaves:1)
B(-7,10,0,leaves:1)
B(-7,11,-8,leaves:1)
B(-7,11,-5,leaves:1)
B(-7,11,-1,leaves:1)
B(-7,11,1,Leaves:4)
B(-7,11,2,leaves:1)
B(-7,11,3,Leaves:4)
B(-7,12,-3,leaves:1)
B(-7,12,-2,Leaves:4)
B(-7,12,-1,leaves:1)
B(-7,12,1,leaves:1)
B(-7,13,-6,leaves:1)
B(-7,13,-5,leaves:1)
B(-7,13,-2,leaves:1)
B(-7,13,0,leaves:1)
B(-7,14,-7,leaves:1)
B(-6,1,0,Leaves:4)
B(-6,2,2,leaves:1)
B(-6,2,3,Leaves:4)
B(-6,3,1,leaves:1)
B(-6,4,0,leaves:1)
B(-6,4,1,leaves:1)
B(-6,4,2,LOG_2:13)
B(-6,4,3,Leaves:4)
B(-6,5,-7,Leaves:4)
B(-6,5,-5,Leaves:4)
B(-6,5,-1,Leaves:4)
B(-6,5,2,Leaves:4)
B(-6,6,-8,Leaves:4)
B(-6,6,-1,leaves:1)
B(-6,6,1,Leaves:4)
B(-6,6,2,Leaves:4)
B(-6,7,-6,LOG:13)
B(-6,7,-5,leaves:1)
B(-6,7,-4,leaves:1)
B(-6,7,-1,LOG:13)
B(-6,7,0,LOG_2:13)
B(-6,7,1,leaves:1)
B(-6,8,-7,leaves:1)
B(-6,8,-5,leaves:1)
B(-6,8,0,LOG:13)
B(-6,8,1,LOG:13)
B(-6,8,2,LOG:13)
B(-6,9,-7,Leaves:4)
B(-6,9,-5,Leaves:4)
B(-6,9,-2,Leaves:4)
B(-6,9,0,leaves:1)
B(-6,9,1,leaves:1)
B(-6,9,4,Leaves:4)
B(-6,10,-6,leaves:1)
B(-6,10,-5,Leaves:4)
B(-6,10,-4,Leaves:4)
B(-6,10,-2,Leaves:4)
B(-6,10,0,Leaves:4)
B(-6,11,-9,Leaves:4)
B(-6,11,-7,Leaves:4)
B(-6,11,-6,leaves:1)
B(-6,11,-5,Leaves:4)
B(-6,11,-3,leaves:1)
B(-6,11,0,Leaves:4)
B(-6,11,1,Leaves:4)
B(-6,11,2,Leaves:4)
B(-6,12,-9,Leaves:4)
B(-6,12,-8,leaves:1)
B(-6,12,-7,leaves:1)
B(-6,12,-6,Leaves:4)
B(-6,12,2,leaves:1)
B(-6,13,-8,Leaves:4)
B(-6,14,-8,leaves:1)
B(-6,14,-7,leaves:1)
B(-5,4,0,leaves:1)
B(-5,4,1,LOG:13)
B(-5,5,-6,leaves:1)
B(-5,5,1,LOG_2:13)
B(-5,6,-7,Leaves:4)
B(-5,6,-1,LOG_2:13)
B(-5,7,-7,Leaves:4)
B(-5,7,-5,LOG_2:13)
B(-5,7,-1,LOG_2:13)
B(-5,7,2,leaves:1)
B(-5,8,-7,Leaves:4)
B(-5,8,3,leaves:1)
B(-5,9,-4,leaves:1)
B(-5,9,2,leaves:1)
B(-5,9,3,Leaves:4)
B(-5,10,-8,Leaves:4)
B(-5,10,-2,leaves:1)
B(-5,10,0,Leaves:4)
B(-5,10,1,leaves:1)
B(-5,10,2,Leaves:4)
B(-5,10,3,Leaves:4)
B(-5,11,-8,leaves:1)
B(-5,11,1,Leaves:4)
B(-5,11,3,Leaves:4)
B(-5,11,4,Leaves:4)
B(-5,12,-8,leaves:1)
B(-5,12,-7,Leaves:4)
B(-5,12,-4,leaves:1)
B(-5,12,0,leaves:1)
B(-5,12,1,Leaves:4)
B(-5,13,-10,leaves:1)
B(-5,13,-8,leaves:1)
B(-5,13,1,Leaves:4)
B(-5,13,2,leaves:1)
B(-5,14,-9,Leaves:4)
B(-5,14,-7,leaves:1)
B(-4,4,2,Leaves:4)
B(-4,5,0,LOG:13)
B(-4,5,1,LOG:13)
B(-4,6,-5,LOG:13)
B(-4,6,-4,LOG_2:13)
B(-4,6,-2,LOG:13)
B(-4,6,-1,LOG:13)
B(-4,6,0,LOG:13)
B(-4,7,-6,leaves:1)
B(-4,7,-2,LOG_2:13)
B(-4,7,4,Leaves:4)
B(-4,8,-6,Leaves:4)
B(-4,8,2,Leaves:4)
B(-4,9,2,leaves:1)
B(-4,9,3,leaves:1)
B(-4,9,4,leaves:1)
B(-4,9,5,leaves:1)
B(-4,10,3,LOG:13)
B(-4,11,-8,leaves:1)
B(-4,11,-7,leaves:1)
B(-4,11,-6,LOG_2:13)
B(-4,11,1,leaves:1)
B(-4,11,2,LOG:13)
B(-4,11,3,Leaves:4)
B(-4,11,4,leaves:1)
B(-4,12,-11,Leaves:4)
B(-4,12,-10,leaves:1)
B(-4,12,-8,leaves:1)
B(-4,12,-7,LOG:13)
B(-4,12,0,Leaves:4)
B(-4,12,2,leaves:1)
B(-4,13,-10,Leaves:4)
B(-4,13,-8,LOG:13)
B(-4,13,-6,leaves:1)
B(-4,13,2,leaves:1)
B(-4,13,3,Leaves:4)
B(-4,14,-10,Leaves:4)
B(-4,14,-8,Leaves:4)
B(-4,14,-7,Leaves:4)
B(-4,15,-8,leaves:1)
B(-4,15,-7,leaves:1)
B(-3,4,1,LOG_2:13)
B(-3,5,0,LOG:13)
B(-3,5,1,LOG:13)
B(-3,6,-4,LOG:13)
B(-3,6,-3,LOG_2:13)
B(-3,6,1,LOG_2:13)
B(-3,7,-3,LOG_2:13)
B(-3,7,-2,LOG:13)
B(-3,7,1,LOG_2:13)
B(-3,7,2,LOG_2:13)
B(-3,7,3,Leaves:4)
B(-3,8,-3,LOG_2:13)
B(-3,8,1,Leaves:4)
B(-3,8,2,LOG_2:13)
B(-3,8,3,LOG:13)
B(-3,9,1,Leaves:4)
B(-3,9,2,Leaves:4)
B(-3,9,3,LOG_2:13)
B(-3,9,4,leaves:1)
B(-3,9,5,leaves:1)
B(-3,10,2,leaves:1)
B(-3,10,3,leaves:1)
B(-3,10,4,leaves:1)
B(-3,10,5,Leaves:4)
B(-3,11,-13,Leaves:4)
B(-3,11,-6,LOG:13)
B(-3,11,-1,Leaves:4)
B(-3,11,3,Leaves:4)
B(-3,11,4,Leaves:4)
B(-3,11,5,leaves:1)
B(-3,12,-11,leaves:1)
B(-3,12,2,leaves:1)
B(-3,13,-10,Leaves:4)
B(-3,16,-9,leaves:1)
B(-2,3,-1,LOG_2:13)
B(-2,3,0,LOG:13)
B(-2,4,-1,LOG_2:13)
B(-2,4,0,LOG:13)
B(-2,4,1,LOG:13)
B(-2,7,1,leaves:1)
B(-2,7,4,Leaves:4)
B(-2,8,-3,LOG_2:13)
B(-2,8,2,leaves:1)
B(-2,9,-3,LOG_2:13)
B(-2,9,0,Leaves:4)
B(-2,9,4,leaves:1)
B(-2,10,-10,Leaves:4)
B(-2,10,-6,LOG:13)
B(-2,10,-2,LOG:13)
B(-2,10,1,leaves:1)
B(-2,10,3,leaves:1)
B(-2,11,-11,Leaves:4)
B(-2,11,-6,LOG:13)
B(-2,11,1,leaves:1)
B(-2,11,2,leaves:1)
B(-2,11,3,leaves:1)
B(-2,12,-12,leaves:1)
B(-2,12,-11,Leaves:4)
B(-2,12,-8,leaves:1)
B(-2,12,-2,Leaves:4)
B(-2,12,2,leaves:1)
B(-2,13,-10,leaves:1)
B(-2,13,-7,Leaves:4)
B(-2,13,-6,Leaves:4)
B(-2,13,-1,leaves:1)
B(-2,14,-12,Leaves:4)
B(-2,14,-8,leaves:1)
B(-2,14,-6,leaves:1)
B(-2,15,-8,Leaves:4)
B(-2,15,-6,leaves:1)
B(-2,16,-8,Leaves:4)
B(-2,16,-7,Leaves:4)
B(-1,0,0,LOG_2:13)
B(-1,1,0,LOG_2:13)
B(-1,2,0,LOG_2:13)
B(-1,3,-1,LOG_2:13)
B(-1,3,0,LOG_2:13)
B(-1,4,0,LOG:13)
B(-1,8,0,leaves:1)
B(-1,8,1,leaves:1)
B(-1,8,3,Leaves:4)
B(-1,9,-7,LOG:13)
B(-1,9,1,Leaves:4)
B(-1,9,2,Leaves:4)
B(-1,9,3,leaves:1)
B(-1,9,4,Leaves:4)
B(-1,10,-7,LOG_2:13)
B(-1,10,-6,LOG:13)
B(-1,10,-1,Leaves:4)
B(-1,10,3,Leaves:4)
B(-1,10,4,leaves:1)
B(-1,11,-10,Leaves:4)
B(-1,11,-8,leaves:1)
B(-1,11,-1,LOG_2:13)
B(-1,11,0,Leaves:4)
B(-1,11,2,Leaves:4)
B(-1,11,3,Leaves:4)
B(-1,12,-13,Leaves:4)
B(-1,12,-11,leaves:1)
B(-1,12,-8,Leaves:4)
B(-1,12,-6,LOG_2:13)
B(-1,12,-5,Leaves:4)
B(-1,12,-2,Leaves:4)
B(-1,12,1,leaves:1)
B(-1,13,-13,leaves:1)
B(-1,13,-9,leaves:1)
B(-1,13,-7,leaves:1)
B(-1,13,-6,Leaves:4)
B(-1,13,-1,leaves:1)
B(-1,14,-11,leaves:1)
B(-1,14,-10,leaves:1)
B(-1,14,-9,leaves:1)
B(-1,14,-8,Leaves:4)
B(-1,14,-5,leaves:1)
B(-1,15,-10,Leaves:4)
B(-1,15,-8,Leaves:4)
B(-1,15,-7,leaves:1)
B(-1,15,-6,leaves:1)
B(-1,16,-9,Leaves:4)
B(-1,16,-8,Leaves:4)
B(0,0,-1,LOG_2:13)
B(0,0,0,LOG_2:13)
B(0,1,-1,LOG_2:13)
B(0,1,0,LOG:13)
B(0,2,-2,LOG_2:13)
B(0,2,-1,LOG_2:13)
B(0,8,3,Leaves:4)
B(0,9,-12,leaves:1)
B(0,9,-7,LOG_2:13)
B(0,9,0,leaves:1)
B(0,9,2,leaves:1)
B(0,9,3,leaves:1)
B(0,9,4,Leaves:4)
B(0,10,-11,leaves:1)
B(0,10,-10,Leaves:4)
B(0,10,-2,leaves:1)
B(0,10,4,Leaves:4)
B(0,11,-13,leaves:1)
B(0,11,-11,LOG:13)
B(0,11,-7,leaves:1)
B(0,11,-2,Leaves:4)
B(0,11,-1,Leaves:4)
B(0,11,3,Leaves:4)
B(0,12,-11,Leaves:4)
B(0,12,-6,LOG_2:13)
B(0,12,0,Leaves:4)
B(0,13,-11,leaves:1)
B(0,13,-8,Leaves:4)
B(0,13,-7,LOG_2:13)
B(0,13,-6,Leaves:4)
B(0,13,1,Leaves:4)
B(0,14,-7,leaves:1)
B(0,15,-7,leaves:1)
B(0,16,-7,Leaves:4)
B(1,-3,2,LOG:13)
B(1,-3,3,LOG_2:13)
B(1,-3,4,LOG_2:13)
B(1,-3,5,LOG:13)
B(1,-2,-1,LOG_2:13)
B(1,-2,0,LOG_2:13)
B(1,-2,1,LOG:13)
B(1,-1,-1,LOG:13)
B(1,-1,0,LOG:13)
B(1,-1,1,LOG:13)
B(1,0,-1,LOG:13)
B(1,0,0,LOG_2:13)
B(1,0,1,LOG:13)
B(1,1,-1,LOG:13)
B(1,1,0,LOG:13)
B(1,2,-2,LOG:13)
B(1,2,-1,LOG_2:13)
B(1,3,-3,LOG_2:13)
B(1,3,-2,LOG_2:13)
B(1,4,-3,LOG_2:13)
B(1,7,-7,LOG:13)
B(1,7,-6,LOG:13)
B(1,8,-8,LOG:13)
B(1,8,-7,LOG:13)
B(1,8,2,LOG:13)
B(1,8,3,Leaves:4)
B(1,9,-12,leaves:1)
B(1,9,-10,leaves:1)
B(1,9,-9,LOG:13)
B(1,9,-7,LOG_2:13)
B(1,9,2,LOG_2:13)
B(1,9,3,leaves:1)
B(1,10,-10,LOG:13)
B(1,10,0,Leaves:4)
B(1,10,1,leaves:1)
B(1,10,2,leaves:1)
B(1,11,-11,Leaves:4)
B(1,11,-10,leaves:1)
B(1,11,-9,Leaves:4)
B(1,12,-11,leaves:1)
B(1,12,-1,leaves:1)
B(1,12,2,Leaves:4)
B(1,12,3,leaves:1)
B(1,13,-5,leaves:1)
B(1,13,-1,Leaves:4)
B(1,15,-7,leaves:1)
B(2,-3,-1,LOG_2:13)
B(2,-3,0,LOG:13)
B(2,-3,1,LOG:13)
B(2,-3,2,LOG:13)
B(2,-3,3,LOG_2:13)
B(2,-3,6,LOG:13)
B(2,-2,-1,LOG:13)
B(2,-2,0,LOG_2:13)
B(2,-2,1,LOG:13)
B(2,-2,2,LOG_2:13)
B(2,-1,-1,LOG_2:13)
B(2,-1,0,LOG_2:13)
B(2,-1,1,LOG_2:13)
B(2,0,-1,LOG_2:13)
B(2,0,0,LOG:13)
B(2,3,-3,LOG_2:13)
B(2,4,-3,LOG_2:13)
B(2,6,-5,LOG_2:13)
B(2,7,-7,LOG_2:13)
B(2,7,-6,LOG:13)
B(2,7,-5,LOG:13)
B(2,8,1,LOG_2:13)
B(2,8,2,LOG:13)
B(2,8,4,Leaves:4)
B(2,9,-9,leaves:1)
B(2,9,0,Leaves:4)
B(2,9,4,Leaves:4)
B(2,10,-10,leaves:1)
B(2,10,1,leaves:1)
B(2,10,2,leaves:1)
B(2,10,3,Leaves:4)
B(2,11,-10,leaves:1)
B(2,11,0,Leaves:4)
B(2,11,3,leaves:1)
B(2,11,4,Leaves:4)
B(2,12,-12,leaves:1)
B(2,12,-11,leaves:1)
B(2,12,-10,Leaves:4)
B(2,12,-9,Leaves:4)
B(2,12,-8,leaves:1)
B(2,12,-1,leaves:1)
B(2,12,0,Leaves:4)
B(2,12,1,Leaves:4)
B(2,13,-9,leaves:1)
B(2,13,-8,Leaves:4)
B(3,-3,0,LOG_2:13)
B(3,-3,1,LOG:13)
B(3,-3,2,LOG_2:13)
B(3,-2,1,LOG:13)
B(3,4,-4,LOG:13)
B(3,4,-3,LOG:13)
B(3,4,-2,LOG_2:13)
B(3,5,-5,LOG_2:13)
B(3,5,-4,LOG:13)
B(3,5,-3,LOG:13)
B(3,5,-2,LOG:13)
B(3,6,-5,LOG_2:13)
B(3,6,-4,LOG_2:13)
B(3,7,1,LOG:13)
B(3,8,-9,leaves:1)
B(3,8,-6,Leaves:4)
B(3,8,-5,leaves:1)
B(3,8,1,LOG_2:13)
B(3,9,-10,Leaves:4)
B(3,9,-9,leaves:1)
B(3,9,1,Leaves:4)
B(3,9,2,leaves:1)
B(3,10,-11,Leaves:4)
B(3,10,-10,leaves:1)
B(3,10,-9,Leaves:4)
B(3,10,-8,Leaves:4)
B(3,10,-7,leaves:1)
B(3,10,0,Leaves:4)
B(3,10,1,Leaves:4)
B(3,11,-11,Leaves:4)
B(3,11,-10,Leaves:4)
B(3,11,-9,leaves:1)
B(3,11,-8,leaves:1)
B(3,11,-7,Leaves:4)
B(3,11,0,leaves:1)
B(3,11,1,Leaves:4)
B(3,11,3,leaves:1)
B(3,12,-10,Leaves:4)
B(3,12,0,leaves:1)
B(3,12,3,Leaves:4)
B(3,13,-8,Leaves:4)
B(3,13,1,Leaves:4)
B(3,14,0,leaves:1)
B(4,-3,1,LOG_2:13)
B(4,-3,2,LOG:13)
B(4,3,-5,leaves:1)
B(4,3,-3,leaves:1)
B(4,4,-4,leaves:1)
B(4,4,-3,leaves:1)
B(4,4,-2,leaves:1)
B(4,5,-2,LOG_2:13)
B(4,5,-1,LOG:13)
B(4,6,-5,LOG_2:13)
B(4,6,-1,LOG:13)
B(4,6,0,LOG:13)
B(4,7,-7,leaves:1)
B(4,7,-5,LOG_2:13)
B(4,7,0,LOG:13)
B(4,7,1,LOG:13)
B(4,8,-8,leaves:1)
B(4,8,-7,Leaves:4)
B(4,8,-6,leaves:1)
B(4,8,-5,leaves:1)
B(4,9,-8,Leaves:4)
B(4,9,-7,leaves:1)
B(4,9,-1,Leaves:4)
B(4,9,0,leaves:1)
B(4,10,-10,leaves:1)
B(4,10,-8,leaves:1)
B(4,10,-7,Leaves:4)
B(4,10,-6,leaves:1)
B(4,10,-1,leaves:1)
B(4,10,0,Leaves:4)
B(4,10,2,leaves:1)
B(4,11,-11,leaves:1)
B(4,11,-7,Leaves:4)
B(4,11,-4,Leaves:4)
B(4,11,-3,Leaves:4)
B(4,11,1,leaves:1)
B(4,11,2,leaves:1)
B(4,12,0,Leaves:4)
B(4,12,1,leaves:1)
B(4,12,2,leaves:1)
B(4,13,1,leaves:1)
B(5,-3,2,LOG_2:13)
B(5,-3,3,LOG_2:13)
B(5,2,-5,Leaves:4)
B(5,2,-4,leaves:1)
B(5,3,-4,Leaves:4)
B(5,3,-3,leaves:1)
B(5,4,-6,Leaves:4)
B(5,4,-4,Leaves:4)
B(5,5,-2,leaves:1)
B(5,6,-5,Leaves:4)
B(5,6,-4,leaves:1)
B(5,7,-8,Leaves:4)
B(5,7,-7,Leaves:4)
B(5,7,-6,LOG_2:13)
B(5,7,-5,LOG_2:13)
B(5,7,-3,Leaves:4)
B(5,8,-8,leaves:1)
B(5,8,-7,Leaves:4)
B(5,8,-6,LOG:13)
B(5,8,-5,leaves:1)
B(5,8,-4,leaves:1)
B(5,8,0,LOG:13)
B(5,9,-10,leaves:1)
B(5,9,-4,Leaves:4)
B(5,9,-3,leaves:1)
B(5,9,-1,leaves:1)
B(5,9,1,Leaves:4)
B(5,10,-6,Leaves:4)
B(5,10,-5,Leaves:4)
B(5,10,-2,leaves:1)
B(5,10,-1,Leaves:4)
B(5,10,1,leaves:1)
B(5,11,-9,leaves:1)
B(5,11,-7,Leaves:4)
B(5,11,-6,Leaves:4)
B(5,11,-4,Leaves:4)
B(5,11,-2,Leaves:4)
B(5,11,-1,leaves:1)
B(5,11,0,Leaves:4)
B(5,11,1,leaves:1)
B(5,11,2,Leaves:4)
B(5,12,-4,leaves:1)
B(5,12,-3,Leaves:4)
B(5,12,-2,Leaves:4)
B(5,12,-1,leaves:1)
B(5,13,-2,leaves:1)
B(5,13,-1,Leaves:4)
B(5,13,0,leaves:1)
B(6,-3,3,LOG_2:13)
B(6,1,-3,Leaves:4)
B(6,2,-4,leaves:1)
B(6,3,-5,leaves:1)
B(6,3,-4,Leaves:4)
B(6,3,-3,LOG:13)
B(6,3,-2,Leaves:4)
B(6,3,-1,Leaves:4)
B(6,4,-4,LOG_2:13)
B(6,4,-3,leaves:1)
B(6,4,-2,Leaves:4)
B(6,5,-6,LOG:13)
B(6,5,-5,LOG:13)
B(6,6,-6,LOG_2:13)
B(6,6,-5,leaves:1)
B(6,6,-4,Leaves:4)
B(6,7,-8,leaves:1)
B(6,7,-7,leaves:1)
B(6,7,-6,Leaves:4)
B(6,7,-4,Leaves:4)
B(6,7,-3,Leaves:4)
B(6,7,-2,leaves:1)
B(6,8,-7,LOG:13)
B(6,8,-6,LOG_2:13)
B(6,8,-5,Leaves:4)
B(6,8,-4,Leaves:4)
B(6,8,-1,Leaves:4)
B(6,8,0,Leaves:4)
B(6,9,-7,leaves:1)
B(6,9,0,leaves:1)
B(6,9,1,LOG_2:13)
B(6,10,-7,leaves:1)
B(6,10,-3,leaves:1)
B(6,10,-2,Leaves:4)
B(6,10,0,Leaves:4)
B(6,10,1,leaves:1)
B(6,10,2,Leaves:4)
B(6,11,-6,Leaves:4)
B(6,11,-3,Leaves:4)
B(6,11,-2,leaves:1)
B(6,11,-1,leaves:1)
B(6,11,0,leaves:1)
B(6,11,1,leaves:1)
B(6,12,-6,Leaves:4)
B(6,12,-5,leaves:1)
B(6,12,-2,Leaves:4)
B(6,12,0,leaves:1)
B(6,12,1,leaves:1)
B(6,12,2,Leaves:4)
B(6,13,-3,leaves:1)
B(6,13,-2,leaves:1)
B(7,-3,4,LOG_2:13)
B(7,3,-4,Leaves:4)
B(7,3,-2,Leaves:4)
B(7,4,-4,leaves:1)
B(7,4,-1,leaves:1)
B(7,5,-3,Leaves:4)
B(7,5,-2,leaves:1)
B(7,6,-8,leaves:1)
B(7,6,-6,leaves:1)
B(7,6,-5,leaves:1)
B(7,6,-4,leaves:1)
B(7,6,-3,Leaves:4)
B(7,7,-7,leaves:1)
B(7,7,-6,Leaves:4)
B(7,7,-4,Leaves:4)
B(7,7,-3,Leaves:4)
B(7,7,-2,leaves:1)
B(7,7,-1,leaves:1)
B(7,8,-7,leaves:1)
B(7,8,-6,Leaves:4)
B(7,8,-3,Leaves:4)
B(7,8,-1,Leaves:4)
B(7,8,0,Leaves:4)
B(7,8,2,leaves:1)
B(7,9,-6,Leaves:4)
B(7,9,-5,Leaves:4)
B(7,9,-3,Leaves:4)
B(7,9,-2,leaves:1)
B(7,9,-1,leaves:1)
B(7,10,-8,leaves:1)
B(7,10,-1,Leaves:4)
B(7,10,0,Leaves:4)
B(7,10,1,LOG:13)
B(7,10,3,Leaves:4)
B(7,11,-3,Leaves:4)
B(7,11,-1,Leaves:4)
B(7,11,0,leaves:1)
B(7,11,1,leaves:1)
B(7,11,3,Leaves:4)
B(7,12,-2,leaves:1)
B(7,12,-1,leaves:1)
B(7,12,0,Leaves:4)
B(7,12,1,leaves:1)
B(7,12,2,leaves:1)
B(8,4,-5,leaves:1)
B(8,5,-6,Leaves:4)
B(8,5,-4,leaves:1)
B(8,7,-3,leaves:1)
B(8,7,-2,leaves:1)
B(8,7,-1,leaves:1)
B(8,9,0,leaves:1)
B(8,9,1,leaves:1)
B(8,9,3,Leaves:4)
B(8,10,-4,leaves:1)
B(8,10,-3,leaves:1)
B(8,10,-1,Leaves:4)
B(8,10,1,leaves:1)
B(8,10,3,Leaves:4)
B(8,11,-4,Leaves:4)
B(8,11,-2,leaves:1)
B(8,11,0,leaves:1)
B(8,12,2,leaves:1)
B(9,6,-4,Leaves:4)
B(9,6,-2,leaves:1)
B(9,8,-2,Leaves:4)
B(9,8,-1,leaves:1)
B(9,9,-1,leaves:1)
B(9,10,-1,Leaves:4)
B(9,11,-1,leaves:1)

#
# +-----------------------------------------------------------------+ #
# |                            BO3 checks                           | #
# +-----------------------------------------------------------------+ #
#

BlockCheck(0,-1,0,grass,dirt)

#
# +-----------------------------------------------------------------+ #
# |                             Branches                            | #
# +-----------------------------------------------------------------+ #
#

