
#######################################################################
# +-----------------------------------------------------------------+ #
# |                            BO3 object                           | #
# +-----------------------------------------------------------------+ #
#######################################################################

Author: NLBlackEagle

Description: Converted version of the BO2 EUR13S

Version: 3

SettingsMode: WriteDisable


#######################################################################
# +-----------------------------------------------------------------+ #
# |                          Main settings                          | #
# +-----------------------------------------------------------------+ #
#######################################################################

Tree: true

Frequency: 1

Rarity: 100.0

RotateRandomly: true

SpawnHeight: highestSolidBlock

SpawnHeightOffset: 0

SpawnHeightVariance: 0

##############################
# Height Limits for the BO3. #
##############################

MinHeight: 0

MaxHeight: 199

######################
# Extrusion settings #
######################

ExtrudeMode: None

ExtrudeThroughBlocks: AIR

MaxBranchDepth: 10

ExcludedBiomes: 


#######################################################################
# +-----------------------------------------------------------------+ #
# |                      Source block settings                      | #
# +-----------------------------------------------------------------+ #
#######################################################################

SourceBlocks: AIR,GRASS,DIRT,SAND

MaxPercentageOutsideSourceBlock: 0

OutsideSourceBlock: placeAnyway

IsOTGPlus: false

InheritBO3: 

InheritBO3Rotation: NORTH

OverrideChildSettings: true

OverrideParentHeight: false

CanOverride: false

BranchFrequency: 0

BranchFrequencyGroup: 

MustBeBelowOther: false

MustBeInside: 

CannotBeInside: 

ReplacesBO3: 

CanSpawnOnWater: true

SpawnOnWaterOnly: false

SpawnUnderWater: false

SpawnAtWaterLevel: false

HeightOffset: 0

RemoveAir: true

ReplaceAbove: 

ReplaceBelow: 

ReplaceWithBiomeBlocks: true

ReplaceWithGroundBlock: DIRT

ReplaceWithSurfaceBlock: GRASS

SmoothRadius: 0

SmoothHeightOffset: 0

SmoothStartTop: false

SmoothStartWood: false

SmoothingSurfaceBlock: 

SmoothingGroundBlock: 

BO3Group: 

IsSpawnPoint: false


#######################################################################
# +-----------------------------------------------------------------+ #
# |                              Blocks                             | #
# +-----------------------------------------------------------------+ #
#######################################################################

B(2,7,3,Leaves:4)
Block(-1,8,3,LOG:12)
Block(-1,7,3,Leaves:4)
Block(-1,6,3,Leaves:4)
B(2,9,3,Leaves:4)
Block(-1,9,4,Leaves:4)
Block(-1,5,3,Leaves:4)
B(2,4,3,Leaves:4)
B(2,5,3,Leaves:4)
B(2,6,3,Leaves:4)
Block(-1,3,4,Leaves:4)
B(2,4,2,Leaves:4)
Block(-4,10,1,LEAVES:4)
B(2,7,2,Leaves:4)
Block(-1,7,4,Leaves:4)
B(2,8,2,Leaves:4)
B(2,9,2,Leaves:4)
B(1,7,5,Leaves:4)
B(1,9,5,Leaves:4)
B(1,5,5,Leaves:4)
B(1,5,4,Leaves:4)
B(1,9,4,Leaves:4)
B(0,3,2,Leaves:4)
B(0,12,-2,LEAVES:4)
B(0,1,2,LOG:12)
Block(-3,11,2,LEAVES:4)
B(0,0,2,LOG:12)
Block(-2,-1,0,LOG:12)
Block(-1,2,0,LOG:12)
Block(-2,-2,0,LOG:12)
Block(-3,7,4,Leaves:4)
B(0,10,2,Leaves:4)
Block(-3,8,4,LOG:12)
Block(-3,9,4,LOG:12)
B(3,9,1,Leaves:4)
Block(-4,12,1,LEAVES:4)
Block(-4,11,1,LEAVES:4)
B(3,6,1,Leaves:4)
Block(-4,13,1,LEAVES:4)
B(3,7,1,LOG:12)
Block(-1,4,0,Leaves:4)
B(3,6,0,Leaves:4)
Block(-1,5,0,Leaves:4)
Block(-1,6,0,Leaves:4)
B(3,7,0,Leaves:4)
Block(-1,7,0,Leaves:4)
B(3,8,0,Leaves:4)
Block(-3,10,1,Leaves:4)
B(3,4,0,Leaves:4)
B(0,10,0,Leaves:4)
Block(-5,5,0,Leaves:4)
Block(-5,6,0,Leaves:4)
B(0,9,3,Leaves:4)
B(0,7,3,Leaves:4)
B(0,6,3,Leaves:4)
B(0,8,2,LOG:12)
B(0,9,2,Leaves:4)
B(0,6,2,Leaves:4)
B(0,7,2,Leaves:4)
B(0,7,6,Leaves:4)
B(2,3,2,Leaves:4)
B(2,0,2,LOG:12)
Block(-5,7,4,Leaves:4)
Block(-3,10,-3,Leaves:4)
B(5,5,1,Leaves:4)
Block(-5,9,-1,Leaves:4)
Block(-5,6,-1,Leaves:4)
Block(-4,9,2,Leaves:4)
B(2,7,6,Leaves:4)
B(1,3,-1,Leaves:4)
B(1,3,-2,Leaves:4)
B(1,8,-1,Leaves:4)
B(1,6,-1,Leaves:4)
B(4,5,-2,Leaves:4)
B(2,8,6,Leaves:4)
B(1,6,-3,Leaves:4)
B(1,9,-4,Leaves:4)
B(0,4,3,Leaves:4)
Block(-3,9,5,Leaves:4)
Block(-3,6,5,Leaves:4)
B(0,-1,2,LOG:12)
Block(-2,12,0,LEAVES:4)
Block(-3,5,5,Leaves:4)
B(0,-2,2,LOG:12)
Block(-3,7,3,Leaves:4)
Block(-3,8,3,Leaves:4)
Block(-3,9,3,Leaves:4)
B(0,0,1,LOG:12)
B(0,2,1,LOG:12)
Block(-3,6,3,Leaves:4)
B(0,1,1,LOG:12)
B(0,4,1,Leaves:4)
Block(-3,0,3,LOG:12)
B(0,3,1,LOG:12)
B(0,6,1,Leaves:4)
B(0,5,1,Leaves:4)
Block(-5,9,1,Leaves:4)
B(3,3,1,Leaves:4)
Block(-4,10,4,LEAVES:4)
Block(-4,7,-4,Leaves:4)
Block(-4,9,-4,Leaves:4)
Block(-3,10,-1,Leaves:4)
Block(-4,8,-4,Leaves:4)
B(6,8,1,Leaves:4)
Block(-3,10,-2,Leaves:4)
Block(-4,8,1,Leaves:4)
Block(-4,9,1,Leaves:4)
Block(-3,10,-5,Leaves:4)
B(5,6,0,Leaves:4)
B(2,4,1,Leaves:4)
Block(-4,6,1,Leaves:4)
B(2,2,1,Leaves:4)
Block(-4,7,1,Leaves:4)
Block(-5,9,3,Leaves:4)
Block(-3,10,0,Leaves:4)
Block(-3,11,0,LEAVES:4)
Block(-4,7,3,Leaves:4)
Block(-4,6,3,Leaves:4)
B(5,8,2,LEAVES:4)
Block(-4,8,-1,Leaves:4)
Block(-4,8,3,Leaves:4)
Block(-4,3,-1,Leaves:4)
B(1,0,3,LOG:12)
B(2,9,0,Leaves:4)
Block(-1,3,2,Leaves:4)
B(2,8,0,Leaves:4)
Block(-1,4,2,LOG:12)
B(2,7,0,Leaves:4)
B(3,6,2,Leaves:4)
B(2,6,0,LOG:12)
Block(-1,5,2,LOG:12)
Block(-1,6,2,Leaves:4)
B(3,7,2,Leaves:4)
B(3,8,2,Leaves:4)
B(3,9,2,Leaves:4)
B(3,6,3,Leaves:4)
B(3,7,3,Leaves:4)
Block(-1,8,1,Leaves:4)
Block(-3,9,-5,Leaves:4)
Block(-3,6,-5,LEAVES:4)
Block(-1,3,1,Leaves:4)
B(2,8,1,Leaves:4)
B(2,7,1,Leaves:4)
B(2,6,1,Leaves:4)
Block(-1,5,1,Leaves:4)
Block(-1,6,1,Leaves:4)
B(3,5,3,Leaves:4)
B(2,5,1,Leaves:4)
Block(-1,12,-3,LEAVES:4)
Block(-1,0,1,LOG:12)
B(1,8,2,Leaves:4)
B(1,7,2,Leaves:4)
B(1,6,2,Leaves:4)
Block(-1,10,-3,Leaves:4)
B(1,5,2,Leaves:4)
Block(-1,1,1,LOG:12)
B(0,8,-5,LEAVES:4)
Block(-3,8,6,Leaves:4)
B(0,8,-3,Leaves:4)
Block(-3,9,6,Leaves:4)
B(0,6,-3,Leaves:4)
B(1,9,2,Leaves:4)
B(1,9,3,Leaves:4)
B(1,8,3,Leaves:4)
B(1,7,3,Leaves:4)
B(1,6,3,Leaves:4)
Block(-3,6,-3,Leaves:4)
B(1,5,3,Leaves:4)
Block(-3,5,-3,Leaves:4)
B(1,4,3,Leaves:4)
Block(-1,0,2,LOG:12)
B(1,8,6,Leaves:4)
B(4,5,2,Leaves:4)
B(4,7,2,Leaves:4)
B(4,6,2,Leaves:4)
B(4,9,2,Leaves:4)
B(4,8,2,LOG:12)
B(4,6,4,Leaves:4)
B(4,7,4,Leaves:4)
B(4,8,4,Leaves:4)
B(1,10,-1,Leaves:4)
B(6,6,2,Leaves:4)
Block(-2,10,-2,Leaves:4)
B(2,10,3,Leaves:4)
Block(-2,7,5,Leaves:4)
B(6,8,2,Leaves:4)
Block(-5,12,0,LEAVES:4)
B(0,3,-1,Leaves:4)
B(6,7,4,Leaves:4)
B(5,10,2,Leaves:4)
B(0,9,-1,Leaves:4)
B(0,6,-1,LOG:12)
B(0,7,4,Leaves:4)
B(0,4,4,Leaves:4)
B(0,9,4,Leaves:4)
B(6,9,0,Leaves:4)
B(0,9,5,Leaves:4)
B(6,7,0,Leaves:4)
B(0,7,5,Leaves:4)
B(0,8,5,Leaves:4)
B(6,10,0,Leaves:4)
B(1,0,2,LOG:12)
Block(-4,10,3,LEAVES:4)
B(3,7,-1,Leaves:4)
B(3,2,2,Leaves:4)
B(2,3,0,Leaves:4)
B(2,5,0,Leaves:4)
Block(-5,6,2,Leaves:4)
Block(-5,8,2,Leaves:4)
Block(-3,6,-4,Leaves:4)
Block(-1,8,-4,Leaves:4)
B(2,11,4,LEAVES:4)
Block(-1,6,-4,Leaves:4)
B(1,11,0,LEAVES:4)
Block(-3,8,-4,Leaves:4)
Block(-3,7,-4,Leaves:4)
Block(-1,8,-3,LOG:12)
Block(-1,6,-2,Leaves:4)
Block(-1,9,-3,Leaves:4)
Block(-1,6,-3,Leaves:4)
Block(-1,3,-2,Leaves:4)
Block(-2,10,2,Leaves:4)
Block(-1,9,-2,Leaves:4)
Block(-1,7,-2,Leaves:4)
Block(-1,8,-2,Leaves:4)
Block(-1,-1,1,LOG:12)
Block(-1,-3,1,LOG:12)
Block(-1,-2,1,LOG:12)
B(4,6,3,Leaves:4)
B(4,8,3,Leaves:4)
B(4,7,3,Leaves:4)
Block(-1,10,-1,Leaves:4)
Block(-3,6,0,LOG:12)
B(1,-1,2,LOG:12)
B(1,-2,2,LOG:12)
B(1,-3,2,LOG:12)
Block(-2,11,-1,LEAVES:4)
B(4,9,3,Leaves:4)
Block(-5,10,1,LEAVES:4)
Block(-2,6,6,Leaves:4)
Block(-2,7,6,Leaves:4)
B(6,9,3,Leaves:4)
B(2,8,-3,Leaves:4)
B(4,10,4,Leaves:4)
B(5,8,-1,Leaves:4)
Block(-4,6,-3,Leaves:4)
B(2,9,-2,Leaves:4)
Block(-4,8,-3,Leaves:4)
B(2,3,-1,Leaves:4)
B(2,8,-2,Leaves:4)
B(2,4,-1,Leaves:4)
B(2,6,-1,Leaves:4)
Block(-1,-1,2,LOG:12)
B(1,12,2,LEAVES:4)
Block(-4,7,6,Leaves:4)
B(1,11,2,LEAVES:4)
B(1,11,1,LEAVES:4)
B(1,4,1,Leaves:4)
B(1,3,1,LOG:12)
B(1,2,1,LOG:12)
B(0,12,3,LEAVES:4)
Block(-4,11,0,LEAVES:4)
Block(-3,11,5,Leaves:4)
Block(-4,10,0,LEAVES:4)
B(5,11,3,LEAVES:4)
Block(-4,11,2,LEAVES:4)
B(5,10,3,Leaves:4)
B(3,8,5,Leaves:4)
B(3,7,5,Leaves:4)
Block(-2,8,-5,LEAVES:4)
Block(-1,8,-6,Leaves:4)
Block(-1,10,-2,Leaves:4)
Block(-5,7,-2,Leaves:4)
Block(-5,6,-2,Leaves:4)
B(1,-1,3,LOG:12)
Block(-2,7,0,Leaves:4)
Block(-2,8,0,Leaves:4)
Block(-2,9,0,Leaves:4)
B(3,8,-2,Leaves:4)
B(3,9,-2,Leaves:4)
Block(-1,10,2,Leaves:4)
Block(-2,5,0,Leaves:4)
Block(-5,8,-3,Leaves:4)
B(3,7,-2,Leaves:4)
B(1,1,0,Leaves:4)
Block(-2,0,0,LOG:12)
Block(-2,2,0,Leaves:4)
Block(-4,7,5,Leaves:4)
B(1,0,0,Leaves:4)
B(0,10,1,Leaves:4)
B(1,5,0,LOG:12)
Block(-4,9,5,Leaves:4)
B(0,11,1,LEAVES:4)
B(1,6,0,LOG:12)
Block(-4,8,5,Leaves:4)
B(1,3,0,Leaves:4)
B(1,4,0,LOG:12)
Block(-4,10,-2,Leaves:4)
B(5,7,4,Leaves:4)
Block(-1,11,-4,LEAVES:4)
Block(-3,6,-2,Leaves:4)
Block(-3,7,-2,Leaves:4)
Block(-2,3,3,Leaves:4)
Block(-2,0,3,LOG:12)
Block(-2,7,3,LOG:12)
Block(-2,6,3,LOG:12)
Block(-2,9,4,Leaves:4)
Block(-2,5,3,Leaves:4)
Block(-2,8,4,Leaves:4)
Block(-2,4,3,Leaves:4)
Block(-2,6,4,Leaves:4)
Block(-2,4,4,Leaves:4)
Block(-2,9,3,Leaves:4)
Block(-2,8,3,Leaves:4)
B(4,9,1,Leaves:4)
B(4,7,1,Leaves:4)
B(4,7,0,Leaves:4)
B(1,6,1,Leaves:4)
B(1,9,1,Leaves:4)
B(0,7,-2,LOG:12)
B(0,9,-2,Leaves:4)
B(0,3,-2,Leaves:4)
B(1,8,0,Leaves:4)
B(0,4,-2,Leaves:4)
B(1,10,-2,Leaves:4)
B(0,6,-2,Leaves:4)
B(1,9,0,Leaves:4)
Block(-6,7,1,LEAVES:4)
B(3,7,4,Leaves:4)
B(3,5,4,Leaves:4)
B(3,9,4,Leaves:4)
B(5,5,3,Leaves:4)
B(5,7,3,Leaves:4)
Block(-4,6,4,Leaves:4)
B(0,2,0,Leaves:4)
B(0,3,0,LOG:8)
B(0,6,0,Leaves:4)
B(0,7,0,Leaves:4)
B(0,4,0,Leaves:4)
B(0,5,0,Leaves:4)
Block(-3,9,-1,Leaves:4)
Block(-4,8,0,Leaves:4)
Block(-4,7,0,Leaves:4)
Block(-4,6,0,Leaves:4)
Block(-3,12,3,LEAVES:4)
Block(-5,10,3,LEAVES:4)
Block(-2,12,5,Leaves:4)
Block(-5,11,3,LEAVES:4)
Block(-3,7,2,Leaves:4)
Block(-3,6,2,Leaves:4)
Block(-3,5,2,Leaves:4)
Block(-3,4,2,Leaves:4)
Block(-3,9,1,Leaves:4)
Block(-3,3,1,Leaves:4)
Block(-3,2,1,Leaves:4)
Block(-3,6,1,Leaves:4)
Block(-3,9,2,Leaves:4)
Block(-3,8,2,Leaves:4)
Block(-2,-3,3,LOG:12)
Block(-2,-1,3,LOG:12)
Block(-6,9,4,LEAVES:4)
Block(-2,10,-4,Leaves:4)
Block(-2,-2,3,LOG:12)
Block(-1,10,3,Leaves:4)
B(2,-1,2,LOG:12)
Block(-6,7,0,LEAVES:4)
B(0,10,-4,Leaves:4)
B(4,9,-1,Leaves:4)
B(4,8,-1,Leaves:4)
Block(-1,8,5,Leaves:4)
Block(-2,6,-2,Leaves:4)
B(0,8,0,Leaves:4)
B(2,9,5,Leaves:4)
B(2,7,4,Leaves:4)
Block(-1,9,5,Leaves:4)
Block(-2,9,-2,Leaves:4)
Block(-2,8,-2,Leaves:4)
B(0,9,1,Leaves:4)
Block(-2,7,2,Leaves:4)
Block(-2,3,2,Leaves:4)
Block(-2,5,1,LOG:12)
Block(-3,11,4,Leaves:4)
Block(-2,4,1,Leaves:4)
Block(-3,10,4,Leaves:4)
Block(-2,9,1,Leaves:4)
Block(-2,8,1,Leaves:4)
Block(-2,7,1,Leaves:4)
Block(-2,6,1,Leaves:4)
Block(-2,9,2,Leaves:4)
Block(-1,10,0,Leaves:4)
Block(-3,-1,3,LOG:12)
B(0,10,-1,Leaves:4)
Block(-4,10,6,Leaves:4)
Block(-3,10,3,Leaves:4)
B(2,11,0,LEAVES:4)
Block(-2,12,3,LEAVES:4)
Block(-2,10,3,Leaves:4)
B(3,10,-3,Leaves:4)
Block(-2,8,-1,Leaves:4)
Block(-2,7,-1,Leaves:4)
Block(-2,5,-1,Leaves:4)
Block(-2,4,-1,Leaves:4)
Block(-2,3,-1,Leaves:4)
B(4,10,1,Leaves:4)
Block(-2,5,-3,Leaves:4)
Block(-1,3,-1,Leaves:4)
Block(-1,6,-1,Leaves:4)
Block(-1,7,-1,Leaves:4)
B(4,10,2,Leaves:4)
Block(-2,8,-4,LOG:12)
Block(-2,9,-4,Leaves:4)
Block(-2,10,4,Leaves:4)
Block(-1,8,-1,Leaves:4)
B(4,11,2,LEAVES:4)
Block(-2,7,-4,Leaves:4)
Block(-1,9,-1,Leaves:4)
Block(-2,8,-3,Leaves:4)

#######################################################################
# +-----------------------------------------------------------------+ #
# |                            BO3 checks                           | #
# +-----------------------------------------------------------------+ #
#######################################################################

BlockCheck(0,-1,0,GRASS,DIRT)

#######################################################################
# +-----------------------------------------------------------------+ #
# |                             Branches                            | #
# +-----------------------------------------------------------------+ #
#######################################################################


#######################################################################
# +-----------------------------------------------------------------+ #
# |                             Entities                            | #
# +-----------------------------------------------------------------+ #
#######################################################################


#######################################################################
# +-----------------------------------------------------------------+ #
# |                            Particles                            | #
# +-----------------------------------------------------------------+ #
#######################################################################


#######################################################################
# +-----------------------------------------------------------------+ #
# |                             Spawners                            | #
# +-----------------------------------------------------------------+ #
#######################################################################


#######################################################################
# +-----------------------------------------------------------------+ #
# |                             ModData                             | #
# +-----------------------------------------------------------------+ #
#######################################################################

