
#######################################################################
# +-----------------------------------------------------------------+ #
# |                            BO3 object                           | #
# +-----------------------------------------------------------------+ #
#######################################################################

Author: NLBlackEagle

Description: Converted version of the BO2 EUR1S

Version: 3

SettingsMode: WriteDisable


#######################################################################
# +-----------------------------------------------------------------+ #
# |                          Main settings                          | #
# +-----------------------------------------------------------------+ #
#######################################################################

Tree: true

Frequency: 1

Rarity: 100.0

RotateRandomly: true

SpawnHeight: highestSolidBlock

SpawnHeightOffset: 0

SpawnHeightVariance: 0

##############################
# Height Limits for the BO3. #
##############################

MinHeight: 0

MaxHeight: 199

######################
# Extrusion settings #
######################

ExtrudeMode: None

ExtrudeThroughBlocks: AIR

MaxBranchDepth: 10

ExcludedBiomes: 


#######################################################################
# +-----------------------------------------------------------------+ #
# |                      Source block settings                      | #
# +-----------------------------------------------------------------+ #
#######################################################################

SourceBlocks: AIR,GRASS,DIRT,SAND

MaxPercentageOutsideSourceBlock: 0

OutsideSourceBlock: placeAnyway

IsOTGPlus: false

InheritBO3: 

InheritBO3Rotation: NORTH

OverrideChildSettings: true

OverrideParentHeight: false

CanOverride: false

BranchFrequency: 0

BranchFrequencyGroup: 

MustBeBelowOther: false

MustBeInside: 

CannotBeInside: 

ReplacesBO3: 

CanSpawnOnWater: true

SpawnOnWaterOnly: false

SpawnUnderWater: false

SpawnAtWaterLevel: false

HeightOffset: 0

RemoveAir: true

ReplaceAbove: 

ReplaceBelow: 

ReplaceWithBiomeBlocks: true

ReplaceWithGroundBlock: DIRT

ReplaceWithSurfaceBlock: GRASS

SmoothRadius: 0

SmoothHeightOffset: 0

SmoothStartTop: false

SmoothStartWood: false

SmoothingSurfaceBlock: 

SmoothingGroundBlock: 

BO3Group: 

IsSpawnPoint: false


#######################################################################
# +-----------------------------------------------------------------+ #
# |                              Blocks                             | #
# +-----------------------------------------------------------------+ #
#######################################################################

B(1,14,1,Leaves:4)
Block(-1,6,3,Leaves:4)
Block(-1,3,3,Leaves:4)
B(2,4,3,Leaves:4)
Block(-1,2,3,Leaves:4)
B(2,4,2,Leaves:4)
B(2,6,2,Leaves:4)
B(1,10,2,Leaves:4)
B(1,10,1,Leaves:4)
B(2,9,2,Leaves:4)
B(1,12,1,LEAVES:4)
B(1,5,1,Leaves:4)
B(3,8,-3,Leaves:4)
B(1,4,1,Leaves:4)
B(1,3,1,Leaves:4)
B(3,5,-3,Leaves:4)
B(1,2,1,Leaves:4)
B(3,3,-3,Leaves:4)
B(3,4,-3,Leaves:4)
B(0,10,-2,Leaves:4)
B(0,5,2,Leaves:4)
B(0,14,-2,LEAVES:4)
Block(-1,1,0,Leaves:4)
Block(-1,3,0,Leaves:4)
B(0,1,2,Leaves:4)
Block(-1,2,0,Leaves:4)
B(3,8,1,Leaves:4)
B(3,5,1,Leaves:4)
B(3,7,1,Leaves:4)
Block(-1,5,0,Leaves:4)
B(3,7,0,Leaves:4)
B(3,8,0,Leaves:4)
Block(-1,7,0,Leaves:4)
Block(-1,8,0,Leaves:4)
B(3,1,0,Leaves:4)
B(6,3,-1,LEAVES:4)
B(0,13,0,LEAVES:4)
B(0,12,0,LEAVES:4)
B(0,11,0,LEAVES:4)
B(1,4,-6,Leaves:4)
B(1,4,-5,Leaves:4)
B(1,3,-5,Leaves:4)
B(0,6,2,Leaves:4)
B(0,7,2,Leaves:4)
B(1,5,-5,Leaves:4)
B(1,11,-3,Leaves:4)
B(1,14,-3,Leaves:4)
B(1,12,-3,LEAVES:4)
Block(-4,5,2,Leaves:4)
B(3,13,-2,Leaves:4)
B(3,14,-2,Leaves:4)
B(5,3,1,Leaves:4)
Block(-1,10,-2,Leaves:4)
B(5,9,1,Leaves:4)
B(5,7,1,Leaves:4)
B(3,4,-2,Leaves:4)
B(4,9,-2,Leaves:4)
B(1,0,-1,LOG:12)
B(3,5,-2,Leaves:4)
B(4,8,-2,Leaves:4)
B(1,3,-1,LOG:12)
B(1,6,-2,Leaves:4)
B(1,7,-2,Leaves:4)
B(3,1,-2,Leaves:4)
B(1,4,-1,LOG:12)
B(1,1,-1,LOG:12)
B(1,2,-1,LOG:12)
B(1,5,-2,Leaves:4)
B(1,7,-1,LOG:12)
B(1,2,-2,LOG:12)
Block(-2,8,0,Leaves:4)
B(1,8,-1,LOG)
B(1,3,-2,Leaves:4)
B(1,5,-1,LOG:12)
Block(-1,12,-2,Leaves:4)
B(1,1,-2,Leaves:4)
B(1,6,-1,LOG:12)
B(3,8,-2,Leaves:4)
Block(-2,3,0,Leaves:4)
B(4,6,-2,Leaves:4)
Block(-2,4,0,Leaves:4)
B(1,9,-1,LOG)
B(4,4,-2,Leaves:4)
B(3,6,-2,Leaves:4)
B(3,7,-2,Leaves:4)
B(4,3,-2,Leaves:4)
B(4,6,-3,Leaves:4)
Block(-2,6,0,Leaves:4)
B(1,1,0,Leaves:4)
B(1,6,-3,Leaves:4)
B(1,5,-3,Leaves:4)
B(3,9,-4,Leaves:4)
B(1,4,-3,Leaves:4)
B(1,3,-3,Leaves:4)
Block(-2,1,0,Leaves:4)
B(1,5,0,Leaves:4)
B(1,6,0,Leaves:4)
B(1,8,-3,Leaves:4)
B(3,5,-4,Leaves:4)
B(3,4,-4,Leaves:4)
B(1,4,0,Leaves:4)
B(1,9,-4,Leaves:4)
B(1,8,-4,Leaves:4)
B(0,3,-6,Leaves:4)
B(1,6,-4,Leaves:4)
B(1,2,-3,LOG:12)
B(1,5,-4,Leaves:4)
B(1,4,-4,Leaves:4)
B(4,3,0,Leaves:4)
B(3,12,0,LEAVES:4)
B(3,10,0,Leaves:4)
Block(-3,8,-2,Leaves:4)
B(3,6,-6,Leaves:4)
B(0,2,1,Leaves:4)
Block(-2,3,4,Leaves:4)
B(3,5,-6,Leaves:4)
B(0,6,1,Leaves:4)
B(3,4,-6,Leaves:4)
B(0,5,1,Leaves:4)
B(3,3,1,Leaves:4)
Block(-5,5,1,Leaves:4)
B(4,5,1,Leaves:4)
B(4,7,0,Leaves:4)
B(4,4,0,Leaves:4)
B(4,5,0,Leaves:4)
B(1,7,1,Leaves:4)
Block(-4,2,-1,Leaves:4)
B(1,6,1,Leaves:4)
B(5,8,0,Leaves:4)
B(1,8,1,Leaves:4)
B(5,5,-3,Leaves:4)
B(0,7,-2,Leaves:4)
B(1,11,-2,Leaves:4)
B(1,14,-2,LEAVES:4)
B(1,13,-2,LEAVES:4)
B(2,4,1,Leaves:4)
B(0,4,-2,Leaves:4)
B(2,2,1,Leaves:4)
B(0,6,-2,Leaves:4)
B(3,11,1,LEAVES:4)
B(1,3,3,Leaves:4)
Block(-4,6,-1,Leaves:4)
B(3,3,2,Leaves:4)
Block(-1,2,2,Leaves:4)
B(2,8,0,Leaves:4)
Block(-1,5,2,Leaves:4)
B(2,6,0,Leaves:4)
B(0,2,0,LOG:12)
B(0,3,0,Leaves:4)
B(2,9,1,Leaves:4)
Block(-1,3,1,Leaves:4)
B(3,14,-1,Leaves:4)
B(0,7,0,Leaves:4)
Block(-1,4,1,Leaves:4)
B(0,7,-5,Leaves:4)
B(0,4,-5,Leaves:4)
Block(-1,5,1,Leaves:4)
B(2,6,1,Leaves:4)
B(0,5,0,Leaves:4)
B(3,10,-1,Leaves:4)
Block(-3,7,-1,Leaves:4)
Block(-4,4,0,Leaves:4)
B(3,11,-1,Leaves:4)
B(0,4,-3,Leaves:4)
Block(-1,2,1,LOG:12)
Block(-4,2,0,Leaves:4)
Block(-1,1,1,Leaves:4)
Block(-4,6,0,Leaves:4)
B(1,9,2,Leaves:4)
Block(-3,4,-1,Leaves:4)
B(0,1,-3,Leaves:4)
B(1,4,3,Leaves:4)
B(1,14,-1,LOG:1)
B(1,15,-1,LEAVES:4)
B(3,2,-5,Leaves:4)
Block(-1,11,1,LEAVES:4)
Block(-1,12,1,LEAVES:4)
B(4,9,2,Leaves:4)
B(4,8,2,Leaves:4)
B(1,11,-1,LOG:1)
B(1,10,-1,LOG:1)
B(1,13,-1,LOG:1)
B(1,12,-1,LOG:1)
B(0,2,-1,Leaves:4)
B(2,10,-3,Leaves:4)
B(0,9,-1,Leaves:4)
B(0,6,-1,Leaves:4)
B(0,5,-1,Leaves:4)
B(0,4,-1,Leaves:4)
B(1,2,2,Leaves:4)
B(1,3,2,Leaves:4)
B(2,15,-1,Leaves:4)
B(4,5,-6,Leaves:4)
Block(-2,2,-2,Leaves:4)
B(5,5,-2,Leaves:4)
B(0,9,0,Leaves:4)
B(3,8,-1,Leaves:4)
B(0,8,0,Leaves:4)
B(3,7,-1,Leaves:4)
B(4,7,-4,Leaves:4)
Block(-2,5,-2,Leaves:4)
B(2,2,0,Leaves:4)
B(3,4,-1,Leaves:4)
B(0,7,1,Leaves:4)
B(2,3,0,Leaves:4)
B(3,3,-1,LOG:12)
Block(-2,9,-2,Leaves:4)
B(4,3,-4,Leaves:4)
B(3,6,-1,Leaves:4)
B(0,9,1,Leaves:4)
Block(-2,8,-2,Leaves:4)
B(3,5,-1,Leaves:4)
B(4,7,-1,Leaves:4)
B(3,2,-1,Leaves:4)
B(5,8,-2,Leaves:4)
B(2,1,0,Leaves:4)
B(4,6,-1,Leaves:4)
Block(-2,8,2,Leaves:4)
Block(-2,7,2,Leaves:4)
Block(-2,5,2,Leaves:4)
B(1,14,0,LEAVES:4)
Block(-1,3,-5,Leaves:4)
Block(-1,2,-5,Leaves:4)
Block(-1,7,-4,Leaves:4)
Block(-1,6,-4,Leaves:4)
Block(-2,5,1,Leaves:4)
B(1,11,0,LEAVES:4)
Block(-1,3,-4,Leaves:4)
Block(-2,3,1,Leaves:4)
Block(-1,2,-4,Leaves:4)
Block(-2,2,1,Leaves:4)
Block(-2,8,1,Leaves:4)
Block(-1,11,-1,LEAVES:4)
Block(-1,8,-3,Leaves:4)
B(0,7,-4,Leaves:4)
Block(-1,5,-2,Leaves:4)
Block(-1,9,-3,Leaves:4)
Block(-1,6,-2,Leaves:4)
Block(-1,3,-2,Leaves:4)
Block(-1,2,-2,Leaves:4)
B(0,2,-4,Leaves:4)
Block(-1,5,-3,Leaves:4)
Block(-1,2,-3,Leaves:4)
Block(-1,8,-2,Leaves:4)
B(0,13,-3,Leaves:4)
Block(-1,14,0,Leaves:4)
Block(-3,3,0,Leaves:4)
Block(-3,2,0,Leaves:4)
B(4,8,3,Leaves:4)
Block(-3,7,0,Leaves:4)
Block(-3,6,0,Leaves:4)
B(0,11,-1,LEAVES:4)
B(4,9,3,Leaves:4)
B(0,13,-1,LEAVES:4)
B(2,6,-6,Leaves:4)
B(2,4,-6,Leaves:4)
B(2,10,-2,Leaves:4)
B(2,12,-2,Leaves:4)
B(2,7,-3,Leaves:4)
B(2,6,-3,Leaves:4)
B(2,13,1,Leaves:4)
B(2,5,-3,Leaves:4)
B(2,4,-3,Leaves:4)
B(2,9,-3,Leaves:4)
B(2,8,-3,Leaves:4)
B(2,8,-4,Leaves:4)
B(2,6,-4,Leaves:4)
B(2,14,1,Leaves:4)
B(2,2,-3,Leaves:4)
B(2,5,-4,Leaves:4)
B(2,1,-3,Leaves:4)
B(2,4,-4,Leaves:4)
B(2,3,-4,Leaves:4)
B(3,10,-3,Leaves:4)
Block(-2,8,-1,Leaves:4)
Block(-2,7,-1,Leaves:4)
Block(-2,6,-1,Leaves:4)
Block(-2,5,-1,Leaves:4)
B(5,8,-1,Leaves:4)
Block(-2,4,-1,Leaves:4)
Block(-2,3,-1,Leaves:4)
Block(-1,2,-1,Leaves:4)
Block(-1,3,-1,Leaves:4)
B(2,3,-1,LOG:12)
Block(-1,7,-1,Leaves:4)
B(2,2,-1,Leaves:4)
Block(-1,4,-1,Leaves:4)
B(2,7,-2,Leaves:4)
B(2,4,-1,Leaves:4)
B(4,10,2,Leaves:4)
Block(-1,8,-1,Leaves:4)
B(2,8,-1,Leaves:4)
B(2,3,-2,Leaves:4)

#######################################################################
# +-----------------------------------------------------------------+ #
# |                            BO3 checks                           | #
# +-----------------------------------------------------------------+ #
#######################################################################

BlockCheck(0,-1,0,GRASS,DIRT)

#######################################################################
# +-----------------------------------------------------------------+ #
# |                             Branches                            | #
# +-----------------------------------------------------------------+ #
#######################################################################


#######################################################################
# +-----------------------------------------------------------------+ #
# |                             Entities                            | #
# +-----------------------------------------------------------------+ #
#######################################################################


#######################################################################
# +-----------------------------------------------------------------+ #
# |                            Particles                            | #
# +-----------------------------------------------------------------+ #
#######################################################################


#######################################################################
# +-----------------------------------------------------------------+ #
# |                             Spawners                            | #
# +-----------------------------------------------------------------+ #
#######################################################################


#######################################################################
# +-----------------------------------------------------------------+ #
# |                             ModData                             | #
# +-----------------------------------------------------------------+ #
#######################################################################

