
#######################################################################
# +-----------------------------------------------------------------+ #
# |                            BO3 object                           | #
# +-----------------------------------------------------------------+ #
#######################################################################

Author: NLBlackEagle

Description: Converted version of the BO2 EUR3L

Version: 3

SettingsMode: WriteDisable


#######################################################################
# +-----------------------------------------------------------------+ #
# |                          Main settings                          | #
# +-----------------------------------------------------------------+ #
#######################################################################

Tree: true

Frequency: 1

Rarity: 100.0

RotateRandomly: true

SpawnHeight: highestSolidBlock

SpawnHeightOffset: 0

SpawnHeightVariance: 0

##############################
# Height Limits for the BO3. #
##############################

MinHeight: 0

MaxHeight: 199

######################
# Extrusion settings #
######################

ExtrudeMode: None

ExtrudeThroughBlocks: AIR

MaxBranchDepth: 10

ExcludedBiomes: 


#######################################################################
# +-----------------------------------------------------------------+ #
# |                      Source block settings                      | #
# +-----------------------------------------------------------------+ #
#######################################################################

SourceBlocks: AIR,GRASS,DIRT,SAND

MaxPercentageOutsideSourceBlock: 0

OutsideSourceBlock: placeAnyway

IsOTGPlus: false

InheritBO3: 

InheritBO3Rotation: NORTH

OverrideChildSettings: true

OverrideParentHeight: false

CanOverride: false

BranchFrequency: 0

BranchFrequencyGroup: 

MustBeBelowOther: false

MustBeInside: 

CannotBeInside: 

ReplacesBO3: 

CanSpawnOnWater: true

SpawnOnWaterOnly: false

SpawnUnderWater: false

SpawnAtWaterLevel: false

HeightOffset: 0

RemoveAir: true

ReplaceAbove: 

ReplaceBelow: 

ReplaceWithBiomeBlocks: true

ReplaceWithGroundBlock: DIRT

ReplaceWithSurfaceBlock: GRASS

SmoothRadius: 0

SmoothHeightOffset: 0

SmoothStartTop: false

SmoothStartWood: false

SmoothingSurfaceBlock: 

SmoothingGroundBlock: 

BO3Group: 

IsSpawnPoint: false


#######################################################################
# +-----------------------------------------------------------------+ #
# |                              Blocks                             | #
# +-----------------------------------------------------------------+ #
#######################################################################

B(1,13,1,Leaves:4)
B(1,14,3,Leaves:4)
B(1,14,1,Leaves:4)
B(2,8,3,Leaves:4)
B(1,17,-4,LOG:14)
B(1,15,1,Leaves:4)
B(1,18,-4,LOG:14)
B(4,11,-5,Leaves:4)
B(1,18,1,Leaves:4)
B(4,12,-5,Leaves:4)
B(1,14,2,LOG:14)
B(2,6,3,Leaves:4)
B(5,20,-5,Leaves:4)
B(1,13,2,LOG:14)
B(1,12,2,LOG:14)
B(1,11,2,Leaves:4)
B(1,10,1,LOG:14)
B(1,15,3,Leaves:4)
B(1,11,1,LOG:14)
Block(-1,9,3,Leaves:4)
B(1,12,1,LOG:14)
B(3,17,-6,Leaves:4)
B(3,9,-3,Leaves:4)
B(4,16,-5,Leaves:4)
B(1,12,-4,Leaves:4)
B(4,15,-5,Leaves:4)
B(4,18,-5,LOG:1)
B(1,10,-4,Leaves:4)
B(4,17,-5,LOG:14)
B(1,16,-4,LOG:14)
B(4,19,-5,Leaves:4)
B(1,15,-4,LOG:14)
B(3,4,-3,Leaves:4)
B(0,10,-2,Leaves:4)
B(0,13,3,Leaves:4)
B(0,14,-2,Leaves:4)
B(0,14,2,Leaves:4)
B(0,13,2,Leaves:4)
B(3,9,1,Leaves:4)
Block(-4,14,1,Leaves:4)
B(3,5,0,Leaves:4)
B(3,13,2,Leaves:4)
Block(-3,15,1,Leaves:4)
B(3,14,2,Leaves:4)
B(0,16,-2,Leaves:4)
Block(-1,8,0,Leaves:4)
B(3,11,2,Leaves:4)
B(0,10,0,LOG:14)
B(3,3,0,Leaves:4)
B(5,16,3,Leaves:4)
Block(-5,9,0,LEAVES:4)
B(0,17,0,Leaves:4)
B(0,16,0,Leaves:4)
B(0,15,0,Leaves:4)
B(0,13,0,Leaves:4)
B(0,12,0,Leaves:4)
B(0,7,2,Leaves:4)
B(7,16,-1,Leaves:4)
B(1,7,-5,Leaves:4)
B(1,11,-3,LOG:14)
B(1,10,-3,Leaves:4)
B(6,13,-3,Leaves:4)
B(1,15,-3,LOG:14)
B(1,14,-3,LOG:14)
B(1,13,-3,LOG:14)
B(1,12,-3,LOG:14)
B(2,16,-4,Leaves:4)
B(3,15,-4,LOG:14)
B(3,11,-4,Leaves:4)
B(3,18,-2,Leaves:4)
B(3,12,-4,Leaves:4)
B(2,10,-4,Leaves:4)
B(3,13,-4,LOG:14)
B(3,14,-4,LOG:14)
Block(-4,6,2,Leaves:4)
B(2,11,-4,LOG:14)
B(2,12,-4,LOG:14)
B(3,13,-2,Leaves:4)
B(3,14,-5,Leaves:4)
B(2,13,-4,LOG:14)
B(2,15,-4,Leaves:4)
B(1,16,-3,Leaves:4)
Block(-5,7,-1,Leaves:4)
Block(-1,12,-5,Leaves:4)
B(1,8,-2,Leaves:4)
Block(-1,18,2,Leaves:4)
Block(-1,17,2,Leaves:4)
B(1,5,-2,Leaves:4)
B(1,8,-1,Leaves:4)
B(1,5,-1,LOG:14)
B(1,6,-1,LOG:14)
Block(-1,18,-2,Leaves:4)
B(4,5,-2,Leaves:4)
B(4,14,-6,Leaves:4)
B(4,6,-3,Leaves:4)
Block(-2,10,-3,Leaves:4)
B(4,18,-6,Leaves:4)
B(1,9,-3,Leaves:4)
B(0,14,1,LOG:14)
B(0,15,1,LOG:14)
B(1,7,-4,Leaves:4)
B(0,12,1,LOG:14)
Block(-4,12,-2,Leaves:4)
B(0,13,1,LOG:14)
B(0,18,1,Leaves:4)
Block(-4,14,-2,Leaves:4)
B(5,7,4,Leaves:4)
B(0,17,1,Leaves:4)
Block(-5,16,-2,Leaves:4)
Block(-2,17,0,Leaves:4)
B(3,15,0,Leaves:4)
B(6,11,-2,Leaves:4)
Block(-2,19,-3,Leaves:4)
Block(-1,11,-4,Leaves:4)
B(3,12,0,Leaves:4)
Block(-2,15,0,Leaves:4)
Block(-2,14,-3,Leaves:4)
Block(-2,8,3,Leaves:4)
B(4,17,0,Leaves:4)
B(2,17,2,Leaves:4)
B(2,16,2,LOG:14)
B(2,15,2,LOG:14)
B(4,12,-2,Leaves:4)
Block(-1,20,-4,Leaves:4)
Block(-3,11,-1,Leaves:4)
B(2,14,2,LOG:14)
B(2,13,2,Leaves:4)
B(5,19,-4,Leaves:4)
Block(-1,15,-4,Leaves:4)
Block(-1,18,-4,Leaves:4)
B(1,16,5,Leaves:4)
B(4,7,1,Leaves:4)
B(4,11,-2,Leaves:4)
B(0,12,-5,Leaves:4)
B(0,17,-5,Leaves:4)
B(5,12,-5,Leaves:4)
B(5,15,-6,Leaves:4)
B(5,4,-3,Leaves:4)
Block(-5,16,-3,LEAVES:4)
B(5,7,-3,Leaves:4)
B(1,12,-2,Leaves:4)
B(1,8,0,LOG:14)
B(0,3,-2,Leaves:4)
B(1,7,0,LOG:14)
Block(-4,12,-4,Leaves:4)
Block(-3,13,-4,Leaves:4)
B(3,6,4,Leaves:4)
B(3,10,1,Leaves:4)
B(5,18,-5,Leaves:4)
B(5,8,2,Leaves:4)
Block(-4,6,-1,Leaves:4)
B(3,7,2,Leaves:4)
B(3,6,3,Leaves:4)
B(3,16,3,Leaves:4)
B(0,5,-3,Leaves:4)
B(3,10,-1,LOG:14)
Block(-1,12,-3,Leaves:4)
B(3,11,-1,Leaves:4)
B(5,19,-2,Leaves:4)
B(5,9,-4,Leaves:4)
Block(-4,8,0,Leaves:4)
Block(-4,6,0,Leaves:4)
B(0,6,-3,Leaves:4)
Block(-4,9,0,Leaves:4)
B(5,12,-2,Leaves:4)
Block(-1,17,1,Leaves:4)
B(0,10,4,Leaves:4)
Block(-1,18,1,Leaves:4)
Block(-1,18,-3,Leaves:4)
B(0,15,4,Leaves:4)
Block(-1,10,1,Leaves:4)
B(0,16,4,Leaves:4)
Block(-1,13,-3,Leaves:4)
B(4,8,2,Leaves:4)
Block(-1,20,-3,Leaves:4)
B(4,18,-7,Leaves:4)
B(2,16,3,Leaves:4)
Block(-4,15,-1,Leaves:4)
B(0,20,-3,Leaves:4)
B(2,15,3,Leaves:4)
B(2,15,-5,Leaves:4)
Block(-5,16,0,Leaves:4)
B(2,10,3,Leaves:4)
B(2,12,-5,Leaves:4)
Block(-1,16,3,Leaves:4)
Block(-2,11,-4,Leaves:4)
B(7,11,-2,Leaves:4)
Block(-6,14,-1,LEAVES:4)
B(2,18,-5,Leaves:4)
B(2,10,-3,LOG:14)
B(2,15,-6,Leaves:4)
B(2,16,-6,Leaves:4)
B(0,9,-1,Leaves:4)
B(2,10,-6,Leaves:4)
B(2,13,-3,Leaves:4)
B(2,12,-3,Leaves:4)
B(2,11,-3,LOG:14)
B(2,13,-6,Leaves:4)
B(4,16,-4,LOG:14)
B(4,17,-4,LOG:14)
B(4,14,-4,Leaves:4)
B(4,15,-4,LOG:14)
Block(-1,18,-6,Leaves:4)
B(4,18,-4,Leaves:4)
B(5,17,-7,Leaves:4)
B(0,16,-4,Leaves:4)
B(2,15,-1,Leaves:4)
B(0,10,-4,Leaves:4)
B(0,13,-4,Leaves:4)
B(4,16,3,Leaves:4)
B(4,8,-1,Leaves:4)
B(5,5,-2,Leaves:4)
B(0,18,-4,Leaves:4)
B(3,8,-1,Leaves:4)
Block(-2,7,-2,Leaves:4)
B(4,5,-4,Leaves:4)
B(0,9,0,LOG:14)
B(4,8,-4,Leaves:4)
B(3,9,-1,LOG:14)
B(2,3,0,Leaves:4)
B(3,6,-1,Leaves:4)
Block(-2,8,-2,Leaves:4)
B(4,13,-4,Leaves:4)
B(4,12,-4,Leaves:4)
B(4,6,-1,Leaves:4)
B(1,16,0,Leaves:4)
Block(-1,9,-4,Leaves:4)
B(2,10,4,Leaves:4)
B(1,10,0,LOG:14)
B(1,11,-6,Leaves:4)
B(1,11,0,Leaves:4)
B(1,12,-6,Leaves:4)
B(1,13,-6,Leaves:4)
Block(-2,6,1,Leaves:4)
Block(-1,11,-1,Leaves:4)
B(1,19,-6,Leaves:4)
Block(-1,9,-3,Leaves:4)
B(0,4,-4,Leaves:4)
B(6,18,-7,Leaves:4)
B(1,11,4,Leaves:4)
Block(-2,11,2,Leaves:4)
Block(-1,4,-3,Leaves:4)
B(0,12,-6,Leaves:4)
B(7,18,-4,Leaves:4)
B(7,17,0,Leaves:4)
B(7,15,0,Leaves:4)
B(5,17,1,Leaves:4)
Block(-3,6,0,Leaves:4)
Block(-1,15,4,Leaves:4)
B(0,10,-1,Leaves:4)
B(0,19,-3,Leaves:4)
B(0,11,-1,Leaves:4)
B(3,15,5,Leaves:4)
Block(-2,13,-1,Leaves:4)
B(2,5,-5,Leaves:4)
B(1,19,-5,Leaves:4)
B(1,18,-5,Leaves:4)
B(2,9,-5,Leaves:4)
B(2,7,-5,Leaves:4)
B(2,7,-3,Leaves:4)
B(2,18,-2,Leaves:4)
B(6,16,-4,Leaves:4)
B(2,10,1,Leaves:4)
B(1,13,-5,Leaves:4)
B(6,19,-4,Leaves:4)
B(1,11,-5,Leaves:4)
B(0,18,-7,Leaves:4)
B(1,17,-5,Leaves:4)
B(2,17,-2,Leaves:4)
B(2,9,-3,LOG:14)
B(2,8,-3,LOG:14)
B(2,3,-3,Leaves:4)
B(2,6,-4,Leaves:4)
B(2,5,-4,Leaves:4)
Block(-2,19,-5,Leaves:4)
Block(-2,14,-5,Leaves:4)
B(3,10,-3,Leaves:4)
B(4,19,-1,Leaves:4)
B(4,16,1,Leaves:4)
B(3,11,-3,Leaves:4)
B(3,12,-3,Leaves:4)
B(4,6,-5,Leaves:4)
B(4,14,1,Leaves:4)
B(4,14,-1,Leaves:4)
B(4,11,1,Leaves:4)
B(4,13,-1,Leaves:4)
B(2,9,-2,Leaves:4)
Block(-2,11,1,Leaves:4)
B(2,1,-1,LOG:14)
Block(-2,10,1,Leaves:4)
B(2,0,-1,LOG:14)
B(2,6,-2,LOG:14)
B(2,2,-1,LOG:14)
B(2,5,-2,LOG:14)
B(2,8,-2,LOG:14)
B(2,7,-2,LOG:14)
B(2,2,-2,Leaves:4)
B(2,6,-1,Leaves:4)
B(2,9,-1,Leaves:4)
B(2,4,-2,LOG:14)
Block(-2,17,1,Leaves:4)
B(2,3,-2,LOG:14)
B(3,19,-3,Leaves:4)
B(4,16,2,Leaves:4)
B(4,16,4,Leaves:4)

#######################################################################
# +-----------------------------------------------------------------+ #
# |                            BO3 checks                           | #
# +-----------------------------------------------------------------+ #
#######################################################################

BlockCheck(0,-1,0,GRASS,DIRT)

#######################################################################
# +-----------------------------------------------------------------+ #
# |                             Branches                            | #
# +-----------------------------------------------------------------+ #
#######################################################################


#######################################################################
# +-----------------------------------------------------------------+ #
# |                             Entities                            | #
# +-----------------------------------------------------------------+ #
#######################################################################


#######################################################################
# +-----------------------------------------------------------------+ #
# |                            Particles                            | #
# +-----------------------------------------------------------------+ #
#######################################################################


#######################################################################
# +-----------------------------------------------------------------+ #
# |                             Spawners                            | #
# +-----------------------------------------------------------------+ #
#######################################################################


#######################################################################
# +-----------------------------------------------------------------+ #
# |                             ModData                             | #
# +-----------------------------------------------------------------+ #
#######################################################################

