
#######################################################################
# +-----------------------------------------------------------------+ #
# |                            BO3 object                           | #
# +-----------------------------------------------------------------+ #
#######################################################################

Author: NLBlackEagle

Description: Converted version of the BO2 EUR6L

Version: 3

SettingsMode: WriteDisable


#######################################################################
# +-----------------------------------------------------------------+ #
# |                          Main settings                          | #
# +-----------------------------------------------------------------+ #
#######################################################################

Tree: true

Frequency: 1

Rarity: 100.0

RotateRandomly: true

SpawnHeight: highestSolidBlock

SpawnHeightOffset: 0

SpawnHeightVariance: 0

##############################
# Height Limits for the BO3. #
##############################

MinHeight: 0

MaxHeight: 199

######################
# Extrusion settings #
######################

ExtrudeMode: None

ExtrudeThroughBlocks: AIR

MaxBranchDepth: 10

ExcludedBiomes: 


#######################################################################
# +-----------------------------------------------------------------+ #
# |                      Source block settings                      | #
# +-----------------------------------------------------------------+ #
#######################################################################

SourceBlocks: AIR,GRASS,DIRT,SAND

MaxPercentageOutsideSourceBlock: 0

OutsideSourceBlock: placeAnyway

IsOTGPlus: false

InheritBO3: 

InheritBO3Rotation: NORTH

OverrideChildSettings: true

OverrideParentHeight: false

CanOverride: false

BranchFrequency: 0

BranchFrequencyGroup: 

MustBeBelowOther: false

MustBeInside: 

CannotBeInside: 

ReplacesBO3: 

CanSpawnOnWater: true

SpawnOnWaterOnly: false

SpawnUnderWater: false

SpawnAtWaterLevel: false

HeightOffset: 0

RemoveAir: true

ReplaceAbove: 

ReplaceBelow: 

ReplaceWithBiomeBlocks: true

ReplaceWithGroundBlock: DIRT

ReplaceWithSurfaceBlock: GRASS

SmoothRadius: 0

SmoothHeightOffset: 0

SmoothStartTop: false

SmoothStartWood: false

SmoothingSurfaceBlock: 

SmoothingGroundBlock: 

BO3Group: 

IsSpawnPoint: false


#######################################################################
# +-----------------------------------------------------------------+ #
# |                              Blocks                             | #
# +-----------------------------------------------------------------+ #
#######################################################################

B(0,20,-2,LOG:1)
Block(-1,9,4,LEAVES:4)
B(0,21,-2,Leaves:4)
B(4,10,-5,LEAVES:4)
B(0,21,2,Leaves:4)
Block(-7,8,4,LEAVES:4)
B(0,20,2,LOG:1)
Block(-7,6,4,LEAVES:4)
B(2,8,2,Leaves:4)
Block(-7,4,4,LEAVES:4)
Block(-1,6,4,Leaves:4)
B(1,9,5,LEAVES:4)
Block(-3,21,1,Leaves:4)
Block(-3,20,1,Leaves:4)
B(0,5,2,Leaves:4)
B(0,18,2,Leaves:4)
B(0,17,2,Leaves:4)
Block(-1,1,0,LOG:13)
B(0,16,2,Leaves:4)
Block(-3,3,4,Leaves:4)
Block(-1,0,0,LOG:13)
B(0,12,-2,LEAVES:4)
Block(-3,4,4,Leaves:4)
Block(-1,2,0,LOG:13)
B(0,0,2,LOG:13)
Block(-2,-1,0,LOG:13)
B(0,13,-2,LOG:13)
Block(-2,-2,0,LOG:13)
Block(-3,6,4,LOG:13)
Block(-3,7,4,Leaves:4)
Block(-3,9,4,LEAVES:4)
B(3,7,1,Leaves:4)
B(0,19,-2,LOG:1)
B(8,15,-4,LEAVES:4)
Block(-3,15,1,Leaves:4)
Block(-1,8,0,Leaves:4)
Block(-3,12,1,LEAVES:4)
Block(-3,10,1,LEAVES:4)
B(1,9,-5,LEAVES:4)
Block(-7,6,8,LEAVES:4)
B(3,21,-2,Leaves:4)
B(3,26,-2,Leaves:4)
B(3,25,-2,Leaves:4)
B(0,9,2,LEAVES:4)
B(0,7,2,Leaves:4)
B(1,6,-5,Leaves:4)
B(0,7,6,LEAVES:4)
B(3,17,-2,Leaves:4)
B(3,18,-2,Leaves:4)
B(3,19,-2,Leaves:4)
B(3,13,-2,Leaves:4)
B(3,15,-5,Leaves:4)
B(3,14,-2,Leaves:4)
B(3,15,-2,Leaves:4)
B(5,7,1,LEAVES:4)
B(4,8,-2,Leaves:4)
Block(-4,5,9,LEAVES:4)
B(1,6,-2,Leaves:4)
B(1,4,-2,LOG:13)
B(4,6,-2,Leaves:4)
B(4,3,-2,Leaves:4)
Block(-2,23,0,Leaves:4)
Block(-5,6,8,LEAVES:4)
B(3,15,0,Leaves:4)
B(5,22,2,Leaves:4)
B(0,-1,2,LOG:13)
B(3,12,0,LOG:13)
Block(-2,12,0,LEAVES:4)
B(0,-2,2,LOG:13)
B(3,13,0,LOG:13)
B(0,21,-5,Leaves:4)
B(3,18,4,LEAVES:4)
B(3,17,4,LEAVES:4)
B(5,20,2,Leaves:4)
B(0,23,-5,Leaves:4)
Block(-3,18,-1,Leaves:4)
Block(-3,17,-1,Leaves:4)
Block(-3,19,-1,Leaves:4)
Block(-3,20,-2,Leaves:4)
Block(-3,14,-1,Leaves:4)
Block(-3,15,-1,Leaves:4)
Block(-3,19,-2,Leaves:4)
B(0,10,-5,LEAVES:4)
B(1,13,5,LEAVES:4)
Block(-3,15,-2,Leaves:4)
B(1,18,5,LEAVES:4)
Block(-3,10,-2,LEAVES:4)
B(3,10,6,LEAVES:4)
Block(-5,3,3,Leaves:4)
Block(-6,3,5,LEAVES:4)
Block(-4,3,1,Leaves:4)
Block(-5,9,3,LEAVES:4)
Block(-5,3,5,Leaves:4)
B(1,22,5,LEAVES:4)
B(5,9,-7,LEAVES:4)
Block(-5,4,5,Leaves:4)
B(5,3,-7,LEAVES:4)
Block(-4,4,3,Leaves:4)
Block(-6,2,7,Leaves:4)
Block(-5,2,5,Leaves:4)
Block(-3,21,-2,Leaves:4)
Block(-1,5,2,LOG:13)
Block(-1,9,2,LOG:13)
Block(-9,4,6,LEAVES:4)
B(4,6,8,LEAVES:4)
B(3,8,3,LOG:13)
B(4,5,8,LEAVES:4)
B(2,26,-1,Leaves:4)
B(4,9,8,LEAVES:4)
B(4,8,6,LEAVES:4)
Block(-3,4,6,Leaves:4)
B(4,9,6,LEAVES:4)
Block(-2,24,-2,Leaves:4)
Block(-3,6,6,LEAVES:4)
Block(-2,23,-2,Leaves:4)
Block(-3,7,6,LEAVES:4)
B(2,23,-1,Leaves:4)
Block(-5,13,6,LEAVES:4)
B(1,9,3,LEAVES:4)
B(1,8,3,Leaves:4)
Block(-3,3,6,Leaves:4)
B(4,3,2,Leaves:4)
B(4,6,2,Leaves:4)
Block(-2,20,-2,Leaves:4)
B(4,8,2,Leaves:4)
Block(-2,12,-2,LOG:13)
Block(-7,7,6,LEAVES:4)
Block(-2,11,-2,LOG:13)
Block(-7,5,6,LEAVES:4)
Block(-2,14,-2,Leaves:4)
Block(-7,4,6,LEAVES:4)
Block(-2,13,-2,Leaves:4)
B(4,4,4,Leaves:4)
Block(-2,16,-2,Leaves:4)
B(4,7,4,LOG:13)
B(0,7,-7,LEAVES:4)
Block(-2,19,-2,Leaves:4)
B(9,15,-2,LEAVES:4)
B(2,16,3,LEAVES:4)
B(2,15,3,Leaves:4)
B(2,12,3,LEAVES:4)
Block(-3,12,7,LEAVES:4)
Block(-4,13,3,Leaves:4)
B(6,20,0,LEAVES:4)
Block(-5,20,0,LEAVES:4)
Block(-2,23,-1,Leaves:4)
B(0,1,-1,LOG:13)
B(0,0,-1,LOG:13)
Block(-2,21,-1,Leaves:4)
B(3,21,0,Leaves:4)
B(7,4,5,LEAVES:4)
B(2,-1,1,LOG:13)
B(2,-2,1,LOG:13)
B(7,6,5,LEAVES:4)
B(5,10,2,LEAVES:4)
B(5,12,2,LEAVES:4)
B(5,13,2,LEAVES:4)
B(5,15,2,Leaves:4)
B(0,4,-1,LOG:13)
B(5,17,2,Leaves:4)
B(0,7,4,Leaves:4)
B(6,18,0,LEAVES:4)
B(6,17,0,LEAVES:4)
B(4,13,-3,Leaves:4)
Block(-4,10,3,LEAVES:4)
B(2,10,-1,LEAVES:4)
B(2,0,0,LOG:13)
B(2,5,-7,LEAVES:4)
B(7,15,2,LEAVES:4)
B(7,13,2,LEAVES:4)
Block(-1,19,-1,Leaves:4)
Block(-5,21,2,LEAVES:4)
Block(-1,12,-1,LEAVES:4)
Block(-1,20,-1,Leaves:4)
Block(-1,21,-1,Leaves:4)
Block(-2,18,2,Leaves:4)
Block(-2,12,2,LOG:13)
Block(-2,11,2,LOG:13)
B(6,4,6,LEAVES:4)
B(4,20,-3,Leaves:4)
Block(-2,17,2,Leaves:4)
Block(-2,14,2,Leaves:4)
Block(-2,15,2,Leaves:4)
B(0,-2,-2,LOG:13)
B(2,20,3,LEAVES:4)
B(2,21,3,LEAVES:4)
B(8,7,4,LEAVES:4)
B(2,20,1,LOG:1)
Block(-3,5,0,Leaves:4)
Block(-1,10,-1,LOG:13)
Block(-2,18,-1,Leaves:4)
B(2,23,1,Leaves:4)
Block(-2,14,-1,Leaves:4)
Block(-2,21,2,Leaves:4)
Block(-2,11,-1,LEAVES:4)
B(0,-1,-2,LOG:13)
B(2,3,-5,Leaves:4)
B(2,8,-5,Leaves:4)
B(2,7,-5,Leaves:4)
B(2,19,-2,LOG:1)
B(2,11,1,LEAVES:4)
B(6,8,3,LEAVES:4)
B(2,7,-3,Leaves:4)
B(2,18,-2,Leaves:4)
Block(-2,9,6,LEAVES:4)
B(2,14,-2,Leaves:4)
B(2,8,-3,Leaves:4)
B(2,19,1,LOG:1)
Block(-2,12,-5,LEAVES:4)
Block(-2,14,-5,LEAVES:4)
Block(-1,23,-1,Leaves:4)
B(2,21,-2,LOG:1)
B(2,22,-2,Leaves:4)
Block(-1,24,-1,Leaves:4)
B(2,20,-2,LOG:1)
B(2,26,-2,Leaves:4)
Block(-4,9,-2,LEAVES:4)
B(1,23,-3,Leaves:4)
B(1,19,2,Leaves:4)
B(1,16,2,Leaves:4)
B(3,7,-3,Leaves:4)
B(3,5,-3,Leaves:4)
B(3,9,-3,LEAVES:4)
B(3,4,-3,Leaves:4)
B(3,4,-7,LEAVES:4)
Block(-4,15,0,Leaves:4)
Block(-4,19,2,Leaves:4)
Block(-4,18,2,Leaves:4)
Block(-4,15,2,Leaves:4)
Block(-4,20,2,Leaves:4)
Block(-4,21,2,Leaves:4)
B(5,16,3,Leaves:4)
B(5,11,3,LEAVES:4)
B(0,20,5,LEAVES:4)
B(1,15,-3,Leaves:4)
B(7,4,3,LEAVES:4)
B(0,20,1,LOG:1)
B(5,20,3,LEAVES:4)
B(0,21,1,Leaves:4)
Block(-1,18,2,Leaves:4)
Block(-1,17,2,Leaves:4)
Block(-1,14,2,Leaves:4)
Block(-4,6,7,LEAVES:4)
Block(-1,12,2,LEAVES:4)
Block(-1,19,-2,Leaves:4)
Block(-6,12,-3,LEAVES:4)
Block(-1,10,2,LOG:13)
Block(-1,17,-2,Leaves:4)
Block(-1,16,-2,Leaves:4)
B(1,1,0,LOG:13)
Block(-4,5,5,LOG:13)
B(5,19,5,LEAVES:4)
B(1,0,0,LOG:13)
B(1,5,0,Leaves:4)
B(1,6,0,Leaves:4)
Block(-1,22,-2,Leaves:4)
Block(-1,20,-2,LOG:1)
B(0,12,1,LEAVES:4)
B(0,18,1,LOG:13)
B(0,19,1,LOG:13)
B(0,17,1,Leaves:4)
Block(-1,22,-5,Leaves:4)
Block(-1,20,-5,Leaves:4)
Block(-1,24,-2,Leaves:4)
Block(-1,25,-2,Leaves:4)
Block(-2,6,3,LOG:13)
Block(-2,9,3,LEAVES:4)
Block(-1,19,-5,Leaves:4)
Block(-4,20,-1,Leaves:4)
Block(-1,17,-5,Leaves:4)
B(2,18,2,Leaves:4)
B(2,15,2,Leaves:4)
B(2,10,2,LEAVES:4)
Block(-1,22,-4,Leaves:4)
Block(-1,21,-4,Leaves:4)
Block(-4,22,-4,LEAVES:4)
B(5,15,-1,LOG:13)
B(3,20,1,Leaves:4)
B(5,17,-1,Leaves:4)
B(5,11,-1,LEAVES:4)
B(3,24,1,Leaves:4)
Block(-1,19,-4,Leaves:4)
Block(-5,12,-3,LEAVES:4)
B(1,20,2,Leaves:4)
B(3,9,6,LEAVES:4)
B(1,22,2,Leaves:4)
B(3,7,6,LEAVES:4)
B(1,23,2,Leaves:4)
B(3,8,6,LEAVES:4)
Block(-5,15,-3,LEAVES:4)
Block(-4,19,-4,Leaves:4)
B(1,24,2,Leaves:4)
Block(-6,5,3,LEAVES:4)
B(2,21,2,LOG:1)
B(2,20,2,LOG:1)
B(1,8,0,LOG:13)
B(2,22,2,Leaves:4)
Block(-4,12,-4,LEAVES:4)
B(1,9,0,LOG:13)
B(2,24,2,Leaves:4)
Block(-6,6,1,LEAVES:4)
B(3,7,4,Leaves:4)
B(3,6,4,Leaves:4)
B(3,10,1,LEAVES:4)
B(3,12,1,LEAVES:4)
B(3,18,1,Leaves:4)
Block(-9,4,7,LEAVES:4)
B(3,9,4,LEAVES:4)
B(0,-1,1,LOG:13)
B(5,5,3,Leaves:4)
B(0,2,0,LOG:13)
B(0,3,0,LOG:13)
B(0,0,0,LOG:13)
B(0,1,0,LOG:13)
B(5,6,-6,LEAVES:4)
B(0,6,0,LOG:13)
B(0,7,0,LOG:13)
B(0,4,0,LOG:13)
B(0,5,0,LOG:13)
B(4,20,3,LEAVES:4)
B(5,4,-4,Leaves:4)
B(6,15,-5,LEAVES:4)
B(3,6,-5,LOG:13)
B(3,9,-5,LEAVES:4)
B(5,20,-1,Leaves:4)
B(5,5,7,LEAVES:4)
Block(-4,10,-1,LEAVES:4)
Block(-3,9,1,LEAVES:4)
B(9,14,-1,LEAVES:4)
Block(-4,14,-1,Leaves:4)
Block(-3,3,1,Leaves:4)
B(0,21,-3,Leaves:4)
Block(-4,19,-1,Leaves:4)
Block(-3,8,1,Leaves:4)
B(0,24,-3,Leaves:4)
B(2,19,-5,Leaves:4)
B(4,17,-4,Leaves:4)
B(7,10,3,LEAVES:4)
B(8,15,2,LEAVES:4)
Block(-1,22,2,LOG:1)
B(2,5,4,Leaves:4)
B(4,16,3,Leaves:4)
Block(-1,20,2,LOG:1)
Block(-6,7,9,LEAVES:4)
B(4,14,3,Leaves:4)
Block(-1,21,2,LOG:1)
B(0,9,0,LOG:13)
Block(-1,3,6,Leaves:4)
B(0,8,0,LOG:13)
B(4,12,3,LEAVES:4)
Block(-1,4,6,Leaves:4)
Block(-1,7,6,LEAVES:4)
B(4,13,-4,Leaves:4)
B(7,15,3,LEAVES:4)
Block(-2,15,4,Leaves:4)
Block(-3,10,4,LEAVES:4)
Block(-4,13,-3,Leaves:4)
Block(-5,4,6,LOG:13)
Block(-4,15,-3,Leaves:4)
Block(-2,22,1,Leaves:4)
B(1,10,4,LEAVES:4)
B(5,23,1,Leaves:4)
Block(-2,20,4,LEAVES:4)
B(0,15,-3,LOG:13)
B(0,14,-3,LOG:13)
Block(-1,20,4,Leaves:4)
Block(-1,12,0,LEAVES:4)
B(0,11,-3,LEAVES:4)
Block(-1,15,0,Leaves:4)
Block(-3,21,4,Leaves:4)
Block(-1,16,0,Leaves:4)
B(0,17,5,Leaves:4)
B(5,19,1,Leaves:4)
Block(-3,14,4,LOG:13)
Block(-3,15,4,Leaves:4)
Block(-1,16,4,Leaves:4)
Block(-1,17,4,Leaves:4)
Block(-1,18,4,LEAVES:4)
Block(-1,24,0,Leaves:4)
Block(-1,22,0,Leaves:4)
Block(-1,23,0,Leaves:4)
Block(-1,20,0,Leaves:4)
B(6,11,-1,LEAVES:4)
B(2,11,6,LEAVES:4)
B(6,13,-1,LEAVES:4)
B(6,16,-1,LEAVES:4)
B(2,10,6,LEAVES:4)
Block(-1,24,4,LEAVES:4)
Block(-1,22,4,Leaves:4)
Block(-1,18,6,LEAVES:4)
B(4,4,-5,Leaves:4)
B(4,7,-5,Leaves:4)
B(4,9,-5,LEAVES:4)
B(2,22,6,LEAVES:4)
Block(-2,14,1,Leaves:4)
Block(-2,13,1,Leaves:4)
Block(-1,20,6,LEAVES:4)
Block(-1,21,6,LEAVES:4)
B(1,20,4,LEAVES:4)
B(1,21,4,LEAVES:4)
B(2,7,3,Leaves:4)
B(2,8,3,LOG:13)
B(1,17,-4,Leaves:4)
B(6,6,-8,LEAVES:4)
B(2,5,3,Leaves:4)
Block(-4,10,1,LEAVES:4)
B(1,4,4,Leaves:4)
Block(-3,20,0,Leaves:4)
B(1,6,4,Leaves:4)
Block(-3,21,0,Leaves:4)
B(1,7,4,Leaves:4)
Block(-1,6,8,LEAVES:4)
B(0,21,6,LEAVES:4)
B(1,9,4,LEAVES:4)
Block(-3,17,2,Leaves:4)
Block(-5,6,9,LEAVES:4)
Block(-5,4,9,Leaves:4)
Block(-5,12,1,LEAVES:4)
Block(-5,13,1,LEAVES:4)
Block(-4,20,1,Leaves:4)
Block(-3,19,2,Leaves:4)
Block(-4,12,1,LEAVES:4)
B(3,16,2,Leaves:4)
B(3,18,2,Leaves:4)
B(3,12,2,LEAVES:4)
B(3,13,2,Leaves:4)
B(1,20,-4,Leaves:4)
B(3,8,0,Leaves:4)
B(1,24,-4,Leaves:4)
Block(-5,6,7,LEAVES:4)
B(0,10,0,LOG:13)
Block(-1,12,5,LEAVES:4)
Block(-1,17,5,Leaves:4)
Block(-3,13,-3,LOG:13)
Block(-3,14,-3,LOG:13)
B(0,17,0,LOG:13)
Block(-5,6,0,Leaves:4)
B(0,16,0,LOG:13)
B(0,15,0,LOG:13)
B(0,14,0,LOG:13)
B(0,13,0,LOG:13)
B(0,12,0,LOG:13)
B(0,11,0,LOG:13)
B(1,7,-6,LEAVES:4)
B(0,7,3,Leaves:4)
B(0,8,3,Leaves:4)
B(3,22,2,Leaves:4)
B(3,20,2,Leaves:4)
Block(-1,20,5,Leaves:4)
B(3,23,2,Leaves:4)
B(0,8,7,LEAVES:4)
B(0,20,0,Leaves:4)
B(2,-3,0,LOG:13)
B(2,-2,0,LOG:13)
B(2,-1,0,LOG:13)
Block(-4,5,2,Leaves:4)
Block(-5,7,4,LEAVES:4)
B(0,19,0,Leaves:4)
Block(-5,6,4,Leaves:4)
Block(-5,3,4,Leaves:4)
Block(-6,4,6,LEAVES:4)
Block(-6,7,6,LEAVES:4)
Block(-6,5,6,LEAVES:4)
Block(-3,9,7,LEAVES:4)
B(4,7,5,Leaves:4)
Block(-3,10,-4,LEAVES:4)
Block(-7,2,5,Leaves:4)
B(1,6,-1,Leaves:4)
B(5,8,8,LEAVES:4)
B(1,4,-3,LOG:13)
B(4,22,0,Leaves:4)
Block(-7,7,3,LEAVES:4)
B(6,10,4,LEAVES:4)
Block(-3,4,5,Leaves:4)
Block(-3,3,5,Leaves:4)
Block(-7,4,7,LEAVES:4)
Block(-2,17,-3,Leaves:4)
Block(-2,12,-3,LEAVES:4)
Block(-2,15,-3,Leaves:4)
B(4,14,0,LOG:13)
B(8,17,-1,LEAVES:4)
Block(-3,7,3,Leaves:4)
Block(-3,9,3,LEAVES:4)
B(0,0,1,LOG:13)
B(0,2,1,LOG:13)
B(0,1,1,LOG:13)
Block(-3,6,3,Leaves:4)
B(0,4,1,LOG:13)
B(0,3,1,LOG:13)
B(4,16,0,Leaves:4)
B(0,6,1,LOG:13)
B(8,14,-1,LEAVES:4)
B(4,17,0,Leaves:4)
B(0,5,1,LOG:13)
Block(-4,13,4,Leaves:4)
Block(-4,10,4,LEAVES:4)
Block(-4,11,4,LEAVES:4)
B(5,14,-4,LEAVES:4)
B(5,16,-4,Leaves:4)
B(5,15,-4,Leaves:4)
Block(-2,23,-3,Leaves:4)
B(3,7,-9,LEAVES:4)
B(3,8,-9,LEAVES:4)
Block(-1,-1,0,LOG:13)
B(3,4,-9,LEAVES:4)
Block(-4,11,5,LEAVES:4)
Block(-4,15,5,Leaves:4)
B(2,0,1,LOG:13)
B(7,7,-6,LEAVES:4)
Block(-3,21,-4,Leaves:4)
B(6,15,1,LOG:13)
Block(-3,12,0,LEAVES:4)
B(5,7,2,LEAVES:4)
B(5,4,-8,LEAVES:4)
B(5,6,-8,LEAVES:4)
B(7,6,-4,LEAVES:4)
Block(-3,17,0,Leaves:4)
B(3,5,2,Leaves:4)
B(6,5,7,LEAVES:4)
B(0,20,4,Leaves:4)
B(0,22,4,Leaves:4)
B(3,10,3,LEAVES:4)
Block(-1,7,1,Leaves:4)
Block(-1,21,1,Leaves:4)
Block(-1,8,1,LOG:13)
Block(-1,22,1,Leaves:4)
B(3,12,3,LEAVES:4)
B(3,17,-1,Leaves:4)
B(1,-2,0,LOG:13)
Block(-1,20,1,Leaves:4)
B(1,-1,0,LOG:13)
B(2,7,1,Leaves:4)
Block(-1,6,1,Leaves:4)
Block(-1,0,1,LOG:13)
B(3,11,-1,LEAVES:4)
B(1,7,2,LOG:13)
B(1,19,-1,Leaves:4)
B(0,13,4,Leaves:4)
B(1,15,-1,LOG:13)
B(0,11,4,LEAVES:4)
B(1,7,6,LEAVES:4)
B(1,16,-1,LOG:13)
B(1,17,-1,Leaves:4)
B(3,23,3,LEAVES:4)
Block(-1,16,-3,Leaves:4)
Block(-1,21,-3,LOG:1)
Block(-1,20,-3,LOG:1)
Block(-1,23,-3,Leaves:4)
B(5,15,0,LOG:13)
B(5,18,0,Leaves:4)
B(2,18,-3,Leaves:4)
B(5,23,0,Leaves:4)
B(6,7,4,LEAVES:4)
B(5,22,0,Leaves:4)
B(5,20,0,Leaves:4)
B(6,3,4,Leaves:4)
Block(-2,3,7,LEAVES:4)
B(6,4,4,Leaves:4)
Block(-2,2,7,Leaves:4)
B(0,7,5,Leaves:4)
B(6,7,0,LEAVES:4)
B(0,6,5,Leaves:4)
Block(-9,5,7,LEAVES:4)
B(3,8,-1,Leaves:4)
B(5,11,4,LEAVES:4)
Block(-5,9,2,LEAVES:4)
B(1,18,0,Leaves:4)
B(4,4,7,LEAVES:4)
B(2,14,4,Leaves:4)
B(2,16,4,LEAVES:4)
B(1,12,0,LEAVES:4)
B(4,25,-1,Leaves:4)
Block(-2,16,6,LEAVES:4)
Block(-1,4,-5,Leaves:4)
B(4,7,7,LEAVES:4)
B(2,18,4,LEAVES:4)
B(0,5,-4,Leaves:4)
B(4,20,-1,Leaves:4)
B(2,24,4,LEAVES:4)
Block(-1,-1,1,LOG:13)
B(2,20,4,LEAVES:4)
Block(-1,-3,1,LOG:13)
B(7,13,0,LEAVES:4)
Block(-1,-2,1,LOG:13)
B(7,12,0,LEAVES:4)
B(7,17,0,LEAVES:4)
B(4,6,3,Leaves:4)
B(4,7,3,Leaves:4)
B(4,9,3,LEAVES:4)
B(6,10,3,LEAVES:4)
B(2,6,-6,LEAVES:4)
B(2,3,-6,Leaves:4)
B(4,20,4,LEAVES:4)
B(7,8,4,LEAVES:4)
B(0,-1,0,LOG:13)
B(6,17,-4,LEAVES:4)
Block(-8,2,6,Leaves:4)
B(6,13,-4,LEAVES:4)
B(2,5,-4,LOG:13)
B(6,15,3,LEAVES:4)
B(4,10,4,LEAVES:4)
B(4,15,-1,Leaves:4)
B(4,12,-1,LEAVES:4)
B(1,20,0,Leaves:4)
B(5,6,-1,LEAVES:4)
B(3,20,-1,Leaves:4)
B(1,13,1,Leaves:4)
B(1,12,3,LEAVES:4)
B(1,19,1,LOG:13)
B(8,17,1,LEAVES:4)
Block(-3,20,-6,Leaves:4)
B(6,4,5,Leaves:4)
B(0,12,3,LEAVES:4)
B(0,10,3,LEAVES:4)
B(1,20,3,Leaves:4)
B(0,16,3,Leaves:4)
B(1,21,1,Leaves:4)
B(0,20,3,Leaves:4)
B(0,22,3,Leaves:4)
Block(-5,13,4,LEAVES:4)
B(2,25,-4,Leaves:4)
Block(-2,13,7,LEAVES:4)
B(6,13,-3,LEAVES:4)
Block(-6,3,2,Leaves:4)
B(8,14,0,LEAVES:4)
B(8,13,0,LEAVES:4)
Block(-5,15,4,LEAVES:4)
B(2,19,-4,Leaves:4)
B(2,18,-4,Leaves:4)
Block(-5,20,4,LEAVES:4)
B(2,12,-4,LEAVES:4)
B(2,15,-4,Leaves:4)
B(2,20,-3,LEAVES:4)
B(3,5,-2,Leaves:4)
B(2,21,-3,LOG:1)
Block(-5,9,-2,LEAVES:4)
B(3,3,-2,Leaves:4)
B(5,8,6,LEAVES:4)
B(5,6,6,LEAVES:4)
B(2,22,-3,LOG:1)
B(2,23,-3,LOG:1)
Block(-5,10,-4,LEAVES:4)
Block(-2,7,0,Leaves:4)
Block(-5,12,-4,LEAVES:4)
B(3,6,-2,Leaves:4)
Block(-2,0,0,LOG:13)
B(5,6,4,LEAVES:4)
Block(-4,19,-2,Leaves:4)
B(3,2,-4,Leaves:4)
Block(-4,13,-2,Leaves:4)
B(9,15,0,LEAVES:4)
Block(-4,14,-2,Leaves:4)
Block(-3,9,-2,LEAVES:4)
B(3,3,-8,LEAVES:4)
Block(-5,20,-1,LEAVES:4)
B(5,23,-3,Leaves:4)
Block(-2,9,4,LEAVES:4)
B(2,10,5,LEAVES:4)
Block(-2,6,4,Leaves:4)
Block(-2,4,4,Leaves:4)
B(3,8,-8,LEAVES:4)
Block(-5,12,-1,LEAVES:4)
B(4,13,-2,Leaves:4)
Block(-5,11,-1,LEAVES:4)
B(1,20,-2,Leaves:4)
B(5,14,-3,LEAVES:4)
B(5,15,-3,Leaves:4)
B(5,11,-3,LEAVES:4)
B(4,8,0,Leaves:4)
B(4,7,0,Leaves:4)
B(1,7,1,Leaves:4)
B(1,21,-1,Leaves:4)
B(0,0,-2,LOG:13)
B(1,23,-1,Leaves:4)
B(4,26,-2,Leaves:4)
B(1,11,-2,LEAVES:4)
B(1,14,-2,Leaves:4)
B(0,6,-2,Leaves:4)
B(1,19,-2,LOG:13)
Block(-3,11,-6,LEAVES:4)
B(4,21,-2,Leaves:4)
Block(-1,24,-3,Leaves:4)
B(1,17,-2,LOG:13)
B(1,18,-2,LOG:13)
B(5,15,-5,Leaves:4)
Block(-4,8,4,Leaves:4)
Block(-4,3,4,Leaves:4)
Block(-2,18,5,Leaves:4)
Block(-4,4,4,Leaves:4)
Block(-2,17,5,Leaves:4)
Block(-2,13,5,LEAVES:4)
Block(-2,21,5,Leaves:4)
Block(-3,12,3,LEAVES:4)
B(0,-1,-1,LOG:13)
B(0,-2,-1,LOG:13)
B(0,-3,-1,LOG:13)
Block(-2,11,5,LEAVES:4)
Block(-4,6,8,LEAVES:4)
Block(-4,5,8,LEAVES:4)
B(0,13,7,LEAVES:4)
Block(-5,12,3,LEAVES:4)
Block(-2,10,5,LEAVES:4)
Block(-3,6,2,Leaves:4)
Block(-3,5,2,Leaves:4)
Block(-3,4,2,Leaves:4)
Block(-3,3,2,Leaves:4)
Block(-5,16,3,LEAVES:4)
Block(-6,7,4,LEAVES:4)
Block(-6,8,4,LEAVES:4)
Block(-1,16,3,Leaves:4)
Block(-1,15,3,Leaves:4)
Block(-1,10,3,LEAVES:4)
Block(-1,18,-6,Leaves:4)
B(0,16,-4,LOG:13)
Block(-1,7,5,Leaves:4)
Block(-1,21,3,Leaves:4)
B(2,9,5,LEAVES:4)
Block(-1,24,3,LEAVES:4)
B(4,4,-4,Leaves:4)
Block(-1,5,5,Leaves:4)
B(2,6,5,Leaves:4)
Block(-2,8,2,Leaves:4)
B(3,20,-3,Leaves:4)
Block(-2,9,2,LEAVES:4)
B(5,8,-5,LEAVES:4)
B(3,25,-3,Leaves:4)
Block(-2,14,-4,Leaves:4)
Block(-2,16,-4,Leaves:4)
B(0,18,-1,Leaves:4)
Block(-2,17,-4,Leaves:4)
B(0,19,-1,Leaves:4)
B(0,12,-1,LOG:13)
Block(-2,21,-4,Leaves:4)
Block(-2,20,3,Leaves:4)
B(1,19,-5,Leaves:4)
B(1,12,-5,LEAVES:4)
Block(-3,11,3,LEAVES:4)
B(2,19,0,Leaves:4)
Block(-2,16,3,Leaves:4)
B(2,11,0,LOG:13)
B(0,20,-1,Leaves:4)
Block(-2,13,3,LOG:13)
B(0,21,-1,Leaves:4)
B(2,10,0,LOG:13)
Block(-6,10,-2,LEAVES:4)
B(3,10,-3,LEAVES:4)
B(4,17,1,Leaves:4)
Block(-6,13,-2,LEAVES:4)
Block(-6,11,-2,LEAVES:4)
B(4,13,1,Leaves:4)
Block(-2,8,-4,Leaves:4)
B(3,15,-3,Leaves:4)
B(4,12,2,LEAVES:4)
Block(-1,9,-1,LOG:13)
B(3,19,-3,Leaves:4)
B(2,20,0,Leaves:4)

#######################################################################
# +-----------------------------------------------------------------+ #
# |                            BO3 checks                           | #
# +-----------------------------------------------------------------+ #
#######################################################################

BlockCheck(0,-1,0,GRASS,DIRT)

#######################################################################
# +-----------------------------------------------------------------+ #
# |                             Branches                            | #
# +-----------------------------------------------------------------+ #
#######################################################################


#######################################################################
# +-----------------------------------------------------------------+ #
# |                             Entities                            | #
# +-----------------------------------------------------------------+ #
#######################################################################


#######################################################################
# +-----------------------------------------------------------------+ #
# |                            Particles                            | #
# +-----------------------------------------------------------------+ #
#######################################################################


#######################################################################
# +-----------------------------------------------------------------+ #
# |                             Spawners                            | #
# +-----------------------------------------------------------------+ #
#######################################################################


#######################################################################
# +-----------------------------------------------------------------+ #
# |                             ModData                             | #
# +-----------------------------------------------------------------+ #
#######################################################################

