#######################################################################
# +-----------------------------------------------------------------+ #
# |                            BO3 object                           | #
# +-----------------------------------------------------------------+ #
#######################################################################

Author: Bo3 BulkEdit

Description: Converted Schematic - Modified by Bo3BulkEdit

Version: 3

SettingsMode: WriteDisable

#######################################################################
# +-----------------------------------------------------------------+ #
# |                          Main settings                          | #
# +-----------------------------------------------------------------+ #
#######################################################################

IsOTGPlus: false
Tree: true
Frequency: 1
Rarity: 100
RotateRandomly: true
SpawnHeight: randomY
SpawnHeightOffset: 0
SpawnHeightVariance: 0
MaxBranchDepth: 10
ExcludedBiomes: All

##############################
# Height Limits for the BO3. #
##############################

MinHeight: 0
MaxHeight: 20

#######################################################################
# +-----------------------------------------------------------------+ #
# |                      Source block settings                      | #
# +-----------------------------------------------------------------+ #
#######################################################################

SourceBlocks: AIR,GRASS,DIRT,STONE,WATER
MaxPercentageOutsideSourceBlock: 0
OutsideSourceBlock: placeAnyway

ReplaceBelow: STONE
ReplaceWithBiomeBlocks: true
ReplaceWithGroundBlock: DIRT
ReplaceWithSurfaceBlock: GRASS
ReplaceWithStoneBlock: STONE
SmoothRadius: 0
SmoothHeightOffset: 0

#######################################################################
# +-----------------------------------------------------------------+ #
# |                              Blocks                             | #
# +-----------------------------------------------------------------+ #
#######################################################################

Block(0,-2,0,LOG:13)
Block(0,-1,0,LOG:13)
Block(0,1,-1,LOG:13)
Block(1,1,-1,SPRUCE_STAIRS:1)
Block(0,1,0,PLANKS:5)
Block(1,1,0,PLANKS:5)
Block(0,2,-1,WOODEN_SLAB:1)
Block(1,2,-1,WOODEN_SLAB:1)
Block(0,2,0,PLANKS:5)
Block(1,2,0,LOG:13)
Block(0,3,0,SPRUCE_STAIRS)
Block(1,3,0,WOODEN_SLAB:9)
Block(0,4,0,LOG:13)
Block(1,4,0,WOODEN_SLAB:1)
Block(0,5,0,LOG:13)
Block(0,6,0,PLANKS:5)
Block(0,7,0,LOG:13)
Block(0,8,0,LOG:13)
Block(-1,9,0,WOODEN_SLAB:9)
Block(0,9,0,SPRUCE_STAIRS:2)
Block(-1,10,0,WOODEN_SLAB:1)
Block(0,10,0,PLANKS:5)
Block(0,11,0,LOG:13)
Block(0,12,0,PLANKS:5)
Block(0,13,0,PLANKS:5)
Block(0,13,1,PLANKS:5)
Block(3,14,-3,STAINED_GLASS_PANE)
Block(1,14,-1,SPRUCE_STAIRS:6)
Block(0,14,0,LOG:13)
Block(1,14,0,PLANKS:5)
Block(0,14,1,PLANKS:5)
Block(1,15,-3,STAINED_GLASS_PANE)
Block(2,15,-3,WOODEN_BUTTON:4)
Block(3,15,-3,STAINED_GLASS_PANE)
Block(1,15,-2,WOODEN_BUTTON:4)
Block(2,15,-2,WOODEN_SLAB:9)
Block(3,15,-2,WOODEN_BUTTON:1)
Block(0,15,-1,WOODEN_BUTTON:2)
Block(1,15,-1,PLANKS:5)
Block(2,15,-1,PLANKS:5)
Block(3,15,-1,WOODEN_BUTTON:1)
Block(0,15,0,LOG:13)
Block(1,15,0,WOODEN_SLAB:1)
Block(2,15,0,WOODEN_BUTTON:1)
Block(-2,15,1,LOG:13)
Block(-1,15,1,LOG:13)
Block(0,15,1,LOG:13)
Block(1,15,1,WOODEN_BUTTON:3)
Block(-5,15,2,STAINED_GLASS_PANE)
Block(-2,15,2,LOG:13)
Block(1,16,-3,STAINED_GLASS_PANE)
Block(2,16,-3,STAINED_GLASS_PANE)
Block(3,16,-3,STAINED_GLASS_PANE)
Block(2,16,-2,PLANKS:5)
Block(-1,16,0,WOODEN_SLAB:9)
Block(0,16,0,PLANKS:5)
Block(-5,16,2,STAINED_GLASS_PANE)
Block(-3,16,2,LOG:13)
Block(-2,16,2,LOG:13)
Block(1,17,-3,STAINED_GLASS_PANE)
Block(2,17,-3,LEAVES:8)
Block(3,17,-3,STAINED_GLASS_PANE)
Block(1,17,-2,LEAVES:8)
Block(2,17,-2,PLANKS:5)
Block(3,17,-2,LEAVES:8)
Block(2,17,-1,LEAVES:8)
Block(-1,17,0,WOODEN_SLAB:1)
Block(0,17,0,SPRUCE_STAIRS:5)
Block(-5,17,2,STAINED_GLASS_PANE)
Block(-3,17,2,LOG:13)
Block(1,18,-3,LEAVES:8)
Block(2,18,-3,SEA_LANTERN)
Block(3,18,-3,LEAVES:8)
Block(1,18,-2,SEA_LANTERN)
Block(2,18,-2,LOG:13)
Block(3,18,-2,SEA_LANTERN)
Block(-1,18,-1,WOODEN_BUTTON:4)
Block(0,18,-1,WOODEN_BUTTON:4)
Block(1,18,-1,LEAVES:8)
Block(2,18,-1,SEA_LANTERN)
Block(3,18,-1,LEAVES:8)
Block(-2,18,0,WOODEN_BUTTON:2)
Block(-1,18,0,PLANKS:5)
Block(0,18,0,SPRUCE_STAIRS:1)
Block(1,18,0,WOODEN_BUTTON:1)
Block(-5,18,1,STAINED_GLASS_PANE)
Block(-3,18,1,LEAVES:8)
Block(-1,18,1,WOODEN_BUTTON:3)
Block(0,18,1,WOODEN_BUTTON:3)
Block(-5,18,2,STAINED_GLASS_PANE)
Block(-4,18,2,LEAVES:8)
Block(-3,18,2,LOG:13)
Block(-2,18,2,LEAVES:8)
Block(-3,18,3,LEAVES:8)
Block(2,19,-3,LEAVES:8)
Block(1,19,-2,LEAVES:8)
Block(2,19,-2,SEA_LANTERN)
Block(3,19,-2,LEAVES:8)
Block(2,19,-1,LEAVES:8)
Block(-1,19,0,LOG:13)
Block(-5,19,1,STAINED_GLASS_PANE)
Block(-4,19,1,LEAVES:8)
Block(-3,19,1,SEA_LANTERN)
Block(-2,19,1,LEAVES:8)
Block(-5,19,2,STAINED_GLASS_PANE)
Block(-4,19,2,SEA_LANTERN)
Block(-3,19,2,LOG:13)
Block(-2,19,2,SEA_LANTERN)
Block(-4,19,3,LEAVES:8)
Block(-3,19,3,SEA_LANTERN)
Block(-2,19,3,LEAVES:8)
Block(-1,20,0,LOG:13)
Block(-3,20,1,LEAVES:8)
Block(-4,20,2,LEAVES:8)
Block(-3,20,2,SEA_LANTERN)
Block(-2,20,2,LEAVES:8)
Block(-3,20,3,LEAVES:8)
Block(2,21,-2,STAINED_GLASS_PANE)
Block(-1,21,0,LOG:13)
Block(0,22,-2,LOG:13)
Block(2,22,-2,STAINED_GLASS_PANE)
Block(-1,22,-1,LOG:13)
Block(0,22,-1,LOG:13)
Block(-1,22,0,LOG:13)
Block(0,23,-2,LOG:13)
Block(1,23,-2,LOG:13)
Block(2,23,-2,STAINED_GLASS_PANE)
Block(-1,23,0,LOG:13)
Block(1,24,-3,LOG:13)
Block(1,24,-2,LOG:13)
Block(2,24,-2,STAINED_GLASS_PANE)
Block(-1,24,0,LOG:13)
Block(1,25,-3,LOG:13)
Block(2,25,-2,STAINED_GLASS_PANE)
Block(-1,25,0,LOG:13)
Block(-2,25,4,STAINED_GLASS_PANE)
Block(1,26,-4,LEAVES:8)
Block(0,26,-3,LEAVES:8)
Block(1,26,-3,LOG:13)
Block(2,26,-3,LEAVES:8)
Block(1,26,-2,LEAVES:8)
Block(2,26,-2,STAINED_GLASS_PANE)
Block(-1,26,0,LOG:13)
Block(-2,26,1,LOG:13)
Block(-1,26,1,LOG:13)
Block(-2,26,2,LOG:13)
Block(-2,26,4,STAINED_GLASS_PANE)
Block(0,27,-4,LEAVES:8)
Block(1,27,-4,SEA_LANTERN)
Block(2,27,-4,LEAVES:8)
Block(0,27,-3,SEA_LANTERN)
Block(1,27,-3,LOG:13)
Block(2,27,-3,SEA_LANTERN)
Block(0,27,-2,LEAVES:8)
Block(1,27,-2,SEA_LANTERN)
Block(2,27,-2,LEAVES:8)
Block(-1,27,0,LOG:13)
Block(-3,27,2,LOG:13)
Block(-2,27,2,LOG:13)
Block(-4,27,3,LEAVES:8)
Block(-3,27,3,LOG:13)
Block(-2,27,3,LEAVES:8)
Block(-3,27,4,LEAVES:8)
Block(-2,27,4,STAINED_GLASS_PANE)
Block(-1,27,4,STAINED_GLASS_PANE)
Block(1,28,-4,LEAVES:8)
Block(0,28,-3,LEAVES:8)
Block(1,28,-3,SEA_LANTERN)
Block(2,28,-3,LEAVES:8)
Block(1,28,-2,LEAVES:8)
Block(2,28,-2,STAINED_GLASS_PANE)
Block(-1,28,0,LOG:13)
Block(-3,28,1,LEAVES:8)
Block(-4,28,2,LEAVES:8)
Block(-3,28,2,SEA_LANTERN)
Block(-2,28,2,LEAVES:8)
Block(-5,28,3,LEAVES:8)
Block(-4,28,3,SEA_LANTERN)
Block(-3,28,3,LOG:13)
Block(-2,28,3,SEA_LANTERN)
Block(-1,28,3,LEAVES:8)
Block(-4,28,4,LEAVES:8)
Block(-3,28,4,SEA_LANTERN)
Block(-2,28,4,LEAVES:8)
Block(-1,28,4,STAINED_GLASS_PANE)
Block(-3,28,5,LEAVES:8)
Block(-2,28,5,STAINED_GLASS_PANE)
Block(-1,29,0,LOG:13)
Block(-4,29,1,LEAVES:8)
Block(-3,29,1,LEAVES:8)
Block(-2,29,1,LEAVES:8)
Block(-5,29,2,LEAVES:8)
Block(-4,29,2,SEA_LANTERN)
Block(-3,29,2,SEA_LANTERN)
Block(-2,29,2,SEA_LANTERN)
Block(-1,29,2,LEAVES:8)
Block(-5,29,3,LEAVES:8)
Block(-4,29,3,SEA_LANTERN)
Block(-3,29,3,SEA_LANTERN)
Block(-2,29,3,SEA_LANTERN)
Block(-1,29,3,LEAVES:8)
Block(-5,29,4,LEAVES:8)
Block(-4,29,4,SEA_LANTERN)
Block(-3,29,4,SEA_LANTERN)
Block(-2,29,4,SEA_LANTERN)
Block(-1,29,4,LEAVES:8)
Block(-4,29,5,LEAVES:8)
Block(-3,29,5,LEAVES:8)
Block(-2,29,5,LEAVES:8)
Block(-1,30,0,LOG:13)
Block(0,30,0,WOODEN_SLAB:9)
Block(-3,30,1,LEAVES:8)
Block(-4,30,2,LEAVES:8)
Block(-3,30,2,SEA_LANTERN)
Block(-2,30,2,LEAVES:8)
Block(-5,30,3,LEAVES:8)
Block(-4,30,3,SEA_LANTERN)
Block(-3,30,3,SEA_LANTERN)
Block(-2,30,3,SEA_LANTERN)
Block(-1,30,3,LEAVES:8)
Block(-4,30,4,LEAVES:8)
Block(-3,30,4,SEA_LANTERN)
Block(-2,30,4,LEAVES:8)
Block(-3,30,5,LEAVES:8)
Block(-4,31,-3,STAINED_GLASS_PANE)
Block(-1,31,0,LOG:13)
Block(0,31,0,LOG:13)
Block(-3,31,2,LEAVES:8)
Block(-4,31,3,LEAVES:8)
Block(-3,31,3,LEAVES:8)
Block(-2,31,3,LEAVES:8)
Block(-3,31,4,LEAVES:8)
Block(-4,32,-3,STAINED_GLASS_PANE)
Block(-2,32,-1,LOG:13)
Block(-1,32,-1,LOG:13)
Block(-1,32,0,LOG:13)
Block(0,32,0,LOG:13)
Block(0,32,1,LOG:13)
Block(1,32,1,LOG:13)
Block(2,32,5,STAINED_GLASS_PANE)
Block(-4,33,-4,STAINED_GLASS_PANE)
Block(-5,33,-3,STAINED_GLASS_PANE)
Block(-4,33,-3,STAINED_GLASS_PANE)
Block(-3,33,-3,LEAVES:8)
Block(-4,33,-2,LEAVES:8)
Block(-3,33,-2,SEA_LANTERN)
Block(-2,33,-2,LEAVES:8)
Block(-3,33,-1,LOG:13)
Block(-2,33,-1,LOG:13)
Block(1,33,1,WOODEN_SLAB:1)
Block(1,33,2,LOG:13)
Block(2,33,2,LOG:13)
Block(2,33,5,STAINED_GLASS_PANE)
Block(-4,34,-4,STAINED_GLASS_PANE)
Block(-3,34,-4,LEAVES:8)
Block(-5,34,-3,STAINED_GLASS_PANE)
Block(-4,34,-3,LEAVES:8)
Block(-3,34,-3,SEA_LANTERN)
Block(-2,34,-3,LEAVES:8)
Block(-5,34,-2,LEAVES:8)
Block(-4,34,-2,SEA_LANTERN)
Block(-3,34,-2,LOG:13)
Block(-2,34,-2,SEA_LANTERN)
Block(-1,34,-2,LEAVES:8)
Block(-4,34,-1,LEAVES:8)
Block(-3,34,-1,SEA_LANTERN)
Block(-2,34,-1,LEAVES:8)
Block(-3,34,0,LEAVES:8)
Block(2,34,2,LOG:13)
Block(2,34,5,STAINED_GLASS_PANE)
Block(3,34,5,STAINED_GLASS_PANE)
Block(-4,35,-4,LEAVES:8)
Block(-3,35,-4,LEAVES:8)
Block(-2,35,-4,LEAVES:8)
Block(-5,35,-3,LEAVES:8)
Block(-4,35,-3,SEA_LANTERN)
Block(-3,35,-3,SEA_LANTERN)
Block(-2,35,-3,SEA_LANTERN)
Block(-1,35,-3,LEAVES:8)
Block(-5,35,-2,LEAVES:8)
Block(-4,35,-2,SEA_LANTERN)
Block(-3,35,-2,SEA_LANTERN)
Block(-2,35,-2,SEA_LANTERN)
Block(-1,35,-2,LEAVES:8)
Block(-5,35,-1,LEAVES:8)
Block(-4,35,-1,SEA_LANTERN)
Block(-3,35,-1,SEA_LANTERN)
Block(-2,35,-1,SEA_LANTERN)
Block(-1,35,-1,LEAVES:8)
Block(-4,35,0,LEAVES:8)
Block(-3,35,0,LEAVES:8)
Block(-2,35,0,LEAVES:8)
Block(2,35,2,LOG:13)
Block(5,35,2,STAINED_GLASS_PANE)
Block(2,35,3,LOG:13)
Block(2,35,5,STAINED_GLASS_PANE)
Block(3,35,5,STAINED_GLASS_PANE)
Block(-3,36,-4,LEAVES:8)
Block(-4,36,-3,LEAVES:8)
Block(-3,36,-3,SEA_LANTERN)
Block(-2,36,-3,LEAVES:8)
Block(-5,36,-2,LEAVES:8)
Block(-4,36,-2,SEA_LANTERN)
Block(-3,36,-2,SEA_LANTERN)
Block(-2,36,-2,SEA_LANTERN)
Block(-1,36,-2,LEAVES:8)
Block(-4,36,-1,LEAVES:8)
Block(-3,36,-1,SEA_LANTERN)
Block(-2,36,-1,LEAVES:8)
Block(-3,36,0,LEAVES:8)
Block(5,36,1,STAINED_GLASS_PANE)
Block(3,36,2,LEAVES:8)
Block(5,36,2,STAINED_GLASS_PANE)
Block(2,36,3,LOG:13)
Block(3,36,3,LEAVES:4)
Block(4,36,3,LEAVES:8)
Block(3,36,4,LEAVES:8)
Block(2,36,5,STAINED_GLASS_PANE)
Block(3,36,5,STAINED_GLASS_PANE)
Block(-3,37,-3,LEAVES:8)
Block(-4,37,-2,LEAVES:8)
Block(-3,37,-2,LEAVES:8)
Block(-2,37,-2,LEAVES:8)
Block(-3,37,-1,LEAVES:8)
Block(3,37,1,LEAVES:8)
Block(5,37,1,STAINED_GLASS_PANE)
Block(2,37,2,LEAVES:8)
Block(3,37,2,SEA_LANTERN)
Block(4,37,2,LEAVES:8)
Block(5,37,2,STAINED_GLASS_PANE)
Block(1,37,3,LEAVES:8)
Block(2,37,3,SEA_LANTERN)
Block(3,37,3,SEA_LANTERN)
Block(4,37,3,SEA_LANTERN)
Block(5,37,3,LEAVES:8)
Block(2,37,4,LEAVES:8)
Block(3,37,4,SEA_LANTERN)
Block(4,37,4,LEAVES:8)
Block(2,37,5,STAINED_GLASS_PANE)
Block(3,37,5,LEAVES:8)
Block(2,38,1,LEAVES:8)
Block(3,38,1,LEAVES:8)
Block(4,38,1,LEAVES:8)
Block(5,38,1,STAINED_GLASS_PANE)
Block(1,38,2,LEAVES:8)
Block(2,38,2,SEA_LANTERN)
Block(3,38,2,SEA_LANTERN)
Block(4,38,2,SEA_LANTERN)
Block(5,38,2,LEAVES:8)
Block(1,38,3,LEAVES:8)
Block(2,38,3,SEA_LANTERN)
Block(3,38,3,LOG:1)
Block(4,38,3,SEA_LANTERN)
Block(5,38,3,LEAVES:8)
Block(1,38,4,LEAVES:8)
Block(2,38,4,SEA_LANTERN)
Block(3,38,4,SEA_LANTERN)
Block(4,38,4,SEA_LANTERN)
Block(5,38,4,LEAVES:8)
Block(2,38,5,LEAVES:8)
Block(3,38,5,LEAVES:8)
Block(4,38,5,LEAVES:8)
Block(3,39,1,LEAVES:8)
Block(2,39,2,LEAVES:8)
Block(3,39,2,SEA_LANTERN)
Block(4,39,2,LEAVES:8)
Block(1,39,3,LEAVES:8)
Block(2,39,3,SEA_LANTERN)
Block(3,39,3,SEA_LANTERN)
Block(4,39,3,SEA_LANTERN)
Block(5,39,3,LEAVES:8)
Block(2,39,4,LEAVES:8)
Block(3,39,4,SEA_LANTERN)
Block(4,39,4,LEAVES:8)
Block(3,39,5,LEAVES:8)
Block(3,40,2,LEAVES:8)
Block(2,40,3,LEAVES:8)
Block(3,40,3,LEAVES:8)
Block(4,40,3,LEAVES:8)
Block(3,40,4,LEAVES:8)
Block(0,0,0,LOG:2)

BC(0,0,0,STONE,GRASS)