#######################################################################
# +-----------------------------------------------------------------+ #
# |                            BO3 object                           | #
# +-----------------------------------------------------------------+ #
#######################################################################

Author: Bo3 BulkEdit

Description: Converted Schematic - Modified by Bo3BulkEdit

Version: 3

SettingsMode: WriteDisable

#######################################################################
# +-----------------------------------------------------------------+ #
# |                          Main settings                          | #
# +-----------------------------------------------------------------+ #
#######################################################################

IsOTGPlus: false
Tree: true
Frequency: 1
Rarity: 100
RotateRandomly: true
SpawnHeight: randomY
SpawnHeightOffset: 0
SpawnHeightVariance: 0
MaxBranchDepth: 10
ExcludedBiomes: All

##############################
# Height Limits for the BO3. #
##############################

MinHeight: 0
MaxHeight: 20

#######################################################################
# +-----------------------------------------------------------------+ #
# |                      Source block settings                      | #
# +-----------------------------------------------------------------+ #
#######################################################################

SourceBlocks: AIR,GRASS,DIRT,STONE,WATER
MaxPercentageOutsideSourceBlock: 0
OutsideSourceBlock: placeAnyway

ReplaceBelow: STONE
ReplaceWithBiomeBlocks: true
ReplaceWithGroundBlock: DIRT
ReplaceWithSurfaceBlock: GRASS
ReplaceWithStoneBlock: STONE
SmoothRadius: 0
SmoothHeightOffset: 0

#######################################################################
# +-----------------------------------------------------------------+ #
# |                              Blocks                             | #
# +-----------------------------------------------------------------+ #
#######################################################################

Block(0,1,-1,DIRT:1)
Block(1,1,-1,DIRT:1)
Block(-1,1,0,DIRT:1)
Block(0,1,0,DIRT)
Block(1,1,0,PLANKS:1)
Block(2,1,0,PLANKS:1)
Block(-1,1,1,PLANKS:1)
Block(0,1,1,DIRT)
Block(1,1,1,DIRT:1)
Block(0,1,2,PLANKS:1)
Block(5,1,2,SPRUCE_FENCE)
Block(6,1,2,SPRUCE_FENCE)
Block(0,2,-1,RED_FLOWER:3)
Block(1,2,-1,SPRUCE_FENCE)
Block(2,2,-1,SPRUCE_FENCE)
Block(-2,2,0,LOG:2)
Block(-1,2,0,LOG:2)
Block(0,2,0,PLANKS:1)
Block(-2,2,1,PLANKS:1)
Block(-1,2,1,DIRT:1)
Block(0,2,1,LOG:2)
Block(1,2,1,LOG:2)
Block(2,2,1,SPRUCE_FENCE)
Block(3,2,1,SPRUCE_FENCE)
Block(3,2,2,SPRUCE_FENCE)
Block(4,2,2,SPRUCE_FENCE)
Block(5,2,2,SPRUCE_FENCE)
Block(-3,3,0,LOG:2)
Block(-2,3,0,PLANKS:1)
Block(-1,3,0,PLANKS:1)
Block(-3,3,1,LOG:2)
Block(-2,3,1,DIRT)
Block(-1,3,1,LOG:2)
Block(-3,3,2,PLANKS:1)
Block(-2,3,2,PLANKS:1)
Block(-3,4,-1,STAINED_GLASS_PANE)
Block(-3,4,0,PLANKS:1)
Block(-2,4,0,PLANKS:1)
Block(-4,4,1,LOG:2)
Block(-3,4,1,DIRT)
Block(-2,4,1,DIRT:1)
Block(-4,4,2,DIRT:1)
Block(-3,4,2,PLANKS:1)
Block(-2,4,2,PLANKS:1)
Block(-4,4,3,DIRT:1)
Block(-4,5,-1,LEAVES:8)
Block(-3,5,-1,LEAVES:8)
Block(-3,5,1,PLANKS:1)
Block(-2,5,1,RED_FLOWER:3)
Block(-4,5,2,PLANKS:1)
Block(-3,5,2,PLANKS:1)
Block(-2,5,2,DIRT:1)
Block(-4,5,3,PLANKS:1)
Block(-3,5,3,PLANKS:1)
Block(-2,5,3,PLANKS:1)
Block(-4,5,4,DIRT:1)
Block(-3,5,4,DIRT:1)
Block(-2,5,4,PLANKS:1)
Block(-2,6,2,DIRT:1)
Block(2,6,2,DIRT:1)
Block(-3,6,3,PLANKS:1)
Block(-2,6,3,DIRT)
Block(-1,6,3,DIRT:1)
Block(1,6,3,DIRT:1)
Block(2,6,3,PLANKS:1)
Block(-3,6,4,DIRT:1)
Block(-2,6,4,DIRT:1)
Block(-1,6,4,DIRT:1)
Block(0,6,4,DIRT:1)
Block(3,7,1,DIRT:1)
Block(-2,7,2,RED_FLOWER:3)
Block(2,7,2,DIRT:1)
Block(3,7,2,PLANKS:1)
Block(-2,7,3,PLANKS:1)
Block(-1,7,3,DIRT:1)
Block(0,7,3,DIRT:1)
Block(1,7,3,LOG:2)
Block(-2,7,4,PLANKS:1)
Block(-1,7,4,DIRT:1)
Block(0,7,4,DIRT:1)
Block(1,7,4,DIRT:1)
Block(-4,7,7,LEAVES:8)
Block(-2,8,-1,LEAVES:8)
Block(3,8,1,DIRT:1)
Block(0,8,2,PLANKS:1)
Block(2,8,2,SAPLING:1)
Block(-1,8,3,PLANKS:1)
Block(0,8,3,PLANKS:1)
Block(-1,8,4,PLANKS:1)
Block(0,8,4,LOG:2)
Block(1,8,4,SAPLING:9)
Block(-2,8,5,STAINED_GLASS_PANE)
Block(-1,8,5,STAINED_GLASS_PANE)
Block(-4,8,6,LEAVES:8)
Block(-3,8,6,LEAVES:8)
Block(-3,8,7,LEAVES:8)
Block(-1,9,-1,LEAVES:8)
Block(5,9,-1,LEAVES:8)
Block(-2,9,0,LEAVES:8)
Block(-1,9,0,LEAVES:8)
Block(3,9,0,STAINED_GLASS_PANE)
Block(4,9,0,STAINED_GLASS_PANE)
Block(0,9,1,STAINED_GLASS_PANE)
Block(2,9,1,PLANKS:1)
Block(3,9,1,PLANKS:1)
Block(0,9,2,PLANKS:1)
Block(1,9,2,PLANKS:1)
Block(2,9,2,DIRT:1)
Block(0,9,3,LOG:2)
Block(0,9,4,LOG:2)
Block(-3,9,5,LEAVES:8)
Block(-2,9,5,LEAVES:8)
Block(-3,9,6,SEA_LANTERN)
Block(-2,9,6,LEAVES:8)
Block(4,10,-1,LEAVES:8)
Block(-1,10,0,SEA_LANTERN)
Block(0,10,0,LEAVES:8)
Block(4,10,0,LEAVES:8)
Block(5,10,0,LEAVES:8)
Block(-1,10,1,LEAVES:8)
Block(0,10,1,LEAVES:8)
Block(2,10,1,PLANKS:1)
Block(3,10,1,PLANKS:1)
Block(2,10,2,PLANKS:1)
Block(1,11,2,PLANKS:1)
Block(2,11,2,PLANKS:1)
Block(1,12,1,STAINED_GLASS_PANE)
Block(1,12,2,PLANKS:1)
Block(-1,12,4,LEAVES:8)
Block(4,13,-1,LEAVES:8)
Block(5,13,-1,LEAVES:8)
Block(1,13,1,STAINED_GLASS_PANE)
Block(2,13,1,STAINED_GLASS_PANE)
Block(0,13,2,STAINED_GLASS_PANE)
Block(1,13,2,STAINED_GLASS_PANE)
Block(-1,13,3,LEAVES:8)
Block(0,13,3,STAINED_GLASS_PANE)
Block(0,13,4,LEAVES:8)
Block(2,14,-1,LEAVES:8)
Block(3,14,-1,LEAVES:8)
Block(3,14,0,LEAVES:8)
Block(4,14,0,LEAVES:8)
Block(2,14,1,STAINED_GLASS_PANE)
Block(4,14,1,LEAVES:8)
Block(0,14,2,LEAVES:8)
Block(0,14,3,LEAVES:8)
Block(1,14,3,LEAVES:8)
Block(2,15,0,LEAVES:8)
Block(2,15,1,LEAVES:8)
Block(3,15,1,LEAVES:8)
Block(0,0,0,LOG:2)

#######################################################################
# +-----------------------------------------------------------------+ #
# |                            BO3 checks                           | #
# +-----------------------------------------------------------------+ #
#######################################################################

BlockCheck(0,0,-1,Solid)
BlockCheck(1,0,-1,Solid)
BlockCheck(-1,0,0,Solid)
BlockCheck(1,0,0,Solid)
BlockCheck(2,0,0,Solid)
BlockCheck(-1,0,1,Solid)
BlockCheck(0,0,1,Solid)
BlockCheck(1,0,1,Solid)
BlockCheck(0,0,2,Solid)
BlockCheck(5,0,2,Solid)
BlockCheck(6,0,2,Solid)

