#######################################################################
# +-----------------------------------------------------------------+ #
# |                            BO3 object                           | #
# +-----------------------------------------------------------------+ #
#######################################################################

Author: Bo3 BulkEdit

Description: Converted Schematic - Modified by Bo3BulkEdit

Version: 3

SettingsMode: WriteDisable

#######################################################################
# +-----------------------------------------------------------------+ #
# |                          Main settings                          | #
# +-----------------------------------------------------------------+ #
#######################################################################

IsOTGPlus: false
Tree: true
Frequency: 1
Rarity: 100
RotateRandomly: true
SpawnHeight: randomY
SpawnHeightOffset: 0
SpawnHeightVariance: 0
MaxBranchDepth: 10
ExcludedBiomes: All

##############################
# Height Limits for the BO3. #
##############################

MinHeight: 65
MaxHeight: 70

#######################################################################
# +-----------------------------------------------------------------+ #
# |                      Source block settings                      | #
# +-----------------------------------------------------------------+ #
#######################################################################

SourceBlocks: AIR,GRASS,DIRT,STONE
MaxPercentageOutsideSourceBlock: 0
OutsideSourceBlock: placeAnyway

ReplaceBelow: STONE
ReplaceWithBiomeBlocks: true
ReplaceWithGroundBlock: DIRT
ReplaceWithSurfaceBlock: GRASS
ReplaceWithStoneBlock: STONE
SmoothRadius: 0
SmoothHeightOffset: 0

#######################################################################
# +-----------------------------------------------------------------+ #
# |                              Blocks                             | #
# +-----------------------------------------------------------------+ #
#######################################################################

Block(0,-30,5,BIRCH_FENCE)
Block(1,-30,5,BIRCH_FENCE)
Block(1,-29,4,BIRCH_FENCE)
Block(1,-29,5,BIRCH_FENCE)
Block(-4,-28,-3,BIRCH_FENCE)
Block(7,-28,-1,BIRCH_FENCE)
Block(1,-28,4,BIRCH_FENCE)
Block(3,-27,-6,BIRCH_FENCE)
Block(-4,-27,-3,BIRCH_FENCE)
Block(-3,-27,-3,BIRCH_FENCE)
Block(-3,-27,-2,BIRCH_FENCE)
Block(-3,-27,-1,BIRCH_FENCE)
Block(-2,-27,-1,BIRCH_FENCE)
Block(7,-27,-1,BIRCH_FENCE)
Block(2,-27,3,BIRCH_FENCE)
Block(1,-27,4,BIRCH_FENCE)
Block(2,-27,4,BIRCH_FENCE)
Block(2,-26,-6,BIRCH_FENCE)
Block(3,-26,-6,BIRCH_FENCE)
Block(2,-26,-5,BIRCH_FENCE)
Block(-2,-26,-1,BIRCH_FENCE)
Block(6,-26,-1,BIRCH_FENCE)
Block(7,-26,-1,BIRCH_FENCE)
Block(2,-26,3,BIRCH_FENCE)
Block(2,-25,-5,BIRCH_FENCE)
Block(-2,-25,-1,BIRCH_FENCE)
Block(6,-25,-1,BIRCH_FENCE)
Block(2,-25,3,BIRCH_FENCE)
Block(2,-24,-5,WOODEN_SLAB:13)
Block(2,-24,-4,LEAVES:12)
Block(2,-24,-3,LEAVES:12)
Block(3,-24,-3,LEAVES:12)
Block(1,-24,-2,LEAVES:12)
Block(3,-24,-2,LEAVES:12)
Block(4,-24,-2,LEAVES:12)
Block(-2,-24,-1,WOODEN_SLAB:13)
Block(-1,-24,-1,LEAVES:12)
Block(0,-24,-1,LEAVES:12)
Block(4,-24,-1,LEAVES:12)
Block(5,-24,-1,LEAVES:12)
Block(6,-24,-1,WOODEN_SLAB:13)
Block(0,-24,0,LEAVES:12)
Block(1,-24,0,LEAVES:12)
Block(3,-24,0,LEAVES:12)
Block(4,-24,0,LEAVES:12)
Block(1,-24,1,LEAVES:12)
Block(2,-24,1,LEAVES:12)
Block(3,-24,1,LEAVES:12)
Block(2,-24,2,LEAVES:12)
Block(2,-24,3,WOODEN_SLAB:13)
Block(-5,-23,-6,BIRCH_FENCE)
Block(2,-23,-4,WOODEN_SLAB:5)
Block(2,-23,-3,DARK_OAK_STAIRS:2)
Block(1,-23,-2,LOG:1)
Block(2,-23,-2,CONCRETE:15)
Block(3,-23,-2,LOG:1)
Block(-1,-23,-1,WOODEN_SLAB:5)
Block(0,-23,-1,DARK_OAK_STAIRS)
Block(1,-23,-1,CONCRETE:15)
Block(2,-23,-1,SEA_LANTERN)
Block(3,-23,-1,CONCRETE:15)
Block(4,-23,-1,DARK_OAK_STAIRS:1)
Block(5,-23,-1,WOODEN_SLAB:5)
Block(1,-23,0,LOG:1)
Block(2,-23,0,CONCRETE:15)
Block(3,-23,0,LOG:1)
Block(2,-23,1,DARK_OAK_STAIRS:3)
Block(2,-23,2,WOODEN_SLAB:5)
Block(-5,-22,-6,BIRCH_FENCE)
Block(2,-22,-2,CONCRETE:15)
Block(1,-22,-1,CONCRETE:15)
Block(2,-22,-1,LOG:13)
Block(3,-22,-1,CONCRETE:15)
Block(2,-22,0,CONCRETE:15)
Block(-5,-21,-6,BIRCH_FENCE)
Block(-1,-21,-6,LEAVES:12)
Block(-5,-21,-5,BIRCH_FENCE)
Block(-2,-21,-5,LEAVES:12)
Block(-1,-21,-5,SEA_LANTERN)
Block(0,-21,-5,LEAVES:12)
Block(-1,-21,-4,LEAVES:12)
Block(2,-21,-1,LOG:13)
Block(2,-21,0,BIRCH_FENCE)
Block(-1,-20,-9,WOODEN_BUTTON)
Block(-1,-20,-7,LEAVES:12)
Block(-2,-20,-6,LEAVES:12)
Block(-1,-20,-6,LEAVES:12)
Block(0,-20,-6,LEAVES:12)
Block(-5,-20,-5,BIRCH_FENCE)
Block(-3,-20,-5,LEAVES:12)
Block(-2,-20,-5,LEAVES:12)
Block(-1,-20,-5,LOG:1)
Block(0,-20,-5,LEAVES:12)
Block(1,-20,-5,LEAVES:12)
Block(3,-20,-5,WOODEN_BUTTON)
Block(-2,-20,-4,LEAVES:12)
Block(-1,-20,-4,LEAVES:12)
Block(0,-20,-4,LEAVES:12)
Block(-1,-20,-3,LEAVES:12)
Block(-1,-20,-1,BIRCH_FENCE)
Block(2,-20,-1,LOG:13)
Block(2,-20,0,BIRCH_FENCE)
Block(-1,-19,-9,WOODEN_SLAB:5)
Block(-1,-19,-8,DARK_OAK_STAIRS:7)
Block(-3,-19,-7,WOODEN_SLAB:13)
Block(-1,-19,-7,LEAVES:12)
Block(1,-19,-7,WOODEN_SLAB:13)
Block(-2,-19,-6,LEAVES:12)
Block(-1,-19,-6,LEAVES:12)
Block(0,-19,-6,LEAVES:12)
Block(-5,-19,-5,WOODEN_SLAB:5)
Block(-4,-19,-5,DARK_OAK_STAIRS:5)
Block(-3,-19,-5,LEAVES:12)
Block(-2,-19,-5,LEAVES:12)
Block(-1,-19,-5,SEA_LANTERN)
Block(0,-19,-5,LEAVES:12)
Block(1,-19,-5,LEAVES:12)
Block(2,-19,-5,DARK_OAK_STAIRS:4)
Block(3,-19,-5,WOODEN_SLAB:5)
Block(-2,-19,-4,LEAVES:12)
Block(-1,-19,-4,LEAVES:12)
Block(0,-19,-4,LEAVES:12)
Block(-3,-19,-3,WOODEN_SLAB:13)
Block(-1,-19,-3,LEAVES:12)
Block(1,-19,-3,WOODEN_SLAB:13)
Block(-1,-19,-2,DARK_OAK_STAIRS:6)
Block(-1,-19,-1,WOODEN_SLAB:5)
Block(2,-19,-1,LOG:13)
Block(-2,-18,-7,WOODEN_SLAB:5)
Block(-1,-18,-7,CONCRETE:15)
Block(0,-18,-7,WOODEN_SLAB:5)
Block(-3,-18,-6,WOODEN_SLAB:5)
Block(-2,-18,-6,CONCRETE:15)
Block(-1,-18,-6,LEAVES:12)
Block(0,-18,-6,CONCRETE:15)
Block(1,-18,-6,WOODEN_SLAB:5)
Block(-3,-18,-5,CONCRETE:15)
Block(-2,-18,-5,LEAVES:12)
Block(-1,-18,-5,LOG:13)
Block(0,-18,-5,LEAVES:12)
Block(1,-18,-5,CONCRETE:15)
Block(-3,-18,-4,WOODEN_SLAB:5)
Block(-2,-18,-4,CONCRETE:15)
Block(-1,-18,-4,LEAVES:12)
Block(0,-18,-4,CONCRETE:15)
Block(1,-18,-4,WOODEN_SLAB:5)
Block(-2,-18,-3,WOODEN_SLAB:5)
Block(-1,-18,-3,CONCRETE:15)
Block(0,-18,-3,WOODEN_SLAB:5)
Block(2,-18,-1,LOG:12)
Block(-1,-17,-5,LOG:13)
Block(-1,-17,-1,WOODEN_BUTTON)
Block(2,-17,-1,LOG:12)
Block(3,-17,-1,BIRCH_FENCE)
Block(-1,-17,0,LEAVES:12)
Block(-3,-17,1,WOODEN_BUTTON)
Block(-2,-17,1,LEAVES:12)
Block(-1,-17,1,SEA_LANTERN)
Block(0,-17,1,LEAVES:12)
Block(1,-17,1,WOODEN_BUTTON)
Block(-1,-17,2,LEAVES:12)
Block(-1,-17,3,WOODEN_BUTTON)
Block(-1,-16,-5,LOG:13)
Block(2,-16,-2,DARK_OAK_STAIRS:6)
Block(-1,-16,-1,DARK_OAK_STAIRS:2)
Block(2,-16,-1,LOG:13)
Block(3,-16,-1,BIRCH_FENCE)
Block(-2,-16,0,WOODEN_SLAB:13)
Block(-1,-16,0,LEAVES:12)
Block(0,-16,0,WOODEN_SLAB:13)
Block(-3,-16,1,DARK_OAK_STAIRS)
Block(-2,-16,1,LEAVES:12)
Block(-1,-16,1,LOG:1)
Block(0,-16,1,LEAVES:12)
Block(1,-16,1,DARK_OAK_STAIRS:1)
Block(-2,-16,2,WOODEN_SLAB:13)
Block(-1,-16,2,LEAVES:12)
Block(0,-16,2,WOODEN_SLAB:13)
Block(-1,-16,3,DARK_OAK_STAIRS:3)
Block(-1,-15,-5,LOG:13)
Block(0,-15,-4,LOG:13)
Block(2,-15,-2,LOG:13)
Block(3,-15,-2,BIRCH_FENCE)
Block(2,-15,-1,LOG:13)
Block(3,-15,-1,BIRCH_FENCE)
Block(-2,-15,0,CONCRETE:15)
Block(-1,-15,0,LEAVES:12)
Block(0,-15,0,CONCRETE:15)
Block(-2,-15,1,LEAVES:12)
Block(-1,-15,1,SEA_LANTERN)
Block(0,-15,1,LEAVES:12)
Block(-2,-15,2,CONCRETE:15)
Block(-1,-15,2,LEAVES:12)
Block(0,-15,2,CONCRETE:15)
Block(-1,-14,-5,DOUBLE_WOODEN_SLAB:5)
Block(-1,-14,-4,BIRCH_FENCE)
Block(0,-14,-4,LOG:13)
Block(2,-14,-2,CONCRETE:15)
Block(3,-14,-2,BIRCH_FENCE)
Block(2,-14,-1,LOG:13)
Block(-2,-14,0,WOODEN_SLAB:5)
Block(-1,-14,0,CONCRETE:15)
Block(0,-14,0,WOODEN_SLAB:5)
Block(-2,-14,1,CONCRETE:15)
Block(-1,-14,1,LOG:13)
Block(0,-14,1,LEAVES:12)
Block(-2,-14,2,WOODEN_SLAB:5)
Block(-1,-14,2,CONCRETE:15)
Block(0,-14,2,WOODEN_SLAB:5)
Block(-1,-13,-4,BIRCH_FENCE)
Block(0,-13,-4,LOG:13)
Block(2,-13,-2,CONCRETE:15)
Block(3,-13,-2,BIRCH_FENCE)
Block(-1,-13,1,LOG:13)
Block(-1,-13,2,BIRCH_FENCE)
Block(0,-12,-5,WOODEN_BUTTON:4)
Block(-1,-12,-4,WOODEN_BUTTON:2)
Block(0,-12,-4,CONCRETE:15)
Block(1,-12,-4,WOODEN_BUTTON:1)
Block(0,-12,-3,WOODEN_BUTTON:3)
Block(1,-12,-2,LOG:13)
Block(2,-12,-2,CONCRETE:15)
Block(-1,-12,1,LOG:12)
Block(0,-12,1,LOG:12)
Block(-1,-12,2,BIRCH_FENCE)
Block(0,-11,-4,CONCRETE:15)
Block(1,-11,-4,CONCRETE:15)
Block(1,-11,-3,LOG:13)
Block(1,-11,-2,LOG:12)
Block(-1,-11,1,WOODEN_SLAB:5)
Block(0,-11,1,LOG:12)
Block(0,-10,-4,WOODEN_SLAB:5)
Block(1,-10,-4,WOODEN_SLAB:5)
Block(1,-10,-3,WOODEN_SLAB:5)
Block(0,-10,-2,BIRCH_FENCE)
Block(1,-10,-2,LOG:12)
Block(0,-10,0,CONCRETE:15)
Block(0,-10,1,CONCRETE:15)
Block(0,-9,-2,BIRCH_FENCE)
Block(1,-9,-2,LOG:12)
Block(0,-9,0,CONCRETE:15)
Block(0,-9,1,DARK_OAK_STAIRS:3)
Block(0,-8,-2,BIRCH_FENCE)
Block(1,-8,-2,LOG:12)
Block(0,-8,-1,WOODEN_BUTTON:4)
Block(-1,-8,0,WOODEN_BUTTON:2)
Block(0,-8,0,LOG:13)
Block(1,-8,0,WOODEN_BUTTON:1)
Block(0,-8,1,WOODEN_BUTTON:3)
Block(0,-7,-2,CONCRETE:15)
Block(1,-7,-2,CONCRETE:15)
Block(0,-7,-1,LOG:13)
Block(0,-7,0,LOG:13)
Block(0,-6,-2,CONCRETE:15)
Block(0,-6,-1,LOG:12)
Block(0,-6,0,WOODEN_SLAB:5)
Block(0,-5,-2,DOUBLE_WOODEN_SLAB:5)
Block(-1,-5,-1,BIRCH_FENCE)
Block(0,-5,-1,LOG:12)
Block(0,-4,-2,WOODEN_BUTTON:4)
Block(-1,-4,-1,WOODEN_BUTTON:2)
Block(0,-4,-1,LOG:12)
Block(1,-4,-1,WOODEN_BUTTON:1)
Block(0,-4,0,WOODEN_BUTTON:3)
Block(0,-3,-1,CONCRETE:15)
Block(0,-3,0,LOG:13)
Block(0,-2,0,LOG:13)
Block(0,-1,0,LOG:13)
Block(0,0,0,LOG:13)

BC(0,0,0,STONE)