#######################################################################
# +-----------------------------------------------------------------+ #
# |                            BO3 object                           | #
# +-----------------------------------------------------------------+ #
#######################################################################

Author: Bo3 BulkEdit

Description: Converted Schematic - Modified by Bo3BulkEdit

Version: 3

SettingsMode: WriteDisable

#######################################################################
# +-----------------------------------------------------------------+ #
# |                          Main settings                          | #
# +-----------------------------------------------------------------+ #
#######################################################################

IsOTGPlus: false
Tree: true
Frequency: 1
Rarity: 100
RotateRandomly: true
SpawnHeight: randomY
SpawnHeightOffset: 0
SpawnHeightVariance: 0
MaxBranchDepth: 10
ExcludedBiomes: All

##############################
# Height Limits for the BO3. #
##############################

MinHeight: 0
MaxHeight: 20

#######################################################################
# +-----------------------------------------------------------------+ #
# |                      Source block settings                      | #
# +-----------------------------------------------------------------+ #
#######################################################################

SourceBlocks: AIR,GRASS,DIRT,STONE,WATER
MaxPercentageOutsideSourceBlock: 0
OutsideSourceBlock: placeAnyway

ReplaceBelow: STONE
ReplaceWithBiomeBlocks: true
ReplaceWithGroundBlock: DIRT
ReplaceWithSurfaceBlock: GRASS
ReplaceWithStoneBlock: STONE
SmoothRadius: 0
SmoothHeightOffset: 0

#######################################################################
# +-----------------------------------------------------------------+ #
# |                              Blocks                             | #
# +-----------------------------------------------------------------+ #
#######################################################################

Block(-12,1,-5,PLANKS:5)
Block(-11,1,-5,PLANKS:5)
Block(5,1,-5,WOODEN_SLAB:5)
Block(6,1,-5,LEAVES:14)
Block(-11,1,-4,PLANKS:5)
Block(-10,1,-4,PLANKS:5)
Block(3,1,-4,WOODEN_SLAB:13)
Block(4,1,-4,PLANKS:5)
Block(5,1,-4,PLANKS:5)
Block(6,1,-4,WOODEN_SLAB:5)
Block(7,1,-4,LEAVES:14)
Block(-10,1,-3,WOODEN_SLAB:13)
Block(-4,1,-3,LOG:13)
Block(-3,1,-3,LOG:13)
Block(2,1,-3,PLANKS:1)
Block(3,1,-3,PLANKS:1)
Block(4,1,-3,PLANKS:5)
Block(5,1,-3,PLANKS:5)
Block(6,1,-3,LOG:13)
Block(-5,1,-2,WOODEN_SLAB:9)
Block(-4,1,-2,PLANKS:1)
Block(-3,1,-2,PLANKS:1)
Block(1,1,-2,PLANKS:1)
Block(2,1,-2,PLANKS:1)
Block(3,1,-2,PLANKS:1)
Block(4,1,-2,PLANKS:1)
Block(5,1,-2,LOG:13)
Block(6,1,-2,LOG:13)
Block(-5,1,-1,PLANKS:1)
Block(-4,1,-1,PLANKS:1)
Block(-3,1,-1,PLANKS:1)
Block(1,1,-1,PLANKS:1)
Block(2,1,-1,PLANKS:1)
Block(3,1,-1,PLANKS:1)
Block(4,1,-1,PLANKS:1)
Block(5,1,-1,PLANKS:1)
Block(6,1,-1,PLANKS:1)
Block(7,1,-1,PLANKS:1)
Block(-4,1,0,PLANKS:1)
Block(-3,1,0,PLANKS:1)
Block(-2,1,0,PLANKS:1)
Block(-1,1,0,WOODEN_SLAB:9)
Block(0,1,0,PLANKS:1)
Block(1,1,0,PLANKS:1)
Block(2,1,0,WOODEN_SLAB:9)
Block(3,1,0,PLANKS:1)
Block(4,1,0,PLANKS:1)
Block(5,1,0,PLANKS:1)
Block(7,1,0,PLANKS:1)
Block(8,1,0,PLANKS:1)
Block(9,1,0,TRAPDOOR:3)
Block(-3,1,1,WOODEN_SLAB:9)
Block(-2,1,1,PLANKS:1)
Block(-1,1,1,PLANKS:1)
Block(0,1,1,PLANKS:1)
Block(1,1,1,WOODEN_SLAB:9)
Block(2,1,1,WOODEN_SLAB:9)
Block(3,1,1,PLANKS:1)
Block(-1,1,2,PLANKS:1)
Block(0,1,2,PLANKS:1)
Block(1,1,2,WOODEN_SLAB:9)
Block(4,2,-5,NETHER_BRICK_FENCE)
Block(5,2,-5,NETHER_BRICK_FENCE)
Block(-10,2,-4,PLANKS:5)
Block(-9,2,-4,PLANKS:5)
Block(3,2,-4,PLANKS:5)
Block(4,2,-4,PLANKS:5)
Block(5,2,-4,WOODEN_SLAB:5)
Block(6,2,-4,LEAVES:14)
Block(-10,2,-3,WOODEN_SLAB:5)
Block(-9,2,-3,PLANKS:5)
Block(-4,2,-3,LOG:13)
Block(-3,2,-3,LOG:13)
Block(3,2,-3,PLANKS:5)
Block(4,2,-3,PLANKS:5)
Block(5,2,-3,PLANKS:5)
Block(6,2,-3,LEAVES:14)
Block(-5,2,-2,PLANKS:1)
Block(-4,2,-2,PLANKS:1)
Block(-3,2,-2,LOG:13)
Block(-2,2,-2,LOG:13)
Block(1,2,-2,PLANKS:5)
Block(2,2,-2,WOODEN_SLAB:13)
Block(3,2,-2,PLANKS:1)
Block(4,2,-2,LOG:13)
Block(5,2,-2,LOG:13)
Block(-5,2,-1,PLANKS:1)
Block(-4,2,-1,PLANKS:1)
Block(-2,2,-1,LOG:13)
Block(0,2,-1,PLANKS:5)
Block(1,2,-1,PLANKS:5)
Block(2,2,-1,PLANKS:1)
Block(3,2,-1,PLANKS:1)
Block(4,2,-1,LOG:13)
Block(-5,2,0,PLANKS:1)
Block(-4,2,0,PLANKS:1)
Block(-3,2,0,PLANKS:1)
Block(-2,2,0,PLANKS:1)
Block(-1,2,0,PLANKS:1)
Block(0,2,0,PLANKS:5)
Block(1,2,0,PLANKS:1)
Block(2,2,0,PLANKS:1)
Block(3,2,0,PLANKS:1)
Block(4,2,0,WOODEN_SLAB:1)
Block(-7,2,1,WEB)
Block(-6,2,1,WEB)
Block(-4,2,1,PLANKS:1)
Block(-3,2,1,WOODEN_SLAB:1)
Block(-2,2,1,PLANKS:1)
Block(-1,2,1,PLANKS:5)
Block(0,2,1,PLANKS:1)
Block(1,2,1,PLANKS:1)
Block(2,2,1,PLANKS:1)
Block(-2,2,2,PLANKS:1)
Block(-1,2,2,PLANKS:1)
Block(0,2,2,PLANKS:1)
Block(1,2,2,WOODEN_SLAB:1)
Block(4,3,-6,STONE_SLAB:14)
Block(5,3,-5,NETHER_BRICK_FENCE)
Block(-9,3,-4,WOODEN_SLAB:5)
Block(-6,3,-4,LOG:13)
Block(-5,3,-4,LOG:13)
Block(3,3,-4,LEAVES:14)
Block(4,3,-4,LEAVES:14)
Block(5,3,-4,LEAVES:14)
Block(-9,3,-3,PLANKS:5)
Block(-6,3,-3,LOG:13)
Block(-5,3,-3,LOG:13)
Block(2,3,-3,PLANKS:5)
Block(3,3,-3,PLANKS:5)
Block(4,3,-3,WOODEN_SLAB:5)
Block(5,3,-3,LEAVES:14)
Block(-4,3,-2,PLANKS:1)
Block(1,3,-2,PLANKS:5)
Block(2,3,-2,PLANKS:5)
Block(3,3,-2,SEA_LANTERN)
Block(4,3,-2,LOG:13)
Block(5,3,-2,LOG:13)
Block(-5,3,-1,PLANKS:1)
Block(-4,3,-1,PLANKS:1)
Block(-2,3,-1,LOG:13)
Block(0,3,-1,WOODEN_SLAB:5)
Block(1,3,-1,PLANKS:5)
Block(3,3,-1,LOG:13)
Block(4,3,-1,LOG:13)
Block(5,3,-1,LOG:13)
Block(-6,3,0,PLANKS:1)
Block(-5,3,0,PLANKS:1)
Block(-4,3,0,PLANKS:1)
Block(-2,3,0,LOG:13)
Block(-1,3,0,LOG:13)
Block(0,3,0,LOG:13)
Block(1,3,0,LOG:13)
Block(2,3,0,PLANKS:1)
Block(-6,3,1,WOODEN_SLAB:9)
Block(-5,3,1,PLANKS:1)
Block(-4,3,1,PLANKS:1)
Block(-2,3,1,PLANKS:5)
Block(-1,3,1,PLANKS:5)
Block(0,3,1,PLANKS:5)
Block(-2,3,2,WOODEN_SLAB:13)
Block(-1,3,2,WOODEN_SLAB:13)
Block(4,4,-6,LEAVES:4)
Block(5,4,-5,NETHER_BRICK_STAIRS:1)
Block(-6,4,-4,LOG:13)
Block(-9,4,-3,PLANKS:5)
Block(-8,4,-3,PLANKS:5)
Block(3,4,-3,LEAVES:14)
Block(4,4,-3,LEAVES:14)
Block(-3,4,-2,WEB)
Block(-2,4,-2,WEB)
Block(4,4,-2,LEAVES:14)
Block(-4,4,-1,WOODEN_SLAB:1)
Block(-1,4,-1,WEB)
Block(3,4,-1,LOG:13)
Block(4,4,-1,LOG:13)
Block(-6,4,0,PLANKS:1)
Block(-5,4,0,PLANKS:1)
Block(1,4,0,LOG:13)
Block(2,4,0,LOG:13)
Block(3,4,0,LOG:13)
Block(-6,4,1,PLANKS:1)
Block(-5,4,1,PLANKS:1)
Block(-3,4,1,PLANKS:5)
Block(-2,4,1,PLANKS:5)
Block(-1,4,1,WOODEN_SLAB:5)
Block(2,4,1,NETHER_BRICK_FENCE)
Block(-3,4,2,WOODEN_SLAB:13)
Block(-2,4,2,PLANKS:5)
Block(2,4,2,NETHER_BRICK_FENCE)
Block(3,4,2,NETHER_BRICK_FENCE)
Block(-10,5,-3,LEAVES:14)
Block(-9,5,-3,PLANKS:5)
Block(-8,5,-3,PLANKS:5)
Block(-4,5,-2,WEB)
Block(0,5,-1,WEB)
Block(-6,5,0,PLANKS:1)
Block(-5,5,0,WOODEN_SLAB:1)
Block(-4,5,0,PLANKS:5)
Block(-3,5,0,PLANKS:5)
Block(1,5,0,WEB)
Block(-6,5,1,PLANKS:1)
Block(-5,5,1,WOODEN_SLAB:1)
Block(-3,5,1,PLANKS:5)
Block(-3,5,2,WOODEN_SLAB:5)
Block(3,5,2,NETHER_BRICK_FENCE)
Block(4,5,2,STONE_SLAB:14)
Block(-10,6,-3,LEAVES:14)
Block(-9,6,-3,PLANKS:5)
Block(-8,6,-3,PLANKS:5)
Block(-7,6,-3,PLANKS:5)
Block(-9,6,-2,LEAVES:14)
Block(-8,6,-2,WOODEN_SLAB:13)
Block(-7,6,-2,PLANKS:5)
Block(-4,6,-2,WEB)
Block(-4,6,-1,PLANKS:5)
Block(-3,6,-1,PLANKS:5)
Block(-6,6,0,PLANKS:1)
Block(-4,6,0,PLANKS:5)
Block(-3,6,0,PLANKS:5)
Block(2,6,1,WEB)
Block(3,6,2,NETHER_BRICK_STAIRS)
Block(4,6,2,STONE_SLAB:6)
Block(-9,7,-3,LEAVES:14)
Block(-8,7,-3,PLANKS:5)
Block(-7,7,-3,PLANKS:5)
Block(-9,7,-2,LEAVES:14)
Block(-8,7,-2,PLANKS:5)
Block(-7,7,-2,PLANKS:5)
Block(-6,7,-2,PLANKS:5)
Block(-5,7,-2,WOODEN_SLAB:13)
Block(-4,7,-2,PLANKS:5)
Block(-8,7,-1,LEAVES:14)
Block(-5,7,-1,PLANKS:5)
Block(-4,7,-1,PLANKS:5)
Block(-3,7,-1,PLANKS:5)
Block(-8,8,-3,LEAVES:14)
Block(-9,8,-2,LEAVES:14)
Block(-8,8,-2,PLANKS:5)
Block(-7,8,-2,PLANKS:5)
Block(-6,8,-2,PLANKS:5)
Block(-5,8,-2,PLANKS:5)
Block(-4,8,-2,PLANKS:5)
Block(-9,8,-1,NETHER_BRICK_FENCE)
Block(-8,8,-1,NETHER_BRICK_FENCE)
Block(-7,8,-1,LEAVES:14)
Block(-5,8,-1,WOODEN_SLAB:5)
Block(-4,8,-1,PLANKS:5)
Block(-8,8,0,LEAVES:14)
Block(-7,9,-3,LEAVES:14)
Block(-8,9,-2,LEAVES:14)
Block(-7,9,-2,SEA_LANTERN)
Block(-6,9,-2,PLANKS:5)
Block(-5,9,-2,PLANKS:5)
Block(-9,9,-1,NETHER_BRICK_FENCE)
Block(-8,9,-1,LEAVES:14)
Block(-7,9,-1,LEAVES:6)
Block(-6,9,-1,LEAVES:14)
Block(-9,9,0,NETHER_BRICK_FENCE)
Block(-7,10,-2,LEAVES:14)
Block(-6,10,-2,LEAVES:14)
Block(-10,10,0,NETHER_BRICK_FENCE)
Block(-9,10,0,NETHER_BRICK_FENCE)
Block(-12,10,1,NETHER_BRICK_STAIRS:4)
Block(-11,10,1,NETHER_BRICK_FENCE)
Block(-10,10,1,NETHER_BRICK_FENCE)
Block(-11,10,2,NETHER_BRICK_STAIRS:7)
Block(-12,11,1,LEAVES:4)
Block(-13,11,2,LEAVES:4)
Block(-12,11,2,LEAVES:4)
Block(-11,11,2,LEAVES:4)
Block(-12,11,3,LEAVES:4)
Block(-12,12,1,LEAVES:4)
Block(-12,12,2,LEAVES:4)
Block(-11,12,2,LEAVES:12)
Block(-12,12,3,LEAVES:8)
Block(0,0,0,LOG:2)

#######################################################################
# +-----------------------------------------------------------------+ #
# |                            BO3 checks                           | #
# +-----------------------------------------------------------------+ #
#######################################################################

BlockCheck(5,0,-5,Solid)
BlockCheck(6,0,-5,Solid)
BlockCheck(4,0,-4,Solid)
BlockCheck(5,0,-4,Solid)
BlockCheck(6,0,-4,Solid)
BlockCheck(7,0,-4,Solid)
BlockCheck(-4,0,-3,Solid)
BlockCheck(-3,0,-3,Solid)
BlockCheck(2,0,-3,Solid)
BlockCheck(3,0,-3,Solid)
BlockCheck(4,0,-3,Solid)
BlockCheck(5,0,-3,Solid)
BlockCheck(6,0,-3,Solid)
BlockCheck(-4,0,-2,Solid)
BlockCheck(-3,0,-2,Solid)
BlockCheck(1,0,-2,Solid)
BlockCheck(2,0,-2,Solid)
BlockCheck(3,0,-2,Solid)
BlockCheck(4,0,-2,Solid)
BlockCheck(5,0,-2,Solid)
BlockCheck(6,0,-2,Solid)
BlockCheck(-5,0,-1,Solid)
BlockCheck(-4,0,-1,Solid)
BlockCheck(-3,0,-1,Solid)
BlockCheck(1,0,-1,Solid)
BlockCheck(2,0,-1,Solid)
BlockCheck(3,0,-1,Solid)
BlockCheck(4,0,-1,Solid)
BlockCheck(5,0,-1,Solid)
BlockCheck(6,0,-1,Solid)
BlockCheck(7,0,-1,Solid)
BlockCheck(-4,0,0,Solid)
BlockCheck(-3,0,0,Solid)
BlockCheck(-2,0,0,Solid)
BlockCheck(1,0,0,Solid)
BlockCheck(3,0,0,Solid)
BlockCheck(4,0,0,Solid)
BlockCheck(5,0,0,Solid)
BlockCheck(7,0,0,Solid)
BlockCheck(8,0,0,Solid)
BlockCheck(9,0,0,Solid)
BlockCheck(-2,0,1,Solid)
BlockCheck(-1,0,1,Solid)
BlockCheck(0,0,1,Solid)
BlockCheck(3,0,1,Solid)
BlockCheck(-1,0,2,Solid)
BlockCheck(0,0,2,Solid)

