#######################################################################
# +-----------------------------------------------------------------+ #
# |                            BO3 object                           | #
# +-----------------------------------------------------------------+ #
#######################################################################

Author: Bo3 BulkEdit

Description: Converted Schematic - Modified by Bo3BulkEdit

Version: 3

SettingsMode: WriteDisable

#######################################################################
# +-----------------------------------------------------------------+ #
# |                          Main settings                          | #
# +-----------------------------------------------------------------+ #
#######################################################################

IsOTGPlus: false
Tree: true
Frequency: 1
Rarity: 100
RotateRandomly: true
SpawnHeight: randomY
SpawnHeightOffset: 0
SpawnHeightVariance: 0
MaxBranchDepth: 10
ExcludedBiomes: All

##############################
# Height Limits for the BO3. #
##############################

MinHeight: 65
MaxHeight: 70

#######################################################################
# +-----------------------------------------------------------------+ #
# |                      Source block settings                      | #
# +-----------------------------------------------------------------+ #
#######################################################################

SourceBlocks: AIR,GRASS,DIRT,STONE
MaxPercentageOutsideSourceBlock: 0
OutsideSourceBlock: placeAnyway

ReplaceBelow: STONE
ReplaceWithBiomeBlocks: true
ReplaceWithGroundBlock: DIRT
ReplaceWithSurfaceBlock: GRASS
ReplaceWithStoneBlock: STONE
SmoothRadius: 0
SmoothHeightOffset: 0

#######################################################################
# +-----------------------------------------------------------------+ #
# |                              Blocks                             | #
# +-----------------------------------------------------------------+ #
#######################################################################

Block(9,-18,8,CONCRETE:15)
Block(8,-17,7,CONCRETE:15)
Block(9,-17,7,CONCRETE:15)
Block(8,-17,8,CONCRETE:15)
Block(9,-17,8,CONCRETE:15)
Block(7,-16,7,CONCRETE:15)
Block(8,-16,7,CONCRETE:15)
Block(7,-15,6,CONCRETE:15)
Block(8,-15,6,CONCRETE:15)
Block(7,-15,7,CONCRETE:15)
Block(8,-15,7,CONCRETE:15)
Block(6,-14,5,CONCRETE:15)
Block(7,-14,5,CONCRETE:15)
Block(6,-14,6,CONCRETE:15)
Block(7,-14,6,CONCRETE:15)
Block(7,-14,7,CONCRETE:15)
Block(5,-13,5,CONCRETE:15)
Block(6,-13,5,CONCRETE:15)
Block(7,-13,5,CONCRETE:15)
Block(6,-13,6,CONCRETE:15)
Block(7,-13,6,CONCRETE:15)
Block(5,-12,4,CONCRETE:15)
Block(6,-12,4,CONCRETE:15)
Block(5,-12,5,CONCRETE:15)
Block(6,-12,5,CONCRETE:15)
Block(7,-12,5,CONCRETE:15)
Block(5,-12,6,CONCRETE:15)
Block(6,-12,6,CONCRETE:15)
Block(4,-11,4,CONCRETE:15)
Block(5,-11,4,CONCRETE:15)
Block(6,-11,4,CONCRETE:15)
Block(4,-11,5,CONCRETE:15)
Block(5,-11,5,CONCRETE:15)
Block(6,-11,5,CONCRETE:15)
Block(3,-10,3,CONCRETE:15)
Block(4,-10,3,CONCRETE:15)
Block(5,-10,3,CONCRETE:15)
Block(3,-10,4,CONCRETE:15)
Block(4,-10,4,CONCRETE:15)
Block(5,-10,4,CONCRETE:15)
Block(6,-10,4,CONCRETE:15)
Block(4,-10,5,CONCRETE:15)
Block(5,-10,5,CONCRETE:15)
Block(3,-9,2,CONCRETE:15)
Block(3,-9,3,CONCRETE:15)
Block(4,-9,3,CONCRETE:15)
Block(5,-9,3,CONCRETE:15)
Block(3,-9,4,CONCRETE:15)
Block(4,-9,4,CONCRETE:15)
Block(5,-9,4,CONCRETE:15)
Block(4,-9,5,CONCRETE:15)
Block(5,-9,5,CONCRETE:15)
Block(2,-8,2,CONCRETE:15)
Block(3,-8,2,CONCRETE:15)
Block(4,-8,2,CONCRETE:15)
Block(2,-8,3,CONCRETE:15)
Block(3,-8,3,CONCRETE:15)
Block(4,-8,3,CONCRETE:15)
Block(5,-8,3,CONCRETE:15)
Block(3,-8,4,CONCRETE:15)
Block(4,-8,4,CONCRETE:15)
Block(5,-8,4,CONCRETE:15)
Block(2,-7,1,CONCRETE:15)
Block(2,-7,2,CONCRETE:15)
Block(3,-7,2,CONCRETE:15)
Block(4,-7,2,CONCRETE:15)
Block(2,-7,3,CONCRETE:15)
Block(3,-7,3,CONCRETE:15)
Block(4,-7,3,CONCRETE:15)
Block(2,-7,4,CONCRETE:15)
Block(3,-7,4,CONCRETE:15)
Block(4,-7,4,CONCRETE:15)
Block(1,-6,1,CONCRETE:15)
Block(2,-6,1,CONCRETE:15)
Block(3,-6,1,CONCRETE:15)
Block(1,-6,2,CONCRETE:15)
Block(2,-6,2,CONCRETE:15)
Block(3,-6,2,CONCRETE:15)
Block(4,-6,2,CONCRETE:15)
Block(1,-6,3,CONCRETE:15)
Block(2,-6,3,CONCRETE:15)
Block(3,-6,3,CONCRETE:15)
Block(4,-6,3,CONCRETE:15)
Block(2,-6,4,CONCRETE:15)
Block(3,-6,4,CONCRETE:15)
Block(0,-5,0,CONCRETE:15)
Block(1,-5,0,CONCRETE:15)
Block(2,-5,0,CONCRETE:15)
Block(1,-5,1,CONCRETE:15)
Block(2,-5,1,CONCRETE:15)
Block(3,-5,1,CONCRETE:15)
Block(0,-5,2,CONCRETE:15)
Block(1,-5,2,CONCRETE:15)
Block(2,-5,2,CONCRETE:15)
Block(3,-5,2,CONCRETE:15)
Block(1,-5,3,CONCRETE:15)
Block(2,-5,3,CONCRETE:15)
Block(3,-5,3,CONCRETE:15)
Block(0,-4,-1,CONCRETE:15)
Block(0,-4,0,CONCRETE:15)
Block(1,-4,0,CONCRETE:15)
Block(2,-4,0,CONCRETE:15)
Block(0,-4,1,CONCRETE:15)
Block(3,-4,1,CONCRETE:15)
Block(0,-4,2,CONCRETE:15)
Block(1,-4,2,CONCRETE:15)
Block(2,-4,2,CONCRETE:15)
Block(3,-4,2,CONCRETE:15)
Block(0,-4,3,CONCRETE:15)
Block(1,-4,3,CONCRETE:15)
Block(2,-4,3,CONCRETE:15)
Block(-1,-3,-1,CONCRETE:15)
Block(0,-3,-1,CONCRETE:15)
Block(1,-3,-1,CONCRETE:15)
Block(0,-3,0,CONCRETE:15)
Block(1,-3,0,CONCRETE:15)
Block(2,-3,0,CONCRETE:15)
Block(-1,-3,1,CONCRETE:15)
Block(0,-3,1,CONCRETE:15)
Block(1,-3,1,CONCRETE:15)
Block(2,-3,1,CONCRETE:15)
Block(3,-3,1,CONCRETE:15)
Block(0,-3,2,CONCRETE:15)
Block(1,-3,2,CONCRETE:15)
Block(2,-3,2,CONCRETE:15)
Block(-2,-2,-2,CONCRETE:15)
Block(-1,-2,-2,CONCRETE:15)
Block(-1,-2,-1,CONCRETE:15)
Block(0,-2,-1,CONCRETE:15)
Block(1,-2,-1,CONCRETE:15)
Block(-2,-2,0,CONCRETE:15)
Block(-1,-2,0,CONCRETE:15)
Block(2,-2,0,CONCRETE:15)
Block(-1,-2,1,CONCRETE:15)
Block(0,-2,1,CONCRETE:15)
Block(1,-2,1,CONCRETE:15)
Block(2,-2,1,CONCRETE:15)
Block(-1,-2,2,CONCRETE:15)
Block(0,-2,2,CONCRETE:15)
Block(1,-2,2,CONCRETE:15)
Block(2,-2,2,CONCRETE:15)
Block(-2,-1,-2,CONCRETE:15)
Block(-1,-1,-2,CONCRETE:15)
Block(0,-1,-2,CONCRETE:15)
Block(-1,-1,-1,CONCRETE:15)
Block(0,-1,-1,CONCRETE:15)
Block(1,-1,-1,CONCRETE:15)
Block(-2,-1,0,CONCRETE:15)
Block(-1,-1,0,CONCRETE:15)
Block(0,-1,0,CONCRETE:15)
Block(1,-1,0,CONCRETE:15)
Block(2,-1,0,CONCRETE:15)
Block(-2,-1,1,CONCRETE:15)
Block(-1,-1,1,CONCRETE:15)
Block(0,-1,1,CONCRETE:15)
Block(1,-1,1,CONCRETE:15)
Block(-1,-1,2,CONCRETE:15)
Block(1,-1,2,CONCRETE:15)
Block(0,0,0,LOG:13)

#######################################################################
# +-----------------------------------------------------------------+ #
# |                            BO3 checks                           | #
# +-----------------------------------------------------------------+ #
#######################################################################

BlockCheck(-2,0,-2,Solid)
BlockCheck(-1,0,-2,Solid)
BlockCheck(0,0,-2,Solid)
BlockCheck(-1,0,-1,Solid)
BlockCheck(0,0,-1,Solid)
BlockCheck(1,0,-1,Solid)
BlockCheck(-2,0,0,Solid)
BlockCheck(-1,0,0,Solid)
BlockCheck(1,0,0,Solid)
BlockCheck(-2,0,1,Solid)
BlockCheck(-1,0,1,Solid)
BlockCheck(0,0,1,Solid)
BlockCheck(1,0,1,Solid)
BlockCheck(-1,0,2,Solid)
BlockCheck(1,0,2,Solid)

