#######################################################################
# +-----------------------------------------------------------------+ #
# |                            BO3 object                           | #
# +-----------------------------------------------------------------+ #
#######################################################################

Author: Bo3 BulkEdit

Description: Converted Schematic - Modified by Bo3BulkEdit

Version: 3

SettingsMode: WriteDisable

#######################################################################
# +-----------------------------------------------------------------+ #
# |                          Main settings                          | #
# +-----------------------------------------------------------------+ #
#######################################################################

IsOTGPlus: false
Tree: true
Frequency: 1
Rarity: 100
RotateRandomly: true
SpawnHeight: randomY
SpawnHeightOffset: 0
SpawnHeightVariance: 0
MaxBranchDepth: 10
ExcludedBiomes: All

##############################
# Height Limits for the BO3. #
##############################

MinHeight: 0
MaxHeight: 20

#######################################################################
# +-----------------------------------------------------------------+ #
# |                      Source block settings                      | #
# +-----------------------------------------------------------------+ #
#######################################################################

SourceBlocks: AIR,GRASS,DIRT,STONE,WATER
MaxPercentageOutsideSourceBlock: 0
OutsideSourceBlock: placeAnyway

ReplaceBelow: STONE
ReplaceWithBiomeBlocks: true
ReplaceWithGroundBlock: DIRT
ReplaceWithSurfaceBlock: GRASS
ReplaceWithStoneBlock: STONE
SmoothRadius: 0
SmoothHeightOffset: 0

#######################################################################
# +-----------------------------------------------------------------+ #
# |                              Blocks                             | #
# +-----------------------------------------------------------------+ #
#######################################################################

Block(0,-2,0,LOG:13)
Block(0,-1,0,LOG:13)
Block(0,1,0,LOG:13)
Block(0,2,0,LOG:13)
Block(0,3,0,LOG:13)
Block(0,4,0,LOG:13)
Block(-2,5,0,STAINED_GLASS_PANE)
Block(0,5,0,LOG:13)
Block(1,5,0,LOG:13)
Block(-1,6,-1,LOG:13)
Block(-2,6,0,STAINED_GLASS_PANE)
Block(-1,6,0,LOG:13)
Block(0,6,0,LOG:13)
Block(1,6,0,LOG:13)
Block(-1,7,-1,LOG:13)
Block(-2,7,0,STAINED_GLASS_PANE)
Block(1,7,0,LOG:13)
Block(-1,8,-2,LEAVES:4)
Block(-2,8,-1,LEAVES:8)
Block(-1,8,-1,LOG:13)
Block(0,8,-1,LEAVES:8)
Block(-2,8,0,STAINED_GLASS_PANE)
Block(-1,8,0,LEAVES:8)
Block(1,8,0,LOG:13)
Block(-2,9,-2,LEAVES:8)
Block(-1,9,-2,SEA_LANTERN)
Block(0,9,-2,LEAVES:8)
Block(-2,9,-1,SEA_LANTERN)
Block(-1,9,-1,LOG:13)
Block(0,9,-1,SEA_LANTERN)
Block(-2,9,0,LEAVES:8)
Block(-1,9,0,SEA_LANTERN)
Block(0,9,0,LEAVES:8)
Block(1,9,0,LOG:13)
Block(5,9,3,STAINED_GLASS_PANE)
Block(-1,10,-2,LEAVES:8)
Block(-2,10,-1,LEAVES:8)
Block(-1,10,-1,SEA_LANTERN)
Block(0,10,-1,LEAVES:8)
Block(-1,10,0,LEAVES:8)
Block(1,10,0,LOG:13)
Block(1,10,1,LOG:13)
Block(5,10,3,STAINED_GLASS_PANE)
Block(0,11,1,LOG:13)
Block(1,11,1,LOG:13)
Block(2,11,1,LOG:13)
Block(2,11,2,LOG:13)
Block(5,11,3,STAINED_GLASS_PANE)
Block(0,12,1,LOG:13)
Block(2,12,2,LOG:13)
Block(3,12,2,LOG:13)
Block(3,12,3,LOG:13)
Block(5,12,3,STAINED_GLASS_PANE)
Block(0,13,1,LOG:13)
Block(3,13,2,LEAVES:8)
Block(2,13,3,LEAVES:8)
Block(3,13,3,LOG:13)
Block(4,13,3,LEAVES:8)
Block(5,13,3,STAINED_GLASS_PANE)
Block(3,13,4,LEAVES:8)
Block(0,14,1,PLANKS:5)
Block(2,14,2,LEAVES:8)
Block(3,14,2,SEA_LANTERN)
Block(4,14,2,LEAVES:8)
Block(2,14,3,SEA_LANTERN)
Block(3,14,3,LOG:13)
Block(4,14,3,SEA_LANTERN)
Block(5,14,3,STAINED_GLASS_PANE)
Block(2,14,4,LEAVES:8)
Block(3,14,4,SEA_LANTERN)
Block(4,14,4,LEAVES:8)
Block(0,15,1,PLANKS:5)
Block(3,15,2,LEAVES:8)
Block(2,15,3,LEAVES:8)
Block(3,15,3,SEA_LANTERN)
Block(4,15,3,LEAVES:8)
Block(3,15,4,LEAVES:8)
Block(0,16,1,LOG:13)
Block(-3,16,2,STAINED_GLASS_PANE)
Block(0,17,0,LOG:13)
Block(-1,17,1,WOODEN_BUTTON:4)
Block(0,17,1,LOG:13)
Block(-3,17,2,STAINED_GLASS_PANE)
Block(-2,17,2,WOODEN_BUTTON:2)
Block(-1,17,2,PLANKS:5)
Block(0,17,2,LOG:13)
Block(-2,17,3,WOODEN_BUTTON:2)
Block(-1,17,3,SPRUCE_STAIRS:7)
Block(0,17,3,WOODEN_BUTTON:1)
Block(-1,17,4,WOODEN_BUTTON:3)
Block(0,18,-1,WOODEN_SLAB:9)
Block(0,18,0,PLANKS:5)
Block(-3,18,2,STAINED_GLASS_PANE)
Block(-2,18,3,WOODEN_SLAB:9)
Block(-1,18,3,PLANKS:5)
Block(0,19,-1,WOODEN_SLAB:1)
Block(0,19,0,PLANKS:5)
Block(-3,19,2,STAINED_GLASS_PANE)
Block(-2,19,3,LOG:13)
Block(-1,19,3,WOODEN_SLAB:1)
Block(4,20,-1,STAINED_GLASS_PANE)
Block(0,20,0,SPRUCE_STAIRS:3)
Block(4,20,0,STAINED_GLASS_PANE)
Block(-3,20,2,STAINED_GLASS_PANE)
Block(-2,20,2,LEAVES:8)
Block(-3,20,3,LEAVES:8)
Block(-2,20,3,LOG:13)
Block(-1,20,3,LEAVES:8)
Block(-2,20,4,LEAVES:8)
Block(3,21,-3,STAINED_GLASS_PANE)
Block(4,21,-1,STAINED_GLASS_PANE)
Block(0,21,0,LOG:13)
Block(4,21,0,STAINED_GLASS_PANE)
Block(-3,21,2,LEAVES:8)
Block(-2,21,2,SEA_LANTERN)
Block(-1,21,2,LEAVES:8)
Block(-3,21,3,SEA_LANTERN)
Block(-2,21,3,LOG:13)
Block(-1,21,3,SEA_LANTERN)
Block(-3,21,4,LEAVES:8)
Block(-2,21,4,SEA_LANTERN)
Block(-1,21,4,LEAVES:8)
Block(3,22,-3,STAINED_GLASS_PANE)
Block(4,22,-2,STAINED_GLASS_PANE)
Block(1,22,-1,WOODEN_BUTTON:4)
Block(4,22,-1,STAINED_GLASS_PANE)
Block(-1,22,0,LOG:13)
Block(0,22,0,LOG:13)
Block(1,22,0,SPRUCE_STAIRS:5)
Block(2,22,0,WOODEN_BUTTON:1)
Block(4,22,0,STAINED_GLASS_PANE)
Block(1,22,1,WOODEN_BUTTON:3)
Block(-2,22,2,LEAVES:8)
Block(-3,22,3,LEAVES:8)
Block(-2,22,3,SEA_LANTERN)
Block(-1,22,3,LEAVES:8)
Block(-2,22,4,LEAVES:8)
Block(3,23,-3,STAINED_GLASS_PANE)
Block(4,23,-2,STAINED_GLASS_PANE)
Block(1,23,-1,LOG:13)
Block(2,23,-1,PLANKS:5)
Block(4,23,-1,STAINED_GLASS_PANE)
Block(-1,23,0,PLANKS:5)
Block(1,23,0,LOG:13)
Block(4,23,0,STAINED_GLASS_PANE)
Block(-5,23,2,STAINED_GLASS_PANE)
Block(3,24,-3,STAINED_GLASS_PANE)
Block(2,24,-2,LEAVES:8)
Block(4,24,-2,STAINED_GLASS_PANE)
Block(1,24,-1,LEAVES:8)
Block(2,24,-1,LOG:13)
Block(3,24,-1,LEAVES:8)
Block(4,24,-1,STAINED_GLASS_PANE)
Block(-1,24,0,LOG:13)
Block(2,24,0,LEAVES:8)
Block(4,24,0,STAINED_GLASS_PANE)
Block(-5,24,2,STAINED_GLASS_PANE)
Block(2,25,-3,LEAVES:8)
Block(3,25,-3,STAINED_GLASS_PANE)
Block(1,25,-2,LEAVES:8)
Block(2,25,-2,SEA_LANTERN)
Block(3,25,-2,LEAVES:8)
Block(4,25,-2,STAINED_GLASS_PANE)
Block(0,25,-1,LEAVES:8)
Block(1,25,-1,SEA_LANTERN)
Block(2,25,-1,LOG:13)
Block(3,25,-1,SEA_LANTERN)
Block(4,25,-1,LEAVES:8)
Block(-1,25,0,LOG:13)
Block(1,25,0,LEAVES:8)
Block(2,25,0,SEA_LANTERN)
Block(3,25,0,LEAVES:8)
Block(4,25,0,STAINED_GLASS_PANE)
Block(-5,25,1,STAINED_GLASS_PANE)
Block(2,25,1,LEAVES:8)
Block(-5,25,2,STAINED_GLASS_PANE)
Block(1,26,-3,LEAVES:8)
Block(2,26,-3,LEAVES:8)
Block(3,26,-3,LEAVES:8)
Block(0,26,-2,LEAVES:8)
Block(1,26,-2,SEA_LANTERN)
Block(2,26,-2,SEA_LANTERN)
Block(3,26,-2,SEA_LANTERN)
Block(4,26,-2,LEAVES:8)
Block(0,26,-1,LEAVES:8)
Block(1,26,-1,SEA_LANTERN)
Block(2,26,-1,LOG:13)
Block(3,26,-1,SEA_LANTERN)
Block(4,26,-1,LEAVES:8)
Block(-1,26,0,LOG:13)
Block(0,26,0,LEAVES:8)
Block(1,26,0,SEA_LANTERN)
Block(2,26,0,SEA_LANTERN)
Block(3,26,0,SEA_LANTERN)
Block(4,26,0,LEAVES:8)
Block(-5,26,1,STAINED_GLASS_PANE)
Block(1,26,1,LEAVES:8)
Block(2,26,1,LEAVES:8)
Block(3,26,1,LEAVES:8)
Block(-5,26,2,STAINED_GLASS_PANE)
Block(-1,26,3,STAINED_GLASS_PANE)
Block(2,27,-3,LEAVES:8)
Block(1,27,-2,LEAVES:8)
Block(2,27,-2,SEA_LANTERN)
Block(3,27,-2,LEAVES:8)
Block(-1,27,-1,LOG:13)
Block(0,27,-1,LEAVES:8)
Block(1,27,-1,SEA_LANTERN)
Block(2,27,-1,SEA_LANTERN)
Block(3,27,-1,SEA_LANTERN)
Block(4,27,-1,LEAVES:8)
Block(-1,27,0,LOG:13)
Block(1,27,0,LEAVES:8)
Block(2,27,0,SEA_LANTERN)
Block(3,27,0,LEAVES:8)
Block(-5,27,1,STAINED_GLASS_PANE)
Block(-2,27,1,LOG:13)
Block(-1,27,1,LOG:13)
Block(2,27,1,LEAVES:8)
Block(-5,27,2,STAINED_GLASS_PANE)
Block(-1,27,3,STAINED_GLASS_PANE)
Block(2,28,-2,LEAVES:8)
Block(-1,28,-1,LOG:13)
Block(0,28,-1,LOG:13)
Block(1,28,-1,LEAVES:8)
Block(2,28,-1,LEAVES:8)
Block(3,28,-1,LEAVES:8)
Block(2,28,0,LEAVES:8)
Block(-5,28,1,STAINED_GLASS_PANE)
Block(-2,28,1,LOG:13)
Block(-5,28,2,STAINED_GLASS_PANE)
Block(-3,28,2,LOG:13)
Block(-2,28,2,LOG:13)
Block(-1,28,3,STAINED_GLASS_PANE)
Block(-2,28,4,STAINED_GLASS_PANE)
Block(0,29,-1,LOG:13)
Block(-5,29,1,STAINED_GLASS_PANE)
Block(-3,29,1,LEAVES:8)
Block(-5,29,2,STAINED_GLASS_PANE)
Block(-4,29,2,LEAVES:8)
Block(-3,29,2,LOG:13)
Block(-2,29,2,LEAVES:8)
Block(-3,29,3,LEAVES:8)
Block(-1,29,3,STAINED_GLASS_PANE)
Block(-2,29,4,STAINED_GLASS_PANE)
Block(0,30,-1,LOG:13)
Block(-3,30,0,LEAVES:8)
Block(-5,30,1,STAINED_GLASS_PANE)
Block(-4,30,1,LEAVES:8)
Block(-3,30,1,SEA_LANTERN)
Block(-2,30,1,LEAVES:8)
Block(-5,30,2,LEAVES:8)
Block(-4,30,2,SEA_LANTERN)
Block(-3,30,2,LOG:13)
Block(-2,30,2,SEA_LANTERN)
Block(-1,30,2,LEAVES:8)
Block(-4,30,3,LEAVES:8)
Block(-3,30,3,SEA_LANTERN)
Block(-2,30,3,LEAVES:8)
Block(-1,30,3,STAINED_GLASS_PANE)
Block(-3,30,4,LEAVES:8)
Block(-2,30,4,STAINED_GLASS_PANE)
Block(0,31,-2,LEAVES:8)
Block(-1,31,-1,LEAVES:8)
Block(0,31,-1,LOG:13)
Block(1,31,-1,LEAVES:8)
Block(-4,31,0,LEAVES:8)
Block(-3,31,0,LEAVES:8)
Block(-2,31,0,LEAVES:8)
Block(0,31,0,LEAVES:8)
Block(-5,31,1,LEAVES:8)
Block(-4,31,1,SEA_LANTERN)
Block(-3,31,1,SEA_LANTERN)
Block(-2,31,1,SEA_LANTERN)
Block(-1,31,1,LEAVES:8)
Block(1,31,1,STAINED_GLASS_PANE)
Block(-5,31,2,LEAVES:8)
Block(-4,31,2,SEA_LANTERN)
Block(-3,31,2,LOG:13)
Block(-2,31,2,SEA_LANTERN)
Block(-1,31,2,SEA_LANTERN)
Block(-5,31,3,LEAVES:8)
Block(-4,31,3,SEA_LANTERN)
Block(-3,31,3,SEA_LANTERN)
Block(-2,31,3,SEA_LANTERN)
Block(-1,31,3,LEAVES:8)
Block(-4,31,4,LEAVES:8)
Block(-3,31,4,LEAVES:8)
Block(-2,31,4,LEAVES:8)
Block(0,32,-3,LEAVES:8)
Block(-1,32,-2,LEAVES:8)
Block(0,32,-2,SEA_LANTERN)
Block(1,32,-2,LEAVES:8)
Block(-2,32,-1,LEAVES:8)
Block(-1,32,-1,SEA_LANTERN)
Block(0,32,-1,LOG:13)
Block(1,32,-1,SEA_LANTERN)
Block(2,32,-1,LEAVES:8)
Block(-3,32,0,LEAVES:8)
Block(-1,32,0,LEAVES:8)
Block(0,32,0,SEA_LANTERN)
Block(1,32,0,LEAVES:8)
Block(-4,32,1,LEAVES:8)
Block(-3,32,1,SEA_LANTERN)
Block(-2,32,1,LEAVES:8)
Block(0,32,1,LEAVES:8)
Block(1,32,1,STAINED_GLASS_PANE)
Block(-5,32,2,LEAVES:8)
Block(-4,32,2,SEA_LANTERN)
Block(-3,32,2,SEA_LANTERN)
Block(-2,32,2,SEA_LANTERN)
Block(-1,32,2,LEAVES:8)
Block(-4,32,3,LEAVES:8)
Block(-3,32,3,SEA_LANTERN)
Block(-2,32,3,LEAVES:8)
Block(-3,32,4,LEAVES:8)
Block(-1,33,-3,LEAVES:8)
Block(0,33,-3,LEAVES:8)
Block(1,33,-3,LEAVES:8)
Block(-2,33,-2,LEAVES:8)
Block(-1,33,-2,SEA_LANTERN)
Block(0,33,-2,SEA_LANTERN)
Block(1,33,-2,SEA_LANTERN)
Block(2,33,-2,LEAVES:8)
Block(-2,33,-1,LEAVES:8)
Block(-1,33,-1,SEA_LANTERN)
Block(0,33,-1,LOG:13)
Block(1,33,-1,SEA_LANTERN)
Block(2,33,-1,LEAVES:8)
Block(-2,33,0,LEAVES:8)
Block(-1,33,0,SEA_LANTERN)
Block(0,33,0,LOG:13)
Block(1,33,0,SEA_LANTERN)
Block(2,33,0,LEAVES:8)
Block(-3,33,1,LEAVES:8)
Block(-1,33,1,LEAVES:8)
Block(0,33,1,LEAVES:8)
Block(1,33,1,LEAVES:8)
Block(-4,33,2,LEAVES:8)
Block(-3,33,2,LEAVES:8)
Block(-2,33,2,LEAVES:8)
Block(-3,33,3,LEAVES:8)
Block(0,34,-3,LEAVES:8)
Block(-1,34,-2,LEAVES:8)
Block(0,34,-2,SEA_LANTERN)
Block(1,34,-2,LEAVES:8)
Block(-2,34,-1,LEAVES:8)
Block(-1,34,-1,SEA_LANTERN)
Block(0,34,-1,SEA_LANTERN)
Block(1,34,-1,SEA_LANTERN)
Block(2,34,-1,LEAVES:8)
Block(-1,34,0,LEAVES:8)
Block(0,34,0,SEA_LANTERN)
Block(1,34,0,LEAVES:8)
Block(0,34,1,LEAVES:8)
Block(0,35,-2,LEAVES:8)
Block(-1,35,-1,LEAVES:8)
Block(0,35,-1,LEAVES:8)
Block(1,35,-1,LEAVES:8)
Block(0,35,0,LEAVES:8)
Block(0,0,0,LOG:2)

BC(0,0,0,STONE,GRASS)