#######################################################################
# +-----------------------------------------------------------------+ #
# |                            BO3 object                           | #
# +-----------------------------------------------------------------+ #
#######################################################################

Author: Bo3 BulkEdit

Description: Converted Schematic - Modified by Bo3BulkEdit

Version: 3

SettingsMode: WriteDisable

#######################################################################
# +-----------------------------------------------------------------+ #
# |                          Main settings                          | #
# +-----------------------------------------------------------------+ #
#######################################################################

IsOTGPlus: false
Tree: true
Frequency: 1
Rarity: 100
RotateRandomly: true
SpawnHeight: randomY
SpawnHeightOffset: 0
SpawnHeightVariance: 0
MaxBranchDepth: 10
ExcludedBiomes: All

##############################
# Height Limits for the BO3. #
##############################

MinHeight: 65
MaxHeight: 70

#######################################################################
# +-----------------------------------------------------------------+ #
# |                      Source block settings                      | #
# +-----------------------------------------------------------------+ #
#######################################################################

SourceBlocks: AIR,GRASS,DIRT,STONE
MaxPercentageOutsideSourceBlock: 0
OutsideSourceBlock: placeAnyway

ReplaceBelow: STONE
ReplaceWithBiomeBlocks: true
ReplaceWithGroundBlock: DIRT
ReplaceWithSurfaceBlock: GRASS
ReplaceWithStoneBlock: STONE
SmoothRadius: 0
SmoothHeightOffset: 0

#######################################################################
# +-----------------------------------------------------------------+ #
# |                              Blocks                             | #
# +-----------------------------------------------------------------+ #
#######################################################################

Block(3,-33,-4,LEAVES:4)
Block(2,-33,-3,LEAVES:4)
Block(3,-33,-3,LEAVES:4)
Block(4,-33,-3,LEAVES:4)
Block(3,-33,-2,LEAVES:4)
Block(3,-32,-5,LEAVES:4)
Block(2,-32,-4,LEAVES:4)
Block(3,-32,-4,LEAVES:4)
Block(4,-32,-4,LEAVES:4)
Block(1,-32,-3,LEAVES:4)
Block(2,-32,-3,LEAVES:4)
Block(3,-32,-3,LOG:13)
Block(4,-32,-3,LEAVES:4)
Block(5,-32,-3,LEAVES:4)
Block(2,-32,-2,LEAVES:4)
Block(3,-32,-2,LEAVES:4)
Block(4,-32,-2,LEAVES:4)
Block(3,-32,-1,LEAVES:4)
Block(3,-31,-5,LEAVES:4)
Block(2,-31,-4,LEAVES:4)
Block(3,-31,-4,LEAVES:4)
Block(4,-31,-4,LEAVES:4)
Block(1,-31,-3,LEAVES:4)
Block(2,-31,-3,LEAVES:12)
Block(3,-31,-3,SEA_LANTERN)
Block(4,-31,-3,LEAVES:4)
Block(5,-31,-3,LEAVES:4)
Block(2,-31,-2,LEAVES:12)
Block(3,-31,-2,LEAVES:12)
Block(4,-31,-2,LEAVES:4)
Block(3,-31,-1,LEAVES:4)
Block(3,-30,-4,LEAVES:4)
Block(2,-30,-3,LEAVES:12)
Block(3,-30,-3,LOG:13)
Block(4,-30,-3,LEAVES:4)
Block(3,-30,-2,LEAVES:4)
Block(3,-29,-3,LOG:13)
Block(0,-29,2,LEAVES:12)
Block(-1,-29,3,LEAVES:12)
Block(0,-29,3,LEAVES:12)
Block(1,-29,3,LEAVES:12)
Block(0,-29,4,LEAVES:12)
Block(3,-28,-3,LOG:13)
Block(0,-28,1,LEAVES:12)
Block(-1,-28,2,LEAVES:12)
Block(0,-28,2,LEAVES:12)
Block(1,-28,2,LEAVES:12)
Block(-2,-28,3,LEAVES:12)
Block(-1,-28,3,LEAVES:12)
Block(0,-28,3,LOG:13)
Block(1,-28,3,LEAVES:12)
Block(2,-28,3,LEAVES:12)
Block(-1,-28,4,LEAVES:12)
Block(0,-28,4,LEAVES:12)
Block(1,-28,4,LEAVES:12)
Block(0,-28,5,LEAVES:12)
Block(2,-27,-3,LOG:13)
Block(3,-27,-3,LOG:13)
Block(0,-27,1,LEAVES:12)
Block(-1,-27,2,LEAVES:12)
Block(0,-27,2,LEAVES:12)
Block(1,-27,2,LEAVES:12)
Block(-2,-27,3,LEAVES:12)
Block(-1,-27,3,LEAVES:12)
Block(0,-27,3,SEA_LANTERN)
Block(1,-27,3,LEAVES:12)
Block(2,-27,3,LEAVES:12)
Block(-1,-27,4,LEAVES:12)
Block(0,-27,4,LEAVES:12)
Block(1,-27,4,LEAVES:12)
Block(0,-27,5,LEAVES:12)
Block(-3,-26,-3,LEAVES:4)
Block(2,-26,-3,LOG:13)
Block(-4,-26,-2,LEAVES:4)
Block(-3,-26,-2,LEAVES:4)
Block(-2,-26,-2,LEAVES:12)
Block(-3,-26,-1,LEAVES:12)
Block(0,-26,2,LEAVES:12)
Block(-1,-26,3,LEAVES:12)
Block(0,-26,3,LOG:13)
Block(1,-26,3,LEAVES:12)
Block(0,-26,4,LEAVES:12)
Block(-3,-25,-4,LEAVES:12)
Block(-4,-25,-3,LEAVES:12)
Block(-3,-25,-3,LEAVES:12)
Block(-2,-25,-3,LEAVES:12)
Block(1,-25,-3,BIRCH_FENCE)
Block(2,-25,-3,LOG:13)
Block(-5,-25,-2,LEAVES:12)
Block(-4,-25,-2,LEAVES:12)
Block(-3,-25,-2,LOG:13)
Block(-2,-25,-2,LEAVES:12)
Block(-1,-25,-2,LEAVES:12)
Block(-4,-25,-1,LEAVES:12)
Block(-3,-25,-1,LEAVES:12)
Block(-2,-25,-1,LEAVES:12)
Block(-3,-25,0,LEAVES:12)
Block(0,-25,3,LOG)
Block(-3,-24,-4,LEAVES:12)
Block(2,-24,-4,WOODEN_BUTTON:4)
Block(-4,-24,-3,LEAVES:12)
Block(-3,-24,-3,LEAVES:12)
Block(-2,-24,-3,LEAVES:12)
Block(1,-24,-3,BIRCH_FENCE)
Block(2,-24,-3,LOG:13)
Block(3,-24,-3,WOODEN_BUTTON:1)
Block(-5,-24,-2,LEAVES:12)
Block(-4,-24,-2,LEAVES:12)
Block(-3,-24,-2,SEA_LANTERN)
Block(-2,-24,-2,LEAVES:12)
Block(-1,-24,-2,LEAVES:12)
Block(2,-24,-2,WOODEN_BUTTON:3)
Block(-4,-24,-1,LEAVES:12)
Block(-3,-24,-1,LEAVES:12)
Block(-2,-24,-1,LEAVES:12)
Block(-3,-24,0,LEAVES:12)
Block(0,-24,3,LOG)
Block(1,-24,3,BIRCH_FENCE)
Block(-6,-23,-4,BIRCH_FENCE)
Block(-3,-23,-3,LEAVES:12)
Block(1,-23,-3,BIRCH_FENCE)
Block(2,-23,-3,LOG)
Block(-4,-23,-2,LEAVES:12)
Block(-3,-23,-2,LOG:13)
Block(-2,-23,-2,LEAVES:12)
Block(-3,-23,-1,LEAVES:12)
Block(4,-23,1,LEAVES:12)
Block(3,-23,2,LEAVES:12)
Block(4,-23,2,LEAVES:12)
Block(5,-23,2,LEAVES:12)
Block(0,-23,3,LOG:13)
Block(1,-23,3,BIRCH_FENCE)
Block(4,-23,3,LEAVES:12)
Block(0,-23,4,BIRCH_FENCE)
Block(1,-23,4,BIRCH_FENCE)
Block(-6,-22,-4,BIRCH_FENCE)
Block(2,-22,-4,OAK_STAIRS:6)
Block(1,-22,-3,BIRCH_FENCE)
Block(2,-22,-3,LOG)
Block(-3,-22,-2,LOG:13)
Block(4,-22,0,LEAVES:12)
Block(3,-22,1,LEAVES:12)
Block(4,-22,1,LEAVES:12)
Block(5,-22,1,LEAVES:12)
Block(0,-22,2,LOG:13)
Block(2,-22,2,LEAVES:12)
Block(3,-22,2,LEAVES:12)
Block(4,-22,2,LOG:13)
Block(5,-22,2,LEAVES:12)
Block(6,-22,2,LEAVES:4)
Block(0,-22,3,LOG:13)
Block(3,-22,3,LEAVES:12)
Block(4,-22,3,LEAVES:12)
Block(5,-22,3,LEAVES:12)
Block(0,-22,4,BIRCH_FENCE)
Block(4,-22,4,LEAVES:12)
Block(-6,-21,-4,BIRCH_FENCE)
Block(-5,-21,-4,BIRCH_FENCE)
Block(2,-21,-4,WOODEN_SLAB:5)
Block(2,-21,-3,LOG)
Block(-3,-21,-2,LOG)
Block(4,-21,0,LEAVES:12)
Block(3,-21,1,LEAVES:12)
Block(4,-21,1,LEAVES:12)
Block(5,-21,1,LEAVES:12)
Block(0,-21,2,LOG:13)
Block(2,-21,2,LEAVES:12)
Block(3,-21,2,LEAVES:12)
Block(4,-21,2,SEA_LANTERN)
Block(5,-21,2,LEAVES:12)
Block(6,-21,2,LEAVES:4)
Block(0,-21,3,BIRCH_FENCE)
Block(3,-21,3,LEAVES:12)
Block(4,-21,3,LEAVES:12)
Block(5,-21,3,LEAVES:12)
Block(4,-21,4,LEAVES:12)
Block(-5,-20,-4,BIRCH_FENCE)
Block(-5,-20,-3,BIRCH_FENCE)
Block(-4,-20,-3,BIRCH_FENCE)
Block(2,-20,-3,LOG:13)
Block(-3,-20,-2,LOG)
Block(0,-20,1,WOODEN_BUTTON:4)
Block(4,-20,1,LEAVES:12)
Block(-1,-20,2,WOODEN_BUTTON:2)
Block(0,-20,2,LOG:13)
Block(1,-20,2,WOODEN_BUTTON:1)
Block(3,-20,2,LEAVES:12)
Block(4,-20,2,LOG:13)
Block(5,-20,2,LEAVES:12)
Block(0,-20,3,WOODEN_BUTTON:3)
Block(4,-20,3,LEAVES:12)
Block(-4,-19,-3,BIRCH_FENCE)
Block(1,-19,-3,LOG:13)
Block(2,-19,-3,LOG:13)
Block(-4,-19,-2,BIRCH_FENCE)
Block(-3,-19,-2,LOG:13)
Block(1,-19,-2,LOG:13)
Block(-3,-19,-1,LOG:13)
Block(-1,-19,2,BIRCH_FENCE)
Block(0,-19,2,LOG:13)
Block(4,-19,2,LOG:13)
Block(0,-18,-6,BIRCH_FENCE)
Block(0,-18,-5,BIRCH_FENCE)
Block(-3,-18,-2,WOODEN_BUTTON:4)
Block(1,-18,-2,LOG:13)
Block(-4,-18,-1,WOODEN_BUTTON:2)
Block(-3,-18,-1,LOG:13)
Block(-2,-18,-1,WOODEN_BUTTON:1)
Block(-3,-18,0,WOODEN_BUTTON:3)
Block(-1,-18,2,BIRCH_FENCE)
Block(0,-18,2,LOG:13)
Block(4,-18,2,LOG:13)
Block(5,-18,2,BIRCH_FENCE)
Block(0,-17,-5,BIRCH_FENCE)
Block(1,-17,-2,LOG:13)
Block(-4,-17,-1,OAK_STAIRS:4)
Block(-3,-17,-1,LOG:13)
Block(-3,-17,1,BIRCH_FENCE)
Block(0,-17,1,LOG:13)
Block(3,-17,1,LOG:13)
Block(4,-17,1,LOG:13)
Block(5,-17,1,BIRCH_FENCE)
Block(-1,-17,2,BIRCH_FENCE)
Block(0,-17,2,LOG:13)
Block(4,-17,2,LOG:13)
Block(5,-17,2,BIRCH_FENCE)
Block(0,-16,-5,BIRCH_FENCE)
Block(0,-16,-4,BIRCH_FENCE)
Block(1,-16,-2,LOG:13)
Block(-4,-16,-1,WOODEN_SLAB:5)
Block(-3,-16,-1,LOG:13)
Block(-3,-16,1,BIRCH_FENCE)
Block(0,-16,1,LOG:13)
Block(3,-16,1,LOG)
Block(4,-16,1,BIRCH_FENCE)
Block(5,-16,1,BIRCH_FENCE)
Block(0,-16,2,BIRCH_FENCE)
Block(0,-15,-4,BIRCH_FENCE)
Block(0,-15,-3,BIRCH_FENCE)
Block(1,-15,-3,BIRCH_FENCE)
Block(1,-15,-2,LOG:13)
Block(-3,-15,-1,LOG:13)
Block(-2,-15,-1,LOG:13)
Block(-3,-15,0,BIRCH_FENCE)
Block(-2,-15,0,LOG:13)
Block(-3,-15,1,BIRCH_FENCE)
Block(0,-15,1,LOG:13)
Block(3,-15,1,LOG)
Block(1,-14,-2,LOG:13)
Block(-3,-14,-1,BIRCH_FENCE)
Block(-2,-14,-1,BIRCH_FENCE)
Block(1,-14,-1,LOG:13)
Block(-2,-14,0,LOG:13)
Block(3,-14,0,WOODEN_BUTTON:4)
Block(0,-14,1,LOG:13)
Block(2,-14,1,WOODEN_BUTTON:2)
Block(3,-14,1,LOG:13)
Block(4,-14,1,WOODEN_BUTTON:1)
Block(3,-14,2,WOODEN_BUTTON:3)
Block(0,-14,4,BIRCH_FENCE)
Block(0,-14,5,BIRCH_FENCE)
Block(-2,-13,-1,BIRCH_FENCE)
Block(1,-13,-1,LOG:13)
Block(-2,-13,0,LOG)
Block(0,-13,1,LOG:13)
Block(2,-13,1,LOG:13)
Block(3,-13,1,LOG:13)
Block(0,-13,2,DARK_OAK_STAIRS:7)
Block(0,-13,4,BIRCH_FENCE)
Block(1,-12,-1,LOG:13)
Block(-2,-12,0,LOG)
Block(0,-12,1,LOG:13)
Block(2,-12,1,LOG:13)
Block(3,-12,1,BIRCH_FENCE)
Block(0,-12,2,BIRCH_FENCE)
Block(0,-12,3,BIRCH_FENCE)
Block(0,-12,4,BIRCH_FENCE)
Block(0,-11,-1,LOG:13)
Block(1,-11,-1,LOG:13)
Block(-2,-11,0,LOG)
Block(0,-11,1,LOG:13)
Block(2,-11,1,LOG:13)
Block(3,-11,1,BIRCH_FENCE)
Block(0,-10,-1,LOG:13)
Block(1,-10,-1,BIRCH_FENCE)
Block(-2,-10,0,LOG:13)
Block(-1,-10,0,LOG:13)
Block(0,-10,1,LOG)
Block(2,-10,1,LOG:13)
Block(3,-10,1,BIRCH_FENCE)
Block(-1,-9,-1,BIRCH_FENCE)
Block(0,-9,-1,LOG:13)
Block(1,-9,-1,BIRCH_FENCE)
Block(-2,-9,0,WOODEN_SLAB:5)
Block(-1,-9,0,LOG:13)
Block(0,-9,1,LOG)
Block(2,-9,1,LOG:13)
Block(-1,-8,-1,BIRCH_FENCE)
Block(0,-8,-1,LOG:13)
Block(1,-8,-1,BIRCH_FENCE)
Block(-1,-8,0,LOG:13)
Block(0,-8,0,LOG:13)
Block(1,-8,0,LOG:13)
Block(2,-8,0,LOG:13)
Block(0,-8,1,DARK_OAK_STAIRS:3)
Block(2,-8,1,LOG:13)
Block(1,-7,-1,BIRCH_FENCE)
Block(0,-7,0,LOG:13)
Block(1,-7,0,LOG:13)
Block(0,-6,0,LOG)
Block(1,-6,0,DARK_OAK_STAIRS:1)
Block(0,-5,0,LOG)
Block(0,-4,0,LOG)
Block(0,-3,0,LOG:13)
Block(0,-2,0,LOG:13)
Block(0,-1,0,LOG:13)
Block(0,0,0,LOG:13)

BC(0,0,0,STONE)