#######################################################################
# +-----------------------------------------------------------------+ #
# |                            BO3 object                           | #
# +-----------------------------------------------------------------+ #
#######################################################################

Author: Bo3 BulkEdit

Description: Converted Schematic - Modified by Bo3BulkEdit

Version: 3

SettingsMode: WriteDisable

#######################################################################
# +-----------------------------------------------------------------+ #
# |                          Main settings                          | #
# +-----------------------------------------------------------------+ #
#######################################################################

IsOTGPlus: false
Tree: true
Frequency: 1
Rarity: 100
RotateRandomly: true
SpawnHeight: randomY
SpawnHeightOffset: 0
SpawnHeightVariance: 0
MaxBranchDepth: 10
ExcludedBiomes: All

##############################
# Height Limits for the BO3. #
##############################

MinHeight: 0
MaxHeight: 20

#######################################################################
# +-----------------------------------------------------------------+ #
# |                      Source block settings                      | #
# +-----------------------------------------------------------------+ #
#######################################################################

SourceBlocks: AIR,GRASS,DIRT,STONE,WATER
MaxPercentageOutsideSourceBlock: 0
OutsideSourceBlock: placeAnyway

ReplaceBelow: STONE
ReplaceWithBiomeBlocks: true
ReplaceWithGroundBlock: DIRT
ReplaceWithSurfaceBlock: GRASS
ReplaceWithStoneBlock: STONE
SmoothRadius: 0
SmoothHeightOffset: 0

#######################################################################
# +-----------------------------------------------------------------+ #
# |                              Blocks                             | #
# +-----------------------------------------------------------------+ #
#######################################################################

Block(10,1,-4,WEB)
Block(2,1,-1,LOG:12)
Block(0,1,0,LOG2:13)
Block(1,1,0,LOG:12)
Block(9,1,0,WEB)
Block(-1,1,1,LOG:12)
Block(0,1,1,LOG:12)
Block(5,2,-6,WEB)
Block(5,2,-5,WEB)
Block(11,2,-5,LEAVES:8)
Block(0,2,0,LOG:12)
Block(1,2,0,LOG:12)
Block(10,2,0,WEB)
Block(11,3,-6,LEAVES:8)
Block(5,3,-5,WEB)
Block(11,3,-5,SPRUCE_FENCE)
Block(10,3,-4,SPRUCE_FENCE)
Block(11,3,-4,SPRUCE_FENCE)
Block(-5,3,-2,WEB)
Block(-4,3,-2,WEB)
Block(1,3,-1,LOG2:13)
Block(2,3,-1,LOG2:13)
Block(1,3,0,LOG2:13)
Block(9,3,0,WEB)
Block(-4,3,1,WEB)
Block(9,3,1,WEB)
Block(-5,3,4,WEB)
Block(11,4,-6,LEAVES:8)
Block(6,4,-5,LEAVES:8)
Block(11,4,-5,LEAVES:8)
Block(10,4,-4,SPRUCE_FENCE)
Block(7,4,-3,LOG2:13)
Block(8,4,-3,LOG:12)
Block(9,4,-3,LOG:12)
Block(10,4,-3,SPRUCE_FENCE)
Block(-4,4,-2,WEB)
Block(2,4,-1,LOG2:13)
Block(3,4,-1,STAINED_HARDENED_CLAY:12)
Block(8,4,-1,WEB)
Block(-4,4,2,WEB)
Block(-5,4,3,WEB)
Block(5,5,-5,LEAVES:8)
Block(6,5,-5,LEAVES:8)
Block(11,5,-5,LEAVES:8)
Block(-4,5,-3,WEB)
Block(5,5,-3,LOG2:13)
Block(6,5,-3,LOG2:13)
Block(7,5,-3,LOG2:13)
Block(4,5,-2,LOG2:13)
Block(5,5,-2,LOG2:13)
Block(7,5,-2,SPRUCE_FENCE)
Block(8,5,-2,SPRUCE_FENCE)
Block(-2,5,-1,WEB)
Block(3,5,-1,LOG2:13)
Block(4,5,-1,STAINED_HARDENED_CLAY:12)
Block(8,5,-1,SPRUCE_FENCE)
Block(-2,5,0,WEB)
Block(3,5,0,STAINED_HARDENED_CLAY:12)
Block(9,5,0,WEB)
Block(-5,5,1,WEB)
Block(-4,5,1,WEB)
Block(7,5,2,WEB)
Block(-5,5,4,WEB)
Block(-4,5,4,WEB)
Block(8,5,6,WEB)
Block(-2,6,-7,WEB)
Block(-1,6,-7,WEB)
Block(0,6,-7,WEB)
Block(4,6,-7,WEB)
Block(0,6,-6,WEB)
Block(5,6,-6,SPRUCE_FENCE)
Block(5,6,-5,SPRUCE_FENCE)
Block(4,6,-4,LEAVES:8)
Block(5,6,-4,SPRUCE_FENCE)
Block(6,6,-4,SPRUCE_FENCE)
Block(-1,6,-3,WEB)
Block(6,6,-3,SPRUCE_FENCE)
Block(8,6,-3,LEAVES:8)
Block(-4,6,-2,WEB)
Block(4,6,-2,STAINED_HARDENED_CLAY:12)
Block(-2,6,-1,WEB)
Block(3,6,-1,STAINED_HARDENED_CLAY:12)
Block(4,6,-1,LOG2:13)
Block(8,6,-1,SPRUCE_FENCE)
Block(9,6,-1,SPRUCE_FENCE)
Block(-3,6,0,WEB)
Block(1,6,0,LOG:12)
Block(2,6,0,STAINED_HARDENED_CLAY:12)
Block(3,6,0,LOG2:13)
Block(9,6,0,SPRUCE_FENCE)
Block(10,6,0,LEAVES:8)
Block(0,6,1,LOG2:13)
Block(1,6,1,LOG:12)
Block(6,6,2,WEB)
Block(0,6,4,WEB)
Block(-6,6,5,LEAVES:8)
Block(0,6,5,WEB)
Block(7,6,6,WEB)
Block(-3,7,-8,WEB)
Block(-2,7,-7,WEB)
Block(3,7,-7,WEB)
Block(0,7,-6,WEB)
Block(-1,7,-5,WEB)
Block(5,7,-5,LEAVES:8)
Block(4,7,-4,LEAVES:8)
Block(0,7,-3,LEAVES:8)
Block(8,7,-3,LEAVES:8)
Block(8,7,-2,LEAVES:8)
Block(9,7,-2,LEAVES:8)
Block(-5,7,-1,SPRUCE_FENCE)
Block(-3,7,-1,LEAVES:8)
Block(4,7,-1,STAINED_HARDENED_CLAY:12)
Block(-5,7,0,SPRUCE_FENCE)
Block(9,7,0,LEAVES:8)
Block(10,7,0,LEAVES:8)
Block(-4,7,1,LEAVES:8)
Block(0,7,1,LOG2:13)
Block(7,7,1,WEB)
Block(-1,7,2,LOG2:13)
Block(0,7,2,LOG2:13)
Block(7,7,2,WEB)
Block(1,7,3,WEB)
Block(-5,7,4,LEAVES:8)
Block(-3,7,4,SEA_LANTERN)
Block(0,7,4,WEB)
Block(-6,7,5,LEAVES:8)
Block(1,7,5,WEB)
Block(8,7,5,WEB)
Block(1,7,6,WEB)
Block(8,7,6,WEB)
Block(4,8,-8,WEB)
Block(-2,8,-7,WEB)
Block(4,8,-7,WEB)
Block(-3,8,-6,WEB)
Block(0,8,-6,SEA_LANTERN)
Block(1,8,-5,WEB)
Block(5,8,-5,LEAVES:8)
Block(-1,8,-3,LEAVES:8)
Block(0,8,-3,LEAVES:8)
Block(3,8,-3,LOG2:13)
Block(-4,8,-2,LEAVES:8)
Block(-1,8,-2,LEAVES:8)
Block(3,8,-2,LOG2:13)
Block(4,8,-2,LOG2:13)
Block(8,8,-2,LEAVES:8)
Block(9,8,-2,LEAVES:8)
Block(-3,8,-1,LEAVES:8)
Block(-2,8,-1,LEAVES:8)
Block(4,8,-1,LOG:12)
Block(5,8,-1,LOG:12)
Block(7,8,-1,LEAVES:8)
Block(-5,8,0,SPRUCE_FENCE)
Block(-4,8,0,SPRUCE_FENCE)
Block(-1,8,0,SPRUCE_FENCE)
Block(0,8,0,SPRUCE_FENCE)
Block(2,8,0,WEB)
Block(9,8,0,LEAVES:8)
Block(-4,8,1,SPRUCE_FENCE)
Block(0,8,1,SPRUCE_FENCE)
Block(2,8,1,WEB)
Block(-4,8,2,SPRUCE_FENCE)
Block(-3,8,2,SPRUCE_FENCE)
Block(-1,8,2,LOG:12)
Block(-5,8,3,LEAVES:8)
Block(-3,8,3,LOG:12)
Block(-2,8,3,LOG2:13)
Block(-1,8,3,LOG2:13)
Block(3,8,3,WEB)
Block(4,8,3,WEB)
Block(8,8,3,LEAVES:8)
Block(-5,8,4,SPRUCE_FENCE)
Block(-4,8,4,LOG:12)
Block(-3,8,4,LOG:12)
Block(0,8,4,LEAVES:8)
Block(2,8,4,LEAVES:8)
Block(1,8,5,LEAVES:8)
Block(9,8,7,WEB)
Block(-2,9,-7,SPRUCE_FENCE)
Block(-1,9,-7,SPRUCE_FENCE)
Block(-1,9,-6,SPRUCE_FENCE)
Block(0,9,-6,LOG:12)
Block(1,9,-6,LOG:12)
Block(5,9,-6,WEB)
Block(1,9,-5,LOG:12)
Block(2,9,-5,LOG:12)
Block(-2,9,-4,LEAVES:8)
Block(2,9,-4,LOG:12)
Block(-1,9,-3,LEAVES:8)
Block(2,9,-3,LOG2:13)
Block(3,9,-3,LOG2:13)
Block(-4,9,-2,LEAVES:8)
Block(-1,9,-2,SPRUCE_FENCE)
Block(8,9,-2,LEAVES:8)
Block(-2,9,-1,LEAVES:8)
Block(-1,9,-1,SPRUCE_FENCE)
Block(3,9,-1,WEB)
Block(5,9,-1,LOG2:13)
Block(7,9,-1,LEAVES:8)
Block(-1,9,0,SPRUCE_FENCE)
Block(2,9,0,WEB)
Block(5,9,0,LOG2:13)
Block(6,9,0,LOG2:13)
Block(-4,9,1,LEAVES:8)
Block(6,9,1,LOG2:13)
Block(7,9,2,LEAVES:8)
Block(-5,9,3,LEAVES:8)
Block(-1,9,3,SPRUCE_FENCE)
Block(0,9,3,SPRUCE_FENCE)
Block(4,9,3,WEB)
Block(8,9,3,LEAVES:8)
Block(-5,9,4,LEAVES:8)
Block(0,9,4,SPRUCE_FENCE)
Block(2,9,4,LEAVES:8)
Block(7,9,4,SEA_LANTERN)
Block(1,9,5,LEAVES:8)
Block(8,9,6,LEAVES:8)
Block(-2,10,-8,LEAVES:8)
Block(4,10,-7,LEAVES:8)
Block(-1,10,-6,LEAVES:8)
Block(2,10,-6,SPRUCE_FENCE)
Block(3,10,-6,SPRUCE_FENCE)
Block(1,10,-5,SPRUCE_FENCE)
Block(2,10,-5,SPRUCE_FENCE)
Block(-2,10,-4,LEAVES:8)
Block(0,10,-4,SPRUCE_FENCE)
Block(1,10,-4,SPRUCE_FENCE)
Block(-1,10,-3,LEAVES:8)
Block(0,10,-3,SPRUCE_FENCE)
Block(3,10,-3,SPRUCE_FENCE)
Block(8,10,-3,LEAVES:8)
Block(3,10,-2,SPRUCE_FENCE)
Block(8,10,-2,SPRUCE_FENCE)
Block(-2,10,-1,LEAVES:8)
Block(1,10,-1,LEAVES:8)
Block(2,10,-1,SPRUCE_FENCE)
Block(3,10,-1,SPRUCE_FENCE)
Block(6,10,-1,SPRUCE_FENCE)
Block(7,10,-1,SPRUCE_FENCE)
Block(8,10,-1,SPRUCE_FENCE)
Block(2,10,0,LEAVES:8)
Block(6,10,0,SPRUCE_FENCE)
Block(-4,10,1,LEAVES:8)
Block(6,10,1,LOG2:13)
Block(4,10,2,WEB)
Block(6,10,2,LOG:12)
Block(7,10,2,LOG:12)
Block(7,10,3,LOG:12)
Block(-5,10,4,LEAVES:8)
Block(0,10,4,SPRUCE_FENCE)
Block(1,10,4,SPRUCE_FENCE)
Block(7,10,4,LOG:12)
Block(8,10,4,SPRUCE_FENCE)
Block(1,10,5,SPRUCE_FENCE)
Block(8,10,5,SPRUCE_FENCE)
Block(7,10,6,LEAVES:8)
Block(8,10,6,SPRUCE_FENCE)
Block(-2,11,-8,LEAVES:8)
Block(3,11,-7,SPRUCE_FENCE)
Block(4,11,-7,SPRUCE_FENCE)
Block(-1,11,-6,LEAVES:8)
Block(3,11,-6,SPRUCE_FENCE)
Block(-1,11,-3,SPRUCE_FENCE)
Block(0,11,-3,SPRUCE_FENCE)
Block(8,11,-3,LEAVES:8)
Block(8,11,-2,LEAVES:8)
Block(-2,11,-1,LEAVES:8)
Block(1,11,-1,LEAVES:8)
Block(2,11,-1,SPRUCE_FENCE)
Block(2,11,0,SPRUCE_FENCE)
Block(6,11,2,SPRUCE_FENCE)
Block(7,11,2,LEAVES:8)
Block(4,11,3,SPRUCE_FENCE)
Block(5,11,3,SPRUCE_FENCE)
Block(6,11,3,SPRUCE_FENCE)
Block(2,11,5,LEAVES:8)
Block(7,11,6,LEAVES:8)
Block(8,11,6,LEAVES:8)
Block(4,12,-7,LEAVES:8)
Block(-1,12,-3,LEAVES:8)
Block(8,12,-2,LEAVES:8)
Block(3,12,0,LEAVES:8)
Block(7,12,2,LEAVES:8)
Block(4,12,3,SPRUCE_FENCE)
Block(3,12,4,SPRUCE_FENCE)
Block(4,12,4,SPRUCE_FENCE)
Block(5,12,4,LEAVES:8)
Block(2,12,5,LEAVES:8)
Block(8,12,6,LEAVES:8)
Block(4,13,-7,LEAVES:8)
Block(-1,13,-3,LEAVES:8)
Block(3,13,0,LEAVES:8)
Block(4,13,3,LEAVES:8)
Block(5,13,4,LEAVES:8)
Block(4,14,3,LEAVES:8)
Block(0,0,0,LOG:2)

#######################################################################
# +-----------------------------------------------------------------+ #
# |                            BO3 checks                           | #
# +-----------------------------------------------------------------+ #
#######################################################################

BlockCheck(2,0,-1,Solid)
BlockCheck(1,0,0,Solid)
BlockCheck(-1,0,1,Solid)
BlockCheck(0,0,1,Solid)

