#######################################################################
# +-----------------------------------------------------------------+ #
# |                            BO3 object                           | #
# +-----------------------------------------------------------------+ #
#######################################################################

Author: Bo3 BulkEdit

Description: Converted Schematic - Modified by Bo3BulkEdit

Version: 3

SettingsMode: WriteDisable

#######################################################################
# +-----------------------------------------------------------------+ #
# |                          Main settings                          | #
# +-----------------------------------------------------------------+ #
#######################################################################

IsOTGPlus: false
Tree: true
Frequency: 1
Rarity: 100
RotateRandomly: true
SpawnHeight: randomY
SpawnHeightOffset: 0
SpawnHeightVariance: 0
MaxBranchDepth: 10
ExcludedBiomes: All

##############################
# Height Limits for the BO3. #
##############################

MinHeight: 0
MaxHeight: 20

#######################################################################
# +-----------------------------------------------------------------+ #
# |                      Source block settings                      | #
# +-----------------------------------------------------------------+ #
#######################################################################

SourceBlocks: AIR,GRASS,DIRT,STONE,WATER
MaxPercentageOutsideSourceBlock: 0
OutsideSourceBlock: placeAnyway

ReplaceBelow: STONE
ReplaceWithBiomeBlocks: true
ReplaceWithGroundBlock: DIRT
ReplaceWithSurfaceBlock: GRASS
ReplaceWithStoneBlock: STONE
SmoothRadius: 0
SmoothHeightOffset: 0

#######################################################################
# +-----------------------------------------------------------------+ #
# |                              Blocks                             | #
# +-----------------------------------------------------------------+ #
#######################################################################

Block(0,1,-1,LOG:13)
Block(-1,1,0,LOG:13)
Block(0,1,0,GOLD_BLOCK)
Block(1,1,0,LOG:13)
Block(0,1,1,LOG:13)
Block(0,2,-1,LOG:13)
Block(-1,2,0,LOG:13)
Block(0,2,0,GOLD_BLOCK)
Block(1,2,0,LOG:13)
Block(0,2,1,LOG:13)
Block(-1,3,0,LOG:13)
Block(0,3,0,LOG:13)
Block(-2,3,1,LOG:13)
Block(-1,3,1,LOG:13)
Block(0,3,1,LOG:13)
Block(-1,3,2,LOG:13)
Block(-1,4,0,LOG:13)
Block(-2,4,1,LOG:13)
Block(-1,4,1,GOLD_BLOCK)
Block(0,4,1,LOG:13)
Block(-1,4,2,LOG:13)
Block(-2,5,1,LOG:13)
Block(-1,5,1,LOG:13)
Block(-1,5,2,LOG:13)
Block(-2,6,1,LOG:13)
Block(-2,6,2,LOG:13)
Block(-1,6,2,LOG:13)
Block(-2,7,1,LOG:13)
Block(-2,7,2,LOG:13)
Block(-1,7,2,LOG:13)
Block(-2,8,2,LOG:13)
Block(-2,9,2,LOG:13)
Block(-3,9,3,LOG:13)
Block(-2,9,3,LOG:13)
Block(-3,10,3,LOG:13)
Block(-3,11,2,WOODEN_BUTTON:4)
Block(-4,11,3,WOODEN_BUTTON:2)
Block(-3,11,3,LOG:13)
Block(-2,11,3,WOODEN_BUTTON:1)
Block(-3,11,4,WOODEN_BUTTON:3)
Block(-3,12,3,LOG:13)
Block(-4,13,3,LOG:13)
Block(-3,13,3,LOG:13)
Block(-4,14,3,LOG:13)
Block(-4,15,3,LOG:12)
Block(-4,16,2,WOODEN_BUTTON:4)
Block(-5,16,3,WOODEN_BUTTON:2)
Block(-4,16,3,LOG:12)
Block(-4,16,4,WOODEN_BUTTON:3)
Block(-4,17,3,LOG:12)
Block(-3,17,3,BIRCH_FENCE)
Block(-2,17,3,OAK_STAIRS:5)
Block(-4,18,3,LOG:12)
Block(-2,18,3,WOODEN_SLAB:5)
Block(-4,19,2,WOODEN_BUTTON:4)
Block(-5,19,3,WOODEN_BUTTON:2)
Block(-4,19,3,LOG:12)
Block(-3,19,3,WOODEN_BUTTON:1)
Block(-4,19,4,WOODEN_BUTTON:3)
Block(-7,20,2,BIRCH_FENCE)
Block(-6,20,2,BIRCH_FENCE)
Block(-6,20,3,BIRCH_FENCE)
Block(-5,20,3,LOG:13)
Block(-4,20,3,LOG:12)
Block(-5,20,4,LOG:13)
Block(-7,21,2,WOODEN_SLAB:5)
Block(-5,21,4,LOG:13)
Block(-5,22,4,LOG:13)
Block(-5,23,3,WOODEN_BUTTON:4)
Block(-6,23,4,WOODEN_BUTTON:2)
Block(-5,23,4,LOG:13)
Block(-4,23,4,WOODEN_BUTTON:1)
Block(-5,23,5,WOODEN_BUTTON:3)
Block(-5,24,4,LOG:13)
Block(-7,25,3,WOODEN_SLAB:13)
Block(-6,25,3,LOG:13)
Block(-5,25,3,WOODEN_SLAB:13)
Block(-6,25,4,WOODEN_SLAB:5)
Block(-5,25,4,LOG:13)
Block(-4,25,4,WOODEN_SLAB:13)
Block(-6,25,5,WOODEN_SLAB:13)
Block(-5,25,5,WOODEN_SLAB:13)
Block(-4,25,5,WOODEN_SLAB:13)
Block(-6,25,6,WOODEN_SLAB:13)
Block(-3,26,0,WOODEN_SLAB:13)
Block(-2,26,0,WOODEN_SLAB:13)
Block(-7,26,1,WOODEN_SLAB:13)
Block(-4,26,1,WOODEN_SLAB:13)
Block(-3,26,1,WOODEN_SLAB:13)
Block(-7,26,2,DOUBLE_WOODEN_SLAB:5)
Block(-4,26,2,WOODEN_SLAB:5)
Block(-7,26,3,WOODEN_SLAB:5)
Block(-5,26,5,WOODEN_SLAB:13)
Block(-4,26,5,LOG:13)
Block(-3,26,5,WOODEN_SLAB:5)
Block(-2,26,5,WOODEN_SLAB:13)
Block(-7,26,6,WOODEN_SLAB:5)
Block(-3,26,6,WOODEN_SLAB:5)
Block(-2,26,6,DOUBLE_WOODEN_SLAB:5)
Block(-1,26,6,WOODEN_SLAB:13)
Block(-8,26,7,WOODEN_SLAB:13)
Block(-7,26,7,WOODEN_SLAB:13)
Block(-1,26,7,WOODEN_SLAB:13)
Block(-8,26,8,WOODEN_SLAB:13)
Block(-4,27,-3,LEAVES:8)
Block(0,27,-3,LEAVES:8)
Block(-7,27,-2,LEAVES:8)
Block(-5,27,-2,LEAVES:8)
Block(-4,27,-2,LEAVES:8)
Block(-11,27,-1,SEA_LANTERN)
Block(-5,27,-1,WOODEN_SLAB:13)
Block(-4,27,-1,LEAVES:8)
Block(-3,27,-1,LEAVES:8)
Block(-2,27,-1,WOODEN_SLAB:5)
Block(-1,27,-1,SEA_LANTERN)
Block(-9,27,0,WOODEN_SLAB:13)
Block(-6,27,0,WOODEN_SLAB:13)
Block(-5,27,0,LEAVES:8)
Block(-3,27,0,LEAVES:8)
Block(-1,27,0,LEAVES:8)
Block(-13,27,1,LEAVES:8)
Block(-11,27,1,LEAVES:8)
Block(-9,27,1,WOODEN_SLAB:5)
Block(-8,27,1,WOODEN_SLAB:5)
Block(-7,27,1,WOODEN_SLAB:5)
Block(-6,27,1,WOODEN_SLAB:5)
Block(-4,27,1,LEAVES:8)
Block(-14,27,2,LEAVES:8)
Block(-12,27,2,LEAVES:8)
Block(-11,27,2,LEAVES:8)
Block(-10,27,2,LEAVES:8)
Block(-2,27,2,LEAVES:8)
Block(-13,27,3,LEAVES:8)
Block(-12,27,3,LEAVES:8)
Block(-2,27,3,WOODEN_SLAB:13)
Block(-1,27,3,WOODEN_SLAB:13)
Block(0,27,3,LEAVES:8)
Block(-15,27,4,LEAVES:8)
Block(-7,27,4,WOODEN_SLAB:13)
Block(-2,27,4,DOUBLE_WOODEN_SLAB:5)
Block(-13,27,5,LEAVES:8)
Block(-12,27,5,SEA_LANTERN)
Block(-7,27,5,WOODEN_SLAB:5)
Block(-6,27,5,WOODEN_SLAB:5)
Block(-5,27,5,WOODEN_SLAB:5)
Block(-2,27,5,WOODEN_SLAB:5)
Block(0,27,5,LEAVES:8)
Block(-10,27,6,LEAVES:8)
Block(-9,27,6,WOODEN_SLAB:5)
Block(-7,27,6,LEAVES:8)
Block(-4,27,6,WOODEN_SLAB:13)
Block(-3,27,6,LEAVES:8)
Block(-1,27,6,LEAVES:8)
Block(0,27,6,LEAVES:8)
Block(1,27,6,LEAVES:8)
Block(-10,27,7,LEAVES:8)
Block(-8,27,7,SEA_LANTERN)
Block(-7,27,7,LEAVES:8)
Block(-6,27,7,LEAVES:8)
Block(-2,27,7,LEAVES:8)
Block(-1,27,7,LEAVES:8)
Block(0,27,7,WOODEN_SLAB:5)
Block(-9,27,8,LEAVES:8)
Block(-8,27,8,LEAVES:8)
Block(-6,27,8,WOODEN_SLAB:5)
Block(-4,27,8,SEA_LANTERN)
Block(-11,27,9,LEAVES:8)
Block(-2,27,9,LEAVES:8)
Block(-1,27,9,LEAVES:8)
Block(-9,27,10,LEAVES:8)
Block(-8,27,10,LEAVES:8)
Block(1,27,10,LEAVES:8)
Block(-6,27,11,LEAVES:8)
Block(-4,28,-4,LEAVES:8)
Block(-2,28,-4,CONCRETE:15)
Block(-10,28,-3,LEAVES:8)
Block(-6,28,-3,LEAVES:8)
Block(-5,28,-3,LEAVES:8)
Block(-3,28,-3,CONCRETE:15)
Block(-1,28,-3,CONCRETE:15)
Block(-13,28,-2,LEAVES:8)
Block(-11,28,-2,SEA_LANTERN)
Block(-10,28,-2,LEAVES:8)
Block(-4,28,-2,SEA_LANTERN)
Block(0,28,-2,CONCRETE:15)
Block(-10,28,-1,LEAVES:8)
Block(-9,28,-1,LEAVES:8)
Block(-7,28,-1,LEAVES:8)
Block(-6,28,-1,LEAVES:8)
Block(-5,28,-1,LEAVES:8)
Block(-2,28,-1,CONCRETE:15)
Block(-14,28,0,CONCRETE:15)
Block(-12,28,0,LEAVES:8)
Block(-11,28,0,LEAVES:8)
Block(-9,28,0,LEAVES:8)
Block(-7,28,0,LEAVES:8)
Block(-5,28,0,LEAVES:8)
Block(-4,28,0,LEAVES:8)
Block(-2,28,0,LEAVES:8)
Block(-1,28,0,LEAVES:8)
Block(0,28,0,LEAVES:8)
Block(-14,28,1,CONCRETE:15)
Block(-13,28,1,CONCRETE:15)
Block(-12,28,1,LEAVES:8)
Block(-10,28,1,LEAVES:8)
Block(-6,28,1,SEA_LANTERN)
Block(-5,28,1,LEAVES:8)
Block(-3,28,1,LEAVES:8)
Block(-1,28,1,LEAVES:8)
Block(0,28,1,LEAVES:8)
Block(1,28,1,SEA_LANTERN)
Block(-15,28,2,CONCRETE:15)
Block(-13,28,2,CONCRETE:15)
Block(-11,28,2,LEAVES:8)
Block(-9,28,2,LEAVES:8)
Block(-8,28,2,LEAVES:8)
Block(-4,28,2,LEAVES:8)
Block(-3,28,2,LEAVES:8)
Block(-1,28,2,LEAVES:8)
Block(1,28,2,LEAVES:8)
Block(-16,28,3,CONCRETE:15)
Block(-14,28,3,CONCRETE:15)
Block(-10,28,3,LEAVES:8)
Block(-3,28,3,LEAVES:8)
Block(-1,28,3,LEAVES:8)
Block(0,28,3,SEA_LANTERN)
Block(-13,28,4,LEAVES:8)
Block(-12,28,4,LEAVES:8)
Block(-9,28,4,LEAVES:8)
Block(-3,28,4,SEA_LANTERN)
Block(-1,28,4,SEA_LANTERN)
Block(0,28,4,SEA_LANTERN)
Block(1,28,4,LEAVES:8)
Block(3,28,4,LEAVES:8)
Block(-15,28,5,CONCRETE:15)
Block(-14,28,5,CONCRETE:15)
Block(-13,28,5,CONCRETE:15)
Block(-10,28,5,LEAVES:8)
Block(-8,28,5,LEAVES:8)
Block(-7,28,5,LEAVES:8)
Block(-4,28,5,SEA_LANTERN)
Block(-3,28,5,LEAVES:8)
Block(-2,28,5,LEAVES:8)
Block(-1,28,5,LEAVES:8)
Block(0,28,5,LEAVES:8)
Block(1,28,5,LEAVES:8)
Block(-13,28,6,CONCRETE:15)
Block(-11,28,6,LEAVES:8)
Block(-10,28,6,LEAVES:8)
Block(-9,28,6,LEAVES:8)
Block(-8,28,6,LEAVES:8)
Block(-7,28,6,LEAVES:8)
Block(-6,28,6,SEA_LANTERN)
Block(-4,28,6,LEAVES:8)
Block(-2,28,6,LEAVES:8)
Block(0,28,6,LEAVES:8)
Block(2,28,6,LEAVES:8)
Block(-14,28,7,CONCRETE:15)
Block(-11,28,7,LEAVES:8)
Block(-9,28,7,LEAVES:8)
Block(-7,28,7,LEAVES:8)
Block(-6,28,7,LEAVES:8)
Block(-5,28,7,LEAVES:8)
Block(-4,28,7,LEAVES:8)
Block(-3,28,7,LEAVES:8)
Block(1,28,7,LEAVES:8)
Block(-12,28,8,CONCRETE:15)
Block(-11,28,8,LOG:13)
Block(-10,28,8,CONCRETE:15)
Block(-8,28,8,LEAVES:8)
Block(-6,28,8,SEA_LANTERN)
Block(-4,28,8,LEAVES:8)
Block(-2,28,8,LEAVES:8)
Block(-1,28,8,LEAVES:8)
Block(2,28,8,LEAVES:8)
Block(-9,28,9,CONCRETE:15)
Block(-8,28,9,CONCRETE:15)
Block(-7,28,9,LEAVES:8)
Block(-5,28,9,LEAVES:8)
Block(-4,28,9,SEA_LANTERN)
Block(-3,28,9,LEAVES:8)
Block(-2,28,9,LEAVES:8)
Block(1,28,9,LEAVES:8)
Block(-11,28,10,CONCRETE:15)
Block(-10,28,10,CONCRETE:15)
Block(-9,28,10,CONCRETE:15)
Block(-6,28,10,LEAVES:8)
Block(-5,28,10,LEAVES:8)
Block(-2,28,10,LEAVES:8)
Block(0,28,10,LEAVES:8)
Block(-9,28,11,CONCRETE:15)
Block(-7,28,11,LEAVES:8)
Block(-3,28,11,LEAVES:8)
Block(-10,28,12,CONCRETE:15)
Block(-10,29,-4,CONCRETE:15)
Block(-8,29,-4,CONCRETE:15)
Block(-11,29,-3,LEAVES:8)
Block(-9,29,-3,CONCRETE:15)
Block(-7,29,-3,CONCRETE:15)
Block(-10,29,-2,CONCRETE:15)
Block(-9,29,-2,LOG:13)
Block(-6,29,-2,SEA_LANTERN)
Block(-2,29,-2,CONCRETE:15)
Block(-13,29,-1,CONCRETE:15)
Block(-12,29,-1,CONCRETE:15)
Block(-11,29,-1,CONCRETE:15)
Block(-8,29,-1,LEAVES:8)
Block(-6,29,-1,LOG:13)
Block(-4,29,-1,CONCRETE:15)
Block(-3,29,-1,CONCRETE:15)
Block(-1,29,-1,CONCRETE:15)
Block(-12,29,0,LOG:13)
Block(-11,29,0,CONCRETE:15)
Block(-10,29,0,CONCRETE:15)
Block(-8,29,0,LEAVES:8)
Block(-7,29,0,LEAVES:8)
Block(-6,29,0,LEAVES:8)
Block(-3,29,0,CONCRETE:15)
Block(-2,29,0,CONCRETE:15)
Block(0,29,0,CONCRETE:15)
Block(-15,29,1,LEAVES:8)
Block(-12,29,1,CONCRETE:15)
Block(-11,29,1,CONCRETE:15)
Block(-10,29,1,LOG:13)
Block(-9,29,1,CONCRETE:15)
Block(-7,29,1,SEA_LANTERN)
Block(-5,29,1,CONCRETE:15)
Block(-3,29,1,CONCRETE:15)
Block(-1,29,1,CONCRETE:15)
Block(1,29,1,CONCRETE:15)
Block(2,29,1,CONCRETE:15)
Block(-13,29,2,LOG:13)
Block(-12,29,2,CONCRETE:15)
Block(-10,29,2,CONCRETE:15)
Block(-7,29,2,SEA_LANTERN)
Block(-5,29,2,LEAVES:8)
Block(-4,29,2,CONCRETE:15)
Block(-3,29,2,CONCRETE:15)
Block(-2,29,2,CONCRETE:15)
Block(0,29,2,CONCRETE:15)
Block(1,29,2,CONCRETE:15)
Block(-14,29,3,CONCRETE:15)
Block(-13,29,3,CONCRETE:15)
Block(-12,29,3,CONCRETE:15)
Block(-9,29,3,LEAVES:8)
Block(-3,29,3,LOG:13)
Block(-2,29,3,LEAVES:8)
Block(1,29,3,CONCRETE:15)
Block(2,29,3,CONCRETE:15)
Block(-13,29,4,CONCRETE:15)
Block(-11,29,4,CONCRETE:15)
Block(-9,29,4,LEAVES:8)
Block(-7,29,4,SEA_LANTERN)
Block(-5,29,4,LEAVES:8)
Block(-4,29,4,LEAVES:8)
Block(-1,29,4,LOG:13)
Block(0,29,4,LEAVES:8)
Block(-8,29,5,SEA_LANTERN)
Block(-7,29,5,LEAVES:8)
Block(-6,29,5,LEAVES:8)
Block(-4,29,5,CONCRETE:15)
Block(-3,29,5,CONCRETE:15)
Block(-1,29,5,CONCRETE:15)
Block(1,29,5,LEAVES:8)
Block(-11,29,6,LEAVES:8)
Block(-7,29,6,CONCRETE:15)
Block(-3,29,6,CONCRETE:15)
Block(-2,29,6,CONCRETE:15)
Block(-1,29,6,CONCRETE:15)
Block(0,29,6,CONCRETE:15)
Block(-9,29,7,CONCRETE:15)
Block(-8,29,7,CONCRETE:15)
Block(-5,29,7,LEAVES:8)
Block(-4,29,7,LOG:13)
Block(-3,29,7,CONCRETE:15)
Block(-2,29,7,CONCRETE:15)
Block(-1,29,7,CONCRETE:15)
Block(-10,29,8,CONCRETE:15)
Block(-9,29,8,CONCRETE:15)
Block(-8,29,8,CONCRETE:15)
Block(-7,29,8,CONCRETE:15)
Block(-5,29,8,CONCRETE:15)
Block(-4,29,8,CONCRETE:15)
Block(-3,29,8,CONCRETE:15)
Block(-2,29,8,CONCRETE:15)
Block(-1,29,8,LOG:13)
Block(0,29,8,CONCRETE:15)
Block(-9,29,9,CONCRETE:15)
Block(-8,29,9,CONCRETE:15)
Block(-7,29,9,CONCRETE:15)
Block(-6,29,9,CONCRETE:15)
Block(-4,29,9,CONCRETE:15)
Block(-2,29,9,CONCRETE:15)
Block(-7,29,10,CONCRETE:15)
Block(-4,29,10,CONCRETE:15)
Block(-6,29,11,CONCRETE:15)
Block(-12,30,-2,CONCRETE:15)
Block(-8,30,-2,CONCRETE:15)
Block(-10,30,-1,CONCRETE:15)
Block(-9,30,-1,CONCRETE:15)
Block(-13,30,0,CONCRETE:15)
Block(-9,30,0,CONCRETE:15)
Block(-8,30,0,CONCRETE:15)
Block(1,30,0,LEAVES:8)
Block(-9,30,1,CONCRETE:15)
Block(-7,30,1,LEAVES:8)
Block(-6,30,1,LEAVES:8)
Block(-1,30,1,CONCRETE:15)
Block(-11,30,2,CONCRETE:15)
Block(-4,30,2,LEAVES:8)
Block(-2,30,2,CONCRETE:15)
Block(-1,30,2,CONCRETE:15)
Block(3,30,2,CONCRETE:15)
Block(-7,30,3,LEAVES:8)
Block(-6,30,3,SEA_LANTERN)
Block(-1,30,3,CONCRETE:15)
Block(0,30,3,CONCRETE:15)
Block(-9,30,4,LEAVES:8)
Block(-8,30,4,LEAVES:8)
Block(-7,30,4,LEAVES:8)
Block(-5,30,4,LEAVES:8)
Block(-2,30,4,CONCRETE:15)
Block(2,30,4,CONCRETE:15)
Block(-8,30,5,LEAVES:8)
Block(-6,30,5,LEAVES:8)
Block(-9,30,6,CONCRETE:15)
Block(-5,30,6,CONCRETE:15)
Block(-8,30,7,CONCRETE:15)
Block(-7,30,7,CONCRETE:15)
Block(-6,30,7,CONCRETE:15)
Block(-10,30,8,CONCRETE:15)
Block(-7,30,8,LOG:13)
Block(-6,30,8,CONCRETE:15)
Block(-5,30,8,CONCRETE:15)
Block(-6,30,9,CONCRETE:15)
Block(-8,30,10,CONCRETE:15)
Block(-5,31,-1,CONCRETE:15)
Block(-8,31,0,CONCRETE:15)
Block(-6,31,0,CONCRETE:15)
Block(-9,31,1,CONCRETE:15)
Block(-6,31,1,CONCRETE:15)
Block(-5,31,1,CONCRETE:15)
Block(-4,31,1,CONCRETE:15)
Block(-10,31,2,LEAVES:8)
Block(-7,31,2,CONCRETE:15)
Block(-6,31,2,CONCRETE:15)
Block(-9,31,3,CONCRETE:15)
Block(-5,31,3,CONCRETE:15)
Block(-3,31,3,CONCRETE:15)
Block(-10,31,4,LEAVES:8)
Block(-8,31,4,CONCRETE:15)
Block(-6,31,4,CONCRETE:15)
Block(-4,31,4,CONCRETE:15)
Block(-9,31,5,LEAVES:8)
Block(-7,31,5,CONCRETE:15)
Block(-6,31,5,CONCRETE:15)
Block(-5,31,5,CONCRETE:15)
Block(-7,31,6,CONCRETE:15)
Block(-5,31,6,CONCRETE:15)
Block(-8,32,2,CONCRETE:15)
Block(-6,32,2,CONCRETE:15)
Block(-7,32,3,CONCRETE:15)
Block(-6,32,3,CONCRETE:15)
Block(-5,32,3,CONCRETE:15)
Block(-7,32,4,CONCRETE:15)
Block(-4,32,5,CONCRETE:15)
Block(-8,32,6,CONCRETE:15)
Block(-6,32,7,CONCRETE:15)
Block(0,0,0,LOG:2)

#######################################################################
# +-----------------------------------------------------------------+ #
# |                            BO3 checks                           | #
# +-----------------------------------------------------------------+ #
#######################################################################

BlockCheck(0,0,-1,Solid)
BlockCheck(-1,0,0,Solid)
BlockCheck(1,0,0,Solid)
BlockCheck(0,0,1,Solid)

