
#
# +-----------------------------------------------------------------+ #
# |                            BO3 object                           | #
# +-----------------------------------------------------------------+ #
#

Author: NLBlackEagle

Description: No description given

Version: 3

SettingsMode: WriteDisable


#
# +-----------------------------------------------------------------+ #
# |                          Main settings                          | #
# +-----------------------------------------------------------------+ #
#

Tree: true

Frequency: 1

Rarity: 100.0

RotateRandomly: true

SpawnHeight: highestSolidBlock

SpawnHeightOffset: 0

SpawnHeightVariance: 0


# Height Limits for the BO3. #


MinHeight: 0

MaxHeight: 256


# Extrusion settings #


ExtrudeMode: None

ExtrudeThroughBlocks: air

MaxBranchDepth: 10

ExcludedBiomes: All


#
# +-----------------------------------------------------------------+ #
# |                      Source block settings                      | #
# +-----------------------------------------------------------------+ #
#

SourceBlocks: AIR,GRASS,DIRT,SAND

MaxPercentageOutsideSourceBlock: 0

OutsideSourceBlock: placeAnyway


#
# +-----------------------------------------------------------------+ #
# |                              Blocks                             | #
# +-----------------------------------------------------------------+ #
#

B(-15,11,0,wooden_slab:4)
B(-15,11,2,wooden_slab:4)
B(-15,11,4,red_sandstone:2)
B(-15,12,2,stained_hardened_clay:1)
B(-15,12,4,LOG:13)
B(-15,13,0,red_sandstone:2)
B(-15,13,1,LOG:13)
B(-15,13,2,LOG:13)
B(-15,13,3,LOG:13)
B(-15,13,4,LOG:13)
B(-15,14,-2,stone_slab2)
B(-15,14,-1,stained_hardened_clay:1)
B(-15,14,0,wooden_slab:4)
B(-15,14,1,stained_hardened_clay:1)
B(-15,14,2,stone_slab2)
B(-15,14,4,red_sandstone:2)
B(-15,15,0,stone_slab2)
B(-15,15,1,wooden_slab:4)
B(-15,16,0,stained_hardened_clay:1)
B(-15,16,1,wooden_slab:4)
B(-15,17,-11,stained_hardened_clay:1)
B(-15,17,-1,wooden_slab:4)
B(-15,17,1,wooden_slab:4)
B(-15,17,2,stone_slab2)
B(-15,18,-13,stained_hardened_clay:1)
B(-15,19,0,stone_slab2)
B(-14,10,1,stone_slab2)
B(-14,10,2,stained_hardened_clay:1)
B(-14,11,5,LOG:13)
B(-14,11,6,LOG:13)
B(-14,12,4,LOG:13)
B(-14,12,5,LOG:13)
B(-14,12,6,LOG:13)
B(-14,13,0,wooden_slab:4)
B(-14,14,0,stone_slab2)
B(-14,15,-15,red_sandstone:2)
B(-14,15,-10,stained_hardened_clay:1)
B(-14,15,0,red_sandstone:2)
B(-14,16,-12,stone_slab2)
B(-14,16,-2,red_sandstone:2)
B(-14,16,1,stone_slab2)
B(-14,16,3,stained_hardened_clay:1)
B(-14,17,-13,red_sandstone:2)
B(-14,17,-12,wooden_slab:4)
B(-14,17,-2,stained_hardened_clay:1)
B(-14,17,1,red_sandstone:2)
B(-14,17,2,stained_hardened_clay:1)
B(-14,18,1,stone_slab2)
B(-14,19,1,stone_slab2)
B(-13,6,-6,red_sandstone:2)
B(-13,11,1,stone_slab2)
B(-13,11,3,red_sandstone:2)
B(-13,11,6,LOG:13)
B(-13,11,7,LOG:13)
B(-13,11,8,red_sandstone:2)
B(-13,13,1,wooden_slab:4)
B(-13,13,3,stone_slab2)
B(-13,14,2,stone_slab2)
B(-13,15,-15,stone_slab2)
B(-13,15,-13,stone_slab2)
B(-13,15,-12,stone_slab2)
B(-13,15,1,red_sandstone:2)
B(-13,15,2,red_sandstone:2)
B(-13,15,4,stained_hardened_clay:1)
B(-13,15,10,red_sandstone:2)
B(-13,16,-15,stained_hardened_clay:1)
B(-13,16,-14,stone_slab2)
B(-13,16,-13,wooden_slab:4)
B(-13,16,-10,stained_hardened_clay:1)
B(-13,16,1,stained_hardened_clay:1)
B(-13,16,9,stone_slab2)
B(-13,16,11,red_sandstone:2)
B(-13,17,-15,stained_hardened_clay:1)
B(-13,17,-10,stained_hardened_clay:1)
B(-13,17,-1,red_sandstone:2)
B(-13,18,-12,stone_slab2)
B(-13,18,-11,wooden_slab:4)
B(-13,18,0,stone_slab2)
B(-13,18,1,stone_slab2)
B(-13,18,4,stone_slab2)
B(-13,20,0,red_sandstone:2)
B(-13,20,1,stone_slab2)
B(-13,22,0,wooden_slab:4)
B(-12,2,5,LOG:13)
B(-12,3,5,LOG:13)
B(-12,4,-7,LOG:13)
B(-12,4,5,LOG:13)
B(-12,5,-7,LOG:13)
B(-12,5,4,wooden_slab:4)
B(-12,5,5,LOG:13)
B(-12,6,-7,LOG:13)
B(-12,6,-6,red_sandstone:2)
B(-12,7,-7,LOG:13)
B(-12,7,6,stone_slab2)
B(-12,8,-8,stone_slab2)
B(-12,8,5,stained_hardened_clay:1)
B(-12,8,6,wooden_slab:4)
B(-12,9,-7,red_sandstone:2)
B(-12,9,6,wooden_slab:4)
B(-12,11,7,LOG:13)
B(-12,12,7,stained_hardened_clay:1)
B(-12,12,9,stained_hardened_clay:1)
B(-12,13,-9,stained_hardened_clay:1)
B(-12,14,-13,stone_slab2)
B(-12,14,-12,stained_hardened_clay:1)
B(-12,14,-11,red_sandstone:2)
B(-12,15,-15,red_sandstone:2)
B(-12,15,-11,stone_slab2)
B(-12,15,-10,red_sandstone:2)
B(-12,15,5,red_sandstone:2)
B(-12,16,-16,red_sandstone:2)
B(-12,16,-12,stained_hardened_clay:1)
B(-12,16,-10,stained_hardened_clay:1)
B(-12,16,-9,stained_hardened_clay:1)
B(-12,16,7,red_sandstone:2)
B(-12,16,8,wooden_slab:4)
B(-12,17,-15,red_sandstone:2)
B(-12,17,-14,LOG:13)
B(-12,17,-13,LOG:13)
B(-12,17,-12,LOG:13)
B(-12,17,-11,red_sandstone:2)
B(-12,17,-10,red_sandstone:2)
B(-12,17,7,red_sandstone:2)
B(-12,18,-11,stained_hardened_clay:1)
B(-12,18,1,red_sandstone:2)
B(-12,18,2,stained_hardened_clay:1)
B(-12,18,3,stone_slab2)
B(-12,18,11,stone_slab2)
B(-12,19,-15,stained_hardened_clay:1)
B(-12,19,-12,stained_hardened_clay:1)
B(-12,19,3,stone_slab2)
B(-12,20,-13,wooden_slab:4)
B(-12,20,1,red_sandstone:2)
B(-12,21,-11,stone_slab2)
B(-12,21,1,stained_hardened_clay:1)
B(-12,22,2,stone_slab2)
B(-12,23,1,red_sandstone:2)
B(-11,4,4,stained_hardened_clay:1)
B(-11,5,-6,stained_hardened_clay:1)
B(-11,5,5,LOG:13)
B(-11,5,6,red_sandstone:2)
B(-11,6,-6,stained_hardened_clay:1)
B(-11,6,-5,wooden_slab:4)
B(-11,6,5,LOG:13)
B(-11,7,-8,stone_slab2)
B(-11,7,-7,LOG:13)
B(-11,7,5,LOG:13)
B(-11,7,6,LOG:13)
B(-11,8,-7,LOG:13)
B(-11,8,5,stone_slab2)
B(-11,8,6,LOG:13)
B(-11,9,-8,wooden_slab:4)
B(-11,9,-7,LOG:13)
B(-11,9,6,LOG:13)
B(-11,9,7,LOG:13)
B(-11,10,-8,stained_hardened_clay:1)
B(-11,10,-7,LOG:13)
B(-11,10,-6,stone_slab2)
B(-11,10,6,LOG:13)
B(-11,10,7,LOG:13)
B(-11,11,7,LOG:13)
B(-11,11,10,stained_hardened_clay:1)
B(-11,12,-8,wooden_slab:4)
B(-11,12,5,red_sandstone:2)
B(-11,12,7,LOG:13)
B(-11,12,8,LOG:13)
B(-11,13,-10,red_sandstone:2)
B(-11,13,-8,red_sandstone:2)
B(-11,13,8,LOG:13)
B(-11,13,9,LOG:13)
B(-11,14,-11,stained_hardened_clay:1)
B(-11,14,-10,stained_hardened_clay:1)
B(-11,14,-9,stone_slab2)
B(-11,14,-8,red_sandstone:2)
B(-11,14,8,wooden_slab:4)
B(-11,14,9,LOG:13)
B(-11,15,-14,stone_slab2)
B(-11,15,-12,red_sandstone:2)
B(-11,15,-11,LOG:13)
B(-11,15,4,stone_slab2)
B(-11,15,5,red_sandstone:2)
B(-11,15,7,stone_slab2)
B(-11,15,9,LOG:13)
B(-11,15,10,LOG:13)
B(-11,16,-12,LOG:13)
B(-11,16,-11,LOG:13)
B(-11,16,-9,stained_hardened_clay:1)
B(-11,16,1,stone_slab2)
B(-11,16,7,stained_hardened_clay:1)
B(-11,16,9,stone_slab2)
B(-11,16,10,red_sandstone:2)
B(-11,16,12,stained_hardened_clay:1)
B(-11,17,-15,red_sandstone:2)
B(-11,17,-13,red_sandstone:2)
B(-11,17,-12,LOG:13)
B(-11,17,-11,stone_slab2)
B(-11,17,-10,wooden_slab:4)
B(-11,17,1,red_sandstone:2)
B(-11,17,2,stone_slab2)
B(-11,17,4,stone_slab2)
B(-11,17,6,wooden_slab:4)
B(-11,17,7,stained_hardened_clay:1)
B(-11,18,1,red_sandstone:2)
B(-11,19,-11,stained_hardened_clay:1)
B(-11,19,0,LOG:13)
B(-11,19,1,LOG:13)
B(-11,19,2,red_sandstone:2)
B(-11,19,4,stone_slab2)
B(-11,19,11,stone_slab2)
B(-11,20,-2,wooden_slab:4)
B(-11,20,-1,stained_hardened_clay:1)
B(-11,20,1,LOG:13)
B(-11,20,3,red_sandstone:2)
B(-11,20,4,wooden_slab:4)
B(-11,20,7,stained_hardened_clay:1)
B(-11,21,-2,stone_slab2)
B(-11,21,0,stained_hardened_clay:1)
B(-11,21,3,red_sandstone:2)
B(-11,22,-12,red_sandstone:2)
B(-11,23,2,red_sandstone:2)
B(-10,5,5,stained_hardened_clay:1)
B(-10,5,6,stone_slab2)
B(-10,7,7,stone_slab2)
B(-10,8,5,stained_hardened_clay:1)
B(-10,9,-6,stained_hardened_clay:1)
B(-10,9,8,wooden_slab:4)
B(-10,10,-7,LOG:13)
B(-10,10,-6,stained_hardened_clay:1)
B(-10,10,8,wooden_slab:4)
B(-10,11,-7,LOG:13)
B(-10,12,-8,LOG:13)
B(-10,12,6,stained_hardened_clay:1)
B(-10,12,7,LOG:13)
B(-10,12,8,LOG:13)
B(-10,12,9,wooden_slab:4)
B(-10,13,-10,LOG:13)
B(-10,13,-9,stained_hardened_clay:1)
B(-10,13,7,LOG:13)
B(-10,13,8,LOG:13)
B(-10,14,-11,LOG:13)
B(-10,14,-10,LOG:13)
B(-10,14,5,red_sandstone:2)
B(-10,14,6,wooden_slab:4)
B(-10,14,7,stone_slab2)
B(-10,14,9,red_sandstone:2)
B(-10,15,-12,wooden_slab:4)
B(-10,15,-11,LOG:13)
B(-10,15,-10,stone_slab2)
B(-10,15,4,red_sandstone:2)
B(-10,15,7,wooden_slab:4)
B(-10,15,8,stained_hardened_clay:1)
B(-10,15,9,red_sandstone:2)
B(-10,15,10,LOG:13)
B(-10,16,-11,stone_slab2)
B(-10,16,7,stained_hardened_clay:1)
B(-10,16,9,red_sandstone:2)
B(-10,16,10,LOG:13)
B(-10,16,11,red_sandstone:2)
B(-10,16,12,stone_slab2)
B(-10,17,-13,stone_slab2)
B(-10,17,1,stained_hardened_clay:1)
B(-10,17,3,stained_hardened_clay:1)
B(-10,17,4,stone_slab2)
B(-10,17,6,wooden_slab:4)
B(-10,17,7,wooden_slab:4)
B(-10,17,10,stone_slab2)
B(-10,17,12,red_sandstone:2)
B(-10,18,-14,stone_slab2)
B(-10,18,-13,red_sandstone:2)
B(-10,18,-12,red_sandstone:2)
B(-10,18,5,stone_slab2)
B(-10,18,9,stained_hardened_clay:1)
B(-10,18,10,wooden_slab:4)
B(-10,19,-13,stained_hardened_clay:1)
B(-10,19,0,stained_hardened_clay:1)
B(-10,19,1,LOG:13)
B(-10,19,2,LOG:13)
B(-10,19,3,stained_hardened_clay:1)
B(-10,19,5,wooden_slab:4)
B(-10,19,10,red_sandstone:2)
B(-10,20,-13,red_sandstone:2)
B(-10,20,-8,wooden_slab:4)
B(-10,20,-7,wooden_slab:4)
B(-10,20,-1,wooden_slab:4)
B(-10,20,1,wooden_slab:4)
B(-10,20,2,stone_slab2)
B(-10,20,4,wooden_slab:4)
B(-10,20,7,stone_slab2)
B(-10,21,-12,red_sandstone:2)
B(-10,21,-7,stone_slab2)
B(-10,21,1,stone_slab2)
B(-9,9,6,stone_slab2)
B(-9,10,-7,red_sandstone:2)
B(-9,10,-6,wooden_slab:4)
B(-9,11,-8,LOG:13)
B(-9,11,-7,LOG:13)
B(-9,11,-6,LOG:13)
B(-9,11,-5,stained_hardened_clay:1)
B(-9,11,-2,LOG:13)
B(-9,12,-10,LOG:13)
B(-9,12,-9,LOG:13)
B(-9,12,-8,LOG:13)
B(-9,12,-7,LOG:13)
B(-9,12,5,red_sandstone:2)
B(-9,12,7,LOG:13)
B(-9,12,9,stone_slab2)
B(-9,13,-10,LOG:13)
B(-9,13,-9,LOG:13)
B(-9,13,7,LOG:13)
B(-9,13,8,stained_hardened_clay:1)
B(-9,14,5,stained_hardened_clay:1)
B(-9,14,8,wooden_slab:4)
B(-9,15,6,red_sandstone:2)
B(-9,15,7,red_sandstone:2)
B(-9,15,8,red_sandstone:2)
B(-9,15,9,stone_slab2)
B(-9,16,-12,red_sandstone:2)
B(-9,16,-11,stained_hardened_clay:1)
B(-9,16,7,wooden_slab:4)
B(-9,16,10,LOG:13)
B(-9,16,11,LOG:13)
B(-9,16,12,stone_slab2)
B(-9,17,-12,stained_hardened_clay:1)
B(-9,17,3,LOG:13)
B(-9,17,6,stone_slab2)
B(-9,17,11,wooden_slab:4)
B(-9,18,-14,stone_slab2)
B(-9,18,-13,stone_slab2)
B(-9,18,-12,red_sandstone:2)
B(-9,18,-11,red_sandstone:2)
B(-9,18,-10,stained_hardened_clay:1)
B(-9,18,3,LOG:13)
B(-9,18,4,red_sandstone:2)
B(-9,18,5,stone_slab2)
B(-9,18,6,stone_slab2)
B(-9,18,9,red_sandstone:2)
B(-9,19,-15,wooden_slab:4)
B(-9,19,-11,wooden_slab:4)
B(-9,19,-10,red_sandstone:2)
B(-9,19,-5,stone_slab2)
B(-9,19,2,LOG:13)
B(-9,19,3,LOG:13)
B(-9,19,9,stained_hardened_clay:1)
B(-9,20,-14,stained_hardened_clay:1)
B(-9,20,-13,red_sandstone:2)
B(-9,20,-12,stone_slab2)
B(-9,20,-10,stone_slab2)
B(-9,20,-7,stone_slab2)
B(-9,20,-6,red_sandstone:2)
B(-9,20,1,stained_hardened_clay:1)
B(-9,20,2,red_sandstone:2)
B(-9,21,-13,wooden_slab:4)
B(-9,21,-4,stone_slab2)
B(-9,21,1,wooden_slab:4)
B(-9,22,-10,stained_hardened_clay:1)
B(-9,22,-4,stone_slab2)
B(-9,22,0,wooden_slab:4)
B(-9,23,-12,wooden_slab:4)
B(-8,10,-6,LOG:13)
B(-8,10,-5,LOG:13)
B(-8,10,-4,LOG:13)
B(-8,10,-3,LOG:13)
B(-8,11,-11,LOG:13)
B(-8,11,-10,LOG:13)
B(-8,11,-9,LOG:13)
B(-8,11,-7,LOG:13)
B(-8,11,-6,LOG:13)
B(-8,11,-4,LOG:13)
B(-8,11,-3,LOG:13)
B(-8,11,-2,LOG:13)
B(-8,11,5,wooden_slab:4)
B(-8,11,7,stone_slab2)
B(-8,11,9,red_sandstone:2)
B(-8,12,-10,LOG:13)
B(-8,12,-9,LOG:13)
B(-8,12,-8,LOG:13)
B(-8,12,-3,LOG:13)
B(-8,12,-2,LOG:13)
B(-8,12,-1,LOG:13)
B(-8,12,7,LOG:13)
B(-8,13,-2,LOG:13)
B(-8,13,-1,LOG:13)
B(-8,13,0,LOG:13)
B(-8,13,7,LOG:13)
B(-8,13,8,wooden_slab:4)
B(-8,14,7,red_sandstone:2)
B(-8,14,10,stone_slab2)
B(-8,15,6,red_sandstone:2)
B(-8,15,9,stained_hardened_clay:1)
B(-8,15,10,stone_slab2)
B(-8,15,11,wooden_slab:4)
B(-8,15,12,stained_hardened_clay:1)
B(-8,16,-11,stained_hardened_clay:1)
B(-8,16,3,LOG:13)
B(-8,16,6,stained_hardened_clay:1)
B(-8,16,7,stained_hardened_clay:1)
B(-8,16,11,LOG:13)
B(-8,17,-13,wooden_slab:4)
B(-8,17,-12,red_sandstone:2)
B(-8,17,3,LOG:13)
B(-8,17,6,red_sandstone:2)
B(-8,17,7,wooden_slab:4)
B(-8,17,8,stained_hardened_clay:1)
B(-8,17,11,LOG:13)
B(-8,17,12,wooden_slab:4)
B(-8,18,-15,stained_hardened_clay:1)
B(-8,18,-11,wooden_slab:4)
B(-8,18,-7,stained_hardened_clay:1)
B(-8,18,6,wooden_slab:4)
B(-8,19,-13,stone_slab2)
B(-8,19,-5,wooden_slab:4)
B(-8,19,-2,red_sandstone:2)
B(-8,19,2,wooden_slab:4)
B(-8,19,5,stone_slab2)
B(-8,20,-15,stained_hardened_clay:1)
B(-8,20,-13,wooden_slab:4)
B(-8,20,-12,stained_hardened_clay:1)
B(-8,20,-11,wooden_slab:4)
B(-8,20,-4,LOG:13)
B(-8,20,-3,wooden_slab:4)
B(-8,20,0,red_sandstone:2)
B(-8,20,11,stone_slab2)
B(-8,21,-11,stained_hardened_clay:1)
B(-8,21,-5,stone_slab2)
B(-8,22,-7,stained_hardened_clay:1)
B(-8,22,-5,red_sandstone:2)
B(-7,8,-5,LOG:13)
B(-7,9,-5,LOG:13)
B(-7,10,-10,LOG:13)
B(-7,10,-6,LOG:13)
B(-7,10,-5,LOG:13)
B(-7,10,-4,LOG:13)
B(-7,11,-11,LOG:13)
B(-7,11,-10,LOG:13)
B(-7,11,-9,LOG:13)
B(-7,11,-4,LOG:13)
B(-7,11,-3,LOG:13)
B(-7,11,-2,LOG:13)
B(-7,12,-12,LOG:13)
B(-7,12,-11,LOG:13)
B(-7,12,-2,LOG:13)
B(-7,12,6,LOG:13)
B(-7,12,7,LOG:13)
B(-7,13,-1,LOG:13)
B(-7,13,0,LOG:13)
B(-7,13,6,LOG:13)
B(-7,13,7,LOG:13)
B(-7,14,0,LOG:13)
B(-7,14,6,LOG:13)
B(-7,15,0,LOG:13)
B(-7,15,1,LOG:13)
B(-7,15,2,LOG:13)
B(-7,15,3,LOG:13)
B(-7,15,9,stone_slab2)
B(-7,15,11,stained_hardened_clay:1)
B(-7,16,3,LOG:13)
B(-7,16,6,red_sandstone:2)
B(-7,16,11,stained_hardened_clay:1)
B(-7,16,12,stained_hardened_clay:1)
B(-7,17,-13,wooden_slab:4)
B(-7,17,-4,stained_hardened_clay:1)
B(-7,17,-3,wooden_slab:4)
B(-7,17,6,red_sandstone:2)
B(-7,17,7,stone_slab2)
B(-7,17,11,LOG:13)
B(-7,18,-9,red_sandstone:2)
B(-7,18,-6,stained_hardened_clay:1)
B(-7,18,-5,stone_slab2)
B(-7,18,2,stone_slab2)
B(-7,18,3,red_sandstone:2)
B(-7,18,5,red_sandstone:2)
B(-7,18,10,stone_slab2)
B(-7,19,-13,stone_slab2)
B(-7,19,-12,stone_slab2)
B(-7,19,-10,wooden_slab:4)
B(-7,19,-9,stone_slab2)
B(-7,19,-8,red_sandstone:2)
B(-7,19,-5,red_sandstone:2)
B(-7,19,-3,wooden_slab:4)
B(-7,19,-1,red_sandstone:2)
B(-7,19,5,stone_slab2)
B(-7,20,-15,red_sandstone:2)
B(-7,20,-7,wooden_slab:4)
B(-7,20,-6,stone_slab2)
B(-7,20,-5,LOG:13)
B(-7,20,-4,LOG:13)
B(-7,20,-1,wooden_slab:4)
B(-7,21,-13,wooden_slab:4)
B(-7,21,-11,red_sandstone:2)
B(-7,22,-12,stained_hardened_clay:1)
B(-7,22,-9,stone_slab2)
B(-7,22,-8,stone_slab2)
B(-7,22,-6,stained_hardened_clay:1)
B(-7,22,-5,red_sandstone:2)
B(-7,23,-13,stone_slab2)
B(-7,23,-12,stone_slab2)
B(-7,23,-7,red_sandstone:2)
B(-6,7,-5,LOG:13)
B(-6,8,-6,LOG:13)
B(-6,8,-5,LOG:13)
B(-6,9,-5,LOG:13)
B(-6,11,-11,LOG:13)
B(-6,12,-12,LOG:13)
B(-6,12,-11,LOG:13)
B(-6,13,-13,LOG:13)
B(-6,13,-12,LOG:13)
B(-6,13,5,LOG:13)
B(-6,13,6,LOG:13)
B(-6,14,0,LOG:13)
B(-6,14,3,LOG:13)
B(-6,14,4,LOG:13)
B(-6,14,5,LOG:13)
B(-6,14,6,LOG:13)
B(-6,14,11,stone_slab2)
B(-6,15,1,LOG:13)
B(-6,15,2,LOG:13)
B(-6,15,3,LOG:13)
B(-6,15,4,LOG:13)
B(-6,15,5,stained_hardened_clay:1)
B(-6,15,11,stone_slab2)
B(-6,16,-13,stained_hardened_clay:1)
B(-6,16,-12,red_sandstone:2)
B(-6,16,3,wooden_slab:4)
B(-6,16,8,red_sandstone:2)
B(-6,17,8,red_sandstone:2)
B(-6,18,-12,wooden_slab:4)
B(-6,18,-11,stained_hardened_clay:1)
B(-6,18,-10,stone_slab2)
B(-6,18,-9,stained_hardened_clay:1)
B(-6,18,-3,stone_slab2)
B(-6,18,4,stone_slab2)
B(-6,18,6,stained_hardened_clay:1)
B(-6,18,7,stained_hardened_clay:1)
B(-6,18,9,wooden_slab:4)
B(-6,19,-13,red_sandstone:2)
B(-6,19,-12,wooden_slab:4)
B(-6,19,-7,stone_slab2)
B(-6,19,-6,wooden_slab:4)
B(-6,20,-15,stained_hardened_clay:1)
B(-6,20,-13,red_sandstone:2)
B(-6,20,-6,stone_slab2)
B(-6,20,-5,LOG:13)
B(-6,20,5,stone_slab2)
B(-6,20,7,wooden_slab:4)
B(-6,20,10,stone_slab2)
B(-6,21,-12,LOG:13)
B(-6,21,-9,stained_hardened_clay:1)
B(-6,21,-2,red_sandstone:2)
B(-6,22,-12,LOG:13)
B(-6,22,-9,stained_hardened_clay:1)
B(-6,22,-4,stone_slab2)
B(-6,23,-15,wooden_slab:4)
B(-6,23,-9,wooden_slab:4)
B(-6,23,5,wooden_slab:4)
B(-6,24,-12,stone_slab2)
B(-6,24,-11,red_sandstone:2)
B(-5,4,-3,LOG:13)
B(-5,4,-2,LOG:13)
B(-5,5,-3,LOG:13)
B(-5,6,-4,LOG:13)
B(-5,7,-5,LOG:13)
B(-5,7,-4,LOG:13)
B(-5,8,-5,LOG:13)
B(-5,12,-12,LOG:13)
B(-5,12,-11,LOG:13)
B(-5,13,-13,LOG:13)
B(-5,13,-12,LOG:13)
B(-5,15,3,LOG:13)
B(-5,15,10,stained_hardened_clay:1)
B(-5,17,6,wooden_slab:4)
B(-5,17,9,wooden_slab:4)
B(-5,18,-11,wooden_slab:4)
B(-5,18,-9,stained_hardened_clay:1)
B(-5,18,-7,wooden_slab:4)
B(-5,18,2,red_sandstone:2)
B(-5,18,3,stained_hardened_clay:1)
B(-5,18,4,stone_slab2)
B(-5,18,5,wooden_slab:4)
B(-5,19,-4,stained_hardened_clay:1)
B(-5,19,2,stained_hardened_clay:1)
B(-5,19,3,wooden_slab:4)
B(-5,19,4,stone_slab2)
B(-5,19,6,red_sandstone:2)
B(-5,19,11,red_sandstone:2)
B(-5,20,-12,LOG:13)
B(-5,20,-6,LOG:13)
B(-5,20,-5,LOG:13)
B(-5,20,-3,stone_slab2)
B(-5,20,2,wooden_slab:4)
B(-5,20,5,wooden_slab:4)
B(-5,20,6,red_sandstone:2)
B(-5,20,7,red_sandstone:2)
B(-5,21,-12,LOG:13)
B(-5,21,-11,stone_slab2)
B(-5,21,-6,red_sandstone:2)
B(-5,21,1,stone_slab2)
B(-5,21,2,stone_slab2)
B(-5,21,3,stone_slab2)
B(-5,21,7,stained_hardened_clay:1)
B(-5,22,-15,wooden_slab:4)
B(-5,22,-14,red_sandstone:2)
B(-5,22,1,wooden_slab:4)
B(-5,23,-13,wooden_slab:4)
B(-5,23,-12,stone_slab2)
B(-5,23,5,wooden_slab:4)
B(-5,24,-10,wooden_slab:4)
B(-4,2,-1,LOG:13)
B(-4,3,-3,LOG:13)
B(-4,3,-2,LOG:13)
B(-4,3,-1,LOG:13)
B(-4,4,-4,LOG:13)
B(-4,4,-2,LOG:13)
B(-4,4,-1,LOG:13)
B(-4,5,-4,LOG:13)
B(-4,5,-3,LOG:13)
B(-4,5,-2,LOG:13)
B(-4,6,-4,LOG:13)
B(-4,6,-3,LOG:13)
B(-4,7,-4,LOG:13)
B(-4,12,-14,LOG:13)
B(-4,12,-13,LOG:13)
B(-4,13,-13,LOG:13)
B(-4,13,-12,LOG:13)
B(-4,14,-14,LOG:13)
B(-4,14,-13,LOG:13)
B(-4,16,-9,stone_slab2)
B(-4,16,10,wooden_slab:4)
B(-4,17,3,wooden_slab:4)
B(-4,17,11,stained_hardened_clay:1)
B(-4,18,-8,LOG:13)
B(-4,18,3,wooden_slab:4)
B(-4,18,5,wooden_slab:4)
B(-4,19,-12,LOG:13)
B(-4,19,-11,LOG:13)
B(-4,19,-10,LOG:13)
B(-4,19,-6,LOG:13)
B(-4,19,-5,red_sandstone:2)
B(-4,19,0,stone_slab2)
B(-4,19,1,wooden_slab:4)
B(-4,19,4,stained_hardened_clay:1)
B(-4,19,6,stone_slab2)
B(-4,20,-12,LOG:13)
B(-4,20,-9,stone_slab2)
B(-4,20,-8,wooden_slab:4)
B(-4,20,-7,red_sandstone:2)
B(-4,20,-6,LOG:13)
B(-4,20,-4,wooden_slab:4)
B(-4,20,-3,red_sandstone:2)
B(-4,20,4,stained_hardened_clay:1)
B(-4,20,7,red_sandstone:2)
B(-4,21,-14,stone_slab2)
B(-4,21,-12,stained_hardened_clay:1)
B(-4,21,-11,wooden_slab:4)
B(-4,21,-10,wooden_slab:4)
B(-4,21,-4,wooden_slab:4)
B(-4,21,1,red_sandstone:2)
B(-4,22,-12,stained_hardened_clay:1)
B(-4,23,-6,red_sandstone:2)
B(-4,23,-5,wooden_slab:4)
B(-4,23,6,red_sandstone:2)
B(-4,24,-14,wooden_slab:4)
B(-3,-6,-5,LOG:13)
B(-3,-6,-4,LOG:13)
B(-3,-5,-4,LOG:13)
B(-3,-5,-3,LOG:13)
B(-3,-5,-2,LOG:1)
B(-3,-4,-4,LOG:13)
B(-3,-4,-3,LOG:13)
B(-3,-4,-2,LOG:13)
B(-3,-4,-1,LOG:13)
B(-3,-3,0,LOG:13)
B(-3,2,-2,LOG:13)
B(-3,2,-1,LOG:13)
B(-3,3,-2,LOG:13)
B(-3,3,-1,LOG:13)
B(-3,4,-4,LOG:13)
B(-3,4,-3,LOG:13)
B(-3,4,-2,LOG:13)
B(-3,5,-4,LOG:13)
B(-3,5,-3,LOG:13)
B(-3,6,-5,LOG:13)
B(-3,6,-4,LOG:13)
B(-3,12,-14,LOG:13)
B(-3,12,-13,LOG:13)
B(-3,13,-13,LOG:13)
B(-3,13,-12,LOG:13)
B(-3,14,-14,LOG:13)
B(-3,14,-13,LOG:13)
B(-3,14,-9,red_sandstone:2)
B(-3,15,-7,red_sandstone:2)
B(-3,16,-9,wooden_slab:4)
B(-3,16,-8,stone_slab2)
B(-3,17,-12,stained_hardened_clay:1)
B(-3,17,-10,LOG:13)
B(-3,17,-9,LOG:13)
B(-3,17,-8,wooden_slab:4)
B(-3,17,0,stained_hardened_clay:1)
B(-3,18,-10,LOG:13)
B(-3,18,-9,LOG:13)
B(-3,18,-8,LOG:13)
B(-3,18,-7,LOG:13)
B(-3,18,1,stained_hardened_clay:1)
B(-3,19,-11,LOG:13)
B(-3,19,-10,LOG:13)
B(-3,19,-7,LOG:13)
B(-3,19,-6,LOG:13)
B(-3,19,2,wooden_slab:4)
B(-3,20,-15,red_sandstone:2)
B(-3,20,-14,red_sandstone:2)
B(-3,20,-12,stained_hardened_clay:1)
B(-3,20,-8,red_sandstone:2)
B(-3,20,-7,stone_slab2)
B(-3,20,-6,red_sandstone:2)
B(-3,20,-5,red_sandstone:2)
B(-3,20,0,stained_hardened_clay:1)
B(-3,20,2,stained_hardened_clay:1)
B(-3,20,3,stained_hardened_clay:1)
B(-3,20,7,stone_slab2)
B(-3,21,-14,red_sandstone:2)
B(-3,21,-12,red_sandstone:2)
B(-3,21,-4,wooden_slab:4)
B(-3,22,-15,stone_slab2)
B(-3,22,-14,red_sandstone:2)
B(-3,22,-12,stained_hardened_clay:1)
B(-3,22,-11,red_sandstone:2)
B(-3,22,1,stained_hardened_clay:1)
B(-3,22,2,stained_hardened_clay:1)
B(-3,23,-15,red_sandstone:2)
B(-2,-7,-5,LOG:1)
B(-2,-7,-4,LOG:1)
B(-2,-6,-5,LOG:13)
B(-2,-6,-4,LOG:1)
B(-2,-5,-1,LOG:1)
B(-2,-4,-3,LOG:1)
B(-2,-4,-1,LOG:13)
B(-2,-4,0,LOG:13)
B(-2,-3,-1,LOG:13)
B(-2,-3,0,LOG:13)
B(-2,0,-1,LOG:13)
B(-2,0,0,LOG:13)
B(-2,1,-2,LOG:13)
B(-2,1,-1,LOG:13)
B(-2,1,0,LOG:13)
B(-2,2,-2,LOG:13)
B(-2,2,-1,LOG:13)
B(-2,2,0,LOG:13)
B(-2,3,-2,LOG:13)
B(-2,3,-1,LOG:13)
B(-2,3,0,LOG:13)
B(-2,6,-5,LOG:13)
B(-2,6,-4,LOG:13)
B(-2,7,-5,LOG:13)
B(-2,7,-4,LOG:13)
B(-2,8,-5,LOG:13)
B(-2,8,-4,LOG:13)
B(-2,11,-14,LOG:13)
B(-2,12,-14,LOG:13)
B(-2,14,-13,LOG:13)
B(-2,14,-12,LOG:13)
B(-2,15,-14,LOG:13)
B(-2,15,-13,LOG:13)
B(-2,15,-12,LOG:13)
B(-2,16,-12,LOG:13)
B(-2,16,-11,LOG:13)
B(-2,17,-11,LOG:13)
B(-2,17,-10,LOG:13)
B(-2,17,-9,red_sandstone:2)
B(-2,17,3,red_sandstone:2)
B(-2,19,-13,stone_slab2)
B(-2,19,-9,red_sandstone:2)
B(-2,19,3,stained_hardened_clay:1)
B(-2,20,-10,stained_hardened_clay:1)
B(-2,20,-6,stone_slab2)
B(-2,20,-4,stone_slab2)
B(-2,20,-3,stained_hardened_clay:1)
B(-2,20,-2,red_sandstone:2)
B(-2,20,2,wooden_slab:4)
B(-2,21,-14,stone_slab2)
B(-2,21,-13,red_sandstone:2)
B(-2,21,-12,stone_slab2)
B(-2,21,-5,stained_hardened_clay:1)
B(-2,21,-1,stone_slab2)
B(-2,21,0,stone_slab2)
B(-2,21,1,wooden_slab:4)
B(-2,21,3,red_sandstone:2)
B(-2,22,-13,stained_hardened_clay:1)
B(-2,22,-11,wooden_slab:4)
B(-2,22,3,red_sandstone:2)
B(-2,23,-13,stone_slab2)
B(-2,23,-10,wooden_slab:4)
B(-2,23,-5,stone_slab2)
B(-2,24,-12,stone_slab2)
B(-2,25,-12,stained_hardened_clay:1)
B(-1,-7,-5,LOG:1)
B(-1,-6,-4,LOG:1)
B(-1,-4,0,LOG:1)
B(-1,-4,2,LOG:13)
B(-1,-4,3,LOG:1)
B(-1,-3,0,LOG:13)
B(-1,-2,-1,LOG:13)
B(-1,-2,0,LOG:13)
B(-1,-2,1,LOG:13)
B(-1,-1,-1,LOG:13)
B(-1,-1,0,LOG:13)
B(-1,-1,1,LOG:13)
B(-1,0,-2,LOG:13)
B(-1,0,-1,LOG:13)
B(-1,0,0,LOG:13)
B(-1,0,1,LOG:13)
B(-1,1,-1,LOG:13)
B(-1,1,0,LOG:13)
B(-1,2,-2,LOG:13)
B(-1,2,-1,LOG:13)
B(-1,2,0,LOG:13)
B(-1,3,-1,LOG:13)
B(-1,7,-5,LOG:13)
B(-1,7,-4,LOG:13)
B(-1,8,-5,LOG:13)
B(-1,8,-4,LOG:13)
B(-1,9,-5,LOG:13)
B(-1,11,-14,LOG:13)
B(-1,13,-15,red_sandstone:2)
B(-1,14,-17,stone_slab2)
B(-1,15,-13,LOG:13)
B(-1,15,-12,LOG:13)
B(-1,16,-11,LOG:13)
B(-1,17,-10,red_sandstone:2)
B(-1,17,-2,stained_hardened_clay:1)
B(-1,18,-12,stone_slab2)
B(-1,18,0,wooden_slab:4)
B(-1,18,3,wooden_slab:4)
B(-1,19,-15,wooden_slab:4)
B(-1,19,-14,red_sandstone:2)
B(-1,19,0,LOG:13)
B(-1,19,1,LOG:13)
B(-1,19,2,red_sandstone:2)
B(-1,20,-15,red_sandstone:2)
B(-1,20,-11,wooden_slab:4)
B(-1,20,-5,red_sandstone:2)
B(-1,20,0,stone_slab2)
B(-1,20,7,red_sandstone:2)
B(-1,21,-15,red_sandstone:2)
B(-1,21,-14,stone_slab2)
B(-1,21,-3,stained_hardened_clay:1)
B(-1,21,0,stone_slab2)
B(-1,21,1,stone_slab2)
B(-1,21,2,red_sandstone:2)
B(-1,22,-14,stained_hardened_clay:1)
B(-1,22,-7,stained_hardened_clay:1)
B(-1,22,-6,stained_hardened_clay:1)
B(-1,22,-4,stained_hardened_clay:1)
B(-1,22,-1,red_sandstone:2)
B(-1,22,0,stone_slab2)
B(-1,22,1,stone_slab2)
B(-1,23,-7,red_sandstone:2)
B(-1,23,-5,stained_hardened_clay:1)
B(-1,23,-3,stained_hardened_clay:1)
B(-1,23,-2,red_sandstone:2)
B(-1,24,-14,wooden_slab:4)
B(-1,24,-6,wooden_slab:4)
B(-1,24,-4,red_sandstone:2)
B(0,-5,2,LOG:1)
B(0,-4,2,LOG:13)
B(0,-3,-2,LOG:13)
B(0,-3,-1,LOG:13)
B(0,-3,2,LOG:13)
B(0,-2,-2,LOG:13)
B(0,-2,-1,LOG:13)
B(0,-2,0,LOG:13)
B(0,-2,1,LOG:13)
B(0,-1,-1,LOG:13)
B(0,-1,0,LOG:13)
B(0,-1,1,LOG:13)
B(0,0,-1,LOG:13)
B(0,0,0,LOG:13)
B(0,0,1,LOG:13)
B(0,1,0,LOG:13)
B(0,8,-5,LOG:13)
B(0,9,-6,LOG:13)
B(0,9,-5,LOG:13)
B(0,10,-5,LOG:13)
B(0,11,-17,wooden_slab:4)
B(0,11,-16,wooden_slab:4)
B(0,11,-14,LOG:13)
B(0,13,-17,stained_hardened_clay:1)
B(0,16,0,wooden_slab:4)
B(0,16,1,stained_hardened_clay:1)
B(0,18,-10,wooden_slab:4)
B(0,18,0,LOG:13)
B(0,18,3,stained_hardened_clay:1)
B(0,19,-13,wooden_slab:4)
B(0,19,-12,wooden_slab:4)
B(0,19,-11,wooden_slab:4)
B(0,19,-7,stained_hardened_clay:1)
B(0,19,0,LOG:13)
B(0,20,-13,stone_slab2)
B(0,20,-6,stained_hardened_clay:1)
B(0,20,-5,stained_hardened_clay:1)
B(0,20,3,wooden_slab:4)
B(0,21,-16,stone_slab2)
B(0,21,-15,stone_slab2)
B(0,21,-14,stone_slab2)
B(0,21,-13,stained_hardened_clay:1)
B(0,21,-12,wooden_slab:4)
B(0,21,-11,stained_hardened_clay:1)
B(0,21,-3,red_sandstone:2)
B(0,21,-1,stained_hardened_clay:1)
B(0,21,1,red_sandstone:2)
B(0,21,2,wooden_slab:4)
B(0,22,-16,stained_hardened_clay:1)
B(0,22,-11,red_sandstone:2)
B(0,22,-8,red_sandstone:2)
B(0,22,-6,wooden_slab:4)
B(0,22,-5,stained_hardened_clay:1)
B(0,22,1,red_sandstone:2)
B(0,22,8,wooden_slab:4)
B(0,23,-12,stone_slab2)
B(0,23,-7,stone_slab2)
B(0,24,-14,red_sandstone:2)
B(0,24,-13,stone_slab2)
B(0,24,-6,wooden_slab:4)
B(0,25,-5,wooden_slab:4)
B(1,-5,2,LOG:1)
B(1,-4,2,LOG:1)
B(1,-3,-2,LOG:13)
B(1,-3,2,LOG:13)
B(1,-2,-3,LOG:13)
B(1,-2,-2,LOG:13)
B(1,-2,-1,LOG:13)
B(1,-2,0,LOG:13)
B(1,-2,1,LOG:13)
B(1,-2,2,LOG:13)
B(1,-1,-1,LOG:13)
B(1,-1,0,LOG:13)
B(1,-1,1,LOG:13)
B(1,9,-5,LOG:13)
B(1,10,-15,stained_hardened_clay:1)
B(1,10,-6,LOG:13)
B(1,10,-5,LOG:13)
B(1,11,-14,LOG:13)
B(1,11,-13,LOG:13)
B(1,11,-6,LOG:13)
B(1,13,-17,stone_slab2)
B(1,13,-14,red_sandstone:2)
B(1,17,-14,stained_hardened_clay:1)
B(1,17,0,stone_slab2)
B(1,18,-16,stone_slab2)
B(1,18,-14,red_sandstone:2)
B(1,18,-13,stained_hardened_clay:1)
B(1,18,-12,stone_slab2)
B(1,18,0,LOG:13)
B(1,18,1,LOG:13)
B(1,18,8,wooden_slab:4)
B(1,19,-13,stone_slab2)
B(1,19,-6,wooden_slab:4)
B(1,19,0,wooden_slab:4)
B(1,19,1,wooden_slab:4)
B(1,19,10,wooden_slab:4)
B(1,20,-14,red_sandstone:2)
B(1,20,-13,stained_hardened_clay:1)
B(1,20,-12,wooden_slab:4)
B(1,20,-4,wooden_slab:4)
B(1,20,-2,wooden_slab:4)
B(1,20,-1,stone_slab2)
B(1,20,3,red_sandstone:2)
B(1,20,10,red_sandstone:2)
B(1,21,-12,stained_hardened_clay:1)
B(1,21,-8,stone_slab2)
B(1,21,-5,stone_slab2)
B(1,21,-3,stone_slab2)
B(1,21,-2,wooden_slab:4)
B(1,21,1,wooden_slab:4)
B(1,22,-16,wooden_slab:4)
B(1,22,-14,stone_slab2)
B(1,22,-10,stone_slab2)
B(1,22,-6,stone_slab2)
B(1,22,-3,stone_slab2)
B(1,22,-2,stained_hardened_clay:1)
B(1,22,-1,stone_slab2)
B(1,22,10,red_sandstone:2)
B(1,23,-14,stone_slab2)
B(1,23,-13,wooden_slab:4)
B(1,23,-11,stained_hardened_clay:1)
B(1,23,-4,stained_hardened_clay:1)
B(1,23,-2,red_sandstone:2)
B(1,24,-14,red_sandstone:2)
B(1,24,-8,red_sandstone:2)
B(1,24,-1,red_sandstone:2)
B(1,25,-6,red_sandstone:2)
B(2,-3,-3,LOG:13)
B(2,-3,-2,LOG:13)
B(2,-3,4,LOG:1)
B(2,-2,-3,LOG:13)
B(2,-2,-2,LOG:13)
B(2,-2,1,LOG:13)
B(2,-2,2,LOG:13)
B(2,10,-17,wooden_slab:4)
B(2,10,-6,LOG:13)
B(2,10,-5,LOG:13)
B(2,11,-16,stone_slab2)
B(2,11,-14,wooden_slab:4)
B(2,11,-13,LOG:13)
B(2,11,-7,LOG:13)
B(2,11,-6,LOG:13)
B(2,12,-13,LOG:13)
B(2,12,-6,LOG:13)
B(2,13,-17,stone_slab2)
B(2,13,-16,wooden_slab:4)
B(2,13,-13,stone_slab2)
B(2,16,-17,stone_slab2)
B(2,16,-15,stone_slab2)
B(2,17,1,LOG:13)
B(2,17,2,LOG:13)
B(2,17,8,stained_hardened_clay:1)
B(2,18,-12,stone_slab2)
B(2,18,-6,LOG:13)
B(2,18,1,LOG:13)
B(2,18,8,stained_hardened_clay:1)
B(2,19,-16,red_sandstone:2)
B(2,19,-14,stained_hardened_clay:1)
B(2,19,-7,LOG:13)
B(2,19,-6,LOG:13)
B(2,19,-1,red_sandstone:2)
B(2,19,1,stained_hardened_clay:1)
B(2,19,8,stone_slab2)
B(2,20,-17,stone_slab2)
B(2,20,-16,red_sandstone:2)
B(2,20,-13,stained_hardened_clay:1)
B(2,20,-11,stone_slab2)
B(2,20,-7,LOG:13)
B(2,20,-6,wooden_slab:4)
B(2,20,-3,stone_slab2)
B(2,20,-2,red_sandstone:2)
B(2,20,-1,stone_slab2)
B(2,20,0,stone_slab2)
B(2,20,6,red_sandstone:2)
B(2,20,8,LOG:13)
B(2,20,9,LOG:13)
B(2,21,-15,wooden_slab:4)
B(2,21,-13,stone_slab2)
B(2,21,-12,stone_slab2)
B(2,21,-8,wooden_slab:4)
B(2,21,-5,wooden_slab:4)
B(2,21,-2,stone_slab2)
B(2,21,1,stone_slab2)
B(2,21,2,stained_hardened_clay:1)
B(2,21,3,red_sandstone:2)
B(2,21,4,red_sandstone:2)
B(2,21,5,red_sandstone:2)
B(2,22,-12,stained_hardened_clay:1)
B(2,22,-4,stone_slab2)
B(2,22,-2,red_sandstone:2)
B(2,22,0,red_sandstone:2)
B(2,22,2,stone_slab2)
B(2,22,8,wooden_slab:4)
B(2,22,10,wooden_slab:4)
B(2,23,-16,stone_slab2)
B(2,23,-14,red_sandstone:2)
B(2,23,-13,stone_slab2)
B(2,23,-8,stained_hardened_clay:1)
B(2,23,-4,red_sandstone:2)
B(2,23,2,red_sandstone:2)
B(2,23,9,red_sandstone:2)
B(2,24,-15,red_sandstone:2)
B(2,24,-14,wooden_slab:4)
B(2,24,-8,red_sandstone:2)
B(2,24,-7,stone_slab2)
B(2,25,-7,stone_slab2)
B(3,-7,4,LOG:1)
B(3,-6,4,LOG:1)
B(3,-5,3,LOG:1)
B(3,-5,4,LOG:13)
B(3,-4,-3,LOG:13)
B(3,-4,4,LOG:13)
B(3,-3,-4,LOG:13)
B(3,-3,-3,LOG:13)
B(3,-3,4,LOG:13)
B(3,-2,-4,LOG:13)
B(3,-2,-3,LOG:13)
B(3,-2,2,LOG:13)
B(3,-2,3,LOG:13)
B(3,10,-16,stained_hardened_clay:1)
B(3,11,-17,stained_hardened_clay:1)
B(3,11,-14,wooden_slab:4)
B(3,11,-7,LOG:13)
B(3,12,-13,LOG:13)
B(3,12,-7,LOG:13)
B(3,13,-18,red_sandstone:2)
B(3,13,-14,stone_slab2)
B(3,13,-13,stone_slab2)
B(3,13,2,stone_slab2)
B(3,14,2,stained_hardened_clay:1)
B(3,15,-15,wooden_slab:4)
B(3,15,-14,red_sandstone:2)
B(3,16,-15,red_sandstone:2)
B(3,17,-5,LOG:13)
B(3,17,2,LOG:13)
B(3,17,4,wooden_slab:4)
B(3,17,5,stone_slab2)
B(3,18,-13,stone_slab2)
B(3,18,-6,LOG:13)
B(3,18,-5,LOG:13)
B(3,18,3,stained_hardened_clay:1)
B(3,18,5,red_sandstone:2)
B(3,19,-8,stone_slab2)
B(3,19,-6,red_sandstone:2)
B(3,19,-4,stained_hardened_clay:1)
B(3,19,-3,stained_hardened_clay:1)
B(3,19,-2,red_sandstone:2)
B(3,19,1,red_sandstone:2)
B(3,19,2,stained_hardened_clay:1)
B(3,19,3,red_sandstone:2)
B(3,19,7,stone_slab2)
B(3,20,-15,wooden_slab:4)
B(3,20,-9,red_sandstone:2)
B(3,20,-8,red_sandstone:2)
B(3,20,-7,LOG:13)
B(3,20,-6,LOG:13)
B(3,20,-3,stained_hardened_clay:1)
B(3,20,-2,stained_hardened_clay:1)
B(3,20,3,stone_slab2)
B(3,20,7,LOG:13)
B(3,20,8,LOG:13)
B(3,20,11,stained_hardened_clay:1)
B(3,21,-15,wooden_slab:4)
B(3,21,-13,stained_hardened_clay:1)
B(3,21,-12,wooden_slab:4)
B(3,21,-10,wooden_slab:4)
B(3,21,-7,LOG:13)
B(3,21,-6,red_sandstone:2)
B(3,21,-1,stained_hardened_clay:1)
B(3,21,2,stained_hardened_clay:1)
B(3,21,4,stained_hardened_clay:1)
B(3,21,6,wooden_slab:4)
B(3,21,8,wooden_slab:4)
B(3,22,-16,red_sandstone:2)
B(3,22,-15,stone_slab2)
B(3,22,-14,stone_slab2)
B(3,22,-13,LOG:13)
B(3,22,-12,red_sandstone:2)
B(3,22,-11,red_sandstone:2)
B(3,22,-10,wooden_slab:4)
B(3,22,-6,red_sandstone:2)
B(3,22,-1,red_sandstone:2)
B(3,22,4,stone_slab2)
B(3,22,8,stone_slab2)
B(3,23,-14,stone_slab2)
B(3,23,-10,red_sandstone:2)
B(3,23,-5,wooden_slab:4)
B(3,23,-4,stone_slab2)
B(3,23,-1,stained_hardened_clay:1)
B(3,23,0,wooden_slab:4)
B(3,24,-13,wooden_slab:4)
B(3,24,-8,red_sandstone:2)
B(3,24,-5,stained_hardened_clay:1)
B(3,24,-4,wooden_slab:4)
B(3,24,-2,stone_slab2)
B(3,24,0,wooden_slab:4)
B(4,-5,-3,LOG:13)
B(4,-5,-2,LOG:13)
B(4,-5,4,LOG:1)
B(4,-4,-3,LOG:13)
B(4,-3,-4,LOG:13)
B(4,-3,-3,LOG:13)
B(4,-3,4,LOG:13)
B(4,-2,3,LOG:13)
B(4,-2,4,LOG:13)
B(4,11,-7,LOG:13)
B(4,12,-14,LOG:13)
B(4,12,-13,LOG:13)
B(4,12,-7,LOG:13)
B(4,12,-6,LOG:13)
B(4,13,-7,LOG:13)
B(4,13,2,stone_slab2)
B(4,14,-15,stone_slab2)
B(4,14,-12,stone_slab2)
B(4,15,-16,stone_slab2)
B(4,15,-15,stained_hardened_clay:1)
B(4,15,-5,LOG:13)
B(4,15,1,LOG:13)
B(4,16,-14,red_sandstone:2)
B(4,16,-5,LOG:13)
B(4,16,1,LOG:13)
B(4,16,2,LOG:13)
B(4,16,5,stained_hardened_clay:1)
B(4,17,-12,stained_hardened_clay:1)
B(4,17,-5,LOG:13)
B(4,17,1,wooden_slab:4)
B(4,17,2,LOG:13)
B(4,17,3,LOG:13)
B(4,17,7,stone_slab2)
B(4,18,-1,stained_hardened_clay:1)
B(4,18,1,stone_slab2)
B(4,18,3,LOG:13)
B(4,18,4,LOG:13)
B(4,19,-14,stained_hardened_clay:1)
B(4,19,-12,red_sandstone:2)
B(4,19,-8,stone_slab2)
B(4,19,-3,stone_slab2)
B(4,19,0,wooden_slab:4)
B(4,19,1,wooden_slab:4)
B(4,19,2,stone_slab2)
B(4,19,3,wooden_slab:4)
B(4,19,4,LOG:13)
B(4,19,6,red_sandstone:2)
B(4,19,7,stone_slab2)
B(4,20,-13,wooden_slab:4)
B(4,20,-12,wooden_slab:4)
B(4,20,-7,LOG:13)
B(4,20,-3,stone_slab2)
B(4,20,-2,red_sandstone:2)
B(4,20,0,stone_slab2)
B(4,20,4,stained_hardened_clay:1)
B(4,20,5,red_sandstone:2)
B(4,20,7,LOG:13)
B(4,20,8,stained_hardened_clay:1)
B(4,21,-11,wooden_slab:4)
B(4,21,-6,red_sandstone:2)
B(4,21,-4,wooden_slab:4)
B(4,21,-1,stone_slab2)
B(4,21,1,stained_hardened_clay:1)
B(4,21,5,stained_hardened_clay:1)
B(4,21,6,wooden_slab:4)
B(4,21,10,stained_hardened_clay:1)
B(4,22,-16,stone_slab2)
B(4,22,-13,LOG:13)
B(4,22,-12,red_sandstone:2)
B(4,22,-8,red_sandstone:2)
B(4,22,-6,stained_hardened_clay:1)
B(4,22,-5,stained_hardened_clay:1)
B(4,22,-4,red_sandstone:2)
B(4,22,-1,stone_slab2)
B(4,22,0,red_sandstone:2)
B(4,22,1,red_sandstone:2)
B(4,22,5,stained_hardened_clay:1)
B(4,23,-16,stained_hardened_clay:1)
B(4,23,-14,wooden_slab:4)
B(4,23,-13,stained_hardened_clay:1)
B(4,23,-11,stone_slab2)
B(4,23,-7,red_sandstone:2)
B(4,23,6,stained_hardened_clay:1)
B(4,24,-15,stained_hardened_clay:1)
B(4,24,-14,wooden_slab:4)
B(4,25,-12,stained_hardened_clay:1)
B(5,10,-5,red_sandstone:2)
B(5,11,-18,stained_hardened_clay:1)
B(5,11,-5,red_sandstone:2)
B(5,12,-17,wooden_slab:4)
B(5,12,-15,LOG:13)
B(5,12,-14,LOG:13)
B(5,12,-13,red_sandstone:2)
B(5,12,-7,LOG:13)
B(5,12,-6,LOG:13)
B(5,12,2,wooden_slab:4)
B(5,12,3,wooden_slab:4)
B(5,13,-15,stained_hardened_clay:1)
B(5,13,-13,stone_slab2)
B(5,13,-7,LOG:13)
B(5,13,-6,LOG:13)
B(5,13,-5,LOG:13)
B(5,13,2,wooden_slab:4)
B(5,14,-16,stained_hardened_clay:1)
B(5,14,-15,red_sandstone:2)
B(5,14,-14,stained_hardened_clay:1)
B(5,14,-5,LOG:13)
B(5,14,-2,red_sandstone:2)
B(5,14,0,LOG:13)
B(5,15,-18,wooden_slab:4)
B(5,15,-15,stained_hardened_clay:1)
B(5,15,-14,stained_hardened_clay:1)
B(5,15,-5,LOG:13)
B(5,15,0,LOG:13)
B(5,15,1,LOG:13)
B(5,16,-13,red_sandstone:2)
B(5,16,-12,stained_hardened_clay:1)
B(5,16,0,wooden_slab:4)
B(5,16,1,stone_slab2)
B(5,16,3,stone_slab2)
B(5,16,6,red_sandstone:2)
B(5,17,-2,stained_hardened_clay:1)
B(5,17,-1,red_sandstone:2)
B(5,17,1,wooden_slab:4)
B(5,17,4,stained_hardened_clay:1)
B(5,17,5,red_sandstone:2)
B(5,17,6,red_sandstone:2)
B(5,17,8,wooden_slab:4)
B(5,18,-15,stained_hardened_clay:1)
B(5,18,-1,red_sandstone:2)
B(5,18,4,stone_slab2)
B(5,18,6,wooden_slab:4)
B(5,19,-8,wooden_slab:4)
B(5,19,-3,wooden_slab:4)
B(5,19,2,stained_hardened_clay:1)
B(5,19,4,LOG:13)
B(5,19,5,LOG:13)
B(5,19,6,LOG:13)
B(5,20,-13,stained_hardened_clay:1)
B(5,20,-11,stone_slab2)
B(5,20,-7,wooden_slab:4)
B(5,20,-3,red_sandstone:2)
B(5,20,1,stained_hardened_clay:1)
B(5,20,3,stone_slab2)
B(5,20,4,stone_slab2)
B(5,20,6,LOG:13)
B(5,20,7,LOG:13)
B(5,21,-15,wooden_slab:4)
B(5,21,-13,LOG:13)
B(5,21,-12,LOG:13)
B(5,21,-11,red_sandstone:2)
B(5,21,-10,stained_hardened_clay:1)
B(5,21,3,wooden_slab:4)
B(5,21,5,stained_hardened_clay:1)
B(5,21,7,wooden_slab:4)
B(5,21,9,wooden_slab:4)
B(5,22,-13,LOG:13)
B(5,22,-4,stone_slab2)
B(5,22,4,red_sandstone:2)
B(5,22,6,stone_slab2)
B(5,23,-12,stained_hardened_clay:1)
B(5,23,-1,wooden_slab:4)
B(6,6,6,stone_slab2)
B(6,6,7,stained_hardened_clay:1)
B(6,7,6,red_sandstone:2)
B(6,7,7,stone_slab2)
B(6,9,-16,wooden_slab:4)
B(6,9,-6,stained_hardened_clay:1)
B(6,10,-16,stained_hardened_clay:1)
B(6,10,-2,red_sandstone:2)
B(6,11,-17,stained_hardened_clay:1)
B(6,11,-3,wooden_slab:4)
B(6,11,3,stone_slab2)
B(6,12,-15,stained_hardened_clay:1)
B(6,12,-5,LOG:13)
B(6,12,4,wooden_slab:4)
B(6,13,-6,LOG:13)
B(6,13,-5,LOG:13)
B(6,13,-4,LOG:13)
B(6,13,-2,stained_hardened_clay:1)
B(6,13,0,LOG:13)
B(6,13,3,stone_slab2)
B(6,13,4,wooden_slab:4)
B(6,14,-5,LOG:13)
B(6,14,-4,LOG:13)
B(6,14,-3,LOG:13)
B(6,14,-1,stained_hardened_clay:1)
B(6,14,0,LOG:13)
B(6,14,4,stone_slab2)
B(6,14,6,stained_hardened_clay:1)
B(6,14,7,red_sandstone:2)
B(6,15,-15,stained_hardened_clay:1)
B(6,15,4,red_sandstone:2)
B(6,16,-18,red_sandstone:2)
B(6,16,-15,stained_hardened_clay:1)
B(6,16,-11,red_sandstone:2)
B(6,16,-1,red_sandstone:2)
B(6,16,6,red_sandstone:2)
B(6,17,6,stained_hardened_clay:1)
B(6,18,-13,wooden_slab:4)
B(6,18,1,stained_hardened_clay:1)
B(6,18,2,stained_hardened_clay:1)
B(6,18,3,wooden_slab:4)
B(6,19,-10,wooden_slab:4)
B(6,19,-9,stained_hardened_clay:1)
B(6,19,-8,red_sandstone:2)
B(6,19,-5,stained_hardened_clay:1)
B(6,19,0,stained_hardened_clay:1)
B(6,19,1,stained_hardened_clay:1)
B(6,19,5,stained_hardened_clay:1)
B(6,19,7,stained_hardened_clay:1)
B(6,20,-15,stained_hardened_clay:1)
B(6,20,-13,stone_slab2)
B(6,20,-11,stone_slab2)
B(6,20,-9,stained_hardened_clay:1)
B(6,20,-5,wooden_slab:4)
B(6,20,-2,red_sandstone:2)
B(6,20,4,stained_hardened_clay:1)
B(6,20,6,stained_hardened_clay:1)
B(6,20,7,wooden_slab:4)
B(6,21,-15,stone_slab2)
B(6,21,-12,LOG:13)
B(6,21,-11,LOG:13)
B(6,21,4,stained_hardened_clay:1)
B(6,21,5,wooden_slab:4)
B(6,22,-12,red_sandstone:2)
B(6,22,5,red_sandstone:2)
B(6,23,-14,wooden_slab:4)
B(6,23,-11,stained_hardened_clay:1)
B(6,24,-13,red_sandstone:2)
B(7,2,6,LOG:13)
B(7,3,6,LOG:13)
B(7,4,6,LOG:13)
B(7,4,7,stained_hardened_clay:1)
B(7,5,6,LOG:13)
B(7,6,5,stained_hardened_clay:1)
B(7,6,6,LOG:13)
B(7,7,4,stained_hardened_clay:1)
B(7,7,5,LOG:13)
B(7,7,6,LOG:13)
B(7,8,4,stained_hardened_clay:1)
B(7,8,5,LOG:13)
B(7,8,6,red_sandstone:2)
B(7,9,4,stained_hardened_clay:1)
B(7,9,5,LOG:13)
B(7,10,-7,wooden_slab:4)
B(7,10,-2,stone_slab2)
B(7,10,4,LOG:13)
B(7,10,5,LOG:13)
B(7,11,-4,stone_slab2)
B(7,11,3,LOG:13)
B(7,12,-7,stone_slab2)
B(7,12,-5,stone_slab2)
B(7,12,-4,LOG:13)
B(7,12,0,LOG:13)
B(7,12,1,LOG:13)
B(7,12,3,stained_hardened_clay:1)
B(7,12,4,red_sandstone:2)
B(7,12,7,wooden_slab:4)
B(7,13,-13,red_sandstone:2)
B(7,13,-5,red_sandstone:2)
B(7,13,-4,LOG:13)
B(7,13,-2,LOG:13)
B(7,13,-1,LOG:13)
B(7,13,0,LOG:13)
B(7,14,-16,red_sandstone:2)
B(7,14,-5,LOG:13)
B(7,14,-4,LOG:13)
B(7,14,-3,LOG:13)
B(7,14,-2,LOG:13)
B(7,14,-1,LOG:13)
B(7,15,-16,red_sandstone:2)
B(7,15,-12,stained_hardened_clay:1)
B(7,15,-6,LOG:13)
B(7,15,-5,LOG:13)
B(7,15,-4,LOG:13)
B(7,15,-3,red_sandstone:2)
B(7,15,-1,stained_hardened_clay:1)
B(7,15,1,wooden_slab:4)
B(7,15,3,red_sandstone:2)
B(7,16,-6,LOG:13)
B(7,16,0,red_sandstone:2)
B(7,16,4,stone_slab2)
B(7,17,-16,red_sandstone:2)
B(7,17,-15,red_sandstone:2)
B(7,17,-14,wooden_slab:4)
B(7,17,-13,red_sandstone:2)
B(7,17,-3,stained_hardened_clay:1)
B(7,17,3,wooden_slab:4)
B(7,17,5,stone_slab2)
B(7,18,-16,red_sandstone:2)
B(7,18,-15,red_sandstone:2)
B(7,18,-13,stained_hardened_clay:1)
B(7,18,-10,wooden_slab:4)
B(7,18,-8,stained_hardened_clay:1)
B(7,18,5,stained_hardened_clay:1)
B(7,18,9,stained_hardened_clay:1)
B(7,19,-15,wooden_slab:4)
B(7,19,1,stained_hardened_clay:1)
B(7,19,3,red_sandstone:2)
B(7,19,6,wooden_slab:4)
B(7,20,-13,stained_hardened_clay:1)
B(7,20,-11,LOG:13)
B(7,20,-10,wooden_slab:4)
B(7,20,0,stained_hardened_clay:1)
B(7,20,3,stained_hardened_clay:1)
B(7,20,6,stained_hardened_clay:1)
B(7,20,7,red_sandstone:2)
B(7,21,-13,stained_hardened_clay:1)
B(7,21,-12,stained_hardened_clay:1)
B(7,21,-11,LOG:13)
B(7,21,-10,stained_hardened_clay:1)
B(7,21,-9,stone_slab2)
B(7,21,1,stained_hardened_clay:1)
B(7,21,2,wooden_slab:4)
B(7,21,5,stained_hardened_clay:1)
B(7,21,6,stone_slab2)
B(7,22,-11,red_sandstone:2)
B(7,22,5,red_sandstone:2)
B(7,22,6,stone_slab2)
B(7,23,-13,stained_hardened_clay:1)
B(7,23,1,wooden_slab:4)
B(8,5,6,stained_hardened_clay:1)
B(8,6,6,stained_hardened_clay:1)
B(8,7,6,wooden_slab:4)
B(8,8,-4,stained_hardened_clay:1)
B(8,9,4,red_sandstone:2)
B(8,9,5,stone_slab2)
B(8,10,-4,stained_hardened_clay:1)
B(8,10,4,LOG:13)
B(8,10,5,red_sandstone:2)
B(8,10,6,red_sandstone:2)
B(8,11,-7,red_sandstone:2)
B(8,11,-6,stained_hardened_clay:1)
B(8,11,-4,LOG:13)
B(8,11,-1,wooden_slab:4)
B(8,11,2,LOG:13)
B(8,11,3,LOG:13)
B(8,11,4,LOG:13)
B(8,11,6,stained_hardened_clay:1)
B(8,12,-7,stained_hardened_clay:1)
B(8,12,-4,LOG:13)
B(8,12,-2,stone_slab2)
B(8,12,-1,stone_slab2)
B(8,12,1,LOG:13)
B(8,12,2,LOG:13)
B(8,12,3,LOG:13)
B(8,12,4,LOG:13)
B(8,12,6,red_sandstone:2)
B(8,12,7,stone_slab2)
B(8,13,-3,red_sandstone:2)
B(8,13,0,LOG:13)
B(8,14,-5,red_sandstone:2)
B(8,14,-3,LOG:13)
B(8,14,-2,LOG:13)
B(8,14,-1,wooden_slab:4)
B(8,14,0,wooden_slab:4)
B(8,14,2,stone_slab2)
B(8,14,5,wooden_slab:4)
B(8,15,-15,wooden_slab:4)
B(8,15,-4,stained_hardened_clay:1)
B(8,15,-2,stained_hardened_clay:1)
B(8,15,1,wooden_slab:4)
B(8,15,2,stone_slab2)
B(8,15,5,wooden_slab:4)
B(8,16,-14,stained_hardened_clay:1)
B(8,16,-12,stone_slab2)
B(8,16,-10,stone_slab2)
B(8,16,-9,stained_hardened_clay:1)
B(8,16,-6,LOG:13)
B(8,16,-2,wooden_slab:4)
B(8,16,2,red_sandstone:2)
B(8,16,3,stone_slab2)
B(8,17,-7,LOG:13)
B(8,17,-6,LOG:13)
B(8,17,-2,stained_hardened_clay:1)
B(8,17,-1,stone_slab2)
B(8,17,1,red_sandstone:2)
B(8,17,2,red_sandstone:2)
B(8,17,3,stained_hardened_clay:1)
B(8,17,5,red_sandstone:2)
B(8,17,7,red_sandstone:2)
B(8,18,-15,wooden_slab:4)
B(8,18,-12,red_sandstone:2)
B(8,18,-10,stone_slab2)
B(8,18,-7,LOG:13)
B(8,18,-3,red_sandstone:2)
B(8,18,0,stone_slab2)
B(8,18,1,wooden_slab:4)
B(8,18,4,wooden_slab:4)
B(8,18,6,red_sandstone:2)
B(8,19,-13,wooden_slab:4)
B(8,19,-12,wooden_slab:4)
B(8,19,-11,stone_slab2)
B(8,19,-10,LOG:13)
B(8,19,-7,red_sandstone:2)
B(8,19,-5,stone_slab2)
B(8,19,0,stone_slab2)
B(8,19,1,stained_hardened_clay:1)
B(8,19,2,stained_hardened_clay:1)
B(8,19,3,red_sandstone:2)
B(8,19,4,wooden_slab:4)
B(8,19,5,stained_hardened_clay:1)
B(8,19,7,red_sandstone:2)
B(8,20,-12,stained_hardened_clay:1)
B(8,20,-11,LOG:13)
B(8,20,-10,LOG:13)
B(8,20,-7,wooden_slab:4)
B(8,20,0,wooden_slab:4)
B(8,20,1,stained_hardened_clay:1)
B(8,20,2,stone_slab2)
B(8,20,4,stone_slab2)
B(8,20,5,stone_slab2)
B(8,20,6,red_sandstone:2)
B(8,21,-7,red_sandstone:2)
B(8,21,1,wooden_slab:4)
B(8,21,4,stained_hardened_clay:1)
B(8,21,6,red_sandstone:2)
B(8,21,8,stained_hardened_clay:1)
B(8,22,0,wooden_slab:4)
B(8,22,2,wooden_slab:4)
B(8,23,-13,stone_slab2)
B(8,23,3,stone_slab2)
B(8,23,6,red_sandstone:2)
B(8,24,2,stone_slab2)
B(9,3,-3,stone_slab2)
B(9,4,-4,wooden_slab:4)
B(9,4,-2,wooden_slab:4)
B(9,5,-3,stone_slab2)
B(9,6,-3,red_sandstone:2)
B(9,9,-6,red_sandstone:2)
B(9,9,-5,stained_hardened_clay:1)
B(9,9,-4,stone_slab2)
B(9,9,-3,wooden_slab:4)
B(9,10,-7,red_sandstone:2)
B(9,10,-6,red_sandstone:2)
B(9,10,-4,LOG:13)
B(9,10,-2,stained_hardened_clay:1)
B(9,10,6,stained_hardened_clay:1)
B(9,11,-4,LOG:13)
B(9,12,-2,red_sandstone:2)
B(9,12,-1,stained_hardened_clay:1)
B(9,12,2,wooden_slab:4)
B(9,12,3,red_sandstone:2)
B(9,12,4,red_sandstone:2)
B(9,13,-4,stone_slab2)
B(9,13,5,wooden_slab:4)
B(9,14,-4,red_sandstone:2)
B(9,15,-5,red_sandstone:2)
B(9,15,-4,wooden_slab:4)
B(9,16,-8,wooden_slab:4)
B(9,16,-7,stone_slab2)
B(9,16,-4,red_sandstone:2)
B(9,16,-2,stained_hardened_clay:1)
B(9,16,-1,stone_slab2)
B(9,16,0,red_sandstone:2)
B(9,17,-15,stone_slab2)
B(9,17,-13,stained_hardened_clay:1)
B(9,17,-12,stone_slab2)
B(9,17,-9,stone_slab2)
B(9,17,-7,LOG:13)
B(9,17,-3,wooden_slab:4)
B(9,17,-2,stained_hardened_clay:1)
B(9,17,-1,red_sandstone:2)
B(9,17,1,stained_hardened_clay:1)
B(9,17,7,wooden_slab:4)
B(9,18,-11,wooden_slab:4)
B(9,18,-8,LOG:13)
B(9,18,-7,LOG:13)
B(9,18,-6,red_sandstone:2)
B(9,18,2,stained_hardened_clay:1)
B(9,18,4,stained_hardened_clay:1)
B(9,18,6,wooden_slab:4)
B(9,18,7,stained_hardened_clay:1)
B(9,19,-13,stained_hardened_clay:1)
B(9,19,-12,stained_hardened_clay:1)
B(9,19,-10,LOG:13)
B(9,19,-9,LOG:13)
B(9,19,-8,LOG:13)
B(9,19,-7,wooden_slab:4)
B(9,19,-6,red_sandstone:2)
B(9,19,-5,wooden_slab:4)
B(9,19,0,red_sandstone:2)
B(9,19,1,stone_slab2)
B(9,19,4,wooden_slab:4)
B(9,19,5,stone_slab2)
B(9,20,-10,red_sandstone:2)
B(9,20,-9,wooden_slab:4)
B(9,20,-2,stained_hardened_clay:1)
B(9,20,1,stone_slab2)
B(9,20,4,wooden_slab:4)
B(9,21,-13,stone_slab2)
B(9,21,-11,stone_slab2)
B(9,21,-10,stained_hardened_clay:1)
B(9,21,-1,LOG:13)
B(9,21,0,LOG:13)
B(9,21,1,LOG:13)
B(9,21,2,wooden_slab:4)
B(9,21,4,wooden_slab:4)
B(9,21,5,stone_slab2)
B(9,21,6,stone_slab2)
B(9,22,-14,stone_slab2)
B(9,22,-13,wooden_slab:4)
B(9,22,-12,stone_slab2)
B(9,22,-10,red_sandstone:2)
B(9,22,-9,stone_slab2)
B(9,22,2,wooden_slab:4)
B(9,22,3,red_sandstone:2)
B(9,22,4,stained_hardened_clay:1)
B(9,22,5,stone_slab2)
B(9,23,0,stained_hardened_clay:1)
B(9,23,4,wooden_slab:4)
B(9,23,5,stone_slab2)
B(9,24,-1,wooden_slab:4)
B(10,3,-3,wooden_slab:4)
B(10,4,-4,stone_slab2)
B(10,4,-3,LOG:13)
B(10,5,-4,red_sandstone:2)
B(10,5,-3,LOG:13)
B(10,6,-3,LOG:13)
B(10,6,-2,stained_hardened_clay:1)
B(10,7,-4,LOG:13)
B(10,7,-3,LOG:13)
B(10,7,-2,stained_hardened_clay:1)
B(10,8,-5,stained_hardened_clay:1)
B(10,8,-4,LOG:13)
B(10,9,-5,red_sandstone:2)
B(10,9,-4,LOG:13)
B(10,9,-3,wooden_slab:4)
B(10,10,-5,stained_hardened_clay:1)
B(10,10,-4,LOG:13)
B(10,10,-3,stone_slab2)
B(10,10,-2,red_sandstone:2)
B(10,10,6,stone_slab2)
B(10,11,-3,stained_hardened_clay:1)
B(10,12,-4,wooden_slab:4)
B(10,12,-2,wooden_slab:4)
B(10,12,3,wooden_slab:4)
B(10,13,-3,stone_slab2)
B(10,14,-2,stained_hardened_clay:1)
B(10,14,4,stained_hardened_clay:1)
B(10,15,-5,stained_hardened_clay:1)
B(10,15,-3,red_sandstone:2)
B(10,15,-2,wooden_slab:4)
B(10,15,-1,wooden_slab:4)
B(10,15,0,wooden_slab:4)
B(10,16,-7,stained_hardened_clay:1)
B(10,16,-5,stained_hardened_clay:1)
B(10,16,-4,stained_hardened_clay:1)
B(10,16,-1,wooden_slab:4)
B(10,16,1,stone_slab2)
B(10,16,4,stone_slab2)
B(10,17,-10,stained_hardened_clay:1)
B(10,17,-8,wooden_slab:4)
B(10,17,-3,red_sandstone:2)
B(10,17,-2,stone_slab2)
B(10,18,-11,stone_slab2)
B(10,18,-9,stone_slab2)
B(10,18,-8,red_sandstone:2)
B(10,18,-7,LOG:13)
B(10,18,-6,LOG:13)
B(10,18,-4,stone_slab2)
B(10,18,4,wooden_slab:4)
B(10,18,6,red_sandstone:2)
B(10,19,-13,stone_slab2)
B(10,19,-11,wooden_slab:4)
B(10,19,-9,wooden_slab:4)
B(10,19,-7,red_sandstone:2)
B(10,19,-4,stained_hardened_clay:1)
B(10,19,-3,stone_slab2)
B(10,19,0,stone_slab2)
B(10,19,1,stained_hardened_clay:1)
B(10,19,2,stone_slab2)
B(10,19,4,wooden_slab:4)
B(10,20,-13,stained_hardened_clay:1)
B(10,20,-8,red_sandstone:2)
B(10,20,-7,red_sandstone:2)
B(10,20,-6,stone_slab2)
B(10,20,-4,stone_slab2)
B(10,20,-3,wooden_slab:4)
B(10,20,-2,LOG:13)
B(10,20,-1,red_sandstone:2)
B(10,20,1,stone_slab2)
B(10,20,4,red_sandstone:2)
B(10,20,7,red_sandstone:2)
B(10,21,-10,red_sandstone:2)
B(10,21,-9,red_sandstone:2)
B(10,21,-6,stone_slab2)
B(10,21,-3,stone_slab2)
B(10,21,-2,LOG:13)
B(10,21,-1,LOG:13)
B(10,21,1,LOG:13)
B(10,21,4,red_sandstone:2)
B(10,21,7,stone_slab2)
B(10,22,-10,wooden_slab:4)
B(10,22,-9,stained_hardened_clay:1)
B(10,22,-2,stained_hardened_clay:1)
B(10,22,-1,stained_hardened_clay:1)
B(10,22,1,LOG:13)
B(10,22,2,LOG:13)
B(10,22,4,wooden_slab:4)
B(10,22,5,wooden_slab:4)
B(10,22,7,red_sandstone:2)
B(10,23,-1,stained_hardened_clay:1)
B(10,23,1,stained_hardened_clay:1)
B(10,23,5,stained_hardened_clay:1)
B(10,24,2,stained_hardened_clay:1)
B(10,25,1,stone_slab2)
B(11,4,-2,wooden_slab:4)
B(11,6,-3,wooden_slab:4)
B(11,8,-4,red_sandstone:2)
B(11,8,-3,stone_slab2)
B(11,9,-4,wooden_slab:4)
B(11,10,-4,wooden_slab:4)
B(11,11,4,wooden_slab:4)
B(11,12,-3,stained_hardened_clay:1)
B(11,12,4,stained_hardened_clay:1)
B(11,13,-1,stone_slab2)
B(11,13,5,stained_hardened_clay:1)
B(11,14,-2,wooden_slab:4)
B(11,15,-3,stained_hardened_clay:1)
B(11,15,-1,stained_hardened_clay:1)
B(11,15,1,wooden_slab:4)
B(11,16,-11,stone_slab2)
B(11,16,-7,stained_hardened_clay:1)
B(11,16,-5,stained_hardened_clay:1)
B(11,17,-8,red_sandstone:2)
B(11,17,-5,stained_hardened_clay:1)
B(11,17,4,stained_hardened_clay:1)
B(11,18,-12,stone_slab2)
B(11,18,-9,red_sandstone:2)
B(11,18,-6,LOG:13)
B(11,18,-2,stone_slab2)
B(11,18,4,stone_slab2)
B(11,18,5,stained_hardened_clay:1)
B(11,19,-12,red_sandstone:2)
B(11,19,-11,stained_hardened_clay:1)
B(11,19,-10,red_sandstone:2)
B(11,19,-9,red_sandstone:2)
B(11,19,-6,LOG:13)
B(11,19,-5,red_sandstone:2)
B(11,19,-3,wooden_slab:4)
B(11,19,4,wooden_slab:4)
B(11,20,-13,red_sandstone:2)
B(11,20,-11,wooden_slab:4)
B(11,20,-10,stained_hardened_clay:1)
B(11,20,-9,stained_hardened_clay:1)
B(11,20,-8,red_sandstone:2)
B(11,20,-7,stained_hardened_clay:1)
B(11,20,-3,LOG:13)
B(11,20,-2,LOG:13)
B(11,20,0,stone_slab2)
B(11,20,3,wooden_slab:4)
B(11,21,-6,stone_slab2)
B(11,21,-5,stone_slab2)
B(11,21,-4,red_sandstone:2)
B(11,21,-3,stained_hardened_clay:1)
B(11,21,-1,stone_slab2)
B(11,21,2,red_sandstone:2)
B(11,22,-10,stained_hardened_clay:1)
B(11,22,-5,stone_slab2)
B(11,22,5,red_sandstone:2)
B(11,23,-5,stone_slab2)
B(11,23,-2,wooden_slab:4)
B(11,23,1,wooden_slab:4)
B(11,24,2,wooden_slab:4)
B(11,25,-7,red_sandstone:2)
B(12,13,0,stained_hardened_clay:1)
B(12,15,-1,wooden_slab:4)
B(12,15,0,stained_hardened_clay:1)
B(12,16,-11,wooden_slab:4)
B(12,17,-5,red_sandstone:2)
B(12,17,-2,wooden_slab:4)
B(12,17,-1,red_sandstone:2)
B(12,18,-9,wooden_slab:4)
B(12,18,-5,stained_hardened_clay:1)
B(12,19,-8,wooden_slab:4)
B(12,19,-7,stone_slab2)
B(12,19,-6,LOG:13)
B(12,19,-5,LOG:13)
B(12,19,-4,LOG:13)
B(12,19,-2,red_sandstone:2)
B(12,19,2,stained_hardened_clay:1)
B(12,19,5,wooden_slab:4)
B(12,20,-6,stone_slab2)
B(12,20,-5,stained_hardened_clay:1)
B(12,20,-4,LOG:13)
B(12,20,-3,LOG:13)
B(12,20,-1,wooden_slab:4)
B(12,20,0,red_sandstone:2)
B(12,20,1,red_sandstone:2)
B(12,20,3,wooden_slab:4)
B(12,21,-10,red_sandstone:2)
B(12,21,-6,wooden_slab:4)
B(12,21,-5,stone_slab2)
B(12,21,-3,stone_slab2)
B(12,21,-2,stained_hardened_clay:1)
B(12,22,-10,red_sandstone:2)
B(12,22,-7,stained_hardened_clay:1)
B(12,22,-6,wooden_slab:4)
B(12,22,-3,stone_slab2)
B(12,22,-1,red_sandstone:2)
B(12,22,2,stone_slab2)
B(12,23,-6,wooden_slab:4)
B(12,23,-4,stained_hardened_clay:1)
B(12,23,-3,stained_hardened_clay:1)
B(12,24,-6,stone_slab2)
B(12,24,1,red_sandstone:2)
B(12,24,2,stone_slab2)
B(12,25,-6,stone_slab2)
B(13,14,-3,wooden_slab:4)
B(13,17,-10,wooden_slab:4)
B(13,17,-9,wooden_slab:4)
B(13,17,-8,red_sandstone:2)
B(13,17,-7,stone_slab2)
B(13,17,-2,red_sandstone:2)
B(13,18,-12,wooden_slab:4)
B(13,18,-6,wooden_slab:4)
B(13,19,-10,stained_hardened_clay:1)
B(13,19,-5,red_sandstone:2)
B(13,19,-1,stained_hardened_clay:1)
B(13,19,1,stained_hardened_clay:1)
B(13,20,-8,stone_slab2)
B(13,20,-4,stained_hardened_clay:1)
B(13,20,-3,wooden_slab:4)
B(13,20,0,stone_slab2)
B(13,21,-3,red_sandstone:2)
B(13,21,-2,stained_hardened_clay:1)
B(13,21,2,wooden_slab:4)
B(13,21,3,wooden_slab:4)
B(13,22,-9,stone_slab2)
B(13,22,-8,stained_hardened_clay:1)
B(13,22,-6,red_sandstone:2)
B(13,22,-3,red_sandstone:2)
B(13,23,1,stained_hardened_clay:1)
B(13,23,2,stone_slab2)
B(13,24,-6,stained_hardened_clay:1)
B(14,18,-6,wooden_slab:4)
B(14,18,-4,stone_slab2)
B(14,19,-6,red_sandstone:2)
B(14,19,-3,stained_hardened_clay:1)
B(14,20,-6,wooden_slab:4)
B(14,20,-4,stone_slab2)
B(14,21,-1,stained_hardened_clay:1)
B(15,21,-7,wooden_slab:4)
B(15,21,-5,wooden_slab:4)
B(15,22,-6,stone_slab2)
B(15,22,-5,red_sandstone:2)
B(15,23,-5,stone_slab2)

#
# +-----------------------------------------------------------------+ #
# |                            BO3 checks                           | #
# +-----------------------------------------------------------------+ #
#

BlockCheck(0,-1,0,grass,dirt)

#
# +-----------------------------------------------------------------+ #
# |                             Branches                            | #
# +-----------------------------------------------------------------+ #
#

