
#
# +-----------------------------------------------------------------+ #
# |                            BO3 object                           | #
# +-----------------------------------------------------------------+ #
#

Author: NLBlackEagle

Description: Converted version of the BO2 47

Version: 3

SettingsMode: WriteDisable


#
# +-----------------------------------------------------------------+ #
# |                          Main settings                          | #
# +-----------------------------------------------------------------+ #
#

Tree: true

Frequency: 5

Rarity: 25.0

RotateRandomly: true

SpawnHeight: highestSolidBlock

SpawnHeightOffset: 0

SpawnHeightVariance: 0


# Height Limits for the BO3. #


MinHeight: 0

MaxHeight: 130


# Extrusion settings #


ExtrudeMode: None

ExtrudeThroughBlocks: air

MaxBranchDepth: 10

ExcludedBiomes: 


#
# +-----------------------------------------------------------------+ #
# |                      Source block settings                      | #
# +-----------------------------------------------------------------+ #
#

SourceBlocks: AIR,GRASS,DIRT,SAND

MaxPercentageOutsideSourceBlock: 0

OutsideSourceBlock: placeAnyway


#
# +-----------------------------------------------------------------+ #
# |                              Blocks                             | #
# +-----------------------------------------------------------------+ #
#

B(0,29,2,leaves:1)
B(0,20,-2,leaves:1)
B(0,21,-2,leaves:1)
B(0,22,-2,leaves:1)
B(0,25,2,leaves:1)
B(0,24,2,leaves:1)
B(0,21,2,leaves:1)
B(0,20,2,leaves:1)
B(2,9,2,leaves:1)
B(-1,-1,-1,LOG:12)
B(-1,-2,-1,LOG:12)
B(2,9,7,leaves:1)
B(0,28,-2,leaves:1)
B(-3,25,1,leaves:1)
B(0,29,-2,leaves:1)
B(-1,-5,-1,LOG:12)
B(-3,24,1,leaves:1)
B(-1,-7,-1,LOG:12)
B(-3,20,1,leaves:1)
B(0,11,-2,leaves:1)
B(0,18,2,leaves:1)
B(0,17,2,leaves:1)
B(-1,1,0,LOG:12)
B(-1,0,0,LOG:12)
B(-1,3,0,LOG:12)
B(0,0,2,LOG:12)
B(-2,-1,0,LOG:12)
B(-1,2,0,LOG:12)
B(-2,-2,0,LOG:12)
B(0,12,2,leaves:1)
B(0,11,2,leaves:1)
B(-3,8,4,leaves:1)
B(-2,-4,0,LOG:12)
B(-5,10,-5,leaves:1)
B(-2,-5,0,LOG:12)
B(-2,-6,0,LOG:12)
B(-2,-8,0,LOG:12)
B(3,8,1,leaves:1)
B(3,9,1,leaves:1)
B(-1,4,0,LOG:12)
B(-1,5,0,LOG:12)
B(-3,16,1,leaves:1)
B(-1,6,0,LOG:12)
B(-3,15,1,leaves:1)
B(-1,7,0,LOG:12)
B(-3,14,1,leaves:1)
B(-1,8,0,LOG:12)
B(-1,9,0,LOG:12)
B(-3,12,1,leaves:1)
B(-3,11,1,leaves:1)
B(1,9,-5,leaves:1)
B(-7,8,0,leaves:1)
B(-7,9,0,leaves:1)
B(0,34,-2,leaves:1)
B(0,33,-2,leaves:1)
B(0,30,-2,leaves:1)
B(3,10,-2,leaves:1)
B(0,9,6,leaves:1)
B(3,19,-2,leaves:1)
B(3,15,-2,leaves:1)
B(3,16,-2,leaves:1)
B(5,8,1,leaves:1)
B(-2,29,0,log)
B(4,9,-2,leaves:1)
B(-2,28,0,log)
B(-2,27,0,leaves:1)
B(4,7,-2,leaves:1)
B(-3,39,-1,leaves:1)
B(-2,22,0,log)
B(-2,21,0,log)
B(-3,38,-1,leaves:1)
B(-2,20,0,log)
B(-2,26,0,leaves:1)
B(-3,31,-1,leaves:1)
B(-2,25,0,leaves:1)
B(-3,34,-1,leaves:1)
B(-2,24,0,leaves:1)
B(-3,33,-1,leaves:1)
B(-2,23,0,leaves:1)
B(-3,40,-1,leaves:1)
B(-3,33,-2,leaves:1)
B(1,9,-4,leaves:1)
B(-3,32,-2,leaves:1)
B(-3,35,-2,leaves:1)
B(-3,36,-2,leaves:1)
B(-2,17,0,leaves:1)
B(-2,16,0,leaves:1)
B(3,17,0,leaves:1)
B(3,14,0,leaves:1)
B(-2,19,0,log)
B(3,15,0,leaves:1)
B(-2,18,0,leaves:1)
B(-3,29,-1,leaves:1)
B(-3,28,-1,leaves:1)
B(-3,27,-1,leaves:1)
B(0,-5,2,LOG:12)
B(0,-3,2,LOG:12)
B(-2,11,0,leaves:1)
B(-2,10,0,leaves:1)
B(0,-4,2,LOG:12)
B(0,-1,2,LOG:12)
B(3,12,0,leaves:1)
B(-2,13,0,leaves:1)
B(-3,22,-1,leaves:1)
B(-2,12,0,leaves:1)
B(3,13,0,leaves:1)
B(-3,21,-1,leaves:1)
B(3,10,0,leaves:1)
B(-2,15,0,leaves:1)
B(3,11,0,leaves:1)
B(-2,14,0,leaves:1)
B(-3,30,-1,leaves:1)
B(-3,-6,1,LOG:12)
B(-3,-7,1,LOG:12)
B(-3,-5,1,LOG:12)
B(-3,18,-1,leaves:1)
B(-3,17,-1,leaves:1)
B(-5,9,1,leaves:1)
B(-4,7,-4,leaves:1)
B(-3,10,-1,leaves:1)
B(-4,8,-4,leaves:1)
B(-3,12,-1,leaves:1)
B(-3,11,-1,leaves:1)
B(-3,13,-1,leaves:1)
B(-3,15,-1,leaves:1)
B(1,10,5,leaves:1)
B(6,8,1,leaves:1)
B(-3,15,-2,leaves:1)
B(-3,14,-2,leaves:1)
B(-3,17,-2,leaves:1)
B(0,12,-5,leaves:1)
B(-3,13,-5,leaves:1)
B(-3,12,-2,leaves:1)
B(-6,8,5,leaves:1)
B(-5,7,3,leaves:1)
B(-2,37,-2,leaves:1)
B(-2,35,-2,leaves:1)
B(-2,36,-2,leaves:1)
B(-2,42,-2,leaves:1)
B(-5,6,5,leaves:1)
B(-5,7,5,leaves:1)
B(-5,8,5,leaves:1)
B(-3,27,-2,leaves:1)
B(-3,26,-2,leaves:1)
B(-3,25,-2,leaves:1)
B(-4,8,3,leaves:1)
B(-3,22,-2,leaves:1)
B(2,9,0,leaves:1)
B(-1,9,2,leaves:1)
B(-3,9,-5,leaves:1)
B(2,26,-1,leaves:1)
B(2,27,-1,leaves:1)
B(-3,7,-5,leaves:1)
B(-2,32,-2,leaves:1)
B(-2,25,-2,leaves:1)
B(-2,24,-2,leaves:1)
B(-2,23,-2,leaves:1)
B(-3,9,-3,leaves:1)
B(-6,9,-3,leaves:1)
B(0,9,-5,leaves:1)
B(-3,6,6,leaves:1)
B(-2,47,-1,leaves:1)
B(-3,8,-3,leaves:1)
B(-3,7,6,leaves:1)
B(0,8,-5,leaves:1)
B(2,20,-1,leaves:1)
B(-2,44,-1,leaves:1)
B(-2,-1,2,LOG:12)
B(-2,43,-1,leaves:1)
B(-2,26,-2,leaves:1)
B(-6,6,-3,leaves:1)
B(-5,10,6,leaves:1)
B(-1,1,2,LOG:12)
B(-1,0,2,LOG:12)
B(-2,-8,2,LOG:12)
B(-5,11,6,leaves:1)
B(-1,44,-1,leaves:1)
B(-1,45,-1,leaves:1)
B(1,9,7,leaves:1)
B(-1,46,-1,leaves:1)
B(-4,25,3,leaves:1)
B(-5,22,0,leaves:1)
B(-5,25,0,leaves:1)
B(2,10,7,leaves:1)
B(-4,26,3,leaves:1)
B(4,7,2,leaves:1)
B(-5,29,0,leaves:1)
B(-5,28,0,leaves:1)
B(4,8,2,leaves:1)
B(-2,54,0,log)
B(-2,12,-2,leaves:1)
B(-2,55,0,log)
B(-2,52,0,log)
B(-2,53,0,log)
B(-2,15,-2,leaves:1)
B(2,32,-1,leaves:1)
B(-2,19,-2,leaves:1)
B(-3,10,7,leaves:1)
B(-2,10,-2,leaves:1)
B(-2,51,0,log)
B(2,12,3,leaves:1)
B(-4,18,3,leaves:1)
B(-2,50,0,log)
B(-4,15,3,leaves:1)
B(-4,14,3,leaves:1)
B(-2,45,0,log)
B(-2,24,-1,leaves:1)
B(-5,20,0,leaves:1)
B(-2,46,0,log)
B(-2,23,-1,leaves:1)
B(-2,47,0,leaves:1)
B(-2,22,-1,leaves:1)
B(-2,48,0,log)
B(-2,21,-1,leaves:1)
B(-2,41,0,leaves:1)
B(-2,28,-1,leaves:1)
B(-2,42,0,leaves:1)
B(-2,27,-1,leaves:1)
B(-2,43,0,log)
B(-2,26,-1,leaves:1)
B(-2,44,0,log)
B(-2,25,-1,leaves:1)
B(5,12,2,leaves:1)
B(-2,29,-1,leaves:1)
B(5,13,2,leaves:1)
B(-2,49,0,log)
B(5,14,2,leaves:1)
B(3,26,0,leaves:1)
B(-2,40,0,log)
B(2,19,-1,leaves:1)
B(2,17,-1,leaves:1)
B(-2,40,-1,leaves:1)
B(2,16,-1,leaves:1)
B(-2,41,-1,leaves:1)
B(2,13,-1,leaves:1)
B(-2,42,-1,leaves:1)
B(-2,36,0,log)
B(-2,33,-1,leaves:1)
B(2,12,-1,leaves:1)
B(-2,37,0,log)
B(2,11,-1,leaves:1)
B(-6,14,4,leaves:1)
B(-2,34,0,log)
B(-6,13,4,leaves:1)
B(-2,35,0,log)
B(-2,34,-1,leaves:1)
B(-5,10,0,leaves:1)
B(-4,12,3,leaves:1)
B(-2,37,-1,leaves:1)
B(-2,32,0,log)
B(-2,36,-1,leaves:1)
B(-2,33,0,log)
B(-2,39,-1,leaves:1)
B(-2,30,0,log)
B(-2,38,-1,leaves:1)
B(-2,31,0,log)
B(-2,38,0,log)
B(5,9,-2,leaves:1)
B(-2,39,0,log)
B(-2,20,2,leaves:1)
B(-1,16,-1,leaves:1)
B(-6,17,2,leaves:1)
B(-1,15,-1,leaves:1)
B(-1,14,-1,leaves:1)
B(-1,13,-1,leaves:1)
B(-6,18,2,leaves:1)
B(-5,23,2,leaves:1)
B(-1,12,-1,leaves:1)
B(-5,22,2,leaves:1)
B(-1,11,-1,leaves:1)
B(-1,20,-1,leaves:1)
B(-1,21,-1,leaves:1)
B(-5,14,2,leaves:1)
B(-2,18,2,leaves:1)
B(-6,22,2,leaves:1)
B(-5,18,2,leaves:1)
B(-9,8,-1,leaves:1)
B(-5,19,2,leaves:1)
B(-9,9,-1,leaves:1)
B(-2,13,2,leaves:1)
B(-2,10,2,leaves:1)
B(-2,16,2,leaves:1)
B(-2,17,2,leaves:1)
B(-2,14,2,leaves:1)
B(2,22,3,leaves:1)
B(-2,20,-1,leaves:1)
B(-2,31,2,leaves:1)
B(-2,30,2,leaves:1)
B(-1,10,-1,leaves:1)
B(-2,19,-1,leaves:1)
B(-2,21,2,leaves:1)
B(-2,14,-1,leaves:1)
B(2,27,1,leaves:1)
B(-2,15,-1,leaves:1)
B(2,26,1,leaves:1)
B(-2,16,-1,leaves:1)
B(1,-3,2,LOG:12)
B(-2,10,-1,leaves:1)
B(1,-5,2,LOG:12)
B(-2,28,2,leaves:1)
B(-2,13,-1,leaves:1)
B(-1,36,-1,leaves:1)
B(2,10,-2,leaves:1)
B(-1,35,-1,leaves:1)
B(2,11,-2,leaves:1)
B(-1,34,-1,leaves:1)
B(-1,33,-1,leaves:1)
B(-1,39,-1,leaves:1)
B(2,9,-5,leaves:1)
B(-1,38,-1,leaves:1)
B(2,11,1,leaves:1)
B(2,10,1,leaves:1)
B(-2,6,6,leaves:1)
B(2,15,-2,leaves:1)
B(-1,43,-1,leaves:1)
B(-1,40,-1,leaves:1)
B(2,9,-3,leaves:1)
B(2,16,-2,leaves:1)
B(-2,38,2,leaves:1)
B(-2,13,-5,leaves:1)
B(2,19,1,leaves:1)
B(-2,12,-5,leaves:1)
B(2,18,1,leaves:1)
B(2,15,1,leaves:1)
B(2,14,1,leaves:1)
B(-2,33,2,leaves:1)
B(-2,17,-5,leaves:1)
B(-1,23,-1,leaves:1)
B(-7,8,-2,leaves:1)
B(-1,22,-1,leaves:1)
B(-1,25,-1,leaves:1)
B(-1,24,-1,leaves:1)
B(-1,26,-1,leaves:1)
B(2,20,-2,leaves:1)
B(-1,30,-1,leaves:1)
B(-1,31,-1,leaves:1)
B(-1,32,-1,leaves:1)
B(2,9,-1,leaves:1)
B(-4,12,-6,leaves:1)
B(-1,-1,2,LOG:12)
B(-4,21,0,leaves:1)
B(-1,-2,2,LOG:12)
B(-4,24,0,leaves:1)
B(1,19,2,leaves:1)
B(-4,23,0,leaves:1)
B(1,18,2,leaves:1)
B(-4,26,0,leaves:1)
B(1,17,2,leaves:1)
B(1,14,2,leaves:1)
B(1,13,2,leaves:1)
B(-4,29,0,leaves:1)
B(1,12,2,leaves:1)
B(-1,-7,2,LOG:12)
B(1,11,2,leaves:1)
B(-1,-6,2,LOG:12)
B(-1,-3,2,LOG:12)
B(-6,17,3,leaves:1)
B(-4,23,2,leaves:1)
B(-1,-4,2,LOG:12)
B(-6,18,3,leaves:1)
B(3,8,-3,leaves:1)
B(1,10,6,leaves:1)
B(3,9,-3,leaves:1)
B(1,27,-3,leaves:1)
B(-4,30,0,leaves:1)
B(-4,31,0,leaves:1)
B(-4,11,0,leaves:1)
B(-4,10,0,leaves:1)
B(-3,11,5,leaves:1)
B(-4,19,2,leaves:1)
B(-4,15,2,leaves:1)
B(0,46,1,leaves:1)
B(-6,14,3,leaves:1)
B(-6,13,3,leaves:1)
B(-4,22,2,leaves:1)
B(-4,45,0,leaves:1)
B(-3,26,4,leaves:1)
B(0,39,1,leaves:1)
B(0,38,1,leaves:1)
B(0,36,1,leaves:1)
B(0,35,1,leaves:1)
B(0,20,5,leaves:1)
B(0,31,1,leaves:1)
B(0,30,1,leaves:1)
B(-4,39,0,leaves:1)
B(-2,-3,1,LOG:12)
B(-4,38,0,leaves:1)
B(1,10,-3,leaves:1)
B(-2,-4,1,LOG:12)
B(-2,-5,1,LOG:12)
B(-2,-6,1,LOG:12)
B(-2,-7,1,LOG:12)
B(1,15,-3,leaves:1)
B(-4,34,0,leaves:1)
B(-4,33,0,leaves:1)
B(-6,9,-5,leaves:1)
B(-6,7,-5,leaves:1)
B(-2,9,-5,leaves:1)
B(-6,6,-5,leaves:1)
B(-2,6,-5,leaves:1)
B(-2,-1,1,LOG:12)
B(-2,-2,1,LOG:12)
B(-2,7,-5,leaves:1)
B(0,24,1,leaves:1)
B(0,23,1,leaves:1)
B(0,25,1,leaves:1)
B(0,20,1,leaves:1)
B(1,19,-3,leaves:1)
B(-3,26,5,leaves:1)
B(-1,11,-2,leaves:1)
B(-3,25,5,leaves:1)
B(0,21,1,leaves:1)
B(-8,8,-1,leaves:1)
B(-1,12,-5,leaves:1)
B(-6,19,-3,leaves:1)
B(-8,9,-1,leaves:1)
B(-1,18,2,leaves:1)
B(-1,17,2,leaves:1)
B(-1,15,-2,leaves:1)
B(-1,13,2,leaves:1)
B(-1,12,2,leaves:1)
B(-1,19,-2,leaves:1)
B(-5,7,-3,leaves:1)
B(-1,11,2,leaves:1)
B(-1,18,-2,leaves:1)
B(-1,10,2,leaves:1)
B(-5,8,-3,leaves:1)
B(-6,15,-3,leaves:1)
B(-4,7,5,leaves:1)
B(0,10,1,leaves:1)
B(-5,10,-2,leaves:1)
B(-4,8,5,leaves:1)
B(0,11,1,leaves:1)
B(0,14,1,leaves:1)
B(0,15,1,leaves:1)
B(0,12,1,leaves:1)
B(-4,34,-1,leaves:1)
B(0,13,1,leaves:1)
B(-4,33,-1,leaves:1)
B(-4,32,-1,leaves:1)
B(0,19,1,leaves:1)
B(0,16,1,leaves:1)
B(-4,30,-1,leaves:1)
B(-5,16,-2,leaves:1)
B(-1,22,-5,leaves:1)
B(-1,24,-2,leaves:1)
B(-1,13,-4,leaves:1)
B(-1,23,-2,leaves:1)
B(-6,17,1,leaves:1)
B(-1,25,-2,leaves:1)
B(-1,29,-2,leaves:1)
B(-5,26,-2,leaves:1)
B(-6,22,1,leaves:1)
B(-5,25,-2,leaves:1)
B(-1,30,-2,leaves:1)
B(-4,28,-1,leaves:1)
B(-5,20,-2,leaves:1)
B(-1,31,-2,leaves:1)
B(-4,27,-1,leaves:1)
B(-4,29,-1,leaves:1)
B(-5,21,-2,leaves:1)
B(-4,26,-1,leaves:1)
B(-2,9,3,leaves:1)
B(-1,17,-5,leaves:1)
B(-4,21,-1,leaves:1)
B(2,18,2,leaves:1)
B(2,17,2,leaves:1)
B(1,34,2,leaves:1)
B(2,19,2,leaves:1)
B(-1,39,-2,leaves:1)
B(-1,38,-2,leaves:1)
B(-1,22,-4,leaves:1)
B(2,14,2,leaves:1)
B(-1,36,-2,leaves:1)
B(2,13,2,leaves:1)
B(-1,35,-2,leaves:1)
B(2,12,2,leaves:1)
B(-1,34,-2,leaves:1)
B(-1,23,-4,leaves:1)
B(-5,32,-2,leaves:1)
B(-1,17,-4,leaves:1)
B(4,9,1,leaves:1)
B(5,11,-1,leaves:1)
B(-1,18,-4,leaves:1)
B(5,10,-1,leaves:1)
B(4,8,1,leaves:1)
B(3,26,1,leaves:1)
B(1,9,8,leaves:1)
B(-5,10,-3,leaves:1)
B(3,9,6,leaves:1)
B(0,-6,1,LOG:12)
B(1,23,2,leaves:1)
B(-5,16,-3,leaves:1)
B(1,24,2,leaves:1)
B(-5,15,-3,leaves:1)
B(-6,9,-2,leaves:1)
B(1,28,2,leaves:1)
B(-6,8,-2,leaves:1)
B(-4,15,-4,leaves:1)
B(-5,19,-3,leaves:1)
B(1,29,2,leaves:1)
B(-1,45,-2,leaves:1)
B(-4,13,-4,leaves:1)
B(-4,12,-4,leaves:1)
B(-6,20,-3,leaves:1)
B(-4,11,-4,leaves:1)
B(-6,8,1,leaves:1)
B(3,10,1,leaves:1)
B(-6,9,1,leaves:1)
B(3,14,1,leaves:1)
B(3,15,1,leaves:1)
B(3,17,1,leaves:1)
B(3,18,1,leaves:1)
B(3,9,4,leaves:1)
B(0,-1,1,LOG:12)
B(0,-2,1,LOG:12)
B(0,-5,1,LOG:12)
B(5,7,3,leaves:1)
B(0,-4,1,LOG:12)
B(-1,43,0,leaves:1)
B(0,2,0,LOG:12)
B(-1,42,0,log)
B(0,3,0,LOG:12)
B(-1,41,0,leaves:1)
B(0,0,0,LOG:12)
B(-1,40,0,leaves:1)
B(0,1,0,LOG:12)
B(-1,47,0,leaves:1)
B(0,6,0,LOG:12)
B(0,7,0,LOG:12)
B(0,4,0,LOG:12)
B(-1,44,0,leaves:1)
B(0,5,0,LOG:12)
B(-3,9,-1,leaves:1)
B(-5,25,-3,leaves:1)
B(-5,26,-3,leaves:1)
B(-5,20,-3,leaves:1)
B(3,9,-5,leaves:1)
B(1,10,7,leaves:1)
B(-4,10,-1,leaves:1)
B(-3,9,1,leaves:1)
B(7,8,1,leaves:1)
B(-4,12,-1,leaves:1)
B(-4,17,-1,leaves:1)
B(0,22,-3,leaves:1)
B(-1,31,2,leaves:1)
B(0,29,-3,leaves:1)
B(-1,32,2,leaves:1)
B(0,28,-3,leaves:1)
B(-1,34,2,leaves:1)
B(-1,35,2,leaves:1)
B(-1,37,2,leaves:1)
B(-1,38,2,leaves:1)
B(-2,42,1,leaves:1)
B(-2,43,1,leaves:1)
B(-2,45,1,leaves:1)
B(-2,46,1,leaves:1)
B(-1,30,2,leaves:1)
B(-3,44,-1,leaves:1)
B(-1,22,2,leaves:1)
B(-3,45,-1,leaves:1)
B(4,8,-1,leaves:1)
B(-3,42,-1,leaves:1)
B(-1,20,2,leaves:1)
B(-3,43,-1,leaves:1)
B(-1,21,2,leaves:1)
B(0,9,0,leaves:1)
B(2,9,4,leaves:1)
B(0,8,0,leaves:1)
B(-3,46,-1,leaves:1)
B(-1,25,2,leaves:1)
B(-1,28,2,leaves:1)
B(-1,9,6,leaves:1)
B(-1,29,2,leaves:1)
B(-1,8,6,leaves:1)
B(4,7,-1,leaves:1)
B(-1,10,4,leaves:1)
B(-2,15,4,leaves:1)
B(-2,14,4,leaves:1)
B(-2,12,4,leaves:1)
B(-5,7,-5,leaves:1)
B(-2,19,4,leaves:1)
B(-2,16,4,leaves:1)
B(-2,5,1,LOG:12)
B(-4,11,-3,leaves:1)
B(-3,12,4,leaves:1)
B(-2,4,1,LOG:12)
B(-5,9,-5,leaves:1)
B(-2,3,1,LOG:12)
B(-4,13,-3,leaves:1)
B(-2,30,1,log)
B(-2,2,1,LOG:12)
B(-4,12,-3,leaves:1)
B(-2,9,1,leaves:1)
B(-4,15,-3,leaves:1)
B(-2,8,1,LOG:12)
B(-2,7,1,LOG:12)
B(-5,8,6,leaves:1)
B(-2,6,1,LOG:12)
B(-4,16,-3,leaves:1)
B(-2,25,1,leaves:1)
B(-2,24,1,leaves:1)
B(1,19,4,leaves:1)
B(-2,27,1,leaves:1)
B(-2,26,1,leaves:1)
B(-2,21,1,leaves:1)
B(-2,0,1,LOG:12)
B(-2,20,1,leaves:1)
B(-2,1,1,LOG:12)
B(-2,23,1,leaves:1)
B(-2,22,1,leaves:1)
B(1,10,4,leaves:1)
B(6,13,2,leaves:1)
B(-2,29,1,leaves:1)
B(1,14,4,leaves:1)
B(-2,28,1,log)
B(-2,26,4,leaves:1)
B(-1,21,4,leaves:1)
B(-2,25,4,leaves:1)
B(-1,20,4,leaves:1)
B(-1,10,0,LOG:12)
B(0,15,5,leaves:1)
B(-1,11,0,leaves:1)
B(-1,12,0,leaves:1)
B(0,10,5,leaves:1)
B(0,10,-3,leaves:1)
B(-1,13,0,leaves:1)
B(-1,14,0,leaves:1)
B(-2,40,1,leaves:1)
B(-1,15,0,leaves:1)
B(-2,41,1,leaves:1)
B(-1,16,0,leaves:1)
B(-1,17,0,leaves:1)
B(-1,18,0,leaves:1)
B(-1,19,0,log)
B(2,10,8,leaves:1)
B(0,19,5,leaves:1)
B(-2,38,1,leaves:1)
B(-2,36,1,leaves:1)
B(-2,34,1,leaves:1)
B(-2,33,1,leaves:1)
B(-2,32,1,leaves:1)
B(-2,31,1,log)
B(-1,16,4,leaves:1)
B(-1,17,4,leaves:1)
B(5,12,1,leaves:1)
B(5,13,1,leaves:1)
B(0,17,-3,leaves:1)
B(-2,39,1,leaves:1)
B(-3,36,1,leaves:1)
B(-1,24,0,leaves:1)
B(-3,37,1,leaves:1)
B(-1,25,0,leaves:1)
B(-1,22,0,log)
B(-1,23,0,leaves:1)
B(-1,20,0,log)
B(-3,33,1,leaves:1)
B(-1,21,0,log)
B(-3,35,1,leaves:1)
B(6,10,-1,leaves:1)
B(6,11,-1,leaves:1)
B(-1,28,0,log)
B(-4,32,-3,leaves:1)
B(-1,29,0,log)
B(-1,26,0,leaves:1)
B(-1,27,0,log)
B(2,10,6,leaves:1)
B(0,34,2,leaves:1)
B(0,30,2,leaves:1)
B(-3,40,1,leaves:1)
B(-3,41,1,leaves:1)
B(0,35,2,leaves:1)
B(0,38,2,leaves:1)
B(-1,33,0,log)
B(-1,34,0,log)
B(-1,19,6,leaves:1)
B(-1,35,0,log)
B(-1,36,0,log)
B(-1,16,6,leaves:1)
B(-1,30,0,log)
B(-1,15,6,leaves:1)
B(-1,31,0,log)
B(-1,32,0,log)
B(-2,9,-1,leaves:1)
B(-4,7,-6,leaves:1)
B(-4,26,-3,leaves:1)
B(-4,25,-3,leaves:1)
B(-1,37,0,leaves:1)
B(-1,38,0,leaves:1)
B(-1,39,0,leaves:1)
B(-2,12,1,leaves:1)
B(-2,11,1,leaves:1)
B(-2,10,1,leaves:1)
B(-4,35,2,leaves:1)
B(-2,16,1,leaves:1)
B(-2,15,1,leaves:1)
B(-2,14,1,leaves:1)
B(-2,13,1,leaves:1)
B(1,23,4,leaves:1)
B(-2,19,1,log)
B(-1,20,6,leaves:1)
B(-2,18,1,log)
B(-2,17,1,leaves:1)
B(-2,9,-3,leaves:1)
B(1,22,4,leaves:1)
B(-2,8,-3,leaves:1)
B(-5,28,1,leaves:1)
B(-2,27,3,leaves:1)
B(-3,30,0,leaves:1)
B(-5,23,1,leaves:1)
B(0,36,0,leaves:1)
B(0,34,0,leaves:1)
B(0,33,0,leaves:1)
B(0,37,0,leaves:1)
B(-3,28,0,leaves:1)
B(-3,29,0,leaves:1)
B(-4,25,4,leaves:1)
B(-2,32,3,leaves:1)
B(-3,22,0,leaves:1)
B(-3,23,0,leaves:1)
B(1,10,-4,leaves:1)
B(-3,21,0,leaves:1)
B(0,20,6,leaves:1)
B(-3,24,0,leaves:1)
B(-3,25,0,leaves:1)
B(-5,18,1,leaves:1)
B(-3,16,2,leaves:1)
B(-3,15,2,leaves:1)
B(0,41,0,leaves:1)
B(-3,13,2,leaves:1)
B(-3,41,0,leaves:1)
B(0,42,0,leaves:1)
B(-3,40,0,leaves:1)
B(-3,19,2,leaves:1)
B(-3,39,0,leaves:1)
B(-4,14,4,leaves:1)
B(3,17,2,leaves:1)
B(3,18,2,leaves:1)
B(-4,17,4,leaves:1)
B(-3,31,0,leaves:1)
B(-5,22,1,leaves:1)
B(3,12,2,leaves:1)
B(0,15,6,leaves:1)
B(-3,32,0,leaves:1)
B(3,13,2,leaves:1)
B(-3,33,0,leaves:1)
B(3,14,2,leaves:1)
B(-3,34,0,leaves:1)
B(3,8,0,leaves:1)
B(-3,35,0,leaves:1)
B(3,9,0,leaves:1)
B(-3,36,0,leaves:1)
B(-3,37,0,leaves:1)
B(-3,38,0,leaves:1)
B(0,10,0,leaves:1)
B(6,7,-1,leaves:1)
B(-3,27,2,leaves:1)
B(-1,16,5,leaves:1)
B(-5,9,0,leaves:1)
B(-3,28,2,leaves:1)
B(-1,19,5,leaves:1)
B(-3,13,-3,leaves:1)
B(0,18,0,leaves:1)
B(-3,14,-3,leaves:1)
B(0,17,0,leaves:1)
B(-3,11,-3,leaves:1)
B(0,16,0,leaves:1)
B(0,15,0,leaves:1)
B(0,14,0,leaves:1)
B(-3,17,-3,leaves:1)
B(0,13,0,leaves:1)
B(-3,18,-3,leaves:1)
B(1,8,-6,leaves:1)
B(0,12,0,leaves:1)
B(0,11,0,leaves:1)
B(-6,15,-4,leaves:1)
B(-3,46,0,leaves:1)
B(-3,47,0,leaves:1)
B(-1,20,5,leaves:1)
B(-3,45,0,leaves:1)
B(-3,32,2,leaves:1)
B(-3,36,2,leaves:1)
B(0,21,0,leaves:1)
B(-3,33,2,leaves:1)
B(0,20,0,leaves:1)
B(0,29,0,leaves:1)
B(0,28,0,leaves:1)
B(-2,10,6,leaves:1)
B(0,23,0,leaves:1)
B(0,22,0,leaves:1)
B(0,9,7,leaves:1)
B(0,24,0,leaves:1)
B(-5,7,4,leaves:1)
B(0,19,0,leaves:1)
B(-5,6,4,leaves:1)
B(-5,9,-1,leaves:1)
B(-6,8,6,leaves:1)
B(-4,8,2,leaves:1)
B(-3,9,7,leaves:1)
B(-3,10,-4,leaves:1)
B(2,9,6,leaves:1)
B(-2,11,-3,leaves:1)
B(6,10,-2,leaves:1)
B(-2,19,-3,leaves:1)
B(-2,18,-3,leaves:1)
B(-2,15,-3,leaves:1)
B(-3,7,5,leaves:1)
B(-2,14,-3,leaves:1)
B(4,11,0,leaves:1)
B(4,12,0,leaves:1)
B(4,13,0,leaves:1)
B(-2,22,-3,leaves:1)
B(-3,9,3,leaves:1)
B(4,10,0,leaves:1)
B(0,0,1,LOG:12)
B(0,2,1,LOG:12)
B(0,1,1,LOG:12)
B(0,4,1,LOG:12)
B(0,3,1,LOG:12)
B(0,6,1,LOG:12)
B(0,5,1,LOG:12)
B(-4,8,-5,leaves:1)
B(-4,12,4,leaves:1)
B(-4,7,-5,leaves:1)
B(-4,13,4,leaves:1)
B(-4,9,-5,leaves:1)
B(-4,11,4,leaves:1)
B(-1,-8,0,LOG:12)
B(-1,-7,0,LOG:12)
B(-1,-6,0,LOG:12)
B(-2,23,-3,leaves:1)
B(-1,-5,0,LOG:12)
B(-1,-4,0,LOG:12)
B(-4,13,5,leaves:1)
B(-4,12,5,leaves:1)
B(-4,11,5,leaves:1)
B(-7,8,1,leaves:1)
B(5,9,0,leaves:1)
B(5,8,0,leaves:1)
B(-2,12,-6,leaves:1)
B(-3,13,-4,leaves:1)
B(-3,13,0,leaves:1)
B(6,13,1,leaves:1)
B(6,12,1,leaves:1)
B(-3,14,-4,leaves:1)
B(-3,17,-4,leaves:1)
B(-4,10,7,leaves:1)
B(-3,12,0,leaves:1)
B(-3,11,0,leaves:1)
B(5,7,2,leaves:1)
B(-4,12,-5,leaves:1)
B(-3,18,0,leaves:1)
B(-1,29,1,log)
B(3,17,3,leaves:1)
B(-1,27,1,log)
B(0,20,4,leaves:1)
B(5,10,-2,leaves:1)
B(-1,28,1,log)
B(0,22,4,leaves:1)
B(0,23,4,leaves:1)
B(3,8,2,leaves:1)
B(-1,21,1,leaves:1)
B(-1,7,1,LOG:12)
B(3,19,-1,leaves:1)
B(-1,22,1,leaves:1)
B(-1,8,1,LOG:12)
B(1,-4,0,LOG:12)
B(-1,9,1,LOG:12)
B(-1,20,1,log)
B(2,9,1,leaves:1)
B(3,16,-1,leaves:1)
B(-1,25,1,leaves:1)
B(-1,3,1,LOG:12)
B(3,15,-1,leaves:1)
B(-1,26,1,leaves:1)
B(-1,4,1,LOG:12)
B(-1,23,1,leaves:1)
B(-1,5,1,LOG:12)
B(-1,24,1,leaves:1)
B(-1,6,1,LOG:12)
B(3,12,-1,leaves:1)
B(3,11,-1,leaves:1)
B(-1,2,1,LOG:12)
B(-1,16,1,leaves:1)
B(0,10,4,leaves:1)
B(-1,17,1,leaves:1)
B(-1,18,1,leaves:1)
B(-1,19,1,log)
B(1,17,-1,leaves:1)
B(1,9,6,leaves:1)
B(-1,18,-3,leaves:1)
B(-1,10,1,LOG:12)
B(0,15,4,leaves:1)
B(-1,11,1,leaves:1)
B(0,16,4,leaves:1)
B(-1,12,1,leaves:1)
B(-1,13,1,leaves:1)
B(-1,14,-3,leaves:1)
B(-1,14,1,leaves:1)
B(0,19,4,leaves:1)
B(-1,15,1,leaves:1)
B(-1,23,-3,leaves:1)
B(5,10,0,leaves:1)
B(5,12,0,leaves:1)
B(1,11,-1,leaves:1)
B(1,12,-1,leaves:1)
B(6,7,2,leaves:1)
B(2,15,-3,leaves:1)
B(2,19,-3,leaves:1)
B(-1,45,1,leaves:1)
B(-1,46,1,leaves:1)
B(-2,7,5,leaves:1)
B(-2,9,7,leaves:1)
B(-6,19,-1,leaves:1)
B(-6,15,-1,leaves:1)
B(-3,-7,0,LOG:12)
B(-1,39,1,leaves:1)
B(0,9,5,leaves:1)
B(-1,35,1,leaves:1)
B(6,8,0,leaves:1)
B(-1,36,1,leaves:1)
B(6,7,0,leaves:1)
B(-1,30,1,leaves:1)
B(-1,31,1,leaves:1)
B(-1,32,1,leaves:1)
B(-1,15,7,leaves:1)
B(-1,33,1,leaves:1)
B(1,-7,0,LOG:12)
B(-1,40,1,leaves:1)
B(3,8,-1,leaves:1)
B(-5,7,2,leaves:1)
B(-5,8,2,leaves:1)
B(1,18,0,leaves:1)
B(1,19,0,leaves:1)
B(1,16,0,leaves:1)
B(1,17,0,leaves:1)
B(1,14,0,leaves:1)
B(1,15,0,leaves:1)
B(1,12,0,leaves:1)
B(1,13,0,leaves:1)
B(1,10,0,leaves:1)
B(-2,15,6,leaves:1)
B(-3,8,-4,leaves:1)
B(0,9,-4,leaves:1)
B(-3,7,-4,leaves:1)
B(0,-5,3,LOG:12)
B(0,-4,3,LOG:12)
B(0,-6,3,LOG:12)
B(2,22,4,leaves:1)
B(-1,-3,1,LOG:12)
B(-1,-2,1,LOG:12)
B(-1,-5,1,LOG:12)
B(-1,-4,1,LOG:12)
B(-1,-6,1,LOG:12)
B(-6,20,-1,leaves:1)
B(4,7,3,leaves:1)
B(1,-4,1,LOG:12)
B(1,-3,1,LOG:12)
B(1,36,0,leaves:1)
B(1,35,0,leaves:1)
B(1,32,0,leaves:1)
B(1,33,0,leaves:1)
B(0,-1,0,LOG:12)
B(0,-2,0,LOG:12)
B(-5,13,5,leaves:1)
B(-5,12,5,leaves:1)
B(-5,11,5,leaves:1)
B(-5,10,5,leaves:1)
B(2,9,-4,leaves:1)
B(2,9,-6,leaves:1)
B(3,26,-1,leaves:1)
B(1,27,0,leaves:1)
B(-7,9,-1,leaves:1)
B(1,28,0,leaves:1)
B(4,15,-1,leaves:1)
B(4,12,-1,leaves:1)
B(5,7,-1,leaves:1)
B(4,11,-1,leaves:1)
B(0,-6,0,LOG:12)
B(0,-5,0,LOG:12)
B(-4,10,-4,leaves:1)
B(2,9,-2,leaves:1)
B(-4,8,-3,leaves:1)
B(0,43,-1,leaves:1)
B(1,11,3,leaves:1)
B(1,15,1,leaves:1)
B(0,42,-1,leaves:1)
B(1,16,1,leaves:1)
B(1,10,3,leaves:1)
B(-8,8,-2,leaves:1)
B(-6,13,2,leaves:1)
B(1,19,1,leaves:1)
B(-4,7,6,leaves:1)
B(1,19,3,leaves:1)
B(1,10,1,leaves:1)
B(8,8,1,leaves:1)
B(-4,6,6,leaves:1)
B(1,11,1,leaves:1)
B(1,12,1,leaves:1)
B(1,27,1,leaves:1)
B(1,23,3,leaves:1)
B(1,24,3,leaves:1)
B(1,32,-2,leaves:1)
B(0,11,3,leaves:1)
B(1,28,1,leaves:1)
B(1,29,1,leaves:1)
B(0,16,3,leaves:1)
B(1,28,3,leaves:1)
B(1,20,1,leaves:1)
B(1,29,3,leaves:1)
B(0,15,3,leaves:1)
B(-2,-6,-1,LOG:12)
B(0,20,3,leaves:1)
B(0,21,3,leaves:1)
B(0,23,3,leaves:1)
B(0,24,3,leaves:1)
B(0,28,3,leaves:1)
B(0,29,3,leaves:1)
B(-5,10,4,leaves:1)
B(-5,13,4,leaves:1)
B(-5,14,4,leaves:1)
B(7,10,-1,leaves:1)
B(-5,11,4,leaves:1)
B(-6,28,0,leaves:1)
B(3,9,5,leaves:1)
B(3,8,5,leaves:1)
B(0,34,3,leaves:1)
B(-5,17,4,leaves:1)
B(-6,8,2,leaves:1)
B(-6,19,0,leaves:1)
B(-5,8,-2,leaves:1)
B(-5,9,-2,leaves:1)
B(-5,10,-4,leaves:1)
B(-2,7,0,LOG:12)
B(-2,8,0,LOG:12)
B(-2,9,0,leaves:1)
B(-2,3,0,LOG:12)
B(3,9,-2,leaves:1)
B(-2,4,0,LOG:12)
B(-5,15,-4,leaves:1)
B(-2,5,0,LOG:12)
B(-2,6,0,LOG:12)
B(-2,0,0,LOG:12)
B(3,9,-4,leaves:1)
B(-2,2,0,LOG:12)
B(-2,1,0,LOG:12)
B(3,8,-4,leaves:1)
B(-7,13,3,leaves:1)
B(-7,12,3,leaves:1)
B(-3,9,-2,leaves:1)
B(-5,28,-1,leaves:1)
B(-5,27,-1,leaves:1)
B(-5,26,-1,leaves:1)
B(-5,21,-1,leaves:1)
B(-5,20,-1,leaves:1)
B(-5,25,-1,leaves:1)
B(-2,8,4,leaves:1)
B(3,9,-6,leaves:1)
B(-5,7,-6,leaves:1)
B(1,32,-1,leaves:1)
B(1,33,-1,leaves:1)
B(-1,-4,3,LOG:12)
B(-5,16,-1,leaves:1)
B(-1,-6,3,LOG:12)
B(4,15,-2,leaves:1)
B(1,21,-2,leaves:1)
B(1,20,-2,leaves:1)
B(-5,10,-1,leaves:1)
B(1,28,-2,leaves:1)
B(4,10,-2,leaves:1)
B(1,27,-2,leaves:1)
B(4,8,0,leaves:1)
B(4,9,0,leaves:1)
B(1,21,-1,leaves:1)
B(1,9,1,leaves:1)
B(1,20,-1,leaves:1)
B(-6,9,-1,leaves:1)
B(1,11,-2,leaves:1)
B(-1,33,-3,leaves:1)
B(-1,34,-3,leaves:1)
B(-6,9,-4,leaves:1)
B(1,10,-2,leaves:1)
B(-6,6,-4,leaves:1)
B(-1,29,-3,leaves:1)
B(-1,28,-3,leaves:1)
B(-3,6,-6,leaves:1)
B(-1,24,-3,leaves:1)
B(1,16,-2,leaves:1)
B(-1,27,-3,leaves:1)
B(-3,12,-6,leaves:1)
B(1,28,-1,leaves:1)
B(1,27,-1,leaves:1)
B(-3,26,3,leaves:1)
B(-4,7,4,leaves:1)
B(-3,27,3,leaves:1)
B(-4,8,4,leaves:1)
B(-2,16,5,leaves:1)
B(-2,15,5,leaves:1)
B(2,32,0,leaves:1)
B(-3,31,3,leaves:1)
B(-3,32,3,leaves:1)
B(-3,15,3,leaves:1)
B(-3,14,3,leaves:1)
B(-3,13,3,leaves:1)
B(-3,12,3,leaves:1)
B(0,-6,-1,LOG:12)
B(-2,11,5,leaves:1)
B(0,28,-4,leaves:1)
B(0,27,-4,leaves:1)
B(-5,15,3,leaves:1)
B(-5,14,3,leaves:1)
B(0,22,-4,leaves:1)
B(-3,9,2,leaves:1)
B(-5,18,3,leaves:1)
B(-2,-3,3,LOG:12)
B(-6,7,4,leaves:1)
B(-1,17,3,leaves:1)
B(-6,8,4,leaves:1)
B(-2,-4,3,LOG:12)
B(-2,10,-4,leaves:1)
B(-6,9,4,leaves:1)
B(-1,11,3,leaves:1)
B(-1,10,3,leaves:1)
B(-3,11,6,leaves:1)
B(-3,10,6,leaves:1)
B(-2,-5,3,LOG:12)
B(-2,-6,3,LOG:12)
B(-1,18,3,leaves:1)
B(-6,9,0,leaves:1)
B(0,17,-4,leaves:1)
B(-8,9,0,leaves:1)
B(-1,28,3,leaves:1)
B(-1,27,3,leaves:1)
B(-1,22,3,leaves:1)
B(-1,21,3,leaves:1)
B(2,9,5,leaves:1)
B(-1,9,5,leaves:1)
B(-8,8,0,leaves:1)
B(0,8,1,LOG:12)
B(0,7,1,LOG:12)
B(-2,9,-2,leaves:1)
B(0,9,1,leaves:1)
B(-5,7,-4,leaves:1)
B(-2,9,2,leaves:1)
B(-3,-5,2,LOG:12)
B(-3,-6,2,LOG:12)
B(-1,34,3,leaves:1)
B(-1,32,3,leaves:1)
B(-2,14,-4,leaves:1)
B(-2,13,-4,leaves:1)
B(0,18,-1,leaves:1)
B(0,17,-1,leaves:1)
B(-2,18,-4,leaves:1)
B(-2,17,-4,leaves:1)
B(0,11,-1,leaves:1)
B(-4,11,6,leaves:1)
B(-2,21,-4,leaves:1)
B(-4,10,6,leaves:1)
B(0,12,-1,leaves:1)
B(-2,22,-4,leaves:1)
B(0,13,-1,leaves:1)
B(-2,20,3,leaves:1)
B(-6,20,-2,leaves:1)
B(0,29,-1,leaves:1)
B(0,28,-1,leaves:1)
B(7,7,2,leaves:1)
B(7,8,0,leaves:1)
B(2,15,0,leaves:1)
B(7,7,0,leaves:1)
B(2,16,0,leaves:1)
B(2,13,0,leaves:1)
B(2,14,0,leaves:1)
B(2,17,0,leaves:1)
B(2,18,0,leaves:1)
B(-2,19,3,leaves:1)
B(-2,17,3,leaves:1)
B(0,22,-1,leaves:1)
B(-2,16,3,leaves:1)
B(-2,15,3,leaves:1)
B(2,11,0,leaves:1)
B(0,21,-1,leaves:1)
B(2,12,0,leaves:1)
B(-2,13,3,leaves:1)
B(-2,12,3,leaves:1)
B(2,10,0,leaves:1)
B(0,38,-1,leaves:1)
B(4,17,1,leaves:1)
B(4,13,1,leaves:1)
B(4,14,1,leaves:1)
B(-6,15,-2,leaves:1)
B(-6,19,-2,leaves:1)
B(4,18,2,leaves:1)
B(4,17,2,leaves:1)
B(-1,0,-1,LOG:12)
B(2,27,0,leaves:1)
B(0,33,-1,leaves:1)
B(-2,8,-4,leaves:1)
B(3,15,-3,leaves:1)
B(0,34,-1,leaves:1)
B(4,12,2,leaves:1)
B(-1,9,-1,leaves:1)
B(-2,7,-4,leaves:1)
B(2,20,0,leaves:1)
B(4,14,2,leaves:1)
B(3,19,-3,leaves:1)
B(0,30,-1,leaves:1)
B(4,13,2,leaves:1)
B(0,31,-1,leaves:1)

#
# +-----------------------------------------------------------------+ #
# |                            BO3 checks                           | #
# +-----------------------------------------------------------------+ #
#

BlockCheck(0,-1,0,Solid)
BlockCheck(0,-1,0,grass,dirt)
BlockCheck(0,-1,2,grass,dirt)
BlockCheck(1,-1,0,grass,dirt)
BlockCheck(-1,-1,0,grass,dirt)
BlockCheck(0,-1,-1,grass,dirt)
BlockCheck(0,-1,0,Solid)
BlockCheckNot(0,-1,0,air)

#
# +-----------------------------------------------------------------+ #
# |                             Branches                            | #
# +-----------------------------------------------------------------+ #
#

