
#
# +-----------------------------------------------------------------+ #
# |                            BO3 object                           | #
# +-----------------------------------------------------------------+ #
#

Author: NLBlackEagle

Description: Converted version of the BO2 48

Version: 3

SettingsMode: WriteDisable


#
# +-----------------------------------------------------------------+ #
# |                          Main settings                          | #
# +-----------------------------------------------------------------+ #
#

Tree: true

Frequency: 5

Rarity: 25.0

RotateRandomly: true

SpawnHeight: highestSolidBlock

SpawnHeightOffset: 0

SpawnHeightVariance: 0


# Height Limits for the BO3. #


MinHeight: 0

MaxHeight: 130


# Extrusion settings #


ExtrudeMode: None

ExtrudeThroughBlocks: air

MaxBranchDepth: 10

ExcludedBiomes: 


#
# +-----------------------------------------------------------------+ #
# |                      Source block settings                      | #
# +-----------------------------------------------------------------+ #
#

SourceBlocks: AIR,GRASS,DIRT,SAND

MaxPercentageOutsideSourceBlock: 0

OutsideSourceBlock: placeAnyway


#
# +-----------------------------------------------------------------+ #
# |                              Blocks                             | #
# +-----------------------------------------------------------------+ #
#

B(-1,9,4,leaves:1)
B(-6,8,7,leaves:1)
B(-6,9,7,leaves:1)
B(-1,5,4,leaves:1)
B(-2,46,10,leaves:1)
B(1,6,5,leaves:1)
B(-2,47,10,leaves:1)
B(-2,48,10,log)
B(-2,49,10,log)
B(1,9,5,leaves:1)
B(-3,1,8,leaves:1)
B(-3,0,8,leaves:1)
B(-7,9,11,leaves:1)
B(-6,-6,6,LOG:12)
B(-2,14,9,leaves:1)
B(-2,40,10,leaves:1)
B(-3,3,8,leaves:1)
B(-3,2,8,leaves:1)
B(-10,8,9,leaves:1)
B(-3,9,8,leaves:1)
B(-2,43,10,leaves:1)
B(-3,8,8,leaves:1)
B(-2,44,10,log)
B(-2,45,10,leaves:1)
B(-10,9,9,leaves:1)
B(-12,6,6,leaves:1)
B(-2,18,9,leaves:1)
B(-3,8,4,leaves:1)
B(-2,19,9,leaves:1)
B(-2,38,10,leaves:1)
B(-2,35,10,leaves:1)
B(-4,-7,6,LOG:12)
B(-2,36,10,leaves:1)
B(-2,23,9,leaves:1)
B(-4,-6,6,LOG:12)
B(-2,24,9,leaves:1)
B(-4,-5,6,LOG:12)
B(-2,39,10,leaves:1)
B(-5,-1,9,LOG:12)
B(-2,30,10,leaves:1)
B(-2,33,10,leaves:1)
B(-5,-5,9,LOG:12)
B(-2,34,10,leaves:1)
B(-5,-4,9,LOG:12)
B(-2,31,10,leaves:1)
B(-5,-3,9,LOG:12)
B(-2,32,10,leaves:1)
B(-5,-2,9,LOG:12)
B(-7,1,8,leaves:2)
B(1,20,10,leaves:1)
B(-7,9,8,leaves:1)
B(1,21,10,leaves:1)
B(-7,8,8,leaves:1)
B(-7,26,10,leaves:1)
B(-7,20,10,leaves:1)
B(-2,37,9,leaves:1)
B(-1,23,10,leaves:1)
B(-2,38,9,leaves:1)
B(-2,29,10,leaves:1)
B(-2,35,9,leaves:1)
B(-1,21,10,leaves:1)
B(-2,36,9,leaves:1)
B(-1,22,10,leaves:1)
B(-1,8,10,leaves:1)
B(-8,10,9,leaves:1)
B(-2,33,9,leaves:1)
B(-1,9,10,leaves:1)
B(-8,11,9,leaves:1)
B(-2,31,9,leaves:1)
B(-2,26,10,leaves:1)
B(-2,32,9,leaves:1)
B(-2,27,10,leaves:1)
B(-2,20,10,leaves:1)
B(-8,15,9,leaves:1)
B(-2,30,9,leaves:1)
B(-1,29,10,leaves:1)
B(-2,23,10,leaves:1)
B(-8,18,9,leaves:1)
B(-7,27,10,leaves:1)
B(-8,19,9,leaves:1)
B(-1,28,10,leaves:1)
B(-7,15,10,leaves:1)
B(1,16,10,leaves:1)
B(-7,10,10,leaves:1)
B(-6,13,6,leaves:1)
B(-6,12,6,leaves:1)
B(-6,11,6,leaves:1)
B(-6,17,6,leaves:1)
B(-2,39,9,leaves:1)
B(-6,16,6,leaves:1)
B(-6,10,15,leaves:1)
B(-6,11,15,leaves:1)
B(-2,46,9,leaves:1)
B(-3,6,13,leaves:1)
B(-2,42,9,leaves:1)
B(-2,43,9,leaves:1)
B(-8,25,9,leaves:1)
B(-2,16,10,leaves:1)
B(-3,9,13,leaves:1)
B(-2,45,9,leaves:1)
B(-2,40,9,leaves:1)
B(-2,41,9,leaves:1)
B(-2,10,10,leaves:1)
B(-7,19,10,leaves:1)
B(-1,7,7,leaves:1)
B(-4,6,9,LOG:12)
B(-4,7,9,LOG:12)
B(-6,27,6,leaves:1)
B(-4,4,9,LOG:12)
B(-4,5,9,LOG:12)
B(-4,2,9,LOG:12)
B(-6,22,6,leaves:1)
B(-4,3,9,LOG:12)
B(-4,0,9,LOG:12)
B(-4,1,9,LOG:12)
B(-6,20,10,leaves:1)
B(-6,21,10,leaves:1)
B(-2,31,12,leaves:1)
B(-2,32,12,leaves:1)
B(-6,27,10,leaves:1)
B(-11,8,8,leaves:1)
B(-6,28,10,leaves:1)
B(-11,9,8,leaves:1)
B(-1,2,9,leaves:1)
B(-1,1,9,leaves:1)
B(-11,6,8,leaves:1)
B(-1,0,9,leaves:1)
B(-11,5,8,leaves:1)
B(-11,6,4,leaves:1)
B(-6,18,6,leaves:1)
B(-1,8,9,leaves:1)
B(-8,9,9,leaves:1)
B(-5,6,8,LOG:12)
B(-5,7,8,LOG:12)
B(-5,4,8,LOG:12)
B(-5,5,8,LOG:12)
B(-5,2,8,LOG:12)
B(-5,3,8,LOG:12)
B(-5,0,8,LOG:12)
B(-5,1,8,LOG:12)
B(-7,31,10,leaves:1)
B(-6,10,10,leaves:1)
B(-6,16,10,leaves:1)
B(-5,14,9,leaves:1)
B(-5,15,9,leaves:1)
B(-5,12,9,leaves:1)
B(-5,13,9,leaves:1)
B(-5,18,9,log)
B(-5,19,9,log)
B(-5,16,9,log)
B(-5,17,9,leaves:1)
B(-5,10,9,leaves:1)
B(-5,11,9,leaves:1)
B(-5,33,6,leaves:1)
B(-5,8,1,leaves:1)
B(-8,7,13,leaves:1)
B(-5,-6,9,LOG:12)
B(1,11,5,leaves:1)
B(1,10,5,leaves:1)
B(-5,9,8,leaves:1)
B(-5,8,8,LOG:12)
B(-10,8,11,leaves:1)
B(-5,28,6,leaves:1)
B(-10,7,11,leaves:1)
B(-4,8,1,leaves:1)
B(-6,8,5,leaves:1)
B(-6,4,5,leaves:2)
B(-6,2,5,leaves:2)
B(-5,8,3,leaves:1)
B(-3,1,10,leaves:1)
B(-3,0,10,leaves:1)
B(-6,32,10,leaves:1)
B(-5,9,3,leaves:1)
B(-3,9,10,leaves:1)
B(-2,54,10,log)
B(-5,3,5,leaves:2)
B(-2,53,10,log)
B(-5,4,5,leaves:2)
B(-2,52,10,log)
B(-5,9,5,leaves:1)
B(-2,51,10,log)
B(-2,50,10,log)
B(-1,-2,10,leaves:1)
B(-6,6,7,leaves:2)
B(-6,4,7,leaves:2)
B(-4,9,3,leaves:1)
B(-4,8,3,leaves:1)
B(-6,5,7,leaves:2)
B(-6,2,7,leaves:2)
B(-5,2,5,leaves:2)
B(-6,3,7,leaves:2)
B(-6,0,7,LOG:12)
B(-6,1,7,leaves:2)
B(-2,24,14,leaves:1)
B(-2,25,14,leaves:1)
B(-3,4,6,leaves:2)
B(-3,5,6,leaves:2)
B(-4,-2,10,leaves:1)
B(-3,25,12,leaves:1)
B(-3,26,12,leaves:1)
B(-3,9,6,leaves:1)
B(-5,16,6,leaves:1)
B(-3,24,12,leaves:1)
B(-5,10,6,leaves:1)
B(-11,12,4,leaves:1)
B(1,9,7,leaves:1)
B(-5,17,6,leaves:1)
B(-2,18,14,leaves:1)
B(-5,18,6,leaves:1)
B(1,5,7,leaves:1)
B(-8,15,10,leaves:1)
B(-12,6,4,leaves:1)
B(-12,7,4,leaves:1)
B(-2,14,14,leaves:1)
B(-8,19,10,leaves:1)
B(-7,7,6,leaves:1)
B(-3,-6,7,LOG:12)
B(-7,5,6,leaves:2)
B(-3,19,12,leaves:1)
B(-7,4,6,leaves:2)
B(-3,16,12,leaves:1)
B(2,7,12,leaves:1)
B(-3,-2,7,leaves:1)
B(-7,3,6,leaves:2)
B(-8,14,10,leaves:1)
B(-7,2,6,leaves:2)
B(2,12,7,leaves:1)
B(-3,-4,7,LOG:12)
B(-7,1,6,leaves:2)
B(-3,15,12,leaves:1)
B(-5,27,6,leaves:1)
B(-3,10,12,leaves:1)
B(-3,11,12,leaves:1)
B(-5,23,6,leaves:1)
B(-5,22,6,leaves:1)
B(-7,8,6,leaves:1)
B(-8,7,5,leaves:1)
B(-8,6,5,leaves:1)
B(-8,1,5,leaves:2)
B(-3,15,7,leaves:1)
B(-3,12,7,leaves:1)
B(-5,37,10,leaves:1)
B(-4,16,13,leaves:1)
B(-7,16,12,leaves:1)
B(-2,10,12,leaves:1)
B(-5,38,10,leaves:1)
B(-5,33,10,leaves:1)
B(-5,34,10,leaves:1)
B(-8,1,7,leaves:2)
B(-2,16,12,leaves:1)
B(-2,15,12,leaves:1)
B(-5,30,10,leaves:1)
B(-4,13,13,leaves:1)
B(-2,19,12,leaves:1)
B(-4,12,13,leaves:1)
B(-4,10,13,leaves:1)
B(0,5,4,leaves:1)
B(0,9,4,leaves:1)
B(-9,11,4,leaves:1)
B(-1,7,12,leaves:1)
B(-4,12,14,leaves:1)
B(-1,8,12,leaves:1)
B(-4,11,14,leaves:1)
B(-7,27,12,leaves:1)
B(-9,11,8,leaves:1)
B(-2,20,12,leaves:1)
B(-9,14,8,leaves:1)
B(-2,25,12,leaves:1)
B(-9,10,8,leaves:1)
B(-5,42,10,leaves:1)
B(-5,41,10,leaves:1)
B(-3,31,12,leaves:1)
B(-2,27,12,leaves:1)
B(-2,26,12,leaves:1)
B(-3,5,15,leaves:1)
B(-3,34,12,leaves:1)
B(-3,6,15,leaves:1)
B(-9,8,6,leaves:1)
B(-3,35,12,leaves:1)
B(-3,32,12,leaves:1)
B(-3,8,15,leaves:1)
B(-9,7,6,leaves:1)
B(-4,19,10,leaves:1)
B(-5,16,14,leaves:1)
B(-5,12,14,leaves:1)
B(-1,44,10,leaves:1)
B(-5,8,10,leaves:1)
B(-9,8,13,leaves:1)
B(-1,45,10,leaves:1)
B(-9,7,13,leaves:1)
B(-4,10,10,leaves:1)
B(-3,14,14,leaves:1)
B(-5,-1,6,LOG:12)
B(-5,9,10,leaves:1)
B(-5,-2,6,LOG:12)
B(-3,13,14,leaves:1)
B(-3,10,14,leaves:1)
B(-3,11,14,leaves:1)
B(-9,8,11,leaves:1)
B(-4,15,10,leaves:1)
B(-11,7,6,leaves:1)
B(-4,14,10,leaves:1)
B(-11,8,6,leaves:1)
B(-4,13,10,leaves:1)
B(-4,12,10,leaves:1)
B(-11,6,6,leaves:1)
B(-4,11,10,leaves:1)
B(-5,6,14,leaves:1)
B(-8,8,7,leaves:1)
B(-1,38,10,leaves:1)
B(-5,5,14,leaves:1)
B(-8,9,7,leaves:1)
B(-1,37,10,leaves:1)
B(-5,8,14,leaves:1)
B(-1,31,12,leaves:1)
B(-1,30,10,leaves:1)
B(-5,-7,6,LOG:12)
B(-1,35,10,leaves:1)
B(-5,-6,6,LOG:12)
B(-1,34,10,leaves:1)
B(-1,33,10,leaves:1)
B(-1,32,10,leaves:1)
B(1,7,13,leaves:1)
B(-4,21,10,leaves:1)
B(-4,20,10,leaves:1)
B(-4,27,10,log)
B(-5,7,12,leaves:1)
B(-4,26,10,leaves:1)
B(-4,29,10,log)
B(-4,28,10,log)
B(-4,23,10,leaves:1)
B(-4,22,10,leaves:1)
B(-4,25,10,leaves:1)
B(-4,24,10,leaves:1)
B(-1,26,12,leaves:1)
B(-1,25,12,leaves:1)
B(-3,-1,7,leaves:1)
B(-1,24,12,leaves:1)
B(-1,27,12,leaves:1)
B(-2,7,6,leaves:1)
B(-4,32,10,leaves:1)
B(-1,14,14,leaves:1)
B(-4,31,10,leaves:1)
B(-4,30,10,leaves:1)
B(-4,36,10,leaves:1)
B(-1,18,14,leaves:1)
B(-4,35,10,leaves:1)
B(-4,34,10,leaves:1)
B(-8,25,7,leaves:1)
B(-4,39,10,leaves:1)
B(-4,38,10,leaves:1)
B(-1,15,12,leaves:1)
B(-1,14,12,leaves:1)
B(-1,19,12,leaves:1)
B(3,11,8,leaves:1)
B(-4,40,10,leaves:1)
B(-8,10,7,leaves:1)
B(-4,43,10,leaves:1)
B(-4,42,10,leaves:1)
B(-8,12,7,leaves:1)
B(-4,45,10,leaves:1)
B(-8,13,7,leaves:1)
B(-4,44,10,leaves:1)
B(-8,14,7,leaves:1)
B(-10,14,9,leaves:1)
B(-8,16,7,leaves:1)
B(-9,8,9,leaves:1)
B(1,12,6,leaves:1)
B(-4,8,15,leaves:1)
B(1,11,6,leaves:1)
B(-9,9,9,leaves:1)
B(-4,6,15,leaves:1)
B(-6,32,11,leaves:1)
B(-2,18,13,leaves:1)
B(-2,19,13,leaves:1)
B(-7,26,11,leaves:1)
B(-7,27,11,leaves:1)
B(0,13,13,leaves:1)
B(-2,14,13,leaves:1)
B(-2,15,13,leaves:1)
B(0,18,13,leaves:1)
B(-8,15,8,leaves:1)
B(-8,14,8,leaves:1)
B(-6,28,11,leaves:1)
B(-6,27,11,leaves:1)
B(-6,22,11,leaves:1)
B(-11,10,7,leaves:1)
B(-6,21,11,leaves:1)
B(-8,18,8,leaves:1)
B(-7,11,14,leaves:1)
B(0,7,13,leaves:1)
B(-5,-7,7,LOG:12)
B(-5,-6,7,LOG:12)
B(-3,-2,10,leaves:1)
B(-5,-4,7,LOG:12)
B(-4,-3,8,LOG:12)
B(-8,11,8,leaves:1)
B(-4,-2,8,LOG:12)
B(-4,-1,8,LOG:12)
B(-3,-1,10,leaves:1)
B(-8,12,8,leaves:1)
B(-1,7,14,leaves:1)
B(-5,-1,7,LOG:12)
B(-5,-2,7,LOG:12)
B(-3,20,5,leaves:1)
B(-5,-3,7,LOG:12)
B(1,7,12,leaves:1)
B(-2,24,13,leaves:1)
B(-2,25,13,leaves:1)
B(-2,26,13,leaves:1)
B(-7,19,11,leaves:1)
B(-7,18,11,leaves:1)
B(-10,6,5,leaves:1)
B(-3,15,5,leaves:1)
B(-3,16,5,leaves:1)
B(-3,19,5,leaves:1)
B(1,7,10,leaves:1)
B(1,6,10,leaves:1)
B(-10,7,5,leaves:1)
B(-2,31,13,leaves:1)
B(-6,5,14,leaves:1)
B(-10,6,7,leaves:1)
B(-10,7,7,leaves:1)
B(-10,9,7,leaves:1)
B(-7,31,8,leaves:1)
B(-7,32,8,leaves:1)
B(-9,6,4,leaves:1)
B(-4,0,7,LOG:12)
B(-4,1,7,leaves:2)
B(-4,2,7,leaves:2)
B(-4,3,7,leaves:2)
B(-4,4,7,leaves:2)
B(-1,14,2,leaves:1)
B(-4,7,7,leaves:1)
B(-4,8,7,leaves:1)
B(-6,2,9,LOG:12)
B(-6,0,9,LOG:12)
B(-4,9,5,leaves:1)
B(-6,1,9,LOG:12)
B(-8,9,11,leaves:1)
B(-8,8,11,leaves:1)
B(-2,3,9,leaves:1)
B(-4,12,8,leaves:1)
B(-2,2,9,leaves:1)
B(-4,13,8,leaves:1)
B(-2,5,9,leaves:1)
B(-4,10,8,leaves:1)
B(-2,4,9,leaves:1)
B(-4,11,8,leaves:1)
B(-4,16,8,log)
B(-2,7,3,leaves:1)
B(-4,17,8,leaves:1)
B(-2,9,9,leaves:1)
B(-4,14,8,leaves:1)
B(0,18,11,leaves:1)
B(-4,15,8,leaves:1)
B(-2,1,9,leaves:1)
B(-2,0,9,leaves:1)
B(-2,9,10,leaves:1)
B(-4,-5,8,LOG:12)
B(-4,-4,8,LOG:12)
B(-4,-7,8,LOG:12)
B(-4,-6,8,LOG:12)
B(1,5,8,leaves:1)
B(0,27,11,leaves:1)
B(-2,7,12,leaves:1)
B(-2,1,10,leaves:1)
B(-2,0,10,leaves:1)
B(-6,17,11,leaves:1)
B(-8,25,8,leaves:1)
B(-2,9,12,leaves:1)
B(-2,8,12,leaves:1)
B(-6,7,3,leaves:1)
B(-6,8,3,leaves:1)
B(-2,5,14,leaves:1)
B(3,5,4,leaves:1)
B(-2,9,14,leaves:1)
B(-2,8,14,leaves:1)
B(-6,11,13,leaves:1)
B(0,8,11,leaves:1)
B(-3,15,13,leaves:1)
B(-2,23,8,leaves:1)
B(-8,17,5,leaves:1)
B(-4,45,8,leaves:1)
B(-1,25,6,leaves:1)
B(-3,10,13,leaves:1)
B(-1,26,6,leaves:1)
B(-3,9,11,leaves:1)
B(-6,16,13,leaves:1)
B(-8,16,5,leaves:1)
B(-3,8,11,leaves:1)
B(-8,13,5,leaves:1)
B(-3,14,13,leaves:1)
B(0,7,11,leaves:1)
B(-8,11,5,leaves:1)
B(-3,11,13,leaves:1)
B(-8,12,5,leaves:1)
B(-6,12,13,leaves:1)
B(-3,12,13,leaves:1)
B(-1,31,6,leaves:1)
B(-9,13,6,leaves:1)
B(-4,8,11,leaves:1)
B(-2,18,8,leaves:1)
B(-9,12,6,leaves:1)
B(-7,-6,8,LOG:12)
B(-2,33,8,leaves:1)
B(-5,41,9,leaves:1)
B(-2,32,8,leaves:1)
B(1,16,7,leaves:1)
B(-3,51,10,log)
B(1,13,7,leaves:1)
B(-3,50,10,log)
B(-2,37,8,leaves:1)
B(1,12,7,leaves:1)
B(-2,27,8,leaves:1)
B(-2,28,8,leaves:1)
B(-10,12,6,leaves:1)
B(-10,11,6,leaves:1)
B(-4,20,8,leaves:1)
B(-3,40,10,leaves:1)
B(-3,42,10,log)
B(-3,41,10,leaves:1)
B(-5,30,9,leaves:1)
B(-3,44,10,log)
B(-5,33,9,leaves:1)
B(-4,8,9,LOG:12)
B(-3,43,10,leaves:1)
B(-4,9,9,LOG:12)
B(-3,46,10,leaves:1)
B(-3,45,10,log)
B(-3,48,10,log)
B(-4,26,8,leaves:1)
B(-3,47,10,leaves:1)
B(-5,36,9,leaves:1)
B(-4,25,8,leaves:1)
B(-4,24,8,leaves:1)
B(-3,8,1,leaves:1)
B(-3,49,10,log)
B(-4,23,8,leaves:1)
B(-4,22,8,leaves:1)
B(-4,21,8,leaves:1)
B(-4,18,8,log)
B(-4,19,8,log)
B(-3,-1,8,leaves:1)
B(-3,-2,8,leaves:1)
B(-2,13,8,leaves:1)
B(-2,12,8,leaves:1)
B(-4,31,8,leaves:1)
B(-2,15,8,leaves:1)
B(-4,30,8,leaves:1)
B(-2,14,8,leaves:1)
B(-3,33,10,leaves:1)
B(-5,22,9,leaves:1)
B(-3,-4,8,LOG:12)
B(-3,32,10,leaves:1)
B(-5,21,9,leaves:1)
B(-3,-3,8,LOG:12)
B(-3,31,10,leaves:1)
B(-6,22,13,leaves:1)
B(-5,20,9,leaves:1)
B(-3,-6,8,LOG:12)
B(-2,11,8,leaves:1)
B(-3,30,10,log)
B(-6,21,13,leaves:1)
B(-3,-5,8,LOG:12)
B(-3,37,10,leaves:1)
B(-3,36,10,log)
B(-4,36,8,leaves:1)
B(-4,39,8,leaves:1)
B(-3,35,10,log)
B(-4,38,8,leaves:1)
B(-3,34,10,log)
B(-5,23,9,leaves:1)
B(-4,32,8,leaves:1)
B(-5,29,9,leaves:1)
B(-3,39,10,leaves:1)
B(-4,35,8,leaves:1)
B(-5,28,9,leaves:1)
B(-3,38,10,leaves:1)
B(-5,27,9,leaves:1)
B(2,5,4,leaves:1)
B(-6,9,9,leaves:1)
B(-9,11,7,leaves:1)
B(-9,10,7,leaves:1)
B(2,6,4,leaves:1)
B(-9,12,7,leaves:1)
B(-1,7,6,leaves:1)
B(-1,6,6,leaves:1)
B(-3,27,10,leaves:1)
B(-7,25,6,leaves:1)
B(-2,15,4,leaves:1)
B(-3,28,10,leaves:1)
B(-2,14,4,leaves:1)
B(-3,29,10,log)
B(-5,29,7,leaves:1)
B(-3,23,10,leaves:1)
B(-2,19,4,leaves:1)
B(-3,24,10,leaves:1)
B(-2,18,4,leaves:1)
B(-3,25,10,leaves:1)
B(-5,1,6,leaves:2)
B(-5,3,6,leaves:2)
B(-3,20,10,leaves:1)
B(-5,2,6,leaves:2)
B(-3,21,10,leaves:1)
B(-5,5,6,leaves:2)
B(-3,22,10,leaves:1)
B(-5,4,6,leaves:2)
B(-5,7,6,leaves:2)
B(-5,6,6,leaves:2)
B(-5,9,6,leaves:1)
B(-7,26,8,leaves:1)
B(-2,-5,8,LOG:12)
B(-10,12,5,leaves:1)
B(-2,-3,8,LOG:12)
B(-11,8,12,leaves:1)
B(0,7,9,leaves:1)
B(-2,-2,8,leaves:1)
B(-2,-6,8,LOG:12)
B(-5,34,7,leaves:1)
B(-10,11,5,leaves:1)
B(-5,18,7,leaves:1)
B(-7,12,6,leaves:1)
B(-7,12,8,leaves:1)
B(-5,19,7,leaves:1)
B(-7,11,8,leaves:1)
B(-7,14,6,leaves:1)
B(-3,17,10,leaves:1)
B(-7,13,6,leaves:1)
B(-7,18,6,leaves:1)
B(0,10,5,leaves:1)
B(-3,12,10,leaves:1)
B(-7,17,6,leaves:1)
B(-3,10,10,leaves:1)
B(-7,19,8,leaves:1)
B(-3,11,10,leaves:1)
B(-7,17,8,leaves:1)
B(-7,16,8,leaves:1)
B(2,11,8,leaves:1)
B(2,12,8,leaves:1)
B(-7,15,8,leaves:1)
B(-7,13,8,leaves:1)
B(-3,18,4,leaves:1)
B(-3,19,4,leaves:1)
B(-3,14,4,leaves:1)
B(-3,15,4,leaves:1)
B(-5,23,7,leaves:1)
B(-5,28,7,leaves:1)
B(-1,13,4,leaves:1)
B(-1,14,4,leaves:1)
B(-1,24,13,leaves:1)
B(-1,25,13,leaves:1)
B(-2,-2,10,leaves:1)
B(-2,-1,10,leaves:1)
B(2,11,6,leaves:1)
B(-5,17,7,leaves:1)
B(-1,10,6,leaves:1)
B(-1,11,6,leaves:1)
B(-5,14,7,leaves:1)
B(-5,13,7,leaves:1)
B(-5,12,7,leaves:1)
B(-5,11,7,leaves:1)
B(-5,10,7,leaves:1)
B(-4,27,5,leaves:1)
B(-10,10,8,leaves:1)
B(-2,-1,8,leaves:1)
B(-10,14,8,leaves:1)
B(-10,8,13,leaves:1)
B(-1,8,3,leaves:1)
B(-11,6,7,leaves:1)
B(-11,9,7,leaves:1)
B(0,17,8,leaves:1)
B(-1,0,8,leaves:1)
B(-1,1,8,leaves:1)
B(0,32,9,leaves:1)
B(0,13,8,leaves:1)
B(0,33,9,leaves:1)
B(-11,8,9,leaves:1)
B(-7,8,12,leaves:1)
B(1,5,4,leaves:1)
B(-6,21,5,leaves:1)
B(-1,6,8,leaves:1)
B(-1,7,8,leaves:1)
B(1,8,4,leaves:1)
B(1,9,4,leaves:1)
B(-5,2,9,LOG:12)
B(-5,1,9,LOG:12)
B(-11,7,5,leaves:1)
B(-5,0,9,LOG:12)
B(-5,6,9,LOG:12)
B(-5,5,9,LOG:12)
B(-5,4,9,LOG:12)
B(-5,3,9,LOG:12)
B(-4,21,4,leaves:1)
B(0,21,8,leaves:1)
B(-9,7,10,leaves:1)
B(0,27,9,leaves:1)
B(-9,8,10,leaves:1)
B(-5,8,11,leaves:1)
B(-4,18,4,leaves:1)
B(-4,14,4,leaves:1)
B(-5,0,7,LOG:12)
B(0,21,9,leaves:1)
B(0,22,9,leaves:1)
B(-6,16,5,leaves:1)
B(-5,3,7,leaves:2)
B(-5,4,7,leaves:2)
B(-5,1,7,leaves:2)
B(-5,2,7,leaves:2)
B(-5,7,7,leaves:2)
B(-5,8,7,leaves:1)
B(-6,11,5,leaves:1)
B(-5,5,7,leaves:2)
B(-6,10,5,leaves:1)
B(-5,6,7,leaves:2)
B(-4,22,12,leaves:1)
B(-4,-7,7,LOG:12)
B(-3,46,8,leaves:1)
B(-4,20,12,leaves:1)
B(-4,21,12,leaves:1)
B(-4,-4,7,LOG:12)
B(-10,8,12,leaves:1)
B(-3,45,8,leaves:1)
B(-4,-3,7,LOG:12)
B(-4,-6,7,LOG:12)
B(-4,-5,7,LOG:12)
B(-3,41,8,leaves:1)
B(-4,-6,9,LOG:12)
B(-4,-5,9,LOG:12)
B(-7,9,9,leaves:1)
B(0,8,3,leaves:1)
B(-1,8,11,leaves:1)
B(-1,9,11,leaves:1)
B(-10,7,10,leaves:1)
B(-10,8,10,leaves:1)
B(-3,39,8,leaves:1)
B(-3,35,8,leaves:1)
B(0,6,7,leaves:1)
B(-4,10,12,leaves:1)
B(-7,17,5,leaves:1)
B(-4,11,12,leaves:1)
B(-3,38,8,leaves:1)
B(-1,24,5,leaves:1)
B(-7,16,5,leaves:1)
B(-3,31,8,leaves:1)
B(-7,11,5,leaves:1)
B(-3,32,8,leaves:1)
B(-3,33,8,leaves:1)
B(-3,34,8,leaves:1)
B(-7,12,5,leaves:1)
B(-4,17,12,leaves:1)
B(-3,9,9,leaves:1)
B(-2,13,6,leaves:1)
B(-2,11,6,leaves:1)
B(-3,30,8,leaves:1)
B(-4,13,12,leaves:1)
B(-4,14,12,leaves:1)
B(-4,16,12,leaves:1)
B(-5,9,4,leaves:1)
B(-5,8,4,leaves:1)
B(-4,-1,9,LOG:12)
B(-4,-2,9,LOG:12)
B(-4,-3,9,LOG:12)
B(-4,-4,9,LOG:12)
B(-6,4,6,leaves:2)
B(-4,-1,7,LOG:12)
B(-4,-2,7,LOG:12)
B(-6,3,6,leaves:2)
B(-1,-1,9,leaves:1)
B(-6,2,6,leaves:2)
B(-6,1,6,leaves:2)
B(-3,29,8,leaves:1)
B(-3,28,8,leaves:1)
B(-4,8,2,leaves:1)
B(-6,7,6,leaves:2)
B(-6,6,6,leaves:2)
B(-4,9,2,leaves:1)
B(-6,5,6,leaves:2)
B(2,5,6,leaves:1)
B(-3,8,7,leaves:1)
B(-3,4,7,leaves:2)
B(-3,23,8,leaves:1)
B(-3,22,8,leaves:1)
B(-7,4,5,leaves:2)
B(-3,21,8,leaves:1)
B(-3,0,7,leaves:1)
B(-3,20,8,leaves:1)
B(-3,27,8,leaves:1)
B(-3,26,8,log)
B(2,8,6,leaves:1)
B(-3,25,8,leaves:1)
B(-3,24,8,leaves:1)
B(-3,19,8,leaves:1)
B(-3,0,9,leaves:1)
B(-3,17,8,leaves:1)
B(-8,7,8,leaves:1)
B(-6,32,8,leaves:1)
B(-8,8,8,leaves:1)
B(-6,31,8,leaves:1)
B(-3,8,9,leaves:1)
B(-6,35,8,leaves:1)
B(-6,34,8,leaves:1)
B(-3,3,9,leaves:1)
B(-3,1,9,leaves:1)
B(-3,2,9,leaves:1)
B(-7,1,7,leaves:2)
B(-12,9,7,leaves:1)
B(-7,2,7,leaves:2)
B(-7,4,7,leaves:2)
B(-12,6,7,leaves:1)
B(-3,10,8,leaves:1)
B(-2,38,8,leaves:1)
B(-3,9,5,leaves:1)
B(-3,12,8,leaves:1)
B(-4,29,7,leaves:1)
B(-3,11,8,leaves:1)
B(-3,14,8,leaves:1)
B(-3,13,8,leaves:1)
B(-4,34,12,leaves:1)
B(-3,16,8,leaves:1)
B(-3,8,5,leaves:1)
B(-3,15,8,leaves:1)
B(-4,34,7,leaves:1)
B(-4,33,7,leaves:1)
B(-2,45,8,leaves:1)
B(-4,38,7,leaves:1)
B(-3,7,3,leaves:1)
B(-4,37,7,leaves:1)
B(-3,8,3,leaves:1)
B(-6,26,8,leaves:1)
B(-4,30,7,leaves:1)
B(-6,27,8,leaves:1)
B(-2,40,8,leaves:1)
B(-12,7,5,leaves:1)
B(-3,6,16,leaves:1)
B(-3,5,16,leaves:1)
B(-3,8,16,leaves:1)
B(-10,11,7,leaves:1)
B(0,17,9,leaves:1)
B(-10,10,7,leaves:1)
B(-4,13,4,leaves:1)
B(0,13,9,leaves:1)
B(-4,17,7,leaves:1)
B(-4,19,7,leaves:1)
B(-6,11,8,leaves:1)
B(-4,24,7,leaves:1)
B(-4,21,7,leaves:1)
B(-5,8,9,leaves:1)
B(-4,20,7,leaves:1)
B(-5,7,9,LOG:12)
B(-4,23,7,leaves:1)
B(-5,9,9,leaves:1)
B(-4,14,5,leaves:1)
B(-6,18,8,leaves:1)
B(-6,17,8,leaves:1)
B(-6,16,8,leaves:1)
B(-6,15,8,leaves:1)
B(-7,9,10,leaves:1)
B(-6,14,8,leaves:1)
B(-8,6,4,leaves:1)
B(-6,12,8,leaves:1)
B(-4,19,5,leaves:1)
B(-4,15,5,leaves:1)
B(-4,18,5,leaves:1)
B(-3,9,14,leaves:1)
B(-3,42,11,leaves:1)
B(-3,6,14,leaves:1)
B(-3,41,11,leaves:1)
B(-4,16,7,leaves:1)
B(-3,7,12,leaves:1)
B(-4,12,7,leaves:1)
B(-4,11,7,leaves:1)
B(-4,10,7,leaves:1)
B(-4,22,5,leaves:1)
B(-5,15,8,leaves:1)
B(-5,16,8,leaves:1)
B(-5,28,5,leaves:1)
B(-5,27,5,leaves:1)
B(-5,18,8,leaves:1)
B(-5,11,8,leaves:1)
B(-5,12,8,leaves:1)
B(-5,11,15,leaves:1)
B(-5,13,8,leaves:1)
B(-5,14,8,leaves:1)
B(-4,41,9,leaves:1)
B(-4,42,9,leaves:1)
B(-1,22,9,leaves:1)
B(-4,43,9,leaves:1)
B(-5,10,8,leaves:1)
B(-5,18,10,leaves:1)
B(-1,23,9,leaves:1)
B(-5,22,12,leaves:1)
B(-5,21,12,leaves:1)
B(-5,14,10,leaves:1)
B(-1,18,9,leaves:1)
B(-6,13,7,leaves:1)
B(-9,8,12,leaves:1)
B(-6,14,7,leaves:1)
B(-1,10,7,leaves:1)
B(-5,11,10,leaves:1)
B(-6,15,7,leaves:1)
B(-5,10,10,leaves:1)
B(-1,11,7,leaves:1)
B(-5,13,10,leaves:1)
B(-6,18,7,leaves:1)
B(-5,12,10,leaves:1)
B(-1,13,7,leaves:1)
B(-5,27,12,leaves:1)
B(-5,23,12,leaves:1)
B(-6,10,7,leaves:1)
B(-4,39,9,leaves:1)
B(-5,28,8,leaves:1)
B(-5,29,8,leaves:1)
B(-4,37,9,leaves:1)
B(-4,38,9,leaves:1)
B(-5,27,8,leaves:1)
B(-5,18,5,leaves:1)
B(-4,35,9,log)
B(-5,24,8,leaves:1)
B(-5,6,13,leaves:1)
B(1,5,6,leaves:1)
B(-4,36,9,leaves:1)
B(-5,7,13,leaves:1)
B(1,6,6,leaves:1)
B(-4,33,9,log)
B(-5,22,8,leaves:1)
B(-5,8,13,leaves:1)
B(-4,34,9,log)
B(-5,23,8,leaves:1)
B(-5,9,13,leaves:1)
B(-1,33,9,leaves:1)
B(-4,31,9,leaves:1)
B(-5,20,8,leaves:1)
B(1,9,6,leaves:1)
B(-4,32,9,log)
B(-4,30,9,log)
B(-1,36,9,leaves:1)
B(-1,35,9,leaves:1)
B(-5,29,10,leaves:1)
B(-1,34,9,leaves:1)
B(-8,18,11,leaves:1)
B(-5,10,12,leaves:1)
B(-5,24,10,leaves:1)
B(-5,23,10,leaves:1)
B(-6,26,7,leaves:1)
B(-5,22,10,leaves:1)
B(-6,27,7,leaves:1)
B(-5,21,10,leaves:1)
B(-5,20,10,leaves:1)
B(-5,17,12,leaves:1)
B(-5,22,5,leaves:1)
B(-5,18,12,leaves:1)
B(-5,13,12,leaves:1)
B(-5,19,8,leaves:1)
B(-5,34,8,leaves:1)
B(-5,35,8,leaves:1)
B(-7,8,7,leaves:1)
B(-7,9,7,leaves:1)
B(-1,26,7,leaves:1)
B(-2,6,5,leaves:1)
B(-1,25,7,leaves:1)
B(-5,32,8,leaves:1)
B(-2,8,7,leaves:1)
B(-2,7,7,leaves:1)
B(-1,31,7,leaves:1)
B(-2,0,7,leaves:1)
B(-1,7,13,leaves:1)
B(-1,8,13,leaves:1)
B(0,9,5,leaves:1)
B(0,6,5,leaves:1)
B(-1,14,7,leaves:1)
B(-9,7,7,leaves:1)
B(-9,8,7,leaves:1)
B(-5,33,12,leaves:1)
B(-9,9,7,leaves:1)
B(-5,32,12,leaves:1)
B(-5,8,2,leaves:1)
B(-1,28,11,leaves:1)
B(-5,-5,10,LOG:12)
B(-5,-7,10,LOG:12)
B(-1,27,11,leaves:1)
B(-1,24,11,leaves:1)
B(-1,25,11,leaves:1)
B(-5,-4,8,LOG:12)
B(-2,15,6,leaves:1)
B(-5,-3,8,LOG:12)
B(-10,9,8,leaves:1)
B(-2,14,6,leaves:1)
B(-10,6,8,leaves:1)
B(-1,21,11,leaves:1)
B(-2,19,6,leaves:1)
B(-2,18,6,leaves:1)
B(-8,13,6,leaves:1)
B(-8,14,6,leaves:1)
B(-8,17,6,leaves:1)
B(-8,16,6,leaves:1)
B(-1,-2,9,leaves:1)
B(-5,-2,10,LOG:12)
B(-5,-3,10,LOG:12)
B(-6,-2,7,LOG:12)
B(-6,-1,7,LOG:12)
B(-6,-3,7,LOG:12)
B(-5,5,16,leaves:1)
B(-2,26,6,leaves:1)
B(-2,25,6,leaves:1)
B(-1,31,11,leaves:1)
B(-8,7,6,leaves:1)
B(-1,32,11,leaves:1)
B(-8,8,6,leaves:1)
B(2,7,13,leaves:1)
B(-2,31,6,leaves:1)
B(-5,-7,8,LOG:12)
B(-5,-8,8,LOG:12)
B(-5,-5,8,LOG:12)
B(-5,-6,8,LOG:12)
B(-4,21,9,log)
B(-4,20,9,log)
B(-4,23,9,leaves:1)
B(-4,22,9,leaves:1)
B(-4,25,9,leaves:1)
B(-4,24,9,leaves:1)
B(-4,27,9,log)
B(-4,26,9,log)
B(-4,29,9,log)
B(-4,28,9,log)
B(-4,19,9,log)
B(-8,2,6,leaves:2)
B(-5,13,5,leaves:1)
B(-6,16,14,leaves:1)
B(-6,11,14,leaves:1)
B(-1,14,9,leaves:1)
B(-4,6,13,leaves:1)
B(-4,7,13,leaves:1)
B(-1,13,9,leaves:1)
B(-1,14,13,leaves:1)
B(-1,19,11,leaves:1)
B(-4,9,13,leaves:1)
B(-4,10,9,leaves:1)
B(-10,6,4,leaves:1)
B(-4,14,9,leaves:1)
B(-4,13,9,leaves:1)
B(-4,12,9,leaves:1)
B(-4,11,9,leaves:1)
B(-1,19,13,leaves:1)
B(-4,18,9,log)
B(-4,17,9,leaves:1)
B(-4,16,9,leaves:1)
B(-1,18,13,leaves:1)
B(-4,15,9,leaves:1)
B(-4,5,16,leaves:1)
B(-4,2,6,leaves:2)
B(-4,1,6,leaves:2)
B(-4,6,16,leaves:1)
B(-1,22,8,leaves:1)
B(-6,32,9,leaves:1)
B(-1,25,8,leaves:1)
B(-4,9,6,leaves:1)
B(-5,21,13,leaves:1)
B(-4,4,6,leaves:2)
B(-5,20,13,leaves:1)
B(-4,3,6,leaves:2)
B(-4,5,6,leaves:2)
B(-3,40,9,leaves:1)
B(-3,41,9,leaves:1)
B(-3,42,9,log)
B(-7,21,13,leaves:1)
B(-1,17,8,leaves:1)
B(-1,18,8,leaves:1)
B(-3,47,9,leaves:1)
B(1,13,8,leaves:1)
B(-4,6,14,leaves:1)
B(1,12,8,leaves:1)
B(-3,43,9,leaves:1)
B(1,17,8,leaves:1)
B(-3,44,9,log)
B(1,16,8,leaves:1)
B(-3,45,9,log)
B(-4,9,14,leaves:1)
B(-3,46,9,leaves:1)
B(-4,8,14,leaves:1)
B(-1,14,8,leaves:1)
B(-8,9,10,leaves:1)
B(-8,8,10,leaves:1)
B(-6,16,9,leaves:1)
B(-6,14,9,leaves:1)
B(-2,9,11,leaves:1)
B(-2,8,11,leaves:1)
B(-6,17,9,leaves:1)
B(-3,21,7,leaves:1)
B(-3,20,7,leaves:1)
B(-6,12,9,leaves:1)
B(-6,11,9,leaves:1)
B(-6,10,9,leaves:1)
B(-3,19,7,leaves:1)
B(-3,17,7,leaves:1)
B(-3,16,7,leaves:1)
B(3,11,7,leaves:1)
B(-5,6,15,leaves:1)
B(-2,13,7,leaves:1)
B(-2,14,7,leaves:1)
B(-2,11,7,leaves:1)
B(-5,5,15,leaves:1)
B(-2,12,7,leaves:1)
B(-2,15,7,leaves:1)
B(-6,27,9,leaves:1)
B(-2,18,7,leaves:1)
B(-6,26,9,leaves:1)
B(-2,17,7,leaves:1)
B(-6,6,13,leaves:1)
B(-2,19,7,leaves:1)
B(-1,31,8,leaves:1)
B(-3,31,7,leaves:1)
B(-1,30,8,leaves:1)
B(-3,33,7,leaves:1)
B(-1,36,8,leaves:1)
B(-3,34,7,leaves:1)
B(-6,21,9,leaves:1)
B(-1,35,8,leaves:1)
B(-6,20,9,leaves:1)
B(-6,7,2,leaves:1)
B(3,5,5,leaves:1)
B(-3,37,7,leaves:1)
B(-6,8,2,leaves:1)
B(-3,28,7,leaves:1)
B(-2,5,15,leaves:1)
B(-3,27,7,leaves:1)
B(-1,26,8,leaves:1)
B(-3,29,7,leaves:1)
B(-5,21,4,leaves:1)
B(-2,8,15,leaves:1)
B(-5,22,4,leaves:1)
B(0,26,10,leaves:1)
B(0,27,10,leaves:1)
B(-9,7,8,leaves:1)
B(0,21,10,leaves:1)
B(0,22,10,leaves:1)
B(-2,26,7,leaves:1)
B(-2,27,7,leaves:1)
B(-4,38,11,leaves:1)
B(-4,35,11,leaves:1)
B(-2,32,7,leaves:1)
B(-4,34,11,leaves:1)
B(-2,31,7,leaves:1)
B(-4,36,11,leaves:1)
B(0,16,10,leaves:1)
B(-4,29,11,leaves:1)
B(-4,25,11,leaves:1)
B(-4,24,11,leaves:1)
B(-4,23,11,leaves:1)
B(-2,7,4,leaves:1)
B(-4,22,11,leaves:1)
B(-2,5,4,leaves:1)
B(-6,-1,9,LOG:12)
B(-6,-2,9,LOG:12)
B(-6,-5,9,LOG:12)
B(-6,-6,9,LOG:12)
B(-6,-3,9,LOG:12)
B(-9,12,5,leaves:1)
B(-9,13,5,leaves:1)
B(1,7,11,leaves:1)
B(-6,31,7,leaves:1)
B(-4,45,11,leaves:1)
B(-7,11,13,leaves:1)
B(-10,7,6,leaves:1)
B(-10,8,6,leaves:1)
B(-9,6,5,leaves:1)
B(-4,44,11,leaves:1)
B(-6,0,8,LOG:12)
B(-3,27,6,leaves:1)
B(-6,2,8,leaves:2)
B(-4,9,4,leaves:1)
B(-6,1,8,LOG:12)
B(-4,8,4,leaves:1)
B(-6,3,8,leaves:2)
B(-2,18,5,leaves:1)
B(-2,19,5,leaves:1)
B(-2,14,5,leaves:1)
B(-2,16,5,leaves:1)
B(-2,15,5,leaves:1)
B(-5,33,11,leaves:1)
B(-2,32,11,leaves:1)
B(-5,34,11,leaves:1)
B(-2,33,11,leaves:1)
B(-3,20,11,leaves:1)
B(-5,37,11,leaves:1)
B(-5,38,11,leaves:1)
B(-2,30,11,leaves:1)
B(-3,28,11,leaves:1)
B(-3,25,11,leaves:1)
B(-2,37,11,leaves:1)
B(-3,33,6,leaves:1)
B(-5,30,11,leaves:1)
B(-6,-8,8,LOG:12)
B(-2,38,11,leaves:1)
B(-3,27,11,leaves:1)
B(-6,-7,8,LOG:12)
B(-3,26,11,leaves:1)
B(-6,-6,8,LOG:12)
B(2,11,9,leaves:1)
B(-3,14,3,leaves:1)
B(-2,7,8,leaves:1)
B(-3,13,3,leaves:1)
B(-2,8,8,leaves:1)
B(-2,5,8,leaves:1)
B(-3,18,3,leaves:1)
B(-2,3,8,leaves:1)
B(-2,4,8,leaves:1)
B(-2,1,8,leaves:1)
B(-3,-1,9,leaves:1)
B(-2,2,8,leaves:1)
B(-3,-2,9,leaves:1)
B(-3,-3,9,LOG:12)
B(-2,0,8,leaves:1)
B(-5,24,11,leaves:1)
B(-4,6,8,LOG:12)
B(0,12,7,leaves:1)
B(-3,33,11,leaves:1)
B(-4,5,8,LOG:12)
B(0,13,7,leaves:1)
B(-3,32,11,leaves:1)
B(-5,22,11,leaves:1)
B(-7,16,7,leaves:1)
B(-4,8,8,LOG:12)
B(0,10,7,leaves:1)
B(-3,31,11,leaves:1)
B(-5,23,11,leaves:1)
B(-7,17,7,leaves:1)
B(-4,7,8,LOG:12)
B(-2,10,5,leaves:1)
B(-5,28,11,leaves:1)
B(0,16,7,leaves:1)
B(-4,2,8,LOG:12)
B(-7,14,7,leaves:1)
B(-5,29,11,leaves:1)
B(-2,20,11,leaves:1)
B(0,17,7,leaves:1)
B(-4,1,8,LOG:12)
B(-4,4,8,LOG:12)
B(-4,3,8,LOG:12)
B(-7,13,7,leaves:1)
B(-7,10,7,leaves:1)
B(-2,29,11,leaves:1)
B(-4,0,8,LOG:12)
B(-8,8,12,leaves:1)
B(-2,27,11,leaves:1)
B(-3,37,11,leaves:1)
B(-2,28,11,leaves:1)
B(-3,36,11,leaves:1)
B(-3,35,11,leaves:1)
B(-2,26,11,leaves:1)
B(2,16,9,leaves:1)
B(-6,9,11,leaves:1)
B(-4,11,11,leaves:1)
B(-2,7,13,leaves:1)
B(-7,-7,7,LOG:12)
B(-4,14,11,leaves:1)
B(-2,8,13,leaves:1)
B(-4,9,8,leaves:1)
B(-2,9,13,leaves:1)
B(-4,12,11,leaves:1)
B(-4,18,11,leaves:1)
B(-2,5,13,leaves:1)
B(-2,-3,9,LOG:12)
B(-3,8,2,leaves:1)
B(-2,6,13,leaves:1)
B(0,25,7,leaves:1)
B(-6,8,4,leaves:1)
B(-5,17,11,leaves:1)
B(-5,18,11,leaves:1)
B(-3,-4,9,LOG:12)
B(-1,14,3,leaves:1)
B(-5,13,11,leaves:1)
B(0,24,7,leaves:1)
B(-5,14,11,leaves:1)
B(-10,12,4,leaves:1)
B(-10,11,4,leaves:1)
B(-9,10,9,leaves:1)
B(-3,19,6,leaves:1)
B(-6,-1,8,LOG:12)
B(-6,-2,8,LOG:12)
B(-9,14,9,leaves:1)
B(-9,15,9,leaves:1)
B(-6,-3,8,LOG:12)
B(-6,-4,8,LOG:12)
B(-3,16,6,leaves:1)
B(-6,-5,8,LOG:12)
B(-9,18,9,leaves:1)
B(-2,24,5,leaves:1)
B(-2,41,11,leaves:1)
B(-2,42,11,leaves:1)
B(-2,-2,9,leaves:1)
B(-2,-1,9,leaves:1)
B(-3,11,11,leaves:1)
B(2,9,5,leaves:1)
B(-2,44,11,leaves:1)
B(-3,16,11,leaves:1)
B(2,8,5,leaves:1)
B(-1,6,5,leaves:1)
B(2,5,5,leaves:1)
B(2,6,5,leaves:1)
B(-1,5,5,leaves:1)
B(-6,9,8,leaves:1)
B(-3,20,6,leaves:1)
B(-6,7,8,leaves:1)
B(-6,8,8,leaves:1)
B(-7,16,9,leaves:1)
B(-9,18,10,leaves:1)
B(-6,22,12,leaves:1)
B(-9,19,10,leaves:1)
B(-7,15,9,leaves:1)
B(0,7,12,leaves:1)
B(0,8,12,leaves:1)
B(-6,27,12,leaves:1)
B(-1,10,5,leaves:1)
B(-9,14,10,leaves:1)
B(-6,26,12,leaves:1)
B(-7,19,9,leaves:1)
B(-4,8,10,leaves:1)
B(-4,9,10,leaves:1)
B(-6,21,12,leaves:1)
B(-1,-2,8,leaves:1)
B(-7,10,9,leaves:1)
B(-1,-1,8,leaves:1)
B(-7,11,9,leaves:1)
B(0,6,8,leaves:1)
B(-4,8,12,leaves:1)
B(-4,7,12,leaves:1)
B(0,5,8,leaves:1)
B(0,8,10,leaves:1)
B(0,7,10,leaves:1)
B(0,18,12,leaves:1)
B(0,13,12,leaves:1)
B(-3,15,9,leaves:1)
B(-6,12,12,leaves:1)
B(-3,14,9,leaves:1)
B(-3,17,9,log)
B(-3,16,9,leaves:1)
B(-6,13,12,leaves:1)
B(-6,16,12,leaves:1)
B(-3,11,9,leaves:1)
B(-3,10,9,leaves:1)
B(-3,13,9,leaves:1)
B(-6,17,12,leaves:1)
B(-3,12,9,leaves:1)
B(-4,15,6,leaves:1)
B(0,26,12,leaves:1)
B(-4,10,6,leaves:1)
B(-3,24,9,leaves:1)
B(-3,23,9,leaves:1)
B(-3,22,9,leaves:1)
B(-3,21,9,leaves:1)
B(-4,19,6,leaves:1)
B(-3,28,9,log)
B(-3,27,9,log)
B(-3,26,9,leaves:1)
B(-3,25,9,leaves:1)
B(1,21,9,leaves:1)
B(1,20,9,leaves:1)
B(-3,20,9,leaves:1)
B(-7,31,9,leaves:1)
B(-2,15,11,leaves:1)
B(-2,16,11,leaves:1)
B(-2,19,3,leaves:1)
B(-4,20,6,leaves:1)
B(-2,18,3,leaves:1)
B(-7,26,7,leaves:1)
B(-3,18,9,log)
B(-7,25,7,leaves:1)
B(-3,19,9,log)
B(-2,15,3,leaves:1)
B(-2,14,3,leaves:1)
B(-4,23,6,leaves:1)
B(-3,33,9,log)
B(-4,29,6,leaves:1)
B(-3,32,9,log)
B(-3,35,9,log)
B(-4,27,6,leaves:1)
B(-3,34,9,log)
B(-4,28,6,leaves:1)
B(-3,37,9,log)
B(-7,25,9,leaves:1)
B(-3,36,9,log)
B(-7,26,9,leaves:1)
B(-3,39,9,log)
B(-3,38,9,log)
B(1,12,9,leaves:1)
B(1,11,9,leaves:1)
B(-4,11,15,leaves:1)
B(-4,10,15,leaves:1)
B(-3,31,9,log)
B(-3,30,9,log)
B(-7,20,9,leaves:1)
B(1,17,9,leaves:1)
B(-5,12,13,leaves:1)
B(1,16,9,leaves:1)
B(-4,33,6,leaves:1)
B(-3,29,9,log)
B(-5,17,13,leaves:1)
B(-2,-1,7,leaves:1)
B(-2,-2,7,leaves:1)
B(-5,13,13,leaves:1)
B(-5,16,13,leaves:1)

#
# +-----------------------------------------------------------------+ #
# |                            BO3 checks                           | #
# +-----------------------------------------------------------------+ #
#

BlockCheck(0,-1,0,Solid)
BlockCheck(0,-1,0,grass,dirt)
BlockCheck(0,-1,2,grass,dirt)
BlockCheck(1,-1,0,grass,dirt)
BlockCheck(-1,-1,0,grass,dirt)
BlockCheck(0,-1,-1,grass,dirt)
BlockCheck(0,-1,0,Solid)
BlockCheckNot(0,-1,0,air)

#
# +-----------------------------------------------------------------+ #
# |                             Branches                            | #
# +-----------------------------------------------------------------+ #
#

