Author: Bo3 BulkEdit

Description: Converted Schematic - Modified by Bo3BulkEdit

Version: 3

SettingsMode: WriteDisable

IsOTGPlus: false
Tree: true
Frequency: 1
Rarity: 100
RotateRandomly: true
SpawnHeight: highestSolidBlock
MaxBranchDepth: 10
ExcludedBiomes: All

MinHeight: 70
MaxHeight: 90

SourceBlocks: AIR,GRASS,DIRT,SAND
MaxPercentageOutsideSourceBlock: 0

Blockcheck(0,-1,-2,DIRT:2,STAINED_CLAY:14,Mycelium)
Blockcheck(-1,-1,-1,DIRT:2,STAINED_CLAY:14,Mycelium)
Blockcheck(0,-1,-1,DIRT:2,STAINED_CLAY:14,Mycelium)
Blockcheck(1,-1,-1,DIRT:2,STAINED_CLAY:14,Mycelium)
Blockcheck(-2,-1,0,DIRT:2,STAINED_CLAY:14,Mycelium)
Blockcheck(-1,-1,0,DIRT:2,STAINED_CLAY:14,Mycelium)
Blockcheck(0,-1,0,DIRT:2,STAINED_CLAY:14,Mycelium)
Blockcheck(1,-1,0,DIRT:2,STAINED_CLAY:14,Mycelium)
Blockcheck(2,-1,0,DIRT:2,STAINED_CLAY:14,Mycelium)
Blockcheck(-1,-1,1,DIRT:2,STAINED_CLAY:14,Mycelium)
Blockcheck(0,-1,1,DIRT:2,STAINED_CLAY:14,Mycelium)
Blockcheck(1,-1,1,DIRT:2,STAINED_CLAY:14,Mycelium)
Blockcheck(0,-1,2,DIRT:2,STAINED_CLAY:14,Mycelium)

B(0,0,-2,RED_MUSHROOM_BLOCK:10)
B(-1,0,-1,RED_MUSHROOM_BLOCK:10)
B(0,0,-1,RED_MUSHROOM_BLOCK:10)
B(1,0,-1,RED_MUSHROOM_BLOCK:10)
B(-2,0,0,RED_MUSHROOM_BLOCK:10)
B(-1,0,0,RED_MUSHROOM_BLOCK:10)
B(0,0,0,RED_MUSHROOM_BLOCK:10)
B(1,0,0,RED_MUSHROOM_BLOCK:10)
B(2,0,0,RED_MUSHROOM_BLOCK:10)
B(-1,0,1,RED_MUSHROOM_BLOCK:10)
B(0,0,1,RED_MUSHROOM_BLOCK:10)
B(1,0,1,RED_MUSHROOM_BLOCK:10)
B(0,0,2,RED_MUSHROOM_BLOCK:10)
B(0,1,-2,RED_MUSHROOM_BLOCK:10)
B(-1,1,-1,RED_MUSHROOM_BLOCK:10)
B(0,1,-1,DIRT:0)
B(1,1,-1,RED_MUSHROOM_BLOCK:10)
B(-2,1,0,RED_MUSHROOM_BLOCK:10)
B(-1,1,0,RED_MUSHROOM_BLOCK:10)
B(0,1,0,RED_MUSHROOM_BLOCK:10)
B(1,1,0,DIRT:0)
B(2,1,0,RED_MUSHROOM_BLOCK:10)
B(-1,1,1,RED_MUSHROOM_BLOCK:10)
B(0,1,1,RED_MUSHROOM_BLOCK:10)
B(1,1,1,RED_MUSHROOM_BLOCK:10)
B(0,1,2,RED_MUSHROOM_BLOCK:10)
B(0,2,-1,RED_MUSHROOM_BLOCK:10)
B(-1,2,0,RED_MUSHROOM_BLOCK:10)
B(0,2,0,RED_MUSHROOM_BLOCK:10)
B(1,2,0,RED_MUSHROOM_BLOCK:10)
B(-1,2,1,RED_MUSHROOM_BLOCK:10)
B(0,2,1,RED_MUSHROOM_BLOCK:10)
B(-1,3,0,RED_MUSHROOM_BLOCK:10)
B(0,3,0,RED_MUSHROOM_BLOCK:10)
B(-2,3,1,RED_MUSHROOM_BLOCK:10)
B(-1,3,1,RED_MUSHROOM_BLOCK:10)
B(0,3,1,RED_MUSHROOM_BLOCK:10)
B(-2,4,1,RED_MUSHROOM_BLOCK:10)
B(-1,4,1,RED_MUSHROOM_BLOCK:10)
B(-1,4,2,RED_MUSHROOM_BLOCK:10)
B(-3,5,-2,RED_MUSHROOM_BLOCK:1)
B(-2,5,-2,RED_MUSHROOM_BLOCK:1)
B(-1,5,-2,RED_MUSHROOM_BLOCK:3)
B(0,5,-2,RED_MUSHROOM_BLOCK:3)
B(-4,5,-1,RED_MUSHROOM_BLOCK:1)
B(-3,5,-1,RED_MUSHROOM_BLOCK:1)
B(-2,5,-1,RED_MUSHROOM_BLOCK:1)
B(-1,5,-1,RED_MUSHROOM_BLOCK:3)
B(0,5,-1,RED_MUSHROOM_BLOCK:3)
B(1,5,-1,RED_MUSHROOM_BLOCK:3)
B(-5,5,0,RED_MUSHROOM_BLOCK:1)
B(-4,5,0,RED_MUSHROOM_BLOCK:1)
B(1,5,0,RED_MUSHROOM_BLOCK:3)
B(2,5,0,RED_MUSHROOM_BLOCK:3)
B(-5,5,1,RED_MUSHROOM_BLOCK:1)
B(-4,5,1,RED_MUSHROOM_BLOCK:1)
B(-2,5,1,RED_MUSHROOM_BLOCK:10)
B(-1,5,1,RED_MUSHROOM_BLOCK:10)
B(1,5,1,RED_MUSHROOM_BLOCK:3)
B(2,5,1,RED_MUSHROOM_BLOCK:3)
B(-5,5,2,RED_MUSHROOM_BLOCK:7)
B(-4,5,2,RED_MUSHROOM_BLOCK:7)
B(-2,5,2,RED_MUSHROOM_BLOCK:10)
B(-1,5,2,RED_MUSHROOM_BLOCK:10)
B(1,5,2,RED_MUSHROOM_BLOCK:9)
B(2,5,2,RED_MUSHROOM_BLOCK:9)
B(-5,5,3,RED_MUSHROOM_BLOCK:7)
B(-4,5,3,RED_MUSHROOM_BLOCK:7)
B(1,5,3,RED_MUSHROOM_BLOCK:9)
B(2,5,3,RED_MUSHROOM_BLOCK:9)
B(-4,5,4,RED_MUSHROOM_BLOCK:7)
B(-3,5,4,RED_MUSHROOM_BLOCK:7)
B(-2,5,4,RED_MUSHROOM_BLOCK:7)
B(-1,5,4,RED_MUSHROOM_BLOCK:9)
B(0,5,4,RED_MUSHROOM_BLOCK:9)
B(1,5,4,RED_MUSHROOM_BLOCK:9)
B(-3,5,5,RED_MUSHROOM_BLOCK:7)
B(-2,5,5,RED_MUSHROOM_BLOCK:7)
B(-1,5,5,RED_MUSHROOM_BLOCK:9)
B(0,5,5,RED_MUSHROOM_BLOCK:9)
B(-3,6,-1,RED_MUSHROOM_BLOCK:1)
B(-2,6,-1,RED_MUSHROOM_BLOCK:1)
B(-1,6,-1,RED_MUSHROOM_BLOCK:3)
B(0,6,-1,RED_MUSHROOM_BLOCK:3)
B(-4,6,0,RED_MUSHROOM_BLOCK:1)
B(-3,6,0,RED_MUSHROOM_BLOCK:1)
B(0,6,0,RED_MUSHROOM_BLOCK:3)
B(1,6,0,RED_MUSHROOM_BLOCK:3)
B(-4,6,1,RED_MUSHROOM_BLOCK:1)
B(-2,6,1,RED_MUSHROOM_BLOCK:10)
B(-1,6,1,RED_MUSHROOM_BLOCK:10)
B(0,6,1,RED_MUSHROOM_BLOCK:10)
B(1,6,1,RED_MUSHROOM_BLOCK:3)
B(-4,6,2,RED_MUSHROOM_BLOCK:7)
B(-2,6,2,RED_MUSHROOM_BLOCK:10)
B(-1,6,2,RED_MUSHROOM_BLOCK:10)
B(1,6,2,RED_MUSHROOM_BLOCK:9)
B(-4,6,3,RED_MUSHROOM_BLOCK:7)
B(-3,6,3,RED_MUSHROOM_BLOCK:7)
B(0,6,3,RED_MUSHROOM_BLOCK:9)
B(1,6,3,RED_MUSHROOM_BLOCK:9)
B(-3,6,4,RED_MUSHROOM_BLOCK:7)
B(-2,6,4,RED_MUSHROOM_BLOCK:7)
B(-1,6,4,RED_MUSHROOM_BLOCK:9)
B(0,6,4,RED_MUSHROOM_BLOCK:9)
B(-2,7,0,RED_MUSHROOM_BLOCK:1)
B(-1,7,0,RED_MUSHROOM_BLOCK:3)
B(-3,7,1,RED_MUSHROOM_BLOCK:1)
B(-2,7,1,RED_MUSHROOM_BLOCK:9)
B(-1,7,1,RED_MUSHROOM_BLOCK:9)
B(0,7,1,RED_MUSHROOM_BLOCK:3)
B(-3,7,2,RED_MUSHROOM_BLOCK:7)
B(-2,7,2,RED_MUSHROOM_BLOCK:9)
B(-1,7,2,RED_MUSHROOM_BLOCK:9)
B(0,7,2,RED_MUSHROOM_BLOCK:9)
B(-2,7,3,RED_MUSHROOM_BLOCK:7)
B(-1,7,3,RED_MUSHROOM_BLOCK:9)

