Author: Bo3 BulkEdit

Description: Converted Schematic - Modified by Bo3BulkEdit

Version: 3

SettingsMode: WriteDisable

IsOTGPlus: false
Tree: true
Frequency: 1
Rarity: 100
RotateRandomly: true
SpawnHeight: highestSolidBlock
MaxBranchDepth: 10
ExcludedBiomes: All

MinHeight: 70
MaxHeight: 90

SourceBlocks: AIR,GRASS,DIRT,SAND
MaxPercentageOutsideSourceBlock: 0

Blockcheck(0,-1,-1,DIRT:2,STAINED_CLAY:14)
Blockcheck(1,-1,-1,DIRT:2,STAINED_CLAY:14)
Blockcheck(-1,-1,0,DIRT:2,STAINED_CLAY:14)
Blockcheck(1,-1,0,DIRT:2,STAINED_CLAY:14)
Blockcheck(0,-1,1,DIRT:2,STAINED_CLAY:14)
Blockcheck(0,-1,0,DIRT:2,STAINED_CLAY:14)

B(0,0,-1,RED_MUSHROOM_BLOCK:10)
B(1,0,-1,RED_MUSHROOM_BLOCK:10)
B(-1,0,0,RED_MUSHROOM_BLOCK:10)
B(1,0,0,RED_MUSHROOM_BLOCK:10)
B(0,0,1,RED_MUSHROOM_BLOCK:10)
B(0,0,0,RED_MUSHROOM_BLOCK:10)
B(0,1,-1,RED_MUSHROOM_BLOCK:10)
B(1,1,-1,RED_MUSHROOM_BLOCK:10)
B(-1,1,0,RED_MUSHROOM_BLOCK:10)
B(0,1,0,RED_MUSHROOM_BLOCK:10)
B(1,1,0,RED_MUSHROOM_BLOCK:10)
B(0,1,1,RED_MUSHROOM_BLOCK:10)
B(0,2,-1,RED_MUSHROOM_BLOCK:10)
B(-1,2,0,RED_MUSHROOM_BLOCK:10)
B(0,2,0,RED_MUSHROOM_BLOCK:10)
B(1,2,0,RED_MUSHROOM_BLOCK:10)
B(0,3,-1,RED_MUSHROOM_BLOCK:10)
B(0,3,0,RED_MUSHROOM_BLOCK:10)
B(-1,4,-1,RED_MUSHROOM_BLOCK:10)
B(0,4,-1,RED_MUSHROOM_BLOCK:10)
B(0,4,0,RED_MUSHROOM_BLOCK:10)
B(-1,5,-1,RED_MUSHROOM_BLOCK:10)
B(-2,5,0,RED_MUSHROOM_BLOCK:10)
B(-1,5,0,RED_MUSHROOM_BLOCK:10)
B(0,5,0,RED_MUSHROOM_BLOCK:10)
B(-1,6,-1,RED_MUSHROOM_BLOCK:10)
B(-2,6,0,RED_MUSHROOM_BLOCK:10)
B(-1,6,0,RED_MUSHROOM_BLOCK:10)
B(-2,6,1,RED_MUSHROOM_BLOCK:10)
B(-1,6,1,RED_MUSHROOM_BLOCK:10)
B(-2,7,0,RED_MUSHROOM_BLOCK:10)
B(-1,7,0,RED_MUSHROOM_BLOCK:10)
B(-3,7,1,RED_MUSHROOM_BLOCK:10)
B(-2,7,1,RED_MUSHROOM_BLOCK:10)
B(-1,7,1,RED_MUSHROOM_BLOCK:10)
B(-2,7,2,RED_MUSHROOM_BLOCK:10)
B(-4,8,-5,RED_MUSHROOM_BLOCK:1)
B(-3,8,-5,RED_MUSHROOM_BLOCK:1)
B(-2,8,-5,RED_MUSHROOM_BLOCK:1)
B(-1,8,-5,RED_MUSHROOM_BLOCK:3)
B(0,8,-5,RED_MUSHROOM_BLOCK:3)
B(-6,8,-4,RED_MUSHROOM_BLOCK:1)
B(-5,8,-4,RED_MUSHROOM_BLOCK:1)
B(1,8,-4,RED_MUSHROOM_BLOCK:3)
B(2,8,-4,RED_MUSHROOM_BLOCK:3)
B(-7,8,-3,RED_MUSHROOM_BLOCK:1)
B(3,8,-3,RED_MUSHROOM_BLOCK:3)
B(-7,8,-2,RED_MUSHROOM_BLOCK:1)
B(3,8,-2,RED_MUSHROOM_BLOCK:3)
B(-8,8,-1,RED_MUSHROOM_BLOCK:1)
B(4,8,-1,RED_MUSHROOM_BLOCK:3)
B(-8,8,0,RED_MUSHROOM_BLOCK:1)
B(-2,8,0,RED_MUSHROOM_BLOCK:10)
B(4,8,0,RED_MUSHROOM_BLOCK:3)
B(-8,8,1,RED_MUSHROOM_BLOCK:7)
B(-3,8,1,RED_MUSHROOM_BLOCK:10)
B(-2,8,1,RED_MUSHROOM_BLOCK:10)
B(-1,8,1,RED_MUSHROOM_BLOCK:10)
B(4,8,1,RED_MUSHROOM_BLOCK:3)
B(-8,8,2,RED_MUSHROOM_BLOCK:7)
B(-2,8,2,RED_MUSHROOM_BLOCK:10)
B(4,8,2,RED_MUSHROOM_BLOCK:9)
B(-8,8,3,RED_MUSHROOM_BLOCK:7)
B(4,8,3,RED_MUSHROOM_BLOCK:9)
B(-7,8,4,RED_MUSHROOM_BLOCK:7)
B(3,8,4,RED_MUSHROOM_BLOCK:9)
B(-7,8,5,RED_MUSHROOM_BLOCK:7)
B(2,8,5,RED_MUSHROOM_BLOCK:9)
B(3,8,5,RED_MUSHROOM_BLOCK:9)
B(-6,8,6,RED_MUSHROOM_BLOCK:7)
B(-5,8,6,RED_MUSHROOM_BLOCK:7)
B(1,8,6,RED_MUSHROOM_BLOCK:9)
B(2,8,6,RED_MUSHROOM_BLOCK:9)
B(-4,8,7,RED_MUSHROOM_BLOCK:7)
B(-3,8,7,RED_MUSHROOM_BLOCK:7)
B(-2,8,7,RED_MUSHROOM_BLOCK:9)
B(-1,8,7,RED_MUSHROOM_BLOCK:9)
B(0,8,7,RED_MUSHROOM_BLOCK:9)
B(-3,9,-5,RED_MUSHROOM_BLOCK:1)
B(-2,9,-5,RED_MUSHROOM_BLOCK:1)
B(-1,9,-5,RED_MUSHROOM_BLOCK:3)
B(-5,9,-4,RED_MUSHROOM_BLOCK:1)
B(-4,9,-4,RED_MUSHROOM_BLOCK:1)
B(0,9,-4,RED_MUSHROOM_BLOCK:3)
B(1,9,-4,RED_MUSHROOM_BLOCK:3)
B(-6,9,-3,RED_MUSHROOM_BLOCK:1)
B(2,9,-3,RED_MUSHROOM_BLOCK:3)
B(-7,9,-2,RED_MUSHROOM_BLOCK:1)
B(2,9,-2,RED_MUSHROOM_BLOCK:3)
B(3,9,-2,RED_MUSHROOM_BLOCK:3)
B(-7,9,-1,RED_MUSHROOM_BLOCK:1)
B(3,9,-1,RED_MUSHROOM_BLOCK:3)
B(-8,9,0,RED_MUSHROOM_BLOCK:1)
B(-2,9,0,RED_MUSHROOM_BLOCK:10)
B(4,9,0,RED_MUSHROOM_BLOCK:3)
B(-8,9,1,RED_MUSHROOM_BLOCK:7)
B(-3,9,1,RED_MUSHROOM_BLOCK:10)
B(-2,9,1,LOG:0)
B(-1,9,1,RED_MUSHROOM_BLOCK:10)
B(4,9,1,RED_MUSHROOM_BLOCK:3)
B(-8,9,2,RED_MUSHROOM_BLOCK:7)
B(-2,9,2,RED_MUSHROOM_BLOCK:10)
B(4,9,2,RED_MUSHROOM_BLOCK:9)
B(-7,9,3,RED_MUSHROOM_BLOCK:7)
B(3,9,3,RED_MUSHROOM_BLOCK:9)
B(-7,9,4,RED_MUSHROOM_BLOCK:7)
B(3,9,4,RED_MUSHROOM_BLOCK:9)
B(-6,9,5,RED_MUSHROOM_BLOCK:7)
B(2,9,5,RED_MUSHROOM_BLOCK:9)
B(-5,9,6,RED_MUSHROOM_BLOCK:7)
B(-4,9,6,RED_MUSHROOM_BLOCK:7)
B(0,9,6,RED_MUSHROOM_BLOCK:9)
B(1,9,6,RED_MUSHROOM_BLOCK:9)
B(-3,9,7,RED_MUSHROOM_BLOCK:7)
B(-2,9,7,RED_MUSHROOM_BLOCK:9)
B(-1,9,7,RED_MUSHROOM_BLOCK:9)
B(-3,10,-4,RED_MUSHROOM_BLOCK:1)
B(-2,10,-4,RED_MUSHROOM_BLOCK:1)
B(-1,10,-4,RED_MUSHROOM_BLOCK:3)
B(-5,10,-3,RED_MUSHROOM_BLOCK:1)
B(-4,10,-3,RED_MUSHROOM_BLOCK:1)
B(-3,10,-3,RED_MUSHROOM_BLOCK:1)
B(-2,10,-3,RED_MUSHROOM_BLOCK:1)
B(-1,10,-3,RED_MUSHROOM_BLOCK:3)
B(0,10,-3,RED_MUSHROOM_BLOCK:3)
B(1,10,-3,RED_MUSHROOM_BLOCK:3)
B(-6,10,-2,RED_MUSHROOM_BLOCK:1)
B(-5,10,-2,RED_MUSHROOM_BLOCK:7)
B(-4,10,-2,RED_MUSHROOM_BLOCK:7)
B(-3,10,-2,RED_MUSHROOM_BLOCK:2)
B(-2,10,-2,RED_MUSHROOM_BLOCK:2)
B(-1,10,-2,RED_MUSHROOM_BLOCK:2)
B(0,10,-2,RED_MUSHROOM_BLOCK:7)
B(1,10,-2,RED_MUSHROOM_BLOCK:7)
B(2,10,-2,RED_MUSHROOM_BLOCK:3)
B(-6,10,-1,RED_MUSHROOM_BLOCK:1)
B(-5,10,-1,RED_MUSHROOM_BLOCK:7)
B(-4,10,-1,RED_MUSHROOM_BLOCK:2)
B(0,10,-1,RED_MUSHROOM_BLOCK:2)
B(1,10,-1,RED_MUSHROOM_BLOCK:7)
B(2,10,-1,RED_MUSHROOM_BLOCK:3)
B(-7,10,0,RED_MUSHROOM_BLOCK:1)
B(-6,10,0,RED_MUSHROOM_BLOCK:1)
B(-5,10,0,RED_MUSHROOM_BLOCK:7)
B(-2,10,0,RED_MUSHROOM_BLOCK:10)
B(1,10,0,RED_MUSHROOM_BLOCK:2)
B(2,10,0,RED_MUSHROOM_BLOCK:3)
B(3,10,0,RED_MUSHROOM_BLOCK:3)
B(-7,10,1,RED_MUSHROOM_BLOCK:7)
B(-6,10,1,RED_MUSHROOM_BLOCK:7)
B(-5,10,1,RED_MUSHROOM_BLOCK:7)
B(-3,10,1,RED_MUSHROOM_BLOCK:10)
B(-2,10,1,LOG:0)
B(-1,10,1,RED_MUSHROOM_BLOCK:10)
B(1,10,1,RED_MUSHROOM_BLOCK:2)
B(2,10,1,RED_MUSHROOM_BLOCK:3)
B(3,10,1,RED_MUSHROOM_BLOCK:3)
B(-7,10,2,RED_MUSHROOM_BLOCK:7)
B(-6,10,2,RED_MUSHROOM_BLOCK:7)
B(-5,10,2,RED_MUSHROOM_BLOCK:7)
B(-2,10,2,RED_MUSHROOM_BLOCK:10)
B(1,10,2,RED_MUSHROOM_BLOCK:2)
B(2,10,2,RED_MUSHROOM_BLOCK:9)
B(3,10,2,RED_MUSHROOM_BLOCK:9)
B(-6,10,3,RED_MUSHROOM_BLOCK:7)
B(-5,10,3,RED_MUSHROOM_BLOCK:7)
B(-4,10,3,RED_MUSHROOM_BLOCK:7)
B(0,10,3,RED_MUSHROOM_BLOCK:6)
B(1,10,3,RED_MUSHROOM_BLOCK:7)
B(2,10,3,RED_MUSHROOM_BLOCK:9)
B(-6,10,4,RED_MUSHROOM_BLOCK:7)
B(-5,10,4,RED_MUSHROOM_BLOCK:9)
B(-4,10,4,RED_MUSHROOM_BLOCK:9)
B(-3,10,4,RED_MUSHROOM_BLOCK:9)
B(-2,10,4,RED_MUSHROOM_BLOCK:9)
B(-1,10,4,RED_MUSHROOM_BLOCK:9)
B(0,10,4,RED_MUSHROOM_BLOCK:9)
B(1,10,4,RED_MUSHROOM_BLOCK:9)
B(2,10,4,RED_MUSHROOM_BLOCK:9)
B(-5,10,5,RED_MUSHROOM_BLOCK:7)
B(-4,10,5,RED_MUSHROOM_BLOCK:7)
B(-3,10,5,RED_MUSHROOM_BLOCK:7)
B(-2,10,5,RED_MUSHROOM_BLOCK:9)
B(-1,10,5,RED_MUSHROOM_BLOCK:9)
B(0,10,5,RED_MUSHROOM_BLOCK:9)
B(1,10,5,RED_MUSHROOM_BLOCK:9)
B(-3,10,6,RED_MUSHROOM_BLOCK:7)
B(-2,10,6,RED_MUSHROOM_BLOCK:9)
B(-1,10,6,RED_MUSHROOM_BLOCK:9)
B(-3,11,-1,RED_MUSHROOM_BLOCK:1)
B(-2,11,-1,RED_MUSHROOM_BLOCK:3)
B(-1,11,-1,RED_MUSHROOM_BLOCK:3)
B(-4,11,0,RED_MUSHROOM_BLOCK:1)
B(-3,11,0,RED_MUSHROOM_BLOCK:3)
B(-2,11,0,RED_MUSHROOM_BLOCK:3)
B(-1,11,0,RED_MUSHROOM_BLOCK:3)
B(0,11,0,RED_MUSHROOM_BLOCK:3)
B(-4,11,1,RED_MUSHROOM_BLOCK:7)
B(-3,11,1,RED_MUSHROOM_BLOCK:7)
B(-2,11,1,RED_MUSHROOM_BLOCK:7)
B(-1,11,1,RED_MUSHROOM_BLOCK:9)
B(0,11,1,RED_MUSHROOM_BLOCK:9)
B(-4,11,2,RED_MUSHROOM_BLOCK:7)
B(-3,11,2,RED_MUSHROOM_BLOCK:7)
B(-2,11,2,RED_MUSHROOM_BLOCK:7)
B(-1,11,2,RED_MUSHROOM_BLOCK:9)
B(0,11,2,RED_MUSHROOM_BLOCK:9)
B(-3,11,3,RED_MUSHROOM_BLOCK:7)
B(-2,11,3,RED_MUSHROOM_BLOCK:7)
B(-1,11,3,RED_MUSHROOM_BLOCK:9)

