
#######################################################################
# +-----------------------------------------------------------------+ #
# |                            BO3 object                           | #
# +-----------------------------------------------------------------+ #
#######################################################################

Author: NLBlackEagle

Description: Converted version of the BO2 NA14L

Version: 3

SettingsMode: WriteDisable


#######################################################################
# +-----------------------------------------------------------------+ #
# |                          Main settings                          | #
# +-----------------------------------------------------------------+ #
#######################################################################

Tree: true

Frequency: 1

Rarity: 100.0

RotateRandomly: true

SpawnHeight: highestSolidBlock

SpawnHeightOffset: -2

SpawnHeightVariance: 0

##############################
# Height Limits for the BO3. #
##############################

MinHeight: 0

MaxHeight: 199

######################
# Extrusion settings #
######################

ExtrudeMode: None

ExtrudeThroughBlocks: AIR

MaxBranchDepth: 10

ExcludedBiomes: 


#######################################################################
# +-----------------------------------------------------------------+ #
# |                      Source block settings                      | #
# +-----------------------------------------------------------------+ #
#######################################################################

SourceBlocks: AIR,GRASS,DIRT,SAND

MaxPercentageOutsideSourceBlock: 0

OutsideSourceBlock: placeAnyway

IsOTGPlus: false

InheritBO3: 

InheritBO3Rotation: NORTH

OverrideChildSettings: true

OverrideParentHeight: false

CanOverride: false

BranchFrequency: 0

BranchFrequencyGroup: 

MustBeBelowOther: false

MustBeInside: 

CannotBeInside: 

ReplacesBO3: 

CanSpawnOnWater: true

SpawnOnWaterOnly: false

SpawnUnderWater: false

SpawnAtWaterLevel: false

HeightOffset: 0

RemoveAir: true

ReplaceAbove: 

ReplaceBelow: 

ReplaceWithBiomeBlocks: true

ReplaceWithGroundBlock: DIRT

ReplaceWithSurfaceBlock: GRASS

SmoothRadius: 0

SmoothHeightOffset: 0

SmoothStartTop: false

SmoothStartWood: false

SmoothingSurfaceBlock: 

SmoothingGroundBlock: 

BO3Group: 

IsSpawnPoint: false


#######################################################################
# +-----------------------------------------------------------------+ #
# |                              Blocks                             | #
# +-----------------------------------------------------------------+ #
#######################################################################

B(0,28,2,LEAVES:4)
B(0,20,-2,LOG:12)
B(0,22,-2,LEAVES:4)
Block(-1,8,4,Leaves:4)
B(0,25,2,LEAVES:4)
B(0,23,-2,LEAVES:4)
B(0,24,2,LEAVES:4)
B(0,24,-2,LOG:12)
B(0,27,2,LEAVES:4)
B(0,25,-2,LEAVES:4)
B(2,5,2,Leaves:4)
B(0,20,2,LEAVES:4)
B(0,23,2,LEAVES:4)
B(0,22,2,LEAVES:4)
Block(-1,7,4,Leaves:4)
B(2,9,2,Leaves:4)
Block(-1,5,4,Leaves:4)
B(1,8,5,Leaves:4)
Block(-5,16,-5,LEAVES:4)
B(1,9,5,Leaves:4)
Block(-5,12,-5,LEAVES:4)
Block(-3,26,1,LEAVES:4)
Block(-3,25,1,LEAVES:4)
B(0,29,-2,LEAVES:4)
Block(-3,27,1,LEAVES:4)
Block(-3,22,1,LEAVES:4)
Block(-3,23,1,LEAVES:4)
B(0,19,2,LOG:12)
Block(-3,20,1,LEAVES:4)
B(0,18,2,LEAVES:4)
B(0,17,2,LEAVES:4)
B(0,14,-2,LEAVES:4)
B(0,16,2,LEAVES:4)
B(0,15,-2,LOG:12)
B(0,14,2,LEAVES:4)
B(0,13,2,LOG:12)
B(0,13,-2,Leaves:4)
B(0,12,2,Leaves:4)
B(0,11,2,Leaves:4)
Block(-3,7,4,Leaves:4)
B(3,9,1,Leaves:4)
B(3,6,1,Leaves:4)
Block(-3,19,1,LEAVES:4)
B(0,19,-2,LEAVES:4)
Block(-3,16,1,LEAVES:4)
B(0,18,-2,LEAVES:4)
B(0,16,-2,LEAVES:4)
Block(-1,9,0,LOG:12)
Block(-3,10,1,Leaves:4)
B(3,23,-2,LEAVES:4)
B(3,21,-2,LEAVES:4)
B(3,20,-2,LEAVES:4)
B(3,23,4,LEAVES:4)
B(3,24,4,LEAVES:4)
B(3,25,4,LEAVES:4)
B(3,26,4,LEAVES:4)
B(3,27,4,LEAVES:4)
B(3,24,-2,LEAVES:4)
B(3,25,-2,LEAVES:4)
B(0,8,2,Leaves:4)
B(0,9,2,Leaves:4)
B(0,6,2,Leaves:4)
B(0,7,2,LOG:12)
B(3,10,-2,LOG:12)
B(3,12,-2,Leaves:4)
B(3,11,-2,Leaves:4)
B(0,7,6,Leaves:4)
B(0,9,6,Leaves:4)
B(3,11,-5,Leaves:4)
B(3,17,-2,LEAVES:4)
B(3,18,-2,LEAVES:4)
B(3,13,-2,Leaves:4)
B(3,16,-2,LEAVES:4)
B(4,26,1,LEAVES:4)
B(4,22,1,LEAVES:4)
B(4,8,-2,Leaves:4)
B(1,8,-2,Leaves:4)
Block(-2,27,0,LEAVES:4)
Block(-2,22,0,LOG:12)
Block(-2,21,0,LEAVES:4)
Block(-2,20,0,LEAVES:4)
Block(-2,26,0,LEAVES:4)
Block(-2,25,0,LEAVES:4)
Block(-2,24,0,LEAVES:4)
B(5,25,2,LEAVES:4)
B(3,17,0,LEAVES:4)
B(3,15,0,LEAVES:4)
B(5,21,2,LEAVES:4)
B(5,24,2,LEAVES:4)
B(3,18,0,LOG:12)
B(5,23,2,LEAVES:4)
B(3,19,0,LEAVES:4)
Block(-3,27,-1,LEAVES:4)
Block(-3,26,-1,LEAVES:4)
Block(-2,11,0,Leaves:4)
Block(-2,10,0,LOG:12)
Block(-3,23,-1,LEAVES:4)
B(3,12,0,Leaves:4)
Block(-2,12,0,Leaves:4)
B(3,10,0,Leaves:4)
Block(-2,15,0,LEAVES:4)
Block(-3,21,-1,LEAVES:4)
Block(-2,14,0,LEAVES:4)
Block(-3,20,-1,LEAVES:4)
B(0,21,-5,LEAVES:4)
B(3,13,4,Leaves:4)
B(0,23,-5,LEAVES:4)
B(0,24,-5,LEAVES:4)
Block(-3,20,-2,LEAVES:4)
Block(-3,12,-1,Leaves:4)
Block(-3,11,-1,Leaves:4)
Block(-3,14,-1,LEAVES:4)
Block(-3,13,-1,Leaves:4)
Block(-3,16,-1,LEAVES:4)
B(1,10,5,Leaves:4)
B(1,16,5,LEAVES:4)
B(1,13,5,LEAVES:4)
B(1,14,5,LEAVES:4)
Block(-3,15,-2,LEAVES:4)
Block(-3,14,-2,LEAVES:4)
Block(-3,17,-2,LEAVES:4)
Block(-3,16,-2,LEAVES:4)
Block(-3,11,-2,Leaves:4)
B(0,17,-5,LEAVES:4)
Block(-3,14,-5,LEAVES:4)
B(0,18,-5,LEAVES:4)
Block(-3,13,-2,Leaves:4)
B(0,15,-5,LEAVES:4)
Block(-3,12,-2,Leaves:4)
B(0,16,-5,LEAVES:4)
Block(-4,8,1,Leaves:4)
Block(-4,9,1,Leaves:4)
Block(-5,8,3,Leaves:4)
Block(-5,7,3,Leaves:4)
Block(-5,9,3,Leaves:4)
B(1,24,5,LEAVES:4)
Block(-4,8,3,Leaves:4)
Block(-3,24,-2,LEAVES:4)
Block(-3,22,-2,LEAVES:4)
Block(-3,21,-2,LEAVES:4)
B(2,8,0,Leaves:4)
Block(-1,7,2,LOG:12)
Block(-1,8,2,Leaves:4)
Block(-1,9,2,Leaves:4)
B(3,6,3,Leaves:4)
Block(-6,16,4,LEAVES:4)
B(2,25,-1,LEAVES:4)
B(3,7,3,Leaves:4)
Block(-6,18,4,LEAVES:4)
Block(-2,25,-2,LEAVES:4)
Block(-2,23,-2,LEAVES:4)
Block(-3,8,6,Leaves:4)
B(0,9,-3,Leaves:4)
B(2,21,-1,LEAVES:4)
B(2,20,-1,LEAVES:4)
Block(-2,26,-2,LEAVES:4)
B(2,22,-1,LEAVES:4)
B(1,9,3,Leaves:4)
B(1,8,3,LOG:12)
B(1,7,3,Leaves:4)
B(1,6,3,Leaves:4)
B(1,5,3,Leaves:4)
Block(-5,22,0,LEAVES:4)
Block(-5,25,0,LEAVES:4)
B(4,8,2,Leaves:4)
Block(-2,21,-2,LEAVES:4)
Block(-2,11,-2,Leaves:4)
Block(-2,14,-2,LEAVES:4)
Block(-2,13,-2,LOG:12)
Block(-2,16,-2,LEAVES:4)
Block(-2,15,-2,LEAVES:4)
B(4,8,4,Leaves:4)
B(2,18,3,LEAVES:4)
B(2,14,3,LEAVES:4)
B(2,15,3,LEAVES:4)
Block(-4,18,3,LEAVES:4)
Block(-4,17,3,LEAVES:4)
Block(-4,16,3,LEAVES:4)
Block(-5,13,0,Leaves:4)
B(2,11,3,Leaves:4)
Block(-4,15,3,LEAVES:4)
Block(-4,13,3,Leaves:4)
B(3,24,0,LEAVES:4)
Block(-4,22,3,LEAVES:4)
B(5,18,2,LEAVES:4)
Block(-4,23,3,LEAVES:4)
Block(-2,23,-1,LEAVES:4)
B(5,19,2,LEAVES:4)
B(3,22,0,LOG:12)
B(3,21,0,LEAVES:4)
B(3,20,0,LEAVES:4)
Block(-2,27,-1,LEAVES:4)
B(5,11,2,Leaves:4)
B(5,12,2,Leaves:4)
B(0,9,-1,Leaves:4)
Block(-2,29,-1,LEAVES:4)
B(5,13,2,LEAVES:4)
B(3,27,0,LEAVES:4)
B(3,26,0,LEAVES:4)
B(0,7,4,Leaves:4)
B(6,18,0,LEAVES:4)
B(0,8,4,Leaves:4)
B(2,19,-1,LEAVES:4)
B(2,17,-1,LEAVES:4)
B(2,13,-1,Leaves:4)
B(2,14,-1,LEAVES:4)
B(4,12,-3,Leaves:4)
B(2,10,-1,Leaves:4)
Block(-4,12,3,Leaves:4)
Block(-5,10,0,Leaves:4)
B(4,24,-3,LEAVES:4)
Block(-4,13,-6,LEAVES:4)
Block(-2,20,2,LEAVES:4)
Block(-6,17,2,LEAVES:4)
Block(-1,15,-1,LEAVES:4)
Block(-6,16,2,LEAVES:4)
Block(-1,14,-1,LEAVES:4)
Block(-5,21,2,LEAVES:4)
Block(-1,13,-1,LOG:12)
Block(-6,18,2,LEAVES:4)
Block(-5,22,2,LEAVES:4)
Block(-2,19,2,LEAVES:4)
Block(-5,17,2,LEAVES:4)
Block(-2,11,2,Leaves:4)
Block(-2,16,2,LOG:12)
B(4,22,-3,LEAVES:4)
Block(-2,14,2,LEAVES:4)
B(4,23,-3,LEAVES:4)
B(2,20,3,LEAVES:4)
B(2,22,3,LEAVES:4)
Block(-2,20,-1,LEAVES:4)
B(2,24,3,LEAVES:4)
B(2,27,3,LEAVES:4)
Block(-5,12,2,Leaves:4)
Block(-5,11,2,Leaves:4)
B(2,20,1,LEAVES:4)
B(2,24,1,LEAVES:4)
Block(-3,7,0,Leaves:4)
B(2,22,1,LEAVES:4)
Block(-3,9,0,Leaves:4)
Block(-3,8,0,Leaves:4)
B(2,21,1,LEAVES:4)
Block(-2,14,-1,LEAVES:4)
B(2,27,1,LEAVES:4)
B(2,26,1,LEAVES:4)
Block(-2,16,-1,LEAVES:4)
Block(-2,24,2,LEAVES:4)
Block(-2,25,2,LEAVES:4)
Block(-2,26,2,LEAVES:4)
Block(-2,11,-1,Leaves:4)
Block(-2,27,2,LEAVES:4)
B(2,10,-2,Leaves:4)
B(2,9,-5,Leaves:4)
B(2,19,-2,LEAVES:4)
B(2,10,1,Leaves:4)
B(2,18,-2,LEAVES:4)
B(2,13,1,Leaves:4)
B(2,12,1,Leaves:4)
B(2,8,-3,Leaves:4)
B(2,16,-2,LEAVES:4)
Block(-2,13,-5,LEAVES:4)
B(2,19,1,LEAVES:4)
B(2,18,1,LEAVES:4)
B(2,15,1,LEAVES:4)
Block(-2,14,-5,LEAVES:4)
Block(-1,23,-1,LEAVES:4)
B(2,24,-2,LEAVES:4)
Block(-1,22,-1,LEAVES:4)
Block(-1,25,-1,LEAVES:4)
B(2,22,-2,LEAVES:4)
B(2,20,-2,LEAVES:4)
Block(-1,29,-1,LEAVES:4)
Block(-1,30,-1,LEAVES:4)
B(2,27,-2,LEAVES:4)
B(2,26,-2,LEAVES:4)
Block(-2,21,-5,LEAVES:4)
Block(-2,23,-5,LEAVES:4)
B(1,23,-3,LEAVES:4)
Block(-4,21,0,LEAVES:4)
B(1,26,-3,LEAVES:4)
Block(-4,24,0,LEAVES:4)
B(1,25,-3,LOG:12)
Block(-4,26,0,LEAVES:4)
B(1,17,2,LEAVES:4)
Block(-4,25,0,LEAVES:4)
B(1,16,2,LEAVES:4)
B(1,21,-3,LEAVES:4)
B(1,11,2,Leaves:4)
Block(-6,16,3,LEAVES:4)
Block(-6,17,3,LEAVES:4)
Block(-4,23,2,LEAVES:4)
B(3,7,-3,Leaves:4)
B(3,9,-3,Leaves:4)
B(1,27,-3,LEAVES:4)
B(1,28,-3,LEAVES:4)
Block(-4,13,0,Leaves:4)
Block(-4,12,0,Leaves:4)
Block(-4,11,0,Leaves:4)
Block(-4,10,0,Leaves:4)
Block(-4,17,0,LEAVES:4)
Block(-4,15,0,LEAVES:4)
Block(-4,14,0,LEAVES:4)
Block(-4,17,2,LEAVES:4)
Block(-4,18,2,LEAVES:4)
Block(-4,21,2,LEAVES:4)
Block(-4,20,0,LEAVES:4)
B(5,13,3,LEAVES:4)
B(5,14,3,LEAVES:4)
B(5,12,3,Leaves:4)
Block(-4,11,2,Leaves:4)
Block(-3,15,5,LEAVES:4)
B(0,20,5,LEAVES:4)
Block(-3,17,5,LEAVES:4)
B(0,21,5,LEAVES:4)
Block(-3,16,5,LEAVES:4)
B(1,13,-3,Leaves:4)
B(0,28,1,LEAVES:4)
B(0,27,1,LEAVES:4)
B(0,24,1,LEAVES:4)
B(0,23,1,LEAVES:4)
B(0,25,1,LEAVES:4)
B(0,20,1,LEAVES:4)
B(1,16,-3,LEAVES:4)
B(0,21,1,LEAVES:4)
Block(-1,14,-5,LEAVES:4)
Block(-1,19,2,LEAVES:4)
Block(-1,17,2,LEAVES:4)
Block(-1,16,2,LEAVES:4)
Block(-1,14,-2,LEAVES:4)
Block(-1,15,2,LEAVES:4)
Block(-1,13,-2,Leaves:4)
Block(-1,14,2,LEAVES:4)
Block(-1,13,2,Leaves:4)
Block(-1,12,-2,Leaves:4)
Block(-1,12,2,Leaves:4)
Block(-1,11,2,Leaves:4)
Block(-6,14,-3,LEAVES:4)
B(1,1,0,LOG:12)
Block(-6,12,1,LEAVES:4)
B(1,2,0,LOG:12)
Block(-5,14,-2,LEAVES:4)
B(1,0,0,LOG:12)
B(0,10,1,Leaves:4)
B(1,5,0,LOG:12)
Block(-4,9,5,Leaves:4)
B(0,11,1,Leaves:4)
B(1,6,0,LOG:12)
Block(-4,8,5,Leaves:4)
B(1,3,0,LOG:12)
B(1,4,0,LOG:12)
B(0,14,1,LEAVES:4)
B(0,15,1,LEAVES:4)
B(0,12,1,LOG:12)
B(0,13,1,Leaves:4)
B(0,18,1,LEAVES:4)
B(0,19,1,LOG:12)
Block(-5,16,-2,LEAVES:4)
Block(-1,25,-5,LEAVES:4)
Block(-1,23,-5,LEAVES:4)
Block(-1,24,-2,LEAVES:4)
Block(-1,13,-4,Leaves:4)
Block(-1,25,-2,LEAVES:4)
Block(-1,27,-2,LEAVES:4)
Block(-5,23,-2,LEAVES:4)
Block(-6,23,1,LEAVES:4)
Block(-2,7,3,Leaves:4)
Block(-2,6,3,Leaves:4)
Block(-5,22,-2,LEAVES:4)
Block(-2,5,3,Leaves:4)
Block(-5,21,-2,LEAVES:4)
Block(-4,24,-1,LEAVES:4)
Block(-4,25,-1,LEAVES:4)
Block(-2,8,3,LOG:12)
Block(-1,18,-5,LEAVES:4)
Block(-1,17,-5,LEAVES:4)
Block(-4,22,-1,LEAVES:4)
Block(-1,16,-5,LEAVES:4)
Block(-1,15,-5,LEAVES:4)
Block(-4,21,-1,LEAVES:4)
B(2,19,2,LEAVES:4)
Block(-1,22,-4,LEAVES:4)
B(2,14,2,LEAVES:4)
B(2,13,2,Leaves:4)
Block(-1,21,-4,LEAVES:4)
Block(-1,24,-4,LEAVES:4)
B(2,11,2,Leaves:4)
Block(-1,14,-4,LEAVES:4)
B(3,20,1,LEAVES:4)
B(5,14,-1,LEAVES:4)
B(3,21,1,LEAVES:4)
Block(-1,16,-4,LEAVES:4)
B(5,16,-1,LEAVES:4)
B(3,24,1,LEAVES:4)
B(4,9,1,Leaves:4)
B(3,22,1,LEAVES:4)
B(5,13,-1,LEAVES:4)
B(5,12,-1,Leaves:4)
B(3,28,1,LEAVES:4)
Block(-1,26,-5,LEAVES:4)
B(3,26,1,LEAVES:4)
B(5,18,-1,LEAVES:4)
B(2,27,2,LEAVES:4)
B(2,26,2,LEAVES:4)
B(1,20,2,LEAVES:4)
B(1,21,2,LEAVES:4)
Block(-5,14,-3,LEAVES:4)
B(1,22,2,LEAVES:4)
B(1,23,2,LEAVES:4)
Block(-5,16,-3,LEAVES:4)
B(1,25,2,LEAVES:4)
B(1,26,2,LEAVES:4)
Block(-4,17,-4,LEAVES:4)
B(1,27,2,LEAVES:4)
B(2,21,2,LEAVES:4)
B(1,28,2,LEAVES:4)
B(1,29,2,LEAVES:4)
B(2,23,2,LEAVES:4)
Block(-4,14,-4,LEAVES:4)
B(1,8,0,Leaves:4)
B(2,22,2,LEAVES:4)
B(1,7,0,Leaves:4)
B(2,25,2,LOG:12)
B(2,24,2,LEAVES:4)
B(1,9,0,Leaves:4)
Block(-1,27,-4,LEAVES:4)
B(3,8,4,Leaves:4)
B(3,7,4,Leaves:4)
B(3,6,4,Leaves:4)
B(3,10,1,Leaves:4)
B(3,11,1,Leaves:4)
B(3,12,1,LOG:12)
B(3,14,1,LEAVES:4)
B(3,15,1,LEAVES:4)
B(3,17,1,LEAVES:4)
B(3,19,1,LEAVES:4)
B(0,2,0,LOG:12)
B(0,3,0,LOG:12)
B(0,6,0,LOG:12)
B(0,7,0,LOG:12)
B(0,4,0,LOG:12)
B(0,5,0,LOG:12)
B(4,22,3,LEAVES:4)
B(4,24,3,LEAVES:4)
B(4,23,3,LEAVES:4)
B(4,26,3,LEAVES:4)
B(4,25,3,LEAVES:4)
B(5,8,-4,Leaves:4)
B(5,22,-1,LEAVES:4)
B(5,23,-1,LEAVES:4)
B(2,23,-5,LEAVES:4)
B(2,25,-5,LEAVES:4)
B(5,20,-1,LEAVES:4)
Block(-4,10,-1,Leaves:4)
Block(-4,11,-1,Leaves:4)
Block(-3,9,1,Leaves:4)
Block(-4,14,-1,LEAVES:4)
B(0,20,-3,LEAVES:4)
B(0,21,-3,LOG:12)
B(0,22,-3,LEAVES:4)
B(0,23,-3,LEAVES:4)
B(0,24,-3,LEAVES:4)
Block(-3,8,1,Leaves:4)
B(0,25,-3,LEAVES:4)
B(0,26,-3,LEAVES:4)
B(2,10,-5,Leaves:4)
B(0,27,-3,LEAVES:4)
B(0,28,-3,LEAVES:4)
B(4,24,-4,LEAVES:4)
Block(-1,22,2,LEAVES:4)
B(4,9,-1,Leaves:4)
Block(-1,23,2,LEAVES:4)
Block(-1,26,2,LEAVES:4)
B(0,9,0,LOG:12)
B(0,8,0,LOG:12)
Block(-1,25,2,LEAVES:4)
B(2,26,-6,LEAVES:4)
B(2,24,-6,LEAVES:4)
B(4,19,3,LEAVES:4)
B(4,18,3,LEAVES:4)
Block(-2,14,4,LEAVES:4)
Block(-2,17,4,LEAVES:4)
Block(-2,16,4,LEAVES:4)
Block(-3,12,4,Leaves:4)
Block(-4,11,-3,Leaves:4)
Block(-4,13,-3,Leaves:4)
Block(-2,9,1,Leaves:4)
Block(-4,14,-3,LEAVES:4)
Block(-4,17,-3,LEAVES:4)
Block(-2,6,1,Leaves:4)
Block(-4,16,-3,LEAVES:4)
Block(-2,24,1,LEAVES:4)
Block(-2,27,1,LEAVES:4)
Block(-2,20,1,LEAVES:4)
Block(-2,23,1,LEAVES:4)
Block(-2,22,1,LEAVES:4)
B(5,22,1,LEAVES:4)
B(1,10,4,Leaves:4)
B(1,11,4,Leaves:4)
B(3,24,5,LEAVES:4)
B(5,21,1,LEAVES:4)
B(1,14,4,LEAVES:4)
Block(-2,28,1,LEAVES:4)
B(0,12,5,Leaves:4)
B(0,16,-3,LOG:12)
B(0,15,-3,LEAVES:4)
B(0,14,-3,LEAVES:4)
B(0,14,5,LEAVES:4)
B(0,13,-3,Leaves:4)
Block(-1,10,0,Leaves:4)
B(0,15,5,LEAVES:4)
Block(-1,12,0,Leaves:4)
B(0,11,-3,Leaves:4)
B(0,10,5,Leaves:4)
B(0,10,-3,Leaves:4)
Block(-1,14,0,LEAVES:4)
Block(-1,16,0,LEAVES:4)
Block(-3,20,4,LEAVES:4)
B(1,22,-6,LEAVES:4)
B(6,22,-1,LEAVES:4)
B(6,23,-1,LEAVES:4)
B(0,18,5,LEAVES:4)
B(6,21,-1,LEAVES:4)
Block(-3,17,4,LEAVES:4)
B(5,18,1,LEAVES:4)
Block(-3,14,4,LEAVES:4)
Block(-3,15,4,LEAVES:4)
Block(-1,16,4,LEAVES:4)
Block(-1,18,4,LEAVES:4)
B(5,13,1,LEAVES:4)
B(0,19,-3,LEAVES:4)
Block(-1,12,4,Leaves:4)
B(5,16,1,LEAVES:4)
B(0,18,-3,LEAVES:4)
Block(-1,25,0,LEAVES:4)
B(6,18,-1,LEAVES:4)
Block(-1,22,0,LOG:12)
Block(-1,23,0,LEAVES:4)
B(6,10,-1,LEAVES:4)
Block(-1,27,0,LEAVES:4)
Block(-1,14,6,LEAVES:4)
Block(-1,13,6,LEAVES:4)
Block(-4,23,-3,LEAVES:4)
Block(-4,22,-3,LEAVES:4)
Block(-2,10,1,Leaves:4)
Block(-2,15,1,LEAVES:4)
Block(-2,14,1,LEAVES:4)
Block(-2,13,1,Leaves:4)
Block(-2,19,1,LEAVES:4)
Block(-2,18,1,LEAVES:4)
Block(-2,11,4,Leaves:4)
Block(-2,17,1,LEAVES:4)
B(2,7,3,Leaves:4)
Block(-1,8,3,Leaves:4)
Block(-1,7,3,Leaves:4)
B(2,8,3,Leaves:4)
Block(-1,6,3,Leaves:4)
B(2,9,3,Leaves:4)
Block(-1,5,3,Leaves:4)
B(1,18,-4,LEAVES:4)
Block(-2,24,3,LEAVES:4)
Block(-5,24,1,LEAVES:4)
B(0,30,0,LEAVES:4)
Block(-2,22,3,LEAVES:4)
B(2,5,3,Leaves:4)
Block(-2,23,3,LEAVES:4)
Block(-3,22,0,LEAVES:4)
Block(-3,23,0,LOG:12)
B(1,10,-4,Leaves:4)
Block(-3,20,0,LEAVES:4)
Block(-3,10,2,Leaves:4)
B(1,6,4,Leaves:4)
Block(-3,21,0,LEAVES:4)
B(1,7,4,Leaves:4)
B(0,20,6,LEAVES:4)
Block(-3,27,0,LEAVES:4)
Block(-3,24,0,LEAVES:4)
B(1,14,-4,LEAVES:4)
Block(-3,25,0,LEAVES:4)
Block(-5,18,1,LEAVES:4)
Block(-3,15,2,LEAVES:4)
Block(-3,14,2,LEAVES:4)
Block(-5,15,1,LEAVES:4)
Block(-4,21,1,LEAVES:4)
Block(-4,20,4,LEAVES:4)
Block(-3,19,2,LEAVES:4)
Block(-4,11,1,Leaves:4)
Block(-4,14,1,LEAVES:4)
B(3,18,2,LEAVES:4)
Block(-4,17,4,LEAVES:4)
B(3,19,2,LEAVES:4)
B(3,12,2,Leaves:4)
Block(-3,20,2,LEAVES:4)
B(1,21,-4,LEAVES:4)
B(3,13,2,Leaves:4)
B(1,23,-4,LEAVES:4)
B(0,13,6,LEAVES:4)
B(3,8,0,Leaves:4)
B(3,9,0,Leaves:4)
B(3,10,2,Leaves:4)
B(1,26,-4,LEAVES:4)
B(3,11,2,Leaves:4)
Block(-3,23,2,LEAVES:4)
B(0,10,0,LOG:12)
Block(-3,22,2,LEAVES:4)
Block(-1,13,5,LEAVES:4)
Block(-1,14,5,LEAVES:4)
Block(-1,15,5,LEAVES:4)
Block(-1,16,5,LEAVES:4)
Block(-1,17,5,LEAVES:4)
Block(-1,18,5,LEAVES:4)
Block(-3,13,-3,Leaves:4)
B(0,18,0,LOG:12)
Block(-3,14,-3,LOG:12)
B(0,17,0,LOG:12)
Block(-3,11,-3,Leaves:4)
B(0,16,0,LOG:12)
Block(-3,12,-3,Leaves:4)
B(0,15,0,LOG:12)
B(0,14,0,LOG:12)
Block(-3,17,-3,LEAVES:4)
B(0,13,0,LOG:12)
B(0,12,0,LOG:12)
Block(-3,15,-3,LEAVES:4)
B(0,11,0,LOG:12)
Block(-3,16,-3,LEAVES:4)
B(3,25,-4,LEAVES:4)
B(0,9,3,Leaves:4)
B(0,7,3,Leaves:4)
B(3,20,-4,LEAVES:4)
Block(-3,21,-3,LEAVES:4)
B(0,8,3,Leaves:4)
B(0,5,3,Leaves:4)
B(3,22,2,LEAVES:4)
B(3,20,2,LEAVES:4)
B(3,25,2,LEAVES:4)
B(3,26,2,LEAVES:4)
B(3,23,2,LEAVES:4)
B(0,21,0,LOG:12)
B(0,20,0,LOG:12)
B(0,27,0,LOG:12)
B(0,26,0,LOG:12)
B(0,29,0,LEAVES:4)
B(0,23,0,LOG:12)
B(0,22,0,LOG:12)
B(3,15,-4,LEAVES:4)
B(0,25,0,LOG:12)
B(0,24,0,LOG:12)
B(3,17,-4,LEAVES:4)
B(3,12,-4,Leaves:4)
Block(-5,9,4,Leaves:4)
Block(-5,7,4,Leaves:4)
B(0,19,0,LOG:12)
Block(-3,10,-3,Leaves:4)
B(3,10,-4,Leaves:4)
Block(-4,8,2,Leaves:4)
B(2,7,6,Leaves:4)
B(1,3,-1,LOG:12)
B(1,2,-1,LOG:12)
B(1,8,-1,LOG:12)
B(2,8,6,Leaves:4)
B(4,24,0,LEAVES:4)
B(4,25,0,LEAVES:4)
Block(-2,11,-3,Leaves:4)
B(4,22,0,LEAVES:4)
B(4,20,0,LEAVES:4)
B(6,23,1,LEAVES:4)
B(4,21,0,LEAVES:4)
B(6,22,1,LEAVES:4)
B(6,10,-2,LEAVES:4)
Block(-3,23,-3,LEAVES:4)
Block(-3,22,-3,LEAVES:4)
Block(-2,17,-3,LEAVES:4)
Block(-2,16,-3,LEAVES:4)
Block(-2,12,-3,Leaves:4)
Block(-3,8,5,Leaves:4)
Block(-2,15,-3,LEAVES:4)
Block(-2,14,-3,LEAVES:4)
B(4,12,0,Leaves:4)
Block(-2,21,-3,LEAVES:4)
Block(-2,22,-3,LEAVES:4)
Block(-3,7,3,Leaves:4)
Block(-3,8,3,Leaves:4)
B(4,19,0,LEAVES:4)
B(0,2,1,LOG:12)
Block(-3,5,3,Leaves:4)
B(0,1,1,LOG:12)
B(4,15,0,LEAVES:4)
B(0,3,1,LOG:12)
B(0,6,1,LOG:12)
B(4,18,0,LEAVES:4)
Block(-2,25,-3,LEAVES:4)
Block(-2,24,-3,LEAVES:4)
Block(-2,23,-3,LEAVES:4)
B(5,11,-4,Leaves:4)
Block(-4,23,1,LEAVES:4)
Block(-4,26,1,LEAVES:4)
Block(-2,14,-6,LEAVES:4)
B(5,9,0,Leaves:4)
B(5,8,0,Leaves:4)
B(2,3,1,LOG:12)
B(2,2,1,LOG:12)
B(2,1,1,LOG:12)
Block(-3,14,0,LEAVES:4)
Block(-3,13,0,Leaves:4)
B(6,13,1,LEAVES:4)
Block(-3,14,-4,LEAVES:4)
B(6,12,1,LEAVES:4)
Block(-3,15,0,LEAVES:4)
Block(-3,10,0,Leaves:4)
Block(-3,16,-4,LEAVES:4)
Block(-3,12,0,Leaves:4)
Block(-3,11,0,LOG:12)
Block(-4,9,-1,Leaves:4)
Block(-4,14,-5,LEAVES:4)
Block(-3,18,0,LEAVES:4)
Block(-4,16,-5,LEAVES:4)
B(0,20,4,LEAVES:4)
Block(-1,28,1,LEAVES:4)
B(0,21,4,LEAVES:4)
B(3,6,2,Leaves:4)
B(3,19,3,LEAVES:4)
B(0,22,4,LEAVES:4)
B(3,10,3,Leaves:4)
B(3,19,-1,LEAVES:4)
Block(-1,22,1,LEAVES:4)
Block(-1,8,1,Leaves:4)
B(3,18,-1,LEAVES:4)
Block(-1,9,1,Leaves:4)
B(3,11,3,Leaves:4)
B(3,16,-1,LEAVES:4)
Block(-1,25,1,LEAVES:4)
B(3,15,-1,LEAVES:4)
B(3,14,-1,LEAVES:4)
Block(-1,23,1,LEAVES:4)
B(3,13,-1,Leaves:4)
Block(-1,24,1,LEAVES:4)
Block(-1,6,1,Leaves:4)
Block(-1,12,-3,Leaves:4)
B(1,8,2,Leaves:4)
B(3,11,-1,Leaves:4)
B(1,7,2,Leaves:4)
B(1,5,2,Leaves:4)
B(5,19,-2,LEAVES:4)
B(1,9,2,Leaves:4)
B(5,11,-2,Leaves:4)
B(5,12,-2,Leaves:4)
Block(-1,16,1,LOG:12)
Block(-5,17,5,LEAVES:4)
B(1,18,-1,LEAVES:4)
B(0,10,4,Leaves:4)
Block(-1,18,1,LEAVES:4)
Block(-5,19,5,LEAVES:4)
Block(-1,19,1,LEAVES:4)
B(1,14,-1,LEAVES:4)
B(0,14,4,LEAVES:4)
B(1,15,-1,LEAVES:4)
B(1,16,-1,LEAVES:4)
B(0,12,4,Leaves:4)
B(1,8,6,Leaves:4)
B(3,23,3,LEAVES:4)
B(0,17,4,LEAVES:4)
Block(-1,18,-3,LEAVES:4)
B(0,18,4,LEAVES:4)
Block(-1,10,1,Leaves:4)
Block(-1,19,-3,LEAVES:4)
Block(-1,13,1,Leaves:4)
Block(-1,14,-3,LEAVES:4)
B(3,25,3,LEAVES:4)
Block(-1,14,1,LEAVES:4)
Block(-1,15,-3,LEAVES:4)
B(0,19,4,LEAVES:4)
Block(-1,15,1,LEAVES:4)
Block(-1,16,-3,LEAVES:4)
B(5,10,0,Leaves:4)
Block(-1,22,-3,LEAVES:4)
B(5,11,0,Leaves:4)
B(1,10,-1,Leaves:4)
B(5,17,0,LEAVES:4)
B(5,18,0,LEAVES:4)
B(1,12,-1,Leaves:4)
B(5,24,-2,LEAVES:4)
B(5,23,-2,LEAVES:4)
B(2,18,-3,LEAVES:4)
B(2,16,-3,LEAVES:4)
B(2,19,-3,LEAVES:4)
Block(-2,7,5,Leaves:4)
Block(-2,9,5,Leaves:4)
B(5,24,0,LEAVES:4)
B(5,21,0,LEAVES:4)
B(5,20,0,LEAVES:4)
B(2,10,-3,Leaves:4)
Block(-6,11,-1,LEAVES:4)
B(2,14,-3,LEAVES:4)
B(2,13,-3,Leaves:4)
B(2,11,-3,Leaves:4)
B(0,9,5,Leaves:4)
B(0,7,5,Leaves:4)
Block(-1,30,1,LEAVES:4)
B(3,7,-1,Leaves:4)
B(2,13,4,Leaves:4)
B(1,18,0,LEAVES:4)
B(0,24,-6,LEAVES:4)
B(1,16,0,LEAVES:4)
B(1,17,0,LOG:12)
B(1,12,0,Leaves:4)
B(2,12,4,Leaves:4)
B(1,10,0,Leaves:4)
B(1,11,0,LOG:12)
Block(-2,14,6,LEAVES:4)
B(0,22,-6,LEAVES:4)
B(2,18,4,LEAVES:4)
B(0,21,-6,LEAVES:4)
B(4,20,-1,LEAVES:4)
B(2,25,4,LEAVES:4)
B(2,22,4,LEAVES:4)
B(4,7,3,Leaves:4)
Block(-5,11,1,Leaves:4)
Block(-5,15,5,LEAVES:4)
B(4,23,4,LEAVES:4)
B(2,9,-4,Leaves:4)
B(4,25,4,LEAVES:4)
B(4,26,4,LEAVES:4)
B(1,24,0,LEAVES:4)
B(1,25,0,LEAVES:4)
B(3,25,-1,LEAVES:4)
B(3,27,-1,LEAVES:4)
B(1,28,0,LEAVES:4)
B(4,17,-1,LEAVES:4)
B(1,20,0,LEAVES:4)
B(1,21,0,LOG:12)
B(1,22,0,LEAVES:4)
B(4,13,-1,Leaves:4)
B(2,9,-2,LOG:12)
B(4,10,-1,Leaves:4)
B(2,8,-2,Leaves:4)
B(4,12,4,Leaves:4)
B(3,20,-1,LEAVES:4)
B(3,22,-1,LEAVES:4)
B(3,21,-1,LEAVES:4)
B(1,13,1,Leaves:4)
B(1,14,1,LEAVES:4)
B(1,14,3,LEAVES:4)
B(1,11,3,Leaves:4)
B(1,16,1,LEAVES:4)
B(1,10,3,Leaves:4)
B(1,18,1,LEAVES:4)
Block(-3,14,-6,LEAVES:4)
Block(-6,11,0,LEAVES:4)
B(1,19,3,LEAVES:4)
B(1,11,1,Leaves:4)
B(1,26,1,LEAVES:4)
B(1,22,3,LEAVES:4)
B(0,12,3,Leaves:4)
B(1,27,1,LEAVES:4)
B(1,23,3,LEAVES:4)
B(0,13,3,Leaves:4)
B(1,24,1,LOG:12)
B(0,10,3,Leaves:4)
B(1,25,1,LEAVES:4)
B(1,28,1,LEAVES:4)
B(1,20,3,LEAVES:4)
B(0,18,3,LEAVES:4)
B(1,22,1,LEAVES:4)
B(0,16,3,LEAVES:4)
B(0,17,3,LEAVES:4)
B(1,28,3,LEAVES:4)
B(0,14,3,LEAVES:4)
B(1,20,1,LEAVES:4)
B(0,20,3,LOG:12)
B(0,22,3,LEAVES:4)
B(0,23,3,LEAVES:4)
B(0,26,3,LEAVES:4)
B(0,28,3,LEAVES:4)
B(2,21,-4,LEAVES:4)
Block(-6,23,0,LEAVES:4)
Block(-5,16,4,LEAVES:4)
B(3,6,5,Leaves:4)
B(2,11,-4,Leaves:4)
B(2,14,-4,LEAVES:4)
B(2,20,-3,LEAVES:4)
B(2,21,-3,LEAVES:4)
Block(-1,15,-6,LEAVES:4)
B(2,25,-3,LEAVES:4)
B(2,22,-3,LEAVES:4)
B(2,23,-3,LEAVES:4)
Block(-2,8,0,Leaves:4)
Block(-2,9,0,Leaves:4)
Block(-5,13,-4,Leaves:4)
Block(-5,14,-4,LEAVES:4)
B(3,8,-2,Leaves:4)
Block(-5,15,-4,LEAVES:4)
Block(-5,16,-4,LEAVES:4)
Block(-4,17,-2,LEAVES:4)
Block(-4,10,-2,Leaves:4)
Block(-4,15,-2,LEAVES:4)
Block(-3,9,-2,Leaves:4)
Block(-2,8,4,Leaves:4)
Block(-2,6,4,Leaves:4)
Block(-4,21,-2,LEAVES:4)
B(1,25,-2,LEAVES:4)
B(4,12,-2,Leaves:4)
Block(-5,13,-1,Leaves:4)
B(1,21,-2,LEAVES:4)
B(4,16,-2,LEAVES:4)
B(1,20,-2,LEAVES:4)
B(2,20,5,LEAVES:4)
B(2,22,5,LEAVES:4)
B(2,24,5,LEAVES:4)
B(5,11,-3,Leaves:4)
B(1,28,-2,LEAVES:4)
B(2,25,5,LEAVES:4)
B(1,26,-2,LEAVES:4)
B(1,27,-2,LEAVES:4)
B(1,23,-1,LEAVES:4)
B(1,24,-1,LEAVES:4)
B(1,20,-1,LEAVES:4)
B(4,26,-2,LEAVES:4)
B(1,11,-2,Leaves:4)
B(4,24,-2,LEAVES:4)
B(1,19,-2,LEAVES:4)
Block(-1,28,-3,LEAVES:4)
Block(-1,25,-3,LEAVES:4)
B(4,21,-2,LEAVES:4)
Block(-1,24,-3,LEAVES:4)
Block(-1,27,-3,LEAVES:4)
Block(-1,26,-3,LEAVES:4)
B(1,18,-2,LEAVES:4)
B(1,25,-1,LEAVES:4)
B(1,28,-1,LEAVES:4)
Block(-3,23,3,LEAVES:4)
Block(-4,8,4,Leaves:4)
Block(-2,18,5,LEAVES:4)
Block(-2,19,5,LEAVES:4)
Block(-2,15,5,LEAVES:4)
Block(-2,20,5,LEAVES:4)
Block(-3,15,3,LEAVES:4)
Block(-3,14,3,LEAVES:4)
Block(-3,13,3,Leaves:4)
Block(-3,12,3,Leaves:4)
Block(-3,19,3,LEAVES:4)
Block(-3,18,3,LEAVES:4)
Block(-3,17,3,LOG:12)
Block(-3,16,3,LEAVES:4)
Block(-2,10,5,Leaves:4)
B(1,25,-5,LEAVES:4)
Block(-3,22,3,LEAVES:4)
B(1,23,-5,LEAVES:4)
Block(-3,20,3,LEAVES:4)
B(0,20,-4,LEAVES:4)
Block(-5,17,3,LEAVES:4)
Block(-1,20,3,LEAVES:4)
Block(-5,15,3,LEAVES:4)
B(0,24,-4,LEAVES:4)
B(0,22,-4,LEAVES:4)
Block(-3,9,2,Leaves:4)
Block(-3,8,2,Leaves:4)
Block(-5,18,3,LEAVES:4)
Block(-1,17,3,LEAVES:4)
Block(-1,16,3,LEAVES:4)
Block(-1,15,3,LEAVES:4)
Block(-1,14,3,LOG:12)
Block(-1,13,3,Leaves:4)
Block(-1,12,3,Leaves:4)
Block(-1,11,3,Leaves:4)
Block(-1,18,3,LEAVES:4)
Block(-3,17,6,LEAVES:4)
Block(-1,17,-6,LEAVES:4)
Block(-1,16,-6,LEAVES:4)
Block(-3,16,6,LEAVES:4)
B(0,14,-4,LEAVES:4)
B(0,17,-4,LEAVES:4)
B(0,16,-4,LEAVES:4)
B(0,13,-4,Leaves:4)
Block(-1,27,3,LEAVES:4)
Block(-1,8,5,Leaves:4)
B(0,18,-4,LEAVES:4)
Block(-1,21,3,LEAVES:4)
B(0,19,-4,LEAVES:4)
Block(-1,23,3,LEAVES:4)
Block(-1,9,5,Leaves:4)
B(2,7,5,Leaves:4)
B(0,8,1,Leaves:4)
B(2,8,5,Leaves:4)
Block(-2,9,-2,Leaves:4)
B(2,6,5,Leaves:4)
B(0,9,1,Leaves:4)
Block(-1,20,-6,LEAVES:4)
B(3,23,-3,LEAVES:4)
B(3,22,-3,LEAVES:4)
B(3,20,-3,LEAVES:4)
Block(-2,9,2,Leaves:4)
Block(-2,14,-4,LEAVES:4)
B(0,16,-1,LEAVES:4)
B(0,15,-1,LOG:12)
Block(-2,16,-4,LEAVES:4)
B(0,18,-1,LEAVES:4)
B(0,17,-1,LEAVES:4)
Block(-2,17,-4,LEAVES:4)
Block(-2,19,-4,LEAVES:4)
B(0,10,-1,Leaves:4)
Block(-2,20,-4,LEAVES:4)
Block(-2,20,3,LEAVES:4)
B(0,28,-1,LEAVES:4)
B(0,27,-1,LEAVES:4)
Block(-3,10,3,Leaves:4)
B(2,19,0,LEAVES:4)
B(2,17,0,LOG:12)
B(1,15,-5,LEAVES:4)
Block(-2,19,3,LEAVES:4)
B(0,24,-1,LOG:12)
Block(-2,18,3,LEAVES:4)
B(0,25,-1,LEAVES:4)
B(4,22,2,LEAVES:4)
Block(-2,17,3,LEAVES:4)
B(0,22,-1,LEAVES:4)
Block(-2,16,3,LEAVES:4)
B(0,23,-1,LEAVES:4)
Block(-2,15,3,LEAVES:4)
B(4,27,2,LEAVES:4)
B(2,11,0,LOG:12)
Block(-2,14,3,LEAVES:4)
B(0,20,-1,LOG:12)
B(4,26,2,LEAVES:4)
Block(-2,13,3,Leaves:4)
B(2,12,0,Leaves:4)
B(0,21,-1,LEAVES:4)
B(4,25,2,LEAVES:4)
Block(-2,12,3,Leaves:4)
B(4,24,2,LEAVES:4)
Block(-2,11,3,Leaves:4)
B(2,10,0,Leaves:4)
Block(-2,10,3,Leaves:4)
B(3,10,-3,Leaves:4)
Block(-6,13,-2,LEAVES:4)
B(3,11,-3,Leaves:4)
B(3,12,-3,Leaves:4)
B(4,12,1,Leaves:4)
B(4,15,1,LEAVES:4)
B(4,14,1,LEAVES:4)
Block(-6,15,-2,LEAVES:4)
B(4,11,1,Leaves:4)
B(2,24,0,LEAVES:4)
B(2,25,0,LEAVES:4)
B(2,26,0,LEAVES:4)
B(2,27,0,LEAVES:4)
B(4,10,2,Leaves:4)
B(4,12,2,Leaves:4)
B(3,17,-3,LEAVES:4)
Block(-1,9,-1,Leaves:4)
B(2,20,0,LEAVES:4)
B(2,21,0,LOG:12)
B(2,22,0,LEAVES:4)
B(4,16,2,LEAVES:4)
B(2,23,0,LEAVES:4)

#######################################################################
# +-----------------------------------------------------------------+ #
# |                            BO3 checks                           | #
# +-----------------------------------------------------------------+ #
#######################################################################

BlockCheck(0,-1,0,GRASS,DIRT)

#######################################################################
# +-----------------------------------------------------------------+ #
# |                             Branches                            | #
# +-----------------------------------------------------------------+ #
#######################################################################


#######################################################################
# +-----------------------------------------------------------------+ #
# |                             Entities                            | #
# +-----------------------------------------------------------------+ #
#######################################################################


#######################################################################
# +-----------------------------------------------------------------+ #
# |                            Particles                            | #
# +-----------------------------------------------------------------+ #
#######################################################################


#######################################################################
# +-----------------------------------------------------------------+ #
# |                             Spawners                            | #
# +-----------------------------------------------------------------+ #
#######################################################################


#######################################################################
# +-----------------------------------------------------------------+ #
# |                             ModData                             | #
# +-----------------------------------------------------------------+ #
#######################################################################

