
#######################################################################
# +-----------------------------------------------------------------+ #
# |                            BO3 object                           | #
# +-----------------------------------------------------------------+ #
#######################################################################

Author: NLBlackEagle

Description: Converted version of the BO2 NA17L

Version: 3

SettingsMode: WriteDisable


#######################################################################
# +-----------------------------------------------------------------+ #
# |                          Main settings                          | #
# +-----------------------------------------------------------------+ #
#######################################################################

Tree: true

Frequency: 1

Rarity: 100.0

RotateRandomly: true

SpawnHeight: highestSolidBlock

SpawnHeightOffset: -2

SpawnHeightVariance: 0

##############################
# Height Limits for the BO3. #
##############################

MinHeight: 0

MaxHeight: 110

######################
# Extrusion settings #
######################

ExtrudeMode: None

ExtrudeThroughBlocks: AIR

MaxBranchDepth: 10

ExcludedBiomes: 


#######################################################################
# +-----------------------------------------------------------------+ #
# |                      Source block settings                      | #
# +-----------------------------------------------------------------+ #
#######################################################################

SourceBlocks: AIR,GRASS,DIRT,SAND

MaxPercentageOutsideSourceBlock: 0

OutsideSourceBlock: placeAnyway

IsOTGPlus: false

InheritBO3: 

InheritBO3Rotation: NORTH

OverrideChildSettings: true

OverrideParentHeight: false

CanOverride: false

BranchFrequency: 0

BranchFrequencyGroup: 

MustBeBelowOther: false

MustBeInside: 

CannotBeInside: 

ReplacesBO3: 

CanSpawnOnWater: true

SpawnOnWaterOnly: false

SpawnUnderWater: false

SpawnAtWaterLevel: false

HeightOffset: 0

RemoveAir: true

ReplaceAbove: 

ReplaceBelow: 

ReplaceWithBiomeBlocks: true

ReplaceWithGroundBlock: DIRT

ReplaceWithSurfaceBlock: GRASS

SmoothRadius: 0

SmoothHeightOffset: 0

SmoothStartTop: false

SmoothStartWood: false

SmoothingSurfaceBlock: 

SmoothingGroundBlock: 

BO3Group: 

IsSpawnPoint: false


#######################################################################
# +-----------------------------------------------------------------+ #
# |                              Blocks                             | #
# +-----------------------------------------------------------------+ #
#######################################################################

Block(1,17,-4,LOG:12)
Block(0,25,-2,LOG:12)
Block(-2,22,3,leaves:1)
Block(2,5,3,leaves:1)
Block(0,26,-2,leaves:1)
Block(-2,23,3,leaves:1)
Block(0,34,0,LOG:12)
Block(3,16,-6,leaves:1)
Block(2,6,2,leaves:1)
Block(2,7,2,LOG:12)
Block(3,15,-6,leaves:1)
Block(2,8,2,leaves:1)
Block(-1,-1,-1,LOG:12)
Block(-1,-2,-1,LOG:12)
Block(-1,-3,-1,LOG:12)
Block(-5,15,-5,leaves:1)
Block(-5,14,-5,LOG:4)
Block(0,28,-2,LOG:12)
Block(-3,23,0,leaves:1)
Block(1,11,-4,leaves:1)
Block(0,29,-2,leaves:1)
Block(-3,26,0,leaves:1)
Block(-3,25,0,leaves:1)
Block(-3,23,1,LOG:12)
Block(1,28,-4,leaves:1)
Block(-3,18,2,leaves:1)
Block(0,19,2,leaves:1)
Block(-3,17,2,leaves:1)
Block(0,18,2,leaves:1)
Block(-3,16,2,leaves:1)
Block(0,17,2,leaves:1)
Block(-3,15,2,LOG:12)
Block(0,16,2,leaves:1)
Block(0,15,2,LOG:12)
Block(0,12,-2,LOG:12)
Block(0,13,-2,leaves:1)
Block(-3,19,2,leaves:1)
Block(3,8,1,leaves:1)
Block(-4,14,4,leaves:1)
Block(-4,15,4,leaves:1)
Block(-3,19,1,leaves:1)
Block(-3,18,1,leaves:1)
Block(3,7,1,LOG:12)
Block(-3,17,1,leaves:1)
Block(-3,21,2,leaves:1)
Block(1,23,-4,leaves:1)
Block(0,17,-2,LOG:12)
Block(3,7,0,leaves:1)
Block(-3,34,0,leaves:1)
Block(-3,13,1,leaves:1)
Block(1,24,-4,leaves:1)
Block(-3,12,1,leaves:1)
Block(-3,10,1,leaves:1)
Block(-3,23,2,leaves:1)
Block(-3,22,2,leaves:1)
Block(1,9,-5,leaves:1)
Block(0,18,0,leaves:1)
Block(-5,4,0,leaves:1)
Block(3,22,-2,leaves:1)
Block(-5,5,0,leaves:1)
Block(-3,14,-3,LOG:12)
Block(3,21,-2,leaves:1)
Block(0,16,0,leaves:1)
Block(0,15,0,leaves:1)
Block(0,14,0,leaves:1)
Block(0,13,0,leaves:1)
Block(1,8,-6,leaves:1)
Block(0,12,0,leaves:1)
Block(-3,15,-3,leaves:1)
Block(1,9,-6,leaves:1)
Block(-5,3,0,leaves:1)
Block(-3,21,-3,leaves:1)
Block(-3,20,-3,LOG:12)
Block(0,8,3,leaves:1)
Block(1,8,-5,leaves:1)
Block(0,36,-2,LOG:12)
Block(-5,3,-1,leaves:1)
Block(0,21,0,leaves:1)
Block(0,20,0,leaves:1)
Block(0,29,0,leaves:1)
Block(3,16,-5,leaves:1)
Block(0,28,0,leaves:1)
Block(3,17,-5,leaves:1)
Block(3,15,-4,leaves:1)
Block(3,17,-4,leaves:1)
Block(3,11,-5,leaves:1)
Block(3,11,-4,leaves:1)
Block(3,12,-4,leaves:1)
Block(0,19,0,leaves:1)
Block(3,15,-5,leaves:1)
Block(3,10,-4,leaves:1)
Block(3,12,-5,leaves:1)
Block(-5,4,-1,leaves:1)
Block(1,8,-2,leaves:1)
Block(1,9,-2,leaves:1)
Block(0,8,-6,leaves:1)
Block(0,9,-6,leaves:1)
Block(-3,10,-4,leaves:1)
Block(-2,26,0,leaves:1)
Block(4,9,-3,leaves:1)
Block(-3,31,-1,leaves:1)
Block(-2,25,0,leaves:1)
Block(-2,24,0,leaves:1)
Block(-2,23,0,LOG:12)
Block(1,9,-4,leaves:1)
Block(-3,32,-2,leaves:1)
Block(-3,35,-2,leaves:1)
Block(-3,34,-2,leaves:1)
Block(-2,17,0,leaves:1)
Block(-3,29,-3,leaves:1)
Block(-2,19,0,leaves:1)
Block(-3,27,-1,leaves:1)
Block(-3,26,-1,LOG:12)
Block(-3,30,-1,leaves:1)
Block(-3,30,-3,leaves:1)
Block(-3,31,-3,leaves:1)
Block(0,3,1,leaves:1)
Block(0,6,1,leaves:1)
Block(-3,17,-1,leaves:1)
Block(-4,8,-5,leaves:1)
Block(-4,5,-4,leaves:1)
Block(-4,10,-5,leaves:1)
Block(-4,12,4,leaves:1)
Block(-4,7,-5,leaves:1)
Block(-4,4,-4,leaves:1)
Block(-4,11,-5,leaves:1)
Block(-4,13,4,leaves:1)
Block(-4,7,-4,leaves:1)
Block(-4,9,-5,leaves:1)
Block(-4,6,-4,leaves:1)
Block(-4,4,-5,leaves:1)
Block(-4,3,-5,leaves:1)
Block(-4,6,-5,leaves:1)
Block(-4,5,-5,leaves:1)
Block(-2,29,-3,leaves:1)
Block(-3,16,-1,LOG:4)
Block(-5,6,1,leaves:1)
Block(-5,5,1,LOG:12)
Block(-3,19,-2,leaves:1)
Block(-3,18,-2,leaves:1)
Block(0,10,-5,leaves:1)
Block(-2,31,-3,leaves:1)
Block(-3,15,-2,leaves:1)
Block(-3,14,-2,leaves:1)
Block(0,11,-5,leaves:1)
Block(-4,23,1,LOG:12)
Block(-3,16,-2,leaves:1)
Block(0,12,-5,leaves:1)
Block(-3,13,-2,leaves:1)
Block(-3,31,-2,LOG:12)
Block(-4,3,1,leaves:1)
Block(-2,35,-2,leaves:1)
Block(-4,4,1,leaves:1)
Block(-2,34,-2,leaves:1)
Block(-3,13,-4,leaves:1)
Block(-3,14,0,leaves:1)
Block(-3,12,-4,leaves:1)
Block(-3,13,0,leaves:1)
Block(-3,14,-4,leaves:1)
Block(-3,15,0,leaves:1)
Block(-4,12,-5,leaves:1)
Block(-3,25,-2,leaves:1)
Block(-3,23,-2,leaves:1)
Block(-4,3,-1,leaves:1)
Block(-4,4,-1,leaves:1)
Block(-1,29,1,LOG:12)
Block(2,7,0,leaves:1)
Block(3,5,2,leaves:1)
Block(3,6,2,leaves:1)
Block(2,6,0,leaves:1)
Block(3,7,2,leaves:1)
Block(-1,8,2,leaves:1)
Block(-1,9,2,leaves:1)
Block(3,19,-1,leaves:1)
Block(-3,8,-5,leaves:1)
Block(3,18,-1,leaves:1)
Block(-3,7,-5,LOG:12)
Block(-2,31,-2,leaves:1)
Block(2,8,1,leaves:1)
Block(2,7,1,LOG:12)
Block(-2,30,-2,leaves:1)
Block(1,8,2,leaves:1)
Block(0,5,-3,leaves:1)
Block(0,4,-3,leaves:1)
Block(1,6,2,leaves:1)
Block(0,3,-3,leaves:1)
Block(0,8,-5,leaves:1)
Block(1,5,2,leaves:1)
Block(-2,29,-2,leaves:1)
Block(0,9,-3,leaves:1)
Block(0,8,-3,leaves:1)
Block(0,7,-3,leaves:1)
Block(2,22,-1,leaves:1)
Block(0,6,-3,leaves:1)
Block(1,9,2,leaves:1)
Block(-3,3,-3,leaves:1)
Block(1,7,3,leaves:1)
Block(-3,7,-3,leaves:1)
Block(-3,6,-3,leaves:1)
Block(1,5,3,leaves:1)
Block(-3,5,-3,leaves:1)
Block(-3,4,-3,leaves:1)
Block(-1,19,1,LOG:12)
Block(0,13,4,leaves:1)
Block(0,14,4,leaves:1)
Block(0,12,4,leaves:1)
Block(-5,23,0,leaves:1)
Block(-5,22,0,leaves:1)
Block(0,15,4,leaves:1)
Block(-2,20,-2,LOG:12)
Block(-2,21,-2,leaves:1)
Block(-1,15,1,LOG:12)
Block(-1,23,-3,leaves:1)
Block(-2,14,-2,LOG:12)
Block(-1,22,-3,LOG:12)
Block(2,18,-3,leaves:1)
Block(2,15,-3,leaves:1)
Block(2,16,-3,leaves:1)
Block(2,19,-3,leaves:1)
Block(-5,19,0,leaves:1)
Block(-5,18,0,leaves:1)
Block(2,12,3,leaves:1)
Block(-4,16,3,leaves:1)
Block(-2,31,-1,LOG:12)
Block(-4,15,3,LOG:12)
Block(-5,20,0,leaves:1)
Block(-5,21,0,leaves:1)
Block(0,0,-1,LOG:12)
Block(-2,27,-1,leaves:1)
Block(-2,26,-1,LOG:12)
Block(2,10,-3,leaves:1)
Block(2,14,-3,leaves:1)
Block(2,13,-3,leaves:1)
Block(2,12,-3,leaves:1)
Block(2,11,-3,leaves:1)
Block(-3,-1,0,LOG:12)
Block(-3,-2,0,LOG:12)
Block(-1,30,1,leaves:1)
Block(4,12,-3,leaves:1)
Block(-2,32,-1,leaves:1)
Block(4,11,-3,leaves:1)
Block(-2,35,-1,LOG:12)
Block(-2,37,-1,leaves:1)
Block(-2,36,-1,leaves:1)
Block(2,5,0,leaves:1)
Block(1,18,0,leaves:1)
Block(-3,6,-4,leaves:1)
Block(-3,4,-4,leaves:1)
Block(-4,13,-6,leaves:1)
Block(-3,3,-4,leaves:1)
Block(-1,3,-5,leaves:1)
Block(-1,7,-4,leaves:1)
Block(-1,6,-4,leaves:1)
Block(-1,19,-1,LOG:12)
Block(-1,5,-4,leaves:1)
Block(-1,18,-1,LOG:12)
Block(-1,7,-5,leaves:1)
Block(-1,4,-4,leaves:1)
Block(-1,17,-1,LOG:12)
Block(-1,6,-5,leaves:1)
Block(-1,3,-4,leaves:1)
Block(-1,16,-1,LOG:12)
Block(-1,5,-5,leaves:1)
Block(-1,4,-5,leaves:1)
Block(-1,15,-1,LOG:12)
Block(-5,21,2,leaves:1)
Block(-1,14,-1,LOG:12)
Block(-5,20,2,leaves:1)
Block(-3,9,-4,leaves:1)
Block(-1,13,-1,LOG:12)
Block(-5,23,2,leaves:1)
Block(-3,8,-4,leaves:1)
Block(-1,12,-1,LOG:12)
Block(-5,22,2,leaves:1)
Block(0,9,-4,leaves:1)
Block(-3,7,-4,leaves:1)
Block(-1,11,-1,LOG:12)
Block(-1,20,-1,LOG:12)
Block(-1,8,-3,leaves:1)
Block(-5,13,2,leaves:1)
Block(-1,21,-1,LOG:12)
Block(0,8,-4,leaves:1)
Block(-5,14,2,leaves:1)
Block(-2,19,2,LOG:12)
Block(-1,7,-3,LOG:12)
Block(-5,18,2,leaves:1)
Block(-5,19,2,leaves:1)
Block(-1,0,-2,LOG:12)
Block(-1,7,-2,LOG:12)
Block(-2,15,2,LOG:12)
Block(0,12,-6,leaves:1)
Block(-3,0,0,LOG:12)
Block(0,11,-6,leaves:1)
Block(0,10,-6,leaves:1)
Block(-2,29,2,leaves:1)
Block(-3,3,0,leaves:1)
Block(-1,10,-1,LOG:12)
Block(-2,23,2,LOG:12)
Block(-2,16,-1,LOG:4)
Block(1,34,0,leaves:1)
Block(-1,36,-1,LOG:12)
Block(2,10,-2,leaves:1)
Block(-1,35,-1,LOG:12)
Block(-1,34,-1,LOG:12)
Block(-1,33,-1,LOG:12)
Block(2,8,-5,leaves:1)
Block(-1,39,-1,leaves:1)
Block(1,33,0,leaves:1)
Block(2,9,-5,leaves:1)
Block(-1,38,-1,leaves:1)
Block(-1,37,-1,LOG:12)
Block(0,-1,0,LOG:12)
Block(0,-2,0,LOG:12)
Block(-1,40,-1,leaves:1)
Block(2,9,-3,leaves:1)
Block(2,8,-3,leaves:1)
Block(-6,14,-5,leaves:1)
Block(-6,12,-5,leaves:1)
Block(-6,13,-5,leaves:1)
Block(-1,23,-1,LOG:12)
Block(2,23,-2,leaves:1)
Block(2,24,-2,leaves:1)
Block(-1,22,-1,LOG:12)
Block(-1,25,-1,LOG:12)
Block(-1,24,-1,LOG:12)
Block(2,22,-2,LOG:12)
Block(-1,27,-1,LOG:12)
Block(-1,26,-1,LOG:12)
Block(1,20,0,leaves:1)
Block(-1,29,-1,LOG:12)
Block(1,21,0,leaves:1)
Block(-1,28,-1,LOG:12)
Block(1,22,0,leaves:1)
Block(2,9,-2,leaves:1)
Block(-4,8,-3,leaves:1)
Block(-5,13,-6,leaves:1)
Block(-1,30,-1,LOG:12)
Block(-1,31,-1,LOG:12)
Block(2,26,-2,leaves:1)
Block(2,8,-2,leaves:1)
Block(-4,4,-3,leaves:1)
Block(-1,32,-1,LOG:12)
Block(2,25,-2,leaves:1)
Block(-5,14,-6,leaves:1)
Block(-4,12,-6,leaves:1)
Block(-4,4,-2,LOG:12)
Block(-4,11,-6,leaves:1)
Block(3,20,-1,leaves:1)
Block(3,22,-1,leaves:1)
Block(3,21,-1,leaves:1)
Block(1,13,1,leaves:1)
Block(-4,21,0,leaves:1)
Block(-1,-1,-2,LOG:12)
Block(1,14,1,leaves:1)
Block(1,26,-3,leaves:1)
Block(1,15,1,leaves:1)
Block(1,25,-3,LOG:12)
Block(-4,23,0,leaves:1)
Block(-4,26,0,leaves:1)
Block(-4,25,0,leaves:1)
Block(-1,-2,-2,LOG:12)
Block(1,21,-3,leaves:1)
Block(1,14,2,leaves:1)
Block(1,13,2,leaves:1)
Block(1,11,2,leaves:1)
Block(1,10,2,leaves:1)
Block(1,10,1,leaves:1)
Block(1,11,1,leaves:1)
Block(1,15,3,LOG:12)
Block(1,16,3,leaves:1)
Block(1,12,1,leaves:1)
Block(1,5,1,leaves:1)
Block(1,28,-3,LOG:12)
Block(1,29,-3,leaves:1)
Block(0,12,3,leaves:1)
Block(0,10,3,leaves:1)
Block(0,11,3,leaves:1)
Block(1,34,-2,leaves:1)
Block(1,35,-2,leaves:1)
Block(1,36,-2,leaves:1)
Block(-4,19,2,leaves:1)
Block(-4,19,0,leaves:1)
Block(-4,18,2,leaves:1)
Block(-4,13,2,leaves:1)
Block(0,14,3,leaves:1)
Block(-4,15,2,leaves:1)
Block(-4,14,2,leaves:1)
Block(-4,20,2,leaves:1)
Block(-4,22,2,leaves:1)
Block(2,28,-4,leaves:1)
Block(2,27,-4,leaves:1)
Block(-2,-1,-1,LOG:12)
Block(2,26,-4,leaves:1)
Block(0,34,1,leaves:1)
Block(0,33,1,leaves:1)
Block(-2,4,-5,leaves:1)
Block(1,12,-3,LOG:12)
Block(2,17,-4,leaves:1)
Block(2,16,-4,leaves:1)
Block(-5,15,4,leaves:1)
Block(-2,6,-5,leaves:1)
Block(-2,5,-5,leaves:1)
Block(-2,7,-5,leaves:1)
Block(0,28,1,leaves:1)
Block(0,29,1,leaves:1)
Block(2,12,-4,LOG:12)
Block(2,13,-4,leaves:1)
Block(2,15,-4,leaves:1)
Block(1,19,-3,leaves:1)
Block(1,17,-3,LOG:12)
Block(2,20,-3,leaves:1)
Block(-5,18,-4,leaves:1)
Block(2,21,-3,leaves:1)
Block(-5,19,-4,leaves:1)
Block(2,25,-3,leaves:1)
Block(-5,4,-2,leaves:1)
Block(2,22,-3,leaves:1)
Block(-1,18,2,leaves:1)
Block(2,23,-3,leaves:1)
Block(-5,3,-3,leaves:1)
Block(-5,11,-4,leaves:1)
Block(-1,15,2,leaves:1)
Block(-5,4,-3,leaves:1)
Block(-5,12,-4,leaves:1)
Block(-1,14,2,leaves:1)
Block(-5,5,-3,LOG:12)
Block(-1,13,2,leaves:1)
Block(-5,6,-3,leaves:1)
Block(-2,3,0,leaves:1)
Block(-1,12,2,leaves:1)
Block(-5,14,-4,leaves:1)
Block(-2,4,0,leaves:1)
Block(-1,11,2,leaves:1)
Block(-5,8,-3,leaves:1)
Block(-1,10,2,leaves:1)
Block(-5,17,-4,leaves:1)
Block(-5,9,-3,leaves:1)
Block(-4,18,-2,leaves:1)
Block(-4,19,-2,leaves:1)
Block(3,9,-4,leaves:1)
Block(3,8,-4,leaves:1)
Block(1,5,0,leaves:1)
Block(0,10,1,leaves:1)
Block(-1,22,-2,LOG:12)
Block(0,11,1,leaves:1)
Block(1,3,0,leaves:1)
Block(1,4,0,leaves:1)
Block(2,28,-3,leaves:1)
Block(0,15,1,leaves:1)
Block(2,27,-3,leaves:1)
Block(0,12,1,leaves:1)
Block(-5,19,-2,leaves:1)
Block(0,18,1,leaves:1)
Block(0,19,1,leaves:1)
Block(-5,18,-2,leaves:1)
Block(-4,31,-1,leaves:1)
Block(-5,17,-2,leaves:1)
Block(-4,30,-1,leaves:1)
Block(0,17,1,leaves:1)
Block(-1,22,-5,leaves:1)
Block(-4,30,-2,leaves:1)
Block(-1,21,-5,leaves:1)
Block(-3,4,-2,leaves:1)
Block(-5,20,-2,leaves:1)
Block(-4,29,-1,leaves:1)
Block(-4,24,-1,leaves:1)
Block(-4,23,-1,leaves:1)
Block(-4,23,-2,leaves:1)
Block(-4,26,-1,leaves:1)
Block(-4,20,-2,leaves:1)
Block(-2,9,3,leaves:1)
Block(-4,25,-1,leaves:1)
Block(-1,19,-5,leaves:1)
Block(-2,8,3,leaves:1)
Block(-4,26,-2,leaves:1)
Block(-1,18,-5,leaves:1)
Block(-4,24,-2,leaves:1)
Block(-4,25,-2,leaves:1)
Block(-1,37,-2,leaves:1)
Block(-1,22,-4,LOG:12)
Block(1,21,-2,leaves:1)
Block(-1,36,-2,leaves:1)
Block(1,20,-2,leaves:1)
Block(-1,35,-2,leaves:1)
Block(-1,34,-2,leaves:1)
Block(-1,23,-4,leaves:1)
Block(1,28,-2,leaves:1)
Block(-1,36,-3,leaves:1)
Block(1,26,-2,leaves:1)
Block(4,7,1,leaves:1)
Block(-1,35,-3,leaves:1)
Block(1,27,-2,leaves:1)
Block(4,5,0,leaves:1)
Block(1,7,1,leaves:1)
Block(-5,10,-3,leaves:1)
Block(1,22,-1,LOG:12)
Block(1,6,1,leaves:1)
Block(1,9,1,leaves:1)
Block(-5,12,-3,leaves:1)
Block(1,8,1,leaves:1)
Block(-5,11,-3,leaves:1)
Block(-5,14,-3,leaves:1)
Block(-5,13,-3,leaves:1)
Block(-4,18,-4,leaves:1)
Block(-4,17,-4,leaves:1)
Block(-6,4,-4,leaves:1)
Block(1,11,-2,leaves:1)
Block(1,14,-2,leaves:1)
Block(-5,19,-3,leaves:1)
Block(1,13,-2,leaves:1)
Block(-4,15,-4,leaves:1)
Block(-4,13,-4,leaves:1)
Block(1,10,-2,leaves:1)
Block(-4,20,-4,leaves:1)
Block(1,19,-2,leaves:1)
Block(1,15,-2,leaves:1)
Block(1,16,-2,leaves:1)
Block(1,18,-2,leaves:1)
Block(-6,3,1,leaves:1)
Block(-6,4,1,leaves:1)
Block(-6,5,1,leaves:1)
Block(0,0,0,LOG:12)
Block(0,6,0,LOG:12)
Block(-4,4,0,leaves:1)
Block(-4,3,0,leaves:1)
Block(-4,6,0,leaves:1)
Block(-4,5,0,LOG:12)
Block(-3,4,-1,LOG:12)
Block(-3,15,3,leaves:1)
Block(-3,14,3,leaves:1)
Block(-3,13,3,leaves:1)
Block(-3,19,3,leaves:1)
Block(-3,18,3,leaves:1)
Block(-3,17,3,leaves:1)
Block(-3,22,3,leaves:1)
Block(-3,20,3,leaves:1)
Block(0,20,-4,leaves:1)
Block(-4,13,-1,leaves:1)
Block(-4,14,-1,leaves:1)
Block(-4,15,-1,leaves:1)
Block(0,20,-3,leaves:1)
Block(-4,16,-1,leaves:1)
Block(0,21,-3,leaves:1)
Block(-3,3,1,leaves:1)
Block(-5,15,3,leaves:1)
Block(0,24,-3,leaves:1)
Block(2,12,-5,LOG:12)
Block(2,11,-5,leaves:1)
Block(0,26,-3,leaves:1)
Block(2,10,-5,leaves:1)
Block(0,21,-4,leaves:1)
Block(0,28,-3,leaves:1)
Block(2,17,-5,LOG:12)
Block(2,15,-6,leaves:1)
Block(2,10,-6,leaves:1)
Block(-1,19,3,leaves:1)
Block(2,12,-6,leaves:1)
Block(-1,18,3,leaves:1)
Block(0,34,-3,leaves:1)
Block(-6,5,0,leaves:1)
Block(-6,4,0,leaves:1)
Block(-6,3,0,leaves:1)
Block(0,11,-4,leaves:1)
Block(0,10,-4,leaves:1)
Block(0,35,-3,leaves:1)
Block(0,36,-3,leaves:1)
Block(0,12,-4,leaves:1)
Block(-1,22,2,leaves:1)
Block(-1,23,2,leaves:1)
Block(-1,20,2,leaves:1)
Block(-1,21,2,leaves:1)
Block(-1,21,3,leaves:1)
Block(-2,6,-2,leaves:1)
Block(-2,4,-2,leaves:1)
Block(0,8,1,leaves:1)
Block(-1,28,2,leaves:1)
Block(-1,29,2,leaves:1)
Block(1,10,-6,leaves:1)
Block(1,11,-6,leaves:1)
Block(-4,11,-3,leaves:1)
Block(1,12,-6,leaves:1)
Block(1,13,-6,leaves:1)
Block(-5,5,-4,leaves:1)
Block(1,14,-6,leaves:1)
Block(1,15,-6,leaves:1)
Block(1,16,-6,leaves:1)
Block(-5,3,-4,leaves:1)
Block(-4,14,-3,leaves:1)
Block(1,17,-6,leaves:1)
Block(-2,21,1,leaves:1)
Block(-2,20,1,leaves:1)
Block(-2,23,1,leaves:1)
Block(-2,22,1,leaves:1)
Block(-4,20,-3,LOG:12)
Block(-2,29,1,leaves:1)
Block(1,14,4,leaves:1)
Block(-2,28,1,leaves:1)
Block(1,15,4,leaves:1)
Block(1,13,4,leaves:1)
Block(0,16,-3,leaves:1)
Block(0,15,-3,leaves:1)
Block(0,14,-3,leaves:1)
Block(0,13,-3,leaves:1)
Block(0,12,-3,leaves:1)
Block(0,11,-3,leaves:1)
Block(0,10,-3,leaves:1)
Block(-1,15,0,LOG:12)
Block(-1,19,0,LOG:12)
Block(-2,20,-4,leaves:1)
Block(-2,22,-4,leaves:1)
Block(0,17,-3,leaves:1)
Block(0,18,-3,leaves:1)
Block(-2,20,3,leaves:1)
Block(-1,29,0,LOG:12)
Block(1,12,-5,leaves:1)
Block(1,13,-5,leaves:1)
Block(1,10,-5,leaves:1)
Block(1,11,-5,leaves:1)
Block(1,16,-5,leaves:1)
Block(1,17,-5,leaves:1)
Block(1,14,-5,leaves:1)
Block(2,18,0,leaves:1)
Block(1,15,-5,leaves:1)
Block(-2,18,3,leaves:1)
Block(0,22,-1,LOG:12)
Block(-2,15,3,leaves:1)
Block(-2,14,3,leaves:1)
Block(-2,11,3,leaves:1)
Block(-1,33,0,leaves:1)
Block(-1,34,0,leaves:1)
Block(-1,35,0,leaves:1)
Block(-2,10,3,leaves:1)
Block(0,38,-1,leaves:1)
Block(-1,30,0,leaves:1)
Block(-4,6,-6,leaves:1)
Block(3,12,-3,LOG:12)
Block(-1,32,0,leaves:1)
Block(-4,7,-6,leaves:1)
Block(3,13,-3,leaves:1)
Block(-4,5,-6,leaves:1)
Block(-2,4,-1,LOG:12)
Block(-1,38,0,leaves:1)
Block(-4,21,-3,leaves:1)
Block(-2,1,-1,LOG:12)
Block(-1,2,-1,LOG:12)
Block(-2,5,-3,leaves:1)
Block(-6,13,-6,leaves:1)
Block(-2,6,-3,leaves:1)
Block(-1,3,-1,LOG:12)
Block(-2,0,-1,LOG:12)
Block(-6,14,-6,leaves:1)
Block(-2,3,-3,leaves:1)
Block(-1,0,-1,LOG:12)
Block(-6,11,-6,leaves:1)
Block(-1,1,-1,LOG:12)
Block(-2,4,-3,leaves:1)
Block(-6,12,-6,leaves:1)
Block(-1,6,-1,LOG:12)
Block(-1,7,-1,LOG:12)
Block(-1,4,-1,LOG:12)
Block(-1,5,-1,LOG:12)
Block(-2,8,-4,leaves:1)
Block(0,34,-1,leaves:1)
Block(-2,19,1,leaves:1)
Block(0,35,-1,leaves:1)
Block(-2,18,1,leaves:1)
Block(-1,8,-1,LOG:12)
Block(0,36,-1,leaves:1)
Block(-2,7,-4,LOG:12)
Block(-1,9,-1,LOG:12)
Block(2,21,0,leaves:1)
Block(2,22,0,leaves:1)
Block(-2,7,-3,leaves:1)
Block(0,-1,0,LOG:5)

#######################################################################
# +-----------------------------------------------------------------+ #
# |                            BO3 checks                           | #
# +-----------------------------------------------------------------+ #
#######################################################################

BlockCheck(0,-1,0,GRASS,DIRT)

#######################################################################
# +-----------------------------------------------------------------+ #
# |                             Branches                            | #
# +-----------------------------------------------------------------+ #
#######################################################################


#######################################################################
# +-----------------------------------------------------------------+ #
# |                             Entities                            | #
# +-----------------------------------------------------------------+ #
#######################################################################


#######################################################################
# +-----------------------------------------------------------------+ #
# |                            Particles                            | #
# +-----------------------------------------------------------------+ #
#######################################################################


#######################################################################
# +-----------------------------------------------------------------+ #
# |                             Spawners                            | #
# +-----------------------------------------------------------------+ #
#######################################################################


#######################################################################
# +-----------------------------------------------------------------+ #
# |                             ModData                             | #
# +-----------------------------------------------------------------+ #
#######################################################################

