
#######################################################################
# +-----------------------------------------------------------------+ #
# |                            BO3 object                           | #
# +-----------------------------------------------------------------+ #
#######################################################################

Author: NLBlackEagle

Description: Converted version of the BO2 NA21S

Version: 3

SettingsMode: WriteDisable


#######################################################################
# +-----------------------------------------------------------------+ #
# |                          Main settings                          | #
# +-----------------------------------------------------------------+ #
#######################################################################

Tree: true

Frequency: 1

Rarity: 100.0

RotateRandomly: true

SpawnHeight: highestSolidBlock

SpawnHeightOffset: -2

SpawnHeightVariance: 0

##############################
# Height Limits for the BO3. #
##############################

MinHeight: 0

MaxHeight: 199

######################
# Extrusion settings #
######################

ExtrudeMode: None

ExtrudeThroughBlocks: AIR

MaxBranchDepth: 10

ExcludedBiomes: 


#######################################################################
# +-----------------------------------------------------------------+ #
# |                      Source block settings                      | #
# +-----------------------------------------------------------------+ #
#######################################################################

SourceBlocks: AIR,GRASS,DIRT,SAND

MaxPercentageOutsideSourceBlock: 0

OutsideSourceBlock: placeAnyway

IsOTGPlus: false

InheritBO3: 

InheritBO3Rotation: NORTH

OverrideChildSettings: true

OverrideParentHeight: false

CanOverride: false

BranchFrequency: 0

BranchFrequencyGroup: 

MustBeBelowOther: false

MustBeInside: 

CannotBeInside: 

ReplacesBO3: 

CanSpawnOnWater: true

SpawnOnWaterOnly: false

SpawnUnderWater: false

SpawnAtWaterLevel: false

HeightOffset: 0

RemoveAir: true

ReplaceAbove: 

ReplaceBelow: 

ReplaceWithBiomeBlocks: true

ReplaceWithGroundBlock: DIRT

ReplaceWithSurfaceBlock: GRASS

SmoothRadius: 0

SmoothHeightOffset: 0

SmoothStartTop: false

SmoothStartWood: false

SmoothingSurfaceBlock: 

SmoothingGroundBlock: 

BO3Group: 

IsSpawnPoint: false


#######################################################################
# +-----------------------------------------------------------------+ #
# |                              Blocks                             | #
# +-----------------------------------------------------------------+ #
#######################################################################

B(1,19,-4,LEAVES:4)
Block(-1,8,3,Leaves:4)
B(0,20,-2,Leaves:4)
Block(-1,5,3,Leaves:4)
B(2,3,3,Leaves:4)
Block(-1,7,4,Leaves:4)
B(2,9,2,Leaves:4)
B(1,3,4,Leaves:4)
B(1,12,-4,LEAVES:4)
Block(-3,10,2,LEAVES:4)
B(1,7,4,Leaves:4)
B(1,16,-4,Leaves:4)
B(1,9,4,Leaves:4)
B(0,11,-2,Leaves:4)
B(0,18,2,Leaves:4)
B(0,5,2,Leaves:4)
B(0,14,-2,Leaves:4)
Block(-1,0,0,LOG:12)
B(0,15,-2,Leaves:4)
Block(-3,11,2,Leaves:4)
B(0,13,2,Leaves:4)
Block(-2,-2,0,LOG:12)
Block(-2,-3,0,LOG:12)
B(0,11,2,Leaves:4)
B(3,5,1,Leaves:4)
Block(-4,11,1,Leaves:4)
B(3,6,1,Leaves:4)
Block(-4,14,1,Leaves:4)
Block(-4,13,1,LEAVES:4)
Block(-1,5,0,Leaves:4)
B(3,7,0,Leaves:4)
Block(-1,7,0,Leaves:4)
Block(-3,11,1,Leaves:4)
B(6,5,-1,LEAVES:4)
B(6,3,-1,Leaves:4)
B(0,18,0,Leaves:4)
Block(-3,13,-3,Leaves:4)
B(0,17,0,LOG:12)
Block(-3,11,-3,Leaves:4)
B(0,16,0,LOG:12)
B(0,15,0,LOG:12)
B(0,14,0,LOG:12)
B(0,13,0,LOG:12)
B(0,12,0,LOG:12)
B(1,9,-6,Leaves:4)
B(0,11,0,LOG:12)
B(1,5,-6,LEAVES:4)
B(1,3,-6,Leaves:4)
B(0,7,3,Leaves:4)
B(0,5,3,Leaves:4)
B(0,9,2,Leaves:4)
B(0,23,0,Leaves:4)
B(0,25,0,Leaves:4)
B(2,-1,0,LOG:12)
B(2,3,2,Leaves:4)
B(3,11,-4,Leaves:4)
B(3,13,-4,Leaves:4)
B(3,14,-2,Leaves:4)
B(5,3,1,Leaves:4)
Block(-5,9,-1,Leaves:4)
Block(-4,7,2,Leaves:4)
B(5,9,1,Leaves:4)
Block(-5,7,-1,LEAVES:4)
Block(-4,9,2,Leaves:4)
B(4,5,-3,Leaves:4)
B(1,0,-1,LOG:12)
B(1,3,-1,LOG:12)
B(1,4,-1,LOG:12)
B(1,7,-2,Leaves:4)
B(1,4,-2,Leaves:4)
B(1,1,-1,LOG:12)
B(1,5,-2,Leaves:4)
B(1,2,-1,LOG:12)
B(1,7,-1,Leaves:4)
Block(-3,11,-4,Leaves:4)
Block(-2,20,0,Leaves:4)
B(1,5,-1,LOG:12)
B(1,0,-2,LOG:12)
B(1,6,-1,LOG:12)
B(4,6,-2,Leaves:4)
B(4,5,-2,Leaves:4)
B(4,7,-3,Leaves:4)
Block(-2,23,0,Leaves:4)
B(4,3,-2,Leaves:4)
B(1,5,-3,Leaves:4)
Block(-2,11,-3,Leaves:4)
B(1,3,-3,Leaves:4)
B(1,9,-4,Leaves:4)
B(1,7,-4,Leaves:4)
B(1,5,-4,Leaves:4)
B(1,3,-4,Leaves:4)
B(3,14,0,Leaves:4)
B(3,18,0,Leaves:4)
B(0,3,3,Leaves:4)
Block(-2,18,-3,Leaves:4)
B(4,11,0,Leaves:4)
B(0,3,1,Leaves:4)
Block(-3,18,-1,Leaves:4)
B(3,3,1,Leaves:4)
Block(-4,7,-4,Leaves:4)
Block(-3,12,-1,LEAVES:4)
Block(-3,11,-1,Leaves:4)
Block(-3,13,-1,Leaves:4)
Block(-1,-1,0,LOG:12)
Block(-3,15,-1,Leaves:4)
B(0,14,-5,Leaves:4)
Block(-3,14,-2,Leaves:4)
B(0,11,-5,Leaves:4)
Block(-3,11,-2,Leaves:4)
Block(-2,11,-6,Leaves:4)
B(5,5,-3,Leaves:4)
B(5,7,-3,Leaves:4)
Block(-4,5,1,Leaves:4)
Block(-4,7,1,Leaves:4)
Block(-3,14,0,Leaves:4)
B(2,-3,-1,LOG:12)
Block(-3,16,0,Leaves:4)
B(2,-2,-1,LOG:12)
Block(-4,9,-1,Leaves:4)
B(5,5,2,Leaves:4)
Block(-4,7,-1,Leaves:4)
B(1,3,3,Leaves:4)
B(2,7,0,Leaves:4)
B(3,8,2,Leaves:4)
B(3,9,2,Leaves:4)
Block(-1,7,1,Leaves:4)
B(3,18,-1,Leaves:4)
B(3,17,-1,Leaves:4)
Block(-3,7,-5,Leaves:4)
B(2,9,1,Leaves:4)
B(2,8,1,Leaves:4)
B(2,7,1,Leaves:4)
B(3,14,-1,Leaves:4)
B(3,5,3,Leaves:4)
B(0,5,-5,Leaves:4)
B(0,4,-3,Leaves:4)
B(1,7,2,Leaves:4)
B(3,11,-1,Leaves:4)
B(1,5,2,Leaves:4)
B(2,21,-1,Leaves:4)
B(2,20,-1,Leaves:4)
B(0,7,-3,Leaves:4)
B(1,9,2,Leaves:4)
Block(-3,7,-3,Leaves:4)
B(1,5,3,Leaves:4)
B(1,18,-1,Leaves:4)
B(0,10,4,LEAVES:4)
Block(-1,19,1,Leaves:4)
B(1,14,-1,Leaves:4)
B(0,11,4,Leaves:4)
B(1,16,-1,Leaves:4)
B(4,3,2,Leaves:4)
B(4,5,2,Leaves:4)
Block(-1,13,-3,Leaves:4)
Block(-1,14,-3,Leaves:4)
Block(-2,20,-2,Leaves:4)
Block(-1,21,-3,Leaves:4)
Block(-2,16,-2,Leaves:4)
Block(-2,18,-2,Leaves:4)
B(1,13,-1,Leaves:4)
B(2,16,-3,Leaves:4)
B(1,-1,-2,LOG:12)
B(2,11,3,Leaves:4)
B(0,3,-1,LOG:12)
Block(-2,23,-1,Leaves:4)
B(0,2,-1,LOG:12)
B(0,1,-1,LOG:12)
Block(-2,21,-1,Leaves:4)
B(0,0,-1,LOG:12)
B(2,-2,1,LOG:12)
B(2,-3,1,LOG:12)
B(0,9,-1,LOG:12)
B(0,8,-1,LOG:12)
B(0,7,-1,LOG:12)
B(0,6,-1,LOG:12)
B(0,5,-1,LOG:12)
B(0,4,-1,LOG:12)
B(2,11,-3,Leaves:4)
B(0,5,4,Leaves:4)
B(0,9,4,Leaves:4)
B(1,3,2,Leaves:4)
B(6,3,0,Leaves:4)
B(4,14,-3,Leaves:4)
B(4,10,-3,Leaves:4)
B(3,4,-1,Leaves:4)
B(3,3,-1,Leaves:4)
B(2,4,0,Leaves:4)
B(2,5,0,Leaves:4)
B(3,5,-1,Leaves:4)
B(6,5,-3,LEAVES:4)
B(6,3,-3,Leaves:4)
B(2,0,0,LOG:12)
Block(-3,6,-4,Leaves:4)
Block(-1,3,-5,Leaves:4)
Block(-1,5,-4,Leaves:4)
Block(-1,7,-5,Leaves:4)
Block(-1,3,-4,Leaves:4)
Block(-1,17,-1,Leaves:4)
Block(-3,7,-4,Leaves:4)
B(0,7,-4,Leaves:4)
Block(-1,5,-2,Leaves:4)
B(0,5,-4,Leaves:4)
Block(-1,7,-3,Leaves:4)
B(0,4,-4,Leaves:4)
Block(-1,0,-2,LOG:12)
Block(-1,4,-3,Leaves:4)
Block(-1,5,-3,Leaves:4)
Block(-1,7,-2,Leaves:4)
Block(-1,3,-3,Leaves:4)
Block(-1,-2,-3,LOG:12)
B(1,-1,-1,LOG:12)
B(4,5,3,Leaves:4)
Block(-3,7,0,Leaves:4)
B(4,3,3,Leaves:4)
Block(-2,16,-1,Leaves:4)
B(1,-2,1,LOG:12)
B(1,-1,1,LOG:12)
Block(-2,-2,-2,LOG:12)
Block(-2,11,-1,Leaves:4)
Block(-2,-3,-2,LOG:12)
B(2,7,-6,LEAVES:4)
B(2,5,-6,LEAVES:4)
B(2,3,-6,Leaves:4)
Block(-5,11,1,Leaves:4)
B(2,5,-5,Leaves:4)
B(2,11,-2,Leaves:4)
B(2,3,-5,Leaves:4)
B(2,9,-5,Leaves:4)
B(2,19,-2,LEAVES:4)
B(2,7,-3,Leaves:4)
B(2,18,-2,Leaves:4)
B(2,14,-2,Leaves:4)
Block(-2,13,-5,Leaves:4)
B(2,7,-4,Leaves:4)
B(2,3,-3,Leaves:4)
B(2,14,1,Leaves:4)
B(2,3,-4,Leaves:4)
B(2,23,-2,Leaves:4)
B(5,3,-1,Leaves:4)
Block(-1,25,-1,Leaves:4)
B(4,14,-1,Leaves:4)
B(5,5,-1,Leaves:4)
B(4,13,-1,Leaves:4)
Block(-4,7,-3,Leaves:4)
B(2,5,-2,Leaves:4)
B(2,4,-1,Leaves:4)
B(2,7,-2,Leaves:4)
Block(-4,3,-2,Leaves:4)
B(2,7,-1,Leaves:4)
B(6,3,-2,Leaves:4)
B(2,9,-1,Leaves:4)
Block(-4,9,-3,Leaves:4)
B(6,5,-2,LEAVES:4)
Block(-1,-1,-2,LOG:12)
B(1,11,3,Leaves:4)
B(1,22,-3,Leaves:4)
B(1,14,2,Leaves:4)
B(1,13,2,Leaves:4)
B(1,11,2,Leaves:4)
B(1,11,1,Leaves:4)
B(3,7,-3,Leaves:4)
B(3,8,-3,Leaves:4)
B(1,3,1,Leaves:4)
B(1,0,1,LOG:12)
B(3,9,-3,Leaves:4)
B(0,11,3,Leaves:4)
B(0,14,3,Leaves:4)
B(1,21,1,Leaves:4)
B(1,13,-3,Leaves:4)
Block(-2,7,-5,Leaves:4)
Block(-1,3,-6,Leaves:4)
Block(-1,9,-6,Leaves:4)
B(0,20,1,Leaves:4)
B(0,22,1,Leaves:4)
Block(-1,11,-2,Leaves:4)
Block(-5,7,-2,LEAVES:4)
Block(-1,11,-6,Leaves:4)
B(3,5,-2,Leaves:4)
Block(-1,13,-2,Leaves:4)
Block(-1,14,2,Leaves:4)
B(1,1,0,LOG:12)
B(3,9,-4,Leaves:4)
B(1,0,0,LOG:12)
B(1,5,0,Leaves:4)
Block(-5,11,-2,Leaves:4)
Block(-1,22,-2,Leaves:4)
B(1,3,0,Leaves:4)
Block(-1,20,-2,Leaves:4)
B(1,4,0,Leaves:4)
B(0,18,1,Leaves:4)
Block(-1,24,-2,Leaves:4)
Block(-1,13,-4,Leaves:4)
Block(-3,3,-2,Leaves:4)
Block(-3,5,-2,Leaves:4)
Block(-2,3,3,Leaves:4)
Block(-2,7,3,Leaves:4)
Block(-2,5,3,Leaves:4)
Block(-2,7,4,Leaves:4)
Block(-5,11,-1,Leaves:4)
B(4,15,-2,LEAVES:4)
Block(-1,14,-4,Leaves:4)
B(4,3,1,Leaves:4)
B(5,10,-3,LEAVES:4)
Block(-1,18,-4,Leaves:4)
Block(-1,19,-4,LEAVES:4)
B(4,11,-2,Leaves:4)
B(4,9,0,Leaves:4)
B(4,7,0,Leaves:4)
B(4,5,0,Leaves:4)
B(1,23,-1,Leaves:4)
B(1,24,-1,Leaves:4)
B(1,8,1,Leaves:4)
Block(-5,11,-3,Leaves:4)
B(1,20,-1,Leaves:4)
B(0,7,-2,Leaves:4)
B(1,11,-2,Leaves:4)
B(0,9,-2,Leaves:4)
B(0,4,-2,Leaves:4)
B(1,7,0,Leaves:4)
Block(-2,7,-6,LEAVES:4)
B(1,-3,-3,LOG:12)
B(3,5,4,Leaves:4)
B(1,-2,-3,LOG:12)
Block(-2,9,-6,Leaves:4)
B(3,11,1,Leaves:4)
B(1,18,-2,Leaves:4)
B(0,2,0,LOG:12)
B(0,3,0,LOG:12)
B(0,0,0,LOG:12)
B(0,1,0,LOG:12)
B(0,7,0,Leaves:4)
B(0,5,0,Leaves:4)
Block(-3,7,-1,Leaves:4)
Block(-4,7,0,Leaves:4)
Block(-3,5,-1,Leaves:4)
B(5,5,-4,Leaves:4)
B(3,7,-5,Leaves:4)
Block(-3,7,2,Leaves:4)
Block(-4,11,-1,Leaves:4)
Block(-4,14,-1,Leaves:4)
B(0,21,-3,LEAVES:4)
Block(-3,3,1,Leaves:4)
B(2,14,-5,Leaves:4)
B(0,23,-3,Leaves:4)
B(2,11,-5,Leaves:4)
Block(-2,11,-4,Leaves:4)
Block(-1,14,3,Leaves:4)
B(2,11,-6,Leaves:4)
B(0,16,-4,Leaves:4)
B(0,11,-4,Leaves:4)
Block(-2,3,-2,Leaves:4)
B(4,9,-1,Leaves:4)
B(2,5,4,Leaves:4)
B(2,3,4,Leaves:4)
Block(-2,7,-2,Leaves:4)
B(4,5,-4,Leaves:4)
B(0,18,-4,Leaves:4)
Block(-2,6,-2,Leaves:4)
B(2,9,4,Leaves:4)
B(4,7,-4,Leaves:4)
B(0,7,1,Leaves:4)
B(4,3,-1,Leaves:4)
B(4,5,-1,Leaves:4)
B(4,7,-1,Leaves:4)
Block(-2,8,2,Leaves:4)
Block(-2,3,2,Leaves:4)
Block(-2,3,1,Leaves:4)
Block(-4,14,-3,Leaves:4)
Block(-2,6,1,Leaves:4)
B(1,11,4,Leaves:4)
B(0,16,-1,LOG:12)
B(0,15,-1,LOG:12)
B(0,18,-1,LOG:12)
B(0,17,-1,LOG:12)
Block(-1,11,0,Leaves:4)
B(0,19,-1,LOG:12)
B(0,11,-3,Leaves:4)
Block(-1,18,0,Leaves:4)
Block(-1,19,0,Leaves:4)
B(0,10,-1,LOG:12)
B(0,11,-1,LOG:12)
B(0,12,-1,LOG:12)
B(0,13,-1,LOG:12)
B(0,14,-1,LOG:12)
B(0,18,-3,Leaves:4)
Block(-1,24,0,Leaves:4)
B(2,16,0,Leaves:4)
B(2,14,0,Leaves:4)
B(0,24,-1,Leaves:4)
B(0,25,-1,LEAVES:4)
B(0,22,-1,LOG:12)
B(0,23,-1,LOG:12)
B(0,20,-1,LOG:12)
B(0,21,-1,LOG:12)
B(2,10,0,LEAVES:4)
Block(-2,11,3,Leaves:4)
B(4,3,-5,Leaves:4)
B(4,14,1,Leaves:4)
Block(-2,4,-1,Leaves:4)
Block(-2,3,-1,Leaves:4)
Block(-1,3,-1,Leaves:4)
Block(-2,11,1,Leaves:4)
Block(-2,3,-3,Leaves:4)
Block(-2,4,-3,Leaves:4)
Block(-1,7,-1,Leaves:4)
Block(-2,14,1,Leaves:4)
Block(-2,8,-4,Leaves:4)
B(3,14,-3,Leaves:4)
Block(-2,10,4,LEAVES:4)
Block(-2,7,-4,Leaves:4)
Block(-2,11,4,Leaves:4)
B(2,23,0,Leaves:4)

#######################################################################
# +-----------------------------------------------------------------+ #
# |                            BO3 checks                           | #
# +-----------------------------------------------------------------+ #
#######################################################################

BlockCheck(0,-1,0,GRASS,DIRT)

#######################################################################
# +-----------------------------------------------------------------+ #
# |                             Branches                            | #
# +-----------------------------------------------------------------+ #
#######################################################################


#######################################################################
# +-----------------------------------------------------------------+ #
# |                             Entities                            | #
# +-----------------------------------------------------------------+ #
#######################################################################


#######################################################################
# +-----------------------------------------------------------------+ #
# |                            Particles                            | #
# +-----------------------------------------------------------------+ #
#######################################################################


#######################################################################
# +-----------------------------------------------------------------+ #
# |                             Spawners                            | #
# +-----------------------------------------------------------------+ #
#######################################################################


#######################################################################
# +-----------------------------------------------------------------+ #
# |                             ModData                             | #
# +-----------------------------------------------------------------+ #
#######################################################################

