
#
# +-----------------------------------------------------------------+ #
# |                            BO3 object                           | #
# +-----------------------------------------------------------------+ #
#

Author: NLBlackEagle

Description: No description given

Version: 3

SettingsMode: WriteDisable


#
# +-----------------------------------------------------------------+ #
# |                          Main settings                          | #
# +-----------------------------------------------------------------+ #
#

Tree: true

Frequency: 1

Rarity: 100.0

RotateRandomly: true

SpawnHeight: highestSolidBlock

SpawnHeightOffset: 0

SpawnHeightVariance: 0


# Height Limits for the BO3. #


MinHeight: 60

MaxHeight: 256


# Extrusion settings #


ExtrudeMode: None

ExtrudeThroughBlocks: air

MaxBranchDepth: 10

ExcludedBiomes: All


#
# +-----------------------------------------------------------------+ #
# |                      Source block settings                      | #
# +-----------------------------------------------------------------+ #
#

SourceBlocks: AIR,GRASS,DIRT,SAND,stone,sand,grass,dirt

MaxPercentageOutsideSourceBlock: 0

OutsideSourceBlock: dontPlace


#
# +-----------------------------------------------------------------+ #
# |                              Blocks                             | #
# +-----------------------------------------------------------------+ #
#

B(-11,9,-11,leaves:3)
B(-11,10,-7,leaves:3)
B(-10,7,-10,leaves:3)
B(-10,10,-10,leaves:3)
B(-10,10,-9,leaves:3)
B(-10,11,-7,leaves:3)
B(-10,12,-9,leaves:3)
B(-10,12,-6,leaves:3)
B(-9,7,-4,leaves:3)
B(-9,8,-9,leaves:3)
B(-9,8,-7,leaves:3)
B(-9,8,-5,leaves:3)
B(-9,9,-9,leaves:3)
B(-9,9,-7,leaves:3)
B(-9,9,-5,leaves:3)
B(-9,10,-8,leaves:3)
B(-9,11,-7,leaves:3)
B(-9,11,-6,leaves:3)
B(-9,12,-8,leaves:3)
B(-9,12,-7,leaves:3)
B(-8,9,-11,leaves:3)
B(-8,9,-7,leaves:3)
B(-8,10,-8,leaves:3)
B(-8,10,-7,leaves:3)
B(-8,10,-6,leaves:3)
B(-8,11,-8,leaves:3)
B(-8,11,-7,leaves:3)
B(-8,12,-9,leaves:3)
B(-8,12,-6,leaves:3)
B(-8,12,-4,leaves:3)
B(-7,7,-10,leaves:3)
B(-7,8,-9,leaves:3)
B(-7,8,-7,log:3)
B(-7,9,-8,leaves:3)
B(-7,9,-7,log:3)
B(-7,9,-6,leaves:3)
B(-7,9,-5,leaves:3)
B(-7,10,-11,leaves:3)
B(-7,10,-9,leaves:3)
B(-7,10,-8,leaves:3)
B(-7,10,-7,leaves:3)
B(-7,10,-6,leaves:3)
B(-7,11,-10,leaves:3)
B(-7,11,-7,leaves:3)
B(-7,11,-6,leaves:3)
B(-7,11,-5,leaves:3)
B(-7,12,-7,leaves:3)
B(-7,13,-7,leaves:3)
B(-7,14,-9,leaves:3)
B(-7,14,-8,leaves:3)
B(-7,14,-5,leaves:3)
B(-6,-3,-6,LOG:15)
B(-6,5,-6,wooden_slab:9)
B(-6,6,-6,log:3)
B(-6,6,-3,leaves:3)
B(-6,7,-6,log:3)
B(-6,7,-4,leaves:3)
B(-6,8,-6,leaves:3)
B(-6,8,-4,leaves:3)
B(-6,9,-7,leaves:3)
B(-6,9,-6,leaves:3)
B(-6,10,-8,leaves:3)
B(-6,10,-7,leaves:3)
B(-6,10,-6,leaves:3)
B(-6,10,-5,leaves:3)
B(-6,11,-8,leaves:3)
B(-6,11,-7,leaves:3)
B(-6,11,-6,leaves:3)
B(-6,11,-4,leaves:3)
B(-6,12,-9,leaves:3)
B(-6,12,-7,leaves:3)
B(-6,12,-6,leaves:3)
B(-6,13,-6,leaves:3)
B(-6,14,-8,leaves:3)
B(-5,-3,-6,LOG:15)
B(-5,-3,4,LOG:15)
B(-5,-2,-6,LOG:15)
B(-5,-2,-5,LOG:15)
B(-5,-2,3,LOG:15)
B(-5,-2,4,LOG:15)
B(-5,3,-5,wooden_slab:9)
B(-5,4,-5,log:3)
B(-5,5,-5,log:3)
B(-5,8,-8,leaves:3)
B(-5,9,-8,leaves:3)
B(-5,9,-6,leaves:3)
B(-5,11,-9,leaves:3)
B(-5,11,-7,leaves:3)
B(-5,11,-5,leaves:3)
B(-5,12,-7,leaves:3)
B(-5,13,-5,leaves:3)
B(-4,-3,3,LOG:15)
B(-4,-2,-5,LOG:15)
B(-4,-2,3,LOG:15)
B(-4,-1,-5,LOG:15)
B(-4,-1,-4,LOG:15)
B(-4,-1,3,LOG:15)
B(-4,2,-4,wooden_slab:9)
B(-4,3,-4,log:3)
B(-4,7,-8,leaves:3)
B(-4,7,-5,leaves:3)
B(-4,8,-5,leaves:3)
B(-4,9,-11,leaves:3)
B(-4,10,-10,leaves:3)
B(-4,10,-7,leaves:3)
B(-4,10,-4,leaves:3)
B(-4,11,-10,leaves:3)
B(-4,11,-7,leaves:3)
B(-4,11,-4,leaves:3)
B(-4,13,-8,leaves:3)
B(-4,13,-5,leaves:3)
B(-3,-1,-4,LOG:15)
B(-3,-1,-3,LOG:15)
B(-3,-1,-2,LOG:15)
B(-3,-1,2,LOG:15)
B(-3,-1,3,LOG:15)
B(-3,1,-3,wooden_slab:9)
B(-3,2,-3,log:3)
B(-3,6,-9,leaves:3)
B(-3,6,-5,leaves:3)
B(-3,9,-7,leaves:3)
B(-3,9,-3,leaves:3)
B(-3,10,-7,leaves:3)
B(-3,12,-5,leaves:3)
B(-2,-2,-1,LOG:15)
B(-2,-1,-2,LOG:15)
B(-2,-1,-1,LOG:15)
B(-2,-1,2,LOG:15)
B(-2,0,-2,wooden_slab:9)
B(-2,1,-2,log:3)
B(-2,2,-2,wooden_slab:1)
B(-2,8,-7,leaves:3)
B(-1,-2,2,LOG:15)
B(-1,-1,-1,LOG:15)
B(-1,-1,0,LOG:15)
B(-1,-1,1,LOG:15)
B(-1,-1,2,LOG:15)
B(-1,0,-1,wooden_slab:9)
B(-1,0,0,log:3)
B(-1,0,1,spruce_stairs:4)
B(-1,1,-1,log:3)
B(-1,1,0,wooden_slab:1)
B(-1,4,1,leaves:3)
B(-1,5,1,leaves:3)
B(0,-1,0,log:3)
B(0,-1,1,log:3)
B(0,0,-1,spruce_stairs:5)
B(0,0,0,log:3)
B(0,0,1,log:3)
B(0,1,-1,spruce_stairs:1)
B(0,1,0,log:3)
B(0,1,1,wooden_slab:1)
B(0,2,0,log:3)
B(0,3,3,leaves:3)
B(0,4,-1,leaves:3)
B(0,5,1,leaves:3)
B(0,6,-1,leaves:3)
B(0,7,2,leaves:3)
B(1,-1,-1,LOG:15)
B(1,-1,0,LOG:15)
B(1,0,0,spruce_stairs:5)
B(1,1,0,wooden_slab:1)
B(1,3,0,log:3)
B(1,4,0,leaves:3)
B(1,4,1,leaves:3)
B(1,4,2,leaves:3)
B(1,5,0,leaves:3)
B(1,6,1,leaves:3)
B(2,-2,-1,LOG:15)
B(2,-1,-2,LOG:15)
B(2,-1,-1,LOG:15)
B(2,2,-1,leaves:3)
B(2,2,3,leaves:3)
B(2,3,-1,leaves:3)
B(2,3,2,leaves:3)
B(2,4,0,leaves:3)
B(2,4,1,log:3)
B(2,4,2,leaves:3)
B(2,4,4,leaves:3)
B(2,5,1,leaves:3)
B(2,5,3,leaves:3)
B(2,6,-2,leaves:3)
B(2,6,0,leaves:3)
B(2,6,2,leaves:3)
B(2,7,-1,leaves:3)
B(3,-3,-3,LOG:15)
B(3,-2,-4,LOG:15)
B(3,-2,-3,LOG:15)
B(3,-1,-3,LOG:15)
B(3,-1,-2,LOG:15)
B(3,4,1,leaves:3)
B(3,5,0,leaves:3)
B(3,5,2,leaves:3)
B(3,6,1,leaves:3)
B(3,7,1,leaves:3)
B(4,-3,-5,LOG:15)
B(4,-2,-5,LOG:15)
B(4,-2,-4,LOG:15)
B(4,3,1,leaves:3)
B(4,3,3,leaves:3)
B(4,4,-1,leaves:3)
B(4,4,3,leaves:3)
B(4,6,1,leaves:3)
B(4,6,3,leaves:3)
B(5,5,1,leaves:3)

#
# +-----------------------------------------------------------------+ #
# |                            BO3 checks                           | #
# +-----------------------------------------------------------------+ #
#

BlockCheck(0,-1,0,sand)
BlockCheckNot(-32,-3,32,water)
BlockCheckNot(-32,-3,-32,water)
BlockCheckNot(32,-3,-32,water)
BlockCheckNot(32,-3,32,water)
BlockCheckNot(-32,-3,32,water)

#
# +-----------------------------------------------------------------+ #
# |                             Branches                            | #
# +-----------------------------------------------------------------+ #
#

