Author: BO3 BulkEdit (by LanToaster)
Description: This Object was Created with BO3_BulkEdit
Version: 3
SettingsMode: WriteDisable
Tree: true
Frequency: 1
Rarity: 100.0
RotateRandomly: true
SpawnHeight: highestBlock
MinHeight: 0
MaxHeight: 256
MaxBranchDepth: 10
ExcludedBiomes: All
SourceBlocks: AIR,GRASS,DIRT,SAND,STONE,LOG
MaxPercentageOutsideSourceBlock: 30
OutsideSourceBlock: placeAnyway
Block(-7,-11,-16,LOG:15)
Block(-16,-11,-15,LOG:15)
Block(-8,-11,-15,LOG:15)
Block(-7,-11,-15,LOG:15)
Block(-6,-11,-15,LOG:15)
Block(6,-11,-15,LOG:15)
Block(7,-11,-15,LOG:15)
Block(8,-11,-15,LOG:15)
Block(9,-11,-15,LOG:15)
Block(-17,-11,-14,LOG:15)
Block(-16,-11,-14,LOG:15)
Block(-15,-11,-14,LOG:15)
Block(-7,-11,-14,LOG:15)
Block(-6,-11,-14,LOG:15)
Block(-5,-11,-14,LOG:15)
Block(-4,-11,-14,LOG:15)
Block(5,-11,-14,LOG:15)
Block(6,-11,-14,LOG:15)
Block(7,-11,-14,LOG:15)
Block(8,-11,-14,LOG:15)
Block(-17,-11,-13,LOG:15)
Block(-16,-11,-13,LOG:15)
Block(-15,-11,-13,LOG:15)
Block(-12,-11,-13,LOG:15)
Block(-6,-11,-13,LOG:15)
Block(-5,-11,-13,LOG:15)
Block(-4,-11,-13,LOG:15)
Block(-3,-11,-13,LOG:15)
Block(5,-11,-13,LOG:15)
Block(6,-11,-13,LOG:15)
Block(7,-11,-13,LOG:15)
Block(13,-11,-13,LOG:15)
Block(-17,-11,-12,LOG:15)
Block(-16,-11,-12,LOG:15)
Block(-15,-11,-12,LOG:15)
Block(-14,-11,-12,LOG:15)
Block(-11,-11,-12,LOG:15)
Block(-5,-11,-12,LOG:15)
Block(-4,-11,-12,LOG:15)
Block(-3,-11,-12,LOG:15)
Block(6,-11,-12,LOG:15)
Block(11,-11,-12,LOG:15)
Block(12,-11,-12,LOG:15)
Block(-16,-11,-11,LOG:15)
Block(-15,-11,-11,LOG:15)
Block(-12,-11,-11,LOG:15)
Block(-11,-11,-11,LOG:15)
Block(-10,-11,-11,LOG:15)
Block(-9,-11,-11,LOG:15)
Block(-4,-11,-11,LOG:15)
Block(10,-11,-11,LOG:15)
Block(11,-11,-11,LOG:15)
Block(12,-11,-11,LOG:15)
Block(13,-11,-11,LOG:15)
Block(-11,-11,-10,LOG:15)
Block(-10,-11,-10,LOG:15)
Block(-9,-11,-10,LOG:15)
Block(-8,-11,-10,LOG:15)
Block(4,-11,-10,LOG:15)
Block(9,-11,-10,LOG:15)
Block(10,-11,-10,LOG:15)
Block(11,-11,-10,LOG:15)
Block(12,-11,-10,LOG:15)
Block(-15,-11,-9,LOG:15)
Block(-10,-11,-9,LOG:15)
Block(-9,-11,-9,LOG:15)
Block(-8,-11,-9,LOG:15)
Block(-9,-11,-8,LOG:15)
Block(8,-11,-8,LOG:15)
Block(-15,-11,-6,LOG:15)
Block(-16,-11,-5,LOG:15)
Block(-15,-11,-5,LOG:15)
Block(-14,-11,-5,LOG:15)
Block(-16,-11,-4,LOG:15)
Block(-15,-11,-4,LOG:15)
Block(-14,-11,-4,LOG:15)
Block(-15,-11,-3,LOG:15)
Block(-12,-11,-2,LOG:15)
Block(12,-11,-1,LOG:15)
Block(13,-11,-1,LOG:15)
Block(-16,-11,0,LOG:15)
Block(8,-11,0,LOG:15)
Block(13,-11,0,LOG:15)
Block(12,-11,1,LOG:15)
Block(13,-11,1,LOG:15)
Block(14,-11,1,LOG:15)
Block(-17,-11,2,LOG:15)
Block(12,-11,2,LOG:15)
Block(13,-11,2,LOG:15)
Block(14,-11,2,LOG:15)
Block(-15,-11,3,LOG:15)
Block(13,-11,3,LOG:15)
Block(-16,-11,4,LOG:15)
Block(-15,-11,4,LOG:15)
Block(-14,-11,4,LOG:15)
Block(-17,-11,5,LOG:15)
Block(-16,-11,5,LOG:15)
Block(-15,-11,5,LOG:15)
Block(-14,-11,5,LOG:15)
Block(-16,-11,6,LOG:15)
Block(-15,-11,6,LOG:15)
Block(-15,-11,7,LOG:15)
Block(11,-11,7,LOG:15)
Block(-15,-11,8,LOG:15)
Block(-14,-11,8,LOG:15)
Block(-16,-11,9,LOG:15)
Block(-15,-11,9,LOG:15)
Block(-14,-11,9,LOG:15)
Block(-13,-11,9,LOG:15)
Block(-16,-11,10,LOG:15)
Block(-15,-11,10,LOG:15)
Block(-14,-11,10,LOG:15)
Block(-13,-11,10,LOG:15)
Block(-12,-11,10,LOG:15)
Block(-6,-11,10,LOG:15)
Block(-5,-11,10,LOG:15)
Block(1,-11,10,LOG:15)
Block(6,-11,10,LOG:15)
Block(7,-11,10,LOG:15)
Block(8,-11,10,LOG:15)
Block(9,-11,10,LOG:15)
Block(11,-11,10,LOG:15)
Block(12,-11,10,LOG:15)
Block(-15,-11,11,LOG:15)
Block(-14,-11,11,LOG:15)
Block(-13,-11,11,LOG:15)
Block(-12,-11,11,LOG:15)
Block(-11,-11,11,LOG:15)
Block(-7,-11,11,LOG:15)
Block(-6,-11,11,LOG:15)
Block(-5,-11,11,LOG:15)
Block(-4,-11,11,LOG:15)
Block(6,-11,11,LOG:15)
Block(7,-11,11,LOG:15)
Block(8,-11,11,LOG:15)
Block(9,-11,11,LOG:15)
Block(10,-11,11,LOG:15)
Block(11,-11,11,LOG:15)
Block(12,-11,11,LOG:15)
Block(13,-11,11,LOG:15)
Block(-14,-11,12,LOG:15)
Block(-13,-11,12,LOG:15)
Block(-12,-11,12,LOG:15)
Block(-6,-11,12,LOG:15)
Block(-5,-11,12,LOG:15)
Block(-1,-11,12,LOG:15)
Block(7,-11,12,LOG:15)
Block(8,-11,12,LOG:15)
Block(9,-11,12,LOG:15)
Block(10,-11,12,LOG:15)
Block(11,-11,12,LOG:15)
Block(12,-11,12,LOG:15)
Block(13,-11,12,LOG:15)
Block(-4,-11,13,LOG:15)
Block(3,-11,13,LOG:15)
Block(9,-11,13,LOG:15)
Block(12,-11,13,LOG:15)
Block(-7,-10,-15,LOG:15)
Block(-16,-10,-14,LOG:15)
Block(-6,-10,-14,LOG:15)
Block(5,-10,-14,LOG:15)
Block(6,-10,-14,LOG:15)
Block(7,-10,-14,LOG:15)
Block(-16,-10,-13,LOG:15)
Block(-5,-10,-13,LOG:15)
Block(-4,-10,-13,LOG:15)
Block(4,-10,-13,LOG:15)
Block(5,-10,-13,LOG:15)
Block(6,-10,-13,LOG:15)
Block(7,-10,-13,LOG:15)
Block(-16,-10,-12,LOG:15)
Block(-15,-10,-12,LOG:15)
Block(-6,-10,-12,LOG:15)
Block(-5,-10,-12,LOG:15)
Block(-4,-10,-12,LOG:15)
Block(-3,-10,-12,LOG:15)
Block(4,-10,-12,LOG:15)
Block(5,-10,-12,LOG:15)
Block(6,-10,-12,LOG:15)
Block(11,-10,-12,LOG:15)
Block(-15,-10,-11,LOG:15)
Block(-11,-10,-11,LOG:15)
Block(-5,-10,-11,LOG:15)
Block(-4,-10,-11,LOG:15)
Block(-3,-10,-11,LOG:15)
Block(4,-10,-11,LOG:15)
Block(9,-10,-11,LOG:15)
Block(10,-10,-11,LOG:15)
Block(11,-10,-11,LOG:15)
Block(12,-10,-11,LOG:15)
Block(-9,-10,-10,LOG:15)
Block(-8,-10,-10,LOG:15)
Block(4,-10,-10,LOG:15)
Block(8,-10,-10,LOG:15)
Block(9,-10,-10,LOG:15)
Block(10,-10,-10,LOG:15)
Block(11,-10,-10,LOG:15)
Block(12,-10,-10,LOG:15)
Block(-15,-10,-9,LOG:15)
Block(-10,-10,-9,LOG:15)
Block(-9,-10,-9,LOG:15)
Block(-8,-10,-9,LOG:15)
Block(-7,-10,-9,LOG:15)
Block(9,-10,-9,LOG:15)
Block(10,-10,-9,LOG:15)
Block(11,-10,-9,LOG:15)
Block(-9,-10,-8,LOG:15)
Block(-8,-10,-8,LOG:15)
Block(8,-10,-8,LOG:15)
Block(-15,-10,-5,LOG:15)
Block(-16,-10,-4,LOG:15)
Block(-15,-10,-4,LOG:15)
Block(-14,-10,-4,LOG:15)
Block(-16,-10,-3,LOG:15)
Block(-15,-10,-3,LOG:15)
Block(-14,-10,-3,LOG:15)
Block(-15,-10,-2,LOG:15)
Block(-12,-10,-2,LOG:15)
Block(12,-10,-2,LOG:15)
Block(13,-10,-2,LOG:15)
Block(11,-10,-1,LOG:15)
Block(12,-10,-1,LOG:15)
Block(13,-10,-1,LOG:15)
Block(14,-10,-1,LOG:15)
Block(-16,-10,0,LOG:15)
Block(8,-10,0,LOG:15)
Block(12,-10,0,LOG:15)
Block(13,-10,0,LOG:15)
Block(14,-10,0,LOG:15)
Block(12,-10,1,LOG:15)
Block(13,-10,1,LOG:15)
Block(14,-10,1,LOG:15)
Block(-17,-10,2,LOG:15)
Block(13,-10,2,LOG:15)
Block(-16,-10,3,LOG:15)
Block(-15,-10,3,LOG:15)
Block(-17,-10,4,LOG:15)
Block(-16,-10,4,LOG:15)
Block(-15,-10,4,LOG:15)
Block(-14,-10,4,LOG:15)
Block(-16,-10,5,LOG:15)
Block(-15,-10,5,LOG:15)
Block(-14,-10,7,LOG:15)
Block(-13,-10,7,LOG:15)
Block(11,-10,7,LOG:15)
Block(-15,-10,8,LOG:15)
Block(-14,-10,8,LOG:15)
Block(-13,-10,8,LOG:15)
Block(-15,-10,9,LOG:15)
Block(-14,-10,9,LOG:15)
Block(-13,-10,9,LOG:15)
Block(6,-10,9,LOG:15)
Block(7,-10,9,LOG:15)
Block(11,-10,9,LOG:15)
Block(-15,-10,10,LOG:15)
Block(-14,-10,10,LOG:15)
Block(-12,-10,10,LOG:15)
Block(-11,-10,10,LOG:15)
Block(1,-10,10,LOG:15)
Block(5,-10,10,LOG:15)
Block(6,-10,10,LOG:15)
Block(7,-10,10,LOG:15)
Block(8,-10,10,LOG:15)
Block(10,-10,10,LOG:15)
Block(11,-10,10,LOG:15)
Block(12,-10,10,LOG:15)
Block(-13,-10,11,LOG:15)
Block(-12,-10,11,LOG:15)
Block(-11,-10,11,LOG:15)
Block(-10,-10,11,LOG:15)
Block(-6,-10,11,LOG:15)
Block(-5,-10,11,LOG:15)
Block(6,-10,11,LOG:15)
Block(7,-10,11,LOG:15)
Block(8,-10,11,LOG:15)
Block(9,-10,11,LOG:15)
Block(10,-10,11,LOG:15)
Block(11,-10,11,LOG:15)
Block(12,-10,11,LOG:15)
Block(-12,-10,12,LOG:15)
Block(-11,-10,12,LOG:15)
Block(-1,-10,12,LOG:15)
Block(7,-10,12,LOG:15)
Block(9,-10,12,LOG:15)
Block(11,-10,12,LOG:15)
Block(12,-10,12,LOG:15)
Block(-4,-10,13,LOG:15)
Block(3,-10,13,LOG:15)
Block(5,-9,-14,LOG:15)
Block(-5,-9,-13,LOG:15)
Block(-4,-9,-13,LOG:15)
Block(4,-9,-13,LOG:15)
Block(5,-9,-13,LOG:15)
Block(6,-9,-13,LOG:15)
Block(-15,-9,-12,LOG:15)
Block(-6,-9,-12,LOG:15)
Block(-5,-9,-12,LOG:15)
Block(-4,-9,-12,LOG:15)
Block(-3,-9,-12,LOG:15)
Block(3,-9,-12,LOG:15)
Block(4,-9,-12,LOG:15)
Block(5,-9,-12,LOG:15)
Block(6,-9,-12,LOG:15)
Block(-16,-9,-11,LOG:15)
Block(-15,-9,-11,LOG:15)
Block(-14,-9,-11,LOG:15)
Block(-5,-9,-11,LOG:15)
Block(-4,-9,-11,LOG:15)
Block(-3,-9,-11,LOG:15)
Block(-2,-9,-11,LOG:15)
Block(3,-9,-11,LOG:15)
Block(4,-9,-11,LOG:15)
Block(5,-9,-11,LOG:15)
Block(9,-9,-11,LOG:15)
Block(11,-9,-11,LOG:15)
Block(-15,-9,-10,LOG:15)
Block(-9,-9,-10,LOG:15)
Block(-8,-9,-10,LOG:15)
Block(-4,-9,-10,LOG:15)
Block(-3,-9,-10,LOG:15)
Block(4,-9,-10,LOG:15)
Block(8,-9,-10,LOG:15)
Block(9,-9,-10,LOG:15)
Block(10,-9,-10,LOG:15)
Block(11,-9,-10,LOG:15)
Block(-15,-9,-9,LOG:15)
Block(-10,-9,-9,LOG:15)
Block(-9,-9,-9,LOG:15)
Block(-8,-9,-9,LOG:15)
Block(-7,-9,-9,LOG:15)
Block(2,-9,-9,LOG:15)
Block(8,-9,-9,LOG:15)
Block(9,-9,-9,LOG:15)
Block(10,-9,-9,LOG:15)
Block(-9,-9,-8,LOG:15)
Block(-8,-9,-8,LOG:15)
Block(-7,-9,-8,LOG:15)
Block(-2,-9,-8,LOG:15)
Block(8,-9,-8,LOG:15)
Block(9,-9,-8,LOG:15)
Block(-14,-9,-7,LOG:15)
Block(-5,-9,-7,LOG:15)
Block(-8,-9,-5,LOG:15)
Block(-15,-9,-4,LOG:15)
Block(-2,-9,-4,LOG:15)
Block(-16,-9,-3,LOG:15)
Block(-15,-9,-3,LOG:15)
Block(-14,-9,-3,LOG:15)
Block(-16,-9,-2,LOG:15)
Block(-15,-9,-2,LOG:15)
Block(-14,-9,-2,LOG:15)
Block(-12,-9,-2,LOG:15)
Block(11,-9,-2,LOG:15)
Block(12,-9,-2,LOG:15)
Block(-15,-9,-1,LOG:15)
Block(11,-9,-1,LOG:15)
Block(12,-9,-1,LOG:15)
Block(13,-9,-1,LOG:15)
Block(-16,-9,0,LOG:15)
Block(8,-9,0,LOG:15)
Block(12,-9,0,LOG:15)
Block(13,-9,0,LOG:15)
Block(-3,-9,1,LOG:15)
Block(13,-9,1,LOG:15)
Block(-17,-9,2,LOG:15)
Block(-15,-9,2,LOG:15)
Block(-16,-9,3,LOG:15)
Block(-15,-9,3,LOG:15)
Block(-14,-9,3,LOG:15)
Block(-10,-9,3,LOG:15)
Block(-16,-9,4,LOG:15)
Block(-15,-9,4,LOG:15)
Block(-14,-9,4,LOG:15)
Block(-15,-9,5,LOG:15)
Block(-14,-9,6,LOG:15)
Block(-13,-9,6,LOG:15)
Block(-15,-9,7,LOG:15)
Block(-14,-9,7,LOG:15)
Block(-13,-9,7,LOG:15)
Block(-12,-9,7,LOG:15)
Block(11,-9,7,LOG:15)
Block(-15,-9,8,LOG:15)
Block(-14,-9,8,LOG:15)
Block(-13,-9,8,LOG:15)
Block(-14,-9,9,LOG:15)
Block(6,-9,9,LOG:15)
Block(11,-9,9,LOG:15)
Block(-11,-9,10,LOG:15)
Block(-5,-9,10,LOG:15)
Block(0,-9,10,LOG:15)
Block(1,-9,10,LOG:15)
Block(5,-9,10,LOG:15)
Block(6,-9,10,LOG:15)
Block(7,-9,10,LOG:15)
Block(10,-9,10,LOG:15)
Block(11,-9,10,LOG:15)
Block(12,-9,10,LOG:15)
Block(-12,-9,11,LOG:15)
Block(-11,-9,11,LOG:15)
Block(-10,-9,11,LOG:15)
Block(-9,-9,11,LOG:15)
Block(-6,-9,11,LOG:15)
Block(-5,-9,11,LOG:15)
Block(-4,-9,11,LOG:15)
Block(6,-9,11,LOG:15)
Block(7,-9,11,LOG:15)
Block(10,-9,11,LOG:15)
Block(11,-9,11,LOG:15)
Block(12,-9,11,LOG:15)
Block(-11,-9,12,LOG:15)
Block(-5,-9,12,LOG:15)
Block(-1,-9,12,LOG:15)
Block(11,-9,12,LOG:15)
Block(-4,-9,13,LOG:15)
Block(3,-9,13,LOG:15)
Block(5,-8,-13,LOG:15)
Block(-15,-8,-12,LOG:15)
Block(-14,-8,-12,LOG:15)
Block(-5,-8,-12,LOG:15)
Block(-4,-8,-12,LOG:15)
Block(-3,-8,-12,LOG:15)
Block(3,-8,-12,LOG:15)
Block(4,-8,-12,LOG:15)
Block(5,-8,-12,LOG:15)
Block(-16,-8,-11,LOG:15)
Block(-15,-8,-11,LOG:15)
Block(-14,-8,-11,LOG:15)
Block(-13,-8,-11,LOG:15)
Block(-4,-8,-11,LOG:15)
Block(-3,-8,-11,LOG:15)
Block(-2,-8,-11,LOG:15)
Block(2,-8,-11,LOG:15)
Block(3,-8,-11,LOG:15)
Block(4,-8,-11,LOG:15)
Block(5,-8,-11,LOG:15)
Block(-15,-8,-10,LOG:15)
Block(-14,-8,-10,LOG:15)
Block(-8,-8,-10,LOG:15)
Block(-7,-8,-10,LOG:15)
Block(-4,-8,-10,LOG:15)
Block(-3,-8,-10,LOG:15)
Block(-2,-8,-10,LOG:15)
Block(3,-8,-10,LOG:15)
Block(4,-8,-10,LOG:15)
Block(8,-8,-10,LOG:15)
Block(9,-8,-10,LOG:15)
Block(-15,-8,-9,LOG:15)
Block(-14,-8,-9,LOG:15)
Block(-9,-8,-9,LOG:15)
Block(-8,-8,-9,LOG:15)
Block(-7,-8,-9,LOG:15)
Block(-6,-8,-9,LOG:15)
Block(-3,-8,-9,LOG:15)
Block(0,-8,-9,LOG:15)
Block(2,-8,-9,LOG:15)
Block(7,-8,-9,LOG:15)
Block(8,-8,-9,LOG:15)
Block(9,-8,-9,LOG:15)
Block(10,-8,-9,LOG:15)
Block(-8,-8,-8,LOG:15)
Block(-7,-8,-8,LOG:15)
Block(-6,-8,-8,LOG:15)
Block(-2,-8,-8,LOG:15)
Block(7,-8,-8,LOG:15)
Block(8,-8,-8,LOG:15)
Block(9,-8,-8,LOG:15)
Block(-14,-8,-7,LOG:15)
Block(-7,-8,-7,LOG:15)
Block(-5,-8,-7,LOG:15)
Block(0,-8,-7,LOG:15)
Block(5,-8,-7,LOG:15)
Block(8,-8,-7,LOG:15)
Block(-11,-8,-5,LOG:15)
Block(-8,-8,-5,LOG:15)
Block(-2,-8,-4,LOG:15)
Block(8,-8,-4,LOG:15)
Block(-15,-8,-3,LOG:15)
Block(-5,-8,-3,LOG:15)
Block(5,-8,-3,LOG:15)
Block(11,-8,-3,LOG:15)
Block(12,-8,-3,LOG:15)
Block(-16,-8,-2,LOG:15)
Block(-15,-8,-2,LOG:15)
Block(-14,-8,-2,LOG:15)
Block(-12,-8,-2,LOG:15)
Block(-3,-8,-2,LOG:15)
Block(10,-8,-2,LOG:15)
Block(11,-8,-2,LOG:15)
Block(12,-8,-2,LOG:15)
Block(13,-8,-2,LOG:15)
Block(-15,-8,-1,LOG:15)
Block(8,-8,-1,LOG:15)
Block(11,-8,-1,LOG:15)
Block(12,-8,-1,LOG:15)
Block(13,-8,-1,LOG:15)
Block(-16,-8,0,LOG:15)
Block(-15,-8,0,LOG:15)
Block(8,-8,0,LOG:15)
Block(12,-8,0,LOG:15)
Block(-15,-8,1,LOG:15)
Block(-3,-8,1,LOG:15)
Block(-17,-8,2,LOG:15)
Block(-16,-8,2,LOG:15)
Block(-15,-8,2,LOG:15)
Block(-14,-8,2,LOG:15)
Block(5,-8,2,LOG:15)
Block(-16,-8,3,LOG:15)
Block(-15,-8,3,LOG:15)
Block(-14,-8,3,LOG:15)
Block(-10,-8,3,LOG:15)
Block(-15,-8,4,LOG:15)
Block(-13,-8,5,LOG:15)
Block(-5,-8,5,LOG:15)
Block(0,-8,5,LOG:15)
Block(8,-8,5,LOG:15)
Block(-14,-8,6,LOG:15)
Block(-13,-8,6,LOG:15)
Block(-12,-8,6,LOG:15)
Block(-14,-8,7,LOG:15)
Block(-13,-8,7,LOG:15)
Block(-12,-8,7,LOG:15)
Block(8,-8,7,LOG:15)
Block(11,-8,7,LOG:15)
Block(-14,-8,8,LOG:15)
Block(-13,-8,8,LOG:15)
Block(-12,-8,8,LOG:15)
Block(-5,-8,8,LOG:15)
Block(0,-8,8,LOG:15)
Block(2,-8,8,LOG:15)
Block(11,-8,8,LOG:15)
Block(-13,-8,9,LOG:15)
Block(5,-8,9,LOG:15)
Block(6,-8,9,LOG:15)
Block(10,-8,9,LOG:15)
Block(11,-8,9,LOG:15)
Block(12,-8,9,LOG:15)
Block(-11,-8,10,LOG:15)
Block(-10,-8,10,LOG:15)
Block(-9,-8,10,LOG:15)
Block(-5,-8,10,LOG:15)
Block(-4,-8,10,LOG:15)
Block(0,-8,10,LOG:15)
Block(4,-8,10,LOG:15)
Block(5,-8,10,LOG:15)
Block(6,-8,10,LOG:15)
Block(7,-8,10,LOG:15)
Block(10,-8,10,LOG:15)
Block(11,-8,10,LOG:15)
Block(12,-8,10,LOG:15)
Block(-12,-8,11,LOG:15)
Block(-11,-8,11,LOG:15)
Block(-10,-8,11,LOG:15)
Block(-9,-8,11,LOG:15)
Block(-8,-8,11,LOG:15)
Block(-6,-8,11,LOG:15)
Block(-5,-8,11,LOG:15)
Block(-4,-8,11,LOG:15)
Block(-3,-8,11,LOG:15)
Block(5,-8,11,LOG:15)
Block(6,-8,11,LOG:15)
Block(11,-8,11,LOG:15)
Block(-11,-8,12,LOG:15)
Block(-10,-8,12,LOG:15)
Block(-9,-8,12,LOG:15)
Block(-5,-8,12,LOG:15)
Block(-4,-8,12,LOG:15)
Block(-1,-8,12,LOG:15)
Block(-4,-8,13,LOG:15)
Block(3,-8,13,LOG:15)
Block(-14,-7,-12,LOG:15)
Block(3,-7,-12,LOG:15)
Block(4,-7,-12,LOG:15)
Block(-15,-7,-11,LOG:15)
Block(-14,-7,-11,LOG:15)
Block(-13,-7,-11,LOG:15)
Block(-3,-7,-11,LOG:15)
Block(-2,-7,-11,LOG:15)
Block(2,-7,-11,LOG:15)
Block(3,-7,-11,LOG:15)
Block(4,-7,-11,LOG:15)
Block(5,-7,-11,LOG:15)
Block(-15,-7,-10,LOG:15)
Block(-14,-7,-10,LOG:15)
Block(-13,-7,-10,LOG:15)
Block(-4,-7,-10,LOG:15)
Block(-3,-7,-10,LOG:15)
Block(-2,-7,-10,LOG:15)
Block(-1,-7,-10,LOG:15)
Block(2,-7,-10,LOG:15)
Block(3,-7,-10,LOG:15)
Block(4,-7,-10,LOG:15)
Block(8,-7,-10,LOG:15)
Block(-15,-7,-9,LOG:15)
Block(-14,-7,-9,LOG:15)
Block(-13,-7,-9,LOG:15)
Block(-8,-7,-9,LOG:15)
Block(-7,-7,-9,LOG:15)
Block(-3,-7,-9,LOG:15)
Block(-2,-7,-9,LOG:15)
Block(0,-7,-9,LOG:15)
Block(2,-7,-9,LOG:15)
Block(7,-7,-9,LOG:15)
Block(8,-7,-9,LOG:15)
Block(9,-7,-9,LOG:15)
Block(-14,-7,-8,LOG:15)
Block(-8,-7,-8,LOG:15)
Block(-7,-7,-8,LOG:15)
Block(-6,-7,-8,LOG:15)
Block(-2,-7,-8,LOG:15)
Block(7,-7,-8,LOG:15)
Block(8,-7,-8,LOG:15)
Block(9,-7,-8,LOG:15)
Block(-14,-7,-7,LOG:15)
Block(-7,-7,-7,LOG:15)
Block(-5,-7,-7,LOG:15)
Block(0,-7,-7,LOG:15)
Block(5,-7,-7,LOG:15)
Block(8,-7,-7,LOG:15)
Block(-11,-7,-5,LOG:15)
Block(-8,-7,-5,LOG:15)
Block(-4,-7,-5,LOG:15)
Block(-13,-7,-4,LOG:15)
Block(-2,-7,-4,LOG:15)
Block(8,-7,-4,LOG:15)
Block(-15,-7,-3,LOG:15)
Block(-14,-7,-3,LOG:15)
Block(-5,-7,-3,LOG:15)
Block(3,-7,-3,LOG:15)
Block(5,-7,-3,LOG:15)
Block(10,-7,-3,LOG:15)
Block(11,-7,-3,LOG:15)
Block(-16,-7,-2,LOG:15)
Block(-15,-7,-2,LOG:15)
Block(-14,-7,-2,LOG:15)
Block(-13,-7,-2,LOG:15)
Block(-3,-7,-2,LOG:15)
Block(9,-7,-2,LOG:15)
Block(10,-7,-2,LOG:15)
Block(11,-7,-2,LOG:15)
Block(12,-7,-2,LOG:15)
Block(-16,-7,-1,LOG:15)
Block(-15,-7,-1,LOG:15)
Block(-14,-7,-1,LOG:15)
Block(8,-7,-1,LOG:15)
Block(10,-7,-1,LOG:15)
Block(11,-7,-1,LOG:15)
Block(12,-7,-1,LOG:15)
Block(-16,-7,0,LOG:15)
Block(-15,-7,0,LOG:15)
Block(-14,-7,0,LOG:15)
Block(3,-7,0,LOG:15)
Block(-16,-7,1,LOG:15)
Block(-15,-7,1,LOG:15)
Block(-14,-7,1,LOG:15)
Block(-11,-7,1,LOG:15)
Block(-8,-7,1,LOG:15)
Block(-3,-7,1,LOG:15)
Block(-2,-7,1,LOG:15)
Block(1,-7,1,LOG:15)
Block(-16,-7,2,LOG:15)
Block(-15,-7,2,LOG:15)
Block(-14,-7,2,LOG:15)
Block(5,-7,2,LOG:15)
Block(8,-7,2,LOG:15)
Block(-15,-7,3,LOG:15)
Block(-11,-7,3,LOG:15)
Block(-10,-7,3,LOG:15)
Block(-3,-7,3,LOG:15)
Block(-1,-7,3,LOG:15)
Block(2,-7,3,LOG:15)
Block(5,-7,4,LOG:15)
Block(-13,-7,5,LOG:15)
Block(-5,-7,5,LOG:15)
Block(0,-7,5,LOG:15)
Block(8,-7,5,LOG:15)
Block(-14,-7,6,LOG:15)
Block(-13,-7,6,LOG:15)
Block(-12,-7,6,LOG:15)
Block(-13,-7,7,LOG:15)
Block(8,-7,7,LOG:15)
Block(11,-7,7,LOG:15)
Block(-13,-7,8,LOG:15)
Block(-5,-7,8,LOG:15)
Block(0,-7,8,LOG:15)
Block(2,-7,8,LOG:15)
Block(10,-7,8,LOG:15)
Block(11,-7,8,LOG:15)
Block(4,-7,9,LOG:15)
Block(5,-7,9,LOG:15)
Block(10,-7,9,LOG:15)
Block(11,-7,9,LOG:15)
Block(12,-7,9,LOG:15)
Block(-9,-7,10,LOG:15)
Block(-4,-7,10,LOG:15)
Block(0,-7,10,LOG:15)
Block(3,-7,10,LOG:15)
Block(4,-7,10,LOG:15)
Block(5,-7,10,LOG:15)
Block(6,-7,10,LOG:15)
Block(11,-7,10,LOG:15)
Block(-11,-7,11,LOG:15)
Block(-10,-7,11,LOG:15)
Block(-9,-7,11,LOG:15)
Block(-8,-7,11,LOG:15)
Block(-5,-7,11,LOG:15)
Block(-4,-7,11,LOG:15)
Block(-3,-7,11,LOG:15)
Block(4,-7,11,LOG:15)
Block(5,-7,11,LOG:15)
Block(-9,-7,12,LOG:15)
Block(-4,-7,12,LOG:15)
Block(-1,-7,12,LOG:15)
Block(3,-7,12,LOG:15)
Block(3,-7,13,LOG:15)
Block(3,-6,-12,LOG:15)
Block(-14,-6,-11,LOG:15)
Block(-2,-6,-11,LOG:15)
Block(2,-6,-11,LOG:15)
Block(3,-6,-11,LOG:15)
Block(4,-6,-11,LOG:15)
Block(-14,-6,-10,LOG:15)
Block(-3,-6,-10,LOG:15)
Block(-2,-6,-10,LOG:15)
Block(-1,-6,-10,LOG:15)
Block(1,-6,-10,LOG:15)
Block(2,-6,-10,LOG:15)
Block(3,-6,-10,LOG:15)
Block(4,-6,-10,LOG:15)
Block(-15,-6,-9,LOG:15)
Block(-14,-6,-9,LOG:15)
Block(-13,-6,-9,LOG:15)
Block(-7,-6,-9,LOG:15)
Block(-6,-6,-9,LOG:15)
Block(-3,-6,-9,LOG:15)
Block(-2,-6,-9,LOG:15)
Block(-1,-6,-9,LOG:15)
Block(0,-6,-9,LOG:15)
Block(2,-6,-9,LOG:15)
Block(3,-6,-9,LOG:15)
Block(8,-6,-9,LOG:15)
Block(-14,-6,-8,LOG:15)
Block(-13,-6,-8,LOG:15)
Block(-8,-6,-8,LOG:15)
Block(-7,-6,-8,LOG:15)
Block(-6,-6,-8,LOG:15)
Block(-5,-6,-8,LOG:15)
Block(-2,-6,-8,LOG:15)
Block(7,-6,-8,LOG:15)
Block(8,-6,-8,LOG:15)
Block(9,-6,-8,LOG:15)
Block(-14,-6,-7,LOG:15)
Block(-7,-6,-7,LOG:15)
Block(-6,-6,-7,LOG:15)
Block(-5,-6,-7,LOG:15)
Block(0,-6,-7,LOG:15)
Block(5,-6,-7,LOG:15)
Block(7,-6,-7,LOG:15)
Block(8,-6,-7,LOG:15)
Block(9,-6,-7,LOG:15)
Block(8,-6,-6,LOG:15)
Block(-11,-6,-5,LOG:15)
Block(-8,-6,-5,LOG:15)
Block(-4,-6,-5,LOG:15)
Block(4,-6,-5,LOG:15)
Block(-13,-6,-4,LOG:15)
Block(-2,-6,-4,LOG:15)
Block(8,-6,-4,LOG:15)
Block(-5,-6,-3,LOG:15)
Block(3,-6,-3,LOG:15)
Block(5,-6,-3,LOG:15)
Block(7,-6,-3,LOG:15)
Block(8,-6,-3,LOG:15)
Block(9,-6,-3,LOG:15)
Block(10,-6,-3,LOG:15)
Block(-15,-6,-2,LOG:15)
Block(-14,-6,-2,LOG:15)
Block(-3,-6,-2,LOG:15)
Block(9,-6,-2,LOG:15)
Block(10,-6,-2,LOG:15)
Block(11,-6,-2,LOG:15)
Block(-16,-6,-1,LOG:15)
Block(-15,-6,-1,LOG:15)
Block(-14,-6,-1,LOG:15)
Block(-5,-6,-1,LOG:15)
Block(8,-6,-1,LOG:15)
Block(10,-6,-1,LOG:15)
Block(-15,-6,0,LOG:15)
Block(3,-6,0,LOG:15)
Block(-15,-6,1,LOG:15)
Block(-11,-6,1,LOG:15)
Block(-8,-6,1,LOG:15)
Block(-2,-6,1,LOG:15)
Block(1,-6,1,LOG:15)
Block(-15,-6,2,LOG:15)
Block(-6,-6,2,LOG:15)
Block(5,-6,2,LOG:15)
Block(8,-6,2,LOG:15)
Block(-11,-6,3,LOG:15)
Block(-3,-6,3,LOG:15)
Block(-1,-6,3,LOG:15)
Block(2,-6,3,LOG:15)
Block(5,-6,4,LOG:15)
Block(-13,-6,5,LOG:15)
Block(-12,-6,5,LOG:15)
Block(-5,-6,5,LOG:15)
Block(0,-6,5,LOG:15)
Block(8,-6,5,LOG:15)
Block(-14,-6,6,LOG:15)
Block(-13,-6,6,LOG:15)
Block(-12,-6,6,LOG:15)
Block(-11,-6,6,LOG:15)
Block(-13,-6,7,LOG:15)
Block(-12,-6,7,LOG:15)
Block(8,-6,7,LOG:15)
Block(9,-6,7,LOG:15)
Block(10,-6,7,LOG:15)
Block(11,-6,7,LOG:15)
Block(-5,-6,8,LOG:15)
Block(0,-6,8,LOG:15)
Block(2,-6,8,LOG:15)
Block(9,-6,8,LOG:15)
Block(10,-6,8,LOG:15)
Block(11,-6,8,LOG:15)
Block(-4,-6,9,LOG:15)
Block(4,-6,9,LOG:15)
Block(9,-6,9,LOG:15)
Block(10,-6,9,LOG:15)
Block(11,-6,9,LOG:15)
Block(12,-6,9,LOG:15)
Block(-9,-6,10,LOG:15)
Block(-5,-6,10,LOG:15)
Block(-4,-6,10,LOG:15)
Block(-3,-6,10,LOG:15)
Block(0,-6,10,LOG:15)
Block(3,-6,10,LOG:15)
Block(4,-6,10,LOG:15)
Block(5,-6,10,LOG:15)
Block(10,-6,10,LOG:15)
Block(11,-6,10,LOG:15)
Block(-10,-6,11,LOG:15)
Block(-9,-6,11,LOG:15)
Block(-8,-6,11,LOG:15)
Block(-5,-6,11,LOG:15)
Block(-4,-6,11,LOG:15)
Block(-3,-6,11,LOG:15)
Block(-2,-6,11,LOG:15)
Block(4,-6,11,LOG:15)
Block(-9,-6,12,LOG:15)
Block(-4,-6,12,LOG:15)
Block(-3,-6,12,LOG:15)
Block(-1,-6,12,LOG:15)
Block(3,-6,12,LOG:15)
Block(2,-5,-11,LOG:15)
Block(3,-5,-11,LOG:15)
Block(-14,-5,-10,LOG:15)
Block(-2,-5,-10,LOG:15)
Block(-1,-5,-10,LOG:15)
Block(1,-5,-10,LOG:15)
Block(2,-5,-10,LOG:15)
Block(3,-5,-10,LOG:15)
Block(-15,-5,-9,LOG:15)
Block(-14,-5,-9,LOG:15)
Block(-13,-5,-9,LOG:15)
Block(-6,-5,-9,LOG:15)
Block(-5,-5,-9,LOG:15)
Block(-3,-5,-9,LOG:15)
Block(-2,-5,-9,LOG:15)
Block(-1,-5,-9,LOG:15)
Block(0,-5,-9,LOG:15)
Block(2,-5,-9,LOG:15)
Block(-15,-5,-8,LOG:15)
Block(-14,-5,-8,LOG:15)
Block(-13,-5,-8,LOG:15)
Block(-12,-5,-8,LOG:15)
Block(-7,-5,-8,LOG:15)
Block(-6,-5,-8,LOG:15)
Block(-5,-5,-8,LOG:15)
Block(-4,-5,-8,LOG:15)
Block(-2,-5,-8,LOG:15)
Block(-1,-5,-8,LOG:15)
Block(7,-5,-8,LOG:15)
Block(8,-5,-8,LOG:15)
Block(-14,-5,-7,LOG:15)
Block(-13,-5,-7,LOG:15)
Block(-6,-5,-7,LOG:15)
Block(-5,-5,-7,LOG:15)
Block(0,-5,-7,LOG:15)
Block(5,-5,-7,LOG:15)
Block(6,-5,-7,LOG:15)
Block(7,-5,-7,LOG:15)
Block(8,-5,-7,LOG:15)
Block(9,-5,-7,LOG:15)
Block(-12,-5,-6,LOG:15)
Block(-9,-5,-6,LOG:15)
Block(7,-5,-6,LOG:15)
Block(8,-5,-6,LOG:15)
Block(-11,-5,-5,LOG:15)
Block(-9,-5,-5,LOG:15)
Block(-8,-5,-5,LOG:15)
Block(-7,-5,-5,LOG:15)
Block(-4,-5,-5,LOG:15)
Block(-2,-5,-5,LOG:15)
Block(4,-5,-5,LOG:15)
Block(-13,-5,-4,LOG:15)
Block(-12,-5,-4,LOG:15)
Block(-7,-5,-4,LOG:15)
Block(-6,-5,-4,LOG:15)
Block(-3,-5,-4,LOG:15)
Block(-2,-5,-4,LOG:15)
Block(-1,-5,-4,LOG:15)
Block(7,-5,-4,LOG:15)
Block(8,-5,-4,LOG:15)
Block(9,-5,-4,LOG:15)
Block(10,-5,-4,LOG:15)
Block(-15,-5,-3,LOG:15)
Block(-14,-5,-3,LOG:15)
Block(-13,-5,-3,LOG:15)
Block(-5,-5,-3,LOG:15)
Block(-4,-5,-3,LOG:15)
Block(-2,-5,-3,LOG:15)
Block(3,-5,-3,LOG:15)
Block(5,-5,-3,LOG:15)
Block(6,-5,-3,LOG:15)
Block(7,-5,-3,LOG:15)
Block(8,-5,-3,LOG:15)
Block(9,-5,-3,LOG:15)
Block(10,-5,-3,LOG:15)
Block(11,-5,-3,LOG:15)
Block(-16,-5,-2,LOG:15)
Block(-15,-5,-2,LOG:15)
Block(-14,-5,-2,LOG:15)
Block(-13,-5,-2,LOG:15)
Block(-3,-5,-2,LOG:15)
Block(7,-5,-2,LOG:15)
Block(8,-5,-2,LOG:15)
Block(9,-5,-2,LOG:15)
Block(10,-5,-2,LOG:15)
Block(11,-5,-2,LOG:15)
Block(-16,-5,-1,LOG:15)
Block(-15,-5,-1,LOG:15)
Block(-14,-5,-1,LOG:15)
Block(-5,-5,-1,LOG:15)
Block(-2,-5,-1,LOG:15)
Block(8,-5,-1,LOG:15)
Block(10,-5,-1,LOG:15)
Block(-15,-5,0,LOG:15)
Block(-2,-5,0,LOG:15)
Block(3,-5,0,LOG:15)
Block(-11,-5,1,LOG:15)
Block(-8,-5,1,LOG:15)
Block(-2,-5,1,LOG:15)
Block(1,-5,1,LOG:15)
Block(-6,-5,2,LOG:15)
Block(5,-5,2,LOG:15)
Block(8,-5,2,LOG:15)
Block(-11,-5,3,LOG:15)
Block(-3,-5,3,LOG:15)
Block(-1,-5,3,LOG:15)
Block(2,-5,3,LOG:15)
Block(5,-5,3,LOG:15)
Block(-12,-5,4,LOG:15)
Block(-11,-5,4,LOG:15)
Block(5,-5,4,LOG:15)
Block(-13,-5,5,LOG:15)
Block(-12,-5,5,LOG:15)
Block(-5,-5,5,LOG:15)
Block(0,-5,5,LOG:15)
Block(8,-5,5,LOG:15)
Block(-14,-5,6,LOG:15)
Block(-13,-5,6,LOG:15)
Block(-12,-5,6,LOG:15)
Block(-11,-5,6,LOG:15)
Block(8,-5,6,LOG:15)
Block(9,-5,6,LOG:15)
Block(-13,-5,7,LOG:15)
Block(-12,-5,7,LOG:15)
Block(0,-5,7,LOG:15)
Block(1,-5,7,LOG:15)
Block(8,-5,7,LOG:15)
Block(9,-5,7,LOG:15)
Block(10,-5,7,LOG:15)
Block(-5,-5,8,LOG:15)
Block(0,-5,8,LOG:15)
Block(1,-5,8,LOG:15)
Block(2,-5,8,LOG:15)
Block(8,-5,8,LOG:15)
Block(9,-5,8,LOG:15)
Block(10,-5,8,LOG:15)
Block(11,-5,8,LOG:15)
Block(0,-5,9,LOG:15)
Block(1,-5,9,LOG:15)
Block(2,-5,9,LOG:15)
Block(4,-5,9,LOG:15)
Block(9,-5,9,LOG:15)
Block(10,-5,9,LOG:15)
Block(11,-5,9,LOG:15)
Block(-9,-5,10,LOG:15)
Block(-8,-5,10,LOG:15)
Block(-4,-5,10,LOG:15)
Block(-3,-5,10,LOG:15)
Block(-2,-5,10,LOG:15)
Block(0,-5,10,LOG:15)
Block(2,-5,10,LOG:15)
Block(3,-5,10,LOG:15)
Block(4,-5,10,LOG:15)
Block(5,-5,10,LOG:15)
Block(-10,-5,11,LOG:15)
Block(-9,-5,11,LOG:15)
Block(-8,-5,11,LOG:15)
Block(-7,-5,11,LOG:15)
Block(-4,-5,11,LOG:15)
Block(-3,-5,11,LOG:15)
Block(-2,-5,11,LOG:15)
Block(-1,-5,11,LOG:15)
Block(3,-5,11,LOG:15)
Block(4,-5,11,LOG:15)
Block(5,-5,11,LOG:15)
Block(-9,-5,12,LOG:15)
Block(-8,-5,12,LOG:15)
Block(-3,-5,12,LOG:15)
Block(-2,-5,12,LOG:15)
Block(-1,-5,12,LOG:15)
Block(3,-5,12,LOG:15)
Block(2,-4,-11,LOG:15)
Block(-1,-4,-10,LOG:15)
Block(1,-4,-10,LOG:15)
Block(2,-4,-10,LOG:15)
Block(3,-4,-10,LOG:15)
Block(-14,-4,-9,LOG:15)
Block(-13,-4,-9,LOG:15)
Block(-5,-4,-9,LOG:15)
Block(-2,-4,-9,LOG:15)
Block(-1,-4,-9,LOG:15)
Block(0,-4,-9,LOG:15)
Block(1,-4,-9,LOG:15)
Block(2,-4,-9,LOG:15)
Block(3,-4,-9,LOG:15)
Block(-14,-4,-8,LOG:15)
Block(-13,-4,-8,LOG:15)
Block(-12,-4,-8,LOG:15)
Block(-6,-4,-8,LOG:15)
Block(-5,-4,-8,LOG:15)
Block(-4,-4,-8,LOG:15)
Block(-2,-4,-8,LOG:15)
Block(-1,-4,-8,LOG:15)
Block(0,-4,-8,LOG:15)
Block(2,-4,-8,LOG:15)
Block(7,-4,-8,LOG:15)
Block(-13,-4,-7,LOG:15)
Block(-12,-4,-7,LOG:15)
Block(-9,-4,-7,LOG:15)
Block(-5,-4,-7,LOG:15)
Block(-2,-4,-7,LOG:15)
Block(-1,-4,-7,LOG:15)
Block(0,-4,-7,LOG:15)
Block(5,-4,-7,LOG:15)
Block(6,-4,-7,LOG:15)
Block(7,-4,-7,LOG:15)
Block(8,-4,-7,LOG:15)
Block(-13,-4,-6,LOG:15)
Block(-12,-4,-6,LOG:15)
Block(-11,-4,-6,LOG:15)
Block(-10,-4,-6,LOG:15)
Block(-9,-4,-6,LOG:15)
Block(-8,-4,-6,LOG:15)
Block(-7,-4,-6,LOG:15)
Block(-2,-4,-6,LOG:15)
Block(6,-4,-6,LOG:15)
Block(7,-4,-6,LOG:15)
Block(8,-4,-6,LOG:15)
Block(-13,-4,-5,LOG:15)
Block(-12,-4,-5,LOG:15)
Block(-11,-4,-5,LOG:15)
Block(-10,-4,-5,LOG:15)
Block(-9,-4,-5,LOG:15)
Block(-8,-4,-5,LOG:15)
Block(-7,-4,-5,LOG:15)
Block(-6,-4,-5,LOG:15)
Block(-4,-4,-5,LOG:15)
Block(-3,-4,-5,LOG:15)
Block(-2,-4,-5,LOG:15)
Block(4,-4,-5,LOG:15)
Block(7,-4,-5,LOG:15)
Block(-14,-4,-4,LOG:15)
Block(-13,-4,-4,LOG:15)
Block(-12,-4,-4,LOG:15)
Block(-11,-4,-4,LOG:15)
Block(-9,-4,-4,LOG:15)
Block(-8,-4,-4,LOG:15)
Block(-7,-4,-4,LOG:15)
Block(-6,-4,-4,LOG:15)
Block(-5,-4,-4,LOG:15)
Block(-4,-4,-4,LOG:15)
Block(-3,-4,-4,LOG:15)
Block(-2,-4,-4,LOG:15)
Block(-1,-4,-4,LOG:15)
Block(3,-4,-4,LOG:15)
Block(6,-4,-4,LOG:15)
Block(7,-4,-4,LOG:15)
Block(-15,-4,-3,LOG:15)
Block(-14,-4,-3,LOG:15)
Block(-13,-4,-3,LOG:15)
Block(-12,-4,-3,LOG:15)
Block(-7,-4,-3,LOG:15)
Block(-6,-4,-3,LOG:15)
Block(-5,-4,-3,LOG:15)
Block(-4,-4,-3,LOG:15)
Block(-3,-4,-3,LOG:15)
Block(-2,-4,-3,LOG:15)
Block(1,-4,-3,LOG:15)
Block(2,-4,-3,LOG:15)
Block(3,-4,-3,LOG:15)
Block(4,-4,-3,LOG:15)
Block(5,-4,-3,LOG:15)
Block(6,-4,-3,LOG:15)
Block(7,-4,-3,LOG:15)
Block(8,-4,-3,LOG:15)
Block(9,-4,-3,LOG:15)
Block(10,-4,-3,LOG:15)
Block(-15,-4,-2,LOG:15)
Block(-14,-4,-2,LOG:15)
Block(-13,-4,-2,LOG:15)
Block(-5,-4,-2,LOG:15)
Block(-4,-4,-2,LOG:15)
Block(-3,-4,-2,LOG:15)
Block(-2,-4,-2,LOG:15)
Block(-1,-4,-2,LOG:15)
Block(0,-4,-2,LOG:15)
Block(3,-4,-2,LOG:15)
Block(6,-4,-2,LOG:15)
Block(7,-4,-2,LOG:15)
Block(10,-4,-2,LOG:15)
Block(-15,-4,-1,LOG:15)
Block(-14,-4,-1,LOG:15)
Block(-5,-4,-1,LOG:15)
Block(-3,-4,-1,LOG:15)
Block(-2,-4,-1,LOG:15)
Block(-1,-4,-1,LOG:15)
Block(0,-4,-1,LOG:15)
Block(-3,-4,0,LOG:15)
Block(-2,-4,0,LOG:15)
Block(-1,-4,0,LOG:15)
Block(3,-4,0,LOG:15)
Block(-11,-4,1,LOG:15)
Block(-9,-4,1,LOG:15)
Block(-8,-4,1,LOG:15)
Block(-4,-4,1,LOG:15)
Block(-2,-4,1,LOG:15)
Block(1,-4,1,LOG:15)
Block(5,-4,1,LOG:15)
Block(-9,-4,2,LOG:15)
Block(-6,-4,2,LOG:15)
Block(-4,-4,2,LOG:15)
Block(4,-4,2,LOG:15)
Block(5,-4,2,LOG:15)
Block(6,-4,2,LOG:15)
Block(8,-4,2,LOG:15)
Block(-12,-4,3,LOG:15)
Block(-11,-4,3,LOG:15)
Block(-3,-4,3,LOG:15)
Block(-1,-4,3,LOG:15)
Block(2,-4,3,LOG:15)
Block(4,-4,3,LOG:15)
Block(5,-4,3,LOG:15)
Block(6,-4,3,LOG:15)
Block(-13,-4,4,LOG:15)
Block(-12,-4,4,LOG:15)
Block(-11,-4,4,LOG:15)
Block(-10,-4,4,LOG:15)
Block(-4,-4,4,LOG:15)
Block(5,-4,4,LOG:15)
Block(7,-4,4,LOG:15)
Block(8,-4,4,LOG:15)
Block(-13,-4,5,LOG:15)
Block(-12,-4,5,LOG:15)
Block(-11,-4,5,LOG:15)
Block(-5,-4,5,LOG:15)
Block(-4,-4,5,LOG:15)
Block(0,-4,5,LOG:15)
Block(7,-4,5,LOG:15)
Block(8,-4,5,LOG:15)
Block(9,-4,5,LOG:15)
Block(-13,-4,6,LOG:15)
Block(-12,-4,6,LOG:15)
Block(-11,-4,6,LOG:15)
Block(-4,-4,6,LOG:15)
Block(0,-4,6,LOG:15)
Block(1,-4,6,LOG:15)
Block(7,-4,6,LOG:15)
Block(8,-4,6,LOG:15)
Block(9,-4,6,LOG:15)
Block(10,-4,6,LOG:15)
Block(-12,-4,7,LOG:15)
Block(-5,-4,7,LOG:15)
Block(-4,-4,7,LOG:15)
Block(-1,-4,7,LOG:15)
Block(0,-4,7,LOG:15)
Block(1,-4,7,LOG:15)
Block(2,-4,7,LOG:15)
Block(8,-4,7,LOG:15)
Block(9,-4,7,LOG:15)
Block(10,-4,7,LOG:15)
Block(-6,-4,8,LOG:15)
Block(-5,-4,8,LOG:15)
Block(-1,-4,8,LOG:15)
Block(0,-4,8,LOG:15)
Block(1,-4,8,LOG:15)
Block(2,-4,8,LOG:15)
Block(9,-4,8,LOG:15)
Block(10,-4,8,LOG:15)
Block(-6,-4,9,LOG:15)
Block(-1,-4,9,LOG:15)
Block(0,-4,9,LOG:15)
Block(1,-4,9,LOG:15)
Block(2,-4,9,LOG:15)
Block(3,-4,9,LOG:15)
Block(4,-4,9,LOG:15)
Block(10,-4,9,LOG:15)
Block(-8,-4,10,LOG:15)
Block(-7,-4,10,LOG:15)
Block(-2,-4,10,LOG:15)
Block(-1,-4,10,LOG:15)
Block(0,-4,10,LOG:15)
Block(1,-4,10,LOG:15)
Block(2,-4,10,LOG:15)
Block(3,-4,10,LOG:15)
Block(4,-4,10,LOG:15)
Block(5,-4,10,LOG:15)
Block(-9,-4,11,LOG:15)
Block(-8,-4,11,LOG:15)
Block(-7,-4,11,LOG:15)
Block(-3,-4,11,LOG:15)
Block(-2,-4,11,LOG:15)
Block(-1,-4,11,LOG:15)
Block(0,-4,11,LOG:15)
Block(2,-4,11,LOG:15)
Block(3,-4,11,LOG:15)
Block(4,-4,11,LOG:15)
Block(-8,-4,12,LOG:15)
Block(-2,-4,12,LOG:15)
Block(-1,-4,12,LOG:15)
Block(1,-3,-10,LOG:15)
Block(2,-3,-10,LOG:15)
Block(-5,-3,-9,LOG:15)
Block(-1,-3,-9,LOG:15)
Block(0,-3,-9,LOG:15)
Block(1,-3,-9,LOG:15)
Block(2,-3,-9,LOG:15)
Block(3,-3,-9,LOG:15)
Block(-13,-3,-8,LOG:15)
Block(-12,-3,-8,LOG:15)
Block(-6,-3,-8,LOG:15)
Block(-5,-3,-8,LOG:15)
Block(-4,-3,-8,LOG:15)
Block(-2,-3,-8,LOG:15)
Block(-1,-3,-8,LOG:15)
Block(0,-3,-8,LOG:15)
Block(1,-3,-8,LOG:15)
Block(2,-3,-8,LOG:15)
Block(-14,-3,-7,LOG:15)
Block(-13,-3,-7,LOG:15)
Block(-12,-3,-7,LOG:15)
Block(-11,-3,-7,LOG:15)
Block(-9,-3,-7,LOG:15)
Block(-5,-3,-7,LOG:15)
Block(-4,-3,-7,LOG:15)
Block(-3,-3,-7,LOG:15)
Block(-2,-3,-7,LOG:15)
Block(-1,-3,-7,LOG:15)
Block(0,-3,-7,LOG:15)
Block(6,-3,-7,LOG:15)
Block(7,-3,-7,LOG:15)
Block(-13,-3,-6,LOG:15)
Block(-12,-3,-6,LOG:15)
Block(-11,-3,-6,LOG:15)
Block(-10,-3,-6,LOG:15)
Block(-9,-3,-6,LOG:15)
Block(-8,-3,-6,LOG:15)
Block(-4,-3,-6,LOG:15)
Block(-3,-3,-6,LOG:15)
Block(-2,-3,-6,LOG:15)
Block(-1,-3,-6,LOG:15)
Block(5,-3,-6,LOG:15)
Block(6,-3,-6,LOG:15)
Block(7,-3,-6,LOG:15)
Block(8,-3,-6,LOG:15)
Block(-12,-3,-5,LOG:15)
Block(-11,-3,-5,LOG:15)
Block(-10,-3,-5,LOG:15)
Block(-9,-3,-5,LOG:15)
Block(-8,-3,-5,LOG:15)
Block(-7,-3,-5,LOG:15)
Block(-5,-3,-5,LOG:15)
Block(-4,-3,-5,LOG:15)
Block(-3,-3,-5,LOG:15)
Block(-2,-3,-5,LOG:15)
Block(-1,-3,-5,LOG:15)
Block(0,-3,-5,LOG:15)
Block(4,-3,-5,LOG:15)
Block(5,-3,-5,LOG:15)
Block(6,-3,-5,LOG:15)
Block(7,-3,-5,LOG:15)
Block(-13,-3,-4,LOG:15)
Block(-12,-3,-4,LOG:15)
Block(-11,-3,-4,LOG:15)
Block(-8,-3,-4,LOG:15)
Block(-7,-3,-4,LOG:15)
Block(-6,-3,-4,LOG:15)
Block(-5,-3,-4,LOG:15)
Block(-4,-3,-4,LOG:15)
Block(-3,-3,-4,LOG:15)
Block(-2,-3,-4,LOG:15)
Block(-1,-3,-4,LOG:15)
Block(0,-3,-4,LOG:15)
Block(1,-3,-4,LOG:15)
Block(3,-3,-4,LOG:15)
Block(5,-3,-4,LOG:15)
Block(6,-3,-4,LOG:15)
Block(7,-3,-4,LOG:15)
Block(-14,-3,-3,LOG:15)
Block(-13,-3,-3,LOG:15)
Block(-12,-3,-3,LOG:15)
Block(-11,-3,-3,LOG:15)
Block(-7,-3,-3,LOG:15)
Block(-6,-3,-3,LOG:15)
Block(-5,-3,-3,LOG:15)
Block(-4,-3,-3,LOG:15)
Block(-3,-3,-3,LOG:15)
Block(-2,-3,-3,LOG:15)
Block(-1,-3,-3,LOG:15)
Block(0,-3,-3,LOG:15)
Block(1,-3,-3,LOG:15)
Block(2,-3,-3,LOG:15)
Block(3,-3,-3,LOG:15)
Block(4,-3,-3,LOG:15)
Block(5,-3,-3,LOG:15)
Block(6,-3,-3,LOG:15)
Block(7,-3,-3,LOG:15)
Block(8,-3,-3,LOG:15)
Block(-15,-3,-2,LOG:15)
Block(-14,-3,-2,LOG:15)
Block(-13,-3,-2,LOG:15)
Block(-6,-3,-2,LOG:15)
Block(-5,-3,-2,LOG:15)
Block(-4,-3,-2,LOG:15)
Block(-3,-3,-2,LOG:15)
Block(-2,-3,-2,LOG:15)
Block(-1,-3,-2,LOG:15)
Block(0,-3,-2,LOG:15)
Block(1,-3,-2,LOG:15)
Block(3,-3,-2,LOG:15)
Block(6,-3,-2,LOG:15)
Block(7,-3,-2,LOG:15)
Block(-15,-3,-1,LOG:15)
Block(-14,-3,-1,LOG:15)
Block(-7,-3,-1,LOG:15)
Block(-6,-3,-1,LOG:15)
Block(-5,-3,-1,LOG:15)
Block(-4,-3,-1,LOG:15)
Block(-3,-3,-1,LOG:15)
Block(-2,-3,-1,LOG:15)
Block(-1,-3,-1,LOG:15)
Block(0,-3,-1,LOG:15)
Block(1,-3,-1,LOG:15)
Block(-15,-3,0,LOG:15)
Block(-9,-3,0,LOG:15)
Block(-6,-3,0,LOG:15)
Block(-5,-3,0,LOG:15)
Block(-3,-3,0,LOG:15)
Block(-2,-3,0,LOG:15)
Block(-1,-3,0,LOG:15)
Block(0,-3,0,LOG:15)
Block(1,-3,0,LOG:15)
Block(3,-3,0,LOG:15)
Block(4,-3,0,LOG:15)
Block(-14,-3,1,LOG:15)
Block(-13,-3,1,LOG:15)
Block(-12,-3,1,LOG:15)
Block(-11,-3,1,LOG:15)
Block(-10,-3,1,LOG:15)
Block(-9,-3,1,LOG:15)
Block(-8,-3,1,LOG:15)
Block(-7,-3,1,LOG:15)
Block(-6,-3,1,LOG:15)
Block(-5,-3,1,LOG:15)
Block(-4,-3,1,LOG:15)
Block(-3,-3,1,LOG:15)
Block(-2,-3,1,LOG:15)
Block(-1,-3,1,LOG:15)
Block(0,-3,1,LOG:15)
Block(1,-3,1,LOG:15)
Block(2,-3,1,LOG:15)
Block(4,-3,1,LOG:15)
Block(5,-3,1,LOG:15)
Block(-12,-3,2,LOG:15)
Block(-11,-3,2,LOG:15)
Block(-10,-3,2,LOG:15)
Block(-9,-3,2,LOG:15)
Block(-8,-3,2,LOG:15)
Block(-7,-3,2,LOG:15)
Block(-6,-3,2,LOG:15)
Block(-5,-3,2,LOG:15)
Block(-4,-3,2,LOG:15)
Block(-3,-3,2,LOG:15)
Block(2,-3,2,LOG:15)
Block(3,-3,2,LOG:15)
Block(4,-3,2,LOG:15)
Block(5,-3,2,LOG:15)
Block(6,-3,2,LOG:15)
Block(7,-3,2,LOG:15)
Block(8,-3,2,LOG:15)
Block(-11,-3,3,LOG:15)
Block(-10,-3,3,LOG:15)
Block(-9,-3,3,LOG:15)
Block(-4,-3,3,LOG:15)
Block(-3,-3,3,LOG:15)
Block(-2,-3,3,LOG:15)
Block(-1,-3,3,LOG:15)
Block(1,-3,3,LOG:15)
Block(2,-3,3,LOG:15)
Block(4,-3,3,LOG:15)
Block(5,-3,3,LOG:15)
Block(6,-3,3,LOG:15)
Block(7,-3,3,LOG:15)
Block(8,-3,3,LOG:15)
Block(-12,-3,4,LOG:15)
Block(-11,-3,4,LOG:15)
Block(-10,-3,4,LOG:15)
Block(-9,-3,4,LOG:15)
Block(-5,-3,4,LOG:15)
Block(-4,-3,4,LOG:15)
Block(-3,-3,4,LOG:15)
Block(-1,-3,4,LOG:15)
Block(0,-3,4,LOG:15)
Block(6,-3,4,LOG:15)
Block(7,-3,4,LOG:15)
Block(8,-3,4,LOG:15)
Block(-13,-3,5,LOG:15)
Block(-12,-3,5,LOG:15)
Block(-11,-3,5,LOG:15)
Block(-5,-3,5,LOG:15)
Block(-4,-3,5,LOG:15)
Block(-3,-3,5,LOG:15)
Block(-1,-3,5,LOG:15)
Block(0,-3,5,LOG:15)
Block(1,-3,5,LOG:15)
Block(6,-3,5,LOG:15)
Block(7,-3,5,LOG:15)
Block(8,-3,5,LOG:15)
Block(9,-3,5,LOG:15)
Block(-11,-3,6,LOG:15)
Block(-6,-3,6,LOG:15)
Block(-5,-3,6,LOG:15)
Block(-4,-3,6,LOG:15)
Block(-3,-3,6,LOG:15)
Block(-1,-3,6,LOG:15)
Block(0,-3,6,LOG:15)
Block(1,-3,6,LOG:15)
Block(7,-3,6,LOG:15)
Block(8,-3,6,LOG:15)
Block(9,-3,6,LOG:15)
Block(-6,-3,7,LOG:15)
Block(-5,-3,7,LOG:15)
Block(-4,-3,7,LOG:15)
Block(-3,-3,7,LOG:15)
Block(-1,-3,7,LOG:15)
Block(0,-3,7,LOG:15)
Block(1,-3,7,LOG:15)
Block(8,-3,7,LOG:15)
Block(9,-3,7,LOG:15)
Block(10,-3,7,LOG:15)
Block(-8,-3,8,LOG:15)
Block(-7,-3,8,LOG:15)
Block(-6,-3,8,LOG:15)
Block(-5,-3,8,LOG:15)
Block(-4,-3,8,LOG:15)
Block(-3,-3,8,LOG:15)
Block(-1,-3,8,LOG:15)
Block(0,-3,8,LOG:15)
Block(1,-3,8,LOG:15)
Block(2,-3,8,LOG:15)
Block(3,-3,8,LOG:15)
Block(9,-3,8,LOG:15)
Block(10,-3,8,LOG:15)
Block(-8,-3,9,LOG:15)
Block(-7,-3,9,LOG:15)
Block(-6,-3,9,LOG:15)
Block(-5,-3,9,LOG:15)
Block(0,-3,9,LOG:15)
Block(1,-3,9,LOG:15)
Block(2,-3,9,LOG:15)
Block(3,-3,9,LOG:15)
Block(9,-3,9,LOG:15)
Block(-9,-3,10,LOG:15)
Block(-8,-3,10,LOG:15)
Block(-7,-3,10,LOG:15)
Block(-6,-3,10,LOG:15)
Block(-1,-3,10,LOG:15)
Block(0,-3,10,LOG:15)
Block(2,-3,10,LOG:15)
Block(3,-3,10,LOG:15)
Block(4,-3,10,LOG:15)
Block(-9,-3,11,LOG:15)
Block(-8,-3,11,LOG:15)
Block(-7,-3,11,LOG:15)
Block(0,-3,11,LOG:15)
Block(-8,-3,12,LOG:15)
Block(-5,-2,-9,LOG:15)
Block(1,-2,-9,LOG:15)
Block(2,-2,-9,LOG:15)
Block(-13,-2,-8,LOG:15)
Block(-5,-2,-8,LOG:15)
Block(-4,-2,-8,LOG:15)
Block(-1,-2,-8,LOG:15)
Block(0,-2,-8,LOG:15)
Block(1,-2,-8,LOG:15)
Block(2,-2,-8,LOG:15)
Block(-13,-2,-7,LOG:15)
Block(-4,-2,-7,LOG:15)
Block(-2,-2,-7,LOG:15)
Block(-1,-2,-7,LOG:15)
Block(0,-2,-7,LOG:15)
Block(1,-2,-7,LOG:15)
Block(-12,-2,-6,LOG:15)
Block(-11,-2,-6,LOG:15)
Block(-10,-2,-6,LOG:15)
Block(-9,-2,-6,LOG:15)
Block(-4,-2,-6,LOG:15)
Block(-3,-2,-6,LOG:15)
Block(-2,-2,-6,LOG:15)
Block(-1,-2,-6,LOG:15)
Block(0,-2,-6,LOG:15)
Block(5,-2,-6,LOG:15)
Block(6,-2,-6,LOG:15)
Block(7,-2,-6,LOG:15)
Block(-12,-2,-5,LEAVES:3)
Block(-11,-2,-5,LOG:15)
Block(-9,-2,-5,LOG:15)
Block(-8,-2,-5,LOG:15)
Block(-4,-2,-5,LOG:15)
Block(-3,-2,-5,LOG:15)
Block(-2,-2,-5,LOG:15)
Block(-1,-2,-5,LOG:15)
Block(5,-2,-5,LOG:15)
Block(6,-2,-5,LOG:15)
Block(-12,-2,-4,LOG:15)
Block(-7,-2,-4,LOG:15)
Block(-6,-2,-4,LOG:15)
Block(-5,-2,-4,LOG:15)
Block(-4,-2,-4,LOG:15)
Block(-3,-2,-4,LOG:15)
Block(-2,-2,-4,LOG:15)
Block(-1,-2,-4,LOG:15)
Block(0,-2,-4,LOG:15)
Block(2,-2,-4,LOG:15)
Block(4,-2,-4,LOG:15)
Block(5,-2,-4,LOG:15)
Block(7,-2,-4,LOG:15)
Block(-13,-2,-3,LOG:15)
Block(-12,-2,-3,LOG:15)
Block(-6,-2,-3,LOG:15)
Block(-5,-2,-3,LOG:15)
Block(-4,-2,-3,LOG:15)
Block(-3,-2,-3,LOG:15)
Block(-2,-2,-3,LOG:15)
Block(-1,-2,-3,LOG:15)
Block(0,-2,-3,LOG:15)
Block(1,-2,-3,LOG:15)
Block(2,-2,-3,LOG:15)
Block(3,-2,-3,LOG:15)
Block(4,-2,-3,LOG:15)
Block(6,-2,-3,LOG:15)
Block(7,-2,-3,LOG:15)
Block(-15,-2,-2,LEAVES:3)
Block(-14,-2,-2,LOG:15)
Block(-5,-2,-2,LOG:15)
Block(-4,-2,-2,LOG:15)
Block(-3,-2,-2,LOG:15)
Block(-2,-2,-2,LOG:15)
Block(-1,-2,-2,LOG:15)
Block(0,-2,-2,LOG:15)
Block(1,-2,-2,LOG:15)
Block(-15,-2,-1,LOG:15)
Block(-6,-2,-1,LOG:15)
Block(-5,-2,-1,LOG:15)
Block(-4,-2,-1,LOG:15)
Block(-3,-2,-1,LOG:15)
Block(-2,-2,-1,LOG:15)
Block(-1,-2,-1,LOG:15)
Block(0,-2,-1,LOG:15)
Block(1,-2,-1,LOG:15)
Block(-6,-2,0,LOG:15)
Block(-5,-2,0,LOG:15)
Block(-4,-2,0,LOG:15)
Block(-3,-2,0,LOG:15)
Block(-2,-2,0,LOG:15)
Block(-1,-2,0,LOG:15)
Block(0,-2,0,LOG:15)
Block(1,-2,0,LOG:15)
Block(3,-2,0,LOG:15)
Block(-13,-2,1,LOG:15)
Block(-12,-2,1,LOG:15)
Block(-9,-2,1,LOG:15)
Block(-7,-2,1,LOG:15)
Block(-6,-2,1,LOG:15)
Block(-5,-2,1,LOG:15)
Block(-4,-2,1,LOG:15)
Block(-3,-2,1,LOG:15)
Block(-2,-2,1,LOG:15)
Block(-1,-2,1,LOG:15)
Block(0,-2,1,LOG:15)
Block(1,-2,1,LOG:15)
Block(2,-2,1,LOG:15)
Block(3,-2,1,LOG:15)
Block(-12,-2,2,LOG:15)
Block(-11,-2,2,LOG:15)
Block(-10,-2,2,LOG:15)
Block(-9,-2,2,LOG:15)
Block(-8,-2,2,LOG:15)
Block(-4,-2,2,LEAVES:3)
Block(-3,-2,2,LOG:15)
Block(-2,-2,2,LOG:15)
Block(-1,-2,2,LOG:15)
Block(0,-2,2,LOG:15)
Block(1,-2,2,LOG:15)
Block(2,-2,2,LOG:15)
Block(3,-2,2,LOG:15)
Block(4,-2,2,LOG:15)
Block(5,-2,2,LOG:15)
Block(-10,-2,3,LOG:15)
Block(-9,-2,3,LOG:15)
Block(-3,-2,3,LOG:15)
Block(-1,-2,3,LOG:15)
Block(0,-2,3,LOG:15)
Block(4,-2,3,LOG:15)
Block(5,-2,3,LOG:15)
Block(6,-2,3,LOG:15)
Block(8,-2,3,LOG:15)
Block(-11,-2,4,LOG:15)
Block(-4,-2,4,LOG:15)
Block(-3,-2,4,LOG:15)
Block(0,-2,4,LOG:15)
Block(4,-2,4,LOG:15)
Block(6,-2,4,LOG:15)
Block(7,-2,4,LOG:15)
Block(-4,-2,5,LOG:15)
Block(0,-2,5,LOG:15)
Block(7,-2,5,LOG:15)
Block(8,-2,5,LOG:15)
Block(9,-2,5,LOG:15)
Block(-5,-2,6,LOG:15)
Block(-4,-2,6,LOG:15)
Block(1,-2,6,LOG:15)
Block(7,-2,6,LOG:15)
Block(9,-2,6,LOG:15)
Block(-5,-2,7,LOG:15)
Block(-4,-2,7,LOG:15)
Block(0,-2,7,LOG:15)
Block(1,-2,7,LOG:15)
Block(9,-2,7,LEAVES:3)
Block(10,-2,7,LOG:15)
Block(-6,-2,8,LOG:15)
Block(-5,-2,8,LOG:15)
Block(-4,-2,8,LOG:15)
Block(0,-2,8,LEAVES:3)
Block(1,-2,8,LOG:15)
Block(2,-2,8,LOG:15)
Block(-8,-2,9,LOG:15)
Block(-7,-2,9,LOG:15)
Block(-6,-2,9,LOG:15)
Block(-5,-2,9,LOG:15)
Block(0,-2,9,LEAVES:3)
Block(-7,-2,10,LOG:15)
Block(-6,-2,10,LEAVES:3)
Block(0,-2,10,LOG:15)
Block(2,-2,10,LOG:15)
Block(-8,-2,11,LOG:15)
Block(-7,-2,11,LOG:15)
Block(-5,-1,-9,LOG:15)
Block(2,-1,-9,LOG:15)
Block(-4,-1,-8,LOG:15)
Block(1,-1,-8,LOG:15)
Block(2,-1,-8,LOG:15)
Block(-4,-1,-7,LOG:15)
Block(1,-1,-7,LOG:15)
Block(-12,-1,-6,LEAVES:3)
Block(-11,-1,-6,LEAVES:3)
Block(-10,-1,-6,LEAVES:3)
Block(-5,-1,-6,LEAVES:3)
Block(-4,-1,-6,LOG:15)
Block(-3,-1,-6,LOG:15)
Block(0,-1,-6,LOG:15)
Block(-9,-1,-5,LOG:15)
Block(-8,-1,-5,LOG:15)
Block(-4,-1,-5,LOG:15)
Block(-3,-1,-5,LOG:15)
Block(-2,-1,-5,LOG:15)
Block(-1,-1,-5,LOG:15)
Block(5,-1,-5,LOG:15)
Block(6,-1,-5,LOG:15)
Block(-7,-1,-4,LOG:15)
Block(-6,-1,-4,LOG:15)
Block(-5,-1,-4,LOG:15)
Block(-4,-1,-4,LOG:15)
Block(-3,-1,-4,LOG:15)
Block(-2,-1,-4,LOG:15)
Block(-1,-1,-4,LOG:15)
Block(0,-1,-4,LOG:15)
Block(2,-1,-4,LOG:15)
Block(4,-1,-4,LOG:15)
Block(5,-1,-4,LOG:15)
Block(7,-1,-4,LOG:15)
Block(-12,-1,-3,LEAVES:3)
Block(-6,-1,-3,LOG:15)
Block(-5,-1,-3,LOG:15)
Block(-4,-1,-3,LOG:15)
Block(-3,-1,-3,LOG:15)
Block(-2,-1,-3,LOG:15)
Block(-1,-1,-3,LOG:15)
Block(0,-1,-3,LOG:15)
Block(1,-1,-3,LOG:15)
Block(2,-1,-3,LOG:15)
Block(3,-1,-3,LOG:15)
Block(-5,-1,-2,LOG:15)
Block(-4,-1,-2,LOG:15)
Block(-3,-1,-2,LOG:15)
Block(-2,-1,-2,LOG:15)
Block(-1,-1,-2,LOG:15)
Block(0,-1,-2,LOG:15)
Block(1,-1,-2,LOG:15)
Block(-15,-1,-1,LEAVES:3)
Block(-5,-1,-1,LOG:15)
Block(-4,-1,-1,LOG:15)
Block(-3,-1,-1,LOG:15)
Block(-2,-1,-1,LOG:15)
Block(-1,-1,-1,LOG:15)
Block(0,-1,-1,LOG:15)
Block(1,-1,-1,LOG:15)
Block(-6,-1,0,LOG:15)
Block(-5,-1,0,LOG:15)
Block(-4,-1,0,LOG:15)
Block(-3,-1,0,LOG:15)
Block(-2,-1,0,LOG:15)
Block(-1,-1,0,LOG:15)
Block(0,-1,0,LOG:15)
Block(1,-1,0,LOG:15)
Block(-7,-1,1,LOG:15)
Block(-6,-1,1,LOG:15)
Block(-4,-1,1,LOG:15)
Block(-3,-1,1,LOG:15)
Block(-2,-1,1,LOG:15)
Block(-1,-1,1,LOG:15)
Block(0,-1,1,LOG:15)
Block(1,-1,1,LOG:15)
Block(2,-1,1,LOG:15)
Block(-8,-1,2,LOG:15)
Block(-7,-1,2,LEAVES:3)
Block(-6,-1,2,LEAVES:3)
Block(-3,-1,2,LEAVES:3)
Block(-2,-1,2,LOG:15)
Block(-1,-1,2,LOG:15)
Block(0,-1,2,LOG:15)
Block(1,-1,2,LOG:15)
Block(3,-1,2,LOG:15)
Block(-10,-1,3,LEAVES:3)
Block(-9,-1,3,LOG:15)
Block(-3,-1,3,LOG:15)
Block(-1,-1,3,LOG:15)
Block(4,-1,3,LOG:15)
Block(5,-1,3,LOG:15)
Block(6,-1,3,LOG:15)
Block(-11,-1,4,LEAVES:3)
Block(-4,-1,4,LEAVES:3)
Block(-3,-1,4,LOG:15)
Block(-1,-1,4,LEAVES:3)
Block(0,-1,4,LOG:15)
Block(6,-1,4,LEAVES:3)
Block(7,-1,4,LEAVES:3)
Block(-4,-1,5,LOG:15)
Block(-1,-1,5,LEAVES:3)
Block(0,-1,5,LOG:15)
Block(8,-1,5,LEAVES:3)
Block(-5,-1,6,LOG:15)
Block(-4,-1,6,LOG:15)
Block(1,-1,6,LOG:15)
Block(9,-1,6,LEAVES:3)
Block(-4,-1,7,LEAVES:3)
Block(0,-1,7,LEAVES:3)
Block(1,-1,7,LOG:15)
Block(-4,-1,8,LEAVES:3)
Block(1,-1,8,LEAVES:3)
Block(-5,-1,9,LEAVES:3)
Block(-7,-1,11,LEAVES:3)
Block(-4,0,-8,LEAVES:3)
Block(2,0,-8,LOG:15)
Block(-4,0,-7,LOG:15)
Block(1,0,-7,LOG:15)
Block(-4,0,-6,LOG:15)
Block(-3,0,-6,LOG:15)
Block(0,0,-6,LOG:15)
Block(-8,0,-5,LOG:15)
Block(5,0,-5,LOG:15)
Block(-8,0,-4,LEAVES:3)
Block(-7,0,-4,LOG:15)
Block(-6,0,-4,LOG:15)
Block(-4,0,-4,LEAVES:3)
Block(-3,0,-4,LOG:15)
Block(-1,0,-4,LOG:15)
Block(0,0,-4,LOG:15)
Block(4,0,-4,LOG:15)
Block(-6,0,-3,LOG:15)
Block(-4,0,-3,LOG:15)
Block(-3,0,-3,LOG:15)
Block(-1,0,-3,LOG:15)
Block(0,0,-3,LOG:15)
Block(1,0,-3,LOG:15)
Block(3,0,-3,LOG:15)
Block(-4,0,-2,LOG:15)
Block(-3,0,-2,LOG:15)
Block(0,0,-1,LOG:15)
Block(1,0,-1,LOG:15)
Block(-6,0,0,LEAVES:3)
Block(-4,0,0,LOG:15)
Block(-3,0,0,LOG:15)
Block(-2,0,0,LOG:15)
Block(0,0,0,LOG:15)
Block(1,0,0,LOG:15)
Block(-7,0,1,LOG:15)
Block(-6,0,1,LOG:15)
Block(-4,0,1,LEAVES:3)
Block(-3,0,1,LOG:15)
Block(-2,0,1,LOG:15)
Block(0,0,1,LOG:15)
Block(1,0,1,LOG:15)
Block(-8,0,2,LOG:15)
Block(3,0,2,LOG:15)
Block(-8,0,3,LEAVES:3)
Block(-4,0,3,LEAVES:3)
Block(-3,0,3,LOG:15)
Block(-1,0,3,LOG:15)
Block(4,0,3,LOG:15)
Block(5,0,3,LOG:15)
Block(-3,0,4,LOG:15)
Block(0,0,4,LOG:15)
Block(-4,0,5,LOG:15)
Block(0,0,5,LOG:15)
Block(1,0,7,LEAVES:3)
Block(-4,1,-8,LEAVES:3)
Block(-5,1,-7,LEAVES:3)
Block(-4,1,-7,LOG:15)
Block(0,1,-7,LEAVES:3)
Block(1,1,-7,LEAVES:3)
Block(-5,1,-6,LEAVES:3)
Block(-4,1,-6,LOG:15)
Block(0,1,-6,LOG:15)
Block(-6,1,-5,LEAVES:3)
Block(-4,1,-5,LOG:15)
Block(-3,1,-5,LEAVES:3)
Block(-2,1,-5,LEAVES:3)
Block(-1,1,-5,LOG:15)
Block(-8,1,-4,LEAVES:3)
Block(-7,1,-4,LOG:15)
Block(-6,1,-4,LOG:15)
Block(-4,1,-4,LEAVES:3)
Block(-3,1,-4,LOG:15)
Block(-2,1,-4,LOG:15)
Block(-1,1,-4,LOG:15)
Block(0,1,-4,LOG:15)
Block(4,1,-4,LOG:15)
Block(-6,1,-3,LOG:15)
Block(-5,1,-3,LOG:15)
Block(-4,1,-3,LOG:15)
Block(-3,1,-3,LOG:15)
Block(-2,1,-3,LOG:15)
Block(-1,1,-3,LOG:15)
Block(0,1,-3,LOG:15)
Block(1,1,-3,LOG:15)
Block(2,1,-3,LOG:15)
Block(3,1,-3,LOG:15)
Block(-5,1,-2,LEAVES:3)
Block(-4,1,-2,LOG:15)
Block(-3,1,-2,LOG:15)
Block(-2,1,-2,LOG:15)
Block(-1,1,-2,LOG:15)
Block(0,1,-2,LOG:15)
Block(-4,1,-1,LOG:15)
Block(-3,1,-1,LOG:15)
Block(-2,1,-1,LOG:15)
Block(-1,1,-1,LOG:15)
Block(0,1,-1,LOG:15)
Block(1,1,-1,LOG:15)
Block(-6,1,0,LEAVES:3)
Block(-5,1,0,LOG:15)
Block(-4,1,0,LOG:15)
Block(-3,1,0,LOG:15)
Block(-2,1,0,LOG:15)
Block(-1,1,0,LOG:15)
Block(0,1,0,LOG:15)
Block(1,1,0,LOG:15)
Block(-7,1,1,LOG:15)
Block(-6,1,1,LOG:15)
Block(-5,1,1,LEAVES:3)
Block(-3,1,1,LOG:15)
Block(-2,1,1,LOG:15)
Block(-1,1,1,LOG:15)
Block(0,1,1,LOG:15)
Block(1,1,1,LOG:15)
Block(2,1,1,LOG:15)
Block(-6,1,2,LEAVES:3)
Block(-2,1,2,LOG:15)
Block(-1,1,2,LOG:15)
Block(3,1,2,LOG:15)
Block(4,1,2,LEAVES:3)
Block(-3,1,3,LOG:15)
Block(-2,1,3,LEAVES:3)
Block(-1,1,3,LOG:15)
Block(4,1,3,LEAVES:3)
Block(5,1,3,LEAVES:3)
Block(-4,1,5,LEAVES:3)
Block(-4,2,-6,LOG:15)
Block(0,2,-6,LOG:15)
Block(-4,2,-5,LOG:15)
Block(-3,2,-5,LEAVES:3)
Block(-1,2,-5,LOG:15)
Block(-6,2,-4,LOG:15)
Block(-5,2,-4,LEAVES:3)
Block(-4,2,-4,LEAVES:3)
Block(-3,2,-4,LOG:15)
Block(-2,2,-4,LOG:15)
Block(-1,2,-4,LOG:15)
Block(0,2,-4,LOG:15)
Block(-7,2,-3,LEAVES:3)
Block(-6,2,-3,LOG:15)
Block(-5,2,-3,LOG:15)
Block(-4,2,-3,LOG:15)
Block(-3,2,-3,LOG:15)
Block(-2,2,-3,LOG:15)
Block(-1,2,-3,LOG:15)
Block(0,2,-3,LOG:15)
Block(1,2,-3,LOG:15)
Block(2,2,-3,LOG:15)
Block(3,2,-3,LOG:15)
Block(-3,2,-2,LOG:15)
Block(-2,2,-2,LOG:15)
Block(-1,2,-2,LOG:15)
Block(0,2,-2,LOG:15)
Block(-4,2,-1,LOG:15)
Block(-3,2,-1,LOG:15)
Block(-2,2,-1,LOG:15)
Block(-1,2,-1,LOG:15)
Block(0,2,-1,LOG:15)
Block(1,2,-1,LOG:15)
Block(-7,2,0,LEAVES:3)
Block(-6,2,0,LEAVES:3)
Block(-5,2,0,LOG:15)
Block(-4,2,0,LOG:15)
Block(-3,2,0,LOG:15)
Block(-2,2,0,LOG:15)
Block(-1,2,0,LOG:15)
Block(0,2,0,LOG:15)
Block(-7,2,1,LEAVES:3)
Block(-6,2,1,LOG:15)
Block(-5,2,1,LEAVES:3)
Block(-4,2,1,LEAVES:3)
Block(-3,2,1,LOG:15)
Block(-2,2,1,LOG:15)
Block(-1,2,1,LOG:15)
Block(0,2,1,LOG:15)
Block(1,2,1,LOG:15)
Block(2,2,1,LEAVES:3)
Block(-7,2,2,LEAVES:3)
Block(-6,2,2,LEAVES:3)
Block(-5,2,2,LEAVES:3)
Block(-3,2,2,LEAVES:3)
Block(-2,2,2,LOG:15)
Block(-1,2,2,LOG:15)
Block(2,2,2,LEAVES:3)
Block(-3,2,3,LOG:15)
Block(-1,2,3,LOG:15)
Block(0,3,-6,LEAVES:3)
Block(-5,3,-5,LEAVES:3)
Block(-4,3,-5,LOG:15)
Block(-2,3,-5,LEAVES:3)
Block(-1,3,-5,LOG:15)
Block(0,3,-5,LEAVES:3)
Block(-3,3,-4,LOG:15)
Block(-2,3,-4,LOG:15)
Block(-1,3,-4,LOG:15)
Block(0,3,-4,LOG:15)
Block(-7,3,-3,LEAVES:3)
Block(-6,3,-3,LOG:15)
Block(-5,3,-3,LOG:15)
Block(-4,3,-3,LOG:15)
Block(-3,3,-3,LOG:15)
Block(-2,3,-3,LOG:15)
Block(-1,3,-3,LOG:15)
Block(0,3,-3,LOG:15)
Block(1,3,-3,LOG:15)
Block(2,3,-3,LOG:15)
Block(-6,3,-2,LEAVES:3)
Block(-5,3,-2,LEAVES:3)
Block(-3,3,-2,LOG:15)
Block(-2,3,-2,LOG:15)
Block(-1,3,-2,LOG:15)
Block(0,3,-2,LOG:15)
Block(1,3,-2,LEAVES:3)
Block(-4,3,-1,LOG:15)
Block(-3,3,-1,LOG:15)
Block(-2,3,-1,LOG:15)
Block(-1,3,-1,LOG:15)
Block(0,3,-1,LOG:15)
Block(1,3,-1,LOG:15)
Block(2,3,-1,LEAVES:3)
Block(-6,3,0,LEAVES:3)
Block(-5,3,0,LOG:15)
Block(-4,3,0,LOG:15)
Block(-3,3,0,LOG:15)
Block(-2,3,0,LOG:15)
Block(-1,3,0,LOG:15)
Block(0,3,0,LOG:15)
Block(1,3,0,LEAVES:3)
Block(-7,3,1,LEAVES:3)
Block(-6,3,1,LEAVES:3)
Block(-5,3,1,LEAVES:3)
Block(-4,3,1,LEAVES:3)
Block(-3,3,1,LOG:15)
Block(-2,3,1,LOG:15)
Block(-1,3,1,LOG:15)
Block(0,3,1,LOG:15)
Block(-6,3,2,LEAVES:3)
Block(-4,3,2,LEAVES:3)
Block(-3,3,2,LEAVES:3)
Block(-2,3,2,LOG:15)
Block(-1,3,2,LOG:15)
Block(-4,4,-6,LEAVES:3)
Block(-4,4,-5,LOG:15)
Block(-3,4,-5,LEAVES:3)
Block(-2,4,-5,LEAVES:3)
Block(-1,4,-5,LOG:15)
Block(-3,4,-4,LOG:15)
Block(-2,4,-4,LOG:15)
Block(-1,4,-4,LOG:15)
Block(0,4,-4,LOG:15)
Block(-4,4,-3,LOG:15)
Block(-3,4,-3,LOG:15)
Block(-2,4,-3,LOG:15)
Block(-1,4,-3,LOG:15)
Block(0,4,-3,LOG:15)
Block(1,4,-3,LOG:15)
Block(2,4,-3,LOG:15)
Block(-3,4,-2,LOG:15)
Block(-2,4,-2,LOG:15)
Block(-1,4,-2,LOG:15)
Block(0,4,-2,LOG:15)
Block(1,4,-2,LEAVES:3)
Block(2,4,-2,LEAVES:3)
Block(-5,4,-1,LEAVES:3)
Block(-4,4,-1,LOG:15)
Block(-3,4,-1,LOG:15)
Block(-2,4,-1,LOG:15)
Block(-1,4,-1,LOG:15)
Block(0,4,-1,LOG:15)
Block(1,4,-1,LOG:15)
Block(2,4,-1,LEAVES:3)
Block(-5,4,0,LOG:15)
Block(-4,4,0,LOG:15)
Block(-3,4,0,LOG:15)
Block(-2,4,0,LOG:15)
Block(-1,4,0,LOG:15)
Block(0,4,0,LOG:15)
Block(1,4,0,LEAVES:3)
Block(2,4,0,LEAVES:3)
Block(-4,4,1,LEAVES:3)
Block(-3,4,1,LOG:15)
Block(-2,4,1,LOG:15)
Block(-1,4,1,LOG:15)
Block(0,4,1,LOG:15)
Block(-3,4,2,LEAVES:3)
Block(-2,4,2,LOG:15)
Block(-1,4,2,LOG:15)
Block(-2,5,-5,LEAVES:3)
Block(-1,5,-5,LOG:15)
Block(-3,5,-4,LOG:15)
Block(-2,5,-4,LOG:15)
Block(-1,5,-4,LOG:15)
Block(0,5,-4,LOG:15)
Block(-4,5,-3,LOG:15)
Block(-3,5,-3,LOG:15)
Block(-2,5,-3,LOG:15)
Block(-1,5,-3,LOG:15)
Block(0,5,-3,LOG:15)
Block(1,5,-3,LOG:15)
Block(2,5,-3,LOG:15)
Block(-3,5,-2,LOG:15)
Block(-2,5,-2,LOG:15)
Block(-1,5,-2,LOG:15)
Block(0,5,-2,LOG:15)
Block(1,5,-2,LEAVES:3)
Block(-5,5,-1,LEAVES:3)
Block(-4,5,-1,LOG:15)
Block(-3,5,-1,LOG:15)
Block(-2,5,-1,LOG:15)
Block(-1,5,-1,LOG:15)
Block(0,5,-1,LOG:15)
Block(1,5,-1,LEAVES:3)
Block(2,5,-1,LEAVES:3)
Block(-4,5,0,LOG:15)
Block(-3,5,0,LOG:15)
Block(-2,5,0,LOG:15)
Block(-1,5,0,LOG:15)
Block(0,5,0,LOG:15)
Block(1,5,0,LEAVES:3)
Block(-3,5,1,LOG:15)
Block(-2,5,1,LOG:15)
Block(-1,5,1,LOG:15)
Block(-2,5,2,LOG:15)
Block(-3,6,-5,LEAVES:3)
Block(-2,6,-5,LEAVES:3)
Block(-1,6,-5,LEAVES:3)
Block(-3,6,-4,LEAVES:3)
Block(-2,6,-4,LOG:15)
Block(-1,6,-4,LOG:15)
Block(-3,6,-3,LOG:15)
Block(-2,6,-3,LOG:15)
Block(-1,6,-3,LOG:15)
Block(0,6,-3,LOG:15)
Block(1,6,-3,LOG:15)
Block(-3,6,-2,LOG:15)
Block(-2,6,-2,LOG:15)
Block(-1,6,-2,LOG:15)
Block(0,6,-2,LOG:15)
Block(1,6,-2,LEAVES:3)
Block(-4,6,-1,LOG:15)
Block(-3,6,-1,LOG:15)
Block(-2,6,-1,LOG:15)
Block(-1,6,-1,LOG:15)
Block(0,6,-1,LOG:15)
Block(1,6,-1,LEAVES:3)
Block(-3,6,0,LOG:15)
Block(-2,6,0,LOG:15)
Block(-1,6,0,LOG:15)
Block(-3,6,1,LEAVES:3)
Block(-2,6,1,LOG:15)
Block(-1,6,1,LEAVES:3)
Block(-3,6,2,LEAVES:3)
Block(-2,6,2,LEAVES:3)
Block(-1,6,2,LEAVES:3)
Block(-2,7,-5,LEAVES:3)
Block(-3,7,-4,LEAVES:3)
Block(-2,7,-4,LEAVES:3)
Block(-1,7,-4,LOG:15)
Block(-3,7,-3,LOG:15)
Block(-2,7,-3,LOG:15)
Block(-1,7,-3,LOG:15)
Block(0,7,-3,LOG:15)
Block(1,7,-3,LOG:15)
Block(-2,7,-2,LOG:15)
Block(-1,7,-2,LOG:15)
Block(0,7,-2,LOG:15)
Block(-4,7,-1,LOG:15)
Block(-3,7,-1,LOG:15)
Block(-2,7,-1,LOG:15)
Block(-1,7,-1,LOG:15)
Block(0,7,-1,LOG:15)
Block(-3,7,0,LOG:15)
Block(-2,7,0,LOG:15)
Block(-1,7,0,LOG:15)
Block(-3,7,1,LEAVES:3)
Block(-2,7,1,LOG:15)
Block(-1,7,1,LEAVES:3)
Block(-2,7,2,LEAVES:3)
Block(-2,8,-4,LEAVES:3)
Block(-1,8,-4,LOG:15)
Block(-3,8,-3,LOG:15)
Block(-2,8,-3,LOG:15)
Block(-1,8,-3,LOG:15)
Block(0,8,-3,LOG:15)
Block(-2,8,-2,LOG:15)
Block(-1,8,-2,LOG:15)
Block(0,8,-2,LOG:15)
Block(-3,8,-1,LOG:15)
Block(-2,8,-1,LOG:15)
Block(-1,8,-1,LOG:15)
Block(-3,8,0,LEAVES:3)
Block(-2,8,0,LOG:15)
Block(-1,8,0,LOG:15)
Block(-2,8,1,LOG:15)
Block(-3,9,-4,LEAVES:3)
Block(-2,9,-4,LEAVES:3)
Block(-1,9,-4,LOG:15)
Block(-3,9,-3,LOG:15)
Block(-2,9,-3,LOG:15)
Block(-1,9,-3,LOG:15)
Block(0,9,-3,LOG:15)
Block(-2,9,-2,LOG:15)
Block(-1,9,-2,LOG:15)
Block(-3,9,-1,LOG:15)
Block(-2,9,-1,LOG:15)
Block(-1,9,-1,LOG:15)
Block(-3,9,0,LEAVES:3)
Block(-2,9,0,LOG:15)
Block(-2,9,1,LOG:15)
Block(-2,10,-4,LEAVES:3)
Block(-1,10,-4,LOG:15)
Block(-3,10,-3,LEAVES:3)
Block(-2,10,-3,LOG:15)
Block(-1,10,-3,LOG:15)
Block(0,10,-3,LOG:15)
Block(-2,10,-2,LOG:15)
Block(-1,10,-2,LOG:15)
Block(-3,10,-1,LOG:15)
Block(-2,10,-1,LOG:15)
Block(-1,10,-1,LOG:15)
Block(-2,10,0,LOG:15)
Block(-1,11,-4,LOG:15)
Block(-2,11,-3,LOG:15)
Block(-1,11,-3,LOG:15)
Block(0,11,-3,LOG:15)
Block(-2,11,-2,LOG:15)
Block(-1,11,-2,LOG:15)
Block(-3,11,-1,LOG:15)
Block(-2,11,-1,LOG:15)
Block(-1,11,-1,LOG:15)
Block(-2,11,0,LOG:15)
Block(-2,12,-3,LOG:15)
Block(-1,12,-3,LOG:15)
Block(0,12,-3,LOG:15)
Block(-2,12,-2,LOG:15)
Block(-1,12,-2,LOG:15)
Block(-2,12,-1,LOG:15)
Block(-1,12,-1,LOG:15)
Block(-2,13,-3,LOG:15)
Block(-1,13,-3,LOG:15)
Block(-3,13,-2,LOG:15)
Block(-2,13,-2,LOG:15)
Block(-1,13,-2,LOG:15)
Block(-2,13,-1,LOG:15)
Block(-2,14,-3,LOG:15)
Block(-1,14,-3,LOG:15)
Block(-3,14,-2,LOG:15)
Block(-2,14,-2,LOG:15)
Block(-1,14,-2,LOG:15)
Block(-2,14,-1,LOG:15)
Block(-2,15,-4,LOG:15)
Block(-2,15,-3,LOG:15)
Block(-1,15,-3,LOG:15)
Block(-3,15,-2,LOG:15)
Block(-2,15,-2,LOG:15)
Block(-1,15,-2,LOG:15)
Block(-2,15,-1,LOG:15)
Block(-2,16,-4,LOG:15)
Block(-2,16,-3,LOG:15)
Block(-1,16,-3,LOG:15)
Block(0,16,-3,LOG:15)
Block(-3,16,-2,LOG:15)
Block(-2,16,-2,LOG:15)
Block(-1,16,-2,LOG:15)
Block(-2,16,-1,LOG:15)
Block(-2,17,-4,LOG:15)
Block(-2,17,-3,LOG:15)
Block(-1,17,-3,LOG:15)
Block(0,17,-3,LOG:15)
Block(-3,17,-2,LOG:15)
Block(-2,17,-2,LOG:15)
Block(-1,17,-2,LOG:15)
Block(-2,17,-1,LOG:15)
Block(-1,17,-1,LOG:15)
Block(-3,17,0,LOG:15)
Block(-2,18,-4,LOG:15)
Block(-2,18,-3,LOG:15)
Block(-1,18,-3,LOG:15)
Block(0,18,-3,LOG:15)
Block(-3,18,-2,LOG:15)
Block(-2,18,-2,LOG:15)
Block(-1,18,-2,LOG:15)
Block(-2,18,-1,LOG:15)
Block(-1,18,-1,LOG:15)
Block(-3,18,0,LOG:15)
Block(-2,18,0,LOG:15)
Block(-1,19,-14,LEAVES:3)
Block(-2,19,-4,LOG:15)
Block(-1,19,-4,LOG:15)
Block(-3,19,-3,LOG:15)
Block(-2,19,-3,LOG:15)
Block(-1,19,-3,LOG:15)
Block(0,19,-3,LOG:15)
Block(1,19,-3,LOG:15)
Block(4,19,-3,LEAVES:3)
Block(-3,19,-2,LOG:15)
Block(-2,19,-2,LOG:15)
Block(-1,19,-2,LOG:15)
Block(0,19,-2,LOG:15)
Block(-2,19,-1,LOG:15)
Block(-1,19,-1,LOG:15)
Block(-3,19,0,LOG:15)
Block(-2,19,0,LOG:15)
Block(-1,19,0,LOG:15)
Block(-1,19,6,LEAVES:3)
Block(-1,20,-14,LEAVES:3)
Block(-2,20,-4,LOG:15)
Block(-1,20,-4,LOG:15)
Block(0,20,-4,LOG:15)
Block(-3,20,-3,LOG:15)
Block(-2,20,-3,LOG:15)
Block(-1,20,-3,LOG:15)
Block(0,20,-3,LOG:15)
Block(1,20,-3,LOG:15)
Block(4,20,-3,LEAVES:3)
Block(-3,20,-2,LOG:15)
Block(-2,20,-2,LOG:15)
Block(-1,20,-2,LOG:15)
Block(0,20,-2,LOG:15)
Block(-3,20,-1,LOG:15)
Block(-2,20,-1,LOG:15)
Block(-1,20,-1,LOG:15)
Block(0,20,-1,LOG:15)
Block(-3,20,0,LOG:15)
Block(-2,20,0,LOG:15)
Block(-1,20,0,LOG:15)
Block(-2,20,1,LOG:15)
Block(-1,20,1,LOG:15)
Block(10,20,1,LEAVES:3)
Block(-1,20,6,LEAVES:3)
Block(-3,20,8,LEAVES:11)
Block(4,20,9,LEAVES:3)
Block(-1,21,-14,LEAVES:3)
Block(-2,21,-4,LOG:15)
Block(-1,21,-4,LOG:15)
Block(0,21,-4,LOG:15)
Block(-2,21,-3,LOG:15)
Block(-1,21,-3,LOG:15)
Block(0,21,-3,LOG:15)
Block(4,21,-3,LEAVES:3)
Block(-3,21,-2,LOG:15)
Block(-2,21,-2,LOG:15)
Block(-1,21,-2,LOG:15)
Block(0,21,-2,LOG:15)
Block(-3,21,-1,LOG:15)
Block(-2,21,-1,LOG:15)
Block(-1,21,-1,LOG:15)
Block(0,21,-1,LOG:15)
Block(7,21,-1,LEAVES:3)
Block(-3,21,0,LOG:15)
Block(-2,21,0,LOG:15)
Block(-1,21,0,LOG:15)
Block(-2,21,1,LOG:15)
Block(-1,21,1,LOG:15)
Block(10,21,1,LEAVES:3)
Block(10,21,3,LEAVES:3)
Block(-1,21,6,LEAVES:3)
Block(-3,21,8,LEAVES:3)
Block(4,21,9,LEAVES:3)
Block(-1,22,-14,LEAVES:3)
Block(-2,22,-11,LEAVES:3)
Block(-4,22,-9,LEAVES:3)
Block(-12,22,-5,LEAVES:3)
Block(7,22,-5,LEAVES:3)
Block(9,22,-5,LEAVES:3)
Block(-2,22,-4,LOG:15)
Block(0,22,-4,LOG:15)
Block(-3,22,-3,LOG:15)
Block(-2,22,-3,LOG:15)
Block(0,22,-3,LOG:15)
Block(4,22,-3,LEAVES:3)
Block(-10,22,-2,LEAVES:3)
Block(-3,22,-2,LOG:15)
Block(-2,22,-2,LOG:15)
Block(-1,22,-2,LOG:15)
Block(0,22,-2,LOG:15)
Block(-4,22,-1,LOG:15)
Block(-3,22,-1,LOG:15)
Block(-2,22,-1,LOG:15)
Block(-1,22,-1,LOG:15)
Block(0,22,-1,LOG:15)
Block(7,22,-1,LEAVES:3)
Block(-3,22,0,LOG:15)
Block(-2,22,0,LOG:15)
Block(-1,22,0,LOG:15)
Block(0,22,0,LOG:15)
Block(-8,22,1,LEAVES:3)
Block(-3,22,1,LOG:15)
Block(-2,22,1,LOG:15)
Block(-1,22,1,LOG:15)
Block(10,22,1,LEAVES:3)
Block(-11,22,2,LEAVES:3)
Block(-1,22,2,LOG:15)
Block(0,22,2,LOG:15)
Block(1,22,2,LOG:15)
Block(10,22,3,LEAVES:3)
Block(-1,22,6,LEAVES:3)
Block(-3,22,8,LEAVES:3)
Block(4,22,9,LEAVES:3)
Block(-1,23,-14,LEAVES:3)
Block(-2,23,-11,LEAVES:3)
Block(-8,23,-9,LEAVES:3)
Block(-4,23,-9,LEAVES:3)
Block(-14,23,-8,LEAVES:3)
Block(-12,23,-5,LEAVES:3)
Block(7,23,-5,LEAVES:3)
Block(9,23,-5,LEAVES:3)
Block(-11,23,-4,LEAVES:3)
Block(-3,23,-4,LOG:15)
Block(-2,23,-4,LOG:15)
Block(1,23,-4,LOG:15)
Block(4,23,-4,LEAVES:3)
Block(-3,23,-3,LOG:15)
Block(0,23,-3,LOG:15)
Block(1,23,-3,LOG:15)
Block(3,23,-3,LEAVES:3)
Block(4,23,-3,LEAVES:3)
Block(5,23,-3,LEAVES:3)
Block(-10,23,-2,LEAVES:3)
Block(-2,23,-2,LOG:15)
Block(0,23,-2,LOG:15)
Block(4,23,-2,LEAVES:3)
Block(-5,23,-1,LOG:15)
Block(-4,23,-1,LOG:15)
Block(0,23,-1,LOG:15)
Block(7,23,-1,LEAVES:3)
Block(0,23,0,LOG:15)
Block(1,23,0,LOG:15)
Block(-8,23,1,LEAVES:3)
Block(-3,23,1,LOG:15)
Block(-1,23,1,LOG:15)
Block(10,23,1,LEAVES:3)
Block(-11,23,2,LEAVES:3)
Block(-1,23,2,LOG:15)
Block(0,23,2,LOG:15)
Block(0,23,3,LOG:15)
Block(1,23,3,LOG:15)
Block(10,23,3,LEAVES:3)
Block(-1,23,4,LOG:15)
Block(0,23,4,LOG:15)
Block(1,23,4,LOG:15)
Block(-7,23,5,LEAVES:11)
Block(-1,23,5,LOG:15)
Block(-2,23,6,LEAVES:3)
Block(-1,23,6,LOG:15)
Block(0,23,6,LEAVES:3)
Block(-3,23,7,LEAVES:3)
Block(-2,23,7,LEAVES:3)
Block(-1,23,7,LEAVES:3)
Block(2,23,7,LEAVES:3)
Block(-4,23,8,LEAVES:3)
Block(-3,23,8,LEAVES:3)
Block(-2,23,8,LEAVES:3)
Block(-5,23,9,LEAVES:3)
Block(-4,23,9,LEAVES:3)
Block(-3,23,9,LEAVES:3)
Block(4,23,9,LEAVES:3)
Block(-4,23,10,LEAVES:3)
Block(-1,24,-15,LEAVES:3)
Block(-2,24,-14,LEAVES:3)
Block(-1,24,-14,LEAVES:3)
Block(0,24,-14,LEAVES:3)
Block(-1,24,-13,LEAVES:3)
Block(-2,24,-11,LEAVES:3)
Block(-8,24,-9,LEAVES:11)
Block(-4,24,-9,LEAVES:3)
Block(-14,24,-8,LEAVES:3)
Block(-12,24,-5,LEAVES:3)
Block(-3,24,-5,LOG:15)
Block(7,24,-5,LEAVES:3)
Block(9,24,-5,LEAVES:3)
Block(-11,24,-4,LEAVES:3)
Block(-4,24,-4,LOG:15)
Block(-3,24,-4,LOG:15)
Block(1,24,-4,LOG:15)
Block(3,24,-4,LEAVES:3)
Block(4,24,-4,LEAVES:3)
Block(5,24,-4,LEAVES:3)
Block(-4,24,-3,LOG:15)
Block(-3,24,-3,LOG:15)
Block(0,24,-3,LOG:15)
Block(1,24,-3,LOG:15)
Block(2,24,-3,LOG:15)
Block(3,24,-3,LOG:15)
Block(4,24,-3,LOG:15)
Block(5,24,-3,LEAVES:3)
Block(-10,24,-2,LEAVES:3)
Block(3,24,-2,LEAVES:3)
Block(4,24,-2,LEAVES:3)
Block(5,24,-2,LEAVES:3)
Block(-8,24,-1,LEAVES:3)
Block(-5,24,-1,LOG:15)
Block(-4,24,-1,LOG:15)
Block(7,24,-1,LEAVES:3)
Block(-9,24,0,LEAVES:3)
Block(-8,24,0,LEAVES:3)
Block(-7,24,0,LEAVES:3)
Block(-6,24,0,LOG:15)
Block(-5,24,0,LOG:15)
Block(1,24,0,LOG:15)
Block(-10,24,1,LEAVES:3)
Block(-9,24,1,LEAVES:3)
Block(-8,24,1,LEAVES:3)
Block(-3,24,1,LOG:15)
Block(1,24,1,LOG:15)
Block(10,24,1,LEAVES:3)
Block(-11,24,2,LEAVES:3)
Block(-9,24,2,LEAVES:3)
Block(9,24,2,LEAVES:3)
Block(10,24,2,LEAVES:3)
Block(11,24,2,LEAVES:3)
Block(10,24,3,LEAVES:3)
Block(1,24,4,LOG:15)
Block(-7,24,5,LEAVES:3)
Block(-3,24,5,LEAVES:15)
Block(-2,24,5,LEAVES:3)
Block(-1,24,5,LOG:15)
Block(1,24,5,LOG:15)
Block(2,24,5,LOG:15)
Block(-3,24,6,LEAVES:3)
Block(-2,24,6,LOG:15)
Block(-1,24,6,LOG:15)
Block(0,24,6,LEAVES:15)
Block(1,24,6,LOG:15)
Block(2,24,6,LOG:15)
Block(3,24,6,LEAVES:3)
Block(-4,24,7,LEAVES:3)
Block(-3,24,7,LEAVES:3)
Block(-2,24,7,LOG:15)
Block(-1,24,7,LEAVES:3)
Block(1,24,7,LOG:15)
Block(2,24,7,LOG:15)
Block(3,24,7,LEAVES:3)
Block(-5,24,8,LEAVES:3)
Block(-4,24,8,LEAVES:3)
Block(-3,24,8,LEAVES:11)
Block(-2,24,8,LEAVES:3)
Block(-1,24,8,LEAVES:3)
Block(0,24,8,LEAVES:15)
Block(2,24,8,LEAVES:3)
Block(3,24,8,LEAVES:3)
Block(4,24,8,LEAVES:3)
Block(-6,24,9,LEAVES:15)
Block(-5,24,9,LEAVES:3)
Block(-4,24,9,LEAVES:3)
Block(-3,24,9,LEAVES:3)
Block(-2,24,9,LEAVES:3)
Block(3,24,9,LEAVES:3)
Block(4,24,9,LEAVES:3)
Block(5,24,9,LEAVES:3)
Block(-7,24,10,LEAVES:15)
Block(-6,24,10,LEAVES:15)
Block(-5,24,10,LEAVES:3)
Block(-4,24,10,LEAVES:3)
Block(-3,24,10,LEAVES:3)
Block(4,24,10,LEAVES:3)
Block(-2,25,-15,LEAVES:3)
Block(-1,25,-15,LEAVES:3)
Block(0,25,-15,LEAVES:3)
Block(-2,25,-14,LEAVES:3)
Block(-1,25,-14,LEAVES:3)
Block(0,25,-14,LEAVES:3)
Block(1,25,-14,LEAVES:3)
Block(-2,25,-13,LEAVES:3)
Block(-1,25,-13,LEAVES:3)
Block(0,25,-13,LEAVES:3)
Block(-2,25,-11,LEAVES:3)
Block(-8,25,-9,LEAVES:3)
Block(-4,25,-9,LEAVES:3)
Block(0,25,-9,LEAVES:15)
Block(3,25,-9,LEAVES:15)
Block(-14,25,-8,LEAVES:3)
Block(3,25,-8,LEAVES:15)
Block(4,25,-8,LEAVES:15)
Block(5,25,-8,LEAVES:15)
Block(3,25,-7,LEAVES:15)
Block(-14,25,-6,LEAVES:3)
Block(-3,25,-6,LOG:15)
Block(-2,25,-6,LOG:15)
Block(4,25,-6,LEAVES:15)
Block(5,25,-6,LEAVES:15)
Block(-12,25,-5,LEAVES:3)
Block(-11,25,-5,LEAVES:3)
Block(-5,25,-5,LOG:15)
Block(-3,25,-5,LOG:15)
Block(5,25,-5,LEAVES:15)
Block(7,25,-5,LEAVES:3)
Block(9,25,-5,LEAVES:3)
Block(-12,25,-4,LEAVES:3)
Block(-11,25,-4,LEAVES:3)
Block(-10,25,-4,LEAVES:3)
Block(-5,25,-4,LOG:15)
Block(-4,25,-4,LOG:15)
Block(-3,25,-4,LEAVES:3)
Block(1,25,-4,LOG:15)
Block(2,25,-4,LOG:15)
Block(3,25,-4,LEAVES:3)
Block(4,25,-4,LEAVES:3)
Block(5,25,-4,LEAVES:3)
Block(-11,25,-3,LEAVES:3)
Block(-10,25,-3,LEAVES:3)
Block(-9,25,-3,LEAVES:3)
Block(-3,25,-3,LOG:15)
Block(1,25,-3,LOG:15)
Block(3,25,-3,LOG:15)
Block(4,25,-3,LOG:15)
Block(5,25,-3,LOG:15)
Block(6,25,-3,LEAVES:3)
Block(-10,25,-2,LEAVES:3)
Block(-9,25,-2,LEAVES:15)
Block(-8,25,-2,LOG:15)
Block(3,25,-2,LEAVES:3)
Block(4,25,-2,LEAVES:3)
Block(5,25,-2,LEAVES:3)
Block(8,25,-2,LEAVES:3)
Block(-9,25,-1,LEAVES:3)
Block(-8,25,-1,LOG:15)
Block(-7,25,-1,LOG:15)
Block(7,25,-1,LEAVES:3)
Block(8,25,-1,LEAVES:3)
Block(9,25,-1,LEAVES:3)
Block(-10,25,0,LEAVES:3)
Block(-9,25,0,LEAVES:3)
Block(-8,25,0,LOG:15)
Block(-7,25,0,LOG:15)
Block(-6,25,0,LOG:15)
Block(-5,25,0,LOG:15)
Block(-1,25,0,LEAVES:15)
Block(0,25,0,LEAVES:3)
Block(1,25,0,LOG:15)
Block(8,25,0,LEAVES:3)
Block(9,25,0,LEAVES:3)
Block(-10,25,1,LEAVES:3)
Block(-9,25,1,LEAVES:3)
Block(-8,25,1,LOG:15)
Block(-7,25,1,LEAVES:3)
Block(-6,25,1,LEAVES:15)
Block(-3,25,1,LOG:15)
Block(1,25,1,LOG:15)
Block(8,25,1,LEAVES:3)
Block(9,25,1,LEAVES:3)
Block(10,25,1,LEAVES:3)
Block(11,25,1,LEAVES:3)
Block(-11,25,2,LEAVES:3)
Block(-10,25,2,LEAVES:3)
Block(-9,25,2,LEAVES:3)
Block(-8,25,2,LEAVES:3)
Block(-7,25,2,LEAVES:15)
Block(-6,25,2,LEAVES:15)
Block(9,25,2,LEAVES:3)
Block(10,25,2,LOG:15)
Block(11,25,2,LEAVES:3)
Block(-8,25,3,LEAVES:15)
Block(-6,25,3,LEAVES:15)
Block(5,25,3,LEAVES:15)
Block(6,25,3,LEAVES:15)
Block(9,25,3,LEAVES:3)
Block(10,25,3,LEAVES:3)
Block(11,25,3,LEAVES:3)
Block(9,25,4,LEAVES:15)
Block(-7,25,5,LEAVES:3)
Block(-3,25,5,LEAVES:15)
Block(-2,25,5,LEAVES:15)
Block(-1,25,5,LEAVES:15)
Block(-3,25,6,LEAVES:15)
Block(-2,25,6,LEAVES:3)
Block(-1,25,6,LEAVES:15)
Block(0,25,6,LEAVES:15)
Block(1,25,6,LEAVES:3)
Block(2,25,6,LOG:15)
Block(3,25,6,LEAVES:3)
Block(-3,25,7,LOG:15)
Block(-2,25,7,LOG:15)
Block(-1,25,7,LEAVES:3)
Block(0,25,7,LEAVES:15)
Block(1,25,7,LOG:15)
Block(2,25,7,LOG:15)
Block(3,25,7,LEAVES:3)
Block(4,25,7,LEAVES:3)
Block(-6,25,8,LEAVES:15)
Block(-5,25,8,LOG:15)
Block(-4,25,8,LOG:15)
Block(-3,25,8,LOG:15)
Block(-2,25,8,LEAVES:3)
Block(-1,25,8,LEAVES:15)
Block(0,25,8,LEAVES:15)
Block(1,25,8,LEAVES:15)
Block(2,25,8,LOG:15)
Block(3,25,8,LOG:15)
Block(4,25,8,LEAVES:3)
Block(5,25,8,LEAVES:3)
Block(-7,25,9,LEAVES:15)
Block(-6,25,9,LEAVES:15)
Block(-5,25,9,LOG:15)
Block(-4,25,9,LEAVES:3)
Block(-3,25,9,LEAVES:3)
Block(-1,25,9,LEAVES:15)
Block(0,25,9,LEAVES:15)
Block(1,25,9,LEAVES:15)
Block(2,25,9,LEAVES:3)
Block(3,25,9,LEAVES:3)
Block(4,25,9,LEAVES:3)
Block(5,25,9,LEAVES:3)
Block(-7,25,10,LEAVES:15)
Block(-6,25,10,LEAVES:15)
Block(-5,25,10,LEAVES:15)
Block(-4,25,10,LEAVES:3)
Block(-3,25,10,LEAVES:15)
Block(-1,25,10,LEAVES:15)
Block(0,25,10,LEAVES:15)
Block(1,25,10,LEAVES:15)
Block(2,25,10,LEAVES:15)
Block(3,25,10,LEAVES:3)
Block(4,25,10,LEAVES:3)
Block(5,25,10,LEAVES:3)
Block(6,25,10,LEAVES:15)
Block(-6,25,11,LEAVES:15)
Block(-5,25,11,LEAVES:15)
Block(-4,25,11,LEAVES:15)
Block(-3,25,11,LEAVES:15)
Block(2,25,11,LEAVES:15)
Block(6,25,11,LEAVES:15)
Block(-3,25,12,LEAVES:15)
Block(-2,25,12,LEAVES:15)
Block(-2,25,13,LEAVES:15)
Block(-1,25,13,LEAVES:15)
Block(-2,26,-15,LEAVES:3)
Block(-1,26,-15,LEAVES:3)
Block(0,26,-15,LEAVES:3)
Block(1,26,-15,LEAVES:3)
Block(-2,26,-14,LEAVES:3)
Block(-1,26,-14,LOG:15)
Block(0,26,-14,LOG:15)
Block(1,26,-14,LEAVES:3)
Block(-12,26,-13,LEAVES:15)
Block(-2,26,-13,LEAVES:3)
Block(-1,26,-13,LEAVES:3)
Block(0,26,-13,LEAVES:3)
Block(1,26,-13,LEAVES:3)
Block(-12,26,-12,LEAVES:15)
Block(-5,26,-12,LEAVES:15)
Block(2,26,-12,LEAVES:15)
Block(-2,26,-11,LEAVES:3)
Block(-8,26,-10,LEAVES:3)
Block(0,26,-10,LEAVES:15)
Block(1,26,-10,LEAVES:15)
Block(3,26,-10,LEAVES:15)
Block(4,26,-10,LEAVES:15)
Block(-9,26,-9,LEAVES:3)
Block(-8,26,-9,LEAVES:3)
Block(-7,26,-9,LEAVES:3)
Block(-6,26,-9,LEAVES:3)
Block(-4,26,-9,LEAVES:3)
Block(-1,26,-9,LEAVES:15)
Block(0,26,-9,LEAVES:15)
Block(1,26,-9,LEAVES:15)
Block(2,26,-9,LEAVES:15)
Block(3,26,-9,LEAVES:15)
Block(4,26,-9,LEAVES:15)
Block(5,26,-9,LEAVES:15)
Block(6,26,-9,LEAVES:15)
Block(-14,26,-8,LEAVES:3)
Block(-10,26,-8,LEAVES:15)
Block(-9,26,-8,LEAVES:15)
Block(-8,26,-8,LEAVES:3)
Block(-7,26,-8,LEAVES:3)
Block(-6,26,-8,LEAVES:3)
Block(-5,26,-8,LEAVES:3)
Block(-2,26,-8,LEAVES:3)
Block(-1,26,-8,LEAVES:3)
Block(0,26,-8,LEAVES:3)
Block(1,26,-8,LEAVES:15)
Block(2,26,-8,LEAVES:15)
Block(3,26,-8,LEAVES:15)
Block(4,26,-8,LEAVES:15)
Block(5,26,-8,LEAVES:15)
Block(6,26,-8,LEAVES:15)
Block(-9,26,-7,LEAVES:15)
Block(-7,26,-7,LEAVES:3)
Block(-3,26,-7,LEAVES:15)
Block(-2,26,-7,LOG:15)
Block(-1,26,-7,LOG:15)
Block(2,26,-7,LEAVES:15)
Block(3,26,-7,LEAVES:3)
Block(4,26,-7,LEAVES:15)
Block(5,26,-7,LEAVES:15)
Block(6,26,-7,LEAVES:15)
Block(-14,26,-6,LEAVES:3)
Block(-11,26,-6,LEAVES:15)
Block(-7,26,-6,LOG:15)
Block(-6,26,-6,LOG:15)
Block(-5,26,-6,LOG:15)
Block(-3,26,-6,LEAVES:15)
Block(-2,26,-6,LOG:15)
Block(3,26,-6,LEAVES:3)
Block(4,26,-6,LEAVES:3)
Block(5,26,-6,LEAVES:15)
Block(6,26,-6,LEAVES:15)
Block(7,26,-6,LEAVES:15)
Block(8,26,-6,LEAVES:15)
Block(-12,26,-5,LEAVES:3)
Block(-11,26,-5,LEAVES:3)
Block(-10,26,-5,LEAVES:3)
Block(-7,26,-5,LEAVES:3)
Block(-6,26,-5,LOG:15)
Block(-5,26,-5,LOG:15)
Block(-3,26,-5,LEAVES:15)
Block(2,26,-5,LOG:15)
Block(3,26,-5,LEAVES:3)
Block(4,26,-5,LEAVES:15)
Block(5,26,-5,LEAVES:15)
Block(6,26,-5,LEAVES:15)
Block(7,26,-5,LEAVES:3)
Block(9,26,-5,LEAVES:3)
Block(-12,26,-4,LEAVES:3)
Block(-11,26,-4,LEAVES:3)
Block(-10,26,-4,LOG:15)
Block(-9,26,-4,LEAVES:3)
Block(-4,26,-4,LEAVES:15)
Block(-3,26,-4,LEAVES:15)
Block(2,26,-4,LOG:15)
Block(3,26,-4,LEAVES:3)
Block(4,26,-4,LEAVES:3)
Block(5,26,-4,LEAVES:3)
Block(6,26,-4,LOG:15)
Block(7,26,-4,LEAVES:3)
Block(8,26,-4,LEAVES:3)
Block(-12,26,-3,LEAVES:3)
Block(-11,26,-3,LEAVES:3)
Block(-10,26,-3,LOG:15)
Block(-9,26,-3,LOG:15)
Block(-8,26,-3,LEAVES:15)
Block(-4,26,-3,LEAVES:15)
Block(-3,26,-3,LEAVES:15)
Block(-2,26,-3,LEAVES:15)
Block(2,26,-3,LEAVES:3)
Block(3,26,-3,LEAVES:3)
Block(4,26,-3,LEAVES:3)
Block(5,26,-3,LOG:15)
Block(6,26,-3,LOG:15)
Block(7,26,-3,LEAVES:3)
Block(8,26,-3,LEAVES:15)
Block(-11,26,-2,LEAVES:3)
Block(-10,26,-2,LEAVES:3)
Block(-9,26,-2,LOG:15)
Block(-8,26,-2,LOG:15)
Block(-2,26,-2,LEAVES:15)
Block(2,26,-2,LEAVES:15)
Block(3,26,-2,LEAVES:3)
Block(4,26,-2,LEAVES:3)
Block(5,26,-2,LOG:15)
Block(6,26,-2,LEAVES:3)
Block(7,26,-2,LEAVES:3)
Block(8,26,-2,LEAVES:3)
Block(9,26,-2,LEAVES:3)
Block(-9,26,-1,LEAVES:15)
Block(-8,26,-1,LOG:15)
Block(-7,26,-1,LEAVES:15)
Block(-6,26,-1,LEAVES:15)
Block(-2,26,-1,LEAVES:15)
Block(-1,26,-1,LEAVES:15)
Block(0,26,-1,LEAVES:15)
Block(1,26,-1,LEAVES:15)
Block(2,26,-1,LEAVES:15)
Block(6,26,-1,LEAVES:3)
Block(7,26,-1,LEAVES:3)
Block(8,26,-1,LEAVES:3)
Block(9,26,-1,LEAVES:3)
Block(10,26,-1,LEAVES:15)
Block(-9,26,0,LEAVES:3)
Block(-8,26,0,LEAVES:3)
Block(-7,26,0,LEAVES:3)
Block(-6,26,0,LEAVES:15)
Block(-1,26,0,LEAVES:15)
Block(0,26,0,LEAVES:15)
Block(1,26,0,LEAVES:3)
Block(7,26,0,LEAVES:3)
Block(8,26,0,LEAVES:3)
Block(9,26,0,LEAVES:3)
Block(10,26,0,LEAVES:3)
Block(-11,26,1,LEAVES:3)
Block(-10,26,1,LEAVES:3)
Block(-9,26,1,LOG:15)
Block(-8,26,1,LOG:15)
Block(-7,26,1,LEAVES:15)
Block(-6,26,1,LEAVES:15)
Block(-3,26,1,LOG:15)
Block(1,26,1,LOG:15)
Block(2,26,1,LOG:15)
Block(5,26,1,LEAVES:15)
Block(6,26,1,LEAVES:15)
Block(8,26,1,LEAVES:3)
Block(9,26,1,LOG:15)
Block(10,26,1,LOG:15)
Block(-12,26,2,LEAVES:3)
Block(-11,26,2,LEAVES:3)
Block(-10,26,2,LEAVES:3)
Block(-9,26,2,LOG:15)
Block(-8,26,2,LEAVES:15)
Block(-7,26,2,LEAVES:15)
Block(-6,26,2,LEAVES:15)
Block(-4,26,2,LOG:15)
Block(-3,26,2,LOG:15)
Block(2,26,2,LOG:15)
Block(5,26,2,LEAVES:15)
Block(6,26,2,LEAVES:15)
Block(8,26,2,LEAVES:3)
Block(9,26,2,LEAVES:3)
Block(10,26,2,LOG:15)
Block(11,26,2,LEAVES:3)
Block(-11,26,3,LEAVES:3)
Block(-9,26,3,LEAVES:15)
Block(-8,26,3,LEAVES:15)
Block(-7,26,3,LEAVES:15)
Block(-6,26,3,LEAVES:15)
Block(-4,26,3,LOG:15)
Block(4,26,3,LEAVES:15)
Block(5,26,3,LEAVES:15)
Block(6,26,3,LEAVES:15)
Block(7,26,3,LEAVES:15)
Block(9,26,3,LEAVES:15)
Block(10,26,3,LEAVES:3)
Block(-8,26,4,LEAVES:15)
Block(-6,26,4,LEAVES:3)
Block(-5,26,4,LEAVES:3)
Block(4,26,4,LEAVES:15)
Block(5,26,4,LEAVES:15)
Block(6,26,4,LEAVES:15)
Block(8,26,4,LEAVES:15)
Block(9,26,4,LEAVES:15)
Block(10,26,4,LEAVES:15)
Block(-7,26,5,LEAVES:3)
Block(-5,26,5,LEAVES:3)
Block(-3,26,5,LEAVES:15)
Block(-2,26,5,LEAVES:15)
Block(-1,26,5,LEAVES:15)
Block(3,26,5,LEAVES:15)
Block(4,26,5,LEAVES:15)
Block(9,26,5,LEAVES:15)
Block(-8,26,6,LEAVES:3)
Block(-3,26,6,LEAVES:15)
Block(-2,26,6,LEAVES:15)
Block(-1,26,6,LEAVES:15)
Block(0,26,6,LEAVES:15)
Block(1,26,6,LEAVES:15)
Block(2,26,6,LEAVES:15)
Block(3,26,6,LEAVES:15)
Block(5,26,6,LEAVES:15)
Block(8,26,6,LEAVES:15)
Block(9,26,6,LEAVES:15)
Block(-8,26,7,LEAVES:15)
Block(-7,26,7,LEAVES:3)
Block(-4,26,7,LEAVES:15)
Block(-3,26,7,LEAVES:15)
Block(-2,26,7,LEAVES:15)
Block(-1,26,7,LEAVES:15)
Block(0,26,7,LEAVES:15)
Block(1,26,7,LEAVES:15)
Block(2,26,7,LEAVES:15)
Block(3,26,7,LEAVES:3)
Block(4,26,7,LEAVES:15)
Block(5,26,7,LEAVES:15)
Block(8,26,7,LEAVES:15)
Block(-9,26,8,LEAVES:15)
Block(-8,26,8,LEAVES:15)
Block(-7,26,8,LEAVES:15)
Block(-6,26,8,LEAVES:15)
Block(-5,26,8,LOG:15)
Block(-4,26,8,LOG:15)
Block(-3,26,8,LEAVES:15)
Block(-2,26,8,LEAVES:15)
Block(-1,26,8,LEAVES:15)
Block(0,26,8,LEAVES:15)
Block(1,26,8,LEAVES:15)
Block(2,26,8,LEAVES:3)
Block(3,26,8,LOG:15)
Block(4,26,8,LOG:15)
Block(5,26,8,LEAVES:15)
Block(-8,26,9,LEAVES:15)
Block(-7,26,9,LEAVES:15)
Block(-6,26,9,LEAVES:15)
Block(-5,26,9,LOG:15)
Block(-4,26,9,LOG:15)
Block(-3,26,9,LEAVES:15)
Block(-2,26,9,LEAVES:15)
Block(-1,26,9,LEAVES:15)
Block(0,26,9,LEAVES:15)
Block(1,26,9,LEAVES:15)
Block(2,26,9,LEAVES:15)
Block(3,26,9,LEAVES:3)
Block(4,26,9,LOG:15)
Block(5,26,9,LEAVES:3)
Block(6,26,9,LEAVES:15)
Block(7,26,9,LEAVES:15)
Block(-7,26,10,LEAVES:15)
Block(-6,26,10,LEAVES:15)
Block(-5,26,10,LEAVES:15)
Block(-4,26,10,LEAVES:15)
Block(-3,26,10,LEAVES:15)
Block(-2,26,10,LEAVES:15)
Block(-1,26,10,LEAVES:15)
Block(0,26,10,LEAVES:15)
Block(1,26,10,LEAVES:15)
Block(2,26,10,LEAVES:15)
Block(3,26,10,LEAVES:15)
Block(4,26,10,LEAVES:3)
Block(5,26,10,LEAVES:15)
Block(6,26,10,LEAVES:15)
Block(-5,26,11,LEAVES:15)
Block(-4,26,11,LEAVES:15)
Block(-3,26,11,LEAVES:15)
Block(-2,26,11,LEAVES:15)
Block(-1,26,11,LEAVES:15)
Block(0,26,11,LEAVES:15)
Block(1,26,11,LEAVES:15)
Block(2,26,11,LEAVES:15)
Block(3,26,11,LEAVES:15)
Block(4,26,11,LEAVES:15)
Block(5,26,11,LEAVES:15)
Block(6,26,11,LEAVES:15)
Block(-4,26,12,LEAVES:15)
Block(-3,26,12,LEAVES:15)
Block(-2,26,12,LEAVES:15)
Block(-1,26,12,LEAVES:15)
Block(0,26,12,LEAVES:15)
Block(3,26,12,LEAVES:15)
Block(4,26,12,LEAVES:15)
Block(-3,26,13,LEAVES:15)
Block(-2,26,13,LEAVES:15)
Block(-1,26,13,LEAVES:15)
Block(3,26,13,LEAVES:15)
Block(-1,27,-15,LEAVES:3)
Block(0,27,-15,LEAVES:3)
Block(1,27,-15,LEAVES:15)
Block(-12,27,-14,LEAVES:15)
Block(-2,27,-14,LEAVES:3)
Block(-1,27,-14,LOG:15)
Block(0,27,-14,LEAVES:3)
Block(1,27,-14,LEAVES:3)
Block(2,27,-14,LEAVES:15)
Block(-13,27,-13,LEAVES:15)
Block(-12,27,-13,LEAVES:15)
Block(-11,27,-13,LEAVES:3)
Block(-5,27,-13,LEAVES:15)
Block(-1,27,-13,LOG:15)
Block(0,27,-13,LEAVES:3)
Block(1,27,-13,LEAVES:15)
Block(2,27,-13,LEAVES:15)
Block(3,27,-13,LEAVES:15)
Block(-13,27,-12,LEAVES:15)
Block(-12,27,-12,LEAVES:3)
Block(-11,27,-12,LEAVES:15)
Block(-6,27,-12,LEAVES:15)
Block(-5,27,-12,LEAVES:15)
Block(-4,27,-12,LEAVES:15)
Block(-3,27,-12,LEAVES:3)
Block(-2,27,-12,LEAVES:3)
Block(-1,27,-12,LEAVES:3)
Block(0,27,-12,LEAVES:3)
Block(1,27,-12,LEAVES:15)
Block(2,27,-12,LEAVES:15)
Block(3,27,-12,LEAVES:15)
Block(-12,27,-11,LEAVES:15)
Block(-8,27,-11,LEAVES:15)
Block(-5,27,-11,LEAVES:15)
Block(-4,27,-11,LEAVES:3)
Block(-3,27,-11,LEAVES:3)
Block(-2,27,-11,LEAVES:3)
Block(-1,27,-11,LEAVES:3)
Block(0,27,-11,LEAVES:15)
Block(1,27,-11,LEAVES:15)
Block(2,27,-11,LEAVES:15)
Block(3,27,-11,LEAVES:15)
Block(4,27,-11,LEAVES:15)
Block(5,27,-11,LEAVES:15)
Block(6,27,-11,LEAVES:15)
Block(-9,27,-10,LEAVES:3)
Block(-8,27,-10,LEAVES:3)
Block(-7,27,-10,LEAVES:3)
Block(-4,27,-10,LEAVES:3)
Block(-3,27,-10,LEAVES:3)
Block(-1,27,-10,LEAVES:15)
Block(0,27,-10,LEAVES:15)
Block(1,27,-10,LEAVES:15)
Block(2,27,-10,LEAVES:15)
Block(3,27,-10,LEAVES:15)
Block(4,27,-10,LEAVES:15)
Block(5,27,-10,LEAVES:15)
Block(6,27,-10,LEAVES:15)
Block(-10,27,-9,LEAVES:3)
Block(-9,27,-9,LEAVES:3)
Block(-8,27,-9,LEAVES:3)
Block(-7,27,-9,LEAVES:3)
Block(-6,27,-9,LEAVES:3)
Block(-5,27,-9,LEAVES:3)
Block(-4,27,-9,LEAVES:3)
Block(-3,27,-9,LEAVES:3)
Block(0,27,-9,LEAVES:15)
Block(1,27,-9,LEAVES:15)
Block(2,27,-9,LEAVES:15)
Block(3,27,-9,LEAVES:15)
Block(4,27,-9,LEAVES:15)
Block(5,27,-9,LEAVES:15)
Block(6,27,-9,LEAVES:15)
Block(7,27,-9,LEAVES:15)
Block(-14,27,-8,LEAVES:3)
Block(-10,27,-8,LEAVES:15)
Block(-9,27,-8,LEAVES:3)
Block(-8,27,-8,LEAVES:3)
Block(-7,27,-8,LOG:15)
Block(-6,27,-8,LEAVES:3)
Block(-5,27,-8,LOG:15)
Block(-4,27,-8,LEAVES:3)
Block(-2,27,-8,LEAVES:15)
Block(-1,27,-8,LEAVES:3)
Block(0,27,-8,LEAVES:15)
Block(1,27,-8,LEAVES:15)
Block(2,27,-8,LEAVES:15)
Block(3,27,-8,LEAVES:15)
Block(4,27,-8,LEAVES:15)
Block(5,27,-8,LEAVES:3)
Block(6,27,-8,LEAVES:15)
Block(7,27,-8,LEAVES:15)
Block(-15,27,-7,LEAVES:3)
Block(-14,27,-7,LEAVES:3)
Block(-13,27,-7,LEAVES:3)
Block(-12,27,-7,LEAVES:15)
Block(-10,27,-7,LEAVES:15)
Block(-9,27,-7,LEAVES:15)
Block(-8,27,-7,LEAVES:3)
Block(-7,27,-7,LOG:15)
Block(-6,27,-7,LOG:15)
Block(-5,27,-7,LOG:15)
Block(-4,27,-7,LEAVES:15)
Block(-3,27,-7,LEAVES:15)
Block(-2,27,-7,LEAVES:3)
Block(-1,27,-7,LOG:15)
Block(0,27,-7,LEAVES:3)
Block(1,27,-7,LEAVES:15)
Block(2,27,-7,LEAVES:3)
Block(3,27,-7,LEAVES:3)
Block(4,27,-7,LEAVES:3)
Block(5,27,-7,LEAVES:15)
Block(6,27,-7,LEAVES:15)
Block(7,27,-7,LEAVES:15)
Block(8,27,-7,LEAVES:15)
Block(-14,27,-6,LEAVES:3)
Block(-13,27,-6,LEAVES:15)
Block(-12,27,-6,LEAVES:15)
Block(-11,27,-6,LEAVES:15)
Block(-10,27,-6,LEAVES:15)
Block(-8,27,-6,LEAVES:15)
Block(-7,27,-6,LOG:15)
Block(-6,27,-6,LOG:15)
Block(-5,27,-6,LOG:15)
Block(-4,27,-6,LEAVES:15)
Block(-3,27,-6,LEAVES:15)
Block(-2,27,-6,LEAVES:15)
Block(2,27,-6,LEAVES:3)
Block(3,27,-6,LOG:15)
Block(4,27,-6,LEAVES:3)
Block(5,27,-6,LEAVES:15)
Block(6,27,-6,LEAVES:15)
Block(7,27,-6,LEAVES:15)
Block(8,27,-6,LEAVES:3)
Block(9,27,-6,LEAVES:15)
Block(-13,27,-5,LEAVES:15)
Block(-12,27,-5,LEAVES:15)
Block(-11,27,-5,LEAVES:3)
Block(-10,27,-5,LEAVES:15)
Block(-9,27,-5,LEAVES:15)
Block(-8,27,-5,LEAVES:15)
Block(-7,27,-5,LEAVES:15)
Block(-6,27,-5,LOG:15)
Block(-5,27,-5,LEAVES:15)
Block(-4,27,-5,LEAVES:15)
Block(-3,27,-5,LEAVES:15)
Block(-2,27,-5,LEAVES:15)
Block(2,27,-5,LOG:15)
Block(3,27,-5,LOG:15)
Block(4,27,-5,LEAVES:3)
Block(5,27,-5,LEAVES:15)
Block(6,27,-5,LEAVES:3)
Block(7,27,-5,LOG:15)
Block(8,27,-5,LOG:15)
Block(9,27,-5,LEAVES:3)
Block(-14,27,-4,LEAVES:15)
Block(-13,27,-4,LEAVES:15)
Block(-12,27,-4,LOG:15)
Block(-11,27,-4,LOG:15)
Block(-10,27,-4,LOG:15)
Block(-9,27,-4,LEAVES:15)
Block(-8,27,-4,LEAVES:15)
Block(-6,27,-4,LEAVES:15)
Block(-5,27,-4,LEAVES:15)
Block(-4,27,-4,LEAVES:15)
Block(-3,27,-4,LEAVES:15)
Block(-2,27,-4,LEAVES:15)
Block(2,27,-4,LEAVES:15)
Block(3,27,-4,LEAVES:15)
Block(4,27,-4,LEAVES:15)
Block(5,27,-4,LEAVES:3)
Block(6,27,-4,LOG:15)
Block(7,27,-4,LOG:15)
Block(8,27,-4,LEAVES:3)
Block(-13,27,-3,LEAVES:15)
Block(-11,27,-3,LEAVES:3)
Block(-10,27,-3,LEAVES:3)
Block(-9,27,-3,LOG:15)
Block(-8,27,-3,LEAVES:15)
Block(-7,27,-3,LEAVES:15)
Block(-6,27,-3,LEAVES:15)
Block(-5,27,-3,LEAVES:15)
Block(-4,27,-3,LEAVES:15)
Block(-3,27,-3,LEAVES:15)
Block(-2,27,-3,LEAVES:15)
Block(-1,27,-3,LEAVES:15)
Block(0,27,-3,LEAVES:15)
Block(1,27,-3,LEAVES:15)
Block(2,27,-3,LEAVES:15)
Block(3,27,-3,LEAVES:15)
Block(4,27,-3,LEAVES:3)
Block(5,27,-3,LEAVES:3)
Block(6,27,-3,LEAVES:3)
Block(7,27,-3,LEAVES:3)
Block(8,27,-3,LEAVES:3)
Block(9,27,-3,LEAVES:15)
Block(-10,27,-2,LEAVES:3)
Block(-9,27,-2,LEAVES:15)
Block(-8,27,-2,LEAVES:15)
Block(-7,27,-2,LEAVES:15)
Block(-6,27,-2,LEAVES:15)
Block(-5,27,-2,LEAVES:15)
Block(-4,27,-2,LEAVES:15)
Block(-3,27,-2,LEAVES:15)
Block(-2,27,-2,LEAVES:15)
Block(-1,27,-2,LEAVES:15)
Block(0,27,-2,LEAVES:15)
Block(1,27,-2,LEAVES:15)
Block(2,27,-2,LEAVES:15)
Block(3,27,-2,LEAVES:15)
Block(4,27,-2,LEAVES:15)
Block(5,27,-2,LOG:15)
Block(6,27,-2,LOG:15)
Block(7,27,-2,LEAVES:3)
Block(8,27,-2,LEAVES:3)
Block(9,27,-2,LEAVES:15)
Block(10,27,-2,LEAVES:15)
Block(-9,27,-1,LEAVES:15)
Block(-8,27,-1,LEAVES:15)
Block(-7,27,-1,LEAVES:15)
Block(-6,27,-1,LEAVES:15)
Block(-5,27,-1,LEAVES:15)
Block(-4,27,-1,LEAVES:15)
Block(-3,27,-1,LEAVES:15)
Block(-2,27,-1,LEAVES:15)
Block(-1,27,-1,LEAVES:15)
Block(0,27,-1,LEAVES:15)
Block(1,27,-1,LEAVES:15)
Block(2,27,-1,LEAVES:15)
Block(3,27,-1,LEAVES:15)
Block(4,27,-1,LEAVES:15)
Block(5,27,-1,LEAVES:15)
Block(6,27,-1,LOG:15)
Block(7,27,-1,LOG:15)
Block(8,27,-1,LEAVES:3)
Block(9,27,-1,LEAVES:3)
Block(10,27,-1,LEAVES:15)
Block(11,27,-1,LEAVES:15)
Block(-10,27,0,LEAVES:15)
Block(-9,27,0,LEAVES:15)
Block(-8,27,0,LEAVES:15)
Block(-7,27,0,LEAVES:15)
Block(-6,27,0,LEAVES:15)
Block(-5,27,0,LEAVES:15)
Block(-4,27,0,LEAVES:15)
Block(-3,27,0,LEAVES:15)
Block(-2,27,0,LEAVES:15)
Block(-1,27,0,LEAVES:15)
Block(0,27,0,LEAVES:15)
Block(1,27,0,LEAVES:15)
Block(2,27,0,LEAVES:15)
Block(3,27,0,LEAVES:15)
Block(4,27,0,LEAVES:15)
Block(5,27,0,LEAVES:15)
Block(6,27,0,LEAVES:3)
Block(7,27,0,LOG:15)
Block(8,27,0,LOG:15)
Block(9,27,0,LOG:15)
Block(10,27,0,LEAVES:15)
Block(11,27,0,LEAVES:15)
Block(-12,27,1,LEAVES:3)
Block(-11,27,1,LEAVES:3)
Block(-10,27,1,LEAVES:3)
Block(-9,27,1,LOG:15)
Block(-8,27,1,LEAVES:15)
Block(-7,27,1,LEAVES:15)
Block(-6,27,1,LEAVES:15)
Block(-5,27,1,LEAVES:15)
Block(-1,27,1,LEAVES:15)
Block(0,27,1,LEAVES:15)
Block(1,27,1,LEAVES:15)
Block(2,27,1,LOG:15)
Block(3,27,1,LEAVES:15)
Block(4,27,1,LEAVES:15)
Block(5,27,1,LEAVES:15)
Block(6,27,1,LEAVES:15)
Block(7,27,1,LEAVES:15)
Block(8,27,1,LEAVES:3)
Block(9,27,1,LOG:15)
Block(10,27,1,LEAVES:3)
Block(11,27,1,LEAVES:15)
Block(-12,27,2,LEAVES:3)
Block(-11,27,2,LOG:15)
Block(-10,27,2,LOG:15)
Block(-9,27,2,LOG:15)
Block(-8,27,2,LEAVES:15)
Block(-7,27,2,LEAVES:15)
Block(-6,27,2,LEAVES:15)
Block(-5,27,2,LEAVES:3)
Block(-4,27,2,LOG:15)
Block(-1,27,2,LEAVES:15)
Block(2,27,2,LOG:15)
Block(3,27,2,LEAVES:3)
Block(4,27,2,LEAVES:15)
Block(5,27,2,LEAVES:15)
Block(6,27,2,LEAVES:15)
Block(8,27,2,LEAVES:15)
Block(9,27,2,LEAVES:3)
Block(10,27,2,LEAVES:15)
Block(-12,27,3,LEAVES:3)
Block(-11,27,3,LEAVES:3)
Block(-10,27,3,LEAVES:3)
Block(-9,27,3,LEAVES:15)
Block(-8,27,3,LEAVES:15)
Block(-7,27,3,LEAVES:15)
Block(-6,27,3,LEAVES:3)
Block(-5,27,3,LOG:15)
Block(-4,27,3,LOG:15)
Block(-1,27,3,LEAVES:15)
Block(3,27,3,LEAVES:15)
Block(4,27,3,LEAVES:15)
Block(5,27,3,LEAVES:15)
Block(6,27,3,LEAVES:15)
Block(8,27,3,LEAVES:15)
Block(9,27,3,LEAVES:15)
Block(10,27,3,LEAVES:15)
Block(-8,27,4,LEAVES:15)
Block(-7,27,4,LEAVES:3)
Block(-6,27,4,LOG:15)
Block(-5,27,4,LOG:15)
Block(-4,27,4,LEAVES:3)
Block(-3,27,4,LEAVES:15)
Block(-2,27,4,LEAVES:15)
Block(-1,27,4,LEAVES:15)
Block(3,27,4,LEAVES:15)
Block(4,27,4,LEAVES:15)
Block(5,27,4,LEAVES:15)
Block(6,27,4,LEAVES:15)
Block(7,27,4,LEAVES:15)
Block(8,27,4,LEAVES:15)
Block(9,27,4,LEAVES:15)
Block(10,27,4,LEAVES:15)
Block(-8,27,5,LEAVES:3)
Block(-7,27,5,LEAVES:3)
Block(-6,27,5,LEAVES:3)
Block(-5,27,5,LEAVES:3)
Block(-4,27,5,LEAVES:3)
Block(-3,27,5,LEAVES:15)
Block(-2,27,5,LEAVES:15)
Block(-1,27,5,LEAVES:15)
Block(0,27,5,LEAVES:15)
Block(1,27,5,LEAVES:15)
Block(2,27,5,LEAVES:15)
Block(3,27,5,LEAVES:15)
Block(4,27,5,LEAVES:15)
Block(5,27,5,LEAVES:15)
Block(7,27,5,LEAVES:15)
Block(8,27,5,LEAVES:15)
Block(9,27,5,LEAVES:15)
Block(10,27,5,LEAVES:15)
Block(-9,27,6,LEAVES:3)
Block(-8,27,6,LEAVES:15)
Block(-7,27,6,LEAVES:3)
Block(-4,27,6,LEAVES:15)
Block(-3,27,6,LEAVES:15)
Block(-2,27,6,LEAVES:15)
Block(-1,27,6,LEAVES:15)
Block(0,27,6,LEAVES:15)
Block(1,27,6,LEAVES:15)
Block(2,27,6,LEAVES:15)
Block(3,27,6,LEAVES:15)
Block(4,27,6,LEAVES:15)
Block(5,27,6,LEAVES:15)
Block(6,27,6,LEAVES:15)
Block(7,27,6,LEAVES:15)
Block(8,27,6,LEAVES:15)
Block(9,27,6,LEAVES:15)
Block(10,27,6,LEAVES:15)
Block(-9,27,7,LEAVES:15)
Block(-8,27,7,LEAVES:15)
Block(-7,27,7,LEAVES:15)
Block(-5,27,7,LEAVES:15)
Block(-4,27,7,LEAVES:15)
Block(-3,27,7,LEAVES:15)
Block(-2,27,7,LEAVES:15)
Block(-1,27,7,LEAVES:15)
Block(0,27,7,LEAVES:15)
Block(1,27,7,LEAVES:15)
Block(2,27,7,LEAVES:15)
Block(3,27,7,LEAVES:15)
Block(4,27,7,LEAVES:15)
Block(5,27,7,LEAVES:15)
Block(6,27,7,LEAVES:15)
Block(7,27,7,LEAVES:15)
Block(8,27,7,LEAVES:15)
Block(9,27,7,LEAVES:3)
Block(-10,27,8,LEAVES:15)
Block(-9,27,8,LEAVES:15)
Block(-8,27,8,LEAVES:15)
Block(-7,27,8,LEAVES:15)
Block(-6,27,8,LEAVES:15)
Block(-5,27,8,LEAVES:15)
Block(-4,27,8,LEAVES:15)
Block(-3,27,8,LEAVES:15)
Block(-2,27,8,LEAVES:15)
Block(-1,27,8,LEAVES:15)
Block(0,27,8,LEAVES:15)
Block(1,27,8,LEAVES:15)
Block(2,27,8,LEAVES:15)
Block(3,27,8,LEAVES:15)
Block(4,27,8,LEAVES:15)
Block(5,27,8,LEAVES:15)
Block(6,27,8,LEAVES:15)
Block(8,27,8,LEAVES:3)
Block(9,27,8,LEAVES:3)
Block(-9,27,9,LEAVES:15)
Block(-8,27,9,LEAVES:15)
Block(-7,27,9,LEAVES:15)
Block(-6,27,9,LEAVES:15)
Block(-5,27,9,LEAVES:15)
Block(-4,27,9,LEAVES:15)
Block(-3,27,9,LEAVES:15)
Block(-2,27,9,LEAVES:15)
Block(-1,27,9,LEAVES:15)
Block(0,27,9,LEAVES:15)
Block(1,27,9,LEAVES:15)
Block(2,27,9,LEAVES:15)
Block(3,27,9,LEAVES:15)
Block(4,27,9,LEAVES:15)
Block(5,27,9,LEAVES:15)
Block(6,27,9,LEAVES:15)
Block(8,27,9,LEAVES:15)
Block(9,27,9,LEAVES:3)
Block(-7,27,10,LEAVES:15)
Block(-6,27,10,LEAVES:15)
Block(-4,27,10,LEAVES:15)
Block(-3,27,10,LEAVES:15)
Block(-2,27,10,LEAVES:15)
Block(-1,27,10,LEAVES:15)
Block(0,27,10,LEAVES:15)
Block(1,27,10,LEAVES:15)
Block(2,27,10,LEAVES:15)
Block(3,27,10,LEAVES:15)
Block(4,27,10,LEAVES:15)
Block(5,27,10,LEAVES:15)
Block(6,27,10,LEAVES:15)
Block(7,27,10,LEAVES:15)
Block(-4,27,11,LEAVES:15)
Block(-3,27,11,LEAVES:15)
Block(-2,27,11,LEAVES:15)
Block(-1,27,11,LEAVES:15)
Block(0,27,11,LEAVES:15)
Block(1,27,11,LEAVES:15)
Block(2,27,11,LEAVES:15)
Block(3,27,11,LEAVES:15)
Block(4,27,11,LEAVES:15)
Block(6,27,11,LEAVES:15)
Block(7,27,11,LEAVES:15)
Block(-4,27,12,LEAVES:15)
Block(-3,27,12,LEAVES:15)
Block(-2,27,12,LEAVES:15)
Block(-1,27,12,LEAVES:15)
Block(0,27,12,LEAVES:15)
Block(2,27,12,LEAVES:15)
Block(-3,27,13,LEAVES:15)
Block(-2,27,13,LEAVES:15)
Block(-1,27,13,LEAVES:15)
Block(0,27,13,LEAVES:15)
Block(3,27,13,LEAVES:15)
Block(-1,28,-14,LEAVES:15)
Block(1,28,-14,LEAVES:15)
Block(2,28,-14,LEAVES:15)
Block(3,28,-14,LEAVES:15)
Block(-12,28,-13,LEAVES:15)
Block(-11,28,-13,LEAVES:3)
Block(-6,28,-13,LEAVES:15)
Block(-5,28,-13,LEAVES:15)
Block(-2,28,-13,LEAVES:3)
Block(-1,28,-13,LOG:15)
Block(0,28,-13,LEAVES:3)
Block(1,28,-13,LEAVES:15)
Block(2,28,-13,LEAVES:15)
Block(3,28,-13,LEAVES:15)
Block(4,28,-13,LEAVES:15)
Block(-13,28,-12,LEAVES:3)
Block(-12,28,-12,LOG:15)
Block(-11,28,-12,LEAVES:3)
Block(-7,28,-12,LEAVES:15)
Block(-6,28,-12,LEAVES:15)
Block(-5,28,-12,LEAVES:15)
Block(-4,28,-12,LEAVES:3)
Block(-3,28,-12,LEAVES:3)
Block(-2,28,-12,LEAVES:3)
Block(-1,28,-12,LOG:15)
Block(0,28,-12,LEAVES:3)
Block(1,28,-12,LEAVES:15)
Block(2,28,-12,LEAVES:15)
Block(3,28,-12,LEAVES:15)
Block(4,28,-12,LEAVES:15)
Block(5,28,-12,LEAVES:15)
Block(6,28,-12,LEAVES:15)
Block(-9,28,-11,LEAVES:15)
Block(-6,28,-11,LEAVES:15)
Block(-5,28,-11,LEAVES:15)
Block(-4,28,-11,LEAVES:3)
Block(-3,28,-11,LEAVES:3)
Block(-2,28,-11,LEAVES:3)
Block(-1,28,-11,LEAVES:3)
Block(0,28,-11,LEAVES:3)
Block(2,28,-11,LEAVES:15)
Block(3,28,-11,LEAVES:15)
Block(4,28,-11,LEAVES:15)
Block(5,28,-11,LEAVES:15)
Block(6,28,-11,LEAVES:15)
Block(7,28,-11,LEAVES:15)
Block(-10,28,-10,LEAVES:3)
Block(-9,28,-10,LEAVES:3)
Block(-8,28,-10,LEAVES:3)
Block(-7,28,-10,LEAVES:15)
Block(-6,28,-10,LEAVES:15)
Block(-5,28,-10,LEAVES:3)
Block(-4,28,-10,LEAVES:3)
Block(-3,28,-10,LOG:15)
Block(-2,28,-10,LEAVES:3)
Block(-1,28,-10,LEAVES:15)
Block(0,28,-10,LEAVES:15)
Block(1,28,-10,LEAVES:15)
Block(2,28,-10,LEAVES:15)
Block(3,28,-10,LEAVES:15)
Block(4,28,-10,LEAVES:15)
Block(5,28,-10,LEAVES:15)
Block(6,28,-10,LEAVES:15)
Block(7,28,-10,LEAVES:15)
Block(-14,28,-9,LEAVES:15)
Block(-10,28,-9,LEAVES:3)
Block(-9,28,-9,LEAVES:3)
Block(-8,28,-9,LEAVES:3)
Block(-7,28,-9,LEAVES:3)
Block(-6,28,-9,LEAVES:3)
Block(-5,28,-9,LEAVES:3)
Block(-4,28,-9,LOG:15)
Block(-3,28,-9,LOG:15)
Block(-1,28,-9,LEAVES:15)
Block(0,28,-9,LEAVES:15)
Block(1,28,-9,LEAVES:15)
Block(2,28,-9,LEAVES:3)
Block(3,28,-9,LEAVES:15)
Block(4,28,-9,LEAVES:15)
Block(5,28,-9,LEAVES:15)
Block(6,28,-9,LEAVES:15)
Block(7,28,-9,LEAVES:15)
Block(-15,28,-8,LEAVES:3)
Block(-14,28,-8,LEAVES:3)
Block(-13,28,-8,LEAVES:3)
Block(-10,28,-8,LEAVES:3)
Block(-9,28,-8,LEAVES:3)
Block(-8,28,-8,LEAVES:3)
Block(-7,28,-8,LOG:15)
Block(-6,28,-8,LEAVES:3)
Block(-5,28,-8,LOG:15)
Block(-4,28,-8,LOG:15)
Block(-3,28,-8,LEAVES:3)
Block(-2,28,-8,LEAVES:15)
Block(-1,28,-8,LEAVES:15)
Block(0,28,-8,LEAVES:15)
Block(1,28,-8,LEAVES:3)
Block(2,28,-8,LOG:15)
Block(3,28,-8,LOG:15)
Block(4,28,-8,LEAVES:15)
Block(5,28,-8,LEAVES:3)
Block(6,28,-8,LEAVES:15)
Block(7,28,-8,LEAVES:15)
Block(8,28,-8,LEAVES:15)
Block(-15,28,-7,LEAVES:3)
Block(-14,28,-7,LOG:15)
Block(-13,28,-7,LOG:15)
Block(-12,28,-7,LEAVES:15)
Block(-11,28,-7,LEAVES:15)
Block(-9,28,-7,LEAVES:15)
Block(-8,28,-7,LEAVES:15)
Block(-7,28,-7,LOG:15)
Block(-6,28,-7,LEAVES:3)
Block(-5,28,-7,LOG:15)
Block(-4,28,-7,LEAVES:15)
Block(-3,28,-7,LEAVES:15)
Block(-2,28,-7,LEAVES:15)
Block(-1,28,-7,LEAVES:15)
Block(0,28,-7,LEAVES:15)
Block(1,28,-7,LEAVES:15)
Block(2,28,-7,LOG:15)
Block(3,28,-7,LOG:15)
Block(4,28,-7,LEAVES:15)
Block(5,28,-7,LEAVES:15)
Block(6,28,-7,LEAVES:15)
Block(7,28,-7,LEAVES:15)
Block(8,28,-7,LEAVES:15)
Block(-15,28,-6,LEAVES:3)
Block(-14,28,-6,LEAVES:3)
Block(-13,28,-6,LOG:15)
Block(-12,28,-6,LOG:15)
Block(-11,28,-6,LEAVES:15)
Block(-9,28,-6,LEAVES:15)
Block(-8,28,-6,LEAVES:15)
Block(-7,28,-6,LEAVES:15)
Block(-6,28,-6,LEAVES:15)
Block(-5,28,-6,LEAVES:15)
Block(-4,28,-6,LEAVES:15)
Block(-3,28,-6,LEAVES:15)
Block(-2,28,-6,LEAVES:15)
Block(-1,28,-6,LEAVES:15)
Block(0,28,-6,LEAVES:15)
Block(1,28,-6,LEAVES:15)
Block(2,28,-6,LEAVES:3)
Block(3,28,-6,LOG:15)
Block(4,28,-6,LEAVES:3)
Block(5,28,-6,LEAVES:15)
Block(6,28,-6,LEAVES:15)
Block(7,28,-6,LEAVES:3)
Block(8,28,-6,LEAVES:3)
Block(9,28,-6,LEAVES:3)
Block(-14,28,-5,LEAVES:15)
Block(-13,28,-5,LEAVES:15)
Block(-12,28,-5,LOG:15)
Block(-11,28,-5,LEAVES:15)
Block(-10,28,-5,LEAVES:15)
Block(-9,28,-5,LEAVES:15)
Block(-8,28,-5,LEAVES:15)
Block(-7,28,-5,LEAVES:15)
Block(-6,28,-5,LEAVES:15)
Block(-5,28,-5,LEAVES:15)
Block(-3,28,-5,LEAVES:15)
Block(-2,28,-5,LEAVES:15)
Block(-1,28,-5,LEAVES:15)
Block(0,28,-5,LEAVES:15)
Block(1,28,-5,LEAVES:15)
Block(2,28,-5,LOG:15)
Block(3,28,-5,LOG:15)
Block(4,28,-5,LEAVES:3)
Block(5,28,-5,LEAVES:15)
Block(6,28,-5,LEAVES:15)
Block(7,28,-5,LEAVES:3)
Block(8,28,-5,LOG:15)
Block(9,28,-5,LEAVES:3)
Block(-14,28,-4,LEAVES:15)
Block(-13,28,-4,LOG:15)
Block(-12,28,-4,LOG:15)
Block(-11,28,-4,LEAVES:15)
Block(-10,28,-4,LEAVES:15)
Block(-9,28,-4,LEAVES:15)
Block(-8,28,-4,LEAVES:15)
Block(-7,28,-4,LEAVES:15)
Block(-6,28,-4,LEAVES:15)
Block(-5,28,-4,LEAVES:15)
Block(-4,28,-4,LEAVES:15)
Block(-3,28,-4,LEAVES:15)
Block(-2,28,-4,LEAVES:15)
Block(-1,28,-4,LEAVES:15)
Block(0,28,-4,LEAVES:15)
Block(1,28,-4,LEAVES:15)
Block(2,28,-4,LEAVES:15)
Block(3,28,-4,LEAVES:3)
Block(4,28,-4,LEAVES:15)
Block(5,28,-4,LEAVES:15)
Block(6,28,-4,LEAVES:3)
Block(7,28,-4,LEAVES:3)
Block(8,28,-4,LEAVES:3)
Block(9,28,-4,LEAVES:3)
Block(-14,28,-3,LEAVES:15)
Block(-13,28,-3,LEAVES:15)
Block(-12,28,-3,LEAVES:15)
Block(-10,28,-3,LEAVES:15)
Block(-9,28,-3,LEAVES:15)
Block(-8,28,-3,LEAVES:15)
Block(-7,28,-3,LEAVES:15)
Block(-6,28,-3,LEAVES:15)
Block(-5,28,-3,LEAVES:15)
Block(-4,28,-3,LEAVES:15)
Block(-3,28,-3,LEAVES:15)
Block(-2,28,-3,LEAVES:15)
Block(-1,28,-3,LEAVES:15)
Block(0,28,-3,LEAVES:15)
Block(1,28,-3,LEAVES:15)
Block(2,28,-3,LEAVES:15)
Block(3,28,-3,LEAVES:15)
Block(4,28,-3,LEAVES:15)
Block(5,28,-3,LEAVES:15)
Block(6,28,-3,LEAVES:15)
Block(7,28,-3,LEAVES:3)
Block(8,28,-3,LEAVES:15)
Block(-9,28,-2,LEAVES:15)
Block(-8,28,-2,LEAVES:15)
Block(-7,28,-2,LEAVES:15)
Block(-5,28,-2,LEAVES:15)
Block(-4,28,-2,LEAVES:15)
Block(-3,28,-2,LEAVES:15)
Block(-2,28,-2,LEAVES:15)
Block(-1,28,-2,LEAVES:15)
Block(0,28,-2,LEAVES:15)
Block(1,28,-2,LEAVES:15)
Block(2,28,-2,LEAVES:15)
Block(3,28,-2,LEAVES:15)
Block(4,28,-2,LEAVES:15)
Block(5,28,-2,LEAVES:15)
Block(6,28,-2,LEAVES:15)
Block(7,28,-2,LEAVES:3)
Block(8,28,-2,LEAVES:15)
Block(-9,28,-1,LEAVES:15)
Block(-8,28,-1,LEAVES:15)
Block(-7,28,-1,LEAVES:15)
Block(-6,28,-1,LEAVES:15)
Block(-4,28,-1,LEAVES:15)
Block(-3,28,-1,LEAVES:15)
Block(-2,28,-1,LEAVES:15)
Block(-1,28,-1,LEAVES:15)
Block(0,28,-1,LEAVES:15)
Block(1,28,-1,LEAVES:15)
Block(2,28,-1,LEAVES:15)
Block(3,28,-1,LEAVES:15)
Block(4,28,-1,LEAVES:15)
Block(6,28,-1,LEAVES:3)
Block(7,28,-1,LOG:15)
Block(8,28,-1,LOG:15)
Block(9,28,-1,LEAVES:15)
Block(10,28,-1,LEAVES:15)
Block(-9,28,0,LEAVES:15)
Block(-8,28,0,LEAVES:15)
Block(-7,28,0,LEAVES:15)
Block(-6,28,0,LEAVES:15)
Block(-5,28,0,LEAVES:15)
Block(-4,28,0,LEAVES:15)
Block(-3,28,0,LEAVES:15)
Block(-2,28,0,LEAVES:15)
Block(-1,28,0,LEAVES:15)
Block(0,28,0,LEAVES:15)
Block(1,28,0,LEAVES:15)
Block(2,28,0,LEAVES:15)
Block(3,28,0,LEAVES:15)
Block(4,28,0,LEAVES:15)
Block(5,28,0,LEAVES:15)
Block(6,28,0,LEAVES:15)
Block(7,28,0,LEAVES:3)
Block(8,28,0,LOG:15)
Block(9,28,0,LEAVES:15)
Block(10,28,0,LEAVES:15)
Block(-11,28,1,LEAVES:3)
Block(-10,28,1,LEAVES:15)
Block(-9,28,1,LEAVES:15)
Block(-8,28,1,LEAVES:15)
Block(-7,28,1,LEAVES:15)
Block(-6,28,1,LEAVES:15)
Block(-5,28,1,LEAVES:15)
Block(-4,28,1,LEAVES:15)
Block(-3,28,1,LEAVES:15)
Block(-2,28,1,LEAVES:15)
Block(-1,28,1,LEAVES:15)
Block(0,28,1,LEAVES:15)
Block(1,28,1,LEAVES:3)
Block(2,28,1,LOG:15)
Block(3,28,1,LEAVES:3)
Block(4,28,1,LEAVES:15)
Block(5,28,1,LEAVES:15)
Block(6,28,1,LEAVES:15)
Block(7,28,1,LEAVES:15)
Block(8,28,1,LOG:15)
Block(9,28,1,LEAVES:15)
Block(10,28,1,LEAVES:15)
Block(-12,28,2,LEAVES:3)
Block(-11,28,2,LEAVES:3)
Block(-10,28,2,LEAVES:3)
Block(-9,28,2,LEAVES:15)
Block(-8,28,2,LEAVES:15)
Block(-7,28,2,LEAVES:15)
Block(-6,28,2,LEAVES:15)
Block(-5,28,2,LEAVES:15)
Block(-4,28,2,LEAVES:15)
Block(-3,28,2,LEAVES:15)
Block(-2,28,2,LEAVES:15)
Block(0,28,2,LEAVES:15)
Block(1,28,2,LEAVES:3)
Block(2,28,2,LOG:15)
Block(3,28,2,LEAVES:3)
Block(4,28,2,LEAVES:15)
Block(6,28,2,LEAVES:15)
Block(7,28,2,LEAVES:15)
Block(8,28,2,LEAVES:15)
Block(9,28,2,LEAVES:15)
Block(10,28,2,LEAVES:15)
Block(-11,28,3,LEAVES:3)
Block(-10,28,3,LEAVES:15)
Block(-9,28,3,LEAVES:15)
Block(-8,28,3,LEAVES:15)
Block(-7,28,3,LEAVES:15)
Block(-6,28,3,LEAVES:15)
Block(-5,28,3,LEAVES:3)
Block(-4,28,3,LEAVES:15)
Block(-3,28,3,LEAVES:15)
Block(-1,28,3,LEAVES:15)
Block(0,28,3,LEAVES:15)
Block(1,28,3,LEAVES:3)
Block(2,28,3,LEAVES:3)
Block(3,28,3,LEAVES:3)
Block(4,28,3,LEAVES:15)
Block(6,28,3,LEAVES:15)
Block(7,28,3,LEAVES:15)
Block(8,28,3,LEAVES:15)
Block(9,28,3,LEAVES:15)
Block(-9,28,4,LEAVES:15)
Block(-8,28,4,LEAVES:3)
Block(-7,28,4,LEAVES:3)
Block(-6,28,4,LOG:15)
Block(-5,28,4,LEAVES:3)
Block(-4,28,4,LEAVES:3)
Block(-3,28,4,LEAVES:15)
Block(-2,28,4,LEAVES:15)
Block(-1,28,4,LEAVES:15)
Block(0,28,4,LEAVES:15)
Block(1,28,4,LEAVES:15)
Block(2,28,4,LEAVES:15)
Block(3,28,4,LEAVES:15)
Block(4,28,4,LEAVES:15)
Block(5,28,4,LEAVES:15)
Block(6,28,4,LEAVES:15)
Block(7,28,4,LEAVES:15)
Block(8,28,4,LEAVES:15)
Block(9,28,4,LEAVES:15)
Block(10,28,4,LEAVES:15)
Block(-8,28,5,LEAVES:3)
Block(-7,28,5,LOG:15)
Block(-6,28,5,LOG:15)
Block(-5,28,5,LEAVES:3)
Block(-4,28,5,LEAVES:15)
Block(-3,28,5,LEAVES:15)
Block(-2,28,5,LEAVES:15)
Block(-1,28,5,LEAVES:15)
Block(0,28,5,LEAVES:15)
Block(1,28,5,LEAVES:15)
Block(2,28,5,LEAVES:15)
Block(3,28,5,LEAVES:15)
Block(4,28,5,LEAVES:15)
Block(5,28,5,LEAVES:15)
Block(6,28,5,LEAVES:15)
Block(7,28,5,LEAVES:15)
Block(8,28,5,LEAVES:15)
Block(9,28,5,LEAVES:15)
Block(10,28,5,LEAVES:15)
Block(-9,28,6,LEAVES:15)
Block(-8,28,6,LEAVES:3)
Block(-7,28,6,LOG:15)
Block(-6,28,6,LEAVES:3)
Block(-5,28,6,LEAVES:15)
Block(-4,28,6,LEAVES:15)
Block(-3,28,6,LEAVES:15)
Block(-2,28,6,LEAVES:15)
Block(-1,28,6,LEAVES:15)
Block(0,28,6,LEAVES:15)
Block(1,28,6,LEAVES:15)
Block(2,28,6,LEAVES:15)
Block(3,28,6,LEAVES:15)
Block(4,28,6,LEAVES:15)
Block(5,28,6,LEAVES:15)
Block(6,28,6,LEAVES:15)
Block(7,28,6,LEAVES:15)
Block(8,28,6,LEAVES:15)
Block(9,28,6,LEAVES:15)
Block(10,28,6,LEAVES:15)
Block(-9,28,7,LOG:15)
Block(-8,28,7,LEAVES:15)
Block(-7,28,7,LEAVES:3)
Block(-6,28,7,LEAVES:15)
Block(-5,28,7,LEAVES:15)
Block(-4,28,7,LEAVES:15)
Block(-3,28,7,LEAVES:15)
Block(-1,28,7,LEAVES:15)
Block(0,28,7,LEAVES:15)
Block(1,28,7,LEAVES:15)
Block(2,28,7,LEAVES:15)
Block(3,28,7,LEAVES:15)
Block(4,28,7,LEAVES:15)
Block(5,28,7,LEAVES:15)
Block(6,28,7,LEAVES:15)
Block(8,28,7,LEAVES:3)
Block(9,28,7,LEAVES:3)
Block(10,28,7,LEAVES:3)
Block(-9,28,8,LEAVES:15)
Block(-8,28,8,LEAVES:15)
Block(-5,28,8,LEAVES:15)
Block(-4,28,8,LEAVES:15)
Block(-3,28,8,LEAVES:15)
Block(-2,28,8,LEAVES:15)
Block(0,28,8,LEAVES:15)
Block(1,28,8,LEAVES:15)
Block(2,28,8,LEAVES:15)
Block(3,28,8,LEAVES:15)
Block(4,28,8,LEAVES:15)
Block(5,28,8,LEAVES:15)
Block(6,28,8,LEAVES:15)
Block(7,28,8,LEAVES:15)
Block(8,28,8,LEAVES:3)
Block(9,28,8,LEAVES:15)
Block(10,28,8,LEAVES:15)
Block(-9,28,9,LEAVES:15)
Block(-8,28,9,LEAVES:15)
Block(-4,28,9,LEAVES:15)
Block(-3,28,9,LEAVES:15)
Block(-2,28,9,LEAVES:15)
Block(1,28,9,LEAVES:15)
Block(2,28,9,LEAVES:15)
Block(3,28,9,LEAVES:15)
Block(4,28,9,LEAVES:15)
Block(5,28,9,LEAVES:15)
Block(6,28,9,LEAVES:15)
Block(7,28,9,LEAVES:15)
Block(8,28,9,LEAVES:3)
Block(9,28,9,LEAVES:3)
Block(-4,28,10,LEAVES:15)
Block(-3,28,10,LEAVES:15)
Block(-2,28,10,LEAVES:15)
Block(0,28,10,LEAVES:15)
Block(3,28,10,LEAVES:15)
Block(4,28,10,LEAVES:15)
Block(5,28,10,LEAVES:15)
Block(6,28,10,LEAVES:15)
Block(7,28,10,LEAVES:15)
Block(8,28,10,LEAVES:15)
Block(-3,28,11,LEAVES:15)
Block(-1,28,11,LEAVES:15)
Block(0,28,11,LEAVES:15)
Block(2,28,11,LEAVES:15)
Block(3,28,11,LEAVES:15)
Block(4,28,11,LEAVES:15)
Block(5,28,11,LEAVES:15)
Block(6,28,11,LEAVES:15)
Block(8,28,11,LEAVES:15)
Block(-3,28,12,LEAVES:15)
Block(3,28,12,LEAVES:15)
Block(4,28,12,LEAVES:15)
Block(-11,29,-14,LEAVES:15)
Block(-2,29,-14,LEAVES:15)
Block(-1,29,-14,LEAVES:15)
Block(0,29,-14,LEAVES:15)
Block(-13,29,-13,LEAVES:3)
Block(-12,29,-13,LEAVES:15)
Block(-11,29,-13,LEAVES:3)
Block(-10,29,-13,LEAVES:15)
Block(-7,29,-13,LEAVES:15)
Block(-6,29,-13,LEAVES:15)
Block(-5,29,-13,LEAVES:15)
Block(-2,29,-13,LEAVES:15)
Block(-1,29,-13,LEAVES:3)
Block(0,29,-13,LEAVES:15)
Block(2,29,-13,LEAVES:15)
Block(3,29,-13,LEAVES:15)
Block(-13,29,-12,LEAVES:15)
Block(-12,29,-12,LOG:15)
Block(-11,29,-12,LEAVES:3)
Block(-10,29,-12,LEAVES:3)
Block(-9,29,-12,LEAVES:15)
Block(-7,29,-12,LEAVES:15)
Block(-6,29,-12,LEAVES:15)
Block(-5,29,-12,LEAVES:15)
Block(-4,29,-12,LEAVES:15)
Block(-3,29,-12,LEAVES:3)
Block(-2,29,-12,LOG:15)
Block(-1,29,-12,LOG:15)
Block(0,29,-12,LEAVES:3)
Block(1,29,-12,LEAVES:15)
Block(2,29,-12,LEAVES:3)
Block(3,29,-12,LEAVES:15)
Block(-11,29,-11,LEAVES:3)
Block(-10,29,-11,LEAVES:3)
Block(-9,29,-11,LEAVES:15)
Block(-8,29,-11,LEAVES:15)
Block(-7,29,-11,LEAVES:15)
Block(-6,29,-11,LEAVES:15)
Block(-5,29,-11,LEAVES:15)
Block(-4,29,-11,LEAVES:3)
Block(-3,29,-11,LOG:15)
Block(-2,29,-11,LOG:15)
Block(-1,29,-11,LEAVES:3)
Block(0,29,-11,LEAVES:15)
Block(1,29,-11,LEAVES:3)
Block(2,29,-11,LEAVES:3)
Block(3,29,-11,LEAVES:3)
Block(4,29,-11,LEAVES:15)
Block(5,29,-11,LEAVES:15)
Block(6,29,-11,LEAVES:15)
Block(-11,29,-10,LEAVES:3)
Block(-10,29,-10,LEAVES:3)
Block(-9,29,-10,LEAVES:3)
Block(-8,29,-10,LEAVES:15)
Block(-7,29,-10,LEAVES:15)
Block(-6,29,-10,LEAVES:15)
Block(-5,29,-10,LEAVES:15)
Block(-4,29,-10,LEAVES:3)
Block(-3,29,-10,LOG:15)
Block(-2,29,-10,LEAVES:3)
Block(-1,29,-10,LEAVES:15)
Block(0,29,-10,LEAVES:15)
Block(1,29,-10,LEAVES:15)
Block(2,29,-10,LEAVES:3)
Block(3,29,-10,LEAVES:15)
Block(6,29,-10,LEAVES:15)
Block(-15,29,-9,LEAVES:15)
Block(-14,29,-9,LEAVES:15)
Block(-13,29,-9,LEAVES:15)
Block(-12,29,-9,LEAVES:15)
Block(-11,29,-9,LEAVES:15)
Block(-10,29,-9,LEAVES:3)
Block(-9,29,-9,LEAVES:3)
Block(-8,29,-9,LEAVES:3)
Block(-7,29,-9,LEAVES:15)
Block(-6,29,-9,LEAVES:15)
Block(-5,29,-9,LEAVES:3)
Block(-4,29,-9,LEAVES:3)
Block(-3,29,-9,LEAVES:3)
Block(-2,29,-9,LEAVES:3)
Block(-1,29,-9,LEAVES:15)
Block(0,29,-9,LEAVES:15)
Block(1,29,-9,LEAVES:3)
Block(2,29,-9,LOG:15)
Block(3,29,-9,LEAVES:3)
Block(5,29,-9,LEAVES:15)
Block(-15,29,-8,LEAVES:15)
Block(-14,29,-8,LOG:15)
Block(-13,29,-8,LEAVES:15)
Block(-12,29,-8,LEAVES:15)
Block(-11,29,-8,LEAVES:15)
Block(-9,29,-8,LEAVES:3)
Block(-8,29,-8,LOG:15)
Block(-7,29,-8,LOG:15)
Block(-6,29,-8,LEAVES:15)
Block(-5,29,-8,LEAVES:15)
Block(-4,29,-8,LEAVES:3)
Block(-3,29,-8,LEAVES:15)
Block(-2,29,-8,LEAVES:15)
Block(0,29,-8,LEAVES:15)
Block(1,29,-8,LEAVES:3)
Block(2,29,-8,LOG:15)
Block(3,29,-8,LOG:15)
Block(4,29,-8,LEAVES:15)
Block(5,29,-8,LEAVES:3)
Block(6,29,-8,LEAVES:15)
Block(7,29,-8,LEAVES:15)
Block(-15,29,-7,LEAVES:3)
Block(-14,29,-7,LOG:15)
Block(-13,29,-7,LEAVES:3)
Block(-12,29,-7,LEAVES:15)
Block(-10,29,-7,LEAVES:15)
Block(-9,29,-7,LEAVES:15)
Block(-8,29,-7,LEAVES:15)
Block(-7,29,-7,LEAVES:15)
Block(-6,29,-7,LEAVES:15)
Block(-5,29,-7,LEAVES:15)
Block(-4,29,-7,LEAVES:15)
Block(-3,29,-7,LEAVES:15)
Block(-2,29,-7,LEAVES:15)
Block(-1,29,-7,LEAVES:15)
Block(0,29,-7,LEAVES:15)
Block(1,29,-7,LEAVES:3)
Block(2,29,-7,LEAVES:3)
Block(3,29,-7,LEAVES:3)
Block(5,29,-7,LEAVES:15)
Block(7,29,-7,LEAVES:15)
Block(-14,29,-6,LEAVES:3)
Block(-13,29,-6,LEAVES:15)
Block(-12,29,-6,LEAVES:15)
Block(-11,29,-6,LEAVES:15)
Block(-10,29,-6,LEAVES:15)
Block(-9,29,-6,LEAVES:15)
Block(-8,29,-6,LEAVES:15)
Block(-7,29,-6,LEAVES:15)
Block(-6,29,-6,LEAVES:15)
Block(-5,29,-6,LEAVES:15)
Block(-4,29,-6,LEAVES:15)
Block(-3,29,-6,LEAVES:15)
Block(-2,29,-6,LEAVES:15)
Block(-1,29,-6,LEAVES:15)
Block(0,29,-6,LEAVES:15)
Block(1,29,-6,LEAVES:15)
Block(2,29,-6,LEAVES:3)
Block(3,29,-6,LEAVES:3)
Block(4,29,-6,LEAVES:3)
Block(7,29,-6,LEAVES:15)
Block(8,29,-6,LEAVES:3)
Block(-13,29,-5,LEAVES:15)
Block(-12,29,-5,LEAVES:15)
Block(-10,29,-5,LEAVES:15)
Block(-9,29,-5,LEAVES:15)
Block(-8,29,-5,LEAVES:15)
Block(-7,29,-5,LEAVES:15)
Block(-6,29,-5,LEAVES:15)
Block(-5,29,-5,LEAVES:15)
Block(-4,29,-5,LEAVES:15)
Block(-3,29,-5,LEAVES:15)
Block(-2,29,-5,LEAVES:15)
Block(-1,29,-5,LEAVES:15)
Block(0,29,-5,LEAVES:15)
Block(1,29,-5,LEAVES:15)
Block(2,29,-5,LEAVES:3)
Block(3,29,-5,LOG:15)
Block(4,29,-5,LEAVES:3)
Block(5,29,-5,LEAVES:15)
Block(6,29,-5,LEAVES:15)
Block(7,29,-5,LEAVES:3)
Block(8,29,-5,LEAVES:3)
Block(9,29,-5,LEAVES:3)
Block(-14,29,-4,LEAVES:15)
Block(-13,29,-4,LEAVES:15)
Block(-12,29,-4,LEAVES:15)
Block(-10,29,-4,LEAVES:15)
Block(-9,29,-4,LEAVES:15)
Block(-8,29,-4,LEAVES:15)
Block(-6,29,-4,LEAVES:15)
Block(-5,29,-4,LEAVES:15)
Block(-4,29,-4,LEAVES:15)
Block(-3,29,-4,LEAVES:15)
Block(-2,29,-4,LEAVES:15)
Block(-1,29,-4,LEAVES:15)
Block(0,29,-4,LEAVES:15)
Block(1,29,-4,LEAVES:15)
Block(2,29,-4,LEAVES:3)
Block(3,29,-4,LEAVES:3)
Block(4,29,-4,LEAVES:3)
Block(5,29,-4,LEAVES:15)
Block(6,29,-4,LEAVES:15)
Block(7,29,-4,LEAVES:15)
Block(8,29,-4,LEAVES:3)
Block(-13,29,-3,LEAVES:15)
Block(-9,29,-3,LEAVES:15)
Block(-8,29,-3,LEAVES:15)
Block(-7,29,-3,LEAVES:15)
Block(-5,29,-3,LEAVES:15)
Block(-4,29,-3,LEAVES:15)
Block(-3,29,-3,LEAVES:15)
Block(-2,29,-3,LEAVES:15)
Block(-1,29,-3,LEAVES:15)
Block(0,29,-3,LEAVES:15)
Block(1,29,-3,LEAVES:15)
Block(2,29,-3,LEAVES:15)
Block(3,29,-3,LEAVES:15)
Block(4,29,-3,LEAVES:15)
Block(5,29,-3,LEAVES:15)
Block(6,29,-3,LEAVES:15)
Block(7,29,-3,LEAVES:15)
Block(8,29,-3,LEAVES:15)
Block(9,29,-3,LEAVES:15)
Block(-9,29,-2,LEAVES:15)
Block(-8,29,-2,LEAVES:15)
Block(-7,29,-2,LEAVES:15)
Block(-6,29,-2,LEAVES:15)
Block(-4,29,-2,LEAVES:15)
Block(-3,29,-2,LEAVES:15)
Block(-2,29,-2,LEAVES:15)
Block(-1,29,-2,LEAVES:15)
Block(0,29,-2,LEAVES:15)
Block(1,29,-2,LEAVES:15)
Block(2,29,-2,LEAVES:15)
Block(3,29,-2,LEAVES:15)
Block(4,29,-2,LEAVES:15)
Block(6,29,-2,LEAVES:15)
Block(7,29,-2,LEAVES:15)
Block(8,29,-2,LEAVES:15)
Block(9,29,-2,LEAVES:15)
Block(-9,29,-1,LEAVES:15)
Block(-8,29,-1,LEAVES:15)
Block(-7,29,-1,LEAVES:15)
Block(-5,29,-1,LEAVES:15)
Block(-4,29,-1,LEAVES:15)
Block(-3,29,-1,LEAVES:15)
Block(-2,29,-1,LEAVES:15)
Block(-1,29,-1,LEAVES:15)
Block(0,29,-1,LEAVES:15)
Block(1,29,-1,LEAVES:15)
Block(2,29,-1,LEAVES:15)
Block(3,29,-1,LEAVES:15)
Block(4,29,-1,LEAVES:15)
Block(5,29,-1,LEAVES:15)
Block(6,29,-1,LEAVES:15)
Block(7,29,-1,LEAVES:15)
Block(8,29,-1,LEAVES:15)
Block(9,29,-1,LEAVES:15)
Block(-8,29,0,LEAVES:15)
Block(-7,29,0,LEAVES:15)
Block(-6,29,0,LEAVES:15)
Block(-5,29,0,LEAVES:15)
Block(-4,29,0,LEAVES:15)
Block(-3,29,0,LEAVES:15)
Block(-2,29,0,LEAVES:15)
Block(-1,29,0,LEAVES:15)
Block(0,29,0,LEAVES:15)
Block(1,29,0,LEAVES:15)
Block(2,29,0,LEAVES:15)
Block(3,29,0,LEAVES:15)
Block(4,29,0,LEAVES:15)
Block(5,29,0,LEAVES:15)
Block(6,29,0,LEAVES:15)
Block(7,29,0,LEAVES:15)
Block(8,29,0,LEAVES:15)
Block(9,29,0,LEAVES:15)
Block(-10,29,1,LEAVES:15)
Block(-7,29,1,LEAVES:15)
Block(-6,29,1,LEAVES:15)
Block(-5,29,1,LEAVES:15)
Block(-4,29,1,LEAVES:15)
Block(-3,29,1,LEAVES:15)
Block(-2,29,1,LEAVES:15)
