
#
# +-----------------------------------------------------------------+ #
# |                            BO3 object                           | #
# +-----------------------------------------------------------------+ #
#

Author: NLBlackEagle

Description: No description given

Version: 3

SettingsMode: WriteDisable


#
# +-----------------------------------------------------------------+ #
# |                          Main settings                          | #
# +-----------------------------------------------------------------+ #
#

Tree: true

Frequency: 1

Rarity: 100.0

RotateRandomly: true

SpawnHeight: highestSolidBlock

SpawnHeightOffset: 0

SpawnHeightVariance: 0


# Height Limits for the BO3. #


MinHeight: 60

MaxHeight: 256


# Extrusion settings #


ExtrudeMode: None

ExtrudeThroughBlocks: air

MaxBranchDepth: 10

ExcludedBiomes: All


#
# +-----------------------------------------------------------------+ #
# |                      Source block settings                      | #
# +-----------------------------------------------------------------+ #
#

SourceBlocks: AIR,GRASS,DIRT,SAND

MaxPercentageOutsideSourceBlock: 0

OutsideSourceBlock: placeAnyway


#
# +-----------------------------------------------------------------+ #
# |                              Blocks                             | #
# +-----------------------------------------------------------------+ #
#

B(-4,6,0,leaves:3)
B(-3,5,0,leaves:3)
B(-3,6,-1,leaves:3)
B(-3,6,0,log:7)
B(-3,6,1,leaves:3)
B(-3,7,0,leaves:3)
B(-2,5,0,log:7)
B(-2,6,-1,leaves:3)
B(-2,6,0,leaves:3)
B(-2,6,1,leaves:3)
B(-2,7,-1,leaves:3)
B(-2,7,0,leaves:3)
B(-2,7,1,leaves:3)
B(-2,8,0,leaves:3)
B(-1,4,0,leaves:3)
B(-1,5,-1,leaves:3)
B(-1,5,0,log:7)
B(-1,5,1,leaves:3)
B(-1,6,-2,leaves:3)
B(-1,6,-1,leaves:3)
B(-1,6,0,leaves:3)
B(-1,6,1,leaves:3)
B(-1,6,2,leaves:3)
B(-1,7,-1,leaves:3)
B(-1,7,0,leaves:3)
B(-1,7,1,leaves:3)
B(-1,8,-1,leaves:3)
B(-1,8,0,leaves:3)
B(0,-6,0,log:3)
B(0,-5,0,log:3)
B(0,-4,0,log:3)
B(0,-3,0,log:3)
B(0,-2,0,log:3)
B(0,-1,0,log:3)
B(0,0,0,log:3)
B(0,1,0,log:3)
B(0,2,0,log:3)
B(0,3,0,log:3)
B(0,4,-1,LOG:11)
B(0,4,0,log:3)
B(0,5,-2,LOG:11)
B(0,5,-1,leaves:3)
B(0,5,0,log:3)
B(0,5,1,LOG:11)
B(0,5,2,leaves:3)
B(0,6,-3,leaves:3)
B(0,6,-2,log:3)
B(0,6,-1,leaves:3)
B(0,6,0,leaves:3)
B(0,6,1,leaves:3)
B(0,6,2,LOG:11)
B(0,6,3,leaves:3)
B(0,7,-2,leaves:3)
B(0,7,-1,leaves:3)
B(0,7,0,leaves:3)
B(0,7,1,leaves:3)
B(0,7,2,leaves:3)
B(0,8,-1,leaves:3)
B(0,8,0,leaves:3)
B(0,8,1,leaves:3)
B(1,4,0,log:7)
B(1,5,-1,leaves:3)
B(1,5,0,leaves:3)
B(1,5,1,leaves:3)
B(1,6,-2,leaves:3)
B(1,6,-1,leaves:3)
B(1,6,0,leaves:3)
B(1,6,1,leaves:3)
B(1,6,2,leaves:3)
B(1,7,-1,leaves:3)
B(1,7,0,leaves:3)
B(1,7,1,leaves:3)
B(1,8,0,leaves:3)
B(1,8,1,leaves:3)
B(2,5,0,log:3)
B(2,6,-1,leaves:3)
B(2,6,0,log:3)
B(2,6,1,leaves:3)
B(2,7,-1,leaves:3)
B(2,7,0,leaves:3)
B(2,7,1,leaves:3)
B(2,8,0,leaves:3)
B(3,6,0,leaves:3)
B(3,7,-1,leaves:3)
B(3,7,0,log:7)
B(3,7,1,leaves:3)
B(3,8,0,leaves:3)
B(4,7,0,leaves:3)

#
# +-----------------------------------------------------------------+ #
# |                            BO3 checks                           | #
# +-----------------------------------------------------------------+ #
#

BlockCheck(0,-1,0,grass,dirt)
BlockCheckNot(0,0,0,water)
BlockCheckNot(0,1,0,water)
BlockCheckNot(-1,2,-1,water)
BlockCheckNot(-1,3,-1,water)
BlockCheckNot(-1,0,1,water)
BlockCheckNot(-1,0,1,water)

#
# +-----------------------------------------------------------------+ #
# |                             Branches                            | #
# +-----------------------------------------------------------------+ #
#

