
#
# +-----------------------------------------------------------------+ #
# |                            BO3 object                           | #
# +-----------------------------------------------------------------+ #
#

Author: NLBlackEagle

Description: No description given

Version: 3

SettingsMode: WriteDisable


#
# +-----------------------------------------------------------------+ #
# |                          Main settings                          | #
# +-----------------------------------------------------------------+ #
#

Tree: false

Frequency: 20

Rarity: 100.0

RotateRandomly: true

SpawnHeight: randomY

SpawnHeightOffset: 0

SpawnHeightVariance: 0


# Height Limits for the BO3. #


MinHeight: 50

MaxHeight: 100


# Extrusion settings #


ExtrudeMode: None

ExtrudeThroughBlocks: air

MaxBranchDepth: 10

ExcludedBiomes: All


#
# +-----------------------------------------------------------------+ #
# |                      Source block settings                      | #
# +-----------------------------------------------------------------+ #
#

SourceBlocks: AIR,GRASS,DIRT,SAND

MaxPercentageOutsideSourceBlock: 45

OutsideSourceBlock: dontPlace


#
# +-----------------------------------------------------------------+ #
# |                              Blocks                             | #
# +-----------------------------------------------------------------+ #
#

B(-15,0,-14,LOG:11)
B(-15,0,-13,log:3)
B(-15,0,15,LOG:11)
B(-14,0,-15,log:3)
B(-14,0,-14,LOG:11)
B(-14,0,-13,LOG:11)
B(-14,0,-12,log:7)
B(-14,0,14,log:3)
B(-14,0,15,log:3)
B(-14,0,16,log:3)
B(-14,1,-14,LOG:11)
B(-14,1,-13,log:3)
B(-14,1,14,log:7)
B(-14,1,15,LOG:11)
B(-14,27,-1,leaves:3)
B(-14,28,-3,leaves:3)
B(-14,28,-2,leaves:3)
B(-14,28,-1,leaves:3)
B(-14,28,0,leaves:3)
B(-14,29,-4,leaves:3)
B(-14,29,-3,leaves:3)
B(-14,29,-2,log:7)
B(-14,29,-1,log:7)
B(-14,30,-3,leaves:3)
B(-14,30,-1,LOG:11)
B(-13,0,-14,LOG:11)
B(-13,0,-13,LOG:11)
B(-13,0,-12,log:3)
B(-13,0,-11,log:7)
B(-13,0,3,log:7)
B(-13,0,4,LOG:11)
B(-13,0,14,log:3)
B(-13,0,15,log:7)
B(-13,0,16,log:7)
B(-13,1,-13,log:3)
B(-13,1,-12,log:7)
B(-13,1,13,log:3)
B(-13,1,14,LOG:11)
B(-13,1,15,LOG:11)
B(-13,1,16,log:7)
B(-13,2,-12,log:7)
B(-13,2,-11,log:7)
B(-13,2,13,log:7)
B(-13,2,14,log:7)
B(-13,2,15,log:7)
B(-13,3,-11,LOG:11)
B(-13,3,-10,LOG:11)
B(-13,3,13,log:7)
B(-13,4,13,log:3)
B(-13,24,0,leaves:3)
B(-13,25,0,leaves:3)
B(-13,26,0,leaves:3)
B(-13,27,-2,leaves:3)
B(-13,27,-1,leaves:3)
B(-13,27,0,leaves:3)
B(-13,28,-4,leaves:3)
B(-13,28,-3,leaves:3)
B(-13,28,-2,LOG:11)
B(-13,28,-1,LOG:11)
B(-13,28,0,leaves:3)
B(-13,29,-4,leaves:3)
B(-13,29,-3,log:3)
B(-13,29,-2,LOG:11)
B(-13,29,-1,log:3)
B(-13,29,0,log:3)
B(-13,30,-4,leaves:3)
B(-13,30,-3,leaves:3)
B(-13,30,-2,log:3)
B(-13,30,-1,log:7)
B(-13,30,0,log:3)
B(-13,30,1,leaves:3)
B(-13,31,-1,log:3)
B(-13,31,0,leaves:3)
B(-13,32,-2,leaves:3)
B(-13,32,-1,leaves:3)
B(-13,32,0,leaves:3)
B(-13,33,-1,leaves:3)
B(-12,0,-13,log:3)
B(-12,0,-12,log:3)
B(-12,0,-11,log:7)
B(-12,0,-9,log:3)
B(-12,0,1,log:7)
B(-12,0,2,LOG:11)
B(-12,0,9,log:3)
B(-12,0,12,log:3)
B(-12,0,14,log:7)
B(-12,0,15,log:7)
B(-12,1,-13,LOG:11)
B(-12,1,-12,log:3)
B(-12,1,-11,log:3)
B(-12,1,-9,log:3)
B(-12,1,9,log:3)
B(-12,1,12,log:3)
B(-12,1,13,log:3)
B(-12,1,14,log:7)
B(-12,1,15,log:7)
B(-12,2,-13,LOG:11)
B(-12,2,-12,log:7)
B(-12,2,-11,log:3)
B(-12,2,-10,log:7)
B(-12,2,-9,log:3)
B(-12,2,9,log:3)
B(-12,2,12,log:7)
B(-12,2,13,log:3)
B(-12,2,14,log:3)
B(-12,2,15,log:3)
B(-12,3,-12,log:7)
B(-12,3,-11,log:7)
B(-12,3,-10,log:3)
B(-12,3,-9,log:3)
B(-12,3,9,log:7)
B(-12,3,12,LOG:11)
B(-12,3,13,LOG:11)
B(-12,3,14,log:3)
B(-12,4,-11,log:3)
B(-12,4,-10,log:7)
B(-12,4,-9,log:3)
B(-12,4,12,LOG:11)
B(-12,4,13,log:7)
B(-12,4,14,LOG:11)
B(-12,5,12,LOG:11)
B(-12,5,13,log:7)
B(-12,27,-1,leaves:3)
B(-12,28,-3,leaves:3)
B(-12,28,-2,leaves:3)
B(-12,28,-1,leaves:3)
B(-12,28,0,leaves:3)
B(-12,29,-4,leaves:3)
B(-12,29,-3,leaves:3)
B(-12,29,-2,LOG:11)
B(-12,29,-1,log:7)
B(-12,29,0,leaves:3)
B(-12,29,1,leaves:3)
B(-12,30,-3,leaves:3)
B(-12,30,-2,LOG:11)
B(-12,30,-1,LOG:11)
B(-12,30,0,log:3)
B(-12,30,1,leaves:3)
B(-12,31,-3,leaves:3)
B(-12,31,-2,log:3)
B(-12,31,-1,LOG:11)
B(-12,31,0,log:3)
B(-12,31,1,leaves:3)
B(-12,32,-2,leaves:3)
B(-12,32,-1,log:7)
B(-12,32,0,LOG:11)
B(-12,33,-2,leaves:3)
B(-12,33,-1,leaves:3)
B(-12,33,0,leaves:3)
B(-11,0,-12,log:7)
B(-11,0,-7,log:3)
B(-11,0,0,log:7)
B(-11,0,1,LOG:11)
B(-11,0,2,LOG:11)
B(-11,0,3,log:7)
B(-11,1,-12,log:7)
B(-11,1,-7,log:3)
B(-11,1,0,log:7)
B(-11,1,1,LOG:11)
B(-11,1,2,log:7)
B(-11,1,14,log:3)
B(-11,2,-12,log:7)
B(-11,2,-11,log:7)
B(-11,2,-10,log:3)
B(-11,2,-9,log:7)
B(-11,2,-7,log:7)
B(-11,2,0,log:3)
B(-11,2,1,log:7)
B(-11,2,12,LOG:11)
B(-11,2,13,log:7)
B(-11,2,14,LOG:11)
B(-11,3,-11,LOG:11)
B(-11,3,-10,LOG:11)
B(-11,3,-9,LOG:11)
B(-11,3,-8,log:3)
B(-11,3,9,log:3)
B(-11,3,11,log:7)
B(-11,3,12,log:3)
B(-11,3,13,LOG:11)
B(-11,3,14,log:7)
B(-11,4,-10,log:7)
B(-11,4,-9,log:7)
B(-11,4,-8,log:3)
B(-11,4,9,log:7)
B(-11,4,11,LOG:11)
B(-11,4,12,log:3)
B(-11,4,13,LOG:11)
B(-11,5,-9,LOG:11)
B(-11,5,-8,log:7)
B(-11,5,11,LOG:11)
B(-11,5,12,LOG:11)
B(-11,5,13,log:3)
B(-11,6,-8,LOG:11)
B(-11,6,12,log:7)
B(-11,8,-6,leaves:3)
B(-11,29,0,leaves:3)
B(-11,30,-3,leaves:3)
B(-11,30,-2,leaves:3)
B(-11,30,-1,log:3)
B(-11,30,0,log:7)
B(-11,30,1,leaves:3)
B(-11,31,-3,leaves:3)
B(-11,31,-2,log:3)
B(-11,31,-1,log:3)
B(-11,31,0,log:3)
B(-11,31,1,LOG:11)
B(-11,32,-3,leaves:3)
B(-11,32,-2,leaves:3)
B(-11,32,-1,log:3)
B(-11,32,0,log:3)
B(-11,32,1,LOG:11)
B(-11,32,2,leaves:3)
B(-11,33,-2,leaves:3)
B(-11,33,-1,leaves:3)
B(-11,33,0,log:3)
B(-11,33,1,leaves:3)
B(-11,34,-1,leaves:3)
B(-10,0,-10,log:3)
B(-10,0,-5,log:3)
B(-10,0,-3,log:3)
B(-10,0,0,log:3)
B(-10,0,1,LOG:11)
B(-10,0,2,log:7)
B(-10,0,8,log:3)
B(-10,1,-10,log:3)
B(-10,1,-5,log:3)
B(-10,1,-3,log:7)
B(-10,1,-1,log:7)
B(-10,1,0,log:3)
B(-10,1,1,LOG:11)
B(-10,1,2,log:7)
B(-10,1,8,log:3)
B(-10,1,10,log:3)
B(-10,2,-10,log:3)
B(-10,2,-7,log:3)
B(-10,2,-5,log:3)
B(-10,2,-1,log:7)
B(-10,2,0,log:3)
B(-10,2,1,LOG:11)
B(-10,2,2,log:7)
B(-10,2,10,log:3)
B(-10,3,-10,LOG:11)
B(-10,3,-9,log:3)
B(-10,3,-8,LOG:11)
B(-10,3,-7,log:3)
B(-10,3,-5,log:7)
B(-10,3,0,log:7)
B(-10,3,1,log:3)
B(-10,3,10,log:3)
B(-10,3,12,log:7)
B(-10,3,13,log:7)
B(-10,4,-10,LOG:11)
B(-10,4,-9,log:3)
B(-10,4,-8,log:3)
B(-10,4,-7,LOG:11)
B(-10,4,0,LOG:11)
B(-10,4,9,LOG:11)
B(-10,4,10,log:3)
B(-10,4,11,log:7)
B(-10,4,12,log:7)
B(-10,5,-9,log:3)
B(-10,5,-8,log:7)
B(-10,5,-7,log:3)
B(-10,5,0,log:3)
B(-10,5,10,LOG:11)
B(-10,5,11,log:3)
B(-10,5,12,log:7)
B(-10,5,13,log:3)
B(-10,6,-9,log:3)
B(-10,6,-8,LOG:11)
B(-10,6,-7,log:3)
B(-10,6,11,LOG:11)
B(-10,6,12,LOG:11)
B(-10,7,-8,LOG:11)
B(-10,7,-7,log:3)
B(-10,7,-6,log:7)
B(-10,7,10,log:7)
B(-10,7,11,log:3)
B(-10,8,-7,leaves:3)
B(-10,8,-6,log:3)
B(-10,8,-5,leaves:3)
B(-10,9,-6,leaves:3)
B(-10,26,-2,leaves:3)
B(-10,27,-2,leaves:3)
B(-10,28,-2,leaves:3)
B(-10,29,-2,leaves:3)
B(-10,30,-2,leaves:3)
B(-10,31,-3,leaves:3)
B(-10,31,-2,leaves:3)
B(-10,31,-1,log:7)
B(-10,31,0,log:3)
B(-10,31,1,leaves:3)
B(-10,31,2,leaves:3)
B(-10,32,-2,leaves:3)
B(-10,32,-1,log:3)
B(-10,32,0,log:3)
B(-10,32,1,log:7)
B(-10,32,2,leaves:3)
B(-10,33,-2,leaves:3)
B(-10,33,-1,log:3)
B(-10,33,0,log:3)
B(-10,33,1,log:7)
B(-10,33,2,leaves:3)
B(-10,34,-2,leaves:3)
B(-10,34,-1,leaves:3)
B(-10,34,0,LOG:11)
B(-10,35,0,leaves:3)
B(-9,0,-14,LOG:11)
B(-9,0,-12,log:7)
B(-9,0,6,log:3)
B(-9,1,-3,log:3)
B(-9,1,0,LOG:11)
B(-9,1,1,log:3)
B(-9,2,-3,log:3)
B(-9,2,-1,log:7)
B(-9,2,0,log:7)
B(-9,2,1,LOG:11)
B(-9,2,8,log:7)
B(-9,3,-5,log:3)
B(-9,3,-3,LOG:11)
B(-9,3,-2,log:3)
B(-9,3,-1,log:7)
B(-9,3,0,log:7)
B(-9,3,1,LOG:11)
B(-9,4,-9,LOG:11)
B(-9,4,-8,log:3)
B(-9,4,-5,log:3)
B(-9,4,-2,LOG:11)
B(-9,4,-1,log:3)
B(-9,4,0,log:3)
B(-9,4,1,log:3)
B(-9,4,12,log:3)
B(-9,5,-8,LOG:11)
B(-9,5,-7,LOG:11)
B(-9,5,-5,log:3)
B(-9,5,-1,log:3)
B(-9,5,0,log:3)
B(-9,5,1,log:3)
B(-9,5,11,log:3)
B(-9,5,12,log:3)
B(-9,5,13,log:3)
B(-9,6,-9,log:7)
B(-9,6,-8,log:3)
B(-9,6,-7,LOG:11)
B(-9,6,-6,log:7)
B(-9,6,-5,log:3)
B(-9,6,-1,log:3)
B(-9,6,0,log:7)
B(-9,6,10,log:7)
B(-9,6,11,LOG:11)
B(-9,6,12,LOG:11)
B(-9,6,13,log:3)
B(-9,7,-8,log:3)
B(-9,7,-7,log:3)
B(-9,7,-6,LOG:11)
B(-9,7,-5,log:7)
B(-9,7,9,log:3)
B(-9,7,10,LOG:11)
B(-9,7,11,log:3)
B(-9,7,12,log:7)
B(-9,8,-7,log:7)
B(-9,8,-6,log:7)
B(-9,8,-5,log:7)
B(-9,8,10,log:7)
B(-9,8,11,log:7)
B(-9,9,-6,log:7)
B(-9,31,1,leaves:3)
B(-9,31,10,leaves:3)
B(-9,32,-1,leaves:3)
B(-9,32,0,log:7)
B(-9,32,1,log:3)
B(-9,32,2,leaves:3)
B(-9,32,9,leaves:3)
B(-9,32,10,leaves:3)
B(-9,32,11,leaves:3)
B(-9,33,-2,leaves:3)
B(-9,33,-1,log:3)
B(-9,33,0,LOG:11)
B(-9,33,1,log:7)
B(-9,33,2,LOG:11)
B(-9,33,3,leaves:3)
B(-9,33,10,leaves:3)
B(-9,34,-1,log:3)
B(-9,34,0,LOG:11)
B(-9,34,1,log:3)
B(-9,34,2,leaves:3)
B(-9,34,10,leaves:3)
B(-9,34,11,log:3)
B(-9,35,-1,leaves:3)
B(-9,35,0,log:3)
B(-9,35,1,leaves:3)
B(-9,35,9,leaves:3)
B(-9,35,10,leaves:3)
B(-9,35,11,leaves:3)
B(-9,36,0,leaves:3)
B(-9,36,10,leaves:3)
B(-8,0,-13,log:7)
B(-8,0,-12,log:3)
B(-8,0,-11,LOG:11)
B(-8,0,8,log:3)
B(-8,1,-12,LOG:11)
B(-8,1,6,log:7)
B(-8,1,8,log:3)
B(-8,2,0,log:7)
B(-8,2,8,log:3)
B(-8,3,-8,log:3)
B(-8,3,0,LOG:11)
B(-8,3,2,log:3)
B(-8,3,8,LOG:11)
B(-8,3,9,log:3)
B(-8,4,-8,log:3)
B(-8,4,-1,LOG:11)
B(-8,4,0,log:7)
B(-8,4,1,log:3)
B(-8,4,2,LOG:11)
B(-8,4,9,log:3)
B(-8,5,-8,log:3)
B(-8,5,-2,log:3)
B(-8,5,-1,log:3)
B(-8,5,0,LOG:11)
B(-8,5,1,log:7)
B(-8,5,9,log:3)
B(-8,5,12,LOG:11)
B(-8,6,-8,log:7)
B(-8,6,-7,log:3)
B(-8,6,-6,log:3)
B(-8,6,-2,log:7)
B(-8,6,-1,log:7)
B(-8,6,0,log:7)
B(-8,6,9,LOG:11)
B(-8,6,10,log:7)
B(-8,6,11,LOG:11)
B(-8,6,12,LOG:11)
B(-8,7,-7,log:3)
B(-8,7,-6,log:3)
B(-8,7,-5,LOG:11)
B(-8,7,-2,log:7)
B(-8,7,-1,log:3)
B(-8,7,8,log:7)
B(-8,7,9,log:7)
B(-8,7,10,LOG:11)
B(-8,7,11,LOG:11)
B(-8,8,-8,log:7)
B(-8,8,-7,leaves:3)
B(-8,8,-6,log:3)
B(-8,8,-5,log:7)
B(-8,8,-4,log:3)
B(-8,8,9,log:7)
B(-8,8,10,log:7)
B(-8,9,-6,leaves:3)
B(-8,9,9,leaves:3)
B(-8,9,10,LOG:11)
B(-8,28,9,leaves:3)
B(-8,29,3,leaves:3)
B(-8,29,9,leaves:3)
B(-8,30,3,leaves:3)
B(-8,30,9,leaves:3)
B(-8,31,1,leaves:3)
B(-8,31,3,leaves:3)
B(-8,31,9,leaves:3)
B(-8,31,10,leaves:3)
B(-8,31,11,leaves:3)
B(-8,32,0,leaves:3)
B(-8,32,1,LOG:11)
B(-8,32,2,leaves:3)
B(-8,32,3,leaves:3)
B(-8,32,9,leaves:3)
B(-8,32,10,leaves:3)
B(-8,32,11,leaves:3)
B(-8,33,0,log:3)
B(-8,33,1,log:7)
B(-8,33,2,log:7)
B(-8,33,3,leaves:3)
B(-8,33,9,leaves:3)
B(-8,33,10,leaves:3)
B(-8,33,11,log:3)
B(-8,34,0,log:7)
B(-8,34,1,log:7)
B(-8,34,2,log:3)
B(-8,34,3,leaves:3)
B(-8,34,9,leaves:3)
B(-8,34,10,log:7)
B(-8,34,11,log:3)
B(-8,34,12,log:7)
B(-8,35,0,leaves:3)
B(-8,35,1,log:3)
B(-8,35,8,leaves:3)
B(-8,35,9,leaves:3)
B(-8,35,10,LOG:11)
B(-8,35,11,LOG:11)
B(-8,36,9,leaves:3)
B(-8,36,10,log:3)
B(-8,36,11,leaves:3)
B(-8,36,12,leaves:3)
B(-8,37,11,leaves:3)
B(-7,0,-13,log:7)
B(-7,0,-12,LOG:11)
B(-7,0,-11,log:3)
B(-7,0,2,log:3)
B(-7,0,6,log:3)
B(-7,1,-13,log:7)
B(-7,1,-12,log:3)
B(-7,1,-11,log:3)
B(-7,1,2,log:3)
B(-7,1,6,log:3)
B(-7,2,-12,log:7)
B(-7,2,-11,LOG:11)
B(-7,2,2,log:3)
B(-7,2,6,log:7)
B(-7,3,-6,log:3)
B(-7,3,2,log:7)
B(-7,4,-6,log:3)
B(-7,5,-6,log:3)
B(-7,5,-1,LOG:11)
B(-7,5,0,log:3)
B(-7,6,-6,log:3)
B(-7,6,-2,LOG:11)
B(-7,6,-1,log:7)
B(-7,6,0,log:3)
B(-7,6,9,LOG:11)
B(-7,7,-6,LOG:11)
B(-7,7,-5,log:7)
B(-7,7,-4,log:7)
B(-7,7,-3,log:7)
B(-7,7,-2,log:7)
B(-7,7,-1,log:7)
B(-7,7,0,log:7)
B(-7,7,8,log:3)
B(-7,7,9,log:7)
B(-7,7,10,log:3)
B(-7,8,-6,LOG:11)
B(-7,8,-5,log:3)
B(-7,8,-4,log:7)
B(-7,8,-3,log:7)
B(-7,8,-2,LOG:11)
B(-7,8,-1,LOG:11)
B(-7,8,9,log:3)
B(-7,8,10,log:3)
B(-7,9,-5,log:3)
B(-7,9,-4,LOG:11)
B(-7,9,-3,LOG:11)
B(-7,9,8,log:7)
B(-7,9,9,log:3)
B(-7,9,10,leaves:3)
B(-7,10,-3,LOG:11)
B(-7,10,9,leaves:3)
B(-7,11,-3,leaves:3)
B(-7,26,0,leaves:3)
B(-7,27,0,leaves:3)
B(-7,28,0,leaves:3)
B(-7,29,0,leaves:3)
B(-7,30,0,leaves:3)
B(-7,31,0,leaves:3)
B(-7,31,1,leaves:3)
B(-7,31,2,leaves:3)
B(-7,31,10,leaves:3)
B(-7,32,0,leaves:3)
B(-7,32,1,log:3)
B(-7,32,2,log:7)
B(-7,32,9,leaves:3)
B(-7,32,10,leaves:3)
B(-7,32,11,leaves:3)
B(-7,33,0,LOG:11)
B(-7,33,1,log:7)
B(-7,33,2,LOG:11)
B(-7,33,3,LOG:11)
B(-7,33,9,leaves:3)
B(-7,33,10,LOG:11)
B(-7,33,11,log:7)
B(-7,34,1,LOG:11)
B(-7,34,2,log:7)
B(-7,34,3,leaves:3)
B(-7,34,8,leaves:3)
B(-7,34,9,log:7)
B(-7,34,10,LOG:11)
B(-7,34,11,log:3)
B(-7,34,12,LOG:11)
B(-7,35,2,leaves:3)
B(-7,35,8,leaves:3)
B(-7,35,9,log:7)
B(-7,35,10,log:3)
B(-7,35,11,LOG:11)
B(-7,35,12,log:3)
B(-7,36,8,leaves:3)
B(-7,36,9,log:7)
B(-7,36,10,LOG:11)
B(-7,36,11,LOG:11)
B(-7,36,12,leaves:3)
B(-7,37,9,log:3)
B(-7,37,10,log:7)
B(-7,37,11,leaves:3)
B(-7,37,12,leaves:3)
B(-7,38,8,leaves:3)
B(-7,38,9,leaves:3)
B(-7,38,10,leaves:3)
B(-7,39,9,leaves:3)
B(-6,0,-12,log:7)
B(-6,0,4,log:3)
B(-6,1,-13,log:7)
B(-6,1,-12,log:3)
B(-6,1,-11,LOG:11)
B(-6,1,4,log:3)
B(-6,2,-13,LOG:11)
B(-6,2,-12,log:3)
B(-6,2,-11,log:7)
B(-6,2,-10,log:7)
B(-6,2,4,log:3)
B(-6,2,6,log:3)
B(-6,3,-12,LOG:11)
B(-6,3,-11,LOG:11)
B(-6,3,-10,log:3)
B(-6,3,-2,log:3)
B(-6,3,5,LOG:11)
B(-6,3,6,log:3)
B(-6,4,-2,log:3)
B(-6,4,6,LOG:11)
B(-6,4,7,log:3)
B(-6,5,-2,log:3)
B(-6,5,7,log:3)
B(-6,6,-4,log:7)
B(-6,6,-3,log:3)
B(-6,6,-2,LOG:11)
B(-6,6,-1,log:3)
B(-6,6,7,log:3)
B(-6,6,8,log:3)
B(-6,6,9,LOG:11)
B(-6,7,-5,log:3)
B(-6,7,-4,LOG:11)
B(-6,7,-3,log:3)
B(-6,7,-2,log:7)
B(-6,7,-1,LOG:11)
B(-6,7,7,log:3)
B(-6,7,8,log:7)
B(-6,7,9,log:3)
B(-6,7,10,log:3)
B(-6,8,-5,log:3)
B(-6,8,-4,LOG:11)
B(-6,8,-3,log:3)
B(-6,8,-2,log:3)
B(-6,8,7,log:3)
B(-6,8,8,LOG:11)
B(-6,8,9,LOG:11)
B(-6,9,-5,LOG:11)
B(-6,9,-4,LOG:11)
B(-6,9,-3,log:3)
B(-6,9,-2,LOG:11)
B(-6,9,7,log:7)
B(-6,9,8,LOG:11)
B(-6,9,9,log:3)
B(-6,9,10,LOG:11)
B(-6,10,-4,LOG:11)
B(-6,10,-3,log:7)
B(-6,10,-2,log:7)
B(-6,10,7,LOG:11)
B(-6,10,8,LOG:11)
B(-6,10,9,log:3)
B(-6,11,-4,leaves:3)
B(-6,11,-3,log:3)
B(-6,11,-2,log:3)
B(-6,12,-3,leaves:3)
B(-6,12,-2,leaves:3)
B(-6,30,2,leaves:3)
B(-6,31,1,leaves:3)
B(-6,31,2,log:3)
B(-6,31,3,leaves:3)
B(-6,32,0,leaves:3)
B(-6,32,1,LOG:11)
B(-6,32,2,log:7)
B(-6,32,3,log:3)
B(-6,32,10,leaves:3)
B(-6,33,1,log:7)
B(-6,33,2,LOG:11)
B(-6,33,3,LOG:11)
B(-6,33,9,leaves:3)
B(-6,33,10,leaves:3)
B(-6,33,11,leaves:3)
B(-6,34,1,leaves:3)
B(-6,34,2,log:3)
B(-6,34,3,leaves:3)
B(-6,34,9,leaves:3)
B(-6,34,10,log:3)
B(-6,34,11,log:7)
B(-6,34,12,leaves:3)
B(-6,35,1,leaves:3)
B(-6,35,2,leaves:3)
B(-6,35,3,leaves:3)
B(-6,35,8,leaves:3)
B(-6,35,9,log:3)
B(-6,35,10,LOG:11)
B(-6,35,11,log:7)
B(-6,35,12,leaves:3)
B(-6,36,7,leaves:3)
B(-6,36,8,log:7)
B(-6,36,9,LOG:11)
B(-6,36,10,LOG:11)
B(-6,36,11,log:3)
B(-6,36,12,leaves:3)
B(-6,37,8,LOG:11)
B(-6,37,9,log:3)
B(-6,37,10,log:7)
B(-6,37,11,leaves:3)
B(-6,38,8,log:7)
B(-6,38,9,log:7)
B(-6,38,10,leaves:3)
B(-6,39,8,leaves:3)
B(-6,39,9,leaves:3)
B(-6,39,10,leaves:3)
B(-5,0,-10,log:3)
B(-5,0,3,log:3)
B(-5,1,-12,log:7)
B(-5,1,-11,LOG:11)
B(-5,1,-10,log:3)
B(-5,1,3,log:3)
B(-5,2,-12,LOG:11)
B(-5,2,-11,log:7)
B(-5,2,-10,LOG:11)
B(-5,2,3,log:3)
B(-5,3,-12,LOG:11)
B(-5,3,-11,log:7)
B(-5,3,-10,LOG:11)
B(-5,3,-9,log:3)
B(-5,3,3,log:3)
B(-5,4,-11,log:3)
B(-5,4,-10,log:3)
B(-5,4,-9,log:3)
B(-5,4,3,log:3)
B(-5,5,-9,log:7)
B(-5,5,3,log:3)
B(-5,6,-3,log:3)
B(-5,6,-2,LOG:11)
B(-5,7,-4,LOG:11)
B(-5,7,-3,LOG:11)
B(-5,7,-2,LOG:11)
B(-5,7,-1,log:7)
B(-5,7,8,LOG:11)
B(-5,7,9,log:7)
B(-5,8,-4,LOG:11)
B(-5,8,-3,LOG:11)
B(-5,8,-2,log:7)
B(-5,8,6,log:7)
B(-5,8,7,LOG:11)
B(-5,8,8,log:7)
B(-5,9,-4,LOG:11)
B(-5,9,-3,LOG:11)
B(-5,9,-2,log:3)
B(-5,9,-1,LOG:11)
B(-5,9,6,LOG:11)
B(-5,9,7,log:3)
B(-5,9,8,LOG:11)
B(-5,9,9,log:3)
B(-5,10,-4,log:7)
B(-5,10,-3,LOG:11)
B(-5,10,-2,log:7)
B(-5,10,-1,log:7)
B(-5,10,6,LOG:11)
B(-5,10,7,LOG:11)
B(-5,10,8,log:3)
B(-5,11,-3,log:3)
B(-5,11,-2,log:3)
B(-5,11,-1,LOG:11)
B(-5,11,7,log:7)
B(-5,12,-3,leaves:3)
B(-5,12,-2,LOG:11)
B(-5,12,-1,LOG:11)
B(-5,12,0,log:7)
B(-5,13,-2,leaves:3)
B(-5,30,1,leaves:3)
B(-5,30,2,leaves:3)
B(-5,30,3,leaves:3)
B(-5,31,1,leaves:3)
B(-5,31,2,log:7)
B(-5,31,3,log:7)
B(-5,31,4,leaves:3)
B(-5,32,1,log:3)
B(-5,32,2,log:3)
B(-5,32,3,log:3)
B(-5,32,4,leaves:3)
B(-5,32,5,leaves:3)
B(-5,33,1,log:3)
B(-5,33,2,log:7)
B(-5,33,3,log:3)
B(-5,33,4,leaves:3)
B(-5,34,1,leaves:3)
B(-5,34,2,log:3)
B(-5,34,3,leaves:3)
B(-5,34,11,leaves:3)
B(-5,35,2,leaves:3)
B(-5,35,7,leaves:3)
B(-5,35,8,leaves:3)
B(-5,35,9,leaves:3)
B(-5,35,10,leaves:3)
B(-5,35,11,leaves:3)
B(-5,35,12,leaves:3)
B(-5,36,7,leaves:3)
B(-5,36,8,log:3)
B(-5,36,9,log:3)
B(-5,36,10,log:7)
B(-5,36,11,leaves:3)
B(-5,37,7,log:7)
B(-5,37,8,LOG:11)
B(-5,37,9,log:7)
B(-5,37,10,log:7)
B(-5,38,7,LOG:11)
B(-5,38,8,log:7)
B(-5,38,9,log:3)
B(-5,38,10,leaves:3)
B(-5,39,7,leaves:3)
B(-5,39,8,log:3)
B(-5,39,9,leaves:3)
B(-5,40,8,leaves:3)
B(-4,2,-11,log:7)
B(-4,2,-10,LOG:11)
B(-4,3,-11,log:3)
B(-4,3,-10,LOG:11)
B(-4,3,-9,log:7)
B(-4,3,0,log:3)
B(-4,4,-11,log:7)
B(-4,4,-10,log:3)
B(-4,4,-9,log:3)
B(-4,4,-8,LOG:11)
B(-4,4,0,log:3)
B(-4,5,-10,log:3)
B(-4,5,-9,log:3)
B(-4,5,-8,LOG:11)
B(-4,5,0,log:3)
B(-4,5,5,log:3)
B(-4,6,-9,log:3)
B(-4,6,0,log:3)
B(-4,6,3,log:7)
B(-4,6,5,log:3)
B(-4,7,-3,log:3)
B(-4,7,-2,LOG:11)
B(-4,7,0,log:3)
B(-4,7,5,log:3)
B(-4,8,-2,LOG:11)
B(-4,8,-1,log:3)
B(-4,8,0,log:3)
B(-4,8,5,log:3)
B(-4,8,7,LOG:11)
B(-4,9,-3,log:3)
B(-4,9,-2,LOG:11)
B(-4,9,-1,log:3)
B(-4,9,0,LOG:11)
B(-4,9,5,log:3)
B(-4,9,6,LOG:11)
B(-4,9,7,log:7)
B(-4,9,8,log:3)
B(-4,10,-3,log:7)
B(-4,10,-2,log:3)
B(-4,10,-1,log:3)
B(-4,10,0,log:7)
B(-4,10,5,log:3)
B(-4,10,6,LOG:11)
B(-4,10,7,LOG:11)
B(-4,10,8,log:3)
B(-4,11,-3,log:7)
B(-4,11,-2,log:3)
B(-4,11,-1,log:7)
B(-4,11,0,log:7)
B(-4,11,3,log:3)
B(-4,11,4,LOG:11)
B(-4,11,5,log:7)
B(-4,11,6,log:7)
B(-4,11,7,log:7)
B(-4,11,8,leaves:3)
B(-4,12,-2,log:7)
B(-4,12,-1,log:3)
B(-4,12,0,log:7)
B(-4,12,1,LOG:11)
B(-4,12,5,leaves:3)
B(-4,12,7,leaves:3)
B(-4,13,-1,log:3)
B(-4,13,0,log:7)
B(-4,13,1,log:3)
B(-4,13,2,leaves:3)
B(-4,20,4,leaves:3)
B(-4,24,4,leaves:3)
B(-4,25,2,leaves:3)
B(-4,30,2,leaves:3)
B(-4,30,3,LOG:11)
B(-4,31,1,leaves:3)
B(-4,31,2,log:7)
B(-4,31,3,log:7)
B(-4,31,4,log:3)
B(-4,31,5,leaves:3)
B(-4,31,8,leaves:3)
B(-4,32,1,LOG:11)
B(-4,32,2,log:3)
B(-4,32,3,LOG:11)
B(-4,32,4,log:3)
B(-4,32,5,leaves:3)
B(-4,32,8,leaves:3)
B(-4,33,2,log:3)
B(-4,33,3,LOG:11)
B(-4,33,4,leaves:3)
B(-4,33,5,leaves:3)
B(-4,33,8,leaves:3)
B(-4,34,8,leaves:3)
B(-4,35,8,leaves:3)
B(-4,36,7,leaves:3)
B(-4,36,8,log:3)
B(-4,36,9,leaves:3)
B(-4,37,7,log:3)
B(-4,37,8,log:7)
B(-4,37,9,log:3)
B(-4,37,10,leaves:3)
B(-4,38,7,log:3)
B(-4,38,8,log:3)
B(-4,38,9,LOG:11)
B(-4,39,7,leaves:3)
B(-4,39,8,log:7)
B(-4,39,9,leaves:3)
B(-4,40,7,leaves:3)
B(-4,40,8,leaves:3)
B(-4,40,9,leaves:3)
B(-3,0,-8,log:3)
B(-3,1,-8,log:3)
B(-3,2,-8,log:3)
B(-3,3,-10,log:7)
B(-3,3,-8,log:3)
B(-3,4,-10,LOG:11)
B(-3,4,-9,LOG:11)
B(-3,4,-8,log:7)
B(-3,4,3,log:3)
B(-3,5,-10,log:7)
B(-3,5,-9,log:7)
B(-3,5,-8,log:7)
B(-3,5,-7,log:3)
B(-3,5,3,log:3)
B(-3,6,-9,LOG:11)
B(-3,6,-8,log:3)
B(-3,6,-7,log:7)
B(-3,6,3,log:3)
B(-3,7,-8,log:7)
B(-3,7,-7,LOG:11)
B(-3,7,3,log:3)
B(-3,8,-7,LOG:11)
B(-3,8,3,log:3)
B(-3,9,-2,log:3)
B(-3,9,-1,log:7)
B(-3,9,3,log:3)
B(-3,9,5,log:7)
B(-3,9,6,LOG:11)
B(-3,10,-2,log:3)
B(-3,10,-1,log:3)
B(-3,10,3,log:7)
B(-3,10,4,log:3)
B(-3,10,5,log:3)
B(-3,10,6,LOG:11)
B(-3,10,7,log:3)
B(-3,11,-3,log:3)
B(-3,11,-2,log:7)
B(-3,11,-1,LOG:11)
B(-3,11,1,log:7)
B(-3,11,2,log:3)
B(-3,11,3,LOG:11)
B(-3,11,4,log:7)
B(-3,11,5,log:3)
B(-3,11,6,LOG:11)
B(-3,11,7,leaves:3)
B(-3,12,-3,log:7)
B(-3,12,-2,log:7)
B(-3,12,-1,LOG:11)
B(-3,12,0,log:3)
B(-3,12,1,LOG:11)
B(-3,12,2,LOG:11)
B(-3,12,3,LOG:11)
B(-3,12,4,log:3)
B(-3,12,5,LOG:11)
B(-3,12,6,leaves:3)
B(-3,13,-2,log:3)
B(-3,13,-1,log:3)
B(-3,13,0,log:7)
B(-3,13,1,log:3)
B(-3,13,2,LOG:11)
B(-3,13,3,leaves:3)
B(-3,13,5,leaves:3)
B(-3,14,-1,leaves:3)
B(-3,14,1,LOG:11)
B(-3,14,2,leaves:3)
B(-3,18,3,log:3)
B(-3,18,4,log:7)
B(-3,18,5,LOG:11)
B(-3,19,2,log:3)
B(-3,19,3,LOG:11)
B(-3,19,4,leaves:3)
B(-3,20,0,LOG:11)
B(-3,20,1,log:7)
B(-3,20,2,log:3)
B(-3,20,3,leaves:3)
B(-3,20,4,leaves:3)
B(-3,20,5,leaves:3)
B(-3,21,1,leaves:3)
B(-3,21,4,leaves:3)
B(-3,23,4,leaves:3)
B(-3,24,2,log:7)
B(-3,24,3,LOG:11)
B(-3,24,4,log:7)
B(-3,24,5,leaves:3)
B(-3,25,0,leaves:3)
B(-3,25,1,log:7)
B(-3,25,2,LOG:11)
B(-3,25,3,leaves:3)
B(-3,25,4,leaves:3)
B(-3,26,2,leaves:3)
B(-3,30,3,LOG:11)
B(-3,31,2,log:7)
B(-3,31,3,log:3)
B(-3,31,4,LOG:11)
B(-3,32,-7,leaves:3)
B(-3,32,-3,leaves:3)
B(-3,32,1,leaves:3)
B(-3,32,2,log:7)
B(-3,32,3,log:3)
B(-3,32,4,leaves:3)
B(-3,32,5,leaves:3)
B(-3,33,-8,leaves:3)
B(-3,33,-7,leaves:3)
B(-3,33,-6,leaves:3)
B(-3,33,-4,leaves:3)
B(-3,33,-3,leaves:3)
B(-3,33,-2,leaves:3)
B(-3,33,4,leaves:3)
B(-3,34,-9,leaves:3)
B(-3,34,-8,leaves:3)
B(-3,34,-7,leaves:3)
B(-3,34,-3,leaves:3)
B(-3,35,7,leaves:3)
B(-3,36,6,leaves:3)
B(-3,36,7,log:7)
B(-3,36,8,leaves:3)
B(-3,37,6,log:7)
B(-3,37,7,log:3)
B(-3,37,8,log:7)
B(-3,38,5,leaves:3)
B(-3,38,6,log:7)
B(-3,38,7,log:7)
B(-3,38,8,log:7)
B(-3,38,9,LOG:11)
B(-3,39,6,leaves:3)
B(-3,39,7,LOG:11)
B(-3,39,8,LOG:11)
B(-3,39,9,leaves:3)
B(-3,40,8,leaves:3)
B(-2,4,-8,LOG:11)
B(-2,5,-9,log:3)
B(-2,5,-8,log:7)
B(-2,5,-7,log:3)
B(-2,6,-9,LOG:11)
B(-2,6,-8,log:3)
B(-2,6,-7,log:3)
B(-2,6,-6,log:3)
B(-2,7,-9,LOG:11)
B(-2,7,-8,log:7)
B(-2,7,-7,log:3)
B(-2,7,-6,LOG:11)
B(-2,7,-5,log:7)
B(-2,8,-8,log:7)
B(-2,8,-7,log:7)
B(-2,8,-6,LOG:11)
B(-2,8,-5,log:7)
B(-2,9,-7,log:7)
B(-2,10,1,log:3)
B(-2,10,2,LOG:11)
B(-2,10,4,log:3)
B(-2,10,5,log:7)
B(-2,10,6,LOG:11)
B(-2,11,-2,LOG:11)
B(-2,11,-1,LOG:11)
B(-2,11,0,LOG:11)
B(-2,11,1,log:3)
B(-2,11,2,log:3)
B(-2,11,3,log:3)
B(-2,11,4,log:3)
B(-2,11,5,log:3)
B(-2,12,-2,log:7)
B(-2,12,-1,log:3)
B(-2,12,0,log:7)
B(-2,12,1,log:3)
B(-2,12,2,log:7)
B(-2,12,3,LOG:11)
B(-2,12,4,log:7)
B(-2,12,5,LOG:11)
B(-2,12,6,log:3)
B(-2,13,-2,log:7)
B(-2,13,-1,log:3)
B(-2,13,0,LOG:11)
B(-2,13,1,log:7)
B(-2,13,2,LOG:11)
B(-2,13,3,LOG:11)
B(-2,13,4,log:3)
B(-2,13,5,log:3)
B(-2,14,-1,log:7)
B(-2,14,0,LOG:11)
B(-2,14,1,log:7)
B(-2,17,3,LOG:11)
B(-2,17,4,log:3)
B(-2,17,5,LOG:11)
B(-2,18,2,LOG:11)
B(-2,18,3,log:7)
B(-2,18,4,log:7)
B(-2,18,5,LOG:11)
B(-2,18,6,log:7)
B(-2,19,0,log:3)
B(-2,19,1,log:3)
B(-2,19,2,LOG:11)
B(-2,19,3,log:7)
B(-2,19,4,LOG:11)
B(-2,19,5,LOG:11)
B(-2,19,6,leaves:3)
B(-2,20,-1,log:3)
B(-2,20,0,log:7)
B(-2,20,1,log:7)
B(-2,20,2,LOG:11)
B(-2,20,3,log:3)
B(-2,20,4,leaves:3)
B(-2,20,5,leaves:3)
B(-2,21,0,log:7)
B(-2,21,1,log:3)
B(-2,21,2,log:7)
B(-2,21,3,leaves:3)
B(-2,21,4,leaves:3)
B(-2,22,1,leaves:3)
B(-2,22,4,leaves:3)
B(-2,23,2,log:7)
B(-2,23,3,log:7)
B(-2,23,4,LOG:11)
B(-2,23,5,leaves:3)
B(-2,24,-1,leaves:3)
B(-2,24,0,leaves:3)
B(-2,24,1,log:3)
B(-2,24,2,log:7)
B(-2,24,3,LOG:11)
B(-2,24,4,log:7)
B(-2,24,5,log:7)
B(-2,25,-2,leaves:3)
B(-2,25,-1,leaves:3)
B(-2,25,0,log:7)
B(-2,25,1,log:7)
B(-2,25,2,log:3)
B(-2,25,3,LOG:11)
B(-2,25,4,log:7)
B(-2,26,-1,leaves:3)
B(-2,26,0,leaves:3)
B(-2,26,1,LOG:11)
B(-2,26,2,log:7)
B(-2,29,3,log:3)
B(-2,30,2,LOG:11)
B(-2,30,3,LOG:11)
B(-2,30,4,LOG:11)
B(-2,31,1,log:7)
B(-2,31,2,LOG:11)
B(-2,31,3,LOG:11)
B(-2,31,4,log:7)
B(-2,32,-8,leaves:3)
B(-2,32,-7,leaves:3)
B(-2,32,-6,leaves:3)
B(-2,32,-4,leaves:3)
B(-2,32,-3,leaves:3)
B(-2,32,-2,leaves:3)
B(-2,32,-1,LOG:11)
B(-2,32,0,leaves:3)
B(-2,32,1,log:7)
B(-2,32,2,leaves:3)
B(-2,32,3,LOG:11)
B(-2,33,-9,leaves:3)
B(-2,33,-8,leaves:3)
B(-2,33,-7,leaves:3)
B(-2,33,-6,leaves:3)
B(-2,33,-4,leaves:3)
B(-2,33,-3,log:7)
B(-2,33,-2,log:7)
B(-2,33,-1,log:3)
B(-2,33,1,leaves:3)
B(-2,34,-10,leaves:3)
B(-2,34,-9,leaves:3)
B(-2,34,-8,leaves:3)
B(-2,34,-7,leaves:3)
B(-2,34,-6,leaves:3)
B(-2,34,-4,log:3)
B(-2,34,-3,log:7)
B(-2,34,-2,leaves:3)
B(-2,35,-9,leaves:3)
B(-2,35,-8,leaves:3)
B(-2,35,-7,leaves:3)
B(-2,35,-6,leaves:3)
B(-2,35,-5,leaves:3)
B(-2,35,-4,leaves:3)
B(-2,35,-3,leaves:3)
B(-2,35,6,leaves:3)
B(-2,35,7,leaves:3)
B(-2,35,8,leaves:3)
B(-2,36,6,leaves:3)
B(-2,36,7,log:7)
B(-2,36,8,leaves:3)
B(-2,37,5,leaves:3)
B(-2,37,6,log:7)
B(-2,37,7,log:7)
B(-2,37,8,log:7)
B(-2,37,9,leaves:3)
B(-2,38,5,leaves:3)
B(-2,38,6,log:3)
B(-2,38,7,log:7)
B(-2,38,8,log:7)
B(-2,39,5,leaves:3)
B(-2,39,6,leaves:3)
B(-2,39,7,LOG:11)
B(-1,0,14,log:7)
B(-1,2,-8,log:3)
B(-1,3,-8,log:3)
B(-1,4,-8,log:3)
B(-1,5,-8,log:3)
B(-1,5,1,log:3)
B(-1,6,-8,LOG:11)
B(-1,6,-7,log:7)
B(-1,6,-6,log:7)
B(-1,6,-5,log:3)
B(-1,6,1,log:3)
B(-1,7,-8,log:7)
B(-1,7,-7,log:3)
B(-1,7,-6,log:3)
B(-1,7,-5,log:3)
B(-1,7,-4,LOG:11)
B(-1,7,1,log:3)
B(-1,8,-7,LOG:11)
B(-1,8,-6,log:7)
B(-1,8,-5,log:7)
B(-1,8,-4,LOG:11)
B(-1,8,1,log:3)
B(-1,9,-6,leaves:3)
B(-1,9,-5,log:7)
B(-1,9,1,log:3)
B(-1,10,1,log:3)
B(-1,11,1,log:3)
B(-1,11,2,log:7)
B(-1,11,3,log:3)
B(-1,11,4,log:7)
B(-1,12,-1,LOG:11)
B(-1,12,0,LOG:11)
B(-1,12,1,LOG:11)
B(-1,12,2,log:3)
B(-1,12,3,log:7)
B(-1,12,4,log:7)
B(-1,12,5,LOG:11)
B(-1,13,-1,log:3)
B(-1,13,0,LOG:11)
B(-1,13,1,log:3)
B(-1,13,3,log:3)
B(-1,13,4,LOG:11)
B(-1,13,5,leaves:3)
B(-1,14,-1,LOG:11)
B(-1,14,0,log:7)
B(-1,14,1,log:3)
B(-1,14,4,leaves:3)
B(-1,15,0,log:3)
B(-1,16,5,log:3)
B(-1,17,4,log:3)
B(-1,17,5,log:3)
B(-1,17,6,LOG:11)
B(-1,18,3,log:7)
B(-1,18,4,LOG:11)
B(-1,18,5,log:7)
B(-1,18,6,log:3)
B(-1,19,0,LOG:11)
B(-1,19,2,log:7)
B(-1,19,3,log:3)
B(-1,19,4,leaves:3)
B(-1,19,5,log:7)
B(-1,19,6,leaves:3)
B(-1,19,7,leaves:3)
B(-1,20,-1,LOG:11)
B(-1,20,0,log:3)
B(-1,20,1,log:3)
B(-1,20,2,log:3)
B(-1,20,3,leaves:3)
B(-1,20,4,leaves:3)
B(-1,20,5,leaves:3)
B(-1,20,6,leaves:3)
B(-1,21,-1,leaves:3)
B(-1,21,0,log:3)
B(-1,21,1,leaves:3)
B(-1,22,0,leaves:3)
B(-1,23,4,log:3)
B(-1,24,-2,leaves:3)
B(-1,24,-1,leaves:3)
B(-1,24,0,log:3)
B(-1,24,1,log:7)
B(-1,24,2,log:7)
B(-1,24,3,log:3)
B(-1,24,4,log:3)
B(-1,24,5,log:7)
B(-1,25,-2,leaves:3)
B(-1,25,-1,log:7)
B(-1,25,0,log:3)
B(-1,25,1,log:7)
B(-1,25,2,LOG:11)
B(-1,25,4,log:3)
B(-1,26,-2,leaves:3)
B(-1,26,-1,leaves:3)
B(-1,26,0,LOG:11)
B(-1,26,1,log:7)
B(-1,28,-9,leaves:3)
B(-1,28,-3,leaves:3)
B(-1,29,-9,leaves:3)
B(-1,29,-3,leaves:3)
B(-1,29,2,log:3)
B(-1,29,3,log:3)
B(-1,29,4,log:7)
B(-1,30,-9,leaves:3)
B(-1,30,-3,leaves:3)
B(-1,30,1,log:7)
B(-1,30,2,log:3)
B(-1,30,3,log:7)
B(-1,30,4,LOG:11)
B(-1,30,5,log:3)
B(-1,31,-9,leaves:3)
B(-1,31,-3,leaves:3)
B(-1,31,-1,log:3)
B(-1,31,0,log:3)
B(-1,31,1,log:7)
B(-1,31,2,LOG:11)
B(-1,31,3,LOG:11)
B(-1,31,4,log:3)
B(-1,31,7,leaves:3)
B(-1,32,-10,leaves:3)
B(-1,32,-9,leaves:3)
B(-1,32,-8,leaves:3)
B(-1,32,-7,leaves:3)
B(-1,32,-3,log:7)
B(-1,32,-2,log:3)
B(-1,32,-1,LOG:11)
B(-1,32,0,log:7)
B(-1,32,1,log:7)
B(-1,32,2,log:3)
B(-1,32,7,leaves:3)
B(-1,33,-11,leaves:3)
B(-1,33,-9,leaves:3)
B(-1,33,-8,log:7)
B(-1,33,-7,leaves:3)
B(-1,33,-6,leaves:3)
B(-1,33,-4,log:3)
B(-1,33,-3,log:7)
B(-1,33,-2,log:7)
B(-1,33,-1,log:7)
B(-1,33,0,log:7)
B(-1,33,1,log:7)
B(-1,33,7,leaves:3)
B(-1,34,-11,leaves:3)
B(-1,34,-10,leaves:3)
B(-1,34,-9,leaves:3)
B(-1,34,-8,log:3)
B(-1,34,-7,LOG:11)
B(-1,34,-6,log:7)
B(-1,34,-5,log:7)
B(-1,34,-4,LOG:11)
B(-1,34,-3,log:3)
B(-1,34,-2,LOG:11)
B(-1,34,-1,log:3)
B(-1,34,7,leaves:3)
B(-1,35,-9,leaves:3)
B(-1,35,-8,log:7)
B(-1,35,-7,LOG:11)
B(-1,35,-6,log:3)
B(-1,35,-5,LOG:11)
B(-1,35,-4,LOG:11)
B(-1,35,-3,log:3)
B(-1,35,-2,leaves:3)
B(-1,35,7,leaves:3)
B(-1,36,-6,leaves:3)
B(-1,36,-5,leaves:3)
B(-1,36,-4,leaves:3)
B(-1,36,-3,leaves:3)
B(-1,36,6,log:7)
B(-1,36,7,log:3)
B(-1,36,8,leaves:3)
B(-1,36,9,leaves:3)
B(-1,37,5,log:3)
B(-1,37,6,log:7)
B(-1,37,7,log:3)
B(-1,37,8,log:7)
B(-1,37,9,leaves:3)
B(-1,38,5,leaves:3)
B(-1,38,6,log:3)
B(-1,38,7,LOG:11)
B(-1,38,8,leaves:3)
B(-1,38,9,leaves:3)
B(-1,39,6,leaves:3)
B(0,0,13,LOG:11)
B(0,0,14,log:3)
B(0,0,15,log:7)
B(0,1,14,log:7)
B(0,2,-5,log:3)
B(0,3,-5,log:3)
B(0,4,-5,log:3)
B(0,4,-1,log:3)
B(0,5,-5,log:3)
B(0,5,-1,log:3)
B(0,5,4,log:3)
B(0,6,-5,log:7)
B(0,6,-4,LOG:11)
B(0,6,-1,log:3)
B(0,6,4,log:3)
B(0,7,-6,LOG:11)
B(0,7,-5,log:7)
B(0,7,-4,log:3)
B(0,7,-3,log:3)
B(0,7,-1,log:3)
B(0,7,4,log:3)
B(0,8,-6,log:3)
B(0,8,-5,log:7)
B(0,8,-4,log:3)
B(0,8,-3,LOG:11)
B(0,8,-1,log:3)
B(0,8,0,log:3)
B(0,8,1,log:3)
B(0,8,4,log:3)
B(0,9,-5,LOG:11)
B(0,9,-4,leaves:3)
B(0,9,-1,log:7)
B(0,9,4,log:3)
B(0,10,3,LOG:11)
B(0,10,4,log:3)
B(0,11,3,LOG:11)
B(0,11,4,log:3)
B(0,11,5,log:7)
B(0,12,3,log:3)
B(0,12,4,log:7)
B(0,12,5,LOG:11)
B(0,12,6,leaves:3)
B(0,13,-1,leaves:3)
B(0,13,0,log:7)
B(0,13,4,log:3)
B(0,13,5,leaves:3)
B(0,14,-2,leaves:3)
B(0,14,-1,LOG:11)
B(0,14,0,log:3)
B(0,14,1,log:7)
B(0,15,-1,leaves:3)
B(0,15,0,log:7)
B(0,16,5,log:3)
B(0,17,4,log:3)
B(0,17,5,LOG:11)
B(0,17,6,log:7)
B(0,18,5,LOG:11)
B(0,19,0,LOG:11)
B(0,19,5,leaves:3)
B(0,19,6,leaves:3)
B(0,20,-1,log:7)
B(0,20,0,log:3)
B(0,20,1,LOG:11)
B(0,21,-1,leaves:3)
B(0,21,0,LOG:11)
B(0,23,4,LOG:11)
B(0,24,-1,leaves:3)
B(0,24,0,log:3)
B(0,24,3,log:7)
B(0,24,4,log:3)
B(0,24,5,log:7)
B(0,25,-2,leaves:3)
B(0,25,-1,log:3)
B(0,25,0,log:7)
B(0,25,1,log:3)
B(0,25,4,log:7)
B(0,26,-1,leaves:3)
B(0,26,0,log:3)
B(0,26,1,leaves:3)
B(0,27,0,leaves:3)
B(0,29,4,LOG:11)
B(0,30,-13,leaves:3)
B(0,30,0,log:7)
B(0,30,1,log:7)
B(0,30,2,log:7)
B(0,30,3,log:3)
B(0,30,4,LOG:11)
B(0,30,5,log:3)
B(0,31,-14,leaves:3)
B(0,31,-13,leaves:3)
B(0,31,-12,leaves:3)
B(0,31,-11,leaves:3)
B(0,31,-10,leaves:3)
B(0,31,-1,LOG:11)
B(0,31,0,log:7)
B(0,31,1,log:3)
B(0,31,4,log:3)
B(0,32,-13,leaves:3)
B(0,32,-12,leaves:3)
B(0,32,-11,leaves:3)
B(0,32,-10,leaves:3)
B(0,32,-9,leaves:3)
B(0,32,-8,log:7)
B(0,32,-6,leaves:3)
B(0,32,-2,LOG:11)
B(0,32,-1,LOG:11)
B(0,32,0,LOG:11)
B(0,32,1,log:3)
B(0,33,-12,leaves:3)
B(0,33,-11,leaves:3)
B(0,33,-10,leaves:3)
B(0,33,-9,LOG:11)
B(0,33,-8,log:7)
B(0,33,-7,log:7)
B(0,33,-6,log:3)
B(0,33,-5,log:7)
B(0,33,-4,log:3)
B(0,33,-3,log:7)
B(0,33,-2,LOG:11)
B(0,33,-1,log:7)
B(0,33,0,leaves:3)
B(0,34,-12,leaves:3)
B(0,34,-11,leaves:3)
B(0,34,-10,log:3)
B(0,34,-9,log:7)
B(0,34,-8,log:7)
B(0,34,-7,log:3)
B(0,34,-6,LOG:11)
B(0,34,-5,LOG:11)
B(0,34,-4,LOG:11)
B(0,34,-3,LOG:11)
B(0,34,-2,log:7)
B(0,34,-1,leaves:3)
B(0,35,-11,leaves:3)
B(0,35,-9,LOG:11)
B(0,35,-8,log:3)
B(0,35,-7,LOG:11)
B(0,35,-6,LOG:11)
B(0,35,-5,log:7)
B(0,35,-4,log:3)
B(0,35,-3,log:3)
B(0,35,-2,leaves:3)
B(0,35,-1,leaves:3)
B(0,35,5,leaves:3)
B(0,36,-8,log:7)
B(0,36,-7,log:3)
B(0,36,-6,log:7)
B(0,36,-5,log:7)
B(0,36,-3,leaves:3)
B(0,36,-2,leaves:3)
B(0,36,4,LOG:11)
B(0,36,5,LOG:11)
B(0,36,6,log:3)
B(0,36,8,leaves:3)
B(0,37,4,log:7)
B(0,37,5,LOG:11)
B(0,37,6,log:7)
B(0,37,7,log:3)
B(0,37,8,leaves:3)
B(0,37,9,leaves:3)
B(0,38,3,leaves:3)
B(0,38,4,leaves:3)
B(0,38,5,log:3)
B(0,38,6,log:7)
B(0,38,8,leaves:3)
B(0,39,4,leaves:3)
B(1,0,13,log:3)
B(1,0,14,log:3)
B(1,0,15,LOG:11)
B(1,1,14,log:3)
B(1,1,15,log:7)
B(1,2,13,LOG:11)
B(1,2,14,log:3)
B(1,3,2,log:3)
B(1,3,14,log:3)
B(1,4,2,log:3)
B(1,5,-2,log:3)
B(1,5,2,log:3)
B(1,6,-2,log:3)
B(1,6,2,log:3)
B(1,7,-5,log:7)
B(1,7,-4,log:3)
B(1,7,-2,log:3)
B(1,7,-1,log:3)
B(1,7,0,log:3)
B(1,7,2,log:3)
B(1,8,-5,LOG:11)
B(1,8,-4,log:7)
B(1,8,-3,log:7)
B(1,8,-2,log:3)
B(1,8,-1,log:3)
B(1,8,0,log:7)
B(1,8,1,LOG:11)
B(1,8,2,LOG:11)
B(1,9,-3,log:7)
B(1,9,-2,log:7)
B(1,9,-1,log:7)
B(1,9,0,log:3)
B(1,9,1,LOG:11)
B(1,9,3,log:7)
B(1,9,4,LOG:11)
B(1,9,6,log:7)
B(1,9,7,log:7)
B(1,10,-2,leaves:3)
B(1,10,-1,LOG:11)
B(1,10,0,log:3)
B(1,10,1,log:7)
B(1,10,2,log:3)
B(1,10,3,log:7)
B(1,10,4,LOG:11)
B(1,10,5,log:7)
B(1,10,6,log:3)
B(1,11,2,log:3)
B(1,11,3,LOG:11)
B(1,11,4,log:7)
B(1,11,5,log:7)
B(1,11,6,LOG:11)
B(1,12,3,log:3)
B(1,12,4,log:7)
B(1,12,5,log:7)
B(1,12,6,leaves:3)
B(1,12,7,leaves:3)
B(1,13,0,log:7)
B(1,14,-1,log:3)
B(1,14,0,log:7)
B(1,14,1,log:7)
B(1,15,0,log:7)
B(1,15,1,log:3)
B(1,16,4,log:3)
B(1,16,5,log:7)
B(1,17,3,log:3)
B(1,17,4,LOG:11)
B(1,17,5,LOG:11)
B(1,17,6,log:3)
B(1,18,4,log:3)
B(1,18,5,log:7)
B(1,19,0,LOG:11)
B(1,20,-1,LOG:11)
B(1,20,0,LOG:11)
B(1,20,1,log:7)
B(1,21,-2,leaves:3)
B(1,21,-1,log:3)
B(1,21,0,log:7)
B(1,21,1,log:7)
B(1,22,-1,leaves:3)
B(1,22,0,log:7)
B(1,22,4,leaves:3)
B(1,23,3,leaves:3)
B(1,23,4,LOG:11)
B(1,23,5,leaves:3)
B(1,24,3,log:7)
B(1,24,4,log:7)
B(1,24,5,log:7)
B(1,25,-1,LOG:11)
B(1,25,0,LOG:11)
B(1,25,1,log:3)
B(1,25,4,log:7)
B(1,26,-1,leaves:3)
B(1,26,0,log:3)
B(1,26,1,leaves:3)
B(1,27,-1,leaves:3)
B(1,27,0,LOG:11)
B(1,27,1,leaves:3)
B(1,29,4,log:7)
B(1,30,-14,leaves:3)
B(1,30,-13,LOG:11)
B(1,30,-12,leaves:3)
B(1,30,-1,LOG:11)
B(1,30,0,log:7)
B(1,30,3,LOG:11)
B(1,30,4,LOG:11)
B(1,30,5,log:3)
B(1,31,-14,leaves:3)
B(1,31,-13,LOG:11)
B(1,31,-12,LOG:11)
B(1,31,-11,log:7)
B(1,31,-10,leaves:3)
B(1,31,-2,log:3)
B(1,31,-1,log:7)
B(1,31,0,LOG:11)
B(1,31,1,log:3)
B(1,31,4,log:3)
B(1,32,-14,leaves:3)
B(1,32,-13,leaves:3)
B(1,32,-12,LOG:11)
B(1,32,-11,log:7)
B(1,32,-10,leaves:3)
B(1,32,-7,leaves:3)
B(1,32,-6,leaves:3)
B(1,32,-5,leaves:3)
B(1,32,-2,log:3)
B(1,32,-1,log:7)
B(1,32,0,LOG:11)
B(1,33,-12,leaves:3)
B(1,33,-11,log:3)
B(1,33,-10,LOG:11)
B(1,33,-9,LOG:11)
B(1,33,-8,log:3)
B(1,33,-7,leaves:3)
B(1,33,-6,leaves:3)
B(1,33,-5,leaves:3)
B(1,33,-4,leaves:3)
B(1,33,-2,leaves:3)
B(1,33,-1,log:3)
B(1,33,0,leaves:3)
B(1,34,-11,log:7)
B(1,34,-10,LOG:11)
B(1,34,-9,LOG:11)
B(1,34,-8,LOG:11)
B(1,34,-7,log:7)
B(1,34,-6,log:7)
B(1,34,-5,log:3)
B(1,34,-4,log:7)
B(1,34,-3,log:7)
B(1,34,-2,leaves:3)
B(1,34,-1,leaves:3)
B(1,34,0,leaves:3)
B(1,35,-11,leaves:3)
B(1,35,-10,log:3)
B(1,35,-9,log:3)
B(1,35,-8,log:3)
B(1,35,-7,LOG:11)
B(1,35,-6,LOG:11)
B(1,35,-5,log:3)
B(1,35,-4,leaves:3)
B(1,35,-3,leaves:3)
B(1,35,-2,leaves:3)
B(1,35,4,log:7)
B(1,35,5,leaves:3)
B(1,35,6,leaves:3)
B(1,36,-10,leaves:3)
B(1,36,-8,LOG:11)
B(1,36,3,log:7)
B(1,36,4,log:3)
B(1,36,5,log:7)
B(1,36,6,leaves:3)
B(1,36,7,leaves:3)
B(1,37,3,LOG:11)
B(1,37,4,log:3)
B(1,37,5,LOG:11)
B(1,37,6,log:7)
B(1,37,7,leaves:3)
B(1,38,3,leaves:3)
B(1,38,4,log:7)
B(1,38,5,LOG:11)
B(1,38,6,leaves:3)
B(1,38,7,leaves:3)
B(1,39,3,leaves:3)
B(1,39,4,leaves:3)
B(1,39,5,leaves:3)
B(2,0,13,LOG:11)
B(2,0,14,log:7)
B(2,0,15,log:3)
B(2,1,13,log:7)
B(2,1,14,log:3)
B(2,1,15,log:7)
B(2,2,7,log:3)
B(2,2,13,log:3)
B(2,2,14,log:3)
B(2,2,15,log:7)
B(2,3,-1,log:3)
B(2,3,7,log:3)
B(2,3,13,LOG:11)
B(2,3,14,LOG:11)
B(2,3,15,log:7)
B(2,4,-1,log:3)
B(2,4,5,log:3)
B(2,4,7,log:3)
B(2,4,14,LOG:11)
B(2,5,-1,log:3)
B(2,5,5,log:3)
B(2,5,7,log:3)
B(2,6,-1,LOG:11)
B(2,6,0,log:7)
B(2,6,5,log:3)
B(2,6,7,log:3)
B(2,7,-3,LOG:11)
B(2,7,-2,log:7)
B(2,7,-1,log:3)
B(2,7,0,LOG:11)
B(2,7,1,log:7)
B(2,7,5,log:3)
B(2,7,7,log:3)
B(2,8,-3,log:3)
B(2,8,-2,LOG:11)
B(2,8,-1,LOG:11)
B(2,8,0,log:3)
B(2,8,1,log:3)
B(2,8,2,log:3)
B(2,8,5,log:3)
B(2,8,6,log:7)
B(2,8,7,log:7)
B(2,9,-2,log:3)
B(2,9,-1,log:3)
B(2,9,0,LOG:11)
B(2,9,1,log:7)
B(2,9,2,LOG:11)
B(2,9,3,log:3)
B(2,9,5,log:3)
B(2,9,6,LOG:11)
B(2,9,7,log:7)
B(2,9,8,log:3)
B(2,10,-3,leaves:3)
B(2,10,-2,leaves:3)
B(2,10,-1,log:7)
B(2,10,0,LOG:11)
B(2,10,1,log:7)
B(2,10,2,log:7)
B(2,10,3,log:7)
B(2,10,4,log:3)
B(2,10,5,log:7)
B(2,10,6,LOG:11)
B(2,10,7,LOG:11)
B(2,11,-2,leaves:3)
B(2,11,-1,leaves:3)
B(2,11,0,log:3)
B(2,11,1,LOG:11)
B(2,11,2,log:3)
B(2,11,3,LOG:11)
B(2,11,4,log:7)
B(2,11,5,LOG:11)
B(2,11,6,LOG:11)
B(2,11,7,LOG:11)
B(2,12,2,log:3)
B(2,12,3,leaves:3)
B(2,12,5,log:7)
B(2,12,6,log:7)
B(2,12,7,leaves:3)
B(2,12,8,leaves:3)
B(2,13,-1,log:7)
B(2,13,0,log:3)
B(2,13,6,leaves:3)
B(2,13,7,leaves:3)
B(2,14,-2,log:3)
B(2,14,-1,log:7)
B(2,14,0,LOG:11)
B(2,14,1,LOG:11)
B(2,15,-1,log:7)
B(2,15,0,log:7)
B(2,15,1,LOG:11)
B(2,15,2,log:3)
B(2,15,4,LOG:11)
B(2,16,0,LOG:11)
B(2,16,1,log:3)
B(2,16,2,log:7)
B(2,16,3,log:3)
B(2,16,4,log:3)
B(2,16,5,log:3)
B(2,17,3,log:7)
B(2,17,4,LOG:11)
B(2,17,5,log:3)
B(2,18,3,leaves:3)
B(2,18,4,LOG:11)
B(2,18,5,leaves:3)
B(2,19,4,leaves:3)
B(2,20,0,LOG:11)
B(2,21,-1,log:3)
B(2,21,0,LOG:11)
B(2,21,1,log:3)
B(2,22,0,log:3)
B(2,22,1,log:3)
B(2,22,2,log:3)
B(2,22,3,LOG:11)
B(2,22,4,LOG:11)
B(2,23,3,LOG:11)
B(2,23,4,log:3)
B(2,23,5,LOG:11)
B(2,24,3,LOG:11)
B(2,24,4,LOG:11)
B(2,24,5,log:3)
B(2,25,0,leaves:3)
B(2,25,1,log:3)
B(2,25,4,LOG:11)
B(2,26,-1,LOG:11)
B(2,26,0,log:3)
B(2,26,1,LOG:11)
B(2,27,-1,LOG:11)
B(2,27,0,log:7)
B(2,27,1,log:7)
B(2,28,0,LOG:11)
B(2,28,4,log:3)
B(2,29,-13,log:3)
B(2,29,3,log:3)
B(2,29,4,log:7)
B(2,29,5,log:3)
B(2,30,-14,LOG:11)
B(2,30,-13,log:3)
B(2,30,-12,log:7)
B(2,30,-11,log:7)
B(2,30,3,log:3)
B(2,30,4,LOG:11)
B(2,30,5,log:7)
B(2,31,-14,log:3)
B(2,31,-13,LOG:11)
B(2,31,-12,log:7)
B(2,31,-11,log:3)
B(2,31,-10,log:7)
B(2,31,-1,log:7)
B(2,31,0,LOG:11)
B(2,31,4,log:7)
B(2,32,-13,log:3)
B(2,32,-12,log:3)
B(2,32,-11,log:3)
B(2,32,-10,log:3)
B(2,32,-6,leaves:3)
B(2,32,-2,log:3)
B(2,32,-1,LOG:11)
B(2,32,0,log:3)
B(2,33,-13,leaves:3)
B(2,33,-12,LOG:11)
B(2,33,-11,log:3)
B(2,33,-10,log:7)
B(2,33,-9,log:7)
B(2,33,-7,leaves:3)
B(2,33,-6,leaves:3)
B(2,33,-5,leaves:3)
B(2,33,-2,leaves:3)
B(2,33,-1,LOG:11)
B(2,33,0,leaves:3)
B(2,33,1,leaves:3)
B(2,34,-12,leaves:3)
B(2,34,-11,log:7)
B(2,34,-10,log:3)
B(2,34,-9,log:3)
B(2,34,-8,log:3)
B(2,34,-7,leaves:3)
B(2,34,-6,leaves:3)
B(2,34,-5,leaves:3)
B(2,34,-4,leaves:3)
B(2,34,-1,leaves:3)
B(2,34,0,leaves:3)
B(2,34,3,log:7)
B(2,34,4,log:3)
B(2,34,5,leaves:3)
B(2,35,-11,leaves:3)
B(2,35,-10,LOG:11)
B(2,35,-9,leaves:3)
B(2,35,-8,LOG:11)
B(2,35,-7,leaves:3)
B(2,35,-5,leaves:3)
B(2,35,3,log:3)
B(2,35,4,log:3)
B(2,35,5,log:7)
B(2,35,6,leaves:3)
B(2,36,-11,leaves:3)
B(2,36,-10,leaves:3)
B(2,36,-9,leaves:3)
B(2,36,-8,leaves:3)
B(2,36,-7,leaves:3)
B(2,36,3,LOG:11)
B(2,36,4,log:7)
B(2,36,5,log:7)
B(2,36,6,leaves:3)
B(2,37,4,log:3)
B(2,37,5,log:7)
B(2,37,6,leaves:3)
B(2,37,7,leaves:3)
B(2,38,3,leaves:3)
B(2,38,4,leaves:3)
B(2,38,5,leaves:3)
B(2,38,6,leaves:3)
B(2,39,4,leaves:3)
B(3,0,14,log:3)
B(3,1,14,LOG:11)
B(3,1,15,log:3)
B(3,2,14,log:3)
B(3,3,-3,log:3)
B(3,3,13,LOG:11)
B(3,3,14,log:7)
B(3,3,15,log:7)
B(3,4,-3,log:3)
B(3,4,1,log:3)
B(3,4,13,log:3)
B(3,4,14,log:7)
B(3,4,15,log:7)
B(3,5,-3,log:3)
B(3,5,1,log:3)
B(3,5,13,log:7)
B(3,5,14,LOG:11)
B(3,6,-3,LOG:11)
B(3,6,1,log:3)
B(3,7,-4,LOG:11)
B(3,7,-3,LOG:11)
B(3,7,-2,log:7)
B(3,7,-1,log:7)
B(3,7,0,log:7)
B(3,7,1,log:3)
B(3,7,8,log:3)
B(3,7,9,log:7)
B(3,8,-3,log:7)
B(3,8,-2,log:3)
B(3,8,-1,LOG:11)
B(3,8,0,log:7)
B(3,8,1,LOG:11)
B(3,8,4,log:7)
B(3,8,6,LOG:11)
B(3,8,7,log:3)
B(3,8,8,log:7)
B(3,8,9,log:3)
B(3,9,-2,log:3)
B(3,9,-1,LOG:11)
B(3,9,0,LOG:11)
B(3,9,1,LOG:11)
B(3,9,5,LOG:11)
B(3,9,6,log:7)
B(3,9,7,LOG:11)
B(3,9,8,log:7)
B(3,10,-2,leaves:3)
B(3,10,-1,leaves:3)
B(3,10,0,log:3)
B(3,10,1,log:3)
B(3,10,2,log:7)
B(3,10,3,log:7)
B(3,10,6,LOG:11)
B(3,10,7,log:3)
B(3,11,1,leaves:3)
B(3,11,2,log:7)
B(3,11,3,leaves:3)
B(3,11,5,log:7)
B(3,11,6,LOG:11)
B(3,12,-1,log:7)
B(3,12,6,leaves:3)
B(3,12,7,leaves:3)
B(3,13,-2,log:3)
B(3,13,-1,log:7)
B(3,13,0,LOG:11)
B(3,14,-2,log:3)
B(3,14,-1,log:7)
B(3,14,0,LOG:11)
B(3,14,1,LOG:11)
B(3,14,2,LOG:11)
B(3,15,-2,leaves:3)
B(3,15,-1,LOG:11)
B(3,15,0,LOG:11)
B(3,15,1,LOG:11)
B(3,15,2,LOG:11)
B(3,15,3,LOG:11)
B(3,15,4,log:7)
B(3,16,-1,leaves:3)
B(3,16,1,log:7)
B(3,16,2,log:3)
B(3,16,3,log:3)
B(3,16,4,log:7)
B(3,16,5,LOG:11)
B(3,17,2,log:3)
B(3,17,3,log:3)
B(3,17,4,log:7)
B(3,18,4,leaves:3)
B(3,20,0,LOG:11)
B(3,21,-1,log:7)
B(3,21,0,log:3)
B(3,21,1,log:3)
B(3,21,2,log:7)
B(3,21,3,log:7)
B(3,22,1,log:7)
B(3,22,2,log:7)
B(3,22,3,log:7)
B(3,22,4,log:3)
B(3,22,5,leaves:3)
B(3,23,1,log:3)
B(3,23,2,LOG:11)
B(3,23,3,log:3)
B(3,23,4,LOG:11)
B(3,23,5,LOG:11)
B(3,23,6,leaves:3)
B(3,24,3,log:7)
B(3,24,4,log:3)
B(3,24,5,leaves:3)
B(3,26,-11,leaves:3)
B(3,26,0,log:3)
B(3,27,-11,leaves:3)
B(3,27,-1,log:3)
B(3,27,0,LOG:11)
B(3,27,1,log:3)
B(3,27,4,log:7)
B(3,28,-11,leaves:3)
B(3,28,-1,log:3)
B(3,28,0,LOG:11)
B(3,28,1,LOG:11)
B(3,28,2,LOG:11)
B(3,28,3,log:7)
B(3,28,4,log:3)
B(3,28,5,LOG:11)
B(3,29,-13,LOG:11)
B(3,29,-11,leaves:3)
B(3,29,0,log:3)
B(3,29,3,log:7)
B(3,29,4,log:7)
B(3,29,5,log:7)
B(3,30,-14,log:7)
B(3,30,-13,LOG:11)
B(3,30,-12,log:3)
B(3,30,-11,leaves:3)
B(3,30,2,leaves:3)
B(3,30,3,leaves:3)
B(3,30,4,log:3)
B(3,31,-14,leaves:3)
B(3,31,-13,log:7)
B(3,31,-12,LOG:11)
B(3,31,-11,LOG:11)
B(3,31,-2,leaves:3)
B(3,31,-1,LOG:11)
B(3,31,0,LOG:11)
B(3,31,3,leaves:3)
B(3,32,-15,leaves:3)
B(3,32,-14,leaves:3)
B(3,32,-13,log:7)
B(3,32,-12,log:3)
B(3,32,-11,log:7)
B(3,32,-10,leaves:3)
B(3,32,-9,leaves:3)
B(3,32,-2,LOG:11)
B(3,32,-1,LOG:11)
B(3,32,0,log:3)
B(3,32,1,log:7)
B(3,33,-14,leaves:3)
B(3,33,-13,leaves:3)
B(3,33,-12,log:7)
B(3,33,-11,LOG:11)
B(3,33,-10,log:3)
B(3,33,-9,leaves:3)
B(3,33,-2,leaves:3)
B(3,33,-1,LOG:11)
B(3,33,0,log:3)
B(3,33,1,log:7)
B(3,33,2,log:7)
B(3,33,3,log:7)
B(3,34,-13,leaves:3)
B(3,34,-12,leaves:3)
B(3,34,-11,leaves:3)
B(3,34,-10,log:7)
B(3,34,-9,leaves:3)
B(3,34,-8,leaves:3)
B(3,34,-1,leaves:3)
B(3,34,0,leaves:3)
B(3,34,1,leaves:3)
B(3,34,2,log:7)
B(3,34,3,log:3)
B(3,34,4,log:3)
B(3,34,5,leaves:3)
B(3,34,6,leaves:3)
B(3,35,-11,leaves:3)
B(3,35,-10,leaves:3)
B(3,35,-9,leaves:3)
B(3,35,-8,leaves:3)
B(3,35,-7,leaves:3)
B(3,35,0,leaves:3)
B(3,35,1,leaves:3)
B(3,35,2,log:3)
B(3,35,3,log:7)
B(3,35,4,log:7)
B(3,35,5,log:7)
B(3,35,6,leaves:3)
B(3,36,-10,leaves:3)
B(3,36,-8,leaves:3)
B(3,36,1,leaves:3)
B(3,36,2,leaves:3)
B(3,36,3,log:3)
B(3,36,4,log:3)
B(3,36,5,leaves:3)
B(3,36,6,leaves:3)
B(3,37,2,leaves:3)
B(4,3,14,LOG:11)
B(4,4,13,LOG:11)
B(4,4,14,LOG:11)
B(4,4,15,log:3)
B(4,5,12,LOG:11)
B(4,5,13,log:3)
B(4,5,14,LOG:11)
B(4,5,15,log:7)
B(4,6,-3,LOG:11)
B(4,6,8,log:7)
B(4,6,9,LOG:11)
B(4,6,13,LOG:11)
B(4,6,14,LOG:11)
B(4,7,-4,LOG:11)
B(4,7,-3,LOG:11)
B(4,7,-2,LOG:11)
B(4,7,7,log:7)
B(4,7,8,LOG:11)
B(4,7,9,log:7)
B(4,7,10,log:7)
B(4,7,11,log:3)
B(4,8,-4,log:3)
B(4,8,-3,log:3)
B(4,8,-2,LOG:11)
B(4,8,-1,log:3)
B(4,8,7,leaves:3)
B(4,8,8,log:7)
B(4,8,9,LOG:11)
B(4,8,10,LOG:11)
B(4,8,11,LOG:11)
B(4,9,-4,leaves:3)
B(4,9,-3,log:3)
B(4,9,-2,log:7)
B(4,9,6,log:7)
B(4,9,7,log:7)
B(4,9,8,leaves:3)
B(4,9,9,log:3)
B(4,10,1,leaves:3)
B(4,10,7,leaves:3)
B(4,11,-1,log:3)
B(4,12,-1,log:7)
B(4,13,-2,log:7)
B(4,13,-1,log:3)
B(4,13,0,log:7)
B(4,14,-1,log:3)
B(4,14,1,leaves:3)
B(4,15,-1,leaves:3)
B(4,15,0,leaves:3)
B(4,15,1,log:3)
B(4,15,2,log:3)
B(4,15,3,leaves:3)
B(4,16,1,leaves:3)
B(4,16,2,LOG:11)
B(4,16,3,log:7)
B(4,16,4,log:3)
B(4,17,3,leaves:3)
B(4,20,0,leaves:3)
B(4,21,-1,leaves:3)
B(4,21,0,log:3)
B(4,21,1,leaves:3)
B(4,21,2,leaves:3)
B(4,22,0,leaves:3)
B(4,22,1,log:7)
B(4,22,2,log:3)
B(4,22,3,log:7)
B(4,23,2,leaves:3)
B(4,23,3,log:3)
B(4,23,4,log:3)
B(4,23,5,leaves:3)
B(4,27,-15,leaves:3)
B(4,27,-1,leaves:3)
B(4,27,0,log:3)
B(4,27,1,log:7)
B(4,27,2,log:3)
B(4,27,3,LOG:11)
B(4,27,4,LOG:11)
B(4,28,-15,leaves:3)
B(4,28,-1,leaves:3)
B(4,28,0,LOG:11)
B(4,28,1,log:3)
B(4,28,2,LOG:11)
B(4,28,3,log:7)
B(4,28,4,log:3)
B(4,28,5,LOG:11)
B(4,29,-15,leaves:3)
B(4,29,-1,leaves:3)
B(4,29,0,leaves:3)
B(4,29,1,log:3)
B(4,29,2,LOG:11)
B(4,29,3,log:3)
B(4,29,4,LOG:11)
B(4,29,5,log:7)
B(4,30,-15,leaves:3)
B(4,30,-13,log:7)
B(4,30,-12,leaves:3)
B(4,30,2,leaves:3)
B(4,30,3,LOG:11)
B(4,30,4,log:7)
B(4,31,-15,leaves:3)
B(4,31,-14,leaves:3)
B(4,31,-13,leaves:3)
B(4,31,-12,leaves:3)
B(4,31,-11,leaves:3)
B(4,31,-1,leaves:3)
B(4,31,0,log:7)
B(4,31,2,leaves:3)
B(4,31,3,leaves:3)
B(4,31,4,leaves:3)
B(4,32,-15,leaves:3)
B(4,32,-14,leaves:3)
B(4,32,-13,leaves:3)
B(4,32,-12,LOG:11)
B(4,32,-10,leaves:3)
B(4,32,-2,leaves:3)
B(4,32,-1,log:3)
B(4,32,0,LOG:11)
B(4,32,1,log:3)
B(4,32,2,LOG:11)
B(4,33,-15,leaves:3)
B(4,33,-14,leaves:3)
B(4,33,-13,leaves:3)
B(4,33,-12,leaves:3)
B(4,33,-11,leaves:3)
B(4,33,-10,leaves:3)
B(4,33,-9,leaves:3)
B(4,33,-2,log:7)
B(4,33,-1,log:3)
B(4,33,0,LOG:11)
B(4,33,1,log:3)
B(4,33,2,log:3)
B(4,33,3,log:3)
B(4,34,-14,leaves:3)
B(4,34,-13,leaves:3)
B(4,34,-12,leaves:3)
B(4,34,-11,leaves:3)
B(4,34,-10,leaves:3)
B(4,34,-9,leaves:3)
B(4,34,-1,log:7)
B(4,34,0,LOG:11)
B(4,34,1,log:3)
B(4,34,2,log:3)
B(4,34,3,LOG:11)
B(4,34,4,LOG:11)
B(4,34,5,leaves:3)
B(4,35,-10,leaves:3)
B(4,35,-1,log:3)
B(4,35,0,leaves:3)
B(4,35,1,log:7)
B(4,35,2,log:3)
B(4,35,3,LOG:11)
B(4,35,4,LOG:11)
B(4,35,5,leaves:3)
B(4,35,6,leaves:3)
B(4,36,-2,leaves:3)
B(4,36,-1,leaves:3)
B(4,36,0,leaves:3)
B(4,36,1,leaves:3)
B(4,36,2,log:3)
B(4,36,3,leaves:3)
B(4,36,5,leaves:3)
B(4,37,-1,leaves:3)
B(4,37,1,leaves:3)
B(4,37,2,leaves:3)
B(4,37,3,leaves:3)
B(5,1,11,log:3)
B(5,2,11,log:3)
B(5,3,-4,log:3)
B(5,3,-2,log:3)
B(5,3,11,log:3)
B(5,4,-4,log:3)
B(5,4,-2,log:3)
B(5,4,8,log:3)
B(5,4,11,log:3)
B(5,4,13,log:7)
B(5,4,14,log:7)
B(5,5,-4,log:3)
B(5,5,-2,log:3)
B(5,5,8,log:3)
B(5,5,11,log:3)
B(5,5,12,LOG:11)
B(5,5,13,LOG:11)
B(5,5,14,LOG:11)
B(5,6,-5,log:7)
B(5,6,-4,log:7)
B(5,6,-3,log:3)
B(5,6,-2,log:3)
B(5,6,8,log:3)
B(5,6,10,log:7)
B(5,6,11,LOG:11)
B(5,6,13,log:3)
B(5,7,-5,LOG:11)
B(5,7,-4,log:7)
B(5,7,-3,LOG:11)
B(5,7,-2,LOG:11)
B(5,7,8,log:3)
B(5,7,9,log:3)
B(5,7,10,LOG:11)
B(5,7,11,LOG:11)
B(5,7,12,log:3)
B(5,8,-5,log:7)
B(5,8,-4,LOG:11)
B(5,8,-3,LOG:11)
B(5,8,-2,LOG:11)
B(5,8,8,log:3)
B(5,8,9,log:7)
B(5,8,10,LOG:11)
B(5,8,11,log:7)
B(5,8,12,LOG:11)
B(5,9,-5,leaves:3)
B(5,9,-4,log:7)
B(5,9,-3,LOG:11)
B(5,9,-2,log:3)
B(5,9,-1,log:3)
B(5,9,7,leaves:3)
B(5,9,10,leaves:3)
B(5,9,11,LOG:11)
B(5,9,12,leaves:3)
B(5,10,-4,leaves:3)
B(5,10,-3,log:3)
B(5,10,-2,log:3)
B(5,10,-1,LOG:11)
B(5,11,-2,LOG:11)
B(5,11,-1,log:7)
B(5,11,0,LOG:11)
B(5,12,-2,LOG:11)
B(5,12,-1,log:3)
B(5,12,0,LOG:11)
B(5,13,-2,log:7)
B(5,13,-1,log:3)
B(5,13,0,log:7)
B(5,14,-1,log:7)
B(5,15,1,leaves:3)
B(5,15,3,leaves:3)
B(5,16,2,leaves:3)
B(5,16,3,leaves:3)
B(5,16,4,leaves:3)
B(5,17,3,leaves:3)
B(5,21,0,leaves:3)
B(5,22,2,leaves:3)
B(5,24,-1,leaves:3)
B(5,25,-1,leaves:3)
B(5,26,-1,leaves:3)
B(5,27,-1,leaves:3)
B(5,27,0,leaves:3)
B(5,28,-1,leaves:3)
B(5,28,0,leaves:3)
B(5,28,1,log:3)
B(5,28,2,LOG:11)
B(5,28,3,log:3)
B(5,28,4,log:3)
B(5,28,5,leaves:3)
B(5,29,0,leaves:3)
B(5,29,3,log:7)
B(5,29,4,LOG:11)
B(5,29,5,LOG:11)
B(5,29,6,leaves:3)
B(5,30,2,leaves:3)
B(5,30,3,log:3)
B(5,30,4,LOG:11)
B(5,30,5,LOG:11)
B(5,31,-14,leaves:3)
B(5,31,3,leaves:3)
B(5,31,4,LOG:11)
B(5,31,5,LOG:11)
B(5,32,-15,leaves:3)
B(5,32,-14,leaves:3)
B(5,32,-13,leaves:3)
B(5,32,0,log:3)
B(5,32,4,leaves:3)
B(5,32,5,leaves:3)
B(5,32,6,leaves:3)
B(5,33,-14,leaves:3)
B(5,33,-13,leaves:3)
B(5,33,-12,leaves:3)
B(5,33,-1,LOG:11)
B(5,33,0,log:7)
B(5,33,1,log:7)
B(5,33,2,log:3)
B(5,33,3,leaves:3)
B(5,33,4,leaves:3)
B(5,33,5,leaves:3)
B(5,34,-13,leaves:3)
B(5,34,-2,LOG:11)
B(5,34,-1,LOG:11)
B(5,34,0,log:3)
B(5,34,1,log:3)
B(5,34,2,log:3)
B(5,34,3,log:3)
B(5,34,4,leaves:3)
B(5,35,-3,leaves:3)
B(5,35,-2,log:7)
B(5,35,-1,LOG:11)
B(5,35,0,log:3)
B(5,35,1,leaves:3)
B(5,35,2,log:3)
B(5,35,3,leaves:3)
B(5,35,4,leaves:3)
B(5,36,-2,leaves:3)
B(5,36,-1,log:7)
B(5,36,0,leaves:3)
B(5,36,1,leaves:3)
B(5,36,2,leaves:3)
B(5,36,3,leaves:3)
B(5,37,-2,leaves:3)
B(5,37,-1,leaves:3)
B(5,37,0,leaves:3)
B(5,37,2,leaves:3)
B(6,0,14,log:3)
B(6,1,14,log:3)
B(6,2,14,log:3)
B(6,3,14,log:3)
B(6,4,13,LOG:11)
B(6,4,14,log:3)
B(6,5,-5,LOG:11)
B(6,5,12,log:7)
B(6,5,13,LOG:11)
B(6,5,14,LOG:11)
B(6,6,-7,LOG:11)
B(6,6,-6,log:7)
B(6,6,-5,log:3)
B(6,6,-4,log:7)
B(6,6,11,log:3)
B(6,6,12,log:7)
B(6,6,13,LOG:11)
B(6,6,14,log:3)
B(6,7,-7,log:7)
B(6,7,-6,log:3)
B(6,7,-5,LOG:11)
B(6,7,-4,log:7)
B(6,7,-3,log:3)
B(6,7,10,log:3)
B(6,7,11,log:7)
B(6,7,12,LOG:11)
B(6,7,13,log:7)
B(6,8,-6,log:7)
B(6,8,-5,log:7)
B(6,8,-4,log:7)
B(6,8,-3,LOG:11)
B(6,8,10,log:7)
B(6,8,11,log:7)
B(6,8,12,LOG:11)
B(6,8,13,log:3)
B(6,9,-6,leaves:3)
B(6,9,-5,log:7)
B(6,9,-4,leaves:3)
B(6,9,-3,log:3)
B(6,9,-2,LOG:11)
B(6,9,-1,log:3)
B(6,9,11,log:7)
B(6,9,12,log:7)
B(6,9,13,leaves:3)
B(6,10,-5,leaves:3)
B(6,10,-2,log:3)
B(6,10,-1,LOG:11)
B(6,10,0,log:3)
B(6,10,12,leaves:3)
B(6,11,-2,log:3)
B(6,11,-1,log:7)
B(6,11,0,log:7)
B(6,12,-1,LOG:11)
B(6,13,-1,log:7)
B(6,16,3,leaves:3)
B(6,25,4,leaves:3)
B(6,26,4,leaves:3)
B(6,27,4,leaves:3)
B(6,28,4,leaves:3)
B(6,28,5,leaves:3)
B(6,28,6,leaves:3)
B(6,29,2,leaves:3)
B(6,29,3,leaves:3)
B(6,29,4,LOG:11)
B(6,29,5,log:3)
B(6,29,6,leaves:3)
B(6,30,2,leaves:3)
B(6,30,3,log:3)
B(6,30,4,log:3)
B(6,30,5,log:7)
B(6,30,6,log:7)
B(6,30,7,leaves:3)
B(6,31,2,leaves:3)
B(6,31,3,leaves:3)
B(6,31,4,log:3)
B(6,31,5,LOG:11)
B(6,31,6,log:7)
B(6,31,7,leaves:3)
B(6,31,8,leaves:3)
B(6,32,4,leaves:3)
B(6,32,5,LOG:11)
B(6,32,6,leaves:3)
B(6,32,7,leaves:3)
B(6,33,0,log:3)
B(6,33,3,leaves:3)
B(6,33,4,leaves:3)
B(6,33,5,leaves:3)
B(6,33,6,leaves:3)
B(6,34,-3,leaves:3)
B(6,34,-2,leaves:3)
B(6,34,-1,LOG:11)
B(6,34,0,LOG:11)
B(6,34,2,leaves:3)
B(6,34,3,leaves:3)
B(6,34,4,leaves:3)
B(6,35,-3,leaves:3)
B(6,35,-2,LOG:11)
B(6,35,-1,log:3)
B(6,35,0,log:3)
B(6,35,3,leaves:3)
B(6,36,-3,leaves:3)
B(6,36,-2,leaves:3)
B(6,36,-1,log:7)
B(6,36,0,leaves:3)
B(6,37,-1,leaves:3)
B(7,1,-6,log:3)
B(7,2,-6,log:3)
B(7,3,-6,log:3)
B(7,3,-4,log:3)
B(7,4,-6,log:3)
B(7,4,-4,log:3)
B(7,4,0,log:3)
B(7,5,-8,LOG:11)
B(7,5,-7,log:7)
B(7,5,-6,log:7)
B(7,5,-4,log:3)
B(7,5,0,log:3)
B(7,5,13,log:7)
B(7,5,14,log:7)
B(7,6,-8,LOG:11)
B(7,6,-7,LOG:11)
B(7,6,-6,log:3)
B(7,6,-5,log:3)
B(7,6,-4,log:3)
B(7,6,0,log:3)
B(7,6,12,LOG:11)
B(7,6,13,log:7)
B(7,6,14,log:7)
B(7,6,15,LOG:11)
B(7,7,-8,log:3)
B(7,7,-7,log:3)
B(7,7,-6,log:3)
B(7,7,-5,log:3)
B(7,7,-4,log:3)
B(7,7,-1,log:3)
B(7,7,0,log:3)
B(7,7,11,log:3)
B(7,7,12,log:3)
B(7,7,13,LOG:11)
B(7,7,14,log:7)
B(7,8,-7,log:7)
B(7,8,-6,LOG:11)
B(7,8,-5,LOG:11)
B(7,8,-1,log:3)
B(7,8,0,log:3)
B(7,8,11,LOG:11)
B(7,8,12,LOG:11)
B(7,8,13,LOG:11)
B(7,9,-5,leaves:3)
B(7,9,-2,log:3)
B(7,9,-1,LOG:11)
B(7,9,0,log:3)
B(7,9,12,LOG:11)
B(7,10,-2,LOG:11)
B(7,10,-1,log:7)
B(7,10,0,LOG:11)
B(7,11,-2,leaves:3)
B(7,11,-1,log:7)
B(7,11,0,leaves:3)
B(7,12,-1,leaves:3)
B(7,26,8,leaves:3)
B(7,27,8,leaves:3)
B(7,28,5,leaves:3)
B(7,28,8,leaves:3)
B(7,29,3,leaves:3)
B(7,29,4,leaves:3)
B(7,29,5,leaves:3)
B(7,29,6,leaves:3)
B(7,29,8,leaves:3)
B(7,30,2,leaves:3)
B(7,30,3,leaves:3)
B(7,30,4,log:3)
B(7,30,5,log:3)
B(7,30,6,LOG:11)
B(7,30,7,leaves:3)
B(7,30,8,leaves:3)
B(7,31,3,leaves:3)
B(7,31,4,log:3)
B(7,31,5,log:3)
B(7,31,6,LOG:11)
B(7,31,7,LOG:11)
B(7,31,8,leaves:3)
B(7,32,4,leaves:3)
B(7,32,5,log:7)
B(7,32,6,log:7)
B(7,32,7,log:7)
B(7,32,8,leaves:3)
B(7,33,-1,leaves:3)
B(7,33,5,leaves:3)
B(7,33,6,leaves:3)
B(7,33,7,leaves:3)
B(7,34,-2,leaves:3)
B(7,34,-1,log:3)
B(7,34,0,leaves:3)
B(7,35,-3,leaves:3)
B(7,35,-2,log:3)
B(7,35,-1,LOG:11)
B(7,35,0,LOG:11)
B(7,36,-2,leaves:3)
B(7,36,-1,LOG:11)
B(7,37,-2,leaves:3)
B(7,37,-1,leaves:3)
B(7,37,0,leaves:3)
B(7,38,-1,leaves:3)
B(8,0,-9,log:3)
B(8,0,12,log:3)
B(8,1,-9,log:3)
B(8,1,12,log:3)
B(8,2,-9,log:3)
B(8,2,12,log:3)
B(8,3,-9,log:3)
B(8,3,12,log:3)
B(8,4,-9,log:7)
B(8,4,-8,log:3)
B(8,4,-7,LOG:11)
B(8,4,12,log:7)
B(8,4,13,log:3)
B(8,5,-9,log:7)
B(8,5,-8,log:7)
B(8,5,-7,log:3)
B(8,5,-6,LOG:11)
B(8,5,12,LOG:11)
B(8,5,13,log:7)
B(8,5,14,log:7)
B(8,6,-8,log:7)
B(8,6,-7,log:3)
B(8,6,-6,log:7)
B(8,6,-1,log:7)
B(8,6,12,log:7)
B(8,6,13,LOG:11)
B(8,6,14,log:7)
B(8,7,-7,LOG:11)
B(8,7,-6,LOG:11)
B(8,7,-5,LOG:11)
B(8,7,-2,log:7)
B(8,7,-1,log:3)
B(8,7,0,log:3)
B(8,7,12,LOG:11)
B(8,7,13,log:3)
B(8,8,-7,LOG:11)
B(8,8,-2,log:7)
B(8,8,-1,log:7)
B(8,8,0,log:3)
B(8,8,12,log:3)
B(8,9,-2,log:7)
B(8,9,-1,log:3)
B(8,9,0,LOG:11)
B(8,10,-1,log:7)
B(8,11,-2,leaves:3)
B(8,11,-1,leaves:3)
B(8,11,0,leaves:3)
B(8,12,-1,leaves:3)
B(8,29,5,leaves:3)
B(8,29,6,leaves:3)
B(8,29,7,leaves:3)
B(8,30,5,leaves:3)
B(8,30,6,log:7)
B(8,30,7,LOG:11)
B(8,31,4,leaves:3)
B(8,31,5,log:3)
B(8,31,6,log:7)
B(8,31,7,LOG:11)
B(8,31,8,log:3)
B(8,32,4,leaves:3)
B(8,32,5,leaves:3)
B(8,32,6,LOG:11)
B(8,32,7,LOG:11)
B(8,32,8,log:3)
B(8,33,-2,leaves:3)
B(8,33,-1,leaves:3)
B(8,33,0,leaves:3)
B(8,33,4,leaves:3)
B(8,33,5,leaves:3)
B(8,33,6,leaves:3)
B(8,33,7,log:3)
B(8,33,8,leaves:3)
B(8,33,9,leaves:3)
B(8,34,-2,leaves:3)
B(8,34,-1,log:3)
B(8,34,0,leaves:3)
B(8,34,8,leaves:3)
B(8,35,-2,log:3)
B(8,35,-1,log:3)
B(8,35,0,log:3)
B(8,36,-2,LOG:11)
B(8,36,-1,log:3)
B(8,36,0,LOG:11)
B(8,37,-2,leaves:3)
B(8,37,-1,LOG:11)
B(8,37,0,leaves:3)
B(8,38,-2,leaves:3)
B(8,38,-1,leaves:3)
B(8,38,0,leaves:3)
B(9,0,1,log:3)
B(9,0,15,log:3)
B(9,1,1,log:3)
B(9,1,15,log:3)
B(9,2,-7,log:3)
B(9,2,1,log:3)
B(9,2,14,log:3)
B(9,2,15,LOG:11)
B(9,3,-10,log:3)
B(9,3,-9,log:3)
B(9,3,-8,log:3)
B(9,3,-7,log:3)
B(9,3,-2,log:3)
B(9,3,1,log:3)
B(9,3,12,log:7)
B(9,3,14,log:3)
B(9,4,-10,LOG:11)
B(9,4,-9,log:7)
B(9,4,-8,LOG:11)
B(9,4,-7,log:3)
B(9,4,-2,log:3)
B(9,4,1,log:7)
B(9,4,11,LOG:11)
B(9,4,12,log:7)
B(9,4,13,log:3)
B(9,4,14,log:3)
B(9,5,-9,log:7)
B(9,5,-8,log:3)
B(9,5,-7,log:7)
B(9,5,-2,log:3)
B(9,5,11,LOG:11)
B(9,5,12,log:3)
B(9,5,13,LOG:11)
B(9,5,14,LOG:11)
B(9,6,-8,log:7)
B(9,6,-7,LOG:11)
B(9,6,-2,log:3)
B(9,6,-1,log:3)
B(9,6,0,log:7)
B(9,6,12,LOG:11)
B(9,6,13,log:3)
B(9,7,-2,LOG:11)
B(9,7,-1,log:7)
B(9,7,0,log:7)
B(9,8,-1,log:3)
B(9,9,-2,log:3)
B(9,9,-1,log:3)
B(9,9,0,log:3)
B(9,10,-1,LOG:11)
B(9,11,-1,leaves:3)
B(9,28,-2,leaves:3)
B(9,29,-2,leaves:3)
B(9,29,6,leaves:3)
B(9,29,9,leaves:3)
B(9,30,-2,leaves:3)
B(9,30,5,leaves:3)
B(9,30,6,leaves:3)
B(9,30,7,leaves:3)
B(9,30,8,leaves:3)
B(9,30,9,leaves:3)
B(9,30,10,leaves:3)
B(9,31,-2,leaves:3)
B(9,31,5,leaves:3)
B(9,31,6,log:3)
B(9,31,7,LOG:11)
B(9,31,8,log:7)
B(9,31,9,leaves:3)
B(9,31,10,leaves:3)
B(9,32,-2,leaves:3)
B(9,32,4,leaves:3)
B(9,32,5,leaves:3)
B(9,32,6,LOG:11)
B(9,32,7,log:7)
B(9,32,8,LOG:11)
B(9,32,9,LOG:11)
B(9,32,10,leaves:3)
B(9,32,11,leaves:3)
B(9,33,-2,leaves:3)
B(9,33,-1,leaves:3)
B(9,33,5,leaves:3)
B(9,33,7,log:7)
B(9,33,8,log:7)
B(9,33,9,leaves:3)
B(9,33,10,leaves:3)
B(9,34,-2,leaves:3)
B(9,34,-1,leaves:3)
B(9,34,0,leaves:3)
B(9,34,7,leaves:3)
B(9,34,8,leaves:3)
B(9,34,9,leaves:3)
B(9,35,-2,log:3)
B(9,35,-1,log:3)
B(9,36,-3,log:3)
B(9,36,-2,LOG:11)
B(9,36,-1,log:7)
B(9,36,0,LOG:11)
B(9,37,-3,leaves:3)
B(9,37,-2,log:3)
B(9,37,-1,log:3)
B(9,37,0,leaves:3)
B(9,38,-2,leaves:3)
B(9,38,-1,leaves:3)
B(10,0,-10,log:3)
B(10,0,10,LOG:11)
B(10,0,11,log:3)
B(10,1,-10,log:3)
B(10,1,10,log:3)
B(10,1,11,log:7)
B(10,2,-10,LOG:11)
B(10,2,-9,log:7)
B(10,2,11,log:3)
B(10,2,12,log:7)
B(10,3,-11,log:3)
B(10,3,-10,log:3)
B(10,3,-9,log:3)
B(10,3,-8,log:3)
B(10,3,11,LOG:11)
B(10,3,12,LOG:11)
B(10,3,13,log:7)
B(10,4,-10,log:3)
B(10,4,-9,log:3)
B(10,4,-8,log:7)
B(10,4,1,log:7)
B(10,4,11,LOG:11)
B(10,4,12,log:3)
B(10,4,13,log:7)
B(10,5,-9,log:3)
B(10,5,-8,log:7)
B(10,5,0,log:7)
B(10,5,1,log:7)
B(10,5,12,log:7)
B(10,5,13,log:7)
B(10,6,-1,LOG:11)
B(10,6,0,log:3)
B(10,6,1,log:7)
B(10,7,-2,LOG:11)
B(10,7,-1,LOG:11)
B(10,7,0,log:3)
B(10,7,1,LOG:11)
B(10,8,-2,leaves:3)
B(10,8,-1,log:7)
B(10,8,0,leaves:3)
B(10,9,-1,log:3)
B(10,25,10,leaves:3)
B(10,26,10,leaves:3)
B(10,27,10,leaves:3)
B(10,28,10,leaves:3)
B(10,29,8,leaves:3)
B(10,29,9,leaves:3)
B(10,29,10,leaves:3)
B(10,29,11,leaves:3)
B(10,30,8,leaves:3)
B(10,30,9,log:3)
B(10,30,10,leaves:3)
B(10,31,7,leaves:3)
B(10,31,8,LOG:11)
B(10,31,9,log:3)
B(10,31,10,log:3)
B(10,31,11,leaves:3)
B(10,32,7,LOG:11)
B(10,32,8,LOG:11)
B(10,32,9,log:7)
B(10,32,10,LOG:11)
B(10,32,11,leaves:3)
B(10,33,7,leaves:3)
B(10,33,8,LOG:11)
B(10,33,9,log:3)
B(10,33,10,leaves:3)
B(10,33,11,leaves:3)
B(10,34,-2,LOG:11)
B(10,34,8,leaves:3)
B(10,35,-3,LOG:11)
B(10,35,-2,log:3)
B(10,35,-1,log:7)
B(10,36,-3,log:3)
B(10,36,-2,log:3)
B(10,36,-1,log:7)
B(10,37,-3,leaves:3)
B(10,37,-2,LOG:11)
B(10,37,-1,leaves:3)
B(10,38,-3,leaves:3)
B(10,38,-2,leaves:3)
B(10,38,-1,leaves:3)
B(11,0,-12,log:7)
B(11,0,-1,log:3)
B(11,0,9,LOG:11)
B(11,0,10,LOG:11)
B(11,0,11,LOG:11)
B(11,0,12,log:3)
B(11,1,-12,log:3)
B(11,1,-1,log:3)
B(11,1,1,LOG:11)
B(11,1,9,log:3)
B(11,1,10,log:3)
B(11,1,11,LOG:11)
B(11,1,12,log:3)
B(11,2,-12,log:3)
B(11,2,-11,log:3)
B(11,2,-10,LOG:11)
B(11,2,-1,log:7)
B(11,2,1,log:3)
B(11,2,10,log:7)
B(11,2,11,LOG:11)
B(11,2,12,log:3)
B(11,2,13,LOG:11)
B(11,3,-12,log:7)
B(11,3,-11,LOG:11)
B(11,3,-10,LOG:11)
B(11,3,-9,LOG:11)
B(11,3,1,LOG:11)
B(11,3,11,log:7)
B(11,3,12,log:3)
B(11,3,13,log:3)
B(11,4,-11,log:3)
B(11,4,-10,LOG:11)
B(11,4,-9,log:3)
B(11,4,0,LOG:11)
B(11,4,1,log:7)
B(11,4,2,log:3)
B(11,4,12,log:3)
B(11,5,0,log:7)
B(11,5,1,LOG:11)
B(11,5,2,log:7)
B(11,6,-1,log:3)
B(11,6,0,LOG:11)
B(11,6,1,log:7)
B(11,6,2,LOG:11)
B(11,7,-1,log:3)
B(11,7,0,log:3)
B(11,7,1,LOG:11)
B(11,28,9,leaves:3)
B(11,28,10,leaves:3)
B(11,28,11,leaves:3)
B(11,29,9,log:3)
B(11,29,10,LOG:11)
B(11,29,11,leaves:3)
B(11,30,7,leaves:3)
B(11,30,8,log:3)
B(11,30,9,LOG:11)
B(11,30,10,log:3)
B(11,30,11,leaves:3)
B(11,30,12,leaves:3)
B(11,31,7,leaves:3)
B(11,31,8,log:3)
B(11,31,9,log:3)
B(11,31,10,log:7)
B(11,31,11,LOG:11)
B(11,32,7,leaves:3)
B(11,32,8,log:3)
B(11,32,9,log:7)
B(11,32,10,log:3)
B(11,32,11,leaves:3)
B(11,33,-2,log:7)
B(11,33,9,log:7)
B(11,33,10,leaves:3)
B(11,33,11,leaves:3)
B(11,34,-3,log:3)
B(11,34,-2,log:7)
B(11,34,-1,LOG:11)
B(11,35,-3,log:3)
B(11,35,-2,log:3)
B(11,35,-1,LOG:11)
B(11,36,-2,LOG:11)
B(11,37,-3,leaves:3)
B(11,37,-2,leaves:3)
B(11,37,-1,leaves:3)
B(11,38,-2,leaves:3)
B(12,0,-13,log:7)
B(12,0,-12,LOG:11)
B(12,0,-11,LOG:11)
B(12,0,1,log:3)
B(12,0,8,log:3)
B(12,0,9,log:7)
B(12,0,10,LOG:11)
B(12,0,11,log:7)
B(12,1,-13,log:3)
B(12,1,-12,log:7)
B(12,1,-11,log:7)
B(12,1,0,LOG:11)
B(12,1,1,log:7)
B(12,1,2,log:3)
B(12,1,10,LOG:11)
B(12,1,11,LOG:11)
B(12,2,-13,log:7)
B(12,2,-12,LOG:11)
B(12,2,-11,log:3)
B(12,2,-10,log:7)
B(12,2,-1,LOG:11)
B(12,2,0,log:7)
B(12,2,1,log:3)
B(12,2,2,log:3)
B(12,2,11,log:7)
B(12,2,12,log:3)
B(12,2,13,LOG:11)
B(12,3,-12,log:3)
B(12,3,-11,LOG:11)
B(12,3,-10,log:7)
B(12,3,0,log:7)
B(12,3,1,log:3)
B(12,3,2,log:7)
B(12,3,12,log:3)
B(12,4,-11,log:3)
B(12,4,0,LOG:11)
B(12,4,1,log:3)
B(12,4,2,log:3)
B(12,5,1,log:3)
B(12,6,0,LOG:11)
B(12,6,1,log:3)
B(12,28,10,LOG:11)
B(12,29,9,LOG:11)
B(12,29,10,LOG:11)
B(12,29,11,LOG:11)
B(12,29,12,leaves:3)
B(12,30,8,leaves:3)
B(12,30,9,log:7)
B(12,30,10,log:3)
B(12,30,11,LOG:11)
B(12,30,12,leaves:3)
B(12,31,7,leaves:3)
B(12,31,8,leaves:3)
B(12,31,9,log:3)
B(12,31,10,log:3)
B(12,31,11,LOG:11)
B(12,31,12,leaves:3)
B(12,32,8,leaves:3)
B(12,32,9,LOG:11)
B(12,32,10,LOG:11)
B(12,32,11,leaves:3)
B(12,33,-3,leaves:3)
B(12,33,-2,LOG:11)
B(12,33,10,leaves:3)
B(12,34,-4,leaves:3)
B(12,34,-3,LOG:11)
B(12,34,-2,log:3)
B(12,34,-1,log:3)
B(12,35,-3,leaves:3)
B(12,35,-2,log:7)
B(12,35,-1,leaves:3)
B(12,36,-3,leaves:3)
B(12,36,-2,leaves:3)
B(12,36,-1,leaves:3)
B(13,0,-14,log:3)
B(13,0,-13,log:7)
B(13,0,-12,log:7)
B(13,0,-11,log:7)
B(13,0,-2,LOG:11)
B(13,0,0,log:3)
B(13,0,1,log:7)
B(13,0,2,log:7)
B(13,0,7,log:7)
B(13,0,8,log:7)
B(13,0,9,LOG:11)
B(13,0,10,LOG:11)
B(13,0,13,log:3)
B(13,1,-13,log:7)
B(13,1,-12,log:3)
B(13,1,-1,log:7)
B(13,1,0,LOG:11)
B(13,1,1,LOG:11)
B(13,1,2,log:7)
B(13,1,8,LOG:11)
B(13,1,13,log:3)
B(13,2,-12,log:7)
B(13,2,-11,log:7)
B(13,2,-2,log:7)
B(13,2,-1,log:7)
B(13,2,0,LOG:11)
B(13,2,1,LOG:11)
B(13,2,13,log:7)
B(13,3,-11,LOG:11)
B(13,3,-1,log:7)
B(13,3,0,log:7)
B(13,3,1,LOG:11)
B(13,4,1,LOG:11)
B(13,26,8,leaves:3)
B(13,27,8,leaves:3)
B(13,28,8,leaves:3)
B(13,29,-4,leaves:3)
B(13,29,8,leaves:3)
B(13,29,10,LOG:11)
B(13,29,11,leaves:3)
B(13,30,-4,leaves:3)
B(13,30,8,leaves:3)
B(13,30,9,leaves:3)
B(13,30,10,log:3)
B(13,30,11,leaves:3)
B(13,30,12,leaves:3)
B(13,31,-4,leaves:3)
B(13,31,8,leaves:3)
B(13,31,9,leaves:3)
B(13,31,10,LOG:11)
B(13,31,11,leaves:3)
B(13,32,-4,leaves:3)
B(13,32,-3,leaves:3)
B(13,32,9,leaves:3)
B(13,33,-4,leaves:3)
B(13,33,-3,log:7)
B(13,33,-2,LOG:11)
B(13,34,-4,log:7)
B(13,34,-3,LOG:11)
B(13,34,-2,log:3)
B(13,34,-1,LOG:11)
B(13,35,-4,leaves:3)
B(13,35,-3,leaves:3)
B(13,35,-2,log:7)
B(13,35,-1,leaves:3)
B(13,36,-2,leaves:3)
B(14,0,-13,log:3)
B(14,0,-12,log:3)
B(14,0,-3,LOG:11)
B(14,0,-2,log:3)
B(14,0,-1,LOG:11)
B(14,0,0,log:7)
B(14,0,1,log:3)
B(14,0,2,log:3)
B(14,0,7,log:7)
B(14,0,8,log:3)
B(14,1,-2,log:3)
B(14,1,0,log:7)
B(14,1,1,log:3)
B(14,2,-1,log:3)
B(14,2,0,LOG:11)
B(14,32,-4,leaves:3)
B(14,32,-3,log:7)
B(14,32,-2,leaves:3)
B(14,33,-4,log:3)
B(14,33,-3,log:3)
B(14,33,-2,log:7)
B(14,34,-4,leaves:3)
B(14,34,-3,leaves:3)
B(14,34,-2,LOG:11)
B(14,35,-3,leaves:3)
B(15,0,-2,log:3)
B(15,0,-1,log:7)
B(15,0,1,LOG:11)
B(15,32,-3,leaves:3)
B(15,33,-4,leaves:3)
B(15,33,-3,leaves:3)
B(15,33,-2,leaves:3)
B(15,34,-3,leaves:3)

#
# +-----------------------------------------------------------------+ #
# |                            BO3 checks                           | #
# +-----------------------------------------------------------------+ #
#

BlockCheck(0,8,0,grass,dirt)
BlockCheckNot(-32,-3,32,water)
BlockCheckNot(-32,-3,-32,water)
BlockCheckNot(32,-3,-32,water)
BlockCheckNot(32,-3,32,water)
BlockCheckNot(-32,-3,32,water)

#
# +-----------------------------------------------------------------+ #
# |                             Branches                            | #
# +-----------------------------------------------------------------+ #
#

