
#######################################################################
# +-----------------------------------------------------------------+ #
# |                            BO3 object                           | #
# +-----------------------------------------------------------------+ #
#######################################################################

Author: NLBlackEagle

Description: Converted version of the BO2 SA11L

Version: 3

SettingsMode: WriteDisable


#######################################################################
# +-----------------------------------------------------------------+ #
# |                          Main settings                          | #
# +-----------------------------------------------------------------+ #
#######################################################################

Tree: true

Frequency: 1

Rarity: 100.0

RotateRandomly: true

SpawnHeight: highestSolidBlock

SpawnHeightOffset: 0

SpawnHeightVariance: 0

##############################
# Height Limits for the BO3. #
##############################

MinHeight: 0

MaxHeight: 199

######################
# Extrusion settings #
######################

ExtrudeMode: None

ExtrudeThroughBlocks: AIR

MaxBranchDepth: 10

ExcludedBiomes: 


#######################################################################
# +-----------------------------------------------------------------+ #
# |                      Source block settings                      | #
# +-----------------------------------------------------------------+ #
#######################################################################

SourceBlocks: AIR,GRASS,DIRT,SAND

MaxPercentageOutsideSourceBlock: 0

OutsideSourceBlock: placeAnyway

IsOTGPlus: false

InheritBO3: 

InheritBO3Rotation: NORTH

OverrideChildSettings: true

OverrideParentHeight: false

CanOverride: false

BranchFrequency: 0

BranchFrequencyGroup: 

MustBeBelowOther: false

MustBeInside: 

CannotBeInside: 

ReplacesBO3: 

CanSpawnOnWater: true

SpawnOnWaterOnly: false

SpawnUnderWater: false

SpawnAtWaterLevel: false

HeightOffset: 0

RemoveAir: true

ReplaceAbove: 

ReplaceBelow: 

ReplaceWithBiomeBlocks: true

ReplaceWithGroundBlock: DIRT

ReplaceWithSurfaceBlock: GRASS

SmoothRadius: 0

SmoothHeightOffset: 0

SmoothStartTop: false

SmoothStartWood: false

SmoothingSurfaceBlock: 

SmoothingGroundBlock: 

BO3Group: 

IsSpawnPoint: false


#######################################################################
# +-----------------------------------------------------------------+ #
# |                              Blocks                             | #
# +-----------------------------------------------------------------+ #
#######################################################################

B(1,14,3,Leaves:4)
B(1,11,3,Leaves:4)
B(2,9,3,Leaves:4)
B(4,10,-5,LOG:14)
B(1,10,3,LOG:14)
B(4,14,-5,Leaves:4)
B(3,14,-6,Leaves:4)
B(1,11,2,Leaves:4)
B(1,10,2,Leaves:4)
B(2,8,2,LEAVES:4)
B(1,10,1,Leaves:4)
Block(-1,9,3,Leaves:4)
B(1,12,-4,Leaves:4)
B(1,11,-4,Leaves:4)
Block(-3,10,2,LOG:14)
B(6,8,-6,Leaves:4)
Block(-3,12,5,Leaves:4)
B(0,12,3,Leaves:4)
B(0,11,-2,Leaves:4)
Block(-3,12,2,Leaves:4)
B(0,11,2,Leaves:4)
B(0,10,2,Leaves:4)
Block(-4,13,2,Leaves:4)
B(3,9,1,Leaves:4)
Block(-6,12,3,Leaves:4)
B(3,4,1,LEAVES:4)
Block(-4,11,1,LOG:14)
B(3,6,1,LEAVES:4)
B(3,7,1,LOG:14)
B(3,9,-7,Leaves:4)
B(3,6,0,LOG:14)
B(3,14,2,Leaves:4)
Block(-3,13,1,Leaves:4)
B(8,10,-4,Leaves:4)
Block(-3,12,1,Leaves:4)
B(3,10,2,Leaves:4)
B(8,13,-4,Leaves:4)
B(3,11,2,Leaves:4)
Block(-1,13,5,Leaves:4)
B(5,12,3,Leaves:4)
Block(-3,13,-3,Leaves:4)
Block(-3,11,-3,Leaves:4)
B(7,14,-1,Leaves:4)
Block(-5,13,4,Leaves:4)
Block(-4,11,2,Leaves:4)
Block(-6,14,-4,LEAVES:4)
B(7,11,-1,Leaves:4)
B(0,8,2,LOG:14)
B(5,10,3,Leaves:4)
B(0,9,2,Leaves:4)
B(1,10,-3,Leaves:4)
B(6,12,-3,Leaves:4)
B(3,10,-2,LOG:14)
Block(-2,8,-5,Leaves:4)
Block(-6,12,0,Leaves:4)
B(3,11,-4,Leaves:4)
B(3,11,-5,LOG:14)
B(3,10,-5,Leaves:4)
Block(-1,9,-6,Leaves:4)
B(3,10,-4,Leaves:4)
B(5,9,1,LEAVES:4)
B(6,10,-3,Leaves:4)
B(6,9,-5,Leaves:4)
Block(-1,11,-5,Leaves:4)
Block(-1,11,-6,Leaves:4)
B(4,9,-2,Leaves:4)
Block(-1,10,-6,Leaves:4)
Block(-1,13,-5,Leaves:4)
B(4,8,-2,LEAVES:4)
Block(-1,14,-5,Leaves:4)
B(1,9,-2,Leaves:4)
Block(-3,10,-4,Leaves:4)
Block(-2,8,0,Leaves:4)
B(1,8,-1,LEAVES:4)
Block(-1,14,2,Leaves:4)
Block(-5,13,-4,Leaves:4)
B(1,6,-1,LEAVES:4)
Block(-6,10,-3,LEAVES:4)
Block(-5,14,-4,Leaves:4)
Block(-6,13,-3,LEAVES:4)
B(4,9,-3,Leaves:4)
B(4,8,-3,LOG:14)
B(3,9,-2,Leaves:4)
Block(-5,8,-3,Leaves:4)
Block(-1,10,2,Leaves:4)
B(3,7,-2,LOG:14)
Block(-5,9,-3,Leaves:4)
Block(-2,10,-3,Leaves:4)
B(1,5,0,LOG:14)
B(3,7,-4,Leaves:4)
B(8,8,-3,Leaves:4)
B(1,4,0,LOG:14)
B(0,12,1,Leaves:4)
Block(-7,11,-3,LEAVES:4)
B(8,9,-2,Leaves:4)
B(0,13,1,Leaves:4)
Block(-7,10,-3,LEAVES:4)
B(6,9,-7,Leaves:4)
B(6,12,-2,Leaves:4)
B(6,10,-2,Leaves:4)
B(6,11,-2,LOG:14)
Block(-1,11,-4,LOG:14)
Block(-2,10,0,Leaves:4)
Block(-2,12,0,Leaves:4)
B(4,11,0,LOG:14)
B(4,13,0,Leaves:4)
B(4,14,0,Leaves:4)
B(4,10,0,LOG:14)
B(3,7,-6,Leaves:4)
Block(-4,10,-5,Leaves:4)
Block(-4,11,4,Leaves:4)
Block(-4,9,-4,LOG:14)
B(2,10,2,Leaves:4)
B(2,14,2,Leaves:4)
B(5,13,-3,Leaves:4)
B(2,11,2,LOG:14)
Block(-1,14,-4,Leaves:4)
B(5,11,-3,Leaves:4)
B(5,11,-1,Leaves:4)
B(4,9,1,LEAVES:4)
B(6,8,1,LEAVES:4)
B(5,10,-4,Leaves:4)
B(5,11,-4,Leaves:4)
B(4,10,-2,Leaves:4)
B(5,12,-4,Leaves:4)
B(4,11,-2,Leaves:4)
B(6,6,1,LEAVES:4)
Block(-3,13,-5,LEAVES:4)
Block(-3,13,-2,Leaves:4)
B(4,4,0,LEAVES:4)
Block(-3,12,-2,Leaves:4)
Block(-3,12,-5,Leaves:4)
Block(-5,10,-3,LOG:14)
Block(-3,11,-5,LOG:14)
B(5,12,-5,Leaves:4)
Block(-2,11,-6,LEAVES:4)
B(5,8,0,Leaves:4)
Block(-5,11,-3,LOG:14)
B(5,7,0,LEAVES:4)
B(5,9,-3,Leaves:4)
B(2,4,1,LEAVES:4)
Block(-4,12,-4,Leaves:4)
Block(-4,11,-4,Leaves:4)
B(1,9,0,Leaves:4)
B(5,8,-7,Leaves:4)
B(7,9,-4,Leaves:4)
B(3,11,1,Leaves:4)
Block(-3,11,-6,LEAVES:4)
B(3,12,1,Leaves:4)
Block(-1,11,-7,LEAVES:4)
Block(-4,8,3,Leaves:4)
B(2,7,0,LEAVES:4)
B(5,10,-2,LOG:14)
B(3,7,2,LEAVES:4)
B(6,10,-5,Leaves:4)
Block(-1,7,1,LOG:14)
B(0,2,0,LOG:14)
Block(-1,8,1,Leaves:4)
B(3,7,3,LEAVES:4)
B(0,3,0,LOG:14)
B(0,0,0,LOG:14)
B(5,9,-6,Leaves:4)
B(0,1,0,LOG:14)
B(2,8,1,Leaves:4)
Block(-2,13,5,Leaves:4)
B(0,7,0,LEAVES:4)
B(0,4,0,LOG:14)
Block(-1,5,1,LOG:14)
B(2,5,1,LEAVES:4)
B(3,5,3,LEAVES:4)
Block(-1,6,1,LOG:14)
B(1,8,2,Leaves:4)
B(3,11,-1,Leaves:4)
Block(-1,11,-3,Leaves:4)
B(6,11,-6,Leaves:4)
Block(-6,8,-3,LEAVES:4)
B(1,7,2,LEAVES:4)
Block(-6,9,-3,LEAVES:4)
Block(-3,9,-3,Leaves:4)
Block(-1,10,-3,LOG:14)
Block(-3,8,-3,LOG:14)
B(5,9,-4,LOG:14)
B(1,9,3,LOG:14)
B(5,11,-2,Leaves:4)
B(5,14,-2,Leaves:4)
Block(-3,14,3,Leaves:4)
Block(-3,12,3,Leaves:4)
B(0,11,4,LOG:14)
B(0,12,4,Leaves:4)
B(4,5,2,LEAVES:4)
Block(-1,11,1,LOG:14)
Block(-1,12,1,Leaves:4)
B(3,9,-5,Leaves:4)
Block(-1,13,1,Leaves:4)
Block(-5,11,3,Leaves:4)
Block(-2,11,-2,Leaves:4)
B(8,13,-2,Leaves:4)
B(5,10,0,Leaves:4)
B(5,11,0,Leaves:4)
B(4,8,4,LEAVES:4)
B(4,9,4,Leaves:4)
B(1,10,-1,Leaves:4)
B(6,7,2,LEAVES:4)
Block(-3,9,1,Leaves:4)
B(9,11,-2,Leaves:4)
B(2,13,3,Leaves:4)
B(6,9,2,Leaves:4)
B(2,10,3,Leaves:4)
B(2,11,-5,Leaves:4)
B(6,8,2,LEAVES:4)
Block(-4,14,3,Leaves:4)
Block(-5,12,0,Leaves:4)
B(9,11,-1,Leaves:4)
Block(-3,9,2,LOG:14)
B(2,10,-5,Leaves:4)
Block(-5,11,0,Leaves:4)
Block(-2,10,-4,Leaves:4)
Block(-1,12,3,Leaves:4)
Block(-3,11,6,Leaves:4)
B(5,12,2,Leaves:4)
B(0,8,-1,LOG:14)
B(0,7,-1,LOG:14)
B(2,10,-6,Leaves:4)
B(2,12,-3,Leaves:4)
B(6,9,0,Leaves:4)
B(0,10,-4,Leaves:4)
B(4,9,-1,LOG:14)
B(4,11,-3,Leaves:4)
B(4,8,-1,LOG:14)
Block(-4,11,3,Leaves:4)
B(4,10,-3,Leaves:4)
B(2,10,-1,Leaves:4)
B(5,10,-7,Leaves:4)
Block(-2,7,-2,LOG:14)
B(0,9,0,LOG:14)
B(4,12,3,Leaves:4)
B(3,7,-1,LEAVES:4)
B(2,9,4,Leaves:4)
Block(-6,10,4,Leaves:4)
B(4,11,3,Leaves:4)
B(4,8,-4,Leaves:4)
B(2,7,4,LEAVES:4)
B(3,9,-1,LEAVES:4)
B(0,8,1,LEAVES:4)
B(6,6,-3,Leaves:4)
Block(-2,8,2,LOG:14)
Block(-2,13,4,Leaves:4)
Block(-2,12,4,Leaves:4)
Block(-1,9,-4,Leaves:4)
Block(-1,8,-4,Leaves:4)
Block(-4,11,-3,Leaves:4)
Block(-5,8,-4,Leaves:4)
B(1,10,0,LOG:14)
B(1,11,0,LOG:14)
Block(-5,9,-5,Leaves:4)
Block(-4,14,-3,Leaves:4)
Block(-1,12,-1,Leaves:4)
Block(-1,11,-1,Leaves:4)
Block(-1,8,-5,Leaves:4)
Block(-1,9,-3,Leaves:4)
B(5,9,-5,Leaves:4)
B(3,10,-8,LEAVES:4)
B(6,13,2,Leaves:4)
B(6,11,2,Leaves:4)
Block(-2,11,2,Leaves:4)
B(7,13,-4,Leaves:4)
Block(-1,10,0,LOG:14)
Block(-1,11,0,Leaves:4)
B(0,10,-3,Leaves:4)
B(7,12,0,Leaves:4)
Block(-5,11,2,Leaves:4)
B(0,11,-6,Leaves:4)
Block(-3,13,4,Leaves:4)
Block(-3,14,4,Leaves:4)
B(0,11,-1,Leaves:4)
Block(-1,12,4,Leaves:4)
B(2,11,-2,Leaves:4)
B(8,10,-5,Leaves:4)
B(6,11,-1,Leaves:4)
B(6,10,-4,LOG:14)
B(6,12,-1,Leaves:4)
B(6,11,-4,Leaves:4)
B(2,9,-5,Leaves:4)
B(2,10,1,Leaves:4)
B(2,13,0,Leaves:4)
Block(-3,11,3,LOG:14)
B(1,10,-5,Leaves:4)
B(2,12,1,Leaves:4)
Block(-3,10,3,Leaves:4)
Block(-5,10,5,Leaves:4)
Block(-2,14,3,Leaves:4)
B(0,12,-7,Leaves:4)
Block(-2,11,3,Leaves:4)
B(2,10,0,Leaves:4)
B(5,9,-1,Leaves:4)
B(3,11,-3,Leaves:4)
Block(-6,11,-2,Leaves:4)
B(6,9,-4,Leaves:4)
B(4,8,-5,Leaves:4)
B(5,7,-1,LEAVES:4)
B(4,13,-1,Leaves:4)
B(5,5,-1,LEAVES:4)
Block(-7,9,-2,LEAVES:4)
Block(-4,10,-4,LOG:14)
Block(-2,11,1,Leaves:4)
Block(-1,6,-1,LOG:14)
B(1,11,-7,Leaves:4)
Block(-1,5,-1,LOG:14)
B(4,10,2,Leaves:4)
B(2,6,-1,LOG:14)
B(4,11,4,Leaves:4)
Block(-2,10,4,Leaves:4)
Block(-2,11,4,Leaves:4)
B(4,11,2,Leaves:4)
Block(-4,11,-6,LEAVES:4)
B(6,8,-2,Leaves:4)
Block(-2,9,-3,LOG:14)
B(4,13,2,Leaves:4)
Block(-4,9,-2,Leaves:4)
Block(-4,8,-2,Leaves:4)

#######################################################################
# +-----------------------------------------------------------------+ #
# |                            BO3 checks                           | #
# +-----------------------------------------------------------------+ #
#######################################################################

BlockCheck(0,-1,0,GRASS,DIRT)

#######################################################################
# +-----------------------------------------------------------------+ #
# |                             Branches                            | #
# +-----------------------------------------------------------------+ #
#######################################################################


#######################################################################
# +-----------------------------------------------------------------+ #
# |                             Entities                            | #
# +-----------------------------------------------------------------+ #
#######################################################################


#######################################################################
# +-----------------------------------------------------------------+ #
# |                            Particles                            | #
# +-----------------------------------------------------------------+ #
#######################################################################


#######################################################################
# +-----------------------------------------------------------------+ #
# |                             Spawners                            | #
# +-----------------------------------------------------------------+ #
#######################################################################


#######################################################################
# +-----------------------------------------------------------------+ #
# |                             ModData                             | #
# +-----------------------------------------------------------------+ #
#######################################################################

