
#
# +-----------------------------------------------------------------+ #
# |                            BO3 object                           | #
# +-----------------------------------------------------------------+ #
#

Author: NLBlackEagle

Description: Converted version of the BO2 SA14L

Version: 3

SettingsMode: WriteDisable


#
# +-----------------------------------------------------------------+ #
# |                          Main settings                          | #
# +-----------------------------------------------------------------+ #
#

Tree: true

Frequency: 1

Rarity: 100.0

RotateRandomly: true

SpawnHeight: highestSolidBlock

SpawnHeightOffset: 0

SpawnHeightVariance: 0


# Height Limits for the BO3. #


MinHeight: 0

MaxHeight: 199


# Extrusion settings #


ExtrudeMode: None

ExtrudeThroughBlocks: air

MaxBranchDepth: 10

ExcludedBiomes: 


#
# +-----------------------------------------------------------------+ #
# |                      Source block settings                      | #
# +-----------------------------------------------------------------+ #
#

SourceBlocks: AIR,GRASS,DIRT,SAND

MaxPercentageOutsideSourceBlock: 0

OutsideSourceBlock: placeAnyway


#
# +-----------------------------------------------------------------+ #
# |                              Blocks                             | #
# +-----------------------------------------------------------------+ #
#

B(0,50,-4,Leaves:4)
B(0,51,-4,Leaves:4)
B(3,40,4,leaves:4)
B(3,41,4,leaves:4)
B(-1,39,-7,leaves:4)
B(-1,46,-7,leaves:4)
B(-1,-3,-1,LOG:14)
B(-7,52,-3,leaves:4)
B(-7,51,-3,leaves:4)
B(-1,41,-7,leaves:4)
B(10,51,0,leaves:4)
B(3,51,4,Leaves:4)
B(7,50,-6,LOG:14)
B(-1,38,-7,leaves:4)
B(-7,47,-3,Leaves:4)
B(4,41,1,leaves:4)
B(0,43,-8,leaves:4)
B(-1,51,4,Leaves:4)
B(-1,52,4,LOG:14)
B(4,46,1,LOG:14)
B(-1,53,4,Leaves:4)
B(4,47,1,LOG:14)
B(0,42,-8,leaves:4)
B(-6,51,-5,Leaves:4)
B(-4,44,-6,leaves:4)
B(7,45,-6,leaves:4)
B(2,51,1,Leaves:4)
B(7,46,-6,leaves:4)
B(-5,39,-5,leaves:4)
B(-5,38,-5,leaves:4)
B(4,39,1,leaves:4)
B(0,52,-8,Leaves:4)
B(0,50,-5,LOG:14)
B(0,53,-8,leaves:4)
B(0,53,-5,Leaves:4)
B(0,49,-2,Leaves:4)
B(0,52,-5,Leaves:4)
B(-9,44,-2,leaves:4)
B(-4,53,-6,leaves:4)
B(-4,52,-6,leaves:4)
B(0,49,-4,Leaves:4)
B(0,45,-4,leaves:4)
B(-9,45,-2,leaves:4)
B(0,46,-4,leaves:4)
B(3,39,4,leaves:4)
B(-3,47,-5,LOG:14)
B(-4,49,-6,LOG:14)
B(-4,46,-6,leaves:4)
B(5,38,2,leaves:4)
B(1,8,-2,LOG:14)
B(1,9,-2,LOG:14)
B(3,53,-6,Leaves:4)
B(1,6,-2,LOG:14)
B(-3,43,-5,leaves:4)
B(-3,39,-1,leaves:4)
B(1,7,-2,LOG:14)
B(1,4,-2,LOG:14)
B(-3,45,-5,leaves:4)
B(1,5,-2,LOG:14)
B(-3,44,-5,leaves:4)
B(4,52,-5,Leaves:4)
B(1,2,-2,LOG:14)
B(1,3,-2,LOG:14)
B(1,0,-2,LOG:14)
B(4,53,-5,Leaves:4)
B(3,52,-6,Leaves:4)
B(1,1,-2,LOG:14)
B(6,44,0,LOG:14)
B(6,49,0,LOG:14)
B(9,53,-7,leaves:4)
B(0,37,-5,leaves:4)
B(9,54,-7,leaves:4)
B(-3,39,-5,leaves:4)
B(-3,36,-2,leaves:4)
B(-3,39,-2,LOG:14)
B(-3,38,-2,leaves:4)
B(0,51,-2,Leaves:4)
B(-3,53,-2,Leaves:4)
B(0,50,-2,Leaves:4)
B(9,45,-7,leaves:4)
B(-3,51,-2,Leaves:4)
B(4,47,-5,LOG:14)
B(4,46,-5,leaves:4)
B(4,44,-5,leaves:4)
B(-3,49,-2,LOG:14)
B(6,50,-10,Leaves:4)
B(-4,52,-10,leaves:4)
B(-2,45,-2,LOG:14)
B(-2,51,-2,Leaves:4)
B(1,53,-10,leaves:4)
B(1,52,-8,LOG:14)
B(3,42,-6,leaves:4)
B(1,51,-8,Leaves:4)
B(3,43,-6,LOG:14)
B(5,45,2,leaves:4)
B(5,48,2,LOG:14)
B(1,53,-8,leaves:4)
B(6,44,-10,leaves:4)
B(6,52,0,Leaves:4)
B(-2,39,-2,leaves:4)
B(6,46,-10,leaves:4)
B(-2,38,-2,LOG:14)
B(-5,50,0,Leaves:4)
B(2,-3,-1,LOG:14)
B(-2,40,-2,leaves:4)
B(2,-2,-1,LOG:14)
B(2,-1,-1,LOG:14)
B(10,56,-5,leaves:4)
B(10,54,-2,leaves:4)
B(5,43,-6,leaves:4)
B(10,55,-2,leaves:4)
B(5,45,-6,leaves:4)
B(5,43,-3,LOG:14)
B(2,24,-1,LOG:14)
B(2,25,-1,LOG:14)
B(2,26,-1,LOG:14)
B(2,27,-1,LOG:14)
B(2,28,-1,LOG:14)
B(2,29,-1,LOG:14)
B(10,54,-5,leaves:4)
B(10,55,-5,leaves:4)
B(-5,37,0,leaves:4)
B(3,42,0,leaves:4)
B(3,55,-8,leaves:4)
B(-2,48,-1,LOG:14)
B(2,21,-1,LOG:14)
B(10,46,-1,leaves:4)
B(-8,48,-2,Leaves:4)
B(7,50,2,Leaves:4)
B(2,20,-1,LOG:14)
B(10,45,-1,leaves:4)
B(3,45,0,LOG:14)
B(2,23,-1,LOG:14)
B(3,44,0,LOG:14)
B(2,22,-1,LOG:14)
B(-8,47,-2,Leaves:4)
B(5,48,-6,LOG:14)
B(1,45,-8,leaves:4)
B(5,47,-3,leaves:4)
B(3,52,-8,Leaves:4)
B(1,42,-10,leaves:4)
B(7,44,-9,leaves:4)
B(0,0,-3,LOG:14)
B(1,40,-8,leaves:4)
B(3,53,-8,leaves:4)
B(1,41,-8,leaves:4)
B(5,50,-3,LOG:14)
B(10,45,-2,leaves:4)
B(5,51,-3,LOG:14)
B(10,43,-2,leaves:4)
B(5,52,-3,Leaves:4)
B(-5,54,2,leaves:4)
B(5,53,-3,Leaves:4)
B(10,46,-2,leaves:4)
B(-1,47,-1,LOG:14)
B(2,37,-1,LOG:14)
B(7,49,2,Leaves:4)
B(2,35,-1,LOG:14)
B(2,36,-1,LOG:14)
B(7,45,2,leaves:4)
B(7,46,2,LOG:14)
B(2,39,-1,leaves:4)
B(7,47,2,leaves:4)
B(2,30,-1,LOG:14)
B(-2,52,0,Leaves:4)
B(7,44,2,leaves:4)
B(11,47,-4,leaves:4)
B(2,34,-1,LOG:14)
B(2,33,-1,LOG:14)
B(2,32,-1,LOG:14)
B(11,44,-4,leaves:4)
B(2,31,-1,LOG:14)
B(4,-2,-2,LOG:14)
B(4,-3,-2,LOG:14)
B(7,52,-9,Leaves:4)
B(12,45,-3,leaves:4)
B(-3,52,-9,leaves:4)
B(-2,41,0,leaves:4)
B(-2,49,0,LOG:14)
B(2,-1,-2,LOG:14)
B(-6,53,-10,leaves:4)
B(10,47,-5,leaves:4)
B(10,45,-5,leaves:4)
B(10,46,-5,leaves:4)
B(2,19,-1,LOG:14)
B(2,17,-1,LOG:14)
B(2,18,-1,LOG:14)
B(-1,-3,-4,LOG:14)
B(2,15,-1,LOG:14)
B(-1,-2,-4,LOG:14)
B(2,16,-1,LOG:14)
B(-2,41,-1,leaves:4)
B(2,13,-1,LOG:14)
B(2,14,-1,LOG:14)
B(2,12,-1,LOG:14)
B(2,11,-1,LOG:14)
B(2,10,-1,LOG:14)
B(10,55,-1,leaves:4)
B(10,54,-1,leaves:4)
B(10,52,-1,leaves:4)
B(10,51,-1,leaves:4)
B(5,53,-11,leaves:4)
B(5,52,-11,leaves:4)
B(3,36,0,leaves:4)
B(3,39,0,leaves:4)
B(-2,39,0,leaves:4)
B(3,38,0,leaves:4)
B(9,45,4,leaves:4)
B(2,30,-2,LOG:14)
B(2,38,3,leaves:4)
B(2,39,-2,LOG:14)
B(3,41,-2,LOG:14)
B(2,55,-9,leaves:4)
B(8,52,4,Leaves:4)
B(8,51,4,Leaves:4)
B(2,53,-9,leaves:4)
B(-8,45,1,Leaves:4)
B(2,36,1,leaves:4)
B(-8,44,1,Leaves:4)
B(8,50,4,Leaves:4)
B(2,39,1,leaves:4)
B(2,40,-2,LOG:14)
B(9,50,4,Leaves:4)
B(5,54,-8,leaves:4)
B(2,44,-9,leaves:4)
B(5,52,-8,Leaves:4)
B(5,51,-8,Leaves:4)
B(7,48,-4,leaves:4)
B(9,55,-2,leaves:4)
B(8,54,-7,leaves:4)
B(9,54,-2,leaves:4)
B(8,51,-7,LOG:14)
B(-4,54,-8,leaves:4)
B(7,47,-4,leaves:4)
B(2,52,3,Leaves:4)
B(-4,52,-8,leaves:4)
B(2,10,-2,LOG:14)
B(2,11,-2,LOG:14)
B(2,12,-2,LOG:14)
B(2,13,-2,LOG:14)
B(-1,39,-1,leaves:4)
B(2,19,-2,LOG:14)
B(2,18,-2,LOG:14)
B(10,47,0,leaves:4)
B(2,15,-2,LOG:14)
B(10,45,0,leaves:4)
B(2,14,-2,LOG:14)
B(2,17,-2,LOG:14)
B(2,16,-2,LOG:14)
B(2,50,3,Leaves:4)
B(7,43,-4,leaves:4)
B(9,50,-2,Leaves:4)
B(2,43,-1,LOG:14)
B(2,0,-3,LOG:14)
B(8,44,-7,leaves:4)
B(-2,52,2,Leaves:4)
B(2,41,3,leaves:4)
B(2,23,-2,LOG:14)
B(2,24,-2,LOG:14)
B(2,21,-2,LOG:14)
B(2,22,-2,LOG:14)
B(8,54,-9,leaves:4)
B(2,20,-2,LOG:14)
B(12,46,-6,leaves:4)
B(8,52,-9,Leaves:4)
B(3,42,-8,leaves:4)
B(3,53,-2,Leaves:4)
B(2,42,-11,leaves:4)
B(2,1,-1,LOG:14)
B(2,0,-1,LOG:14)
B(2,29,-2,LOG:14)
B(3,51,-2,Leaves:4)
B(2,3,-1,LOG:14)
B(2,28,-2,LOG:14)
B(-6,53,2,Leaves:4)
B(3,52,-2,Leaves:4)
B(2,2,-1,LOG:14)
B(2,27,-2,LOG:14)
B(2,5,-1,LOG:14)
B(2,26,-2,LOG:14)
B(3,50,-2,Leaves:4)
B(2,4,-1,LOG:14)
B(2,25,-2,LOG:14)
B(2,7,-1,LOG:14)
B(2,6,-1,LOG:14)
B(2,9,-1,LOG:14)
B(4,54,-3,Leaves:4)
B(2,8,-1,LOG:14)
B(2,51,-1,Leaves:4)
B(4,51,-3,Leaves:4)
B(8,47,-7,leaves:4)
B(2,52,-1,Leaves:4)
B(2,43,-11,leaves:4)
B(3,44,-8,leaves:4)
B(-4,51,3,Leaves:4)
B(2,50,-1,LOG:14)
B(4,50,-3,Leaves:4)
B(3,45,-8,leaves:4)
B(-6,52,-3,Leaves:4)
B(-6,53,-3,Leaves:4)
B(3,51,-10,Leaves:4)
B(-1,44,-4,leaves:4)
B(-2,46,-5,LOG:14)
B(3,52,-10,Leaves:4)
B(-1,45,-4,LOG:14)
B(3,53,-10,leaves:4)
B(0,40,5,leaves:4)
B(-2,44,-5,leaves:4)
B(-2,42,-5,leaves:4)
B(11,54,-8,leaves:4)
B(8,52,-6,LOG:14)
B(11,52,-8,leaves:4)
B(11,48,1,leaves:4)
B(0,51,1,Leaves:4)
B(11,42,1,leaves:4)
B(-2,39,-5,LOG:14)
B(-2,38,-5,leaves:4)
B(3,42,1,leaves:4)
B(-1,39,-4,leaves:4)
B(-2,37,-5,leaves:4)
B(-1,38,-4,leaves:4)
B(-2,36,-5,leaves:4)
B(0,51,5,Leaves:4)
B(-6,47,-3,Leaves:4)
B(-1,53,-4,Leaves:4)
B(-1,50,-4,Leaves:4)
B(-1,51,-4,LOG:14)
B(-6,46,-3,Leaves:4)
B(0,47,1,LOG:14)
B(3,38,1,leaves:4)
B(3,39,1,LOG:14)
B(0,40,1,leaves:4)
B(0,-1,-3,LOG:14)
B(3,36,1,leaves:4)
B(0,-2,-3,LOG:14)
B(0,41,1,leaves:4)
B(-1,49,-4,Leaves:4)
B(0,52,5,Leaves:4)
B(1,39,-3,LOG:14)
B(2,51,2,Leaves:4)
B(7,45,-7,leaves:4)
B(7,43,-7,leaves:4)
B(7,42,-7,leaves:4)
B(0,39,1,leaves:4)
B(8,52,5,leaves:4)
B(11,43,-6,leaves:4)
B(11,44,-6,leaves:4)
B(7,47,-7,leaves:4)
B(-4,50,0,Leaves:4)
B(11,47,-6,leaves:4)
B(8,50,5,Leaves:4)
B(11,45,-6,leaves:4)
B(-4,53,0,Leaves:4)
B(8,51,5,Leaves:4)
B(2,50,2,Leaves:4)
B(5,44,-10,leaves:4)
B(-4,39,0,leaves:4)
B(-2,53,-5,Leaves:4)
B(5,41,-8,leaves:4)
B(3,45,-10,leaves:4)
B(5,47,-8,leaves:4)
B(5,42,-8,leaves:4)
B(5,43,-8,leaves:4)
B(5,44,-8,LOG:14)
B(5,45,-8,leaves:4)
B(2,53,-2,Leaves:4)
B(8,47,5,leaves:4)
B(2,52,-2,Leaves:4)
B(-3,41,4,leaves:4)
B(0,39,5,leaves:4)
B(2,50,-2,LOG:14)
B(8,46,5,leaves:4)
B(10,53,-7,leaves:4)
B(-2,48,-5,leaves:4)
B(-2,47,-5,leaves:4)
B(1,52,2,Leaves:4)
B(1,53,2,Leaves:4)
B(1,50,2,LOG:14)
B(1,51,2,Leaves:4)
B(8,44,2,leaves:4)
B(-4,44,-4,leaves:4)
B(8,43,2,leaves:4)
B(-4,46,-4,leaves:4)
B(8,52,-8,Leaves:4)
B(5,37,3,leaves:4)
B(4,53,-7,leaves:4)
B(4,52,-10,Leaves:4)
B(4,51,-10,Leaves:4)
B(13,44,1,leaves:4)
B(-4,50,-4,Leaves:4)
B(-4,52,-4,Leaves:4)
B(8,48,2,leaves:4)
B(-4,53,-4,Leaves:4)
B(4,51,-1,Leaves:4)
B(4,49,-4,LOG:14)
B(4,48,-4,LOG:14)
B(4,52,-7,Leaves:4)
B(5,44,3,leaves:4)
B(2,40,2,leaves:4)
B(-4,39,-4,leaves:4)
B(5,48,3,leaves:4)
B(-4,38,-4,leaves:4)
B(1,49,2,LOG:14)
B(2,39,4,leaves:4)
B(5,52,-10,Leaves:4)
B(4,43,-7,LOG:14)
B(5,40,3,leaves:4)
B(4,49,-7,LOG:14)
B(-4,40,-4,leaves:4)
B(7,44,1,leaves:4)
B(7,45,1,LOG:14)
B(4,41,-7,leaves:4)
B(7,49,1,leaves:4)
B(7,53,1,leaves:4)
B(9,51,-1,Leaves:4)
B(9,50,-1,Leaves:4)
B(9,56,-1,leaves:4)
B(9,55,-1,leaves:4)
B(9,54,-1,leaves:4)
B(1,39,2,LOG:14)
B(-1,39,-2,leaves:4)
B(4,47,3,leaves:4)
B(11,46,-1,leaves:4)
B(4,46,3,leaves:4)
B(11,43,-1,leaves:4)
B(-5,37,-2,leaves:4)
B(9,44,-3,LOG:14)
B(-4,53,-1,Leaves:4)
B(2,51,-5,Leaves:4)
B(-5,39,-2,leaves:4)
B(-4,52,-1,Leaves:4)
B(9,42,-3,leaves:4)
B(9,52,-9,Leaves:4)
B(4,50,-4,Leaves:4)
B(9,53,-9,LOG:14)
B(-1,41,-5,leaves:4)
B(4,54,-4,Leaves:4)
B(9,43,-1,leaves:4)
B(-1,47,-5,LOG:14)
B(9,54,-9,leaves:4)
B(9,46,-1,leaves:4)
B(-4,51,-1,Leaves:4)
B(9,45,-1,leaves:4)
B(-1,46,-2,leaves:4)
B(-5,50,-2,Leaves:4)
B(-1,52,-2,Leaves:4)
B(-1,39,-8,leaves:4)
B(5,49,5,Leaves:4)
B(-5,46,-2,Leaves:4)
B(-1,50,-2,Leaves:4)
B(2,42,-5,leaves:4)
B(-6,44,1,Leaves:4)
B(-1,51,-2,Leaves:4)
B(-5,47,-2,Leaves:4)
B(9,53,-3,leaves:4)
B(-1,39,-5,leaves:4)
B(-5,49,-2,Leaves:4)
B(9,54,-3,leaves:4)
B(9,55,-3,LOG:14)
B(3,-1,-1,LOG:14)
B(9,56,-3,leaves:4)
B(3,-2,-1,LOG:14)
B(-4,46,-1,Leaves:4)
B(-4,45,-1,LOG:14)
B(-4,48,-1,Leaves:4)
B(2,50,4,Leaves:4)
B(-4,47,-1,Leaves:4)
B(-6,51,-6,leaves:4)
B(-6,52,-6,leaves:4)
B(-6,53,-6,leaves:4)
B(0,40,-3,leaves:4)
B(7,43,3,leaves:4)
B(-1,49,-5,Leaves:4)
B(-1,40,0,leaves:4)
B(0,49,-3,Leaves:4)
B(1,50,4,Leaves:4)
B(-5,53,-2,Leaves:4)
B(1,51,4,Leaves:4)
B(0,43,-3,LOG:14)
B(-5,54,-2,leaves:4)
B(0,44,-3,leaves:4)
B(10,55,-10,leaves:4)
B(1,53,4,Leaves:4)
B(10,54,-10,leaves:4)
B(1,52,4,Leaves:4)
B(-1,53,2,Leaves:4)
B(10,53,-10,leaves:4)
B(7,48,3,Leaves:4)
B(7,49,3,leaves:4)
B(-1,53,-5,Leaves:4)
B(-1,52,-5,Leaves:4)
B(-1,51,-5,Leaves:4)
B(0,51,-3,Leaves:4)
B(10,45,2,leaves:4)
B(0,52,-3,Leaves:4)
B(10,47,2,leaves:4)
B(-1,51,2,Leaves:4)
B(10,42,2,leaves:4)
B(10,44,2,leaves:4)
B(-1,41,6,leaves:4)
B(1,41,4,leaves:4)
B(2,41,-6,leaves:4)
B(4,39,3,leaves:4)
B(-1,42,2,leaves:4)
B(6,51,6,leaves:4)
B(-5,38,-3,leaves:4)
B(2,43,-6,leaves:4)
B(2,44,-6,leaves:4)
B(-5,50,-3,Leaves:4)
B(-2,52,1,Leaves:4)
B(-5,52,-3,LOG:14)
B(-1,53,6,Leaves:4)
B(-2,42,4,leaves:4)
B(-2,41,4,leaves:4)
B(-1,52,6,Leaves:4)
B(-1,51,6,Leaves:4)
B(6,51,-1,Leaves:4)
B(6,52,-1,Leaves:4)
B(6,45,-1,leaves:4)
B(6,43,-1,LOG:14)
B(-4,50,-7,LOG:14)
B(3,40,2,leaves:4)
B(6,49,-6,LOG:14)
B(-3,51,-1,Leaves:4)
B(0,36,-3,LOG:14)
B(5,40,-1,leaves:4)
B(6,42,-6,leaves:4)
B(-3,45,-1,LOG:14)
B(5,42,-1,LOG:14)
B(3,41,2,leaves:4)
B(-5,53,-3,Leaves:4)
B(-5,54,-3,leaves:4)
B(-3,54,1,Leaves:4)
B(-5,53,-8,leaves:4)
B(-5,52,-8,LOG:14)
B(3,39,-9,leaves:4)
B(0,51,2,Leaves:4)
B(8,53,-4,leaves:4)
B(-6,54,-8,leaves:4)
B(-6,52,-8,leaves:4)
B(-2,41,1,leaves:4)
B(9,43,2,leaves:4)
B(7,46,5,leaves:4)
B(3,51,-5,Leaves:4)
B(-4,51,2,Leaves:4)
B(-4,39,-3,leaves:4)
B(-4,53,2,Leaves:4)
B(7,51,-3,Leaves:4)
B(3,53,-5,Leaves:4)
B(7,53,-3,leaves:4)
B(7,52,-3,Leaves:4)
B(7,55,-3,leaves:4)
B(7,52,5,leaves:4)
B(9,56,-5,leaves:4)
B(2,54,-6,Leaves:4)
B(0,39,2,leaves:4)
B(6,39,2,leaves:4)
B(13,44,-4,leaves:4)
B(2,53,-6,Leaves:4)
B(2,52,-6,Leaves:4)
B(3,51,-9,Leaves:4)
B(3,52,-9,Leaves:4)
B(3,53,-9,leaves:4)
B(13,45,-4,leaves:4)
B(8,47,-4,leaves:4)
B(8,44,-4,leaves:4)
B(8,45,-4,leaves:4)
B(-2,47,-8,leaves:4)
B(8,45,-6,leaves:4)
B(3,46,-5,LOG:14)
B(-1,39,0,leaves:4)
B(3,42,-5,LOG:14)
B(7,45,-3,leaves:4)
B(9,48,-5,leaves:4)
B(7,43,-3,leaves:4)
B(3,45,-9,leaves:4)
B(7,44,-3,leaves:4)
B(3,46,-9,leaves:4)
B(-2,39,-8,leaves:4)
B(8,43,-6,leaves:4)
B(0,41,2,leaves:4)
B(9,43,-5,leaves:4)
B(8,44,-6,leaves:4)
B(1,51,-3,Leaves:4)
B(9,45,-5,leaves:4)
B(-3,53,1,Leaves:4)
B(1,52,-3,Leaves:4)
B(6,49,2,Leaves:4)
B(1,53,-3,Leaves:4)
B(-3,52,1,Leaves:4)
B(6,48,2,leaves:4)
B(-3,51,1,LOG:14)
B(-3,50,1,Leaves:4)
B(8,42,-4,leaves:4)
B(3,44,-9,leaves:4)
B(6,44,2,leaves:4)
B(-1,39,4,leaves:4)
B(6,46,2,leaves:4)
B(6,50,4,Leaves:4)
B(-6,38,-2,leaves:4)
B(6,51,4,Leaves:4)
B(3,45,-4,LOG:14)
B(11,43,-3,leaves:4)
B(11,45,-3,leaves:4)
B(-2,38,3,leaves:4)
B(0,41,0,leaves:4)
B(-3,40,0,leaves:4)
B(-6,50,-4,Leaves:4)
B(0,45,0,LOG:14)
B(-6,52,-4,Leaves:4)
B(-6,51,-4,Leaves:4)
B(0,46,0,LOG:14)
B(-4,40,-5,leaves:4)
B(-3,39,0,leaves:4)
B(-4,38,-5,leaves:4)
B(0,51,-6,Leaves:4)
B(-4,39,-5,leaves:4)
B(-6,48,-2,Leaves:4)
B(-6,49,-2,Leaves:4)
B(4,-2,0,LOG:14)
B(10,45,4,leaves:4)
B(4,-3,0,LOG:14)
B(-1,54,5,leaves:4)
B(-1,52,5,Leaves:4)
B(-1,51,5,Leaves:4)
B(-6,46,-2,Leaves:4)
B(-1,50,5,Leaves:4)
B(-6,47,-2,LOG:14)
B(1,38,-6,leaves:4)
B(-6,45,-2,Leaves:4)
B(-4,51,-3,LOG:14)
B(-4,50,-3,LOG:14)
B(-4,53,-3,Leaves:4)
B(-3,50,0,LOG:14)
B(-4,52,-3,Leaves:4)
B(-2,45,-6,leaves:4)
B(-2,43,-6,leaves:4)
B(-4,45,-5,leaves:4)
B(8,46,3,leaves:4)
B(8,45,3,leaves:4)
B(-4,46,-5,leaves:4)
B(-2,37,-6,leaves:4)
B(-2,39,-6,leaves:4)
B(6,45,1,leaves:4)
B(-4,47,-3,Leaves:4)
B(5,52,-4,Leaves:4)
B(6,43,1,leaves:4)
B(-6,52,-2,Leaves:4)
B(-5,54,1,leaves:4)
B(6,49,4,Leaves:4)
B(6,46,4,leaves:4)
B(9,54,-4,LOG:14)
B(3,39,2,leaves:4)
B(9,56,-4,leaves:4)
B(-4,51,-9,Leaves:4)
B(-2,49,-6,leaves:4)
B(11,56,-3,leaves:4)
B(11,55,-3,leaves:4)
B(-3,54,0,Leaves:4)
B(-4,54,-3,leaves:4)
B(-4,53,1,Leaves:4)
B(1,0,-1,LOG:14)
B(12,47,3,leaves:4)
B(-4,52,1,LOG:14)
B(-4,51,1,Leaves:4)
B(-3,37,-3,leaves:4)
B(1,3,-1,LOG:14)
B(1,4,-1,LOG:14)
B(1,1,-1,LOG:14)
B(1,2,-1,LOG:14)
B(1,7,-1,LOG:14)
B(1,8,-1,LOG:14)
B(1,5,-1,LOG:14)
B(1,6,-1,LOG:14)
B(1,9,-1,LOG:14)
B(-3,53,2,Leaves:4)
B(4,50,-9,Leaves:4)
B(4,51,-9,Leaves:4)
B(4,54,-9,leaves:4)
B(-3,40,-3,leaves:4)
B(9,46,-4,leaves:4)
B(1,51,-4,Leaves:4)
B(9,45,-4,leaves:4)
B(1,52,-4,Leaves:4)
B(9,44,-4,leaves:4)
B(9,43,-4,leaves:4)
B(1,50,-4,Leaves:4)
B(9,42,-4,leaves:4)
B(0,50,4,Leaves:4)
B(5,45,-4,leaves:4)
B(6,39,1,leaves:4)
B(5,43,-4,leaves:4)
B(4,42,-9,leaves:4)
B(13,45,-3,leaves:4)
B(13,46,-3,leaves:4)
B(0,52,4,Leaves:4)
B(4,46,-9,leaves:4)
B(0,54,4,leaves:4)
B(4,44,-9,leaves:4)
B(4,41,0,leaves:4)
B(-3,45,-3,leaves:4)
B(-2,39,-3,leaves:4)
B(-2,40,-3,leaves:4)
B(4,39,0,leaves:4)
B(-3,52,-3,Leaves:4)
B(-4,38,1,leaves:4)
B(-3,53,-3,Leaves:4)
B(2,55,-7,leaves:4)
B(5,54,-9,leaves:4)
B(7,49,0,LOG:14)
B(8,47,-1,leaves:4)
B(1,-2,0,LOG:14)
B(5,53,-9,leaves:4)
B(2,51,-7,Leaves:4)
B(5,52,-9,LOG:14)
B(2,53,-7,leaves:4)
B(5,51,-9,Leaves:4)
B(5,50,-9,Leaves:4)
B(-3,53,-4,Leaves:4)
B(11,42,2,leaves:4)
B(-3,52,-4,Leaves:4)
B(-7,51,-4,leaves:4)
B(2,52,-8,Leaves:4)
B(2,53,-8,LOG:14)
B(2,54,-8,leaves:4)
B(6,52,-8,Leaves:4)
B(2,51,-8,Leaves:4)
B(8,53,-1,leaves:4)
B(1,18,-1,LOG:14)
B(8,54,-1,leaves:4)
B(1,19,-1,LOG:14)
B(8,51,-1,Leaves:4)
B(2,44,-7,leaves:4)
B(8,52,-1,LOG:14)
B(2,45,-7,leaves:4)
B(1,14,-1,LOG:14)
B(6,44,-4,LOG:14)
B(1,15,-1,LOG:14)
B(8,55,-1,leaves:4)
B(1,16,-1,LOG:14)
B(8,56,-1,leaves:4)
B(6,53,-2,Leaves:4)
B(1,17,-1,LOG:14)
B(-3,53,-8,leaves:4)
B(-3,39,-4,leaves:4)
B(2,42,-7,LOG:14)
B(-7,47,-1,Leaves:4)
B(7,53,-10,leaves:4)
B(-7,49,-1,Leaves:4)
B(-3,40,-4,leaves:4)
B(1,11,-1,LOG:14)
B(10,55,-9,leaves:4)
B(1,10,-1,LOG:14)
B(10,52,-9,leaves:4)
B(1,13,-1,LOG:14)
B(6,45,-4,leaves:4)
B(10,53,-9,leaves:4)
B(7,52,-8,Leaves:4)
B(1,12,-1,LOG:14)
B(-7,44,-1,Leaves:4)
B(-7,45,-1,LOG:14)
B(9,55,-8,leaves:4)
B(0,40,4,leaves:4)
B(10,43,-4,leaves:4)
B(10,42,-4,leaves:4)
B(3,39,3,leaves:4)
B(9,52,-8,LOG:14)
B(0,42,4,leaves:4)
B(-7,53,-8,leaves:4)
B(-7,52,-8,leaves:4)
B(1,-3,-2,LOG:14)
B(10,46,-4,leaves:4)
B(3,38,3,leaves:4)
B(1,-2,-2,LOG:14)
B(10,45,-4,LOG:14)
B(1,-1,-2,LOG:14)
B(10,44,-4,leaves:4)
B(-7,51,-8,leaves:4)
B(2,42,-10,leaves:4)
B(7,43,-10,leaves:4)
B(7,42,-10,leaves:4)
B(2,39,-8,leaves:4)
B(10,54,-3,leaves:4)
B(-1,39,1,leaves:4)
B(10,53,-4,leaves:4)
B(0,38,4,leaves:4)
B(3,40,3,leaves:4)
B(3,41,3,leaves:4)
B(-1,40,1,leaves:4)
B(2,45,-8,leaves:4)
B(3,0,-1,LOG:14)
B(2,43,-8,leaves:4)
B(5,39,0,leaves:4)
B(2,44,-8,leaves:4)
B(2,41,-8,leaves:4)
B(6,45,-8,leaves:4)
B(2,42,-8,LOG:14)
B(3,53,3,Leaves:4)
B(5,53,-2,Leaves:4)
B(-5,53,-6,leaves:4)
B(-5,46,-6,leaves:4)
B(12,47,1,leaves:4)
B(-6,39,-1,leaves:4)
B(3,52,-1,Leaves:4)
B(3,51,-1,Leaves:4)
B(5,48,0,LOG:14)
B(3,50,-1,Leaves:4)
B(5,46,0,leaves:4)
B(12,43,1,leaves:4)
B(1,-1,-1,LOG:14)
B(1,-3,-1,LOG:14)
B(1,-2,-1,LOG:14)
B(10,47,-3,leaves:4)
B(10,42,1,leaves:4)
B(10,44,-3,leaves:4)
B(10,45,-3,leaves:4)
B(1,-3,1,LOG:14)
B(10,48,1,leaves:4)
B(10,47,1,leaves:4)
B(3,40,-1,leaves:4)
B(10,45,1,LOG:14)
B(10,44,1,leaves:4)
B(1,37,0,leaves:4)
B(0,49,-6,LOG:14)
B(3,38,-1,leaves:4)
B(0,46,-6,leaves:4)
B(0,44,-6,leaves:4)
B(-6,53,-4,Leaves:4)
B(2,-3,-3,LOG:14)
B(2,-2,-3,LOG:14)
B(2,-1,-3,LOG:14)
B(8,53,-3,leaves:4)
B(8,52,-3,Leaves:4)
B(0,41,-9,leaves:4)
B(7,45,-8,leaves:4)
B(7,44,-8,leaves:4)
B(0,42,-9,leaves:4)
B(-6,52,-1,Leaves:4)
B(-6,51,-1,Leaves:4)
B(7,43,-8,leaves:4)
B(0,38,-6,leaves:4)
B(9,53,-11,leaves:4)
B(-6,46,1,Leaves:4)
B(8,44,-3,leaves:4)
B(2,9,-2,LOG:14)
B(-6,46,-1,LOG:14)
B(-6,45,-1,Leaves:4)
B(2,6,-2,LOG:14)
B(-2,51,6,Leaves:4)
B(2,5,-2,LOG:14)
B(2,8,-2,LOG:14)
B(2,7,-2,LOG:14)
B(-1,41,-8,leaves:4)
B(2,2,-2,LOG:14)
B(-1,42,-8,leaves:4)
B(2,1,-2,LOG:14)
B(9,52,-11,leaves:4)
B(2,4,-2,LOG:14)
B(2,3,-2,LOG:14)
B(-6,47,-1,Leaves:4)
B(2,0,-2,LOG:14)
B(1,42,-2,LOG:14)
B(8,45,0,leaves:4)
B(-5,54,-4,leaves:4)
B(10,45,3,leaves:4)
B(1,40,-2,LOG:14)
B(1,41,-2,LOG:14)
B(-5,52,-7,leaves:4)
B(0,37,-7,leaves:4)
B(-5,51,-7,LOG:14)
B(10,46,3,leaves:4)
B(-5,50,-7,Leaves:4)
B(-4,54,-2,leaves:4)
B(1,41,0,leaves:4)
B(1,49,-2,Leaves:4)
B(6,52,-9,Leaves:4)
B(8,43,0,LOG:14)
B(2,52,5,Leaves:4)
B(1,30,-2,LOG:14)
B(0,52,-1,Leaves:4)
B(1,31,-2,LOG:14)
B(0,51,-1,Leaves:4)
B(1,32,-2,LOG:14)
B(1,33,-2,LOG:14)
B(1,34,-2,LOG:14)
B(1,35,-2,LOG:14)
B(1,36,-2,LOG:14)
B(-9,45,-1,leaves:4)
B(0,50,-1,Leaves:4)
B(6,44,-9,leaves:4)
B(4,41,-8,leaves:4)
B(6,47,-9,leaves:4)
B(1,38,-2,LOG:14)
B(1,37,-2,LOG:14)
B(8,53,-10,leaves:4)
B(1,39,-2,LOG:14)
B(1,39,1,LOG:14)
B(1,43,-9,leaves:4)
B(6,47,3,leaves:4)
B(6,45,3,leaves:4)
B(0,50,-7,LOG:14)
B(1,42,-11,leaves:4)
B(1,43,-11,leaves:4)
B(6,49,3,LOG:14)
B(5,44,-5,leaves:4)
B(-4,36,-2,leaves:4)
B(-4,38,-2,leaves:4)
B(4,52,-8,Leaves:4)
B(4,53,-8,leaves:4)
B(4,50,-8,LOG:14)
B(4,51,-8,LOG:14)
B(-5,40,-4,leaves:4)
B(4,54,-8,leaves:4)
B(-3,46,-6,leaves:4)
B(4,54,-2,Leaves:4)
B(-5,46,-1,LOG:14)
B(-3,48,-6,LOG:14)
B(1,55,-9,leaves:4)
B(0,41,-7,leaves:4)
B(-5,47,-4,Leaves:4)
B(1,51,-2,LOG:14)
B(1,48,1,LOG:14)
B(1,52,-2,Leaves:4)
B(1,53,-2,Leaves:4)
B(1,51,-9,Leaves:4)
B(6,46,5,leaves:4)
B(6,45,5,leaves:4)
B(0,38,3,leaves:4)
B(0,39,3,leaves:4)
B(0,37,3,leaves:4)
B(1,40,1,leaves:4)
B(-5,49,-1,Leaves:4)
B(6,48,5,Leaves:4)
B(6,50,3,Leaves:4)
B(-5,51,-4,Leaves:4)
B(1,52,-1,Leaves:4)
B(11,46,0,leaves:4)
B(1,53,-1,Leaves:4)
B(1,52,1,Leaves:4)
B(-6,52,0,Leaves:4)
B(1,50,-1,Leaves:4)
B(11,44,0,leaves:4)
B(1,51,-1,Leaves:4)
B(-5,39,-1,leaves:4)
B(1,53,1,Leaves:4)
B(6,51,-11,leaves:4)
B(0,43,3,leaves:4)
B(0,40,3,LOG:14)
B(11,42,0,leaves:4)
B(11,43,0,leaves:4)
B(7,46,-2,leaves:4)
B(0,41,3,leaves:4)
B(2,40,-4,LOG:14)
B(2,44,-4,LOG:14)
B(-6,48,0,Leaves:4)
B(-6,47,0,Leaves:4)
B(2,41,-4,LOG:14)
B(-6,45,0,Leaves:4)
B(11,45,-2,leaves:4)
B(11,46,-2,leaves:4)
B(1,41,-1,leaves:4)
B(-6,44,0,Leaves:4)
B(8,43,1,leaves:4)
B(1,44,-1,LOG:14)
B(1,45,-1,LOG:14)
B(-1,51,-3,Leaves:4)
B(0,52,3,Leaves:4)
B(0,51,3,LOG:14)
B(0,50,3,Leaves:4)
B(4,42,-2,LOG:14)
B(-7,48,-2,Leaves:4)
B(-7,47,-2,Leaves:4)
B(8,47,1,leaves:4)
B(8,45,1,leaves:4)
B(-7,46,-2,Leaves:4)
B(-7,45,-2,Leaves:4)
B(8,46,1,leaves:4)
B(1,49,-1,Leaves:4)
B(7,50,-1,LOG:14)
B(7,51,-1,LOG:14)
B(2,43,-3,LOG:14)
B(1,25,-2,LOG:14)
B(-1,44,-3,LOG:14)
B(1,24,-2,LOG:14)
B(1,23,-2,LOG:14)
B(1,22,-2,LOG:14)
B(-1,40,-3,leaves:4)
B(1,21,-2,LOG:14)
B(7,45,-5,LOG:14)
B(5,51,4,Leaves:4)
B(-1,41,-3,leaves:4)
B(1,20,-2,LOG:14)
B(7,46,-5,leaves:4)
B(7,47,-5,leaves:4)
B(7,48,-5,leaves:4)
B(-1,39,-3,leaves:4)
B(1,28,-2,LOG:14)
B(1,29,-2,LOG:14)
B(-1,37,-3,LOG:14)
B(1,26,-2,LOG:14)
B(1,27,-2,LOG:14)
B(12,44,-4,leaves:4)
B(7,53,-1,leaves:4)
B(7,52,-1,Leaves:4)
B(7,54,-1,leaves:4)
B(12,47,-4,leaves:4)
B(1,21,-1,LOG:14)
B(1,22,-1,LOG:14)
B(2,52,-3,Leaves:4)
B(1,20,-1,LOG:14)
B(1,12,-2,LOG:14)
B(1,11,-2,LOG:14)
B(1,14,-2,LOG:14)
B(2,50,-3,Leaves:4)
B(1,13,-2,LOG:14)
B(5,44,4,leaves:4)
B(4,41,-6,leaves:4)
B(1,10,-2,LOG:14)
B(7,53,-2,leaves:4)
B(8,54,0,leaves:4)
B(1,19,-2,LOG:14)
B(8,53,0,leaves:4)
B(8,52,0,Leaves:4)
B(8,50,0,Leaves:4)
B(1,15,-2,LOG:14)
B(1,16,-2,LOG:14)
B(1,17,-2,LOG:14)
B(5,48,4,leaves:4)
B(1,18,-2,LOG:14)
B(5,47,4,leaves:4)
B(2,52,-4,Leaves:4)
B(7,47,-1,leaves:4)
B(7,46,-1,leaves:4)
B(7,45,-1,leaves:4)
B(7,43,-1,LOG:14)
B(9,52,1,Leaves:4)
B(4,44,-11,leaves:4)
B(6,53,-7,leaves:4)
B(6,52,-7,Leaves:4)
B(9,46,3,leaves:4)
B(9,47,3,leaves:4)
B(-5,51,-10,leaves:4)
B(-5,52,-10,leaves:4)
B(9,45,3,leaves:4)
B(-7,46,0,Leaves:4)
B(-7,47,0,Leaves:4)
B(4,46,2,leaves:4)
B(-7,48,0,Leaves:4)
B(4,47,2,leaves:4)
B(9,48,3,leaves:4)
B(-1,51,-6,Leaves:4)
B(2,38,0,LOG:14)
B(2,37,0,leaves:4)
B(6,44,-5,leaves:4)
B(-1,39,-6,leaves:4)
B(-1,38,-6,leaves:4)
B(6,43,-5,leaves:4)
B(1,53,5,Leaves:4)
B(9,46,0,leaves:4)
B(0,-2,-1,LOG:14)
B(11,43,-5,leaves:4)
B(6,46,-7,leaves:4)
B(9,44,0,LOG:14)
B(-1,41,-6,leaves:4)
B(1,52,5,Leaves:4)
B(-1,48,-6,LOG:14)
B(2,49,0,LOG:14)
B(8,54,-5,leaves:4)
B(8,53,-5,LOG:14)
B(7,52,4,Leaves:4)
B(-7,51,-9,leaves:4)
B(7,50,4,LOG:14)
B(-2,38,5,leaves:4)
B(-7,52,-9,leaves:4)
B(-5,53,-5,leaves:4)
B(-5,52,-5,Leaves:4)
B(-5,51,-5,Leaves:4)
B(2,52,0,Leaves:4)
B(-2,41,5,leaves:4)
B(8,43,-2,LOG:14)
B(3,52,-7,Leaves:4)
B(-2,42,5,leaves:4)
B(3,53,-7,leaves:4)
B(8,45,-2,leaves:4)
B(3,51,-7,Leaves:4)
B(1,50,-5,Leaves:4)
B(-3,52,3,Leaves:4)
B(3,54,-7,leaves:4)
B(1,42,-7,leaves:4)
B(8,55,-5,leaves:4)
B(-3,51,3,Leaves:4)
B(-8,44,-3,Leaves:4)
B(3,51,-3,LOG:14)
B(-7,44,0,Leaves:4)
B(3,53,-3,Leaves:4)
B(-7,43,0,Leaves:4)
B(3,52,-3,LOG:14)
B(3,54,-3,Leaves:4)
B(7,45,4,leaves:4)
B(7,49,4,Leaves:4)
B(3,42,-7,leaves:4)
B(1,51,-7,LOG:14)
B(8,48,-5,leaves:4)
B(1,45,-5,leaves:4)
B(8,45,-5,leaves:4)
B(1,47,-5,leaves:4)
B(-2,46,-7,leaves:4)
B(1,50,3,Leaves:4)
B(-2,48,-7,leaves:4)
B(-1,40,3,leaves:4)
B(11,54,-10,leaves:4)
B(10,52,-11,leaves:4)
B(-5,51,-9,Leaves:4)
B(1,52,3,LOG:14)
B(-2,38,-7,leaves:4)
B(1,53,3,Leaves:4)
B(8,50,-2,Leaves:4)
B(-1,51,3,Leaves:4)
B(-1,50,3,Leaves:4)
B(-1,53,3,Leaves:4)
B(-3,39,-7,leaves:4)
B(-3,45,-7,leaves:4)
B(-1,43,3,leaves:4)
B(8,56,-2,leaves:4)
B(10,47,-6,leaves:4)
B(8,55,-2,leaves:4)
B(8,53,-2,leaves:4)
B(-2,49,-4,Leaves:4)
B(-2,48,-4,leaves:4)
B(-2,47,-4,leaves:4)
B(3,54,-4,Leaves:4)
B(3,51,-4,Leaves:4)
B(-3,53,-7,leaves:4)
B(1,38,3,leaves:4)
B(1,37,3,leaves:4)
B(-3,51,-7,Leaves:4)
B(-3,52,-7,leaves:4)
B(1,39,3,leaves:4)
B(-8,43,-1,Leaves:4)
B(-8,47,-1,Leaves:4)
B(5,44,-7,leaves:4)
B(-2,53,-4,Leaves:4)
B(6,44,-3,leaves:4)
B(-8,46,-1,Leaves:4)
B(-2,51,-4,Leaves:4)
B(-2,52,-4,Leaves:4)
B(5,45,-7,leaves:4)
B(13,45,-5,leaves:4)
B(-2,50,-4,Leaves:4)
B(-2,39,-4,leaves:4)
B(-2,36,-4,leaves:4)
B(-2,38,-4,LOG:14)
B(9,42,1,leaves:4)
B(9,46,1,leaves:4)
B(5,52,-7,Leaves:4)
B(5,53,-7,leaves:4)
B(1,41,3,leaves:4)
B(1,40,3,leaves:4)
B(-2,41,-4,leaves:4)

#
# +-----------------------------------------------------------------+ #
# |                            BO3 checks                           | #
# +-----------------------------------------------------------------+ #
#

BlockCheck(0,-1,0,grass,dirt)

#
# +-----------------------------------------------------------------+ #
# |                             Branches                            | #
# +-----------------------------------------------------------------+ #
#

