
#
# +-----------------------------------------------------------------+ #
# |                            BO3 object                           | #
# +-----------------------------------------------------------------+ #
#

Author: NLBlackEagle

Description: Converted version of the BO2 SA20S

Version: 3

SettingsMode: WriteDisable


#
# +-----------------------------------------------------------------+ #
# |                          Main settings                          | #
# +-----------------------------------------------------------------+ #
#

Tree: true

Frequency: 1

Rarity: 100.0

RotateRandomly: true

SpawnHeight: highestSolidBlock

SpawnHeightOffset: 0

SpawnHeightVariance: 0


# Height Limits for the BO3. #


MinHeight: 0

MaxHeight: 199


# Extrusion settings #


ExtrudeMode: None

ExtrudeThroughBlocks: air

MaxBranchDepth: 10

ExcludedBiomes: 


#
# +-----------------------------------------------------------------+ #
# |                      Source block settings                      | #
# +-----------------------------------------------------------------+ #
#

SourceBlocks: AIR,GRASS,DIRT,SAND

MaxPercentageOutsideSourceBlock: 0

OutsideSourceBlock: placeAnyway


#
# +-----------------------------------------------------------------+ #
# |                              Blocks                             | #
# +-----------------------------------------------------------------+ #
#

B(1,13,1,Leaves:4)
B(1,14,1,Leaves:4)
B(0,-3,1,LOG:15)
B(1,15,2,Leaves:4)
B(1,-2,0,LOG:15)
B(1,-1,0,LOG:15)
B(3,14,-1,Leaves:4)
B(3,13,-1,Leaves:4)
B(-1,-2,-1,LOG:15)
B(1,15,-4,Leaves:4)
B(0,14,-2,Leaves:4)
B(0,-1,-1,LOG:15)
B(3,-2,0,LOG:15)
B(0,-2,-1,LOG:15)
B(-1,15,-3,Leaves:4)
B(-1,15,1,Leaves:4)
B(-2,12,-2,Leaves:4)
B(1,11,-1,LOG:13)
B(1,10,-1,log:3)
B(1,13,-1,Leaves:4)
B(1,12,-1,LOG:13)
B(1,-1,-2,LOG:15)
B(0,14,0,Leaves:4)
B(0,0,-1,LOG:1)
B(1,14,-3,Leaves:4)
B(1,13,-3,Leaves:4)
B(3,10,-2,LOG:1)
B(3,11,-2,Leaves:4)
B(4,12,-3,Leaves:4)
B(2,12,-1,Leaves:4)
B(2,11,-1,Leaves:4)
B(2,10,-1,Leaves:4)
B(1,0,-1,LOG:15)
B(1,3,-1,LOG:15)
B(1,4,-1,LOG:15)
B(1,1,-1,LOG:15)
B(1,12,0,Leaves:4)
B(1,2,-1,LOG:15)
B(1,7,-1,log:3)
B(1,10,0,LOG:1)
B(1,8,-1,log:3)
B(1,11,0,Leaves:4)
B(1,0,-2,LOG:1)
B(1,5,-1,LOG:15)
B(1,6,-1,log:3)
B(-1,14,-1,Leaves:4)
B(-1,13,-1,Leaves:4)
B(1,9,-1,log:3)
B(-1,11,-1,Leaves:4)
B(1,0,0,LOG:1)
B(1,-3,-4,LOG:15)
B(0,-2,-2,LOG:15)
B(-1,-2,-3,LOG:15)
B(1,-1,-1,LOG:15)
B(-2,15,-1,Leaves:4)
B(0,10,-1,LOG:1)
B(0,11,-1,Leaves:4)
B(0,12,-1,Leaves:4)
B(0,-1,-2,LOG:15)
B(2,13,0,Leaves:4)
B(2,14,0,Leaves:4)
B(2,14,-2,Leaves:4)
B(2,10,0,Leaves:4)
B(-3,12,-2,Leaves:4)
B(0,0,-2,LOG:15)
B(1,12,-2,Leaves:4)
B(1,11,-2,Leaves:4)
B(4,15,-1,Leaves:4)
B(1,10,-2,LOG:1)
B(1,9,0,LOG:1)
B(2,1,-1,LOG:1)
B(2,0,-1,LOG:15)
B(1,-2,-3,LOG:15)
B(3,11,1,Leaves:4)
B(2,-2,-1,LOG:15)
B(2,-1,-1,LOG:15)
B(3,15,-3,Leaves:4)
B(3,15,1,Leaves:4)
B(2,9,-1,LOG:1)
B(4,11,2,Leaves:4)

#
# +-----------------------------------------------------------------+ #
# |                            BO3 checks                           | #
# +-----------------------------------------------------------------+ #
#

BlockCheck(0,-1,0,grass,dirt)

#
# +-----------------------------------------------------------------+ #
# |                             Branches                            | #
# +-----------------------------------------------------------------+ #
#

