
#
# +-----------------------------------------------------------------+ #
# |                            BO3 object                           | #
# +-----------------------------------------------------------------+ #
#

Author: NLBlackEagle

Description: Converted version of the BO2 SA21L

Version: 3

SettingsMode: WriteDisable


#
# +-----------------------------------------------------------------+ #
# |                          Main settings                          | #
# +-----------------------------------------------------------------+ #
#

Tree: true

Frequency: 1

Rarity: 100.0

RotateRandomly: true

SpawnHeight: highestSolidBlock

SpawnHeightOffset: 0

SpawnHeightVariance: 0


# Height Limits for the BO3. #


MinHeight: 0

MaxHeight: 199


# Extrusion settings #


ExtrudeMode: None

ExtrudeThroughBlocks: air

MaxBranchDepth: 10

ExcludedBiomes: 


#
# +-----------------------------------------------------------------+ #
# |                      Source block settings                      | #
# +-----------------------------------------------------------------+ #
#

SourceBlocks: AIR,GRASS,DIRT,SAND

MaxPercentageOutsideSourceBlock: 0

OutsideSourceBlock: placeAnyway


#
# +-----------------------------------------------------------------+ #
# |                              Blocks                             | #
# +-----------------------------------------------------------------+ #
#

B(-1,7,3,Leaves:4)
B(-1,6,2,Leaves:4)
B(2,4,3,Leaves:4)
B(0,2,0,cocoa:10)
B(2,5,2,Leaves:4)
B(0,3,0,Leaves:4)
B(0,6,0,Leaves:4)
B(-1,3,1,cocoa:10)
B(3,3,3,Leaves:4)
B(-1,5,4,Leaves:4)
B(0,4,0,Leaves:4)
B(0,5,0,Leaves:4)
B(1,8,2,Leaves:4)
B(0,5,-3,LOG:15)
B(0,4,-3,LOG:15)
B(3,5,-3,Leaves:4)
B(3,6,-3,Leaves:4)
B(1,2,1,cocoa:10)
B(-3,5,-1,Leaves:4)
B(0,6,-3,Leaves:4)
B(3,3,-3,Leaves:4)
B(1,6,3,Leaves:4)
B(-3,4,-3,Leaves:4)
B(0,5,2,Leaves:4)
B(0,4,2,Leaves:4)
B(-1,3,0,LOG:15)
B(3,5,1,Leaves:4)
B(3,6,1,Leaves:4)
B(3,3,0,LOG:15)
B(-3,5,2,Leaves:4)
B(-3,4,2,Leaves:4)
B(-5,4,0,Leaves:4)
B(-3,2,1,Leaves:4)
B(-3,5,1,Leaves:4)
B(0,3,-1,Leaves:4)
B(0,2,-1,LOG:15)
B(0,1,-1,LOG:15)
B(0,0,-1,LOG:15)
B(0,8,2,Leaves:4)
B(0,6,-1,Leaves:4)
B(0,5,-1,Leaves:4)
B(0,4,-1,Leaves:4)
B(-2,3,-2,cocoa:11)
B(-1,4,-6,Leaves:4)
B(-4,5,2,Leaves:4)
B(5,5,-2,Leaves:4)
B(-2,6,-2,Leaves:4)
B(2,2,0,cocoa:9)
B(0,7,1,Leaves:4)
B(3,3,-1,Leaves:4)
B(2,3,0,LOG:15)
B(5,4,1,Leaves:4)
B(4,3,-1,Leaves:4)
B(5,3,1,Leaves:4)
B(4,6,-1,Leaves:4)
B(3,4,-2,Leaves:4)
B(1,3,-1,Leaves:4)
B(1,4,-1,Leaves:4)
B(1,2,-1,cocoa:9)
B(-1,5,-4,Leaves:4)
B(-2,7,0,Leaves:4)
B(-2,5,1,Leaves:4)
B(1,2,-2,Leaves:4)
B(1,5,-1,Leaves:4)
B(-2,3,0,cocoa:11)
B(-2,4,0,LOG:15)
B(-2,6,0,Leaves:4)
B(-1,6,-2,Leaves:4)
B(1,2,0,LOG:15)
B(-1,6,-3,Leaves:4)
B(-1,3,-2,LOG:15)
B(-1,7,-3,Leaves:4)
B(-1,4,-2,Leaves:4)
B(1,5,0,Leaves:4)
B(0,3,-4,Leaves:4)
B(0,4,-4,Leaves:4)
B(1,6,-4,Leaves:4)
B(1,4,-4,Leaves:4)
B(-1,3,-3,cocoa:8)
B(5,2,0,Leaves:4)
B(4,3,0,Leaves:4)
B(-3,5,-2,Leaves:4)
B(-3,3,0,Leaves:4)
B(-3,5,0,LOG:15)
B(-3,5,3,Leaves:4)
B(-3,6,3,Leaves:4)
B(0,4,1,LOG:15)
B(0,3,1,Leaves:4)
B(0,6,1,Leaves:4)
B(0,5,1,LOG:15)
B(3,3,1,Leaves:4)
B(2,5,-5,Leaves:4)
B(2,6,-3,Leaves:4)
B(6,2,1,Leaves:4)
B(2,4,-3,Leaves:4)
B(4,4,1,LOG:15)
B(4,4,0,Leaves:4)
B(4,5,0,Leaves:4)
B(0,2,-2,cocoa:8)
B(5,3,-1,Leaves:4)
B(-2,4,-1,Leaves:4)
B(-2,2,-1,Leaves:4)
B(0,5,-2,Leaves:4)
B(0,6,-2,Leaves:4)
B(-1,2,-1,cocoa:11)
B(-2,5,-3,Leaves:4)
B(-1,3,-1,Leaves:4)
B(-2,4,-3,Leaves:4)
B(2,6,-2,Leaves:4)
B(-1,7,-1,Leaves:4)
B(2,5,-2,Leaves:4)
B(2,5,-1,Leaves:4)
B(2,4,-1,Leaves:4)
B(-4,3,-2,Leaves:4)
B(-2,6,-4,Leaves:4)
B(2,3,-2,Leaves:4)
B(5,2,2,Leaves:4)

#
# +-----------------------------------------------------------------+ #
# |                            BO3 checks                           | #
# +-----------------------------------------------------------------+ #
#

BlockCheck(0,-1,0,grass,dirt)

#
# +-----------------------------------------------------------------+ #
# |                             Branches                            | #
# +-----------------------------------------------------------------+ #
#

