
#
# +-----------------------------------------------------------------+ #
# |                            BO3 object                           | #
# +-----------------------------------------------------------------+ #
#

Author: NLBlackEagle

Description: Converted version of the BO2 SA5L

Version: 3

SettingsMode: WriteDisable


#
# +-----------------------------------------------------------------+ #
# |                          Main settings                          | #
# +-----------------------------------------------------------------+ #
#

Tree: true

Frequency: 1

Rarity: 100.0

RotateRandomly: true

SpawnHeight: highestSolidBlock

SpawnHeightOffset: 0

SpawnHeightVariance: 0


# Height Limits for the BO3. #


MinHeight: 70

MaxHeight: 199


# Extrusion settings #


ExtrudeMode: None

ExtrudeThroughBlocks: air

MaxBranchDepth: 10

ExcludedBiomes: 


#
# +-----------------------------------------------------------------+ #
# |                      Source block settings                      | #
# +-----------------------------------------------------------------+ #
#

SourceBlocks: AIR,GRASS,DIRT,SAND

MaxPercentageOutsideSourceBlock: 0

OutsideSourceBlock: placeAnyway


#
# +-----------------------------------------------------------------+ #
# |                              Blocks                             | #
# +-----------------------------------------------------------------+ #
#

B(1,14,1,Leaves:4)
B(3,17,3,Leaves:4)
B(1,15,1,Leaves:4)
B(0,2,0,LOG:12)
B(0,3,0,LOG:12)
B(3,12,3,Leaves:4)
B(0,0,0,LOG:12)
B(0,1,0,LOG:12)
B(0,6,0,LOG:12)
B(1,10,1,LOG:1)
B(0,7,0,LOG:12)
B(1,11,1,Leaves:4)
B(0,4,0,LOG:12)
B(0,5,0,LOG:12)
B(0,14,-2,Leaves:4)
B(-4,17,0,Leaves:4)
B(0,15,-2,Leaves:4)
B(1,15,-1,Leaves:4)
B(0,15,2,Leaves:4)
B(0,14,2,Leaves:4)
B(-3,17,3,Leaves:4)
B(0,17,4,Leaves:4)
B(-1,11,1,pumpkin:3)
B(0,16,3,Leaves:4)
B(-1,15,1,Leaves:4)
B(-2,16,-2,Leaves:4)
B(-4,17,4,Leaves:4)
B(1,11,-1,LOG:1)
B(1,10,-1,pumpkin:0)
B(5,17,0,Leaves:4)
B(0,10,0,log)
B(-4,13,-1,Leaves:4)
B(-1,17,5,Leaves:4)
B(-5,17,0,leaves:4)
B(0,14,0,Leaves:4)
B(-3,17,-3,Leaves:4)
B(0,13,0,log)
B(0,12,0,log)
B(0,11,0,log)
B(4,17,-4,Leaves:4)
B(0,17,-4,Leaves:4)
B(4,13,-3,Leaves:4)
B(2,12,-1,Leaves:4)
B(0,9,0,LOG:12)
B(3,13,-2,Leaves:4)
B(0,8,0,LOG:12)
B(1,12,0,Leaves:4)
B(1,13,0,Leaves:4)
B(1,10,0,LOG:1)
B(1,11,0,Leaves:4)
B(-1,15,-1,Leaves:4)
B(-5,12,-2,Leaves:4)
B(0,10,1,LOG:1)
B(0,11,1,LOG:1)
B(0,12,1,Leaves:4)
B(0,13,1,Leaves:4)
B(-2,16,2,Leaves:4)
B(0,16,-3,Leaves:4)
B(3,16,0,Leaves:4)
B(-1,11,0,LOG:1)
B(-1,12,0,Leaves:4)
B(-1,13,0,Leaves:4)
B(-2,12,0,Leaves:4)
B(-2,15,0,Leaves:4)
B(-2,14,0,Leaves:4)
B(-1,10,-1,LOG:1)
B(0,10,-1,LOG:1)
B(0,11,-1,LOG:1)
B(0,12,-1,Leaves:4)
B(0,13,-1,Leaves:4)
B(4,17,0,Leaves:4)
B(2,16,2,Leaves:4)
B(-3,13,-1,Leaves:4)
B(2,12,2,Leaves:4)
B(2,15,0,Leaves:4)
B(2,14,0,Leaves:4)
B(5,12,-4,Leaves:4)
B(2,16,-2,Leaves:4)
B(0,17,-5,leaves:4)
B(1,9,1,pumpkin)
B(-4,17,-4,Leaves:4)
B(-3,16,0,Leaves:4)
B(4,11,4,Leaves:4)
B(3,17,-3,Leaves:4)
B(-1,9,-1,pumpkin:3)
B(4,17,4,Leaves:4)

#
# +-----------------------------------------------------------------+ #
# |                            BO3 checks                           | #
# +-----------------------------------------------------------------+ #
#

BlockCheck(0,-1,0,GRASS)

#
# +-----------------------------------------------------------------+ #
# |                             Branches                            | #
# +-----------------------------------------------------------------+ #
#

