
#
# +-----------------------------------------------------------------+ #
# |                            BO3 object                           | #
# +-----------------------------------------------------------------+ #
#

Author: NLBlackEagle

Description: Converted version of the BO2 SA7L

Version: 3

SettingsMode: WriteDisable


#
# +-----------------------------------------------------------------+ #
# |                          Main settings                          | #
# +-----------------------------------------------------------------+ #
#

Tree: true

Frequency: 1

Rarity: 100.0

RotateRandomly: true

SpawnHeight: highestSolidBlock

SpawnHeightOffset: 0

SpawnHeightVariance: 0


# Height Limits for the BO3. #


MinHeight: 0

MaxHeight: 199


# Extrusion settings #


ExtrudeMode: None

ExtrudeThroughBlocks: air

MaxBranchDepth: 10

ExcludedBiomes: 


#
# +-----------------------------------------------------------------+ #
# |                      Source block settings                      | #
# +-----------------------------------------------------------------+ #
#

SourceBlocks: AIR,GRASS,DIRT,SAND

MaxPercentageOutsideSourceBlock: 0

OutsideSourceBlock: placeAnyway


#
# +-----------------------------------------------------------------+ #
# |                              Blocks                             | #
# +-----------------------------------------------------------------+ #
#

B(0,20,-2,leaves:4)
B(0,21,-2,leaves:4)
B(1,15,1,leaves:4)
B(-4,23,0,leaves:4)
B(3,19,3,leaves:4)
B(1,18,-4,leaves:4)
B(1,18,2,leaves:4)
B(1,20,-3,LOG:12)
B(1,17,2,leaves:4)
B(1,18,1,leaves:4)
B(1,21,-3,leaves:4)
B(5,20,-5,leaves:4)
B(3,19,-1,leaves:4)
B(1,19,3,leaves:4)
B(1,15,3,leaves:4)
B(5,22,-7,leaves:4)
B(2,21,-1,leaves:4)
B(2,20,-1,leaves:4)
B(-3,20,0,LOG:12)
B(-3,21,0,leaves:4)
B(1,22,3,leaves:4)
B(-3,18,2,leaves:4)
B(5,23,-1,leaves:4)
B(-4,19,2,leaves:4)
B(-1,19,-3,leaves:4)
B(0,19,3,leaves:4)
B(1,20,1,leaves:4)
B(-1,15,1,leaves:4)
B(-1,21,-3,leaves:4)
B(-1,22,-3,leaves:4)
B(5,20,-1,leaves:4)
B(1,21,-4,leaves:4)
B(0,18,-2,leaves:4)
B(0,17,-2,leaves:4)
B(5,18,0,leaves:4)
B(-3,21,3,leaves:4)
B(-4,20,0,leaves:4)
B(7,22,-3,leaves:4)
B(7,21,-3,leaves:4)
B(0,20,-4,leaves:4)
B(2,17,-3,leaves:4)
B(2,19,3,leaves:4)
B(-5,19,0,leaves:4)
B(0,21,-3,LOG:12)
B(0,22,-3,leaves:4)
B(0,16,0,LOG:12)
B(3,20,-2,leaves:4)
B(0,15,0,leaves:4)
B(0,24,-3,leaves:4)
B(6,22,0,leaves:4)
B(2,21,-4,leaves:4)
B(5,18,2,leaves:4)
B(3,22,-4,leaves:4)
B(-2,21,-1,leaves:4)
B(3,21,-4,LOG:12)
B(-3,20,-3,leaves:4)
B(2,23,-4,leaves:4)
B(3,20,2,leaves:4)
B(4,22,-4,LOG:12)
B(7,20,1,leaves:4)
B(3,23,2,leaves:4)
B(4,16,-4,leaves:4)
B(6,23,-5,leaves:4)
B(4,18,-4,leaves:4)
B(2,16,-4,leaves:4)
B(3,19,-5,leaves:4)
B(2,17,-1,LOG:12)
B(2,16,-1,LOG:12)
B(-6,21,0,leaves:4)
B(3,18,-2,leaves:4)
B(3,19,-2,leaves:4)
B(0,19,0,leaves:4)
B(1,18,-3,leaves:4)
B(1,16,-3,leaves:4)
B(2,24,-6,leaves:4)
B(4,20,1,LOG:12)
B(4,21,1,leaves:4)
B(6,24,-5,leaves:4)
B(1,18,0,LOG:12)
B(1,16,0,leaves:4)
B(1,17,0,leaves:4)
B(-2,20,2,leaves:4)
B(1,14,0,LOG:12)
B(3,20,-3,LOG:12)
B(1,15,0,LOG:12)
B(2,22,-3,leaves:4)
B(1,12,0,LOG:12)
B(1,13,0,LOG:12)
B(-1,15,-2,leaves:4)
B(1,10,0,LOG:12)
B(6,20,1,leaves:4)
B(1,11,0,LOG:12)
B(-1,13,-2,leaves:4)
B(4,22,-1,leaves:4)
B(-1,15,-1,leaves:4)
B(1,1,0,LOG:12)
B(-1,21,-1,leaves:4)
B(1,2,0,LOG:12)
B(1,0,0,LOG:12)
B(4,20,0,leaves:4)
B(4,20,-1,leaves:4)
B(1,5,0,LOG:12)
B(4,21,-1,leaves:4)
B(1,6,0,LOG:12)
B(7,22,-5,leaves:4)
B(1,3,0,LOG:12)
B(1,4,0,LOG:12)
B(5,21,1,leaves:4)
B(7,21,-4,leaves:4)
B(4,20,-3,leaves:4)
B(6,18,2,leaves:4)
B(0,19,1,LOG:12)
B(-2,20,-1,leaves:4)
B(3,22,-7,leaves:4)
B(3,18,0,LOG:12)
B(3,19,0,leaves:4)
B(-1,17,0,LOG:12)
B(-2,19,-3,leaves:4)
B(3,24,-5,leaves:4)
B(-5,22,-1,leaves:4)
B(-2,14,0,leaves:4)
B(-2,20,-3,leaves:4)
B(-2,22,-3,leaves:4)
B(-1,19,4,leaves:4)
B(-2,18,-1,LOG:12)
B(2,23,1,leaves:4)
B(-2,19,-1,LOG:12)
B(2,21,1,leaves:4)
B(-5,21,-2,leaves:4)
B(-2,21,2,leaves:4)
B(4,19,0,leaves:4)
B(-2,17,-1,leaves:4)
B(-2,20,-4,leaves:4)
B(4,15,0,leaves:4)
B(0,19,-3,leaves:4)
B(0,23,-5,leaves:4)
B(4,17,0,leaves:4)
B(-2,20,3,leaves:4)
B(-5,19,-1,leaves:4)
B(-3,19,-1,leaves:4)
B(-1,20,0,leaves:4)
B(4,19,-2,leaves:4)
B(2,19,-2,LOG:12)
B(2,18,-2,LOG:12)
B(2,13,0,leaves:4)
B(2,17,-2,leaves:4)
B(4,23,2,leaves:4)
B(6,18,3,leaves:4)
B(4,22,2,leaves:4)
B(2,18,1,leaves:4)
B(4,21,2,leaves:4)
B(0,20,-1,leaves:4)
B(5,18,-1,leaves:4)
B(-2,19,-5,leaves:4)
B(1,20,2,LOG:12)
B(4,19,1,LOG:12)
B(4,16,-1,leaves:4)
B(6,22,-4,leaves:4)
B(5,25,-4,leaves:4)
B(1,14,-2,leaves:4)
B(1,8,0,LOG:12)
B(1,20,0,leaves:4)
B(1,7,0,LOG:12)
B(1,9,0,LOG:12)
B(1,20,5,leaves:4)
B(4,19,4,leaves:4)
B(4,22,-2,leaves:4)
B(4,20,-2,leaves:4)
B(-2,21,-5,leaves:4)
B(3,17,1,leaves:4)
B(3,18,1,leaves:4)
B(2,20,0,leaves:4)
B(3,19,-3,leaves:4)
B(3,22,-1,leaves:4)
B(3,21,-1,leaves:4)

#
# +-----------------------------------------------------------------+ #
# |                            BO3 checks                           | #
# +-----------------------------------------------------------------+ #
#

BlockCheck(0,-1,0,grass,dirt)

#
# +-----------------------------------------------------------------+ #
# |                             Branches                            | #
# +-----------------------------------------------------------------+ #
#

