Author: BO3 BulkEdit (by LanToaster)
Description: This Object was Created with BO3_BulkEdit
Version: 3
SettingsMode: WriteDisable
Tree: true
Frequency: 1
Rarity: 100.0
RotateRandomly: true
SpawnHeight: randomY
MinHeight: 17
MaxHeight: 17
MaxBranchDepth: 10
ExcludedBiomes: All
SourceBlocks: AIR,GRASS,DIRT,SAND,STONE,WATER
MaxPercentageOutsideSourceBlock: 4
OutsideSourceBlock: dontPlace
Block(-14,-11,-17,LOG:15)
Block(-15,-11,-16,LOG:15)
Block(-14,-11,-16,LOG:15)
Block(-13,-11,-16,LOG:15)
Block(3,-11,-16,LOG:15)
Block(5,-11,-16,LOG:15)
Block(12,-11,-16,LOG:15)
Block(13,-11,-16,LOG:15)
Block(-15,-11,-15,LOG:15)
Block(-14,-11,-15,LOG:15)
Block(-13,-11,-15,LOG:15)
Block(-12,-11,-15,LOG:15)
Block(2,-11,-15,LOG:15)
Block(3,-11,-15,LOG:15)
Block(4,-11,-15,LOG:15)
Block(5,-11,-15,LOG:15)
Block(6,-11,-15,LOG:15)
Block(11,-11,-15,LOG:15)
Block(13,-11,-15,LOG:15)
Block(-14,-11,-14,LOG:15)
Block(-13,-11,-14,LOG:15)
Block(-9,-11,-14,LOG:15)
Block(1,-11,-14,LOG:15)
Block(2,-11,-14,LOG:15)
Block(3,-11,-14,LOG:15)
Block(4,-11,-14,LOG:15)
Block(5,-11,-14,LOG:15)
Block(12,-11,-14,LOG:15)
Block(1,-11,-13,LOG:15)
Block(2,-11,-13,LOG:15)
Block(3,-11,-13,LOG:15)
Block(2,-11,-12,LOG:15)
Block(-10,-11,-11,LOG:15)
Block(-2,-11,-11,LOG:15)
Block(0,-11,-8,LOG:15)
Block(-8,-11,-6,LOG:15)
Block(-11,-11,-5,LOG:15)
Block(-12,-11,-4,LOG:15)
Block(-11,-11,-4,LOG:15)
Block(-10,-11,-4,LOG:15)
Block(-12,-11,-3,LOG:15)
Block(-11,-11,-3,LOG:15)
Block(-10,-11,-3,LOG:15)
Block(12,-11,-3,LOG:15)
Block(13,-11,-3,LOG:15)
Block(-12,-11,-2,LOG:15)
Block(-11,-11,-2,LOG:15)
Block(12,-11,-2,LOG:15)
Block(-14,-11,-1,LOG:15)
Block(-13,-11,-1,LOG:15)
Block(11,-11,-1,LOG:15)
Block(12,-11,-1,LOG:15)
Block(13,-11,-1,LOG:15)
Block(11,-11,0,LOG:15)
Block(12,-11,0,LOG:15)
Block(13,-11,0,LOG:15)
Block(12,-11,1,LOG:15)
Block(13,-11,1,LOG:15)
Block(12,-11,2,LOG:15)
Block(-12,-11,3,LOG:15)
Block(-10,-11,3,LOG:15)
Block(10,-11,4,LOG:15)
Block(-11,-11,6,LOG:15)
Block(8,-11,6,LOG:15)
Block(12,-11,6,LOG:15)
Block(-10,-11,8,LOG:15)
Block(-1,-11,8,LOG:15)
Block(8,-11,8,LOG:15)
Block(10,-11,8,LOG:15)
Block(11,-11,8,LOG:15)
Block(-14,-11,9,LOG:15)
Block(-13,-11,9,LOG:15)
Block(3,-11,9,LOG:15)
Block(9,-11,9,LOG:15)
Block(10,-11,9,LOG:15)
Block(11,-11,9,LOG:15)
Block(12,-11,9,LOG:15)
Block(-15,-11,10,LOG:15)
Block(-14,-11,10,LOG:15)
Block(-13,-11,10,LOG:15)
Block(-12,-11,10,LOG:15)
Block(9,-11,10,LOG:15)
Block(10,-11,10,LOG:15)
Block(11,-11,10,LOG:15)
Block(12,-11,10,LOG:15)
Block(-15,-11,11,LOG:15)
Block(-14,-11,11,LOG:15)
Block(-13,-11,11,LOG:15)
Block(-1,-11,11,LOG:15)
Block(8,-11,11,LOG:15)
Block(9,-11,11,LOG:15)
Block(10,-11,11,LOG:15)
Block(11,-11,11,LOG:15)
Block(-14,-11,12,LOG:15)
Block(-13,-11,12,LOG:15)
Block(2,-11,12,LOG:15)
Block(3,-11,12,LOG:15)
Block(4,-11,12,LOG:15)
Block(8,-11,12,LOG:15)
Block(9,-11,12,LOG:15)
Block(10,-11,12,LOG:15)
Block(-14,-11,13,LOG:15)
Block(3,-11,13,LOG:15)
Block(4,-11,13,LOG:15)
Block(5,-11,13,LOG:15)
Block(9,-11,13,LOG:15)
Block(4,-11,14,LOG:15)
Block(-14,-10,-16,LOG:15)
Block(-13,-10,-16,LOG:15)
Block(-12,-10,-16,LOG:15)
Block(12,-10,-16,LOG:15)
Block(-14,-10,-15,LOG:15)
Block(-13,-10,-15,LOG:15)
Block(-12,-10,-15,LOG:15)
Block(-11,-10,-15,LOG:15)
Block(2,-10,-15,LOG:15)
Block(3,-10,-15,LOG:15)
Block(5,-10,-15,LOG:15)
Block(11,-10,-15,LOG:15)
Block(13,-10,-15,LOG:15)
Block(-13,-10,-14,LOG:15)
Block(-12,-10,-14,LOG:15)
Block(-11,-10,-14,LOG:15)
Block(-10,-10,-14,LOG:15)
Block(-9,-10,-14,LOG:15)
Block(1,-10,-14,LOG:15)
Block(2,-10,-14,LOG:15)
Block(3,-10,-14,LOG:15)
Block(11,-10,-14,LOG:15)
Block(12,-10,-14,LOG:15)
Block(-10,-10,-13,LOG:15)
Block(1,-10,-13,LOG:15)
Block(2,-10,-13,LOG:15)
Block(3,-10,-13,LOG:15)
Block(1,-10,-12,LOG:15)
Block(2,-10,-12,LOG:15)
Block(9,-10,-12,LOG:15)
Block(-10,-10,-11,LOG:15)
Block(-2,-10,-11,LOG:15)
Block(0,-10,-8,LOG:15)
Block(-8,-10,-6,LOG:15)
Block(-11,-10,-5,LOG:15)
Block(-10,-10,-5,LOG:15)
Block(-12,-10,-4,LOG:15)
Block(-11,-10,-4,LOG:15)
Block(-10,-10,-4,LOG:15)
Block(-9,-10,-4,LOG:15)
Block(-6,-10,-4,LOG:15)
Block(-11,-10,-3,LOG:15)
Block(-10,-10,-3,LOG:15)
Block(12,-10,-1,LOG:15)
Block(11,-10,0,LOG:15)
Block(12,-10,0,LOG:15)
Block(13,-10,0,LOG:15)
Block(11,-10,1,LOG:15)
Block(12,-10,1,LOG:15)
Block(13,-10,1,LOG:15)
Block(11,-10,2,LOG:15)
Block(12,-10,2,LOG:15)
Block(13,-10,2,LOG:15)
Block(-12,-10,3,LOG:15)
Block(-10,-10,3,LOG:15)
Block(12,-10,3,LOG:15)
Block(10,-10,4,LOG:15)
Block(-11,-10,6,LOG:15)
Block(8,-10,6,LOG:15)
Block(12,-10,6,LOG:15)
Block(-13,-10,8,LOG:15)
Block(-12,-10,8,LOG:15)
Block(-10,-10,8,LOG:15)
Block(-1,-10,8,LOG:15)
Block(8,-10,8,LOG:15)
Block(11,-10,8,LOG:15)
Block(-14,-10,9,LOG:15)
Block(-13,-10,9,LOG:15)
Block(-12,-10,9,LOG:15)
Block(3,-10,9,LOG:15)
Block(10,-10,9,LOG:15)
Block(11,-10,9,LOG:15)
Block(-14,-10,10,LOG:15)
Block(-13,-10,10,LOG:15)
Block(-12,-10,10,LOG:15)
Block(10,-10,10,LOG:15)
Block(11,-10,10,LOG:15)
Block(12,-10,10,LOG:15)
Block(-14,-10,11,LOG:15)
Block(-13,-10,11,LOG:15)
Block(-1,-10,11,LOG:15)
Block(2,-10,11,LOG:15)
Block(3,-10,11,LOG:15)
Block(9,-10,11,LOG:15)
Block(11,-10,11,LOG:15)
Block(-14,-10,12,LOG:15)
Block(1,-10,12,LOG:15)
Block(2,-10,12,LOG:15)
Block(3,-10,12,LOG:15)
Block(4,-10,12,LOG:15)
Block(9,-10,12,LOG:15)
Block(2,-10,13,LOG:15)
Block(3,-10,13,LOG:15)
Block(4,-10,13,LOG:15)
Block(5,-10,13,LOG:15)
Block(3,-10,14,LOG:15)
Block(4,-10,14,LOG:15)
Block(-12,-9,-16,LOG:15)
Block(12,-9,-16,LOG:15)
Block(-13,-9,-15,LOG:15)
Block(-12,-9,-15,LOG:15)
Block(-11,-9,-15,LOG:15)
Block(-10,-9,-15,LOG:15)
Block(11,-9,-15,LOG:15)
Block(13,-9,-15,LOG:15)
Block(-13,-9,-14,LOG:15)
Block(-12,-9,-14,LOG:15)
Block(-11,-9,-14,LOG:15)
Block(-10,-9,-14,LOG:15)
Block(-9,-9,-14,LOG:15)
Block(1,-9,-14,LOG:15)
Block(2,-9,-14,LOG:15)
Block(10,-9,-14,LOG:15)
Block(11,-9,-14,LOG:15)
Block(12,-9,-14,LOG:15)
Block(13,-9,-14,LOG:15)
Block(-12,-9,-13,LOG:15)
Block(-11,-9,-13,LOG:15)
Block(-10,-9,-13,LOG:15)
Block(-9,-9,-13,LOG:15)
Block(0,-9,-13,LOG:15)
Block(1,-9,-13,LOG:15)
Block(2,-9,-13,LOG:15)
Block(3,-9,-13,LOG:15)
Block(11,-9,-13,LOG:15)
Block(12,-9,-13,LOG:15)
Block(-10,-9,-12,LOG:15)
Block(0,-9,-12,LOG:15)
Block(1,-9,-12,LOG:15)
Block(2,-9,-12,LOG:15)
Block(9,-9,-12,LOG:15)
Block(-10,-9,-11,LOG:15)
Block(-2,-9,-11,LOG:15)
Block(0,-9,-11,LOG:15)
Block(1,-9,-11,LOG:15)
Block(-3,-9,-8,LOG:15)
Block(0,-9,-8,LOG:15)
Block(-5,-9,-7,LOG:15)
Block(-8,-9,-6,LOG:15)
Block(-10,-9,-5,LOG:15)
Block(-9,-9,-5,LOG:15)
Block(-11,-9,-4,LOG:15)
Block(-10,-9,-4,LOG:15)
Block(-9,-9,-4,LOG:15)
Block(-8,-9,-4,LOG:15)
Block(-6,-9,-4,LOG:15)
Block(-10,-9,-3,LOG:15)
Block(-9,-9,-3,LOG:15)
Block(-4,-9,-2,LOG:15)
Block(12,-9,0,LOG:15)
Block(11,-9,1,LOG:15)
Block(12,-9,1,LOG:15)
Block(10,-9,2,LOG:15)
Block(11,-9,2,LOG:15)
Block(12,-9,2,LOG:15)
Block(13,-9,2,LOG:15)
Block(-12,-9,3,LOG:15)
Block(-10,-9,3,LOG:15)
Block(11,-9,3,LOG:15)
Block(12,-9,3,LOG:15)
Block(10,-9,4,LOG:15)
Block(-12,-9,6,LOG:15)
Block(-11,-9,6,LOG:15)
Block(8,-9,6,LOG:15)
Block(12,-9,6,LOG:15)
Block(-12,-9,7,LOG:15)
Block(11,-9,7,LOG:15)
Block(-13,-9,8,LOG:15)
Block(-12,-9,8,LOG:15)
Block(-11,-9,8,LOG:15)
Block(-10,-9,8,LOG:15)
Block(-1,-9,8,LOG:15)
Block(8,-9,8,LOG:15)
Block(10,-9,8,LOG:15)
Block(11,-9,8,LOG:15)
Block(12,-9,8,LOG:15)
Block(-14,-9,9,LOG:15)
Block(-13,-9,9,LOG:15)
Block(-12,-9,9,LOG:15)
Block(-11,-9,9,LOG:15)
Block(3,-9,9,LOG:15)
Block(10,-9,9,LOG:15)
Block(11,-9,9,LOG:15)
Block(12,-9,9,LOG:15)
Block(-13,-9,10,LOG:15)
Block(-12,-9,10,LOG:15)
Block(2,-9,10,LOG:15)
Block(10,-9,10,LOG:15)
Block(11,-9,10,LOG:15)
Block(12,-9,10,LOG:15)
Block(-1,-9,11,LOG:15)
Block(0,-9,11,LOG:15)
Block(1,-9,11,LOG:15)
Block(2,-9,11,LOG:15)
Block(3,-9,11,LOG:15)
Block(11,-9,11,LOG:15)
Block(1,-9,12,LOG:15)
Block(2,-9,12,LOG:15)
Block(3,-9,12,LOG:15)
Block(2,-9,13,LOG:15)
Block(3,-9,13,LOG:15)
Block(4,-9,13,LOG:15)
Block(-12,-8,-15,LOG:15)
Block(-10,-8,-15,LOG:15)
Block(10,-8,-15,LOG:15)
Block(11,-8,-15,LOG:15)
Block(-12,-8,-14,LOG:15)
Block(-11,-8,-14,LOG:15)
Block(-10,-8,-14,LOG:15)
Block(-9,-8,-14,LOG:15)
Block(9,-8,-14,LOG:15)
Block(10,-8,-14,LOG:15)
Block(11,-8,-14,LOG:15)
Block(12,-8,-14,LOG:15)
Block(-10,-8,-13,LOG:15)
Block(0,-8,-13,LOG:15)
Block(1,-8,-13,LOG:15)
Block(2,-8,-13,LOG:15)
Block(10,-8,-13,LOG:15)
Block(11,-8,-13,LOG:15)
Block(-7,-8,-12,LOG:15)
Block(-1,-8,-12,LOG:15)
Block(0,-8,-12,LOG:15)
Block(1,-8,-12,LOG:15)
Block(2,-8,-12,LOG:15)
Block(9,-8,-12,LOG:15)
Block(-10,-8,-11,LOG:15)
Block(-2,-8,-11,LOG:15)
Block(-1,-8,-11,LOG:15)
Block(0,-8,-11,LOG:15)
Block(1,-8,-11,LOG:15)
Block(-7,-8,-10,LOG:15)
Block(-1,-8,-10,LOG:15)
Block(0,-8,-10,LOG:15)
Block(7,-8,-10,LOG:15)
Block(-5,-8,-9,LOG:15)
Block(-3,-8,-8,LOG:15)
Block(0,-8,-8,LOG:15)
Block(3,-8,-8,LOG:15)
Block(-5,-8,-7,LOG:15)
Block(-2,-8,-7,LOG:15)
Block(-8,-8,-6,LOG:15)
Block(4,-8,-6,LOG:15)
Block(-9,-8,-5,LOG:15)
Block(2,-8,-5,LOG:15)
Block(-10,-8,-4,LOG:15)
Block(-9,-8,-4,LOG:15)
Block(-8,-8,-4,LOG:15)
Block(-6,-8,-4,LOG:15)
Block(-9,-8,-3,LOG:15)
Block(-4,-8,-2,LOG:15)
Block(-9,-8,0,LOG:15)
Block(-4,-8,0,LOG:15)
Block(-2,-8,0,LOG:15)
Block(-6,-8,1,LOG:15)
Block(2,-8,1,LOG:15)
Block(11,-8,1,LOG:15)
Block(-8,-8,2,LOG:15)
Block(-2,-8,2,LOG:15)
Block(0,-8,2,LOG:15)
Block(10,-8,2,LOG:15)
Block(11,-8,2,LOG:15)
Block(12,-8,2,LOG:15)
Block(-12,-8,3,LOG:15)
Block(-10,-8,3,LOG:15)
Block(5,-8,3,LOG:15)
Block(10,-8,3,LOG:15)
Block(11,-8,3,LOG:15)
Block(12,-8,3,LOG:15)
Block(-3,-8,4,LOG:15)
Block(10,-8,4,LOG:15)
Block(11,-8,4,LOG:15)
Block(-12,-8,5,LOG:15)
Block(-1,-8,5,LOG:15)
Block(7,-8,5,LOG:15)
Block(-13,-8,6,LOG:15)
Block(-12,-8,6,LOG:15)
Block(-11,-8,6,LOG:15)
Block(1,-8,6,LOG:15)
Block(8,-8,6,LOG:15)
Block(11,-8,6,LOG:15)
Block(12,-8,6,LOG:15)
Block(-13,-8,7,LOG:15)
Block(-12,-8,7,LOG:15)
Block(-11,-8,7,LOG:15)
Block(-1,-8,7,LOG:15)
Block(10,-8,7,LOG:15)
Block(11,-8,7,LOG:15)
Block(-13,-8,8,LOG:15)
Block(-12,-8,8,LOG:15)
Block(-11,-8,8,LOG:15)
Block(-1,-8,8,LOG:15)
Block(8,-8,8,LOG:15)
Block(9,-8,8,LOG:15)
Block(10,-8,8,LOG:15)
Block(11,-8,8,LOG:15)
Block(12,-8,8,LOG:15)
Block(-13,-8,9,LOG:15)
Block(-12,-8,9,LOG:15)
Block(3,-8,9,LOG:15)
Block(10,-8,9,LOG:15)
Block(11,-8,9,LOG:15)
Block(1,-8,10,LOG:15)
Block(2,-8,10,LOG:15)
Block(11,-8,10,LOG:15)
Block(0,-8,11,LOG:15)
Block(1,-8,11,LOG:15)
Block(2,-8,11,LOG:15)
Block(3,-8,11,LOG:15)
Block(2,-8,12,LOG:15)
Block(-10,-7,-15,LOG:15)
Block(10,-7,-15,LOG:15)
Block(-11,-7,-14,LOG:15)
Block(-10,-7,-14,LOG:15)
Block(-9,-7,-14,LOG:15)
Block(9,-7,-14,LOG:15)
Block(10,-7,-14,LOG:15)
Block(11,-7,-14,LOG:15)
Block(-10,-7,-13,LOG:15)
Block(10,-7,-13,LOG:15)
Block(-10,-7,-12,LOG:15)
Block(-7,-7,-12,LOG:15)
Block(-1,-7,-12,LOG:15)
Block(0,-7,-12,LOG:15)
Block(1,-7,-12,LOG:15)
Block(9,-7,-12,LOG:15)
Block(-10,-7,-11,LOG:15)
Block(-2,-7,-11,LOG:15)
Block(-1,-7,-11,LOG:15)
Block(0,-7,-11,LOG:15)
Block(1,-7,-11,LOG:15)
Block(-7,-7,-10,LOG:15)
Block(-2,-7,-10,LOG:15)
Block(-1,-7,-10,LOG:15)
Block(0,-7,-10,LOG:15)
Block(7,-7,-10,LOG:15)
Block(9,-7,-10,LOG:15)
Block(-5,-7,-9,LOG:15)
Block(-2,-7,-9,LOG:15)
Block(-1,-7,-9,LOG:15)
Block(0,-7,-9,LOG:15)
Block(-3,-7,-8,LOG:15)
Block(0,-7,-8,LOG:15)
Block(3,-7,-8,LOG:15)
Block(5,-7,-8,LOG:15)
Block(-5,-7,-7,LOG:15)
Block(-2,-7,-7,LOG:15)
Block(4,-7,-6,LOG:15)
Block(-9,-7,-5,LOG:15)
Block(-8,-7,-5,LOG:15)
Block(-4,-7,-5,LOG:15)
Block(2,-7,-5,LOG:15)
Block(-10,-7,-4,LOG:15)
Block(-9,-7,-4,LOG:15)
Block(-8,-7,-4,LOG:15)
Block(-7,-7,-4,LOG:15)
Block(-6,-7,-4,LOG:15)
Block(-2,-7,-4,LOG:15)
Block(-9,-7,-3,LOG:15)
Block(-8,-7,-3,LOG:15)
Block(-4,-7,-2,LOG:15)
Block(-2,-7,-2,LOG:15)
Block(0,-7,-2,LOG:15)
Block(3,-7,-2,LOG:15)
Block(-9,-7,0,LOG:15)
Block(-4,-7,0,LOG:15)
Block(-2,-7,0,LOG:15)
Block(0,-7,0,LOG:15)
Block(4,-7,0,LOG:15)
Block(-6,-7,1,LOG:15)
Block(2,-7,1,LOG:15)
Block(7,-7,1,LOG:15)
Block(-8,-7,2,LOG:15)
Block(-2,-7,2,LOG:15)
Block(0,-7,2,LOG:15)
Block(10,-7,2,LOG:15)
Block(11,-7,2,LOG:15)
Block(-12,-7,3,LOG:15)
Block(-10,-7,3,LOG:15)
Block(5,-7,3,LOG:15)
Block(9,-7,3,LOG:15)
Block(10,-7,3,LOG:15)
Block(11,-7,3,LOG:15)
Block(12,-7,3,LOG:15)
Block(-12,-7,4,LOG:15)
Block(-3,-7,4,LOG:15)
Block(10,-7,4,LOG:15)
Block(11,-7,4,LOG:15)
Block(-12,-7,5,LOG:15)
Block(-1,-7,5,LOG:15)
Block(7,-7,5,LOG:15)
Block(-13,-7,6,LOG:15)
Block(-12,-7,6,LOG:15)
Block(-11,-7,6,LOG:15)
Block(1,-7,6,LOG:15)
Block(8,-7,6,LOG:15)
Block(11,-7,6,LOG:15)
Block(-12,-7,7,LOG:15)
Block(-1,-7,7,LOG:15)
Block(10,-7,7,LOG:15)
Block(11,-7,7,LOG:15)
Block(12,-7,7,LOG:15)
Block(-12,-7,8,LOG:15)
Block(10,-7,8,LOG:15)
Block(11,-7,8,LOG:15)
Block(12,-7,8,LOG:15)
Block(1,-7,9,LOG:15)
Block(2,-7,9,LOG:15)
Block(3,-7,9,LOG:15)
Block(11,-7,9,LOG:15)
Block(0,-7,10,LOG:15)
Block(1,-7,10,LOG:15)
Block(2,-7,10,LOG:15)
Block(3,-7,10,LOG:15)
Block(0,-7,11,LOG:15)
Block(1,-7,11,LOG:15)
Block(2,-7,11,LOG:15)
Block(3,-7,11,LOG:15)
Block(2,-7,12,LOG:15)
Block(-10,-6,-15,LOG:15)
Block(10,-6,-15,LOG:15)
Block(-11,-6,-14,LOG:15)
Block(-10,-6,-14,LOG:15)
Block(-9,-6,-14,LOG:15)
Block(9,-6,-14,LOG:15)
Block(10,-6,-14,LOG:15)
Block(11,-6,-14,LOG:15)
Block(-11,-6,-13,LOG:15)
Block(-10,-6,-13,LOG:15)
Block(-9,-6,-13,LOG:15)
Block(9,-6,-13,LOG:15)
Block(10,-6,-13,LOG:15)
Block(11,-6,-13,LOG:15)
Block(-10,-6,-12,LOG:15)
Block(-7,-6,-12,LOG:15)
Block(8,-6,-12,LOG:15)
Block(9,-6,-12,LOG:15)
Block(10,-6,-12,LOG:15)
Block(-2,-6,-11,LOG:15)
Block(-1,-6,-11,LOG:15)
Block(0,-6,-11,LOG:15)
Block(9,-6,-11,LOG:15)
Block(-7,-6,-10,LOG:15)
Block(-3,-6,-10,LOG:15)
Block(-2,-6,-10,LOG:15)
Block(-1,-6,-10,LOG:15)
Block(0,-6,-10,LOG:15)
Block(1,-6,-10,LOG:15)
Block(7,-6,-10,LOG:15)
Block(8,-6,-10,LOG:15)
Block(9,-6,-10,LOG:15)
Block(-5,-6,-9,LOG:15)
Block(-3,-6,-9,LOG:15)
Block(-2,-6,-9,LOG:15)
Block(-1,-6,-9,LOG:15)
Block(0,-6,-9,LOG:15)
Block(-3,-6,-8,LOG:15)
Block(-2,-6,-8,LOG:15)
Block(3,-6,-8,LOG:15)
Block(5,-6,-8,LOG:15)
Block(-5,-6,-7,LOG:15)
Block(-2,-6,-7,LOG:15)
Block(4,-6,-6,LOG:15)
Block(-8,-6,-5,LOG:15)
Block(-7,-6,-5,LOG:15)
Block(-4,-6,-5,LOG:15)
Block(2,-6,-5,LOG:15)
Block(-9,-6,-4,LOG:15)
Block(-8,-6,-4,LOG:15)
Block(-7,-6,-4,LOG:15)
Block(-6,-6,-4,LOG:15)
Block(-2,-6,-4,LOG:15)
Block(-8,-6,-3,LOG:15)
Block(-7,-6,-3,LOG:15)
Block(-4,-6,-2,LOG:15)
Block(-2,-6,-2,LOG:15)
Block(0,-6,-2,LOG:15)
Block(3,-6,-2,LOG:15)
Block(-9,-6,0,LOG:15)
Block(-4,-6,0,LOG:15)
Block(-2,-6,0,LOG:15)
Block(0,-6,0,LOG:15)
Block(4,-6,0,LOG:15)
Block(-6,-6,1,LOG:15)
Block(2,-6,1,LOG:15)
Block(7,-6,1,LOG:15)
Block(-8,-6,2,LOG:15)
Block(-2,-6,2,LOG:15)
Block(0,-6,2,LOG:15)
Block(10,-6,2,LOG:15)
Block(-10,-6,3,LOG:15)
Block(5,-6,3,LOG:15)
Block(9,-6,3,LOG:15)
Block(10,-6,3,LOG:15)
Block(11,-6,3,LOG:15)
Block(-12,-6,4,LOG:15)
Block(-3,-6,4,LOG:15)
Block(0,-6,4,LOG:15)
Block(10,-6,4,LOG:15)
Block(-13,-6,5,LOG:15)
Block(-12,-6,5,LOG:15)
Block(-11,-6,5,LOG:15)
Block(-1,-6,5,LOG:15)
Block(7,-6,5,LOG:15)
Block(10,-6,5,LOG:15)
Block(-13,-6,6,LOG:15)
Block(-12,-6,6,LOG:15)
Block(-11,-6,6,LOG:15)
Block(1,-6,6,LOG:15)
Block(8,-6,6,LOG:15)
Block(9,-6,6,LOG:15)
Block(10,-6,6,LOG:15)
Block(11,-6,6,LOG:15)
Block(-12,-6,7,LOG:15)
Block(-1,-6,7,LOG:15)
Block(10,-6,7,LOG:15)
Block(11,-6,7,LOG:15)
Block(12,-6,7,LOG:15)
Block(11,-6,8,LOG:15)
Block(1,-6,9,LOG:15)
Block(0,-6,10,LOG:15)
Block(1,-6,10,LOG:15)
Block(2,-6,10,LOG:15)
Block(1,-6,11,LOG:15)
Block(2,-6,11,LOG:15)
Block(3,-6,11,LOG:15)
Block(-10,-5,-14,LOG:15)
Block(-9,-5,-14,LOG:15)
Block(10,-5,-14,LOG:15)
Block(-11,-5,-13,LOG:15)
Block(-10,-5,-13,LOG:15)
Block(-9,-5,-13,LOG:15)
Block(-8,-5,-13,LOG:15)
Block(9,-5,-13,LOG:15)
Block(10,-5,-13,LOG:15)
Block(-10,-5,-12,LOG:15)
Block(-9,-5,-12,LOG:15)
Block(-8,-5,-12,LOG:15)
Block(-7,-5,-12,LOG:15)
Block(8,-5,-12,LOG:15)
Block(9,-5,-12,LOG:15)
Block(10,-5,-12,LOG:15)
Block(-7,-5,-11,LOG:15)
Block(7,-5,-11,LOG:15)
Block(8,-5,-11,LOG:15)
Block(9,-5,-11,LOG:15)
Block(-7,-5,-10,LOG:15)
Block(-6,-5,-10,LOG:15)
Block(-2,-5,-10,LOG:15)
Block(-1,-5,-10,LOG:15)
Block(0,-5,-10,LOG:15)
Block(6,-5,-10,LOG:15)
Block(7,-5,-10,LOG:15)
Block(8,-5,-10,LOG:15)
Block(9,-5,-10,LOG:15)
Block(-6,-5,-9,LOG:15)
Block(-5,-5,-9,LOG:15)
Block(-3,-5,-9,LOG:15)
Block(-2,-5,-9,LOG:15)
Block(-1,-5,-9,LOG:15)
Block(0,-5,-9,LOG:15)
Block(5,-5,-9,LOG:15)
Block(7,-5,-9,LOG:15)
Block(8,-5,-9,LOG:15)
Block(-6,-5,-8,LOG:15)
Block(-5,-5,-8,LOG:15)
Block(-4,-5,-8,LOG:15)
Block(-3,-5,-8,LOG:15)
Block(-2,-5,-8,LOG:15)
Block(-1,-5,-8,LOG:15)
Block(3,-5,-8,LOG:15)
Block(4,-5,-8,LOG:15)
Block(5,-5,-8,LOG:15)
Block(-5,-5,-7,LOG:15)
Block(-4,-5,-7,LOG:15)
Block(-3,-5,-7,LOG:15)
Block(-2,-5,-7,LOG:15)
Block(3,-5,-7,LOG:15)
Block(-4,-5,-6,LOG:15)
Block(-3,-5,-6,LOG:15)
Block(2,-5,-6,LOG:15)
Block(3,-5,-6,LOG:15)
Block(4,-5,-6,LOG:15)
Block(-7,-5,-5,LOG:15)
Block(-6,-5,-5,LOG:15)
Block(-5,-5,-5,LOG:15)
Block(-4,-5,-5,LOG:15)
Block(-3,-5,-5,LOG:15)
Block(-2,-5,-5,LOG:15)
Block(2,-5,-5,LOG:15)
Block(-8,-5,-4,LOG:15)
Block(-7,-5,-4,LOG:15)
Block(-6,-5,-4,LOG:15)
Block(-5,-5,-4,LOG:15)
Block(-2,-5,-4,LOG:15)
Block(-7,-5,-3,LOG:15)
Block(-6,-5,-3,LOG:15)
Block(-2,-5,-3,LOG:15)
Block(1,-5,-3,LOG:15)
Block(-4,-5,-2,LOG:15)
Block(-2,-5,-2,LOG:15)
Block(0,-5,-2,LOG:15)
Block(3,-5,-2,LOG:15)
Block(-4,-5,-1,LOG:15)
Block(-9,-5,0,LOG:15)
Block(-4,-5,0,LOG:15)
Block(-2,-5,0,LOG:15)
Block(0,-5,0,LOG:15)
Block(4,-5,0,LOG:15)
Block(-9,-5,1,LOG:15)
Block(-8,-5,1,LOG:15)
Block(-7,-5,1,LOG:15)
Block(-6,-5,1,LOG:15)
Block(2,-5,1,LOG:15)
Block(3,-5,1,LOG:15)
Block(7,-5,1,LOG:15)
Block(-10,-5,2,LOG:15)
Block(-9,-5,2,LOG:15)
Block(-8,-5,2,LOG:15)
Block(-2,-5,2,LOG:15)
Block(0,-5,2,LOG:15)
Block(4,-5,2,LOG:15)
Block(5,-5,2,LOG:15)
Block(10,-5,2,LOG:15)
Block(-11,-5,3,LOG:15)
Block(-10,-5,3,LOG:15)
Block(-2,-5,3,LOG:15)
Block(5,-5,3,LOG:15)
Block(6,-5,3,LOG:15)
Block(9,-5,3,LOG:15)
Block(10,-5,3,LOG:15)
Block(11,-5,3,LOG:15)
Block(-12,-5,4,LOG:15)
Block(-11,-5,4,LOG:15)
Block(-3,-5,4,LOG:15)
Block(-2,-5,4,LOG:15)
Block(-1,-5,4,LOG:15)
Block(0,-5,4,LOG:15)
Block(6,-5,4,LOG:15)
Block(7,-5,4,LOG:15)
Block(9,-5,4,LOG:15)
Block(10,-5,4,LOG:15)
Block(11,-5,4,LOG:15)
Block(-12,-5,5,LOG:15)
Block(-1,-5,5,LOG:15)
Block(7,-5,5,LOG:15)
Block(8,-5,5,LOG:15)
Block(9,-5,5,LOG:15)
Block(10,-5,5,LOG:15)
Block(11,-5,5,LOG:15)
Block(-12,-5,6,LOG:15)
Block(-1,-5,6,LOG:15)
Block(0,-5,6,LOG:15)
Block(1,-5,6,LOG:15)
Block(9,-5,6,LOG:15)
Block(10,-5,6,LOG:15)
Block(11,-5,6,LOG:15)
Block(12,-5,6,LOG:15)
Block(-1,-5,7,LOG:15)
Block(0,-5,7,LOG:15)
Block(10,-5,7,LOG:15)
Block(11,-5,7,LOG:15)
Block(12,-5,7,LOG:15)
Block(0,-5,8,LOG:15)
Block(11,-5,8,LOG:15)
Block(0,-5,9,LOG:15)
Block(1,-5,9,LOG:15)
Block(1,-5,10,LOG:15)
Block(1,-5,11,LOG:15)
Block(2,-5,11,LOG:15)
Block(-9,-4,-14,LOG:15)
Block(-8,-4,-14,LOG:15)
Block(-10,-4,-13,LOG:15)
Block(-9,-4,-13,LOG:15)
Block(-8,-4,-13,LOG:15)
Block(-7,-4,-13,LOG:15)
Block(9,-4,-13,LOG:15)
Block(-9,-4,-12,LOG:15)
Block(-8,-4,-12,LOG:15)
Block(-7,-4,-12,LOG:15)
Block(-6,-4,-12,LOG:15)
Block(8,-4,-12,LOG:15)
Block(9,-4,-12,LOG:15)
Block(10,-4,-12,LOG:15)
Block(-8,-4,-11,LOG:15)
Block(-7,-4,-11,LOG:15)
Block(-6,-4,-11,LOG:15)
Block(7,-4,-11,LOG:15)
Block(8,-4,-11,LOG:15)
Block(9,-4,-11,LOG:15)
Block(10,-4,-11,LOG:15)
Block(-8,-4,-10,LOG:15)
Block(-7,-4,-10,LOG:15)
Block(-6,-4,-10,LOG:15)
Block(-5,-4,-10,LOG:15)
Block(5,-4,-10,LOG:15)
Block(6,-4,-10,LOG:15)
Block(7,-4,-10,LOG:15)
Block(8,-4,-10,LOG:15)
Block(9,-4,-10,LOG:15)
Block(-7,-4,-9,LOG:15)
Block(-6,-4,-9,LOG:15)
Block(-5,-4,-9,LOG:15)
Block(-4,-4,-9,LOG:15)
Block(-3,-4,-9,LOG:15)
Block(-2,-4,-9,LOG:15)
Block(-1,-4,-9,LOG:15)
Block(4,-4,-9,LOG:15)
Block(5,-4,-9,LOG:15)
Block(7,-4,-9,LOG:15)
Block(8,-4,-9,LOG:15)
Block(-7,-4,-8,LOG:15)
Block(-6,-4,-8,LOG:15)
Block(-5,-4,-8,LOG:15)
Block(-4,-4,-8,LOG:15)
Block(-3,-4,-8,LOG:15)
Block(-2,-4,-8,LOG:15)
Block(3,-4,-8,LOG:15)
Block(4,-4,-8,LOG:15)
Block(5,-4,-8,LOG:15)
Block(6,-4,-8,LOG:15)
Block(7,-4,-8,LOG:15)
Block(-6,-4,-7,LOG:15)
Block(-5,-4,-7,LOG:15)
Block(-4,-4,-7,LOG:15)
Block(-3,-4,-7,LOG:15)
Block(-2,-4,-7,LOG:15)
Block(2,-4,-7,LOG:15)
Block(3,-4,-7,LOG:15)
Block(5,-4,-7,LOG:15)
Block(-5,-4,-6,LOG:15)
Block(-4,-4,-6,LOG:15)
Block(-3,-4,-6,LOG:15)
Block(-2,-4,-6,LOG:15)
Block(1,-4,-6,LOG:15)
Block(2,-4,-6,LOG:15)
Block(3,-4,-6,LOG:15)
Block(4,-4,-6,LOG:15)
Block(-6,-4,-5,LOG:15)
Block(-5,-4,-5,LOG:15)
Block(-4,-4,-5,LOG:15)
Block(-3,-4,-5,LOG:15)
Block(-2,-4,-5,LOG:15)
Block(-1,-4,-5,LOG:15)
Block(2,-4,-5,LOG:15)
Block(3,-4,-5,LOG:15)
Block(-7,-4,-4,LOG:15)
Block(-6,-4,-4,LOG:15)
Block(-5,-4,-4,LOG:15)
Block(-4,-4,-4,LOG:15)
Block(-3,-4,-4,LOG:15)
Block(-2,-4,-4,LOG:15)
Block(-1,-4,-4,LOG:15)
Block(1,-4,-4,LOG:15)
Block(2,-4,-4,LOG:15)
Block(-6,-4,-3,LOG:15)
Block(-5,-4,-3,LOG:15)
Block(-4,-4,-3,LOG:15)
Block(-3,-4,-3,LOG:15)
Block(-2,-4,-3,LOG:15)
Block(-1,-4,-3,LOG:15)
Block(0,-4,-3,LOG:15)
Block(1,-4,-3,LOG:15)
Block(2,-4,-3,LOG:15)
Block(-5,-4,-2,LOG:15)
Block(-4,-4,-2,LOG:15)
Block(-3,-4,-2,LOG:15)
Block(-2,-4,-2,LOG:15)
Block(0,-4,-2,LOG:15)
Block(1,-4,-2,LOG:15)
Block(2,-4,-2,LOG:15)
Block(3,-4,-2,LOG:15)
Block(-6,-4,-1,LOG:15)
Block(-5,-4,-1,LOG:15)
Block(-4,-4,-1,LOG:15)
Block(-3,-4,-1,LOG:15)
Block(1,-4,-1,LOG:15)
Block(-9,-4,0,LOG:15)
Block(-8,-4,0,LOG:15)
Block(-7,-4,0,LOG:15)
Block(-6,-4,0,LOG:15)
Block(-4,-4,0,LOG:15)
Block(-2,-4,0,LOG:15)
Block(0,-4,0,LOG:15)
Block(2,-4,0,LOG:15)
Block(3,-4,0,LOG:15)
Block(4,-4,0,LOG:15)
Block(-10,-4,1,LOG:15)
Block(-9,-4,1,LOG:15)
Block(-8,-4,1,LOG:15)
Block(-7,-4,1,LOG:15)
Block(-6,-4,1,LOG:15)
Block(2,-4,1,LOG:15)
Block(3,-4,1,LOG:15)
Block(4,-4,1,LOG:15)
Block(5,-4,1,LOG:15)
Block(7,-4,1,LOG:15)
Block(-11,-4,2,LOG:15)
Block(-10,-4,2,LOG:15)
Block(-9,-4,2,LOG:15)
Block(-8,-4,2,LOG:15)
Block(-7,-4,2,LOG:15)
Block(-2,-4,2,LOG:15)
Block(-1,-4,2,LOG:15)
Block(0,-4,2,LOG:15)
Block(3,-4,2,LOG:15)
Block(4,-4,2,LOG:15)
Block(5,-4,2,LOG:15)
Block(6,-4,2,LOG:15)
Block(-12,-4,3,LOG:15)
Block(-11,-4,3,LOG:15)
Block(-10,-4,3,LOG:15)
Block(-9,-4,3,LOG:15)
Block(-3,-4,3,LOG:15)
Block(-2,-4,3,LOG:15)
Block(-1,-4,3,LOG:15)
Block(4,-4,3,LOG:15)
Block(5,-4,3,LOG:15)
Block(6,-4,3,LOG:15)
Block(7,-4,3,LOG:15)
Block(10,-4,3,LOG:15)
Block(-12,-4,4,LOG:15)
Block(-11,-4,4,LOG:15)
Block(-10,-4,4,LOG:15)
Block(-3,-4,4,LOG:15)
Block(-2,-4,4,LOG:15)
Block(-1,-4,4,LOG:15)
Block(0,-4,4,LOG:15)
Block(5,-4,4,LOG:15)
Block(6,-4,4,LOG:15)
Block(7,-4,4,LOG:15)
Block(8,-4,4,LOG:15)
Block(9,-4,4,LOG:15)
Block(10,-4,4,LOG:15)
Block(-12,-4,5,LOG:15)
Block(-11,-4,5,LOG:15)
Block(-2,-4,5,LOG:15)
Block(-1,-4,5,LOG:15)
Block(0,-4,5,LOG:15)
Block(6,-4,5,LOG:15)
Block(7,-4,5,LOG:15)
Block(8,-4,5,LOG:15)
Block(9,-4,5,LOG:15)
Block(10,-4,5,LOG:15)
Block(-12,-4,6,LOG:15)
Block(-2,-4,6,LOG:15)
Block(-1,-4,6,LOG:15)
Block(0,-4,6,LOG:15)
Block(1,-4,6,LOG:15)
Block(7,-4,6,LOG:15)
Block(8,-4,6,LOG:15)
Block(9,-4,6,LOG:15)
Block(10,-4,6,LOG:15)
Block(11,-4,6,LOG:15)
Block(-1,-4,7,LOG:15)
Block(0,-4,7,LOG:15)
Block(1,-4,7,LOG:15)
Block(9,-4,7,LOG:15)
Block(10,-4,7,LOG:15)
Block(11,-4,7,LOG:15)
Block(-1,-4,8,LOG:15)
Block(0,-4,8,LOG:15)
Block(1,-4,8,LOG:15)
Block(-1,-4,9,LOG:15)
Block(0,-4,9,LOG:15)
Block(1,-4,9,LOG:15)
Block(2,-4,9,LOG:15)
Block(0,-4,10,LOG:15)
Block(1,-4,10,LOG:15)
Block(-8,-3,-14,LOG:15)
Block(-9,-3,-13,LOG:15)
Block(-8,-3,-13,LOG:15)
Block(-7,-3,-13,LOG:15)
Block(8,-3,-13,LOG:15)
Block(9,-3,-13,LOG:15)
Block(-10,-3,-12,LOG:15)
Block(-9,-3,-12,LEAVES:3)
Block(-8,-3,-12,LOG:15)
Block(-7,-3,-12,LOG:15)
Block(-6,-3,-12,LOG:15)
Block(7,-3,-12,LOG:15)
Block(8,-3,-12,LOG:15)
Block(9,-3,-12,LOG:15)
Block(10,-3,-12,LOG:15)
Block(-9,-3,-11,LOG:15)
Block(-8,-3,-11,LEAVES:3)
Block(-7,-3,-11,LOG:15)
Block(-6,-3,-11,LOG:15)
Block(7,-3,-11,LEAVES:3)
Block(8,-3,-11,LOG:15)
Block(9,-3,-11,LEAVES:3)
Block(-7,-3,-10,LOG:15)
Block(-6,-3,-10,LOG:15)
Block(-5,-3,-10,LOG:15)
Block(5,-3,-10,LOG:15)
Block(6,-3,-10,LOG:15)
Block(7,-3,-10,LOG:15)
Block(8,-3,-10,LOG:15)
Block(9,-3,-10,LOG:15)
Block(-7,-3,-9,LOG:15)
Block(-6,-3,-9,LOG:15)
Block(-5,-3,-9,LOG:15)
Block(-4,-3,-9,LOG:15)
Block(4,-3,-9,LOG:15)
Block(5,-3,-9,LOG:15)
Block(7,-3,-9,LOG:15)
Block(8,-3,-9,LOG:15)
Block(-7,-3,-8,LOG:15)
Block(-6,-3,-8,LOG:15)
Block(-5,-3,-8,LOG:15)
Block(-4,-3,-8,LOG:15)
Block(-3,-3,-8,LOG:15)
Block(2,-3,-8,LOG:15)
Block(3,-3,-8,LOG:15)
Block(4,-3,-8,LOG:15)
Block(5,-3,-8,LOG:15)
Block(6,-3,-8,LOG:15)
Block(7,-3,-8,LOG:15)
Block(-7,-3,-7,LOG:15)
Block(-6,-3,-7,LOG:15)
Block(-5,-3,-7,LOG:15)
Block(-4,-3,-7,LOG:15)
Block(-3,-3,-7,LOG:15)
Block(2,-3,-7,LOG:15)
Block(3,-3,-7,LOG:15)
Block(5,-3,-7,LOG:15)
Block(6,-3,-7,LOG:15)
Block(-6,-3,-6,LOG:15)
Block(-5,-3,-6,LOG:15)
Block(-4,-3,-6,LOG:15)
Block(-3,-3,-6,LOG:15)
Block(-2,-3,-6,LOG:15)
Block(1,-3,-6,LOG:15)
Block(2,-3,-6,LOG:15)
Block(3,-3,-6,LOG:15)
Block(4,-3,-6,LOG:15)
Block(-5,-3,-5,LOG:15)
Block(-4,-3,-5,LOG:15)
Block(-3,-3,-5,LOG:15)
Block(-2,-3,-5,LOG:15)
Block(-1,-3,-5,LOG:15)
Block(1,-3,-5,LOG:15)
Block(2,-3,-5,LOG:15)
Block(3,-3,-5,LOG:15)
Block(-6,-3,-4,LOG:15)
Block(-5,-3,-4,LOG:15)
Block(-4,-3,-4,LOG:15)
Block(-3,-3,-4,LOG:15)
Block(-2,-3,-4,LOG:15)
Block(-1,-3,-4,LOG:15)
Block(0,-3,-4,LOG:15)
Block(1,-3,-4,LOG:15)
Block(2,-3,-4,LOG:15)
Block(3,-3,-4,LOG:15)
Block(-5,-3,-3,LOG:15)
Block(-4,-3,-3,LOG:15)
Block(-3,-3,-3,LOG:15)
Block(-2,-3,-3,LOG:15)
Block(-1,-3,-3,LOG:15)
Block(0,-3,-3,LOG:15)
Block(1,-3,-3,LOG:15)
Block(2,-3,-3,LOG:15)
Block(-6,-3,-2,LOG:15)
Block(-5,-3,-2,LOG:15)
Block(-4,-3,-2,LOG:15)
Block(-3,-3,-2,LOG:15)
Block(-2,-3,-2,LOG:15)
Block(-1,-3,-2,LOG:15)
Block(0,-3,-2,LOG:15)
Block(1,-3,-2,LOG:15)
Block(2,-3,-2,LOG:15)
Block(3,-3,-2,LOG:15)
Block(-8,-3,-1,LOG:15)
Block(-7,-3,-1,LOG:15)
Block(-6,-3,-1,LOG:15)
Block(-5,-3,-1,LOG:15)
Block(-4,-3,-1,LOG:15)
Block(-3,-3,-1,LOG:15)
Block(-2,-3,-1,LOG:15)
Block(-1,-3,-1,LOG:15)
Block(0,-3,-1,LOG:15)
Block(1,-3,-1,LOG:15)
Block(2,-3,-1,LOG:15)
Block(3,-3,-1,LOG:15)
Block(-10,-3,0,LOG:15)
Block(-9,-3,0,LOG:15)
Block(-8,-3,0,LOG:15)
Block(-7,-3,0,LOG:15)
Block(-6,-3,0,LOG:15)
Block(-5,-3,0,LOG:15)
Block(-4,-3,0,LOG:15)
Block(-3,-3,0,LOG:15)
Block(-2,-3,0,LOG:15)
Block(-1,-3,0,LOG:15)
Block(0,-3,0,LOG:15)
Block(1,-3,0,LOG:15)
Block(2,-3,0,LOG:15)
Block(3,-3,0,LOG:15)
Block(4,-3,0,LOG:15)
Block(-11,-3,1,LOG:15)
Block(-10,-3,1,LOG:15)
Block(-9,-3,1,LOG:15)
Block(-8,-3,1,LOG:15)
Block(-7,-3,1,LOG:15)
Block(-6,-3,1,LOG:15)
Block(-3,-3,1,LOG:15)
Block(-2,-3,1,LOG:15)
Block(-1,-3,1,LOG:15)
Block(0,-3,1,LOG:15)
Block(1,-3,1,LOG:15)
Block(2,-3,1,LOG:15)
Block(3,-3,1,LOG:15)
Block(4,-3,1,LOG:15)
Block(5,-3,1,LOG:15)
Block(6,-3,1,LOG:15)
Block(7,-3,1,LOG:15)
Block(-11,-3,2,LOG:15)
Block(-10,-3,2,LOG:15)
Block(-9,-3,2,LOG:15)
Block(-8,-3,2,LOG:15)
Block(-7,-3,2,LOG:15)
Block(-3,-3,2,LOG:15)
Block(-2,-3,2,LOG:15)
Block(-1,-3,2,LOG:15)
Block(0,-3,2,LOG:15)
Block(2,-3,2,LOG:15)
Block(3,-3,2,LOG:15)
Block(4,-3,2,LOG:15)
Block(5,-3,2,LOG:15)
Block(6,-3,2,LOG:15)
Block(7,-3,2,LOG:15)
Block(8,-3,2,LOG:15)
Block(-12,-3,3,LOG:15)
Block(-11,-3,3,LOG:15)
Block(-10,-3,3,LOG:15)
Block(-9,-3,3,LOG:15)
Block(-3,-3,3,LOG:15)
Block(-2,-3,3,LOG:15)
Block(-1,-3,3,LOG:15)
Block(0,-3,3,LOG:15)
Block(5,-3,3,LOG:15)
Block(6,-3,3,LOG:15)
Block(7,-3,3,LOG:15)
Block(8,-3,3,LOG:15)
Block(-12,-3,4,LOG:15)
Block(-11,-3,4,LOG:15)
Block(-3,-3,4,LOG:15)
Block(-2,-3,4,LOG:15)
Block(-1,-3,4,LOG:15)
Block(0,-3,4,LOG:15)
Block(6,-3,4,LOG:15)
Block(7,-3,4,LOG:15)
Block(8,-3,4,LOG:15)
Block(9,-3,4,LOG:15)
Block(-11,-3,5,LOG:15)
Block(-2,-3,5,LOG:15)
Block(-1,-3,5,LOG:15)
Block(0,-3,5,LOG:15)
Block(1,-3,5,LOG:15)
Block(7,-3,5,LOG:15)
Block(8,-3,5,LOG:15)
Block(9,-3,5,LOG:15)
Block(10,-3,5,LOG:15)
Block(-2,-3,6,LOG:15)
Block(-1,-3,6,LOG:15)
Block(0,-3,6,LOG:15)
Block(1,-3,6,LOG:15)
Block(7,-3,6,LOG:15)
Block(8,-3,6,LOG:15)
Block(9,-3,6,LOG:15)
Block(10,-3,6,LOG:15)
Block(11,-3,6,LOG:15)
Block(-1,-3,7,LOG:15)
Block(0,-3,7,LOG:15)
Block(1,-3,7,LOG:15)
Block(10,-3,7,LOG:15)
Block(0,-3,8,LOG:15)
Block(1,-3,8,LOG:15)
Block(0,-3,9,LOG:15)
Block(1,-3,9,LOG:15)
Block(-9,-2,-12,LOG:15)
Block(-8,-2,-12,LEAVES:3)
Block(9,-2,-12,LEAVES:3)
Block(-6,-2,-11,LEAVES:3)
Block(-7,-2,-10,LEAVES:3)
Block(-6,-2,-10,LEAVES:3)
Block(-5,-2,-10,LEAVES:3)
Block(6,-2,-10,LOG:15)
Block(7,-2,-10,LEAVES:3)
Block(-7,-2,-9,LEAVES:3)
Block(-6,-2,-9,LOG:15)
Block(-5,-2,-9,LEAVES:3)
Block(3,-2,-9,LOG:15)
Block(4,-2,-9,LOG:15)
Block(5,-2,-9,LOG:15)
Block(7,-2,-9,LOG:15)
Block(-7,-2,-8,LOG:15)
Block(-6,-2,-8,LOG:15)
Block(-5,-2,-8,LOG:15)
Block(-4,-2,-8,LOG:15)
Block(3,-2,-8,LOG:15)
Block(4,-2,-8,LOG:15)
Block(5,-2,-8,LOG:15)
Block(6,-2,-8,LOG:15)
Block(-6,-2,-7,LOG:15)
Block(-5,-2,-7,LOG:15)
Block(-4,-2,-7,LOG:15)
Block(-3,-2,-7,LOG:15)
Block(2,-2,-7,LOG:15)
Block(3,-2,-7,LOG:15)
Block(5,-2,-7,LOG:15)
Block(-5,-2,-6,LOG:15)
Block(-4,-2,-6,LOG:15)
Block(-3,-2,-6,LOG:15)
Block(-2,-2,-6,LOG:15)
Block(1,-2,-6,LOG:15)
Block(2,-2,-6,LOG:15)
Block(3,-2,-6,LOG:15)
Block(4,-2,-6,LOG:15)
Block(-4,-2,-5,LOG:15)
Block(-3,-2,-5,LOG:15)
Block(-2,-2,-5,LOG:15)
Block(-1,-2,-5,LOG:15)
Block(1,-2,-5,LOG:15)
Block(2,-2,-5,LOG:15)
Block(3,-2,-5,LOG:15)
Block(4,-2,-5,LOG:15)
Block(-3,-2,-4,LOG:15)
Block(-2,-2,-4,LOG:15)
Block(-1,-2,-4,LOG:15)
Block(0,-2,-4,LOG:15)
Block(1,-2,-4,LOG:15)
Block(2,-2,-4,LOG:15)
Block(-6,-2,-3,LOG:15)
Block(-5,-2,-3,LOG:15)
Block(-4,-2,-3,LOG:15)
Block(-3,-2,-3,LOG:15)
Block(-2,-2,-3,LOG:15)
Block(-1,-2,-3,LOG:15)
Block(0,-2,-3,LOG:15)
Block(1,-2,-3,LOG:15)
Block(2,-2,-3,LOG:15)
Block(-6,-2,-2,LOG:15)
Block(-5,-2,-2,LOG:15)
Block(-4,-2,-2,LOG:15)
Block(-3,-2,-2,LOG:15)
Block(-2,-2,-2,LOG:15)
Block(-1,-2,-2,LOG:15)
Block(0,-2,-2,LOG:15)
Block(1,-2,-2,LOG:15)
Block(2,-2,-2,LOG:15)
Block(-7,-2,-1,LOG:15)
Block(-6,-2,-1,LOG:15)
Block(-5,-2,-1,LOG:15)
Block(-4,-2,-1,LOG:15)
Block(-3,-2,-1,LOG:15)
Block(-2,-2,-1,LOG:15)
Block(-1,-2,-1,LOG:15)
Block(0,-2,-1,LOG:15)
Block(1,-2,-1,LOG:15)
Block(2,-2,-1,LOG:15)
Block(-9,-2,0,LOG:15)
Block(-8,-2,0,LOG:15)
Block(-7,-2,0,LOG:15)
Block(-6,-2,0,LOG:15)
Block(-5,-2,0,LOG:15)
Block(-4,-2,0,LOG:15)
Block(-3,-2,0,LOG:15)
Block(-2,-2,0,LOG:15)
Block(-1,-2,0,LOG:15)
Block(1,-2,0,LOG:15)
Block(2,-2,0,LOG:15)
Block(3,-2,0,LOG:15)
Block(4,-2,0,LOG:15)
Block(-10,-2,1,LOG:15)
Block(-9,-2,1,LOG:15)
Block(-8,-2,1,LOG:15)
Block(-7,-2,1,LOG:15)
Block(-6,-2,1,LOG:15)
Block(-3,-2,1,LOG:15)
Block(-2,-2,1,LOG:15)
Block(-1,-2,1,LOG:15)
Block(0,-2,1,LOG:15)
Block(2,-2,1,LOG:15)
Block(3,-2,1,LOG:15)
Block(4,-2,1,LOG:15)
Block(5,-2,1,LOG:15)
Block(6,-2,1,LOG:15)
Block(-11,-2,2,LOG:15)
Block(-10,-2,2,LOG:15)
Block(-9,-2,2,LOG:15)
Block(-8,-2,2,LOG:15)
Block(-7,-2,2,LOG:15)
Block(-6,-2,2,LOG:15)
Block(-3,-2,2,LOG:15)
Block(-2,-2,2,LOG:15)
Block(-1,-2,2,LOG:15)
Block(2,-2,2,LOG:15)
Block(3,-2,2,LOG:15)
Block(4,-2,2,LOG:15)
Block(5,-2,2,LOG:15)
Block(6,-2,2,LOG:15)
Block(7,-2,2,LOG:15)
Block(-11,-2,3,LEAVES:3)
Block(-10,-2,3,LOG:15)
Block(-9,-2,3,LEAVES:3)
Block(-3,-2,3,LOG:15)
Block(-2,-2,3,LOG:15)
Block(-1,-2,3,LOG:15)
Block(0,-2,3,LOG:15)
Block(5,-2,3,LOG:15)
Block(6,-2,3,LOG:15)
Block(7,-2,3,LOG:15)
Block(8,-2,3,LOG:15)
Block(-2,-2,4,LOG:15)
Block(-1,-2,4,LOG:15)
Block(0,-2,4,LOG:15)
Block(5,-2,4,LOG:15)
Block(6,-2,4,LOG:15)
Block(7,-2,4,LOG:15)
Block(8,-2,4,LOG:15)
Block(9,-2,4,LEAVES:3)
Block(-2,-2,5,LOG:15)
Block(-1,-2,5,LOG:15)
Block(0,-2,5,LOG:15)
Block(7,-2,5,LOG:15)
Block(8,-2,5,LOG:15)
Block(9,-2,5,LOG:15)
Block(10,-2,5,LEAVES:3)
Block(-1,-2,6,LOG:15)
Block(0,-2,6,LOG:15)
Block(1,-2,6,LOG:15)
Block(8,-2,6,LOG:15)
Block(9,-2,6,LEAVES:3)
Block(0,-2,7,LOG:15)
Block(-6,-1,-10,LEAVES:3)
Block(-6,-1,-9,LEAVES:3)
Block(4,-1,-9,LOG:15)
Block(5,-1,-9,LEAVES:3)
Block(-5,-1,-8,LOG:15)
Block(-4,-1,-8,LOG:15)
Block(-3,-1,-8,LOG:15)
Block(3,-1,-8,LOG:15)
Block(4,-1,-8,LOG:15)
Block(5,-1,-8,LOG:15)
Block(6,-1,-8,LEAVES:3)
Block(-6,-1,-7,LEAVES:3)
Block(-5,-1,-7,LOG:15)
Block(-4,-1,-7,LOG:15)
Block(-3,-1,-7,LOG:15)
Block(-2,-1,-7,LOG:15)
Block(1,-1,-7,LOG:15)
Block(2,-1,-7,LOG:15)
Block(3,-1,-7,LOG:15)
Block(5,-1,-7,LEAVES:3)
Block(-5,-1,-6,LOG:15)
Block(-4,-1,-6,LOG:15)
Block(-3,-1,-6,LOG:15)
Block(-2,-1,-6,LOG:15)
Block(-1,-1,-6,LOG:15)
Block(1,-1,-6,LOG:15)
Block(2,-1,-6,LOG:15)
Block(3,-1,-6,LOG:15)
Block(4,-1,-6,LOG:15)
Block(-4,-1,-5,LOG:15)
Block(-3,-1,-5,LOG:15)
Block(-2,-1,-5,LOG:15)
Block(-1,-1,-5,LOG:15)
Block(0,-1,-5,LOG:15)
Block(1,-1,-5,LOG:15)
Block(2,-1,-5,LOG:15)
Block(3,-1,-5,LOG:15)
Block(-3,-1,-4,LOG:15)
Block(-2,-1,-4,LOG:15)
Block(-1,-1,-4,LOG:15)
Block(0,-1,-4,LOG:15)
Block(1,-1,-4,LOG:15)
Block(2,-1,-4,LOG:15)
Block(-5,-1,-3,LOG:15)
Block(-4,-1,-3,LOG:15)
Block(-3,-1,-3,LOG:15)
Block(-2,-1,-3,LOG:15)
Block(-1,-1,-3,LOG:15)
Block(0,-1,-3,LOG:15)
Block(1,-1,-3,LOG:15)
Block(2,-1,-3,LOG:15)
Block(-6,-1,-2,LOG:15)
Block(-5,-1,-2,LOG:15)
Block(-4,-1,-2,LOG:15)
Block(-3,-1,-2,LOG:15)
Block(-2,-1,-2,LOG:15)
Block(-1,-1,-2,LOG:15)
Block(0,-1,-2,LOG:15)
Block(1,-1,-2,LOG:15)
Block(2,-1,-2,LOG:15)
Block(-7,-1,-1,LEAVES:3)
Block(-6,-1,-1,LOG:15)
Block(-5,-1,-1,LOG:15)
Block(-4,-1,-1,LOG:15)
Block(-3,-1,-1,LOG:15)
Block(-2,-1,-1,LOG:15)
Block(-1,-1,-1,LOG:15)
Block(0,-1,-1,LOG:15)
Block(1,-1,-1,LOG:15)
Block(2,-1,-1,LOG:15)
Block(-8,-1,0,LEAVES:3)
Block(-7,-1,0,LOG:15)
Block(-6,-1,0,LEAVES:3)
Block(-5,-1,0,LOG:15)
Block(-4,-1,0,LOG:15)
Block(-3,-1,0,LOG:15)
Block(-2,-1,0,LOG:15)
Block(-1,-1,0,LOG:15)
Block(0,-1,0,LOG:15)
Block(1,-1,0,LOG:15)
Block(2,-1,0,LOG:15)
Block(3,-1,0,LOG:15)
Block(4,-1,0,LOG:15)
Block(5,-1,0,LOG:15)
Block(-9,-1,1,LEAVES:3)
Block(-8,-1,1,LOG:15)
Block(-7,-1,1,LOG:15)
Block(-6,-1,1,LOG:15)
Block(-4,-1,1,LOG:15)
Block(-3,-1,1,LOG:15)
Block(-2,-1,1,LOG:15)
Block(-1,-1,1,LOG:15)
Block(2,-1,1,LOG:15)
Block(3,-1,1,LOG:15)
Block(4,-1,1,LOG:15)
Block(5,-1,1,LOG:15)
Block(6,-1,1,LOG:15)
Block(-9,-1,2,LEAVES:3)
Block(-8,-1,2,LEAVES:3)
Block(-7,-1,2,LOG:15)
Block(-3,-1,2,LOG:15)
Block(-2,-1,2,LOG:15)
Block(-1,-1,2,LOG:15)
Block(3,-1,2,LOG:15)
Block(4,-1,2,LOG:15)
Block(5,-1,2,LOG:15)
Block(6,-1,2,LOG:15)
Block(-2,-1,3,LOG:15)
Block(-1,-1,3,LOG:15)
Block(4,-1,3,LOG:15)
Block(5,-1,3,LOG:15)
Block(6,-1,3,LOG:15)
Block(7,-1,3,LOG:15)
Block(-3,-1,4,LEAVES:3)
Block(-2,-1,4,LOG:15)
Block(-1,-1,4,LOG:15)
Block(0,-1,4,LOG:15)
Block(6,-1,4,LOG:15)
Block(-2,-1,5,LEAVES:3)
Block(-1,-1,5,LOG:15)
Block(8,-1,5,LEAVES:3)
Block(9,-1,5,LEAVES:3)
Block(0,-1,6,LEAVES:3)
Block(-4,0,-8,LOG:15)
Block(5,0,-8,LEAVES:3)
Block(-5,0,-7,LOG:15)
Block(-4,0,-7,LOG:15)
Block(-3,0,-7,LOG:15)
Block(-2,0,-7,LOG:15)
Block(2,0,-7,LOG:15)
Block(3,0,-7,LEAVES:3)
Block(-4,0,-6,LOG:15)
Block(-3,0,-6,LOG:15)
Block(-2,0,-6,LOG:15)
Block(1,0,-6,LOG:15)
Block(2,0,-6,LOG:15)
Block(3,0,-6,LOG:15)
Block(3,0,-5,LOG:15)
Block(-1,0,-4,LOG:15)
Block(0,0,-4,LOG:15)
Block(1,0,-4,LOG:15)
Block(3,0,-4,LOG:15)
Block(-3,0,-3,LOG:15)
Block(-1,0,-3,LOG:15)
Block(0,0,-3,LOG:15)
Block(1,0,-3,LOG:15)
Block(-4,0,-2,LOG:15)
Block(-3,0,-2,LOG:15)
Block(-6,0,-1,LEAVES:3)
Block(0,0,-1,LOG:15)
Block(1,0,-1,LOG:15)
Block(-4,0,0,LOG:15)
Block(-3,0,0,LOG:15)
Block(-2,0,0,LOG:15)
Block(0,0,0,LOG:15)
Block(1,0,0,LOG:15)
Block(3,0,0,LOG:15)
Block(4,0,0,LOG:15)
Block(-8,0,1,LEAVES:3)
Block(-4,0,1,LOG:15)
Block(-3,0,1,LOG:15)
Block(-2,0,1,LOG:15)
Block(3,0,1,LOG:15)
Block(4,0,1,LOG:15)
Block(5,0,1,LOG:15)
Block(4,0,2,LOG:15)
Block(5,0,2,LOG:15)
Block(-3,0,3,LOG:15)
Block(-2,0,3,LOG:15)
Block(-1,0,3,LOG:15)
Block(5,0,3,LOG:15)
Block(-2,0,4,LEAVES:3)
Block(-4,1,-7,LEAVES:3)
Block(-3,1,-7,LOG:15)
Block(2,1,-7,LEAVES:3)
Block(-5,1,-6,LEAVES:3)
Block(-4,1,-6,LOG:15)
Block(-3,1,-6,LOG:15)
Block(-2,1,-6,LOG:15)
Block(-1,1,-6,LOG:15)
Block(1,1,-6,LEAVES:3)
Block(2,1,-6,LOG:15)
Block(3,1,-6,LEAVES:3)
Block(-4,1,-5,LEAVES:3)
Block(-3,1,-5,LOG:15)
Block(-2,1,-5,LOG:15)
Block(-1,1,-5,LOG:15)
Block(0,1,-5,LOG:15)
Block(1,1,-5,LOG:15)
Block(2,1,-5,LOG:15)
Block(3,1,-5,LOG:15)
Block(-3,1,-4,LOG:15)
Block(-2,1,-4,LOG:15)
Block(-1,1,-4,LOG:15)
Block(0,1,-4,LOG:15)
Block(1,1,-4,LOG:15)
Block(2,1,-4,LOG:15)
Block(-3,1,-3,LOG:15)
Block(-2,1,-3,LOG:15)
Block(-1,1,-3,LOG:15)
Block(0,1,-3,LOG:15)
Block(1,1,-3,LOG:15)
Block(2,1,-3,LOG:15)
Block(-5,1,-2,LOG:15)
Block(-4,1,-2,LOG:15)
Block(-3,1,-2,LOG:15)
Block(-2,1,-2,LOG:15)
Block(-1,1,-2,LOG:15)
Block(0,1,-2,LOG:15)
Block(1,1,-2,LOG:15)
Block(2,1,-2,LOG:15)
Block(-5,1,-1,LOG:15)
Block(-4,1,-1,LOG:15)
Block(-3,1,-1,LOG:15)
Block(-2,1,-1,LOG:15)
Block(-1,1,-1,LOG:15)
Block(0,1,-1,LOG:15)
Block(1,1,-1,LOG:15)
Block(2,1,-1,LOG:15)
Block(3,1,-1,LOG:15)
Block(-5,1,0,LOG:15)
Block(-4,1,0,LOG:15)
Block(-3,1,0,LOG:15)
Block(-2,1,0,LOG:15)
Block(-1,1,0,LOG:15)
Block(0,1,0,LOG:15)
Block(1,1,0,LOG:15)
Block(2,1,0,LOG:15)
Block(3,1,0,LOG:15)
Block(-4,1,1,LOG:15)
Block(-3,1,1,LOG:15)
Block(-2,1,1,LOG:15)
Block(-1,1,1,LOG:15)
Block(1,1,1,LOG:15)
Block(2,1,1,LOG:15)
Block(3,1,1,LOG:15)
Block(4,1,1,LEAVES:3)
Block(-3,1,2,LOG:15)
Block(-2,1,2,LOG:15)
Block(-1,1,2,LOG:15)
Block(3,1,2,LEAVES:3)
Block(5,1,2,LEAVES:3)
Block(-2,1,3,LOG:15)
Block(-3,2,-7,LEAVES:3)
Block(-4,2,-6,LEAVES:3)
Block(-3,2,-6,LEAVES:3)
Block(-2,2,-6,LOG:15)
Block(-1,2,-6,LOG:15)
Block(0,2,-6,LOG:15)
Block(2,2,-6,LEAVES:3)
Block(-4,2,-5,LEAVES:3)
Block(-3,2,-5,LOG:15)
Block(-2,2,-5,LOG:15)
Block(-1,2,-5,LOG:15)
Block(0,2,-5,LOG:15)
Block(1,2,-5,LOG:15)
Block(-3,2,-4,LOG:15)
Block(-2,2,-4,LOG:15)
Block(-1,2,-4,LOG:15)
Block(0,2,-4,LOG:15)
Block(1,2,-4,LOG:15)
Block(2,2,-4,LOG:15)
Block(-3,2,-3,LOG:15)
Block(-2,2,-3,LOG:15)
Block(-1,2,-3,LOG:15)
Block(0,2,-3,LOG:15)
Block(1,2,-3,LOG:15)
Block(2,2,-3,LOG:15)
Block(-4,2,-2,LOG:15)
Block(-3,2,-2,LOG:15)
Block(-2,2,-2,LOG:15)
Block(-1,2,-2,LOG:15)
Block(0,2,-2,LOG:15)
Block(1,2,-2,LOG:15)
Block(-5,2,-1,LOG:15)
Block(-4,2,-1,LOG:15)
Block(-3,2,-1,LOG:15)
Block(-2,2,-1,LOG:15)
Block(-1,2,-1,LOG:15)
Block(0,2,-1,LOG:15)
Block(1,2,-1,LOG:15)
Block(2,2,-1,LOG:15)
Block(-4,2,0,LOG:15)
Block(-3,2,0,LOG:15)
Block(-2,2,0,LOG:15)
Block(-1,2,0,LOG:15)
Block(0,2,0,LOG:15)
Block(1,2,0,LOG:15)
Block(2,2,0,LOG:15)
Block(3,2,0,LOG:15)
Block(-3,2,1,LOG:15)
Block(-2,2,1,LOG:15)
Block(-1,2,1,LOG:15)
Block(2,2,1,LOG:15)
Block(3,2,1,LEAVES:3)
Block(-2,2,2,LOG:15)
Block(-3,3,-6,LEAVES:3)
Block(-1,3,-6,LOG:15)
Block(-3,3,-5,LEAVES:3)
Block(-2,3,-5,LOG:15)
Block(-1,3,-5,LOG:15)
Block(0,3,-5,LOG:15)
Block(1,3,-5,LOG:15)
Block(2,3,-5,LOG:15)
Block(-3,3,-4,LOG:15)
Block(-2,3,-4,LOG:15)
Block(-1,3,-4,LOG:15)
Block(0,3,-4,LOG:15)
Block(1,3,-4,LOG:15)
Block(2,3,-4,LOG:15)
Block(-3,3,-3,LOG:15)
Block(-2,3,-3,LOG:15)
Block(-1,3,-3,LOG:15)
Block(0,3,-3,LOG:15)
Block(1,3,-3,LOG:15)
Block(2,3,-3,LOG:15)
Block(-3,3,-2,LOG:15)
Block(-2,3,-2,LOG:15)
Block(-1,3,-2,LOG:15)
Block(0,3,-2,LOG:15)
Block(1,3,-2,LOG:15)
Block(2,3,-2,LOG:15)
Block(-3,3,-1,LOG:15)
Block(-2,3,-1,LOG:15)
Block(-1,3,-1,LOG:15)
Block(0,3,-1,LOG:15)
Block(1,3,-1,LOG:15)
Block(2,3,-1,LOG:15)
Block(-2,3,0,LOG:15)
Block(-1,3,0,LOG:15)
Block(0,3,0,LOG:15)
Block(1,3,0,LOG:15)
Block(2,3,0,LEAVES:3)
Block(3,3,0,LEAVES:3)
Block(-1,4,-6,LEAVES:3)
Block(-2,4,-5,LEAVES:3)
Block(-1,4,-5,LOG:15)
Block(0,4,-5,LEAVES:3)
Block(1,4,-5,LOG:15)
Block(-2,4,-4,LOG:15)
Block(-1,4,-4,LOG:15)
Block(0,4,-4,LOG:15)
Block(1,4,-4,LOG:15)
Block(2,4,-4,LOG:15)
Block(-2,4,-3,LOG:15)
Block(-1,4,-3,LOG:15)
Block(0,4,-3,LOG:15)
Block(1,4,-3,LOG:15)
Block(2,4,-3,LOG:15)
Block(-2,4,-2,LOG:15)
Block(-1,4,-2,LOG:15)
Block(0,4,-2,LOG:15)
Block(1,4,-2,LOG:15)
Block(2,4,-2,LOG:15)
Block(-2,4,-1,LOG:15)
Block(-1,4,-1,LOG:15)
Block(0,4,-1,LOG:15)
Block(1,4,-1,LOG:15)
Block(2,4,-1,LOG:15)
Block(3,4,-1,LEAVES:3)
Block(-1,4,0,LOG:15)
Block(0,4,0,LOG:15)
Block(1,4,0,LOG:15)
Block(2,4,0,LEAVES:3)
Block(3,4,0,LEAVES:3)
Block(4,4,0,LEAVES:3)
Block(2,4,1,LEAVES:3)
Block(3,4,1,LEAVES:3)
Block(-2,5,-5,LOG:15)
Block(-1,5,-5,LOG:15)
Block(0,5,-5,LOG:15)
Block(-2,5,-4,LOG:15)
Block(-1,5,-4,LOG:15)
Block(0,5,-4,LOG:15)
Block(1,5,-4,LOG:15)
Block(2,5,-4,LOG:15)
Block(-2,5,-3,LOG:15)
Block(-1,5,-3,LOG:15)
Block(0,5,-3,LOG:15)
Block(1,5,-3,LOG:15)
Block(2,5,-3,LOG:15)
Block(3,5,-3,LOG:15)
Block(-2,5,-2,LOG:15)
Block(-1,5,-2,LOG:15)
Block(0,5,-2,LOG:15)
Block(1,5,-2,LOG:15)
Block(2,5,-2,LOG:15)
Block(3,5,-2,LOG:15)
Block(4,5,-2,LOG:15)
Block(-2,5,-1,LOG:15)
Block(-1,5,-1,LOG:15)
Block(0,5,-1,LOG:15)
Block(1,5,-1,LOG:15)
Block(2,5,-1,LOG:15)
Block(3,5,-1,LOG:15)
Block(4,5,-1,LOG:15)
Block(-1,5,0,LOG:15)
Block(0,5,0,LOG:15)
Block(1,5,0,LOG:15)
Block(2,5,0,LOG:15)
Block(3,5,0,LOG:15)
Block(4,5,0,LOG:15)
Block(5,5,0,LEAVES:3)
Block(4,5,1,LEAVES:3)
Block(-1,6,-6,LEAVES:3)
Block(-2,6,-5,LEAVES:3)
Block(-1,6,-5,LOG:15)
Block(0,6,-5,LEAVES:3)
Block(-2,6,-4,LOG:15)
Block(-1,6,-4,LOG:15)
Block(0,6,-4,LOG:15)
Block(1,6,-4,LOG:15)
Block(2,6,-4,LOG:15)
Block(-1,6,-3,LOG:15)
Block(0,6,-3,LOG:15)
Block(1,6,-3,LOG:15)
Block(2,6,-3,LOG:15)
Block(3,6,-3,LOG:15)
Block(4,6,-3,LOG:15)
Block(-1,6,-2,LOG:15)
Block(0,6,-2,LOG:15)
Block(1,6,-2,LOG:15)
Block(2,6,-2,LOG:15)
Block(3,6,-2,LOG:15)
Block(4,6,-2,LOG:15)
Block(5,6,-2,LOG:15)
Block(-1,6,-1,LOG:15)
Block(0,6,-1,LOG:15)
Block(1,6,-1,LOG:15)
Block(2,6,-1,LOG:15)
Block(3,6,-1,LOG:15)
Block(4,6,-1,LOG:15)
Block(5,6,-1,LOG:15)
Block(0,6,0,LOG:15)
Block(1,6,0,LOG:15)
Block(2,6,0,LOG:15)
Block(3,6,0,LOG:15)
Block(4,6,0,LOG:15)
Block(5,6,0,LOG:15)
Block(6,6,0,LEAVES:3)
Block(2,6,1,LOG:15)
Block(3,6,1,LOG:15)
Block(4,6,1,LOG:15)
Block(5,6,1,LEAVES:3)
Block(-1,7,-5,LEAVES:3)
Block(1,7,-5,LEAVES:3)
Block(0,7,-4,LOG:15)
Block(1,7,-4,LOG:15)
Block(2,7,-4,LOG:15)
Block(-1,7,-3,LOG:15)
Block(0,7,-3,LOG:15)
Block(1,7,-3,LOG:15)
Block(2,7,-3,LOG:15)
Block(3,7,-3,LOG:15)
Block(4,7,-3,LOG:15)
Block(-1,7,-2,LOG:15)
Block(0,7,-2,LOG:15)
Block(1,7,-2,LOG:15)
Block(2,7,-2,LOG:15)
Block(3,7,-2,LOG:15)
Block(4,7,-2,LOG:15)
Block(5,7,-2,LOG:15)
Block(-1,7,-1,LOG:15)
Block(0,7,-1,LOG:15)
Block(1,7,-1,LOG:15)
Block(2,7,-1,LOG:15)
Block(3,7,-1,LOG:15)
Block(4,7,-1,LOG:15)
Block(5,7,-1,LOG:15)
Block(0,7,0,LOG:15)
Block(1,7,0,LOG:15)
Block(2,7,0,LOG:15)
Block(3,7,0,LOG:15)
Block(4,7,0,LOG:15)
Block(5,7,0,LOG:15)
Block(6,7,0,LEAVES:3)
Block(2,7,1,LOG:15)
Block(3,7,1,LOG:15)
Block(4,7,1,LOG:15)
Block(5,7,1,LEAVES:3)
Block(1,8,-4,LEAVES:3)
Block(0,8,-3,LOG:15)
Block(1,8,-3,LOG:15)
Block(2,8,-3,LOG:15)
Block(3,8,-3,LOG:15)
Block(4,8,-3,LOG:15)
Block(0,8,-2,LOG:15)
Block(1,8,-2,LOG:15)
Block(2,8,-2,LOG:15)
Block(3,8,-2,LOG:15)
Block(4,8,-2,LOG:15)
Block(5,8,-2,LOG:15)
Block(0,8,-1,LOG:15)
Block(1,8,-1,LOG:15)
Block(2,8,-1,LOG:15)
Block(3,8,-1,LOG:15)
Block(4,8,-1,LOG:15)
Block(5,8,-1,LOG:15)
Block(1,8,0,LOG:15)
Block(2,8,0,LOG:15)
Block(3,8,0,LOG:15)
Block(4,8,0,LOG:15)
Block(5,8,0,LOG:15)
Block(1,8,1,LOG:15)
Block(2,8,1,LOG:15)
Block(3,8,1,LOG:15)
Block(4,8,1,LOG:15)
Block(5,8,1,LOG:15)
Block(6,8,1,LEAVES:3)
Block(2,8,2,LOG:15)
Block(3,8,2,LOG:15)
Block(4,8,2,LOG:15)
Block(5,8,2,LEAVES:3)
Block(2,9,-3,LEAVES:3)
Block(1,9,-2,LEAVES:3)
Block(2,9,-2,LOG:15)
Block(3,9,-2,LOG:15)
Block(4,9,-2,LOG:15)
Block(1,9,-1,LOG:15)
Block(2,9,-1,LOG:15)
Block(3,9,-1,LOG:15)
Block(4,9,-1,LOG:15)
Block(5,9,-1,LOG:15)
Block(1,9,0,LOG:15)
Block(2,9,0,LOG:15)
Block(3,9,0,LOG:15)
Block(4,9,0,LOG:15)
Block(5,9,0,LOG:15)
Block(1,9,1,LOG:15)
Block(2,9,1,LOG:15)
Block(3,9,1,LOG:15)
Block(4,9,1,LOG:15)
Block(5,9,1,LOG:15)
Block(1,9,2,LOG:15)
Block(2,9,2,LOG:15)
Block(3,9,2,LOG:15)
Block(4,9,2,LOG:15)
Block(5,9,2,LEAVES:3)
Block(4,9,3,LEAVES:3)
Block(3,10,-3,LEAVES:3)
Block(2,10,-2,LOG:15)
Block(3,10,-2,LOG:15)
Block(4,10,-2,LOG:15)
Block(1,10,-1,LOG:15)
Block(2,10,-1,LOG:15)
Block(3,10,-1,LOG:15)
Block(4,10,-1,LOG:15)
Block(5,10,-1,LOG:15)
Block(0,10,0,LOG:15)
Block(1,10,0,LOG:15)
Block(2,10,0,LOG:15)
Block(3,10,0,LOG:15)
Block(4,10,0,LOG:15)
Block(5,10,0,LOG:15)
Block(-2,10,1,LEAVES:3)
Block(-1,10,1,LOG:15)
Block(0,10,1,LOG:15)
Block(1,10,1,LOG:15)
Block(2,10,1,LOG:15)
Block(3,10,1,LOG:15)
Block(4,10,1,LOG:15)
Block(5,10,1,LOG:15)
Block(-1,10,2,LOG:15)
Block(0,10,2,LOG:15)
Block(1,10,2,LOG:15)
Block(2,10,2,LOG:15)
Block(3,10,2,LOG:15)
Block(4,10,2,LOG:15)
Block(-1,10,3,LOG:15)
Block(0,10,3,LOG:15)
Block(1,10,3,LOG:15)
Block(2,10,3,LOG:15)
Block(3,10,3,LOG:15)
Block(4,10,3,LEAVES:3)
Block(1,10,4,LOG:15)
Block(0,10,5,LEAVES:3)
Block(1,10,5,LOG:15)
Block(-3,10,7,LEAVES:3)
Block(1,10,9,LEAVES:3)
Block(3,11,-2,LEAVES:3)
Block(1,11,-1,LOG:15)
Block(2,11,-1,LOG:15)
Block(3,11,-1,LOG:15)
Block(4,11,-1,LOG:15)
Block(-2,11,0,LEAVES:3)
Block(-1,11,0,LOG:15)
Block(0,11,0,LOG:15)
Block(1,11,0,LOG:15)
Block(2,11,0,LOG:15)
Block(3,11,0,LOG:15)
Block(4,11,0,LOG:15)
Block(-3,11,1,LEAVES:3)
Block(-2,11,1,LOG:15)
Block(-1,11,1,LOG:15)
Block(0,11,1,LOG:15)
Block(1,11,1,LOG:15)
Block(2,11,1,LOG:15)
Block(3,11,1,LOG:15)
Block(4,11,1,LOG:15)
Block(-2,11,2,LOG:15)
Block(-1,11,2,LOG:15)
Block(0,11,2,LOG:15)
Block(1,11,2,LOG:15)
Block(2,11,2,LOG:15)
Block(3,11,2,LOG:15)
Block(4,11,2,LOG:15)
Block(-2,11,3,LOG:15)
Block(-1,11,3,LOG:15)
Block(0,11,3,LOG:15)
Block(1,11,3,LOG:15)
Block(2,11,3,LOG:15)
Block(3,11,3,LOG:15)
Block(4,11,3,LEAVES:3)
Block(-1,11,4,LOG:15)
Block(0,11,4,LOG:15)
Block(1,11,4,LOG:15)
Block(2,11,4,LOG:15)
Block(3,11,4,LEAVES:3)
Block(4,11,4,LEAVES:3)
Block(-1,11,5,LEAVES:3)
Block(0,11,5,LOG:15)
Block(1,11,5,LOG:15)
Block(2,11,5,LOG:15)
Block(3,11,5,LEAVES:3)
Block(0,11,6,LEAVES:3)
Block(1,11,6,LOG:15)
Block(-3,11,7,LEAVES:3)
Block(1,11,9,LEAVES:3)
Block(4,11,9,LEAVES:3)
Block(7,11,9,LEAVES:3)
Block(3,12,-2,LEAVES:3)
Block(1,12,-1,LOG:15)
Block(2,12,-1,LOG:15)
Block(3,12,-1,LOG:15)
Block(4,12,-1,LEAVES:3)
Block(-1,12,0,LOG:15)
Block(0,12,0,LOG:15)
Block(1,12,0,LOG:15)
Block(2,12,0,LOG:15)
Block(3,12,0,LOG:15)
Block(4,12,0,LOG:15)
Block(-2,12,1,LOG:15)
Block(-1,12,1,LOG:15)
Block(0,12,1,LOG:15)
Block(1,12,1,LOG:15)
Block(2,12,1,LOG:15)
Block(3,12,1,LOG:15)
Block(4,12,1,LOG:15)
Block(-2,12,2,LOG:15)
Block(-1,12,2,LOG:15)
Block(0,12,2,LOG:15)
Block(1,12,2,LOG:15)
Block(2,12,2,LOG:15)
Block(3,12,2,LOG:15)
Block(4,12,2,LOG:15)
Block(-2,12,3,LOG:15)
Block(-1,12,3,LOG:15)
Block(0,12,3,LOG:15)
Block(1,12,3,LOG:15)
Block(2,12,3,LOG:15)
Block(3,12,3,LOG:15)
Block(-2,12,4,LEAVES:3)
Block(-1,12,4,LOG:15)
Block(0,12,4,LOG:15)
Block(1,12,4,LOG:15)
Block(0,12,5,LOG:15)
Block(1,12,5,LOG:15)
Block(2,12,5,LOG:15)
Block(0,12,6,LOG:15)
Block(1,12,6,LOG:15)
Block(2,12,6,LOG:15)
Block(3,12,6,LOG:15)
Block(4,12,6,LEAVES:3)
Block(-3,12,7,LEAVES:3)
Block(1,12,7,LOG:15)
Block(3,12,7,LEAVES:3)
Block(1,12,8,LEAVES:3)
Block(1,12,9,LEAVES:3)
Block(4,12,9,LEAVES:3)
Block(7,12,9,LEAVES:3)
Block(3,13,-1,LEAVES:3)
Block(-2,13,0,LOG:15)
Block(-1,13,0,LOG:15)
Block(0,13,0,LOG:15)
Block(1,13,0,LOG:15)
Block(2,13,0,LOG:15)
Block(3,13,0,LOG:15)
Block(4,13,0,LEAVES:3)
Block(-3,13,1,LOG:15)
Block(-2,13,1,LOG:15)
Block(-1,13,1,LOG:15)
Block(0,13,1,LOG:15)
Block(1,13,1,LOG:15)
Block(2,13,1,LOG:15)
Block(3,13,1,LOG:15)
Block(-3,13,2,LOG:15)
Block(-2,13,2,LOG:15)
Block(-1,13,2,LOG:15)
Block(0,13,2,LOG:15)
Block(1,13,2,LOG:15)
Block(2,13,2,LOG:15)
Block(3,13,2,LOG:15)
Block(-3,13,3,LOG:15)
Block(-2,13,3,LOG:15)
Block(-1,13,3,LOG:15)
Block(0,13,3,LOG:15)
Block(1,13,3,LOG:15)
Block(2,13,3,LOG:15)
Block(-3,13,4,LEAVES:3)
Block(-2,13,4,LOG:15)
Block(-1,13,4,LOG:15)
Block(0,13,4,LOG:15)
Block(1,13,4,LOG:15)
Block(-2,13,5,LEAVES:3)
Block(1,13,5,LOG:15)
Block(0,13,6,LOG:15)
Block(1,13,6,LOG:15)
Block(2,13,6,LOG:15)
Block(3,13,6,LOG:15)
Block(4,13,6,LOG:15)
Block(5,13,6,LEAVES:3)
Block(-3,13,7,LEAVES:3)
Block(-1,13,7,LOG:15)
Block(0,13,7,LOG:15)
Block(1,13,7,LOG:15)
Block(2,13,7,LOG:15)
Block(3,13,7,LOG:15)
Block(4,13,7,LOG:15)
Block(0,13,8,LEAVES:3)
Block(1,13,8,LOG:15)
Block(3,13,8,LEAVES:3)
Block(1,13,9,LEAVES:3)
Block(4,13,9,LEAVES:3)
Block(7,13,9,LEAVES:3)
Block(-6,13,10,LEAVES:3)
Block(-1,13,12,LEAVES:3)
Block(-6,14,-3,LEAVES:3)
Block(0,14,-1,LEAVES:3)
Block(-3,14,0,LOG:15)
Block(-2,14,0,LOG:15)
Block(-1,14,0,LOG:15)
Block(0,14,0,LOG:15)
Block(1,14,0,LEAVES:3)
Block(3,14,0,LEAVES:3)
Block(-3,14,1,LOG:15)
Block(-2,14,1,LOG:15)
Block(-1,14,1,LOG:15)
Block(0,14,1,LOG:15)
Block(1,14,1,LOG:15)
Block(-6,14,2,LEAVES:3)
Block(-3,14,2,LOG:15)
Block(-2,14,2,LOG:15)
Block(-1,14,2,LOG:15)
Block(0,14,2,LOG:15)
Block(1,14,2,LOG:15)
Block(-3,14,3,LOG:15)
Block(-2,14,3,LOG:15)
Block(-1,14,3,LOG:15)
Block(0,14,3,LOG:15)
Block(1,14,3,LOG:15)
Block(-2,14,4,LOG:15)
Block(-1,14,4,LOG:15)
Block(0,14,4,LOG:15)
Block(-1,14,5,LEAVES:3)
Block(1,14,6,LOG:15)
Block(5,14,6,LEAVES:3)
Block(-3,14,7,LEAVES:3)
Block(-2,14,7,LOG:15)
Block(-1,14,7,LOG:15)
Block(0,14,7,LOG:15)
Block(1,14,7,LOG:15)
Block(2,14,7,LOG:15)
Block(4,14,7,LOG:15)
Block(5,14,7,LOG:15)
Block(-2,14,8,LOG:15)
Block(-1,14,8,LEAVES:3)
Block(0,14,8,LOG:15)
Block(1,14,8,LOG:15)
Block(2,14,8,LOG:15)
Block(4,14,8,LOG:15)
Block(5,14,8,LOG:15)
Block(0,14,9,LEAVES:3)
Block(1,14,9,LOG:15)
Block(4,14,9,LEAVES:3)
Block(5,14,9,LEAVES:3)
Block(6,14,9,LEAVES:3)
Block(7,14,9,LEAVES:3)
Block(-6,14,10,LEAVES:3)
Block(0,14,10,LEAVES:3)
Block(6,14,10,LEAVES:3)
Block(-1,14,12,LEAVES:3)
Block(-6,15,-3,LEAVES:3)
Block(-3,15,-2,LOG:15)
Block(-2,15,-2,LOG:15)
Block(-1,15,-2,LOG:15)
Block(-3,15,-1,LOG:15)
Block(-2,15,-1,LOG:15)
Block(-1,15,-1,LOG:15)
Block(-4,15,0,LOG:15)
Block(-3,15,0,LOG:15)
Block(-2,15,0,LOG:15)
Block(-1,15,0,LOG:15)
Block(0,15,0,LOG:15)
Block(-4,15,1,LOG:15)
Block(-3,15,1,LOG:15)
Block(-2,15,1,LOG:15)
Block(-1,15,1,LOG:15)
Block(0,15,1,LOG:15)
Block(1,15,1,LOG:15)
Block(-6,15,2,LEAVES:3)
Block(-4,15,2,LOG:15)
Block(-3,15,2,LOG:15)
Block(-2,15,2,LOG:15)
Block(-1,15,2,LOG:15)
Block(0,15,2,LOG:15)
Block(1,15,2,LOG:15)
Block(-3,15,3,LOG:15)
Block(-2,15,3,LOG:15)
Block(-1,15,3,LOG:15)
Block(0,15,3,LOG:15)
Block(1,15,3,LOG:15)
Block(-2,15,4,LOG:15)
Block(-1,15,4,LOG:15)
Block(0,15,4,LOG:15)
Block(-2,15,5,LEAVES:3)
Block(-1,15,5,LEAVES:3)
Block(0,15,5,LEAVES:3)
Block(5,15,6,LEAVES:3)
Block(1,15,7,LOG:15)
Block(-3,15,8,LOG:15)
Block(-2,15,8,LOG:15)
Block(0,15,8,LOG:15)
Block(1,15,8,LOG:15)
Block(2,15,8,LOG:15)
Block(5,15,8,LOG:15)
Block(6,15,8,LOG:15)
Block(-3,15,9,LOG:15)
Block(0,15,9,LOG:15)
Block(1,15,9,LOG:15)
Block(2,15,9,LOG:15)
Block(5,15,9,LEAVES:3)
Block(6,15,9,LOG:15)
Block(7,15,9,LEAVES:3)
Block(-6,15,10,LEAVES:3)
Block(0,15,10,LEAVES:3)
Block(1,15,10,LOG:15)
Block(6,15,10,LEAVES:3)
Block(-1,15,12,LEAVES:3)
Block(2,16,-4,LEAVES:3)
Block(-6,16,-3,LEAVES:3)
Block(-3,16,-3,LOG:15)
Block(-2,16,-3,LOG:15)
Block(-1,16,-3,LOG:15)
Block(-4,16,-2,LOG:15)
Block(-3,16,-2,LOG:15)
Block(-2,16,-2,LOG:15)
Block(-1,16,-2,LOG:15)
Block(0,16,-2,LOG:15)
Block(-4,16,-1,LOG:15)
Block(-3,16,-1,LOG:15)
Block(-2,16,-1,LOG:15)
Block(-1,16,-1,LOG:15)
Block(0,16,-1,LOG:15)
Block(-5,16,0,LEAVES:3)
Block(-4,16,0,LOG:15)
Block(-3,16,0,LOG:15)
Block(-2,16,0,LOG:15)
Block(-1,16,0,LOG:15)
Block(0,16,0,LOG:15)
Block(-4,16,1,LOG:15)
Block(-3,16,1,LOG:15)
Block(-2,16,1,LOG:15)
Block(-1,16,1,LOG:15)
Block(0,16,1,LOG:15)
Block(-6,16,2,LEAVES:3)
Block(-4,16,2,LOG:15)
Block(-3,16,2,LOG:15)
Block(-2,16,2,LOG:15)
Block(-1,16,2,LOG:15)
Block(0,16,2,LOG:15)
Block(-3,16,3,LOG:15)
Block(-2,16,3,LOG:15)
Block(-1,16,3,LOG:15)
Block(0,16,3,LOG:15)
Block(-2,16,4,LEAVES:3)
Block(-1,16,4,LEAVES:3)
Block(0,16,4,LEAVES:3)
Block(-1,16,5,LEAVES:3)
Block(5,16,6,LEAVES:3)
Block(1,16,8,LOG:15)
Block(5,16,8,LEAVES:3)
Block(6,16,8,LEAVES:3)
Block(7,16,8,LEAVES:3)
Block(-5,16,9,LEAVES:3)
Block(-4,16,9,LOG:15)
Block(-3,16,9,LOG:15)
Block(1,16,9,LOG:15)
Block(5,16,9,LEAVES:3)
Block(6,16,9,LOG:15)
Block(7,16,9,LEAVES:3)
Block(-6,16,10,LEAVES:3)
Block(-5,16,10,LEAVES:3)
Block(-4,16,10,LEAVES:3)
Block(0,16,10,LOG:15)
Block(1,16,10,LOG:15)
Block(5,16,10,LEAVES:3)
Block(6,16,10,LEAVES:3)
Block(7,16,10,LEAVES:3)
Block(-5,16,11,LEAVES:3)
Block(-4,16,11,LEAVES:3)
Block(-3,16,11,LEAVES:3)
Block(-2,16,11,LEAVES:3)
Block(0,16,11,LEAVES:3)
Block(1,16,11,LOG:15)
Block(-1,16,12,LEAVES:3)
Block(-4,17,-4,LEAVES:15)
Block(-1,17,-4,LOG:15)
Block(2,17,-4,LEAVES:3)
Block(-6,17,-3,LEAVES:3)
Block(-5,17,-3,LEAVES:3)
Block(-4,17,-3,LEAVES:15)
Block(-3,17,-3,LOG:15)
Block(-2,17,-3,LOG:15)
Block(-1,17,-3,LOG:15)
Block(0,17,-3,LOG:15)
Block(-5,17,-2,LEAVES:3)
Block(-4,17,-2,LOG:15)
Block(-3,17,-2,LOG:15)
Block(-2,17,-2,LOG:15)
Block(-1,17,-2,LOG:15)
Block(0,17,-2,LOG:15)
Block(-4,17,-1,LOG:15)
Block(-3,17,-1,LOG:15)
Block(-2,17,-1,LOG:15)
Block(-1,17,-1,LOG:15)
Block(0,17,-1,LOG:15)
Block(-4,17,0,LOG:15)
Block(-3,17,0,LOG:15)
Block(-2,17,0,LOG:15)
Block(-1,17,0,LOG:15)
Block(0,17,0,LOG:15)
Block(-4,17,1,LOG:15)
Block(-3,17,1,LOG:15)
Block(-2,17,1,LOG:15)
Block(-1,17,1,LOG:15)
Block(0,17,1,LOG:15)
Block(-6,17,2,LEAVES:3)
Block(-5,17,2,LOG:15)
Block(-4,17,2,LOG:15)
Block(-3,17,2,LOG:15)
Block(-2,17,2,LOG:15)
Block(-1,17,2,LOG:15)
Block(0,17,2,LOG:15)
Block(-4,17,3,LOG:15)
Block(-3,17,3,LOG:15)
Block(-2,17,3,LOG:15)
Block(-1,17,3,LOG:15)
Block(0,17,3,LEAVES:3)
Block(-1,17,4,LEAVES:3)
Block(5,17,6,LEAVES:3)
Block(-4,17,7,LEAVES:3)
Block(4,17,7,LEAVES:3)
Block(5,17,7,LEAVES:3)
Block(6,17,7,LEAVES:3)
Block(-5,17,8,LEAVES:3)
Block(-4,17,8,LEAVES:3)
Block(-3,17,8,LEAVES:3)
Block(4,17,8,LEAVES:3)
Block(5,17,8,LEAVES:3)
Block(6,17,8,LEAVES:3)
Block(-6,17,9,LEAVES:3)
Block(-5,17,9,LEAVES:3)
Block(-4,17,9,LOG:15)
Block(-3,17,9,LEAVES:3)
Block(-1,17,9,LEAVES:3)
Block(4,17,9,LEAVES:3)
Block(5,17,9,LEAVES:3)
Block(6,17,9,LEAVES:3)
Block(7,17,9,LEAVES:3)
Block(-6,17,10,LOG:15)
Block(-5,17,10,LOG:15)
Block(-4,17,10,LOG:15)
Block(-3,17,10,LEAVES:3)
Block(-2,17,10,LEAVES:3)
Block(-1,17,10,LEAVES:3)
Block(0,17,10,LOG:15)
Block(1,17,10,LEAVES:3)
Block(2,17,10,LEAVES:3)
Block(6,17,10,LEAVES:3)
Block(-6,17,11,LEAVES:3)
Block(-5,17,11,LEAVES:3)
Block(-4,17,11,LEAVES:3)
Block(-3,17,11,LEAVES:3)
Block(-2,17,11,LEAVES:3)
Block(-1,17,11,LEAVES:3)
Block(0,17,11,LOG:15)
Block(1,17,11,LOG:15)
Block(2,17,11,LEAVES:3)
Block(-5,17,12,LEAVES:3)
Block(-4,17,12,LEAVES:3)
Block(-3,17,12,LEAVES:3)
Block(-2,17,12,LEAVES:3)
Block(-1,17,12,LEAVES:3)
Block(1,17,12,LEAVES:3)
Block(2,17,12,LEAVES:3)
Block(-2,18,-5,LEAVES:15)
Block(-1,18,-5,LOG:15)
Block(-5,18,-4,LEAVES:15)
Block(-4,18,-4,LEAVES:15)
Block(-3,18,-4,LEAVES:15)
Block(-2,18,-4,LOG:15)
Block(-1,18,-4,LOG:15)
Block(0,18,-4,LOG:15)
Block(2,18,-4,LEAVES:3)
Block(-6,18,-3,LEAVES:3)
Block(-5,18,-3,LEAVES:3)
Block(-4,18,-3,LOG:15)
Block(-3,18,-3,LOG:15)
Block(-2,18,-3,LOG:15)
Block(-1,18,-3,LOG:15)
Block(0,18,-3,LOG:15)
Block(-5,18,-2,LOG:15)
Block(-4,18,-2,LOG:15)
Block(-3,18,-2,LOG:15)
Block(-2,18,-2,LOG:15)
Block(-1,18,-2,LOG:15)
Block(0,18,-2,LOG:15)
Block(-5,18,-1,LOG:15)
Block(-4,18,-1,LOG:15)
Block(-3,18,-1,LOG:15)
Block(-2,18,-1,LOG:15)
Block(-1,18,-1,LOG:15)
Block(0,18,-1,LOG:15)
Block(1,18,-1,LOG:15)
Block(-4,18,0,LOG:15)
Block(-3,18,0,LOG:15)
Block(-2,18,0,LOG:15)
Block(-1,18,0,LOG:15)
Block(0,18,0,LOG:15)
Block(1,18,0,LOG:15)
Block(6,18,0,LEAVES:3)
Block(-4,18,1,LOG:15)
Block(-3,18,1,LOG:15)
Block(-2,18,1,LOG:15)
Block(-1,18,1,LOG:15)
Block(0,18,1,LOG:15)
Block(1,18,1,LOG:15)
Block(2,18,1,LOG:15)
Block(-6,18,2,LEAVES:3)
Block(-5,18,2,LOG:15)
Block(-4,18,2,LOG:15)
Block(-3,18,2,LOG:15)
Block(-2,18,2,LOG:15)
Block(-1,18,2,LOG:15)
Block(0,18,2,LOG:15)
Block(-4,18,3,LOG:15)
Block(-3,18,3,LOG:15)
Block(-2,18,3,LEAVES:3)
Block(-1,18,3,LEAVES:3)
Block(0,18,3,LEAVES:3)
Block(1,18,3,LEAVES:3)
Block(-2,18,4,LEAVES:3)
Block(-1,18,4,LEAVES:3)
Block(0,18,4,LEAVES:3)
Block(-3,18,5,LEAVES:3)
Block(-2,18,5,LEAVES:3)
Block(-1,18,5,LEAVES:3)
Block(3,18,5,LEAVES:3)
Block(-4,18,6,LEAVES:3)
Block(-3,18,6,LEAVES:3)
Block(-2,18,6,LEAVES:3)
Block(0,18,6,LEAVES:3)
Block(2,18,6,LEAVES:3)
Block(3,18,6,LEAVES:3)
Block(4,18,6,LEAVES:3)
Block(5,18,6,LEAVES:3)
Block(6,18,6,LEAVES:3)
Block(-5,18,7,LEAVES:3)
Block(-4,18,7,LEAVES:3)
Block(-3,18,7,LEAVES:3)
Block(-1,18,7,LEAVES:3)
Block(0,18,7,LEAVES:3)
Block(1,18,7,LEAVES:3)
Block(3,18,7,LEAVES:3)
Block(4,18,7,LEAVES:3)
Block(5,18,7,LEAVES:3)
Block(6,18,7,LEAVES:3)
Block(-6,18,8,LEAVES:3)
Block(-5,18,8,LEAVES:3)
Block(-4,18,8,LEAVES:3)
Block(-3,18,8,LEAVES:3)
Block(-1,18,8,LEAVES:3)
Block(0,18,8,LEAVES:3)
Block(1,18,8,LEAVES:3)
Block(2,18,8,LEAVES:3)
Block(4,18,8,LEAVES:3)
Block(5,18,8,LEAVES:3)
Block(6,18,8,LEAVES:3)
Block(-6,18,9,LEAVES:3)
Block(-5,18,9,LEAVES:3)
Block(-4,18,9,LEAVES:3)
Block(-3,18,9,LEAVES:3)
Block(-2,18,9,LEAVES:3)
Block(-1,18,9,LEAVES:3)
Block(0,18,9,LEAVES:3)
Block(1,18,9,LEAVES:3)
Block(2,18,9,LEAVES:3)
Block(3,18,9,LEAVES:3)
Block(4,18,9,LEAVES:3)
Block(5,18,9,LEAVES:3)
Block(6,18,9,LEAVES:3)
Block(-6,18,10,LEAVES:3)
Block(-5,18,10,LEAVES:3)
Block(-4,18,10,LEAVES:3)
Block(-3,18,10,LEAVES:3)
Block(-2,18,10,LEAVES:3)
Block(-1,18,10,LEAVES:3)
Block(0,18,10,LEAVES:3)
Block(1,18,10,LEAVES:3)
Block(2,18,10,LEAVES:3)
Block(3,18,10,LEAVES:3)
Block(4,18,10,LEAVES:3)
Block(5,18,10,LEAVES:3)
Block(-5,18,11,LEAVES:3)
Block(-4,18,11,LEAVES:3)
Block(-3,18,11,LEAVES:3)
Block(-2,18,11,LEAVES:3)
Block(-1,18,11,LEAVES:3)
Block(0,18,11,LEAVES:3)
Block(1,18,11,LOG:15)
Block(2,18,11,LEAVES:3)
Block(-2,18,12,LEAVES:3)
Block(-1,18,12,LEAVES:3)
Block(0,18,12,LEAVES:3)
Block(1,18,12,LEAVES:3)
Block(2,18,12,LEAVES:3)
Block(3,18,12,LEAVES:3)
Block(-1,18,13,LEAVES:3)
Block(2,18,13,LEAVES:3)
Block(-10,19,-8,LEAVES:3)
Block(-2,19,-7,LEAVES:15)
Block(1,19,-7,LOG:15)
Block(-3,19,-6,LEAVES:15)
Block(-2,19,-6,LEAVES:15)
Block(-1,19,-6,LEAVES:15)
Block(0,19,-6,LOG:15)
Block(1,19,-6,LOG:15)
Block(2,19,-6,LOG:15)
Block(-3,19,-5,LEAVES:15)
Block(-2,19,-5,LOG:15)
Block(-1,19,-5,LOG:15)
Block(0,19,-5,LOG:15)
Block(1,19,-5,LOG:15)
Block(-6,19,-4,LEAVES:3)
Block(-4,19,-4,LEAVES:15)
Block(-3,19,-4,LEAVES:15)
Block(-2,19,-4,LOG:15)
Block(-1,19,-4,LOG:15)
Block(0,19,-4,LOG:15)
Block(2,19,-4,LEAVES:3)
Block(-6,19,-3,LOG:15)
Block(-5,19,-3,LOG:15)
Block(-4,19,-3,LOG:15)
Block(-3,19,-3,LEAVES:15)
Block(-2,19,-3,LOG:15)
Block(-1,19,-3,LOG:15)
Block(0,19,-3,LOG:15)
Block(-6,19,-2,LOG:15)
Block(-5,19,-2,LOG:15)
Block(-4,19,-2,LOG:15)
Block(-3,19,-2,LOG:15)
Block(-2,19,-2,LOG:15)
Block(-1,19,-2,LOG:15)
Block(0,19,-2,LEAVES:15)
Block(1,19,-2,LEAVES:15)
Block(-6,19,-1,LEAVES:3)
Block(-5,19,-1,LOG:15)
Block(-4,19,-1,LOG:15)
Block(-3,19,-1,LOG:15)
Block(-2,19,-1,LOG:15)
Block(-1,19,-1,LOG:15)
Block(0,19,-1,LOG:15)
Block(-5,19,0,LEAVES:3)
Block(-4,19,0,LOG:15)
Block(-3,19,0,LOG:15)
Block(-2,19,0,LOG:15)
Block(-1,19,0,LOG:15)
Block(0,19,0,LOG:15)
Block(1,19,0,LOG:15)
Block(2,19,0,LOG:15)
Block(6,19,0,LEAVES:3)
Block(-3,19,1,LEAVES:15)
Block(-2,19,1,LEAVES:3)
Block(-1,19,1,LOG:15)
Block(0,19,1,LOG:15)
Block(1,19,1,LOG:15)
Block(2,19,1,LOG:15)
Block(3,19,1,LOG:15)
Block(-9,19,2,LEAVES:3)
Block(-4,19,2,LOG:15)
Block(-3,19,2,LEAVES:3)
Block(-2,19,2,LEAVES:3)
Block(-1,19,2,LEAVES:3)
Block(0,19,2,LOG:15)
Block(1,19,2,LOG:15)
Block(2,19,2,LOG:15)
Block(3,19,2,LEAVES:3)
Block(-6,19,3,LEAVES:3)
Block(-5,19,3,LOG:15)
Block(-4,19,3,LOG:15)
Block(-3,19,3,LOG:15)
Block(-2,19,3,LEAVES:3)
Block(-1,19,3,LEAVES:3)
Block(0,19,3,LEAVES:3)
Block(1,19,3,LEAVES:3)
Block(2,19,3,LEAVES:3)
Block(-6,19,4,LEAVES:3)
Block(-5,19,4,LOG:15)
Block(-4,19,4,LOG:15)
Block(-3,19,4,LEAVES:3)
Block(-2,19,4,LEAVES:3)
Block(-1,19,4,LEAVES:3)
Block(0,19,4,LEAVES:3)
Block(1,19,4,LEAVES:3)
Block(2,19,4,LEAVES:3)
Block(3,19,4,LEAVES:3)
Block(-4,19,5,LEAVES:3)
Block(-3,19,5,LEAVES:3)
Block(-2,19,5,LEAVES:3)
Block(-1,19,5,LEAVES:3)
Block(0,19,5,LEAVES:3)
Block(2,19,5,LEAVES:3)
Block(3,19,5,LEAVES:3)
Block(4,19,5,LEAVES:3)
Block(-5,19,6,LEAVES:3)
Block(-4,19,6,LEAVES:3)
Block(-3,19,6,LEAVES:3)
Block(-2,19,6,LEAVES:3)
Block(-1,19,6,LEAVES:3)
Block(0,19,6,LEAVES:3)
Block(1,19,6,LEAVES:3)
Block(2,19,6,LEAVES:3)
Block(3,19,6,LEAVES:3)
Block(4,19,6,LEAVES:3)
Block(5,19,6,LEAVES:3)
Block(-5,19,7,LEAVES:3)
Block(-4,19,7,LEAVES:3)
Block(-3,19,7,LEAVES:3)
Block(-2,19,7,LEAVES:3)
Block(-1,19,7,LEAVES:3)
Block(0,19,7,LEAVES:3)
Block(1,19,7,LEAVES:3)
Block(2,19,7,LEAVES:3)
Block(3,19,7,LEAVES:3)
Block(4,19,7,LEAVES:3)
Block(5,19,7,LEAVES:3)
Block(6,19,7,LEAVES:3)
Block(-9,19,8,LEAVES:3)
Block(-5,19,8,LEAVES:3)
Block(-4,19,8,LEAVES:3)
Block(-3,19,8,LEAVES:3)
Block(-2,19,8,LEAVES:3)
Block(-1,19,8,LEAVES:3)
Block(0,19,8,LEAVES:3)
Block(1,19,8,LEAVES:3)
Block(2,19,8,LEAVES:3)
Block(3,19,8,LEAVES:3)
Block(4,19,8,LEAVES:3)
Block(5,19,8,LEAVES:3)
Block(6,19,8,LEAVES:3)
Block(-6,19,9,LEAVES:3)
Block(-5,19,9,LEAVES:3)
Block(-4,19,9,LEAVES:3)
Block(-3,19,9,LEAVES:3)
Block(-2,19,9,LEAVES:3)
Block(-1,19,9,LEAVES:3)
Block(0,19,9,LEAVES:3)
Block(1,19,9,LEAVES:3)
Block(2,19,9,LEAVES:3)
Block(4,19,9,LEAVES:3)
Block(5,19,9,LEAVES:3)
Block(-5,19,10,LEAVES:3)
Block(-2,19,10,LEAVES:3)
Block(-1,19,10,LEAVES:3)
Block(0,19,10,LEAVES:3)
Block(1,19,10,LEAVES:3)
Block(2,19,10,LEAVES:3)
Block(-1,19,11,LEAVES:3)
Block(0,19,11,LEAVES:3)
Block(1,19,11,LEAVES:3)
Block(2,19,11,LEAVES:3)
Block(-1,19,12,LEAVES:3)
Block(1,19,12,LEAVES:3)
Block(2,19,12,LEAVES:3)
Block(6,20,-13,LEAVES:3)
Block(10,20,-13,LEAVES:3)
Block(-1,20,-10,LEAVES:15)
Block(8,20,-10,LEAVES:3)
Block(-2,20,-9,LEAVES:15)
Block(-1,20,-9,LEAVES:15)
Block(0,20,-9,LEAVES:15)
Block(-10,20,-8,LEAVES:3)
Block(-1,20,-8,LEAVES:15)
Block(1,20,-8,LOG:15)
Block(-3,20,-7,LEAVES:15)
Block(-2,20,-7,LEAVES:15)
Block(-1,20,-7,LEAVES:15)
Block(0,20,-7,LOG:15)
Block(1,20,-7,LOG:15)
Block(2,20,-7,LOG:15)
Block(-3,20,-6,LEAVES:15)
Block(-2,20,-6,LOG:15)
Block(-1,20,-6,LOG:15)
Block(0,20,-6,LOG:15)
Block(1,20,-6,LOG:15)
Block(2,20,-6,LOG:15)
Block(-8,20,-5,LEAVES:3)
Block(-7,20,-5,LEAVES:3)
Block(-3,20,-5,LEAVES:15)
Block(-2,20,-5,LOG:15)
Block(-1,20,-5,LOG:15)
Block(0,20,-5,LOG:15)
Block(1,20,-5,LOG:15)
Block(2,20,-5,LOG:15)
Block(-7,20,-4,LOG:15)
Block(-6,20,-4,LOG:15)
Block(-5,20,-4,LOG:15)
Block(-3,20,-4,LEAVES:15)
Block(-2,20,-4,LOG:15)
Block(-1,20,-4,LOG:15)
Block(0,20,-4,LOG:15)
Block(1,20,-4,LOG:15)
Block(2,20,-4,LEAVES:3)
Block(9,20,-4,LEAVES:3)
Block(-7,20,-3,LOG:15)
Block(-6,20,-3,LOG:15)
Block(-5,20,-3,LOG:15)
Block(-4,20,-3,LOG:15)
Block(-3,20,-3,LEAVES:15)
Block(-2,20,-3,LOG:15)
Block(-1,20,-3,LOG:15)
Block(0,20,-3,LOG:15)
Block(1,20,-3,LEAVES:3)
Block(-6,20,-2,LOG:15)
Block(-5,20,-2,LOG:15)
Block(-4,20,-2,LOG:15)
Block(-3,20,-2,LEAVES:3)
Block(-2,20,-2,LEAVES:15)
Block(-1,20,-2,LEAVES:15)
Block(0,20,-2,LEAVES:3)
Block(1,20,-2,LEAVES:15)
Block(-5,20,-1,LOG:15)
Block(-4,20,-1,LOG:15)
Block(-3,20,-1,LEAVES:3)
Block(-2,20,-1,LEAVES:3)
Block(-1,20,-1,LEAVES:15)
Block(0,20,-1,LEAVES:15)
Block(1,20,-1,LEAVES:15)
Block(10,20,-1,LEAVES:3)
Block(-13,20,0,LEAVES:3)
Block(-3,20,0,LEAVES:3)
Block(-2,20,0,LEAVES:15)
Block(-1,20,0,LEAVES:15)
Block(0,20,0,LOG:15)
Block(1,20,0,LOG:15)
Block(2,20,0,LOG:15)
Block(3,20,0,LOG:15)
Block(6,20,0,LEAVES:3)
Block(-4,20,1,LEAVES:3)
Block(-2,20,1,LEAVES:15)
Block(-1,20,1,LEAVES:15)
Block(0,20,1,LOG:15)
Block(1,20,1,LOG:15)
Block(2,20,1,LOG:15)
Block(3,20,1,LOG:15)
Block(4,20,1,LOG:15)
Block(-9,20,2,LEAVES:3)
Block(-5,20,2,LOG:15)
Block(-4,20,2,LOG:15)
Block(-3,20,2,LEAVES:3)
Block(0,20,2,LEAVES:3)
Block(1,20,2,LOG:15)
Block(2,20,2,LOG:15)
Block(3,20,2,LOG:15)
Block(4,20,2,LOG:15)
Block(-6,20,3,LOG:15)
Block(-5,20,3,LOG:15)
Block(-4,20,3,LOG:15)
Block(-3,20,3,LOG:15)
Block(-1,20,3,LEAVES:3)
Block(0,20,3,LEAVES:3)
Block(1,20,3,LEAVES:3)
Block(2,20,3,LEAVES:3)
Block(3,20,3,LEAVES:3)
Block(-7,20,4,LEAVES:3)
Block(-6,20,4,LOG:15)
Block(-5,20,4,LOG:15)
Block(-4,20,4,LOG:15)
Block(-2,20,4,LEAVES:3)
Block(-1,20,4,LEAVES:3)
Block(0,20,4,LEAVES:3)
Block(1,20,4,LEAVES:3)
Block(2,20,4,LEAVES:3)
Block(3,20,4,LEAVES:3)
Block(4,20,4,LEAVES:3)
Block(-5,20,5,LOG:15)
Block(-3,20,5,LEAVES:3)
Block(-2,20,5,LEAVES:3)
Block(-1,20,5,LEAVES:3)
Block(0,20,5,LEAVES:3)
Block(1,20,5,LEAVES:3)
Block(2,20,5,LEAVES:3)
Block(3,20,5,LEAVES:3)
Block(4,20,5,LEAVES:3)
Block(-12,20,6,LEAVES:3)
Block(-4,20,6,LEAVES:3)
Block(-3,20,6,LEAVES:3)
Block(-2,20,6,LEAVES:3)
Block(-1,20,6,LEAVES:3)
Block(0,20,6,LEAVES:3)
Block(1,20,6,LEAVES:3)
Block(2,20,6,LEAVES:3)
Block(3,20,6,LEAVES:3)
Block(4,20,6,LEAVES:3)
Block(-5,20,7,LEAVES:3)
Block(-4,20,7,LEAVES:3)
Block(-3,20,7,LEAVES:3)
Block(-1,20,7,LEAVES:3)
Block(0,20,7,LEAVES:3)
Block(1,20,7,LEAVES:3)
Block(3,20,7,LEAVES:3)
Block(4,20,7,LEAVES:3)
Block(5,20,7,LEAVES:3)
Block(-9,20,8,LEAVES:3)
Block(-4,20,8,LEAVES:3)
Block(-1,20,8,LEAVES:3)
Block(0,20,8,LEAVES:3)
Block(1,20,8,LEAVES:3)
Block(2,20,8,LEAVES:3)
Block(4,20,8,LEAVES:3)
Block(-1,20,9,LEAVES:3)
Block(0,20,9,LEAVES:3)
Block(1,20,9,LEAVES:3)
Block(2,20,9,LEAVES:3)
Block(1,20,10,LEAVES:3)
Block(6,21,-13,LEAVES:3)
Block(10,21,-13,LEAVES:3)
Block(1,21,-12,LEAVES:3)
Block(-6,21,-11,LEAVES:3)
Block(-3,21,-11,LEAVES:3)
Block(-2,21,-10,LEAVES:15)
Block(-1,21,-10,LEAVES:15)
Block(0,21,-10,LEAVES:15)
Block(4,21,-10,LOG:15)
Block(8,21,-10,LEAVES:3)
Block(-2,21,-9,LEAVES:15)
Block(-1,21,-9,LEAVES:15)
Block(0,21,-9,LEAVES:15)
Block(1,21,-9,LEAVES:15)
Block(3,21,-9,LOG:15)
Block(4,21,-9,LOG:15)
Block(5,21,-9,LOG:15)
Block(-10,21,-8,LEAVES:3)
Block(-3,21,-8,LOG:15)
Block(-2,21,-8,LEAVES:15)
Block(-1,21,-8,LEAVES:15)
Block(0,21,-8,LOG:15)
Block(1,21,-8,LOG:15)
Block(2,21,-8,LOG:15)
Block(3,21,-8,LOG:15)
Block(4,21,-8,LOG:15)
Block(-10,21,-7,LEAVES:3)
Block(-4,21,-7,LEAVES:15)
Block(-3,21,-7,LOG:15)
Block(-2,21,-7,LOG:15)
Block(0,21,-7,LOG:15)
Block(1,21,-7,LOG:15)
Block(2,21,-7,LOG:15)
Block(3,21,-7,LOG:15)
Block(-9,21,-6,LEAVES:3)
Block(-3,21,-6,LEAVES:15)
Block(-2,21,-6,LOG:15)
Block(-1,21,-6,LEAVES:15)
Block(0,21,-6,LOG:15)
Block(1,21,-6,LOG:15)
Block(2,21,-6,LOG:15)
Block(3,21,-6,LEAVES:15)
Block(4,21,-6,LEAVES:15)
Block(-9,21,-5,LEAVES:3)
Block(-8,21,-5,LOG:15)
Block(-7,21,-5,LOG:15)
Block(-6,21,-5,LOG:15)
Block(-2,21,-5,LEAVES:15)
Block(-1,21,-5,LOG:15)
Block(0,21,-5,LOG:15)
Block(1,21,-5,LOG:15)
Block(2,21,-5,LEAVES:15)
Block(3,21,-5,LEAVES:15)
Block(4,21,-5,LEAVES:15)
Block(5,21,-5,LEAVES:15)
Block(-8,21,-4,LOG:15)
Block(-7,21,-4,LOG:15)
Block(-6,21,-4,LOG:15)
Block(-5,21,-4,LOG:15)
Block(-3,21,-4,LEAVES:15)
Block(-2,21,-4,LOG:15)
Block(-1,21,-4,LOG:15)
Block(0,21,-4,LOG:15)
Block(4,21,-4,LEAVES:15)
Block(9,21,-4,LEAVES:3)
Block(-8,21,-3,LEAVES:3)
Block(-7,21,-3,LOG:15)
Block(-6,21,-3,LOG:15)
Block(-5,21,-3,LOG:15)
Block(-3,21,-3,LEAVES:15)
Block(-2,21,-3,LEAVES:15)
Block(-1,21,-3,LOG:15)
Block(0,21,-3,LEAVES:3)
Block(-7,21,-2,LEAVES:3)
Block(-6,21,-2,LOG:15)
Block(-5,21,-2,LOG:15)
Block(-4,21,-2,LEAVES:15)
Block(-3,21,-2,LEAVES:15)
Block(-2,21,-2,LEAVES:15)
Block(-1,21,-2,LEAVES:15)
Block(0,21,-2,LEAVES:15)
Block(1,21,-2,LEAVES:15)
Block(-5,21,-1,LEAVES:15)
Block(-4,21,-1,LEAVES:15)
Block(-3,21,-1,LEAVES:3)
Block(-2,21,-1,LEAVES:15)
Block(-1,21,-1,LEAVES:15)
Block(0,21,-1,LEAVES:15)
Block(10,21,-1,LEAVES:3)
Block(-13,21,0,LEAVES:3)
Block(-4,21,0,LEAVES:15)
Block(-2,21,0,LEAVES:15)
Block(-1,21,0,LEAVES:15)
Block(0,21,0,LEAVES:15)
Block(1,21,0,LEAVES:15)
Block(2,21,0,LEAVES:3)
Block(3,21,0,LOG:15)
Block(4,21,0,LOG:15)
Block(5,21,0,LEAVES:3)
Block(6,21,0,LEAVES:3)
Block(-3,21,1,LEAVES:15)
Block(-2,21,1,LEAVES:15)
Block(-1,21,1,LEAVES:15)
Block(0,21,1,LEAVES:15)
Block(1,21,1,LOG:15)
Block(2,21,1,LOG:15)
Block(3,21,1,LOG:15)
Block(4,21,1,LOG:15)
Block(5,21,1,LOG:15)
Block(-9,21,2,LEAVES:3)
Block(-4,21,2,LEAVES:3)
Block(-3,21,2,LEAVES:15)
Block(-2,21,2,LEAVES:15)
Block(-1,21,2,LEAVES:15)
Block(0,21,2,LEAVES:15)
Block(1,21,2,LEAVES:3)
Block(2,21,2,LEAVES:3)
Block(3,21,2,LOG:15)
Block(4,21,2,LOG:15)
Block(5,21,2,LOG:15)
Block(-6,21,3,LOG:15)
Block(-5,21,3,LOG:15)
Block(-4,21,3,LOG:15)
Block(-3,21,3,LEAVES:15)
Block(-1,21,3,LEAVES:15)
Block(0,21,3,LEAVES:3)
Block(1,21,3,LEAVES:3)
Block(2,21,3,LEAVES:3)
Block(4,21,3,LOG:15)
Block(-8,21,4,LEAVES:3)
Block(-7,21,4,LOG:15)
Block(-6,21,4,LOG:15)
Block(-5,21,4,LOG:15)
Block(-4,21,4,LOG:15)
Block(-1,21,4,LEAVES:3)
Block(1,21,4,LEAVES:3)
Block(2,21,4,LEAVES:3)
Block(3,21,4,LEAVES:3)
Block(-9,21,5,LEAVES:3)
Block(-8,21,5,LOG:15)
Block(-7,21,5,LOG:15)
Block(-6,21,5,LOG:15)
Block(-5,21,5,LOG:15)
Block(-2,21,5,LEAVES:3)
Block(-1,21,5,LEAVES:3)
Block(0,21,5,LEAVES:3)
Block(2,21,5,LEAVES:3)
Block(3,21,5,LEAVES:3)
Block(4,21,5,LEAVES:3)
Block(11,21,5,LEAVES:3)
Block(-12,21,6,LEAVES:3)
Block(-1,21,6,LEAVES:3)
Block(0,21,6,LEAVES:3)
Block(1,21,6,LEAVES:3)
Block(3,21,6,LEAVES:3)
Block(0,21,7,LEAVES:3)
Block(-9,21,8,LEAVES:3)
Block(-2,22,-14,LEAVES:3)
Block(-2,22,-13,LEAVES:15)
Block(6,22,-13,LEAVES:3)
Block(10,22,-13,LEAVES:3)
Block(-3,22,-12,LEAVES:15)
Block(-2,22,-12,LEAVES:15)
Block(-1,22,-12,LEAVES:15)
Block(1,22,-12,LEAVES:3)
Block(-14,22,-11,LEAVES:3)
Block(-6,22,-11,LEAVES:3)
Block(-3,22,-11,LEAVES:3)
Block(-2,22,-11,LEAVES:15)
Block(0,22,-11,LEAVES:15)
Block(-12,22,-10,LEAVES:3)
Block(-1,22,-10,LEAVES:15)
Block(0,22,-10,LEAVES:15)
Block(1,22,-10,LEAVES:15)
Block(3,22,-10,LOG:15)
Block(4,22,-10,LOG:15)
Block(5,22,-10,LOG:15)
Block(8,22,-10,LEAVES:3)
Block(-3,22,-9,LOG:15)
Block(-2,22,-9,LEAVES:15)
Block(-1,22,-9,LEAVES:15)
Block(0,22,-9,LOG:15)
Block(1,22,-9,LOG:15)
Block(2,22,-9,LOG:15)
Block(3,22,-9,LOG:15)
Block(4,22,-9,LOG:15)
Block(5,22,-9,LOG:15)
Block(-10,22,-8,LEAVES:3)
Block(-4,22,-8,LEAVES:15)
Block(-3,22,-8,LOG:15)
Block(-2,22,-8,LEAVES:15)
Block(-1,22,-8,LEAVES:15)
Block(0,22,-8,LEAVES:15)
Block(1,22,-8,LOG:15)
Block(2,22,-8,LOG:15)
Block(3,22,-8,LOG:15)
Block(4,22,-8,LOG:15)
Block(5,22,-8,LOG:15)
Block(-10,22,-7,LOG:15)
Block(-9,22,-7,LOG:15)
Block(-4,22,-7,LEAVES:15)
Block(-3,22,-7,LOG:15)
Block(-2,22,-7,LEAVES:15)
Block(0,22,-7,LOG:15)
Block(1,22,-7,LOG:15)
Block(2,22,-7,LOG:15)
Block(3,22,-7,LOG:15)
Block(4,22,-7,LOG:15)
Block(-9,22,-6,LOG:15)
Block(-8,22,-6,LOG:15)
Block(-4,22,-6,LEAVES:15)
Block(-3,22,-6,LEAVES:15)
Block(-2,22,-6,LOG:15)
Block(-1,22,-6,LEAVES:15)
Block(0,22,-6,LEAVES:15)
Block(1,22,-6,LOG:15)
Block(2,22,-6,LOG:15)
Block(3,22,-6,LOG:15)
Block(4,22,-6,LOG:15)
Block(5,22,-6,LEAVES:15)
Block(8,22,-6,LEAVES:3)
Block(-9,22,-5,LOG:15)
Block(-8,22,-5,LOG:15)
Block(-7,22,-5,LOG:15)
Block(-6,22,-5,LEAVES:3)
Block(-3,22,-5,LEAVES:15)
Block(-2,22,-5,LEAVES:15)
Block(-1,22,-5,LEAVES:15)
Block(0,22,-5,LEAVES:3)
Block(1,22,-5,LEAVES:15)
Block(2,22,-5,LEAVES:15)
Block(3,22,-5,LEAVES:15)
Block(4,22,-5,LEAVES:15)
Block(5,22,-5,LEAVES:15)
Block(-10,22,-4,LOG:15)
Block(-9,22,-4,LOG:15)
Block(-8,22,-4,LOG:15)
Block(-7,22,-4,LOG:15)
Block(-6,22,-4,LOG:15)
Block(-5,22,-4,LEAVES:3)
Block(-2,22,-4,LEAVES:15)
Block(-1,22,-4,LEAVES:15)
Block(0,22,-4,LEAVES:15)
Block(1,22,-4,LEAVES:15)
Block(3,22,-4,LEAVES:15)
Block(4,22,-4,LEAVES:15)
Block(5,22,-4,LEAVES:15)
Block(9,22,-4,LEAVES:3)
Block(-13,22,-3,LEAVES:3)
Block(-8,22,-3,LOG:15)
Block(-7,22,-3,LOG:15)
Block(-6,22,-3,LOG:15)
Block(-5,22,-3,LEAVES:3)
Block(-4,22,-3,LEAVES:3)
Block(-3,22,-3,LEAVES:15)
Block(-2,22,-3,LEAVES:15)
Block(-1,22,-3,LEAVES:15)
Block(0,22,-3,LEAVES:15)
Block(-6,22,-2,LEAVES:3)
Block(-5,22,-2,LEAVES:3)
Block(-4,22,-2,LEAVES:15)
Block(-3,22,-2,LEAVES:15)
Block(-2,22,-2,LEAVES:15)
Block(-1,22,-2,LEAVES:15)
Block(0,22,-2,LEAVES:15)
Block(-5,22,-1,LEAVES:15)
Block(-4,22,-1,LEAVES:15)
Block(-3,22,-1,LEAVES:15)
Block(-1,22,-1,LEAVES:15)
Block(5,22,-1,LEAVES:3)
Block(10,22,-1,LEAVES:3)
Block(-13,22,0,LEAVES:3)
Block(-5,22,0,LEAVES:15)
Block(-4,22,0,LEAVES:15)
Block(-3,22,0,LEAVES:15)
Block(-2,22,0,LEAVES:15)
Block(-1,22,0,LEAVES:15)
Block(0,22,0,LEAVES:15)
Block(2,22,0,LEAVES:15)
Block(3,22,0,LEAVES:15)
Block(4,22,0,LOG:15)
Block(5,22,0,LOG:15)
Block(6,22,0,LEAVES:3)
Block(-4,22,1,LEAVES:15)
Block(-3,22,1,LEAVES:15)
Block(-2,22,1,LEAVES:15)
Block(-1,22,1,LEAVES:15)
Block(0,22,1,LEAVES:15)
Block(1,22,1,LEAVES:15)
Block(2,22,1,LEAVES:3)
Block(3,22,1,LOG:15)
Block(4,22,1,LOG:15)
Block(5,22,1,LEAVES:3)
Block(-9,22,2,LEAVES:3)
Block(-5,22,2,LEAVES:15)
Block(-4,22,2,LEAVES:15)
Block(-3,22,2,LEAVES:15)
Block(-2,22,2,LEAVES:15)
Block(-1,22,2,LEAVES:15)
Block(0,22,2,LEAVES:15)
Block(2,22,2,LEAVES:15)
Block(3,22,2,LEAVES:15)
Block(4,22,2,LOG:15)
Block(5,22,2,LOG:15)
Block(-7,22,3,LOG:15)
Block(-6,22,3,LOG:15)
Block(-5,22,3,LOG:15)
Block(-4,22,3,LEAVES:15)
Block(-3,22,3,LEAVES:15)
Block(-2,22,3,LEAVES:15)
Block(-1,22,3,LEAVES:15)
Block(0,22,3,LEAVES:15)
Block(-8,22,4,LOG:15)
Block(-7,22,4,LOG:15)
Block(-6,22,4,LOG:15)
Block(-5,22,4,LOG:15)
Block(-4,22,4,LOG:15)
Block(-9,22,5,LOG:15)
Block(-8,22,5,LOG:15)
Block(-7,22,5,LOG:15)
Block(-6,22,5,LOG:15)
Block(-5,22,5,LOG:15)
Block(-4,22,5,LEAVES:15)
Block(11,22,5,LEAVES:3)
Block(-12,22,6,LEAVES:3)
Block(-8,22,6,LOG:15)
Block(-7,22,6,LOG:15)
Block(-9,22,8,LEAVES:3)
Block(-2,23,-14,LEAVES:3)
Block(6,23,-14,LEAVES:15)
Block(-3,23,-13,LEAVES:15)
Block(-2,23,-13,LEAVES:15)
Block(-1,23,-13,LEAVES:15)
Block(5,23,-13,LEAVES:15)
Block(6,23,-13,LEAVES:3)
Block(7,23,-13,LEAVES:15)
Block(10,23,-13,LEAVES:3)
Block(-3,23,-12,LEAVES:15)
Block(-2,23,-12,LEAVES:15)
Block(-1,23,-12,LEAVES:15)
Block(0,23,-12,LEAVES:15)
Block(1,23,-12,LEAVES:3)
Block(6,23,-12,LEAVES:3)
Block(-14,23,-11,LEAVES:3)
Block(-6,23,-11,LEAVES:3)
Block(-3,23,-11,LEAVES:3)
Block(-2,23,-11,LEAVES:15)
Block(-1,23,-11,LEAVES:15)
Block(0,23,-11,LOG:15)
Block(1,23,-11,LEAVES:15)
Block(4,23,-11,LOG:15)
Block(5,23,-11,LOG:15)
Block(6,23,-11,LOG:15)
Block(7,23,-11,LEAVES:3)
Block(-12,23,-10,LEAVES:3)
Block(-4,23,-10,LEAVES:3)
Block(-3,23,-10,LOG:15)
Block(-2,23,-10,LEAVES:3)
Block(-1,23,-10,LEAVES:15)
Block(0,23,-10,LOG:15)
Block(1,23,-10,LEAVES:15)
Block(3,23,-10,LOG:15)
Block(4,23,-10,LOG:15)
Block(5,23,-10,LOG:15)
Block(6,23,-10,LOG:15)
Block(8,23,-10,LEAVES:3)
Block(-3,23,-9,LOG:15)
Block(-1,23,-9,LEAVES:15)
Block(0,23,-9,LOG:15)
Block(1,23,-9,LOG:15)
Block(3,23,-9,LOG:15)
Block(4,23,-9,LOG:15)
Block(5,23,-9,LOG:15)
Block(-11,23,-8,LOG:15)
Block(-10,23,-8,LOG:15)
Block(-9,23,-8,LOG:15)
Block(-6,23,-8,LOG:15)
Block(-3,23,-8,LOG:15)
Block(0,23,-8,LEAVES:15)
Block(2,23,-8,LOG:15)
Block(3,23,-8,LOG:15)
Block(4,23,-8,LOG:15)
Block(5,23,-8,LOG:15)
Block(-11,23,-7,LOG:15)
Block(-10,23,-7,LOG:15)
Block(-9,23,-7,LOG:15)
Block(-8,23,-7,LOG:15)
Block(-7,23,-7,LOG:15)
Block(-6,23,-7,LOG:15)
Block(-4,23,-7,LEAVES:15)
Block(-3,23,-7,LEAVES:15)
Block(-2,23,-7,LEAVES:15)
Block(1,23,-7,LOG:15)
Block(2,23,-7,LOG:15)
Block(3,23,-7,LOG:15)
Block(4,23,-7,LEAVES:15)
Block(5,23,-7,LEAVES:15)
Block(-10,23,-6,LOG:15)
Block(-9,23,-6,LOG:15)
Block(-8,23,-6,LOG:15)
Block(-7,23,-6,LOG:15)
Block(-4,23,-6,LEAVES:15)
Block(-3,23,-6,LEAVES:15)
Block(-2,23,-6,LEAVES:15)
Block(-1,23,-6,LEAVES:15)
Block(0,23,-6,LEAVES:15)
Block(1,23,-6,LEAVES:3)
Block(2,23,-6,LOG:15)
Block(3,23,-6,LEAVES:3)
Block(4,23,-6,LOG:15)
Block(5,23,-6,LOG:15)
Block(6,23,-6,LOG:15)
Block(8,23,-6,LEAVES:3)
Block(-9,23,-5,LOG:15)
Block(-8,23,-5,LOG:15)
Block(-7,23,-5,LOG:15)
Block(-4,23,-5,LEAVES:15)
Block(-3,23,-5,LEAVES:15)
Block(-2,23,-5,LEAVES:15)
Block(-1,23,-5,LEAVES:15)
Block(0,23,-5,LEAVES:15)
Block(1,23,-5,LEAVES:15)
Block(2,23,-5,LEAVES:3)
Block(3,23,-5,LEAVES:15)
Block(4,23,-5,LEAVES:15)
Block(5,23,-5,LEAVES:15)
Block(6,23,-5,LOG:15)
Block(-10,23,-4,LOG:15)
Block(-9,23,-4,LOG:15)
Block(-8,23,-4,LOG:15)
Block(-7,23,-4,LOG:15)
Block(-6,23,-4,LEAVES:3)
Block(-4,23,-4,LEAVES:15)
Block(-3,23,-4,LEAVES:15)
Block(-2,23,-4,LEAVES:15)
Block(-1,23,-4,LEAVES:15)
Block(0,23,-4,LEAVES:15)
Block(1,23,-4,LEAVES:15)
Block(2,23,-4,LEAVES:15)
Block(3,23,-4,LEAVES:15)
Block(4,23,-4,LEAVES:15)
Block(9,23,-4,LEAVES:3)
Block(-13,23,-3,LEAVES:3)
Block(-11,23,-3,LOG:15)
Block(-10,23,-3,LOG:15)
Block(-6,23,-3,LEAVES:3)
Block(-5,23,-3,LEAVES:3)
Block(-4,23,-3,LEAVES:15)
Block(-3,23,-3,LEAVES:15)
Block(-1,23,-3,LEAVES:15)
Block(0,23,-3,LEAVES:15)
Block(1,23,-3,LEAVES:15)
Block(3,23,-3,LEAVES:15)
Block(-5,23,-2,LEAVES:15)
Block(-4,23,-2,LEAVES:15)
Block(-3,23,-2,LEAVES:15)
Block(-5,23,-1,LEAVES:15)
Block(-4,23,-1,LEAVES:15)
Block(-3,23,-1,LEAVES:15)
Block(-2,23,-1,LEAVES:15)
Block(0,23,-1,LEAVES:15)
Block(2,23,-1,LEAVES:15)
Block(6,23,-1,LOG:15)
Block(10,23,-1,LEAVES:3)
Block(-13,23,0,LEAVES:3)
Block(-4,23,0,LEAVES:15)
Block(-3,23,0,LEAVES:15)
Block(-2,23,0,LEAVES:15)
Block(-1,23,0,LEAVES:15)
Block(0,23,0,LEAVES:15)
Block(1,23,0,LEAVES:15)
Block(2,23,0,LEAVES:15)
Block(3,23,0,LEAVES:15)
Block(4,23,0,LEAVES:15)
Block(5,23,0,LOG:15)
Block(6,23,0,LOG:15)
Block(-10,23,1,LEAVES:3)
Block(-5,23,1,LEAVES:15)
Block(-4,23,1,LEAVES:15)
Block(-3,23,1,LEAVES:15)
Block(-2,23,1,LEAVES:15)
Block(-1,23,1,LEAVES:15)
Block(0,23,1,LEAVES:15)
Block(1,23,1,LEAVES:15)
Block(2,23,1,LEAVES:15)
Block(3,23,1,LEAVES:15)
Block(4,23,1,LEAVES:15)
Block(-11,23,2,LEAVES:3)
Block(-10,23,2,LEAVES:3)
Block(-9,23,2,LEAVES:3)
Block(-6,23,2,LEAVES:15)
Block(-5,23,2,LEAVES:15)
Block(-4,23,2,LEAVES:15)
Block(-3,23,2,LEAVES:15)
Block(-2,23,2,LEAVES:15)
Block(-1,23,2,LEAVES:15)
Block(0,23,2,LEAVES:15)
Block(1,23,2,LEAVES:15)
Block(2,23,2,LEAVES:15)
Block(3,23,2,LEAVES:15)
Block(4,23,2,LEAVES:15)
Block(5,23,2,LOG:15)
Block(6,23,2,LOG:15)
Block(7,23,2,LOG:15)
Block(-11,23,3,LEAVES:3)
Block(-10,23,3,LOG:15)
Block(-9,23,3,LEAVES:3)
Block(-7,23,3,LEAVES:15)
Block(-6,23,3,LEAVES:15)
Block(-5,23,3,LEAVES:3)
Block(-4,23,3,LEAVES:15)
Block(-3,23,3,LEAVES:15)
Block(-1,23,3,LEAVES:15)
Block(2,23,3,LEAVES:15)
Block(3,23,3,LEAVES:15)
Block(4,23,3,LEAVES:15)
Block(6,23,3,LOG:15)
Block(7,23,3,LOG:15)
Block(-10,23,4,LOG:15)
Block(-9,23,4,LOG:15)
Block(-8,23,4,LOG:15)
Block(-7,23,4,LOG:15)
Block(-6,23,4,LOG:15)
Block(-5,23,4,LOG:15)
Block(-4,23,4,LEAVES:3)
Block(-3,23,4,LEAVES:15)
Block(3,23,4,LEAVES:15)
Block(4,23,4,LEAVES:15)
Block(5,23,4,LEAVES:15)
Block(6,23,4,LEAVES:3)
Block(7,23,4,LOG:15)
Block(8,23,4,LOG:15)
Block(-10,23,5,LEAVES:3)
Block(-9,23,5,LOG:15)
Block(-8,23,5,LOG:15)
Block(-7,23,5,LOG:15)
Block(-6,23,5,LEAVES:3)
Block(-5,23,5,LEAVES:3)
Block(-4,23,5,LEAVES:15)
Block(-3,23,5,LEAVES:15)
Block(4,23,5,LEAVES:15)
Block(7,23,5,LEAVES:3)
Block(8,23,5,LEAVES:3)
Block(9,23,5,LEAVES:3)
Block(11,23,5,LEAVES:3)
Block(-12,23,6,LEAVES:3)
Block(-10,23,6,LEAVES:3)
Block(-9,23,6,LEAVES:3)
Block(-8,23,6,LOG:15)
Block(-7,23,6,LEAVES:3)
Block(-6,23,6,LEAVES:15)
Block(-5,23,6,LEAVES:15)
Block(-4,23,6,LEAVES:15)
Block(7,23,6,LEAVES:15)
Block(8,23,6,LEAVES:3)
Block(9,23,6,LEAVES:15)
Block(-10,23,7,LEAVES:3)
Block(-9,23,7,LEAVES:3)
Block(-8,23,7,LEAVES:3)
Block(-7,23,7,LEAVES:15)
Block(-6,23,7,LEAVES:15)
Block(-5,23,7,LEAVES:15)
Block(-4,23,7,LEAVES:15)
Block(7,23,7,LEAVES:15)
Block(8,23,7,LEAVES:15)
Block(9,23,7,LEAVES:15)
Block(-9,23,8,LEAVES:3)
Block(5,24,-16,LEAVES:15)
Block(4,24,-15,LEAVES:15)
Block(5,24,-15,LEAVES:15)
Block(6,24,-15,LEAVES:15)
Block(-2,24,-14,LEAVES:3)
Block(5,24,-14,LEAVES:15)
Block(6,24,-14,LEAVES:15)
Block(7,24,-14,LEAVES:3)
Block(9,24,-14,LEAVES:3)
Block(-2,24,-13,LEAVES:15)
Block(-1,24,-13,LEAVES:15)
Block(0,24,-13,LEAVES:3)
Block(4,24,-13,LEAVES:15)
Block(5,24,-13,LEAVES:15)
Block(6,24,-13,LEAVES:3)
Block(7,24,-13,LOG:15)
Block(8,24,-13,LEAVES:3)
Block(9,24,-13,LEAVES:3)
Block(10,24,-13,LEAVES:3)
Block(-6,24,-12,LEAVES:15)
Block(-3,24,-12,LEAVES:3)
Block(-2,24,-12,LEAVES:15)
Block(-1,24,-12,LOG:15)
Block(0,24,-12,LEAVES:3)
Block(1,24,-12,LEAVES:3)
Block(3,24,-12,LEAVES:15)
Block(4,24,-12,LEAVES:15)
Block(5,24,-12,LEAVES:3)
Block(6,24,-12,LOG:15)
Block(7,24,-12,LOG:15)
Block(8,24,-12,LEAVES:3)
Block(9,24,-12,LEAVES:3)
Block(-14,24,-11,LEAVES:3)
Block(-7,24,-11,LEAVES:15)
Block(-6,24,-11,LEAVES:3)
Block(-5,24,-11,LEAVES:3)
Block(-4,24,-11,LEAVES:3)
Block(-3,24,-11,LEAVES:3)
Block(-2,24,-11,LEAVES:3)
Block(-1,24,-11,LOG:15)
Block(0,24,-11,LOG:15)
Block(4,24,-11,LEAVES:3)
Block(5,24,-11,LEAVES:3)
Block(6,24,-11,LOG:15)
Block(7,24,-11,LEAVES:3)
Block(8,24,-11,LEAVES:3)
Block(9,24,-11,LEAVES:3)
Block(-12,24,-10,LEAVES:3)
Block(-6,24,-10,LOG:15)
Block(-5,24,-10,LOG:15)
Block(-4,24,-10,LEAVES:3)
Block(-3,24,-10,LOG:15)
Block(-2,24,-10,LEAVES:3)
Block(-1,24,-10,LEAVES:3)
Block(0,24,-10,LOG:15)
Block(1,24,-10,LEAVES:15)
Block(4,24,-10,LOG:15)
Block(5,24,-10,LOG:15)
Block(6,24,-10,LEAVES:3)
Block(7,24,-10,LEAVES:3)
Block(8,24,-10,LEAVES:3)
Block(-13,24,-9,LEAVES:3)
Block(-12,24,-9,LEAVES:3)
Block(-11,24,-9,LOG:15)
Block(-10,24,-9,LOG:15)
Block(-7,24,-9,LEAVES:3)
Block(-6,24,-9,LOG:15)
Block(-5,24,-9,LOG:15)
Block(-4,24,-9,LEAVES:3)
Block(-3,24,-9,LEAVES:3)
Block(-2,24,-9,LEAVES:3)
Block(0,24,-9,LEAVES:15)
Block(3,24,-9,LOG:15)
Block(4,24,-9,LOG:15)
Block(5,24,-9,LOG:15)
Block(6,24,-9,LEAVES:3)
Block(-12,24,-8,LOG:15)
Block(-11,24,-8,LOG:15)
Block(-10,24,-8,LOG:15)
Block(-9,24,-8,LOG:15)
Block(-6,24,-8,LOG:15)
Block(-3,24,-8,LEAVES:3)
Block(4,24,-8,LOG:15)
Block(5,24,-8,LEAVES:3)
Block(-11,24,-7,LOG:15)
Block(-10,24,-7,LOG:15)
Block(-9,24,-7,LOG:15)
Block(-7,24,-7,LOG:15)
Block(-3,24,-7,LEAVES:15)
Block(1,24,-7,LEAVES:15)
Block(4,24,-7,LEAVES:15)
Block(-10,24,-6,LOG:15)
Block(-9,24,-6,LOG:15)
Block(-8,24,-6,LOG:15)
Block(-4,24,-6,LEAVES:15)
Block(-3,24,-6,LEAVES:15)
Block(-2,24,-6,LEAVES:15)
Block(0,24,-6,LEAVES:15)
Block(1,24,-6,LEAVES:15)
Block(2,24,-6,LEAVES:3)
Block(3,24,-6,LEAVES:15)
Block(4,24,-6,LEAVES:15)
Block(5,24,-6,LOG:15)
Block(6,24,-6,LOG:15)
Block(7,24,-6,LOG:15)
Block(8,24,-6,LEAVES:3)
Block(-8,24,-5,LOG:15)
Block(-4,24,-5,LEAVES:15)
Block(-3,24,-5,LEAVES:15)
Block(-2,24,-5,LEAVES:15)
Block(-1,24,-5,LEAVES:15)
Block(0,24,-5,LEAVES:15)
Block(1,24,-5,LEAVES:15)
Block(2,24,-5,LEAVES:15)
Block(3,24,-5,LEAVES:15)
Block(4,24,-5,LEAVES:15)
Block(5,24,-5,LEAVES:15)
Block(6,24,-5,LOG:15)
Block(7,24,-5,LOG:15)
Block(8,24,-5,LOG:15)
Block(9,24,-5,LEAVES:3)
Block(-12,24,-4,LEAVES:3)
Block(-5,24,-4,LEAVES:15)
Block(-4,24,-4,LEAVES:15)
Block(-3,24,-4,LEAVES:15)
Block(-2,24,-4,LEAVES:15)
Block(-1,24,-4,LEAVES:15)
Block(0,24,-4,LEAVES:15)
Block(1,24,-4,LEAVES:15)
Block(2,24,-4,LEAVES:15)
Block(3,24,-4,LEAVES:15)
Block(4,24,-4,LEAVES:15)
Block(5,24,-4,LEAVES:15)
Block(6,24,-4,LEAVES:15)
Block(7,24,-4,LEAVES:3)
Block(8,24,-4,LEAVES:3)
Block(9,24,-4,LEAVES:3)
Block(-13,24,-3,LEAVES:3)
Block(-12,24,-3,LEAVES:3)
Block(-11,24,-3,LOG:15)
Block(-6,24,-3,LEAVES:15)
Block(-5,24,-3,LEAVES:15)
Block(-4,24,-3,LEAVES:15)
Block(-3,24,-3,LEAVES:15)
Block(-1,24,-3,LEAVES:15)
Block(0,24,-3,LEAVES:15)
Block(2,24,-3,LEAVES:15)
Block(3,24,-3,LEAVES:15)
Block(4,24,-3,LEAVES:15)
Block(5,24,-3,LEAVES:15)
Block(6,24,-3,LEAVES:15)
Block(7,24,-3,LEAVES:15)
Block(8,24,-3,LEAVES:3)
Block(-12,24,-2,LEAVES:3)
Block(-11,24,-2,LEAVES:3)
Block(-5,24,-2,LEAVES:15)
Block(-4,24,-2,LEAVES:15)
Block(-3,24,-2,LEAVES:15)
Block(3,24,-2,LEAVES:15)
Block(4,24,-2,LEAVES:15)
Block(5,24,-2,LEAVES:15)
Block(6,24,-2,LEAVES:15)
Block(7,24,-2,LOG:15)
Block(8,24,-2,LOG:15)
Block(-12,24,-1,LEAVES:3)
Block(-11,24,-1,LEAVES:3)
Block(-10,24,-1,LEAVES:3)
Block(-4,24,-1,LEAVES:15)
Block(-3,24,-1,LEAVES:15)
Block(-2,24,-1,LEAVES:15)
Block(-1,24,-1,LEAVES:15)
Block(0,24,-1,LEAVES:15)
Block(1,24,-1,LEAVES:15)
Block(2,24,-1,LEAVES:15)
Block(3,24,-1,LEAVES:15)
Block(4,24,-1,LEAVES:15)
Block(5,24,-1,LEAVES:15)
Block(6,24,-1,LOG:15)
Block(7,24,-1,LOG:15)
Block(10,24,-1,LEAVES:3)
Block(-13,24,0,LEAVES:3)
Block(-12,24,0,LEAVES:3)
Block(-11,24,0,LEAVES:3)
Block(-5,24,0,LEAVES:15)
Block(-3,24,0,LEAVES:15)
Block(-2,24,0,LEAVES:15)
Block(-1,24,0,LEAVES:15)
Block(0,24,0,LEAVES:15)
Block(1,24,0,LEAVES:15)
Block(2,24,0,LEAVES:15)
Block(3,24,0,LEAVES:15)
Block(4,24,0,LEAVES:15)
Block(5,24,0,LEAVES:15)
Block(6,24,0,LEAVES:15)
Block(7,24,0,LEAVES:15)
Block(9,24,0,LEAVES:3)
Block(10,24,0,LEAVES:3)
Block(11,24,0,LEAVES:3)
Block(-13,24,1,LEAVES:3)
Block(-12,24,1,LOG:15)
Block(-11,24,1,LEAVES:3)
Block(-10,24,1,LEAVES:3)
Block(-9,24,1,LEAVES:3)
Block(-6,24,1,LEAVES:15)
Block(-5,24,1,LEAVES:15)
Block(-4,24,1,LEAVES:15)
Block(-3,24,1,LEAVES:15)
Block(-2,24,1,LEAVES:15)
Block(-1,24,1,LEAVES:15)
Block(0,24,1,LEAVES:15)
Block(1,24,1,LEAVES:15)
Block(2,24,1,LEAVES:15)
Block(3,24,1,LEAVES:15)
Block(4,24,1,LEAVES:15)
Block(6,24,1,LEAVES:15)
Block(8,24,1,LOG:15)
Block(9,24,1,LOG:15)
Block(10,24,1,LEAVES:3)
Block(-14,24,2,LEAVES:3)
Block(-13,24,2,LEAVES:3)
Block(-12,24,2,LOG:15)
Block(-11,24,2,LOG:15)
Block(-10,24,2,LEAVES:3)
Block(-9,24,2,LEAVES:3)
Block(-6,24,2,LEAVES:15)
Block(-5,24,2,LEAVES:15)
Block(-4,24,2,LEAVES:15)
Block(-3,24,2,LEAVES:15)
Block(0,24,2,LEAVES:15)
Block(2,24,2,LEAVES:15)
Block(3,24,2,LEAVES:15)
Block(4,24,2,LEAVES:15)
Block(5,24,2,LEAVES:15)
Block(6,24,2,LEAVES:15)
Block(7,24,2,LOG:15)
Block(8,24,2,LOG:15)
Block(9,24,2,LEAVES:15)
Block(-13,24,3,LEAVES:3)
Block(-12,24,3,LEAVES:3)
Block(-11,24,3,LOG:15)
Block(-10,24,3,LOG:15)
Block(-9,24,3,LEAVES:3)
Block(-7,24,3,LEAVES:15)
Block(-6,24,3,LEAVES:15)
Block(-5,24,3,LEAVES:15)
Block(-4,24,3,LEAVES:15)
Block(-3,24,3,LEAVES:15)
Block(-2,24,3,LEAVES:15)
Block(-1,24,3,LEAVES:15)
Block(0,24,3,LEAVES:15)
Block(1,24,3,LEAVES:15)
Block(2,24,3,LEAVES:15)
Block(3,24,3,LEAVES:15)
Block(4,24,3,LEAVES:15)
Block(5,24,3,LEAVES:15)
Block(6,24,3,LEAVES:3)
Block(7,24,3,LOG:15)
Block(8,24,3,LEAVES:3)
Block(9,24,3,LEAVES:15)
Block(-12,24,4,LEAVES:3)
Block(-11,24,4,LEAVES:3)
Block(-10,24,4,LEAVES:3)
Block(-9,24,4,LEAVES:3)
Block(-8,24,4,LEAVES:15)
Block(-7,24,4,LEAVES:15)
Block(-6,24,4,LEAVES:15)
Block(-5,24,4,LEAVES:3)
Block(-4,24,4,LEAVES:15)
Block(-3,24,4,LEAVES:15)
Block(0,24,4,LEAVES:15)
Block(2,24,4,LEAVES:15)
Block(3,24,4,LEAVES:15)
Block(4,24,4,LEAVES:15)
Block(5,24,4,LEAVES:15)
Block(6,24,4,LEAVES:3)
Block(7,24,4,LOG:15)
Block(8,24,4,LEAVES:3)
Block(9,24,4,LEAVES:3)
Block(-12,24,5,LEAVES:3)
Block(-11,24,5,LEAVES:3)
Block(-10,24,5,LEAVES:3)
Block(-9,24,5,LOG:15)
Block(-8,24,5,LOG:15)
Block(-7,24,5,LEAVES:3)
Block(-6,24,5,LEAVES:15)
Block(-5,24,5,LEAVES:15)
Block(-4,24,5,LEAVES:15)
Block(-3,24,5,LEAVES:15)
Block(2,24,5,LEAVES:15)
Block(3,24,5,LEAVES:15)
Block(4,24,5,LEAVES:15)
Block(5,24,5,LEAVES:15)
Block(6,24,5,LEAVES:3)
Block(7,24,5,LOG:15)
Block(8,24,5,LOG:15)
Block(9,24,5,LEAVES:3)
Block(10,24,5,LEAVES:15)
Block(11,24,5,LEAVES:3)
Block(-13,24,6,LEAVES:3)
Block(-12,24,6,LEAVES:3)
Block(-11,24,6,LEAVES:3)
Block(-10,24,6,LOG:15)
Block(-9,24,6,LOG:15)
Block(-8,24,6,LOG:15)
Block(-7,24,6,LEAVES:15)
Block(-6,24,6,LEAVES:15)
Block(-5,24,6,LEAVES:15)
Block(-4,24,6,LEAVES:15)
Block(-3,24,6,LEAVES:15)
Block(2,24,6,LEAVES:15)
Block(3,24,6,LEAVES:15)
Block(4,24,6,LEAVES:15)
Block(6,24,6,LEAVES:15)
Block(7,24,6,LEAVES:3)
Block(8,24,6,LOG:15)
Block(9,24,6,LEAVES:3)
Block(10,24,6,LEAVES:15)
Block(-12,24,7,LEAVES:3)
Block(-11,24,7,LEAVES:3)
Block(-10,24,7,LOG:15)
Block(-9,24,7,LOG:15)
Block(-8,24,7,LEAVES:3)
Block(-7,24,7,LEAVES:15)
Block(-6,24,7,LEAVES:15)
Block(-5,24,7,LEAVES:15)
Block(-4,24,7,LEAVES:15)
Block(-3,24,7,LEAVES:15)
Block(2,24,7,LEAVES:15)
Block(3,24,7,LEAVES:15)
Block(4,24,7,LEAVES:15)
Block(6,24,7,LEAVES:15)
Block(7,24,7,LEAVES:15)
Block(8,24,7,LEAVES:15)
Block(9,24,7,LEAVES:15)
Block(10,24,7,LEAVES:15)
Block(-13,24,8,LEAVES:3)
Block(-12,24,8,LEAVES:3)
Block(-11,24,8,LEAVES:3)
Block(-10,24,8,LEAVES:3)
Block(-9,24,8,LEAVES:3)
Block(-8,24,8,LEAVES:3)
Block(-7,24,8,LEAVES:15)
Block(-6,24,8,LEAVES:15)
Block(-5,24,8,LEAVES:15)
Block(-4,24,8,LEAVES:15)
Block(-3,24,8,LEAVES:15)
Block(4,24,8,LEAVES:15)
Block(5,24,8,LEAVES:15)
Block(6,24,8,LEAVES:15)
Block(7,24,8,LEAVES:15)
Block(8,24,8,LEAVES:15)
Block(9,24,8,LEAVES:15)
Block(-12,24,9,LEAVES:3)
Block(-10,24,9,LEAVES:3)
Block(-8,24,9,LEAVES:15)
Block(-7,24,9,LEAVES:15)
Block(-6,24,9,LEAVES:15)
Block(-5,24,9,LEAVES:15)
Block(-4,24,9,LEAVES:15)
Block(-3,24,9,LEAVES:15)
Block(4,24,9,LEAVES:15)
Block(5,24,9,LEAVES:15)
Block(6,24,9,LEAVES:15)
Block(-5,24,10,LEAVES:15)
Block(-4,24,10,LEAVES:15)
Block(-3,24,10,LEAVES:15)
Block(4,24,10,LEAVES:15)
Block(5,24,10,LEAVES:15)
Block(6,24,10,LEAVES:15)
Block(-5,24,11,LEAVES:15)
Block(-4,24,11,LEAVES:15)
Block(-3,24,11,LEAVES:15)
Block(-5,24,12,LEAVES:15)
Block(-4,24,12,LEAVES:15)
Block(-3,24,12,LEAVES:15)
Block(4,25,-16,LEAVES:15)
Block(5,25,-16,LEAVES:15)
Block(6,25,-16,LEAVES:15)
Block(3,25,-15,LEAVES:15)
Block(4,25,-15,LEAVES:15)
Block(5,25,-15,LEAVES:15)
Block(6,25,-15,LEAVES:15)
Block(-2,25,-14,LEAVES:3)
Block(0,25,-14,LEAVES:3)
Block(2,25,-14,LEAVES:15)
Block(3,25,-14,LEAVES:15)
Block(4,25,-14,LEAVES:15)
Block(5,25,-14,LEAVES:15)
Block(6,25,-14,LEAVES:3)
Block(7,25,-14,LEAVES:3)
Block(8,25,-14,LOG:15)
Block(9,25,-14,LEAVES:3)
Block(10,25,-14,LEAVES:3)
Block(-3,25,-13,LEAVES:3)
Block(-2,25,-13,LOG:15)
Block(-1,25,-13,LEAVES:3)
Block(0,25,-13,LEAVES:3)
Block(1,25,-13,LEAVES:3)
Block(3,25,-13,LEAVES:15)
Block(4,25,-13,LEAVES:15)
Block(5,25,-13,LEAVES:15)
Block(6,25,-13,LEAVES:3)
Block(7,25,-13,LOG:15)
Block(8,25,-13,LOG:15)
Block(9,25,-13,LOG:15)
Block(10,25,-13,LEAVES:3)
Block(-14,25,-12,LEAVES:3)
Block(-7,25,-12,LEAVES:15)
Block(-6,25,-12,LEAVES:15)
Block(-5,25,-12,LEAVES:15)
Block(-4,25,-12,LEAVES:3)
Block(-3,25,-12,LEAVES:3)
Block(-2,25,-12,LOG:15)
Block(-1,25,-12,LOG:15)
Block(0,25,-12,LEAVES:3)
Block(1,25,-12,LEAVES:3)
Block(3,25,-12,LEAVES:15)
Block(4,25,-12,LEAVES:15)
Block(5,25,-12,LEAVES:15)
Block(6,25,-12,LEAVES:3)
Block(7,25,-12,LEAVES:3)
Block(8,25,-12,LEAVES:3)
Block(9,25,-12,LEAVES:3)
Block(10,25,-12,LEAVES:3)
Block(-15,25,-11,LEAVES:3)
Block(-14,25,-11,LEAVES:3)
Block(-13,25,-11,LEAVES:3)
Block(-12,25,-11,LEAVES:3)
Block(-8,25,-11,LEAVES:15)
Block(-7,25,-11,LEAVES:15)
Block(-6,25,-11,LEAVES:3)
Block(-5,25,-11,LEAVES:3)
Block(-4,25,-11,LEAVES:3)
Block(-3,25,-11,LEAVES:3)
Block(-2,25,-11,LEAVES:3)
Block(-1,25,-11,LOG:15)
Block(0,25,-11,LEAVES:3)
Block(1,25,-11,LEAVES:3)
Block(3,25,-11,LEAVES:15)
Block(4,25,-11,LEAVES:15)
Block(5,25,-11,LEAVES:3)
Block(6,25,-11,LEAVES:3)
Block(7,25,-11,LEAVES:3)
Block(8,25,-11,LEAVES:3)
Block(9,25,-11,LEAVES:3)
Block(-14,25,-10,LEAVES:3)
Block(-13,25,-10,LEAVES:3)
Block(-12,25,-10,LOG:15)
Block(-11,25,-10,LOG:15)
Block(-8,25,-10,LEAVES:15)
Block(-7,25,-10,LEAVES:3)
Block(-6,25,-10,LOG:15)
Block(-5,25,-10,LOG:15)
Block(-4,25,-10,LEAVES:3)
Block(-3,25,-10,LEAVES:3)
Block(-2,25,-10,LEAVES:3)
Block(-1,25,-10,LEAVES:3)
Block(0,25,-10,LEAVES:3)
Block(4,25,-10,LEAVES:3)
Block(5,25,-10,LEAVES:3)
Block(6,25,-10,LEAVES:3)
Block(7,25,-10,LEAVES:3)
Block(8,25,-10,LEAVES:3)
Block(9,25,-10,LEAVES:3)
Block(-14,25,-9,LEAVES:3)
Block(-13,25,-9,LEAVES:3)
Block(-12,25,-9,LOG:15)
Block(-11,25,-9,LOG:15)
Block(-10,25,-9,LEAVES:3)
Block(-9,25,-9,LEAVES:15)
Block(-8,25,-9,LEAVES:15)
Block(-7,25,-9,LEAVES:3)
Block(-6,25,-9,LEAVES:3)
Block(-5,25,-9,LEAVES:3)
Block(-4,25,-9,LEAVES:3)
Block(-3,25,-9,LEAVES:3)
Block(-2,25,-9,LEAVES:3)
Block(-1,25,-9,LEAVES:3)
Block(5,25,-9,LEAVES:3)
Block(-13,25,-8,LEAVES:3)
Block(-12,25,-8,LEAVES:3)
Block(-11,25,-8,LOG:15)
Block(-10,25,-8,LOG:15)
Block(-9,25,-8,LEAVES:3)
Block(-7,25,-8,LEAVES:3)
Block(-6,25,-8,LEAVES:3)
Block(-5,25,-8,LEAVES:3)
Block(-4,25,-8,LEAVES:3)
Block(-3,25,-8,LEAVES:3)
Block(-2,25,-8,LEAVES:3)
Block(1,25,-8,LEAVES:15)
Block(-11,25,-7,LEAVES:3)
Block(-10,25,-7,LOG:15)
Block(-9,25,-7,LEAVES:3)
Block(-8,25,-7,LEAVES:3)
Block(-3,25,-7,LEAVES:3)
Block(0,25,-7,LEAVES:15)
Block(1,25,-7,LEAVES:15)
Block(2,25,-7,LEAVES:15)
Block(-10,25,-6,LEAVES:3)
Block(-9,25,-6,LEAVES:3)
Block(-3,25,-6,LEAVES:15)
Block(0,25,-6,LEAVES:15)
Block(1,25,-6,LEAVES:15)
Block(2,25,-6,LEAVES:15)
Block(6,25,-6,LEAVES:3)
Block(7,25,-6,LEAVES:3)
Block(8,25,-6,LEAVES:3)
Block(9,25,-6,LEAVES:3)
Block(-12,25,-5,LEAVES:3)
Block(-4,25,-5,LEAVES:15)
Block(-3,25,-5,LEAVES:15)
Block(-2,25,-5,LEAVES:15)
Block(-1,25,-5,LEAVES:15)
Block(0,25,-5,LEAVES:15)
Block(1,25,-5,LEAVES:15)
Block(2,25,-5,LEAVES:15)
Block(3,25,-5,LEAVES:15)
Block(4,25,-5,LEAVES:15)
Block(5,25,-5,LEAVES:15)
Block(6,25,-5,LEAVES:3)
Block(7,25,-5,LOG:15)
Block(8,25,-5,LOG:15)
Block(9,25,-5,LEAVES:3)
Block(-13,25,-4,LEAVES:3)
Block(-12,25,-4,LEAVES:3)
Block(-11,25,-4,LEAVES:3)
Block(-6,25,-4,LEAVES:15)
Block(-5,25,-4,LEAVES:15)
Block(-4,25,-4,LEAVES:15)
Block(-3,25,-4,LEAVES:15)
Block(-2,25,-4,LEAVES:15)
Block(-1,25,-4,LEAVES:15)
Block(0,25,-4,LEAVES:15)
Block(1,25,-4,LEAVES:15)
Block(2,25,-4,LEAVES:15)
Block(3,25,-4,LEAVES:15)
Block(4,25,-4,LEAVES:15)
Block(5,25,-4,LEAVES:15)
Block(6,25,-4,LEAVES:3)
Block(7,25,-4,LEAVES:3)
Block(8,25,-4,LOG:15)
Block(9,25,-4,LOG:15)
Block(10,25,-4,LEAVES:15)
Block(-13,25,-3,LEAVES:3)
Block(-12,25,-3,LOG:15)
Block(-11,25,-3,LOG:15)
Block(-10,25,-3,LEAVES:3)
Block(-9,25,-3,LEAVES:15)
Block(-8,25,-3,LEAVES:15)
Block(-7,25,-3,LEAVES:15)
Block(-6,25,-3,LEAVES:15)
Block(-5,25,-3,LEAVES:15)
Block(-4,25,-3,LEAVES:15)
Block(-3,25,-3,LEAVES:15)
Block(-2,25,-3,LEAVES:15)
Block(-1,25,-3,LEAVES:15)
Block(0,25,-3,LEAVES:15)
Block(1,25,-3,LEAVES:15)
Block(2,25,-3,LEAVES:15)
Block(3,25,-3,LEAVES:15)
Block(4,25,-3,LEAVES:15)
Block(5,25,-3,LEAVES:15)
Block(6,25,-3,LEAVES:3)
Block(7,25,-3,LEAVES:3)
Block(8,25,-3,LEAVES:3)
Block(9,25,-3,LEAVES:3)
Block(10,25,-3,LEAVES:3)
Block(-13,25,-2,LEAVES:3)
Block(-12,25,-2,LEAVES:3)
Block(-11,25,-2,LEAVES:3)
Block(-10,25,-2,LEAVES:3)
Block(-9,25,-2,LEAVES:15)
Block(-8,25,-2,LEAVES:15)
Block(-6,25,-2,LEAVES:15)
Block(-5,25,-2,LEAVES:15)
Block(-4,25,-2,LEAVES:15)
Block(1,25,-2,LEAVES:15)
Block(2,25,-2,LEAVES:15)
Block(3,25,-2,LEAVES:15)
Block(4,25,-2,LEAVES:15)
Block(5,25,-2,LEAVES:3)
Block(6,25,-2,LEAVES:3)
Block(7,25,-2,LEAVES:3)
Block(8,25,-2,LOG:15)
Block(9,25,-2,LOG:15)
Block(10,25,-2,LEAVES:3)
Block(-13,25,-1,LEAVES:3)
Block(-12,25,-1,LEAVES:3)
Block(-11,25,-1,LEAVES:3)
Block(-10,25,-1,LEAVES:3)
Block(-9,25,-1,LEAVES:15)
Block(-8,25,-1,LEAVES:15)
Block(-2,25,-1,LEAVES:15)
Block(-1,25,-1,LEAVES:15)
Block(0,25,-1,LEAVES:15)
Block(2,25,-1,LEAVES:15)
Block(3,25,-1,LEAVES:15)
Block(4,25,-1,LEAVES:15)
Block(5,25,-1,LEAVES:15)
Block(6,25,-1,LEAVES:3)
Block(7,25,-1,LEAVES:3)
Block(8,25,-1,LEAVES:3)
Block(9,25,-1,LEAVES:3)
Block(10,25,-1,LEAVES:3)
Block(11,25,-1,LEAVES:3)
Block(-13,25,0,LOG:15)
Block(-12,25,0,LEAVES:3)
Block(-11,25,0,LEAVES:3)
Block(-10,25,0,LEAVES:3)
Block(-6,25,0,LEAVES:15)
Block(-5,25,0,LEAVES:15)
Block(-4,25,0,LEAVES:15)
Block(-3,25,0,LEAVES:15)
Block(-2,25,0,LEAVES:15)
Block(-1,25,0,LEAVES:15)
Block(0,25,0,LEAVES:15)
Block(1,25,0,LEAVES:15)
Block(2,25,0,LEAVES:15)
Block(3,25,0,LEAVES:15)
Block(4,25,0,LEAVES:15)
Block(5,25,0,LEAVES:15)
Block(6,25,0,LEAVES:15)
Block(7,25,0,LEAVES:3)
Block(8,25,0,LEAVES:3)
Block(9,25,0,LOG:15)
Block(10,25,0,LOG:15)
Block(11,25,0,LEAVES:3)
Block(-14,25,1,LEAVES:3)
Block(-13,25,1,LOG:15)
Block(-12,25,1,LOG:15)
Block(-11,25,1,LEAVES:3)
Block(-10,25,1,LEAVES:3)
Block(-7,25,1,LEAVES:15)
Block(-6,25,1,LEAVES:15)
Block(-5,25,1,LEAVES:15)
Block(-4,25,1,LEAVES:15)
Block(-3,25,1,LEAVES:15)
Block(-2,25,1,LEAVES:15)
Block(-1,25,1,LEAVES:15)
Block(0,25,1,LEAVES:15)
Block(1,25,1,LEAVES:15)
Block(2,25,1,LEAVES:15)
Block(3,25,1,LEAVES:15)
Block(4,25,1,LEAVES:15)
Block(5,25,1,LEAVES:15)
Block(6,25,1,LEAVES:15)
Block(7,25,1,LEAVES:3)
Block(8,25,1,LOG:15)
Block(9,25,1,LOG:15)
Block(10,25,1,LEAVES:3)
Block(11,25,1,LEAVES:3)
Block(-15,25,2,LEAVES:3)
Block(-14,25,2,LEAVES:3)
Block(-13,25,2,LEAVES:3)
Block(-12,25,2,LEAVES:3)
Block(-11,25,2,LEAVES:3)
Block(-10,25,2,LEAVES:3)
Block(-9,25,2,LEAVES:3)
Block(-6,25,2,LEAVES:15)
Block(-5,25,2,LEAVES:15)
Block(-4,25,2,LEAVES:15)
Block(-3,25,2,LEAVES:15)
Block(-2,25,2,LEAVES:15)
Block(-1,25,2,LEAVES:15)
Block(0,25,2,LEAVES:15)
Block(1,25,2,LEAVES:15)
Block(2,25,2,LEAVES:15)
Block(3,25,2,LEAVES:15)
Block(4,25,2,LEAVES:15)
Block(5,25,2,LEAVES:15)
Block(6,25,2,LEAVES:15)
Block(7,25,2,LEAVES:15)
Block(8,25,2,LEAVES:3)
Block(9,25,2,LEAVES:15)
Block(10,25,2,LEAVES:15)
Block(-14,25,3,LEAVES:3)
Block(-13,25,3,LEAVES:3)
Block(-12,25,3,LEAVES:3)
Block(-11,25,3,LEAVES:3)
Block(-10,25,3,LEAVES:3)
Block(-9,25,3,LEAVES:3)
Block(-7,25,3,LEAVES:15)
Block(-6,25,3,LEAVES:15)
Block(-5,25,3,LEAVES:15)
Block(-4,25,3,LEAVES:15)
Block(-3,25,3,LEAVES:15)
Block(-2,25,3,LEAVES:15)
Block(-1,25,3,LEAVES:15)
Block(0,25,3,LEAVES:15)
Block(1,25,3,LEAVES:15)
Block(2,25,3,LEAVES:15)
Block(3,25,3,LEAVES:15)
Block(4,25,3,LEAVES:15)
Block(5,25,3,LEAVES:15)
Block(6,25,3,LEAVES:15)
Block(7,25,3,LEAVES:3)
Block(8,25,3,LEAVES:15)
Block(9,25,3,LEAVES:3)
Block(10,25,3,LEAVES:15)
Block(-13,25,4,LEAVES:3)
Block(-12,25,4,LEAVES:3)
Block(-11,25,4,LEAVES:3)
Block(-10,25,4,LEAVES:3)
Block(-9,25,4,LEAVES:7)
Block(-8,25,4,LEAVES:7)
Block(-7,25,4,LEAVES:15)
Block(-6,25,4,LEAVES:15)
Block(-5,25,4,LEAVES:15)
Block(-4,25,4,LEAVES:15)
Block(-3,25,4,LEAVES:15)
Block(-2,25,4,LEAVES:15)
Block(-1,25,4,LEAVES:15)
Block(0,25,4,LEAVES:15)
Block(1,25,4,LEAVES:15)
Block(2,25,4,LEAVES:15)
Block(3,25,4,LEAVES:15)
Block(4,25,4,LEAVES:15)
Block(5,25,4,LEAVES:15)
Block(6,25,4,LEAVES:3)
Block(7,25,4,LEAVES:3)
Block(8,25,4,LEAVES:3)
Block(9,25,4,LEAVES:3)
Block(10,25,4,LEAVES:3)
Block(-13,25,5,LEAVES:3)
Block(-12,25,5,LEAVES:3)
Block(-11,25,5,LEAVES:3)
Block(-10,25,5,LEAVES:3)
Block(-9,25,5,LEAVES:3)
Block(-8,25,5,LEAVES:15)
Block(-7,25,5,LEAVES:15)
Block(-6,25,5,LEAVES:15)
Block(-5,25,5,LEAVES:15)
Block(-4,25,5,LEAVES:15)
Block(-3,25,5,LEAVES:15)
Block(1,25,5,LEAVES:15)
Block(2,25,5,LEAVES:15)
Block(3,25,5,LEAVES:15)
Block(4,25,5,LEAVES:15)
Block(5,25,5,LEAVES:15)
Block(6,25,5,LEAVES:3)
Block(7,25,5,LEAVES:3)
Block(8,25,5,LOG:15)
Block(9,25,5,LOG:15)
Block(10,25,5,LEAVES:3)
Block(11,25,5,LEAVES:3)
Block(-13,25,6,LEAVES:3)
Block(-12,25,6,LEAVES:3)
Block(-11,25,6,LEAVES:3)
Block(-10,25,6,LEAVES:3)
Block(-9,25,6,LEAVES:3)
Block(-8,25,6,LEAVES:3)
Block(-7,25,6,LEAVES:15)
Block(-6,25,6,LEAVES:15)
Block(-5,25,6,LEAVES:15)
Block(-4,25,6,LEAVES:15)
Block(-3,25,6,LEAVES:15)
Block(1,25,6,LEAVES:15)
Block(2,25,6,LEAVES:15)
Block(3,25,6,LEAVES:15)
Block(4,25,6,LEAVES:15)
Block(5,25,6,LEAVES:15)
Block(6,25,6,LEAVES:15)
Block(7,25,6,LEAVES:3)
Block(8,25,6,LEAVES:3)
Block(9,25,6,LOG:15)
Block(10,25,6,LEAVES:3)
Block(-13,25,7,LEAVES:3)
Block(-12,25,7,LEAVES:3)
Block(-11,25,7,LOG:15)
Block(-10,25,7,LOG:15)
Block(-9,25,7,LEAVES:3)
Block(-8,25,7,LEAVES:3)
Block(-7,25,7,LEAVES:15)
Block(-6,25,7,LEAVES:15)
Block(-5,25,7,LEAVES:15)
Block(-4,25,7,LEAVES:15)
Block(-3,25,7,LEAVES:15)
Block(-2,25,7,LEAVES:15)
Block(1,25,7,LEAVES:15)
Block(2,25,7,LEAVES:15)
Block(3,25,7,LEAVES:15)
Block(4,25,7,LEAVES:15)
Block(5,25,7,LEAVES:15)
Block(6,25,7,LEAVES:15)
Block(7,25,7,LEAVES:15)
Block(8,25,7,LEAVES:15)
Block(9,25,7,LOG:15)
Block(10,25,7,LEAVES:15)
Block(-13,25,8,LEAVES:3)
Block(-12,25,8,LEAVES:3)
Block(-11,25,8,LOG:15)
Block(-10,25,8,LEAVES:3)
Block(-9,25,8,LEAVES:3)
Block(-8,25,8,LEAVES:15)
Block(-7,25,8,LEAVES:15)
Block(-6,25,8,LEAVES:15)
Block(-5,25,8,LEAVES:15)
Block(-4,25,8,LEAVES:15)
Block(-3,25,8,LEAVES:15)
Block(-2,25,8,LEAVES:15)
Block(-1,25,8,LEAVES:15)
Block(2,25,8,LEAVES:15)
Block(3,25,8,LEAVES:15)
Block(4,25,8,LEAVES:15)
Block(5,25,8,LEAVES:15)
Block(6,25,8,LEAVES:15)
Block(7,25,8,LEAVES:15)
Block(8,25,8,LEAVES:15)
Block(9,25,8,LEAVES:15)
Block(-13,25,9,LEAVES:3)
Block(-12,25,9,LEAVES:3)
Block(-11,25,9,LEAVES:3)
Block(-10,25,9,LEAVES:3)
Block(-9,25,9,LEAVES:3)
Block(-8,25,9,LEAVES:15)
Block(-7,25,9,LEAVES:15)
Block(-6,25,9,LEAVES:15)
Block(-5,25,9,LEAVES:15)
Block(-4,25,9,LEAVES:15)
Block(-3,25,9,LEAVES:15)
Block(-2,25,9,LEAVES:15)
Block(3,25,9,LEAVES:15)
Block(4,25,9,LEAVES:15)
Block(5,25,9,LEAVES:15)
Block(6,25,9,LEAVES:15)
Block(7,25,9,LEAVES:15)
Block(-10,25,10,LEAVES:15)
Block(-8,25,10,LEAVES:15)
Block(-7,25,10,LEAVES:15)
Block(-6,25,10,LEAVES:15)
Block(-5,25,10,LEAVES:15)
Block(-4,25,10,LEAVES:15)
Block(-3,25,10,LEAVES:15)
Block(-2,25,10,LEAVES:15)
Block(3,25,10,LEAVES:15)
Block(4,25,10,LEAVES:15)
Block(5,25,10,LEAVES:15)
Block(6,25,10,LEAVES:15)
Block(7,25,10,LEAVES:15)
Block(-7,25,11,LEAVES:15)
Block(-6,25,11,LEAVES:15)
Block(-5,25,11,LEAVES:15)
Block(-4,25,11,LEAVES:15)
Block(-3,25,11,LEAVES:15)
Block(-2,25,11,LEAVES:15)
Block(4,25,11,LEAVES:15)
Block(5,25,11,LEAVES:15)
Block(6,25,11,LEAVES:15)
Block(-6,25,12,LEAVES:15)
Block(-5,25,12,LEAVES:15)
Block(-4,25,12,LEAVES:15)
Block(-3,25,12,LEAVES:15)
Block(-2,25,12,LEAVES:15)
Block(-5,25,13,LEAVES:15)
Block(-4,25,13,LEAVES:15)
Block(-3,25,13,LEAVES:15)
Block(-4,25,14,LEAVES:15)
Block(5,26,-16,LEAVES:15)
Block(2,26,-15,LEAVES:15)
Block(3,26,-15,LEAVES:15)
Block(4,26,-15,LEAVES:15)
Block(5,26,-15,LEAVES:15)
Block(6,26,-15,LEAVES:15)
Block(8,26,-15,LEAVES:15)
Block(-3,26,-14,LEAVES:3)
Block(-2,26,-14,LEAVES:3)
Block(-1,26,-14,LEAVES:3)
Block(0,26,-14,LEAVES:3)
Block(1,26,-14,LEAVES:3)
Block(2,26,-14,LEAVES:15)
Block(3,26,-14,LEAVES:15)
Block(4,26,-14,LEAVES:15)
Block(5,26,-14,LEAVES:15)
Block(6,26,-14,LEAVES:15)
Block(7,26,-14,LEAVES:3)
Block(8,26,-14,LEAVES:15)
Block(9,26,-14,LEAVES:3)
Block(-6,26,-13,LEAVES:15)
Block(-4,26,-13,LEAVES:3)
Block(-3,26,-13,LEAVES:3)
Block(-2,26,-13,LOG:15)
Block(-1,26,-13,LEAVES:3)
Block(0,26,-13,LEAVES:3)
Block(1,26,-13,LEAVES:3)
Block(2,26,-13,LEAVES:15)
Block(3,26,-13,LEAVES:15)
Block(4,26,-13,LEAVES:15)
Block(5,26,-13,LEAVES:15)
Block(6,26,-13,LEAVES:3)
Block(7,26,-13,LEAVES:3)
Block(8,26,-13,LEAVES:3)
Block(9,26,-13,LEAVES:3)
Block(10,26,-13,LEAVES:3)
Block(-15,26,-12,LEAVES:3)
Block(-14,26,-12,LEAVES:3)
Block(-13,26,-12,LEAVES:3)
Block(-9,26,-12,LEAVES:15)
Block(-8,26,-12,LEAVES:15)
Block(-7,26,-12,LEAVES:15)
Block(-6,26,-12,LEAVES:3)
Block(-5,26,-12,LEAVES:15)
Block(-3,26,-12,LEAVES:3)
Block(-2,26,-12,LEAVES:3)
Block(-1,26,-12,LEAVES:3)
Block(0,26,-12,LEAVES:3)
Block(1,26,-12,LEAVES:3)
Block(2,26,-12,LEAVES:15)
Block(3,26,-12,LEAVES:15)
Block(4,26,-12,LEAVES:15)
Block(5,26,-12,LEAVES:15)
Block(6,26,-12,LEAVES:3)
Block(7,26,-12,LEAVES:3)
Block(8,26,-12,LEAVES:3)
Block(9,26,-12,LEAVES:3)
Block(10,26,-12,LEAVES:15)
Block(-15,26,-11,LEAVES:3)
Block(-14,26,-11,LEAVES:3)
Block(-13,26,-11,LOG:15)
Block(-12,26,-11,LEAVES:3)
Block(-11,26,-11,LEAVES:3)
Block(-10,26,-11,LEAVES:15)
Block(-9,26,-11,LEAVES:15)
Block(-8,26,-11,LEAVES:15)
Block(-7,26,-11,LEAVES:3)
Block(-6,26,-11,LOG:15)
Block(-5,26,-11,LEAVES:3)
Block(-4,26,-11,LEAVES:3)
Block(-3,26,-11,LEAVES:3)
Block(-2,26,-11,LEAVES:3)
Block(-1,26,-11,LEAVES:3)
