Author: BO3 BulkEdit (by LanToaster)
Description: This Object was Created with BO3_BulkEdit
Version: 3
SettingsMode: WriteDisable
Tree: true
Frequency: 1
Rarity: 100.0
RotateRandomly: true
SpawnHeight: randomY
MinHeight: 17
MaxHeight: 17
MaxBranchDepth: 10
ExcludedBiomes: All
SourceBlocks: AIR,GRASS,DIRT,SAND,STONE,WATER
MaxPercentageOutsideSourceBlock: 4
OutsideSourceBlock: dontPlace
Block(-15,-11,-17,LOG:15)
Block(-16,-11,-16,LOG:15)
Block(-15,-11,-16,LOG:15)
Block(-14,-11,-16,LOG:15)
Block(-10,-11,-16,LOG:15)
Block(12,-11,-16,LOG:15)
Block(-16,-11,-15,LOG:15)
Block(-15,-11,-15,LOG:15)
Block(-14,-11,-15,LOG:15)
Block(-13,-11,-15,LOG:15)
Block(-9,-11,-15,LOG:15)
Block(-8,-11,-15,LOG:15)
Block(11,-11,-15,LOG:15)
Block(13,-11,-15,LOG:15)
Block(-15,-11,-14,LOG:15)
Block(-14,-11,-14,LOG:15)
Block(-13,-11,-14,LOG:15)
Block(-12,-11,-14,LOG:15)
Block(-10,-11,-14,LOG:15)
Block(-9,-11,-14,LOG:15)
Block(-8,-11,-14,LOG:15)
Block(-7,-11,-14,LOG:15)
Block(10,-11,-14,LOG:15)
Block(11,-11,-14,LOG:15)
Block(12,-11,-14,LOG:15)
Block(13,-11,-14,LOG:15)
Block(-14,-11,-13,LOG:15)
Block(-13,-11,-13,LOG:15)
Block(-9,-11,-13,LOG:15)
Block(-8,-11,-13,LOG:15)
Block(11,-11,-13,LOG:15)
Block(12,-11,-13,LOG:15)
Block(-11,-11,-12,LOG:15)
Block(-6,-11,-12,LOG:15)
Block(9,-11,-12,LOG:15)
Block(-13,-11,-11,LOG:15)
Block(7,-11,-11,LOG:15)
Block(-4,-11,-10,LOG:15)
Block(-12,-11,-9,LOG:15)
Block(-11,-11,-7,LOG:15)
Block(-11,-11,-5,LOG:15)
Block(13,-11,-5,LOG:15)
Block(12,-11,-4,LOG:15)
Block(13,-11,-4,LOG:15)
Block(14,-11,-4,LOG:15)
Block(10,-11,-3,LOG:15)
Block(13,-11,-3,LOG:15)
Block(14,-11,-3,LOG:15)
Block(-12,-11,-2,LOG:15)
Block(-11,-11,-2,LOG:15)
Block(12,-11,-2,LOG:15)
Block(13,-11,-2,LOG:15)
Block(-13,-11,-1,LOG:15)
Block(-12,-11,-1,LOG:15)
Block(-11,-11,-1,LOG:15)
Block(8,-11,-1,LOG:15)
Block(11,-11,-1,LOG:15)
Block(12,-11,-1,LOG:15)
Block(13,-11,-1,LOG:15)
Block(14,-11,-1,LOG:15)
Block(-13,-11,0,LOG:15)
Block(-12,-11,0,LOG:15)
Block(-11,-11,0,LOG:15)
Block(-8,-11,0,LOG:15)
Block(12,-11,0,LOG:15)
Block(13,-11,0,LOG:15)
Block(-14,-11,1,LOG:15)
Block(-12,-11,1,LOG:15)
Block(-6,-11,1,LOG:15)
Block(-14,-11,2,LOG:15)
Block(-7,-11,2,LOG:15)
Block(-10,-11,4,LOG:15)
Block(-8,-11,4,LOG:15)
Block(12,-11,5,LOG:15)
Block(13,-11,5,LOG:15)
Block(-11,-11,6,LOG:15)
Block(11,-11,6,LOG:15)
Block(12,-11,6,LOG:15)
Block(13,-11,6,LOG:15)
Block(-13,-11,7,LOG:15)
Block(10,-11,7,LOG:15)
Block(11,-11,7,LOG:15)
Block(12,-11,7,LOG:15)
Block(9,-11,8,LOG:15)
Block(10,-11,8,LOG:15)
Block(11,-11,8,LOG:15)
Block(12,-11,8,LOG:15)
Block(9,-11,9,LOG:15)
Block(10,-11,9,LOG:15)
Block(11,-11,9,LOG:15)
Block(-13,-11,10,LOG:15)
Block(7,-11,10,LOG:15)
Block(10,-11,10,LOG:15)
Block(-1,-11,11,LOG:15)
Block(0,-11,11,LOG:15)
Block(1,-11,11,LOG:15)
Block(12,-11,11,LOG:15)
Block(-14,-11,12,LOG:15)
Block(-13,-11,12,LOG:15)
Block(-2,-11,12,LOG:15)
Block(-1,-11,12,LOG:15)
Block(0,-11,12,LOG:15)
Block(1,-11,12,LOG:15)
Block(2,-11,12,LOG:15)
Block(5,-11,12,LOG:15)
Block(-16,-11,13,LOG:15)
Block(-15,-11,13,LOG:15)
Block(-14,-11,13,LOG:15)
Block(-13,-11,13,LOG:15)
Block(-1,-11,13,LOG:15)
Block(0,-11,13,LOG:15)
Block(1,-11,13,LOG:15)
Block(8,-11,13,LOG:15)
Block(-15,-11,14,LOG:15)
Block(-14,-11,14,LOG:15)
Block(-15,-10,-16,LOG:15)
Block(-15,-10,-15,LOG:15)
Block(-14,-10,-15,LOG:15)
Block(-13,-10,-15,LOG:15)
Block(-8,-10,-15,LOG:15)
Block(-7,-10,-15,LOG:15)
Block(11,-10,-15,LOG:15)
Block(-14,-10,-14,LOG:15)
Block(-13,-10,-14,LOG:15)
Block(-12,-10,-14,LOG:15)
Block(-9,-10,-14,LOG:15)
Block(-8,-10,-14,LOG:15)
Block(-7,-10,-14,LOG:15)
Block(-6,-10,-14,LOG:15)
Block(10,-10,-14,LOG:15)
Block(11,-10,-14,LOG:15)
Block(12,-10,-14,LOG:15)
Block(-13,-10,-13,LOG:15)
Block(-8,-10,-13,LOG:15)
Block(-7,-10,-13,LOG:15)
Block(-6,-10,-13,LOG:15)
Block(11,-10,-13,LOG:15)
Block(-11,-10,-12,LOG:15)
Block(-6,-10,-12,LOG:15)
Block(9,-10,-12,LOG:15)
Block(-13,-10,-11,LOG:15)
Block(7,-10,-11,LOG:15)
Block(-4,-10,-10,LOG:15)
Block(-12,-10,-9,LOG:15)
Block(6,-10,-8,LOG:15)
Block(-11,-10,-7,LOG:15)
Block(-11,-10,-5,LOG:15)
Block(-10,-10,-5,LOG:15)
Block(13,-10,-4,LOG:15)
Block(-11,-10,-3,LOG:15)
Block(10,-10,-3,LOG:15)
Block(12,-10,-3,LOG:15)
Block(-12,-10,-2,LOG:15)
Block(-11,-10,-2,LOG:15)
Block(-10,-10,-2,LOG:15)
Block(11,-10,-2,LOG:15)
Block(12,-10,-2,LOG:15)
Block(13,-10,-2,LOG:15)
Block(-12,-10,-1,LOG:15)
Block(-11,-10,-1,LOG:15)
Block(-10,-10,-1,LOG:15)
Block(8,-10,-1,LOG:15)
Block(10,-10,-1,LOG:15)
Block(11,-10,-1,LOG:15)
Block(12,-10,-1,LOG:15)
Block(13,-10,-1,LOG:15)
Block(-12,-10,0,LOG:15)
Block(-11,-10,0,LOG:15)
Block(-8,-10,0,LOG:15)
Block(11,-10,0,LOG:15)
Block(12,-10,0,LOG:15)
Block(-6,-10,1,LOG:15)
Block(-7,-10,2,LOG:15)
Block(-9,-10,4,LOG:15)
Block(-8,-10,4,LOG:15)
Block(-11,-10,6,LOG:15)
Block(12,-10,6,LOG:15)
Block(-13,-10,7,LOG:15)
Block(10,-10,7,LOG:15)
Block(-11,-10,8,LOG:15)
Block(9,-10,8,LOG:15)
Block(10,-10,8,LOG:15)
Block(11,-10,8,LOG:15)
Block(4,-10,9,LOG:15)
Block(9,-10,9,LOG:15)
Block(10,-10,9,LOG:15)
Block(11,-10,9,LOG:15)
Block(-13,-10,10,LOG:15)
Block(7,-10,10,LOG:15)
Block(10,-10,10,LOG:15)
Block(-14,-10,11,LOG:15)
Block(-13,-10,11,LOG:15)
Block(1,-10,11,LOG:15)
Block(12,-10,11,LOG:15)
Block(-14,-10,12,LOG:15)
Block(-13,-10,12,LOG:15)
Block(-12,-10,12,LOG:15)
Block(-1,-10,12,LOG:15)
Block(0,-10,12,LOG:15)
Block(1,-10,12,LOG:15)
Block(2,-10,12,LOG:15)
Block(5,-10,12,LOG:15)
Block(-15,-10,13,LOG:15)
Block(-14,-10,13,LOG:15)
Block(-13,-10,13,LOG:15)
Block(0,-10,13,LOG:15)
Block(1,-10,13,LOG:15)
Block(2,-10,13,LOG:15)
Block(8,-10,13,LOG:15)
Block(-14,-10,14,LOG:15)
Block(-13,-9,-15,LOG:15)
Block(-7,-9,-15,LOG:15)
Block(11,-9,-15,LOG:15)
Block(-14,-9,-14,LOG:15)
Block(-13,-9,-14,LOG:15)
Block(-12,-9,-14,LOG:15)
Block(-8,-9,-14,LOG:15)
Block(-7,-9,-14,LOG:15)
Block(-6,-9,-14,LOG:15)
Block(10,-9,-14,LOG:15)
Block(11,-9,-14,LOG:15)
Block(12,-9,-14,LOG:15)
Block(-14,-9,-13,LOG:15)
Block(-13,-9,-13,LOG:15)
Block(-12,-9,-13,LOG:15)
Block(-8,-9,-13,LOG:15)
Block(-7,-9,-13,LOG:15)
Block(-6,-9,-13,LOG:15)
Block(-5,-9,-13,LOG:15)
Block(10,-9,-13,LOG:15)
Block(11,-9,-13,LOG:15)
Block(12,-9,-13,LOG:15)
Block(-13,-9,-12,LOG:15)
Block(-12,-9,-12,LOG:15)
Block(-11,-9,-12,LOG:15)
Block(-7,-9,-12,LOG:15)
Block(-6,-9,-12,LOG:15)
Block(-5,-9,-12,LOG:15)
Block(9,-9,-12,LOG:15)
Block(10,-9,-12,LOG:15)
Block(11,-9,-12,LOG:15)
Block(-13,-9,-11,LOG:15)
Block(-12,-9,-11,LOG:15)
Block(7,-9,-11,LOG:15)
Block(9,-9,-11,LOG:15)
Block(-4,-9,-10,LOG:15)
Block(-2,-9,-10,LOG:15)
Block(-12,-9,-9,LOG:15)
Block(-11,-9,-9,LOG:15)
Block(8,-9,-9,LOG:15)
Block(6,-9,-8,LOG:15)
Block(-11,-9,-7,LOG:15)
Block(-1,-9,-7,LOG:15)
Block(-10,-9,-5,LOG:15)
Block(12,-9,-4,LOG:15)
Block(-11,-9,-3,LOG:15)
Block(-10,-9,-3,LOG:15)
Block(10,-9,-3,LOG:15)
Block(11,-9,-3,LOG:15)
Block(12,-9,-3,LOG:15)
Block(13,-9,-3,LOG:15)
Block(-12,-9,-2,LOG:15)
Block(-11,-9,-2,LOG:15)
Block(-10,-9,-2,LOG:15)
Block(-9,-9,-2,LOG:15)
Block(11,-9,-2,LOG:15)
Block(12,-9,-2,LOG:15)
Block(13,-9,-2,LOG:15)
Block(-12,-9,-1,LOG:15)
Block(-11,-9,-1,LOG:15)
Block(-10,-9,-1,LOG:15)
Block(8,-9,-1,LOG:15)
Block(10,-9,-1,LOG:15)
Block(11,-9,-1,LOG:15)
Block(12,-9,-1,LOG:15)
Block(-11,-9,0,LOG:15)
Block(-8,-9,0,LOG:15)
Block(11,-9,0,LOG:15)
Block(-6,-9,1,LOG:15)
Block(-7,-9,2,LOG:15)
Block(-8,-9,4,LOG:15)
Block(1,-9,5,LOG:15)
Block(-10,-9,6,LOG:15)
Block(-13,-9,7,LOG:15)
Block(-11,-9,8,LOG:15)
Block(10,-9,8,LOG:15)
Block(4,-9,9,LOG:15)
Block(9,-9,9,LOG:15)
Block(10,-9,9,LOG:15)
Block(11,-9,9,LOG:15)
Block(-13,-9,10,LOG:15)
Block(-12,-9,10,LOG:15)
Block(7,-9,10,LOG:15)
Block(9,-9,10,LOG:15)
Block(10,-9,10,LOG:15)
Block(11,-9,10,LOG:15)
Block(-14,-9,11,LOG:15)
Block(-13,-9,11,LOG:15)
Block(-12,-9,11,LOG:15)
Block(0,-9,11,LOG:15)
Block(1,-9,11,LOG:15)
Block(10,-9,11,LOG:15)
Block(11,-9,11,LOG:15)
Block(12,-9,11,LOG:15)
Block(-14,-9,12,LOG:15)
Block(-13,-9,12,LOG:15)
Block(-12,-9,12,LOG:15)
Block(0,-9,12,LOG:15)
Block(1,-9,12,LOG:15)
Block(2,-9,12,LOG:15)
Block(5,-9,12,LOG:15)
Block(8,-9,12,LOG:15)
Block(-14,-9,13,LOG:15)
Block(-13,-9,13,LOG:15)
Block(1,-9,13,LOG:15)
Block(8,-9,13,LOG:15)
Block(-13,-8,-14,LOG:15)
Block(-7,-8,-14,LOG:15)
Block(-6,-8,-14,LOG:15)
Block(10,-8,-14,LOG:15)
Block(11,-8,-14,LOG:15)
Block(-14,-8,-13,LOG:15)
Block(-13,-8,-13,LOG:15)
Block(-12,-8,-13,LOG:15)
Block(-7,-8,-13,LOG:15)
Block(-6,-8,-13,LOG:15)
Block(-5,-8,-13,LOG:15)
Block(9,-8,-13,LOG:15)
Block(10,-8,-13,LOG:15)
Block(11,-8,-13,LOG:15)
Block(12,-8,-13,LOG:15)
Block(-14,-8,-12,LOG:15)
Block(-13,-8,-12,LOG:15)
Block(-12,-8,-12,LOG:15)
Block(-11,-8,-12,LOG:15)
Block(-7,-8,-12,LOG:15)
Block(-6,-8,-12,LOG:15)
Block(-5,-8,-12,LOG:15)
Block(-4,-8,-12,LOG:15)
Block(8,-8,-12,LOG:15)
Block(9,-8,-12,LOG:15)
Block(10,-8,-12,LOG:15)
Block(11,-8,-12,LOG:15)
Block(-13,-8,-11,LOG:15)
Block(-12,-8,-11,LOG:15)
Block(-11,-8,-11,LOG:15)
Block(-6,-8,-11,LOG:15)
Block(-5,-8,-11,LOG:15)
Block(7,-8,-11,LOG:15)
Block(8,-8,-11,LOG:15)
Block(9,-8,-11,LOG:15)
Block(10,-8,-11,LOG:15)
Block(-12,-8,-10,LOG:15)
Block(-11,-8,-10,LOG:15)
Block(-9,-8,-10,LOG:15)
Block(-4,-8,-10,LOG:15)
Block(-2,-8,-10,LOG:15)
Block(8,-8,-10,LOG:15)
Block(9,-8,-10,LOG:15)
Block(-11,-8,-9,LOG:15)
Block(8,-8,-9,LOG:15)
Block(-8,-8,-8,LOG:15)
Block(6,-8,-8,LOG:15)
Block(-11,-8,-7,LOG:15)
Block(-10,-8,-7,LOG:15)
Block(-1,-8,-7,LOG:15)
Block(4,-8,-6,LOG:15)
Block(6,-8,-6,LOG:15)
Block(-10,-8,-5,LOG:15)
Block(2,-8,-5,LOG:15)
Block(-10,-8,-4,LOG:15)
Block(-7,-8,-4,LOG:15)
Block(4,-8,-4,LOG:15)
Block(8,-8,-4,LOG:15)
Block(-10,-8,-3,LOG:15)
Block(1,-8,-3,LOG:15)
Block(12,-8,-3,LOG:15)
Block(-11,-8,-2,LOG:15)
Block(-10,-8,-2,LOG:15)
Block(-9,-8,-2,LOG:15)
Block(-5,-8,-2,LOG:15)
Block(11,-8,-2,LOG:15)
Block(12,-8,-2,LOG:15)
Block(-11,-8,-1,LOG:15)
Block(-10,-8,-1,LOG:15)
Block(8,-8,-1,LOG:15)
Block(10,-8,-1,LOG:15)
Block(11,-8,-1,LOG:15)
Block(12,-8,-1,LOG:15)
Block(-9,-8,0,LOG:15)
Block(-8,-8,0,LOG:15)
Block(0,-8,0,LOG:15)
Block(11,-8,0,LOG:15)
Block(-6,-8,1,LOG:15)
Block(-7,-8,3,LOG:15)
Block(1,-8,5,LOG:15)
Block(-13,-8,7,LOG:15)
Block(-12,-8,7,LOG:15)
Block(-9,-8,7,LOG:15)
Block(-11,-8,8,LOG:15)
Block(-12,-8,9,LOG:15)
Block(4,-8,9,LOG:15)
Block(9,-8,9,LOG:15)
Block(10,-8,9,LOG:15)
Block(-13,-8,10,LOG:15)
Block(-12,-8,10,LOG:15)
Block(-11,-8,10,LOG:15)
Block(7,-8,10,LOG:15)
Block(8,-8,10,LOG:15)
Block(9,-8,10,LOG:15)
Block(10,-8,10,LOG:15)
Block(11,-8,10,LOG:15)
Block(-14,-8,11,LOG:15)
Block(-13,-8,11,LOG:15)
Block(-12,-8,11,LOG:15)
Block(-11,-8,11,LOG:15)
Block(1,-8,11,LOG:15)
Block(2,-8,11,LOG:15)
Block(9,-8,11,LOG:15)
Block(10,-8,11,LOG:15)
Block(-13,-8,12,LOG:15)
Block(-12,-8,12,LOG:15)
Block(0,-8,12,LOG:15)
Block(1,-8,12,LOG:15)
Block(2,-8,12,LOG:15)
Block(3,-8,12,LOG:15)
Block(5,-8,12,LOG:15)
Block(8,-8,12,LOG:15)
Block(1,-8,13,LOG:15)
Block(2,-8,13,LOG:15)
Block(-13,-7,-13,LOG:15)
Block(-6,-7,-13,LOG:15)
Block(-5,-7,-13,LOG:15)
Block(10,-7,-13,LOG:15)
Block(11,-7,-13,LOG:15)
Block(-13,-7,-12,LOG:15)
Block(-12,-7,-12,LOG:15)
Block(-11,-7,-12,LOG:15)
Block(-6,-7,-12,LOG:15)
Block(-5,-7,-12,LOG:15)
Block(-4,-7,-12,LOG:15)
Block(8,-7,-12,LOG:15)
Block(9,-7,-12,LOG:15)
Block(10,-7,-12,LOG:15)
Block(-13,-7,-11,LOG:15)
Block(-12,-7,-11,LOG:15)
Block(-11,-7,-11,LOG:15)
Block(-10,-7,-11,LOG:15)
Block(-6,-7,-11,LOG:15)
Block(-5,-7,-11,LOG:15)
Block(-4,-7,-11,LOG:15)
Block(7,-7,-11,LOG:15)
Block(8,-7,-11,LOG:15)
Block(9,-7,-11,LOG:15)
Block(10,-7,-11,LOG:15)
Block(-12,-7,-10,LOG:15)
Block(-11,-7,-10,LOG:15)
Block(-10,-7,-10,LOG:15)
Block(-9,-7,-10,LOG:15)
Block(-5,-7,-10,LOG:15)
Block(-4,-7,-10,LOG:15)
Block(-3,-7,-10,LOG:15)
Block(-2,-7,-10,LOG:15)
Block(7,-7,-10,LOG:15)
Block(8,-7,-10,LOG:15)
Block(9,-7,-10,LOG:15)
Block(-11,-7,-9,LOG:15)
Block(7,-7,-9,LOG:15)
Block(8,-7,-9,LOG:15)
Block(-8,-7,-8,LOG:15)
Block(6,-7,-8,LOG:15)
Block(-10,-7,-7,LOG:15)
Block(-1,-7,-7,LOG:15)
Block(4,-7,-6,LOG:15)
Block(6,-7,-6,LOG:15)
Block(2,-7,-5,LOG:15)
Block(-10,-7,-4,LOG:15)
Block(-7,-7,-4,LOG:15)
Block(4,-7,-4,LOG:15)
Block(8,-7,-4,LOG:15)
Block(-10,-7,-3,LOG:15)
Block(-9,-7,-3,LOG:15)
Block(-1,-7,-3,LOG:15)
Block(1,-7,-3,LOG:15)
Block(-11,-7,-2,LOG:15)
Block(-10,-7,-2,LOG:15)
Block(-9,-7,-2,LOG:15)
Block(-5,-7,-2,LOG:15)
Block(6,-7,-2,LOG:15)
Block(10,-7,-2,LOG:15)
Block(11,-7,-2,LOG:15)
Block(-10,-7,-1,LOG:15)
Block(-9,-7,-1,LOG:15)
Block(2,-7,-1,LOG:15)
Block(8,-7,-1,LOG:15)
Block(9,-7,-1,LOG:15)
Block(10,-7,-1,LOG:15)
Block(11,-7,-1,LOG:15)
Block(12,-7,-1,LOG:15)
Block(-9,-7,0,LOG:15)
Block(0,-7,0,LOG:15)
Block(10,-7,0,LOG:15)
Block(11,-7,0,LOG:15)
Block(-6,-7,1,LOG:15)
Block(-4,-7,1,LOG:15)
Block(1,-7,3,LOG:15)
Block(-7,-7,5,LOG:15)
Block(1,-7,5,LOG:15)
Block(4,-7,6,LOG:15)
Block(-12,-7,7,LOG:15)
Block(-11,-7,7,LOG:15)
Block(-9,-7,7,LOG:15)
Block(-11,-7,8,LOG:15)
Block(-12,-7,9,LOG:15)
Block(-11,-7,9,LOG:15)
Block(4,-7,9,LOG:15)
Block(8,-7,9,LOG:15)
Block(9,-7,9,LOG:15)
Block(-13,-7,10,LOG:15)
Block(-12,-7,10,LOG:15)
Block(-11,-7,10,LOG:15)
Block(-10,-7,10,LOG:15)
Block(7,-7,10,LOG:15)
Block(8,-7,10,LOG:15)
Block(9,-7,10,LOG:15)
Block(10,-7,10,LOG:15)
Block(-14,-7,11,LOG:15)
Block(-13,-7,11,LOG:15)
Block(-12,-7,11,LOG:15)
Block(2,-7,11,LOG:15)
Block(3,-7,11,LOG:15)
Block(4,-7,11,LOG:15)
Block(5,-7,11,LOG:15)
Block(7,-7,11,LOG:15)
Block(8,-7,11,LOG:15)
Block(9,-7,11,LOG:15)
Block(-13,-7,12,LOG:15)
Block(1,-7,12,LOG:15)
Block(2,-7,12,LOG:15)
Block(3,-7,12,LOG:15)
Block(4,-7,12,LOG:15)
Block(5,-7,12,LOG:15)
Block(8,-7,12,LOG:15)
Block(2,-7,13,LOG:15)
Block(3,-7,13,LOG:15)
Block(-5,-6,-12,LOG:15)
Block(-4,-6,-12,LOG:15)
Block(-12,-6,-11,LOG:15)
Block(-11,-6,-11,LOG:15)
Block(-6,-6,-11,LOG:15)
Block(-5,-6,-11,LOG:15)
Block(-4,-6,-11,LOG:15)
Block(-3,-6,-11,LOG:15)
Block(7,-6,-11,LOG:15)
Block(8,-6,-11,LOG:15)
Block(9,-6,-11,LOG:15)
Block(-12,-6,-10,LOG:15)
Block(-11,-6,-10,LOG:15)
Block(-10,-6,-10,LOG:15)
Block(-9,-6,-10,LOG:15)
Block(-5,-6,-10,LOG:15)
Block(-4,-6,-10,LOG:15)
Block(-3,-6,-10,LOG:15)
Block(-2,-6,-10,LOG:15)
Block(6,-6,-10,LOG:15)
Block(7,-6,-10,LOG:15)
Block(8,-6,-10,LOG:15)
Block(9,-6,-10,LOG:15)
Block(-11,-6,-9,LOG:15)
Block(-10,-6,-9,LOG:15)
Block(-4,-6,-9,LOG:15)
Block(-3,-6,-9,LOG:15)
Block(7,-6,-9,LOG:15)
Block(8,-6,-9,LOG:15)
Block(-8,-6,-8,LOG:15)
Block(6,-6,-8,LOG:15)
Block(7,-6,-8,LOG:15)
Block(-10,-6,-7,LOG:15)
Block(-1,-6,-7,LOG:15)
Block(5,-6,-7,LOG:15)
Block(4,-6,-6,LOG:15)
Block(6,-6,-6,LOG:15)
Block(2,-6,-5,LOG:15)
Block(-9,-6,-4,LOG:15)
Block(-7,-6,-4,LOG:15)
Block(0,-6,-4,LOG:15)
Block(4,-6,-4,LOG:15)
Block(8,-6,-4,LOG:15)
Block(-10,-6,-3,LOG:15)
Block(-9,-6,-3,LOG:15)
Block(-8,-6,-3,LOG:15)
Block(-1,-6,-3,LOG:15)
Block(1,-6,-3,LOG:15)
Block(-11,-6,-2,LOG:15)
Block(-10,-6,-2,LOG:15)
Block(-9,-6,-2,LOG:15)
Block(-8,-6,-2,LOG:15)
Block(-5,-6,-2,LOG:15)
Block(6,-6,-2,LOG:15)
Block(9,-6,-2,LOG:15)
Block(10,-6,-2,LOG:15)
Block(-10,-6,-1,LOG:15)
Block(-9,-6,-1,LOG:15)
Block(-2,-6,-1,LOG:15)
Block(2,-6,-1,LOG:15)
Block(9,-6,-1,LOG:15)
Block(10,-6,-1,LOG:15)
Block(11,-6,-1,LOG:15)
Block(0,-6,0,LOG:15)
Block(10,-6,0,LOG:15)
Block(-6,-6,1,LOG:15)
Block(-4,-6,1,LOG:15)
Block(-1,-6,2,LOG:15)
Block(-5,-6,3,LOG:15)
Block(1,-6,3,LOG:15)
Block(-7,-6,5,LOG:15)
Block(1,-6,5,LOG:15)
Block(4,-6,6,LOG:15)
Block(-9,-6,7,LOG:15)
Block(-11,-6,8,LOG:15)
Block(-12,-6,9,LOG:15)
Block(-11,-6,9,LOG:15)
Block(-10,-6,9,LOG:15)
Block(4,-6,9,LOG:15)
Block(8,-6,9,LOG:15)
Block(-13,-6,10,LOG:15)
Block(-12,-6,10,LOG:15)
Block(-11,-6,10,LOG:15)
Block(-10,-6,10,LOG:15)
Block(-9,-6,10,LOG:15)
Block(3,-6,10,LOG:15)
Block(4,-6,10,LOG:15)
Block(5,-6,10,LOG:15)
Block(7,-6,10,LOG:15)
Block(8,-6,10,LOG:15)
Block(9,-6,10,LOG:15)
Block(-13,-6,11,LOG:15)
Block(-12,-6,11,LOG:15)
Block(-11,-6,11,LOG:15)
Block(-10,-6,11,LOG:15)
Block(2,-6,11,LOG:15)
Block(3,-6,11,LOG:15)
Block(4,-6,11,LOG:15)
Block(5,-6,11,LOG:15)
Block(6,-6,11,LOG:15)
Block(7,-6,11,LOG:15)
Block(8,-6,11,LOG:15)
Block(9,-6,11,LOG:15)
Block(2,-6,12,LOG:15)
Block(3,-6,12,LOG:15)
Block(4,-6,12,LOG:15)
Block(5,-6,12,LOG:15)
Block(6,-6,12,LOG:15)
Block(7,-6,12,LOG:15)
Block(8,-6,12,LOG:15)
Block(3,-6,13,LOG:15)
Block(-11,-5,-11,LOG:15)
Block(-10,-5,-11,LOG:15)
Block(-5,-5,-11,LOG:15)
Block(-4,-5,-11,LOG:15)
Block(-3,-5,-11,LOG:15)
Block(-12,-5,-10,LOG:15)
Block(-11,-5,-10,LOG:15)
Block(-10,-5,-10,LOG:15)
Block(-9,-5,-10,LOG:15)
Block(-4,-5,-10,LOG:15)
Block(-3,-5,-10,LOG:15)
Block(-2,-5,-10,LOG:15)
Block(6,-5,-10,LOG:15)
Block(7,-5,-10,LOG:15)
Block(8,-5,-10,LOG:15)
Block(-11,-5,-9,LOG:15)
Block(-10,-5,-9,LOG:15)
Block(-9,-5,-9,LOG:15)
Block(-4,-5,-9,LOG:15)
Block(-3,-5,-9,LOG:15)
Block(-2,-5,-9,LOG:15)
Block(5,-5,-9,LOG:15)
Block(7,-5,-9,LOG:15)
Block(8,-5,-9,LOG:15)
Block(-10,-5,-8,LOG:15)
Block(-9,-5,-8,LOG:15)
Block(-8,-5,-8,LOG:15)
Block(-3,-5,-8,LOG:15)
Block(-2,-5,-8,LOG:15)
Block(5,-5,-8,LOG:15)
Block(6,-5,-8,LOG:15)
Block(7,-5,-8,LOG:15)
Block(-10,-5,-7,LOG:15)
Block(-2,-5,-7,LOG:15)
Block(-1,-5,-7,LOG:15)
Block(5,-5,-7,LOG:15)
Block(6,-5,-7,LOG:15)
Block(-7,-5,-6,LOG:15)
Block(-1,-5,-6,LOG:15)
Block(4,-5,-6,LOG:15)
Block(5,-5,-6,LOG:15)
Block(6,-5,-6,LOG:15)
Block(-7,-5,-5,LOG:15)
Block(-6,-5,-5,LOG:15)
Block(2,-5,-5,LOG:15)
Block(3,-5,-5,LOG:15)
Block(4,-5,-5,LOG:15)
Block(-9,-5,-4,LOG:15)
Block(-8,-5,-4,LOG:15)
Block(-7,-5,-4,LOG:15)
Block(-6,-5,-4,LOG:15)
Block(0,-5,-4,LOG:15)
Block(4,-5,-4,LOG:15)
Block(8,-5,-4,LOG:15)
Block(-10,-5,-3,LOG:15)
Block(-9,-5,-3,LOG:15)
Block(-8,-5,-3,LOG:15)
Block(-7,-5,-3,LOG:15)
Block(-1,-5,-3,LOG:15)
Block(1,-5,-3,LOG:15)
Block(7,-5,-3,LOG:15)
Block(8,-5,-3,LOG:15)
Block(9,-5,-3,LOG:15)
Block(10,-5,-3,LOG:15)
Block(-10,-5,-2,LOG:15)
Block(-9,-5,-2,LOG:15)
Block(-8,-5,-2,LOG:15)
Block(-5,-5,-2,LOG:15)
Block(1,-5,-2,LOG:15)
Block(6,-5,-2,LOG:15)
Block(8,-5,-2,LOG:15)
Block(9,-5,-2,LOG:15)
Block(10,-5,-2,LOG:15)
Block(11,-5,-2,LOG:15)
Block(-2,-5,-1,LOG:15)
Block(2,-5,-1,LOG:15)
Block(9,-5,-1,LOG:15)
Block(10,-5,-1,LOG:15)
Block(11,-5,-1,LOG:15)
Block(0,-5,0,LOG:15)
Block(10,-5,0,LOG:15)
Block(-5,-5,1,LOG:15)
Block(-4,-5,1,LOG:15)
Block(-1,-5,2,LOG:15)
Block(-5,-5,3,LOG:15)
Block(1,-5,3,LOG:15)
Block(-7,-5,5,LOG:15)
Block(1,-5,5,LOG:15)
Block(-7,-5,6,LOG:15)
Block(3,-5,6,LOG:15)
Block(4,-5,6,LOG:15)
Block(-9,-5,7,LOG:15)
Block(-8,-5,7,LOG:15)
Block(-7,-5,7,LOG:15)
Block(3,-5,7,LOG:15)
Block(-10,-5,8,LOG:15)
Block(-9,-5,8,LOG:15)
Block(4,-5,8,LOG:15)
Block(-11,-5,9,LOG:15)
Block(-10,-5,9,LOG:15)
Block(-9,-5,9,LOG:15)
Block(4,-5,9,LOG:15)
Block(5,-5,9,LOG:15)
Block(-12,-5,10,LOG:15)
Block(-11,-5,10,LOG:15)
Block(-10,-5,10,LOG:15)
Block(-9,-5,10,LOG:15)
Block(5,-5,10,LOG:15)
Block(6,-5,10,LOG:15)
Block(7,-5,10,LOG:15)
Block(8,-5,10,LOG:15)
Block(-10,-5,11,LOG:15)
Block(3,-5,11,LOG:15)
Block(4,-5,11,LOG:15)
Block(5,-5,11,LOG:15)
Block(6,-5,11,LOG:15)
Block(7,-5,11,LOG:15)
Block(8,-5,11,LOG:15)
Block(3,-5,12,LOG:15)
Block(5,-5,12,LOG:15)
Block(6,-5,12,LOG:15)
Block(7,-5,12,LOG:15)
Block(6,-5,13,LOG:15)
Block(-3,-4,-11,LOG:15)
Block(-11,-4,-10,LOG:15)
Block(-10,-4,-10,LOG:15)
Block(-4,-4,-10,LOG:15)
Block(-3,-4,-10,LOG:15)
Block(-2,-4,-10,LOG:15)
Block(6,-4,-10,LOG:15)
Block(-11,-4,-9,LOG:15)
Block(-10,-4,-9,LOG:15)
Block(-9,-4,-9,LOG:15)
Block(-4,-4,-9,LOG:15)
Block(-3,-4,-9,LOG:15)
Block(-2,-4,-9,LOG:15)
Block(5,-4,-9,LOG:15)
Block(7,-4,-9,LOG:15)
Block(-11,-4,-8,LOG:15)
Block(-10,-4,-8,LOG:15)
Block(-9,-4,-8,LOG:15)
Block(-8,-4,-8,LOG:15)
Block(-3,-4,-8,LOG:15)
Block(-2,-4,-8,LOG:15)
Block(-1,-4,-8,LOG:15)
Block(5,-4,-8,LOG:15)
Block(6,-4,-8,LOG:15)
Block(7,-4,-8,LOG:15)
Block(-10,-4,-7,LOG:15)
Block(-9,-4,-7,LOG:15)
Block(-8,-4,-7,LOG:15)
Block(-7,-4,-7,LOG:15)
Block(-3,-4,-7,LOG:15)
Block(-2,-4,-7,LOG:15)
Block(-1,-4,-7,LOG:15)
Block(0,-4,-7,LOG:15)
Block(5,-4,-7,LOG:15)
Block(6,-4,-7,LOG:15)
Block(7,-4,-7,LOG:15)
Block(-8,-4,-6,LOG:15)
Block(-7,-4,-6,LOG:15)
Block(-6,-4,-6,LOG:15)
Block(-2,-4,-6,LOG:15)
Block(-1,-4,-6,LOG:15)
Block(0,-4,-6,LOG:15)
Block(2,-4,-6,LOG:15)
Block(3,-4,-6,LOG:15)
Block(4,-4,-6,LOG:15)
Block(5,-4,-6,LOG:15)
Block(6,-4,-6,LOG:15)
Block(-8,-4,-5,LOG:15)
Block(-7,-4,-5,LOG:15)
Block(-6,-4,-5,LOG:15)
Block(-5,-4,-5,LOG:15)
Block(-1,-4,-5,LOG:15)
Block(1,-4,-5,LOG:15)
Block(2,-4,-5,LOG:15)
Block(3,-4,-5,LOG:15)
Block(4,-4,-5,LOG:15)
Block(5,-4,-5,LOG:15)
Block(-9,-4,-4,LOG:15)
Block(-8,-4,-4,LOG:15)
Block(-7,-4,-4,LOG:15)
Block(-6,-4,-4,LOG:15)
Block(-5,-4,-4,LOG:15)
Block(0,-4,-4,LOG:15)
Block(1,-4,-4,LOG:15)
Block(2,-4,-4,LOG:15)
Block(3,-4,-4,LOG:15)
Block(4,-4,-4,LOG:15)
Block(7,-4,-4,LOG:15)
Block(8,-4,-4,LOG:15)
Block(9,-4,-4,LOG:15)
Block(-9,-4,-3,LOG:15)
Block(-8,-4,-3,LOG:15)
Block(-7,-4,-3,LOG:15)
Block(-6,-4,-3,LOG:15)
Block(-1,-4,-3,LOG:15)
Block(0,-4,-3,LOG:15)
Block(1,-4,-3,LOG:15)
Block(2,-4,-3,LOG:15)
Block(6,-4,-3,LOG:15)
Block(7,-4,-3,LOG:15)
Block(8,-4,-3,LOG:15)
Block(9,-4,-3,LOG:15)
Block(10,-4,-3,LOG:15)
Block(-8,-4,-2,LOG:15)
Block(-5,-4,-2,LOG:15)
Block(0,-4,-2,LOG:15)
Block(1,-4,-2,LOG:15)
Block(2,-4,-2,LOG:15)
Block(6,-4,-2,LOG:15)
Block(7,-4,-2,LOG:15)
Block(8,-4,-2,LOG:15)
Block(9,-4,-2,LOG:15)
Block(10,-4,-2,LOG:15)
Block(-2,-4,-1,LOG:15)
Block(1,-4,-1,LOG:15)
Block(2,-4,-1,LOG:15)
Block(9,-4,-1,LOG:15)
Block(10,-4,-1,LOG:15)
Block(0,-4,0,LOG:15)
Block(-4,-4,1,LOG:15)
Block(-1,-4,2,LOG:15)
Block(-5,-4,3,LOG:15)
Block(1,-4,3,LOG:15)
Block(-7,-4,5,LOG:15)
Block(1,-4,5,LOG:15)
Block(3,-4,5,LOG:15)
Block(-8,-4,6,LOG:15)
Block(-7,-4,6,LOG:15)
Block(-6,-4,6,LOG:15)
Block(2,-4,6,LOG:15)
Block(3,-4,6,LOG:15)
Block(4,-4,6,LOG:15)
Block(-10,-4,7,LOG:15)
Block(-9,-4,7,LOG:15)
Block(-8,-4,7,LOG:15)
Block(-7,-4,7,LOG:15)
Block(-6,-4,7,LOG:15)
Block(2,-4,7,LOG:15)
Block(3,-4,7,LOG:15)
Block(4,-4,7,LOG:15)
Block(-11,-4,8,LOG:15)
Block(-10,-4,8,LOG:15)
Block(-9,-4,8,LOG:15)
Block(-8,-4,8,LOG:15)
Block(-7,-4,8,LOG:15)
Block(3,-4,8,LOG:15)
Block(4,-4,8,LOG:15)
Block(5,-4,8,LOG:15)
Block(-11,-4,9,LOG:15)
Block(-10,-4,9,LOG:15)
Block(-9,-4,9,LOG:15)
Block(3,-4,9,LOG:15)
Block(4,-4,9,LOG:15)
Block(5,-4,9,LOG:15)
Block(6,-4,9,LOG:15)
Block(-10,-4,10,LOG:15)
Block(4,-4,10,LOG:15)
Block(5,-4,10,LOG:15)
Block(6,-4,10,LOG:15)
Block(7,-4,10,LOG:15)
Block(5,-4,11,LOG:15)
Block(6,-4,11,LOG:15)
Block(7,-4,11,LOG:15)
Block(6,-4,12,LOG:15)
Block(-9,-3,-10,LOG:15)
Block(-3,-3,-10,LOG:15)
Block(-11,-3,-9,LEAVES:3)
Block(-10,-3,-9,LOG:15)
Block(-9,-3,-9,LEAVES:3)
Block(-4,-3,-9,LOG:15)
Block(-3,-3,-9,LOG:15)
Block(-2,-3,-9,LOG:15)
Block(7,-3,-9,LOG:15)
Block(-12,-3,-8,LEAVES:3)
Block(-11,-3,-8,LOG:15)
Block(-10,-3,-8,LOG:15)
Block(-9,-3,-8,LOG:15)
Block(-8,-3,-8,LOG:15)
Block(-3,-3,-8,LOG:15)
Block(-2,-3,-8,LOG:15)
Block(-1,-3,-8,LOG:15)
Block(5,-3,-8,LOG:15)
Block(6,-3,-8,LOG:15)
Block(-11,-3,-7,LEAVES:3)
Block(-10,-3,-7,LOG:15)
Block(-9,-3,-7,LOG:15)
Block(-8,-3,-7,LOG:15)
Block(-7,-3,-7,LOG:15)
Block(-3,-3,-7,LOG:15)
Block(-2,-3,-7,LOG:15)
Block(-1,-3,-7,LOG:15)
Block(0,-3,-7,LOG:15)
Block(5,-3,-7,LOG:15)
Block(6,-3,-7,LOG:15)
Block(-9,-3,-6,LOG:15)
Block(-8,-3,-6,LOG:15)
Block(-7,-3,-6,LOG:15)
Block(-6,-3,-6,LOG:15)
Block(-2,-3,-6,LOG:15)
Block(-1,-3,-6,LOG:15)
Block(0,-3,-6,LOG:15)
Block(3,-3,-6,LOG:15)
Block(4,-3,-6,LOG:15)
Block(5,-3,-6,LOG:15)
Block(-8,-3,-5,LOG:15)
Block(-7,-3,-5,LOG:15)
Block(-6,-3,-5,LOG:15)
Block(-1,-3,-5,LOG:15)
Block(0,-3,-5,LOG:15)
Block(1,-3,-5,LOG:15)
Block(2,-3,-5,LOG:15)
Block(3,-3,-5,LOG:15)
Block(4,-3,-5,LOG:15)
Block(5,-3,-5,LOG:15)
Block(-8,-3,-4,LOG:15)
Block(-7,-3,-4,LOG:15)
Block(-6,-3,-4,LOG:15)
Block(-5,-3,-4,LOG:15)
Block(0,-3,-4,LOG:15)
Block(1,-3,-4,LOG:15)
Block(2,-3,-4,LOG:15)
Block(3,-3,-4,LOG:15)
Block(4,-3,-4,LOG:15)
Block(7,-3,-4,LOG:15)
Block(9,-3,-4,LEAVES:3)
Block(-8,-3,-3,LOG:15)
Block(-5,-3,-3,LOG:15)
Block(-1,-3,-3,LOG:15)
Block(0,-3,-3,LOG:15)
Block(1,-3,-3,LOG:15)
Block(2,-3,-3,LOG:15)
Block(3,-3,-3,LOG:15)
Block(6,-3,-3,LOG:15)
Block(7,-3,-3,LOG:15)
Block(8,-3,-3,LOG:15)
Block(9,-3,-3,LOG:15)
Block(-5,-3,-2,LOG:15)
Block(-1,-3,-2,LOG:15)
Block(0,-3,-2,LOG:15)
Block(1,-3,-2,LOG:15)
Block(2,-3,-2,LOG:15)
Block(6,-3,-2,LOG:15)
Block(7,-3,-2,LOG:15)
Block(9,-3,-2,LEAVES:3)
Block(-2,-3,-1,LOG:15)
Block(-1,-3,-1,LOG:15)
Block(0,-3,-1,LOG:15)
Block(1,-3,-1,LOG:15)
Block(2,-3,-1,LOG:15)
Block(0,-3,0,LOG:15)
Block(1,-3,0,LOG:15)
Block(-4,-3,1,LOG:15)
Block(-1,-3,2,LOG:15)
Block(2,-3,2,LOG:15)
Block(-5,-3,3,LOG:15)
Block(1,-3,3,LOG:15)
Block(-6,-3,4,LOG:15)
Block(1,-3,4,LOG:15)
Block(2,-3,4,LOG:15)
Block(-7,-3,5,LOG:15)
Block(-6,-3,5,LOG:15)
Block(-5,-3,5,LOG:15)
Block(1,-3,5,LOG:15)
Block(2,-3,5,LOG:15)
Block(3,-3,5,LEAVES:3)
Block(-7,-3,6,LOG:15)
Block(-6,-3,6,LOG:15)
Block(2,-3,6,LOG:15)
Block(3,-3,6,LOG:15)
Block(4,-3,6,LOG:15)
Block(-9,-3,7,LOG:15)
Block(-8,-3,7,LOG:15)
Block(-7,-3,7,LOG:15)
Block(2,-3,7,LOG:15)
Block(3,-3,7,LOG:15)
Block(4,-3,7,LOG:15)
Block(-10,-3,8,LOG:15)
Block(-9,-3,8,LOG:15)
Block(-8,-3,8,LOG:15)
Block(3,-3,8,LOG:15)
Block(4,-3,8,LOG:15)
Block(5,-3,8,LOG:15)
Block(-10,-3,9,LOG:15)
Block(3,-3,9,LOG:15)
Block(4,-3,9,LOG:15)
Block(5,-3,9,LOG:15)
Block(6,-3,9,LOG:15)
Block(4,-3,10,LOG:15)
Block(5,-3,10,LOG:15)
Block(6,-3,10,LOG:15)
Block(7,-3,10,LOG:15)
Block(5,-3,11,LOG:15)
Block(6,-3,11,LOG:15)
Block(-3,-2,-9,LOG:15)
Block(-11,-2,-8,LEAVES:3)
Block(-10,-2,-8,LOG:15)
Block(-9,-2,-8,LEAVES:3)
Block(-2,-2,-8,LEAVES:3)
Block(5,-2,-8,LEAVES:3)
Block(-8,-2,-7,LOG:15)
Block(-7,-2,-7,LOG:15)
Block(-2,-2,-7,LOG:15)
Block(-1,-2,-7,LOG:15)
Block(5,-2,-7,LOG:15)
Block(6,-2,-7,LEAVES:3)
Block(-8,-2,-6,LOG:15)
Block(-7,-2,-6,LOG:15)
Block(-6,-2,-6,LOG:15)
Block(-1,-2,-6,LEAVES:3)
Block(3,-2,-6,LEAVES:3)
Block(4,-2,-6,LOG:15)
Block(5,-2,-6,LEAVES:3)
Block(-8,-2,-5,LOG:15)
Block(-7,-2,-5,LOG:15)
Block(-6,-2,-5,LOG:15)
Block(-5,-2,-5,LOG:15)
Block(0,-2,-5,LOG:15)
Block(3,-2,-5,LOG:15)
Block(4,-2,-5,LOG:15)
Block(5,-2,-5,LOG:15)
Block(-7,-2,-4,LOG:15)
Block(-6,-2,-4,LOG:15)
Block(-5,-2,-4,LOG:15)
Block(-4,-2,-4,LOG:15)
Block(0,-2,-4,LOG:15)
Block(1,-2,-4,LOG:15)
Block(2,-2,-4,LOG:15)
Block(3,-2,-4,LOG:15)
Block(4,-2,-4,LOG:15)
Block(5,-2,-4,LOG:15)
Block(6,-2,-4,LOG:15)
Block(7,-2,-4,LOG:15)
Block(8,-2,-4,LOG:15)
Block(-6,-2,-3,LOG:15)
Block(-5,-2,-3,LOG:15)
Block(-4,-2,-3,LOG:15)
Block(-1,-2,-3,LOG:15)
Block(0,-2,-3,LOG:15)
Block(1,-2,-3,LOG:15)
Block(2,-2,-3,LOG:15)
Block(4,-2,-3,LOG:15)
Block(5,-2,-3,LOG:15)
Block(6,-2,-3,LOG:15)
Block(7,-2,-3,LOG:15)
Block(8,-2,-3,LOG:15)
Block(9,-2,-3,LOG:15)
Block(-5,-2,-2,LOG:15)
Block(0,-2,-2,LOG:15)
Block(1,-2,-2,LOG:15)
Block(2,-2,-2,LOG:15)
Block(6,-2,-2,LOG:15)
Block(7,-2,-2,LOG:15)
Block(8,-2,-2,LOG:15)
Block(-2,-2,-1,LOG:15)
Block(0,-2,-1,LOG:15)
Block(1,-2,-1,LOG:15)
Block(2,-2,-1,LOG:15)
Block(1,-2,0,LOG:15)
Block(-4,-2,1,LOG:15)
Block(0,-2,1,LOG:15)
Block(1,-2,1,LOG:15)
Block(-1,-2,2,LOG:15)
Block(0,-2,2,LOG:15)
Block(-5,-2,3,LOG:15)
Block(-4,-2,3,LOG:15)
Block(1,-2,3,LOG:15)
Block(2,-2,3,LOG:15)
Block(-6,-2,4,LOG:15)
Block(-5,-2,4,LOG:15)
Block(-4,-2,4,LOG:15)
Block(0,-2,4,LOG:15)
Block(1,-2,4,LOG:15)
Block(2,-2,4,LOG:15)
Block(3,-2,4,LOG:15)
Block(-7,-2,5,LOG:15)
Block(-6,-2,5,LOG:15)
Block(-5,-2,5,LOG:15)
Block(0,-2,5,LOG:15)
Block(1,-2,5,LOG:15)
Block(2,-2,5,LOG:15)
Block(3,-2,5,LOG:15)
Block(4,-2,5,LEAVES:3)
Block(-8,-2,6,LOG:15)
Block(-7,-2,6,LOG:15)
Block(-6,-2,6,LOG:15)
Block(-5,-2,6,LOG:15)
Block(1,-2,6,LOG:15)
Block(2,-2,6,LOG:15)
Block(3,-2,6,LEAVES:3)
Block(-9,-2,7,LEAVES:3)
Block(-8,-2,7,LOG:15)
Block(-7,-2,7,LOG:15)
Block(-6,-2,7,LOG:15)
Block(3,-2,7,LOG:15)
Block(-9,-2,8,LOG:15)
Block(-8,-2,8,LEAVES:3)
Block(-7,-2,8,LOG:15)
Block(4,-2,8,LEAVES:3)
Block(4,-2,9,LOG:15)
Block(5,-2,9,LOG:15)
Block(4,-2,10,LEAVES:3)
Block(5,-2,10,LOG:15)
Block(6,-2,10,LOG:15)
Block(5,-2,11,LEAVES:3)
Block(5,-1,-7,LEAVES:3)
Block(-7,-1,-6,LOG:15)
Block(-6,-1,-6,LOG:15)
Block(4,-1,-6,LEAVES:3)
Block(-8,-1,-5,LOG:15)
Block(-7,-1,-5,LOG:15)
Block(-6,-1,-5,LOG:15)
Block(-5,-1,-5,LOG:15)
Block(1,-1,-5,LEAVES:3)
Block(4,-1,-5,LOG:15)
Block(-7,-1,-4,LOG:15)
Block(-6,-1,-4,LOG:15)
Block(-5,-1,-4,LOG:15)
Block(-4,-1,-4,LOG:15)
Block(0,-1,-4,LEAVES:3)
Block(1,-1,-4,LEAVES:3)
Block(2,-1,-4,LEAVES:3)
Block(4,-1,-4,LOG:15)
Block(5,-1,-4,LOG:15)
Block(6,-1,-4,LOG:15)
Block(-6,-1,-3,LOG:15)
Block(-5,-1,-3,LOG:15)
Block(-4,-1,-3,LOG:15)
Block(0,-1,-3,LOG:15)
Block(1,-1,-3,LOG:15)
Block(2,-1,-3,LEAVES:3)
Block(4,-1,-3,LOG:15)
Block(5,-1,-3,LOG:15)
Block(6,-1,-3,LOG:15)
Block(7,-1,-3,LOG:15)
Block(8,-1,-3,LOG:15)
Block(-5,-1,-2,LOG:15)
Block(0,-1,-2,LOG:15)
Block(1,-1,-2,LOG:15)
Block(2,-1,-2,LOG:15)
Block(5,-1,-2,LOG:15)
Block(6,-1,-2,LOG:15)
Block(-3,-1,-1,LOG:15)
Block(-2,-1,-1,LOG:15)
Block(0,-1,-1,LOG:15)
Block(1,-1,-1,LOG:15)
Block(2,-1,-1,LOG:15)
Block(3,-1,-1,LEAVES:3)
Block(-3,-1,0,LOG:15)
Block(0,-1,0,LOG:15)
Block(1,-1,0,LOG:15)
Block(2,-1,0,LOG:15)
Block(-4,-1,1,LOG:15)
Block(-1,-1,1,LOG:15)
Block(0,-1,1,LOG:15)
Block(1,-1,1,LOG:15)
Block(2,-1,1,LOG:15)
Block(-4,-1,2,LOG:15)
Block(-3,-1,2,LOG:15)
Block(-1,-1,2,LOG:15)
Block(0,-1,2,LOG:15)
Block(1,-1,2,LOG:15)
Block(-5,-1,3,LOG:15)
Block(-4,-1,3,LOG:15)
Block(-3,-1,3,LOG:15)
Block(0,-1,3,LOG:15)
Block(1,-1,3,LOG:15)
Block(-6,-1,4,LOG:15)
Block(-5,-1,4,LOG:15)
Block(-4,-1,4,LOG:15)
Block(-3,-1,4,LOG:15)
Block(0,-1,4,LOG:15)
Block(1,-1,4,LOG:15)
Block(2,-1,4,LOG:15)
Block(-7,-1,5,LOG:15)
Block(-6,-1,5,LOG:15)
Block(-5,-1,5,LOG:15)
Block(-4,-1,5,LOG:15)
Block(1,-1,5,LOG:15)
Block(2,-1,5,LOG:15)
Block(3,-1,5,LEAVES:3)
Block(-7,-1,6,LOG:15)
Block(-6,-1,6,LOG:15)
Block(-5,-1,6,LOG:15)
Block(-8,-1,7,LEAVES:3)
Block(-7,-1,7,LOG:15)
Block(5,-1,10,LEAVES:3)
Block(-7,0,-6,LEAVES:3)
Block(-8,0,-5,LEAVES:3)
Block(-7,0,-5,LOG:15)
Block(-6,0,-5,LOG:15)
Block(-7,0,-4,LOG:15)
Block(-6,0,-4,LOG:15)
Block(-4,0,-4,LOG:15)
Block(-3,0,-4,LOG:15)
Block(1,0,-4,LEAVES:3)
Block(4,0,-4,LOG:15)
Block(5,0,-4,LOG:15)
Block(7,0,-4,LEAVES:3)
Block(-6,0,-3,LOG:15)
Block(-4,0,-3,LOG:15)
Block(-3,0,-3,LOG:15)
Block(1,0,-3,LEAVES:3)
Block(3,0,-3,LOG:15)
Block(4,0,-3,LOG:15)
Block(5,0,-3,LOG:15)
Block(7,0,-3,LEAVES:3)
Block(8,0,-3,LEAVES:3)
Block(-3,0,-2,LOG:15)
Block(4,0,-2,LOG:15)
Block(5,0,-2,LOG:15)
Block(7,0,-2,LEAVES:3)
Block(1,0,-1,LOG:15)
Block(-4,0,0,LOG:15)
Block(-3,0,0,LOG:15)
Block(-2,0,0,LOG:15)
Block(0,0,0,LOG:15)
Block(1,0,0,LOG:15)
Block(-4,0,1,LOG:15)
Block(-3,0,1,LOG:15)
Block(-2,0,1,LOG:15)
Block(0,0,1,LOG:15)
Block(1,0,1,LOG:15)
Block(-5,0,3,LOG:15)
Block(-4,0,3,LOG:15)
Block(-3,0,3,LOG:15)
Block(-1,0,3,LOG:15)
Block(0,0,3,LOG:15)
Block(1,0,3,LOG:15)
Block(2,0,3,LOG:15)
Block(-5,0,4,LOG:15)
Block(-4,0,4,LOG:15)
Block(0,0,4,LOG:15)
Block(1,0,4,LOG:15)
Block(2,0,4,LOG:15)
Block(-6,0,5,LOG:15)
Block(-5,0,5,LOG:15)
Block(-4,0,5,LEAVES:3)
Block(1,0,5,LOG:15)
Block(-7,1,-5,LEAVES:3)
Block(-6,1,-5,LEAVES:3)
Block(-4,1,-5,LOG:15)
Block(-7,1,-4,LEAVES:3)
Block(-6,1,-4,LOG:15)
Block(-5,1,-4,LOG:15)
Block(-4,1,-4,LOG:15)
Block(-3,1,-4,LOG:15)
Block(4,1,-4,LOG:15)
Block(-6,1,-3,LOG:15)
Block(-5,1,-3,LOG:15)
Block(-4,1,-3,LOG:15)
Block(-3,1,-3,LOG:15)
Block(-2,1,-3,LOG:15)
Block(2,1,-3,LOG:15)
Block(3,1,-3,LOG:15)
Block(4,1,-3,LOG:15)
Block(5,1,-3,LOG:15)
Block(6,1,-3,LEAVES:3)
Block(7,1,-3,LEAVES:3)
Block(-6,1,-2,LOG:15)
Block(-5,1,-2,LOG:15)
Block(-4,1,-2,LOG:15)
Block(-3,1,-2,LOG:15)
Block(-2,1,-2,LOG:15)
Block(4,1,-2,LOG:15)
Block(-5,1,-1,LOG:15)
Block(-4,1,-1,LOG:15)
Block(-3,1,-1,LOG:15)
Block(-2,1,-1,LOG:15)
Block(-4,1,0,LOG:15)
Block(-3,1,0,LOG:15)
Block(-2,1,0,LOG:15)
Block(1,1,0,LOG:15)
Block(-4,1,1,LOG:15)
Block(-3,1,1,LOG:15)
Block(-2,1,1,LOG:15)
Block(-1,1,1,LOG:15)
Block(0,1,1,LOG:15)
Block(1,1,1,LEAVES:3)
Block(-4,1,2,LOG:15)
Block(-3,1,2,LOG:15)
Block(-2,1,2,LOG:15)
Block(-1,1,2,LOG:15)
Block(0,1,2,LOG:15)
Block(-5,1,3,LEAVES:3)
Block(-4,1,3,LOG:15)
Block(-3,1,3,LOG:15)
Block(-2,1,3,LOG:15)
Block(-1,1,3,LOG:15)
Block(0,1,3,LOG:15)
Block(1,1,3,LOG:15)
Block(-4,1,4,LEAVES:3)
Block(-3,1,4,LOG:15)
Block(-1,1,4,LEAVES:3)
Block(0,1,4,LEAVES:3)
Block(1,1,4,LOG:15)
Block(2,1,4,LEAVES:3)
Block(-5,1,5,LEAVES:3)
Block(0,1,5,LEAVES:3)
Block(1,1,5,LEAVES:3)
Block(2,1,5,LEAVES:3)
Block(1,1,6,LEAVES:3)
Block(-6,2,-4,LEAVES:3)
Block(-4,2,-4,LOG:15)
Block(-3,2,-4,LOG:15)
Block(2,2,-4,LOG:15)
Block(3,2,-4,LOG:15)
Block(4,2,-4,LOG:15)
Block(-5,2,-3,LOG:15)
Block(-4,2,-3,LOG:15)
Block(-3,2,-3,LOG:15)
Block(-2,2,-3,LOG:15)
Block(-1,2,-3,LEAVES:3)
Block(1,2,-3,LOG:15)
Block(2,2,-3,LOG:15)
Block(3,2,-3,LOG:15)
Block(4,2,-3,LOG:15)
Block(5,2,-3,LOG:15)
Block(-5,2,-2,LOG:15)
Block(-4,2,-2,LOG:15)
Block(-3,2,-2,LOG:15)
Block(-2,2,-2,LOG:15)
Block(-1,2,-2,LOG:15)
Block(0,2,-2,LOG:15)
Block(1,2,-2,LOG:15)
Block(2,2,-2,LOG:15)
Block(3,2,-2,LOG:15)
Block(4,2,-2,LOG:15)
Block(-5,2,-1,LOG:15)
Block(-4,2,-1,LOG:15)
Block(-3,2,-1,LOG:15)
Block(-2,2,-1,LOG:15)
Block(-5,2,0,LEAVES:3)
Block(-4,2,0,LOG:15)
Block(-3,2,0,LOG:15)
Block(-4,2,1,LEAVES:3)
Block(-3,2,1,LOG:15)
Block(-2,2,1,LOG:15)
Block(-3,2,2,LOG:15)
Block(-2,2,2,LOG:15)
Block(-1,2,2,LOG:15)
Block(-4,2,3,LEAVES:3)
Block(-3,2,3,LOG:15)
Block(-2,2,3,LEAVES:3)
Block(-1,2,3,LEAVES:3)
Block(1,2,4,LEAVES:3)
Block(1,2,5,LEAVES:3)
Block(-1,3,-4,LEAVES:3)
Block(1,3,-4,LOG:15)
Block(2,3,-4,LOG:15)
Block(-4,3,-3,LEAVES:3)
Block(-3,3,-3,LOG:15)
Block(-2,3,-3,LOG:15)
Block(-1,3,-3,LOG:15)
Block(0,3,-3,LOG:15)
Block(1,3,-3,LOG:15)
Block(2,3,-3,LOG:15)
Block(3,3,-3,LOG:15)
Block(4,3,-3,LOG:15)
Block(-3,3,-2,LOG:15)
Block(-2,3,-2,LOG:15)
Block(-1,3,-2,LOG:15)
Block(0,3,-2,LOG:15)
Block(1,3,-2,LOG:15)
Block(2,3,-2,LOG:15)
Block(-4,3,-1,LOG:15)
Block(-3,3,-1,LOG:15)
Block(-2,3,-1,LOG:15)
Block(-1,3,-1,LOG:15)
Block(0,3,-1,LOG:15)
Block(1,3,-1,LOG:15)
Block(2,3,-1,LOG:15)
Block(3,3,-1,LEAVES:3)
Block(-4,3,0,LEAVES:3)
Block(2,3,0,LOG:15)
Block(-2,3,2,LEAVES:3)
Block(2,4,-4,LEAVES:3)
Block(-1,4,-3,LEAVES:3)
Block(1,4,-3,LOG:15)
Block(2,4,-3,LOG:15)
Block(3,4,-3,LEAVES:3)
Block(-2,4,-2,LOG:15)
Block(-1,4,-2,LOG:15)
Block(0,4,-2,LOG:15)
Block(1,4,-2,LOG:15)
Block(2,4,-2,LOG:15)
Block(3,4,-2,LEAVES:3)
Block(0,4,-1,LOG:15)
Block(1,4,-1,LOG:15)
Block(2,4,-1,LOG:15)
Block(3,4,-1,LOG:15)
Block(4,4,-1,LEAVES:3)
Block(1,4,0,LOG:15)
Block(2,4,0,LOG:15)
Block(3,4,0,LOG:15)
Block(2,4,1,LOG:15)
Block(3,4,1,LEAVES:3)
Block(4,4,1,LEAVES:3)
Block(1,4,2,LOG:15)
Block(2,4,2,LOG:15)
Block(2,5,-3,LEAVES:3)
Block(1,5,-2,LOG:15)
Block(1,5,-1,LOG:15)
Block(2,5,-1,LOG:15)
Block(3,5,-1,LEAVES:3)
Block(1,5,0,LOG:15)
Block(2,5,0,LOG:15)
Block(3,5,0,LOG:15)
Block(4,5,0,LEAVES:3)
Block(1,5,1,LOG:15)
Block(2,5,1,LOG:15)
Block(3,5,1,LOG:15)
Block(4,5,1,LEAVES:3)
Block(5,5,1,LEAVES:3)
Block(0,5,2,LOG:15)
Block(1,5,2,LOG:15)
Block(2,5,2,LOG:15)
Block(3,5,2,LOG:15)
Block(4,5,2,LEAVES:3)
Block(-2,5,3,LOG:15)
Block(-1,5,3,LOG:15)
Block(0,5,3,LOG:15)
Block(1,5,3,LOG:15)
Block(2,5,3,LOG:15)
Block(2,6,0,LOG:15)
Block(-3,6,1,LOG:15)
Block(0,6,1,LOG:15)
Block(1,6,1,LOG:15)
Block(2,6,1,LOG:15)
Block(3,6,1,LEAVES:3)
Block(4,6,1,LEAVES:3)
Block(-3,6,2,LOG:15)
Block(-2,6,2,LOG:15)
Block(-1,6,2,LOG:15)
Block(0,6,2,LOG:15)
Block(1,6,2,LOG:15)
Block(2,6,2,LOG:15)
Block(-3,6,3,LOG:15)
Block(-2,6,3,LOG:15)
Block(-1,6,3,LOG:15)
Block(0,6,3,LOG:15)
Block(1,6,3,LOG:15)
Block(-2,6,4,LOG:15)
Block(-1,6,4,LOG:15)
Block(0,6,4,LOG:15)
Block(-3,7,0,LOG:15)
Block(-4,7,1,LOG:15)
Block(-3,7,1,LOG:15)
Block(-2,7,1,LOG:15)
Block(1,7,1,LEAVES:3)
Block(-4,7,2,LOG:15)
Block(-3,7,2,LOG:15)
Block(-2,7,2,LOG:15)
Block(0,7,2,LOG:15)
Block(1,7,2,LOG:15)
Block(2,7,2,LEAVES:3)
Block(-4,7,3,LOG:15)
Block(-3,7,3,LOG:15)
Block(-2,7,3,LOG:15)
Block(-1,7,3,LOG:15)
Block(0,7,3,LOG:15)
Block(1,7,3,LEAVES:3)
Block(-3,7,4,LOG:15)
Block(-2,7,4,LOG:15)
Block(-3,8,-2,LOG:15)
Block(-2,8,-2,LOG:15)
Block(-1,8,-2,LOG:15)
Block(0,8,-2,LOG:15)
Block(-3,8,-1,LOG:15)
Block(-4,8,0,LOG:15)
Block(-3,8,0,LOG:15)
Block(-2,8,0,LOG:15)
Block(-4,8,1,LOG:15)
Block(-3,8,1,LOG:15)
Block(-2,8,1,LOG:15)
Block(-4,8,2,LEAVES:3)
Block(-3,8,2,LOG:15)
Block(-2,8,2,LEAVES:3)
Block(1,8,2,LEAVES:3)
Block(-3,8,3,LOG:15)
Block(-2,8,3,LOG:15)
Block(-1,8,3,LEAVES:3)
Block(-3,8,4,LEAVES:3)
Block(-2,8,4,LEAVES:3)
Block(-1,8,4,LEAVES:3)
Block(-2,8,5,LEAVES:3)
Block(-3,9,-3,LOG:15)
Block(-2,9,-3,LOG:15)
Block(-1,9,-3,LOG:15)
Block(0,9,-3,LOG:15)
Block(-4,9,-2,LOG:15)
Block(-3,9,-2,LOG:15)
Block(-2,9,-2,LOG:15)
Block(-1,9,-2,LOG:15)
Block(0,9,-2,LOG:15)
Block(1,9,-2,LOG:15)
Block(2,9,-2,LOG:15)
Block(3,9,-2,LEAVES:3)
Block(-4,9,-1,LOG:15)
Block(-3,9,-1,LOG:15)
Block(-2,9,-1,LOG:15)
Block(-1,9,-1,LOG:15)
Block(0,9,-1,LOG:15)
Block(-4,9,0,LOG:15)
Block(-3,9,0,LOG:15)
Block(-2,9,0,LOG:15)
Block(-4,9,1,LEAVES:3)
Block(-3,9,1,LOG:15)
Block(-2,9,1,LEAVES:3)
Block(-5,9,2,LEAVES:3)
Block(-4,9,2,LEAVES:3)
Block(-3,9,2,LEAVES:3)
Block(-2,9,2,LEAVES:3)
Block(-4,9,3,LEAVES:3)
Block(-3,9,3,LEAVES:3)
Block(-2,9,3,LEAVES:3)
Block(-2,9,4,LEAVES:3)
Block(0,10,-4,LEAVES:3)
Block(-2,10,-3,LEAVES:3)
Block(-1,10,-3,LEAVES:3)
Block(0,10,-3,LOG:15)
Block(1,10,-3,LOG:15)
Block(2,10,-3,LOG:15)
Block(3,10,-3,LEAVES:3)
Block(-3,10,-2,LOG:15)
Block(-2,10,-2,LOG:15)
Block(-1,10,-2,LOG:15)
Block(0,10,-2,LOG:15)
Block(1,10,-2,LOG:15)
Block(2,10,-2,LOG:15)
Block(3,10,-2,LOG:15)
Block(4,10,-2,LEAVES:3)
Block(-4,10,-1,LEAVES:3)
Block(-3,10,-1,LOG:15)
Block(-2,10,-1,LEAVES:3)
Block(0,10,-1,LOG:15)
Block(1,10,-1,LOG:15)
Block(2,10,-1,LOG:15)
Block(3,10,-1,LEAVES:3)
Block(-3,10,0,LOG:15)
Block(2,10,0,LOG:15)
Block(3,10,0,LEAVES:3)
Block(-3,10,1,LEAVES:3)
Block(2,10,1,LOG:15)
Block(-4,10,2,LEAVES:3)
Block(-3,10,2,LEAVES:3)
Block(0,11,-3,LEAVES:3)
Block(-2,11,-2,LEAVES:3)
Block(0,11,-2,LOG:15)
Block(1,11,-2,LOG:15)
Block(3,11,-2,LEAVES:3)
Block(-3,11,-1,LEAVES:3)
Block(1,11,-1,LOG:15)
Block(2,11,-1,LOG:15)
Block(3,11,-1,LOG:15)
Block(1,11,0,LOG:15)
Block(2,11,0,LOG:15)
Block(3,11,0,LOG:15)
Block(4,11,0,LEAVES:3)
Block(1,11,1,LOG:15)
Block(2,11,1,LOG:15)
Block(3,11,1,LOG:15)
Block(-3,11,2,LEAVES:3)
Block(0,11,2,LEAVES:3)
Block(1,11,2,LOG:15)
Block(2,11,2,LOG:15)
Block(2,11,3,LEAVES:3)
Block(2,12,-1,LOG:15)
Block(-3,12,0,LOG:15)
Block(2,12,0,LOG:15)
Block(3,12,0,LEAVES:3)
Block(-3,12,1,LOG:15)
Block(0,12,1,LEAVES:3)
Block(1,12,1,LOG:15)
Block(2,12,1,LOG:15)
Block(3,12,1,LOG:15)
Block(-4,12,2,LEAVES:3)
Block(-3,12,2,LOG:15)
Block(-2,12,2,LOG:15)
Block(-1,12,2,LOG:15)
Block(0,12,2,LOG:15)
Block(1,12,2,LOG:15)
Block(2,12,2,LOG:15)
Block(3,12,2,LOG:15)
Block(-3,12,3,LEAVES:3)
Block(0,12,3,LEAVES:3)
Block(1,12,3,LOG:15)
Block(2,12,3,LOG:15)
Block(3,12,3,LEAVES:3)
Block(2,12,4,LEAVES:3)
Block(-2,13,-4,LEAVES:3)
Block(-3,13,-3,LEAVES:3)
Block(-2,13,-3,LEAVES:3)
Block(-1,13,-3,LEAVES:3)
Block(4,13,-3,LEAVES:3)
Block(-14,13,-2,LEAVES:3)
Block(-3,13,-2,LEAVES:3)
Block(-2,13,-2,LOG:15)
Block(-1,13,-2,LOG:15)
Block(-3,13,-1,LOG:15)
Block(-2,13,-1,LOG:15)
Block(-4,13,0,LOG:15)
Block(-3,13,0,LOG:15)
Block(-2,13,0,LOG:15)
Block(-4,13,1,LOG:15)
Block(-3,13,1,LOG:15)
Block(-2,13,1,LOG:15)
Block(-1,13,1,LOG:15)
Block(0,13,1,LOG:15)
Block(1,13,1,LOG:15)
Block(2,13,1,LOG:15)
Block(-5,13,2,LEAVES:3)
Block(-4,13,2,LOG:15)
Block(-3,13,2,LOG:15)
Block(-2,13,2,LOG:15)
Block(-1,13,2,LOG:15)
Block(0,13,2,LOG:15)
Block(1,13,2,LOG:15)
Block(2,13,2,LOG:15)
Block(-4,13,3,LEAVES:3)
Block(-3,13,3,LOG:15)
Block(-2,13,3,LOG:15)
Block(-1,13,3,LOG:15)
Block(0,13,3,LOG:15)
Block(1,13,3,LOG:15)
Block(2,13,3,LEAVES:3)
Block(-3,14,-4,LEAVES:3)
Block(-2,14,-4,LEAVES:3)
Block(-1,14,-4,LEAVES:3)
Block(-3,14,-3,LEAVES:3)
Block(-2,14,-3,LOG:15)
Block(-1,14,-3,LOG:15)
Block(0,14,-3,LOG:15)
Block(4,14,-3,LEAVES:3)
Block(-14,14,-2,LEAVES:3)
Block(-4,14,-2,LEAVES:3)
Block(-3,14,-2,LOG:15)
Block(-2,14,-2,LOG:15)
Block(-1,14,-2,LOG:15)
Block(0,14,-2,LOG:15)
Block(1,14,-2,LEAVES:3)
Block(-4,14,-1,LOG:15)
Block(-3,14,-1,LOG:15)
Block(-2,14,-1,LOG:15)
Block(-1,14,-1,LOG:15)
Block(0,14,-1,LOG:15)
Block(1,14,-1,LOG:15)
Block(-5,14,0,LEAVES:3)
Block(-4,14,0,LOG:15)
Block(-3,14,0,LOG:15)
Block(-2,14,0,LOG:15)
Block(-4,14,1,LEAVES:3)
Block(-3,14,1,LOG:15)
Block(-4,14,2,LEAVES:3)
Block(-3,14,2,LOG:15)
Block(-2,14,2,LOG:15)
Block(-1,14,2,LOG:15)
Block(0,14,2,LOG:15)
Block(1,14,2,LOG:15)
Block(5,14,2,LEAVES:3)
Block(9,14,8,LEAVES:3)
Block(2,15,-13,LEAVES:3)
Block(-11,15,-4,LEAVES:3)
Block(-2,15,-4,LEAVES:3)
Block(-3,15,-3,LEAVES:3)
Block(-2,15,-3,LEAVES:3)
Block(-1,15,-3,LEAVES:3)
Block(0,15,-3,LEAVES:3)
Block(1,15,-3,LOG:15)
Block(4,15,-3,LEAVES:3)
Block(-14,15,-2,LEAVES:3)
Block(-8,15,-2,LEAVES:3)
Block(-3,15,-2,LEAVES:3)
Block(-2,15,-2,LOG:15)
Block(-1,15,-2,LOG:15)
Block(0,15,-2,LOG:15)
Block(1,15,-2,LOG:15)
Block(2,15,-2,LOG:15)
Block(-3,15,-1,LOG:15)
Block(-2,15,-1,LOG:15)
Block(-1,15,-1,LEAVES:3)
Block(0,15,-1,LEAVES:3)
Block(1,15,-1,LOG:15)
Block(-4,15,0,LEAVES:3)
Block(-3,15,0,LOG:15)
Block(5,15,2,LEAVES:3)
Block(6,15,6,LEAVES:3)
Block(12,15,6,LEAVES:3)
Block(9,15,8,LEAVES:3)
Block(3,16,-17,LEAVES:3)
Block(2,16,-13,LEAVES:3)
Block(-14,16,-4,LEAVES:3)
Block(-11,16,-4,LEAVES:3)
Block(-15,16,-3,LEAVES:3)
Block(-14,16,-3,LEAVES:3)
Block(-13,16,-3,LEAVES:3)
Block(0,16,-3,LEAVES:3)
Block(1,16,-3,LOG:15)
Block(2,16,-3,LOG:15)
Block(3,16,-3,LEAVES:3)
Block(4,16,-3,LEAVES:3)
Block(-14,16,-2,LEAVES:3)
Block(-8,16,-2,LEAVES:3)
Block(-1,16,-2,LEAVES:3)
Block(0,16,-2,LOG:15)
Block(1,16,-2,LOG:15)
Block(2,16,-2,LOG:15)
Block(3,16,-2,LOG:15)
Block(4,16,-2,LEAVES:3)
Block(0,16,-1,LEAVES:3)
Block(1,16,-1,LOG:15)
Block(2,16,-1,LOG:15)
Block(3,16,-1,LOG:15)
Block(3,16,0,LOG:15)
Block(3,16,1,LOG:15)
Block(2,16,2,LOG:15)
Block(3,16,2,LOG:15)
Block(5,16,2,LEAVES:3)
Block(6,16,6,LEAVES:3)
Block(12,16,6,LEAVES:3)
Block(9,16,8,LEAVES:3)
Block(3,17,-17,LEAVES:3)
Block(2,17,-13,LEAVES:3)
Block(-2,17,-11,LEAVES:3)
Block(-14,17,-6,LEAVES:3)
Block(-15,17,-5,LEAVES:3)
Block(-14,17,-5,LEAVES:3)
Block(-13,17,-5,LEAVES:3)
Block(-2,17,-5,LEAVES:3)
Block(-15,17,-4,LEAVES:3)
Block(-14,17,-4,LOG:15)
Block(-13,17,-4,LEAVES:3)
Block(-11,17,-4,LEAVES:3)
Block(8,17,-4,LEAVES:3)
Block(-15,17,-3,LEAVES:3)
Block(-14,17,-3,LOG:15)
Block(-13,17,-3,LEAVES:3)
Block(2,17,-3,LOG:15)
Block(3,17,-3,LEAVES:3)
Block(4,17,-3,LEAVES:3)
Block(-15,17,-2,LEAVES:3)
Block(-14,17,-2,LEAVES:3)
Block(-13,17,-2,LEAVES:3)
Block(-8,17,-2,LEAVES:3)
Block(1,17,-2,LOG:15)
Block(2,17,-2,LOG:15)
Block(3,17,-2,LOG:15)
Block(4,17,-2,LEAVES:3)
Block(2,17,-1,LOG:15)
Block(3,17,-1,LOG:15)
Block(4,17,-1,LOG:15)
Block(2,17,0,LOG:15)
Block(3,17,0,LOG:15)
Block(4,17,0,LOG:15)
Block(2,17,1,LOG:15)
Block(3,17,1,LOG:15)
Block(4,17,1,LOG:15)
Block(1,17,2,LOG:15)
Block(2,17,2,LOG:15)
Block(3,17,2,LOG:15)
Block(4,17,2,LOG:15)
Block(5,17,2,LEAVES:3)
Block(2,17,3,LOG:15)
Block(3,17,3,LOG:15)
Block(4,17,3,LEAVES:3)
Block(5,17,3,LEAVES:3)
Block(6,17,3,LEAVES:3)
Block(5,17,4,LEAVES:3)
Block(6,17,6,LEAVES:3)
Block(12,17,6,LEAVES:3)
Block(-9,17,7,LEAVES:3)
Block(10,17,7,LEAVES:3)
Block(9,17,8,LEAVES:3)
Block(10,17,8,LEAVES:3)
Block(11,17,8,LOG:15)
Block(10,17,9,LEAVES:3)
Block(3,18,-17,LEAVES:3)
Block(1,18,-15,LOG:15)
Block(2,18,-15,LOG:15)
Block(2,18,-13,LEAVES:3)
Block(-2,18,-11,LEAVES:3)
Block(-15,18,-6,LEAVES:3)
Block(-14,18,-6,LEAVES:3)
Block(-13,18,-6,LEAVES:3)
Block(12,18,-6,LEAVES:3)
Block(-15,18,-5,LEAVES:3)
Block(-14,18,-5,LOG:15)
Block(-13,18,-5,LEAVES:3)
Block(-2,18,-5,LEAVES:3)
Block(-15,18,-4,LOG:15)
Block(-14,18,-4,LOG:15)
Block(-13,18,-4,LOG:15)
Block(-11,18,-4,LEAVES:3)
Block(8,18,-4,LEAVES:3)
Block(-15,18,-3,LOG:15)
Block(-14,18,-3,LOG:15)
Block(-13,18,-3,LOG:15)
Block(3,18,-3,LEAVES:3)
Block(-14,18,-2,LOG:15)
Block(-13,18,-2,LEAVES:3)
Block(-12,18,-2,LEAVES:3)
Block(-8,18,-2,LEAVES:3)
Block(2,18,-2,LOG:15)
Block(3,18,-2,LEAVES:3)
Block(4,18,-2,LEAVES:3)
Block(-13,18,-1,LEAVES:3)
Block(3,18,-1,LOG:15)
Block(-2,18,0,LOG:15)
Block(3,18,0,LOG:15)
Block(5,18,0,LEAVES:3)
Block(-9,18,1,LEAVES:3)
Block(-3,18,1,LOG:15)
Block(-2,18,1,LOG:15)
Block(1,18,1,LOG:15)
Block(2,18,1,LOG:15)
Block(3,18,1,LOG:15)
Block(4,18,1,LOG:15)
Block(5,18,1,LEAVES:3)
Block(6,18,1,LEAVES:3)
Block(-3,18,2,LEAVES:15)
Block(-2,18,2,LOG:15)
Block(-1,18,2,LOG:15)
Block(0,18,2,LOG:15)
Block(1,18,2,LOG:15)
Block(2,18,2,LOG:15)
Block(3,18,2,LOG:15)
Block(4,18,2,LOG:15)
Block(5,18,2,LOG:15)
Block(6,18,2,LEAVES:3)
Block(-4,18,3,LEAVES:15)
Block(-3,18,3,LEAVES:15)
Block(-2,18,3,LEAVES:15)
Block(-1,18,3,LEAVES:15)
Block(1,18,3,LOG:15)
Block(2,18,3,LOG:15)
Block(3,18,3,LOG:15)
Block(4,18,3,LOG:15)
Block(5,18,3,LOG:15)
Block(6,18,3,LEAVES:3)
Block(7,18,3,LEAVES:3)
Block(-3,18,4,LEAVES:15)
Block(-2,18,4,LEAVES:15)
Block(1,18,4,LEAVES:15)
Block(2,18,4,LEAVES:15)
Block(3,18,4,LEAVES:15)
Block(4,18,4,LEAVES:3)
Block(5,18,4,LEAVES:3)
Block(6,18,4,LEAVES:3)
Block(7,18,4,LEAVES:3)
Block(8,18,4,LEAVES:3)
Block(1,18,5,LEAVES:15)
Block(2,18,5,LEAVES:15)
Block(3,18,5,LEAVES:15)
Block(7,18,5,LEAVES:3)
Block(-1,18,6,LEAVES:15)
Block(2,18,6,LEAVES:15)
Block(6,18,6,LEAVES:3)
Block(9,18,6,LEAVES:3)
Block(12,18,6,LEAVES:3)
Block(-9,18,7,LEAVES:3)
Block(-6,18,7,LEAVES:15)
Block(-2,18,7,LEAVES:15)
Block(-1,18,7,LEAVES:15)
Block(0,18,7,LEAVES:15)
Block(8,18,7,LEAVES:3)
Block(9,18,7,LEAVES:3)
Block(10,18,7,LOG:15)
Block(11,18,7,LOG:15)
Block(-7,18,8,LEAVES:15)
Block(-6,18,8,LEAVES:15)
Block(-5,18,8,LEAVES:15)
Block(-1,18,8,LEAVES:15)
Block(9,18,8,LEAVES:3)
Block(10,18,8,LOG:15)
Block(11,18,8,LOG:15)
Block(12,18,8,LOG:15)
Block(-6,18,9,LEAVES:15)
Block(9,18,9,LEAVES:3)
Block(10,18,9,LEAVES:3)
Block(11,18,9,LOG:15)
Block(12,18,9,LEAVES:3)
Block(11,18,10,LEAVES:3)
Block(3,19,-17,LEAVES:3)
Block(0,19,-16,LEAVES:3)
Block(1,19,-16,LOG:15)
Block(2,19,-16,LOG:15)
Block(-1,19,-15,LEAVES:3)
Block(0,19,-15,LOG:15)
Block(1,19,-15,LOG:15)
Block(2,19,-15,LOG:15)
Block(3,19,-15,LOG:15)
Block(0,19,-14,LEAVES:3)
Block(1,19,-14,LOG:15)
Block(2,19,-14,LOG:15)
Block(3,19,-14,LEAVES:3)
Block(1,19,-13,LOG:15)
Block(2,19,-13,LEAVES:3)
Block(-2,19,-11,LEAVES:3)
Block(-13,19,-7,LEAVES:15)
Block(-14,19,-6,LEAVES:3)
Block(-13,19,-6,LEAVES:15)
Block(-12,19,-6,LEAVES:15)
Block(12,19,-6,LEAVES:3)
Block(-15,19,-5,LEAVES:3)
Block(-14,19,-5,LEAVES:3)
Block(-13,19,-5,LEAVES:3)
Block(-12,19,-5,LEAVES:3)
Block(-2,19,-5,LEAVES:3)
Block(-14,19,-4,LOG:15)
Block(-13,19,-4,LOG:15)
Block(-12,19,-4,LEAVES:3)
Block(-11,19,-4,LEAVES:3)
Block(8,19,-4,LEAVES:3)
Block(-15,19,-3,LOG:15)
Block(-14,19,-3,LOG:15)
Block(-13,19,-3,LOG:15)
Block(-12,19,-3,LOG:15)
Block(0,19,-3,LOG:15)
Block(-14,19,-2,LOG:15)
Block(-13,19,-2,LOG:15)
Block(-12,19,-2,LOG:15)
Block(-8,19,-2,LEAVES:3)
Block(-1,19,-2,LOG:15)
Block(0,19,-2,LOG:15)
Block(-14,19,-1,LEAVES:3)
Block(-13,19,-1,LEAVES:3)
Block(-12,19,-1,LEAVES:3)
Block(-6,19,-1,LEAVES:3)
Block(-2,19,-1,LOG:15)
Block(-1,19,-1,LOG:15)
Block(-7,19,0,LEAVES:3)
Block(-6,19,0,LEAVES:3)
Block(-5,19,0,LEAVES:3)
Block(-3,19,0,LOG:15)
Block(-2,19,0,LOG:15)
Block(-1,19,0,LOG:15)
Block(2,19,0,LEAVES:3)
Block(3,19,0,LEAVES:3)
Block(4,19,0,LEAVES:3)
Block(5,19,0,LEAVES:3)
Block(6,19,0,LEAVES:3)
Block(-9,19,1,LEAVES:3)
Block(-6,19,1,LEAVES:3)
Block(-5,19,1,LOG:15)
Block(-4,19,1,LOG:15)
Block(-3,19,1,LOG:15)
Block(-2,19,1,LOG:15)
Block(-1,19,1,LOG:15)
Block(0,19,1,LOG:15)
Block(1,19,1,LOG:15)
Block(2,19,1,LEAVES:3)
Block(3,19,1,LOG:15)
Block(4,19,1,LOG:15)
Block(5,19,1,LOG:15)
Block(6,19,1,LEAVES:3)
Block(-4,19,2,LEAVES:15)
Block(-3,19,2,LOG:15)
Block(-2,19,2,LOG:15)
Block(-1,19,2,LOG:15)
Block(0,19,2,LOG:15)
Block(1,19,2,LOG:15)
Block(2,19,2,LOG:15)
Block(3,19,2,LOG:15)
Block(4,19,2,LOG:15)
Block(5,19,2,LOG:15)
Block(6,19,2,LOG:15)
Block(-4,19,3,LEAVES:15)
Block(-3,19,3,LEAVES:15)
Block(-2,19,3,LOG:15)
Block(-1,19,3,LOG:15)
Block(0,19,3,LOG:15)
Block(1,19,3,LOG:15)
Block(2,19,3,LEAVES:15)
Block(3,19,3,LEAVES:15)
Block(4,19,3,LOG:15)
Block(5,19,3,LOG:15)
Block(6,19,3,LOG:15)
Block(7,19,3,LEAVES:3)
Block(8,19,3,LEAVES:3)
Block(-4,19,4,LEAVES:15)
Block(-3,19,4,LEAVES:15)
Block(-2,19,4,LEAVES:15)
Block(-1,19,4,LEAVES:15)
Block(0,19,4,LEAVES:15)
Block(1,19,4,LEAVES:15)
Block(2,19,4,LEAVES:15)
Block(3,19,4,LEAVES:15)
Block(5,19,4,LOG:15)
Block(6,19,4,LOG:15)
Block(7,19,4,LOG:15)
Block(8,19,4,LEAVES:3)
Block(0,19,5,LEAVES:15)
Block(1,19,5,LEAVES:15)
Block(2,19,5,LEAVES:15)
Block(3,19,5,LEAVES:15)
Block(5,19,5,LEAVES:3)
Block(6,19,5,LEAVES:3)
Block(7,19,5,LOG:15)
Block(8,19,5,LEAVES:3)
Block(10,19,5,LEAVES:3)
Block(-6,19,6,LEAVES:15)
Block(-4,19,6,LEAVES:15)
Block(-2,19,6,LEAVES:15)
Block(-1,19,6,LEAVES:15)
Block(0,19,6,LEAVES:15)
Block(1,19,6,LEAVES:15)
Block(2,19,6,LEAVES:15)
Block(3,19,6,LEAVES:15)
Block(6,19,6,LEAVES:3)
Block(8,19,6,LEAVES:3)
Block(9,19,6,LEAVES:3)
Block(10,19,6,LOG:15)
Block(11,19,6,LEAVES:3)
Block(12,19,6,LEAVES:3)
Block(-9,19,7,LEAVES:3)
Block(-7,19,7,LEAVES:15)
Block(-6,19,7,LEAVES:15)
Block(-5,19,7,LEAVES:15)
Block(-4,19,7,LEAVES:15)
Block(-3,19,7,LEAVES:15)
Block(-2,19,7,LEAVES:15)
Block(-1,19,7,LEAVES:15)
Block(0,19,7,LEAVES:15)
Block(1,19,7,LEAVES:15)
Block(2,19,7,LEAVES:15)
Block(3,19,7,LEAVES:15)
Block(4,19,7,LEAVES:15)
Block(8,19,7,LEAVES:3)
Block(9,19,7,LOG:15)
Block(10,19,7,LOG:15)
Block(11,19,7,LOG:15)
Block(12,19,7,LEAVES:3)
Block(-7,19,8,LEAVES:15)
Block(-6,19,8,LEAVES:15)
Block(-5,19,8,LEAVES:15)
Block(-4,19,8,LEAVES:15)
Block(-2,19,8,LEAVES:15)
Block(-1,19,8,LEAVES:15)
Block(0,19,8,LEAVES:15)
Block(1,19,8,LEAVES:15)
Block(3,19,8,LEAVES:15)
Block(8,19,8,LEAVES:3)
Block(9,19,8,LEAVES:3)
Block(10,19,8,LOG:15)
Block(11,19,8,LOG:15)
Block(12,19,8,LOG:15)
Block(-7,19,9,LEAVES:15)
Block(-6,19,9,LEAVES:15)
Block(-5,19,9,LEAVES:15)
Block(0,19,9,LEAVES:15)
Block(10,19,9,LEAVES:3)
Block(11,19,9,LOG:15)
Block(12,19,9,LEAVES:3)
Block(10,19,10,LEAVES:3)
Block(11,19,10,LEAVES:3)
Block(12,19,10,LEAVES:3)
Block(3,20,-17,LEAVES:3)
Block(-1,20,-16,LEAVES:3)
Block(0,20,-16,LEAVES:3)
Block(1,20,-16,LOG:15)
Block(2,20,-16,LEAVES:3)
Block(3,20,-16,LEAVES:3)
Block(4,20,-16,LEAVES:3)
Block(-1,20,-15,LEAVES:3)
Block(0,20,-15,LOG:15)
Block(1,20,-15,LOG:15)
Block(2,20,-15,LOG:15)
Block(3,20,-15,LEAVES:3)
Block(-1,20,-14,LEAVES:3)
Block(0,20,-14,LOG:15)
Block(1,20,-14,LOG:15)
Block(2,20,-14,LOG:15)
Block(3,20,-14,LEAVES:3)
Block(-1,20,-13,LEAVES:3)
Block(0,20,-13,LOG:15)
Block(1,20,-13,LOG:15)
Block(2,20,-13,LOG:15)
Block(3,20,-13,LEAVES:3)
Block(-1,20,-12,LEAVES:3)
Block(0,20,-12,LEAVES:3)
Block(1,20,-12,LOG:15)
Block(-2,20,-11,LEAVES:3)
Block(-7,20,-9,LEAVES:15)
Block(-10,20,-8,LEAVES:15)
Block(-9,20,-8,LEAVES:15)
Block(-8,20,-8,LEAVES:15)
Block(-7,20,-8,LEAVES:15)
Block(-6,20,-8,LEAVES:15)
Block(-14,20,-7,LEAVES:15)
Block(-13,20,-7,LEAVES:15)
Block(-12,20,-7,LEAVES:15)
Block(-11,20,-7,LEAVES:15)
Block(-10,20,-7,LEAVES:15)
Block(-9,20,-7,LEAVES:15)
Block(-8,20,-7,LEAVES:15)
Block(-7,20,-7,LEAVES:15)
Block(-14,20,-6,LEAVES:15)
Block(-13,20,-6,LEAVES:15)
Block(-12,20,-6,LEAVES:15)
Block(-11,20,-6,LEAVES:15)
Block(-10,20,-6,LEAVES:15)
Block(-9,20,-6,LEAVES:15)
Block(-8,20,-6,LEAVES:15)
Block(12,20,-6,LEAVES:3)
Block(-16,20,-5,LEAVES:15)
Block(-14,20,-5,LEAVES:15)
Block(-13,20,-5,LEAVES:3)
Block(-12,20,-5,LEAVES:3)
Block(-11,20,-5,LEAVES:3)
Block(-2,20,-5,LEAVES:3)
Block(-17,20,-4,LEAVES:15)
Block(-16,20,-4,LEAVES:15)
Block(-15,20,-4,LEAVES:15)
Block(-13,20,-4,LOG:15)
Block(-12,20,-4,LOG:15)
Block(-11,20,-4,LEAVES:3)
Block(0,20,-4,LOG:15)
Block(2,20,-4,LEAVES:3)
Block(8,20,-4,LEAVES:3)
Block(-16,20,-3,LEAVES:15)
Block(-14,20,-3,LOG:15)
Block(-13,20,-3,LOG:15)
Block(-12,20,-3,LOG:15)
Block(-11,20,-3,LOG:15)
Block(-2,20,-3,LOG:15)
Block(-1,20,-3,LOG:15)
Block(0,20,-3,LOG:15)
Block(1,20,-3,LOG:15)
Block(2,20,-3,LOG:15)
Block(3,20,-3,LEAVES:3)
Block(-15,20,-2,LEAVES:15)
Block(-14,20,-2,LEAVES:3)
Block(-13,20,-2,LOG:15)
Block(-12,20,-2,LOG:15)
Block(-11,20,-2,LOG:15)
Block(-8,20,-2,LEAVES:3)
Block(-2,20,-2,LOG:15)
Block(-1,20,-2,LOG:15)
Block(0,20,-2,LOG:15)
Block(1,20,-2,LOG:15)
Block(2,20,-2,LOG:15)
Block(3,20,-2,LOG:15)
Block(-15,20,-1,LEAVES:15)
Block(-14,20,-1,LEAVES:15)
Block(-13,20,-1,LEAVES:3)
Block(-12,20,-1,LOG:15)
Block(-11,20,-1,LEAVES:3)
Block(-10,20,-1,LEAVES:3)
Block(-9,20,-1,LEAVES:3)
Block(-8,20,-1,LEAVES:3)
Block(-7,20,-1,LEAVES:3)
Block(-6,20,-1,LEAVES:3)
Block(-5,20,-1,LEAVES:3)
Block(-3,20,-1,LOG:15)
Block(-2,20,-1,LOG:15)
Block(-1,20,-1,LOG:15)
Block(0,20,-1,LOG:15)
Block(-14,20,0,LEAVES:15)
Block(-11,20,0,LEAVES:3)
Block(-8,20,0,LEAVES:3)
Block(-7,20,0,LOG:15)
Block(-6,20,0,LOG:15)
Block(-5,20,0,LOG:15)
Block(-4,20,0,LOG:15)
Block(-3,20,0,LOG:15)
Block(-2,20,0,LOG:15)
Block(3,20,0,LEAVES:3)
Block(5,20,0,LEAVES:3)
Block(-9,20,1,LEAVES:3)
Block(-7,20,1,LEAVES:3)
Block(-6,20,1,LOG:15)
Block(-5,20,1,LOG:15)
Block(-4,20,1,LOG:15)
Block(-3,20,1,LOG:15)
Block(-2,20,1,LOG:15)
Block(2,20,1,LEAVES:3)
Block(3,20,1,LEAVES:3)
Block(4,20,1,LEAVES:3)
Block(5,20,1,LEAVES:3)
Block(6,20,1,LEAVES:3)
Block(-6,20,2,LEAVES:3)
Block(-5,20,2,LOG:15)
Block(-4,20,2,LOG:15)
Block(-3,20,2,LOG:15)
Block(-2,20,2,LOG:15)
Block(-1,20,2,LOG:15)
Block(0,20,2,LOG:15)
Block(1,20,2,LOG:15)
Block(2,20,2,LEAVES:15)
Block(3,20,2,LEAVES:3)
Block(4,20,2,LOG:15)
Block(5,20,2,LOG:15)
Block(6,20,2,LOG:15)
Block(7,20,2,LEAVES:3)
Block(-5,20,3,LEAVES:3)
Block(-4,20,3,LEAVES:15)
Block(-3,20,3,LEAVES:15)
Block(-2,20,3,LEAVES:15)
Block(-1,20,3,LEAVES:15)
Block(0,20,3,LEAVES:15)
Block(1,20,3,LEAVES:15)
Block(2,20,3,LEAVES:15)
Block(3,20,3,LEAVES:15)
Block(4,20,3,LOG:15)
Block(5,20,3,LOG:15)
Block(6,20,3,LOG:15)
Block(7,20,3,LOG:15)
Block(8,20,3,LEAVES:3)
Block(-7,20,4,LEAVES:15)
Block(-5,20,4,LEAVES:15)
Block(-4,20,4,LEAVES:15)
Block(-3,20,4,LEAVES:15)
Block(-2,20,4,LEAVES:15)
Block(-1,20,4,LEAVES:15)
Block(0,20,4,LEAVES:15)
Block(1,20,4,LEAVES:15)
Block(2,20,4,LEAVES:15)
Block(3,20,4,LEAVES:15)
Block(5,20,4,LOG:15)
Block(6,20,4,LOG:15)
Block(7,20,4,LOG:15)
Block(8,20,4,LOG:15)
Block(-8,20,5,LEAVES:15)
Block(-7,20,5,LEAVES:15)
Block(-6,20,5,LEAVES:15)
Block(-4,20,5,LEAVES:15)
Block(-2,20,5,LEAVES:3)
Block(-1,20,5,LEAVES:15)
Block(0,20,5,LEAVES:15)
Block(1,20,5,LEAVES:15)
Block(2,20,5,LEAVES:15)
Block(3,20,5,LEAVES:15)
Block(5,20,5,LEAVES:3)
Block(6,20,5,LOG:15)
Block(7,20,5,LOG:15)
Block(8,20,5,LOG:15)
Block(9,20,5,LEAVES:3)
Block(10,20,5,LEAVES:3)
Block(11,20,5,LEAVES:3)
Block(-7,20,6,LEAVES:15)
Block(-6,20,6,LEAVES:15)
Block(-5,20,6,LEAVES:3)
Block(-4,20,6,LEAVES:15)
Block(-3,20,6,LEAVES:15)
Block(-1,20,6,LEAVES:15)
Block(0,20,6,LEAVES:15)
Block(1,20,6,LEAVES:15)
Block(2,20,6,LEAVES:15)
Block(3,20,6,LEAVES:15)
Block(4,20,6,LEAVES:15)
Block(5,20,6,LEAVES:3)
Block(6,20,6,LEAVES:3)
Block(7,20,6,LOG:15)
Block(8,20,6,LOG:15)
Block(9,20,6,LOG:15)
Block(10,20,6,LOG:15)
Block(11,20,6,LEAVES:3)
Block(12,20,6,LEAVES:3)
Block(-9,20,7,LEAVES:3)
Block(-7,20,7,LEAVES:15)
Block(-6,20,7,LEAVES:15)
Block(-5,20,7,LEAVES:15)
Block(-4,20,7,LEAVES:15)
Block(-3,20,7,LEAVES:15)
Block(-2,20,7,LEAVES:15)
Block(-1,20,7,LEAVES:15)
Block(0,20,7,LEAVES:15)
Block(1,20,7,LEAVES:15)
Block(2,20,7,LEAVES:15)
Block(3,20,7,LEAVES:15)
Block(4,20,7,LEAVES:15)
Block(8,20,7,LEAVES:3)
Block(9,20,7,LOG:15)
Block(10,20,7,LOG:15)
Block(11,20,7,LOG:15)
Block(12,20,7,LEAVES:3)
Block(-10,20,8,LEAVES:3)
Block(-9,20,8,LEAVES:3)
Block(-8,20,8,LEAVES:3)
Block(-7,20,8,LEAVES:15)
Block(-6,20,8,LEAVES:15)
Block(-5,20,8,LEAVES:15)
Block(-4,20,8,LEAVES:15)
Block(-3,20,8,LEAVES:15)
Block(-1,20,8,LEAVES:15)
Block(0,20,8,LEAVES:15)
Block(1,20,8,LEAVES:15)
Block(2,20,8,LEAVES:15)
Block(3,20,8,LEAVES:15)
Block(4,20,8,LEAVES:15)
Block(8,20,8,LEAVES:3)
Block(9,20,8,LOG:15)
Block(10,20,8,LOG:15)
Block(11,20,8,LOG:15)
Block(12,20,8,LOG:15)
Block(-9,20,9,LEAVES:3)
Block(-6,20,9,LEAVES:15)
Block(-4,20,9,LEAVES:15)
Block(-3,20,9,LEAVES:15)
Block(-2,20,9,LEAVES:15)
Block(-1,20,9,LEAVES:15)
Block(0,20,9,LEAVES:15)
Block(1,20,9,LEAVES:15)
Block(3,20,9,LEAVES:15)
Block(7,20,9,LEAVES:15)
Block(8,20,9,LEAVES:15)
Block(9,20,9,LEAVES:3)
Block(10,20,9,LOG:15)
Block(11,20,9,LOG:15)
Block(12,20,9,LEAVES:3)
Block(-9,20,10,LEAVES:15)
Block(-3,20,10,LEAVES:15)
Block(-1,20,10,LEAVES:15)
Block(8,20,10,LEAVES:15)
Block(11,20,10,LEAVES:3)
Block(-10,20,11,LEAVES:15)
Block(-9,20,11,LEAVES:15)
Block(-8,20,11,LEAVES:15)
Block(-2,20,11,LEAVES:15)
Block(-1,20,11,LEAVES:15)
Block(0,20,11,LEAVES:15)
Block(-9,20,12,LEAVES:15)
Block(-1,20,12,LEAVES:15)
Block(2,21,-17,LEAVES:3)
Block(3,21,-17,LEAVES:3)
Block(4,21,-17,LEAVES:3)
Block(0,21,-16,LEAVES:3)
Block(2,21,-16,LEAVES:3)
Block(3,21,-16,LEAVES:3)
Block(4,21,-16,LEAVES:3)
Block(-1,21,-15,LEAVES:3)
Block(0,21,-15,LEAVES:3)
Block(1,21,-15,LOG:15)
Block(2,21,-15,LOG:15)
Block(3,21,-15,LEAVES:3)
Block(4,21,-15,LEAVES:3)
Block(-1,21,-14,LEAVES:3)
Block(0,21,-14,LOG:15)
Block(1,21,-14,LOG:15)
Block(2,21,-14,LOG:15)
Block(3,21,-14,LOG:15)
Block(-1,21,-13,LEAVES:3)
Block(0,21,-13,LOG:15)
Block(1,21,-13,LOG:15)
Block(2,21,-13,LOG:15)
Block(-3,21,-12,LEAVES:15)
Block(-2,21,-12,LEAVES:3)
Block(-1,21,-12,LEAVES:3)
Block(0,21,-12,LEAVES:3)
Block(1,21,-12,LOG:15)
Block(2,21,-12,LEAVES:3)
Block(3,21,-12,LEAVES:3)
Block(-4,21,-11,LEAVES:15)
Block(-3,21,-11,LEAVES:15)
Block(-2,21,-11,LEAVES:3)
Block(-1,21,-11,LEAVES:3)
Block(2,21,-11,LEAVES:3)
Block(-7,21,-10,LEAVES:15)
Block(-5,21,-10,LEAVES:15)
Block(-4,21,-10,LEAVES:15)
Block(-3,21,-10,LEAVES:3)
Block(-2,21,-10,LEAVES:3)
Block(-1,21,-10,LOG:15)
Block(-8,21,-9,LEAVES:15)
Block(-7,21,-9,LEAVES:15)
Block(-6,21,-9,LEAVES:15)
Block(-5,21,-9,LEAVES:15)
Block(-4,21,-9,LEAVES:3)
Block(-3,21,-9,LEAVES:3)
Block(-2,21,-9,LEAVES:3)
Block(0,21,-9,LEAVES:3)
Block(-11,21,-8,LEAVES:15)
Block(-10,21,-8,LEAVES:15)
Block(-9,21,-8,LEAVES:15)
Block(-8,21,-8,LEAVES:15)
Block(-7,21,-8,LEAVES:15)
Block(-6,21,-8,LEAVES:15)
Block(-5,21,-8,LEAVES:15)
Block(-3,21,-8,LEAVES:3)
Block(-1,21,-8,LEAVES:3)
Block(0,21,-8,LEAVES:3)
Block(1,21,-8,LEAVES:3)
Block(-13,21,-7,LEAVES:15)
Block(-12,21,-7,LEAVES:15)
Block(-11,21,-7,LEAVES:15)
Block(-10,21,-7,LEAVES:15)
Block(-9,21,-7,LEAVES:15)
Block(-8,21,-7,LEAVES:15)
Block(-7,21,-7,LEAVES:15)
Block(-6,21,-7,LEAVES:15)
Block(0,21,-7,LEAVES:3)
Block(-14,21,-6,LEAVES:15)
Block(-13,21,-6,LEAVES:15)
Block(-12,21,-6,LEAVES:15)
Block(-11,21,-6,LEAVES:15)
Block(-10,21,-6,LEAVES:15)
Block(-9,21,-6,LEAVES:15)
Block(-8,21,-6,LEAVES:15)
Block(-7,21,-6,LEAVES:15)
Block(-3,21,-6,LEAVES:3)
Block(12,21,-6,LEAVES:3)
Block(13,21,-6,LEAVES:3)
Block(-17,21,-5,LEAVES:15)
Block(-16,21,-5,LEAVES:15)
Block(-15,21,-5,LEAVES:15)
Block(-13,21,-5,LEAVES:15)
Block(-12,21,-5,LEAVES:3)
Block(-11,21,-5,LEAVES:15)
Block(-10,21,-5,LEAVES:15)
Block(-4,21,-5,LEAVES:3)
Block(-3,21,-5,LEAVES:3)
Block(-2,21,-5,LOG:15)
Block(12,21,-5,LEAVES:3)
Block(13,21,-5,LOG:15)
Block(14,21,-5,LEAVES:3)
Block(-17,21,-4,LEAVES:15)
Block(-16,21,-4,LEAVES:15)
Block(-15,21,-4,LEAVES:15)
Block(-14,21,-4,LEAVES:3)
Block(-13,21,-4,LEAVES:3)
Block(-12,21,-4,LEAVES:3)
Block(-11,21,-4,LEAVES:3)
Block(-3,21,-4,LEAVES:3)
Block(-2,21,-4,LOG:15)
Block(-1,21,-4,LOG:15)
Block(0,21,-4,LOG:15)
Block(1,21,-4,LOG:15)
Block(2,21,-4,LOG:15)
Block(3,21,-4,LEAVES:3)
Block(8,21,-4,LEAVES:3)
Block(13,21,-4,LEAVES:3)
Block(-17,21,-3,LEAVES:15)
Block(-16,21,-3,LEAVES:15)
Block(-15,21,-3,LEAVES:15)
Block(-14,21,-3,LEAVES:3)
Block(-13,21,-3,LOG:15)
Block(-12,21,-3,LOG:15)
Block(-11,21,-3,LOG:15)
Block(-10,21,-3,LEAVES:3)
Block(-3,21,-3,LOG:15)
Block(-2,21,-3,LOG:15)
Block(-1,21,-3,LOG:15)
Block(0,21,-3,LOG:15)
Block(1,21,-3,LOG:15)
Block(2,21,-3,LOG:15)
Block(3,21,-3,LOG:15)
Block(13,21,-3,LEAVES:15)
Block(-15,21,-2,LEAVES:15)
Block(-14,21,-2,LEAVES:3)
Block(-13,21,-2,LOG:15)
Block(-12,21,-2,LOG:15)
Block(-11,21,-2,LOG:15)
Block(-10,21,-2,LOG:15)
Block(-9,21,-2,LEAVES:3)
Block(-8,21,-2,LEAVES:3)
Block(-7,21,-2,LEAVES:3)
Block(-3,21,-2,LEAVES:3)
Block(-2,21,-2,LOG:15)
Block(-1,21,-2,LOG:15)
Block(0,21,-2,LOG:15)
Block(1,21,-2,LOG:15)
Block(2,21,-2,LOG:15)
Block(3,21,-2,LOG:15)
Block(4,21,-2,LOG:15)
Block(12,21,-2,LEAVES:15)
Block(13,21,-2,LEAVES:15)
Block(14,21,-2,LEAVES:15)
Block(-15,21,-1,LEAVES:15)
Block(-14,21,-1,LEAVES:15)
Block(-13,21,-1,LEAVES:15)
Block(-12,21,-1,LOG:15)
Block(-11,21,-1,LOG:15)
Block(-10,21,-1,LOG:15)
Block(-9,21,-1,LOG:15)
Block(-8,21,-1,LOG:15)
Block(-7,21,-1,LOG:15)
Block(-6,21,-1,LOG:15)
Block(-5,21,-1,LOG:15)
Block(-4,21,-1,LEAVES:3)
Block(-3,21,-1,LOG:15)
Block(-2,21,-1,LOG:15)
Block(-1,21,-1,LOG:15)
Block(2,21,-1,LOG:15)
Block(3,21,-1,LOG:15)
Block(11,21,-1,LEAVES:15)
Block(12,21,-1,LEAVES:15)
Block(13,21,-1,LEAVES:15)
Block(14,21,-1,LEAVES:15)
Block(-15,21,0,LEAVES:15)
Block(-14,21,0,LEAVES:15)
Block(-13,21,0,LEAVES:15)
Block(-12,21,0,LEAVES:3)
Block(-11,21,0,LEAVES:3)
Block(-10,21,0,LEAVES:3)
Block(-9,21,0,LEAVES:3)
Block(-8,21,0,LOG:15)
Block(-7,21,0,LOG:15)
Block(-6,21,0,LOG:15)
Block(-5,21,0,LOG:15)
Block(-4,21,0,LOG:15)
Block(-3,21,0,LEAVES:3)
Block(-2,21,0,LOG:15)
Block(3,21,0,LOG:15)
Block(11,21,0,LEAVES:15)
Block(12,21,0,LEAVES:15)
Block(13,21,0,LEAVES:15)
Block(-13,21,1,LEAVES:15)
Block(-12,21,1,LEAVES:15)
Block(-11,21,1,LEAVES:15)
Block(-9,21,1,LEAVES:3)
Block(-7,21,1,LOG:15)
Block(-6,21,1,LOG:15)
Block(-5,21,1,LOG:15)
Block(-4,21,1,LOG:15)
Block(-3,21,1,LOG:15)
Block(2,21,1,LEAVES:15)
Block(3,21,1,LEAVES:15)
Block(4,21,1,LEAVES:15)
Block(10,21,1,LEAVES:15)
Block(11,21,1,LEAVES:15)
Block(12,21,1,LEAVES:15)
Block(-12,21,2,LEAVES:15)
Block(-8,21,2,LEAVES:15)
Block(-7,21,2,LEAVES:15)
Block(-6,21,2,LEAVES:3)
Block(-5,21,2,LOG:15)
Block(-4,21,2,LEAVES:3)
Block(2,21,2,LEAVES:15)
Block(3,21,2,LEAVES:15)
Block(4,21,2,LEAVES:3)
Block(5,21,2,LEAVES:3)
Block(6,21,2,LEAVES:3)
Block(7,21,2,LEAVES:3)
Block(8,21,2,LEAVES:3)
Block(9,21,2,LEAVES:15)
Block(10,21,2,LEAVES:15)
Block(11,21,2,LEAVES:15)
Block(-7,21,3,LEAVES:15)
Block(-6,21,3,LEAVES:3)
Block(-5,21,3,LEAVES:3)
Block(-4,21,3,LEAVES:3)
Block(-3,21,3,LEAVES:15)
Block(0,21,3,LEAVES:15)
Block(1,21,3,LEAVES:15)
Block(2,21,3,LEAVES:15)
Block(3,21,3,LEAVES:15)
Block(4,21,3,LEAVES:3)
Block(5,21,3,LOG:15)
Block(6,21,3,LOG:15)
Block(7,21,3,LEAVES:3)
Block(8,21,3,LEAVES:3)
Block(10,21,3,LEAVES:15)
Block(-8,21,4,LEAVES:15)
Block(-7,21,4,LEAVES:15)
Block(-6,21,4,LEAVES:15)
Block(-5,21,4,LEAVES:15)
Block(-4,21,4,LEAVES:15)
Block(-3,21,4,LEAVES:15)
Block(-2,21,4,LEAVES:15)
Block(-1,21,4,LEAVES:15)
Block(0,21,4,LEAVES:15)
Block(1,21,4,LEAVES:15)
Block(2,21,4,LEAVES:15)
Block(3,21,4,LEAVES:15)
Block(4,21,4,LEAVES:3)
Block(5,21,4,LEAVES:3)
Block(6,21,4,LOG:15)
Block(7,21,4,LOG:15)
Block(8,21,4,LOG:15)
Block(-8,21,5,LEAVES:15)
Block(-7,21,5,LEAVES:15)
Block(-6,21,5,LEAVES:15)
Block(-5,21,5,LEAVES:15)
Block(-4,21,5,LEAVES:15)
Block(-3,21,5,LEAVES:15)
Block(-2,21,5,LEAVES:3)
Block(-1,21,5,LEAVES:15)
Block(0,21,5,LEAVES:15)
Block(1,21,5,LEAVES:15)
Block(2,21,5,LEAVES:15)
Block(3,21,5,LEAVES:15)
Block(5,21,5,LEAVES:3)
Block(6,21,5,LOG:15)
Block(7,21,5,LOG:15)
Block(8,21,5,LOG:15)
Block(9,21,5,LOG:15)
Block(10,21,5,LEAVES:3)
Block(-8,21,6,LEAVES:15)
Block(-7,21,6,LEAVES:15)
Block(-6,21,6,LEAVES:15)
Block(-5,21,6,LEAVES:3)
Block(-4,21,6,LEAVES:15)
Block(-3,21,6,LEAVES:15)
Block(-2,21,6,LEAVES:15)
Block(-1,21,6,LEAVES:15)
Block(0,21,6,LEAVES:15)
Block(1,21,6,LEAVES:15)
Block(2,21,6,LEAVES:15)
Block(3,21,6,LEAVES:15)
Block(6,21,6,LEAVES:3)
Block(7,21,6,LOG:15)
Block(8,21,6,LOG:15)
Block(9,21,6,LOG:15)
Block(10,21,6,LOG:15)
Block(11,21,6,LEAVES:3)
Block(-10,21,7,LEAVES:3)
Block(-9,21,7,LEAVES:3)
Block(-8,21,7,LEAVES:3)
Block(-7,21,7,LEAVES:15)
Block(-6,21,7,LEAVES:15)
Block(-5,21,7,LEAVES:15)
Block(-4,21,7,LEAVES:15)
Block(-3,21,7,LEAVES:15)
Block(-2,21,7,LEAVES:15)
Block(-1,21,7,LEAVES:15)
Block(0,21,7,LEAVES:15)
Block(1,21,7,LEAVES:15)
Block(2,21,7,LEAVES:15)
Block(3,21,7,LEAVES:15)
Block(4,21,7,LEAVES:15)
Block(6,21,7,LEAVES:15)
Block(7,21,7,LEAVES:15)
Block(8,21,7,LOG:15)
Block(9,21,7,LOG:15)
Block(10,21,7,LOG:15)
Block(11,21,7,LOG:15)
Block(12,21,7,LEAVES:3)
Block(-10,21,8,LEAVES:3)
Block(-9,21,8,LEAVES:3)
Block(-8,21,8,LEAVES:3)
Block(-7,21,8,LEAVES:3)
Block(-6,21,8,LEAVES:15)
Block(-4,21,8,LEAVES:15)
Block(-3,21,8,LEAVES:15)
Block(-2,21,8,LEAVES:15)
Block(-1,21,8,LEAVES:15)
Block(0,21,8,LEAVES:15)
Block(1,21,8,LEAVES:15)
Block(2,21,8,LEAVES:15)
Block(3,21,8,LEAVES:15)
Block(4,21,8,LEAVES:15)
Block(5,21,8,LEAVES:15)
Block(7,21,8,LEAVES:15)
Block(8,21,8,LEAVES:3)
Block(9,21,8,LOG:15)
Block(10,21,8,LOG:15)
Block(11,21,8,LOG:15)
Block(12,21,8,LEAVES:15)
Block(-10,21,9,LEAVES:3)
Block(-9,21,9,LEAVES:3)
Block(-8,21,9,LEAVES:3)
Block(-7,21,9,LEAVES:15)
Block(-6,21,9,LEAVES:15)
Block(-5,21,9,LEAVES:15)
Block(-4,21,9,LEAVES:15)
Block(-3,21,9,LEAVES:15)
Block(-2,21,9,LEAVES:15)
Block(-1,21,9,LEAVES:15)
Block(0,21,9,LEAVES:15)
Block(1,21,9,LEAVES:15)
Block(2,21,9,LEAVES:15)
Block(3,21,9,LEAVES:15)
Block(4,21,9,LEAVES:15)
Block(5,21,9,LEAVES:15)
Block(7,21,9,LEAVES:15)
Block(8,21,9,LEAVES:3)
Block(9,21,9,LEAVES:3)
Block(10,21,9,LEAVES:3)
Block(11,21,9,LEAVES:3)
Block(-10,21,10,LEAVES:15)
Block(-9,21,10,LEAVES:15)
Block(-8,21,10,LEAVES:15)
Block(-7,21,10,LEAVES:15)
Block(-6,21,10,LEAVES:15)
Block(-5,21,10,LEAVES:15)
Block(-4,21,10,LEAVES:15)
Block(-3,21,10,LEAVES:15)
Block(-2,21,10,LEAVES:15)
Block(-1,21,10,LEAVES:15)
Block(0,21,10,LEAVES:15)
Block(1,21,10,LEAVES:15)
Block(2,21,10,LEAVES:15)
Block(4,21,10,LEAVES:15)
Block(7,21,10,LEAVES:15)
Block(8,21,10,LEAVES:15)
Block(9,21,10,LEAVES:15)
Block(-10,21,11,LEAVES:15)
Block(-9,21,11,LEAVES:15)
Block(-8,21,11,LEAVES:15)
Block(-7,21,11,LEAVES:15)
Block(-5,21,11,LEAVES:15)
Block(-2,21,11,LEAVES:15)
Block(-1,21,11,LEAVES:15)
Block(0,21,11,LEAVES:15)
Block(1,21,11,LEAVES:15)
Block(2,21,11,LEAVES:15)
Block(3,21,11,LEAVES:15)
Block(-10,21,12,LEAVES:15)
Block(-9,21,12,LEAVES:15)
Block(-8,21,12,LEAVES:15)
Block(-2,21,12,LEAVES:15)
Block(-1,21,12,LEAVES:15)
Block(0,21,12,LEAVES:15)
Block(2,21,12,LEAVES:15)
Block(3,22,-17,LEAVES:3)
Block(2,22,-16,LEAVES:3)
Block(3,22,-16,LEAVES:3)
Block(4,22,-16,LEAVES:3)
Block(1,22,-15,LEAVES:3)
Block(2,22,-15,LEAVES:3)
Block(3,22,-15,LEAVES:3)
Block(4,22,-15,LEAVES:3)
Block(-1,22,-14,LEAVES:3)
Block(0,22,-14,LEAVES:3)
Block(1,22,-14,LOG:15)
Block(2,22,-14,LOG:15)
Block(3,22,-14,LEAVES:3)
Block(4,22,-14,LEAVES:3)
Block(-2,22,-13,LEAVES:3)
Block(-1,22,-13,LEAVES:3)
Block(0,22,-13,LOG:15)
Block(1,22,-13,LOG:15)
Block(2,22,-13,LOG:15)
Block(3,22,-13,LEAVES:3)
Block(-4,22,-12,LEAVES:15)
Block(-3,22,-12,LEAVES:15)
Block(-2,22,-12,LEAVES:15)
Block(-1,22,-12,LEAVES:3)
Block(0,22,-12,LOG:15)
Block(1,22,-12,LOG:15)
Block(2,22,-12,LOG:15)
Block(3,22,-12,LEAVES:3)
Block(-5,22,-11,LEAVES:15)
Block(-4,22,-11,LEAVES:15)
Block(-3,22,-11,LEAVES:3)
Block(-2,22,-11,LEAVES:3)
Block(-1,22,-11,LOG:15)
Block(0,22,-11,LOG:15)
Block(1,22,-11,LOG:15)
Block(2,22,-11,LEAVES:3)
Block(3,22,-11,LEAVES:3)
Block(-8,22,-10,LEAVES:15)
Block(-7,22,-10,LEAVES:15)
Block(-6,22,-10,LEAVES:15)
Block(-5,22,-10,LEAVES:15)
Block(-4,22,-10,LEAVES:3)
Block(-3,22,-10,LEAVES:3)
Block(-2,22,-10,LOG:15)
Block(-1,22,-10,LOG:15)
Block(0,22,-10,LOG:15)
Block(-8,22,-9,LEAVES:15)
Block(-7,22,-9,LEAVES:15)
Block(-6,22,-9,LEAVES:15)
Block(-5,22,-9,LEAVES:15)
Block(-4,22,-9,LEAVES:3)
Block(-3,22,-9,LEAVES:3)
Block(-2,22,-9,LEAVES:3)
Block(-1,22,-9,LOG:15)
Block(0,22,-9,LEAVES:3)
Block(1,22,-9,LEAVES:3)
Block(-10,22,-8,LEAVES:15)
Block(-9,22,-8,LEAVES:15)
Block(-8,22,-8,LEAVES:15)
Block(-7,22,-8,LEAVES:15)
Block(-6,22,-8,LEAVES:15)
Block(-5,22,-8,LEAVES:15)
Block(-4,22,-8,LEAVES:3)
Block(-3,22,-8,LEAVES:3)
Block(-2,22,-8,LEAVES:3)
Block(-1,22,-8,LOG:15)
Block(0,22,-8,LEAVES:3)
Block(1,22,-8,LEAVES:3)
Block(-12,22,-7,LEAVES:15)
Block(-11,22,-7,LEAVES:15)
Block(-10,22,-7,LEAVES:15)
Block(-9,22,-7,LEAVES:15)
Block(-8,22,-7,LEAVES:15)
Block(-7,22,-7,LEAVES:15)
Block(-6,22,-7,LEAVES:15)
Block(-5,22,-7,LEAVES:15)
Block(-1,22,-7,LOG:15)
Block(0,22,-7,LEAVES:3)
Block(1,22,-7,LEAVES:3)
Block(-13,22,-6,LEAVES:15)
Block(-12,22,-6,LEAVES:15)
Block(-11,22,-6,LEAVES:15)
Block(-10,22,-6,LEAVES:15)
Block(-9,22,-6,LEAVES:15)
Block(-8,22,-6,LEAVES:15)
Block(-7,22,-6,LEAVES:15)
Block(-6,22,-6,LEAVES:15)
Block(-4,22,-6,LEAVES:3)
Block(-3,22,-6,LEAVES:3)
Block(-2,22,-6,LOG:15)
Block(-1,22,-6,LOG:15)
Block(0,22,-6,LEAVES:3)
Block(12,22,-6,LEAVES:3)
Block(13,22,-6,LOG:15)
Block(14,22,-6,LEAVES:3)
Block(-16,22,-5,LEAVES:15)
Block(-15,22,-5,LEAVES:15)
Block(-14,22,-5,LEAVES:15)
Block(-12,22,-5,LEAVES:15)
Block(-11,22,-5,LEAVES:15)
Block(-4,22,-5,LEAVES:3)
Block(-3,22,-5,LOG:15)
Block(-2,22,-5,LOG:15)
Block(-1,22,-5,LOG:15)
Block(11,22,-5,LEAVES:3)
Block(12,22,-5,LOG:15)
Block(13,22,-5,LOG:15)
Block(14,22,-5,LEAVES:3)
Block(-17,22,-4,LEAVES:15)
Block(-16,22,-4,LEAVES:15)
Block(-15,22,-4,LEAVES:15)
Block(-14,22,-4,LEAVES:15)
Block(-13,22,-4,LEAVES:3)
Block(-12,22,-4,LEAVES:3)
Block(-11,22,-4,LEAVES:3)
Block(-10,22,-4,LEAVES:3)
Block(-4,22,-4,LEAVES:3)
Block(-3,22,-4,LOG:15)
Block(-2,22,-4,LOG:15)
Block(-1,22,-4,LOG:15)
Block(0,22,-4,LEAVES:3)
Block(1,22,-4,LEAVES:3)
Block(2,22,-4,LEAVES:3)
Block(3,22,-4,LOG:15)
Block(7,22,-4,LEAVES:3)
Block(8,22,-4,LEAVES:3)
Block(10,22,-4,LOG:15)
Block(11,22,-4,LOG:15)
Block(12,22,-4,LOG:15)
Block(13,22,-4,LOG:15)
Block(14,22,-4,LEAVES:3)
Block(-16,22,-3,LEAVES:15)
Block(-15,22,-3,LEAVES:15)
Block(-14,22,-3,LEAVES:3)
Block(-13,22,-3,LEAVES:3)
Block(-12,22,-3,LEAVES:3)
Block(-11,22,-3,LOG:15)
Block(-10,22,-3,LOG:15)
Block(-3,22,-3,LOG:15)
Block(-2,22,-3,LOG:15)
Block(-1,22,-3,LOG:15)
Block(0,22,-3,LOG:15)
Block(1,22,-3,LOG:15)
Block(2,22,-3,LOG:15)
Block(3,22,-3,LOG:15)
Block(4,22,-3,LOG:15)
Block(6,22,-3,LEAVES:3)
Block(7,22,-3,LEAVES:3)
Block(8,22,-3,LEAVES:3)
Block(12,22,-3,LEAVES:15)
Block(13,22,-3,LEAVES:15)
Block(14,22,-3,LEAVES:15)
Block(-15,22,-2,LEAVES:15)
Block(-14,22,-2,LEAVES:15)
Block(-13,22,-2,LEAVES:3)
Block(-12,22,-2,LOG:15)
Block(-11,22,-2,LOG:15)
Block(-10,22,-2,LOG:15)
Block(-9,22,-2,LOG:15)
Block(-8,22,-2,LOG:15)
Block(-4,22,-2,LEAVES:15)
Block(-3,22,-2,LEAVES:15)
Block(-2,22,-2,LOG:15)
Block(-1,22,-2,LEAVES:3)
Block(0,22,-2,LEAVES:3)
Block(1,22,-2,LEAVES:3)
Block(2,22,-2,LOG:15)
Block(3,22,-2,LOG:15)
Block(4,22,-2,LOG:15)
Block(5,22,-2,LOG:15)
Block(7,22,-2,LEAVES:3)
Block(11,22,-2,LEAVES:15)
Block(12,22,-2,LEAVES:15)
Block(13,22,-2,LEAVES:15)
Block(14,22,-2,LEAVES:15)
Block(-15,22,-1,LEAVES:15)
Block(-14,22,-1,LEAVES:15)
Block(-13,22,-1,LEAVES:15)
Block(-12,22,-1,LEAVES:3)
Block(-11,22,-1,LOG:15)
Block(-10,22,-1,LOG:15)
Block(-9,22,-1,LOG:15)
Block(-8,22,-1,LOG:15)
Block(-7,22,-1,LOG:15)
Block(-6,22,-1,LOG:15)
Block(-5,22,-1,LEAVES:15)
Block(-4,22,-1,LEAVES:15)
Block(-3,22,-1,LEAVES:3)
Block(-2,22,-1,LOG:15)
Block(1,22,-1,LEAVES:3)
Block(2,22,-1,LOG:15)
Block(3,22,-1,LOG:15)
Block(4,22,-1,LOG:15)
Block(11,22,-1,LEAVES:15)
Block(12,22,-1,LEAVES:15)
Block(13,22,-1,LEAVES:15)
Block(14,22,-1,LEAVES:15)
Block(-14,22,0,LEAVES:15)
Block(-13,22,0,LEAVES:15)
Block(-12,22,0,LEAVES:15)
Block(-11,22,0,LEAVES:3)
Block(-10,22,0,LOG:15)
Block(-9,22,0,LOG:15)
Block(-8,22,0,LOG:15)
Block(-7,22,0,LOG:15)
Block(-6,22,0,LOG:15)
Block(-5,22,0,LOG:15)
Block(-4,22,0,LEAVES:15)
Block(-3,22,0,LEAVES:15)
Block(-2,22,0,LEAVES:15)
Block(2,22,0,LOG:15)
Block(3,22,0,LOG:15)
Block(4,22,0,LOG:15)
Block(10,22,0,LEAVES:15)
Block(11,22,0,LEAVES:15)
Block(12,22,0,LEAVES:15)
Block(13,22,0,LEAVES:15)
Block(14,22,0,LEAVES:15)
Block(-14,22,1,LEAVES:15)
Block(-13,22,1,LEAVES:15)
Block(-12,22,1,LEAVES:15)
Block(-11,22,1,LEAVES:15)
Block(-10,22,1,LEAVES:3)
Block(-9,22,1,LEAVES:3)
Block(-8,22,1,LOG:15)
Block(-7,22,1,LOG:15)
Block(-6,22,1,LOG:15)
Block(-5,22,1,LOG:15)
Block(-4,22,1,LEAVES:15)
Block(-3,22,1,LEAVES:15)
Block(2,22,1,LOG:15)
Block(3,22,1,LOG:15)
Block(4,22,1,LEAVES:3)
Block(5,22,1,LEAVES:3)
Block(9,22,1,LEAVES:15)
Block(10,22,1,LEAVES:15)
Block(11,22,1,LEAVES:15)
Block(12,22,1,LEAVES:15)
Block(13,22,1,LEAVES:15)
Block(-13,22,2,LEAVES:15)
Block(-12,22,2,LEAVES:15)
Block(-11,22,2,LEAVES:15)
Block(-10,22,2,LEAVES:15)
Block(-9,22,2,LEAVES:15)
Block(-8,22,2,LEAVES:15)
Block(-7,22,2,LEAVES:15)
Block(-6,22,2,LEAVES:3)
Block(-5,22,2,LEAVES:3)
Block(-4,22,2,LEAVES:3)
Block(2,22,2,LEAVES:15)
Block(3,22,2,LEAVES:15)
Block(4,22,2,LEAVES:3)
Block(5,22,2,LEAVES:3)
Block(7,22,2,LEAVES:3)
Block(9,22,2,LEAVES:15)
Block(10,22,2,LEAVES:15)
Block(11,22,2,LEAVES:15)
Block(12,22,2,LEAVES:15)
Block(-13,22,3,LEAVES:15)
Block(-12,22,3,LEAVES:15)
Block(-11,22,3,LEAVES:15)
Block(-10,22,3,LEAVES:15)
Block(-9,22,3,LEAVES:15)
Block(-8,22,3,LEAVES:15)
Block(-7,22,3,LEAVES:15)
Block(-6,22,3,LEAVES:15)
Block(-5,22,3,LEAVES:3)
Block(-4,22,3,LEAVES:15)
Block(-3,22,3,LEAVES:15)
Block(-2,22,3,LEAVES:15)
Block(1,22,3,LEAVES:15)
Block(2,22,3,LEAVES:15)
Block(3,22,3,LEAVES:15)
Block(4,22,3,LEAVES:3)
Block(5,22,3,LEAVES:3)
Block(6,22,3,LEAVES:3)
Block(7,22,3,LEAVES:3)
Block(8,22,3,LEAVES:3)
Block(9,22,3,LEAVES:15)
Block(10,22,3,LEAVES:15)
Block(11,22,3,LEAVES:15)
Block(-13,22,4,LEAVES:15)
Block(-12,22,4,LEAVES:15)
Block(-11,22,4,LEAVES:15)
Block(-10,22,4,LEAVES:15)
Block(-8,22,4,LEAVES:15)
Block(-7,22,4,LEAVES:15)
Block(-6,22,4,LEAVES:15)
Block(-5,22,4,LEAVES:15)
Block(-4,22,4,LEAVES:15)
Block(-3,22,4,LEAVES:15)
Block(-2,22,4,LEAVES:15)
Block(-1,22,4,LEAVES:15)
Block(0,22,4,LEAVES:15)
Block(1,22,4,LEAVES:15)
Block(2,22,4,LEAVES:15)
Block(3,22,4,LEAVES:15)
Block(4,22,4,LEAVES:15)
Block(5,22,4,LEAVES:3)
Block(6,22,4,LEAVES:3)
Block(7,22,4,LEAVES:3)
Block(8,22,4,LEAVES:15)
Block(9,22,4,LEAVES:15)
Block(10,22,4,LEAVES:15)
Block(-14,22,5,LEAVES:15)
Block(-13,22,5,LEAVES:15)
Block(-12,22,5,LEAVES:15)
Block(-11,22,5,LEAVES:15)
Block(-8,22,5,LEAVES:15)
Block(-7,22,5,LEAVES:15)
Block(-6,22,5,LEAVES:15)
Block(-5,22,5,LEAVES:15)
Block(-4,22,5,LEAVES:15)
Block(-3,22,5,LEAVES:15)
Block(-2,22,5,LEAVES:3)
Block(-1,22,5,LEAVES:15)
Block(0,22,5,LEAVES:15)
Block(1,22,5,LEAVES:15)
Block(2,22,5,LEAVES:15)
Block(3,22,5,LEAVES:15)
Block(4,22,5,LEAVES:15)
Block(5,22,5,LEAVES:15)
Block(6,22,5,LEAVES:3)
Block(7,22,5,LOG:15)
Block(8,22,5,LOG:15)
Block(9,22,5,LEAVES:3)
Block(10,22,5,LEAVES:15)
Block(11,22,5,LEAVES:15)
Block(-13,22,6,LEAVES:15)
Block(-12,22,6,LEAVES:15)
Block(-11,22,6,LEAVES:15)
Block(-7,22,6,LEAVES:15)
Block(-6,22,6,LEAVES:15)
Block(-5,22,6,LEAVES:3)
Block(-4,22,6,LEAVES:15)
Block(-3,22,6,LEAVES:15)
Block(-1,22,6,LEAVES:15)
Block(0,22,6,LEAVES:15)
Block(1,22,6,LEAVES:15)
Block(2,22,6,LEAVES:15)
Block(3,22,6,LEAVES:15)
Block(4,22,6,LEAVES:15)
Block(6,22,6,LEAVES:15)
Block(7,22,6,LEAVES:3)
Block(8,22,6,LOG:15)
Block(9,22,6,LOG:15)
Block(10,22,6,LEAVES:15)
Block(-12,22,7,LEAVES:15)
Block(-11,22,7,LEAVES:15)
Block(-10,22,7,LEAVES:15)
Block(-9,22,7,LEAVES:3)
Block(-8,22,7,LEAVES:3)
Block(-7,22,7,LEAVES:3)
Block(-6,22,7,LEAVES:15)
Block(-5,22,7,LEAVES:15)
Block(-4,22,7,LEAVES:15)
Block(-3,22,7,LEAVES:15)
Block(-2,22,7,LEAVES:15)
Block(-1,22,7,LEAVES:15)
Block(0,22,7,LEAVES:15)
Block(1,22,7,LEAVES:15)
Block(2,22,7,LEAVES:15)
Block(3,22,7,LEAVES:15)
Block(4,22,7,LEAVES:15)
Block(5,22,7,LEAVES:15)
Block(6,22,7,LEAVES:15)
Block(7,22,7,LEAVES:3)
Block(8,22,7,LEAVES:3)
Block(9,22,7,LOG:15)
Block(10,22,7,LOG:15)
Block(11,22,7,LEAVES:15)
Block(12,22,7,LEAVES:15)
Block(-13,22,8,LEAVES:15)
Block(-12,22,8,LEAVES:15)
Block(-11,22,8,LEAVES:15)
Block(-10,22,8,LEAVES:3)
Block(-9,22,8,LEAVES:3)
Block(-8,22,8,LOG:15)
Block(-7,22,8,LEAVES:3)
Block(-6,22,8,LEAVES:15)
Block(-5,22,8,LEAVES:15)
Block(-4,22,8,LEAVES:15)
Block(-3,22,8,LEAVES:15)
Block(-2,22,8,LEAVES:15)
Block(-1,22,8,LEAVES:15)
Block(0,22,8,LEAVES:15)
Block(1,22,8,LEAVES:15)
Block(2,22,8,LEAVES:15)
Block(3,22,8,LEAVES:15)
Block(4,22,8,LEAVES:15)
Block(5,22,8,LEAVES:15)
Block(6,22,8,LEAVES:15)
Block(7,22,8,LEAVES:15)
Block(8,22,8,LEAVES:3)
Block(9,22,8,LEAVES:3)
Block(10,22,8,LEAVES:3)
Block(11,22,8,LEAVES:3)
Block(12,22,8,LEAVES:15)
Block(-12,22,9,LEAVES:15)
Block(-9,22,9,LOG:15)
Block(-8,22,9,LOG:15)
Block(-7,22,9,LEAVES:3)
Block(-6,22,9,LEAVES:15)
Block(-5,22,9,LEAVES:15)
Block(-4,22,9,LEAVES:15)
Block(-3,22,9,LEAVES:15)
Block(-2,22,9,LEAVES:15)
Block(-1,22,9,LEAVES:15)
Block(0,22,9,LEAVES:15)
Block(1,22,9,LEAVES:15)
Block(2,22,9,LEAVES:15)
Block(3,22,9,LEAVES:15)
Block(4,22,9,LEAVES:15)
Block(5,22,9,LEAVES:15)
Block(7,22,9,LEAVES:15)
Block(8,22,9,LEAVES:15)
Block(9,22,9,LEAVES:3)
Block(10,22,9,LEAVES:3)
Block(11,22,9,LEAVES:15)
Block(12,22,9,LEAVES:15)
Block(-10,22,10,LEAVES:15)
Block(-9,22,10,LEAVES:15)
Block(-8,22,10,LEAVES:15)
Block(-7,22,10,LEAVES:15)
Block(-6,22,10,LEAVES:15)
Block(-5,22,10,LEAVES:15)
Block(-4,22,10,LEAVES:15)
Block(-3,22,10,LEAVES:15)
Block(-2,22,10,LEAVES:15)
Block(-1,22,10,LEAVES:15)
Block(0,22,10,LEAVES:15)
Block(1,22,10,LEAVES:15)
Block(2,22,10,LEAVES:15)
Block(3,22,10,LEAVES:15)
Block(4,22,10,LEAVES:15)
Block(5,22,10,LEAVES:15)
Block(8,22,10,LEAVES:15)
Block(-10,22,11,LEAVES:15)
Block(-9,22,11,LEAVES:15)
Block(-8,22,11,LEAVES:15)
Block(-7,22,11,LEAVES:15)
Block(-6,22,11,LEAVES:15)
Block(-5,22,11,LEAVES:15)
Block(-4,22,11,LEAVES:15)
Block(-3,22,11,LEAVES:15)
Block(-2,22,11,LEAVES:15)
Block(-1,22,11,LEAVES:15)
Block(0,22,11,LEAVES:15)
Block(1,22,11,LEAVES:15)
Block(2,22,11,LEAVES:15)
Block(3,22,11,LEAVES:15)
Block(-9,22,12,LEAVES:15)
Block(-8,22,12,LEAVES:15)
Block(-7,22,12,LEAVES:15)
Block(-5,22,12,LEAVES:15)
Block(-3,22,12,LEAVES:15)
Block(-2,22,12,LEAVES:15)
Block(-1,22,12,LEAVES:15)
Block(1,22,12,LEAVES:15)
Block(2,22,12,LEAVES:15)
Block(3,22,12,LEAVES:15)
Block(-2,22,13,LEAVES:15)
Block(3,23,-16,LEAVES:3)
Block(2,23,-15,LEAVES:3)
Block(3,23,-15,LEAVES:3)
Block(4,23,-15,LEAVES:3)
Block(-1,23,-14,LEAVES:3)
Block(1,23,-14,LEAVES:3)
Block(2,23,-14,LEAVES:3)
Block(3,23,-14,LEAVES:3)
Block(-2,23,-13,LEAVES:3)
Block(-1,23,-13,LEAVES:3)
Block(0,23,-13,LOG:15)
Block(1,23,-13,LOG:15)
Block(2,23,-13,LEAVES:3)
Block(3,23,-13,LEAVES:3)
Block(-3,23,-12,LEAVES:3)
Block(-2,23,-12,LEAVES:3)
Block(-1,23,-12,LOG:15)
Block(0,23,-12,LOG:15)
Block(1,23,-12,LOG:15)
Block(2,23,-12,LOG:15)
Block(3,23,-12,LEAVES:3)
Block(4,23,-12,LEAVES:15)
Block(-4,23,-11,LEAVES:3)
Block(-3,23,-11,LEAVES:3)
Block(-2,23,-11,LEAVES:3)
Block(-1,23,-11,LOG:15)
Block(0,23,-11,LOG:15)
Block(1,23,-11,LOG:15)
Block(2,23,-11,LEAVES:3)
Block(3,23,-11,LEAVES:3)
Block(4,23,-11,LEAVES:15)
Block(5,23,-11,LEAVES:15)
Block(-7,23,-10,LEAVES:15)
Block(-5,23,-10,LEAVES:15)
Block(-4,23,-10,LEAVES:3)
Block(-3,23,-10,LEAVES:3)
Block(-2,23,-10,LOG:15)
Block(-1,23,-10,LOG:15)
Block(0,23,-10,LOG:15)
Block(1,23,-10,LOG:15)
Block(2,23,-10,LEAVES:3)
Block(3,23,-10,LEAVES:15)
Block(4,23,-10,LEAVES:15)
Block(-8,23,-9,LEAVES:15)
Block(-7,23,-9,LEAVES:15)
Block(-6,23,-9,LEAVES:15)
Block(-5,23,-9,LEAVES:15)
Block(-4,23,-9,LEAVES:3)
Block(-3,23,-9,LEAVES:3)
Block(-2,23,-9,LOG:15)
Block(-1,23,-9,LOG:15)
Block(0,23,-9,LOG:15)
Block(1,23,-9,LEAVES:3)
Block(2,23,-9,LEAVES:15)
Block(3,23,-9,LEAVES:15)
Block(11,23,-9,LEAVES:15)
Block(-7,23,-8,LEAVES:15)
Block(-6,23,-8,LEAVES:15)
Block(-5,23,-8,LEAVES:15)
Block(-4,23,-8,LEAVES:15)
Block(-3,23,-8,LEAVES:3)
Block(-2,23,-8,LOG:15)
Block(-1,23,-8,LOG:15)
Block(0,23,-8,LOG:15)
Block(1,23,-8,LEAVES:3)
Block(2,23,-8,LEAVES:15)
Block(10,23,-8,LEAVES:15)
Block(11,23,-8,LEAVES:15)
Block(12,23,-8,LEAVES:15)
Block(-8,23,-7,LEAVES:15)
Block(-7,23,-7,LEAVES:15)
Block(-6,23,-7,LEAVES:15)
Block(-5,23,-7,LEAVES:15)
Block(-4,23,-7,LEAVES:15)
Block(-3,23,-7,LEAVES:15)
Block(-2,23,-7,LOG:15)
Block(-1,23,-7,LOG:15)
Block(0,23,-7,LOG:15)
Block(1,23,-7,LEAVES:3)
Block(2,23,-7,LEAVES:15)
Block(5,23,-7,LEAVES:15)
Block(10,23,-7,LEAVES:15)
Block(11,23,-7,LEAVES:15)
Block(12,23,-7,LEAVES:15)
Block(-11,23,-6,LEAVES:15)
Block(-10,23,-6,LEAVES:15)
Block(-9,23,-6,LEAVES:15)
Block(-8,23,-6,LEAVES:15)
Block(-7,23,-6,LEAVES:15)
Block(-6,23,-6,LEAVES:15)
Block(-5,23,-6,LEAVES:15)
Block(-4,23,-6,LEAVES:15)
Block(-3,23,-6,LOG:15)
Block(-2,23,-6,LOG:15)
Block(-1,23,-6,LOG:15)
Block(0,23,-6,LOG:15)
Block(1,23,-6,LEAVES:3)
Block(4,23,-6,LEAVES:15)
Block(5,23,-6,LEAVES:15)
Block(6,23,-6,LEAVES:15)
Block(11,23,-6,LEAVES:3)
Block(12,23,-6,LOG:15)
Block(13,23,-6,LEAVES:3)
Block(-15,23,-5,LEAVES:15)
Block(-12,23,-5,LEAVES:15)
Block(-11,23,-5,LEAVES:15)
Block(-10,23,-5,LEAVES:15)
Block(-9,23,-5,LEAVES:15)
Block(-8,23,-5,LEAVES:15)
Block(-7,23,-5,LEAVES:15)
Block(-6,23,-5,LEAVES:15)
Block(-4,23,-5,LEAVES:3)
Block(-3,23,-5,LOG:15)
Block(-2,23,-5,LOG:15)
Block(-1,23,-5,LOG:15)
Block(0,23,-5,LOG:15)
Block(1,23,-5,LEAVES:15)
Block(3,23,-5,LEAVES:15)
Block(4,23,-5,LEAVES:15)
Block(5,23,-5,LEAVES:3)
Block(6,23,-5,LEAVES:15)
Block(7,23,-5,LEAVES:15)
Block(10,23,-5,LOG:15)
Block(11,23,-5,LOG:15)
Block(12,23,-5,LOG:15)
Block(13,23,-5,LEAVES:3)
Block(14,23,-5,LEAVES:3)
Block(-16,23,-4,LEAVES:15)
Block(-15,23,-4,LEAVES:15)
Block(-14,23,-4,LEAVES:15)
Block(-11,23,-4,LEAVES:3)
Block(-10,23,-4,LEAVES:15)
Block(-9,23,-4,LEAVES:15)
Block(-8,23,-4,LEAVES:15)
Block(-3,23,-4,LEAVES:3)
Block(-2,23,-4,LOG:15)
Block(-1,23,-4,LOG:15)
Block(0,23,-4,LEAVES:3)
Block(4,23,-4,LOG:15)
Block(5,23,-4,LEAVES:3)
Block(6,23,-4,LEAVES:3)
Block(7,23,-4,LEAVES:3)
Block(8,23,-4,LEAVES:3)
Block(9,23,-4,LOG:15)
Block(10,23,-4,LOG:15)
Block(11,23,-4,LOG:15)
Block(12,23,-4,LOG:15)
Block(13,23,-4,LOG:15)
Block(14,23,-4,LEAVES:15)
Block(-15,23,-3,LEAVES:15)
Block(-14,23,-3,LEAVES:15)
Block(-13,23,-3,LEAVES:15)
Block(-12,23,-3,LEAVES:3)
Block(-11,23,-3,LEAVES:3)
Block(-10,23,-3,LOG:15)
Block(-3,23,-3,LEAVES:15)
Block(-2,23,-3,LOG:15)
Block(-1,23,-3,LEAVES:3)
Block(0,23,-3,LEAVES:3)
Block(1,23,-3,LEAVES:3)
Block(2,23,-3,LEAVES:3)
Block(3,23,-3,LOG:15)
Block(4,23,-3,LOG:15)
Block(5,23,-3,LOG:15)
Block(6,23,-3,LOG:15)
Block(7,23,-3,LOG:15)
Block(8,23,-3,LEAVES:3)
Block(10,23,-3,LOG:15)
Block(11,23,-3,LOG:15)
Block(12,23,-3,LOG:15)
Block(13,23,-3,LEAVES:15)
Block(14,23,-3,LEAVES:15)
Block(-14,23,-2,LEAVES:15)
Block(-13,23,-2,LEAVES:15)
Block(-12,23,-2,LEAVES:15)
Block(-11,23,-2,LOG:15)
Block(-10,23,-2,LOG:15)
Block(-9,23,-2,LOG:15)
Block(-8,23,-2,LEAVES:15)
Block(-6,23,-2,LEAVES:15)
Block(-4,23,-2,LEAVES:15)
Block(-3,23,-2,LEAVES:15)
Block(-2,23,-2,LEAVES:15)
Block(0,23,-2,LEAVES:3)
Block(1,23,-2,LEAVES:3)
Block(2,23,-2,LEAVES:3)
Block(3,23,-2,LOG:15)
Block(4,23,-2,LOG:15)
Block(5,23,-2,LOG:15)
Block(6,23,-2,LEAVES:3)
Block(7,23,-2,LEAVES:3)
Block(8,23,-2,LEAVES:3)
Block(10,23,-2,LEAVES:15)
Block(11,23,-2,LEAVES:15)
Block(12,23,-2,LEAVES:15)
Block(13,23,-2,LEAVES:15)
Block(14,23,-2,LEAVES:15)
Block(-13,23,-1,LEAVES:15)
Block(-12,23,-1,LEAVES:15)
Block(-11,23,-1,LEAVES:15)
Block(-10,23,-1,LOG:15)
Block(-9,23,-1,LOG:15)
Block(-8,23,-1,LOG:15)
Block(-7,23,-1,LEAVES:3)
Block(-6,23,-1,LEAVES:3)
Block(-5,23,-1,LEAVES:15)
Block(-4,23,-1,LEAVES:15)
Block(-3,23,-1,LEAVES:15)
Block(-2,23,-1,LEAVES:15)
Block(1,23,-1,LEAVES:15)
Block(2,23,-1,LEAVES:3)
Block(3,23,-1,LOG:15)
Block(4,23,-1,LOG:15)
Block(6,23,-1,LEAVES:15)
Block(7,23,-1,LEAVES:15)
Block(8,23,-1,LEAVES:15)
Block(9,23,-1,LEAVES:15)
Block(10,23,-1,LEAVES:15)
Block(11,23,-1,LEAVES:15)
Block(12,23,-1,LEAVES:15)
Block(13,23,-1,LEAVES:15)
Block(14,23,-1,LEAVES:15)
Block(-14,23,0,LEAVES:15)
Block(-13,23,0,LEAVES:15)
Block(-12,23,0,LEAVES:15)
Block(-11,23,0,LEAVES:15)
Block(-10,23,0,LEAVES:3)
Block(-9,23,0,LOG:15)
Block(-8,23,0,LOG:15)
Block(-7,23,0,LOG:15)
Block(-6,23,0,LOG:15)
Block(-5,23,0,LEAVES:15)
Block(-4,23,0,LEAVES:15)
Block(-3,23,0,LEAVES:15)
Block(1,23,0,LEAVES:15)
Block(2,23,0,LOG:15)
Block(3,23,0,LOG:15)
Block(4,23,0,LOG:15)
Block(5,23,0,LEAVES:3)
Block(6,23,0,LEAVES:15)
Block(7,23,0,LEAVES:15)
Block(8,23,0,LEAVES:15)
Block(9,23,0,LEAVES:15)
Block(10,23,0,LEAVES:15)
Block(11,23,0,LEAVES:15)
Block(12,23,0,LEAVES:15)
Block(13,23,0,LEAVES:15)
Block(-14,23,1,LEAVES:15)
Block(-13,23,1,LEAVES:15)
Block(-12,23,1,LEAVES:15)
Block(-11,23,1,LEAVES:15)
Block(-10,23,1,LEAVES:15)
Block(-9,23,1,LEAVES:3)
Block(-8,23,1,LEAVES:3)
Block(-7,23,1,LEAVES:3)
Block(-6,23,1,LEAVES:3)
Block(-5,23,1,LEAVES:15)
Block(-4,23,1,LEAVES:15)
Block(-3,23,1,LEAVES:15)
Block(0,23,1,LEAVES:15)
Block(1,23,1,LOG:15)
Block(2,23,1,LOG:15)
Block(3,23,1,LOG:15)
Block(4,23,1,LOG:15)
Block(5,23,1,LEAVES:3)
Block(6,23,1,LEAVES:15)
Block(8,23,1,LEAVES:15)
Block(9,23,1,LEAVES:15)
Block(10,23,1,LEAVES:15)
Block(11,23,1,LEAVES:15)
Block(12,23,1,LEAVES:15)
Block(-14,23,2,LEAVES:15)
Block(-13,23,2,LEAVES:15)
Block(-12,23,2,LEAVES:15)
Block(-11,23,2,LEAVES:15)
Block(-10,23,2,LEAVES:15)
Block(-9,23,2,LEAVES:15)
Block(-8,23,2,LEAVES:15)
Block(-7,23,2,LEAVES:15)
Block(-6,23,2,LEAVES:15)
Block(-5,23,2,LEAVES:15)
Block(-4,23,2,LEAVES:15)
Block(-3,23,2,LEAVES:15)
Block(-2,23,2,LEAVES:15)
Block(1,23,2,LOG:15)
Block(2,23,2,LOG:15)
Block(3,23,2,LOG:15)
Block(4,23,2,LEAVES:3)
Block(5,23,2,LEAVES:3)
Block(8,23,2,LEAVES:15)
Block(9,23,2,LEAVES:15)
Block(10,23,2,LEAVES:15)
Block(11,23,2,LEAVES:15)
Block(-13,23,3,LEAVES:15)
Block(-12,23,3,LEAVES:15)
Block(-11,23,3,LEAVES:15)
Block(-10,23,3,LEAVES:15)
Block(-9,23,3,LEAVES:15)
Block(-8,23,3,LEAVES:15)
Block(-7,23,3,LEAVES:15)
Block(-6,23,3,LEAVES:15)
Block(-5,23,3,LEAVES:15)
Block(-4,23,3,LEAVES:15)
Block(-3,23,3,LEAVES:15)
Block(-2,23,3,LEAVES:15)
Block(1,23,3,LEAVES:3)
Block(2,23,3,LEAVES:3)
Block(3,23,3,LEAVES:3)
Block(4,23,3,LEAVES:15)
Block(5,23,3,LEAVES:15)
Block(6,23,3,LEAVES:15)
Block(8,23,3,LEAVES:15)
Block(9,23,3,LEAVES:15)
Block(10,23,3,LEAVES:15)
Block(11,23,3,LEAVES:15)
Block(-14,23,4,LEAVES:15)
Block(-13,23,4,LEAVES:15)
Block(-12,23,4,LEAVES:15)
Block(-11,23,4,LEAVES:15)
Block(-10,23,4,LEAVES:15)
Block(-9,23,4,LEAVES:15)
Block(-8,23,4,LEAVES:15)
Block(-7,23,4,LEAVES:15)
Block(-6,23,4,LEAVES:15)
Block(-5,23,4,LEAVES:15)
Block(-4,23,4,LEAVES:15)
Block(-3,23,4,LEAVES:15)
Block(-2,23,4,LEAVES:15)
Block(0,23,4,LEAVES:15)
Block(1,23,4,LEAVES:15)
Block(2,23,4,LEAVES:3)
Block(3,23,4,LEAVES:15)
Block(4,23,4,LEAVES:15)
Block(5,23,4,LEAVES:15)
Block(6,23,4,LEAVES:15)
Block(7,23,4,LEAVES:15)
Block(8,23,4,LEAVES:15)
Block(9,23,4,LEAVES:15)
Block(10,23,4,LEAVES:15)
Block(11,23,4,LEAVES:15)
Block(-14,23,5,LEAVES:15)
Block(-13,23,5,LEAVES:15)
Block(-12,23,5,LEAVES:15)
Block(-11,23,5,LEAVES:15)
Block(-10,23,5,LEAVES:15)
Block(-9,23,5,LEAVES:15)
Block(-7,23,5,LEAVES:15)
Block(-6,23,5,LEAVES:15)
Block(-5,23,5,LEAVES:15)
Block(-4,23,5,LEAVES:15)
Block(-3,23,5,LEAVES:15)
Block(-2,23,5,LEAVES:3)
Block(-1,23,5,LEAVES:15)
Block(0,23,5,LEAVES:15)
Block(1,23,5,LEAVES:15)
Block(2,23,5,LEAVES:15)
Block(3,23,5,LEAVES:15)
Block(4,23,5,LEAVES:15)
Block(5,23,5,LEAVES:15)
Block(6,23,5,LEAVES:15)
Block(7,23,5,LEAVES:15)
Block(8,23,5,LEAVES:3)
Block(9,23,5,LEAVES:15)
Block(10,23,5,LEAVES:15)
Block(11,23,5,LEAVES:15)
Block(-14,23,6,LEAVES:15)
Block(-13,23,6,LEAVES:15)
Block(-12,23,6,LEAVES:15)
Block(-11,23,6,LEAVES:15)
Block(-10,23,6,LEAVES:15)
Block(-9,23,6,LEAVES:15)
Block(-8,23,6,LEAVES:3)
Block(-7,23,6,LEAVES:15)
Block(-6,23,6,LEAVES:15)
Block(-5,23,6,LEAVES:3)
Block(-4,23,6,LEAVES:15)
Block(-3,23,6,LEAVES:15)
Block(-1,23,6,LEAVES:15)
Block(0,23,6,LEAVES:15)
Block(1,23,6,LEAVES:15)
Block(2,23,6,LEAVES:15)
Block(3,23,6,LEAVES:15)
Block(4,23,6,LEAVES:15)
Block(5,23,6,LEAVES:15)
Block(6,23,6,LEAVES:15)
Block(7,23,6,LEAVES:3)
Block(8,23,6,LEAVES:3)
Block(9,23,6,LEAVES:3)
Block(10,23,6,LEAVES:15)
Block(11,23,6,LEAVES:15)
Block(-13,23,7,LEAVES:15)
Block(-12,23,7,LEAVES:15)
Block(-11,23,7,LEAVES:15)
Block(-10,23,7,LEAVES:15)
Block(-9,23,7,LEAVES:3)
Block(-8,23,7,LOG:15)
Block(-7,23,7,LEAVES:3)
Block(-6,23,7,LEAVES:15)
Block(-5,23,7,LEAVES:15)
Block(-4,23,7,LEAVES:15)
Block(-3,23,7,LEAVES:15)
Block(-2,23,7,LEAVES:15)
Block(-1,23,7,LEAVES:15)
Block(0,23,7,LEAVES:15)
Block(1,23,7,LEAVES:15)
Block(2,23,7,LEAVES:15)
Block(3,23,7,LEAVES:15)
Block(4,23,7,LEAVES:15)
Block(5,23,7,LEAVES:15)
Block(6,23,7,LEAVES:15)
Block(7,23,7,LEAVES:15)
Block(8,23,7,LEAVES:3)
Block(9,23,7,LEAVES:15)
Block(10,23,7,LEAVES:15)
Block(11,23,7,LEAVES:15)
Block(-13,23,8,LEAVES:15)
Block(-12,23,8,LEAVES:15)
Block(-11,23,8,LEAVES:15)
Block(-10,23,8,LEAVES:3)
Block(-9,23,8,LOG:15)
Block(-8,23,8,LOG:15)
Block(-7,23,8,LOG:15)
Block(-6,23,8,LEAVES:15)
Block(-5,23,8,LEAVES:15)
Block(-4,23,8,LEAVES:15)
Block(-3,23,8,LEAVES:15)
Block(-2,23,8,LEAVES:15)
Block(-1,23,8,LEAVES:15)
Block(0,23,8,LEAVES:15)
Block(1,23,8,LEAVES:15)
Block(2,23,8,LEAVES:15)
Block(3,23,8,LEAVES:15)
Block(4,23,8,LEAVES:15)
Block(5,23,8,LEAVES:15)
Block(6,23,8,LEAVES:15)
Block(7,23,8,LEAVES:15)
Block(8,23,8,LEAVES:15)
Block(9,23,8,LEAVES:15)
Block(10,23,8,LEAVES:15)
Block(11,23,8,LEAVES:15)
Block(12,23,8,LEAVES:15)
Block(-13,23,9,LEAVES:15)
Block(-12,23,9,LEAVES:15)
Block(-11,23,9,LEAVES:15)
Block(-10,23,9,LOG:15)
Block(-9,23,9,LOG:15)
Block(-8,23,9,LOG:15)
Block(-7,23,9,LOG:15)
Block(-6,23,9,LEAVES:3)
Block(-5,23,9,LEAVES:15)
Block(-4,23,9,LEAVES:15)
Block(-3,23,9,LEAVES:15)
Block(-2,23,9,LEAVES:15)
Block(-1,23,9,LEAVES:15)
Block(0,23,9,LEAVES:15)
Block(1,23,9,LEAVES:15)
Block(2,23,9,LEAVES:15)
Block(3,23,9,LEAVES:15)
Block(4,23,9,LEAVES:15)
Block(5,23,9,LEAVES:15)
Block(6,23,9,LEAVES:15)
Block(7,23,9,LEAVES:15)
Block(8,23,9,LEAVES:15)
Block(11,23,9,LEAVES:15)
Block(-10,23,10,LEAVES:15)
Block(-9,23,10,LOG:15)
Block(-8,23,10,LOG:15)
Block(-7,23,10,LEAVES:3)
Block(-6,23,10,LEAVES:15)
Block(-5,23,10,LEAVES:15)
Block(-4,23,10,LEAVES:15)
Block(-3,23,10,LEAVES:15)
Block(-2,23,10,LEAVES:15)
Block(-1,23,10,LEAVES:15)
Block(0,23,10,LEAVES:15)
Block(1,23,10,LEAVES:15)
Block(2,23,10,LEAVES:15)
Block(4,23,10,LEAVES:15)
Block(-10,23,11,LEAVES:15)
Block(-9,23,11,LEAVES:15)
Block(-8,23,11,LEAVES:15)
Block(-7,23,11,LEAVES:15)
Block(-6,23,11,LEAVES:15)
Block(-5,23,11,LEAVES:15)
Block(-4,23,11,LEAVES:15)
Block(-3,23,11,LEAVES:15)
Block(-2,23,11,LEAVES:15)
Block(-1,23,11,LEAVES:15)
Block(1,23,11,LEAVES:15)
Block(2,23,11,LEAVES:15)
Block(3,23,11,LEAVES:15)
Block(-8,23,12,LEAVES:15)
Block(-7,23,12,LEAVES:15)
Block(-6,23,12,LEAVES:15)
Block(-5,23,12,LEAVES:15)
Block(-4,23,12,LEAVES:15)
Block(-3,23,12,LEAVES:15)
Block(-2,23,12,LEAVES:15)
Block(-1,23,12,LEAVES:15)
Block(2,23,12,LEAVES:15)
Block(-5,23,13,LEAVES:15)
Block(-4,23,13,LEAVES:15)
Block(-3,23,13,LEAVES:15)
Block(-2,23,13,LEAVES:15)
Block(-1,23,13,LEAVES:15)
Block(-1,24,-13,LEAVES:3)
Block(0,24,-13,LEAVES:3)
Block(1,24,-13,LEAVES:3)
Block(2,24,-13,LEAVES:3)
Block(-1,24,-12,LEAVES:15)
Block(0,24,-12,LOG:15)
Block(1,24,-12,LOG:15)
Block(2,24,-12,LEAVES:3)
Block(3,24,-12,LEAVES:3)
Block(4,24,-12,LEAVES:15)
Block(5,24,-12,LEAVES:15)
Block(-3,24,-11,LEAVES:3)
Block(-2,24,-11,LEAVES:3)
Block(-1,24,-11,LOG:15)
Block(0,24,-11,LOG:15)
Block(1,24,-11,LEAVES:3)
Block(2,24,-11,LEAVES:3)
Block(3,24,-11,LEAVES:15)
Block(4,24,-11,LEAVES:15)
Block(5,24,-11,LEAVES:15)
Block(-3,24,-10,LEAVES:3)
Block(-2,24,-10,LOG:15)
Block(-1,24,-10,LOG:15)
Block(0,24,-10,LOG:15)
Block(1,24,-10,LOG:15)
Block(2,24,-10,LEAVES:3)
Block(3,24,-10,LEAVES:15)
Block(4,24,-10,LEAVES:15)
Block(5,24,-10,LEAVES:15)
Block(-4,24,-9,LEAVES:15)
Block(-3,24,-9,LEAVES:3)
Block(-2,24,-9,LOG:15)
Block(-1,24,-9,LOG:15)
Block(0,24,-9,LOG:15)
Block(1,24,-9,LEAVES:3)
Block(2,24,-9,LEAVES:3)
Block(3,24,-9,LEAVES:15)
Block(4,24,-9,LEAVES:15)
Block(5,24,-9,LEAVES:15)
Block(6,24,-9,LEAVES:15)
Block(10,24,-9,LEAVES:15)
Block(11,24,-9,LEAVES:15)
Block(12,24,-9,LEAVES:15)
Block(-6,24,-8,LEAVES:15)
Block(-5,24,-8,LEAVES:15)
Block(-4,24,-8,LEAVES:15)
Block(-3,24,-8,LEAVES:3)
Block(-2,24,-8,LOG:15)
Block(-1,24,-8,LOG:15)
Block(0,24,-8,LOG:15)
Block(1,24,-8,LEAVES:15)
Block(2,24,-8,LEAVES:15)
Block(3,24,-8,LEAVES:15)
Block(5,24,-8,LEAVES:15)
Block(6,24,-8,LEAVES:15)
Block(7,24,-8,LEAVES:15)
Block(10,24,-8,LEAVES:15)
Block(11,24,-8,LEAVES:15)
Block(12,24,-8,LEAVES:15)
Block(-8,24,-7,LEAVES:15)
Block(-7,24,-7,LEAVES:15)
Block(-6,24,-7,LEAVES:15)
Block(-5,24,-7,LEAVES:15)
Block(-4,24,-7,LEAVES:15)
Block(-3,24,-7,LEAVES:3)
Block(-2,24,-7,LOG:15)
Block(-1,24,-7,LOG:15)
Block(0,24,-7,LOG:15)
Block(1,24,-7,LEAVES:3)
Block(2,24,-7,LEAVES:15)
Block(4,24,-7,LEAVES:15)
Block(5,24,-7,LEAVES:15)
Block(6,24,-7,LEAVES:15)
Block(7,24,-7,LEAVES:15)
Block(8,24,-7,LEAVES:15)
Block(9,24,-7,LEAVES:15)
Block(10,24,-7,LEAVES:15)
Block(11,24,-7,LEAVES:15)
Block(12,24,-7,LEAVES:15)
Block(-10,24,-6,LEAVES:15)
Block(-9,24,-6,LEAVES:15)
Block(-8,24,-6,LEAVES:15)
Block(-7,24,-6,LEAVES:15)
Block(-6,24,-6,LEAVES:15)
Block(-5,24,-6,LEAVES:15)
Block(-4,24,-6,LEAVES:15)
Block(-3,24,-6,LEAVES:3)
Block(-2,24,-6,LOG:15)
Block(-1,24,-6,LOG:15)
Block(0,24,-6,LEAVES:3)
Block(1,24,-6,LEAVES:15)
Block(2,24,-6,LEAVES:15)
Block(3,24,-6,LEAVES:15)
Block(4,24,-6,LEAVES:15)
Block(5,24,-6,LEAVES:15)
Block(6,24,-6,LEAVES:15)
Block(7,24,-6,LEAVES:15)
Block(8,24,-6,LEAVES:15)
Block(9,24,-6,LEAVES:15)
Block(10,24,-6,LEAVES:15)
Block(11,24,-6,LEAVES:15)
Block(12,24,-6,LEAVES:3)
Block(-11,24,-5,LEAVES:15)
Block(-10,24,-5,LEAVES:15)
Block(-9,24,-5,LEAVES:15)
Block(-8,24,-5,LEAVES:15)
Block(-7,24,-5,LEAVES:15)
Block(-6,24,-5,LEAVES:15)
Block(-5,24,-5,LEAVES:15)
Block(-4,24,-5,LEAVES:15)
Block(-3,24,-5,LEAVES:3)
Block(-2,24,-5,LOG:15)
Block(-1,24,-5,LOG:15)
Block(0,24,-5,LEAVES:3)
Block(1,24,-5,LEAVES:15)
Block(2,24,-5,LEAVES:15)
Block(3,24,-5,LEAVES:15)
Block(4,24,-5,LEAVES:3)
Block(5,24,-5,LEAVES:3)
Block(6,24,-5,LEAVES:3)
Block(7,24,-5,LEAVES:15)
Block(8,24,-5,LEAVES:15)
Block(9,24,-5,LOG:15)
Block(10,24,-5,LOG:15)
Block(11,24,-5,LEAVES:3)
Block(12,24,-5,LEAVES:3)
Block(13,24,-5,LEAVES:3)
Block(-12,24,-4,LEAVES:15)
Block(-11,24,-4,LEAVES:15)
Block(-10,24,-4,LEAVES:15)
Block(-9,24,-4,LEAVES:15)
Block(-8,24,-4,LEAVES:15)
Block(-7,24,-4,LEAVES:15)
Block(-5,24,-4,LEAVES:15)
Block(-4,24,-4,LEAVES:15)
Block(-3,24,-4,LEAVES:15)
Block(-2,24,-4,LEAVES:3)
Block(-1,24,-4,LEAVES:3)
Block(0,24,-4,LEAVES:3)
Block(1,24,-4,LEAVES:15)
Block(2,24,-4,LEAVES:15)
Block(3,24,-4,LEAVES:15)
Block(4,24,-4,LOG:15)
Block(5,24,-4,LOG:15)
Block(6,24,-4,LOG:15)
Block(7,24,-4,LOG:15)
Block(8,24,-4,LOG:15)
Block(9,24,-4,LOG:15)
Block(10,24,-4,LOG:15)
Block(11,24,-4,LOG:15)
Block(12,24,-4,LOG:15)
Block(13,24,-4,LEAVES:15)
Block(-11,24,-3,LEAVES:15)
Block(-10,24,-3,LEAVES:3)
Block(-6,24,-3,LEAVES:15)
Block(-5,24,-3,LEAVES:15)
Block(-4,24,-3,LEAVES:15)
Block(-3,24,-3,LEAVES:15)
Block(-2,24,-3,LEAVES:15)
Block(-1,24,-3,LEAVES:3)
Block(0,24,-3,LEAVES:15)
Block(1,24,-3,LEAVES:15)
Block(2,24,-3,LEAVES:15)
Block(3,24,-3,LOG:15)
Block(4,24,-3,LOG:15)
Block(5,24,-3,LOG:15)
Block(6,24,-3,LOG:15)
Block(7,24,-3,LOG:15)
Block(8,24,-3,LOG:15)
Block(9,24,-3,LOG:15)
Block(10,24,-3,LOG:15)
Block(11,24,-3,LEAVES:3)
Block(12,24,-3,LEAVES:3)
Block(13,24,-3,LEAVES:15)
Block(14,24,-3,LEAVES:15)
Block(-12,24,-2,LEAVES:15)
Block(-11,24,-2,LEAVES:3)
Block(-10,24,-2,LOG:15)
Block(-9,24,-2,LEAVES:3)
Block(-8,24,-2,LEAVES:15)
Block(-7,24,-2,LEAVES:15)
Block(-6,24,-2,LEAVES:15)
Block(-5,24,-2,LEAVES:15)
Block(-4,24,-2,LEAVES:15)
Block(-3,24,-2,LEAVES:15)
Block(-2,24,-2,LEAVES:15)
Block(0,24,-2,LEAVES:15)
Block(1,24,-2,LEAVES:15)
Block(2,24,-2,LEAVES:3)
Block(3,24,-2,LEAVES:3)
Block(4,24,-2,LOG:15)
Block(5,24,-2,LOG:15)
Block(6,24,-2,LOG:15)
Block(7,24,-2,LOG:15)
Block(8,24,-2,LEAVES:15)
Block(9,24,-2,LEAVES:15)
Block(10,24,-2,LEAVES:15)
Block(11,24,-2,LEAVES:15)
Block(12,24,-2,LEAVES:15)
Block(13,24,-2,LEAVES:15)
Block(-12,24,-1,LEAVES:15)
Block(-11,24,-1,LEAVES:15)
Block(-10,24,-1,LEAVES:3)
Block(-9,24,-1,LOG:15)
Block(-8,24,-1,LEAVES:15)
Block(-7,24,-1,LEAVES:3)
Block(-6,24,-1,LEAVES:15)
Block(-5,24,-1,LEAVES:15)
Block(-4,24,-1,LEAVES:15)
Block(-3,24,-1,LEAVES:15)
Block(-2,24,-1,LEAVES:15)
Block(1,24,-1,LEAVES:15)
Block(2,24,-1,LEAVES:3)
Block(3,24,-1,LOG:15)
Block(4,24,-1,LEAVES:3)
Block(5,24,-1,LEAVES:15)
Block(6,24,-1,LEAVES:15)
Block(7,24,-1,LEAVES:15)
Block(8,24,-1,LEAVES:15)
Block(9,24,-1,LEAVES:15)
Block(10,24,-1,LEAVES:15)
Block(11,24,-1,LEAVES:15)
Block(12,24,-1,LEAVES:15)
Block(-13,24,0,LEAVES:15)
Block(-12,24,0,LEAVES:15)
Block(-11,24,0,LEAVES:15)
Block(-10,24,0,LEAVES:15)
Block(-9,24,0,LEAVES:15)
Block(-8,24,0,LEAVES:3)
Block(-7,24,0,LEAVES:3)
Block(-6,24,0,LEAVES:3)
Block(-5,24,0,LEAVES:15)
Block(-4,24,0,LEAVES:15)
Block(-3,24,0,LEAVES:15)
Block(0,24,0,LEAVES:15)
Block(1,24,0,LEAVES:15)
Block(2,24,0,LOG:15)
Block(3,24,0,LOG:15)
Block(4,24,0,LOG:15)
Block(5,24,0,LEAVES:15)
Block(6,24,0,LEAVES:15)
Block(7,24,0,LEAVES:15)
Block(8,24,0,LEAVES:15)
Block(9,24,0,LEAVES:15)
Block(10,24,0,LEAVES:15)
Block(11,24,0,LEAVES:15)
Block(12,24,0,LEAVES:15)
Block(-14,24,1,LEAVES:15)
Block(-13,24,1,LEAVES:15)
Block(-12,24,1,LEAVES:15)
Block(-10,24,1,LEAVES:15)
Block(-9,24,1,LEAVES:15)
Block(-8,24,1,LEAVES:15)
Block(-7,24,1,LEAVES:3)
Block(-6,24,1,LEAVES:15)
Block(-5,24,1,LEAVES:15)
Block(-4,24,1,LEAVES:15)
Block(-3,24,1,LEAVES:15)
Block(-2,24,1,LEAVES:15)
Block(-1,24,1,LEAVES:15)
Block(0,24,1,LEAVES:15)
Block(1,24,1,LOG:15)
Block(2,24,1,LOG:15)
Block(3,24,1,LOG:15)
Block(4,24,1,LEAVES:3)
Block(5,24,1,LEAVES:3)
Block(6,24,1,LEAVES:15)
Block(7,24,1,LEAVES:15)
Block(8,24,1,LEAVES:15)
Block(9,24,1,LEAVES:15)
Block(10,24,1,LEAVES:15)
Block(11,24,1,LEAVES:15)
Block(-13,24,2,LEAVES:15)
Block(-12,24,2,LEAVES:15)
Block(-10,24,2,LEAVES:15)
Block(-9,24,2,LEAVES:15)
Block(-8,24,2,LEAVES:15)
Block(-7,24,2,LEAVES:15)
Block(-6,24,2,LEAVES:15)
Block(-4,24,2,LEAVES:15)
Block(-3,24,2,LEAVES:15)
Block(-2,24,2,LEAVES:15)
Block(-1,24,2,LEAVES:15)
Block(0,24,2,LOG:15)
Block(1,24,2,LOG:15)
Block(2,24,2,LOG:15)
Block(3,24,2,LOG:15)
Block(4,24,2,LEAVES:3)
Block(5,24,2,LEAVES:15)
Block(6,24,2,LEAVES:15)
Block(7,24,2,LEAVES:15)
Block(8,24,2,LEAVES:15)
Block(9,24,2,LEAVES:15)
Block(10,24,2,LEAVES:15)
Block(-13,24,3,LEAVES:15)
Block(-12,24,3,LEAVES:15)
Block(-11,24,3,LEAVES:15)
Block(-10,24,3,LEAVES:15)
Block(-9,24,3,LEAVES:15)
Block(-8,24,3,LEAVES:15)
Block(-7,24,3,LEAVES:15)
Block(-6,24,3,LEAVES:15)
Block(-5,24,3,LEAVES:15)
Block(-4,24,3,LEAVES:15)
Block(-3,24,3,LEAVES:15)
Block(-2,24,3,LEAVES:15)
Block(-1,24,3,LEAVES:3)
Block(0,24,3,LEAVES:3)
Block(1,24,3,LOG:15)
Block(2,24,3,LOG:15)
Block(3,24,3,LEAVES:3)
Block(4,24,3,LEAVES:15)
Block(5,24,3,LEAVES:15)
Block(6,24,3,LEAVES:15)
Block(7,24,3,LEAVES:15)
Block(8,24,3,LEAVES:15)
Block(9,24,3,LEAVES:15)
Block(10,24,3,LEAVES:15)
Block(11,24,3,LEAVES:15)
Block(-13,24,4,LEAVES:15)
Block(-12,24,4,LEAVES:15)
Block(-11,24,4,LEAVES:15)
Block(-10,24,4,LEAVES:15)
Block(-9,24,4,LEAVES:15)
Block(-8,24,4,LEAVES:15)
Block(-7,24,4,LEAVES:15)
Block(-6,24,4,LEAVES:15)
Block(-5,24,4,LEAVES:15)
Block(-4,24,4,LEAVES:15)
Block(-3,24,4,LEAVES:3)
Block(-2,24,4,LEAVES:15)
Block(0,24,4,LEAVES:3)
Block(1,24,4,LEAVES:3)
Block(2,24,4,LEAVES:3)
Block(3,24,4,LEAVES:3)
Block(4,24,4,LEAVES:15)
Block(5,24,4,LEAVES:15)
Block(6,24,4,LEAVES:15)
Block(7,24,4,LEAVES:15)
Block(8,24,4,LEAVES:15)
Block(9,24,4,LEAVES:15)
Block(10,24,4,LEAVES:15)
Block(-14,24,5,LEAVES:15)
Block(-13,24,5,LEAVES:15)
Block(-12,24,5,LEAVES:15)
Block(-11,24,5,LEAVES:15)
Block(-10,24,5,LEAVES:15)
Block(-9,24,5,LEAVES:15)
Block(-8,24,5,LEAVES:15)
Block(-7,24,5,LEAVES:15)
Block(-6,24,5,LEAVES:3)
Block(-5,24,5,LEAVES:15)
Block(-4,24,5,LEAVES:3)
Block(-3,24,5,LEAVES:3)
Block(-2,24,5,LEAVES:3)
Block(-1,24,5,LEAVES:15)
Block(0,24,5,LEAVES:15)
Block(1,24,5,LEAVES:15)
Block(2,24,5,LEAVES:15)
Block(3,24,5,LEAVES:15)
Block(4,24,5,LEAVES:15)
Block(5,24,5,LEAVES:15)
Block(6,24,5,LEAVES:15)
Block(7,24,5,LEAVES:15)
Block(8,24,5,LEAVES:15)
Block(9,24,5,LEAVES:15)
Block(10,24,5,LEAVES:15)
Block(11,24,5,LEAVES:15)
Block(-13,24,6,LEAVES:15)
Block(-12,24,6,LEAVES:15)
Block(-11,24,6,LEAVES:15)
Block(-10,24,6,LEAVES:15)
Block(-9,24,6,LEAVES:3)
Block(-8,24,6,LEAVES:3)
Block(-7,24,6,LEAVES:3)
Block(-6,24,6,LEAVES:3)
Block(-5,24,6,LEAVES:3)
Block(-4,24,6,LEAVES:15)
Block(-3,24,6,LEAVES:3)
Block(-2,24,6,LEAVES:15)
Block(-1,24,6,LEAVES:15)
Block(0,24,6,LEAVES:15)
Block(1,24,6,LEAVES:15)
Block(2,24,6,LEAVES:15)
Block(3,24,6,LEAVES:15)
Block(4,24,6,LEAVES:15)
Block(5,24,6,LEAVES:15)
Block(6,24,6,LEAVES:15)
Block(7,24,6,LEAVES:15)
Block(8,24,6,LEAVES:15)
Block(9,24,6,LEAVES:15)
Block(10,24,6,LEAVES:15)
Block(11,24,6,LEAVES:15)
Block(-12,24,7,LEAVES:15)
Block(-11,24,7,LEAVES:15)
Block(-10,24,7,LEAVES:3)
Block(-9,24,7,LEAVES:3)
Block(-8,24,7,LOG:15)
Block(-7,24,7,LOG:15)
Block(-6,24,7,LEAVES:3)
Block(-5,24,7,LEAVES:15)
Block(-4,24,7,LEAVES:15)
Block(-3,24,7,LEAVES:15)
Block(-2,24,7,LEAVES:15)
Block(-1,24,7,LEAVES:15)
Block(0,24,7,LEAVES:15)
Block(1,24,7,LEAVES:15)
Block(2,24,7,LEAVES:15)
Block(3,24,7,LEAVES:15)
Block(4,24,7,LEAVES:15)
Block(5,24,7,LEAVES:15)
Block(6,24,7,LEAVES:15)
Block(7,24,7,LEAVES:15)
Block(9,24,7,LEAVES:15)
Block(10,24,7,LEAVES:15)
Block(11,24,7,LEAVES:15)
Block(-13,24,8,LEAVES:15)
Block(-12,24,8,LEAVES:15)
Block(-11,24,8,LEAVES:15)
Block(-10,24,8,LEAVES:3)
Block(-9,24,8,LOG:15)
Block(-8,24,8,LOG:15)
Block(-7,24,8,LOG:15)
Block(-6,24,8,LEAVES:3)
Block(-5,24,8,LEAVES:15)
Block(-4,24,8,LEAVES:15)
Block(-3,24,8,LEAVES:15)
Block(-2,24,8,LEAVES:15)
Block(-1,24,8,LEAVES:15)
Block(0,24,8,LEAVES:15)
Block(1,24,8,LEAVES:15)
Block(2,24,8,LEAVES:15)
Block(3,24,8,LEAVES:15)
Block(4,24,8,LEAVES:15)
Block(5,24,8,LEAVES:15)
Block(6,24,8,LEAVES:15)
Block(7,24,8,LEAVES:15)
Block(8,24,8,LEAVES:15)
Block(10,24,8,LEAVES:15)
Block(-12,24,9,LEAVES:15)
Block(-10,24,9,LEAVES:3)
Block(-9,24,9,LOG:15)
Block(-8,24,9,LOG:15)
Block(-7,24,9,LOG:15)
Block(-6,24,9,LEAVES:3)
Block(-5,24,9,LEAVES:15)
Block(-4,24,9,LEAVES:15)
Block(-3,24,9,LEAVES:15)
Block(-2,24,9,LEAVES:15)
Block(-1,24,9,LEAVES:15)
Block(0,24,9,LEAVES:15)
Block(1,24,9,LEAVES:15)
Block(2,24,9,LEAVES:15)
Block(4,24,9,LEAVES:15)
Block(7,24,9,LEAVES:15)
Block(-10,24,10,LEAVES:15)
Block(-9,24,10,LEAVES:15)
Block(-8,24,10,LOG:15)
Block(-7,24,10,LEAVES:3)
Block(-6,24,10,LEAVES:3)
Block(-5,24,10,LEAVES:15)
Block(-4,24,10,LEAVES:15)
Block(-3,24,10,LEAVES:15)
Block(-2,24,10,LEAVES:15)
Block(-1,24,10,LEAVES:15)
Block(0,24,10,LEAVES:15)
Block(1,24,10,LEAVES:15)
Block(-9,24,11,LEAVES:15)
Block(-8,24,11,LEAVES:15)
Block(-7,24,11,LEAVES:15)
Block(-6,24,11,LEAVES:15)
Block(-5,24,11,LEAVES:15)
Block(-4,24,11,LEAVES:15)
Block(-3,24,11,LEAVES:15)
