
#######################################################################
# +-----------------------------------------------------------------+ #
# |                            BO3 object                           | #
# +-----------------------------------------------------------------+ #
#######################################################################

Author: Bo3 BulkEdit

Description: Converted Schematic - Modified by Bo3BulkEdit

Version: 3

SettingsMode: WriteWithoutComments


#######################################################################
# +-----------------------------------------------------------------+ #
# |                          Main settings                          | #
# +-----------------------------------------------------------------+ #
#######################################################################

Tree: false

Frequency: 1

Rarity: 100.0

RotateRandomly: false

SpawnHeight: randomY

SpawnHeightOffset: 0

SpawnHeightVariance: 0

##############################
# Height Limits for the BO3. #
##############################

MinHeight: 62

MaxHeight: 62

######################
# Extrusion settings #
######################

ExtrudeMode: None

ExtrudeThroughBlocks: minecraft:air

MaxBranchDepth: 50


#######################################################################
# +-----------------------------------------------------------------+ #
# |                      Source block settings                      | #
# +-----------------------------------------------------------------+ #
#######################################################################

SourceBlocks: otg:air

MaxPercentageOutsideSourceBlock: 100

OutsideSourceBlock: placeAnyway

DoReplaceBlocks: true

IsOTGPlus: false


#######################################################################
# +-----------------------------------------------------------------+ #
# |                              Blocks                             | #
# +-----------------------------------------------------------------+ #
#######################################################################

B(-8,0,3,minecraft:dirt)
B(-8,1,3,minecraft:grass_block)
B(-8,0,4,minecraft:dirt)
B(-8,1,4,minecraft:dirt)
B(-8,2,4,minecraft:grass_block)
B(-8,0,5,minecraft:dirt)
B(-8,1,5,minecraft:dirt)
B(-8,2,5,minecraft:grass_block)
B(-8,0,6,minecraft:dirt)
B(-8,1,6,minecraft:dirt)
B(-8,2,6,minecraft:dirt)
B(-8,3,6,minecraft:grass_block)
B(-8,0,7,minecraft:dirt)
B(-8,1,7,minecraft:dirt)
B(-8,2,7,minecraft:dirt)
B(-8,3,7,minecraft:dirt)
B(-8,4,7,minecraft:stone)
B(-7,0,2,minecraft:grass_block)
B(-7,0,3,minecraft:dirt)
B(-7,1,3,minecraft:grass_block)
B(-7,0,4,minecraft:dirt)
B(-7,1,4,minecraft:dirt)
B(-7,2,4,minecraft:grass_block)
B(-7,0,5,minecraft:dirt)
B(-7,1,5,minecraft:dirt)
B(-7,2,5,minecraft:dirt)
B(-7,3,5,minecraft:grass_block)
B(-7,0,6,minecraft:dirt)
B(-7,1,6,minecraft:dirt)
B(-7,2,6,minecraft:dirt)
B(-7,3,6,minecraft:grass_block)
B(-7,0,7,minecraft:stone)
B(-7,1,7,minecraft:stone)
B(-7,2,7,minecraft:dirt)
B(-7,3,7,minecraft:dirt)
B(-7,4,7,minecraft:stone)
B(-6,0,2,minecraft:grass_block)
B(-6,0,3,minecraft:dirt)
B(-6,1,3,minecraft:dirt)
B(-6,2,3,minecraft:grass_block)
B(-6,0,4,minecraft:dirt)
B(-6,1,4,minecraft:dirt)
B(-6,2,4,minecraft:grass_block)
B(-6,0,5,minecraft:dirt)
B(-6,1,5,minecraft:dirt)
B(-6,2,5,minecraft:dirt)
B(-6,3,5,minecraft:grass_block)
B(-6,0,6,minecraft:dirt)
B(-6,1,6,minecraft:dirt)
B(-6,2,6,minecraft:dirt)
B(-6,3,6,minecraft:grass_block)
B(-6,0,7,minecraft:stone)
B(-6,1,7,minecraft:stone)
B(-6,2,7,minecraft:stone)
B(-6,3,7,minecraft:dirt)
B(-6,4,7,minecraft:stone)
B(-5,0,1,minecraft:grass_block)
B(-5,0,2,minecraft:grass_block)
B(-5,0,3,minecraft:dirt)
B(-5,1,3,minecraft:dirt)
B(-5,2,3,minecraft:grass_block)
B(-5,0,4,minecraft:dirt)
B(-5,1,4,minecraft:dirt)
B(-5,2,4,minecraft:grass_block)
B(-5,0,5,minecraft:dirt)
B(-5,1,5,minecraft:dirt)
B(-5,2,5,minecraft:dirt)
B(-5,3,5,minecraft:grass_block)
B(-5,1,6,minecraft:stone)
B(-5,2,6,minecraft:stone)
B(-5,3,6,minecraft:grass_block)
B(-5,0,7,minecraft:stone)
B(-5,1,7,minecraft:stone)
B(-5,2,7,minecraft:stone)
B(-5,3,7,minecraft:dirt)
B(-5,4,7,minecraft:stone)
B(-4,0,1,minecraft:grass_block)
B(-4,0,2,minecraft:grass_block)
B(-4,0,3,minecraft:dirt)
B(-4,1,3,minecraft:dirt)
B(-4,2,3,minecraft:grass_block)
B(-4,0,4,minecraft:dirt)
B(-4,1,4,minecraft:dirt)
B(-4,2,4,minecraft:grass_block)
B(-4,0,5,minecraft:dirt)
B(-4,1,5,minecraft:dirt)
B(-4,2,5,minecraft:stone)
B(-4,3,5,minecraft:grass_block)
B(-4,0,6,minecraft:stone)
B(-4,1,6,minecraft:stone)
B(-4,2,6,minecraft:stone)
B(-4,3,6,minecraft:grass_block)
B(-4,0,7,minecraft:stone)
B(-4,1,7,minecraft:stone)
B(-4,2,7,minecraft:stone)
B(-4,3,7,minecraft:dirt)
B(-4,4,7,minecraft:stone)
B(-3,0,0,minecraft:grass_block)
B(-3,0,1,minecraft:grass_block)
B(-3,0,2,minecraft:dirt)
B(-3,1,2,minecraft:dirt)
B(-3,2,2,minecraft:grass_block)
B(-3,0,3,minecraft:dirt)
B(-3,1,3,minecraft:dirt)
B(-3,2,3,minecraft:grass_block)
B(-3,0,4,minecraft:dirt)
B(-3,1,4,minecraft:dirt)
B(-3,2,4,minecraft:dirt)
B(-3,3,4,minecraft:stone)
B(-3,0,5,minecraft:dirt)
B(-3,1,5,minecraft:dirt)
B(-3,2,5,minecraft:stone)
B(-3,3,5,minecraft:stone)
B(-3,0,6,minecraft:stone)
B(-3,1,6,minecraft:stone)
B(-3,2,6,minecraft:stone)
B(-3,3,6,minecraft:stone)
B(-3,4,6,minecraft:stone)
B(-3,0,7,minecraft:stone)
B(-3,1,7,minecraft:stone)
B(-3,2,7,minecraft:stone)
B(-3,3,7,minecraft:stone)
B(-3,4,7,minecraft:stone)
B(-2,0,0,minecraft:dirt)
B(-2,1,0,minecraft:grass_block)
B(-2,0,1,minecraft:dirt)
B(-2,1,1,minecraft:grass_block)
B(-2,0,2,minecraft:dirt)
B(-2,1,2,minecraft:dirt)
B(-2,2,2,minecraft:grass_block)
B(-2,0,3,minecraft:dirt)
B(-2,1,3,minecraft:dirt)
B(-2,2,3,minecraft:dirt)
B(-2,3,3,minecraft:stone)
B(-2,0,4,minecraft:dirt)
B(-2,1,4,minecraft:dirt)
B(-2,2,4,minecraft:dirt)
B(-2,3,4,minecraft:stone)
B(-2,0,5,minecraft:stone)
B(-2,1,5,minecraft:stone)
B(-2,2,5,minecraft:stone)
B(-2,3,5,minecraft:stone)
B(-2,4,5,minecraft:stone)
B(-2,0,6,minecraft:stone)
B(-2,1,6,minecraft:stone)
B(-2,2,6,minecraft:stone)
B(-2,3,6,minecraft:stone)
B(-2,4,6,minecraft:stone)
B(-2,0,7,minecraft:stone)
B(-2,1,7,minecraft:stone)
B(-2,2,7,minecraft:stone)
B(-2,3,7,minecraft:stone)
B(-2,4,7,minecraft:stone)
B(-2,5,7,minecraft:stone)
B(-2,6,7,minecraft:stone)
B(-1,0,0,minecraft:dirt)
B(-1,1,0,minecraft:grass_block)
B(-1,0,1,minecraft:dirt)
B(-1,1,1,minecraft:dirt)
B(-1,2,1,minecraft:stone)
B(-1,0,2,minecraft:dirt)
B(-1,1,2,minecraft:dirt)
B(-1,2,2,minecraft:stone)
B(-1,3,2,minecraft:stone)
B(-1,0,3,minecraft:dirt)
B(-1,1,3,minecraft:dirt)
B(-1,2,3,minecraft:stone)
B(-1,3,3,minecraft:stone)
B(-1,1,4,minecraft:stone)
B(-1,2,4,minecraft:stone)
B(-1,3,4,minecraft:stone)
B(-1,4,4,minecraft:stone)
B(-1,0,5,minecraft:stone)
B(-1,1,5,minecraft:stone)
B(-1,2,5,minecraft:stone)
B(-1,3,5,minecraft:stone)
B(-1,4,5,minecraft:stone)
B(-1,1,6,minecraft:stone)
B(-1,2,6,minecraft:stone)
B(-1,3,6,minecraft:stone)
B(-1,4,6,minecraft:stone)
B(-1,5,6,minecraft:stone)
B(-1,6,6,minecraft:stone)
B(-1,0,7,minecraft:stone)
B(-1,1,7,minecraft:stone)
B(-1,2,7,minecraft:stone)
B(-1,3,7,minecraft:stone)
B(-1,4,7,minecraft:stone)
B(-1,5,7,minecraft:stone)
B(-1,6,7,minecraft:stone)
B(0,0,-6,minecraft:grass_block)
B(0,0,-5,minecraft:grass_block)
B(0,0,-4,minecraft:grass_block)
B(0,0,-3,minecraft:grass_block)
B(0,0,-2,minecraft:grass_block)
B(0,0,-1,minecraft:dirt)
B(0,1,-1,minecraft:grass_block)
B(0,0,0,minecraft:dirt)
B(0,1,0,minecraft:grass_block)
B(0,0,1,minecraft:dirt)
B(0,1,1,minecraft:stone)
B(0,2,1,minecraft:stone)
B(0,0,2,minecraft:dirt)
B(0,1,2,minecraft:stone)
B(0,2,2,minecraft:stone)
B(0,3,2,minecraft:stone)
B(0,0,3,minecraft:stone)
B(0,1,3,minecraft:stone)
B(0,2,3,minecraft:stone)
B(0,3,3,minecraft:stone)
B(0,1,4,minecraft:stone)
B(0,2,4,minecraft:stone)
B(0,3,4,minecraft:stone)
B(0,4,4,minecraft:stone)
B(0,5,4,minecraft:stone)
B(0,1,5,minecraft:stone)
B(0,2,5,minecraft:stone)
B(0,3,5,minecraft:stone)
B(0,4,5,minecraft:stone)
B(0,5,5,minecraft:stone)
B(0,2,6,minecraft:stone)
B(0,3,6,minecraft:stone)
B(0,4,6,minecraft:stone)
B(0,5,6,minecraft:stone)
B(0,6,6,minecraft:stone)
B(0,0,7,minecraft:stone)
B(0,1,7,minecraft:stone)
B(0,2,7,minecraft:stone)
B(0,3,7,minecraft:stone)
B(0,4,7,minecraft:stone)
B(0,5,7,minecraft:stone)
B(0,6,7,minecraft:stone)
B(1,0,-8,minecraft:grass_block)
B(1,0,-7,minecraft:grass_block)
B(1,0,-6,minecraft:grass_block)
B(1,0,-5,minecraft:grass_block)
B(1,0,-4,minecraft:dirt)
B(1,1,-4,minecraft:grass_block)
B(1,0,-3,minecraft:dirt)
B(1,1,-3,minecraft:grass_block)
B(1,0,-2,minecraft:dirt)
B(1,1,-2,minecraft:stone)
B(1,0,-1,minecraft:dirt)
B(1,1,-1,minecraft:stone)
B(1,0,0,minecraft:stone)
B(1,1,0,minecraft:stone)
B(1,2,0,minecraft:stone)
B(1,0,1,minecraft:stone)
B(1,1,1,minecraft:stone)
B(1,2,1,minecraft:stone)
B(1,0,2,minecraft:stone)
B(1,1,2,minecraft:stone)
B(1,2,2,minecraft:stone)
B(1,3,2,minecraft:stone)
B(1,0,3,minecraft:stone)
B(1,1,3,minecraft:stone)
B(1,2,3,minecraft:stone)
B(1,3,3,minecraft:stone)
B(1,4,3,minecraft:stone)
B(1,5,3,minecraft:stone)
B(1,1,4,minecraft:stone)
B(1,2,4,minecraft:stone)
B(1,3,4,minecraft:stone)
B(1,4,4,minecraft:stone)
B(1,5,4,minecraft:stone)
B(1,0,5,minecraft:stone)
B(1,1,5,minecraft:stone)
B(1,2,5,minecraft:stone)
B(1,3,5,minecraft:stone)
B(1,4,5,minecraft:stone)
B(1,5,5,minecraft:stone)
B(1,6,5,minecraft:grass_block)
B(1,1,6,minecraft:stone)
B(1,2,6,minecraft:stone)
B(1,3,6,minecraft:stone)
B(1,4,6,minecraft:stone)
B(1,5,6,minecraft:stone)
B(1,6,6,minecraft:stone)
B(1,3,7,minecraft:stone)
B(1,4,7,minecraft:stone)
B(1,5,7,minecraft:stone)
B(1,6,7,minecraft:stone)
B(1,7,7,minecraft:stone)
B(2,0,-8,minecraft:dirt)
B(2,1,-8,minecraft:grass_block)
B(2,0,-7,minecraft:dirt)
B(2,1,-7,minecraft:stone)
B(2,0,-6,minecraft:dirt)
B(2,1,-6,minecraft:stone)
B(2,0,-5,minecraft:dirt)
B(2,1,-5,minecraft:stone)
B(2,2,-5,minecraft:stone)
B(2,0,-4,minecraft:dirt)
B(2,1,-4,minecraft:stone)
B(2,2,-4,minecraft:stone)
B(2,0,-3,minecraft:stone)
B(2,1,-3,minecraft:stone)
B(2,2,-3,minecraft:stone)
B(2,0,-2,minecraft:stone)
B(2,1,-2,minecraft:stone)
B(2,2,-2,minecraft:stone)
B(2,3,-2,minecraft:stone)
B(2,0,-1,minecraft:stone)
B(2,1,-1,minecraft:stone)
B(2,2,-1,minecraft:stone)
B(2,3,-1,minecraft:stone)
B(2,0,0,minecraft:stone)
B(2,1,0,minecraft:stone)
B(2,2,0,minecraft:stone)
B(2,3,0,minecraft:stone)
B(2,0,1,minecraft:stone)
B(2,1,1,minecraft:stone)
B(2,2,1,minecraft:stone)
B(2,3,1,minecraft:stone)
B(2,0,2,minecraft:stone)
B(2,1,2,minecraft:stone)
B(2,2,2,minecraft:stone)
B(2,3,2,minecraft:stone)
B(2,0,3,minecraft:stone)
B(2,1,3,minecraft:stone)
B(2,2,3,minecraft:stone)
B(2,3,3,minecraft:stone)
B(2,4,3,minecraft:stone)
B(2,5,3,minecraft:stone)
B(2,0,4,minecraft:stone)
B(2,1,4,minecraft:stone)
B(2,2,4,minecraft:stone)
B(2,3,4,minecraft:stone)
B(2,4,4,minecraft:stone)
B(2,5,4,minecraft:stone)
B(2,0,5,minecraft:stone)
B(2,3,5,minecraft:stone)
B(2,4,5,minecraft:stone)
B(2,5,5,minecraft:stone)
B(2,6,5,minecraft:grass_block)
B(2,0,6,minecraft:stone)
B(2,1,6,minecraft:stone)
B(2,4,6,minecraft:stone)
B(2,5,6,minecraft:stone)
B(2,6,6,minecraft:dirt)
B(2,7,6,minecraft:stone)
B(2,0,7,minecraft:stone)
B(2,1,7,minecraft:stone)
B(2,2,7,minecraft:stone)
B(2,4,7,minecraft:stone)
B(2,5,7,minecraft:stone)
B(2,6,7,minecraft:stone)
B(2,7,7,minecraft:stone)
B(3,0,-8,minecraft:dirt)
B(3,1,-8,minecraft:grass_block)
B(3,0,-7,minecraft:stone)
B(3,1,-7,minecraft:stone)
B(3,0,-6,minecraft:stone)
B(3,1,-6,minecraft:stone)
B(3,2,-6,minecraft:stone)
B(3,0,-5,minecraft:stone)
B(3,1,-5,minecraft:stone)
B(3,2,-5,minecraft:stone)
B(3,0,-4,minecraft:stone)
B(3,1,-4,minecraft:stone)
B(3,2,-4,minecraft:stone)
B(3,0,-3,minecraft:stone)
B(3,1,-3,minecraft:stone)
B(3,2,-3,minecraft:stone)
B(3,3,-3,minecraft:stone)
B(3,0,-2,minecraft:stone)
B(3,1,-2,minecraft:stone)
B(3,2,-2,minecraft:stone)
B(3,3,-2,minecraft:stone)
B(3,0,-1,minecraft:stone)
B(3,1,-1,minecraft:stone)
B(3,2,-1,minecraft:stone)
B(3,3,-1,minecraft:stone)
B(3,0,0,minecraft:stone)
B(3,1,0,minecraft:stone)
B(3,2,0,minecraft:stone)
B(3,3,0,minecraft:stone)
B(3,4,0,minecraft:stone)
B(3,0,1,minecraft:stone)
B(3,1,1,minecraft:stone)
B(3,2,1,minecraft:stone)
B(3,3,1,minecraft:stone)
B(3,4,1,minecraft:stone)
B(3,5,1,minecraft:stone)
B(3,0,2,minecraft:stone)
B(3,1,2,minecraft:stone)
B(3,2,2,minecraft:stone)
B(3,3,2,minecraft:stone)
B(3,4,2,minecraft:stone)
B(3,5,2,minecraft:stone)
B(3,0,3,minecraft:stone)
B(3,1,3,minecraft:stone)
B(3,2,3,minecraft:stone)
B(3,3,3,minecraft:stone)
B(3,4,3,minecraft:stone)
B(3,5,3,minecraft:stone)
B(3,6,3,minecraft:grass_block)
B(3,0,4,minecraft:stone)
B(3,2,4,minecraft:stone)
B(3,3,4,minecraft:stone)
B(3,4,4,minecraft:stone)
B(3,5,4,minecraft:stone)
B(3,6,4,minecraft:grass_block)
B(3,1,5,minecraft:stone)
B(3,2,5,minecraft:stone)
B(3,4,5,minecraft:stone)
B(3,5,5,minecraft:stone)
B(3,6,5,minecraft:dirt)
B(3,7,5,minecraft:stone)
B(3,4,6,minecraft:stone)
B(3,5,6,minecraft:stone)
B(3,6,6,minecraft:dirt)
B(3,7,6,minecraft:stone)
B(3,0,7,minecraft:stone)
B(3,1,7,minecraft:stone)
B(3,2,7,minecraft:stone)
B(3,3,7,minecraft:stone)
B(3,4,7,minecraft:stone)
B(3,5,7,minecraft:stone)
B(3,6,7,minecraft:stone)
B(3,7,7,minecraft:stone)
B(3,8,7,minecraft:stone)
B(4,0,-8,minecraft:stone)
B(4,1,-8,minecraft:stone)
B(4,2,-8,minecraft:stone)
B(4,0,-7,minecraft:stone)
B(4,1,-7,minecraft:stone)
B(4,2,-7,minecraft:stone)
B(4,0,-6,minecraft:stone)
B(4,1,-6,minecraft:stone)
B(4,2,-6,minecraft:stone)
B(4,3,-6,minecraft:grass_block)
B(4,0,-5,minecraft:stone)
B(4,1,-5,minecraft:stone)
B(4,2,-5,minecraft:stone)
B(4,3,-5,minecraft:grass_block)
B(4,0,-4,minecraft:stone)
B(4,1,-4,minecraft:stone)
B(4,2,-4,minecraft:stone)
B(4,3,-4,minecraft:stone)
B(4,0,-3,minecraft:stone)
B(4,1,-3,minecraft:stone)
B(4,2,-3,minecraft:stone)
B(4,3,-3,minecraft:stone)
B(4,4,-3,minecraft:stone)
B(4,0,-2,minecraft:stone)
B(4,1,-2,minecraft:stone)
B(4,2,-2,minecraft:stone)
B(4,3,-2,minecraft:stone)
B(4,4,-2,minecraft:stone)
B(4,0,-1,minecraft:stone)
B(4,1,-1,minecraft:stone)
B(4,2,-1,minecraft:stone)
B(4,3,-1,minecraft:stone)
B(4,4,-1,minecraft:stone)
B(4,0,0,minecraft:stone)
B(4,1,0,minecraft:stone)
B(4,2,0,minecraft:stone)
B(4,3,0,minecraft:stone)
B(4,4,0,minecraft:stone)
B(4,5,0,minecraft:stone)
B(4,0,1,minecraft:stone)
B(4,1,1,minecraft:stone)
B(4,2,1,minecraft:stone)
B(4,3,1,minecraft:stone)
B(4,4,1,minecraft:stone)
B(4,5,1,minecraft:stone)
B(4,0,2,minecraft:stone)
B(4,1,2,minecraft:stone)
B(4,2,2,minecraft:stone)
B(4,3,2,minecraft:stone)
B(4,4,2,minecraft:stone)
B(4,5,2,minecraft:stone)
B(4,6,2,minecraft:grass_block)
B(4,0,3,minecraft:stone)
B(4,1,3,minecraft:stone)
B(4,3,3,minecraft:stone)
B(4,4,3,minecraft:stone)
B(4,5,3,minecraft:stone)
B(4,6,3,minecraft:grass_block)
B(4,0,4,minecraft:stone)
B(4,1,4,minecraft:stone)
B(4,3,4,minecraft:stone)
B(4,4,4,minecraft:stone)
B(4,5,4,minecraft:stone)
B(4,6,4,minecraft:dirt)
B(4,7,4,minecraft:stone)
B(4,0,5,minecraft:stone)
B(4,2,5,minecraft:stone)
B(4,3,5,minecraft:stone)
B(4,4,5,minecraft:stone)
B(4,5,5,minecraft:stone)
B(4,6,5,minecraft:dirt)
B(4,7,5,minecraft:stone)
B(4,0,6,minecraft:stone)
B(4,1,6,minecraft:stone)
B(4,2,6,minecraft:stone)
B(4,3,6,minecraft:stone)
B(4,5,6,minecraft:stone)
B(4,6,6,minecraft:dirt)
B(4,7,6,minecraft:stone)
B(4,8,6,minecraft:stone)
B(4,0,7,minecraft:stone)
B(4,1,7,minecraft:stone)
B(4,3,7,minecraft:stone)
B(4,4,7,minecraft:stone)
B(4,5,7,minecraft:stone)
B(4,6,7,minecraft:stone)
B(4,7,7,minecraft:stone)
B(4,8,7,minecraft:stone)
B(5,0,-8,minecraft:stone)
B(5,1,-8,minecraft:stone)
B(5,2,-8,minecraft:dirt)
B(5,3,-8,minecraft:grass_block)
B(5,0,-7,minecraft:stone)
B(5,1,-7,minecraft:stone)
B(5,2,-7,minecraft:stone)
B(5,3,-7,minecraft:grass_block)
B(5,0,-6,minecraft:stone)
B(5,1,-6,minecraft:stone)
B(5,2,-6,minecraft:stone)
B(5,3,-6,minecraft:dirt)
B(5,4,-6,minecraft:stone)
B(5,0,-5,minecraft:stone)
B(5,1,-5,minecraft:stone)
B(5,2,-5,minecraft:stone)
B(5,3,-5,minecraft:dirt)
B(5,4,-5,minecraft:stone)
B(5,0,-4,minecraft:stone)
B(5,1,-4,minecraft:stone)
B(5,2,-4,minecraft:stone)
B(5,3,-4,minecraft:stone)
B(5,4,-4,minecraft:stone)
B(5,0,-3,minecraft:stone)
B(5,1,-3,minecraft:stone)
B(5,2,-3,minecraft:stone)
B(5,3,-3,minecraft:stone)
B(5,4,-3,minecraft:stone)
B(5,5,-3,minecraft:grass_block)
B(5,0,-2,minecraft:stone)
B(5,2,-2,minecraft:stone)
B(5,3,-2,minecraft:stone)
B(5,4,-2,minecraft:stone)
B(5,5,-2,minecraft:grass_block)
B(5,0,-1,minecraft:stone)
B(5,2,-1,minecraft:stone)
B(5,3,-1,minecraft:stone)
B(5,4,-1,minecraft:stone)
B(5,5,-1,minecraft:grass_block)
B(5,3,0,minecraft:stone)
B(5,4,0,minecraft:stone)
B(5,5,0,minecraft:dirt)
B(5,6,0,minecraft:grass_block)
B(5,3,1,minecraft:stone)
B(5,4,1,minecraft:stone)
B(5,5,1,minecraft:stone)
B(5,6,1,minecraft:grass_block)
B(5,1,2,minecraft:stone)
B(5,2,2,minecraft:stone)
B(5,3,2,minecraft:stone)
B(5,4,2,minecraft:stone)
B(5,5,2,minecraft:stone)
B(5,6,2,minecraft:grass_block)
B(5,0,3,minecraft:stone)
B(5,1,3,minecraft:stone)
B(5,2,3,minecraft:stone)
B(5,3,3,minecraft:stone)
B(5,4,3,minecraft:stone)
B(5,5,3,minecraft:stone)
B(5,6,3,minecraft:dirt)
B(5,7,3,minecraft:stone)
B(5,0,4,minecraft:stone)
B(5,2,4,minecraft:stone)
B(5,3,4,minecraft:stone)
B(5,4,4,minecraft:stone)
B(5,5,4,minecraft:stone)
B(5,6,4,minecraft:dirt)
B(5,7,4,minecraft:stone)
B(5,0,5,minecraft:stone)
B(5,1,5,minecraft:stone)
B(5,3,5,minecraft:stone)
B(5,4,5,minecraft:stone)
B(5,5,5,minecraft:stone)
B(5,6,5,minecraft:dirt)
B(5,7,5,minecraft:stone)
B(5,8,5,minecraft:stone)
B(5,1,6,minecraft:stone)
B(5,2,6,minecraft:stone)
B(5,5,6,minecraft:stone)
B(5,6,6,minecraft:stone)
B(5,7,6,minecraft:stone)
B(5,8,6,minecraft:stone)
B(5,1,7,minecraft:stone)
B(5,2,7,minecraft:stone)
B(5,4,7,minecraft:stone)
B(5,5,7,minecraft:stone)
B(5,6,7,minecraft:stone)
B(5,7,7,minecraft:stone)
B(5,8,7,minecraft:stone)
B(5,9,7,minecraft:grass_block)
B(6,0,-8,minecraft:stone)
B(6,1,-8,minecraft:stone)
B(6,2,-8,minecraft:dirt)
B(6,3,-8,minecraft:dirt)
B(6,4,-8,minecraft:stone)
B(6,0,-7,minecraft:stone)
B(6,1,-7,minecraft:stone)
B(6,2,-7,minecraft:stone)
B(6,3,-7,minecraft:dirt)
B(6,4,-7,minecraft:stone)
B(6,5,-7,minecraft:stone)
B(6,0,-6,minecraft:stone)
B(6,1,-6,minecraft:stone)
B(6,2,-6,minecraft:stone)
B(6,3,-6,minecraft:dirt)
B(6,4,-6,minecraft:stone)
B(6,5,-6,minecraft:grass_block)
B(6,0,-5,minecraft:stone)
B(6,1,-5,minecraft:stone)
B(6,2,-5,minecraft:stone)
B(6,3,-5,minecraft:dirt)
B(6,4,-5,minecraft:stone)
B(6,5,-5,minecraft:grass_block)
B(6,3,-4,minecraft:stone)
B(6,4,-4,minecraft:stone)
B(6,5,-4,minecraft:grass_block)
B(6,0,-3,minecraft:stone)
B(6,2,-3,minecraft:stone)
B(6,3,-3,minecraft:stone)
B(6,4,-3,minecraft:stone)
B(6,5,-3,minecraft:grass_block)
B(6,0,-2,minecraft:stone)
B(6,1,-2,minecraft:stone)
B(6,2,-2,minecraft:stone)
B(6,3,-2,minecraft:stone)
B(6,4,-2,minecraft:stone)
B(6,5,-2,minecraft:grass_block)
B(6,1,-1,minecraft:stone)
B(6,2,-1,minecraft:stone)
B(6,3,-1,minecraft:stone)
B(6,5,-1,minecraft:dirt)
B(6,6,-1,minecraft:grass_block)
B(6,0,0,minecraft:stone)
B(6,2,0,minecraft:stone)
B(6,5,0,minecraft:dirt)
B(6,6,0,minecraft:grass_block)
B(6,1,1,minecraft:stone)
B(6,2,1,minecraft:stone)
B(6,3,1,minecraft:stone)
B(6,4,1,minecraft:stone)
B(6,5,1,minecraft:stone)
B(6,6,1,minecraft:grass_block)
B(6,1,2,minecraft:stone)
B(6,2,2,minecraft:stone)
B(6,3,2,minecraft:stone)
B(6,4,2,minecraft:stone)
B(6,5,2,minecraft:stone)
B(6,6,2,minecraft:dirt)
B(6,7,2,minecraft:stone)
B(6,0,3,minecraft:stone)
B(6,2,3,minecraft:stone)
B(6,4,3,minecraft:stone)
B(6,5,3,minecraft:stone)
B(6,6,3,minecraft:dirt)
B(6,7,3,minecraft:stone)
B(6,8,3,minecraft:stone)
B(6,0,4,minecraft:stone)
B(6,1,4,minecraft:stone)
B(6,2,4,minecraft:stone)
B(6,3,4,minecraft:stone)
B(6,4,4,minecraft:stone)
B(6,5,4,minecraft:stone)
B(6,6,4,minecraft:dirt)
B(6,7,4,minecraft:stone)
B(6,8,4,minecraft:stone)
B(6,9,4,minecraft:grass_block)
B(6,0,5,minecraft:stone)
B(6,3,5,minecraft:stone)
B(6,4,5,minecraft:stone)
B(6,5,5,minecraft:stone)
B(6,6,5,minecraft:stone)
B(6,7,5,minecraft:stone)
B(6,8,5,minecraft:stone)
B(6,9,5,minecraft:grass_block)
B(6,0,6,minecraft:stone)
B(6,1,6,minecraft:stone)
B(6,3,6,minecraft:stone)
B(6,4,6,minecraft:stone)
B(6,7,6,minecraft:stone)
B(6,8,6,minecraft:stone)
B(6,9,6,minecraft:dirt)
B(6,10,6,minecraft:grass_block)
B(6,0,7,minecraft:stone)
B(6,1,7,minecraft:stone)
B(6,2,7,minecraft:stone)
B(6,3,7,minecraft:stone)
B(6,4,7,minecraft:stone)
B(6,5,7,minecraft:stone)
B(6,6,7,minecraft:stone)
B(6,7,7,minecraft:stone)
B(6,8,7,minecraft:stone)
B(6,9,7,minecraft:dirt)
B(6,10,7,minecraft:grass_block)
B(7,1,-8,minecraft:stone)
B(7,2,-8,minecraft:dirt)
B(7,3,-8,minecraft:dirt)
B(7,4,-8,minecraft:stone)
B(7,0,-7,minecraft:stone)
B(7,1,-7,minecraft:stone)
B(7,2,-7,minecraft:stone)
B(7,3,-7,minecraft:dirt)
B(7,4,-7,minecraft:stone)
B(7,5,-7,minecraft:stone)
B(7,6,-7,minecraft:stone)
B(7,0,-6,minecraft:stone)
B(7,1,-6,minecraft:stone)
B(7,2,-6,minecraft:stone)
B(7,3,-6,minecraft:dirt)
B(7,4,-6,minecraft:stone)
B(7,5,-6,minecraft:dirt)
B(7,6,-6,minecraft:stone)
B(7,2,-5,minecraft:stone)
B(7,3,-5,minecraft:stone)
B(7,4,-5,minecraft:stone)
B(7,5,-5,minecraft:dirt)
B(7,6,-5,minecraft:stone)
B(7,2,-4,minecraft:stone)
B(7,3,-4,minecraft:stone)
B(7,4,-4,minecraft:stone)
B(7,5,-4,minecraft:dirt)
B(7,6,-4,minecraft:stone)
B(7,1,-3,minecraft:stone)
B(7,2,-3,minecraft:stone)
B(7,3,-3,minecraft:stone)
B(7,4,-3,minecraft:stone)
B(7,5,-3,minecraft:dirt)
B(7,6,-3,minecraft:stone)
B(7,7,-3,minecraft:stone)
B(7,0,-2,minecraft:stone)
B(7,1,-2,minecraft:stone)
B(7,3,-2,minecraft:stone)
B(7,5,-2,minecraft:dirt)
B(7,6,-2,minecraft:dirt)
B(7,7,-2,minecraft:stone)
B(7,0,-1,minecraft:stone)
B(7,1,-1,minecraft:stone)
B(7,4,-1,minecraft:stone)
B(7,5,-1,minecraft:dirt)
B(7,6,-1,minecraft:dirt)
B(7,7,-1,minecraft:stone)
B(7,2,0,minecraft:stone)
B(7,5,0,minecraft:dirt)
B(7,6,0,minecraft:dirt)
B(7,7,0,minecraft:stone)
B(7,8,0,minecraft:stone)
B(7,1,1,minecraft:stone)
B(7,3,1,minecraft:stone)
B(7,4,1,minecraft:stone)
B(7,5,1,minecraft:stone)
B(7,6,1,minecraft:dirt)
B(7,7,1,minecraft:stone)
B(7,8,1,minecraft:stone)
B(7,1,2,minecraft:stone)
B(7,2,2,minecraft:stone)
B(7,3,2,minecraft:stone)
B(7,4,2,minecraft:stone)
B(7,5,2,minecraft:stone)
B(7,6,2,minecraft:dirt)
B(7,7,2,minecraft:stone)
B(7,8,2,minecraft:stone)
B(7,9,2,minecraft:grass_block)
B(7,0,3,minecraft:stone)
B(7,1,3,minecraft:stone)
B(7,3,3,minecraft:stone)
B(7,4,3,minecraft:stone)
B(7,5,3,minecraft:stone)
B(7,6,3,minecraft:stone)
B(7,7,3,minecraft:stone)
B(7,8,3,minecraft:stone)
B(7,9,3,minecraft:grass_block)
B(7,0,4,minecraft:stone)
B(7,1,4,minecraft:stone)
B(7,2,4,minecraft:stone)
B(7,4,4,minecraft:stone)
B(7,5,4,minecraft:stone)
B(7,6,4,minecraft:stone)
B(7,7,4,minecraft:stone)
B(7,8,4,minecraft:stone)
B(7,9,4,minecraft:grass_block)
B(7,1,5,minecraft:stone)
B(7,3,5,minecraft:stone)
B(7,6,5,minecraft:stone)
B(7,7,5,minecraft:stone)
B(7,8,5,minecraft:stone)
B(7,9,5,minecraft:dirt)
B(7,10,5,minecraft:grass_block)
B(7,1,6,minecraft:stone)
B(7,2,6,minecraft:stone)
B(7,6,6,minecraft:stone)
B(7,7,6,minecraft:stone)
B(7,8,6,minecraft:stone)
B(7,9,6,minecraft:dirt)
B(7,10,6,minecraft:grass_block)
B(7,1,7,minecraft:stone)
B(7,2,7,minecraft:stone)
B(7,3,7,minecraft:stone)
B(7,4,7,minecraft:stone)
B(7,7,7,minecraft:stone)
B(7,8,7,minecraft:stone)
B(7,9,7,minecraft:dirt)
B(7,10,7,minecraft:grass_block)
RB(7,0,-8,minecraft:coal_ore,33,minecraft:stone,100)
RB(7,0,-5,minecraft:coal_ore,33,minecraft:stone,100)
RB(6,0,-4,minecraft:coal_ore,33,minecraft:stone,100)
RB(7,0,-4,minecraft:coal_ore,33,minecraft:stone,100)
RB(7,0,-3,minecraft:coal_ore,33,minecraft:stone,100)
RB(6,0,-1,minecraft:coal_ore,33,minecraft:stone,100)
RB(5,0,0,minecraft:coal_ore,33,minecraft:stone,100)
RB(7,0,0,minecraft:coal_ore,33,minecraft:stone,100)
RB(5,0,1,minecraft:coal_ore,33,minecraft:stone,100)
RB(6,0,1,minecraft:coal_ore,33,minecraft:stone,100)
RB(7,0,1,minecraft:coal_ore,33,minecraft:stone,100)
RB(5,0,2,minecraft:coal_ore,33,minecraft:stone,100)
RB(6,0,2,minecraft:coal_ore,33,minecraft:stone,100)
RB(7,0,2,minecraft:coal_ore,33,minecraft:stone,100)
RB(-1,0,4,minecraft:coal_ore,33,minecraft:stone,100)
RB(0,0,4,minecraft:coal_ore,33,minecraft:stone,100)
RB(1,0,4,minecraft:coal_ore,33,minecraft:stone,100)
RB(0,0,5,minecraft:coal_ore,33,minecraft:stone,100)
RB(3,0,5,minecraft:coal_ore,33,minecraft:stone,100)
RB(7,0,5,minecraft:coal_ore,33,minecraft:stone,100)
RB(-5,0,6,minecraft:coal_ore,33,minecraft:stone,100)
RB(-1,0,6,minecraft:coal_ore,33,minecraft:stone,100)
RB(0,0,6,minecraft:coal_ore,33,minecraft:stone,100)
RB(1,0,6,minecraft:coal_ore,33,minecraft:stone,100)
RB(3,0,6,minecraft:coal_ore,33,minecraft:stone,100)
RB(5,0,6,minecraft:coal_ore,33,minecraft:stone,100)
RB(7,0,6,minecraft:coal_ore,33,minecraft:stone,100)
RB(1,0,7,minecraft:coal_ore,33,minecraft:stone,100)
RB(5,0,7,minecraft:coal_ore,33,minecraft:stone,100)
RB(7,0,7,minecraft:coal_ore,33,minecraft:stone,100)
RB(7,1,-5,minecraft:coal_ore,33,minecraft:stone,100)
RB(6,1,-4,minecraft:coal_ore,33,minecraft:stone,100)
RB(7,1,-4,minecraft:coal_ore,33,minecraft:stone,100)
RB(6,1,-3,minecraft:coal_ore,33,minecraft:stone,100)
RB(5,1,-2,minecraft:coal_ore,33,minecraft:stone,100)
RB(5,1,-1,minecraft:coal_ore,33,minecraft:stone,100)
RB(5,1,0,minecraft:coal_ore,33,minecraft:stone,100)
RB(6,1,0,minecraft:coal_ore,33,minecraft:stone,100)
RB(7,1,0,minecraft:coal_ore,33,minecraft:stone,100)
RB(5,1,1,minecraft:coal_ore,33,minecraft:stone,100)
RB(6,1,3,minecraft:coal_ore,33,minecraft:stone,100)
RB(3,1,4,minecraft:coal_ore,33,minecraft:stone,100)
RB(5,1,4,minecraft:coal_ore,33,minecraft:stone,100)
RB(2,1,5,minecraft:coal_ore,33,minecraft:stone,100)
RB(4,1,5,minecraft:coal_ore,33,minecraft:stone,100)
RB(6,1,5,minecraft:coal_ore,33,minecraft:stone,100)
RB(0,1,6,minecraft:coal_ore,33,minecraft:stone,100)
RB(3,1,6,minecraft:coal_ore,33,minecraft:stone,100)
RB(1,1,7,minecraft:coal_ore,33,minecraft:stone,100)
RB(6,2,-4,minecraft:coal_ore,33,minecraft:stone,100)
RB(7,2,-2,minecraft:coal_ore,33,minecraft:stone,100)
RB(7,2,-1,minecraft:coal_ore,33,minecraft:stone,100)
RB(5,2,0,minecraft:coal_ore,33,minecraft:stone,100)
RB(5,2,1,minecraft:coal_ore,33,minecraft:stone,100)
RB(7,2,1,minecraft:coal_ore,33,minecraft:stone,100)
RB(4,2,3,minecraft:coal_ore,33,minecraft:stone,100)
RB(7,2,3,minecraft:coal_ore,33,minecraft:stone,100)
RB(4,2,4,minecraft:coal_ore,33,minecraft:stone,100)
RB(2,2,5,minecraft:coal_ore,33,minecraft:stone,100)
RB(5,2,5,minecraft:coal_ore,33,minecraft:stone,100)
RB(6,2,5,minecraft:coal_ore,33,minecraft:stone,100)
RB(7,2,5,minecraft:coal_ore,33,minecraft:stone,100)
RB(2,2,6,minecraft:coal_ore,33,minecraft:stone,100)
RB(3,2,6,minecraft:coal_ore,33,minecraft:stone,100)
RB(6,2,6,minecraft:coal_ore,33,minecraft:stone,100)
RB(1,2,7,minecraft:coal_ore,33,minecraft:stone,100)
RB(4,2,7,minecraft:coal_ore,33,minecraft:stone,100)
RB(7,3,-1,minecraft:coal_ore,33,minecraft:stone,100)
RB(6,3,0,minecraft:coal_ore,33,minecraft:stone,100)
RB(7,3,0,minecraft:coal_ore,33,minecraft:stone,100)
RB(6,3,3,minecraft:coal_ore,33,minecraft:stone,100)
RB(7,3,4,minecraft:coal_ore,33,minecraft:stone,100)
RB(3,3,5,minecraft:coal_ore,33,minecraft:stone,100)
RB(2,3,6,minecraft:coal_ore,33,minecraft:stone,100)
RB(3,3,6,minecraft:coal_ore,33,minecraft:stone,100)
RB(5,3,6,minecraft:coal_ore,33,minecraft:stone,100)
RB(7,3,6,minecraft:coal_ore,33,minecraft:stone,100)
RB(2,3,7,minecraft:coal_ore,33,minecraft:stone,100)
RB(5,3,7,minecraft:coal_ore,33,minecraft:stone,100)
RB(7,4,-2,minecraft:coal_ore,33,minecraft:stone,100)
RB(6,4,-1,minecraft:coal_ore,33,minecraft:stone,100)
RB(6,4,0,minecraft:coal_ore,33,minecraft:stone,100)
RB(7,4,0,minecraft:coal_ore,33,minecraft:stone,100)
RB(7,4,5,minecraft:coal_ore,33,minecraft:stone,100)
RB(4,4,6,minecraft:coal_ore,33,minecraft:stone,100)
RB(5,4,6,minecraft:coal_ore,33,minecraft:stone,100)
RB(7,4,6,minecraft:coal_ore,33,minecraft:stone,100)
RB(7,5,5,minecraft:coal_ore,33,minecraft:stone,100)
RB(6,5,6,minecraft:coal_ore,33,minecraft:stone,100)
RB(7,5,6,minecraft:coal_ore,33,minecraft:stone,100)
RB(7,5,7,minecraft:coal_ore,33,minecraft:stone,100)
RB(6,6,6,minecraft:coal_ore,33,minecraft:stone,100)
RB(7,6,7,minecraft:coal_ore,33,minecraft:stone,100)

#######################################################################
# +-----------------------------------------------------------------+ #
# |                            BO3 checks                           | #
# +-----------------------------------------------------------------+ #
#######################################################################


#######################################################################
# +-----------------------------------------------------------------+ #
# |                             Branches                            | #
# +-----------------------------------------------------------------+ #
#######################################################################

Branch(-16,0,0,Quarry_1x1,NORTH,100.0)

#######################################################################
# +-----------------------------------------------------------------+ #
# |                             Entities                            | #
# +-----------------------------------------------------------------+ #
#######################################################################

