#######################################################################
# +-----------------------------------------------------------------+ #
# |                            BO3 object                           | #
# +-----------------------------------------------------------------+ #
#######################################################################

Author: Bo3 BulkEdit

Description: Converted Schematic - Modified by Bo3BulkEdit

Version: 3

SettingsMode: WriteDisable

#######################################################################
# +-----------------------------------------------------------------+ #
# |                          Main settings                          | #
# +-----------------------------------------------------------------+ #
#######################################################################

IsOTGPlus: false
Tree: false
Frequency: 1
Rarity: 100
RotateRandomly: false
SpawnHeight: randomY
SpawnHeightOffset: 0
SpawnHeightVariance: 0
MaxBranchDepth: 50
ExcludedBiomes: All

##############################
# Height Limits for the BO3. #
##############################

MinHeight: 62
MaxHeight: 62

#######################################################################
# +-----------------------------------------------------------------+ #
# |                      Source block settings                      | #
# +-----------------------------------------------------------------+ #
#######################################################################

SourceBlocks: AIR
MaxPercentageOutsideSourceBlock: 100
OutsideSourceBlock: placeAnyway

#######################################################################
# +-----------------------------------------------------------------+ #
# |                              Blocks                             | #
# +-----------------------------------------------------------------+ #
#######################################################################

B(-8,0,-8,STONE)
B(-7,0,-8,STONE)
B(-6,0,-8,STONE)
B(-5,0,-8,STONE)
B(-4,0,-8,STONE)
B(-3,0,-8,STONE)
B(-2,0,-8,STONE)
B(-1,0,-8,STONE)
B(0,0,-8,STONE)
B(1,0,-8,STONE)
B(2,0,-8,STONE)
B(3,0,-8,STONE)
B(4,0,-8,STONE)
B(5,0,-8,STONE)
B(6,0,-8,STONE)
B(7,0,-8,STONE)
B(-8,0,-7,STONE)
B(-7,0,-7,STONE)
B(-6,0,-7,STONE)
B(-5,0,-7,STONE)
B(-4,0,-7,STONE)
B(-3,0,-7,STONE)
B(-2,0,-7,STONE)
B(-1,0,-7,STONE)
B(0,0,-7,STONE)
B(1,0,-7,STONE)
B(2,0,-7,STONE)
B(3,0,-7,STONE)
B(4,0,-7,STONE)
B(5,0,-7,STONE)
B(6,0,-7,STONE)
B(7,0,-7,STONE)
B(-8,0,-6,STONE)
B(-7,0,-6,STONE)
B(-6,0,-6,STONE)
B(-5,0,-6,STONE)
B(-4,0,-6,STONE)
B(-3,0,-6,STONE)
B(-2,0,-6,STONE)
B(-1,0,-6,STONE)
B(0,0,-6,STONE)
B(1,0,-6,STONE)
B(2,0,-6,STONE)
B(3,0,-6,STONE)
B(4,0,-6,STONE)
B(5,0,-6,STONE)
B(6,0,-6,STONE)
B(7,0,-6,STONE)
B(-8,0,-5,STONE)
B(-7,0,-5,STONE)
B(-6,0,-5,STONE)
B(-5,0,-5,STONE)
B(-4,0,-5,STONE)
B(-3,0,-5,STONE)
B(-2,0,-5,STONE)
B(-1,0,-5,STONE)
B(0,0,-5,STONE)
B(1,0,-5,STONE)
B(2,0,-5,STONE)
B(3,0,-5,STONE)
B(4,0,-5,STONE)
B(5,0,-5,STONE)
B(6,0,-5,STONE)
B(7,0,-5,STONE)
B(-7,0,-4,STONE)
B(-6,0,-4,STONE)
B(-5,0,-4,STONE)
B(-4,0,-4,STONE)
B(-3,0,-4,STONE)
B(-2,0,-4,STONE)
B(-1,0,-4,STONE)
B(0,0,-4,STONE)
B(1,0,-4,STONE)
B(2,0,-4,STONE)
B(3,0,-4,STONE)
B(4,0,-4,STONE)
B(5,0,-4,STONE)
B(6,0,-4,STONE)
B(7,0,-4,STONE)
B(-7,0,-3,STONE)
B(-6,0,-3,STONE)
B(-5,0,-3,STONE)
B(-4,0,-3,STONE)
B(-3,0,-3,STONE)
B(-2,0,-3,STONE)
B(-1,0,-3,STONE)
B(0,0,-3,STONE)
B(1,0,-3,STONE)
B(2,0,-3,STONE)
B(3,0,-3,STONE)
B(4,0,-3,STONE)
B(5,0,-3,STONE)
B(6,0,-3,STONE)
B(7,0,-3,STONE)
B(-3,0,-2,STONE)
B(-2,0,-2,STONE)
B(-1,0,-2,STONE)
B(0,0,-2,STONE)
B(1,0,-2,STONE)
B(2,0,-2,STONE)
B(3,0,-2,STONE)
B(4,0,-2,STONE)
B(5,0,-2,STONE)
B(6,0,-2,STONE)
B(7,0,-2,STONE)
B(-1,0,-1,STONE)
B(0,0,-1,STONE)
B(1,0,-1,STONE)
B(2,0,-1,STONE)
B(3,0,-1,STONE)
B(4,0,-1,STONE)
B(5,0,-1,STONE)
B(6,0,-1,STONE)
B(7,0,-1,STONE)
B(0,0,0,STONE)
B(1,0,0,STONE)
B(2,0,0,STONE)
B(3,0,0,STONE)
B(4,0,0,STONE)
B(5,0,0,STONE)
B(6,0,0,STONE)
B(7,0,0,STONE)
B(2,0,1,STONE)
B(3,0,1,STONE)
B(4,0,1,STONE)
B(5,0,1,STONE)
B(6,0,1,STONE)
B(7,0,1,STONE)
B(2,0,2,STONE)
B(3,0,2,STONE)
B(4,0,2,STONE)
B(5,0,2,STONE)
B(6,0,2,STONE)
B(7,0,2,STONE)
B(2,0,3,STONE)
B(3,0,3,STONE)
B(4,0,3,STONE)
B(5,0,3,STONE)
B(6,0,3,STONE)
B(7,0,3,STONE)
B(5,0,4,STONE)
B(6,0,4,STONE)
B(7,0,4,STONE)
B(-8,1,-8,STONE)
B(-7,1,-8,STONE)
B(-6,1,-8,STONE)
B(-5,1,-8,STONE)
B(-4,1,-8,STONE)
B(-3,1,-8,STONE)
B(-2,1,-8,STONE)
B(-1,1,-8,STONE)
B(0,1,-8,STONE)
B(1,1,-8,STONE)
B(2,1,-8,STONE)
B(3,1,-8,STONE)
B(4,1,-8,STONE)
B(5,1,-8,STONE)
B(6,1,-8,STONE)
B(7,1,-8,STONE)
B(-8,1,-7,STONE)
B(-7,1,-7,STONE)
B(-6,1,-7,STONE)
B(-5,1,-7,STONE)
B(-4,1,-7,STONE)
B(-3,1,-7,STONE)
B(-2,1,-7,STONE)
B(-1,1,-7,STONE)
B(0,1,-7,STONE)
B(1,1,-7,STONE)
B(2,1,-7,STONE)
B(3,1,-7,STONE)
B(4,1,-7,STONE)
B(5,1,-7,STONE)
B(6,1,-7,STONE)
B(7,1,-7,STONE)
B(-8,1,-6,STONE)
B(-7,1,-6,STONE)
B(-6,1,-6,STONE)
B(-5,1,-6,STONE)
B(-4,1,-6,STONE)
B(-3,1,-6,STONE)
B(-2,1,-6,STONE)
B(-1,1,-6,STONE)
B(0,1,-6,STONE)
B(1,1,-6,STONE)
B(2,1,-6,STONE)
B(3,1,-6,STONE)
B(4,1,-6,STONE)
B(5,1,-6,STONE)
B(6,1,-6,STONE)
B(7,1,-6,STONE)
B(-8,1,-5,STONE)
B(-7,1,-5,STONE)
B(-6,1,-5,STONE)
B(-5,1,-5,STONE)
B(-4,1,-5,STONE)
B(-3,1,-5,STONE)
B(-2,1,-5,STONE)
B(-1,1,-5,STONE)
B(0,1,-5,STONE)
B(1,1,-5,STONE)
B(2,1,-5,STONE)
B(3,1,-5,STONE)
B(4,1,-5,STONE)
B(5,1,-5,STONE)
B(6,1,-5,STONE)
B(7,1,-5,STONE)
B(-6,1,-4,STONE)
B(-5,1,-4,STONE)
B(-4,1,-4,STONE)
B(-3,1,-4,STONE)
B(-2,1,-4,STONE)
B(-1,1,-4,STONE)
B(0,1,-4,STONE)
B(1,1,-4,STONE)
B(2,1,-4,STONE)
B(3,1,-4,STONE)
B(4,1,-4,STONE)
B(5,1,-4,STONE)
B(6,1,-4,STONE)
B(7,1,-4,STONE)
B(-4,1,-3,STONE)
B(-3,1,-3,STONE)
B(-2,1,-3,STONE)
B(-1,1,-3,STONE)
B(0,1,-3,STONE)
B(1,1,-3,STONE)
B(2,1,-3,STONE)
B(3,1,-3,STONE)
B(4,1,-3,STONE)
B(5,1,-3,STONE)
B(6,1,-3,STONE)
B(7,1,-3,STONE)
B(-3,1,-2,STONE)
B(-2,1,-2,STONE)
B(-1,1,-2,STONE)
B(0,1,-2,STONE)
B(1,1,-2,STONE)
B(2,1,-2,STONE)
B(3,1,-2,STONE)
B(4,1,-2,STONE)
B(5,1,-2,STONE)
B(6,1,-2,STONE)
B(7,1,-2,STONE)
B(-1,1,-1,STONE)
B(0,1,-1,STONE)
B(1,1,-1,STONE)
B(2,1,-1,STONE)
B(3,1,-1,STONE)
B(4,1,-1,STONE)
B(5,1,-1,STONE)
B(6,1,-1,STONE)
B(7,1,-1,STONE)
B(0,1,0,STONE)
B(1,1,0,STONE)
B(2,1,0,STONE)
B(3,1,0,STONE)
B(4,1,0,STONE)
B(5,1,0,STONE)
B(6,1,0,STONE)
B(7,1,0,STONE)
B(2,1,1,STONE)
B(3,1,1,STONE)
B(4,1,1,STONE)
B(5,1,1,STONE)
B(6,1,1,STONE)
B(7,1,1,STONE)
B(2,1,2,STONE)
B(3,1,2,STONE)
B(4,1,2,STONE)
B(5,1,2,STONE)
B(6,1,2,STONE)
B(7,1,2,STONE)
B(2,1,3,STONE)
B(3,1,3,STONE)
B(4,1,3,STONE)
B(5,1,3,STONE)
B(6,1,3,STONE)
B(7,1,3,STONE)
B(7,1,4,STONE)
B(-8,2,-8,STONE)
B(-7,2,-8,STONE)
B(-6,2,-8,STONE)
B(-5,2,-8,STONE)
B(-4,2,-8,STONE)
B(-3,2,-8,STONE)
B(-2,2,-8,STONE)
B(-1,2,-8,STONE)
B(0,2,-8,STONE)
B(1,2,-8,STONE)
B(2,2,-8,STONE)
B(3,2,-8,STONE)
B(4,2,-8,STONE)
B(5,2,-8,STONE)
B(6,2,-8,STONE)
B(7,2,-8,STONE)
B(-8,2,-7,STONE)
B(-7,2,-7,STONE)
B(-6,2,-7,STONE)
B(-5,2,-7,STONE)
B(-4,2,-7,STONE)
B(-3,2,-7,STONE)
B(-2,2,-7,STONE)
B(-1,2,-7,STONE)
B(0,2,-7,STONE)
B(1,2,-7,STONE)
B(2,2,-7,STONE)
B(3,2,-7,STONE)
B(4,2,-7,STONE)
B(5,2,-7,STONE)
B(6,2,-7,STONE)
B(7,2,-7,STONE)
B(-8,2,-6,STONE)
B(-7,2,-6,STONE)
B(-6,2,-6,STONE)
B(-5,2,-6,STONE)
B(-4,2,-6,STONE)
B(-3,2,-6,STONE)
B(-2,2,-6,STONE)
B(-1,2,-6,STONE)
B(0,2,-6,STONE)
B(1,2,-6,STONE)
B(2,2,-6,STONE)
B(3,2,-6,STONE)
B(4,2,-6,STONE)
B(5,2,-6,STONE)
B(6,2,-6,STONE)
B(7,2,-6,STONE)
B(-6,2,-5,STONE)
B(-5,2,-5,STONE)
B(-4,2,-5,STONE)
B(-3,2,-5,STONE)
B(-2,2,-5,STONE)
B(-1,2,-5,STONE)
B(0,2,-5,STONE)
B(1,2,-5,STONE)
B(2,2,-5,STONE)
B(3,2,-5,STONE)
B(4,2,-5,STONE)
B(5,2,-5,STONE)
B(6,2,-5,STONE)
B(7,2,-5,STONE)
B(-5,2,-4,STONE)
B(-4,2,-4,STONE)
B(-3,2,-4,STONE)
B(-2,2,-4,STONE)
B(-1,2,-4,STONE)
B(0,2,-4,STONE)
B(1,2,-4,STONE)
B(2,2,-4,STONE)
B(3,2,-4,STONE)
B(4,2,-4,STONE)
B(5,2,-4,STONE)
B(6,2,-4,STONE)
B(7,2,-4,STONE)
B(-3,2,-3,STONE)
B(-2,2,-3,STONE)
B(-1,2,-3,STONE)
B(0,2,-3,STONE)
B(1,2,-3,STONE)
B(2,2,-3,STONE)
B(3,2,-3,STONE)
B(4,2,-3,STONE)
B(5,2,-3,STONE)
B(6,2,-3,STONE)
B(7,2,-3,STONE)
B(-2,2,-2,STONE)
B(-1,2,-2,STONE)
B(0,2,-2,STONE)
B(1,2,-2,STONE)
B(2,2,-2,STONE)
B(3,2,-2,STONE)
B(4,2,-2,STONE)
B(5,2,-2,STONE)
B(6,2,-2,STONE)
B(7,2,-2,STONE)
B(-1,2,-1,STONE)
B(0,2,-1,STONE)
B(1,2,-1,STONE)
B(2,2,-1,STONE)
B(3,2,-1,STONE)
B(4,2,-1,STONE)
B(5,2,-1,STONE)
B(6,2,-1,STONE)
B(7,2,-1,STONE)
B(1,2,0,STONE)
B(2,2,0,STONE)
B(3,2,0,STONE)
B(4,2,0,STONE)
B(5,2,0,STONE)
B(6,2,0,STONE)
B(7,2,0,STONE)
B(2,2,1,STONE)
B(3,2,1,STONE)
B(4,2,1,STONE)
B(5,2,1,STONE)
B(6,2,1,STONE)
B(7,2,1,STONE)
B(2,2,2,STONE)
B(3,2,2,STONE)
B(4,2,2,STONE)
B(5,2,2,STONE)
B(6,2,2,STONE)
B(7,2,2,STONE)
B(3,2,3,STONE)
B(4,2,3,STONE)
B(5,2,3,STONE)
B(6,2,3,STONE)
B(7,2,3,STONE)
B(-8,3,-8,STONE)
B(-7,3,-8,STONE)
B(-6,3,-8,STONE)
B(-5,3,-8,STONE)
B(-4,3,-8,STONE)
B(-3,3,-8,STONE)
B(-2,3,-8,STONE)
B(-1,3,-8,STONE)
B(0,3,-8,STONE)
B(1,3,-8,STONE)
B(2,3,-8,STONE)
B(3,3,-8,STONE)
B(4,3,-8,STONE)
B(5,3,-8,STONE)
B(6,3,-8,STONE)
B(7,3,-8,STONE)
B(-8,3,-7,STONE)
B(-7,3,-7,STONE)
B(-6,3,-7,STONE)
B(-5,3,-7,STONE)
B(-4,3,-7,STONE)
B(-3,3,-7,STONE)
B(-2,3,-7,STONE)
B(-1,3,-7,STONE)
B(0,3,-7,STONE)
B(1,3,-7,STONE)
B(2,3,-7,STONE)
B(3,3,-7,STONE)
B(4,3,-7,STONE)
B(5,3,-7,STONE)
B(6,3,-7,STONE)
B(7,3,-7,STONE)
B(-6,3,-6,STONE)
B(-5,3,-6,STONE)
B(-4,3,-6,STONE)
B(-3,3,-6,STONE)
B(-2,3,-6,STONE)
B(-1,3,-6,STONE)
B(0,3,-6,STONE)
B(1,3,-6,STONE)
B(2,3,-6,STONE)
B(3,3,-6,STONE)
B(4,3,-6,STONE)
B(5,3,-6,STONE)
B(6,3,-6,STONE)
B(7,3,-6,STONE)
B(-5,3,-5,STONE)
B(-4,3,-5,STONE)
B(-3,3,-5,STONE)
B(-2,3,-5,STONE)
B(-1,3,-5,STONE)
B(0,3,-5,STONE)
B(1,3,-5,STONE)
B(2,3,-5,STONE)
B(3,3,-5,STONE)
B(4,3,-5,STONE)
B(5,3,-5,STONE)
B(6,3,-5,STONE)
B(7,3,-5,STONE)
B(-4,3,-4,STONE)
B(-3,3,-4,STONE)
B(-2,3,-4,STONE)
B(-1,3,-4,STONE)
B(0,3,-4,STONE)
B(1,3,-4,STONE)
B(2,3,-4,STONE)
B(3,3,-4,STONE)
B(4,3,-4,STONE)
B(5,3,-4,STONE)
B(6,3,-4,STONE)
B(7,3,-4,STONE)
B(-2,3,-3,STONE)
B(-1,3,-3,STONE)
B(0,3,-3,STONE)
B(1,3,-3,STONE)
B(2,3,-3,STONE)
B(3,3,-3,STONE)
B(4,3,-3,STONE)
B(5,3,-3,STONE)
B(6,3,-3,STONE)
B(7,3,-3,STONE)
B(-1,3,-2,STONE)
B(0,3,-2,STONE)
B(1,3,-2,STONE)
B(2,3,-2,STONE)
B(3,3,-2,STONE)
B(4,3,-2,STONE)
B(5,3,-2,STONE)
B(6,3,-2,STONE)
B(7,3,-2,STONE)
B(-1,3,-1,STONE)
B(0,3,-1,STONE)
B(1,3,-1,STONE)
B(2,3,-1,STONE)
B(3,3,-1,STONE)
B(4,3,-1,STONE)
B(5,3,-1,STONE)
B(6,3,-1,STONE)
B(7,3,-1,STONE)
B(1,3,0,STONE)
B(2,3,0,STONE)
B(3,3,0,STONE)
B(4,3,0,STONE)
B(5,3,0,STONE)
B(6,3,0,STONE)
B(7,3,0,STONE)
B(2,3,1,STONE)
B(3,3,1,STONE)
B(4,3,1,STONE)
B(5,3,1,STONE)
B(6,3,1,STONE)
B(7,3,1,STONE)
B(4,3,2,STONE)
B(5,3,2,STONE)
B(6,3,2,STONE)
B(7,3,2,STONE)
B(5,3,3,STONE)
B(6,3,3,STONE)
B(7,3,3,STONE)
B(-5,4,-8,STONE)
B(-4,4,-8,STONE)
B(-3,4,-8,STONE)
B(-2,4,-8,STONE)
B(-1,4,-8,STONE)
B(0,4,-8,STONE)
B(1,4,-8,STONE)
B(2,4,-8,STONE)
B(3,4,-8,STONE)
B(4,4,-8,STONE)
B(5,4,-8,STONE)
B(6,4,-8,STONE)
B(7,4,-8,STONE)
B(-5,4,-7,STONE)
B(-4,4,-7,STONE)
B(-3,4,-7,STONE)
B(-2,4,-7,STONE)
B(-1,4,-7,STONE)
B(0,4,-7,STONE)
B(1,4,-7,STONE)
B(2,4,-7,STONE)
B(3,4,-7,STONE)
B(4,4,-7,STONE)
B(5,4,-7,STONE)
B(6,4,-7,STONE)
B(7,4,-7,STONE)
B(-5,4,-6,STONE)
B(-4,4,-6,STONE)
B(-3,4,-6,STONE)
B(-2,4,-6,STONE)
B(-1,4,-6,STONE)
B(0,4,-6,STONE)
B(1,4,-6,STONE)
B(2,4,-6,STONE)
B(3,4,-6,STONE)
B(4,4,-6,STONE)
B(5,4,-6,STONE)
B(6,4,-6,STONE)
B(7,4,-6,STONE)
B(-5,4,-5,STONE)
B(-4,4,-5,STONE)
B(-3,4,-5,STONE)
B(-2,4,-5,STONE)
B(-1,4,-5,STONE)
B(0,4,-5,STONE)
B(1,4,-5,STONE)
B(2,4,-5,STONE)
B(3,4,-5,STONE)
B(4,4,-5,STONE)
B(5,4,-5,STONE)
B(6,4,-5,STONE)
B(7,4,-5,STONE)
B(-2,4,-4,STONE)
B(-1,4,-4,STONE)
B(0,4,-4,STONE)
B(1,4,-4,STONE)
B(2,4,-4,STONE)
B(3,4,-4,STONE)
B(4,4,-4,STONE)
B(5,4,-4,STONE)
B(6,4,-4,STONE)
B(7,4,-4,STONE)
B(-1,4,-3,STONE)
B(0,4,-3,STONE)
B(1,4,-3,STONE)
B(2,4,-3,STONE)
B(3,4,-3,STONE)
B(4,4,-3,STONE)
B(5,4,-3,STONE)
B(6,4,-3,STONE)
B(7,4,-3,STONE)
B(-1,4,-2,STONE)
B(0,4,-2,STONE)
B(1,4,-2,STONE)
B(2,4,-2,STONE)
B(3,4,-2,STONE)
B(4,4,-2,STONE)
B(5,4,-2,STONE)
B(6,4,-2,STONE)
B(7,4,-2,STONE)
B(0,4,-1,STONE)
B(1,4,-1,STONE)
B(2,4,-1,STONE)
B(3,4,-1,STONE)
B(4,4,-1,STONE)
B(5,4,-1,STONE)
B(6,4,-1,STONE)
B(7,4,-1,STONE)
B(1,4,0,STONE)
B(2,4,0,STONE)
B(3,4,0,STONE)
B(4,4,0,STONE)
B(5,4,0,STONE)
B(6,4,0,STONE)
B(7,4,0,STONE)
B(4,4,1,STONE)
B(5,4,1,STONE)
B(6,4,1,STONE)
B(7,4,1,STONE)
B(5,4,2,STONE)
B(6,4,2,STONE)
B(7,4,2,STONE)
B(6,4,3,STONE)
B(7,4,3,STONE)
B(-5,5,-8,STONE)
B(-4,5,-8,STONE)
B(-3,5,-8,STONE)
B(-2,5,-8,STONE)
B(-1,5,-8,STONE)
B(0,5,-8,STONE)
B(1,5,-8,STONE)
B(2,5,-8,STONE)
B(3,5,-8,STONE)
B(4,5,-8,STONE)
B(5,5,-8,STONE)
B(6,5,-8,STONE)
B(7,5,-8,STONE)
B(-4,5,-7,STONE)
B(-3,5,-7,STONE)
B(-2,5,-7,STONE)
B(-1,5,-7,STONE)
B(0,5,-7,STONE)
B(1,5,-7,STONE)
B(2,5,-7,STONE)
B(3,5,-7,STONE)
B(4,5,-7,STONE)
B(5,5,-7,STONE)
B(6,5,-7,STONE)
B(7,5,-7,STONE)
B(-4,5,-6,STONE)
B(-3,5,-6,STONE)
B(-2,5,-6,STONE)
B(-1,5,-6,STONE)
B(0,5,-6,STONE)
B(1,5,-6,STONE)
B(2,5,-6,STONE)
B(3,5,-6,STONE)
B(4,5,-6,STONE)
B(5,5,-6,STONE)
B(6,5,-6,STONE)
B(7,5,-6,STONE)
B(-2,5,-5,STONE)
B(-1,5,-5,STONE)
B(0,5,-5,STONE)
B(1,5,-5,STONE)
B(2,5,-5,STONE)
B(3,5,-5,STONE)
B(4,5,-5,STONE)
B(5,5,-5,STONE)
B(6,5,-5,STONE)
B(7,5,-5,STONE)
B(-1,5,-4,STONE)
B(0,5,-4,STONE)
B(1,5,-4,STONE)
B(2,5,-4,STONE)
B(3,5,-4,STONE)
B(4,5,-4,STONE)
B(5,5,-4,STONE)
B(6,5,-4,STONE)
B(7,5,-4,STONE)
B(-1,5,-3,STONE)
B(0,5,-3,STONE)
B(1,5,-3,STONE)
B(2,5,-3,STONE)
B(3,5,-3,STONE)
B(4,5,-3,STONE)
B(5,5,-3,STONE)
B(6,5,-3,STONE)
B(7,5,-3,STONE)
B(0,5,-2,STONE)
B(1,5,-2,STONE)
B(2,5,-2,STONE)
B(3,5,-2,STONE)
B(4,5,-2,STONE)
B(5,5,-2,STONE)
B(6,5,-2,STONE)
B(7,5,-2,STONE)
B(0,5,-1,STONE)
B(1,5,-1,STONE)
B(2,5,-1,STONE)
B(3,5,-1,STONE)
B(4,5,-1,STONE)
B(5,5,-1,STONE)
B(6,5,-1,STONE)
B(7,5,-1,STONE)
B(3,5,0,STONE)
B(4,5,0,STONE)
B(5,5,0,STONE)
B(6,5,0,STONE)
B(7,5,0,STONE)
B(4,5,1,STONE)
B(5,5,1,STONE)
B(6,5,1,STONE)
B(7,5,1,STONE)
B(6,5,2,STONE)
B(7,5,2,STONE)
B(7,5,3,STONE)
B(-3,6,-8,STONE)
B(-2,6,-8,STONE)
B(-1,6,-8,STONE)
B(0,6,-8,STONE)
B(1,6,-8,STONE)
B(2,6,-8,STONE)
B(3,6,-8,STONE)
B(4,6,-8,STONE)
B(5,6,-8,STONE)
B(6,6,-8,STONE)
B(7,6,-8,STONE)
B(-3,6,-7,STONE)
B(-2,6,-7,STONE)
B(-1,6,-7,STONE)
B(0,6,-7,STONE)
B(1,6,-7,STONE)
B(2,6,-7,STONE)
B(3,6,-7,STONE)
B(4,6,-7,STONE)
B(5,6,-7,STONE)
B(6,6,-7,STONE)
B(7,6,-7,STONE)
B(-2,6,-6,STONE)
B(-1,6,-6,STONE)
B(0,6,-6,STONE)
B(1,6,-6,STONE)
B(2,6,-6,STONE)
B(3,6,-6,STONE)
B(4,6,-6,STONE)
B(5,6,-6,STONE)
B(6,6,-6,STONE)
B(7,6,-6,STONE)
B(-1,6,-5,STONE)
B(0,6,-5,STONE)
B(1,6,-5,STONE)
B(2,6,-5,STONE)
B(3,6,-5,STONE)
B(4,6,-5,STONE)
B(5,6,-5,STONE)
B(6,6,-5,STONE)
B(7,6,-5,STONE)
B(0,6,-4,STONE)
B(1,6,-4,STONE)
B(2,6,-4,STONE)
B(3,6,-4,STONE)
B(4,6,-4,STONE)
B(5,6,-4,STONE)
B(6,6,-4,STONE)
B(7,6,-4,STONE)
B(0,6,-3,STONE)
B(1,6,-3,STONE)
B(2,6,-3,STONE)
B(3,6,-3,STONE)
B(4,6,-3,STONE)
B(5,6,-3,STONE)
B(6,6,-3,STONE)
B(7,6,-3,STONE)
B(1,6,-2,STONE)
B(2,6,-2,STONE)
B(3,6,-2,STONE)
B(4,6,-2,STONE)
B(5,6,-2,STONE)
B(6,6,-2,STONE)
B(7,6,-2,STONE)
B(2,6,-1,STONE)
B(3,6,-1,STONE)
B(4,6,-1,STONE)
B(5,6,-1,STONE)
B(6,6,-1,STONE)
B(7,6,-1,STONE)
B(4,6,0,STONE)
B(5,6,0,STONE)
B(6,6,0,STONE)
B(7,6,0,STONE)
B(5,6,1,STONE)
B(6,6,1,STONE)
B(7,6,1,STONE)
B(7,6,2,STONE)
B(-2,7,-8,STONE)
B(-1,7,-8,STONE)
B(0,7,-8,STONE)
B(1,7,-8,STONE)
B(2,7,-8,STONE)
B(3,7,-8,STONE)
B(4,7,-8,STONE)
B(5,7,-8,STONE)
B(6,7,-8,STONE)
B(7,7,-8,STONE)
B(-2,7,-7,STONE)
B(-1,7,-7,STONE)
B(0,7,-7,STONE)
B(1,7,-7,STONE)
B(2,7,-7,STONE)
B(3,7,-7,STONE)
B(4,7,-7,STONE)
B(5,7,-7,STONE)
B(6,7,-7,STONE)
B(7,7,-7,STONE)
B(-2,7,-6,STONE)
B(-1,7,-6,STONE)
B(0,7,-6,STONE)
B(1,7,-6,STONE)
B(2,7,-6,STONE)
B(3,7,-6,STONE)
B(4,7,-6,STONE)
B(5,7,-6,STONE)
B(6,7,-6,STONE)
B(7,7,-6,STONE)
B(-1,7,-5,STONE)
B(0,7,-5,STONE)
B(1,7,-5,STONE)
B(2,7,-5,STONE)
B(3,7,-5,STONE)
B(4,7,-5,STONE)
B(5,7,-5,STONE)
B(6,7,-5,STONE)
B(7,7,-5,STONE)
B(0,7,-4,STONE)
B(1,7,-4,STONE)
B(2,7,-4,STONE)
B(3,7,-4,STONE)
B(4,7,-4,STONE)
B(5,7,-4,STONE)
B(6,7,-4,STONE)
B(7,7,-4,STONE)
B(1,7,-3,STONE)
B(2,7,-3,STONE)
B(3,7,-3,STONE)
B(4,7,-3,STONE)
B(5,7,-3,STONE)
B(6,7,-3,STONE)
B(7,7,-3,STONE)
B(2,7,-2,STONE)
B(3,7,-2,STONE)
B(4,7,-2,STONE)
B(5,7,-2,STONE)
B(6,7,-2,STONE)
B(7,7,-2,STONE)
B(4,7,-1,STONE)
B(5,7,-1,STONE)
B(6,7,-1,STONE)
B(7,7,-1,STONE)
B(5,7,0,STONE)
B(6,7,0,STONE)
B(7,7,0,STONE)
B(6,7,1,STONE)
B(7,7,1,STONE)
B(-1,8,-8,STONE)
B(0,8,-8,STONE)
B(1,8,-8,STONE)
B(2,8,-8,STONE)
B(3,8,-8,STONE)
B(4,8,-8,STONE)
B(5,8,-8,STONE)
B(6,8,-8,STONE)
B(7,8,-8,STONE)
B(-1,8,-7,STONE)
B(0,8,-7,STONE)
B(1,8,-7,STONE)
B(2,8,-7,STONE)
B(3,8,-7,STONE)
B(4,8,-7,STONE)
B(5,8,-7,STONE)
B(6,8,-7,STONE)
B(7,8,-7,STONE)
B(-1,8,-6,STONE)
B(0,8,-6,STONE)
B(1,8,-6,STONE)
B(2,8,-6,STONE)
B(3,8,-6,STONE)
B(4,8,-6,STONE)
B(5,8,-6,STONE)
B(6,8,-6,STONE)
B(7,8,-6,STONE)
B(-1,8,-5,STONE)
B(0,8,-5,STONE)
B(1,8,-5,STONE)
B(2,8,-5,STONE)
B(3,8,-5,STONE)
B(4,8,-5,STONE)
B(5,8,-5,STONE)
B(6,8,-5,STONE)
B(7,8,-5,STONE)
B(1,8,-4,STONE)
B(2,8,-4,STONE)
B(3,8,-4,STONE)
B(4,8,-4,STONE)
B(5,8,-4,STONE)
B(6,8,-4,STONE)
B(7,8,-4,STONE)
B(2,8,-3,STONE)
B(3,8,-3,STONE)
B(4,8,-3,STONE)
B(5,8,-3,STONE)
B(6,8,-3,STONE)
B(7,8,-3,STONE)
B(3,8,-2,STONE)
B(4,8,-2,STONE)
B(5,8,-2,STONE)
B(6,8,-2,STONE)
B(7,8,-2,STONE)
B(4,8,-1,STONE)
B(5,8,-1,STONE)
B(6,8,-1,STONE)
B(7,8,-1,STONE)
B(5,8,0,STONE)
B(6,8,0,STONE)
B(7,8,0,STONE)
B(6,8,1,STONE)
B(7,8,1,STONE)
B(0,9,-8,STONE)
B(1,9,-8,GRASS)
B(2,9,-8,GRASS)
B(3,9,-8,STONE)
B(4,9,-8,STONE)
B(5,9,-8,STONE)
B(6,9,-8,STONE)
B(7,9,-8,STONE)
B(0,9,-7,STONE)
B(1,9,-7,STONE)
B(2,9,-7,GRASS)
B(3,9,-7,STONE)
B(4,9,-7,STONE)
B(5,9,-7,STONE)
B(6,9,-7,STONE)
B(7,9,-7,STONE)
B(0,9,-6,STONE)
B(1,9,-6,STONE)
B(2,9,-6,STONE)
B(3,9,-6,STONE)
B(4,9,-6,STONE)
B(5,9,-6,STONE)
B(6,9,-6,STONE)
B(7,9,-6,STONE)
B(2,9,-5,STONE)
B(3,9,-5,GRASS)
B(4,9,-5,STONE)
B(5,9,-5,STONE)
B(6,9,-5,STONE)
B(7,9,-5,STONE)
B(3,9,-4,GRASS)
B(4,9,-4,STONE)
B(5,9,-4,STONE)
B(6,9,-4,STONE)
B(7,9,-4,STONE)
B(3,9,-3,STONE)
B(4,9,-3,STONE)
B(5,9,-3,STONE)
B(6,9,-3,STONE)
B(7,9,-3,STONE)
B(4,9,-2,GRASS)
B(5,9,-2,STONE)
B(6,9,-2,STONE)
B(7,9,-2,STONE)
B(4,9,-1,STONE)
B(5,9,-1,STONE)
B(6,9,-1,STONE)
B(7,9,-1,STONE)
B(5,9,0,STONE)
B(6,9,0,STONE)
B(7,9,0,STONE)
B(7,9,1,STONE)
B(3,10,-8,GRASS)
B(4,10,-8,STONE)
B(5,10,-8,STONE)
B(6,10,-8,STONE)
B(7,10,-8,STONE)
B(3,10,-7,GRASS)
B(4,10,-7,STONE)
B(5,10,-7,STONE)
B(6,10,-7,STONE)
B(7,10,-7,STONE)
B(3,10,-6,GRASS)
B(4,10,-6,GRASS)
B(5,10,-6,STONE)
B(6,10,-6,STONE)
B(7,10,-6,STONE)
B(4,10,-5,GRASS)
B(5,10,-5,STONE)
B(6,10,-5,STONE)
B(7,10,-5,STONE)
B(4,10,-4,GRASS)
B(5,10,-4,STONE)
B(6,10,-4,STONE)
B(7,10,-4,STONE)
B(4,10,-3,GRASS)
B(5,10,-3,STONE)
B(6,10,-3,STONE)
B(7,10,-3,STONE)
B(5,10,-2,STONE)
B(6,10,-2,STONE)
B(7,10,-2,STONE)
B(5,10,-1,STONE)
B(6,10,-1,STONE)
B(7,10,-1,STONE)
B(6,10,0,STONE)
B(7,10,0,STONE)
B(7,10,1,STONE)
B(4,11,-8,GRASS)
B(5,11,-8,GRASS)
B(6,11,-8,STONE)
B(7,11,-8,STONE)
B(4,11,-7,GRASS)
B(5,11,-7,GRASS)
B(6,11,-7,GRASS)
B(7,11,-7,STONE)
B(5,11,-6,GRASS)
B(6,11,-6,STONE)
B(7,11,-6,STONE)
B(5,11,-5,STONE)
B(6,11,-5,STONE)
B(7,11,-5,STONE)
B(5,11,-4,STONE)
B(6,11,-4,STONE)
B(7,11,-4,STONE)
B(5,11,-3,STONE)
B(6,11,-3,STONE)
B(7,11,-3,STONE)
B(5,11,-2,STONE)
B(6,11,-2,STONE)
B(7,11,-2,STONE)
B(5,11,-1,GRASS)
B(6,11,-1,STONE)
B(7,11,-1,STONE)
B(6,11,0,STONE)
B(7,11,0,STONE)
B(7,11,1,STONE)
B(6,12,-8,GRASS)
B(7,12,-8,STONE)
B(7,12,-7,STONE)
B(6,12,-6,GRASS)
B(7,12,-6,STONE)
B(5,12,-5,GRASS)
B(6,12,-5,STONE)
B(7,12,-5,STONE)
B(5,12,-4,GRASS)
B(6,12,-4,STONE)
B(7,12,-4,STONE)
B(5,12,-3,GRASS)
B(6,12,-3,STONE)
B(7,12,-3,STONE)
B(5,12,-2,GRASS)
B(6,12,-2,STONE)
B(7,12,-2,STONE)
B(6,12,-1,STONE)
B(7,12,-1,STONE)
B(6,12,0,STONE)
B(7,12,0,STONE)
B(7,13,-8,GRASS)
B(7,13,-7,GRASS)
B(7,13,-6,GRASS)
B(6,13,-5,GRASS)
B(7,13,-5,STONE)
B(6,13,-4,GRASS)
B(7,13,-4,STONE)
B(6,13,-3,GRASS)
B(7,13,-3,STONE)
B(6,13,-2,GRASS)
B(7,13,-2,STONE)
B(6,13,-1,STONE)
B(7,13,-1,STONE)
B(6,13,0,GRASS)
B(7,13,0,GRASS)
B(7,14,-5,GRASS)
B(7,14,-4,GRASS)
B(7,14,-3,GRASS)
B(7,14,-2,GRASS)
B(6,14,-1,GRASS)
B(7,14,-1,GRASS)

#######################################################################
# +-----------------------------------------------------------------+ #
# |                             Branches                            | #
# +-----------------------------------------------------------------+ #
#######################################################################

BR(-16,0,0,Quarry_0x8,NORTH,100)
