#######################################################################
# +-----------------------------------------------------------------+ #
# |                            BO3 object                           | #
# +-----------------------------------------------------------------+ #
#######################################################################

# This is the config file of a custom object.
# If you add this object correctly to your BiomeConfigs, it will spawn in the world.

# This is the creator of this BO3 object
Author: BO3 BulkEdit (by LanToaster)

# A short description of this BO3 object
Description: This Object was Created with BO3_BulkEdit

# The BO3 version, don't change this! It can be used by external applications to do a version check.
Version: 3

# The settings mode, WriteAll, WriteWithoutComments or WriteDisable. See WorldConfig.
SettingsMode: WriteDisable


#######################################################################
# +-----------------------------------------------------------------+ #
# |                          Main settings                          | #
# +-----------------------------------------------------------------+ #
#######################################################################

# This needs to be set to true to spawn the object in the Tree and Sapling resources.
Tree: false

# The frequency of the BO3 from 1 to 200. Tries this many times to spawn this BO3 when using the CustomObject(...) resource.

Frequency: 1

# The rarity of the BO3 from 0 to 100. Each spawn attempt has rarity% chance to succeed when using the CustomObject(...) resource.

Rarity: 100.0

# If you set this to true, the BO3 will be placed with a random rotation.
RotateRandomly: false

# The spawn height of the BO3 - randomY, highestBlock or highestSolidBlock.
SpawnHeight: highestBlock

# The height limits for the BO3.
MinHeight: 0

MaxHeight: 256

# Objects can have other objects attacthed to it: branches. Branches can also
# have branches attached to it, which can also have branches, etc. This is the
# maximum branch depth for this objects.
MaxBranchDepth: 10

# When spawned with the UseWorld keyword, this BO3 should NOT spawn in the following biomes.
# If you writer.write the BO3 name directly in the BiomeConfigs, this will be ignored.
ExcludedBiomes: All


#######################################################################
# +-----------------------------------------------------------------+ #
# |                      Source block settings                      | #
# +-----------------------------------------------------------------+ #
#######################################################################

# The block(s) the BO3 should spawn in.
SourceBlocks: AIR

# The maximum percentage of the BO3 that can be outside the SourceBlock.
# The BO3 won't be placed on a location with more blocks outside the SourceBlock than this percentage.
MaxPercentageOutsideSourceBlock: 100

# What to do when a block is about to be placed outside the SourceBlock? (dontPlace, placeAnyway)
OutsideSourceBlock: placeAnyway


#######################################################################
# +-----------------------------------------------------------------+ #
# |                              Blocks                             | #
# +-----------------------------------------------------------------+ #
#######################################################################

# All the blocks used in the BO3 are listed here. Possible blocks:
# Block(x,y,z,id[.data][,nbtfile.nbt)
# RandomBlock(x,y,z,id[:data][,nbtfile.nbt],chance[,id[:data][,nbtfile.nbt],chance[,...]])
# So RandomBlock(0,0,0,CHEST,chest.nbt,50,CHEST,anotherchest.nbt,100) will spawn a chest at
# the BO3 origin, and give it a 50% chance to have the contents of chest.nbt, or, if that
# fails, a 100% percent chance to have the contents of anotherchest.nbt.
Block(8,3,8,STAINED_GLASS:15)
Block(8,4,6,STAINED_GLASS:11)
Block(8,4,7,STAINED_GLASS:11)
Block(7,4,8,STAINED_GLASS:11)
Block(8,4,8,STAINED_GLASS:11)
Block(8,5,3,STAINED_GLASS:15)
Block(7,5,4,STAINED_GLASS:11)
Block(8,5,4,STAINED_GLASS:15)
Block(6,5,5,STAINED_GLASS:11)
Block(7,5,5,STAINED_GLASS:11)
Block(8,5,5,STAINED_GLASS:11)
Block(6,5,6,STAINED_GLASS:11)
Block(7,5,6,STAINED_GLASS:11)
Block(8,5,6,STAINED_GLASS:11)
Block(7,5,7,STAINED_GLASS:11)
Block(8,5,7,STAINED_GLASS:11)
Block(7,5,8,STAINED_GLASS:11)
Block(8,5,8,STAINED_GLASS:11)
Block(8,6,1,STAINED_GLASS:15)
Block(6,6,2,STAINED_GLASS:15)
Block(7,6,2,STAINED_GLASS:15)
Block(8,6,2,STAINED_GLASS:15)
Block(5,6,3,STAINED_GLASS:11)
Block(6,6,3,STAINED_GLASS:11)
Block(7,6,3,STAINED_GLASS:15)
Block(8,6,3,STAINED_GLASS:15)
Block(5,6,4,STAINED_GLASS:11)
Block(6,6,4,STAINED_GLASS:11)
Block(7,6,4,STAINED_GLASS:11)
Block(8,6,4,STAINED_GLASS:2)
Block(5,6,5,STAINED_GLASS:11)
Block(6,6,5,STAINED_GLASS:11)
Block(7,6,5,STAINED_GLASS:11)
Block(8,6,5,STAINED_GLASS:11)
Block(6,6,6,STAINED_GLASS:11)
Block(7,6,6,STAINED_GLASS:11)
Block(8,6,6,STAINED_GLASS:11)
Block(7,6,7,STAINED_GLASS:11)
Block(8,6,7,STAINED_GLASS:11)
Block(7,6,8,STAINED_GLASS:11)
Block(8,6,8,STAINED_GLASS:11)
Block(7,7,-1,STAINED_GLASS:15)
Block(8,7,-1,STAINED_GLASS:15)
Block(6,7,0,STAINED_GLASS:15)
Block(7,7,0,STAINED_GLASS:15)
Block(8,7,0,STAINED_GLASS:15)
Block(5,7,1,STAINED_GLASS:11)
Block(6,7,1,STAINED_GLASS:15)
Block(7,7,1,STAINED_GLASS:15)
Block(8,7,1,STAINED_GLASS:15)
Block(3,7,2,STAINED_GLASS:11)
Block(4,7,2,STAINED_GLASS:11)
Block(5,7,2,STAINED_GLASS:11)
Block(6,7,2,STAINED_GLASS:2)
Block(7,7,2,STAINED_GLASS:15)
Block(8,7,2,STAINED_GLASS:15)
Block(4,7,3,STAINED_GLASS:11)
Block(5,7,3,STAINED_GLASS:11)
Block(6,7,3,STAINED_GLASS:11)
Block(7,7,3,STAINED_GLASS:2)
Block(8,7,3,STAINED_GLASS:15)
Block(4,7,4,STAINED_GLASS:11)
Block(5,7,4,STAINED_GLASS:11)
Block(6,7,4,STAINED_GLASS:11)
Block(7,7,4,STAINED_GLASS:11)
Block(8,7,4,SEA_LANTERN:0)
Block(5,7,5,STAINED_GLASS:11)
Block(6,7,5,STAINED_GLASS:11)
Block(7,7,5,STAINED_GLASS:2)
Block(8,7,5,STAINED_GLASS:2)
Block(6,7,6,STAINED_GLASS:11)
Block(7,7,6,STAINED_GLASS:11)
Block(8,7,6,STAINED_GLASS:2)
Block(7,7,7,STAINED_GLASS:11)
Block(8,7,7,STAINED_GLASS:2)
Block(7,7,8,STAINED_GLASS:11)
Block(8,7,8,STAINED_GLASS:10)
Block(5,8,-2,STAINED_GLASS:15)
Block(6,8,-2,STAINED_GLASS:15)
Block(7,8,-2,STAINED_GLASS:11)
Block(3,8,-1,STAINED_GLASS:11)
Block(4,8,-1,STAINED_GLASS:15)
Block(5,8,-1,STAINED_GLASS:15)
Block(6,8,-1,STAINED_GLASS:15)
Block(7,8,-1,STAINED_GLASS:11)
Block(8,8,-1,STAINED_GLASS:11)
Block(3,8,0,STAINED_GLASS:11)
Block(4,8,0,STAINED_GLASS:11)
Block(5,8,0,STAINED_GLASS:15)
Block(6,8,0,STAINED_GLASS:15)
Block(7,8,0,STAINED_GLASS:11)
Block(8,8,0,STAINED_GLASS:11)
Block(3,8,1,STAINED_GLASS:11)
Block(4,8,1,STAINED_GLASS:11)
Block(5,8,1,STAINED_GLASS:11)
Block(6,8,1,STAINED_GLASS:2)
Block(7,8,1,STAINED_GLASS:15)
Block(8,8,1,STAINED_GLASS:15)
Block(3,8,2,STAINED_GLASS:11)
Block(4,8,2,STAINED_GLASS:11)
Block(5,8,2,STAINED_GLASS:11)
Block(6,8,2,STAINED_GLASS:2)
Block(7,8,2,STAINED_GLASS:2)
Block(8,8,2,STAINED_GLASS:2)
Block(4,8,3,STAINED_GLASS:11)
Block(5,8,3,STAINED_GLASS:11)
Block(6,8,3,STAINED_GLASS:2)
Block(7,8,3,SEA_LANTERN:0)
Block(8,8,3,STAINED_GLASS:2)
Block(4,8,4,STAINED_GLASS:11)
Block(5,8,4,STAINED_GLASS:11)
Block(6,8,4,STAINED_GLASS:2)
Block(7,8,4,STAINED_GLASS:2)
Block(8,8,4,SEA_LANTERN:0)
Block(5,8,5,STAINED_GLASS:11)
Block(6,8,5,STAINED_GLASS:11)
Block(7,8,5,STAINED_GLASS:15)
Block(8,8,5,SEA_LANTERN:0)
Block(6,8,6,STAINED_GLASS:11)
Block(7,8,6,STAINED_GLASS:10)
Block(8,8,6,STAINED_GLASS:15)
Block(7,8,7,STAINED_GLASS:15)
Block(8,8,7,STAINED_GLASS:15)
Block(7,8,8,STAINED_GLASS:15)
Block(8,8,8,STAINED_GLASS:11)
Block(3,9,-4,STAINED_GLASS:15)
Block(4,9,-4,STAINED_GLASS:15)
Block(5,9,-4,STAINED_GLASS:11)
Block(2,9,-3,STAINED_GLASS:15)
Block(3,9,-3,STAINED_GLASS:15)
Block(4,9,-3,STAINED_GLASS:15)
Block(5,9,-3,STAINED_GLASS:11)
Block(6,9,-3,STAINED_GLASS:11)
Block(1,9,-2,STAINED_GLASS:15)
Block(2,9,-2,STAINED_GLASS:15)
Block(3,9,-2,STAINED_GLASS:15)
Block(4,9,-2,STAINED_GLASS:15)
Block(5,9,-2,STAINED_GLASS:11)
Block(6,9,-2,STAINED_GLASS:11)
Block(7,9,-2,STAINED_GLASS:11)
Block(1,9,-1,STAINED_GLASS:2)
Block(2,9,-1,STAINED_GLASS:11)
Block(3,9,-1,STAINED_GLASS:11)
Block(4,9,-1,STAINED_GLASS:2)
Block(5,9,-1,STAINED_GLASS:15)
Block(6,9,-1,STAINED_GLASS:11)
Block(7,9,-1,STAINED_GLASS:11)
Block(8,9,-1,STAINED_GLASS:11)
Block(2,9,0,STAINED_GLASS:11)
Block(3,9,0,STAINED_GLASS:11)
Block(4,9,0,STAINED_GLASS:11)
Block(5,9,0,STAINED_GLASS:2)
Block(6,9,0,STAINED_GLASS:11)
Block(7,9,0,STAINED_GLASS:2)
Block(8,9,0,STAINED_GLASS:11)
Block(3,9,1,STAINED_GLASS:11)
Block(4,9,1,STAINED_GLASS:11)
Block(5,9,1,STAINED_GLASS:11)
Block(6,9,1,STAINED_GLASS:15)
Block(7,9,1,STAINED_GLASS:2)
Block(8,9,1,STAINED_GLASS:2)
Block(3,9,2,STAINED_GLASS:11)
Block(4,9,2,STAINED_GLASS:2)
Block(5,9,2,STAINED_GLASS:2)
Block(6,9,2,SEA_LANTERN:0)
Block(7,9,2,STAINED_GLASS:15)
Block(8,9,2,STAINED_GLASS:15)
Block(4,9,3,STAINED_GLASS:11)
Block(5,9,3,STAINED_GLASS:2)
Block(6,9,3,SEA_LANTERN:0)
Block(7,9,3,SEA_LANTERN:0)
Block(8,9,3,STAINED_GLASS:15)
Block(4,9,4,STAINED_GLASS:11)
Block(5,9,4,STAINED_GLASS:2)
Block(6,9,4,STAINED_GLASS:15)
Block(7,9,4,SEA_LANTERN:0)
Block(8,9,4,SEA_LANTERN:0)
Block(5,9,5,STAINED_GLASS:15)
Block(6,9,5,STAINED_GLASS:2)
Block(7,9,5,STAINED_GLASS:10)
Block(8,9,5,STAINED_GLASS:2)
Block(6,9,6,STAINED_GLASS:15)
Block(7,9,6,STAINED_GLASS:11)
Block(8,9,6,STAINED_GLASS:10)
Block(7,9,7,STAINED_GLASS:15)
Block(8,9,7,STAINED_GLASS:11)
Block(7,9,8,STAINED_GLASS:11)
Block(8,9,8,STAINED_GLASS:11)
Block(3,10,-6,STAINED_GLASS:15)
Block(2,10,-5,STAINED_GLASS:15)
Block(3,10,-5,STAINED_GLASS:15)
Block(4,10,-5,STAINED_GLASS:15)
Block(5,10,-5,STAINED_GLASS:15)
Block(0,10,-4,STAINED_GLASS:2)
Block(1,10,-4,STAINED_GLASS:15)
Block(2,10,-4,STAINED_GLASS:15)
Block(3,10,-4,STAINED_GLASS:15)
Block(4,10,-4,STAINED_GLASS:11)
Block(5,10,-4,STAINED_GLASS:11)
Block(0,10,-3,STAINED_GLASS:2)
Block(1,10,-3,STAINED_GLASS:2)
Block(2,10,-3,STAINED_GLASS:15)
Block(3,10,-3,STAINED_GLASS:2)
Block(4,10,-3,STAINED_GLASS:11)
Block(5,10,-3,STAINED_GLASS:11)
Block(6,10,-3,STAINED_GLASS:11)
Block(0,10,-2,STAINED_GLASS:2)
Block(1,10,-2,STAINED_GLASS:2)
Block(2,10,-2,STAINED_GLASS:2)
Block(3,10,-2,STAINED_GLASS:11)
Block(4,10,-2,STAINED_GLASS:11)
Block(5,10,-2,STAINED_GLASS:11)
Block(6,10,-2,STAINED_GLASS:11)
Block(7,10,-2,STAINED_GLASS:11)
Block(1,10,-1,STAINED_GLASS:2)
Block(2,10,-1,STAINED_GLASS:2)
Block(3,10,-1,STAINED_GLASS:11)
Block(4,10,-1,STAINED_GLASS:2)
Block(5,10,-1,STAINED_GLASS:2)
Block(6,10,-1,STAINED_GLASS:2)
Block(7,10,-1,STAINED_GLASS:11)
Block(8,10,-1,STAINED_GLASS:11)
Block(2,10,0,STAINED_GLASS:2)
Block(3,10,0,STAINED_GLASS:11)
Block(4,10,0,STAINED_GLASS:2)
Block(5,10,0,SEA_LANTERN:0)
Block(6,10,0,STAINED_GLASS:2)
Block(7,10,0,STAINED_GLASS:15)
Block(8,10,0,STAINED_GLASS:10)
Block(3,10,1,STAINED_GLASS:2)
Block(4,10,1,STAINED_GLASS:2)
Block(5,10,1,STAINED_GLASS:2)
Block(6,10,1,SEA_LANTERN:0)
Block(7,10,1,SEA_LANTERN:0)
Block(8,10,1,STAINED_GLASS:15)
Block(3,10,2,STAINED_GLASS:2)
Block(4,10,2,STAINED_GLASS:15)
Block(5,10,2,SEA_LANTERN:0)
Block(6,10,2,SEA_LANTERN:0)
Block(7,10,2,STAINED_GLASS:2)
Block(8,10,2,STAINED_GLASS:2)
Block(4,10,3,STAINED_GLASS:2)
Block(5,10,3,STAINED_GLASS:15)
Block(6,10,3,STAINED_GLASS:2)
Block(7,10,3,STAINED_GLASS:15)
Block(8,10,3,STAINED_GLASS:2)
Block(4,10,4,STAINED_GLASS:11)
Block(5,10,4,STAINED_GLASS:15)
Block(6,10,4,STAINED_GLASS:2)
Block(7,10,4,STAINED_GLASS:2)
Block(8,10,4,STAINED_GLASS:15)
Block(5,10,5,STAINED_GLASS:15)
Block(6,10,5,STAINED_GLASS:11)
Block(7,10,5,STAINED_GLASS:2)
Block(8,10,5,STAINED_GLASS:11)
Block(6,10,6,STAINED_GLASS:11)
Block(7,10,6,STAINED_GLASS:11)
Block(8,10,6,STAINED_GLASS:11)
Block(7,10,7,STAINED_GLASS:11)
Block(8,10,7,STAINED_GLASS:11)
Block(7,10,8,STAINED_GLASS:11)
Block(8,10,8,STAINED_GLASS:11)
Block(1,11,-7,STAINED_GLASS:15)
Block(2,11,-7,STAINED_GLASS:15)
Block(3,11,-7,STAINED_GLASS:15)
Block(4,11,-7,STAINED_GLASS:10)
Block(0,11,-6,STAINED_GLASS:15)
Block(1,11,-6,STAINED_GLASS:15)
Block(2,11,-6,STAINED_GLASS:15)
Block(3,11,-6,STAINED_GLASS:15)
Block(4,11,-6,STAINED_GLASS:10)
Block(-1,11,-5,STAINED_GLASS:2)
Block(0,11,-5,STAINED_GLASS:2)
Block(1,11,-5,STAINED_GLASS:15)
Block(2,11,-5,STAINED_GLASS:2)
Block(3,11,-5,STAINED_GLASS:15)
Block(4,11,-5,STAINED_GLASS:11)
Block(5,11,-5,STAINED_GLASS:10)
Block(-1,11,-4,STAINED_GLASS:2)
Block(0,11,-4,STAINED_GLASS:2)
Block(1,11,-4,STAINED_GLASS:15)
Block(2,11,-4,STAINED_GLASS:2)
Block(3,11,-4,STAINED_GLASS:15)
Block(4,11,-4,STAINED_GLASS:11)
Block(5,11,-4,STAINED_GLASS:11)
Block(-1,11,-3,STAINED_GLASS:2)
Block(0,11,-3,STAINED_GLASS:2)
Block(1,11,-3,STAINED_GLASS:2)
Block(2,11,-3,STAINED_GLASS:11)
Block(3,11,-3,SEA_LANTERN:0)
Block(4,11,-3,STAINED_GLASS:2)
Block(5,11,-3,STAINED_GLASS:10)
Block(6,11,-3,STAINED_GLASS:11)
Block(0,11,-2,STAINED_GLASS:2)
Block(1,11,-2,STAINED_GLASS:2)
Block(2,11,-2,STAINED_GLASS:2)
Block(3,11,-2,STAINED_GLASS:2)
Block(4,11,-2,STAINED_GLASS:2)
Block(5,11,-2,STAINED_GLASS:2)
Block(6,11,-2,STAINED_GLASS:2)
Block(7,11,-2,STAINED_GLASS:10)
Block(1,11,-1,STAINED_GLASS:2)
Block(2,11,-1,STAINED_GLASS:2)
Block(3,11,-1,STAINED_GLASS:2)
Block(4,11,-1,SEA_LANTERN:0)
Block(5,11,-1,SEA_LANTERN:0)
Block(6,11,-1,STAINED_GLASS:15)
Block(7,11,-1,STAINED_GLASS:10)
Block(8,11,-1,STAINED_GLASS:11)
Block(2,11,0,STAINED_GLASS:2)
Block(3,11,0,STAINED_GLASS:2)
Block(4,11,0,SEA_LANTERN:0)
Block(5,11,0,SEA_LANTERN:0)
Block(6,11,0,SEA_LANTERN:0)
Block(7,11,0,STAINED_GLASS:2)
Block(8,11,0,STAINED_GLASS:11)
Block(3,11,1,STAINED_GLASS:2)
Block(4,11,1,STAINED_GLASS:15)
Block(5,11,1,SEA_LANTERN:0)
Block(6,11,1,SEA_LANTERN:0)
Block(7,11,1,STAINED_GLASS:2)
Block(8,11,1,STAINED_GLASS:10)
Block(3,11,2,STAINED_GLASS:2)
Block(4,11,2,STAINED_GLASS:2)
Block(5,11,2,STAINED_GLASS:2)
Block(6,11,2,STAINED_GLASS:15)
Block(7,11,2,STAINED_GLASS:2)
Block(8,11,2,STAINED_GLASS:2)
Block(4,11,3,STAINED_GLASS:2)
Block(5,11,3,STAINED_GLASS:2)
Block(6,11,3,STAINED_GLASS:2)
Block(7,11,3,STAINED_GLASS:2)
Block(8,11,3,STAINED_GLASS:2)
Block(4,11,4,STAINED_GLASS:2)
Block(5,11,4,STAINED_GLASS:11)
Block(6,11,4,STAINED_GLASS:11)
Block(7,11,4,STAINED_GLASS:2)
Block(8,11,4,STAINED_GLASS:2)
Block(5,11,5,STAINED_GLASS:15)
Block(6,11,5,STAINED_GLASS:11)
Block(7,11,5,STAINED_GLASS:2)
Block(8,11,5,STAINED_GLASS:2)
Block(6,11,6,STAINED_GLASS:11)
Block(7,11,6,STAINED_GLASS:11)
Block(8,11,6,STAINED_GLASS:11)
Block(7,11,7,STAINED_GLASS:11)
Block(8,11,7,STAINED_GLASS:11)
Block(-2,12,-7,STAINED_GLASS:2)
Block(-1,12,-7,STAINED_GLASS:2)
Block(0,12,-7,STAINED_GLASS:15)
Block(1,12,-7,STAINED_GLASS:15)
Block(2,12,-7,STAINED_GLASS:15)
Block(3,12,-7,STAINED_GLASS:10)
Block(4,12,-7,STAINED_GLASS:10)
Block(-2,12,-6,STAINED_GLASS:2)
Block(-1,12,-6,STAINED_GLASS:2)
Block(0,12,-6,STAINED_GLASS:2)
Block(1,12,-6,STAINED_GLASS:2)
Block(2,12,-6,STAINED_GLASS:15)
Block(3,12,-6,STAINED_GLASS:2)
Block(4,12,-6,STAINED_GLASS:10)
Block(-1,12,-5,STAINED_GLASS:2)
Block(0,12,-5,STAINED_GLASS:2)
Block(1,12,-5,STAINED_GLASS:15)
Block(2,12,-5,STAINED_GLASS:15)
Block(3,12,-5,STAINED_GLASS:2)
Block(4,12,-5,STAINED_GLASS:10)
Block(5,12,-5,STAINED_GLASS:10)
Block(-1,12,-4,STAINED_GLASS:2)
Block(0,12,-4,STAINED_GLASS:2)
Block(1,12,-4,STAINED_GLASS:2)
Block(2,12,-4,STAINED_GLASS:15)
Block(3,12,-4,STAINED_GLASS:2)
Block(4,12,-4,STAINED_GLASS:10)
Block(5,12,-4,STAINED_GLASS:10)
Block(-1,12,-3,STAINED_GLASS:2)
Block(0,12,-3,STAINED_GLASS:2)
Block(1,12,-3,STAINED_GLASS:2)
Block(2,12,-3,STAINED_GLASS:2)
Block(3,12,-3,SEA_LANTERN:0)
Block(4,12,-3,STAINED_GLASS:15)
Block(5,12,-3,STAINED_GLASS:2)
Block(6,12,-3,STAINED_GLASS:10)
Block(0,12,-2,STAINED_GLASS:2)
Block(1,12,-2,STAINED_GLASS:2)
Block(2,12,-2,STAINED_GLASS:15)
Block(3,12,-2,STAINED_GLASS:15)
Block(4,12,-2,SEA_LANTERN:0)
Block(5,12,-2,STAINED_GLASS:15)
Block(6,12,-2,STAINED_GLASS:10)
Block(7,12,-2,STAINED_GLASS:10)
Block(1,12,-1,STAINED_GLASS:2)
Block(2,12,-1,STAINED_GLASS:2)
Block(3,12,-1,STAINED_GLASS:15)
Block(4,12,-1,SEA_LANTERN:0)
Block(5,12,-1,STAINED_GLASS:2)
Block(6,12,-1,STAINED_GLASS:2)
Block(7,12,-1,STAINED_GLASS:10)
Block(8,12,-1,STAINED_GLASS:10)
Block(2,12,0,STAINED_GLASS:2)
Block(3,12,0,STAINED_GLASS:2)
Block(4,12,0,STAINED_GLASS:2)
Block(5,12,0,STAINED_GLASS:15)
Block(6,12,0,STAINED_GLASS:2)
Block(7,12,0,STAINED_GLASS:10)
Block(8,12,0,STAINED_GLASS:10)
Block(3,12,1,STAINED_GLASS:2)
Block(4,12,1,STAINED_GLASS:2)
Block(5,12,1,STAINED_GLASS:2)
Block(6,12,1,STAINED_GLASS:15)
Block(7,12,1,STAINED_GLASS:2)
Block(8,12,1,STAINED_GLASS:2)
Block(3,12,2,STAINED_GLASS:2)
Block(4,12,2,STAINED_GLASS:2)
Block(5,12,2,STAINED_GLASS:2)
Block(6,12,2,STAINED_GLASS:2)
Block(7,12,2,STAINED_GLASS:2)
Block(8,12,2,STAINED_GLASS:2)
Block(4,12,3,STAINED_GLASS:2)
Block(5,12,3,STAINED_GLASS:2)
Block(6,12,3,STAINED_GLASS:2)
Block(7,12,3,STAINED_GLASS:2)
Block(8,12,3,STAINED_GLASS:2)
Block(4,12,4,STAINED_GLASS:2)
Block(5,12,4,STAINED_GLASS:2)
Block(6,12,4,STAINED_GLASS:2)
Block(7,12,4,STAINED_GLASS:2)
Block(8,12,4,STAINED_GLASS:2)
Block(5,12,5,STAINED_GLASS:11)
Block(6,12,5,STAINED_GLASS:11)
Block(7,12,5,STAINED_GLASS:2)
Block(-3,13,-7,STAINED_GLASS:2)
Block(-2,13,-7,STAINED_GLASS:2)
Block(-1,13,-7,STAINED_GLASS:2)
Block(0,13,-7,STAINED_GLASS:2)
Block(1,13,-7,STAINED_GLASS:2)
Block(2,13,-7,STAINED_GLASS:2)
Block(3,13,-7,STAINED_GLASS:10)
Block(4,13,-7,STAINED_GLASS:10)
Block(-2,13,-6,STAINED_GLASS:2)
Block(-1,13,-6,STAINED_GLASS:2)
Block(0,13,-6,STAINED_GLASS:2)
Block(1,13,-6,STAINED_GLASS:15)
Block(2,13,-6,STAINED_GLASS:2)
Block(3,13,-6,STAINED_GLASS:2)
Block(4,13,-6,STAINED_GLASS:10)
Block(-1,13,-5,STAINED_GLASS:2)
Block(0,13,-5,STAINED_GLASS:2)
Block(1,13,-5,STAINED_GLASS:2)
Block(2,13,-5,STAINED_GLASS:15)
Block(3,13,-5,SEA_LANTERN:0)
Block(4,13,-5,STAINED_GLASS:2)
Block(5,13,-5,STAINED_GLASS:10)
Block(-1,13,-4,STAINED_GLASS:2)
Block(0,13,-4,STAINED_GLASS:2)
Block(1,13,-4,SEA_LANTERN:0)
Block(2,13,-4,SEA_LANTERN:0)
Block(3,13,-4,SEA_LANTERN:0)
Block(4,13,-4,STAINED_GLASS:2)
Block(5,13,-4,STAINED_GLASS:10)
Block(-1,13,-3,STAINED_GLASS:2)
Block(0,13,-3,STAINED_GLASS:2)
Block(1,13,-3,STAINED_GLASS:15)
Block(2,13,-3,SEA_LANTERN:0)
Block(3,13,-3,SEA_LANTERN:0)
Block(4,13,-3,STAINED_GLASS:2)
Block(5,13,-3,STAINED_GLASS:10)
Block(6,13,-3,STAINED_GLASS:10)
Block(0,13,-2,STAINED_GLASS:2)
Block(1,13,-2,STAINED_GLASS:2)
Block(2,13,-2,STAINED_GLASS:2)
Block(3,13,-2,STAINED_GLASS:2)
Block(4,13,-2,STAINED_GLASS:2)
Block(5,13,-2,STAINED_GLASS:2)
Block(6,13,-2,STAINED_GLASS:10)
Block(7,13,-2,STAINED_GLASS:10)
Block(1,13,-1,STAINED_GLASS:2)
Block(2,13,-1,STAINED_GLASS:2)
Block(3,13,-1,STAINED_GLASS:2)
Block(4,13,-1,STAINED_GLASS:15)
Block(5,13,-1,STAINED_GLASS:10)
Block(6,13,-1,STAINED_GLASS:10)
Block(7,13,-1,STAINED_GLASS:10)
Block(8,13,-1,STAINED_GLASS:10)
Block(2,13,0,STAINED_GLASS:2)
Block(3,13,0,STAINED_GLASS:2)
Block(4,13,0,STAINED_GLASS:11)
Block(5,13,0,STAINED_GLASS:2)
Block(6,13,0,STAINED_GLASS:11)
Block(7,13,0,STAINED_GLASS:10)
Block(8,13,0,STAINED_GLASS:2)
Block(3,13,1,STAINED_GLASS:2)
Block(4,13,1,STAINED_GLASS:2)
Block(5,13,1,STAINED_GLASS:15)
Block(6,13,1,STAINED_GLASS:2)
Block(7,13,1,STAINED_GLASS:2)
Block(8,13,1,STAINED_GLASS:2)
Block(3,13,2,STAINED_GLASS:2)
Block(4,13,2,STAINED_GLASS:2)
Block(5,13,2,STAINED_GLASS:2)
Block(6,13,2,STAINED_GLASS:2)
Block(7,13,2,STAINED_GLASS:2)
Block(4,13,3,STAINED_GLASS:2)
Block(5,13,3,STAINED_GLASS:2)
Block(6,13,3,STAINED_GLASS:2)
Block(4,13,4,STAINED_GLASS:2)
Block(5,13,4,STAINED_GLASS:2)
Block(-3,14,-7,STAINED_GLASS:2)
Block(-2,14,-7,STAINED_GLASS:2)
Block(-1,14,-7,STAINED_GLASS:2)
Block(0,14,-7,STAINED_GLASS:15)
Block(1,14,-7,STAINED_GLASS:2)
Block(2,14,-7,STAINED_GLASS:15)
Block(3,14,-7,STAINED_GLASS:2)
Block(4,14,-7,STAINED_GLASS:10)
Block(-2,14,-6,STAINED_GLASS:11)
Block(-1,14,-6,STAINED_GLASS:10)
Block(0,14,-6,STAINED_GLASS:2)
Block(1,14,-6,SEA_LANTERN:0)
Block(2,14,-6,SEA_LANTERN:0)
Block(3,14,-6,STAINED_GLASS:15)
Block(4,14,-6,STAINED_GLASS:10)
Block(-1,14,-5,STAINED_GLASS:11)
Block(0,14,-5,STAINED_GLASS:15)
Block(1,14,-5,SEA_LANTERN:0)
Block(2,14,-5,SEA_LANTERN:0)
Block(3,14,-5,STAINED_GLASS:2)
Block(4,14,-5,STAINED_GLASS:10)
Block(5,14,-5,STAINED_GLASS:10)
Block(-1,14,-4,STAINED_GLASS:2)
Block(0,14,-4,STAINED_GLASS:15)
Block(1,14,-4,STAINED_GLASS:2)
Block(2,14,-4,SEA_LANTERN:0)
Block(3,14,-4,STAINED_GLASS:2)
Block(4,14,-4,STAINED_GLASS:10)
Block(5,14,-4,STAINED_GLASS:10)
Block(-1,14,-3,STAINED_GLASS:2)
Block(0,14,-3,STAINED_GLASS:11)
Block(1,14,-3,STAINED_GLASS:2)
Block(2,14,-3,STAINED_GLASS:2)
Block(3,14,-3,STAINED_GLASS:2)
Block(4,14,-3,STAINED_GLASS:10)
Block(5,14,-3,STAINED_GLASS:10)
Block(6,14,-3,STAINED_GLASS:10)
Block(0,14,-2,STAINED_GLASS:11)
Block(1,14,-2,STAINED_GLASS:11)
Block(2,14,-2,STAINED_GLASS:11)
Block(3,14,-2,STAINED_GLASS:11)
Block(4,14,-2,STAINED_GLASS:10)
Block(5,14,-2,STAINED_GLASS:10)
Block(6,14,-2,STAINED_GLASS:10)
Block(7,14,-2,STAINED_GLASS:10)
Block(1,14,-1,STAINED_GLASS:11)
Block(2,14,-1,STAINED_GLASS:11)
Block(3,14,-1,STAINED_GLASS:11)
Block(4,14,-1,STAINED_GLASS:2)
Block(5,14,-1,STAINED_GLASS:11)
Block(6,14,-1,STAINED_GLASS:10)
Block(7,14,-1,STAINED_GLASS:10)
Block(2,14,0,STAINED_GLASS:2)
Block(3,14,0,STAINED_GLASS:2)
Block(4,14,0,STAINED_GLASS:11)
Block(5,14,0,STAINED_GLASS:11)
Block(6,14,0,STAINED_GLASS:11)
Block(7,14,0,STAINED_GLASS:11)
Block(3,14,1,STAINED_GLASS:2)
Block(4,14,1,STAINED_GLASS:2)
Block(5,14,1,STAINED_GLASS:11)
Block(6,14,1,STAINED_GLASS:11)
Block(4,14,2,STAINED_GLASS:2)
Block(-3,15,-7,STAINED_GLASS:11)
Block(-2,15,-7,STAINED_GLASS:10)
Block(-1,15,-7,SEA_LANTERN:0)
Block(0,15,-7,SEA_LANTERN:0)
Block(1,15,-7,SEA_LANTERN:0)
Block(2,15,-7,STAINED_GLASS:2)
Block(3,15,-7,STAINED_GLASS:11)
Block(4,15,-7,STAINED_GLASS:10)
Block(-2,15,-6,STAINED_GLASS:11)
Block(-1,15,-6,STAINED_GLASS:15)
Block(0,15,-6,SEA_LANTERN:0)
Block(1,15,-6,SEA_LANTERN:0)
Block(2,15,-6,STAINED_GLASS:2)
Block(3,15,-6,STAINED_GLASS:2)
Block(4,15,-6,STAINED_GLASS:10)
Block(-1,15,-5,STAINED_GLASS:10)
Block(0,15,-5,STAINED_GLASS:10)
Block(1,15,-5,STAINED_GLASS:2)
Block(2,15,-5,STAINED_GLASS:15)
Block(3,15,-5,STAINED_GLASS:15)
Block(4,15,-5,STAINED_GLASS:11)
Block(5,15,-5,STAINED_GLASS:10)
Block(-1,15,-4,STAINED_GLASS:11)
Block(0,15,-4,STAINED_GLASS:2)
Block(1,15,-4,STAINED_GLASS:11)
Block(2,15,-4,STAINED_GLASS:2)
Block(3,15,-4,STAINED_GLASS:11)
Block(4,15,-4,STAINED_GLASS:11)
Block(5,15,-4,STAINED_GLASS:11)
Block(-1,15,-3,STAINED_GLASS:11)
Block(0,15,-3,STAINED_GLASS:11)
Block(1,15,-3,STAINED_GLASS:11)
Block(2,15,-3,STAINED_GLASS:11)
Block(3,15,-3,STAINED_GLASS:2)
Block(4,15,-3,STAINED_GLASS:11)
Block(5,15,-3,STAINED_GLASS:10)
Block(6,15,-3,STAINED_GLASS:11)
Block(0,15,-2,STAINED_GLASS:11)
Block(1,15,-2,STAINED_GLASS:11)
Block(2,15,-2,STAINED_GLASS:11)
Block(3,15,-2,STAINED_GLASS:11)
Block(4,15,-2,STAINED_GLASS:11)
Block(5,15,-2,STAINED_GLASS:11)
Block(6,15,-2,STAINED_GLASS:11)
Block(1,15,-1,STAINED_GLASS:11)
Block(2,15,-1,STAINED_GLASS:11)
Block(3,15,-1,STAINED_GLASS:11)
Block(4,15,-1,STAINED_GLASS:11)
Block(5,15,-1,STAINED_GLASS:11)
Block(2,15,0,STAINED_GLASS:11)
Block(3,15,0,STAINED_GLASS:11)
Block(4,15,0,STAINED_GLASS:11)
Block(-3,16,-7,STAINED_GLASS:11)
Block(-2,16,-7,STAINED_GLASS:11)
Block(-1,16,-7,STAINED_GLASS:2)
Block(0,16,-7,STAINED_GLASS:15)
Block(1,16,-7,STAINED_GLASS:2)
Block(2,16,-7,STAINED_GLASS:11)
Block(3,16,-7,STAINED_GLASS:11)
Block(4,16,-7,STAINED_GLASS:11)
Block(-2,16,-6,STAINED_GLASS:11)
Block(-1,16,-6,STAINED_GLASS:10)
Block(0,16,-6,STAINED_GLASS:2)
Block(1,16,-6,STAINED_GLASS:2)
Block(2,16,-6,STAINED_GLASS:11)
Block(3,16,-6,STAINED_GLASS:11)
Block(4,16,-6,STAINED_GLASS:11)
Block(-1,16,-5,STAINED_GLASS:11)
Block(0,16,-5,STAINED_GLASS:11)
Block(1,16,-5,STAINED_GLASS:11)
Block(2,16,-5,STAINED_GLASS:2)
Block(3,16,-5,STAINED_GLASS:15)
Block(4,16,-5,STAINED_GLASS:11)
Block(5,16,-5,STAINED_GLASS:15)
Block(-1,16,-4,STAINED_GLASS:11)
Block(0,16,-4,STAINED_GLASS:11)
Block(1,16,-4,STAINED_GLASS:11)
Block(2,16,-4,STAINED_GLASS:11)
Block(3,16,-4,STAINED_GLASS:11)
Block(4,16,-4,STAINED_GLASS:15)
Block(-1,16,-3,STAINED_GLASS:11)
Block(0,16,-3,STAINED_GLASS:11)
Block(1,16,-3,STAINED_GLASS:11)
Block(2,16,-3,STAINED_GLASS:11)
Block(3,16,-3,STAINED_GLASS:11)
Block(4,16,-3,STAINED_GLASS:11)
Block(0,16,-2,STAINED_GLASS:11)
Block(1,16,-2,STAINED_GLASS:11)
Block(2,16,-2,STAINED_GLASS:11)
Block(-3,17,-7,STAINED_GLASS:11)
Block(-2,17,-7,STAINED_GLASS:11)
Block(-1,17,-7,STAINED_GLASS:11)
Block(0,17,-7,STAINED_GLASS:2)
Block(1,17,-7,STAINED_GLASS:11)
Block(2,17,-7,STAINED_GLASS:11)
Block(3,17,-7,STAINED_GLASS:11)
Block(4,17,-7,STAINED_GLASS:11)
Block(-2,17,-6,STAINED_GLASS:11)
Block(-1,17,-6,STAINED_GLASS:11)
Block(0,17,-6,STAINED_GLASS:11)
Block(1,17,-6,STAINED_GLASS:2)
Block(2,17,-6,STAINED_GLASS:11)
Block(3,17,-6,STAINED_GLASS:15)
Block(4,17,-6,STAINED_GLASS:11)
Block(-1,17,-5,STAINED_GLASS:11)
Block(0,17,-5,STAINED_GLASS:11)
Block(1,17,-5,STAINED_GLASS:11)
Block(2,17,-5,STAINED_GLASS:11)
Block(3,17,-5,STAINED_GLASS:15)
Block(4,17,-5,STAINED_GLASS:15)
Block(-1,17,-4,STAINED_GLASS:11)
Block(0,17,-4,STAINED_GLASS:11)
Block(1,17,-4,STAINED_GLASS:11)
Block(-1,17,-3,STAINED_GLASS:11)
Block(0,17,-3,STAINED_GLASS:11)
Block(-3,18,-7,STAINED_GLASS:11)
Block(-2,18,-7,STAINED_GLASS:11)
Block(-1,18,-7,STAINED_GLASS:11)
Block(0,18,-7,STAINED_GLASS:11)
Block(1,18,-7,STAINED_GLASS:11)
Block(2,18,-7,STAINED_GLASS:15)
Block(-2,18,-6,STAINED_GLASS:11)
Block(-1,18,-6,STAINED_GLASS:11)
Block(0,18,-6,STAINED_GLASS:11)
Block(1,18,-6,STAINED_GLASS:11)
Block(-1,18,-5,STAINED_GLASS:11)
Block(0,18,-5,STAINED_GLASS:11)
Block(-3,19,-7,STAINED_GLASS:11)
Block(-2,19,-7,STAINED_GLASS:11)
Block(-1,19,-7,STAINED_GLASS:11)
Branch(0,0,-16,spike-IL-13_01-00,NORTH,100)
