
#######################################################################
# +-----------------------------------------------------------------+ #
# |                            BO3 object                           | #
# +-----------------------------------------------------------------+ #
#######################################################################

Author: NLBlackEagle

Description: Converted version of the BO2 forestrock4

Version: 3

SettingsMode: WriteWithoutComments


#######################################################################
# +-----------------------------------------------------------------+ #
# |                          Main settings                          | #
# +-----------------------------------------------------------------+ #
#######################################################################

Tree: false

Frequency: 1

Rarity: 10.0

RotateRandomly: true

SpawnHeight: highestSolidBlock

SpawnHeightOffset: 0

SpawnHeightVariance: 0

##############################
# Height Limits for the BO3. #
##############################

MinHeight: 0

MaxHeight: 127

######################
# Extrusion settings #
######################

ExtrudeMode: None

ExtrudeThroughBlocks: otg:air

MaxBranchDepth: 10


#######################################################################
# +-----------------------------------------------------------------+ #
# |                      Source block settings                      | #
# +-----------------------------------------------------------------+ #
#######################################################################

SourceBlocks: otg:air,otg:stone,otg:dirt,minecraft:grass_block

MaxPercentageOutsideSourceBlock: 2

OutsideSourceBlock: placeAnyway

DoReplaceBlocks: true

IsOTGPlus: false


#######################################################################
# +-----------------------------------------------------------------+ #
# |                              Blocks                             | #
# +-----------------------------------------------------------------+ #
#######################################################################

B(-4,3,-1,minecraft:granite)
B(-4,4,-1,minecraft:granite)
B(-4,2,0,minecraft:stone)
B(-4,3,0,minecraft:granite)
B(-4,4,0,minecraft:polished_granite)
B(-4,-1,1,minecraft:stone)
B(-4,0,1,minecraft:andesite)
B(-4,1,1,minecraft:andesite)
B(-4,2,1,minecraft:iron_ore)
B(-4,3,1,minecraft:granite)
B(-4,-2,2,minecraft:andesite)
B(-4,-1,2,minecraft:stone)
B(-4,0,2,minecraft:andesite)
B(-4,1,2,minecraft:stone)
B(-4,2,2,minecraft:granite)
B(-4,-1,3,minecraft:andesite)
B(-4,0,3,minecraft:gravel)
B(-3,3,-2,minecraft:cobweb)
B(-3,4,-2,minecraft:granite)
B(-3,-2,-1,minecraft:andesite)
B(-3,-1,-1,minecraft:andesite)
B(-3,0,-1,minecraft:andesite)
B(-3,1,-1,minecraft:andesite)
B(-3,2,-1,minecraft:andesite)
B(-3,3,-1,minecraft:granite)
B(-3,4,-1,minecraft:polished_granite)
B(-3,5,-1,minecraft:polished_granite)
B(-3,-4,0,minecraft:stone)
B(-3,-3,0,minecraft:andesite)
B(-3,-2,0,minecraft:stone)
B(-3,-1,0,minecraft:andesite)
B(-3,0,0,minecraft:andesite)
B(-3,1,0,minecraft:andesite)
B(-3,2,0,minecraft:iron_ore)
B(-3,3,0,minecraft:iron_ore)
B(-3,4,0,minecraft:polished_granite)
B(-3,5,0,minecraft:polished_granite)
B(-3,6,0,minecraft:polished_granite)
B(-3,-4,1,minecraft:stone)
B(-3,-3,1,minecraft:andesite)
B(-3,-2,1,minecraft:stone)
B(-3,-1,1,minecraft:andesite)
B(-3,0,1,minecraft:stone)
B(-3,1,1,minecraft:stone)
B(-3,2,1,minecraft:iron_ore)
B(-3,3,1,minecraft:iron_ore)
B(-3,4,1,minecraft:polished_granite)
B(-3,5,1,minecraft:polished_granite)
B(-3,6,1,minecraft:polished_granite)
B(-3,-3,2,minecraft:stone)
B(-3,-2,2,minecraft:andesite)
B(-3,-1,2,minecraft:andesite)
B(-3,0,2,minecraft:stone)
B(-3,1,2,minecraft:stone)
B(-3,2,2,minecraft:stone)
B(-3,3,2,minecraft:iron_ore)
B(-3,4,2,minecraft:polished_granite)
B(-3,-2,3,minecraft:stone)
B(-3,-1,3,minecraft:andesite)
B(-3,0,3,minecraft:andesite)
B(-3,1,3,minecraft:andesite)
B(-3,2,3,minecraft:granite)
B(-3,3,3,minecraft:granite)
B(-2,3,-3,minecraft:granite)
B(-2,-3,-2,minecraft:stone)
B(-2,-2,-2,minecraft:andesite)
B(-2,-1,-2,minecraft:andesite)
B(-2,0,-2,minecraft:stone)
B(-2,1,-2,minecraft:andesite)
B(-2,2,-2,minecraft:polished_granite)
B(-2,3,-2,minecraft:polished_granite)
B(-2,4,-2,minecraft:polished_granite)
B(-2,5,-2,minecraft:polished_granite)
B(-2,-5,-1,minecraft:andesite)
B(-2,-4,-1,minecraft:andesite)
B(-2,-3,-1,minecraft:andesite)
B(-2,-2,-1,minecraft:andesite)
B(-2,-1,-1,minecraft:andesite)
B(-2,0,-1,minecraft:andesite)
B(-2,1,-1,minecraft:andesite)
B(-2,2,-1,minecraft:andesite)
B(-2,3,-1,minecraft:polished_granite)
B(-2,4,-1,minecraft:polished_granite)
B(-2,5,-1,minecraft:polished_granite)
B(-2,6,-1,minecraft:polished_granite)
B(-2,-6,0,minecraft:andesite)
B(-2,-5,0,minecraft:andesite)
B(-2,-4,0,minecraft:andesite)
B(-2,-3,0,minecraft:andesite)
B(-2,-2,0,minecraft:andesite)
B(-2,-1,0,minecraft:andesite)
B(-2,0,0,minecraft:stone)
B(-2,1,0,minecraft:andesite)
B(-2,2,0,minecraft:iron_ore)
B(-2,3,0,minecraft:iron_ore)
B(-2,4,0,minecraft:polished_granite)
B(-2,5,0,minecraft:polished_granite)
B(-2,6,0,minecraft:polished_granite)
B(-2,7,0,minecraft:polished_granite)
B(-2,-5,1,minecraft:andesite)
B(-2,-4,1,minecraft:andesite)
B(-2,-3,1,minecraft:andesite)
B(-2,-2,1,minecraft:andesite)
B(-2,-1,1,minecraft:stone)
B(-2,0,1,minecraft:stone)
B(-2,1,1,minecraft:iron_ore)
B(-2,2,1,minecraft:iron_ore)
B(-2,3,1,minecraft:iron_ore)
B(-2,4,1,minecraft:polished_granite)
B(-2,5,1,minecraft:polished_granite)
B(-2,6,1,minecraft:polished_granite)
B(-2,7,1,minecraft:polished_granite)
B(-2,-5,2,minecraft:andesite)
B(-2,-4,2,minecraft:stone)
B(-2,-3,2,minecraft:andesite)
B(-2,-2,2,minecraft:andesite)
B(-2,-1,2,minecraft:stone)
B(-2,0,2,minecraft:stone)
B(-2,1,2,minecraft:stone)
B(-2,2,2,minecraft:stone)
B(-2,3,2,minecraft:polished_granite)
B(-2,4,2,minecraft:polished_granite)
B(-2,5,2,minecraft:polished_granite)
B(-2,6,2,minecraft:polished_granite)
B(-2,-4,3,minecraft:andesite)
B(-2,-3,3,minecraft:andesite)
B(-2,-2,3,minecraft:stone)
B(-2,-1,3,minecraft:andesite)
B(-2,0,3,minecraft:andesite)
B(-2,1,3,minecraft:stone)
B(-2,2,3,minecraft:stone)
B(-2,3,3,minecraft:polished_granite)
B(-2,4,3,minecraft:polished_granite)
B(-2,-1,4,minecraft:stone)
B(-2,0,4,minecraft:andesite)
B(-2,1,4,minecraft:stone)
B(-2,2,4,minecraft:stone)
B(-1,-3,-3,minecraft:andesite)
B(-1,-2,-3,minecraft:stone)
B(-1,-1,-3,minecraft:andesite)
B(-1,0,-3,minecraft:stone)
B(-1,1,-3,minecraft:gravel)
B(-1,2,-3,minecraft:polished_granite)
B(-1,3,-3,minecraft:polished_granite)
B(-1,-4,-2,minecraft:andesite)
B(-1,-3,-2,minecraft:andesite)
B(-1,-2,-2,minecraft:andesite)
B(-1,-1,-2,minecraft:andesite)
B(-1,0,-2,minecraft:stone)
B(-1,1,-2,minecraft:polished_granite)
B(-1,2,-2,minecraft:polished_granite)
B(-1,3,-2,minecraft:polished_granite)
B(-1,4,-2,minecraft:granite)
B(-1,5,-2,minecraft:gravel)
B(-1,-6,-1,minecraft:andesite)
B(-1,-5,-1,minecraft:andesite)
B(-1,-4,-1,minecraft:stone)
B(-1,-3,-1,minecraft:stone)
B(-1,-2,-1,minecraft:andesite)
B(-1,-1,-1,minecraft:stone)
B(-1,0,-1,minecraft:stone)
B(-1,1,-1,minecraft:stone)
B(-1,2,-1,minecraft:polished_granite)
B(-1,3,-1,minecraft:polished_granite)
B(-1,4,-1,minecraft:polished_granite)
B(-1,5,-1,minecraft:polished_granite)
B(-1,6,-1,minecraft:polished_granite)
B(-1,-6,0,minecraft:andesite)
B(-1,-5,0,minecraft:andesite)
B(-1,-4,0,minecraft:stone)
B(-1,-3,0,minecraft:stone)
B(-1,-2,0,minecraft:stone)
B(-1,0,0,minecraft:stone)
B(-1,1,0,minecraft:iron_ore)
B(-1,2,0,minecraft:iron_ore)
B(-1,3,0,minecraft:iron_ore)
B(-1,4,0,minecraft:polished_granite)
B(-1,5,0,minecraft:polished_granite)
B(-1,6,0,minecraft:grass_block)
B(-1,7,0,minecraft:fern)
B(-1,-6,1,minecraft:stone)
B(-1,-5,1,minecraft:andesite)
B(-1,-4,1,minecraft:andesite)
B(-1,-3,1,minecraft:stone)
B(-1,-2,1,minecraft:stone)
B(-1,-1,1,minecraft:stone)
B(-1,0,1,minecraft:stone)
B(-1,1,1,minecraft:iron_ore)
B(-1,2,1,minecraft:iron_ore)
B(-1,3,1,minecraft:iron_ore)
B(-1,4,1,minecraft:polished_granite)
B(-1,5,1,minecraft:polished_granite)
B(-1,6,1,minecraft:polished_granite)
B(-1,7,1,minecraft:polished_granite)
B(-1,-5,2,minecraft:andesite)
B(-1,-4,2,minecraft:andesite)
B(-1,-3,2,minecraft:andesite)
B(-1,-2,2,minecraft:andesite)
B(-1,-1,2,minecraft:andesite)
B(-1,0,2,minecraft:stone)
B(-1,1,2,minecraft:stone)
B(-1,2,2,minecraft:stone)
B(-1,3,2,minecraft:polished_granite)
B(-1,4,2,minecraft:polished_granite)
B(-1,5,2,minecraft:polished_granite)
B(-1,6,2,minecraft:polished_granite)
B(-1,7,2,minecraft:polished_granite)
B(-1,-4,3,minecraft:andesite)
B(-1,-3,3,minecraft:stone)
B(-1,-2,3,minecraft:andesite)
B(-1,-1,3,minecraft:andesite)
B(-1,0,3,minecraft:andesite)
B(-1,1,3,minecraft:stone)
B(-1,2,3,minecraft:stone)
B(-1,3,3,minecraft:polished_granite)
B(-1,-1,4,minecraft:stone)
B(-1,0,4,minecraft:andesite)
B(-1,1,4,minecraft:gravel)
B(0,-1,-4,minecraft:stone)
B(0,0,-4,minecraft:andesite)
B(0,1,-4,minecraft:stone)
B(0,-4,-3,minecraft:andesite)
B(0,-3,-3,minecraft:andesite)
B(0,-2,-3,minecraft:andesite)
B(0,-1,-3,minecraft:andesite)
B(0,0,-3,minecraft:andesite)
B(0,1,-3,minecraft:polished_granite)
B(0,2,-3,minecraft:granite)
B(0,3,-3,minecraft:gravel)
B(0,-5,-2,minecraft:stone)
B(0,-4,-2,minecraft:andesite)
B(0,-3,-2,minecraft:andesite)
B(0,-2,-2,minecraft:andesite)
B(0,-1,-2,minecraft:andesite)
B(0,0,-2,minecraft:stone)
B(0,1,-2,minecraft:polished_granite)
B(0,2,-2,minecraft:polished_granite)
B(0,3,-2,minecraft:polished_granite)
B(0,4,-2,minecraft:polished_andesite)
B(0,-6,-1,minecraft:andesite)
B(0,-5,-1,minecraft:andesite)
B(0,-4,-1,minecraft:andesite)
B(0,-3,-1,minecraft:stone)
B(0,-2,-1,minecraft:stone)
B(0,-1,-1,minecraft:stone)
B(0,0,-1,minecraft:stone)
B(0,1,-1,minecraft:stone)
B(0,2,-1,minecraft:polished_granite)
B(0,3,-1,minecraft:polished_granite)
B(0,4,-1,minecraft:polished_granite)
B(0,5,-1,minecraft:polished_andesite)
B(0,6,-1,minecraft:polished_andesite)
B(0,-6,0,minecraft:andesite)
B(0,-5,0,minecraft:andesite)
B(0,-4,0,minecraft:andesite)
B(0,-3,0,minecraft:stone)
B(0,-2,0,minecraft:andesite)
B(0,-1,0,minecraft:stone)
B(0,0,0,minecraft:stone)
B(0,1,0,minecraft:stone)
B(0,2,0,minecraft:stone)
B(0,3,0,minecraft:iron_ore)
B(0,4,0,minecraft:iron_ore)
B(0,5,0,minecraft:polished_granite)
B(0,6,0,minecraft:polished_andesite)
B(0,-5,1,minecraft:stone)
B(0,-4,1,minecraft:andesite)
B(0,-3,1,minecraft:andesite)
B(0,-2,1,minecraft:andesite)
B(0,-1,1,minecraft:andesite)
B(0,0,1,minecraft:andesite)
B(0,1,1,minecraft:stone)
B(0,2,1,minecraft:stone)
B(0,3,1,minecraft:iron_ore)
B(0,4,1,minecraft:polished_granite)
B(0,5,1,minecraft:polished_granite)
B(0,6,1,minecraft:polished_granite)
B(0,-5,2,minecraft:stone)
B(0,-4,2,minecraft:stone)
B(0,-3,2,minecraft:stone)
B(0,-2,2,minecraft:andesite)
B(0,-1,2,minecraft:andesite)
B(0,0,2,minecraft:andesite)
B(0,1,2,minecraft:andesite)
B(0,2,2,minecraft:stone)
B(0,3,2,minecraft:polished_granite)
B(0,4,2,minecraft:polished_granite)
B(0,-3,3,minecraft:stone)
B(0,-2,3,minecraft:stone)
B(0,-1,3,minecraft:andesite)
B(0,0,3,minecraft:andesite)
B(0,1,3,minecraft:stone)
B(0,2,3,minecraft:stone)
B(1,-2,-4,minecraft:stone)
B(1,-1,-4,minecraft:andesite)
B(1,0,-4,minecraft:stone)
B(1,-5,-3,minecraft:andesite)
B(1,-4,-3,minecraft:andesite)
B(1,-3,-3,minecraft:stone)
B(1,-1,-3,minecraft:andesite)
B(1,0,-3,minecraft:andesite)
B(1,1,-3,minecraft:andesite)
B(1,2,-3,minecraft:polished_granite)
B(1,-5,-2,minecraft:andesite)
B(1,-4,-2,minecraft:andesite)
B(1,-3,-2,minecraft:andesite)
B(1,0,-2,minecraft:stone)
B(1,1,-2,minecraft:stone)
B(1,2,-2,minecraft:polished_granite)
B(1,3,-2,minecraft:polished_andesite)
B(1,4,-2,minecraft:polished_andesite)
B(1,-5,-1,minecraft:andesite)
B(1,-4,-1,minecraft:andesite)
B(1,-3,-1,minecraft:stone)
B(1,-2,-1,minecraft:andesite)
B(1,-1,-1,minecraft:stone)
B(1,0,-1,minecraft:stone)
B(1,1,-1,minecraft:stone)
B(1,2,-1,minecraft:stone)
B(1,3,-1,minecraft:stone)
B(1,4,-1,minecraft:polished_granite)
B(1,5,-1,minecraft:polished_andesite)
B(1,-6,0,minecraft:andesite)
B(1,-5,0,minecraft:andesite)
B(1,-4,0,minecraft:andesite)
B(1,-3,0,minecraft:andesite)
B(1,-2,0,minecraft:stone)
B(1,-1,0,minecraft:stone)
B(1,0,0,minecraft:stone)
B(1,1,0,minecraft:stone)
B(1,2,0,minecraft:stone)
B(1,3,0,minecraft:stone)
B(1,-4,1,minecraft:andesite)
B(1,-3,1,minecraft:andesite)
B(1,-2,1,minecraft:andesite)
B(1,-1,1,minecraft:stone)
B(1,0,1,minecraft:stone)
B(1,1,1,minecraft:andesite)
B(1,2,1,minecraft:stone)
B(1,-2,2,minecraft:andesite)
B(1,-1,2,minecraft:stone)
B(1,0,2,minecraft:andesite)
B(1,1,2,minecraft:andesite)
B(2,-4,-3,minecraft:andesite)
B(2,-3,-3,minecraft:andesite)
B(2,-2,-3,minecraft:andesite)
B(2,-1,-3,minecraft:stone)
B(2,0,-3,minecraft:andesite)
B(2,1,-3,minecraft:polished_granite)
B(2,-5,-2,minecraft:andesite)
B(2,-4,-2,minecraft:andesite)
B(2,-3,-2,minecraft:andesite)
B(2,-2,-2,minecraft:andesite)
B(2,-1,-2,minecraft:stone)
B(2,0,-2,minecraft:andesite)
B(2,1,-2,minecraft:andesite)
B(2,2,-2,minecraft:iron_ore)
B(2,3,-2,minecraft:polished_granite)
B(2,-5,-1,minecraft:stone)
B(2,-4,-1,minecraft:stone)
B(2,-3,-1,minecraft:andesite)
B(2,-2,-1,minecraft:stone)
B(2,-1,-1,minecraft:stone)
B(2,0,-1,minecraft:stone)
B(2,1,-1,minecraft:stone)
B(2,2,-1,minecraft:stone)
B(2,3,-1,minecraft:stone)
B(2,4,-1,minecraft:stone)
B(2,-4,0,minecraft:andesite)
B(2,-3,0,minecraft:andesite)
B(2,-2,0,minecraft:stone)
B(2,-1,0,minecraft:stone)
B(2,0,0,minecraft:stone)
B(2,1,0,minecraft:andesite)
B(2,2,0,minecraft:gravel)
B(2,-27,2,minecraft:snow_block)
B(3,-3,-2,minecraft:stone)
B(3,-3,-1,minecraft:stone)
B(3,-2,-1,minecraft:andesite)

#######################################################################
# +-----------------------------------------------------------------+ #
# |                            BO3 checks                           | #
# +-----------------------------------------------------------------+ #
#######################################################################

BlockCheck(0,-1,0,otg:dirt,minecraft:grass_block,minecraft:podzol)
BlockCheck(0,-2,0,otg:dirt)

#######################################################################
# +-----------------------------------------------------------------+ #
# |                             Branches                            | #
# +-----------------------------------------------------------------+ #
#######################################################################


#######################################################################
# +-----------------------------------------------------------------+ #
# |                             Entities                            | #
# +-----------------------------------------------------------------+ #
#######################################################################

