
#######################################################################
# +-----------------------------------------------------------------+ #
# |                            BO3 object                           | #
# +-----------------------------------------------------------------+ #
#######################################################################

Author: NLBlackEagle

Description: No description given

Version: 3

SettingsMode: WriteWithoutComments


#######################################################################
# +-----------------------------------------------------------------+ #
# |                          Main settings                          | #
# +-----------------------------------------------------------------+ #
#######################################################################

Tree: true

Frequency: 1

Rarity: 30.0

RotateRandomly: true

SpawnHeight: highestSolidBlock

SpawnHeightOffset: -6

SpawnHeightVariance: 0

##############################
# Height Limits for the BO3. #
##############################

MinHeight: 0

MaxHeight: 255

######################
# Extrusion settings #
######################

ExtrudeMode: None

ExtrudeThroughBlocks: otg:air

MaxBranchDepth: 10


#######################################################################
# +-----------------------------------------------------------------+ #
# |                      Source block settings                      | #
# +-----------------------------------------------------------------+ #
#######################################################################

SourceBlocks: otg:air,otg:stone,otg:dirt,minecraft:grass_block

MaxPercentageOutsideSourceBlock: 0

OutsideSourceBlock: placeAnyway

DoReplaceBlocks: true

IsOTGPlus: false


#######################################################################
# +-----------------------------------------------------------------+ #
# |                              Blocks                             | #
# +-----------------------------------------------------------------+ #
#######################################################################

B(-3,4,-2,minecraft:iron_ore)
B(-3,3,-1,minecraft:iron_ore)
B(-3,4,-1,minecraft:stone)
B(-3,5,-1,minecraft:stone)
B(-3,4,0,minecraft:iron_ore)
B(-3,5,0,minecraft:grass_block)
B(-3,6,0,minecraft:fern)
B(-3,4,1,minecraft:stone)
B(-3,5,1,minecraft:spruce_leaves[distance=2,persistent=false])
B(-3,6,1,minecraft:spruce_leaves)
B(-3,3,2,minecraft:stone)
B(-3,4,2,minecraft:stone)
B(-3,5,2,minecraft:stone)
B(-3,4,3,minecraft:stone)
B(-2,4,-4,minecraft:stone)
B(-2,3,-3,minecraft:stone)
B(-2,4,-3,minecraft:iron_ore)
B(-2,5,-3,minecraft:stone)
B(-2,3,-2,minecraft:iron_ore)
B(-2,4,-2,minecraft:stone)
B(-2,5,-2,minecraft:iron_ore)
B(-2,6,-2,minecraft:dirt)
B(-2,7,-2,minecraft:grass_block)
B(-2,8,-2,minecraft:spruce_leaves[distance=2,persistent=false])
B(-2,2,-1,minecraft:iron_ore)
B(-2,3,-1,minecraft:stone)
B(-2,4,-1,minecraft:iron_ore)
B(-2,5,-1,minecraft:stone)
B(-2,6,-1,minecraft:stone)
B(-2,7,-1,minecraft:stone)
B(-2,8,-1,minecraft:grass_block)
B(-2,9,-1,minecraft:red_tulip)
B(-2,3,0,minecraft:stone)
B(-2,4,0,minecraft:stone)
B(-2,5,0,minecraft:stone)
B(-2,6,0,minecraft:iron_ore)
B(-2,7,0,minecraft:stone)
B(-2,8,0,minecraft:iron_ore)
B(-2,0,1,minecraft:stone)
B(-2,1,1,minecraft:stone)
B(-2,2,1,minecraft:iron_ore)
B(-2,3,1,minecraft:stone)
B(-2,4,1,minecraft:stone)
B(-2,5,1,minecraft:stone)
B(-2,6,1,minecraft:spruce_log)
B(-2,7,1,minecraft:grass_block)
B(-2,8,1,minecraft:oxeye_daisy)
B(-2,0,2,minecraft:stone)
B(-2,1,2,minecraft:iron_ore)
B(-2,2,2,minecraft:iron_ore)
B(-2,3,2,minecraft:stone)
B(-2,4,2,minecraft:stone)
B(-2,5,2,minecraft:stone)
B(-2,6,2,minecraft:iron_ore)
B(-2,7,2,minecraft:grass_block)
B(-2,8,2,minecraft:red_tulip)
B(-2,1,3,minecraft:iron_ore)
B(-2,3,3,minecraft:stone)
B(-2,4,3,minecraft:iron_ore)
B(-2,5,3,minecraft:stone)
B(-2,4,4,minecraft:stone)
B(-1,4,-5,minecraft:stone)
B(-1,3,-4,minecraft:stone)
B(-1,4,-4,minecraft:stone)
B(-1,5,-4,minecraft:stone)
B(-1,6,-4,minecraft:grass_block)
B(-1,7,-4,minecraft:oxeye_daisy)
B(-1,2,-3,minecraft:stone)
B(-1,3,-3,minecraft:iron_ore)
B(-1,4,-3,minecraft:stone)
B(-1,5,-3,minecraft:iron_ore)
B(-1,6,-3,minecraft:stone)
B(-1,7,-3,minecraft:spruce_leaves)
B(-1,2,-2,minecraft:stone)
B(-1,3,-2,minecraft:stone)
B(-1,4,-2,minecraft:stone)
B(-1,5,-2,minecraft:iron_ore)
B(-1,6,-2,minecraft:stone)
B(-1,7,-2,minecraft:spruce_log)
B(-1,8,-2,minecraft:spruce_leaves)
B(-1,2,-1,minecraft:iron_ore)
B(-1,3,-1,minecraft:iron_ore)
B(-1,4,-1,minecraft:stone)
B(-1,5,-1,minecraft:iron_ore)
B(-1,6,-1,minecraft:stone)
B(-1,7,-1,minecraft:stone)
B(-1,8,-1,minecraft:stone)
B(-1,9,-1,minecraft:grass_block)
B(-1,10,-1,minecraft:red_tulip)
B(-1,0,0,minecraft:stone)
B(-1,1,0,minecraft:iron_ore)
B(-1,2,0,minecraft:iron_ore)
B(-1,3,0,minecraft:stone)
B(-1,4,0,minecraft:iron_ore)
B(-1,5,0,minecraft:iron_ore)
B(-1,6,0,minecraft:iron_ore)
B(-1,7,0,minecraft:stone)
B(-1,8,0,minecraft:stone)
B(-1,9,0,minecraft:stone)
B(-1,0,1,minecraft:stone)
B(-1,1,1,minecraft:stone)
B(-1,2,1,minecraft:iron_ore)
B(-1,3,1,minecraft:stone)
B(-1,4,1,minecraft:iron_ore)
B(-1,5,1,minecraft:stone)
B(-1,6,1,minecraft:iron_ore)
B(-1,7,1,minecraft:iron_ore)
B(-1,8,1,minecraft:iron_ore)
B(-1,0,2,minecraft:stone)
B(-1,1,2,minecraft:stone)
B(-1,2,2,minecraft:stone)
B(-1,3,2,minecraft:stone)
B(-1,4,2,minecraft:stone)
B(-1,5,2,minecraft:iron_ore)
B(-1,6,2,minecraft:stone)
B(-1,7,2,minecraft:stone)
B(-1,8,2,minecraft:grass_block)
B(-1,9,2,minecraft:fern)
B(-1,0,3,minecraft:iron_ore)
B(-1,1,3,minecraft:stone)
B(-1,2,3,minecraft:stone)
B(-1,3,3,minecraft:stone)
B(-1,4,3,minecraft:stone)
B(-1,5,3,minecraft:iron_ore)
B(-1,6,3,minecraft:iron_ore)
B(-1,1,4,minecraft:stone)
B(-1,3,4,minecraft:stone)
B(-1,4,4,minecraft:stone)
B(-1,5,4,minecraft:iron_ore)
B(0,3,-5,minecraft:iron_ore)
B(0,4,-5,minecraft:iron_ore)
B(0,5,-5,minecraft:stone)
B(0,6,-5,minecraft:grass_block)
B(0,7,-5,minecraft:oxeye_daisy)
B(0,2,-4,minecraft:stone)
B(0,3,-4,minecraft:stone)
B(0,4,-4,minecraft:iron_ore)
B(0,5,-4,minecraft:stone)
B(0,6,-4,minecraft:iron_ore)
B(0,2,-3,minecraft:iron_ore)
B(0,3,-3,minecraft:stone)
B(0,4,-3,minecraft:stone)
B(0,5,-3,minecraft:stone)
B(0,6,-3,minecraft:stone)
B(0,7,-3,minecraft:grass_block)
B(0,8,-3,minecraft:fern)
B(0,2,-2,minecraft:stone)
B(0,3,-2,minecraft:stone)
B(0,4,-2,minecraft:stone)
B(0,5,-2,minecraft:iron_ore)
B(0,6,-2,minecraft:stone)
B(0,7,-2,minecraft:iron_ore)
B(0,8,-2,minecraft:stone)
B(0,0,-1,minecraft:iron_ore)
B(0,2,-1,minecraft:stone)
B(0,3,-1,minecraft:stone)
B(0,4,-1,minecraft:stone)
B(0,5,-1,minecraft:stone)
B(0,6,-1,minecraft:stone)
B(0,7,-1,minecraft:stone)
B(0,8,-1,minecraft:iron_ore)
B(0,9,-1,minecraft:stone)
B(0,0,0,minecraft:stone)
B(0,1,0,minecraft:stone)
B(0,2,0,minecraft:stone)
B(0,3,0,minecraft:stone)
B(0,4,0,minecraft:stone)
B(0,5,0,minecraft:iron_ore)
B(0,6,0,minecraft:iron_ore)
B(0,7,0,minecraft:stone)
B(0,8,0,minecraft:stone)
B(0,9,0,minecraft:stone)
B(0,0,1,minecraft:stone)
B(0,1,1,minecraft:iron_ore)
B(0,2,1,minecraft:iron_ore)
B(0,3,1,minecraft:stone)
B(0,4,1,minecraft:stone)
B(0,5,1,minecraft:stone)
B(0,6,1,minecraft:stone)
B(0,7,1,minecraft:stone)
B(0,8,1,minecraft:stone)
B(0,9,1,minecraft:stone)
B(0,0,2,minecraft:stone)
B(0,1,2,minecraft:stone)
B(0,2,2,minecraft:stone)
B(0,3,2,minecraft:stone)
B(0,4,2,minecraft:iron_ore)
B(0,5,2,minecraft:stone)
B(0,6,2,minecraft:stone)
B(0,7,2,minecraft:stone)
B(0,8,2,minecraft:stone)
B(0,0,3,minecraft:stone)
B(0,1,3,minecraft:stone)
B(0,2,3,minecraft:stone)
B(0,3,3,minecraft:stone)
B(0,4,3,minecraft:iron_ore)
B(0,5,3,minecraft:iron_ore)
B(0,6,3,minecraft:stone)
B(0,7,3,minecraft:grass_block)
B(0,8,3,minecraft:oxeye_daisy)
B(0,0,4,minecraft:iron_ore)
B(0,1,4,minecraft:stone)
B(0,2,4,minecraft:stone)
B(0,4,4,minecraft:stone)
B(0,5,4,minecraft:stone)
B(0,6,4,minecraft:grass_block)
B(0,7,4,minecraft:fern)
B(1,4,-5,minecraft:stone)
B(1,5,-5,minecraft:grass_block)
B(1,6,-5,minecraft:oxeye_daisy)
B(1,3,-4,minecraft:stone)
B(1,4,-4,minecraft:stone)
B(1,5,-4,minecraft:stone)
B(1,6,-4,minecraft:grass_block)
B(1,7,-4,minecraft:large_fern)
B(1,8,-4,minecraft:sunflower)
B(1,2,-3,minecraft:iron_ore)
B(1,3,-3,minecraft:stone)
B(1,4,-3,minecraft:stone)
B(1,5,-3,minecraft:stone)
B(1,6,-3,minecraft:stone)
B(1,7,-3,minecraft:grass_block)
B(1,8,-3,minecraft:oxeye_daisy)
B(1,3,-2,minecraft:stone)
B(1,4,-2,minecraft:stone)
B(1,5,-2,minecraft:stone)
B(1,6,-2,minecraft:iron_ore)
B(1,7,-2,minecraft:iron_ore)
B(1,8,-2,minecraft:spruce_leaves[distance=3,persistent=false])
B(1,3,-1,minecraft:stone)
B(1,4,-1,minecraft:stone)
B(1,5,-1,minecraft:iron_ore)
B(1,6,-1,minecraft:stone)
B(1,7,-1,minecraft:iron_ore)
B(1,8,-1,minecraft:stone)
B(1,9,-1,minecraft:spruce_leaves[distance=7,persistent=true])
B(1,0,0,minecraft:stone)
B(1,1,0,minecraft:stone)
B(1,2,0,minecraft:stone)
B(1,3,0,minecraft:iron_ore)
B(1,4,0,minecraft:iron_ore)
B(1,5,0,minecraft:stone)
B(1,6,0,minecraft:stone)
B(1,7,0,minecraft:iron_ore)
B(1,8,0,minecraft:stone)
B(1,9,0,minecraft:iron_ore)
B(1,0,1,minecraft:stone)
B(1,1,1,minecraft:stone)
B(1,2,1,minecraft:stone)
B(1,3,1,minecraft:stone)
B(1,4,1,minecraft:stone)
B(1,5,1,minecraft:stone)
B(1,6,1,minecraft:stone)
B(1,7,1,minecraft:iron_ore)
B(1,8,1,minecraft:stone)
B(1,0,2,minecraft:stone)
B(1,1,2,minecraft:stone)
B(1,2,2,minecraft:iron_ore)
B(1,3,2,minecraft:stone)
B(1,4,2,minecraft:stone)
B(1,5,2,minecraft:stone)
B(1,6,2,minecraft:stone)
B(1,7,2,minecraft:iron_ore)
B(1,8,2,minecraft:spruce_leaves[distance=2,persistent=false])
B(1,0,3,minecraft:stone)
B(1,1,3,minecraft:stone)
B(1,2,3,minecraft:stone)
B(1,3,3,minecraft:stone)
B(1,4,3,minecraft:stone)
B(1,5,3,minecraft:iron_ore)
B(1,6,3,minecraft:stone)
B(1,7,3,minecraft:stone)
B(1,1,4,minecraft:iron_ore)
B(1,4,4,minecraft:iron_ore)
B(1,5,4,minecraft:stone)
B(1,6,4,minecraft:stone)
B(2,4,-4,minecraft:stone)
B(2,5,-4,minecraft:grass_block)
B(2,6,-4,minecraft:oxeye_daisy)
B(2,3,-3,minecraft:stone)
B(2,4,-3,minecraft:stone)
B(2,5,-3,minecraft:iron_ore)
B(2,6,-3,minecraft:stone)
B(2,3,-2,minecraft:stone)
B(2,4,-2,minecraft:stone)
B(2,5,-2,minecraft:iron_ore)
B(2,6,-2,minecraft:iron_ore)
B(2,7,-2,minecraft:stone)
B(2,8,-2,minecraft:spruce_leaves[distance=2,persistent=false])
B(2,3,-1,minecraft:iron_ore)
B(2,4,-1,minecraft:iron_ore)
B(2,5,-1,minecraft:iron_ore)
B(2,6,-1,minecraft:stone)
B(2,7,-1,minecraft:spruce_log)
B(2,8,-1,minecraft:spruce_leaves)
B(2,2,0,minecraft:stone)
B(2,3,0,minecraft:iron_ore)
B(2,4,0,minecraft:stone)
B(2,5,0,minecraft:stone)
B(2,6,0,minecraft:iron_ore)
B(2,7,0,minecraft:stone)
B(2,8,0,minecraft:stone)
B(2,0,1,minecraft:stone)
B(2,1,1,minecraft:stone)
B(2,2,1,minecraft:stone)
B(2,3,1,minecraft:iron_ore)
B(2,4,1,minecraft:stone)
B(2,5,1,minecraft:stone)
B(2,6,1,minecraft:iron_ore)
B(2,7,1,minecraft:iron_ore)
B(2,8,1,minecraft:grass_block)
B(2,9,1,minecraft:red_tulip)
B(2,0,2,minecraft:iron_ore)
B(2,1,2,minecraft:stone)
B(2,2,2,minecraft:stone)
B(2,3,2,minecraft:stone)
B(2,4,2,minecraft:iron_ore)
B(2,5,2,minecraft:stone)
B(2,6,2,minecraft:stone)
B(2,7,2,minecraft:spruce_log)
B(2,8,2,minecraft:spruce_leaves)
B(2,1,3,minecraft:stone)
B(2,3,3,minecraft:stone)
B(2,4,3,minecraft:stone)
B(2,5,3,minecraft:iron_ore)
B(2,6,3,minecraft:iron_ore)
B(2,7,3,minecraft:grass_block)
B(2,8,3,minecraft:spruce_leaves[distance=2,persistent=false])
B(2,5,4,minecraft:stone)
B(2,6,4,minecraft:grass_block)
B(2,7,4,minecraft:red_tulip)
B(3,5,-3,minecraft:stone)
B(3,6,-3,minecraft:grass_block)
B(3,7,-3,minecraft:oxeye_daisy)
B(3,4,-2,minecraft:stone)
B(3,5,-2,minecraft:iron_ore)
B(3,6,-2,minecraft:stone)
B(3,7,-2,minecraft:grass_block)
B(3,8,-2,minecraft:oxeye_daisy)
B(3,3,-1,minecraft:stone)
B(3,4,-1,minecraft:stone)
B(3,5,-1,minecraft:stone)
B(3,6,-1,minecraft:stone)
B(3,7,-1,minecraft:iron_ore)
B(3,3,0,minecraft:stone)
B(3,4,0,minecraft:stone)
B(3,5,0,minecraft:stone)
B(3,6,0,minecraft:stone)
B(3,7,0,minecraft:grass_block)
B(3,8,0,minecraft:oxeye_daisy)
B(3,2,1,minecraft:iron_ore)
B(3,3,1,minecraft:stone)
B(3,4,1,minecraft:stone)
B(3,5,1,minecraft:iron_ore)
B(3,6,1,minecraft:stone)
B(3,7,1,minecraft:grass_block)
B(3,8,1,minecraft:red_tulip)
B(3,3,2,minecraft:stone)
B(3,4,2,minecraft:stone)
B(3,5,2,minecraft:stone)
B(3,6,2,minecraft:stone)
B(3,7,2,minecraft:spruce_leaves)
B(3,4,3,minecraft:iron_ore)
B(3,5,3,minecraft:stone)
B(3,6,3,minecraft:grass_block)
B(4,5,-2,minecraft:stone)
B(4,6,-2,minecraft:grass_block)
B(4,7,-2,minecraft:oxeye_daisy)
B(4,4,-1,minecraft:iron_ore)
B(4,5,-1,minecraft:iron_ore)
B(4,6,-1,minecraft:stone)
B(4,4,0,minecraft:stone)
B(4,5,0,minecraft:stone)
B(4,6,0,minecraft:grass_block)
B(4,7,0,minecraft:red_tulip)
B(4,3,1,minecraft:stone)
B(4,4,1,minecraft:stone)
B(4,5,1,minecraft:iron_ore)
B(4,4,2,minecraft:stone)

#######################################################################
# +-----------------------------------------------------------------+ #
# |                            BO3 checks                           | #
# +-----------------------------------------------------------------+ #
#######################################################################

BlockCheck(0,-1,0,otg:dirt,otg:stone,minecraft:grass_block,minecraft:podzol,minecraft:snow)

#######################################################################
# +-----------------------------------------------------------------+ #
# |                             Branches                            | #
# +-----------------------------------------------------------------+ #
#######################################################################


#######################################################################
# +-----------------------------------------------------------------+ #
# |                             Entities                            | #
# +-----------------------------------------------------------------+ #
#######################################################################

