
#######################################################################
# +-----------------------------------------------------------------+ #
# |                            BO3 object                           | #
# +-----------------------------------------------------------------+ #
#######################################################################

Author: NLBlackEagle

Description: No description given

Version: 3

SettingsMode: WriteWithoutComments


#######################################################################
# +-----------------------------------------------------------------+ #
# |                          Main settings                          | #
# +-----------------------------------------------------------------+ #
#######################################################################

Tree: true

Frequency: 1

Rarity: 4.0

RotateRandomly: true

SpawnHeight: highestBlock

SpawnHeightOffset: 0

SpawnHeightVariance: 0

##############################
# Height Limits for the BO3. #
##############################

MinHeight: 0

MaxHeight: 80

######################
# Extrusion settings #
######################

ExtrudeMode: None

ExtrudeThroughBlocks: otg:air

MaxBranchDepth: 10


#######################################################################
# +-----------------------------------------------------------------+ #
# |                      Source block settings                      | #
# +-----------------------------------------------------------------+ #
#######################################################################

SourceBlocks: otg:air,otg:stone,otg:dirt,minecraft:grass_block

MaxPercentageOutsideSourceBlock: 0

OutsideSourceBlock: placeAnyway

DoReplaceBlocks: true

IsOTGPlus: false


#######################################################################
# +-----------------------------------------------------------------+ #
# |                              Blocks                             | #
# +-----------------------------------------------------------------+ #
#######################################################################

B(-7,-3,0,minecraft:granite)
B(-7,-2,0,minecraft:red_terracotta)
B(-7,-1,0,minecraft:red_terracotta)
B(-7,0,0,minecraft:red_terracotta)
B(-7,1,0,minecraft:red_terracotta)
B(-6,-3,-1,minecraft:red_terracotta)
B(-6,-2,-1,minecraft:red_terracotta)
B(-6,-1,-1,minecraft:granite)
B(-6,0,-1,minecraft:granite)
B(-6,1,-1,minecraft:granite)
B(-6,2,-1,minecraft:jungle_leaves[distance=7,persistent=true])
B(-6,3,-1,minecraft:jungle_leaves[distance=7,persistent=true])
B(-6,4,-1,minecraft:jungle_leaves[distance=7,persistent=true])
B(-6,5,-1,minecraft:jungle_leaves[distance=7,persistent=true])
B(-6,-4,0,minecraft:granite)
B(-6,-3,0,minecraft:red_terracotta)
B(-6,-2,0,minecraft:granite)
B(-6,-1,0,minecraft:red_terracotta)
B(-6,0,0,minecraft:granite)
B(-6,1,0,minecraft:granite)
B(-6,2,0,minecraft:granite)
B(-6,3,0,minecraft:granite)
B(-6,4,0,minecraft:granite)
B(-6,5,0,minecraft:granite)
B(-6,6,0,minecraft:jungle_leaves[distance=7,persistent=true])
B(-6,-5,1,minecraft:red_terracotta)
B(-6,-4,1,minecraft:granite)
B(-6,-3,1,minecraft:granite)
B(-6,-2,1,minecraft:granite)
B(-6,-1,1,minecraft:granite)
B(-6,0,1,minecraft:granite)
B(-6,1,1,minecraft:granite)
B(-6,2,1,minecraft:granite)
B(-6,3,1,minecraft:granite)
B(-6,4,1,minecraft:granite)
B(-6,5,1,minecraft:jungle_leaves[distance=7,persistent=true])
B(-6,4,2,minecraft:jungle_leaves[distance=7,persistent=true])
B(-5,-4,-1,minecraft:granite)
B(-5,-3,-1,minecraft:red_terracotta)
B(-5,-2,-1,minecraft:granite)
B(-5,-1,-1,minecraft:granite)
B(-5,0,-1,minecraft:granite)
B(-5,1,-1,minecraft:granite)
B(-5,2,-1,minecraft:granite)
B(-5,3,-1,minecraft:granite)
B(-5,4,-1,minecraft:granite)
B(-5,5,-1,minecraft:granite)
B(-5,6,-1,minecraft:granite)
B(-5,-5,0,minecraft:granite)
B(-5,-4,0,minecraft:granite)
B(-5,-3,0,minecraft:granite)
B(-5,-2,0,minecraft:granite)
B(-5,-1,0,minecraft:granite)
B(-5,0,0,minecraft:granite)
B(-5,1,0,minecraft:granite)
B(-5,2,0,minecraft:granite)
B(-5,3,0,minecraft:granite)
B(-5,4,0,minecraft:granite)
B(-5,5,0,minecraft:granite)
B(-5,6,0,minecraft:granite)
B(-5,7,0,minecraft:granite)
B(-5,-5,1,minecraft:red_terracotta)
B(-5,-4,1,minecraft:granite)
B(-5,-3,1,minecraft:granite)
B(-5,-2,1,minecraft:granite)
B(-5,-1,1,minecraft:red_terracotta)
B(-5,0,1,minecraft:granite)
B(-5,1,1,minecraft:granite)
B(-5,2,1,minecraft:granite)
B(-5,3,1,minecraft:granite)
B(-5,4,1,minecraft:granite)
B(-5,5,1,minecraft:granite)
B(-5,6,1,minecraft:granite)
B(-5,7,1,minecraft:granite)
B(-5,-6,2,minecraft:red_terracotta)
B(-5,-5,2,minecraft:red_terracotta)
B(-5,-4,2,minecraft:red_terracotta)
B(-5,-3,2,minecraft:granite)
B(-5,-2,2,minecraft:red_terracotta)
B(-5,-1,2,minecraft:red_terracotta)
B(-5,0,2,minecraft:granite)
B(-5,1,2,minecraft:granite)
B(-5,2,2,minecraft:granite)
B(-5,3,2,minecraft:granite)
B(-5,4,2,minecraft:granite)
B(-5,5,2,minecraft:granite)
B(-5,6,2,minecraft:jungle_leaves[distance=7,persistent=true])
B(-5,0,3,minecraft:jungle_leaves[distance=7,persistent=true])
B(-5,1,3,minecraft:jungle_leaves[distance=7,persistent=true])
B(-5,2,3,minecraft:jungle_leaves[distance=7,persistent=true])
B(-5,3,3,minecraft:jungle_leaves[distance=7,persistent=true])
B(-4,-3,-3,minecraft:granite)
B(-4,-2,-3,minecraft:red_terracotta)
B(-4,-1,-3,minecraft:granite)
B(-4,0,-3,minecraft:granite)
B(-4,1,-3,minecraft:red_terracotta)
B(-4,2,-3,minecraft:granite)
B(-4,3,-3,minecraft:granite)
B(-4,4,-3,minecraft:granite)
B(-4,-3,-2,minecraft:granite)
B(-4,-2,-2,minecraft:granite)
B(-4,-1,-2,minecraft:granite)
B(-4,0,-2,minecraft:granite)
B(-4,1,-2,minecraft:granite)
B(-4,2,-2,minecraft:granite)
B(-4,3,-2,minecraft:granite)
B(-4,4,-2,minecraft:granite)
B(-4,5,-2,minecraft:granite)
B(-4,6,-2,minecraft:granite)
B(-4,-3,-1,minecraft:granite)
B(-4,-2,-1,minecraft:granite)
B(-4,-1,-1,minecraft:granite)
B(-4,0,-1,minecraft:granite)
B(-4,1,-1,minecraft:granite)
B(-4,2,-1,minecraft:granite)
B(-4,3,-1,minecraft:granite)
B(-4,4,-1,minecraft:granite)
B(-4,5,-1,minecraft:granite)
B(-4,6,-1,minecraft:granite)
B(-4,7,-1,minecraft:granite)
B(-4,8,-1,minecraft:jungle_leaves[distance=7,persistent=true])
B(-4,-6,0,minecraft:granite)
B(-4,-5,0,minecraft:granite)
B(-4,-4,0,minecraft:granite)
B(-4,-3,0,minecraft:granite)
B(-4,-2,0,minecraft:granite)
B(-4,-1,0,minecraft:granite)
B(-4,0,0,minecraft:granite)
B(-4,1,0,minecraft:granite)
B(-4,2,0,minecraft:granite)
B(-4,3,0,minecraft:granite)
B(-4,4,0,minecraft:granite)
B(-4,5,0,minecraft:granite)
B(-4,6,0,minecraft:granite)
B(-4,7,0,minecraft:granite)
B(-4,8,0,minecraft:granite)
B(-4,9,0,minecraft:granite)
B(-4,10,0,minecraft:granite)
B(-4,-7,1,minecraft:granite)
B(-4,-6,1,minecraft:granite)
B(-4,-5,1,minecraft:granite)
B(-4,-4,1,minecraft:red_terracotta)
B(-4,-3,1,minecraft:granite)
B(-4,-2,1,minecraft:granite)
B(-4,-1,1,minecraft:granite)
B(-4,0,1,minecraft:granite)
B(-4,1,1,minecraft:granite)
B(-4,2,1,minecraft:granite)
B(-4,3,1,minecraft:granite)
B(-4,4,1,minecraft:granite)
B(-4,5,1,minecraft:granite)
B(-4,6,1,minecraft:granite)
B(-4,7,1,minecraft:granite)
B(-4,8,1,minecraft:granite)
B(-4,9,1,minecraft:granite)
B(-4,-5,2,minecraft:red_terracotta)
B(-4,-4,2,minecraft:red_terracotta)
B(-4,-3,2,minecraft:red_terracotta)
B(-4,-2,2,minecraft:red_terracotta)
B(-4,-1,2,minecraft:red_terracotta)
B(-4,0,2,minecraft:granite)
B(-4,1,2,minecraft:granite)
B(-4,2,2,minecraft:granite)
B(-4,3,2,minecraft:granite)
B(-4,4,2,minecraft:granite)
B(-4,5,2,minecraft:granite)
B(-4,6,2,minecraft:granite)
B(-4,7,2,minecraft:jungle_leaves[distance=7,persistent=true])
B(-4,8,2,minecraft:jungle_leaves[distance=7,persistent=true])
B(-4,-5,3,minecraft:granite)
B(-4,-4,3,minecraft:red_terracotta)
B(-4,-3,3,minecraft:red_terracotta)
B(-4,-2,3,minecraft:red_terracotta)
B(-4,-1,3,minecraft:red_terracotta)
B(-4,0,3,minecraft:red_terracotta)
B(-4,1,3,minecraft:granite)
B(-4,2,3,minecraft:granite)
B(-4,3,3,minecraft:granite)
B(-4,4,3,minecraft:granite)
B(-4,5,3,minecraft:jungle_leaves[distance=7,persistent=true])
B(-4,6,3,minecraft:jungle_leaves[distance=7,persistent=true])
B(-4,0,4,minecraft:jungle_leaves[distance=7,persistent=true])
B(-4,1,4,minecraft:jungle_leaves[distance=7,persistent=true])
B(-4,2,4,minecraft:jungle_leaves[distance=7,persistent=true])
B(-3,0,-4,minecraft:jungle_leaves[distance=7,persistent=true])
B(-3,1,-4,minecraft:jungle_leaves[distance=7,persistent=true])
B(-3,2,-4,minecraft:jungle_leaves[distance=7,persistent=true])
B(-3,3,-4,minecraft:jungle_leaves[distance=7,persistent=true])
B(-3,4,-4,minecraft:jungle_leaves[distance=7,persistent=true])
B(-3,5,-4,minecraft:jungle_leaves[distance=7,persistent=true])
B(-3,-4,-3,minecraft:granite)
B(-3,-3,-3,minecraft:red_terracotta)
B(-3,-2,-3,minecraft:red_terracotta)
B(-3,-1,-3,minecraft:red_terracotta)
B(-3,0,-3,minecraft:red_terracotta)
B(-3,1,-3,minecraft:red_terracotta)
B(-3,2,-3,minecraft:red_terracotta)
B(-3,3,-3,minecraft:granite)
B(-3,4,-3,minecraft:granite)
B(-3,5,-3,minecraft:granite)
B(-3,6,-3,minecraft:red_terracotta)
B(-3,-3,-2,minecraft:granite)
B(-3,-2,-2,minecraft:red_terracotta)
B(-3,-1,-2,minecraft:granite)
B(-3,0,-2,minecraft:granite)
B(-3,1,-2,minecraft:red_terracotta)
B(-3,2,-2,minecraft:granite)
B(-3,3,-2,minecraft:granite)
B(-3,4,-2,minecraft:granite)
B(-3,5,-2,minecraft:granite)
B(-3,6,-2,minecraft:red_terracotta)
B(-3,7,-2,minecraft:red_terracotta)
B(-3,8,-2,minecraft:red_terracotta)
B(-3,9,-2,minecraft:jungle_leaves[distance=7,persistent=true])
B(-3,-6,-1,minecraft:granite)
B(-3,-4,-1,minecraft:granite)
B(-3,-3,-1,minecraft:granite)
B(-3,-2,-1,minecraft:granite)
B(-3,-1,-1,minecraft:granite)
B(-3,0,-1,minecraft:granite)
B(-3,1,-1,minecraft:granite)
B(-3,2,-1,minecraft:granite)
B(-3,3,-1,minecraft:granite)
B(-3,4,-1,minecraft:granite)
B(-3,5,-1,minecraft:granite)
B(-3,6,-1,minecraft:granite)
B(-3,7,-1,minecraft:granite)
B(-3,8,-1,minecraft:red_terracotta)
B(-3,9,-1,minecraft:granite)
B(-3,10,-1,minecraft:granite)
B(-3,-6,0,minecraft:granite)
B(-3,-5,0,minecraft:granite)
B(-3,-4,0,minecraft:granite)
B(-3,-3,0,minecraft:granite)
B(-3,-2,0,minecraft:granite)
B(-3,-1,0,minecraft:granite)
B(-3,0,0,minecraft:granite)
B(-3,1,0,minecraft:granite)
B(-3,2,0,minecraft:granite)
B(-3,3,0,minecraft:granite)
B(-3,4,0,minecraft:granite)
B(-3,5,0,minecraft:granite)
B(-3,6,0,minecraft:granite)
B(-3,7,0,minecraft:granite)
B(-3,8,0,minecraft:granite)
B(-3,9,0,minecraft:granite)
B(-3,10,0,minecraft:granite)
B(-3,11,0,minecraft:granite)
B(-3,-6,1,minecraft:granite)
B(-3,-5,1,minecraft:granite)
B(-3,-4,1,minecraft:granite)
B(-3,-3,1,minecraft:granite)
B(-3,-2,1,minecraft:granite)
B(-3,-1,1,minecraft:granite)
B(-3,0,1,minecraft:granite)
B(-3,1,1,minecraft:granite)
B(-3,2,1,minecraft:granite)
B(-3,3,1,minecraft:granite)
B(-3,4,1,minecraft:granite)
B(-3,5,1,minecraft:granite)
B(-3,6,1,minecraft:granite)
B(-3,7,1,minecraft:granite)
B(-3,8,1,minecraft:granite)
B(-3,9,1,minecraft:granite)
B(-3,10,1,minecraft:granite)
B(-3,-6,2,minecraft:granite)
B(-3,-5,2,minecraft:granite)
B(-3,-4,2,minecraft:red_terracotta)
B(-3,-3,2,minecraft:granite)
B(-3,-2,2,minecraft:granite)
B(-3,-1,2,minecraft:granite)
B(-3,0,2,minecraft:granite)
B(-3,1,2,minecraft:granite)
B(-3,2,2,minecraft:granite)
B(-3,3,2,minecraft:granite)
B(-3,4,2,minecraft:granite)
B(-3,5,2,minecraft:granite)
B(-3,6,2,minecraft:granite)
B(-3,7,2,minecraft:granite)
B(-3,8,2,minecraft:granite)
B(-3,9,2,minecraft:jungle_leaves[distance=7,persistent=true])
B(-3,-5,3,minecraft:granite)
B(-3,-4,3,minecraft:granite)
B(-3,-3,3,minecraft:granite)
B(-3,-2,3,minecraft:red_terracotta)
B(-3,-1,3,minecraft:granite)
B(-3,0,3,minecraft:granite)
B(-3,1,3,minecraft:granite)
B(-3,2,3,minecraft:granite)
B(-3,3,3,minecraft:granite)
B(-3,4,3,minecraft:granite)
B(-3,5,3,minecraft:granite)
B(-3,6,3,minecraft:granite)
B(-3,7,3,minecraft:jungle_leaves[distance=7,persistent=true])
B(-3,-5,4,minecraft:granite)
B(-3,-4,4,minecraft:granite)
B(-3,-3,4,minecraft:granite)
B(-3,-2,4,minecraft:granite)
B(-3,-1,4,minecraft:granite)
B(-3,0,4,minecraft:granite)
B(-3,1,4,minecraft:granite)
B(-3,2,4,minecraft:jungle_leaves[distance=7,persistent=true])
B(-3,3,4,minecraft:jungle_leaves[distance=7,persistent=true])
B(-3,4,4,minecraft:jungle_leaves[distance=7,persistent=true])
B(-2,-4,-4,minecraft:red_terracotta)
B(-2,-3,-4,minecraft:granite)
B(-2,-2,-4,minecraft:red_terracotta)
B(-2,-1,-4,minecraft:granite)
B(-2,0,-4,minecraft:granite)
B(-2,1,-4,minecraft:red_terracotta)
B(-2,2,-4,minecraft:red_terracotta)
B(-2,3,-4,minecraft:red_terracotta)
B(-2,4,-4,minecraft:red_terracotta)
B(-2,5,-4,minecraft:red_terracotta)
B(-2,6,-4,minecraft:jungle_leaves[distance=7,persistent=true])
B(-2,-5,-3,minecraft:red_terracotta)
B(-2,-4,-3,minecraft:granite)
B(-2,-3,-3,minecraft:granite)
B(-2,-2,-3,minecraft:red_terracotta)
B(-2,-1,-3,minecraft:granite)
B(-2,0,-3,minecraft:granite)
B(-2,1,-3,minecraft:red_terracotta)
B(-2,2,-3,minecraft:granite)
B(-2,3,-3,minecraft:red_terracotta)
B(-2,4,-3,minecraft:granite)
B(-2,5,-3,minecraft:red_terracotta)
B(-2,6,-3,minecraft:granite)
B(-2,7,-3,minecraft:granite)
B(-2,-6,-2,minecraft:granite)
B(-2,-5,-2,minecraft:granite)
B(-2,-4,-2,minecraft:granite)
B(-2,-3,-2,minecraft:granite)
B(-2,-2,-2,minecraft:granite)
B(-2,-1,-2,minecraft:granite)
B(-2,0,-2,minecraft:granite)
B(-2,1,-2,minecraft:granite)
B(-2,2,-2,minecraft:granite)
B(-2,3,-2,minecraft:granite)
B(-2,4,-2,minecraft:granite)
B(-2,5,-2,minecraft:granite)
B(-2,6,-2,minecraft:granite)
B(-2,7,-2,minecraft:red_terracotta)
B(-2,8,-2,minecraft:granite)
B(-2,9,-2,minecraft:granite)
B(-2,10,-2,minecraft:granite)
B(-2,11,-2,minecraft:granite)
B(-2,-6,-1,minecraft:granite)
B(-2,-5,-1,minecraft:granite)
B(-2,-4,-1,minecraft:granite)
B(-2,-3,-1,minecraft:granite)
B(-2,-2,-1,minecraft:granite)
B(-2,-1,-1,minecraft:granite)
B(-2,0,-1,minecraft:granite)
B(-2,1,-1,minecraft:granite)
B(-2,2,-1,minecraft:granite)
B(-2,3,-1,minecraft:granite)
B(-2,4,-1,minecraft:granite)
B(-2,5,-1,minecraft:granite)
B(-2,6,-1,minecraft:granite)
B(-2,7,-1,minecraft:granite)
B(-2,8,-1,minecraft:granite)
B(-2,9,-1,minecraft:granite)
B(-2,10,-1,minecraft:granite)
B(-2,11,-1,minecraft:granite)
B(-2,12,-1,minecraft:granite)
B(-2,-6,0,minecraft:granite)
B(-2,-5,0,minecraft:granite)
B(-2,-4,0,minecraft:granite)
B(-2,-3,0,minecraft:granite)
B(-2,-2,0,minecraft:granite)
B(-2,-1,0,minecraft:granite)
B(-2,0,0,minecraft:granite)
B(-2,1,0,minecraft:granite)
B(-2,2,0,minecraft:granite)
B(-2,3,0,minecraft:granite)
B(-2,4,0,minecraft:granite)
B(-2,5,0,minecraft:granite)
B(-2,6,0,minecraft:granite)
B(-2,7,0,minecraft:granite)
B(-2,8,0,minecraft:granite)
B(-2,9,0,minecraft:granite)
B(-2,10,0,minecraft:granite)
B(-2,11,0,minecraft:granite)
B(-2,12,0,minecraft:granite)
B(-2,-6,1,minecraft:granite)
B(-2,-5,1,minecraft:granite)
B(-2,-4,1,minecraft:granite)
B(-2,-3,1,minecraft:granite)
B(-2,-2,1,minecraft:granite)
B(-2,-1,1,minecraft:granite)
B(-2,0,1,minecraft:granite)
B(-2,1,1,minecraft:granite)
B(-2,2,1,minecraft:granite)
B(-2,3,1,minecraft:granite)
B(-2,4,1,minecraft:granite)
B(-2,5,1,minecraft:granite)
B(-2,6,1,minecraft:granite)
B(-2,7,1,minecraft:granite)
B(-2,8,1,minecraft:granite)
B(-2,9,1,minecraft:granite)
B(-2,10,1,minecraft:granite)
B(-2,11,1,minecraft:jungle_leaves[distance=7,persistent=true])
B(-2,-6,2,minecraft:granite)
B(-2,-5,2,minecraft:granite)
B(-2,-4,2,minecraft:granite)
B(-2,-3,2,minecraft:granite)
B(-2,-2,2,minecraft:granite)
B(-2,-1,2,minecraft:granite)
B(-2,0,2,minecraft:granite)
B(-2,1,2,minecraft:granite)
B(-2,2,2,minecraft:granite)
B(-2,3,2,minecraft:granite)
B(-2,4,2,minecraft:granite)
B(-2,5,2,minecraft:granite)
B(-2,6,2,minecraft:granite)
B(-2,7,2,minecraft:granite)
B(-2,8,2,minecraft:granite)
B(-2,9,2,minecraft:jungle_leaves[distance=7,persistent=true])
B(-2,10,2,minecraft:jungle_leaves[distance=7,persistent=true])
B(-2,-5,3,minecraft:granite)
B(-2,-4,3,minecraft:granite)
B(-2,-3,3,minecraft:granite)
B(-2,-2,3,minecraft:granite)
B(-2,-1,3,minecraft:granite)
B(-2,0,3,minecraft:granite)
B(-2,1,3,minecraft:granite)
B(-2,2,3,minecraft:granite)
B(-2,3,3,minecraft:granite)
B(-2,4,3,minecraft:granite)
B(-2,5,3,minecraft:granite)
B(-2,6,3,minecraft:granite)
B(-2,7,3,minecraft:granite)
B(-2,8,3,minecraft:granite)
B(-2,-5,4,minecraft:red_terracotta)
B(-2,-4,4,minecraft:granite)
B(-2,-3,4,minecraft:granite)
B(-2,-2,4,minecraft:granite)
B(-2,-1,4,minecraft:granite)
B(-2,0,4,minecraft:granite)
B(-2,1,4,minecraft:granite)
B(-2,2,4,minecraft:granite)
B(-2,3,4,minecraft:red_terracotta)
B(-2,4,4,minecraft:red_terracotta)
B(-2,5,4,minecraft:red_terracotta)
B(-2,6,4,minecraft:granite)
B(-2,7,4,minecraft:jungle_leaves[distance=7,persistent=true])
B(-1,-2,-4,minecraft:red_terracotta)
B(-1,-1,-4,minecraft:red_terracotta)
B(-1,0,-4,minecraft:red_terracotta)
B(-1,1,-4,minecraft:red_terracotta)
B(-1,2,-4,minecraft:red_terracotta)
B(-1,3,-4,minecraft:red_terracotta)
B(-1,4,-4,minecraft:granite)
B(-1,5,-4,minecraft:red_terracotta)
B(-1,6,-4,minecraft:red_terracotta)
B(-1,7,-4,minecraft:jungle_leaves[distance=7,persistent=true])
B(-1,-6,-3,minecraft:granite)
B(-1,-5,-3,minecraft:granite)
B(-1,-4,-3,minecraft:granite)
B(-1,-3,-3,minecraft:granite)
B(-1,-2,-3,minecraft:red_terracotta)
B(-1,-1,-3,minecraft:granite)
B(-1,0,-3,minecraft:granite)
B(-1,1,-3,minecraft:red_terracotta)
B(-1,2,-3,minecraft:red_terracotta)
B(-1,3,-3,minecraft:granite)
B(-1,4,-3,minecraft:granite)
B(-1,5,-3,minecraft:granite)
B(-1,6,-3,minecraft:red_terracotta)
B(-1,7,-3,minecraft:granite)
B(-1,8,-3,minecraft:granite)
B(-1,9,-3,minecraft:granite)
B(-1,-6,-2,minecraft:granite)
B(-1,-5,-2,minecraft:granite)
B(-1,-4,-2,minecraft:granite)
B(-1,-3,-2,minecraft:granite)
B(-1,-2,-2,minecraft:granite)
B(-1,-1,-2,minecraft:granite)
B(-1,0,-2,minecraft:granite)
B(-1,1,-2,minecraft:granite)
B(-1,2,-2,minecraft:granite)
B(-1,3,-2,minecraft:granite)
B(-1,4,-2,minecraft:granite)
B(-1,5,-2,minecraft:granite)
B(-1,6,-2,minecraft:granite)
B(-1,7,-2,minecraft:granite)
B(-1,8,-2,minecraft:granite)
B(-1,9,-2,minecraft:granite)
B(-1,10,-2,minecraft:granite)
B(-1,11,-2,minecraft:granite)
B(-1,-6,-1,minecraft:granite)
B(-1,-5,-1,minecraft:granite)
B(-1,-4,-1,minecraft:granite)
B(-1,-3,-1,minecraft:granite)
B(-1,-2,-1,minecraft:granite)
B(-1,-1,-1,minecraft:granite)
B(-1,0,-1,minecraft:granite)
B(-1,1,-1,minecraft:granite)
B(-1,2,-1,minecraft:granite)
B(-1,3,-1,minecraft:granite)
B(-1,4,-1,minecraft:granite)
B(-1,5,-1,minecraft:granite)
B(-1,6,-1,minecraft:granite)
B(-1,7,-1,minecraft:granite)
B(-1,8,-1,minecraft:granite)
B(-1,9,-1,minecraft:granite)
B(-1,10,-1,minecraft:granite)
B(-1,11,-1,minecraft:granite)
B(-1,12,-1,minecraft:granite)
B(-1,-6,0,minecraft:granite)
B(-1,-5,0,minecraft:granite)
B(-1,-4,0,minecraft:granite)
B(-1,-3,0,minecraft:granite)
B(-1,-2,0,minecraft:granite)
B(-1,-1,0,minecraft:granite)
B(-1,0,0,minecraft:granite)
B(-1,1,0,minecraft:granite)
B(-1,2,0,minecraft:granite)
B(-1,3,0,minecraft:granite)
B(-1,4,0,minecraft:granite)
B(-1,5,0,minecraft:granite)
B(-1,6,0,minecraft:granite)
B(-1,7,0,minecraft:granite)
B(-1,8,0,minecraft:granite)
B(-1,9,0,minecraft:granite)
B(-1,10,0,minecraft:granite)
B(-1,11,0,minecraft:granite)
B(-1,12,0,minecraft:granite)
B(-1,-6,1,minecraft:granite)
B(-1,-5,1,minecraft:granite)
B(-1,-4,1,minecraft:granite)
B(-1,-3,1,minecraft:granite)
B(-1,-2,1,minecraft:granite)
B(-1,-1,1,minecraft:granite)
B(-1,0,1,minecraft:granite)
B(-1,1,1,minecraft:granite)
B(-1,2,1,minecraft:granite)
B(-1,3,1,minecraft:granite)
B(-1,4,1,minecraft:granite)
B(-1,5,1,minecraft:granite)
B(-1,6,1,minecraft:granite)
B(-1,7,1,minecraft:granite)
B(-1,8,1,minecraft:granite)
B(-1,9,1,minecraft:granite)
B(-1,10,1,minecraft:granite)
B(-1,11,1,minecraft:granite)
B(-1,12,1,minecraft:jungle_leaves[distance=7,persistent=true])
B(-1,-6,2,minecraft:granite)
B(-1,-5,2,minecraft:granite)
B(-1,-4,2,minecraft:granite)
B(-1,-3,2,minecraft:granite)
B(-1,-2,2,minecraft:granite)
B(-1,-1,2,minecraft:granite)
B(-1,0,2,minecraft:granite)
B(-1,1,2,minecraft:granite)
B(-1,2,2,minecraft:granite)
B(-1,3,2,minecraft:granite)
B(-1,4,2,minecraft:granite)
B(-1,5,2,minecraft:granite)
B(-1,6,2,minecraft:granite)
B(-1,7,2,minecraft:granite)
B(-1,8,2,minecraft:granite)
B(-1,9,2,minecraft:granite)
B(-1,10,2,minecraft:granite)
B(-1,11,2,minecraft:red_terracotta)
B(-1,12,2,minecraft:red_terracotta)
B(-1,-5,3,minecraft:red_terracotta)
B(-1,-4,3,minecraft:granite)
B(-1,-3,3,minecraft:granite)
B(-1,-2,3,minecraft:granite)
B(-1,-1,3,minecraft:granite)
B(-1,0,3,minecraft:granite)
B(-1,1,3,minecraft:granite)
B(-1,2,3,minecraft:granite)
B(-1,3,3,minecraft:red_terracotta)
B(-1,4,3,minecraft:red_terracotta)
B(-1,5,3,minecraft:red_terracotta)
B(-1,6,3,minecraft:granite)
B(-1,7,3,minecraft:granite)
B(-1,8,3,minecraft:granite)
B(-1,9,3,minecraft:granite)
B(-1,10,3,minecraft:granite)
B(-1,-4,4,minecraft:red_terracotta)
B(-1,-3,4,minecraft:granite)
B(-1,-2,4,minecraft:granite)
B(-1,-1,4,minecraft:granite)
B(-1,0,4,minecraft:red_terracotta)
B(-1,1,4,minecraft:red_terracotta)
B(-1,2,4,minecraft:red_terracotta)
B(-1,3,4,minecraft:red_terracotta)
B(-1,4,4,minecraft:red_terracotta)
B(-1,5,4,minecraft:red_terracotta)
B(-1,6,4,minecraft:red_terracotta)
B(-1,7,4,minecraft:granite)
B(-1,8,4,minecraft:jungle_leaves[distance=7,persistent=true])
B(0,-1,-4,minecraft:granite)
B(0,0,-4,minecraft:granite)
B(0,1,-4,minecraft:red_terracotta)
B(0,2,-4,minecraft:red_terracotta)
B(0,3,-4,minecraft:granite)
B(0,4,-4,minecraft:granite)
B(0,5,-4,minecraft:granite)
B(0,6,-4,minecraft:red_terracotta)
B(0,7,-4,minecraft:granite)
B(0,8,-4,minecraft:jungle_leaves[distance=7,persistent=true])
B(0,-5,-3,minecraft:granite)
B(0,-3,-3,minecraft:red_terracotta)
B(0,-2,-3,minecraft:granite)
B(0,-1,-3,minecraft:granite)
B(0,0,-3,minecraft:granite)
B(0,1,-3,minecraft:granite)
B(0,2,-3,minecraft:granite)
B(0,3,-3,minecraft:granite)
B(0,4,-3,minecraft:granite)
B(0,5,-3,minecraft:granite)
B(0,6,-3,minecraft:granite)
B(0,7,-3,minecraft:granite)
B(0,8,-3,minecraft:granite)
B(0,9,-3,minecraft:granite)
B(0,-6,-2,minecraft:granite)
B(0,-5,-2,minecraft:granite)
B(0,-4,-2,minecraft:granite)
B(0,-3,-2,minecraft:granite)
B(0,-2,-2,minecraft:granite)
B(0,-1,-2,minecraft:granite)
B(0,0,-2,minecraft:granite)
B(0,1,-2,minecraft:granite)
B(0,2,-2,minecraft:granite)
B(0,3,-2,minecraft:granite)
B(0,4,-2,minecraft:granite)
B(0,5,-2,minecraft:granite)
B(0,6,-2,minecraft:granite)
B(0,7,-2,minecraft:granite)
B(0,8,-2,minecraft:granite)
B(0,9,-2,minecraft:granite)
B(0,10,-2,minecraft:granite)
B(0,11,-2,minecraft:granite)
B(0,-6,-1,minecraft:granite)
B(0,-5,-1,minecraft:granite)
B(0,-4,-1,minecraft:granite)
B(0,-3,-1,minecraft:granite)
B(0,-2,-1,minecraft:granite)
B(0,-1,-1,minecraft:granite)
B(0,0,-1,minecraft:granite)
B(0,1,-1,minecraft:granite)
B(0,2,-1,minecraft:granite)
B(0,3,-1,minecraft:granite)
B(0,4,-1,minecraft:granite)
B(0,5,-1,minecraft:granite)
B(0,6,-1,minecraft:granite)
B(0,7,-1,minecraft:granite)
B(0,8,-1,minecraft:granite)
B(0,9,-1,minecraft:granite)
B(0,10,-1,minecraft:granite)
B(0,11,-1,minecraft:granite)
B(0,-6,0,minecraft:granite)
B(0,-5,0,minecraft:granite)
B(0,-4,0,minecraft:granite)
B(0,-3,0,minecraft:granite)
B(0,-2,0,minecraft:granite)
B(0,-1,0,minecraft:granite)
B(0,0,0,minecraft:granite)
B(0,1,0,minecraft:granite)
B(0,2,0,minecraft:granite)
B(0,3,0,minecraft:granite)
B(0,4,0,minecraft:granite)
B(0,5,0,minecraft:granite)
B(0,6,0,minecraft:granite)
B(0,7,0,minecraft:granite)
B(0,8,0,minecraft:granite)
B(0,9,0,minecraft:granite)
B(0,10,0,minecraft:granite)
B(0,11,0,minecraft:granite)
B(0,12,0,minecraft:jungle_leaves[distance=7,persistent=true])
B(0,-5,1,minecraft:granite)
B(0,-4,1,minecraft:granite)
B(0,-3,1,minecraft:granite)
B(0,-2,1,minecraft:granite)
B(0,-1,1,minecraft:granite)
B(0,0,1,minecraft:granite)
B(0,1,1,minecraft:granite)
B(0,2,1,minecraft:granite)
B(0,3,1,minecraft:granite)
B(0,4,1,minecraft:granite)
B(0,5,1,minecraft:granite)
B(0,6,1,minecraft:granite)
B(0,7,1,minecraft:granite)
B(0,8,1,minecraft:granite)
B(0,9,1,minecraft:granite)
B(0,10,1,minecraft:granite)
B(0,11,1,minecraft:granite)
B(0,12,1,minecraft:jungle_leaves[distance=7,persistent=true])
B(0,-4,2,minecraft:granite)
B(0,-3,2,minecraft:granite)
B(0,-2,2,minecraft:granite)
B(0,-1,2,minecraft:granite)
B(0,0,2,minecraft:granite)
B(0,1,2,minecraft:granite)
B(0,2,2,minecraft:granite)
B(0,3,2,minecraft:granite)
B(0,4,2,minecraft:granite)
B(0,5,2,minecraft:granite)
B(0,6,2,minecraft:granite)
B(0,7,2,minecraft:granite)
B(0,9,2,minecraft:granite)
B(0,10,2,minecraft:granite)
B(0,11,2,minecraft:granite)
B(0,-4,3,minecraft:red_terracotta)
B(0,-3,3,minecraft:granite)
B(0,-2,3,minecraft:granite)
B(0,-1,3,minecraft:granite)
B(0,0,3,minecraft:red_terracotta)
B(0,1,3,minecraft:red_terracotta)
B(0,2,3,minecraft:red_terracotta)
B(0,3,3,minecraft:granite)
B(0,4,3,minecraft:granite)
B(0,5,3,minecraft:granite)
B(0,6,3,minecraft:granite)
B(0,7,3,minecraft:granite)
B(0,8,3,minecraft:granite)
B(0,9,3,minecraft:red_terracotta)
B(0,10,3,minecraft:jungle_leaves[distance=7,persistent=true])
B(0,-4,4,minecraft:red_terracotta)
B(0,-3,4,minecraft:red_terracotta)
B(0,-2,4,minecraft:red_terracotta)
B(0,-1,4,minecraft:red_terracotta)
B(0,0,4,minecraft:red_terracotta)
B(0,1,4,minecraft:red_terracotta)
B(0,2,4,minecraft:red_terracotta)
B(0,3,4,minecraft:red_terracotta)
B(0,4,4,minecraft:red_terracotta)
B(0,5,4,minecraft:red_terracotta)
B(0,6,4,minecraft:granite)
B(0,7,4,minecraft:granite)
B(0,8,4,minecraft:granite)
B(0,9,4,minecraft:jungle_leaves[distance=7,persistent=true])
B(1,-1,-4,minecraft:granite)
B(1,0,-4,minecraft:granite)
B(1,1,-4,minecraft:granite)
B(1,2,-4,minecraft:granite)
B(1,3,-4,minecraft:granite)
B(1,4,-4,minecraft:granite)
B(1,5,-4,minecraft:granite)
B(1,6,-4,minecraft:granite)
B(1,7,-4,minecraft:granite)
B(1,8,-4,minecraft:granite)
B(1,9,-4,minecraft:jungle_leaves[distance=7,persistent=true])
B(1,-4,-3,minecraft:granite)
B(1,-3,-3,minecraft:granite)
B(1,-1,-3,minecraft:granite)
B(1,0,-3,minecraft:granite)
B(1,1,-3,minecraft:granite)
B(1,2,-3,minecraft:granite)
B(1,3,-3,minecraft:granite)
B(1,4,-3,minecraft:granite)
B(1,5,-3,minecraft:granite)
B(1,6,-3,minecraft:granite)
B(1,7,-3,minecraft:granite)
B(1,8,-3,minecraft:granite)
B(1,9,-3,minecraft:granite)
B(1,10,-3,minecraft:jungle_leaves[distance=7,persistent=true])
B(1,-5,-2,minecraft:granite)
B(1,-4,-2,minecraft:granite)
B(1,-3,-2,minecraft:granite)
B(1,-2,-2,minecraft:granite)
B(1,-1,-2,minecraft:granite)
B(1,0,-2,minecraft:granite)
B(1,1,-2,minecraft:granite)
B(1,2,-2,minecraft:granite)
B(1,3,-2,minecraft:granite)
B(1,4,-2,minecraft:granite)
B(1,5,-2,minecraft:granite)
B(1,6,-2,minecraft:granite)
B(1,7,-2,minecraft:granite)
B(1,8,-2,minecraft:granite)
B(1,9,-2,minecraft:granite)
B(1,10,-2,minecraft:jungle_leaves[distance=7,persistent=true])
B(1,-6,-1,minecraft:granite)
B(1,-5,-1,minecraft:granite)
B(1,-4,-1,minecraft:granite)
B(1,-3,-1,minecraft:granite)
B(1,-2,-1,minecraft:granite)
B(1,-1,-1,minecraft:granite)
B(1,0,-1,minecraft:granite)
B(1,1,-1,minecraft:granite)
B(1,2,-1,minecraft:granite)
B(1,3,-1,minecraft:granite)
B(1,4,-1,minecraft:granite)
B(1,5,-1,minecraft:granite)
B(1,6,-1,minecraft:granite)
B(1,7,-1,minecraft:granite)
B(1,8,-1,minecraft:granite)
B(1,9,-1,minecraft:granite)
B(1,10,-1,minecraft:granite)
B(1,11,-1,minecraft:jungle_leaves[distance=7,persistent=true])
B(1,-6,0,minecraft:granite)
B(1,-5,0,minecraft:granite)
B(1,-4,0,minecraft:granite)
B(1,-3,0,minecraft:granite)
B(1,-2,0,minecraft:granite)
B(1,-1,0,minecraft:granite)
B(1,0,0,minecraft:granite)
B(1,1,0,minecraft:granite)
B(1,2,0,minecraft:granite)
B(1,3,0,minecraft:granite)
B(1,4,0,minecraft:granite)
B(1,5,0,minecraft:granite)
B(1,6,0,minecraft:granite)
B(1,8,0,minecraft:granite)
B(1,9,0,minecraft:granite)
B(1,10,0,minecraft:granite)
B(1,11,0,minecraft:granite)
B(1,-4,1,minecraft:granite)
B(1,-3,1,minecraft:granite)
B(1,-2,1,minecraft:granite)
B(1,-1,1,minecraft:granite)
B(1,0,1,minecraft:granite)
B(1,1,1,minecraft:granite)
B(1,2,1,minecraft:granite)
B(1,3,1,minecraft:granite)
B(1,4,1,minecraft:granite)
B(1,5,1,minecraft:granite)
B(1,6,1,minecraft:granite)
B(1,12,1,minecraft:red_terracotta)
B(1,-4,2,minecraft:granite)
B(1,-3,2,minecraft:granite)
B(1,-2,2,minecraft:granite)
B(1,-1,2,minecraft:granite)
B(1,0,2,minecraft:granite)
B(1,1,2,minecraft:granite)
B(1,2,2,minecraft:granite)
B(1,3,2,minecraft:granite)
B(1,4,2,minecraft:granite)
B(1,5,2,minecraft:granite)
B(1,6,2,minecraft:granite)
B(1,7,2,minecraft:granite)
B(1,8,2,minecraft:granite)
B(1,9,2,minecraft:granite)
B(1,10,2,minecraft:granite)
B(1,11,2,minecraft:granite)
B(1,12,2,minecraft:red_terracotta)
B(1,-4,3,minecraft:red_terracotta)
B(1,-3,3,minecraft:red_terracotta)
B(1,-2,3,minecraft:red_terracotta)
B(1,-1,3,minecraft:red_terracotta)
B(1,0,3,minecraft:granite)
B(1,1,3,minecraft:granite)
B(1,2,3,minecraft:granite)
B(1,3,3,minecraft:granite)
B(1,4,3,minecraft:granite)
B(1,5,3,minecraft:granite)
B(1,6,3,minecraft:granite)
B(1,7,3,minecraft:granite)
B(1,8,3,minecraft:jungle_leaves[distance=7,persistent=true])
B(1,9,3,minecraft:jungle_leaves[distance=7,persistent=true])
B(1,-4,4,minecraft:red_terracotta)
B(1,-3,4,minecraft:red_terracotta)
B(1,-2,4,minecraft:red_terracotta)
B(1,-1,4,minecraft:red_terracotta)
B(1,0,4,minecraft:red_terracotta)
B(1,1,4,minecraft:red_terracotta)
B(1,2,4,minecraft:red_terracotta)
B(1,3,4,minecraft:granite)
B(1,4,4,minecraft:granite)
B(1,5,4,minecraft:granite)
B(1,6,4,minecraft:granite)
B(1,7,4,minecraft:red_terracotta)
B(2,-1,-5,minecraft:granite)
B(2,0,-5,minecraft:granite)
B(2,1,-5,minecraft:granite)
B(2,2,-5,minecraft:granite)
B(2,3,-5,minecraft:granite)
B(2,4,-5,minecraft:granite)
B(2,5,-5,minecraft:granite)
B(2,6,-5,minecraft:granite)
B(2,7,-5,minecraft:granite)
B(2,-1,-4,minecraft:granite)
B(2,0,-4,minecraft:granite)
B(2,1,-4,minecraft:granite)
B(2,2,-4,minecraft:granite)
B(2,3,-4,minecraft:granite)
B(2,4,-4,minecraft:granite)
B(2,5,-4,minecraft:granite)
B(2,6,-4,minecraft:granite)
B(2,7,-4,minecraft:granite)
B(2,8,-4,minecraft:granite)
B(2,-5,-3,minecraft:granite)
B(2,-4,-3,minecraft:granite)
B(2,-2,-3,minecraft:granite)
B(2,-1,-3,minecraft:granite)
B(2,0,-3,minecraft:granite)
B(2,1,-3,minecraft:granite)
B(2,2,-3,minecraft:granite)
B(2,3,-3,minecraft:granite)
B(2,4,-3,minecraft:granite)
B(2,5,-3,minecraft:granite)
B(2,6,-3,minecraft:granite)
B(2,7,-3,minecraft:granite)
B(2,8,-3,minecraft:granite)
B(2,9,-3,minecraft:granite)
B(2,-5,-2,minecraft:granite)
B(2,-4,-2,minecraft:granite)
B(2,-3,-2,minecraft:granite)
B(2,-2,-2,minecraft:granite)
B(2,-1,-2,minecraft:granite)
B(2,0,-2,minecraft:granite)
B(2,1,-2,minecraft:granite)
B(2,2,-2,minecraft:granite)
B(2,3,-2,minecraft:granite)
B(2,4,-2,minecraft:granite)
B(2,5,-2,minecraft:granite)
B(2,6,-2,minecraft:granite)
B(2,7,-2,minecraft:granite)
B(2,8,-2,minecraft:granite)
B(2,9,-2,minecraft:granite)
B(2,10,-2,minecraft:jungle_leaves[distance=7,persistent=true])
B(2,-6,-1,minecraft:granite)
B(2,-5,-1,minecraft:granite)
B(2,-4,-1,minecraft:granite)
B(2,-3,-1,minecraft:granite)
B(2,-2,-1,minecraft:granite)
B(2,-1,-1,minecraft:granite)
B(2,0,-1,minecraft:granite)
B(2,1,-1,minecraft:granite)
B(2,2,-1,minecraft:granite)
B(2,3,-1,minecraft:granite)
B(2,4,-1,minecraft:granite)
B(2,5,-1,minecraft:granite)
B(2,6,-1,minecraft:granite)
B(2,7,-1,minecraft:granite)
B(2,8,-1,minecraft:granite)
B(2,9,-1,minecraft:granite)
B(2,10,-1,minecraft:granite)
B(2,-7,0,minecraft:granite)
B(2,-6,0,minecraft:granite)
B(2,-5,0,minecraft:granite)
B(2,-4,0,minecraft:granite)
B(2,-3,0,minecraft:granite)
B(2,-2,0,minecraft:granite)
B(2,-1,0,minecraft:granite)
B(2,0,0,minecraft:granite)
B(2,1,0,minecraft:granite)
B(2,2,0,minecraft:granite)
B(2,3,0,minecraft:granite)
B(2,4,0,minecraft:granite)
B(2,5,0,minecraft:granite)
B(2,6,0,minecraft:granite)
B(2,7,0,minecraft:granite)
B(2,8,0,minecraft:granite)
B(2,9,0,minecraft:granite)
B(2,10,0,minecraft:red_terracotta)
B(2,11,0,minecraft:red_terracotta)
B(2,12,0,minecraft:jungle_leaves[distance=7,persistent=true])
B(2,-7,1,minecraft:granite)
B(2,-5,1,minecraft:granite)
B(2,-4,1,minecraft:granite)
B(2,-3,1,minecraft:granite)
B(2,-2,1,minecraft:granite)
B(2,-1,1,minecraft:granite)
B(2,0,1,minecraft:granite)
B(2,1,1,minecraft:granite)
B(2,2,1,minecraft:granite)
B(2,3,1,minecraft:granite)
B(2,4,1,minecraft:granite)
B(2,5,1,minecraft:granite)
B(2,6,1,minecraft:granite)
B(2,7,1,minecraft:granite)
B(2,8,1,minecraft:granite)
B(2,9,1,minecraft:red_terracotta)
B(2,10,1,minecraft:red_terracotta)
B(2,11,1,minecraft:red_terracotta)
B(2,12,1,minecraft:jungle_leaves[distance=7,persistent=true])
B(2,-4,2,minecraft:granite)
B(2,-3,2,minecraft:granite)
B(2,-2,2,minecraft:granite)
B(2,-1,2,minecraft:granite)
B(2,0,2,minecraft:granite)
B(2,1,2,minecraft:granite)
B(2,2,2,minecraft:granite)
B(2,3,2,minecraft:granite)
B(2,4,2,minecraft:granite)
B(2,5,2,minecraft:granite)
B(2,6,2,minecraft:granite)
B(2,7,2,minecraft:granite)
B(2,8,2,minecraft:granite)
B(2,9,2,minecraft:jungle_leaves[distance=7,persistent=true])
B(2,10,2,minecraft:jungle_leaves[distance=7,persistent=true])
B(2,11,2,minecraft:jungle_leaves[distance=7,persistent=true])
B(2,-5,3,minecraft:granite)
B(2,-4,3,minecraft:granite)
B(2,-3,3,minecraft:granite)
B(2,-2,3,minecraft:granite)
B(2,-1,3,minecraft:granite)
B(2,0,3,minecraft:granite)
B(2,1,3,minecraft:granite)
B(2,2,3,minecraft:granite)
B(2,3,3,minecraft:granite)
B(2,4,3,minecraft:granite)
B(2,5,3,minecraft:granite)
B(2,6,3,minecraft:granite)
B(2,7,3,minecraft:jungle_leaves[distance=7,persistent=true])
B(2,-5,4,minecraft:granite)
B(2,-4,4,minecraft:red_terracotta)
B(2,-3,4,minecraft:red_terracotta)
B(2,-2,4,minecraft:red_terracotta)
B(2,-1,4,minecraft:red_terracotta)
B(2,0,4,minecraft:granite)
B(2,1,4,minecraft:granite)
B(2,2,4,minecraft:granite)
B(2,3,4,minecraft:granite)
B(2,4,4,minecraft:granite)
B(2,5,4,minecraft:granite)
B(2,6,4,minecraft:granite)
B(2,7,4,minecraft:granite)
B(2,-6,5,minecraft:granite)
B(2,-5,5,minecraft:granite)
B(2,-4,5,minecraft:granite)
B(2,-3,5,minecraft:granite)
B(2,-2,5,minecraft:granite)
B(2,-1,5,minecraft:granite)
B(2,0,5,minecraft:granite)
B(2,3,5,minecraft:granite)
B(3,-1,-4,minecraft:red_terracotta)
B(3,0,-4,minecraft:granite)
B(3,1,-4,minecraft:granite)
B(3,2,-4,minecraft:granite)
B(3,3,-4,minecraft:granite)
B(3,4,-4,minecraft:granite)
B(3,5,-4,minecraft:granite)
B(3,6,-4,minecraft:granite)
B(3,7,-4,minecraft:granite)
B(3,-5,-3,minecraft:granite)
B(3,-4,-3,minecraft:granite)
B(3,-3,-3,minecraft:granite)
B(3,-2,-3,minecraft:granite)
B(3,-1,-3,minecraft:granite)
B(3,0,-3,minecraft:granite)
B(3,1,-3,minecraft:granite)
B(3,2,-3,minecraft:granite)
B(3,3,-3,minecraft:granite)
B(3,4,-3,minecraft:granite)
B(3,5,-3,minecraft:granite)
B(3,6,-3,minecraft:granite)
B(3,7,-3,minecraft:granite)
B(3,8,-3,minecraft:granite)
B(3,-5,-2,minecraft:granite)
B(3,-4,-2,minecraft:granite)
B(3,-3,-2,minecraft:granite)
B(3,-2,-2,minecraft:granite)
B(3,-1,-2,minecraft:granite)
B(3,0,-2,minecraft:granite)
B(3,1,-2,minecraft:granite)
B(3,2,-2,minecraft:granite)
B(3,3,-2,minecraft:granite)
B(3,4,-2,minecraft:granite)
B(3,5,-2,minecraft:granite)
B(3,6,-2,minecraft:granite)
B(3,7,-2,minecraft:granite)
B(3,8,-2,minecraft:granite)
B(3,9,-2,minecraft:granite)
B(3,-6,-1,minecraft:granite)
B(3,-5,-1,minecraft:granite)
B(3,-4,-1,minecraft:granite)
B(3,-3,-1,minecraft:granite)
B(3,-2,-1,minecraft:granite)
B(3,-1,-1,minecraft:granite)
B(3,0,-1,minecraft:granite)
B(3,1,-1,minecraft:granite)
B(3,2,-1,minecraft:granite)
B(3,3,-1,minecraft:granite)
B(3,4,-1,minecraft:granite)
B(3,5,-1,minecraft:granite)
B(3,6,-1,minecraft:granite)
B(3,7,-1,minecraft:granite)
B(3,8,-1,minecraft:granite)
B(3,9,-1,minecraft:granite)
B(3,10,-1,minecraft:jungle_leaves[distance=7,persistent=true])
B(3,-6,0,minecraft:granite)
B(3,-5,0,minecraft:granite)
B(3,-4,0,minecraft:granite)
B(3,-3,0,minecraft:granite)
B(3,-2,0,minecraft:granite)
B(3,-1,0,minecraft:granite)
B(3,0,0,minecraft:granite)
B(3,1,0,minecraft:granite)
B(3,2,0,minecraft:granite)
B(3,3,0,minecraft:granite)
B(3,4,0,minecraft:granite)
B(3,5,0,minecraft:granite)
B(3,6,0,minecraft:granite)
B(3,7,0,minecraft:granite)
B(3,8,0,minecraft:granite)
B(3,9,0,minecraft:granite)
B(3,10,0,minecraft:granite)
B(3,11,0,minecraft:red_terracotta)
B(3,-6,1,minecraft:granite)
B(3,-5,1,minecraft:granite)
B(3,-4,1,minecraft:granite)
B(3,-3,1,minecraft:granite)
B(3,-2,1,minecraft:granite)
B(3,-1,1,minecraft:granite)
B(3,0,1,minecraft:granite)
B(3,1,1,minecraft:granite)
B(3,2,1,minecraft:granite)
B(3,3,1,minecraft:granite)
B(3,4,1,minecraft:granite)
B(3,5,1,minecraft:granite)
B(3,6,1,minecraft:granite)
B(3,7,1,minecraft:granite)
B(3,8,1,minecraft:granite)
B(3,9,1,minecraft:granite)
B(3,10,1,minecraft:granite)
B(3,-6,2,minecraft:granite)
B(3,-5,2,minecraft:granite)
B(3,-4,2,minecraft:granite)
B(3,-3,2,minecraft:granite)
B(3,-2,2,minecraft:granite)
B(3,-1,2,minecraft:granite)
B(3,0,2,minecraft:granite)
B(3,1,2,minecraft:granite)
B(3,2,2,minecraft:granite)
B(3,3,2,minecraft:granite)
B(3,4,2,minecraft:granite)
B(3,5,2,minecraft:granite)
B(3,6,2,minecraft:granite)
B(3,7,2,minecraft:jungle_leaves[distance=7,persistent=true])
B(3,-5,3,minecraft:granite)
B(3,-4,3,minecraft:granite)
B(3,-3,3,minecraft:granite)
B(3,-2,3,minecraft:granite)
B(3,-1,3,minecraft:granite)
B(3,0,3,minecraft:granite)
B(3,1,3,minecraft:granite)
B(3,2,3,minecraft:granite)
B(3,3,3,minecraft:granite)
B(3,4,3,minecraft:granite)
B(3,5,3,minecraft:granite)
B(3,6,3,minecraft:granite)
B(3,7,3,minecraft:granite)
B(3,8,3,minecraft:jungle_leaves[distance=7,persistent=true])
B(3,-5,4,minecraft:granite)
B(3,-4,4,minecraft:granite)
B(3,-3,4,minecraft:granite)
B(3,-2,4,minecraft:granite)
B(3,-1,4,minecraft:granite)
B(3,0,4,minecraft:red_terracotta)
B(3,1,4,minecraft:granite)
B(3,2,4,minecraft:granite)
B(3,3,4,minecraft:granite)
B(3,4,4,minecraft:granite)
B(3,5,4,minecraft:granite)
B(3,6,4,minecraft:granite)
B(3,7,4,minecraft:jungle_leaves[distance=7,persistent=true])
B(3,-6,5,minecraft:red_terracotta)
B(3,-5,5,minecraft:granite)
B(3,-4,5,minecraft:red_terracotta)
B(3,-3,5,minecraft:granite)
B(3,-2,5,minecraft:granite)
B(3,-1,5,minecraft:granite)
B(3,0,5,minecraft:granite)
B(3,1,5,minecraft:granite)
B(3,2,5,minecraft:granite)
B(3,3,5,minecraft:granite)
B(3,4,5,minecraft:jungle_leaves[distance=7,persistent=true])
B(3,5,5,minecraft:jungle_leaves[distance=7,persistent=true])
B(3,6,5,minecraft:jungle_leaves[distance=7,persistent=true])
B(4,-2,-4,minecraft:red_terracotta)
B(4,-1,-4,minecraft:red_terracotta)
B(4,0,-4,minecraft:red_terracotta)
B(4,1,-4,minecraft:granite)
B(4,2,-4,minecraft:granite)
B(4,3,-4,minecraft:granite)
B(4,4,-4,minecraft:granite)
B(4,-3,-3,minecraft:red_terracotta)
B(4,-2,-3,minecraft:granite)
B(4,-1,-3,minecraft:red_terracotta)
B(4,0,-3,minecraft:red_terracotta)
B(4,1,-3,minecraft:granite)
B(4,2,-3,minecraft:red_terracotta)
B(4,3,-3,minecraft:red_terracotta)
B(4,4,-3,minecraft:granite)
B(4,5,-3,minecraft:granite)
B(4,6,-3,minecraft:granite)
B(4,7,-3,minecraft:granite)
B(4,-2,-2,minecraft:granite)
B(4,-1,-2,minecraft:granite)
B(4,0,-2,minecraft:granite)
B(4,1,-2,minecraft:granite)
B(4,2,-2,minecraft:granite)
B(4,3,-2,minecraft:granite)
B(4,4,-2,minecraft:granite)
B(4,5,-2,minecraft:granite)
B(4,6,-2,minecraft:granite)
B(4,7,-2,minecraft:granite)
B(4,8,-2,minecraft:granite)
B(4,-5,-1,minecraft:granite)
B(4,-3,-1,minecraft:granite)
B(4,-2,-1,minecraft:granite)
B(4,-1,-1,minecraft:granite)
B(4,0,-1,minecraft:granite)
B(4,1,-1,minecraft:granite)
B(4,2,-1,minecraft:granite)
B(4,3,-1,minecraft:granite)
B(4,4,-1,minecraft:granite)
B(4,5,-1,minecraft:granite)
B(4,6,-1,minecraft:granite)
B(4,7,-1,minecraft:granite)
B(4,8,-1,minecraft:granite)
B(4,9,-1,minecraft:granite)
B(4,-6,0,minecraft:granite)
B(4,-5,0,minecraft:granite)
B(4,-4,0,minecraft:granite)
B(4,-3,0,minecraft:granite)
B(4,-2,0,minecraft:granite)
B(4,-1,0,minecraft:granite)
B(4,0,0,minecraft:granite)
B(4,1,0,minecraft:granite)
B(4,2,0,minecraft:granite)
B(4,3,0,minecraft:granite)
B(4,4,0,minecraft:granite)
B(4,5,0,minecraft:granite)
B(4,6,0,minecraft:granite)
B(4,7,0,minecraft:granite)
B(4,8,0,minecraft:granite)
B(4,9,0,minecraft:granite)
B(4,10,0,minecraft:jungle_leaves[distance=7,persistent=true])
B(4,-6,1,minecraft:granite)
B(4,-5,1,minecraft:granite)
B(4,-4,1,minecraft:granite)
B(4,-3,1,minecraft:granite)
B(4,-2,1,minecraft:granite)
B(4,-1,1,minecraft:granite)
B(4,0,1,minecraft:granite)
B(4,1,1,minecraft:granite)
B(4,2,1,minecraft:granite)
B(4,3,1,minecraft:granite)
B(4,4,1,minecraft:granite)
B(4,5,1,minecraft:granite)
B(4,6,1,minecraft:red_terracotta)
B(4,7,1,minecraft:red_terracotta)
B(4,8,1,minecraft:red_terracotta)
B(4,9,1,minecraft:granite)
B(4,-5,2,minecraft:granite)
B(4,-4,2,minecraft:granite)
B(4,-3,2,minecraft:granite)
B(4,-2,2,minecraft:granite)
B(4,-1,2,minecraft:granite)
B(4,0,2,minecraft:granite)
B(4,1,2,minecraft:granite)
B(4,2,2,minecraft:granite)
B(4,3,2,minecraft:granite)
B(4,4,2,minecraft:granite)
B(4,5,2,minecraft:granite)
B(4,6,2,minecraft:red_terracotta)
B(4,7,2,minecraft:red_terracotta)
B(4,8,2,minecraft:red_terracotta)
B(4,-4,3,minecraft:granite)
B(4,-3,3,minecraft:granite)
B(4,-2,3,minecraft:granite)
B(4,-1,3,minecraft:granite)
B(4,0,3,minecraft:red_terracotta)
B(4,1,3,minecraft:granite)
B(4,2,3,minecraft:granite)
B(4,3,3,minecraft:granite)
B(4,4,3,minecraft:granite)
B(4,5,3,minecraft:granite)
B(4,6,3,minecraft:red_terracotta)
B(4,7,3,minecraft:jungle_leaves[distance=7,persistent=true])
B(4,-5,4,minecraft:granite)
B(4,-4,4,minecraft:red_terracotta)
B(4,-3,4,minecraft:red_terracotta)
B(4,-2,4,minecraft:granite)
B(4,-1,4,minecraft:red_terracotta)
B(4,0,4,minecraft:red_terracotta)
B(4,1,4,minecraft:granite)
B(4,2,4,minecraft:granite)
B(4,3,4,minecraft:granite)
B(4,4,4,minecraft:granite)
B(4,5,4,minecraft:granite)
B(4,-5,5,minecraft:red_terracotta)
B(4,-4,5,minecraft:red_terracotta)
B(4,-3,5,minecraft:red_terracotta)
B(4,-2,5,minecraft:granite)
B(4,-1,5,minecraft:granite)
B(4,0,5,minecraft:red_terracotta)
B(4,1,5,minecraft:jungle_leaves[distance=7,persistent=true])
B(4,2,5,minecraft:jungle_leaves[distance=7,persistent=true])
B(4,3,5,minecraft:jungle_leaves[distance=7,persistent=true])
B(5,-2,-3,minecraft:granite)
B(5,-1,-3,minecraft:red_terracotta)
B(5,0,-3,minecraft:red_terracotta)
B(5,1,-3,minecraft:red_terracotta)
B(5,2,-3,minecraft:red_terracotta)
B(5,3,-3,minecraft:jungle_leaves[distance=7,persistent=true])
B(5,4,-3,minecraft:jungle_leaves[distance=7,persistent=true])
B(5,5,-3,minecraft:jungle_leaves[distance=7,persistent=true])
B(5,6,-3,minecraft:jungle_leaves[distance=7,persistent=true])
B(5,7,-3,minecraft:jungle_leaves[distance=7,persistent=true])
B(5,-2,-2,minecraft:granite)
B(5,-1,-2,minecraft:granite)
B(5,0,-2,minecraft:red_terracotta)
B(5,1,-2,minecraft:granite)
B(5,2,-2,minecraft:red_terracotta)
B(5,3,-2,minecraft:granite)
B(5,4,-2,minecraft:granite)
B(5,5,-2,minecraft:granite)
B(5,6,-2,minecraft:granite)
B(5,7,-2,minecraft:jungle_leaves[distance=7,persistent=true])
B(5,-2,-1,minecraft:granite)
B(5,-1,-1,minecraft:granite)
B(5,0,-1,minecraft:granite)
B(5,1,-1,minecraft:granite)
B(5,2,-1,minecraft:granite)
B(5,3,-1,minecraft:granite)
B(5,4,-1,minecraft:granite)
B(5,5,-1,minecraft:granite)
B(5,6,-1,minecraft:granite)
B(5,7,-1,minecraft:granite)
B(5,8,-1,minecraft:jungle_leaves[distance=7,persistent=true])
B(5,-5,0,minecraft:granite)
B(5,-4,0,minecraft:granite)
B(5,-3,0,minecraft:granite)
B(5,-2,0,minecraft:granite)
B(5,-1,0,minecraft:granite)
B(5,0,0,minecraft:granite)
B(5,1,0,minecraft:granite)
B(5,2,0,minecraft:granite)
B(5,3,0,minecraft:granite)
B(5,4,0,minecraft:granite)
B(5,5,0,minecraft:granite)
B(5,6,0,minecraft:granite)
B(5,7,0,minecraft:granite)
B(5,8,0,minecraft:granite)
B(5,9,0,minecraft:jungle_leaves[distance=7,persistent=true])
B(5,-4,1,minecraft:granite)
B(5,-3,1,minecraft:granite)
B(5,-2,1,minecraft:granite)
B(5,-1,1,minecraft:granite)
B(5,0,1,minecraft:granite)
B(5,1,1,minecraft:granite)
B(5,2,1,minecraft:granite)
B(5,3,1,minecraft:granite)
B(5,4,1,minecraft:granite)
B(5,5,1,minecraft:granite)
B(5,6,1,minecraft:red_terracotta)
B(5,7,1,minecraft:red_terracotta)
B(5,8,1,minecraft:red_terracotta)
B(5,-4,2,minecraft:granite)
B(5,-3,2,minecraft:granite)
B(5,-2,2,minecraft:granite)
B(5,-1,2,minecraft:granite)
B(5,0,2,minecraft:granite)
B(5,1,2,minecraft:red_terracotta)
B(5,2,2,minecraft:red_terracotta)
B(5,3,2,minecraft:red_terracotta)
B(5,4,2,minecraft:granite)
B(5,5,2,minecraft:granite)
B(5,6,2,minecraft:red_terracotta)
B(5,7,2,minecraft:red_terracotta)
B(5,-4,3,minecraft:granite)
B(5,-3,3,minecraft:red_terracotta)
B(5,-2,3,minecraft:red_terracotta)
B(5,-1,3,minecraft:red_terracotta)
B(5,0,3,minecraft:red_terracotta)
B(5,1,3,minecraft:red_terracotta)
B(5,2,3,minecraft:red_terracotta)
B(5,3,3,minecraft:red_terracotta)
B(5,4,3,minecraft:granite)
B(5,5,3,minecraft:granite)
B(5,6,3,minecraft:red_terracotta)
B(5,7,3,minecraft:jungle_leaves[distance=7,persistent=true])
B(5,-4,4,minecraft:red_terracotta)
B(5,-3,4,minecraft:red_terracotta)
B(5,-2,4,minecraft:red_terracotta)
B(5,-1,4,minecraft:red_terracotta)
B(5,0,4,minecraft:red_terracotta)
B(5,1,4,minecraft:red_terracotta)
B(5,2,4,minecraft:red_terracotta)
B(5,3,4,minecraft:red_terracotta)
B(5,4,4,minecraft:granite)
B(5,0,5,minecraft:jungle_leaves[distance=7,persistent=true])
B(6,0,-2,minecraft:jungle_leaves[distance=7,persistent=true])
B(6,1,-2,minecraft:jungle_leaves[distance=7,persistent=true])
B(6,2,-2,minecraft:jungle_leaves[distance=7,persistent=true])
B(6,-3,-1,minecraft:granite)
B(6,-2,-1,minecraft:red_terracotta)
B(6,-1,-1,minecraft:granite)
B(6,0,-1,minecraft:granite)
B(6,1,-1,minecraft:red_terracotta)
B(6,2,-1,minecraft:granite)
B(6,3,-1,minecraft:granite)
B(6,4,-1,minecraft:granite)
B(6,5,-1,minecraft:granite)
B(6,-4,0,minecraft:granite)
B(6,-3,0,minecraft:granite)
B(6,-2,0,minecraft:granite)
B(6,-1,0,minecraft:granite)
B(6,0,0,minecraft:granite)
B(6,1,0,minecraft:granite)
B(6,2,0,minecraft:granite)
B(6,3,0,minecraft:granite)
B(6,4,0,minecraft:granite)
B(6,5,0,minecraft:granite)
B(6,-4,1,minecraft:granite)
B(6,-3,1,minecraft:granite)
B(6,-2,1,minecraft:granite)
B(6,-1,1,minecraft:granite)
B(6,0,1,minecraft:granite)
B(6,1,1,minecraft:granite)
B(6,2,1,minecraft:granite)
B(6,3,1,minecraft:granite)
B(6,4,1,minecraft:granite)
B(6,5,1,minecraft:granite)
B(6,6,1,minecraft:red_terracotta)
B(6,-4,2,minecraft:granite)
B(6,-3,2,minecraft:granite)
B(6,-2,2,minecraft:granite)
B(6,-1,2,minecraft:granite)
B(6,0,2,minecraft:granite)
B(6,1,2,minecraft:red_terracotta)
B(6,2,2,minecraft:red_terracotta)
B(6,3,2,minecraft:red_terracotta)
B(6,4,2,minecraft:granite)
B(6,5,2,minecraft:granite)
B(6,6,2,minecraft:red_terracotta)
B(6,-4,3,minecraft:granite)
B(6,-3,3,minecraft:granite)
B(6,-2,3,minecraft:red_terracotta)
B(6,-1,3,minecraft:red_terracotta)
B(6,0,3,minecraft:red_terracotta)
B(6,1,3,minecraft:red_terracotta)
B(6,2,3,minecraft:red_terracotta)
B(6,3,3,minecraft:red_terracotta)
B(6,4,3,minecraft:granite)
B(6,5,3,minecraft:jungle_leaves[distance=7,persistent=true])
B(6,6,3,minecraft:jungle_leaves[distance=7,persistent=true])
B(6,-5,4,minecraft:red_terracotta)
B(6,-4,4,minecraft:granite)
B(6,-3,4,minecraft:red_terracotta)
B(6,-2,4,minecraft:red_terracotta)
B(6,-1,4,minecraft:red_terracotta)
B(6,0,4,minecraft:red_terracotta)
B(6,1,4,minecraft:red_terracotta)
B(6,2,4,minecraft:jungle_leaves[distance=7,persistent=true])
B(6,3,4,minecraft:jungle_leaves[distance=7,persistent=true])
B(6,4,4,minecraft:jungle_leaves[distance=7,persistent=true])
B(7,-3,-1,minecraft:red_terracotta)
B(7,-2,-1,minecraft:red_terracotta)
B(7,-1,-1,minecraft:red_terracotta)
B(7,0,-1,minecraft:red_terracotta)
B(7,1,-1,minecraft:red_terracotta)
B(7,2,-1,minecraft:red_terracotta)
B(7,-3,0,minecraft:granite)
B(7,-2,0,minecraft:red_terracotta)
B(7,-1,0,minecraft:granite)
B(7,0,0,minecraft:granite)
B(7,1,0,minecraft:red_terracotta)
B(7,2,0,minecraft:granite)
B(7,3,0,minecraft:granite)
B(7,4,0,minecraft:granite)
B(7,-2,1,minecraft:granite)
B(7,-1,1,minecraft:granite)
B(7,0,1,minecraft:granite)
B(7,1,1,minecraft:granite)
B(7,2,1,minecraft:red_terracotta)
B(7,3,1,minecraft:granite)
B(7,4,1,minecraft:granite)
B(7,-3,2,minecraft:granite)
B(7,-2,2,minecraft:granite)
B(7,-1,2,minecraft:granite)
B(7,0,2,minecraft:granite)
B(7,1,2,minecraft:red_terracotta)
B(7,2,2,minecraft:red_terracotta)
B(7,3,2,minecraft:red_terracotta)
B(7,4,2,minecraft:granite)
B(7,-4,3,minecraft:granite)
B(7,-3,3,minecraft:granite)
B(7,-2,3,minecraft:red_terracotta)
B(7,-1,3,minecraft:red_terracotta)
B(7,0,3,minecraft:red_terracotta)
B(7,1,3,minecraft:red_terracotta)
B(7,0,4,minecraft:jungle_leaves[distance=7,persistent=true])
B(7,1,4,minecraft:jungle_leaves[distance=7,persistent=true])
B(8,-2,1,minecraft:granite)
B(8,-1,1,minecraft:granite)
B(8,0,1,minecraft:granite)
B(8,1,1,minecraft:red_terracotta)

#######################################################################
# +-----------------------------------------------------------------+ #
# |                            BO3 checks                           | #
# +-----------------------------------------------------------------+ #
#######################################################################

BlockCheck(2,-1,-4,minecraft:sand,otg:dirt,minecraft:grass_block,minecraft:granite)

#######################################################################
# +-----------------------------------------------------------------+ #
# |                             Branches                            | #
# +-----------------------------------------------------------------+ #
#######################################################################


#######################################################################
# +-----------------------------------------------------------------+ #
# |                             Entities                            | #
# +-----------------------------------------------------------------+ #
#######################################################################

