#######################################################################
# +-----------------------------------------------------------------+ #
# |                            BO3 object                           | #
# +-----------------------------------------------------------------+ #
#######################################################################

Author: Bo3 BulkEdit

Description: Converted Schematic - Modified by Bo3BulkEdit

Version: 3

SettingsMode: WriteDisable

#######################################################################
# +-----------------------------------------------------------------+ #
# |                          Main settings                          | #
# +-----------------------------------------------------------------+ #
#######################################################################



Frequency: 0


SpawnHeight: randomY





##############################
# Height Limits for the BO3. #
##############################

MinHeight: 0
MaxHeight: 256

#######################################################################
# +-----------------------------------------------------------------+ #
# |                      Source block settings                      | #
# +-----------------------------------------------------------------+ #
#######################################################################

CanOverride: true
MaxPercentageOutsideSourceBlock: 100
OutsideSourceBlock: placeAnyway

#######################################################################
# +-----------------------------------------------------------------+ #
# |                               OTG+                              | #
# +-----------------------------------------------------------------+ #
#######################################################################

#######################################################################
# +-----------------------------------------------------------------+ #
# |                              Blocks                             | #
# +-----------------------------------------------------------------+ #
#######################################################################

B(0,750,0,AIR)
B(15,750,15,AIR)
B(10,-4,6,STAINED_GLASS:15)
B(11,-4,6,STAINED_GLASS:15)
B(9,-3,5,STAINED_GLASS:15)
B(10,-3,5,STAINED_GLASS:15)
B(11,-3,5,STAINED_GLASS:15)
B(10,-3,6,STAINED_GLASS:15)
B(11,-3,6,STAINED_GLASS:15)
B(8,-2,4,STAINED_GLASS:15)
B(9,-2,4,STAINED_GLASS:15)
B(10,-2,4,STAINED_GLASS:15)
B(11,-2,4,STAINED_GLASS:15)
B(9,-2,5,STAINED_GLASS:15)
B(10,-2,5,STAINED_GLASS:15)
B(11,-2,5,STAINED_GLASS:15)
B(10,-2,6,STAINED_GLASS:15)
B(11,-2,6,STAINED_GLASS:15)
B(7,-1,3,STAINED_GLASS:15)
B(8,-1,3,STAINED_GLASS:15)
B(9,-1,3,STAINED_GLASS:15)
B(10,-1,3,STAINED_GLASS:15)
B(8,-1,4,STAINED_GLASS:15)
B(9,-1,4,STAINED_GLASS:15)
B(10,-1,4,STAINED_GLASS:15)
B(11,-1,4,STAINED_GLASS:15)
B(9,-1,5,STAINED_GLASS:15)
B(10,-1,5,STAINED_GLASS:15)
B(11,-1,5,STAINED_GLASS:15)
B(10,-1,6,STAINED_GLASS:15)
B(7,0,2,STAINED_GLASS:15)
B(8,0,2,STAINED_GLASS:15)
B(9,0,2,STAINED_GLASS:15)
B(10,0,2,STAINED_GLASS:15)
B(7,0,3,STAINED_GLASS:15)
B(8,0,3,STAINED_GLASS:15)
B(9,0,3,STAINED_GLASS:15)
B(10,0,3,STAINED_GLASS:15)
B(11,0,3,STAINED_GLASS:15)
B(8,0,4,STAINED_GLASS:15)
B(10,0,4,STAINED_GLASS:15)
B(11,0,4,STAINED_GLASS:15)
B(9,0,5,STAINED_GLASS:15)
B(10,0,5,STAINED_GLASS:15)
B(11,0,5,STAINED_GLASS:15)
B(7,1,1,STAINED_GLASS:15)
B(8,1,1,STAINED_GLASS:15)
B(9,1,1,STAINED_GLASS:15)
B(10,1,1,STAINED_GLASS:15)
B(7,1,2,STAINED_GLASS:15)
B(8,1,2,STAINED_GLASS:15)
B(9,1,2,STAINED_GLASS:15)
B(10,1,2,STAINED_GLASS:15)
B(11,1,2,STAINED_GLASS:15)
B(7,1,3,STAINED_GLASS:15)
B(8,1,3,STAINED_GLASS:15)
B(9,1,3,SEA_LANTERN)
B(10,1,3,STAINED_GLASS:15)
B(11,1,3,STAINED_GLASS:15)
B(6,1,4,STAINED_GLASS:15)
B(7,1,4,STAINED_GLASS:15)
B(8,1,4,STAINED_GLASS:15)
B(9,1,4,SEA_LANTERN)
B(10,1,4,STAINED_GLASS:15)
B(11,1,4,STAINED_GLASS:15)
B(7,1,5,STAINED_GLASS:15)
B(8,1,5,STAINED_GLASS:15)
B(9,1,5,STAINED_GLASS:15)
B(10,1,5,STAINED_GLASS:15)
B(11,1,5,STAINED_GLASS:15)
B(8,2,0,STAINED_GLASS:15)
B(9,2,0,STAINED_GLASS:15)
B(6,2,1,STAINED_GLASS:15)
B(7,2,1,STAINED_GLASS:15)
B(8,2,1,STAINED_GLASS:15)
B(9,2,1,STAINED_GLASS:15)
B(10,2,1,STAINED_GLASS:15)
B(6,2,2,STAINED_GLASS:15)
B(7,2,2,STAINED_GLASS:15)
B(8,2,2,SEA_LANTERN)
B(9,2,2,SEA_LANTERN)
B(10,2,2,SEA_LANTERN)
B(11,2,2,STAINED_GLASS:15)
B(6,2,3,STAINED_GLASS:15)
B(7,2,3,STAINED_GLASS:15)
B(8,2,3,SEA_LANTERN)
B(9,2,3,SEA_LANTERN)
B(10,2,3,STAINED_GLASS:15)
B(6,2,4,STAINED_GLASS:15)
B(7,2,4,STAINED_GLASS:15)
B(8,2,4,STAINED_GLASS:15)
B(9,2,4,SEA_LANTERN)
B(10,2,4,STAINED_GLASS:15)
B(11,2,4,STAINED_GLASS:15)
B(7,2,5,STAINED_GLASS:15)
B(8,2,5,STAINED_GLASS:15)
B(9,2,5,STAINED_GLASS:15)
B(8,3,0,STAINED_GLASS:15)
B(9,3,0,STAINED_GLASS:11)
B(6,3,1,STAINED_GLASS:15)
B(7,3,1,STAINED_GLASS:15)
B(8,3,1,SEA_LANTERN)
B(9,3,1,STAINED_GLASS:11)
B(10,3,1,STAINED_GLASS:15)
B(6,3,2,STAINED_GLASS:15)
B(7,3,2,STAINED_GLASS:11)
B(8,3,2,SEA_LANTERN)
B(9,3,2,SEA_LANTERN)
B(10,3,2,SEA_LANTERN)
B(11,3,2,STAINED_GLASS:11)
B(6,3,3,STAINED_GLASS:15)
B(7,3,3,STAINED_GLASS:15)
B(8,3,3,STAINED_GLASS:11)
B(9,3,3,SEA_LANTERN)
B(10,3,3,STAINED_GLASS:11)
B(6,3,4,STAINED_GLASS:15)
B(7,3,4,STAINED_GLASS:15)
B(8,3,4,STAINED_GLASS:15)
B(9,3,4,SEA_LANTERN)
B(10,3,4,STAINED_GLASS:15)
B(11,3,4,STAINED_GLASS:15)
B(7,3,5,STAINED_GLASS:15)
B(6,4,0,STAINED_GLASS:15)
B(7,4,0,STAINED_GLASS:15)
B(8,4,0,SEA_LANTERN)
B(9,4,0,STAINED_GLASS:11)
B(6,4,1,STAINED_GLASS:15)
B(7,4,1,STAINED_GLASS:11)
B(8,4,1,SEA_LANTERN)
B(9,4,1,STAINED_GLASS:11)
B(10,4,1,STAINED_GLASS:11)
B(6,4,2,STAINED_GLASS:15)
B(7,4,2,SEA_LANTERN)
B(8,4,2,SEA_LANTERN)
B(9,4,2,SEA_LANTERN)
B(10,4,2,SEA_LANTERN)
B(11,4,2,STAINED_GLASS:11)
B(6,4,3,STAINED_GLASS:15)
B(7,4,3,STAINED_GLASS:15)
B(8,4,3,STAINED_GLASS:11)
B(9,4,3,SEA_LANTERN)
B(10,4,3,STAINED_GLASS:11)
B(6,4,4,STAINED_GLASS:15)
B(7,4,4,STAINED_GLASS:15)
B(8,4,4,STAINED_GLASS:15)
B(9,4,4,STAINED_GLASS:15)
B(10,4,4,STAINED_GLASS:15)
B(5,5,0,STAINED_GLASS:15)
B(6,5,0,STAINED_GLASS:15)
B(7,5,0,STAINED_GLASS:15)
B(8,5,0,SEA_LANTERN)
B(9,5,0,SEA_LANTERN)
B(6,5,1,STAINED_GLASS:15)
B(7,5,1,STAINED_GLASS:11)
B(8,5,1,SEA_LANTERN)
B(9,5,1,SEA_LANTERN)
B(10,5,1,STAINED_GLASS:11)
B(6,5,2,STAINED_GLASS:15)
B(7,5,2,SEA_LANTERN)
B(8,5,2,SEA_LANTERN)
B(9,5,2,SEA_LANTERN)
B(10,5,2,STAINED_GLASS:11)
B(11,5,2,STAINED_GLASS:11)
B(6,5,3,STAINED_GLASS:15)
B(7,5,3,STAINED_GLASS:15)
B(8,5,3,STAINED_GLASS:15)
B(9,5,3,STAINED_GLASS:15)
B(10,5,3,STAINED_GLASS:11)
B(6,5,4,STAINED_GLASS:15)
B(7,5,4,STAINED_GLASS:15)
B(8,5,4,STAINED_GLASS:15)
B(9,5,4,STAINED_GLASS:15)
B(5,6,0,STAINED_GLASS:15)
B(6,6,0,STAINED_GLASS:15)
B(7,6,0,SEA_LANTERN)
B(8,6,0,SEA_LANTERN)
B(9,6,0,SEA_LANTERN)
B(6,6,1,STAINED_GLASS:15)
B(7,6,1,STAINED_GLASS:11)
B(8,6,1,SEA_LANTERN)
B(9,6,1,SEA_LANTERN)
B(10,6,1,STAINED_GLASS:11)
B(6,6,2,STAINED_GLASS:15)
B(7,6,2,STAINED_GLASS:11)
B(8,6,2,SEA_LANTERN)
B(9,6,2,SEA_LANTERN)
B(10,6,2,STAINED_GLASS:11)
B(11,6,2,STAINED_GLASS:15)
B(6,6,3,STAINED_GLASS:15)
B(7,6,3,STAINED_GLASS:15)
B(8,6,3,STAINED_GLASS:15)
B(9,6,3,STAINED_GLASS:15)
B(5,7,0,STAINED_GLASS:15)
B(6,7,0,STAINED_GLASS:15)
B(7,7,0,SEA_LANTERN)
B(8,7,0,SEA_LANTERN)
B(9,7,0,SEA_LANTERN)
B(6,7,1,STAINED_GLASS:15)
B(7,7,1,SEA_LANTERN)
B(8,7,1,SEA_LANTERN)
B(9,7,1,SEA_LANTERN)
B(10,7,1,STAINED_GLASS:15)
B(6,7,2,STAINED_GLASS:15)
B(7,7,2,STAINED_GLASS:11)
B(8,7,2,STAINED_GLASS:15)
B(9,7,2,SEA_LANTERN)
B(10,7,2,STAINED_GLASS:15)
B(6,7,3,STAINED_GLASS:15)
B(7,7,3,STAINED_GLASS:15)
B(8,7,3,STAINED_GLASS:15)
B(9,7,3,STAINED_GLASS:15)
B(5,8,0,STAINED_GLASS:15)
B(6,8,0,STAINED_GLASS:15)
B(7,8,0,SEA_LANTERN)
B(8,8,0,SEA_LANTERN)
B(9,8,0,STAINED_GLASS:11)
B(6,8,1,STAINED_GLASS:15)
B(7,8,1,SEA_LANTERN)
B(8,8,1,SEA_LANTERN)
B(9,8,1,STAINED_GLASS:11)
B(10,8,1,STAINED_GLASS:11)
B(6,8,2,STAINED_GLASS:15)
B(7,8,2,STAINED_GLASS:15)
B(8,8,2,STAINED_GLASS:15)
B(9,8,2,STAINED_GLASS:15)
B(10,8,2,STAINED_GLASS:11)
B(7,8,3,STAINED_GLASS:15)
B(5,9,0,STAINED_GLASS:15)
B(6,9,0,STAINED_GLASS:15)
B(7,9,0,SEA_LANTERN)
B(8,9,0,SEA_LANTERN)
B(9,9,0,STAINED_GLASS:11)
B(6,9,1,STAINED_GLASS:15)
B(7,9,1,STAINED_GLASS:11)
B(8,9,1,SEA_LANTERN)
B(9,9,1,STAINED_GLASS:11)
B(10,9,1,STAINED_GLASS:11)
B(6,9,2,STAINED_GLASS:15)
B(7,9,2,STAINED_GLASS:15)
B(9,9,2,STAINED_GLASS:11)
B(5,10,0,STAINED_GLASS:15)
B(6,10,0,STAINED_GLASS:15)
B(7,10,0,SEA_LANTERN)
B(8,10,0,SEA_LANTERN)
B(9,10,0,STAINED_GLASS:11)
B(6,10,1,STAINED_GLASS:15)
B(7,10,1,STAINED_GLASS:11)
B(8,10,1,STAINED_GLASS:11)
B(9,10,1,STAINED_GLASS:11)
B(7,10,2,STAINED_GLASS:11)
B(9,10,2,STAINED_GLASS:11)
B(5,11,0,STAINED_GLASS:15)
B(6,11,0,STAINED_GLASS:15)
B(7,11,0,SEA_LANTERN)
B(8,11,0,STAINED_GLASS:11)
B(9,11,0,STAINED_GLASS:11)
B(6,11,1,STAINED_GLASS:15)
B(7,11,1,STAINED_GLASS:11)
B(8,11,1,STAINED_GLASS:11)
B(9,11,1,STAINED_GLASS:11)
B(5,12,0,STAINED_GLASS:15)
B(6,12,0,STAINED_GLASS:15)
B(7,12,0,SEA_LANTERN)
B(8,12,0,STAINED_GLASS:11)
B(6,12,1,STAINED_GLASS:15)
B(7,12,1,STAINED_GLASS:11)
B(5,13,0,STAINED_GLASS:15)
B(6,13,0,STAINED_GLASS:15)
B(7,13,0,STAINED_GLASS:11)
B(8,13,0,STAINED_GLASS:11)
B(7,13,1,STAINED_GLASS:11)
B(5,14,0,STAINED_GLASS:15)
B(6,14,0,STAINED_GLASS:11)
B(7,14,0,STAINED_GLASS:11)
B(5,15,0,STAINED_GLASS:15)

#######################################################################
# +-----------------------------------------------------------------+ #
# |                             Branches                            | #
# +-----------------------------------------------------------------+ #
#######################################################################

BR(0,0,-16,true,SPIKE-SET-MED-BIG-04_0x0,NORTH,100,0)
