Author: Bo3 BulkEdit

Description: Converted Schematic - Modified by Bo3BulkEdit

Version: 3

SettingsMode: WriteDisable

IsOTGPlus: false
Tree: false
Frequency: 1
Rarity: 100
RotateRandomly: true
SpawnHeight: randomY
SpawnHeightOffset: 0
MaxBranchDepth: 10
ExcludedBiomes: All

MinHeight: 0
MaxHeight: 254

SourceBlocks: AIR,DIRT,STONE,DIRT:1,DIRT:2,GRASS,STATIONARY_WATER,LEAVES
MaxPercentageOutsideSourceBlock: 5
OutsideSourceBlock: placeAnyway

BlockCheck(-7,1,-4,Solid)
BlockCheck(9,1,-4,Solid)
BlockCheck(-9,1,0,Solid)
BlockCheck(-9,1,4,Solid)
BlockCheck(9,1,4,Solid)
BlockCheck(0,2,0,AIR,WATER)

E(7,6,2,VILLAGER,1)

B(-7,2,-4,LOG:1)
B(9,2,-4,LOG:1)
B(-9,2,0,LOG:1)
B(-9,2,4,LOG:1)
B(9,2,4,LOG:1)
B(-7,0,-4,LOG:1)
B(-6,0,-4,COBBLESTONE:0)
B(-5,0,-4,COBBLESTONE:0)
B(-4,0,-4,COBBLESTONE:0)
B(-3,0,-4,LOG:1)
B(-2,0,-4,COBBLESTONE:0)
B(-1,0,-4,COBBLESTONE:0)
B(0,0,-4,COBBLESTONE:0)
B(1,0,-4,LOG:1)
B(2,0,-4,COBBLESTONE:0)
B(3,0,-4,COBBLESTONE:0)
B(4,0,-4,COBBLESTONE:0)
B(5,0,-4,LOG:1)
B(6,0,-4,COBBLESTONE:0)
B(7,0,-4,COBBLESTONE:0)
B(8,0,-4,COBBLESTONE:0)
B(9,0,-4,LOG:1)
B(-7,0,-3,COBBLESTONE:0)
B(-6,0,-3,DIRT:0)
B(-5,0,-3,DIRT:0)
B(-4,0,-3,DIRT:0)
B(-3,0,-3,DIRT:0)
B(-2,0,-3,DIRT:0)
B(-1,0,-3,DIRT:0)
B(0,0,-3,DIRT:0)
B(1,0,-3,DIRT:0)
B(2,0,-3,DIRT:0)
B(3,0,-3,DIRT:0)
B(4,0,-3,DIRT:0)
B(5,0,-3,DIRT:0)
B(6,0,-3,DIRT:0)
B(7,0,-3,DIRT:0)
B(8,0,-3,DIRT:0)
B(9,0,-3,COBBLESTONE:0)
B(-7,0,-2,COBBLESTONE:0)
B(-6,0,-2,DIRT:0)
B(-5,0,-2,DIRT:0)
B(-4,0,-2,DIRT:0)
B(-3,0,-2,DIRT:0)
B(-2,0,-2,DIRT:0)
B(-1,0,-2,DIRT:0)
B(0,0,-2,DIRT:0)
B(1,0,-2,DIRT:0)
B(2,0,-2,DIRT:0)
B(3,0,-2,DIRT:0)
B(4,0,-2,DIRT:0)
B(5,0,-2,DIRT:0)
B(6,0,-2,DIRT:0)
B(7,0,-2,DIRT:0)
B(8,0,-2,DIRT:0)
B(9,0,-2,COBBLESTONE:0)
B(-7,0,-1,COBBLESTONE:0)
B(-6,0,-1,DIRT:0)
B(-5,0,-1,DIRT:0)
B(-4,0,-1,DIRT:0)
B(-3,0,-1,DIRT:0)
B(-2,0,-1,DIRT:0)
B(-1,0,-1,DIRT:0)
B(0,0,-1,DIRT:0)
B(1,0,-1,DIRT:0)
B(2,0,-1,DIRT:0)
B(3,0,-1,DIRT:0)
B(4,0,-1,DIRT:0)
B(5,0,-1,DIRT:0)
B(6,0,-1,DIRT:0)
B(7,0,-1,DIRT:0)
B(8,0,-1,DIRT:0)
B(9,0,-1,COBBLESTONE:0)
B(-9,0,0,LOG:1)
B(-8,0,0,COBBLESTONE:0)
B(-7,0,0,DIRT:0)
B(-6,0,0,DIRT:0)
B(-5,0,0,DIRT:0)
B(-4,0,0,DIRT:0)
B(-3,0,0,DIRT:0)
B(-2,0,0,DIRT:0)
B(-1,0,0,DIRT:0)
B(0,0,0,DIRT:0)
B(1,0,0,DIRT:0)
B(2,0,0,DIRT:0)
B(3,0,0,DIRT:0)
B(4,0,0,DIRT:0)
B(5,0,0,LOG:1)
B(6,0,0,STONEBRICK:0)
B(7,0,0,STONEBRICK:0)
B(8,0,0,STONEBRICK:0)
B(9,0,0,LOG:1)
B(-9,0,1,COBBLESTONE:0)
B(-8,0,1,DIRT:0)
B(-7,0,1,DIRT:0)
B(-6,0,1,DIRT:0)
B(-5,0,1,DIRT:0)
B(-4,0,1,DIRT:0)
B(-3,0,1,DIRT:0)
B(-2,0,1,STONEBRICK:0)
B(-1,0,1,STONEBRICK:0)
B(0,0,1,STONEBRICK:0)
B(1,0,1,DIRT:0)
B(2,0,1,DIRT:0)
B(3,0,1,DIRT:0)
B(4,0,1,DIRT:0)
B(5,0,1,STONEBRICK:0)
B(6,0,1,MAGMA:0)
B(7,0,1,MAGMA:0)
B(8,0,1,MAGMA:0)
B(9,0,1,STONEBRICK:0)
B(-9,0,2,COBBLESTONE:0)
B(-8,0,2,DIRT:0)
B(-7,0,2,DIRT:0)
B(-6,0,2,DIRT:0)
B(-5,0,2,DIRT:0)
B(-4,0,2,DIRT:0)
B(-3,0,2,DIRT:0)
B(-2,0,2,STONEBRICK:0)
B(-1,0,2,STONEBRICK:0)
B(0,0,2,STONEBRICK:0)
B(1,0,2,DIRT:0)
B(2,0,2,DIRT:0)
B(3,0,2,DIRT:0)
B(4,0,2,DIRT:0)
B(5,0,2,STONEBRICK:0)
B(6,0,2,MAGMA:0)
B(7,0,2,MAGMA:0)
B(8,0,2,MAGMA:0)
B(9,0,2,STONEBRICK:0)
B(-9,0,3,COBBLESTONE:0)
B(-8,0,3,DIRT:0)
B(-7,0,3,DIRT:0)
B(-6,0,3,DIRT:0)
B(-5,0,3,DIRT:0)
B(-4,0,3,DIRT:0)
B(-3,0,3,DIRT:0)
B(-2,0,3,STONEBRICK:0)
B(-1,0,3,STONEBRICK:0)
B(0,0,3,STONEBRICK:0)
B(1,0,3,DIRT:0)
B(2,0,3,DIRT:0)
B(3,0,3,DIRT:0)
B(4,0,3,DIRT:0)
B(5,0,3,STONEBRICK:0)
B(6,0,3,MAGMA:0)
B(7,0,3,MAGMA:0)
B(8,0,3,MAGMA:0)
B(9,0,3,STONEBRICK:0)
B(-9,0,4,LOG:1)
B(-8,0,4,COBBLESTONE:0)
B(-7,0,4,LOG:1)
B(-6,0,4,COBBLESTONE:0)
B(-5,0,4,COBBLESTONE:0)
B(-4,0,4,COBBLESTONE:0)
B(-3,0,4,LOG:1)
B(-2,0,4,STONEBRICK:0)
B(-1,0,4,STONEBRICK:0)
B(0,0,4,STONEBRICK:0)
B(1,0,4,LOG:1)
B(2,0,4,COBBLESTONE:0)
B(3,0,4,COBBLESTONE:0)
B(4,0,4,COBBLESTONE:0)
B(5,0,4,LOG:1)
B(6,0,4,STONEBRICK:0)
B(7,0,4,STONEBRICK:0)
B(8,0,4,STONEBRICK:0)
B(9,0,4,LOG:1)
B(-7,1,-4,LOG:1)
B(-6,1,-4,COBBLESTONE:0)
B(-5,1,-4,COBBLESTONE:0)
B(-4,1,-4,COBBLESTONE:0)
B(-3,1,-4,LOG:1)
B(-2,1,-4,COBBLESTONE:0)
B(-1,1,-4,COBBLESTONE:0)
B(0,1,-4,COBBLESTONE:0)
B(1,1,-4,LOG:1)
B(2,1,-4,COBBLESTONE:0)
B(3,1,-4,COBBLESTONE:0)
B(4,1,-4,COBBLESTONE:0)
B(5,1,-4,LOG:1)
B(6,1,-4,COBBLESTONE:0)
B(7,1,-4,COBBLESTONE:0)
B(8,1,-4,COBBLESTONE:0)
B(9,1,-4,LOG:1)
B(-7,1,-3,COBBLESTONE:0)
B(-6,1,-3,DIRT:0)
B(-5,1,-3,DIRT:0)
B(-4,1,-3,DIRT:0)
B(-3,1,-3,DIRT:0)
B(-2,1,-3,DIRT:0)
B(-1,1,-3,DIRT:0)
B(0,1,-3,DIRT:0)
B(1,1,-3,DIRT:0)
B(2,1,-3,DIRT:0)
B(3,1,-3,DIRT:0)
B(4,1,-3,DIRT:0)
B(5,1,-3,DIRT:0)
B(6,1,-3,DIRT:0)
B(7,1,-3,DIRT:0)
B(8,1,-3,DIRT:0)
B(9,1,-3,COBBLESTONE:0)
B(-7,1,-2,COBBLESTONE:0)
B(-6,1,-2,DIRT:0)
B(-5,1,-2,DIRT:0)
B(-4,1,-2,DIRT:0)
B(-3,1,-2,DIRT:0)
B(-2,1,-2,DIRT:0)
B(-1,1,-2,DIRT:0)
B(0,1,-2,DIRT:0)
B(1,1,-2,DIRT:0)
B(2,1,-2,DIRT:0)
B(3,1,-2,DIRT:0)
B(4,1,-2,DIRT:0)
B(5,1,-2,DIRT:0)
B(6,1,-2,DIRT:0)
B(7,1,-2,DIRT:0)
B(8,1,-2,DIRT:0)
B(9,1,-2,COBBLESTONE:0)
B(-7,1,-1,COBBLESTONE:0)
B(-6,1,-1,DIRT:0)
B(-5,1,-1,DIRT:0)
B(-4,1,-1,DIRT:0)
B(-3,1,-1,DIRT:0)
B(-2,1,-1,DIRT:0)
B(-1,1,-1,DIRT:0)
B(0,1,-1,DIRT:0)
B(1,1,-1,DIRT:0)
B(2,1,-1,DIRT:0)
B(3,1,-1,DIRT:0)
B(4,1,-1,DIRT:0)
B(5,1,-1,DIRT:0)
B(6,1,-1,DIRT:0)
B(7,1,-1,DIRT:0)
B(8,1,-1,DIRT:0)
B(9,1,-1,COBBLESTONE:0)
B(-9,1,0,LOG:1)
B(-8,1,0,COBBLESTONE:0)
B(-7,1,0,DIRT:0)
B(-6,1,0,DIRT:0)
B(-5,1,0,DIRT:0)
B(-4,1,0,DIRT:0)
B(-3,1,0,LOG:1)
B(-2,1,0,STONEBRICK:0)
B(-1,1,0,STONEBRICK:0)
B(0,1,0,STONEBRICK:0)
B(1,1,0,LOG:1)
B(2,1,0,DIRT:0)
B(3,1,0,DIRT:0)
B(4,1,0,DIRT:0)
B(5,1,0,LOG:1)
B(6,1,0,STONEBRICK:0)
B(7,1,0,STONEBRICK:0)
B(8,1,0,STONEBRICK:0)
B(9,1,0,LOG:1)
B(-9,1,1,COBBLESTONE:0)
B(-8,1,1,DIRT:0)
B(-7,1,1,DIRT:0)
B(-6,1,1,DIRT:0)
B(-5,1,1,DIRT:0)
B(-4,1,1,DIRT:0)
B(-3,1,1,STONEBRICK:0)
B(-2,1,1,WEB:0)
RB(-1,1,1,SKULL:1,../NBT/Skulls/dungeon_skull_01.nbt,6,AIR,9,SKULL:1,../NBT/Skulls/dungeon_skull_02.nbt,12,AIR,15,SKULL:1,../NBT/Skulls/dungeon_skull_03.nbt,18,AIR,21,SKULL:1,../NBT/Skulls/dungeon_skull_04.nbt,24,AIR,27,SKULL:1,../NBT/Skulls/dungeon_skull_05.nbt,30,AIR,33,SKULL:1,../NBT/Skulls/dungeon_skull_06.nbt,36,AIR,39,SKULL:1,../NBT/Skulls/dungeon_skull_07.nbt,42,AIR,45,SKULL:1,../NBT/Skulls/dungeon_skull_08.nbt,48,AIR,51,SKULL:1,../NBT/Skulls/dungeon_skull_09.nbt,54,AIR,57,SKULL:1,../NBT/Skulls/dungeon_skull_10.nbt,60,AIR,63,SKULL:1,../NBT/Skulls/dungeon_skull_11.nbt,66,AIR,69,SKULL:1,../NBT/Skulls/dungeon_skull_12.nbt,72,AIR,75,SKULL:1,../NBT/Skulls/dungeon_skull_13.nbt,78,AIR,81,SKULL:1,../NBT/Skulls/dungeon_skull_14.nbt,84,AIR,87,SKULL:1,../NBT/Skulls/dungeon_skull_15.nbt,90,AIR,93,SKULL:1,../NBT/Skulls/dungeon_skull_16.nbt,96,AIR,100)
B(0,1,1,AIR:0)
B(1,1,1,STONEBRICK:0)
B(2,1,1,DIRT:0)
B(3,1,1,DIRT:0)
B(4,1,1,DIRT:0)
B(5,1,1,STONEBRICK:0)
B(6,1,1,AIR:0)
B(7,1,1,AIR:0)
B(8,1,1,AIR:0)
B(9,1,1,STONEBRICK:0)
B(-9,1,2,COBBLESTONE:0)
B(-8,1,2,DIRT:0)
B(-7,1,2,DIRT:0)
B(-6,1,2,DIRT:0)
B(-5,1,2,DIRT:0)
B(-4,1,2,DIRT:0)
B(-3,1,2,STONEBRICK:0)
B(-2,1,2,AIR:0)
B(-1,1,2,AIR:0)
RB(0,1,2,SKULL:1,../NBT/Skulls/dungeon_skull_01.nbt,6,AIR,9,SKULL:1,../NBT/Skulls/dungeon_skull_02.nbt,12,AIR,15,SKULL:1,../NBT/Skulls/dungeon_skull_03.nbt,18,AIR,21,SKULL:1,../NBT/Skulls/dungeon_skull_04.nbt,24,AIR,27,SKULL:1,../NBT/Skulls/dungeon_skull_05.nbt,30,AIR,33,SKULL:1,../NBT/Skulls/dungeon_skull_06.nbt,36,AIR,39,SKULL:1,../NBT/Skulls/dungeon_skull_07.nbt,42,AIR,45,SKULL:1,../NBT/Skulls/dungeon_skull_08.nbt,48,AIR,51,SKULL:1,../NBT/Skulls/dungeon_skull_09.nbt,54,AIR,57,SKULL:1,../NBT/Skulls/dungeon_skull_10.nbt,60,AIR,63,SKULL:1,../NBT/Skulls/dungeon_skull_11.nbt,66,AIR,69,SKULL:1,../NBT/Skulls/dungeon_skull_12.nbt,72,AIR,75,SKULL:1,../NBT/Skulls/dungeon_skull_13.nbt,78,AIR,81,SKULL:1,../NBT/Skulls/dungeon_skull_14.nbt,84,AIR,87,SKULL:1,../NBT/Skulls/dungeon_skull_15.nbt,90,AIR,93,SKULL:1,../NBT/Skulls/dungeon_skull_16.nbt,96,AIR,100)
B(1,1,2,STONEBRICK:0)
B(2,1,2,DIRT:0)
B(3,1,2,DIRT:0)
B(4,1,2,DIRT:0)
B(5,1,2,STONEBRICK:0)
B(6,1,2,AIR:0)
B(7,1,2,AIR:0)
B(8,1,2,AIR:0)
B(9,1,2,STONEBRICK:0)
B(-9,1,3,COBBLESTONE:0)
B(-8,1,3,DIRT:0)
B(-7,1,3,DIRT:0)
B(-6,1,3,DIRT:0)
B(-5,1,3,DIRT:0)
B(-4,1,3,DIRT:0)
B(-3,1,3,STONEBRICK:0)
RB(-2,1,3,SKULL:1,../NBT/Skulls/dungeon_skull_01.nbt,6,AIR,9,SKULL:1,../NBT/Skulls/dungeon_skull_02.nbt,12,AIR,15,SKULL:1,../NBT/Skulls/dungeon_skull_03.nbt,18,AIR,21,SKULL:1,../NBT/Skulls/dungeon_skull_04.nbt,24,AIR,27,SKULL:1,../NBT/Skulls/dungeon_skull_05.nbt,30,AIR,33,SKULL:1,../NBT/Skulls/dungeon_skull_06.nbt,36,AIR,39,SKULL:1,../NBT/Skulls/dungeon_skull_07.nbt,42,AIR,45,SKULL:1,../NBT/Skulls/dungeon_skull_08.nbt,48,AIR,51,SKULL:1,../NBT/Skulls/dungeon_skull_09.nbt,54,AIR,57,SKULL:1,../NBT/Skulls/dungeon_skull_10.nbt,60,AIR,63,SKULL:1,../NBT/Skulls/dungeon_skull_11.nbt,66,AIR,69,SKULL:1,../NBT/Skulls/dungeon_skull_12.nbt,72,AIR,75,SKULL:1,../NBT/Skulls/dungeon_skull_13.nbt,78,AIR,81,SKULL:1,../NBT/Skulls/dungeon_skull_14.nbt,84,AIR,87,SKULL:1,../NBT/Skulls/dungeon_skull_15.nbt,90,AIR,93,SKULL:1,../NBT/Skulls/dungeon_skull_16.nbt,96,AIR,100)
B(0,1,3,WEB:0)
B(1,1,3,STONEBRICK:0)
B(2,1,3,DIRT:0)
B(3,1,3,DIRT:0)
B(4,1,3,DIRT:0)
B(5,1,3,STONEBRICK:0)
B(6,1,3,AIR:0)
B(7,1,3,AIR:0)
B(8,1,3,AIR:0)
B(9,1,3,STONEBRICK:0)
B(-9,1,4,LOG:1)
B(-8,1,4,COBBLESTONE:0)
B(-7,1,4,LOG:1)
B(-6,1,4,COBBLESTONE:0)
B(-5,1,4,COBBLESTONE:0)
B(-4,1,4,COBBLESTONE:0)
B(-3,1,4,LOG:1)
B(-2,1,4,STONEBRICK:0)
B(-1,1,4,STONEBRICK:0)
B(0,1,4,STONEBRICK:0)
B(1,1,4,LOG:1)
B(2,1,4,COBBLESTONE:0)
B(3,1,4,COBBLESTONE:0)
B(4,1,4,COBBLESTONE:0)
B(5,1,4,LOG:1)
B(6,1,4,STONEBRICK:0)
B(7,1,4,STONEBRICK:0)
B(8,1,4,STONEBRICK:0)
B(9,1,4,LOG:1)
B(-6,2,-4,COBBLESTONE:0)
B(-5,2,-4,COBBLESTONE:0)
B(-4,2,-4,COBBLESTONE:0)
B(-3,2,-4,LOG:1)
B(-2,2,-4,COBBLESTONE:0)
B(-1,2,-4,COBBLESTONE:0)
B(0,2,-4,COBBLESTONE:0)
B(1,2,-4,LOG:1)
B(2,2,-4,COBBLESTONE:0)
B(3,2,-4,COBBLESTONE:0)
B(4,2,-4,COBBLESTONE:0)
B(5,2,-4,LOG:1)
B(6,2,-4,COBBLESTONE:0)
B(7,2,-4,COBBLESTONE:0)
B(8,2,-4,COBBLESTONE:0)
B(-7,2,-3,COBBLESTONE:0)
B(-6,2,-3,GRASS:0)
B(-5,2,-3,GRASS:0)
B(-4,2,-3,GRASS:0)
B(-3,2,-3,GRASS:0)
B(-2,2,-3,GRASS:0)
B(-1,2,-3,GRASS:0)
B(0,2,-3,GRASS:0)
B(1,2,-3,DIRT:0)
B(2,2,-3,GRASS:0)
B(3,2,-3,DIRT:0)
B(4,2,-3,GRASS:0)
B(5,2,-3,GRASS:0)
B(6,2,-3,GRASS:0)
B(7,2,-3,GRASS:0)
B(8,2,-3,DIRT:0)
B(9,2,-3,COBBLESTONE:0)
B(-7,2,-2,COBBLESTONE:0)
B(-6,2,-2,GRASS:0)
B(-5,2,-2,GRASS:0)
B(-4,2,-2,GRASS:0)
B(-3,2,-2,GRASS:0)
B(-2,2,-2,GRASS:0)
B(-1,2,-2,DIRT:0)
B(0,2,-2,GRASS:0)
B(1,2,-2,GRASS:0)
B(2,2,-2,GRASS:0)
B(3,2,-2,GRASS:0)
B(4,2,-2,GRASS:0)
B(5,2,-2,GRASS:0)
B(6,2,-2,GRASS:0)
B(7,2,-2,DIRT:0)
B(8,2,-2,GRASS:0)
B(9,2,-2,COBBLESTONE:0)
B(-7,2,-1,COBBLESTONE:0)
B(-6,2,-1,GRASS:0)
B(-5,2,-1,GRASS:0)
B(-4,2,-1,GRASS:0)
B(-3,2,-1,GRASS:0)
B(-2,2,-1,GRASS:0)
B(-1,2,-1,GRASS:0)
B(0,2,-1,GRASS:0)
B(1,2,-1,GRASS:0)
B(2,2,-1,GRASS:0)
B(3,2,-1,GRASS:0)
B(4,2,-1,GRASS:0)
B(5,2,-1,GRASS:0)
B(6,2,-1,GRASS:0)
B(7,2,-1,GRASS:0)
B(8,2,-1,DIRT:0)
B(9,2,-1,COBBLESTONE:0)
B(-8,2,0,COBBLESTONE:0)
B(-7,2,0,DIRT:0)
B(-6,2,0,GRASS:0)
B(-5,2,0,GRASS:0)
B(-4,2,0,GRASS:0)
B(-3,2,0,LOG:1)
B(-2,2,0,STONE_BRICK_STAIRS:3)
B(-1,2,0,STONE_BRICK_STAIRS:3)
B(0,2,0,STONE_BRICK_STAIRS:3)
B(1,2,0,LOG:1)
B(2,2,0,GRASS:0)
B(3,2,0,GRASS:0)
B(4,2,0,DIRT:0)
B(5,2,0,LOG:1)
B(6,2,0,STONE_BRICK_STAIRS:3)
B(7,2,0,STONE_BRICK_STAIRS:3)
B(8,2,0,STONE_BRICK_STAIRS:3)
B(9,2,0,LOG:1)
B(-9,2,1,COBBLESTONE:0)
B(-8,2,1,COBBLESTONE:0)
B(-7,2,1,GRASS:0)
B(-6,2,1,GRASS:0)
B(-5,2,1,GRASS:0)
B(-4,2,1,GRASS:0)
B(-3,2,1,STONE_BRICK_STAIRS:1)
B(-2,2,1,AIR:0)
B(-1,2,1,AIR:0)
B(0,2,1,AIR:0)
B(1,2,1,STONE_BRICK_STAIRS:0)
B(2,2,1,DIRT:0)
B(3,2,1,GRASS:0)
B(4,2,1,GRASS:0)
B(5,2,1,STONE_BRICK_STAIRS:1)
B(6,2,1,AIR:0)
B(7,2,1,AIR:0)
B(8,2,1,AIR:0)
B(9,2,1,STONE_BRICK_STAIRS:0)
B(-9,2,2,COBBLESTONE:0)
B(-8,2,2,COBBLESTONE:0)
B(-7,2,2,GRASS:0)
B(-6,2,2,GRASS:0)
B(-5,2,2,GRASS:0)
B(-4,2,2,GRASS:0)
B(-3,2,2,STONE_BRICK_STAIRS:1)
B(-2,2,2,AIR:0)
B(-1,2,2,AIR:0)
B(0,2,2,AIR:0)
B(1,2,2,STONE_BRICK_STAIRS:0)
B(2,2,2,GRASS:0)
B(3,2,2,GRASS:0)
B(4,2,2,GRASS:0)
B(5,2,2,STONE_BRICK_STAIRS:1)
B(6,2,2,AIR:0)
B(7,2,2,AIR:0)
B(8,2,2,AIR:0)
B(9,2,2,STONE_BRICK_STAIRS:0)
B(-9,2,3,COBBLESTONE:0)
B(-8,2,3,COBBLESTONE:0)
B(-7,2,3,GRASS:0)
B(-6,2,3,GRASS:0)
B(-5,2,3,GRASS:0)
B(-4,2,3,GRASS:0)
B(-3,2,3,STONE_BRICK_STAIRS:1)
B(-2,2,3,AIR:0)
B(-1,2,3,AIR:0)
B(0,2,3,AIR:0)
B(1,2,3,STONE_BRICK_STAIRS:0)
B(2,2,3,GRASS:0)
B(3,2,3,GRASS:0)
B(4,2,3,GRASS:0)
B(5,2,3,STONE_BRICK_STAIRS:1)
B(6,2,3,AIR:0)
B(7,2,3,AIR:0)
B(8,2,3,AIR:0)
B(9,2,3,STONE_BRICK_STAIRS:0)
B(-8,2,4,COBBLESTONE:0)
B(-7,2,4,LOG:1)
B(-6,2,4,COBBLESTONE:0)
B(-5,2,4,COBBLESTONE:0)
B(-4,2,4,COBBLESTONE:0)
B(-3,2,4,LOG:1)
B(-2,2,4,STONE_BRICK_STAIRS:2)
B(-1,2,4,STONE_BRICK_STAIRS:2)
B(0,2,4,STONE_BRICK_STAIRS:2)
B(1,2,4,LOG:1)
B(2,2,4,COBBLESTONE:0)
B(3,2,4,COBBLESTONE:0)
B(4,2,4,COBBLESTONE:0)
B(5,2,4,LOG:1)
B(6,2,4,STONE_BRICK_STAIRS:2)
B(7,2,4,STONE_BRICK_STAIRS:2)
B(8,2,4,STONE_BRICK_STAIRS:2)
B(-7,3,-4,LOG:1)
B(-6,3,-4,FENCE:0)
B(-5,3,-4,FENCE:0)
B(-4,3,-4,FENCE:0)
B(-3,3,-4,LOG:1)
B(-2,3,-4,FENCE:0)
B(-1,3,-4,FENCE:0)
B(0,3,-4,FENCE:0)
B(1,3,-4,LOG:1)
B(2,3,-4,FENCE:0)
B(3,3,-4,FENCE:0)
B(4,3,-4,FENCE:0)
B(5,3,-4,LOG:1)
B(6,3,-4,FENCE:0)
B(7,3,-4,FENCE:0)
B(8,3,-4,FENCE:0)
B(9,3,-4,LOG:1)
B(-7,3,-3,FENCE:0)
B(-6,3,-3,AIR:0)
B(-5,3,-3,AIR:0)
B(-4,3,-3,AIR:0)
B(-3,3,-3,AIR:0)
B(-2,3,-3,AIR:0)
B(-1,3,-3,AIR:0)
B(0,3,-3,AIR:0)
B(1,3,-3,AIR:0)
B(2,3,-3,AIR:0)
B(3,3,-3,AIR:0)
B(4,3,-3,AIR:0)
B(5,3,-3,FENCE:0)
B(6,3,-3,AIR:0)
B(7,3,-3,AIR:0)
B(8,3,-3,AIR:0)
B(9,3,-3,FENCE:0)
B(-7,3,-2,FENCE:0)
B(-6,3,-2,AIR:0)
B(-5,3,-2,AIR:0)
B(-4,3,-2,AIR:0)
B(-3,3,-2,AIR:0)
B(-2,3,-2,AIR:0)
B(-1,3,-2,LOG:1)
B(0,3,-2,AIR:0)
B(1,3,-2,AIR:0)
B(2,3,-2,AIR:0)
B(3,3,-2,AIR:0)
B(4,3,-2,AIR:0)
B(5,3,-2,FENCE:0)
B(6,3,-2,AIR:0)
B(7,3,-2,LOG:1)
B(8,3,-2,AIR:0)
B(9,3,-2,FENCE:0)
B(-7,3,-1,FENCE:0)
B(-6,3,-1,AIR:0)
B(-5,3,-1,AIR:0)
B(-4,3,-1,AIR:0)
B(-3,3,-1,AIR:0)
B(-2,3,-1,AIR:0)
B(-1,3,-1,AIR:0)
B(0,3,-1,AIR:0)
B(1,3,-1,AIR:0)
B(2,3,-1,AIR:0)
B(3,3,-1,AIR:0)
B(4,3,-1,AIR:0)
B(5,3,-1,FENCE:0)
B(6,3,-1,AIR:0)
B(7,3,-1,AIR:0)
B(8,3,-1,AIR:0)
B(9,3,-1,FENCE:0)
B(-9,3,0,LOG:1)
B(-8,3,0,FENCE:0)
B(-7,3,0,LOG:1)
B(-6,3,0,AIR:0)
B(-5,3,0,AIR:0)
B(-4,3,0,AIR:0)
B(-3,3,0,LOG:1)
B(-2,3,0,FENCE:0)
B(-1,3,0,FENCE:0)
B(0,3,0,FENCE:0)
B(1,3,0,LOG:1)
B(2,3,0,AIR:0)
B(3,3,0,AIR:0)
B(4,3,0,AIR:0)
B(5,3,0,LOG:1)
B(6,3,0,FENCE:0)
B(7,3,0,FENCE:0)
B(8,3,0,FENCE:0)
B(9,3,0,LOG:1)
B(-9,3,1,SPRUCE_STAIRS:0)
B(-8,3,1,SPRUCE_STAIRS:5)
B(-7,3,1,FENCE:0)
B(-6,3,1,AIR:0)
B(-5,3,1,AIR:0)
B(-4,3,1,AIR:0)
B(-3,3,1,FENCE:0)
B(-2,3,1,AIR:0)
B(-1,3,1,AIR:0)
B(0,3,1,WEB:0)
B(1,3,1,FENCE:0)
B(2,3,1,AIR:0)
B(3,3,1,AIR:0)
B(4,3,1,AIR:0)
B(5,3,1,FENCE:0)
B(6,3,1,AIR:0)
B(7,3,1,AIR:0)
B(8,3,1,AIR:0)
B(9,3,1,FENCE:0)
B(-9,3,2,SPRUCE_STAIRS:0)
B(-8,3,2,SPRUCE_STAIRS:5)
B(-7,3,2,FENCE:0)
B(-6,3,2,AIR:0)
B(-5,3,2,AIR:0)
B(-4,3,2,AIR:0)
B(-3,3,2,FENCE:0)
B(-2,3,2,AIR:0)
B(-1,3,2,AIR:0)
B(0,3,2,AIR:0)
B(1,3,2,FENCE:0)
B(2,3,2,AIR:0)
B(3,3,2,AIR:0)
B(4,3,2,AIR:0)
B(5,3,2,FENCE:0)
B(6,3,2,AIR:0)
B(7,3,2,AIR:0)
B(8,3,2,AIR:0)
B(9,3,2,FENCE:0)
B(-9,3,3,SPRUCE_STAIRS:0)
B(-8,3,3,SPRUCE_STAIRS:5)
B(-7,3,3,FENCE:0)
B(-6,3,3,AIR:0)
B(-5,3,3,AIR:0)
B(-4,3,3,AIR:0)
B(-3,3,3,FENCE:0)
B(-2,3,3,WEB:0)
B(-1,3,3,AIR:0)
B(0,3,3,AIR:0)
B(1,3,3,FENCE:0)
B(2,3,3,AIR:0)
B(3,3,3,AIR:0)
B(4,3,3,AIR:0)
B(5,3,3,FENCE:0)
B(6,3,3,AIR:0)
B(7,3,3,AIR:0)
B(8,3,3,AIR:0)
B(9,3,3,FENCE:0)
B(-9,3,4,LOG:1)
B(-8,3,4,FENCE:0)
B(-7,3,4,LOG:1)
B(-6,3,4,FENCE:0)
B(-5,3,4,FENCE:0)
B(-4,3,4,FENCE:0)
B(-3,3,4,LOG:1)
B(-2,3,4,FENCE:0)
B(-1,3,4,FENCE:0)
B(0,3,4,FENCE:0)
B(1,3,4,LOG:1)
B(2,3,4,FENCE:0)
B(3,3,4,FENCE:0)
B(4,3,4,FENCE:0)
B(5,3,4,LOG:1)
B(6,3,4,FENCE:0)
B(7,3,4,FENCE:0)
B(8,3,4,FENCE:0)
B(9,3,4,LOG:1)
RB(-7,4,-5,WALL_BANNER:2,../NBT/Banners/Banner1.nbt,25,WALL_BANNER:2,../NBT/Banners/Banner2.nbt,25,WALL_BANNER:2,../NBT/Banners/Banner3.nbt,100)
RB(-3,4,-5,WALL_BANNER:2,../NBT/Banners/Banner1.nbt,25,WALL_BANNER:2,../NBT/Banners/Banner2.nbt,25,WALL_BANNER:2,../NBT/Banners/Banner3.nbt,100)
RB(1,4,-5,WALL_BANNER:2,../NBT/Banners/Banner1.nbt,25,WALL_BANNER:2,../NBT/Banners/Banner2.nbt,25,WALL_BANNER:2,../NBT/Banners/Banner3.nbt,100)
RB(5,4,-5,WALL_BANNER:2,../NBT/Banners/Banner1.nbt,25,WALL_BANNER:2,../NBT/Banners/Banner2.nbt,25,WALL_BANNER:2,../NBT/Banners/Banner3.nbt,100)
RB(9,4,-5,WALL_BANNER:2,../NBT/Banners/Banner1.nbt,25,WALL_BANNER:2,../NBT/Banners/Banner2.nbt,25,WALL_BANNER:2,../NBT/Banners/Banner3.nbt,100)
RB(-8,4,-4,WALL_BANNER:4,../NBT/Banners/Banner1.nbt,25,WALL_BANNER:4,../NBT/Banners/Banner2.nbt,25,WALL_BANNER:4,../NBT/Banners/Banner3.nbt,100)
B(-7,4,-4,LOG:1)
B(-6,4,-4,LOG2:5)
B(-5,4,-4,LOG2:5)
B(-4,4,-4,LOG2:5)
B(-3,4,-4,LOG:1)
B(-2,4,-4,LOG2:5)
B(-1,4,-4,LOG2:5)
B(0,4,-4,LOG2:5)
B(1,4,-4,LOG:1)
B(2,4,-4,LOG2:5)
B(3,4,-4,LOG2:5)
B(4,4,-4,LOG2:5)
B(5,4,-4,LOG:1)
B(6,4,-4,LOG2:5)
B(7,4,-4,LOG2:5)
B(8,4,-4,LOG2:5)
B(9,4,-4,LOG:1)
RB(10,4,-4,WALL_BANNER:5,../NBT/Banners/Banner1.nbt,25,WALL_BANNER:5,../NBT/Banners/Banner2.nbt,25,WALL_BANNER:5,../NBT/Banners/Banner3.nbt,100)
B(-7,4,-3,LOG2:9)
B(-6,4,-3,WOODEN_SLAB:8)
B(-5,4,-3,WOODEN_SLAB:8)
B(-4,4,-3,WOODEN_SLAB:8)
B(-3,4,-3,LOG2:9)
B(-2,4,-3,WOODEN_SLAB:8)
B(-1,4,-3,WOODEN_SLAB:8)
B(0,4,-3,WOODEN_SLAB:8)
B(1,4,-3,LOG2:9)
B(2,4,-3,WOODEN_SLAB:8)
B(3,4,-3,WOODEN_SLAB:8)
B(4,4,-3,WOODEN_SLAB:8)
B(5,4,-3,LOG2:9)
B(6,4,-3,WOODEN_SLAB:8)
B(7,4,-3,WOODEN_SLAB:8)
B(8,4,-3,WOODEN_SLAB:8)
B(9,4,-3,LOG2:9)
B(-7,4,-2,LOG2:9)
B(-6,4,-2,WOODEN_SLAB:8)
B(-5,4,-2,WOODEN_SLAB:8)
B(-4,4,-2,WOODEN_SLAB:8)
B(-3,4,-2,LOG2:9)
B(-2,4,-2,WOODEN_SLAB:8)
B(-1,4,-2,LOG:1)
B(0,4,-2,WOODEN_SLAB:8)
B(1,4,-2,LOG2:9)
B(2,4,-2,WOODEN_SLAB:8)
B(3,4,-2,WOODEN_SLAB:8)
B(4,4,-2,WOODEN_SLAB:8)
B(5,4,-2,LOG2:9)
B(6,4,-2,WOODEN_SLAB:8)
B(7,4,-2,LOG:1)
B(8,4,-2,WOODEN_SLAB:8)
B(9,4,-2,LOG2:9)
B(-7,4,-1,LOG2:9)
B(-6,4,-1,WOODEN_SLAB:8)
B(-5,4,-1,WOODEN_SLAB:8)
B(-4,4,-1,WOODEN_SLAB:8)
B(-3,4,-1,LOG2:9)
B(-2,4,-1,WOODEN_SLAB:8)
B(-1,4,-1,WOODEN_SLAB:8)
B(0,4,-1,WOODEN_SLAB:8)
B(1,4,-1,LOG2:9)
B(2,4,-1,WOODEN_SLAB:8)
B(3,4,-1,WOODEN_SLAB:8)
B(4,4,-1,WOODEN_SLAB:8)
B(5,4,-1,LOG2:9)
B(6,4,-1,WOODEN_SLAB:8)
B(7,4,-1,WOODEN_SLAB:8)
B(8,4,-1,WOODEN_SLAB:8)
B(9,4,-1,LOG2:9)
B(-7,4,0,LOG:1)
B(-6,4,0,LOG2:5)
B(-5,4,0,LOG2:5)
B(-4,4,0,LOG2:5)
B(-3,4,0,LOG:1)
B(-2,4,0,LOG2:5)
B(-1,4,0,LOG2:5)
B(0,4,0,LOG2:5)
B(1,4,0,LOG:1)
B(2,4,0,LOG2:5)
B(3,4,0,LOG2:5)
B(4,4,0,LOG2:5)
B(5,4,0,LOG:1)
B(6,4,0,LOG2:5)
B(7,4,0,LOG2:5)
B(8,4,0,LOG2:5)
B(9,4,0,LOG:1)
RB(10,4,0,WALL_BANNER:5,../NBT/Banners/Banner1.nbt,25,WALL_BANNER:5,../NBT/Banners/Banner2.nbt,25,WALL_BANNER:5,../NBT/Banners/Banner3.nbt,100)
B(-8,4,1,SPRUCE_STAIRS:0)
B(-7,4,1,LOG2:9)
B(-6,4,1,WOODEN_SLAB:8)
B(-5,4,1,WOODEN_SLAB:8)
B(-4,4,1,WOODEN_SLAB:8)
B(-3,4,1,LOG2:9)
B(-2,4,1,WOODEN_SLAB:8)
B(-1,4,1,WOODEN_SLAB:8)
B(0,4,1,WOODEN_SLAB:8)
B(1,4,1,LOG2:9)
B(2,4,1,WOODEN_SLAB:8)
B(3,4,1,WOODEN_SLAB:8)
B(4,4,1,WOODEN_SLAB:8)
B(5,4,1,LOG2:9)
B(6,4,1,AIR:0)
B(7,4,1,AIR:0)
B(8,4,1,AIR:0)
B(9,4,1,LOG2:9)
B(-8,4,2,SPRUCE_STAIRS:0)
B(-7,4,2,LOG2:9)
B(-6,4,2,WOODEN_SLAB:8)
B(-5,4,2,WOODEN_SLAB:8)
B(-4,4,2,WOODEN_SLAB:8)
B(-3,4,2,LOG2:9)
B(-2,4,2,WOODEN_SLAB:8)
B(-1,4,2,AIR:0)
B(0,4,2,WOODEN_SLAB:8)
B(1,4,2,LOG2:9)
B(2,4,2,WOODEN_SLAB:8)
B(3,4,2,WOODEN_SLAB:8)
B(4,4,2,WOODEN_SLAB:8)
B(5,4,2,LOG2:9)
B(6,4,2,AIR:0)
B(7,4,2,HOPPER:0)
B(8,4,2,AIR:0)
B(9,4,2,LOG2:9)
B(-8,4,3,SPRUCE_STAIRS:0)
B(-7,4,3,LOG2:9)
B(-6,4,3,WOODEN_SLAB:8)
B(-5,4,3,WOODEN_SLAB:8)
B(-4,4,3,WOODEN_SLAB:8)
B(-3,4,3,LOG2:9)
B(-2,4,3,WOODEN_SLAB:8)
B(-1,4,3,WOODEN_SLAB:8)
B(0,4,3,WOODEN_SLAB:8)
B(1,4,3,LOG2:9)
B(2,4,3,WOODEN_SLAB:8)
B(3,4,3,WOODEN_SLAB:8)
B(4,4,3,WOODEN_SLAB:8)
B(5,4,3,LOG2:9)
B(6,4,3,AIR:0)
B(7,4,3,AIR:0)
B(8,4,3,AIR:0)
B(9,4,3,LOG2:9)
B(-7,4,4,LOG:1)
B(-6,4,4,LOG2:5)
B(-5,4,4,LOG2:5)
B(-4,4,4,LOG2:5)
B(-3,4,4,LOG:1)
B(-2,4,4,LOG2:5)
B(-1,4,4,LOG2:5)
B(0,4,4,LOG2:5)
B(1,4,4,LOG:1)
B(2,4,4,LOG2:5)
B(3,4,4,LOG2:5)
B(4,4,4,LOG2:5)
B(5,4,4,LOG:1)
B(6,4,4,LOG2:5)
B(7,4,4,LOG2:5)
B(8,4,4,LOG2:5)
B(9,4,4,LOG:1)
RB(10,4,4,WALL_BANNER:5,../NBT/Banners/Banner1.nbt,25,WALL_BANNER:5,../NBT/Banners/Banner2.nbt,25,WALL_BANNER:5,../NBT/Banners/Banner3.nbt,100)
RB(-7,4,5,WALL_BANNER:3,../NBT/Banners/Banner1.nbt,25,WALL_BANNER:3,../NBT/Banners/Banner2.nbt,25,WALL_BANNER:3,../NBT/Banners/Banner3.nbt,100)
RB(-3,4,5,WALL_BANNER:3,../NBT/Banners/Banner1.nbt,25,WALL_BANNER:3,../NBT/Banners/Banner2.nbt,25,WALL_BANNER:3,../NBT/Banners/Banner3.nbt,100)
RB(1,4,5,WALL_BANNER:3,../NBT/Banners/Banner1.nbt,25,WALL_BANNER:3,../NBT/Banners/Banner2.nbt,25,WALL_BANNER:3,../NBT/Banners/Banner3.nbt,100)
RB(5,4,5,WALL_BANNER:3,../NBT/Banners/Banner1.nbt,25,WALL_BANNER:3,../NBT/Banners/Banner2.nbt,25,WALL_BANNER:3,../NBT/Banners/Banner3.nbt,100)
RB(9,4,5,WALL_BANNER:3,../NBT/Banners/Banner1.nbt,25,WALL_BANNER:3,../NBT/Banners/Banner2.nbt,25,WALL_BANNER:3,../NBT/Banners/Banner3.nbt,100)
B(-7,5,-4,FENCE:0)
B(-5,5,-4,HAY_BLOCK:8)
B(-4,5,-4,HAY_BLOCK:0)
B(1,5,-4,FENCE:0)
B(9,5,-4,FENCE:0)
B(-6,5,-3,HAY_BLOCK:8)
B(-5,5,-3,HAY_BLOCK:0)
B(-4,5,-3,HAY_BLOCK:8)
B(-3,5,-3,HAY_BLOCK:0)
B(-6,5,-2,HAY_BLOCK:8)
B(-5,5,-2,HAY_BLOCK:8)
B(-4,5,-2,HAY_BLOCK:4)
B(-3,5,-2,SPRUCE_STAIRS:3)
B(-2,5,-2,LOG:5)
B(-1,5,-2,LOG:1)
B(0,5,-2,LOG:5)
B(1,5,-2,SPRUCE_STAIRS:1)
B(5,5,-2,SPRUCE_STAIRS:3)
B(6,5,-2,LOG:5)
B(7,5,-2,LOG:1)
B(8,5,-2,LOG:5)
B(9,5,-2,SPRUCE_STAIRS:1)
B(-6,5,-1,HAY_BLOCK:0)
B(-5,5,-1,HAY_BLOCK:8)
B(-1,5,-1,LOG:9)
B(7,5,-1,LOG:9)
B(7,5,0,SPRUCE_STAIRS:3)
B(7,5,1,LADDER:2)
B(-1,5,2,TRAPDOOR:10)
B(0,5,2,LOG2:1)
B(1,5,2,LOG2:1)
B(2,5,2,SPRUCE_STAIRS:1)
B(6,5,2,LADDER:4)
B(8,5,2,LADDER:5)
B(0,5,3,LEVER:3)
B(7,5,3,LADDER:3)
B(-7,5,4,FENCE:0)
B(1,5,4,FENCE:0)
B(9,5,4,FENCE:0)
B(-7,6,-4,TORCH:5)
B(1,6,-4,TORCH:5)
B(9,6,-4,TORCH:5)
B(-5,6,-3,HAY_BLOCK:0)
B(-4,6,-3,HAY_BLOCK:0)
B(-1,6,-3,TRIPWIRE_HOOK:2)
B(7,6,-3,TRIPWIRE_HOOK:2)
B(-6,6,-2,HAY_BLOCK:4)
B(-5,6,-2,HAY_BLOCK:0)
B(-2,6,-2,SPRUCE_STAIRS:3)
B(-1,6,-2,LOG:1)
B(0,6,-2,SPRUCE_STAIRS:1)
B(6,6,-2,SPRUCE_STAIRS:3)
B(7,6,-2,LOG:1)
B(8,6,-2,SPRUCE_STAIRS:1)
B(-1,6,-1,SPRUCE_STAIRS:3)
B(7,6,-1,SPRUCE_STAIRS:3)
B(0,6,1,TRIPWIRE_HOOK:2)
B(7,6,1,LADDER:2)
B(0,6,2,LOG2:1)
B(1,6,2,SPRUCE_STAIRS:1)
B(6,6,2,LADDER:4)
B(8,6,2,LADDER:5)
B(7,6,3,LADDER:3)
B(-7,6,4,TORCH:5)
B(1,6,4,TORCH:5)
B(9,6,4,TORCH:5)
B(-5,7,-2,HAY_BLOCK:0)
B(-1,7,-2,LOG:1)
B(7,7,-2,LOG:1)
B(7,7,-1,LEVER:3)
B(7,7,2,ANVIL:3)
B(-1,8,-3,TRIPWIRE_HOOK:2)
B(7,8,-3,TRIPWIRE_HOOK:2)
B(-2,8,-2,TRIPWIRE_HOOK:1)
B(-1,8,-2,LOG:1)
B(0,8,-2,TRIPWIRE_HOOK:3)
B(6,8,-2,TRIPWIRE_HOOK:1)
B(7,8,-2,LOG:1)
B(8,8,-2,TRIPWIRE_HOOK:3)
B(-1,8,-1,SPRUCE_STAIRS:7)
B(7,8,-1,SPRUCE_STAIRS:7)
B(-1,8,2,FENCE:0)
B(7,8,2,NETHER_BRICK_FENCE:0)
B(-1,9,-3,SPRUCE_STAIRS:6)
B(7,9,-3,SPRUCE_STAIRS:5)
B(-1,9,-2,LOG:1)
B(7,9,-2,LOG:1)
B(-1,9,-1,SPRUCE_STAIRS:2)
B(7,9,-1,SPRUCE_STAIRS:2)
B(-1,9,0,SPRUCE_STAIRS:7)
B(7,9,0,SPRUCE_STAIRS:7)
B(-1,9,2,FENCE:0)
B(7,9,2,NETHER_BRICK_FENCE:0)
B(-1,10,-4,TRIPWIRE_HOOK:2)
B(7,10,-4,TRIPWIRE_HOOK:2)
B(-1,10,-3,LOG:9)
B(7,10,-3,LOG:9)
B(-2,10,-2,TRIPWIRE_HOOK:1)
B(-1,10,-2,LOG:1)
B(0,10,-2,TRIPWIRE_HOOK:3)
B(6,10,-2,TRIPWIRE_HOOK:1)
B(7,10,-2,LOG:1)
B(8,10,-2,TRIPWIRE_HOOK:3)
B(-1,10,-1,LOG:9)
B(7,10,-1,LOG:9)
B(-1,10,0,LOG:9)
B(7,10,0,LOG:9)
B(-1,10,1,LOG:9)
B(7,10,1,LOG:9)
B(-1,10,2,LOG:9)
B(7,10,2,LOG:9)
B(-1,10,3,TRIPWIRE_HOOK:0)
B(7,10,3,TRIPWIRE_HOOK:0)

