
#######################################################################
# +-----------------------------------------------------------------+ #
# |                            BO3 object                           | #
# +-----------------------------------------------------------------+ #
#######################################################################

Author: BO3 BulkEdit (by LanToaster)

Description: This Object was Created with BO3_BulkEdit

Version: 3

SettingsMode: WriteDisable


#######################################################################
# +-----------------------------------------------------------------+ #
# |                          Main settings                          | #
# +-----------------------------------------------------------------+ #
#######################################################################

Tree: false

Frequency: 1

Rarity: 100.0

RotateRandomly: false

SpawnHeight: randomY

SpawnHeightOffset: 0

SpawnHeightVariance: 0

##############################
# Height Limits for the BO3. #
##############################

MinHeight: 82

MaxHeight: 82

######################
# Extrusion settings #
######################

ExtrudeMode: None

ExtrudeThroughBlocks: AIR

MaxBranchDepth: 10

ExcludedBiomes: All


#######################################################################
# +-----------------------------------------------------------------+ #
# |                      Source block settings                      | #
# +-----------------------------------------------------------------+ #
#######################################################################

SourceBlocks: AIR

MaxPercentageOutsideSourceBlock: 100

OutsideSourceBlock: placeAnyway

IsOTGPlus: false

InheritBO3: 

InheritBO3Rotation: NORTH

OverrideChildSettings: true

OverrideParentHeight: false

CanOverride: false

BranchFrequency: 0

BranchFrequencyGroup: 

MustBeBelowOther: false

MustBeInside: 

CannotBeInside: 

ReplacesBO3: 

CanSpawnOnWater: true

SpawnOnWaterOnly: false

SpawnUnderWater: false

SpawnAtWaterLevel: false

HeightOffset: 0

RemoveAir: true

ReplaceAbove: 

ReplaceBelow: 

ReplaceWithBiomeBlocks: true

ReplaceWithGroundBlock: DIRT

ReplaceWithSurfaceBlock: GRASS

SmoothRadius: 0

SmoothHeightOffset: 0

SmoothStartTop: false

SmoothStartWood: false

SmoothingSurfaceBlock: 

SmoothingGroundBlock: 

BO3Group: 

IsSpawnPoint: false


#######################################################################
# +-----------------------------------------------------------------+ #
# |                              Blocks                             | #
# +-----------------------------------------------------------------+ #
#######################################################################

Block(-2,-10,-7,WOOD:3)
Block(-1,-10,-7,WOOD:3)
Block(-4,-10,-6,LOG:3)
Block(-3,-10,-6,WOOD:3)
Block(-2,-10,-6,WOOD:3)
Block(-6,-10,-5,WOOD:3)
Block(-5,-10,-5,WOOD:3)
Block(-7,-10,-4,WOOD:3)
Block(-2,-9,-7,WOOD:3)
Block(-1,-9,-7,WOOD:3)
Block(-4,-9,-6,LOG:3)
Block(-3,-9,-6,WOOD:3)
Block(-2,-9,-6,WOOD:3)
Block(-6,-9,-5,WOOD:3)
Block(-5,-9,-5,WOOD:3)
Block(-7,-9,-4,WOOD:3)
Block(-2,-8,-7,WOOD:3)
Block(-1,-8,-7,WOOD:3)
Block(-4,-8,-6,LOG:3)
Block(-3,-8,-6,WOOD:3)
Block(-2,-8,-6,WOOD:3)
Block(-6,-8,-5,WOOD:3)
Block(-5,-8,-5,WOOD:3)
Block(-7,-8,-4,WOOD:3)
Block(-2,-7,-7,WOOD:3)
Block(-1,-7,-7,WOOD:3)
Block(-4,-7,-6,LOG:3)
Block(-3,-7,-6,WOOD:3)
Block(-2,-7,-6,WOOD:3)
Block(-6,-7,-5,WOOD:3)
Block(-5,-7,-5,WOOD:3)
Block(-7,-7,-4,WOOD:3)
Block(-2,-6,-7,WOOD:3)
Block(-1,-6,-7,WOOD:3)
Block(-4,-6,-6,LOG:3)
Block(-3,-6,-6,WOOD:3)
Block(-2,-6,-6,WOOD:3)
Block(-6,-6,-5,WOOD:3)
Block(-5,-6,-5,WOOD:3)
Block(-7,-6,-4,WOOD:3)
Block(-2,-5,-7,WOOD:3)
Block(-1,-5,-7,WOOD:3)
Block(-4,-5,-6,LOG:3)
Block(-3,-5,-6,WOOD:3)
Block(-2,-5,-6,WOOD:3)
Block(-6,-5,-5,WOOD:3)
Block(-5,-5,-5,WOOD:3)
Block(-7,-5,-4,WOOD:3)
Block(-2,-4,-7,WOOD:3)
Block(-1,-4,-7,WOOD:3)
Block(-4,-4,-6,LOG:3)
Block(-3,-4,-6,WOOD:3)
Block(-2,-4,-6,WOOD:3)
Block(-6,-4,-5,WOOD:3)
Block(-5,-4,-5,WOOD:3)
Block(-7,-4,-4,WOOD:3)
Block(-2,-3,-7,WOOD:3)
Block(-1,-3,-7,WOOD:3)
Block(-4,-3,-6,LOG:3)
Block(-3,-3,-6,WOOD:3)
Block(-2,-3,-6,WOOD:3)
Block(-6,-3,-5,WOOD:3)
Block(-5,-3,-5,WOOD:3)
Block(-7,-3,-4,WOOD:3)
Block(-2,-2,-7,WOOD:3)
Block(-1,-2,-7,WOOD:3)
Block(-4,-2,-6,LOG:3)
Block(-3,-2,-6,WOOD:3)
Block(-2,-2,-6,WOOD:3)
Block(-6,-2,-5,WOOD:3)
Block(-5,-2,-5,WOOD:3)
Block(-7,-2,-4,WOOD:3)
Block(-2,-1,-7,WOOD:3)
Block(-1,-1,-7,WOOD:3)
Block(-4,-1,-6,LOG:3)
Block(-3,-1,-6,WOOD:3)
Block(-2,-1,-6,WOOD:3)
Block(-6,-1,-5,WOOD:3)
Block(-5,-1,-5,WOOD:3)
Block(-7,-1,-4,WOOD:3)
Block(8,-1,0,GRASS_PATH)
Block(7,-1,1,GRASS_PATH)
Block(8,-1,1,GRASS_PATH)
Block(7,-1,2,GRASS_PATH)
Block(8,-1,2,GRASS_PATH)
Block(8,-1,3,GRASS_PATH)
Block(8,-1,6,WOOD:3)
Block(8,-1,7,GRASS_PATH)
Block(-3,0,-7,SPRUCE_FENCE)
Block(-2,0,-7,WOOD:3)
Block(-1,0,-7,WOOD:3)
Block(-6,0,-6,SPRUCE_FENCE)
Block(-5,0,-6,SPRUCE_FENCE)
Block(-4,0,-6,LOG:3)
Block(-3,0,-6,WOOD:3)
Block(-2,0,-6,WOOD:3)
Block(-6,0,-5,WOOD:3)
Block(-5,0,-5,WOOD:3)
Block(-7,0,-4,WOOD:3)
Block(-3,1,-7,SPRUCE_FENCE)
Block(-2,1,-7,WOOD:3)
Block(-1,1,-7,WOOD:3)
Block(-4,1,-6,LOG:3)
Block(-3,1,-6,WOOD:3)
Block(-2,1,-6,WOOD:3)
Block(-6,1,-5,WOOD:3)
Block(-5,1,-5,WOOD:3)
Block(-7,1,-4,WOOD:3)
Block(-2,2,-7,WOOD:3)
Block(-1,2,-7,WOOD:3)
Block(-4,2,-6,LOG:3)
Block(-3,2,-6,WOOD:3)
Block(-2,2,-6,WOOD:3)
Block(-6,2,-5,WOOD:3)
Block(-5,2,-5,WOOD:3)
Block(-7,2,-4,WOOD:3)
Block(-2,3,-7,WOOD:3)
Block(-1,3,-7,WOOD:3)
Block(-4,3,-6,LOG:3)
Block(-3,3,-6,WOOD:3)
Block(-2,3,-6,WOOD:3)
Block(-6,3,-5,WOOD:3)
Block(-5,3,-5,WOOD:3)
Block(-7,3,-4,WOOD:3)
RandomBlock(-4,4,-6,STANDING_BANNER:6,../JungleNBT/banners/JungleBanner01.nbt,8,STANDING_BANNER:6,../JungleNBT/banners/JungleBanner02.nbt,8,STANDING_BANNER:6,../JungleNBT/banners/JungleBanner03.nbt,8,STANDING_BANNER:6,../JungleNBT/banners/JungleBanner04.nbt,8,STANDING_BANNER:6,../JungleNBT/banners/JungleBanner05.nbt,8,STANDING_BANNER:6,../JungleNBT/banners/JungleBanner06.nbt,8,STANDING_BANNER:6,../JungleNBT/banners/JungleBanner07.nbt,8,STANDING_BANNER:6,../JungleNBT/banners/JungleBanner08.nbt,8,STANDING_BANNER:6,../JungleNBT/banners/JungleBanner09.nbt,8,STANDING_BANNER:6,../JungleNBT/banners/JungleBanner10.nbt,8,STANDING_BANNER:6,../JungleNBT/banners/JungleBanner11.nbt,8,STANDING_BANNER:6,../JungleNBT/banners/JungleBanner12.nbt,8,STANDING_BANNER:6,../JungleNBT/banners/JungleBanner13.nbt,8,STANDING_BANNER:6,../JungleNBT/banners/JungleBanner14.nbt,8,STANDING_BANNER:6,../JungleNBT/banners/JungleBanner15.nbt,8,STANDING_BANNER:6,../JungleNBT/banners/JungleBanner16.nbt,8,STANDING_BANNER:6,../JungleNBT/banners/JungleBanner17.nbt,8,STANDING_BANNER:6,../JungleNBT/banners/JungleBanner18.nbt,8,STANDING_BANNER:6,../JungleNBT/banners/JungleBanner19.nbt,8,STANDING_BANNER:6,../JungleNBT/banners/JungleBanner20.nbt,100)
Block(-6,4,-5,WOOD:3)
Block(-5,4,-5,WOOD:3)
Block(-7,4,-4,WOOD:3)

#######################################################################
# +-----------------------------------------------------------------+ #
# |                            BO3 checks                           | #
# +-----------------------------------------------------------------+ #
#######################################################################


#######################################################################
# +-----------------------------------------------------------------+ #
# |                             Branches                            | #
# +-----------------------------------------------------------------+ #
#######################################################################

WeightedBranch(-1,0,7, House01,NORTH,10.0,House02,NORTH,10.0,House03,NORTH,10.0,House04,NORTH,10.0,House05,NORTH,10.0,House06,NORTH,10.0,House07,NORTH,10.0,House08,NORTH,10.0,House09,NORTH,10.0,House10,NORTH,10.0,House01,EAST,10.0,House02,EAST,10.0,House03,EAST,10.0,House04,EAST,10.0,House05,EAST,10.0,House06,EAST,10.0,House07,EAST,10.0,House08,EAST,10.0,House09,EAST,10.0,House10,EAST,10.0,House01,WEST,10.0,House02,WEST,10.0,House03,WEST,10.0,House04,WEST,10.0,House05,WEST,10.0,House06,WEST,10.0,House07,WEST,10.0,House08,WEST,10.0,House09,WEST,10.0,House10,WEST,10.0,House01,SOUTH,10.0,House02,SOUTH,10.0,House03,SOUTH,10.0,House04,SOUTH,10.0,House05,SOUTH,10.0,House06,SOUTH,10.0,House07,SOUTH,10.0,House08,SOUTH,10.0,House09,SOUTH,10.0,House10,SOUTH,10.0,400.0)
Branch(0,0,-16, JungleVillagePath05_03-02,NORTH,100.0)

#######################################################################
# +-----------------------------------------------------------------+ #
# |                             Entities                            | #
# +-----------------------------------------------------------------+ #
#######################################################################


#######################################################################
# +-----------------------------------------------------------------+ #
# |                            Particles                            | #
# +-----------------------------------------------------------------+ #
#######################################################################


#######################################################################
# +-----------------------------------------------------------------+ #
# |                             Spawners                            | #
# +-----------------------------------------------------------------+ #
#######################################################################


#######################################################################
# +-----------------------------------------------------------------+ #
# |                             ModData                             | #
# +-----------------------------------------------------------------+ #
#######################################################################

