#######################################################################
# +-----------------------------------------------------------------+ #
# |                            BO3 object                           | #
# +-----------------------------------------------------------------+ #
#######################################################################

Author: Bo3 BulkEdit

Description: Converted Schematic - Modified by Bo3BulkEdit

Version: 3

SettingsMode: WriteDisable

#######################################################################
# +-----------------------------------------------------------------+ #
# |                          Main settings                          | #
# +-----------------------------------------------------------------+ #
#######################################################################



Frequency: 0


SpawnHeight: randomY





##############################
# Height Limits for the BO3. #
##############################

MinHeight: 0
MaxHeight: 256

#######################################################################
# +-----------------------------------------------------------------+ #
# |                      Source block settings                      | #
# +-----------------------------------------------------------------+ #
#######################################################################

CanOverride: true
MaxPercentageOutsideSourceBlock: 100
OutsideSourceBlock: placeAnyway

#######################################################################
# +-----------------------------------------------------------------+ #
# |                               OTG+                              | #
# +-----------------------------------------------------------------+ #
#######################################################################

#######################################################################
# +-----------------------------------------------------------------+ #
# |                              Blocks                             | #
# +-----------------------------------------------------------------+ #
#######################################################################

B(0,750,0,AIR)
B(15,750,15,AIR)
B(6,7,15,STAINED_GLASS:11)
B(8,7,15,STAINED_GLASS:11)
B(4,8,15,STAINED_GLASS:15)
B(6,8,15,STAINED_GLASS:15)
B(7,8,15,STAINED_GLASS:11)
B(8,8,15,STAINED_GLASS:11)
B(6,9,14,STAINED_GLASS:15)
B(4,9,15,STAINED_GLASS:15)
B(5,9,15,STAINED_GLASS:15)
B(6,9,15,STAINED_GLASS:15)
B(7,9,15,STAINED_GLASS:15)
B(8,9,15,STAINED_GLASS:15)
B(5,10,14,STAINED_GLASS:15)
B(6,10,14,STAINED_GLASS:15)
B(7,10,14,STAINED_GLASS:15)
B(3,10,15,STAINED_GLASS:15)
B(4,10,15,STAINED_GLASS:6)
B(5,10,15,STAINED_GLASS:15)
B(6,10,15,SEA_LANTERN)
B(7,10,15,STAINED_GLASS:11)
B(8,10,15,STAINED_GLASS:11)
B(4,11,14,STAINED_GLASS:15)
B(5,11,14,STAINED_GLASS:15)
B(6,11,14,STAINED_GLASS:6)
B(7,11,14,STAINED_GLASS:11)
B(3,11,15,STAINED_GLASS:15)
B(4,11,15,STAINED_GLASS:6)
B(5,11,15,SEA_LANTERN)
B(6,11,15,SEA_LANTERN)
B(7,11,15,STAINED_GLASS:11)
B(8,11,15,STAINED_GLASS:11)
B(7,12,12,STAINED_GLASS:15)
B(4,12,13,STAINED_GLASS:15)
B(6,12,13,STAINED_GLASS:15)
B(4,12,14,STAINED_GLASS:15)
B(5,12,14,STAINED_GLASS:15)
B(6,12,14,STAINED_GLASS:6)
B(7,12,14,STAINED_GLASS:15)
B(3,12,15,STAINED_GLASS:15)
B(4,12,15,SEA_LANTERN)
B(5,12,15,SEA_LANTERN)
B(6,12,15,SEA_LANTERN)
B(7,12,15,STAINED_GLASS:11)
B(8,12,15,STAINED_GLASS:11)
B(7,13,12,STAINED_GLASS:15)
B(4,13,13,STAINED_GLASS:15)
B(5,13,13,STAINED_GLASS:15)
B(6,13,13,STAINED_GLASS:15)
B(7,13,13,STAINED_GLASS:15)
B(3,13,14,STAINED_GLASS:15)
B(4,13,14,STAINED_GLASS:6)
B(5,13,14,SEA_LANTERN)
B(6,13,14,STAINED_GLASS:6)
B(7,13,14,STAINED_GLASS:15)
B(3,13,15,STAINED_GLASS:15)
B(4,13,15,SEA_LANTERN)
B(5,13,15,SEA_LANTERN)
B(6,13,15,SEA_LANTERN)
B(7,13,15,STAINED_GLASS:11)
B(8,13,15,STAINED_GLASS:11)
B(5,14,12,STAINED_GLASS:11)
B(6,14,12,STAINED_GLASS:11)
B(7,14,12,STAINED_GLASS:11)
B(3,14,13,STAINED_GLASS:11)
B(4,14,13,SEA_LANTERN)
B(5,14,13,STAINED_GLASS:11)
B(6,14,13,STAINED_GLASS:6)
B(7,14,13,STAINED_GLASS:11)
B(3,14,14,STAINED_GLASS:15)
B(4,14,14,STAINED_GLASS:6)
B(5,14,14,SEA_LANTERN)
B(6,14,14,SEA_LANTERN)
B(7,14,14,STAINED_GLASS:11)
B(3,14,15,STAINED_GLASS:15)
B(4,14,15,SEA_LANTERN)
B(5,14,15,SEA_LANTERN)
B(6,14,15,SEA_LANTERN)
B(7,14,15,STAINED_GLASS:11)
B(8,14,15,STAINED_GLASS:11)
B(7,15,11,STAINED_GLASS:11)
B(3,15,12,STAINED_GLASS:11)
B(4,15,12,STAINED_GLASS:11)
B(5,15,12,STAINED_GLASS:11)
B(6,15,12,STAINED_GLASS:11)
B(7,15,12,STAINED_GLASS:11)
B(3,15,13,STAINED_GLASS:11)
B(4,15,13,SEA_LANTERN)
B(5,15,13,STAINED_GLASS:11)
B(6,15,13,STAINED_GLASS:6)
B(7,15,13,STAINED_GLASS:11)
B(3,15,14,STAINED_GLASS:15)
B(4,15,14,SEA_LANTERN)
B(5,15,14,SEA_LANTERN)
B(6,15,14,SEA_LANTERN)
B(7,15,14,STAINED_GLASS:11)
B(3,15,15,STAINED_GLASS:15)
B(4,15,15,STAINED_GLASS:6)
B(5,15,15,SEA_LANTERN)
B(6,15,15,SEA_LANTERN)
B(7,15,15,STAINED_GLASS:11)
B(8,15,15,STAINED_GLASS:11)
B(7,16,11,STAINED_GLASS:15)
B(3,16,12,STAINED_GLASS:11)
B(4,16,12,STAINED_GLASS:15)
B(5,16,12,SEA_LANTERN)
B(6,16,12,STAINED_GLASS:6)
B(7,16,12,STAINED_GLASS:11)
B(3,16,13,STAINED_GLASS:6)
B(4,16,13,SEA_LANTERN)
B(5,16,13,SEA_LANTERN)
B(6,16,13,STAINED_GLASS:6)
B(7,16,13,STAINED_GLASS:11)
B(3,16,14,STAINED_GLASS:15)
B(4,16,14,SEA_LANTERN)
B(5,16,14,SEA_LANTERN)
B(6,16,14,STAINED_GLASS:6)
B(7,16,14,STAINED_GLASS:11)
B(3,16,15,STAINED_GLASS:15)
B(4,16,15,STAINED_GLASS:6)
B(5,16,15,SEA_LANTERN)
B(6,16,15,SEA_LANTERN)
B(7,16,15,STAINED_GLASS:15)
B(3,17,11,STAINED_GLASS:11)
B(4,17,11,STAINED_GLASS:15)
B(5,17,11,STAINED_GLASS:15)
B(6,17,11,STAINED_GLASS:15)
B(7,17,11,STAINED_GLASS:15)
B(3,17,12,STAINED_GLASS:15)
B(4,17,12,STAINED_GLASS:15)
B(5,17,12,SEA_LANTERN)
B(6,17,12,STAINED_GLASS:6)
B(7,17,12,STAINED_GLASS:11)
B(3,17,13,STAINED_GLASS:15)
B(4,17,13,SEA_LANTERN)
B(5,17,13,SEA_LANTERN)
B(6,17,13,SEA_LANTERN)
B(7,17,13,STAINED_GLASS:11)
B(3,17,14,STAINED_GLASS:15)
B(4,17,14,STAINED_GLASS:15)
B(5,17,14,SEA_LANTERN)
B(6,17,14,SEA_LANTERN)
B(7,17,14,STAINED_GLASS:11)
B(3,17,15,STAINED_GLASS:15)
B(4,17,15,STAINED_GLASS:15)
B(5,17,15,STAINED_GLASS:6)
B(6,17,15,STAINED_GLASS:15)
B(7,17,15,STAINED_GLASS:11)
B(5,18,10,STAINED_GLASS:15)
B(6,18,10,STAINED_GLASS:15)
B(2,18,11,STAINED_GLASS:11)
B(3,18,11,STAINED_GLASS:11)
B(4,18,11,STAINED_GLASS:15)
B(5,18,11,STAINED_GLASS:15)
B(6,18,11,STAINED_GLASS:15)
B(7,18,11,STAINED_GLASS:11)
B(3,18,12,STAINED_GLASS:11)
B(4,18,12,STAINED_GLASS:6)
B(5,18,12,SEA_LANTERN)
B(6,18,12,SEA_LANTERN)
B(7,18,12,STAINED_GLASS:11)
B(3,18,13,STAINED_GLASS:15)
B(4,18,13,SEA_LANTERN)
B(5,18,13,SEA_LANTERN)
B(6,18,13,SEA_LANTERN)
B(7,18,13,STAINED_GLASS:11)
B(3,18,14,STAINED_GLASS:15)
B(4,18,14,STAINED_GLASS:15)
B(5,18,14,SEA_LANTERN)
B(6,18,14,SEA_LANTERN)
B(7,18,14,STAINED_GLASS:11)
B(3,18,15,STAINED_GLASS:15)
B(4,18,15,STAINED_GLASS:15)
B(5,18,15,STAINED_GLASS:6)
B(6,18,15,STAINED_GLASS:15)
B(7,18,15,STAINED_GLASS:11)
B(5,19,10,STAINED_GLASS:15)
B(6,19,10,STAINED_GLASS:15)
B(2,19,11,STAINED_GLASS:11)
B(3,19,11,STAINED_GLASS:11)
B(4,19,11,SEA_LANTERN)
B(5,19,11,SEA_LANTERN)
B(6,19,11,STAINED_GLASS:6)
B(7,19,11,STAINED_GLASS:15)
B(3,19,12,STAINED_GLASS:15)
B(4,19,12,STAINED_GLASS:6)
B(5,19,12,SEA_LANTERN)
B(6,19,12,SEA_LANTERN)
B(7,19,12,STAINED_GLASS:11)
B(3,19,13,STAINED_GLASS:15)
B(4,19,13,STAINED_GLASS:6)
B(5,19,13,SEA_LANTERN)
B(6,19,13,SEA_LANTERN)
B(7,19,13,STAINED_GLASS:11)
B(3,19,14,STAINED_GLASS:15)
B(4,19,14,STAINED_GLASS:15)
B(5,19,14,SEA_LANTERN)
B(6,19,14,STAINED_GLASS:15)
B(7,19,14,STAINED_GLASS:15)
B(3,19,15,STAINED_GLASS:15)
B(5,19,15,STAINED_GLASS:15)
B(4,20,9,STAINED_GLASS:15)
B(6,20,9,STAINED_GLASS:15)
B(3,20,10,STAINED_GLASS:15)
B(4,20,10,STAINED_GLASS:15)
B(5,20,10,STAINED_GLASS:15)
B(6,20,10,STAINED_GLASS:15)
B(2,20,11,STAINED_GLASS:15)
B(3,20,11,STAINED_GLASS:15)
B(4,20,11,SEA_LANTERN)
B(5,20,11,SEA_LANTERN)
B(6,20,11,STAINED_GLASS:6)
B(7,20,11,STAINED_GLASS:11)
B(3,20,12,STAINED_GLASS:15)
B(4,20,12,SEA_LANTERN)
B(5,20,12,SEA_LANTERN)
B(6,20,12,SEA_LANTERN)
B(7,20,12,STAINED_GLASS:15)
B(3,20,13,STAINED_GLASS:15)
B(4,20,13,STAINED_GLASS:6)
B(5,20,13,SEA_LANTERN)
B(6,20,13,SEA_LANTERN)
B(7,20,13,STAINED_GLASS:15)
B(3,20,14,STAINED_GLASS:15)
B(4,20,14,STAINED_GLASS:15)
B(5,20,14,STAINED_GLASS:15)
B(6,20,14,STAINED_GLASS:15)
B(5,20,15,STAINED_GLASS:15)
B(6,21,8,STAINED_GLASS:15)
B(2,21,9,STAINED_GLASS:11)
B(3,21,9,STAINED_GLASS:15)
B(4,21,9,STAINED_GLASS:15)
B(5,21,9,STAINED_GLASS:15)
B(6,21,9,STAINED_GLASS:15)
B(2,21,10,STAINED_GLASS:11)
B(3,21,10,STAINED_GLASS:11)
B(4,21,10,STAINED_GLASS:15)
B(5,21,10,SEA_LANTERN)
B(6,21,10,STAINED_GLASS:11)
B(2,21,11,STAINED_GLASS:15)
B(3,21,11,STAINED_GLASS:15)
B(4,21,11,SEA_LANTERN)
B(5,21,11,SEA_LANTERN)
B(6,21,11,SEA_LANTERN)
B(7,21,11,STAINED_GLASS:11)
B(3,21,12,STAINED_GLASS:15)
B(4,21,12,SEA_LANTERN)
B(5,21,12,SEA_LANTERN)
B(6,21,12,STAINED_GLASS:6)
B(7,21,12,STAINED_GLASS:11)
B(3,21,13,STAINED_GLASS:15)
B(4,21,13,STAINED_GLASS:6)
B(5,21,13,SEA_LANTERN)
B(6,21,13,SEA_LANTERN)
B(7,21,13,STAINED_GLASS:11)
B(3,21,14,STAINED_GLASS:15)
B(4,21,14,STAINED_GLASS:15)
B(5,21,14,STAINED_GLASS:15)
B(6,22,8,STAINED_GLASS:15)
B(2,22,9,STAINED_GLASS:11)
B(3,22,9,STAINED_GLASS:11)
B(4,22,9,SEA_LANTERN)
B(5,22,9,STAINED_GLASS:15)
B(6,22,9,STAINED_GLASS:6)
B(2,22,10,STAINED_GLASS:11)
B(3,22,10,STAINED_GLASS:11)
B(4,22,10,SEA_LANTERN)
B(5,22,10,SEA_LANTERN)
B(6,22,10,STAINED_GLASS:15)
B(2,22,11,STAINED_GLASS:11)
B(3,22,11,STAINED_GLASS:15)
B(4,22,11,SEA_LANTERN)
B(5,22,11,SEA_LANTERN)
B(6,22,11,SEA_LANTERN)
B(7,22,11,STAINED_GLASS:11)
B(3,22,12,STAINED_GLASS:15)
B(4,22,12,STAINED_GLASS:6)
B(5,22,12,SEA_LANTERN)
B(6,22,12,STAINED_GLASS:6)
B(7,22,12,STAINED_GLASS:15)
B(3,22,13,STAINED_GLASS:15)
B(4,22,13,STAINED_GLASS:15)
B(5,22,13,SEA_LANTERN)
B(6,22,13,STAINED_GLASS:15)
B(7,22,13,STAINED_GLASS:15)
B(3,22,14,STAINED_GLASS:15)
B(4,23,8,STAINED_GLASS:15)
B(5,23,8,STAINED_GLASS:15)
B(6,23,8,STAINED_GLASS:15)
B(2,23,9,STAINED_GLASS:11)
B(3,23,9,STAINED_GLASS:15)
B(4,23,9,SEA_LANTERN)
B(5,23,9,STAINED_GLASS:15)
B(6,23,9,STAINED_GLASS:6)
B(2,23,10,STAINED_GLASS:11)
B(3,23,10,STAINED_GLASS:11)
B(4,23,10,SEA_LANTERN)
B(5,23,10,SEA_LANTERN)
B(6,23,10,STAINED_GLASS:15)
B(2,23,11,STAINED_GLASS:15)
B(3,23,11,STAINED_GLASS:15)
B(4,23,11,SEA_LANTERN)
B(5,23,11,SEA_LANTERN)
B(6,23,11,SEA_LANTERN)
B(7,23,11,STAINED_GLASS:15)
B(3,23,12,STAINED_GLASS:15)
B(4,23,12,STAINED_GLASS:6)
B(5,23,12,STAINED_GLASS:15)
B(6,23,12,STAINED_GLASS:15)
B(3,23,13,STAINED_GLASS:15)
B(4,23,13,STAINED_GLASS:15)
B(5,23,13,STAINED_GLASS:15)
B(6,23,13,STAINED_GLASS:15)
B(4,24,7,STAINED_GLASS:15)
B(6,24,7,STAINED_GLASS:15)
B(2,24,8,STAINED_GLASS:15)
B(3,24,8,STAINED_GLASS:15)
B(4,24,8,STAINED_GLASS:15)
B(5,24,8,STAINED_GLASS:15)
B(6,24,8,STAINED_GLASS:15)
B(2,24,9,STAINED_GLASS:11)
B(3,24,9,STAINED_GLASS:6)
B(4,24,9,SEA_LANTERN)
B(5,24,9,SEA_LANTERN)
B(6,24,9,SEA_LANTERN)
B(2,24,10,STAINED_GLASS:11)
B(3,24,10,STAINED_GLASS:11)
B(4,24,10,SEA_LANTERN)
B(5,24,10,SEA_LANTERN)
B(6,24,10,STAINED_GLASS:11)
B(2,24,11,STAINED_GLASS:15)
B(3,24,11,STAINED_GLASS:15)
B(4,24,11,SEA_LANTERN)
B(5,24,11,SEA_LANTERN)
B(6,24,11,STAINED_GLASS:6)
B(7,24,11,STAINED_GLASS:15)
B(3,24,12,STAINED_GLASS:15)
B(4,24,12,STAINED_GLASS:6)
B(5,24,12,STAINED_GLASS:15)
B(6,24,12,STAINED_GLASS:15)
B(3,24,13,STAINED_GLASS:15)
B(5,24,13,STAINED_GLASS:15)
B(4,25,7,STAINED_GLASS:15)
B(6,25,7,STAINED_GLASS:15)
B(2,25,8,STAINED_GLASS:11)
B(3,25,8,STAINED_GLASS:15)
B(4,25,8,SEA_LANTERN)
B(5,25,8,STAINED_GLASS:6)
B(6,25,8,STAINED_GLASS:11)
B(2,25,9,STAINED_GLASS:11)
B(3,25,9,STAINED_GLASS:6)
B(4,25,9,SEA_LANTERN)
B(5,25,9,SEA_LANTERN)
B(6,25,9,SEA_LANTERN)
B(2,25,10,STAINED_GLASS:11)
B(3,25,10,STAINED_GLASS:11)
B(4,25,10,SEA_LANTERN)
B(5,25,10,SEA_LANTERN)
B(6,25,10,STAINED_GLASS:11)
B(2,25,11,STAINED_GLASS:11)
B(3,25,11,STAINED_GLASS:15)
B(4,25,11,SEA_LANTERN)
B(5,25,11,SEA_LANTERN)
B(6,25,11,STAINED_GLASS:6)
B(7,25,11,STAINED_GLASS:11)
B(3,25,12,STAINED_GLASS:15)
B(4,25,12,STAINED_GLASS:15)
B(2,26,7,STAINED_GLASS:15)
B(3,26,7,STAINED_GLASS:15)
B(4,26,7,STAINED_GLASS:15)
B(5,26,7,STAINED_GLASS:15)
B(6,26,7,STAINED_GLASS:15)
B(2,26,8,STAINED_GLASS:15)
B(3,26,8,STAINED_GLASS:15)
B(4,26,8,SEA_LANTERN)
B(5,26,8,STAINED_GLASS:6)
B(6,26,8,STAINED_GLASS:15)
B(2,26,9,STAINED_GLASS:11)
B(3,26,9,SEA_LANTERN)
B(4,26,9,SEA_LANTERN)
B(5,26,9,SEA_LANTERN)
B(6,26,9,SEA_LANTERN)
B(2,26,10,STAINED_GLASS:11)
B(3,26,10,STAINED_GLASS:11)
B(4,26,10,SEA_LANTERN)
B(5,26,10,SEA_LANTERN)
B(6,26,10,STAINED_GLASS:11)
B(2,26,11,STAINED_GLASS:15)
B(3,26,11,STAINED_GLASS:15)
B(4,26,11,STAINED_GLASS:15)
B(5,26,11,STAINED_GLASS:15)
B(6,26,11,STAINED_GLASS:11)
B(4,26,12,STAINED_GLASS:15)
B(4,27,6,STAINED_GLASS:15)
B(5,27,6,STAINED_GLASS:15)
B(1,27,7,STAINED_GLASS:15)
B(2,27,7,STAINED_GLASS:15)
B(3,27,7,STAINED_GLASS:15)
B(4,27,7,SEA_LANTERN)
B(5,27,7,STAINED_GLASS:15)
B(6,27,7,STAINED_GLASS:15)
B(2,27,8,STAINED_GLASS:15)
B(3,27,8,STAINED_GLASS:6)
B(4,27,8,SEA_LANTERN)
B(5,27,8,SEA_LANTERN)
B(6,27,8,STAINED_GLASS:15)
B(2,27,9,STAINED_GLASS:15)
B(3,27,9,SEA_LANTERN)
B(4,27,9,SEA_LANTERN)
B(5,27,9,SEA_LANTERN)
B(6,27,9,STAINED_GLASS:6)
B(2,27,10,STAINED_GLASS:15)
B(3,27,10,STAINED_GLASS:15)
B(4,27,10,SEA_LANTERN)
B(5,27,10,SEA_LANTERN)
B(6,27,10,STAINED_GLASS:15)
B(2,27,11,STAINED_GLASS:15)
B(3,27,11,STAINED_GLASS:15)
B(4,27,11,STAINED_GLASS:15)
B(5,27,11,STAINED_GLASS:15)
B(6,27,11,STAINED_GLASS:15)
B(4,28,6,STAINED_GLASS:15)
B(5,28,6,STAINED_GLASS:15)
B(1,28,7,STAINED_GLASS:15)
B(2,28,7,STAINED_GLASS:15)
B(3,28,7,SEA_LANTERN)
B(4,28,7,SEA_LANTERN)
B(5,28,7,STAINED_GLASS:6)
B(6,28,7,STAINED_GLASS:15)
B(2,28,8,STAINED_GLASS:11)
B(3,28,8,STAINED_GLASS:6)
B(4,28,8,SEA_LANTERN)
B(5,28,8,SEA_LANTERN)
B(6,28,8,STAINED_GLASS:15)
B(2,28,9,STAINED_GLASS:11)
B(3,28,9,STAINED_GLASS:6)
B(4,28,9,SEA_LANTERN)
B(5,28,9,SEA_LANTERN)
B(6,28,9,STAINED_GLASS:6)
B(2,28,10,STAINED_GLASS:11)
B(3,28,10,STAINED_GLASS:15)
B(4,28,10,SEA_LANTERN)
B(5,28,10,STAINED_GLASS:11)
B(6,28,10,STAINED_GLASS:15)
B(2,28,11,STAINED_GLASS:15)
B(3,29,5,STAINED_GLASS:15)
B(4,29,5,STAINED_GLASS:15)
B(5,29,5,STAINED_GLASS:15)
B(2,29,6,STAINED_GLASS:11)
B(3,29,6,STAINED_GLASS:15)
B(4,29,6,STAINED_GLASS:15)
B(5,29,6,STAINED_GLASS:15)
B(1,29,7,STAINED_GLASS:11)
B(2,29,7,STAINED_GLASS:11)
B(3,29,7,SEA_LANTERN)
B(4,29,7,SEA_LANTERN)
B(5,29,7,STAINED_GLASS:6)
B(6,29,7,STAINED_GLASS:15)
B(2,29,8,STAINED_GLASS:11)
B(3,29,8,SEA_LANTERN)
B(4,29,8,SEA_LANTERN)
B(5,29,8,SEA_LANTERN)
B(6,29,8,STAINED_GLASS:15)
B(2,29,9,STAINED_GLASS:11)
B(3,29,9,STAINED_GLASS:6)
B(4,29,9,STAINED_GLASS:11)
B(5,29,9,SEA_LANTERN)
B(6,29,9,STAINED_GLASS:11)
B(2,29,10,STAINED_GLASS:11)
B(3,29,10,STAINED_GLASS:11)
B(4,29,10,STAINED_GLASS:11)
B(5,29,10,STAINED_GLASS:11)
B(5,30,4,STAINED_GLASS:15)
B(1,30,5,STAINED_GLASS:11)
B(2,30,5,STAINED_GLASS:15)
B(3,30,5,STAINED_GLASS:15)
B(4,30,5,STAINED_GLASS:15)
B(5,30,5,STAINED_GLASS:15)
B(1,30,6,STAINED_GLASS:11)
B(2,30,6,STAINED_GLASS:11)
B(3,30,6,STAINED_GLASS:15)
B(4,30,6,SEA_LANTERN)
B(5,30,6,STAINED_GLASS:15)
B(1,30,7,STAINED_GLASS:11)
B(2,30,7,STAINED_GLASS:11)
B(3,30,7,SEA_LANTERN)
B(4,30,7,SEA_LANTERN)
B(5,30,7,SEA_LANTERN)
B(6,30,7,STAINED_GLASS:15)
B(2,30,8,STAINED_GLASS:11)
B(3,30,8,SEA_LANTERN)
B(4,30,8,SEA_LANTERN)
B(5,30,8,STAINED_GLASS:6)
B(6,30,8,STAINED_GLASS:15)
B(2,30,9,STAINED_GLASS:11)
B(3,30,9,STAINED_GLASS:6)
B(4,30,9,STAINED_GLASS:11)
B(5,30,9,SEA_LANTERN)
B(6,30,9,STAINED_GLASS:11)
B(2,30,10,STAINED_GLASS:11)
B(3,30,10,STAINED_GLASS:15)
B(4,30,10,STAINED_GLASS:11)
B(5,31,4,STAINED_GLASS:15)
B(1,31,5,STAINED_GLASS:15)
B(2,31,5,STAINED_GLASS:15)
B(3,31,5,SEA_LANTERN)
B(4,31,5,STAINED_GLASS:6)
B(5,31,5,STAINED_GLASS:6)
B(1,31,6,STAINED_GLASS:15)
B(2,31,6,STAINED_GLASS:11)
B(3,31,6,SEA_LANTERN)
B(4,31,6,SEA_LANTERN)
B(5,31,6,STAINED_GLASS:15)
B(1,31,7,STAINED_GLASS:11)
B(2,31,7,STAINED_GLASS:11)
B(3,31,7,SEA_LANTERN)
B(4,31,7,SEA_LANTERN)
B(5,31,7,SEA_LANTERN)
B(6,31,7,STAINED_GLASS:15)
B(2,31,8,STAINED_GLASS:15)
B(3,31,8,STAINED_GLASS:6)
B(4,31,8,SEA_LANTERN)
B(5,31,8,STAINED_GLASS:6)
B(6,31,8,STAINED_GLASS:15)
B(2,31,9,STAINED_GLASS:15)
B(3,31,9,STAINED_GLASS:15)
B(4,31,9,STAINED_GLASS:15)
B(5,31,9,STAINED_GLASS:15)
B(2,31,10,STAINED_GLASS:15)
B(4,31,10,STAINED_GLASS:15)
B(3,32,4,STAINED_GLASS:15)
B(4,32,4,STAINED_GLASS:15)
B(5,32,4,STAINED_GLASS:15)
B(1,32,5,STAINED_GLASS:15)
B(2,32,5,STAINED_GLASS:15)
B(3,32,5,SEA_LANTERN)
B(4,32,5,STAINED_GLASS:6)
B(5,32,5,STAINED_GLASS:6)
B(1,32,6,STAINED_GLASS:15)
B(2,32,6,STAINED_GLASS:11)
B(3,32,6,SEA_LANTERN)
B(4,32,6,SEA_LANTERN)
B(5,32,6,STAINED_GLASS:15)
B(1,32,7,STAINED_GLASS:11)
B(2,32,7,STAINED_GLASS:11)
B(3,32,7,SEA_LANTERN)
B(4,32,7,SEA_LANTERN)
B(5,32,7,SEA_LANTERN)
B(6,32,7,STAINED_GLASS:15)
B(2,32,8,STAINED_GLASS:15)
B(3,32,8,STAINED_GLASS:6)
B(4,32,8,STAINED_GLASS:15)
B(5,32,8,STAINED_GLASS:15)
B(3,32,9,STAINED_GLASS:15)
B(5,32,9,STAINED_GLASS:15)
B(3,33,3,STAINED_GLASS:15)
B(4,33,3,STAINED_GLASS:15)
B(5,33,3,STAINED_GLASS:15)
B(0,33,4,STAINED_GLASS:15)
B(1,33,4,STAINED_GLASS:15)
B(2,33,4,STAINED_GLASS:15)
B(3,33,4,STAINED_GLASS:15)
B(4,33,4,STAINED_GLASS:15)
B(5,33,4,STAINED_GLASS:15)
B(1,33,5,STAINED_GLASS:11)
B(2,33,5,STAINED_GLASS:6)
B(3,33,5,SEA_LANTERN)
B(4,33,5,STAINED_GLASS:6)
B(5,33,5,STAINED_GLASS:6)
B(1,33,6,STAINED_GLASS:11)
B(2,33,6,STAINED_GLASS:11)
B(3,33,6,SEA_LANTERN)
B(4,33,6,SEA_LANTERN)
B(5,33,6,STAINED_GLASS:15)
B(1,33,7,STAINED_GLASS:11)
B(2,33,7,STAINED_GLASS:11)
B(3,33,7,SEA_LANTERN)
B(4,33,7,SEA_LANTERN)
B(5,33,7,STAINED_GLASS:6)
B(6,33,7,STAINED_GLASS:15)
B(2,33,8,STAINED_GLASS:11)
B(3,33,8,STAINED_GLASS:6)
B(4,33,8,STAINED_GLASS:15)
B(5,33,8,STAINED_GLASS:15)
B(3,34,3,STAINED_GLASS:15)
B(4,34,3,STAINED_GLASS:15)
B(5,34,3,STAINED_GLASS:15)
B(0,34,4,STAINED_GLASS:15)
B(1,34,4,STAINED_GLASS:15)
B(2,34,4,STAINED_GLASS:15)
B(3,34,4,SEA_LANTERN)
B(4,34,4,STAINED_GLASS:6)
B(5,34,4,STAINED_GLASS:15)
B(1,34,5,STAINED_GLASS:15)
B(2,34,5,STAINED_GLASS:6)
B(3,34,5,SEA_LANTERN)
B(4,34,5,SEA_LANTERN)
B(5,34,5,SEA_LANTERN)
B(1,34,6,STAINED_GLASS:15)
B(2,34,6,STAINED_GLASS:11)
B(3,34,6,SEA_LANTERN)
B(4,34,6,SEA_LANTERN)
B(5,34,6,STAINED_GLASS:15)
B(1,34,7,STAINED_GLASS:11)
B(2,34,7,STAINED_GLASS:11)
B(3,34,7,SEA_LANTERN)
B(4,34,7,STAINED_GLASS:15)
B(5,34,7,STAINED_GLASS:6)
B(6,34,7,STAINED_GLASS:15)
B(2,34,8,STAINED_GLASS:15)
B(3,34,8,STAINED_GLASS:15)
B(4,34,8,STAINED_GLASS:15)
B(1,35,3,STAINED_GLASS:15)
B(2,35,3,STAINED_GLASS:15)
B(3,35,3,STAINED_GLASS:15)
B(4,35,3,STAINED_GLASS:15)
B(5,35,3,STAINED_GLASS:15)
B(0,35,4,STAINED_GLASS:15)
B(1,35,4,STAINED_GLASS:15)
B(2,35,4,STAINED_GLASS:15)
B(3,35,4,SEA_LANTERN)
B(4,35,4,STAINED_GLASS:6)
B(5,35,4,STAINED_GLASS:15)
B(1,35,5,STAINED_GLASS:15)
B(2,35,5,SEA_LANTERN)
B(3,35,5,SEA_LANTERN)
B(4,35,5,SEA_LANTERN)
B(5,35,5,SEA_LANTERN)
B(1,35,6,STAINED_GLASS:15)
B(2,35,6,STAINED_GLASS:15)
B(3,35,6,SEA_LANTERN)
B(4,35,6,SEA_LANTERN)
B(5,35,6,STAINED_GLASS:15)
B(1,35,7,STAINED_GLASS:15)
B(2,35,7,STAINED_GLASS:15)
B(3,35,7,STAINED_GLASS:15)
B(4,35,7,STAINED_GLASS:15)
B(5,35,7,STAINED_GLASS:15)
B(3,35,8,STAINED_GLASS:15)
B(4,36,1,STAINED_GLASS:15)
B(3,36,2,STAINED_GLASS:15)
B(4,36,2,STAINED_GLASS:15)
B(0,36,3,STAINED_GLASS:15)
B(1,36,3,STAINED_GLASS:15)
B(2,36,3,STAINED_GLASS:15)
B(3,36,3,SEA_LANTERN)
B(4,36,3,STAINED_GLASS:15)
B(5,36,3,STAINED_GLASS:15)
B(0,36,4,STAINED_GLASS:15)
B(1,36,4,STAINED_GLASS:15)
B(2,36,4,STAINED_GLASS:6)
B(3,36,4,SEA_LANTERN)
B(4,36,4,STAINED_GLASS:6)
B(5,36,4,STAINED_GLASS:15)
B(1,36,5,STAINED_GLASS:15)
B(2,36,5,SEA_LANTERN)
B(3,36,5,SEA_LANTERN)
B(4,36,5,STAINED_GLASS:6)
B(5,36,5,STAINED_GLASS:6)
B(1,36,6,STAINED_GLASS:15)
B(2,36,6,STAINED_GLASS:11)
B(3,36,6,SEA_LANTERN)
B(4,36,6,SEA_LANTERN)
B(5,36,6,STAINED_GLASS:15)
B(1,36,7,STAINED_GLASS:11)
B(2,36,7,STAINED_GLASS:11)
B(3,36,7,STAINED_GLASS:15)
B(5,36,7,STAINED_GLASS:15)
B(4,37,1,STAINED_GLASS:15)
B(3,37,2,STAINED_GLASS:15)
B(4,37,2,STAINED_GLASS:15)
B(0,37,3,STAINED_GLASS:15)
B(1,37,3,STAINED_GLASS:15)
B(2,37,3,SEA_LANTERN)
B(3,37,3,SEA_LANTERN)
B(4,37,3,STAINED_GLASS:15)
B(5,37,3,STAINED_GLASS:15)
B(0,37,4,STAINED_GLASS:15)
B(1,37,4,STAINED_GLASS:15)
B(2,37,4,STAINED_GLASS:6)
B(3,37,4,SEA_LANTERN)
B(4,37,4,SEA_LANTERN)
B(5,37,4,STAINED_GLASS:15)
B(1,37,5,STAINED_GLASS:11)
B(2,37,5,STAINED_GLASS:6)
B(3,37,5,SEA_LANTERN)
B(4,37,5,STAINED_GLASS:6)
B(5,37,5,STAINED_GLASS:6)
B(1,37,6,STAINED_GLASS:11)
B(2,37,6,STAINED_GLASS:11)
B(3,37,6,SEA_LANTERN)
B(4,37,6,STAINED_GLASS:15)
B(5,37,6,STAINED_GLASS:15)
B(1,37,7,STAINED_GLASS:11)
B(3,37,7,STAINED_GLASS:11)
B(2,38,1,STAINED_GLASS:15)
B(3,38,1,STAINED_GLASS:15)
B(4,38,1,STAINED_GLASS:15)
B(0,38,2,STAINED_GLASS:15)
B(1,38,2,STAINED_GLASS:15)
B(2,38,2,STAINED_GLASS:15)
B(3,38,2,STAINED_GLASS:15)
B(4,38,2,STAINED_GLASS:15)
B(0,38,3,STAINED_GLASS:15)
B(1,38,3,STAINED_GLASS:15)
B(2,38,3,SEA_LANTERN)
B(3,38,3,SEA_LANTERN)
B(4,38,3,STAINED_GLASS:15)
B(5,38,3,STAINED_GLASS:15)
B(0,38,4,STAINED_GLASS:15)
B(1,38,4,STAINED_GLASS:15)
B(2,38,4,SEA_LANTERN)
B(3,38,4,SEA_LANTERN)
B(4,38,4,SEA_LANTERN)
B(5,38,4,STAINED_GLASS:15)
B(1,38,5,STAINED_GLASS:15)
B(2,38,5,STAINED_GLASS:6)
B(3,38,5,STAINED_GLASS:11)
B(4,38,5,STAINED_GLASS:15)
B(5,38,5,STAINED_GLASS:15)
B(1,38,6,STAINED_GLASS:15)
B(2,38,6,STAINED_GLASS:11)
B(3,38,6,STAINED_GLASS:11)
B(4,38,6,STAINED_GLASS:11)
B(1,39,1,STAINED_GLASS:15)
B(2,39,1,STAINED_GLASS:15)
B(3,39,1,STAINED_GLASS:15)
B(4,39,1,STAINED_GLASS:15)
B(0,39,2,STAINED_GLASS:15)
B(1,39,2,STAINED_GLASS:15)
B(2,39,2,STAINED_GLASS:15)
B(3,39,2,SEA_LANTERN)
B(4,39,2,STAINED_GLASS:15)
B(0,39,3,STAINED_GLASS:15)
B(1,39,3,STAINED_GLASS:15)
B(2,39,3,SEA_LANTERN)
B(3,39,3,SEA_LANTERN)
B(4,39,3,STAINED_GLASS:15)
B(5,39,3,STAINED_GLASS:15)
B(0,39,4,STAINED_GLASS:15)
B(1,39,4,STAINED_GLASS:15)
B(2,39,4,SEA_LANTERN)
B(3,39,4,SEA_LANTERN)
B(4,39,4,STAINED_GLASS:6)
B(5,39,4,STAINED_GLASS:15)
B(1,39,5,STAINED_GLASS:15)
B(2,39,5,STAINED_GLASS:6)
B(3,39,5,STAINED_GLASS:11)
B(4,39,5,STAINED_GLASS:15)
B(5,39,5,STAINED_GLASS:15)
B(1,39,6,STAINED_GLASS:15)
B(2,39,6,STAINED_GLASS:11)
B(3,39,6,STAINED_GLASS:11)
B(1,40,1,STAINED_GLASS:15)
B(2,40,1,STAINED_GLASS:15)
B(3,40,1,STAINED_GLASS:15)
B(4,40,1,STAINED_GLASS:15)
B(0,40,2,STAINED_GLASS:15)
B(1,40,2,STAINED_GLASS:15)
B(2,40,2,STAINED_GLASS:15)
B(3,40,2,SEA_LANTERN)
B(4,40,2,STAINED_GLASS:15)
B(0,40,3,STAINED_GLASS:15)
B(1,40,3,STAINED_GLASS:15)
B(2,40,3,SEA_LANTERN)
B(3,40,3,SEA_LANTERN)
B(4,40,3,STAINED_GLASS:15)
B(5,40,3,STAINED_GLASS:15)
B(0,40,4,STAINED_GLASS:15)
B(1,40,4,STAINED_GLASS:15)
B(2,40,4,STAINED_GLASS:6)
B(3,40,4,SEA_LANTERN)
B(4,40,4,STAINED_GLASS:6)
B(5,40,4,STAINED_GLASS:15)
B(1,40,5,STAINED_GLASS:15)
B(2,40,5,STAINED_GLASS:11)
B(3,40,5,STAINED_GLASS:11)
B(1,40,6,STAINED_GLASS:15)
B(3,40,6,STAINED_GLASS:11)
B(1,41,1,STAINED_GLASS:15)
B(2,41,1,STAINED_GLASS:15)
B(3,41,1,STAINED_GLASS:15)
B(0,41,2,STAINED_GLASS:15)
B(1,41,2,STAINED_GLASS:15)
B(2,41,2,STAINED_GLASS:15)
B(3,41,2,SEA_LANTERN)
B(4,41,2,STAINED_GLASS:15)
B(1,41,3,STAINED_GLASS:15)
B(2,41,3,SEA_LANTERN)
B(3,41,3,STAINED_GLASS:15)
B(4,41,3,STAINED_GLASS:15)
B(2,41,4,STAINED_GLASS:15)
B(3,41,4,STAINED_GLASS:11)
B(4,41,4,STAINED_GLASS:11)
B(2,41,5,STAINED_GLASS:11)
B(1,42,1,STAINED_GLASS:15)
B(2,42,1,STAINED_GLASS:11)
B(3,42,1,STAINED_GLASS:11)
B(0,42,2,STAINED_GLASS:15)
B(1,42,2,STAINED_GLASS:15)
B(2,42,2,STAINED_GLASS:11)
B(3,42,2,SEA_LANTERN)
B(4,42,2,STAINED_GLASS:15)
B(1,42,3,STAINED_GLASS:15)
B(2,42,3,STAINED_GLASS:11)
B(3,42,3,STAINED_GLASS:15)
B(2,42,4,STAINED_GLASS:11)
B(2,43,0,STAINED_GLASS:15)
B(1,43,1,STAINED_GLASS:15)
B(2,43,1,STAINED_GLASS:11)
B(3,43,1,STAINED_GLASS:11)
B(0,43,2,STAINED_GLASS:15)
B(1,43,2,STAINED_GLASS:15)
B(2,43,2,STAINED_GLASS:11)
B(3,43,2,STAINED_GLASS:11)
B(1,43,3,STAINED_GLASS:15)
B(2,43,3,STAINED_GLASS:11)
B(2,44,0,STAINED_GLASS:15)
B(1,44,1,STAINED_GLASS:15)
B(2,44,1,STAINED_GLASS:11)
B(2,44,2,STAINED_GLASS:11)
B(3,44,2,STAINED_GLASS:11)
B(2,45,0,STAINED_GLASS:15)
B(2,45,1,STAINED_GLASS:15)
B(2,45,2,STAINED_GLASS:15)
B(2,46,0,STAINED_GLASS:15)

