#######################################################################
# +-----------------------------------------------------------------+ #
# |                            BO3 object                           | #
# +-----------------------------------------------------------------+ #
#######################################################################

Author: Bo3 BulkEdit

Description: Converted Schematic - Modified by Bo3BulkEdit

Version: 3

SettingsMode: WriteDisable

#######################################################################
# +-----------------------------------------------------------------+ #
# |                          Main settings                          | #
# +-----------------------------------------------------------------+ #
#######################################################################



Frequency: 0


SpawnHeight: randomY





##############################
# Height Limits for the BO3. #
##############################

MinHeight: 0
MaxHeight: 256

#######################################################################
# +-----------------------------------------------------------------+ #
# |                      Source block settings                      | #
# +-----------------------------------------------------------------+ #
#######################################################################

CanOverride: true
MaxPercentageOutsideSourceBlock: 100
OutsideSourceBlock: placeAnyway

#######################################################################
# +-----------------------------------------------------------------+ #
# |                               OTG+                              | #
# +-----------------------------------------------------------------+ #
#######################################################################

#######################################################################
# +-----------------------------------------------------------------+ #
# |                              Blocks                             | #
# +-----------------------------------------------------------------+ #
#######################################################################

B(0,750,0,AIR)
B(15,750,15,AIR)
B(10,-3,10,STAINED_GLASS:15)
B(11,-3,10,STAINED_GLASS:15)
B(10,-3,11,STAINED_GLASS:15)
B(11,-3,11,STAINED_GLASS:15)
B(8,-2,8,STAINED_GLASS:15)
B(9,-2,8,STAINED_GLASS:15)
B(10,-2,8,STAINED_GLASS:15)
B(8,-2,9,STAINED_GLASS:15)
B(9,-2,9,STAINED_GLASS:15)
B(10,-2,9,STAINED_GLASS:15)
B(11,-2,9,STAINED_GLASS:15)
B(8,-2,10,STAINED_GLASS:15)
B(9,-2,10,STAINED_GLASS:15)
B(10,-2,10,STAINED_GLASS:15)
B(11,-2,10,STAINED_GLASS:15)
B(9,-2,11,STAINED_GLASS:15)
B(10,-2,11,STAINED_GLASS:15)
B(11,-2,11,STAINED_GLASS:15)
B(7,-1,5,STAINED_GLASS:15)
B(8,-1,5,STAINED_GLASS:15)
B(6,-1,6,STAINED_GLASS:15)
B(7,-1,6,STAINED_GLASS:15)
B(8,-1,6,STAINED_GLASS:15)
B(9,-1,6,STAINED_GLASS:15)
B(5,-1,7,STAINED_GLASS:15)
B(6,-1,7,STAINED_GLASS:15)
B(7,-1,7,STAINED_GLASS:15)
B(8,-1,7,STAINED_GLASS:15)
B(9,-1,7,STAINED_GLASS:15)
B(10,-1,7,STAINED_GLASS:15)
B(5,-1,8,STAINED_GLASS:15)
B(6,-1,8,STAINED_GLASS:15)
B(7,-1,8,STAINED_GLASS:15)
B(8,-1,8,STAINED_GLASS:15)
B(9,-1,8,STAINED_GLASS:15)
B(10,-1,8,STAINED_GLASS:15)
B(11,-1,8,STAINED_GLASS:15)
B(6,-1,9,STAINED_GLASS:15)
B(7,-1,9,STAINED_GLASS:15)
B(8,-1,9,STAINED_GLASS:15)
B(10,-1,9,STAINED_GLASS:15)
B(11,-1,9,STAINED_GLASS:15)
B(7,-1,10,STAINED_GLASS:15)
B(8,-1,10,STAINED_GLASS:15)
B(9,-1,10,STAINED_GLASS:15)
B(10,-1,10,STAINED_GLASS:15)
B(8,-1,11,STAINED_GLASS:15)
B(9,-1,11,STAINED_GLASS:15)
B(6,0,3,STAINED_GLASS:15)
B(7,0,3,STAINED_GLASS:15)
B(5,0,4,STAINED_GLASS:15)
B(6,0,4,STAINED_GLASS:15)
B(7,0,4,STAINED_GLASS:15)
B(8,0,4,STAINED_GLASS:15)
B(4,0,5,STAINED_GLASS:15)
B(5,0,5,STAINED_GLASS:15)
B(6,0,5,STAINED_GLASS:15)
B(7,0,5,STAINED_GLASS:15)
B(8,0,5,STAINED_GLASS:15)
B(9,0,5,STAINED_GLASS:15)
B(3,0,6,STAINED_GLASS:15)
B(4,0,6,STAINED_GLASS:15)
B(5,0,6,STAINED_GLASS:15)
B(7,0,6,STAINED_GLASS:15)
B(8,0,6,STAINED_GLASS:15)
B(9,0,6,STAINED_GLASS:15)
B(10,0,6,STAINED_GLASS:15)
B(3,0,7,STAINED_GLASS:15)
B(4,0,7,STAINED_GLASS:15)
B(5,0,7,STAINED_GLASS:15)
B(6,0,7,STAINED_GLASS:15)
B(7,0,7,STAINED_GLASS:15)
B(10,0,7,STAINED_GLASS:15)
B(11,0,7,STAINED_GLASS:15)
B(4,0,8,STAINED_GLASS:15)
B(5,0,8,STAINED_GLASS:15)
B(6,0,8,STAINED_GLASS:15)
B(10,0,8,STAINED_GLASS:15)
B(11,0,8,STAINED_GLASS:15)
B(5,0,9,STAINED_GLASS:15)
B(6,0,9,STAINED_GLASS:15)
B(10,0,9,STAINED_GLASS:15)
B(5,0,10,STAINED_GLASS:15)
B(6,0,10,STAINED_GLASS:15)
B(7,0,10,STAINED_GLASS:15)
B(8,0,10,STAINED_GLASS:15)
B(9,0,10,STAINED_GLASS:15)
B(7,0,11,STAINED_GLASS:15)
B(8,0,11,STAINED_GLASS:15)
B(5,1,1,STAINED_GLASS:15)
B(6,1,1,STAINED_GLASS:15)
B(4,1,2,STAINED_GLASS:15)
B(5,1,2,STAINED_GLASS:15)
B(6,1,2,STAINED_GLASS:15)
B(7,1,2,STAINED_GLASS:15)
B(8,1,2,STAINED_GLASS:15)
B(3,1,3,STAINED_GLASS:15)
B(4,1,3,STAINED_GLASS:15)
B(5,1,3,STAINED_GLASS:15)
B(6,1,3,STAINED_GLASS:15)
B(7,1,3,STAINED_GLASS:15)
B(8,1,3,STAINED_GLASS:15)
B(9,1,3,STAINED_GLASS:15)
B(2,1,4,STAINED_GLASS:15)
B(3,1,4,STAINED_GLASS:15)
B(4,1,4,STAINED_GLASS:15)
B(5,1,4,STAINED_GLASS:15)
B(6,1,4,STAINED_GLASS:15)
B(7,1,4,STAINED_GLASS:15)
B(8,1,4,STAINED_GLASS:15)
B(9,1,4,STAINED_GLASS:15)
B(1,1,5,STAINED_GLASS:15)
B(2,1,5,STAINED_GLASS:15)
B(3,1,5,STAINED_GLASS:15)
B(4,1,5,STAINED_GLASS:15)
B(5,1,5,STAINED_GLASS:15)
B(6,1,5,SEA_LANTERN)
B(9,1,5,STAINED_GLASS:15)
B(10,1,5,STAINED_GLASS:15)
B(1,1,6,STAINED_GLASS:15)
B(2,1,6,STAINED_GLASS:15)
B(3,1,6,STAINED_GLASS:15)
B(5,1,6,SEA_LANTERN)
B(6,1,6,SEA_LANTERN)
B(7,1,6,SEA_LANTERN)
B(10,1,6,STAINED_GLASS:15)
B(2,1,7,STAINED_GLASS:15)
B(3,1,7,STAINED_GLASS:15)
B(4,1,7,STAINED_GLASS:15)
B(6,1,7,SEA_LANTERN)
B(9,1,7,STAINED_GLASS:15)
B(2,1,8,STAINED_GLASS:15)
B(3,1,8,STAINED_GLASS:15)
B(4,1,8,STAINED_GLASS:15)
B(9,1,8,STAINED_GLASS:15)
B(10,1,8,STAINED_GLASS:15)
B(3,1,9,STAINED_GLASS:15)
B(4,1,9,STAINED_GLASS:15)
B(5,1,9,STAINED_GLASS:15)
B(6,1,9,STAINED_GLASS:15)
B(7,1,9,STAINED_GLASS:15)
B(8,1,9,STAINED_GLASS:15)
B(9,1,9,STAINED_GLASS:15)
B(10,1,9,STAINED_GLASS:15)
B(5,1,10,STAINED_GLASS:15)
B(6,1,10,STAINED_GLASS:15)
B(7,1,10,STAINED_GLASS:15)
B(9,1,10,STAINED_GLASS:15)
B(4,2,0,STAINED_GLASS:15)
B(5,2,0,STAINED_GLASS:15)
B(3,2,1,STAINED_GLASS:15)
B(4,2,1,STAINED_GLASS:15)
B(5,2,1,STAINED_GLASS:15)
B(6,2,1,STAINED_GLASS:15)
B(7,2,1,STAINED_GLASS:15)
B(2,2,2,STAINED_GLASS:15)
B(3,2,2,STAINED_GLASS:15)
B(4,2,2,STAINED_GLASS:15)
B(5,2,2,STAINED_GLASS:15)
B(6,2,2,STAINED_GLASS:15)
B(7,2,2,STAINED_GLASS:15)
B(8,2,2,STAINED_GLASS:15)
B(1,2,3,STAINED_GLASS:15)
B(2,2,3,STAINED_GLASS:15)
B(3,2,3,STAINED_GLASS:15)
B(4,2,3,STAINED_GLASS:11)
B(5,2,3,STAINED_GLASS:10)
B(6,2,3,STAINED_GLASS:10)
B(7,2,3,STAINED_GLASS:11)
B(8,2,3,STAINED_GLASS:15)
B(9,2,3,STAINED_GLASS:9)
B(0,2,4,STAINED_GLASS:15)
B(1,2,4,STAINED_GLASS:15)
B(2,2,4,STAINED_GLASS:15)
B(3,2,4,STAINED_GLASS:11)
B(4,2,4,STAINED_GLASS:10)
B(5,2,4,STAINED_GLASS:10)
B(6,2,4,STAINED_GLASS:10)
B(7,2,4,STAINED_GLASS:10)
B(8,2,4,STAINED_GLASS:11)
B(9,2,4,STAINED_GLASS:11)
B(10,2,4,STAINED_GLASS:15)
B(0,2,5,STAINED_GLASS:15)
B(1,2,5,STAINED_GLASS:15)
B(2,2,5,STAINED_GLASS:11)
B(3,2,5,STAINED_GLASS:10)
B(4,2,5,STAINED_GLASS:10)
B(5,2,5,SEA_LANTERN)
B(6,2,5,SEA_LANTERN)
B(7,2,5,STAINED_GLASS:10)
B(8,2,5,STAINED_GLASS:10)
B(9,2,5,STAINED_GLASS:11)
B(10,2,5,STAINED_GLASS:15)
B(1,2,6,STAINED_GLASS:15)
B(2,2,6,STAINED_GLASS:15)
B(3,2,6,STAINED_GLASS:10)
B(4,2,6,STAINED_GLASS:10)
B(5,2,6,SEA_LANTERN)
B(6,2,6,SEA_LANTERN)
B(7,2,6,STAINED_GLASS:10)
B(8,2,6,STAINED_GLASS:10)
B(9,2,6,STAINED_GLASS:11)
B(10,2,6,STAINED_GLASS:15)
B(1,2,7,STAINED_GLASS:15)
B(2,2,7,STAINED_GLASS:15)
B(3,2,7,STAINED_GLASS:11)
B(4,2,7,STAINED_GLASS:10)
B(5,2,7,STAINED_GLASS:10)
B(6,2,7,STAINED_GLASS:10)
B(7,2,7,STAINED_GLASS:10)
B(8,2,7,STAINED_GLASS:11)
B(9,2,7,STAINED_GLASS:15)
B(2,2,8,STAINED_GLASS:15)
B(3,2,8,STAINED_GLASS:15)
B(4,2,8,STAINED_GLASS:11)
B(5,2,8,STAINED_GLASS:10)
B(6,2,8,STAINED_GLASS:10)
B(7,2,8,STAINED_GLASS:11)
B(8,2,8,STAINED_GLASS:11)
B(9,2,8,STAINED_GLASS:15)
B(3,2,9,STAINED_GLASS:15)
B(4,2,9,STAINED_GLASS:15)
B(5,2,9,STAINED_GLASS:11)
B(6,2,9,STAINED_GLASS:15)
B(7,2,9,STAINED_GLASS:9)
B(8,2,9,STAINED_GLASS:15)
B(4,2,10,STAINED_GLASS:15)
B(5,2,10,STAINED_GLASS:15)
B(6,2,10,STAINED_GLASS:15)
B(3,3,0,STAINED_GLASS:9)
B(4,3,0,STAINED_GLASS:11)
B(5,3,0,STAINED_GLASS:9)
B(2,3,1,STAINED_GLASS:9)
B(3,3,1,STAINED_GLASS:11)
B(4,3,1,STAINED_GLASS:9)
B(5,3,1,STAINED_GLASS:11)
B(6,3,1,STAINED_GLASS:9)
B(7,3,1,STAINED_GLASS:9)
B(1,3,2,STAINED_GLASS:9)
B(2,3,2,STAINED_GLASS:11)
B(3,3,2,STAINED_GLASS:9)
B(4,3,2,STAINED_GLASS:11)
B(5,3,2,STAINED_GLASS:10)
B(6,3,2,STAINED_GLASS:11)
B(7,3,2,STAINED_GLASS:9)
B(8,3,2,STAINED_GLASS:9)
B(0,3,3,STAINED_GLASS:9)
B(1,3,3,STAINED_GLASS:11)
B(2,3,3,STAINED_GLASS:9)
B(3,3,3,STAINED_GLASS:11)
B(4,3,3,STAINED_GLASS:10)
B(5,3,3,STAINED_GLASS:10)
B(6,3,3,STAINED_GLASS:10)
B(7,3,3,STAINED_GLASS:11)
B(8,3,3,STAINED_GLASS:11)
B(9,3,3,STAINED_GLASS:15)
B(0,3,4,STAINED_GLASS:11)
B(1,3,4,STAINED_GLASS:9)
B(2,3,4,STAINED_GLASS:11)
B(3,3,4,STAINED_GLASS:10)
B(4,3,4,STAINED_GLASS:10)
B(5,3,4,SEA_LANTERN)
B(6,3,4,STAINED_GLASS:10)
B(7,3,4,STAINED_GLASS:10)
B(8,3,4,STAINED_GLASS:11)
B(9,3,4,STAINED_GLASS:15)
B(0,3,5,STAINED_GLASS:9)
B(1,3,5,STAINED_GLASS:11)
B(2,3,5,STAINED_GLASS:10)
B(3,3,5,STAINED_GLASS:10)
B(4,3,5,SEA_LANTERN)
B(5,3,5,SEA_LANTERN)
B(6,3,5,SEA_LANTERN)
B(7,3,5,STAINED_GLASS:10)
B(8,3,5,STAINED_GLASS:10)
B(9,3,5,STAINED_GLASS:11)
B(10,3,5,STAINED_GLASS:15)
B(1,3,6,STAINED_GLASS:15)
B(2,3,6,STAINED_GLASS:11)
B(3,3,6,STAINED_GLASS:10)
B(4,3,6,STAINED_GLASS:10)
B(5,3,6,SEA_LANTERN)
B(6,3,6,STAINED_GLASS:10)
B(7,3,6,STAINED_GLASS:10)
B(8,3,6,STAINED_GLASS:11)
B(9,3,6,STAINED_GLASS:15)
B(1,3,7,STAINED_GLASS:15)
B(2,3,7,STAINED_GLASS:15)
B(3,3,7,STAINED_GLASS:11)
B(4,3,7,STAINED_GLASS:10)
B(5,3,7,STAINED_GLASS:10)
B(6,3,7,STAINED_GLASS:10)
B(7,3,7,STAINED_GLASS:11)
B(8,3,7,STAINED_GLASS:11)
B(9,3,7,STAINED_GLASS:15)
B(2,3,8,STAINED_GLASS:15)
B(3,3,8,STAINED_GLASS:11)
B(4,3,8,STAINED_GLASS:11)
B(5,3,8,STAINED_GLASS:10)
B(6,3,8,STAINED_GLASS:11)
B(7,3,8,STAINED_GLASS:11)
B(8,3,8,STAINED_GLASS:15)
B(3,3,9,STAINED_GLASS:15)
B(4,3,9,STAINED_GLASS:9)
B(5,3,9,STAINED_GLASS:11)
B(6,3,9,STAINED_GLASS:9)
B(7,3,9,STAINED_GLASS:9)
B(5,3,10,STAINED_GLASS:9)
B(2,4,0,STAINED_GLASS:9)
B(3,4,0,STAINED_GLASS:11)
B(4,4,0,STAINED_GLASS:9)
B(5,4,0,STAINED_GLASS:9)
B(6,4,0,STAINED_GLASS:9)
B(1,4,1,STAINED_GLASS:9)
B(2,4,1,STAINED_GLASS:11)
B(3,4,1,STAINED_GLASS:9)
B(4,4,1,STAINED_GLASS:11)
B(5,4,1,STAINED_GLASS:11)
B(6,4,1,STAINED_GLASS:9)
B(7,4,1,STAINED_GLASS:9)
B(0,4,2,STAINED_GLASS:9)
B(1,4,2,STAINED_GLASS:11)
B(2,4,2,STAINED_GLASS:9)
B(3,4,2,STAINED_GLASS:11)
B(4,4,2,STAINED_GLASS:10)
B(5,4,2,STAINED_GLASS:10)
B(6,4,2,STAINED_GLASS:11)
B(7,4,2,STAINED_GLASS:11)
B(8,4,2,STAINED_GLASS:9)
B(0,4,3,STAINED_GLASS:11)
B(1,4,3,STAINED_GLASS:9)
B(2,4,3,STAINED_GLASS:11)
B(3,4,3,STAINED_GLASS:10)
B(4,4,3,STAINED_GLASS:10)
B(5,4,3,STAINED_GLASS:10)
B(6,4,3,STAINED_GLASS:10)
B(7,4,3,STAINED_GLASS:11)
B(8,4,3,STAINED_GLASS:11)
B(9,4,3,STAINED_GLASS:15)
B(0,4,4,STAINED_GLASS:9)
B(1,4,4,STAINED_GLASS:11)
B(2,4,4,STAINED_GLASS:10)
B(3,4,4,STAINED_GLASS:10)
B(4,4,4,SEA_LANTERN)
B(5,4,4,SEA_LANTERN)
B(6,4,4,STAINED_GLASS:10)
B(7,4,4,STAINED_GLASS:10)
B(8,4,4,STAINED_GLASS:11)
B(9,4,4,STAINED_GLASS:9)
B(0,4,5,STAINED_GLASS:9)
B(1,4,5,STAINED_GLASS:11)
B(2,4,5,STAINED_GLASS:10)
B(3,4,5,STAINED_GLASS:10)
B(4,4,5,SEA_LANTERN)
B(5,4,5,SEA_LANTERN)
B(6,4,5,STAINED_GLASS:10)
B(7,4,5,STAINED_GLASS:10)
B(8,4,5,STAINED_GLASS:11)
B(9,4,5,STAINED_GLASS:15)
B(0,4,6,STAINED_GLASS:15)
B(1,4,6,STAINED_GLASS:15)
B(2,4,6,STAINED_GLASS:11)
B(3,4,6,STAINED_GLASS:10)
B(4,4,6,STAINED_GLASS:10)
B(5,4,6,STAINED_GLASS:10)
B(6,4,6,STAINED_GLASS:10)
B(7,4,6,STAINED_GLASS:11)
B(8,4,6,STAINED_GLASS:15)
B(1,4,7,STAINED_GLASS:15)
B(2,4,7,STAINED_GLASS:11)
B(3,4,7,STAINED_GLASS:11)
B(4,4,7,STAINED_GLASS:10)
B(5,4,7,STAINED_GLASS:10)
B(6,4,7,STAINED_GLASS:11)
B(7,4,7,STAINED_GLASS:11)
B(8,4,7,STAINED_GLASS:15)
B(2,4,8,STAINED_GLASS:15)
B(3,4,8,STAINED_GLASS:11)
B(4,4,8,STAINED_GLASS:11)
B(5,4,8,STAINED_GLASS:11)
B(6,4,8,STAINED_GLASS:9)
B(7,4,8,STAINED_GLASS:15)
B(3,4,9,STAINED_GLASS:9)
B(4,4,9,STAINED_GLASS:9)
B(5,4,9,STAINED_GLASS:9)
B(1,5,0,STAINED_GLASS:9)
B(2,5,0,STAINED_GLASS:11)
B(3,5,0,STAINED_GLASS:9)
B(4,5,0,STAINED_GLASS:11)
B(5,5,0,STAINED_GLASS:15)
B(6,5,0,STAINED_GLASS:15)
B(0,5,1,STAINED_GLASS:9)
B(1,5,1,STAINED_GLASS:11)
B(2,5,1,STAINED_GLASS:9)
B(3,5,1,STAINED_GLASS:11)
B(4,5,1,STAINED_GLASS:10)
B(5,5,1,STAINED_GLASS:11)
B(6,5,1,STAINED_GLASS:9)
B(7,5,1,STAINED_GLASS:15)
B(0,5,2,STAINED_GLASS:11)
B(1,5,2,STAINED_GLASS:9)
B(2,5,2,STAINED_GLASS:11)
B(3,5,2,STAINED_GLASS:10)
B(4,5,2,STAINED_GLASS:10)
B(5,5,2,STAINED_GLASS:10)
B(6,5,2,STAINED_GLASS:11)
B(7,5,2,STAINED_GLASS:11)
B(8,5,2,STAINED_GLASS:15)
B(0,5,3,STAINED_GLASS:9)
B(1,5,3,STAINED_GLASS:11)
B(2,5,3,STAINED_GLASS:10)
B(3,5,3,STAINED_GLASS:10)
B(4,5,3,SEA_LANTERN)
B(5,5,3,STAINED_GLASS:10)
B(6,5,3,STAINED_GLASS:10)
B(7,5,3,STAINED_GLASS:11)
B(8,5,3,STAINED_GLASS:15)
B(0,5,4,STAINED_GLASS:11)
B(1,5,4,STAINED_GLASS:10)
B(2,5,4,STAINED_GLASS:10)
B(3,5,4,SEA_LANTERN)
B(4,5,4,SEA_LANTERN)
B(5,5,4,SEA_LANTERN)
B(6,5,4,STAINED_GLASS:10)
B(7,5,4,STAINED_GLASS:10)
B(8,5,4,STAINED_GLASS:11)
B(9,5,4,STAINED_GLASS:9)
B(0,5,5,STAINED_GLASS:15)
B(1,5,5,STAINED_GLASS:11)
B(2,5,5,STAINED_GLASS:10)
B(3,5,5,STAINED_GLASS:10)
B(4,5,5,SEA_LANTERN)
B(5,5,5,STAINED_GLASS:10)
B(6,5,5,STAINED_GLASS:10)
B(7,5,5,STAINED_GLASS:11)
B(8,5,5,STAINED_GLASS:9)
B(0,5,6,STAINED_GLASS:15)
B(1,5,6,STAINED_GLASS:15)
B(2,5,6,STAINED_GLASS:11)
B(3,5,6,STAINED_GLASS:10)
B(4,5,6,STAINED_GLASS:10)
B(5,5,6,STAINED_GLASS:10)
B(6,5,6,STAINED_GLASS:11)
B(7,5,6,STAINED_GLASS:11)
B(8,5,6,STAINED_GLASS:15)
B(1,5,7,STAINED_GLASS:15)
B(2,5,7,STAINED_GLASS:11)
B(3,5,7,STAINED_GLASS:11)
B(4,5,7,STAINED_GLASS:10)
B(5,5,7,STAINED_GLASS:11)
B(6,5,7,STAINED_GLASS:11)
B(7,5,7,STAINED_GLASS:15)
B(2,5,8,STAINED_GLASS:9)
B(3,5,8,STAINED_GLASS:9)
B(4,5,8,STAINED_GLASS:11)
B(5,5,8,STAINED_GLASS:9)
B(6,5,8,STAINED_GLASS:9)
B(4,5,9,STAINED_GLASS:9)
B(0,6,0,STAINED_GLASS:9)
B(1,6,0,STAINED_GLASS:11)
B(2,6,0,STAINED_GLASS:9)
B(3,6,0,STAINED_GLASS:11)
B(4,6,0,STAINED_GLASS:11)
B(5,6,0,STAINED_GLASS:15)
B(6,6,0,STAINED_GLASS:15)
B(0,6,1,STAINED_GLASS:11)
B(1,6,1,STAINED_GLASS:9)
B(2,6,1,STAINED_GLASS:11)
B(3,6,1,STAINED_GLASS:10)
B(4,6,1,STAINED_GLASS:10)
B(5,6,1,STAINED_GLASS:11)
B(6,6,1,STAINED_GLASS:11)
B(7,6,1,STAINED_GLASS:15)
B(0,6,2,STAINED_GLASS:9)
B(1,6,2,STAINED_GLASS:11)
B(2,6,2,STAINED_GLASS:10)
B(3,6,2,STAINED_GLASS:10)
B(4,6,2,STAINED_GLASS:10)
B(5,6,2,STAINED_GLASS:10)
B(6,6,2,STAINED_GLASS:11)
B(7,6,2,STAINED_GLASS:11)
B(8,6,2,STAINED_GLASS:9)
B(0,6,3,STAINED_GLASS:11)
B(1,6,3,STAINED_GLASS:10)
B(2,6,3,STAINED_GLASS:10)
B(3,6,3,SEA_LANTERN)
B(4,6,3,SEA_LANTERN)
B(5,6,3,STAINED_GLASS:10)
B(6,6,3,STAINED_GLASS:10)
B(7,6,3,STAINED_GLASS:11)
B(8,6,3,STAINED_GLASS:9)
B(0,6,4,STAINED_GLASS:11)
B(1,6,4,STAINED_GLASS:10)
B(2,6,4,STAINED_GLASS:10)
B(3,6,4,SEA_LANTERN)
B(4,6,4,SEA_LANTERN)
B(5,6,4,STAINED_GLASS:10)
B(6,6,4,STAINED_GLASS:10)
B(7,6,4,STAINED_GLASS:11)
B(8,6,4,STAINED_GLASS:9)
B(0,6,5,STAINED_GLASS:15)
B(1,6,5,STAINED_GLASS:11)
B(2,6,5,STAINED_GLASS:10)
B(3,6,5,STAINED_GLASS:10)
B(4,6,5,STAINED_GLASS:10)
B(5,6,5,STAINED_GLASS:10)
B(6,6,5,STAINED_GLASS:11)
B(7,6,5,STAINED_GLASS:15)
B(0,6,6,STAINED_GLASS:15)
B(1,6,6,STAINED_GLASS:11)
B(2,6,6,STAINED_GLASS:11)
B(3,6,6,STAINED_GLASS:10)
B(4,6,6,STAINED_GLASS:10)
B(5,6,6,STAINED_GLASS:11)
B(6,6,6,STAINED_GLASS:11)
B(7,6,6,STAINED_GLASS:15)
B(1,6,7,STAINED_GLASS:15)
B(2,6,7,STAINED_GLASS:11)
B(3,6,7,STAINED_GLASS:11)
B(4,6,7,STAINED_GLASS:11)
B(5,6,7,STAINED_GLASS:9)
B(6,6,7,STAINED_GLASS:15)
B(2,6,8,STAINED_GLASS:9)
B(3,6,8,STAINED_GLASS:9)
B(4,6,8,STAINED_GLASS:9)
B(0,7,0,STAINED_GLASS:11)
B(1,7,0,STAINED_GLASS:9)
B(2,7,0,STAINED_GLASS:11)
B(3,7,0,STAINED_GLASS:10)
B(4,7,0,STAINED_GLASS:11)
B(5,7,0,STAINED_GLASS:15)
B(6,7,0,STAINED_GLASS:15)
B(0,7,1,STAINED_GLASS:9)
B(1,7,1,STAINED_GLASS:11)
B(2,7,1,STAINED_GLASS:10)
B(3,7,1,STAINED_GLASS:10)
B(4,7,1,STAINED_GLASS:10)
B(5,7,1,STAINED_GLASS:11)
B(6,7,1,STAINED_GLASS:11)
B(7,7,1,STAINED_GLASS:9)
B(0,7,2,STAINED_GLASS:11)
B(1,7,2,STAINED_GLASS:10)
B(2,7,2,STAINED_GLASS:10)
B(3,7,2,SEA_LANTERN)
B(4,7,2,STAINED_GLASS:10)
B(5,7,2,STAINED_GLASS:10)
B(6,7,2,STAINED_GLASS:11)
B(7,7,2,STAINED_GLASS:9)
B(0,7,3,STAINED_GLASS:10)
B(1,7,3,STAINED_GLASS:10)
B(2,7,3,SEA_LANTERN)
B(3,7,3,SEA_LANTERN)
B(4,7,3,SEA_LANTERN)
B(5,7,3,STAINED_GLASS:10)
B(6,7,3,STAINED_GLASS:10)
B(7,7,3,STAINED_GLASS:11)
B(8,7,3,STAINED_GLASS:9)
B(0,7,4,STAINED_GLASS:11)
B(1,7,4,STAINED_GLASS:10)
B(2,7,4,STAINED_GLASS:10)
B(3,7,4,SEA_LANTERN)
B(4,7,4,STAINED_GLASS:10)
B(5,7,4,STAINED_GLASS:10)
B(6,7,4,STAINED_GLASS:11)
B(7,7,4,STAINED_GLASS:9)
B(0,7,5,STAINED_GLASS:15)
B(1,7,5,STAINED_GLASS:11)
B(2,7,5,STAINED_GLASS:10)
B(3,7,5,STAINED_GLASS:10)
B(4,7,5,STAINED_GLASS:10)
B(5,7,5,STAINED_GLASS:11)
B(6,7,5,STAINED_GLASS:11)
B(7,7,5,STAINED_GLASS:15)
B(0,7,6,STAINED_GLASS:15)
B(1,7,6,STAINED_GLASS:11)
B(2,7,6,STAINED_GLASS:11)
B(3,7,6,STAINED_GLASS:10)
B(4,7,6,STAINED_GLASS:11)
B(5,7,6,STAINED_GLASS:11)
B(6,7,6,STAINED_GLASS:15)
B(1,7,7,STAINED_GLASS:15)
B(2,7,7,STAINED_GLASS:9)
B(3,7,7,STAINED_GLASS:11)
B(4,7,7,STAINED_GLASS:9)
B(5,7,7,STAINED_GLASS:9)
B(3,7,8,STAINED_GLASS:9)
B(0,8,0,STAINED_GLASS:9)
B(1,8,0,STAINED_GLASS:11)
B(2,8,0,STAINED_GLASS:10)
B(3,8,0,STAINED_GLASS:10)
B(4,8,0,STAINED_GLASS:11)
B(5,8,0,STAINED_GLASS:11)
B(6,8,0,STAINED_GLASS:9)
B(0,8,1,STAINED_GLASS:11)
B(1,8,1,STAINED_GLASS:10)
B(2,8,1,STAINED_GLASS:10)
B(3,8,1,STAINED_GLASS:10)
B(4,8,1,STAINED_GLASS:10)
B(5,8,1,STAINED_GLASS:11)
B(6,8,1,STAINED_GLASS:11)
B(7,8,1,STAINED_GLASS:9)
B(0,8,2,STAINED_GLASS:10)
B(1,8,2,STAINED_GLASS:10)
B(2,8,2,SEA_LANTERN)
B(3,8,2,SEA_LANTERN)
B(4,8,2,STAINED_GLASS:10)
B(5,8,2,STAINED_GLASS:10)
B(6,8,2,STAINED_GLASS:11)
B(7,8,2,STAINED_GLASS:9)
B(0,8,3,STAINED_GLASS:10)
B(1,8,3,STAINED_GLASS:10)
B(2,8,3,SEA_LANTERN)
B(3,8,3,SEA_LANTERN)
B(4,8,3,STAINED_GLASS:10)
B(5,8,3,STAINED_GLASS:10)
B(6,8,3,STAINED_GLASS:11)
B(7,8,3,STAINED_GLASS:9)
B(0,8,4,STAINED_GLASS:11)
B(1,8,4,STAINED_GLASS:10)
B(2,8,4,STAINED_GLASS:10)
B(3,8,4,STAINED_GLASS:10)
B(4,8,4,STAINED_GLASS:10)
B(5,8,4,STAINED_GLASS:11)
B(6,8,4,STAINED_GLASS:9)
B(0,8,5,STAINED_GLASS:11)
B(1,8,5,STAINED_GLASS:11)
B(2,8,5,STAINED_GLASS:10)
B(3,8,5,STAINED_GLASS:10)
B(4,8,5,STAINED_GLASS:11)
B(5,8,5,STAINED_GLASS:11)
B(6,8,5,STAINED_GLASS:15)
B(0,8,6,STAINED_GLASS:15)
B(1,8,6,STAINED_GLASS:11)
B(2,8,6,STAINED_GLASS:11)
B(3,8,6,STAINED_GLASS:11)
B(4,8,6,STAINED_GLASS:9)
B(5,8,6,STAINED_GLASS:9)
B(1,8,7,STAINED_GLASS:9)
B(2,8,7,STAINED_GLASS:9)
B(3,8,7,STAINED_GLASS:9)
B(0,9,0,STAINED_GLASS:11)
B(1,9,0,STAINED_GLASS:10)
B(2,9,0,STAINED_GLASS:10)
B(3,9,0,STAINED_GLASS:10)
B(4,9,0,STAINED_GLASS:11)
B(5,9,0,STAINED_GLASS:11)
B(6,9,0,STAINED_GLASS:9)
B(0,9,1,STAINED_GLASS:10)
B(1,9,1,STAINED_GLASS:10)
B(2,9,1,SEA_LANTERN)
B(3,9,1,STAINED_GLASS:10)
B(4,9,1,STAINED_GLASS:10)
B(5,9,1,STAINED_GLASS:11)
B(6,9,1,STAINED_GLASS:9)
B(0,9,2,STAINED_GLASS:10)
B(1,9,2,SEA_LANTERN)
B(2,9,2,SEA_LANTERN)
B(3,9,2,SEA_LANTERN)
B(4,9,2,STAINED_GLASS:10)
B(5,9,2,STAINED_GLASS:10)
B(6,9,2,STAINED_GLASS:11)
B(7,9,2,STAINED_GLASS:9)
B(0,9,3,STAINED_GLASS:10)
B(1,9,3,STAINED_GLASS:10)
B(2,9,3,SEA_LANTERN)
B(3,9,3,STAINED_GLASS:10)
B(4,9,3,STAINED_GLASS:10)
B(5,9,3,STAINED_GLASS:11)
B(6,9,3,STAINED_GLASS:9)
B(0,9,4,STAINED_GLASS:11)
B(1,9,4,STAINED_GLASS:10)
B(2,9,4,STAINED_GLASS:10)
B(3,9,4,STAINED_GLASS:10)
B(4,9,4,STAINED_GLASS:11)
B(5,9,4,STAINED_GLASS:11)
B(6,9,4,STAINED_GLASS:15)
B(0,9,5,STAINED_GLASS:11)
B(1,9,5,STAINED_GLASS:11)
B(2,9,5,STAINED_GLASS:10)
B(3,9,5,STAINED_GLASS:11)
B(4,9,5,STAINED_GLASS:11)
B(5,9,5,STAINED_GLASS:15)
B(0,9,6,STAINED_GLASS:15)
B(1,9,6,STAINED_GLASS:15)
B(2,9,6,STAINED_GLASS:11)
B(3,9,6,STAINED_GLASS:9)
B(2,9,7,STAINED_GLASS:9)
B(0,10,0,STAINED_GLASS:10)
B(1,10,0,STAINED_GLASS:10)
B(2,10,0,STAINED_GLASS:10)
B(3,10,0,STAINED_GLASS:10)
B(4,10,0,STAINED_GLASS:11)
B(5,10,0,STAINED_GLASS:11)
B(6,10,0,STAINED_GLASS:9)
B(0,10,1,STAINED_GLASS:10)
B(1,10,1,SEA_LANTERN)
B(2,10,1,SEA_LANTERN)
B(3,10,1,STAINED_GLASS:10)
B(4,10,1,STAINED_GLASS:10)
B(5,10,1,STAINED_GLASS:11)
B(6,10,1,STAINED_GLASS:9)
B(0,10,2,STAINED_GLASS:10)
B(1,10,2,SEA_LANTERN)
B(2,10,2,SEA_LANTERN)
B(3,10,2,STAINED_GLASS:10)
B(4,10,2,STAINED_GLASS:10)
B(5,10,2,STAINED_GLASS:11)
B(6,10,2,STAINED_GLASS:9)
B(0,10,3,STAINED_GLASS:10)
B(1,10,3,STAINED_GLASS:10)
B(2,10,3,STAINED_GLASS:10)
B(3,10,3,STAINED_GLASS:10)
B(4,10,3,STAINED_GLASS:11)
B(5,10,3,STAINED_GLASS:9)
B(0,10,4,STAINED_GLASS:11)
B(1,10,4,STAINED_GLASS:10)
B(2,10,4,STAINED_GLASS:10)
B(3,10,4,STAINED_GLASS:11)
B(4,10,4,STAINED_GLASS:11)
B(5,10,4,STAINED_GLASS:9)
B(0,10,5,STAINED_GLASS:11)
B(1,10,5,STAINED_GLASS:11)
B(2,10,5,STAINED_GLASS:11)
B(3,10,5,STAINED_GLASS:9)
B(4,10,5,STAINED_GLASS:9)
B(0,10,6,STAINED_GLASS:15)
B(1,10,6,STAINED_GLASS:15)
B(2,10,6,STAINED_GLASS:9)
B(0,11,0,STAINED_GLASS:10)
B(1,11,0,SEA_LANTERN)
B(2,11,0,STAINED_GLASS:10)
B(3,11,0,STAINED_GLASS:10)
B(4,11,0,STAINED_GLASS:11)
B(5,11,0,STAINED_GLASS:9)
B(0,11,1,SEA_LANTERN)
B(1,11,1,SEA_LANTERN)
B(2,11,1,SEA_LANTERN)
B(3,11,1,STAINED_GLASS:10)
B(4,11,1,STAINED_GLASS:10)
B(5,11,1,STAINED_GLASS:11)
B(6,11,1,STAINED_GLASS:9)
B(0,11,2,STAINED_GLASS:10)
B(1,11,2,SEA_LANTERN)
B(2,11,2,STAINED_GLASS:10)
B(3,11,2,STAINED_GLASS:10)
B(4,11,2,STAINED_GLASS:11)
B(5,11,2,STAINED_GLASS:9)
B(0,11,3,STAINED_GLASS:10)
B(1,11,3,STAINED_GLASS:10)
B(2,11,3,STAINED_GLASS:10)
B(3,11,3,STAINED_GLASS:11)
B(4,11,3,STAINED_GLASS:11)
B(5,11,3,STAINED_GLASS:9)
B(0,11,4,STAINED_GLASS:11)
B(1,11,4,STAINED_GLASS:10)
B(2,11,4,STAINED_GLASS:11)
B(3,11,4,STAINED_GLASS:11)
B(4,11,4,STAINED_GLASS:9)
B(0,11,5,STAINED_GLASS:15)
B(1,11,5,STAINED_GLASS:11)
B(2,11,5,STAINED_GLASS:9)
B(3,11,5,STAINED_GLASS:9)
B(1,11,6,STAINED_GLASS:9)
B(0,12,0,SEA_LANTERN)
B(1,12,0,SEA_LANTERN)
B(2,12,0,STAINED_GLASS:10)
B(3,12,0,STAINED_GLASS:10)
B(4,12,0,STAINED_GLASS:11)
B(5,12,0,STAINED_GLASS:15)
B(0,12,1,SEA_LANTERN)
B(1,12,1,SEA_LANTERN)
B(2,12,1,STAINED_GLASS:10)
B(3,12,1,STAINED_GLASS:10)
B(4,12,1,STAINED_GLASS:11)
B(5,12,1,STAINED_GLASS:15)
B(0,12,2,STAINED_GLASS:10)
B(1,12,2,STAINED_GLASS:10)
B(2,12,2,STAINED_GLASS:10)
B(3,12,2,STAINED_GLASS:11)
B(4,12,2,STAINED_GLASS:9)
B(0,12,3,STAINED_GLASS:10)
B(1,12,3,STAINED_GLASS:10)
B(2,12,3,STAINED_GLASS:11)
B(3,12,3,STAINED_GLASS:11)
B(4,12,3,STAINED_GLASS:9)
B(0,12,4,STAINED_GLASS:11)
B(1,12,4,STAINED_GLASS:11)
B(2,12,4,STAINED_GLASS:15)
B(3,12,4,STAINED_GLASS:9)
B(0,12,5,STAINED_GLASS:15)
B(1,12,5,STAINED_GLASS:15)
B(0,13,0,SEA_LANTERN)
B(1,13,0,SEA_LANTERN)
B(2,13,0,STAINED_GLASS:10)
B(3,13,0,STAINED_GLASS:10)
B(4,13,0,STAINED_GLASS:11)
B(5,13,0,STAINED_GLASS:15)
B(0,13,1,SEA_LANTERN)
B(1,13,1,STAINED_GLASS:10)
B(2,13,1,STAINED_GLASS:10)
B(3,13,1,STAINED_GLASS:11)
B(4,13,1,STAINED_GLASS:15)
B(0,13,2,STAINED_GLASS:10)
B(1,13,2,STAINED_GLASS:10)
B(2,13,2,STAINED_GLASS:11)
B(3,13,2,STAINED_GLASS:11)
B(4,13,2,STAINED_GLASS:9)
B(0,13,3,STAINED_GLASS:10)
B(1,13,3,STAINED_GLASS:11)
B(2,13,3,STAINED_GLASS:11)
B(3,13,3,STAINED_GLASS:9)
B(0,13,4,STAINED_GLASS:11)
B(1,13,4,STAINED_GLASS:15)
B(2,13,4,STAINED_GLASS:15)
B(0,13,5,STAINED_GLASS:15)
B(0,14,0,SEA_LANTERN)
B(1,14,0,STAINED_GLASS:10)
B(2,14,0,STAINED_GLASS:10)
B(3,14,0,STAINED_GLASS:11)
B(4,14,0,STAINED_GLASS:15)
B(0,14,1,STAINED_GLASS:10)
B(1,14,1,STAINED_GLASS:10)
B(2,14,1,STAINED_GLASS:11)
B(3,14,1,STAINED_GLASS:15)
B(0,14,2,STAINED_GLASS:10)
B(1,14,2,STAINED_GLASS:11)
B(2,14,2,STAINED_GLASS:11)
B(3,14,2,STAINED_GLASS:9)
B(0,14,3,STAINED_GLASS:11)
B(1,14,3,STAINED_GLASS:15)
B(2,14,3,STAINED_GLASS:9)
B(0,14,4,STAINED_GLASS:15)
B(0,15,0,STAINED_GLASS:10)
B(1,15,0,STAINED_GLASS:10)
B(2,15,0,STAINED_GLASS:11)
B(3,15,0,STAINED_GLASS:15)
B(0,15,1,STAINED_GLASS:10)
B(1,15,1,STAINED_GLASS:11)
B(2,15,1,STAINED_GLASS:11)
B(3,15,1,STAINED_GLASS:9)
B(0,15,2,STAINED_GLASS:11)
B(1,15,2,STAINED_GLASS:11)
B(2,15,2,STAINED_GLASS:9)
B(0,15,3,STAINED_GLASS:15)
B(1,15,3,STAINED_GLASS:9)
B(0,16,0,STAINED_GLASS:10)
B(1,16,0,STAINED_GLASS:11)
B(2,16,0,STAINED_GLASS:15)
B(0,16,1,STAINED_GLASS:11)
B(1,16,1,STAINED_GLASS:11)
B(2,16,1,STAINED_GLASS:9)
B(0,16,2,STAINED_GLASS:9)
B(1,16,2,STAINED_GLASS:9)
B(0,17,0,STAINED_GLASS:11)
B(1,17,0,STAINED_GLASS:11)
B(2,17,0,STAINED_GLASS:9)
B(0,17,1,STAINED_GLASS:11)
B(1,17,1,STAINED_GLASS:9)
B(0,17,2,STAINED_GLASS:15)
B(0,18,0,STAINED_GLASS:9)
B(1,18,0,STAINED_GLASS:15)
B(0,18,1,STAINED_GLASS:15)
B(0,19,0,STAINED_GLASS:15)

#######################################################################
# +-----------------------------------------------------------------+ #
# |                             Branches                            | #
# +-----------------------------------------------------------------+ #
#######################################################################

BR(0,0,-16,true,SPIKE-MED-EXTREME-03_1x0,NORTH,100,0)
BR(-16,0,0,true,SPIKE-MED-EXTREME-03_0x1,NORTH,100,0)
