#######################################################################
# +-----------------------------------------------------------------+ #
# |                            BO3 object                           | #
# +-----------------------------------------------------------------+ #
#######################################################################

# This is the config file of a custom object.
# If you add this object correctly to your BiomeConfigs, it will spawn in the world.

# This is the creator of this BO3 object
Author: BO3 BulkEdit (by LanToaster)

# A short description of this BO3 object
Description: This Object was Created with BO3_BulkEdit

# The BO3 version, don't change this! It can be used by external applications to do a version check.
Version: 3

# The settings mode, WriteAll, WriteWithoutComments or WriteDisable. See WorldConfig.
SettingsMode: WriteDisable


#######################################################################
# +-----------------------------------------------------------------+ #
# |                          Main settings                          | #
# +-----------------------------------------------------------------+ #
#######################################################################

# This needs to be set to true to spawn the object in the Tree and Sapling resources.
Tree: false

# The frequency of the BO3 from 1 to 200. Tries this many times to spawn this BO3 when using the CustomObject(...) resource.

Frequency: 1

# The rarity of the BO3 from 0 to 100. Each spawn attempt has rarity% chance to succeed when using the CustomObject(...) resource.

Rarity: 100.0

# If you set this to true, the BO3 will be placed with a random rotation.
RotateRandomly: false

# The spawn height of the BO3 - randomY, highestBlock or highestSolidBlock.
SpawnHeight: highestBlock

# The height limits for the BO3.
MinHeight: 0

MaxHeight: 256

# Objects can have other objects attacthed to it: branches. Branches can also
# have branches attached to it, which can also have branches, etc. This is the
# maximum branch depth for this objects.
MaxBranchDepth: 10

# When spawned with the UseWorld keyword, this BO3 should NOT spawn in the following biomes.
# If you writer.write the BO3 name directly in the BiomeConfigs, this will be ignored.
ExcludedBiomes: All


#######################################################################
# +-----------------------------------------------------------------+ #
# |                      Source block settings                      | #
# +-----------------------------------------------------------------+ #
#######################################################################

# The block(s) the BO3 should spawn in.
SourceBlocks: AIR

# The maximum percentage of the BO3 that can be outside the SourceBlock.
# The BO3 won't be placed on a location with more blocks outside the SourceBlock than this percentage.
MaxPercentageOutsideSourceBlock: 100

# What to do when a block is about to be placed outside the SourceBlock? (dontPlace, placeAnyway)
OutsideSourceBlock: placeAnyway


#######################################################################
# +-----------------------------------------------------------------+ #
# |                              Blocks                             | #
# +-----------------------------------------------------------------+ #
#######################################################################

# All the blocks used in the BO3 are listed here. Possible blocks:
# Block(x,y,z,id[.data][,nbtfile.nbt)
# RandomBlock(x,y,z,id[:data][,nbtfile.nbt],chance[,id[:data][,nbtfile.nbt],chance[,...]])
# So RandomBlock(0,0,0,CHEST,chest.nbt,50,CHEST,anotherchest.nbt,100) will spawn a chest at
# the BO3 origin, and give it a 50% chance to have the contents of chest.nbt, or, if that
# fails, a 100% percent chance to have the contents of anotherchest.nbt.
Block(-2,30,8,STAINED_GLASS:15)
Block(-6,31,8,STAINED_GLASS:9)
Block(-5,31,8,STAINED_GLASS:15)
Block(-4,31,8,STAINED_GLASS:15)
Block(-3,31,8,STAINED_GLASS:15)
Block(-2,31,8,STAINED_GLASS:15)
Block(-4,32,7,STAINED_GLASS:15)
Block(-3,32,7,STAINED_GLASS:15)
Block(-7,32,8,STAINED_GLASS:9)
Block(-6,32,8,STAINED_GLASS:9)
Block(-5,32,8,STAINED_GLASS:9)
Block(-4,32,8,STAINED_GLASS:9)
Block(-3,32,8,STAINED_GLASS:9)
Block(-2,32,8,STAINED_GLASS:15)
Block(-6,33,7,STAINED_GLASS:15)
Block(-5,33,7,STAINED_GLASS:15)
Block(-4,33,7,STAINED_GLASS:9)
Block(-3,33,7,STAINED_GLASS:15)
Block(-7,33,8,STAINED_GLASS:9)
Block(-6,33,8,STAINED_GLASS:15)
Block(-5,33,8,STAINED_GLASS:15)
Block(-4,33,8,STAINED_GLASS:15)
Block(-3,33,8,STAINED_GLASS:15)
Block(-2,33,8,STAINED_GLASS:15)
Block(-6,34,6,STAINED_GLASS:15)
Block(-5,34,6,STAINED_GLASS:15)
Block(-4,34,6,STAINED_GLASS:15)
Block(-3,34,6,STAINED_GLASS:15)
Block(-7,34,7,STAINED_GLASS:15)
Block(-6,34,7,STAINED_GLASS:9)
Block(-5,34,7,STAINED_GLASS:9)
Block(-4,34,7,STAINED_GLASS:15)
Block(-3,34,7,STAINED_GLASS:15)
Block(-7,34,8,STAINED_GLASS:15)
Block(-6,34,8,STAINED_GLASS:9)
Block(-5,34,8,STAINED_GLASS:9)
Block(-4,34,8,STAINED_GLASS:9)
Block(-3,34,8,STAINED_GLASS:9)
Block(-2,34,8,STAINED_GLASS:15)
Block(-4,35,5,STAINED_GLASS:15)
Block(-7,35,6,STAINED_GLASS:15)
Block(-6,35,6,STAINED_GLASS:9)
Block(-5,35,6,STAINED_GLASS:9)
Block(-4,35,6,STAINED_GLASS:9)
Block(-3,35,6,STAINED_GLASS:15)
Block(-7,35,7,STAINED_GLASS:9)
Block(-6,35,7,STAINED_GLASS:15)
Block(-5,35,7,STAINED_GLASS:15)
Block(-4,35,7,STAINED_GLASS:9)
Block(-3,35,7,STAINED_GLASS:15)
Block(-2,35,7,STAINED_GLASS:9)
Block(-7,35,8,STAINED_GLASS:9)
Block(-6,35,8,STAINED_GLASS:11)
Block(-5,35,8,STAINED_GLASS:11)
Block(-4,35,8,STAINED_GLASS:11)
Block(-3,35,8,STAINED_GLASS:9)
Block(-2,35,8,STAINED_GLASS:9)
Block(-4,36,5,STAINED_GLASS:15)
Block(-7,36,6,STAINED_GLASS:15)
Block(-6,36,6,STAINED_GLASS:9)
Block(-5,36,6,STAINED_GLASS:9)
Block(-4,36,6,STAINED_GLASS:9)
Block(-3,36,6,STAINED_GLASS:15)
Block(-7,36,7,STAINED_GLASS:9)
Block(-6,36,7,STAINED_GLASS:15)
Block(-5,36,7,STAINED_GLASS:15)
Block(-4,36,7,STAINED_GLASS:9)
Block(-3,36,7,STAINED_GLASS:15)
Block(-2,36,7,STAINED_GLASS:9)
Block(-7,36,8,STAINED_GLASS:9)
Block(-6,36,8,STAINED_GLASS:11)
Block(-5,36,8,STAINED_GLASS:11)
Block(-4,36,8,STAINED_GLASS:11)
Block(-3,36,8,STAINED_GLASS:9)
Block(-2,36,8,STAINED_GLASS:9)
Block(-5,37,4,STAINED_GLASS:15)
Block(-6,37,5,STAINED_GLASS:15)
Block(-5,37,5,STAINED_GLASS:15)
Block(-4,37,5,STAINED_GLASS:15)
Block(-7,37,6,STAINED_GLASS:9)
Block(-6,37,6,STAINED_GLASS:15)
Block(-5,37,6,STAINED_GLASS:15)
Block(-4,37,6,STAINED_GLASS:15)
Block(-3,37,6,STAINED_GLASS:15)
Block(-7,37,7,STAINED_GLASS:15)
Block(-6,37,7,STAINED_GLASS:9)
Block(-5,37,7,STAINED_GLASS:9)
Block(-4,37,7,STAINED_GLASS:9)
Block(-3,37,7,STAINED_GLASS:15)
Block(-7,37,8,STAINED_GLASS:11)
Block(-6,37,8,SEA_LANTERN:0)
Block(-5,37,8,STAINED_GLASS:11)
Block(-4,37,8,STAINED_GLASS:11)
Block(-3,37,8,STAINED_GLASS:9)
Block(-2,37,8,STAINED_GLASS:9)
Block(-5,38,4,STAINED_GLASS:15)
Block(-6,38,5,STAINED_GLASS:15)
Block(-5,38,5,STAINED_GLASS:15)
Block(-4,38,5,STAINED_GLASS:15)
Block(-7,38,6,STAINED_GLASS:9)
Block(-6,38,6,STAINED_GLASS:15)
Block(-5,38,6,STAINED_GLASS:15)
Block(-4,38,6,STAINED_GLASS:15)
Block(-7,38,7,STAINED_GLASS:15)
Block(-6,38,7,STAINED_GLASS:9)
Block(-5,38,7,STAINED_GLASS:9)
Block(-4,38,7,STAINED_GLASS:9)
Block(-7,38,8,STAINED_GLASS:11)
Block(-6,38,8,SEA_LANTERN:0)
Block(-5,38,8,STAINED_GLASS:11)
Block(-4,38,8,STAINED_GLASS:11)
Block(-3,38,8,STAINED_GLASS:9)
Block(-7,39,4,STAINED_GLASS:15)
Block(-6,39,4,STAINED_GLASS:15)
Block(-5,39,4,STAINED_GLASS:15)
Block(-7,39,5,STAINED_GLASS:15)
Block(-6,39,5,STAINED_GLASS:9)
Block(-5,39,5,STAINED_GLASS:15)
Block(-4,39,5,STAINED_GLASS:3)
Block(-7,39,6,STAINED_GLASS:15)
Block(-6,39,6,STAINED_GLASS:9)
Block(-5,39,6,STAINED_GLASS:9)
Block(-4,39,6,STAINED_GLASS:9)
Block(-7,39,7,STAINED_GLASS:9)
Block(-6,39,7,STAINED_GLASS:9)
Block(-5,39,7,STAINED_GLASS:9)
Block(-4,39,7,STAINED_GLASS:9)
Block(-7,39,8,STAINED_GLASS:11)
Block(-6,39,8,STAINED_GLASS:11)
Block(-5,39,8,STAINED_GLASS:9)
Block(-4,39,8,STAINED_GLASS:9)
Block(-3,39,8,STAINED_GLASS:9)
Block(-7,40,4,STAINED_GLASS:15)
Block(-6,40,4,STAINED_GLASS:15)
Block(-5,40,4,STAINED_GLASS:3)
Block(-7,40,5,STAINED_GLASS:15)
Block(-6,40,5,STAINED_GLASS:9)
Block(-5,40,5,STAINED_GLASS:3)
Block(-7,40,6,STAINED_GLASS:15)
Block(-6,40,6,STAINED_GLASS:9)
Block(-5,40,6,STAINED_GLASS:9)
Block(-4,40,6,STAINED_GLASS:9)
Block(-7,40,7,STAINED_GLASS:9)
Block(-6,40,7,STAINED_GLASS:11)
Block(-5,40,7,STAINED_GLASS:9)
Block(-4,40,7,STAINED_GLASS:9)
Block(-7,40,8,STAINED_GLASS:9)
Block(-6,40,8,STAINED_GLASS:11)
Block(-5,40,8,STAINED_GLASS:9)
Block(-4,40,8,STAINED_GLASS:9)
Block(-7,41,4,STAINED_GLASS:15)
Block(-6,41,4,STAINED_GLASS:15)
Block(-5,41,4,STAINED_GLASS:3)
Block(-7,41,5,STAINED_GLASS:15)
Block(-6,41,5,STAINED_GLASS:9)
Block(-5,41,5,STAINED_GLASS:3)
Block(-7,41,6,STAINED_GLASS:15)
Block(-6,41,6,STAINED_GLASS:9)
Block(-5,41,6,STAINED_GLASS:9)
Block(-4,41,6,STAINED_GLASS:9)
Block(-7,41,7,STAINED_GLASS:9)
Block(-6,41,7,STAINED_GLASS:11)
Block(-5,41,7,STAINED_GLASS:9)
Block(-4,41,7,STAINED_GLASS:9)
Block(-7,41,8,STAINED_GLASS:15)
Block(-6,41,8,STAINED_GLASS:9)
Block(-5,41,8,STAINED_GLASS:9)
Block(-4,41,8,STAINED_GLASS:9)
Block(-7,42,4,STAINED_GLASS:9)
Block(-6,42,4,STAINED_GLASS:15)
Block(-7,42,5,STAINED_GLASS:9)
Block(-6,42,5,STAINED_GLASS:15)
Block(-7,42,6,STAINED_GLASS:9)
Block(-6,42,6,STAINED_GLASS:9)
Block(-7,42,7,STAINED_GLASS:9)
Block(-6,42,7,STAINED_GLASS:9)
Block(-5,42,7,STAINED_GLASS:9)
Block(-7,42,8,STAINED_GLASS:15)
Block(-6,42,8,STAINED_GLASS:15)
Block(-5,42,8,STAINED_GLASS:9)
Block(-4,42,8,STAINED_GLASS:9)
Block(-7,43,4,STAINED_GLASS:9)
Block(-6,43,4,STAINED_GLASS:3)
Block(-7,43,5,STAINED_GLASS:9)
Block(-6,43,5,STAINED_GLASS:15)
Block(-7,43,6,STAINED_GLASS:9)
Block(-6,43,6,STAINED_GLASS:9)
Block(-7,43,7,STAINED_GLASS:9)
Block(-6,43,7,STAINED_GLASS:9)
Block(-5,43,7,STAINED_GLASS:9)
Block(-7,43,8,STAINED_GLASS:15)
Block(-7,44,3,STAINED_GLASS:15)
Block(-7,44,4,STAINED_GLASS:15)
Block(-7,44,5,STAINED_GLASS:15)
Block(-6,44,5,STAINED_GLASS:15)
Block(-7,44,6,STAINED_GLASS:9)
Block(-6,44,6,STAINED_GLASS:9)
Block(-7,44,7,STAINED_GLASS:15)
Block(-7,45,3,STAINED_GLASS:15)
Block(-7,45,4,STAINED_GLASS:15)
Block(-7,45,5,STAINED_GLASS:15)
Block(-6,45,5,STAINED_GLASS:15)
Block(-7,45,6,STAINED_GLASS:15)
Block(-7,46,3,STAINED_GLASS:15)
Block(-7,46,4,STAINED_GLASS:15)
Block(-7,46,5,STAINED_GLASS:15)
