#######################################################################
# +-----------------------------------------------------------------+ #
# |                            BO3 object                           | #
# +-----------------------------------------------------------------+ #
#######################################################################

# This is the config file of a custom object.
# If you add this object correctly to your BiomeConfigs, it will spawn in the world.

# This is the creator of this BO3 object
Author: BO3 BulkEdit (by LanToaster)

# A short description of this BO3 object
Description: This Object was Created with BO3_BulkEdit

# The BO3 version, don't change this! It can be used by external applications to do a version check.
Version: 3

# The settings mode, WriteAll, WriteWithoutComments or WriteDisable. See WorldConfig.
SettingsMode: WriteDisable


#######################################################################
# +-----------------------------------------------------------------+ #
# |                          Main settings                          | #
# +-----------------------------------------------------------------+ #
#######################################################################

# This needs to be set to true to spawn the object in the Tree and Sapling resources.
Tree: false

# The frequency of the BO3 from 1 to 200. Tries this many times to spawn this BO3 when using the CustomObject(...) resource.
# Ignored by Tree(..), Sapling(..) and CustomStructure(..)
Frequency: 1

# The rarity of the BO3 from 0 to 100. Each spawn attempt has rarity% chance to succeed when using the CustomObject(...) resource.
# Ignored by Tree(..), Sapling(..) and CustomStructure(..)
Rarity: 100.0

# If you set this to true, the BO3 will be placed with a random rotation.
RotateRandomly: false

# The spawn height of the BO3 - randomY, highestBlock or highestSolidBlock.
SpawnHeight: randomY

# The height limits for the BO3.
MinHeight: 62

MaxHeight: 62

# Objects can have other objects attacthed to it: branches. Branches can also
# have branches attached to it, which can also have branches, etc. This is the
# maximum branch depth for this objects.
MaxBranchDepth: 10

# When spawned with the UseWorld keyword, this BO3 should NOT spawn in the following biomes.
# If you writer.write the BO3 name directly in the BiomeConfigs, this will be ignored.
ExcludedBiomes: All


#######################################################################
# +-----------------------------------------------------------------+ #
# |                      Source block settings                      | #
# +-----------------------------------------------------------------+ #
#######################################################################

# The block(s) the BO3 should spawn in.
SourceBlocks: AIR

# The maximum percentage of the BO3 that can be outside the SourceBlock.
# The BO3 won't be placed on a location with more blocks outside the SourceBlock than this percentage.
MaxPercentageOutsideSourceBlock: 100

# What to do when a block is about to be placed outside the SourceBlock? (dontPlace, placeAnyway)
OutsideSourceBlock: placeAnyway


#######################################################################
# +-----------------------------------------------------------------+ #
# |                              Blocks                             | #
# +-----------------------------------------------------------------+ #
#######################################################################

# All the blocks used in the BO3 are listed here. Possible blocks:
# Block(x,y,z,id[.data][,nbtfile.nbt)
# RandomBlock(x,y,z,id[:data][,nbtfile.nbt],chance[,id[:data][,nbtfile.nbt],chance[,...]])
# So RandomBlock(0,0,0,CHEST,chest.nbt,50,CHEST,anotherchest.nbt,100) will spawn a chest at
# the BO3 origin, and give it a 50% chance to have the contents of chest.nbt, or, if that
# fails, a 100% percent chance to have the contents of anotherchest.nbt.
Block(5,0,-7,DIRT:0)
Block(6,0,-7,DIRT:0)
Block(7,0,-7,STONE:0)
Block(8,0,-7,STONE:0)
Block(4,0,-6,DIRT:0)
Block(5,0,-6,DIRT:0)
Block(6,0,-6,DIRT:0)
Block(7,0,-6,DIRT:0)
Block(8,0,-6,STONE:0)
Block(4,0,-5,DIRT:0)
Block(5,0,-5,DIRT:0)
Block(6,0,-5,DIRT:0)
Block(7,0,-5,STONE:0)
Block(8,0,-5,STONE:0)
Block(3,0,-4,DIRT:0)
Block(4,0,-4,DIRT:0)
Block(5,0,-4,DIRT:0)
Block(6,0,-4,STONE:0)
Block(7,0,-4,STONE:0)
Block(8,0,-4,STONE:0)
Block(2,0,-3,DIRT:0)
Block(3,0,-3,DIRT:0)
Block(4,0,-3,DIRT:0)
Block(5,0,-3,DIRT:0)
Block(6,0,-3,STONE:0)
Block(7,0,-3,STONE:0)
Block(8,0,-3,STONE:0)
Block(1,0,-2,STONE:0)
Block(2,0,-2,DIRT:0)
Block(3,0,-2,DIRT:0)
Block(4,0,-2,DIRT:0)
Block(5,0,-2,STONE:0)
Block(6,0,-2,STONE:0)
Block(7,0,-2,STONE:0)
Block(8,0,-2,STONE:0)
Block(1,0,-1,STONE:0)
Block(2,0,-1,STONE:0)
Block(3,0,-1,DIRT:0)
Block(4,0,-1,STONE:0)
Block(5,0,-1,STONE:0)
Block(6,0,-1,STONE:0)
Block(7,0,-1,STONE:0)
Block(8,0,-1,STONE:0)
Block(5,1,-7,DIRT:0)
Block(6,1,-7,DIRT:0)
Block(7,1,-7,DIRT:0)
Block(8,1,-7,DIRT:0)
Block(4,1,-6,DIRT:0)
Block(5,1,-6,DIRT:0)
Block(6,1,-6,DIRT:0)
Block(7,1,-6,DIRT:0)
Block(8,1,-6,DIRT:0)
Block(4,1,-5,DIRT:0)
Block(5,1,-5,DIRT:0)
Block(6,1,-5,DIRT:0)
Block(7,1,-5,DIRT:0)
Block(8,1,-5,DIRT:0)
Block(3,1,-4,DIRT:0)
Block(4,1,-4,DIRT:0)
Block(5,1,-4,DIRT:0)
Block(6,1,-4,DIRT:0)
Block(7,1,-4,DIRT:0)
Block(8,1,-4,STONE:0)
Block(2,1,-3,DIRT:0)
Block(3,1,-3,DIRT:0)
Block(4,1,-3,DIRT:0)
Block(5,1,-3,DIRT:0)
Block(6,1,-3,DIRT:0)
Block(7,1,-3,STONE:0)
Block(8,1,-3,STONE:0)
Block(1,1,-2,DIRT:0)
Block(2,1,-2,DIRT:0)
Block(3,1,-2,DIRT:0)
Block(4,1,-2,DIRT:0)
Block(5,1,-2,DIRT:0)
Block(6,1,-2,DIRT:0)
Block(7,1,-2,STONE:0)
Block(8,1,-2,STONE:0)
Block(1,1,-1,DIRT:0)
Block(2,1,-1,DIRT:0)
Block(3,1,-1,DIRT:0)
Block(4,1,-1,DIRT:0)
Block(5,1,-1,DIRT:0)
Block(6,1,-1,STONE:0)
Block(7,1,-1,STONE:0)
Block(8,1,-1,STONE:0)
Block(5,2,-7,DIRT:0)
Block(6,2,-7,DIRT:0)
Block(7,2,-7,DIRT:0)
Block(8,2,-7,DIRT:0)
Block(4,2,-6,GRASS:0)
Block(5,2,-6,DIRT:0)
Block(6,2,-6,DIRT:0)
Block(7,2,-6,DIRT:0)
Block(8,2,-6,DIRT:0)
Block(4,2,-5,DIRT:0)
Block(5,2,-5,DIRT:0)
Block(6,2,-5,DIRT:0)
Block(7,2,-5,DIRT:0)
Block(8,2,-5,DIRT:0)
Block(3,2,-4,GRASS:0)
Block(4,2,-4,DIRT:0)
Block(5,2,-4,DIRT:0)
Block(6,2,-4,DIRT:0)
Block(7,2,-4,DIRT:0)
Block(8,2,-4,DIRT:0)
Block(2,2,-3,GRASS:0)
Block(3,2,-3,DIRT:0)
Block(4,2,-3,DIRT:0)
Block(5,2,-3,DIRT:0)
Block(6,2,-3,DIRT:0)
Block(7,2,-3,DIRT:0)
Block(8,2,-3,STONE:0)
Block(1,2,-2,DIRT:0)
Block(2,2,-2,DIRT:0)
Block(3,2,-2,DIRT:0)
Block(4,2,-2,DIRT:0)
Block(5,2,-2,DIRT:0)
Block(6,2,-2,DIRT:0)
Block(7,2,-2,STONE:0)
Block(8,2,-2,STONE:0)
Block(1,2,-1,DIRT:0)
Block(2,2,-1,DIRT:0)
Block(3,2,-1,DIRT:0)
Block(4,2,-1,DIRT:0)
Block(5,2,-1,DIRT:0)
Block(6,2,-1,DIRT:0)
Block(7,2,-1,STONE:0)
Block(8,2,-1,STONE:0)
Block(5,3,-7,DIRT:0)
Block(6,3,-7,DIRT:0)
Block(7,3,-7,DIRT:0)
Block(8,3,-7,DIRT:0)
Block(5,3,-6,DIRT:0)
Block(6,3,-6,DIRT:0)
Block(7,3,-6,DIRT:0)
Block(8,3,-6,DIRT:0)
Block(4,3,-5,GRASS:0)
Block(5,3,-5,DIRT:0)
Block(6,3,-5,DIRT:0)
Block(7,3,-5,DIRT:0)
Block(8,3,-5,DIRT:0)
Block(4,3,-4,DIRT:0)
Block(5,3,-4,DIRT:0)
Block(6,3,-4,DIRT:0)
Block(7,3,-4,DIRT:0)
Block(8,3,-4,DIRT:0)
Block(3,3,-3,DIRT:0)
Block(4,3,-3,DIRT:0)
Block(5,3,-3,DIRT:0)
Block(6,3,-3,DIRT:0)
Block(7,3,-3,DIRT:0)
Block(8,3,-3,DIRT:0)
Block(1,3,-2,GRASS:0)
Block(2,3,-2,DIRT:0)
Block(3,3,-2,DIRT:0)
Block(4,3,-2,DIRT:0)
Block(5,3,-2,DIRT:0)
Block(6,3,-2,DIRT:0)
Block(7,3,-2,DIRT:0)
Block(8,3,-2,STONE:0)
Block(1,3,-1,GRASS:0)
Block(2,3,-1,DIRT:0)
Block(3,3,-1,DIRT:0)
Block(4,3,-1,DIRT:0)
Block(5,3,-1,DIRT:0)
Block(6,3,-1,DIRT:0)
Block(7,3,-1,STONE:0)
Block(8,3,-1,STONE:0)
Block(5,4,-7,GRASS:0)
Block(6,4,-7,DIRT:0)
Block(7,4,-7,DIRT:0)
Block(8,4,-7,DIRT:0)
Block(5,4,-6,GRASS:0)
Block(6,4,-6,DIRT:0)
Block(7,4,-6,DIRT:0)
Block(8,4,-6,DIRT:0)
Block(5,4,-5,DIRT:0)
Block(6,4,-5,DIRT:0)
Block(7,4,-5,DIRT:0)
Block(8,4,-5,DIRT:0)
Block(4,4,-4,DIRT:0)
Block(5,4,-4,DIRT:0)
Block(6,4,-4,DIRT:0)
Block(7,4,-4,DIRT:0)
Block(8,4,-4,DIRT:0)
Block(3,4,-3,GRASS:0)
Block(4,4,-3,DIRT:0)
Block(5,4,-3,DIRT:0)
Block(6,4,-3,DIRT:0)
Block(7,4,-3,DIRT:0)
Block(8,4,-3,DIRT:0)
Block(2,4,-2,GRASS:0)
Block(3,4,-2,DIRT:0)
Block(4,4,-2,DIRT:0)
Block(5,4,-2,DIRT:0)
Block(6,4,-2,DIRT:0)
Block(7,4,-2,DIRT:0)
Block(8,4,-2,STONE:0)
Block(2,4,-1,GRASS:0)
Block(3,4,-1,DIRT:0)
Block(4,4,-1,DIRT:0)
Block(5,4,-1,DIRT:0)
Block(6,4,-1,DIRT:0)
Block(7,4,-1,DIRT:0)
Block(8,4,-1,STONE:0)
Block(6,5,-7,GRASS:0)
Block(7,5,-7,DIRT:0)
Block(8,5,-7,DIRT:0)
Block(6,5,-6,DIRT:0)
Block(7,5,-6,DIRT:0)
Block(8,5,-6,DIRT:0)
Block(5,5,-5,GRASS:0)
Block(6,5,-5,DIRT:0)
Block(7,5,-5,DIRT:0)
Block(8,5,-5,DIRT:0)
Block(4,5,-4,GRASS:0)
Block(5,5,-4,DIRT:0)
Block(6,5,-4,DIRT:0)
Block(7,5,-4,DIRT:0)
Block(8,5,-4,DIRT:0)
Block(4,5,-3,DIRT:0)
Block(5,5,-3,DIRT:0)
Block(6,5,-3,DIRT:0)
Block(7,5,-3,DIRT:0)
Block(8,5,-3,DIRT:0)
Block(3,5,-2,GRASS:0)
Block(4,5,-2,DIRT:0)
Block(5,5,-2,DIRT:0)
Block(6,5,-2,DIRT:0)
Block(7,5,-2,DIRT:0)
Block(8,5,-2,STONE:0)
Block(3,5,-1,GRASS:0)
Block(4,5,-1,DIRT:0)
Block(5,5,-1,DIRT:0)
Block(6,5,-1,DIRT:0)
Block(7,5,-1,STONE:0)
Block(8,5,-1,STONE:0)
Block(7,6,-7,DIRT:0)
Block(8,6,-7,DIRT:0)
Block(6,6,-6,GRASS:0)
Block(7,6,-6,DIRT:0)
Block(8,6,-6,DIRT:0)
Block(6,6,-5,DIRT:0)
Block(7,6,-5,DIRT:0)
Block(8,6,-5,DIRT:0)
Block(4,6,-4,LEAVES:7)
Block(5,6,-4,DIRT:0)
Block(6,6,-4,DIRT:0)
Block(7,6,-4,DIRT:0)
Block(8,6,-4,DIRT:0)
Block(3,6,-3,LEAVES:7)
Block(4,6,-3,GRASS:0)
Block(5,6,-3,DIRT:0)
Block(6,6,-3,DIRT:0)
Block(7,6,-3,DIRT:0)
Block(8,6,-3,STONE:0)
Block(3,6,-2,LEAVES:7)
Block(4,6,-2,GRASS:0)
Block(5,6,-2,DIRT:0)
Block(6,6,-2,DIRT:0)
Block(7,6,-2,STONE:0)
Block(8,6,-2,STONE:0)
Block(3,6,-1,LEAVES:7)
Block(4,6,-1,GRASS:0)
Block(5,6,-1,DIRT:0)
Block(6,6,-1,DIRT:0)
Block(7,6,-1,STONE:0)
Block(8,6,-1,STONE:0)
Block(7,7,-7,DIRT:0)
Block(8,7,-7,DIRT:0)
Block(7,7,-6,DIRT:0)
Block(8,7,-6,DIRT:0)
Block(6,7,-5,GRASS:0)
Block(7,7,-5,DIRT:0)
Block(8,7,-5,DIRT:0)
Block(3,7,-4,LEAVES:7)
Block(4,7,-4,LEAVES:7)
Block(5,7,-4,GRASS:0)
Block(6,7,-4,DIRT:0)
Block(7,7,-4,DIRT:0)
Block(8,7,-4,DIRT:0)
Block(3,7,-3,LEAVES:7)
Block(4,7,-3,LEAVES:7)
Block(5,7,-3,DIRT:0)
Block(6,7,-3,DIRT:0)
Block(7,7,-3,STONE:0)
Block(8,7,-3,STONE:0)
Block(3,7,-2,LEAVES:7)
Block(4,7,-2,LEAVES:7)
Block(5,7,-2,DIRT:0)
Block(6,7,-2,DIRT:0)
Block(7,7,-2,STONE:0)
Block(8,7,-2,STONE:0)
Block(4,7,-1,LEAVES:7)
Block(5,7,-1,DIRT:0)
Block(6,7,-1,STONE:0)
Block(7,7,-1,STONE:0)
Block(8,7,-1,STONE:0)
Block(7,8,-7,DIRT:0)
Block(8,8,-7,DIRT:0)
Block(6,8,-6,LEAVES:7)
Block(7,8,-6,DIRT:0)
Block(8,8,-6,DIRT:0)
Block(5,8,-5,LEAVES:7)
Block(6,8,-5,LEAVES:7)
Block(7,8,-5,DIRT:0)
Block(8,8,-5,DIRT:0)
Block(4,8,-4,LEAVES:7)
Block(5,8,-4,LEAVES:7)
Block(6,8,-4,DIRT:0)
Block(7,8,-4,DIRT:0)
Block(8,8,-4,DIRT:0)
Block(3,8,-3,LEAVES:7)
Block(4,8,-3,LEAVES:7)
Block(5,8,-3,GRASS:0)
Block(6,8,-3,STONE:0)
Block(7,8,-3,STONE:0)
Block(8,8,-3,STONE:0)
Block(4,8,-2,LEAVES:7)
Block(5,8,-2,STONE:0)
Block(6,8,-2,STONE:0)
Block(7,8,-2,STONE:0)
Block(8,8,-2,STONE:0)
Block(5,8,-1,STONE:0)
Block(6,8,-1,STONE:0)
Block(7,8,-1,STONE:0)
Block(8,8,-1,STONE:0)
Block(7,9,-7,DIRT:0)
Block(8,9,-7,DIRT:0)
Block(5,9,-6,LEAVES:7)
Block(6,9,-6,LEAVES:7)
Block(7,9,-6,DIRT:0)
Block(8,9,-6,DIRT:0)
Block(5,9,-5,LEAVES:7)
Block(6,9,-5,LEAVES:7)
Block(7,9,-5,DIRT:0)
Block(8,9,-5,DIRT:0)
Block(5,9,-4,LEAVES:7)
Block(6,9,-4,STONE:0)
Block(7,9,-4,DIRT:0)
Block(8,9,-4,STONE:0)
Block(6,9,-3,STONE:0)
Block(7,9,-3,STONE:0)
Block(8,9,-3,STONE:0)
Block(5,9,-2,STONE:0)
Block(6,9,-2,STONE:0)
Block(7,9,-2,STONE:0)
Block(8,9,-2,STONE:0)
Block(5,9,-1,STONE:0)
Block(6,9,-1,STONE:0)
Block(7,9,-1,STONE:0)
Block(8,9,-1,STONE:0)
Block(6,10,-7,LEAVES:7)
Block(7,10,-7,LEAVES:7)
Block(8,10,-7,DIRT:0)
Block(6,10,-6,LEAVES:7)
Block(7,10,-6,DIRT:0)
Block(8,10,-6,DIRT:0)
Block(5,10,-5,LEAVES:7)
Block(6,10,-5,LEAVES:7)
Block(7,10,-5,DIRT:0)
Block(8,10,-5,DIRT:0)
Block(6,10,-4,STONE:0)
Block(7,10,-4,STONE:0)
Block(8,10,-4,STONE:0)
Block(6,10,-3,STONE:0)
Block(7,10,-3,STONE:0)
Block(8,10,-3,STONE:0)
Block(5,10,-2,STONE:0)
Block(6,10,-2,STONE:0)
Block(7,10,-2,STONE:0)
Block(8,10,-2,STONE:0)
Block(5,10,-1,STONE:0)
Block(6,10,-1,STONE:0)
Block(7,10,-1,STONE:0)
Block(8,10,-1,STONE:0)
Block(7,11,-7,LEAVES:7)
Block(8,11,-7,DIRT:0)
Block(6,11,-6,LEAVES:7)
Block(7,11,-6,DIRT:0)
Block(8,11,-6,STONE:0)
Block(7,11,-5,STONE:0)
Block(8,11,-5,STONE:0)
Block(6,11,-4,STONE:0)
Block(7,11,-4,STONE:0)
Block(8,11,-4,STONE:0)
Block(5,11,-3,STONE:0)
Block(6,11,-3,STONE:0)
Block(7,11,-3,STONE:0)
Block(8,11,-3,STONE:0)
Block(5,11,-2,STONE:0)
Block(6,11,-2,STONE:0)
Block(7,11,-2,STONE:0)
Block(8,11,-2,STONE:0)
Block(5,11,-1,STONE:0)
Block(6,11,-1,STONE:0)
Block(7,11,-1,STONE:0)
Block(8,11,-1,STONE:0)
Block(7,12,-7,LEAVES:7)
Block(8,12,-7,DIRT:0)
Block(7,12,-6,STONE:0)
Block(8,12,-6,STONE:0)
Block(6,12,-5,STONE:0)
Block(7,12,-5,STONE:0)
Block(8,12,-5,STONE:0)
Block(6,12,-4,STONE:0)
Block(7,12,-4,STONE:0)
Block(8,12,-4,STONE:0)
Block(5,12,-3,STONE:0)
Block(6,12,-3,STONE:0)
Block(7,12,-3,STONE:0)
Block(8,12,-3,STONE:0)
Block(5,12,-2,STONE:0)
Block(6,12,-2,STONE:0)
Block(7,12,-2,STONE:0)
Block(8,12,-2,STONE:0)
Block(5,12,-1,STONE:0)
Block(6,12,-1,STONE:0)
Block(7,12,-1,STONE:0)
Block(8,12,-1,STONE:0)
Block(8,13,-7,STONE:0)
Block(7,13,-6,STONE:0)
Block(8,13,-6,STONE:0)
Block(6,13,-5,STONE:0)
Block(7,13,-5,STONE:0)
Block(8,13,-5,STONE:0)
Block(6,13,-4,STONE:0)
Block(7,13,-4,STONE:0)
Block(8,13,-4,STONE:0)
Block(5,13,-3,STONE:0)
Block(6,13,-3,STONE:0)
Block(7,13,-3,STONE:0)
Block(8,13,-3,STONE:0)
Block(4,13,-2,STONE:0)
Block(5,13,-2,STONE:0)
Block(6,13,-2,STONE:0)
Block(7,13,-2,STONE:0)
Block(8,13,-2,STONE:0)
Block(4,13,-1,STONE:0)
Block(5,13,-1,STONE:0)
Block(6,13,-1,STONE:0)
Block(7,13,-1,STONE:0)
Block(8,13,-1,STONE:0)
Block(8,14,-7,STONE:0)
Block(7,14,-6,STONE:0)
Block(8,14,-6,STONE:0)
Block(6,14,-5,STONE:0)
Block(7,14,-5,STONE:0)
Block(8,14,-5,STONE:0)
Block(6,14,-4,STONE:0)
Block(7,14,-4,STONE:0)
Block(8,14,-4,STONE:0)
Block(5,14,-3,STONE:0)
Block(6,14,-3,STONE:0)
Block(7,14,-3,STONE:0)
Block(8,14,-3,STONE:0)
Block(4,14,-2,STONE:0)
Block(5,14,-2,STONE:0)
Block(6,14,-2,STONE:0)
Block(7,14,-2,STONE:0)
Block(8,14,-2,STONE:0)
Block(4,14,-1,STONE:0)
Block(5,14,-1,STONE:0)
Block(6,14,-1,STONE:0)
Block(7,14,-1,STONE:0)
Block(8,14,-1,STONE:0)
Block(8,15,-7,STONE:0)
Block(7,15,-6,STONE:0)
Block(8,15,-6,STONE:0)
Block(6,15,-5,STONE:0)
Block(7,15,-5,STONE:0)
Block(8,15,-5,STONE:0)
Block(6,15,-4,STONE:0)
Block(7,15,-4,STONE:0)
Block(8,15,-4,STONE:0)
Block(5,15,-3,STONE:3)
Block(6,15,-3,STONE:0)
Block(7,15,-3,STONE:0)
Block(8,15,-3,STONE:0)
Block(2,15,-2,STONE:3)
Block(3,15,-2,STONE:3)
Block(4,15,-2,STONE:3)
Block(5,15,-2,STONE:0)
Block(6,15,-2,STONE:0)
Block(7,15,-2,STONE:0)
Block(8,15,-2,STONE:0)
Block(2,15,-1,STONE:3)
Block(3,15,-1,STONE:3)
Block(4,15,-1,STONE:0)
Block(5,15,-1,STONE:0)
Block(6,15,-1,STONE:0)
Block(7,15,-1,STONE:0)
Block(8,15,-1,STONE:0)
Block(8,16,-7,STONE:0)
Block(7,16,-6,STONE:0)
Block(8,16,-6,STONE:0)
Block(6,16,-5,STONE:3)
Block(7,16,-5,STONE:0)
Block(8,16,-5,STONE:0)
Block(5,16,-4,STONE:3)
Block(6,16,-4,STONE:0)
Block(7,16,-4,STONE:0)
Block(8,16,-4,STONE:0)
Block(4,16,-3,STONE:3)
Block(5,16,-3,STONE:3)
Block(6,16,-3,STONE:0)
Block(7,16,-3,STONE:0)
Block(8,16,-3,STONE:0)
Block(2,16,-2,STONE:3)
Block(3,16,-2,STONE:3)
Block(4,16,-2,STONE:3)
Block(5,16,-2,STONE:3)
Block(6,16,-2,STONE:0)
Block(7,16,-2,STONE:0)
Block(8,16,-2,STONE:0)
Block(2,16,-1,STONE:3)
Block(3,16,-1,STONE:0)
Block(4,16,-1,STONE:0)
Block(5,16,-1,STONE:0)
Block(6,16,-1,STONE:0)
Block(7,16,-1,STONE:0)
Block(8,16,-1,STONE:0)
Block(7,17,-7,STONE:0)
Block(8,17,-7,STONE:0)
Block(6,17,-6,STONE:3)
Block(7,17,-6,STONE:3)
Block(8,17,-6,STONE:0)
Block(5,17,-5,STONE:3)
Block(6,17,-5,STONE:3)
Block(7,17,-5,STONE:0)
Block(8,17,-5,STONE:0)
Block(5,17,-4,STONE:3)
Block(6,17,-4,STONE:3)
Block(7,17,-4,STONE:0)
Block(8,17,-4,STONE:0)
Block(4,17,-3,STONE:3)
Block(5,17,-3,STONE:3)
Block(6,17,-3,STONE:0)
Block(7,17,-3,STONE:0)
Block(8,17,-3,STONE:0)
Block(2,17,-2,STONE:0)
Block(3,17,-2,STONE:0)
Block(4,17,-2,STONE:3)
Block(5,17,-2,STONE:0)
Block(6,17,-2,STONE:0)
Block(7,17,-2,STONE:0)
Block(8,17,-2,STONE:0)
Block(2,17,-1,STONE:0)
Block(3,17,-1,STONE:0)
Block(4,17,-1,STONE:0)
Block(5,17,-1,STONE:0)
Block(6,17,-1,STONE:0)
Block(7,17,-1,STONE:0)
Block(8,17,-1,STONE:0)
Block(7,18,-7,STONE:3)
Block(8,18,-7,STONE:3)
Block(6,18,-6,STONE:3)
Block(7,18,-6,STONE:3)
Block(8,18,-6,STONE:3)
Block(5,18,-5,STONE:3)
Block(6,18,-5,STONE:3)
Block(7,18,-5,STONE:3)
Block(8,18,-5,STONE:0)
Block(5,18,-4,STONE:3)
Block(6,18,-4,STONE:0)
Block(7,18,-4,STONE:0)
Block(8,18,-4,STONE:0)
Block(4,18,-3,STONE:0)
Block(5,18,-3,STONE:0)
Block(6,18,-3,STONE:0)
Block(7,18,-3,STONE:0)
Block(8,18,-3,STONE:0)
Block(2,18,-2,STONE:0)
Block(3,18,-2,STONE:0)
Block(4,18,-2,STONE:0)
Block(5,18,-2,STONE:0)
Block(6,18,-2,STONE:0)
Block(7,18,-2,STONE:0)
Block(8,18,-2,STONE:0)
Block(2,18,-1,STONE:0)
Block(3,18,-1,STONE:0)
Block(4,18,-1,STONE:0)
Block(5,18,-1,STONE:0)
Block(6,18,-1,STONE:0)
Block(7,18,-1,STONE:0)
Block(8,18,-1,STONE:0)
Block(7,19,-7,STONE:3)
Block(8,19,-7,STONE:3)
Block(6,19,-6,STONE:3)
Block(7,19,-6,STONE:3)
Block(8,19,-6,STONE:3)
Block(5,19,-5,STONE:0)
Block(6,19,-5,STONE:3)
Block(7,19,-5,STONE:0)
Block(8,19,-5,STONE:0)
Block(5,19,-4,STONE:0)
Block(6,19,-4,STONE:0)
Block(7,19,-4,STONE:0)
Block(8,19,-4,STONE:0)
Block(4,19,-3,STONE:0)
Block(5,19,-3,STONE:0)
Block(6,19,-3,STONE:0)
Block(7,19,-3,STONE:0)
Block(8,19,-3,STONE:0)
Block(2,19,-2,STONE:0)
Block(3,19,-2,STONE:0)
Block(4,19,-2,STONE:0)
Block(5,19,-2,STONE:0)
Block(6,19,-2,STONE:0)
Block(7,19,-2,STONE:0)
Block(8,19,-2,STONE:0)
Block(2,19,-1,STONE:0)
Block(3,19,-1,STONE:0)
Block(4,19,-1,STONE:0)
Block(5,19,-1,STONE:0)
Block(6,19,-1,STONE:0)
Block(7,19,-1,STONE:0)
Block(8,19,-1,STONE:0)
Block(7,20,-7,STONE:3)
Block(8,20,-7,STONE:3)
Block(6,20,-6,STONE:0)
Block(7,20,-6,STONE:0)
Block(8,20,-6,STONE:3)
Block(5,20,-5,STONE:0)
Block(6,20,-5,STONE:0)
Block(7,20,-5,STONE:0)
Block(8,20,-5,STONE:0)
Block(5,20,-4,STONE:0)
Block(6,20,-4,STONE:0)
Block(7,20,-4,STONE:0)
Block(8,20,-4,STONE:0)
Block(4,20,-3,STONE:0)
Block(5,20,-3,STONE:0)
Block(6,20,-3,STONE:0)
Block(7,20,-3,STONE:0)
Block(8,20,-3,STONE:0)
Block(2,20,-2,STONE:0)
Block(3,20,-2,STONE:0)
Block(4,20,-2,STONE:0)
Block(5,20,-2,STONE:0)
Block(6,20,-2,STONE:0)
Block(7,20,-2,STONE:0)
Block(8,20,-2,STONE:0)
Block(2,20,-1,STONE:0)
Block(3,20,-1,STONE:0)
Block(4,20,-1,STONE:0)
Block(5,20,-1,STONE:0)
Block(6,20,-1,STONE:0)
Block(7,20,-1,STONE:0)
Block(8,20,-1,STONE:0)
Block(8,21,-7,STONE:0)
Block(7,21,-6,STONE:0)
Block(8,21,-6,STONE:0)
Block(6,21,-5,STONE:0)
Block(7,21,-5,STONE:0)
Block(8,21,-5,STONE:0)
Block(5,21,-4,STONE:0)
Block(6,21,-4,STONE:0)
Block(7,21,-4,STONE:0)
Block(8,21,-4,STONE:0)
Block(5,21,-3,STONE:0)
Block(6,21,-3,STONE:0)
Block(7,21,-3,STONE:0)
Block(8,21,-3,STONE:0)
Block(2,21,-2,DIRT:0)
Block(3,21,-2,DIRT:0)
Block(4,21,-2,DIRT:0)
Block(5,21,-2,DIRT:0)
Block(6,21,-2,STONE:0)
Block(7,21,-2,STONE:0)
Block(8,21,-2,STONE:0)
Block(2,21,-1,DIRT:0)
Block(3,21,-1,DIRT:0)
Block(4,21,-1,DIRT:0)
Block(5,21,-1,STONE:0)
Block(6,21,-1,STONE:0)
Block(7,21,-1,STONE:0)
Block(8,21,-1,STONE:0)
Block(8,22,-7,STONE:0)
Block(7,22,-6,STONE:0)
Block(8,22,-6,STONE:0)
Block(6,22,-5,STONE:0)
Block(7,22,-5,STONE:0)
Block(8,22,-5,STONE:0)
Block(5,22,-4,DIRT:0)
Block(6,22,-4,STONE:0)
Block(7,22,-4,STONE:0)
Block(8,22,-4,STONE:0)
Block(4,22,-3,DIRT:0)
Block(5,22,-3,DIRT:0)
Block(6,22,-3,DIRT:0)
Block(7,22,-3,STONE:0)
Block(8,22,-3,STONE:0)
Block(2,22,-2,DIRT:0)
Block(3,22,-2,DIRT:0)
Block(4,22,-2,DIRT:0)
Block(5,22,-2,DIRT:0)
Block(6,22,-2,DIRT:0)
Block(7,22,-2,STONE:0)
Block(8,22,-2,STONE:0)
Block(2,22,-1,DIRT:0)
Block(3,22,-1,DIRT:0)
Block(4,22,-1,DIRT:0)
Block(5,22,-1,DIRT:0)
Block(6,22,-1,DIRT:0)
Block(7,22,-1,STONE:0)
Block(8,22,-1,STONE:0)
Block(8,23,-7,STONE:0)
Block(7,23,-6,STONE:0)
Block(8,23,-6,STONE:0)
Block(5,23,-5,DIRT:0)
Block(6,23,-5,STONE:0)
Block(7,23,-5,STONE:0)
Block(8,23,-5,STONE:0)
Block(5,23,-4,DIRT:0)
Block(6,23,-4,DIRT:0)
Block(7,23,-4,STONE:0)
Block(8,23,-4,STONE:0)
Block(4,23,-3,DIRT:0)
Block(5,23,-3,DIRT:0)
Block(6,23,-3,DIRT:0)
Block(7,23,-3,STONE:0)
Block(8,23,-3,STONE:0)
Block(3,23,-2,DIRT:0)
Block(4,23,-2,DIRT:0)
Block(5,23,-2,DIRT:0)
Block(6,23,-2,DIRT:0)
Block(7,23,-2,DIRT:0)
Block(8,23,-2,STONE:0)
Block(2,23,-1,DIRT:0)
Block(3,23,-1,DIRT:0)
Block(4,23,-1,DIRT:0)
Block(5,23,-1,DIRT:0)
Block(6,23,-1,DIRT:0)
Block(7,23,-1,STONE:0)
Block(8,23,-1,STONE:0)
Block(8,24,-7,STONE:0)
Block(6,24,-6,STONE:0)
Block(7,24,-6,STONE:0)
Block(8,24,-6,STONE:0)
Block(5,24,-5,DIRT:0)
Block(6,24,-5,DIRT:0)
Block(7,24,-5,STONE:0)
Block(8,24,-5,STONE:0)
Block(4,24,-4,DIRT:0)
Block(5,24,-4,DIRT:0)
Block(6,24,-4,DIRT:0)
Block(7,24,-4,DIRT:0)
Block(8,24,-4,STONE:0)
Block(4,24,-3,DIRT:0)
Block(5,24,-3,DIRT:0)
Block(6,24,-3,DIRT:0)
Block(7,24,-3,DIRT:0)
Block(8,24,-3,STONE:0)
Block(3,24,-2,DIRT:0)
Block(4,24,-2,DIRT:0)
Block(5,24,-2,DIRT:0)
Block(6,24,-2,DIRT:0)
Block(7,24,-2,DIRT:0)
Block(8,24,-2,STONE:0)
Block(2,24,-1,DIRT:0)
Block(3,24,-1,DIRT:0)
Block(4,24,-1,DIRT:0)
Block(5,24,-1,DIRT:0)
Block(6,24,-1,DIRT:0)
Block(7,24,-1,DIRT:0)
Block(8,24,-1,STONE:0)
Block(8,25,-7,DIRT:0)
Block(6,25,-6,DIRT:0)
Block(7,25,-6,DIRT:0)
Block(8,25,-6,STONE:0)
Block(4,25,-5,DIRT:0)
Block(5,25,-5,DIRT:0)
Block(6,25,-5,DIRT:0)
Block(7,25,-5,DIRT:0)
Block(8,25,-5,STONE:0)
Block(4,25,-4,DIRT:0)
Block(5,25,-4,DIRT:0)
Block(6,25,-4,DIRT:0)
Block(7,25,-4,DIRT:0)
Block(8,25,-4,STONE:0)
Block(4,25,-3,DIRT:0)
Block(5,25,-3,DIRT:0)
Block(6,25,-3,DIRT:0)
Block(7,25,-3,DIRT:0)
Block(8,25,-3,DIRT:0)
Block(3,25,-2,DIRT:0)
Block(4,25,-2,DIRT:0)
Block(5,25,-2,DIRT:0)
Block(6,25,-2,DIRT:0)
Block(7,25,-2,DIRT:0)
Block(8,25,-2,STONE:0)
Block(3,25,-1,DIRT:0)
Block(4,25,-1,DIRT:0)
Block(5,25,-1,DIRT:0)
Block(6,25,-1,DIRT:0)
Block(7,25,-1,DIRT:0)
Block(8,25,-1,STONE:0)
Block(8,26,-7,DIRT:0)
Block(6,26,-6,DIRT:0)
Block(7,26,-6,DIRT:0)
Block(8,26,-6,DIRT:0)
Block(4,26,-5,DIRT:0)
Block(5,26,-5,DIRT:0)
Block(6,26,-5,DIRT:0)
Block(7,26,-5,DIRT:0)
Block(8,26,-5,DIRT:0)
Block(4,26,-4,DIRT:0)
Block(5,26,-4,DIRT:0)
Block(6,26,-4,DIRT:0)
Block(7,26,-4,DIRT:0)
Block(8,26,-4,DIRT:0)
Block(4,26,-3,DIRT:0)
Block(5,26,-3,DIRT:0)
Block(6,26,-3,DIRT:0)
Block(7,26,-3,DIRT:0)
Block(8,26,-3,DIRT:0)
Block(3,26,-2,DIRT:0)
Block(4,26,-2,DIRT:0)
Block(5,26,-2,DIRT:0)
Block(6,26,-2,DIRT:0)
Block(7,26,-2,DIRT:0)
Block(8,26,-2,DIRT:0)
Block(2,26,-1,DIRT:0)
Block(3,26,-1,DIRT:0)
Block(4,26,-1,DIRT:0)
Block(5,26,-1,DIRT:0)
Block(6,26,-1,DIRT:0)
Block(7,26,-1,DIRT:0)
Block(8,26,-1,STONE:0)
Block(7,27,-7,DIRT:0)
Block(8,27,-7,DIRT:0)
Block(6,27,-6,DIRT:0)
Block(7,27,-6,DIRT:0)
Block(8,27,-6,DIRT:0)
Block(4,27,-5,DIRT:0)
Block(5,27,-5,DIRT:0)
Block(6,27,-5,DIRT:0)
Block(7,27,-5,DIRT:0)
Block(8,27,-5,DIRT:0)
Block(4,27,-4,DIRT:0)
Block(5,27,-4,DIRT:0)
Block(6,27,-4,DIRT:0)
Block(7,27,-4,DIRT:0)
Block(8,27,-4,DIRT:0)
Block(4,27,-3,DIRT:0)
Block(5,27,-3,DIRT:0)
Block(6,27,-3,DIRT:0)
Block(7,27,-3,DIRT:0)
Block(8,27,-3,DIRT:0)
Block(2,27,-2,DIRT:0)
Block(3,27,-2,DIRT:0)
Block(4,27,-2,DIRT:0)
Block(5,27,-2,DIRT:0)
Block(6,27,-2,DIRT:0)
Block(7,27,-2,DIRT:0)
Block(8,27,-2,DIRT:0)
Block(1,27,-1,DIRT:0)
Block(2,27,-1,DIRT:0)
Block(3,27,-1,DIRT:0)
Block(4,27,-1,DIRT:0)
Block(5,27,-1,DIRT:0)
Block(6,27,-1,DIRT:0)
Block(7,27,-1,DIRT:0)
Block(8,27,-1,DIRT:0)
Block(6,28,-7,DIRT:0)
Block(7,28,-7,DIRT:0)
Block(8,28,-7,DIRT:0)
Block(6,28,-6,DIRT:0)
Block(7,28,-6,DIRT:0)
Block(8,28,-6,DIRT:0)
Block(4,28,-5,DIRT:0)
Block(5,28,-5,DIRT:0)
Block(6,28,-5,DIRT:0)
Block(7,28,-5,DIRT:0)
Block(8,28,-5,DIRT:0)
Block(4,28,-4,DIRT:0)
Block(5,28,-4,DIRT:0)
Block(6,28,-4,DIRT:0)
Block(7,28,-4,DIRT:0)
Block(8,28,-4,DIRT:0)
Block(4,28,-3,DIRT:0)
Block(5,28,-3,DIRT:0)
Block(6,28,-3,DIRT:0)
Block(7,28,-3,DIRT:0)
Block(8,28,-3,DIRT:0)
Block(2,28,-2,DIRT:0)
Block(3,28,-2,DIRT:0)
Block(4,28,-2,DIRT:0)
Block(5,28,-2,DIRT:0)
Block(6,28,-2,DIRT:0)
Block(7,28,-2,DIRT:0)
Block(8,28,-2,DIRT:0)
Block(1,28,-1,DIRT:0)
Block(2,28,-1,DIRT:0)
Block(3,28,-1,DIRT:0)
Block(4,28,-1,DIRT:0)
Block(5,28,-1,DIRT:0)
Block(6,28,-1,DIRT:0)
Block(7,28,-1,DIRT:0)
Block(8,28,-1,STONE:0)
Block(6,29,-7,DIRT:0)
Block(7,29,-7,DIRT:0)
Block(8,29,-7,DIRT:0)
Block(6,29,-6,DIRT:0)
Block(7,29,-6,DIRT:0)
Block(8,29,-6,DIRT:0)
Block(5,29,-5,DIRT:0)
Block(6,29,-5,DIRT:0)
Block(7,29,-5,DIRT:0)
Block(8,29,-5,DIRT:0)
Block(4,29,-4,DIRT:0)
Block(5,29,-4,DIRT:0)
Block(6,29,-4,DIRT:0)
Block(7,29,-4,DIRT:0)
Block(8,29,-4,DIRT:0)
Block(4,29,-3,DIRT:0)
Block(5,29,-3,DIRT:0)
Block(6,29,-3,DIRT:0)
Block(7,29,-3,DIRT:0)
Block(8,29,-3,DIRT:0)
Block(2,29,-2,DIRT:0)
Block(3,29,-2,DIRT:0)
Block(4,29,-2,DIRT:0)
Block(5,29,-2,DIRT:0)
Block(6,29,-2,DIRT:0)
Block(7,29,-2,DIRT:0)
Block(8,29,-2,DIRT:0)
Block(2,29,-1,DIRT:0)
Block(3,29,-1,DIRT:0)
Block(4,29,-1,DIRT:0)
Block(5,29,-1,DIRT:0)
Block(6,29,-1,DIRT:0)
Block(7,29,-1,DIRT:0)
Block(8,29,-1,STONE:0)
Block(6,30,-7,DIRT:0)
Block(7,30,-7,DIRT:0)
Block(8,30,-7,DIRT:0)
Block(5,30,-6,DIRT:0)
Block(6,30,-6,DIRT:0)
Block(7,30,-6,DIRT:0)
Block(8,30,-6,DIRT:0)
Block(4,30,-5,DIRT:0)
Block(5,30,-5,DIRT:0)
Block(6,30,-5,DIRT:0)
Block(7,30,-5,DIRT:0)
Block(8,30,-5,DIRT:0)
Block(4,30,-4,DIRT:0)
Block(5,30,-4,DIRT:0)
Block(6,30,-4,DIRT:0)
Block(7,30,-4,DIRT:0)
Block(8,30,-4,DIRT:0)
Block(4,30,-3,DIRT:0)
Block(5,30,-3,DIRT:0)
Block(6,30,-3,DIRT:0)
Block(7,30,-3,DIRT:0)
Block(8,30,-3,DIRT:0)
Block(2,30,-2,DIRT:0)
Block(3,30,-2,DIRT:0)
Block(4,30,-2,DIRT:0)
Block(5,30,-2,DIRT:0)
Block(6,30,-2,DIRT:0)
Block(7,30,-2,DIRT:0)
Block(8,30,-2,DIRT:0)
Block(2,30,-1,DIRT:0)
Block(3,30,-1,DIRT:0)
Block(4,30,-1,DIRT:0)
Block(5,30,-1,DIRT:0)
Block(6,30,-1,DIRT:0)
Block(7,30,-1,DIRT:0)
Block(8,30,-1,STONE:0)
Block(6,31,-7,GRASS:0)
Block(7,31,-7,DIRT:0)
Block(8,31,-7,DIRT:0)
Block(5,31,-6,DIRT:0)
Block(6,31,-6,DIRT:0)
Block(7,31,-6,DIRT:0)
Block(8,31,-6,DIRT:0)
Block(4,31,-5,DIRT:0)
Block(5,31,-5,DIRT:0)
Block(6,31,-5,DIRT:0)
Block(7,31,-5,DIRT:0)
Block(8,31,-5,DIRT:0)
Block(4,31,-4,DIRT:0)
Block(5,31,-4,DIRT:0)
Block(6,31,-4,DIRT:0)
Block(7,31,-4,DIRT:0)
Block(8,31,-4,DIRT:0)
Block(4,31,-3,DIRT:0)
Block(5,31,-3,DIRT:0)
Block(6,31,-3,DIRT:0)
Block(7,31,-3,DIRT:0)
Block(8,31,-3,DIRT:0)
Block(3,31,-2,DIRT:0)
Block(4,31,-2,DIRT:0)
Block(5,31,-2,DIRT:0)
Block(6,31,-2,DIRT:0)
Block(7,31,-2,DIRT:0)
Block(8,31,-2,STONE:0)
Block(3,31,-1,DIRT:0)
Block(4,31,-1,DIRT:0)
Block(5,31,-1,DIRT:0)
Block(6,31,-1,DIRT:0)
Block(7,31,-1,STONE:0)
Block(8,31,-1,STONE:0)
Block(5,32,-7,LEAVES:7)
Block(6,32,-7,LEAVES:7)
Block(7,32,-7,DIRT:0)
Block(8,32,-7,DIRT:0)
Block(4,32,-6,LEAVES:7)
Block(5,32,-6,DIRT:0)
Block(6,32,-6,DIRT:0)
Block(7,32,-6,DIRT:0)
Block(8,32,-6,DIRT:0)
Block(4,32,-5,GRASS:0)
Block(5,32,-5,DIRT:0)
Block(6,32,-5,DIRT:0)
Block(7,32,-5,DIRT:0)
Block(8,32,-5,DIRT:0)
Block(4,32,-4,DIRT:0)
Block(5,32,-4,DIRT:0)
Block(6,32,-4,DIRT:0)
Block(7,32,-4,DIRT:0)
Block(8,32,-4,DIRT:0)
Block(4,32,-3,DIRT:0)
Block(5,32,-3,DIRT:0)
Block(6,32,-3,DIRT:0)
Block(7,32,-3,DIRT:0)
Block(8,32,-3,STONE:0)
Block(3,32,-2,DIRT:0)
Block(4,32,-2,DIRT:0)
Block(5,32,-2,DIRT:0)
Block(6,32,-2,DIRT:0)
Block(7,32,-2,STONE:0)
Block(8,32,-2,STONE:0)
Block(3,32,-1,DIRT:0)
Block(4,32,-1,DIRT:0)
Block(5,32,-1,DIRT:0)
Block(6,32,-1,STONE:0)
Block(7,32,-1,STONE:0)
Block(8,32,-1,STONE:0)
Block(4,33,-7,LEAVES:7)
Block(5,33,-7,LEAVES:7)
Block(6,33,-7,LEAVES:7)
Block(7,33,-7,DIRT:0)
Block(8,33,-7,DIRT:0)
Block(4,33,-6,LEAVES:7)
Block(5,33,-6,DIRT:0)
Block(6,33,-6,DIRT:0)
Block(7,33,-6,DIRT:0)
Block(8,33,-6,DIRT:0)
Block(3,33,-5,LEAVES:7)
Block(4,33,-5,LEAVES:7)
Block(5,33,-5,DIRT:0)
Block(6,33,-5,DIRT:0)
Block(7,33,-5,DIRT:0)
Block(8,33,-5,DIRT:0)
Block(4,33,-4,GRASS:0)
Block(5,33,-4,DIRT:0)
Block(6,33,-4,DIRT:0)
Block(7,33,-4,DIRT:0)
Block(8,33,-4,DIRT:0)
Block(4,33,-3,DIRT:0)
Block(5,33,-3,DIRT:0)
Block(6,33,-3,DIRT:0)
Block(7,33,-3,STONE:0)
Block(8,33,-3,STONE:0)
Block(3,33,-2,DIRT:0)
Block(4,33,-2,DIRT:0)
Block(5,33,-2,STONE:0)
Block(6,33,-2,STONE:0)
Block(7,33,-2,STONE:0)
Block(8,33,-2,STONE:0)
Block(3,33,-1,DIRT:0)
Block(4,33,-1,STONE:0)
Block(5,33,-1,STONE:0)
Block(6,33,-1,STONE:0)
Block(7,33,-1,STONE:0)
Block(8,33,-1,STONE:0)
Block(5,34,-7,LEAVES:7)
Block(6,34,-7,LEAVES:7)
Block(7,34,-7,DIRT:0)
Block(8,34,-7,DIRT:0)
Block(3,34,-6,LEAVES:7)
Block(4,34,-6,LEAVES:7)
Block(5,34,-6,GRASS:0)
Block(6,34,-6,DIRT:0)
Block(7,34,-6,DIRT:0)
Block(8,34,-6,DIRT:0)
Block(3,34,-5,LEAVES:7)
Block(4,34,-5,LEAVES:7)
Block(5,34,-5,DIRT:0)
Block(6,34,-5,DIRT:0)
Block(7,34,-5,DIRT:0)
Block(8,34,-5,DIRT:0)
Block(3,34,-4,LEAVES:7)
Block(4,34,-4,LEAVES:7)
Block(5,34,-4,DIRT:0)
Block(6,34,-4,DIRT:0)
Block(7,34,-4,DIRT:0)
Block(8,34,-4,STONE:0)
Block(4,34,-3,STONE:0)
Block(5,34,-3,STONE:0)
Block(6,34,-3,STONE:0)
Block(7,34,-3,STONE:0)
Block(8,34,-3,STONE:0)
Block(3,34,-2,STONE:0)
Block(4,34,-2,STONE:0)
Block(5,34,-2,STONE:0)
Block(6,34,-2,STONE:0)
Block(7,34,-2,STONE:0)
Block(8,34,-2,STONE:0)
Block(3,34,-1,STONE:0)
Block(4,34,-1,STONE:0)
Block(5,34,-1,STONE:0)
Block(6,34,-1,STONE:0)
Block(7,34,-1,STONE:0)
Block(8,34,-1,STONE:0)
Block(7,35,-7,DIRT:0)
Block(8,35,-7,DIRT:0)
Block(4,35,-6,LEAVES:7)
Block(5,35,-6,LEAVES:7)
Block(6,35,-6,DIRT:0)
Block(7,35,-6,DIRT:0)
Block(8,35,-6,STONE:0)
Block(3,35,-5,LEAVES:7)
Block(4,35,-5,LEAVES:7)
Block(5,35,-5,STONE:0)
Block(6,35,-5,DIRT:0)
Block(7,35,-5,STONE:0)
Block(8,35,-5,STONE:0)
Block(4,35,-4,LEAVES:7)
Block(5,35,-4,STONE:0)
Block(6,35,-4,STONE:0)
Block(7,35,-4,STONE:0)
Block(8,35,-4,STONE:0)
Block(4,35,-3,STONE:3)
Block(5,35,-3,STONE:3)
Block(6,35,-3,STONE:0)
Block(7,35,-3,STONE:0)
Block(8,35,-3,STONE:0)
Block(3,35,-2,STONE:0)
Block(4,35,-2,STONE:3)
Block(5,35,-2,STONE:0)
Block(6,35,-2,STONE:0)
Block(7,35,-2,STONE:0)
Block(8,35,-2,STONE:0)
Block(3,35,-1,STONE:0)
Block(4,35,-1,STONE:0)
Block(5,35,-1,STONE:0)
Block(6,35,-1,STONE:0)
Block(7,35,-1,STONE:0)
Block(8,35,-1,STONE:0)
Block(7,36,-7,STONE:3)
Block(8,36,-7,DIRT:0)
Block(5,36,-6,LEAVES:7)
Block(6,36,-6,STONE:3)
Block(7,36,-6,STONE:3)
Block(8,36,-6,STONE:0)
Block(4,36,-5,LEAVES:7)
Block(5,36,-5,LEAVES:7)
Block(6,36,-5,STONE:3)
Block(7,36,-5,STONE:3)
Block(8,36,-5,STONE:0)
Block(4,36,-4,LEAVES:7)
Block(5,36,-4,STONE:3)
Block(6,36,-4,STONE:3)
Block(7,36,-4,STONE:0)
Block(8,36,-4,STONE:0)
Block(4,36,-3,STONE:3)
Block(5,36,-3,STONE:3)
Block(6,36,-3,STONE:0)
Block(7,36,-3,STONE:0)
Block(8,36,-3,STONE:0)
Block(3,36,-2,STONE:3)
Block(4,36,-2,STONE:3)
Block(5,36,-2,STONE:3)
Block(6,36,-2,STONE:0)
Block(7,36,-2,STONE:0)
Block(8,36,-2,STONE:0)
Block(2,36,-1,STONE:3)
Block(3,36,-1,STONE:3)
Block(4,36,-1,STONE:0)
Block(5,36,-1,STONE:0)
Block(6,36,-1,STONE:0)
Block(7,36,-1,STONE:0)
Block(8,36,-1,STONE:0)
Block(7,37,-7,STONE:3)
Block(8,37,-7,STONE:3)
Block(4,37,-6,LEAVES:7)
Block(5,37,-6,LEAVES:7)
Block(6,37,-6,STONE:3)
Block(7,37,-6,STONE:3)
Block(8,37,-6,STONE:3)
Block(3,37,-5,LEAVES:7)
Block(4,37,-5,LEAVES:7)
Block(5,37,-5,LEAVES:7)
Block(6,37,-5,STONE:3)
Block(7,37,-5,STONE:3)
Block(8,37,-5,STONE:0)
Block(4,37,-4,LEAVES:7)
Block(5,37,-4,STONE:3)
Block(6,37,-4,STONE:3)
Block(7,37,-4,STONE:0)
Block(8,37,-4,STONE:0)
Block(3,37,-3,GRASS:0)
Block(4,37,-3,STONE:3)
Block(5,37,-3,STONE:3)
Block(6,37,-3,STONE:3)
Block(7,37,-3,STONE:0)
Block(8,37,-3,STONE:0)
Block(2,37,-2,STONE:3)
Block(3,37,-2,STONE:3)
Block(4,37,-2,STONE:3)
Block(5,37,-2,STONE:0)
Block(6,37,-2,STONE:0)
Block(7,37,-2,STONE:0)
Block(8,37,-2,STONE:0)
Block(2,37,-1,STONE:3)
Block(3,37,-1,STONE:3)
Block(4,37,-1,STONE:3)
Block(5,37,-1,STONE:0)
Block(6,37,-1,STONE:0)
Block(7,37,-1,STONE:0)
Block(8,37,-1,STONE:0)
Block(7,38,-7,STONE:3)
Block(8,38,-7,STONE:3)
Block(3,38,-6,LEAVES:7)
Block(4,38,-6,LEAVES:7)
Block(5,38,-6,LEAVES:7)
Block(6,38,-6,STONE:3)
Block(7,38,-6,STONE:3)
Block(8,38,-6,STONE:0)
Block(3,38,-5,LEAVES:7)
Block(4,38,-5,LEAVES:7)
Block(5,38,-5,LEAVES:7)
Block(6,38,-5,STONE:3)
Block(7,38,-5,STONE:0)
Block(8,38,-5,STONE:0)
Block(3,38,-4,LEAVES:7)
Block(4,38,-4,LEAVES:7)
Block(5,38,-4,STONE:3)
Block(6,38,-4,STONE:3)
Block(7,38,-4,STONE:0)
Block(8,38,-4,STONE:0)
Block(4,38,-3,STONE:0)
Block(5,38,-3,STONE:3)
Block(6,38,-3,STONE:0)
Block(7,38,-3,STONE:0)
Block(8,38,-3,STONE:0)
Block(3,38,-2,STONE:3)
Block(4,38,-2,STONE:3)
Block(5,38,-2,STONE:0)
Block(6,38,-2,STONE:0)
Block(7,38,-2,STONE:0)
Block(8,38,-2,STONE:0)
Block(2,38,-1,STONE:3)
Block(3,38,-1,STONE:3)
Block(4,38,-1,STONE:0)
Block(5,38,-1,STONE:0)
Block(6,38,-1,STONE:0)
Block(7,38,-1,STONE:0)
Block(8,38,-1,STONE:0)
Block(6,39,-7,LEAVES:7)
Block(7,39,-7,STONE:0)
Block(8,39,-7,STONE:3)
Block(4,39,-6,LEAVES:7)
Block(5,39,-6,LEAVES:7)
Block(6,39,-6,STONE:0)
Block(7,39,-6,STONE:0)
Block(8,39,-6,STONE:0)
Block(3,39,-5,LEAVES:7)
Block(4,39,-5,LEAVES:7)
Block(5,39,-5,STONE:0)
Block(6,39,-5,STONE:0)
Block(7,39,-5,STONE:0)
Block(8,39,-5,STONE:0)
Block(4,39,-4,STONE:0)
Block(5,39,-4,STONE:0)
Block(6,39,-4,STONE:0)
Block(7,39,-4,STONE:0)
Block(8,39,-4,STONE:0)
Block(4,39,-3,STONE:0)
Block(5,39,-3,STONE:0)
Block(6,39,-3,STONE:0)
Block(7,39,-3,STONE:0)
Block(8,39,-3,STONE:0)
Block(3,39,-2,STONE:0)
Block(4,39,-2,STONE:0)
Block(5,39,-2,STONE:0)
Block(6,39,-2,STONE:0)
Block(7,39,-2,STONE:0)
Block(8,39,-2,STONE:0)
Block(3,39,-1,STONE:0)
Block(4,39,-1,STONE:0)
Block(5,39,-1,STONE:0)
Block(6,39,-1,STONE:0)
Block(7,39,-1,STONE:0)
Block(8,39,-1,STONE:0)
Block(6,40,-7,LEAVES:7)
Block(7,40,-7,STONE:0)
Block(8,40,-7,STONE:0)
Block(5,40,-6,LEAVES:7)
Block(6,40,-6,STONE:0)
Block(7,40,-6,STONE:0)
Block(8,40,-6,STONE:0)
Block(4,40,-5,LEAVES:7)
Block(5,40,-5,STONE:0)
Block(6,40,-5,STONE:0)
Block(7,40,-5,STONE:0)
Block(8,40,-5,STONE:0)
Block(4,40,-4,STONE:0)
Block(5,40,-4,STONE:0)
Block(6,40,-4,STONE:0)
Block(7,40,-4,STONE:0)
Block(8,40,-4,STONE:0)
Block(4,40,-3,STONE:0)
Block(5,40,-3,STONE:0)
Block(6,40,-3,STONE:0)
Block(7,40,-3,STONE:0)
Block(8,40,-3,STONE:0)
Block(3,40,-2,STONE:0)
Block(4,40,-2,STONE:0)
Block(5,40,-2,STONE:0)
Block(6,40,-2,STONE:0)
Block(7,40,-2,STONE:0)
Block(8,40,-2,STONE:0)
Block(3,40,-1,STONE:0)
Block(4,40,-1,STONE:0)
Block(5,40,-1,STONE:0)
Block(6,40,-1,STONE:0)
Block(7,40,-1,STONE:0)
Block(8,40,-1,STONE:0)
Block(5,41,-7,LEAVES:7)
Block(6,41,-7,LEAVES:7)
Block(7,41,-7,STONE:0)
Block(8,41,-7,STONE:0)
Block(3,41,-6,LEAVES:7)
Block(4,41,-6,LEAVES:7)
Block(5,41,-6,LEAVES:7)
Block(6,41,-6,STONE:0)
Block(7,41,-6,STONE:0)
Block(8,41,-6,STONE:0)
Block(2,41,-5,LEAVES:7)
Block(3,41,-5,LEAVES:7)
Block(4,41,-5,LEAVES:7)
Block(5,41,-5,STONE:0)
Block(6,41,-5,STONE:0)
Block(7,41,-5,STONE:0)
Block(8,41,-5,STONE:0)
Block(3,41,-4,LEAVES:7)
Block(4,41,-4,STONE:0)
Block(5,41,-4,STONE:0)
Block(6,41,-4,STONE:0)
Block(7,41,-4,STONE:0)
Block(8,41,-4,STONE:0)
Block(4,41,-3,STONE:0)
Block(5,41,-3,STONE:0)
Block(6,41,-3,STONE:0)
Block(7,41,-3,STONE:0)
Block(8,41,-3,STONE:0)
Block(4,41,-2,STONE:0)
Block(5,41,-2,STONE:0)
Block(6,41,-2,STONE:0)
Block(7,41,-2,STONE:0)
Block(8,41,-2,STONE:0)
Block(4,41,-1,STONE:0)
Block(5,41,-1,STONE:0)
Block(6,41,-1,STONE:0)
Block(7,41,-1,STONE:0)
Block(8,41,-1,STONE:0)
Block(3,42,-7,LEAVES:7)
Block(4,42,-7,LEAVES:7)
Block(5,42,-7,LEAVES:7)
Block(6,42,-7,LEAVES:7)
Block(8,42,-7,STONE:0)
Block(2,42,-6,LEAVES:7)
Block(3,42,-6,LEAVES:7)
Block(4,42,-6,LEAVES:7)
Block(5,42,-6,LEAVES:7)
Block(6,42,-6,STONE:0)
Block(7,42,-6,STONE:0)
Block(8,42,-6,STONE:0)
Block(2,42,-5,LEAVES:7)
Block(3,42,-5,LEAVES:7)
Block(4,42,-5,LEAVES:7)
Block(5,42,-5,STONE:0)
Block(6,42,-5,STONE:0)
Block(7,42,-5,STONE:0)
Block(8,42,-5,STONE:0)
Block(2,42,-4,LEAVES:7)
Block(3,42,-4,LEAVES:7)
Block(4,42,-4,STONE:0)
Block(5,42,-4,STONE:0)
Block(6,42,-4,STONE:0)
Block(7,42,-4,STONE:0)
Block(8,42,-4,STONE:0)
Block(3,42,-3,LEAVES:7)
Block(4,42,-3,STONE:0)
Block(5,42,-3,STONE:0)
Block(6,42,-3,STONE:0)
Block(7,42,-3,STONE:0)
Block(8,42,-3,STONE:0)
Block(4,42,-2,STONE:0)
Block(5,42,-2,STONE:0)
Block(6,42,-2,STONE:0)
Block(7,42,-2,STONE:0)
Block(8,42,-2,STONE:0)
Block(4,42,-1,STONE:0)
Block(5,42,-1,STONE:0)
Block(6,42,-1,STONE:0)
Block(7,42,-1,STONE:0)
Block(8,42,-1,STONE:0)
Block(2,43,-7,LEAVES:7)
Block(3,43,-7,LEAVES:7)
Block(4,43,-7,LEAVES:7)
Block(5,43,-7,LEAVES:7)
Block(6,43,-7,LEAVES:7)
Block(7,43,-7,STONE:0)
Block(8,43,-7,STONE:0)
Block(2,43,-6,LEAVES:7)
Block(3,43,-6,LEAVES:7)
Block(4,43,-6,LEAVES:7)
Block(5,43,-6,LEAVES:7)
Block(6,43,-6,STONE:0)
Block(7,43,-6,STONE:0)
Block(8,43,-6,STONE:0)
Block(2,43,-5,LEAVES:7)
Block(3,43,-5,LEAVES:7)
Block(4,43,-5,LEAVES:7)
Block(5,43,-5,LEAVES:7)
Block(6,43,-5,STONE:0)
Block(7,43,-5,STONE:0)
Block(8,43,-5,STONE:0)
Block(3,43,-4,LEAVES:7)
Block(4,43,-4,STONE:0)
Block(5,43,-4,STONE:0)
Block(6,43,-4,STONE:0)
Block(7,43,-4,STONE:0)
Block(8,43,-4,STONE:0)
Block(4,43,-3,STONE:0)
Block(5,43,-3,STONE:0)
Block(6,43,-3,STONE:0)
Block(7,43,-3,STONE:0)
Block(8,43,-3,STONE:0)
Block(4,43,-2,STONE:0)
Block(5,43,-2,STONE:0)
Block(6,43,-2,STONE:0)
Block(7,43,-2,STONE:0)
Block(8,43,-2,STONE:0)
Block(4,43,-1,STONE:0)
Block(5,43,-1,STONE:0)
Block(6,43,-1,STONE:0)
Block(7,43,-1,STONE:0)
Block(8,43,-1,STONE:0)
Block(3,44,-7,LEAVES:7)
Block(4,44,-7,LEAVES:7)
Block(5,44,-7,LEAVES:7)
Block(6,44,-7,LEAVES:7)
Block(7,44,-7,STONE:0)
Block(8,44,-7,STONE:0)
Block(2,44,-6,LEAVES:7)
Block(3,44,-6,LEAVES:7)
Block(4,44,-6,LEAVES:7)
Block(5,44,-6,LEAVES:7)
Block(6,44,-6,STONE:0)
Block(7,44,-6,STONE:0)
Block(8,44,-6,STONE:0)
Block(3,44,-5,LEAVES:7)
Block(6,44,-5,STONE:0)
Block(7,44,-5,STONE:0)
Block(8,44,-5,STONE:0)
Block(5,44,-4,STONE:0)
Block(6,44,-4,STONE:0)
Block(7,44,-4,STONE:0)
Block(8,44,-4,STONE:0)
Block(4,44,-3,STONE:0)
Block(5,44,-3,STONE:0)
Block(6,44,-3,STONE:0)
Block(7,44,-3,STONE:0)
Block(8,44,-3,STONE:0)
Block(4,44,-2,STONE:0)
Block(5,44,-2,STONE:0)
Block(6,44,-2,STONE:0)
Block(7,44,-2,STONE:0)
Block(8,44,-2,STONE:0)
Block(4,44,-1,STONE:0)
Block(5,44,-1,STONE:0)
Block(6,44,-1,STONE:0)
Block(7,44,-1,STONE:0)
Block(8,44,-1,STONE:0)
Block(7,45,-7,STONE:0)
Block(8,45,-7,STONE:0)
Block(4,45,-6,LEAVES:7)
Block(5,45,-6,LEAVES:7)
Block(6,45,-6,STONE:0)
Block(7,45,-6,STONE:0)
Block(8,45,-6,STONE:0)
Block(3,45,-5,LEAVES:7)
Block(4,45,-5,LEAVES:7)
Block(5,45,-5,LEAVES:7)
Block(6,45,-5,STONE:0)
Block(7,45,-5,STONE:0)
Block(8,45,-5,STONE:0)
Block(4,45,-4,LEAVES:7)
Block(5,45,-4,STONE:0)
Block(6,45,-4,STONE:0)
Block(7,45,-4,STONE:0)
Block(8,45,-4,STONE:0)
Block(4,45,-3,STONE:0)
Block(5,45,-3,STONE:0)
Block(6,45,-3,STONE:0)
Block(7,45,-3,STONE:0)
Block(8,45,-3,STONE:0)
Block(4,45,-2,STONE:0)
Block(5,45,-2,STONE:0)
Block(6,45,-2,STONE:0)
Block(7,45,-2,STONE:0)
Block(8,45,-2,STONE:0)
Block(4,45,-1,STONE:0)
Block(5,45,-1,STONE:0)
Block(6,45,-1,STONE:0)
Block(7,45,-1,STONE:0)
Block(8,45,-1,STONE:0)
Block(7,46,-7,STONE:0)
Block(8,46,-7,STONE:0)
Block(3,46,-6,LEAVES:7)
Block(4,46,-6,LEAVES:7)
Block(5,46,-6,LEAVES:7)
Block(6,46,-6,STONE:0)
Block(7,46,-6,STONE:0)
Block(8,46,-6,STONE:0)
Block(3,46,-5,LEAVES:7)
Block(4,46,-5,LEAVES:7)
Block(5,46,-5,LEAVES:7)
Block(6,46,-5,STONE:0)
Block(7,46,-5,STONE:0)
Block(8,46,-5,STONE:0)
Block(3,46,-4,LEAVES:7)
Block(4,46,-4,LEAVES:7)
Block(5,46,-4,STONE:0)
Block(6,46,-4,STONE:0)
Block(7,46,-4,STONE:0)
Block(8,46,-4,STONE:0)
Block(4,46,-3,STONE:0)
Block(5,46,-3,STONE:0)
Block(6,46,-3,STONE:0)
Block(7,46,-3,STONE:0)
Block(8,46,-3,STONE:0)
Block(4,46,-2,STONE:0)
Block(5,46,-2,STONE:0)
Block(6,46,-2,STONE:0)
Block(7,46,-2,STONE:0)
Block(8,46,-2,STONE:0)
Block(4,46,-1,STONE:0)
Block(5,46,-1,STONE:0)
Block(6,46,-1,STONE:0)
Block(7,46,-1,STONE:0)
Block(8,46,-1,STONE:0)
Block(6,47,-7,STONE:0)
Block(7,47,-7,STONE:0)
Block(8,47,-7,STONE:0)
Block(3,47,-6,LEAVES:7)
Block(4,47,-6,LEAVES:7)
Block(5,47,-6,LEAVES:7)
Block(6,47,-6,STONE:0)
Block(7,47,-6,STONE:0)
Block(8,47,-6,STONE:0)
Block(2,47,-5,LEAVES:7)
Block(3,47,-5,LEAVES:7)
Block(4,47,-5,LEAVES:7)
Block(5,47,-5,STONE:0)
Block(6,47,-5,STONE:0)
Block(7,47,-5,STONE:0)
Block(8,47,-5,STONE:0)
Block(3,47,-4,LEAVES:7)
Block(4,47,-4,STONE:0)
Block(5,47,-4,STONE:0)
Block(6,47,-4,STONE:0)
Block(7,47,-4,STONE:0)
Block(8,47,-4,STONE:0)
Block(4,47,-3,STONE:0)
Block(5,47,-3,STONE:0)
Block(6,47,-3,STONE:0)
Block(7,47,-3,STONE:0)
Block(8,47,-3,STONE:0)
Block(4,47,-2,STONE:0)
Block(5,47,-2,STONE:0)
Block(6,47,-2,STONE:0)
Block(7,47,-2,STONE:0)
Block(8,47,-2,STONE:0)
Block(4,47,-1,STONE:0)
Block(5,47,-1,STONE:0)
Block(6,47,-1,STONE:0)
Block(7,47,-1,STONE:0)
Block(8,47,-1,STONE:0)
Block(5,48,-7,STONE:0)
Block(6,48,-7,STONE:0)
Block(7,48,-7,STONE:0)
Block(8,48,-7,DIRT:0)
Block(2,48,-6,LEAVES:7)
Block(3,48,-6,LEAVES:7)
Block(4,48,-6,LEAVES:7)
Block(5,48,-6,STONE:0)
Block(6,48,-6,STONE:0)
Block(7,48,-6,STONE:0)
Block(8,48,-6,STONE:0)
Block(2,48,-5,LEAVES:7)
Block(3,48,-5,LEAVES:7)
Block(4,48,-5,LEAVES:7)
Block(5,48,-5,STONE:0)
Block(6,48,-5,STONE:0)
Block(7,48,-5,STONE:0)
Block(8,48,-5,STONE:0)
Block(2,48,-4,LEAVES:7)
Block(3,48,-4,LEAVES:7)
Block(4,48,-4,STONE:0)
Block(5,48,-4,STONE:0)
Block(6,48,-4,STONE:0)
Block(7,48,-4,STONE:0)
Block(8,48,-4,STONE:0)
Block(3,48,-3,LEAVES:7)
Block(4,48,-3,STONE:0)
Block(5,48,-3,STONE:0)
Block(6,48,-3,STONE:0)
Block(7,48,-3,STONE:0)
Block(8,48,-3,STONE:0)
Block(4,48,-2,STONE:0)
Block(5,48,-2,STONE:0)
Block(6,48,-2,STONE:0)
Block(7,48,-2,STONE:0)
Block(8,48,-2,STONE:0)
Block(4,48,-1,STONE:0)
Block(5,48,-1,STONE:0)
Block(6,48,-1,STONE:0)
Block(7,48,-1,STONE:0)
Block(8,48,-1,STONE:0)
Block(5,49,-7,GRASS:0)
Block(6,49,-7,DIRT:0)
Block(7,49,-7,DIRT:0)
Block(8,49,-7,DIRT:0)
Block(3,49,-6,LEAVES:7)
Block(4,49,-6,LEAVES:7)
Block(5,49,-6,STONE:0)
Block(6,49,-6,DIRT:0)
Block(7,49,-6,STONE:0)
Block(8,49,-6,STONE:0)
Block(2,49,-5,LEAVES:7)
Block(3,49,-5,LEAVES:7)
Block(4,49,-5,LEAVES:7)
Block(5,49,-5,STONE:0)
Block(6,49,-5,STONE:0)
Block(7,49,-5,STONE:0)
Block(8,49,-5,STONE:0)
Block(3,49,-4,LEAVES:7)
Block(4,49,-4,STONE:0)
Block(5,49,-4,STONE:0)
Block(6,49,-4,STONE:0)
Block(7,49,-4,STONE:0)
Block(8,49,-4,STONE:0)
Block(4,49,-3,STONE:0)
Block(5,49,-3,STONE:0)
Block(6,49,-3,STONE:0)
Block(7,49,-3,STONE:0)
Block(8,49,-3,STONE:0)
Block(3,49,-2,STONE:0)
Block(4,49,-2,STONE:0)
Block(5,49,-2,STONE:0)
Block(6,49,-2,STONE:0)
Block(7,49,-2,STONE:0)
Block(8,49,-2,STONE:0)
Block(3,49,-1,STONE:0)
Block(4,49,-1,STONE:0)
Block(5,49,-1,STONE:0)
Block(6,49,-1,STONE:0)
Block(7,49,-1,STONE:0)
Block(8,49,-1,STONE:0)
Block(6,50,-7,DIRT:0)
Block(7,50,-7,DIRT:0)
Block(8,50,-7,DIRT:0)
Block(3,50,-6,LEAVES:7)
Block(4,50,-6,LEAVES:7)
Block(5,50,-6,DIRT:0)
Block(6,50,-6,DIRT:0)
Block(7,50,-6,DIRT:0)
Block(8,50,-6,STONE:0)
Block(3,50,-5,LEAVES:7)
Block(4,50,-5,LEAVES:7)
Block(5,50,-5,STONE:0)
Block(6,50,-5,STONE:0)
Block(7,50,-5,STONE:0)
Block(8,50,-5,STONE:0)
Block(3,50,-4,LEAVES:7)
Block(4,50,-4,STONE:0)
Block(5,50,-4,STONE:0)
Block(6,50,-4,STONE:0)
Block(7,50,-4,STONE:0)
Block(8,50,-4,STONE:0)
Block(4,50,-3,STONE:0)
Block(5,50,-3,STONE:0)
Block(6,50,-3,STONE:0)
Block(7,50,-3,STONE:0)
Block(8,50,-3,STONE:0)
Block(3,50,-2,STONE:0)
Block(4,50,-2,STONE:0)
Block(5,50,-2,STONE:0)
Block(6,50,-2,STONE:0)
Block(7,50,-2,STONE:0)
Block(8,50,-2,STONE:0)
Block(3,50,-1,STONE:0)
Block(4,50,-1,STONE:0)
Block(5,50,-1,STONE:0)
Block(6,50,-1,STONE:0)
Block(7,50,-1,STONE:0)
Block(8,50,-1,STONE:0)
Block(6,51,-7,DIRT:0)
Block(7,51,-7,DIRT:0)
Block(8,51,-7,STONE:0)
Block(4,51,-6,LEAVES:7)
Block(5,51,-6,GRASS:0)
Block(6,51,-6,DIRT:0)
Block(7,51,-6,STONE:0)
Block(8,51,-6,STONE:0)
Block(3,51,-5,LEAVES:7)
Block(4,51,-5,LEAVES:7)
Block(5,51,-5,STONE:0)
Block(6,51,-5,STONE:0)
Block(7,51,-5,STONE:0)
Block(8,51,-5,STONE:0)
Block(3,51,-4,LEAVES:7)
Block(4,51,-4,STONE:0)
Block(5,51,-4,STONE:0)
Block(6,51,-4,STONE:0)
Block(7,51,-4,STONE:0)
Block(8,51,-4,STONE:0)
Block(3,51,-3,LEAVES:7)
Block(4,51,-3,STONE:0)
Block(5,51,-3,STONE:0)
Block(6,51,-3,STONE:0)
Block(7,51,-3,STONE:0)
Block(8,51,-3,STONE:0)
Block(3,51,-2,STONE:3)
Block(4,51,-2,STONE:3)
Block(5,51,-2,STONE:0)
Block(6,51,-2,STONE:0)
Block(7,51,-2,STONE:0)
Block(8,51,-2,STONE:0)
Block(3,51,-1,STONE:3)
Block(4,51,-1,STONE:0)
Block(5,51,-1,STONE:0)
Block(6,51,-1,STONE:0)
Block(7,51,-1,STONE:0)
Block(8,51,-1,STONE:0)
Block(6,52,-7,GRASS:0)
Block(7,52,-7,STONE:0)
Block(8,52,-7,STONE:0)
Block(6,52,-6,STONE:3)
Block(7,52,-6,STONE:3)
Block(8,52,-6,STONE:0)
Block(4,52,-5,LEAVES:7)
Block(5,52,-5,STONE:3)
Block(6,52,-5,STONE:3)
Block(7,52,-5,STONE:0)
Block(8,52,-5,STONE:0)
Block(3,52,-4,LEAVES:7)
Block(4,52,-4,STONE:3)
Block(5,52,-4,STONE:3)
Block(6,52,-4,STONE:0)
Block(7,52,-4,STONE:0)
Block(8,52,-4,STONE:0)
Block(4,52,-3,STONE:3)
Block(5,52,-3,STONE:3)
Block(6,52,-3,STONE:0)
Block(7,52,-3,STONE:0)
Block(8,52,-3,STONE:0)
Block(3,52,-2,STONE:3)
Block(4,52,-2,STONE:3)
Block(5,52,-2,STONE:0)
Block(6,52,-2,STONE:0)
Block(7,52,-2,STONE:0)
Block(8,52,-2,STONE:0)
Block(3,52,-1,STONE:3)
Block(4,52,-1,STONE:3)
Block(5,52,-1,STONE:0)
Block(6,52,-1,STONE:0)
Block(7,52,-1,STONE:0)
Block(8,52,-1,STONE:0)
Block(7,53,-7,STONE:3)
Block(8,53,-7,STONE:3)
Block(6,53,-6,STONE:3)
Block(7,53,-6,STONE:3)
Block(8,53,-6,STONE:0)
Block(4,53,-5,LEAVES:7)
Block(5,53,-5,STONE:3)
Block(6,53,-5,STONE:3)
Block(7,53,-5,STONE:3)
Block(8,53,-5,STONE:0)
Block(3,53,-4,LEAVES:7)
Block(4,53,-4,STONE:3)
Block(5,53,-4,STONE:3)
Block(6,53,-4,STONE:3)
Block(7,53,-4,STONE:0)
Block(8,53,-4,STONE:0)
Block(4,53,-3,STONE:3)
Block(5,53,-3,STONE:3)
Block(6,53,-3,STONE:0)
Block(7,53,-3,STONE:0)
Block(8,53,-3,STONE:0)
Block(3,53,-2,STONE:3)
Block(4,53,-2,STONE:3)
Block(5,53,-2,STONE:3)
Block(6,53,-2,STONE:0)
Block(7,53,-2,STONE:0)
Block(8,53,-2,STONE:0)
Block(3,53,-1,STONE:3)
Block(4,53,-1,STONE:0)
Block(5,53,-1,STONE:0)
Block(6,53,-1,STONE:0)
Block(7,53,-1,STONE:0)
Block(8,53,-1,STONE:0)
Block(7,54,-7,STONE:0)
Block(8,54,-7,STONE:0)
Block(6,54,-6,STONE:3)
Block(7,54,-6,STONE:3)
Block(8,54,-6,STONE:0)
Block(3,54,-5,LEAVES:7)
Block(4,54,-5,LEAVES:7)
Block(5,54,-5,STONE:3)
Block(6,54,-5,STONE:3)
Block(7,54,-5,STONE:0)
Block(8,54,-5,STONE:0)
Block(3,54,-4,LEAVES:7)
Block(4,54,-4,STONE:3)
Block(5,54,-4,STONE:3)
Block(6,54,-4,STONE:0)
Block(7,54,-4,STONE:0)
Block(8,54,-4,STONE:0)
Block(3,54,-3,LEAVES:7)
Block(4,54,-3,STONE:3)
Block(5,54,-3,STONE:3)
Block(6,54,-3,STONE:0)
Block(7,54,-3,STONE:0)
Block(8,54,-3,STONE:0)
Block(3,54,-2,STONE:0)
Block(4,54,-2,STONE:3)
Block(5,54,-2,STONE:0)
Block(6,54,-2,STONE:0)
Block(7,54,-2,STONE:0)
Block(8,54,-2,STONE:0)
Block(3,54,-1,STONE:0)
Block(4,54,-1,STONE:0)
Block(5,54,-1,STONE:0)
Block(6,54,-1,STONE:0)
Block(7,54,-1,STONE:0)
Block(8,54,-1,STONE:0)
Block(7,55,-7,GRASS:0)
Block(8,55,-7,STONE:0)
Block(6,55,-6,GRASS:0)
Block(7,55,-6,STONE:0)
Block(8,55,-6,STONE:0)
Block(4,55,-5,LEAVES:7)
Block(5,55,-5,GRASS:0)
Block(6,55,-5,STONE:0)
Block(7,55,-5,STONE:0)
Block(8,55,-5,STONE:0)
Block(3,55,-4,LEAVES:7)
Block(4,55,-4,GRASS:0)
Block(5,55,-4,STONE:0)
Block(6,55,-4,STONE:0)
Block(7,55,-4,STONE:0)
Block(8,55,-4,STONE:0)
Block(4,55,-3,STONE:0)
Block(5,55,-3,STONE:0)
Block(6,55,-3,STONE:0)
Block(7,55,-3,STONE:0)
Block(8,55,-3,STONE:0)
Block(3,55,-2,STONE:0)
Block(4,55,-2,STONE:0)
Block(5,55,-2,STONE:0)
Block(6,55,-2,STONE:0)
Block(7,55,-2,STONE:0)
Block(8,55,-2,STONE:0)
Block(3,55,-1,STONE:0)
Block(4,55,-1,STONE:0)
Block(5,55,-1,STONE:0)
Block(6,55,-1,STONE:0)
Block(7,55,-1,STONE:0)
Block(8,55,-1,STONE:0)
Block(8,56,-7,GRASS:0)
Block(7,56,-6,STONE:0)
Block(8,56,-6,STONE:0)
Block(4,56,-5,LEAVES:7)
Block(5,56,-5,LEAVES:7)
Block(6,56,-5,STONE:0)
Block(7,56,-5,STONE:0)
Block(8,56,-5,STONE:0)
Block(3,56,-4,LEAVES:7)
Block(4,56,-4,LEAVES:7)
Block(5,56,-4,STONE:0)
Block(6,56,-4,STONE:0)
Block(7,56,-4,STONE:0)
Block(8,56,-4,STONE:0)
Block(4,56,-3,GRASS:0)
Block(5,56,-3,STONE:0)
Block(6,56,-3,STONE:0)
Block(7,56,-3,STONE:0)
Block(8,56,-3,STONE:0)
Block(4,56,-2,STONE:0)
Block(5,56,-2,STONE:0)
Block(6,56,-2,STONE:0)
Block(7,56,-2,STONE:0)
Block(8,56,-2,STONE:0)
Block(3,56,-1,STONE:0)
Block(4,56,-1,STONE:0)
Block(5,56,-1,STONE:0)
Block(6,56,-1,STONE:0)
Block(7,56,-1,STONE:0)
Block(8,56,-1,STONE:0)
Block(7,57,-6,STONE:0)
Block(8,57,-6,STONE:0)
Block(3,57,-5,LEAVES:7)
Block(4,57,-5,LEAVES:7)
Block(5,57,-5,LEAVES:7)
Block(6,57,-5,STONE:0)
Block(7,57,-5,STONE:0)
Block(8,57,-5,STONE:0)
Block(3,57,-4,LEAVES:7)
Block(4,57,-4,LEAVES:7)
Block(5,57,-4,GRASS:0)
Block(6,57,-4,STONE:0)
Block(7,57,-4,STONE:0)
Block(8,57,-4,STONE:0)
Block(3,57,-3,LEAVES:7)
Block(4,57,-3,LEAVES:7)
Block(5,57,-3,STONE:0)
Block(6,57,-3,STONE:0)
Block(7,57,-3,STONE:0)
Block(8,57,-3,STONE:0)
Block(3,57,-2,STONE:0)
Block(4,57,-2,STONE:0)
Block(5,57,-2,STONE:0)
Block(6,57,-2,STONE:0)
Block(7,57,-2,STONE:0)
Block(8,57,-2,STONE:0)
Block(3,57,-1,STONE:0)
Block(4,57,-1,STONE:0)
Block(5,57,-1,STONE:0)
Block(6,57,-1,STONE:0)
Block(7,57,-1,STONE:0)
Block(8,57,-1,STONE:0)
Block(7,58,-6,STONE:0)
Block(8,58,-6,STONE:0)
Block(4,58,-5,LEAVES:7)
Block(5,58,-5,LEAVES:7)
Block(6,58,-5,STONE:0)
Block(7,58,-5,STONE:0)
Block(8,58,-5,STONE:0)
Block(3,58,-4,LEAVES:7)
Block(4,58,-4,LEAVES:7)
Block(5,58,-4,LEAVES:7)
Block(6,58,-4,STONE:0)
Block(7,58,-4,STONE:0)
Block(8,58,-4,STONE:0)
Block(4,58,-3,LEAVES:7)
Block(5,58,-3,STONE:0)
Block(6,58,-3,STONE:0)
Block(7,58,-3,STONE:0)
Block(8,58,-3,STONE:0)
Block(3,58,-2,STONE:0)
Block(4,58,-2,STONE:0)
Block(5,58,-2,STONE:0)
Block(6,58,-2,STONE:0)
Block(7,58,-2,STONE:0)
Block(8,58,-2,STONE:0)
Block(3,58,-1,STONE:0)
Block(4,58,-1,STONE:0)
Block(5,58,-1,STONE:0)
Block(6,58,-1,STONE:0)
Block(7,58,-1,STONE:0)
Block(8,58,-1,STONE:0)
Block(7,59,-6,GRASS:0)
Block(8,59,-6,STONE:0)
Block(4,59,-5,LEAVES:7)
Block(5,59,-5,LEAVES:7)
Block(6,59,-5,STONE:0)
Block(7,59,-5,STONE:0)
Block(8,59,-5,STONE:0)
Block(4,59,-4,LEAVES:7)
Block(5,59,-4,LEAVES:7)
Block(6,59,-4,STONE:0)
Block(7,59,-4,STONE:0)
Block(8,59,-4,STONE:0)
Block(4,59,-3,LEAVES:7)
Block(5,59,-3,STONE:0)
Block(6,59,-3,STONE:0)
Block(7,59,-3,STONE:0)
Block(8,59,-3,STONE:0)
Block(4,59,-2,STONE:0)
Block(5,59,-2,STONE:0)
Block(6,59,-2,STONE:0)
Block(7,59,-2,STONE:0)
Block(8,59,-2,STONE:0)
Block(4,59,-1,STONE:0)
Block(5,59,-1,STONE:0)
Block(6,59,-1,STONE:0)
Block(7,59,-1,STONE:0)
Block(8,59,-1,STONE:0)
Block(5,60,-6,LEAVES:7)
Block(8,60,-6,STONE:0)
Block(4,60,-5,LEAVES:7)
Block(5,60,-5,LEAVES:7)
Block(6,60,-5,STONE:0)
Block(7,60,-5,STONE:0)
Block(8,60,-5,STONE:0)
Block(4,60,-4,LEAVES:7)
Block(5,60,-4,LEAVES:7)
Block(6,60,-4,STONE:0)
Block(7,60,-4,STONE:0)
Block(8,60,-4,STONE:0)
Block(5,60,-3,STONE:0)
Block(6,60,-3,STONE:0)
Block(7,60,-3,STONE:0)
Block(8,60,-3,STONE:0)
Block(4,60,-2,STONE:0)
Block(5,60,-2,STONE:0)
Block(6,60,-2,STONE:0)
Block(7,60,-2,STONE:0)
Block(8,60,-2,STONE:0)
Block(4,60,-1,STONE:0)
Block(5,60,-1,STONE:0)
Block(6,60,-1,STONE:0)
Block(7,60,-1,STONE:0)
Block(8,60,-1,STONE:0)
Block(4,61,-6,LEAVES:7)
Block(5,61,-6,LEAVES:7)
Block(6,61,-6,LEAVES:7)
Block(8,61,-6,STONE:0)
Block(4,61,-5,LEAVES:7)
Block(5,61,-5,LEAVES:7)
Block(6,61,-5,STONE:0)
Block(7,61,-5,STONE:0)
Block(8,61,-5,STONE:0)
Block(4,61,-4,LEAVES:7)
Block(5,61,-4,LEAVES:7)
Block(6,61,-4,STONE:0)
Block(7,61,-4,STONE:0)
Block(8,61,-4,STONE:0)
Block(5,61,-3,STONE:0)
Block(6,61,-3,STONE:0)
Block(7,61,-3,STONE:0)
Block(8,61,-3,STONE:0)
Block(4,61,-2,STONE:0)
Block(5,61,-2,STONE:0)
Block(6,61,-2,STONE:0)
Block(7,61,-2,STONE:0)
Block(8,61,-2,STONE:0)
Block(4,61,-1,STONE:0)
Block(5,61,-1,STONE:0)
Block(6,61,-1,STONE:0)
Block(7,61,-1,STONE:0)
Block(8,61,-1,STONE:0)
Block(5,62,-6,LEAVES:7)
Block(6,62,-6,LEAVES:7)
Block(7,62,-6,LEAVES:7)
Block(8,62,-6,GRASS:0)
Block(4,62,-5,LEAVES:7)
Block(5,62,-5,LEAVES:7)
Block(6,62,-5,GRASS:0)
Block(7,62,-5,GRASS:0)
Block(8,62,-5,STONE:0)
Block(5,62,-4,LEAVES:7)
Block(6,62,-4,GRASS:0)
Block(7,62,-4,STONE:0)
Block(8,62,-4,STONE:0)
Block(6,62,-3,STONE:0)
Block(7,62,-3,STONE:0)
Block(8,62,-3,STONE:0)
Block(4,62,-2,GRASS:0)
Block(5,62,-2,STONE:0)
Block(6,62,-2,STONE:0)
Block(7,62,-2,STONE:0)
Block(8,62,-2,STONE:0)
Block(4,62,-1,STONE:0)
Block(5,62,-1,STONE:0)
Block(6,62,-1,STONE:0)
Block(7,62,-1,STONE:0)
Block(8,62,-1,STONE:0)
Block(6,63,-6,LEAVES:7)
Block(8,63,-6,LEAVES:7)
Block(5,63,-5,LEAVES:7)
Block(6,63,-5,LEAVES:7)
Block(7,63,-5,LEAVES:7)
Block(8,63,-5,GRASS:0)
Block(6,63,-4,LEAVES:7)
Block(7,63,-4,GRASS:0)
Block(8,63,-4,STONE:3)
Block(5,63,-3,STONE:0)
Block(6,63,-3,STONE:3)
Block(7,63,-3,STONE:3)
Block(8,63,-3,STONE:3)
Block(5,63,-2,STONE:0)
Block(6,63,-2,STONE:0)
Block(7,63,-2,STONE:3)
Block(8,63,-2,STONE:0)
Block(5,63,-1,STONE:0)
Block(6,63,-1,STONE:0)
Block(7,63,-1,STONE:0)
Block(8,63,-1,STONE:0)
Block(8,64,-7,LEAVES:7)
Block(8,64,-6,LEAVES:7)
Block(8,64,-5,LEAVES:7)
Block(8,64,-4,STONE:3)
Block(5,64,-3,STONE:3)
Block(6,64,-3,STONE:3)
Block(7,64,-3,STONE:3)
Block(8,64,-3,STONE:3)
Block(5,64,-2,STONE:3)
Block(6,64,-2,STONE:3)
Block(7,64,-2,STONE:3)
Block(8,64,-2,STONE:3)
Block(5,64,-1,STONE:0)
Block(6,64,-1,STONE:0)
Block(7,64,-1,STONE:0)
Block(8,64,-1,STONE:0)
Block(8,65,-6,LEAVES:7)
Block(8,65,-4,STONE:3)
Block(5,65,-3,STONE:3)
Block(6,65,-3,STONE:3)
Block(7,65,-3,STONE:3)
Block(8,65,-3,STONE:3)
Block(5,65,-2,STONE:3)
Block(6,65,-2,STONE:3)
Block(7,65,-2,STONE:3)
Block(8,65,-2,STONE:0)
Block(5,65,-1,STONE:0)
Block(6,65,-1,STONE:0)
Block(7,65,-1,STONE:0)
Block(8,65,-1,STONE:0)
Block(8,66,-4,GRASS:0)
Block(6,66,-3,GRASS:0)
Block(7,66,-3,STONE:3)
Block(8,66,-3,STONE:0)
Block(6,66,-2,GRASS:0)
Block(7,66,-2,STONE:0)
Block(8,66,-2,STONE:0)
Block(6,66,-1,STONE:0)
Block(7,66,-1,STONE:0)
Block(8,66,-1,STONE:0)
Block(7,67,-3,GRASS:0)
Block(8,67,-3,STONE:0)
Block(7,67,-2,GRASS:0)
Block(8,67,-2,STONE:0)
Block(7,67,-1,GRASS:0)
Block(8,67,-1,STONE:0)
Block(8,68,-3,STONE:0)
Block(8,68,-2,STONE:0)
Block(8,68,-1,STONE:0)
Block(8,69,-3,GRASS:0)
Block(8,69,-2,GRASS:0)
Block(8,69,-1,GRASS:0)
