Author: Bo3 BulkEdit

Description: Converted Schematic - Modified by Bo3BulkEdit

Version: 3

SettingsMode: WriteDisable

IsOTGPlus: false
Tree: false
Frequency: 1
Rarity: 100
RotateRandomly: false
SpawnHeight: randomY
MaxBranchDepth: 20
ExcludedBiomes: All

MinHeight: 0
MaxHeight: 256

SourceBlocks: AIR
MaxPercentageOutsideSourceBlock: 100
OutsideSourceBlock: placeAnyway

B(-8,0,-8,LOG:1)
B(-7,0,-8,STONE:6)
B(-4,0,-5,STONE:6)
B(-8,0,-4,LOG:1)
B(-4,0,-4,LOG:1)
B(-8,1,-8,LOG:1)
B(-7,1,-8,STONE:6)
B(-8,1,-7,LOG:9)
B(-8,1,-6,LOG:9)
B(-8,1,-5,LOG:9)
B(-4,1,-5,STONE:6)
B(-8,1,-4,LOG:1)
B(-4,1,-4,LOG:1)
B(-4,1,-3,LOG:9)
B(-4,1,-2,LOG:9)
B(-4,1,-1,LOG:9)
B(-8,2,-8,LOG:1)
B(-7,2,-8,STONE:6)
B(-4,2,-5,STONE:6)
B(-8,2,-4,LOG:1)
B(-4,2,-4,LOG:1)
B(-3,2,-4,LOG:5)
B(-2,2,-4,LOG:5)
B(-1,2,-4,LOG:5)
B(-8,3,-8,LOG:1)
B(-7,3,-8,STONE:6)
B(-8,3,-7,LOG:9)
B(-8,3,-6,LOG:9)
B(-8,3,-5,LOG:9)
B(-4,3,-5,STONE:6)
B(-8,3,-4,LOG:1)
B(-7,3,-4,LOG:5)
B(-6,3,-4,LOG:5)
B(-5,3,-4,LOG:5)
B(-4,3,-4,LOG:1)
B(-8,3,-3,LOG:9)
B(-8,3,-2,LOG:9)
B(-8,3,-1,LOG:9)
B(-8,4,-8,LOG:1)
B(-7,4,-8,STONE:6)
B(-4,4,-5,STONE:6)
B(-8,4,-4,LOG:1)
B(-4,4,-4,LOG:1)
B(-8,5,-8,LOG:1)
B(-7,5,-8,STONE:6)
B(-8,5,-7,LOG:9)
B(-8,5,-6,LOG:9)
B(-8,5,-5,LOG:9)
B(-4,5,-5,STONE:6)
B(-8,5,-4,LOG:1)
B(-4,5,-4,LOG:1)
B(-4,5,-3,LOG:9)
B(-4,5,-2,LOG:9)
B(-4,5,-1,LOG:9)
B(-8,6,-8,LOG:1)
B(-7,6,-8,STONE:6)
B(-4,6,-5,STONE:6)
B(-8,6,-4,LOG:1)
B(-4,6,-4,LOG:1)
B(-3,6,-4,LOG:5)
B(-2,6,-4,LOG:5)
B(-1,6,-4,LOG:5)
B(-8,7,-8,LOG:1)
B(-7,7,-8,STONE:6)
B(-8,7,-7,LOG:9)
B(-8,7,-6,LOG:9)
B(-8,7,-5,LOG:9)
B(-4,7,-5,STONE:6)
B(-8,7,-4,LOG:1)
B(-7,7,-4,LOG:5)
B(-6,7,-4,LOG:5)
B(-5,7,-4,LOG:5)
B(-4,7,-4,LOG:1)
B(-8,7,-3,LOG:9)
B(-8,7,-2,LOG:9)
B(-8,7,-1,LOG:9)
B(-8,8,-8,LOG:1)
B(-7,8,-8,STONE:6)
B(-4,8,-5,STONE:6)
B(-8,8,-4,LOG:1)
B(-4,8,-4,LOG:1)
B(-8,9,-8,LOG:1)
B(-7,9,-8,STONE:6)
B(-8,9,-7,LOG:9)
B(-8,9,-6,LOG:9)
B(-8,9,-5,LOG:9)
B(-4,9,-5,STONE:6)
B(-8,9,-4,LOG:1)
B(-4,9,-4,LOG:1)
B(-4,9,-3,LOG:9)
B(-4,9,-2,LOG:9)
B(-4,9,-1,LOG:9)
B(-8,10,-8,LOG:1)
B(-7,10,-8,STONE:6)
B(-4,10,-5,STONE:6)
B(-8,10,-4,LOG:1)
B(-4,10,-4,LOG:1)
B(-3,10,-4,LOG:5)
B(-2,10,-4,LOG:5)
B(-1,10,-4,LOG:5)
B(-8,11,-8,LOG:1)
B(-7,11,-8,STONE:6)
B(-8,11,-7,LOG:9)
B(-8,11,-6,LOG:9)
B(-8,11,-5,LOG:9)
B(-4,11,-5,STONE:6)
B(-8,11,-4,LOG:1)
B(-7,11,-4,LOG:5)
B(-6,11,-4,LOG:5)
B(-5,11,-4,LOG:5)
B(-4,11,-4,LOG:1)
B(-8,11,-3,LOG:9)
B(-8,11,-2,LOG:9)
B(-8,11,-1,LOG:9)
B(-8,12,-8,LOG:1)
B(-7,12,-8,STONE:6)
B(-4,12,-5,STONE:6)
B(-8,12,-4,LOG:1)
B(-4,12,-4,LOG:1)
B(-8,13,-8,LOG:1)
B(-7,13,-8,STONE:6)
B(-8,13,-7,LOG:9)
B(-8,13,-6,LOG:9)
B(-8,13,-5,LOG:9)
B(-4,13,-5,STONE:6)
B(-8,13,-4,LOG:1)
B(-4,13,-4,LOG:1)
B(-4,13,-3,LOG:9)
B(-4,13,-2,LOG:9)
B(-4,13,-1,LOG:9)
B(-8,14,-8,LOG:1)
B(-7,14,-8,STONE:6)
B(-4,14,-5,STONE:6)
B(-8,14,-4,LOG:1)
B(-4,14,-4,LOG:1)
B(-3,14,-4,LOG:5)
B(-2,14,-4,LOG:5)
B(-1,14,-4,LOG:5)
B(-8,15,-8,LOG:1)
B(-7,15,-8,STONE:6)
B(-8,15,-7,LOG:9)
B(-8,15,-6,LOG:9)
B(-8,15,-5,LOG:9)
B(-4,15,-5,STONE:6)
B(-8,15,-4,LOG:1)
B(-7,15,-4,LOG:5)
B(-6,15,-4,LOG:5)
B(-5,15,-4,LOG:5)
B(-4,15,-4,LOG:1)
B(-8,15,-3,LOG:9)
B(-8,15,-2,LOG:9)
B(-8,15,-1,LOG:9)
B(-8,16,-8,LOG:1)
B(-7,16,-8,STONE:6)
B(-4,16,-5,STONE:6)
B(-8,16,-4,LOG:1)
B(-4,16,-4,LOG:1)
B(-8,17,-8,LOG:1)
B(-7,17,-8,STONE:6)
B(-8,17,-7,LOG:9)
B(-8,17,-6,LOG:9)
B(-8,17,-5,LOG:9)
B(-4,17,-5,STONE:6)
B(-8,17,-4,LOG:1)
B(-4,17,-4,LOG:1)
B(-4,17,-3,LOG:9)
B(-4,17,-2,LOG:9)
B(-4,17,-1,LOG:9)
B(-8,18,-8,LOG:1)
B(-7,18,-8,STONE:6)
B(-4,18,-5,STONE:6)
B(-8,18,-4,LOG:1)
B(-4,18,-4,LOG:1)
B(-3,18,-4,LOG:5)
B(-2,18,-4,LOG:5)
B(-1,18,-4,LOG:5)
B(-8,19,-8,LOG:1)
B(-7,19,-8,STONE:6)
B(-8,19,-7,LOG:9)
B(-8,19,-6,LOG:9)
B(-8,19,-5,LOG:9)
B(-4,19,-5,STONE:6)
B(-8,19,-4,LOG:1)
B(-7,19,-4,LOG:5)
B(-6,19,-4,LOG:5)
B(-5,19,-4,LOG:5)
B(-4,19,-4,LOG:1)
B(-8,19,-3,LOG:9)
B(-8,19,-2,LOG:9)
B(-8,19,-1,LOG:9)
B(-8,20,-8,LOG:1)
B(-7,20,-8,STONE:6)
B(-4,20,-5,STONE:6)
B(-8,20,-4,LOG:1)
B(-4,20,-4,LOG:1)
B(-8,21,-8,LOG:1)
B(-7,21,-8,STONE:6)
B(-8,21,-7,LOG:9)
B(-8,21,-6,LOG:9)
B(-8,21,-5,LOG:9)
B(-4,21,-5,STONE:6)
B(-8,21,-4,LOG:1)
B(-4,21,-4,LOG:1)
B(-4,21,-3,LOG:9)
B(-4,21,-2,LOG:9)
B(-4,21,-1,LOG:9)
B(-8,22,-8,LOG:1)
B(-7,22,-8,STONE:6)
B(-4,22,-5,STONE:6)
B(-8,22,-4,LOG:1)
B(-4,22,-4,LOG:1)
B(-3,22,-4,LOG:5)
B(-2,22,-4,LOG:5)
B(-1,22,-4,LOG:5)
B(-8,23,-8,LOG:1)
B(-7,23,-8,STONE:6)
B(-8,23,-7,LOG:9)
B(-8,23,-6,LOG:9)
B(-8,23,-5,LOG:9)
B(-4,23,-5,STONE:6)
B(-8,23,-4,LOG:1)
B(-7,23,-4,LOG:5)
B(-6,23,-4,LOG:5)
B(-5,23,-4,LOG:5)
B(-4,23,-4,LOG:1)
B(-8,23,-3,LOG:9)
B(-8,23,-2,LOG:9)
B(-8,23,-1,LOG:9)
B(-8,24,-8,LOG:1)
B(-7,24,-8,STONE:6)
B(-4,24,-5,STONE:6)
B(-8,24,-4,LOG:1)
B(-4,24,-4,LOG:1)
B(-8,25,-8,LOG:1)
B(-7,25,-8,STONE:6)
B(-8,25,-7,LOG:9)
B(-8,25,-6,LOG:9)
B(-8,25,-5,LOG:9)
B(-4,25,-5,STONE:6)
B(-8,25,-4,LOG:1)
B(-4,25,-4,LOG:1)
B(-4,25,-3,LOG:9)
B(-4,25,-2,LOG:9)
B(-4,25,-1,LOG:9)
B(-8,26,-8,LOG:1)
B(-7,26,-8,STONE:6)
B(-4,26,-5,STONE:6)
B(-8,26,-4,LOG:1)
B(-4,26,-4,LOG:1)
B(-3,26,-4,LOG:5)
B(-2,26,-4,LOG:5)
B(-1,26,-4,LOG:5)
B(-8,27,-8,LOG:1)
B(-7,27,-8,STONE:6)
B(-8,27,-7,LOG:9)
B(-8,27,-6,LOG:9)
B(-8,27,-5,LOG:9)
B(-4,27,-5,STONE:6)
B(-8,27,-4,LOG:1)
B(-7,27,-4,LOG:5)
B(-6,27,-4,LOG:5)
B(-5,27,-4,LOG:5)
B(-4,27,-4,LOG:1)
B(-8,27,-3,LOG:9)
B(-8,27,-2,LOG:9)
B(-8,27,-1,LOG:9)
B(-8,28,-8,LOG:1)
B(-7,28,-8,STONE:6)
B(-4,28,-5,STONE:6)
B(-8,28,-4,LOG:1)
B(-4,28,-4,LOG:1)
B(-8,29,-8,LOG:1)
B(-7,29,-8,STONE:6)
B(-8,29,-7,LOG:9)
B(-8,29,-6,LOG:9)
B(-8,29,-5,LOG:9)
B(-4,29,-5,STONE:6)
B(-8,29,-4,LOG:1)
B(-4,29,-4,LOG:1)
B(-4,29,-3,LOG:9)
B(-4,29,-2,LOG:9)
B(-4,29,-1,LOG:9)
B(-8,30,-8,LOG:1)
B(-7,30,-8,STONE:6)
B(-4,30,-5,STONE:6)
B(-8,30,-4,LOG:1)
B(-4,30,-4,LOG:1)
B(-3,30,-4,LOG:5)
B(-2,30,-4,LOG:5)
B(-1,30,-4,LOG:5)
B(-8,31,-8,LOG:1)
B(-7,31,-8,STONE:6)
B(-8,31,-7,LOG:9)
B(-8,31,-6,LOG:9)
B(-8,31,-5,LOG:9)
B(-4,31,-5,STONE:6)
B(-8,31,-4,LOG:1)
B(-7,31,-4,LOG:5)
B(-6,31,-4,LOG:5)
B(-5,31,-4,LOG:5)
B(-4,31,-4,LOG:1)
B(-8,31,-3,LOG:9)
B(-8,31,-2,LOG:9)
B(-8,31,-1,LOG:9)
B(-8,32,-8,LOG:1)
B(-7,32,-8,STONE:6)
B(-4,32,-5,STONE:6)
B(-8,32,-4,LOG:1)
B(-4,32,-4,LOG:1)
B(-8,33,-8,LOG:1)
B(-7,33,-8,STONE:6)
B(-8,33,-7,LOG:9)
B(-8,33,-6,LOG:9)
B(-8,33,-5,LOG:9)
B(-4,33,-5,STONE:6)
B(-8,33,-4,LOG:1)
B(-4,33,-4,LOG:1)
B(-4,33,-3,LOG:9)
B(-4,33,-2,LOG:9)
B(-4,33,-1,LOG:9)
B(-8,34,-8,LOG:1)
B(-7,34,-8,STONE:6)
B(-4,34,-5,STONE:6)
B(-8,34,-4,LOG:1)
B(-4,34,-4,LOG:1)
B(-3,34,-4,LOG:5)
B(-2,34,-4,LOG:5)
B(-1,34,-4,LOG:5)
B(-8,35,-8,LOG:1)
B(-7,35,-8,STONE:6)
B(-8,35,-7,LOG:9)
B(-8,35,-6,LOG:9)
B(-8,35,-5,LOG:9)
B(-4,35,-5,STONE:6)
B(-8,35,-4,LOG:1)
B(-7,35,-4,LOG:5)
B(-6,35,-4,LOG:5)
B(-5,35,-4,LOG:5)
B(-4,35,-4,LOG:1)
B(-8,35,-3,LOG:9)
B(-8,35,-2,LOG:9)
B(-8,35,-1,LOG:9)
B(-8,36,-8,LOG:1)
B(-7,36,-8,STONE:6)
B(-4,36,-5,STONE:6)
B(-8,36,-4,LOG:1)
B(-4,36,-4,LOG:1)
B(-8,37,-8,LOG:1)
B(-7,37,-8,STONE:6)
B(-8,37,-7,LOG:9)
B(-8,37,-6,LOG:9)
B(-8,37,-5,LOG:9)
B(-4,37,-5,STONE:6)
B(-8,37,-4,LOG:1)
B(-4,37,-4,LOG:1)
B(-4,37,-3,LOG:9)
B(-4,37,-2,LOG:9)
B(-4,37,-1,LOG:9)
B(-8,38,-8,LOG:1)
B(-7,38,-8,STONE:6)
B(-4,38,-5,STONE:6)
B(-8,38,-4,LOG:1)
B(-4,38,-4,LOG:1)
B(-3,38,-4,LOG:5)
B(-2,38,-4,LOG:5)
B(-1,38,-4,LOG:5)
B(-8,39,-8,LOG:1)
B(-7,39,-8,STONE:6)
B(-8,39,-7,LOG:9)
B(-8,39,-6,LOG:9)
B(-8,39,-5,LOG:9)
B(-4,39,-5,STONE:6)
B(-8,39,-4,LOG:1)
B(-7,39,-4,LOG:5)
B(-6,39,-4,LOG:5)
B(-5,39,-4,LOG:5)
B(-4,39,-4,LOG:1)
B(-8,39,-3,LOG:9)
B(-8,39,-2,LOG:9)
B(-8,39,-1,LOG:9)
B(-8,40,-8,LOG:1)
B(-7,40,-8,STONE:6)
B(-4,40,-5,STONE:6)
B(-8,40,-4,LOG:1)
B(-4,40,-4,LOG:1)
B(-8,41,-8,LOG:1)
B(-7,41,-8,STONE:6)
B(-8,41,-7,LOG:9)
B(-8,41,-6,LOG:9)
B(-8,41,-5,LOG:9)
B(-4,41,-5,STONE:6)
B(-8,41,-4,LOG:1)
B(-4,41,-4,LOG:1)
B(-4,41,-3,LOG:9)
B(-4,41,-2,LOG:9)
B(-4,41,-1,LOG:9)
B(-8,42,-8,LOG:1)
B(-7,42,-8,STONE:6)
B(-4,42,-5,STONE:6)
B(-8,42,-4,LOG:1)
B(-4,42,-4,LOG:1)
B(-3,42,-4,LOG:5)
B(-2,42,-4,LOG:5)
B(-1,42,-4,LOG:5)
B(-8,43,-8,LOG:1)
B(-7,43,-8,STONE:6)
B(-8,43,-7,LOG:9)
B(-8,43,-6,LOG:9)
B(-8,43,-5,LOG:9)
B(-4,43,-5,STONE:6)
B(-8,43,-4,LOG:1)
B(-7,43,-4,LOG:5)
B(-6,43,-4,LOG:5)
B(-5,43,-4,LOG:5)
B(-4,43,-4,LOG:1)
B(-8,43,-3,LOG:9)
B(-8,43,-2,LOG:9)
B(-8,43,-1,LOG:9)
B(-8,44,-8,LOG:1)
B(-7,44,-8,STONE:6)
B(-4,44,-5,STONE:6)
B(-8,44,-4,LOG:1)
B(-4,44,-4,LOG:1)
B(-8,45,-8,LOG:1)
B(-7,45,-8,STONE:6)
B(-8,45,-7,LOG:9)
B(-8,45,-6,LOG:9)
B(-8,45,-5,LOG:9)
B(-4,45,-5,STONE:6)
B(-8,45,-4,LOG:1)
B(-4,45,-4,LOG:1)
B(-4,45,-3,LOG:9)
B(-4,45,-2,LOG:9)
B(-4,45,-1,LOG:9)
B(-8,46,-8,LOG:1)
B(-7,46,-8,STONE:6)
B(-4,46,-5,STONE:6)
B(-8,46,-4,LOG:1)
B(-4,46,-4,LOG:1)
B(-3,46,-4,LOG:5)
B(-2,46,-4,LOG:5)
B(-1,46,-4,LOG:5)
B(-8,47,-8,LOG:1)
B(-7,47,-8,STONE:6)
B(-8,47,-7,LOG:9)
B(-8,47,-6,LOG:9)
B(-8,47,-5,LOG:9)
B(-4,47,-5,STONE:6)
B(-8,47,-4,LOG:1)
B(-7,47,-4,LOG:5)
B(-6,47,-4,LOG:5)
B(-5,47,-4,LOG:5)
B(-4,47,-4,LOG:1)
B(-8,47,-3,LOG:9)
B(-8,47,-2,LOG:9)
B(-8,47,-1,LOG:9)
B(-8,48,-8,LOG:1)
B(-7,48,-8,STONE:6)
B(-8,48,-7,LOG:9)
B(-8,48,-6,LOG:9)
B(-8,48,-5,LOG:9)
B(-4,48,-5,STONE:6)
B(-8,48,-4,LOG:1)
B(-7,48,-4,LOG:5)
B(-6,48,-4,LOG:5)
B(-5,48,-4,LOG:5)
B(-4,48,-4,LOG:1)
B(-8,48,-3,LOG:9)
B(-8,48,-2,LOG:9)
B(-8,48,-1,LOG:9)
B(-8,49,-8,LOG:1)
B(-7,49,-8,STONE:6)
B(-4,49,-5,STONE:6)
B(-8,49,-4,LOG:1)
B(-4,49,-4,LOG:1)
B(-8,50,-8,LOG:1)
B(-7,50,-8,STONE_BRICK_STAIRS:1)
B(-8,50,-7,LOG:9)
B(-7,50,-7,WOODEN_BUTTON:1)
B(-8,50,-6,LOG:9)
B(-7,50,-6,WOODEN_BUTTON:1)
B(-8,50,-5,LOG:9)
B(-6,50,-5,WOODEN_BUTTON:4)
B(-5,50,-5,WOODEN_BUTTON:4)
B(-4,50,-5,STONE:6)
B(-3,50,-5,WOODEN_BUTTON:4)
B(-2,50,-5,WOODEN_BUTTON:4)
B(-1,50,-5,WOODEN_BUTTON:4)
B(-8,50,-4,LOG:1)
B(-7,50,-4,LOG:5)
B(-6,50,-4,LOG:5)
B(-5,50,-4,LOG:5)
B(-4,50,-4,LOG:1)
B(-3,50,-4,LOG:5)
B(-2,50,-4,LOG:5)
B(-1,50,-4,LOG:5)
B(-8,50,-3,LOG:9)
B(-4,50,-3,LOG:9)
B(-8,50,-2,LOG:9)
B(-4,50,-2,LOG:9)
B(-8,50,-1,LOG:9)
B(-4,50,-1,LOG:9)
B(-8,51,-8,LOG:1)
B(-7,51,-8,STONE_BRICK_STAIRS:5)
B(-8,51,-7,WOODEN_SLAB:5)
B(-7,51,-7,WOODEN_SLAB:13)
B(-8,51,-6,WOODEN_SLAB:5)
B(-7,51,-6,WOODEN_SLAB:13)
B(-8,51,-5,WOODEN_SLAB:5)
B(-7,51,-5,WOODEN_SLAB:13)
B(-6,51,-5,WOODEN_SLAB:13)
B(-5,51,-5,WOODEN_SLAB:13)
B(-4,51,-5,STONE_BRICK_STAIRS:2)
B(-8,51,-4,LOG:1)
B(-7,51,-4,WOODEN_SLAB:5)
B(-6,51,-4,WOODEN_SLAB:5)
B(-5,51,-4,WOODEN_SLAB:5)
B(-4,51,-4,LOG:1)
B(-3,51,-4,WOODEN_SLAB:5)
B(-2,51,-4,WOODEN_SLAB:5)
B(-1,51,-4,WOODEN_SLAB:5)
B(-8,51,-3,WOODEN_SLAB:5)
B(-7,51,-3,WOODEN_SLAB:8)
B(-6,51,-3,WOODEN_SLAB:8)
B(-5,51,-3,WOODEN_SLAB:8)
B(-4,51,-3,DOUBLE_WOODEN_SLAB:5)
B(-8,51,-2,WOODEN_SLAB:5)
B(-7,51,-2,WOODEN_SLAB:8)
B(-6,51,-2,WOODEN_SLAB:8)
B(-5,51,-2,WOODEN_SLAB:8)
B(-4,51,-2,WOODEN_SLAB:5)
B(-8,51,-1,WOODEN_SLAB:5)
B(-7,51,-1,WOODEN_SLAB:8)
B(-6,51,-1,WOODEN_SLAB:8)
B(-5,51,-1,WOODEN_SLAB:8)
B(-4,51,-1,DOUBLE_WOODEN_SLAB:5)
B(-8,52,-8,LOG:1)
B(-7,52,-8,STONE:6)
B(-8,52,-7,LOG:9)
B(-7,52,-7,STONE_SLAB:0)
B(-8,52,-6,LOG:9)
B(-7,52,-6,STONE_SLAB:0)
B(-8,52,-5,LOG:9)
B(-7,52,-5,STONE_SLAB:0)
B(-6,52,-5,STONE_SLAB:0)
B(-5,52,-5,STONE_SLAB:0)
B(-4,52,-5,STONE_BRICK_STAIRS:6)
B(-3,52,-5,WOODEN_SLAB:13)
B(-2,52,-5,WOODEN_SLAB:13)
B(-1,52,-5,WOODEN_SLAB:13)
B(-8,52,-4,LOG:1)
B(-7,52,-4,LOG:5)
B(-6,52,-4,LOG:5)
B(-5,52,-4,LOG:5)
B(-4,52,-4,LOG:1)
B(-3,52,-4,WOODEN_SLAB:8)
B(-1,52,-4,WOODEN_SLAB:8)
B(-8,52,-3,STONE_SLAB:0)
B(-7,52,-3,STONE_SLAB:0)
B(-6,52,-3,STONE_SLAB:0)
B(-5,52,-3,STONE_SLAB:0)
B(-4,52,-3,DOUBLE_STONE_SLAB:0)
B(-3,52,-3,WOODEN_SLAB:8)
B(-1,52,-3,WOODEN_SLAB:8)
B(-8,52,-2,STONE_SLAB:0)
B(-7,52,-2,STONE_SLAB:0)
B(-6,52,-2,STONE_SLAB:0)
B(-5,52,-2,STONE_SLAB:0)
B(-4,52,-2,DOUBLE_STONE_SLAB:0)
B(-3,52,-2,WOODEN_SLAB:8)
B(-1,52,-2,WOODEN_SLAB:8)
B(-8,52,-1,STONE_SLAB:0)
B(-7,52,-1,STONE_SLAB:0)
B(-6,52,-1,STONE_SLAB:0)
B(-5,52,-1,STONE_SLAB:0)
B(-4,52,-1,DOUBLE_STONE_SLAB:0)
B(-3,52,-1,WOODEN_SLAB:8)
B(-1,52,-1,WOODEN_SLAB:8)
B(-8,53,-8,STONEBRICK:3)
B(-7,53,-8,STONE_BRICK_STAIRS:1)
B(-8,53,-7,SPRUCE_FENCE:0)
B(-8,53,-6,SPRUCE_FENCE:0)
B(-8,53,-5,SPRUCE_FENCE:0)
B(-4,53,-5,STONE:6)
B(-3,53,-5,STONE_SLAB:0)
B(-2,53,-5,STONE_SLAB:0)
B(-1,53,-5,STONE_SLAB:0)
B(-8,53,-4,STONEBRICK:3)
B(-7,53,-4,SPRUCE_FENCE:0)
B(-6,53,-4,SPRUCE_FENCE:0)
B(-5,53,-4,SPRUCE_FENCE:0)
B(-4,53,-4,LOG:1)
B(-3,53,-4,LOG:5)
B(-2,53,-4,LOG:5)
B(-1,53,-4,LOG:5)
B(-3,53,-3,STONE_SLAB:0)
B(-2,53,-3,STONE_SLAB:0)
B(-1,53,-3,DOUBLE_STONE_SLAB:0)
B(-3,53,-2,STONE_SLAB:0)
B(-2,53,-2,STONE_SLAB:0)
B(-1,53,-2,DOUBLE_STONE_SLAB:0)
B(-3,53,-1,STONE_SLAB:0)
B(-2,53,-1,STONE_SLAB:0)
B(-1,53,-1,DOUBLE_STONE_SLAB:0)
B(-8,54,-8,STONE_SLAB:0)
B(-7,54,-8,STONE_SLAB:0)
B(-4,54,-5,STONE_BRICK_STAIRS:2)
B(-8,54,-4,STONE_SLAB:0)
B(-4,54,-4,STONE_BRICK_STAIRS:3)
B(-3,54,-4,SPRUCE_FENCE:0)
B(-2,54,-4,SPRUCE_FENCE:0)
B(-1,54,-4,SPRUCE_FENCE:0)
B(-4,55,-5,STONE_SLAB:0)
B(-4,55,-4,STONE_SLAB:0)

BR(-8,0,0,WestPort_7x3,NORTH,100)
