Author: Bo3 BulkEdit

Description: Converted Schematic - Modified by Bo3BulkEdit

Version: 3

SettingsMode: WriteDisable

IsOTGPlus: false
Tree: false
Frequency: 1
Rarity: 100
RotateRandomly: false
SpawnHeight: randomY
MaxBranchDepth: 20
ExcludedBiomes: All

MinHeight: 0
MaxHeight: 256

SourceBlocks: AIR
MaxPercentageOutsideSourceBlock: 100
OutsideSourceBlock: placeAnyway

B(-2,0,-7,LOG:1)
B(-4,1,-8,LOG:9)
B(-4,1,-7,LOG:9)
B(-3,1,-7,LOG:5)
B(-2,1,-7,LOG:1)
B(-4,1,-6,LOG:9)
B(-4,1,-5,LOG:9)
B(-2,2,-7,LOG:1)
B(-1,2,-7,LOG:5)
B(-8,3,-8,LOG:9)
B(-4,3,-8,LOG:9)
B(-8,3,-7,LOG:9)
B(-4,3,-7,LOG:9)
B(-2,3,-7,LOG:1)
B(-8,3,-6,LOG:9)
B(-4,3,-6,LOG:9)
B(-2,3,-6,LOG:9)
B(-8,3,-5,LOG:9)
B(-4,3,-5,LOG:9)
B(-2,3,-5,LOG:9)
B(-2,4,-7,LOG:1)
B(-4,5,-8,LOG:9)
B(-4,5,-7,LOG:9)
B(-3,5,-7,LOG:5)
B(-2,5,-7,LOG:1)
B(-4,5,-6,LOG:9)
B(-4,5,-5,LOG:9)
B(-2,6,-7,LOG:1)
B(-1,6,-7,LOG:5)
B(-8,7,-8,LOG:9)
B(-4,7,-8,LOG:9)
B(-8,7,-7,LOG:9)
B(-4,7,-7,LOG:9)
B(-2,7,-7,LOG:1)
B(-8,7,-6,LOG:9)
B(-4,7,-6,LOG:9)
B(-2,7,-6,LOG:9)
B(-8,7,-5,LOG:9)
B(-4,7,-5,LOG:9)
B(-2,7,-5,LOG:9)
B(-2,8,-7,LOG:1)
B(-4,9,-8,LOG:9)
B(-4,9,-7,LOG:9)
B(-3,9,-7,LOG:5)
B(-2,9,-7,LOG:1)
B(-4,9,-6,LOG:9)
B(-4,9,-5,LOG:9)
B(-2,10,-7,LOG:1)
B(-1,10,-7,LOG:5)
B(-8,11,-8,LOG:9)
B(-4,11,-8,LOG:9)
B(-8,11,-7,LOG:9)
B(-4,11,-7,LOG:9)
B(-2,11,-7,LOG:1)
B(-8,11,-6,LOG:9)
B(-4,11,-6,LOG:9)
B(-2,11,-6,LOG:9)
B(-8,11,-5,LOG:9)
B(-4,11,-5,LOG:9)
B(-2,11,-5,LOG:9)
B(-2,12,-7,LOG:1)
B(-4,13,-8,LOG:9)
B(-4,13,-7,LOG:9)
B(-3,13,-7,LOG:5)
B(-2,13,-7,LOG:1)
B(-4,13,-6,LOG:9)
B(-4,13,-5,LOG:9)
B(-2,14,-7,LOG:1)
B(-1,14,-7,LOG:5)
B(-8,15,-8,LOG:9)
B(-4,15,-8,LOG:9)
B(-8,15,-7,LOG:9)
B(-4,15,-7,LOG:9)
B(-2,15,-7,LOG:1)
B(-8,15,-6,LOG:9)
B(-4,15,-6,LOG:9)
B(-2,15,-6,LOG:9)
B(-8,15,-5,LOG:9)
B(-4,15,-5,LOG:9)
B(-2,15,-5,LOG:9)
B(-2,16,-7,LOG:1)
B(-4,17,-8,LOG:9)
B(-4,17,-7,LOG:9)
B(-3,17,-7,LOG:5)
B(-2,17,-7,LOG:1)
B(-4,17,-6,LOG:9)
B(-4,17,-5,LOG:9)
B(-2,18,-7,LOG:1)
B(-1,18,-7,LOG:5)
B(-8,19,-8,LOG:9)
B(-4,19,-8,LOG:9)
B(-8,19,-7,LOG:9)
B(-4,19,-7,LOG:9)
B(-2,19,-7,LOG:1)
B(-8,19,-6,LOG:9)
B(-4,19,-6,LOG:9)
B(-2,19,-6,LOG:9)
B(-8,19,-5,LOG:9)
B(-4,19,-5,LOG:9)
B(-2,19,-5,LOG:9)
B(-2,20,-7,LOG:1)
B(-4,21,-8,LOG:9)
B(-4,21,-7,LOG:9)
B(-3,21,-7,LOG:5)
B(-2,21,-7,LOG:1)
B(-4,21,-6,LOG:9)
B(-4,21,-5,LOG:9)
B(-2,22,-7,LOG:1)
B(-1,22,-7,LOG:5)
B(-8,23,-8,LOG:9)
B(-4,23,-8,LOG:9)
B(-8,23,-7,LOG:9)
B(-4,23,-7,LOG:9)
B(-2,23,-7,LOG:1)
B(-8,23,-6,LOG:9)
B(-4,23,-6,LOG:9)
B(-2,23,-6,LOG:9)
B(-8,23,-5,LOG:9)
B(-4,23,-5,LOG:9)
B(-2,23,-5,LOG:9)
B(-2,24,-7,LOG:1)
B(-4,25,-8,LOG:9)
B(-4,25,-7,LOG:9)
B(-3,25,-7,LOG:5)
B(-2,25,-7,LOG:1)
B(-4,25,-6,LOG:9)
B(-4,25,-5,LOG:9)
B(-2,26,-7,LOG:1)
B(-1,26,-7,LOG:5)
B(-8,27,-8,LOG:9)
B(-4,27,-8,LOG:9)
B(-8,27,-7,LOG:9)
B(-4,27,-7,LOG:9)
B(-2,27,-7,LOG:1)
B(-8,27,-6,LOG:9)
B(-4,27,-6,LOG:9)
B(-2,27,-6,LOG:9)
B(-8,27,-5,LOG:9)
B(-4,27,-5,LOG:9)
B(-2,27,-5,LOG:9)
B(-2,28,-7,LOG:1)
B(-4,29,-8,LOG:9)
B(-4,29,-7,LOG:9)
B(-3,29,-7,LOG:5)
B(-2,29,-7,LOG:1)
B(-4,29,-6,LOG:9)
B(-4,29,-5,LOG:9)
B(-2,30,-7,LOG:1)
B(-1,30,-7,LOG:5)
B(-8,31,-8,LOG:9)
B(-4,31,-8,LOG:9)
B(-8,31,-7,LOG:9)
B(-4,31,-7,LOG:9)
B(-2,31,-7,LOG:1)
B(-8,31,-6,LOG:9)
B(-4,31,-6,LOG:9)
B(-2,31,-6,LOG:9)
B(-8,31,-5,LOG:9)
B(-4,31,-5,LOG:9)
B(-2,31,-5,LOG:9)
B(-2,32,-7,LOG:1)
B(-4,33,-8,LOG:9)
B(-4,33,-7,LOG:9)
B(-3,33,-7,LOG:5)
B(-2,33,-7,LOG:1)
B(-4,33,-6,LOG:9)
B(-4,33,-5,LOG:9)
B(-2,34,-7,LOG:1)
B(-1,34,-7,LOG:5)
B(-8,35,-8,LOG:9)
B(-4,35,-8,LOG:9)
B(-8,35,-7,LOG:9)
B(-4,35,-7,LOG:9)
B(-2,35,-7,LOG:1)
B(-8,35,-6,LOG:9)
B(-4,35,-6,LOG:9)
B(-2,35,-6,LOG:9)
B(-8,35,-5,LOG:9)
B(-4,35,-5,LOG:9)
B(-2,35,-5,LOG:9)
B(-2,36,-7,LOG:1)
B(-4,37,-8,LOG:9)
B(-4,37,-7,LOG:9)
B(-3,37,-7,LOG:5)
B(-2,37,-7,LOG:1)
B(-4,37,-6,LOG:9)
B(-4,37,-5,LOG:9)
B(-2,38,-7,LOG:1)
B(-1,38,-7,LOG:5)
B(-8,39,-8,LOG:9)
B(-4,39,-8,LOG:9)
B(-8,39,-7,LOG:9)
B(-4,39,-7,LOG:9)
B(-2,39,-7,LOG:1)
B(-8,39,-6,LOG:9)
B(-4,39,-6,LOG:9)
B(-2,39,-6,LOG:9)
B(-8,39,-5,LOG:9)
B(-4,39,-5,LOG:9)
B(-2,39,-5,LOG:9)
B(-2,40,-7,LOG:1)
B(-4,41,-8,LOG:9)
B(-4,41,-7,LOG:9)
B(-3,41,-7,LOG:5)
B(-2,41,-7,LOG:1)
B(-4,41,-6,LOG:9)
B(-4,41,-5,LOG:9)
B(-2,42,-7,LOG:1)
B(-1,42,-7,LOG:5)
B(-8,43,-8,LOG:9)
B(-4,43,-8,LOG:9)
B(-8,43,-7,LOG:9)
B(-4,43,-7,LOG:9)
B(-2,43,-7,LOG:1)
B(-8,43,-6,LOG:9)
B(-4,43,-6,LOG:9)
B(-2,43,-6,LOG:9)
B(-8,43,-5,LOG:9)
B(-4,43,-5,LOG:9)
B(-2,43,-5,LOG:9)
B(-2,44,-7,LOG:1)
B(-4,45,-8,LOG:9)
B(-4,45,-7,LOG:9)
B(-3,45,-7,LOG:5)
B(-2,45,-7,LOG:1)
B(-4,45,-6,LOG:9)
B(-4,45,-5,LOG:9)
B(-2,46,-7,LOG:1)
B(-1,46,-7,LOG:5)
B(-8,47,-8,LOG:9)
B(-4,47,-8,LOG:9)
B(-8,47,-7,LOG:9)
B(-4,47,-7,LOG:9)
B(-2,47,-7,LOG:1)
B(-8,47,-6,LOG:9)
B(-4,47,-6,LOG:9)
B(-2,47,-6,LOG:9)
B(-8,47,-5,LOG:9)
B(-4,47,-5,LOG:9)
B(-2,47,-5,LOG:9)
B(-8,48,-8,LOG:9)
B(-4,48,-8,LOG:9)
B(-8,48,-7,LOG:9)
B(-4,48,-7,LOG:9)
B(-2,48,-7,LOG:1)
B(-8,48,-6,LOG:9)
B(-4,48,-6,LOG:9)
B(-2,48,-6,LOG:9)
B(-8,48,-5,LOG:9)
B(-4,48,-5,LOG:9)
B(-2,48,-5,LOG:9)
B(-2,49,-7,LOG:1)
B(-2,50,-7,LOG:1)
B(-2,50,-6,WOODEN_SLAB:8)
B(-1,50,-6,WOODEN_SLAB:8)
B(-2,50,-5,WOODEN_SLAB:8)
B(-1,50,-5,WOODEN_SLAB:8)
B(-8,51,-8,LOG:9)
B(-7,51,-8,WOODEN_SLAB:8)
B(-6,51,-8,WOODEN_SLAB:8)
B(-5,51,-8,WOODEN_SLAB:8)
B(-4,51,-8,LOG:9)
B(-8,51,-7,LOG:9)
B(-7,51,-7,WOODEN_SLAB:8)
B(-6,51,-7,WOODEN_SLAB:8)
B(-5,51,-7,WOODEN_SLAB:8)
B(-4,51,-7,LOG:9)
B(-3,51,-7,LOG:5)
B(-2,51,-7,LOG:5)
B(-1,51,-7,LOG:5)
B(-8,51,-6,LOG:9)
B(-7,51,-6,WOODEN_SLAB:8)
B(-6,51,-6,WOODEN_SLAB:8)
B(-5,51,-6,WOODEN_SLAB:8)
B(-4,51,-6,LOG:9)
B(-3,51,-6,WOODEN_SLAB:0)
B(-8,51,-5,LOG:9)
B(-7,51,-5,WOODEN_SLAB:8)
B(-6,51,-5,WOODEN_SLAB:8)
B(-5,51,-5,WOODEN_SLAB:8)
B(-4,51,-5,LOG:9)
B(-3,51,-5,WOODEN_SLAB:0)
B(-8,52,-8,DARK_OAK_STAIRS:3)
B(-5,52,-8,HAY_BLOCK:0)
B(-4,52,-8,SPRUCE_FENCE:0)
B(-5,52,-7,HAY_BLOCK:8)
B(-4,52,-7,SPRUCE_FENCE:0)
B(-3,52,-7,SPRUCE_FENCE:0)
B(-2,52,-7,STONE_BRICK_STAIRS:0)
B(-1,52,-7,STONE:6)
B(-5,53,-8,HAY_BLOCK:0)
B(-1,53,-7,STONE:6)
B(-1,54,-7,STONE_BRICK_STAIRS:0)
B(-6,55,-7,TRAPDOOR:12)
B(-1,55,-7,STONE_SLAB:0)
B(-7,55,-6,HAY_BLOCK:4)
B(-6,55,-6,HAY_BLOCK:4)
B(-5,55,-6,HAY_BLOCK:4)
B(-6,55,-5,TRAPDOOR:13)
B(-6,56,-6,SPRUCE_FENCE:0)
B(-6,57,-6,SPRUCE_FENCE:0)
B(-6,58,-6,SPRUCE_FENCE:0)
B(-6,59,-8,WOODEN_SLAB:9)
B(-6,59,-6,SPRUCE_FENCE:0)
B(-8,60,-8,OAK_STAIRS:5)
B(-6,60,-8,SPRUCE_FENCE:0)
B(-4,60,-8,OAK_STAIRS:4)
B(-3,60,-8,OAK_STAIRS:1)
B(-6,60,-7,SPRUCE_FENCE:0)
B(-6,60,-6,SPRUCE_FENCE:0)
B(-6,60,-5,SPRUCE_STAIRS:7)
B(-8,61,-8,OAK_STAIRS:0)
B(-7,61,-8,OAK_STAIRS:5)
B(-6,61,-8,WOODEN_SLAB:1)
B(-5,61,-8,OAK_STAIRS:4)
B(-4,61,-8,OAK_STAIRS:1)
B(-6,61,-7,WOODEN_SLAB:1)
B(-6,61,-6,WOODEN_SLAB:1)
B(-6,61,-5,WOODEN_SLAB:1)
B(-7,62,-8,OAK_STAIRS:0)
B(-6,62,-8,OAK_STAIRS:7)
B(-5,62,-8,OAK_STAIRS:1)
B(-6,63,-8,WOODEN_SLAB:0)

BR(-8,0,0,WestPort_7x8,NORTH,100)
