Author: Bo3 BulkEdit

Description: Converted Schematic - Modified by Bo3BulkEdit

Version: 3

SettingsMode: WriteDisable

IsOTGPlus: false
Tree: false
Frequency: 1
Rarity: 100
RotateRandomly: false
SpawnHeight: randomY
MaxBranchDepth: 20
ExcludedBiomes: All

MinHeight: 0
MaxHeight: 256

SourceBlocks: AIR
MaxPercentageOutsideSourceBlock: 100
OutsideSourceBlock: placeAnyway

B(-4,0,-5,LOG:1)
B(-8,0,-3,LOG:1)
B(-4,0,-3,LOG:1)
B(-2,0,-3,LOG:1)
B(-8,1,-8,LOG:9)
B(-8,1,-7,LOG:9)
B(-8,1,-6,LOG:9)
B(-8,1,-5,LOG:9)
B(-4,1,-5,LOG:1)
B(-8,1,-4,LOG:9)
B(-8,1,-3,LOG:1)
B(-7,1,-3,LOG:5)
B(-6,1,-3,LOG:5)
B(-5,1,-3,LOG:5)
B(-4,1,-3,LOG:1)
B(-2,1,-3,LOG:1)
B(-4,1,-2,LOG:9)
B(-2,1,-2,LOG:9)
B(-4,1,-1,LOG:9)
B(-2,1,-1,LOG:9)
B(-4,2,-5,LOG:1)
B(-8,2,-3,LOG:1)
B(-4,2,-3,LOG:1)
B(-2,2,-3,LOG:1)
B(-8,2,-2,LOG:9)
B(-8,2,-1,LOG:9)
B(-4,3,-5,LOG:1)
B(-8,3,-3,LOG:1)
B(-7,3,-3,LOG:5)
B(-6,3,-3,LOG:5)
B(-5,3,-3,LOG:5)
B(-4,3,-3,LOG:1)
B(-2,3,-3,LOG:1)
B(-4,3,-2,LOG:9)
B(-2,3,-2,LOG:9)
B(-4,3,-1,LOG:9)
B(-2,3,-1,LOG:9)
B(-4,4,-5,LOG:1)
B(-8,4,-3,LOG:1)
B(-4,4,-3,LOG:1)
B(-2,4,-3,LOG:1)
B(-8,5,-8,LOG:9)
B(-8,5,-7,LOG:9)
B(-8,5,-6,LOG:9)
B(-8,5,-5,LOG:9)
B(-4,5,-5,LOG:1)
B(-8,5,-4,LOG:9)
B(-8,5,-3,LOG:1)
B(-7,5,-3,LOG:5)
B(-6,5,-3,LOG:5)
B(-5,5,-3,LOG:5)
B(-4,5,-3,LOG:1)
B(-2,5,-3,LOG:1)
B(-4,5,-2,LOG:9)
B(-2,5,-2,LOG:9)
B(-4,5,-1,LOG:9)
B(-2,5,-1,LOG:9)
B(-4,6,-5,LOG:1)
B(-8,6,-3,LOG:1)
B(-4,6,-3,LOG:1)
B(-2,6,-3,LOG:1)
B(-8,6,-2,LOG:9)
B(-8,6,-1,LOG:9)
B(-4,7,-5,LOG:1)
B(-8,7,-3,LOG:1)
B(-7,7,-3,LOG:5)
B(-6,7,-3,LOG:5)
B(-5,7,-3,LOG:5)
B(-4,7,-3,LOG:1)
B(-2,7,-3,LOG:1)
B(-4,7,-2,LOG:9)
B(-2,7,-2,LOG:9)
B(-4,7,-1,LOG:9)
B(-2,7,-1,LOG:9)
B(-4,8,-5,LOG:1)
B(-8,8,-3,LOG:1)
B(-4,8,-3,LOG:1)
B(-2,8,-3,LOG:1)
B(-8,9,-8,LOG:9)
B(-8,9,-7,LOG:9)
B(-8,9,-6,LOG:9)
B(-8,9,-5,LOG:9)
B(-4,9,-5,LOG:1)
B(-8,9,-4,LOG:9)
B(-8,9,-3,LOG:1)
B(-7,9,-3,LOG:5)
B(-6,9,-3,LOG:5)
B(-5,9,-3,LOG:5)
B(-4,9,-3,LOG:1)
B(-2,9,-3,LOG:1)
B(-4,9,-2,LOG:9)
B(-2,9,-2,LOG:9)
B(-4,9,-1,LOG:9)
B(-2,9,-1,LOG:9)
B(-4,10,-5,LOG:1)
B(-8,10,-3,LOG:1)
B(-4,10,-3,LOG:1)
B(-2,10,-3,LOG:1)
B(-8,10,-2,LOG:9)
B(-8,10,-1,LOG:9)
B(-4,11,-5,LOG:1)
B(-8,11,-3,LOG:1)
B(-7,11,-3,LOG:5)
B(-6,11,-3,LOG:5)
B(-5,11,-3,LOG:5)
B(-4,11,-3,LOG:1)
B(-2,11,-3,LOG:1)
B(-4,11,-2,LOG:9)
B(-2,11,-2,LOG:9)
B(-4,11,-1,LOG:9)
B(-2,11,-1,LOG:9)
B(-4,12,-5,LOG:1)
B(-8,12,-3,LOG:1)
B(-4,12,-3,LOG:1)
B(-2,12,-3,LOG:1)
B(-8,13,-8,LOG:9)
B(-8,13,-7,LOG:9)
B(-8,13,-6,LOG:9)
B(-8,13,-5,LOG:9)
B(-4,13,-5,LOG:1)
B(-8,13,-4,LOG:9)
B(-8,13,-3,LOG:1)
B(-7,13,-3,LOG:5)
B(-6,13,-3,LOG:5)
B(-5,13,-3,LOG:5)
B(-4,13,-3,LOG:1)
B(-2,13,-3,LOG:1)
B(-4,13,-2,LOG:9)
B(-2,13,-2,LOG:9)
B(-4,13,-1,LOG:9)
B(-2,13,-1,LOG:9)
B(-4,14,-5,LOG:1)
B(-8,14,-3,LOG:1)
B(-4,14,-3,LOG:1)
B(-2,14,-3,LOG:1)
B(-8,14,-2,LOG:9)
B(-8,14,-1,LOG:9)
B(-4,15,-5,LOG:1)
B(-8,15,-3,LOG:1)
B(-7,15,-3,LOG:5)
B(-6,15,-3,LOG:5)
B(-5,15,-3,LOG:5)
B(-4,15,-3,LOG:1)
B(-2,15,-3,LOG:1)
B(-4,15,-2,LOG:9)
B(-2,15,-2,LOG:9)
B(-4,15,-1,LOG:9)
B(-2,15,-1,LOG:9)
B(-4,16,-5,LOG:1)
B(-8,16,-3,LOG:1)
B(-4,16,-3,LOG:1)
B(-2,16,-3,LOG:1)
B(-8,17,-8,LOG:9)
B(-8,17,-7,LOG:9)
B(-8,17,-6,LOG:9)
B(-8,17,-5,LOG:9)
B(-4,17,-5,LOG:1)
B(-8,17,-4,LOG:9)
B(-8,17,-3,LOG:1)
B(-7,17,-3,LOG:5)
B(-6,17,-3,LOG:5)
B(-5,17,-3,LOG:5)
B(-4,17,-3,LOG:1)
B(-2,17,-3,LOG:1)
B(-4,17,-2,LOG:9)
B(-2,17,-2,LOG:9)
B(-4,17,-1,LOG:9)
B(-2,17,-1,LOG:9)
B(-4,18,-5,LOG:1)
B(-8,18,-3,LOG:1)
B(-4,18,-3,LOG:1)
B(-2,18,-3,LOG:1)
B(-8,18,-2,LOG:9)
B(-8,18,-1,LOG:9)
B(-4,19,-5,LOG:1)
B(-8,19,-3,LOG:1)
B(-7,19,-3,LOG:5)
B(-6,19,-3,LOG:5)
B(-5,19,-3,LOG:5)
B(-4,19,-3,LOG:1)
B(-2,19,-3,LOG:1)
B(-4,19,-2,LOG:9)
B(-2,19,-2,LOG:9)
B(-4,19,-1,LOG:9)
B(-2,19,-1,LOG:9)
B(-4,20,-5,LOG:1)
B(-8,20,-3,LOG:1)
B(-4,20,-3,LOG:1)
B(-2,20,-3,LOG:1)
B(-8,21,-8,LOG:9)
B(-8,21,-7,LOG:9)
B(-8,21,-6,LOG:9)
B(-8,21,-5,LOG:9)
B(-4,21,-5,LOG:1)
B(-8,21,-4,LOG:9)
B(-8,21,-3,LOG:1)
B(-7,21,-3,LOG:5)
B(-6,21,-3,LOG:5)
B(-5,21,-3,LOG:5)
B(-4,21,-3,LOG:1)
B(-2,21,-3,LOG:1)
B(-4,21,-2,LOG:9)
B(-2,21,-2,LOG:9)
B(-4,21,-1,LOG:9)
B(-2,21,-1,LOG:9)
B(-4,22,-5,LOG:1)
B(-8,22,-3,LOG:1)
B(-4,22,-3,LOG:1)
B(-2,22,-3,LOG:1)
B(-8,22,-2,LOG:9)
B(-8,22,-1,LOG:9)
B(-4,23,-5,LOG:1)
B(-8,23,-3,LOG:1)
B(-7,23,-3,LOG:5)
B(-6,23,-3,LOG:5)
B(-5,23,-3,LOG:5)
B(-4,23,-3,LOG:1)
B(-2,23,-3,LOG:1)
B(-4,23,-2,LOG:9)
B(-2,23,-2,LOG:9)
B(-4,23,-1,LOG:9)
B(-2,23,-1,LOG:9)
B(-4,24,-5,LOG:1)
B(-8,24,-3,LOG:1)
B(-4,24,-3,LOG:1)
B(-2,24,-3,LOG:1)
B(-8,25,-8,LOG:9)
B(-8,25,-7,LOG:9)
B(-8,25,-6,LOG:9)
B(-8,25,-5,LOG:9)
B(-4,25,-5,LOG:1)
B(-8,25,-4,LOG:9)
B(-8,25,-3,LOG:1)
B(-7,25,-3,LOG:5)
B(-6,25,-3,LOG:5)
B(-5,25,-3,LOG:5)
B(-4,25,-3,LOG:1)
B(-2,25,-3,LOG:1)
B(-4,25,-2,LOG:9)
B(-2,25,-2,LOG:9)
B(-4,25,-1,LOG:9)
B(-2,25,-1,LOG:9)
B(-4,26,-5,LOG:1)
B(-8,26,-3,LOG:1)
B(-4,26,-3,LOG:1)
B(-2,26,-3,LOG:1)
B(-8,26,-2,LOG:9)
B(-8,26,-1,LOG:9)
B(-4,27,-5,LOG:1)
B(-8,27,-3,LOG:1)
B(-7,27,-3,LOG:5)
B(-6,27,-3,LOG:5)
B(-5,27,-3,LOG:5)
B(-4,27,-3,LOG:1)
B(-2,27,-3,LOG:1)
B(-4,27,-2,LOG:9)
B(-2,27,-2,LOG:9)
B(-4,27,-1,LOG:9)
B(-2,27,-1,LOG:9)
B(-4,28,-5,LOG:1)
B(-8,28,-3,LOG:1)
B(-4,28,-3,LOG:1)
B(-2,28,-3,LOG:1)
B(-8,29,-8,LOG:9)
B(-8,29,-7,LOG:9)
B(-8,29,-6,LOG:9)
B(-8,29,-5,LOG:9)
B(-4,29,-5,LOG:1)
B(-8,29,-4,LOG:9)
B(-8,29,-3,LOG:1)
B(-7,29,-3,LOG:5)
B(-6,29,-3,LOG:5)
B(-5,29,-3,LOG:5)
B(-4,29,-3,LOG:1)
B(-2,29,-3,LOG:1)
B(-4,29,-2,LOG:9)
B(-2,29,-2,LOG:9)
B(-4,29,-1,LOG:9)
B(-2,29,-1,LOG:9)
B(-4,30,-5,LOG:1)
B(-8,30,-3,LOG:1)
B(-4,30,-3,LOG:1)
B(-2,30,-3,LOG:1)
B(-8,30,-2,LOG:9)
B(-8,30,-1,LOG:9)
B(-4,31,-5,LOG:1)
B(-8,31,-3,LOG:1)
B(-7,31,-3,LOG:5)
B(-6,31,-3,LOG:5)
B(-5,31,-3,LOG:5)
B(-4,31,-3,LOG:1)
B(-2,31,-3,LOG:1)
B(-4,31,-2,LOG:9)
B(-2,31,-2,LOG:9)
B(-4,31,-1,LOG:9)
B(-2,31,-1,LOG:9)
B(-4,32,-5,LOG:1)
B(-8,32,-3,LOG:1)
B(-4,32,-3,LOG:1)
B(-2,32,-3,LOG:1)
B(-8,33,-8,LOG:9)
B(-8,33,-7,LOG:9)
B(-8,33,-6,LOG:9)
B(-8,33,-5,LOG:9)
B(-4,33,-5,LOG:1)
B(-8,33,-4,LOG:9)
B(-8,33,-3,LOG:1)
B(-7,33,-3,LOG:5)
B(-6,33,-3,LOG:5)
B(-5,33,-3,LOG:5)
B(-4,33,-3,LOG:1)
B(-2,33,-3,LOG:1)
B(-4,33,-2,LOG:9)
B(-2,33,-2,LOG:9)
B(-4,33,-1,LOG:9)
B(-2,33,-1,LOG:9)
B(-4,34,-5,LOG:1)
B(-8,34,-3,LOG:1)
B(-4,34,-3,LOG:1)
B(-2,34,-3,LOG:1)
B(-8,34,-2,LOG:9)
B(-8,34,-1,LOG:9)
B(-4,35,-5,LOG:1)
B(-8,35,-3,LOG:1)
B(-7,35,-3,LOG:5)
B(-6,35,-3,LOG:5)
B(-5,35,-3,LOG:5)
B(-4,35,-3,LOG:1)
B(-2,35,-3,LOG:1)
B(-4,35,-2,LOG:9)
B(-2,35,-2,LOG:9)
B(-4,35,-1,LOG:9)
B(-2,35,-1,LOG:9)
B(-4,36,-5,LOG:1)
B(-8,36,-3,LOG:1)
B(-4,36,-3,LOG:1)
B(-2,36,-3,LOG:1)
B(-8,37,-8,LOG:9)
B(-8,37,-7,LOG:9)
B(-8,37,-6,LOG:9)
B(-8,37,-5,LOG:9)
B(-4,37,-5,LOG:1)
B(-8,37,-4,LOG:9)
B(-8,37,-3,LOG:1)
B(-7,37,-3,LOG:5)
B(-6,37,-3,LOG:5)
B(-5,37,-3,LOG:5)
B(-4,37,-3,LOG:1)
B(-2,37,-3,LOG:1)
B(-4,37,-2,LOG:9)
B(-2,37,-2,LOG:9)
B(-4,37,-1,LOG:9)
B(-2,37,-1,LOG:9)
B(-4,38,-5,LOG:1)
B(-8,38,-3,LOG:1)
B(-4,38,-3,LOG:1)
B(-2,38,-3,LOG:1)
B(-8,38,-2,LOG:9)
B(-8,38,-1,LOG:9)
B(-4,39,-5,LOG:1)
B(-8,39,-3,LOG:1)
B(-7,39,-3,LOG:5)
B(-6,39,-3,LOG:5)
B(-5,39,-3,LOG:5)
B(-4,39,-3,LOG:1)
B(-2,39,-3,LOG:1)
B(-4,39,-2,LOG:9)
B(-2,39,-2,LOG:9)
B(-4,39,-1,LOG:9)
B(-2,39,-1,LOG:9)
B(-4,40,-5,LOG:1)
B(-8,40,-3,LOG:1)
B(-4,40,-3,LOG:1)
B(-2,40,-3,LOG:1)
B(-8,41,-8,LOG:9)
B(-8,41,-7,LOG:9)
B(-8,41,-6,LOG:9)
B(-8,41,-5,LOG:9)
B(-4,41,-5,LOG:1)
B(-8,41,-4,LOG:9)
B(-8,41,-3,LOG:1)
B(-7,41,-3,LOG:5)
B(-6,41,-3,LOG:5)
B(-5,41,-3,LOG:5)
B(-4,41,-3,LOG:1)
B(-2,41,-3,LOG:1)
B(-4,41,-2,LOG:9)
B(-2,41,-2,LOG:9)
B(-4,41,-1,LOG:9)
B(-2,41,-1,LOG:9)
B(-4,42,-5,LOG:1)
B(-8,42,-3,LOG:1)
B(-4,42,-3,LOG:1)
B(-2,42,-3,LOG:1)
B(-8,42,-2,LOG:9)
B(-8,42,-1,LOG:9)
B(-4,43,-5,LOG:1)
B(-8,43,-3,LOG:1)
B(-7,43,-3,LOG:5)
B(-6,43,-3,LOG:5)
B(-5,43,-3,LOG:5)
B(-4,43,-3,LOG:1)
B(-2,43,-3,LOG:1)
B(-4,43,-2,LOG:9)
B(-2,43,-2,LOG:9)
B(-4,43,-1,LOG:9)
B(-2,43,-1,LOG:9)
B(-4,44,-5,LOG:1)
B(-8,44,-3,LOG:1)
B(-4,44,-3,LOG:1)
B(-2,44,-3,LOG:1)
B(-8,45,-8,LOG:9)
B(-8,45,-7,LOG:9)
B(-8,45,-6,LOG:9)
B(-8,45,-5,LOG:9)
B(-4,45,-5,LOG:1)
B(-8,45,-4,LOG:9)
B(-8,45,-3,LOG:1)
B(-7,45,-3,LOG:5)
B(-6,45,-3,LOG:5)
B(-5,45,-3,LOG:5)
B(-4,45,-3,LOG:1)
B(-2,45,-3,LOG:1)
B(-4,45,-2,LOG:9)
B(-2,45,-2,LOG:9)
B(-4,45,-1,LOG:9)
B(-2,45,-1,LOG:9)
B(-4,46,-5,LOG:1)
B(-8,46,-3,LOG:1)
B(-4,46,-3,LOG:1)
B(-2,46,-3,LOG:1)
B(-8,46,-2,LOG:9)
B(-8,46,-1,LOG:9)
B(-4,47,-5,LOG:1)
B(-8,47,-3,LOG:1)
B(-7,47,-3,LOG:5)
B(-6,47,-3,LOG:5)
B(-5,47,-3,LOG:5)
B(-4,47,-3,LOG:1)
B(-2,47,-3,LOG:1)
B(-4,47,-2,LOG:9)
B(-2,47,-2,LOG:9)
B(-4,47,-1,LOG:9)
B(-2,47,-1,LOG:9)
B(-4,48,-5,LOG:1)
B(-8,48,-3,LOG:1)
B(-7,48,-3,LOG:5)
B(-6,48,-3,LOG:5)
B(-5,48,-3,LOG:5)
B(-4,48,-3,LOG:1)
B(-2,48,-3,LOG:1)
B(-4,48,-2,LOG:9)
B(-2,48,-2,LOG:9)
B(-4,48,-1,LOG:9)
B(-2,48,-1,LOG:9)
B(-4,49,-5,LOG:1)
B(-8,49,-3,LOG:1)
B(-4,49,-3,LOG:1)
B(-2,49,-3,LOG:1)
B(-4,50,-5,LOG:1)
B(-8,50,-3,LOG:1)
B(-4,50,-3,LOG:1)
B(-2,50,-3,LOG:1)
B(-8,50,-2,LOG:9)
B(-8,50,-1,LOG:9)
B(-8,51,-8,LOG:9)
B(-8,51,-7,LOG:9)
B(-8,51,-6,LOG:9)
B(-8,51,-5,LOG:9)
B(-4,51,-5,STONE_BRICK_STAIRS:2)
B(-8,51,-4,LOG:9)
B(-4,51,-4,LOG:9)
B(-8,51,-3,LOG:1)
B(-4,51,-3,LOG:1)
B(-3,51,-3,LOG:5)
B(-2,51,-3,STONE_BRICK_STAIRS:1)
B(-8,51,-2,PLANKS:0)
B(-4,51,-2,LOG:9)
B(-8,51,-1,PLANKS:0)
B(-4,51,-1,LOG:9)
B(-8,52,-8,DARK_OAK_STAIRS:7)
B(-8,52,-7,WOODEN_SLAB:5)
B(-8,52,-6,WOODEN_SLAB:5)
B(-8,52,-5,WOODEN_SLAB:5)
B(-8,52,-4,DARK_OAK_STAIRS:6)
B(-4,52,-4,STONE_BRICK_STAIRS:6)
B(-8,52,-3,LOG:1)
B(-4,52,-3,LOG:1)
B(-3,52,-3,STONE_BRICK_STAIRS:5)
B(-8,52,-2,PLANKS:0)
B(-8,52,-1,DARK_OAK_FENCE:0)
B(-8,53,-8,LOG:9)
B(-7,53,-8,WOODEN_BUTTON:1)
B(-8,53,-7,LOG:9)
B(-7,53,-7,WOODEN_BUTTON:1)
B(-8,53,-6,LOG:9)
B(-7,53,-6,WOODEN_BUTTON:1)
B(-8,53,-5,LOG:9)
B(-7,53,-5,WOODEN_BUTTON:1)
B(-8,53,-4,LOG:9)
B(-6,53,-4,WOODEN_BUTTON:4)
B(-5,53,-4,WOODEN_BUTTON:4)
B(-4,53,-4,STONE:6)
B(-8,53,-3,LOG:1)
B(-7,53,-3,LOG:5)
B(-6,53,-3,LOG:5)
B(-5,53,-3,LOG:5)
B(-4,53,-3,LOG:1)
B(-3,53,-3,STONE:6)
B(-8,53,-2,DOUBLE_STONE_SLAB:0)
B(-7,53,-2,STONE_SLAB:8)
B(-6,53,-2,STONE_SLAB:8)
B(-5,53,-2,STONE_SLAB:8)
B(-4,53,-2,LOG:9)
B(-3,53,-2,WOODEN_BUTTON:1)
B(-8,53,-1,DOUBLE_STONE_SLAB:0)
B(-7,53,-1,STONE_SLAB:8)
B(-6,53,-1,STONE_SLAB:8)
B(-5,53,-1,STONE_SLAB:8)
B(-4,53,-1,LOG:9)
B(-3,53,-1,WOODEN_BUTTON:1)
B(-8,54,-8,STONEBRICK:3)
B(-8,54,-7,SPRUCE_FENCE:0)
B(-8,54,-6,SPRUCE_FENCE:0)
B(-8,54,-5,SPRUCE_FENCE:0)
B(-8,54,-4,SPRUCE_FENCE:0)
B(-4,54,-4,STONE_BRICK_STAIRS:2)
B(-8,54,-3,STONEBRICK:3)
B(-7,54,-3,SPRUCE_FENCE:0)
B(-6,54,-3,SPRUCE_FENCE:0)
B(-5,54,-3,SPRUCE_FENCE:0)
B(-4,54,-3,STONEBRICK:3)
B(-3,54,-3,STONE_BRICK_STAIRS:1)
B(-8,54,-2,IRON_ORE:0)
B(-7,54,-2,IRON_ORE:0)
B(-6,54,-2,IRON_ORE:0)
B(-5,54,-2,IRON_ORE:0)
B(-4,54,-2,SPRUCE_FENCE:0)
B(-7,54,-1,IRON_ORE:0)
B(-6,54,-1,IRON_ORE:0)
B(-5,54,-1,IRON_ORE:0)
B(-4,54,-1,SPRUCE_FENCE:0)
B(-3,54,-1,WOODEN_BUTTON:4)
B(-2,54,-1,WOODEN_BUTTON:4)
B(-1,54,-1,WOODEN_BUTTON:4)
B(-8,55,-8,STONE_SLAB:0)
B(-8,55,-3,STONE_SLAB:0)
B(-4,55,-3,STONE_SLAB:0)
B(-6,55,-1,IRON_ORE:0)

BR(-8,0,0,WestPort_9x7,NORTH,100)
BR(8,0,0,WestPort_11x7,NORTH,100)
BR(0,0,8,WestPort_10x8,NORTH,100)
