Author: Bo3 BulkEdit

Description: Converted Schematic - Modified by Bo3BulkEdit

Version: 3

SettingsMode: WriteDisable

IsOTGPlus: false
Tree: false
Frequency: 1
Rarity: 100
RotateRandomly: false
SpawnHeight: randomY
MaxBranchDepth: 20
ExcludedBiomes: All

MinHeight: 0
MaxHeight: 256

SourceBlocks: AIR
MaxPercentageOutsideSourceBlock: 100
OutsideSourceBlock: placeAnyway

B(-8,0,-7,LOG:1)
B(-4,0,-7,LOG:1)
B(-1,0,-7,LOG:1)
B(-7,0,-3,LOG:1)
B(-3,0,-3,LOG:1)
B(-8,1,-7,LOG:1)
B(-4,1,-7,LOG:1)
B(-1,1,-7,LOG:1)
B(-7,1,-3,LOG:1)
B(-6,1,-3,LOG:5)
B(-5,1,-3,LOG:5)
B(-4,1,-3,LOG:5)
B(-3,1,-3,LOG:1)
B(-4,2,-8,LOG:9)
B(-8,2,-7,LOG:1)
B(-4,2,-7,LOG:1)
B(-1,2,-7,LOG:1)
B(-8,2,-3,LOG:5)
B(-7,2,-3,LOG:1)
B(-3,2,-3,LOG:1)
B(-6,3,-8,LOG:9)
B(-1,3,-8,LOG:9)
B(-8,3,-7,LOG:1)
B(-7,3,-7,LOG:5)
B(-6,3,-7,LOG:5)
B(-5,3,-7,LOG:5)
B(-4,3,-7,LOG:1)
B(-1,3,-7,LOG:1)
B(-7,3,-3,LOG:1)
B(-3,3,-3,LOG:1)
B(-2,3,-3,LOG:5)
B(-1,3,-3,LOG:5)
B(-7,3,-2,LOG:9)
B(-3,3,-2,LOG:9)
B(-7,3,-1,LOG:9)
B(-3,3,-1,LOG:9)
B(-8,4,-7,LOG:1)
B(-4,4,-7,LOG:1)
B(-1,4,-7,LOG:1)
B(-7,4,-3,LOG:1)
B(-3,4,-3,LOG:1)
B(-8,5,-7,LOG:1)
B(-4,5,-7,LOG:1)
B(-1,5,-7,LOG:1)
B(-7,5,-3,LOG:1)
B(-6,5,-3,LOG:5)
B(-5,5,-3,LOG:5)
B(-4,5,-3,LOG:5)
B(-3,5,-3,LOG:1)
B(-4,6,-8,LOG:9)
B(-8,6,-7,LOG:1)
B(-4,6,-7,LOG:1)
B(-1,6,-7,LOG:1)
B(-8,6,-3,LOG:5)
B(-7,6,-3,LOG:1)
B(-3,6,-3,LOG:1)
B(-6,7,-8,LOG:9)
B(-1,7,-8,LOG:9)
B(-8,7,-7,LOG:1)
B(-7,7,-7,LOG:5)
B(-6,7,-7,LOG:5)
B(-5,7,-7,LOG:5)
B(-4,7,-7,LOG:1)
B(-1,7,-7,LOG:1)
B(-7,7,-3,LOG:1)
B(-3,7,-3,LOG:1)
B(-2,7,-3,LOG:5)
B(-1,7,-3,LOG:5)
B(-7,7,-2,LOG:9)
B(-3,7,-2,LOG:9)
B(-7,7,-1,LOG:9)
B(-3,7,-1,LOG:9)
B(-8,8,-7,LOG:1)
B(-4,8,-7,LOG:1)
B(-1,8,-7,LOG:1)
B(-7,8,-3,LOG:1)
B(-3,8,-3,LOG:1)
B(-8,9,-7,LOG:1)
B(-4,9,-7,LOG:1)
B(-1,9,-7,LOG:1)
B(-7,9,-3,LOG:1)
B(-6,9,-3,LOG:5)
B(-5,9,-3,LOG:5)
B(-4,9,-3,LOG:5)
B(-3,9,-3,LOG:1)
B(-4,10,-8,LOG:9)
B(-8,10,-7,LOG:1)
B(-4,10,-7,LOG:1)
B(-1,10,-7,LOG:1)
B(-8,10,-3,LOG:5)
B(-7,10,-3,LOG:1)
B(-3,10,-3,LOG:1)
B(-6,11,-8,LOG:9)
B(-1,11,-8,LOG:9)
B(-8,11,-7,LOG:1)
B(-7,11,-7,LOG:5)
B(-6,11,-7,LOG:5)
B(-5,11,-7,LOG:5)
B(-4,11,-7,LOG:1)
B(-1,11,-7,LOG:1)
B(-7,11,-3,LOG:1)
B(-3,11,-3,LOG:1)
B(-2,11,-3,LOG:5)
B(-1,11,-3,LOG:5)
B(-7,11,-2,LOG:9)
B(-3,11,-2,LOG:9)
B(-7,11,-1,LOG:9)
B(-3,11,-1,LOG:9)
B(-8,12,-7,LOG:1)
B(-4,12,-7,LOG:1)
B(-1,12,-7,LOG:1)
B(-7,12,-3,LOG:1)
B(-3,12,-3,LOG:1)
B(-8,13,-7,LOG:1)
B(-4,13,-7,LOG:1)
B(-1,13,-7,LOG:1)
B(-7,13,-3,LOG:1)
B(-6,13,-3,LOG:5)
B(-5,13,-3,LOG:5)
B(-4,13,-3,LOG:5)
B(-3,13,-3,LOG:1)
B(-4,14,-8,LOG:9)
B(-8,14,-7,LOG:1)
B(-4,14,-7,LOG:1)
B(-1,14,-7,LOG:1)
B(-8,14,-3,LOG:5)
B(-7,14,-3,LOG:1)
B(-3,14,-3,LOG:1)
B(-6,15,-8,LOG:9)
B(-1,15,-8,LOG:9)
B(-8,15,-7,LOG:1)
B(-7,15,-7,LOG:5)
B(-6,15,-7,LOG:5)
B(-5,15,-7,LOG:5)
B(-4,15,-7,LOG:1)
B(-1,15,-7,LOG:1)
B(-7,15,-3,LOG:1)
B(-3,15,-3,LOG:1)
B(-2,15,-3,LOG:5)
B(-1,15,-3,LOG:5)
B(-7,15,-2,LOG:9)
B(-3,15,-2,LOG:9)
B(-7,15,-1,LOG:9)
B(-3,15,-1,LOG:9)
B(-8,16,-7,LOG:1)
B(-4,16,-7,LOG:1)
B(-1,16,-7,LOG:1)
B(-7,16,-3,LOG:1)
B(-3,16,-3,LOG:1)
B(-8,17,-7,LOG:1)
B(-4,17,-7,LOG:1)
B(-1,17,-7,LOG:1)
B(-7,17,-3,LOG:1)
B(-6,17,-3,LOG:5)
B(-5,17,-3,LOG:5)
B(-4,17,-3,LOG:5)
B(-3,17,-3,LOG:1)
B(-4,18,-8,LOG:9)
B(-8,18,-7,LOG:1)
B(-4,18,-7,LOG:1)
B(-1,18,-7,LOG:1)
B(-8,18,-3,LOG:5)
B(-7,18,-3,LOG:1)
B(-3,18,-3,LOG:1)
B(-6,19,-8,LOG:9)
B(-1,19,-8,LOG:9)
B(-8,19,-7,LOG:1)
B(-7,19,-7,LOG:5)
B(-6,19,-7,LOG:5)
B(-5,19,-7,LOG:5)
B(-4,19,-7,LOG:1)
B(-1,19,-7,LOG:1)
B(-7,19,-3,LOG:1)
B(-3,19,-3,LOG:1)
B(-2,19,-3,LOG:5)
B(-1,19,-3,LOG:5)
B(-7,19,-2,LOG:9)
B(-3,19,-2,LOG:9)
B(-7,19,-1,LOG:9)
B(-3,19,-1,LOG:9)
B(-8,20,-7,LOG:1)
B(-4,20,-7,LOG:1)
B(-1,20,-7,LOG:1)
B(-7,20,-3,LOG:1)
B(-3,20,-3,LOG:1)
B(-8,21,-7,LOG:1)
B(-4,21,-7,LOG:1)
B(-1,21,-7,LOG:1)
B(-7,21,-3,LOG:1)
B(-6,21,-3,LOG:5)
B(-5,21,-3,LOG:5)
B(-4,21,-3,LOG:5)
B(-3,21,-3,LOG:1)
B(-4,22,-8,LOG:9)
B(-8,22,-7,LOG:1)
B(-4,22,-7,LOG:1)
B(-1,22,-7,LOG:1)
B(-8,22,-3,LOG:5)
B(-7,22,-3,LOG:1)
B(-3,22,-3,LOG:1)
B(-6,23,-8,LOG:9)
B(-1,23,-8,LOG:9)
B(-8,23,-7,LOG:1)
B(-7,23,-7,LOG:5)
B(-6,23,-7,LOG:5)
B(-5,23,-7,LOG:5)
B(-4,23,-7,LOG:1)
B(-1,23,-7,LOG:1)
B(-7,23,-3,LOG:1)
B(-3,23,-3,LOG:1)
B(-2,23,-3,LOG:5)
B(-1,23,-3,LOG:5)
B(-7,23,-2,LOG:9)
B(-3,23,-2,LOG:9)
B(-7,23,-1,LOG:9)
B(-3,23,-1,LOG:9)
B(-8,24,-7,LOG:1)
B(-4,24,-7,LOG:1)
B(-1,24,-7,LOG:1)
B(-7,24,-3,LOG:1)
B(-3,24,-3,LOG:1)
B(-8,25,-7,LOG:1)
B(-4,25,-7,LOG:1)
B(-1,25,-7,LOG:1)
B(-7,25,-3,LOG:1)
B(-6,25,-3,LOG:5)
B(-5,25,-3,LOG:5)
B(-4,25,-3,LOG:5)
B(-3,25,-3,LOG:1)
B(-4,26,-8,LOG:9)
B(-8,26,-7,LOG:1)
B(-4,26,-7,LOG:1)
B(-1,26,-7,LOG:1)
B(-8,26,-3,LOG:5)
B(-7,26,-3,LOG:1)
B(-3,26,-3,LOG:1)
B(-6,27,-8,LOG:9)
B(-1,27,-8,LOG:9)
B(-8,27,-7,LOG:1)
B(-7,27,-7,LOG:5)
B(-6,27,-7,LOG:5)
B(-5,27,-7,LOG:5)
B(-4,27,-7,LOG:1)
B(-1,27,-7,LOG:1)
B(-7,27,-3,LOG:1)
B(-3,27,-3,LOG:1)
B(-2,27,-3,LOG:5)
B(-1,27,-3,LOG:5)
B(-7,27,-2,LOG:9)
B(-3,27,-2,LOG:9)
B(-7,27,-1,LOG:9)
B(-3,27,-1,LOG:9)
B(-8,28,-7,LOG:1)
B(-4,28,-7,LOG:1)
B(-1,28,-7,LOG:1)
B(-7,28,-3,LOG:1)
B(-3,28,-3,LOG:1)
B(-8,29,-7,LOG:1)
B(-4,29,-7,LOG:1)
B(-1,29,-7,LOG:1)
B(-7,29,-3,LOG:1)
B(-6,29,-3,LOG:5)
B(-5,29,-3,LOG:5)
B(-4,29,-3,LOG:5)
B(-3,29,-3,LOG:1)
B(-4,30,-8,LOG:9)
B(-8,30,-7,LOG:1)
B(-4,30,-7,LOG:1)
B(-1,30,-7,LOG:1)
B(-8,30,-3,LOG:5)
B(-7,30,-3,LOG:1)
B(-3,30,-3,LOG:1)
B(-6,31,-8,LOG:9)
B(-1,31,-8,LOG:9)
B(-8,31,-7,LOG:1)
B(-7,31,-7,LOG:5)
B(-6,31,-7,LOG:5)
B(-5,31,-7,LOG:5)
B(-4,31,-7,LOG:1)
B(-1,31,-7,LOG:1)
B(-7,31,-3,LOG:1)
B(-3,31,-3,LOG:1)
B(-2,31,-3,LOG:5)
B(-1,31,-3,LOG:5)
B(-7,31,-2,LOG:9)
B(-3,31,-2,LOG:9)
B(-7,31,-1,LOG:9)
B(-3,31,-1,LOG:9)
B(-8,32,-7,LOG:1)
B(-4,32,-7,LOG:1)
B(-1,32,-7,LOG:1)
B(-7,32,-3,LOG:1)
B(-3,32,-3,LOG:1)
B(-8,33,-7,LOG:1)
B(-4,33,-7,LOG:1)
B(-1,33,-7,LOG:1)
B(-7,33,-3,LOG:1)
B(-6,33,-3,LOG:5)
B(-5,33,-3,LOG:5)
B(-4,33,-3,LOG:5)
B(-3,33,-3,LOG:1)
B(-4,34,-8,LOG:9)
B(-8,34,-7,LOG:1)
B(-4,34,-7,LOG:1)
B(-1,34,-7,LOG:1)
B(-8,34,-3,LOG:5)
B(-7,34,-3,LOG:1)
B(-3,34,-3,LOG:1)
B(-6,35,-8,LOG:9)
B(-1,35,-8,LOG:9)
B(-8,35,-7,LOG:1)
B(-7,35,-7,LOG:5)
B(-6,35,-7,LOG:5)
B(-5,35,-7,LOG:5)
B(-4,35,-7,LOG:1)
B(-1,35,-7,LOG:1)
B(-7,35,-3,LOG:1)
B(-3,35,-3,LOG:1)
B(-2,35,-3,LOG:5)
B(-1,35,-3,LOG:5)
B(-7,35,-2,LOG:9)
B(-3,35,-2,LOG:9)
B(-7,35,-1,LOG:9)
B(-3,35,-1,LOG:9)
B(-8,36,-7,LOG:1)
B(-4,36,-7,LOG:1)
B(-1,36,-7,LOG:1)
B(-7,36,-3,LOG:1)
B(-3,36,-3,LOG:1)
B(-8,37,-7,LOG:1)
B(-4,37,-7,LOG:1)
B(-1,37,-7,LOG:1)
B(-7,37,-3,LOG:1)
B(-6,37,-3,LOG:5)
B(-5,37,-3,LOG:5)
B(-4,37,-3,LOG:5)
B(-3,37,-3,LOG:1)
B(-4,38,-8,LOG:9)
B(-8,38,-7,LOG:1)
B(-4,38,-7,LOG:1)
B(-1,38,-7,LOG:1)
B(-8,38,-3,LOG:5)
B(-7,38,-3,LOG:1)
B(-3,38,-3,LOG:1)
B(-6,39,-8,LOG:9)
B(-1,39,-8,LOG:9)
B(-8,39,-7,LOG:1)
B(-7,39,-7,LOG:5)
B(-6,39,-7,LOG:5)
B(-5,39,-7,LOG:5)
B(-4,39,-7,LOG:1)
B(-1,39,-7,LOG:1)
B(-7,39,-3,LOG:1)
B(-3,39,-3,LOG:1)
B(-2,39,-3,LOG:5)
B(-1,39,-3,LOG:5)
B(-7,39,-2,LOG:9)
B(-3,39,-2,LOG:9)
B(-7,39,-1,LOG:9)
B(-3,39,-1,LOG:9)
B(-8,40,-7,LOG:1)
B(-4,40,-7,LOG:1)
B(-1,40,-7,LOG:1)
B(-7,40,-3,LOG:1)
B(-3,40,-3,LOG:1)
B(-8,41,-7,LOG:1)
B(-4,41,-7,LOG:1)
B(-1,41,-7,LOG:1)
B(-7,41,-3,LOG:1)
B(-6,41,-3,LOG:5)
B(-5,41,-3,LOG:5)
B(-4,41,-3,LOG:5)
B(-3,41,-3,LOG:1)
B(-4,42,-8,LOG:9)
B(-8,42,-7,LOG:1)
B(-4,42,-7,LOG:1)
B(-1,42,-7,LOG:1)
B(-8,42,-3,LOG:5)
B(-7,42,-3,LOG:1)
B(-3,42,-3,LOG:1)
B(-6,43,-8,LOG:9)
B(-1,43,-8,LOG:9)
B(-8,43,-7,LOG:1)
B(-7,43,-7,LOG:5)
B(-6,43,-7,LOG:5)
B(-5,43,-7,LOG:5)
B(-4,43,-7,LOG:1)
B(-1,43,-7,LOG:1)
B(-7,43,-3,LOG:1)
B(-3,43,-3,LOG:1)
B(-2,43,-3,LOG:5)
B(-1,43,-3,LOG:5)
B(-7,43,-2,LOG:9)
B(-3,43,-2,LOG:9)
B(-7,43,-1,LOG:9)
B(-3,43,-1,LOG:9)
B(-8,44,-7,LOG:1)
B(-4,44,-7,LOG:1)
B(-1,44,-7,LOG:1)
B(-7,44,-3,LOG:1)
B(-3,44,-3,LOG:1)
B(-8,45,-7,LOG:1)
B(-4,45,-7,LOG:1)
B(-1,45,-7,LOG:1)
B(-7,45,-3,LOG:1)
B(-6,45,-3,LOG:5)
B(-5,45,-3,LOG:5)
B(-4,45,-3,LOG:5)
B(-3,45,-3,LOG:1)
B(-4,46,-8,LOG:9)
B(-8,46,-7,LOG:1)
B(-4,46,-7,LOG:1)
B(-1,46,-7,LOG:1)
B(-8,46,-3,LOG:5)
B(-7,46,-3,LOG:1)
B(-3,46,-3,LOG:1)
B(-6,47,-8,LOG:9)
B(-1,47,-8,LOG:9)
B(-8,47,-7,LOG:1)
B(-7,47,-7,LOG:5)
B(-6,47,-7,LOG:5)
B(-5,47,-7,LOG:5)
B(-4,47,-7,LOG:1)
B(-1,47,-7,LOG:1)
B(-7,47,-3,LOG:1)
B(-3,47,-3,LOG:1)
B(-2,47,-3,LOG:5)
B(-1,47,-3,LOG:5)
B(-7,47,-2,LOG:9)
B(-3,47,-2,LOG:9)
B(-7,47,-1,LOG:9)
B(-3,47,-1,LOG:9)
B(-6,48,-8,LOG:9)
B(-1,48,-8,LOG:9)
B(-8,48,-7,LOG:1)
B(-7,48,-7,LOG:5)
B(-6,48,-7,LOG:5)
B(-5,48,-7,LOG:5)
B(-4,48,-7,LOG:1)
B(-1,48,-7,LOG:1)
B(-7,48,-3,LOG:1)
B(-3,48,-3,LOG:1)
B(-2,48,-3,LOG:5)
B(-1,48,-3,LOG:5)
B(-7,48,-2,LOG:9)
B(-3,48,-2,LOG:9)
B(-7,48,-1,LOG:9)
B(-3,48,-1,LOG:9)
B(-8,49,-7,LOG:1)
B(-4,49,-7,LOG:1)
B(-1,49,-7,LOG:1)
B(-7,49,-3,LOG:1)
B(-3,49,-3,LOG:1)
B(-8,50,-7,LOG:1)
B(-4,50,-7,LOG:1)
B(-1,50,-7,LOG:1)
B(-7,50,-3,LOG:1)
B(-3,50,-3,LOG:1)
B(-4,51,-8,LOG:5)
B(-3,51,-8,LOG:5)
B(-2,51,-8,LOG:5)
B(-1,51,-8,LOG:9)
B(-8,51,-7,LOG:1)
B(-4,51,-7,LOG:1)
B(-3,51,-7,WOODEN_SLAB:9)
B(-2,51,-7,SPRUCE_STAIRS:4)
B(-1,51,-7,LOG:1)
B(-4,51,-6,SPRUCE_STAIRS:7)
B(-3,51,-6,WOODEN_SLAB:9)
B(-2,51,-6,WOODEN_SLAB:9)
B(-1,51,-6,SPRUCE_STAIRS:7)
B(-8,51,-4,WOODEN_SLAB:8)
B(-7,51,-4,SPRUCE_STAIRS:6)
B(-6,51,-4,WOODEN_SLAB:8)
B(-5,51,-4,WOODEN_SLAB:8)
B(-4,51,-4,WOODEN_SLAB:8)
B(-3,51,-4,SPRUCE_STAIRS:6)
B(-2,51,-4,WOODEN_SLAB:8)
B(-1,51,-4,WOODEN_SLAB:8)
B(-8,51,-3,LOG:5)
B(-7,51,-3,LOG:1)
B(-6,51,-3,LOG:5)
B(-5,51,-3,LOG:5)
B(-4,51,-3,LOG:5)
B(-3,51,-3,LOG:1)
B(-2,51,-3,LOG:5)
B(-1,51,-3,LOG:5)
B(-8,51,-2,WOODEN_SLAB:8)
B(-7,51,-2,LOG:9)
B(-6,51,-2,WOODEN_SLAB:8)
B(-5,51,-2,WOODEN_SLAB:8)
B(-4,51,-2,WOODEN_SLAB:8)
B(-3,51,-2,WOODEN_SLAB:8)
B(-2,51,-2,WOODEN_SLAB:8)
B(-1,51,-2,WOODEN_SLAB:8)
B(-8,51,-1,WOODEN_SLAB:8)
B(-7,51,-1,LOG:9)
B(-6,51,-1,WOODEN_SLAB:8)
B(-5,51,-1,WOODEN_SLAB:8)
B(-4,51,-1,WOODEN_SLAB:8)
B(-3,51,-1,WOODEN_SLAB:8)
B(-2,51,-1,WOODEN_SLAB:8)
B(-1,51,-1,WOODEN_SLAB:8)
B(-8,52,-8,WOODEN_SLAB:8)
B(-7,52,-8,WOODEN_SLAB:8)
B(-6,52,-8,WOODEN_SLAB:8)
B(-5,52,-8,WOODEN_SLAB:8)
B(-4,52,-8,LOG:9)
B(-3,52,-8,WOODEN_SLAB:1)
B(-1,52,-8,COBBLESTONE:0)
B(-8,52,-7,LOG:1)
B(-7,52,-7,LOG:5)
B(-6,52,-7,LOG:5)
B(-5,52,-7,LOG:5)
B(-4,52,-7,LOG:1)
B(-1,52,-7,LOG:1)
B(-5,52,-6,OAK_STAIRS:4)
B(-4,52,-6,OAK_STAIRS:1)
B(-8,52,-3,SPRUCE_FENCE:0)
B(-7,52,-3,LOG:1)
B(-6,52,-3,COBBLESTONE:0)
B(-5,52,-3,COBBLESTONE:0)
B(-4,52,-3,COBBLESTONE:0)
B(-3,52,-3,LOG:1)
B(-2,52,-3,COBBLESTONE:0)
B(-1,52,-3,COBBLESTONE:0)
B(-7,52,-2,COBBLESTONE:0)
B(-6,52,-2,BRICK_BLOCK:0)
B(-5,52,-2,CARPET:8)
B(-4,52,-2,BIRCH_STAIRS:0)
B(-3,52,-2,PLANKS:1)
B(-2,52,-2,BIRCH_STAIRS:5)
B(-1,52,-2,WOODEN_SLAB:10)
B(-7,52,-1,DARK_OAK_DOOR:2)
B(-6,52,-1,CARPET:8)
B(-4,52,-1,BIRCH_STAIRS:0)
B(-3,52,-1,PLANKS:1)
B(-2,52,-1,CRAFTING_TABLE:0)
B(-1,52,-1,CARPET:8)
B(-8,53,-8,BIRCH_STAIRS:2)
B(-7,53,-8,TRAPDOOR:7)
B(-6,53,-8,CARPET:1)
B(-5,53,-8,BOOKSHELF:0)
B(-4,53,-8,COBBLESTONE:0)
B(-1,53,-8,PLANKS:1)
B(-8,53,-7,LOG:1)
B(-7,53,-7,COBBLESTONE:0)
B(-6,53,-7,COBBLESTONE:0)
B(-5,53,-7,COBBLESTONE:0)
B(-4,53,-7,LOG:1)
B(-1,53,-7,LOG:1)
B(-6,53,-6,OAK_STAIRS:4)
B(-5,53,-6,OAK_STAIRS:1)
B(-7,53,-3,LOG:1)
B(-6,53,-3,PLANKS:1)
B(-5,53,-3,DARK_OAK_FENCE:0)
B(-4,53,-3,PLANKS:1)
B(-3,53,-3,LOG:1)
B(-2,53,-3,PLANKS:1)
B(-1,53,-3,DARK_OAK_FENCE:0)
B(-7,53,-2,COBBLESTONE:0)
RB(-6,53,-2,FLOWER_POT:0,../NBT/Flowers/flower_pot_01.nbt,5,FLOWER_POT:0,../NBT/Flowers/flower_pot_02.nbt,5,FLOWER_POT:0,../NBT/Flowers/flower_pot_03.nbt,5,FLOWER_POT:0,../NBT/Flowers/flower_pot_04.nbt,5,FLOWER_POT:0,../NBT/Flowers/flower_pot_05.nbt,5,FLOWER_POT:0,../NBT/Flowers/flower_pot_06.nbt,5,FLOWER_POT:0,../NBT/Flowers/flower_pot_07.nbt,5,FLOWER_POT:0,../NBT/Flowers/flower_pot_08.nbt,5,FLOWER_POT:0,../NBT/Flowers/flower_pot_09.nbt,5,FLOWER_POT:0,../NBT/Flowers/flower_pot_10.nbt,5,FLOWER_POT:0,../NBT/Flowers/flower_pot_11.nbt,5,FLOWER_POT:0,../NBT/Flowers/flower_pot_12.nbt,5,FLOWER_POT:0,../NBT/Flowers/flower_pot_13.nbt,5,FLOWER_POT:0,../NBT/Flowers/flower_pot_14.nbt,5,FLOWER_POT:0,../NBT/Flowers/flower_pot_15.nbt,5,FLOWER_POT:0,../NBT/Flowers/flower_pot_16.nbt,5,FLOWER_POT:0,../NBT/Flowers/flower_pot_17.nbt,5,FLOWER_POT:0,../NBT/Flowers/flower_pot_18.nbt,5,FLOWER_POT:0,../NBT/Flowers/flower_pot_19.nbt,5,FLOWER_POT:0,../NBT/Flowers/flower_pot_20.nbt,100)
B(-3,53,-2,PLANKS:1)
RB(-2,53,-2,FLOWER_POT:0,../NBT/Flowers/flower_pot_01.nbt,5,FLOWER_POT:0,../NBT/Flowers/flower_pot_02.nbt,5,FLOWER_POT:0,../NBT/Flowers/flower_pot_03.nbt,5,FLOWER_POT:0,../NBT/Flowers/flower_pot_04.nbt,5,FLOWER_POT:0,../NBT/Flowers/flower_pot_05.nbt,5,FLOWER_POT:0,../NBT/Flowers/flower_pot_06.nbt,5,FLOWER_POT:0,../NBT/Flowers/flower_pot_07.nbt,5,FLOWER_POT:0,../NBT/Flowers/flower_pot_08.nbt,5,FLOWER_POT:0,../NBT/Flowers/flower_pot_09.nbt,5,FLOWER_POT:0,../NBT/Flowers/flower_pot_10.nbt,5,FLOWER_POT:0,../NBT/Flowers/flower_pot_11.nbt,5,FLOWER_POT:0,../NBT/Flowers/flower_pot_12.nbt,5,FLOWER_POT:0,../NBT/Flowers/flower_pot_13.nbt,5,FLOWER_POT:0,../NBT/Flowers/flower_pot_14.nbt,5,FLOWER_POT:0,../NBT/Flowers/flower_pot_15.nbt,5,FLOWER_POT:0,../NBT/Flowers/flower_pot_16.nbt,5,FLOWER_POT:0,../NBT/Flowers/flower_pot_17.nbt,5,FLOWER_POT:0,../NBT/Flowers/flower_pot_18.nbt,5,FLOWER_POT:0,../NBT/Flowers/flower_pot_19.nbt,5,FLOWER_POT:0,../NBT/Flowers/flower_pot_20.nbt,100)
B(-7,53,-1,DARK_OAK_DOOR:8)
B(-3,53,-1,PLANKS:1)
B(-2,53,-1,STONE_PRESSURE_PLATE:0)
B(-5,54,-8,BOOKSHELF:0)
B(-4,54,-8,COBBLESTONE:0)
B(-2,54,-8,WOODEN_SLAB:9)
B(-1,54,-8,LOG:9)
B(-8,54,-7,LOG:1)
B(-7,54,-7,PLANKS:1)
B(-6,54,-7,PLANKS:1)
B(-5,54,-7,PLANKS:1)
B(-4,54,-7,LOG:1)
B(-2,54,-7,SPRUCE_STAIRS:4)
B(-1,54,-7,LOG:1)
B(-7,54,-6,OAK_STAIRS:4)
B(-6,54,-6,OAK_STAIRS:1)
B(-1,54,-6,SPRUCE_STAIRS:7)
B(-1,54,-5,WOODEN_SLAB:9)
B(-7,54,-4,SPRUCE_STAIRS:6)
B(-6,54,-4,WOODEN_SLAB:9)
B(-5,54,-4,WOODEN_SLAB:9)
B(-4,54,-4,WOODEN_SLAB:9)
B(-3,54,-4,SPRUCE_STAIRS:6)
B(-2,54,-4,WOODEN_SLAB:9)
B(-1,54,-4,SPRUCE_STAIRS:6)
B(-8,54,-3,SPRUCE_STAIRS:4)
B(-7,54,-3,LOG:1)
B(-6,54,-3,LOG:5)
B(-5,54,-3,LOG:5)
B(-4,54,-3,LOG:5)
B(-3,54,-3,LOG:1)
B(-2,54,-3,LOG:5)
B(-1,54,-3,LOG:5)
B(-8,54,-2,WOODEN_SLAB:9)
B(-7,54,-2,LOG:9)
B(-6,54,-2,WOODEN_SLAB:8)
B(-5,54,-2,WOODEN_SLAB:8)
B(-4,54,-2,WOODEN_SLAB:8)
B(-3,54,-2,DOUBLE_WOODEN_SLAB:0)
B(-2,54,-2,WOODEN_SLAB:8)
B(-1,54,-2,WOODEN_SLAB:8)
B(-8,54,-1,WOODEN_SLAB:9)
B(-7,54,-1,LOG:9)
B(-6,54,-1,WOODEN_SLAB:8)
B(-5,54,-1,WOODEN_SLAB:8)
B(-4,54,-1,WOODEN_SLAB:8)
B(-3,54,-1,DOUBLE_WOODEN_SLAB:0)
B(-2,54,-1,WOODEN_SLAB:8)
B(-1,54,-1,WOODEN_SLAB:8)
B(-8,55,-8,WOODEN_SLAB:8)
B(-7,55,-8,WOODEN_SLAB:8)
B(-6,55,-8,WOODEN_SLAB:8)
B(-5,55,-8,WOODEN_SLAB:8)
B(-4,55,-8,LOG:9)
B(-2,55,-8,SPRUCE_FENCE:0)
B(-8,55,-7,LOG:1)
B(-7,55,-7,LOG:5)
B(-6,55,-7,LOG:5)
B(-5,55,-7,LOG:5)
B(-4,55,-7,LOG:1)
B(-2,55,-7,LOG:1)
B(-8,55,-6,OAK_STAIRS:4)
B(-7,55,-6,OAK_STAIRS:1)
B(-7,55,-4,LOG:1)
B(-6,55,-4,SPRUCE_FENCE:0)
B(-5,55,-4,SPRUCE_FENCE:0)
B(-4,55,-4,SPRUCE_FENCE:0)
B(-3,55,-4,LOG:1)
B(-2,55,-4,SPRUCE_FENCE:0)
B(-8,55,-3,LOG:1)
B(-8,55,-2,SPRUCE_FENCE:0)
B(-6,55,-2,LOG:1)
B(-5,55,-2,COBBLESTONE:0)
B(-4,55,-2,COBBLESTONE:0)
B(-3,55,-2,COBBLESTONE:0)
B(-2,55,-2,LOG:1)
B(-1,55,-2,SPRUCE_DOOR:3)
B(-8,55,-1,SPRUCE_FENCE:0)
B(-6,55,-1,COBBLESTONE:0)
B(-5,55,-1,BED:10)
RB(-4,55,-1,AIR,25,CHEST:3,../NBT/StructureLoot/JunkChest_1.nbt,15,CHEST:3,../NBT/StructureLoot/JunkChest_2.nbt,15,CHEST:3,../NBT/StructureLoot/JunkChest_3.nbt,15,CHEST:3,../NBT/StructureLoot/JunkChest_4.nbt,15,CHEST:3,../NBT/StructureLoot/JunkChest_5.nbt,15,CHEST:3,../NBT/StructureLoot/Common1.nbt,15,CHEST:3,../NBT/StructureLoot/Common2.nbt,15,CHEST:3,../NBT/StructureLoot/Common3.nbt,15,CHEST:3,../NBT/StructureLoot/Common4.nbt,15,CHEST:3,../NBT/StructureLoot/Common5.nbt,15,CHEST:3,../NBT/StructureLoot/Common6.nbt,15,CHEST:3,../NBT/StructureLoot/Common7.nbt,15,CHEST:3,../NBT/StructureLoot/Common8.nbt,15,CHEST:3,../NBT/StructureLoot/Common9.nbt,15,CHEST:3,../NBT/StructureLoot/Common10.nbt,15,CHEST:3,../NBT/StructureLoot/Common11.nbt,15,CHEST:3,../NBT/StructureLoot/Common12.nbt,15,CHEST:3,../NBT/StructureLoot/Common13.nbt,15,CHEST:3,../NBT/StructureLoot/Common14.nbt,15,CHEST:3,../NBT/StructureLoot/Common15.nbt,100)
B(-3,55,-1,BED:10)
B(-2,55,-1,PLANKS:1)
B(-1,55,-1,CARPET:10)
B(-8,56,-8,COBBLESTONE:0)
B(-4,56,-8,SPRUCE_FENCE:0)
B(-8,56,-7,LOG:1)
B(-7,56,-7,SPRUCE_FENCE:0)
B(-6,56,-7,SPRUCE_FENCE:0)
B(-5,56,-7,SPRUCE_FENCE:0)
B(-4,56,-7,LOG:1)
B(-2,56,-7,STONE_SLAB:0)
B(-7,56,-4,STONE_SLAB:0)
B(-3,56,-4,STONE_SLAB:0)
B(-8,56,-3,STONE_SLAB:0)
B(-6,56,-2,LOG:1)
B(-5,56,-2,PLANKS:1)
B(-4,56,-2,DARK_OAK_FENCE:0)
B(-3,56,-2,PLANKS:1)
B(-2,56,-2,LOG:1)
B(-1,56,-2,SPRUCE_DOOR:8)
B(-6,56,-1,PLANKS:1)
B(-2,56,-1,PLANKS:1)
B(-8,57,-8,PLANKS:1)
B(-8,57,-7,LOG:1)
B(-5,57,-7,SPRUCE_FENCE:0)
B(-4,57,-7,STONE_SLAB:0)
B(-5,57,-6,SPRUCE_FENCE:0)
B(-6,57,-2,LOG:1)
B(-5,57,-2,LOG:5)
B(-4,57,-2,LOG:5)
B(-3,57,-2,LOG:5)
B(-2,57,-2,LOG:1)
B(-1,57,-2,LOG:5)
B(-6,57,-1,LOG:9)
B(-5,57,-1,WOODEN_SLAB:8)
B(-4,57,-1,WOODEN_SLAB:8)
B(-3,57,-1,WOODEN_SLAB:8)
B(-2,57,-1,DOUBLE_WOODEN_SLAB:0)
B(-1,57,-1,WOODEN_SLAB:8)
B(-8,58,-8,LOG:9)
B(-7,58,-8,WOODEN_SLAB:9)
B(-8,58,-7,LOG:1)
B(-7,58,-7,SPRUCE_STAIRS:5)
B(-8,58,-6,SPRUCE_STAIRS:7)
B(-5,58,-6,TORCH:5)
B(-6,58,-2,LOG:1)
B(-5,58,-2,SPRUCE_FENCE:0)
B(-4,58,-2,LOG:1)
B(-3,58,-2,SPRUCE_FENCE:0)
B(-2,58,-2,LOG:1)
B(-1,58,-2,SPRUCE_FENCE:0)
B(-6,58,-1,SPRUCE_FENCE:0)
B(-8,59,-8,COBBLESTONE:0)
B(-7,59,-8,SPRUCE_FENCE:0)
B(-8,59,-7,LOG:1)
B(-7,59,-7,WOODEN_SLAB:1)
B(-8,59,-6,WOODEN_SLAB:1)
B(-6,59,-2,COBBLESTONE_WALL:0)
B(-4,59,-2,COBBLESTONE_WALL:0)
B(-2,59,-2,COBBLESTONE_WALL:0)
B(-8,60,-8,PLANKS:1)
B(-8,60,-7,LOG:1)
B(-6,60,-2,WOODEN_SLAB:0)
B(-5,60,-2,WOODEN_SLAB:0)
B(-4,60,-2,WOODEN_SLAB:0)
B(-3,60,-2,WOODEN_SLAB:0)
B(-2,60,-2,WOODEN_SLAB:0)
B(-1,60,-2,WOODEN_SLAB:0)
B(-6,60,-1,DOUBLE_WOODEN_SLAB:0)
B(-5,60,-1,WOODEN_SLAB:9)
B(-4,60,-1,WOODEN_SLAB:9)
B(-3,60,-1,WOODEN_SLAB:9)
B(-2,60,-1,WOODEN_SLAB:9)
B(-1,60,-1,WOODEN_SLAB:9)
B(-8,61,-8,LOG:9)
B(-8,61,-7,LOG:1)
B(-8,61,-6,WOODEN_SLAB:8)
B(-7,61,-6,WOODEN_SLAB:8)
B(-8,62,-8,PLANKS:1)
B(-7,62,-8,OAK_STAIRS:6)
B(-8,62,-7,SPRUCE_STAIRS:3)
B(-7,62,-7,OAK_STAIRS:3)
B(-8,63,-8,SPRUCE_STAIRS:3)
B(-7,63,-8,OAK_STAIRS:3)

BR(-8,0,0,WestPort_6x5,NORTH,100)
