Author: Bo3 BulkEdit

Description: Converted Schematic - Modified by Bo3BulkEdit

Version: 3

SettingsMode: WriteDisable

IsOTGPlus: false
Tree: false
Frequency: 1
Rarity: 100
RotateRandomly: false
SpawnHeight: randomY
MaxBranchDepth: 20
ExcludedBiomes: All

MinHeight: 0
MaxHeight: 256

SourceBlocks: AIR
MaxPercentageOutsideSourceBlock: 100
OutsideSourceBlock: placeAnyway

B(-6,0,-8,LOG:1)
B(-3,0,-8,LOG:1)
B(-2,0,-8,LOG:5)
B(-1,0,-8,LOG:5)
B(-6,0,-4,LOG:1)
B(-3,0,-4,LOG:1)
B(-6,1,-8,LOG:1)
B(-3,1,-8,LOG:1)
B(-6,1,-7,LOG:9)
B(-3,1,-7,LOG:9)
B(-6,1,-6,LOG:9)
B(-3,1,-6,LOG:9)
B(-6,1,-5,LOG:9)
B(-3,1,-5,LOG:9)
B(-6,1,-4,LOG:1)
B(-3,1,-4,LOG:1)
B(-3,1,-3,LOG:9)
B(-3,1,-2,LOG:9)
B(-3,1,-1,LOG:9)
B(-6,2,-8,LOG:1)
B(-5,2,-8,LOG:5)
B(-4,2,-8,LOG:5)
B(-3,2,-8,LOG:1)
B(-2,2,-8,LOG:5)
B(-1,2,-8,LOG:5)
B(-1,2,-7,LOG:9)
B(-1,2,-6,LOG:9)
B(-1,2,-5,LOG:9)
B(-6,2,-4,LOG:1)
B(-3,2,-4,LOG:1)
B(-2,2,-4,LOG:5)
B(-1,2,-4,LOG:5)
B(-6,2,-3,LOG:9)
B(-6,2,-2,LOG:9)
B(-6,2,-1,LOG:9)
B(-6,3,-8,LOG:1)
B(-3,3,-8,LOG:1)
B(-6,3,-4,LOG:1)
B(-3,3,-4,LOG:1)
B(-6,4,-8,LOG:1)
B(-3,4,-8,LOG:1)
B(-2,4,-8,LOG:5)
B(-1,4,-8,LOG:5)
B(-6,4,-4,LOG:1)
B(-3,4,-4,LOG:1)
B(-6,5,-8,LOG:1)
B(-3,5,-8,LOG:1)
B(-6,5,-7,LOG:9)
B(-3,5,-7,LOG:9)
B(-6,5,-6,LOG:9)
B(-3,5,-6,LOG:9)
B(-6,5,-5,LOG:9)
B(-3,5,-5,LOG:9)
B(-6,5,-4,LOG:1)
B(-3,5,-4,LOG:1)
B(-3,5,-3,LOG:9)
B(-3,5,-2,LOG:9)
B(-3,5,-1,LOG:9)
B(-6,6,-8,LOG:1)
B(-5,6,-8,LOG:5)
B(-4,6,-8,LOG:5)
B(-3,6,-8,LOG:1)
B(-2,6,-8,LOG:5)
B(-1,6,-8,LOG:5)
B(-1,6,-7,LOG:9)
B(-1,6,-6,LOG:9)
B(-1,6,-5,LOG:9)
B(-6,6,-4,LOG:1)
B(-3,6,-4,LOG:1)
B(-2,6,-4,LOG:5)
B(-1,6,-4,LOG:5)
B(-6,6,-3,LOG:9)
B(-6,6,-2,LOG:9)
B(-6,6,-1,LOG:9)
B(-6,7,-8,LOG:1)
B(-3,7,-8,LOG:1)
B(-6,7,-4,LOG:1)
B(-3,7,-4,LOG:1)
B(-6,8,-8,LOG:1)
B(-3,8,-8,LOG:1)
B(-2,8,-8,LOG:5)
B(-1,8,-8,LOG:5)
B(-6,8,-4,LOG:1)
B(-3,8,-4,LOG:1)
B(-6,9,-8,LOG:1)
B(-3,9,-8,LOG:1)
B(-6,9,-7,LOG:9)
B(-3,9,-7,LOG:9)
B(-6,9,-6,LOG:9)
B(-3,9,-6,LOG:9)
B(-6,9,-5,LOG:9)
B(-3,9,-5,LOG:9)
B(-6,9,-4,LOG:1)
B(-3,9,-4,LOG:1)
B(-3,9,-3,LOG:9)
B(-3,9,-2,LOG:9)
B(-3,9,-1,LOG:9)
B(-6,10,-8,LOG:1)
B(-5,10,-8,LOG:5)
B(-4,10,-8,LOG:5)
B(-3,10,-8,LOG:1)
B(-2,10,-8,LOG:5)
B(-1,10,-8,LOG:5)
B(-1,10,-7,LOG:9)
B(-1,10,-6,LOG:9)
B(-1,10,-5,LOG:9)
B(-6,10,-4,LOG:1)
B(-3,10,-4,LOG:1)
B(-2,10,-4,LOG:5)
B(-1,10,-4,LOG:5)
B(-6,10,-3,LOG:9)
B(-6,10,-2,LOG:9)
B(-6,10,-1,LOG:9)
B(-6,11,-8,LOG:1)
B(-3,11,-8,LOG:1)
B(-6,11,-4,LOG:1)
B(-3,11,-4,LOG:1)
B(-6,12,-8,LOG:1)
B(-3,12,-8,LOG:1)
B(-2,12,-8,LOG:5)
B(-1,12,-8,LOG:5)
B(-6,12,-4,LOG:1)
B(-3,12,-4,LOG:1)
B(-6,13,-8,LOG:1)
B(-3,13,-8,LOG:1)
B(-6,13,-7,LOG:9)
B(-3,13,-7,LOG:9)
B(-6,13,-6,LOG:9)
B(-3,13,-6,LOG:9)
B(-6,13,-5,LOG:9)
B(-3,13,-5,LOG:9)
B(-6,13,-4,LOG:1)
B(-3,13,-4,LOG:1)
B(-3,13,-3,LOG:9)
B(-3,13,-2,LOG:9)
B(-3,13,-1,LOG:9)
B(-6,14,-8,LOG:1)
B(-5,14,-8,LOG:5)
B(-4,14,-8,LOG:5)
B(-3,14,-8,LOG:1)
B(-2,14,-8,LOG:5)
B(-1,14,-8,LOG:5)
B(-1,14,-7,LOG:9)
B(-1,14,-6,LOG:9)
B(-1,14,-5,LOG:9)
B(-6,14,-4,LOG:1)
B(-3,14,-4,LOG:1)
B(-2,14,-4,LOG:5)
B(-1,14,-4,LOG:5)
B(-6,14,-3,LOG:9)
B(-6,14,-2,LOG:9)
B(-6,14,-1,LOG:9)
B(-6,15,-8,LOG:1)
B(-3,15,-8,LOG:1)
B(-6,15,-4,LOG:1)
B(-3,15,-4,LOG:1)
B(-6,16,-8,LOG:1)
B(-3,16,-8,LOG:1)
B(-2,16,-8,LOG:5)
B(-1,16,-8,LOG:5)
B(-6,16,-4,LOG:1)
B(-3,16,-4,LOG:1)
B(-6,17,-8,LOG:1)
B(-3,17,-8,LOG:1)
B(-6,17,-7,LOG:9)
B(-3,17,-7,LOG:9)
B(-6,17,-6,LOG:9)
B(-3,17,-6,LOG:9)
B(-6,17,-5,LOG:9)
B(-3,17,-5,LOG:9)
B(-6,17,-4,LOG:1)
B(-3,17,-4,LOG:1)
B(-3,17,-3,LOG:9)
B(-3,17,-2,LOG:9)
B(-3,17,-1,LOG:9)
B(-6,18,-8,LOG:1)
B(-5,18,-8,LOG:5)
B(-4,18,-8,LOG:5)
B(-3,18,-8,LOG:1)
B(-2,18,-8,LOG:5)
B(-1,18,-8,LOG:5)
B(-1,18,-7,LOG:9)
B(-1,18,-6,LOG:9)
B(-1,18,-5,LOG:9)
B(-6,18,-4,LOG:1)
B(-3,18,-4,LOG:1)
B(-2,18,-4,LOG:5)
B(-1,18,-4,LOG:5)
B(-6,18,-3,LOG:9)
B(-6,18,-2,LOG:9)
B(-6,18,-1,LOG:9)
B(-6,19,-8,LOG:1)
B(-3,19,-8,LOG:1)
B(-6,19,-4,LOG:1)
B(-3,19,-4,LOG:1)
B(-6,20,-8,LOG:1)
B(-3,20,-8,LOG:1)
B(-2,20,-8,LOG:5)
B(-1,20,-8,LOG:5)
B(-6,20,-4,LOG:1)
B(-3,20,-4,LOG:1)
B(-6,21,-8,LOG:1)
B(-3,21,-8,LOG:1)
B(-6,21,-7,LOG:9)
B(-3,21,-7,LOG:9)
B(-6,21,-6,LOG:9)
B(-3,21,-6,LOG:9)
B(-6,21,-5,LOG:9)
B(-3,21,-5,LOG:9)
B(-6,21,-4,LOG:1)
B(-3,21,-4,LOG:1)
B(-3,21,-3,LOG:9)
B(-3,21,-2,LOG:9)
B(-3,21,-1,LOG:9)
B(-6,22,-8,LOG:1)
B(-5,22,-8,LOG:5)
B(-4,22,-8,LOG:5)
B(-3,22,-8,LOG:1)
B(-2,22,-8,LOG:5)
B(-1,22,-8,LOG:5)
B(-1,22,-7,LOG:9)
B(-1,22,-6,LOG:9)
B(-1,22,-5,LOG:9)
B(-6,22,-4,LOG:1)
B(-3,22,-4,LOG:1)
B(-2,22,-4,LOG:5)
B(-1,22,-4,LOG:5)
B(-6,22,-3,LOG:9)
B(-6,22,-2,LOG:9)
B(-6,22,-1,LOG:9)
B(-6,23,-8,LOG:1)
B(-3,23,-8,LOG:1)
B(-6,23,-4,LOG:1)
B(-3,23,-4,LOG:1)
B(-6,24,-8,LOG:1)
B(-3,24,-8,LOG:1)
B(-2,24,-8,LOG:5)
B(-1,24,-8,LOG:5)
B(-6,24,-4,LOG:1)
B(-3,24,-4,LOG:1)
B(-6,25,-8,LOG:1)
B(-3,25,-8,LOG:1)
B(-6,25,-7,LOG:9)
B(-3,25,-7,LOG:9)
B(-6,25,-6,LOG:9)
B(-3,25,-6,LOG:9)
B(-6,25,-5,LOG:9)
B(-3,25,-5,LOG:9)
B(-6,25,-4,LOG:1)
B(-3,25,-4,LOG:1)
B(-3,25,-3,LOG:9)
B(-3,25,-2,LOG:9)
B(-3,25,-1,LOG:9)
B(-6,26,-8,LOG:1)
B(-5,26,-8,LOG:5)
B(-4,26,-8,LOG:5)
B(-3,26,-8,LOG:1)
B(-2,26,-8,LOG:5)
B(-1,26,-8,LOG:5)
B(-1,26,-7,LOG:9)
B(-1,26,-6,LOG:9)
B(-1,26,-5,LOG:9)
B(-6,26,-4,LOG:1)
B(-3,26,-4,LOG:1)
B(-2,26,-4,LOG:5)
B(-1,26,-4,LOG:5)
B(-6,26,-3,LOG:9)
B(-6,26,-2,LOG:9)
B(-6,26,-1,LOG:9)
B(-6,27,-8,LOG:1)
B(-3,27,-8,LOG:1)
B(-6,27,-4,LOG:1)
B(-3,27,-4,LOG:1)
B(-6,28,-8,LOG:1)
B(-3,28,-8,LOG:1)
B(-2,28,-8,LOG:5)
B(-1,28,-8,LOG:5)
B(-6,28,-4,LOG:1)
B(-3,28,-4,LOG:1)
B(-6,29,-8,LOG:1)
B(-3,29,-8,LOG:1)
B(-6,29,-7,LOG:9)
B(-3,29,-7,LOG:9)
B(-6,29,-6,LOG:9)
B(-3,29,-6,LOG:9)
B(-6,29,-5,LOG:9)
B(-3,29,-5,LOG:9)
B(-6,29,-4,LOG:1)
B(-3,29,-4,LOG:1)
B(-3,29,-3,LOG:9)
B(-3,29,-2,LOG:9)
B(-3,29,-1,LOG:9)
B(-6,30,-8,LOG:1)
B(-5,30,-8,LOG:5)
B(-4,30,-8,LOG:5)
B(-3,30,-8,LOG:1)
B(-2,30,-8,LOG:5)
B(-1,30,-8,LOG:5)
B(-1,30,-7,LOG:9)
B(-1,30,-6,LOG:9)
B(-1,30,-5,LOG:9)
B(-6,30,-4,LOG:1)
B(-3,30,-4,LOG:1)
B(-2,30,-4,LOG:5)
B(-1,30,-4,LOG:5)
B(-6,30,-3,LOG:9)
B(-6,30,-2,LOG:9)
B(-6,30,-1,LOG:9)
B(-6,31,-8,LOG:1)
B(-3,31,-8,LOG:1)
B(-6,31,-4,LOG:1)
B(-3,31,-4,LOG:1)
B(-6,32,-8,LOG:1)
B(-3,32,-8,LOG:1)
B(-2,32,-8,LOG:5)
B(-1,32,-8,LOG:5)
B(-6,32,-4,LOG:1)
B(-3,32,-4,LOG:1)
B(-6,33,-8,LOG:1)
B(-3,33,-8,LOG:1)
B(-6,33,-7,LOG:9)
B(-3,33,-7,LOG:9)
B(-6,33,-6,LOG:9)
B(-3,33,-6,LOG:9)
B(-6,33,-5,LOG:9)
B(-3,33,-5,LOG:9)
B(-6,33,-4,LOG:1)
B(-3,33,-4,LOG:1)
B(-3,33,-3,LOG:9)
B(-3,33,-2,LOG:9)
B(-3,33,-1,LOG:9)
B(-6,34,-8,LOG:1)
B(-5,34,-8,LOG:5)
B(-4,34,-8,LOG:5)
B(-3,34,-8,LOG:1)
B(-2,34,-8,LOG:5)
B(-1,34,-8,LOG:5)
B(-1,34,-7,LOG:9)
B(-1,34,-6,LOG:9)
B(-1,34,-5,LOG:9)
B(-6,34,-4,LOG:1)
B(-3,34,-4,LOG:1)
B(-2,34,-4,LOG:5)
B(-1,34,-4,LOG:5)
B(-6,34,-3,LOG:9)
B(-6,34,-2,LOG:9)
B(-6,34,-1,LOG:9)
B(-6,35,-8,LOG:1)
B(-3,35,-8,LOG:1)
B(-6,35,-4,LOG:1)
B(-3,35,-4,LOG:1)
B(-6,36,-8,LOG:1)
B(-3,36,-8,LOG:1)
B(-2,36,-8,LOG:5)
B(-1,36,-8,LOG:5)
B(-6,36,-4,LOG:1)
B(-3,36,-4,LOG:1)
B(-6,37,-8,LOG:1)
B(-3,37,-8,LOG:1)
B(-6,37,-7,LOG:9)
B(-3,37,-7,LOG:9)
B(-6,37,-6,LOG:9)
B(-3,37,-6,LOG:9)
B(-6,37,-5,LOG:9)
B(-3,37,-5,LOG:9)
B(-6,37,-4,LOG:1)
B(-3,37,-4,LOG:1)
B(-3,37,-3,LOG:9)
B(-3,37,-2,LOG:9)
B(-3,37,-1,LOG:9)
B(-6,38,-8,LOG:1)
B(-5,38,-8,LOG:5)
B(-4,38,-8,LOG:5)
B(-3,38,-8,LOG:1)
B(-2,38,-8,LOG:5)
B(-1,38,-8,LOG:5)
B(-1,38,-7,LOG:9)
B(-1,38,-6,LOG:9)
B(-1,38,-5,LOG:9)
B(-6,38,-4,LOG:1)
B(-3,38,-4,LOG:1)
B(-2,38,-4,LOG:5)
B(-1,38,-4,LOG:5)
B(-6,38,-3,LOG:9)
B(-6,38,-2,LOG:9)
B(-6,38,-1,LOG:9)
B(-6,39,-8,LOG:1)
B(-3,39,-8,LOG:1)
B(-6,39,-4,LOG:1)
B(-3,39,-4,LOG:1)
B(-6,40,-8,LOG:1)
B(-3,40,-8,LOG:1)
B(-2,40,-8,LOG:5)
B(-1,40,-8,LOG:5)
B(-6,40,-4,LOG:1)
B(-3,40,-4,LOG:1)
B(-6,41,-8,LOG:1)
B(-3,41,-8,LOG:1)
B(-6,41,-7,LOG:9)
B(-3,41,-7,LOG:9)
B(-6,41,-6,LOG:9)
B(-3,41,-6,LOG:9)
B(-6,41,-5,LOG:9)
B(-3,41,-5,LOG:9)
B(-6,41,-4,LOG:1)
B(-3,41,-4,LOG:1)
B(-3,41,-3,LOG:9)
B(-3,41,-2,LOG:9)
B(-3,41,-1,LOG:9)
B(-6,42,-8,LOG:1)
B(-5,42,-8,LOG:5)
B(-4,42,-8,LOG:5)
B(-3,42,-8,LOG:1)
B(-2,42,-8,LOG:5)
B(-1,42,-8,LOG:5)
B(-1,42,-7,LOG:9)
B(-1,42,-6,LOG:9)
B(-1,42,-5,LOG:9)
B(-6,42,-4,LOG:1)
B(-3,42,-4,LOG:1)
B(-2,42,-4,LOG:5)
B(-1,42,-4,LOG:5)
B(-6,42,-3,LOG:9)
B(-6,42,-2,LOG:9)
B(-6,42,-1,LOG:9)
B(-6,43,-8,LOG:1)
B(-3,43,-8,LOG:1)
B(-6,43,-4,LOG:1)
B(-3,43,-4,LOG:1)
B(-6,44,-8,LOG:1)
B(-3,44,-8,LOG:1)
B(-2,44,-8,LOG:5)
B(-1,44,-8,LOG:5)
B(-6,44,-4,LOG:1)
B(-3,44,-4,LOG:1)
B(-6,45,-8,LOG:1)
B(-3,45,-8,LOG:1)
B(-6,45,-7,LOG:9)
B(-3,45,-7,LOG:9)
B(-6,45,-6,LOG:9)
B(-3,45,-6,LOG:9)
B(-6,45,-5,LOG:9)
B(-3,45,-5,LOG:9)
B(-6,45,-4,LOG:1)
B(-3,45,-4,LOG:1)
B(-3,45,-3,LOG:9)
B(-3,45,-2,LOG:9)
B(-3,45,-1,LOG:9)
B(-6,46,-8,LOG:1)
B(-5,46,-8,LOG:5)
B(-4,46,-8,LOG:5)
B(-3,46,-8,LOG:1)
B(-2,46,-8,LOG:5)
B(-1,46,-8,LOG:5)
B(-1,46,-7,LOG:9)
B(-1,46,-6,LOG:9)
B(-1,46,-5,LOG:9)
B(-6,46,-4,LOG:1)
B(-3,46,-4,LOG:1)
B(-2,46,-4,LOG:5)
B(-1,46,-4,LOG:5)
B(-6,46,-3,LOG:9)
B(-6,46,-2,LOG:9)
B(-6,46,-1,LOG:9)
B(-6,47,-8,LOG:1)
B(-3,47,-8,LOG:1)
B(-6,47,-4,LOG:1)
B(-3,47,-4,LOG:1)
B(-6,47,-2,LOG:1)
B(-6,48,-8,LOG:1)
B(-3,48,-8,LOG:1)
B(-6,48,-4,LOG:1)
B(-3,48,-4,LOG:1)
B(-6,48,-2,LOG:1)
B(-6,49,-8,LOG:1)
B(-3,49,-8,LOG:1)
B(-6,49,-4,LOG:1)
B(-3,49,-4,LOG:1)
B(-6,49,-2,LOG:1)
B(-7,50,-8,WOODEN_BUTTON:2)
B(-6,50,-8,LOG:1)
B(-5,50,-8,LOG:5)
B(-4,50,-8,LOG:5)
B(-3,50,-8,LOG:1)
B(-2,50,-8,WOODEN_SLAB:8)
B(-1,50,-8,WOODEN_SLAB:8)
B(-6,50,-7,LOG:9)
B(-5,50,-7,WOODEN_SLAB:8)
B(-4,50,-7,WOODEN_SLAB:8)
B(-3,50,-7,LOG:9)
B(-2,50,-7,WOODEN_SLAB:8)
B(-1,50,-7,WOODEN_SLAB:8)
B(-6,50,-6,LOG:9)
B(-5,50,-6,WOODEN_SLAB:8)
B(-4,50,-6,WOODEN_SLAB:8)
B(-3,50,-6,LOG:9)
B(-2,50,-6,WOODEN_SLAB:8)
B(-1,50,-6,WOODEN_SLAB:8)
B(-6,50,-5,LOG:9)
B(-5,50,-5,WOODEN_SLAB:8)
B(-4,50,-5,WOODEN_SLAB:8)
B(-3,50,-5,LOG:9)
B(-2,50,-5,WOODEN_SLAB:8)
B(-1,50,-5,WOODEN_SLAB:8)
B(-7,50,-4,WOODEN_BUTTON:2)
B(-6,50,-4,LOG:1)
B(-5,50,-4,LOG:5)
B(-4,50,-4,LOG:5)
B(-3,50,-4,LOG:1)
B(-2,50,-4,WOODEN_SLAB:8)
B(-1,50,-4,WOODEN_SLAB:8)
B(-6,50,-3,LOG:9)
B(-5,50,-3,WOODEN_SLAB:8)
B(-4,50,-3,WOODEN_SLAB:8)
B(-3,50,-3,LOG:9)
B(-2,50,-3,WOODEN_SLAB:8)
B(-1,50,-3,WOODEN_SLAB:8)
B(-7,50,-2,LADDER:4)
B(-6,50,-2,LOG:9)
B(-5,50,-2,WOODEN_SLAB:8)
B(-4,50,-2,WOODEN_SLAB:8)
B(-3,50,-2,LOG:9)
B(-2,50,-2,WOODEN_SLAB:8)
B(-1,50,-2,WOODEN_SLAB:8)
B(-6,50,-1,LOG:9)
B(-5,50,-1,WOODEN_SLAB:8)
B(-4,50,-1,WOODEN_SLAB:8)
B(-3,50,-1,LOG:9)
B(-2,50,-1,WOODEN_SLAB:8)
B(-1,50,-1,WOODEN_SLAB:8)
B(-6,51,-8,COBBLESTONE_WALL:0)
B(-5,51,-8,LOG:1)
B(-4,51,-8,OAK_STAIRS:3)
B(-3,51,-8,LOG:1)
B(-2,51,-8,GOLD_ORE:0)
B(-1,51,-8,GOLD_ORE:0)
B(-6,51,-7,DARK_OAK_STAIRS:3)
B(-3,51,-7,COBBLESTONE:0)
B(-2,51,-7,PLANKS:1)
B(-1,51,-7,IRON_DOOR:3)
B(-3,51,-6,COBBLESTONE:0)
B(-2,51,-6,HAY_BLOCK:8)
B(-6,51,-5,DARK_OAK_STAIRS:2)
B(-3,51,-5,COBBLESTONE:0)
B(-2,51,-5,PUMPKIN:2)
B(-6,51,-4,COBBLESTONE_WALL:0)
B(-3,51,-4,LOG:1)
B(-2,51,-4,HAY_BLOCK:0)
B(-6,51,-3,DARK_OAK_STAIRS:3)
B(-3,51,-3,COBBLESTONE:0)
B(-2,51,-3,HAY_BLOCK:8)
B(-3,51,-2,COBBLESTONE:0)
B(-2,51,-2,MELON_BLOCK:0)
B(-6,51,-1,DARK_OAK_STAIRS:2)
B(-3,51,-1,COBBLESTONE:0)
B(-2,51,-1,PUMPKIN:2)
B(-5,52,-8,LOG:1)
B(-3,52,-8,LOG:1)
B(-3,52,-7,PLANKS:1)
B(-2,52,-7,PLANKS:1)
B(-1,52,-7,IRON_DOOR:8)
B(-3,52,-6,SPRUCE_FENCE:0)
B(-2,52,-6,HAY_BLOCK:0)
B(-3,52,-5,PLANKS:1)
B(-2,52,-5,HAY_BLOCK:0)
B(-3,52,-4,LOG:1)
B(-3,52,-3,PLANKS:1)
B(-2,52,-3,HAY_BLOCK:0)
B(-3,52,-2,SPRUCE_FENCE:0)
B(-3,52,-1,PLANKS:1)
B(-2,52,-1,HAY_BLOCK:0)
B(-5,53,-8,LOG:1)
B(-3,53,-8,LOG:1)
B(-2,53,-8,WOODEN_SLAB:8)
B(-1,53,-8,WOODEN_SLAB:8)
B(-3,53,-7,LOG:9)
B(-2,53,-7,DOUBLE_WOODEN_SLAB:0)
B(-1,53,-7,DOUBLE_WOODEN_SLAB:0)
B(-3,53,-6,LOG:9)
B(-2,53,-6,WOODEN_SLAB:8)
B(-1,53,-6,WOODEN_SLAB:8)
B(-3,53,-5,LOG:9)
B(-2,53,-5,WOODEN_SLAB:8)
B(-1,53,-5,WOODEN_SLAB:8)
B(-4,53,-4,SPRUCE_STAIRS:4)
B(-3,53,-4,LOG:1)
B(-2,53,-4,WOODEN_SLAB:8)
B(-1,53,-4,WOODEN_SLAB:8)
B(-4,53,-3,WOODEN_SLAB:9)
B(-3,53,-3,LOG:9)
B(-2,53,-3,WOODEN_SLAB:8)
B(-1,53,-3,WOODEN_SLAB:8)
B(-4,53,-2,WOODEN_SLAB:9)
B(-3,53,-2,LOG:9)
B(-2,53,-2,WOODEN_SLAB:8)
B(-1,53,-2,WOODEN_SLAB:8)
B(-4,53,-1,WOODEN_SLAB:9)
B(-3,53,-1,LOG:9)
B(-2,53,-1,WOODEN_SLAB:8)
B(-1,53,-1,WOODEN_SLAB:8)
B(-5,54,-8,LOG:1)
B(-3,54,-8,LOG:1)
B(-2,54,-8,COBBLESTONE:0)
B(-1,54,-8,SPRUCE_DOOR:1)
B(-3,54,-7,COBBLESTONE:0)
B(-2,54,-7,BOOKSHELF:0)
B(-1,54,-7,CARPET:5)
B(-3,54,-6,COBBLESTONE:0)
B(-2,54,-6,BOOKSHELF:0)
B(-3,54,-5,COBBLESTONE:0)
B(-2,54,-5,BOOKSHELF:0)
B(-1,54,-5,CARPET:5)
B(-4,54,-4,LOG:1)
B(-3,54,-4,LOG:1)
B(-2,54,-4,BIRCH_STAIRS:1)
B(-4,54,-3,SPRUCE_FENCE:0)
B(-3,54,-3,COBBLESTONE:0)
B(-2,54,-3,BIRCH_STAIRS:1)
B(-1,54,-3,CARPET:5)
B(-4,54,-2,SPRUCE_FENCE:0)
B(-3,54,-2,COBBLESTONE:0)
B(-2,54,-2,BIRCH_STAIRS:1)
B(-1,54,-2,CARPET:5)
B(-4,54,-1,SPRUCE_FENCE:0)
B(-3,54,-1,COBBLESTONE:0)
B(-2,54,-1,BOOKSHELF:0)
B(-5,55,-8,LOG:1)
B(-3,55,-8,LOG:1)
B(-2,55,-8,PLANKS:1)
B(-1,55,-8,SPRUCE_DOOR:8)
B(-3,55,-7,PLANKS:1)
B(-2,55,-7,BOOKSHELF:0)
B(-3,55,-6,PLANKS:1)
B(-2,55,-6,BOOKSHELF:0)
B(-3,55,-5,PLANKS:1)
B(-2,55,-5,BOOKSHELF:0)
B(-4,55,-4,STONE_SLAB:0)
B(-3,55,-4,LOG:1)
B(-3,55,-3,PLANKS:1)
B(-3,55,-2,DARK_OAK_FENCE:0)
B(-3,55,-1,PLANKS:1)
B(-2,55,-1,BOOKSHELF:0)
B(-6,56,-8,SPRUCE_STAIRS:4)
B(-5,56,-8,LOG:1)
B(-4,56,-8,LOG:5)
B(-3,56,-8,LOG:1)
B(-2,56,-8,LOG:5)
B(-1,56,-8,LOG:5)
B(-5,56,-7,SPRUCE_STAIRS:7)
B(-4,56,-7,WOODEN_SLAB:9)
B(-3,56,-7,LOG:9)
B(-2,56,-7,WOODEN_SLAB:8)
B(-1,56,-7,WOODEN_SLAB:8)
B(-3,56,-6,LOG:9)
B(-2,56,-6,WOODEN_SLAB:8)
B(-1,56,-6,WOODEN_SLAB:8)
B(-3,56,-5,LOG:9)
B(-2,56,-5,WOODEN_SLAB:8)
B(-1,56,-5,WOODEN_SLAB:8)
B(-3,56,-4,LOG:1)
B(-2,56,-4,LOG:5)
B(-1,56,-4,LOG:5)
B(-3,56,-3,LOG:9)
B(-2,56,-3,WOODEN_SLAB:8)
B(-1,56,-3,WOODEN_SLAB:8)
B(-3,56,-2,LOG:9)
B(-2,56,-2,WOODEN_SLAB:8)
B(-1,56,-2,WOODEN_SLAB:8)
B(-3,56,-1,LOG:9)
B(-2,56,-1,WOODEN_SLAB:8)
B(-1,56,-1,WOODEN_SLAB:8)
B(-6,57,-8,LOG:1)
B(-5,57,-7,LOG:1)
B(-4,57,-7,SPRUCE_FENCE:0)
B(-3,57,-7,SPRUCE_FENCE:0)
B(-3,57,-6,SPRUCE_FENCE:0)
B(-3,57,-5,SPRUCE_FENCE:0)
B(-3,57,-4,LOG:1)
B(-2,57,-4,COBBLESTONE:0)
B(-1,57,-4,DARK_OAK_DOOR:3)
B(-3,57,-3,COBBLESTONE:0)
B(-2,57,-3,CRAFTING_TABLE:0)
B(-3,57,-2,COBBLESTONE:0)
B(-2,57,-2,FURNACE:5)
B(-1,57,-2,CARPET:9)
B(-3,57,-1,COBBLESTONE:0)
B(-2,57,-1,DARK_OAK_STAIRS:7)
B(-6,58,-8,STONE_SLAB:0)
B(-5,58,-7,STONE_SLAB:0)
B(-3,58,-4,LOG:1)
B(-2,58,-4,PLANKS:1)
B(-1,58,-4,DARK_OAK_DOOR:8)
B(-3,58,-3,PLANKS:1)
B(-3,58,-2,DARK_OAK_FENCE:0)
B(-3,58,-1,PLANKS:1)
B(-1,59,-6,DARK_OAK_FENCE:0)
B(-4,59,-5,OAK_STAIRS:0)
B(-3,59,-5,OAK_STAIRS:5)
B(-4,59,-4,OAK_STAIRS:0)
B(-3,59,-4,LOG:1)
B(-2,59,-4,LOG:5)
B(-1,59,-4,LOG:5)
B(-4,59,-3,OAK_STAIRS:0)
B(-3,59,-3,LOG:9)
B(-2,59,-3,WOODEN_SLAB:8)
B(-1,59,-3,WOODEN_SLAB:8)
B(-4,59,-2,OAK_STAIRS:0)
B(-3,59,-2,LOG:9)
B(-2,59,-2,WOODEN_SLAB:8)
B(-1,59,-2,WOODEN_SLAB:8)
B(-4,59,-1,OAK_STAIRS:0)
B(-3,59,-1,LOG:9)
B(-2,59,-1,WOODEN_SLAB:8)
B(-1,59,-1,WOODEN_SLAB:8)
B(-1,60,-6,DARK_OAK_FENCE:0)
B(-3,60,-5,OAK_STAIRS:0)
B(-2,60,-5,OAK_STAIRS:5)
B(-3,60,-4,SPRUCE_STAIRS:0)
B(-2,60,-4,PLANKS:1)
B(-3,60,-3,SPRUCE_STAIRS:0)
B(-2,60,-3,PLANKS:1)
B(-3,60,-2,SPRUCE_STAIRS:0)
B(-2,60,-2,COBBLESTONE:0)
B(-3,60,-1,SPRUCE_STAIRS:0)
B(-2,60,-1,COBBLESTONE:0)
B(-1,61,-7,DARK_OAK_STAIRS:6)
B(-1,61,-6,LOG:9)
B(-2,61,-5,OAK_STAIRS:0)
B(-1,61,-5,LOG:9)
B(-2,61,-4,SPRUCE_STAIRS:0)
B(-1,61,-4,SPRUCE_STAIRS:7)
B(-2,61,-3,SPRUCE_STAIRS:0)
B(-2,61,-2,SPRUCE_STAIRS:0)
B(-2,61,-1,SPRUCE_STAIRS:0)
B(-1,62,-5,WOODEN_SLAB:0)
B(-1,62,-4,WOODEN_SLAB:1)
B(-1,62,-3,WOODEN_SLAB:1)
B(-1,62,-2,WOODEN_SLAB:1)
B(-1,62,-1,WOODEN_SLAB:1)

