Author: Bo3 BulkEdit

Description: Converted Schematic - Modified by Bo3BulkEdit

Version: 3

SettingsMode: WriteDisable

IsOTGPlus: false
Tree: false
Frequency: 1
Rarity: 100
RotateRandomly: false
SpawnHeight: randomY
MaxBranchDepth: 20
ExcludedBiomes: All

MinHeight: 0
MaxHeight: 256

SourceBlocks: AIR
MaxPercentageOutsideSourceBlock: 100
OutsideSourceBlock: placeAnyway

B(-7,0,-7,LOG:1)
B(-7,0,-3,LOG:1)
B(-8,1,-7,LOG:5)
B(-7,1,-7,LOG:1)
B(-7,1,-3,LOG:1)
B(-7,2,-7,LOG:1)
B(-6,2,-7,LOG:5)
B(-5,2,-7,LOG:5)
B(-4,2,-7,LOG:5)
B(-3,2,-7,LOG:5)
B(-2,2,-7,LOG:5)
B(-1,2,-7,LOG:5)
B(-7,2,-6,LOG:9)
B(-7,2,-5,LOG:9)
B(-7,2,-4,LOG:9)
B(-7,2,-3,LOG:1)
B(-7,2,-2,LOG:9)
B(-7,2,-1,LOG:9)
B(-7,3,-8,LOG:9)
B(-3,3,-8,LOG:9)
B(-7,3,-7,LOG:1)
B(-3,3,-7,LOG:9)
B(-3,3,-6,LOG:9)
B(-3,3,-5,LOG:9)
B(-3,3,-4,LOG:9)
B(-7,3,-3,LOG:1)
B(-3,3,-3,LOG:9)
B(-2,3,-3,LOG:5)
B(-1,3,-3,LOG:5)
B(-3,3,-2,LOG:9)
B(-3,3,-1,LOG:9)
B(-7,4,-7,LOG:1)
B(-7,4,-3,LOG:1)
B(-8,5,-7,LOG:5)
B(-7,5,-7,LOG:1)
B(-7,5,-3,LOG:1)
B(-7,6,-7,LOG:1)
B(-6,6,-7,LOG:5)
B(-5,6,-7,LOG:5)
B(-4,6,-7,LOG:5)
B(-3,6,-7,LOG:5)
B(-2,6,-7,LOG:5)
B(-1,6,-7,LOG:5)
B(-7,6,-6,LOG:9)
B(-7,6,-5,LOG:9)
B(-7,6,-4,LOG:9)
B(-7,6,-3,LOG:1)
B(-7,6,-2,LOG:9)
B(-7,6,-1,LOG:9)
B(-7,7,-8,LOG:9)
B(-3,7,-8,LOG:9)
B(-7,7,-7,LOG:1)
B(-3,7,-7,LOG:9)
B(-3,7,-6,LOG:9)
B(-3,7,-5,LOG:9)
B(-3,7,-4,LOG:9)
B(-7,7,-3,LOG:1)
B(-3,7,-3,LOG:9)
B(-2,7,-3,LOG:5)
B(-1,7,-3,LOG:5)
B(-3,7,-2,LOG:9)
B(-3,7,-1,LOG:9)
B(-7,8,-7,LOG:1)
B(-7,8,-3,LOG:1)
B(-8,9,-7,LOG:5)
B(-7,9,-7,LOG:1)
B(-7,9,-3,LOG:1)
B(-7,10,-7,LOG:1)
B(-6,10,-7,LOG:5)
B(-5,10,-7,LOG:5)
B(-4,10,-7,LOG:5)
B(-3,10,-7,LOG:5)
B(-2,10,-7,LOG:5)
B(-1,10,-7,LOG:5)
B(-7,10,-6,LOG:9)
B(-7,10,-5,LOG:9)
B(-7,10,-4,LOG:9)
B(-7,10,-3,LOG:1)
B(-7,10,-2,LOG:9)
B(-7,10,-1,LOG:9)
B(-7,11,-8,LOG:9)
B(-3,11,-8,LOG:9)
B(-7,11,-7,LOG:1)
B(-3,11,-7,LOG:9)
B(-3,11,-6,LOG:9)
B(-3,11,-5,LOG:9)
B(-3,11,-4,LOG:9)
B(-7,11,-3,LOG:1)
B(-3,11,-3,LOG:9)
B(-2,11,-3,LOG:5)
B(-1,11,-3,LOG:5)
B(-3,11,-2,LOG:9)
B(-3,11,-1,LOG:9)
B(-7,12,-7,LOG:1)
B(-7,12,-3,LOG:1)
B(-8,13,-7,LOG:5)
B(-7,13,-7,LOG:1)
B(-7,13,-3,LOG:1)
B(-7,14,-7,LOG:1)
B(-6,14,-7,LOG:5)
B(-5,14,-7,LOG:5)
B(-4,14,-7,LOG:5)
B(-3,14,-7,LOG:5)
B(-2,14,-7,LOG:5)
B(-1,14,-7,LOG:5)
B(-7,14,-6,LOG:9)
B(-7,14,-5,LOG:9)
B(-7,14,-4,LOG:9)
B(-7,14,-3,LOG:1)
B(-7,14,-2,LOG:9)
B(-7,14,-1,LOG:9)
B(-7,15,-8,LOG:9)
B(-3,15,-8,LOG:9)
B(-7,15,-7,LOG:1)
B(-3,15,-7,LOG:9)
B(-3,15,-6,LOG:9)
B(-3,15,-5,LOG:9)
B(-3,15,-4,LOG:9)
B(-7,15,-3,LOG:1)
B(-3,15,-3,LOG:9)
B(-2,15,-3,LOG:5)
B(-1,15,-3,LOG:5)
B(-3,15,-2,LOG:9)
B(-3,15,-1,LOG:9)
B(-7,16,-7,LOG:1)
B(-7,16,-3,LOG:1)
B(-8,17,-7,LOG:5)
B(-7,17,-7,LOG:1)
B(-7,17,-3,LOG:1)
B(-7,18,-7,LOG:1)
B(-6,18,-7,LOG:5)
B(-5,18,-7,LOG:5)
B(-4,18,-7,LOG:5)
B(-3,18,-7,LOG:5)
B(-2,18,-7,LOG:5)
B(-1,18,-7,LOG:5)
B(-7,18,-6,LOG:9)
B(-7,18,-5,LOG:9)
B(-7,18,-4,LOG:9)
B(-7,18,-3,LOG:1)
B(-7,18,-2,LOG:9)
B(-7,18,-1,LOG:9)
B(-7,19,-8,LOG:9)
B(-3,19,-8,LOG:9)
B(-7,19,-7,LOG:1)
B(-3,19,-7,LOG:9)
B(-3,19,-6,LOG:9)
B(-3,19,-5,LOG:9)
B(-3,19,-4,LOG:9)
B(-7,19,-3,LOG:1)
B(-3,19,-3,LOG:9)
B(-2,19,-3,LOG:5)
B(-1,19,-3,LOG:5)
B(-3,19,-2,LOG:9)
B(-3,19,-1,LOG:9)
B(-7,20,-7,LOG:1)
B(-7,20,-3,LOG:1)
B(-8,21,-7,LOG:5)
B(-7,21,-7,LOG:1)
B(-7,21,-3,LOG:1)
B(-7,22,-7,LOG:1)
B(-6,22,-7,LOG:5)
B(-5,22,-7,LOG:5)
B(-4,22,-7,LOG:5)
B(-3,22,-7,LOG:5)
B(-2,22,-7,LOG:5)
B(-1,22,-7,LOG:5)
B(-7,22,-6,LOG:9)
B(-7,22,-5,LOG:9)
B(-7,22,-4,LOG:9)
B(-7,22,-3,LOG:1)
B(-7,22,-2,LOG:9)
B(-7,22,-1,LOG:9)
B(-7,23,-8,LOG:9)
B(-3,23,-8,LOG:9)
B(-7,23,-7,LOG:1)
B(-3,23,-7,LOG:9)
B(-3,23,-6,LOG:9)
B(-3,23,-5,LOG:9)
B(-3,23,-4,LOG:9)
B(-7,23,-3,LOG:1)
B(-3,23,-3,LOG:9)
B(-2,23,-3,LOG:5)
B(-1,23,-3,LOG:5)
B(-3,23,-2,LOG:9)
B(-3,23,-1,LOG:9)
B(-7,24,-7,LOG:1)
B(-7,24,-3,LOG:1)
B(-8,25,-7,LOG:5)
B(-7,25,-7,LOG:1)
B(-7,25,-3,LOG:1)
B(-7,26,-7,LOG:1)
B(-6,26,-7,LOG:5)
B(-5,26,-7,LOG:5)
B(-4,26,-7,LOG:5)
B(-3,26,-7,LOG:5)
B(-2,26,-7,LOG:5)
B(-1,26,-7,LOG:5)
B(-7,26,-6,LOG:9)
B(-7,26,-5,LOG:9)
B(-7,26,-4,LOG:9)
B(-7,26,-3,LOG:1)
B(-7,26,-2,LOG:9)
B(-7,26,-1,LOG:9)
B(-7,27,-8,LOG:9)
B(-3,27,-8,LOG:9)
B(-7,27,-7,LOG:1)
B(-3,27,-7,LOG:9)
B(-3,27,-6,LOG:9)
B(-3,27,-5,LOG:9)
B(-3,27,-4,LOG:9)
B(-7,27,-3,LOG:1)
B(-3,27,-3,LOG:9)
B(-2,27,-3,LOG:5)
B(-1,27,-3,LOG:5)
B(-3,27,-2,LOG:9)
B(-3,27,-1,LOG:9)
B(-7,28,-7,LOG:1)
B(-7,28,-3,LOG:1)
B(-8,29,-7,LOG:5)
B(-7,29,-7,LOG:1)
B(-7,29,-3,LOG:1)
B(-7,30,-7,LOG:1)
B(-6,30,-7,LOG:5)
B(-5,30,-7,LOG:5)
B(-4,30,-7,LOG:5)
B(-3,30,-7,LOG:5)
B(-2,30,-7,LOG:5)
B(-1,30,-7,LOG:5)
B(-7,30,-6,LOG:9)
B(-7,30,-5,LOG:9)
B(-7,30,-4,LOG:9)
B(-7,30,-3,LOG:1)
B(-7,30,-2,LOG:9)
B(-7,30,-1,LOG:9)
B(-7,31,-8,LOG:9)
B(-3,31,-8,LOG:9)
B(-7,31,-7,LOG:1)
B(-3,31,-7,LOG:9)
B(-3,31,-6,LOG:9)
B(-3,31,-5,LOG:9)
B(-3,31,-4,LOG:9)
B(-7,31,-3,LOG:1)
B(-3,31,-3,LOG:9)
B(-2,31,-3,LOG:5)
B(-1,31,-3,LOG:5)
B(-3,31,-2,LOG:9)
B(-3,31,-1,LOG:9)
B(-7,32,-7,LOG:1)
B(-7,32,-3,LOG:1)
B(-8,33,-7,LOG:5)
B(-7,33,-7,LOG:1)
B(-7,33,-3,LOG:1)
B(-7,34,-7,LOG:1)
B(-6,34,-7,LOG:5)
B(-5,34,-7,LOG:5)
B(-4,34,-7,LOG:5)
B(-3,34,-7,LOG:5)
B(-2,34,-7,LOG:5)
B(-1,34,-7,LOG:5)
B(-7,34,-6,LOG:9)
B(-7,34,-5,LOG:9)
B(-7,34,-4,LOG:9)
B(-7,34,-3,LOG:1)
B(-7,34,-2,LOG:9)
B(-7,34,-1,LOG:9)
B(-7,35,-8,LOG:9)
B(-3,35,-8,LOG:9)
B(-7,35,-7,LOG:1)
B(-3,35,-7,LOG:9)
B(-3,35,-6,LOG:9)
B(-3,35,-5,LOG:9)
B(-3,35,-4,LOG:9)
B(-7,35,-3,LOG:1)
B(-3,35,-3,LOG:9)
B(-2,35,-3,LOG:5)
B(-1,35,-3,LOG:5)
B(-3,35,-2,LOG:9)
B(-3,35,-1,LOG:9)
B(-7,36,-7,LOG:1)
B(-7,36,-3,LOG:1)
B(-8,37,-7,LOG:5)
B(-7,37,-7,LOG:1)
B(-7,37,-3,LOG:1)
B(-7,38,-7,LOG:1)
B(-6,38,-7,LOG:5)
B(-5,38,-7,LOG:5)
B(-4,38,-7,LOG:5)
B(-3,38,-7,LOG:5)
B(-2,38,-7,LOG:5)
B(-1,38,-7,LOG:5)
B(-7,38,-6,LOG:9)
B(-7,38,-5,LOG:9)
B(-7,38,-4,LOG:9)
B(-7,38,-3,LOG:1)
B(-7,38,-2,LOG:9)
B(-7,38,-1,LOG:9)
B(-7,39,-8,LOG:9)
B(-3,39,-8,LOG:9)
B(-7,39,-7,LOG:1)
B(-3,39,-7,LOG:9)
B(-3,39,-6,LOG:9)
B(-3,39,-5,LOG:9)
B(-3,39,-4,LOG:9)
B(-7,39,-3,LOG:1)
B(-3,39,-3,LOG:9)
B(-2,39,-3,LOG:5)
B(-1,39,-3,LOG:5)
B(-3,39,-2,LOG:9)
B(-3,39,-1,LOG:9)
B(-7,40,-7,LOG:1)
B(-7,40,-3,LOG:1)
B(-8,41,-7,LOG:5)
B(-7,41,-7,LOG:1)
B(-7,41,-3,LOG:1)
B(-7,42,-7,LOG:1)
B(-6,42,-7,LOG:5)
B(-5,42,-7,LOG:5)
B(-4,42,-7,LOG:5)
B(-3,42,-7,LOG:5)
B(-2,42,-7,LOG:5)
B(-1,42,-7,LOG:5)
B(-7,42,-6,LOG:9)
B(-7,42,-5,LOG:9)
B(-7,42,-4,LOG:9)
B(-7,42,-3,LOG:1)
B(-7,42,-2,LOG:9)
B(-7,42,-1,LOG:9)
B(-7,43,-8,LOG:9)
B(-3,43,-8,LOG:9)
B(-7,43,-7,LOG:1)
B(-3,43,-7,LOG:9)
B(-3,43,-6,LOG:9)
B(-3,43,-5,LOG:9)
B(-3,43,-4,LOG:9)
B(-7,43,-3,LOG:1)
B(-3,43,-3,LOG:9)
B(-2,43,-3,LOG:5)
B(-1,43,-3,LOG:5)
B(-3,43,-2,LOG:9)
B(-3,43,-1,LOG:9)
B(-7,44,-7,LOG:1)
B(-7,44,-3,LOG:1)
B(-8,45,-7,LOG:5)
B(-7,45,-7,LOG:1)
B(-7,45,-3,LOG:1)
B(-7,46,-7,LOG:1)
B(-6,46,-7,LOG:5)
B(-5,46,-7,LOG:5)
B(-4,46,-7,LOG:5)
B(-3,46,-7,LOG:5)
B(-2,46,-7,LOG:5)
B(-1,46,-7,LOG:5)
B(-7,46,-6,LOG:9)
B(-7,46,-5,LOG:9)
B(-7,46,-4,LOG:9)
B(-7,46,-3,LOG:1)
B(-7,46,-2,LOG:9)
B(-7,46,-1,LOG:9)
B(-7,47,-8,LOG:9)
B(-3,47,-8,LOG:9)
B(-7,47,-7,LOG:1)
B(-3,47,-7,LOG:9)
B(-3,47,-6,LOG:9)
B(-3,47,-5,LOG:9)
B(-3,47,-4,LOG:9)
B(-7,47,-3,LOG:1)
B(-3,47,-3,LOG:9)
B(-2,47,-3,LOG:5)
B(-1,47,-3,LOG:5)
B(-3,47,-2,LOG:9)
B(-3,47,-1,LOG:9)
B(-7,48,-8,LOG:9)
B(-3,48,-8,LOG:9)
B(-7,48,-7,LOG:1)
B(-3,48,-7,LOG:9)
B(-3,48,-6,LOG:9)
B(-3,48,-5,LOG:9)
B(-2,48,-5,LOG:5)
B(-1,48,-5,LOG:5)
B(-3,48,-4,LOG:9)
B(-7,48,-3,LOG:1)
B(-3,48,-3,LOG:9)
B(-2,48,-3,LOG:5)
B(-1,48,-3,LOG:5)
B(-3,48,-2,LOG:9)
B(-3,48,-1,LOG:9)
B(-7,49,-7,LOG:1)
B(-2,49,-5,COBBLESTONE:0)
B(-1,49,-5,COBBLESTONE:0)
B(-2,49,-4,COBBLESTONE:0)
B(-1,49,-4,COBBLESTONE:0)
B(-7,49,-3,LOG:1)
B(-2,49,-3,COBBLESTONE:0)
B(-1,49,-3,COBBLESTONE:0)
B(-7,50,-7,LOG:1)
B(-2,50,-5,COBBLESTONE:0)
B(-1,50,-5,COBBLESTONE:0)
B(-2,50,-4,COBBLESTONE:0)
B(-1,50,-4,COBBLESTONE:0)
B(-7,50,-3,LOG:1)
B(-2,50,-3,COBBLESTONE:0)
B(-1,50,-3,COBBLESTONE:0)
B(-8,51,-8,WOODEN_SLAB:8)
B(-7,51,-8,LOG:9)
B(-6,51,-8,WOODEN_SLAB:8)
B(-5,51,-8,WOODEN_SLAB:8)
B(-4,51,-8,WOODEN_SLAB:8)
B(-3,51,-8,WOODEN_SLAB:8)
B(-2,51,-8,WOODEN_SLAB:8)
B(-1,51,-8,WOODEN_SLAB:8)
B(-8,51,-7,LOG:5)
B(-7,51,-7,LOG:1)
B(-6,51,-7,WOODEN_SLAB:8)
B(-5,51,-7,WOODEN_SLAB:8)
B(-4,51,-7,WOODEN_SLAB:8)
B(-3,51,-7,WOODEN_SLAB:8)
B(-2,51,-7,WOODEN_SLAB:8)
B(-1,51,-7,WOODEN_SLAB:8)
B(-8,51,-6,WOODEN_SLAB:8)
B(-7,51,-6,WOODEN_SLAB:8)
B(-6,51,-6,WOODEN_SLAB:8)
B(-5,51,-6,WOODEN_SLAB:8)
B(-4,51,-6,WOODEN_SLAB:8)
B(-3,51,-6,WOODEN_SLAB:8)
B(-2,51,-6,WOODEN_SLAB:8)
B(-1,51,-6,WOODEN_SLAB:8)
B(-8,51,-5,WOODEN_SLAB:8)
B(-7,51,-5,WOODEN_SLAB:8)
B(-6,51,-5,WOODEN_SLAB:8)
B(-5,51,-5,WOODEN_SLAB:8)
B(-4,51,-5,WOODEN_SLAB:8)
B(-3,51,-5,WOODEN_SLAB:8)
B(-2,51,-5,DOUBLE_STONE_SLAB:0)
B(-1,51,-5,COBBLESTONE:0)
B(-8,51,-4,WOODEN_SLAB:8)
B(-7,51,-4,WOODEN_SLAB:8)
B(-6,51,-4,WOODEN_SLAB:8)
B(-5,51,-4,WOODEN_SLAB:8)
B(-4,51,-4,WOODEN_SLAB:8)
B(-3,51,-4,WOODEN_SLAB:8)
B(-2,51,-4,COBBLESTONE:0)
B(-1,51,-4,MAGMA:0)
B(-8,51,-3,LOG:5)
B(-7,51,-3,LOG:1)
B(-6,51,-3,WOODEN_SLAB:8)
B(-5,51,-3,WOODEN_SLAB:8)
B(-4,51,-3,WOODEN_SLAB:8)
B(-3,51,-3,WOODEN_SLAB:8)
B(-2,51,-3,DOUBLE_STONE_SLAB:0)
B(-1,51,-3,COBBLESTONE:0)
B(-8,51,-2,WOODEN_SLAB:8)
B(-7,51,-2,WOODEN_SLAB:8)
B(-6,51,-2,WOODEN_SLAB:8)
B(-5,51,-2,WOODEN_SLAB:8)
B(-4,51,-2,WOODEN_SLAB:8)
B(-3,51,-2,WOODEN_SLAB:8)
B(-2,51,-2,WOODEN_SLAB:8)
B(-1,51,-2,WOODEN_SLAB:8)
B(-8,51,-1,WOODEN_SLAB:8)
B(-7,51,-1,WOODEN_SLAB:8)
B(-6,51,-1,WOODEN_SLAB:8)
B(-5,51,-1,WOODEN_SLAB:8)
B(-4,51,-1,WOODEN_SLAB:8)
B(-3,51,-1,WOODEN_SLAB:8)
B(-2,51,-1,WOODEN_SLAB:8)
B(-1,51,-1,WOODEN_SLAB:8)
B(-7,52,-8,COBBLESTONE:0)
B(-6,52,-8,PLANKS:1)
B(-5,52,-8,SPRUCE_DOOR:1)
B(-4,52,-8,PLANKS:1)
B(-3,52,-8,PLANKS:1)
B(-2,52,-8,FURNACE:5)
B(-1,52,-8,CARPET:8)
B(-7,52,-7,LOG:1)
B(-6,52,-7,OAK_STAIRS:1)
B(-5,52,-7,CARPET:8)
B(-3,52,-7,CARPET:8)
B(-1,52,-7,CARPET:8)
B(-7,52,-6,COBBLESTONE:0)
B(-6,52,-6,PLANKS:1)
B(-5,52,-6,SPRUCE_DOOR:3)
B(-4,52,-6,PLANKS:1)
B(-3,52,-6,PLANKS:1)
B(-2,52,-6,CARPET:8)
B(-7,52,-5,COBBLESTONE:0)
B(-6,52,-5,BED:0)
B(-5,52,-5,CARPET:8)
B(-4,52,-5,BED:0)
B(-3,52,-5,PLANKS:1)
B(-2,52,-5,COBBLESTONE_WALL:0)
B(-1,52,-5,STONE_SLAB:0)
B(-7,52,-4,COBBLESTONE:0)
B(-6,52,-4,BED:8)
RB(-5,52,-4,AIR,25,CHEST:2,../NBT/StructureLoot/JunkChest_1.nbt,15,CHEST:2,../NBT/StructureLoot/JunkChest_2.nbt,15,CHEST:2,../NBT/StructureLoot/JunkChest_3.nbt,15,CHEST:2,../NBT/StructureLoot/JunkChest_4.nbt,15,CHEST:2,../NBT/StructureLoot/JunkChest_5.nbt,15,CHEST:2,../NBT/StructureLoot/Common1.nbt,15,CHEST:2,../NBT/StructureLoot/Common2.nbt,15,CHEST:2,../NBT/StructureLoot/Common3.nbt,15,CHEST:2,../NBT/StructureLoot/Common4.nbt,15,CHEST:2,../NBT/StructureLoot/Common5.nbt,15,CHEST:2,../NBT/StructureLoot/Common6.nbt,15,CHEST:2,../NBT/StructureLoot/Common7.nbt,15,CHEST:2,../NBT/StructureLoot/Common8.nbt,15,CHEST:2,../NBT/StructureLoot/Common9.nbt,15,CHEST:2,../NBT/StructureLoot/Common10.nbt,15,CHEST:2,../NBT/StructureLoot/Common11.nbt,15,CHEST:2,../NBT/StructureLoot/Common12.nbt,15,CHEST:2,../NBT/StructureLoot/Common13.nbt,15,CHEST:2,../NBT/StructureLoot/Common14.nbt,15,CHEST:2,../NBT/StructureLoot/Common15.nbt,100)
B(-4,52,-4,BED:8)
B(-3,52,-4,PLANKS:1)
B(-2,52,-4,COBBLESTONE:0)
B(-7,52,-3,LOG:1)
B(-6,52,-3,COBBLESTONE:0)
B(-5,52,-3,COBBLESTONE:0)
B(-4,52,-3,COBBLESTONE:0)
B(-3,52,-3,COBBLESTONE:0)
B(-2,52,-3,COBBLESTONE_WALL:0)
B(-1,52,-3,STONE_SLAB:0)
B(-7,52,-2,COBBLESTONE:0)
B(-6,52,-2,BED:9)
B(-5,52,-2,BED:1)
B(-3,52,-2,PLANKS:1)
B(-2,52,-2,CARPET:3)
B(-7,52,-1,COBBLESTONE:0)
B(-6,52,-1,STONE:2)
RB(-5,52,-1,AIR,25,CHEST:5,../NBT/StructureLoot/JunkChest_1.nbt,15,CHEST:5,../NBT/StructureLoot/JunkChest_2.nbt,15,CHEST:5,../NBT/StructureLoot/JunkChest_3.nbt,15,CHEST:5,../NBT/StructureLoot/JunkChest_4.nbt,15,CHEST:5,../NBT/StructureLoot/JunkChest_5.nbt,15,CHEST:5,../NBT/StructureLoot/Common1.nbt,15,CHEST:5,../NBT/StructureLoot/Common2.nbt,15,CHEST:5,../NBT/StructureLoot/Common3.nbt,15,CHEST:5,../NBT/StructureLoot/Common4.nbt,15,CHEST:5,../NBT/StructureLoot/Common5.nbt,15,CHEST:5,../NBT/StructureLoot/Common6.nbt,15,CHEST:5,../NBT/StructureLoot/Common7.nbt,15,CHEST:5,../NBT/StructureLoot/Common8.nbt,15,CHEST:5,../NBT/StructureLoot/Common9.nbt,15,CHEST:5,../NBT/StructureLoot/Common10.nbt,15,CHEST:5,../NBT/StructureLoot/Common11.nbt,15,CHEST:5,../NBT/StructureLoot/Common12.nbt,15,CHEST:5,../NBT/StructureLoot/Common13.nbt,15,CHEST:5,../NBT/StructureLoot/Common14.nbt,15,CHEST:5,../NBT/StructureLoot/Common15.nbt,100)
B(-4,52,-1,CARPET:3)
B(-3,52,-1,DARK_OAK_DOOR:2)
B(-1,52,-1,CARPET:3)
B(-7,53,-8,COBBLESTONE:0)
B(-6,53,-8,PLANKS:1)
B(-5,53,-8,SPRUCE_DOOR:8)
B(-4,53,-8,PLANKS:1)
B(-3,53,-8,PLANKS:1)
B(-2,53,-8,WOODEN_PRESSURE_PLATE:0)
B(-1,53,-8,AIR)
B(-7,53,-7,LOG:1)
B(-7,53,-6,PLANKS:1)
B(-6,53,-6,PLANKS:1)
B(-5,53,-6,SPRUCE_DOOR:8)
B(-4,53,-6,PLANKS:1)
B(-3,53,-6,PLANKS:1)
B(-7,53,-5,PLANKS:1)
B(-3,53,-5,PLANKS:1)
B(-2,53,-5,DOUBLE_STONE_SLAB:0)
B(-1,53,-5,STONE_SLAB:8)
B(-7,53,-4,PLANKS:1)
B(-5,53,-4,TORCH:4)
B(-3,53,-4,PLANKS:1)
B(-2,53,-4,COBBLESTONE:0)
B(-7,53,-3,LOG:1)
B(-6,53,-3,PLANKS:1)
B(-5,53,-3,PLANKS:1)
B(-4,53,-3,PLANKS:1)
B(-3,53,-3,PLANKS:1)
B(-2,53,-3,DOUBLE_STONE_SLAB:0)
B(-1,53,-3,STONE_SLAB:8)
B(-7,53,-2,PLANKS:1)
B(-3,53,-2,PLANKS:1)
B(-7,53,-1,DARK_OAK_FENCE:0)
RB(-6,53,-1,FLOWER_POT:0,../NBT/Flowers/flower_pot_01.nbt,5,FLOWER_POT:0,../NBT/Flowers/flower_pot_02.nbt,5,FLOWER_POT:0,../NBT/Flowers/flower_pot_03.nbt,5,FLOWER_POT:0,../NBT/Flowers/flower_pot_04.nbt,5,FLOWER_POT:0,../NBT/Flowers/flower_pot_05.nbt,5,FLOWER_POT:0,../NBT/Flowers/flower_pot_06.nbt,5,FLOWER_POT:0,../NBT/Flowers/flower_pot_07.nbt,5,FLOWER_POT:0,../NBT/Flowers/flower_pot_08.nbt,5,FLOWER_POT:0,../NBT/Flowers/flower_pot_09.nbt,5,FLOWER_POT:0,../NBT/Flowers/flower_pot_10.nbt,5,FLOWER_POT:0,../NBT/Flowers/flower_pot_11.nbt,5,FLOWER_POT:0,../NBT/Flowers/flower_pot_12.nbt,5,FLOWER_POT:0,../NBT/Flowers/flower_pot_13.nbt,5,FLOWER_POT:0,../NBT/Flowers/flower_pot_14.nbt,5,FLOWER_POT:0,../NBT/Flowers/flower_pot_15.nbt,5,FLOWER_POT:0,../NBT/Flowers/flower_pot_16.nbt,5,FLOWER_POT:0,../NBT/Flowers/flower_pot_17.nbt,5,FLOWER_POT:0,../NBT/Flowers/flower_pot_18.nbt,5,FLOWER_POT:0,../NBT/Flowers/flower_pot_19.nbt,5,FLOWER_POT:0,../NBT/Flowers/flower_pot_20.nbt,100)
B(-3,53,-1,DARK_OAK_DOOR:8)
B(-1,53,-1,AIR)
B(-8,54,-8,WOODEN_SLAB:9)
B(-7,54,-8,LOG:9)
B(-6,54,-8,DOUBLE_WOODEN_SLAB:0)
B(-5,54,-8,DOUBLE_WOODEN_SLAB:0)
B(-4,54,-8,DOUBLE_WOODEN_SLAB:0)
B(-3,54,-8,DOUBLE_WOODEN_SLAB:0)
B(-2,54,-8,WOODEN_SLAB:8)
B(-1,54,-8,WOODEN_SLAB:8)
B(-8,54,-7,SPRUCE_STAIRS:4)
B(-7,54,-7,LOG:1)
B(-6,54,-7,WOODEN_SLAB:8)
B(-5,54,-7,WOODEN_SLAB:8)
B(-4,54,-7,WOODEN_SLAB:8)
B(-3,54,-7,WOODEN_SLAB:8)
B(-2,54,-7,WOODEN_SLAB:8)
B(-1,54,-7,WOODEN_SLAB:8)
B(-8,54,-6,WOODEN_SLAB:9)
B(-7,54,-6,LOG:9)
B(-6,54,-6,DOUBLE_WOODEN_SLAB:0)
B(-5,54,-6,DOUBLE_WOODEN_SLAB:0)
B(-4,54,-6,DOUBLE_WOODEN_SLAB:0)
B(-3,54,-6,DOUBLE_WOODEN_SLAB:0)
B(-2,54,-6,WOODEN_SLAB:8)
B(-1,54,-6,WOODEN_SLAB:8)
B(-8,54,-5,WOODEN_SLAB:9)
B(-7,54,-5,LOG:9)
B(-6,54,-5,WOODEN_SLAB:8)
B(-5,54,-5,WOODEN_SLAB:8)
B(-4,54,-5,WOODEN_SLAB:8)
B(-3,54,-5,DOUBLE_WOODEN_SLAB:0)
B(-2,54,-5,COBBLESTONE:0)
B(-1,54,-5,COBBLESTONE:0)
B(-8,54,-4,WOODEN_SLAB:9)
B(-7,54,-4,LOG:9)
B(-6,54,-4,WOODEN_SLAB:8)
B(-5,54,-4,WOODEN_SLAB:8)
B(-4,54,-4,WOODEN_SLAB:8)
B(-3,54,-4,DOUBLE_WOODEN_SLAB:0)
B(-2,54,-4,COBBLESTONE:0)
B(-1,54,-4,COBBLESTONE:0)
B(-8,54,-3,SPRUCE_STAIRS:4)
B(-7,54,-3,LOG:1)
B(-6,54,-3,DOUBLE_WOODEN_SLAB:0)
B(-5,54,-3,DOUBLE_WOODEN_SLAB:0)
B(-4,54,-3,DOUBLE_WOODEN_SLAB:0)
B(-3,54,-3,DOUBLE_WOODEN_SLAB:0)
B(-2,54,-3,COBBLESTONE:0)
B(-1,54,-3,COBBLESTONE:0)
B(-8,54,-2,WOODEN_SLAB:9)
B(-7,54,-2,LOG:9)
B(-6,54,-2,WOODEN_SLAB:8)
B(-5,54,-2,WOODEN_SLAB:8)
B(-4,54,-2,WOODEN_SLAB:8)
B(-3,54,-2,DOUBLE_WOODEN_SLAB:0)
B(-2,54,-2,WOODEN_SLAB:8)
B(-1,54,-2,WOODEN_SLAB:8)
B(-8,54,-1,WOODEN_SLAB:9)
B(-7,54,-1,LOG:9)
B(-6,54,-1,WOODEN_SLAB:8)
B(-5,54,-1,WOODEN_SLAB:8)
B(-4,54,-1,WOODEN_SLAB:8)
B(-3,54,-1,DOUBLE_WOODEN_SLAB:0)
B(-2,54,-1,WOODEN_SLAB:8)
B(-1,54,-1,WOODEN_SLAB:8)
B(-8,55,-8,SPRUCE_FENCE:0)
B(-6,55,-8,COBBLESTONE:0)
B(-5,55,-8,BED:2)
B(-3,55,-8,BED:2)
B(-2,55,-8,PLANKS:1)
B(-8,55,-7,LOG:1)
B(-6,55,-7,COBBLESTONE:0)
B(-5,55,-7,TRAPDOOR:4)
B(-4,55,-7,CARPET:10)
B(-3,55,-7,CARPET:10)
B(-1,55,-7,CARPET:10)
B(-8,55,-6,SPRUCE_FENCE:0)
B(-6,55,-6,LOG:1)
B(-5,55,-6,BIRCH_STAIRS:1)
B(-3,55,-6,CARPET:10)
B(-8,55,-5,SPRUCE_FENCE:0)
B(-6,55,-5,DARK_OAK_DOOR:2)
B(-3,55,-5,CARPET:10)
B(-2,55,-5,STONE_SLAB:0)
B(-1,55,-5,COBBLESTONE_WALL:0)
B(-8,55,-4,SPRUCE_FENCE:0)
B(-6,55,-4,LOG:1)
B(-4,55,-4,CARPET:10)
B(-3,55,-4,CARPET:10)
B(-2,55,-4,STONE_SLAB:0)
B(-8,55,-3,LOG:1)
B(-6,55,-3,COBBLESTONE:0)
B(-5,55,-3,FURNACE:5)
B(-4,55,-3,CARPET:10)
B(-3,55,-3,CARPET:10)
B(-2,55,-3,STONE_SLAB:0)
B(-1,55,-3,COBBLESTONE_WALL:0)
B(-8,55,-2,SPRUCE_FENCE:0)
B(-6,55,-2,COBBLESTONE:0)
B(-5,55,-2,CRAFTING_TABLE:0)
B(-3,55,-2,CARPET:10)
B(-1,55,-2,CARPET:10)
B(-8,55,-1,SPRUCE_FENCE:0)
B(-6,55,-1,COBBLESTONE:0)
B(-5,55,-1,BIRCH_STAIRS:5)
B(-4,55,-1,WOODEN_SLAB:10)
B(-3,55,-1,WOODEN_SLAB:10)
B(-2,55,-1,BIRCH_STAIRS:4)
B(-6,56,-8,DARK_OAK_FENCE:0)
B(-2,56,-8,PLANKS:1)
B(-8,56,-7,STONE_SLAB:0)
B(-6,56,-7,PLANKS:1)
B(-6,56,-6,LOG:1)
B(-3,56,-6,AIR)
B(-8,56,-5,SPRUCE_FENCE:0)
B(-6,56,-5,DARK_OAK_DOOR:8)
B(-1,56,-5,DOUBLE_STONE_SLAB:0)
B(-6,56,-4,LOG:1)
B(-3,56,-4,AIR)
B(-1,56,-4,STONE_SLAB:8)
B(-8,56,-3,STONE_SLAB:0)
B(-6,56,-3,PLANKS:1)
B(-5,56,-3,WOODEN_PRESSURE_PLATE:0)
B(-1,56,-3,DOUBLE_STONE_SLAB:0)
B(-6,56,-2,DARK_OAK_FENCE:0)
B(-5,56,-2,STONE_PRESSURE_PLATE:0)
B(-6,56,-1,PLANKS:1)
RB(-3,56,-1,FLOWER_POT:0,../NBT/Flowers/flower_pot_01.nbt,5,FLOWER_POT:0,../NBT/Flowers/flower_pot_02.nbt,5,FLOWER_POT:0,../NBT/Flowers/flower_pot_03.nbt,5,FLOWER_POT:0,../NBT/Flowers/flower_pot_04.nbt,5,FLOWER_POT:0,../NBT/Flowers/flower_pot_05.nbt,5,FLOWER_POT:0,../NBT/Flowers/flower_pot_06.nbt,5,FLOWER_POT:0,../NBT/Flowers/flower_pot_07.nbt,5,FLOWER_POT:0,../NBT/Flowers/flower_pot_08.nbt,5,FLOWER_POT:0,../NBT/Flowers/flower_pot_09.nbt,5,FLOWER_POT:0,../NBT/Flowers/flower_pot_10.nbt,5,FLOWER_POT:0,../NBT/Flowers/flower_pot_11.nbt,5,FLOWER_POT:0,../NBT/Flowers/flower_pot_12.nbt,5,FLOWER_POT:0,../NBT/Flowers/flower_pot_13.nbt,5,FLOWER_POT:0,../NBT/Flowers/flower_pot_14.nbt,5,FLOWER_POT:0,../NBT/Flowers/flower_pot_15.nbt,5,FLOWER_POT:0,../NBT/Flowers/flower_pot_16.nbt,5,FLOWER_POT:0,../NBT/Flowers/flower_pot_17.nbt,5,FLOWER_POT:0,../NBT/Flowers/flower_pot_18.nbt,5,FLOWER_POT:0,../NBT/Flowers/flower_pot_19.nbt,5,FLOWER_POT:0,../NBT/Flowers/flower_pot_20.nbt,100)
B(-6,57,-8,LOG:9)
B(-5,57,-8,WOODEN_SLAB:8)
B(-4,57,-8,WOODEN_SLAB:8)
B(-3,57,-8,WOODEN_SLAB:8)
B(-2,57,-8,DOUBLE_WOODEN_SLAB:0)
B(-1,57,-8,WOODEN_SLAB:8)
B(-6,57,-7,LOG:9)
B(-5,57,-7,LOG:5)
B(-4,57,-7,LOG:5)
B(-3,57,-7,LOG:5)
B(-2,57,-7,LOG:5)
B(-1,57,-7,LOG:5)
B(-6,57,-6,LOG:1)
B(-5,57,-6,WOODEN_SLAB:8)
B(-4,57,-6,WOODEN_SLAB:8)
B(-3,57,-6,WOODEN_SLAB:8)
B(-2,57,-6,WOODEN_SLAB:8)
B(-1,57,-6,WOODEN_SLAB:8)
B(-6,57,-5,LOG:9)
B(-5,57,-5,WOODEN_SLAB:8)
B(-4,57,-5,WOODEN_SLAB:8)
B(-3,57,-5,WOODEN_SLAB:8)
B(-2,57,-5,WOODEN_SLAB:8)
B(-1,57,-5,WOODEN_SLAB:8)
B(-6,57,-4,LOG:1)
B(-5,57,-4,WOODEN_SLAB:8)
B(-4,57,-4,WOODEN_SLAB:8)
B(-3,57,-4,WOODEN_SLAB:8)
B(-2,57,-4,WOODEN_SLAB:8)
B(-1,57,-4,WOODEN_SLAB:8)
B(-6,57,-3,LOG:9)
B(-5,57,-3,WOODEN_SLAB:8)
B(-4,57,-3,WOODEN_SLAB:8)
B(-3,57,-3,WOODEN_SLAB:8)
B(-2,57,-3,WOODEN_SLAB:8)
B(-1,57,-3,WOODEN_SLAB:8)
B(-6,57,-2,LOG:9)
B(-5,57,-2,WOODEN_SLAB:8)
B(-4,57,-2,WOODEN_SLAB:8)
B(-3,57,-2,WOODEN_SLAB:8)
B(-2,57,-2,WOODEN_SLAB:8)
B(-1,57,-2,WOODEN_SLAB:8)
B(-6,57,-1,LOG:9)
B(-5,57,-1,WOODEN_SLAB:8)
B(-4,57,-1,WOODEN_SLAB:8)
B(-3,57,-1,WOODEN_SLAB:8)
B(-2,57,-1,WOODEN_SLAB:8)
B(-1,57,-1,WOODEN_SLAB:8)
B(-6,58,-8,SPRUCE_FENCE:0)
B(-6,58,-7,SPRUCE_FENCE:0)
B(-5,58,-7,BIRCH_STAIRS:2)
B(-4,58,-7,TRAPDOOR:7)
B(-2,58,-7,TRAPDOOR:6)
B(-1,58,-7,BIRCH_STAIRS:2)
B(-6,58,-6,LOG:1)
B(-5,58,-6,COBBLESTONE:0)
B(-4,58,-6,COBBLESTONE:0)
B(-3,58,-6,DARK_OAK_DOOR:3)
B(-2,58,-6,COBBLESTONE:0)
B(-1,58,-6,LOG:1)
B(-6,58,-5,COBBLESTONE:0)
B(-5,58,-5,CRAFTING_TABLE:0)
B(-4,58,-5,LOG:1)
B(-2,58,-5,STONE:2)
B(-1,58,-5,COBBLESTONE:0)
B(-6,58,-4,COBBLESTONE:0)
B(-5,58,-4,FURNACE:5)
B(-3,58,-4,CARPET:12)
B(-1,58,-4,STONE_STAIRS:3)
B(-6,58,-3,COBBLESTONE:0)
B(-5,58,-3,BIRCH_STAIRS:7)
B(-4,58,-3,CARPET:12)
B(-3,58,-3,CARPET:12)
B(-2,58,-3,CARPET:12)
B(-6,58,-2,COBBLESTONE:0)
B(-5,58,-2,WOODEN_SLAB:10)
B(-4,58,-2,LOG:1)
B(-3,58,-2,CARPET:12)
B(-2,58,-2,CARPET:12)
B(-1,58,-2,CARPET:12)
B(-6,58,-1,COBBLESTONE:0)
B(-5,58,-1,WOODEN_SLAB:10)
B(-4,58,-1,WOODEN_SLAB:10)
B(-3,58,-1,BIRCH_STAIRS:4)
B(-2,58,-1,TRAPDOOR:6)
B(-1,58,-1,BIRCH_STAIRS:2)
B(-6,59,-6,LOG:1)
B(-5,59,-6,PLANKS:1)
B(-4,59,-6,PLANKS:1)
B(-3,59,-6,DARK_OAK_DOOR:8)
B(-2,59,-6,PLANKS:1)
B(-1,59,-6,LOG:1)
B(-6,59,-5,PLANKS:1)
B(-4,59,-5,LOG:1)
RB(-2,59,-5,FLOWER_POT:0,../NBT/Flowers/flower_pot_01.nbt,5,FLOWER_POT:0,../NBT/Flowers/flower_pot_02.nbt,5,FLOWER_POT:0,../NBT/Flowers/flower_pot_03.nbt,5,FLOWER_POT:0,../NBT/Flowers/flower_pot_04.nbt,5,FLOWER_POT:0,../NBT/Flowers/flower_pot_05.nbt,5,FLOWER_POT:0,../NBT/Flowers/flower_pot_06.nbt,5,FLOWER_POT:0,../NBT/Flowers/flower_pot_07.nbt,5,FLOWER_POT:0,../NBT/Flowers/flower_pot_08.nbt,5,FLOWER_POT:0,../NBT/Flowers/flower_pot_09.nbt,5,FLOWER_POT:0,../NBT/Flowers/flower_pot_10.nbt,5,FLOWER_POT:0,../NBT/Flowers/flower_pot_11.nbt,5,FLOWER_POT:0,../NBT/Flowers/flower_pot_12.nbt,5,FLOWER_POT:0,../NBT/Flowers/flower_pot_13.nbt,5,FLOWER_POT:0,../NBT/Flowers/flower_pot_14.nbt,5,FLOWER_POT:0,../NBT/Flowers/flower_pot_15.nbt,5,FLOWER_POT:0,../NBT/Flowers/flower_pot_16.nbt,5,FLOWER_POT:0,../NBT/Flowers/flower_pot_17.nbt,5,FLOWER_POT:0,../NBT/Flowers/flower_pot_18.nbt,5,FLOWER_POT:0,../NBT/Flowers/flower_pot_19.nbt,5,FLOWER_POT:0,../NBT/Flowers/flower_pot_20.nbt,100)
B(-1,59,-5,COBBLESTONE:0)
B(-6,59,-4,DARK_OAK_FENCE:0)
B(-1,59,-4,STONE_SLAB:0)
B(-6,59,-3,DARK_OAK_FENCE:0)
B(-5,59,-3,CARPET:0)
B(-6,59,-2,PLANKS:1)
B(-4,59,-2,LOG:1)
B(-6,59,-1,PLANKS:1)
RB(-3,59,-1,FLOWER_POT:0,../NBT/Flowers/flower_pot_01.nbt,5,FLOWER_POT:0,../NBT/Flowers/flower_pot_02.nbt,5,FLOWER_POT:0,../NBT/Flowers/flower_pot_03.nbt,5,FLOWER_POT:0,../NBT/Flowers/flower_pot_04.nbt,5,FLOWER_POT:0,../NBT/Flowers/flower_pot_05.nbt,5,FLOWER_POT:0,../NBT/Flowers/flower_pot_06.nbt,5,FLOWER_POT:0,../NBT/Flowers/flower_pot_07.nbt,5,FLOWER_POT:0,../NBT/Flowers/flower_pot_08.nbt,5,FLOWER_POT:0,../NBT/Flowers/flower_pot_09.nbt,5,FLOWER_POT:0,../NBT/Flowers/flower_pot_10.nbt,5,FLOWER_POT:0,../NBT/Flowers/flower_pot_11.nbt,5,FLOWER_POT:0,../NBT/Flowers/flower_pot_12.nbt,5,FLOWER_POT:0,../NBT/Flowers/flower_pot_13.nbt,5,FLOWER_POT:0,../NBT/Flowers/flower_pot_14.nbt,5,FLOWER_POT:0,../NBT/Flowers/flower_pot_15.nbt,5,FLOWER_POT:0,../NBT/Flowers/flower_pot_16.nbt,5,FLOWER_POT:0,../NBT/Flowers/flower_pot_17.nbt,5,FLOWER_POT:0,../NBT/Flowers/flower_pot_18.nbt,5,FLOWER_POT:0,../NBT/Flowers/flower_pot_19.nbt,5,FLOWER_POT:0,../NBT/Flowers/flower_pot_20.nbt,100)
B(-6,60,-8,WOODEN_SLAB:8)
B(-7,60,-7,OAK_STAIRS:2)
B(-6,60,-7,OAK_STAIRS:6)
B(-7,60,-6,OAK_STAIRS:7)
B(-6,60,-6,LOG:1)
B(-5,60,-6,LOG:5)
B(-4,60,-6,LOG:5)
B(-3,60,-6,LOG:5)
B(-2,60,-6,LOG:5)
B(-1,60,-6,LOG:5)
B(-6,60,-5,LOG:9)
B(-5,60,-5,WOODEN_SLAB:8)
B(-4,60,-5,LOG:1)
B(-3,60,-5,LOG:5)
B(-2,60,-5,LOG:5)
B(-1,60,-5,LOG:9)
B(-6,60,-4,LOG:9)
B(-5,60,-4,WOODEN_SLAB:8)
B(-4,60,-4,LOG:9)
B(-3,60,-4,WOODEN_SLAB:8)
B(-2,60,-4,WOODEN_SLAB:8)
B(-1,60,-4,LOG:9)
B(-6,60,-3,LOG:9)
B(-5,60,-3,WOODEN_SLAB:8)
B(-4,60,-3,LOG:9)
B(-3,60,-3,WOODEN_SLAB:8)
B(-2,60,-3,WOODEN_SLAB:8)
B(-1,60,-3,LOG:9)
B(-6,60,-2,LOG:9)
B(-5,60,-2,WOODEN_SLAB:8)
B(-4,60,-2,LOG:1)
B(-3,60,-2,LOG:5)
B(-2,60,-2,LOG:5)
B(-1,60,-2,LOG:9)
B(-6,60,-1,LOG:9)
B(-5,60,-1,WOODEN_SLAB:8)
B(-4,60,-1,WOODEN_SLAB:8)
B(-3,60,-1,WOODEN_SLAB:8)
B(-2,60,-1,WOODEN_SLAB:8)
B(-1,60,-1,LOG:9)
B(-6,61,-8,WOODEN_SLAB:0)
B(-5,61,-8,WOODEN_SLAB:1)
B(-4,61,-8,WOODEN_SLAB:1)
B(-3,61,-8,WOODEN_SLAB:1)
B(-2,61,-8,WOODEN_SLAB:1)
B(-1,61,-8,WOODEN_SLAB:1)
B(-6,61,-7,WOODEN_SLAB:0)
B(-5,61,-7,WOODEN_SLAB:1)
B(-4,61,-7,WOODEN_SLAB:1)
B(-3,61,-7,WOODEN_SLAB:1)
B(-2,61,-7,WOODEN_SLAB:1)
B(-1,61,-7,WOODEN_SLAB:1)
B(-7,61,-6,OAK_STAIRS:2)
B(-6,61,-6,SPRUCE_STAIRS:2)
B(-5,61,-6,SPRUCE_STAIRS:2)
B(-4,61,-6,SPRUCE_STAIRS:2)
B(-3,61,-6,SPRUCE_STAIRS:2)
B(-2,61,-6,SPRUCE_STAIRS:2)
B(-1,61,-6,SPRUCE_STAIRS:2)
B(-7,61,-5,OAK_STAIRS:7)
B(-6,61,-5,PLANKS:1)
B(-5,61,-5,PLANKS:1)
B(-4,61,-5,LOG:1)
B(-3,61,-5,DARK_OAK_FENCE:0)
B(-2,61,-5,DARK_OAK_FENCE:0)
B(-1,61,-5,LOG:1)
B(-6,61,-4,PLANKS:1)
B(-5,61,-4,PLANKS:1)
B(-4,61,-4,PLANKS:1)
B(-3,61,-4,LADDER:5)
B(-2,61,-4,CARPET:13)
B(-1,61,-4,CARPET:13)
B(-6,61,-3,PLANKS:1)
B(-5,61,-3,CARPET:13)
B(-2,61,-3,CARPET:13)
B(-6,61,-2,PLANKS:1)
B(-5,61,-2,PLANKS:1)
B(-4,61,-2,LOG:1)
B(-3,61,-2,CARPET:13)
B(-2,61,-2,CARPET:13)
B(-1,61,-2,LOG:1)
B(-7,61,-1,OAK_STAIRS:6)
B(-6,61,-1,PLANKS:1)
B(-5,61,-1,PLANKS:1)
B(-4,61,-1,PLANKS:1)
B(-3,61,-1,DARK_OAK_FENCE:0)
B(-2,61,-1,DARK_OAK_FENCE:0)
B(-1,61,-1,PLANKS:1)
B(-4,62,-6,OAK_STAIRS:0)
B(-1,62,-6,OAK_STAIRS:1)
B(-7,62,-5,OAK_STAIRS:2)
B(-6,62,-5,SPRUCE_STAIRS:2)
B(-5,62,-5,SPRUCE_STAIRS:2)
B(-4,62,-5,LOG:1)
B(-3,62,-5,DARK_OAK_FENCE:0)
B(-2,62,-5,DARK_OAK_FENCE:0)
B(-1,62,-5,LOG:1)
B(-7,62,-4,OAK_STAIRS:7)
B(-6,62,-4,PLANKS:1)
B(-5,62,-4,PLANKS:1)
B(-4,62,-4,PLANKS:1)
B(-3,62,-4,LADDER:5)
B(-6,62,-3,DARK_OAK_FENCE:0)
B(-1,62,-3,AIR)
B(-7,62,-2,OAK_STAIRS:6)
B(-6,62,-2,PLANKS:1)
B(-5,62,-2,PLANKS:1)
B(-4,62,-2,LOG:1)
B(-1,62,-2,LOG:1)
B(-7,62,-1,OAK_STAIRS:3)
B(-6,62,-1,SPRUCE_STAIRS:3)
B(-5,62,-1,SPRUCE_STAIRS:3)
B(-4,62,-1,SPRUCE_STAIRS:0)
B(-3,62,-1,DARK_OAK_FENCE:0)
B(-2,62,-1,DARK_OAK_FENCE:0)
B(-1,62,-1,SPRUCE_STAIRS:1)
B(-4,63,-6,OAK_STAIRS:0)
B(-3,63,-6,OAK_STAIRS:5)
B(-2,63,-6,OAK_STAIRS:4)
B(-1,63,-6,OAK_STAIRS:1)
B(-4,63,-5,LOG:1)
B(-3,63,-5,PLANKS:1)
B(-2,63,-5,PLANKS:1)
B(-1,63,-5,LOG:1)
B(-7,63,-4,OAK_STAIRS:2)
B(-6,63,-4,SPRUCE_STAIRS:2)
B(-5,63,-4,SPRUCE_STAIRS:2)
B(-4,63,-4,PLANKS:1)
B(-3,63,-4,LADDER:5)
B(-1,63,-4,PLANKS:1)
B(-7,63,-3,OAK_STAIRS:4)
B(-6,63,-3,PLANKS:1)
B(-5,63,-3,PLANKS:1)
B(-4,63,-3,PLANKS:1)
B(-1,63,-3,PLANKS:1)
B(-7,63,-2,OAK_STAIRS:3)
B(-6,63,-2,SPRUCE_STAIRS:3)
B(-5,63,-2,SPRUCE_STAIRS:3)
B(-4,63,-2,LOG:1)
B(-3,63,-2,PLANKS:1)
B(-2,63,-2,PLANKS:1)
B(-1,63,-2,LOG:1)
B(-4,63,-1,SPRUCE_STAIRS:0)
B(-3,63,-1,PLANKS:1)
B(-2,63,-1,PLANKS:1)
B(-1,63,-1,SPRUCE_STAIRS:1)
B(-3,64,-6,OAK_STAIRS:0)
B(-2,64,-6,OAK_STAIRS:1)
B(-4,64,-5,LOG:1)
B(-3,64,-5,PLANKS:1)
B(-2,64,-5,PLANKS:1)
B(-1,64,-5,LOG:1)
B(-4,64,-4,PLANKS:1)
B(-3,64,-4,LADDER:5)
B(-1,64,-4,PLANKS:1)
B(-7,64,-3,WOODEN_SLAB:0)
B(-6,64,-3,WOODEN_SLAB:1)
B(-5,64,-3,WOODEN_SLAB:1)
B(-4,64,-3,PLANKS:1)
B(-1,64,-3,PLANKS:1)
B(-4,64,-2,LOG:1)
B(-3,64,-2,PLANKS:1)
B(-2,64,-2,PLANKS:1)
B(-1,64,-2,LOG:1)
B(-3,64,-1,SPRUCE_STAIRS:0)
B(-2,64,-1,SPRUCE_STAIRS:1)
B(-4,65,-6,SPRUCE_STAIRS:6)
B(-3,65,-6,SPRUCE_FENCE:0)
B(-2,65,-6,SPRUCE_FENCE:0)
B(-1,65,-6,SPRUCE_STAIRS:6)
B(-5,65,-5,SPRUCE_STAIRS:4)
B(-4,65,-5,LOG:1)
B(-3,65,-5,LOG:5)
B(-2,65,-5,LOG:5)
B(-1,65,-5,LOG:1)
B(-5,65,-4,SPRUCE_FENCE:0)
B(-4,65,-4,LOG:9)
B(-3,65,-4,LADDER:5)
B(-2,65,-4,WOODEN_SLAB:8)
B(-1,65,-4,LOG:9)
B(-5,65,-3,SPRUCE_FENCE:0)
B(-4,65,-3,LOG:9)
B(-3,65,-3,WOODEN_SLAB:8)
B(-2,65,-3,WOODEN_SLAB:8)
B(-1,65,-3,LOG:9)
B(-5,65,-2,SPRUCE_STAIRS:4)
B(-4,65,-2,LOG:1)
B(-3,65,-2,LOG:5)
B(-2,65,-2,LOG:5)
B(-1,65,-2,LOG:1)
B(-4,65,-1,SPRUCE_STAIRS:7)
B(-3,65,-1,SPRUCE_FENCE:0)
B(-2,65,-1,SPRUCE_FENCE:0)
B(-1,65,-1,SPRUCE_STAIRS:7)
B(-4,66,-6,LOG:1)
B(-3,66,-6,SPRUCE_FENCE:0)
B(-2,66,-6,SPRUCE_FENCE:0)
B(-1,66,-6,LOG:1)
B(-5,66,-5,LOG:1)
B(-1,66,-5,SPRUCE_FENCE:0)
B(-5,66,-4,SPRUCE_FENCE:0)
B(-5,66,-3,SPRUCE_FENCE:0)
B(-5,66,-2,LOG:1)
B(-4,66,-1,LOG:1)
B(-3,66,-1,SPRUCE_FENCE:0)
B(-2,66,-1,SPRUCE_FENCE:0)
B(-1,66,-1,LOG:1)
B(-4,67,-6,COBBLESTONE_WALL:0)
B(-1,67,-6,COBBLESTONE_WALL:0)
B(-5,67,-5,COBBLESTONE_WALL:0)
B(-1,67,-5,TORCH:5)
B(-5,67,-2,COBBLESTONE_WALL:0)
B(-4,67,-1,COBBLESTONE_WALL:0)
B(-1,67,-1,COBBLESTONE_WALL:0)
B(-4,68,-6,SPRUCE_STAIRS:0)
B(-3,68,-6,SPRUCE_STAIRS:2)
B(-2,68,-6,SPRUCE_STAIRS:2)
B(-1,68,-6,SPRUCE_STAIRS:1)
B(-5,68,-5,SPRUCE_STAIRS:2)
B(-4,68,-5,WOODEN_SLAB:9)
B(-3,68,-5,WOODEN_SLAB:9)
B(-2,68,-5,WOODEN_SLAB:9)
B(-1,68,-5,WOODEN_SLAB:9)
B(-5,68,-4,SPRUCE_STAIRS:0)
B(-4,68,-4,WOODEN_SLAB:9)
B(-1,68,-4,WOODEN_SLAB:9)
B(-5,68,-3,SPRUCE_STAIRS:0)
B(-4,68,-3,WOODEN_SLAB:9)
B(-1,68,-3,WOODEN_SLAB:9)
B(-5,68,-2,SPRUCE_STAIRS:3)
B(-4,68,-2,WOODEN_SLAB:9)
B(-3,68,-2,WOODEN_SLAB:9)
B(-2,68,-2,WOODEN_SLAB:9)
B(-1,68,-2,WOODEN_SLAB:9)
B(-4,68,-1,SPRUCE_STAIRS:0)
B(-3,68,-1,SPRUCE_STAIRS:3)
B(-2,68,-1,SPRUCE_STAIRS:3)
B(-1,68,-1,SPRUCE_STAIRS:1)
B(-4,69,-5,WOODEN_SLAB:1)
B(-3,69,-5,DOUBLE_WOODEN_SLAB:1)
B(-2,69,-5,DOUBLE_WOODEN_SLAB:1)
B(-1,69,-5,WOODEN_SLAB:1)
B(-4,69,-4,DOUBLE_WOODEN_SLAB:1)
B(-3,69,-4,DOUBLE_WOODEN_SLAB:1)
B(-2,69,-4,DOUBLE_WOODEN_SLAB:1)
B(-1,69,-4,DOUBLE_WOODEN_SLAB:1)
B(-4,69,-3,DOUBLE_WOODEN_SLAB:1)
B(-3,69,-3,DOUBLE_WOODEN_SLAB:1)
B(-2,69,-3,DOUBLE_WOODEN_SLAB:1)
B(-1,69,-3,DOUBLE_WOODEN_SLAB:1)
B(-4,69,-2,WOODEN_SLAB:1)
B(-3,69,-2,DOUBLE_WOODEN_SLAB:1)
B(-2,69,-2,DOUBLE_WOODEN_SLAB:1)
B(-1,69,-2,WOODEN_SLAB:1)
B(-3,70,-5,SPRUCE_STAIRS:2)
B(-2,70,-5,SPRUCE_STAIRS:2)
B(-4,70,-4,SPRUCE_STAIRS:0)
B(-3,70,-4,DOUBLE_WOODEN_SLAB:1)
B(-2,70,-4,DOUBLE_WOODEN_SLAB:1)
B(-1,70,-4,SPRUCE_STAIRS:1)
B(-4,70,-3,SPRUCE_STAIRS:0)
B(-3,70,-3,DOUBLE_WOODEN_SLAB:1)
B(-2,70,-3,DOUBLE_WOODEN_SLAB:1)
B(-1,70,-3,SPRUCE_STAIRS:1)
B(-3,70,-2,SPRUCE_STAIRS:3)
B(-2,70,-2,SPRUCE_STAIRS:3)
B(-3,71,-4,SPRUCE_STAIRS:2)
B(-2,71,-4,SPRUCE_STAIRS:1)
B(-3,71,-3,SPRUCE_STAIRS:0)
B(-2,71,-3,SPRUCE_STAIRS:3)

E(-1,53,-8,VILLAGER,1,../NBT/MOBS/RandomVillager.txt)
E(-1,53,-1,VILLAGER,1,../NBT/MOBS/RandomVillager.txt)
E(-3,56,-6,VILLAGER,1,../NBT/MOBS/RandomVillager.txt)
E(-3,56,-4,VILLAGER,1,../NBT/MOBS/RandomVillager.txt)
E(-1,62,-3,VILLAGER,1,../NBT/MOBS/RandomVillager.txt)

BR(-8,0,0,WestPort_6x6,NORTH,100)
