Author: Bo3 BulkEdit

Description: Converted Schematic - Modified by Bo3BulkEdit

Version: 3

SettingsMode: WriteDisable

IsOTGPlus: false
Tree: false
Frequency: 1
Rarity: 100
RotateRandomly: false
SpawnHeight: randomY
MaxBranchDepth: 20
ExcludedBiomes: All

MinHeight: 0
MaxHeight: 256

SourceBlocks: AIR
MaxPercentageOutsideSourceBlock: 100
OutsideSourceBlock: placeAnyway

B(-7,0,-8,LOG:1)
B(-3,0,-8,LOG:1)
B(-8,0,-5,LOG:1)
B(-4,0,-5,LOG:1)
B(-4,0,-1,LOG:1)
B(-7,1,-8,LOG:1)
B(-6,1,-8,LOG:5)
B(-5,1,-8,LOG:5)
B(-4,1,-8,LOG:5)
B(-3,1,-8,LOG:1)
B(-8,1,-5,LOG:1)
B(-4,1,-5,LOG:1)
B(-3,1,-5,LOG:5)
B(-2,1,-5,LOG:5)
B(-1,1,-5,LOG:5)
B(-4,1,-1,LOG:1)
B(-8,2,-8,LOG:9)
B(-7,2,-8,LOG:1)
B(-3,2,-8,LOG:1)
B(-2,2,-8,LOG:5)
B(-1,2,-8,LOG:5)
B(-8,2,-7,LOG:9)
B(-8,2,-6,LOG:9)
B(-8,2,-5,LOG:1)
B(-7,2,-5,LOG:5)
B(-6,2,-5,LOG:5)
B(-5,2,-5,LOG:5)
B(-4,2,-5,LOG:1)
B(-8,2,-4,LOG:9)
B(-8,2,-3,LOG:9)
B(-8,2,-2,LOG:9)
B(-8,2,-1,LOG:5)
B(-7,2,-1,LOG:5)
B(-6,2,-1,LOG:5)
B(-5,2,-1,LOG:5)
B(-4,2,-1,LOG:1)
B(-3,2,-1,LOG:5)
B(-2,2,-1,LOG:5)
B(-1,2,-1,LOG:5)
B(-7,3,-8,LOG:1)
B(-3,3,-8,LOG:1)
B(-8,3,-5,LOG:1)
B(-4,3,-5,LOG:1)
B(-4,3,-1,LOG:1)
B(-7,4,-8,LOG:1)
B(-3,4,-8,LOG:1)
B(-8,4,-5,LOG:1)
B(-4,4,-5,LOG:1)
B(-4,4,-1,LOG:1)
B(-7,5,-8,LOG:1)
B(-6,5,-8,LOG:5)
B(-5,5,-8,LOG:5)
B(-4,5,-8,LOG:5)
B(-3,5,-8,LOG:1)
B(-8,5,-5,LOG:1)
B(-4,5,-5,LOG:1)
B(-3,5,-5,LOG:5)
B(-2,5,-5,LOG:5)
B(-1,5,-5,LOG:5)
B(-4,5,-1,LOG:1)
B(-8,6,-8,LOG:9)
B(-7,6,-8,LOG:1)
B(-3,6,-8,LOG:1)
B(-2,6,-8,LOG:5)
B(-1,6,-8,LOG:5)
B(-8,6,-7,LOG:9)
B(-8,6,-6,LOG:9)
B(-8,6,-5,LOG:1)
B(-7,6,-5,LOG:5)
B(-6,6,-5,LOG:5)
B(-5,6,-5,LOG:5)
B(-4,6,-5,LOG:1)
B(-8,6,-4,LOG:9)
B(-8,6,-3,LOG:9)
B(-8,6,-2,LOG:9)
B(-8,6,-1,LOG:5)
B(-7,6,-1,LOG:5)
B(-6,6,-1,LOG:5)
B(-5,6,-1,LOG:5)
B(-4,6,-1,LOG:1)
B(-3,6,-1,LOG:5)
B(-2,6,-1,LOG:5)
B(-1,6,-1,LOG:5)
B(-7,7,-8,LOG:1)
B(-3,7,-8,LOG:1)
B(-8,7,-5,LOG:1)
B(-4,7,-5,LOG:1)
B(-4,7,-1,LOG:1)
B(-7,8,-8,LOG:1)
B(-3,8,-8,LOG:1)
B(-8,8,-5,LOG:1)
B(-4,8,-5,LOG:1)
B(-4,8,-1,LOG:1)
B(-7,9,-8,LOG:1)
B(-6,9,-8,LOG:5)
B(-5,9,-8,LOG:5)
B(-4,9,-8,LOG:5)
B(-3,9,-8,LOG:1)
B(-8,9,-5,LOG:1)
B(-4,9,-5,LOG:1)
B(-3,9,-5,LOG:5)
B(-2,9,-5,LOG:5)
B(-1,9,-5,LOG:5)
B(-4,9,-1,LOG:1)
B(-8,10,-8,LOG:9)
B(-7,10,-8,LOG:1)
B(-3,10,-8,LOG:1)
B(-2,10,-8,LOG:5)
B(-1,10,-8,LOG:5)
B(-8,10,-7,LOG:9)
B(-8,10,-6,LOG:9)
B(-8,10,-5,LOG:1)
B(-7,10,-5,LOG:5)
B(-6,10,-5,LOG:5)
B(-5,10,-5,LOG:5)
B(-4,10,-5,LOG:1)
B(-8,10,-4,LOG:9)
B(-8,10,-3,LOG:9)
B(-8,10,-2,LOG:9)
B(-8,10,-1,LOG:5)
B(-7,10,-1,LOG:5)
B(-6,10,-1,LOG:5)
B(-5,10,-1,LOG:5)
B(-4,10,-1,LOG:1)
B(-3,10,-1,LOG:5)
B(-2,10,-1,LOG:5)
B(-1,10,-1,LOG:5)
B(-7,11,-8,LOG:1)
B(-3,11,-8,LOG:1)
B(-8,11,-5,LOG:1)
B(-4,11,-5,LOG:1)
B(-4,11,-1,LOG:1)
B(-7,12,-8,LOG:1)
B(-3,12,-8,LOG:1)
B(-8,12,-5,LOG:1)
B(-4,12,-5,LOG:1)
B(-4,12,-1,LOG:1)
B(-7,13,-8,LOG:1)
B(-6,13,-8,LOG:5)
B(-5,13,-8,LOG:5)
B(-4,13,-8,LOG:5)
B(-3,13,-8,LOG:1)
B(-8,13,-5,LOG:1)
B(-4,13,-5,LOG:1)
B(-3,13,-5,LOG:5)
B(-2,13,-5,LOG:5)
B(-1,13,-5,LOG:5)
B(-4,13,-1,LOG:1)
B(-8,14,-8,LOG:9)
B(-7,14,-8,LOG:1)
B(-3,14,-8,LOG:1)
B(-2,14,-8,LOG:5)
B(-1,14,-8,LOG:5)
B(-8,14,-7,LOG:9)
B(-8,14,-6,LOG:9)
B(-8,14,-5,LOG:1)
B(-7,14,-5,LOG:5)
B(-6,14,-5,LOG:5)
B(-5,14,-5,LOG:5)
B(-4,14,-5,LOG:1)
B(-8,14,-4,LOG:9)
B(-8,14,-3,LOG:9)
B(-8,14,-2,LOG:9)
B(-8,14,-1,LOG:5)
B(-7,14,-1,LOG:5)
B(-6,14,-1,LOG:5)
B(-5,14,-1,LOG:5)
B(-4,14,-1,LOG:1)
B(-3,14,-1,LOG:5)
B(-2,14,-1,LOG:5)
B(-1,14,-1,LOG:5)
B(-7,15,-8,LOG:1)
B(-3,15,-8,LOG:1)
B(-8,15,-5,LOG:1)
B(-4,15,-5,LOG:1)
B(-4,15,-1,LOG:1)
B(-7,16,-8,LOG:1)
B(-3,16,-8,LOG:1)
B(-8,16,-5,LOG:1)
B(-4,16,-5,LOG:1)
B(-4,16,-1,LOG:1)
B(-7,17,-8,LOG:1)
B(-6,17,-8,LOG:5)
B(-5,17,-8,LOG:5)
B(-4,17,-8,LOG:5)
B(-3,17,-8,LOG:1)
B(-8,17,-5,LOG:1)
B(-4,17,-5,LOG:1)
B(-3,17,-5,LOG:5)
B(-2,17,-5,LOG:5)
B(-1,17,-5,LOG:5)
B(-4,17,-1,LOG:1)
B(-8,18,-8,LOG:9)
B(-7,18,-8,LOG:1)
B(-3,18,-8,LOG:1)
B(-2,18,-8,LOG:5)
B(-1,18,-8,LOG:5)
B(-8,18,-7,LOG:9)
B(-8,18,-6,LOG:9)
B(-8,18,-5,LOG:1)
B(-7,18,-5,LOG:5)
B(-6,18,-5,LOG:5)
B(-5,18,-5,LOG:5)
B(-4,18,-5,LOG:1)
B(-8,18,-4,LOG:9)
B(-8,18,-3,LOG:9)
B(-8,18,-2,LOG:9)
B(-8,18,-1,LOG:5)
B(-7,18,-1,LOG:5)
B(-6,18,-1,LOG:5)
B(-5,18,-1,LOG:5)
B(-4,18,-1,LOG:1)
B(-3,18,-1,LOG:5)
B(-2,18,-1,LOG:5)
B(-1,18,-1,LOG:5)
B(-7,19,-8,LOG:1)
B(-3,19,-8,LOG:1)
B(-8,19,-5,LOG:1)
B(-4,19,-5,LOG:1)
B(-4,19,-1,LOG:1)
B(-7,20,-8,LOG:1)
B(-3,20,-8,LOG:1)
B(-8,20,-5,LOG:1)
B(-4,20,-5,LOG:1)
B(-4,20,-1,LOG:1)
B(-7,21,-8,LOG:1)
B(-6,21,-8,LOG:5)
B(-5,21,-8,LOG:5)
B(-4,21,-8,LOG:5)
B(-3,21,-8,LOG:1)
B(-8,21,-5,LOG:1)
B(-4,21,-5,LOG:1)
B(-3,21,-5,LOG:5)
B(-2,21,-5,LOG:5)
B(-1,21,-5,LOG:5)
B(-4,21,-1,LOG:1)
B(-8,22,-8,LOG:9)
B(-7,22,-8,LOG:1)
B(-3,22,-8,LOG:1)
B(-2,22,-8,LOG:5)
B(-1,22,-8,LOG:5)
B(-8,22,-7,LOG:9)
B(-8,22,-6,LOG:9)
B(-8,22,-5,LOG:1)
B(-7,22,-5,LOG:5)
B(-6,22,-5,LOG:5)
B(-5,22,-5,LOG:5)
B(-4,22,-5,LOG:1)
B(-8,22,-4,LOG:9)
B(-8,22,-3,LOG:9)
B(-8,22,-2,LOG:9)
B(-8,22,-1,LOG:5)
B(-7,22,-1,LOG:5)
B(-6,22,-1,LOG:5)
B(-5,22,-1,LOG:5)
B(-4,22,-1,LOG:1)
B(-3,22,-1,LOG:5)
B(-2,22,-1,LOG:5)
B(-1,22,-1,LOG:5)
B(-7,23,-8,LOG:1)
B(-3,23,-8,LOG:1)
B(-8,23,-5,LOG:1)
B(-4,23,-5,LOG:1)
B(-4,23,-1,LOG:1)
B(-7,24,-8,LOG:1)
B(-3,24,-8,LOG:1)
B(-8,24,-5,LOG:1)
B(-4,24,-5,LOG:1)
B(-4,24,-1,LOG:1)
B(-7,25,-8,LOG:1)
B(-6,25,-8,LOG:5)
B(-5,25,-8,LOG:5)
B(-4,25,-8,LOG:5)
B(-3,25,-8,LOG:1)
B(-8,25,-5,LOG:1)
B(-4,25,-5,LOG:1)
B(-3,25,-5,LOG:5)
B(-2,25,-5,LOG:5)
B(-1,25,-5,LOG:5)
B(-4,25,-1,LOG:1)
B(-8,26,-8,LOG:9)
B(-7,26,-8,LOG:1)
B(-3,26,-8,LOG:1)
B(-2,26,-8,LOG:5)
B(-1,26,-8,LOG:5)
B(-8,26,-7,LOG:9)
B(-8,26,-6,LOG:9)
B(-8,26,-5,LOG:1)
B(-7,26,-5,LOG:5)
B(-6,26,-5,LOG:5)
B(-5,26,-5,LOG:5)
B(-4,26,-5,LOG:1)
B(-8,26,-4,LOG:9)
B(-8,26,-3,LOG:9)
B(-8,26,-2,LOG:9)
B(-8,26,-1,LOG:5)
B(-7,26,-1,LOG:5)
B(-6,26,-1,LOG:5)
B(-5,26,-1,LOG:5)
B(-4,26,-1,LOG:1)
B(-3,26,-1,LOG:5)
B(-2,26,-1,LOG:5)
B(-1,26,-1,LOG:5)
B(-7,27,-8,LOG:1)
B(-3,27,-8,LOG:1)
B(-8,27,-5,LOG:1)
B(-4,27,-5,LOG:1)
B(-4,27,-1,LOG:1)
B(-7,28,-8,LOG:1)
B(-3,28,-8,LOG:1)
B(-8,28,-5,LOG:1)
B(-4,28,-5,LOG:1)
B(-4,28,-1,LOG:1)
B(-7,29,-8,LOG:1)
B(-6,29,-8,LOG:5)
B(-5,29,-8,LOG:5)
B(-4,29,-8,LOG:5)
B(-3,29,-8,LOG:1)
B(-8,29,-5,LOG:1)
B(-4,29,-5,LOG:1)
B(-3,29,-5,LOG:5)
B(-2,29,-5,LOG:5)
B(-1,29,-5,LOG:5)
B(-4,29,-1,LOG:1)
B(-8,30,-8,LOG:9)
B(-7,30,-8,LOG:1)
B(-3,30,-8,LOG:1)
B(-2,30,-8,LOG:5)
B(-1,30,-8,LOG:5)
B(-8,30,-7,LOG:9)
B(-8,30,-6,LOG:9)
B(-8,30,-5,LOG:1)
B(-7,30,-5,LOG:5)
B(-6,30,-5,LOG:5)
B(-5,30,-5,LOG:5)
B(-4,30,-5,LOG:1)
B(-8,30,-4,LOG:9)
B(-8,30,-3,LOG:9)
B(-8,30,-2,LOG:9)
B(-8,30,-1,LOG:5)
B(-7,30,-1,LOG:5)
B(-6,30,-1,LOG:5)
B(-5,30,-1,LOG:5)
B(-4,30,-1,LOG:1)
B(-3,30,-1,LOG:5)
B(-2,30,-1,LOG:5)
B(-1,30,-1,LOG:5)
B(-7,31,-8,LOG:1)
B(-3,31,-8,LOG:1)
B(-8,31,-5,LOG:1)
B(-4,31,-5,LOG:1)
B(-4,31,-1,LOG:1)
B(-7,32,-8,LOG:1)
B(-3,32,-8,LOG:1)
B(-8,32,-5,LOG:1)
B(-4,32,-5,LOG:1)
B(-4,32,-1,LOG:1)
B(-7,33,-8,LOG:1)
B(-6,33,-8,LOG:5)
B(-5,33,-8,LOG:5)
B(-4,33,-8,LOG:5)
B(-3,33,-8,LOG:1)
B(-8,33,-5,LOG:1)
B(-4,33,-5,LOG:1)
B(-3,33,-5,LOG:5)
B(-2,33,-5,LOG:5)
B(-1,33,-5,LOG:5)
B(-4,33,-1,LOG:1)
B(-8,34,-8,LOG:9)
B(-7,34,-8,LOG:1)
B(-3,34,-8,LOG:1)
B(-2,34,-8,LOG:5)
B(-1,34,-8,LOG:5)
B(-8,34,-7,LOG:9)
B(-8,34,-6,LOG:9)
B(-8,34,-5,LOG:1)
B(-7,34,-5,LOG:5)
B(-6,34,-5,LOG:5)
B(-5,34,-5,LOG:5)
B(-4,34,-5,LOG:1)
B(-8,34,-4,LOG:9)
B(-8,34,-3,LOG:9)
B(-8,34,-2,LOG:9)
B(-8,34,-1,LOG:5)
B(-7,34,-1,LOG:5)
B(-6,34,-1,LOG:5)
B(-5,34,-1,LOG:5)
B(-4,34,-1,LOG:1)
B(-3,34,-1,LOG:5)
B(-2,34,-1,LOG:5)
B(-1,34,-1,LOG:5)
B(-7,35,-8,LOG:1)
B(-3,35,-8,LOG:1)
B(-8,35,-5,LOG:1)
B(-4,35,-5,LOG:1)
B(-4,35,-1,LOG:1)
B(-7,36,-8,LOG:1)
B(-3,36,-8,LOG:1)
B(-8,36,-5,LOG:1)
B(-4,36,-5,LOG:1)
B(-4,36,-1,LOG:1)
B(-7,37,-8,LOG:1)
B(-6,37,-8,LOG:5)
B(-5,37,-8,LOG:5)
B(-4,37,-8,LOG:5)
B(-3,37,-8,LOG:1)
B(-8,37,-5,LOG:1)
B(-4,37,-5,LOG:1)
B(-3,37,-5,LOG:5)
B(-2,37,-5,LOG:5)
B(-1,37,-5,LOG:5)
B(-4,37,-1,LOG:1)
B(-8,38,-8,LOG:9)
B(-7,38,-8,LOG:1)
B(-3,38,-8,LOG:1)
B(-2,38,-8,LOG:5)
B(-1,38,-8,LOG:5)
B(-8,38,-7,LOG:9)
B(-8,38,-6,LOG:9)
B(-8,38,-5,LOG:1)
B(-7,38,-5,LOG:5)
B(-6,38,-5,LOG:5)
B(-5,38,-5,LOG:5)
B(-4,38,-5,LOG:1)
B(-8,38,-4,LOG:9)
B(-8,38,-3,LOG:9)
B(-8,38,-2,LOG:9)
B(-8,38,-1,LOG:5)
B(-7,38,-1,LOG:5)
B(-6,38,-1,LOG:5)
B(-5,38,-1,LOG:5)
B(-4,38,-1,LOG:1)
B(-3,38,-1,LOG:5)
B(-2,38,-1,LOG:5)
B(-1,38,-1,LOG:5)
B(-7,39,-8,LOG:1)
B(-3,39,-8,LOG:1)
B(-8,39,-5,LOG:1)
B(-4,39,-5,LOG:1)
B(-4,39,-1,LOG:1)
B(-7,40,-8,LOG:1)
B(-3,40,-8,LOG:1)
B(-8,40,-5,LOG:1)
B(-4,40,-5,LOG:1)
B(-4,40,-1,LOG:1)
B(-7,41,-8,LOG:1)
B(-6,41,-8,LOG:5)
B(-5,41,-8,LOG:5)
B(-4,41,-8,LOG:5)
B(-3,41,-8,LOG:1)
B(-8,41,-5,LOG:1)
B(-4,41,-5,LOG:1)
B(-3,41,-5,LOG:5)
B(-2,41,-5,LOG:5)
B(-1,41,-5,LOG:5)
B(-4,41,-1,LOG:1)
B(-8,42,-8,LOG:9)
B(-7,42,-8,LOG:1)
B(-3,42,-8,LOG:1)
B(-2,42,-8,LOG:5)
B(-1,42,-8,LOG:5)
B(-8,42,-7,LOG:9)
B(-8,42,-6,LOG:9)
B(-8,42,-5,LOG:1)
B(-7,42,-5,LOG:5)
B(-6,42,-5,LOG:5)
B(-5,42,-5,LOG:5)
B(-4,42,-5,LOG:1)
B(-8,42,-4,LOG:9)
B(-8,42,-3,LOG:9)
B(-8,42,-2,LOG:9)
B(-8,42,-1,LOG:5)
B(-7,42,-1,LOG:5)
B(-6,42,-1,LOG:5)
B(-5,42,-1,LOG:5)
B(-4,42,-1,LOG:1)
B(-3,42,-1,LOG:5)
B(-2,42,-1,LOG:5)
B(-1,42,-1,LOG:5)
B(-7,43,-8,LOG:1)
B(-3,43,-8,LOG:1)
B(-8,43,-5,LOG:1)
B(-4,43,-5,LOG:1)
B(-4,43,-1,LOG:1)
B(-7,44,-8,LOG:1)
B(-3,44,-8,LOG:1)
B(-8,44,-5,LOG:1)
B(-4,44,-5,LOG:1)
B(-4,44,-1,LOG:1)
B(-7,45,-8,LOG:1)
B(-6,45,-8,LOG:5)
B(-5,45,-8,LOG:5)
B(-4,45,-8,LOG:5)
B(-3,45,-8,LOG:1)
B(-8,45,-5,LOG:1)
B(-4,45,-5,LOG:1)
B(-3,45,-5,LOG:5)
B(-2,45,-5,LOG:5)
B(-1,45,-5,LOG:5)
B(-4,45,-1,LOG:1)
B(-8,46,-8,LOG:9)
B(-7,46,-8,LOG:1)
B(-3,46,-8,LOG:1)
B(-2,46,-8,LOG:5)
B(-1,46,-8,LOG:5)
B(-8,46,-7,LOG:9)
B(-8,46,-6,LOG:9)
B(-8,46,-5,LOG:1)
B(-7,46,-5,LOG:5)
B(-6,46,-5,LOG:5)
B(-5,46,-5,LOG:5)
B(-4,46,-5,LOG:1)
B(-8,46,-4,LOG:9)
B(-8,46,-3,LOG:9)
B(-8,46,-2,LOG:9)
B(-8,46,-1,LOG:5)
B(-7,46,-1,LOG:5)
B(-6,46,-1,LOG:5)
B(-5,46,-1,LOG:5)
B(-4,46,-1,LOG:1)
B(-3,46,-1,LOG:5)
B(-2,46,-1,LOG:5)
B(-1,46,-1,LOG:5)
B(-7,47,-8,LOG:1)
B(-3,47,-8,LOG:1)
B(-8,47,-5,LOG:1)
B(-4,47,-5,LOG:1)
B(-4,47,-1,LOG:1)
B(-7,48,-8,LOG:1)
B(-3,48,-8,LOG:1)
B(-8,48,-5,LOG:1)
B(-4,48,-5,LOG:1)
B(-4,48,-1,LOG:1)
B(-7,49,-8,LOG:1)
B(-3,49,-8,LOG:1)
B(-8,49,-5,LOG:1)
B(-4,49,-5,LOG:1)
B(-4,49,-1,LOG:1)
B(-7,50,-8,LOG:1)
B(-6,50,-8,LOG:5)
B(-5,50,-8,LOG:5)
B(-4,50,-8,LOG:5)
B(-3,50,-8,LOG:1)
B(-2,50,-8,LOG:5)
B(-1,50,-8,LOG:5)
B(-7,50,-7,DARK_OAK_STAIRS:7)
B(-6,50,-7,WOODEN_SLAB:8)
B(-5,50,-7,WOODEN_SLAB:8)
B(-4,50,-7,WOODEN_SLAB:8)
B(-3,50,-7,DARK_OAK_STAIRS:7)
B(-2,50,-7,WOODEN_SLAB:8)
B(-1,50,-7,WOODEN_SLAB:8)
B(-8,50,-5,LOG:1)
B(-4,50,-5,LOG:1)
B(-4,50,-1,LOG:1)
B(-3,50,-1,WOODEN_SLAB:8)
B(-2,50,-1,WOODEN_SLAB:8)
B(-1,50,-1,WOODEN_SLAB:8)
B(-8,51,-8,LOG:9)
B(-3,51,-8,LOG:1)
B(-2,51,-8,COBBLESTONE:0)
B(-1,51,-8,COBBLESTONE:0)
B(-8,51,-7,LOG:9)
B(-8,51,-6,LOG:9)
B(-8,51,-5,LOG:1)
B(-7,51,-5,LOG:5)
B(-6,51,-5,LOG:5)
B(-5,51,-5,LOG:5)
B(-4,51,-5,LOG:1)
B(-3,51,-5,LOG:5)
B(-2,51,-5,LOG:5)
B(-1,51,-5,LOG:5)
B(-8,51,-4,WOODEN_SLAB:8)
B(-7,51,-4,WOODEN_SLAB:8)
B(-6,51,-4,WOODEN_SLAB:8)
B(-5,51,-4,WOODEN_SLAB:8)
B(-4,51,-4,WOODEN_SLAB:8)
B(-3,51,-4,WOODEN_SLAB:8)
B(-2,51,-4,WOODEN_SLAB:8)
B(-1,51,-4,WOODEN_SLAB:8)
B(-8,51,-3,WOODEN_SLAB:8)
B(-7,51,-3,WOODEN_SLAB:8)
B(-6,51,-3,WOODEN_SLAB:8)
B(-5,51,-3,WOODEN_SLAB:8)
B(-4,51,-3,WOODEN_SLAB:8)
B(-3,51,-3,WOODEN_SLAB:8)
B(-2,51,-3,WOODEN_SLAB:8)
B(-1,51,-3,WOODEN_SLAB:8)
B(-8,51,-2,WOODEN_SLAB:8)
B(-7,51,-2,WOODEN_SLAB:8)
B(-6,51,-2,WOODEN_SLAB:8)
B(-5,51,-2,WOODEN_SLAB:8)
B(-4,51,-2,WOODEN_SLAB:8)
B(-3,51,-2,WOODEN_SLAB:8)
B(-2,51,-2,WOODEN_SLAB:8)
B(-1,51,-2,WOODEN_SLAB:8)
B(-8,51,-1,WOODEN_SLAB:8)
B(-7,51,-1,WOODEN_SLAB:8)
B(-6,51,-1,WOODEN_SLAB:8)
B(-5,51,-1,WOODEN_SLAB:8)
B(-4,51,-1,LOG:1)
B(-3,51,-1,LOG:5)
B(-2,51,-1,LOG:5)
B(-1,51,-1,LOG:5)
B(-8,52,-8,COBBLESTONE:0)
B(-3,52,-8,LOG:1)
B(-2,52,-8,PLANKS:1)
B(-1,52,-8,SPRUCE_FENCE:0)
B(-8,52,-7,COBBLESTONE:0)
B(-8,52,-6,COBBLESTONE:0)
B(-8,52,-5,LOG:1)
B(-7,52,-5,COBBLESTONE:0)
B(-6,52,-5,COBBLESTONE:0)
B(-5,52,-5,COBBLESTONE:0)
B(-4,52,-5,LOG:1)
B(-3,52,-5,SPRUCE_FENCE:0)
B(-2,52,-5,SPRUCE_FENCE:0)
B(-1,52,-5,SPRUCE_FENCE:0)
B(-8,52,-4,WOODEN_SLAB:10)
B(-7,52,-4,WOODEN_SLAB:10)
B(-6,52,-4,BIRCH_STAIRS:4)
B(-5,52,-4,BOOKSHELF:0)
B(-4,52,-4,COBBLESTONE:0)
B(-6,52,-3,CARPET:12)
B(-4,52,-3,SPRUCE_DOOR:0)
B(-8,52,-2,CARPET:12)
RB(-6,52,-2,AIR,25,CHEST:2,../NBT/StructureLoot/JunkChest_1.nbt,15,CHEST:2,../NBT/StructureLoot/JunkChest_2.nbt,15,CHEST:2,../NBT/StructureLoot/JunkChest_3.nbt,15,CHEST:2,../NBT/StructureLoot/JunkChest_4.nbt,15,CHEST:2,../NBT/StructureLoot/JunkChest_5.nbt,15,CHEST:2,../NBT/StructureLoot/Common1.nbt,15,CHEST:2,../NBT/StructureLoot/Common2.nbt,15,CHEST:2,../NBT/StructureLoot/Common3.nbt,15,CHEST:2,../NBT/StructureLoot/Common4.nbt,15,CHEST:2,../NBT/StructureLoot/Common5.nbt,15,CHEST:2,../NBT/StructureLoot/Common6.nbt,15,CHEST:2,../NBT/StructureLoot/Common7.nbt,15,CHEST:2,../NBT/StructureLoot/Common8.nbt,15,CHEST:2,../NBT/StructureLoot/Common9.nbt,15,CHEST:2,../NBT/StructureLoot/Common10.nbt,15,CHEST:2,../NBT/StructureLoot/Common11.nbt,15,CHEST:2,../NBT/StructureLoot/Common12.nbt,15,CHEST:2,../NBT/StructureLoot/Common13.nbt,15,CHEST:2,../NBT/StructureLoot/Common14.nbt,15,CHEST:2,../NBT/StructureLoot/Common15.nbt,100)
RB(-5,52,-2,AIR,25,CHEST:2,../NBT/StructureLoot/JunkChest_1.nbt,15,CHEST:2,../NBT/StructureLoot/JunkChest_2.nbt,15,CHEST:2,../NBT/StructureLoot/JunkChest_3.nbt,15,CHEST:2,../NBT/StructureLoot/JunkChest_4.nbt,15,CHEST:2,../NBT/StructureLoot/JunkChest_5.nbt,15,CHEST:2,../NBT/StructureLoot/Common1.nbt,15,CHEST:2,../NBT/StructureLoot/Common2.nbt,15,CHEST:2,../NBT/StructureLoot/Common3.nbt,15,CHEST:2,../NBT/StructureLoot/Common4.nbt,15,CHEST:2,../NBT/StructureLoot/Common5.nbt,15,CHEST:2,../NBT/StructureLoot/Common6.nbt,15,CHEST:2,../NBT/StructureLoot/Common7.nbt,15,CHEST:2,../NBT/StructureLoot/Common8.nbt,15,CHEST:2,../NBT/StructureLoot/Common9.nbt,15,CHEST:2,../NBT/StructureLoot/Common10.nbt,15,CHEST:2,../NBT/StructureLoot/Common11.nbt,15,CHEST:2,../NBT/StructureLoot/Common12.nbt,15,CHEST:2,../NBT/StructureLoot/Common13.nbt,15,CHEST:2,../NBT/StructureLoot/Common14.nbt,15,CHEST:2,../NBT/StructureLoot/Common15.nbt,100)
B(-4,52,-2,COBBLESTONE:0)
B(-8,52,-1,PLANKS:1)
B(-7,52,-1,PLANKS:1)
B(-6,52,-1,PLANKS:1)
B(-5,52,-1,PLANKS:1)
B(-4,52,-1,LOG:1)
B(-8,53,-8,PLANKS:1)
B(-4,53,-8,DARK_OAK_STAIRS:4)
B(-3,53,-8,LOG:1)
B(-2,53,-8,LOG:5)
B(-1,53,-8,LOG:5)
B(-8,53,-7,PLANKS:1)
B(-3,53,-7,DARK_OAK_STAIRS:7)
B(-2,53,-7,WOODEN_SLAB:9)
B(-1,53,-7,WOODEN_SLAB:9)
B(-8,53,-6,PLANKS:1)
B(-8,53,-5,LOG:1)
B(-7,53,-5,PLANKS:1)
B(-6,53,-5,DARK_OAK_FENCE:0)
B(-5,53,-5,PLANKS:1)
B(-4,53,-5,LOG:1)
B(-5,53,-4,BOOKSHELF:0)
B(-4,53,-4,COBBLESTONE:0)
B(-4,53,-3,SPRUCE_DOOR:8)
B(-4,53,-2,COBBLESTONE:0)
B(-8,53,-1,PLANKS:1)
B(-7,53,-1,PLANKS:1)
B(-6,53,-1,PLANKS:1)
B(-5,53,-1,PLANKS:1)
B(-4,53,-1,LOG:1)
B(-8,54,-8,LOG:9)
B(-4,54,-8,LOG:1)
B(-3,54,-8,LOG:1)
B(-2,54,-8,COBBLESTONE:0)
B(-1,54,-8,COBBLESTONE:0)
B(-8,54,-7,LOG:9)
B(-3,54,-7,LOG:1)
B(-2,54,-7,SPRUCE_FENCE:0)
B(-1,54,-7,SPRUCE_FENCE:0)
B(-8,54,-6,LOG:9)
B(-8,54,-5,LOG:1)
B(-7,54,-5,LOG:5)
B(-6,54,-5,LOG:5)
B(-5,54,-5,LOG:5)
B(-4,54,-5,LOG:1)
B(-3,54,-5,LOG:5)
B(-2,54,-5,LOG:5)
B(-1,54,-5,LOG:5)
B(-8,54,-4,WOODEN_SLAB:8)
B(-7,54,-4,WOODEN_SLAB:8)
B(-6,54,-4,WOODEN_SLAB:8)
B(-5,54,-4,WOODEN_SLAB:8)
B(-4,54,-4,LOG:9)
B(-3,54,-4,WOODEN_SLAB:8)
B(-2,54,-4,WOODEN_SLAB:8)
B(-1,54,-4,LOG:9)
B(-8,54,-3,WOODEN_SLAB:8)
B(-7,54,-3,WOODEN_SLAB:8)
B(-6,54,-3,WOODEN_SLAB:8)
B(-5,54,-3,WOODEN_SLAB:8)
B(-4,54,-3,LOG:9)
B(-3,54,-3,WOODEN_SLAB:8)
B(-2,54,-3,WOODEN_SLAB:8)
B(-1,54,-3,LOG:9)
B(-8,54,-2,WOODEN_SLAB:8)
B(-7,54,-2,WOODEN_SLAB:8)
B(-6,54,-2,WOODEN_SLAB:8)
B(-5,54,-2,WOODEN_SLAB:8)
B(-4,54,-2,LOG:9)
B(-3,54,-2,WOODEN_SLAB:8)
B(-2,54,-2,WOODEN_SLAB:8)
B(-1,54,-2,LOG:9)
B(-8,54,-1,DOUBLE_WOODEN_SLAB:0)
B(-7,54,-1,DOUBLE_WOODEN_SLAB:0)
B(-6,54,-1,DOUBLE_WOODEN_SLAB:0)
B(-5,54,-1,DOUBLE_WOODEN_SLAB:0)
B(-4,54,-1,LOG:1)
B(-3,54,-1,LOG:5)
B(-2,54,-1,LOG:5)
B(-1,54,-1,LOG:5)
B(-8,55,-8,COBBLESTONE:0)
B(-4,55,-8,STONE_SLAB:0)
B(-3,55,-8,LOG:1)
B(-2,55,-8,PLANKS:1)
B(-1,55,-8,PLANKS:1)
B(-8,55,-7,COBBLESTONE:0)
B(-3,55,-7,STONE_SLAB:0)
B(-8,55,-6,COBBLESTONE:0)
B(-8,55,-5,LOG:1)
B(-7,55,-5,COBBLESTONE:0)
B(-6,55,-5,COBBLESTONE:0)
B(-5,55,-5,COBBLESTONE:0)
B(-4,55,-5,LOG:1)
B(-3,55,-5,SPRUCE_FENCE:0)
B(-2,55,-5,SPRUCE_FENCE:0)
B(-1,55,-5,SPRUCE_FENCE:0)
B(-8,55,-4,PLANKS:1)
B(-7,55,-4,DARK_OAK_FENCE:0)
B(-6,55,-4,TRAPDOOR:6)
B(-5,55,-4,DARK_OAK_STAIRS:3)
B(-4,55,-4,COBBLESTONE:0)
B(-8,55,-3,PLANKS:1)
B(-7,55,-3,CARPET:4)
B(-5,55,-3,CARPET:4)
B(-4,55,-3,SPRUCE_DOOR:0)
B(-8,55,-2,SPRUCE_DOOR:2)
B(-6,55,-2,CARPET:4)
B(-5,55,-2,CARPET:4)
B(-4,55,-2,COBBLESTONE:0)
B(-8,55,-1,PLANKS:1)
B(-7,55,-1,PLANKS:1)
B(-6,55,-1,SPRUCE_DOOR:1)
B(-5,55,-1,PLANKS:1)
B(-4,55,-1,LOG:1)
B(-3,55,-1,LOG:1)
B(-2,55,-1,SPRUCE_FENCE:0)
B(-1,55,-1,SPRUCE_FENCE:0)
B(-8,56,-8,PLANKS:1)
B(-3,56,-8,LOG:1)
B(-2,56,-8,LOG:5)
B(-1,56,-8,LOG:5)
B(-8,56,-7,DARK_OAK_FENCE:0)
B(-8,56,-6,PLANKS:1)
B(-8,56,-5,LOG:1)
B(-7,56,-5,PLANKS:1)
B(-6,56,-5,PLANKS:1)
B(-5,56,-5,PLANKS:1)
B(-4,56,-5,LOG:1)
B(-8,56,-4,PLANKS:1)
B(-7,56,-4,TORCH:5)
B(-4,56,-4,PLANKS:1)
B(-8,56,-3,PLANKS:1)
B(-4,56,-3,SPRUCE_DOOR:8)
B(-8,56,-2,SPRUCE_DOOR:8)
B(-4,56,-2,PLANKS:1)
B(-8,56,-1,PLANKS:1)
B(-7,56,-1,PLANKS:1)
B(-6,56,-1,SPRUCE_DOOR:8)
B(-5,56,-1,PLANKS:1)
B(-4,56,-1,LOG:1)
B(-3,56,-1,STONE_SLAB:0)
B(-1,56,-1,SPRUCE_FENCE:0)
B(-8,57,-8,LOG:9)
B(-7,57,-8,WOODEN_SLAB:9)
B(-3,57,-8,LOG:1)
B(-2,57,-8,COBBLESTONE:0)
B(-1,57,-8,COBBLESTONE:0)
B(-8,57,-7,LOG:9)
B(-7,57,-7,WOODEN_SLAB:9)
B(-8,57,-6,LOG:9)
B(-7,57,-6,WOODEN_SLAB:9)
B(-6,57,-6,WOODEN_SLAB:9)
B(-5,57,-6,WOODEN_SLAB:9)
B(-4,57,-6,SPRUCE_STAIRS:6)
B(-8,57,-5,LOG:1)
B(-7,57,-5,LOG:5)
B(-6,57,-5,LOG:5)
B(-5,57,-5,LOG:5)
B(-4,57,-5,LOG:1)
B(-3,57,-5,SPRUCE_STAIRS:5)
B(-8,57,-4,DOUBLE_WOODEN_SLAB:0)
B(-7,57,-4,WOODEN_SLAB:8)
B(-6,57,-4,WOODEN_SLAB:8)
B(-5,57,-4,WOODEN_SLAB:8)
B(-4,57,-4,LOG:9)
B(-3,57,-4,WOODEN_SLAB:9)
B(-8,57,-3,DOUBLE_WOODEN_SLAB:0)
B(-7,57,-3,WOODEN_SLAB:8)
B(-6,57,-3,WOODEN_SLAB:8)
B(-5,57,-3,WOODEN_SLAB:8)
B(-4,57,-3,LOG:9)
B(-3,57,-3,WOODEN_SLAB:9)
B(-8,57,-2,DOUBLE_WOODEN_SLAB:0)
B(-7,57,-2,WOODEN_SLAB:8)
B(-6,57,-2,WOODEN_SLAB:8)
B(-5,57,-2,WOODEN_SLAB:8)
B(-4,57,-2,LOG:9)
B(-3,57,-2,WOODEN_SLAB:9)
B(-8,57,-1,DOUBLE_WOODEN_SLAB:0)
B(-7,57,-1,DOUBLE_WOODEN_SLAB:0)
B(-6,57,-1,DOUBLE_WOODEN_SLAB:0)
B(-5,57,-1,DOUBLE_WOODEN_SLAB:0)
B(-4,57,-1,LOG:1)
B(-3,57,-1,SPRUCE_STAIRS:5)
B(-7,58,-8,SPRUCE_FENCE:0)
B(-3,58,-8,LOG:1)
B(-2,58,-8,PLANKS:1)
B(-1,58,-8,DARK_OAK_FENCE:0)
B(-8,58,-7,LOG:1)
B(-7,58,-7,SPRUCE_FENCE:0)
B(-7,58,-6,LOG:1)
B(-6,58,-6,SPRUCE_FENCE:0)
B(-5,58,-6,SPRUCE_FENCE:0)
B(-4,58,-6,LOG:1)
B(-3,58,-5,LOG:1)
B(-3,58,-4,DARK_OAK_FENCE:0)
B(-8,58,-3,COBBLESTONE:0)
B(-7,58,-3,SPRUCE_DOOR:3)
B(-6,58,-3,COBBLESTONE:0)
B(-5,58,-3,LOG:1)
B(-3,58,-3,DARK_OAK_FENCE:0)
B(-8,58,-2,DARK_OAK_STAIRS:3)
B(-7,58,-2,TRAPDOOR:7)
B(-6,58,-2,DARK_OAK_FENCE:0)
B(-5,58,-2,COBBLESTONE:0)
B(-3,58,-2,DARK_OAK_FENCE:0)
B(-8,58,-1,CARPET:4)
B(-5,58,-1,COBBLESTONE:0)
B(-3,58,-1,LOG:1)
B(-3,59,-8,LOG:1)
B(-2,59,-8,LOG:5)
B(-1,59,-8,LOG:5)
B(-8,59,-7,LOG:1)
B(-3,59,-7,DARK_OAK_STAIRS:7)
B(-2,59,-7,WOODEN_SLAB:9)
B(-1,59,-7,WOODEN_SLAB:9)
B(-7,59,-6,STONE_SLAB:0)
B(-4,59,-6,STONE_SLAB:0)
B(-3,59,-5,STONE_SLAB:0)
B(-8,59,-3,PLANKS:1)
B(-7,59,-3,SPRUCE_DOOR:8)
B(-6,59,-3,PLANKS:1)
B(-5,59,-3,LOG:1)
B(-6,59,-2,TORCH:5)
B(-5,59,-2,PLANKS:1)
B(-5,59,-1,DARK_OAK_FENCE:0)
B(-3,59,-1,STONE_SLAB:0)
B(-8,60,-8,LOG:9)
B(-3,60,-8,LOG:1)
B(-2,60,-8,COBBLESTONE:0)
B(-1,60,-8,DARK_OAK_DOOR:1)
B(-8,60,-7,STONE_BRICK_STAIRS:3)
B(-3,60,-7,LOG:1)
B(-2,60,-7,SPRUCE_FENCE:0)
B(-1,60,-7,SPRUCE_FENCE:0)
B(-8,60,-4,OAK_STAIRS:2)
B(-7,60,-4,OAK_STAIRS:2)
B(-6,60,-4,OAK_STAIRS:2)
B(-5,60,-4,OAK_STAIRS:2)
B(-4,60,-4,OAK_STAIRS:2)
B(-8,60,-3,LOG:5)
B(-7,60,-3,LOG:5)
B(-6,60,-3,LOG:5)
B(-5,60,-3,LOG:1)
B(-4,60,-3,OAK_STAIRS:7)
B(-8,60,-2,WOODEN_SLAB:8)
B(-7,60,-2,WOODEN_SLAB:8)
B(-6,60,-2,WOODEN_SLAB:8)
B(-5,60,-2,LOG:9)
B(-8,60,-1,WOODEN_SLAB:8)
B(-7,60,-1,WOODEN_SLAB:8)
B(-6,60,-1,WOODEN_SLAB:8)
B(-5,60,-1,LOG:9)
B(-3,61,-8,LOG:1)
B(-2,61,-8,PLANKS:1)
B(-1,61,-8,DARK_OAK_DOOR:8)
B(-3,61,-7,STONE_SLAB:0)
B(-7,61,-3,SPRUCE_STAIRS:1)
B(-6,61,-3,SPRUCE_STAIRS:2)
B(-5,61,-3,SPRUCE_STAIRS:2)
B(-4,61,-3,OAK_STAIRS:2)
B(-8,61,-2,DARK_OAK_FENCE:0)
B(-7,61,-2,PLANKS:1)
B(-6,61,-2,PLANKS:1)
B(-5,61,-2,PLANKS:1)
B(-4,61,-2,OAK_STAIRS:7)
B(-5,61,-1,PLANKS:1)
B(-4,62,-8,OAK_STAIRS:6)
B(-3,62,-8,LOG:1)
B(-2,62,-8,LOG:5)
B(-1,62,-8,LOG:5)
B(-4,62,-7,OAK_STAIRS:3)
B(-3,62,-7,OAK_STAIRS:3)
B(-2,62,-7,OAK_STAIRS:3)
B(-1,62,-7,OAK_STAIRS:3)
B(-8,62,-3,SPRUCE_STAIRS:6)
B(-7,62,-3,SPRUCE_STAIRS:1)
B(-8,62,-2,SPRUCE_STAIRS:7)
B(-7,62,-2,SPRUCE_STAIRS:2)
B(-6,62,-2,SPRUCE_STAIRS:2)
B(-5,62,-2,SPRUCE_STAIRS:2)
B(-4,62,-2,OAK_STAIRS:2)
B(-5,62,-1,PLANKS:1)
B(-4,62,-1,OAK_STAIRS:7)
B(-4,63,-8,OAK_STAIRS:3)
B(-3,63,-8,SPRUCE_STAIRS:3)
B(-2,63,-8,SPRUCE_STAIRS:3)
B(-1,63,-8,SPRUCE_STAIRS:3)
B(-8,63,-3,WOODEN_SLAB:1)
B(-8,63,-2,WOODEN_SLAB:1)
B(-8,63,-1,SPRUCE_STAIRS:2)
B(-7,63,-1,SPRUCE_STAIRS:2)
B(-6,63,-1,SPRUCE_STAIRS:2)
B(-5,63,-1,SPRUCE_STAIRS:2)
B(-4,63,-1,OAK_STAIRS:2)
B(-8,64,-8,DARK_OAK_FENCE:0)
B(-8,65,-8,DARK_OAK_FENCE:0)
B(-8,66,-8,COBBLESTONE_WALL:0)
B(-8,67,-8,COBBLESTONE_WALL:0)
B(-8,68,-8,COBBLESTONE_WALL:0)

BR(-8,0,0,WestPort_2x6,NORTH,100)
