Author: Bo3 BulkEdit

Description: Converted Schematic - Modified by Bo3BulkEdit

Version: 3

SettingsMode: WriteDisable

IsOTGPlus: false
Tree: false
Frequency: 1
Rarity: 100
RotateRandomly: false
SpawnHeight: randomY
MaxBranchDepth: 20
ExcludedBiomes: All

MinHeight: 0
MaxHeight: 256

SourceBlocks: AIR
MaxPercentageOutsideSourceBlock: 100
OutsideSourceBlock: placeAnyway

B(-8,0,-7,LOG:1)
B(-4,0,-7,LOG:1)
B(-8,0,-3,LOG:1)
B(-4,0,-3,LOG:1)
B(-8,0,-1,LOG:1)
B(-4,0,-1,LOG:1)
B(-8,1,-8,LOG:9)
B(-4,1,-8,LOG:9)
B(-8,1,-7,LOG:1)
B(-4,1,-7,LOG:1)
B(-8,1,-3,LOG:1)
B(-4,1,-3,LOG:1)
B(-8,1,-2,LOG:9)
B(-4,1,-2,LOG:9)
B(-8,1,-1,LOG:1)
B(-7,1,-1,LOG:5)
B(-6,1,-1,LOG:5)
B(-5,1,-1,LOG:5)
B(-4,1,-1,LOG:1)
B(-3,1,-1,LOG:5)
B(-2,1,-1,LOG:5)
B(-1,1,-1,LOG:5)
B(-8,2,-7,LOG:1)
B(-4,2,-7,LOG:1)
B(-3,2,-7,LOG:5)
B(-2,2,-7,LOG:5)
B(-1,2,-7,LOG:5)
B(-8,2,-6,LOG:9)
B(-4,2,-6,LOG:9)
B(-8,2,-5,LOG:9)
B(-7,2,-5,LOG:5)
B(-6,2,-5,LOG:5)
B(-5,2,-5,LOG:5)
B(-4,2,-5,LOG:9)
B(-8,2,-4,LOG:9)
B(-4,2,-4,LOG:9)
B(-8,2,-3,LOG:1)
B(-4,2,-3,LOG:1)
B(-3,2,-3,LOG:5)
B(-2,2,-3,LOG:5)
B(-1,2,-3,LOG:5)
B(-8,2,-1,LOG:1)
B(-4,2,-1,LOG:1)
B(-8,3,-7,LOG:1)
B(-4,3,-7,LOG:1)
B(-8,3,-3,LOG:1)
B(-4,3,-3,LOG:1)
B(-8,3,-1,LOG:1)
B(-4,3,-1,LOG:1)
B(-8,4,-7,LOG:1)
B(-4,4,-7,LOG:1)
B(-8,4,-3,LOG:1)
B(-4,4,-3,LOG:1)
B(-8,4,-1,LOG:1)
B(-4,4,-1,LOG:1)
B(-8,5,-8,LOG:9)
B(-4,5,-8,LOG:9)
B(-8,5,-7,LOG:1)
B(-4,5,-7,LOG:1)
B(-8,5,-3,LOG:1)
B(-4,5,-3,LOG:1)
B(-8,5,-2,LOG:9)
B(-4,5,-2,LOG:9)
B(-8,5,-1,LOG:1)
B(-7,5,-1,LOG:5)
B(-6,5,-1,LOG:5)
B(-5,5,-1,LOG:5)
B(-4,5,-1,LOG:1)
B(-3,5,-1,LOG:5)
B(-2,5,-1,LOG:5)
B(-1,5,-1,LOG:5)
B(-8,6,-7,LOG:1)
B(-4,6,-7,LOG:1)
B(-3,6,-7,LOG:5)
B(-2,6,-7,LOG:5)
B(-1,6,-7,LOG:5)
B(-8,6,-6,LOG:9)
B(-4,6,-6,LOG:9)
B(-8,6,-5,LOG:9)
B(-7,6,-5,LOG:5)
B(-6,6,-5,LOG:5)
B(-5,6,-5,LOG:5)
B(-4,6,-5,LOG:9)
B(-8,6,-4,LOG:9)
B(-4,6,-4,LOG:9)
B(-8,6,-3,LOG:1)
B(-4,6,-3,LOG:1)
B(-3,6,-3,LOG:5)
B(-2,6,-3,LOG:5)
B(-1,6,-3,LOG:5)
B(-8,6,-1,LOG:1)
B(-4,6,-1,LOG:1)
B(-8,7,-7,LOG:1)
B(-4,7,-7,LOG:1)
B(-8,7,-3,LOG:1)
B(-4,7,-3,LOG:1)
B(-8,7,-1,LOG:1)
B(-4,7,-1,LOG:1)
B(-8,8,-7,LOG:1)
B(-4,8,-7,LOG:1)
B(-8,8,-3,LOG:1)
B(-4,8,-3,LOG:1)
B(-8,8,-1,LOG:1)
B(-4,8,-1,LOG:1)
B(-8,9,-8,LOG:9)
B(-4,9,-8,LOG:9)
B(-8,9,-7,LOG:1)
B(-4,9,-7,LOG:1)
B(-8,9,-3,LOG:1)
B(-4,9,-3,LOG:1)
B(-8,9,-2,LOG:9)
B(-4,9,-2,LOG:9)
B(-8,9,-1,LOG:1)
B(-7,9,-1,LOG:5)
B(-6,9,-1,LOG:5)
B(-5,9,-1,LOG:5)
B(-4,9,-1,LOG:1)
B(-3,9,-1,LOG:5)
B(-2,9,-1,LOG:5)
B(-1,9,-1,LOG:5)
B(-8,10,-7,LOG:1)
B(-4,10,-7,LOG:1)
B(-3,10,-7,LOG:5)
B(-2,10,-7,LOG:5)
B(-1,10,-7,LOG:5)
B(-8,10,-6,LOG:9)
B(-4,10,-6,LOG:9)
B(-8,10,-5,LOG:9)
B(-7,10,-5,LOG:5)
B(-6,10,-5,LOG:5)
B(-5,10,-5,LOG:5)
B(-4,10,-5,LOG:9)
B(-8,10,-4,LOG:9)
B(-4,10,-4,LOG:9)
B(-8,10,-3,LOG:1)
B(-4,10,-3,LOG:1)
B(-3,10,-3,LOG:5)
B(-2,10,-3,LOG:5)
B(-1,10,-3,LOG:5)
B(-8,10,-1,LOG:1)
B(-4,10,-1,LOG:1)
B(-8,11,-7,LOG:1)
B(-4,11,-7,LOG:1)
B(-8,11,-3,LOG:1)
B(-4,11,-3,LOG:1)
B(-8,11,-1,LOG:1)
B(-4,11,-1,LOG:1)
B(-8,12,-7,LOG:1)
B(-4,12,-7,LOG:1)
B(-8,12,-3,LOG:1)
B(-4,12,-3,LOG:1)
B(-8,12,-1,LOG:1)
B(-4,12,-1,LOG:1)
B(-8,13,-8,LOG:9)
B(-4,13,-8,LOG:9)
B(-8,13,-7,LOG:1)
B(-4,13,-7,LOG:1)
B(-8,13,-3,LOG:1)
B(-4,13,-3,LOG:1)
B(-8,13,-2,LOG:9)
B(-4,13,-2,LOG:9)
B(-8,13,-1,LOG:1)
B(-7,13,-1,LOG:5)
B(-6,13,-1,LOG:5)
B(-5,13,-1,LOG:5)
B(-4,13,-1,LOG:1)
B(-3,13,-1,LOG:5)
B(-2,13,-1,LOG:5)
B(-1,13,-1,LOG:5)
B(-8,14,-7,LOG:1)
B(-4,14,-7,LOG:1)
B(-3,14,-7,LOG:5)
B(-2,14,-7,LOG:5)
B(-1,14,-7,LOG:5)
B(-8,14,-6,LOG:9)
B(-4,14,-6,LOG:9)
B(-8,14,-5,LOG:9)
B(-7,14,-5,LOG:5)
B(-6,14,-5,LOG:5)
B(-5,14,-5,LOG:5)
B(-4,14,-5,LOG:9)
B(-8,14,-4,LOG:9)
B(-4,14,-4,LOG:9)
B(-8,14,-3,LOG:1)
B(-4,14,-3,LOG:1)
B(-3,14,-3,LOG:5)
B(-2,14,-3,LOG:5)
B(-1,14,-3,LOG:5)
B(-8,14,-1,LOG:1)
B(-4,14,-1,LOG:1)
B(-8,15,-7,LOG:1)
B(-4,15,-7,LOG:1)
B(-8,15,-3,LOG:1)
B(-4,15,-3,LOG:1)
B(-8,15,-1,LOG:1)
B(-4,15,-1,LOG:1)
B(-8,16,-7,LOG:1)
B(-4,16,-7,LOG:1)
B(-8,16,-3,LOG:1)
B(-4,16,-3,LOG:1)
B(-8,16,-1,LOG:1)
B(-4,16,-1,LOG:1)
B(-8,17,-8,LOG:9)
B(-4,17,-8,LOG:9)
B(-8,17,-7,LOG:1)
B(-4,17,-7,LOG:1)
B(-8,17,-3,LOG:1)
B(-4,17,-3,LOG:1)
B(-8,17,-2,LOG:9)
B(-4,17,-2,LOG:9)
B(-8,17,-1,LOG:1)
B(-7,17,-1,LOG:5)
B(-6,17,-1,LOG:5)
B(-5,17,-1,LOG:5)
B(-4,17,-1,LOG:1)
B(-3,17,-1,LOG:5)
B(-2,17,-1,LOG:5)
B(-1,17,-1,LOG:5)
B(-8,18,-7,LOG:1)
B(-4,18,-7,LOG:1)
B(-3,18,-7,LOG:5)
B(-2,18,-7,LOG:5)
B(-1,18,-7,LOG:5)
B(-8,18,-6,LOG:9)
B(-4,18,-6,LOG:9)
B(-8,18,-5,LOG:9)
B(-7,18,-5,LOG:5)
B(-6,18,-5,LOG:5)
B(-5,18,-5,LOG:5)
B(-4,18,-5,LOG:9)
B(-8,18,-4,LOG:9)
B(-4,18,-4,LOG:9)
B(-8,18,-3,LOG:1)
B(-4,18,-3,LOG:1)
B(-3,18,-3,LOG:5)
B(-2,18,-3,LOG:5)
B(-1,18,-3,LOG:5)
B(-8,18,-1,LOG:1)
B(-4,18,-1,LOG:1)
B(-8,19,-7,LOG:1)
B(-4,19,-7,LOG:1)
B(-8,19,-3,LOG:1)
B(-4,19,-3,LOG:1)
B(-8,19,-1,LOG:1)
B(-4,19,-1,LOG:1)
B(-8,20,-7,LOG:1)
B(-4,20,-7,LOG:1)
B(-8,20,-3,LOG:1)
B(-4,20,-3,LOG:1)
B(-8,20,-1,LOG:1)
B(-4,20,-1,LOG:1)
B(-8,21,-8,LOG:9)
B(-4,21,-8,LOG:9)
B(-8,21,-7,LOG:1)
B(-4,21,-7,LOG:1)
B(-8,21,-3,LOG:1)
B(-4,21,-3,LOG:1)
B(-8,21,-2,LOG:9)
B(-4,21,-2,LOG:9)
B(-8,21,-1,LOG:1)
B(-7,21,-1,LOG:5)
B(-6,21,-1,LOG:5)
B(-5,21,-1,LOG:5)
B(-4,21,-1,LOG:1)
B(-3,21,-1,LOG:5)
B(-2,21,-1,LOG:5)
B(-1,21,-1,LOG:5)
B(-8,22,-7,LOG:1)
B(-4,22,-7,LOG:1)
B(-3,22,-7,LOG:5)
B(-2,22,-7,LOG:5)
B(-1,22,-7,LOG:5)
B(-8,22,-6,LOG:9)
B(-4,22,-6,LOG:9)
B(-8,22,-5,LOG:9)
B(-7,22,-5,LOG:5)
B(-6,22,-5,LOG:5)
B(-5,22,-5,LOG:5)
B(-4,22,-5,LOG:9)
B(-8,22,-4,LOG:9)
B(-4,22,-4,LOG:9)
B(-8,22,-3,LOG:1)
B(-4,22,-3,LOG:1)
B(-3,22,-3,LOG:5)
B(-2,22,-3,LOG:5)
B(-1,22,-3,LOG:5)
B(-8,22,-1,LOG:1)
B(-4,22,-1,LOG:1)
B(-8,23,-7,LOG:1)
B(-4,23,-7,LOG:1)
B(-8,23,-3,LOG:1)
B(-4,23,-3,LOG:1)
B(-8,23,-1,LOG:1)
B(-4,23,-1,LOG:1)
B(-8,24,-7,LOG:1)
B(-4,24,-7,LOG:1)
B(-8,24,-3,LOG:1)
B(-4,24,-3,LOG:1)
B(-8,24,-1,LOG:1)
B(-4,24,-1,LOG:1)
B(-8,25,-8,LOG:9)
B(-4,25,-8,LOG:9)
B(-8,25,-7,LOG:1)
B(-4,25,-7,LOG:1)
B(-8,25,-3,LOG:1)
B(-4,25,-3,LOG:1)
B(-8,25,-2,LOG:9)
B(-4,25,-2,LOG:9)
B(-8,25,-1,LOG:1)
B(-7,25,-1,LOG:5)
B(-6,25,-1,LOG:5)
B(-5,25,-1,LOG:5)
B(-4,25,-1,LOG:1)
B(-3,25,-1,LOG:5)
B(-2,25,-1,LOG:5)
B(-1,25,-1,LOG:5)
B(-8,26,-7,LOG:1)
B(-4,26,-7,LOG:1)
B(-3,26,-7,LOG:5)
B(-2,26,-7,LOG:5)
B(-1,26,-7,LOG:5)
B(-8,26,-6,LOG:9)
B(-4,26,-6,LOG:9)
B(-8,26,-5,LOG:9)
B(-7,26,-5,LOG:5)
B(-6,26,-5,LOG:5)
B(-5,26,-5,LOG:5)
B(-4,26,-5,LOG:9)
B(-8,26,-4,LOG:9)
B(-4,26,-4,LOG:9)
B(-8,26,-3,LOG:1)
B(-4,26,-3,LOG:1)
B(-3,26,-3,LOG:5)
B(-2,26,-3,LOG:5)
B(-1,26,-3,LOG:5)
B(-8,26,-1,LOG:1)
B(-4,26,-1,LOG:1)
B(-8,27,-7,LOG:1)
B(-4,27,-7,LOG:1)
B(-8,27,-3,LOG:1)
B(-4,27,-3,LOG:1)
B(-8,27,-1,LOG:1)
B(-4,27,-1,LOG:1)
B(-8,28,-7,LOG:1)
B(-4,28,-7,LOG:1)
B(-8,28,-3,LOG:1)
B(-4,28,-3,LOG:1)
B(-8,28,-1,LOG:1)
B(-4,28,-1,LOG:1)
B(-8,29,-8,LOG:9)
B(-4,29,-8,LOG:9)
B(-8,29,-7,LOG:1)
B(-4,29,-7,LOG:1)
B(-8,29,-3,LOG:1)
B(-4,29,-3,LOG:1)
B(-8,29,-2,LOG:9)
B(-4,29,-2,LOG:9)
B(-8,29,-1,LOG:1)
B(-7,29,-1,LOG:5)
B(-6,29,-1,LOG:5)
B(-5,29,-1,LOG:5)
B(-4,29,-1,LOG:1)
B(-3,29,-1,LOG:5)
B(-2,29,-1,LOG:5)
B(-1,29,-1,LOG:5)
B(-8,30,-7,LOG:1)
B(-4,30,-7,LOG:1)
B(-3,30,-7,LOG:5)
B(-2,30,-7,LOG:5)
B(-1,30,-7,LOG:5)
B(-8,30,-6,LOG:9)
B(-4,30,-6,LOG:9)
B(-8,30,-5,LOG:9)
B(-7,30,-5,LOG:5)
B(-6,30,-5,LOG:5)
B(-5,30,-5,LOG:5)
B(-4,30,-5,LOG:9)
B(-8,30,-4,LOG:9)
B(-4,30,-4,LOG:9)
B(-8,30,-3,LOG:1)
B(-4,30,-3,LOG:1)
B(-3,30,-3,LOG:5)
B(-2,30,-3,LOG:5)
B(-1,30,-3,LOG:5)
B(-8,30,-1,LOG:1)
B(-4,30,-1,LOG:1)
B(-8,31,-7,LOG:1)
B(-4,31,-7,LOG:1)
B(-8,31,-3,LOG:1)
B(-4,31,-3,LOG:1)
B(-8,31,-1,LOG:1)
B(-4,31,-1,LOG:1)
B(-8,32,-7,LOG:1)
B(-4,32,-7,LOG:1)
B(-8,32,-3,LOG:1)
B(-4,32,-3,LOG:1)
B(-8,32,-1,LOG:1)
B(-4,32,-1,LOG:1)
B(-8,33,-8,LOG:9)
B(-4,33,-8,LOG:9)
B(-8,33,-7,LOG:1)
B(-4,33,-7,LOG:1)
B(-8,33,-3,LOG:1)
B(-4,33,-3,LOG:1)
B(-8,33,-2,LOG:9)
B(-4,33,-2,LOG:9)
B(-8,33,-1,LOG:1)
B(-7,33,-1,LOG:5)
B(-6,33,-1,LOG:5)
B(-5,33,-1,LOG:5)
B(-4,33,-1,LOG:1)
B(-3,33,-1,LOG:5)
B(-2,33,-1,LOG:5)
B(-1,33,-1,LOG:5)
B(-8,34,-7,LOG:1)
B(-4,34,-7,LOG:1)
B(-3,34,-7,LOG:5)
B(-2,34,-7,LOG:5)
B(-1,34,-7,LOG:5)
B(-8,34,-6,LOG:9)
B(-4,34,-6,LOG:9)
B(-8,34,-5,LOG:9)
B(-7,34,-5,LOG:5)
B(-6,34,-5,LOG:5)
B(-5,34,-5,LOG:5)
B(-4,34,-5,LOG:9)
B(-8,34,-4,LOG:9)
B(-4,34,-4,LOG:9)
B(-8,34,-3,LOG:1)
B(-4,34,-3,LOG:1)
B(-3,34,-3,LOG:5)
B(-2,34,-3,LOG:5)
B(-1,34,-3,LOG:5)
B(-8,34,-1,LOG:1)
B(-4,34,-1,LOG:1)
B(-8,35,-7,LOG:1)
B(-4,35,-7,LOG:1)
B(-8,35,-3,LOG:1)
B(-4,35,-3,LOG:1)
B(-8,35,-1,LOG:1)
B(-4,35,-1,LOG:1)
B(-8,36,-7,LOG:1)
B(-4,36,-7,LOG:1)
B(-8,36,-3,LOG:1)
B(-4,36,-3,LOG:1)
B(-8,36,-1,LOG:1)
B(-4,36,-1,LOG:1)
B(-8,37,-8,LOG:9)
B(-4,37,-8,LOG:9)
B(-8,37,-7,LOG:1)
B(-4,37,-7,LOG:1)
B(-8,37,-3,LOG:1)
B(-4,37,-3,LOG:1)
B(-8,37,-2,LOG:9)
B(-4,37,-2,LOG:9)
B(-8,37,-1,LOG:1)
B(-7,37,-1,LOG:5)
B(-6,37,-1,LOG:5)
B(-5,37,-1,LOG:5)
B(-4,37,-1,LOG:1)
B(-3,37,-1,LOG:5)
B(-2,37,-1,LOG:5)
B(-1,37,-1,LOG:5)
B(-8,38,-7,LOG:1)
B(-4,38,-7,LOG:1)
B(-3,38,-7,LOG:5)
B(-2,38,-7,LOG:5)
B(-1,38,-7,LOG:5)
B(-8,38,-6,LOG:9)
B(-4,38,-6,LOG:9)
B(-8,38,-5,LOG:9)
B(-7,38,-5,LOG:5)
B(-6,38,-5,LOG:5)
B(-5,38,-5,LOG:5)
B(-4,38,-5,LOG:9)
B(-8,38,-4,LOG:9)
B(-4,38,-4,LOG:9)
B(-8,38,-3,LOG:1)
B(-4,38,-3,LOG:1)
B(-3,38,-3,LOG:5)
B(-2,38,-3,LOG:5)
B(-1,38,-3,LOG:5)
B(-8,38,-1,LOG:1)
B(-4,38,-1,LOG:1)
B(-8,39,-7,LOG:1)
B(-4,39,-7,LOG:1)
B(-8,39,-3,LOG:1)
B(-4,39,-3,LOG:1)
B(-8,39,-1,LOG:1)
B(-4,39,-1,LOG:1)
B(-8,40,-7,LOG:1)
B(-4,40,-7,LOG:1)
B(-8,40,-3,LOG:1)
B(-4,40,-3,LOG:1)
B(-8,40,-1,LOG:1)
B(-4,40,-1,LOG:1)
B(-8,41,-8,LOG:9)
B(-4,41,-8,LOG:9)
B(-8,41,-7,LOG:1)
B(-4,41,-7,LOG:1)
B(-8,41,-3,LOG:1)
B(-4,41,-3,LOG:1)
B(-8,41,-2,LOG:9)
B(-4,41,-2,LOG:9)
B(-8,41,-1,LOG:1)
B(-7,41,-1,LOG:5)
B(-6,41,-1,LOG:5)
B(-5,41,-1,LOG:5)
B(-4,41,-1,LOG:1)
B(-3,41,-1,LOG:5)
B(-2,41,-1,LOG:5)
B(-1,41,-1,LOG:5)
B(-8,42,-7,LOG:1)
B(-4,42,-7,LOG:1)
B(-3,42,-7,LOG:5)
B(-2,42,-7,LOG:5)
B(-1,42,-7,LOG:5)
B(-8,42,-6,LOG:9)
B(-4,42,-6,LOG:9)
B(-8,42,-5,LOG:9)
B(-7,42,-5,LOG:5)
B(-6,42,-5,LOG:5)
B(-5,42,-5,LOG:5)
B(-4,42,-5,LOG:9)
B(-8,42,-4,LOG:9)
B(-4,42,-4,LOG:9)
B(-8,42,-3,LOG:1)
B(-4,42,-3,LOG:1)
B(-3,42,-3,LOG:5)
B(-2,42,-3,LOG:5)
B(-1,42,-3,LOG:5)
B(-8,42,-1,LOG:1)
B(-4,42,-1,LOG:1)
B(-8,43,-7,LOG:1)
B(-4,43,-7,LOG:1)
B(-8,43,-3,LOG:1)
B(-4,43,-3,LOG:1)
B(-8,43,-1,LOG:1)
B(-4,43,-1,LOG:1)
B(-8,44,-7,LOG:1)
B(-4,44,-7,LOG:1)
B(-8,44,-3,LOG:1)
B(-4,44,-3,LOG:1)
B(-8,44,-1,LOG:1)
B(-4,44,-1,LOG:1)
B(-8,45,-8,LOG:9)
B(-4,45,-8,LOG:9)
B(-8,45,-7,LOG:1)
B(-4,45,-7,LOG:1)
B(-8,45,-3,LOG:1)
B(-4,45,-3,LOG:1)
B(-8,45,-2,LOG:9)
B(-4,45,-2,LOG:9)
B(-8,45,-1,LOG:1)
B(-7,45,-1,LOG:5)
B(-6,45,-1,LOG:5)
B(-5,45,-1,LOG:5)
B(-4,45,-1,LOG:1)
B(-3,45,-1,LOG:5)
B(-2,45,-1,LOG:5)
B(-1,45,-1,LOG:5)
B(-8,46,-7,LOG:1)
B(-4,46,-7,LOG:1)
B(-3,46,-7,LOG:5)
B(-2,46,-7,LOG:5)
B(-1,46,-7,LOG:5)
B(-8,46,-6,LOG:9)
B(-4,46,-6,LOG:9)
B(-8,46,-5,LOG:9)
B(-7,46,-5,LOG:5)
B(-6,46,-5,LOG:5)
B(-5,46,-5,LOG:5)
B(-4,46,-5,LOG:9)
B(-8,46,-4,LOG:9)
B(-4,46,-4,LOG:9)
B(-8,46,-3,LOG:1)
B(-4,46,-3,LOG:1)
B(-3,46,-3,LOG:5)
B(-2,46,-3,LOG:5)
B(-1,46,-3,LOG:5)
B(-8,46,-1,LOG:1)
B(-4,46,-1,LOG:1)
B(-8,47,-7,LOG:1)
B(-4,47,-7,LOG:1)
B(-8,47,-3,LOG:1)
B(-4,47,-3,LOG:1)
B(-8,47,-1,LOG:1)
B(-4,47,-1,LOG:1)
B(-8,48,-7,LOG:1)
B(-4,48,-7,LOG:1)
B(-8,48,-3,LOG:1)
B(-4,48,-3,LOG:1)
B(-8,48,-1,LOG:1)
B(-4,48,-1,LOG:1)
B(-8,49,-7,LOG:1)
B(-4,49,-7,LOG:1)
B(-8,49,-3,LOG:1)
B(-4,49,-3,LOG:1)
B(-8,49,-1,LOG:1)
B(-4,49,-1,LOG:1)
B(-8,50,-8,WOODEN_BUTTON:4)
B(-4,50,-8,WOODEN_BUTTON:4)
B(-8,50,-7,LOG:1)
B(-7,50,-7,WOODEN_BUTTON:1)
B(-5,50,-7,WOODEN_BUTTON:2)
B(-4,50,-7,LOG:1)
B(-3,50,-7,WOODEN_BUTTON:1)
B(-1,50,-7,WOODEN_BUTTON:2)
B(-8,50,-6,WOODEN_BUTTON:3)
B(-4,50,-6,WOODEN_BUTTON:3)
B(-8,50,-4,WOODEN_BUTTON:4)
B(-4,50,-4,WOODEN_BUTTON:4)
B(-8,50,-3,LOG:1)
B(-7,50,-3,WOODEN_BUTTON:1)
B(-5,50,-3,WOODEN_BUTTON:2)
B(-4,50,-3,LOG:1)
B(-3,50,-3,WOODEN_BUTTON:1)
B(-1,50,-3,WOODEN_BUTTON:2)
B(-8,50,-2,WOODEN_BUTTON:3)
B(-4,50,-2,WOODEN_BUTTON:3)
B(-8,50,-1,LOG:1)
B(-4,50,-1,LOG:1)
B(-8,51,-8,LOG:9)
B(-4,51,-8,LOG:9)
B(-8,51,-7,LOG:1)
B(-7,51,-7,WOODEN_BUTTON:1)
B(-5,51,-7,WOODEN_BUTTON:2)
B(-4,51,-7,LOG:1)
B(-3,51,-7,WOODEN_BUTTON:1)
B(-1,51,-7,WOODEN_BUTTON:2)
B(-8,51,-6,WOODEN_BUTTON:3)
B(-4,51,-6,WOODEN_BUTTON:3)
B(-8,51,-4,WOODEN_BUTTON:4)
B(-4,51,-4,WOODEN_BUTTON:4)
B(-8,51,-3,LOG:1)
B(-7,51,-3,WOODEN_BUTTON:1)
B(-5,51,-3,WOODEN_BUTTON:2)
B(-4,51,-3,LOG:1)
B(-3,51,-3,WOODEN_BUTTON:1)
B(-1,51,-3,WOODEN_BUTTON:2)
B(-8,51,-2,LOG:9)
B(-4,51,-2,LOG:9)
B(-8,51,-1,STONE_BRICK_STAIRS:3)
B(-4,51,-1,STONE_BRICK_STAIRS:3)
B(-8,52,-8,STONE_BRICK_STAIRS:6)
B(-4,52,-8,STONE_BRICK_STAIRS:6)
B(-8,52,-7,LOG:1)
B(-7,52,-7,DARK_OAK_STAIRS:5)
B(-6,52,-7,WOODEN_SLAB:13)
B(-5,52,-7,DARK_OAK_STAIRS:4)
B(-4,52,-7,LOG:1)
B(-3,52,-7,DARK_OAK_STAIRS:5)
B(-2,52,-7,WOODEN_SLAB:13)
B(-1,52,-7,DARK_OAK_STAIRS:4)
B(-8,52,-3,LOG:1)
B(-7,52,-3,DARK_OAK_STAIRS:5)
B(-6,52,-3,WOODEN_SLAB:13)
B(-5,52,-3,DARK_OAK_STAIRS:4)
B(-4,52,-3,LOG:1)
B(-3,52,-3,DARK_OAK_STAIRS:5)
B(-2,52,-3,WOODEN_SLAB:13)
B(-1,52,-3,DARK_OAK_STAIRS:4)
B(-8,52,-2,STONE_BRICK_STAIRS:7)
B(-4,52,-2,STONE_BRICK_STAIRS:7)
B(-8,53,-8,STONE:6)
B(-7,53,-8,DARK_OAK_STAIRS:5)
B(-5,53,-8,DARK_OAK_STAIRS:4)
B(-4,53,-8,STONE:6)
B(-3,53,-8,DARK_OAK_STAIRS:5)
B(-1,53,-8,DARK_OAK_STAIRS:4)
B(-8,53,-7,LOG:1)
B(-7,53,-7,WOODEN_SLAB:13)
B(-6,53,-7,WOODEN_SLAB:13)
B(-5,53,-7,WOODEN_SLAB:13)
B(-4,53,-7,LOG:1)
B(-3,53,-7,WOODEN_SLAB:13)
B(-2,53,-7,WOODEN_SLAB:13)
B(-1,53,-7,WOODEN_SLAB:13)
B(-8,53,-6,LOG:9)
B(-7,53,-6,WOODEN_SLAB:0)
B(-6,53,-6,WOODEN_SLAB:0)
B(-5,53,-6,WOODEN_SLAB:0)
B(-4,53,-6,LOG:9)
B(-3,53,-6,WOODEN_SLAB:0)
B(-2,53,-6,WOODEN_SLAB:0)
B(-1,53,-6,WOODEN_SLAB:0)
B(-8,53,-5,LOG:9)
B(-7,53,-5,WOODEN_SLAB:8)
B(-6,53,-5,WOODEN_SLAB:8)
B(-5,53,-5,WOODEN_SLAB:8)
B(-4,53,-5,LOG:9)
B(-3,53,-5,WOODEN_SLAB:8)
B(-2,53,-5,WOODEN_SLAB:8)
B(-1,53,-5,WOODEN_SLAB:8)
B(-8,53,-4,LOG:9)
B(-7,53,-4,WOODEN_SLAB:0)
B(-6,53,-4,WOODEN_SLAB:0)
B(-5,53,-4,WOODEN_SLAB:0)
B(-4,53,-4,LOG:9)
B(-3,53,-4,WOODEN_SLAB:0)
B(-2,53,-4,WOODEN_SLAB:0)
B(-1,53,-4,WOODEN_SLAB:0)
B(-8,53,-3,LOG:1)
B(-7,53,-3,WOODEN_SLAB:13)
B(-6,53,-3,WOODEN_SLAB:13)
B(-5,53,-3,WOODEN_SLAB:13)
B(-4,53,-3,LOG:1)
B(-3,53,-3,WOODEN_SLAB:13)
B(-2,53,-3,WOODEN_SLAB:13)
B(-1,53,-3,WOODEN_SLAB:13)
B(-8,53,-2,STONE:6)
B(-7,53,-2,DARK_OAK_STAIRS:5)
B(-5,53,-2,DARK_OAK_STAIRS:4)
B(-4,53,-2,STONE:6)
B(-3,53,-2,DARK_OAK_STAIRS:5)
B(-1,53,-2,DARK_OAK_STAIRS:4)
B(-8,54,-8,STONE_BRICK_STAIRS:2)
B(-7,54,-8,LOG:5)
B(-6,54,-8,LOG:5)
B(-5,54,-8,LOG:5)
B(-4,54,-8,STONE_BRICK_STAIRS:2)
B(-3,54,-8,LOG:5)
B(-2,54,-8,LOG:5)
B(-1,54,-8,LOG:5)
B(-8,54,-7,STONE_SLAB:0)
B(-7,54,-7,STONE_SLAB:0)
B(-6,54,-7,STONE_SLAB:0)
B(-5,54,-7,STONE_SLAB:0)
B(-4,54,-7,STONE_SLAB:0)
B(-3,54,-7,STONE_SLAB:0)
B(-2,54,-7,STONE_SLAB:0)
B(-1,54,-7,STONE_SLAB:0)
B(-8,54,-6,STONE_SLAB:0)
B(-7,54,-6,STONE_SLAB:0)
B(-6,54,-6,STONE_SLAB:0)
B(-5,54,-6,STONE_SLAB:0)
B(-4,54,-6,STONE_SLAB:0)
B(-3,54,-6,STONE_SLAB:0)
B(-2,54,-6,STONE_SLAB:0)
B(-1,54,-6,STONE_SLAB:0)
B(-8,54,-5,STONE_SLAB:0)
B(-7,54,-5,STONE_SLAB:0)
B(-6,54,-5,STONE_SLAB:0)
B(-5,54,-5,STONE_SLAB:0)
B(-4,54,-5,STONE_SLAB:0)
B(-3,54,-5,STONE_SLAB:0)
B(-2,54,-5,STONE_SLAB:0)
B(-1,54,-5,STONE_SLAB:0)
B(-8,54,-4,STONE_SLAB:0)
B(-7,54,-4,STONE_SLAB:0)
B(-6,54,-4,STONE_SLAB:0)
B(-5,54,-4,STONE_SLAB:0)
B(-4,54,-4,STONE_SLAB:0)
B(-3,54,-4,STONE_SLAB:0)
B(-2,54,-4,STONE_SLAB:0)
B(-1,54,-4,STONE_SLAB:0)
B(-8,54,-3,STONE_SLAB:0)
B(-7,54,-3,STONE_SLAB:0)
B(-6,54,-3,STONE_SLAB:0)
B(-5,54,-3,STONE_SLAB:0)
B(-4,54,-3,STONE_SLAB:0)
B(-3,54,-3,STONE_SLAB:0)
B(-2,54,-3,STONE_SLAB:0)
B(-1,54,-3,STONE_SLAB:0)
B(-8,54,-2,STONE_BRICK_STAIRS:3)
B(-7,54,-2,LOG:5)
B(-6,54,-2,LOG:5)
B(-5,54,-2,LOG:5)
B(-4,54,-2,STONE_BRICK_STAIRS:3)
B(-3,54,-2,LOG:5)
B(-2,54,-2,LOG:5)
B(-1,54,-2,LOG:5)
B(-7,54,-1,WOODEN_BUTTON:3)
B(-6,54,-1,WOODEN_BUTTON:3)
B(-5,54,-1,WOODEN_BUTTON:3)
B(-3,54,-1,WOODEN_BUTTON:3)
B(-2,54,-1,WOODEN_BUTTON:3)
B(-1,54,-1,WOODEN_BUTTON:3)
B(-8,55,-8,STONE_SLAB:0)
B(-7,55,-8,SPRUCE_FENCE:0)
B(-6,55,-8,SPRUCE_FENCE:0)
B(-5,55,-8,SPRUCE_FENCE:0)
B(-4,55,-8,STONE_SLAB:0)
B(-3,55,-8,SPRUCE_FENCE:0)
B(-2,55,-8,SPRUCE_FENCE:0)
B(-1,55,-8,SPRUCE_FENCE:0)
B(-8,55,-2,STONE_SLAB:0)
B(-7,55,-2,SPRUCE_FENCE:0)
B(-6,55,-2,SPRUCE_FENCE:0)
B(-5,55,-2,SPRUCE_FENCE:0)
B(-4,55,-2,STONE_SLAB:0)
B(-3,55,-2,SPRUCE_FENCE:0)
B(-2,55,-2,SPRUCE_FENCE:0)
B(-1,55,-2,SPRUCE_FENCE:0)
B(-2,56,-8,SPRUCE_FENCE:0)
B(-2,56,-2,SPRUCE_FENCE:0)
B(-2,57,-8,SPRUCE_FENCE:0)
B(-2,57,-7,SPRUCE_FENCE:0)
B(-2,57,-3,SPRUCE_FENCE:0)
B(-2,57,-2,SPRUCE_FENCE:0)
B(-2,58,-7,TORCH:5)
B(-2,58,-3,TORCH:5)

BR(8,0,0,WestPort_14x8,NORTH,100)
