Author: Bo3 BulkEdit

Description: Converted Schematic - Modified by Bo3BulkEdit

Version: 3

SettingsMode: WriteDisable

IsOTGPlus: false
Tree: false
Frequency: 1
Rarity: 100
RotateRandomly: false
SpawnHeight: randomY
MaxBranchDepth: 20
ExcludedBiomes: All

MinHeight: 0
MaxHeight: 256

SourceBlocks: AIR
MaxPercentageOutsideSourceBlock: 100
OutsideSourceBlock: placeAnyway

B(-8,0,-7,LOG:1)
B(-4,0,-7,LOG:1)
B(-8,0,-3,LOG:1)
B(-4,0,-3,LOG:1)
B(-8,1,-8,LOG:9)
B(-8,1,-7,LOG:1)
B(-4,1,-7,LOG:1)
B(-3,1,-7,LOG:5)
B(-2,1,-7,LOG:5)
B(-1,1,-7,LOG:5)
B(-8,1,-3,LOG:1)
B(-4,1,-3,LOG:1)
B(-6,2,-8,LOG:9)
B(-4,2,-8,LOG:9)
B(-8,2,-7,LOG:1)
B(-6,2,-7,LOG:9)
B(-4,2,-7,LOG:1)
B(-8,2,-6,LOG:9)
B(-6,2,-6,LOG:9)
B(-8,2,-5,LOG:9)
B(-6,2,-5,LOG:9)
B(-8,2,-4,LOG:9)
B(-6,2,-4,LOG:9)
B(-8,2,-3,LOG:1)
B(-7,2,-3,LOG:5)
B(-6,2,-3,LOG:5)
B(-5,2,-3,LOG:5)
B(-4,2,-3,LOG:1)
B(-3,2,-3,LOG:5)
B(-2,2,-3,LOG:5)
B(-1,2,-3,LOG:5)
B(-2,2,-2,LOG:9)
B(-2,2,-1,LOG:9)
B(-8,3,-7,LOG:1)
B(-4,3,-7,LOG:1)
B(-8,3,-3,LOG:1)
B(-4,3,-3,LOG:1)
B(-8,4,-7,LOG:1)
B(-4,4,-7,LOG:1)
B(-8,4,-3,LOG:1)
B(-4,4,-3,LOG:1)
B(-8,5,-8,LOG:9)
B(-8,5,-7,LOG:1)
B(-4,5,-7,LOG:1)
B(-3,5,-7,LOG:5)
B(-2,5,-7,LOG:5)
B(-1,5,-7,LOG:5)
B(-8,5,-3,LOG:1)
B(-4,5,-3,LOG:1)
B(-6,6,-8,LOG:9)
B(-4,6,-8,LOG:9)
B(-8,6,-7,LOG:1)
B(-6,6,-7,LOG:9)
B(-4,6,-7,LOG:1)
B(-8,6,-6,LOG:9)
B(-6,6,-6,LOG:9)
B(-8,6,-5,LOG:9)
B(-6,6,-5,LOG:9)
B(-8,6,-4,LOG:9)
B(-6,6,-4,LOG:9)
B(-8,6,-3,LOG:1)
B(-7,6,-3,LOG:5)
B(-6,6,-3,LOG:5)
B(-5,6,-3,LOG:5)
B(-4,6,-3,LOG:1)
B(-3,6,-3,LOG:5)
B(-2,6,-3,LOG:5)
B(-1,6,-3,LOG:5)
B(-2,6,-2,LOG:9)
B(-2,6,-1,LOG:9)
B(-8,7,-7,LOG:1)
B(-4,7,-7,LOG:1)
B(-8,7,-3,LOG:1)
B(-4,7,-3,LOG:1)
B(-8,8,-7,LOG:1)
B(-4,8,-7,LOG:1)
B(-8,8,-3,LOG:1)
B(-4,8,-3,LOG:1)
B(-8,9,-8,LOG:9)
B(-8,9,-7,LOG:1)
B(-4,9,-7,LOG:1)
B(-3,9,-7,LOG:5)
B(-2,9,-7,LOG:5)
B(-1,9,-7,LOG:5)
B(-8,9,-3,LOG:1)
B(-4,9,-3,LOG:1)
B(-6,10,-8,LOG:9)
B(-4,10,-8,LOG:9)
B(-8,10,-7,LOG:1)
B(-6,10,-7,LOG:9)
B(-4,10,-7,LOG:1)
B(-8,10,-6,LOG:9)
B(-6,10,-6,LOG:9)
B(-8,10,-5,LOG:9)
B(-6,10,-5,LOG:9)
B(-8,10,-4,LOG:9)
B(-6,10,-4,LOG:9)
B(-8,10,-3,LOG:1)
B(-7,10,-3,LOG:5)
B(-6,10,-3,LOG:5)
B(-5,10,-3,LOG:5)
B(-4,10,-3,LOG:1)
B(-3,10,-3,LOG:5)
B(-2,10,-3,LOG:5)
B(-1,10,-3,LOG:5)
B(-2,10,-2,LOG:9)
B(-2,10,-1,LOG:9)
B(-8,11,-7,LOG:1)
B(-4,11,-7,LOG:1)
B(-8,11,-3,LOG:1)
B(-4,11,-3,LOG:1)
B(-8,12,-7,LOG:1)
B(-4,12,-7,LOG:1)
B(-8,12,-3,LOG:1)
B(-4,12,-3,LOG:1)
B(-8,13,-8,LOG:9)
B(-8,13,-7,LOG:1)
B(-4,13,-7,LOG:1)
B(-3,13,-7,LOG:5)
B(-2,13,-7,LOG:5)
B(-1,13,-7,LOG:5)
B(-8,13,-3,LOG:1)
B(-4,13,-3,LOG:1)
B(-6,14,-8,LOG:9)
B(-4,14,-8,LOG:9)
B(-8,14,-7,LOG:1)
B(-6,14,-7,LOG:9)
B(-4,14,-7,LOG:1)
B(-8,14,-6,LOG:9)
B(-6,14,-6,LOG:9)
B(-8,14,-5,LOG:9)
B(-6,14,-5,LOG:9)
B(-8,14,-4,LOG:9)
B(-6,14,-4,LOG:9)
B(-8,14,-3,LOG:1)
B(-7,14,-3,LOG:5)
B(-6,14,-3,LOG:5)
B(-5,14,-3,LOG:5)
B(-4,14,-3,LOG:1)
B(-3,14,-3,LOG:5)
B(-2,14,-3,LOG:5)
B(-1,14,-3,LOG:5)
B(-2,14,-2,LOG:9)
B(-2,14,-1,LOG:9)
B(-8,15,-7,LOG:1)
B(-4,15,-7,LOG:1)
B(-8,15,-3,LOG:1)
B(-4,15,-3,LOG:1)
B(-8,16,-7,LOG:1)
B(-4,16,-7,LOG:1)
B(-8,16,-3,LOG:1)
B(-4,16,-3,LOG:1)
B(-8,17,-8,LOG:9)
B(-8,17,-7,LOG:1)
B(-4,17,-7,LOG:1)
B(-3,17,-7,LOG:5)
B(-2,17,-7,LOG:5)
B(-1,17,-7,LOG:5)
B(-8,17,-3,LOG:1)
B(-4,17,-3,LOG:1)
B(-6,18,-8,LOG:9)
B(-4,18,-8,LOG:9)
B(-8,18,-7,LOG:1)
B(-6,18,-7,LOG:9)
B(-4,18,-7,LOG:1)
B(-8,18,-6,LOG:9)
B(-6,18,-6,LOG:9)
B(-8,18,-5,LOG:9)
B(-6,18,-5,LOG:9)
B(-8,18,-4,LOG:9)
B(-6,18,-4,LOG:9)
B(-8,18,-3,LOG:1)
B(-7,18,-3,LOG:5)
B(-6,18,-3,LOG:5)
B(-5,18,-3,LOG:5)
B(-4,18,-3,LOG:1)
B(-3,18,-3,LOG:5)
B(-2,18,-3,LOG:5)
B(-1,18,-3,LOG:5)
B(-2,18,-2,LOG:9)
B(-2,18,-1,LOG:9)
B(-8,19,-7,LOG:1)
B(-4,19,-7,LOG:1)
B(-8,19,-3,LOG:1)
B(-4,19,-3,LOG:1)
B(-8,20,-7,LOG:1)
B(-4,20,-7,LOG:1)
B(-8,20,-3,LOG:1)
B(-4,20,-3,LOG:1)
B(-8,21,-8,LOG:9)
B(-8,21,-7,LOG:1)
B(-4,21,-7,LOG:1)
B(-3,21,-7,LOG:5)
B(-2,21,-7,LOG:5)
B(-1,21,-7,LOG:5)
B(-8,21,-3,LOG:1)
B(-4,21,-3,LOG:1)
B(-6,22,-8,LOG:9)
B(-4,22,-8,LOG:9)
B(-8,22,-7,LOG:1)
B(-6,22,-7,LOG:9)
B(-4,22,-7,LOG:1)
B(-8,22,-6,LOG:9)
B(-6,22,-6,LOG:9)
B(-8,22,-5,LOG:9)
B(-6,22,-5,LOG:9)
B(-8,22,-4,LOG:9)
B(-6,22,-4,LOG:9)
B(-8,22,-3,LOG:1)
B(-7,22,-3,LOG:5)
B(-6,22,-3,LOG:5)
B(-5,22,-3,LOG:5)
B(-4,22,-3,LOG:1)
B(-3,22,-3,LOG:5)
B(-2,22,-3,LOG:5)
B(-1,22,-3,LOG:5)
B(-2,22,-2,LOG:9)
B(-2,22,-1,LOG:9)
B(-8,23,-7,LOG:1)
B(-4,23,-7,LOG:1)
B(-8,23,-3,LOG:1)
B(-4,23,-3,LOG:1)
B(-8,24,-7,LOG:1)
B(-4,24,-7,LOG:1)
B(-8,24,-3,LOG:1)
B(-4,24,-3,LOG:1)
B(-8,25,-8,LOG:9)
B(-8,25,-7,LOG:1)
B(-4,25,-7,LOG:1)
B(-3,25,-7,LOG:5)
B(-2,25,-7,LOG:5)
B(-1,25,-7,LOG:5)
B(-8,25,-3,LOG:1)
B(-4,25,-3,LOG:1)
B(-6,26,-8,LOG:9)
B(-4,26,-8,LOG:9)
B(-8,26,-7,LOG:1)
B(-6,26,-7,LOG:9)
B(-4,26,-7,LOG:1)
B(-8,26,-6,LOG:9)
B(-6,26,-6,LOG:9)
B(-8,26,-5,LOG:9)
B(-6,26,-5,LOG:9)
B(-8,26,-4,LOG:9)
B(-6,26,-4,LOG:9)
B(-8,26,-3,LOG:1)
B(-7,26,-3,LOG:5)
B(-6,26,-3,LOG:5)
B(-5,26,-3,LOG:5)
B(-4,26,-3,LOG:1)
B(-3,26,-3,LOG:5)
B(-2,26,-3,LOG:5)
B(-1,26,-3,LOG:5)
B(-2,26,-2,LOG:9)
B(-2,26,-1,LOG:9)
B(-8,27,-7,LOG:1)
B(-4,27,-7,LOG:1)
B(-8,27,-3,LOG:1)
B(-4,27,-3,LOG:1)
B(-8,28,-7,LOG:1)
B(-4,28,-7,LOG:1)
B(-8,28,-3,LOG:1)
B(-4,28,-3,LOG:1)
B(-8,29,-8,LOG:9)
B(-8,29,-7,LOG:1)
B(-4,29,-7,LOG:1)
B(-3,29,-7,LOG:5)
B(-2,29,-7,LOG:5)
B(-1,29,-7,LOG:5)
B(-8,29,-3,LOG:1)
B(-4,29,-3,LOG:1)
B(-6,30,-8,LOG:9)
B(-4,30,-8,LOG:9)
B(-8,30,-7,LOG:1)
B(-6,30,-7,LOG:9)
B(-4,30,-7,LOG:1)
B(-8,30,-6,LOG:9)
B(-6,30,-6,LOG:9)
B(-8,30,-5,LOG:9)
B(-6,30,-5,LOG:9)
B(-8,30,-4,LOG:9)
B(-6,30,-4,LOG:9)
B(-8,30,-3,LOG:1)
B(-7,30,-3,LOG:5)
B(-6,30,-3,LOG:5)
B(-5,30,-3,LOG:5)
B(-4,30,-3,LOG:1)
B(-3,30,-3,LOG:5)
B(-2,30,-3,LOG:5)
B(-1,30,-3,LOG:5)
B(-2,30,-2,LOG:9)
B(-2,30,-1,LOG:9)
B(-8,31,-7,LOG:1)
B(-4,31,-7,LOG:1)
B(-8,31,-3,LOG:1)
B(-4,31,-3,LOG:1)
B(-8,32,-7,LOG:1)
B(-4,32,-7,LOG:1)
B(-8,32,-3,LOG:1)
B(-4,32,-3,LOG:1)
B(-8,33,-8,LOG:9)
B(-8,33,-7,LOG:1)
B(-4,33,-7,LOG:1)
B(-3,33,-7,LOG:5)
B(-2,33,-7,LOG:5)
B(-1,33,-7,LOG:5)
B(-8,33,-3,LOG:1)
B(-4,33,-3,LOG:1)
B(-6,34,-8,LOG:9)
B(-4,34,-8,LOG:9)
B(-8,34,-7,LOG:1)
B(-6,34,-7,LOG:9)
B(-4,34,-7,LOG:1)
B(-8,34,-6,LOG:9)
B(-6,34,-6,LOG:9)
B(-8,34,-5,LOG:9)
B(-6,34,-5,LOG:9)
B(-8,34,-4,LOG:9)
B(-6,34,-4,LOG:9)
B(-8,34,-3,LOG:1)
B(-7,34,-3,LOG:5)
B(-6,34,-3,LOG:5)
B(-5,34,-3,LOG:5)
B(-4,34,-3,LOG:1)
B(-3,34,-3,LOG:5)
B(-2,34,-3,LOG:5)
B(-1,34,-3,LOG:5)
B(-2,34,-2,LOG:9)
B(-2,34,-1,LOG:9)
B(-8,35,-7,LOG:1)
B(-4,35,-7,LOG:1)
B(-8,35,-3,LOG:1)
B(-4,35,-3,LOG:1)
B(-8,36,-7,LOG:1)
B(-4,36,-7,LOG:1)
B(-8,36,-3,LOG:1)
B(-4,36,-3,LOG:1)
B(-8,37,-8,LOG:9)
B(-8,37,-7,LOG:1)
B(-4,37,-7,LOG:1)
B(-3,37,-7,LOG:5)
B(-2,37,-7,LOG:5)
B(-1,37,-7,LOG:5)
B(-8,37,-3,LOG:1)
B(-4,37,-3,LOG:1)
B(-6,38,-8,LOG:9)
B(-4,38,-8,LOG:9)
B(-8,38,-7,LOG:1)
B(-6,38,-7,LOG:9)
B(-4,38,-7,LOG:1)
B(-8,38,-6,LOG:9)
B(-6,38,-6,LOG:9)
B(-8,38,-5,LOG:9)
B(-6,38,-5,LOG:9)
B(-8,38,-4,LOG:9)
B(-6,38,-4,LOG:9)
B(-8,38,-3,LOG:1)
B(-7,38,-3,LOG:5)
B(-6,38,-3,LOG:5)
B(-5,38,-3,LOG:5)
B(-4,38,-3,LOG:1)
B(-3,38,-3,LOG:5)
B(-2,38,-3,LOG:5)
B(-1,38,-3,LOG:5)
B(-2,38,-2,LOG:9)
B(-2,38,-1,LOG:9)
B(-8,39,-7,LOG:1)
B(-4,39,-7,LOG:1)
B(-8,39,-3,LOG:1)
B(-4,39,-3,LOG:1)
B(-8,40,-7,LOG:1)
B(-4,40,-7,LOG:1)
B(-8,40,-3,LOG:1)
B(-4,40,-3,LOG:1)
B(-8,41,-8,LOG:9)
B(-8,41,-7,LOG:1)
B(-4,41,-7,LOG:1)
B(-3,41,-7,LOG:5)
B(-2,41,-7,LOG:5)
B(-1,41,-7,LOG:5)
B(-8,41,-3,LOG:1)
B(-4,41,-3,LOG:1)
B(-6,42,-8,LOG:9)
B(-4,42,-8,LOG:9)
B(-8,42,-7,LOG:1)
B(-6,42,-7,LOG:9)
B(-4,42,-7,LOG:1)
B(-8,42,-6,LOG:9)
B(-6,42,-6,LOG:9)
B(-8,42,-5,LOG:9)
B(-6,42,-5,LOG:9)
B(-8,42,-4,LOG:9)
B(-6,42,-4,LOG:9)
B(-8,42,-3,LOG:1)
B(-7,42,-3,LOG:5)
B(-6,42,-3,LOG:5)
B(-5,42,-3,LOG:5)
B(-4,42,-3,LOG:1)
B(-3,42,-3,LOG:5)
B(-2,42,-3,LOG:5)
B(-1,42,-3,LOG:5)
B(-2,42,-2,LOG:9)
B(-2,42,-1,LOG:9)
B(-8,43,-7,LOG:1)
B(-4,43,-7,LOG:1)
B(-8,43,-3,LOG:1)
B(-4,43,-3,LOG:1)
B(-8,44,-7,LOG:1)
B(-4,44,-7,LOG:1)
B(-8,44,-3,LOG:1)
B(-4,44,-3,LOG:1)
B(-8,45,-8,LOG:9)
B(-8,45,-7,LOG:1)
B(-4,45,-7,LOG:1)
B(-3,45,-7,LOG:5)
B(-2,45,-7,LOG:5)
B(-1,45,-7,LOG:5)
B(-8,45,-3,LOG:1)
B(-4,45,-3,LOG:1)
B(-6,46,-8,LOG:9)
B(-4,46,-8,LOG:9)
B(-8,46,-7,LOG:1)
B(-6,46,-7,LOG:9)
B(-4,46,-7,LOG:1)
B(-8,46,-6,LOG:9)
B(-6,46,-6,LOG:9)
B(-8,46,-5,LOG:9)
B(-6,46,-5,LOG:9)
B(-8,46,-4,LOG:9)
B(-6,46,-4,LOG:9)
B(-8,46,-3,LOG:1)
B(-7,46,-3,LOG:5)
B(-6,46,-3,LOG:5)
B(-5,46,-3,LOG:5)
B(-4,46,-3,LOG:1)
B(-3,46,-3,LOG:5)
B(-2,46,-3,LOG:5)
B(-1,46,-3,LOG:5)
B(-2,46,-2,LOG:9)
B(-2,46,-1,LOG:9)
B(-8,47,-7,LOG:1)
B(-4,47,-7,LOG:1)
B(-8,47,-3,LOG:1)
B(-4,47,-3,LOG:1)
B(-8,48,-7,LOG:1)
B(-4,48,-7,LOG:1)
B(-8,48,-3,LOG:1)
B(-4,48,-3,LOG:1)
B(-8,49,-7,LOG:1)
B(-4,49,-7,LOG:1)
B(-8,49,-3,LOG:1)
B(-4,49,-3,LOG:1)
B(-8,50,-7,LOG:1)
B(-4,50,-7,LOG:1)
B(-8,50,-3,LOG:1)
B(-4,50,-3,LOG:1)
B(-8,51,-7,LOG:1)
B(-4,51,-7,LOG:1)
B(-4,51,-4,SPRUCE_STAIRS:6)
B(-3,51,-4,WOODEN_SLAB:8)
B(-2,51,-4,WOODEN_SLAB:8)
B(-1,51,-4,WOODEN_SLAB:8)
B(-8,51,-3,LOG:1)
B(-4,51,-3,LOG:1)
B(-3,51,-3,LOG:5)
B(-2,51,-3,LOG:5)
B(-1,51,-3,LOG:5)
B(-3,51,-2,WOODEN_SLAB:8)
B(-2,51,-2,WOODEN_SLAB:8)
B(-1,51,-2,WOODEN_SLAB:8)
B(-3,51,-1,WOODEN_SLAB:8)
B(-2,51,-1,WOODEN_SLAB:8)
B(-1,51,-1,WOODEN_SLAB:8)
B(-8,52,-8,LOG:9)
B(-7,52,-8,WOODEN_SLAB:8)
B(-6,52,-8,WOODEN_SLAB:8)
B(-5,52,-8,WOODEN_SLAB:8)
B(-4,52,-8,WOODEN_SLAB:8)
B(-3,52,-8,WOODEN_SLAB:8)
B(-2,52,-8,WOODEN_SLAB:8)
B(-1,52,-8,WOODEN_SLAB:8)
B(-8,52,-7,LOG:1)
B(-7,52,-7,WOODEN_SLAB:8)
B(-6,52,-7,WOODEN_SLAB:8)
B(-5,52,-7,WOODEN_SLAB:8)
B(-4,52,-7,LOG:1)
B(-3,52,-7,LOG:5)
B(-2,52,-7,LOG:5)
B(-1,52,-7,LOG:5)
B(-8,52,-6,LOG:9)
B(-7,52,-6,WOODEN_SLAB:8)
B(-6,52,-6,WOODEN_SLAB:8)
B(-5,52,-6,WOODEN_SLAB:8)
B(-4,52,-6,LOG:9)
B(-8,52,-5,LOG:9)
B(-7,52,-5,WOODEN_SLAB:8)
B(-6,52,-5,WOODEN_SLAB:8)
B(-5,52,-5,WOODEN_SLAB:8)
B(-4,52,-5,LOG:9)
B(-8,52,-4,LOG:9)
B(-7,52,-4,WOODEN_SLAB:8)
B(-6,52,-4,WOODEN_SLAB:8)
B(-5,52,-4,WOODEN_SLAB:8)
B(-4,52,-4,LOG:9)
B(-8,52,-3,LOG:1)
B(-7,52,-3,WOODEN_SLAB:8)
B(-6,52,-3,WOODEN_SLAB:8)
B(-5,52,-3,WOODEN_SLAB:8)
B(-4,52,-3,LOG:1)
B(-3,52,-3,SPRUCE_FENCE:0)
B(-2,52,-3,SPRUCE_FENCE:0)
B(-8,52,-2,LOG:9)
B(-7,52,-2,WOODEN_SLAB:8)
B(-6,52,-2,WOODEN_SLAB:8)
B(-5,52,-2,WOODEN_SLAB:8)
B(-4,52,-2,LOG:9)
B(-8,52,-1,LOG:9)
B(-7,52,-1,WOODEN_SLAB:8)
B(-6,52,-1,WOODEN_SLAB:8)
B(-5,52,-1,WOODEN_SLAB:8)
B(-4,52,-1,LOG:9)
B(-3,52,-1,SPRUCE_STAIRS:1)
B(-8,53,-8,COBBLESTONE:0)
B(-7,53,-8,CARPET:1)
RB(-5,53,-8,AIR,25,CHEST:4,../NBT/StructureLoot/JunkChest_1.nbt,15,CHEST:4,../NBT/StructureLoot/JunkChest_2.nbt,15,CHEST:4,../NBT/StructureLoot/JunkChest_3.nbt,15,CHEST:4,../NBT/StructureLoot/JunkChest_4.nbt,15,CHEST:4,../NBT/StructureLoot/JunkChest_5.nbt,15,CHEST:4,../NBT/StructureLoot/Common1.nbt,15,CHEST:4,../NBT/StructureLoot/Common2.nbt,15,CHEST:4,../NBT/StructureLoot/Common3.nbt,15,CHEST:4,../NBT/StructureLoot/Common4.nbt,15,CHEST:4,../NBT/StructureLoot/Common5.nbt,15,CHEST:4,../NBT/StructureLoot/Common6.nbt,15,CHEST:4,../NBT/StructureLoot/Common7.nbt,15,CHEST:4,../NBT/StructureLoot/Common8.nbt,15,CHEST:4,../NBT/StructureLoot/Common9.nbt,15,CHEST:4,../NBT/StructureLoot/Common10.nbt,15,CHEST:4,../NBT/StructureLoot/Common11.nbt,15,CHEST:4,../NBT/StructureLoot/Common12.nbt,15,CHEST:4,../NBT/StructureLoot/Common13.nbt,15,CHEST:4,../NBT/StructureLoot/Common14.nbt,15,CHEST:4,../NBT/StructureLoot/Common15.nbt,100)
B(-4,53,-8,PLANKS:1)
B(-3,53,-8,BOOKSHELF:0)
B(-2,53,-8,CARPET:1)
B(-1,53,-8,TRAPDOOR:6)
B(-8,53,-7,LOG:1)
B(-7,53,-7,PLANKS:1)
B(-6,53,-7,SPRUCE_DOOR:1)
B(-5,53,-7,PLANKS:1)
B(-4,53,-7,LOG:1)
B(-3,53,-7,COBBLESTONE:0)
B(-2,53,-7,COBBLESTONE:0)
B(-1,53,-7,COBBLESTONE:0)
B(-8,53,-6,COBBLESTONE:0)
B(-7,53,-6,BED:10)
B(-6,53,-6,CARPET:7)
B(-5,53,-6,BOOKSHELF:0)
B(-4,53,-6,COBBLESTONE:0)
B(-8,53,-5,COBBLESTONE:0)
B(-7,53,-5,BED:2)
B(-5,53,-5,BIRCH_STAIRS:0)
B(-4,53,-5,COBBLESTONE:0)
B(-8,53,-4,COBBLESTONE:0)
B(-7,53,-4,CARPET:7)
B(-6,53,-4,CARPET:7)
B(-5,53,-4,BIRCH_STAIRS:0)
B(-4,53,-4,COBBLESTONE:0)
B(-8,53,-3,COBBLESTONE:0)
RB(-7,53,-3,AIR,25,CHEST:5,../NBT/StructureLoot/JunkChest_1.nbt,15,CHEST:5,../NBT/StructureLoot/JunkChest_2.nbt,15,CHEST:5,../NBT/StructureLoot/JunkChest_3.nbt,15,CHEST:5,../NBT/StructureLoot/JunkChest_4.nbt,15,CHEST:5,../NBT/StructureLoot/JunkChest_5.nbt,15,CHEST:5,../NBT/StructureLoot/Common1.nbt,15,CHEST:5,../NBT/StructureLoot/Common2.nbt,15,CHEST:5,../NBT/StructureLoot/Common3.nbt,15,CHEST:5,../NBT/StructureLoot/Common4.nbt,15,CHEST:5,../NBT/StructureLoot/Common5.nbt,15,CHEST:5,../NBT/StructureLoot/Common6.nbt,15,CHEST:5,../NBT/StructureLoot/Common7.nbt,15,CHEST:5,../NBT/StructureLoot/Common8.nbt,15,CHEST:5,../NBT/StructureLoot/Common9.nbt,15,CHEST:5,../NBT/StructureLoot/Common10.nbt,15,CHEST:5,../NBT/StructureLoot/Common11.nbt,15,CHEST:5,../NBT/StructureLoot/Common12.nbt,15,CHEST:5,../NBT/StructureLoot/Common13.nbt,15,CHEST:5,../NBT/StructureLoot/Common14.nbt,15,CHEST:5,../NBT/StructureLoot/Common15.nbt,100)
B(-6,53,-3,CARPET:7)
B(-5,53,-3,BIRCH_STAIRS:0)
B(-4,53,-3,LOG:1)
B(-8,53,-2,COBBLESTONE:0)
RB(-7,53,-2,AIR,25,CHEST:5,../NBT/StructureLoot/JunkChest_1.nbt,15,CHEST:5,../NBT/StructureLoot/JunkChest_2.nbt,15,CHEST:5,../NBT/StructureLoot/JunkChest_3.nbt,15,CHEST:5,../NBT/StructureLoot/JunkChest_4.nbt,15,CHEST:5,../NBT/StructureLoot/JunkChest_5.nbt,15,CHEST:5,../NBT/StructureLoot/Common1.nbt,15,CHEST:5,../NBT/StructureLoot/Common2.nbt,15,CHEST:5,../NBT/StructureLoot/Common3.nbt,15,CHEST:5,../NBT/StructureLoot/Common4.nbt,15,CHEST:5,../NBT/StructureLoot/Common5.nbt,15,CHEST:5,../NBT/StructureLoot/Common6.nbt,15,CHEST:5,../NBT/StructureLoot/Common7.nbt,15,CHEST:5,../NBT/StructureLoot/Common8.nbt,15,CHEST:5,../NBT/StructureLoot/Common9.nbt,15,CHEST:5,../NBT/StructureLoot/Common10.nbt,15,CHEST:5,../NBT/StructureLoot/Common11.nbt,15,CHEST:5,../NBT/StructureLoot/Common12.nbt,15,CHEST:5,../NBT/StructureLoot/Common13.nbt,15,CHEST:5,../NBT/StructureLoot/Common14.nbt,15,CHEST:5,../NBT/StructureLoot/Common15.nbt,100)
B(-5,53,-2,TRAPDOOR:5)
B(-4,53,-2,COBBLESTONE:0)
B(-8,53,-1,COBBLESTONE:0)
B(-7,53,-1,FURNACE:5)
B(-6,53,-1,CARPET:7)
B(-5,53,-1,CARPET:7)
B(-4,53,-1,SPRUCE_DOOR:0)
B(-8,54,-8,PLANKS:1)
B(-6,54,-8,AIR)
B(-4,54,-8,PLANKS:1)
B(-3,54,-8,BOOKSHELF:0)
B(-8,54,-7,LOG:1)
B(-7,54,-7,PLANKS:1)
B(-6,54,-7,SPRUCE_DOOR:8)
B(-5,54,-7,PLANKS:1)
B(-4,54,-7,LOG:1)
B(-3,54,-7,PLANKS:1)
B(-2,54,-7,DARK_OAK_FENCE:0)
B(-1,54,-7,PLANKS:1)
B(-8,54,-6,PLANKS:1)
B(-6,54,-6,AIR)
B(-5,54,-6,BOOKSHELF:0)
B(-4,54,-6,PLANKS:1)
B(-8,54,-5,PLANKS:1)
B(-4,54,-5,PLANKS:1)
B(-8,54,-4,PLANKS:1)
B(-4,54,-4,PLANKS:1)
B(-8,54,-3,PLANKS:1)
B(-4,54,-3,LOG:1)
B(-8,54,-2,PLANKS:1)
B(-4,54,-2,COBBLESTONE:0)
B(-8,54,-1,PLANKS:1)
B(-4,54,-1,SPRUCE_DOOR:8)
B(-8,55,-8,LOG:9)
B(-7,55,-8,WOODEN_SLAB:8)
B(-6,55,-8,WOODEN_SLAB:8)
B(-5,55,-8,WOODEN_SLAB:8)
B(-4,55,-8,DOUBLE_WOODEN_SLAB:0)
B(-3,55,-8,WOODEN_SLAB:8)
B(-2,55,-8,WOODEN_SLAB:8)
B(-1,55,-8,WOODEN_SLAB:8)
B(-8,55,-7,LOG:1)
B(-7,55,-7,DOUBLE_WOODEN_SLAB:0)
B(-6,55,-7,DOUBLE_WOODEN_SLAB:0)
B(-5,55,-7,DOUBLE_WOODEN_SLAB:0)
B(-4,55,-7,LOG:1)
B(-3,55,-7,LOG:5)
B(-2,55,-7,LOG:5)
B(-1,55,-7,LOG:5)
B(-8,55,-6,LOG:9)
B(-7,55,-6,WOODEN_SLAB:8)
B(-6,55,-6,WOODEN_SLAB:8)
B(-5,55,-6,WOODEN_SLAB:8)
B(-4,55,-6,LOG:9)
B(-3,55,-6,SPRUCE_STAIRS:5)
B(-2,55,-6,WOODEN_SLAB:8)
B(-1,55,-6,WOODEN_SLAB:8)
B(-8,55,-5,LOG:9)
B(-7,55,-5,WOODEN_SLAB:8)
B(-6,55,-5,WOODEN_SLAB:8)
B(-5,55,-5,WOODEN_SLAB:8)
B(-4,55,-5,LOG:9)
B(-3,55,-5,WOODEN_SLAB:9)
B(-8,55,-4,LOG:9)
B(-7,55,-4,WOODEN_SLAB:8)
B(-6,55,-4,WOODEN_SLAB:8)
B(-5,55,-4,WOODEN_SLAB:8)
B(-4,55,-4,LOG:9)
B(-3,55,-4,WOODEN_SLAB:9)
B(-8,55,-3,LOG:9)
B(-7,55,-3,WOODEN_SLAB:8)
B(-6,55,-3,WOODEN_SLAB:8)
B(-5,55,-3,WOODEN_SLAB:8)
B(-4,55,-3,LOG:1)
B(-3,55,-3,SPRUCE_STAIRS:5)
B(-8,55,-2,LOG:9)
B(-7,55,-2,WOODEN_SLAB:8)
B(-6,55,-2,WOODEN_SLAB:8)
B(-5,55,-2,WOODEN_SLAB:8)
B(-4,55,-2,LOG:9)
B(-3,55,-2,WOODEN_SLAB:9)
B(-8,55,-1,LOG:9)
B(-7,55,-1,WOODEN_SLAB:8)
B(-6,55,-1,WOODEN_SLAB:8)
B(-5,55,-1,WOODEN_SLAB:8)
B(-4,55,-1,LOG:9)
B(-3,55,-1,WOODEN_SLAB:9)
B(-8,56,-8,SPRUCE_FENCE:0)
B(-5,56,-8,PLANKS:1)
B(-4,56,-8,BED:8)
RB(-3,56,-8,AIR,25,CHEST:2,../NBT/StructureLoot/JunkChest_1.nbt,15,CHEST:2,../NBT/StructureLoot/JunkChest_2.nbt,15,CHEST:2,../NBT/StructureLoot/JunkChest_3.nbt,15,CHEST:2,../NBT/StructureLoot/JunkChest_4.nbt,15,CHEST:2,../NBT/StructureLoot/JunkChest_5.nbt,15,CHEST:2,../NBT/StructureLoot/Common1.nbt,15,CHEST:2,../NBT/StructureLoot/Common2.nbt,15,CHEST:2,../NBT/StructureLoot/Common3.nbt,15,CHEST:2,../NBT/StructureLoot/Common4.nbt,15,CHEST:2,../NBT/StructureLoot/Common5.nbt,15,CHEST:2,../NBT/StructureLoot/Common6.nbt,15,CHEST:2,../NBT/StructureLoot/Common7.nbt,15,CHEST:2,../NBT/StructureLoot/Common8.nbt,15,CHEST:2,../NBT/StructureLoot/Common9.nbt,15,CHEST:2,../NBT/StructureLoot/Common10.nbt,15,CHEST:2,../NBT/StructureLoot/Common11.nbt,15,CHEST:2,../NBT/StructureLoot/Common12.nbt,15,CHEST:2,../NBT/StructureLoot/Common13.nbt,15,CHEST:2,../NBT/StructureLoot/Common14.nbt,15,CHEST:2,../NBT/StructureLoot/Common15.nbt,100)
RB(-1,56,-8,AIR,25,CHEST:4,../NBT/StructureLoot/JunkChest_1.nbt,15,CHEST:4,../NBT/StructureLoot/JunkChest_2.nbt,15,CHEST:4,../NBT/StructureLoot/JunkChest_3.nbt,15,CHEST:4,../NBT/StructureLoot/JunkChest_4.nbt,15,CHEST:4,../NBT/StructureLoot/JunkChest_5.nbt,15,CHEST:4,../NBT/StructureLoot/Common1.nbt,15,CHEST:4,../NBT/StructureLoot/Common2.nbt,15,CHEST:4,../NBT/StructureLoot/Common3.nbt,15,CHEST:4,../NBT/StructureLoot/Common4.nbt,15,CHEST:4,../NBT/StructureLoot/Common5.nbt,15,CHEST:4,../NBT/StructureLoot/Common6.nbt,15,CHEST:4,../NBT/StructureLoot/Common7.nbt,15,CHEST:4,../NBT/StructureLoot/Common8.nbt,15,CHEST:4,../NBT/StructureLoot/Common9.nbt,15,CHEST:4,../NBT/StructureLoot/Common10.nbt,15,CHEST:4,../NBT/StructureLoot/Common11.nbt,15,CHEST:4,../NBT/StructureLoot/Common12.nbt,15,CHEST:4,../NBT/StructureLoot/Common13.nbt,15,CHEST:4,../NBT/StructureLoot/Common14.nbt,15,CHEST:4,../NBT/StructureLoot/Common15.nbt,100)
B(-8,56,-7,LOG:1)
B(-5,56,-7,LOG:1)
B(-4,56,-7,LOG:1)
B(-3,56,-7,COBBLESTONE:0)
B(-2,56,-7,SPRUCE_DOOR:1)
B(-1,56,-7,COBBLESTONE:0)
B(-8,56,-6,SPRUCE_FENCE:0)
B(-4,56,-6,COBBLESTONE:0)
B(-3,56,-6,WOODEN_SLAB:1)
B(-8,56,-5,SPRUCE_FENCE:0)
B(-5,56,-5,OAK_STAIRS:6)
B(-4,56,-5,COBBLESTONE:0)
B(-8,56,-4,SPRUCE_FENCE:0)
B(-5,56,-4,OAK_STAIRS:3)
B(-4,56,-4,COBBLESTONE:0)
B(-8,56,-3,SPRUCE_FENCE:0)
B(-4,56,-3,LOG:1)
B(-3,56,-3,WOODEN_SLAB:1)
B(-4,56,-2,COBBLESTONE:0)
B(-8,56,-1,SPRUCE_FENCE:0)
B(-4,56,-1,COBBLESTONE:0)
B(-5,57,-8,PLANKS:1)
B(-8,57,-7,LOG:1)
B(-5,57,-7,LOG:1)
B(-4,57,-7,LOG:1)
B(-3,57,-7,PLANKS:1)
B(-2,57,-7,SPRUCE_DOOR:8)
B(-1,57,-7,PLANKS:1)
B(-5,57,-6,OAK_STAIRS:6)
B(-4,57,-6,PLANKS:1)
B(-5,57,-5,OAK_STAIRS:3)
B(-4,57,-5,PLANKS:1)
B(-4,57,-4,PLANKS:1)
B(-4,57,-3,LOG:1)
B(-4,57,-2,PLANKS:1)
B(-4,57,-1,DARK_OAK_FENCE:0)
B(-8,58,-8,LOG:9)
B(-7,58,-8,WOODEN_SLAB:8)
B(-6,58,-8,WOODEN_SLAB:8)
B(-5,58,-8,LOG:9)
B(-4,58,-8,WOODEN_SLAB:8)
B(-3,58,-8,WOODEN_SLAB:8)
B(-2,58,-8,WOODEN_SLAB:8)
B(-1,58,-8,WOODEN_SLAB:8)
B(-8,58,-7,LOG:1)
B(-7,58,-7,LOG:5)
B(-6,58,-7,LOG:5)
B(-5,58,-7,LOG:5)
B(-4,58,-7,LOG:1)
B(-3,58,-7,LOG:5)
B(-2,58,-7,LOG:5)
B(-1,58,-7,LOG:5)
B(-8,58,-6,LOG:9)
B(-7,58,-6,WOODEN_SLAB:8)
B(-6,58,-6,WOODEN_SLAB:8)
B(-5,58,-6,OAK_STAIRS:3)
B(-4,58,-6,LOG:9)
B(-3,58,-6,WOODEN_SLAB:9)
B(-2,58,-6,WOODEN_SLAB:9)
B(-1,58,-6,WOODEN_SLAB:9)
B(-8,58,-5,LOG:9)
B(-7,58,-5,WOODEN_SLAB:8)
B(-6,58,-5,WOODEN_SLAB:8)
B(-4,58,-5,LOG:9)
B(-3,58,-5,WOODEN_SLAB:9)
B(-8,58,-4,LOG:9)
B(-7,58,-4,WOODEN_SLAB:8)
B(-6,58,-4,WOODEN_SLAB:8)
B(-4,58,-4,LOG:9)
B(-3,58,-4,WOODEN_SLAB:9)
B(-8,58,-3,LOG:9)
B(-7,58,-3,WOODEN_SLAB:8)
B(-6,58,-3,WOODEN_SLAB:8)
B(-4,58,-3,LOG:1)
B(-3,58,-3,SPRUCE_STAIRS:5)
B(-8,58,-2,LOG:9)
B(-7,58,-2,WOODEN_SLAB:8)
B(-6,58,-2,WOODEN_SLAB:8)
B(-5,58,-2,WOODEN_SLAB:8)
B(-4,58,-2,LOG:9)
B(-3,58,-2,WOODEN_SLAB:9)
B(-8,58,-1,LOG:9)
B(-7,58,-1,WOODEN_SLAB:8)
B(-6,58,-1,WOODEN_SLAB:8)
B(-5,58,-1,WOODEN_SLAB:8)
B(-4,58,-1,LOG:9)
B(-3,58,-1,WOODEN_SLAB:9)
B(-8,59,-8,COBBLESTONE:0)
B(-7,59,-8,CARPET:14)
B(-6,59,-8,BOOKSHELF:0)
B(-4,59,-8,CARPET:14)
B(-3,59,-8,BOOKSHELF:0)
B(-2,59,-8,BOOKSHELF:0)
B(-1,59,-8,STONE:6)
B(-8,59,-7,LOG:1)
B(-7,59,-7,DARK_OAK_DOOR:3)
B(-6,59,-7,PLANKS:1)
B(-5,59,-7,DARK_OAK_DOOR:1)
B(-4,59,-7,LOG:1)
B(-3,59,-7,COBBLESTONE:0)
B(-2,59,-7,COBBLESTONE:0)
B(-1,59,-7,COBBLESTONE:0)
B(-8,59,-6,COBBLESTONE:0)
B(-7,59,-6,CARPET:14)
B(-6,59,-6,PLANKS:1)
B(-4,59,-6,COBBLESTONE:0)
B(-3,59,-6,WOODEN_SLAB:1)
B(-2,59,-6,SPRUCE_FENCE:0)
B(-1,59,-6,SPRUCE_FENCE:0)
B(-8,59,-5,COBBLESTONE:0)
B(-7,59,-5,CARPET:14)
B(-6,59,-5,PLANKS:1)
B(-4,59,-5,COBBLESTONE:0)
B(-3,59,-5,SPRUCE_FENCE:0)
B(-8,59,-4,COBBLESTONE:0)
B(-6,59,-4,PLANKS:1)
B(-4,59,-4,COBBLESTONE:0)
B(-3,59,-4,SPRUCE_FENCE:0)
B(-8,59,-3,COBBLESTONE:0)
B(-7,59,-3,CARPET:14)
B(-6,59,-3,PLANKS:1)
B(-4,59,-3,LOG:1)
B(-3,59,-3,WOODEN_SLAB:1)
B(-8,59,-2,COBBLESTONE:0)
B(-7,59,-2,CARPET:14)
B(-6,59,-2,PLANKS:1)
B(-5,59,-2,PLANKS:1)
B(-4,59,-2,COBBLESTONE:0)
B(-3,59,-2,SPRUCE_FENCE:0)
B(-8,59,-1,COBBLESTONE:0)
B(-5,59,-1,FURNACE:4)
B(-4,59,-1,COBBLESTONE:0)
B(-3,59,-1,SPRUCE_FENCE:0)
B(-8,60,-8,PLANKS:1)
B(-6,60,-8,BOOKSHELF:0)
B(-3,60,-8,BOOKSHELF:0)
RB(-1,60,-8,FLOWER_POT:0,../NBT/Flowers/flower_pot_01.nbt,5,FLOWER_POT:0,../NBT/Flowers/flower_pot_02.nbt,5,FLOWER_POT:0,../NBT/Flowers/flower_pot_03.nbt,5,FLOWER_POT:0,../NBT/Flowers/flower_pot_04.nbt,5,FLOWER_POT:0,../NBT/Flowers/flower_pot_05.nbt,5,FLOWER_POT:0,../NBT/Flowers/flower_pot_06.nbt,5,FLOWER_POT:0,../NBT/Flowers/flower_pot_07.nbt,5,FLOWER_POT:0,../NBT/Flowers/flower_pot_08.nbt,5,FLOWER_POT:0,../NBT/Flowers/flower_pot_09.nbt,5,FLOWER_POT:0,../NBT/Flowers/flower_pot_10.nbt,5,FLOWER_POT:0,../NBT/Flowers/flower_pot_11.nbt,5,FLOWER_POT:0,../NBT/Flowers/flower_pot_12.nbt,5,FLOWER_POT:0,../NBT/Flowers/flower_pot_13.nbt,5,FLOWER_POT:0,../NBT/Flowers/flower_pot_14.nbt,5,FLOWER_POT:0,../NBT/Flowers/flower_pot_15.nbt,5,FLOWER_POT:0,../NBT/Flowers/flower_pot_16.nbt,5,FLOWER_POT:0,../NBT/Flowers/flower_pot_17.nbt,5,FLOWER_POT:0,../NBT/Flowers/flower_pot_18.nbt,5,FLOWER_POT:0,../NBT/Flowers/flower_pot_19.nbt,5,FLOWER_POT:0,../NBT/Flowers/flower_pot_20.nbt,100)
B(-8,60,-7,LOG:1)
B(-7,60,-7,DARK_OAK_DOOR:8)
B(-6,60,-7,PLANKS:1)
B(-5,60,-7,DARK_OAK_DOOR:8)
B(-4,60,-7,LOG:1)
B(-3,60,-7,PLANKS:1)
B(-2,60,-7,DARK_OAK_FENCE:0)
B(-1,60,-7,PLANKS:1)
B(-8,60,-6,PLANKS:1)
B(-6,60,-6,PLANKS:1)
B(-4,60,-6,PLANKS:1)
B(-8,60,-5,DARK_OAK_FENCE:0)
B(-6,60,-5,PLANKS:1)
B(-4,60,-5,DARK_OAK_FENCE:0)
B(-8,60,-4,PLANKS:1)
B(-6,60,-4,PLANKS:1)
B(-4,60,-4,PLANKS:1)
B(-8,60,-3,DARK_OAK_FENCE:0)
B(-6,60,-3,PLANKS:1)
B(-4,60,-3,LOG:1)
B(-8,60,-2,PLANKS:1)
B(-6,60,-2,PLANKS:1)
B(-5,60,-2,PLANKS:1)
B(-4,60,-2,PLANKS:1)
B(-8,60,-1,DARK_OAK_FENCE:0)
B(-4,60,-1,DARK_OAK_FENCE:0)
B(-8,61,-8,LOG:9)
B(-7,61,-8,DOUBLE_WOODEN_SLAB:0)
B(-6,61,-8,DOUBLE_WOODEN_SLAB:0)
B(-5,61,-8,DOUBLE_WOODEN_SLAB:0)
B(-4,61,-8,LOG:9)
B(-3,61,-8,WOODEN_SLAB:8)
B(-2,61,-8,WOODEN_SLAB:8)
B(-1,61,-8,WOODEN_SLAB:8)
B(-8,61,-7,LOG:1)
B(-7,61,-7,DOUBLE_WOODEN_SLAB:0)
B(-6,61,-7,DOUBLE_WOODEN_SLAB:0)
B(-5,61,-7,DOUBLE_WOODEN_SLAB:0)
B(-4,61,-7,LOG:1)
B(-3,61,-7,LOG:5)
B(-2,61,-7,LOG:5)
B(-1,61,-7,LOG:5)
B(-8,61,-6,LOG:9)
B(-7,61,-6,DOUBLE_WOODEN_SLAB:0)
B(-6,61,-6,DOUBLE_WOODEN_SLAB:0)
B(-5,61,-6,DOUBLE_WOODEN_SLAB:0)
B(-4,61,-6,LOG:9)
B(-3,61,-6,WOODEN_SLAB:8)
B(-2,61,-6,WOODEN_SLAB:8)
B(-1,61,-6,WOODEN_SLAB:8)
B(-8,61,-5,LOG:9)
B(-7,61,-5,DOUBLE_WOODEN_SLAB:0)
B(-6,61,-5,DOUBLE_WOODEN_SLAB:0)
B(-5,61,-5,DOUBLE_WOODEN_SLAB:0)
B(-4,61,-5,LOG:9)
B(-3,61,-5,WOODEN_SLAB:8)
B(-8,61,-4,LOG:9)
B(-7,61,-4,DOUBLE_WOODEN_SLAB:0)
B(-6,61,-4,DOUBLE_WOODEN_SLAB:0)
B(-5,61,-4,DOUBLE_WOODEN_SLAB:0)
B(-4,61,-4,LOG:9)
B(-3,61,-4,WOODEN_SLAB:8)
B(-8,61,-3,LOG:9)
B(-7,61,-3,DOUBLE_WOODEN_SLAB:0)
B(-6,61,-3,DOUBLE_WOODEN_SLAB:0)
B(-5,61,-3,DOUBLE_WOODEN_SLAB:0)
B(-4,61,-3,LOG:1)
B(-3,61,-3,WOODEN_SLAB:8)
B(-8,61,-2,LOG:9)
B(-7,61,-2,DOUBLE_WOODEN_SLAB:0)
B(-6,61,-2,DOUBLE_WOODEN_SLAB:0)
B(-5,61,-2,DOUBLE_WOODEN_SLAB:0)
B(-4,61,-2,LOG:9)
B(-3,61,-2,WOODEN_SLAB:8)
B(-8,61,-1,LOG:9)
B(-7,61,-1,DOUBLE_WOODEN_SLAB:0)
B(-6,61,-1,DOUBLE_WOODEN_SLAB:0)
B(-5,61,-1,DOUBLE_WOODEN_SLAB:0)
B(-4,61,-1,LOG:9)
B(-3,61,-1,WOODEN_SLAB:8)
B(-8,62,-8,PLANKS:1)
B(-7,62,-8,BOOKSHELF:0)
B(-6,62,-8,BOOKSHELF:0)
B(-5,62,-8,BOOKSHELF:0)
B(-4,62,-8,BOOKSHELF:0)
B(-8,62,-7,PLANKS:1)
B(-7,62,-7,COBBLESTONE:0)
B(-6,62,-7,COBBLESTONE:0)
B(-5,62,-7,DOUBLE_WOODEN_SLAB:1)
B(-4,62,-7,SPRUCE_STAIRS:3)
B(-3,62,-7,SPRUCE_STAIRS:3)
B(-2,62,-7,SPRUCE_STAIRS:3)
B(-1,62,-7,SPRUCE_STAIRS:3)
B(-8,62,-6,PLANKS:1)
B(-7,62,-6,COBBLESTONE:0)
B(-6,62,-6,COBBLESTONE:0)
B(-5,62,-6,DOUBLE_WOODEN_SLAB:1)
B(-4,62,-6,WOODEN_SLAB:1)
B(-8,62,-5,PLANKS:1)
B(-7,62,-5,COBBLESTONE:0)
B(-6,62,-5,COBBLESTONE:0)
B(-5,62,-5,DOUBLE_WOODEN_SLAB:1)
B(-4,62,-5,WOODEN_SLAB:1)
B(-8,62,-4,PLANKS:1)
B(-7,62,-4,COBBLESTONE:0)
B(-6,62,-4,COBBLESTONE:0)
B(-5,62,-4,DOUBLE_WOODEN_SLAB:1)
B(-4,62,-4,WOODEN_SLAB:1)
B(-8,62,-3,PLANKS:1)
B(-7,62,-3,COBBLESTONE:0)
B(-6,62,-3,COBBLESTONE:0)
B(-5,62,-3,DOUBLE_WOODEN_SLAB:1)
B(-4,62,-3,WOODEN_SLAB:1)
B(-8,62,-2,PLANKS:1)
B(-7,62,-2,COBBLESTONE:0)
B(-6,62,-2,COBBLESTONE:0)
B(-5,62,-2,DOUBLE_WOODEN_SLAB:1)
B(-4,62,-2,WOODEN_SLAB:1)
B(-8,62,-1,PLANKS:1)
B(-7,62,-1,COBBLESTONE:0)
B(-6,62,-1,COBBLESTONE:0)
B(-5,62,-1,DOUBLE_WOODEN_SLAB:1)
B(-4,62,-1,WOODEN_SLAB:1)
B(-8,63,-8,SPRUCE_STAIRS:3)
B(-7,63,-8,DOUBLE_WOODEN_SLAB:1)
B(-6,63,-8,SPRUCE_STAIRS:3)
B(-5,63,-8,SPRUCE_STAIRS:3)
B(-4,63,-8,SPRUCE_STAIRS:3)
B(-3,63,-8,SPRUCE_STAIRS:3)
B(-2,63,-8,SPRUCE_STAIRS:3)
B(-1,63,-8,SPRUCE_STAIRS:3)
B(-8,63,-7,WOODEN_SLAB:1)
B(-7,63,-7,DOUBLE_WOODEN_SLAB:1)
B(-6,63,-7,WOODEN_SLAB:1)
B(-8,63,-6,WOODEN_SLAB:1)
B(-7,63,-6,DOUBLE_WOODEN_SLAB:1)
B(-6,63,-6,WOODEN_SLAB:1)
B(-8,63,-5,WOODEN_SLAB:1)
B(-7,63,-5,DOUBLE_WOODEN_SLAB:1)
B(-6,63,-5,WOODEN_SLAB:1)
B(-8,63,-4,WOODEN_SLAB:1)
B(-7,63,-4,DOUBLE_WOODEN_SLAB:1)
B(-6,63,-4,WOODEN_SLAB:1)
B(-8,63,-3,WOODEN_SLAB:1)
B(-7,63,-3,DOUBLE_WOODEN_SLAB:1)
B(-6,63,-3,WOODEN_SLAB:1)
B(-8,63,-2,WOODEN_SLAB:1)
B(-7,63,-2,DOUBLE_WOODEN_SLAB:1)
B(-6,63,-2,WOODEN_SLAB:1)
B(-8,63,-1,WOODEN_SLAB:1)
B(-7,63,-1,DOUBLE_WOODEN_SLAB:1)
B(-6,63,-1,WOODEN_SLAB:1)

E(-6,54,-8,VILLAGER,1,../NBT/MOBS/RandomVillager.txt)
E(-6,54,-6,VILLAGER,1,../NBT/MOBS/RandomVillager.txt)

BR(-8,0,0,WestPort_5x5,NORTH,100)
