
#######################################################################
# +-----------------------------------------------------------------+ #
# |                            BO3 object                           | #
# +-----------------------------------------------------------------+ #
#######################################################################

Author: NLBlackEagle

Description: No description given

Version: 3

SettingsMode: WriteDisable


#######################################################################
# +-----------------------------------------------------------------+ #
# |                          Main settings                          | #
# +-----------------------------------------------------------------+ #
#######################################################################

Tree: true

Frequency: 1

Rarity: 100.0

RotateRandomly: true

SpawnHeight: randomY

SpawnHeightOffset: 0

SpawnHeightVariance: 0

##############################
# Height Limits for the BO3. #
##############################

MinHeight: 10

MaxHeight: 20

######################
# Extrusion settings #
######################

ExtrudeMode: None

ExtrudeThroughBlocks: AIR

MaxBranchDepth: 10

ExcludedBiomes: All


#######################################################################
# +-----------------------------------------------------------------+ #
# |                      Source block settings                      | #
# +-----------------------------------------------------------------+ #
#######################################################################

SourceBlocks: AIR,GRASS,DIRT,SAND

MaxPercentageOutsideSourceBlock: 0

OutsideSourceBlock: placeAnyway

IsOTGPlus: false

InheritBO3: 

InheritBO3Rotation: NORTH

OverrideChildSettings: true

OverrideParentHeight: false

CanOverride: false

BranchFrequency: 0

BranchFrequencyGroup: 

MustBeBelowOther: false

MustBeInside: 

CannotBeInside: 

ReplacesBO3: 

CanSpawnOnWater: true

SpawnOnWaterOnly: false

SpawnUnderWater: false

SpawnAtWaterLevel: false

HeightOffset: 0

RemoveAir: true

ReplaceAbove: 

ReplaceBelow: 

ReplaceWithBiomeBlocks: true

ReplaceWithGroundBlock: DIRT

ReplaceWithSurfaceBlock: GRASS

SmoothRadius: 0

SmoothHeightOffset: 0

SmoothStartTop: false

SmoothStartWood: false

SmoothingSurfaceBlock: 

SmoothingGroundBlock: 

BO3Group: 

IsSpawnPoint: false


#######################################################################
# +-----------------------------------------------------------------+ #
# |                              Blocks                             | #
# +-----------------------------------------------------------------+ #
#######################################################################

Block(-8,-2,9,LOG:15)
Block(-8,-1,-4,LOG:15)
Block(-8,-1,8,LOG:15)
Block(-8,-1,9,LOG:15)
Block(-8,0,-4,LOG:15)
Block(-8,0,8,LOG:15)
Block(-8,9,1,leaves:3)
Block(-7,0,5,LOG:15)
Block(-7,0,7,LOG:15)
Block(-7,0,8,LOG:15)
Block(-7,1,-4,LOG:15)
Block(-7,1,5,LOG:15)
Block(-7,1,6,LOG:15)
Block(-7,1,7,LOG:15)
Block(-7,7,-1,leaves:3)
Block(-7,9,3,leaves:3)
Block(-7,10,0,leaves:3)
Block(-7,11,-3,leaves:3)
Block(-7,11,0,leaves:3)
Block(-6,-1,1,LOG:15)
Block(-6,-1,2,LOG:15)
Block(-6,-1,3,LOG:15)
Block(-6,0,3,LOG:15)
Block(-6,0,4,LOG:15)
Block(-6,0,5,LOG:15)
Block(-6,1,-4,LOG:15)
Block(-6,8,-4,leaves:3)
Block(-6,8,-1,leaves:3)
Block(-6,9,-1,leaves:3)
Block(-6,10,3,leaves:3)
Block(-6,11,3,leaves:3)
Block(-6,12,-3,leaves:3)
Block(-6,12,0,leaves:3)
Block(-5,-1,1,LOG:15)
Block(-5,1,-4,LOG:15)
Block(-5,7,2,leaves:3)
Block(-5,8,-3,leaves:3)
Block(-5,8,1,leaves:3)
Block(-5,9,-3,leaves:3)
Block(-5,10,-3,leaves:3)
Block(-5,10,-1,leaves:3)
Block(-5,11,0,leaves:3)
Block(-5,11,2,leaves:3)
Block(-5,12,-2,leaves:3)
Block(-5,12,0,leaves:3)
Block(-5,12,2,leaves:3)
Block(-5,14,1,leaves:3)
Block(-4,-1,1,LOG:15)
Block(-4,-1,2,LOG:15)
Block(-4,0,-4,LOG:15)
Block(-4,0,1,LOG:15)
Block(-4,1,-4,LOG:15)
Block(-4,9,-1,leaves:3)
Block(-4,9,1,leaves:3)
Block(-4,10,-2,leaves:3)
Block(-4,10,-1,leaves:3)
Block(-4,10,0,leaves:3)
Block(-4,11,-2,leaves:3)
Block(-4,11,-1,leaves:3)
Block(-4,11,0,leaves:3)
Block(-4,11,1,leaves:3)
Block(-4,12,-1,leaves:3)
Block(-4,12,0,leaves:3)
Block(-4,13,0,leaves:3)
Block(-4,14,-2,leaves:3)
Block(-3,-1,2,LOG:15)
Block(-3,-1,3,LOG:15)
Block(-3,-1,4,LOG:15)
Block(-3,0,-4,LOG:15)
Block(-3,1,1,LOG:15)
Block(-3,7,0,leaves:3)
Block(-3,8,-1,leaves:3)
Block(-3,9,-2,leaves:3)
Block(-3,9,-1,LOG:3)
Block(-3,9,0,leaves:3)
Block(-3,10,-3,leaves:3)
Block(-3,10,-2,leaves:3)
Block(-3,10,-1,leaves:3)
Block(-3,10,0,leaves:3)
Block(-3,10,1,leaves:3)
Block(-3,10,3,leaves:3)
Block(-3,11,-5,leaves:3)
Block(-3,11,-1,leaves:3)
Block(-3,11,0,leaves:3)
Block(-3,11,1,leaves:3)
Block(-3,11,2,leaves:3)
Block(-3,12,-4,leaves:3)
Block(-3,12,-3,leaves:3)
Block(-3,12,-2,leaves:3)
Block(-3,12,-1,leaves:3)
Block(-3,12,1,leaves:3)
Block(-3,13,-1,leaves:3)
Block(-3,13,2,leaves:3)
Block(-3,13,3,leaves:3)
Block(-2,0,-4,LOG:15)
Block(-2,0,-3,LOG:15)
Block(-2,0,7,LOG:15)
Block(-2,1,1,LOG:15)
Block(-2,6,-1,WOOD_STEP:9)
Block(-2,7,-1,LOG:3)
Block(-2,8,-4,leaves:3)
Block(-2,8,-1,LOG:3)
Block(-2,8,0,leaves:3)
Block(-2,9,-4,leaves:3)
Block(-2,9,-1,SPRUCE_WOOD_STAIRS:1)
Block(-2,9,1,leaves:3)
Block(-2,9,3,leaves:3)
Block(-2,10,-2,leaves:3)
Block(-2,10,-1,leaves:3)
Block(-2,10,0,leaves:3)
Block(-2,11,-1,leaves:3)
Block(-2,11,0,leaves:3)
Block(-2,11,1,leaves:3)
Block(-2,12,0,leaves:3)
Block(-2,13,0,leaves:3)
Block(-1,0,-3,LOG:15)
Block(-1,0,-2,LOG:15)
Block(-1,0,6,LOG:15)
Block(-1,0,7,LOG:15)
Block(-1,1,1,LOG:15)
Block(-1,1,5,LOG:15)
Block(-1,1,6,LOG:15)
Block(-1,2,1,LOG:15)
Block(-1,3,1,SPRUCE_WOOD_STAIRS:0)
Block(-1,4,0,SPRUCE_WOOD_STAIRS:4)
Block(-1,5,0,LOG:3)
Block(-1,6,0,LOG:3)
Block(-1,7,0,WOOD_STEP:1)
Block(-1,7,1,leaves:3)
Block(-1,8,-5,leaves:3)
Block(-1,8,1,leaves:3)
Block(-1,9,-2,leaves:3)
Block(-1,10,-2,leaves:3)
Block(-1,11,0,leaves:3)
Block(-1,12,-1,leaves:3)
Block(-1,12,1,leaves:3)
Block(-1,12,2,leaves:3)
Block(-1,14,-1,leaves:3)
Block(0,0,-2,LOG:15)
Block(0,0,-1,LOG:15)
Block(0,1,-1,LOG:15)
Block(0,1,0,LOG:15)
Block(0,1,1,LOG:15)
Block(0,1,4,LOG:15)
Block(0,1,5,LOG:15)
Block(0,2,0,SPRUCE_WOOD_STAIRS:6)
Block(0,2,1,LOG:15)
Block(0,2,2,SPRUCE_WOOD_STAIRS:7)
Block(0,3,0,WOOD_STEP:1)
Block(0,3,1,LOG:15)
Block(0,3,2,LOG:15)
Block(0,4,1,LOG:3)
Block(0,4,2,WOOD_STEP:1)
Block(0,5,1,WOOD_STEP:1)
Block(0,6,2,leaves:3)
Block(0,8,-3,leaves:3)
Block(0,10,3,leaves:3)
Block(0,11,0,leaves:3)
Block(0,11,3,leaves:3)
Block(0,12,0,leaves:3)
Block(1,1,1,LOG:15)
Block(1,1,2,LOG:15)
Block(1,1,3,LOG:15)
Block(1,1,4,LOG:15)
Block(1,2,1,LOG:15)
Block(1,3,1,WOOD_STEP:1)
Block(1,4,1,SPRUCE_WOOD_STAIRS:5)
Block(1,5,1,LOG:3)
Block(1,6,1,WOOD_STEP:1)
Block(1,7,-4,leaves:3)
Block(1,9,-1,leaves:3)
Block(1,10,0,leaves:3)
Block(1,12,4,leaves:3)
Block(1,13,4,leaves:3)
Block(2,0,0,LOG:15)
Block(2,0,1,LOG:15)
Block(2,1,1,LOG:15)
Block(2,1,3,LOG:15)
Block(2,5,1,WOOD_STEP:9)
Block(2,6,1,LOG:3)
Block(2,7,1,LOG:3)
Block(2,8,1,SPRUCE_WOOD_STAIRS:0)
Block(2,9,5,leaves:3)
Block(2,10,3,leaves:3)
Block(2,12,0,leaves:3)
Block(2,14,5,leaves:3)
Block(3,0,-2,LOG:15)
Block(3,0,-1,LOG:15)
Block(3,0,1,LOG:15)
Block(3,1,3,LOG:15)
Block(3,1,4,LOG:15)
Block(3,7,1,WOOD_STEP:9)
Block(3,8,1,LOG:3)
Block(3,8,2,SPRUCE_WOOD_STAIRS:7)
Block(3,9,2,LOG:3)
Block(3,10,2,WOOD_STEP:1)
Block(3,10,5,leaves:3)
Block(3,10,8,leaves:3)
Block(3,11,3,leaves:3)
Block(3,11,5,leaves:3)
Block(3,11,8,leaves:3)
Block(3,12,3,leaves:3)
Block(3,13,1,leaves:3)
Block(3,14,1,leaves:3)
Block(3,14,8,leaves:3)
Block(3,15,5,leaves:3)
Block(3,15,8,leaves:3)
Block(4,0,-3,LOG:15)
Block(4,0,1,LOG:15)
Block(4,0,5,LOG:15)
Block(4,1,4,LOG:15)
Block(4,9,3,WOOD_STEP:9)
Block(4,10,3,LOG:3)
Block(4,11,2,leaves:3)
Block(4,11,3,LOG:3)
Block(4,11,7,leaves:3)
Block(4,12,3,WOOD_STEP:1)
Block(4,12,5,leaves:3)
Block(4,12,7,leaves:3)
Block(4,13,3,leaves:3)
Block(4,14,2,leaves:3)
Block(4,14,4,leaves:3)
Block(4,15,3,leaves:3)
Block(4,15,5,leaves:3)
Block(4,16,7,leaves:3)
Block(4,17,0,leaves:3)
Block(4,17,4,leaves:3)
Block(5,0,-3,LOG:15)
Block(5,0,1,LOG:15)
Block(5,0,5,LOG:15)
Block(5,0,6,LOG:15)
Block(5,0,7,LOG:15)
Block(5,1,1,LOG:15)
Block(5,12,3,leaves:3)
Block(5,12,4,LOG:3)
Block(5,13,4,leaves:3)
Block(5,13,5,leaves:3)
Block(5,13,6,leaves:3)
Block(5,14,5,leaves:3)
Block(5,14,9,leaves:3)
Block(5,15,2,leaves:3)
Block(5,15,6,leaves:3)
Block(5,16,1,leaves:3)
Block(5,16,4,leaves:3)
Block(6,-1,7,LOG:15)
Block(6,0,-4,LOG:15)
Block(6,0,-3,LOG:15)
Block(6,1,1,LOG:15)
Block(6,10,2,leaves:3)
Block(6,10,8,leaves:3)
Block(6,11,0,leaves:3)
Block(6,11,3,leaves:3)
Block(6,11,7,leaves:3)
Block(6,11,8,leaves:3)
Block(6,12,3,leaves:3)
Block(6,12,5,leaves:3)
Block(6,12,6,leaves:3)
Block(6,12,7,leaves:3)
Block(6,13,0,leaves:3)
Block(6,13,4,leaves:3)
Block(6,13,5,LOG:3)
Block(6,13,6,leaves:3)
Block(6,14,0,leaves:3)
Block(6,14,2,leaves:3)
Block(6,14,3,leaves:3)
Block(6,14,4,leaves:3)
Block(6,14,5,leaves:3)
Block(6,14,6,leaves:3)
Block(6,15,1,leaves:3)
Block(6,15,3,leaves:3)
Block(6,15,4,leaves:3)
Block(6,15,5,leaves:3)
Block(6,15,6,leaves:3)
Block(6,15,7,leaves:3)
Block(6,15,8,leaves:3)
Block(6,16,3,leaves:3)
Block(6,16,5,leaves:3)
Block(6,17,6,leaves:3)
Block(7,-1,7,LOG:15)
Block(7,-1,8,LOG:15)
Block(7,0,-4,LOG:15)
Block(7,1,1,LOG:15)
Block(7,1,2,LOG:15)
Block(7,11,1,leaves:3)
Block(7,12,1,leaves:3)
Block(7,12,4,leaves:3)
Block(7,12,6,leaves:3)
Block(7,13,2,leaves:3)
Block(7,13,3,leaves:3)
Block(7,13,4,leaves:3)
Block(7,13,5,leaves:3)
Block(7,13,6,leaves:3)
Block(7,14,3,leaves:3)
Block(7,14,4,leaves:3)
Block(7,14,5,leaves:3)
Block(7,14,7,leaves:3)
Block(7,15,1,leaves:3)
Block(7,15,2,leaves:3)
Block(7,15,5,leaves:3)
Block(7,15,6,leaves:3)
Block(7,16,0,leaves:3)
Block(7,17,2,leaves:3)
Block(8,-2,8,LOG:15)
Block(8,-1,-5,LOG:15)
Block(8,-1,8,LOG:15)
Block(8,0,-5,LOG:15)
Block(8,0,-4,LOG:15)
Block(8,1,2,LOG:15)
Block(8,10,7,leaves:3)
Block(8,11,3,leaves:3)
Block(8,11,5,leaves:3)
Block(8,11,7,leaves:3)
Block(8,12,3,leaves:3)
Block(8,12,5,leaves:3)
Block(8,12,6,leaves:3)
Block(8,13,4,leaves:3)
Block(8,13,5,leaves:3)
Block(8,14,-1,leaves:3)
Block(8,14,2,leaves:3)
Block(8,14,3,leaves:3)
Block(8,15,-1,leaves:3)
Block(8,15,2,leaves:3)
Block(8,15,3,leaves:3)
Block(8,16,6,leaves:3)
Block(9,-1,-5,LOG:15)
Block(9,0,3,LOG:15)
Block(9,1,2,LOG:15)
Block(9,1,3,LOG:15)
Block(9,10,1,leaves:3)
Block(9,10,5,leaves:3)
Block(9,10,8,leaves:3)
Block(9,11,2,leaves:3)
Block(9,11,5,leaves:3)
Block(9,12,4,leaves:3)
Block(9,13,3,leaves:3)
Block(9,14,4,leaves:3)
Block(9,14,7,leaves:3)
Block(9,15,1,leaves:3)
Block(9,15,2,leaves:3)
Block(9,15,7,leaves:3)
Block(10,-1,-5,LOG:15)
Block(10,-1,4,LOG:15)
Block(10,0,3,LOG:15)
Block(10,0,4,LOG:15)
Block(10,10,5,leaves:3)
Block(10,11,3,leaves:3)
Block(10,12,4,leaves:3)
Block(10,13,1,leaves:3)
Block(10,14,1,leaves:3)
Block(10,14,8,leaves:3)
Block(10,15,4,leaves:3)
Block(11,13,4,leaves:3)
Block(11,14,4,leaves:3)
Block(12,12,5,leaves:3)

#######################################################################
# +-----------------------------------------------------------------+ #
# |                            BO3 checks                           | #
# +-----------------------------------------------------------------+ #
#######################################################################

BlockCheckNot(0,1,0,Solid,STATIONARY_WATER)
BlockCheck(0,-1,0,DIRT,GRASS,SAND)
BlockCheck(0,-2,0,DIRT,GRASS,SAND,STONE)

BlockCheck(1,-2,0,DIRT,GRASS,SAND,STONE)
BlockCheck(0,-2,1,DIRT,GRASS,SAND,STONE)
BlockCheck(0,-2,-1,DIRT,GRASS,SAND,STONE)
BlockCheck(-1,-2,0,DIRT,GRASS,SAND,STONE)
#######################################################################
# +-----------------------------------------------------------------+ #
# |                             Branches                            | #
# +-----------------------------------------------------------------+ #
#######################################################################


#######################################################################
# +-----------------------------------------------------------------+ #
# |                             Entities                            | #
# +-----------------------------------------------------------------+ #
#######################################################################


#######################################################################
# +-----------------------------------------------------------------+ #
# |                            Particles                            | #
# +-----------------------------------------------------------------+ #
#######################################################################


#######################################################################
# +-----------------------------------------------------------------+ #
# |                             Spawners                            | #
# +-----------------------------------------------------------------+ #
#######################################################################


#######################################################################
# +-----------------------------------------------------------------+ #
# |                             ModData                             | #
# +-----------------------------------------------------------------+ #
#######################################################################

