
#######################################################################
# +-----------------------------------------------------------------+ #
# |                            BO3 object                           | #
# +-----------------------------------------------------------------+ #
#######################################################################

Author: NLBlackEagle

Description: No description given

Version: 3

SettingsMode: WriteDisable


#######################################################################
# +-----------------------------------------------------------------+ #
# |                          Main settings                          | #
# +-----------------------------------------------------------------+ #
#######################################################################

Tree: true

Frequency: 1

Rarity: 100.0

RotateRandomly: true

SpawnHeight: randomY

SpawnHeightOffset: 0

SpawnHeightVariance: 0

##############################
# Height Limits for the BO3. #
##############################

MinHeight: 10

MaxHeight: 20

######################
# Extrusion settings #
######################

ExtrudeMode: None

ExtrudeThroughBlocks: AIR

MaxBranchDepth: 10

ExcludedBiomes: All


#######################################################################
# +-----------------------------------------------------------------+ #
# |                      Source block settings                      | #
# +-----------------------------------------------------------------+ #
#######################################################################

SourceBlocks: AIR,GRASS,DIRT,SAND

MaxPercentageOutsideSourceBlock: 0

OutsideSourceBlock: placeAnyway

IsOTGPlus: false

InheritBO3: 

InheritBO3Rotation: NORTH

OverrideChildSettings: true

OverrideParentHeight: false

CanOverride: false

BranchFrequency: 0

BranchFrequencyGroup: 

MustBeBelowOther: false

MustBeInside: 

CannotBeInside: 

ReplacesBO3: 

CanSpawnOnWater: true

SpawnOnWaterOnly: false

SpawnUnderWater: false

SpawnAtWaterLevel: false

HeightOffset: 0

RemoveAir: true

ReplaceAbove: 

ReplaceBelow: 

ReplaceWithBiomeBlocks: true

ReplaceWithGroundBlock: DIRT

ReplaceWithSurfaceBlock: GRASS

SmoothRadius: 0

SmoothHeightOffset: 0

SmoothStartTop: false

SmoothStartWood: false

SmoothingSurfaceBlock: 

SmoothingGroundBlock: 

BO3Group: 

IsSpawnPoint: false


#######################################################################
# +-----------------------------------------------------------------+ #
# |                              Blocks                             | #
# +-----------------------------------------------------------------+ #
#######################################################################

Block(-6,11,-2,leaves:3)
Block(-5,-2,-6,LOG:15)
Block(-5,-2,-5,LOG:15)
Block(-5,-2,3,LOG:15)
Block(-5,-2,4,LOG:15)
Block(-5,9,-2,leaves:3)
Block(-5,11,-6,leaves:3)
Block(-5,12,-2,leaves:3)
Block(-5,12,2,leaves:3)
Block(-4,-2,-5,LOG:15)
Block(-4,-2,3,LOG:15)
Block(-4,-1,-5,LOG:15)
Block(-4,-1,-4,LOG:15)
Block(-4,-1,2,LOG:15)
Block(-4,-1,3,LOG:15)
Block(-4,9,-5,leaves:3)
Block(-4,9,1,leaves:3)
Block(-4,10,-2,leaves:3)
Block(-4,10,1,leaves:3)
Block(-4,11,-5,leaves:3)
Block(-4,12,-5,leaves:3)
Block(-4,12,-2,leaves:3)
Block(-4,13,1,leaves:3)
Block(-3,-1,-4,LOG:15)
Block(-3,-1,-3,LOG:15)
Block(-3,-1,1,LOG:15)
Block(-3,-1,2,LOG:15)
Block(-3,0,-4,LOG:15)
Block(-3,0,-3,LOG:15)
Block(-3,0,1,LOG:15)
Block(-3,1,1,LOG:15)
Block(-3,9,-4,leaves:3)
Block(-3,10,-4,leaves:3)
Block(-3,10,-2,leaves:3)
Block(-3,10,0,leaves:3)
Block(-3,11,-3,leaves:3)
Block(-3,11,-1,leaves:3)
Block(-3,12,-4,leaves:3)
Block(-3,12,0,leaves:3)
Block(-3,13,-2,leaves:3)
Block(-3,13,0,leaves:3)
Block(-3,14,-4,leaves:3)
Block(-3,15,-2,leaves:3)
Block(-2,0,-3,LOG:15)
Block(-2,0,-2,LOG:15)
Block(-2,0,-1,LOG:15)
Block(-2,1,0,LOG:15)
Block(-2,1,1,LOG:15)
Block(-2,8,-3,leaves:3)
Block(-2,8,-1,leaves:3)
Block(-2,9,-2,leaves:3)
Block(-2,10,-3,leaves:3)
Block(-2,10,-2,leaves:3)
Block(-2,10,-1,leaves:3)
Block(-2,11,-4,leaves:3)
Block(-2,11,-3,leaves:3)
Block(-2,11,-2,leaves:3)
Block(-2,11,-1,leaves:3)
Block(-2,11,0,leaves:3)
Block(-2,12,-5,leaves:3)
Block(-2,12,-3,leaves:3)
Block(-2,12,-2,leaves:3)
Block(-2,12,-1,leaves:3)
Block(-2,13,-2,leaves:3)
Block(-2,13,-1,leaves:3)
Block(-2,14,-1,leaves:3)
Block(-2,15,-3,leaves:3)
Block(-2,15,0,leaves:3)
Block(-2,16,-3,leaves:3)
Block(-1,0,-2,LOG:15)
Block(-1,0,-1,LOG:15)
Block(-1,1,-1,LOG:15)
Block(-1,1,0,LOG:15)
Block(-1,2,-1,WOOD_STEP:1)
Block(-1,2,0,SPRUCE_WOOD_STAIRS:0)
Block(-1,5,-1,SPRUCE_WOOD_STAIRS:4)
Block(-1,6,-2,SPRUCE_WOOD_STAIRS:6)
Block(-1,6,-1,LOG:15)
Block(-1,7,-2,LOG:15)
Block(-1,7,-1,SPRUCE_WOOD_STAIRS:0)
Block(-1,8,-7,leaves:3)
Block(-1,8,-2,LOG:15)
Block(-1,8,2,leaves:3)
Block(-1,9,-6,leaves:3)
Block(-1,9,-5,leaves:3)
Block(-1,9,-3,leaves:3)
Block(-1,9,-2,LOG:15)
Block(-1,9,0,leaves:3)
Block(-1,9,1,leaves:3)
Block(-1,10,-4,leaves:3)
Block(-1,10,-3,leaves:3)
Block(-1,10,-2,LOG:15)
Block(-1,10,-1,leaves:3)
Block(-1,10,0,leaves:3)
Block(-1,11,-6,leaves:3)
Block(-1,11,-3,leaves:3)
Block(-1,11,-2,LOG:15)
Block(-1,11,-1,leaves:3)
Block(-1,11,2,leaves:3)
Block(-1,11,3,leaves:3)
Block(-1,12,-5,leaves:3)
Block(-1,12,-4,leaves:3)
Block(-1,12,-3,leaves:3)
Block(-1,12,-2,leaves:3)
Block(-1,12,-1,leaves:3)
Block(-1,12,0,leaves:3)
Block(-1,12,1,leaves:3)
Block(-1,13,-3,leaves:3)
Block(-1,13,-2,leaves:3)
Block(-1,13,-1,leaves:3)
Block(-1,14,-3,leaves:3)
Block(-1,14,-2,leaves:3)
Block(-1,15,-4,leaves:3)
Block(0,1,-1,SPRUCE_WOOD_STAIRS:1)
Block(0,1,0,LOG:15)
Block(0,1,1,LOG:15)
Block(0,2,0,LOG:15)
Block(0,2,1,WOOD_STEP:1)
Block(0,3,-1,LOG:15)
Block(0,3,0,LOG:15)
Block(0,4,-1,LOG:15)
Block(0,4,0,WOOD_STEP:1)
Block(0,5,-1,LOG:15)
Block(0,6,-1,SPRUCE_WOOD_STAIRS:1)
Block(0,8,0,leaves:3)
Block(0,9,-2,leaves:3)
Block(0,9,-1,leaves:3)
Block(0,10,-3,leaves:3)
Block(0,10,-2,leaves:3)
Block(0,10,-1,leaves:3)
Block(0,10,0,leaves:3)
Block(0,11,-4,leaves:3)
Block(0,11,-3,leaves:3)
Block(0,11,-2,leaves:3)
Block(0,11,-1,leaves:3)
Block(0,11,0,leaves:3)
Block(0,11,2,leaves:3)
Block(0,12,-3,leaves:3)
Block(0,12,-2,leaves:3)
Block(0,12,-1,leaves:3)
Block(0,13,-3,leaves:3)
Block(0,13,0,leaves:3)
Block(0,14,-5,leaves:3)
Block(0,14,0,leaves:3)
Block(0,15,-2,leaves:3)
Block(0,16,-2,leaves:3)
Block(1,-1,-3,LOG:15)
Block(1,0,-2,LOG:15)
Block(1,0,1,LOG:15)
Block(1,1,0,SPRUCE_WOOD_STAIRS:5)
Block(1,1,1,LOG:15)
Block(1,2,0,LOG:15)
Block(1,3,0,SPRUCE_WOOD_STAIRS:1)
Block(1,8,-2,leaves:3)
Block(1,9,-4,leaves:3)
Block(1,9,0,leaves:3)
Block(1,10,-4,leaves:3)
Block(1,10,-2,leaves:3)
Block(1,10,0,leaves:3)
Block(1,11,-5,leaves:3)
Block(1,11,-1,leaves:3)
Block(1,12,-4,leaves:3)
Block(1,12,-2,leaves:3)
Block(1,12,0,leaves:3)
Block(1,13,-2,leaves:3)
Block(1,13,0,leaves:3)
Block(1,14,-3,leaves:3)
Block(1,16,-1,leaves:3)
Block(2,-2,-5,LOG:15)
Block(2,-1,-5,LOG:15)
Block(2,-1,-4,LOG:15)
Block(2,-1,-3,LOG:15)
Block(2,-1,2,LOG:15)
Block(2,-1,3,LOG:15)
Block(2,0,2,LOG:15)
Block(2,8,-5,leaves:3)
Block(2,9,-2,leaves:3)
Block(2,9,1,leaves:3)
Block(2,11,-6,leaves:3)
Block(2,12,-5,leaves:3)
Block(2,12,2,leaves:3)
Block(2,13,-3,leaves:3)
Block(2,13,-2,leaves:3)
Block(2,13,1,leaves:3)
Block(3,-2,-5,LOG:15)
Block(3,-2,3,LOG:15)
Block(3,-1,3,LOG:15)
Block(3,9,-2,leaves:3)
Block(3,10,-6,leaves:3)
Block(3,12,-2,leaves:3)
Block(3,12,2,leaves:3)
Block(4,11,-2,leaves:3)
Block(4,12,-1,leaves:3)

#######################################################################
# +-----------------------------------------------------------------+ #
# |                            BO3 checks                           | #
# +-----------------------------------------------------------------+ #
#######################################################################
BlockCheck(2,-3,-5,DIRT,GRASS,SAND)
BlockCheck(3,-3,-5,DIRT,GRASS,SAND)
BlockCheck(3,-3,3,DIRT,GRASS,SAND)
BlockCheck(-4,-3,-5,DIRT,GRASS,SAND)
BlockCheck(-4,-3,3,DIRT,GRASS,SAND)
BlockCheck(-5,-3,-6,DIRT,GRASS,SAND)
BlockCheck(-5,-3,-5,DIRT,GRASS,SAND)
BlockCheck(-5,-3,3,DIRT,GRASS,SAND)
BlockCheck(-5,-3,4,DIRT,GRASS,SAND)
BlockCheckNot(0,1,0,Solid)
BlockCheck(0,-1,0,DIRT,GRASS,SAND)
BlockCheck(0,-2,0,DIRT,GRASS,SAND,STONE)

BlockCheck(1,-2,0,DIRT,GRASS,SAND,STONE)
BlockCheck(0,-2,1,DIRT,GRASS,SAND,STONE)
BlockCheck(0,-2,-1,DIRT,GRASS,SAND,STONE)
BlockCheck(-1,-2,0,DIRT,GRASS,SAND,STONE)

#######################################################################
# +-----------------------------------------------------------------+ #
# |                             Branches                            | #
# +-----------------------------------------------------------------+ #
#######################################################################


#######################################################################
# +-----------------------------------------------------------------+ #
# |                             Entities                            | #
# +-----------------------------------------------------------------+ #
#######################################################################


#######################################################################
# +-----------------------------------------------------------------+ #
# |                            Particles                            | #
# +-----------------------------------------------------------------+ #
#######################################################################


#######################################################################
# +-----------------------------------------------------------------+ #
# |                             Spawners                            | #
# +-----------------------------------------------------------------+ #
#######################################################################


#######################################################################
# +-----------------------------------------------------------------+ #
# |                             ModData                             | #
# +-----------------------------------------------------------------+ #
#######################################################################

