
#######################################################################
# +-----------------------------------------------------------------+ #
# |                            BO3 object                           | #
# +-----------------------------------------------------------------+ #
#######################################################################

Author: Bo3 BulkEdit

Description: Converted Schematic - Modified by Bo3BulkEdit

Version: 3

SettingsMode: WriteWithoutComments


#######################################################################
# +-----------------------------------------------------------------+ #
# |                          Main settings                          | #
# +-----------------------------------------------------------------+ #
#######################################################################

Tree: false

Frequency: 1

Rarity: 100.0

RotateRandomly: false

SpawnHeight: randomY

SpawnHeightOffset: 0

SpawnHeightVariance: 0

##############################
# Height Limits for the BO3. #
##############################

MinHeight: 0

MaxHeight: 255

######################
# Extrusion settings #
######################

ExtrudeMode: None

ExtrudeThroughBlocks: minecraft:air

MaxBranchDepth: 20


#######################################################################
# +-----------------------------------------------------------------+ #
# |                      Source block settings                      | #
# +-----------------------------------------------------------------+ #
#######################################################################

SourceBlocks: otg:air

MaxPercentageOutsideSourceBlock: 100

OutsideSourceBlock: placeAnyway

DoReplaceBlocks: true

IsOTGPlus: false


#######################################################################
# +-----------------------------------------------------------------+ #
# |                              Blocks                             | #
# +-----------------------------------------------------------------+ #
#######################################################################

B(-2,-2,6,minecraft:dark_oak_slab)
B(-2,-1,6,minecraft:dark_oak_slab)
B(-2,-2,7,minecraft:dark_oak_slab[type=top,waterlogged=false])
B(-2,-1,7,minecraft:dark_oak_slab[type=top,waterlogged=false])
B(-2,-2,8,minecraft:dark_oak_slab[type=top,waterlogged=false])
B(-2,-1,8,minecraft:dark_oak_slab[type=top,waterlogged=false])
B(-2,0,8,minecraft:cyan_terracotta)
B(-1,-3,3,minecraft:dark_oak_slab[type=top,waterlogged=false])
B(-1,-2,4,minecraft:dark_oak_stairs)
B(-1,-1,4,minecraft:dark_oak_slab)
B(-1,-2,5,minecraft:dark_oak_slab)
B(-1,-1,5,minecraft:dark_oak_slab)
B(-1,0,6,minecraft:cyan_terracotta)
B(-1,0,7,minecraft:cyan_terracotta)
B(-1,1,7,minecraft:dark_oak_planks)
B(-1,-3,8,minecraft:water)
B(-1,-2,8,minecraft:water)
B(-1,0,8,minecraft:cyan_terracotta)
B(-1,1,8,minecraft:dark_oak_planks)
B(0,-9,-7,minecraft:spruce_slab)
B(0,-9,-6,minecraft:spruce_slab[type=double,waterlogged=false])
B(0,-9,-5,minecraft:spruce_slab[type=double,waterlogged=false])
B(0,-8,-5,minecraft:spruce_slab)
B(0,-9,-4,minecraft:spruce_slab[type=top,waterlogged=false])
B(0,-8,-4,minecraft:spruce_slab[type=double,waterlogged=false])
B(0,-8,-3,minecraft:spruce_slab[type=double,waterlogged=false])
B(0,-7,-3,minecraft:spruce_slab)
B(0,-8,-2,minecraft:spruce_slab[type=top,waterlogged=false])
B(0,-7,-2,minecraft:spruce_slab[type=double,waterlogged=false])
B(0,-7,-1,minecraft:spruce_slab[type=double,waterlogged=false])
B(0,-6,-1,minecraft:spruce_slab)
B(0,-7,0,minecraft:spruce_slab[type=top,waterlogged=false])
B(0,-6,0,minecraft:spruce_slab[type=double,waterlogged=false])
B(0,-6,1,minecraft:spruce_slab[type=double,waterlogged=false])
B(0,-5,1,minecraft:spruce_slab)
B(0,-2,1,minecraft:dark_oak_slab)
B(0,-6,2,minecraft:spruce_slab[type=top,waterlogged=false])
B(0,-5,2,minecraft:spruce_slab[type=double,waterlogged=false])
B(0,-4,2,minecraft:dark_oak_stairs[facing=north,half=top,shape=straight,waterlogged=false])
B(0,-3,2,minecraft:dark_oak_slab[type=double,waterlogged=false])
B(0,-2,2,minecraft:dark_oak_stairs[facing=south,half=bottom,shape=straight,waterlogged=false])
B(0,-5,3,minecraft:spruce_slab[type=double,waterlogged=false])
B(0,-4,3,minecraft:spruce_slab)
B(0,-3,3,minecraft:cyan_terracotta)
B(0,-2,3,minecraft:cyan_terracotta)
B(0,-1,3,minecraft:cyan_terracotta)
B(0,-5,4,minecraft:spruce_slab[type=top,waterlogged=false])
B(0,-4,4,minecraft:spruce_slab[type=double,waterlogged=false])
B(0,-3,4,minecraft:cyan_terracotta)
B(0,-2,4,minecraft:cyan_terracotta)
B(0,-1,4,minecraft:cyan_terracotta)
B(0,0,4,minecraft:cyan_terracotta)
B(0,-4,5,minecraft:spruce_slab[type=double,waterlogged=false])
B(0,-3,5,minecraft:spruce_slab)
B(0,0,5,minecraft:cyan_terracotta)
B(0,1,5,minecraft:dark_oak_planks)
B(0,-4,6,minecraft:spruce_slab[type=top,waterlogged=false])
B(0,-3,6,minecraft:spruce_slab[type=double,waterlogged=false])
B(0,0,6,minecraft:cyan_terracotta)
B(0,1,6,minecraft:dark_oak_planks)
B(0,2,6,minecraft:dark_oak_planks)
B(0,-3,7,minecraft:spruce_slab[type=double,waterlogged=false])
B(0,-2,7,minecraft:spruce_slab)
B(0,0,7,minecraft:cyan_terracotta)
B(0,1,7,minecraft:dark_oak_planks)
B(0,2,7,minecraft:dark_oak_planks)
B(0,-4,8,minecraft:water)
B(0,-3,8,minecraft:spruce_slab[type=top,waterlogged=false])
B(0,-2,8,minecraft:spruce_slab[type=double,waterlogged=false])
B(0,0,8,minecraft:cyan_terracotta)
B(0,1,8,minecraft:dark_oak_planks)
B(0,2,8,minecraft:dark_oak_planks)
B(0,3,8,minecraft:dark_oak_planks)
B(1,-3,3,minecraft:dark_oak_slab[type=top,waterlogged=false])
B(1,-2,4,minecraft:dark_oak_stairs)
B(1,-1,4,minecraft:dark_oak_slab)
B(1,-2,5,minecraft:dark_oak_slab)
B(1,-1,5,minecraft:dark_oak_slab)
B(1,0,6,minecraft:cyan_terracotta)
B(1,0,7,minecraft:cyan_terracotta)
B(1,1,7,minecraft:dark_oak_planks)
B(1,0,8,minecraft:cyan_terracotta)
B(1,1,8,minecraft:dark_oak_planks)
B(2,-2,6,minecraft:dark_oak_slab)
B(2,-1,6,minecraft:dark_oak_slab)
B(2,-2,7,minecraft:dark_oak_slab[type=top,waterlogged=false])
B(2,-1,7,minecraft:dark_oak_slab[type=top,waterlogged=false])
B(2,-2,8,minecraft:dark_oak_slab[type=top,waterlogged=false])
B(2,-1,8,minecraft:dark_oak_slab[type=top,waterlogged=false])
B(2,0,8,minecraft:cyan_terracotta)

#######################################################################
# +-----------------------------------------------------------------+ #
# |                            BO3 checks                           | #
# +-----------------------------------------------------------------+ #
#######################################################################


#######################################################################
# +-----------------------------------------------------------------+ #
# |                             Branches                            | #
# +-----------------------------------------------------------------+ #
#######################################################################


#######################################################################
# +-----------------------------------------------------------------+ #
# |                             Entities                            | #
# +-----------------------------------------------------------------+ #
#######################################################################

