#######################################################################
# +-----------------------------------------------------------------+ #
# |                            BO3 object                           | #
# +-----------------------------------------------------------------+ #
#######################################################################

Author: Bo3 BulkEdit

Description: Converted Schematic - Modified by Bo3BulkEdit

Version: 3

SettingsMode: WriteDisable

#######################################################################
# +-----------------------------------------------------------------+ #
# |                          Main settings                          | #
# +-----------------------------------------------------------------+ #
#######################################################################



Frequency: 0


SpawnHeight: randomY





##############################
# Height Limits for the BO3. #
##############################

MinHeight: 0
MaxHeight: 256

#######################################################################
# +-----------------------------------------------------------------+ #
# |                      Source block settings                      | #
# +-----------------------------------------------------------------+ #
#######################################################################

CanOverride: true
MaxPercentageOutsideSourceBlock: 100
OutsideSourceBlock: placeAnyway

#######################################################################
# +-----------------------------------------------------------------+ #
# |                               OTG+                              | #
# +-----------------------------------------------------------------+ #
#######################################################################

#######################################################################
# +-----------------------------------------------------------------+ #
# |                              Blocks                             | #
# +-----------------------------------------------------------------+ #
#######################################################################

B(0,750,0,AIR)
B(15,750,15,AIR)
B(13,-1,13,STAINED_GLASS:15)
B(14,-1,13,STAINED_GLASS:15)
B(15,-1,13,STAINED_GLASS:15)
B(13,-1,14,STAINED_GLASS:15)
B(14,-1,14,STAINED_GLASS:15)
B(15,-1,14,STAINED_GLASS:15)
B(12,-1,15,STAINED_GLASS:15)
B(13,-1,15,STAINED_GLASS:15)
B(14,-1,15,STAINED_GLASS:15)
B(15,-1,15,STAINED_GLASS:15)
B(12,0,10,STAINED_GLASS:15)
B(13,0,10,STAINED_GLASS:15)
B(14,0,10,STAINED_GLASS:15)
B(15,0,10,STAINED_GLASS:15)
B(11,0,11,STAINED_GLASS:15)
B(12,0,11,STAINED_GLASS:15)
B(13,0,11,STAINED_GLASS:15)
B(14,0,11,STAINED_GLASS:15)
B(15,0,11,STAINED_GLASS:15)
B(10,0,12,STAINED_GLASS:15)
B(11,0,12,STAINED_GLASS:15)
B(12,0,12,STAINED_GLASS:15)
B(13,0,12,STAINED_GLASS:15)
B(14,0,12,STAINED_GLASS:15)
B(15,0,12,STAINED_GLASS:15)
B(9,0,13,STAINED_GLASS:15)
B(10,0,13,STAINED_GLASS:15)
B(11,0,13,STAINED_GLASS:15)
B(12,0,13,STAINED_GLASS:15)
B(13,0,13,STAINED_GLASS:15)
B(14,0,13,STAINED_GLASS:15)
B(15,0,13,STAINED_GLASS:15)
B(10,0,14,STAINED_GLASS:15)
B(11,0,14,STAINED_GLASS:15)
B(12,0,14,STAINED_GLASS:15)
B(13,0,14,STAINED_GLASS:15)
B(15,0,14,SEA_LANTERN)
B(10,0,15,STAINED_GLASS:15)
B(11,0,15,STAINED_GLASS:15)
B(12,0,15,STAINED_GLASS:15)
B(13,0,15,STAINED_GLASS:15)
B(14,0,15,SEA_LANTERN)
B(12,1,8,STAINED_GLASS:15)
B(13,1,8,STAINED_GLASS:15)
B(11,1,9,STAINED_GLASS:15)
B(12,1,9,STAINED_GLASS:15)
B(13,1,9,STAINED_GLASS:15)
B(14,1,9,STAINED_GLASS:15)
B(15,1,9,STAINED_GLASS:15)
B(10,1,10,STAINED_GLASS:15)
B(11,1,10,STAINED_GLASS:15)
B(12,1,10,STAINED_GLASS:15)
B(13,1,10,STAINED_GLASS:15)
B(14,1,10,STAINED_GLASS:15)
B(15,1,10,STAINED_GLASS:15)
B(9,1,11,STAINED_GLASS:15)
B(10,1,11,STAINED_GLASS:15)
B(11,1,11,STAINED_GLASS:15)
B(12,1,11,STAINED_GLASS:6)
B(13,1,11,STAINED_GLASS:10)
B(14,1,11,STAINED_GLASS:10)
B(15,1,11,STAINED_GLASS:6)
B(8,1,12,STAINED_GLASS:15)
B(9,1,12,STAINED_GLASS:15)
B(10,1,12,STAINED_GLASS:15)
B(11,1,12,STAINED_GLASS:6)
B(12,1,12,STAINED_GLASS:10)
B(13,1,12,STAINED_GLASS:10)
B(14,1,12,STAINED_GLASS:10)
B(15,1,12,STAINED_GLASS:10)
B(8,1,13,STAINED_GLASS:15)
B(9,1,13,STAINED_GLASS:15)
B(10,1,13,STAINED_GLASS:15)
B(11,1,13,STAINED_GLASS:10)
B(12,1,13,STAINED_GLASS:10)
B(13,1,13,SEA_LANTERN)
B(14,1,13,SEA_LANTERN)
B(15,1,13,STAINED_GLASS:10)
B(9,1,14,STAINED_GLASS:15)
B(10,1,14,STAINED_GLASS:15)
B(11,1,14,STAINED_GLASS:10)
B(12,1,14,STAINED_GLASS:10)
B(13,1,14,SEA_LANTERN)
B(14,1,14,SEA_LANTERN)
B(15,1,14,STAINED_GLASS:10)
B(9,1,15,STAINED_GLASS:9)
B(10,1,15,STAINED_GLASS:15)
B(11,1,15,STAINED_GLASS:15)
B(12,1,15,STAINED_GLASS:10)
B(13,1,15,STAINED_GLASS:10)
B(14,1,15,STAINED_GLASS:10)
B(15,1,15,STAINED_GLASS:10)
B(12,2,7,STAINED_GLASS:15)
B(11,2,8,STAINED_GLASS:9)
B(12,2,8,STAINED_GLASS:9)
B(13,2,8,STAINED_GLASS:15)
B(10,2,9,STAINED_GLASS:9)
B(11,2,9,STAINED_GLASS:9)
B(12,2,9,STAINED_GLASS:9)
B(13,2,9,STAINED_GLASS:9)
B(14,2,9,STAINED_GLASS:15)
B(15,2,9,STAINED_GLASS:15)
B(9,2,10,STAINED_GLASS:9)
B(10,2,10,STAINED_GLASS:9)
B(11,2,10,STAINED_GLASS:9)
B(12,2,10,STAINED_GLASS:9)
B(13,2,10,STAINED_GLASS:6)
B(14,2,10,STAINED_GLASS:9)
B(15,2,10,STAINED_GLASS:15)
B(8,2,11,STAINED_GLASS:15)
B(9,2,11,STAINED_GLASS:15)
B(10,2,11,STAINED_GLASS:15)
B(11,2,11,STAINED_GLASS:9)
B(12,2,11,STAINED_GLASS:6)
B(13,2,11,STAINED_GLASS:6)
B(14,2,11,STAINED_GLASS:6)
B(15,2,11,STAINED_GLASS:9)
B(7,2,12,STAINED_GLASS:15)
B(8,2,12,STAINED_GLASS:15)
B(9,2,12,STAINED_GLASS:15)
B(10,2,12,STAINED_GLASS:9)
B(11,2,12,STAINED_GLASS:6)
B(12,2,12,STAINED_GLASS:6)
B(13,2,12,SEA_LANTERN)
B(14,2,12,STAINED_GLASS:6)
B(15,2,12,STAINED_GLASS:6)
B(8,2,13,STAINED_GLASS:15)
B(9,2,13,STAINED_GLASS:9)
B(10,2,13,STAINED_GLASS:6)
B(11,2,13,STAINED_GLASS:6)
B(12,2,13,SEA_LANTERN)
B(13,2,13,SEA_LANTERN)
B(14,2,13,SEA_LANTERN)
B(15,2,13,STAINED_GLASS:6)
B(9,2,14,STAINED_GLASS:9)
B(10,2,14,STAINED_GLASS:9)
B(11,2,14,STAINED_GLASS:6)
B(12,2,14,STAINED_GLASS:6)
B(13,2,14,SEA_LANTERN)
B(14,2,14,STAINED_GLASS:6)
B(15,2,14,STAINED_GLASS:6)
B(9,2,15,STAINED_GLASS:9)
B(10,2,15,STAINED_GLASS:15)
B(11,2,15,STAINED_GLASS:9)
B(12,2,15,STAINED_GLASS:6)
B(13,2,15,STAINED_GLASS:6)
B(14,2,15,STAINED_GLASS:6)
B(15,2,15,STAINED_GLASS:15)
B(11,3,7,STAINED_GLASS:9)
B(12,3,7,STAINED_GLASS:15)
B(10,3,8,STAINED_GLASS:9)
B(11,3,8,STAINED_GLASS:9)
B(12,3,8,STAINED_GLASS:15)
B(13,3,8,STAINED_GLASS:15)
B(14,3,8,STAINED_GLASS:15)
B(9,3,9,STAINED_GLASS:9)
B(10,3,9,STAINED_GLASS:9)
B(11,3,9,STAINED_GLASS:9)
B(12,3,9,STAINED_GLASS:9)
B(13,3,9,STAINED_GLASS:9)
B(14,3,9,STAINED_GLASS:15)
B(15,3,9,STAINED_GLASS:9)
B(8,3,10,STAINED_GLASS:15)
B(9,3,10,STAINED_GLASS:9)
B(10,3,10,STAINED_GLASS:9)
B(11,3,10,STAINED_GLASS:9)
B(12,3,10,STAINED_GLASS:6)
B(13,3,10,STAINED_GLASS:6)
B(14,3,10,STAINED_GLASS:9)
B(15,3,10,STAINED_GLASS:9)
B(7,3,11,STAINED_GLASS:15)
B(8,3,11,STAINED_GLASS:15)
B(9,3,11,STAINED_GLASS:15)
B(10,3,11,STAINED_GLASS:9)
B(11,3,11,STAINED_GLASS:6)
B(12,3,11,STAINED_GLASS:6)
B(13,3,11,STAINED_GLASS:6)
B(14,3,11,STAINED_GLASS:6)
B(15,3,11,STAINED_GLASS:9)
B(7,3,12,STAINED_GLASS:9)
B(8,3,12,STAINED_GLASS:15)
B(9,3,12,STAINED_GLASS:9)
B(10,3,12,STAINED_GLASS:6)
B(11,3,12,STAINED_GLASS:6)
B(12,3,12,SEA_LANTERN)
B(13,3,12,SEA_LANTERN)
B(14,3,12,STAINED_GLASS:6)
B(15,3,12,STAINED_GLASS:6)
B(8,3,13,STAINED_GLASS:15)
B(9,3,13,STAINED_GLASS:9)
B(10,3,13,STAINED_GLASS:6)
B(11,3,13,STAINED_GLASS:6)
B(12,3,13,SEA_LANTERN)
B(13,3,13,SEA_LANTERN)
B(14,3,13,STAINED_GLASS:6)
B(15,3,13,STAINED_GLASS:6)
B(8,3,14,STAINED_GLASS:15)
B(9,3,14,STAINED_GLASS:15)
B(10,3,14,STAINED_GLASS:9)
B(11,3,14,STAINED_GLASS:6)
B(12,3,14,STAINED_GLASS:6)
B(13,3,14,STAINED_GLASS:6)
B(14,3,14,STAINED_GLASS:6)
B(15,3,14,STAINED_GLASS:9)
B(9,3,15,STAINED_GLASS:9)
B(10,3,15,STAINED_GLASS:9)
B(11,3,15,STAINED_GLASS:9)
B(12,3,15,STAINED_GLASS:6)
B(13,3,15,STAINED_GLASS:6)
B(14,3,15,STAINED_GLASS:9)
B(15,3,15,STAINED_GLASS:9)
B(11,4,6,STAINED_GLASS:15)
B(10,4,7,STAINED_GLASS:9)
B(11,4,7,STAINED_GLASS:9)
B(12,4,7,STAINED_GLASS:15)
B(9,4,8,STAINED_GLASS:9)
B(10,4,8,STAINED_GLASS:9)
B(11,4,8,STAINED_GLASS:9)
B(12,4,8,STAINED_GLASS:9)
B(13,4,8,STAINED_GLASS:15)
B(14,4,8,STAINED_GLASS:15)
B(8,4,9,STAINED_GLASS:9)
B(9,4,9,STAINED_GLASS:9)
B(10,4,9,STAINED_GLASS:9)
B(11,4,9,STAINED_GLASS:9)
B(12,4,9,STAINED_GLASS:6)
B(13,4,9,STAINED_GLASS:15)
B(14,4,9,STAINED_GLASS:15)
B(15,4,9,STAINED_GLASS:15)
B(7,4,10,STAINED_GLASS:15)
B(8,4,10,STAINED_GLASS:9)
B(9,4,10,STAINED_GLASS:15)
B(10,4,10,STAINED_GLASS:9)
B(11,4,10,STAINED_GLASS:6)
B(12,4,10,STAINED_GLASS:6)
B(13,4,10,STAINED_GLASS:6)
B(14,4,10,STAINED_GLASS:9)
B(15,4,10,STAINED_GLASS:9)
B(6,4,11,STAINED_GLASS:15)
B(7,4,11,STAINED_GLASS:9)
B(8,4,11,STAINED_GLASS:15)
B(9,4,11,STAINED_GLASS:9)
B(10,4,11,STAINED_GLASS:6)
B(11,4,11,STAINED_GLASS:6)
B(12,4,11,SEA_LANTERN)
B(13,4,11,STAINED_GLASS:6)
B(14,4,11,STAINED_GLASS:6)
B(15,4,11,STAINED_GLASS:9)
B(7,4,12,STAINED_GLASS:15)
B(8,4,12,STAINED_GLASS:9)
B(9,4,12,STAINED_GLASS:6)
B(10,4,12,STAINED_GLASS:6)
B(11,4,12,SEA_LANTERN)
B(12,4,12,SEA_LANTERN)
B(13,4,12,SEA_LANTERN)
B(14,4,12,STAINED_GLASS:6)
B(15,4,12,STAINED_GLASS:6)
B(8,4,13,STAINED_GLASS:15)
B(9,4,13,STAINED_GLASS:15)
B(10,4,13,STAINED_GLASS:6)
B(11,4,13,STAINED_GLASS:6)
B(12,4,13,SEA_LANTERN)
B(13,4,13,STAINED_GLASS:6)
B(14,4,13,STAINED_GLASS:6)
B(15,4,13,STAINED_GLASS:9)
B(8,4,14,STAINED_GLASS:15)
B(9,4,14,STAINED_GLASS:15)
B(10,4,14,STAINED_GLASS:9)
B(11,4,14,STAINED_GLASS:6)
B(12,4,14,STAINED_GLASS:6)
B(13,4,14,STAINED_GLASS:6)
B(14,4,14,STAINED_GLASS:9)
B(15,4,14,STAINED_GLASS:9)
B(9,4,15,STAINED_GLASS:15)
B(10,4,15,STAINED_GLASS:15)
B(11,4,15,STAINED_GLASS:9)
B(12,4,15,STAINED_GLASS:6)
B(13,4,15,STAINED_GLASS:9)
B(14,4,15,STAINED_GLASS:9)
B(15,4,15,STAINED_GLASS:9)
B(10,5,6,STAINED_GLASS:9)
B(11,5,6,STAINED_GLASS:9)
B(9,5,7,STAINED_GLASS:9)
B(10,5,7,STAINED_GLASS:9)
B(11,5,7,STAINED_GLASS:15)
B(12,5,7,STAINED_GLASS:9)
B(13,5,7,STAINED_GLASS:15)
B(8,5,8,STAINED_GLASS:9)
B(9,5,8,STAINED_GLASS:9)
B(10,5,8,STAINED_GLASS:9)
B(11,5,8,STAINED_GLASS:9)
B(12,5,8,STAINED_GLASS:9)
B(13,5,8,STAINED_GLASS:15)
B(14,5,8,STAINED_GLASS:15)
B(7,5,9,STAINED_GLASS:15)
B(8,5,9,STAINED_GLASS:9)
B(9,5,9,STAINED_GLASS:9)
B(10,5,9,STAINED_GLASS:9)
B(11,5,9,STAINED_GLASS:6)
B(12,5,9,STAINED_GLASS:6)
B(13,5,9,STAINED_GLASS:15)
B(14,5,9,STAINED_GLASS:15)
B(15,5,9,STAINED_GLASS:15)
B(6,5,10,STAINED_GLASS:15)
B(7,5,10,STAINED_GLASS:9)
B(8,5,10,STAINED_GLASS:15)
B(9,5,10,STAINED_GLASS:9)
B(10,5,10,STAINED_GLASS:6)
B(11,5,10,STAINED_GLASS:6)
B(12,5,10,STAINED_GLASS:6)
B(13,5,10,STAINED_GLASS:6)
B(14,5,10,STAINED_GLASS:9)
B(15,5,10,STAINED_GLASS:9)
B(6,5,11,STAINED_GLASS:15)
B(7,5,11,STAINED_GLASS:15)
B(8,5,11,STAINED_GLASS:9)
B(9,5,11,STAINED_GLASS:6)
B(10,5,11,STAINED_GLASS:6)
B(11,5,11,SEA_LANTERN)
B(12,5,11,SEA_LANTERN)
B(13,5,11,STAINED_GLASS:6)
B(14,5,11,STAINED_GLASS:6)
B(15,5,11,STAINED_GLASS:9)
B(7,5,12,STAINED_GLASS:15)
B(8,5,12,STAINED_GLASS:9)
B(9,5,12,STAINED_GLASS:6)
B(10,5,12,STAINED_GLASS:6)
B(11,5,12,SEA_LANTERN)
B(12,5,12,SEA_LANTERN)
B(13,5,12,STAINED_GLASS:6)
B(14,5,12,STAINED_GLASS:6)
B(15,5,12,STAINED_GLASS:9)
B(7,5,13,STAINED_GLASS:9)
B(8,5,13,STAINED_GLASS:15)
B(9,5,13,STAINED_GLASS:9)
B(10,5,13,STAINED_GLASS:6)
B(11,5,13,STAINED_GLASS:6)
B(12,5,13,STAINED_GLASS:6)
B(13,5,13,STAINED_GLASS:6)
B(14,5,13,STAINED_GLASS:9)
B(15,5,13,STAINED_GLASS:15)
B(8,5,14,STAINED_GLASS:15)
B(9,5,14,STAINED_GLASS:15)
B(10,5,14,STAINED_GLASS:15)
B(11,5,14,STAINED_GLASS:6)
B(12,5,14,STAINED_GLASS:6)
B(13,5,14,STAINED_GLASS:9)
B(14,5,14,STAINED_GLASS:9)
B(15,5,14,STAINED_GLASS:15)
B(9,5,15,STAINED_GLASS:15)
B(10,5,15,STAINED_GLASS:15)
B(11,5,15,STAINED_GLASS:9)
B(12,5,15,STAINED_GLASS:9)
B(13,5,15,STAINED_GLASS:9)
B(14,5,15,STAINED_GLASS:9)
B(10,6,5,STAINED_GLASS:15)
B(9,6,6,STAINED_GLASS:9)
B(10,6,6,STAINED_GLASS:9)
B(11,6,6,STAINED_GLASS:15)
B(8,6,7,STAINED_GLASS:9)
B(9,6,7,STAINED_GLASS:9)
B(10,6,7,STAINED_GLASS:9)
B(11,6,7,STAINED_GLASS:9)
B(12,6,7,STAINED_GLASS:15)
B(13,6,7,STAINED_GLASS:15)
B(7,6,8,STAINED_GLASS:9)
B(8,6,8,STAINED_GLASS:9)
B(9,6,8,STAINED_GLASS:9)
B(10,6,8,STAINED_GLASS:9)
B(11,6,8,STAINED_GLASS:6)
B(12,6,8,STAINED_GLASS:9)
B(13,6,8,STAINED_GLASS:15)
B(14,6,8,STAINED_GLASS:15)
B(6,6,9,STAINED_GLASS:15)
B(7,6,9,STAINED_GLASS:9)
B(8,6,9,STAINED_GLASS:15)
B(9,6,9,STAINED_GLASS:9)
B(10,6,9,STAINED_GLASS:6)
B(11,6,9,STAINED_GLASS:6)
B(12,6,9,STAINED_GLASS:6)
B(13,6,9,STAINED_GLASS:9)
B(14,6,9,STAINED_GLASS:15)
B(15,6,9,STAINED_GLASS:15)
B(5,6,10,STAINED_GLASS:15)
B(6,6,10,STAINED_GLASS:15)
B(7,6,10,STAINED_GLASS:15)
B(8,6,10,STAINED_GLASS:9)
B(9,6,10,STAINED_GLASS:6)
B(10,6,10,STAINED_GLASS:6)
B(11,6,10,SEA_LANTERN)
B(12,6,10,STAINED_GLASS:6)
B(13,6,10,STAINED_GLASS:6)
B(14,6,10,STAINED_GLASS:9)
B(15,6,10,STAINED_GLASS:15)
B(6,6,11,STAINED_GLASS:15)
B(7,6,11,STAINED_GLASS:9)
B(8,6,11,STAINED_GLASS:6)
B(9,6,11,STAINED_GLASS:6)
B(10,6,11,SEA_LANTERN)
B(11,6,11,SEA_LANTERN)
B(12,6,11,SEA_LANTERN)
B(13,6,11,STAINED_GLASS:6)
B(14,6,11,STAINED_GLASS:6)
B(15,6,11,STAINED_GLASS:9)
B(7,6,12,STAINED_GLASS:15)
B(8,6,12,STAINED_GLASS:9)
B(9,6,12,STAINED_GLASS:6)
B(10,6,12,STAINED_GLASS:6)
B(11,6,12,SEA_LANTERN)
B(12,6,12,STAINED_GLASS:6)
B(13,6,12,STAINED_GLASS:6)
B(14,6,12,STAINED_GLASS:9)
B(15,6,12,STAINED_GLASS:15)
B(7,6,13,STAINED_GLASS:9)
B(8,6,13,STAINED_GLASS:15)
B(9,6,13,STAINED_GLASS:9)
B(10,6,13,STAINED_GLASS:6)
B(11,6,13,STAINED_GLASS:6)
B(12,6,13,STAINED_GLASS:6)
B(13,6,13,STAINED_GLASS:9)
B(14,6,13,STAINED_GLASS:9)
B(15,6,13,STAINED_GLASS:15)
B(8,6,14,STAINED_GLASS:15)
B(9,6,14,STAINED_GLASS:15)
B(10,6,14,STAINED_GLASS:9)
B(11,6,14,STAINED_GLASS:6)
B(12,6,14,STAINED_GLASS:9)
B(13,6,14,STAINED_GLASS:9)
B(14,6,14,STAINED_GLASS:9)
B(9,6,15,STAINED_GLASS:15)
B(10,6,15,STAINED_GLASS:15)
B(11,6,15,STAINED_GLASS:9)
B(12,6,15,STAINED_GLASS:9)
B(13,6,15,STAINED_GLASS:9)
B(9,7,5,STAINED_GLASS:9)
B(10,7,5,STAINED_GLASS:15)
B(8,7,6,STAINED_GLASS:9)
B(9,7,6,STAINED_GLASS:9)
B(10,7,6,STAINED_GLASS:9)
B(11,7,6,STAINED_GLASS:15)
B(12,7,6,STAINED_GLASS:15)
B(7,7,7,STAINED_GLASS:9)
B(8,7,7,STAINED_GLASS:9)
B(9,7,7,STAINED_GLASS:9)
B(10,7,7,STAINED_GLASS:9)
B(11,7,7,STAINED_GLASS:9)
B(12,7,7,STAINED_GLASS:15)
B(13,7,7,STAINED_GLASS:15)
B(6,7,8,STAINED_GLASS:15)
B(7,7,8,STAINED_GLASS:9)
B(8,7,8,STAINED_GLASS:9)
B(9,7,8,STAINED_GLASS:9)
B(10,7,8,STAINED_GLASS:6)
B(11,7,8,STAINED_GLASS:6)
B(12,7,8,STAINED_GLASS:15)
B(13,7,8,STAINED_GLASS:15)
B(14,7,8,STAINED_GLASS:15)
B(5,7,9,STAINED_GLASS:15)
B(6,7,9,STAINED_GLASS:9)
B(7,7,9,STAINED_GLASS:15)
B(8,7,9,STAINED_GLASS:9)
B(9,7,9,STAINED_GLASS:6)
B(10,7,9,STAINED_GLASS:6)
B(11,7,9,STAINED_GLASS:6)
B(12,7,9,STAINED_GLASS:6)
B(13,7,9,STAINED_GLASS:9)
B(14,7,9,STAINED_GLASS:9)
B(15,7,9,STAINED_GLASS:15)
B(5,7,10,STAINED_GLASS:15)
B(6,7,10,STAINED_GLASS:15)
B(7,7,10,STAINED_GLASS:9)
B(8,7,10,STAINED_GLASS:6)
B(9,7,10,STAINED_GLASS:6)
B(10,7,10,SEA_LANTERN)
B(11,7,10,SEA_LANTERN)
B(12,7,10,STAINED_GLASS:6)
B(13,7,10,STAINED_GLASS:6)
B(14,7,10,STAINED_GLASS:9)
B(15,7,10,STAINED_GLASS:15)
B(6,7,11,STAINED_GLASS:15)
B(7,7,11,STAINED_GLASS:9)
B(8,7,11,STAINED_GLASS:6)
B(9,7,11,STAINED_GLASS:6)
B(10,7,11,SEA_LANTERN)
B(11,7,11,SEA_LANTERN)
B(12,7,11,STAINED_GLASS:6)
B(13,7,11,STAINED_GLASS:6)
B(14,7,11,STAINED_GLASS:9)
B(15,7,11,STAINED_GLASS:15)
B(6,7,12,STAINED_GLASS:9)
B(7,7,12,STAINED_GLASS:15)
B(8,7,12,STAINED_GLASS:9)
B(9,7,12,STAINED_GLASS:6)
B(10,7,12,STAINED_GLASS:6)
B(11,7,12,STAINED_GLASS:6)
B(12,7,12,STAINED_GLASS:6)
B(13,7,12,STAINED_GLASS:9)
B(14,7,12,STAINED_GLASS:15)
B(7,7,13,STAINED_GLASS:15)
B(8,7,13,STAINED_GLASS:15)
B(9,7,13,STAINED_GLASS:15)
B(10,7,13,STAINED_GLASS:6)
B(11,7,13,STAINED_GLASS:6)
B(12,7,13,STAINED_GLASS:9)
B(13,7,13,STAINED_GLASS:9)
B(14,7,13,STAINED_GLASS:15)
B(8,7,14,STAINED_GLASS:15)
B(9,7,14,STAINED_GLASS:15)
B(10,7,14,STAINED_GLASS:15)
B(11,7,14,STAINED_GLASS:9)
B(12,7,14,STAINED_GLASS:9)
B(13,7,14,STAINED_GLASS:9)
B(9,7,15,STAINED_GLASS:15)
B(10,7,15,STAINED_GLASS:15)
B(11,7,15,STAINED_GLASS:9)
B(9,8,4,STAINED_GLASS:9)
B(8,8,5,STAINED_GLASS:9)
B(9,8,5,STAINED_GLASS:9)
B(10,8,5,STAINED_GLASS:9)
B(7,8,6,STAINED_GLASS:9)
B(8,8,6,STAINED_GLASS:9)
B(9,8,6,STAINED_GLASS:9)
B(10,8,6,STAINED_GLASS:9)
B(11,8,6,STAINED_GLASS:15)
B(12,8,6,STAINED_GLASS:15)
B(6,8,7,STAINED_GLASS:15)
B(7,8,7,STAINED_GLASS:9)
B(8,8,7,STAINED_GLASS:9)
B(9,8,7,STAINED_GLASS:9)
B(10,8,7,STAINED_GLASS:6)
B(11,8,7,STAINED_GLASS:9)
B(12,8,7,STAINED_GLASS:15)
B(13,8,7,STAINED_GLASS:15)
B(5,8,8,STAINED_GLASS:15)
B(6,8,8,STAINED_GLASS:9)
B(7,8,8,STAINED_GLASS:15)
B(8,8,8,STAINED_GLASS:9)
B(9,8,8,STAINED_GLASS:6)
B(10,8,8,STAINED_GLASS:6)
B(11,8,8,STAINED_GLASS:6)
B(12,8,8,STAINED_GLASS:9)
B(13,8,8,STAINED_GLASS:15)
B(14,8,8,STAINED_GLASS:15)
B(4,8,9,STAINED_GLASS:15)
B(5,8,9,STAINED_GLASS:15)
B(6,8,9,STAINED_GLASS:15)
B(7,8,9,STAINED_GLASS:9)
B(8,8,9,STAINED_GLASS:6)
B(9,8,9,STAINED_GLASS:6)
B(10,8,9,SEA_LANTERN)
B(11,8,9,STAINED_GLASS:6)
B(12,8,9,STAINED_GLASS:6)
B(13,8,9,STAINED_GLASS:9)
B(14,8,9,STAINED_GLASS:15)
B(5,8,10,STAINED_GLASS:15)
B(6,8,10,STAINED_GLASS:9)
B(7,8,10,STAINED_GLASS:6)
B(8,8,10,STAINED_GLASS:6)
B(9,8,10,SEA_LANTERN)
B(10,8,10,SEA_LANTERN)
B(11,8,10,SEA_LANTERN)
B(12,8,10,STAINED_GLASS:6)
B(13,8,10,STAINED_GLASS:6)
B(14,8,10,STAINED_GLASS:9)
B(15,8,10,STAINED_GLASS:15)
B(6,8,11,STAINED_GLASS:15)
B(7,8,11,STAINED_GLASS:9)
B(8,8,11,STAINED_GLASS:6)
B(9,8,11,STAINED_GLASS:6)
B(10,8,11,SEA_LANTERN)
B(11,8,11,STAINED_GLASS:6)
B(12,8,11,STAINED_GLASS:6)
B(13,8,11,STAINED_GLASS:9)
B(14,8,11,STAINED_GLASS:15)
B(6,8,12,STAINED_GLASS:15)
B(7,8,12,STAINED_GLASS:15)
B(8,8,12,STAINED_GLASS:15)
B(9,8,12,STAINED_GLASS:6)
B(10,8,12,STAINED_GLASS:6)
B(11,8,12,STAINED_GLASS:6)
B(12,8,12,STAINED_GLASS:9)
B(13,8,12,STAINED_GLASS:9)
B(14,8,12,STAINED_GLASS:15)
B(7,8,13,STAINED_GLASS:15)
B(8,8,13,STAINED_GLASS:15)
B(9,8,13,STAINED_GLASS:15)
B(10,8,13,STAINED_GLASS:6)
B(11,8,13,STAINED_GLASS:9)
B(12,8,13,STAINED_GLASS:9)
B(13,8,13,STAINED_GLASS:9)
B(8,8,14,STAINED_GLASS:15)
B(9,8,14,STAINED_GLASS:15)
B(10,8,14,STAINED_GLASS:15)
B(11,8,14,STAINED_GLASS:9)
B(12,8,14,STAINED_GLASS:9)
B(10,8,15,STAINED_GLASS:15)
B(8,9,4,STAINED_GLASS:9)
B(9,9,4,STAINED_GLASS:9)
B(7,9,5,STAINED_GLASS:9)
B(8,9,5,STAINED_GLASS:9)
B(9,9,5,STAINED_GLASS:9)
B(10,9,5,STAINED_GLASS:15)
B(11,9,5,STAINED_GLASS:15)
B(6,9,6,STAINED_GLASS:15)
B(7,9,6,STAINED_GLASS:9)
B(8,9,6,STAINED_GLASS:9)
B(9,9,6,STAINED_GLASS:9)
B(10,9,6,STAINED_GLASS:9)
B(11,9,6,STAINED_GLASS:15)
B(12,9,6,STAINED_GLASS:15)
B(5,9,7,STAINED_GLASS:15)
B(6,9,7,STAINED_GLASS:9)
B(7,9,7,STAINED_GLASS:15)
B(8,9,7,STAINED_GLASS:9)
B(9,9,7,STAINED_GLASS:6)
B(10,9,7,STAINED_GLASS:6)
B(11,9,7,STAINED_GLASS:15)
B(12,9,7,STAINED_GLASS:15)
B(13,9,7,STAINED_GLASS:15)
B(4,9,8,STAINED_GLASS:15)
B(5,9,8,STAINED_GLASS:9)
B(6,9,8,STAINED_GLASS:15)
B(7,9,8,STAINED_GLASS:9)
B(8,9,8,STAINED_GLASS:6)
B(9,9,8,STAINED_GLASS:6)
B(10,9,8,STAINED_GLASS:6)
B(11,9,8,STAINED_GLASS:6)
B(12,9,8,STAINED_GLASS:9)
B(13,9,8,STAINED_GLASS:9)
B(14,9,8,STAINED_GLASS:15)
B(4,9,9,STAINED_GLASS:15)
B(5,9,9,STAINED_GLASS:15)
B(6,9,9,STAINED_GLASS:9)
B(7,9,9,STAINED_GLASS:6)
B(8,9,9,STAINED_GLASS:6)
B(9,9,9,SEA_LANTERN)
B(10,9,9,SEA_LANTERN)
B(11,9,9,STAINED_GLASS:6)
B(12,9,9,STAINED_GLASS:6)
B(13,9,9,STAINED_GLASS:15)
B(14,9,9,STAINED_GLASS:15)
B(5,9,10,STAINED_GLASS:15)
B(6,9,10,STAINED_GLASS:9)
B(7,9,10,STAINED_GLASS:6)
B(8,9,10,STAINED_GLASS:6)
B(9,9,10,SEA_LANTERN)
B(10,9,10,SEA_LANTERN)
B(11,9,10,STAINED_GLASS:6)
B(12,9,10,STAINED_GLASS:6)
B(13,9,10,STAINED_GLASS:9)
B(14,9,10,STAINED_GLASS:15)
B(5,9,11,STAINED_GLASS:15)
B(6,9,11,STAINED_GLASS:15)
B(7,9,11,STAINED_GLASS:9)
B(8,9,11,STAINED_GLASS:6)
B(9,9,11,STAINED_GLASS:6)
B(10,9,11,STAINED_GLASS:6)
B(11,9,11,STAINED_GLASS:6)
B(12,9,11,STAINED_GLASS:9)
B(13,9,11,STAINED_GLASS:15)
B(6,9,12,STAINED_GLASS:15)
B(7,9,12,STAINED_GLASS:15)
B(8,9,12,STAINED_GLASS:9)
B(9,9,12,STAINED_GLASS:6)
B(10,9,12,STAINED_GLASS:6)
B(11,9,12,STAINED_GLASS:9)
B(12,9,12,STAINED_GLASS:9)
B(13,9,12,STAINED_GLASS:9)
B(7,9,13,STAINED_GLASS:15)
B(8,9,13,STAINED_GLASS:15)
B(9,9,13,STAINED_GLASS:9)
B(10,9,13,STAINED_GLASS:9)
B(11,9,13,STAINED_GLASS:9)
B(12,9,13,STAINED_GLASS:9)
B(8,9,14,STAINED_GLASS:15)
B(9,9,14,STAINED_GLASS:15)
B(10,9,14,STAINED_GLASS:15)
B(8,10,3,STAINED_GLASS:9)
B(7,10,4,STAINED_GLASS:9)
B(8,10,4,STAINED_GLASS:9)
B(9,10,4,STAINED_GLASS:9)
B(6,10,5,STAINED_GLASS:9)
B(7,10,5,STAINED_GLASS:9)
B(8,10,5,STAINED_GLASS:9)
B(9,10,5,STAINED_GLASS:9)
B(10,10,5,STAINED_GLASS:9)
B(11,10,5,STAINED_GLASS:9)
B(5,10,6,STAINED_GLASS:15)
B(6,10,6,STAINED_GLASS:9)
B(7,10,6,STAINED_GLASS:9)
B(8,10,6,STAINED_GLASS:9)
B(9,10,6,STAINED_GLASS:6)
B(10,10,6,STAINED_GLASS:9)
B(11,10,6,STAINED_GLASS:15)
B(12,10,6,STAINED_GLASS:15)
B(4,10,7,STAINED_GLASS:15)
B(5,10,7,STAINED_GLASS:9)
B(6,10,7,STAINED_GLASS:15)
B(7,10,7,STAINED_GLASS:9)
B(8,10,7,STAINED_GLASS:6)
B(9,10,7,STAINED_GLASS:6)
B(10,10,7,STAINED_GLASS:6)
B(11,10,7,STAINED_GLASS:9)
B(12,10,7,STAINED_GLASS:15)
B(13,10,7,STAINED_GLASS:15)
B(3,10,8,STAINED_GLASS:15)
B(4,10,8,STAINED_GLASS:9)
B(5,10,8,STAINED_GLASS:15)
B(6,10,8,STAINED_GLASS:9)
B(7,10,8,STAINED_GLASS:6)
B(8,10,8,STAINED_GLASS:6)
B(9,10,8,SEA_LANTERN)
B(10,10,8,STAINED_GLASS:6)
B(11,10,8,STAINED_GLASS:6)
B(12,10,8,STAINED_GLASS:9)
B(13,10,8,STAINED_GLASS:15)
B(4,10,9,STAINED_GLASS:15)
B(5,10,9,STAINED_GLASS:9)
B(6,10,9,STAINED_GLASS:6)
B(7,10,9,STAINED_GLASS:6)
B(8,10,9,SEA_LANTERN)
B(9,10,9,SEA_LANTERN)
B(10,10,9,SEA_LANTERN)
B(11,10,9,STAINED_GLASS:6)
B(12,10,9,STAINED_GLASS:6)
B(13,10,9,STAINED_GLASS:15)
B(14,10,9,STAINED_GLASS:15)
B(5,10,10,STAINED_GLASS:15)
B(6,10,10,STAINED_GLASS:9)
B(7,10,10,STAINED_GLASS:6)
B(8,10,10,STAINED_GLASS:6)
B(9,10,10,SEA_LANTERN)
B(10,10,10,STAINED_GLASS:6)
B(11,10,10,STAINED_GLASS:6)
B(12,10,10,STAINED_GLASS:9)
B(13,10,10,STAINED_GLASS:15)
B(5,10,11,STAINED_GLASS:15)
B(6,10,11,STAINED_GLASS:15)
B(7,10,11,STAINED_GLASS:9)
B(8,10,11,STAINED_GLASS:6)
B(9,10,11,STAINED_GLASS:6)
B(10,10,11,STAINED_GLASS:6)
B(11,10,11,STAINED_GLASS:9)
B(12,10,11,STAINED_GLASS:9)
B(13,10,11,STAINED_GLASS:15)
B(6,10,12,STAINED_GLASS:15)
B(7,10,12,STAINED_GLASS:9)
B(8,10,12,STAINED_GLASS:9)
B(9,10,12,STAINED_GLASS:6)
B(10,10,12,STAINED_GLASS:9)
B(11,10,12,STAINED_GLASS:9)
B(12,10,12,STAINED_GLASS:9)
B(7,10,13,STAINED_GLASS:15)
B(8,10,13,STAINED_GLASS:15)
B(9,10,13,STAINED_GLASS:15)
B(10,10,13,STAINED_GLASS:9)
B(11,10,13,STAINED_GLASS:9)
B(9,10,14,STAINED_GLASS:15)
B(7,11,3,STAINED_GLASS:9)
B(8,11,3,STAINED_GLASS:9)
B(6,11,4,STAINED_GLASS:9)
B(7,11,4,STAINED_GLASS:9)
B(8,11,4,STAINED_GLASS:9)
B(9,11,4,STAINED_GLASS:9)
B(10,11,4,STAINED_GLASS:9)
B(5,11,5,STAINED_GLASS:9)
B(6,11,5,STAINED_GLASS:9)
B(7,11,5,STAINED_GLASS:9)
B(8,11,5,STAINED_GLASS:9)
B(9,11,5,STAINED_GLASS:9)
B(10,11,5,STAINED_GLASS:9)
B(11,11,5,STAINED_GLASS:9)
B(4,11,6,STAINED_GLASS:9)
B(5,11,6,STAINED_GLASS:9)
B(6,11,6,STAINED_GLASS:9)
B(7,11,6,STAINED_GLASS:9)
B(8,11,6,STAINED_GLASS:6)
B(9,11,6,STAINED_GLASS:6)
B(10,11,6,STAINED_GLASS:9)
B(11,11,6,STAINED_GLASS:9)
B(12,11,6,STAINED_GLASS:15)
B(3,11,7,STAINED_GLASS:15)
B(4,11,7,STAINED_GLASS:9)
B(5,11,7,STAINED_GLASS:9)
B(6,11,7,STAINED_GLASS:9)
B(7,11,7,STAINED_GLASS:6)
B(8,11,7,STAINED_GLASS:6)
B(9,11,7,STAINED_GLASS:6)
B(10,11,7,STAINED_GLASS:6)
B(11,11,7,STAINED_GLASS:9)
B(12,11,7,STAINED_GLASS:9)
B(13,11,7,STAINED_GLASS:15)
B(3,11,8,STAINED_GLASS:15)
B(4,11,8,STAINED_GLASS:15)
B(5,11,8,STAINED_GLASS:9)
B(6,11,8,STAINED_GLASS:6)
B(7,11,8,STAINED_GLASS:6)
B(8,11,8,SEA_LANTERN)
B(9,11,8,SEA_LANTERN)
B(10,11,8,STAINED_GLASS:6)
B(11,11,8,STAINED_GLASS:6)
B(12,11,8,STAINED_GLASS:9)
B(13,11,8,STAINED_GLASS:15)
B(4,11,9,STAINED_GLASS:15)
B(5,11,9,STAINED_GLASS:9)
B(6,11,9,STAINED_GLASS:6)
B(7,11,9,STAINED_GLASS:6)
B(8,11,9,SEA_LANTERN)
B(9,11,9,SEA_LANTERN)
B(10,11,9,STAINED_GLASS:6)
B(11,11,9,STAINED_GLASS:6)
B(12,11,9,STAINED_GLASS:9)
B(13,11,9,STAINED_GLASS:15)
B(4,11,10,STAINED_GLASS:15)
B(5,11,10,STAINED_GLASS:15)
B(6,11,10,STAINED_GLASS:9)
B(7,11,10,STAINED_GLASS:6)
B(8,11,10,STAINED_GLASS:6)
B(9,11,10,STAINED_GLASS:6)
B(10,11,10,STAINED_GLASS:6)
B(11,11,10,STAINED_GLASS:15)
B(12,11,10,STAINED_GLASS:15)
B(5,11,11,STAINED_GLASS:15)
B(6,11,11,STAINED_GLASS:15)
B(7,11,11,STAINED_GLASS:9)
B(8,11,11,STAINED_GLASS:6)
B(9,11,11,STAINED_GLASS:6)
B(10,11,11,STAINED_GLASS:9)
B(11,11,11,STAINED_GLASS:9)
B(12,11,11,STAINED_GLASS:9)
B(6,11,12,STAINED_GLASS:15)
B(7,11,12,STAINED_GLASS:9)
B(8,11,12,STAINED_GLASS:15)
B(9,11,12,STAINED_GLASS:15)
B(10,11,12,STAINED_GLASS:9)
B(11,11,12,STAINED_GLASS:9)
B(7,11,13,STAINED_GLASS:15)
B(8,11,13,STAINED_GLASS:15)
B(9,11,13,STAINED_GLASS:15)
B(7,12,2,STAINED_GLASS:15)
B(6,12,3,STAINED_GLASS:9)
B(7,12,3,STAINED_GLASS:9)
B(8,12,3,STAINED_GLASS:9)
B(5,12,4,STAINED_GLASS:9)
B(6,12,4,STAINED_GLASS:9)
B(7,12,4,STAINED_GLASS:9)
B(8,12,4,STAINED_GLASS:9)
B(9,12,4,STAINED_GLASS:9)
B(10,12,4,STAINED_GLASS:9)
B(4,12,5,STAINED_GLASS:9)
B(5,12,5,STAINED_GLASS:9)
B(6,12,5,STAINED_GLASS:9)
B(7,12,5,STAINED_GLASS:9)
B(8,12,5,STAINED_GLASS:6)
B(9,12,5,STAINED_GLASS:9)
B(10,12,5,STAINED_GLASS:9)
B(11,12,5,STAINED_GLASS:9)
B(3,12,6,STAINED_GLASS:9)
B(4,12,6,STAINED_GLASS:9)
B(5,12,6,STAINED_GLASS:9)
B(6,12,6,STAINED_GLASS:9)
B(7,12,6,STAINED_GLASS:6)
B(8,12,6,STAINED_GLASS:6)
B(9,12,6,STAINED_GLASS:6)
B(10,12,6,STAINED_GLASS:9)
B(11,12,6,STAINED_GLASS:9)
B(12,12,6,STAINED_GLASS:15)
B(2,12,7,STAINED_GLASS:9)
B(3,12,7,STAINED_GLASS:9)
B(4,12,7,STAINED_GLASS:9)
B(5,12,7,STAINED_GLASS:9)
B(6,12,7,STAINED_GLASS:6)
B(7,12,7,STAINED_GLASS:6)
B(8,12,7,SEA_LANTERN)
B(9,12,7,STAINED_GLASS:6)
B(10,12,7,STAINED_GLASS:6)
B(11,12,7,STAINED_GLASS:9)
B(12,12,7,STAINED_GLASS:15)
B(3,12,8,STAINED_GLASS:9)
B(4,12,8,STAINED_GLASS:9)
B(5,12,8,STAINED_GLASS:6)
B(6,12,8,STAINED_GLASS:6)
B(7,12,8,SEA_LANTERN)
B(8,12,8,SEA_LANTERN)
B(9,12,8,SEA_LANTERN)
B(10,12,8,STAINED_GLASS:6)
B(11,12,8,STAINED_GLASS:6)
B(12,12,8,STAINED_GLASS:9)
B(13,12,8,STAINED_GLASS:15)
B(4,12,9,STAINED_GLASS:15)
B(5,12,9,STAINED_GLASS:9)
B(6,12,9,STAINED_GLASS:6)
B(7,12,9,STAINED_GLASS:6)
B(8,12,9,SEA_LANTERN)
B(9,12,9,STAINED_GLASS:6)
B(10,12,9,STAINED_GLASS:6)
B(11,12,9,STAINED_GLASS:9)
B(12,12,9,STAINED_GLASS:15)
B(4,12,10,STAINED_GLASS:15)
B(5,12,10,STAINED_GLASS:15)
B(6,12,10,STAINED_GLASS:15)
B(7,12,10,STAINED_GLASS:6)
B(8,12,10,STAINED_GLASS:6)
B(9,12,10,STAINED_GLASS:6)
B(10,12,10,STAINED_GLASS:9)
B(11,12,10,STAINED_GLASS:9)
B(12,12,10,STAINED_GLASS:9)
B(5,12,11,STAINED_GLASS:15)
B(6,12,11,STAINED_GLASS:15)
B(7,12,11,STAINED_GLASS:9)
B(8,12,11,STAINED_GLASS:6)
B(9,12,11,STAINED_GLASS:15)
B(10,12,11,STAINED_GLASS:15)
B(11,12,11,STAINED_GLASS:9)
B(6,12,12,STAINED_GLASS:15)
B(7,12,12,STAINED_GLASS:15)
B(8,12,12,STAINED_GLASS:15)
B(9,12,12,STAINED_GLASS:15)
B(10,12,12,STAINED_GLASS:9)
B(8,12,13,STAINED_GLASS:15)
B(6,13,2,STAINED_GLASS:15)
B(7,13,2,STAINED_GLASS:15)
B(5,13,3,STAINED_GLASS:15)
B(6,13,3,STAINED_GLASS:9)
B(7,13,3,STAINED_GLASS:15)
B(8,13,3,STAINED_GLASS:9)
B(9,13,3,STAINED_GLASS:9)
B(4,13,4,STAINED_GLASS:9)
B(5,13,4,STAINED_GLASS:9)
B(6,13,4,STAINED_GLASS:15)
B(7,13,4,STAINED_GLASS:9)
B(8,13,4,STAINED_GLASS:9)
B(9,13,4,STAINED_GLASS:9)
B(10,13,4,STAINED_GLASS:9)
B(3,13,5,STAINED_GLASS:9)
B(4,13,5,STAINED_GLASS:9)
B(5,13,5,STAINED_GLASS:9)
B(6,13,5,STAINED_GLASS:9)
B(7,13,5,STAINED_GLASS:6)
B(8,13,5,STAINED_GLASS:6)
B(9,13,5,STAINED_GLASS:9)
B(10,13,5,STAINED_GLASS:9)
B(11,13,5,STAINED_GLASS:9)
B(2,13,6,STAINED_GLASS:9)
B(3,13,6,STAINED_GLASS:9)
B(4,13,6,STAINED_GLASS:9)
B(5,13,6,STAINED_GLASS:9)
B(6,13,6,STAINED_GLASS:6)
B(7,13,6,STAINED_GLASS:6)
B(8,13,6,STAINED_GLASS:6)
B(9,13,6,STAINED_GLASS:6)
B(10,13,6,STAINED_GLASS:9)
B(11,13,6,STAINED_GLASS:9)
B(12,13,6,STAINED_GLASS:15)
B(2,13,7,STAINED_GLASS:9)
B(3,13,7,STAINED_GLASS:9)
B(4,13,7,STAINED_GLASS:9)
B(5,13,7,STAINED_GLASS:6)
B(6,13,7,STAINED_GLASS:6)
B(7,13,7,SEA_LANTERN)
B(8,13,7,SEA_LANTERN)
B(9,13,7,STAINED_GLASS:6)
B(10,13,7,STAINED_GLASS:6)
B(11,13,7,STAINED_GLASS:9)
B(12,13,7,STAINED_GLASS:15)
B(3,13,8,STAINED_GLASS:9)
B(4,13,8,STAINED_GLASS:9)
B(5,13,8,STAINED_GLASS:6)
B(6,13,8,STAINED_GLASS:6)
B(7,13,8,SEA_LANTERN)
B(8,13,8,SEA_LANTERN)
B(9,13,8,STAINED_GLASS:6)
B(10,13,8,STAINED_GLASS:6)
B(11,13,8,STAINED_GLASS:9)
B(12,13,8,STAINED_GLASS:15)
B(3,13,9,STAINED_GLASS:15)
B(4,13,9,STAINED_GLASS:9)
B(5,13,9,STAINED_GLASS:9)
B(6,13,9,STAINED_GLASS:6)
B(7,13,9,STAINED_GLASS:6)
B(8,13,9,STAINED_GLASS:6)
B(9,13,9,STAINED_GLASS:6)
B(10,13,9,STAINED_GLASS:9)
B(11,13,9,STAINED_GLASS:9)
B(4,13,10,STAINED_GLASS:15)
B(5,13,10,STAINED_GLASS:15)
B(6,13,10,STAINED_GLASS:9)
B(7,13,10,STAINED_GLASS:6)
B(8,13,10,STAINED_GLASS:6)
B(9,13,10,STAINED_GLASS:15)
B(10,13,10,STAINED_GLASS:9)
B(11,13,10,STAINED_GLASS:9)
B(5,13,11,STAINED_GLASS:15)
B(6,13,11,STAINED_GLASS:15)
B(7,13,11,STAINED_GLASS:15)
B(8,13,11,STAINED_GLASS:15)
B(9,13,11,STAINED_GLASS:15)
B(10,13,11,STAINED_GLASS:9)
B(6,13,12,STAINED_GLASS:15)
B(7,13,12,STAINED_GLASS:15)
B(8,13,12,STAINED_GLASS:15)
B(6,14,1,STAINED_GLASS:15)
B(5,14,2,STAINED_GLASS:15)
B(6,14,2,STAINED_GLASS:9)
B(7,14,2,STAINED_GLASS:15)
B(4,14,3,STAINED_GLASS:15)
B(5,14,3,STAINED_GLASS:9)
B(6,14,3,STAINED_GLASS:15)
B(7,14,3,STAINED_GLASS:9)
B(8,14,3,STAINED_GLASS:9)
B(9,14,3,STAINED_GLASS:9)
B(3,14,4,STAINED_GLASS:9)
B(4,14,4,STAINED_GLASS:9)
B(5,14,4,STAINED_GLASS:15)
B(6,14,4,STAINED_GLASS:9)
B(7,14,4,STAINED_GLASS:6)
B(8,14,4,STAINED_GLASS:9)
B(9,14,4,STAINED_GLASS:9)
B(10,14,4,STAINED_GLASS:9)
B(2,14,5,STAINED_GLASS:9)
B(3,14,5,STAINED_GLASS:9)
B(4,14,5,STAINED_GLASS:9)
B(5,14,5,STAINED_GLASS:9)
B(6,14,5,STAINED_GLASS:6)
B(7,14,5,STAINED_GLASS:6)
B(8,14,5,STAINED_GLASS:6)
B(9,14,5,STAINED_GLASS:9)
B(10,14,5,STAINED_GLASS:9)
B(11,14,5,STAINED_GLASS:9)
B(1,14,6,STAINED_GLASS:15)
B(2,14,6,STAINED_GLASS:9)
B(3,14,6,STAINED_GLASS:9)
B(4,14,6,STAINED_GLASS:9)
B(5,14,6,STAINED_GLASS:6)
B(6,14,6,STAINED_GLASS:6)
B(7,14,6,SEA_LANTERN)
B(8,14,6,STAINED_GLASS:6)
B(9,14,6,STAINED_GLASS:6)
B(10,14,6,STAINED_GLASS:9)
B(11,14,6,STAINED_GLASS:15)
B(2,14,7,STAINED_GLASS:15)
B(3,14,7,STAINED_GLASS:9)
B(4,14,7,STAINED_GLASS:6)
B(5,14,7,STAINED_GLASS:6)
B(6,14,7,SEA_LANTERN)
B(7,14,7,SEA_LANTERN)
B(8,14,7,SEA_LANTERN)
B(9,14,7,STAINED_GLASS:6)
B(10,14,7,STAINED_GLASS:6)
B(11,14,7,STAINED_GLASS:9)
B(12,14,7,STAINED_GLASS:15)
B(3,14,8,STAINED_GLASS:9)
B(4,14,8,STAINED_GLASS:9)
B(5,14,8,STAINED_GLASS:6)
B(6,14,8,STAINED_GLASS:6)
B(7,14,8,SEA_LANTERN)
B(8,14,8,STAINED_GLASS:6)
B(9,14,8,STAINED_GLASS:6)
B(10,14,8,STAINED_GLASS:9)
B(11,14,8,STAINED_GLASS:9)
B(3,14,9,STAINED_GLASS:15)
B(4,14,9,STAINED_GLASS:15)
B(5,14,9,STAINED_GLASS:9)
B(6,14,9,STAINED_GLASS:6)
B(7,14,9,STAINED_GLASS:6)
B(8,14,9,STAINED_GLASS:6)
B(9,14,9,STAINED_GLASS:9)
B(10,14,9,STAINED_GLASS:9)
B(11,14,9,STAINED_GLASS:9)
B(4,14,10,STAINED_GLASS:15)
B(5,14,10,STAINED_GLASS:9)
B(6,14,10,STAINED_GLASS:9)
B(7,14,10,STAINED_GLASS:6)
B(8,14,10,STAINED_GLASS:9)
B(9,14,10,STAINED_GLASS:15)
B(10,14,10,STAINED_GLASS:9)
B(5,14,11,STAINED_GLASS:15)
B(6,14,11,STAINED_GLASS:15)
B(7,14,11,STAINED_GLASS:9)
B(8,14,11,STAINED_GLASS:15)
B(9,14,11,STAINED_GLASS:15)
B(7,14,12,STAINED_GLASS:15)
B(5,15,1,STAINED_GLASS:15)
B(6,15,1,STAINED_GLASS:15)
B(4,15,2,STAINED_GLASS:15)
B(5,15,2,STAINED_GLASS:9)
B(6,15,2,STAINED_GLASS:15)
B(7,15,2,STAINED_GLASS:15)
B(8,15,2,STAINED_GLASS:9)
B(3,15,3,STAINED_GLASS:15)
B(4,15,3,STAINED_GLASS:9)
B(5,15,3,STAINED_GLASS:15)
B(6,15,3,STAINED_GLASS:9)
B(7,15,3,STAINED_GLASS:9)
B(8,15,3,STAINED_GLASS:9)
B(9,15,3,STAINED_GLASS:9)
B(2,15,4,STAINED_GLASS:15)
B(3,15,4,STAINED_GLASS:9)
B(4,15,4,STAINED_GLASS:15)
B(5,15,4,STAINED_GLASS:9)
B(6,15,4,STAINED_GLASS:6)
B(7,15,4,STAINED_GLASS:6)
B(8,15,4,STAINED_GLASS:9)
B(9,15,4,STAINED_GLASS:9)
B(10,15,4,STAINED_GLASS:9)
B(1,15,5,STAINED_GLASS:15)
B(2,15,5,STAINED_GLASS:9)
B(3,15,5,STAINED_GLASS:15)
B(4,15,5,STAINED_GLASS:9)
B(5,15,5,STAINED_GLASS:6)
B(6,15,5,STAINED_GLASS:6)
B(7,15,5,STAINED_GLASS:6)
B(8,15,5,STAINED_GLASS:6)
B(9,15,5,STAINED_GLASS:9)
B(10,15,5,STAINED_GLASS:9)
B(11,15,5,STAINED_GLASS:15)
B(1,15,6,STAINED_GLASS:9)
B(2,15,6,STAINED_GLASS:15)
B(3,15,6,STAINED_GLASS:9)
B(4,15,6,STAINED_GLASS:6)
B(5,15,6,STAINED_GLASS:6)
B(6,15,6,SEA_LANTERN)
B(7,15,6,SEA_LANTERN)
B(8,15,6,STAINED_GLASS:6)
B(9,15,6,STAINED_GLASS:6)
B(10,15,6,STAINED_GLASS:9)
B(11,15,6,STAINED_GLASS:15)
B(2,15,7,STAINED_GLASS:9)
B(3,15,7,STAINED_GLASS:9)
B(4,15,7,STAINED_GLASS:6)
B(5,15,7,STAINED_GLASS:6)
B(6,15,7,SEA_LANTERN)
B(7,15,7,SEA_LANTERN)
B(8,15,7,STAINED_GLASS:6)
B(9,15,7,STAINED_GLASS:6)
B(10,15,7,STAINED_GLASS:9)
B(11,15,7,STAINED_GLASS:9)
B(2,15,8,STAINED_GLASS:9)
B(3,15,8,STAINED_GLASS:9)
B(4,15,8,STAINED_GLASS:9)
B(5,15,8,STAINED_GLASS:6)
B(6,15,8,STAINED_GLASS:6)
B(7,15,8,STAINED_GLASS:6)
B(8,15,8,STAINED_GLASS:6)
B(9,15,8,STAINED_GLASS:9)
B(10,15,8,STAINED_GLASS:9)
B(3,15,9,STAINED_GLASS:9)
B(4,15,9,STAINED_GLASS:9)
B(5,15,9,STAINED_GLASS:15)
B(6,15,9,STAINED_GLASS:6)
B(7,15,9,STAINED_GLASS:6)
B(8,15,9,STAINED_GLASS:9)
B(9,15,9,STAINED_GLASS:9)
B(10,15,9,STAINED_GLASS:9)
B(4,15,10,STAINED_GLASS:15)
B(5,15,10,STAINED_GLASS:15)
B(6,15,10,STAINED_GLASS:15)
B(7,15,10,STAINED_GLASS:9)
B(8,15,10,STAINED_GLASS:15)
B(9,15,10,STAINED_GLASS:9)
B(5,15,11,STAINED_GLASS:15)
B(6,15,11,STAINED_GLASS:15)
B(7,15,11,STAINED_GLASS:15)
B(5,16,0,STAINED_GLASS:15)
B(4,16,1,STAINED_GLASS:15)
B(5,16,1,STAINED_GLASS:9)
B(6,16,1,STAINED_GLASS:15)
B(3,16,2,STAINED_GLASS:15)
B(4,16,2,STAINED_GLASS:9)
B(5,16,2,STAINED_GLASS:15)
B(6,16,2,STAINED_GLASS:9)
B(7,16,2,STAINED_GLASS:15)
B(8,16,2,STAINED_GLASS:9)
B(2,16,3,STAINED_GLASS:15)
B(3,16,3,STAINED_GLASS:9)
B(4,16,3,STAINED_GLASS:15)
B(5,16,3,STAINED_GLASS:9)
B(6,16,3,STAINED_GLASS:6)
B(7,16,3,STAINED_GLASS:9)
B(8,16,3,STAINED_GLASS:9)
B(9,16,3,STAINED_GLASS:9)
B(1,16,4,STAINED_GLASS:15)
B(2,16,4,STAINED_GLASS:9)
B(3,16,4,STAINED_GLASS:15)
B(4,16,4,STAINED_GLASS:9)
B(5,16,4,STAINED_GLASS:6)
B(6,16,4,STAINED_GLASS:6)
B(7,16,4,STAINED_GLASS:6)
B(8,16,4,STAINED_GLASS:9)
B(9,16,4,STAINED_GLASS:9)
B(10,16,4,STAINED_GLASS:9)
B(0,16,5,STAINED_GLASS:15)
B(1,16,5,STAINED_GLASS:9)
B(2,16,5,STAINED_GLASS:15)
B(3,16,5,STAINED_GLASS:9)
B(4,16,5,STAINED_GLASS:6)
B(5,16,5,STAINED_GLASS:6)
B(6,16,5,SEA_LANTERN)
B(7,16,5,STAINED_GLASS:6)
B(8,16,5,STAINED_GLASS:6)
B(9,16,5,STAINED_GLASS:9)
B(10,16,5,STAINED_GLASS:15)
B(1,16,6,STAINED_GLASS:15)
B(2,16,6,STAINED_GLASS:9)
B(3,16,6,STAINED_GLASS:6)
B(4,16,6,STAINED_GLASS:6)
B(5,16,6,SEA_LANTERN)
B(6,16,6,SEA_LANTERN)
B(7,16,6,SEA_LANTERN)
B(8,16,6,STAINED_GLASS:6)
B(9,16,6,STAINED_GLASS:6)
B(10,16,6,STAINED_GLASS:9)
B(11,16,6,STAINED_GLASS:9)
B(2,16,7,STAINED_GLASS:9)
B(3,16,7,STAINED_GLASS:9)
B(4,16,7,STAINED_GLASS:6)
B(5,16,7,STAINED_GLASS:6)
B(6,16,7,SEA_LANTERN)
B(7,16,7,STAINED_GLASS:6)
B(8,16,7,STAINED_GLASS:6)
B(9,16,7,STAINED_GLASS:9)
B(10,16,7,STAINED_GLASS:9)
B(2,16,8,STAINED_GLASS:9)
B(3,16,8,STAINED_GLASS:9)
B(4,16,8,STAINED_GLASS:9)
B(5,16,8,STAINED_GLASS:6)
B(6,16,8,STAINED_GLASS:6)
B(7,16,8,STAINED_GLASS:6)
B(8,16,8,STAINED_GLASS:9)
B(9,16,8,STAINED_GLASS:9)
B(10,16,8,STAINED_GLASS:9)
B(3,16,9,STAINED_GLASS:9)
B(4,16,9,STAINED_GLASS:15)
B(5,16,9,STAINED_GLASS:15)
B(6,16,9,STAINED_GLASS:6)
B(7,16,9,STAINED_GLASS:9)
B(8,16,9,STAINED_GLASS:9)
B(9,16,9,STAINED_GLASS:9)
B(4,16,10,STAINED_GLASS:15)
B(5,16,10,STAINED_GLASS:15)
B(6,16,10,STAINED_GLASS:15)
B(7,16,10,STAINED_GLASS:15)
B(8,16,10,STAINED_GLASS:15)
B(6,16,11,STAINED_GLASS:15)
B(4,17,0,STAINED_GLASS:15)
B(5,17,0,STAINED_GLASS:15)
B(3,17,1,STAINED_GLASS:15)
B(4,17,1,STAINED_GLASS:9)
B(5,17,1,STAINED_GLASS:15)
B(6,17,1,STAINED_GLASS:15)
B(7,17,1,STAINED_GLASS:9)
B(2,17,2,STAINED_GLASS:15)
B(3,17,2,STAINED_GLASS:9)
B(4,17,2,STAINED_GLASS:15)
B(5,17,2,STAINED_GLASS:9)
B(6,17,2,STAINED_GLASS:9)
B(7,17,2,STAINED_GLASS:9)
B(8,17,2,STAINED_GLASS:9)
B(1,17,3,STAINED_GLASS:15)
B(2,17,3,STAINED_GLASS:9)
B(3,17,3,STAINED_GLASS:15)
B(4,17,3,STAINED_GLASS:9)
B(5,17,3,STAINED_GLASS:6)
B(6,17,3,STAINED_GLASS:6)
B(7,17,3,STAINED_GLASS:9)
B(8,17,3,STAINED_GLASS:9)
B(9,17,3,STAINED_GLASS:9)
B(0,17,4,STAINED_GLASS:15)
B(1,17,4,STAINED_GLASS:9)
B(2,17,4,STAINED_GLASS:15)
B(3,17,4,STAINED_GLASS:9)
B(4,17,4,STAINED_GLASS:6)
B(5,17,4,STAINED_GLASS:6)
B(6,17,4,STAINED_GLASS:6)
B(7,17,4,STAINED_GLASS:6)
B(8,17,4,STAINED_GLASS:9)
B(9,17,4,STAINED_GLASS:9)
B(10,17,4,STAINED_GLASS:9)
B(0,17,5,STAINED_GLASS:9)
B(1,17,5,STAINED_GLASS:15)
B(2,17,5,STAINED_GLASS:9)
B(3,17,5,STAINED_GLASS:6)
B(4,17,5,STAINED_GLASS:6)
B(5,17,5,SEA_LANTERN)
B(6,17,5,SEA_LANTERN)
B(7,17,5,STAINED_GLASS:6)
B(8,17,5,STAINED_GLASS:6)
B(9,17,5,STAINED_GLASS:9)
B(10,17,5,STAINED_GLASS:15)
B(1,17,6,STAINED_GLASS:9)
B(2,17,6,STAINED_GLASS:9)
B(3,17,6,STAINED_GLASS:6)
B(4,17,6,STAINED_GLASS:6)
B(5,17,6,SEA_LANTERN)
B(6,17,6,SEA_LANTERN)
B(7,17,6,STAINED_GLASS:6)
B(8,17,6,STAINED_GLASS:6)
B(9,17,6,STAINED_GLASS:15)
B(10,17,6,STAINED_GLASS:9)
B(1,17,7,STAINED_GLASS:9)
B(2,17,7,STAINED_GLASS:15)
B(3,17,7,STAINED_GLASS:9)
B(4,17,7,STAINED_GLASS:6)
B(5,17,7,STAINED_GLASS:6)
B(6,17,7,STAINED_GLASS:6)
B(7,17,7,STAINED_GLASS:6)
B(8,17,7,STAINED_GLASS:15)
B(9,17,7,STAINED_GLASS:9)
B(2,17,8,STAINED_GLASS:15)
B(3,17,8,STAINED_GLASS:15)
B(4,17,8,STAINED_GLASS:9)
B(5,17,8,STAINED_GLASS:6)
B(6,17,8,STAINED_GLASS:6)
B(7,17,8,STAINED_GLASS:9)
B(8,17,8,STAINED_GLASS:15)
B(9,17,8,STAINED_GLASS:15)
B(3,17,9,STAINED_GLASS:15)
B(4,17,9,STAINED_GLASS:15)
B(5,17,9,STAINED_GLASS:15)
B(6,17,9,STAINED_GLASS:9)
B(7,17,9,STAINED_GLASS:15)
B(8,17,9,STAINED_GLASS:15)
B(4,17,10,STAINED_GLASS:15)
B(5,17,10,STAINED_GLASS:15)
B(6,17,10,STAINED_GLASS:15)
B(4,18,0,STAINED_GLASS:15)
B(5,18,0,STAINED_GLASS:15)
B(3,18,1,STAINED_GLASS:15)
B(4,18,1,STAINED_GLASS:9)
B(5,18,1,STAINED_GLASS:15)
B(6,18,1,STAINED_GLASS:15)
B(7,18,1,STAINED_GLASS:9)
B(2,18,2,STAINED_GLASS:15)
B(3,18,2,STAINED_GLASS:9)
B(4,18,2,STAINED_GLASS:15)
B(5,18,2,STAINED_GLASS:9)
B(6,18,2,STAINED_GLASS:9)
B(7,18,2,STAINED_GLASS:9)
B(8,18,2,STAINED_GLASS:9)
B(1,18,3,STAINED_GLASS:15)
B(2,18,3,STAINED_GLASS:9)
B(3,18,3,STAINED_GLASS:15)
B(4,18,3,STAINED_GLASS:9)
B(5,18,3,STAINED_GLASS:6)
B(6,18,3,STAINED_GLASS:6)
B(7,18,3,STAINED_GLASS:9)
B(8,18,3,STAINED_GLASS:9)
B(9,18,3,STAINED_GLASS:9)
B(0,18,4,STAINED_GLASS:15)
B(1,18,4,STAINED_GLASS:9)
B(2,18,4,STAINED_GLASS:15)
B(3,18,4,STAINED_GLASS:9)
B(4,18,4,STAINED_GLASS:6)
B(5,18,4,SEA_LANTERN)
B(6,18,4,STAINED_GLASS:6)
B(7,18,4,STAINED_GLASS:6)
B(8,18,4,STAINED_GLASS:9)
B(9,18,4,STAINED_GLASS:9)
B(0,18,5,STAINED_GLASS:9)
B(1,18,5,STAINED_GLASS:15)
B(2,18,5,STAINED_GLASS:9)
B(3,18,5,STAINED_GLASS:6)
B(4,18,5,SEA_LANTERN)
B(5,18,5,SEA_LANTERN)
B(6,18,5,SEA_LANTERN)
B(7,18,5,STAINED_GLASS:6)
B(8,18,5,STAINED_GLASS:6)
B(9,18,5,STAINED_GLASS:9)
B(10,18,5,STAINED_GLASS:15)
B(1,18,6,STAINED_GLASS:9)
B(2,18,6,STAINED_GLASS:9)
B(3,18,6,STAINED_GLASS:6)
B(4,18,6,STAINED_GLASS:6)
B(5,18,6,SEA_LANTERN)
B(6,18,6,STAINED_GLASS:6)
B(7,18,6,STAINED_GLASS:6)
B(8,18,6,STAINED_GLASS:9)
B(9,18,6,STAINED_GLASS:15)
B(1,18,7,STAINED_GLASS:15)
B(2,18,7,STAINED_GLASS:15)
B(3,18,7,STAINED_GLASS:15)
B(4,18,7,STAINED_GLASS:6)
B(5,18,7,STAINED_GLASS:6)
B(6,18,7,STAINED_GLASS:6)
B(7,18,7,STAINED_GLASS:15)
B(8,18,7,STAINED_GLASS:15)
B(9,18,7,STAINED_GLASS:15)
B(2,18,8,STAINED_GLASS:15)
B(3,18,8,STAINED_GLASS:15)
B(4,18,8,STAINED_GLASS:15)
B(5,18,8,STAINED_GLASS:6)
B(6,18,8,STAINED_GLASS:9)
B(7,18,8,STAINED_GLASS:9)
B(8,18,8,STAINED_GLASS:15)
B(3,18,9,STAINED_GLASS:15)
B(4,18,9,STAINED_GLASS:15)
B(5,18,9,STAINED_GLASS:9)
B(6,18,9,STAINED_GLASS:15)
B(7,18,9,STAINED_GLASS:15)
B(5,18,10,STAINED_GLASS:15)
B(3,19,0,STAINED_GLASS:15)
B(4,19,0,STAINED_GLASS:15)
B(5,19,0,STAINED_GLASS:15)
B(2,19,1,STAINED_GLASS:15)
B(3,19,1,STAINED_GLASS:9)
B(4,19,1,STAINED_GLASS:15)
B(5,19,1,STAINED_GLASS:15)
B(6,19,1,STAINED_GLASS:15)
B(1,19,2,STAINED_GLASS:15)
B(2,19,2,STAINED_GLASS:9)
B(3,19,2,STAINED_GLASS:15)
B(4,19,2,STAINED_GLASS:9)
B(5,19,2,STAINED_GLASS:9)
B(6,19,2,STAINED_GLASS:9)
B(7,19,2,STAINED_GLASS:9)
B(0,19,3,STAINED_GLASS:15)
B(1,19,3,STAINED_GLASS:9)
B(2,19,3,STAINED_GLASS:15)
B(3,19,3,STAINED_GLASS:9)
B(4,19,3,STAINED_GLASS:6)
B(5,19,3,STAINED_GLASS:6)
B(6,19,3,STAINED_GLASS:6)
B(7,19,3,STAINED_GLASS:9)
B(8,19,3,STAINED_GLASS:9)
B(0,19,4,STAINED_GLASS:15)
B(1,19,4,STAINED_GLASS:15)
B(2,19,4,STAINED_GLASS:9)
B(3,19,4,STAINED_GLASS:6)
B(4,19,4,SEA_LANTERN)
B(5,19,4,SEA_LANTERN)
B(6,19,4,STAINED_GLASS:6)
B(7,19,4,STAINED_GLASS:6)
B(8,19,4,STAINED_GLASS:9)
B(9,19,4,STAINED_GLASS:9)
B(0,19,5,STAINED_GLASS:15)
B(1,19,5,STAINED_GLASS:15)
B(2,19,5,STAINED_GLASS:9)
B(3,19,5,STAINED_GLASS:6)
B(4,19,5,SEA_LANTERN)
B(5,19,5,SEA_LANTERN)
B(6,19,5,STAINED_GLASS:6)
B(7,19,5,STAINED_GLASS:6)
B(8,19,5,STAINED_GLASS:9)
B(9,19,5,STAINED_GLASS:9)
B(1,19,6,STAINED_GLASS:15)
B(2,19,6,STAINED_GLASS:9)
B(3,19,6,STAINED_GLASS:6)
B(4,19,6,STAINED_GLASS:6)
B(5,19,6,STAINED_GLASS:6)
B(6,19,6,STAINED_GLASS:6)
B(7,19,6,STAINED_GLASS:9)
B(8,19,6,STAINED_GLASS:9)
B(2,19,7,STAINED_GLASS:15)
B(3,19,7,STAINED_GLASS:15)
B(4,19,7,STAINED_GLASS:6)
B(5,19,7,STAINED_GLASS:6)
B(6,19,7,STAINED_GLASS:9)
B(7,19,7,STAINED_GLASS:15)
B(8,19,7,STAINED_GLASS:15)
B(3,19,8,STAINED_GLASS:15)
B(4,19,8,STAINED_GLASS:15)
B(5,19,8,STAINED_GLASS:15)
B(6,19,8,STAINED_GLASS:15)
B(7,19,8,STAINED_GLASS:15)
B(4,19,9,STAINED_GLASS:15)
B(5,19,9,STAINED_GLASS:15)
B(3,20,0,STAINED_GLASS:15)
B(4,20,0,STAINED_GLASS:15)
B(2,20,1,STAINED_GLASS:15)
B(3,20,1,STAINED_GLASS:9)
B(4,20,1,STAINED_GLASS:15)
B(5,20,1,STAINED_GLASS:15)
B(1,20,2,STAINED_GLASS:15)
B(2,20,2,STAINED_GLASS:9)
B(3,20,2,STAINED_GLASS:15)
B(4,20,2,STAINED_GLASS:9)
B(5,20,2,STAINED_GLASS:9)
B(6,20,2,STAINED_GLASS:9)
B(0,20,3,STAINED_GLASS:15)
B(1,20,3,STAINED_GLASS:9)
B(2,20,3,STAINED_GLASS:15)
B(3,20,3,STAINED_GLASS:9)
B(4,20,3,STAINED_GLASS:6)
B(5,20,3,STAINED_GLASS:6)
B(6,20,3,STAINED_GLASS:9)
B(7,20,3,STAINED_GLASS:9)
B(0,20,4,STAINED_GLASS:15)
B(1,20,4,STAINED_GLASS:15)
B(2,20,4,STAINED_GLASS:9)
B(3,20,4,STAINED_GLASS:6)
B(4,20,4,SEA_LANTERN)
B(5,20,4,STAINED_GLASS:6)
B(6,20,4,STAINED_GLASS:6)
B(7,20,4,STAINED_GLASS:9)
B(8,20,4,STAINED_GLASS:9)
B(1,20,5,STAINED_GLASS:15)
B(2,20,5,STAINED_GLASS:9)
B(3,20,5,STAINED_GLASS:6)
B(4,20,5,STAINED_GLASS:6)
B(5,20,5,STAINED_GLASS:6)
B(6,20,5,STAINED_GLASS:6)
B(7,20,5,STAINED_GLASS:9)
B(8,20,5,STAINED_GLASS:9)
B(2,20,6,STAINED_GLASS:15)
B(3,20,6,STAINED_GLASS:15)
B(4,20,6,STAINED_GLASS:6)
B(5,20,6,STAINED_GLASS:6)
B(6,20,6,STAINED_GLASS:9)
B(7,20,6,STAINED_GLASS:9)
B(8,20,6,STAINED_GLASS:9)
B(3,20,7,STAINED_GLASS:15)
B(4,20,7,STAINED_GLASS:15)
B(5,20,7,STAINED_GLASS:15)
B(6,20,7,STAINED_GLASS:9)
B(7,20,7,STAINED_GLASS:15)
B(4,20,8,STAINED_GLASS:15)
B(5,20,8,STAINED_GLASS:15)
B(6,20,8,STAINED_GLASS:15)
B(2,21,0,STAINED_GLASS:15)
B(3,21,0,STAINED_GLASS:15)
B(4,21,0,STAINED_GLASS:9)
B(1,21,1,STAINED_GLASS:15)
B(2,21,1,STAINED_GLASS:9)
B(3,21,1,STAINED_GLASS:15)
B(4,21,1,STAINED_GLASS:15)
B(5,21,1,STAINED_GLASS:9)
B(0,21,2,STAINED_GLASS:15)
B(1,21,2,STAINED_GLASS:9)
B(2,21,2,STAINED_GLASS:15)
B(3,21,2,STAINED_GLASS:9)
B(4,21,2,STAINED_GLASS:9)
B(5,21,2,STAINED_GLASS:9)
B(6,21,2,STAINED_GLASS:9)
B(0,21,3,STAINED_GLASS:15)
B(1,21,3,STAINED_GLASS:15)
B(2,21,3,STAINED_GLASS:9)
B(3,21,3,STAINED_GLASS:9)
B(4,21,3,STAINED_GLASS:6)
B(5,21,3,STAINED_GLASS:9)
B(6,21,3,STAINED_GLASS:9)
B(7,21,3,STAINED_GLASS:9)
B(0,21,4,STAINED_GLASS:15)
B(1,21,4,STAINED_GLASS:15)
B(2,21,4,STAINED_GLASS:9)
B(3,21,4,STAINED_GLASS:6)
B(4,21,4,STAINED_GLASS:6)
B(5,21,4,STAINED_GLASS:6)
B(6,21,4,STAINED_GLASS:9)
B(7,21,4,STAINED_GLASS:9)
B(1,21,5,STAINED_GLASS:15)
B(2,21,5,STAINED_GLASS:9)
B(3,21,5,STAINED_GLASS:9)
B(4,21,5,STAINED_GLASS:6)
B(5,21,5,STAINED_GLASS:6)
B(6,21,5,STAINED_GLASS:9)
B(7,21,5,STAINED_GLASS:9)
B(2,21,6,STAINED_GLASS:9)
B(3,21,6,STAINED_GLASS:15)
B(4,21,6,STAINED_GLASS:15)
B(5,21,6,STAINED_GLASS:15)
B(6,21,6,STAINED_GLASS:9)
B(7,21,6,STAINED_GLASS:9)
B(3,21,7,STAINED_GLASS:15)
B(4,21,7,STAINED_GLASS:15)
B(5,21,7,STAINED_GLASS:15)
B(6,21,7,STAINED_GLASS:15)
B(2,22,0,STAINED_GLASS:15)
B(3,22,0,STAINED_GLASS:15)
B(1,22,1,STAINED_GLASS:15)
B(2,22,1,STAINED_GLASS:9)
B(3,22,1,STAINED_GLASS:15)
B(4,22,1,STAINED_GLASS:15)
B(0,22,2,STAINED_GLASS:15)
B(1,22,2,STAINED_GLASS:9)
B(2,22,2,STAINED_GLASS:15)
B(3,22,2,STAINED_GLASS:9)
B(4,22,2,STAINED_GLASS:9)
B(5,22,2,STAINED_GLASS:9)
B(0,22,3,STAINED_GLASS:15)
B(1,22,3,STAINED_GLASS:15)
B(2,22,3,STAINED_GLASS:9)
B(3,22,3,STAINED_GLASS:6)
B(4,22,3,STAINED_GLASS:9)
B(5,22,3,STAINED_GLASS:9)
B(6,22,3,STAINED_GLASS:9)
B(1,22,4,STAINED_GLASS:15)
B(2,22,4,STAINED_GLASS:15)
B(3,22,4,STAINED_GLASS:9)
B(4,22,4,SEA_LANTERN)
B(5,22,4,STAINED_GLASS:9)
B(6,22,4,STAINED_GLASS:9)
B(2,22,5,STAINED_GLASS:15)
B(3,22,5,STAINED_GLASS:15)
B(4,22,5,STAINED_GLASS:9)
B(5,22,5,STAINED_GLASS:9)
B(6,22,5,STAINED_GLASS:9)
B(7,22,5,STAINED_GLASS:9)
B(3,22,6,STAINED_GLASS:15)
B(4,22,6,STAINED_GLASS:15)
B(5,22,6,STAINED_GLASS:9)
B(6,22,6,STAINED_GLASS:9)
B(5,22,7,STAINED_GLASS:15)
B(2,23,0,STAINED_GLASS:15)
B(3,23,0,STAINED_GLASS:9)
B(1,23,1,STAINED_GLASS:15)
B(2,23,1,STAINED_GLASS:9)
B(3,23,1,STAINED_GLASS:15)
B(4,23,1,STAINED_GLASS:9)
B(0,23,2,STAINED_GLASS:15)
B(1,23,2,STAINED_GLASS:9)
B(2,23,2,STAINED_GLASS:15)
B(3,23,2,STAINED_GLASS:9)
B(4,23,2,STAINED_GLASS:9)
B(5,23,2,STAINED_GLASS:9)
B(0,23,3,STAINED_GLASS:9)
B(1,23,3,STAINED_GLASS:9)
B(2,23,3,STAINED_GLASS:9)
B(3,23,3,STAINED_GLASS:6)
B(4,23,3,STAINED_GLASS:9)
B(5,23,3,STAINED_GLASS:9)
B(1,23,4,STAINED_GLASS:9)
B(2,23,4,STAINED_GLASS:15)
B(3,23,4,STAINED_GLASS:15)
B(4,23,4,STAINED_GLASS:9)
B(5,23,4,STAINED_GLASS:9)
B(6,23,4,STAINED_GLASS:9)
B(2,23,5,STAINED_GLASS:15)
B(3,23,5,STAINED_GLASS:9)
B(4,23,5,STAINED_GLASS:9)
B(5,23,5,STAINED_GLASS:9)
B(6,23,5,STAINED_GLASS:9)
B(4,23,6,STAINED_GLASS:9)
B(5,23,6,STAINED_GLASS:9)
B(1,24,0,STAINED_GLASS:15)
B(2,24,0,STAINED_GLASS:15)
B(0,24,1,STAINED_GLASS:15)
B(1,24,1,STAINED_GLASS:9)
B(2,24,1,STAINED_GLASS:15)
B(3,24,1,STAINED_GLASS:15)
B(0,24,2,STAINED_GLASS:9)
B(1,24,2,STAINED_GLASS:9)
B(2,24,2,STAINED_GLASS:9)
B(3,24,2,STAINED_GLASS:9)
B(4,24,2,STAINED_GLASS:9)
B(1,24,3,STAINED_GLASS:9)
B(2,24,3,STAINED_GLASS:9)
B(3,24,3,STAINED_GLASS:9)
B(4,24,3,STAINED_GLASS:9)
B(5,24,3,STAINED_GLASS:9)
B(2,24,4,STAINED_GLASS:9)
B(3,24,4,STAINED_GLASS:9)
B(4,24,4,STAINED_GLASS:9)
B(5,24,4,STAINED_GLASS:9)
B(3,24,5,STAINED_GLASS:9)
B(4,24,5,STAINED_GLASS:9)
B(1,25,0,STAINED_GLASS:15)
B(2,25,0,STAINED_GLASS:9)
B(0,25,1,STAINED_GLASS:15)
B(1,25,1,STAINED_GLASS:9)
B(2,25,1,STAINED_GLASS:15)
B(3,25,1,STAINED_GLASS:9)
B(0,25,2,STAINED_GLASS:15)
B(1,25,2,STAINED_GLASS:9)
B(2,25,2,STAINED_GLASS:9)
B(3,25,2,STAINED_GLASS:9)
B(4,25,2,STAINED_GLASS:9)
B(1,25,3,STAINED_GLASS:9)
B(2,25,3,STAINED_GLASS:9)
B(3,25,3,STAINED_GLASS:9)
B(4,25,3,STAINED_GLASS:9)
B(2,25,4,STAINED_GLASS:9)
B(3,25,4,STAINED_GLASS:9)
B(0,26,0,STAINED_GLASS:15)
B(1,26,0,STAINED_GLASS:15)
B(0,26,1,STAINED_GLASS:15)
B(1,26,1,STAINED_GLASS:15)
B(2,26,1,STAINED_GLASS:15)
B(1,26,2,STAINED_GLASS:15)
B(2,26,2,STAINED_GLASS:9)
B(3,26,2,STAINED_GLASS:9)
B(2,26,3,STAINED_GLASS:15)
B(0,27,0,STAINED_GLASS:15)
B(1,27,0,STAINED_GLASS:15)
B(0,27,1,STAINED_GLASS:15)
B(1,27,1,STAINED_GLASS:15)
B(2,27,1,STAINED_GLASS:15)
B(1,27,2,STAINED_GLASS:15)
B(2,27,2,STAINED_GLASS:15)
B(0,28,0,STAINED_GLASS:15)
B(1,28,1,STAINED_GLASS:15)

#######################################################################
# +-----------------------------------------------------------------+ #
# |                             Branches                            | #
# +-----------------------------------------------------------------+ #
#######################################################################

BR(0,0,16,true,SPIKE-FAT-SMALL-01_0x1,NORTH,100,0)
BR(16,0,0,true,SPIKE-FAT-SMALL-01_1x0,NORTH,100,0)
