
#######################################################################
# +-----------------------------------------------------------------+ #
# |                            BO3 object                           | #
# +-----------------------------------------------------------------+ #
#######################################################################

Author: BO3 BulkEdit (by LanToaster)

Description: This Object was Created with BO3_BulkEdit

Version: 3

SettingsMode: WriteWithoutComments


#######################################################################
# +-----------------------------------------------------------------+ #
# |                          Main settings                          | #
# +-----------------------------------------------------------------+ #
#######################################################################

Tree: false

Frequency: 1

Rarity: 100.0

RotateRandomly: false

SpawnHeight: randomY

SpawnHeightOffset: 0

SpawnHeightVariance: 0

##############################
# Height Limits for the BO3. #
##############################

MinHeight: 82

MaxHeight: 82

######################
# Extrusion settings #
######################

ExtrudeMode: None

ExtrudeThroughBlocks: minecraft:air

MaxBranchDepth: 10


#######################################################################
# +-----------------------------------------------------------------+ #
# |                      Source block settings                      | #
# +-----------------------------------------------------------------+ #
#######################################################################

SourceBlocks: otg:air

MaxPercentageOutsideSourceBlock: 100

OutsideSourceBlock: placeAnyway

DoReplaceBlocks: true

IsOTGPlus: false


#######################################################################
# +-----------------------------------------------------------------+ #
# |                              Blocks                             | #
# +-----------------------------------------------------------------+ #
#######################################################################

B(-7,0,1,minecraft:stone_brick_slab)
B(-7,0,2,minecraft:stone_brick_stairs)
B(-7,0,3,minecraft:stone_brick_slab[type=double,waterlogged=false])
B(-7,1,3,minecraft:stone_brick_slab)
B(-7,3,4,minecraft:stone_brick_slab[type=double,waterlogged=false])
B(-7,3,6,minecraft:grass_block)
B(-7,2,7,minecraft:stone_brick_slab[type=top,waterlogged=false])
B(-7,3,7,minecraft:grass_block)
B(-7,6,8,minecraft:stone_brick_slab)
B(-6,0,1,minecraft:stone_brick_slab)
B(-6,0,2,minecraft:stone_brick_stairs)
B(-6,3,6,minecraft:dirt)
B(-6,2,7,minecraft:stone_brick_slab[type=top,waterlogged=false])
B(-6,3,7,minecraft:grass_block)
B(-6,6,8,minecraft:stone_brick_slab)
B(-5,0,1,minecraft:stone_brick_stairs[facing=south,half=bottom,shape=straight,waterlogged=false])
B(-5,0,2,minecraft:stone_brick_stairs)
B(-5,1,2,minecraft:stone_brick_stairs[facing=south,half=bottom,shape=straight,waterlogged=false])
B(-5,2,3,minecraft:chiseled_stone_bricks)
B(-5,3,3,minecraft:stone_brick_stairs[facing=south,half=bottom,shape=straight,waterlogged=false])
B(-5,4,5,minecraft:stone_brick_slab)
B(-5,3,6,minecraft:grass_block)
B(-5,2,7,minecraft:stone_brick_slab[type=top,waterlogged=false])
B(-5,3,7,minecraft:grass_block)
B(-5,4,7,minecraft:stone_brick_stairs[facing=south,half=bottom,shape=straight,waterlogged=false])
B(-5,6,8,minecraft:stone_brick_stairs[facing=south,half=bottom,shape=straight,waterlogged=false])
B(-4,0,1,minecraft:stone_brick_slab)
B(-4,0,2,minecraft:stone_brick_stairs)
B(-4,3,4,minecraft:stone_brick_slab)
B(-4,3,6,minecraft:grass_block)
B(-4,0,7,minecraft:stone_brick_slab)
B(-4,2,7,minecraft:stone_brick_slab[type=top,waterlogged=false])
B(-4,3,7,minecraft:grass_block)
B(-4,0,8,minecraft:stone_brick_slab)
B(-4,6,8,minecraft:stone_brick_slab)
B(-3,0,1,minecraft:stone_brick_stairs[facing=south,half=bottom,shape=straight,waterlogged=false])
B(-3,0,2,minecraft:stone_brick_stairs)
B(-3,3,4,minecraft:stone_brick_slab)
B(-3,4,5,minecraft:jungle_leaves[distance=7,persistent=true])
B(-3,3,6,minecraft:grass_block)
B(-3,4,6,minecraft:jungle_leaves[distance=7,persistent=true])
B(-3,2,7,minecraft:stone_brick_slab[type=top,waterlogged=false])
B(-3,3,7,minecraft:grass_block)
B(-2,0,1,minecraft:stone_brick_stairs[facing=south,half=bottom,shape=straight,waterlogged=false])
B(-2,0,2,minecraft:stone_brick_stairs)
B(-2,1,2,minecraft:stone_brick_stairs[facing=south,half=bottom,shape=straight,waterlogged=false])
B(-2,2,3,minecraft:chiseled_stone_bricks)
B(-2,3,3,minecraft:jungle_leaves[distance=7,persistent=true])
B(-2,3,4,minecraft:jungle_leaves[distance=7,persistent=true])
B(-2,4,4,minecraft:jungle_leaves[distance=7,persistent=true])
B(-2,3,6,minecraft:grass_block)
B(-2,4,6,minecraft:jungle_leaves[distance=7,persistent=true])
B(-2,1,7,minecraft:stone_brick_slab)
B(-2,2,7,minecraft:stone_brick_slab[type=top,waterlogged=false])
B(-2,3,7,minecraft:grass_block)
B(-2,4,7,minecraft:jungle_leaves[distance=7,persistent=true])
B(-2,5,7,minecraft:jungle_leaves[distance=7,persistent=true])
B(-2,0,8,minecraft:water)
B(-2,6,8,minecraft:jungle_leaves[distance=7,persistent=true])
B(-1,0,1,minecraft:stone_brick_stairs[facing=south,half=bottom,shape=straight,waterlogged=false])
B(-1,0,2,minecraft:stone_brick_stairs)
B(-1,1,3,minecraft:jungle_leaves[distance=7,persistent=true])
B(-1,2,3,minecraft:jungle_leaves[distance=7,persistent=true])
B(-1,3,4,minecraft:stone_brick_slab)
B(-1,3,6,minecraft:grass_block)
B(-1,1,7,minecraft:stone_brick_slab)
B(-1,2,7,minecraft:stone_brick_slab[type=top,waterlogged=false])
B(-1,3,7,minecraft:grass_block)
B(-1,0,8,minecraft:water)
B(-1,6,8,minecraft:stone_brick_slab)
B(0,0,1,minecraft:jungle_leaves[distance=7,persistent=true])
B(0,1,1,minecraft:jungle_leaves[distance=7,persistent=true])
B(0,0,2,minecraft:stone_brick_stairs)
B(0,1,2,minecraft:jungle_leaves[distance=7,persistent=true])
B(0,1,3,minecraft:jungle_leaves[distance=7,persistent=true])
B(0,3,4,minecraft:stone_brick_slab)
B(0,3,6,minecraft:grass_block)
B(0,1,7,minecraft:stone_brick_slab)
B(0,2,7,minecraft:stone_brick_slab[type=top,waterlogged=false])
B(0,3,7,minecraft:grass_block)
B(0,0,8,minecraft:water)
B(0,6,8,minecraft:stone_brick_slab)
B(1,-1,1,minecraft:jungle_leaves[distance=7,persistent=true])
B(1,0,1,minecraft:jungle_leaves[distance=7,persistent=true])
B(1,0,2,minecraft:stone_brick_stairs)
B(1,1,2,minecraft:stone_brick_stairs[facing=south,half=bottom,shape=straight,waterlogged=false])
B(1,2,3,minecraft:chiseled_stone_bricks)
B(1,3,3,minecraft:stone_brick_stairs[facing=south,half=bottom,shape=straight,waterlogged=false])
B(1,3,6,minecraft:grass_block)
B(1,4,6,minecraft:jungle_leaves[distance=7,persistent=true])
B(1,1,7,minecraft:stone_brick_slab)
B(1,2,7,minecraft:stone_brick_slab[type=top,waterlogged=false])
B(1,3,7,minecraft:grass_block)
B(1,4,7,minecraft:stone_brick_stairs[facing=south,half=bottom,shape=straight,waterlogged=false])
B(1,5,7,minecraft:jungle_leaves[distance=7,persistent=true])
B(1,0,8,minecraft:water)
B(1,6,8,minecraft:stone_brick_stairs[facing=south,half=bottom,shape=straight,waterlogged=false])
B(2,0,1,minecraft:stone_brick_stairs[facing=south,half=bottom,shape=straight,waterlogged=false])
B(2,0,2,minecraft:stone_brick_stairs)
B(2,3,4,minecraft:stone_brick_slab[type=double,waterlogged=false])
B(2,3,6,minecraft:grass_block)
B(2,4,6,minecraft:jungle_leaves[distance=7,persistent=true])
B(2,2,7,minecraft:stone_brick_slab[type=top,waterlogged=false])
B(2,3,7,minecraft:grass_block)
B(3,0,1,minecraft:stone_brick_slab)
B(3,0,2,minecraft:stone_brick_stairs)
B(3,3,4,minecraft:stone_brick_slab)
B(3,3,6,minecraft:grass_block)
B(3,0,7,minecraft:stone_brick_slab)
B(3,2,7,minecraft:stone_brick_slab[type=top,waterlogged=false])
B(3,3,7,minecraft:grass_block)
B(3,0,8,minecraft:stone_brick_slab)
B(4,0,1,minecraft:stone_brick_slab)
B(4,0,2,minecraft:stone_brick_stairs)
B(4,1,2,minecraft:stone_brick_stairs[facing=south,half=bottom,shape=straight,waterlogged=false])
B(4,2,3,minecraft:chiseled_stone_bricks)
B(4,3,3,minecraft:stone_brick_stairs[facing=south,half=bottom,shape=straight,waterlogged=false])
B(4,4,4,minecraft:stone_brick_slab)
B(4,3,6,minecraft:grass_block)
B(4,2,7,minecraft:stone_brick_slab[type=top,waterlogged=false])
B(4,3,7,minecraft:grass_block)
B(4,4,7,minecraft:stone_brick_stairs[facing=south,half=bottom,shape=straight,waterlogged=false])
B(4,6,8,minecraft:stone_brick_stairs[facing=south,half=bottom,shape=straight,waterlogged=false])
B(5,0,1,minecraft:stone_brick_stairs[facing=south,half=bottom,shape=straight,waterlogged=false])
B(5,0,2,minecraft:stone_brick_stairs)
B(5,1,3,minecraft:jungle_leaves[distance=7,persistent=true])
B(5,3,4,minecraft:stone_brick_slab)
B(5,3,6,minecraft:dirt)
B(5,2,7,minecraft:stone_brick_slab[type=top,waterlogged=false])
B(5,3,7,minecraft:grass_block)
B(6,0,1,minecraft:stone_brick_stairs[facing=south,half=bottom,shape=straight,waterlogged=false])
B(6,0,2,minecraft:stone_brick_stairs)
B(6,3,4,minecraft:stone_brick_slab)
B(6,3,5,minecraft:stone_brick_slab[type=double,waterlogged=false])
B(6,3,6,minecraft:grass_block)
B(6,2,7,minecraft:stone_brick_slab[type=top,waterlogged=false])
B(6,3,7,minecraft:grass_block)
B(6,6,8,minecraft:jungle_leaves[distance=7,persistent=true])
B(7,0,1,minecraft:stone_brick_stairs[facing=south,half=bottom,shape=straight,waterlogged=false])
B(7,0,2,minecraft:stone_brick_stairs)
B(7,1,2,minecraft:stone_brick_stairs[facing=south,half=bottom,shape=straight,waterlogged=false])
B(7,2,3,minecraft:chiseled_stone_bricks)
B(7,3,3,minecraft:stone_brick_stairs[facing=south,half=bottom,shape=straight,waterlogged=false])
B(7,3,4,minecraft:stone_brick_slab)
B(7,3,5,minecraft:stone_brick_slab[type=double,waterlogged=false])
B(7,3,6,minecraft:grass_block)
B(7,2,7,minecraft:stone_brick_slab[type=top,waterlogged=false])
B(7,3,7,minecraft:grass_block)
B(7,4,7,minecraft:stone_brick_stairs[facing=south,half=bottom,shape=straight,waterlogged=false])
B(7,6,8,minecraft:jungle_leaves[distance=7,persistent=true])
B(8,0,1,minecraft:stone_brick_stairs[facing=south,half=bottom,shape=straight,waterlogged=false])
B(8,0,2,minecraft:stone_brick_stairs)
B(8,1,2,minecraft:jungle_leaves[distance=7,persistent=true])
B(8,1,3,minecraft:jungle_leaves[distance=7,persistent=true])
B(8,3,4,minecraft:stone_brick_slab)
B(8,3,6,minecraft:grass_block)
B(8,0,7,minecraft:cobblestone_wall)
B(8,1,7,minecraft:torch)
B(8,2,7,minecraft:stone_brick_slab[type=top,waterlogged=false])
B(8,3,7,minecraft:grass_block)
B(8,4,7,minecraft:jungle_leaves[distance=7,persistent=true])
B(8,2,8,minecraft:stone_brick_slab[type=top,waterlogged=false])
B(8,3,8,minecraft:grass_block)
B(8,4,8,minecraft:jungle_leaves[distance=7,persistent=true])
B(8,5,8,minecraft:jungle_leaves[distance=7,persistent=true])
B(8,6,8,minecraft:jungle_leaves[distance=7,persistent=true])
RB(-7,-1,1,minecraft:mossy_stone_bricks,10,minecraft:cracked_stone_bricks,10,minecraft:cobblestone,10,minecraft:mossy_cobblestone,10,minecraft:stone_bricks,100)
RB(-6,-1,1,minecraft:mossy_stone_bricks,10,minecraft:cracked_stone_bricks,10,minecraft:cobblestone,10,minecraft:mossy_cobblestone,10,minecraft:stone_bricks,100)
RB(-5,-1,1,minecraft:mossy_stone_bricks,10,minecraft:cracked_stone_bricks,10,minecraft:cobblestone,10,minecraft:mossy_cobblestone,10,minecraft:stone_bricks,100)
RB(-4,-1,1,minecraft:mossy_stone_bricks,10,minecraft:cracked_stone_bricks,10,minecraft:cobblestone,10,minecraft:mossy_cobblestone,10,minecraft:stone_bricks,100)
RB(-3,-1,1,minecraft:mossy_stone_bricks,10,minecraft:cracked_stone_bricks,10,minecraft:cobblestone,10,minecraft:mossy_cobblestone,10,minecraft:stone_bricks,100)
RB(-2,-1,1,minecraft:mossy_stone_bricks,10,minecraft:cracked_stone_bricks,10,minecraft:cobblestone,10,minecraft:mossy_cobblestone,10,minecraft:stone_bricks,100)
RB(-1,-1,1,minecraft:mossy_stone_bricks,10,minecraft:cracked_stone_bricks,10,minecraft:cobblestone,10,minecraft:mossy_cobblestone,10,minecraft:stone_bricks,100)
RB(0,-1,1,minecraft:mossy_stone_bricks,10,minecraft:cracked_stone_bricks,10,minecraft:cobblestone,10,minecraft:mossy_cobblestone,10,minecraft:stone_bricks,100)
RB(2,-1,1,minecraft:mossy_stone_bricks,10,minecraft:cracked_stone_bricks,10,minecraft:cobblestone,10,minecraft:mossy_cobblestone,10,minecraft:stone_bricks,100)
RB(3,-1,1,minecraft:mossy_stone_bricks,10,minecraft:cracked_stone_bricks,10,minecraft:cobblestone,10,minecraft:mossy_cobblestone,10,minecraft:stone_bricks,100)
RB(4,-1,1,minecraft:mossy_stone_bricks,10,minecraft:cracked_stone_bricks,10,minecraft:cobblestone,10,minecraft:mossy_cobblestone,10,minecraft:stone_bricks,100)
RB(5,-1,1,minecraft:mossy_stone_bricks,10,minecraft:cracked_stone_bricks,10,minecraft:cobblestone,10,minecraft:mossy_cobblestone,10,minecraft:stone_bricks,100)
RB(6,-1,1,minecraft:mossy_stone_bricks,10,minecraft:cracked_stone_bricks,10,minecraft:cobblestone,10,minecraft:mossy_cobblestone,10,minecraft:stone_bricks,100)
RB(7,-1,1,minecraft:mossy_stone_bricks,10,minecraft:cracked_stone_bricks,10,minecraft:cobblestone,10,minecraft:mossy_cobblestone,10,minecraft:stone_bricks,100)
RB(8,-1,1,minecraft:mossy_stone_bricks,10,minecraft:cracked_stone_bricks,10,minecraft:cobblestone,10,minecraft:mossy_cobblestone,10,minecraft:stone_bricks,100)
RB(-7,-1,2,minecraft:mossy_stone_bricks,10,minecraft:cracked_stone_bricks,10,minecraft:cobblestone,10,minecraft:mossy_cobblestone,10,minecraft:stone_bricks,100)
RB(-6,-1,2,minecraft:mossy_stone_bricks,10,minecraft:cracked_stone_bricks,10,minecraft:cobblestone,10,minecraft:mossy_cobblestone,10,minecraft:stone_bricks,100)
RB(-5,-1,2,minecraft:mossy_stone_bricks,10,minecraft:cracked_stone_bricks,10,minecraft:cobblestone,10,minecraft:mossy_cobblestone,10,minecraft:stone_bricks,100)
RB(-4,-1,2,minecraft:mossy_stone_bricks,10,minecraft:cracked_stone_bricks,10,minecraft:cobblestone,10,minecraft:mossy_cobblestone,10,minecraft:stone_bricks,100)
RB(-3,-1,2,minecraft:mossy_stone_bricks,10,minecraft:cracked_stone_bricks,10,minecraft:cobblestone,10,minecraft:mossy_cobblestone,10,minecraft:stone_bricks,100)
RB(-2,-1,2,minecraft:mossy_stone_bricks,10,minecraft:cracked_stone_bricks,10,minecraft:cobblestone,10,minecraft:mossy_cobblestone,10,minecraft:stone_bricks,100)
RB(-1,-1,2,minecraft:mossy_stone_bricks,10,minecraft:cracked_stone_bricks,10,minecraft:cobblestone,10,minecraft:mossy_cobblestone,10,minecraft:stone_bricks,100)
RB(0,-1,2,minecraft:mossy_stone_bricks,10,minecraft:cracked_stone_bricks,10,minecraft:cobblestone,10,minecraft:mossy_cobblestone,10,minecraft:stone_bricks,100)
RB(1,-1,2,minecraft:mossy_stone_bricks,10,minecraft:cracked_stone_bricks,10,minecraft:cobblestone,10,minecraft:mossy_cobblestone,10,minecraft:stone_bricks,100)
RB(2,-1,2,minecraft:mossy_stone_bricks,10,minecraft:cracked_stone_bricks,10,minecraft:cobblestone,10,minecraft:mossy_cobblestone,10,minecraft:stone_bricks,100)
RB(3,-1,2,minecraft:mossy_stone_bricks,10,minecraft:cracked_stone_bricks,10,minecraft:cobblestone,10,minecraft:mossy_cobblestone,10,minecraft:stone_bricks,100)
RB(4,-1,2,minecraft:mossy_stone_bricks,10,minecraft:cracked_stone_bricks,10,minecraft:cobblestone,10,minecraft:mossy_cobblestone,10,minecraft:stone_bricks,100)
RB(5,-1,2,minecraft:mossy_stone_bricks,10,minecraft:cracked_stone_bricks,10,minecraft:cobblestone,10,minecraft:mossy_cobblestone,10,minecraft:stone_bricks,100)
RB(6,-1,2,minecraft:mossy_stone_bricks,10,minecraft:cracked_stone_bricks,10,minecraft:cobblestone,10,minecraft:mossy_cobblestone,10,minecraft:stone_bricks,100)
RB(7,-1,2,minecraft:mossy_stone_bricks,10,minecraft:cracked_stone_bricks,10,minecraft:cobblestone,10,minecraft:mossy_cobblestone,10,minecraft:stone_bricks,100)
RB(8,-1,2,minecraft:mossy_stone_bricks,10,minecraft:cracked_stone_bricks,10,minecraft:cobblestone,10,minecraft:mossy_cobblestone,10,minecraft:stone_bricks,100)
RB(-7,-1,3,minecraft:mossy_stone_bricks,10,minecraft:cracked_stone_bricks,10,minecraft:cobblestone,10,minecraft:mossy_cobblestone,10,minecraft:stone_bricks,100)
RB(-6,-1,3,minecraft:mossy_stone_bricks,10,minecraft:cracked_stone_bricks,10,minecraft:cobblestone,10,minecraft:mossy_cobblestone,10,minecraft:stone_bricks,100)
RB(-5,-1,3,minecraft:mossy_stone_bricks,10,minecraft:cracked_stone_bricks,10,minecraft:cobblestone,10,minecraft:mossy_cobblestone,10,minecraft:stone_bricks,100)
RB(-4,-1,3,minecraft:mossy_stone_bricks,10,minecraft:cracked_stone_bricks,10,minecraft:cobblestone,10,minecraft:mossy_cobblestone,10,minecraft:stone_bricks,100)
RB(-3,-1,3,minecraft:mossy_stone_bricks,10,minecraft:cracked_stone_bricks,10,minecraft:cobblestone,10,minecraft:mossy_cobblestone,10,minecraft:stone_bricks,100)
RB(-2,-1,3,minecraft:mossy_stone_bricks,10,minecraft:cracked_stone_bricks,10,minecraft:cobblestone,10,minecraft:mossy_cobblestone,10,minecraft:stone_bricks,100)
RB(-1,-1,3,minecraft:mossy_stone_bricks,10,minecraft:cracked_stone_bricks,10,minecraft:cobblestone,10,minecraft:mossy_cobblestone,10,minecraft:stone_bricks,100)
RB(0,-1,3,minecraft:mossy_stone_bricks,10,minecraft:cracked_stone_bricks,10,minecraft:cobblestone,10,minecraft:mossy_cobblestone,10,minecraft:stone_bricks,100)
RB(1,-1,3,minecraft:mossy_stone_bricks,10,minecraft:cracked_stone_bricks,10,minecraft:cobblestone,10,minecraft:mossy_cobblestone,10,minecraft:stone_bricks,100)
RB(2,-1,3,minecraft:mossy_stone_bricks,10,minecraft:cracked_stone_bricks,10,minecraft:cobblestone,10,minecraft:mossy_cobblestone,10,minecraft:stone_bricks,100)
RB(3,-1,3,minecraft:mossy_stone_bricks,10,minecraft:cracked_stone_bricks,10,minecraft:cobblestone,10,minecraft:mossy_cobblestone,10,minecraft:stone_bricks,100)
RB(4,-1,3,minecraft:mossy_stone_bricks,10,minecraft:cracked_stone_bricks,10,minecraft:cobblestone,10,minecraft:mossy_cobblestone,10,minecraft:stone_bricks,100)
RB(5,-1,3,minecraft:mossy_stone_bricks,10,minecraft:cracked_stone_bricks,10,minecraft:cobblestone,10,minecraft:mossy_cobblestone,10,minecraft:stone_bricks,100)
RB(6,-1,3,minecraft:mossy_stone_bricks,10,minecraft:cracked_stone_bricks,10,minecraft:cobblestone,10,minecraft:mossy_cobblestone,10,minecraft:stone_bricks,100)
RB(7,-1,3,minecraft:mossy_stone_bricks,10,minecraft:cracked_stone_bricks,10,minecraft:cobblestone,10,minecraft:mossy_cobblestone,10,minecraft:stone_bricks,100)
RB(8,-1,3,minecraft:mossy_stone_bricks,10,minecraft:cracked_stone_bricks,10,minecraft:cobblestone,10,minecraft:mossy_cobblestone,10,minecraft:stone_bricks,100)
RB(-7,-1,4,minecraft:mossy_stone_bricks,10,minecraft:cracked_stone_bricks,10,minecraft:cobblestone,10,minecraft:mossy_cobblestone,10,minecraft:stone_bricks,100)
RB(-6,-1,4,minecraft:mossy_stone_bricks,10,minecraft:cracked_stone_bricks,10,minecraft:cobblestone,10,minecraft:mossy_cobblestone,10,minecraft:stone_bricks,100)
RB(-5,-1,4,minecraft:mossy_stone_bricks,10,minecraft:cracked_stone_bricks,10,minecraft:cobblestone,10,minecraft:mossy_cobblestone,10,minecraft:stone_bricks,100)
RB(-4,-1,4,minecraft:mossy_stone_bricks,10,minecraft:cracked_stone_bricks,10,minecraft:cobblestone,10,minecraft:mossy_cobblestone,10,minecraft:stone_bricks,100)
RB(-3,-1,4,minecraft:mossy_stone_bricks,10,minecraft:cracked_stone_bricks,10,minecraft:cobblestone,10,minecraft:mossy_cobblestone,10,minecraft:stone_bricks,100)
RB(-2,-1,4,minecraft:mossy_stone_bricks,10,minecraft:cracked_stone_bricks,10,minecraft:cobblestone,10,minecraft:mossy_cobblestone,10,minecraft:stone_bricks,100)
RB(-1,-1,4,minecraft:mossy_stone_bricks,10,minecraft:cracked_stone_bricks,10,minecraft:cobblestone,10,minecraft:mossy_cobblestone,10,minecraft:stone_bricks,100)
RB(0,-1,4,minecraft:mossy_stone_bricks,10,minecraft:cracked_stone_bricks,10,minecraft:cobblestone,10,minecraft:mossy_cobblestone,10,minecraft:stone_bricks,100)
RB(1,-1,4,minecraft:mossy_stone_bricks,10,minecraft:cracked_stone_bricks,10,minecraft:cobblestone,10,minecraft:mossy_cobblestone,10,minecraft:stone_bricks,100)
RB(2,-1,4,minecraft:mossy_stone_bricks,10,minecraft:cracked_stone_bricks,10,minecraft:cobblestone,10,minecraft:mossy_cobblestone,10,minecraft:stone_bricks,100)
RB(3,-1,4,minecraft:mossy_stone_bricks,10,minecraft:cracked_stone_bricks,10,minecraft:cobblestone,10,minecraft:mossy_cobblestone,10,minecraft:stone_bricks,100)
RB(4,-1,4,minecraft:mossy_stone_bricks,10,minecraft:cracked_stone_bricks,10,minecraft:cobblestone,10,minecraft:mossy_cobblestone,10,minecraft:stone_bricks,100)
RB(5,-1,4,minecraft:mossy_stone_bricks,10,minecraft:cracked_stone_bricks,10,minecraft:cobblestone,10,minecraft:mossy_cobblestone,10,minecraft:stone_bricks,100)
RB(6,-1,4,minecraft:mossy_stone_bricks,10,minecraft:cracked_stone_bricks,10,minecraft:cobblestone,10,minecraft:mossy_cobblestone,10,minecraft:stone_bricks,100)
RB(7,-1,4,minecraft:mossy_stone_bricks,10,minecraft:cracked_stone_bricks,10,minecraft:cobblestone,10,minecraft:mossy_cobblestone,10,minecraft:stone_bricks,100)
RB(8,-1,4,minecraft:mossy_stone_bricks,10,minecraft:cracked_stone_bricks,10,minecraft:cobblestone,10,minecraft:mossy_cobblestone,10,minecraft:stone_bricks,100)
RB(-7,-1,5,minecraft:mossy_stone_bricks,10,minecraft:cracked_stone_bricks,10,minecraft:cobblestone,10,minecraft:mossy_cobblestone,10,minecraft:stone_bricks,100)
RB(-6,-1,5,minecraft:mossy_stone_bricks,10,minecraft:cracked_stone_bricks,10,minecraft:cobblestone,10,minecraft:mossy_cobblestone,10,minecraft:stone_bricks,100)
RB(-5,-1,5,minecraft:mossy_stone_bricks,10,minecraft:cracked_stone_bricks,10,minecraft:cobblestone,10,minecraft:mossy_cobblestone,10,minecraft:stone_bricks,100)
RB(-4,-1,5,minecraft:mossy_stone_bricks,10,minecraft:cracked_stone_bricks,10,minecraft:cobblestone,10,minecraft:mossy_cobblestone,10,minecraft:stone_bricks,100)
RB(-3,-1,5,minecraft:mossy_stone_bricks,10,minecraft:cracked_stone_bricks,10,minecraft:cobblestone,10,minecraft:mossy_cobblestone,10,minecraft:stone_bricks,100)
RB(-2,-1,5,minecraft:mossy_stone_bricks,10,minecraft:cracked_stone_bricks,10,minecraft:cobblestone,10,minecraft:mossy_cobblestone,10,minecraft:stone_bricks,100)
RB(-1,-1,5,minecraft:mossy_stone_bricks,10,minecraft:cracked_stone_bricks,10,minecraft:cobblestone,10,minecraft:mossy_cobblestone,10,minecraft:stone_bricks,100)
RB(0,-1,5,minecraft:mossy_stone_bricks,10,minecraft:cracked_stone_bricks,10,minecraft:cobblestone,10,minecraft:mossy_cobblestone,10,minecraft:stone_bricks,100)
RB(1,-1,5,minecraft:mossy_stone_bricks,10,minecraft:cracked_stone_bricks,10,minecraft:cobblestone,10,minecraft:mossy_cobblestone,10,minecraft:stone_bricks,100)
RB(2,-1,5,minecraft:mossy_stone_bricks,10,minecraft:cracked_stone_bricks,10,minecraft:cobblestone,10,minecraft:mossy_cobblestone,10,minecraft:stone_bricks,100)
RB(3,-1,5,minecraft:mossy_stone_bricks,10,minecraft:cracked_stone_bricks,10,minecraft:cobblestone,10,minecraft:mossy_cobblestone,10,minecraft:stone_bricks,100)
RB(4,-1,5,minecraft:mossy_stone_bricks,10,minecraft:cracked_stone_bricks,10,minecraft:cobblestone,10,minecraft:mossy_cobblestone,10,minecraft:stone_bricks,100)
RB(5,-1,5,minecraft:mossy_stone_bricks,10,minecraft:cracked_stone_bricks,10,minecraft:cobblestone,10,minecraft:mossy_cobblestone,10,minecraft:stone_bricks,100)
RB(6,-1,5,minecraft:mossy_stone_bricks,10,minecraft:cracked_stone_bricks,10,minecraft:cobblestone,10,minecraft:mossy_cobblestone,10,minecraft:stone_bricks,100)
RB(7,-1,5,minecraft:mossy_stone_bricks,10,minecraft:cracked_stone_bricks,10,minecraft:cobblestone,10,minecraft:mossy_cobblestone,10,minecraft:stone_bricks,100)
RB(8,-1,5,minecraft:mossy_stone_bricks,10,minecraft:cracked_stone_bricks,10,minecraft:cobblestone,10,minecraft:mossy_cobblestone,10,minecraft:stone_bricks,100)
RB(-7,-1,6,minecraft:mossy_stone_bricks,10,minecraft:cracked_stone_bricks,10,minecraft:cobblestone,10,minecraft:mossy_cobblestone,10,minecraft:stone_bricks,100)
RB(-6,-1,6,minecraft:mossy_stone_bricks,10,minecraft:cracked_stone_bricks,10,minecraft:cobblestone,10,minecraft:mossy_cobblestone,10,minecraft:stone_bricks,100)
RB(-5,-1,6,minecraft:mossy_stone_bricks,10,minecraft:cracked_stone_bricks,10,minecraft:cobblestone,10,minecraft:mossy_cobblestone,10,minecraft:stone_bricks,100)
RB(-4,-1,6,minecraft:mossy_stone_bricks,10,minecraft:cracked_stone_bricks,10,minecraft:cobblestone,10,minecraft:mossy_cobblestone,10,minecraft:stone_bricks,100)
RB(-3,-1,6,minecraft:mossy_stone_bricks,10,minecraft:cracked_stone_bricks,10,minecraft:cobblestone,10,minecraft:mossy_cobblestone,10,minecraft:stone_bricks,100)
RB(-2,-1,6,minecraft:mossy_stone_bricks,10,minecraft:cracked_stone_bricks,10,minecraft:cobblestone,10,minecraft:mossy_cobblestone,10,minecraft:stone_bricks,100)
RB(-1,-1,6,minecraft:mossy_stone_bricks,10,minecraft:cracked_stone_bricks,10,minecraft:cobblestone,10,minecraft:mossy_cobblestone,10,minecraft:stone_bricks,100)
RB(0,-1,6,minecraft:mossy_stone_bricks,10,minecraft:cracked_stone_bricks,10,minecraft:cobblestone,10,minecraft:mossy_cobblestone,10,minecraft:stone_bricks,100)
RB(1,-1,6,minecraft:mossy_stone_bricks,10,minecraft:cracked_stone_bricks,10,minecraft:cobblestone,10,minecraft:mossy_cobblestone,10,minecraft:stone_bricks,100)
RB(2,-1,6,minecraft:mossy_stone_bricks,10,minecraft:cracked_stone_bricks,10,minecraft:cobblestone,10,minecraft:mossy_cobblestone,10,minecraft:stone_bricks,100)
RB(3,-1,6,minecraft:mossy_stone_bricks,10,minecraft:cracked_stone_bricks,10,minecraft:cobblestone,10,minecraft:mossy_cobblestone,10,minecraft:stone_bricks,100)
RB(4,-1,6,minecraft:mossy_stone_bricks,10,minecraft:cracked_stone_bricks,10,minecraft:cobblestone,10,minecraft:mossy_cobblestone,10,minecraft:stone_bricks,100)
RB(5,-1,6,minecraft:mossy_stone_bricks,10,minecraft:cracked_stone_bricks,10,minecraft:cobblestone,10,minecraft:mossy_cobblestone,10,minecraft:stone_bricks,100)
RB(6,-1,6,minecraft:mossy_stone_bricks,10,minecraft:cracked_stone_bricks,10,minecraft:cobblestone,10,minecraft:mossy_cobblestone,10,minecraft:stone_bricks,100)
RB(7,-1,6,minecraft:mossy_stone_bricks,10,minecraft:cracked_stone_bricks,10,minecraft:cobblestone,10,minecraft:mossy_cobblestone,10,minecraft:stone_bricks,100)
RB(8,-1,6,minecraft:mossy_stone_bricks,10,minecraft:cracked_stone_bricks,10,minecraft:cobblestone,10,minecraft:mossy_cobblestone,10,minecraft:stone_bricks,100)
RB(-7,-1,7,minecraft:mossy_stone_bricks,10,minecraft:cracked_stone_bricks,10,minecraft:cobblestone,10,minecraft:mossy_cobblestone,10,minecraft:stone_bricks,100)
RB(-6,-1,7,minecraft:mossy_stone_bricks,10,minecraft:cracked_stone_bricks,10,minecraft:cobblestone,10,minecraft:mossy_cobblestone,10,minecraft:stone_bricks,100)
RB(-5,-1,7,minecraft:mossy_stone_bricks,10,minecraft:cracked_stone_bricks,10,minecraft:cobblestone,10,minecraft:mossy_cobblestone,10,minecraft:stone_bricks,100)
RB(-4,-1,7,minecraft:mossy_stone_bricks,10,minecraft:cracked_stone_bricks,10,minecraft:cobblestone,10,minecraft:mossy_cobblestone,10,minecraft:stone_bricks,100)
RB(-3,-1,7,minecraft:mossy_stone_bricks,10,minecraft:cracked_stone_bricks,10,minecraft:cobblestone,10,minecraft:mossy_cobblestone,10,minecraft:stone_bricks,100)
RB(-2,-1,7,minecraft:mossy_stone_bricks,10,minecraft:cracked_stone_bricks,10,minecraft:cobblestone,10,minecraft:mossy_cobblestone,10,minecraft:stone_bricks,100)
RB(-1,-1,7,minecraft:mossy_stone_bricks,10,minecraft:cracked_stone_bricks,10,minecraft:cobblestone,10,minecraft:mossy_cobblestone,10,minecraft:stone_bricks,100)
RB(0,-1,7,minecraft:mossy_stone_bricks,10,minecraft:cracked_stone_bricks,10,minecraft:cobblestone,10,minecraft:mossy_cobblestone,10,minecraft:stone_bricks,100)
RB(1,-1,7,minecraft:mossy_stone_bricks,10,minecraft:cracked_stone_bricks,10,minecraft:cobblestone,10,minecraft:mossy_cobblestone,10,minecraft:stone_bricks,100)
RB(2,-1,7,minecraft:mossy_stone_bricks,10,minecraft:cracked_stone_bricks,10,minecraft:cobblestone,10,minecraft:mossy_cobblestone,10,minecraft:stone_bricks,100)
RB(3,-1,7,minecraft:mossy_stone_bricks,10,minecraft:cracked_stone_bricks,10,minecraft:cobblestone,10,minecraft:mossy_cobblestone,10,minecraft:stone_bricks,100)
RB(4,-1,7,minecraft:mossy_stone_bricks,10,minecraft:cracked_stone_bricks,10,minecraft:cobblestone,10,minecraft:mossy_cobblestone,10,minecraft:stone_bricks,100)
RB(5,-1,7,minecraft:mossy_stone_bricks,10,minecraft:cracked_stone_bricks,10,minecraft:cobblestone,10,minecraft:mossy_cobblestone,10,minecraft:stone_bricks,100)
RB(6,-1,7,minecraft:mossy_stone_bricks,10,minecraft:cracked_stone_bricks,10,minecraft:cobblestone,10,minecraft:mossy_cobblestone,10,minecraft:stone_bricks,100)
RB(7,-1,7,minecraft:mossy_stone_bricks,10,minecraft:cracked_stone_bricks,10,minecraft:cobblestone,10,minecraft:mossy_cobblestone,10,minecraft:stone_bricks,100)
RB(8,-1,7,minecraft:mossy_stone_bricks,10,minecraft:cracked_stone_bricks,10,minecraft:cobblestone,10,minecraft:mossy_cobblestone,10,minecraft:stone_bricks,100)
RB(-7,-1,8,minecraft:mossy_stone_bricks,10,minecraft:cracked_stone_bricks,10,minecraft:cobblestone,10,minecraft:mossy_cobblestone,10,minecraft:stone_bricks,100)
RB(-6,-1,8,minecraft:mossy_stone_bricks,10,minecraft:cracked_stone_bricks,10,minecraft:cobblestone,10,minecraft:mossy_cobblestone,10,minecraft:stone_bricks,100)
RB(-5,-1,8,minecraft:mossy_stone_bricks,10,minecraft:cracked_stone_bricks,10,minecraft:cobblestone,10,minecraft:mossy_cobblestone,10,minecraft:stone_bricks,100)
RB(-4,-1,8,minecraft:mossy_stone_bricks,10,minecraft:cracked_stone_bricks,10,minecraft:cobblestone,10,minecraft:mossy_cobblestone,10,minecraft:stone_bricks,100)
RB(-3,-1,8,minecraft:mossy_stone_bricks,10,minecraft:cracked_stone_bricks,10,minecraft:cobblestone,10,minecraft:mossy_cobblestone,10,minecraft:stone_bricks,100)
RB(-2,-1,8,minecraft:mossy_stone_bricks,10,minecraft:cracked_stone_bricks,10,minecraft:cobblestone,10,minecraft:mossy_cobblestone,10,minecraft:stone_bricks,100)
RB(-1,-1,8,minecraft:mossy_stone_bricks,10,minecraft:cracked_stone_bricks,10,minecraft:cobblestone,10,minecraft:mossy_cobblestone,10,minecraft:stone_bricks,100)
RB(0,-1,8,minecraft:mossy_stone_bricks,10,minecraft:cracked_stone_bricks,10,minecraft:cobblestone,10,minecraft:mossy_cobblestone,10,minecraft:stone_bricks,100)
RB(1,-1,8,minecraft:mossy_stone_bricks,10,minecraft:cracked_stone_bricks,10,minecraft:cobblestone,10,minecraft:mossy_cobblestone,10,minecraft:stone_bricks,100)
RB(2,-1,8,minecraft:mossy_stone_bricks,10,minecraft:cracked_stone_bricks,10,minecraft:cobblestone,10,minecraft:mossy_cobblestone,10,minecraft:stone_bricks,100)
RB(3,-1,8,minecraft:mossy_stone_bricks,10,minecraft:cracked_stone_bricks,10,minecraft:cobblestone,10,minecraft:mossy_cobblestone,10,minecraft:stone_bricks,100)
RB(4,-1,8,minecraft:mossy_stone_bricks,10,minecraft:cracked_stone_bricks,10,minecraft:cobblestone,10,minecraft:mossy_cobblestone,10,minecraft:stone_bricks,100)
RB(5,-1,8,minecraft:mossy_stone_bricks,10,minecraft:cracked_stone_bricks,10,minecraft:cobblestone,10,minecraft:mossy_cobblestone,10,minecraft:stone_bricks,100)
RB(6,-1,8,minecraft:mossy_stone_bricks,10,minecraft:cracked_stone_bricks,10,minecraft:cobblestone,10,minecraft:mossy_cobblestone,10,minecraft:stone_bricks,100)
RB(7,-1,8,minecraft:mossy_stone_bricks,10,minecraft:cracked_stone_bricks,10,minecraft:cobblestone,10,minecraft:mossy_cobblestone,10,minecraft:stone_bricks,100)
RB(8,-1,8,minecraft:mossy_stone_bricks,10,minecraft:cracked_stone_bricks,10,minecraft:cobblestone,10,minecraft:mossy_cobblestone,10,minecraft:stone_bricks,100)
RB(-6,0,3,minecraft:mossy_stone_bricks,10,minecraft:cracked_stone_bricks,10,minecraft:cobblestone,10,minecraft:mossy_cobblestone,10,minecraft:stone_bricks,100)
RB(-5,0,3,minecraft:mossy_stone_bricks,10,minecraft:cracked_stone_bricks,10,minecraft:cobblestone,10,minecraft:mossy_cobblestone,10,minecraft:stone_bricks,100)
RB(-4,0,3,minecraft:mossy_stone_bricks,10,minecraft:cracked_stone_bricks,10,minecraft:cobblestone,10,minecraft:mossy_cobblestone,10,minecraft:stone_bricks,100)
RB(-3,0,3,minecraft:mossy_stone_bricks,10,minecraft:cracked_stone_bricks,10,minecraft:cobblestone,10,minecraft:mossy_cobblestone,10,minecraft:stone_bricks,100)
RB(-2,0,3,minecraft:mossy_stone_bricks,10,minecraft:cracked_stone_bricks,10,minecraft:cobblestone,10,minecraft:mossy_cobblestone,10,minecraft:stone_bricks,100)
RB(-1,0,3,minecraft:mossy_stone_bricks,10,minecraft:cracked_stone_bricks,10,minecraft:cobblestone,10,minecraft:mossy_cobblestone,10,minecraft:stone_bricks,100)
RB(0,0,3,minecraft:mossy_stone_bricks,10,minecraft:cracked_stone_bricks,10,minecraft:cobblestone,10,minecraft:mossy_cobblestone,10,minecraft:stone_bricks,100)
RB(1,0,3,minecraft:mossy_stone_bricks,10,minecraft:cracked_stone_bricks,10,minecraft:cobblestone,10,minecraft:mossy_cobblestone,10,minecraft:stone_bricks,100)
RB(2,0,3,minecraft:mossy_stone_bricks,10,minecraft:cracked_stone_bricks,10,minecraft:cobblestone,10,minecraft:mossy_cobblestone,10,minecraft:stone_bricks,100)
RB(3,0,3,minecraft:mossy_stone_bricks,10,minecraft:cracked_stone_bricks,10,minecraft:cobblestone,10,minecraft:mossy_cobblestone,10,minecraft:stone_bricks,100)
RB(4,0,3,minecraft:mossy_stone_bricks,10,minecraft:cracked_stone_bricks,10,minecraft:cobblestone,10,minecraft:mossy_cobblestone,10,minecraft:stone_bricks,100)
RB(5,0,3,minecraft:mossy_stone_bricks,10,minecraft:cracked_stone_bricks,10,minecraft:cobblestone,10,minecraft:mossy_cobblestone,10,minecraft:stone_bricks,100)
RB(6,0,3,minecraft:mossy_stone_bricks,10,minecraft:cracked_stone_bricks,10,minecraft:cobblestone,10,minecraft:mossy_cobblestone,10,minecraft:stone_bricks,100)
RB(7,0,3,minecraft:mossy_stone_bricks,10,minecraft:cracked_stone_bricks,10,minecraft:cobblestone,10,minecraft:mossy_cobblestone,10,minecraft:stone_bricks,100)
RB(8,0,3,minecraft:mossy_stone_bricks,10,minecraft:cracked_stone_bricks,10,minecraft:cobblestone,10,minecraft:mossy_cobblestone,10,minecraft:stone_bricks,100)
RB(-7,0,4,minecraft:mossy_stone_bricks,10,minecraft:cracked_stone_bricks,10,minecraft:cobblestone,10,minecraft:mossy_cobblestone,10,minecraft:stone_bricks,100)
RB(-6,0,4,minecraft:mossy_stone_bricks,10,minecraft:cracked_stone_bricks,10,minecraft:cobblestone,10,minecraft:mossy_cobblestone,10,minecraft:stone_bricks,100)
RB(-5,0,4,minecraft:mossy_stone_bricks,10,minecraft:cracked_stone_bricks,10,minecraft:cobblestone,10,minecraft:mossy_cobblestone,10,minecraft:stone_bricks,100)
RB(-4,0,4,minecraft:mossy_stone_bricks,10,minecraft:cracked_stone_bricks,10,minecraft:cobblestone,10,minecraft:mossy_cobblestone,10,minecraft:stone_bricks,100)
RB(-3,0,4,minecraft:mossy_stone_bricks,10,minecraft:cracked_stone_bricks,10,minecraft:cobblestone,10,minecraft:mossy_cobblestone,10,minecraft:stone_bricks,100)
RB(-2,0,4,minecraft:mossy_stone_bricks,10,minecraft:cracked_stone_bricks,10,minecraft:cobblestone,10,minecraft:mossy_cobblestone,10,minecraft:stone_bricks,100)
RB(-1,0,4,minecraft:mossy_stone_bricks,10,minecraft:cracked_stone_bricks,10,minecraft:cobblestone,10,minecraft:mossy_cobblestone,10,minecraft:stone_bricks,100)
RB(0,0,4,minecraft:mossy_stone_bricks,10,minecraft:cracked_stone_bricks,10,minecraft:cobblestone,10,minecraft:mossy_cobblestone,10,minecraft:stone_bricks,100)
RB(1,0,4,minecraft:mossy_stone_bricks,10,minecraft:cracked_stone_bricks,10,minecraft:cobblestone,10,minecraft:mossy_cobblestone,10,minecraft:stone_bricks,100)
RB(2,0,4,minecraft:mossy_stone_bricks,10,minecraft:cracked_stone_bricks,10,minecraft:cobblestone,10,minecraft:mossy_cobblestone,10,minecraft:stone_bricks,100)
RB(3,0,4,minecraft:mossy_stone_bricks,10,minecraft:cracked_stone_bricks,10,minecraft:cobblestone,10,minecraft:mossy_cobblestone,10,minecraft:stone_bricks,100)
RB(4,0,4,minecraft:mossy_stone_bricks,10,minecraft:cracked_stone_bricks,10,minecraft:cobblestone,10,minecraft:mossy_cobblestone,10,minecraft:stone_bricks,100)
RB(5,0,4,minecraft:mossy_stone_bricks,10,minecraft:cracked_stone_bricks,10,minecraft:cobblestone,10,minecraft:mossy_cobblestone,10,minecraft:stone_bricks,100)
RB(6,0,4,minecraft:mossy_stone_bricks,10,minecraft:cracked_stone_bricks,10,minecraft:cobblestone,10,minecraft:mossy_cobblestone,10,minecraft:stone_bricks,100)
RB(7,0,4,minecraft:mossy_stone_bricks,10,minecraft:cracked_stone_bricks,10,minecraft:cobblestone,10,minecraft:mossy_cobblestone,10,minecraft:stone_bricks,100)
RB(8,0,4,minecraft:mossy_stone_bricks,10,minecraft:cracked_stone_bricks,10,minecraft:cobblestone,10,minecraft:mossy_cobblestone,10,minecraft:stone_bricks,100)
RB(-7,0,5,minecraft:mossy_stone_bricks,10,minecraft:cracked_stone_bricks,10,minecraft:cobblestone,10,minecraft:mossy_cobblestone,10,minecraft:stone_bricks,100)
RB(-6,0,5,minecraft:mossy_stone_bricks,10,minecraft:cracked_stone_bricks,10,minecraft:cobblestone,10,minecraft:mossy_cobblestone,10,minecraft:stone_bricks,100)
RB(-5,0,5,minecraft:mossy_stone_bricks,10,minecraft:cracked_stone_bricks,10,minecraft:cobblestone,10,minecraft:mossy_cobblestone,10,minecraft:stone_bricks,100)
RB(-4,0,5,minecraft:mossy_stone_bricks,10,minecraft:cracked_stone_bricks,10,minecraft:cobblestone,10,minecraft:mossy_cobblestone,10,minecraft:stone_bricks,100)
RB(-3,0,5,minecraft:mossy_stone_bricks,10,minecraft:cracked_stone_bricks,10,minecraft:cobblestone,10,minecraft:mossy_cobblestone,10,minecraft:stone_bricks,100)
RB(-2,0,5,minecraft:mossy_stone_bricks,10,minecraft:cracked_stone_bricks,10,minecraft:cobblestone,10,minecraft:mossy_cobblestone,10,minecraft:stone_bricks,100)
RB(-1,0,5,minecraft:mossy_stone_bricks,10,minecraft:cracked_stone_bricks,10,minecraft:cobblestone,10,minecraft:mossy_cobblestone,10,minecraft:stone_bricks,100)
RB(0,0,5,minecraft:mossy_stone_bricks,10,minecraft:cracked_stone_bricks,10,minecraft:cobblestone,10,minecraft:mossy_cobblestone,10,minecraft:stone_bricks,100)
RB(1,0,5,minecraft:mossy_stone_bricks,10,minecraft:cracked_stone_bricks,10,minecraft:cobblestone,10,minecraft:mossy_cobblestone,10,minecraft:stone_bricks,100)
RB(2,0,5,minecraft:mossy_stone_bricks,10,minecraft:cracked_stone_bricks,10,minecraft:cobblestone,10,minecraft:mossy_cobblestone,10,minecraft:stone_bricks,100)
RB(3,0,5,minecraft:mossy_stone_bricks,10,minecraft:cracked_stone_bricks,10,minecraft:cobblestone,10,minecraft:mossy_cobblestone,10,minecraft:stone_bricks,100)
RB(4,0,5,minecraft:mossy_stone_bricks,10,minecraft:cracked_stone_bricks,10,minecraft:cobblestone,10,minecraft:mossy_cobblestone,10,minecraft:stone_bricks,100)
RB(5,0,5,minecraft:mossy_stone_bricks,10,minecraft:cracked_stone_bricks,10,minecraft:cobblestone,10,minecraft:mossy_cobblestone,10,minecraft:stone_bricks,100)
RB(6,0,5,minecraft:mossy_stone_bricks,10,minecraft:cracked_stone_bricks,10,minecraft:cobblestone,10,minecraft:mossy_cobblestone,10,minecraft:stone_bricks,100)
RB(7,0,5,minecraft:mossy_stone_bricks,10,minecraft:cracked_stone_bricks,10,minecraft:cobblestone,10,minecraft:mossy_cobblestone,10,minecraft:stone_bricks,100)
RB(8,0,5,minecraft:mossy_stone_bricks,10,minecraft:cracked_stone_bricks,10,minecraft:cobblestone,10,minecraft:mossy_cobblestone,10,minecraft:stone_bricks,100)
RB(-7,0,6,minecraft:mossy_stone_bricks,10,minecraft:cracked_stone_bricks,10,minecraft:cobblestone,10,minecraft:mossy_cobblestone,10,minecraft:stone_bricks,100)
RB(-6,0,6,minecraft:mossy_stone_bricks,10,minecraft:cracked_stone_bricks,10,minecraft:cobblestone,10,minecraft:mossy_cobblestone,10,minecraft:stone_bricks,100)
RB(-5,0,6,minecraft:mossy_stone_bricks,10,minecraft:cracked_stone_bricks,10,minecraft:cobblestone,10,minecraft:mossy_cobblestone,10,minecraft:stone_bricks,100)
RB(-4,0,6,minecraft:mossy_stone_bricks,10,minecraft:cracked_stone_bricks,10,minecraft:cobblestone,10,minecraft:mossy_cobblestone,10,minecraft:stone_bricks,100)
RB(-3,0,6,minecraft:mossy_stone_bricks,10,minecraft:cracked_stone_bricks,10,minecraft:cobblestone,10,minecraft:mossy_cobblestone,10,minecraft:stone_bricks,100)
RB(-2,0,6,minecraft:mossy_stone_bricks,10,minecraft:cracked_stone_bricks,10,minecraft:cobblestone,10,minecraft:mossy_cobblestone,10,minecraft:stone_bricks,100)
RB(-1,0,6,minecraft:mossy_stone_bricks,10,minecraft:cracked_stone_bricks,10,minecraft:cobblestone,10,minecraft:mossy_cobblestone,10,minecraft:stone_bricks,100)
RB(0,0,6,minecraft:mossy_stone_bricks,10,minecraft:cracked_stone_bricks,10,minecraft:cobblestone,10,minecraft:mossy_cobblestone,10,minecraft:stone_bricks,100)
RB(1,0,6,minecraft:mossy_stone_bricks,10,minecraft:cracked_stone_bricks,10,minecraft:cobblestone,10,minecraft:mossy_cobblestone,10,minecraft:stone_bricks,100)
RB(2,0,6,minecraft:mossy_stone_bricks,10,minecraft:cracked_stone_bricks,10,minecraft:cobblestone,10,minecraft:mossy_cobblestone,10,minecraft:stone_bricks,100)
RB(3,0,6,minecraft:mossy_stone_bricks,10,minecraft:cracked_stone_bricks,10,minecraft:cobblestone,10,minecraft:mossy_cobblestone,10,minecraft:stone_bricks,100)
RB(4,0,6,minecraft:mossy_stone_bricks,10,minecraft:cracked_stone_bricks,10,minecraft:cobblestone,10,minecraft:mossy_cobblestone,10,minecraft:stone_bricks,100)
RB(5,0,6,minecraft:mossy_stone_bricks,10,minecraft:cracked_stone_bricks,10,minecraft:cobblestone,10,minecraft:mossy_cobblestone,10,minecraft:stone_bricks,100)
RB(6,0,6,minecraft:mossy_stone_bricks,10,minecraft:cracked_stone_bricks,10,minecraft:cobblestone,10,minecraft:mossy_cobblestone,10,minecraft:stone_bricks,100)
RB(7,0,6,minecraft:mossy_stone_bricks,10,minecraft:cracked_stone_bricks,10,minecraft:cobblestone,10,minecraft:mossy_cobblestone,10,minecraft:stone_bricks,100)
RB(8,0,6,minecraft:mossy_stone_bricks,10,minecraft:cracked_stone_bricks,10,minecraft:cobblestone,10,minecraft:mossy_cobblestone,10,minecraft:stone_bricks,100)
RB(-7,0,7,minecraft:mossy_stone_bricks,10,minecraft:cracked_stone_bricks,10,minecraft:cobblestone,10,minecraft:mossy_cobblestone,10,minecraft:stone_bricks,100)
RB(-6,0,7,minecraft:mossy_stone_bricks,10,minecraft:cracked_stone_bricks,10,minecraft:cobblestone,10,minecraft:mossy_cobblestone,10,minecraft:stone_bricks,100)
RB(-3,0,7,minecraft:mossy_stone_bricks,10,minecraft:cracked_stone_bricks,10,minecraft:cobblestone,10,minecraft:mossy_cobblestone,10,minecraft:stone_bricks,100)
RB(-2,0,7,minecraft:mossy_stone_bricks,10,minecraft:cracked_stone_bricks,10,minecraft:cobblestone,10,minecraft:mossy_cobblestone,10,minecraft:stone_bricks,100)
RB(-1,0,7,minecraft:mossy_stone_bricks,10,minecraft:cracked_stone_bricks,10,minecraft:cobblestone,10,minecraft:mossy_cobblestone,10,minecraft:stone_bricks,100)
RB(0,0,7,minecraft:mossy_stone_bricks,10,minecraft:cracked_stone_bricks,10,minecraft:cobblestone,10,minecraft:mossy_cobblestone,10,minecraft:stone_bricks,100)
RB(1,0,7,minecraft:mossy_stone_bricks,10,minecraft:cracked_stone_bricks,10,minecraft:cobblestone,10,minecraft:mossy_cobblestone,10,minecraft:stone_bricks,100)
RB(2,0,7,minecraft:mossy_stone_bricks,10,minecraft:cracked_stone_bricks,10,minecraft:cobblestone,10,minecraft:mossy_cobblestone,10,minecraft:stone_bricks,100)
RB(5,0,7,minecraft:mossy_stone_bricks,10,minecraft:cracked_stone_bricks,10,minecraft:cobblestone,10,minecraft:mossy_cobblestone,10,minecraft:stone_bricks,100)
RB(6,0,7,minecraft:mossy_stone_bricks,10,minecraft:cracked_stone_bricks,10,minecraft:cobblestone,10,minecraft:mossy_cobblestone,10,minecraft:stone_bricks,100)
RB(-3,0,8,minecraft:mossy_stone_bricks,10,minecraft:cracked_stone_bricks,10,minecraft:cobblestone,10,minecraft:mossy_cobblestone,10,minecraft:stone_bricks,100)
RB(2,0,8,minecraft:mossy_stone_bricks,10,minecraft:cracked_stone_bricks,10,minecraft:cobblestone,10,minecraft:mossy_cobblestone,10,minecraft:stone_bricks,100)
RB(-5,1,3,minecraft:mossy_stone_bricks,10,minecraft:cracked_stone_bricks,10,minecraft:cobblestone,10,minecraft:mossy_cobblestone,10,minecraft:stone_bricks,100)
RB(-2,1,3,minecraft:mossy_stone_bricks,10,minecraft:cracked_stone_bricks,10,minecraft:cobblestone,10,minecraft:mossy_cobblestone,10,minecraft:stone_bricks,100)
RB(1,1,3,minecraft:mossy_stone_bricks,10,minecraft:cracked_stone_bricks,10,minecraft:cobblestone,10,minecraft:mossy_cobblestone,10,minecraft:stone_bricks,100)
RB(4,1,3,minecraft:mossy_stone_bricks,10,minecraft:cracked_stone_bricks,10,minecraft:cobblestone,10,minecraft:mossy_cobblestone,10,minecraft:stone_bricks,100)
RB(7,1,3,minecraft:mossy_stone_bricks,10,minecraft:cracked_stone_bricks,10,minecraft:cobblestone,10,minecraft:mossy_cobblestone,10,minecraft:stone_bricks,100)
RB(-7,1,4,minecraft:mossy_stone_bricks,10,minecraft:cracked_stone_bricks,10,minecraft:cobblestone,10,minecraft:mossy_cobblestone,10,minecraft:stone_bricks,100)
RB(-6,1,4,minecraft:mossy_stone_bricks,10,minecraft:cracked_stone_bricks,10,minecraft:cobblestone,10,minecraft:mossy_cobblestone,10,minecraft:stone_bricks,100)
RB(-5,1,4,minecraft:mossy_stone_bricks,10,minecraft:cracked_stone_bricks,10,minecraft:cobblestone,10,minecraft:mossy_cobblestone,10,minecraft:stone_bricks,100)
RB(-4,1,4,minecraft:mossy_stone_bricks,10,minecraft:cracked_stone_bricks,10,minecraft:cobblestone,10,minecraft:mossy_cobblestone,10,minecraft:stone_bricks,100)
RB(-3,1,4,minecraft:mossy_stone_bricks,10,minecraft:cracked_stone_bricks,10,minecraft:cobblestone,10,minecraft:mossy_cobblestone,10,minecraft:stone_bricks,100)
RB(-2,1,4,minecraft:mossy_stone_bricks,10,minecraft:cracked_stone_bricks,10,minecraft:cobblestone,10,minecraft:mossy_cobblestone,10,minecraft:stone_bricks,100)
RB(-1,1,4,minecraft:mossy_stone_bricks,10,minecraft:cracked_stone_bricks,10,minecraft:cobblestone,10,minecraft:mossy_cobblestone,10,minecraft:stone_bricks,100)
RB(0,1,4,minecraft:mossy_stone_bricks,10,minecraft:cracked_stone_bricks,10,minecraft:cobblestone,10,minecraft:mossy_cobblestone,10,minecraft:stone_bricks,100)
RB(1,1,4,minecraft:mossy_stone_bricks,10,minecraft:cracked_stone_bricks,10,minecraft:cobblestone,10,minecraft:mossy_cobblestone,10,minecraft:stone_bricks,100)
RB(2,1,4,minecraft:mossy_stone_bricks,10,minecraft:cracked_stone_bricks,10,minecraft:cobblestone,10,minecraft:mossy_cobblestone,10,minecraft:stone_bricks,100)
RB(3,1,4,minecraft:mossy_stone_bricks,10,minecraft:cracked_stone_bricks,10,minecraft:cobblestone,10,minecraft:mossy_cobblestone,10,minecraft:stone_bricks,100)
RB(4,1,4,minecraft:mossy_stone_bricks,10,minecraft:cracked_stone_bricks,10,minecraft:cobblestone,10,minecraft:mossy_cobblestone,10,minecraft:stone_bricks,100)
RB(5,1,4,minecraft:mossy_stone_bricks,10,minecraft:cracked_stone_bricks,10,minecraft:cobblestone,10,minecraft:mossy_cobblestone,10,minecraft:stone_bricks,100)
RB(6,1,4,minecraft:mossy_stone_bricks,10,minecraft:cracked_stone_bricks,10,minecraft:cobblestone,10,minecraft:mossy_cobblestone,10,minecraft:stone_bricks,100)
RB(7,1,4,minecraft:mossy_stone_bricks,10,minecraft:cracked_stone_bricks,10,minecraft:cobblestone,10,minecraft:mossy_cobblestone,10,minecraft:stone_bricks,100)
RB(8,1,4,minecraft:mossy_stone_bricks,10,minecraft:cracked_stone_bricks,10,minecraft:cobblestone,10,minecraft:mossy_cobblestone,10,minecraft:stone_bricks,100)
RB(-7,1,5,minecraft:mossy_stone_bricks,10,minecraft:cracked_stone_bricks,10,minecraft:cobblestone,10,minecraft:mossy_cobblestone,10,minecraft:stone_bricks,100)
RB(-6,1,5,minecraft:mossy_stone_bricks,10,minecraft:cracked_stone_bricks,10,minecraft:cobblestone,10,minecraft:mossy_cobblestone,10,minecraft:stone_bricks,100)
RB(-5,1,5,minecraft:mossy_stone_bricks,10,minecraft:cracked_stone_bricks,10,minecraft:cobblestone,10,minecraft:mossy_cobblestone,10,minecraft:stone_bricks,100)
RB(-4,1,5,minecraft:mossy_stone_bricks,10,minecraft:cracked_stone_bricks,10,minecraft:cobblestone,10,minecraft:mossy_cobblestone,10,minecraft:stone_bricks,100)
RB(-3,1,5,minecraft:mossy_stone_bricks,10,minecraft:cracked_stone_bricks,10,minecraft:cobblestone,10,minecraft:mossy_cobblestone,10,minecraft:stone_bricks,100)
RB(-2,1,5,minecraft:mossy_stone_bricks,10,minecraft:cracked_stone_bricks,10,minecraft:cobblestone,10,minecraft:mossy_cobblestone,10,minecraft:stone_bricks,100)
RB(-1,1,5,minecraft:mossy_stone_bricks,10,minecraft:cracked_stone_bricks,10,minecraft:cobblestone,10,minecraft:mossy_cobblestone,10,minecraft:stone_bricks,100)
RB(0,1,5,minecraft:mossy_stone_bricks,10,minecraft:cracked_stone_bricks,10,minecraft:cobblestone,10,minecraft:mossy_cobblestone,10,minecraft:stone_bricks,100)
RB(1,1,5,minecraft:mossy_stone_bricks,10,minecraft:cracked_stone_bricks,10,minecraft:cobblestone,10,minecraft:mossy_cobblestone,10,minecraft:stone_bricks,100)
RB(2,1,5,minecraft:mossy_stone_bricks,10,minecraft:cracked_stone_bricks,10,minecraft:cobblestone,10,minecraft:mossy_cobblestone,10,minecraft:stone_bricks,100)
RB(3,1,5,minecraft:mossy_stone_bricks,10,minecraft:cracked_stone_bricks,10,minecraft:cobblestone,10,minecraft:mossy_cobblestone,10,minecraft:stone_bricks,100)
RB(4,1,5,minecraft:mossy_stone_bricks,10,minecraft:cracked_stone_bricks,10,minecraft:cobblestone,10,minecraft:mossy_cobblestone,10,minecraft:stone_bricks,100)
RB(5,1,5,minecraft:mossy_stone_bricks,10,minecraft:cracked_stone_bricks,10,minecraft:cobblestone,10,minecraft:mossy_cobblestone,10,minecraft:stone_bricks,100)
RB(6,1,5,minecraft:mossy_stone_bricks,10,minecraft:cracked_stone_bricks,10,minecraft:cobblestone,10,minecraft:mossy_cobblestone,10,minecraft:stone_bricks,100)
RB(7,1,5,minecraft:mossy_stone_bricks,10,minecraft:cracked_stone_bricks,10,minecraft:cobblestone,10,minecraft:mossy_cobblestone,10,minecraft:stone_bricks,100)
RB(8,1,5,minecraft:mossy_stone_bricks,10,minecraft:cracked_stone_bricks,10,minecraft:cobblestone,10,minecraft:mossy_cobblestone,10,minecraft:stone_bricks,100)
RB(-7,1,6,minecraft:mossy_stone_bricks,10,minecraft:cracked_stone_bricks,10,minecraft:cobblestone,10,minecraft:mossy_cobblestone,10,minecraft:stone_bricks,100)
RB(-6,1,6,minecraft:mossy_stone_bricks,10,minecraft:cracked_stone_bricks,10,minecraft:cobblestone,10,minecraft:mossy_cobblestone,10,minecraft:stone_bricks,100)
RB(-5,1,6,minecraft:mossy_stone_bricks,10,minecraft:cracked_stone_bricks,10,minecraft:cobblestone,10,minecraft:mossy_cobblestone,10,minecraft:stone_bricks,100)
RB(-4,1,6,minecraft:mossy_stone_bricks,10,minecraft:cracked_stone_bricks,10,minecraft:cobblestone,10,minecraft:mossy_cobblestone,10,minecraft:stone_bricks,100)
RB(-3,1,6,minecraft:mossy_stone_bricks,10,minecraft:cracked_stone_bricks,10,minecraft:cobblestone,10,minecraft:mossy_cobblestone,10,minecraft:stone_bricks,100)
RB(-2,1,6,minecraft:mossy_stone_bricks,10,minecraft:cracked_stone_bricks,10,minecraft:cobblestone,10,minecraft:mossy_cobblestone,10,minecraft:stone_bricks,100)
RB(-1,1,6,minecraft:mossy_stone_bricks,10,minecraft:cracked_stone_bricks,10,minecraft:cobblestone,10,minecraft:mossy_cobblestone,10,minecraft:stone_bricks,100)
RB(0,1,6,minecraft:mossy_stone_bricks,10,minecraft:cracked_stone_bricks,10,minecraft:cobblestone,10,minecraft:mossy_cobblestone,10,minecraft:stone_bricks,100)
RB(1,1,6,minecraft:mossy_stone_bricks,10,minecraft:cracked_stone_bricks,10,minecraft:cobblestone,10,minecraft:mossy_cobblestone,10,minecraft:stone_bricks,100)
RB(2,1,6,minecraft:mossy_stone_bricks,10,minecraft:cracked_stone_bricks,10,minecraft:cobblestone,10,minecraft:mossy_cobblestone,10,minecraft:stone_bricks,100)
RB(3,1,6,minecraft:mossy_stone_bricks,10,minecraft:cracked_stone_bricks,10,minecraft:cobblestone,10,minecraft:mossy_cobblestone,10,minecraft:stone_bricks,100)
RB(4,1,6,minecraft:mossy_stone_bricks,10,minecraft:cracked_stone_bricks,10,minecraft:cobblestone,10,minecraft:mossy_cobblestone,10,minecraft:stone_bricks,100)
RB(5,1,6,minecraft:mossy_stone_bricks,10,minecraft:cracked_stone_bricks,10,minecraft:cobblestone,10,minecraft:mossy_cobblestone,10,minecraft:stone_bricks,100)
RB(6,1,6,minecraft:mossy_stone_bricks,10,minecraft:cracked_stone_bricks,10,minecraft:cobblestone,10,minecraft:mossy_cobblestone,10,minecraft:stone_bricks,100)
RB(7,1,6,minecraft:mossy_stone_bricks,10,minecraft:cracked_stone_bricks,10,minecraft:cobblestone,10,minecraft:mossy_cobblestone,10,minecraft:stone_bricks,100)
RB(8,1,6,minecraft:mossy_stone_bricks,10,minecraft:cracked_stone_bricks,10,minecraft:cobblestone,10,minecraft:mossy_cobblestone,10,minecraft:stone_bricks,100)
RB(-7,1,7,minecraft:chest[facing=south,type=single,waterlogged=false],../JungleNBT/LoreStoryline/MayaLore05.nbt,2,minecraft:chest[facing=south,type=single,waterlogged=false],../JungleNBT/LoreStoryline/MayaLore04.nbt,2,minecraft:chest[facing=south,type=single,waterlogged=false],../JungleNBT/LoreStoryline/MayaLore03.nbt,2,minecraft:chest[facing=south,type=single,waterlogged=false],../JungleNBT/LoreStoryline/MayaLore02.nbt,2,minecraft:chest[facing=south,type=single,waterlogged=false],../JungleNBT/LoreStoryline/MayaLore01.nbt,2,minecraft:chest[facing=south,type=single,waterlogged=false],../JungleNBT/StructureLoot/Common1.nbt,3,minecraft:chest[facing=south,type=single,waterlogged=false],../JungleNBT/StructureLoot/Common2.nbt,3,minecraft:chest[facing=south,type=single,waterlogged=false],../JungleNBT/StructureLoot/Common3.nbt,3,minecraft:chest[facing=south,type=single,waterlogged=false],../JungleNBT/StructureLoot/Common4.nbt,3,minecraft:chest[facing=south,type=single,waterlogged=false],../JungleNBT/StructureLoot/Common5.nbt,3,minecraft:chest[facing=south,type=single,waterlogged=false],../JungleNBT/StructureLoot/Common5.nbt,3,minecraft:chest[facing=south,type=single,waterlogged=false],../JungleNBT/StructureLoot/Common6.nbt,3,minecraft:chest[facing=south,type=single,waterlogged=false],../JungleNBT/StructureLoot/Common7.nbt,3,minecraft:chest[facing=south,type=single,waterlogged=false],../JungleNBT/StructureLoot/Common8.nbt,3,minecraft:chest[facing=south,type=single,waterlogged=false],../JungleNBT/StructureLoot/Common9.nbt,3,minecraft:chest[facing=south,type=single,waterlogged=false],../JungleNBT/StructureLoot/Common10.nbt,3,minecraft:chest[facing=south,type=single,waterlogged=false],../JungleNBT/StructureLoot/Common11.nbt,3,minecraft:chest[facing=south,type=single,waterlogged=false],../JungleNBT/StructureLoot/Common12.nbt,3,minecraft:chest[facing=south,type=single,waterlogged=false],../JungleNBT/StructureLoot/Common13.nbt,3,minecraft:chest[facing=south,type=single,waterlogged=false],../JungleNBT/StructureLoot/Common14.nbt,3,minecraft:chest[facing=south,type=single,waterlogged=false],../JungleNBT/StructureLoot/Common15.nbt,3,minecraft:chest[facing=south,type=single,waterlogged=false],../JungleNBT/StructureLoot/Rare1.nbt,3,minecraft:chest[facing=south,type=single,waterlogged=false],../JungleNBT/StructureLoot/Rare2.nbt,3,minecraft:chest[facing=south,type=single,waterlogged=false],../JungleNBT/StructureLoot/Rare3.nbt,3,minecraft:chest[facing=south,type=single,waterlogged=false],../JungleNBT/StructureLoot/Rare4.nbt,3,minecraft:chest[facing=south,type=single,waterlogged=false],../JungleNBT/StructureLoot/Rare5.nbt,3,minecraft:chest[facing=south,type=single,waterlogged=false],../JungleNBT/StructureLoot/Rare6.nbt,3,minecraft:chest[facing=south,type=single,waterlogged=false],../JungleNBT/StructureLoot/Rare7.nbt,3,minecraft:chest[facing=south,type=single,waterlogged=false],../JungleNBT/StructureLoot/Rare8.nbt,3,minecraft:chest[facing=south,type=single,waterlogged=false],../JungleNBT/StructureLoot/Rare9.nbt,3,minecraft:chest[facing=south,type=single,waterlogged=false],../JungleNBT/StructureLoot/Rare10.nbt,3,minecraft:chest[facing=south,type=single,waterlogged=false],../JungleNBT/StructureLoot/Rare11.nbt,3,minecraft:chest[facing=south,type=single,waterlogged=false],../JungleNBT/StructureLoot/Rare12.nbt,3,minecraft:chest[facing=south,type=single,waterlogged=false],../JungleNBT/StructureLoot/Rare13.nbt,3,minecraft:chest[facing=south,type=single,waterlogged=false],../JungleNBT/StructureLoot/Rare14.nbt,3,minecraft:chest[facing=south,type=single,waterlogged=false],../JungleNBT/StructureLoot/Rare15.nbt,3,minecraft:chest[facing=south,type=single,waterlogged=false],../JungleNBT/StructureLoot/Epic1.nbt,3,minecraft:chest[facing=south,type=single,waterlogged=false],../JungleNBT/StructureLoot/Epic2.nbt,3,minecraft:chest[facing=south,type=single,waterlogged=false],../JungleNBT/StructureLoot/Epic3.nbt,3,minecraft:chest[facing=south,type=single,waterlogged=false],../JungleNBT/StructureLoot/Epic4.nbt,3,minecraft:chest[facing=south,type=single,waterlogged=false],../JungleNBT/StructureLoot/Epic5.nbt,3,minecraft:chest[facing=south,type=single,waterlogged=false],../JungleNBT/StructureLoot/Epic6.nbt,3,minecraft:chest[facing=south,type=single,waterlogged=false],../JungleNBT/StructureLoot/Epic7.nbt,3,minecraft:chest[facing=south,type=single,waterlogged=false],../JungleNBT/StructureLoot/Epic8.nbt,3,minecraft:chest[facing=south,type=single,waterlogged=false],../JungleNBT/StructureLoot/Epic9.nbt,3,minecraft:chest[facing=south,type=single,waterlogged=false],../JungleNBT/StructureLoot/Epic10.nbt,3,minecraft:chest[facing=south,type=single,waterlogged=false],../JungleNBT/StructureLoot/Epic11.nbt,3,minecraft:chest[facing=south,type=single,waterlogged=false],../JungleNBT/StructureLoot/Epic12.nbt,3,minecraft:chest[facing=south,type=single,waterlogged=false],../JungleNBT/StructureLoot/Epic13.nbt,3,minecraft:chest[facing=south,type=single,waterlogged=false],../JungleNBT/StructureLoot/Epic14.nbt,3,minecraft:chest[facing=south,type=single,waterlogged=false],../JungleNBT/StructureLoot/Epic15.nbt,3,minecraft:chest[facing=south,type=single,waterlogged=false],../JungleNBT/LoreStoryline/JungleLore05.nbt,100)
RB(-6,1,7,minecraft:chest[facing=south,type=single,waterlogged=false],../JungleNBT/LoreStoryline/MayaLore05.nbt,2,minecraft:chest[facing=south,type=single,waterlogged=false],../JungleNBT/LoreStoryline/MayaLore04.nbt,2,minecraft:chest[facing=south,type=single,waterlogged=false],../JungleNBT/LoreStoryline/MayaLore03.nbt,2,minecraft:chest[facing=south,type=single,waterlogged=false],../JungleNBT/LoreStoryline/MayaLore02.nbt,2,minecraft:chest[facing=south,type=single,waterlogged=false],../JungleNBT/LoreStoryline/MayaLore01.nbt,2,minecraft:chest[facing=south,type=single,waterlogged=false],../JungleNBT/StructureLoot/Common1.nbt,3,minecraft:chest[facing=south,type=single,waterlogged=false],../JungleNBT/StructureLoot/Common2.nbt,3,minecraft:chest[facing=south,type=single,waterlogged=false],../JungleNBT/StructureLoot/Common3.nbt,3,minecraft:chest[facing=south,type=single,waterlogged=false],../JungleNBT/StructureLoot/Common4.nbt,3,minecraft:chest[facing=south,type=single,waterlogged=false],../JungleNBT/StructureLoot/Common5.nbt,3,minecraft:chest[facing=south,type=single,waterlogged=false],../JungleNBT/StructureLoot/Common5.nbt,3,minecraft:chest[facing=south,type=single,waterlogged=false],../JungleNBT/StructureLoot/Common6.nbt,3,minecraft:chest[facing=south,type=single,waterlogged=false],../JungleNBT/StructureLoot/Common7.nbt,3,minecraft:chest[facing=south,type=single,waterlogged=false],../JungleNBT/StructureLoot/Common8.nbt,3,minecraft:chest[facing=south,type=single,waterlogged=false],../JungleNBT/StructureLoot/Common9.nbt,3,minecraft:chest[facing=south,type=single,waterlogged=false],../JungleNBT/StructureLoot/Common10.nbt,3,minecraft:chest[facing=south,type=single,waterlogged=false],../JungleNBT/StructureLoot/Common11.nbt,3,minecraft:chest[facing=south,type=single,waterlogged=false],../JungleNBT/StructureLoot/Common12.nbt,3,minecraft:chest[facing=south,type=single,waterlogged=false],../JungleNBT/StructureLoot/Common13.nbt,3,minecraft:chest[facing=south,type=single,waterlogged=false],../JungleNBT/StructureLoot/Common14.nbt,3,minecraft:chest[facing=south,type=single,waterlogged=false],../JungleNBT/StructureLoot/Common15.nbt,3,minecraft:chest[facing=south,type=single,waterlogged=false],../JungleNBT/StructureLoot/Rare1.nbt,3,minecraft:chest[facing=south,type=single,waterlogged=false],../JungleNBT/StructureLoot/Rare2.nbt,3,minecraft:chest[facing=south,type=single,waterlogged=false],../JungleNBT/StructureLoot/Rare3.nbt,3,minecraft:chest[facing=south,type=single,waterlogged=false],../JungleNBT/StructureLoot/Rare4.nbt,3,minecraft:chest[facing=south,type=single,waterlogged=false],../JungleNBT/StructureLoot/Rare5.nbt,3,minecraft:chest[facing=south,type=single,waterlogged=false],../JungleNBT/StructureLoot/Rare6.nbt,3,minecraft:chest[facing=south,type=single,waterlogged=false],../JungleNBT/StructureLoot/Rare7.nbt,3,minecraft:chest[facing=south,type=single,waterlogged=false],../JungleNBT/StructureLoot/Rare8.nbt,3,minecraft:chest[facing=south,type=single,waterlogged=false],../JungleNBT/StructureLoot/Rare9.nbt,3,minecraft:chest[facing=south,type=single,waterlogged=false],../JungleNBT/StructureLoot/Rare10.nbt,3,minecraft:chest[facing=south,type=single,waterlogged=false],../JungleNBT/StructureLoot/Rare11.nbt,3,minecraft:chest[facing=south,type=single,waterlogged=false],../JungleNBT/StructureLoot/Rare12.nbt,3,minecraft:chest[facing=south,type=single,waterlogged=false],../JungleNBT/StructureLoot/Rare13.nbt,3,minecraft:chest[facing=south,type=single,waterlogged=false],../JungleNBT/StructureLoot/Rare14.nbt,3,minecraft:chest[facing=south,type=single,waterlogged=false],../JungleNBT/StructureLoot/Rare15.nbt,3,minecraft:chest[facing=south,type=single,waterlogged=false],../JungleNBT/StructureLoot/Epic1.nbt,3,minecraft:chest[facing=south,type=single,waterlogged=false],../JungleNBT/StructureLoot/Epic2.nbt,3,minecraft:chest[facing=south,type=single,waterlogged=false],../JungleNBT/StructureLoot/Epic3.nbt,3,minecraft:chest[facing=south,type=single,waterlogged=false],../JungleNBT/StructureLoot/Epic4.nbt,3,minecraft:chest[facing=south,type=single,waterlogged=false],../JungleNBT/StructureLoot/Epic5.nbt,3,minecraft:chest[facing=south,type=single,waterlogged=false],../JungleNBT/StructureLoot/Epic6.nbt,3,minecraft:chest[facing=south,type=single,waterlogged=false],../JungleNBT/StructureLoot/Epic7.nbt,3,minecraft:chest[facing=south,type=single,waterlogged=false],../JungleNBT/StructureLoot/Epic8.nbt,3,minecraft:chest[facing=south,type=single,waterlogged=false],../JungleNBT/StructureLoot/Epic9.nbt,3,minecraft:chest[facing=south,type=single,waterlogged=false],../JungleNBT/StructureLoot/Epic10.nbt,3,minecraft:chest[facing=south,type=single,waterlogged=false],../JungleNBT/StructureLoot/Epic11.nbt,3,minecraft:chest[facing=south,type=single,waterlogged=false],../JungleNBT/StructureLoot/Epic12.nbt,3,minecraft:chest[facing=south,type=single,waterlogged=false],../JungleNBT/StructureLoot/Epic13.nbt,3,minecraft:chest[facing=south,type=single,waterlogged=false],../JungleNBT/StructureLoot/Epic14.nbt,3,minecraft:chest[facing=south,type=single,waterlogged=false],../JungleNBT/StructureLoot/Epic15.nbt,3,minecraft:chest[facing=south,type=single,waterlogged=false],../JungleNBT/LoreStoryline/JungleLore05.nbt,100)
RB(5,1,7,minecraft:chest[facing=south,type=single,waterlogged=false],../JungleNBT/LoreStoryline/MayaLore05.nbt,2,minecraft:chest[facing=south,type=single,waterlogged=false],../JungleNBT/LoreStoryline/MayaLore04.nbt,2,minecraft:chest[facing=south,type=single,waterlogged=false],../JungleNBT/LoreStoryline/MayaLore03.nbt,2,minecraft:chest[facing=south,type=single,waterlogged=false],../JungleNBT/LoreStoryline/MayaLore02.nbt,2,minecraft:chest[facing=south,type=single,waterlogged=false],../JungleNBT/LoreStoryline/MayaLore01.nbt,2,minecraft:chest[facing=south,type=single,waterlogged=false],../JungleNBT/StructureLoot/Common1.nbt,3,minecraft:chest[facing=south,type=single,waterlogged=false],../JungleNBT/StructureLoot/Common2.nbt,3,minecraft:chest[facing=south,type=single,waterlogged=false],../JungleNBT/StructureLoot/Common3.nbt,3,minecraft:chest[facing=south,type=single,waterlogged=false],../JungleNBT/StructureLoot/Common4.nbt,3,minecraft:chest[facing=south,type=single,waterlogged=false],../JungleNBT/StructureLoot/Common5.nbt,3,minecraft:chest[facing=south,type=single,waterlogged=false],../JungleNBT/StructureLoot/Common5.nbt,3,minecraft:chest[facing=south,type=single,waterlogged=false],../JungleNBT/StructureLoot/Common6.nbt,3,minecraft:chest[facing=south,type=single,waterlogged=false],../JungleNBT/StructureLoot/Common7.nbt,3,minecraft:chest[facing=south,type=single,waterlogged=false],../JungleNBT/StructureLoot/Common8.nbt,3,minecraft:chest[facing=south,type=single,waterlogged=false],../JungleNBT/StructureLoot/Common9.nbt,3,minecraft:chest[facing=south,type=single,waterlogged=false],../JungleNBT/StructureLoot/Common10.nbt,3,minecraft:chest[facing=south,type=single,waterlogged=false],../JungleNBT/StructureLoot/Common11.nbt,3,minecraft:chest[facing=south,type=single,waterlogged=false],../JungleNBT/StructureLoot/Common12.nbt,3,minecraft:chest[facing=south,type=single,waterlogged=false],../JungleNBT/StructureLoot/Common13.nbt,3,minecraft:chest[facing=south,type=single,waterlogged=false],../JungleNBT/StructureLoot/Common14.nbt,3,minecraft:chest[facing=south,type=single,waterlogged=false],../JungleNBT/StructureLoot/Common15.nbt,3,minecraft:chest[facing=south,type=single,waterlogged=false],../JungleNBT/StructureLoot/Rare1.nbt,3,minecraft:chest[facing=south,type=single,waterlogged=false],../JungleNBT/StructureLoot/Rare2.nbt,3,minecraft:chest[facing=south,type=single,waterlogged=false],../JungleNBT/StructureLoot/Rare3.nbt,3,minecraft:chest[facing=south,type=single,waterlogged=false],../JungleNBT/StructureLoot/Rare4.nbt,3,minecraft:chest[facing=south,type=single,waterlogged=false],../JungleNBT/StructureLoot/Rare5.nbt,3,minecraft:chest[facing=south,type=single,waterlogged=false],../JungleNBT/StructureLoot/Rare6.nbt,3,minecraft:chest[facing=south,type=single,waterlogged=false],../JungleNBT/StructureLoot/Rare7.nbt,3,minecraft:chest[facing=south,type=single,waterlogged=false],../JungleNBT/StructureLoot/Rare8.nbt,3,minecraft:chest[facing=south,type=single,waterlogged=false],../JungleNBT/StructureLoot/Rare9.nbt,3,minecraft:chest[facing=south,type=single,waterlogged=false],../JungleNBT/StructureLoot/Rare10.nbt,3,minecraft:chest[facing=south,type=single,waterlogged=false],../JungleNBT/StructureLoot/Rare11.nbt,3,minecraft:chest[facing=south,type=single,waterlogged=false],../JungleNBT/StructureLoot/Rare12.nbt,3,minecraft:chest[facing=south,type=single,waterlogged=false],../JungleNBT/StructureLoot/Rare13.nbt,3,minecraft:chest[facing=south,type=single,waterlogged=false],../JungleNBT/StructureLoot/Rare14.nbt,3,minecraft:chest[facing=south,type=single,waterlogged=false],../JungleNBT/StructureLoot/Rare15.nbt,3,minecraft:chest[facing=south,type=single,waterlogged=false],../JungleNBT/StructureLoot/Epic1.nbt,3,minecraft:chest[facing=south,type=single,waterlogged=false],../JungleNBT/StructureLoot/Epic2.nbt,3,minecraft:chest[facing=south,type=single,waterlogged=false],../JungleNBT/StructureLoot/Epic3.nbt,3,minecraft:chest[facing=south,type=single,waterlogged=false],../JungleNBT/StructureLoot/Epic4.nbt,3,minecraft:chest[facing=south,type=single,waterlogged=false],../JungleNBT/StructureLoot/Epic5.nbt,3,minecraft:chest[facing=south,type=single,waterlogged=false],../JungleNBT/StructureLoot/Epic6.nbt,3,minecraft:chest[facing=south,type=single,waterlogged=false],../JungleNBT/StructureLoot/Epic7.nbt,3,minecraft:chest[facing=south,type=single,waterlogged=false],../JungleNBT/StructureLoot/Epic8.nbt,3,minecraft:chest[facing=south,type=single,waterlogged=false],../JungleNBT/StructureLoot/Epic9.nbt,3,minecraft:chest[facing=south,type=single,waterlogged=false],../JungleNBT/StructureLoot/Epic10.nbt,3,minecraft:chest[facing=south,type=single,waterlogged=false],../JungleNBT/StructureLoot/Epic11.nbt,3,minecraft:chest[facing=south,type=single,waterlogged=false],../JungleNBT/StructureLoot/Epic12.nbt,3,minecraft:chest[facing=south,type=single,waterlogged=false],../JungleNBT/StructureLoot/Epic13.nbt,3,minecraft:chest[facing=south,type=single,waterlogged=false],../JungleNBT/StructureLoot/Epic14.nbt,3,minecraft:chest[facing=south,type=single,waterlogged=false],../JungleNBT/StructureLoot/Epic15.nbt,3,minecraft:chest[facing=south,type=single,waterlogged=false],../JungleNBT/LoreStoryline/JungleLore05.nbt,100)
RB(6,1,7,minecraft:chest[facing=south,type=single,waterlogged=false],../JungleNBT/LoreStoryline/MayaLore05.nbt,2,minecraft:chest[facing=south,type=single,waterlogged=false],../JungleNBT/LoreStoryline/MayaLore04.nbt,2,minecraft:chest[facing=south,type=single,waterlogged=false],../JungleNBT/LoreStoryline/MayaLore03.nbt,2,minecraft:chest[facing=south,type=single,waterlogged=false],../JungleNBT/LoreStoryline/MayaLore02.nbt,2,minecraft:chest[facing=south,type=single,waterlogged=false],../JungleNBT/LoreStoryline/MayaLore01.nbt,2,minecraft:chest[facing=south,type=single,waterlogged=false],../JungleNBT/StructureLoot/Common1.nbt,3,minecraft:chest[facing=south,type=single,waterlogged=false],../JungleNBT/StructureLoot/Common2.nbt,3,minecraft:chest[facing=south,type=single,waterlogged=false],../JungleNBT/StructureLoot/Common3.nbt,3,minecraft:chest[facing=south,type=single,waterlogged=false],../JungleNBT/StructureLoot/Common4.nbt,3,minecraft:chest[facing=south,type=single,waterlogged=false],../JungleNBT/StructureLoot/Common5.nbt,3,minecraft:chest[facing=south,type=single,waterlogged=false],../JungleNBT/StructureLoot/Common5.nbt,3,minecraft:chest[facing=south,type=single,waterlogged=false],../JungleNBT/StructureLoot/Common6.nbt,3,minecraft:chest[facing=south,type=single,waterlogged=false],../JungleNBT/StructureLoot/Common7.nbt,3,minecraft:chest[facing=south,type=single,waterlogged=false],../JungleNBT/StructureLoot/Common8.nbt,3,minecraft:chest[facing=south,type=single,waterlogged=false],../JungleNBT/StructureLoot/Common9.nbt,3,minecraft:chest[facing=south,type=single,waterlogged=false],../JungleNBT/StructureLoot/Common10.nbt,3,minecraft:chest[facing=south,type=single,waterlogged=false],../JungleNBT/StructureLoot/Common11.nbt,3,minecraft:chest[facing=south,type=single,waterlogged=false],../JungleNBT/StructureLoot/Common12.nbt,3,minecraft:chest[facing=south,type=single,waterlogged=false],../JungleNBT/StructureLoot/Common13.nbt,3,minecraft:chest[facing=south,type=single,waterlogged=false],../JungleNBT/StructureLoot/Common14.nbt,3,minecraft:chest[facing=south,type=single,waterlogged=false],../JungleNBT/StructureLoot/Common15.nbt,3,minecraft:chest[facing=south,type=single,waterlogged=false],../JungleNBT/StructureLoot/Rare1.nbt,3,minecraft:chest[facing=south,type=single,waterlogged=false],../JungleNBT/StructureLoot/Rare2.nbt,3,minecraft:chest[facing=south,type=single,waterlogged=false],../JungleNBT/StructureLoot/Rare3.nbt,3,minecraft:chest[facing=south,type=single,waterlogged=false],../JungleNBT/StructureLoot/Rare4.nbt,3,minecraft:chest[facing=south,type=single,waterlogged=false],../JungleNBT/StructureLoot/Rare5.nbt,3,minecraft:chest[facing=south,type=single,waterlogged=false],../JungleNBT/StructureLoot/Rare6.nbt,3,minecraft:chest[facing=south,type=single,waterlogged=false],../JungleNBT/StructureLoot/Rare7.nbt,3,minecraft:chest[facing=south,type=single,waterlogged=false],../JungleNBT/StructureLoot/Rare8.nbt,3,minecraft:chest[facing=south,type=single,waterlogged=false],../JungleNBT/StructureLoot/Rare9.nbt,3,minecraft:chest[facing=south,type=single,waterlogged=false],../JungleNBT/StructureLoot/Rare10.nbt,3,minecraft:chest[facing=south,type=single,waterlogged=false],../JungleNBT/StructureLoot/Rare11.nbt,3,minecraft:chest[facing=south,type=single,waterlogged=false],../JungleNBT/StructureLoot/Rare12.nbt,3,minecraft:chest[facing=south,type=single,waterlogged=false],../JungleNBT/StructureLoot/Rare13.nbt,3,minecraft:chest[facing=south,type=single,waterlogged=false],../JungleNBT/StructureLoot/Rare14.nbt,3,minecraft:chest[facing=south,type=single,waterlogged=false],../JungleNBT/StructureLoot/Rare15.nbt,3,minecraft:chest[facing=south,type=single,waterlogged=false],../JungleNBT/StructureLoot/Epic1.nbt,3,minecraft:chest[facing=south,type=single,waterlogged=false],../JungleNBT/StructureLoot/Epic2.nbt,3,minecraft:chest[facing=south,type=single,waterlogged=false],../JungleNBT/StructureLoot/Epic3.nbt,3,minecraft:chest[facing=south,type=single,waterlogged=false],../JungleNBT/StructureLoot/Epic4.nbt,3,minecraft:chest[facing=south,type=single,waterlogged=false],../JungleNBT/StructureLoot/Epic5.nbt,3,minecraft:chest[facing=south,type=single,waterlogged=false],../JungleNBT/StructureLoot/Epic6.nbt,3,minecraft:chest[facing=south,type=single,waterlogged=false],../JungleNBT/StructureLoot/Epic7.nbt,3,minecraft:chest[facing=south,type=single,waterlogged=false],../JungleNBT/StructureLoot/Epic8.nbt,3,minecraft:chest[facing=south,type=single,waterlogged=false],../JungleNBT/StructureLoot/Epic9.nbt,3,minecraft:chest[facing=south,type=single,waterlogged=false],../JungleNBT/StructureLoot/Epic10.nbt,3,minecraft:chest[facing=south,type=single,waterlogged=false],../JungleNBT/StructureLoot/Epic11.nbt,3,minecraft:chest[facing=south,type=single,waterlogged=false],../JungleNBT/StructureLoot/Epic12.nbt,3,minecraft:chest[facing=south,type=single,waterlogged=false],../JungleNBT/StructureLoot/Epic13.nbt,3,minecraft:chest[facing=south,type=single,waterlogged=false],../JungleNBT/StructureLoot/Epic14.nbt,3,minecraft:chest[facing=south,type=single,waterlogged=false],../JungleNBT/StructureLoot/Epic15.nbt,3,minecraft:chest[facing=south,type=single,waterlogged=false],../JungleNBT/LoreStoryline/JungleLore05.nbt,100)
RB(-7,2,4,minecraft:mossy_stone_bricks,10,minecraft:cracked_stone_bricks,10,minecraft:cobblestone,10,minecraft:mossy_cobblestone,10,minecraft:stone_bricks,100)
RB(-6,2,4,minecraft:mossy_stone_bricks,10,minecraft:cracked_stone_bricks,10,minecraft:cobblestone,10,minecraft:mossy_cobblestone,10,minecraft:stone_bricks,100)
RB(-5,2,4,minecraft:mossy_stone_bricks,10,minecraft:cracked_stone_bricks,10,minecraft:cobblestone,10,minecraft:mossy_cobblestone,10,minecraft:stone_bricks,100)
RB(-4,2,4,minecraft:mossy_stone_bricks,10,minecraft:cracked_stone_bricks,10,minecraft:cobblestone,10,minecraft:mossy_cobblestone,10,minecraft:stone_bricks,100)
RB(-3,2,4,minecraft:mossy_stone_bricks,10,minecraft:cracked_stone_bricks,10,minecraft:cobblestone,10,minecraft:mossy_cobblestone,10,minecraft:stone_bricks,100)
RB(-2,2,4,minecraft:mossy_stone_bricks,10,minecraft:cracked_stone_bricks,10,minecraft:cobblestone,10,minecraft:mossy_cobblestone,10,minecraft:stone_bricks,100)
RB(-1,2,4,minecraft:mossy_stone_bricks,10,minecraft:cracked_stone_bricks,10,minecraft:cobblestone,10,minecraft:mossy_cobblestone,10,minecraft:stone_bricks,100)
RB(0,2,4,minecraft:mossy_stone_bricks,10,minecraft:cracked_stone_bricks,10,minecraft:cobblestone,10,minecraft:mossy_cobblestone,10,minecraft:stone_bricks,100)
RB(1,2,4,minecraft:mossy_stone_bricks,10,minecraft:cracked_stone_bricks,10,minecraft:cobblestone,10,minecraft:mossy_cobblestone,10,minecraft:stone_bricks,100)
RB(2,2,4,minecraft:mossy_stone_bricks,10,minecraft:cracked_stone_bricks,10,minecraft:cobblestone,10,minecraft:mossy_cobblestone,10,minecraft:stone_bricks,100)
RB(3,2,4,minecraft:mossy_stone_bricks,10,minecraft:cracked_stone_bricks,10,minecraft:cobblestone,10,minecraft:mossy_cobblestone,10,minecraft:stone_bricks,100)
RB(4,2,4,minecraft:mossy_stone_bricks,10,minecraft:cracked_stone_bricks,10,minecraft:cobblestone,10,minecraft:mossy_cobblestone,10,minecraft:stone_bricks,100)
RB(5,2,4,minecraft:mossy_stone_bricks,10,minecraft:cracked_stone_bricks,10,minecraft:cobblestone,10,minecraft:mossy_cobblestone,10,minecraft:stone_bricks,100)
RB(6,2,4,minecraft:mossy_stone_bricks,10,minecraft:cracked_stone_bricks,10,minecraft:cobblestone,10,minecraft:mossy_cobblestone,10,minecraft:stone_bricks,100)
RB(7,2,4,minecraft:mossy_stone_bricks,10,minecraft:cracked_stone_bricks,10,minecraft:cobblestone,10,minecraft:mossy_cobblestone,10,minecraft:stone_bricks,100)
RB(8,2,4,minecraft:mossy_stone_bricks,10,minecraft:cracked_stone_bricks,10,minecraft:cobblestone,10,minecraft:mossy_cobblestone,10,minecraft:stone_bricks,100)
RB(-7,2,5,minecraft:mossy_stone_bricks,10,minecraft:cracked_stone_bricks,10,minecraft:cobblestone,10,minecraft:mossy_cobblestone,10,minecraft:stone_bricks,100)
RB(-6,2,5,minecraft:mossy_stone_bricks,10,minecraft:cracked_stone_bricks,10,minecraft:cobblestone,10,minecraft:mossy_cobblestone,10,minecraft:stone_bricks,100)
RB(-5,2,5,minecraft:mossy_stone_bricks,10,minecraft:cracked_stone_bricks,10,minecraft:cobblestone,10,minecraft:mossy_cobblestone,10,minecraft:stone_bricks,100)
RB(-4,2,5,minecraft:mossy_stone_bricks,10,minecraft:cracked_stone_bricks,10,minecraft:cobblestone,10,minecraft:mossy_cobblestone,10,minecraft:stone_bricks,100)
RB(-3,2,5,minecraft:mossy_stone_bricks,10,minecraft:cracked_stone_bricks,10,minecraft:cobblestone,10,minecraft:mossy_cobblestone,10,minecraft:stone_bricks,100)
RB(-2,2,5,minecraft:mossy_stone_bricks,10,minecraft:cracked_stone_bricks,10,minecraft:cobblestone,10,minecraft:mossy_cobblestone,10,minecraft:stone_bricks,100)
RB(-1,2,5,minecraft:mossy_stone_bricks,10,minecraft:cracked_stone_bricks,10,minecraft:cobblestone,10,minecraft:mossy_cobblestone,10,minecraft:stone_bricks,100)
RB(0,2,5,minecraft:mossy_stone_bricks,10,minecraft:cracked_stone_bricks,10,minecraft:cobblestone,10,minecraft:mossy_cobblestone,10,minecraft:stone_bricks,100)
RB(1,2,5,minecraft:mossy_stone_bricks,10,minecraft:cracked_stone_bricks,10,minecraft:cobblestone,10,minecraft:mossy_cobblestone,10,minecraft:stone_bricks,100)
RB(2,2,5,minecraft:mossy_stone_bricks,10,minecraft:cracked_stone_bricks,10,minecraft:cobblestone,10,minecraft:mossy_cobblestone,10,minecraft:stone_bricks,100)
RB(3,2,5,minecraft:mossy_stone_bricks,10,minecraft:cracked_stone_bricks,10,minecraft:cobblestone,10,minecraft:mossy_cobblestone,10,minecraft:stone_bricks,100)
RB(4,2,5,minecraft:mossy_stone_bricks,10,minecraft:cracked_stone_bricks,10,minecraft:cobblestone,10,minecraft:mossy_cobblestone,10,minecraft:stone_bricks,100)
RB(5,2,5,minecraft:mossy_stone_bricks,10,minecraft:cracked_stone_bricks,10,minecraft:cobblestone,10,minecraft:mossy_cobblestone,10,minecraft:stone_bricks,100)
RB(6,2,5,minecraft:mossy_stone_bricks,10,minecraft:cracked_stone_bricks,10,minecraft:cobblestone,10,minecraft:mossy_cobblestone,10,minecraft:stone_bricks,100)
RB(7,2,5,minecraft:mossy_stone_bricks,10,minecraft:cracked_stone_bricks,10,minecraft:cobblestone,10,minecraft:mossy_cobblestone,10,minecraft:stone_bricks,100)
RB(8,2,5,minecraft:mossy_stone_bricks,10,minecraft:cracked_stone_bricks,10,minecraft:cobblestone,10,minecraft:mossy_cobblestone,10,minecraft:stone_bricks,100)
RB(-7,2,6,minecraft:mossy_stone_bricks,10,minecraft:cracked_stone_bricks,10,minecraft:cobblestone,10,minecraft:mossy_cobblestone,10,minecraft:stone_bricks,100)
RB(-6,2,6,minecraft:mossy_stone_bricks,10,minecraft:cracked_stone_bricks,10,minecraft:cobblestone,10,minecraft:mossy_cobblestone,10,minecraft:stone_bricks,100)
RB(-5,2,6,minecraft:mossy_stone_bricks,10,minecraft:cracked_stone_bricks,10,minecraft:cobblestone,10,minecraft:mossy_cobblestone,10,minecraft:stone_bricks,100)
RB(-4,2,6,minecraft:mossy_stone_bricks,10,minecraft:cracked_stone_bricks,10,minecraft:cobblestone,10,minecraft:mossy_cobblestone,10,minecraft:stone_bricks,100)
RB(-3,2,6,minecraft:mossy_stone_bricks,10,minecraft:cracked_stone_bricks,10,minecraft:cobblestone,10,minecraft:mossy_cobblestone,10,minecraft:stone_bricks,100)
RB(-2,2,6,minecraft:mossy_stone_bricks,10,minecraft:cracked_stone_bricks,10,minecraft:cobblestone,10,minecraft:mossy_cobblestone,10,minecraft:stone_bricks,100)
RB(-1,2,6,minecraft:mossy_stone_bricks,10,minecraft:cracked_stone_bricks,10,minecraft:cobblestone,10,minecraft:mossy_cobblestone,10,minecraft:stone_bricks,100)
RB(0,2,6,minecraft:mossy_stone_bricks,10,minecraft:cracked_stone_bricks,10,minecraft:cobblestone,10,minecraft:mossy_cobblestone,10,minecraft:stone_bricks,100)
RB(1,2,6,minecraft:mossy_stone_bricks,10,minecraft:cracked_stone_bricks,10,minecraft:cobblestone,10,minecraft:mossy_cobblestone,10,minecraft:stone_bricks,100)
RB(2,2,6,minecraft:mossy_stone_bricks,10,minecraft:cracked_stone_bricks,10,minecraft:cobblestone,10,minecraft:mossy_cobblestone,10,minecraft:stone_bricks,100)
RB(3,2,6,minecraft:mossy_stone_bricks,10,minecraft:cracked_stone_bricks,10,minecraft:cobblestone,10,minecraft:mossy_cobblestone,10,minecraft:stone_bricks,100)
RB(4,2,6,minecraft:mossy_stone_bricks,10,minecraft:cracked_stone_bricks,10,minecraft:cobblestone,10,minecraft:mossy_cobblestone,10,minecraft:stone_bricks,100)
RB(5,2,6,minecraft:mossy_stone_bricks,10,minecraft:cracked_stone_bricks,10,minecraft:cobblestone,10,minecraft:mossy_cobblestone,10,minecraft:stone_bricks,100)
RB(6,2,6,minecraft:mossy_stone_bricks,10,minecraft:cracked_stone_bricks,10,minecraft:cobblestone,10,minecraft:mossy_cobblestone,10,minecraft:stone_bricks,100)
RB(7,2,6,minecraft:mossy_stone_bricks,10,minecraft:cracked_stone_bricks,10,minecraft:cobblestone,10,minecraft:mossy_cobblestone,10,minecraft:stone_bricks,100)
RB(8,2,6,minecraft:mossy_stone_bricks,10,minecraft:cracked_stone_bricks,10,minecraft:cobblestone,10,minecraft:mossy_cobblestone,10,minecraft:stone_bricks,100)
RB(-5,3,4,minecraft:mossy_stone_bricks,10,minecraft:cracked_stone_bricks,10,minecraft:cobblestone,10,minecraft:mossy_cobblestone,10,minecraft:stone_bricks,100)
RB(1,3,4,minecraft:mossy_stone_bricks,10,minecraft:cracked_stone_bricks,10,minecraft:cobblestone,10,minecraft:mossy_cobblestone,10,minecraft:stone_bricks,100)
RB(4,3,4,minecraft:mossy_stone_bricks,10,minecraft:cracked_stone_bricks,10,minecraft:cobblestone,10,minecraft:mossy_cobblestone,10,minecraft:stone_bricks,100)
RB(-7,3,5,minecraft:mossy_stone_bricks,10,minecraft:cracked_stone_bricks,10,minecraft:cobblestone,10,minecraft:mossy_cobblestone,10,minecraft:stone_bricks,100)
RB(-6,3,5,minecraft:mossy_stone_bricks,10,minecraft:cracked_stone_bricks,10,minecraft:cobblestone,10,minecraft:mossy_cobblestone,10,minecraft:stone_bricks,100)
RB(-5,3,5,minecraft:mossy_stone_bricks,10,minecraft:cracked_stone_bricks,10,minecraft:cobblestone,10,minecraft:mossy_cobblestone,10,minecraft:stone_bricks,100)
RB(-4,3,5,minecraft:mossy_stone_bricks,10,minecraft:cracked_stone_bricks,10,minecraft:cobblestone,10,minecraft:mossy_cobblestone,10,minecraft:stone_bricks,100)
RB(-3,3,5,minecraft:mossy_stone_bricks,10,minecraft:cracked_stone_bricks,10,minecraft:cobblestone,10,minecraft:mossy_cobblestone,10,minecraft:stone_bricks,100)
RB(-2,3,5,minecraft:mossy_stone_bricks,10,minecraft:cracked_stone_bricks,10,minecraft:cobblestone,10,minecraft:mossy_cobblestone,10,minecraft:stone_bricks,100)
RB(-1,3,5,minecraft:mossy_stone_bricks,10,minecraft:cracked_stone_bricks,10,minecraft:cobblestone,10,minecraft:mossy_cobblestone,10,minecraft:stone_bricks,100)
RB(0,3,5,minecraft:mossy_stone_bricks,10,minecraft:cracked_stone_bricks,10,minecraft:cobblestone,10,minecraft:mossy_cobblestone,10,minecraft:stone_bricks,100)
RB(1,3,5,minecraft:mossy_stone_bricks,10,minecraft:cracked_stone_bricks,10,minecraft:cobblestone,10,minecraft:mossy_cobblestone,10,minecraft:stone_bricks,100)
RB(2,3,5,minecraft:mossy_stone_bricks,10,minecraft:cracked_stone_bricks,10,minecraft:cobblestone,10,minecraft:mossy_cobblestone,10,minecraft:stone_bricks,100)
RB(3,3,5,minecraft:mossy_stone_bricks,10,minecraft:cracked_stone_bricks,10,minecraft:cobblestone,10,minecraft:mossy_cobblestone,10,minecraft:stone_bricks,100)
RB(4,3,5,minecraft:mossy_stone_bricks,10,minecraft:cracked_stone_bricks,10,minecraft:cobblestone,10,minecraft:mossy_cobblestone,10,minecraft:stone_bricks,100)
RB(5,3,5,minecraft:mossy_stone_bricks,10,minecraft:cracked_stone_bricks,10,minecraft:cobblestone,10,minecraft:mossy_cobblestone,10,minecraft:stone_bricks,100)
RB(8,3,5,minecraft:mossy_stone_bricks,10,minecraft:cracked_stone_bricks,10,minecraft:cobblestone,10,minecraft:mossy_cobblestone,10,minecraft:stone_bricks,100)
RB(-7,3,8,minecraft:mossy_stone_bricks,10,minecraft:cracked_stone_bricks,10,minecraft:cobblestone,10,minecraft:mossy_cobblestone,10,minecraft:stone_bricks,100)
RB(-6,3,8,minecraft:mossy_stone_bricks,10,minecraft:cracked_stone_bricks,10,minecraft:cobblestone,10,minecraft:mossy_cobblestone,10,minecraft:stone_bricks,100)
RB(-5,3,8,minecraft:mossy_stone_bricks,10,minecraft:cracked_stone_bricks,10,minecraft:cobblestone,10,minecraft:mossy_cobblestone,10,minecraft:stone_bricks,100)
RB(-4,3,8,minecraft:mossy_stone_bricks,10,minecraft:cracked_stone_bricks,10,minecraft:cobblestone,10,minecraft:mossy_cobblestone,10,minecraft:stone_bricks,100)
RB(-3,3,8,minecraft:mossy_stone_bricks,10,minecraft:cracked_stone_bricks,10,minecraft:cobblestone,10,minecraft:mossy_cobblestone,10,minecraft:stone_bricks,100)
RB(-2,3,8,minecraft:mossy_stone_bricks,10,minecraft:cracked_stone_bricks,10,minecraft:cobblestone,10,minecraft:mossy_cobblestone,10,minecraft:stone_bricks,100)
RB(-1,3,8,minecraft:mossy_stone_bricks,10,minecraft:cracked_stone_bricks,10,minecraft:cobblestone,10,minecraft:mossy_cobblestone,10,minecraft:stone_bricks,100)
RB(0,3,8,minecraft:mossy_stone_bricks,10,minecraft:cracked_stone_bricks,10,minecraft:cobblestone,10,minecraft:mossy_cobblestone,10,minecraft:stone_bricks,100)
RB(1,3,8,minecraft:mossy_stone_bricks,10,minecraft:cracked_stone_bricks,10,minecraft:cobblestone,10,minecraft:mossy_cobblestone,10,minecraft:stone_bricks,100)
RB(2,3,8,minecraft:mossy_stone_bricks,10,minecraft:cracked_stone_bricks,10,minecraft:cobblestone,10,minecraft:mossy_cobblestone,10,minecraft:stone_bricks,100)
RB(3,3,8,minecraft:mossy_stone_bricks,10,minecraft:cracked_stone_bricks,10,minecraft:cobblestone,10,minecraft:mossy_cobblestone,10,minecraft:stone_bricks,100)
RB(4,3,8,minecraft:mossy_stone_bricks,10,minecraft:cracked_stone_bricks,10,minecraft:cobblestone,10,minecraft:mossy_cobblestone,10,minecraft:stone_bricks,100)
RB(5,3,8,minecraft:mossy_stone_bricks,10,minecraft:cracked_stone_bricks,10,minecraft:cobblestone,10,minecraft:mossy_cobblestone,10,minecraft:stone_bricks,100)
RB(6,3,8,minecraft:mossy_stone_bricks,10,minecraft:cracked_stone_bricks,10,minecraft:cobblestone,10,minecraft:mossy_cobblestone,10,minecraft:stone_bricks,100)
RB(7,3,8,minecraft:mossy_stone_bricks,10,minecraft:cracked_stone_bricks,10,minecraft:cobblestone,10,minecraft:mossy_cobblestone,10,minecraft:stone_bricks,100)
RB(-5,4,8,minecraft:mossy_stone_bricks,10,minecraft:cracked_stone_bricks,10,minecraft:cobblestone,10,minecraft:mossy_cobblestone,10,minecraft:stone_bricks,100)
RB(-2,4,8,minecraft:mossy_stone_bricks,10,minecraft:cracked_stone_bricks,10,minecraft:cobblestone,10,minecraft:mossy_cobblestone,10,minecraft:stone_bricks,100)
RB(1,4,8,minecraft:mossy_stone_bricks,10,minecraft:cracked_stone_bricks,10,minecraft:cobblestone,10,minecraft:mossy_cobblestone,10,minecraft:stone_bricks,100)
RB(4,4,8,minecraft:mossy_stone_bricks,10,minecraft:cracked_stone_bricks,10,minecraft:cobblestone,10,minecraft:mossy_cobblestone,10,minecraft:stone_bricks,100)
RB(7,4,8,minecraft:mossy_stone_bricks,10,minecraft:cracked_stone_bricks,10,minecraft:cobblestone,10,minecraft:mossy_cobblestone,10,minecraft:stone_bricks,100)
RB(-5,5,8,minecraft:mossy_stone_bricks,10,minecraft:cracked_stone_bricks,10,minecraft:cobblestone,10,minecraft:mossy_cobblestone,10,minecraft:stone_bricks,100)
RB(-2,5,8,minecraft:mossy_stone_bricks,10,minecraft:cracked_stone_bricks,10,minecraft:cobblestone,10,minecraft:mossy_cobblestone,10,minecraft:stone_bricks,100)
RB(1,5,8,minecraft:mossy_stone_bricks,10,minecraft:cracked_stone_bricks,10,minecraft:cobblestone,10,minecraft:mossy_cobblestone,10,minecraft:stone_bricks,100)
RB(4,5,8,minecraft:mossy_stone_bricks,10,minecraft:cracked_stone_bricks,10,minecraft:cobblestone,10,minecraft:mossy_cobblestone,10,minecraft:stone_bricks,100)
RB(7,5,8,minecraft:mossy_stone_bricks,10,minecraft:cracked_stone_bricks,10,minecraft:cobblestone,10,minecraft:mossy_cobblestone,10,minecraft:stone_bricks,100)

#######################################################################
# +-----------------------------------------------------------------+ #
# |                            BO3 checks                           | #
# +-----------------------------------------------------------------+ #
#######################################################################


#######################################################################
# +-----------------------------------------------------------------+ #
# |                             Branches                            | #
# +-----------------------------------------------------------------+ #
#######################################################################


#######################################################################
# +-----------------------------------------------------------------+ #
# |                             Entities                            | #
# +-----------------------------------------------------------------+ #
#######################################################################

Entity(-6,4,6,minecraft:villager,1,../JungleNBT/entities/tribalruinsguard.txt)
Entity(5,4,6,minecraft:villager,1,../JungleNBT/entities/tribalruinsguard.txt)
