
#######################################################################
# +-----------------------------------------------------------------+ #
# |                            BO3 object                           | #
# +-----------------------------------------------------------------+ #
#######################################################################

Author: Bo3 BulkEdit

Description: Converted Schematic - Modified by Bo3BulkEdit

Version: 3

SettingsMode: WriteWithoutComments


#######################################################################
# +-----------------------------------------------------------------+ #
# |                          Main settings                          | #
# +-----------------------------------------------------------------+ #
#######################################################################

Tree: false

Frequency: 1

Rarity: 100.0

RotateRandomly: false

SpawnHeight: randomY

SpawnHeightOffset: 0

SpawnHeightVariance: 0

##############################
# Height Limits for the BO3. #
##############################

MinHeight: 0

MaxHeight: 255

######################
# Extrusion settings #
######################

ExtrudeMode: None

ExtrudeThroughBlocks: minecraft:air

MaxBranchDepth: 20


#######################################################################
# +-----------------------------------------------------------------+ #
# |                      Source block settings                      | #
# +-----------------------------------------------------------------+ #
#######################################################################

SourceBlocks: otg:air

MaxPercentageOutsideSourceBlock: 100

OutsideSourceBlock: placeAnyway

DoReplaceBlocks: true

IsOTGPlus: false


#######################################################################
# +-----------------------------------------------------------------+ #
# |                              Blocks                             | #
# +-----------------------------------------------------------------+ #
#######################################################################

B(-8,-3,-8,minecraft:oak_slab[type=top,waterlogged=false])
B(-8,-3,-7,minecraft:oak_slab[type=top,waterlogged=false])
B(-8,-51,-6,minecraft:spruce_log[axis=x])
B(-8,-47,-6,minecraft:spruce_log[axis=x])
B(-8,-43,-6,minecraft:spruce_log[axis=x])
B(-8,-39,-6,minecraft:spruce_log[axis=x])
B(-8,-35,-6,minecraft:spruce_log[axis=x])
B(-8,-31,-6,minecraft:spruce_log[axis=x])
B(-8,-27,-6,minecraft:spruce_log[axis=x])
B(-8,-23,-6,minecraft:spruce_log[axis=x])
B(-8,-19,-6,minecraft:spruce_log[axis=x])
B(-8,-15,-6,minecraft:spruce_log[axis=x])
B(-8,-11,-6,minecraft:spruce_log[axis=x])
B(-8,-7,-6,minecraft:spruce_log[axis=x])
B(-8,-6,-6,minecraft:spruce_log[axis=x])
B(-8,-3,-6,minecraft:oak_slab[type=double,waterlogged=false])
B(-8,-3,-5,minecraft:oak_slab[type=top,waterlogged=false])
B(-8,-3,-4,minecraft:oak_slab[type=top,waterlogged=false])
B(-8,-53,-3,minecraft:spruce_log[axis=x])
B(-8,-51,-3,minecraft:spruce_log[axis=x])
B(-8,-49,-3,minecraft:spruce_log[axis=x])
B(-8,-47,-3,minecraft:spruce_log[axis=x])
B(-8,-45,-3,minecraft:spruce_log[axis=x])
B(-8,-43,-3,minecraft:spruce_log[axis=x])
B(-8,-41,-3,minecraft:spruce_log[axis=x])
B(-8,-39,-3,minecraft:spruce_log[axis=x])
B(-8,-37,-3,minecraft:spruce_log[axis=x])
B(-8,-35,-3,minecraft:spruce_log[axis=x])
B(-8,-33,-3,minecraft:spruce_log[axis=x])
B(-8,-31,-3,minecraft:spruce_log[axis=x])
B(-8,-29,-3,minecraft:spruce_log[axis=x])
B(-8,-27,-3,minecraft:spruce_log[axis=x])
B(-8,-25,-3,minecraft:spruce_log[axis=x])
B(-8,-23,-3,minecraft:spruce_log[axis=x])
B(-8,-21,-3,minecraft:spruce_log[axis=x])
B(-8,-19,-3,minecraft:spruce_log[axis=x])
B(-8,-17,-3,minecraft:spruce_log[axis=x])
B(-8,-15,-3,minecraft:spruce_log[axis=x])
B(-8,-13,-3,minecraft:spruce_log[axis=x])
B(-8,-11,-3,minecraft:spruce_log[axis=x])
B(-8,-9,-3,minecraft:spruce_log[axis=x])
B(-8,-7,-3,minecraft:spruce_log[axis=x])
B(-8,-6,-3,minecraft:spruce_log[axis=x])
B(-8,-3,-3,minecraft:oak_slab[type=double,waterlogged=false])
B(-8,-3,-2,minecraft:oak_slab[type=top,waterlogged=false])
B(-8,-2,-2,minecraft:coal_ore)
B(-8,-3,-1,minecraft:oak_slab[type=top,waterlogged=false])
B(-8,-2,-1,minecraft:coal_ore)
B(-7,-3,-8,minecraft:oak_slab[type=top,waterlogged=false])
B(-7,-3,-7,minecraft:oak_slab[type=top,waterlogged=false])
B(-7,-51,-6,minecraft:spruce_log[axis=x])
B(-7,-47,-6,minecraft:spruce_log[axis=x])
B(-7,-43,-6,minecraft:spruce_log[axis=x])
B(-7,-39,-6,minecraft:spruce_log[axis=x])
B(-7,-35,-6,minecraft:spruce_log[axis=x])
B(-7,-31,-6,minecraft:spruce_log[axis=x])
B(-7,-27,-6,minecraft:spruce_log[axis=x])
B(-7,-23,-6,minecraft:spruce_log[axis=x])
B(-7,-19,-6,minecraft:spruce_log[axis=x])
B(-7,-15,-6,minecraft:spruce_log[axis=x])
B(-7,-11,-6,minecraft:spruce_log[axis=x])
B(-7,-7,-6,minecraft:spruce_log[axis=x])
B(-7,-6,-6,minecraft:spruce_log[axis=x])
B(-7,-3,-6,minecraft:oak_slab[type=double,waterlogged=false])
B(-7,-3,-5,minecraft:oak_slab[type=top,waterlogged=false])
B(-7,-3,-4,minecraft:oak_slab[type=top,waterlogged=false])
B(-7,-2,-4,minecraft:coal_ore)
B(-7,-53,-3,minecraft:spruce_log[axis=x])
B(-7,-51,-3,minecraft:spruce_log[axis=x])
B(-7,-49,-3,minecraft:spruce_log[axis=x])
B(-7,-47,-3,minecraft:spruce_log[axis=x])
B(-7,-45,-3,minecraft:spruce_log[axis=x])
B(-7,-43,-3,minecraft:spruce_log[axis=x])
B(-7,-41,-3,minecraft:spruce_log[axis=x])
B(-7,-39,-3,minecraft:spruce_log[axis=x])
B(-7,-37,-3,minecraft:spruce_log[axis=x])
B(-7,-35,-3,minecraft:spruce_log[axis=x])
B(-7,-33,-3,minecraft:spruce_log[axis=x])
B(-7,-31,-3,minecraft:spruce_log[axis=x])
B(-7,-29,-3,minecraft:spruce_log[axis=x])
B(-7,-27,-3,minecraft:spruce_log[axis=x])
B(-7,-25,-3,minecraft:spruce_log[axis=x])
B(-7,-23,-3,minecraft:spruce_log[axis=x])
B(-7,-21,-3,minecraft:spruce_log[axis=x])
B(-7,-19,-3,minecraft:spruce_log[axis=x])
B(-7,-17,-3,minecraft:spruce_log[axis=x])
B(-7,-15,-3,minecraft:spruce_log[axis=x])
B(-7,-13,-3,minecraft:spruce_log[axis=x])
B(-7,-11,-3,minecraft:spruce_log[axis=x])
B(-7,-9,-3,minecraft:spruce_log[axis=x])
B(-7,-7,-3,minecraft:spruce_log[axis=x])
B(-7,-6,-3,minecraft:spruce_log[axis=x])
B(-7,-3,-3,minecraft:oak_slab[type=double,waterlogged=false])
B(-7,-2,-3,minecraft:coal_ore)
B(-7,-1,-3,minecraft:coal_ore)
B(-7,-3,-2,minecraft:oak_slab[type=top,waterlogged=false])
B(-7,-2,-2,minecraft:coal_ore)
B(-7,-1,-2,minecraft:coal_ore)
B(-7,-3,-1,minecraft:oak_slab[type=top,waterlogged=false])
B(-7,-2,-1,minecraft:coal_ore)
B(-7,-1,-1,minecraft:coal_ore)
B(-6,-3,-8,minecraft:oak_slab[type=top,waterlogged=false])
B(-6,-3,-7,minecraft:oak_slab[type=top,waterlogged=false])
B(-6,-51,-6,minecraft:spruce_log[axis=x])
B(-6,-47,-6,minecraft:spruce_log[axis=x])
B(-6,-43,-6,minecraft:spruce_log[axis=x])
B(-6,-39,-6,minecraft:spruce_log[axis=x])
B(-6,-35,-6,minecraft:spruce_log[axis=x])
B(-6,-31,-6,minecraft:spruce_log[axis=x])
B(-6,-27,-6,minecraft:spruce_log[axis=x])
B(-6,-23,-6,minecraft:spruce_log[axis=x])
B(-6,-19,-6,minecraft:spruce_log[axis=x])
B(-6,-15,-6,minecraft:spruce_log[axis=x])
B(-6,-11,-6,minecraft:spruce_log[axis=x])
B(-6,-7,-6,minecraft:spruce_log[axis=x])
B(-6,-6,-6,minecraft:spruce_log[axis=x])
B(-6,-3,-6,minecraft:oak_slab[type=double,waterlogged=false])
B(-6,-2,-6,minecraft:iron_ore)
B(-6,-3,-5,minecraft:oak_slab[type=top,waterlogged=false])
B(-6,-2,-5,minecraft:iron_ore)
B(-6,-1,-5,minecraft:iron_ore)
B(-6,-3,-4,minecraft:oak_slab[type=top,waterlogged=false])
B(-6,-2,-4,minecraft:coal_ore)
B(-6,-53,-3,minecraft:spruce_log[axis=x])
B(-6,-51,-3,minecraft:spruce_log[axis=x])
B(-6,-49,-3,minecraft:spruce_log[axis=x])
B(-6,-47,-3,minecraft:spruce_log[axis=x])
B(-6,-45,-3,minecraft:spruce_log[axis=x])
B(-6,-43,-3,minecraft:spruce_log[axis=x])
B(-6,-41,-3,minecraft:spruce_log[axis=x])
B(-6,-39,-3,minecraft:spruce_log[axis=x])
B(-6,-37,-3,minecraft:spruce_log[axis=x])
B(-6,-35,-3,minecraft:spruce_log[axis=x])
B(-6,-33,-3,minecraft:spruce_log[axis=x])
B(-6,-31,-3,minecraft:spruce_log[axis=x])
B(-6,-29,-3,minecraft:spruce_log[axis=x])
B(-6,-27,-3,minecraft:spruce_log[axis=x])
B(-6,-25,-3,minecraft:spruce_log[axis=x])
B(-6,-23,-3,minecraft:spruce_log[axis=x])
B(-6,-21,-3,minecraft:spruce_log[axis=x])
B(-6,-19,-3,minecraft:spruce_log[axis=x])
B(-6,-17,-3,minecraft:spruce_log[axis=x])
B(-6,-15,-3,minecraft:spruce_log[axis=x])
B(-6,-13,-3,minecraft:spruce_log[axis=x])
B(-6,-11,-3,minecraft:spruce_log[axis=x])
B(-6,-9,-3,minecraft:spruce_log[axis=x])
B(-6,-7,-3,minecraft:spruce_log[axis=x])
B(-6,-6,-3,minecraft:spruce_log[axis=x])
B(-6,-3,-3,minecraft:oak_slab[type=double,waterlogged=false])
B(-6,-2,-3,minecraft:coal_ore)
B(-6,-1,-3,minecraft:coal_ore)
B(-6,-3,-2,minecraft:oak_slab[type=top,waterlogged=false])
B(-6,-2,-2,minecraft:coal_ore)
B(-6,-3,-1,minecraft:oak_slab[type=top,waterlogged=false])
B(-6,-2,-1,minecraft:coal_ore)
B(-6,0,-1,minecraft:spruce_fence[east=true,north=false,south=false,waterlogged=false,west=false])
B(-6,1,-1,minecraft:torch)
B(-5,-53,-8,minecraft:spruce_log[axis=z])
B(-5,-51,-8,minecraft:spruce_log[axis=z])
B(-5,-49,-8,minecraft:spruce_log[axis=z])
B(-5,-47,-8,minecraft:spruce_log[axis=z])
B(-5,-45,-8,minecraft:spruce_log[axis=z])
B(-5,-43,-8,minecraft:spruce_log[axis=z])
B(-5,-41,-8,minecraft:spruce_log[axis=z])
B(-5,-39,-8,minecraft:spruce_log[axis=z])
B(-5,-37,-8,minecraft:spruce_log[axis=z])
B(-5,-35,-8,minecraft:spruce_log[axis=z])
B(-5,-33,-8,minecraft:spruce_log[axis=z])
B(-5,-31,-8,minecraft:spruce_log[axis=z])
B(-5,-29,-8,minecraft:spruce_log[axis=z])
B(-5,-27,-8,minecraft:spruce_log[axis=z])
B(-5,-25,-8,minecraft:spruce_log[axis=z])
B(-5,-23,-8,minecraft:spruce_log[axis=z])
B(-5,-21,-8,minecraft:spruce_log[axis=z])
B(-5,-19,-8,minecraft:spruce_log[axis=z])
B(-5,-17,-8,minecraft:spruce_log[axis=z])
B(-5,-15,-8,minecraft:spruce_log[axis=z])
B(-5,-13,-8,minecraft:spruce_log[axis=z])
B(-5,-11,-8,minecraft:spruce_log[axis=z])
B(-5,-9,-8,minecraft:spruce_log[axis=z])
B(-5,-7,-8,minecraft:spruce_log[axis=z])
B(-5,-6,-8,minecraft:spruce_log[axis=z])
B(-5,-3,-8,minecraft:spruce_log[axis=z])
B(-5,-53,-7,minecraft:spruce_log[axis=z])
B(-5,-51,-7,minecraft:spruce_log[axis=z])
B(-5,-49,-7,minecraft:spruce_log[axis=z])
B(-5,-47,-7,minecraft:spruce_log[axis=z])
B(-5,-45,-7,minecraft:spruce_log[axis=z])
B(-5,-43,-7,minecraft:spruce_log[axis=z])
B(-5,-41,-7,minecraft:spruce_log[axis=z])
B(-5,-39,-7,minecraft:spruce_log[axis=z])
B(-5,-37,-7,minecraft:spruce_log[axis=z])
B(-5,-35,-7,minecraft:spruce_log[axis=z])
B(-5,-33,-7,minecraft:spruce_log[axis=z])
B(-5,-31,-7,minecraft:spruce_log[axis=z])
B(-5,-29,-7,minecraft:spruce_log[axis=z])
B(-5,-27,-7,minecraft:spruce_log[axis=z])
B(-5,-25,-7,minecraft:spruce_log[axis=z])
B(-5,-23,-7,minecraft:spruce_log[axis=z])
B(-5,-21,-7,minecraft:spruce_log[axis=z])
B(-5,-19,-7,minecraft:spruce_log[axis=z])
B(-5,-17,-7,minecraft:spruce_log[axis=z])
B(-5,-15,-7,minecraft:spruce_log[axis=z])
B(-5,-13,-7,minecraft:spruce_log[axis=z])
B(-5,-11,-7,minecraft:spruce_log[axis=z])
B(-5,-9,-7,minecraft:spruce_log[axis=z])
B(-5,-7,-7,minecraft:spruce_log[axis=z])
B(-5,-6,-7,minecraft:spruce_log[axis=z])
B(-5,-3,-7,minecraft:spruce_log[axis=z])
B(-5,-2,-7,minecraft:spruce_fence[east=true,north=false,south=false,waterlogged=false,west=false])
B(-5,-54,-6,minecraft:spruce_log)
B(-5,-53,-6,minecraft:spruce_log)
B(-5,-52,-6,minecraft:spruce_log)
B(-5,-51,-6,minecraft:spruce_log)
B(-5,-50,-6,minecraft:spruce_log)
B(-5,-49,-6,minecraft:spruce_log)
B(-5,-48,-6,minecraft:spruce_log)
B(-5,-47,-6,minecraft:spruce_log)
B(-5,-46,-6,minecraft:spruce_log)
B(-5,-45,-6,minecraft:spruce_log)
B(-5,-44,-6,minecraft:spruce_log)
B(-5,-43,-6,minecraft:spruce_log)
B(-5,-42,-6,minecraft:spruce_log)
B(-5,-41,-6,minecraft:spruce_log)
B(-5,-40,-6,minecraft:spruce_log)
B(-5,-39,-6,minecraft:spruce_log)
B(-5,-38,-6,minecraft:spruce_log)
B(-5,-37,-6,minecraft:spruce_log)
B(-5,-36,-6,minecraft:spruce_log)
B(-5,-35,-6,minecraft:spruce_log)
B(-5,-34,-6,minecraft:spruce_log)
B(-5,-33,-6,minecraft:spruce_log)
B(-5,-32,-6,minecraft:spruce_log)
B(-5,-31,-6,minecraft:spruce_log)
B(-5,-30,-6,minecraft:spruce_log)
B(-5,-29,-6,minecraft:spruce_log)
B(-5,-28,-6,minecraft:spruce_log)
B(-5,-27,-6,minecraft:spruce_log)
B(-5,-26,-6,minecraft:spruce_log)
B(-5,-25,-6,minecraft:spruce_log)
B(-5,-24,-6,minecraft:spruce_log)
B(-5,-23,-6,minecraft:spruce_log)
B(-5,-22,-6,minecraft:spruce_log)
B(-5,-21,-6,minecraft:spruce_log)
B(-5,-20,-6,minecraft:spruce_log)
B(-5,-19,-6,minecraft:spruce_log)
B(-5,-18,-6,minecraft:spruce_log)
B(-5,-17,-6,minecraft:spruce_log)
B(-5,-16,-6,minecraft:spruce_log)
B(-5,-15,-6,minecraft:spruce_log)
B(-5,-14,-6,minecraft:spruce_log)
B(-5,-13,-6,minecraft:spruce_log)
B(-5,-12,-6,minecraft:spruce_log)
B(-5,-11,-6,minecraft:spruce_log)
B(-5,-10,-6,minecraft:spruce_log)
B(-5,-9,-6,minecraft:spruce_log)
B(-5,-8,-6,minecraft:spruce_log)
B(-5,-7,-6,minecraft:spruce_log)
B(-5,-6,-6,minecraft:spruce_log)
B(-5,-5,-6,minecraft:spruce_log)
B(-5,-4,-6,minecraft:spruce_log)
B(-5,-3,-6,minecraft:spruce_log)
B(-5,-2,-6,minecraft:smooth_stone_slab)
B(-5,-3,-5,minecraft:spruce_log[axis=z])
B(-5,-2,-5,minecraft:spruce_fence[east=false,north=false,south=true,waterlogged=false,west=true])
B(-5,-3,-4,minecraft:spruce_log[axis=z])
B(-5,-2,-4,minecraft:spruce_fence[east=false,north=true,south=false,waterlogged=false,west=true])
B(-5,-54,-3,minecraft:spruce_log)
B(-5,-53,-3,minecraft:spruce_log)
B(-5,-52,-3,minecraft:spruce_log)
B(-5,-51,-3,minecraft:spruce_log)
B(-5,-50,-3,minecraft:spruce_log)
B(-5,-49,-3,minecraft:spruce_log)
B(-5,-48,-3,minecraft:spruce_log)
B(-5,-47,-3,minecraft:spruce_log)
B(-5,-46,-3,minecraft:spruce_log)
B(-5,-45,-3,minecraft:spruce_log)
B(-5,-44,-3,minecraft:spruce_log)
B(-5,-43,-3,minecraft:spruce_log)
B(-5,-42,-3,minecraft:spruce_log)
B(-5,-41,-3,minecraft:spruce_log)
B(-5,-40,-3,minecraft:spruce_log)
B(-5,-39,-3,minecraft:spruce_log)
B(-5,-38,-3,minecraft:spruce_log)
B(-5,-37,-3,minecraft:spruce_log)
B(-5,-36,-3,minecraft:spruce_log)
B(-5,-35,-3,minecraft:spruce_log)
B(-5,-34,-3,minecraft:spruce_log)
B(-5,-33,-3,minecraft:spruce_log)
B(-5,-32,-3,minecraft:spruce_log)
B(-5,-31,-3,minecraft:spruce_log)
B(-5,-30,-3,minecraft:spruce_log)
B(-5,-29,-3,minecraft:spruce_log)
B(-5,-28,-3,minecraft:spruce_log)
B(-5,-27,-3,minecraft:spruce_log)
B(-5,-26,-3,minecraft:spruce_log)
B(-5,-25,-3,minecraft:spruce_log)
B(-5,-24,-3,minecraft:spruce_log)
B(-5,-23,-3,minecraft:spruce_log)
B(-5,-22,-3,minecraft:spruce_log)
B(-5,-21,-3,minecraft:spruce_log)
B(-5,-20,-3,minecraft:spruce_log)
B(-5,-19,-3,minecraft:spruce_log)
B(-5,-18,-3,minecraft:spruce_log)
B(-5,-17,-3,minecraft:spruce_log)
B(-5,-16,-3,minecraft:spruce_log)
B(-5,-15,-3,minecraft:spruce_log)
B(-5,-14,-3,minecraft:spruce_log)
B(-5,-13,-3,minecraft:spruce_log)
B(-5,-12,-3,minecraft:spruce_log)
B(-5,-11,-3,minecraft:spruce_log)
B(-5,-10,-3,minecraft:spruce_log)
B(-5,-9,-3,minecraft:spruce_log)
B(-5,-8,-3,minecraft:spruce_log)
B(-5,-7,-3,minecraft:spruce_log)
B(-5,-6,-3,minecraft:spruce_log)
B(-5,-5,-3,minecraft:spruce_log)
B(-5,-4,-3,minecraft:spruce_log)
B(-5,-3,-3,minecraft:spruce_log)
B(-5,-2,-3,minecraft:smooth_stone_slab)
B(-5,-52,-2,minecraft:spruce_log[axis=z])
B(-5,-48,-2,minecraft:spruce_log[axis=z])
B(-5,-44,-2,minecraft:spruce_log[axis=z])
B(-5,-40,-2,minecraft:spruce_log[axis=z])
B(-5,-36,-2,minecraft:spruce_log[axis=z])
B(-5,-32,-2,minecraft:spruce_log[axis=z])
B(-5,-28,-2,minecraft:spruce_log[axis=z])
B(-5,-24,-2,minecraft:spruce_log[axis=z])
B(-5,-20,-2,minecraft:spruce_log[axis=z])
B(-5,-16,-2,minecraft:spruce_log[axis=z])
B(-5,-12,-2,minecraft:spruce_log[axis=z])
B(-5,-8,-2,minecraft:spruce_log[axis=z])
B(-5,-3,-2,minecraft:spruce_log[axis=z])
B(-5,-2,-2,minecraft:spruce_fence[east=false,north=false,south=true,waterlogged=false,west=true])
B(-5,-52,-1,minecraft:spruce_log[axis=z])
B(-5,-48,-1,minecraft:spruce_log[axis=z])
B(-5,-44,-1,minecraft:spruce_log[axis=z])
B(-5,-40,-1,minecraft:spruce_log[axis=z])
B(-5,-36,-1,minecraft:spruce_log[axis=z])
B(-5,-32,-1,minecraft:spruce_log[axis=z])
B(-5,-28,-1,minecraft:spruce_log[axis=z])
B(-5,-24,-1,minecraft:spruce_log[axis=z])
B(-5,-20,-1,minecraft:spruce_log[axis=z])
B(-5,-16,-1,minecraft:spruce_log[axis=z])
B(-5,-12,-1,minecraft:spruce_log[axis=z])
B(-5,-8,-1,minecraft:spruce_log[axis=z])
B(-5,-3,-1,minecraft:spruce_log[axis=z])
B(-5,-2,-1,minecraft:spruce_fence[east=false,north=true,south=false,waterlogged=false,west=true])
B(-5,-1,-1,minecraft:spruce_fence)
B(-5,0,-1,minecraft:spruce_fence[east=false,north=false,south=false,waterlogged=false,west=true])
B(-4,-3,-8,minecraft:oak_slab)
B(-4,-51,-7,minecraft:spruce_log[axis=x])
B(-4,-47,-7,minecraft:spruce_log[axis=x])
B(-4,-43,-7,minecraft:spruce_log[axis=x])
B(-4,-39,-7,minecraft:spruce_log[axis=x])
B(-4,-35,-7,minecraft:spruce_log[axis=x])
B(-4,-31,-7,minecraft:spruce_log[axis=x])
B(-4,-27,-7,minecraft:spruce_log[axis=x])
B(-4,-23,-7,minecraft:spruce_log[axis=x])
B(-4,-19,-7,minecraft:spruce_log[axis=x])
B(-4,-15,-7,minecraft:spruce_log[axis=x])
B(-4,-11,-7,minecraft:spruce_log[axis=x])
B(-4,-7,-7,minecraft:spruce_log[axis=x])
B(-4,-6,-7,minecraft:spruce_log[axis=x])
B(-4,-3,-7,minecraft:spruce_log[axis=x])
B(-4,-2,-7,minecraft:spruce_fence[east=false,north=false,south=false,waterlogged=false,west=true])
B(-3,-51,-8,minecraft:spruce_log[axis=z])
B(-3,-47,-8,minecraft:spruce_log[axis=z])
B(-3,-43,-8,minecraft:spruce_log[axis=z])
B(-3,-39,-8,minecraft:spruce_log[axis=z])
B(-3,-35,-8,minecraft:spruce_log[axis=z])
B(-3,-31,-8,minecraft:spruce_log[axis=z])
B(-3,-27,-8,minecraft:spruce_log[axis=z])
B(-3,-23,-8,minecraft:spruce_log[axis=z])
B(-3,-19,-8,minecraft:spruce_log[axis=z])
B(-3,-15,-8,minecraft:spruce_log[axis=z])
B(-3,-11,-8,minecraft:spruce_log[axis=z])
B(-3,-7,-8,minecraft:spruce_log[axis=z])
B(-3,-6,-8,minecraft:spruce_log[axis=z])
B(-3,-4,-8,minecraft:oak_slab[type=top,waterlogged=false])
B(-3,-54,-7,minecraft:spruce_log)
B(-3,-53,-7,minecraft:spruce_log)
B(-3,-52,-7,minecraft:spruce_log)
B(-3,-51,-7,minecraft:spruce_log)
B(-3,-50,-7,minecraft:spruce_log)
B(-3,-49,-7,minecraft:spruce_log)
B(-3,-48,-7,minecraft:spruce_log)
B(-3,-47,-7,minecraft:spruce_log)
B(-3,-46,-7,minecraft:spruce_log)
B(-3,-45,-7,minecraft:spruce_log)
B(-3,-44,-7,minecraft:spruce_log)
B(-3,-43,-7,minecraft:spruce_log)
B(-3,-42,-7,minecraft:spruce_log)
B(-3,-41,-7,minecraft:spruce_log)
B(-3,-40,-7,minecraft:spruce_log)
B(-3,-39,-7,minecraft:spruce_log)
B(-3,-38,-7,minecraft:spruce_log)
B(-3,-37,-7,minecraft:spruce_log)
B(-3,-36,-7,minecraft:spruce_log)
B(-3,-35,-7,minecraft:spruce_log)
B(-3,-34,-7,minecraft:spruce_log)
B(-3,-33,-7,minecraft:spruce_log)
B(-3,-32,-7,minecraft:spruce_log)
B(-3,-31,-7,minecraft:spruce_log)
B(-3,-30,-7,minecraft:spruce_log)
B(-3,-29,-7,minecraft:spruce_log)
B(-3,-28,-7,minecraft:spruce_log)
B(-3,-27,-7,minecraft:spruce_log)
B(-3,-26,-7,minecraft:spruce_log)
B(-3,-25,-7,minecraft:spruce_log)
B(-3,-24,-7,minecraft:spruce_log)
B(-3,-23,-7,minecraft:spruce_log)
B(-3,-22,-7,minecraft:spruce_log)
B(-3,-21,-7,minecraft:spruce_log)
B(-3,-20,-7,minecraft:spruce_log)
B(-3,-19,-7,minecraft:spruce_log)
B(-3,-18,-7,minecraft:spruce_log)
B(-3,-17,-7,minecraft:spruce_log)
B(-3,-16,-7,minecraft:spruce_log)
B(-3,-15,-7,minecraft:spruce_log)
B(-3,-14,-7,minecraft:spruce_log)
B(-3,-13,-7,minecraft:spruce_log)
B(-3,-12,-7,minecraft:spruce_log)
B(-3,-11,-7,minecraft:spruce_log)
B(-3,-10,-7,minecraft:spruce_log)
B(-3,-9,-7,minecraft:spruce_log)
B(-3,-8,-7,minecraft:spruce_log)
B(-3,-7,-7,minecraft:spruce_log)
B(-3,-6,-7,minecraft:spruce_log)
B(-3,-5,-7,minecraft:spruce_log)
B(-3,-4,-7,minecraft:spruce_log)
B(-3,-3,-7,minecraft:spruce_log[axis=x])
B(-3,-2,-7,minecraft:stone_brick_stairs[facing=east,half=bottom,shape=straight,waterlogged=false])
B(-3,-54,-3,minecraft:spruce_log)
B(-3,-53,-3,minecraft:spruce_log)
B(-3,-52,-3,minecraft:spruce_log)
B(-3,-51,-3,minecraft:spruce_log)
B(-3,-50,-3,minecraft:spruce_log)
B(-3,-49,-3,minecraft:spruce_log)
B(-3,-48,-3,minecraft:spruce_log)
B(-3,-47,-3,minecraft:spruce_log)
B(-3,-46,-3,minecraft:spruce_log)
B(-3,-45,-3,minecraft:spruce_log)
B(-3,-44,-3,minecraft:spruce_log)
B(-3,-43,-3,minecraft:spruce_log)
B(-3,-42,-3,minecraft:spruce_log)
B(-3,-41,-3,minecraft:spruce_log)
B(-3,-40,-3,minecraft:spruce_log)
B(-3,-39,-3,minecraft:spruce_log)
B(-3,-38,-3,minecraft:spruce_log)
B(-3,-37,-3,minecraft:spruce_log)
B(-3,-36,-3,minecraft:spruce_log)
B(-3,-35,-3,minecraft:spruce_log)
B(-3,-34,-3,minecraft:spruce_log)
B(-3,-33,-3,minecraft:spruce_log)
B(-3,-32,-3,minecraft:spruce_log)
B(-3,-31,-3,minecraft:spruce_log)
B(-3,-30,-3,minecraft:spruce_log)
B(-3,-29,-3,minecraft:spruce_log)
B(-3,-28,-3,minecraft:spruce_log)
B(-3,-27,-3,minecraft:spruce_log)
B(-3,-26,-3,minecraft:spruce_log)
B(-3,-25,-3,minecraft:spruce_log)
B(-3,-24,-3,minecraft:spruce_log)
B(-3,-23,-3,minecraft:spruce_log)
B(-3,-22,-3,minecraft:spruce_log)
B(-3,-21,-3,minecraft:spruce_log)
B(-3,-20,-3,minecraft:spruce_log)
B(-3,-19,-3,minecraft:spruce_log)
B(-3,-18,-3,minecraft:spruce_log)
B(-3,-17,-3,minecraft:spruce_log)
B(-3,-16,-3,minecraft:spruce_log)
B(-3,-15,-3,minecraft:spruce_log)
B(-3,-14,-3,minecraft:spruce_log)
B(-3,-13,-3,minecraft:spruce_log)
B(-3,-12,-3,minecraft:spruce_log)
B(-3,-11,-3,minecraft:spruce_log)
B(-3,-10,-3,minecraft:spruce_log)
B(-3,-9,-3,minecraft:spruce_log)
B(-3,-8,-3,minecraft:spruce_log)
B(-3,-7,-3,minecraft:spruce_log)
B(-3,-6,-3,minecraft:spruce_log)
B(-3,-5,-3,minecraft:spruce_log)
B(-3,-4,-3,minecraft:spruce_log)
B(-3,-3,-3,minecraft:stone_brick_stairs[facing=east,half=bottom,shape=straight,waterlogged=false])
B(-2,-4,-8,minecraft:oak_slab[type=top,waterlogged=false])
B(-2,-52,-7,minecraft:spruce_log[axis=x])
B(-2,-48,-7,minecraft:spruce_log[axis=x])
B(-2,-44,-7,minecraft:spruce_log[axis=x])
B(-2,-40,-7,minecraft:spruce_log[axis=x])
B(-2,-36,-7,minecraft:spruce_log[axis=x])
B(-2,-32,-7,minecraft:spruce_log[axis=x])
B(-2,-28,-7,minecraft:spruce_log[axis=x])
B(-2,-24,-7,minecraft:spruce_log[axis=x])
B(-2,-20,-7,minecraft:spruce_log[axis=x])
B(-2,-16,-7,minecraft:spruce_log[axis=x])
B(-2,-12,-7,minecraft:spruce_log[axis=x])
B(-2,-8,-7,minecraft:spruce_log[axis=x])
B(-2,-3,-7,minecraft:spruce_log[axis=x])
B(-2,-2,-7,minecraft:polished_andesite)
B(-2,-1,-7,minecraft:polished_andesite)
B(-2,0,-7,minecraft:stone_brick_stairs[facing=east,half=bottom,shape=straight,waterlogged=false])
B(-2,1,-7,minecraft:smooth_stone_slab)
B(-2,-53,-3,minecraft:spruce_log[axis=x])
B(-2,-51,-3,minecraft:spruce_log[axis=x])
B(-2,-49,-3,minecraft:spruce_log[axis=x])
B(-2,-47,-3,minecraft:spruce_log[axis=x])
B(-2,-45,-3,minecraft:spruce_log[axis=x])
B(-2,-43,-3,minecraft:spruce_log[axis=x])
B(-2,-41,-3,minecraft:spruce_log[axis=x])
B(-2,-39,-3,minecraft:spruce_log[axis=x])
B(-2,-37,-3,minecraft:spruce_log[axis=x])
B(-2,-35,-3,minecraft:spruce_log[axis=x])
B(-2,-33,-3,minecraft:spruce_log[axis=x])
B(-2,-31,-3,minecraft:spruce_log[axis=x])
B(-2,-29,-3,minecraft:spruce_log[axis=x])
B(-2,-27,-3,minecraft:spruce_log[axis=x])
B(-2,-25,-3,minecraft:spruce_log[axis=x])
B(-2,-23,-3,minecraft:spruce_log[axis=x])
B(-2,-21,-3,minecraft:spruce_log[axis=x])
B(-2,-19,-3,minecraft:spruce_log[axis=x])
B(-2,-17,-3,minecraft:spruce_log[axis=x])
B(-2,-15,-3,minecraft:spruce_log[axis=x])
B(-2,-13,-3,minecraft:spruce_log[axis=x])
B(-2,-11,-3,minecraft:spruce_log[axis=x])
B(-2,-9,-3,minecraft:spruce_log[axis=x])
B(-2,-7,-3,minecraft:spruce_log[axis=x])
B(-2,-6,-3,minecraft:spruce_log[axis=x])
B(-2,-3,-3,minecraft:spruce_log[axis=x])
B(-2,-2,-3,minecraft:stone_brick_stairs[facing=east,half=top,shape=straight,waterlogged=false])
B(-2,-1,-3,minecraft:polished_andesite)
B(-2,0,-3,minecraft:stone_brick_stairs[facing=east,half=bottom,shape=straight,waterlogged=false])
B(-2,1,-3,minecraft:smooth_stone_slab)
B(-1,-53,-8,minecraft:spruce_log[axis=z])
B(-1,-49,-8,minecraft:spruce_log[axis=z])
B(-1,-45,-8,minecraft:spruce_log[axis=z])
B(-1,-41,-8,minecraft:spruce_log[axis=z])
B(-1,-37,-8,minecraft:spruce_log[axis=z])
B(-1,-33,-8,minecraft:spruce_log[axis=z])
B(-1,-29,-8,minecraft:spruce_log[axis=z])
B(-1,-25,-8,minecraft:spruce_log[axis=z])
B(-1,-21,-8,minecraft:spruce_log[axis=z])
B(-1,-17,-8,minecraft:spruce_log[axis=z])
B(-1,-13,-8,minecraft:spruce_log[axis=z])
B(-1,-9,-8,minecraft:spruce_log[axis=z])
B(-1,-4,-8,minecraft:spruce_log[axis=z])
B(-1,-3,-8,minecraft:spruce_fence[east=false,north=false,south=true,waterlogged=false,west=false])
B(-1,-2,-8,minecraft:spruce_fence[east=false,north=false,south=true,waterlogged=false,west=false])
B(-1,-1,-8,minecraft:spruce_log[axis=z])
B(-1,0,-8,minecraft:spruce_fence[east=false,north=false,south=true,waterlogged=false,west=false])
B(-1,-54,-7,minecraft:spruce_log)
B(-1,-53,-7,minecraft:spruce_log)
B(-1,-52,-7,minecraft:spruce_log)
B(-1,-51,-7,minecraft:spruce_log)
B(-1,-50,-7,minecraft:spruce_log)
B(-1,-49,-7,minecraft:spruce_log)
B(-1,-48,-7,minecraft:spruce_log)
B(-1,-47,-7,minecraft:spruce_log)
B(-1,-46,-7,minecraft:spruce_log)
B(-1,-45,-7,minecraft:spruce_log)
B(-1,-44,-7,minecraft:spruce_log)
B(-1,-43,-7,minecraft:spruce_log)
B(-1,-42,-7,minecraft:spruce_log)
B(-1,-41,-7,minecraft:spruce_log)
B(-1,-40,-7,minecraft:spruce_log)
B(-1,-39,-7,minecraft:spruce_log)
B(-1,-38,-7,minecraft:spruce_log)
B(-1,-37,-7,minecraft:spruce_log)
B(-1,-36,-7,minecraft:spruce_log)
B(-1,-35,-7,minecraft:spruce_log)
B(-1,-34,-7,minecraft:spruce_log)
B(-1,-33,-7,minecraft:spruce_log)
B(-1,-32,-7,minecraft:spruce_log)
B(-1,-31,-7,minecraft:spruce_log)
B(-1,-30,-7,minecraft:spruce_log)
B(-1,-29,-7,minecraft:spruce_log)
B(-1,-28,-7,minecraft:spruce_log)
B(-1,-27,-7,minecraft:spruce_log)
B(-1,-26,-7,minecraft:spruce_log)
B(-1,-25,-7,minecraft:spruce_log)
B(-1,-24,-7,minecraft:spruce_log)
B(-1,-23,-7,minecraft:spruce_log)
B(-1,-22,-7,minecraft:spruce_log)
B(-1,-21,-7,minecraft:spruce_log)
B(-1,-20,-7,minecraft:spruce_log)
B(-1,-19,-7,minecraft:spruce_log)
B(-1,-18,-7,minecraft:spruce_log)
B(-1,-17,-7,minecraft:spruce_log)
B(-1,-16,-7,minecraft:spruce_log)
B(-1,-15,-7,minecraft:spruce_log)
B(-1,-14,-7,minecraft:spruce_log)
B(-1,-13,-7,minecraft:spruce_log)
B(-1,-12,-7,minecraft:spruce_log)
B(-1,-11,-7,minecraft:spruce_log)
B(-1,-10,-7,minecraft:spruce_log)
B(-1,-9,-7,minecraft:spruce_log)
B(-1,-8,-7,minecraft:spruce_log)
B(-1,-7,-7,minecraft:spruce_log)
B(-1,-6,-7,minecraft:spruce_log)
B(-1,-5,-7,minecraft:spruce_log)
B(-1,-4,-7,minecraft:spruce_log)
B(-1,-3,-7,minecraft:spruce_log)
B(-1,-2,-7,minecraft:spruce_log)
B(-1,-1,-7,minecraft:spruce_log)
B(-1,0,-7,minecraft:chiseled_stone_bricks)
B(-1,1,-7,minecraft:smooth_stone_slab)
B(-1,-53,-6,minecraft:spruce_log[axis=z])
B(-1,-51,-6,minecraft:spruce_log[axis=z])
B(-1,-49,-6,minecraft:spruce_log[axis=z])
B(-1,-47,-6,minecraft:spruce_log[axis=z])
B(-1,-45,-6,minecraft:spruce_log[axis=z])
B(-1,-43,-6,minecraft:spruce_log[axis=z])
B(-1,-41,-6,minecraft:spruce_log[axis=z])
B(-1,-39,-6,minecraft:spruce_log[axis=z])
B(-1,-37,-6,minecraft:spruce_log[axis=z])
B(-1,-35,-6,minecraft:spruce_log[axis=z])
B(-1,-33,-6,minecraft:spruce_log[axis=z])
B(-1,-31,-6,minecraft:spruce_log[axis=z])
B(-1,-29,-6,minecraft:spruce_log[axis=z])
B(-1,-27,-6,minecraft:spruce_log[axis=z])
B(-1,-25,-6,minecraft:spruce_log[axis=z])
B(-1,-23,-6,minecraft:spruce_log[axis=z])
B(-1,-21,-6,minecraft:spruce_log[axis=z])
B(-1,-19,-6,minecraft:spruce_log[axis=z])
B(-1,-17,-6,minecraft:spruce_log[axis=z])
B(-1,-15,-6,minecraft:spruce_log[axis=z])
B(-1,-13,-6,minecraft:spruce_log[axis=z])
B(-1,-11,-6,minecraft:spruce_log[axis=z])
B(-1,-9,-6,minecraft:spruce_log[axis=z])
B(-1,-7,-6,minecraft:spruce_log[axis=z])
B(-1,-6,-6,minecraft:spruce_log[axis=z])
B(-1,-4,-6,minecraft:spruce_log[axis=z])
B(-1,-3,-6,minecraft:oak_planks)
B(-1,-2,-6,minecraft:oak_planks)
B(-1,-1,-6,minecraft:spruce_log[axis=z])
B(-1,0,-6,minecraft:spruce_fence[east=false,north=true,south=true,waterlogged=false,west=false])
B(-1,-53,-5,minecraft:spruce_log[axis=z])
B(-1,-51,-5,minecraft:spruce_log[axis=z])
B(-1,-49,-5,minecraft:spruce_log[axis=z])
B(-1,-47,-5,minecraft:spruce_log[axis=z])
B(-1,-45,-5,minecraft:spruce_log[axis=z])
B(-1,-43,-5,minecraft:spruce_log[axis=z])
B(-1,-41,-5,minecraft:spruce_log[axis=z])
B(-1,-39,-5,minecraft:spruce_log[axis=z])
B(-1,-37,-5,minecraft:spruce_log[axis=z])
B(-1,-35,-5,minecraft:spruce_log[axis=z])
B(-1,-33,-5,minecraft:spruce_log[axis=z])
B(-1,-31,-5,minecraft:spruce_log[axis=z])
B(-1,-29,-5,minecraft:spruce_log[axis=z])
B(-1,-27,-5,minecraft:spruce_log[axis=z])
B(-1,-25,-5,minecraft:spruce_log[axis=z])
B(-1,-23,-5,minecraft:spruce_log[axis=z])
B(-1,-21,-5,minecraft:spruce_log[axis=z])
B(-1,-19,-5,minecraft:spruce_log[axis=z])
B(-1,-17,-5,minecraft:spruce_log[axis=z])
B(-1,-15,-5,minecraft:spruce_log[axis=z])
B(-1,-13,-5,minecraft:spruce_log[axis=z])
B(-1,-11,-5,minecraft:spruce_log[axis=z])
B(-1,-9,-5,minecraft:spruce_log[axis=z])
B(-1,-7,-5,minecraft:spruce_log[axis=z])
B(-1,-6,-5,minecraft:spruce_log[axis=z])
B(-1,-4,-5,minecraft:spruce_log[axis=z])
B(-1,-3,-5,minecraft:oak_planks)
B(-1,-2,-5,minecraft:dark_oak_fence[east=false,north=true,south=true,waterlogged=false,west=false])
B(-1,-1,-5,minecraft:spruce_log[axis=z])
B(-1,0,-5,minecraft:spruce_fence[east=false,north=true,south=true,waterlogged=false,west=false])
B(-1,-53,-4,minecraft:spruce_log[axis=z])
B(-1,-51,-4,minecraft:spruce_log[axis=z])
B(-1,-49,-4,minecraft:spruce_log[axis=z])
B(-1,-47,-4,minecraft:spruce_log[axis=z])
B(-1,-45,-4,minecraft:spruce_log[axis=z])
B(-1,-43,-4,minecraft:spruce_log[axis=z])
B(-1,-41,-4,minecraft:spruce_log[axis=z])
B(-1,-39,-4,minecraft:spruce_log[axis=z])
B(-1,-37,-4,minecraft:spruce_log[axis=z])
B(-1,-35,-4,minecraft:spruce_log[axis=z])
B(-1,-33,-4,minecraft:spruce_log[axis=z])
B(-1,-31,-4,minecraft:spruce_log[axis=z])
B(-1,-29,-4,minecraft:spruce_log[axis=z])
B(-1,-27,-4,minecraft:spruce_log[axis=z])
B(-1,-25,-4,minecraft:spruce_log[axis=z])
B(-1,-23,-4,minecraft:spruce_log[axis=z])
B(-1,-21,-4,minecraft:spruce_log[axis=z])
B(-1,-19,-4,minecraft:spruce_log[axis=z])
B(-1,-17,-4,minecraft:spruce_log[axis=z])
B(-1,-15,-4,minecraft:spruce_log[axis=z])
B(-1,-13,-4,minecraft:spruce_log[axis=z])
B(-1,-11,-4,minecraft:spruce_log[axis=z])
B(-1,-9,-4,minecraft:spruce_log[axis=z])
B(-1,-7,-4,minecraft:spruce_log[axis=z])
B(-1,-6,-4,minecraft:spruce_log[axis=z])
B(-1,-4,-4,minecraft:spruce_log[axis=z])
B(-1,-3,-4,minecraft:oak_planks)
B(-1,-2,-4,minecraft:oak_planks)
B(-1,-1,-4,minecraft:spruce_log[axis=z])
B(-1,0,-4,minecraft:spruce_fence[east=false,north=true,south=true,waterlogged=false,west=false])
B(-1,-54,-3,minecraft:spruce_log)
B(-1,-53,-3,minecraft:spruce_log)
B(-1,-52,-3,minecraft:spruce_log)
B(-1,-51,-3,minecraft:spruce_log)
B(-1,-50,-3,minecraft:spruce_log)
B(-1,-49,-3,minecraft:spruce_log)
B(-1,-48,-3,minecraft:spruce_log)
B(-1,-47,-3,minecraft:spruce_log)
B(-1,-46,-3,minecraft:spruce_log)
B(-1,-45,-3,minecraft:spruce_log)
B(-1,-44,-3,minecraft:spruce_log)
B(-1,-43,-3,minecraft:spruce_log)
B(-1,-42,-3,minecraft:spruce_log)
B(-1,-41,-3,minecraft:spruce_log)
B(-1,-40,-3,minecraft:spruce_log)
B(-1,-39,-3,minecraft:spruce_log)
B(-1,-38,-3,minecraft:spruce_log)
B(-1,-37,-3,minecraft:spruce_log)
B(-1,-36,-3,minecraft:spruce_log)
B(-1,-35,-3,minecraft:spruce_log)
B(-1,-34,-3,minecraft:spruce_log)
B(-1,-33,-3,minecraft:spruce_log)
B(-1,-32,-3,minecraft:spruce_log)
B(-1,-31,-3,minecraft:spruce_log)
B(-1,-30,-3,minecraft:spruce_log)
B(-1,-29,-3,minecraft:spruce_log)
B(-1,-28,-3,minecraft:spruce_log)
B(-1,-27,-3,minecraft:spruce_log)
B(-1,-26,-3,minecraft:spruce_log)
B(-1,-25,-3,minecraft:spruce_log)
B(-1,-24,-3,minecraft:spruce_log)
B(-1,-23,-3,minecraft:spruce_log)
B(-1,-22,-3,minecraft:spruce_log)
B(-1,-21,-3,minecraft:spruce_log)
B(-1,-20,-3,minecraft:spruce_log)
B(-1,-19,-3,minecraft:spruce_log)
B(-1,-18,-3,minecraft:spruce_log)
B(-1,-17,-3,minecraft:spruce_log)
B(-1,-16,-3,minecraft:spruce_log)
B(-1,-15,-3,minecraft:spruce_log)
B(-1,-14,-3,minecraft:spruce_log)
B(-1,-13,-3,minecraft:spruce_log)
B(-1,-12,-3,minecraft:spruce_log)
B(-1,-11,-3,minecraft:spruce_log)
B(-1,-10,-3,minecraft:spruce_log)
B(-1,-9,-3,minecraft:spruce_log)
B(-1,-8,-3,minecraft:spruce_log)
B(-1,-7,-3,minecraft:spruce_log)
B(-1,-6,-3,minecraft:spruce_log)
B(-1,-5,-3,minecraft:spruce_log)
B(-1,-4,-3,minecraft:spruce_log)
B(-1,-3,-3,minecraft:spruce_log)
B(-1,-2,-3,minecraft:spruce_log)
B(-1,-1,-3,minecraft:spruce_log)
B(-1,0,-3,minecraft:chiseled_stone_bricks)
B(-1,1,-3,minecraft:smooth_stone_slab)
B(-1,-52,-2,minecraft:spruce_log[axis=z])
B(-1,-48,-2,minecraft:spruce_log[axis=z])
B(-1,-44,-2,minecraft:spruce_log[axis=z])
B(-1,-40,-2,minecraft:spruce_log[axis=z])
B(-1,-36,-2,minecraft:spruce_log[axis=z])
B(-1,-32,-2,minecraft:spruce_log[axis=z])
B(-1,-28,-2,minecraft:spruce_log[axis=z])
B(-1,-24,-2,minecraft:spruce_log[axis=z])
B(-1,-20,-2,minecraft:spruce_log[axis=z])
B(-1,-16,-2,minecraft:spruce_log[axis=z])
B(-1,-12,-2,minecraft:spruce_log[axis=z])
B(-1,-8,-2,minecraft:spruce_log[axis=z])
B(-1,-3,-2,minecraft:spruce_log[axis=z])
B(-1,-2,-2,minecraft:stone_brick_stairs[facing=north,half=top,shape=straight,waterlogged=false])
B(-1,-1,-2,minecraft:polished_andesite)
B(-1,0,-2,minecraft:stone_brick_stairs)
B(-1,1,-2,minecraft:smooth_stone_slab)
B(-1,-54,-1,minecraft:spruce_log)
B(-1,-53,-1,minecraft:spruce_log)
B(-1,-52,-1,minecraft:spruce_log)
B(-1,-51,-1,minecraft:spruce_log)
B(-1,-50,-1,minecraft:spruce_log)
B(-1,-49,-1,minecraft:spruce_log)
B(-1,-48,-1,minecraft:spruce_log)
B(-1,-47,-1,minecraft:spruce_log)
B(-1,-46,-1,minecraft:spruce_log)
B(-1,-45,-1,minecraft:spruce_log)
B(-1,-44,-1,minecraft:spruce_log)
B(-1,-43,-1,minecraft:spruce_log)
B(-1,-42,-1,minecraft:spruce_log)
B(-1,-41,-1,minecraft:spruce_log)
B(-1,-40,-1,minecraft:spruce_log)
B(-1,-39,-1,minecraft:spruce_log)
B(-1,-38,-1,minecraft:spruce_log)
B(-1,-37,-1,minecraft:spruce_log)
B(-1,-36,-1,minecraft:spruce_log)
B(-1,-35,-1,minecraft:spruce_log)
B(-1,-34,-1,minecraft:spruce_log)
B(-1,-33,-1,minecraft:spruce_log)
B(-1,-32,-1,minecraft:spruce_log)
B(-1,-31,-1,minecraft:spruce_log)
B(-1,-30,-1,minecraft:spruce_log)
B(-1,-29,-1,minecraft:spruce_log)
B(-1,-28,-1,minecraft:spruce_log)
B(-1,-27,-1,minecraft:spruce_log)
B(-1,-26,-1,minecraft:spruce_log)
B(-1,-25,-1,minecraft:spruce_log)
B(-1,-24,-1,minecraft:spruce_log)
B(-1,-23,-1,minecraft:spruce_log)
B(-1,-22,-1,minecraft:spruce_log)
B(-1,-21,-1,minecraft:spruce_log)
B(-1,-20,-1,minecraft:spruce_log)
B(-1,-19,-1,minecraft:spruce_log)
B(-1,-18,-1,minecraft:spruce_log)
B(-1,-17,-1,minecraft:spruce_log)
B(-1,-16,-1,minecraft:spruce_log)
B(-1,-15,-1,minecraft:spruce_log)
B(-1,-14,-1,minecraft:spruce_log)
B(-1,-13,-1,minecraft:spruce_log)
B(-1,-12,-1,minecraft:spruce_log)
B(-1,-11,-1,minecraft:spruce_log)
B(-1,-10,-1,minecraft:spruce_log)
B(-1,-9,-1,minecraft:spruce_log)
B(-1,-8,-1,minecraft:spruce_log)
B(-1,-7,-1,minecraft:spruce_log)
B(-1,-6,-1,minecraft:spruce_log)
B(-1,-5,-1,minecraft:spruce_log)
B(-1,-4,-1,minecraft:spruce_log)
B(-1,-3,-1,minecraft:stone_brick_stairs)

#######################################################################
# +-----------------------------------------------------------------+ #
# |                            BO3 checks                           | #
# +-----------------------------------------------------------------+ #
#######################################################################


#######################################################################
# +-----------------------------------------------------------------+ #
# |                             Branches                            | #
# +-----------------------------------------------------------------+ #
#######################################################################

Branch(-8,0,0,WestPortShipPillager_5x1,NORTH,100.0)

#######################################################################
# +-----------------------------------------------------------------+ #
# |                             Entities                            | #
# +-----------------------------------------------------------------+ #
#######################################################################

Entity(-7,-1,-7,minecraft:vindication_illager,1,../NBT/MOBS/RandomPillager.txt)
