
#######################################################################
# +-----------------------------------------------------------------+ #
# |                            BO3 object                           | #
# +-----------------------------------------------------------------+ #
#######################################################################

Author: Bo3 BulkEdit

Description: Converted Schematic - Modified by Bo3BulkEdit

Version: 3

SettingsMode: WriteWithoutComments


#######################################################################
# +-----------------------------------------------------------------+ #
# |                          Main settings                          | #
# +-----------------------------------------------------------------+ #
#######################################################################

Tree: false

Frequency: 1

Rarity: 100.0

RotateRandomly: false

SpawnHeight: randomY

SpawnHeightOffset: 0

SpawnHeightVariance: 0

##############################
# Height Limits for the BO3. #
##############################

MinHeight: 0

MaxHeight: 255

######################
# Extrusion settings #
######################

ExtrudeMode: None

ExtrudeThroughBlocks: minecraft:air

MaxBranchDepth: 20


#######################################################################
# +-----------------------------------------------------------------+ #
# |                      Source block settings                      | #
# +-----------------------------------------------------------------+ #
#######################################################################

SourceBlocks: otg:air

MaxPercentageOutsideSourceBlock: 100

OutsideSourceBlock: placeAnyway

DoReplaceBlocks: true

IsOTGPlus: false


#######################################################################
# +-----------------------------------------------------------------+ #
# |                              Blocks                             | #
# +-----------------------------------------------------------------+ #
#######################################################################

B(-8,-3,-8,minecraft:oak_trapdoor[facing=north,half=top,open=false,powered=false,waterlogged=false])
B(-8,-2,-8,minecraft:oak_button[face=wall,facing=south,powered=false])
B(-7,-2,-8,minecraft:oak_button[face=wall,facing=south,powered=false])
B(-6,-2,-8,minecraft:oak_button[face=wall,facing=south,powered=false])
B(-6,0,-8,minecraft:dispenser[facing=south,triggered=false])
B(-5,-3,-8,minecraft:oak_trapdoor[facing=north,half=top,open=false,powered=false,waterlogged=false])
B(-5,-2,-8,minecraft:oak_button[face=wall,facing=south,powered=false])
B(-4,-2,-8,minecraft:oak_button[face=wall,facing=south,powered=false])
B(-4,16,-8,minecraft:black_wool)
B(-4,17,-8,minecraft:black_wool)
B(-4,18,-8,minecraft:black_wool)
B(-3,-2,-8,minecraft:oak_button[face=wall,facing=south,powered=false])
B(-3,0,-8,minecraft:dispenser[facing=south,triggered=false])
B(-3,14,-8,minecraft:black_wool)
B(-3,15,-8,minecraft:black_wool)
B(-3,19,-8,minecraft:black_wool)
B(-3,20,-8,minecraft:black_wool)
B(-3,14,-7,minecraft:black_wool)
B(-3,15,-7,minecraft:black_wool)
B(-3,19,-7,minecraft:black_wool)
B(-3,20,-7,minecraft:black_wool)
B(-3,21,-7,minecraft:black_wool)
B(-3,20,-6,minecraft:black_wool)
B(-2,-3,-8,minecraft:oak_trapdoor[facing=north,half=top,open=false,powered=false,waterlogged=false])
B(-2,-2,-8,minecraft:oak_button[face=wall,facing=south,powered=false])
B(-2,5,-8,minecraft:black_wool)
B(-2,7,-8,minecraft:black_wool)
B(-2,8,-8,minecraft:black_wool)
B(-2,13,-8,minecraft:black_wool)
B(-2,21,-8,minecraft:black_wool)
B(-2,22,-8,minecraft:black_wool)
B(-2,4,-7,minecraft:black_wool)
B(-2,5,-7,minecraft:black_wool)
B(-2,8,-7,minecraft:black_wool)
B(-2,9,-7,minecraft:black_wool)
B(-2,13,-7,minecraft:black_wool)
B(-2,22,-7,minecraft:black_wool)
B(-2,23,-7,minecraft:black_wool)
B(-2,3,-6,minecraft:black_wool)
B(-2,4,-6,minecraft:black_wool)
B(-2,21,-6,minecraft:black_wool)
B(-2,22,-6,minecraft:black_wool)
B(-2,23,-6,minecraft:black_wool)
B(-1,-2,-8,minecraft:oak_button[face=wall,facing=south,powered=false])
B(-1,2,-8,minecraft:black_wool)
B(-1,3,-8,minecraft:black_wool)
B(-1,4,-8,minecraft:black_wool)
B(-1,9,-8,minecraft:black_wool)
B(-1,10,-8,minecraft:black_wool)
B(-1,12,-8,minecraft:black_wool)
B(-1,13,-8,minecraft:black_wool)
B(-1,23,-8,minecraft:black_wool)
B(-1,24,-8,minecraft:black_wool)
B(-1,1,-7,minecraft:black_wool)
B(-1,2,-7,minecraft:black_wool)
B(-1,3,-7,minecraft:black_wool)
B(-1,10,-7,minecraft:black_wool)
B(-1,12,-7,minecraft:black_wool)
B(-1,24,-7,minecraft:black_wool)
B(-1,1,-6,minecraft:black_wool)
B(-1,2,-6,minecraft:black_wool)
B(-1,9,-6,minecraft:black_wool)
B(-1,10,-6,minecraft:black_wool)
B(-1,11,-6,minecraft:black_wool)
B(-1,24,-6,minecraft:black_wool)
B(-1,10,-5,minecraft:black_wool)
B(-1,22,-5,minecraft:black_wool)
B(-1,23,-5,minecraft:black_wool)

#######################################################################
# +-----------------------------------------------------------------+ #
# |                            BO3 checks                           | #
# +-----------------------------------------------------------------+ #
#######################################################################


#######################################################################
# +-----------------------------------------------------------------+ #
# |                             Branches                            | #
# +-----------------------------------------------------------------+ #
#######################################################################

Branch(-8,0,0,WestPortShipPillager_4x5,NORTH,100.0)

#######################################################################
# +-----------------------------------------------------------------+ #
# |                             Entities                            | #
# +-----------------------------------------------------------------+ #
#######################################################################

