
#######################################################################
# +-----------------------------------------------------------------+ #
# |                            BO3 object                           | #
# +-----------------------------------------------------------------+ #
#######################################################################

Author: Bo3 BulkEdit

Description: Converted Schematic - Modified by Bo3BulkEdit

Version: 3

SettingsMode: WriteWithoutComments


#######################################################################
# +-----------------------------------------------------------------+ #
# |                          Main settings                          | #
# +-----------------------------------------------------------------+ #
#######################################################################

Tree: false

Frequency: 1

Rarity: 100.0

RotateRandomly: false

SpawnHeight: randomY

SpawnHeightOffset: 0

SpawnHeightVariance: 0

##############################
# Height Limits for the BO3. #
##############################

MinHeight: 0

MaxHeight: 255

######################
# Extrusion settings #
######################

ExtrudeMode: None

ExtrudeThroughBlocks: minecraft:air

MaxBranchDepth: 20


#######################################################################
# +-----------------------------------------------------------------+ #
# |                      Source block settings                      | #
# +-----------------------------------------------------------------+ #
#######################################################################

SourceBlocks: otg:air

MaxPercentageOutsideSourceBlock: 100

OutsideSourceBlock: placeAnyway

DoReplaceBlocks: true

IsOTGPlus: false


#######################################################################
# +-----------------------------------------------------------------+ #
# |                              Blocks                             | #
# +-----------------------------------------------------------------+ #
#######################################################################

B(-8,-3,-8,minecraft:oak_trapdoor[facing=south,half=top,open=false,powered=false,waterlogged=false])
B(-8,-2,-8,minecraft:oak_button)
B(-8,-4,-7,minecraft:dark_oak_planks)
B(-8,-3,-7,minecraft:dispenser)
B(-8,-2,-7,minecraft:dark_oak_planks)
B(-8,-1,-7,minecraft:cyan_terracotta)
B(-8,-6,-6,minecraft:dark_oak_wood)
B(-8,-5,-6,minecraft:dark_oak_wood)
B(-8,-4,-6,minecraft:dark_oak_planks)
B(-8,-3,-6,minecraft:black_concrete)
B(-8,-2,-6,minecraft:oak_button[face=floor,facing=east,powered=false])
B(-8,-1,-6,minecraft:dark_oak_slab[type=top,waterlogged=false])
B(-8,0,-6,minecraft:cyan_terracotta)
B(-8,1,-6,minecraft:dark_oak_slab)
B(-8,-7,-5,minecraft:dark_oak_wood)
B(-8,-6,-5,minecraft:melon)
B(-8,-5,-5,minecraft:melon)
B(-8,-4,-5,minecraft:dark_oak_planks)
B(-8,-3,-5,minecraft:dark_oak_stairs)
B(-8,-1,-5,minecraft:dark_oak_slab[type=top,waterlogged=false])
B(-8,-7,-4,minecraft:dark_oak_wood)
B(-8,-6,-4,minecraft:hay_block)
B(-8,-4,-4,minecraft:dark_oak_planks)
B(-8,-1,-4,minecraft:dark_oak_slab[type=top,waterlogged=false])
B(-8,-7,-3,minecraft:dark_oak_wood)
B(-8,-6,-3,minecraft:hay_block)
B(-8,-4,-3,minecraft:dark_oak_planks)
B(-8,-3,-3,minecraft:stone_button)
B(-8,-1,-3,minecraft:dark_oak_slab[type=top,waterlogged=false])
B(-8,0,-3,minecraft:stone_button[face=wall,facing=west,powered=false])
B(-8,-8,-2,minecraft:dark_oak_wood)
B(-8,-4,-2,minecraft:dark_oak_planks)
B(-8,-3,-2,minecraft:birch_planks)
B(-8,-2,-2,minecraft:stone_button[face=floor,facing=east,powered=false])
B(-8,-1,-2,minecraft:dark_oak_slab[type=top,waterlogged=false])
B(-8,16,-2,minecraft:black_wool)
B(-8,17,-2,minecraft:black_wool)
B(-8,18,-2,minecraft:black_wool)
B(-8,-9,-1,minecraft:dark_oak_wood)
B(-8,-8,-1,minecraft:dark_oak_wood)
B(-8,-7,-1,minecraft:ladder[facing=west,waterlogged=false])
B(-8,-6,-1,minecraft:ladder[facing=west,waterlogged=false])
B(-8,-5,-1,minecraft:ladder[facing=west,waterlogged=false])
B(-8,-4,-1,minecraft:oak_trapdoor[facing=south,half=top,open=false,powered=false,waterlogged=false])
B(-8,-3,-1,minecraft:stone_button[face=wall,facing=south,powered=false])
B(-8,0,-1,minecraft:oak_trapdoor[facing=south,half=bottom,open=false,powered=false,waterlogged=false])
B(-8,5,-1,minecraft:black_wool)
B(-8,14,-1,minecraft:black_wool)
B(-8,15,-1,minecraft:black_wool)
B(-8,19,-1,minecraft:black_wool)
B(-7,-2,-8,minecraft:oak_button)
B(-7,-4,-7,minecraft:dark_oak_planks)
B(-7,-3,-7,minecraft:dark_oak_planks)
B(-7,-2,-7,minecraft:dark_oak_planks)
B(-7,-1,-7,minecraft:cyan_terracotta)
B(-7,0,-7,minecraft:cyan_terracotta)
B(-7,1,-7,minecraft:dark_oak_slab)
B(-7,-6,-6,minecraft:dark_oak_wood)
B(-7,-5,-6,minecraft:dark_oak_wood)
B(-7,-4,-6,minecraft:dark_oak_planks)
B(-7,-3,-6,minecraft:stone_button[face=wall,facing=east,powered=false])
B(-7,-2,-6,minecraft:dark_oak_slab)
B(-7,-1,-6,minecraft:dark_oak_slab[type=top,waterlogged=false])
B(-7,0,-6,minecraft:oak_button[face=wall,facing=west,powered=false])
B(-7,-7,-5,minecraft:dark_oak_wood)
B(-7,-6,-5,minecraft:dark_oak_planks)
B(-7,-5,-5,minecraft:dark_oak_planks)
B(-7,-4,-5,minecraft:dark_oak_planks)
B(-7,-1,-5,minecraft:dark_oak_slab[type=top,waterlogged=false])
B(-7,-7,-4,minecraft:dark_oak_wood)
B(-7,-6,-4,minecraft:dark_oak_planks)
B(-7,-5,-4,minecraft:dark_oak_planks)
B(-7,-4,-4,minecraft:dark_oak_planks)
B(-7,-3,-4,minecraft:brown_carpet)
B(-7,-1,-4,minecraft:dark_oak_slab[type=top,waterlogged=false])
B(-7,0,-4,minecraft:stone_button)
B(-7,-8,-3,minecraft:dark_oak_wood)
B(-7,-7,-3,minecraft:dark_oak_planks)
B(-7,-6,-3,minecraft:dark_oak_planks)
B(-7,-5,-3,minecraft:dark_oak_planks)
B(-7,-4,-3,minecraft:dark_oak_planks)
B(-7,-3,-3,minecraft:stone_button)
B(-7,-1,-3,minecraft:dark_oak_slab[type=top,waterlogged=false])
B(-7,0,-3,minecraft:birch_planks)
B(-7,1,-3,minecraft:stone_button[face=floor,facing=east,powered=false])
B(-7,-8,-2,minecraft:dark_oak_wood)
B(-7,-7,-2,minecraft:dark_oak_planks)
B(-7,-6,-2,minecraft:dark_oak_planks)
B(-7,-5,-2,minecraft:dark_oak_planks)
B(-7,-4,-2,minecraft:dark_oak_planks)
B(-7,-3,-2,minecraft:birch_planks)
B(-7,-2,-2,minecraft:stone_button[face=floor,facing=east,powered=false])
B(-7,-1,-2,minecraft:dark_oak_slab[type=top,waterlogged=false])
B(-7,0,-2,minecraft:stone_button[face=wall,facing=south,powered=false])
B(-7,16,-2,minecraft:black_wool)
B(-7,17,-2,minecraft:black_wool)
B(-7,18,-2,minecraft:black_wool)
B(-7,-9,-1,minecraft:dark_oak_wood)
B(-7,-8,-1,minecraft:dark_oak_wood)
B(-7,-7,-1,minecraft:dark_oak_planks)
B(-7,-6,-1,minecraft:dark_oak_planks)
B(-7,-5,-1,minecraft:dark_oak_planks)
B(-7,-4,-1,minecraft:spruce_slab[type=double,waterlogged=false])
B(-7,-3,-1,minecraft:stone_button[face=wall,facing=south,powered=false])
B(-7,0,-1,minecraft:oak_trapdoor[facing=south,half=bottom,open=false,powered=false,waterlogged=false])
B(-7,4,-1,minecraft:black_wool)
B(-7,5,-1,minecraft:black_wool)
B(-7,6,-1,minecraft:black_wool)
B(-7,15,-1,minecraft:black_wool)
B(-7,19,-1,minecraft:black_wool)
B(-7,20,-1,minecraft:black_wool)
B(-6,-2,-8,minecraft:oak_button)
B(-6,0,-8,minecraft:dispenser)
B(-6,-4,-7,minecraft:dark_oak_planks)
B(-6,-3,-7,minecraft:dark_oak_planks)
B(-6,-2,-7,minecraft:dark_oak_planks)
B(-6,-1,-7,minecraft:cyan_terracotta)
B(-6,0,-7,minecraft:black_concrete)
B(-6,-6,-6,minecraft:dark_oak_wood)
B(-6,-5,-6,minecraft:dark_oak_wood)
B(-6,-4,-6,minecraft:dark_oak_planks)
B(-6,-3,-6,minecraft:tripwire_hook[attached=false,facing=south,powered=false])
B(-6,-2,-6,minecraft:dark_oak_slab)
B(-6,-1,-6,minecraft:dark_oak_slab[type=top,waterlogged=false])
B(-6,0,-6,minecraft:dispenser[facing=up,triggered=true])
B(-6,1,-6,minecraft:lever[face=floor,facing=south,powered=true])
B(-6,-7,-5,minecraft:dark_oak_wood)
B(-6,-6,-5,minecraft:lapis_ore)
B(-6,-5,-5,minecraft:lapis_ore)
B(-6,-4,-5,minecraft:dark_oak_planks)
B(-6,-3,-5,minecraft:tripwire)
B(-6,-1,-5,minecraft:dark_oak_slab[type=top,waterlogged=false])
B(-6,0,-5,minecraft:spruce_stairs)
B(-6,-7,-4,minecraft:dark_oak_wood)
B(-6,-6,-4,minecraft:gold_ore)
B(-6,-5,-4,minecraft:redstone_ore)
B(-6,-4,-4,minecraft:dark_oak_planks)
B(-6,-1,-4,minecraft:dark_oak_slab[type=top,waterlogged=false])
B(-6,0,-4,minecraft:stone_button)
B(-6,-8,-3,minecraft:dark_oak_wood)
B(-6,-7,-3,minecraft:gold_ore)
B(-6,-6,-3,minecraft:iron_ore)
B(-6,-4,-3,minecraft:dark_oak_planks)
B(-6,-3,-3,minecraft:stone_button)
B(-6,-1,-3,minecraft:dark_oak_slab[type=top,waterlogged=false])
B(-6,0,-3,minecraft:birch_planks)
B(-6,1,-3,minecraft:stone_button[face=floor,facing=east,powered=false])
B(-6,-8,-2,minecraft:dark_oak_wood)
B(-6,-7,-2,minecraft:iron_ore)
B(-6,-4,-2,minecraft:dark_oak_planks)
B(-6,-3,-2,minecraft:birch_planks)
B(-6,-2,-2,minecraft:stone_button[face=floor,facing=east,powered=false])
B(-6,-1,-2,minecraft:dark_oak_slab[type=top,waterlogged=false])
B(-6,0,-2,minecraft:stone_button[face=wall,facing=south,powered=false])
B(-6,5,-2,minecraft:black_wool)
B(-6,17,-2,minecraft:black_wool)
B(-6,18,-2,minecraft:black_wool)
B(-6,19,-2,minecraft:black_wool)
B(-6,-9,-1,minecraft:dark_oak_wood)
B(-6,-8,-1,minecraft:dark_oak_wood)
B(-6,-7,-1,minecraft:ladder[facing=east,waterlogged=false])
B(-6,-6,-1,minecraft:ladder[facing=east,waterlogged=false])
B(-6,-5,-1,minecraft:ladder[facing=east,waterlogged=false])
B(-6,-4,-1,minecraft:oak_trapdoor[facing=south,half=top,open=false,powered=false,waterlogged=false])
B(-6,-3,-1,minecraft:stone_button[face=wall,facing=south,powered=false])
B(-6,0,-1,minecraft:oak_trapdoor[facing=south,half=bottom,open=false,powered=false,waterlogged=false])
B(-6,4,-1,minecraft:black_wool)
B(-6,6,-1,minecraft:black_wool)
B(-6,15,-1,minecraft:black_wool)
B(-6,16,-1,minecraft:black_wool)
B(-6,20,-1,minecraft:black_wool)
B(-5,-3,-8,minecraft:oak_trapdoor[facing=south,half=top,open=false,powered=false,waterlogged=false])
B(-5,-2,-8,minecraft:oak_button)
B(-5,-4,-7,minecraft:dark_oak_planks)
B(-5,-3,-7,minecraft:dispenser)
B(-5,-2,-7,minecraft:dark_oak_planks)
B(-5,-1,-7,minecraft:cyan_terracotta)
B(-5,0,-7,minecraft:cyan_terracotta)
B(-5,1,-7,minecraft:dark_oak_slab)
B(-5,-6,-6,minecraft:dark_oak_wood)
B(-5,-5,-6,minecraft:dark_oak_wood)
B(-5,-4,-6,minecraft:dark_oak_planks)
B(-5,-3,-6,minecraft:black_concrete)
B(-5,-2,-6,minecraft:oak_button[face=floor,facing=east,powered=false])
B(-5,-1,-6,minecraft:dark_oak_slab[type=top,waterlogged=false])
B(-5,0,-6,minecraft:oak_button[face=wall,facing=east,powered=false])
B(-5,-7,-5,minecraft:dark_oak_wood)
B(-5,-6,-5,minecraft:gold_ore)
B(-5,-5,-5,minecraft:redstone_ore)
B(-5,-4,-5,minecraft:dark_oak_planks)
B(-5,-3,-5,minecraft:dark_oak_stairs)
B(-5,-1,-5,minecraft:dark_oak_slab[type=top,waterlogged=false])
B(-5,-7,-4,minecraft:dark_oak_wood)
B(-5,-6,-4,minecraft:lapis_ore)
B(-5,-5,-4,minecraft:black_concrete)
B(-5,-4,-4,minecraft:dark_oak_planks)
B(-5,-3,-4,minecraft:brown_carpet)
B(-5,-1,-4,minecraft:dark_oak_slab[type=top,waterlogged=false])
B(-5,0,-4,minecraft:stone_button)
B(-5,-8,-3,minecraft:dark_oak_wood)
B(-5,-7,-3,minecraft:iron_ore)
B(-5,-6,-3,minecraft:redstone_ore)
B(-5,-4,-3,minecraft:dark_oak_planks)
B(-5,-3,-3,minecraft:brown_carpet)
B(-5,-1,-3,minecraft:dark_oak_slab[type=top,waterlogged=false])
B(-5,0,-3,minecraft:birch_planks)
B(-5,1,-3,minecraft:stone_button[face=floor,facing=east,powered=false])
B(-5,-8,-2,minecraft:dark_oak_wood)
B(-5,-7,-2,minecraft:iron_ore)
B(-5,-4,-2,minecraft:dark_oak_planks)
B(-5,-3,-2,minecraft:stone_button[face=wall,facing=east,powered=false])
B(-5,-1,-2,minecraft:dark_oak_slab[type=top,waterlogged=false])
B(-5,0,-2,minecraft:stone_button[face=wall,facing=south,powered=false])
B(-5,5,-2,minecraft:black_wool)
B(-5,17,-2,minecraft:black_wool)
B(-5,18,-2,minecraft:black_wool)
B(-5,19,-2,minecraft:black_wool)
B(-5,-9,-1,minecraft:dark_oak_wood)
B(-5,-8,-1,minecraft:coal_ore)
B(-5,-4,-1,minecraft:oak_trapdoor[facing=south,half=top,open=false,powered=false,waterlogged=false])
B(-5,0,-1,minecraft:oak_trapdoor[facing=south,half=bottom,open=false,powered=false,waterlogged=false])
B(-5,4,-1,minecraft:black_wool)
B(-5,6,-1,minecraft:black_wool)
B(-5,7,-1,minecraft:black_wool)
B(-5,15,-1,minecraft:black_wool)
B(-5,16,-1,minecraft:black_wool)
B(-5,20,-1,minecraft:black_wool)
B(-5,21,-1,minecraft:black_wool)
B(-4,-2,-8,minecraft:oak_button)
B(-4,-4,-7,minecraft:dark_oak_planks)
B(-4,-3,-7,minecraft:dark_oak_planks)
B(-4,-2,-7,minecraft:dark_oak_planks)
B(-4,-1,-7,minecraft:cyan_terracotta)
B(-4,0,-7,minecraft:cyan_terracotta)
B(-4,1,-7,minecraft:dark_oak_slab)
B(-4,-6,-6,minecraft:dark_oak_wood)
B(-4,-5,-6,minecraft:dark_oak_wood)
B(-4,-4,-6,minecraft:dark_oak_planks)
B(-4,-3,-6,minecraft:stone_button[face=wall,facing=east,powered=false])
B(-4,-2,-6,minecraft:dark_oak_slab)
B(-4,-1,-6,minecraft:dark_oak_slab[type=top,waterlogged=false])
B(-4,0,-6,minecraft:oak_button[face=wall,facing=west,powered=false])
B(-4,-7,-5,minecraft:dark_oak_wood)
B(-4,-6,-5,minecraft:lapis_ore)
B(-4,-5,-5,minecraft:redstone_ore)
B(-4,-4,-5,minecraft:dark_oak_planks)
B(-4,-1,-5,minecraft:dark_oak_slab[type=top,waterlogged=false])
B(-4,-7,-4,minecraft:dark_oak_wood)
B(-4,-6,-4,minecraft:iron_ore)
B(-4,-5,-4,minecraft:redstone_ore)
B(-4,-4,-4,minecraft:dark_oak_planks)
B(-4,-3,-4,minecraft:green_carpet)
B(-4,-1,-4,minecraft:dark_oak_slab[type=top,waterlogged=false])
B(-4,-8,-3,minecraft:dark_oak_wood)
B(-4,-7,-3,minecraft:gold_ore)
B(-4,-6,-3,minecraft:redstone_ore)
B(-4,-4,-3,minecraft:dark_oak_planks)
B(-4,-3,-3,minecraft:brown_carpet)
B(-4,-1,-3,minecraft:dark_oak_slab[type=top,waterlogged=false])
B(-4,0,-3,minecraft:stone_button[face=wall,facing=east,powered=false])
B(-4,-8,-2,minecraft:dark_oak_wood)
B(-4,-7,-2,minecraft:iron_ore)
B(-4,-4,-2,minecraft:dark_oak_planks)
B(-4,-3,-2,minecraft:stone_button[face=wall,facing=west,powered=false])
B(-4,-1,-2,minecraft:dark_oak_slab[type=top,waterlogged=false])
B(-4,0,-2,minecraft:stone_button[face=wall,facing=west,powered=false])
B(-4,5,-2,minecraft:black_wool)
B(-4,6,-2,minecraft:black_wool)
B(-4,19,-2,minecraft:black_wool)
B(-4,-9,-1,minecraft:dark_oak_wood)
B(-4,-8,-1,minecraft:lapis_ore)
B(-4,-7,-1,minecraft:black_concrete)
B(-4,-4,-1,minecraft:oak_trapdoor[facing=south,half=top,open=false,powered=false,waterlogged=false])
B(-4,0,-1,minecraft:oak_trapdoor[facing=south,half=bottom,open=false,powered=false,waterlogged=false])
B(-4,4,-1,minecraft:black_wool)
B(-4,7,-1,minecraft:black_wool)
B(-4,14,-1,minecraft:black_wool)
B(-4,15,-1,minecraft:black_wool)
B(-4,20,-1,minecraft:black_wool)
B(-4,21,-1,minecraft:black_wool)
B(-3,-2,-8,minecraft:oak_button)
B(-3,0,-8,minecraft:dispenser)
B(-3,-4,-7,minecraft:dark_oak_planks)
B(-3,-3,-7,minecraft:dark_oak_planks)
B(-3,-2,-7,minecraft:dark_oak_planks)
B(-3,-1,-7,minecraft:cyan_terracotta)
B(-3,0,-7,minecraft:black_concrete)
B(-3,-6,-6,minecraft:dark_oak_wood)
B(-3,-5,-6,minecraft:dark_oak_wood)
B(-3,-4,-6,minecraft:dark_oak_planks)
B(-3,-3,-6,minecraft:tripwire_hook[attached=false,facing=south,powered=false])
B(-3,-2,-6,minecraft:dark_oak_slab)
B(-3,-1,-6,minecraft:dark_oak_slab[type=top,waterlogged=false])
B(-3,0,-6,minecraft:dispenser[facing=up,triggered=true])
B(-3,1,-6,minecraft:lever[face=floor,facing=south,powered=true])
B(-3,-7,-5,minecraft:dark_oak_wood)
B(-3,-6,-5,minecraft:lapis_ore)
B(-3,-5,-5,minecraft:iron_ore)
B(-3,-4,-5,minecraft:dark_oak_planks)
B(-3,-3,-5,minecraft:tripwire)
B(-3,-1,-5,minecraft:dark_oak_slab[type=top,waterlogged=false])
B(-3,0,-5,minecraft:spruce_stairs)
B(-3,-7,-4,minecraft:dark_oak_wood)
B(-3,-6,-4,minecraft:iron_ore)
B(-3,-5,-4,minecraft:coal_ore)
B(-3,-4,-4,minecraft:dark_oak_planks)
B(-3,-3,-4,minecraft:brown_carpet)
B(-3,-1,-4,minecraft:dark_oak_slab[type=top,waterlogged=false])
B(-3,-8,-3,minecraft:dark_oak_wood)
B(-3,-7,-3,minecraft:lapis_ore)
B(-3,-6,-3,minecraft:coal_ore)
B(-3,-5,-3,minecraft:black_concrete)
B(-3,-4,-3,minecraft:dark_oak_planks)
B(-3,-3,-3,minecraft:stone_button)
B(-3,-1,-3,minecraft:dark_oak_slab[type=top,waterlogged=false])
B(-3,0,-3,minecraft:stone_button)
B(-3,-8,-2,minecraft:dark_oak_wood)
B(-3,-7,-2,minecraft:coal_ore)
B(-3,-6,-2,minecraft:black_concrete)
B(-3,-4,-2,minecraft:dark_oak_planks)
B(-3,-3,-2,minecraft:birch_planks)
B(-3,-2,-2,minecraft:stone_button[face=floor,facing=east,powered=false])
B(-3,-1,-2,minecraft:dark_oak_slab[type=top,waterlogged=false])
B(-3,0,-2,minecraft:birch_planks)
B(-3,1,-2,minecraft:stone_button[face=floor,facing=east,powered=false])
B(-3,6,-2,minecraft:black_wool)
B(-3,20,-2,minecraft:black_wool)
B(-3,-9,-1,minecraft:dark_oak_wood)
B(-3,-8,-1,minecraft:lapis_ore)
B(-3,-7,-1,minecraft:coal_ore)
B(-3,-4,-1,minecraft:oak_trapdoor[facing=south,half=top,open=false,powered=false,waterlogged=false])
B(-3,-3,-1,minecraft:stone_button[face=wall,facing=west,powered=false])
B(-3,-1,-1,minecraft:dark_oak_slab[type=top,waterlogged=false])
B(-3,0,-1,minecraft:stone_button[face=wall,facing=south,powered=false])
B(-3,3,-1,minecraft:black_wool)
B(-3,4,-1,minecraft:black_wool)
B(-3,5,-1,minecraft:black_wool)
B(-3,7,-1,minecraft:black_wool)
B(-3,8,-1,minecraft:black_wool)
B(-3,21,-1,minecraft:black_wool)
B(-3,22,-1,minecraft:black_wool)
B(-2,-3,-8,minecraft:oak_trapdoor[facing=south,half=top,open=false,powered=false,waterlogged=false])
B(-2,-2,-8,minecraft:oak_button)
B(-2,-4,-7,minecraft:dark_oak_planks)
B(-2,-3,-7,minecraft:dispenser)
B(-2,-2,-7,minecraft:dark_oak_planks)
B(-2,-1,-7,minecraft:cyan_terracotta)
B(-2,0,-7,minecraft:cyan_terracotta)
B(-2,1,-7,minecraft:dark_oak_slab)
B(-2,-6,-6,minecraft:dark_oak_wood)
B(-2,-5,-6,minecraft:dark_oak_wood)
B(-2,-4,-6,minecraft:dark_oak_planks)
B(-2,-3,-6,minecraft:black_concrete)
B(-2,-2,-6,minecraft:oak_button[face=floor,facing=east,powered=false])
B(-2,-1,-6,minecraft:dark_oak_slab[type=top,waterlogged=false])
B(-2,0,-6,minecraft:oak_button[face=wall,facing=east,powered=false])
B(-2,-7,-5,minecraft:dark_oak_wood)
B(-2,-6,-5,minecraft:lapis_ore)
B(-2,-5,-5,minecraft:redstone_ore)
B(-2,-4,-5,minecraft:dark_oak_planks)
B(-2,-3,-5,minecraft:dark_oak_stairs)
B(-2,-1,-5,minecraft:dark_oak_slab[type=top,waterlogged=false])
B(-2,-7,-4,minecraft:dark_oak_wood)
B(-2,-6,-4,minecraft:iron_ore)
B(-2,-5,-4,minecraft:coal_ore)
B(-2,-4,-4,minecraft:dark_oak_planks)
B(-2,-3,-4,minecraft:brown_carpet)
B(-2,-1,-4,minecraft:dark_oak_slab[type=top,waterlogged=false])
B(-2,-8,-3,minecraft:dark_oak_wood)
B(-2,-7,-3,minecraft:gold_ore)
B(-2,-6,-3,minecraft:redstone_ore)
B(-2,-5,-3,minecraft:coal_ore)
B(-2,-4,-3,minecraft:dark_oak_planks)
B(-2,-3,-3,minecraft:stone_button)
B(-2,-1,-3,minecraft:dark_oak_slab[type=top,waterlogged=false])
B(-2,0,-3,minecraft:stone_button)
B(-2,-8,-2,minecraft:dark_oak_wood)
B(-2,-7,-2,minecraft:lapis_ore)
B(-2,-6,-2,minecraft:coal_ore)
B(-2,-4,-2,minecraft:dark_oak_planks)
B(-2,-3,-2,minecraft:birch_planks)
B(-2,-2,-2,minecraft:stone_button[face=floor,facing=east,powered=false])
B(-2,-1,-2,minecraft:dark_oak_slab[type=top,waterlogged=false])
B(-2,0,-2,minecraft:birch_planks)
B(-2,1,-2,minecraft:stone_button[face=floor,facing=east,powered=false])
B(-2,-9,-1,minecraft:dark_oak_wood)
B(-2,-8,-1,minecraft:lapis_ore)
B(-2,-7,-1,minecraft:iron_ore)
B(-2,-6,-1,minecraft:coal_ore)
B(-2,-5,-1,minecraft:black_concrete)
B(-2,-4,-1,minecraft:dark_oak_planks)
B(-2,-3,-1,minecraft:birch_planks)
B(-2,-2,-1,minecraft:stone_button[face=floor,facing=east,powered=false])
B(-2,-1,-1,minecraft:dark_oak_slab[type=top,waterlogged=false])
B(-2,3,-1,minecraft:black_wool)
B(-2,8,-1,minecraft:black_wool)
B(-2,9,-1,minecraft:black_wool)
B(-2,22,-1,minecraft:black_wool)
B(-1,-2,-8,minecraft:oak_button)
B(-1,-4,-7,minecraft:dark_oak_planks)
B(-1,-3,-7,minecraft:dark_oak_planks)
B(-1,-2,-7,minecraft:dark_oak_planks)
B(-1,-1,-7,minecraft:cyan_terracotta)
B(-1,0,-7,minecraft:cyan_terracotta)
B(-1,1,-7,minecraft:dark_oak_slab)
B(-1,-6,-6,minecraft:dark_oak_wood)
B(-1,-5,-6,minecraft:dark_oak_wood)
B(-1,-4,-6,minecraft:dark_oak_planks)
B(-1,-3,-6,minecraft:stone_button[face=wall,facing=east,powered=false])
B(-1,-2,-6,minecraft:dark_oak_slab)
B(-1,-1,-6,minecraft:dark_oak_slab[type=top,waterlogged=false])
B(-1,0,-6,minecraft:oak_button[face=wall,facing=west,powered=false])
B(-1,-7,-5,minecraft:dark_oak_wood)
B(-1,-6,-5,minecraft:gold_ore)
B(-1,-5,-5,minecraft:iron_ore)
B(-1,-4,-5,minecraft:dark_oak_planks)
B(-1,-1,-5,minecraft:dark_oak_slab[type=top,waterlogged=false])
B(-1,-7,-4,minecraft:dark_oak_wood)
B(-1,-6,-4,minecraft:iron_ore)
B(-1,-5,-4,minecraft:coal_ore)
B(-1,-4,-4,minecraft:dark_oak_planks)
B(-1,-1,-4,minecraft:dark_oak_slab[type=top,waterlogged=false])
B(-1,-8,-3,minecraft:dark_oak_wood)
B(-1,-7,-3,minecraft:lapis_ore)
B(-1,-6,-3,minecraft:redstone_ore)
B(-1,-5,-3,minecraft:coal_ore)
B(-1,-4,-3,minecraft:dark_oak_planks)
B(-1,-3,-3,minecraft:brown_carpet)
B(-1,-1,-3,minecraft:dark_oak_slab[type=top,waterlogged=false])
B(-1,-8,-2,minecraft:dark_oak_wood)
B(-1,-7,-2,minecraft:lapis_ore)
B(-1,-6,-2,minecraft:coal_ore)
B(-1,-5,-2,minecraft:coal_ore)
B(-1,-4,-2,minecraft:dark_oak_planks)
B(-1,-3,-2,minecraft:stone_button[face=wall,facing=east,powered=false])
B(-1,-1,-2,minecraft:dark_oak_slab[type=top,waterlogged=false])
B(-1,0,-2,minecraft:dark_oak_fence[east=false,north=false,south=true,waterlogged=false,west=true])
B(-1,17,-2,minecraft:black_wool)
B(-1,-9,-1,minecraft:dark_oak_wood)
B(-1,-8,-1,minecraft:gold_ore)
B(-1,-7,-1,minecraft:iron_ore)
B(-1,-6,-1,minecraft:coal_ore)
B(-1,-5,-1,minecraft:coal_ore)
B(-1,-4,-1,minecraft:dark_oak_planks)
B(-1,-3,-1,minecraft:cyan_terracotta)
B(-1,-2,-1,minecraft:cyan_terracotta)
B(-1,-1,-1,minecraft:dark_oak_slab[type=double,waterlogged=false])
B(-1,0,-1,minecraft:dark_oak_fence[east=false,north=true,south=false,waterlogged=false,west=false])
B(-1,3,-1,minecraft:spruce_fence[east=false,north=false,south=false,waterlogged=false,west=true])
B(-1,16,-1,minecraft:black_wool)
B(-1,17,-1,minecraft:black_wool)
B(-1,18,-1,minecraft:black_wool)
RB(-8,0,-2,minecraft:chest,../NBT/StructureLoot/JunkChest_1.nbt,15,minecraft:chest,../NBT/StructureLoot/JunkChest_2.nbt,15,minecraft:chest,../NBT/StructureLoot/JunkChest_3.nbt,15,minecraft:chest,../NBT/StructureLoot/JunkChest_4.nbt,15,minecraft:chest,../NBT/StructureLoot/JunkChest_5.nbt,15,minecraft:chest,../NBT/StructureLoot/Common1.nbt,15,minecraft:chest,../NBT/StructureLoot/Common2.nbt,15,minecraft:chest,../NBT/StructureLoot/Common3.nbt,15,minecraft:chest,../NBT/StructureLoot/Common4.nbt,15,minecraft:chest,../NBT/StructureLoot/Common5.nbt,15,minecraft:chest,../NBT/StructureLoot/Common6.nbt,15,minecraft:chest,../NBT/StructureLoot/Common7.nbt,15,minecraft:chest,../NBT/StructureLoot/Common8.nbt,15,minecraft:chest,../NBT/StructureLoot/Common9.nbt,15,minecraft:chest,../NBT/StructureLoot/Common10.nbt,15,minecraft:chest,../NBT/StructureLoot/Common11.nbt,15,minecraft:chest,../NBT/StructureLoot/Common12.nbt,15,minecraft:chest,../NBT/StructureLoot/Common13.nbt,15,minecraft:chest,../NBT/StructureLoot/Common14.nbt,15,minecraft:chest,../NBT/StructureLoot/Common15.nbt,100)

#######################################################################
# +-----------------------------------------------------------------+ #
# |                            BO3 checks                           | #
# +-----------------------------------------------------------------+ #
#######################################################################


#######################################################################
# +-----------------------------------------------------------------+ #
# |                             Branches                            | #
# +-----------------------------------------------------------------+ #
#######################################################################

Branch(-8,0,0,WestPortShipPillager_4x3,NORTH,100.0)

#######################################################################
# +-----------------------------------------------------------------+ #
# |                             Entities                            | #
# +-----------------------------------------------------------------+ #
#######################################################################

Entity(-7,-2,-4,minecraft:vindication_illager,1,../NBT/MOBS/RandomPillager.txt)
