
#######################################################################
# +-----------------------------------------------------------------+ #
# |                            BO3 object                           | #
# +-----------------------------------------------------------------+ #
#######################################################################

Author: Bo3 BulkEdit

Description: Converted Schematic - Modified by Bo3BulkEdit

Version: 3

SettingsMode: WriteWithoutComments


#######################################################################
# +-----------------------------------------------------------------+ #
# |                          Main settings                          | #
# +-----------------------------------------------------------------+ #
#######################################################################

Tree: false

Frequency: 1

Rarity: 100.0

RotateRandomly: false

SpawnHeight: randomY

SpawnHeightOffset: 0

SpawnHeightVariance: 0

##############################
# Height Limits for the BO3. #
##############################

MinHeight: 0

MaxHeight: 255

######################
# Extrusion settings #
######################

ExtrudeMode: None

ExtrudeThroughBlocks: minecraft:air

MaxBranchDepth: 20


#######################################################################
# +-----------------------------------------------------------------+ #
# |                      Source block settings                      | #
# +-----------------------------------------------------------------+ #
#######################################################################

SourceBlocks: otg:air

MaxPercentageOutsideSourceBlock: 100

OutsideSourceBlock: placeAnyway

DoReplaceBlocks: true

IsOTGPlus: false


#######################################################################
# +-----------------------------------------------------------------+ #
# |                              Blocks                             | #
# +-----------------------------------------------------------------+ #
#######################################################################

B(-8,-3,-7,minecraft:oak_trapdoor[facing=south,half=top,open=false,powered=false,waterlogged=false])
B(-8,-2,-7,minecraft:oak_button)
B(-8,0,-7,minecraft:dark_oak_stairs[facing=south,half=top,shape=straight,waterlogged=false])
B(-8,1,-7,minecraft:spruce_fence[east=false,north=false,south=true,waterlogged=false,west=false])
B(-8,2,-7,minecraft:spruce_fence)
B(-8,-5,-6,minecraft:dark_oak_wood)
B(-8,-4,-6,minecraft:dark_oak_planks)
B(-8,-3,-6,minecraft:dispenser)
B(-8,-2,-6,minecraft:dark_oak_slab[type=double,waterlogged=false])
B(-8,-1,-6,minecraft:cyan_terracotta)
B(-8,0,-6,minecraft:cyan_terracotta)
B(-8,1,-6,minecraft:cyan_terracotta)
B(-8,2,-6,minecraft:dark_oak_stairs[facing=west,half=bottom,shape=straight,waterlogged=false])
B(-8,-6,-5,minecraft:dark_oak_wood)
B(-8,-5,-5,minecraft:dark_oak_planks)
B(-8,-4,-5,minecraft:dark_oak_planks)
B(-8,-3,-5,minecraft:black_concrete)
B(-8,-2,-5,minecraft:oak_button[face=floor,facing=east,powered=false])
B(-8,-1,-5,minecraft:dark_oak_slab[type=top,waterlogged=false])
B(-8,0,-5,minecraft:cyan_terracotta)
B(-8,1,-5,minecraft:cyan_terracotta)
B(-8,2,-5,minecraft:cyan_terracotta)
B(-8,3,-5,minecraft:dark_oak_stairs[facing=east,half=bottom,shape=straight,waterlogged=false])
B(-8,-7,-4,minecraft:dark_oak_wood)
B(-8,-6,-4,minecraft:dark_oak_planks)
B(-8,-5,-4,minecraft:dark_oak_planks)
B(-8,-4,-4,minecraft:dark_oak_planks)
B(-8,-3,-4,minecraft:dark_oak_stairs)
B(-8,-1,-4,minecraft:dark_oak_slab[type=top,waterlogged=false])
B(-8,0,-4,minecraft:oak_trapdoor[facing=west,half=bottom,open=true,powered=false,waterlogged=false])
B(-8,1,-4,minecraft:cyan_terracotta)
B(-8,2,-4,minecraft:spruce_stairs[facing=east,half=bottom,shape=straight,waterlogged=false])
B(-8,-7,-3,minecraft:dark_oak_wood)
B(-8,-6,-3,minecraft:dark_oak_planks)
B(-8,-5,-3,minecraft:dark_oak_planks)
B(-8,-4,-3,minecraft:dark_oak_planks)
B(-8,-1,-3,minecraft:dark_oak_slab[type=top,waterlogged=false])
B(-8,0,-3,minecraft:cyan_terracotta)
B(-8,1,-3,minecraft:cyan_terracotta)
B(-8,2,-3,minecraft:cyan_terracotta)
B(-8,3,-3,minecraft:dark_oak_fence[east=false,north=false,south=true,waterlogged=false,west=false])
B(-8,-7,-2,minecraft:dark_oak_wood)
B(-8,-6,-2,minecraft:dark_oak_planks)
B(-8,-5,-2,minecraft:dark_oak_planks)
B(-8,-4,-2,minecraft:dark_oak_planks)
B(-8,-1,-2,minecraft:dark_oak_slab[type=top,waterlogged=false])
B(-8,0,-2,minecraft:cyan_terracotta)
B(-8,1,-2,minecraft:cyan_terracotta)
B(-8,2,-2,minecraft:cyan_terracotta)
B(-8,3,-2,minecraft:dark_oak_fence[east=false,north=true,south=false,waterlogged=false,west=false])
B(-8,6,-2,minecraft:spruce_wood)
B(-8,-8,-1,minecraft:dark_oak_wood)
B(-8,-7,-1,minecraft:dark_oak_planks)
B(-8,-6,-1,minecraft:dark_oak_planks)
B(-8,-5,-1,minecraft:dark_oak_planks)
B(-8,-4,-1,minecraft:dark_oak_planks)
B(-8,-3,-1,minecraft:brown_carpet)
B(-8,-1,-1,minecraft:dark_oak_slab[type=top,waterlogged=false])
B(-8,0,-1,minecraft:cyan_terracotta)
B(-8,1,-1,minecraft:cyan_terracotta)
B(-8,2,-1,minecraft:cyan_terracotta)
B(-7,-2,-7,minecraft:oak_button)
B(-7,-4,-6,minecraft:dark_oak_planks)
B(-7,-3,-6,minecraft:dark_oak_planks)
B(-7,-2,-6,minecraft:dark_oak_planks)
B(-7,-1,-6,minecraft:cyan_terracotta)
B(-7,0,-6,minecraft:cyan_terracotta)
B(-7,1,-6,minecraft:dark_oak_stairs[facing=west,half=bottom,shape=straight,waterlogged=false])
B(-7,-6,-5,minecraft:dark_oak_wood)
B(-7,-5,-5,minecraft:dark_oak_wood)
B(-7,-4,-5,minecraft:dark_oak_planks)
B(-7,-3,-5,minecraft:cyan_terracotta)
B(-7,-2,-5,minecraft:cyan_terracotta)
B(-7,-1,-5,minecraft:dark_oak_slab[type=double,waterlogged=false])
B(-7,0,-5,minecraft:furnace[facing=south,lit=false])
B(-7,1,-5,minecraft:iron_trapdoor)
B(-7,2,-5,minecraft:cyan_terracotta)
B(-7,3,-5,minecraft:cyan_terracotta)
B(-7,4,-5,minecraft:dark_oak_slab)
B(-7,-6,-4,minecraft:dark_oak_wood)
B(-7,-4,-4,minecraft:dark_oak_planks)
B(-7,-3,-4,minecraft:cyan_terracotta)
B(-7,-2,-4,minecraft:cyan_terracotta)
B(-7,-1,-4,minecraft:dark_oak_slab[type=double,waterlogged=false])
B(-7,2,-4,minecraft:cyan_terracotta)
B(-7,-7,-3,minecraft:dark_oak_wood)
B(-7,-4,-3,minecraft:dark_oak_planks)
B(-7,-3,-3,minecraft:cyan_terracotta)
B(-7,-2,-3,minecraft:cyan_terracotta)
B(-7,-1,-3,minecraft:dark_oak_slab[type=double,waterlogged=false])
B(-7,2,-3,minecraft:cyan_terracotta)
B(-7,6,-3,minecraft:black_wool)
B(-7,-7,-2,minecraft:dark_oak_wood)
B(-7,-4,-2,minecraft:dark_oak_planks)
B(-7,-3,-2,minecraft:dark_oak_door)
B(-7,-2,-2,minecraft:dark_oak_door[facing=north,half=upper,hinge=left,open=false,powered=false])
B(-7,-1,-2,minecraft:dark_oak_slab[type=double,waterlogged=false])
B(-7,0,-2,minecraft:dark_oak_door)
B(-7,1,-2,minecraft:dark_oak_door[facing=north,half=upper,hinge=left,open=false,powered=false])
B(-7,2,-2,minecraft:cyan_terracotta)
B(-7,6,-2,minecraft:spruce_fence[east=false,north=true,south=false,waterlogged=false,west=true])
B(-7,7,-2,minecraft:spruce_wood)
B(-7,-8,-1,minecraft:dark_oak_wood)
B(-7,-4,-1,minecraft:dark_oak_planks)
B(-7,-3,-1,minecraft:cyan_terracotta)
B(-7,-2,-1,minecraft:cyan_terracotta)
B(-7,-1,-1,minecraft:dark_oak_slab[type=double,waterlogged=false])
B(-7,2,-1,minecraft:cyan_terracotta)
B(-6,-2,-7,minecraft:oak_button)
B(-6,-4,-6,minecraft:dark_oak_planks)
B(-6,-3,-6,minecraft:dark_oak_planks)
B(-6,-2,-6,minecraft:dark_oak_planks)
B(-6,-1,-6,minecraft:cyan_terracotta)
B(-6,0,-6,minecraft:cyan_terracotta)
B(-6,1,-6,minecraft:dark_oak_stairs[facing=east,half=bottom,shape=straight,waterlogged=false])
B(-6,-6,-5,minecraft:dark_oak_wood)
B(-6,-5,-5,minecraft:dark_oak_wood)
B(-6,-4,-5,minecraft:dark_oak_planks)
B(-6,-3,-5,minecraft:tripwire_hook[attached=false,facing=south,powered=false])
B(-6,-2,-5,minecraft:dark_oak_slab)
B(-6,-1,-5,minecraft:dark_oak_slab[type=double,waterlogged=false])
B(-6,0,-5,minecraft:furnace[facing=south,lit=false])
B(-6,1,-5,minecraft:oak_pressure_plate)
B(-6,2,-5,minecraft:cyan_terracotta)
B(-6,3,-5,minecraft:cyan_terracotta)
B(-6,4,-5,minecraft:dark_oak_slab)
B(-6,-6,-4,minecraft:dark_oak_wood)
B(-6,-4,-4,minecraft:dark_oak_planks)
B(-6,-3,-4,minecraft:tripwire)
B(-6,-1,-4,minecraft:dark_oak_slab[type=top,waterlogged=false])
B(-6,2,-4,minecraft:cyan_terracotta)
B(-6,-7,-3,minecraft:dark_oak_wood)
B(-6,-4,-3,minecraft:dark_oak_planks)
B(-6,-1,-3,minecraft:dark_oak_slab[type=top,waterlogged=false])
B(-6,0,-3,minecraft:cauldron[level=3])
B(-6,2,-3,minecraft:cyan_terracotta)
B(-6,6,-3,minecraft:black_wool)
B(-6,7,-3,minecraft:black_wool)
B(-6,-7,-2,minecraft:dark_oak_wood)
B(-6,-4,-2,minecraft:dark_oak_planks)
B(-6,-3,-2,minecraft:green_carpet)
B(-6,-1,-2,minecraft:dark_oak_slab[type=top,waterlogged=false])
B(-6,0,-2,minecraft:cyan_terracotta)
B(-6,1,-2,minecraft:cyan_terracotta)
B(-6,2,-2,minecraft:oak_trapdoor[facing=west,half=top,open=false,powered=false,waterlogged=false])
B(-6,7,-2,minecraft:spruce_fence[east=false,north=true,south=false,waterlogged=false,west=true])
B(-6,8,-2,minecraft:spruce_wood)
B(-6,-8,-1,minecraft:dark_oak_wood)
B(-6,-6,-1,minecraft:iron_bars)
B(-6,-5,-1,minecraft:iron_bars)
B(-6,-4,-1,minecraft:iron_bars[east=false,north=true,south=false,waterlogged=false,west=true])
B(-6,-3,-1,minecraft:iron_bars[east=false,north=false,south=false,waterlogged=false,west=true])
B(-6,-2,-1,minecraft:iron_bars[east=false,north=false,south=false,waterlogged=false,west=true])
B(-6,-1,-1,minecraft:iron_bars[east=false,north=false,south=false,waterlogged=false,west=true])
B(-6,0,-1,minecraft:iron_bars[east=true,north=true,south=false,waterlogged=false,west=false])
B(-6,1,-1,minecraft:iron_bars[east=true,north=true,south=false,waterlogged=false,west=false])
B(-6,2,-1,minecraft:dark_oak_stairs[facing=south,half=top,shape=straight,waterlogged=false])
B(-6,3,-1,minecraft:iron_bars)
B(-6,4,-1,minecraft:dark_oak_stairs[facing=south,half=bottom,shape=straight,waterlogged=false])
B(-5,-3,-7,minecraft:oak_trapdoor[facing=south,half=top,open=false,powered=false,waterlogged=false])
B(-5,-2,-7,minecraft:oak_button)
B(-5,-4,-6,minecraft:dark_oak_planks)
B(-5,-3,-6,minecraft:dispenser)
B(-5,-2,-6,minecraft:dark_oak_slab[type=double,waterlogged=false])
B(-5,-1,-6,minecraft:cyan_terracotta)
B(-5,0,-6,minecraft:dark_oak_stairs[facing=west,half=bottom,shape=straight,waterlogged=false])
B(-5,-5,-5,minecraft:dark_oak_wood)
B(-5,-4,-5,minecraft:dark_oak_planks)
B(-5,-3,-5,minecraft:black_concrete)
B(-5,-2,-5,minecraft:oak_button[face=floor,facing=east,powered=false])
B(-5,-1,-5,minecraft:dark_oak_slab[type=double,waterlogged=false])
B(-5,0,-5,minecraft:cyan_terracotta)
B(-5,1,-5,minecraft:cyan_terracotta)
B(-5,2,-5,minecraft:cyan_terracotta)
B(-5,3,-5,minecraft:cyan_terracotta)
B(-5,4,-5,minecraft:dark_oak_slab)
B(-5,-6,-4,minecraft:dark_oak_wood)
B(-5,-4,-4,minecraft:dark_oak_planks)
B(-5,-3,-4,minecraft:dark_oak_stairs)
B(-5,-1,-4,minecraft:dark_oak_slab[type=top,waterlogged=false])
B(-5,0,-4,minecraft:crafting_table)
B(-5,1,-4,minecraft:cyan_terracotta)
B(-5,2,-4,minecraft:cyan_terracotta)
B(-5,6,-4,minecraft:black_wool)
B(-5,-7,-3,minecraft:dark_oak_wood)
B(-5,-4,-3,minecraft:dark_oak_planks)
B(-5,-1,-3,minecraft:dark_oak_slab[type=top,waterlogged=false])
B(-5,0,-3,minecraft:cyan_terracotta)
B(-5,1,-3,minecraft:cyan_terracotta)
B(-5,2,-3,minecraft:cyan_terracotta)
B(-5,7,-3,minecraft:black_wool)
B(-5,-7,-2,minecraft:dark_oak_wood)
B(-5,-4,-2,minecraft:dark_oak_planks)
B(-5,-3,-2,minecraft:green_carpet)
B(-5,-1,-2,minecraft:dark_oak_slab[type=top,waterlogged=false])
B(-5,0,-2,minecraft:cyan_terracotta)
B(-5,1,-2,minecraft:cyan_terracotta)
B(-5,2,-2,minecraft:cyan_terracotta)
B(-5,8,-2,minecraft:black_wool)
B(-5,-7,-1,minecraft:dark_oak_wood)
B(-5,-6,-1,minecraft:ladder[facing=west,waterlogged=false])
B(-5,-5,-1,minecraft:ladder[facing=west,waterlogged=false])
B(-5,-4,-1,minecraft:oak_trapdoor[facing=east,half=top,open=false,powered=false,waterlogged=false])
B(-5,-1,-1,minecraft:dark_oak_slab[type=top,waterlogged=false])
B(-5,0,-1,minecraft:cyan_terracotta)
B(-5,1,-1,minecraft:cyan_terracotta)
B(-5,2,-1,minecraft:cyan_terracotta)
B(-5,8,-1,minecraft:spruce_fence[east=false,north=true,south=false,waterlogged=false,west=false])
B(-5,9,-1,minecraft:spruce_wood)
B(-5,17,-1,minecraft:black_wool)
B(-4,-2,-7,minecraft:oak_button)
B(-4,-3,-6,minecraft:dark_oak_planks)
B(-4,-2,-6,minecraft:dark_oak_slab[type=double,waterlogged=false])
B(-4,-1,-6,minecraft:dark_oak_stairs[facing=west,half=bottom,shape=straight,waterlogged=false])
B(-4,-5,-5,minecraft:dark_oak_wood)
B(-4,-4,-5,minecraft:dark_oak_planks)
B(-4,-3,-5,minecraft:stone_button[face=wall,facing=east,powered=false])
B(-4,-2,-5,minecraft:dark_oak_slab)
B(-4,-1,-5,minecraft:cyan_terracotta)
B(-4,0,-5,minecraft:cyan_terracotta)
B(-4,1,-5,minecraft:cyan_terracotta)
B(-4,2,-5,minecraft:cyan_terracotta)
B(-4,3,-5,minecraft:cyan_terracotta)
B(-4,4,-5,minecraft:dark_oak_slab)
B(-4,-6,-4,minecraft:dark_oak_wood)
B(-4,-5,-4,minecraft:spruce_slab[type=double,waterlogged=false])
B(-4,-4,-4,minecraft:dark_oak_planks)
B(-4,-1,-4,minecraft:dark_oak_slab[type=top,waterlogged=false])
B(-4,0,-4,minecraft:tripwire_hook[attached=false,facing=south,powered=false])
B(-4,2,-4,minecraft:cyan_terracotta)
B(-4,7,-4,minecraft:black_wool)
B(-4,-7,-3,minecraft:dark_oak_wood)
B(-4,-6,-3,minecraft:spruce_slab[type=double,waterlogged=false])
B(-4,-5,-3,minecraft:spruce_slab[type=double,waterlogged=false])
B(-4,-4,-3,minecraft:dark_oak_planks)
B(-4,-1,-3,minecraft:dark_oak_slab[type=top,waterlogged=false])
B(-4,0,-3,minecraft:tripwire)
B(-4,2,-3,minecraft:cyan_terracotta)
B(-4,8,-3,minecraft:black_wool)
B(-4,16,-3,minecraft:black_wool)
B(-4,17,-3,minecraft:black_wool)
B(-4,-7,-2,minecraft:dark_oak_wood)
B(-4,-6,-2,minecraft:spruce_slab[type=double,waterlogged=false])
B(-4,-5,-2,minecraft:spruce_slab[type=double,waterlogged=false])
B(-4,-4,-2,minecraft:dark_oak_planks)
B(-4,-3,-2,minecraft:green_carpet)
B(-4,-1,-2,minecraft:dark_oak_slab[type=top,waterlogged=false])
B(-4,2,-2,minecraft:cyan_terracotta)
B(-4,9,-2,minecraft:black_wool)
B(-4,15,-2,minecraft:black_wool)
B(-4,16,-2,minecraft:black_wool)
B(-4,17,-2,minecraft:black_wool)
B(-4,18,-2,minecraft:black_wool)
B(-4,-7,-1,minecraft:dark_oak_wood)
B(-4,-6,-1,minecraft:spruce_slab[type=double,waterlogged=false])
B(-4,-5,-1,minecraft:spruce_slab[type=double,waterlogged=false])
B(-4,-4,-1,minecraft:dark_oak_planks)
B(-4,-3,-1,minecraft:green_carpet)
B(-4,-1,-1,minecraft:dark_oak_slab[type=top,waterlogged=false])
B(-4,0,-1,minecraft:green_carpet)
B(-4,2,-1,minecraft:cyan_terracotta)
B(-4,3,-1,minecraft:spruce_slab)
B(-4,9,-1,minecraft:spruce_fence[east=false,north=true,south=false,waterlogged=false,west=true])
B(-4,10,-1,minecraft:spruce_wood)
B(-4,15,-1,minecraft:black_wool)
B(-4,16,-1,minecraft:black_wool)
B(-4,18,-1,minecraft:black_wool)
B(-4,19,-1,minecraft:black_wool)
B(-3,-2,-6,minecraft:oak_button)
B(-3,0,-6,minecraft:oak_trapdoor[facing=south,half=top,open=false,powered=false,waterlogged=false])
B(-3,2,-6,minecraft:dark_oak_stairs[facing=south,half=top,shape=straight,waterlogged=false])
B(-3,3,-6,minecraft:spruce_fence[east=true,north=false,south=true,waterlogged=false,west=false])
B(-3,4,-6,minecraft:spruce_fence[east=true,north=false,south=true,waterlogged=false,west=false])
B(-3,-5,-5,minecraft:dark_oak_wood)
B(-3,-4,-5,minecraft:dark_oak_planks)
B(-3,-3,-5,minecraft:dark_oak_planks)
B(-3,-2,-5,minecraft:dark_oak_planks)
B(-3,-1,-5,minecraft:cyan_terracotta)
B(-3,0,-5,minecraft:dispenser)
B(-3,1,-5,minecraft:cyan_terracotta)
B(-3,2,-5,minecraft:cyan_terracotta)
B(-3,3,-5,minecraft:cyan_terracotta)
B(-3,4,-5,minecraft:spruce_fence[east=true,north=true,south=false,waterlogged=false,west=false])
B(-3,5,-5,minecraft:spruce_fence[east=true,north=false,south=false,waterlogged=false,west=false])
B(-3,6,-5,minecraft:spruce_fence[east=true,north=false,south=true,waterlogged=false,west=false])
B(-3,-6,-4,minecraft:dark_oak_wood)
B(-3,-4,-4,minecraft:dark_oak_planks)
B(-3,-3,-4,minecraft:tripwire_hook[attached=false,facing=south,powered=false])
B(-3,-2,-4,minecraft:dark_oak_slab)
B(-3,-1,-4,minecraft:dark_oak_slab[type=top,waterlogged=false])
B(-3,0,-4,minecraft:black_concrete)
B(-3,1,-4,minecraft:oak_button[face=floor,facing=east,powered=false])
B(-3,2,-4,minecraft:cyan_terracotta)
B(-3,3,-4,minecraft:spruce_slab)
B(-3,6,-4,minecraft:spruce_fence[east=true,north=true,south=false,waterlogged=false,west=false])
B(-3,7,-4,minecraft:black_wool)
B(-3,-6,-3,minecraft:dark_oak_wood)
B(-3,-5,-3,minecraft:dark_oak_wood)
B(-3,-4,-3,minecraft:dark_oak_planks)
B(-3,-3,-3,minecraft:tripwire)
B(-3,-1,-3,minecraft:dark_oak_slab[type=top,waterlogged=false])
B(-3,0,-3,minecraft:spruce_stairs)
B(-3,2,-3,minecraft:cyan_terracotta)
B(-3,3,-3,minecraft:spruce_slab)
B(-3,8,-3,minecraft:black_wool)
B(-3,9,-3,minecraft:black_wool)
B(-3,15,-3,minecraft:black_wool)
B(-3,18,-3,minecraft:black_wool)
B(-3,19,-3,minecraft:black_wool)
B(-3,-7,-2,minecraft:dark_oak_wood)
B(-3,-6,-2,minecraft:purple_bed)
B(-3,-5,-2,minecraft:purple_bed)
B(-3,-4,-2,minecraft:dark_oak_planks)
B(-3,-3,-2,minecraft:brown_carpet)
B(-3,-1,-2,minecraft:dark_oak_slab[type=top,waterlogged=false])
B(-3,0,-2,minecraft:green_carpet)
B(-3,2,-2,minecraft:cyan_terracotta)
B(-3,3,-2,minecraft:spruce_slab)
B(-3,10,-2,minecraft:black_wool)
B(-3,14,-2,minecraft:black_wool)
B(-3,19,-2,minecraft:black_wool)
B(-3,20,-2,minecraft:black_wool)
B(-3,-7,-1,minecraft:dark_oak_wood)
B(-3,-6,-1,minecraft:magenta_bed)
B(-3,-5,-1,minecraft:magenta_bed)
B(-3,-4,-1,minecraft:dark_oak_planks)
B(-3,-1,-1,minecraft:dark_oak_slab[type=top,waterlogged=false])
B(-3,2,-1,minecraft:cyan_terracotta)
B(-3,3,-1,minecraft:spruce_slab)
B(-3,10,-1,minecraft:spruce_fence[east=false,north=true,south=false,waterlogged=false,west=true])
B(-3,11,-1,minecraft:spruce_wood)
B(-3,12,-1,minecraft:spruce_fence[east=true,north=false,south=false,waterlogged=false,west=false])
B(-3,13,-1,minecraft:spruce_fence[east=true,north=false,south=false,waterlogged=false,west=false])
B(-3,14,-1,minecraft:spruce_fence[east=false,north=true,south=false,waterlogged=false,west=false])
B(-3,17,-1,minecraft:dark_oak_slab[type=top,waterlogged=false])
B(-3,18,-1,minecraft:spruce_fence[east=true,north=false,south=false,waterlogged=false,west=true])
B(-3,20,-1,minecraft:spruce_fence[east=false,north=true,south=false,waterlogged=false,west=false])
B(-3,21,-1,minecraft:spruce_log[axis=z])
B(-2,-3,-6,minecraft:oak_trapdoor[facing=south,half=top,open=false,powered=false,waterlogged=false])
B(-2,-2,-6,minecraft:oak_button)
B(-2,2,-6,minecraft:dark_oak_slab[type=top,waterlogged=false])
B(-2,3,-6,minecraft:spruce_fence[east=true,north=false,south=true,waterlogged=false,west=true])
B(-2,4,-6,minecraft:spruce_fence[east=true,north=false,south=true,waterlogged=false,west=true])
B(-2,-5,-5,minecraft:dark_oak_wood)
B(-2,-4,-5,minecraft:dark_oak_planks)
B(-2,-3,-5,minecraft:dispenser)
B(-2,-2,-5,minecraft:dark_oak_planks)
B(-2,-1,-5,minecraft:dark_oak_planks)
B(-2,0,-5,minecraft:cyan_terracotta)
B(-2,1,-5,minecraft:cyan_terracotta)
B(-2,2,-5,minecraft:cyan_terracotta)
B(-2,3,-5,minecraft:cyan_terracotta)
B(-2,4,-5,minecraft:spruce_fence[east=true,north=true,south=true,waterlogged=false,west=true])
B(-2,5,-5,minecraft:spruce_fence[east=true,north=false,south=false,waterlogged=false,west=true])
B(-2,6,-5,minecraft:spruce_fence[east=true,north=false,south=true,waterlogged=false,west=true])
B(-2,-6,-4,minecraft:dark_oak_wood)
B(-2,-5,-4,minecraft:spruce_slab[type=double,waterlogged=false])
B(-2,-4,-4,minecraft:dark_oak_planks)
B(-2,-3,-4,minecraft:black_concrete)
B(-2,-2,-4,minecraft:oak_button[face=floor,facing=east,powered=false])
B(-2,-1,-4,minecraft:dark_oak_slab[type=top,waterlogged=false])
B(-2,0,-4,minecraft:cyan_terracotta)
B(-2,1,-4,minecraft:cyan_terracotta)
B(-2,2,-4,minecraft:cyan_terracotta)
B(-2,3,-4,minecraft:cyan_terracotta)
B(-2,4,-4,minecraft:cyan_terracotta)
B(-2,5,-4,minecraft:dark_oak_stairs[facing=east,half=bottom,shape=straight,waterlogged=false])
B(-2,6,-4,minecraft:spruce_fence[east=true,north=true,south=false,waterlogged=false,west=true])
B(-2,7,-4,minecraft:spruce_fence[east=true,north=false,south=false,waterlogged=false,west=true])
B(-2,8,-4,minecraft:black_wool)
B(-2,15,-4,minecraft:black_wool)
B(-2,19,-4,minecraft:black_wool)
B(-2,-6,-3,minecraft:dark_oak_wood)
B(-2,-5,-3,minecraft:light_blue_bed)
B(-2,-4,-3,minecraft:dark_oak_planks)
B(-2,-3,-3,minecraft:dark_oak_stairs)
B(-2,-1,-3,minecraft:dark_oak_slab[type=top,waterlogged=false])
B(-2,0,-3,minecraft:cyan_terracotta)
B(-2,1,-3,minecraft:cyan_terracotta)
B(-2,2,-3,minecraft:cyan_terracotta)
B(-2,3,-3,minecraft:cyan_terracotta)
B(-2,8,-3,minecraft:spruce_fence[east=true,north=true,south=false,waterlogged=false,west=true])
B(-2,9,-3,minecraft:black_wool)
B(-2,10,-3,minecraft:black_wool)
B(-2,14,-3,minecraft:black_wool)
B(-2,20,-3,minecraft:black_wool)
B(-2,21,-3,minecraft:spruce_log[axis=z])
B(-2,-7,-2,minecraft:dark_oak_wood)
B(-2,-4,-2,minecraft:dark_oak_planks)
B(-2,-1,-2,minecraft:dark_oak_slab[type=top,waterlogged=false])
B(-2,0,-2,minecraft:cyan_terracotta)
B(-2,1,-2,minecraft:cyan_terracotta)
B(-2,2,-2,minecraft:cyan_terracotta)
B(-2,3,-2,minecraft:cyan_terracotta)
B(-2,4,-2,minecraft:dark_oak_fence[east=false,north=false,south=true,waterlogged=false,west=false])
B(-2,10,-2,minecraft:spruce_fence[east=true,north=true,south=false,waterlogged=false,west=true])
B(-2,11,-2,minecraft:black_wool)
B(-2,20,-2,minecraft:spruce_fence[east=false,north=true,south=false,waterlogged=false,west=true])
B(-2,21,-2,minecraft:spruce_log[axis=z])
B(-2,-7,-1,minecraft:dark_oak_wood)
B(-2,-6,-1,minecraft:brown_carpet)
B(-2,-4,-1,minecraft:dark_oak_planks)
B(-2,-1,-1,minecraft:dark_oak_slab[type=top,waterlogged=false])
B(-2,0,-1,minecraft:dark_oak_door)
B(-2,1,-1,minecraft:dark_oak_door[facing=north,half=upper,hinge=left,open=false,powered=false])
B(-2,2,-1,minecraft:cyan_terracotta)
B(-2,3,-1,minecraft:cyan_terracotta)
B(-2,4,-1,minecraft:dark_oak_fence[east=false,north=true,south=false,waterlogged=false,west=false])
B(-2,11,-1,minecraft:spruce_fence[east=true,north=true,south=false,waterlogged=false,west=true])
B(-2,12,-1,minecraft:spruce_wood)
B(-2,13,-1,minecraft:spruce_fence[east=true,north=false,south=false,waterlogged=false,west=true])
B(-2,17,-1,minecraft:dark_oak_slab[type=top,waterlogged=false])
B(-2,18,-1,minecraft:spruce_fence[east=false,north=false,south=false,waterlogged=false,west=true])
B(-1,-2,-6,minecraft:oak_button)
B(-1,2,-6,minecraft:dark_oak_stairs[facing=south,half=top,shape=straight,waterlogged=false])
B(-1,3,-6,minecraft:spruce_fence[east=false,north=false,south=true,waterlogged=false,west=true])
B(-1,4,-6,minecraft:spruce_fence[east=false,north=false,south=true,waterlogged=false,west=true])
B(-1,-5,-5,minecraft:dark_oak_wood)
B(-1,-4,-5,minecraft:dark_oak_planks)
B(-1,-3,-5,minecraft:dark_oak_planks)
B(-1,-2,-5,minecraft:dark_oak_planks)
B(-1,-1,-5,minecraft:dark_oak_planks)
B(-1,0,-5,minecraft:dark_oak_planks)
B(-1,1,-5,minecraft:cyan_terracotta)
B(-1,2,-5,minecraft:cyan_terracotta)
B(-1,3,-5,minecraft:cyan_terracotta)
B(-1,4,-5,minecraft:spruce_fence[east=false,north=true,south=true,waterlogged=false,west=true])
B(-1,5,-5,minecraft:spruce_fence[east=false,north=false,south=true,waterlogged=false,west=true])
B(-1,6,-5,minecraft:spruce_fence[east=false,north=false,south=true,waterlogged=false,west=true])
B(-1,13,-5,minecraft:black_wool)
B(-1,-6,-4,minecraft:dark_oak_wood)
B(-1,-5,-4,minecraft:spruce_slab[type=double,waterlogged=false])
B(-1,-4,-4,minecraft:dark_oak_planks)
B(-1,-3,-4,minecraft:cyan_terracotta)
B(-1,-2,-4,minecraft:cyan_terracotta)
B(-1,-1,-4,minecraft:dark_oak_slab[type=double,waterlogged=false])
B(-1,0,-4,minecraft:spruce_stairs[facing=west,half=bottom,shape=straight,waterlogged=false])
B(-1,3,-4,minecraft:cyan_terracotta)
B(-1,4,-4,minecraft:cyan_terracotta)
B(-1,5,-4,minecraft:cyan_terracotta)
B(-1,6,-4,minecraft:spruce_fence[east=false,north=true,south=false,waterlogged=false,west=true])
B(-1,7,-4,minecraft:spruce_fence[east=false,north=false,south=false,waterlogged=false,west=true])
B(-1,8,-4,minecraft:black_wool)
B(-1,9,-4,minecraft:black_wool)
B(-1,13,-4,minecraft:black_wool)
B(-1,14,-4,minecraft:black_wool)
B(-1,20,-4,minecraft:black_wool)
B(-1,21,-4,minecraft:black_wool)
B(-1,-6,-3,minecraft:dark_oak_wood)
B(-1,-5,-3,minecraft:blue_bed)
B(-1,-4,-3,minecraft:dark_oak_planks)
B(-1,-3,-3,minecraft:cyan_terracotta)
B(-1,-2,-3,minecraft:cyan_terracotta)
B(-1,-1,-3,minecraft:dark_oak_slab[type=double,waterlogged=false])
B(-1,3,-3,minecraft:cyan_terracotta)
B(-1,8,-3,minecraft:spruce_fence[east=false,north=true,south=false,waterlogged=false,west=true])
B(-1,9,-3,minecraft:spruce_fence[east=false,north=true,south=false,waterlogged=false,west=true])
B(-1,10,-3,minecraft:black_wool)
B(-1,11,-3,minecraft:black_wool)
B(-1,20,-3,minecraft:spruce_fence[east=false,north=true,south=false,waterlogged=false,west=true])
B(-1,-7,-2,minecraft:dark_oak_wood)
B(-1,-4,-2,minecraft:dark_oak_planks)
B(-1,-3,-2,minecraft:cyan_terracotta)
B(-1,-2,-2,minecraft:cyan_terracotta)
B(-1,-1,-2,minecraft:dark_oak_slab[type=double,waterlogged=false])
B(-1,0,-2,minecraft:spruce_stairs[facing=west,half=bottom,shape=straight,waterlogged=false])
B(-1,2,-2,minecraft:dark_oak_stairs[facing=west,half=top,shape=straight,waterlogged=false])
B(-1,3,-2,minecraft:cyan_terracotta)
B(-1,10,-2,minecraft:spruce_fence[east=false,north=true,south=false,waterlogged=false,west=true])
B(-1,11,-2,minecraft:spruce_fence[east=false,north=true,south=true,waterlogged=false,west=true])
B(-1,12,-2,minecraft:black_wool)
B(-1,-7,-1,minecraft:dark_oak_wood)
B(-1,-6,-1,minecraft:brown_carpet)
B(-1,-4,-1,minecraft:dark_oak_planks)
B(-1,-3,-1,minecraft:dark_oak_door[facing=west,half=lower,hinge=left,open=false,powered=false])
B(-1,-2,-1,minecraft:dark_oak_door[facing=west,half=upper,hinge=left,open=false,powered=false])
B(-1,-1,-1,minecraft:dark_oak_slab[type=double,waterlogged=false])
B(-1,0,-1,minecraft:red_carpet)
B(-1,3,-1,minecraft:black_stained_glass)
B(-1,4,-1,minecraft:oak_trapdoor[facing=south,half=bottom,open=false,powered=false,waterlogged=false])
B(-1,11,-1,minecraft:spruce_fence[east=false,north=true,south=false,waterlogged=false,west=true])
B(-1,12,-1,minecraft:spruce_fence[east=false,north=true,south=false,waterlogged=false,west=true])
B(-1,13,-1,minecraft:spruce_wood)
B(-1,27,-1,minecraft:black_wool)
RB(-1,-6,-2,minecraft:chest[facing=south,type=single,waterlogged=false],../NBT/StructureLoot/JunkChest_1.nbt,15,minecraft:chest[facing=south,type=single,waterlogged=false],../NBT/StructureLoot/JunkChest_2.nbt,15,minecraft:chest[facing=south,type=single,waterlogged=false],../NBT/StructureLoot/JunkChest_3.nbt,15,minecraft:chest[facing=south,type=single,waterlogged=false],../NBT/StructureLoot/JunkChest_4.nbt,15,minecraft:chest[facing=south,type=single,waterlogged=false],../NBT/StructureLoot/JunkChest_5.nbt,15,minecraft:chest[facing=south,type=single,waterlogged=false],../NBT/StructureLoot/Common1.nbt,15,minecraft:chest[facing=south,type=single,waterlogged=false],../NBT/StructureLoot/Common2.nbt,15,minecraft:chest[facing=south,type=single,waterlogged=false],../NBT/StructureLoot/Common3.nbt,15,minecraft:chest[facing=south,type=single,waterlogged=false],../NBT/StructureLoot/Common4.nbt,15,minecraft:chest[facing=south,type=single,waterlogged=false],../NBT/StructureLoot/Common5.nbt,15,minecraft:chest[facing=south,type=single,waterlogged=false],../NBT/StructureLoot/Common6.nbt,15,minecraft:chest[facing=south,type=single,waterlogged=false],../NBT/StructureLoot/Common7.nbt,15,minecraft:chest[facing=south,type=single,waterlogged=false],../NBT/StructureLoot/Common8.nbt,15,minecraft:chest[facing=south,type=single,waterlogged=false],../NBT/StructureLoot/Common9.nbt,15,minecraft:chest[facing=south,type=single,waterlogged=false],../NBT/StructureLoot/Common10.nbt,15,minecraft:chest[facing=south,type=single,waterlogged=false],../NBT/StructureLoot/Common11.nbt,15,minecraft:chest[facing=south,type=single,waterlogged=false],../NBT/StructureLoot/Common12.nbt,15,minecraft:chest[facing=south,type=single,waterlogged=false],../NBT/StructureLoot/Common13.nbt,15,minecraft:chest[facing=south,type=single,waterlogged=false],../NBT/StructureLoot/Common14.nbt,15,minecraft:chest[facing=south,type=single,waterlogged=false],../NBT/StructureLoot/Common15.nbt,100)

#######################################################################
# +-----------------------------------------------------------------+ #
# |                            BO3 checks                           | #
# +-----------------------------------------------------------------+ #
#######################################################################


#######################################################################
# +-----------------------------------------------------------------+ #
# |                             Branches                            | #
# +-----------------------------------------------------------------+ #
#######################################################################

Branch(0,0,8,WestPortShipPillager_7x4,NORTH,100.0)
Branch(-8,0,0,WestPortShipPillager_6x3,NORTH,100.0)
Branch(8,0,0,WestPortShipPillager_8x3,NORTH,100.0)

#######################################################################
# +-----------------------------------------------------------------+ #
# |                             Entities                            | #
# +-----------------------------------------------------------------+ #
#######################################################################

