#######################################################################
# +-----------------------------------------------------------------+ #
# |                            BO3 object                           | #
# +-----------------------------------------------------------------+ #
#######################################################################

# This is the config file of a custom object.
# If you add this object correctly to your BiomeConfigs, it will spawn in the world.

# This is the creator of this BO3 object
Author: BO3 BulkEdit (by LanToaster)

# A short description of this BO3 object
Description: Bo3 spikes created by NLBlackEagle

# The BO3 version, don't change this! It can be used by external applications to do a version check.
Version: 3

# The settings mode, WriteAll, WriteWithoutComments or WriteDisable. See WorldConfig.
SettingsMode: WriteDisable


#######################################################################
# +-----------------------------------------------------------------+ #
# |                          Main settings                          | #
# +-----------------------------------------------------------------+ #
#######################################################################

# This needs to be set to true to spawn the object in the Tree and Sapling resources.
Tree: false

# The frequency of the BO3 from 1 to 200. Tries this many times to spawn this BO3 when using the CustomObject(...) resource.

Frequency: 100

# The rarity of the BO3 from 0 to 100. Each spawn attempt has rarity% chance to succeed when using the CustomObject(...) resource.

Rarity: 100

# If you set this to true, the BO3 will be placed with a random rotation.
RotateRandomly: true

# The spawn height of the BO3 - randomY, highestBlock or highestSolidBlock.
SpawnHeight: randomY

# The height limits for the BO3.
MinHeight: 0

MaxHeight: 256

# Objects can have other objects attacthed to it: branches. Branches can also
# have branches attached to it, which can also have branches, etc. This is the
# maximum branch depth for this objects.
MaxBranchDepth: 10

# When spawned with the UseWorld keyword, this BO3 should NOT spawn in the following biomes.
# If you writer.write the BO3 name directly in the BiomeConfigs, this will be ignored.
ExcludedBiomes: All


#######################################################################
# +-----------------------------------------------------------------+ #
# |                      Source block settings                      | #
# +-----------------------------------------------------------------+ #
#######################################################################

# The block(s) the BO3 should spawn in.
SourceBlocks: AIR

# The maximum percentage of the BO3 that can be outside the SourceBlock.
# The BO3 won't be placed on a location with more blocks outside the SourceBlock than this percentage.
MaxPercentageOutsideSourceBlock: 100

# What to do when a block is about to be placed outside the SourceBlock? (dontPlace, placeAnyway)
OutsideSourceBlock: placeAnyway


#######################################################################
# +-----------------------------------------------------------------+ #
# |                              Blocks                             | #
# +-----------------------------------------------------------------+ #
#######################################################################

# All the blocks used in the BO3 are listed here. Possible blocks:
# Block(x,y,z,id[.data][,nbtfile.nbt)
# RandomBlock(x,y,z,id[:data][,nbtfile.nbt],chance[,id[:data][,nbtfile.nbt],chance[,...]])
# So RandomBlock(0,0,0,CHEST,chest.nbt,50,CHEST,anotherchest.nbt,100) will spawn a chest at
# the BO3 origin, and give it a 50% chance to have the contents of chest.nbt, or, if that
# fails, a 100% percent chance to have the contents of anotherchest.nbt.
Block(0,-1,-3,STAINED_GLASS:3)
Block(1,-1,-3,STAINED_GLASS:15)
Block(2,-1,-3,STAINED_GLASS:15)
Block(-1,-1,-2,STAINED_GLASS:3)
Block(0,-1,-2,STAINED_GLASS:10)
Block(1,-1,-2,STAINED_GLASS:3)
Block(2,-1,-2,STAINED_GLASS:15)
Block(3,-1,-2,STAINED_GLASS:15)
Block(4,-1,-2,STAINED_GLASS:15)
Block(-2,-1,-1,STAINED_GLASS:15)
Block(-1,-1,-1,STAINED_GLASS:10)
Block(0,-1,-1,STAINED_GLASS:3)
Block(1,-1,-1,STAINED_GLASS:10)
Block(2,-1,-1,STAINED_GLASS:10)
Block(3,-1,-1,STAINED_GLASS:10)
Block(4,-1,-1,STAINED_GLASS:15)
Block(5,-1,-1,STAINED_GLASS:15)
Block(-3,-1,0,STAINED_GLASS:15)
Block(-2,-1,0,STAINED_GLASS:10)
Block(-1,-1,0,STAINED_GLASS:3)
Block(0,-1,0,STAINED_GLASS:10)
Block(1,-1,0,PURPLE_GLAZED_TERRACOTTA:3)
Block(2,-1,0,PURPLE_GLAZED_TERRACOTTA:3)
Block(3,-1,0,PURPLE_GLAZED_TERRACOTTA:3)
Block(4,-1,0,STAINED_GLASS:10)
Block(5,-1,0,STAINED_GLASS:10)
Block(6,-1,0,STAINED_GLASS:15)
Block(-3,-1,1,STAINED_GLASS:15)
Block(-2,-1,1,STAINED_GLASS:15)
Block(-1,-1,1,STAINED_GLASS:10)
Block(0,-1,1,PURPLE_GLAZED_TERRACOTTA:3)
Block(1,-1,1,PURPLE_GLAZED_TERRACOTTA:3)
Block(2,-1,1,PURPLE_GLAZED_TERRACOTTA:3)
Block(3,-1,1,PURPLE_GLAZED_TERRACOTTA:3)
Block(4,-1,1,PURPLE_GLAZED_TERRACOTTA:3)
Block(5,-1,1,STAINED_GLASS:10)
Block(6,-1,1,STAINED_GLASS:10)
Block(7,-1,1,STAINED_GLASS:3)
Block(-3,-1,2,STAINED_GLASS:15)
Block(-2,-1,2,STAINED_GLASS:15)
Block(-1,-1,2,STAINED_GLASS:10)
Block(0,-1,2,PURPLE_GLAZED_TERRACOTTA:3)
Block(1,-1,2,PURPLE_GLAZED_TERRACOTTA:3)
Block(2,-1,2,SEA_LANTERN:0)
Block(3,-1,2,SEA_LANTERN:0)
Block(4,-1,2,PURPLE_GLAZED_TERRACOTTA:3)
Block(5,-1,2,PURPLE_GLAZED_TERRACOTTA:3)
Block(6,-1,2,STAINED_GLASS:10)
Block(7,-1,2,STAINED_GLASS:15)
Block(-2,-1,3,STAINED_GLASS:15)
Block(-1,-1,3,STAINED_GLASS:10)
Block(0,-1,3,PURPLE_GLAZED_TERRACOTTA:3)
Block(1,-1,3,PURPLE_GLAZED_TERRACOTTA:3)
Block(2,-1,3,SEA_LANTERN:0)
Block(3,-1,3,SEA_LANTERN:0)
Block(4,-1,3,PURPLE_GLAZED_TERRACOTTA:3)
Block(5,-1,3,PURPLE_GLAZED_TERRACOTTA:3)
Block(6,-1,3,STAINED_GLASS:10)
Block(7,-1,3,STAINED_GLASS:15)
Block(-2,-1,4,STAINED_GLASS:15)
Block(-1,-1,4,STAINED_GLASS:15)
Block(0,-1,4,STAINED_GLASS:10)
Block(1,-1,4,PURPLE_GLAZED_TERRACOTTA:3)
Block(2,-1,4,PURPLE_GLAZED_TERRACOTTA:3)
Block(3,-1,4,PURPLE_GLAZED_TERRACOTTA:3)
Block(4,-1,4,PURPLE_GLAZED_TERRACOTTA:3)
Block(5,-1,4,STAINED_GLASS:10)
Block(6,-1,4,STAINED_GLASS:15)
Block(-1,-1,5,STAINED_GLASS:3)
Block(0,-1,5,STAINED_GLASS:10)
Block(1,-1,5,STAINED_GLASS:10)
Block(2,-1,5,PURPLE_GLAZED_TERRACOTTA:3)
Block(3,-1,5,PURPLE_GLAZED_TERRACOTTA:3)
Block(4,-1,5,STAINED_GLASS:10)
Block(5,-1,5,STAINED_GLASS:15)
Block(0,-1,6,STAINED_GLASS:15)
Block(1,-1,6,STAINED_GLASS:10)
Block(2,-1,6,STAINED_GLASS:10)
Block(3,-1,6,STAINED_GLASS:10)
Block(4,-1,6,STAINED_GLASS:15)
Block(1,-1,7,STAINED_GLASS:15)
Block(2,-1,7,STAINED_GLASS:15)
Block(3,-1,7,STAINED_GLASS:15)
Block(1,0,-4,STAINED_GLASS:15)
Block(0,0,-3,STAINED_GLASS:15)
Block(1,0,-3,STAINED_GLASS:10)
Block(2,0,-3,STAINED_GLASS:15)
Block(-1,0,-2,STAINED_GLASS:15)
Block(0,0,-2,STAINED_GLASS:10)
Block(1,0,-2,STAINED_GLASS:15)
Block(2,0,-2,STAINED_GLASS:10)
Block(3,0,-2,STAINED_GLASS:15)
Block(4,0,-2,STAINED_GLASS:15)
Block(-2,0,-1,STAINED_GLASS:15)
Block(-1,0,-1,STAINED_GLASS:15)
Block(0,0,-1,STAINED_GLASS:3)
Block(1,0,-1,STAINED_GLASS:10)
Block(2,0,-1,PURPLE_GLAZED_TERRACOTTA:3)
Block(3,0,-1,STAINED_GLASS:10)
Block(4,0,-1,STAINED_GLASS:15)
Block(5,0,-1,STAINED_GLASS:15)
Block(-3,0,0,STAINED_GLASS:15)
Block(-2,0,0,STAINED_GLASS:10)
Block(-1,0,0,STAINED_GLASS:3)
Block(1,0,0,PURPLE_GLAZED_TERRACOTTA:3)
Block(2,0,0,PURPLE_GLAZED_TERRACOTTA:3)
Block(3,0,0,PURPLE_GLAZED_TERRACOTTA:3)
Block(4,0,0,STAINED_GLASS:10)
Block(5,0,0,STAINED_GLASS:10)
Block(6,0,0,STAINED_GLASS:15)
Block(-4,0,1,STAINED_GLASS:15)
Block(-3,0,1,STAINED_GLASS:10)
Block(-2,0,1,STAINED_GLASS:15)
Block(-1,0,1,STAINED_GLASS:10)
Block(0,0,1,PURPLE_GLAZED_TERRACOTTA:3)
Block(1,0,1,PURPLE_GLAZED_TERRACOTTA:3)
Block(2,0,1,SEA_LANTERN:0)
Block(3,0,1,PURPLE_GLAZED_TERRACOTTA:3)
Block(4,0,1,PURPLE_GLAZED_TERRACOTTA:3)
Block(5,0,1,STAINED_GLASS:10)
Block(6,0,1,STAINED_GLASS:15)
Block(-3,0,2,STAINED_GLASS:15)
Block(-2,0,2,STAINED_GLASS:10)
Block(-1,0,2,PURPLE_GLAZED_TERRACOTTA:3)
Block(0,0,2,PURPLE_GLAZED_TERRACOTTA:3)
Block(1,0,2,SEA_LANTERN:0)
Block(2,0,2,SEA_LANTERN:0)
Block(3,0,2,SEA_LANTERN:0)
Block(4,0,2,PURPLE_GLAZED_TERRACOTTA:3)
Block(5,0,2,PURPLE_GLAZED_TERRACOTTA:3)
Block(6,0,2,STAINED_GLASS:10)
Block(7,0,2,STAINED_GLASS:15)
Block(-2,0,3,STAINED_GLASS:15)
Block(-1,0,3,STAINED_GLASS:10)
Block(0,0,3,PURPLE_GLAZED_TERRACOTTA:3)
Block(1,0,3,PURPLE_GLAZED_TERRACOTTA:3)
Block(2,0,3,SEA_LANTERN:0)
Block(3,0,3,PURPLE_GLAZED_TERRACOTTA:3)
Block(4,0,3,PURPLE_GLAZED_TERRACOTTA:3)
Block(5,0,3,STAINED_GLASS:10)
Block(6,0,3,STAINED_GLASS:15)
Block(-2,0,4,STAINED_GLASS:15)
Block(-1,0,4,STAINED_GLASS:15)
Block(0,0,4,STAINED_GLASS:10)
Block(1,0,4,PURPLE_GLAZED_TERRACOTTA:3)
Block(2,0,4,PURPLE_GLAZED_TERRACOTTA:3)
Block(3,0,4,PURPLE_GLAZED_TERRACOTTA:3)
Block(4,0,4,STAINED_GLASS:10)
Block(5,0,4,STAINED_GLASS:15)
Block(-1,0,5,STAINED_GLASS:15)
Block(0,0,5,STAINED_GLASS:10)
Block(1,0,5,STAINED_GLASS:10)
Block(2,0,5,PURPLE_GLAZED_TERRACOTTA:3)
Block(3,0,5,STAINED_GLASS:10)
Block(4,0,5,STAINED_GLASS:15)
Block(0,0,6,STAINED_GLASS:3)
Block(1,0,6,STAINED_GLASS:3)
Block(2,0,6,STAINED_GLASS:10)
Block(3,0,6,STAINED_GLASS:15)
Block(2,0,7,STAINED_GLASS:15)
Block(0,1,-4,STAINED_GLASS:15)
Block(1,1,-4,STAINED_GLASS:15)
Block(-1,1,-3,STAINED_GLASS:15)
Block(0,1,-3,STAINED_GLASS:10)
Block(1,1,-3,STAINED_GLASS:15)
Block(2,1,-3,STAINED_GLASS:15)
Block(3,1,-3,STAINED_GLASS:15)
Block(-2,1,-2,STAINED_GLASS:15)
Block(-1,1,-2,STAINED_GLASS:10)
Block(0,1,-2,STAINED_GLASS:15)
Block(1,1,-2,STAINED_GLASS:10)
Block(2,1,-2,STAINED_GLASS:10)
Block(3,1,-2,STAINED_GLASS:15)
Block(4,1,-2,STAINED_GLASS:15)
Block(-3,1,-1,STAINED_GLASS:15)
Block(-2,1,-1,STAINED_GLASS:10)
Block(-1,1,-1,STAINED_GLASS:3)
Block(0,1,-1,STAINED_GLASS:10)
Block(1,1,-1,PURPLE_GLAZED_TERRACOTTA:3)
Block(2,1,-1,PURPLE_GLAZED_TERRACOTTA:3)
Block(3,1,-1,STAINED_GLASS:10)
Block(4,1,-1,STAINED_GLASS:10)
Block(5,1,-1,STAINED_GLASS:15)
Block(-4,1,0,STAINED_GLASS:15)
Block(-3,1,0,STAINED_GLASS:10)
Block(-2,1,0,STAINED_GLASS:15)
Block(-1,1,0,STAINED_GLASS:10)
Block(0,1,0,PURPLE_GLAZED_TERRACOTTA:3)
Block(1,1,0,PURPLE_GLAZED_TERRACOTTA:3)
Block(2,1,0,PURPLE_GLAZED_TERRACOTTA:3)
Block(3,1,0,STAINED_GLASS:11)
Block(4,1,0,STAINED_GLASS:10)
Block(5,1,0,STAINED_GLASS:10)
Block(6,1,0,STAINED_GLASS:15)
Block(-4,1,1,STAINED_GLASS:15)
Block(-3,1,1,STAINED_GLASS:15)
Block(-2,1,1,STAINED_GLASS:10)
Block(-1,1,1,PURPLE_GLAZED_TERRACOTTA:3)
Block(0,1,1,PURPLE_GLAZED_TERRACOTTA:3)
Block(1,1,1,SEA_LANTERN:0)
Block(2,1,1,SEA_LANTERN:0)
Block(3,1,1,STAINED_GLASS:11)
Block(4,1,1,STAINED_GLASS:11)
Block(5,1,1,STAINED_GLASS:10)
Block(6,1,1,STAINED_GLASS:15)
Block(-3,1,2,STAINED_GLASS:15)
Block(-2,1,2,STAINED_GLASS:10)
Block(-1,1,2,PURPLE_GLAZED_TERRACOTTA:3)
Block(0,1,2,PURPLE_GLAZED_TERRACOTTA:3)
Block(1,1,2,SEA_LANTERN:0)
Block(2,1,2,SEA_LANTERN:0)
Block(3,1,2,PURPLE_GLAZED_TERRACOTTA:3)
Block(4,1,2,PURPLE_GLAZED_TERRACOTTA:3)
Block(5,1,2,STAINED_GLASS:10)
Block(6,1,2,STAINED_GLASS:15)
Block(-3,1,3,STAINED_GLASS:15)
Block(-2,1,3,STAINED_GLASS:15)
Block(-1,1,3,STAINED_GLASS:10)
Block(0,1,3,PURPLE_GLAZED_TERRACOTTA:3)
Block(1,1,3,PURPLE_GLAZED_TERRACOTTA:3)
Block(2,1,3,PURPLE_GLAZED_TERRACOTTA:3)
Block(3,1,3,PURPLE_GLAZED_TERRACOTTA:3)
Block(4,1,3,STAINED_GLASS:10)
Block(5,1,3,STAINED_GLASS:15)
Block(-2,1,4,STAINED_GLASS:15)
Block(-1,1,4,STAINED_GLASS:10)
Block(0,1,4,STAINED_GLASS:10)
Block(1,1,4,PURPLE_GLAZED_TERRACOTTA:3)
Block(2,1,4,PURPLE_GLAZED_TERRACOTTA:3)
Block(3,1,4,STAINED_GLASS:10)
Block(4,1,4,STAINED_GLASS:15)
Block(-1,1,5,STAINED_GLASS:15)
Block(0,1,5,STAINED_GLASS:10)
Block(1,1,5,STAINED_GLASS:10)
Block(2,1,5,STAINED_GLASS:10)
Block(3,1,5,STAINED_GLASS:15)
Block(0,1,6,STAINED_GLASS:3)
Block(1,1,6,STAINED_GLASS:3)
Block(2,1,6,STAINED_GLASS:3)
Block(0,2,-5,STAINED_GLASS:15)
Block(-1,2,-4,STAINED_GLASS:15)
Block(1,2,-4,STAINED_GLASS:15)
Block(-2,2,-3,STAINED_GLASS:15)
Block(0,2,-3,STAINED_GLASS:15)
Block(1,2,-3,STAINED_GLASS:10)
Block(2,2,-3,STAINED_GLASS:15)
Block(-3,2,-2,STAINED_GLASS:15)
Block(-1,2,-2,STAINED_GLASS:15)
Block(0,2,-2,STAINED_GLASS:10)
Block(1,2,-2,PURPLE_GLAZED_TERRACOTTA:3)
Block(2,2,-2,STAINED_GLASS:10)
Block(3,2,-2,STAINED_GLASS:15)
Block(4,2,-2,STAINED_GLASS:15)
Block(-4,2,-1,STAINED_GLASS:15)
Block(-2,2,-1,STAINED_GLASS:15)
Block(-1,2,-1,STAINED_GLASS:10)
Block(0,2,-1,PURPLE_GLAZED_TERRACOTTA:3)
Block(1,2,-1,PURPLE_GLAZED_TERRACOTTA:3)
Block(2,2,-1,STAINED_GLASS:11)
Block(3,2,-1,STAINED_GLASS:10)
Block(4,2,-1,STAINED_GLASS:10)
Block(5,2,-1,STAINED_GLASS:3)
Block(-5,2,0,STAINED_GLASS:15)
Block(-3,2,0,STAINED_GLASS:15)
Block(-2,2,0,STAINED_GLASS:10)
Block(-1,2,0,PURPLE_GLAZED_TERRACOTTA:3)
Block(0,2,0,PURPLE_GLAZED_TERRACOTTA:3)
Block(1,2,0,SEA_LANTERN:0)
Block(2,2,0,STAINED_GLASS:11)
Block(3,2,0,STAINED_GLASS:11)
Block(4,2,0,STAINED_GLASS:10)
Block(5,2,0,STAINED_GLASS:3)
Block(-4,2,1,STAINED_GLASS:15)
Block(-3,2,1,STAINED_GLASS:10)
Block(-2,2,1,PURPLE_GLAZED_TERRACOTTA:3)
Block(-1,2,1,PURPLE_GLAZED_TERRACOTTA:3)
Block(0,2,1,SEA_LANTERN:0)
Block(1,2,1,SEA_LANTERN:0)
Block(2,2,1,SEA_LANTERN:0)
Block(3,2,1,STAINED_GLASS:11)
Block(4,2,1,STAINED_GLASS:11)
Block(5,2,1,STAINED_GLASS:10)
Block(6,2,1,STAINED_GLASS:15)
Block(-3,2,2,STAINED_GLASS:3)
Block(-2,2,2,STAINED_GLASS:10)
Block(-1,2,2,PURPLE_GLAZED_TERRACOTTA:3)
Block(0,2,2,PURPLE_GLAZED_TERRACOTTA:3)
Block(1,2,2,SEA_LANTERN:0)
Block(2,2,2,PURPLE_GLAZED_TERRACOTTA:3)
Block(3,2,2,STAINED_GLASS:11)
Block(4,2,2,STAINED_GLASS:10)
Block(5,2,2,STAINED_GLASS:15)
Block(-2,2,3,STAINED_GLASS:15)
Block(-1,2,3,STAINED_GLASS:10)
Block(0,2,3,STAINED_GLASS:11)
Block(1,2,3,STAINED_GLASS:11)
Block(2,2,3,PURPLE_GLAZED_TERRACOTTA:3)
Block(3,2,3,STAINED_GLASS:10)
Block(4,2,3,STAINED_GLASS:15)
Block(-2,2,4,STAINED_GLASS:15)
Block(-1,2,4,STAINED_GLASS:10)
Block(0,2,4,STAINED_GLASS:10)
Block(1,2,4,STAINED_GLASS:11)
Block(2,2,4,STAINED_GLASS:10)
Block(3,2,4,STAINED_GLASS:15)
Block(-1,2,5,STAINED_GLASS:15)
Block(0,2,5,STAINED_GLASS:3)
Block(1,2,5,STAINED_GLASS:10)
Block(2,2,5,STAINED_GLASS:3)
Block(1,2,6,STAINED_GLASS:3)
Block(-1,3,-5,STAINED_GLASS:15)
Block(0,3,-5,STAINED_GLASS:15)
Block(-2,3,-4,STAINED_GLASS:15)
Block(-1,3,-4,STAINED_GLASS:10)
Block(0,3,-4,STAINED_GLASS:15)
Block(1,3,-4,STAINED_GLASS:15)
Block(2,3,-4,STAINED_GLASS:15)
Block(-3,3,-3,STAINED_GLASS:15)
Block(-2,3,-3,STAINED_GLASS:10)
Block(-1,3,-3,STAINED_GLASS:3)
Block(0,3,-3,STAINED_GLASS:10)
Block(1,3,-3,STAINED_GLASS:10)
Block(2,3,-3,STAINED_GLASS:15)
Block(3,3,-3,STAINED_GLASS:15)
Block(-4,3,-2,STAINED_GLASS:15)
Block(-3,3,-2,STAINED_GLASS:10)
Block(-2,3,-2,STAINED_GLASS:3)
Block(-1,3,-2,STAINED_GLASS:10)
Block(0,3,-2,PURPLE_GLAZED_TERRACOTTA:3)
Block(1,3,-2,PURPLE_GLAZED_TERRACOTTA:3)
Block(2,3,-2,STAINED_GLASS:10)
Block(3,3,-2,STAINED_GLASS:10)
Block(4,3,-2,STAINED_GLASS:15)
Block(-5,3,-1,STAINED_GLASS:15)
Block(-4,3,-1,STAINED_GLASS:10)
Block(-3,3,-1,STAINED_GLASS:3)
Block(-2,3,-1,STAINED_GLASS:10)
Block(-1,3,-1,PURPLE_GLAZED_TERRACOTTA:3)
Block(0,3,-1,PURPLE_GLAZED_TERRACOTTA:3)
Block(1,3,-1,PURPLE_GLAZED_TERRACOTTA:3)
Block(2,3,-1,STAINED_GLASS:11)
Block(3,3,-1,STAINED_GLASS:10)
Block(4,3,-1,STAINED_GLASS:10)
Block(5,3,-1,STAINED_GLASS:15)
Block(-5,3,0,STAINED_GLASS:15)
Block(-4,3,0,STAINED_GLASS:15)
Block(-3,3,0,STAINED_GLASS:10)
Block(-2,3,0,PURPLE_GLAZED_TERRACOTTA:3)
Block(-1,3,0,PURPLE_GLAZED_TERRACOTTA:3)
Block(0,3,0,SEA_LANTERN:0)
Block(1,3,0,SEA_LANTERN:0)
Block(2,3,0,STAINED_GLASS:11)
Block(3,3,0,STAINED_GLASS:11)
Block(4,3,0,STAINED_GLASS:10)
Block(5,3,0,STAINED_GLASS:3)
Block(-4,3,1,STAINED_GLASS:15)
Block(-3,3,1,STAINED_GLASS:10)
Block(-2,3,1,PURPLE_GLAZED_TERRACOTTA:3)
Block(-1,3,1,PURPLE_GLAZED_TERRACOTTA:3)
Block(0,3,1,SEA_LANTERN:0)
Block(1,3,1,SEA_LANTERN:0)
Block(2,3,1,STAINED_GLASS:11)
Block(3,3,1,STAINED_GLASS:11)
Block(4,3,1,STAINED_GLASS:10)
Block(5,3,1,STAINED_GLASS:15)
Block(-4,3,2,STAINED_GLASS:15)
Block(-3,3,2,STAINED_GLASS:15)
Block(-2,3,2,STAINED_GLASS:10)
Block(-1,3,2,STAINED_GLASS:11)
Block(0,3,2,STAINED_GLASS:11)
Block(1,3,2,STAINED_GLASS:11)
Block(2,3,2,STAINED_GLASS:11)
Block(3,3,2,STAINED_GLASS:10)
Block(4,3,2,STAINED_GLASS:15)
Block(-3,3,3,STAINED_GLASS:15)
Block(-2,3,3,STAINED_GLASS:10)
Block(-1,3,3,STAINED_GLASS:10)
Block(0,3,3,STAINED_GLASS:11)
Block(1,3,3,STAINED_GLASS:11)
Block(2,3,3,STAINED_GLASS:10)
Block(3,3,3,STAINED_GLASS:10)
Block(4,3,3,STAINED_GLASS:15)
Block(-2,3,4,STAINED_GLASS:15)
Block(-1,3,4,STAINED_GLASS:10)
Block(0,3,4,STAINED_GLASS:10)
Block(1,3,4,STAINED_GLASS:10)
Block(2,3,4,STAINED_GLASS:3)
Block(3,3,4,STAINED_GLASS:15)
Block(-1,3,5,STAINED_GLASS:15)
Block(0,3,5,STAINED_GLASS:3)
Block(1,3,5,STAINED_GLASS:3)
Block(-1,4,-6,STAINED_GLASS:15)
Block(-2,4,-5,STAINED_GLASS:15)
Block(-1,4,-5,STAINED_GLASS:10)
Block(0,4,-5,STAINED_GLASS:15)
Block(-3,4,-4,STAINED_GLASS:15)
Block(-2,4,-4,STAINED_GLASS:10)
Block(-1,4,-4,STAINED_GLASS:15)
Block(0,4,-4,STAINED_GLASS:10)
Block(1,4,-4,STAINED_GLASS:15)
Block(2,4,-4,STAINED_GLASS:15)
Block(-4,4,-3,STAINED_GLASS:15)
Block(-3,4,-3,STAINED_GLASS:10)
Block(-2,4,-3,STAINED_GLASS:15)
Block(-1,4,-3,STAINED_GLASS:10)
Block(0,4,-3,PURPLE_GLAZED_TERRACOTTA:3)
Block(1,4,-3,STAINED_GLASS:10)
Block(2,4,-3,STAINED_GLASS:15)
Block(3,4,-3,STAINED_GLASS:15)
Block(-5,4,-2,STAINED_GLASS:15)
Block(-4,4,-2,STAINED_GLASS:10)
Block(-3,4,-2,STAINED_GLASS:15)
Block(-2,4,-2,STAINED_GLASS:10)
Block(-1,4,-2,PURPLE_GLAZED_TERRACOTTA:3)
Block(0,4,-2,PURPLE_GLAZED_TERRACOTTA:3)
Block(1,4,-2,STAINED_GLASS:11)
Block(2,4,-2,STAINED_GLASS:10)
Block(3,4,-2,STAINED_GLASS:10)
Block(4,4,-2,STAINED_GLASS:15)
Block(-6,4,-1,STAINED_GLASS:15)
Block(-5,4,-1,STAINED_GLASS:10)
Block(-4,4,-1,STAINED_GLASS:3)
Block(-3,4,-1,STAINED_GLASS:10)
Block(-2,4,-1,PURPLE_GLAZED_TERRACOTTA:3)
Block(-1,4,-1,PURPLE_GLAZED_TERRACOTTA:3)
Block(0,4,-1,SEA_LANTERN:0)
Block(1,4,-1,STAINED_GLASS:11)
Block(2,4,-1,STAINED_GLASS:11)
Block(3,4,-1,STAINED_GLASS:10)
Block(4,4,-1,STAINED_GLASS:15)
Block(-5,4,0,STAINED_GLASS:15)
Block(-4,4,0,STAINED_GLASS:10)
Block(-3,4,0,STAINED_GLASS:11)
Block(-2,4,0,STAINED_GLASS:11)
Block(-1,4,0,SEA_LANTERN:0)
Block(0,4,0,SEA_LANTERN:0)
Block(1,4,0,SEA_LANTERN:0)
Block(2,4,0,STAINED_GLASS:11)
Block(3,4,0,STAINED_GLASS:11)
Block(4,4,0,STAINED_GLASS:10)
Block(5,4,0,STAINED_GLASS:15)
Block(-4,4,1,STAINED_GLASS:15)
Block(-3,4,1,STAINED_GLASS:10)
Block(-2,4,1,STAINED_GLASS:11)
Block(-1,4,1,STAINED_GLASS:11)
Block(0,4,1,SEA_LANTERN:0)
Block(1,4,1,STAINED_GLASS:11)
Block(2,4,1,STAINED_GLASS:11)
Block(3,4,1,STAINED_GLASS:10)
Block(4,4,1,STAINED_GLASS:15)
Block(-4,4,2,STAINED_GLASS:15)
Block(-3,4,2,STAINED_GLASS:15)
Block(-2,4,2,STAINED_GLASS:10)
Block(-1,4,2,STAINED_GLASS:11)
Block(0,4,2,STAINED_GLASS:11)
Block(1,4,2,STAINED_GLASS:11)
Block(2,4,2,STAINED_GLASS:10)
Block(3,4,2,STAINED_GLASS:10)
Block(4,4,2,STAINED_GLASS:15)
Block(-3,4,3,STAINED_GLASS:15)
Block(-2,4,3,STAINED_GLASS:10)
Block(-1,4,3,STAINED_GLASS:10)
Block(0,4,3,STAINED_GLASS:11)
Block(1,4,3,STAINED_GLASS:10)
Block(2,4,3,STAINED_GLASS:10)
Block(3,4,3,STAINED_GLASS:15)
Block(-2,4,4,STAINED_GLASS:15)
Block(-1,4,4,STAINED_GLASS:15)
Block(0,4,4,STAINED_GLASS:10)
Block(1,4,4,STAINED_GLASS:3)
Block(2,4,4,STAINED_GLASS:3)
Block(0,4,5,STAINED_GLASS:3)
Block(-2,5,-6,STAINED_GLASS:15)
Block(-1,5,-6,STAINED_GLASS:15)
Block(-3,5,-5,STAINED_GLASS:15)
Block(-2,5,-5,STAINED_GLASS:10)
Block(-1,5,-5,STAINED_GLASS:15)
Block(0,5,-5,STAINED_GLASS:15)
Block(1,5,-5,STAINED_GLASS:15)
Block(-4,5,-4,STAINED_GLASS:15)
Block(-3,5,-4,STAINED_GLASS:10)
Block(-2,5,-4,STAINED_GLASS:15)
Block(-1,5,-4,STAINED_GLASS:10)
Block(0,5,-4,STAINED_GLASS:10)
Block(1,5,-4,STAINED_GLASS:15)
Block(2,5,-4,STAINED_GLASS:15)
Block(-5,5,-3,STAINED_GLASS:15)
Block(-4,5,-3,STAINED_GLASS:10)
Block(-3,5,-3,STAINED_GLASS:15)
Block(-2,5,-3,STAINED_GLASS:10)
Block(-1,5,-3,STAINED_GLASS:11)
Block(0,5,-3,STAINED_GLASS:11)
Block(1,5,-3,STAINED_GLASS:10)
Block(2,5,-3,STAINED_GLASS:10)
Block(3,5,-3,STAINED_GLASS:15)
Block(-6,5,-2,STAINED_GLASS:15)
Block(-5,5,-2,STAINED_GLASS:10)
Block(-4,5,-2,STAINED_GLASS:15)
Block(-3,5,-2,STAINED_GLASS:10)
Block(-2,5,-2,PURPLE_GLAZED_TERRACOTTA:3)
Block(-1,5,-2,PURPLE_GLAZED_TERRACOTTA:3)
Block(0,5,-2,STAINED_GLASS:11)
Block(1,5,-2,STAINED_GLASS:11)
Block(2,5,-2,STAINED_GLASS:10)
Block(3,5,-2,STAINED_GLASS:10)
Block(4,5,-2,STAINED_GLASS:15)
Block(-6,5,-1,STAINED_GLASS:15)
Block(-5,5,-1,STAINED_GLASS:15)
Block(-4,5,-1,STAINED_GLASS:10)
Block(-3,5,-1,STAINED_GLASS:11)
Block(-2,5,-1,PURPLE_GLAZED_TERRACOTTA:3)
Block(-1,5,-1,SEA_LANTERN:0)
Block(0,5,-1,SEA_LANTERN:0)
Block(1,5,-1,STAINED_GLASS:11)
Block(2,5,-1,STAINED_GLASS:11)
Block(3,5,-1,STAINED_GLASS:10)
Block(4,5,-1,STAINED_GLASS:15)
Block(-5,5,0,STAINED_GLASS:15)
Block(-4,5,0,STAINED_GLASS:10)
Block(-3,5,0,STAINED_GLASS:11)
Block(-2,5,0,STAINED_GLASS:11)
Block(-1,5,0,SEA_LANTERN:0)
Block(0,5,0,SEA_LANTERN:0)
Block(1,5,0,STAINED_GLASS:11)
Block(2,5,0,STAINED_GLASS:11)
Block(3,5,0,STAINED_GLASS:10)
Block(4,5,0,STAINED_GLASS:15)
Block(-5,5,1,STAINED_GLASS:15)
Block(-4,5,1,STAINED_GLASS:15)
Block(-3,5,1,STAINED_GLASS:10)
Block(-2,5,1,STAINED_GLASS:11)
Block(-1,5,1,STAINED_GLASS:11)
Block(0,5,1,STAINED_GLASS:11)
Block(1,5,1,STAINED_GLASS:11)
Block(2,5,1,STAINED_GLASS:10)
Block(3,5,1,STAINED_GLASS:15)
Block(-4,5,2,STAINED_GLASS:15)
Block(-3,5,2,STAINED_GLASS:10)
Block(-2,5,2,STAINED_GLASS:10)
Block(-1,5,2,STAINED_GLASS:11)
Block(0,5,2,STAINED_GLASS:11)
Block(1,5,2,STAINED_GLASS:10)
Block(2,5,2,STAINED_GLASS:10)
Block(3,5,2,STAINED_GLASS:15)
Block(-3,5,3,STAINED_GLASS:15)
Block(-2,5,3,STAINED_GLASS:10)
Block(-1,5,3,STAINED_GLASS:10)
Block(0,5,3,STAINED_GLASS:10)
Block(1,5,3,STAINED_GLASS:3)
Block(2,5,3,STAINED_GLASS:15)
Block(-2,5,4,STAINED_GLASS:15)
Block(-1,5,4,STAINED_GLASS:15)
Block(0,5,4,STAINED_GLASS:3)
Block(-2,6,-7,STAINED_GLASS:15)
Block(-3,6,-6,STAINED_GLASS:15)
Block(-2,6,-6,STAINED_GLASS:10)
Block(-1,6,-6,STAINED_GLASS:15)
Block(-4,6,-5,STAINED_GLASS:15)
Block(-3,6,-5,STAINED_GLASS:10)
Block(-2,6,-5,STAINED_GLASS:15)
Block(-1,6,-5,STAINED_GLASS:10)
Block(0,6,-5,STAINED_GLASS:15)
Block(1,6,-5,STAINED_GLASS:15)
Block(-5,6,-4,STAINED_GLASS:15)
Block(-4,6,-4,STAINED_GLASS:10)
Block(-3,6,-4,STAINED_GLASS:15)
Block(-2,6,-4,STAINED_GLASS:10)
Block(-1,6,-4,STAINED_GLASS:11)
Block(0,6,-4,STAINED_GLASS:10)
Block(1,6,-4,STAINED_GLASS:15)
Block(2,6,-4,STAINED_GLASS:15)
Block(-6,6,-3,STAINED_GLASS:15)
Block(-5,6,-3,STAINED_GLASS:10)
Block(-4,6,-3,STAINED_GLASS:3)
Block(-3,6,-3,STAINED_GLASS:10)
Block(-2,6,-3,STAINED_GLASS:11)
Block(-1,6,-3,STAINED_GLASS:11)
Block(0,6,-3,STAINED_GLASS:11)
Block(1,6,-3,STAINED_GLASS:10)
Block(2,6,-3,STAINED_GLASS:10)
Block(3,6,-3,STAINED_GLASS:15)
Block(-7,6,-2,STAINED_GLASS:15)
Block(-6,6,-2,STAINED_GLASS:10)
Block(-5,6,-2,STAINED_GLASS:15)
Block(-4,6,-2,STAINED_GLASS:10)
Block(-3,6,-2,PURPLE_GLAZED_TERRACOTTA:3)
Block(-2,6,-2,PURPLE_GLAZED_TERRACOTTA:3)
Block(-1,6,-2,SEA_LANTERN:0)
Block(0,6,-2,STAINED_GLASS:11)
Block(1,6,-2,STAINED_GLASS:11)
Block(2,6,-2,STAINED_GLASS:10)
Block(3,6,-2,STAINED_GLASS:15)
Block(-6,6,-1,STAINED_GLASS:15)
Block(-5,6,-1,STAINED_GLASS:10)
Block(-4,6,-1,STAINED_GLASS:11)
Block(-3,6,-1,STAINED_GLASS:11)
Block(-2,6,-1,SEA_LANTERN:0)
Block(-1,6,-1,SEA_LANTERN:0)
Block(0,6,-1,SEA_LANTERN:0)
Block(1,6,-1,STAINED_GLASS:11)
Block(2,6,-1,STAINED_GLASS:11)
Block(3,6,-1,STAINED_GLASS:10)
Block(4,6,-1,STAINED_GLASS:15)
Block(-5,6,0,STAINED_GLASS:15)
Block(-4,6,0,STAINED_GLASS:10)
Block(-3,6,0,STAINED_GLASS:11)
Block(-2,6,0,STAINED_GLASS:11)
Block(-1,6,0,SEA_LANTERN:0)
Block(0,6,0,STAINED_GLASS:11)
Block(1,6,0,STAINED_GLASS:11)
Block(2,6,0,STAINED_GLASS:10)
Block(3,6,0,STAINED_GLASS:15)
Block(-5,6,1,STAINED_GLASS:15)
Block(-4,6,1,STAINED_GLASS:15)
Block(-3,6,1,STAINED_GLASS:10)
Block(-2,6,1,STAINED_GLASS:11)
Block(-1,6,1,STAINED_GLASS:11)
Block(0,6,1,STAINED_GLASS:11)
Block(1,6,1,STAINED_GLASS:10)
Block(2,6,1,STAINED_GLASS:10)
Block(3,6,1,STAINED_GLASS:15)
Block(-4,6,2,STAINED_GLASS:15)
Block(-3,6,2,STAINED_GLASS:10)
Block(-2,6,2,STAINED_GLASS:10)
Block(-1,6,2,STAINED_GLASS:11)
Block(0,6,2,STAINED_GLASS:10)
Block(1,6,2,STAINED_GLASS:10)
Block(2,6,2,STAINED_GLASS:3)
Block(-3,6,3,STAINED_GLASS:15)
Block(-2,6,3,STAINED_GLASS:15)
Block(-1,6,3,STAINED_GLASS:10)
Block(0,6,3,STAINED_GLASS:15)
Block(1,6,3,STAINED_GLASS:3)
Block(-1,6,4,STAINED_GLASS:15)
Block(-3,7,-7,STAINED_GLASS:15)
Block(-2,7,-7,STAINED_GLASS:15)
Block(-4,7,-6,STAINED_GLASS:15)
Block(-3,7,-6,STAINED_GLASS:10)
Block(-2,7,-6,STAINED_GLASS:15)
Block(-1,7,-6,STAINED_GLASS:15)
Block(0,7,-6,STAINED_GLASS:15)
Block(-5,7,-5,STAINED_GLASS:15)
Block(-4,7,-5,STAINED_GLASS:10)
Block(-3,7,-5,STAINED_GLASS:15)
Block(-2,7,-5,STAINED_GLASS:10)
Block(-1,7,-5,STAINED_GLASS:10)
Block(0,7,-5,STAINED_GLASS:15)
Block(1,7,-5,STAINED_GLASS:15)
Block(-6,7,-4,STAINED_GLASS:15)
Block(-5,7,-4,STAINED_GLASS:10)
Block(-4,7,-4,STAINED_GLASS:3)
Block(-3,7,-4,STAINED_GLASS:10)
Block(-2,7,-4,STAINED_GLASS:11)
Block(-1,7,-4,STAINED_GLASS:11)
Block(0,7,-4,STAINED_GLASS:10)
Block(1,7,-4,STAINED_GLASS:10)
Block(2,7,-4,STAINED_GLASS:15)
Block(-7,7,-3,STAINED_GLASS:15)
Block(-6,7,-3,STAINED_GLASS:10)
Block(-5,7,-3,STAINED_GLASS:15)
Block(-4,7,-3,STAINED_GLASS:10)
Block(-3,7,-3,PURPLE_GLAZED_TERRACOTTA:3)
Block(-2,7,-3,STAINED_GLASS:11)
Block(-1,7,-3,STAINED_GLASS:11)
Block(0,7,-3,STAINED_GLASS:11)
Block(1,7,-3,STAINED_GLASS:10)
Block(2,7,-3,STAINED_GLASS:10)
Block(3,7,-3,STAINED_GLASS:15)
Block(-7,7,-2,STAINED_GLASS:15)
Block(-6,7,-2,STAINED_GLASS:15)
Block(-5,7,-2,STAINED_GLASS:10)
Block(-4,7,-2,PURPLE_GLAZED_TERRACOTTA:3)
Block(-3,7,-2,PURPLE_GLAZED_TERRACOTTA:3)
Block(-2,7,-2,SEA_LANTERN:0)
Block(-1,7,-2,SEA_LANTERN:0)
Block(0,7,-2,STAINED_GLASS:11)
Block(1,7,-2,STAINED_GLASS:11)
Block(2,7,-2,STAINED_GLASS:10)
Block(3,7,-2,STAINED_GLASS:15)
Block(-6,7,-1,STAINED_GLASS:15)
Block(-5,7,-1,STAINED_GLASS:10)
Block(-4,7,-1,STAINED_GLASS:11)
Block(-3,7,-1,STAINED_GLASS:11)
Block(-2,7,-1,SEA_LANTERN:0)
Block(-1,7,-1,SEA_LANTERN:0)
Block(0,7,-1,PURPLE_GLAZED_TERRACOTTA:3)
Block(1,7,-1,STAINED_GLASS:11)
Block(2,7,-1,STAINED_GLASS:10)
Block(3,7,-1,STAINED_GLASS:15)
Block(-6,7,0,STAINED_GLASS:15)
Block(-5,7,0,STAINED_GLASS:15)
Block(-4,7,0,STAINED_GLASS:10)
Block(-3,7,0,STAINED_GLASS:11)
Block(-2,7,0,STAINED_GLASS:11)
Block(-1,7,0,STAINED_GLASS:11)
Block(0,7,0,STAINED_GLASS:11)
Block(1,7,0,STAINED_GLASS:10)
Block(2,7,0,STAINED_GLASS:15)
Block(-5,7,1,STAINED_GLASS:15)
Block(-4,7,1,STAINED_GLASS:10)
Block(-3,7,1,STAINED_GLASS:10)
Block(-2,7,1,STAINED_GLASS:11)
Block(-1,7,1,STAINED_GLASS:11)
Block(0,7,1,STAINED_GLASS:10)
Block(1,7,1,STAINED_GLASS:10)
Block(2,7,1,STAINED_GLASS:3)
Block(-4,7,2,STAINED_GLASS:15)
Block(-3,7,2,STAINED_GLASS:10)
Block(-2,7,2,STAINED_GLASS:10)
Block(-1,7,2,STAINED_GLASS:10)
Block(0,7,2,STAINED_GLASS:3)
Block(1,7,2,STAINED_GLASS:3)
Block(-3,7,3,STAINED_GLASS:15)
Block(-2,7,3,STAINED_GLASS:15)
Block(-1,7,3,STAINED_GLASS:15)
Block(-3,8,-8,STAINED_GLASS:3)
Block(-4,8,-7,STAINED_GLASS:3)
Block(-3,8,-7,STAINED_GLASS:11)
Block(-2,8,-7,STAINED_GLASS:3)
Block(-5,8,-6,STAINED_GLASS:3)
Block(-4,8,-6,STAINED_GLASS:10)
Block(-3,8,-6,STAINED_GLASS:3)
Block(-2,8,-6,STAINED_GLASS:11)
Block(-1,8,-6,STAINED_GLASS:15)
Block(0,8,-6,STAINED_GLASS:15)
Block(-6,8,-5,STAINED_GLASS:3)
Block(-5,8,-5,STAINED_GLASS:10)
Block(-4,8,-5,STAINED_GLASS:3)
Block(-3,8,-5,STAINED_GLASS:10)
Block(-2,8,-5,STAINED_GLASS:11)
Block(-1,8,-5,STAINED_GLASS:11)
Block(0,8,-5,STAINED_GLASS:15)
Block(1,8,-5,STAINED_GLASS:15)
Block(-7,8,-4,STAINED_GLASS:15)
Block(-6,8,-4,STAINED_GLASS:10)
Block(-5,8,-4,STAINED_GLASS:15)
Block(-4,8,-4,STAINED_GLASS:10)
Block(-3,8,-4,STAINED_GLASS:11)
Block(-2,8,-4,STAINED_GLASS:11)
Block(-1,8,-4,STAINED_GLASS:11)
Block(0,8,-4,STAINED_GLASS:10)
Block(1,8,-4,STAINED_GLASS:10)
Block(2,8,-4,STAINED_GLASS:15)
Block(-8,8,-3,STAINED_GLASS:15)
Block(-7,8,-3,STAINED_GLASS:10)
Block(-6,8,-3,STAINED_GLASS:15)
Block(-5,8,-3,STAINED_GLASS:10)
Block(-4,8,-3,PURPLE_GLAZED_TERRACOTTA:3)
Block(-3,8,-3,PURPLE_GLAZED_TERRACOTTA:3)
Block(-2,8,-3,SEA_LANTERN:0)
Block(-1,8,-3,STAINED_GLASS:11)
Block(0,8,-3,STAINED_GLASS:11)
Block(1,8,-3,STAINED_GLASS:10)
Block(2,8,-3,STAINED_GLASS:15)
Block(-7,8,-2,STAINED_GLASS:15)
Block(-6,8,-2,STAINED_GLASS:10)
Block(-5,8,-2,PURPLE_GLAZED_TERRACOTTA:3)
Block(-4,8,-2,PURPLE_GLAZED_TERRACOTTA:3)
Block(-3,8,-2,SEA_LANTERN:0)
Block(-2,8,-2,SEA_LANTERN:0)
Block(-1,8,-2,SEA_LANTERN:0)
Block(0,8,-2,STAINED_GLASS:11)
Block(1,8,-2,STAINED_GLASS:11)
Block(2,8,-2,STAINED_GLASS:10)
Block(3,8,-2,STAINED_GLASS:15)
Block(-6,8,-1,STAINED_GLASS:15)
Block(-5,8,-1,STAINED_GLASS:10)
Block(-4,8,-1,STAINED_GLASS:11)
Block(-3,8,-1,STAINED_GLASS:11)
Block(-2,8,-1,SEA_LANTERN:0)
Block(-1,8,-1,STAINED_GLASS:11)
Block(0,8,-1,STAINED_GLASS:11)
Block(1,8,-1,STAINED_GLASS:10)
Block(2,8,-1,STAINED_GLASS:15)
Block(-6,8,0,STAINED_GLASS:15)
Block(-5,8,0,STAINED_GLASS:15)
Block(-4,8,0,STAINED_GLASS:10)
Block(-3,8,0,STAINED_GLASS:11)
Block(-2,8,0,STAINED_GLASS:11)
Block(-1,8,0,STAINED_GLASS:11)
Block(0,8,0,STAINED_GLASS:10)
Block(1,8,0,STAINED_GLASS:10)
Block(2,8,0,STAINED_GLASS:3)
Block(-5,8,1,STAINED_GLASS:15)
Block(-4,8,1,STAINED_GLASS:10)
Block(-3,8,1,STAINED_GLASS:10)
Block(-2,8,1,STAINED_GLASS:11)
Block(-1,8,1,STAINED_GLASS:10)
Block(0,8,1,STAINED_GLASS:10)
Block(1,8,1,STAINED_GLASS:3)
Block(-4,8,2,STAINED_GLASS:15)
Block(-3,8,2,STAINED_GLASS:15)
Block(-2,8,2,STAINED_GLASS:10)
Block(-1,8,2,STAINED_GLASS:15)
Block(0,8,2,STAINED_GLASS:3)
Block(-2,8,3,STAINED_GLASS:15)
Block(-4,9,-8,STAINED_GLASS:15)
Block(-3,9,-8,STAINED_GLASS:15)
Block(-5,9,-7,STAINED_GLASS:3)
Block(-4,9,-7,STAINED_GLASS:3)
Block(-3,9,-7,STAINED_GLASS:15)
Block(-2,9,-7,STAINED_GLASS:15)
Block(-1,9,-7,STAINED_GLASS:15)
Block(-6,9,-6,STAINED_GLASS:3)
Block(-5,9,-6,STAINED_GLASS:3)
Block(-4,9,-6,STAINED_GLASS:15)
Block(-3,9,-6,STAINED_GLASS:3)
Block(-2,9,-6,STAINED_GLASS:15)
Block(-1,9,-6,STAINED_GLASS:15)
Block(0,9,-6,STAINED_GLASS:15)
Block(-7,9,-5,STAINED_GLASS:3)
Block(-6,9,-5,STAINED_GLASS:3)
Block(-5,9,-5,STAINED_GLASS:3)
Block(-4,9,-5,STAINED_GLASS:3)
Block(-3,9,-5,STAINED_GLASS:11)
Block(-2,9,-5,STAINED_GLASS:11)
Block(-1,9,-5,STAINED_GLASS:3)
Block(0,9,-5,STAINED_GLASS:15)
Block(1,9,-5,STAINED_GLASS:3)
Block(-8,9,-4,STAINED_GLASS:15)
Block(-7,9,-4,STAINED_GLASS:15)
Block(-6,9,-4,STAINED_GLASS:15)
Block(-5,9,-4,STAINED_GLASS:3)
Block(-4,9,-4,STAINED_GLASS:10)
Block(-3,9,-4,STAINED_GLASS:10)
Block(-2,9,-4,STAINED_GLASS:11)
Block(-1,9,-4,STAINED_GLASS:11)
Block(0,9,-4,STAINED_GLASS:3)
Block(1,9,-4,STAINED_GLASS:3)
Block(2,9,-4,STAINED_GLASS:15)
Block(-8,9,-3,STAINED_GLASS:15)
Block(-7,9,-3,STAINED_GLASS:15)
Block(-6,9,-3,STAINED_GLASS:3)
Block(-5,9,-3,STAINED_GLASS:10)
Block(-4,9,-3,STAINED_GLASS:10)
Block(-3,9,-3,SEA_LANTERN:0)
Block(-2,9,-3,SEA_LANTERN:0)
Block(-1,9,-3,STAINED_GLASS:10)
Block(0,9,-3,STAINED_GLASS:10)
Block(1,9,-3,STAINED_GLASS:15)
Block(2,9,-3,STAINED_GLASS:3)
Block(-7,9,-2,STAINED_GLASS:15)
Block(-6,9,-2,STAINED_GLASS:3)
Block(-5,9,-2,STAINED_GLASS:10)
Block(-4,9,-2,STAINED_GLASS:10)
Block(-3,9,-2,SEA_LANTERN:0)
Block(-2,9,-2,SEA_LANTERN:0)
Block(-1,9,-2,STAINED_GLASS:10)
Block(0,9,-2,STAINED_GLASS:10)
Block(1,9,-2,STAINED_GLASS:15)
Block(2,9,-2,STAINED_GLASS:3)
Block(-7,9,-1,STAINED_GLASS:15)
Block(-6,9,-1,STAINED_GLASS:15)
Block(-5,9,-1,STAINED_GLASS:15)
Block(-4,9,-1,STAINED_GLASS:10)
Block(-3,9,-1,STAINED_GLASS:10)
Block(-2,9,-1,STAINED_GLASS:10)
Block(-1,9,-1,STAINED_GLASS:10)
Block(0,9,-1,STAINED_GLASS:3)
Block(1,9,-1,STAINED_GLASS:15)
Block(-6,9,0,STAINED_GLASS:15)
Block(-5,9,0,STAINED_GLASS:15)
Block(-4,9,0,STAINED_GLASS:15)
Block(-3,9,0,STAINED_GLASS:10)
Block(-2,9,0,STAINED_GLASS:10)
Block(-1,9,0,STAINED_GLASS:3)
Block(0,9,0,STAINED_GLASS:3)
Block(1,9,0,STAINED_GLASS:3)
Block(-5,9,1,STAINED_GLASS:15)
Block(-4,9,1,STAINED_GLASS:15)
Block(-3,9,1,STAINED_GLASS:3)
Block(-2,9,1,STAINED_GLASS:3)
Block(-1,9,1,STAINED_GLASS:3)
Block(0,9,1,STAINED_GLASS:3)
Block(-4,9,2,STAINED_GLASS:15)
Block(-3,9,2,STAINED_GLASS:15)
Block(-2,9,2,STAINED_GLASS:15)
Block(-4,10,-9,STAINED_GLASS:15)
Block(-5,10,-8,STAINED_GLASS:15)
Block(-4,10,-8,STAINED_GLASS:3)
Block(-3,10,-8,STAINED_GLASS:15)
Block(-6,10,-7,STAINED_GLASS:3)
Block(-5,10,-7,STAINED_GLASS:3)
Block(-4,10,-7,STAINED_GLASS:15)
Block(-3,10,-7,STAINED_GLASS:3)
Block(-2,10,-7,STAINED_GLASS:15)
Block(-1,10,-7,STAINED_GLASS:15)
Block(-7,10,-6,STAINED_GLASS:3)
Block(-6,10,-6,STAINED_GLASS:3)
Block(-5,10,-6,STAINED_GLASS:3)
Block(-4,10,-6,STAINED_GLASS:3)
Block(-3,10,-6,STAINED_GLASS:11)
Block(-2,10,-6,STAINED_GLASS:3)
Block(-1,10,-6,STAINED_GLASS:15)
Block(0,10,-6,STAINED_GLASS:3)
Block(-8,10,-5,STAINED_GLASS:3)
Block(-7,10,-5,STAINED_GLASS:3)
Block(-6,10,-5,STAINED_GLASS:3)
Block(-5,10,-5,STAINED_GLASS:3)
Block(-4,10,-5,PURPLE_GLAZED_TERRACOTTA:3)
Block(-3,10,-5,STAINED_GLASS:11)
Block(-2,10,-5,STAINED_GLASS:11)
Block(-1,10,-5,STAINED_GLASS:3)
Block(0,10,-5,STAINED_GLASS:3)
Block(1,10,-5,STAINED_GLASS:15)
Block(-9,10,-4,STAINED_GLASS:3)
Block(-8,10,-4,STAINED_GLASS:3)
Block(-7,10,-4,STAINED_GLASS:15)
Block(-6,10,-4,STAINED_GLASS:3)
Block(-5,10,-4,STAINED_GLASS:10)
Block(-4,10,-4,STAINED_GLASS:10)
Block(-3,10,-4,SEA_LANTERN:0)
Block(-2,10,-4,STAINED_GLASS:11)
Block(-1,10,-4,STAINED_GLASS:11)
Block(0,10,-4,STAINED_GLASS:15)
Block(1,10,-4,STAINED_GLASS:15)
Block(-8,10,-3,STAINED_GLASS:15)
Block(-7,10,-3,STAINED_GLASS:3)
Block(-6,10,-3,STAINED_GLASS:10)
Block(-5,10,-3,STAINED_GLASS:10)
Block(-4,10,-3,SEA_LANTERN:0)
Block(-3,10,-3,SEA_LANTERN:0)
Block(-2,10,-3,SEA_LANTERN:0)
Block(-1,10,-3,STAINED_GLASS:11)
Block(0,10,-3,STAINED_GLASS:10)
Block(1,10,-3,STAINED_GLASS:15)
Block(2,10,-3,STAINED_GLASS:3)
Block(-7,10,-2,STAINED_GLASS:3)
Block(-6,10,-2,STAINED_GLASS:3)
Block(-5,10,-2,STAINED_GLASS:10)
Block(-4,10,-2,STAINED_GLASS:10)
Block(-3,10,-2,SEA_LANTERN:0)
Block(-2,10,-2,STAINED_GLASS:10)
Block(-1,10,-2,STAINED_GLASS:10)
Block(0,10,-2,STAINED_GLASS:15)
Block(1,10,-2,STAINED_GLASS:15)
Block(-7,10,-1,STAINED_GLASS:3)
Block(-6,10,-1,STAINED_GLASS:15)
Block(-5,10,-1,STAINED_GLASS:3)
Block(-4,10,-1,STAINED_GLASS:10)
Block(-3,10,-1,STAINED_GLASS:10)
Block(-2,10,-1,STAINED_GLASS:10)
Block(-1,10,-1,STAINED_GLASS:15)
Block(0,10,-1,STAINED_GLASS:15)
Block(1,10,-1,STAINED_GLASS:15)
Block(-6,10,0,STAINED_GLASS:15)
Block(-5,10,0,STAINED_GLASS:15)
Block(-4,10,0,STAINED_GLASS:15)
Block(-3,10,0,STAINED_GLASS:10)
Block(-2,10,0,STAINED_GLASS:3)
Block(-1,10,0,STAINED_GLASS:3)
Block(0,10,0,STAINED_GLASS:3)
Block(-5,10,1,STAINED_GLASS:15)
Block(-4,10,1,STAINED_GLASS:15)
Block(-3,10,1,STAINED_GLASS:3)
Block(-2,10,1,STAINED_GLASS:3)
Block(-1,10,1,STAINED_GLASS:3)
Block(-3,10,2,STAINED_GLASS:15)
Block(-5,11,-9,STAINED_GLASS:15)
Block(-4,11,-9,STAINED_GLASS:15)
Block(-6,11,-8,STAINED_GLASS:15)
Block(-5,11,-8,STAINED_GLASS:3)
Block(-4,11,-8,STAINED_GLASS:15)
Block(-3,11,-8,STAINED_GLASS:15)
Block(-2,11,-8,STAINED_GLASS:15)
Block(-7,11,-7,STAINED_GLASS:3)
Block(-6,11,-7,STAINED_GLASS:3)
Block(-5,11,-7,STAINED_GLASS:15)
Block(-4,11,-7,STAINED_GLASS:3)
Block(-3,11,-7,STAINED_GLASS:3)
Block(-2,11,-7,STAINED_GLASS:15)
Block(-1,11,-7,STAINED_GLASS:3)
Block(-8,11,-6,STAINED_GLASS:3)
Block(-7,11,-6,STAINED_GLASS:3)
Block(-6,11,-6,STAINED_GLASS:3)
Block(-5,11,-6,STAINED_GLASS:3)
Block(-4,11,-6,PURPLE_GLAZED_TERRACOTTA:3)
Block(-3,11,-6,STAINED_GLASS:11)
Block(-2,11,-6,STAINED_GLASS:3)
Block(-1,11,-6,STAINED_GLASS:3)
Block(0,11,-6,STAINED_GLASS:3)
Block(-9,11,-5,STAINED_GLASS:3)
Block(-8,11,-5,STAINED_GLASS:3)
Block(-7,11,-5,STAINED_GLASS:3)
Block(-6,11,-5,STAINED_GLASS:3)
Block(-5,11,-5,STAINED_GLASS:10)
Block(-4,11,-5,PURPLE_GLAZED_TERRACOTTA:3)
Block(-3,11,-5,STAINED_GLASS:11)
Block(-2,11,-5,STAINED_GLASS:11)
Block(-1,11,-5,STAINED_GLASS:3)
Block(0,11,-5,STAINED_GLASS:15)
Block(1,11,-5,STAINED_GLASS:15)
Block(-9,11,-4,STAINED_GLASS:3)
Block(-8,11,-4,STAINED_GLASS:3)
Block(-7,11,-4,STAINED_GLASS:3)
Block(-6,11,-4,STAINED_GLASS:10)
Block(-5,11,-4,STAINED_GLASS:10)
Block(-4,11,-4,SEA_LANTERN:0)
Block(-3,11,-4,SEA_LANTERN:0)
Block(-2,11,-4,STAINED_GLASS:11)
Block(-1,11,-4,STAINED_GLASS:11)
Block(0,11,-4,STAINED_GLASS:15)
Block(1,11,-4,STAINED_GLASS:15)
Block(-8,11,-3,STAINED_GLASS:3)
Block(-7,11,-3,STAINED_GLASS:3)
Block(-6,11,-3,STAINED_GLASS:10)
Block(-5,11,-3,STAINED_GLASS:10)
Block(-4,11,-3,SEA_LANTERN:0)
Block(-3,11,-3,SEA_LANTERN:0)
Block(-2,11,-3,PURPLE_GLAZED_TERRACOTTA:3)
Block(-1,11,-3,STAINED_GLASS:11)
Block(0,11,-3,STAINED_GLASS:15)
Block(1,11,-3,STAINED_GLASS:15)
Block(-8,11,-2,STAINED_GLASS:15)
Block(-7,11,-2,STAINED_GLASS:15)
Block(-6,11,-2,STAINED_GLASS:3)
Block(-5,11,-2,STAINED_GLASS:10)
Block(-4,11,-2,STAINED_GLASS:10)
Block(-3,11,-2,STAINED_GLASS:10)
Block(-2,11,-2,STAINED_GLASS:10)
Block(-1,11,-2,STAINED_GLASS:3)
Block(0,11,-2,STAINED_GLASS:15)
Block(-7,11,-1,STAINED_GLASS:3)
Block(-6,11,-1,STAINED_GLASS:3)
Block(-5,11,-1,STAINED_GLASS:3)
Block(-4,11,-1,STAINED_GLASS:10)
Block(-3,11,-1,STAINED_GLASS:10)
Block(-2,11,-1,STAINED_GLASS:3)
Block(-1,11,-1,STAINED_GLASS:3)
Block(0,11,-1,STAINED_GLASS:15)
Block(-6,11,0,STAINED_GLASS:15)
Block(-5,11,0,STAINED_GLASS:3)
Block(-4,11,0,STAINED_GLASS:15)
Block(-3,11,0,STAINED_GLASS:3)
Block(-2,11,0,STAINED_GLASS:3)
Block(-1,11,0,STAINED_GLASS:3)
Block(-5,11,1,STAINED_GLASS:15)
Block(-4,11,1,STAINED_GLASS:15)
Block(-3,11,1,STAINED_GLASS:3)
Block(-5,12,-10,STAINED_GLASS:15)
Block(-6,12,-9,STAINED_GLASS:15)
Block(-5,12,-9,STAINED_GLASS:3)
Block(-4,12,-9,STAINED_GLASS:15)
Block(-7,12,-8,STAINED_GLASS:15)
Block(-6,12,-8,STAINED_GLASS:3)
Block(-5,12,-8,STAINED_GLASS:15)
Block(-4,12,-8,STAINED_GLASS:3)
Block(-3,12,-8,STAINED_GLASS:15)
Block(-2,12,-8,STAINED_GLASS:15)
Block(-8,12,-7,STAINED_GLASS:15)
Block(-7,12,-7,STAINED_GLASS:3)
Block(-6,12,-7,STAINED_GLASS:15)
Block(-5,12,-7,STAINED_GLASS:3)
Block(-4,12,-7,PURPLE_GLAZED_TERRACOTTA:3)
Block(-3,12,-7,STAINED_GLASS:15)
Block(-2,12,-7,STAINED_GLASS:15)
Block(-1,12,-7,STAINED_GLASS:15)
Block(-9,12,-6,STAINED_GLASS:3)
Block(-8,12,-6,STAINED_GLASS:3)
Block(-7,12,-6,STAINED_GLASS:15)
Block(-6,12,-6,STAINED_GLASS:3)
Block(-5,12,-6,PURPLE_GLAZED_TERRACOTTA:3)
Block(-4,12,-6,PURPLE_GLAZED_TERRACOTTA:3)
Block(-3,12,-6,STAINED_GLASS:11)
Block(-2,12,-6,STAINED_GLASS:3)
Block(-1,12,-6,STAINED_GLASS:3)
Block(0,12,-6,STAINED_GLASS:15)
Block(-10,12,-5,STAINED_GLASS:3)
Block(-9,12,-5,STAINED_GLASS:3)
Block(-8,12,-5,STAINED_GLASS:3)
Block(-7,12,-5,STAINED_GLASS:3)
Block(-6,12,-5,STAINED_GLASS:10)
Block(-5,12,-5,PURPLE_GLAZED_TERRACOTTA:3)
Block(-4,12,-5,SEA_LANTERN:0)
Block(-3,12,-5,STAINED_GLASS:11)
Block(-2,12,-5,STAINED_GLASS:11)
Block(-1,12,-5,STAINED_GLASS:3)
Block(0,12,-5,STAINED_GLASS:15)
Block(-9,12,-4,STAINED_GLASS:3)
Block(-8,12,-4,STAINED_GLASS:3)
Block(-7,12,-4,STAINED_GLASS:10)
Block(-6,12,-4,STAINED_GLASS:10)
Block(-5,12,-4,SEA_LANTERN:0)
Block(-4,12,-4,SEA_LANTERN:0)
Block(-3,12,-4,SEA_LANTERN:0)
Block(-2,12,-4,STAINED_GLASS:11)
Block(-1,12,-4,STAINED_GLASS:11)
Block(0,12,-4,STAINED_GLASS:15)
Block(1,12,-4,STAINED_GLASS:15)
Block(-8,12,-3,STAINED_GLASS:15)
Block(-7,12,-3,STAINED_GLASS:15)
Block(-6,12,-3,STAINED_GLASS:10)
Block(-5,12,-3,STAINED_GLASS:10)
Block(-4,12,-3,SEA_LANTERN:0)
Block(-3,12,-3,PURPLE_GLAZED_TERRACOTTA:3)
Block(-2,12,-3,PURPLE_GLAZED_TERRACOTTA:3)
Block(-1,12,-3,STAINED_GLASS:3)
Block(0,12,-3,STAINED_GLASS:15)
Block(-8,12,-2,STAINED_GLASS:15)
Block(-7,12,-2,STAINED_GLASS:15)
Block(-6,12,-2,STAINED_GLASS:3)
Block(-5,12,-2,STAINED_GLASS:10)
Block(-4,12,-2,STAINED_GLASS:10)
Block(-3,12,-2,STAINED_GLASS:10)
Block(-2,12,-2,STAINED_GLASS:3)
Block(-1,12,-2,STAINED_GLASS:3)
Block(0,12,-2,STAINED_GLASS:15)
Block(-7,12,-1,STAINED_GLASS:15)
Block(-6,12,-1,STAINED_GLASS:15)
Block(-5,12,-1,STAINED_GLASS:3)
Block(-4,12,-1,STAINED_GLASS:10)
Block(-3,12,-1,STAINED_GLASS:3)
Block(-2,12,-1,STAINED_GLASS:3)
Block(-1,12,-1,STAINED_GLASS:3)
Block(-6,12,0,STAINED_GLASS:15)
Block(-5,12,0,STAINED_GLASS:15)
Block(-4,12,0,STAINED_GLASS:3)
Block(-3,12,0,STAINED_GLASS:3)
Block(-2,12,0,STAINED_GLASS:3)
Block(-4,12,1,STAINED_GLASS:15)
Block(-6,13,-10,STAINED_GLASS:15)
Block(-5,13,-10,STAINED_GLASS:3)
Block(-7,13,-9,STAINED_GLASS:15)
Block(-6,13,-9,STAINED_GLASS:3)
Block(-5,13,-9,STAINED_GLASS:15)
Block(-4,13,-9,STAINED_GLASS:3)
Block(-3,13,-9,STAINED_GLASS:15)
Block(-8,13,-8,STAINED_GLASS:15)
Block(-7,13,-8,STAINED_GLASS:3)
Block(-6,13,-8,STAINED_GLASS:15)
Block(-5,13,-8,STAINED_GLASS:3)
Block(-4,13,-8,STAINED_GLASS:3)
Block(-3,13,-8,STAINED_GLASS:15)
Block(-2,13,-8,STAINED_GLASS:15)
Block(-9,13,-7,STAINED_GLASS:15)
Block(-8,13,-7,STAINED_GLASS:3)
Block(-7,13,-7,STAINED_GLASS:15)
Block(-6,13,-7,STAINED_GLASS:3)
Block(-5,13,-7,PURPLE_GLAZED_TERRACOTTA:3)
Block(-4,13,-7,PURPLE_GLAZED_TERRACOTTA:3)
Block(-3,13,-7,STAINED_GLASS:15)
Block(-2,13,-7,STAINED_GLASS:15)
Block(-1,13,-7,STAINED_GLASS:15)
Block(-10,13,-6,STAINED_GLASS:15)
Block(-9,13,-6,STAINED_GLASS:3)
Block(-8,13,-6,STAINED_GLASS:15)
Block(-7,13,-6,STAINED_GLASS:3)
Block(-6,13,-6,STAINED_GLASS:10)
Block(-5,13,-6,PURPLE_GLAZED_TERRACOTTA:3)
Block(-4,13,-6,PURPLE_GLAZED_TERRACOTTA:3)
Block(-3,13,-6,STAINED_GLASS:11)
Block(-2,13,-6,STAINED_GLASS:3)
Block(-1,13,-6,STAINED_GLASS:3)
Block(0,13,-6,STAINED_GLASS:15)
Block(-10,13,-5,STAINED_GLASS:3)
Block(-9,13,-5,STAINED_GLASS:3)
Block(-8,13,-5,STAINED_GLASS:3)
Block(-7,13,-5,STAINED_GLASS:10)
Block(-6,13,-5,STAINED_GLASS:10)
Block(-5,13,-5,SEA_LANTERN:0)
Block(-4,13,-5,SEA_LANTERN:0)
Block(-3,13,-5,STAINED_GLASS:11)
Block(-2,13,-5,STAINED_GLASS:11)
Block(-1,13,-5,STAINED_GLASS:3)
Block(0,13,-5,STAINED_GLASS:15)
Block(-9,13,-4,STAINED_GLASS:3)
Block(-8,13,-4,STAINED_GLASS:3)
Block(-7,13,-4,STAINED_GLASS:10)
Block(-6,13,-4,STAINED_GLASS:10)
Block(-5,13,-4,SEA_LANTERN:0)
Block(-4,13,-4,SEA_LANTERN:0)
Block(-3,13,-4,PURPLE_GLAZED_TERRACOTTA:3)
Block(-2,13,-4,STAINED_GLASS:11)
Block(-1,13,-4,STAINED_GLASS:3)
Block(0,13,-4,STAINED_GLASS:15)
Block(-9,13,-3,STAINED_GLASS:3)
Block(-8,13,-3,STAINED_GLASS:3)
Block(-7,13,-3,STAINED_GLASS:3)
Block(-6,13,-3,STAINED_GLASS:10)
Block(-5,13,-3,STAINED_GLASS:10)
Block(-4,13,-3,STAINED_GLASS:10)
Block(-3,13,-3,STAINED_GLASS:10)
Block(-2,13,-3,STAINED_GLASS:3)
Block(-1,13,-3,STAINED_GLASS:15)
Block(-8,13,-2,STAINED_GLASS:15)
Block(-7,13,-2,STAINED_GLASS:15)
Block(-6,13,-2,STAINED_GLASS:15)
Block(-5,13,-2,STAINED_GLASS:10)
Block(-4,13,-2,STAINED_GLASS:10)
Block(-3,13,-2,STAINED_GLASS:3)
Block(-2,13,-2,STAINED_GLASS:3)
Block(-1,13,-2,STAINED_GLASS:3)
Block(-7,13,-1,STAINED_GLASS:15)
Block(-6,13,-1,STAINED_GLASS:15)
Block(-5,13,-1,STAINED_GLASS:3)
Block(-4,13,-1,STAINED_GLASS:15)
Block(-3,13,-1,STAINED_GLASS:15)
Block(-2,13,-1,STAINED_GLASS:3)
Block(-6,13,0,STAINED_GLASS:15)
Block(-5,13,0,STAINED_GLASS:15)
Block(-4,13,0,STAINED_GLASS:15)
Block(-6,14,-11,STAINED_GLASS:15)
Block(-7,14,-10,STAINED_GLASS:15)
Block(-6,14,-10,STAINED_GLASS:3)
Block(-5,14,-10,STAINED_GLASS:15)
Block(-8,14,-9,STAINED_GLASS:15)
Block(-7,14,-9,STAINED_GLASS:3)
Block(-6,14,-9,STAINED_GLASS:15)
Block(-5,14,-9,STAINED_GLASS:3)
Block(-4,14,-9,STAINED_GLASS:15)
Block(-3,14,-9,STAINED_GLASS:15)
Block(-9,14,-8,STAINED_GLASS:15)
Block(-8,14,-8,STAINED_GLASS:3)
Block(-7,14,-8,STAINED_GLASS:15)
Block(-6,14,-8,STAINED_GLASS:3)
Block(-5,14,-8,STAINED_GLASS:10)
Block(-4,14,-8,STAINED_GLASS:3)
Block(-3,14,-8,STAINED_GLASS:15)
Block(-2,14,-8,STAINED_GLASS:15)
Block(-10,14,-7,STAINED_GLASS:15)
Block(-9,14,-7,STAINED_GLASS:3)
Block(-8,14,-7,STAINED_GLASS:15)
Block(-7,14,-7,STAINED_GLASS:3)
Block(-6,14,-7,STAINED_GLASS:10)
Block(-5,14,-7,STAINED_GLASS:11)
Block(-4,14,-7,STAINED_GLASS:11)
Block(-3,14,-7,STAINED_GLASS:3)
Block(-2,14,-7,STAINED_GLASS:15)
Block(-1,14,-7,STAINED_GLASS:15)
Block(-11,14,-6,STAINED_GLASS:15)
Block(-10,14,-6,STAINED_GLASS:15)
Block(-9,14,-6,STAINED_GLASS:15)
Block(-8,14,-6,STAINED_GLASS:3)
Block(-7,14,-6,STAINED_GLASS:10)
Block(-6,14,-6,STAINED_GLASS:10)
Block(-5,14,-6,SEA_LANTERN:0)
Block(-4,14,-6,PURPLE_GLAZED_TERRACOTTA:3)
Block(-3,14,-6,PURPLE_GLAZED_TERRACOTTA:3)
Block(-2,14,-6,STAINED_GLASS:3)
Block(-1,14,-6,STAINED_GLASS:15)
Block(-10,14,-5,STAINED_GLASS:15)
Block(-9,14,-5,STAINED_GLASS:3)
Block(-8,14,-5,STAINED_GLASS:10)
Block(-7,14,-5,STAINED_GLASS:10)
Block(-6,14,-5,SEA_LANTERN:0)
Block(-5,14,-5,SEA_LANTERN:0)
Block(-4,14,-5,SEA_LANTERN:0)
Block(-3,14,-5,PURPLE_GLAZED_TERRACOTTA:3)
Block(-2,14,-5,STAINED_GLASS:11)
Block(-1,14,-5,STAINED_GLASS:3)
Block(0,14,-5,STAINED_GLASS:15)
Block(-9,14,-4,STAINED_GLASS:3)
Block(-8,14,-4,STAINED_GLASS:3)
Block(-7,14,-4,STAINED_GLASS:10)
Block(-6,14,-4,STAINED_GLASS:10)
Block(-5,14,-4,SEA_LANTERN:0)
Block(-4,14,-4,STAINED_GLASS:10)
Block(-3,14,-4,PURPLE_GLAZED_TERRACOTTA:3)
Block(-2,14,-4,STAINED_GLASS:3)
Block(-1,14,-4,STAINED_GLASS:3)
Block(-9,14,-3,STAINED_GLASS:3)
Block(-8,14,-3,STAINED_GLASS:15)
Block(-7,14,-3,STAINED_GLASS:3)
Block(-6,14,-3,STAINED_GLASS:10)
Block(-5,14,-3,STAINED_GLASS:10)
Block(-4,14,-3,STAINED_GLASS:10)
Block(-3,14,-3,STAINED_GLASS:3)
Block(-2,14,-3,STAINED_GLASS:3)
Block(-1,14,-3,STAINED_GLASS:3)
Block(-8,14,-2,STAINED_GLASS:15)
Block(-7,14,-2,STAINED_GLASS:15)
Block(-6,14,-2,STAINED_GLASS:3)
Block(-5,14,-2,STAINED_GLASS:10)
Block(-4,14,-2,STAINED_GLASS:15)
Block(-3,14,-2,STAINED_GLASS:3)
Block(-2,14,-2,STAINED_GLASS:3)
Block(-7,14,-1,STAINED_GLASS:15)
Block(-6,14,-1,STAINED_GLASS:15)
Block(-5,14,-1,STAINED_GLASS:3)
Block(-4,14,-1,STAINED_GLASS:15)
Block(-3,14,-1,STAINED_GLASS:3)
Block(-5,14,0,STAINED_GLASS:15)
Block(-7,15,-11,STAINED_GLASS:3)
Block(-6,15,-11,STAINED_GLASS:15)
Block(-8,15,-10,STAINED_GLASS:3)
Block(-7,15,-10,STAINED_GLASS:3)
Block(-6,15,-10,STAINED_GLASS:3)
Block(-5,15,-10,STAINED_GLASS:15)
Block(-4,15,-10,STAINED_GLASS:15)
Block(-9,15,-9,STAINED_GLASS:15)
Block(-8,15,-9,STAINED_GLASS:3)
Block(-7,15,-9,STAINED_GLASS:3)
Block(-6,15,-9,STAINED_GLASS:3)
Block(-5,15,-9,STAINED_GLASS:3)
Block(-4,15,-9,STAINED_GLASS:15)
Block(-3,15,-9,STAINED_GLASS:15)
Block(-10,15,-8,STAINED_GLASS:15)
Block(-9,15,-8,STAINED_GLASS:3)
Block(-8,15,-8,STAINED_GLASS:15)
Block(-7,15,-8,STAINED_GLASS:3)
Block(-6,15,-8,STAINED_GLASS:10)
Block(-5,15,-8,STAINED_GLASS:10)
Block(-4,15,-8,STAINED_GLASS:15)
Block(-3,15,-8,STAINED_GLASS:15)
Block(-2,15,-8,STAINED_GLASS:15)
Block(-11,15,-7,STAINED_GLASS:15)
Block(-10,15,-7,STAINED_GLASS:3)
Block(-9,15,-7,STAINED_GLASS:15)
Block(-8,15,-7,STAINED_GLASS:3)
Block(-7,15,-7,STAINED_GLASS:10)
Block(-6,15,-7,STAINED_GLASS:10)
Block(-5,15,-7,STAINED_GLASS:10)
Block(-4,15,-7,STAINED_GLASS:11)
Block(-3,15,-7,STAINED_GLASS:3)
Block(-2,15,-7,STAINED_GLASS:3)
Block(-1,15,-7,STAINED_GLASS:3)
Block(-11,15,-6,STAINED_GLASS:15)
Block(-10,15,-6,STAINED_GLASS:15)
Block(-9,15,-6,STAINED_GLASS:3)
Block(-8,15,-6,STAINED_GLASS:10)
Block(-7,15,-6,STAINED_GLASS:10)
Block(-6,15,-6,SEA_LANTERN:0)
Block(-5,15,-6,SEA_LANTERN:0)
Block(-4,15,-6,STAINED_GLASS:11)
Block(-3,15,-6,STAINED_GLASS:11)
Block(-2,15,-6,STAINED_GLASS:3)
Block(-1,15,-6,STAINED_GLASS:3)
Block(-10,15,-5,STAINED_GLASS:3)
Block(-9,15,-5,STAINED_GLASS:3)
Block(-8,15,-5,STAINED_GLASS:10)
Block(-7,15,-5,STAINED_GLASS:10)
Block(-6,15,-5,SEA_LANTERN:0)
Block(-5,15,-5,SEA_LANTERN:0)
Block(-4,15,-5,STAINED_GLASS:10)
Block(-3,15,-5,PURPLE_GLAZED_TERRACOTTA:3)
Block(-2,15,-5,STAINED_GLASS:3)
Block(-1,15,-5,STAINED_GLASS:3)
Block(-10,15,-4,STAINED_GLASS:3)
Block(-9,15,-4,STAINED_GLASS:3)
Block(-8,15,-4,STAINED_GLASS:3)
Block(-7,15,-4,STAINED_GLASS:10)
Block(-6,15,-4,STAINED_GLASS:10)
Block(-5,15,-4,STAINED_GLASS:10)
Block(-4,15,-4,STAINED_GLASS:10)
Block(-3,15,-4,STAINED_GLASS:3)
Block(-2,15,-4,STAINED_GLASS:3)
Block(-9,15,-3,STAINED_GLASS:15)
Block(-8,15,-3,STAINED_GLASS:15)
Block(-7,15,-3,STAINED_GLASS:15)
Block(-6,15,-3,STAINED_GLASS:10)
Block(-5,15,-3,STAINED_GLASS:10)
Block(-4,15,-3,STAINED_GLASS:3)
Block(-3,15,-3,STAINED_GLASS:3)
Block(-2,15,-3,STAINED_GLASS:3)
Block(-8,15,-2,STAINED_GLASS:15)
Block(-7,15,-2,STAINED_GLASS:15)
Block(-6,15,-2,STAINED_GLASS:15)
Block(-5,15,-2,STAINED_GLASS:15)
Block(-4,15,-2,STAINED_GLASS:15)
Block(-3,15,-2,STAINED_GLASS:3)
Block(-7,15,-1,STAINED_GLASS:15)
Block(-6,15,-1,STAINED_GLASS:15)
Block(-5,15,-1,STAINED_GLASS:15)
Block(-7,16,-12,STAINED_GLASS:3)
Block(-8,16,-11,STAINED_GLASS:3)
Block(-7,16,-11,STAINED_GLASS:3)
Block(-6,16,-11,STAINED_GLASS:3)
Block(-9,16,-10,STAINED_GLASS:3)
Block(-8,16,-10,STAINED_GLASS:3)
Block(-7,16,-10,STAINED_GLASS:3)
Block(-6,16,-10,STAINED_GLASS:3)
Block(-5,16,-10,STAINED_GLASS:15)
Block(-4,16,-10,STAINED_GLASS:15)
Block(-10,16,-9,STAINED_GLASS:15)
Block(-9,16,-9,STAINED_GLASS:3)
Block(-8,16,-9,STAINED_GLASS:3)
Block(-7,16,-9,STAINED_GLASS:3)
Block(-6,16,-9,STAINED_GLASS:11)
Block(-5,16,-9,STAINED_GLASS:3)
Block(-4,16,-9,STAINED_GLASS:15)
Block(-3,16,-9,STAINED_GLASS:15)
Block(-11,16,-8,STAINED_GLASS:15)
Block(-10,16,-8,STAINED_GLASS:3)
Block(-9,16,-8,STAINED_GLASS:15)
Block(-8,16,-8,STAINED_GLASS:3)
Block(-7,16,-8,PURPLE_GLAZED_TERRACOTTA:3)
Block(-6,16,-8,STAINED_GLASS:10)
Block(-5,16,-8,STAINED_GLASS:10)
Block(-4,16,-8,STAINED_GLASS:3)
Block(-3,16,-8,STAINED_GLASS:15)
Block(-2,16,-8,STAINED_GLASS:3)
Block(-12,16,-7,STAINED_GLASS:15)
Block(-11,16,-7,STAINED_GLASS:15)
Block(-10,16,-7,STAINED_GLASS:15)
Block(-9,16,-7,STAINED_GLASS:3)
Block(-8,16,-7,STAINED_GLASS:10)
Block(-7,16,-7,STAINED_GLASS:10)
Block(-6,16,-7,SEA_LANTERN:0)
Block(-5,16,-7,STAINED_GLASS:10)
Block(-4,16,-7,STAINED_GLASS:10)
Block(-3,16,-7,STAINED_GLASS:3)
Block(-2,16,-7,STAINED_GLASS:3)
Block(-11,16,-6,STAINED_GLASS:15)
Block(-10,16,-6,STAINED_GLASS:3)
Block(-9,16,-6,STAINED_GLASS:10)
Block(-8,16,-6,STAINED_GLASS:10)
Block(-7,16,-6,SEA_LANTERN:0)
Block(-6,16,-6,SEA_LANTERN:0)
Block(-5,16,-6,SEA_LANTERN:0)
Block(-4,16,-6,STAINED_GLASS:10)
Block(-3,16,-6,STAINED_GLASS:10)
Block(-2,16,-6,STAINED_GLASS:3)
Block(-1,16,-6,STAINED_GLASS:3)
Block(-10,16,-5,STAINED_GLASS:3)
Block(-9,16,-5,STAINED_GLASS:3)
Block(-8,16,-5,STAINED_GLASS:10)
Block(-7,16,-5,STAINED_GLASS:10)
Block(-6,16,-5,SEA_LANTERN:0)
Block(-5,16,-5,STAINED_GLASS:10)
Block(-4,16,-5,STAINED_GLASS:10)
Block(-3,16,-5,STAINED_GLASS:3)
Block(-2,16,-5,STAINED_GLASS:3)
Block(-10,16,-4,STAINED_GLASS:3)
Block(-9,16,-4,STAINED_GLASS:3)
Block(-8,16,-4,STAINED_GLASS:15)
Block(-7,16,-4,STAINED_GLASS:10)
Block(-6,16,-4,STAINED_GLASS:10)
Block(-5,16,-4,STAINED_GLASS:10)
Block(-4,16,-4,STAINED_GLASS:15)
Block(-3,16,-4,STAINED_GLASS:3)
Block(-2,16,-4,STAINED_GLASS:3)
Block(-9,16,-3,STAINED_GLASS:3)
Block(-8,16,-3,STAINED_GLASS:15)
Block(-7,16,-3,STAINED_GLASS:15)
Block(-6,16,-3,STAINED_GLASS:10)
Block(-5,16,-3,STAINED_GLASS:15)
Block(-4,16,-3,STAINED_GLASS:15)
Block(-3,16,-3,STAINED_GLASS:15)
Block(-8,16,-2,STAINED_GLASS:15)
Block(-7,16,-2,STAINED_GLASS:15)
Block(-6,16,-2,STAINED_GLASS:15)
Block(-5,16,-2,STAINED_GLASS:15)
Block(-4,16,-2,STAINED_GLASS:15)
Block(-6,16,-1,STAINED_GLASS:15)
Block(-8,17,-12,STAINED_GLASS:3)
Block(-7,17,-12,STAINED_GLASS:15)
Block(-9,17,-11,STAINED_GLASS:3)
Block(-8,17,-11,STAINED_GLASS:3)
Block(-7,17,-11,STAINED_GLASS:3)
Block(-6,17,-11,STAINED_GLASS:15)
Block(-5,17,-11,STAINED_GLASS:15)
Block(-10,17,-10,STAINED_GLASS:15)
Block(-9,17,-10,STAINED_GLASS:3)
Block(-8,17,-10,STAINED_GLASS:3)
Block(-7,17,-10,STAINED_GLASS:3)
Block(-6,17,-10,STAINED_GLASS:3)
Block(-5,17,-10,STAINED_GLASS:15)
Block(-4,17,-10,STAINED_GLASS:15)
Block(-11,17,-9,STAINED_GLASS:15)
Block(-10,17,-9,STAINED_GLASS:3)
Block(-9,17,-9,STAINED_GLASS:15)
Block(-8,17,-9,STAINED_GLASS:3)
Block(-7,17,-9,PURPLE_GLAZED_TERRACOTTA:3)
Block(-6,17,-9,STAINED_GLASS:11)
Block(-5,17,-9,STAINED_GLASS:15)
Block(-4,17,-9,STAINED_GLASS:3)
Block(-3,17,-9,STAINED_GLASS:3)
Block(-12,17,-8,STAINED_GLASS:15)
Block(-11,17,-8,STAINED_GLASS:3)
Block(-10,17,-8,STAINED_GLASS:15)
Block(-9,17,-8,STAINED_GLASS:3)
Block(-8,17,-8,PURPLE_GLAZED_TERRACOTTA:3)
Block(-7,17,-8,PURPLE_GLAZED_TERRACOTTA:3)
Block(-6,17,-8,STAINED_GLASS:11)
Block(-5,17,-8,STAINED_GLASS:10)
Block(-4,17,-8,STAINED_GLASS:3)
Block(-3,17,-8,STAINED_GLASS:3)
Block(-2,17,-8,STAINED_GLASS:3)
Block(-12,17,-7,STAINED_GLASS:15)
Block(-11,17,-7,STAINED_GLASS:15)
Block(-10,17,-7,STAINED_GLASS:3)
Block(-9,17,-7,STAINED_GLASS:10)
Block(-8,17,-7,STAINED_GLASS:10)
Block(-7,17,-7,SEA_LANTERN:0)
Block(-6,17,-7,SEA_LANTERN:0)
Block(-5,17,-7,STAINED_GLASS:10)
Block(-4,17,-7,STAINED_GLASS:10)
Block(-3,17,-7,STAINED_GLASS:3)
Block(-2,17,-7,STAINED_GLASS:3)
Block(-11,17,-6,STAINED_GLASS:15)
Block(-10,17,-6,STAINED_GLASS:3)
Block(-9,17,-6,STAINED_GLASS:10)
Block(-8,17,-6,STAINED_GLASS:10)
Block(-7,17,-6,SEA_LANTERN:0)
Block(-6,17,-6,SEA_LANTERN:0)
Block(-5,17,-6,STAINED_GLASS:10)
Block(-4,17,-6,STAINED_GLASS:10)
Block(-3,17,-6,STAINED_GLASS:3)
Block(-2,17,-6,STAINED_GLASS:3)
Block(-11,17,-5,STAINED_GLASS:15)
Block(-10,17,-5,STAINED_GLASS:3)
Block(-9,17,-5,STAINED_GLASS:3)
Block(-8,17,-5,STAINED_GLASS:10)
Block(-7,17,-5,STAINED_GLASS:10)
Block(-6,17,-5,STAINED_GLASS:10)
Block(-5,17,-5,STAINED_GLASS:10)
Block(-4,17,-5,STAINED_GLASS:3)
Block(-3,17,-5,STAINED_GLASS:15)
Block(-10,17,-4,STAINED_GLASS:3)
Block(-9,17,-4,STAINED_GLASS:3)
Block(-8,17,-4,STAINED_GLASS:3)
Block(-7,17,-4,STAINED_GLASS:10)
Block(-6,17,-4,STAINED_GLASS:10)
Block(-5,17,-4,STAINED_GLASS:15)
Block(-4,17,-4,STAINED_GLASS:15)
Block(-3,17,-4,STAINED_GLASS:15)
Block(-9,17,-3,STAINED_GLASS:15)
Block(-8,17,-3,STAINED_GLASS:15)
Block(-7,17,-3,STAINED_GLASS:3)
Block(-6,17,-3,STAINED_GLASS:15)
Block(-5,17,-3,STAINED_GLASS:15)
Block(-4,17,-3,STAINED_GLASS:15)
Block(-8,17,-2,STAINED_GLASS:15)
Block(-7,17,-2,STAINED_GLASS:15)
Block(-6,17,-2,STAINED_GLASS:15)
Block(-8,18,-13,STAINED_GLASS:3)
Block(-9,18,-12,STAINED_GLASS:3)
Block(-8,18,-12,STAINED_GLASS:3)
Block(-7,18,-12,STAINED_GLASS:3)
Block(-10,18,-11,STAINED_GLASS:3)
Block(-9,18,-11,STAINED_GLASS:3)
Block(-8,18,-11,STAINED_GLASS:3)
Block(-7,18,-11,STAINED_GLASS:3)
Block(-6,18,-11,STAINED_GLASS:3)
Block(-5,18,-11,STAINED_GLASS:3)
Block(-11,18,-10,STAINED_GLASS:15)
Block(-10,18,-10,STAINED_GLASS:3)
Block(-9,18,-10,STAINED_GLASS:3)
Block(-8,18,-10,STAINED_GLASS:3)
Block(-7,18,-10,PURPLE_GLAZED_TERRACOTTA:3)
Block(-6,18,-10,STAINED_GLASS:3)
Block(-5,18,-10,STAINED_GLASS:3)
Block(-4,18,-10,STAINED_GLASS:3)
Block(-12,18,-9,STAINED_GLASS:15)
Block(-11,18,-9,STAINED_GLASS:3)
Block(-10,18,-9,STAINED_GLASS:15)
Block(-9,18,-9,STAINED_GLASS:3)
Block(-8,18,-9,PURPLE_GLAZED_TERRACOTTA:3)
Block(-7,18,-9,PURPLE_GLAZED_TERRACOTTA:3)
Block(-6,18,-9,STAINED_GLASS:11)
Block(-5,18,-9,STAINED_GLASS:3)
Block(-4,18,-9,STAINED_GLASS:3)
Block(-3,18,-9,STAINED_GLASS:3)
Block(-13,18,-8,STAINED_GLASS:15)
Block(-12,18,-8,STAINED_GLASS:3)
Block(-11,18,-8,STAINED_GLASS:15)
Block(-10,18,-8,STAINED_GLASS:3)
Block(-9,18,-8,PURPLE_GLAZED_TERRACOTTA:3)
Block(-8,18,-8,PURPLE_GLAZED_TERRACOTTA:3)
Block(-7,18,-8,SEA_LANTERN:0)
Block(-6,18,-8,STAINED_GLASS:11)
Block(-5,18,-8,STAINED_GLASS:11)
Block(-4,18,-8,STAINED_GLASS:3)
Block(-3,18,-8,STAINED_GLASS:3)
Block(-12,18,-7,STAINED_GLASS:15)
Block(-11,18,-7,STAINED_GLASS:3)
Block(-10,18,-7,STAINED_GLASS:10)
Block(-9,18,-7,STAINED_GLASS:10)
Block(-8,18,-7,SEA_LANTERN:0)
Block(-7,18,-7,SEA_LANTERN:0)
Block(-6,18,-7,SEA_LANTERN:0)
Block(-5,18,-7,STAINED_GLASS:10)
Block(-4,18,-7,STAINED_GLASS:10)
Block(-3,18,-7,STAINED_GLASS:3)
Block(-2,18,-7,STAINED_GLASS:3)
Block(-11,18,-6,STAINED_GLASS:15)
Block(-10,18,-6,STAINED_GLASS:3)
Block(-9,18,-6,STAINED_GLASS:10)
Block(-8,18,-6,STAINED_GLASS:10)
Block(-7,18,-6,SEA_LANTERN:0)
Block(-6,18,-6,STAINED_GLASS:10)
Block(-5,18,-6,STAINED_GLASS:10)
Block(-4,18,-6,STAINED_GLASS:3)
Block(-3,18,-6,STAINED_GLASS:15)
Block(-11,18,-5,STAINED_GLASS:15)
Block(-10,18,-5,STAINED_GLASS:3)
Block(-9,18,-5,STAINED_GLASS:3)
Block(-8,18,-5,STAINED_GLASS:10)
Block(-7,18,-5,STAINED_GLASS:10)
Block(-6,18,-5,STAINED_GLASS:10)
Block(-5,18,-5,STAINED_GLASS:15)
Block(-4,18,-5,STAINED_GLASS:3)
Block(-3,18,-5,STAINED_GLASS:15)
Block(-10,18,-4,STAINED_GLASS:3)
Block(-9,18,-4,STAINED_GLASS:3)
Block(-8,18,-4,STAINED_GLASS:3)
Block(-7,18,-4,STAINED_GLASS:10)
Block(-6,18,-4,STAINED_GLASS:15)
Block(-5,18,-4,STAINED_GLASS:15)
Block(-4,18,-4,STAINED_GLASS:15)
Block(-9,18,-3,STAINED_GLASS:15)
Block(-8,18,-3,STAINED_GLASS:15)
Block(-7,18,-3,STAINED_GLASS:15)
Block(-6,18,-3,STAINED_GLASS:15)
Block(-5,18,-3,STAINED_GLASS:15)
Block(-7,18,-2,STAINED_GLASS:15)
Block(-9,19,-13,STAINED_GLASS:3)
Block(-8,19,-13,STAINED_GLASS:3)
Block(-10,19,-12,STAINED_GLASS:3)
Block(-9,19,-12,STAINED_GLASS:3)
Block(-8,19,-12,STAINED_GLASS:3)
Block(-7,19,-12,STAINED_GLASS:3)
Block(-6,19,-12,STAINED_GLASS:3)
Block(-11,19,-11,STAINED_GLASS:3)
Block(-10,19,-11,STAINED_GLASS:3)
Block(-9,19,-11,STAINED_GLASS:3)
Block(-8,19,-11,STAINED_GLASS:3)
Block(-7,19,-11,STAINED_GLASS:3)
Block(-6,19,-11,STAINED_GLASS:3)
Block(-5,19,-11,STAINED_GLASS:3)
Block(-12,19,-10,STAINED_GLASS:3)
Block(-11,19,-10,STAINED_GLASS:3)
Block(-10,19,-10,STAINED_GLASS:3)
Block(-9,19,-10,STAINED_GLASS:3)
Block(-8,19,-10,PURPLE_GLAZED_TERRACOTTA:3)
Block(-7,19,-10,PURPLE_GLAZED_TERRACOTTA:3)
Block(-6,19,-10,STAINED_GLASS:3)
Block(-5,19,-10,STAINED_GLASS:3)
Block(-4,19,-10,STAINED_GLASS:3)
Block(-13,19,-9,STAINED_GLASS:15)
Block(-12,19,-9,STAINED_GLASS:3)
Block(-11,19,-9,STAINED_GLASS:3)
Block(-10,19,-9,STAINED_GLASS:3)
Block(-9,19,-9,PURPLE_GLAZED_TERRACOTTA:3)
Block(-8,19,-9,PURPLE_GLAZED_TERRACOTTA:3)
Block(-7,19,-9,PURPLE_GLAZED_TERRACOTTA:3)
Block(-6,19,-9,STAINED_GLASS:11)
Block(-5,19,-9,STAINED_GLASS:3)
Block(-4,19,-9,STAINED_GLASS:3)
Block(-3,19,-9,STAINED_GLASS:3)
Block(-13,19,-8,STAINED_GLASS:15)
Block(-12,19,-8,STAINED_GLASS:15)
Block(-11,19,-8,STAINED_GLASS:3)
Block(-10,19,-8,STAINED_GLASS:10)
Block(-9,19,-8,STAINED_GLASS:10)
Block(-8,19,-8,SEA_LANTERN:0)
Block(-7,19,-8,SEA_LANTERN:0)
Block(-6,19,-8,STAINED_GLASS:11)
Block(-5,19,-8,STAINED_GLASS:10)
Block(-4,19,-8,STAINED_GLASS:3)
Block(-3,19,-8,STAINED_GLASS:3)
Block(-12,19,-7,STAINED_GLASS:15)
Block(-11,19,-7,STAINED_GLASS:3)
Block(-10,19,-7,STAINED_GLASS:10)
Block(-9,19,-7,STAINED_GLASS:10)
Block(-8,19,-7,SEA_LANTERN:0)
Block(-7,19,-7,SEA_LANTERN:0)
Block(-6,19,-7,STAINED_GLASS:10)
Block(-5,19,-7,STAINED_GLASS:10)
Block(-4,19,-7,STAINED_GLASS:3)
Block(-3,19,-7,STAINED_GLASS:15)
Block(-12,19,-6,STAINED_GLASS:15)
Block(-11,19,-6,STAINED_GLASS:15)
Block(-10,19,-6,STAINED_GLASS:3)
Block(-9,19,-6,STAINED_GLASS:10)
Block(-8,19,-6,STAINED_GLASS:10)
Block(-7,19,-6,STAINED_GLASS:10)
Block(-6,19,-6,STAINED_GLASS:10)
Block(-5,19,-6,STAINED_GLASS:15)
Block(-4,19,-6,STAINED_GLASS:15)
Block(-11,19,-5,STAINED_GLASS:3)
Block(-10,19,-5,STAINED_GLASS:3)
Block(-9,19,-5,STAINED_GLASS:3)
Block(-8,19,-5,STAINED_GLASS:10)
Block(-7,19,-5,STAINED_GLASS:10)
Block(-6,19,-5,STAINED_GLASS:15)
Block(-5,19,-5,STAINED_GLASS:15)
Block(-4,19,-5,STAINED_GLASS:15)
Block(-10,19,-4,STAINED_GLASS:3)
Block(-9,19,-4,STAINED_GLASS:3)
Block(-8,19,-4,STAINED_GLASS:15)
Block(-7,19,-4,STAINED_GLASS:15)
Block(-6,19,-4,STAINED_GLASS:15)
Block(-5,19,-4,STAINED_GLASS:15)
Block(-9,19,-3,STAINED_GLASS:3)
Block(-8,19,-3,STAINED_GLASS:15)
Block(-7,19,-3,STAINED_GLASS:15)
Block(-9,20,-14,STAINED_GLASS:15)
Block(-10,20,-13,STAINED_GLASS:3)
Block(-9,20,-13,STAINED_GLASS:3)
Block(-8,20,-13,STAINED_GLASS:15)
Block(-11,20,-12,STAINED_GLASS:3)
Block(-10,20,-12,STAINED_GLASS:3)
Block(-9,20,-12,STAINED_GLASS:3)
Block(-8,20,-12,STAINED_GLASS:3)
Block(-7,20,-12,STAINED_GLASS:3)
Block(-6,20,-12,STAINED_GLASS:3)
Block(-12,20,-11,STAINED_GLASS:3)
Block(-11,20,-11,STAINED_GLASS:3)
Block(-10,20,-11,STAINED_GLASS:3)
Block(-9,20,-11,STAINED_GLASS:3)
Block(-8,20,-11,PURPLE_GLAZED_TERRACOTTA:3)
Block(-7,20,-11,STAINED_GLASS:3)
Block(-6,20,-11,STAINED_GLASS:3)
Block(-5,20,-11,STAINED_GLASS:3)
Block(-13,20,-10,STAINED_GLASS:3)
Block(-12,20,-10,STAINED_GLASS:3)
Block(-11,20,-10,STAINED_GLASS:3)
Block(-10,20,-10,STAINED_GLASS:3)
Block(-9,20,-10,PURPLE_GLAZED_TERRACOTTA:3)
Block(-8,20,-10,PURPLE_GLAZED_TERRACOTTA:3)
Block(-7,20,-10,PURPLE_GLAZED_TERRACOTTA:3)
Block(-6,20,-10,STAINED_GLASS:3)
Block(-5,20,-10,STAINED_GLASS:3)
Block(-4,20,-10,STAINED_GLASS:3)
Block(-14,20,-9,STAINED_GLASS:3)
Block(-13,20,-9,STAINED_GLASS:3)
Block(-12,20,-9,STAINED_GLASS:3)
Block(-11,20,-9,STAINED_GLASS:3)
Block(-10,20,-9,STAINED_GLASS:10)
Block(-9,20,-9,PURPLE_GLAZED_TERRACOTTA:3)
Block(-8,20,-9,SEA_LANTERN:0)
Block(-7,20,-9,PURPLE_GLAZED_TERRACOTTA:3)
Block(-6,20,-9,PURPLE_GLAZED_TERRACOTTA:3)
Block(-5,20,-9,STAINED_GLASS:3)
Block(-4,20,-9,STAINED_GLASS:3)
Block(-13,20,-8,STAINED_GLASS:3)
Block(-12,20,-8,STAINED_GLASS:3)
Block(-11,20,-8,STAINED_GLASS:10)
Block(-10,20,-8,STAINED_GLASS:10)
Block(-9,20,-8,SEA_LANTERN:0)
Block(-8,20,-8,SEA_LANTERN:0)
Block(-7,20,-8,SEA_LANTERN:0)
Block(-6,20,-8,STAINED_GLASS:10)
Block(-5,20,-8,STAINED_GLASS:10)
Block(-4,20,-8,STAINED_GLASS:3)
Block(-3,20,-8,STAINED_GLASS:15)
Block(-12,20,-7,STAINED_GLASS:15)
Block(-11,20,-7,STAINED_GLASS:3)
Block(-10,20,-7,STAINED_GLASS:10)
Block(-9,20,-7,STAINED_GLASS:10)
Block(-8,20,-7,SEA_LANTERN:0)
Block(-7,20,-7,STAINED_GLASS:10)
Block(-6,20,-7,STAINED_GLASS:10)
Block(-5,20,-7,STAINED_GLASS:15)
Block(-4,20,-7,STAINED_GLASS:15)
Block(-12,20,-6,STAINED_GLASS:15)
Block(-11,20,-6,STAINED_GLASS:15)
Block(-10,20,-6,STAINED_GLASS:3)
Block(-9,20,-6,STAINED_GLASS:10)
Block(-8,20,-6,STAINED_GLASS:10)
Block(-7,20,-6,STAINED_GLASS:10)
Block(-6,20,-6,STAINED_GLASS:15)
Block(-5,20,-6,STAINED_GLASS:15)
Block(-4,20,-6,STAINED_GLASS:15)
Block(-11,20,-5,STAINED_GLASS:3)
Block(-10,20,-5,STAINED_GLASS:3)
Block(-9,20,-5,STAINED_GLASS:3)
Block(-8,20,-5,STAINED_GLASS:10)
Block(-7,20,-5,STAINED_GLASS:15)
Block(-6,20,-5,STAINED_GLASS:15)
Block(-5,20,-5,STAINED_GLASS:15)
Block(-10,20,-4,STAINED_GLASS:3)
Block(-9,20,-4,STAINED_GLASS:3)
Block(-8,20,-4,STAINED_GLASS:15)
Block(-7,20,-4,STAINED_GLASS:15)
Block(-6,20,-4,STAINED_GLASS:15)
Block(-8,20,-3,STAINED_GLASS:15)
Block(-10,21,-14,STAINED_GLASS:15)
Block(-9,21,-14,STAINED_GLASS:15)
Block(-11,21,-13,STAINED_GLASS:15)
Block(-10,21,-13,STAINED_GLASS:3)
Block(-9,21,-13,STAINED_GLASS:15)
Block(-8,21,-13,STAINED_GLASS:3)
Block(-7,21,-13,STAINED_GLASS:3)
Block(-12,21,-12,STAINED_GLASS:3)
Block(-11,21,-12,STAINED_GLASS:3)
Block(-10,21,-12,STAINED_GLASS:15)
Block(-9,21,-12,STAINED_GLASS:3)
Block(-8,21,-12,STAINED_GLASS:3)
Block(-7,21,-12,STAINED_GLASS:3)
Block(-6,21,-12,STAINED_GLASS:3)
Block(-13,21,-11,STAINED_GLASS:3)
Block(-12,21,-11,STAINED_GLASS:3)
Block(-11,21,-11,STAINED_GLASS:3)
Block(-10,21,-11,STAINED_GLASS:3)
Block(-9,21,-11,PURPLE_GLAZED_TERRACOTTA:3)
Block(-8,21,-11,PURPLE_GLAZED_TERRACOTTA:3)
Block(-7,21,-11,STAINED_GLASS:3)
Block(-6,21,-11,STAINED_GLASS:3)
Block(-5,21,-11,STAINED_GLASS:3)
Block(-14,21,-10,STAINED_GLASS:3)
Block(-13,21,-10,STAINED_GLASS:3)
Block(-12,21,-10,STAINED_GLASS:3)
Block(-11,21,-10,STAINED_GLASS:3)
Block(-10,21,-10,STAINED_GLASS:10)
Block(-9,21,-10,PURPLE_GLAZED_TERRACOTTA:3)
Block(-8,21,-10,PURPLE_GLAZED_TERRACOTTA:3)
Block(-7,21,-10,PURPLE_GLAZED_TERRACOTTA:3)
Block(-6,21,-10,STAINED_GLASS:3)
Block(-5,21,-10,STAINED_GLASS:3)
Block(-4,21,-10,STAINED_GLASS:15)
Block(-14,21,-9,STAINED_GLASS:3)
Block(-13,21,-9,STAINED_GLASS:3)
Block(-12,21,-9,STAINED_GLASS:3)
Block(-11,21,-9,STAINED_GLASS:10)
Block(-10,21,-9,STAINED_GLASS:10)
Block(-9,21,-9,SEA_LANTERN:0)
Block(-8,21,-9,SEA_LANTERN:0)
Block(-7,21,-9,PURPLE_GLAZED_TERRACOTTA:3)
Block(-6,21,-9,PURPLE_GLAZED_TERRACOTTA:3)
Block(-5,21,-9,STAINED_GLASS:3)
Block(-4,21,-9,STAINED_GLASS:15)
Block(-13,21,-8,STAINED_GLASS:3)
Block(-12,21,-8,STAINED_GLASS:3)
Block(-11,21,-8,STAINED_GLASS:10)
Block(-10,21,-8,STAINED_GLASS:10)
Block(-9,21,-8,SEA_LANTERN:0)
Block(-8,21,-8,SEA_LANTERN:0)
Block(-7,21,-8,STAINED_GLASS:10)
Block(-6,21,-8,STAINED_GLASS:10)
Block(-5,21,-8,STAINED_GLASS:3)
Block(-4,21,-8,STAINED_GLASS:15)
Block(-13,21,-7,STAINED_GLASS:15)
Block(-12,21,-7,STAINED_GLASS:3)
Block(-11,21,-7,STAINED_GLASS:3)
Block(-10,21,-7,STAINED_GLASS:10)
Block(-9,21,-7,STAINED_GLASS:10)
Block(-8,21,-7,STAINED_GLASS:10)
Block(-7,21,-7,STAINED_GLASS:10)
Block(-6,21,-7,STAINED_GLASS:15)
Block(-5,21,-7,STAINED_GLASS:15)
Block(-12,21,-6,STAINED_GLASS:15)
Block(-11,21,-6,STAINED_GLASS:3)
Block(-10,21,-6,STAINED_GLASS:3)
Block(-9,21,-6,STAINED_GLASS:10)
Block(-8,21,-6,STAINED_GLASS:10)
Block(-7,21,-6,STAINED_GLASS:15)
Block(-6,21,-6,STAINED_GLASS:15)
Block(-5,21,-6,STAINED_GLASS:15)
Block(-11,21,-5,STAINED_GLASS:3)
Block(-10,21,-5,STAINED_GLASS:3)
Block(-9,21,-5,STAINED_GLASS:3)
Block(-8,21,-5,STAINED_GLASS:15)
Block(-7,21,-5,STAINED_GLASS:15)
Block(-6,21,-5,STAINED_GLASS:15)
Block(-10,21,-4,STAINED_GLASS:3)
Block(-9,21,-4,STAINED_GLASS:3)
Block(-8,21,-4,STAINED_GLASS:3)
Block(-10,22,-15,STAINED_GLASS:15)
Block(-11,22,-14,STAINED_GLASS:15)
Block(-10,22,-14,STAINED_GLASS:3)
Block(-9,22,-14,STAINED_GLASS:15)
Block(-12,22,-13,STAINED_GLASS:15)
Block(-11,22,-13,STAINED_GLASS:3)
Block(-10,22,-13,STAINED_GLASS:15)
Block(-9,22,-13,STAINED_GLASS:3)
Block(-8,22,-13,STAINED_GLASS:3)
Block(-7,22,-13,STAINED_GLASS:3)
Block(-13,22,-12,STAINED_GLASS:3)
Block(-12,22,-12,STAINED_GLASS:3)
Block(-11,22,-12,STAINED_GLASS:15)
Block(-10,22,-12,STAINED_GLASS:3)
Block(-9,22,-12,PURPLE_GLAZED_TERRACOTTA:3)
Block(-8,22,-12,STAINED_GLASS:3)
Block(-7,22,-12,STAINED_GLASS:3)
Block(-6,22,-12,STAINED_GLASS:3)
Block(-14,22,-11,STAINED_GLASS:3)
Block(-13,22,-11,STAINED_GLASS:3)
Block(-12,22,-11,STAINED_GLASS:3)
Block(-11,22,-11,STAINED_GLASS:3)
Block(-10,22,-11,STAINED_GLASS:10)
Block(-9,22,-11,STAINED_GLASS:10)
Block(-8,22,-11,PURPLE_GLAZED_TERRACOTTA:3)
Block(-7,22,-11,STAINED_GLASS:3)
Block(-6,22,-11,STAINED_GLASS:3)
Block(-5,22,-11,STAINED_GLASS:3)
Block(-15,22,-10,STAINED_GLASS:15)
Block(-14,22,-10,STAINED_GLASS:3)
Block(-13,22,-10,STAINED_GLASS:3)
Block(-12,22,-10,STAINED_GLASS:3)
Block(-11,22,-10,STAINED_GLASS:10)
Block(-10,22,-10,STAINED_GLASS:10)
Block(-9,22,-10,SEA_LANTERN:0)
Block(-8,22,-10,STAINED_GLASS:10)
Block(-7,22,-10,PURPLE_GLAZED_TERRACOTTA:3)
Block(-6,22,-10,STAINED_GLASS:3)
Block(-5,22,-10,STAINED_GLASS:15)
Block(-14,22,-9,STAINED_GLASS:15)
Block(-13,22,-9,STAINED_GLASS:3)
Block(-12,22,-9,STAINED_GLASS:10)
Block(-11,22,-9,STAINED_GLASS:10)
Block(-10,22,-9,SEA_LANTERN:0)
Block(-9,22,-9,SEA_LANTERN:0)
Block(-8,22,-9,SEA_LANTERN:0)
Block(-7,22,-9,STAINED_GLASS:10)
Block(-6,22,-9,STAINED_GLASS:10)
Block(-5,22,-9,STAINED_GLASS:3)
Block(-4,22,-9,STAINED_GLASS:15)
Block(-13,22,-8,STAINED_GLASS:3)
Block(-12,22,-8,STAINED_GLASS:3)
Block(-11,22,-8,STAINED_GLASS:10)
Block(-10,22,-8,STAINED_GLASS:10)
Block(-9,22,-8,SEA_LANTERN:0)
Block(-8,22,-8,STAINED_GLASS:10)
Block(-7,22,-8,STAINED_GLASS:10)
Block(-6,22,-8,STAINED_GLASS:15)
Block(-5,22,-8,STAINED_GLASS:3)
Block(-13,22,-7,STAINED_GLASS:15)
Block(-12,22,-7,STAINED_GLASS:15)
Block(-11,22,-7,STAINED_GLASS:3)
Block(-10,22,-7,STAINED_GLASS:10)
Block(-9,22,-7,STAINED_GLASS:10)
Block(-8,22,-7,STAINED_GLASS:10)
Block(-7,22,-7,STAINED_GLASS:15)
Block(-6,22,-7,STAINED_GLASS:15)
Block(-5,22,-7,STAINED_GLASS:15)
Block(-12,22,-6,STAINED_GLASS:15)
Block(-11,22,-6,STAINED_GLASS:3)
Block(-10,22,-6,STAINED_GLASS:3)
Block(-9,22,-6,STAINED_GLASS:10)
Block(-8,22,-6,STAINED_GLASS:3)
Block(-7,22,-6,STAINED_GLASS:15)
Block(-6,22,-6,STAINED_GLASS:15)
Block(-11,22,-5,STAINED_GLASS:3)
Block(-10,22,-5,STAINED_GLASS:3)
Block(-9,22,-5,STAINED_GLASS:3)
Block(-8,22,-5,STAINED_GLASS:3)
Block(-7,22,-5,STAINED_GLASS:15)
Block(-9,22,-4,STAINED_GLASS:3)
Block(-11,23,-15,STAINED_GLASS:15)
Block(-10,23,-15,STAINED_GLASS:15)
Block(-12,23,-14,STAINED_GLASS:15)
Block(-11,23,-14,STAINED_GLASS:3)
Block(-10,23,-14,STAINED_GLASS:15)
Block(-9,23,-14,STAINED_GLASS:15)
Block(-8,23,-14,STAINED_GLASS:3)
Block(-13,23,-13,STAINED_GLASS:15)
Block(-12,23,-13,STAINED_GLASS:3)
Block(-11,23,-13,STAINED_GLASS:15)
Block(-10,23,-13,STAINED_GLASS:3)
Block(-9,23,-13,STAINED_GLASS:3)
Block(-8,23,-13,STAINED_GLASS:3)
Block(-7,23,-13,STAINED_GLASS:3)
Block(-14,23,-12,STAINED_GLASS:15)
Block(-13,23,-12,STAINED_GLASS:3)
Block(-12,23,-12,STAINED_GLASS:15)
Block(-11,23,-12,STAINED_GLASS:3)
Block(-10,23,-12,STAINED_GLASS:10)
Block(-9,23,-12,STAINED_GLASS:10)
Block(-8,23,-12,STAINED_GLASS:3)
Block(-7,23,-12,STAINED_GLASS:3)
Block(-6,23,-12,STAINED_GLASS:3)
Block(-15,23,-11,STAINED_GLASS:15)
Block(-14,23,-11,STAINED_GLASS:3)
Block(-13,23,-11,STAINED_GLASS:15)
Block(-12,23,-11,STAINED_GLASS:3)
Block(-11,23,-11,STAINED_GLASS:10)
Block(-10,23,-11,STAINED_GLASS:10)
Block(-9,23,-11,STAINED_GLASS:10)
Block(-8,23,-11,STAINED_GLASS:10)
Block(-7,23,-11,STAINED_GLASS:3)
Block(-6,23,-11,STAINED_GLASS:3)
Block(-5,23,-11,STAINED_GLASS:15)
Block(-15,23,-10,STAINED_GLASS:3)
Block(-14,23,-10,STAINED_GLASS:15)
Block(-13,23,-10,STAINED_GLASS:3)
Block(-12,23,-10,STAINED_GLASS:10)
Block(-11,23,-10,STAINED_GLASS:10)
Block(-10,23,-10,SEA_LANTERN:0)
Block(-9,23,-10,SEA_LANTERN:0)
Block(-8,23,-10,STAINED_GLASS:10)
Block(-7,23,-10,STAINED_GLASS:10)
Block(-6,23,-10,STAINED_GLASS:3)
Block(-5,23,-10,STAINED_GLASS:15)
Block(-14,23,-9,STAINED_GLASS:3)
Block(-13,23,-9,STAINED_GLASS:3)
Block(-12,23,-9,STAINED_GLASS:10)
Block(-11,23,-9,STAINED_GLASS:10)
Block(-10,23,-9,SEA_LANTERN:0)
Block(-9,23,-9,SEA_LANTERN:0)
Block(-8,23,-9,STAINED_GLASS:10)
Block(-7,23,-9,STAINED_GLASS:10)
Block(-6,23,-9,STAINED_GLASS:15)
Block(-5,23,-9,STAINED_GLASS:15)
Block(-14,23,-8,STAINED_GLASS:3)
Block(-13,23,-8,STAINED_GLASS:3)
Block(-12,23,-8,STAINED_GLASS:3)
Block(-11,23,-8,STAINED_GLASS:10)
Block(-10,23,-8,STAINED_GLASS:10)
Block(-9,23,-8,STAINED_GLASS:10)
Block(-8,23,-8,STAINED_GLASS:10)
Block(-7,23,-8,STAINED_GLASS:15)
Block(-6,23,-8,STAINED_GLASS:15)
Block(-13,23,-7,STAINED_GLASS:3)
Block(-12,23,-7,STAINED_GLASS:3)
Block(-11,23,-7,STAINED_GLASS:15)
Block(-10,23,-7,STAINED_GLASS:10)
Block(-9,23,-7,STAINED_GLASS:10)
Block(-8,23,-7,STAINED_GLASS:3)
Block(-7,23,-7,STAINED_GLASS:15)
Block(-6,23,-7,STAINED_GLASS:15)
Block(-12,23,-6,STAINED_GLASS:15)
Block(-11,23,-6,STAINED_GLASS:15)
Block(-10,23,-6,STAINED_GLASS:3)
Block(-9,23,-6,STAINED_GLASS:3)
Block(-8,23,-6,STAINED_GLASS:3)
Block(-7,23,-6,STAINED_GLASS:15)
Block(-11,23,-5,STAINED_GLASS:15)
Block(-10,23,-5,STAINED_GLASS:15)
Block(-9,23,-5,STAINED_GLASS:3)
Block(-11,24,-16,STAINED_GLASS:15)
Block(-12,24,-15,STAINED_GLASS:15)
Block(-11,24,-15,STAINED_GLASS:3)
Block(-10,24,-15,STAINED_GLASS:15)
Block(-13,24,-14,STAINED_GLASS:15)
Block(-12,24,-14,STAINED_GLASS:3)
Block(-11,24,-14,STAINED_GLASS:15)
Block(-10,24,-14,STAINED_GLASS:3)
Block(-9,24,-14,STAINED_GLASS:15)
Block(-8,24,-14,STAINED_GLASS:3)
Block(-14,24,-13,STAINED_GLASS:15)
Block(-13,24,-13,STAINED_GLASS:3)
Block(-12,24,-13,STAINED_GLASS:15)
Block(-11,24,-13,STAINED_GLASS:3)
Block(-10,24,-13,STAINED_GLASS:10)
Block(-9,24,-13,STAINED_GLASS:3)
Block(-8,24,-13,STAINED_GLASS:3)
Block(-7,24,-13,STAINED_GLASS:3)
Block(-15,24,-12,STAINED_GLASS:15)
Block(-14,24,-12,STAINED_GLASS:3)
Block(-13,24,-12,STAINED_GLASS:15)
Block(-12,24,-12,STAINED_GLASS:3)
Block(-11,24,-12,STAINED_GLASS:10)
Block(-10,24,-12,STAINED_GLASS:10)
Block(-9,24,-12,STAINED_GLASS:10)
Block(-8,24,-12,STAINED_GLASS:3)
Block(-7,24,-12,STAINED_GLASS:3)
Block(-6,24,-12,STAINED_GLASS:3)
Block(-16,24,-11,STAINED_GLASS:15)
Block(-15,24,-11,STAINED_GLASS:3)
Block(-14,24,-11,STAINED_GLASS:15)
Block(-13,24,-11,STAINED_GLASS:3)
Block(-12,24,-11,STAINED_GLASS:10)
Block(-11,24,-11,STAINED_GLASS:10)
Block(-10,24,-11,SEA_LANTERN:0)
Block(-9,24,-11,STAINED_GLASS:10)
Block(-8,24,-11,STAINED_GLASS:10)
Block(-7,24,-11,STAINED_GLASS:3)
Block(-6,24,-11,STAINED_GLASS:15)
Block(-15,24,-10,STAINED_GLASS:15)
Block(-14,24,-10,STAINED_GLASS:3)
Block(-13,24,-10,STAINED_GLASS:10)
Block(-12,24,-10,STAINED_GLASS:10)
Block(-11,24,-10,SEA_LANTERN:0)
Block(-10,24,-10,SEA_LANTERN:0)
Block(-9,24,-10,SEA_LANTERN:0)
Block(-8,24,-10,STAINED_GLASS:10)
Block(-7,24,-10,STAINED_GLASS:10)
Block(-6,24,-10,STAINED_GLASS:3)
Block(-5,24,-10,STAINED_GLASS:15)
Block(-14,24,-9,STAINED_GLASS:3)
Block(-13,24,-9,STAINED_GLASS:3)
Block(-12,24,-9,STAINED_GLASS:10)
Block(-11,24,-9,STAINED_GLASS:10)
Block(-10,24,-9,SEA_LANTERN:0)
Block(-9,24,-9,STAINED_GLASS:10)
Block(-8,24,-9,STAINED_GLASS:10)
Block(-7,24,-9,STAINED_GLASS:3)
Block(-6,24,-9,STAINED_GLASS:3)
Block(-14,24,-8,STAINED_GLASS:3)
Block(-13,24,-8,STAINED_GLASS:3)
Block(-12,24,-8,STAINED_GLASS:3)
Block(-11,24,-8,STAINED_GLASS:10)
Block(-10,24,-8,STAINED_GLASS:10)
Block(-9,24,-8,STAINED_GLASS:10)
Block(-8,24,-8,STAINED_GLASS:3)
Block(-7,24,-8,STAINED_GLASS:3)
Block(-6,24,-8,STAINED_GLASS:3)
Block(-13,24,-7,STAINED_GLASS:3)
Block(-12,24,-7,STAINED_GLASS:15)
Block(-11,24,-7,STAINED_GLASS:15)
Block(-10,24,-7,STAINED_GLASS:10)
Block(-9,24,-7,STAINED_GLASS:3)
Block(-8,24,-7,STAINED_GLASS:3)
Block(-7,24,-7,STAINED_GLASS:3)
Block(-12,24,-6,STAINED_GLASS:15)
Block(-11,24,-6,STAINED_GLASS:15)
Block(-10,24,-6,STAINED_GLASS:3)
Block(-9,24,-6,STAINED_GLASS:3)
Block(-8,24,-6,STAINED_GLASS:3)
Block(-10,24,-5,STAINED_GLASS:3)
Block(-12,25,-16,STAINED_GLASS:15)
Block(-11,25,-16,STAINED_GLASS:15)
Block(-13,25,-15,STAINED_GLASS:15)
Block(-12,25,-15,STAINED_GLASS:3)
Block(-11,25,-15,STAINED_GLASS:15)
Block(-10,25,-15,STAINED_GLASS:15)
Block(-9,25,-15,STAINED_GLASS:3)
Block(-14,25,-14,STAINED_GLASS:15)
Block(-13,25,-14,STAINED_GLASS:3)
Block(-12,25,-14,STAINED_GLASS:15)
Block(-11,25,-14,STAINED_GLASS:3)
Block(-10,25,-14,STAINED_GLASS:3)
Block(-9,25,-14,STAINED_GLASS:3)
Block(-8,25,-14,STAINED_GLASS:3)
Block(-15,25,-13,STAINED_GLASS:15)
Block(-14,25,-13,STAINED_GLASS:3)
Block(-13,25,-13,STAINED_GLASS:15)
Block(-12,25,-13,STAINED_GLASS:3)
Block(-11,25,-13,STAINED_GLASS:10)
Block(-10,25,-13,STAINED_GLASS:10)
Block(-9,25,-13,STAINED_GLASS:3)
Block(-8,25,-13,STAINED_GLASS:3)
Block(-7,25,-13,STAINED_GLASS:3)
Block(-16,25,-12,STAINED_GLASS:15)
Block(-15,25,-12,STAINED_GLASS:3)
Block(-14,25,-12,STAINED_GLASS:15)
Block(-13,25,-12,STAINED_GLASS:3)
Block(-12,25,-12,STAINED_GLASS:10)
Block(-11,25,-12,STAINED_GLASS:10)
Block(-10,25,-12,STAINED_GLASS:10)
Block(-9,25,-12,STAINED_GLASS:10)
Block(-8,25,-12,STAINED_GLASS:3)
Block(-7,25,-12,STAINED_GLASS:3)
Block(-6,25,-12,STAINED_GLASS:15)
Block(-16,25,-11,STAINED_GLASS:3)
Block(-15,25,-11,STAINED_GLASS:15)
Block(-14,25,-11,STAINED_GLASS:3)
Block(-13,25,-11,STAINED_GLASS:10)
Block(-12,25,-11,STAINED_GLASS:10)
Block(-11,25,-11,SEA_LANTERN:0)
Block(-10,25,-11,SEA_LANTERN:0)
Block(-9,25,-11,STAINED_GLASS:10)
Block(-8,25,-11,STAINED_GLASS:10)
Block(-7,25,-11,STAINED_GLASS:3)
Block(-6,25,-11,STAINED_GLASS:15)
Block(-15,25,-10,STAINED_GLASS:3)
Block(-14,25,-10,STAINED_GLASS:3)
Block(-13,25,-10,STAINED_GLASS:10)
Block(-12,25,-10,STAINED_GLASS:10)
Block(-11,25,-10,SEA_LANTERN:0)
Block(-10,25,-10,SEA_LANTERN:0)
Block(-9,25,-10,STAINED_GLASS:10)
Block(-8,25,-10,STAINED_GLASS:10)
Block(-7,25,-10,STAINED_GLASS:3)
Block(-6,25,-10,STAINED_GLASS:3)
Block(-15,25,-9,STAINED_GLASS:3)
Block(-14,25,-9,STAINED_GLASS:15)
Block(-13,25,-9,STAINED_GLASS:3)
Block(-12,25,-9,STAINED_GLASS:10)
Block(-11,25,-9,STAINED_GLASS:10)
Block(-10,25,-9,STAINED_GLASS:10)
Block(-9,25,-9,STAINED_GLASS:10)
Block(-8,25,-9,STAINED_GLASS:3)
Block(-7,25,-9,STAINED_GLASS:3)
Block(-14,25,-8,STAINED_GLASS:15)
Block(-13,25,-8,STAINED_GLASS:15)
Block(-12,25,-8,STAINED_GLASS:3)
Block(-11,25,-8,STAINED_GLASS:10)
Block(-10,25,-8,STAINED_GLASS:10)
Block(-9,25,-8,STAINED_GLASS:3)
Block(-8,25,-8,STAINED_GLASS:3)
Block(-7,25,-8,STAINED_GLASS:3)
Block(-13,25,-7,STAINED_GLASS:15)
Block(-12,25,-7,STAINED_GLASS:15)
Block(-11,25,-7,STAINED_GLASS:15)
Block(-10,25,-7,STAINED_GLASS:3)
Block(-9,25,-7,STAINED_GLASS:3)
Block(-8,25,-7,STAINED_GLASS:3)
Block(-12,25,-6,STAINED_GLASS:15)
Block(-11,25,-6,STAINED_GLASS:15)
Block(-10,25,-6,STAINED_GLASS:3)
Block(-12,26,-16,STAINED_GLASS:15)
Block(-11,26,-16,STAINED_GLASS:15)
Block(-13,26,-15,STAINED_GLASS:15)
Block(-12,26,-15,STAINED_GLASS:3)
Block(-11,26,-15,STAINED_GLASS:15)
Block(-10,26,-15,STAINED_GLASS:15)
Block(-9,26,-15,STAINED_GLASS:3)
Block(-14,26,-14,STAINED_GLASS:15)
Block(-13,26,-14,STAINED_GLASS:3)
Block(-12,26,-14,STAINED_GLASS:15)
Block(-11,26,-14,STAINED_GLASS:3)
Block(-10,26,-14,STAINED_GLASS:3)
Block(-9,26,-14,STAINED_GLASS:3)
Block(-8,26,-14,STAINED_GLASS:3)
Block(-15,26,-13,STAINED_GLASS:15)
Block(-14,26,-13,STAINED_GLASS:3)
Block(-13,26,-13,STAINED_GLASS:15)
Block(-12,26,-13,STAINED_GLASS:3)
Block(-11,26,-13,STAINED_GLASS:10)
Block(-10,26,-13,STAINED_GLASS:10)
Block(-9,26,-13,STAINED_GLASS:3)
Block(-8,26,-13,STAINED_GLASS:3)
Block(-7,26,-13,STAINED_GLASS:3)
Block(-16,26,-12,STAINED_GLASS:15)
Block(-15,26,-12,STAINED_GLASS:3)
Block(-14,26,-12,STAINED_GLASS:15)
Block(-13,26,-12,STAINED_GLASS:3)
Block(-12,26,-12,STAINED_GLASS:10)
Block(-11,26,-12,SEA_LANTERN:0)
Block(-10,26,-12,PURPLE_GLAZED_TERRACOTTA:3)
Block(-9,26,-12,PURPLE_GLAZED_TERRACOTTA:3)
Block(-8,26,-12,STAINED_GLASS:3)
Block(-7,26,-12,STAINED_GLASS:3)
Block(-16,26,-11,STAINED_GLASS:3)
Block(-15,26,-11,STAINED_GLASS:15)
Block(-14,26,-11,STAINED_GLASS:3)
Block(-13,26,-11,STAINED_GLASS:10)
Block(-12,26,-11,SEA_LANTERN:0)
Block(-11,26,-11,SEA_LANTERN:0)
Block(-10,26,-11,SEA_LANTERN:0)
Block(-9,26,-11,PURPLE_GLAZED_TERRACOTTA:3)
Block(-8,26,-11,PURPLE_GLAZED_TERRACOTTA:3)
Block(-7,26,-11,STAINED_GLASS:3)
Block(-6,26,-11,STAINED_GLASS:3)
Block(-15,26,-10,STAINED_GLASS:3)
Block(-14,26,-10,STAINED_GLASS:3)
Block(-13,26,-10,STAINED_GLASS:10)
Block(-12,26,-10,STAINED_GLASS:10)
Block(-11,26,-10,SEA_LANTERN:0)
Block(-10,26,-10,PURPLE_GLAZED_TERRACOTTA:3)
Block(-9,26,-10,PURPLE_GLAZED_TERRACOTTA:3)
Block(-8,26,-10,STAINED_GLASS:3)
Block(-7,26,-10,STAINED_GLASS:3)
Block(-15,26,-9,STAINED_GLASS:15)
Block(-14,26,-9,STAINED_GLASS:15)
Block(-13,26,-9,STAINED_GLASS:15)
Block(-12,26,-9,STAINED_GLASS:10)
Block(-11,26,-9,STAINED_GLASS:10)
Block(-10,26,-9,STAINED_GLASS:10)
Block(-9,26,-9,STAINED_GLASS:15)
Block(-8,26,-9,STAINED_GLASS:3)
Block(-7,26,-9,STAINED_GLASS:3)
Block(-14,26,-8,STAINED_GLASS:15)
Block(-13,26,-8,STAINED_GLASS:15)
Block(-12,26,-8,STAINED_GLASS:15)
Block(-11,26,-8,STAINED_GLASS:10)
Block(-10,26,-8,STAINED_GLASS:3)
Block(-9,26,-8,STAINED_GLASS:3)
Block(-8,26,-8,STAINED_GLASS:3)
Block(-13,26,-7,STAINED_GLASS:15)
Block(-12,26,-7,STAINED_GLASS:15)
Block(-11,26,-7,STAINED_GLASS:3)
Block(-10,26,-7,STAINED_GLASS:15)
Block(-9,26,-7,STAINED_GLASS:15)
Block(-11,26,-6,STAINED_GLASS:15)
Block(-13,27,-16,STAINED_GLASS:15)
Block(-12,27,-16,STAINED_GLASS:15)
Block(-11,27,-16,STAINED_GLASS:15)
Block(-14,27,-15,STAINED_GLASS:15)
Block(-13,27,-15,STAINED_GLASS:3)
Block(-12,27,-15,STAINED_GLASS:15)
Block(-11,27,-15,STAINED_GLASS:15)
Block(-10,27,-15,STAINED_GLASS:15)
Block(-15,27,-14,STAINED_GLASS:15)
Block(-14,27,-14,STAINED_GLASS:3)
Block(-13,27,-14,STAINED_GLASS:15)
Block(-12,27,-14,STAINED_GLASS:3)
Block(-11,27,-14,STAINED_GLASS:3)
Block(-10,27,-14,STAINED_GLASS:3)
Block(-9,27,-14,STAINED_GLASS:3)
Block(-16,27,-13,STAINED_GLASS:15)
Block(-15,27,-13,STAINED_GLASS:3)
Block(-14,27,-13,STAINED_GLASS:15)
Block(-13,27,-13,STAINED_GLASS:3)
Block(-12,27,-13,STAINED_GLASS:10)
Block(-11,27,-13,PURPLE_GLAZED_TERRACOTTA:3)
Block(-10,27,-13,PURPLE_GLAZED_TERRACOTTA:3)
Block(-9,27,-13,STAINED_GLASS:3)
Block(-8,27,-13,STAINED_GLASS:3)
Block(-16,27,-12,STAINED_GLASS:15)
Block(-15,27,-12,STAINED_GLASS:15)
Block(-14,27,-12,STAINED_GLASS:3)
Block(-13,27,-12,STAINED_GLASS:10)
Block(-12,27,-12,SEA_LANTERN:0)
Block(-11,27,-12,SEA_LANTERN:0)
Block(-10,27,-12,PURPLE_GLAZED_TERRACOTTA:3)
Block(-9,27,-12,PURPLE_GLAZED_TERRACOTTA:3)
Block(-8,27,-12,STAINED_GLASS:3)
Block(-7,27,-12,STAINED_GLASS:3)
Block(-16,27,-11,STAINED_GLASS:15)
Block(-15,27,-11,STAINED_GLASS:15)
Block(-14,27,-11,STAINED_GLASS:3)
Block(-13,27,-11,STAINED_GLASS:10)
Block(-12,27,-11,SEA_LANTERN:0)
Block(-11,27,-11,SEA_LANTERN:0)
Block(-10,27,-11,PURPLE_GLAZED_TERRACOTTA:3)
Block(-9,27,-11,PURPLE_GLAZED_TERRACOTTA:3)
Block(-8,27,-11,STAINED_GLASS:3)
Block(-7,27,-11,STAINED_GLASS:3)
Block(-15,27,-10,STAINED_GLASS:15)
Block(-14,27,-10,STAINED_GLASS:3)
Block(-13,27,-10,STAINED_GLASS:10)
Block(-12,27,-10,PURPLE_GLAZED_TERRACOTTA:3)
Block(-11,27,-10,PURPLE_GLAZED_TERRACOTTA:3)
Block(-10,27,-10,PURPLE_GLAZED_TERRACOTTA:3)
Block(-9,27,-10,STAINED_GLASS:15)
Block(-8,27,-10,STAINED_GLASS:3)
Block(-14,27,-9,STAINED_GLASS:15)
Block(-13,27,-9,STAINED_GLASS:15)
Block(-12,27,-9,STAINED_GLASS:10)
Block(-11,27,-9,PURPLE_GLAZED_TERRACOTTA:3)
Block(-10,27,-9,STAINED_GLASS:3)
Block(-9,27,-9,STAINED_GLASS:15)
Block(-8,27,-9,STAINED_GLASS:15)
Block(-13,27,-8,STAINED_GLASS:15)
Block(-12,27,-8,STAINED_GLASS:15)
Block(-11,27,-8,STAINED_GLASS:15)
Block(-10,27,-8,STAINED_GLASS:15)
Block(-9,27,-8,STAINED_GLASS:15)
Block(-12,27,-7,STAINED_GLASS:15)
Block(-11,27,-7,STAINED_GLASS:15)
Block(-13,28,-16,STAINED_GLASS:15)
Block(-12,28,-16,STAINED_GLASS:15)
Block(-14,28,-15,STAINED_GLASS:15)
Block(-13,28,-15,STAINED_GLASS:3)
Block(-12,28,-15,STAINED_GLASS:15)
Block(-11,28,-15,STAINED_GLASS:15)
Block(-15,28,-14,STAINED_GLASS:15)
Block(-14,28,-14,STAINED_GLASS:3)
Block(-13,28,-14,STAINED_GLASS:15)
Block(-12,28,-14,STAINED_GLASS:3)
Block(-11,28,-14,STAINED_GLASS:3)
Block(-10,28,-14,STAINED_GLASS:3)
Block(-16,28,-13,STAINED_GLASS:15)
Block(-15,28,-13,STAINED_GLASS:3)
Block(-14,28,-13,STAINED_GLASS:15)
Block(-13,28,-13,STAINED_GLASS:3)
Block(-12,28,-13,PURPLE_GLAZED_TERRACOTTA:3)
Block(-11,28,-13,PURPLE_GLAZED_TERRACOTTA:3)
Block(-10,28,-13,STAINED_GLASS:3)
Block(-9,28,-13,STAINED_GLASS:3)
Block(-16,28,-12,STAINED_GLASS:15)
Block(-15,28,-12,STAINED_GLASS:15)
Block(-14,28,-12,STAINED_GLASS:3)
Block(-13,28,-12,STAINED_GLASS:10)
Block(-12,28,-12,SEA_LANTERN:0)
Block(-11,28,-12,PURPLE_GLAZED_TERRACOTTA:3)
Block(-10,28,-12,PURPLE_GLAZED_TERRACOTTA:3)
Block(-9,28,-12,STAINED_GLASS:3)
Block(-8,28,-12,STAINED_GLASS:3)
Block(-15,28,-11,STAINED_GLASS:15)
Block(-14,28,-11,STAINED_GLASS:3)
Block(-13,28,-11,PURPLE_GLAZED_TERRACOTTA:3)
Block(-12,28,-11,PURPLE_GLAZED_TERRACOTTA:3)
Block(-11,28,-11,PURPLE_GLAZED_TERRACOTTA:3)
Block(-10,28,-11,PURPLE_GLAZED_TERRACOTTA:3)
Block(-9,28,-11,STAINED_GLASS:3)
Block(-8,28,-11,STAINED_GLASS:3)
Block(-14,28,-10,STAINED_GLASS:15)
Block(-13,28,-10,STAINED_GLASS:15)
Block(-12,28,-10,PURPLE_GLAZED_TERRACOTTA:3)
Block(-11,28,-10,PURPLE_GLAZED_TERRACOTTA:3)
Block(-10,28,-10,STAINED_GLASS:3)
Block(-9,28,-10,STAINED_GLASS:3)
Block(-8,28,-10,STAINED_GLASS:15)
Block(-13,28,-9,STAINED_GLASS:15)
Block(-12,28,-9,STAINED_GLASS:15)
Block(-11,28,-9,STAINED_GLASS:15)
Block(-10,28,-9,STAINED_GLASS:3)
Block(-9,28,-9,STAINED_GLASS:15)
Block(-12,28,-8,STAINED_GLASS:15)
Block(-11,28,-8,STAINED_GLASS:15)
Block(-10,28,-8,STAINED_GLASS:15)
Block(-14,29,-16,STAINED_GLASS:15)
Block(-13,29,-16,STAINED_GLASS:15)
Block(-12,29,-16,STAINED_GLASS:3)
Block(-15,29,-15,STAINED_GLASS:15)
Block(-14,29,-15,STAINED_GLASS:3)
Block(-13,29,-15,STAINED_GLASS:3)
Block(-12,29,-15,STAINED_GLASS:3)
Block(-11,29,-15,STAINED_GLASS:3)
Block(-16,29,-14,STAINED_GLASS:15)
Block(-15,29,-14,STAINED_GLASS:3)
Block(-14,29,-14,STAINED_GLASS:15)
Block(-13,29,-14,STAINED_GLASS:3)
Block(-12,29,-14,STAINED_GLASS:3)
Block(-11,29,-14,STAINED_GLASS:3)
Block(-10,29,-14,STAINED_GLASS:3)
Block(-16,29,-13,STAINED_GLASS:15)
Block(-15,29,-13,STAINED_GLASS:15)
Block(-14,29,-13,STAINED_GLASS:3)
Block(-13,29,-13,STAINED_GLASS:3)
Block(-12,29,-13,PURPLE_GLAZED_TERRACOTTA:3)
Block(-11,29,-13,STAINED_GLASS:3)
Block(-10,29,-13,STAINED_GLASS:3)
Block(-9,29,-13,STAINED_GLASS:3)
Block(-16,29,-12,STAINED_GLASS:15)
Block(-15,29,-12,STAINED_GLASS:15)
Block(-14,29,-12,STAINED_GLASS:3)
Block(-13,29,-12,PURPLE_GLAZED_TERRACOTTA:3)
Block(-12,29,-12,PURPLE_GLAZED_TERRACOTTA:3)
Block(-11,29,-12,PURPLE_GLAZED_TERRACOTTA:3)
Block(-10,29,-12,STAINED_GLASS:3)
Block(-9,29,-12,STAINED_GLASS:3)
Block(-15,29,-11,STAINED_GLASS:15)
Block(-14,29,-11,STAINED_GLASS:3)
Block(-13,29,-11,STAINED_GLASS:3)
Block(-12,29,-11,PURPLE_GLAZED_TERRACOTTA:3)
Block(-11,29,-11,PURPLE_GLAZED_TERRACOTTA:3)
Block(-10,29,-11,STAINED_GLASS:3)
Block(-9,29,-11,STAINED_GLASS:3)
Block(-14,29,-10,STAINED_GLASS:3)
Block(-13,29,-10,STAINED_GLASS:15)
Block(-12,29,-10,STAINED_GLASS:15)
Block(-11,29,-10,STAINED_GLASS:15)
Block(-10,29,-10,STAINED_GLASS:3)
Block(-9,29,-10,STAINED_GLASS:15)
Block(-13,29,-9,STAINED_GLASS:15)
Block(-12,29,-9,STAINED_GLASS:15)
Block(-11,29,-9,STAINED_GLASS:15)
Block(-10,29,-9,STAINED_GLASS:15)
Block(-14,30,-16,STAINED_GLASS:15)
Block(-13,30,-16,STAINED_GLASS:3)
Block(-15,30,-15,STAINED_GLASS:15)
Block(-14,30,-15,STAINED_GLASS:3)
Block(-13,30,-15,STAINED_GLASS:3)
Block(-12,30,-15,STAINED_GLASS:3)
Block(-16,30,-14,STAINED_GLASS:15)
Block(-15,30,-14,STAINED_GLASS:3)
Block(-14,30,-14,STAINED_GLASS:15)
Block(-13,30,-14,STAINED_GLASS:3)
Block(-12,30,-14,STAINED_GLASS:3)
Block(-11,30,-14,STAINED_GLASS:3)
Block(-16,30,-13,STAINED_GLASS:15)
Block(-15,30,-13,STAINED_GLASS:15)
Block(-14,30,-13,STAINED_GLASS:3)
Block(-13,30,-13,PURPLE_GLAZED_TERRACOTTA:3)
Block(-12,30,-13,STAINED_GLASS:3)
Block(-11,30,-13,STAINED_GLASS:3)
Block(-10,30,-13,STAINED_GLASS:3)
Block(-15,30,-12,STAINED_GLASS:15)
Block(-14,30,-12,STAINED_GLASS:15)
Block(-13,30,-12,STAINED_GLASS:3)
Block(-12,30,-12,PURPLE_GLAZED_TERRACOTTA:3)
Block(-11,30,-12,STAINED_GLASS:3)
Block(-10,30,-12,STAINED_GLASS:15)
Block(-14,30,-11,STAINED_GLASS:15)
Block(-13,30,-11,STAINED_GLASS:15)
Block(-12,30,-11,STAINED_GLASS:15)
Block(-11,30,-11,STAINED_GLASS:15)
Block(-10,30,-11,STAINED_GLASS:3)
Block(-9,30,-11,STAINED_GLASS:15)
Block(-13,30,-10,STAINED_GLASS:15)
Block(-12,30,-10,STAINED_GLASS:15)
Block(-11,30,-10,STAINED_GLASS:15)
Block(-10,30,-10,STAINED_GLASS:15)
Block(-11,30,-9,STAINED_GLASS:15)
Block(-14,31,-16,STAINED_GLASS:15)
Block(-13,31,-16,STAINED_GLASS:3)
Block(-15,31,-15,STAINED_GLASS:15)
Block(-14,31,-15,STAINED_GLASS:3)
Block(-13,31,-15,STAINED_GLASS:3)
Block(-12,31,-15,STAINED_GLASS:3)
Block(-16,31,-14,STAINED_GLASS:15)
Block(-15,31,-14,STAINED_GLASS:3)
Block(-14,31,-14,STAINED_GLASS:15)
Block(-13,31,-14,STAINED_GLASS:3)
Block(-12,31,-14,STAINED_GLASS:3)
Block(-11,31,-14,STAINED_GLASS:3)
Block(-16,31,-13,STAINED_GLASS:15)
Block(-15,31,-13,STAINED_GLASS:15)
Block(-14,31,-13,STAINED_GLASS:3)
Block(-13,31,-13,STAINED_GLASS:10)
Block(-12,31,-13,STAINED_GLASS:3)
Block(-11,31,-13,STAINED_GLASS:3)
Block(-15,31,-12,STAINED_GLASS:15)
Block(-14,31,-12,STAINED_GLASS:15)
Block(-13,31,-12,STAINED_GLASS:15)
Block(-12,31,-12,STAINED_GLASS:3)
Block(-11,31,-12,STAINED_GLASS:3)
Block(-10,31,-12,STAINED_GLASS:15)
Block(-14,31,-11,STAINED_GLASS:15)
Block(-13,31,-11,STAINED_GLASS:15)
Block(-12,31,-11,STAINED_GLASS:15)
Block(-11,31,-11,STAINED_GLASS:15)
Block(-10,31,-11,STAINED_GLASS:15)
Block(-12,31,-10,STAINED_GLASS:15)
Block(-11,31,-10,STAINED_GLASS:15)
Block(-15,32,-16,STAINED_GLASS:15)
Block(-14,32,-16,STAINED_GLASS:15)
Block(-16,32,-15,STAINED_GLASS:15)
Block(-15,32,-15,STAINED_GLASS:3)
Block(-14,32,-15,STAINED_GLASS:15)
Block(-13,32,-15,STAINED_GLASS:15)
Block(-16,32,-14,STAINED_GLASS:15)
Block(-15,32,-14,STAINED_GLASS:15)
Block(-14,32,-14,STAINED_GLASS:3)
Block(-13,32,-14,STAINED_GLASS:3)
Block(-12,32,-14,STAINED_GLASS:3)
Block(-15,32,-13,STAINED_GLASS:15)
Block(-14,32,-13,STAINED_GLASS:3)
Block(-13,32,-13,STAINED_GLASS:3)
Block(-12,32,-13,STAINED_GLASS:3)
Block(-11,32,-13,STAINED_GLASS:3)
Block(-14,32,-12,STAINED_GLASS:15)
Block(-13,32,-12,STAINED_GLASS:15)
Block(-12,32,-12,STAINED_GLASS:15)
Block(-11,32,-12,STAINED_GLASS:15)
Block(-13,32,-11,STAINED_GLASS:15)
Block(-12,32,-11,STAINED_GLASS:15)
Block(-15,33,-16,STAINED_GLASS:15)
Block(-14,33,-16,STAINED_GLASS:3)
Block(-16,33,-15,STAINED_GLASS:15)
Block(-15,33,-15,STAINED_GLASS:3)
Block(-14,33,-15,STAINED_GLASS:15)
Block(-13,33,-15,STAINED_GLASS:3)
Block(-16,33,-14,STAINED_GLASS:15)
Block(-15,33,-14,STAINED_GLASS:15)
Block(-14,33,-14,STAINED_GLASS:3)
Block(-13,33,-14,STAINED_GLASS:3)
Block(-12,33,-14,STAINED_GLASS:3)
Block(-15,33,-13,STAINED_GLASS:15)
Block(-14,33,-13,STAINED_GLASS:3)
Block(-13,33,-13,STAINED_GLASS:3)
Block(-12,33,-13,STAINED_GLASS:3)
Block(-14,33,-12,STAINED_GLASS:15)
Block(-13,33,-12,STAINED_GLASS:15)
Block(-16,34,-16,STAINED_GLASS:15)
Block(-15,34,-16,STAINED_GLASS:15)
Block(-16,34,-15,STAINED_GLASS:15)
Block(-15,34,-15,STAINED_GLASS:15)
Block(-14,34,-15,STAINED_GLASS:15)
Block(-15,34,-14,STAINED_GLASS:15)
Block(-14,34,-14,STAINED_GLASS:3)
Block(-13,34,-14,STAINED_GLASS:3)
Block(-14,34,-13,STAINED_GLASS:15)
Block(-16,35,-16,STAINED_GLASS:15)
Block(-15,35,-16,STAINED_GLASS:15)
Block(-16,35,-15,STAINED_GLASS:15)
Block(-15,35,-15,STAINED_GLASS:15)
Block(-14,35,-15,STAINED_GLASS:15)
Block(-15,35,-14,STAINED_GLASS:15)
Block(-14,35,-14,STAINED_GLASS:15)
Block(-16,36,-16,STAINED_GLASS:15)
Block(-15,36,-15,STAINED_GLASS:15)

#######################################################################
# +-----------------------------------------------------------------+ #
# |                            BO3 checks                           | #
# +-----------------------------------------------------------------+ #
#######################################################################

# Require a condition at a certain location in order for the BO3 to be spawned.
# BlockCheck(x,y,z,BlockName[,BlockName[,...]]) - one of the blocks must be at the location
# BlockCheckNot(x,y,z,BlockName[,BlockName[,...]]) - all the blocks must not be at the location
# LightCheck(x,y,z,minLightLevel,maxLightLevel) - light must be between min and max (inclusive)

# You can use "Solid" as a BlockName for matching all solid blocks or "All" to match all blocks that aren't air.

# Examples:
#   BlockCheck(0,-1,0,GRASS,DIRT)  Require grass or dirt just below the object
#   BlockCheck(0,-1,0,Solid)       Require any solid block just below the object
#   BlockCheck(0,-1,0,WOOL)        Require any type of wool just below the object
#   BlockCheck(0,-1,0,WOOL:0)      Require white wool just below the object
#   BlockCheckNot(0,-1,0,WOOL:0)   Require that there is no white wool below the object
#   LightCheck(0,0,0,0,1)          Require almost complete darkness just below the object

#######################################################################
# +-----------------------------------------------------------------+ #
# |                             Branches                            | #
# +-----------------------------------------------------------------+ #
#######################################################################

# Branches are objects that will spawn when this object spawns when it is used in
# the CustomStructure resource. Branches can also have branches, making complex
# structures possible. See the wiki for more details.

# Regular Branches spawn each branch with an independent chance of spawning.
# Branch(x,y,z,branchName,rotation,chance[,anotherBranchName,rotation,chance[,...]][IndividualChance])
# branchName - name of the object to spawn.
# rotation - NORTH, SOUTH, EAST or WEST.
# IndividualChance - The chance each branch has to spawn, assumed to be 100 when left blank

# Weighted Branches spawn branches with a dependent chance of spawning.
# WeightedBranch(x,y,z,branchName,rotation,chance[,anotherBranchName,rotation,chance[,...]][MaxChanceOutOf])
# MaxChanceOutOf - The chance all branches have to spawn out of, assumed to be 100 when left blank
