
#######################################################################
# +-----------------------------------------------------------------+ #
# |                            BO3 object                           | #
# +-----------------------------------------------------------------+ #
#######################################################################

Author: NLBlackEagle

Description: No description given

Version: 3

SettingsMode: WriteDisable


#######################################################################
# +-----------------------------------------------------------------+ #
# |                          Main settings                          | #
# +-----------------------------------------------------------------+ #
#######################################################################

Tree: true

Frequency: 1

Rarity: 100.0

RotateRandomly: true

SpawnHeight: randomY

SpawnHeightOffset: 0

SpawnHeightVariance: 0

##############################
# Height Limits for the BO3. #
##############################

MinHeight: 80

MaxHeight: 140

######################
# Extrusion settings #
######################

ExtrudeMode: None

ExtrudeThroughBlocks: AIR

MaxBranchDepth: 10

ExcludedBiomes: All


#######################################################################
# +-----------------------------------------------------------------+ #
# |                      Source block settings                      | #
# +-----------------------------------------------------------------+ #
#######################################################################

SourceBlocks: AIR,GRASS,DIRT,SAND

MaxPercentageOutsideSourceBlock: 0

OutsideSourceBlock: placeAnyway

IsOTGPlus: false

InheritBO3: 

InheritBO3Rotation: NORTH

OverrideChildSettings: true

OverrideParentHeight: false

CanOverride: false

BranchFrequency: 0

BranchFrequencyGroup: 

MustBeBelowOther: false

MustBeInside: 

CannotBeInside: 

ReplacesBO3: 

CanSpawnOnWater: true

SpawnOnWaterOnly: false

SpawnUnderWater: false

SpawnAtWaterLevel: false

HeightOffset: 0

RemoveAir: true

ReplaceAbove: 

ReplaceBelow: 

ReplaceWithBiomeBlocks: true

ReplaceWithGroundBlock: DIRT

ReplaceWithSurfaceBlock: GRASS

SmoothRadius: 0

SmoothHeightOffset: 0

SmoothStartTop: false

SmoothStartWood: false

SmoothingSurfaceBlock: 

SmoothingGroundBlock: 

BO3Group: 

IsSpawnPoint: false


#######################################################################
# +-----------------------------------------------------------------+ #
# |                              Blocks                             | #
# +-----------------------------------------------------------------+ #
#######################################################################

Block(-4,2,1,LEAVES:5)
Block(-4,3,1,LEAVES:5)
Block(-3,-3,0,LOG:1)
Block(-3,-3,1,LOG:1)
Block(-3,-2,0,LOG:1)
Block(-3,2,1,LEAVES:5)
Block(-3,3,1,LOG:13)
Block(-3,3,2,LEAVES:5)
Block(-3,4,-3,LEAVES:5)
Block(-3,4,0,LEAVES:5)
Block(-3,4,1,LEAVES:5)
Block(-3,5,-3,LEAVES:5)
Block(-3,5,0,LEAVES:5)
Block(-3,6,-3,LEAVES:5)
Block(-3,6,-2,LEAVES:5)
Block(-2,-2,-1,LOG:13)
Block(-2,-2,0,LOG:1)
Block(-2,3,0,LEAVES:5)
Block(-2,3,1,LEAVES:5)
Block(-2,4,0,LOG:13)
Block(-2,4,1,LEAVES:5)
Block(-2,5,-2,LEAVES:5)
Block(-2,5,0,LEAVES:5)
Block(-2,6,-3,LEAVES:5)
Block(-2,6,-2,LOG:13)
Block(-2,6,-1,LEAVES:5)
Block(-2,7,-2,LEAVES:5)
Block(-2,7,-1,LEAVES:5)
Block(-2,9,-2,LEAVES:5)
Block(-2,10,-2,LEAVES:5)
Block(-2,10,-1,LEAVES:5)
Block(-1,-3,-1,LOG:1)
Block(-1,-2,-1,LOG:13)
Block(-1,-1,-1,LOG:13)
Block(-1,-1,0,LOG:13)
Block(-1,3,0,LEAVES:5)
Block(-1,4,0,LOG:13)
Block(-1,4,1,LEAVES:5)
Block(-1,5,0,LEAVES:5)
Block(-1,5,3,LEAVES:5)
Block(-1,6,-1,LEAVES:5)
Block(-1,6,1,LEAVES:5)
Block(-1,6,2,LEAVES:5)
Block(-1,7,-2,LEAVES:5)
Block(-1,7,-1,LOG:13)
Block(-1,7,0,LEAVES:5)
Block(-1,8,-1,LEAVES:5)
Block(-1,8,0,LEAVES:5)
Block(-1,9,0,LEAVES:5)
Block(-1,10,-2,LEAVES:5)
Block(-1,10,-1,LOG:13)
Block(-1,10,0,LEAVES:5)
Block(-1,11,-1,LEAVES:5)
Block(-1,11,0,LEAVES:5)
Block(-1,11,1,LEAVES:5)
Block(-1,12,0,LEAVES:5)
Block(-1,12,1,LEAVES:5)
Block(-1,13,0,LEAVES:5)
Block(-1,14,0,LEAVES:5)
Block(0,-2,1,LOG:13)
Block(0,-1,0,LOG:13)
Block(0,-1,1,LOG:13)
Block(0,0,0,LOG:13)
Block(0,1,0,LOG:13)
Block(0,2,0,LOG:13)
Block(0,3,0,LOG:13)
Block(0,4,-2,LEAVES:5)
Block(0,4,0,LOG:13)
Block(0,4,1,LEAVES:5)
Block(0,4,3,LEAVES:5)
Block(0,4,4,LEAVES:5)
Block(0,5,-1,LEAVES:5)
Block(0,5,0,LOG:13)
Block(0,5,1,LEAVES:5)
Block(0,5,2,LEAVES:5)
Block(0,5,3,LOG:13)
Block(0,5,4,LEAVES:5)
Block(0,6,-1,LEAVES:5)
Block(0,6,0,LOG:13)
Block(0,6,1,LOG:13)
Block(0,6,2,LOG:13)
Block(0,6,3,LEAVES:5)
Block(0,7,-1,LEAVES:5)
Block(0,7,0,LOG:13)
Block(0,7,1,LEAVES:5)
Block(0,7,2,LEAVES:5)
Block(0,8,-1,LEAVES:5)
Block(0,8,0,LOG:13)
Block(0,8,1,LEAVES:5)
Block(0,9,-1,LEAVES:5)
Block(0,9,0,LOG:13)
Block(0,9,1,LEAVES:5)
Block(0,10,-1,LEAVES:5)
Block(0,10,0,LOG:13)
Block(0,10,1,LEAVES:5)
Block(0,11,0,LOG:13)
Block(0,11,1,LEAVES:5)
Block(0,12,-1,LEAVES:5)
Block(0,12,0,LOG:13)
Block(0,12,1,LEAVES:5)
Block(0,13,-1,LEAVES:5)
Block(0,13,0,LOG:13)
Block(0,13,1,LEAVES:5)
Block(0,14,-1,LEAVES:5)
Block(0,14,0,LOG:13)
Block(0,14,1,LEAVES:5)
Block(0,15,-1,LEAVES:5)
Block(0,15,0,LEAVES:5)
Block(0,16,0,LEAVES:5)
Block(0,17,0,LEAVES:5)
Block(0,18,0,LEAVES:5)
Block(0,19,0,LEAVES:5)
Block(0,20,0,LEAVES:5)
Block(0,21,0,LEAVES:5)
Block(1,-4,-2,LOG:1)
Block(1,-3,-2,LOG:13)
Block(1,-3,1,LOG:1)
Block(1,-2,-2,LOG:13)
Block(1,-2,-1,LOG:13)
Block(1,-2,1,LOG:1)
Block(1,-1,-1,LOG:13)
Block(1,-1,1,LOG:1)
Block(1,3,-3,LEAVES:5)
Block(1,3,-2,LEAVES:5)
Block(1,3,0,LOG:13)
Block(1,3,1,LEAVES:5)
Block(1,4,-3,LEAVES:5)
Block(1,4,-2,LOG:13)
Block(1,4,0,LEAVES:5)
Block(1,4,1,LEAVES:5)
Block(1,5,-2,LEAVES:5)
Block(1,5,-1,LOG:13)
Block(1,5,0,LEAVES:5)
Block(1,5,3,LEAVES:5)
Block(1,6,-1,LEAVES:5)
Block(1,6,1,LEAVES:5)
Block(1,6,2,LEAVES:5)
Block(1,7,1,LEAVES:5)
Block(1,8,0,LOG:13)
Block(1,8,1,LEAVES:5)
Block(1,9,0,LEAVES:5)
Block(1,11,1,LEAVES:5)
Block(1,12,0,LEAVES:5)
Block(1,12,1,LOG:13)
Block(1,12,2,LEAVES:5)
Block(1,13,0,LEAVES:5)
Block(1,14,0,LEAVES:5)
Block(1,15,0,LEAVES:5)
Block(1,16,0,LEAVES:5)
Block(1,17,0,LEAVES:5)
Block(2,-5,-2,LOG:1)
Block(2,-4,-2,LOG:1)
Block(2,-3,1,LOG:1)
Block(2,-3,2,LOG:1)
Block(2,-2,-1,LOG:1)
Block(2,2,-3,LEAVES:5)
Block(2,3,-3,LEAVES:5)
Block(2,3,0,LOG:13)
Block(2,3,1,LEAVES:5)
Block(2,3,2,LEAVES:5)
Block(2,4,-2,LEAVES:5)
Block(2,4,0,LEAVES:5)
Block(2,5,-2,LEAVES:5)
Block(2,5,-1,LEAVES:5)
Block(2,6,0,LEAVES:5)
Block(2,7,0,LOG:13)
Block(2,7,1,LEAVES:5)
Block(2,8,0,LEAVES:5)
Block(2,8,1,LEAVES:5)
Block(2,10,2,LEAVES:5)
Block(2,11,2,LEAVES:5)
Block(2,12,1,LEAVES:5)
Block(2,12,2,LEAVES:5)
Block(3,2,0,LEAVES:5)
Block(3,2,1,LOG:13)
Block(3,2,2,LEAVES:5)
Block(3,3,0,LEAVES:5)
Block(3,3,1,LEAVES:5)
Block(3,6,0,LEAVES:5)
Block(3,7,0,LEAVES:5)
Block(4,2,1,LEAVES:5)
Block(4,5,0,LEAVES:5)
Block(4,6,0,LEAVES:5)

#######################################################################
# +-----------------------------------------------------------------+ #
# |                            BO3 checks                           | #
# +-----------------------------------------------------------------+ #
#######################################################################

BlockCheck(0,-1,0,GRASS,DIRT)
BlockCheck(0,-5,0,Solid)

#######################################################################
# +-----------------------------------------------------------------+ #
# |                             Branches                            | #
# +-----------------------------------------------------------------+ #
#######################################################################


#######################################################################
# +-----------------------------------------------------------------+ #
# |                             Entities                            | #
# +-----------------------------------------------------------------+ #
#######################################################################


#######################################################################
# +-----------------------------------------------------------------+ #
# |                            Particles                            | #
# +-----------------------------------------------------------------+ #
#######################################################################


#######################################################################
# +-----------------------------------------------------------------+ #
# |                             Spawners                            | #
# +-----------------------------------------------------------------+ #
#######################################################################


#######################################################################
# +-----------------------------------------------------------------+ #
# |                             ModData                             | #
# +-----------------------------------------------------------------+ #
#######################################################################

