Author: BO3 BulkEdit (by LanToaster)
Description: This Object was Created with BO3_BulkEdit
Version: 3
SettingsMode: WriteDisable
Tree: false
Frequency: 100
Rarity: 100
RotateRandomly: true
SpawnHeight: randomY
MinHeight: 87
MaxHeight: 87
MaxBranchDepth: 50
ExcludedBiomes: All
SourceBlocks: AIR
MaxPercentageOutsideSourceBlock: 100
OutsideSourceBlock: placeAnyway
Block(-2,-1,-6,LOG:3)
Block(4,-1,-6,LOG:3)
Block(-5,-1,-4,BIRCH_STAIRS:0)
Block(-4,-1,-4,BIRCH_STAIRS:5)
Block(-6,-1,-2,LOG:3)
Block(-2,-1,-2,LOG:3)
Block(4,-1,-2,LOG:3)
Block(-6,-1,3,LOG:3)
Block(-2,-1,3,LOG:3)
Block(4,-1,3,LOG:3)
Block(-2,0,-6,LOG:3)
Block(4,0,-6,LOG:3)
Block(-4,0,-4,BIRCH_STAIRS:0)
Block(-3,0,-4,BIRCH_STAIRS:5)
Block(-6,0,-2,LOG:3)
Block(-2,0,-2,LOG:3)
Block(4,0,-2,LOG:3)
Block(-6,0,3,LOG:3)
Block(-2,0,3,LOG:3)
Block(4,0,3,LOG:3)
Block(-2,1,-6,LOG:3)
Block(-1,1,-6,LOG:7)
Block(0,1,-6,LOG:7)
Block(1,1,-6,LOG:7)
Block(2,1,-6,LOG:7)
Block(3,1,-6,LOG:7)
Block(4,1,-6,LOG:3)
Block(-2,1,-5,LOG:11)
Block(-1,1,-5,WOODEN_SLAB:11)
Block(0,1,-5,WOODEN_SLAB:11)
Block(1,1,-5,WOODEN_SLAB:11)
Block(2,1,-5,WOODEN_SLAB:11)
Block(3,1,-5,WOODEN_SLAB:11)
Block(4,1,-5,LOG:11)
Block(-3,1,-4,BIRCH_STAIRS:0)
Block(-2,1,-4,LOG:11)
Block(-1,1,-4,WOODEN_SLAB:11)
Block(0,1,-4,WOODEN_SLAB:11)
Block(1,1,-4,WOODEN_SLAB:11)
Block(2,1,-4,WOODEN_SLAB:11)
Block(3,1,-4,WOODEN_SLAB:11)
Block(4,1,-4,LOG:11)
Block(-2,1,-3,LOG:11)
Block(-1,1,-3,WOODEN_SLAB:11)
Block(0,1,-3,WOODEN_SLAB:11)
Block(1,1,-3,WOODEN_SLAB:11)
Block(2,1,-3,WOODEN_SLAB:11)
Block(3,1,-3,WOODEN_SLAB:11)
Block(4,1,-3,LOG:11)
Block(-6,1,-2,LOG:3)
Block(-5,1,-2,LOG:7)
Block(-4,1,-2,LOG:7)
Block(-3,1,-2,LOG:7)
Block(-2,1,-2,LOG:3)
Block(-1,1,-2,LOG:7)
Block(0,1,-2,LOG:7)
Block(1,1,-2,LOG:7)
Block(2,1,-2,LOG:7)
Block(3,1,-2,LOG:7)
Block(4,1,-2,LOG:3)
Block(-6,1,-1,LOG:11)
Block(-5,1,-1,WOODEN_SLAB:11)
Block(-4,1,-1,WOODEN_SLAB:11)
Block(-3,1,-1,WOODEN_SLAB:11)
Block(-2,1,-1,LOG:11)
Block(-1,1,-1,WOODEN_SLAB:11)
Block(0,1,-1,WOODEN_SLAB:11)
Block(1,1,-1,WOODEN_SLAB:11)
Block(2,1,-1,WOODEN_SLAB:11)
Block(3,1,-1,WOODEN_SLAB:11)
Block(4,1,-1,LOG:11)
Block(-6,1,0,LOG:11)
Block(-5,1,0,WOODEN_SLAB:11)
Block(-4,1,0,WOODEN_SLAB:11)
Block(-3,1,0,WOODEN_SLAB:11)
Block(-2,1,0,LOG:11)
Block(-1,1,0,WOODEN_SLAB:11)
Block(0,1,0,WOODEN_SLAB:11)
Block(1,1,0,WOODEN_SLAB:11)
Block(2,1,0,WOODEN_SLAB:11)
Block(3,1,0,WOODEN_SLAB:11)
Block(4,1,0,LOG:11)
Block(-6,1,1,LOG:11)
Block(-5,1,1,WOODEN_SLAB:11)
Block(-4,1,1,WOODEN_SLAB:11)
Block(-3,1,1,WOODEN_SLAB:11)
Block(-2,1,1,LOG:11)
Block(-1,1,1,WOODEN_SLAB:11)
Block(0,1,1,WOODEN_SLAB:11)
Block(1,1,1,WOODEN_SLAB:11)
Block(2,1,1,WOODEN_SLAB:11)
Block(3,1,1,WOODEN_SLAB:11)
Block(4,1,1,LOG:11)
Block(-6,1,2,LOG:11)
Block(-5,1,2,WOODEN_SLAB:11)
Block(-4,1,2,WOODEN_SLAB:11)
Block(-3,1,2,WOODEN_SLAB:11)
Block(-2,1,2,LOG:11)
Block(-1,1,2,WOODEN_SLAB:11)
Block(0,1,2,WOODEN_SLAB:11)
Block(1,1,2,WOODEN_SLAB:11)
Block(2,1,2,WOODEN_SLAB:11)
Block(3,1,2,WOODEN_SLAB:11)
Block(4,1,2,LOG:11)
Block(-6,1,3,LOG:3)
Block(-5,1,3,LOG:7)
Block(-4,1,3,LOG:7)
Block(-3,1,3,LOG:7)
Block(-2,1,3,LOG:3)
Block(-1,1,3,LOG:7)
Block(0,1,3,LOG:7)
Block(1,1,3,LOG:7)
Block(2,1,3,LOG:7)
Block(3,1,3,LOG:7)
Block(4,1,3,LOG:3)
Block(-2,2,-6,LOG:3)
Block(-1,2,-6,JUNGLE_FENCE:0)
Block(0,2,-6,JUNGLE_FENCE:0)
Block(1,2,-6,JUNGLE_FENCE:0)
Block(2,2,-6,JUNGLE_FENCE:0)
Block(3,2,-6,JUNGLE_FENCE:0)
Block(4,2,-6,LOG:3)
Block(-2,2,-5,JUNGLE_FENCE:0)
Block(-1,2,-5,JUKEBOX:0)
RandomBlock(0,2,-5,FLOWER_POT:0,../JungleNBT/pots/JunglePot01.nbt,10,FLOWER_POT:0,../JungleNBT/pots/JunglePot02.nbt,10,FLOWER_POT:0,../JungleNBT/pots/JunglePot03.nbt,10,FLOWER_POT:0,../JungleNBT/pots/JunglePot04.nbt,10,FLOWER_POT:0,../JungleNBT/pots/JunglePot05.nbt,10,FLOWER_POT:0,../JungleNBT/pots/JunglePot06.nbt,10,FLOWER_POT:0,../JungleNBT/pots/JunglePot07.nbt,10,FLOWER_POT:0,../JungleNBT/pots/JunglePot08.nbt,100)
Block(1,2,-5,AIR)
Entity(1,2,-5,VILLAGER,1,../JungleNBT/entities/tribalnative.txt)
Block(3,2,-5,SPRUCE_STAIRS:7)
Block(4,2,-5,JUNGLE_FENCE:0)
Block(-2,2,-4,JUNGLE_FENCE_GATE:7)
Block(3,2,-4,WOODEN_SLAB:9)
Block(4,2,-4,JUNGLE_FENCE:0)
Block(-2,2,-3,JUNGLE_FENCE:0)
Block(1,2,-3,AIR)
Block(3,2,-3,SPRUCE_STAIRS:6)
Block(4,2,-3,JUNGLE_FENCE:0)
Block(-6,2,-2,LOG:3)
Block(-5,2,-2,JUNGLE_FENCE:0)
Block(-4,2,-2,JUNGLE_FENCE:0)
Block(-3,2,-2,JUNGLE_FENCE:0)
Block(-2,2,-2,LOG:3)
Block(-1,2,-2,JUNGLE_FENCE:0)
Block(3,2,-2,JUNGLE_FENCE:0)
Block(4,2,-2,LOG:3)
Block(-6,2,-1,JUNGLE_FENCE:0)
RandomBlock(-5,2,-1,CHEST:5,../JungleNBT/StructureLoot/JunkChest_1.nbt,25,CHEST:5,../JungleNBT/StructureLoot/JunkChest_2.nbt,25,CHEST:5,../JungleNBT/StructureLoot/JunkChest_3.nbt,25,CHEST:5,../JungleNBT/StructureLoot/JunkChest_4.nbt,25,CHEST:5,../JungleNBT/StructureLoot/JunkChest_5.nbt,25,CHEST:5,../JungleNBT/LoreStoryline/JungleLore05.nbt,2,CHEST:5,../JungleNBT/LoreStoryline/JungleLore04.nbt,2,CHEST:5,../JungleNBT/LoreStoryline/JungleLore03.nbt,2,CHEST:5,../JungleNBT/LoreStoryline/JungleLore02.nbt,2,CHEST:5,../JungleNBT/LoreStoryline/JungleLore01.nbt,2,CHEST:5,../JungleNBT/StructureLoot/Common1.nbt,3,CHEST:5,../JungleNBT/StructureLoot/Common2.nbt,3,CHEST:5,../JungleNBT/StructureLoot/Common3.nbt,3,CHEST:5,../JungleNBT/StructureLoot/Common4.nbt,3,CHEST:5,../JungleNBT/StructureLoot/Common5.nbt,3,CHEST:5,../JungleNBT/StructureLoot/Common5.nbt,3,CHEST:5,../JungleNBT/StructureLoot/Common6.nbt,3,CHEST:5,../JungleNBT/StructureLoot/Common7.nbt,3,CHEST:5,../JungleNBT/StructureLoot/Common8.nbt,3,CHEST:5,../JungleNBT/StructureLoot/Common9.nbt,3,CHEST:5,../JungleNBT/StructureLoot/Common10.nbt,3,CHEST:5,../JungleNBT/StructureLoot/Common11.nbt,3,CHEST:5,../JungleNBT/StructureLoot/Common12.nbt,3,CHEST:5,../JungleNBT/StructureLoot/Common13.nbt,3,CHEST:5,../JungleNBT/StructureLoot/Common14.nbt,3,CHEST:5,../JungleNBT/StructureLoot/Common15.nbt,3,CHEST:5,../JungleNBT/StructureLoot/Rare1.nbt,3,CHEST:5,../JungleNBT/StructureLoot/Rare2.nbt,3,CHEST:5,../JungleNBT/StructureLoot/Rare3.nbt,3,CHEST:5,../JungleNBT/StructureLoot/Rare4.nbt,3,CHEST:5,../JungleNBT/StructureLoot/Rare5.nbt,3,CHEST:5,../JungleNBT/StructureLoot/Rare6.nbt,3,CHEST:5,../JungleNBT/StructureLoot/Rare7.nbt,3,CHEST:5,../JungleNBT/StructureLoot/Rare8.nbt,3,CHEST:5,../JungleNBT/StructureLoot/Rare9.nbt,3,CHEST:5,../JungleNBT/StructureLoot/Rare10.nbt,3,CHEST:5,../JungleNBT/StructureLoot/Rare11.nbt,3,CHEST:5,../JungleNBT/StructureLoot/Rare12.nbt,3,CHEST:5,../JungleNBT/StructureLoot/Rare13.nbt,3,CHEST:5,../JungleNBT/StructureLoot/Rare14.nbt,3,CHEST:5,../JungleNBT/StructureLoot/Rare15.nbt,3,CHEST:5,../JungleNBT/StructureLoot/Epic1.nbt,3,CHEST:5,../JungleNBT/StructureLoot/Epic2.nbt,3,CHEST:5,../JungleNBT/StructureLoot/Epic3.nbt,3,CHEST:5,../JungleNBT/StructureLoot/Epic4.nbt,3,CHEST:5,../JungleNBT/StructureLoot/Epic5.nbt,3,CHEST:5,../JungleNBT/StructureLoot/Epic6.nbt,3,CHEST:5,../JungleNBT/StructureLoot/Epic7.nbt,3,CHEST:5,../JungleNBT/StructureLoot/Epic8.nbt,3,CHEST:5,../JungleNBT/StructureLoot/Epic9.nbt,3,CHEST:5,../JungleNBT/StructureLoot/Epic10.nbt,3,CHEST:5,../JungleNBT/StructureLoot/Epic11.nbt,3,CHEST:5,../JungleNBT/StructureLoot/Epic12.nbt,3,CHEST:5,../JungleNBT/StructureLoot/Epic13.nbt,3,CHEST:5,../JungleNBT/StructureLoot/Epic14.nbt,3,CHEST:5,../JungleNBT/StructureLoot/Epic15.nbt,100)
Block(-2,2,-1,JUNGLE_FENCE:0)
Block(-1,2,-1,CAULDRON:3)
Block(2,2,-1,BED:3)
Block(3,2,-1,BED:11)
Block(4,2,-1,JUNGLE_FENCE:0)
Block(-6,2,0,JUNGLE_FENCE:0)
Block(-4,2,0,AIR)
Entity(-4,2,0,VILLAGER,1,../JungleNBT/entities/tribalnative.txt)
Block(-2,2,0,JUNGLE_FENCE_GATE:5)
RandomBlock(3,2,0,CHEST:4,../JungleNBT/StructureLoot/JunkChest_1.nbt,25,CHEST:4,../JungleNBT/StructureLoot/JunkChest_2.nbt,25,CHEST:4,../JungleNBT/StructureLoot/JunkChest_3.nbt,25,CHEST:4,../JungleNBT/StructureLoot/JunkChest_4.nbt,25,CHEST:4,../JungleNBT/StructureLoot/JunkChest_5.nbt,25,CHEST:4,../JungleNBT/LoreStoryline/JungleLore05.nbt,2,CHEST:4,../JungleNBT/LoreStoryline/JungleLore04.nbt,2,CHEST:4,../JungleNBT/LoreStoryline/JungleLore03.nbt,2,CHEST:4,../JungleNBT/LoreStoryline/JungleLore02.nbt,2,CHEST:4,../JungleNBT/LoreStoryline/JungleLore01.nbt,2,CHEST:4,../JungleNBT/StructureLoot/Common1.nbt,3,CHEST:4,../JungleNBT/StructureLoot/Common2.nbt,3,CHEST:4,../JungleNBT/StructureLoot/Common3.nbt,3,CHEST:4,../JungleNBT/StructureLoot/Common4.nbt,3,CHEST:4,../JungleNBT/StructureLoot/Common5.nbt,3,CHEST:4,../JungleNBT/StructureLoot/Common5.nbt,3,CHEST:4,../JungleNBT/StructureLoot/Common6.nbt,3,CHEST:4,../JungleNBT/StructureLoot/Common7.nbt,3,CHEST:4,../JungleNBT/StructureLoot/Common8.nbt,3,CHEST:4,../JungleNBT/StructureLoot/Common9.nbt,3,CHEST:4,../JungleNBT/StructureLoot/Common10.nbt,3,CHEST:4,../JungleNBT/StructureLoot/Common11.nbt,3,CHEST:4,../JungleNBT/StructureLoot/Common12.nbt,3,CHEST:4,../JungleNBT/StructureLoot/Common13.nbt,3,CHEST:4,../JungleNBT/StructureLoot/Common14.nbt,3,CHEST:4,../JungleNBT/StructureLoot/Common15.nbt,3,CHEST:4,../JungleNBT/StructureLoot/Rare1.nbt,3,CHEST:4,../JungleNBT/StructureLoot/Rare2.nbt,3,CHEST:4,../JungleNBT/StructureLoot/Rare3.nbt,3,CHEST:4,../JungleNBT/StructureLoot/Rare4.nbt,3,CHEST:4,../JungleNBT/StructureLoot/Rare5.nbt,3,CHEST:4,../JungleNBT/StructureLoot/Rare6.nbt,3,CHEST:4,../JungleNBT/StructureLoot/Rare7.nbt,3,CHEST:4,../JungleNBT/StructureLoot/Rare8.nbt,3,CHEST:4,../JungleNBT/StructureLoot/Rare9.nbt,3,CHEST:4,../JungleNBT/StructureLoot/Rare10.nbt,3,CHEST:4,../JungleNBT/StructureLoot/Rare11.nbt,3,CHEST:4,../JungleNBT/StructureLoot/Rare12.nbt,3,CHEST:4,../JungleNBT/StructureLoot/Rare13.nbt,3,CHEST:4,../JungleNBT/StructureLoot/Rare14.nbt,3,CHEST:4,../JungleNBT/StructureLoot/Rare15.nbt,3,CHEST:4,../JungleNBT/StructureLoot/Epic1.nbt,3,CHEST:4,../JungleNBT/StructureLoot/Epic2.nbt,3,CHEST:4,../JungleNBT/StructureLoot/Epic3.nbt,3,CHEST:4,../JungleNBT/StructureLoot/Epic4.nbt,3,CHEST:4,../JungleNBT/StructureLoot/Epic5.nbt,3,CHEST:4,../JungleNBT/StructureLoot/Epic6.nbt,3,CHEST:4,../JungleNBT/StructureLoot/Epic7.nbt,3,CHEST:4,../JungleNBT/StructureLoot/Epic8.nbt,3,CHEST:4,../JungleNBT/StructureLoot/Epic9.nbt,3,CHEST:4,../JungleNBT/StructureLoot/Epic10.nbt,3,CHEST:4,../JungleNBT/StructureLoot/Epic11.nbt,3,CHEST:4,../JungleNBT/StructureLoot/Epic12.nbt,3,CHEST:4,../JungleNBT/StructureLoot/Epic13.nbt,3,CHEST:4,../JungleNBT/StructureLoot/Epic14.nbt,3,CHEST:4,../JungleNBT/StructureLoot/Epic15.nbt,3,CHEST:4,../JungleNBT/LoreStoryline/JungleLore05.nbt,100)
Block(4,2,0,JUNGLE_FENCE:0)
Block(-6,2,1,JUNGLE_FENCE:0)
RandomBlock(-5,2,1,FLOWER_POT:0,../JungleNBT/pots/JunglePot01.nbt,10,FLOWER_POT:0,../JungleNBT/pots/JunglePot02.nbt,10,FLOWER_POT:0,../JungleNBT/pots/JunglePot03.nbt,10,FLOWER_POT:0,../JungleNBT/pots/JunglePot04.nbt,10,FLOWER_POT:0,../JungleNBT/pots/JunglePot05.nbt,10,FLOWER_POT:0,../JungleNBT/pots/JunglePot06.nbt,10,FLOWER_POT:0,../JungleNBT/pots/JunglePot07.nbt,10,FLOWER_POT:0,../JungleNBT/pots/JunglePot08.nbt,100)
Block(-2,2,1,JUNGLE_FENCE:0)
RandomBlock(-1,2,1,CHEST:5,../JungleNBT/StructureLoot/JunkChest_1.nbt,25,CHEST:5,../JungleNBT/StructureLoot/JunkChest_2.nbt,25,CHEST:5,../JungleNBT/StructureLoot/JunkChest_3.nbt,25,CHEST:5,../JungleNBT/StructureLoot/JunkChest_4.nbt,25,CHEST:5,../JungleNBT/StructureLoot/JunkChest_5.nbt,25,CHEST:5,../JungleNBT/LoreStoryline/JungleLore05.nbt,2,CHEST:5,../JungleNBT/LoreStoryline/JungleLore04.nbt,2,CHEST:5,../JungleNBT/LoreStoryline/JungleLore03.nbt,2,CHEST:5,../JungleNBT/LoreStoryline/JungleLore02.nbt,2,CHEST:5,../JungleNBT/LoreStoryline/JungleLore01.nbt,2,CHEST:5,../JungleNBT/StructureLoot/Common1.nbt,3,CHEST:5,../JungleNBT/StructureLoot/Common2.nbt,3,CHEST:5,../JungleNBT/StructureLoot/Common3.nbt,3,CHEST:5,../JungleNBT/StructureLoot/Common4.nbt,3,CHEST:5,../JungleNBT/StructureLoot/Common5.nbt,3,CHEST:5,../JungleNBT/StructureLoot/Common5.nbt,3,CHEST:5,../JungleNBT/StructureLoot/Common6.nbt,3,CHEST:5,../JungleNBT/StructureLoot/Common7.nbt,3,CHEST:5,../JungleNBT/StructureLoot/Common8.nbt,3,CHEST:5,../JungleNBT/StructureLoot/Common9.nbt,3,CHEST:5,../JungleNBT/StructureLoot/Common10.nbt,3,CHEST:5,../JungleNBT/StructureLoot/Common11.nbt,3,CHEST:5,../JungleNBT/StructureLoot/Common12.nbt,3,CHEST:5,../JungleNBT/StructureLoot/Common13.nbt,3,CHEST:5,../JungleNBT/StructureLoot/Common14.nbt,3,CHEST:5,../JungleNBT/StructureLoot/Common15.nbt,3,CHEST:5,../JungleNBT/StructureLoot/Rare1.nbt,3,CHEST:5,../JungleNBT/StructureLoot/Rare2.nbt,3,CHEST:5,../JungleNBT/StructureLoot/Rare3.nbt,3,CHEST:5,../JungleNBT/StructureLoot/Rare4.nbt,3,CHEST:5,../JungleNBT/StructureLoot/Rare5.nbt,3,CHEST:5,../JungleNBT/StructureLoot/Rare6.nbt,3,CHEST:5,../JungleNBT/StructureLoot/Rare7.nbt,3,CHEST:5,../JungleNBT/StructureLoot/Rare8.nbt,3,CHEST:5,../JungleNBT/StructureLoot/Rare9.nbt,3,CHEST:5,../JungleNBT/StructureLoot/Rare10.nbt,3,CHEST:5,../JungleNBT/StructureLoot/Rare11.nbt,3,CHEST:5,../JungleNBT/StructureLoot/Rare12.nbt,3,CHEST:5,../JungleNBT/StructureLoot/Rare13.nbt,3,CHEST:5,../JungleNBT/StructureLoot/Rare14.nbt,3,CHEST:5,../JungleNBT/StructureLoot/Rare15.nbt,3,CHEST:5,../JungleNBT/StructureLoot/Epic1.nbt,3,CHEST:5,../JungleNBT/StructureLoot/Epic2.nbt,3,CHEST:5,../JungleNBT/StructureLoot/Epic3.nbt,3,CHEST:5,../JungleNBT/StructureLoot/Epic4.nbt,3,CHEST:5,../JungleNBT/StructureLoot/Epic5.nbt,3,CHEST:5,../JungleNBT/StructureLoot/Epic6.nbt,3,CHEST:5,../JungleNBT/StructureLoot/Epic7.nbt,3,CHEST:5,../JungleNBT/StructureLoot/Epic8.nbt,3,CHEST:5,../JungleNBT/StructureLoot/Epic9.nbt,3,CHEST:5,../JungleNBT/StructureLoot/Epic10.nbt,3,CHEST:5,../JungleNBT/StructureLoot/Epic11.nbt,3,CHEST:5,../JungleNBT/StructureLoot/Epic12.nbt,3,CHEST:5,../JungleNBT/StructureLoot/Epic13.nbt,3,CHEST:5,../JungleNBT/StructureLoot/Epic14.nbt,3,CHEST:5,../JungleNBT/StructureLoot/Epic15.nbt,100)
RandomBlock(3,2,1,CHEST:4,../JungleNBT/StructureLoot/JunkChest_1.nbt,25,CHEST:4,../JungleNBT/StructureLoot/JunkChest_2.nbt,25,CHEST:4,../JungleNBT/StructureLoot/JunkChest_3.nbt,25,CHEST:4,../JungleNBT/StructureLoot/JunkChest_4.nbt,25,CHEST:4,../JungleNBT/StructureLoot/JunkChest_5.nbt,25,CHEST:4,../JungleNBT/LoreStoryline/JungleLore05.nbt,2,CHEST:4,../JungleNBT/LoreStoryline/JungleLore04.nbt,2,CHEST:4,../JungleNBT/LoreStoryline/JungleLore03.nbt,2,CHEST:4,../JungleNBT/LoreStoryline/JungleLore02.nbt,2,CHEST:4,../JungleNBT/LoreStoryline/JungleLore01.nbt,2,CHEST:4,../JungleNBT/StructureLoot/Common1.nbt,3,CHEST:4,../JungleNBT/StructureLoot/Common2.nbt,3,CHEST:4,../JungleNBT/StructureLoot/Common3.nbt,3,CHEST:4,../JungleNBT/StructureLoot/Common4.nbt,3,CHEST:4,../JungleNBT/StructureLoot/Common5.nbt,3,CHEST:4,../JungleNBT/StructureLoot/Common5.nbt,3,CHEST:4,../JungleNBT/StructureLoot/Common6.nbt,3,CHEST:4,../JungleNBT/StructureLoot/Common7.nbt,3,CHEST:4,../JungleNBT/StructureLoot/Common8.nbt,3,CHEST:4,../JungleNBT/StructureLoot/Common9.nbt,3,CHEST:4,../JungleNBT/StructureLoot/Common10.nbt,3,CHEST:4,../JungleNBT/StructureLoot/Common11.nbt,3,CHEST:4,../JungleNBT/StructureLoot/Common12.nbt,3,CHEST:4,../JungleNBT/StructureLoot/Common13.nbt,3,CHEST:4,../JungleNBT/StructureLoot/Common14.nbt,3,CHEST:4,../JungleNBT/StructureLoot/Common15.nbt,3,CHEST:4,../JungleNBT/StructureLoot/Rare1.nbt,3,CHEST:4,../JungleNBT/StructureLoot/Rare2.nbt,3,CHEST:4,../JungleNBT/StructureLoot/Rare3.nbt,3,CHEST:4,../JungleNBT/StructureLoot/Rare4.nbt,3,CHEST:4,../JungleNBT/StructureLoot/Rare5.nbt,3,CHEST:4,../JungleNBT/StructureLoot/Rare6.nbt,3,CHEST:4,../JungleNBT/StructureLoot/Rare7.nbt,3,CHEST:4,../JungleNBT/StructureLoot/Rare8.nbt,3,CHEST:4,../JungleNBT/StructureLoot/Rare9.nbt,3,CHEST:4,../JungleNBT/StructureLoot/Rare10.nbt,3,CHEST:4,../JungleNBT/StructureLoot/Rare11.nbt,3,CHEST:4,../JungleNBT/StructureLoot/Rare12.nbt,3,CHEST:4,../JungleNBT/StructureLoot/Rare13.nbt,3,CHEST:4,../JungleNBT/StructureLoot/Rare14.nbt,3,CHEST:4,../JungleNBT/StructureLoot/Rare15.nbt,3,CHEST:4,../JungleNBT/StructureLoot/Epic1.nbt,3,CHEST:4,../JungleNBT/StructureLoot/Epic2.nbt,3,CHEST:4,../JungleNBT/StructureLoot/Epic3.nbt,3,CHEST:4,../JungleNBT/StructureLoot/Epic4.nbt,3,CHEST:4,../JungleNBT/StructureLoot/Epic5.nbt,3,CHEST:4,../JungleNBT/StructureLoot/Epic6.nbt,3,CHEST:4,../JungleNBT/StructureLoot/Epic7.nbt,3,CHEST:4,../JungleNBT/StructureLoot/Epic8.nbt,3,CHEST:4,../JungleNBT/StructureLoot/Epic9.nbt,3,CHEST:4,../JungleNBT/StructureLoot/Epic10.nbt,3,CHEST:4,../JungleNBT/StructureLoot/Epic11.nbt,3,CHEST:4,../JungleNBT/StructureLoot/Epic12.nbt,3,CHEST:4,../JungleNBT/StructureLoot/Epic13.nbt,3,CHEST:4,../JungleNBT/StructureLoot/Epic14.nbt,3,CHEST:4,../JungleNBT/StructureLoot/Epic15.nbt,3,CHEST:4,../JungleNBT/LoreStoryline/JungleLore05.nbt,100)
Block(4,2,1,JUNGLE_FENCE:0)
Block(-6,2,2,JUNGLE_FENCE:0)
RandomBlock(-5,2,2,CHEST:5,../JungleNBT/StructureLoot/JunkChest_1.nbt,25,CHEST:5,../JungleNBT/StructureLoot/JunkChest_2.nbt,25,CHEST:5,../JungleNBT/StructureLoot/JunkChest_3.nbt,25,CHEST:5,../JungleNBT/StructureLoot/JunkChest_4.nbt,25,CHEST:5,../JungleNBT/StructureLoot/JunkChest_5.nbt,25,CHEST:5,../JungleNBT/LoreStoryline/JungleLore05.nbt,2,CHEST:5,../JungleNBT/LoreStoryline/JungleLore04.nbt,2,CHEST:5,../JungleNBT/LoreStoryline/JungleLore03.nbt,2,CHEST:5,../JungleNBT/LoreStoryline/JungleLore02.nbt,2,CHEST:5,../JungleNBT/LoreStoryline/JungleLore01.nbt,2,CHEST:5,../JungleNBT/StructureLoot/Common1.nbt,3,CHEST:5,../JungleNBT/StructureLoot/Common2.nbt,3,CHEST:5,../JungleNBT/StructureLoot/Common3.nbt,3,CHEST:5,../JungleNBT/StructureLoot/Common4.nbt,3,CHEST:5,../JungleNBT/StructureLoot/Common5.nbt,3,CHEST:5,../JungleNBT/StructureLoot/Common5.nbt,3,CHEST:5,../JungleNBT/StructureLoot/Common6.nbt,3,CHEST:5,../JungleNBT/StructureLoot/Common7.nbt,3,CHEST:5,../JungleNBT/StructureLoot/Common8.nbt,3,CHEST:5,../JungleNBT/StructureLoot/Common9.nbt,3,CHEST:5,../JungleNBT/StructureLoot/Common10.nbt,3,CHEST:5,../JungleNBT/StructureLoot/Common11.nbt,3,CHEST:5,../JungleNBT/StructureLoot/Common12.nbt,3,CHEST:5,../JungleNBT/StructureLoot/Common13.nbt,3,CHEST:5,../JungleNBT/StructureLoot/Common14.nbt,3,CHEST:5,../JungleNBT/StructureLoot/Common15.nbt,3,CHEST:5,../JungleNBT/StructureLoot/Rare1.nbt,3,CHEST:5,../JungleNBT/StructureLoot/Rare2.nbt,3,CHEST:5,../JungleNBT/StructureLoot/Rare3.nbt,3,CHEST:5,../JungleNBT/StructureLoot/Rare4.nbt,3,CHEST:5,../JungleNBT/StructureLoot/Rare5.nbt,3,CHEST:5,../JungleNBT/StructureLoot/Rare6.nbt,3,CHEST:5,../JungleNBT/StructureLoot/Rare7.nbt,3,CHEST:5,../JungleNBT/StructureLoot/Rare8.nbt,3,CHEST:5,../JungleNBT/StructureLoot/Rare9.nbt,3,CHEST:5,../JungleNBT/StructureLoot/Rare10.nbt,3,CHEST:5,../JungleNBT/StructureLoot/Rare11.nbt,3,CHEST:5,../JungleNBT/StructureLoot/Rare12.nbt,3,CHEST:5,../JungleNBT/StructureLoot/Rare13.nbt,3,CHEST:5,../JungleNBT/StructureLoot/Rare14.nbt,3,CHEST:5,../JungleNBT/StructureLoot/Rare15.nbt,3,CHEST:5,../JungleNBT/StructureLoot/Epic1.nbt,3,CHEST:5,../JungleNBT/StructureLoot/Epic2.nbt,3,CHEST:5,../JungleNBT/StructureLoot/Epic3.nbt,3,CHEST:5,../JungleNBT/StructureLoot/Epic4.nbt,3,CHEST:5,../JungleNBT/StructureLoot/Epic5.nbt,3,CHEST:5,../JungleNBT/StructureLoot/Epic6.nbt,3,CHEST:5,../JungleNBT/StructureLoot/Epic7.nbt,3,CHEST:5,../JungleNBT/StructureLoot/Epic8.nbt,3,CHEST:5,../JungleNBT/StructureLoot/Epic9.nbt,3,CHEST:5,../JungleNBT/StructureLoot/Epic10.nbt,3,CHEST:5,../JungleNBT/StructureLoot/Epic11.nbt,3,CHEST:5,../JungleNBT/StructureLoot/Epic12.nbt,3,CHEST:5,../JungleNBT/StructureLoot/Epic13.nbt,3,CHEST:5,../JungleNBT/StructureLoot/Epic14.nbt,3,CHEST:5,../JungleNBT/StructureLoot/Epic15.nbt,100)
Block(-2,2,2,JUNGLE_FENCE:0)
Block(-1,2,2,CRAFTING_TABLE:0)
Block(1,2,2,AIR)
Entity(1,2,2,VILLAGER,1,../JungleNBT/entities/tribalnative.txt)
Block(2,2,2,BED:3)
Block(3,2,2,BED:11)
Block(4,2,2,JUNGLE_FENCE:0)
Block(-6,2,3,LOG:3)
Block(-5,2,3,JUNGLE_FENCE:0)
Block(-4,2,3,JUNGLE_FENCE:0)
Block(-3,2,3,JUNGLE_FENCE:0)
Block(-2,2,3,LOG:3)
Block(-1,2,3,JUNGLE_FENCE:0)
Block(0,2,3,JUNGLE_FENCE:0)
Block(1,2,3,JUNGLE_FENCE:0)
Block(2,2,3,JUNGLE_FENCE:0)
Block(3,2,3,JUNGLE_FENCE:0)
Block(4,2,3,LOG:3)
RandomBlock(-1,3,-7,WALL_BANNER:2,../JungleNBT/banners/JungleBanner01.nbt,8,WALL_BANNER:2,../JungleNBT/banners/JungleBanner02.nbt,8,WALL_BANNER:2,../JungleNBT/banners/JungleBanner03.nbt,8,WALL_BANNER:2,../JungleNBT/banners/JungleBanner04.nbt,8,WALL_BANNER:2,../JungleNBT/banners/JungleBanner05.nbt,8,WALL_BANNER:2,../JungleNBT/banners/JungleBanner06.nbt,8,WALL_BANNER:2,../JungleNBT/banners/JungleBanner07.nbt,8,WALL_BANNER:2,../JungleNBT/banners/JungleBanner08.nbt,8,WALL_BANNER:2,../JungleNBT/banners/JungleBanner09.nbt,8,WALL_BANNER:2,../JungleNBT/banners/JungleBanner10.nbt,8,WALL_BANNER:2,../JungleNBT/banners/JungleBanner11.nbt,8,WALL_BANNER:2,../JungleNBT/banners/JungleBanner12.nbt,8,WALL_BANNER:2,../JungleNBT/banners/JungleBanner13.nbt,8,WALL_BANNER:2,../JungleNBT/banners/JungleBanner14.nbt,8,WALL_BANNER:2,../JungleNBT/banners/JungleBanner15.nbt,8,WALL_BANNER:2,../JungleNBT/banners/JungleBanner16.nbt,8,WALL_BANNER:2,../JungleNBT/banners/JungleBanner17.nbt,8,WALL_BANNER:2,../JungleNBT/banners/JungleBanner18.nbt,8,WALL_BANNER:2,../JungleNBT/banners/JungleBanner19.nbt,8,WALL_BANNER:2,../JungleNBT/banners/JungleBanner20.nbt,100)
RandomBlock(0,3,-7,WALL_BANNER:2,../JungleNBT/banners/JungleBanner01.nbt,8,WALL_BANNER:2,../JungleNBT/banners/JungleBanner02.nbt,8,WALL_BANNER:2,../JungleNBT/banners/JungleBanner03.nbt,8,WALL_BANNER:2,../JungleNBT/banners/JungleBanner04.nbt,8,WALL_BANNER:2,../JungleNBT/banners/JungleBanner05.nbt,8,WALL_BANNER:2,../JungleNBT/banners/JungleBanner06.nbt,8,WALL_BANNER:2,../JungleNBT/banners/JungleBanner07.nbt,8,WALL_BANNER:2,../JungleNBT/banners/JungleBanner08.nbt,8,WALL_BANNER:2,../JungleNBT/banners/JungleBanner09.nbt,8,WALL_BANNER:2,../JungleNBT/banners/JungleBanner10.nbt,8,WALL_BANNER:2,../JungleNBT/banners/JungleBanner11.nbt,8,WALL_BANNER:2,../JungleNBT/banners/JungleBanner12.nbt,8,WALL_BANNER:2,../JungleNBT/banners/JungleBanner13.nbt,8,WALL_BANNER:2,../JungleNBT/banners/JungleBanner14.nbt,8,WALL_BANNER:2,../JungleNBT/banners/JungleBanner15.nbt,8,WALL_BANNER:2,../JungleNBT/banners/JungleBanner16.nbt,8,WALL_BANNER:2,../JungleNBT/banners/JungleBanner17.nbt,8,WALL_BANNER:2,../JungleNBT/banners/JungleBanner18.nbt,8,WALL_BANNER:2,../JungleNBT/banners/JungleBanner19.nbt,8,WALL_BANNER:2,../JungleNBT/banners/JungleBanner20.nbt,100)
RandomBlock(1,3,-7,WALL_BANNER:2,../JungleNBT/banners/JungleBanner01.nbt,8,WALL_BANNER:2,../JungleNBT/banners/JungleBanner02.nbt,8,WALL_BANNER:2,../JungleNBT/banners/JungleBanner03.nbt,8,WALL_BANNER:2,../JungleNBT/banners/JungleBanner04.nbt,8,WALL_BANNER:2,../JungleNBT/banners/JungleBanner05.nbt,8,WALL_BANNER:2,../JungleNBT/banners/JungleBanner06.nbt,8,WALL_BANNER:2,../JungleNBT/banners/JungleBanner07.nbt,8,WALL_BANNER:2,../JungleNBT/banners/JungleBanner08.nbt,8,WALL_BANNER:2,../JungleNBT/banners/JungleBanner09.nbt,8,WALL_BANNER:2,../JungleNBT/banners/JungleBanner10.nbt,8,WALL_BANNER:2,../JungleNBT/banners/JungleBanner11.nbt,8,WALL_BANNER:2,../JungleNBT/banners/JungleBanner12.nbt,8,WALL_BANNER:2,../JungleNBT/banners/JungleBanner13.nbt,8,WALL_BANNER:2,../JungleNBT/banners/JungleBanner14.nbt,8,WALL_BANNER:2,../JungleNBT/banners/JungleBanner15.nbt,8,WALL_BANNER:2,../JungleNBT/banners/JungleBanner16.nbt,8,WALL_BANNER:2,../JungleNBT/banners/JungleBanner17.nbt,8,WALL_BANNER:2,../JungleNBT/banners/JungleBanner18.nbt,8,WALL_BANNER:2,../JungleNBT/banners/JungleBanner19.nbt,8,WALL_BANNER:2,../JungleNBT/banners/JungleBanner20.nbt,100)
RandomBlock(2,3,-7,WALL_BANNER:2,../JungleNBT/banners/JungleBanner01.nbt,8,WALL_BANNER:2,../JungleNBT/banners/JungleBanner02.nbt,8,WALL_BANNER:2,../JungleNBT/banners/JungleBanner03.nbt,8,WALL_BANNER:2,../JungleNBT/banners/JungleBanner04.nbt,8,WALL_BANNER:2,../JungleNBT/banners/JungleBanner05.nbt,8,WALL_BANNER:2,../JungleNBT/banners/JungleBanner06.nbt,8,WALL_BANNER:2,../JungleNBT/banners/JungleBanner07.nbt,8,WALL_BANNER:2,../JungleNBT/banners/JungleBanner08.nbt,8,WALL_BANNER:2,../JungleNBT/banners/JungleBanner09.nbt,8,WALL_BANNER:2,../JungleNBT/banners/JungleBanner10.nbt,8,WALL_BANNER:2,../JungleNBT/banners/JungleBanner11.nbt,8,WALL_BANNER:2,../JungleNBT/banners/JungleBanner12.nbt,8,WALL_BANNER:2,../JungleNBT/banners/JungleBanner13.nbt,8,WALL_BANNER:2,../JungleNBT/banners/JungleBanner14.nbt,8,WALL_BANNER:2,../JungleNBT/banners/JungleBanner15.nbt,8,WALL_BANNER:2,../JungleNBT/banners/JungleBanner16.nbt,8,WALL_BANNER:2,../JungleNBT/banners/JungleBanner17.nbt,8,WALL_BANNER:2,../JungleNBT/banners/JungleBanner18.nbt,8,WALL_BANNER:2,../JungleNBT/banners/JungleBanner19.nbt,8,WALL_BANNER:2,../JungleNBT/banners/JungleBanner20.nbt,100)
RandomBlock(3,3,-7,WALL_BANNER:2,../JungleNBT/banners/JungleBanner01.nbt,8,WALL_BANNER:2,../JungleNBT/banners/JungleBanner02.nbt,8,WALL_BANNER:2,../JungleNBT/banners/JungleBanner03.nbt,8,WALL_BANNER:2,../JungleNBT/banners/JungleBanner04.nbt,8,WALL_BANNER:2,../JungleNBT/banners/JungleBanner05.nbt,8,WALL_BANNER:2,../JungleNBT/banners/JungleBanner06.nbt,8,WALL_BANNER:2,../JungleNBT/banners/JungleBanner07.nbt,8,WALL_BANNER:2,../JungleNBT/banners/JungleBanner08.nbt,8,WALL_BANNER:2,../JungleNBT/banners/JungleBanner09.nbt,8,WALL_BANNER:2,../JungleNBT/banners/JungleBanner10.nbt,8,WALL_BANNER:2,../JungleNBT/banners/JungleBanner11.nbt,8,WALL_BANNER:2,../JungleNBT/banners/JungleBanner12.nbt,8,WALL_BANNER:2,../JungleNBT/banners/JungleBanner13.nbt,8,WALL_BANNER:2,../JungleNBT/banners/JungleBanner14.nbt,8,WALL_BANNER:2,../JungleNBT/banners/JungleBanner15.nbt,8,WALL_BANNER:2,../JungleNBT/banners/JungleBanner16.nbt,8,WALL_BANNER:2,../JungleNBT/banners/JungleBanner17.nbt,8,WALL_BANNER:2,../JungleNBT/banners/JungleBanner18.nbt,8,WALL_BANNER:2,../JungleNBT/banners/JungleBanner19.nbt,8,WALL_BANNER:2,../JungleNBT/banners/JungleBanner20.nbt,100)
Block(-2,3,-6,LOG:3)
Block(-1,3,-6,JUNGLE_FENCE:0)
Block(0,3,-6,JUNGLE_FENCE:0)
Block(1,3,-6,JUNGLE_FENCE:0)
Block(2,3,-6,JUNGLE_FENCE:0)
Block(3,3,-6,JUNGLE_FENCE:0)
Block(4,3,-6,LOG:3)
RandomBlock(-3,3,-5,WALL_BANNER:4,../JungleNBT/banners/JungleBanner01.nbt,8,WALL_BANNER:4,../JungleNBT/banners/JungleBanner02.nbt,8,WALL_BANNER:4,../JungleNBT/banners/JungleBanner03.nbt,8,WALL_BANNER:4,../JungleNBT/banners/JungleBanner04.nbt,8,WALL_BANNER:4,../JungleNBT/banners/JungleBanner05.nbt,8,WALL_BANNER:4,../JungleNBT/banners/JungleBanner06.nbt,8,WALL_BANNER:4,../JungleNBT/banners/JungleBanner07.nbt,8,WALL_BANNER:4,../JungleNBT/banners/JungleBanner08.nbt,8,WALL_BANNER:4,../JungleNBT/banners/JungleBanner09.nbt,8,WALL_BANNER:4,../JungleNBT/banners/JungleBanner10.nbt,8,WALL_BANNER:4,../JungleNBT/banners/JungleBanner11.nbt,8,WALL_BANNER:4,../JungleNBT/banners/JungleBanner12.nbt,8,WALL_BANNER:4,../JungleNBT/banners/JungleBanner13.nbt,8,WALL_BANNER:4,../JungleNBT/banners/JungleBanner14.nbt,8,WALL_BANNER:4,../JungleNBT/banners/JungleBanner15.nbt,8,WALL_BANNER:4,../JungleNBT/banners/JungleBanner16.nbt,8,WALL_BANNER:4,../JungleNBT/banners/JungleBanner17.nbt,8,WALL_BANNER:4,../JungleNBT/banners/JungleBanner18.nbt,8,WALL_BANNER:4,../JungleNBT/banners/JungleBanner19.nbt,8,WALL_BANNER:4,../JungleNBT/banners/JungleBanner20.nbt,100)
Block(-2,3,-5,JUNGLE_FENCE:0)
RandomBlock(3,3,-5,FLOWER_POT:0,../JungleNBT/pots/JunglePot01.nbt,10,FLOWER_POT:0,../JungleNBT/pots/JunglePot02.nbt,10,FLOWER_POT:0,../JungleNBT/pots/JunglePot03.nbt,10,FLOWER_POT:0,../JungleNBT/pots/JunglePot04.nbt,10,FLOWER_POT:0,../JungleNBT/pots/JunglePot05.nbt,10,FLOWER_POT:0,../JungleNBT/pots/JunglePot06.nbt,10,FLOWER_POT:0,../JungleNBT/pots/JunglePot07.nbt,10,FLOWER_POT:0,../JungleNBT/pots/JunglePot08.nbt,100)
Block(4,3,-5,JUNGLE_FENCE:0)
RandomBlock(5,3,-5,WALL_BANNER:5,../JungleNBT/banners/JungleBanner01.nbt,8,WALL_BANNER:5,../JungleNBT/banners/JungleBanner02.nbt,8,WALL_BANNER:5,../JungleNBT/banners/JungleBanner03.nbt,8,WALL_BANNER:5,../JungleNBT/banners/JungleBanner04.nbt,8,WALL_BANNER:5,../JungleNBT/banners/JungleBanner05.nbt,8,WALL_BANNER:5,../JungleNBT/banners/JungleBanner06.nbt,8,WALL_BANNER:5,../JungleNBT/banners/JungleBanner07.nbt,8,WALL_BANNER:5,../JungleNBT/banners/JungleBanner08.nbt,8,WALL_BANNER:5,../JungleNBT/banners/JungleBanner09.nbt,8,WALL_BANNER:5,../JungleNBT/banners/JungleBanner10.nbt,8,WALL_BANNER:5,../JungleNBT/banners/JungleBanner11.nbt,8,WALL_BANNER:5,../JungleNBT/banners/JungleBanner12.nbt,8,WALL_BANNER:5,../JungleNBT/banners/JungleBanner13.nbt,8,WALL_BANNER:5,../JungleNBT/banners/JungleBanner14.nbt,8,WALL_BANNER:5,../JungleNBT/banners/JungleBanner15.nbt,8,WALL_BANNER:5,../JungleNBT/banners/JungleBanner16.nbt,8,WALL_BANNER:5,../JungleNBT/banners/JungleBanner17.nbt,8,WALL_BANNER:5,../JungleNBT/banners/JungleBanner18.nbt,8,WALL_BANNER:5,../JungleNBT/banners/JungleBanner19.nbt,8,WALL_BANNER:5,../JungleNBT/banners/JungleBanner20.nbt,100)
Block(-2,3,-4,JUNGLE_FENCE_GATE:7)
Block(4,3,-4,JUNGLE_FENCE:0)
RandomBlock(5,3,-4,WALL_BANNER:5,../JungleNBT/banners/JungleBanner01.nbt,8,WALL_BANNER:5,../JungleNBT/banners/JungleBanner02.nbt,8,WALL_BANNER:5,../JungleNBT/banners/JungleBanner03.nbt,8,WALL_BANNER:5,../JungleNBT/banners/JungleBanner04.nbt,8,WALL_BANNER:5,../JungleNBT/banners/JungleBanner05.nbt,8,WALL_BANNER:5,../JungleNBT/banners/JungleBanner06.nbt,8,WALL_BANNER:5,../JungleNBT/banners/JungleBanner07.nbt,8,WALL_BANNER:5,../JungleNBT/banners/JungleBanner08.nbt,8,WALL_BANNER:5,../JungleNBT/banners/JungleBanner09.nbt,8,WALL_BANNER:5,../JungleNBT/banners/JungleBanner10.nbt,8,WALL_BANNER:5,../JungleNBT/banners/JungleBanner11.nbt,8,WALL_BANNER:5,../JungleNBT/banners/JungleBanner12.nbt,8,WALL_BANNER:5,../JungleNBT/banners/JungleBanner13.nbt,8,WALL_BANNER:5,../JungleNBT/banners/JungleBanner14.nbt,8,WALL_BANNER:5,../JungleNBT/banners/JungleBanner15.nbt,8,WALL_BANNER:5,../JungleNBT/banners/JungleBanner16.nbt,8,WALL_BANNER:5,../JungleNBT/banners/JungleBanner17.nbt,8,WALL_BANNER:5,../JungleNBT/banners/JungleBanner18.nbt,8,WALL_BANNER:5,../JungleNBT/banners/JungleBanner19.nbt,8,WALL_BANNER:5,../JungleNBT/banners/JungleBanner20.nbt,100)
Block(-7,3,-3,WOODEN_SLAB:10)
Block(-6,3,-3,WOODEN_SLAB:10)
RandomBlock(-3,3,-3,WALL_BANNER:4,../JungleNBT/banners/JungleBanner01.nbt,8,WALL_BANNER:4,../JungleNBT/banners/JungleBanner02.nbt,8,WALL_BANNER:4,../JungleNBT/banners/JungleBanner03.nbt,8,WALL_BANNER:4,../JungleNBT/banners/JungleBanner04.nbt,8,WALL_BANNER:4,../JungleNBT/banners/JungleBanner05.nbt,8,WALL_BANNER:4,../JungleNBT/banners/JungleBanner06.nbt,8,WALL_BANNER:4,../JungleNBT/banners/JungleBanner07.nbt,8,WALL_BANNER:4,../JungleNBT/banners/JungleBanner08.nbt,8,WALL_BANNER:4,../JungleNBT/banners/JungleBanner09.nbt,8,WALL_BANNER:4,../JungleNBT/banners/JungleBanner10.nbt,8,WALL_BANNER:4,../JungleNBT/banners/JungleBanner11.nbt,8,WALL_BANNER:4,../JungleNBT/banners/JungleBanner12.nbt,8,WALL_BANNER:4,../JungleNBT/banners/JungleBanner13.nbt,8,WALL_BANNER:4,../JungleNBT/banners/JungleBanner14.nbt,8,WALL_BANNER:4,../JungleNBT/banners/JungleBanner15.nbt,8,WALL_BANNER:4,../JungleNBT/banners/JungleBanner16.nbt,8,WALL_BANNER:4,../JungleNBT/banners/JungleBanner17.nbt,8,WALL_BANNER:4,../JungleNBT/banners/JungleBanner18.nbt,8,WALL_BANNER:4,../JungleNBT/banners/JungleBanner19.nbt,8,WALL_BANNER:4,../JungleNBT/banners/JungleBanner20.nbt,100)
Block(-2,3,-3,JUNGLE_FENCE:0)
Block(4,3,-3,JUNGLE_FENCE:0)
RandomBlock(5,3,-3,WALL_BANNER:5,../JungleNBT/banners/JungleBanner01.nbt,8,WALL_BANNER:5,../JungleNBT/banners/JungleBanner02.nbt,8,WALL_BANNER:5,../JungleNBT/banners/JungleBanner03.nbt,8,WALL_BANNER:5,../JungleNBT/banners/JungleBanner04.nbt,8,WALL_BANNER:5,../JungleNBT/banners/JungleBanner05.nbt,8,WALL_BANNER:5,../JungleNBT/banners/JungleBanner06.nbt,8,WALL_BANNER:5,../JungleNBT/banners/JungleBanner07.nbt,8,WALL_BANNER:5,../JungleNBT/banners/JungleBanner08.nbt,8,WALL_BANNER:5,../JungleNBT/banners/JungleBanner09.nbt,8,WALL_BANNER:5,../JungleNBT/banners/JungleBanner10.nbt,8,WALL_BANNER:5,../JungleNBT/banners/JungleBanner11.nbt,8,WALL_BANNER:5,../JungleNBT/banners/JungleBanner12.nbt,8,WALL_BANNER:5,../JungleNBT/banners/JungleBanner13.nbt,8,WALL_BANNER:5,../JungleNBT/banners/JungleBanner14.nbt,8,WALL_BANNER:5,../JungleNBT/banners/JungleBanner15.nbt,8,WALL_BANNER:5,../JungleNBT/banners/JungleBanner16.nbt,8,WALL_BANNER:5,../JungleNBT/banners/JungleBanner17.nbt,8,WALL_BANNER:5,../JungleNBT/banners/JungleBanner18.nbt,8,WALL_BANNER:5,../JungleNBT/banners/JungleBanner19.nbt,8,WALL_BANNER:5,../JungleNBT/banners/JungleBanner20.nbt,100)
Block(-7,3,-2,WOODEN_SLAB:10)
Block(-6,3,-2,LOG:3)
Block(-3,3,-2,TORCH:5)
Block(-2,3,-2,LOG:3)
Block(-1,3,-2,TORCH:5)
Block(3,3,-2,TORCH:5)
Block(4,3,-2,LOG:3)
Block(-7,3,-1,WOODEN_SLAB:10)
RandomBlock(-3,3,-1,WALL_BANNER:4,../JungleNBT/banners/JungleBanner01.nbt,8,WALL_BANNER:4,../JungleNBT/banners/JungleBanner02.nbt,8,WALL_BANNER:4,../JungleNBT/banners/JungleBanner03.nbt,8,WALL_BANNER:4,../JungleNBT/banners/JungleBanner04.nbt,8,WALL_BANNER:4,../JungleNBT/banners/JungleBanner05.nbt,8,WALL_BANNER:4,../JungleNBT/banners/JungleBanner06.nbt,8,WALL_BANNER:4,../JungleNBT/banners/JungleBanner07.nbt,8,WALL_BANNER:4,../JungleNBT/banners/JungleBanner08.nbt,8,WALL_BANNER:4,../JungleNBT/banners/JungleBanner09.nbt,8,WALL_BANNER:4,../JungleNBT/banners/JungleBanner10.nbt,8,WALL_BANNER:4,../JungleNBT/banners/JungleBanner11.nbt,8,WALL_BANNER:4,../JungleNBT/banners/JungleBanner12.nbt,8,WALL_BANNER:4,../JungleNBT/banners/JungleBanner13.nbt,8,WALL_BANNER:4,../JungleNBT/banners/JungleBanner14.nbt,8,WALL_BANNER:4,../JungleNBT/banners/JungleBanner15.nbt,8,WALL_BANNER:4,../JungleNBT/banners/JungleBanner16.nbt,8,WALL_BANNER:4,../JungleNBT/banners/JungleBanner17.nbt,8,WALL_BANNER:4,../JungleNBT/banners/JungleBanner18.nbt,8,WALL_BANNER:4,../JungleNBT/banners/JungleBanner19.nbt,8,WALL_BANNER:4,../JungleNBT/banners/JungleBanner20.nbt,100)
Block(-2,3,-1,JUNGLE_FENCE:0)
Block(4,3,-1,JUNGLE_FENCE:0)
RandomBlock(5,3,-1,WALL_BANNER:5,../JungleNBT/banners/JungleBanner01.nbt,8,WALL_BANNER:5,../JungleNBT/banners/JungleBanner02.nbt,8,WALL_BANNER:5,../JungleNBT/banners/JungleBanner03.nbt,8,WALL_BANNER:5,../JungleNBT/banners/JungleBanner04.nbt,8,WALL_BANNER:5,../JungleNBT/banners/JungleBanner05.nbt,8,WALL_BANNER:5,../JungleNBT/banners/JungleBanner06.nbt,8,WALL_BANNER:5,../JungleNBT/banners/JungleBanner07.nbt,8,WALL_BANNER:5,../JungleNBT/banners/JungleBanner08.nbt,8,WALL_BANNER:5,../JungleNBT/banners/JungleBanner09.nbt,8,WALL_BANNER:5,../JungleNBT/banners/JungleBanner10.nbt,8,WALL_BANNER:5,../JungleNBT/banners/JungleBanner11.nbt,8,WALL_BANNER:5,../JungleNBT/banners/JungleBanner12.nbt,8,WALL_BANNER:5,../JungleNBT/banners/JungleBanner13.nbt,8,WALL_BANNER:5,../JungleNBT/banners/JungleBanner14.nbt,8,WALL_BANNER:5,../JungleNBT/banners/JungleBanner15.nbt,8,WALL_BANNER:5,../JungleNBT/banners/JungleBanner16.nbt,8,WALL_BANNER:5,../JungleNBT/banners/JungleBanner17.nbt,8,WALL_BANNER:5,../JungleNBT/banners/JungleBanner18.nbt,8,WALL_BANNER:5,../JungleNBT/banners/JungleBanner19.nbt,8,WALL_BANNER:5,../JungleNBT/banners/JungleBanner20.nbt,100)
Block(-7,3,0,WOODEN_SLAB:10)
Block(-2,3,0,JUNGLE_FENCE_GATE:5)
Block(4,3,0,JUNGLE_FENCE:0)
RandomBlock(5,3,0,WALL_BANNER:5,../JungleNBT/banners/JungleBanner01.nbt,8,WALL_BANNER:5,../JungleNBT/banners/JungleBanner02.nbt,8,WALL_BANNER:5,../JungleNBT/banners/JungleBanner03.nbt,8,WALL_BANNER:5,../JungleNBT/banners/JungleBanner04.nbt,8,WALL_BANNER:5,../JungleNBT/banners/JungleBanner05.nbt,8,WALL_BANNER:5,../JungleNBT/banners/JungleBanner06.nbt,8,WALL_BANNER:5,../JungleNBT/banners/JungleBanner07.nbt,8,WALL_BANNER:5,../JungleNBT/banners/JungleBanner08.nbt,8,WALL_BANNER:5,../JungleNBT/banners/JungleBanner09.nbt,8,WALL_BANNER:5,../JungleNBT/banners/JungleBanner10.nbt,8,WALL_BANNER:5,../JungleNBT/banners/JungleBanner11.nbt,8,WALL_BANNER:5,../JungleNBT/banners/JungleBanner12.nbt,8,WALL_BANNER:5,../JungleNBT/banners/JungleBanner13.nbt,8,WALL_BANNER:5,../JungleNBT/banners/JungleBanner14.nbt,8,WALL_BANNER:5,../JungleNBT/banners/JungleBanner15.nbt,8,WALL_BANNER:5,../JungleNBT/banners/JungleBanner16.nbt,8,WALL_BANNER:5,../JungleNBT/banners/JungleBanner17.nbt,8,WALL_BANNER:5,../JungleNBT/banners/JungleBanner18.nbt,8,WALL_BANNER:5,../JungleNBT/banners/JungleBanner19.nbt,8,WALL_BANNER:5,../JungleNBT/banners/JungleBanner20.nbt,100)
Block(-7,3,1,WOODEN_SLAB:10)
RandomBlock(-3,3,1,WALL_BANNER:4,../JungleNBT/banners/JungleBanner01.nbt,8,WALL_BANNER:4,../JungleNBT/banners/JungleBanner02.nbt,8,WALL_BANNER:4,../JungleNBT/banners/JungleBanner03.nbt,8,WALL_BANNER:4,../JungleNBT/banners/JungleBanner04.nbt,8,WALL_BANNER:4,../JungleNBT/banners/JungleBanner05.nbt,8,WALL_BANNER:4,../JungleNBT/banners/JungleBanner06.nbt,8,WALL_BANNER:4,../JungleNBT/banners/JungleBanner07.nbt,8,WALL_BANNER:4,../JungleNBT/banners/JungleBanner08.nbt,8,WALL_BANNER:4,../JungleNBT/banners/JungleBanner09.nbt,8,WALL_BANNER:4,../JungleNBT/banners/JungleBanner10.nbt,8,WALL_BANNER:4,../JungleNBT/banners/JungleBanner11.nbt,8,WALL_BANNER:4,../JungleNBT/banners/JungleBanner12.nbt,8,WALL_BANNER:4,../JungleNBT/banners/JungleBanner13.nbt,8,WALL_BANNER:4,../JungleNBT/banners/JungleBanner14.nbt,8,WALL_BANNER:4,../JungleNBT/banners/JungleBanner15.nbt,8,WALL_BANNER:4,../JungleNBT/banners/JungleBanner16.nbt,8,WALL_BANNER:4,../JungleNBT/banners/JungleBanner17.nbt,8,WALL_BANNER:4,../JungleNBT/banners/JungleBanner18.nbt,8,WALL_BANNER:4,../JungleNBT/banners/JungleBanner19.nbt,8,WALL_BANNER:4,../JungleNBT/banners/JungleBanner20.nbt,100)
Block(-2,3,1,JUNGLE_FENCE:0)
Block(4,3,1,JUNGLE_FENCE:0)
RandomBlock(5,3,1,WALL_BANNER:5,../JungleNBT/banners/JungleBanner01.nbt,8,WALL_BANNER:5,../JungleNBT/banners/JungleBanner02.nbt,8,WALL_BANNER:5,../JungleNBT/banners/JungleBanner03.nbt,8,WALL_BANNER:5,../JungleNBT/banners/JungleBanner04.nbt,8,WALL_BANNER:5,../JungleNBT/banners/JungleBanner05.nbt,8,WALL_BANNER:5,../JungleNBT/banners/JungleBanner06.nbt,8,WALL_BANNER:5,../JungleNBT/banners/JungleBanner07.nbt,8,WALL_BANNER:5,../JungleNBT/banners/JungleBanner08.nbt,8,WALL_BANNER:5,../JungleNBT/banners/JungleBanner09.nbt,8,WALL_BANNER:5,../JungleNBT/banners/JungleBanner10.nbt,8,WALL_BANNER:5,../JungleNBT/banners/JungleBanner11.nbt,8,WALL_BANNER:5,../JungleNBT/banners/JungleBanner12.nbt,8,WALL_BANNER:5,../JungleNBT/banners/JungleBanner13.nbt,8,WALL_BANNER:5,../JungleNBT/banners/JungleBanner14.nbt,8,WALL_BANNER:5,../JungleNBT/banners/JungleBanner15.nbt,8,WALL_BANNER:5,../JungleNBT/banners/JungleBanner16.nbt,8,WALL_BANNER:5,../JungleNBT/banners/JungleBanner17.nbt,8,WALL_BANNER:5,../JungleNBT/banners/JungleBanner18.nbt,8,WALL_BANNER:5,../JungleNBT/banners/JungleBanner19.nbt,8,WALL_BANNER:5,../JungleNBT/banners/JungleBanner20.nbt,100)
Block(-7,3,2,WOODEN_SLAB:10)
RandomBlock(-3,3,2,WALL_BANNER:4,../JungleNBT/banners/JungleBanner01.nbt,8,WALL_BANNER:4,../JungleNBT/banners/JungleBanner02.nbt,8,WALL_BANNER:4,../JungleNBT/banners/JungleBanner03.nbt,8,WALL_BANNER:4,../JungleNBT/banners/JungleBanner04.nbt,8,WALL_BANNER:4,../JungleNBT/banners/JungleBanner05.nbt,8,WALL_BANNER:4,../JungleNBT/banners/JungleBanner06.nbt,8,WALL_BANNER:4,../JungleNBT/banners/JungleBanner07.nbt,8,WALL_BANNER:4,../JungleNBT/banners/JungleBanner08.nbt,8,WALL_BANNER:4,../JungleNBT/banners/JungleBanner09.nbt,8,WALL_BANNER:4,../JungleNBT/banners/JungleBanner10.nbt,8,WALL_BANNER:4,../JungleNBT/banners/JungleBanner11.nbt,8,WALL_BANNER:4,../JungleNBT/banners/JungleBanner12.nbt,8,WALL_BANNER:4,../JungleNBT/banners/JungleBanner13.nbt,8,WALL_BANNER:4,../JungleNBT/banners/JungleBanner14.nbt,8,WALL_BANNER:4,../JungleNBT/banners/JungleBanner15.nbt,8,WALL_BANNER:4,../JungleNBT/banners/JungleBanner16.nbt,8,WALL_BANNER:4,../JungleNBT/banners/JungleBanner17.nbt,8,WALL_BANNER:4,../JungleNBT/banners/JungleBanner18.nbt,8,WALL_BANNER:4,../JungleNBT/banners/JungleBanner19.nbt,8,WALL_BANNER:4,../JungleNBT/banners/JungleBanner20.nbt,100)
Block(-2,3,2,JUNGLE_FENCE:0)
RandomBlock(-1,3,2,FLOWER_POT:0,../JungleNBT/pots/JunglePot01.nbt,10,FLOWER_POT:0,../JungleNBT/pots/JunglePot02.nbt,10,FLOWER_POT:0,../JungleNBT/pots/JunglePot03.nbt,10,FLOWER_POT:0,../JungleNBT/pots/JunglePot04.nbt,10,FLOWER_POT:0,../JungleNBT/pots/JunglePot05.nbt,10,FLOWER_POT:0,../JungleNBT/pots/JunglePot06.nbt,10,FLOWER_POT:0,../JungleNBT/pots/JunglePot07.nbt,10,FLOWER_POT:0,../JungleNBT/pots/JunglePot08.nbt,100)
Block(4,3,2,JUNGLE_FENCE:0)
RandomBlock(5,3,2,WALL_BANNER:5,../JungleNBT/banners/JungleBanner01.nbt,8,WALL_BANNER:5,../JungleNBT/banners/JungleBanner02.nbt,8,WALL_BANNER:5,../JungleNBT/banners/JungleBanner03.nbt,8,WALL_BANNER:5,../JungleNBT/banners/JungleBanner04.nbt,8,WALL_BANNER:5,../JungleNBT/banners/JungleBanner05.nbt,8,WALL_BANNER:5,../JungleNBT/banners/JungleBanner06.nbt,8,WALL_BANNER:5,../JungleNBT/banners/JungleBanner07.nbt,8,WALL_BANNER:5,../JungleNBT/banners/JungleBanner08.nbt,8,WALL_BANNER:5,../JungleNBT/banners/JungleBanner09.nbt,8,WALL_BANNER:5,../JungleNBT/banners/JungleBanner10.nbt,8,WALL_BANNER:5,../JungleNBT/banners/JungleBanner11.nbt,8,WALL_BANNER:5,../JungleNBT/banners/JungleBanner12.nbt,8,WALL_BANNER:5,../JungleNBT/banners/JungleBanner13.nbt,8,WALL_BANNER:5,../JungleNBT/banners/JungleBanner14.nbt,8,WALL_BANNER:5,../JungleNBT/banners/JungleBanner15.nbt,8,WALL_BANNER:5,../JungleNBT/banners/JungleBanner16.nbt,8,WALL_BANNER:5,../JungleNBT/banners/JungleBanner17.nbt,8,WALL_BANNER:5,../JungleNBT/banners/JungleBanner18.nbt,8,WALL_BANNER:5,../JungleNBT/banners/JungleBanner19.nbt,8,WALL_BANNER:5,../JungleNBT/banners/JungleBanner20.nbt,100)
Block(-7,3,3,WOODEN_SLAB:10)
Block(-6,3,3,LOG:3)
Block(-3,3,3,TORCH:5)
Block(-2,3,3,LOG:3)
Block(-1,3,3,JUNGLE_FENCE:0)
Block(0,3,3,JUNGLE_FENCE:0)
Block(1,3,3,JUNGLE_FENCE:0)
Block(2,3,3,JUNGLE_FENCE:0)
Block(3,3,3,JUNGLE_FENCE:0)
Block(4,3,3,LOG:3)
Block(-7,3,4,WOODEN_SLAB:10)
Block(-6,3,4,WOODEN_SLAB:10)
RandomBlock(-1,3,4,WALL_BANNER:3,../JungleNBT/banners/JungleBanner01.nbt,8,WALL_BANNER:3,../JungleNBT/banners/JungleBanner02.nbt,8,WALL_BANNER:3,../JungleNBT/banners/JungleBanner03.nbt,8,WALL_BANNER:3,../JungleNBT/banners/JungleBanner04.nbt,8,WALL_BANNER:3,../JungleNBT/banners/JungleBanner05.nbt,8,WALL_BANNER:3,../JungleNBT/banners/JungleBanner06.nbt,8,WALL_BANNER:3,../JungleNBT/banners/JungleBanner07.nbt,8,WALL_BANNER:3,../JungleNBT/banners/JungleBanner08.nbt,8,WALL_BANNER:3,../JungleNBT/banners/JungleBanner09.nbt,8,WALL_BANNER:3,../JungleNBT/banners/JungleBanner10.nbt,8,WALL_BANNER:3,../JungleNBT/banners/JungleBanner11.nbt,8,WALL_BANNER:3,../JungleNBT/banners/JungleBanner12.nbt,8,WALL_BANNER:3,../JungleNBT/banners/JungleBanner13.nbt,8,WALL_BANNER:3,../JungleNBT/banners/JungleBanner14.nbt,8,WALL_BANNER:3,../JungleNBT/banners/JungleBanner15.nbt,8,WALL_BANNER:3,../JungleNBT/banners/JungleBanner16.nbt,8,WALL_BANNER:3,../JungleNBT/banners/JungleBanner17.nbt,8,WALL_BANNER:3,../JungleNBT/banners/JungleBanner18.nbt,8,WALL_BANNER:3,../JungleNBT/banners/JungleBanner19.nbt,8,WALL_BANNER:3,../JungleNBT/banners/JungleBanner20.nbt,100)
RandomBlock(0,3,4,WALL_BANNER:3,../JungleNBT/banners/JungleBanner01.nbt,8,WALL_BANNER:3,../JungleNBT/banners/JungleBanner02.nbt,8,WALL_BANNER:3,../JungleNBT/banners/JungleBanner03.nbt,8,WALL_BANNER:3,../JungleNBT/banners/JungleBanner04.nbt,8,WALL_BANNER:3,../JungleNBT/banners/JungleBanner05.nbt,8,WALL_BANNER:3,../JungleNBT/banners/JungleBanner06.nbt,8,WALL_BANNER:3,../JungleNBT/banners/JungleBanner07.nbt,8,WALL_BANNER:3,../JungleNBT/banners/JungleBanner08.nbt,8,WALL_BANNER:3,../JungleNBT/banners/JungleBanner09.nbt,8,WALL_BANNER:3,../JungleNBT/banners/JungleBanner10.nbt,8,WALL_BANNER:3,../JungleNBT/banners/JungleBanner11.nbt,8,WALL_BANNER:3,../JungleNBT/banners/JungleBanner12.nbt,8,WALL_BANNER:3,../JungleNBT/banners/JungleBanner13.nbt,8,WALL_BANNER:3,../JungleNBT/banners/JungleBanner14.nbt,8,WALL_BANNER:3,../JungleNBT/banners/JungleBanner15.nbt,8,WALL_BANNER:3,../JungleNBT/banners/JungleBanner16.nbt,8,WALL_BANNER:3,../JungleNBT/banners/JungleBanner17.nbt,8,WALL_BANNER:3,../JungleNBT/banners/JungleBanner18.nbt,8,WALL_BANNER:3,../JungleNBT/banners/JungleBanner19.nbt,8,WALL_BANNER:3,../JungleNBT/banners/JungleBanner20.nbt,100)
RandomBlock(1,3,4,WALL_BANNER:3,../JungleNBT/banners/JungleBanner01.nbt,8,WALL_BANNER:3,../JungleNBT/banners/JungleBanner02.nbt,8,WALL_BANNER:3,../JungleNBT/banners/JungleBanner03.nbt,8,WALL_BANNER:3,../JungleNBT/banners/JungleBanner04.nbt,8,WALL_BANNER:3,../JungleNBT/banners/JungleBanner05.nbt,8,WALL_BANNER:3,../JungleNBT/banners/JungleBanner06.nbt,8,WALL_BANNER:3,../JungleNBT/banners/JungleBanner07.nbt,8,WALL_BANNER:3,../JungleNBT/banners/JungleBanner08.nbt,8,WALL_BANNER:3,../JungleNBT/banners/JungleBanner09.nbt,8,WALL_BANNER:3,../JungleNBT/banners/JungleBanner10.nbt,8,WALL_BANNER:3,../JungleNBT/banners/JungleBanner11.nbt,8,WALL_BANNER:3,../JungleNBT/banners/JungleBanner12.nbt,8,WALL_BANNER:3,../JungleNBT/banners/JungleBanner13.nbt,8,WALL_BANNER:3,../JungleNBT/banners/JungleBanner14.nbt,8,WALL_BANNER:3,../JungleNBT/banners/JungleBanner15.nbt,8,WALL_BANNER:3,../JungleNBT/banners/JungleBanner16.nbt,8,WALL_BANNER:3,../JungleNBT/banners/JungleBanner17.nbt,8,WALL_BANNER:3,../JungleNBT/banners/JungleBanner18.nbt,8,WALL_BANNER:3,../JungleNBT/banners/JungleBanner19.nbt,8,WALL_BANNER:3,../JungleNBT/banners/JungleBanner20.nbt,100)
RandomBlock(2,3,4,WALL_BANNER:3,../JungleNBT/banners/JungleBanner01.nbt,8,WALL_BANNER:3,../JungleNBT/banners/JungleBanner02.nbt,8,WALL_BANNER:3,../JungleNBT/banners/JungleBanner03.nbt,8,WALL_BANNER:3,../JungleNBT/banners/JungleBanner04.nbt,8,WALL_BANNER:3,../JungleNBT/banners/JungleBanner05.nbt,8,WALL_BANNER:3,../JungleNBT/banners/JungleBanner06.nbt,8,WALL_BANNER:3,../JungleNBT/banners/JungleBanner07.nbt,8,WALL_BANNER:3,../JungleNBT/banners/JungleBanner08.nbt,8,WALL_BANNER:3,../JungleNBT/banners/JungleBanner09.nbt,8,WALL_BANNER:3,../JungleNBT/banners/JungleBanner10.nbt,8,WALL_BANNER:3,../JungleNBT/banners/JungleBanner11.nbt,8,WALL_BANNER:3,../JungleNBT/banners/JungleBanner12.nbt,8,WALL_BANNER:3,../JungleNBT/banners/JungleBanner13.nbt,8,WALL_BANNER:3,../JungleNBT/banners/JungleBanner14.nbt,8,WALL_BANNER:3,../JungleNBT/banners/JungleBanner15.nbt,8,WALL_BANNER:3,../JungleNBT/banners/JungleBanner16.nbt,8,WALL_BANNER:3,../JungleNBT/banners/JungleBanner17.nbt,8,WALL_BANNER:3,../JungleNBT/banners/JungleBanner18.nbt,8,WALL_BANNER:3,../JungleNBT/banners/JungleBanner19.nbt,8,WALL_BANNER:3,../JungleNBT/banners/JungleBanner20.nbt,100)
RandomBlock(3,3,4,WALL_BANNER:3,../JungleNBT/banners/JungleBanner01.nbt,8,WALL_BANNER:3,../JungleNBT/banners/JungleBanner02.nbt,8,WALL_BANNER:3,../JungleNBT/banners/JungleBanner03.nbt,8,WALL_BANNER:3,../JungleNBT/banners/JungleBanner04.nbt,8,WALL_BANNER:3,../JungleNBT/banners/JungleBanner05.nbt,8,WALL_BANNER:3,../JungleNBT/banners/JungleBanner06.nbt,8,WALL_BANNER:3,../JungleNBT/banners/JungleBanner07.nbt,8,WALL_BANNER:3,../JungleNBT/banners/JungleBanner08.nbt,8,WALL_BANNER:3,../JungleNBT/banners/JungleBanner09.nbt,8,WALL_BANNER:3,../JungleNBT/banners/JungleBanner10.nbt,8,WALL_BANNER:3,../JungleNBT/banners/JungleBanner11.nbt,8,WALL_BANNER:3,../JungleNBT/banners/JungleBanner12.nbt,8,WALL_BANNER:3,../JungleNBT/banners/JungleBanner13.nbt,8,WALL_BANNER:3,../JungleNBT/banners/JungleBanner14.nbt,8,WALL_BANNER:3,../JungleNBT/banners/JungleBanner15.nbt,8,WALL_BANNER:3,../JungleNBT/banners/JungleBanner16.nbt,8,WALL_BANNER:3,../JungleNBT/banners/JungleBanner17.nbt,8,WALL_BANNER:3,../JungleNBT/banners/JungleBanner18.nbt,8,WALL_BANNER:3,../JungleNBT/banners/JungleBanner19.nbt,8,WALL_BANNER:3,../JungleNBT/banners/JungleBanner20.nbt,100)
Block(-3,4,-7,WOODEN_SLAB:10)
Block(-2,4,-7,WOODEN_SLAB:10)
Block(4,4,-7,WOODEN_SLAB:10)
Block(5,4,-7,WOODEN_SLAB:10)
Block(-3,4,-6,WOODEN_SLAB:10)
Block(-2,4,-6,LOG:3)
Block(-1,4,-6,LOG:7)
Block(0,4,-6,LOG:7)
Block(1,4,-6,LOG:7)
Block(2,4,-6,LOG:7)
Block(3,4,-6,LOG:7)
Block(4,4,-6,LOG:3)
Block(5,4,-6,WOODEN_SLAB:10)
Block(-3,4,-5,WOODEN_SLAB:10)
Block(-2,4,-5,LOG:11)
Block(4,4,-5,LOG:11)
Block(5,4,-5,WOODEN_SLAB:10)
Block(-3,4,-4,WOODEN_SLAB:10)
Block(-2,4,-4,LOG:11)
Block(4,4,-4,LOG:11)
Block(5,4,-4,WOODEN_SLAB:10)
Block(-6,4,-3,WOODEN_SLAB:2)
Block(-5,4,-3,WOODEN_SLAB:2)
Block(-4,4,-3,DOUBLE_WOODEN_SLAB:2)
Block(-3,4,-3,DOUBLE_WOODEN_SLAB:2)
Block(-2,4,-3,LOG:11)
Block(4,4,-3,LOG:11)
Block(5,4,-3,WOODEN_SLAB:10)
Block(-6,4,-2,WOODEN_SLAB:2)
Block(-5,4,-2,DOUBLE_WOODEN_SLAB:2)
Block(-4,4,-2,WOODEN_SLAB:10)
Block(-3,4,-2,WOODEN_SLAB:10)
Block(-2,4,-2,LOG:3)
Block(-1,4,-2,LOG:7)
Block(0,4,-2,LOG:7)
Block(1,4,-2,LOG:7)
Block(2,4,-2,LOG:7)
Block(3,4,-2,LOG:7)
Block(4,4,-2,LOG:3)
Block(5,4,-2,WOODEN_SLAB:10)
Block(-6,4,-1,WOODEN_SLAB:2)
Block(-5,4,-1,WOODEN_SLAB:2)
Block(-4,4,-1,WOODEN_SLAB:10)
Block(-3,4,-1,WOODEN_SLAB:2)
Block(-2,4,-1,LOG:11)
Block(4,4,-1,LOG:11)
Block(5,4,-1,WOODEN_SLAB:10)
Block(-6,4,0,WOODEN_SLAB:2)
Block(-5,4,0,WOODEN_SLAB:2)
Block(-4,4,0,WOODEN_SLAB:2)
Block(-3,4,0,WOODEN_SLAB:2)
Block(-2,4,0,LOG:11)
Block(4,4,0,LOG:11)
Block(5,4,0,WOODEN_SLAB:10)
Block(-6,4,1,WOODEN_SLAB:2)
Block(-5,4,1,WOODEN_SLAB:2)
Block(-4,4,1,WOODEN_SLAB:2)
Block(-3,4,1,WOODEN_SLAB:10)
Block(-2,4,1,LOG:11)
Block(4,4,1,LOG:11)
Block(5,4,1,WOODEN_SLAB:10)
Block(-6,4,2,WOODEN_SLAB:2)
Block(-5,4,2,DOUBLE_WOODEN_SLAB:2)
Block(-4,4,2,WOODEN_SLAB:2)
Block(-3,4,2,WOODEN_SLAB:10)
Block(-2,4,2,LOG:11)
Block(4,4,2,LOG:11)
Block(5,4,2,WOODEN_SLAB:10)
Block(-6,4,3,WOODEN_SLAB:2)
Block(-5,4,3,DOUBLE_WOODEN_SLAB:2)
Block(-4,4,3,WOODEN_SLAB:10)
Block(-3,4,3,WOODEN_SLAB:10)
Block(-2,4,3,LOG:3)
Block(-1,4,3,LOG:7)
Block(0,4,3,LOG:7)
Block(1,4,3,LOG:7)
Block(2,4,3,LOG:7)
Block(3,4,3,LOG:7)
Block(4,4,3,LOG:3)
Block(5,4,3,WOODEN_SLAB:10)
Block(-6,4,4,WOODEN_SLAB:2)
Block(-5,4,4,WOODEN_SLAB:2)
Block(-4,4,4,DOUBLE_WOODEN_SLAB:2)
Block(-3,4,4,WOODEN_SLAB:10)
Block(-2,4,4,WOODEN_SLAB:10)
Block(4,4,4,WOODEN_SLAB:10)
Block(5,4,4,WOODEN_SLAB:10)
Block(-2,5,-7,BIRCH_STAIRS:0)
Block(-1,5,-7,BIRCH_STAIRS:5)
Block(0,5,-7,WOODEN_SLAB:10)
Block(2,5,-7,WOODEN_SLAB:10)
Block(3,5,-7,BIRCH_STAIRS:4)
Block(4,5,-7,BIRCH_STAIRS:1)
Block(-2,5,-6,BIRCH_STAIRS:0)
Block(-1,5,-6,WOODEN_SLAB:10)
Block(0,5,-6,JUNGLE_FENCE:0)
Block(2,5,-6,JUNGLE_FENCE:0)
Block(3,5,-6,WOODEN_SLAB:10)
Block(4,5,-6,BIRCH_STAIRS:1)
Block(-2,5,-5,BIRCH_STAIRS:0)
Block(-1,5,-5,WOODEN_SLAB:10)
Block(2,5,-5,WOODEN_SLAB:9)
Block(3,5,-5,WOODEN_SLAB:1)
Block(4,5,-5,WOODEN_SLAB:1)
Block(-2,5,-4,WOODEN_SLAB:1)
Block(-1,5,-4,WOODEN_SLAB:9)
Block(2,5,-4,WOODEN_SLAB:9)
Block(3,5,-4,WOODEN_SLAB:1)
Block(4,5,-4,WOODEN_SLAB:1)
Block(-2,5,-3,BIRCH_STAIRS:0)
Block(-1,5,-3,WOODEN_SLAB:10)
Block(3,5,-3,WOODEN_SLAB:10)
Block(4,5,-3,BIRCH_STAIRS:1)
Block(-2,5,-2,BIRCH_STAIRS:0)
Block(-1,5,-2,DOUBLE_WOODEN_SLAB:2)
Block(0,5,-2,DOUBLE_WOODEN_SLAB:2)
Block(1,5,-2,DOUBLE_WOODEN_SLAB:2)
Block(2,5,-2,DOUBLE_WOODEN_SLAB:2)
Block(3,5,-2,DOUBLE_WOODEN_SLAB:2)
Block(4,5,-2,BIRCH_STAIRS:1)
Block(-2,5,-1,WOODEN_SLAB:2)
Block(-1,5,-1,WOODEN_SLAB:10)
Block(3,5,-1,WOODEN_SLAB:10)
Block(4,5,-1,BIRCH_STAIRS:1)
Block(-2,5,0,WOODEN_SLAB:2)
Block(-1,5,0,WOODEN_SLAB:10)
Block(3,5,0,WOODEN_SLAB:10)
Block(4,5,0,BIRCH_STAIRS:1)
Block(-2,5,1,BIRCH_STAIRS:0)
Block(-1,5,1,WOODEN_SLAB:10)
Block(3,5,1,WOODEN_SLAB:10)
Block(4,5,1,WOODEN_SLAB:1)
Block(-2,5,2,BIRCH_STAIRS:0)
Block(-1,5,2,WOODEN_SLAB:10)
Block(3,5,2,WOODEN_SLAB:10)
Block(4,5,2,WOODEN_SLAB:1)
Block(-2,5,3,BIRCH_STAIRS:0)
Block(-1,5,3,WOODEN_SLAB:10)
Block(0,5,3,JUNGLE_FENCE:0)
Block(2,5,3,JUNGLE_FENCE:0)
Block(3,5,3,WOODEN_SLAB:10)
Block(4,5,3,WOODEN_SLAB:1)
Block(-2,5,4,BIRCH_STAIRS:0)
Block(-1,5,4,BIRCH_STAIRS:5)
Block(0,5,4,WOODEN_SLAB:10)
Block(2,5,4,WOODEN_SLAB:10)
Block(3,5,4,BIRCH_STAIRS:4)
Block(4,5,4,WOODEN_SLAB:1)
Block(0,6,-7,BIRCH_STAIRS:0)
Block(1,6,-7,WOODEN_SLAB:10)
Block(2,6,-7,BIRCH_STAIRS:1)
Block(0,6,-6,BIRCH_STAIRS:0)
Block(1,6,-6,WOODEN_SLAB:10)
Block(2,6,-6,BIRCH_STAIRS:1)
Block(0,6,-5,WOODEN_SLAB:1)
Block(1,6,-5,WOODEN_SLAB:1)
Block(2,6,-5,WOODEN_SLAB:2)
Block(0,6,-4,BIRCH_STAIRS:0)
Block(1,6,-4,WOODEN_SLAB:1)
Block(0,6,-3,BIRCH_STAIRS:0)
Block(1,6,-3,WOODEN_SLAB:10)
Block(2,6,-3,BIRCH_STAIRS:1)
Block(0,6,-2,BIRCH_STAIRS:0)
Block(1,6,-2,DOUBLE_WOODEN_SLAB:2)
Block(2,6,-2,BIRCH_STAIRS:1)
Block(3,6,-2,WOODEN_SLAB:2)
Block(0,6,-1,BIRCH_STAIRS:0)
Block(1,6,-1,WOODEN_SLAB:10)
Block(2,6,-1,BIRCH_STAIRS:1)
Block(3,6,-1,WOODEN_SLAB:2)
Block(0,6,0,BIRCH_STAIRS:0)
Block(1,6,0,WOODEN_SLAB:10)
Block(2,6,0,BIRCH_STAIRS:1)
Block(-1,6,1,WOODEN_SLAB:2)
Block(0,6,1,BIRCH_STAIRS:0)
Block(1,6,1,WOODEN_SLAB:10)
Block(2,6,1,BIRCH_STAIRS:1)
Block(-1,6,2,WOODEN_SLAB:2)
Block(0,6,2,BIRCH_STAIRS:0)
Block(1,6,2,WOODEN_SLAB:10)
Block(2,6,2,BIRCH_STAIRS:1)
Block(-1,6,3,WOODEN_SLAB:2)
Block(0,6,3,BIRCH_STAIRS:0)
Block(1,6,3,WOODEN_SLAB:10)
Block(2,6,3,BIRCH_STAIRS:1)
Block(0,6,4,BIRCH_STAIRS:0)
Block(1,6,4,WOODEN_SLAB:10)
Block(2,6,4,BIRCH_STAIRS:1)
Block(1,7,-1,WOODEN_SLAB:2)
Block(1,7,0,WOODEN_SLAB:2)
