#######################################################################
# +-----------------------------------------------------------------+ #
# |                            BO3 object                           | #
# +-----------------------------------------------------------------+ #
#######################################################################

Author: Bo3 BulkEdit

Description: Converted Schematic - Modified by Bo3BulkEdit

Version: 3

SettingsMode: WriteDisable

#######################################################################
# +-----------------------------------------------------------------+ #
# |                          Main settings                          | #
# +-----------------------------------------------------------------+ #
#######################################################################

IsOTGPlus: true
Tree: false
Frequency: 1
Rarity: 100.0
RotateRandomly: false
SpawnHeight: randomY
MaxBranchDepth: 10
ExcludedBiomes: All

##############################
# Height Limits for the BO3. #
##############################

MinHeight: 0
MaxHeight: 255

#######################################################################
# +-----------------------------------------------------------------+ #
# |                      Source block settings                      | #
# +-----------------------------------------------------------------+ #
#######################################################################

CanOverride: true
MaxPercentageOutsideSourceBlock: 100
OutsideSourceBlock: placeAnyway

#######################################################################
# +-----------------------------------------------------------------+ #
# |                               OTG+                              | #
# +-----------------------------------------------------------------+ #
#######################################################################

BO3Group: CeilingCrystals:0

#######################################################################
# +-----------------------------------------------------------------+ #
# |                              Blocks                             | #
# +-----------------------------------------------------------------+ #
#######################################################################

B(0,750,0,AIR)
B(15,750,15,AIR)
B(10,-40,13,STAINED_GLASS:15)
B(11,-40,13,STAINED_GLASS:15)
B(10,-40,14,STAINED_GLASS:15)
B(11,-40,14,STAINED_GLASS:15)
B(9,-39,12,STAINED_GLASS:15)
B(10,-39,12,STAINED_GLASS:15)
B(11,-39,12,STAINED_GLASS:15)
B(9,-39,13,STAINED_GLASS:15)
B(10,-39,13,STAINED_GLASS:15)
B(11,-39,13,STAINED_GLASS:15)
B(10,-39,14,STAINED_GLASS:15)
B(11,-39,14,STAINED_GLASS:15)
B(8,-38,11,STAINED_GLASS:15)
B(9,-38,11,STAINED_GLASS:15)
B(10,-38,11,STAINED_GLASS:15)
B(11,-38,11,STAINED_GLASS:15)
B(8,-38,12,STAINED_GLASS:15)
B(9,-38,12,STAINED_GLASS:15)
B(10,-38,12,STAINED_GLASS:15)
B(11,-38,12,STAINED_GLASS:15)
B(12,-38,12,STAINED_GLASS:15)
B(9,-38,13,STAINED_GLASS:15)
B(10,-38,13,STAINED_GLASS:15)
B(11,-38,13,STAINED_GLASS:15)
B(12,-38,13,STAINED_GLASS:15)
B(9,-38,14,STAINED_GLASS:15)
B(10,-38,14,STAINED_GLASS:15)
B(11,-38,14,STAINED_GLASS:15)
B(9,-37,9,STAINED_GLASS:15)
B(10,-37,9,STAINED_GLASS:15)
B(7,-37,10,STAINED_GLASS:15)
B(8,-37,10,STAINED_GLASS:15)
B(9,-37,10,STAINED_GLASS:15)
B(10,-37,10,STAINED_GLASS:15)
B(11,-37,10,STAINED_GLASS:15)
B(7,-37,11,STAINED_GLASS:15)
B(8,-37,11,STAINED_GLASS:15)
B(9,-37,11,STAINED_GLASS:15)
B(10,-37,11,STAINED_GLASS:15)
B(11,-37,11,STAINED_GLASS:15)
B(12,-37,11,STAINED_GLASS:15)
B(7,-37,12,PURPLE_GLAZED_TERRACOTTA:2)
B(8,-37,12,STAINED_GLASS:15)
B(9,-37,12,STAINED_GLASS:15)
B(10,-37,12,SEA_LANTERN)
B(11,-37,12,STAINED_GLASS:15)
B(12,-37,12,STAINED_GLASS:15)
B(8,-37,13,STAINED_GLASS:15)
B(9,-37,13,STAINED_GLASS:15)
B(10,-37,13,STAINED_GLASS:15)
B(11,-37,13,STAINED_GLASS:15)
B(9,-37,14,STAINED_GLASS:15)
B(10,-37,14,STAINED_GLASS:15)
B(8,-36,8,STAINED_GLASS:15)
B(10,-36,8,STAINED_GLASS:15)
B(6,-36,9,STAINED_GLASS:15)
B(7,-36,9,STAINED_GLASS:15)
B(8,-36,9,STAINED_GLASS:15)
B(9,-36,9,STAINED_GLASS:15)
B(10,-36,9,STAINED_GLASS:15)
B(6,-36,10,STAINED_GLASS:15)
B(7,-36,10,STAINED_GLASS:15)
B(8,-36,10,STAINED_GLASS:15)
B(9,-36,10,STAINED_GLASS:15)
B(10,-36,10,STAINED_GLASS:15)
B(11,-36,10,STAINED_GLASS:15)
B(12,-36,10,STAINED_GLASS:15)
B(7,-36,11,STAINED_GLASS:15)
B(8,-36,11,STAINED_GLASS:15)
B(9,-36,11,SEA_LANTERN)
B(10,-36,11,STAINED_GLASS:15)
B(11,-36,11,STAINED_GLASS:15)
B(12,-36,11,STAINED_GLASS:15)
B(7,-36,12,PURPLE_GLAZED_TERRACOTTA:2)
B(8,-36,12,STAINED_GLASS:15)
B(9,-36,12,STAINED_GLASS:15)
B(10,-36,12,PURPLE_GLAZED_TERRACOTTA:2)
B(11,-36,12,STAINED_GLASS:15)
B(7,-36,13,STAINED_GLASS:15)
B(8,-36,13,STAINED_GLASS:15)
B(9,-36,13,STAINED_GLASS:15)
B(10,-36,13,STAINED_GLASS:15)
B(11,-36,13,STAINED_GLASS:15)
B(10,-36,14,STAINED_GLASS:15)
B(11,-35,6,STAINED_GLASS:15)
B(7,-35,7,STAINED_GLASS:15)
B(8,-35,7,STAINED_GLASS:15)
B(9,-35,7,STAINED_GLASS:15)
B(10,-35,7,STAINED_GLASS:15)
B(6,-35,8,STAINED_GLASS:15)
B(7,-35,8,STAINED_GLASS:15)
B(8,-35,8,STAINED_GLASS:15)
B(9,-35,8,STAINED_GLASS:15)
B(10,-35,8,STAINED_GLASS:15)
B(6,-35,9,STAINED_GLASS:15)
B(7,-35,9,STAINED_GLASS:15)
B(8,-35,9,STAINED_GLASS:15)
B(9,-35,9,STAINED_GLASS:15)
B(10,-35,9,STAINED_GLASS:15)
B(11,-35,9,STAINED_GLASS:15)
B(12,-35,9,STAINED_GLASS:15)
B(6,-35,10,STAINED_GLASS:15)
B(7,-35,10,STAINED_GLASS:15)
B(8,-35,10,PURPLE_GLAZED_TERRACOTTA:2)
B(9,-35,10,SEA_LANTERN)
B(10,-35,10,STAINED_GLASS:15)
B(11,-35,10,STAINED_GLASS:15)
B(12,-35,10,STAINED_GLASS:15)
B(7,-35,11,STAINED_GLASS:15)
B(8,-35,11,PURPLE_GLAZED_TERRACOTTA:2)
B(9,-35,11,PURPLE_GLAZED_TERRACOTTA:2)
B(10,-35,11,PURPLE_GLAZED_TERRACOTTA:2)
B(11,-35,11,STAINED_GLASS:10)
B(12,-35,11,STAINED_GLASS:10)
B(7,-35,12,PURPLE_GLAZED_TERRACOTTA:2)
B(8,-35,12,STAINED_GLASS:15)
B(9,-35,12,PURPLE_GLAZED_TERRACOTTA:2)
B(10,-35,12,STAINED_GLASS:15)
B(11,-35,12,STAINED_GLASS:15)
B(7,-35,13,STAINED_GLASS:15)
B(9,-35,13,STAINED_GLASS:15)
B(10,-34,5,STAINED_GLASS:15)
B(7,-34,6,STAINED_GLASS:15)
B(9,-34,6,STAINED_GLASS:15)
B(10,-34,6,STAINED_GLASS:15)
B(11,-34,6,STAINED_GLASS:15)
B(6,-34,7,STAINED_GLASS:15)
B(7,-34,7,STAINED_GLASS:15)
B(8,-34,7,STAINED_GLASS:15)
B(9,-34,7,STAINED_GLASS:15)
B(10,-34,7,STAINED_GLASS:15)
B(11,-34,7,STAINED_GLASS:15)
B(6,-34,8,STAINED_GLASS:15)
B(7,-34,8,STAINED_GLASS:15)
B(8,-34,8,STAINED_GLASS:15)
B(9,-34,8,SEA_LANTERN)
B(10,-34,8,STAINED_GLASS:15)
B(11,-34,8,STAINED_GLASS:15)
B(12,-34,8,STAINED_GLASS:15)
B(6,-34,9,STAINED_GLASS:15)
B(7,-34,9,STAINED_GLASS:10)
B(8,-34,9,SEA_LANTERN)
B(9,-34,9,SEA_LANTERN)
B(10,-34,9,STAINED_GLASS:15)
B(11,-34,9,STAINED_GLASS:15)
B(12,-34,9,STAINED_GLASS:15)
B(13,-34,9,STAINED_GLASS:15)
B(5,-34,10,STAINED_GLASS:15)
B(6,-34,10,STAINED_GLASS:15)
B(7,-34,10,PURPLE_GLAZED_TERRACOTTA:2)
B(8,-34,10,PURPLE_GLAZED_TERRACOTTA:2)
B(9,-34,10,SEA_LANTERN)
B(10,-34,10,PURPLE_GLAZED_TERRACOTTA:2)
B(11,-34,10,PURPLE_GLAZED_TERRACOTTA:2)
B(12,-34,10,STAINED_GLASS:15)
B(6,-34,11,STAINED_GLASS:15)
B(7,-34,11,PURPLE_GLAZED_TERRACOTTA:2)
B(8,-34,11,PURPLE_GLAZED_TERRACOTTA:2)
B(9,-34,11,PURPLE_GLAZED_TERRACOTTA:2)
B(10,-34,11,STAINED_GLASS:15)
B(11,-34,11,STAINED_GLASS:15)
B(12,-34,11,STAINED_GLASS:15)
B(7,-34,12,STAINED_GLASS:15)
B(8,-34,12,STAINED_GLASS:15)
B(9,-34,12,STAINED_GLASS:15)
B(10,-34,12,STAINED_GLASS:15)
B(8,-33,5,STAINED_GLASS:15)
B(9,-33,5,STAINED_GLASS:15)
B(10,-33,5,STAINED_GLASS:10)
B(5,-33,6,STAINED_GLASS:15)
B(6,-33,6,STAINED_GLASS:15)
B(7,-33,6,STAINED_GLASS:10)
B(8,-33,6,STAINED_GLASS:15)
B(9,-33,6,STAINED_GLASS:14)
B(10,-33,6,STAINED_GLASS:10)
B(11,-33,6,STAINED_GLASS:15)
B(6,-33,7,STAINED_GLASS:10)
B(7,-33,7,STAINED_GLASS:10)
B(8,-33,7,STAINED_GLASS:10)
B(9,-33,7,SEA_LANTERN)
B(10,-33,7,STAINED_GLASS:10)
B(11,-33,7,STAINED_GLASS:15)
B(6,-33,8,STAINED_GLASS:10)
B(7,-33,8,STAINED_GLASS:10)
B(8,-33,8,SEA_LANTERN)
B(9,-33,8,SEA_LANTERN)
B(10,-33,8,PURPLE_GLAZED_TERRACOTTA:2)
B(11,-33,8,PURPLE_GLAZED_TERRACOTTA:2)
B(12,-33,8,STAINED_GLASS:15)
B(6,-33,9,STAINED_GLASS:15)
B(7,-33,9,STAINED_GLASS:10)
B(8,-33,9,SEA_LANTERN)
B(9,-33,9,PURPLE_GLAZED_TERRACOTTA:2)
B(10,-33,9,PURPLE_GLAZED_TERRACOTTA:2)
B(11,-33,9,PURPLE_GLAZED_TERRACOTTA:2)
B(12,-33,9,STAINED_GLASS:15)
B(5,-33,10,STAINED_GLASS:15)
B(6,-33,10,STAINED_GLASS:15)
B(7,-33,10,PURPLE_GLAZED_TERRACOTTA:2)
B(8,-33,10,PURPLE_GLAZED_TERRACOTTA:2)
B(9,-33,10,PURPLE_GLAZED_TERRACOTTA:2)
B(10,-33,10,PURPLE_GLAZED_TERRACOTTA:2)
B(11,-33,10,PURPLE_GLAZED_TERRACOTTA:2)
B(12,-33,10,STAINED_GLASS:15)
B(7,-33,11,PURPLE_GLAZED_TERRACOTTA:2)
B(8,-33,11,STAINED_GLASS:15)
B(9,-33,11,STAINED_GLASS:15)
B(10,-33,11,STAINED_GLASS:15)
B(9,-33,12,STAINED_GLASS:15)
B(10,-32,4,STAINED_GLASS:15)
B(6,-32,5,STAINED_GLASS:15)
B(7,-32,5,STAINED_GLASS:15)
B(8,-32,5,STAINED_GLASS:14)
B(9,-32,5,STAINED_GLASS:14)
B(10,-32,5,STAINED_GLASS:10)
B(5,-32,6,STAINED_GLASS:15)
B(6,-32,6,STAINED_GLASS:10)
B(7,-32,6,STAINED_GLASS:10)
B(8,-32,6,STAINED_GLASS:14)
B(9,-32,6,STAINED_GLASS:14)
B(10,-32,6,STAINED_GLASS:10)
B(11,-32,6,STAINED_GLASS:15)
B(6,-32,7,STAINED_GLASS:10)
B(7,-32,7,STAINED_GLASS:10)
B(8,-32,7,SEA_LANTERN)
B(9,-32,7,SEA_LANTERN)
B(10,-32,7,PURPLE_GLAZED_TERRACOTTA:2)
B(11,-32,7,STAINED_GLASS:15)
B(12,-32,7,STAINED_GLASS:15)
B(5,-32,8,STAINED_GLASS:15)
B(6,-32,8,STAINED_GLASS:10)
B(7,-32,8,STAINED_GLASS:10)
B(8,-32,8,SEA_LANTERN)
B(9,-32,8,SEA_LANTERN)
B(10,-32,8,PURPLE_GLAZED_TERRACOTTA:2)
B(11,-32,8,PURPLE_GLAZED_TERRACOTTA:2)
B(12,-32,8,STAINED_GLASS:15)
B(6,-32,9,STAINED_GLASS:15)
B(7,-32,9,STAINED_GLASS:10)
B(8,-32,9,PURPLE_GLAZED_TERRACOTTA:2)
B(9,-32,9,PURPLE_GLAZED_TERRACOTTA:2)
B(10,-32,9,PURPLE_GLAZED_TERRACOTTA:2)
B(11,-32,9,STAINED_GLASS:15)
B(12,-32,9,STAINED_GLASS:15)
B(5,-32,10,STAINED_GLASS:15)
B(6,-32,10,STAINED_GLASS:15)
B(7,-32,10,PURPLE_GLAZED_TERRACOTTA:2)
B(8,-32,10,PURPLE_GLAZED_TERRACOTTA:2)
B(9,-32,10,PURPLE_GLAZED_TERRACOTTA:2)
B(10,-32,10,STAINED_GLASS:15)
B(11,-32,10,STAINED_GLASS:15)
B(7,-32,11,STAINED_GLASS:15)
B(9,-32,11,STAINED_GLASS:15)
B(10,-31,3,STAINED_GLASS:15)
B(6,-31,4,STAINED_GLASS:15)
B(7,-31,4,STAINED_GLASS:15)
B(8,-31,4,STAINED_GLASS:15)
B(9,-31,4,STAINED_GLASS:15)
B(10,-31,4,STAINED_GLASS:14)
B(5,-31,5,STAINED_GLASS:15)
B(6,-31,5,STAINED_GLASS:10)
B(7,-31,5,STAINED_GLASS:14)
B(8,-31,5,STAINED_GLASS:14)
B(9,-31,5,STAINED_GLASS:14)
B(10,-31,5,PURPLE_GLAZED_TERRACOTTA:2)
B(5,-31,6,STAINED_GLASS:15)
B(6,-31,6,STAINED_GLASS:10)
B(7,-31,6,SEA_LANTERN)
B(8,-31,6,STAINED_GLASS:14)
B(9,-31,6,SEA_LANTERN)
B(10,-31,6,PURPLE_GLAZED_TERRACOTTA:2)
B(11,-31,6,STAINED_GLASS:15)
B(6,-31,7,STAINED_GLASS:10)
B(7,-31,7,STAINED_GLASS:10)
B(8,-31,7,SEA_LANTERN)
B(9,-31,7,SEA_LANTERN)
B(10,-31,7,PURPLE_GLAZED_TERRACOTTA:2)
B(11,-31,7,STAINED_GLASS:15)
B(12,-31,7,STAINED_GLASS:15)
B(5,-31,8,STAINED_GLASS:15)
B(6,-31,8,STAINED_GLASS:10)
B(7,-31,8,STAINED_GLASS:10)
B(8,-31,8,SEA_LANTERN)
B(9,-31,8,PURPLE_GLAZED_TERRACOTTA:2)
B(10,-31,8,PURPLE_GLAZED_TERRACOTTA:2)
B(11,-31,8,PURPLE_GLAZED_TERRACOTTA:2)
B(6,-31,9,STAINED_GLASS:15)
B(7,-31,9,STAINED_GLASS:10)
B(8,-31,9,PURPLE_GLAZED_TERRACOTTA:2)
B(9,-31,9,STAINED_GLASS:15)
B(10,-31,9,STAINED_GLASS:15)
B(12,-31,9,STAINED_GLASS:15)
B(6,-31,10,STAINED_GLASS:15)
B(7,-31,10,STAINED_GLASS:15)
B(8,-31,10,STAINED_GLASS:15)
B(9,-31,10,STAINED_GLASS:15)
B(10,-31,10,STAINED_GLASS:15)
B(8,-30,3,STAINED_GLASS:15)
B(9,-30,3,STAINED_GLASS:15)
B(10,-30,3,STAINED_GLASS:15)
B(5,-30,4,STAINED_GLASS:15)
B(6,-30,4,STAINED_GLASS:14)
B(7,-30,4,STAINED_GLASS:14)
B(8,-30,4,STAINED_GLASS:14)
B(9,-30,4,STAINED_GLASS:14)
B(10,-30,4,STAINED_GLASS:14)
B(5,-30,5,STAINED_GLASS:15)
B(6,-30,5,STAINED_GLASS:10)
B(7,-30,5,STAINED_GLASS:14)
B(8,-30,5,SEA_LANTERN)
B(9,-30,5,STAINED_GLASS:14)
B(10,-30,5,PURPLE_GLAZED_TERRACOTTA:2)
B(11,-30,5,STAINED_GLASS:15)
B(12,-30,5,STAINED_GLASS:15)
B(5,-30,6,STAINED_GLASS:15)
B(6,-30,6,STAINED_GLASS:10)
B(7,-30,6,SEA_LANTERN)
B(8,-30,6,SEA_LANTERN)
B(9,-30,6,SEA_LANTERN)
B(10,-30,6,PURPLE_GLAZED_TERRACOTTA:2)
B(11,-30,6,STAINED_GLASS:15)
B(5,-30,7,STAINED_GLASS:15)
B(6,-30,7,STAINED_GLASS:10)
B(7,-30,7,STAINED_GLASS:10)
B(8,-30,7,SEA_LANTERN)
B(9,-30,7,PURPLE_GLAZED_TERRACOTTA:2)
B(10,-30,7,PURPLE_GLAZED_TERRACOTTA:2)
B(11,-30,7,STAINED_GLASS:15)
B(12,-30,7,STAINED_GLASS:15)
B(5,-30,8,STAINED_GLASS:15)
B(6,-30,8,STAINED_GLASS:10)
B(7,-30,8,STAINED_GLASS:10)
B(8,-30,8,STAINED_GLASS:10)
B(9,-30,8,STAINED_GLASS:10)
B(10,-30,8,PURPLE_GLAZED_TERRACOTTA:2)
B(11,-30,8,STAINED_GLASS:15)
B(6,-30,9,STAINED_GLASS:15)
B(7,-30,9,STAINED_GLASS:15)
B(8,-30,9,STAINED_GLASS:15)
B(9,-30,9,STAINED_GLASS:15)
B(9,-30,10,STAINED_GLASS:15)
B(7,-29,2,STAINED_GLASS:15)
B(9,-29,2,STAINED_GLASS:15)
B(10,-29,2,STAINED_GLASS:15)
B(6,-29,3,STAINED_GLASS:15)
B(7,-29,3,STAINED_GLASS:15)
B(8,-29,3,STAINED_GLASS:14)
B(9,-29,3,STAINED_GLASS:10)
B(10,-29,3,STAINED_GLASS:15)
B(5,-29,4,STAINED_GLASS:14)
B(6,-29,4,STAINED_GLASS:14)
B(7,-29,4,STAINED_GLASS:14)
B(8,-29,4,STAINED_GLASS:14)
B(9,-29,4,STAINED_GLASS:10)
B(10,-29,4,STAINED_GLASS:10)
B(5,-29,5,STAINED_GLASS:15)
B(6,-29,5,STAINED_GLASS:10)
B(7,-29,5,SEA_LANTERN)
B(8,-29,5,SEA_LANTERN)
B(9,-29,5,STAINED_GLASS:10)
B(10,-29,5,PURPLE_GLAZED_TERRACOTTA:2)
B(11,-29,5,STAINED_GLASS:15)
B(12,-29,5,STAINED_GLASS:15)
B(5,-29,6,STAINED_GLASS:15)
B(6,-29,6,STAINED_GLASS:10)
B(7,-29,6,SEA_LANTERN)
B(8,-29,6,SEA_LANTERN)
B(9,-29,6,SEA_LANTERN)
B(10,-29,6,PURPLE_GLAZED_TERRACOTTA:2)
B(11,-29,6,STAINED_GLASS:15)
B(5,-29,7,STAINED_GLASS:15)
B(6,-29,7,STAINED_GLASS:10)
B(7,-29,7,STAINED_GLASS:10)
B(8,-29,7,STAINED_GLASS:10)
B(9,-29,7,PURPLE_GLAZED_TERRACOTTA:2)
B(10,-29,7,PURPLE_GLAZED_TERRACOTTA:2)
B(11,-29,7,STAINED_GLASS:15)
B(6,-29,8,STAINED_GLASS:10)
B(7,-29,8,STAINED_GLASS:15)
B(8,-29,8,STAINED_GLASS:10)
B(9,-29,8,STAINED_GLASS:15)
B(10,-29,8,STAINED_GLASS:15)
B(6,-29,9,STAINED_GLASS:15)
B(8,-29,9,STAINED_GLASS:15)
B(9,-28,1,STAINED_GLASS:15)
B(5,-28,2,STAINED_GLASS:15)
B(6,-28,2,STAINED_GLASS:15)
B(7,-28,2,STAINED_GLASS:14)
B(8,-28,2,STAINED_GLASS:15)
B(9,-28,2,STAINED_GLASS:10)
B(10,-28,2,STAINED_GLASS:15)
B(5,-28,3,STAINED_GLASS:15)
B(6,-28,3,STAINED_GLASS:14)
B(7,-28,3,STAINED_GLASS:14)
B(8,-28,3,STAINED_GLASS:10)
B(9,-28,3,STAINED_GLASS:10)
B(10,-28,3,STAINED_GLASS:15)
B(5,-28,4,STAINED_GLASS:14)
B(6,-28,4,STAINED_GLASS:14)
B(7,-28,4,SEA_LANTERN)
B(8,-28,4,SEA_LANTERN)
B(9,-28,4,STAINED_GLASS:10)
B(10,-28,4,STAINED_GLASS:10)
B(11,-28,4,STAINED_GLASS:15)
B(5,-28,5,STAINED_GLASS:15)
B(6,-28,5,STAINED_GLASS:10)
B(7,-28,5,SEA_LANTERN)
B(8,-28,5,SEA_LANTERN)
B(9,-28,5,STAINED_GLASS:10)
B(10,-28,5,STAINED_GLASS:10)
B(11,-28,5,STAINED_GLASS:15)
B(12,-28,5,STAINED_GLASS:15)
B(4,-28,6,STAINED_GLASS:15)
B(5,-28,6,STAINED_GLASS:15)
B(6,-28,6,STAINED_GLASS:10)
B(7,-28,6,STAINED_GLASS:10)
B(8,-28,6,SEA_LANTERN)
B(9,-28,6,STAINED_GLASS:14)
B(10,-28,6,STAINED_GLASS:10)
B(11,-28,6,STAINED_GLASS:15)
B(5,-28,7,STAINED_GLASS:15)
B(6,-28,7,STAINED_GLASS:10)
B(7,-28,7,STAINED_GLASS:10)
B(8,-28,7,STAINED_GLASS:14)
B(9,-28,7,STAINED_GLASS:15)
B(10,-28,7,STAINED_GLASS:15)
B(6,-28,8,STAINED_GLASS:15)
B(8,-28,8,STAINED_GLASS:15)
B(9,-28,8,STAINED_GLASS:15)
B(7,-27,1,STAINED_GLASS:15)
B(8,-27,1,STAINED_GLASS:15)
B(9,-27,1,STAINED_GLASS:10)
B(4,-27,2,STAINED_GLASS:15)
B(5,-27,2,STAINED_GLASS:14)
B(6,-27,2,STAINED_GLASS:14)
B(7,-27,2,STAINED_GLASS:14)
B(8,-27,2,STAINED_GLASS:10)
B(9,-27,2,STAINED_GLASS:10)
B(10,-27,2,STAINED_GLASS:15)
B(5,-27,3,STAINED_GLASS:14)
B(6,-27,3,STAINED_GLASS:14)
B(7,-27,3,STAINED_GLASS:14)
B(8,-27,3,SEA_LANTERN)
B(9,-27,3,STAINED_GLASS:10)
B(10,-27,3,STAINED_GLASS:15)
B(5,-27,4,STAINED_GLASS:14)
B(6,-27,4,STAINED_GLASS:14)
B(7,-27,4,SEA_LANTERN)
B(8,-27,4,SEA_LANTERN)
B(9,-27,4,STAINED_GLASS:10)
B(10,-27,4,STAINED_GLASS:10)
B(11,-27,4,STAINED_GLASS:15)
B(5,-27,5,STAINED_GLASS:15)
B(6,-27,5,STAINED_GLASS:10)
B(7,-27,5,SEA_LANTERN)
B(8,-27,5,STAINED_GLASS:10)
B(9,-27,5,STAINED_GLASS:10)
B(10,-27,5,STAINED_GLASS:10)
B(4,-27,6,STAINED_GLASS:15)
B(5,-27,6,STAINED_GLASS:15)
B(6,-27,6,STAINED_GLASS:10)
B(7,-27,6,STAINED_GLASS:10)
B(8,-27,6,STAINED_GLASS:10)
B(9,-27,6,STAINED_GLASS:14)
B(10,-27,6,STAINED_GLASS:10)
B(11,-27,6,STAINED_GLASS:15)
B(6,-27,7,STAINED_GLASS:10)
B(7,-27,7,STAINED_GLASS:15)
B(8,-27,7,STAINED_GLASS:15)
B(9,-27,7,STAINED_GLASS:15)
B(8,-27,8,STAINED_GLASS:15)
B(7,-26,0,STAINED_GLASS:15)
B(9,-26,0,STAINED_GLASS:15)
B(5,-26,1,STAINED_GLASS:15)
B(6,-26,1,STAINED_GLASS:15)
B(7,-26,1,STAINED_GLASS:10)
B(8,-26,1,STAINED_GLASS:10)
B(9,-26,1,PURPLE_GLAZED_TERRACOTTA:2)
B(4,-26,2,STAINED_GLASS:15)
B(5,-26,2,STAINED_GLASS:10)
B(6,-26,2,STAINED_GLASS:10)
B(7,-26,2,SEA_LANTERN)
B(8,-26,2,STAINED_GLASS:10)
B(9,-26,2,STAINED_GLASS:10)
B(10,-26,2,STAINED_GLASS:15)
B(11,-26,2,STAINED_GLASS:15)
B(5,-26,3,STAINED_GLASS:10)
B(6,-26,3,STAINED_GLASS:10)
B(7,-26,3,SEA_LANTERN)
B(8,-26,3,SEA_LANTERN)
B(9,-26,3,STAINED_GLASS:10)
B(10,-26,3,STAINED_GLASS:15)
B(4,-26,4,STAINED_GLASS:15)
B(5,-26,4,STAINED_GLASS:10)
B(6,-26,4,STAINED_GLASS:10)
B(7,-26,4,SEA_LANTERN)
B(8,-26,4,SEA_LANTERN)
B(9,-26,4,STAINED_GLASS:10)
B(10,-26,4,STAINED_GLASS:10)
B(11,-26,4,STAINED_GLASS:15)
B(5,-26,5,STAINED_GLASS:15)
B(6,-26,5,STAINED_GLASS:10)
B(7,-26,5,STAINED_GLASS:10)
B(8,-26,5,STAINED_GLASS:14)
B(9,-26,5,STAINED_GLASS:14)
B(10,-26,5,STAINED_GLASS:15)
B(4,-26,6,STAINED_GLASS:15)
B(5,-26,6,STAINED_GLASS:15)
B(6,-26,6,STAINED_GLASS:10)
B(7,-26,6,STAINED_GLASS:15)
B(8,-26,6,STAINED_GLASS:14)
B(9,-26,6,STAINED_GLASS:15)
B(10,-26,6,STAINED_GLASS:15)
B(6,-26,7,STAINED_GLASS:15)
B(8,-26,7,STAINED_GLASS:15)
B(5,-25,0,STAINED_GLASS:15)
B(6,-25,0,STAINED_GLASS:15)
B(7,-25,0,STAINED_GLASS:10)
B(8,-25,0,STAINED_GLASS:15)
B(9,-25,0,PURPLE_GLAZED_TERRACOTTA:2)
B(4,-25,1,STAINED_GLASS:15)
B(5,-25,1,STAINED_GLASS:10)
B(6,-25,1,STAINED_GLASS:10)
B(7,-25,1,STAINED_GLASS:10)
B(8,-25,1,PURPLE_GLAZED_TERRACOTTA:2)
B(9,-25,1,PURPLE_GLAZED_TERRACOTTA:2)
B(4,-25,2,STAINED_GLASS:15)
B(5,-25,2,STAINED_GLASS:10)
B(6,-25,2,SEA_LANTERN)
B(7,-25,2,SEA_LANTERN)
B(8,-25,2,SEA_LANTERN)
B(9,-25,2,PURPLE_GLAZED_TERRACOTTA:2)
B(10,-25,2,STAINED_GLASS:15)
B(11,-25,2,STAINED_GLASS:15)
B(5,-25,3,STAINED_GLASS:10)
B(6,-25,3,STAINED_GLASS:10)
B(7,-25,3,SEA_LANTERN)
B(8,-25,3,SEA_LANTERN)
B(9,-25,3,PURPLE_GLAZED_TERRACOTTA:2)
B(10,-25,3,STAINED_GLASS:15)
B(4,-25,4,STAINED_GLASS:15)
B(5,-25,4,STAINED_GLASS:10)
B(6,-25,4,STAINED_GLASS:10)
B(7,-25,4,STAINED_GLASS:10)
B(8,-25,4,STAINED_GLASS:10)
B(9,-25,4,STAINED_GLASS:10)
B(10,-25,4,STAINED_GLASS:10)
B(5,-25,5,STAINED_GLASS:15)
B(6,-25,5,STAINED_GLASS:10)
B(7,-25,5,STAINED_GLASS:10)
B(8,-25,5,STAINED_GLASS:15)
B(9,-25,5,STAINED_GLASS:15)
B(5,-25,6,STAINED_GLASS:15)
B(6,-25,6,STAINED_GLASS:15)
B(7,-25,6,STAINED_GLASS:15)
B(8,-25,6,STAINED_GLASS:15)
B(9,-25,6,STAINED_GLASS:15)
B(4,-24,0,STAINED_GLASS:15)
B(5,-24,0,STAINED_GLASS:14)
B(6,-24,0,STAINED_GLASS:10)
B(7,-24,0,STAINED_GLASS:10)
B(8,-24,0,STAINED_GLASS:10)
B(9,-24,0,PURPLE_GLAZED_TERRACOTTA:2)
B(4,-24,1,STAINED_GLASS:15)
B(5,-24,1,STAINED_GLASS:10)
B(6,-24,1,STAINED_GLASS:10)
B(7,-24,1,SEA_LANTERN)
B(8,-24,1,PURPLE_GLAZED_TERRACOTTA:2)
B(9,-24,1,PURPLE_GLAZED_TERRACOTTA:2)
B(10,-24,1,STAINED_GLASS:15)
B(4,-24,2,STAINED_GLASS:15)
B(5,-24,2,STAINED_GLASS:10)
B(6,-24,2,SEA_LANTERN)
B(7,-24,2,SEA_LANTERN)
B(8,-24,2,SEA_LANTERN)
B(9,-24,2,PURPLE_GLAZED_TERRACOTTA:2)
B(10,-24,2,STAINED_GLASS:15)
B(11,-24,2,STAINED_GLASS:15)
B(3,-24,3,STAINED_GLASS:15)
B(4,-24,3,STAINED_GLASS:15)
B(5,-24,3,STAINED_GLASS:10)
B(6,-24,3,STAINED_GLASS:10)
B(7,-24,3,SEA_LANTERN)
B(8,-24,3,STAINED_GLASS:10)
B(9,-24,3,PURPLE_GLAZED_TERRACOTTA:2)
B(10,-24,3,STAINED_GLASS:15)
B(4,-24,4,STAINED_GLASS:15)
B(5,-24,4,STAINED_GLASS:10)
B(6,-24,4,STAINED_GLASS:10)
B(7,-24,4,STAINED_GLASS:10)
B(8,-24,4,STAINED_GLASS:10)
B(9,-24,4,STAINED_GLASS:10)
B(10,-24,4,STAINED_GLASS:15)
B(5,-24,5,STAINED_GLASS:15)
B(6,-24,5,STAINED_GLASS:15)
B(7,-24,5,STAINED_GLASS:15)
B(8,-24,5,STAINED_GLASS:15)
B(8,-24,6,STAINED_GLASS:15)
B(4,-23,0,STAINED_GLASS:14)
B(5,-23,0,STAINED_GLASS:14)
B(6,-23,0,STAINED_GLASS:10)
B(7,-23,0,SEA_LANTERN)
B(8,-23,0,PURPLE_GLAZED_TERRACOTTA:2)
B(9,-23,0,PURPLE_GLAZED_TERRACOTTA:2)
B(4,-23,1,STAINED_GLASS:15)
B(5,-23,1,STAINED_GLASS:10)
B(6,-23,1,SEA_LANTERN)
B(7,-23,1,SEA_LANTERN)
B(8,-23,1,PURPLE_GLAZED_TERRACOTTA:2)
B(9,-23,1,PURPLE_GLAZED_TERRACOTTA:2)
B(10,-23,1,STAINED_GLASS:15)
B(4,-23,2,STAINED_GLASS:15)
B(5,-23,2,PURPLE_GLAZED_TERRACOTTA:2)
B(6,-23,2,SEA_LANTERN)
B(7,-23,2,STAINED_GLASS:14)
B(8,-23,2,SEA_LANTERN)
B(9,-23,2,PURPLE_GLAZED_TERRACOTTA:2)
B(10,-23,2,STAINED_GLASS:15)
B(3,-23,3,STAINED_GLASS:15)
B(4,-23,3,STAINED_GLASS:15)
B(5,-23,3,PURPLE_GLAZED_TERRACOTTA:2)
B(6,-23,3,PURPLE_GLAZED_TERRACOTTA:2)
B(7,-23,3,STAINED_GLASS:14)
B(8,-23,3,STAINED_GLASS:14)
B(9,-23,3,PURPLE_GLAZED_TERRACOTTA:2)
B(10,-23,3,STAINED_GLASS:15)
B(5,-23,4,PURPLE_GLAZED_TERRACOTTA:2)
B(6,-23,4,STAINED_GLASS:15)
B(7,-23,4,STAINED_GLASS:15)
B(8,-23,4,STAINED_GLASS:15)
B(9,-23,4,STAINED_GLASS:15)
B(5,-23,5,STAINED_GLASS:15)
B(7,-23,5,STAINED_GLASS:15)
B(4,-22,0,STAINED_GLASS:14)
B(5,-22,0,STAINED_GLASS:14)
B(6,-22,0,SEA_LANTERN)
B(7,-22,0,SEA_LANTERN)
B(8,-22,0,PURPLE_GLAZED_TERRACOTTA:2)
B(9,-22,0,PURPLE_GLAZED_TERRACOTTA:2)
B(10,-22,0,STAINED_GLASS:15)
B(3,-22,1,STAINED_GLASS:15)
B(4,-22,1,STAINED_GLASS:15)
B(5,-22,1,PURPLE_GLAZED_TERRACOTTA:2)
B(6,-22,1,SEA_LANTERN)
B(7,-22,1,SEA_LANTERN)
B(8,-22,1,STAINED_GLASS:10)
B(9,-22,1,PURPLE_GLAZED_TERRACOTTA:2)
B(10,-22,1,STAINED_GLASS:15)
B(4,-22,2,STAINED_GLASS:15)
B(5,-22,2,PURPLE_GLAZED_TERRACOTTA:2)
B(6,-22,2,PURPLE_GLAZED_TERRACOTTA:2)
B(7,-22,2,STAINED_GLASS:14)
B(8,-22,2,STAINED_GLASS:10)
B(9,-22,2,STAINED_GLASS:10)
B(10,-22,2,STAINED_GLASS:15)
B(3,-22,3,STAINED_GLASS:15)
B(4,-22,3,STAINED_GLASS:15)
B(5,-22,3,PURPLE_GLAZED_TERRACOTTA:2)
B(6,-22,3,PURPLE_GLAZED_TERRACOTTA:2)
B(7,-22,3,STAINED_GLASS:14)
B(8,-22,3,STAINED_GLASS:15)
B(9,-22,3,STAINED_GLASS:15)
B(5,-22,4,STAINED_GLASS:15)
B(7,-22,4,STAINED_GLASS:15)
B(8,-22,4,STAINED_GLASS:15)
B(4,-21,0,STAINED_GLASS:14)
B(5,-21,0,STAINED_GLASS:10)
B(6,-21,0,SEA_LANTERN)
B(7,-21,0,SEA_LANTERN)
B(8,-21,0,PURPLE_GLAZED_TERRACOTTA:2)
B(9,-21,0,PURPLE_GLAZED_TERRACOTTA:2)
B(10,-21,0,STAINED_GLASS:15)
B(3,-21,1,STAINED_GLASS:15)
B(4,-21,1,STAINED_GLASS:15)
B(5,-21,1,PURPLE_GLAZED_TERRACOTTA:2)
B(6,-21,1,SEA_LANTERN)
B(7,-21,1,STAINED_GLASS:10)
B(8,-21,1,STAINED_GLASS:10)
B(9,-21,1,STAINED_GLASS:10)
B(4,-21,2,STAINED_GLASS:15)
B(5,-21,2,PURPLE_GLAZED_TERRACOTTA:2)
B(6,-21,2,PURPLE_GLAZED_TERRACOTTA:2)
B(7,-21,2,STAINED_GLASS:15)
B(8,-21,2,STAINED_GLASS:10)
B(9,-21,2,STAINED_GLASS:15)
B(10,-21,2,STAINED_GLASS:15)
B(5,-21,3,PURPLE_GLAZED_TERRACOTTA:2)
B(6,-21,3,STAINED_GLASS:15)
B(7,-21,3,STAINED_GLASS:15)
B(8,-21,3,STAINED_GLASS:15)
B(3,-20,0,STAINED_GLASS:15)
B(4,-20,0,STAINED_GLASS:10)
B(5,-20,0,STAINED_GLASS:10)
B(6,-20,0,SEA_LANTERN)
B(7,-20,0,STAINED_GLASS:10)
B(8,-20,0,STAINED_GLASS:10)
B(9,-20,0,STAINED_GLASS:10)
B(10,-20,0,STAINED_GLASS:15)
B(3,-20,1,STAINED_GLASS:15)
B(4,-20,1,STAINED_GLASS:15)
B(5,-20,1,PURPLE_GLAZED_TERRACOTTA:2)
B(6,-20,1,STAINED_GLASS:10)
B(7,-20,1,STAINED_GLASS:10)
B(8,-20,1,STAINED_GLASS:10)
B(9,-20,1,STAINED_GLASS:15)
B(4,-20,2,STAINED_GLASS:15)
B(5,-20,2,STAINED_GLASS:15)
B(6,-20,2,STAINED_GLASS:15)
B(7,-20,2,STAINED_GLASS:15)
B(8,-20,2,STAINED_GLASS:15)
B(5,-20,3,STAINED_GLASS:15)
B(7,-20,3,STAINED_GLASS:15)
B(3,-19,0,STAINED_GLASS:15)
B(4,-19,0,STAINED_GLASS:10)
B(5,-19,0,STAINED_GLASS:14)
B(6,-19,0,STAINED_GLASS:14)
B(7,-19,0,STAINED_GLASS:14)
B(8,-19,0,STAINED_GLASS:10)
B(9,-19,0,STAINED_GLASS:10)
B(4,-19,1,STAINED_GLASS:15)
B(5,-19,1,STAINED_GLASS:14)
B(6,-19,1,STAINED_GLASS:14)
B(7,-19,1,STAINED_GLASS:15)
B(8,-19,1,STAINED_GLASS:15)
B(4,-19,2,STAINED_GLASS:15)
B(6,-19,2,STAINED_GLASS:15)
B(8,-19,2,STAINED_GLASS:15)
B(3,-18,0,STAINED_GLASS:15)
B(4,-18,0,STAINED_GLASS:10)
B(5,-18,0,STAINED_GLASS:14)
B(6,-18,0,STAINED_GLASS:14)
B(7,-18,0,STAINED_GLASS:15)
B(8,-18,0,STAINED_GLASS:10)
B(9,-18,0,STAINED_GLASS:15)
B(4,-18,1,STAINED_GLASS:15)
B(5,-18,1,STAINED_GLASS:15)
B(6,-18,1,STAINED_GLASS:15)
B(7,-18,1,STAINED_GLASS:15)
B(4,-17,0,STAINED_GLASS:10)
B(5,-17,0,STAINED_GLASS:15)
B(6,-17,0,STAINED_GLASS:15)
B(7,-17,0,STAINED_GLASS:15)
B(8,-17,0,STAINED_GLASS:15)
B(4,-17,1,STAINED_GLASS:15)
B(6,-17,1,STAINED_GLASS:15)
B(4,-16,0,STAINED_GLASS:15)
B(6,-16,0,STAINED_GLASS:15)

