
#######################################################################
# +-----------------------------------------------------------------+ #
# |                            BO3 object                           | #
# +-----------------------------------------------------------------+ #
#######################################################################

Author: NLBlackEagle

Description: Converted version of the BO2 25

Version: 3

SettingsMode: WriteWithoutComments


#######################################################################
# +-----------------------------------------------------------------+ #
# |                          Main settings                          | #
# +-----------------------------------------------------------------+ #
#######################################################################

Tree: true

Frequency: 1

Rarity: 100.0

RotateRandomly: true

SpawnHeight: highestSolidBlock

SpawnHeightOffset: 0

SpawnHeightVariance: 0

##############################
# Height Limits for the BO3. #
##############################

MinHeight: 100

MaxHeight: 255

######################
# Extrusion settings #
######################

ExtrudeMode: None

ExtrudeThroughBlocks: otg:air

MaxBranchDepth: 10


#######################################################################
# +-----------------------------------------------------------------+ #
# |                      Source block settings                      | #
# +-----------------------------------------------------------------+ #
#######################################################################

SourceBlocks: otg:air,otg:dirt,minecraft:sand,minecraft:grass_block

MaxPercentageOutsideSourceBlock: 0

OutsideSourceBlock: placeAnyway

DoReplaceBlocks: true

IsOTGPlus: false


#######################################################################
# +-----------------------------------------------------------------+ #
# |                              Blocks                             | #
# +-----------------------------------------------------------------+ #
#######################################################################

B(2,11,-7,minecraft:oak_leaves[distance=5,persistent=false])
B(2,11,-6,minecraft:oak_leaves[distance=4,persistent=false])
B(2,12,-6,minecraft:oak_leaves[distance=7,persistent=true])
B(2,14,-3,minecraft:oak_leaves[distance=5,persistent=false])
B(2,15,-3,minecraft:oak_leaves[distance=7,persistent=true])
B(2,14,-2,minecraft:oak_leaves[distance=7,persistent=true])
B(2,15,-2,minecraft:oak_leaves[distance=7,persistent=true])
B(2,15,-1,minecraft:oak_leaves[distance=7,persistent=true])
B(3,11,-7,minecraft:oak_leaves[distance=4,persistent=false])
B(3,12,-7,minecraft:oak_leaves[distance=3,persistent=false])
B(3,11,-6,minecraft:oak_leaves[distance=3,persistent=false])
B(3,11,-5,minecraft:oak_leaves[distance=2,persistent=false])
B(3,12,-5,minecraft:oak_leaves)
B(3,13,-5,minecraft:oak_leaves[distance=2,persistent=false])
B(3,12,-4,minecraft:oak_leaves[distance=2,persistent=false])
B(3,13,-4,minecraft:oak_leaves[distance=3,persistent=false])
B(3,14,-4,minecraft:oak_leaves[distance=4,persistent=false])
B(3,13,-3,minecraft:oak_leaves[distance=3,persistent=false])
B(3,14,-3,minecraft:oak_leaves[distance=4,persistent=false])
B(3,13,-2,minecraft:oak_leaves[distance=7,persistent=true])
B(3,14,-2,minecraft:oak_leaves[distance=3,persistent=false])
B(3,11,-1,minecraft:oak_leaves[distance=7,persistent=true])
B(3,15,-1,minecraft:oak_leaves[distance=4,persistent=false])
B(4,11,-9,minecraft:oak_leaves[distance=5,persistent=false])
B(4,11,-8,minecraft:oak_leaves[distance=4,persistent=false])
B(4,10,-7,minecraft:oak_leaves[distance=4,persistent=false])
B(4,11,-7,minecraft:oak_leaves[distance=3,persistent=false])
B(4,12,-7,minecraft:oak_leaves[distance=2,persistent=false])
B(4,9,-6,minecraft:oak_leaves[distance=5,persistent=false])
B(4,10,-6,minecraft:oak_leaves[distance=3,persistent=false])
B(4,11,-6,minecraft:oak_leaves[distance=2,persistent=false])
B(4,12,-6,minecraft:oak_leaves)
B(4,10,-5,minecraft:oak_leaves[distance=2,persistent=false])
B(4,11,-5,minecraft:oak_leaves)
B(4,12,-5,minecraft:spruce_wood)
B(4,13,-5,minecraft:oak_leaves)
B(4,14,-5,minecraft:oak_leaves[distance=2,persistent=false])
B(4,11,-4,minecraft:oak_leaves[distance=2,persistent=false])
B(4,12,-4,minecraft:oak_leaves)
B(4,13,-4,minecraft:oak_leaves[distance=2,persistent=false])
B(4,12,-3,minecraft:oak_leaves[distance=2,persistent=false])
B(4,13,-3,minecraft:oak_leaves[distance=2,persistent=false])
B(4,14,-3,minecraft:oak_leaves[distance=3,persistent=false])
B(4,15,-3,minecraft:oak_leaves[distance=4,persistent=false])
B(4,9,-2,minecraft:oak_leaves[distance=2,persistent=false])
B(4,10,-2,minecraft:oak_leaves[distance=2,persistent=false])
B(4,13,-2,minecraft:oak_leaves[distance=2,persistent=false])
B(4,14,-2,minecraft:oak_leaves[distance=2,persistent=false])
B(4,15,-2,minecraft:oak_leaves[distance=3,persistent=false])
B(4,9,-1,minecraft:oak_leaves[distance=7,persistent=true])
B(4,10,-1,minecraft:oak_leaves[distance=3,persistent=false])
B(4,11,-1,minecraft:oak_leaves[distance=7,persistent=true])
B(4,15,-1,minecraft:oak_leaves[distance=3,persistent=false])
B(4,10,0,minecraft:oak_leaves[distance=7,persistent=true])
B(5,11,-9,minecraft:oak_leaves[distance=6,persistent=false])
B(5,10,-8,minecraft:oak_leaves[distance=6,persistent=false])
B(5,11,-8,minecraft:oak_leaves[distance=5,persistent=false])
B(5,8,-7,minecraft:oak_leaves[distance=6,persistent=false])
B(5,9,-7,minecraft:oak_leaves[distance=5,persistent=false])
B(5,10,-7,minecraft:oak_leaves[distance=5,persistent=false])
B(5,11,-7,minecraft:oak_leaves[distance=4,persistent=false])
B(5,8,-6,minecraft:oak_leaves[distance=5,persistent=false])
B(5,9,-6,minecraft:oak_leaves[distance=4,persistent=false])
B(5,10,-6,minecraft:oak_leaves[distance=4,persistent=false])
B(5,11,-6,minecraft:oak_leaves[distance=3,persistent=false])
B(5,12,-6,minecraft:oak_leaves[distance=2,persistent=false])
B(5,8,-5,minecraft:oak_leaves[distance=4,persistent=false])
B(5,9,-5,minecraft:oak_leaves[distance=3,persistent=false])
B(5,10,-5,minecraft:oak_leaves[distance=3,persistent=false])
B(5,11,-5,minecraft:oak_leaves[distance=2,persistent=false])
B(5,12,-5,minecraft:oak_leaves)
B(5,13,-5,minecraft:oak_leaves[distance=2,persistent=false])
B(5,8,-4,minecraft:oak_leaves[distance=3,persistent=false])
B(5,9,-4,minecraft:oak_leaves[distance=2,persistent=false])
B(5,10,-4,minecraft:oak_leaves[distance=2,persistent=false])
B(5,11,-4,minecraft:oak_leaves[distance=2,persistent=false])
B(5,12,-4,minecraft:oak_leaves[distance=2,persistent=false])
B(5,17,-4,minecraft:oak_leaves[distance=4,persistent=false])
B(5,18,-4,minecraft:oak_leaves[distance=5,persistent=false])
B(5,9,-3,minecraft:oak_leaves)
B(5,10,-3,minecraft:oak_leaves)
B(5,11,-3,minecraft:oak_leaves)
B(5,12,-3,minecraft:oak_leaves)
B(5,13,-3,minecraft:oak_leaves)
B(5,14,-3,minecraft:oak_leaves[distance=2,persistent=false])
B(5,15,-3,minecraft:oak_leaves[distance=2,persistent=false])
B(5,17,-3,minecraft:oak_leaves[distance=3,persistent=false])
B(5,18,-3,minecraft:oak_leaves[distance=4,persistent=false])
B(5,4,-2,minecraft:spruce_wood)
B(5,8,-2,minecraft:spruce_wood)
B(5,9,-2,minecraft:oak_leaves)
B(5,10,-2,minecraft:oak_leaves)
B(5,11,-2,minecraft:oak_leaves)
B(5,12,-2,minecraft:oak_leaves)
B(5,13,-2,minecraft:oak_leaves)
B(5,14,-2,minecraft:oak_leaves)
B(5,17,-2,minecraft:oak_leaves[distance=2,persistent=false])
B(5,18,-2,minecraft:oak_leaves[distance=3,persistent=false])
B(5,19,-2,minecraft:oak_leaves[distance=2,persistent=false])
B(5,10,-1,minecraft:oak_leaves[distance=2,persistent=false])
B(5,11,-1,minecraft:oak_leaves[distance=2,persistent=false])
B(5,12,-1,minecraft:oak_leaves[distance=2,persistent=false])
B(5,14,-1,minecraft:oak_leaves[distance=2,persistent=false])
B(5,15,-1,minecraft:oak_leaves[distance=2,persistent=false])
B(5,16,-1,minecraft:oak_leaves[distance=2,persistent=false])
B(5,18,-1,minecraft:oak_leaves[distance=4,persistent=false])
B(5,19,-1,minecraft:oak_leaves[distance=3,persistent=false])
B(5,11,0,minecraft:oak_leaves[distance=7,persistent=true])
B(5,12,0,minecraft:oak_leaves[distance=3,persistent=false])
B(5,13,0,minecraft:oak_leaves[distance=7,persistent=true])
B(5,12,1,minecraft:oak_leaves[distance=7,persistent=true])
B(5,13,1,minecraft:oak_leaves[distance=7,persistent=true])
B(6,8,-8,minecraft:oak_leaves[distance=6,persistent=false])
B(6,8,-7,minecraft:oak_leaves[distance=5,persistent=false])
B(6,8,-6,minecraft:oak_leaves[distance=4,persistent=false])
B(6,15,-6,minecraft:oak_leaves[distance=7,persistent=true])
B(6,-7,-5,minecraft:spruce_wood)
B(6,8,-5,minecraft:oak_leaves[distance=3,persistent=false])
B(6,11,-5,minecraft:oak_leaves[distance=2,persistent=false])
B(6,13,-5,minecraft:oak_leaves[distance=3,persistent=false])
B(6,14,-5,minecraft:oak_leaves[distance=3,persistent=false])
B(6,-6,-4,minecraft:spruce_wood)
B(6,7,-4,minecraft:oak_leaves)
B(6,8,-4,minecraft:oak_leaves[distance=2,persistent=false])
B(6,9,-4,minecraft:oak_leaves)
B(6,10,-4,minecraft:oak_leaves)
B(6,11,-4,minecraft:oak_leaves)
B(6,12,-4,minecraft:oak_leaves)
B(6,14,-4,minecraft:oak_leaves[distance=2,persistent=false])
B(6,15,-4,minecraft:oak_leaves[distance=2,persistent=false])
B(6,16,-4,minecraft:oak_leaves[distance=2,persistent=false])
B(6,17,-4,minecraft:oak_leaves[distance=3,persistent=false])
B(6,18,-4,minecraft:oak_leaves[distance=4,persistent=false])
B(6,-8,-3,minecraft:spruce_wood)
B(6,-7,-3,minecraft:spruce_wood)
B(6,-6,-3,minecraft:spruce_wood)
B(6,-5,-3,minecraft:spruce_wood)
B(6,-4,-3,minecraft:spruce_wood)
B(6,-3,-3,minecraft:spruce_wood)
B(6,-2,-3,minecraft:spruce_wood)
B(6,-1,-3,minecraft:spruce_wood)
B(6,0,-3,minecraft:spruce_wood)
B(6,1,-3,minecraft:spruce_wood)
B(6,2,-3,minecraft:spruce_wood)
B(6,3,-3,minecraft:spruce_wood)
B(6,4,-3,minecraft:spruce_wood)
B(6,5,-3,minecraft:spruce_wood)
B(6,6,-3,minecraft:spruce_wood)
B(6,7,-3,minecraft:spruce_wood)
B(6,8,-3,minecraft:oak_leaves)
B(6,9,-3,minecraft:spruce_wood)
B(6,10,-3,minecraft:spruce_wood)
B(6,11,-3,minecraft:spruce_wood)
B(6,12,-3,minecraft:spruce_wood)
B(6,13,-3,minecraft:spruce_wood)
B(6,14,-3,minecraft:oak_leaves)
B(6,15,-3,minecraft:oak_leaves)
B(6,16,-3,minecraft:oak_leaves)
B(6,17,-3,minecraft:oak_leaves[distance=2,persistent=false])
B(6,18,-3,minecraft:oak_leaves[distance=3,persistent=false])
B(6,19,-3,minecraft:oak_leaves[distance=2,persistent=false])
B(6,20,-3,minecraft:oak_leaves)
B(6,-2,-2,minecraft:spruce_wood)
B(6,-1,-2,minecraft:spruce_wood)
B(6,0,-2,minecraft:spruce_wood)
B(6,1,-2,minecraft:spruce_wood)
B(6,2,-2,minecraft:spruce_wood)
B(6,3,-2,minecraft:spruce_wood)
B(6,4,-2,minecraft:spruce_wood)
B(6,5,-2,minecraft:spruce_wood)
B(6,6,-2,minecraft:spruce_wood)
B(6,7,-2,minecraft:spruce_wood)
B(6,8,-2,minecraft:spruce_wood)
B(6,9,-2,minecraft:spruce_wood)
B(6,10,-2,minecraft:spruce_wood)
B(6,11,-2,minecraft:spruce_wood)
B(6,12,-2,minecraft:spruce_wood)
B(6,13,-2,minecraft:spruce_wood)
B(6,14,-2,minecraft:spruce_wood)
B(6,15,-2,minecraft:spruce_wood)
B(6,16,-2,minecraft:spruce_wood)
B(6,17,-2,minecraft:oak_leaves)
B(6,18,-2,minecraft:oak_leaves[distance=2,persistent=false])
B(6,19,-2,minecraft:oak_leaves)
B(6,20,-2,minecraft:spruce_wood)
B(6,11,-1,minecraft:oak_leaves)
B(6,12,-1,minecraft:oak_leaves)
B(6,13,-1,minecraft:oak_leaves)
B(6,14,-1,minecraft:oak_leaves)
B(6,15,-1,minecraft:oak_leaves)
B(6,16,-1,minecraft:oak_leaves)
B(6,17,-1,minecraft:oak_leaves[distance=2,persistent=false])
B(6,18,-1,minecraft:oak_leaves[distance=3,persistent=false])
B(6,19,-1,minecraft:oak_leaves[distance=2,persistent=false])
B(6,12,0,minecraft:oak_leaves[distance=2,persistent=false])
B(6,13,0,minecraft:oak_leaves[distance=2,persistent=false])
B(6,14,0,minecraft:oak_leaves[distance=2,persistent=false])
B(6,16,0,minecraft:oak_leaves[distance=2,persistent=false])
B(6,12,1,minecraft:oak_leaves[distance=7,persistent=true])
B(7,8,-6,minecraft:oak_leaves[distance=3,persistent=false])
B(7,14,-6,minecraft:oak_leaves[distance=5,persistent=false])
B(7,15,-6,minecraft:oak_leaves[distance=6,persistent=false])
B(7,-8,-5,minecraft:spruce_wood)
B(7,7,-5,minecraft:oak_leaves[distance=3,persistent=false])
B(7,8,-5,minecraft:oak_leaves[distance=2,persistent=false])
B(7,9,-5,minecraft:oak_leaves[distance=2,persistent=false])
B(7,11,-5,minecraft:oak_leaves[distance=3,persistent=false])
B(7,13,-5,minecraft:oak_leaves[distance=3,persistent=false])
B(7,14,-5,minecraft:oak_leaves[distance=4,persistent=false])
B(7,8,-4,minecraft:oak_leaves)
B(7,9,-4,minecraft:oak_leaves)
B(7,11,-4,minecraft:oak_leaves[distance=2,persistent=false])
B(7,12,-4,minecraft:oak_leaves)
B(7,13,-4,minecraft:oak_leaves[distance=2,persistent=false])
B(7,14,-4,minecraft:oak_leaves[distance=3,persistent=false])
B(7,15,-4,minecraft:oak_leaves[distance=3,persistent=false])
B(7,16,-4,minecraft:oak_leaves[distance=3,persistent=false])
B(7,-2,-3,minecraft:spruce_wood)
B(7,-1,-3,minecraft:spruce_wood)
B(7,0,-3,minecraft:spruce_wood)
B(7,1,-3,minecraft:spruce_wood)
B(7,2,-3,minecraft:spruce_wood)
B(7,3,-3,minecraft:spruce_wood)
B(7,4,-3,minecraft:spruce_wood)
B(7,5,-3,minecraft:spruce_wood)
B(7,6,-3,minecraft:spruce_wood)
B(7,7,-3,minecraft:spruce_wood)
B(7,8,-3,minecraft:spruce_wood)
B(7,9,-3,minecraft:spruce_wood)
B(7,10,-3,minecraft:oak_leaves)
B(7,11,-3,minecraft:oak_leaves)
B(7,12,-3,minecraft:spruce_wood)
B(7,13,-3,minecraft:oak_leaves)
B(7,14,-3,minecraft:oak_leaves[distance=2,persistent=false])
B(7,15,-3,minecraft:oak_leaves[distance=2,persistent=false])
B(7,16,-3,minecraft:oak_leaves[distance=2,persistent=false])
B(7,18,-3,minecraft:oak_leaves[distance=4,persistent=false])
B(7,19,-3,minecraft:oak_leaves[distance=3,persistent=false])
B(7,20,-3,minecraft:oak_leaves[distance=2,persistent=false])
B(7,-5,-2,minecraft:spruce_wood)
B(7,-4,-2,minecraft:spruce_wood)
B(7,-3,-2,minecraft:spruce_wood)
B(7,-2,-2,minecraft:spruce_wood)
B(7,-1,-2,minecraft:spruce_wood)
B(7,0,-2,minecraft:spruce_wood)
B(7,1,-2,minecraft:spruce_wood)
B(7,2,-2,minecraft:spruce_wood)
B(7,3,-2,minecraft:spruce_wood)
B(7,4,-2,minecraft:spruce_wood)
B(7,5,-2,minecraft:spruce_wood)
B(7,6,-2,minecraft:spruce_wood)
B(7,7,-2,minecraft:spruce_wood)
B(7,8,-2,minecraft:spruce_wood)
B(7,9,-2,minecraft:spruce_wood)
B(7,10,-2,minecraft:spruce_wood)
B(7,11,-2,minecraft:spruce_wood)
B(7,12,-2,minecraft:oak_leaves)
B(7,13,-2,minecraft:oak_leaves)
B(7,14,-2,minecraft:oak_leaves)
B(7,15,-2,minecraft:oak_leaves)
B(7,16,-2,minecraft:oak_leaves)
B(7,17,-2,minecraft:oak_leaves[distance=2,persistent=false])
B(7,18,-2,minecraft:oak_leaves[distance=3,persistent=false])
B(7,19,-2,minecraft:oak_leaves[distance=2,persistent=false])
B(7,20,-2,minecraft:oak_leaves)
B(7,-8,-1,minecraft:spruce_wood)
B(7,-7,-1,minecraft:spruce_wood)
B(7,-6,-1,minecraft:spruce_wood)
B(7,12,-1,minecraft:oak_leaves[distance=2,persistent=false])
B(7,13,-1,minecraft:oak_leaves[distance=2,persistent=false])
B(7,15,-1,minecraft:oak_leaves[distance=2,persistent=false])
B(7,16,-1,minecraft:oak_leaves[distance=2,persistent=false])
B(7,17,-1,minecraft:oak_leaves[distance=3,persistent=false])
B(7,18,-1,minecraft:oak_leaves[distance=4,persistent=false])
B(7,12,0,minecraft:oak_leaves[distance=3,persistent=false])
B(7,13,0,minecraft:oak_leaves[distance=3,persistent=false])
B(7,14,0,minecraft:oak_leaves[distance=3,persistent=false])
B(7,15,0,minecraft:oak_leaves[distance=7,persistent=true])
B(7,16,0,minecraft:oak_leaves[distance=3,persistent=false])
B(7,17,0,minecraft:oak_leaves[distance=4,persistent=false])
B(8,8,-6,minecraft:oak_leaves[distance=4,persistent=false])
B(8,13,-6,minecraft:oak_leaves[distance=5,persistent=false])
B(8,14,-6,minecraft:oak_leaves[distance=6,persistent=false])
B(8,8,-5,minecraft:oak_leaves[distance=3,persistent=false])
B(8,9,-5,minecraft:oak_leaves[distance=3,persistent=false])
B(8,13,-5,minecraft:oak_leaves[distance=4,persistent=false])
B(8,14,-5,minecraft:oak_leaves[distance=5,persistent=false])
B(8,11,-4,minecraft:oak_leaves[distance=3,persistent=false])
B(8,12,-4,minecraft:oak_leaves[distance=2,persistent=false])
B(8,13,-4,minecraft:oak_leaves[distance=3,persistent=false])
B(8,14,-4,minecraft:oak_leaves[distance=4,persistent=false])
B(8,-7,-3,minecraft:spruce_wood)
B(8,10,-3,minecraft:oak_leaves[distance=2,persistent=false])
B(8,11,-3,minecraft:oak_leaves[distance=2,persistent=false])
B(8,12,-3,minecraft:oak_leaves)
B(8,13,-3,minecraft:oak_leaves[distance=2,persistent=false])
B(8,14,-3,minecraft:oak_leaves[distance=3,persistent=false])
B(8,-6,-2,minecraft:spruce_wood)
B(8,13,-2,minecraft:oak_leaves[distance=2,persistent=false])
B(8,14,-2,minecraft:oak_leaves[distance=2,persistent=false])
B(8,16,-2,minecraft:oak_leaves[distance=2,persistent=false])
B(8,17,-2,minecraft:oak_leaves[distance=3,persistent=false])
B(8,18,-2,minecraft:oak_leaves[distance=4,persistent=false])
B(8,12,-1,minecraft:oak_leaves[distance=3,persistent=false])
B(8,13,-1,minecraft:oak_leaves[distance=3,persistent=false])
B(8,16,-1,minecraft:oak_leaves[distance=3,persistent=false])
B(8,17,-1,minecraft:oak_leaves[distance=4,persistent=false])
B(8,18,-1,minecraft:oak_leaves[distance=5,persistent=false])
B(8,12,0,minecraft:oak_leaves[distance=7,persistent=true])
B(8,13,0,minecraft:oak_leaves[distance=4,persistent=false])
B(8,14,0,minecraft:oak_leaves[distance=7,persistent=true])
B(8,15,0,minecraft:oak_leaves[distance=7,persistent=true])
B(8,16,0,minecraft:oak_leaves[distance=7,persistent=true])
B(8,17,0,minecraft:oak_leaves[distance=5,persistent=false])
B(8,14,1,minecraft:oak_leaves[distance=7,persistent=true])
B(9,15,-5,minecraft:oak_leaves[distance=7,persistent=true])
B(9,11,-4,minecraft:oak_leaves[distance=4,persistent=false])
B(9,12,-4,minecraft:oak_leaves[distance=3,persistent=false])
B(9,-8,-3,minecraft:spruce_wood)
B(9,10,-3,minecraft:oak_leaves[distance=7,persistent=true])
B(9,11,-3,minecraft:oak_leaves[distance=3,persistent=false])
B(9,14,-3,minecraft:oak_leaves[distance=4,persistent=false])
B(9,10,-2,minecraft:oak_leaves[distance=7,persistent=true])
B(9,11,-2,minecraft:oak_leaves[distance=7,persistent=true])
B(9,14,-2,minecraft:oak_leaves[distance=3,persistent=false])
B(9,13,-1,minecraft:oak_leaves[distance=4,persistent=false])
B(9,14,-1,minecraft:oak_leaves[distance=7,persistent=true])
B(9,17,-1,minecraft:oak_leaves[distance=5,persistent=false])
B(9,12,0,minecraft:oak_leaves[distance=7,persistent=true])
B(9,13,0,minecraft:oak_leaves[distance=7,persistent=true])
B(9,14,1,minecraft:oak_leaves[distance=7,persistent=true])
B(10,12,-4,minecraft:oak_leaves[distance=4,persistent=false])
B(10,11,-3,minecraft:oak_leaves[distance=7,persistent=true])
B(10,14,-1,minecraft:oak_leaves[distance=7,persistent=true])
B(10,14,0,minecraft:oak_leaves[distance=7,persistent=true])

#######################################################################
# +-----------------------------------------------------------------+ #
# |                            BO3 checks                           | #
# +-----------------------------------------------------------------+ #
#######################################################################

BlockCheck(0,-2,0,Solid)
BlockCheck(0,-1,0,otg:dirt,minecraft:grass_block)
BlockCheck(0,-1,2,otg:dirt,minecraft:grass_block)
BlockCheck(2,-1,0,otg:dirt,minecraft:grass_block)
BlockCheck(-2,-1,0,otg:dirt,minecraft:grass_block)
BlockCheck(0,-1,-2,otg:dirt,minecraft:grass_block)
BlockCheck(0,-1,0,Solid)
BlockCheckNot(0,-1,0,otg:air)

#######################################################################
# +-----------------------------------------------------------------+ #
# |                             Branches                            | #
# +-----------------------------------------------------------------+ #
#######################################################################


#######################################################################
# +-----------------------------------------------------------------+ #
# |                             Entities                            | #
# +-----------------------------------------------------------------+ #
#######################################################################

