
#######################################################################
# +-----------------------------------------------------------------+ #
# |                            BO3 object                           | #
# +-----------------------------------------------------------------+ #
#######################################################################

Author: NLBlackEagle

Description: Converted version of the BO2 47

Version: 3

SettingsMode: WriteWithoutComments


#######################################################################
# +-----------------------------------------------------------------+ #
# |                          Main settings                          | #
# +-----------------------------------------------------------------+ #
#######################################################################

Tree: true

Frequency: 5

Rarity: 25.0

RotateRandomly: true

SpawnHeight: highestSolidBlock

SpawnHeightOffset: 0

SpawnHeightVariance: 0

##############################
# Height Limits for the BO3. #
##############################

MinHeight: 0

MaxHeight: 199

######################
# Extrusion settings #
######################

ExtrudeMode: None

ExtrudeThroughBlocks: otg:air

MaxBranchDepth: 10


#######################################################################
# +-----------------------------------------------------------------+ #
# |                      Source block settings                      | #
# +-----------------------------------------------------------------+ #
#######################################################################

SourceBlocks: otg:air,otg:dirt,minecraft:sand,minecraft:grass_block

MaxPercentageOutsideSourceBlock: 0

OutsideSourceBlock: placeAnyway

DoReplaceBlocks: true

IsOTGPlus: false


#######################################################################
# +-----------------------------------------------------------------+ #
# |                              Blocks                             | #
# +-----------------------------------------------------------------+ #
#######################################################################

B(-9,8,-1,minecraft:spruce_leaves[distance=7,persistent=true])
B(-9,9,-1,minecraft:spruce_leaves[distance=7,persistent=true])
B(-8,8,-2,minecraft:spruce_leaves[distance=7,persistent=true])
B(-8,8,-1,minecraft:spruce_leaves[distance=7,persistent=true])
B(-8,9,-1,minecraft:spruce_leaves[distance=7,persistent=true])
B(-8,8,0,minecraft:spruce_leaves[distance=7,persistent=true])
B(-8,9,0,minecraft:spruce_leaves[distance=7,persistent=true])
B(-7,8,-2,minecraft:spruce_leaves[distance=7,persistent=true])
B(-7,9,-1,minecraft:spruce_leaves[distance=7,persistent=true])
B(-7,8,0,minecraft:spruce_leaves[distance=7,persistent=true])
B(-7,9,0,minecraft:spruce_leaves[distance=7,persistent=true])
B(-7,8,1,minecraft:spruce_leaves[distance=7,persistent=true])
B(-7,12,3,minecraft:spruce_leaves[distance=7,persistent=true])
B(-7,13,3,minecraft:spruce_leaves[distance=7,persistent=true])
B(-6,6,-5,minecraft:spruce_leaves[distance=7,persistent=true])
B(-6,7,-5,minecraft:spruce_leaves[distance=7,persistent=true])
B(-6,9,-5,minecraft:spruce_leaves[distance=7,persistent=true])
B(-6,6,-4,minecraft:spruce_leaves[distance=7,persistent=true])
B(-6,9,-4,minecraft:spruce_leaves[distance=7,persistent=true])
B(-6,15,-4,minecraft:spruce_leaves[distance=7,persistent=true])
B(-6,6,-3,minecraft:spruce_leaves[distance=7,persistent=true])
B(-6,9,-3,minecraft:spruce_leaves[distance=7,persistent=true])
B(-6,15,-3,minecraft:spruce_leaves[distance=7,persistent=true])
B(-6,19,-3,minecraft:spruce_leaves[distance=7,persistent=true])
B(-6,20,-3,minecraft:spruce_leaves[distance=7,persistent=true])
B(-6,8,-2,minecraft:spruce_leaves[distance=7,persistent=true])
B(-6,9,-2,minecraft:spruce_leaves[distance=7,persistent=true])
B(-6,15,-2,minecraft:spruce_leaves[distance=7,persistent=true])
B(-6,19,-2,minecraft:spruce_leaves[distance=7,persistent=true])
B(-6,20,-2,minecraft:spruce_leaves[distance=7,persistent=true])
B(-6,9,-1,minecraft:spruce_leaves[distance=7,persistent=true])
B(-6,15,-1,minecraft:spruce_leaves[distance=7,persistent=true])
B(-6,19,-1,minecraft:spruce_leaves[distance=7,persistent=true])
B(-6,20,-1,minecraft:spruce_leaves[distance=7,persistent=true])
B(-6,9,0,minecraft:spruce_leaves[distance=7,persistent=true])
B(-6,19,0,minecraft:spruce_leaves[distance=7,persistent=true])
B(-6,28,0,minecraft:spruce_leaves[distance=7,persistent=true])
B(-6,8,1,minecraft:spruce_leaves[distance=7,persistent=true])
B(-6,9,1,minecraft:spruce_leaves[distance=7,persistent=true])
B(-6,17,1,minecraft:spruce_leaves[distance=7,persistent=true])
B(-6,22,1,minecraft:spruce_leaves[distance=7,persistent=true])
B(-6,8,2,minecraft:spruce_leaves[distance=7,persistent=true])
B(-6,13,2,minecraft:spruce_leaves[distance=7,persistent=true])
B(-6,17,2,minecraft:spruce_leaves[distance=7,persistent=true])
B(-6,18,2,minecraft:spruce_leaves[distance=7,persistent=true])
B(-6,22,2,minecraft:spruce_leaves[distance=7,persistent=true])
B(-6,13,3,minecraft:spruce_leaves[distance=7,persistent=true])
B(-6,14,3,minecraft:spruce_leaves[distance=7,persistent=true])
B(-6,17,3,minecraft:spruce_leaves[distance=7,persistent=true])
B(-6,18,3,minecraft:spruce_leaves[distance=7,persistent=true])
B(-6,7,4,minecraft:spruce_leaves[distance=7,persistent=true])
B(-6,8,4,minecraft:spruce_leaves[distance=7,persistent=true])
B(-6,9,4,minecraft:spruce_leaves[distance=7,persistent=true])
B(-6,13,4,minecraft:spruce_leaves[distance=7,persistent=true])
B(-6,14,4,minecraft:spruce_leaves[distance=7,persistent=true])
B(-6,8,5,minecraft:spruce_leaves[distance=7,persistent=true])
B(-6,8,6,minecraft:spruce_leaves[distance=7,persistent=true])
B(-5,7,-6,minecraft:spruce_leaves[distance=7,persistent=true])
B(-5,7,-5,minecraft:spruce_leaves[distance=7,persistent=true])
B(-5,9,-5,minecraft:spruce_leaves[distance=7,persistent=true])
B(-5,10,-5,minecraft:spruce_leaves[distance=7,persistent=true])
B(-5,7,-4,minecraft:spruce_leaves[distance=7,persistent=true])
B(-5,10,-4,minecraft:spruce_leaves[distance=7,persistent=true])
B(-5,15,-4,minecraft:spruce_leaves[distance=7,persistent=true])
B(-5,7,-3,minecraft:spruce_leaves[distance=7,persistent=true])
B(-5,8,-3,minecraft:spruce_leaves[distance=7,persistent=true])
B(-5,10,-3,minecraft:spruce_leaves[distance=7,persistent=true])
B(-5,15,-3,minecraft:spruce_leaves[distance=7,persistent=true])
B(-5,16,-3,minecraft:spruce_leaves[distance=7,persistent=true])
B(-5,19,-3,minecraft:spruce_leaves[distance=7,persistent=true])
B(-5,20,-3,minecraft:spruce_leaves[distance=7,persistent=true])
B(-5,25,-3,minecraft:spruce_leaves[distance=7,persistent=true])
B(-5,26,-3,minecraft:spruce_leaves[distance=7,persistent=true])
B(-5,8,-2,minecraft:spruce_leaves[distance=7,persistent=true])
B(-5,9,-2,minecraft:spruce_leaves[distance=7,persistent=true])
B(-5,10,-2,minecraft:spruce_leaves[distance=7,persistent=true])
B(-5,16,-2,minecraft:spruce_leaves[distance=7,persistent=true])
B(-5,20,-2,minecraft:spruce_leaves[distance=7,persistent=true])
B(-5,21,-2,minecraft:spruce_leaves[distance=5,persistent=false])
B(-5,25,-2,minecraft:spruce_leaves[distance=7,persistent=true])
B(-5,26,-2,minecraft:spruce_leaves[distance=7,persistent=true])
B(-5,32,-2,minecraft:spruce_leaves[distance=7,persistent=true])
B(-5,9,-1,minecraft:spruce_leaves[distance=7,persistent=true])
B(-5,10,-1,minecraft:spruce_leaves[distance=7,persistent=true])
B(-5,16,-1,minecraft:spruce_leaves[distance=7,persistent=true])
B(-5,20,-1,minecraft:spruce_leaves[distance=5,persistent=false])
B(-5,21,-1,minecraft:spruce_leaves[distance=4,persistent=false])
B(-5,25,-1,minecraft:spruce_leaves[distance=7,persistent=true])
B(-5,26,-1,minecraft:spruce_leaves[distance=7,persistent=true])
B(-5,27,-1,minecraft:spruce_leaves[distance=7,persistent=true])
B(-5,28,-1,minecraft:spruce_leaves[distance=4,persistent=false])
B(-5,9,0,minecraft:spruce_leaves[distance=7,persistent=true])
B(-5,10,0,minecraft:spruce_leaves[distance=7,persistent=true])
B(-5,20,0,minecraft:spruce_leaves[distance=7,persistent=true])
B(-5,22,0,minecraft:spruce_leaves[distance=7,persistent=true])
B(-5,25,0,minecraft:spruce_leaves[distance=7,persistent=true])
B(-5,28,0,minecraft:spruce_leaves[distance=7,persistent=true])
B(-5,29,0,minecraft:spruce_leaves[distance=3,persistent=false])
B(-5,9,1,minecraft:spruce_leaves[distance=7,persistent=true])
B(-5,18,1,minecraft:spruce_leaves[distance=7,persistent=true])
B(-5,22,1,minecraft:spruce_leaves[distance=7,persistent=true])
B(-5,23,1,minecraft:spruce_leaves[distance=7,persistent=true])
B(-5,28,1,minecraft:spruce_leaves[distance=7,persistent=true])
B(-5,7,2,minecraft:spruce_leaves[distance=7,persistent=true])
B(-5,8,2,minecraft:spruce_leaves[distance=7,persistent=true])
B(-5,14,2,minecraft:spruce_leaves[distance=7,persistent=true])
B(-5,18,2,minecraft:spruce_leaves[distance=7,persistent=true])
B(-5,19,2,minecraft:spruce_leaves[distance=7,persistent=true])
B(-5,22,2,minecraft:spruce_leaves[distance=7,persistent=true])
B(-5,23,2,minecraft:spruce_leaves[distance=7,persistent=true])
B(-5,7,3,minecraft:spruce_leaves[distance=7,persistent=true])
B(-5,14,3,minecraft:spruce_leaves[distance=7,persistent=true])
B(-5,15,3,minecraft:spruce_leaves[distance=7,persistent=true])
B(-5,18,3,minecraft:spruce_leaves[distance=7,persistent=true])
B(-5,6,4,minecraft:spruce_leaves[distance=7,persistent=true])
B(-5,7,4,minecraft:spruce_leaves[distance=7,persistent=true])
B(-5,10,4,minecraft:spruce_leaves[distance=7,persistent=true])
B(-5,11,4,minecraft:spruce_leaves[distance=7,persistent=true])
B(-5,13,4,minecraft:spruce_leaves[distance=7,persistent=true])
B(-5,14,4,minecraft:spruce_leaves[distance=7,persistent=true])
B(-5,17,4,minecraft:spruce_leaves[distance=7,persistent=true])
B(-5,6,5,minecraft:spruce_leaves[distance=7,persistent=true])
B(-5,7,5,minecraft:spruce_leaves[distance=7,persistent=true])
B(-5,8,5,minecraft:spruce_leaves[distance=7,persistent=true])
B(-5,10,5,minecraft:spruce_leaves[distance=7,persistent=true])
B(-5,11,5,minecraft:spruce_leaves[distance=7,persistent=true])
B(-5,12,5,minecraft:spruce_leaves[distance=7,persistent=true])
B(-5,13,5,minecraft:spruce_leaves[distance=7,persistent=true])
B(-5,8,6,minecraft:spruce_leaves[distance=7,persistent=true])
B(-5,10,6,minecraft:spruce_leaves[distance=7,persistent=true])
B(-5,11,6,minecraft:spruce_leaves[distance=7,persistent=true])
B(-4,7,-6,minecraft:spruce_leaves[distance=7,persistent=true])
B(-4,12,-6,minecraft:spruce_leaves[distance=7,persistent=true])
B(-4,7,-5,minecraft:spruce_leaves[distance=7,persistent=true])
B(-4,8,-5,minecraft:spruce_leaves[distance=7,persistent=true])
B(-4,9,-5,minecraft:spruce_leaves[distance=7,persistent=true])
B(-4,12,-5,minecraft:spruce_leaves[distance=7,persistent=true])
B(-4,7,-4,minecraft:spruce_leaves[distance=7,persistent=true])
B(-4,8,-4,minecraft:spruce_leaves[distance=7,persistent=true])
B(-4,10,-4,minecraft:spruce_leaves[distance=7,persistent=true])
B(-4,11,-4,minecraft:spruce_leaves[distance=7,persistent=true])
B(-4,12,-4,minecraft:spruce_leaves[distance=7,persistent=true])
B(-4,13,-4,minecraft:spruce_leaves[distance=7,persistent=true])
B(-4,15,-4,minecraft:spruce_leaves[distance=7,persistent=true])
B(-4,8,-3,minecraft:spruce_leaves[distance=7,persistent=true])
B(-4,11,-3,minecraft:spruce_leaves[distance=7,persistent=true])
B(-4,12,-3,minecraft:spruce_leaves[distance=7,persistent=true])
B(-4,13,-3,minecraft:spruce_leaves[distance=7,persistent=true])
B(-4,15,-3,minecraft:spruce_leaves[distance=7,persistent=true])
B(-4,16,-3,minecraft:spruce_leaves[distance=7,persistent=true])
B(-4,25,-3,minecraft:spruce_leaves[distance=7,persistent=true])
B(-4,26,-3,minecraft:spruce_leaves[distance=7,persistent=true])
B(-4,32,-3,minecraft:spruce_leaves[distance=7,persistent=true])
B(-4,10,-1,minecraft:spruce_leaves[distance=4,persistent=false])
B(-4,12,-1,minecraft:spruce_leaves[distance=6,persistent=false])
B(-4,17,-1,minecraft:spruce_leaves[distance=7,persistent=true])
B(-4,21,-1,minecraft:spruce_leaves[distance=3,persistent=false])
B(-4,26,-1,minecraft:spruce_leaves[distance=5,persistent=false])
B(-4,27,-1,minecraft:spruce_leaves[distance=4,persistent=false])
B(-4,28,-1,minecraft:spruce_leaves[distance=3,persistent=false])
B(-4,29,-1,minecraft:spruce_leaves[distance=3,persistent=false])
B(-4,30,-1,minecraft:spruce_leaves[distance=3,persistent=false])
B(-4,32,-1,minecraft:spruce_leaves[distance=4,persistent=false])
B(-4,33,-1,minecraft:spruce_leaves[distance=3,persistent=false])
B(-4,34,-1,minecraft:spruce_leaves[distance=3,persistent=false])
B(-4,10,0,minecraft:spruce_leaves[distance=5,persistent=false])
B(-4,11,0,minecraft:spruce_leaves[distance=4,persistent=false])
B(-4,21,0,minecraft:spruce_leaves[distance=2,persistent=false])
B(-4,23,0,minecraft:spruce_leaves[distance=3,persistent=false])
B(-4,24,0,minecraft:spruce_leaves[distance=4,persistent=false])
B(-4,26,0,minecraft:spruce_leaves[distance=7,persistent=true])
B(-4,29,0,minecraft:spruce_leaves[distance=2,persistent=false])
B(-4,30,0,minecraft:spruce_leaves[distance=2,persistent=false])
B(-4,31,0,minecraft:spruce_leaves[distance=2,persistent=false])
B(-4,33,0,minecraft:spruce_leaves[distance=2,persistent=false])
B(-4,34,0,minecraft:spruce_leaves[distance=2,persistent=false])
B(-4,38,0,minecraft:spruce_leaves[distance=2,persistent=false])
B(-4,39,0,minecraft:spruce_leaves[distance=2,persistent=false])
B(-4,45,0,minecraft:spruce_leaves[distance=2,persistent=false])
B(-4,8,2,minecraft:spruce_leaves[distance=7,persistent=true])
B(-4,15,2,minecraft:spruce_leaves[distance=7,persistent=true])
B(-4,19,2,minecraft:spruce_leaves[distance=7,persistent=true])
B(-4,22,2,minecraft:spruce_leaves[distance=7,persistent=true])
B(-4,23,2,minecraft:spruce_leaves[distance=7,persistent=true])
B(-4,35,2,minecraft:spruce_leaves[distance=7,persistent=true])
B(-4,8,3,minecraft:spruce_leaves[distance=7,persistent=true])
B(-4,12,3,minecraft:spruce_leaves[distance=7,persistent=true])
B(-4,14,3,minecraft:spruce_leaves[distance=7,persistent=true])
B(-4,15,3,minecraft:spruce_leaves[distance=7,persistent=true])
B(-4,18,3,minecraft:spruce_leaves[distance=7,persistent=true])
B(-4,25,3,minecraft:spruce_leaves[distance=7,persistent=true])
B(-4,26,3,minecraft:spruce_leaves[distance=7,persistent=true])
B(-4,7,4,minecraft:spruce_leaves[distance=7,persistent=true])
B(-4,8,4,minecraft:spruce_leaves[distance=7,persistent=true])
B(-4,11,4,minecraft:spruce_leaves[distance=7,persistent=true])
B(-4,12,4,minecraft:spruce_leaves[distance=7,persistent=true])
B(-4,13,4,minecraft:spruce_leaves[distance=7,persistent=true])
B(-4,14,4,minecraft:spruce_leaves[distance=7,persistent=true])
B(-4,17,4,minecraft:spruce_leaves[distance=7,persistent=true])
B(-4,25,4,minecraft:spruce_leaves[distance=7,persistent=true])
B(-4,7,5,minecraft:spruce_leaves[distance=7,persistent=true])
B(-4,8,5,minecraft:spruce_leaves[distance=7,persistent=true])
B(-4,11,5,minecraft:spruce_leaves[distance=7,persistent=true])
B(-4,12,5,minecraft:spruce_leaves[distance=7,persistent=true])
B(-4,13,5,minecraft:spruce_leaves[distance=7,persistent=true])
B(-4,6,6,minecraft:spruce_leaves[distance=7,persistent=true])
B(-4,7,6,minecraft:spruce_leaves[distance=7,persistent=true])
B(-4,10,6,minecraft:spruce_leaves[distance=7,persistent=true])
B(-4,11,6,minecraft:spruce_leaves[distance=7,persistent=true])
B(-4,10,7,minecraft:spruce_leaves[distance=7,persistent=true])
B(-3,6,-6,minecraft:spruce_leaves[distance=7,persistent=true])
B(-3,12,-6,minecraft:spruce_leaves[distance=7,persistent=true])
B(-3,7,-5,minecraft:spruce_leaves[distance=7,persistent=true])
B(-3,9,-5,minecraft:spruce_leaves[distance=7,persistent=true])
B(-3,13,-5,minecraft:spruce_leaves[distance=7,persistent=true])
B(-3,7,-4,minecraft:spruce_leaves[distance=7,persistent=true])
B(-3,8,-4,minecraft:spruce_leaves[distance=7,persistent=true])
B(-3,10,-4,minecraft:spruce_leaves[distance=7,persistent=true])
B(-3,13,-4,minecraft:spruce_leaves[distance=7,persistent=true])
B(-3,14,-4,minecraft:spruce_leaves[distance=7,persistent=true])
B(-3,17,-4,minecraft:spruce_leaves[distance=7,persistent=true])
B(-3,8,-3,minecraft:spruce_leaves[distance=7,persistent=true])
B(-3,9,-3,minecraft:spruce_leaves[distance=7,persistent=true])
B(-3,11,-3,minecraft:spruce_leaves[distance=7,persistent=true])
B(-3,13,-3,minecraft:spruce_leaves[distance=7,persistent=true])
B(-3,14,-3,minecraft:spruce_leaves[distance=7,persistent=true])
B(-3,17,-3,minecraft:spruce_leaves[distance=7,persistent=true])
B(-3,18,-3,minecraft:spruce_leaves[distance=7,persistent=true])
B(-3,9,-2,minecraft:spruce_leaves[distance=4,persistent=false])
B(-3,12,-2,minecraft:spruce_leaves[distance=6,persistent=false])
B(-3,14,-2,minecraft:spruce_leaves[distance=7,persistent=true])
B(-3,15,-2,minecraft:spruce_leaves[distance=7,persistent=true])
B(-3,17,-2,minecraft:spruce_leaves[distance=7,persistent=true])
B(-3,22,-2,minecraft:spruce_leaves[distance=3,persistent=false])
B(-3,25,-2,minecraft:spruce_leaves[distance=6,persistent=false])
B(-3,26,-2,minecraft:spruce_leaves[distance=5,persistent=false])
B(-3,27,-2,minecraft:spruce_leaves[distance=4,persistent=false])
B(-3,32,-2,minecraft:spruce_leaves[distance=4,persistent=false])
B(-3,33,-2,minecraft:spruce_leaves[distance=3,persistent=false])
B(-3,35,-2,minecraft:spruce_leaves[distance=7,persistent=true])
B(-3,36,-2,minecraft:spruce_leaves[distance=3,persistent=false])
B(-3,9,-1,minecraft:spruce_leaves[distance=3,persistent=false])
B(-3,10,-1,minecraft:spruce_leaves[distance=3,persistent=false])
B(-3,11,-1,minecraft:spruce_leaves[distance=4,persistent=false])
B(-3,12,-1,minecraft:spruce_leaves[distance=5,persistent=false])
B(-3,13,-1,minecraft:spruce_leaves[distance=6,persistent=false])
B(-3,15,-1,minecraft:spruce_leaves[distance=7,persistent=true])
B(-3,17,-1,minecraft:spruce_leaves[distance=4,persistent=false])
B(-3,18,-1,minecraft:spruce_leaves[distance=3,persistent=false])
B(-3,21,-1,minecraft:spruce_leaves[distance=2,persistent=false])
B(-3,22,-1,minecraft:spruce_leaves[distance=2,persistent=false])
B(-3,27,-1,minecraft:spruce_leaves[distance=3,persistent=false])
B(-3,28,-1,minecraft:spruce_leaves[distance=2,persistent=false])
B(-3,29,-1,minecraft:spruce_leaves[distance=2,persistent=false])
B(-3,30,-1,minecraft:spruce_leaves[distance=2,persistent=false])
B(-3,31,-1,minecraft:spruce_leaves[distance=2,persistent=false])
B(-3,33,-1,minecraft:spruce_leaves[distance=2,persistent=false])
B(-3,34,-1,minecraft:spruce_leaves[distance=2,persistent=false])
B(-3,38,-1,minecraft:spruce_leaves[distance=2,persistent=false])
B(-3,39,-1,minecraft:spruce_leaves[distance=2,persistent=false])
B(-3,40,-1,minecraft:spruce_leaves[distance=2,persistent=false])
B(-3,42,-1,minecraft:spruce_leaves[distance=3,persistent=false])
B(-3,43,-1,minecraft:spruce_leaves[distance=2,persistent=false])
B(-3,44,-1,minecraft:spruce_leaves[distance=2,persistent=false])
B(-3,45,-1,minecraft:spruce_leaves[distance=2,persistent=false])
B(-3,46,-1,minecraft:spruce_leaves[distance=2,persistent=false])
B(-3,-7,0,minecraft:oak_wood)
B(-3,11,0,minecraft:spruce_leaves[distance=3,persistent=false])
B(-3,12,0,minecraft:spruce_leaves[distance=4,persistent=false])
B(-3,13,0,minecraft:spruce_leaves[distance=5,persistent=false])
B(-3,18,0,minecraft:spruce_leaves[distance=2,persistent=false])
B(-3,21,0,minecraft:spruce_leaves)
B(-3,22,0,minecraft:spruce_leaves)
B(-3,23,0,minecraft:spruce_leaves[distance=2,persistent=false])
B(-3,24,0,minecraft:spruce_leaves[distance=3,persistent=false])
B(-3,25,0,minecraft:spruce_leaves[distance=4,persistent=false])
B(-3,28,0,minecraft:spruce_leaves)
B(-3,29,0,minecraft:spruce_leaves)
B(-3,30,0,minecraft:spruce_leaves)
B(-3,31,0,minecraft:spruce_leaves)
B(-3,32,0,minecraft:spruce_leaves)
B(-3,33,0,minecraft:spruce_leaves)
B(-3,34,0,minecraft:spruce_leaves)
B(-3,35,0,minecraft:spruce_leaves)
B(-3,36,0,minecraft:spruce_leaves)
B(-3,37,0,minecraft:spruce_leaves)
B(-3,38,0,minecraft:spruce_leaves)
B(-3,39,0,minecraft:spruce_leaves)
B(-3,40,0,minecraft:spruce_leaves)
B(-3,41,0,minecraft:spruce_leaves[distance=2,persistent=false])
B(-3,45,0,minecraft:spruce_leaves)
B(-3,46,0,minecraft:spruce_leaves)
B(-3,47,0,minecraft:spruce_leaves[distance=2,persistent=false])
B(-3,-7,1,minecraft:oak_wood)
B(-3,-6,1,minecraft:oak_wood)
B(-3,-5,1,minecraft:oak_wood)
B(-3,9,1,minecraft:spruce_leaves[distance=2,persistent=false])
B(-3,11,1,minecraft:spruce_leaves[distance=3,persistent=false])
B(-3,12,1,minecraft:spruce_leaves[distance=4,persistent=false])
B(-3,14,1,minecraft:spruce_leaves[distance=6,persistent=false])
B(-3,15,1,minecraft:spruce_leaves[distance=7,persistent=true])
B(-3,16,1,minecraft:spruce_leaves[distance=3,persistent=false])
B(-3,20,1,minecraft:spruce_leaves[distance=2,persistent=false])
B(-3,24,1,minecraft:spruce_leaves[distance=4,persistent=false])
B(-3,25,1,minecraft:spruce_leaves[distance=4,persistent=false])
B(-3,33,1,minecraft:spruce_leaves[distance=2,persistent=false])
B(-3,35,1,minecraft:spruce_leaves[distance=2,persistent=false])
B(-3,36,1,minecraft:spruce_leaves[distance=2,persistent=false])
B(-3,37,1,minecraft:spruce_leaves[distance=2,persistent=false])
B(-3,40,1,minecraft:spruce_leaves[distance=2,persistent=false])
B(-3,41,1,minecraft:spruce_leaves[distance=3,persistent=false])
B(-3,-6,2,minecraft:oak_wood)
B(-3,-5,2,minecraft:oak_wood)
B(-3,9,2,minecraft:spruce_leaves[distance=3,persistent=false])
B(-3,13,2,minecraft:spruce_leaves[distance=6,persistent=false])
B(-3,15,2,minecraft:spruce_leaves[distance=7,persistent=true])
B(-3,16,2,minecraft:spruce_leaves[distance=4,persistent=false])
B(-3,19,2,minecraft:spruce_leaves[distance=7,persistent=true])
B(-3,27,2,minecraft:spruce_leaves[distance=3,persistent=false])
B(-3,28,2,minecraft:spruce_leaves[distance=2,persistent=false])
B(-3,32,2,minecraft:spruce_leaves[distance=4,persistent=false])
B(-3,33,2,minecraft:spruce_leaves[distance=3,persistent=false])
B(-3,36,2,minecraft:spruce_leaves[distance=3,persistent=false])
B(-3,9,3,minecraft:spruce_leaves[distance=4,persistent=false])
B(-3,12,3,minecraft:spruce_leaves[distance=7,persistent=true])
B(-3,13,3,minecraft:spruce_leaves[distance=7,persistent=true])
B(-3,14,3,minecraft:spruce_leaves[distance=7,persistent=true])
B(-3,15,3,minecraft:spruce_leaves[distance=7,persistent=true])
B(-3,26,3,minecraft:spruce_leaves[distance=7,persistent=true])
B(-3,27,3,minecraft:spruce_leaves[distance=4,persistent=false])
B(-3,31,3,minecraft:spruce_leaves[distance=7,persistent=true])
B(-3,32,3,minecraft:spruce_leaves[distance=5,persistent=false])
B(-3,8,4,minecraft:spruce_leaves[distance=7,persistent=true])
B(-3,12,4,minecraft:spruce_leaves[distance=7,persistent=true])
B(-3,26,4,minecraft:spruce_leaves[distance=7,persistent=true])
B(-3,7,5,minecraft:spruce_leaves[distance=7,persistent=true])
B(-3,11,5,minecraft:spruce_leaves[distance=7,persistent=true])
B(-3,25,5,minecraft:spruce_leaves[distance=7,persistent=true])
B(-3,26,5,minecraft:spruce_leaves[distance=7,persistent=true])
B(-3,6,6,minecraft:spruce_leaves[distance=7,persistent=true])
B(-3,7,6,minecraft:spruce_leaves[distance=7,persistent=true])
B(-3,10,6,minecraft:spruce_leaves[distance=7,persistent=true])
B(-3,11,6,minecraft:spruce_leaves[distance=7,persistent=true])
B(-3,9,7,minecraft:spruce_leaves[distance=7,persistent=true])
B(-3,10,7,minecraft:spruce_leaves[distance=7,persistent=true])
B(-2,12,-6,minecraft:spruce_leaves[distance=7,persistent=true])
B(-2,6,-5,minecraft:spruce_leaves[distance=7,persistent=true])
B(-2,7,-5,minecraft:spruce_leaves[distance=7,persistent=true])
B(-2,9,-5,minecraft:spruce_leaves[distance=7,persistent=true])
B(-2,12,-5,minecraft:spruce_leaves[distance=7,persistent=true])
B(-2,13,-5,minecraft:spruce_leaves[distance=7,persistent=true])
B(-2,17,-5,minecraft:spruce_leaves[distance=7,persistent=true])
B(-2,7,-4,minecraft:spruce_leaves[distance=7,persistent=true])
B(-2,8,-4,minecraft:spruce_leaves[distance=7,persistent=true])
B(-2,10,-4,minecraft:spruce_leaves[distance=7,persistent=true])
B(-2,13,-4,minecraft:spruce_leaves[distance=7,persistent=true])
B(-2,14,-4,minecraft:spruce_leaves[distance=7,persistent=true])
B(-2,17,-4,minecraft:spruce_leaves[distance=7,persistent=true])
B(-2,18,-4,minecraft:spruce_leaves[distance=7,persistent=true])
B(-2,21,-4,minecraft:spruce_leaves[distance=7,persistent=true])
B(-2,22,-4,minecraft:spruce_leaves[distance=6,persistent=false])
B(-2,8,-3,minecraft:spruce_leaves[distance=7,persistent=true])
B(-2,9,-3,minecraft:spruce_leaves[distance=4,persistent=false])
B(-2,11,-3,minecraft:spruce_leaves[distance=7,persistent=true])
B(-2,14,-3,minecraft:spruce_leaves[distance=7,persistent=true])
B(-2,15,-3,minecraft:spruce_leaves[distance=7,persistent=true])
B(-2,18,-3,minecraft:spruce_leaves[distance=7,persistent=true])
B(-2,19,-3,minecraft:spruce_leaves[distance=3,persistent=false])
B(-2,22,-3,minecraft:spruce_leaves[distance=5,persistent=false])
B(-2,23,-3,minecraft:spruce_leaves[distance=4,persistent=false])
B(-2,9,-2,minecraft:spruce_leaves[distance=3,persistent=false])
B(-2,10,-2,minecraft:spruce_leaves[distance=3,persistent=false])
B(-2,12,-2,minecraft:spruce_leaves[distance=7,persistent=true])
B(-2,15,-2,minecraft:spruce_leaves[distance=7,persistent=true])
B(-2,19,-2,minecraft:spruce_leaves[distance=2,persistent=false])
B(-2,23,-2,minecraft:spruce_leaves[distance=3,persistent=false])
B(-2,24,-2,minecraft:spruce_leaves[distance=4,persistent=false])
B(-2,25,-2,minecraft:spruce_leaves[distance=5,persistent=false])
B(-2,26,-2,minecraft:spruce_leaves[distance=4,persistent=false])
B(-2,32,-2,minecraft:spruce_leaves[distance=7,persistent=true])
B(-2,35,-2,minecraft:spruce_leaves[distance=3,persistent=false])
B(-2,36,-2,minecraft:spruce_leaves[distance=2,persistent=false])
B(-2,37,-2,minecraft:spruce_leaves[distance=2,persistent=false])
B(-2,42,-2,minecraft:spruce_leaves[distance=3,persistent=false])
B(-2,-6,-1,minecraft:oak_wood)
B(-2,9,-1,minecraft:spruce_leaves[distance=2,persistent=false])
B(-2,10,-1,minecraft:spruce_leaves[distance=2,persistent=false])
B(-2,13,-1,minecraft:spruce_leaves[distance=5,persistent=false])
B(-2,14,-1,minecraft:spruce_leaves[distance=6,persistent=false])
B(-2,15,-1,minecraft:spruce_leaves[distance=7,persistent=true])
B(-2,16,-1,minecraft:spruce_leaves[distance=4,persistent=false])
B(-2,19,-1,minecraft:spruce_leaves)
B(-2,20,-1,minecraft:spruce_leaves)
B(-2,21,-1,minecraft:spruce_leaves)
B(-2,22,-1,minecraft:spruce_leaves)
B(-2,23,-1,minecraft:spruce_leaves[distance=2,persistent=false])
B(-2,24,-1,minecraft:spruce_leaves[distance=3,persistent=false])
B(-2,25,-1,minecraft:spruce_leaves[distance=4,persistent=false])
B(-2,26,-1,minecraft:spruce_leaves[distance=3,persistent=false])
B(-2,27,-1,minecraft:spruce_leaves[distance=2,persistent=false])
B(-2,28,-1,minecraft:spruce_leaves)
B(-2,29,-1,minecraft:spruce_leaves)
B(-2,33,-1,minecraft:spruce_leaves)
B(-2,34,-1,minecraft:spruce_leaves)
B(-2,36,-1,minecraft:spruce_leaves)
B(-2,37,-1,minecraft:spruce_leaves)
B(-2,38,-1,minecraft:spruce_leaves)
B(-2,39,-1,minecraft:spruce_leaves)
B(-2,40,-1,minecraft:spruce_leaves)
B(-2,41,-1,minecraft:spruce_leaves[distance=2,persistent=false])
B(-2,42,-1,minecraft:spruce_leaves[distance=2,persistent=false])
B(-2,43,-1,minecraft:spruce_leaves)
B(-2,44,-1,minecraft:spruce_leaves)
B(-2,47,-1,minecraft:spruce_leaves[distance=2,persistent=false])
B(-2,-8,0,minecraft:oak_wood)
B(-2,-6,0,minecraft:oak_wood)
B(-2,-5,0,minecraft:oak_wood)
B(-2,-4,0,minecraft:oak_wood)
B(-2,-2,0,minecraft:oak_wood)
B(-2,-1,0,minecraft:oak_wood)
B(-2,0,0,minecraft:oak_wood)
B(-2,1,0,minecraft:oak_wood)
B(-2,2,0,minecraft:oak_wood)
B(-2,3,0,minecraft:oak_wood)
B(-2,4,0,minecraft:oak_wood)
B(-2,5,0,minecraft:oak_wood)
B(-2,6,0,minecraft:oak_wood)
B(-2,7,0,minecraft:oak_wood)
B(-2,8,0,minecraft:oak_wood)
B(-2,9,0,minecraft:spruce_leaves)
B(-2,10,0,minecraft:spruce_leaves)
B(-2,11,0,minecraft:spruce_leaves[distance=2,persistent=false])
B(-2,12,0,minecraft:spruce_leaves[distance=3,persistent=false])
B(-2,13,0,minecraft:spruce_leaves[distance=4,persistent=false])
B(-2,14,0,minecraft:spruce_leaves[distance=5,persistent=false])
B(-2,15,0,minecraft:spruce_leaves[distance=4,persistent=false])
B(-2,16,0,minecraft:spruce_leaves[distance=3,persistent=false])
B(-2,17,0,minecraft:spruce_leaves[distance=2,persistent=false])
B(-2,18,0,minecraft:spruce_leaves)
B(-2,19,0,minecraft:oak_log)
B(-2,20,0,minecraft:oak_log)
B(-2,21,0,minecraft:oak_log)
B(-2,22,0,minecraft:oak_log)
B(-2,23,0,minecraft:spruce_leaves)
B(-2,24,0,minecraft:spruce_leaves[distance=2,persistent=false])
B(-2,25,0,minecraft:spruce_leaves[distance=3,persistent=false])
B(-2,26,0,minecraft:spruce_leaves[distance=2,persistent=false])
B(-2,27,0,minecraft:spruce_leaves)
B(-2,28,0,minecraft:oak_log)
B(-2,29,0,minecraft:oak_log)
B(-2,30,0,minecraft:oak_log)
B(-2,31,0,minecraft:oak_log)
B(-2,32,0,minecraft:oak_log)
B(-2,33,0,minecraft:oak_log)
B(-2,34,0,minecraft:oak_log)
B(-2,35,0,minecraft:oak_log)
B(-2,36,0,minecraft:oak_log)
B(-2,37,0,minecraft:oak_log)
B(-2,38,0,minecraft:oak_log)
B(-2,39,0,minecraft:oak_log)
B(-2,40,0,minecraft:oak_log)
B(-2,41,0,minecraft:spruce_leaves)
B(-2,42,0,minecraft:spruce_leaves)
B(-2,43,0,minecraft:oak_log)
B(-2,44,0,minecraft:oak_log)
B(-2,45,0,minecraft:oak_log)
B(-2,46,0,minecraft:oak_log)
B(-2,47,0,minecraft:spruce_leaves)
B(-2,48,0,minecraft:oak_log)
B(-2,49,0,minecraft:oak_log)
B(-2,50,0,minecraft:oak_log)
B(-2,51,0,minecraft:oak_log)
B(-2,52,0,minecraft:oak_log)
B(-2,53,0,minecraft:oak_log)
B(-2,54,0,minecraft:oak_log)
B(-2,55,0,minecraft:oak_log)
B(-2,-7,1,minecraft:oak_wood)
B(-2,-6,1,minecraft:oak_wood)
B(-2,-5,1,minecraft:oak_wood)
B(-2,-4,1,minecraft:oak_wood)
B(-2,-3,1,minecraft:oak_wood)
B(-2,-2,1,minecraft:oak_wood)
B(-2,-1,1,minecraft:oak_wood)
B(-2,0,1,minecraft:oak_wood)
B(-2,1,1,minecraft:oak_wood)
B(-2,2,1,minecraft:oak_wood)
B(-2,3,1,minecraft:oak_wood)
B(-2,4,1,minecraft:oak_wood)
B(-2,5,1,minecraft:oak_wood)
B(-2,6,1,minecraft:oak_wood)
B(-2,7,1,minecraft:oak_wood)
B(-2,8,1,minecraft:oak_wood)
B(-2,9,1,minecraft:spruce_leaves)
B(-2,10,1,minecraft:spruce_leaves)
B(-2,11,1,minecraft:spruce_leaves[distance=2,persistent=false])
B(-2,12,1,minecraft:spruce_leaves[distance=3,persistent=false])
B(-2,13,1,minecraft:spruce_leaves[distance=4,persistent=false])
B(-2,14,1,minecraft:spruce_leaves[distance=5,persistent=false])
B(-2,15,1,minecraft:spruce_leaves[distance=3,persistent=false])
B(-2,16,1,minecraft:spruce_leaves[distance=2,persistent=false])
B(-2,17,1,minecraft:spruce_leaves)
B(-2,18,1,minecraft:oak_log)
B(-2,19,1,minecraft:oak_log)
B(-2,20,1,minecraft:spruce_leaves)
B(-2,21,1,minecraft:spruce_leaves)
B(-2,22,1,minecraft:spruce_leaves)
B(-2,23,1,minecraft:spruce_leaves[distance=2,persistent=false])
B(-2,24,1,minecraft:spruce_leaves[distance=3,persistent=false])
B(-2,25,1,minecraft:spruce_leaves[distance=3,persistent=false])
B(-2,26,1,minecraft:spruce_leaves[distance=2,persistent=false])
B(-2,27,1,minecraft:spruce_leaves)
B(-2,28,1,minecraft:oak_log)
B(-2,29,1,minecraft:spruce_leaves)
B(-2,30,1,minecraft:oak_log)
B(-2,31,1,minecraft:oak_log)
B(-2,32,1,minecraft:spruce_leaves)
B(-2,33,1,minecraft:spruce_leaves)
B(-2,34,1,minecraft:spruce_leaves)
B(-2,36,1,minecraft:spruce_leaves)
B(-2,38,1,minecraft:spruce_leaves)
B(-2,39,1,minecraft:spruce_leaves)
B(-2,40,1,minecraft:spruce_leaves)
B(-2,41,1,minecraft:spruce_leaves[distance=2,persistent=false])
B(-2,42,1,minecraft:spruce_leaves[distance=2,persistent=false])
B(-2,43,1,minecraft:spruce_leaves)
B(-2,45,1,minecraft:spruce_leaves)
B(-2,46,1,minecraft:spruce_leaves)
B(-2,-8,2,minecraft:oak_wood)
B(-2,-1,2,minecraft:oak_wood)
B(-2,9,2,minecraft:spruce_leaves[distance=2,persistent=false])
B(-2,10,2,minecraft:spruce_leaves[distance=2,persistent=false])
B(-2,13,2,minecraft:spruce_leaves[distance=5,persistent=false])
B(-2,14,2,minecraft:spruce_leaves[distance=6,persistent=false])
B(-2,16,2,minecraft:spruce_leaves[distance=3,persistent=false])
B(-2,17,2,minecraft:spruce_leaves[distance=2,persistent=false])
B(-2,18,2,minecraft:spruce_leaves)
B(-2,20,2,minecraft:spruce_leaves[distance=2,persistent=false])
B(-2,21,2,minecraft:spruce_leaves[distance=2,persistent=false])
B(-2,28,2,minecraft:spruce_leaves)
B(-2,30,2,minecraft:spruce_leaves)
B(-2,31,2,minecraft:spruce_leaves)
B(-2,33,2,minecraft:spruce_leaves[distance=2,persistent=false])
B(-2,38,2,minecraft:spruce_leaves[distance=2,persistent=false])
B(-2,-6,3,minecraft:oak_wood)
B(-2,-5,3,minecraft:oak_wood)
B(-2,-4,3,minecraft:oak_wood)
B(-2,-3,3,minecraft:oak_wood)
B(-2,9,3,minecraft:spruce_leaves[distance=3,persistent=false])
B(-2,12,3,minecraft:spruce_leaves[distance=7,persistent=true])
B(-2,13,3,minecraft:spruce_leaves[distance=6,persistent=false])
B(-2,15,3,minecraft:spruce_leaves[distance=7,persistent=true])
B(-2,16,3,minecraft:spruce_leaves[distance=4,persistent=false])
B(-2,17,3,minecraft:spruce_leaves[distance=3,persistent=false])
B(-2,19,3,minecraft:spruce_leaves[distance=4,persistent=false])
B(-2,20,3,minecraft:spruce_leaves[distance=3,persistent=false])
B(-2,27,3,minecraft:spruce_leaves[distance=4,persistent=false])
B(-2,32,3,minecraft:spruce_leaves[distance=4,persistent=false])
B(-2,8,4,minecraft:spruce_leaves[distance=7,persistent=true])
B(-2,12,4,minecraft:spruce_leaves[distance=7,persistent=true])
B(-2,14,4,minecraft:spruce_leaves[distance=7,persistent=true])
B(-2,15,4,minecraft:spruce_leaves[distance=7,persistent=true])
B(-2,16,4,minecraft:spruce_leaves[distance=7,persistent=true])
B(-2,19,4,minecraft:spruce_leaves[distance=7,persistent=true])
B(-2,25,4,minecraft:spruce_leaves[distance=7,persistent=true])
B(-2,26,4,minecraft:spruce_leaves[distance=7,persistent=true])
B(-2,7,5,minecraft:spruce_leaves[distance=7,persistent=true])
B(-2,11,5,minecraft:spruce_leaves[distance=7,persistent=true])
B(-2,15,5,minecraft:spruce_leaves[distance=7,persistent=true])
B(-2,16,5,minecraft:spruce_leaves[distance=7,persistent=true])
B(-2,6,6,minecraft:spruce_leaves[distance=7,persistent=true])
B(-2,10,6,minecraft:spruce_leaves[distance=7,persistent=true])
B(-2,15,6,minecraft:spruce_leaves[distance=7,persistent=true])
B(-2,9,7,minecraft:spruce_leaves[distance=7,persistent=true])
B(-1,12,-5,minecraft:spruce_leaves[distance=7,persistent=true])
B(-1,17,-5,minecraft:spruce_leaves[distance=7,persistent=true])
B(-1,22,-5,minecraft:spruce_leaves[distance=7,persistent=true])
B(-1,13,-4,minecraft:spruce_leaves[distance=7,persistent=true])
B(-1,17,-4,minecraft:spruce_leaves[distance=7,persistent=true])
B(-1,18,-4,minecraft:spruce_leaves[distance=7,persistent=true])
B(-1,22,-4,minecraft:spruce_leaves[distance=6,persistent=false])
B(-1,23,-4,minecraft:spruce_leaves[distance=5,persistent=false])
B(-1,14,-3,minecraft:spruce_leaves[distance=7,persistent=true])
B(-1,18,-3,minecraft:spruce_leaves[distance=7,persistent=true])
B(-1,23,-3,minecraft:spruce_leaves[distance=4,persistent=false])
B(-1,24,-3,minecraft:spruce_leaves[distance=5,persistent=false])
B(-1,27,-3,minecraft:spruce_leaves[distance=7,persistent=true])
B(-1,28,-3,minecraft:spruce_leaves[distance=7,persistent=true])
B(-1,29,-3,minecraft:spruce_leaves[distance=7,persistent=true])
B(-1,33,-3,minecraft:spruce_leaves[distance=7,persistent=true])
B(-1,34,-3,minecraft:spruce_leaves[distance=3,persistent=false])
B(-1,11,-2,minecraft:spruce_leaves[distance=3,persistent=false])
B(-1,15,-2,minecraft:spruce_leaves[distance=7,persistent=true])
B(-1,18,-2,minecraft:spruce_leaves[distance=7,persistent=true])
B(-1,19,-2,minecraft:spruce_leaves[distance=3,persistent=false])
B(-1,23,-2,minecraft:spruce_leaves[distance=3,persistent=false])
B(-1,24,-2,minecraft:spruce_leaves[distance=4,persistent=false])
B(-1,25,-2,minecraft:spruce_leaves[distance=4,persistent=false])
B(-1,29,-2,minecraft:spruce_leaves[distance=3,persistent=false])
B(-1,30,-2,minecraft:spruce_leaves[distance=2,persistent=false])
B(-1,31,-2,minecraft:spruce_leaves[distance=2,persistent=false])
B(-1,34,-2,minecraft:spruce_leaves[distance=2,persistent=false])
B(-1,35,-2,minecraft:spruce_leaves[distance=2,persistent=false])
B(-1,36,-2,minecraft:spruce_leaves[distance=2,persistent=false])
B(-1,38,-2,minecraft:spruce_leaves[distance=3,persistent=false])
B(-1,39,-2,minecraft:spruce_leaves[distance=3,persistent=false])
B(-1,45,-2,minecraft:spruce_leaves[distance=4,persistent=false])
B(-1,-7,-1,minecraft:oak_wood)
B(-1,-5,-1,minecraft:oak_wood)
B(-1,-2,-1,minecraft:oak_wood)
B(-1,-1,-1,minecraft:oak_wood)
B(-1,0,-1,minecraft:oak_wood)
B(-1,9,-1,minecraft:spruce_leaves)
B(-1,10,-1,minecraft:spruce_leaves)
B(-1,11,-1,minecraft:spruce_leaves[distance=2,persistent=false])
B(-1,12,-1,minecraft:spruce_leaves[distance=3,persistent=false])
B(-1,13,-1,minecraft:spruce_leaves[distance=4,persistent=false])
B(-1,14,-1,minecraft:spruce_leaves[distance=5,persistent=false])
B(-1,15,-1,minecraft:spruce_leaves[distance=5,persistent=false])
B(-1,16,-1,minecraft:spruce_leaves[distance=4,persistent=false])
B(-1,20,-1,minecraft:spruce_leaves)
B(-1,21,-1,minecraft:spruce_leaves)
B(-1,22,-1,minecraft:spruce_leaves)
B(-1,23,-1,minecraft:spruce_leaves[distance=2,persistent=false])
B(-1,24,-1,minecraft:spruce_leaves[distance=3,persistent=false])
B(-1,25,-1,minecraft:spruce_leaves[distance=3,persistent=false])
B(-1,26,-1,minecraft:spruce_leaves[distance=2,persistent=false])
B(-1,30,-1,minecraft:spruce_leaves)
B(-1,31,-1,minecraft:spruce_leaves)
B(-1,32,-1,minecraft:spruce_leaves)
B(-1,33,-1,minecraft:spruce_leaves)
B(-1,34,-1,minecraft:spruce_leaves)
B(-1,35,-1,minecraft:spruce_leaves)
B(-1,36,-1,minecraft:spruce_leaves)
B(-1,38,-1,minecraft:spruce_leaves[distance=2,persistent=false])
B(-1,39,-1,minecraft:spruce_leaves[distance=2,persistent=false])
B(-1,40,-1,minecraft:spruce_leaves[distance=2,persistent=false])
B(-1,43,-1,minecraft:spruce_leaves[distance=2,persistent=false])
B(-1,44,-1,minecraft:spruce_leaves[distance=2,persistent=false])
B(-1,45,-1,minecraft:spruce_leaves[distance=3,persistent=false])
B(-1,46,-1,minecraft:spruce_leaves[distance=4,persistent=false])
B(-1,-8,0,minecraft:oak_wood)
B(-1,-7,0,minecraft:oak_wood)
B(-1,-6,0,minecraft:oak_wood)
B(-1,-5,0,minecraft:oak_wood)
B(-1,-4,0,minecraft:oak_wood)
B(-1,0,0,minecraft:oak_wood)
B(-1,1,0,minecraft:oak_wood)
B(-1,2,0,minecraft:oak_wood)
B(-1,3,0,minecraft:oak_wood)
B(-1,4,0,minecraft:oak_wood)
B(-1,5,0,minecraft:oak_wood)
B(-1,6,0,minecraft:oak_wood)
B(-1,7,0,minecraft:oak_wood)
B(-1,8,0,minecraft:oak_wood)
B(-1,9,0,minecraft:oak_wood)
B(-1,10,0,minecraft:oak_wood)
B(-1,11,0,minecraft:spruce_leaves)
B(-1,12,0,minecraft:spruce_leaves[distance=2,persistent=false])
B(-1,13,0,minecraft:spruce_leaves[distance=3,persistent=false])
B(-1,14,0,minecraft:spruce_leaves[distance=4,persistent=false])
B(-1,15,0,minecraft:spruce_leaves[distance=4,persistent=false])
B(-1,16,0,minecraft:spruce_leaves[distance=3,persistent=false])
B(-1,17,0,minecraft:spruce_leaves[distance=2,persistent=false])
B(-1,18,0,minecraft:spruce_leaves)
B(-1,19,0,minecraft:oak_log)
B(-1,20,0,minecraft:oak_log)
B(-1,21,0,minecraft:oak_log)
B(-1,22,0,minecraft:oak_log)
B(-1,23,0,minecraft:spruce_leaves)
B(-1,24,0,minecraft:spruce_leaves[distance=2,persistent=false])
B(-1,25,0,minecraft:spruce_leaves[distance=2,persistent=false])
B(-1,26,0,minecraft:spruce_leaves)
B(-1,27,0,minecraft:oak_log)
B(-1,28,0,minecraft:oak_log)
B(-1,29,0,minecraft:oak_log)
B(-1,30,0,minecraft:oak_log)
B(-1,31,0,minecraft:oak_log)
B(-1,32,0,minecraft:oak_log)
B(-1,33,0,minecraft:oak_log)
B(-1,34,0,minecraft:oak_log)
B(-1,35,0,minecraft:oak_log)
B(-1,36,0,minecraft:oak_log)
B(-1,37,0,minecraft:spruce_leaves)
B(-1,38,0,minecraft:spruce_leaves)
B(-1,39,0,minecraft:spruce_leaves)
B(-1,40,0,minecraft:spruce_leaves)
B(-1,41,0,minecraft:spruce_leaves)
B(-1,42,0,minecraft:oak_log)
B(-1,43,0,minecraft:spruce_leaves)
B(-1,44,0,minecraft:spruce_leaves)
B(-1,47,0,minecraft:spruce_leaves[distance=2,persistent=false])
B(-1,-6,1,minecraft:oak_wood)
B(-1,-5,1,minecraft:oak_wood)
B(-1,-4,1,minecraft:oak_wood)
B(-1,-3,1,minecraft:oak_wood)
B(-1,-2,1,minecraft:oak_wood)
B(-1,2,1,minecraft:oak_wood)
B(-1,3,1,minecraft:oak_wood)
B(-1,4,1,minecraft:oak_wood)
B(-1,5,1,minecraft:oak_wood)
B(-1,6,1,minecraft:oak_wood)
B(-1,7,1,minecraft:oak_wood)
B(-1,8,1,minecraft:oak_wood)
B(-1,9,1,minecraft:oak_wood)
B(-1,10,1,minecraft:oak_wood)
B(-1,11,1,minecraft:spruce_leaves)
B(-1,12,1,minecraft:spruce_leaves[distance=2,persistent=false])
B(-1,13,1,minecraft:spruce_leaves[distance=3,persistent=false])
B(-1,14,1,minecraft:spruce_leaves[distance=4,persistent=false])
B(-1,15,1,minecraft:spruce_leaves[distance=4,persistent=false])
B(-1,16,1,minecraft:spruce_leaves[distance=3,persistent=false])
B(-1,17,1,minecraft:spruce_leaves[distance=2,persistent=false])
B(-1,18,1,minecraft:spruce_leaves)
B(-1,19,1,minecraft:oak_log)
B(-1,20,1,minecraft:oak_log)
B(-1,21,1,minecraft:spruce_leaves)
B(-1,22,1,minecraft:spruce_leaves)
B(-1,23,1,minecraft:spruce_leaves[distance=2,persistent=false])
B(-1,24,1,minecraft:spruce_leaves[distance=3,persistent=false])
B(-1,25,1,minecraft:spruce_leaves[distance=2,persistent=false])
B(-1,26,1,minecraft:spruce_leaves)
B(-1,27,1,minecraft:oak_log)
B(-1,28,1,minecraft:oak_log)
B(-1,29,1,minecraft:oak_log)
B(-1,30,1,minecraft:spruce_leaves)
B(-1,31,1,minecraft:spruce_leaves)
B(-1,32,1,minecraft:spruce_leaves)
B(-1,33,1,minecraft:spruce_leaves)
B(-1,35,1,minecraft:spruce_leaves)
B(-1,36,1,minecraft:spruce_leaves)
B(-1,39,1,minecraft:spruce_leaves[distance=2,persistent=false])
B(-1,40,1,minecraft:spruce_leaves[distance=2,persistent=false])
B(-1,45,1,minecraft:spruce_leaves[distance=2,persistent=false])
B(-1,46,1,minecraft:spruce_leaves[distance=2,persistent=false])
B(-1,-7,2,minecraft:oak_wood)
B(-1,-6,2,minecraft:oak_wood)
B(-1,-4,2,minecraft:oak_wood)
B(-1,-3,2,minecraft:oak_wood)
B(-1,-2,2,minecraft:oak_wood)
B(-1,-1,2,minecraft:oak_wood)
B(-1,0,2,minecraft:oak_wood)
B(-1,1,2,minecraft:oak_wood)
B(-1,9,2,minecraft:spruce_leaves)
B(-1,10,2,minecraft:spruce_leaves)
B(-1,11,2,minecraft:spruce_leaves[distance=2,persistent=false])
B(-1,12,2,minecraft:spruce_leaves[distance=3,persistent=false])
B(-1,13,2,minecraft:spruce_leaves[distance=4,persistent=false])
B(-1,17,2,minecraft:spruce_leaves[distance=3,persistent=false])
B(-1,18,2,minecraft:spruce_leaves[distance=2,persistent=false])
B(-1,20,2,minecraft:spruce_leaves)
B(-1,21,2,minecraft:spruce_leaves[distance=2,persistent=false])
B(-1,22,2,minecraft:spruce_leaves[distance=2,persistent=false])
B(-1,25,2,minecraft:spruce_leaves[distance=3,persistent=false])
B(-1,28,2,minecraft:spruce_leaves)
B(-1,29,2,minecraft:spruce_leaves)
B(-1,30,2,minecraft:spruce_leaves[distance=2,persistent=false])
B(-1,31,2,minecraft:spruce_leaves[distance=2,persistent=false])
B(-1,32,2,minecraft:spruce_leaves[distance=2,persistent=false])
B(-1,34,2,minecraft:spruce_leaves[distance=3,persistent=false])
B(-1,35,2,minecraft:spruce_leaves[distance=2,persistent=false])
B(-1,37,2,minecraft:spruce_leaves[distance=7,persistent=true])
B(-1,38,2,minecraft:spruce_leaves[distance=3,persistent=false])
B(-1,-6,3,minecraft:oak_wood)
B(-1,-4,3,minecraft:oak_wood)
B(-1,10,3,minecraft:spruce_leaves[distance=2,persistent=false])
B(-1,11,3,minecraft:spruce_leaves[distance=3,persistent=false])
B(-1,17,3,minecraft:spruce_leaves[distance=4,persistent=false])
B(-1,18,3,minecraft:spruce_leaves[distance=3,persistent=false])
B(-1,21,3,minecraft:spruce_leaves[distance=3,persistent=false])
B(-1,22,3,minecraft:spruce_leaves[distance=3,persistent=false])
B(-1,27,3,minecraft:spruce_leaves[distance=3,persistent=false])
B(-1,28,3,minecraft:spruce_leaves[distance=2,persistent=false])
B(-1,32,3,minecraft:spruce_leaves[distance=3,persistent=false])
B(-1,34,3,minecraft:spruce_leaves[distance=7,persistent=true])
B(-1,10,4,minecraft:spruce_leaves[distance=3,persistent=false])
B(-1,16,4,minecraft:spruce_leaves[distance=7,persistent=true])
B(-1,17,4,minecraft:spruce_leaves[distance=5,persistent=false])
B(-1,20,4,minecraft:spruce_leaves[distance=7,persistent=true])
B(-1,21,4,minecraft:spruce_leaves[distance=4,persistent=false])
B(-1,9,5,minecraft:spruce_leaves[distance=7,persistent=true])
B(-1,16,5,minecraft:spruce_leaves[distance=7,persistent=true])
B(-1,19,5,minecraft:spruce_leaves[distance=7,persistent=true])
B(-1,20,5,minecraft:spruce_leaves[distance=7,persistent=true])
B(-1,8,6,minecraft:spruce_leaves[distance=7,persistent=true])
B(-1,9,6,minecraft:spruce_leaves[distance=7,persistent=true])
B(-1,15,6,minecraft:spruce_leaves[distance=7,persistent=true])
B(-1,16,6,minecraft:spruce_leaves[distance=7,persistent=true])
B(-1,19,6,minecraft:spruce_leaves[distance=7,persistent=true])
B(-1,20,6,minecraft:spruce_leaves[distance=7,persistent=true])
B(-1,15,7,minecraft:spruce_leaves[distance=7,persistent=true])
B(0,8,-5,minecraft:spruce_leaves[distance=7,persistent=true])
B(0,9,-5,minecraft:spruce_leaves[distance=7,persistent=true])
B(0,12,-5,minecraft:spruce_leaves[distance=7,persistent=true])
B(0,9,-4,minecraft:spruce_leaves[distance=7,persistent=true])
B(0,17,-4,minecraft:spruce_leaves[distance=7,persistent=true])
B(0,22,-4,minecraft:spruce_leaves[distance=5,persistent=false])
B(0,27,-4,minecraft:spruce_leaves[distance=7,persistent=true])
B(0,28,-4,minecraft:spruce_leaves[distance=7,persistent=true])
B(0,10,-3,minecraft:spruce_leaves[distance=7,persistent=true])
B(0,17,-3,minecraft:spruce_leaves[distance=7,persistent=true])
B(0,22,-3,minecraft:spruce_leaves[distance=4,persistent=false])
B(0,28,-3,minecraft:spruce_leaves[distance=4,persistent=false])
B(0,29,-3,minecraft:spruce_leaves[distance=4,persistent=false])
B(0,11,-2,minecraft:spruce_leaves[distance=4,persistent=false])
B(0,20,-2,minecraft:spruce_leaves[distance=4,persistent=false])
B(0,21,-2,minecraft:spruce_leaves[distance=3,persistent=false])
B(0,22,-2,minecraft:spruce_leaves[distance=3,persistent=false])
B(0,28,-2,minecraft:spruce_leaves[distance=3,persistent=false])
B(0,29,-2,minecraft:spruce_leaves[distance=3,persistent=false])
B(0,30,-2,minecraft:spruce_leaves[distance=3,persistent=false])
B(0,33,-2,minecraft:spruce_leaves[distance=3,persistent=false])
B(0,34,-2,minecraft:spruce_leaves[distance=3,persistent=false])
B(0,-6,-1,minecraft:oak_wood)
B(0,11,-1,minecraft:spruce_leaves[distance=3,persistent=false])
B(0,12,-1,minecraft:spruce_leaves[distance=4,persistent=false])
B(0,13,-1,minecraft:spruce_leaves[distance=5,persistent=false])
B(0,17,-1,minecraft:spruce_leaves[distance=4,persistent=false])
B(0,18,-1,minecraft:spruce_leaves[distance=3,persistent=false])
B(0,21,-1,minecraft:spruce_leaves[distance=2,persistent=false])
B(0,22,-1,minecraft:spruce_leaves[distance=2,persistent=false])
B(0,28,-1,minecraft:spruce_leaves[distance=2,persistent=false])
B(0,29,-1,minecraft:spruce_leaves[distance=2,persistent=false])
B(0,30,-1,minecraft:spruce_leaves[distance=2,persistent=false])
B(0,31,-1,minecraft:spruce_leaves[distance=2,persistent=false])
B(0,33,-1,minecraft:spruce_leaves[distance=2,persistent=false])
B(0,34,-1,minecraft:spruce_leaves[distance=2,persistent=false])
B(0,38,-1,minecraft:spruce_leaves[distance=3,persistent=false])
B(0,42,-1,minecraft:spruce_leaves[distance=2,persistent=false])
B(0,43,-1,minecraft:spruce_leaves[distance=3,persistent=false])
B(0,-6,0,minecraft:oak_wood)
B(0,-5,0,minecraft:oak_wood)
B(0,-2,0,minecraft:oak_wood)
B(0,-1,0,minecraft:oak_wood)
B(0,0,0,minecraft:oak_wood)
B(0,1,0,minecraft:oak_wood)
B(0,2,0,minecraft:oak_wood)
B(0,3,0,minecraft:oak_wood)
B(0,4,0,minecraft:oak_wood)
B(0,5,0,minecraft:oak_wood)
B(0,6,0,minecraft:oak_wood)
B(0,7,0,minecraft:oak_wood)
B(0,8,0,minecraft:spruce_leaves)
B(0,9,0,minecraft:spruce_leaves)
B(0,10,0,minecraft:spruce_leaves)
B(0,11,0,minecraft:spruce_leaves[distance=2,persistent=false])
B(0,12,0,minecraft:spruce_leaves[distance=3,persistent=false])
B(0,13,0,minecraft:spruce_leaves[distance=4,persistent=false])
B(0,14,0,minecraft:spruce_leaves[distance=5,persistent=false])
B(0,15,0,minecraft:spruce_leaves[distance=5,persistent=false])
B(0,16,0,minecraft:spruce_leaves[distance=4,persistent=false])
B(0,17,0,minecraft:spruce_leaves[distance=3,persistent=false])
B(0,18,0,minecraft:spruce_leaves[distance=2,persistent=false])
B(0,19,0,minecraft:spruce_leaves)
B(0,20,0,minecraft:spruce_leaves)
B(0,21,0,minecraft:spruce_leaves)
B(0,22,0,minecraft:spruce_leaves)
B(0,23,0,minecraft:spruce_leaves[distance=2,persistent=false])
B(0,24,0,minecraft:spruce_leaves[distance=3,persistent=false])
B(0,28,0,minecraft:spruce_leaves)
B(0,29,0,minecraft:spruce_leaves)
B(0,33,0,minecraft:spruce_leaves)
B(0,34,0,minecraft:spruce_leaves)
B(0,36,0,minecraft:spruce_leaves)
B(0,37,0,minecraft:spruce_leaves[distance=2,persistent=false])
B(0,41,0,minecraft:spruce_leaves[distance=2,persistent=false])
B(0,42,0,minecraft:spruce_leaves)
B(0,-6,1,minecraft:oak_wood)
B(0,-5,1,minecraft:oak_wood)
B(0,-4,1,minecraft:oak_wood)
B(0,-2,1,minecraft:oak_wood)
B(0,-1,1,minecraft:oak_wood)
B(0,0,1,minecraft:oak_wood)
B(0,1,1,minecraft:oak_wood)
B(0,2,1,minecraft:oak_wood)
B(0,3,1,minecraft:oak_wood)
B(0,4,1,minecraft:oak_wood)
B(0,5,1,minecraft:oak_wood)
B(0,6,1,minecraft:oak_wood)
B(0,7,1,minecraft:oak_wood)
B(0,8,1,minecraft:oak_wood)
B(0,9,1,minecraft:spruce_leaves)
B(0,10,1,minecraft:spruce_leaves)
B(0,11,1,minecraft:spruce_leaves[distance=2,persistent=false])
B(0,12,1,minecraft:spruce_leaves[distance=3,persistent=false])
B(0,13,1,minecraft:spruce_leaves[distance=4,persistent=false])
B(0,14,1,minecraft:spruce_leaves[distance=5,persistent=false])
B(0,15,1,minecraft:spruce_leaves[distance=6,persistent=false])
B(0,16,1,minecraft:spruce_leaves[distance=4,persistent=false])
B(0,19,1,minecraft:spruce_leaves)
B(0,20,1,minecraft:spruce_leaves)
B(0,21,1,minecraft:spruce_leaves[distance=2,persistent=false])
B(0,23,1,minecraft:spruce_leaves[distance=3,persistent=false])
B(0,24,1,minecraft:spruce_leaves[distance=4,persistent=false])
B(0,25,1,minecraft:spruce_leaves[distance=3,persistent=false])
B(0,30,1,minecraft:spruce_leaves[distance=2,persistent=false])
B(0,31,1,minecraft:spruce_leaves[distance=2,persistent=false])
B(0,35,1,minecraft:spruce_leaves[distance=2,persistent=false])
B(0,36,1,minecraft:spruce_leaves[distance=2,persistent=false])
B(0,38,1,minecraft:spruce_leaves[distance=4,persistent=false])
B(0,39,1,minecraft:spruce_leaves[distance=3,persistent=false])
B(0,46,1,minecraft:spruce_leaves[distance=3,persistent=false])
B(0,-5,2,minecraft:oak_wood)
B(0,-4,2,minecraft:oak_wood)
B(0,-3,2,minecraft:oak_wood)
B(0,-1,2,minecraft:oak_wood)
B(0,0,2,minecraft:oak_wood)
B(0,11,2,minecraft:spruce_leaves[distance=3,persistent=false])
B(0,12,2,minecraft:spruce_leaves[distance=4,persistent=false])
B(0,17,2,minecraft:spruce_leaves[distance=4,persistent=false])
B(0,18,2,minecraft:spruce_leaves[distance=3,persistent=false])
B(0,20,2,minecraft:spruce_leaves[distance=2,persistent=false])
B(0,21,2,minecraft:spruce_leaves[distance=3,persistent=false])
B(0,24,2,minecraft:spruce_leaves[distance=5,persistent=false])
B(0,25,2,minecraft:spruce_leaves[distance=4,persistent=false])
B(0,29,2,minecraft:spruce_leaves[distance=2,persistent=false])
B(0,30,2,minecraft:spruce_leaves[distance=3,persistent=false])
B(0,34,2,minecraft:spruce_leaves[distance=7,persistent=true])
B(0,35,2,minecraft:spruce_leaves[distance=3,persistent=false])
B(0,38,2,minecraft:spruce_leaves[distance=7,persistent=true])
B(0,-6,3,minecraft:oak_wood)
B(0,-5,3,minecraft:oak_wood)
B(0,-4,3,minecraft:oak_wood)
B(0,11,3,minecraft:spruce_leaves[distance=4,persistent=false])
B(0,15,3,minecraft:spruce_leaves[distance=7,persistent=true])
B(0,16,3,minecraft:spruce_leaves[distance=7,persistent=true])
B(0,20,3,minecraft:spruce_leaves[distance=3,persistent=false])
B(0,21,3,minecraft:spruce_leaves[distance=4,persistent=false])
B(0,23,3,minecraft:spruce_leaves[distance=7,persistent=true])
B(0,24,3,minecraft:spruce_leaves[distance=6,persistent=false])
B(0,28,3,minecraft:spruce_leaves[distance=3,persistent=false])
B(0,29,3,minecraft:spruce_leaves[distance=3,persistent=false])
B(0,34,3,minecraft:spruce_leaves[distance=7,persistent=true])
B(0,10,4,minecraft:spruce_leaves[distance=7,persistent=true])
B(0,15,4,minecraft:spruce_leaves[distance=7,persistent=true])
B(0,16,4,minecraft:spruce_leaves[distance=7,persistent=true])
B(0,19,4,minecraft:spruce_leaves[distance=7,persistent=true])
B(0,20,4,minecraft:spruce_leaves[distance=4,persistent=false])
B(0,22,4,minecraft:spruce_leaves[distance=7,persistent=true])
B(0,23,4,minecraft:spruce_leaves[distance=7,persistent=true])
B(0,9,5,minecraft:spruce_leaves[distance=7,persistent=true])
B(0,10,5,minecraft:spruce_leaves[distance=7,persistent=true])
B(0,15,5,minecraft:spruce_leaves[distance=7,persistent=true])
B(0,19,5,minecraft:spruce_leaves[distance=7,persistent=true])
B(0,20,5,minecraft:spruce_leaves[distance=7,persistent=true])
B(0,9,6,minecraft:spruce_leaves[distance=7,persistent=true])
B(0,15,6,minecraft:spruce_leaves[distance=7,persistent=true])
B(0,20,6,minecraft:spruce_leaves[distance=7,persistent=true])
B(0,9,7,minecraft:spruce_leaves[distance=7,persistent=true])
B(1,8,-6,minecraft:spruce_leaves[distance=7,persistent=true])
B(1,9,-5,minecraft:spruce_leaves[distance=7,persistent=true])
B(1,9,-4,minecraft:spruce_leaves[distance=7,persistent=true])
B(1,10,-4,minecraft:spruce_leaves[distance=7,persistent=true])
B(1,10,-3,minecraft:spruce_leaves[distance=7,persistent=true])
B(1,15,-3,minecraft:spruce_leaves[distance=7,persistent=true])
B(1,19,-3,minecraft:spruce_leaves[distance=7,persistent=true])
B(1,27,-3,minecraft:spruce_leaves[distance=7,persistent=true])
B(1,10,-2,minecraft:spruce_leaves[distance=6,persistent=false])
B(1,11,-2,minecraft:spruce_leaves[distance=5,persistent=false])
B(1,16,-2,minecraft:spruce_leaves[distance=7,persistent=true])
B(1,20,-2,minecraft:spruce_leaves[distance=5,persistent=false])
B(1,21,-2,minecraft:spruce_leaves[distance=4,persistent=false])
B(1,27,-2,minecraft:spruce_leaves[distance=5,persistent=false])
B(1,28,-2,minecraft:spruce_leaves[distance=4,persistent=false])
B(1,32,-2,minecraft:spruce_leaves[distance=5,persistent=false])
B(1,11,-1,minecraft:spruce_leaves[distance=4,persistent=false])
B(1,12,-1,minecraft:spruce_leaves[distance=5,persistent=false])
B(1,17,-1,minecraft:spruce_leaves[distance=5,persistent=false])
B(1,20,-1,minecraft:spruce_leaves[distance=4,persistent=false])
B(1,21,-1,minecraft:spruce_leaves[distance=3,persistent=false])
B(1,27,-1,minecraft:spruce_leaves[distance=4,persistent=false])
B(1,28,-1,minecraft:spruce_leaves[distance=3,persistent=false])
B(1,32,-1,minecraft:spruce_leaves[distance=4,persistent=false])
B(1,33,-1,minecraft:spruce_leaves[distance=3,persistent=false])
B(1,-7,0,minecraft:oak_wood)
B(1,-4,0,minecraft:oak_wood)
B(1,10,0,minecraft:spruce_leaves[distance=2,persistent=false])
B(1,12,0,minecraft:spruce_leaves[distance=4,persistent=false])
B(1,13,0,minecraft:spruce_leaves[distance=5,persistent=false])
B(1,14,0,minecraft:spruce_leaves[distance=6,persistent=false])
B(1,15,0,minecraft:spruce_leaves[distance=7,persistent=true])
B(1,16,0,minecraft:spruce_leaves[distance=5,persistent=false])
B(1,17,0,minecraft:spruce_leaves[distance=4,persistent=false])
B(1,18,0,minecraft:spruce_leaves[distance=3,persistent=false])
B(1,19,0,minecraft:spruce_leaves[distance=2,persistent=false])
B(1,27,0,minecraft:spruce_leaves[distance=3,persistent=false])
B(1,28,0,minecraft:spruce_leaves[distance=2,persistent=false])
B(1,32,0,minecraft:spruce_leaves[distance=3,persistent=false])
B(1,33,0,minecraft:spruce_leaves[distance=2,persistent=false])
B(1,35,0,minecraft:spruce_leaves[distance=3,persistent=false])
B(1,36,0,minecraft:spruce_leaves[distance=2,persistent=false])
B(1,-4,1,minecraft:oak_wood)
B(1,-3,1,minecraft:oak_wood)
B(1,9,1,minecraft:spruce_leaves[distance=2,persistent=false])
B(1,10,1,minecraft:spruce_leaves[distance=2,persistent=false])
B(1,11,1,minecraft:spruce_leaves[distance=3,persistent=false])
B(1,12,1,minecraft:spruce_leaves[distance=4,persistent=false])
B(1,15,1,minecraft:spruce_leaves[distance=7,persistent=true])
B(1,16,1,minecraft:spruce_leaves[distance=7,persistent=true])
B(1,19,1,minecraft:spruce_leaves[distance=2,persistent=false])
B(1,20,1,minecraft:spruce_leaves[distance=2,persistent=false])
B(1,27,1,minecraft:spruce_leaves[distance=4,persistent=false])
B(1,28,1,minecraft:spruce_leaves[distance=3,persistent=false])
B(1,29,1,minecraft:spruce_leaves[distance=4,persistent=false])
B(1,-5,2,minecraft:oak_wood)
B(1,-3,2,minecraft:oak_wood)
B(1,11,2,minecraft:spruce_leaves[distance=4,persistent=false])
B(1,12,2,minecraft:spruce_leaves[distance=5,persistent=false])
B(1,13,2,minecraft:spruce_leaves[distance=6,persistent=false])
B(1,14,2,minecraft:spruce_leaves[distance=7,persistent=true])
B(1,17,2,minecraft:spruce_leaves[distance=5,persistent=false])
B(1,18,2,minecraft:spruce_leaves[distance=4,persistent=false])
B(1,19,2,minecraft:spruce_leaves[distance=3,persistent=false])
B(1,23,2,minecraft:spruce_leaves[distance=7,persistent=true])
B(1,24,2,minecraft:spruce_leaves[distance=6,persistent=false])
B(1,28,2,minecraft:spruce_leaves[distance=4,persistent=false])
B(1,29,2,minecraft:spruce_leaves[distance=3,persistent=false])
B(1,34,2,minecraft:spruce_leaves[distance=7,persistent=true])
B(1,10,3,minecraft:spruce_leaves[distance=6,persistent=false])
B(1,11,3,minecraft:spruce_leaves[distance=5,persistent=false])
B(1,19,3,minecraft:spruce_leaves[distance=4,persistent=false])
B(1,23,3,minecraft:spruce_leaves[distance=7,persistent=true])
B(1,24,3,minecraft:spruce_leaves[distance=7,persistent=true])
B(1,28,3,minecraft:spruce_leaves[distance=4,persistent=false])
B(1,29,3,minecraft:spruce_leaves[distance=4,persistent=false])
B(1,10,4,minecraft:spruce_leaves[distance=7,persistent=true])
B(1,14,4,minecraft:spruce_leaves[distance=7,persistent=true])
B(1,19,4,minecraft:spruce_leaves[distance=5,persistent=false])
B(1,22,4,minecraft:spruce_leaves[distance=7,persistent=true])
B(1,23,4,minecraft:spruce_leaves[distance=7,persistent=true])
B(1,10,5,minecraft:spruce_leaves[distance=7,persistent=true])
B(1,9,6,minecraft:spruce_leaves[distance=7,persistent=true])
B(1,10,6,minecraft:spruce_leaves[distance=7,persistent=true])
B(1,9,7,minecraft:spruce_leaves[distance=7,persistent=true])
B(1,10,7,minecraft:spruce_leaves[distance=7,persistent=true])
B(1,9,8,minecraft:spruce_leaves[distance=7,persistent=true])
B(2,9,-6,minecraft:spruce_leaves[distance=7,persistent=true])
B(2,9,-5,minecraft:spruce_leaves[distance=7,persistent=true])
B(2,9,-4,minecraft:spruce_leaves[distance=7,persistent=true])
B(2,9,-3,minecraft:spruce_leaves[distance=7,persistent=true])
B(2,15,-3,minecraft:spruce_leaves[distance=7,persistent=true])
B(2,19,-3,minecraft:spruce_leaves[distance=7,persistent=true])
B(2,9,-2,minecraft:spruce_leaves[distance=6,persistent=false])
B(2,10,-2,minecraft:spruce_leaves[distance=7,persistent=true])
B(2,11,-2,minecraft:spruce_leaves[distance=6,persistent=false])
B(2,15,-2,minecraft:spruce_leaves[distance=7,persistent=true])
B(2,16,-2,minecraft:spruce_leaves[distance=7,persistent=true])
B(2,20,-2,minecraft:spruce_leaves[distance=6,persistent=false])
B(2,9,-1,minecraft:spruce_leaves[distance=5,persistent=false])
B(2,11,-1,minecraft:spruce_leaves[distance=5,persistent=false])
B(2,12,-1,minecraft:spruce_leaves[distance=6,persistent=false])
B(2,13,-1,minecraft:spruce_leaves[distance=7,persistent=true])
B(2,16,-1,minecraft:spruce_leaves[distance=7,persistent=true])
B(2,17,-1,minecraft:spruce_leaves[distance=6,persistent=false])
B(2,19,-1,minecraft:spruce_leaves[distance=6,persistent=false])
B(2,20,-1,minecraft:spruce_leaves[distance=5,persistent=false])
B(2,26,-1,minecraft:spruce_leaves[distance=6,persistent=false])
B(2,27,-1,minecraft:spruce_leaves[distance=5,persistent=false])
B(2,32,-1,minecraft:spruce_leaves[distance=5,persistent=false])
B(2,9,0,minecraft:spruce_leaves[distance=4,persistent=false])
B(2,10,0,minecraft:spruce_leaves[distance=3,persistent=false])
B(2,11,0,minecraft:spruce_leaves[distance=4,persistent=false])
B(2,12,0,minecraft:spruce_leaves[distance=5,persistent=false])
B(2,13,0,minecraft:spruce_leaves[distance=6,persistent=false])
B(2,14,0,minecraft:spruce_leaves[distance=7,persistent=true])
B(2,15,0,minecraft:spruce_leaves[distance=7,persistent=true])
B(2,16,0,minecraft:spruce_leaves[distance=6,persistent=false])
B(2,17,0,minecraft:spruce_leaves[distance=5,persistent=false])
B(2,18,0,minecraft:spruce_leaves[distance=4,persistent=false])
B(2,20,0,minecraft:spruce_leaves[distance=6,persistent=false])
B(2,27,0,minecraft:spruce_leaves[distance=4,persistent=false])
B(2,32,0,minecraft:spruce_leaves[distance=4,persistent=false])
B(2,9,1,minecraft:spruce_leaves[distance=3,persistent=false])
B(2,10,1,minecraft:spruce_leaves[distance=3,persistent=false])
B(2,11,1,minecraft:spruce_leaves[distance=4,persistent=false])
B(2,14,1,minecraft:spruce_leaves[distance=7,persistent=true])
B(2,15,1,minecraft:spruce_leaves[distance=7,persistent=true])
B(2,18,1,minecraft:spruce_leaves[distance=4,persistent=false])
B(2,19,1,minecraft:spruce_leaves[distance=3,persistent=false])
B(2,26,1,minecraft:spruce_leaves[distance=6,persistent=false])
B(2,27,1,minecraft:spruce_leaves[distance=5,persistent=false])
B(2,9,2,minecraft:spruce_leaves[distance=4,persistent=false])
B(2,12,2,minecraft:spruce_leaves[distance=6,persistent=false])
B(2,13,2,minecraft:spruce_leaves[distance=7,persistent=true])
B(2,14,2,minecraft:spruce_leaves[distance=7,persistent=true])
B(2,17,2,minecraft:spruce_leaves[distance=6,persistent=false])
B(2,18,2,minecraft:spruce_leaves[distance=5,persistent=false])
B(2,19,2,minecraft:spruce_leaves[distance=4,persistent=false])
B(2,12,3,minecraft:spruce_leaves[distance=7,persistent=true])
B(2,22,3,minecraft:spruce_leaves[distance=7,persistent=true])
B(2,9,4,minecraft:spruce_leaves[distance=7,persistent=true])
B(2,22,4,minecraft:spruce_leaves[distance=7,persistent=true])
B(2,9,5,minecraft:spruce_leaves[distance=7,persistent=true])
B(2,9,6,minecraft:spruce_leaves[distance=7,persistent=true])
B(2,10,6,minecraft:spruce_leaves[distance=7,persistent=true])
B(2,9,7,minecraft:spruce_leaves[distance=7,persistent=true])
B(2,10,7,minecraft:spruce_leaves[distance=7,persistent=true])
B(2,10,8,minecraft:spruce_leaves[distance=7,persistent=true])
B(3,9,-6,minecraft:spruce_leaves[distance=7,persistent=true])
B(3,9,-5,minecraft:spruce_leaves[distance=7,persistent=true])
B(3,8,-4,minecraft:spruce_leaves[distance=7,persistent=true])
B(3,9,-4,minecraft:spruce_leaves[distance=7,persistent=true])
B(3,8,-3,minecraft:spruce_leaves[distance=7,persistent=true])
B(3,9,-3,minecraft:spruce_leaves[distance=7,persistent=true])
B(3,15,-3,minecraft:spruce_leaves[distance=7,persistent=true])
B(3,19,-3,minecraft:spruce_leaves[distance=7,persistent=true])
B(3,9,-2,minecraft:spruce_leaves[distance=7,persistent=true])
B(3,10,-2,minecraft:spruce_leaves[distance=7,persistent=true])
B(3,15,-2,minecraft:spruce_leaves[distance=7,persistent=true])
B(3,16,-2,minecraft:spruce_leaves[distance=7,persistent=true])
B(3,19,-2,minecraft:spruce_leaves[distance=7,persistent=true])
B(3,8,-1,minecraft:spruce_leaves[distance=7,persistent=true])
B(3,11,-1,minecraft:spruce_leaves[distance=6,persistent=false])
B(3,12,-1,minecraft:spruce_leaves[distance=7,persistent=true])
B(3,15,-1,minecraft:spruce_leaves[distance=7,persistent=true])
B(3,16,-1,minecraft:spruce_leaves[distance=7,persistent=true])
B(3,19,-1,minecraft:spruce_leaves[distance=7,persistent=true])
B(3,26,-1,minecraft:spruce_leaves[distance=7,persistent=true])
B(3,8,0,minecraft:spruce_leaves[distance=6,persistent=false])
B(3,9,0,minecraft:spruce_leaves[distance=5,persistent=false])
B(3,10,0,minecraft:spruce_leaves[distance=4,persistent=false])
B(3,11,0,minecraft:spruce_leaves[distance=5,persistent=false])
B(3,12,0,minecraft:spruce_leaves[distance=6,persistent=false])
B(3,13,0,minecraft:spruce_leaves[distance=7,persistent=true])
B(3,14,0,minecraft:spruce_leaves[distance=7,persistent=true])
B(3,15,0,minecraft:spruce_leaves[distance=7,persistent=true])
B(3,17,0,minecraft:spruce_leaves[distance=6,persistent=false])
B(3,26,0,minecraft:spruce_leaves[distance=7,persistent=true])
B(3,8,1,minecraft:spruce_leaves[distance=5,persistent=false])
B(3,9,1,minecraft:spruce_leaves[distance=4,persistent=false])
B(3,10,1,minecraft:spruce_leaves[distance=4,persistent=false])
B(3,14,1,minecraft:spruce_leaves[distance=7,persistent=true])
B(3,15,1,minecraft:spruce_leaves[distance=7,persistent=true])
B(3,17,1,minecraft:spruce_leaves[distance=7,persistent=true])
B(3,18,1,minecraft:spruce_leaves[distance=5,persistent=false])
B(3,26,1,minecraft:spruce_leaves[distance=7,persistent=true])
B(3,8,2,minecraft:spruce_leaves[distance=7,persistent=true])
B(3,12,2,minecraft:spruce_leaves[distance=7,persistent=true])
B(3,13,2,minecraft:spruce_leaves[distance=7,persistent=true])
B(3,14,2,minecraft:spruce_leaves[distance=7,persistent=true])
B(3,17,2,minecraft:spruce_leaves[distance=7,persistent=true])
B(3,18,2,minecraft:spruce_leaves[distance=6,persistent=false])
B(3,17,3,minecraft:spruce_leaves[distance=7,persistent=true])
B(3,9,4,minecraft:spruce_leaves[distance=7,persistent=true])
B(3,8,5,minecraft:spruce_leaves[distance=7,persistent=true])
B(3,9,5,minecraft:spruce_leaves[distance=7,persistent=true])
B(3,9,6,minecraft:spruce_leaves[distance=7,persistent=true])
B(4,7,-2,minecraft:spruce_leaves[distance=7,persistent=true])
B(4,9,-2,minecraft:spruce_leaves[distance=7,persistent=true])
B(4,10,-2,minecraft:spruce_leaves[distance=7,persistent=true])
B(4,15,-2,minecraft:spruce_leaves[distance=7,persistent=true])
B(4,7,-1,minecraft:spruce_leaves[distance=7,persistent=true])
B(4,8,-1,minecraft:spruce_leaves[distance=7,persistent=true])
B(4,11,-1,minecraft:spruce_leaves[distance=7,persistent=true])
B(4,12,-1,minecraft:spruce_leaves[distance=7,persistent=true])
B(4,15,-1,minecraft:spruce_leaves[distance=7,persistent=true])
B(4,8,0,minecraft:spruce_leaves[distance=7,persistent=true])
B(4,9,0,minecraft:spruce_leaves[distance=6,persistent=false])
B(4,10,0,minecraft:spruce_leaves[distance=5,persistent=false])
B(4,11,0,minecraft:spruce_leaves[distance=6,persistent=false])
B(4,12,0,minecraft:spruce_leaves[distance=7,persistent=true])
B(4,13,0,minecraft:spruce_leaves[distance=7,persistent=true])
B(4,8,1,minecraft:spruce_leaves[distance=7,persistent=true])
B(4,9,1,minecraft:spruce_leaves[distance=5,persistent=false])
B(4,13,1,minecraft:spruce_leaves[distance=7,persistent=true])
B(4,14,1,minecraft:spruce_leaves[distance=7,persistent=true])
B(4,17,1,minecraft:spruce_leaves[distance=7,persistent=true])
B(4,7,2,minecraft:spruce_leaves[distance=7,persistent=true])
B(4,8,2,minecraft:spruce_leaves[distance=7,persistent=true])
B(4,12,2,minecraft:spruce_leaves[distance=7,persistent=true])
B(4,13,2,minecraft:spruce_leaves[distance=7,persistent=true])
B(4,14,2,minecraft:spruce_leaves[distance=7,persistent=true])
B(4,17,2,minecraft:spruce_leaves[distance=7,persistent=true])
B(4,18,2,minecraft:spruce_leaves[distance=7,persistent=true])
B(4,7,3,minecraft:spruce_leaves[distance=7,persistent=true])
B(5,9,-2,minecraft:spruce_leaves[distance=7,persistent=true])
B(5,10,-2,minecraft:spruce_leaves[distance=7,persistent=true])
B(5,7,-1,minecraft:spruce_leaves[distance=7,persistent=true])
B(5,10,-1,minecraft:spruce_leaves[distance=7,persistent=true])
B(5,11,-1,minecraft:spruce_leaves[distance=7,persistent=true])
B(5,8,0,minecraft:spruce_leaves[distance=7,persistent=true])
B(5,9,0,minecraft:spruce_leaves[distance=7,persistent=true])
B(5,10,0,minecraft:spruce_leaves[distance=6,persistent=false])
B(5,12,0,minecraft:spruce_leaves[distance=7,persistent=true])
B(5,8,1,minecraft:spruce_leaves[distance=7,persistent=true])
B(5,12,1,minecraft:spruce_leaves[distance=7,persistent=true])
B(5,13,1,minecraft:spruce_leaves[distance=7,persistent=true])
B(5,7,2,minecraft:spruce_leaves[distance=7,persistent=true])
B(5,12,2,minecraft:spruce_leaves[distance=7,persistent=true])
B(5,13,2,minecraft:spruce_leaves[distance=7,persistent=true])
B(5,14,2,minecraft:spruce_leaves[distance=7,persistent=true])
B(5,7,3,minecraft:spruce_leaves[distance=7,persistent=true])
B(6,10,-2,minecraft:spruce_leaves[distance=7,persistent=true])
B(6,7,-1,minecraft:spruce_leaves[distance=7,persistent=true])
B(6,10,-1,minecraft:spruce_leaves[distance=7,persistent=true])
B(6,11,-1,minecraft:spruce_leaves[distance=7,persistent=true])
B(6,7,0,minecraft:spruce_leaves[distance=7,persistent=true])
B(6,8,0,minecraft:spruce_leaves[distance=7,persistent=true])
B(6,8,1,minecraft:spruce_leaves[distance=7,persistent=true])
B(6,12,1,minecraft:spruce_leaves[distance=7,persistent=true])
B(6,13,1,minecraft:spruce_leaves[distance=7,persistent=true])
B(6,7,2,minecraft:spruce_leaves[distance=7,persistent=true])
B(6,13,2,minecraft:spruce_leaves[distance=7,persistent=true])
B(7,10,-1,minecraft:spruce_leaves[distance=7,persistent=true])
B(7,7,0,minecraft:spruce_leaves[distance=7,persistent=true])
B(7,8,0,minecraft:spruce_leaves[distance=7,persistent=true])
B(7,8,1,minecraft:spruce_leaves[distance=7,persistent=true])
B(7,7,2,minecraft:spruce_leaves[distance=7,persistent=true])
B(8,8,1,minecraft:spruce_leaves[distance=7,persistent=true])

#######################################################################
# +-----------------------------------------------------------------+ #
# |                            BO3 checks                           | #
# +-----------------------------------------------------------------+ #
#######################################################################

BlockCheck(0,-1,0,otg:dirt,minecraft:grass_block)
BlockCheck(0,-2,0,Solid)

#######################################################################
# +-----------------------------------------------------------------+ #
# |                             Branches                            | #
# +-----------------------------------------------------------------+ #
#######################################################################


#######################################################################
# +-----------------------------------------------------------------+ #
# |                             Entities                            | #
# +-----------------------------------------------------------------+ #
#######################################################################

