
#######################################################################
# +-----------------------------------------------------------------+ #
# |                            BO3 object                           | #
# +-----------------------------------------------------------------+ #
#######################################################################

Author: NLBlackEagle

Description: Converted version of the BO2 66

Version: 3

SettingsMode: WriteWithoutComments


#######################################################################
# +-----------------------------------------------------------------+ #
# |                          Main settings                          | #
# +-----------------------------------------------------------------+ #
#######################################################################

Tree: true

Frequency: 1

Rarity: 60.0

RotateRandomly: true

SpawnHeight: highestSolidBlock

SpawnHeightOffset: 0

SpawnHeightVariance: 0

##############################
# Height Limits for the BO3. #
##############################

MinHeight: 0

MaxHeight: 199

######################
# Extrusion settings #
######################

ExtrudeMode: None

ExtrudeThroughBlocks: otg:air

MaxBranchDepth: 10


#######################################################################
# +-----------------------------------------------------------------+ #
# |                      Source block settings                      | #
# +-----------------------------------------------------------------+ #
#######################################################################

SourceBlocks: otg:air,otg:dirt,minecraft:sand,minecraft:grass_block

MaxPercentageOutsideSourceBlock: 0

OutsideSourceBlock: placeAnyway

DoReplaceBlocks: true

IsOTGPlus: false


#######################################################################
# +-----------------------------------------------------------------+ #
# |                              Blocks                             | #
# +-----------------------------------------------------------------+ #
#######################################################################

B(-20,27,-14,minecraft:oak_leaves[distance=7,persistent=true])
B(-20,25,-11,minecraft:oak_wood)
B(-19,24,-14,minecraft:oak_leaves[distance=7,persistent=true])
B(-19,25,-14,minecraft:oak_leaves[distance=6,persistent=false])
B(-19,26,-14,minecraft:oak_leaves[distance=7,persistent=true])
B(-19,27,-14,minecraft:oak_leaves[distance=7,persistent=true])
B(-19,25,-13,minecraft:oak_leaves[distance=5,persistent=false])
B(-19,26,-13,minecraft:oak_leaves[distance=6,persistent=false])
B(-19,27,-13,minecraft:oak_leaves[distance=7,persistent=true])
B(-19,28,-13,minecraft:oak_leaves[distance=7,persistent=true])
B(-19,25,-11,minecraft:oak_wood)
B(-19,23,-9,minecraft:oak_leaves[distance=7,persistent=true])
B(-19,23,-8,minecraft:oak_leaves[distance=7,persistent=true])
B(-19,24,-7,minecraft:oak_leaves[distance=7,persistent=true])
B(-18,23,-16,minecraft:oak_leaves[distance=7,persistent=true])
B(-18,23,-13,minecraft:oak_leaves[distance=4,persistent=false])
B(-18,24,-13,minecraft:oak_leaves[distance=3,persistent=false])
B(-18,25,-13,minecraft:oak_leaves[distance=4,persistent=false])
B(-18,26,-13,minecraft:oak_leaves[distance=5,persistent=false])
B(-18,27,-13,minecraft:oak_leaves[distance=6,persistent=false])
B(-18,28,-13,minecraft:oak_leaves[distance=7,persistent=true])
B(-18,27,-12,minecraft:oak_leaves[distance=5,persistent=false])
B(-18,24,-11,minecraft:oak_wood)
B(-18,27,-11,minecraft:oak_leaves[distance=6,persistent=false])
B(-18,30,-11,minecraft:oak_leaves[distance=7,persistent=true])
B(-18,26,-10,minecraft:oak_leaves[distance=6,persistent=false])
B(-18,27,-10,minecraft:oak_leaves[distance=7,persistent=true])
B(-18,30,-10,minecraft:oak_leaves[distance=7,persistent=true])
B(-18,23,-8,minecraft:oak_leaves[distance=7,persistent=true])
B(-18,23,-7,minecraft:oak_leaves[distance=7,persistent=true])
B(-18,24,-7,minecraft:oak_leaves[distance=7,persistent=true])
B(-18,24,-6,minecraft:oak_leaves[distance=7,persistent=true])
B(-18,24,-5,minecraft:oak_leaves[distance=7,persistent=true])
B(-18,25,-5,minecraft:oak_leaves[distance=7,persistent=true])
B(-18,24,-4,minecraft:oak_leaves[distance=7,persistent=true])
B(-18,24,-3,minecraft:oak_leaves[distance=7,persistent=true])
B(-18,25,-3,minecraft:oak_leaves[distance=7,persistent=true])
B(-18,26,3,minecraft:oak_leaves[distance=7,persistent=true])
B(-18,26,4,minecraft:oak_leaves[distance=7,persistent=true])
B(-18,26,5,minecraft:oak_leaves[distance=7,persistent=true])
B(-18,26,6,minecraft:oak_leaves[distance=7,persistent=true])
B(-18,25,7,minecraft:oak_leaves[distance=7,persistent=true])
B(-18,26,7,minecraft:oak_leaves[distance=7,persistent=true])
B(-17,24,-17,minecraft:oak_leaves[distance=7,persistent=true])
B(-17,23,-16,minecraft:oak_leaves[distance=7,persistent=true])
B(-17,24,-16,minecraft:oak_leaves[distance=7,persistent=true])
B(-17,25,-16,minecraft:oak_leaves[distance=7,persistent=true])
B(-17,22,-15,minecraft:oak_leaves[distance=7,persistent=true])
B(-17,23,-15,minecraft:oak_leaves[distance=7,persistent=true])
B(-17,24,-15,minecraft:oak_leaves[distance=6,persistent=false])
B(-17,25,-15,minecraft:oak_leaves[distance=7,persistent=true])
B(-17,26,-15,minecraft:oak_leaves[distance=6,persistent=false])
B(-17,21,-14,minecraft:oak_leaves[distance=5,persistent=false])
B(-17,22,-14,minecraft:oak_leaves[distance=6,persistent=false])
B(-17,26,-14,minecraft:oak_leaves[distance=5,persistent=false])
B(-17,27,-14,minecraft:oak_leaves[distance=6,persistent=false])
B(-17,21,-13,minecraft:oak_leaves[distance=4,persistent=false])
B(-17,24,-13,minecraft:oak_leaves[distance=2,persistent=false])
B(-17,26,-13,minecraft:oak_leaves[distance=4,persistent=false])
B(-17,27,-13,minecraft:oak_leaves[distance=5,persistent=false])
B(-17,20,-12,minecraft:oak_leaves[distance=4,persistent=false])
B(-17,24,-12,minecraft:oak_leaves)
B(-17,25,-12,minecraft:oak_leaves[distance=2,persistent=false])
B(-17,26,-12,minecraft:oak_leaves[distance=3,persistent=false])
B(-17,27,-12,minecraft:oak_leaves[distance=4,persistent=false])
B(-17,28,-12,minecraft:oak_leaves[distance=5,persistent=false])
B(-17,29,-12,minecraft:oak_leaves[distance=6,persistent=false])
B(-17,30,-12,minecraft:oak_leaves[distance=7,persistent=true])
B(-17,23,-11,minecraft:oak_wood)
B(-17,24,-11,minecraft:oak_wood)
B(-17,26,-11,minecraft:oak_leaves[distance=4,persistent=false])
B(-17,28,-11,minecraft:oak_leaves[distance=6,persistent=false])
B(-17,29,-11,minecraft:oak_leaves[distance=7,persistent=true])
B(-17,21,-10,minecraft:oak_leaves[distance=2,persistent=false])
B(-17,25,-10,minecraft:oak_leaves[distance=6,persistent=false])
B(-17,26,-10,minecraft:oak_leaves[distance=5,persistent=false])
B(-17,28,-10,minecraft:oak_leaves[distance=7,persistent=true])
B(-17,29,-10,minecraft:oak_leaves[distance=7,persistent=true])
B(-17,22,-9,minecraft:oak_leaves[distance=4,persistent=false])
B(-17,25,-9,minecraft:oak_leaves[distance=7,persistent=true])
B(-17,28,-9,minecraft:oak_leaves[distance=7,persistent=true])
B(-17,29,-9,minecraft:oak_leaves[distance=7,persistent=true])
B(-17,22,-8,minecraft:oak_leaves[distance=5,persistent=false])
B(-17,23,-8,minecraft:oak_leaves[distance=6,persistent=false])
B(-17,24,-8,minecraft:oak_leaves[distance=7,persistent=true])
B(-17,25,-8,minecraft:oak_leaves[distance=7,persistent=true])
B(-17,28,-8,minecraft:oak_leaves[distance=7,persistent=true])
B(-17,29,-8,minecraft:oak_leaves[distance=7,persistent=true])
B(-17,23,-7,minecraft:oak_leaves[distance=7,persistent=true])
B(-17,28,-7,minecraft:oak_leaves[distance=7,persistent=true])
B(-17,29,-7,minecraft:oak_leaves[distance=7,persistent=true])
B(-17,24,-6,minecraft:oak_leaves[distance=7,persistent=true])
B(-17,28,-6,minecraft:oak_leaves[distance=7,persistent=true])
B(-17,29,-6,minecraft:oak_leaves[distance=7,persistent=true])
B(-17,24,-5,minecraft:oak_leaves[distance=7,persistent=true])
B(-17,23,-4,minecraft:oak_leaves[distance=7,persistent=true])
B(-17,24,-4,minecraft:oak_leaves[distance=7,persistent=true])
B(-17,27,-4,minecraft:oak_leaves[distance=7,persistent=true])
B(-17,28,-4,minecraft:oak_leaves[distance=7,persistent=true])
B(-17,23,-3,minecraft:oak_leaves[distance=7,persistent=true])
B(-17,24,-3,minecraft:oak_leaves[distance=7,persistent=true])
B(-17,25,-3,minecraft:oak_leaves[distance=7,persistent=true])
B(-17,27,-3,minecraft:oak_leaves[distance=7,persistent=true])
B(-17,23,-2,minecraft:oak_leaves[distance=7,persistent=true])
B(-17,27,-2,minecraft:oak_leaves[distance=7,persistent=true])
B(-17,27,-1,minecraft:oak_leaves[distance=7,persistent=true])
B(-17,25,2,minecraft:oak_leaves[distance=7,persistent=true])
B(-17,26,2,minecraft:oak_leaves[distance=7,persistent=true])
B(-17,25,3,minecraft:oak_leaves[distance=7,persistent=true])
B(-17,26,3,minecraft:oak_leaves[distance=7,persistent=true])
B(-17,25,4,minecraft:oak_leaves[distance=7,persistent=true])
B(-17,25,5,minecraft:oak_leaves[distance=7,persistent=true])
B(-17,25,6,minecraft:oak_leaves[distance=7,persistent=true])
B(-17,25,7,minecraft:oak_leaves[distance=7,persistent=true])
B(-17,22,8,minecraft:oak_leaves[distance=7,persistent=true])
B(-17,23,8,minecraft:oak_leaves[distance=7,persistent=true])
B(-17,25,8,minecraft:oak_leaves[distance=7,persistent=true])
B(-17,26,9,minecraft:oak_leaves[distance=7,persistent=true])
B(-16,24,-17,minecraft:oak_leaves[distance=7,persistent=true])
B(-16,22,-16,minecraft:oak_leaves[distance=7,persistent=true])
B(-16,23,-16,minecraft:oak_leaves[distance=7,persistent=true])
B(-16,24,-16,minecraft:oak_leaves[distance=6,persistent=false])
B(-16,22,-15,minecraft:oak_leaves[distance=6,persistent=false])
B(-16,23,-15,minecraft:oak_leaves[distance=6,persistent=false])
B(-16,24,-15,minecraft:oak_leaves[distance=5,persistent=false])
B(-16,22,-14,minecraft:oak_leaves[distance=5,persistent=false])
B(-16,23,-14,minecraft:oak_leaves[distance=5,persistent=false])
B(-16,24,-14,minecraft:oak_leaves[distance=4,persistent=false])
B(-16,25,-14,minecraft:oak_leaves[distance=5,persistent=false])
B(-16,21,-13,minecraft:oak_leaves[distance=3,persistent=false])
B(-16,24,-13,minecraft:oak_leaves[distance=3,persistent=false])
B(-16,25,-13,minecraft:oak_leaves[distance=4,persistent=false])
B(-16,26,-13,minecraft:oak_leaves[distance=5,persistent=false])
B(-16,27,-13,minecraft:oak_leaves[distance=6,persistent=false])
B(-16,28,-13,minecraft:oak_leaves[distance=7,persistent=true])
B(-16,30,-13,minecraft:oak_leaves[distance=7,persistent=true])
B(-16,20,-12,minecraft:oak_leaves[distance=3,persistent=false])
B(-16,24,-12,minecraft:oak_leaves[distance=2,persistent=false])
B(-16,25,-12,minecraft:oak_leaves[distance=3,persistent=false])
B(-16,26,-12,minecraft:oak_leaves[distance=4,persistent=false])
B(-16,27,-12,minecraft:oak_leaves[distance=5,persistent=false])
B(-16,28,-12,minecraft:oak_leaves[distance=6,persistent=false])
B(-16,29,-12,minecraft:oak_leaves[distance=7,persistent=true])
B(-16,20,-11,minecraft:oak_leaves[distance=2,persistent=false])
B(-16,22,-11,minecraft:oak_wood)
B(-16,23,-11,minecraft:oak_wood)
B(-16,25,-11,minecraft:oak_leaves[distance=4,persistent=false])
B(-16,26,-11,minecraft:oak_leaves[distance=5,persistent=false])
B(-16,27,-11,minecraft:oak_leaves[distance=6,persistent=false])
B(-16,28,-11,minecraft:oak_leaves[distance=7,persistent=true])
B(-16,21,-10,minecraft:oak_leaves)
B(-16,24,-10,minecraft:oak_leaves[distance=4,persistent=false])
B(-16,25,-10,minecraft:oak_leaves[distance=5,persistent=false])
B(-16,27,-10,minecraft:oak_leaves[distance=7,persistent=true])
B(-16,28,-10,minecraft:oak_leaves[distance=7,persistent=true])
B(-16,21,-9,minecraft:oak_leaves[distance=2,persistent=false])
B(-16,22,-9,minecraft:oak_leaves[distance=3,persistent=false])
B(-16,24,-9,minecraft:oak_leaves[distance=5,persistent=false])
B(-16,27,-9,minecraft:oak_leaves[distance=7,persistent=true])
B(-16,28,-9,minecraft:oak_leaves[distance=7,persistent=true])
B(-16,22,-8,minecraft:oak_leaves[distance=4,persistent=false])
B(-16,23,-8,minecraft:oak_leaves[distance=5,persistent=false])
B(-16,24,-8,minecraft:oak_leaves[distance=6,persistent=false])
B(-16,27,-8,minecraft:oak_leaves[distance=7,persistent=true])
B(-16,28,-8,minecraft:oak_leaves[distance=7,persistent=true])
B(-16,22,-7,minecraft:oak_leaves[distance=5,persistent=false])
B(-16,23,-7,minecraft:oak_leaves[distance=6,persistent=false])
B(-16,27,-7,minecraft:oak_leaves[distance=7,persistent=true])
B(-16,28,-7,minecraft:oak_leaves[distance=7,persistent=true])
B(-16,23,-6,minecraft:oak_leaves[distance=7,persistent=true])
B(-16,24,-6,minecraft:oak_leaves[distance=7,persistent=true])
B(-16,25,-6,minecraft:oak_leaves[distance=7,persistent=true])
B(-16,26,-6,minecraft:oak_leaves[distance=7,persistent=true])
B(-16,27,-6,minecraft:oak_leaves[distance=7,persistent=true])
B(-16,28,-6,minecraft:oak_leaves[distance=7,persistent=true])
B(-16,23,-5,minecraft:oak_leaves[distance=7,persistent=true])
B(-16,27,-5,minecraft:oak_leaves[distance=7,persistent=true])
B(-16,28,-5,minecraft:oak_leaves[distance=7,persistent=true])
B(-16,23,-4,minecraft:oak_leaves[distance=7,persistent=true])
B(-16,24,-4,minecraft:oak_leaves[distance=7,persistent=true])
B(-16,27,-4,minecraft:oak_leaves[distance=7,persistent=true])
B(-16,22,-3,minecraft:oak_leaves[distance=7,persistent=true])
B(-16,23,-3,minecraft:oak_leaves[distance=7,persistent=true])
B(-16,24,-3,minecraft:oak_leaves[distance=7,persistent=true])
B(-16,25,-3,minecraft:oak_leaves[distance=7,persistent=true])
B(-16,26,-3,minecraft:oak_leaves[distance=7,persistent=true])
B(-16,27,-3,minecraft:oak_leaves[distance=7,persistent=true])
B(-16,22,-2,minecraft:oak_leaves[distance=7,persistent=true])
B(-16,23,-2,minecraft:oak_leaves[distance=7,persistent=true])
B(-16,25,-2,minecraft:oak_leaves[distance=7,persistent=true])
B(-16,26,-2,minecraft:oak_leaves[distance=7,persistent=true])
B(-16,27,-2,minecraft:oak_leaves[distance=7,persistent=true])
B(-16,27,-1,minecraft:oak_leaves[distance=6,persistent=false])
B(-16,25,0,minecraft:oak_leaves[distance=7,persistent=true])
B(-16,27,0,minecraft:oak_leaves[distance=5,persistent=false])
B(-16,25,1,minecraft:oak_leaves[distance=7,persistent=true])
B(-16,28,1,minecraft:oak_leaves[distance=7,persistent=true])
B(-16,25,2,minecraft:oak_leaves[distance=7,persistent=true])
B(-16,25,3,minecraft:oak_leaves[distance=7,persistent=true])
B(-16,25,4,minecraft:oak_leaves[distance=7,persistent=true])
B(-16,25,5,minecraft:oak_leaves[distance=7,persistent=true])
B(-16,25,6,minecraft:oak_leaves[distance=7,persistent=true])
B(-16,21,7,minecraft:oak_leaves[distance=7,persistent=true])
B(-16,22,7,minecraft:oak_leaves[distance=7,persistent=true])
B(-16,23,7,minecraft:oak_leaves[distance=7,persistent=true])
B(-16,24,7,minecraft:oak_leaves[distance=7,persistent=true])
B(-16,25,7,minecraft:oak_leaves[distance=7,persistent=true])
B(-16,25,8,minecraft:oak_leaves[distance=7,persistent=true])
B(-16,26,9,minecraft:oak_leaves[distance=7,persistent=true])
B(-15,25,-19,minecraft:oak_leaves[distance=7,persistent=true])
B(-15,24,-17,minecraft:oak_leaves[distance=7,persistent=true])
B(-15,23,-16,minecraft:oak_leaves[distance=6,persistent=false])
B(-15,24,-16,minecraft:oak_leaves[distance=7,persistent=true])
B(-15,21,-15,minecraft:oak_leaves[distance=4,persistent=false])
B(-15,22,-15,minecraft:oak_leaves[distance=5,persistent=false])
B(-15,23,-15,minecraft:oak_leaves[distance=5,persistent=false])
B(-15,21,-14,minecraft:oak_leaves[distance=3,persistent=false])
B(-15,22,-14,minecraft:oak_leaves[distance=4,persistent=false])
B(-15,23,-14,minecraft:oak_leaves[distance=4,persistent=false])
B(-15,21,-13,minecraft:oak_leaves[distance=2,persistent=false])
B(-15,22,-13,minecraft:oak_leaves[distance=3,persistent=false])
B(-15,23,-13,minecraft:oak_leaves[distance=3,persistent=false])
B(-15,24,-13,minecraft:oak_leaves[distance=4,persistent=false])
B(-15,26,-13,minecraft:oak_leaves[distance=6,persistent=false])
B(-15,27,-13,minecraft:oak_leaves[distance=7,persistent=true])
B(-15,28,-13,minecraft:oak_leaves[distance=7,persistent=true])
B(-15,29,-13,minecraft:oak_leaves[distance=7,persistent=true])
B(-15,30,-13,minecraft:oak_leaves[distance=7,persistent=true])
B(-15,20,-12,minecraft:oak_leaves[distance=2,persistent=false])
B(-15,21,-12,minecraft:oak_leaves)
B(-15,23,-12,minecraft:oak_leaves[distance=2,persistent=false])
B(-15,24,-12,minecraft:oak_leaves[distance=3,persistent=false])
B(-15,25,-12,minecraft:oak_leaves[distance=4,persistent=false])
B(-15,26,-12,minecraft:oak_leaves[distance=5,persistent=false])
B(-15,27,-12,minecraft:oak_leaves[distance=6,persistent=false])
B(-15,28,-12,minecraft:oak_leaves[distance=7,persistent=true])
B(-15,20,-11,minecraft:oak_leaves)
B(-15,21,-11,minecraft:oak_wood)
B(-15,22,-11,minecraft:oak_wood)
B(-15,23,-11,minecraft:oak_leaves)
B(-15,24,-11,minecraft:oak_leaves[distance=2,persistent=false])
B(-15,25,-11,minecraft:oak_leaves[distance=3,persistent=false])
B(-15,26,-11,minecraft:oak_leaves[distance=4,persistent=false])
B(-15,27,-11,minecraft:oak_leaves[distance=5,persistent=false])
B(-15,20,-10,minecraft:oak_leaves)
B(-15,21,-10,minecraft:oak_wood)
B(-15,23,-10,minecraft:oak_leaves[distance=2,persistent=false])
B(-15,24,-10,minecraft:oak_leaves[distance=3,persistent=false])
B(-15,25,-10,minecraft:oak_leaves[distance=4,persistent=false])
B(-15,26,-10,minecraft:oak_leaves[distance=5,persistent=false])
B(-15,21,-9,minecraft:oak_leaves)
B(-15,23,-9,minecraft:oak_leaves[distance=3,persistent=false])
B(-15,25,-9,minecraft:oak_leaves[distance=5,persistent=false])
B(-15,26,-9,minecraft:oak_leaves[distance=6,persistent=false])
B(-15,19,-8,minecraft:oak_leaves[distance=5,persistent=false])
B(-15,21,-8,minecraft:oak_leaves[distance=2,persistent=false])
B(-15,22,-8,minecraft:oak_leaves[distance=3,persistent=false])
B(-15,23,-8,minecraft:oak_leaves[distance=4,persistent=false])
B(-15,25,-8,minecraft:oak_leaves[distance=6,persistent=false])
B(-15,26,-8,minecraft:oak_leaves[distance=7,persistent=true])
B(-15,19,-7,minecraft:oak_leaves[distance=6,persistent=false])
B(-15,21,-7,minecraft:oak_leaves[distance=3,persistent=false])
B(-15,22,-7,minecraft:oak_leaves[distance=4,persistent=false])
B(-15,23,-7,minecraft:oak_leaves[distance=5,persistent=false])
B(-15,25,-7,minecraft:oak_leaves[distance=7,persistent=true])
B(-15,26,-7,minecraft:oak_leaves[distance=7,persistent=true])
B(-15,22,-6,minecraft:oak_leaves[distance=5,persistent=false])
B(-15,23,-6,minecraft:oak_leaves[distance=6,persistent=false])
B(-15,24,-6,minecraft:oak_leaves[distance=7,persistent=true])
B(-15,25,-6,minecraft:oak_leaves[distance=7,persistent=true])
B(-15,26,-6,minecraft:oak_leaves[distance=7,persistent=true])
B(-15,28,-6,minecraft:oak_leaves[distance=7,persistent=true])
B(-15,22,-5,minecraft:oak_leaves[distance=6,persistent=false])
B(-15,23,-5,minecraft:oak_leaves[distance=7,persistent=true])
B(-15,25,-5,minecraft:oak_leaves[distance=7,persistent=true])
B(-15,26,-5,minecraft:oak_leaves[distance=7,persistent=true])
B(-15,27,-5,minecraft:oak_leaves[distance=7,persistent=true])
B(-15,22,-4,minecraft:oak_leaves[distance=7,persistent=true])
B(-15,23,-4,minecraft:oak_leaves[distance=7,persistent=true])
B(-15,24,-4,minecraft:oak_leaves[distance=7,persistent=true])
B(-15,25,-4,minecraft:oak_leaves[distance=7,persistent=true])
B(-15,26,-4,minecraft:oak_leaves[distance=7,persistent=true])
B(-15,27,-4,minecraft:oak_leaves[distance=7,persistent=true])
B(-15,22,-3,minecraft:oak_leaves[distance=7,persistent=true])
B(-15,24,-3,minecraft:oak_leaves[distance=7,persistent=true])
B(-15,26,-3,minecraft:oak_leaves[distance=7,persistent=true])
B(-15,21,-2,minecraft:oak_leaves[distance=7,persistent=true])
B(-15,22,-2,minecraft:oak_leaves[distance=7,persistent=true])
B(-15,23,-2,minecraft:oak_leaves[distance=7,persistent=true])
B(-15,24,-2,minecraft:oak_leaves[distance=7,persistent=true])
B(-15,25,-2,minecraft:oak_leaves[distance=7,persistent=true])
B(-15,26,-2,minecraft:oak_leaves[distance=7,persistent=true])
B(-15,26,-1,minecraft:oak_leaves[distance=6,persistent=false])
B(-15,27,-1,minecraft:oak_leaves[distance=5,persistent=false])
B(-15,25,0,minecraft:oak_leaves[distance=7,persistent=true])
B(-15,27,0,minecraft:oak_leaves[distance=4,persistent=false])
B(-15,25,1,minecraft:oak_leaves[distance=7,persistent=true])
B(-15,27,1,minecraft:oak_leaves[distance=3,persistent=false])
B(-15,25,2,minecraft:oak_leaves[distance=7,persistent=true])
B(-15,27,2,minecraft:oak_leaves[distance=2,persistent=false])
B(-15,24,3,minecraft:oak_leaves[distance=7,persistent=true])
B(-15,25,3,minecraft:oak_leaves[distance=7,persistent=true])
B(-15,24,4,minecraft:oak_leaves[distance=7,persistent=true])
B(-15,25,4,minecraft:oak_leaves[distance=7,persistent=true])
B(-15,24,5,minecraft:oak_leaves[distance=7,persistent=true])
B(-15,20,6,minecraft:oak_leaves[distance=7,persistent=true])
B(-15,21,6,minecraft:oak_leaves[distance=7,persistent=true])
B(-15,22,6,minecraft:oak_leaves[distance=7,persistent=true])
B(-15,23,6,minecraft:oak_leaves[distance=7,persistent=true])
B(-15,24,6,minecraft:oak_leaves[distance=7,persistent=true])
B(-15,20,7,minecraft:oak_leaves[distance=7,persistent=true])
B(-15,21,7,minecraft:oak_leaves[distance=7,persistent=true])
B(-15,22,7,minecraft:oak_leaves[distance=7,persistent=true])
B(-15,23,7,minecraft:oak_leaves[distance=7,persistent=true])
B(-15,25,7,minecraft:oak_leaves[distance=7,persistent=true])
B(-15,25,8,minecraft:oak_leaves[distance=7,persistent=true])
B(-15,26,8,minecraft:oak_leaves[distance=7,persistent=true])
B(-15,26,9,minecraft:oak_leaves[distance=7,persistent=true])
B(-14,25,-20,minecraft:oak_leaves[distance=7,persistent=true])
B(-14,25,-19,minecraft:oak_leaves[distance=7,persistent=true])
B(-14,24,-18,minecraft:oak_leaves[distance=7,persistent=true])
B(-14,25,-18,minecraft:oak_leaves[distance=7,persistent=true])
B(-14,26,-18,minecraft:oak_leaves[distance=7,persistent=true])
B(-14,24,-17,minecraft:oak_leaves[distance=7,persistent=true])
B(-14,25,-17,minecraft:oak_leaves[distance=7,persistent=true])
B(-14,26,-17,minecraft:oak_leaves[distance=7,persistent=true])
B(-14,27,-17,minecraft:oak_leaves[distance=7,persistent=true])
B(-14,23,-16,minecraft:oak_leaves[distance=7,persistent=true])
B(-14,24,-16,minecraft:oak_leaves[distance=7,persistent=true])
B(-14,25,-16,minecraft:oak_leaves[distance=7,persistent=true])
B(-14,26,-16,minecraft:oak_leaves[distance=7,persistent=true])
B(-14,27,-16,minecraft:oak_leaves[distance=7,persistent=true])
B(-14,28,-16,minecraft:oak_leaves[distance=7,persistent=true])
B(-14,20,-15,minecraft:oak_leaves[distance=5,persistent=false])
B(-14,23,-15,minecraft:oak_leaves[distance=6,persistent=false])
B(-14,20,-14,minecraft:oak_leaves[distance=4,persistent=false])
B(-14,21,-14,minecraft:oak_leaves[distance=3,persistent=false])
B(-14,22,-14,minecraft:oak_leaves[distance=4,persistent=false])
B(-14,30,-14,minecraft:oak_leaves[distance=7,persistent=true])
B(-14,20,-13,minecraft:oak_leaves[distance=3,persistent=false])
B(-14,21,-13,minecraft:oak_leaves[distance=2,persistent=false])
B(-14,22,-13,minecraft:oak_leaves[distance=3,persistent=false])
B(-14,27,-13,minecraft:oak_leaves[distance=7,persistent=true])
B(-14,28,-13,minecraft:oak_leaves[distance=7,persistent=true])
B(-14,29,-13,minecraft:oak_leaves[distance=7,persistent=true])
B(-14,20,-12,minecraft:oak_leaves[distance=2,persistent=false])
B(-14,21,-12,minecraft:oak_leaves)
B(-14,22,-12,minecraft:oak_leaves[distance=2,persistent=false])
B(-14,23,-12,minecraft:oak_leaves[distance=3,persistent=false])
B(-14,24,-12,minecraft:oak_leaves[distance=4,persistent=false])
B(-14,25,-12,minecraft:oak_leaves[distance=5,persistent=false])
B(-14,26,-12,minecraft:oak_leaves[distance=6,persistent=false])
B(-14,27,-12,minecraft:oak_leaves[distance=7,persistent=true])
B(-14,28,-12,minecraft:oak_leaves[distance=7,persistent=true])
B(-14,21,-11,minecraft:oak_wood)
B(-14,22,-11,minecraft:oak_leaves)
B(-14,23,-11,minecraft:oak_leaves[distance=2,persistent=false])
B(-14,24,-11,minecraft:oak_leaves[distance=3,persistent=false])
B(-14,25,-11,minecraft:oak_leaves[distance=4,persistent=false])
B(-14,26,-11,minecraft:oak_leaves[distance=5,persistent=false])
B(-14,19,-10,minecraft:oak_leaves[distance=2,persistent=false])
B(-14,20,-10,minecraft:oak_leaves)
B(-14,21,-10,minecraft:oak_wood)
B(-14,22,-10,minecraft:oak_leaves)
B(-14,23,-10,minecraft:oak_leaves[distance=2,persistent=false])
B(-14,24,-10,minecraft:oak_leaves[distance=3,persistent=false])
B(-14,25,-10,minecraft:oak_leaves[distance=4,persistent=false])
B(-14,15,-9,minecraft:oak_leaves[distance=7,persistent=true])
B(-14,16,-9,minecraft:oak_leaves[distance=7,persistent=true])
B(-14,18,-9,minecraft:oak_leaves[distance=4,persistent=false])
B(-14,20,-9,minecraft:oak_leaves[distance=2,persistent=false])
B(-14,21,-9,minecraft:oak_leaves)
B(-14,22,-9,minecraft:oak_leaves[distance=2,persistent=false])
B(-14,23,-9,minecraft:oak_leaves[distance=3,persistent=false])
B(-14,24,-9,minecraft:oak_leaves[distance=4,persistent=false])
B(-14,25,-9,minecraft:oak_leaves[distance=5,persistent=false])
B(-14,18,-8,minecraft:oak_leaves[distance=5,persistent=false])
B(-14,19,-8,minecraft:oak_leaves[distance=4,persistent=false])
B(-14,20,-8,minecraft:oak_leaves[distance=3,persistent=false])
B(-14,21,-8,minecraft:oak_leaves[distance=2,persistent=false])
B(-14,22,-8,minecraft:oak_leaves[distance=3,persistent=false])
B(-14,24,-8,minecraft:oak_leaves[distance=5,persistent=false])
B(-14,25,-8,minecraft:oak_leaves[distance=6,persistent=false])
B(-14,19,-7,minecraft:oak_leaves[distance=5,persistent=false])
B(-14,21,-7,minecraft:oak_leaves[distance=3,persistent=false])
B(-14,22,-7,minecraft:oak_leaves[distance=4,persistent=false])
B(-14,23,-7,minecraft:oak_leaves[distance=5,persistent=false])
B(-14,24,-7,minecraft:oak_leaves[distance=6,persistent=false])
B(-14,25,-7,minecraft:oak_leaves[distance=7,persistent=true])
B(-14,26,-7,minecraft:oak_leaves[distance=7,persistent=true])
B(-14,19,-6,minecraft:oak_leaves[distance=6,persistent=false])
B(-14,21,-6,minecraft:oak_leaves[distance=4,persistent=false])
B(-14,22,-6,minecraft:oak_leaves[distance=5,persistent=false])
B(-14,23,-6,minecraft:oak_leaves[distance=6,persistent=false])
B(-14,24,-6,minecraft:oak_leaves[distance=7,persistent=true])
B(-14,25,-6,minecraft:oak_leaves[distance=7,persistent=true])
B(-14,27,-6,minecraft:oak_leaves[distance=7,persistent=true])
B(-14,28,-6,minecraft:oak_leaves[distance=7,persistent=true])
B(-14,20,-5,minecraft:oak_leaves[distance=7,persistent=true])
B(-14,22,-5,minecraft:oak_leaves[distance=6,persistent=false])
B(-14,23,-5,minecraft:oak_leaves[distance=7,persistent=true])
B(-14,24,-5,minecraft:oak_leaves[distance=7,persistent=true])
B(-14,27,-5,minecraft:oak_leaves[distance=7,persistent=true])
B(-14,20,-4,minecraft:oak_leaves[distance=7,persistent=true])
B(-14,21,-4,minecraft:oak_leaves[distance=7,persistent=true])
B(-14,22,-4,minecraft:oak_leaves[distance=7,persistent=true])
B(-14,23,-4,minecraft:oak_leaves[distance=7,persistent=true])
B(-14,26,-4,minecraft:oak_leaves[distance=7,persistent=true])
B(-14,27,-4,minecraft:oak_leaves[distance=7,persistent=true])
B(-14,30,-4,minecraft:oak_leaves[distance=7,persistent=true])
B(-14,21,-3,minecraft:oak_leaves[distance=7,persistent=true])
B(-14,22,-3,minecraft:oak_leaves[distance=7,persistent=true])
B(-14,23,-3,minecraft:oak_leaves[distance=7,persistent=true])
B(-14,24,-3,minecraft:oak_leaves[distance=7,persistent=true])
B(-14,25,-3,minecraft:oak_leaves[distance=7,persistent=true])
B(-14,26,-3,minecraft:oak_leaves[distance=7,persistent=true])
B(-14,21,-2,minecraft:oak_leaves[distance=7,persistent=true])
B(-14,22,-2,minecraft:oak_leaves[distance=7,persistent=true])
B(-14,23,-2,minecraft:oak_leaves[distance=7,persistent=true])
B(-14,24,-2,minecraft:oak_leaves[distance=6,persistent=false])
B(-14,25,-2,minecraft:oak_leaves[distance=6,persistent=false])
B(-14,26,-2,minecraft:oak_leaves[distance=6,persistent=false])
B(-14,23,-1,minecraft:oak_leaves[distance=6,persistent=false])
B(-14,24,-1,minecraft:oak_leaves[distance=5,persistent=false])
B(-14,25,-1,minecraft:oak_leaves[distance=5,persistent=false])
B(-14,26,-1,minecraft:oak_leaves[distance=5,persistent=false])
B(-14,22,0,minecraft:oak_leaves[distance=6,persistent=false])
B(-14,23,0,minecraft:oak_leaves[distance=5,persistent=false])
B(-14,24,0,minecraft:oak_leaves[distance=4,persistent=false])
B(-14,26,0,minecraft:oak_leaves[distance=4,persistent=false])
B(-14,24,1,minecraft:oak_leaves[distance=5,persistent=false])
B(-14,26,1,minecraft:oak_leaves[distance=3,persistent=false])
B(-14,27,1,minecraft:oak_leaves[distance=2,persistent=false])
B(-14,24,2,minecraft:oak_leaves[distance=6,persistent=false])
B(-14,27,2,minecraft:oak_leaves)
B(-14,24,3,minecraft:oak_leaves[distance=7,persistent=true])
B(-14,27,3,minecraft:oak_wood)
B(-14,24,4,minecraft:oak_leaves[distance=6,persistent=false])
B(-14,21,5,minecraft:oak_leaves[distance=7,persistent=true])
B(-14,22,5,minecraft:oak_leaves[distance=7,persistent=true])
B(-14,23,5,minecraft:oak_leaves[distance=7,persistent=true])
B(-14,24,5,minecraft:oak_leaves[distance=7,persistent=true])
B(-14,26,5,minecraft:oak_leaves[distance=5,persistent=false])
B(-14,27,5,minecraft:oak_leaves[distance=4,persistent=false])
B(-14,28,5,minecraft:oak_leaves[distance=5,persistent=false])
B(-14,29,5,minecraft:oak_leaves[distance=6,persistent=false])
B(-14,25,7,minecraft:oak_leaves[distance=7,persistent=true])
B(-14,25,8,minecraft:oak_leaves[distance=7,persistent=true])
B(-14,26,8,minecraft:oak_leaves[distance=7,persistent=true])
B(-14,26,9,minecraft:oak_leaves[distance=7,persistent=true])
B(-14,27,10,minecraft:oak_leaves[distance=7,persistent=true])
B(-14,24,12,minecraft:oak_leaves[distance=7,persistent=true])
B(-14,25,13,minecraft:oak_leaves[distance=7,persistent=true])
B(-14,26,13,minecraft:oak_leaves[distance=7,persistent=true])
B(-14,26,14,minecraft:oak_leaves[distance=7,persistent=true])
B(-13,24,-20,minecraft:oak_leaves[distance=7,persistent=true])
B(-13,24,-18,minecraft:oak_leaves[distance=7,persistent=true])
B(-13,24,-17,minecraft:oak_leaves[distance=7,persistent=true])
B(-13,23,-16,minecraft:oak_leaves[distance=7,persistent=true])
B(-13,24,-16,minecraft:oak_leaves[distance=7,persistent=true])
B(-13,25,-16,minecraft:oak_leaves[distance=7,persistent=true])
B(-13,26,-16,minecraft:oak_leaves[distance=7,persistent=true])
B(-13,27,-16,minecraft:oak_leaves[distance=7,persistent=true])
B(-13,23,-15,minecraft:oak_leaves[distance=7,persistent=true])
B(-13,24,-15,minecraft:oak_leaves[distance=7,persistent=true])
B(-13,25,-15,minecraft:oak_leaves[distance=7,persistent=true])
B(-13,26,-15,minecraft:oak_leaves[distance=7,persistent=true])
B(-13,27,-15,minecraft:oak_leaves[distance=7,persistent=true])
B(-13,28,-15,minecraft:oak_leaves[distance=7,persistent=true])
B(-13,22,-14,minecraft:oak_leaves[distance=5,persistent=false])
B(-13,29,-14,minecraft:oak_leaves[distance=7,persistent=true])
B(-13,21,-13,minecraft:oak_leaves[distance=3,persistent=false])
B(-13,22,-13,minecraft:oak_leaves[distance=4,persistent=false])
B(-13,27,-13,minecraft:oak_leaves[distance=7,persistent=true])
B(-13,28,-13,minecraft:oak_leaves[distance=7,persistent=true])
B(-13,20,-12,minecraft:oak_leaves[distance=2,persistent=false])
B(-13,21,-12,minecraft:oak_leaves[distance=2,persistent=false])
B(-13,25,-12,minecraft:oak_leaves[distance=6,persistent=false])
B(-13,26,-12,minecraft:oak_leaves[distance=7,persistent=true])
B(-13,27,-12,minecraft:oak_leaves[distance=7,persistent=true])
B(-13,19,-11,minecraft:oak_leaves[distance=2,persistent=false])
B(-13,20,-11,minecraft:oak_leaves)
B(-13,21,-11,minecraft:oak_leaves)
B(-13,22,-11,minecraft:oak_leaves[distance=2,persistent=false])
B(-13,23,-11,minecraft:oak_leaves[distance=3,persistent=false])
B(-13,24,-11,minecraft:oak_leaves[distance=4,persistent=false])
B(-13,25,-11,minecraft:oak_leaves[distance=5,persistent=false])
B(-13,19,-10,minecraft:oak_leaves)
B(-13,20,-10,minecraft:oak_wood)
B(-13,21,-10,minecraft:oak_wood)
B(-13,22,-10,minecraft:oak_leaves)
B(-13,23,-10,minecraft:oak_leaves[distance=2,persistent=false])
B(-13,16,-9,minecraft:oak_leaves[distance=7,persistent=true])
B(-13,18,-9,minecraft:oak_leaves[distance=3,persistent=false])
B(-13,20,-9,minecraft:oak_leaves)
B(-13,21,-9,minecraft:oak_leaves)
B(-13,22,-9,minecraft:oak_leaves[distance=2,persistent=false])
B(-13,23,-9,minecraft:oak_leaves[distance=3,persistent=false])
B(-13,14,-8,minecraft:oak_leaves[distance=7,persistent=true])
B(-13,15,-8,minecraft:oak_leaves[distance=7,persistent=true])
B(-13,16,-8,minecraft:oak_leaves[distance=6,persistent=false])
B(-13,17,-8,minecraft:oak_leaves[distance=5,persistent=false])
B(-13,18,-8,minecraft:oak_leaves[distance=4,persistent=false])
B(-13,19,-8,minecraft:oak_leaves[distance=3,persistent=false])
B(-13,20,-8,minecraft:oak_leaves[distance=2,persistent=false])
B(-13,21,-8,minecraft:oak_leaves[distance=2,persistent=false])
B(-13,23,-8,minecraft:oak_leaves[distance=4,persistent=false])
B(-13,18,-7,minecraft:oak_leaves[distance=5,persistent=false])
B(-13,19,-7,minecraft:oak_leaves[distance=4,persistent=false])
B(-13,20,-7,minecraft:oak_leaves[distance=3,persistent=false])
B(-13,21,-7,minecraft:oak_leaves[distance=3,persistent=false])
B(-13,22,-7,minecraft:oak_leaves[distance=4,persistent=false])
B(-13,23,-7,minecraft:oak_leaves[distance=5,persistent=false])
B(-13,24,-7,minecraft:oak_leaves[distance=6,persistent=false])
B(-13,25,-7,minecraft:oak_leaves[distance=7,persistent=true])
B(-13,26,-7,minecraft:oak_leaves[distance=7,persistent=true])
B(-13,28,-7,minecraft:oak_leaves[distance=7,persistent=true])
B(-13,19,-6,minecraft:oak_leaves[distance=5,persistent=false])
B(-13,21,-6,minecraft:oak_leaves[distance=4,persistent=false])
B(-13,22,-6,minecraft:oak_leaves[distance=5,persistent=false])
B(-13,27,-6,minecraft:oak_leaves[distance=6,persistent=false])
B(-13,28,-6,minecraft:oak_leaves[distance=7,persistent=true])
B(-13,19,-5,minecraft:oak_leaves[distance=6,persistent=false])
B(-13,21,-5,minecraft:oak_leaves[distance=5,persistent=false])
B(-13,22,-5,minecraft:oak_leaves[distance=6,persistent=false])
B(-13,26,-5,minecraft:oak_leaves[distance=6,persistent=false])
B(-13,27,-5,minecraft:oak_leaves[distance=7,persistent=true])
B(-13,29,-5,minecraft:oak_leaves[distance=7,persistent=true])
B(-13,20,-4,minecraft:oak_leaves[distance=7,persistent=true])
B(-13,21,-4,minecraft:oak_leaves[distance=6,persistent=false])
B(-13,22,-4,minecraft:oak_leaves[distance=7,persistent=true])
B(-13,23,-4,minecraft:oak_leaves[distance=7,persistent=true])
B(-13,24,-4,minecraft:oak_leaves[distance=7,persistent=true])
B(-13,25,-4,minecraft:oak_leaves[distance=7,persistent=true])
B(-13,26,-4,minecraft:oak_leaves[distance=7,persistent=true])
B(-13,30,-4,minecraft:oak_leaves[distance=7,persistent=true])
B(-13,20,-3,minecraft:oak_leaves[distance=7,persistent=true])
B(-13,21,-3,minecraft:oak_leaves[distance=7,persistent=true])
B(-13,23,-3,minecraft:oak_leaves[distance=7,persistent=true])
B(-13,24,-3,minecraft:oak_leaves[distance=6,persistent=false])
B(-13,25,-3,minecraft:oak_leaves[distance=6,persistent=false])
B(-13,26,-3,minecraft:oak_leaves[distance=7,persistent=true])
B(-13,30,-3,minecraft:oak_leaves[distance=7,persistent=true])
B(-13,31,-3,minecraft:oak_leaves[distance=7,persistent=true])
B(-13,20,-2,minecraft:oak_leaves[distance=7,persistent=true])
B(-13,21,-2,minecraft:oak_leaves[distance=7,persistent=true])
B(-13,22,-2,minecraft:oak_leaves[distance=7,persistent=true])
B(-13,23,-2,minecraft:oak_leaves[distance=6,persistent=false])
B(-13,24,-2,minecraft:oak_leaves[distance=5,persistent=false])
B(-13,25,-2,minecraft:oak_leaves[distance=5,persistent=false])
B(-13,31,-2,minecraft:oak_leaves[distance=7,persistent=true])
B(-13,22,-1,minecraft:oak_leaves[distance=6,persistent=false])
B(-13,24,-1,minecraft:oak_leaves[distance=4,persistent=false])
B(-13,25,-1,minecraft:oak_leaves[distance=4,persistent=false])
B(-13,32,-1,minecraft:oak_leaves[distance=7,persistent=true])
B(-13,22,0,minecraft:oak_leaves[distance=7,persistent=true])
B(-13,24,0,minecraft:oak_leaves[distance=3,persistent=false])
B(-13,25,0,minecraft:oak_leaves[distance=3,persistent=false])
B(-13,26,0,minecraft:oak_leaves[distance=3,persistent=false])
B(-13,22,1,minecraft:oak_leaves[distance=7,persistent=true])
B(-13,24,1,minecraft:oak_leaves[distance=4,persistent=false])
B(-13,26,1,minecraft:oak_leaves[distance=2,persistent=false])
B(-13,24,2,minecraft:oak_leaves[distance=5,persistent=false])
B(-13,26,2,minecraft:oak_leaves)
B(-13,27,2,minecraft:oak_wood)
B(-13,24,3,minecraft:oak_leaves[distance=6,persistent=false])
B(-13,27,3,minecraft:oak_leaves)
B(-13,32,3,minecraft:oak_leaves[distance=7,persistent=true])
B(-13,23,4,minecraft:oak_leaves[distance=5,persistent=false])
B(-13,24,4,minecraft:oak_leaves[distance=5,persistent=false])
B(-13,25,4,minecraft:oak_leaves[distance=4,persistent=false])
B(-13,26,4,minecraft:oak_leaves[distance=3,persistent=false])
B(-13,27,4,minecraft:oak_leaves[distance=2,persistent=false])
B(-13,28,4,minecraft:oak_leaves[distance=3,persistent=false])
B(-13,29,4,minecraft:oak_leaves[distance=4,persistent=false])
B(-13,19,5,minecraft:oak_leaves[distance=7,persistent=true])
B(-13,20,5,minecraft:oak_leaves[distance=7,persistent=true])
B(-13,21,5,minecraft:oak_leaves[distance=7,persistent=true])
B(-13,22,5,minecraft:oak_leaves[distance=7,persistent=true])
B(-13,23,5,minecraft:oak_leaves[distance=6,persistent=false])
B(-13,24,5,minecraft:oak_leaves[distance=6,persistent=false])
B(-13,27,5,minecraft:oak_leaves[distance=3,persistent=false])
B(-13,28,5,minecraft:oak_leaves[distance=4,persistent=false])
B(-13,29,5,minecraft:oak_leaves[distance=5,persistent=false])
B(-13,24,6,minecraft:oak_leaves[distance=7,persistent=true])
B(-13,25,7,minecraft:oak_leaves[distance=7,persistent=true])
B(-13,25,8,minecraft:oak_leaves[distance=7,persistent=true])
B(-13,26,8,minecraft:oak_leaves[distance=7,persistent=true])
B(-13,26,9,minecraft:oak_leaves[distance=7,persistent=true])
B(-13,27,10,minecraft:oak_leaves[distance=7,persistent=true])
B(-13,23,11,minecraft:oak_leaves[distance=7,persistent=true])
B(-13,24,12,minecraft:oak_leaves[distance=7,persistent=true])
B(-13,25,13,minecraft:oak_leaves[distance=7,persistent=true])
B(-13,26,13,minecraft:oak_leaves[distance=7,persistent=true])
B(-13,26,14,minecraft:oak_leaves[distance=7,persistent=true])
B(-13,27,14,minecraft:oak_leaves[distance=7,persistent=true])
B(-13,27,15,minecraft:oak_leaves[distance=7,persistent=true])
B(-13,28,15,minecraft:oak_leaves[distance=7,persistent=true])
B(-12,24,-20,minecraft:oak_leaves[distance=7,persistent=true])
B(-12,23,-19,minecraft:oak_leaves[distance=7,persistent=true])
B(-12,24,-19,minecraft:oak_leaves[distance=7,persistent=true])
B(-12,23,-18,minecraft:oak_leaves[distance=7,persistent=true])
B(-12,28,-18,minecraft:oak_leaves[distance=7,persistent=true])
B(-12,23,-17,minecraft:oak_leaves[distance=7,persistent=true])
B(-12,27,-17,minecraft:oak_leaves[distance=7,persistent=true])
B(-12,28,-17,minecraft:oak_leaves[distance=7,persistent=true])
B(-12,23,-16,minecraft:oak_leaves[distance=7,persistent=true])
B(-12,27,-16,minecraft:oak_leaves[distance=7,persistent=true])
B(-12,22,-15,minecraft:oak_leaves[distance=7,persistent=true])
B(-12,23,-15,minecraft:oak_leaves[distance=7,persistent=true])
B(-12,26,-15,minecraft:oak_leaves[distance=7,persistent=true])
B(-12,22,-14,minecraft:oak_leaves[distance=6,persistent=false])
B(-12,23,-14,minecraft:oak_leaves[distance=7,persistent=true])
B(-12,24,-14,minecraft:oak_leaves[distance=7,persistent=true])
B(-12,25,-14,minecraft:oak_leaves[distance=7,persistent=true])
B(-12,26,-14,minecraft:oak_leaves[distance=7,persistent=true])
B(-12,27,-14,minecraft:oak_leaves[distance=7,persistent=true])
B(-12,28,-14,minecraft:oak_leaves[distance=7,persistent=true])
B(-12,21,-13,minecraft:oak_leaves[distance=4,persistent=false])
B(-12,22,-13,minecraft:oak_leaves[distance=5,persistent=false])
B(-12,23,-13,minecraft:oak_leaves[distance=6,persistent=false])
B(-12,24,-13,minecraft:oak_leaves[distance=7,persistent=true])
B(-12,25,-13,minecraft:oak_leaves[distance=7,persistent=true])
B(-12,26,-13,minecraft:oak_leaves[distance=7,persistent=true])
B(-12,27,-13,minecraft:oak_leaves[distance=7,persistent=true])
B(-12,28,-13,minecraft:oak_leaves[distance=7,persistent=true])
B(-12,19,-12,minecraft:oak_leaves[distance=4,persistent=false])
B(-12,20,-12,minecraft:oak_leaves[distance=3,persistent=false])
B(-12,21,-12,minecraft:oak_leaves[distance=3,persistent=false])
B(-12,24,-12,minecraft:oak_leaves[distance=6,persistent=false])
B(-12,25,-12,minecraft:oak_leaves[distance=7,persistent=true])
B(-12,26,-12,minecraft:oak_leaves[distance=7,persistent=true])
B(-12,19,-11,minecraft:oak_leaves[distance=3,persistent=false])
B(-12,20,-11,minecraft:oak_leaves[distance=2,persistent=false])
B(-12,23,-11,minecraft:oak_leaves[distance=4,persistent=false])
B(-12,24,-11,minecraft:oak_leaves[distance=5,persistent=false])
B(-12,18,-10,minecraft:oak_leaves[distance=3,persistent=false])
B(-12,19,-10,minecraft:oak_leaves[distance=2,persistent=false])
B(-12,20,-10,minecraft:oak_leaves)
B(-12,21,-10,minecraft:oak_leaves)
B(-12,22,-10,minecraft:oak_leaves[distance=2,persistent=false])
B(-12,27,-10,minecraft:oak_leaves[distance=2,persistent=false])
B(-12,28,-10,minecraft:oak_leaves[distance=3,persistent=false])
B(-12,18,-9,minecraft:oak_leaves[distance=2,persistent=false])
B(-12,19,-9,minecraft:oak_leaves)
B(-12,20,-9,minecraft:oak_leaves)
B(-12,21,-9,minecraft:oak_leaves[distance=2,persistent=false])
B(-12,14,-8,minecraft:oak_leaves[distance=7,persistent=true])
B(-12,15,-8,minecraft:oak_leaves[distance=6,persistent=false])
B(-12,16,-8,minecraft:oak_leaves[distance=5,persistent=false])
B(-12,17,-8,minecraft:oak_leaves[distance=4,persistent=false])
B(-12,18,-8,minecraft:oak_leaves[distance=3,persistent=false])
B(-12,19,-8,minecraft:oak_leaves[distance=2,persistent=false])
B(-12,20,-8,minecraft:oak_leaves[distance=2,persistent=false])
B(-12,18,-7,minecraft:oak_leaves[distance=4,persistent=false])
B(-12,19,-7,minecraft:oak_leaves[distance=3,persistent=false])
B(-12,20,-7,minecraft:oak_leaves[distance=3,persistent=false])
B(-12,21,-7,minecraft:oak_leaves[distance=4,persistent=false])
B(-12,22,-7,minecraft:oak_leaves[distance=5,persistent=false])
B(-12,23,-7,minecraft:oak_leaves[distance=6,persistent=false])
B(-12,24,-7,minecraft:oak_leaves[distance=7,persistent=true])
B(-12,25,-7,minecraft:oak_leaves[distance=7,persistent=true])
B(-12,27,-7,minecraft:oak_leaves[distance=4,persistent=false])
B(-12,18,-6,minecraft:oak_leaves[distance=5,persistent=false])
B(-12,19,-6,minecraft:oak_leaves[distance=4,persistent=false])
B(-12,20,-6,minecraft:oak_leaves[distance=4,persistent=false])
B(-12,21,-6,minecraft:oak_leaves[distance=5,persistent=false])
B(-12,27,-6,minecraft:oak_leaves[distance=5,persistent=false])
B(-12,28,-6,minecraft:oak_leaves[distance=6,persistent=false])
B(-12,19,-5,minecraft:oak_leaves[distance=5,persistent=false])
B(-12,20,-5,minecraft:oak_leaves[distance=5,persistent=false])
B(-12,21,-5,minecraft:oak_leaves[distance=6,persistent=false])
B(-12,22,-5,minecraft:oak_leaves[distance=7,persistent=true])
B(-12,26,-5,minecraft:oak_leaves[distance=5,persistent=false])
B(-12,28,-5,minecraft:oak_leaves[distance=7,persistent=true])
B(-12,29,-5,minecraft:oak_leaves[distance=7,persistent=true])
B(-12,19,-4,minecraft:oak_leaves[distance=6,persistent=false])
B(-12,20,-4,minecraft:oak_leaves[distance=6,persistent=false])
B(-12,21,-4,minecraft:oak_leaves[distance=7,persistent=true])
B(-12,22,-4,minecraft:oak_leaves[distance=7,persistent=true])
B(-12,23,-4,minecraft:oak_leaves[distance=7,persistent=true])
B(-12,24,-4,minecraft:oak_leaves[distance=6,persistent=false])
B(-12,25,-4,minecraft:oak_leaves[distance=6,persistent=false])
B(-12,26,-4,minecraft:oak_leaves[distance=6,persistent=false])
B(-12,29,-4,minecraft:oak_leaves[distance=7,persistent=true])
B(-12,20,-3,minecraft:oak_leaves[distance=7,persistent=true])
B(-12,22,-3,minecraft:oak_leaves[distance=7,persistent=true])
B(-12,25,-3,minecraft:oak_leaves[distance=5,persistent=false])
B(-12,30,-3,minecraft:oak_leaves[distance=7,persistent=true])
B(-12,20,-2,minecraft:oak_leaves[distance=7,persistent=true])
B(-12,21,-2,minecraft:oak_leaves[distance=7,persistent=true])
B(-12,22,-2,minecraft:oak_leaves[distance=6,persistent=false])
B(-12,23,-2,minecraft:oak_leaves[distance=5,persistent=false])
B(-12,24,-2,minecraft:oak_leaves[distance=4,persistent=false])
B(-12,25,-2,minecraft:oak_leaves[distance=4,persistent=false])
B(-12,30,-2,minecraft:oak_leaves[distance=7,persistent=true])
B(-12,31,-2,minecraft:oak_leaves[distance=7,persistent=true])
B(-12,21,-1,minecraft:oak_leaves[distance=6,persistent=false])
B(-12,22,-1,minecraft:oak_leaves[distance=5,persistent=false])
B(-12,23,-1,minecraft:oak_leaves[distance=4,persistent=false])
B(-12,24,-1,minecraft:oak_leaves[distance=3,persistent=false])
B(-12,25,-1,minecraft:oak_leaves[distance=3,persistent=false])
B(-12,31,-1,minecraft:oak_leaves[distance=7,persistent=true])
B(-12,21,0,minecraft:oak_leaves[distance=7,persistent=true])
B(-12,23,0,minecraft:oak_leaves[distance=3,persistent=false])
B(-12,24,0,minecraft:oak_leaves[distance=2,persistent=false])
B(-12,25,0,minecraft:oak_leaves[distance=2,persistent=false])
B(-12,31,0,minecraft:oak_leaves[distance=7,persistent=true])
B(-12,20,1,minecraft:oak_leaves[distance=7,persistent=true])
B(-12,21,1,minecraft:oak_leaves[distance=7,persistent=true])
B(-12,23,1,minecraft:oak_leaves[distance=2,persistent=false])
B(-12,25,1,minecraft:oak_leaves)
B(-12,26,1,minecraft:oak_leaves[distance=2,persistent=false])
B(-12,31,1,minecraft:oak_leaves[distance=7,persistent=true])
B(-12,32,1,minecraft:oak_leaves[distance=7,persistent=true])
B(-12,23,2,minecraft:oak_leaves[distance=2,persistent=false])
B(-12,25,2,minecraft:oak_wood)
B(-12,26,2,minecraft:oak_leaves)
B(-12,27,2,minecraft:oak_wood)
B(-12,31,2,minecraft:oak_leaves[distance=7,persistent=true])
B(-12,23,3,minecraft:oak_leaves[distance=3,persistent=false])
B(-12,25,3,minecraft:oak_leaves)
B(-12,26,3,minecraft:oak_leaves[distance=2,persistent=false])
B(-12,27,3,minecraft:oak_leaves)
B(-12,30,3,minecraft:oak_leaves[distance=6,persistent=false])
B(-12,31,3,minecraft:oak_leaves[distance=7,persistent=true])
B(-12,20,4,minecraft:oak_leaves[distance=7,persistent=true])
B(-12,21,4,minecraft:oak_leaves[distance=6,persistent=false])
B(-12,22,4,minecraft:oak_leaves[distance=5,persistent=false])
B(-12,23,4,minecraft:oak_leaves[distance=4,persistent=false])
B(-12,26,4,minecraft:oak_leaves[distance=3,persistent=false])
B(-12,27,4,minecraft:oak_leaves[distance=2,persistent=false])
B(-12,28,4,minecraft:oak_leaves[distance=3,persistent=false])
B(-12,29,4,minecraft:oak_leaves[distance=4,persistent=false])
B(-12,30,4,minecraft:oak_leaves[distance=5,persistent=false])
B(-12,31,4,minecraft:oak_leaves[distance=6,persistent=false])
B(-12,24,5,minecraft:oak_leaves[distance=7,persistent=true])
B(-12,24,6,minecraft:oak_leaves[distance=7,persistent=true])
B(-12,25,6,minecraft:oak_leaves[distance=7,persistent=true])
B(-12,25,7,minecraft:oak_leaves[distance=7,persistent=true])
B(-12,25,8,minecraft:oak_leaves[distance=7,persistent=true])
B(-12,26,8,minecraft:oak_leaves[distance=7,persistent=true])
B(-12,26,9,minecraft:oak_leaves[distance=7,persistent=true])
B(-12,20,10,minecraft:oak_leaves[distance=6,persistent=false])
B(-12,27,10,minecraft:oak_leaves[distance=7,persistent=true])
B(-12,20,11,minecraft:oak_leaves[distance=6,persistent=false])
B(-12,22,11,minecraft:oak_leaves[distance=5,persistent=false])
B(-12,23,11,minecraft:oak_leaves[distance=6,persistent=false])
B(-12,20,12,minecraft:oak_leaves[distance=7,persistent=true])
B(-12,23,12,minecraft:oak_leaves[distance=5,persistent=false])
B(-12,24,12,minecraft:oak_leaves[distance=6,persistent=false])
B(-12,24,13,minecraft:oak_leaves[distance=5,persistent=false])
B(-12,25,13,minecraft:oak_leaves[distance=6,persistent=false])
B(-12,26,14,minecraft:oak_leaves[distance=6,persistent=false])
B(-12,27,14,minecraft:oak_leaves[distance=7,persistent=true])
B(-12,27,15,minecraft:oak_leaves[distance=7,persistent=true])
B(-11,23,-20,minecraft:oak_leaves[distance=7,persistent=true])
B(-11,23,-19,minecraft:oak_leaves[distance=7,persistent=true])
B(-11,29,-19,minecraft:oak_leaves[distance=7,persistent=true])
B(-11,22,-18,minecraft:oak_leaves[distance=7,persistent=true])
B(-11,23,-18,minecraft:oak_leaves[distance=7,persistent=true])
B(-11,28,-18,minecraft:oak_leaves[distance=7,persistent=true])
B(-11,22,-17,minecraft:oak_leaves[distance=7,persistent=true])
B(-11,23,-17,minecraft:oak_leaves[distance=7,persistent=true])
B(-11,27,-17,minecraft:oak_leaves[distance=7,persistent=true])
B(-11,28,-17,minecraft:oak_leaves[distance=7,persistent=true])
B(-11,22,-16,minecraft:oak_leaves[distance=7,persistent=true])
B(-11,27,-16,minecraft:oak_leaves[distance=7,persistent=true])
B(-11,22,-15,minecraft:oak_leaves[distance=7,persistent=true])
B(-11,26,-15,minecraft:oak_leaves[distance=7,persistent=true])
B(-11,21,-14,minecraft:oak_leaves[distance=5,persistent=false])
B(-11,22,-14,minecraft:oak_leaves[distance=6,persistent=false])
B(-11,25,-14,minecraft:oak_leaves[distance=7,persistent=true])
B(-11,27,-14,minecraft:oak_leaves[distance=7,persistent=true])
B(-11,28,-14,minecraft:oak_leaves[distance=7,persistent=true])
B(-11,21,-13,minecraft:oak_leaves[distance=4,persistent=false])
B(-11,22,-13,minecraft:oak_leaves[distance=5,persistent=false])
B(-11,23,-13,minecraft:oak_leaves[distance=6,persistent=false])
B(-11,24,-13,minecraft:oak_leaves[distance=7,persistent=true])
B(-11,25,-13,minecraft:oak_leaves[distance=7,persistent=true])
B(-11,26,-13,minecraft:oak_leaves[distance=7,persistent=true])
B(-11,27,-13,minecraft:oak_leaves[distance=7,persistent=true])
B(-11,19,-12,minecraft:oak_leaves[distance=3,persistent=false])
B(-11,21,-12,minecraft:oak_leaves[distance=3,persistent=false])
B(-11,22,-12,minecraft:oak_leaves[distance=4,persistent=false])
B(-11,23,-12,minecraft:oak_leaves[distance=5,persistent=false])
B(-11,24,-12,minecraft:oak_leaves[distance=6,persistent=false])
B(-11,25,-12,minecraft:oak_leaves[distance=7,persistent=true])
B(-11,26,-12,minecraft:oak_leaves[distance=7,persistent=true])
B(-11,19,-11,minecraft:oak_leaves[distance=2,persistent=false])
B(-11,20,-11,minecraft:oak_leaves)
B(-11,21,-11,minecraft:oak_leaves[distance=2,persistent=false])
B(-11,23,-11,minecraft:oak_leaves[distance=5,persistent=false])
B(-11,24,-11,minecraft:oak_leaves[distance=6,persistent=false])
B(-11,25,-11,minecraft:oak_leaves[distance=7,persistent=true])
B(-11,18,-10,minecraft:oak_leaves[distance=2,persistent=false])
B(-11,19,-10,minecraft:oak_leaves)
B(-11,20,-10,minecraft:oak_wood)
B(-11,27,-10,minecraft:oak_leaves)
B(-11,28,-10,minecraft:oak_leaves[distance=2,persistent=false])
B(-11,29,-10,minecraft:oak_leaves[distance=3,persistent=false])
B(-11,30,-10,minecraft:oak_leaves[distance=4,persistent=false])
B(-11,18,-9,minecraft:oak_leaves)
B(-11,19,-9,minecraft:oak_wood)
B(-11,20,-9,minecraft:oak_wood)
B(-11,26,-9,minecraft:oak_wood)
B(-11,27,-9,minecraft:oak_wood)
B(-11,13,-8,minecraft:oak_leaves[distance=7,persistent=true])
B(-11,14,-8,minecraft:oak_leaves[distance=6,persistent=false])
B(-11,15,-8,minecraft:oak_leaves[distance=5,persistent=false])
B(-11,16,-8,minecraft:oak_leaves[distance=4,persistent=false])
B(-11,17,-8,minecraft:oak_leaves[distance=3,persistent=false])
B(-11,18,-8,minecraft:oak_leaves[distance=2,persistent=false])
B(-11,19,-8,minecraft:oak_leaves)
B(-11,20,-8,minecraft:oak_leaves)
B(-11,18,-7,minecraft:oak_leaves[distance=3,persistent=false])
B(-11,19,-7,minecraft:oak_leaves[distance=2,persistent=false])
B(-11,20,-7,minecraft:oak_leaves[distance=2,persistent=false])
B(-11,21,-7,minecraft:oak_leaves[distance=3,persistent=false])
B(-11,22,-7,minecraft:oak_leaves[distance=4,persistent=false])
B(-11,23,-7,minecraft:oak_leaves[distance=5,persistent=false])
B(-11,24,-7,minecraft:oak_leaves[distance=6,persistent=false])
B(-11,25,-7,minecraft:oak_leaves[distance=7,persistent=true])
B(-11,27,-7,minecraft:oak_leaves[distance=3,persistent=false])
B(-11,18,-6,minecraft:oak_leaves[distance=4,persistent=false])
B(-11,20,-6,minecraft:oak_leaves[distance=3,persistent=false])
B(-11,26,-6,minecraft:oak_leaves[distance=3,persistent=false])
B(-11,27,-6,minecraft:oak_leaves[distance=4,persistent=false])
B(-11,28,-6,minecraft:oak_leaves[distance=5,persistent=false])
B(-11,18,-5,minecraft:oak_leaves[distance=5,persistent=false])
B(-11,19,-5,minecraft:oak_leaves[distance=5,persistent=false])
B(-11,20,-5,minecraft:oak_leaves[distance=4,persistent=false])
B(-11,21,-5,minecraft:oak_leaves[distance=5,persistent=false])
B(-11,26,-5,minecraft:oak_leaves[distance=4,persistent=false])
B(-11,28,-5,minecraft:oak_leaves[distance=6,persistent=false])
B(-11,19,-4,minecraft:oak_leaves[distance=6,persistent=false])
B(-11,20,-4,minecraft:oak_leaves[distance=5,persistent=false])
B(-11,21,-4,minecraft:oak_leaves[distance=6,persistent=false])
B(-11,22,-4,minecraft:oak_leaves[distance=7,persistent=true])
B(-11,23,-4,minecraft:oak_leaves[distance=6,persistent=false])
B(-11,24,-4,minecraft:oak_leaves[distance=5,persistent=false])
B(-11,25,-4,minecraft:oak_leaves[distance=6,persistent=false])
B(-11,26,-4,minecraft:oak_leaves[distance=5,persistent=false])
B(-11,28,-4,minecraft:oak_leaves[distance=7,persistent=true])
B(-11,29,-4,minecraft:oak_leaves[distance=7,persistent=true])
B(-11,19,-3,minecraft:oak_leaves[distance=7,persistent=true])
B(-11,21,-3,minecraft:oak_leaves[distance=7,persistent=true])
B(-11,24,-3,minecraft:oak_leaves[distance=4,persistent=false])
B(-11,25,-3,minecraft:oak_leaves[distance=5,persistent=false])
B(-11,29,-3,minecraft:oak_leaves[distance=7,persistent=true])
B(-11,30,-3,minecraft:oak_leaves[distance=7,persistent=true])
B(-11,20,-2,minecraft:oak_leaves[distance=7,persistent=true])
B(-11,21,-2,minecraft:oak_leaves[distance=6,persistent=false])
B(-11,22,-2,minecraft:oak_leaves[distance=5,persistent=false])
B(-11,23,-2,minecraft:oak_leaves[distance=4,persistent=false])
B(-11,24,-2,minecraft:oak_leaves[distance=3,persistent=false])
B(-11,29,-2,minecraft:oak_leaves[distance=7,persistent=true])
B(-11,30,-2,minecraft:oak_leaves[distance=7,persistent=true])
B(-11,20,-1,minecraft:oak_leaves[distance=7,persistent=true])
B(-11,21,-1,minecraft:oak_leaves[distance=7,persistent=true])
B(-11,23,-1,minecraft:oak_leaves[distance=3,persistent=false])
B(-11,24,-1,minecraft:oak_leaves[distance=2,persistent=false])
B(-11,29,-1,minecraft:oak_leaves[distance=7,persistent=true])
B(-11,30,-1,minecraft:oak_leaves[distance=7,persistent=true])
B(-11,31,-1,minecraft:oak_leaves[distance=7,persistent=true])
B(-11,20,0,minecraft:oak_leaves[distance=7,persistent=true])
B(-11,23,0,minecraft:oak_leaves[distance=2,persistent=false])
B(-11,24,0,minecraft:oak_leaves)
B(-11,25,0,minecraft:oak_leaves[distance=2,persistent=false])
B(-11,29,0,minecraft:oak_leaves[distance=7,persistent=true])
B(-11,30,0,minecraft:oak_leaves[distance=7,persistent=true])
B(-11,31,0,minecraft:oak_leaves[distance=7,persistent=true])
B(-11,20,1,minecraft:oak_leaves[distance=7,persistent=true])
B(-11,23,1,minecraft:oak_leaves)
B(-11,24,1,minecraft:oak_wood)
B(-11,25,1,minecraft:oak_leaves)
B(-11,29,1,minecraft:oak_leaves[distance=6,persistent=false])
B(-11,30,1,minecraft:oak_leaves[distance=7,persistent=true])
B(-11,31,1,minecraft:oak_leaves[distance=7,persistent=true])
B(-11,23,2,minecraft:oak_leaves)
B(-11,24,2,minecraft:oak_wood)
B(-11,25,2,minecraft:oak_leaves)
B(-11,26,2,minecraft:oak_leaves[distance=2,persistent=false])
B(-11,29,2,minecraft:oak_leaves[distance=5,persistent=false])
B(-11,30,2,minecraft:oak_leaves[distance=6,persistent=false])
B(-11,21,3,minecraft:oak_leaves[distance=4,persistent=false])
B(-11,22,3,minecraft:oak_leaves[distance=3,persistent=false])
B(-11,23,3,minecraft:oak_leaves[distance=2,persistent=false])
B(-11,25,3,minecraft:oak_leaves[distance=2,persistent=false])
B(-11,26,3,minecraft:oak_leaves[distance=3,persistent=false])
B(-11,27,3,minecraft:oak_leaves[distance=2,persistent=false])
B(-11,28,3,minecraft:oak_leaves[distance=3,persistent=false])
B(-11,29,3,minecraft:oak_leaves[distance=4,persistent=false])
B(-11,30,3,minecraft:oak_leaves[distance=5,persistent=false])
B(-11,21,4,minecraft:oak_leaves[distance=5,persistent=false])
B(-11,23,4,minecraft:oak_leaves[distance=3,persistent=false])
B(-11,29,4,minecraft:oak_leaves[distance=5,persistent=false])
B(-11,30,4,minecraft:oak_leaves[distance=6,persistent=false])
B(-11,31,4,minecraft:oak_leaves[distance=7,persistent=true])
B(-11,24,5,minecraft:oak_leaves[distance=7,persistent=true])
B(-11,31,5,minecraft:oak_leaves[distance=7,persistent=true])
B(-11,32,5,minecraft:oak_leaves[distance=7,persistent=true])
B(-11,24,6,minecraft:oak_leaves[distance=7,persistent=true])
B(-11,25,6,minecraft:oak_leaves[distance=7,persistent=true])
B(-11,20,7,minecraft:oak_leaves[distance=7,persistent=true])
B(-11,25,7,minecraft:oak_leaves[distance=7,persistent=true])
B(-11,20,8,minecraft:oak_leaves[distance=7,persistent=true])
B(-11,26,8,minecraft:oak_leaves[distance=7,persistent=true])
B(-11,20,9,minecraft:oak_leaves[distance=6,persistent=false])
B(-11,26,9,minecraft:oak_leaves[distance=7,persistent=true])
B(-11,19,10,minecraft:oak_leaves[distance=4,persistent=false])
B(-11,20,10,minecraft:oak_leaves[distance=5,persistent=false])
B(-11,16,11,minecraft:oak_leaves[distance=7,persistent=true])
B(-11,17,11,minecraft:oak_leaves[distance=6,persistent=false])
B(-11,19,11,minecraft:oak_leaves[distance=4,persistent=false])
B(-11,20,11,minecraft:oak_leaves[distance=5,persistent=false])
B(-11,22,11,minecraft:oak_leaves[distance=4,persistent=false])
B(-11,17,12,minecraft:oak_leaves[distance=7,persistent=true])
B(-11,19,12,minecraft:oak_leaves[distance=5,persistent=false])
B(-11,23,12,minecraft:oak_leaves[distance=4,persistent=false])
B(-11,24,12,minecraft:oak_leaves[distance=5,persistent=false])
B(-11,24,13,minecraft:oak_leaves[distance=4,persistent=false])
B(-11,25,13,minecraft:oak_leaves[distance=5,persistent=false])
B(-11,25,14,minecraft:oak_leaves[distance=4,persistent=false])
B(-11,26,14,minecraft:oak_leaves[distance=5,persistent=false])
B(-11,26,15,minecraft:oak_leaves[distance=6,persistent=false])
B(-11,27,15,minecraft:oak_leaves[distance=7,persistent=true])
B(-11,26,16,minecraft:oak_leaves[distance=7,persistent=true])
B(-11,27,16,minecraft:oak_leaves[distance=7,persistent=true])
B(-11,26,17,minecraft:oak_leaves[distance=7,persistent=true])
B(-10,22,-19,minecraft:oak_leaves[distance=7,persistent=true])
B(-10,22,-18,minecraft:oak_leaves[distance=7,persistent=true])
B(-10,28,-18,minecraft:oak_leaves[distance=7,persistent=true])
B(-10,29,-18,minecraft:oak_leaves[distance=7,persistent=true])
B(-10,21,-17,minecraft:oak_leaves[distance=7,persistent=true])
B(-10,22,-17,minecraft:oak_leaves[distance=7,persistent=true])
B(-10,27,-17,minecraft:oak_leaves[distance=7,persistent=true])
B(-10,28,-17,minecraft:oak_leaves[distance=6,persistent=false])
B(-10,21,-16,minecraft:oak_leaves[distance=7,persistent=true])
B(-10,22,-16,minecraft:oak_leaves[distance=7,persistent=true])
B(-10,27,-16,minecraft:oak_leaves[distance=7,persistent=true])
B(-10,21,-15,minecraft:oak_leaves[distance=7,persistent=true])
B(-10,26,-15,minecraft:oak_leaves[distance=7,persistent=true])
B(-10,21,-14,minecraft:oak_leaves[distance=6,persistent=false])
B(-10,25,-14,minecraft:oak_leaves[distance=7,persistent=true])
B(-10,26,-14,minecraft:oak_leaves[distance=7,persistent=true])
B(-10,20,-13,minecraft:oak_leaves[distance=4,persistent=false])
B(-10,21,-13,minecraft:oak_leaves[distance=5,persistent=false])
B(-10,25,-13,minecraft:oak_leaves[distance=7,persistent=true])
B(-10,26,-13,minecraft:oak_leaves[distance=7,persistent=true])
B(-10,19,-12,minecraft:oak_leaves[distance=3,persistent=false])
B(-10,20,-12,minecraft:oak_leaves[distance=3,persistent=false])
B(-10,21,-12,minecraft:oak_leaves[distance=4,persistent=false])
B(-10,24,-12,minecraft:oak_leaves[distance=7,persistent=true])
B(-10,19,-11,minecraft:oak_leaves[distance=2,persistent=false])
B(-10,20,-11,minecraft:oak_leaves[distance=2,persistent=false])
B(-10,21,-11,minecraft:oak_leaves[distance=3,persistent=false])
B(-10,22,-11,minecraft:oak_leaves[distance=4,persistent=false])
B(-10,23,-11,minecraft:oak_leaves[distance=5,persistent=false])
B(-10,24,-11,minecraft:oak_leaves[distance=6,persistent=false])
B(-10,25,-11,minecraft:oak_leaves[distance=7,persistent=true])
B(-10,18,-10,minecraft:oak_leaves[distance=2,persistent=false])
B(-10,19,-10,minecraft:oak_leaves)
B(-10,20,-10,minecraft:oak_leaves)
B(-10,21,-10,minecraft:oak_leaves[distance=2,persistent=false])
B(-10,22,-10,minecraft:oak_leaves[distance=3,persistent=false])
B(-10,23,-10,minecraft:oak_leaves[distance=4,persistent=false])
B(-10,24,-10,minecraft:oak_leaves[distance=5,persistent=false])
B(-10,28,-10,minecraft:oak_leaves[distance=3,persistent=false])
B(-10,29,-10,minecraft:oak_leaves[distance=4,persistent=false])
B(-10,30,-10,minecraft:oak_leaves[distance=5,persistent=false])
B(-10,18,-9,minecraft:oak_leaves)
B(-10,19,-9,minecraft:oak_wood)
B(-10,20,-9,minecraft:oak_wood)
B(-10,26,-9,minecraft:oak_wood)
B(-10,27,-9,minecraft:oak_leaves)
B(-10,28,-9,minecraft:oak_leaves[distance=2,persistent=false])
B(-10,15,-8,minecraft:oak_leaves[distance=4,persistent=false])
B(-10,16,-8,minecraft:oak_leaves[distance=3,persistent=false])
B(-10,17,-8,minecraft:oak_leaves[distance=2,persistent=false])
B(-10,18,-8,minecraft:oak_leaves)
B(-10,19,-8,minecraft:oak_wood)
B(-10,20,-8,minecraft:oak_leaves)
B(-10,25,-8,minecraft:oak_wood)
B(-10,26,-8,minecraft:oak_wood)
B(-10,13,-7,minecraft:oak_leaves[distance=7,persistent=true])
B(-10,14,-7,minecraft:oak_leaves[distance=6,persistent=false])
B(-10,15,-7,minecraft:oak_leaves[distance=5,persistent=false])
B(-10,16,-7,minecraft:oak_leaves[distance=4,persistent=false])
B(-10,17,-7,minecraft:oak_leaves[distance=3,persistent=false])
B(-10,18,-7,minecraft:oak_leaves[distance=2,persistent=false])
B(-10,19,-7,minecraft:oak_leaves)
B(-10,20,-7,minecraft:oak_leaves[distance=2,persistent=false])
B(-10,21,-7,minecraft:oak_leaves[distance=2,persistent=false])
B(-10,22,-7,minecraft:oak_leaves[distance=3,persistent=false])
B(-10,24,-7,minecraft:oak_leaves[distance=7,persistent=true])
B(-10,26,-7,minecraft:oak_leaves)
B(-10,27,-7,minecraft:oak_leaves[distance=2,persistent=false])
B(-10,18,-6,minecraft:oak_leaves[distance=3,persistent=false])
B(-10,19,-6,minecraft:oak_leaves[distance=2,persistent=false])
B(-10,20,-6,minecraft:oak_leaves[distance=3,persistent=false])
B(-10,26,-6,minecraft:oak_leaves[distance=2,persistent=false])
B(-10,27,-6,minecraft:oak_leaves[distance=3,persistent=false])
B(-10,18,-5,minecraft:oak_leaves[distance=4,persistent=false])
B(-10,20,-5,minecraft:oak_leaves[distance=4,persistent=false])
B(-10,21,-5,minecraft:oak_leaves[distance=5,persistent=false])
B(-10,23,-5,minecraft:oak_leaves[distance=6,persistent=false])
B(-10,24,-5,minecraft:oak_leaves[distance=5,persistent=false])
B(-10,25,-5,minecraft:oak_leaves[distance=4,persistent=false])
B(-10,26,-5,minecraft:oak_leaves[distance=3,persistent=false])
B(-10,27,-5,minecraft:oak_leaves[distance=4,persistent=false])
B(-10,28,-5,minecraft:oak_leaves[distance=5,persistent=false])
B(-10,18,-4,minecraft:oak_leaves[distance=5,persistent=false])
B(-10,19,-4,minecraft:oak_leaves[distance=6,persistent=false])
B(-10,20,-4,minecraft:oak_leaves[distance=5,persistent=false])
B(-10,21,-4,minecraft:oak_leaves[distance=6,persistent=false])
B(-10,22,-4,minecraft:oak_leaves[distance=7,persistent=true])
B(-10,23,-4,minecraft:oak_leaves[distance=6,persistent=false])
B(-10,24,-4,minecraft:oak_leaves[distance=5,persistent=false])
B(-10,25,-4,minecraft:oak_leaves[distance=5,persistent=false])
B(-10,28,-4,minecraft:oak_leaves[distance=6,persistent=false])
B(-10,29,-4,minecraft:oak_leaves[distance=7,persistent=true])
B(-10,19,-3,minecraft:oak_leaves[distance=7,persistent=true])
B(-10,20,-3,minecraft:oak_leaves[distance=6,persistent=false])
B(-10,21,-3,minecraft:oak_leaves[distance=7,persistent=true])
B(-10,24,-3,minecraft:oak_leaves[distance=4,persistent=false])
B(-10,28,-3,minecraft:oak_leaves[distance=7,persistent=true])
B(-10,29,-3,minecraft:oak_leaves[distance=7,persistent=true])
B(-10,19,-2,minecraft:oak_leaves[distance=6,persistent=false])
B(-10,20,-2,minecraft:oak_leaves[distance=7,persistent=true])
B(-10,22,-2,minecraft:oak_leaves[distance=4,persistent=false])
B(-10,23,-2,minecraft:oak_leaves[distance=3,persistent=false])
B(-10,24,-2,minecraft:oak_leaves[distance=3,persistent=false])
B(-10,28,-2,minecraft:oak_leaves[distance=7,persistent=true])
B(-10,29,-2,minecraft:oak_leaves[distance=7,persistent=true])
B(-10,30,-2,minecraft:oak_leaves[distance=7,persistent=true])
B(-10,18,-1,minecraft:oak_leaves[distance=5,persistent=false])
B(-10,19,-1,minecraft:oak_leaves[distance=6,persistent=false])
B(-10,20,-1,minecraft:oak_leaves[distance=7,persistent=true])
B(-10,23,-1,minecraft:oak_leaves[distance=2,persistent=false])
B(-10,24,-1,minecraft:oak_leaves[distance=2,persistent=false])
B(-10,28,-1,minecraft:oak_leaves[distance=7,persistent=true])
B(-10,29,-1,minecraft:oak_leaves[distance=7,persistent=true])
B(-10,30,-1,minecraft:oak_leaves[distance=7,persistent=true])
B(-10,31,-1,minecraft:oak_leaves[distance=7,persistent=true])
B(-10,18,0,minecraft:oak_leaves[distance=6,persistent=false])
B(-10,19,0,minecraft:oak_leaves[distance=7,persistent=true])
B(-10,20,0,minecraft:oak_leaves[distance=7,persistent=true])
B(-10,22,0,minecraft:oak_leaves[distance=2,persistent=false])
B(-10,23,0,minecraft:oak_leaves)
B(-10,24,0,minecraft:oak_leaves)
B(-10,28,0,minecraft:oak_leaves[distance=7,persistent=true])
B(-10,29,0,minecraft:oak_leaves[distance=7,persistent=true])
B(-10,30,0,minecraft:oak_leaves[distance=7,persistent=true])
B(-10,19,1,minecraft:oak_leaves[distance=6,persistent=false])
B(-10,23,1,minecraft:oak_leaves)
B(-10,24,1,minecraft:oak_wood)
B(-10,28,1,minecraft:oak_leaves[distance=6,persistent=false])
B(-10,29,1,minecraft:oak_leaves[distance=7,persistent=true])
B(-10,30,1,minecraft:oak_leaves[distance=7,persistent=true])
B(-10,19,2,minecraft:oak_leaves[distance=6,persistent=false])
B(-10,20,2,minecraft:oak_leaves[distance=5,persistent=false])
B(-10,21,2,minecraft:oak_leaves[distance=4,persistent=false])
B(-10,22,2,minecraft:oak_leaves[distance=3,persistent=false])
B(-10,24,2,minecraft:oak_leaves)
B(-10,25,2,minecraft:oak_leaves[distance=2,persistent=false])
B(-10,26,2,minecraft:oak_leaves[distance=3,persistent=false])
B(-10,27,2,minecraft:oak_leaves[distance=4,persistent=false])
B(-10,28,2,minecraft:oak_leaves[distance=5,persistent=false])
B(-10,29,2,minecraft:oak_leaves[distance=6,persistent=false])
B(-10,20,3,minecraft:oak_leaves[distance=6,persistent=false])
B(-10,21,3,minecraft:oak_leaves[distance=5,persistent=false])
B(-10,22,3,minecraft:oak_leaves[distance=4,persistent=false])
B(-10,23,3,minecraft:oak_leaves[distance=3,persistent=false])
B(-10,25,3,minecraft:oak_leaves[distance=3,persistent=false])
B(-10,28,3,minecraft:oak_leaves[distance=4,persistent=false])
B(-10,29,3,minecraft:oak_leaves[distance=5,persistent=false])
B(-10,20,4,minecraft:oak_leaves[distance=7,persistent=true])
B(-10,23,4,minecraft:oak_leaves[distance=4,persistent=false])
B(-10,28,4,minecraft:oak_leaves[distance=5,persistent=false])
B(-10,29,4,minecraft:oak_leaves[distance=6,persistent=false])
B(-10,30,4,minecraft:oak_leaves[distance=7,persistent=true])
B(-10,20,5,minecraft:oak_leaves[distance=6,persistent=false])
B(-10,24,5,minecraft:oak_leaves[distance=6,persistent=false])
B(-10,30,5,minecraft:oak_leaves[distance=7,persistent=true])
B(-10,31,5,minecraft:oak_leaves[distance=7,persistent=true])
B(-10,19,6,minecraft:oak_leaves[distance=5,persistent=false])
B(-10,20,6,minecraft:oak_leaves[distance=6,persistent=false])
B(-10,21,6,minecraft:oak_leaves[distance=7,persistent=true])
B(-10,24,6,minecraft:oak_leaves[distance=7,persistent=true])
B(-10,25,6,minecraft:oak_leaves[distance=7,persistent=true])
B(-10,18,7,minecraft:oak_leaves[distance=4,persistent=false])
B(-10,19,7,minecraft:oak_leaves[distance=5,persistent=false])
B(-10,20,7,minecraft:oak_leaves[distance=6,persistent=false])
B(-10,25,7,minecraft:oak_leaves[distance=7,persistent=true])
B(-10,19,8,minecraft:oak_leaves[distance=5,persistent=false])
B(-10,20,8,minecraft:oak_leaves[distance=6,persistent=false])
B(-10,26,8,minecraft:oak_leaves[distance=7,persistent=true])
B(-10,19,9,minecraft:oak_leaves[distance=4,persistent=false])
B(-10,26,9,minecraft:oak_leaves[distance=7,persistent=true])
B(-10,15,10,minecraft:oak_leaves[distance=7,persistent=true])
B(-10,16,10,minecraft:oak_leaves[distance=6,persistent=false])
B(-10,17,10,minecraft:oak_leaves[distance=5,persistent=false])
B(-10,19,10,minecraft:oak_leaves[distance=3,persistent=false])
B(-10,17,11,minecraft:oak_leaves[distance=5,persistent=false])
B(-10,18,11,minecraft:oak_leaves[distance=4,persistent=false])
B(-10,19,11,minecraft:oak_leaves[distance=3,persistent=false])
B(-10,22,11,minecraft:oak_leaves[distance=3,persistent=false])
B(-10,19,12,minecraft:oak_leaves[distance=4,persistent=false])
B(-10,23,12,minecraft:oak_leaves[distance=3,persistent=false])
B(-10,24,13,minecraft:oak_leaves[distance=3,persistent=false])
B(-10,25,13,minecraft:oak_leaves[distance=4,persistent=false])
B(-10,22,14,minecraft:oak_leaves[distance=2,persistent=false])
B(-10,24,14,minecraft:oak_leaves[distance=2,persistent=false])
B(-10,25,14,minecraft:oak_leaves[distance=3,persistent=false])
B(-10,26,14,minecraft:oak_leaves[distance=4,persistent=false])
B(-10,27,14,minecraft:oak_leaves[distance=5,persistent=false])
B(-10,28,14,minecraft:oak_leaves[distance=6,persistent=false])
B(-10,22,15,minecraft:oak_leaves[distance=3,persistent=false])
B(-10,23,15,minecraft:oak_leaves[distance=2,persistent=false])
B(-10,24,15,minecraft:oak_leaves[distance=3,persistent=false])
B(-10,25,15,minecraft:oak_leaves[distance=4,persistent=false])
B(-10,23,16,minecraft:oak_leaves[distance=3,persistent=false])
B(-10,24,16,minecraft:oak_leaves[distance=4,persistent=false])
B(-10,25,16,minecraft:oak_leaves[distance=5,persistent=false])
B(-9,30,-22,minecraft:oak_leaves[distance=7,persistent=true])
B(-9,30,-21,minecraft:oak_leaves[distance=7,persistent=true])
B(-9,30,-20,minecraft:oak_leaves[distance=7,persistent=true])
B(-9,29,-19,minecraft:oak_leaves[distance=6,persistent=false])
B(-9,30,-19,minecraft:oak_leaves[distance=7,persistent=true])
B(-9,34,-19,minecraft:oak_leaves[distance=7,persistent=true])
B(-9,21,-18,minecraft:oak_leaves[distance=7,persistent=true])
B(-9,28,-18,minecraft:oak_leaves[distance=6,persistent=false])
B(-9,29,-18,minecraft:oak_leaves[distance=7,persistent=true])
B(-9,33,-18,minecraft:oak_leaves[distance=7,persistent=true])
B(-9,21,-17,minecraft:oak_leaves[distance=7,persistent=true])
B(-9,28,-17,minecraft:oak_leaves[distance=5,persistent=false])
B(-9,33,-17,minecraft:oak_leaves[distance=7,persistent=true])
B(-9,20,-16,minecraft:oak_leaves[distance=7,persistent=true])
B(-9,21,-16,minecraft:oak_leaves[distance=7,persistent=true])
B(-9,27,-16,minecraft:oak_leaves[distance=7,persistent=true])
B(-9,29,-16,minecraft:oak_leaves[distance=7,persistent=true])
B(-9,32,-16,minecraft:oak_leaves[distance=7,persistent=true])
B(-9,20,-15,minecraft:oak_leaves[distance=7,persistent=true])
B(-9,21,-15,minecraft:oak_leaves[distance=7,persistent=true])
B(-9,26,-15,minecraft:oak_leaves[distance=6,persistent=false])
B(-9,20,-14,minecraft:oak_leaves[distance=6,persistent=false])
B(-9,25,-14,minecraft:oak_leaves[distance=7,persistent=true])
B(-9,26,-14,minecraft:oak_leaves[distance=6,persistent=false])
B(-9,29,-14,minecraft:oak_leaves[distance=6,persistent=false])
B(-9,30,-14,minecraft:oak_leaves[distance=7,persistent=true])
B(-9,20,-13,minecraft:oak_leaves[distance=5,persistent=false])
B(-9,25,-13,minecraft:oak_leaves[distance=6,persistent=false])
B(-9,28,-13,minecraft:oak_leaves[distance=7,persistent=true])
B(-9,29,-13,minecraft:oak_leaves[distance=7,persistent=true])
B(-9,19,-12,minecraft:oak_leaves[distance=4,persistent=false])
B(-9,20,-12,minecraft:oak_leaves[distance=4,persistent=false])
B(-9,28,-12,minecraft:oak_leaves[distance=7,persistent=true])
B(-9,19,-11,minecraft:oak_leaves[distance=3,persistent=false])
B(-9,20,-11,minecraft:oak_leaves[distance=3,persistent=false])
B(-9,28,-11,minecraft:oak_leaves[distance=7,persistent=true])
B(-9,18,-10,minecraft:oak_leaves[distance=2,persistent=false])
B(-9,19,-10,minecraft:oak_leaves[distance=2,persistent=false])
B(-9,30,-10,minecraft:oak_leaves[distance=6,persistent=false])
B(-9,18,-9,minecraft:oak_leaves)
B(-9,19,-9,minecraft:oak_leaves)
B(-9,20,-9,minecraft:oak_leaves)
B(-9,26,-9,minecraft:oak_leaves)
B(-9,27,-9,minecraft:oak_leaves[distance=2,persistent=false])
B(-9,28,-9,minecraft:oak_leaves[distance=3,persistent=false])
B(-9,29,-9,minecraft:oak_leaves[distance=4,persistent=false])
B(-9,30,-9,minecraft:oak_leaves[distance=5,persistent=false])
B(-9,31,-9,minecraft:oak_leaves[distance=6,persistent=false])
B(-9,17,-8,minecraft:oak_leaves)
B(-9,18,-8,minecraft:oak_wood)
B(-9,19,-8,minecraft:oak_wood)
B(-9,20,-8,minecraft:oak_wood)
B(-9,24,-8,minecraft:oak_wood)
B(-9,25,-8,minecraft:oak_leaves)
B(-9,26,-8,minecraft:oak_leaves)
B(-9,27,-8,minecraft:oak_leaves[distance=2,persistent=false])
B(-9,31,-8,minecraft:oak_leaves[distance=7,persistent=true])
B(-9,32,-8,minecraft:oak_leaves[distance=7,persistent=true])
B(-9,13,-7,minecraft:oak_leaves[distance=6,persistent=false])
B(-9,14,-7,minecraft:oak_leaves[distance=5,persistent=false])
B(-9,15,-7,minecraft:oak_leaves[distance=4,persistent=false])
B(-9,16,-7,minecraft:oak_leaves[distance=3,persistent=false])
B(-9,17,-7,minecraft:oak_leaves[distance=2,persistent=false])
B(-9,18,-7,minecraft:oak_leaves)
B(-9,19,-7,minecraft:oak_leaves)
B(-9,20,-7,minecraft:oak_leaves)
B(-9,21,-7,minecraft:oak_leaves)
B(-9,26,-7,minecraft:oak_leaves[distance=2,persistent=false])
B(-9,32,-7,minecraft:oak_leaves[distance=7,persistent=true])
B(-9,33,-7,minecraft:oak_leaves[distance=7,persistent=true])
B(-9,17,-6,minecraft:oak_leaves[distance=3,persistent=false])
B(-9,18,-6,minecraft:oak_leaves[distance=2,persistent=false])
B(-9,19,-6,minecraft:oak_leaves[distance=2,persistent=false])
B(-9,25,-6,minecraft:oak_leaves[distance=4,persistent=false])
B(-9,26,-6,minecraft:oak_leaves[distance=3,persistent=false])
B(-9,27,-6,minecraft:oak_leaves[distance=4,persistent=false])
B(-9,33,-6,minecraft:oak_leaves[distance=7,persistent=true])
B(-9,18,-5,minecraft:oak_leaves[distance=3,persistent=false])
B(-9,19,-5,minecraft:oak_leaves[distance=3,persistent=false])
B(-9,20,-5,minecraft:oak_leaves[distance=4,persistent=false])
B(-9,21,-5,minecraft:oak_leaves[distance=5,persistent=false])
B(-9,22,-5,minecraft:oak_leaves[distance=4,persistent=false])
B(-9,23,-5,minecraft:oak_leaves[distance=5,persistent=false])
B(-9,24,-5,minecraft:oak_leaves[distance=6,persistent=false])
B(-9,25,-5,minecraft:oak_leaves[distance=5,persistent=false])
B(-9,27,-5,minecraft:oak_leaves[distance=5,persistent=false])
B(-9,35,-5,minecraft:oak_leaves[distance=7,persistent=true])
B(-9,36,-5,minecraft:oak_leaves[distance=7,persistent=true])
B(-9,18,-3,minecraft:oak_leaves[distance=7,persistent=true])
B(-9,19,-3,minecraft:oak_leaves[distance=6,persistent=false])
B(-9,20,-3,minecraft:oak_leaves[distance=7,persistent=true])
B(-9,24,-3,minecraft:oak_leaves[distance=5,persistent=false])
B(-9,27,-3,minecraft:oak_leaves[distance=7,persistent=true])
B(-9,28,-3,minecraft:oak_leaves[distance=7,persistent=true])
B(-9,29,-3,minecraft:oak_leaves[distance=7,persistent=true])
B(-9,19,-2,minecraft:oak_leaves[distance=5,persistent=false])
B(-9,23,-2,minecraft:oak_leaves[distance=2,persistent=false])
B(-9,26,-2,minecraft:oak_leaves[distance=6,persistent=false])
B(-9,27,-2,minecraft:oak_leaves[distance=7,persistent=true])
B(-9,29,-2,minecraft:oak_leaves[distance=7,persistent=true])
B(-9,18,-1,minecraft:oak_leaves[distance=4,persistent=false])
B(-9,19,-1,minecraft:oak_leaves[distance=5,persistent=false])
B(-9,22,-1,minecraft:oak_leaves[distance=2,persistent=false])
B(-9,23,-1,minecraft:oak_leaves)
B(-9,26,-1,minecraft:oak_leaves[distance=5,persistent=false])
B(-9,27,-1,minecraft:oak_leaves[distance=6,persistent=false])
B(-9,29,-1,minecraft:oak_leaves[distance=7,persistent=true])
B(-9,30,-1,minecraft:oak_leaves[distance=7,persistent=true])
B(-9,31,-1,minecraft:oak_leaves[distance=7,persistent=true])
B(-9,32,-1,minecraft:oak_leaves[distance=7,persistent=true])
B(-9,18,0,minecraft:oak_leaves[distance=5,persistent=false])
B(-9,19,0,minecraft:oak_leaves[distance=6,persistent=false])
B(-9,22,0,minecraft:oak_leaves)
B(-9,23,0,minecraft:oak_wood)
B(-9,24,0,minecraft:oak_wood)
B(-9,26,0,minecraft:oak_leaves[distance=4,persistent=false])
B(-9,27,0,minecraft:oak_leaves[distance=5,persistent=false])
B(-9,29,0,minecraft:oak_leaves[distance=7,persistent=true])
B(-9,19,1,minecraft:oak_leaves[distance=5,persistent=false])
B(-9,20,1,minecraft:oak_leaves[distance=4,persistent=false])
B(-9,22,1,minecraft:oak_leaves)
B(-9,23,1,minecraft:oak_wood)
B(-9,24,1,minecraft:oak_leaves)
B(-9,25,1,minecraft:oak_leaves[distance=2,persistent=false])
B(-9,26,1,minecraft:oak_leaves[distance=3,persistent=false])
B(-9,27,1,minecraft:oak_leaves[distance=4,persistent=false])
B(-9,28,1,minecraft:oak_leaves[distance=5,persistent=false])
B(-9,29,1,minecraft:oak_leaves[distance=6,persistent=false])
B(-9,19,2,minecraft:oak_leaves[distance=5,persistent=false])
B(-9,20,2,minecraft:oak_leaves[distance=4,persistent=false])
B(-9,21,2,minecraft:oak_leaves[distance=3,persistent=false])
B(-9,22,2,minecraft:oak_leaves[distance=2,persistent=false])
B(-9,24,2,minecraft:oak_leaves[distance=2,persistent=false])
B(-9,26,2,minecraft:oak_leaves[distance=4,persistent=false])
B(-9,27,2,minecraft:oak_leaves[distance=5,persistent=false])
B(-9,28,2,minecraft:oak_leaves[distance=6,persistent=false])
B(-9,29,2,minecraft:oak_leaves[distance=7,persistent=true])
B(-9,19,3,minecraft:oak_leaves[distance=6,persistent=false])
B(-9,20,3,minecraft:oak_leaves[distance=5,persistent=false])
B(-9,22,3,minecraft:oak_leaves[distance=3,persistent=false])
B(-9,23,3,minecraft:oak_leaves[distance=4,persistent=false])
B(-9,24,3,minecraft:oak_leaves[distance=3,persistent=false])
B(-9,28,3,minecraft:oak_leaves[distance=5,persistent=false])
B(-9,29,3,minecraft:oak_leaves[distance=6,persistent=false])
B(-9,20,4,minecraft:oak_leaves[distance=6,persistent=false])
B(-9,23,4,minecraft:oak_leaves[distance=5,persistent=false])
B(-9,24,4,minecraft:oak_leaves[distance=4,persistent=false])
B(-9,25,4,minecraft:oak_leaves[distance=5,persistent=false])
B(-9,27,4,minecraft:oak_leaves[distance=7,persistent=true])
B(-9,28,4,minecraft:oak_leaves[distance=6,persistent=false])
B(-9,29,4,minecraft:oak_leaves[distance=7,persistent=true])
B(-9,30,4,minecraft:oak_leaves[distance=7,persistent=true])
B(-9,19,5,minecraft:oak_leaves[distance=4,persistent=false])
B(-9,20,5,minecraft:oak_leaves[distance=5,persistent=false])
B(-9,24,5,minecraft:oak_leaves[distance=5,persistent=false])
B(-9,25,5,minecraft:oak_leaves[distance=6,persistent=false])
B(-9,26,5,minecraft:oak_leaves[distance=7,persistent=true])
B(-9,30,5,minecraft:oak_leaves[distance=7,persistent=true])
B(-9,31,5,minecraft:oak_leaves[distance=7,persistent=true])
B(-9,18,6,minecraft:oak_leaves[distance=3,persistent=false])
B(-9,19,6,minecraft:oak_leaves[distance=4,persistent=false])
B(-9,21,6,minecraft:oak_leaves[distance=7,persistent=true])
B(-9,24,6,minecraft:oak_leaves[distance=6,persistent=false])
B(-9,25,6,minecraft:oak_leaves[distance=7,persistent=true])
B(-9,26,6,minecraft:oak_leaves[distance=7,persistent=true])
B(-9,27,6,minecraft:oak_leaves[distance=7,persistent=true])
B(-9,31,6,minecraft:oak_leaves[distance=7,persistent=true])
B(-9,17,7,minecraft:oak_leaves[distance=4,persistent=false])
B(-9,18,7,minecraft:oak_leaves[distance=3,persistent=false])
B(-9,19,7,minecraft:oak_leaves[distance=4,persistent=false])
B(-9,25,7,minecraft:oak_leaves[distance=7,persistent=true])
B(-9,27,7,minecraft:oak_leaves[distance=7,persistent=true])
B(-9,19,8,minecraft:oak_leaves[distance=4,persistent=false])
B(-9,26,8,minecraft:oak_leaves[distance=7,persistent=true])
B(-9,15,9,minecraft:oak_leaves[distance=6,persistent=false])
B(-9,16,9,minecraft:oak_leaves[distance=5,persistent=false])
B(-9,17,9,minecraft:oak_leaves[distance=4,persistent=false])
B(-9,18,9,minecraft:oak_leaves[distance=3,persistent=false])
B(-9,19,9,minecraft:oak_leaves[distance=3,persistent=false])
B(-9,16,10,minecraft:oak_leaves[distance=5,persistent=false])
B(-9,17,10,minecraft:oak_leaves[distance=4,persistent=false])
B(-9,18,10,minecraft:oak_leaves[distance=3,persistent=false])
B(-9,19,10,minecraft:oak_leaves[distance=2,persistent=false])
B(-9,19,11,minecraft:oak_leaves[distance=2,persistent=false])
B(-9,22,11,minecraft:oak_leaves[distance=2,persistent=false])
B(-9,23,11,minecraft:oak_leaves[distance=3,persistent=false])
B(-9,24,11,minecraft:oak_leaves[distance=4,persistent=false])
B(-9,25,11,minecraft:oak_leaves[distance=5,persistent=false])
B(-9,26,11,minecraft:oak_leaves[distance=6,persistent=false])
B(-9,19,12,minecraft:oak_leaves[distance=3,persistent=false])
B(-9,21,12,minecraft:oak_leaves[distance=2,persistent=false])
B(-9,22,12,minecraft:oak_leaves)
B(-9,23,12,minecraft:oak_leaves[distance=2,persistent=false])
B(-9,24,12,minecraft:oak_leaves[distance=3,persistent=false])
B(-9,25,12,minecraft:oak_leaves[distance=4,persistent=false])
B(-9,26,12,minecraft:oak_leaves[distance=5,persistent=false])
B(-9,20,13,minecraft:oak_leaves[distance=3,persistent=false])
B(-9,23,13,minecraft:oak_leaves)
B(-9,24,13,minecraft:oak_leaves[distance=2,persistent=false])
B(-9,25,13,minecraft:oak_leaves[distance=3,persistent=false])
B(-9,26,13,minecraft:oak_leaves[distance=4,persistent=false])
B(-9,27,13,minecraft:oak_leaves[distance=5,persistent=false])
B(-9,22,14,minecraft:oak_leaves)
B(-9,23,14,minecraft:oak_wood)
B(-9,24,14,minecraft:oak_leaves)
B(-9,27,14,minecraft:oak_leaves[distance=6,persistent=false])
B(-9,28,14,minecraft:oak_leaves[distance=7,persistent=true])
B(-9,22,15,minecraft:oak_leaves[distance=2,persistent=false])
B(-9,23,15,minecraft:oak_leaves)
B(-9,24,15,minecraft:oak_leaves[distance=2,persistent=false])
B(-9,23,16,minecraft:oak_leaves[distance=2,persistent=false])
B(-9,24,16,minecraft:oak_leaves[distance=3,persistent=false])
B(-9,23,17,minecraft:oak_leaves[distance=3,persistent=false])
B(-9,24,17,minecraft:oak_leaves[distance=4,persistent=false])
B(-8,30,-22,minecraft:oak_leaves[distance=7,persistent=true])
B(-8,29,-21,minecraft:oak_leaves[distance=7,persistent=true])
B(-8,30,-21,minecraft:oak_leaves[distance=7,persistent=true])
B(-8,29,-20,minecraft:oak_leaves[distance=6,persistent=false])
B(-8,30,-20,minecraft:oak_leaves[distance=7,persistent=true])
B(-8,34,-20,minecraft:oak_leaves[distance=7,persistent=true])
B(-8,29,-19,minecraft:oak_leaves[distance=5,persistent=false])
B(-8,30,-19,minecraft:oak_leaves[distance=6,persistent=false])
B(-8,31,-19,minecraft:oak_leaves[distance=7,persistent=true])
B(-8,32,-19,minecraft:oak_leaves[distance=7,persistent=true])
B(-8,33,-19,minecraft:oak_leaves[distance=7,persistent=true])
B(-8,34,-19,minecraft:oak_leaves[distance=7,persistent=true])
B(-8,28,-18,minecraft:oak_leaves[distance=5,persistent=false])
B(-8,29,-18,minecraft:oak_leaves[distance=6,persistent=false])
B(-8,30,-18,minecraft:oak_leaves[distance=7,persistent=true])
B(-8,31,-18,minecraft:oak_leaves[distance=7,persistent=true])
B(-8,32,-18,minecraft:oak_leaves[distance=7,persistent=true])
B(-8,33,-18,minecraft:oak_leaves[distance=7,persistent=true])
B(-8,20,-17,minecraft:oak_leaves[distance=7,persistent=true])
B(-8,28,-17,minecraft:oak_leaves[distance=4,persistent=false])
B(-8,32,-17,minecraft:oak_leaves[distance=7,persistent=true])
B(-8,33,-17,minecraft:oak_leaves[distance=7,persistent=true])
B(-8,20,-16,minecraft:oak_leaves[distance=7,persistent=true])
B(-8,23,-16,minecraft:oak_leaves[distance=7,persistent=true])
B(-8,27,-16,minecraft:oak_leaves[distance=6,persistent=false])
B(-8,28,-16,minecraft:oak_leaves[distance=5,persistent=false])
B(-8,31,-16,minecraft:oak_leaves[distance=6,persistent=false])
B(-8,32,-16,minecraft:oak_leaves[distance=7,persistent=true])
B(-8,20,-15,minecraft:oak_leaves[distance=7,persistent=true])
B(-8,26,-15,minecraft:oak_leaves[distance=5,persistent=false])
B(-8,27,-15,minecraft:oak_leaves[distance=5,persistent=false])
B(-8,28,-15,minecraft:oak_leaves[distance=6,persistent=false])
B(-8,29,-15,minecraft:oak_leaves[distance=6,persistent=false])
B(-8,20,-14,minecraft:oak_leaves[distance=7,persistent=true])
B(-8,25,-14,minecraft:oak_leaves[distance=6,persistent=false])
B(-8,26,-14,minecraft:oak_leaves[distance=5,persistent=false])
B(-8,28,-14,minecraft:oak_leaves[distance=5,persistent=false])
B(-8,29,-14,minecraft:oak_leaves[distance=5,persistent=false])
B(-8,30,-14,minecraft:oak_leaves[distance=6,persistent=false])
B(-8,19,-13,minecraft:oak_leaves[distance=6,persistent=false])
B(-8,25,-13,minecraft:oak_leaves[distance=5,persistent=false])
B(-8,28,-13,minecraft:oak_leaves[distance=6,persistent=false])
B(-8,19,-12,minecraft:oak_leaves[distance=5,persistent=false])
B(-8,27,-12,minecraft:oak_leaves[distance=6,persistent=false])
B(-8,28,-12,minecraft:oak_leaves[distance=7,persistent=true])
B(-8,18,-11,minecraft:oak_leaves[distance=3,persistent=false])
B(-8,19,-11,minecraft:oak_leaves[distance=4,persistent=false])
B(-8,27,-11,minecraft:oak_leaves[distance=7,persistent=true])
B(-8,18,-10,minecraft:oak_leaves[distance=2,persistent=false])
B(-8,18,-9,minecraft:oak_leaves)
B(-8,28,-9,minecraft:oak_leaves[distance=4,persistent=false])
B(-8,29,-9,minecraft:oak_leaves[distance=5,persistent=false])
B(-8,30,-9,minecraft:oak_leaves[distance=6,persistent=false])
B(-8,31,-9,minecraft:oak_leaves[distance=7,persistent=true])
B(-8,17,-8,minecraft:oak_leaves)
B(-8,18,-8,minecraft:oak_wood)
B(-8,19,-8,minecraft:oak_wood)
B(-8,20,-8,minecraft:oak_wood)
B(-8,21,-8,minecraft:oak_wood)
B(-8,23,-8,minecraft:oak_wood)
B(-8,24,-8,minecraft:oak_leaves)
B(-8,25,-8,minecraft:oak_leaves[distance=2,persistent=false])
B(-8,26,-8,minecraft:oak_leaves[distance=2,persistent=false])
B(-8,27,-8,minecraft:oak_leaves[distance=3,persistent=false])
B(-8,28,-8,minecraft:oak_leaves[distance=4,persistent=false])
B(-8,29,-8,minecraft:oak_leaves[distance=5,persistent=false])
B(-8,31,-8,minecraft:oak_leaves[distance=7,persistent=true])
B(-8,32,-8,minecraft:oak_leaves[distance=7,persistent=true])
B(-8,14,-7,minecraft:oak_leaves[distance=4,persistent=false])
B(-8,15,-7,minecraft:oak_leaves[distance=3,persistent=false])
B(-8,16,-7,minecraft:oak_leaves[distance=2,persistent=false])
B(-8,17,-7,minecraft:oak_leaves)
B(-8,18,-7,minecraft:oak_wood)
B(-8,19,-7,minecraft:oak_wood)
B(-8,20,-7,minecraft:oak_wood)
B(-8,21,-7,minecraft:oak_wood)
B(-8,22,-7,minecraft:oak_wood)
B(-8,23,-7,minecraft:oak_wood)
B(-8,24,-7,minecraft:oak_leaves)
B(-8,25,-7,minecraft:oak_leaves[distance=2,persistent=false])
B(-8,26,-7,minecraft:oak_leaves[distance=3,persistent=false])
B(-8,32,-7,minecraft:oak_leaves[distance=7,persistent=true])
B(-8,33,-7,minecraft:oak_leaves[distance=7,persistent=true])
B(-8,36,-7,minecraft:oak_leaves[distance=7,persistent=true])
B(-8,37,-7,minecraft:oak_leaves[distance=7,persistent=true])
B(-8,17,-6,minecraft:oak_leaves[distance=2,persistent=false])
B(-8,18,-6,minecraft:oak_leaves)
B(-8,19,-6,minecraft:oak_leaves)
B(-8,25,-6,minecraft:oak_leaves[distance=3,persistent=false])
B(-8,26,-6,minecraft:oak_leaves[distance=4,persistent=false])
B(-8,33,-6,minecraft:oak_leaves[distance=7,persistent=true])
B(-8,35,-6,minecraft:oak_leaves[distance=7,persistent=true])
B(-8,36,-6,minecraft:oak_leaves[distance=7,persistent=true])
B(-8,17,-5,minecraft:oak_leaves[distance=3,persistent=false])
B(-8,18,-5,minecraft:oak_leaves[distance=2,persistent=false])
B(-8,19,-5,minecraft:oak_leaves[distance=2,persistent=false])
B(-8,20,-5,minecraft:oak_leaves[distance=3,persistent=false])
B(-8,21,-5,minecraft:oak_leaves[distance=4,persistent=false])
B(-8,22,-5,minecraft:oak_leaves[distance=3,persistent=false])
B(-8,23,-5,minecraft:oak_leaves[distance=4,persistent=false])
B(-8,24,-5,minecraft:oak_leaves[distance=5,persistent=false])
B(-8,25,-5,minecraft:oak_leaves[distance=4,persistent=false])
B(-8,26,-5,minecraft:oak_leaves[distance=5,persistent=false])
B(-8,27,-5,minecraft:oak_leaves[distance=6,persistent=false])
B(-8,34,-5,minecraft:oak_leaves[distance=7,persistent=true])
B(-8,35,-5,minecraft:oak_leaves[distance=7,persistent=true])
B(-8,18,-4,minecraft:oak_leaves[distance=3,persistent=false])
B(-8,19,-4,minecraft:oak_leaves[distance=3,persistent=false])
B(-8,24,-4,minecraft:oak_leaves[distance=6,persistent=false])
B(-8,27,-4,minecraft:oak_leaves[distance=7,persistent=true])
B(-8,33,-4,minecraft:oak_leaves[distance=7,persistent=true])
B(-8,34,-4,minecraft:oak_leaves[distance=7,persistent=true])
B(-8,17,-2,minecraft:oak_leaves[distance=4,persistent=false])
B(-8,18,-2,minecraft:oak_leaves[distance=3,persistent=false])
B(-8,19,-2,minecraft:oak_leaves[distance=4,persistent=false])
B(-8,23,-2,minecraft:oak_leaves)
B(-8,26,-2,minecraft:oak_leaves[distance=5,persistent=false])
B(-8,28,-2,minecraft:oak_leaves[distance=7,persistent=true])
B(-8,29,-2,minecraft:oak_leaves[distance=7,persistent=true])
B(-8,30,-2,minecraft:oak_leaves[distance=7,persistent=true])
B(-8,31,-2,minecraft:oak_leaves[distance=7,persistent=true])
B(-8,18,-1,minecraft:oak_leaves[distance=3,persistent=false])
B(-8,19,-1,minecraft:oak_leaves[distance=4,persistent=false])
B(-8,22,-1,minecraft:oak_leaves)
B(-8,23,-1,minecraft:oak_wood)
B(-8,25,-1,minecraft:oak_leaves[distance=3,persistent=false])
B(-8,26,-1,minecraft:oak_leaves[distance=4,persistent=false])
B(-8,28,-1,minecraft:oak_leaves[distance=7,persistent=true])
B(-8,29,-1,minecraft:oak_leaves[distance=7,persistent=true])
B(-8,30,-1,minecraft:oak_leaves[distance=7,persistent=true])
B(-8,31,-1,minecraft:oak_leaves[distance=7,persistent=true])
B(-8,32,-1,minecraft:oak_leaves[distance=7,persistent=true])
B(-8,33,-1,minecraft:oak_leaves[distance=7,persistent=true])
B(-8,18,0,minecraft:oak_leaves[distance=4,persistent=false])
B(-8,22,0,minecraft:oak_leaves)
B(-8,23,0,minecraft:oak_wood)
B(-8,24,0,minecraft:oak_leaves)
B(-8,25,0,minecraft:oak_leaves[distance=2,persistent=false])
B(-8,26,0,minecraft:oak_leaves[distance=3,persistent=false])
B(-8,28,0,minecraft:oak_leaves[distance=6,persistent=false])
B(-8,18,1,minecraft:oak_leaves[distance=5,persistent=false])
B(-8,19,1,minecraft:oak_leaves[distance=4,persistent=false])
B(-8,20,1,minecraft:oak_leaves[distance=3,persistent=false])
B(-8,21,1,minecraft:oak_leaves[distance=2,persistent=false])
B(-8,22,1,minecraft:oak_leaves)
B(-8,23,1,minecraft:oak_wood)
B(-8,24,1,minecraft:oak_leaves)
B(-8,25,1,minecraft:oak_leaves[distance=2,persistent=false])
B(-8,26,1,minecraft:oak_leaves[distance=3,persistent=false])
B(-8,27,1,minecraft:oak_leaves[distance=4,persistent=false])
B(-8,28,1,minecraft:oak_leaves[distance=5,persistent=false])
B(-8,30,1,minecraft:oak_leaves[distance=7,persistent=true])
B(-8,18,2,minecraft:oak_leaves[distance=5,persistent=false])
B(-8,19,2,minecraft:oak_leaves[distance=5,persistent=false])
B(-8,20,2,minecraft:oak_leaves[distance=4,persistent=false])
B(-8,22,2,minecraft:oak_leaves[distance=2,persistent=false])
B(-8,26,2,minecraft:oak_leaves[distance=4,persistent=false])
B(-8,27,2,minecraft:oak_leaves[distance=5,persistent=false])
B(-8,28,2,minecraft:oak_leaves[distance=6,persistent=false])
B(-8,30,2,minecraft:oak_leaves[distance=7,persistent=true])
B(-8,31,2,minecraft:oak_leaves[distance=7,persistent=true])
B(-8,18,3,minecraft:oak_leaves[distance=4,persistent=false])
B(-8,19,3,minecraft:oak_leaves[distance=5,persistent=false])
B(-8,21,3,minecraft:oak_leaves[distance=4,persistent=false])
B(-8,22,3,minecraft:oak_leaves[distance=3,persistent=false])
B(-8,23,3,minecraft:oak_leaves[distance=4,persistent=false])
B(-8,27,3,minecraft:oak_leaves[distance=6,persistent=false])
B(-8,28,3,minecraft:oak_leaves[distance=6,persistent=false])
B(-8,31,3,minecraft:oak_leaves[distance=7,persistent=true])
B(-8,18,4,minecraft:oak_leaves[distance=3,persistent=false])
B(-8,19,4,minecraft:oak_leaves[distance=4,persistent=false])
B(-8,22,4,minecraft:oak_leaves[distance=4,persistent=false])
B(-8,23,4,minecraft:oak_leaves[distance=5,persistent=false])
B(-8,24,4,minecraft:oak_leaves[distance=5,persistent=false])
B(-8,27,4,minecraft:oak_leaves[distance=7,persistent=true])
B(-8,28,4,minecraft:oak_leaves[distance=7,persistent=true])
B(-8,29,4,minecraft:oak_leaves[distance=7,persistent=true])
B(-8,31,4,minecraft:oak_leaves[distance=7,persistent=true])
B(-8,32,4,minecraft:oak_leaves[distance=7,persistent=true])
B(-8,18,5,minecraft:oak_leaves[distance=2,persistent=false])
B(-8,19,5,minecraft:oak_leaves[distance=3,persistent=false])
B(-8,20,5,minecraft:oak_leaves[distance=4,persistent=false])
B(-8,21,5,minecraft:oak_leaves[distance=5,persistent=false])
B(-8,23,5,minecraft:oak_leaves[distance=6,persistent=false])
B(-8,24,5,minecraft:oak_leaves[distance=6,persistent=false])
B(-8,25,5,minecraft:oak_leaves[distance=7,persistent=true])
B(-8,29,5,minecraft:oak_leaves[distance=7,persistent=true])
B(-8,30,5,minecraft:oak_leaves[distance=7,persistent=true])
B(-8,32,5,minecraft:oak_leaves[distance=7,persistent=true])
B(-8,17,6,minecraft:oak_leaves[distance=3,persistent=false])
B(-8,18,6,minecraft:oak_leaves[distance=2,persistent=false])
B(-8,19,6,minecraft:oak_leaves[distance=3,persistent=false])
B(-8,21,6,minecraft:oak_leaves[distance=6,persistent=false])
B(-8,24,6,minecraft:oak_leaves[distance=7,persistent=true])
B(-8,25,6,minecraft:oak_leaves[distance=7,persistent=true])
B(-8,26,6,minecraft:oak_leaves[distance=7,persistent=true])
B(-8,31,6,minecraft:oak_leaves[distance=7,persistent=true])
B(-8,32,6,minecraft:oak_leaves[distance=7,persistent=true])
B(-8,16,7,minecraft:oak_leaves[distance=4,persistent=false])
B(-8,17,7,minecraft:oak_leaves[distance=3,persistent=false])
B(-8,18,7,minecraft:oak_leaves[distance=2,persistent=false])
B(-8,19,7,minecraft:oak_leaves[distance=3,persistent=false])
B(-8,25,7,minecraft:oak_leaves[distance=7,persistent=true])
B(-8,26,7,minecraft:oak_leaves[distance=7,persistent=true])
B(-8,27,7,minecraft:oak_leaves[distance=7,persistent=true])
B(-8,15,8,minecraft:oak_leaves[distance=5,persistent=false])
B(-8,16,8,minecraft:oak_leaves[distance=4,persistent=false])
B(-8,17,8,minecraft:oak_leaves[distance=3,persistent=false])
B(-8,18,8,minecraft:oak_leaves[distance=2,persistent=false])
B(-8,26,8,minecraft:oak_leaves[distance=7,persistent=true])
B(-8,27,8,minecraft:oak_leaves[distance=7,persistent=true])
B(-8,28,8,minecraft:oak_leaves[distance=7,persistent=true])
B(-8,16,9,minecraft:oak_leaves[distance=4,persistent=false])
B(-8,17,9,minecraft:oak_leaves[distance=3,persistent=false])
B(-8,18,9,minecraft:oak_leaves[distance=2,persistent=false])
B(-8,25,9,minecraft:oak_leaves[distance=6,persistent=false])
B(-8,27,9,minecraft:oak_leaves[distance=7,persistent=true])
B(-8,18,10,minecraft:oak_leaves[distance=2,persistent=false])
B(-8,19,10,minecraft:oak_leaves)
B(-8,20,10,minecraft:oak_wood)
B(-8,21,10,minecraft:oak_leaves)
B(-8,22,10,minecraft:oak_leaves[distance=2,persistent=false])
B(-8,23,10,minecraft:oak_leaves[distance=3,persistent=false])
B(-8,24,10,minecraft:oak_leaves[distance=4,persistent=false])
B(-8,25,10,minecraft:oak_leaves[distance=5,persistent=false])
B(-8,19,11,minecraft:oak_leaves)
B(-8,20,11,minecraft:oak_wood)
B(-8,21,11,minecraft:oak_wood)
B(-8,22,11,minecraft:oak_leaves)
B(-8,23,11,minecraft:oak_leaves[distance=2,persistent=false])
B(-8,24,11,minecraft:oak_leaves[distance=3,persistent=false])
B(-8,25,11,minecraft:oak_leaves[distance=4,persistent=false])
B(-8,26,11,minecraft:oak_leaves[distance=5,persistent=false])
B(-8,19,12,minecraft:oak_leaves[distance=2,persistent=false])
B(-8,20,12,minecraft:oak_leaves)
B(-8,21,12,minecraft:oak_leaves)
B(-8,22,12,minecraft:oak_wood)
B(-8,23,12,minecraft:oak_leaves)
B(-8,24,12,minecraft:oak_leaves[distance=2,persistent=false])
B(-8,25,12,minecraft:oak_leaves[distance=3,persistent=false])
B(-8,20,13,minecraft:oak_leaves[distance=2,persistent=false])
B(-8,21,13,minecraft:oak_leaves[distance=2,persistent=false])
B(-8,22,13,minecraft:oak_leaves)
B(-8,23,13,minecraft:oak_wood)
B(-8,25,13,minecraft:oak_leaves[distance=4,persistent=false])
B(-8,26,13,minecraft:oak_leaves[distance=5,persistent=false])
B(-8,27,13,minecraft:oak_leaves[distance=6,persistent=false])
B(-8,22,14,minecraft:oak_leaves[distance=2,persistent=false])
B(-8,22,15,minecraft:oak_leaves[distance=3,persistent=false])
B(-8,23,16,minecraft:oak_leaves[distance=3,persistent=false])
B(-8,23,17,minecraft:oak_leaves[distance=4,persistent=false])
B(-7,29,-22,minecraft:oak_leaves[distance=7,persistent=true])
B(-7,34,-22,minecraft:oak_leaves[distance=7,persistent=true])
B(-7,29,-21,minecraft:oak_leaves[distance=6,persistent=false])
B(-7,34,-21,minecraft:oak_leaves[distance=7,persistent=true])
B(-7,25,-20,minecraft:oak_leaves[distance=7,persistent=true])
B(-7,28,-20,minecraft:oak_leaves[distance=6,persistent=false])
B(-7,29,-20,minecraft:oak_leaves[distance=5,persistent=false])
B(-7,33,-20,minecraft:oak_leaves[distance=7,persistent=true])
B(-7,34,-20,minecraft:oak_leaves[distance=7,persistent=true])
B(-7,24,-19,minecraft:oak_leaves[distance=7,persistent=true])
B(-7,25,-19,minecraft:oak_leaves[distance=7,persistent=true])
B(-7,28,-19,minecraft:oak_leaves[distance=5,persistent=false])
B(-7,29,-19,minecraft:oak_leaves[distance=4,persistent=false])
B(-7,33,-19,minecraft:oak_leaves[distance=7,persistent=true])
B(-7,24,-18,minecraft:oak_leaves[distance=7,persistent=true])
B(-7,28,-18,minecraft:oak_leaves[distance=4,persistent=false])
B(-7,29,-18,minecraft:oak_leaves[distance=5,persistent=false])
B(-7,32,-18,minecraft:oak_leaves[distance=6,persistent=false])
B(-7,33,-18,minecraft:oak_leaves[distance=7,persistent=true])
B(-7,23,-17,minecraft:oak_leaves[distance=7,persistent=true])
B(-7,24,-17,minecraft:oak_leaves[distance=7,persistent=true])
B(-7,27,-17,minecraft:oak_leaves[distance=4,persistent=false])
B(-7,28,-17,minecraft:oak_leaves[distance=3,persistent=false])
B(-7,29,-17,minecraft:oak_leaves[distance=4,persistent=false])
B(-7,30,-17,minecraft:oak_leaves[distance=5,persistent=false])
B(-7,31,-17,minecraft:oak_leaves[distance=6,persistent=false])
B(-7,32,-17,minecraft:oak_leaves[distance=7,persistent=true])
B(-7,23,-16,minecraft:oak_leaves[distance=7,persistent=true])
B(-7,27,-16,minecraft:oak_leaves[distance=5,persistent=false])
B(-7,28,-16,minecraft:oak_leaves[distance=4,persistent=false])
B(-7,29,-16,minecraft:oak_leaves[distance=3,persistent=false])
B(-7,30,-16,minecraft:oak_leaves[distance=4,persistent=false])
B(-7,31,-16,minecraft:oak_leaves[distance=5,persistent=false])
B(-7,23,-15,minecraft:oak_leaves[distance=6,persistent=false])
B(-7,26,-15,minecraft:oak_leaves[distance=4,persistent=false])
B(-7,27,-15,minecraft:oak_leaves[distance=4,persistent=false])
B(-7,28,-15,minecraft:oak_leaves[distance=5,persistent=false])
B(-7,19,-14,minecraft:oak_leaves[distance=7,persistent=true])
B(-7,22,-14,minecraft:oak_leaves[distance=6,persistent=false])
B(-7,25,-14,minecraft:oak_leaves[distance=5,persistent=false])
B(-7,26,-14,minecraft:oak_leaves[distance=4,persistent=false])
B(-7,28,-14,minecraft:oak_leaves[distance=4,persistent=false])
B(-7,29,-14,minecraft:oak_leaves[distance=4,persistent=false])
B(-7,30,-14,minecraft:oak_leaves[distance=5,persistent=false])
B(-7,19,-13,minecraft:oak_leaves[distance=6,persistent=false])
B(-7,25,-13,minecraft:oak_leaves[distance=4,persistent=false])
B(-7,27,-13,minecraft:oak_leaves[distance=4,persistent=false])
B(-7,28,-13,minecraft:oak_leaves[distance=5,persistent=false])
B(-7,18,-12,minecraft:oak_leaves[distance=4,persistent=false])
B(-7,19,-12,minecraft:oak_leaves[distance=5,persistent=false])
B(-7,24,-12,minecraft:oak_leaves[distance=5,persistent=false])
B(-7,27,-12,minecraft:oak_leaves[distance=5,persistent=false])
