
#######################################################################
# +-----------------------------------------------------------------+ #
# |                            BO3 object                           | #
# +-----------------------------------------------------------------+ #
#######################################################################

Author: Bo3 BulkEdit

Description: Converted Schematic - Modified by Bo3BulkEdit

Version: 3

SettingsMode: WriteWithoutComments


#######################################################################
# +-----------------------------------------------------------------+ #
# |                          Main settings                          | #
# +-----------------------------------------------------------------+ #
#######################################################################

Tree: true

Frequency: 1

Rarity: 100.0

RotateRandomly: true

SpawnHeight: randomY

SpawnHeightOffset: 0

SpawnHeightVariance: 0

##############################
# Height Limits for the BO3. #
##############################

MinHeight: 65

MaxHeight: 70

######################
# Extrusion settings #
######################

ExtrudeMode: None

ExtrudeThroughBlocks: minecraft:air

MaxBranchDepth: 10


#######################################################################
# +-----------------------------------------------------------------+ #
# |                      Source block settings                      | #
# +-----------------------------------------------------------------+ #
#######################################################################

SourceBlocks: otg:air,otg:dirt,otg:stone,minecraft:grass_block

MaxPercentageOutsideSourceBlock: 0

OutsideSourceBlock: placeAnyway

DoReplaceBlocks: true

IsOTGPlus: false


#######################################################################
# +-----------------------------------------------------------------+ #
# |                              Blocks                             | #
# +-----------------------------------------------------------------+ #
#######################################################################

B(-6,-23,-4,minecraft:birch_fence)
B(-6,-22,-4,minecraft:birch_fence)
B(-6,-21,-4,minecraft:birch_fence[east=true,north=false,south=false,waterlogged=false,west=false])
B(-5,-21,-4,minecraft:birch_fence[east=false,north=false,south=false,waterlogged=false,west=true])
B(-5,-20,-4,minecraft:birch_fence[east=false,north=false,south=true,waterlogged=false,west=false])
B(-5,-20,-3,minecraft:birch_fence[east=true,north=true,south=false,waterlogged=false,west=false])
B(-5,-25,-2,minecraft:oak_leaves[distance=2,persistent=false])
B(-5,-24,-2,minecraft:oak_leaves[distance=3,persistent=false])
B(-4,-25,-3,minecraft:oak_leaves[distance=2,persistent=false])
B(-4,-24,-3,minecraft:oak_leaves[distance=3,persistent=false])
B(-4,-20,-3,minecraft:birch_fence[east=false,north=false,south=false,waterlogged=false,west=true])
B(-4,-19,-3,minecraft:birch_fence[east=false,north=false,south=true,waterlogged=false,west=false])
B(-4,-26,-2,minecraft:oak_leaves[distance=2,persistent=false])
B(-4,-25,-2,minecraft:oak_leaves)
B(-4,-24,-2,minecraft:oak_leaves[distance=2,persistent=false])
B(-4,-23,-2,minecraft:oak_leaves)
B(-4,-19,-2,minecraft:birch_fence[east=true,north=true,south=false,waterlogged=false,west=false])
B(-4,-25,-1,minecraft:oak_leaves[distance=2,persistent=false])
B(-4,-24,-1,minecraft:oak_leaves[distance=3,persistent=false])
B(-4,-18,-1,minecraft:oak_button[face=wall,facing=west,powered=false])
B(-4,-17,-1,minecraft:oak_stairs[facing=east,half=top,shape=straight,waterlogged=false])
B(-4,-16,-1,minecraft:dark_oak_slab)
B(-3,-25,-4,minecraft:oak_leaves[distance=2,persistent=false])
B(-3,-24,-4,minecraft:oak_leaves[distance=3,persistent=false])
B(-3,-26,-3,minecraft:oak_leaves[distance=2,persistent=false])
B(-3,-25,-3,minecraft:oak_leaves)
B(-3,-24,-3,minecraft:oak_leaves[distance=2,persistent=false])
B(-3,-23,-3,minecraft:oak_leaves)
B(-3,-26,-2,minecraft:oak_leaves)
B(-3,-25,-2,minecraft:spruce_wood)
B(-3,-24,-2,minecraft:sea_lantern)
B(-3,-23,-2,minecraft:spruce_wood)
B(-3,-22,-2,minecraft:spruce_wood)
B(-3,-21,-2,minecraft:oak_log)
B(-3,-20,-2,minecraft:oak_log)
B(-3,-19,-2,minecraft:spruce_wood)
B(-3,-18,-2,minecraft:oak_button)
B(-3,-26,-1,minecraft:oak_leaves[distance=2,persistent=false])
B(-3,-25,-1,minecraft:oak_leaves)
B(-3,-24,-1,minecraft:oak_leaves[distance=2,persistent=false])
B(-3,-23,-1,minecraft:oak_leaves)
B(-3,-19,-1,minecraft:spruce_wood)
B(-3,-18,-1,minecraft:spruce_wood)
B(-3,-17,-1,minecraft:spruce_wood)
B(-3,-16,-1,minecraft:spruce_wood)
B(-3,-15,-1,minecraft:spruce_wood)
B(-3,-14,-1,minecraft:birch_fence[east=true,north=false,south=false,waterlogged=false,west=false])
B(-3,-25,0,minecraft:oak_leaves[distance=2,persistent=false])
B(-3,-24,0,minecraft:oak_leaves[distance=3,persistent=false])
B(-3,-18,0,minecraft:oak_button[face=wall,facing=south,powered=false])
B(-3,-15,0,minecraft:birch_fence[east=true,north=true,south=true,waterlogged=false,west=false])
B(-3,-17,1,minecraft:birch_fence)
B(-3,-16,1,minecraft:birch_fence)
B(-3,-15,1,minecraft:birch_fence[east=false,north=true,south=false,waterlogged=false,west=false])
B(-2,-25,-3,minecraft:oak_leaves[distance=2,persistent=false])
B(-2,-24,-3,minecraft:oak_leaves[distance=3,persistent=false])
B(-2,-26,-2,minecraft:oak_leaves[distance=2,persistent=false])
B(-2,-25,-2,minecraft:oak_leaves)
B(-2,-24,-2,minecraft:oak_leaves[distance=2,persistent=false])
B(-2,-23,-2,minecraft:oak_leaves)
B(-2,-25,-1,minecraft:oak_leaves[distance=2,persistent=false])
B(-2,-24,-1,minecraft:oak_leaves[distance=3,persistent=false])
B(-2,-18,-1,minecraft:oak_button[face=wall,facing=east,powered=false])
B(-2,-15,-1,minecraft:spruce_wood)
B(-2,-14,-1,minecraft:birch_fence[east=false,north=false,south=true,waterlogged=false,west=true])
B(-2,-13,-1,minecraft:birch_fence[east=false,north=false,south=true,waterlogged=false,west=false])
B(-2,-15,0,minecraft:spruce_wood)
B(-2,-14,0,minecraft:spruce_wood)
B(-2,-13,0,minecraft:oak_log)
B(-2,-12,0,minecraft:oak_log)
B(-2,-11,0,minecraft:oak_log)
B(-2,-10,0,minecraft:spruce_wood)
B(-2,-9,0,minecraft:dark_oak_slab)
B(-2,-28,3,minecraft:oak_leaves[distance=2,persistent=false])
B(-2,-27,3,minecraft:oak_leaves[distance=3,persistent=false])
B(-1,-25,-2,minecraft:oak_leaves[distance=2,persistent=false])
B(-1,-24,-2,minecraft:oak_leaves[distance=3,persistent=false])
B(-1,-9,-1,minecraft:birch_fence[east=true,north=false,south=true,waterlogged=false,west=false])
B(-1,-8,-1,minecraft:birch_fence[east=true,north=false,south=true,waterlogged=false,west=false])
B(-1,-10,0,minecraft:spruce_wood)
B(-1,-9,0,minecraft:spruce_wood)
B(-1,-8,0,minecraft:spruce_wood)
B(-1,-28,2,minecraft:oak_leaves[distance=2,persistent=false])
B(-1,-27,2,minecraft:oak_leaves[distance=3,persistent=false])
B(-1,-20,2,minecraft:oak_button[face=wall,facing=west,powered=false])
B(-1,-19,2,minecraft:birch_fence[east=true,north=false,south=false,waterlogged=false,west=false])
B(-1,-18,2,minecraft:birch_fence[east=true,north=false,south=false,waterlogged=false,west=false])
B(-1,-17,2,minecraft:birch_fence[east=true,north=false,south=false,waterlogged=false,west=false])
B(-1,-29,3,minecraft:oak_leaves[distance=2,persistent=false])
B(-1,-28,3,minecraft:oak_leaves)
B(-1,-27,3,minecraft:oak_leaves[distance=2,persistent=false])
B(-1,-26,3,minecraft:oak_leaves)
B(-1,-28,4,minecraft:oak_leaves[distance=2,persistent=false])
B(-1,-27,4,minecraft:oak_leaves[distance=3,persistent=false])
B(0,-18,-6,minecraft:birch_fence[east=false,north=false,south=true,waterlogged=false,west=false])
B(0,-18,-5,minecraft:birch_fence[east=false,north=true,south=false,waterlogged=false,west=false])
B(0,-17,-5,minecraft:birch_fence)
B(0,-16,-5,minecraft:birch_fence[east=false,north=false,south=true,waterlogged=false,west=false])
B(0,-16,-4,minecraft:birch_fence[east=false,north=true,south=false,waterlogged=false,west=false])
B(0,-15,-4,minecraft:birch_fence[east=false,north=false,south=true,waterlogged=false,west=false])
B(0,-15,-3,minecraft:birch_fence[east=true,north=true,south=false,waterlogged=false,west=false])
B(0,-11,-1,minecraft:spruce_wood)
B(0,-10,-1,minecraft:spruce_wood)
B(0,-9,-1,minecraft:spruce_wood)
B(0,-8,-1,minecraft:spruce_wood)
B(0,-8,0,minecraft:spruce_wood)
B(0,-7,0,minecraft:spruce_wood)
B(0,-6,0,minecraft:oak_log)
B(0,-5,0,minecraft:oak_log)
B(0,-4,0,minecraft:oak_log)
B(0,-3,0,minecraft:spruce_wood)
B(0,-2,0,minecraft:spruce_wood)
B(0,-1,0,minecraft:spruce_wood)
B(0,0,0,minecraft:spruce_wood)
B(0,-28,1,minecraft:oak_leaves[distance=2,persistent=false])
B(0,-27,1,minecraft:oak_leaves[distance=3,persistent=false])
B(0,-20,1,minecraft:oak_button)
B(0,-17,1,minecraft:spruce_wood)
B(0,-16,1,minecraft:spruce_wood)
B(0,-15,1,minecraft:spruce_wood)
B(0,-14,1,minecraft:spruce_wood)
B(0,-13,1,minecraft:spruce_wood)
B(0,-12,1,minecraft:spruce_wood)
B(0,-11,1,minecraft:spruce_wood)
B(0,-10,1,minecraft:oak_log)
B(0,-9,1,minecraft:oak_log)
B(0,-8,1,minecraft:dark_oak_stairs)
B(0,-29,2,minecraft:oak_leaves[distance=2,persistent=false])
B(0,-28,2,minecraft:oak_leaves)
B(0,-27,2,minecraft:oak_leaves[distance=2,persistent=false])
B(0,-26,2,minecraft:oak_leaves)
B(0,-22,2,minecraft:spruce_wood)
B(0,-21,2,minecraft:spruce_wood)
B(0,-20,2,minecraft:spruce_wood)
B(0,-19,2,minecraft:spruce_wood)
B(0,-18,2,minecraft:spruce_wood)
B(0,-17,2,minecraft:spruce_wood)
B(0,-16,2,minecraft:birch_fence[east=false,north=true,south=false,waterlogged=false,west=false])
B(0,-13,2,minecraft:dark_oak_stairs[facing=north,half=top,shape=straight,waterlogged=false])
B(0,-12,2,minecraft:birch_fence[east=false,north=true,south=true,waterlogged=false,west=false])
B(0,-29,3,minecraft:oak_leaves)
B(0,-28,3,minecraft:spruce_wood)
B(0,-27,3,minecraft:sea_lantern)
B(0,-26,3,minecraft:spruce_wood)
B(0,-25,3,minecraft:oak_log)
B(0,-24,3,minecraft:oak_log)
B(0,-23,3,minecraft:spruce_wood)
B(0,-22,3,minecraft:spruce_wood)
B(0,-21,3,minecraft:birch_fence[east=false,north=true,south=false,waterlogged=false,west=false])
B(0,-20,3,minecraft:oak_button[face=wall,facing=south,powered=false])
B(0,-12,3,minecraft:birch_fence[east=false,north=true,south=true,waterlogged=false,west=false])
B(0,-29,4,minecraft:oak_leaves[distance=2,persistent=false])
B(0,-28,4,minecraft:oak_leaves)
B(0,-27,4,minecraft:oak_leaves[distance=2,persistent=false])
B(0,-26,4,minecraft:oak_leaves)
B(0,-23,4,minecraft:birch_fence[east=true,north=true,south=false,waterlogged=false,west=false])
B(0,-22,4,minecraft:birch_fence[east=false,north=true,south=false,waterlogged=false,west=false])
B(0,-14,4,minecraft:birch_fence[east=false,north=false,south=true,waterlogged=false,west=false])
B(0,-13,4,minecraft:birch_fence)
B(0,-12,4,minecraft:birch_fence[east=false,north=true,south=false,waterlogged=false,west=false])
B(0,-28,5,minecraft:oak_leaves[distance=2,persistent=false])
B(0,-27,5,minecraft:oak_leaves[distance=3,persistent=false])
B(0,-14,5,minecraft:birch_fence[east=false,north=true,south=false,waterlogged=false,west=false])
B(1,-32,-3,minecraft:oak_leaves[distance=2,persistent=false])
B(1,-31,-3,minecraft:oak_leaves[distance=3,persistent=false])
B(1,-25,-3,minecraft:birch_fence[east=true,north=false,south=false,waterlogged=false,west=false])
B(1,-24,-3,minecraft:birch_fence[east=true,north=false,south=false,waterlogged=false,west=false])
B(1,-23,-3,minecraft:birch_fence[east=true,north=false,south=false,waterlogged=false,west=false])
B(1,-22,-3,minecraft:birch_fence[east=true,north=false,south=false,waterlogged=false,west=false])
B(1,-19,-3,minecraft:spruce_wood)
B(1,-15,-3,minecraft:birch_fence[east=false,north=false,south=true,waterlogged=false,west=true])
B(1,-19,-2,minecraft:spruce_wood)
B(1,-18,-2,minecraft:spruce_wood)
B(1,-17,-2,minecraft:spruce_wood)
B(1,-16,-2,minecraft:spruce_wood)
B(1,-15,-2,minecraft:spruce_wood)
B(1,-14,-2,minecraft:spruce_wood)
B(1,-14,-1,minecraft:spruce_wood)
B(1,-13,-1,minecraft:spruce_wood)
B(1,-12,-1,minecraft:spruce_wood)
B(1,-11,-1,minecraft:spruce_wood)
B(1,-10,-1,minecraft:birch_fence[east=false,north=false,south=false,waterlogged=false,west=true])
B(1,-9,-1,minecraft:birch_fence[east=false,north=false,south=false,waterlogged=false,west=true])
B(1,-8,-1,minecraft:birch_fence[east=false,north=false,south=true,waterlogged=false,west=true])
B(1,-7,-1,minecraft:birch_fence[east=false,north=false,south=true,waterlogged=false,west=false])
B(1,-8,0,minecraft:spruce_wood)
B(1,-7,0,minecraft:spruce_wood)
B(1,-6,0,minecraft:dark_oak_stairs[facing=west,half=bottom,shape=straight,waterlogged=false])
B(1,-28,2,minecraft:oak_leaves[distance=2,persistent=false])
B(1,-27,2,minecraft:oak_leaves[distance=3,persistent=false])
B(1,-20,2,minecraft:oak_button[face=wall,facing=east,powered=false])
B(1,-29,3,minecraft:oak_leaves[distance=2,persistent=false])
B(1,-28,3,minecraft:oak_leaves)
B(1,-27,3,minecraft:oak_leaves[distance=2,persistent=false])
B(1,-26,3,minecraft:oak_leaves)
B(1,-24,3,minecraft:birch_fence[east=false,north=false,south=false,waterlogged=false,west=true])
B(1,-23,3,minecraft:birch_fence[east=false,north=false,south=true,waterlogged=false,west=true])
B(1,-28,4,minecraft:oak_leaves[distance=2,persistent=false])
B(1,-27,4,minecraft:oak_leaves[distance=3,persistent=false])
B(1,-23,4,minecraft:birch_fence[east=false,north=true,south=false,waterlogged=false,west=true])
B(2,-32,-4,minecraft:oak_leaves[distance=2,persistent=false])
B(2,-31,-4,minecraft:oak_leaves[distance=3,persistent=false])
B(2,-24,-4,minecraft:oak_button)
B(2,-22,-4,minecraft:oak_stairs[facing=south,half=top,shape=straight,waterlogged=false])
B(2,-21,-4,minecraft:dark_oak_slab)
B(2,-33,-3,minecraft:oak_leaves[distance=2,persistent=false])
B(2,-32,-3,minecraft:oak_leaves)
B(2,-31,-3,minecraft:oak_leaves[distance=2,persistent=false])
B(2,-30,-3,minecraft:oak_leaves)
B(2,-27,-3,minecraft:spruce_wood)
B(2,-26,-3,minecraft:spruce_wood)
B(2,-25,-3,minecraft:spruce_wood)
B(2,-24,-3,minecraft:spruce_wood)
B(2,-23,-3,minecraft:oak_log)
B(2,-22,-3,minecraft:oak_log)
B(2,-21,-3,minecraft:oak_log)
B(2,-20,-3,minecraft:spruce_wood)
B(2,-19,-3,minecraft:spruce_wood)
B(2,-32,-2,minecraft:oak_leaves[distance=2,persistent=false])
B(2,-31,-2,minecraft:oak_leaves[distance=3,persistent=false])
B(2,-24,-2,minecraft:oak_button[face=wall,facing=south,powered=false])
B(2,-8,0,minecraft:spruce_wood)
B(2,-14,1,minecraft:oak_button[face=wall,facing=west,powered=false])
B(2,-13,1,minecraft:spruce_wood)
B(2,-12,1,minecraft:spruce_wood)
B(2,-11,1,minecraft:spruce_wood)
B(2,-10,1,minecraft:spruce_wood)
B(2,-9,1,minecraft:spruce_wood)
B(2,-8,1,minecraft:spruce_wood)
B(2,-22,2,minecraft:oak_leaves[distance=2,persistent=false])
B(2,-21,2,minecraft:oak_leaves[distance=3,persistent=false])
B(2,-28,3,minecraft:oak_leaves[distance=2,persistent=false])
B(2,-27,3,minecraft:oak_leaves[distance=3,persistent=false])
B(3,-32,-5,minecraft:oak_leaves[distance=2,persistent=false])
B(3,-31,-5,minecraft:oak_leaves[distance=3,persistent=false])
B(3,-33,-4,minecraft:oak_leaves[distance=2,persistent=false])
B(3,-32,-4,minecraft:oak_leaves)
B(3,-31,-4,minecraft:oak_leaves[distance=2,persistent=false])
B(3,-30,-4,minecraft:oak_leaves)
B(3,-33,-3,minecraft:oak_leaves)
B(3,-32,-3,minecraft:spruce_wood)
B(3,-31,-3,minecraft:sea_lantern)
B(3,-30,-3,minecraft:spruce_wood)
B(3,-29,-3,minecraft:spruce_wood)
B(3,-28,-3,minecraft:spruce_wood)
B(3,-27,-3,minecraft:spruce_wood)
B(3,-24,-3,minecraft:oak_button[face=wall,facing=east,powered=false])
B(3,-33,-2,minecraft:oak_leaves[distance=2,persistent=false])
B(3,-32,-2,minecraft:oak_leaves)
B(3,-31,-2,minecraft:oak_leaves[distance=2,persistent=false])
B(3,-30,-2,minecraft:oak_leaves)
B(3,-32,-1,minecraft:oak_leaves[distance=2,persistent=false])
B(3,-31,-1,minecraft:oak_leaves[distance=3,persistent=false])
B(3,-14,0,minecraft:oak_button)
B(3,-22,1,minecraft:oak_leaves[distance=2,persistent=false])
B(3,-21,1,minecraft:oak_leaves[distance=3,persistent=false])
B(3,-17,1,minecraft:spruce_wood)
B(3,-16,1,minecraft:oak_log)
B(3,-15,1,minecraft:oak_log)
B(3,-14,1,minecraft:spruce_wood)
B(3,-13,1,minecraft:spruce_wood)
B(3,-12,1,minecraft:birch_fence[east=false,north=false,south=false,waterlogged=false,west=true])
B(3,-11,1,minecraft:birch_fence[east=false,north=false,south=false,waterlogged=false,west=true])
B(3,-10,1,minecraft:birch_fence[east=false,north=false,south=false,waterlogged=false,west=true])
B(3,-23,2,minecraft:oak_leaves[distance=2,persistent=false])
B(3,-22,2,minecraft:oak_leaves)
B(3,-21,2,minecraft:oak_leaves[distance=2,persistent=false])
B(3,-20,2,minecraft:oak_leaves)
B(3,-14,2,minecraft:oak_button[face=wall,facing=south,powered=false])
B(3,-22,3,minecraft:oak_leaves[distance=2,persistent=false])
B(3,-21,3,minecraft:oak_leaves[distance=3,persistent=false])
B(4,-32,-4,minecraft:oak_leaves[distance=2,persistent=false])
B(4,-31,-4,minecraft:oak_leaves[distance=3,persistent=false])
B(4,-33,-3,minecraft:oak_leaves[distance=2,persistent=false])
B(4,-32,-3,minecraft:oak_leaves)
B(4,-31,-3,minecraft:oak_leaves[distance=2,persistent=false])
B(4,-30,-3,minecraft:oak_leaves)
B(4,-32,-2,minecraft:oak_leaves[distance=2,persistent=false])
B(4,-31,-2,minecraft:oak_leaves[distance=3,persistent=false])
B(4,-22,0,minecraft:oak_leaves[distance=2,persistent=false])
B(4,-21,0,minecraft:oak_leaves[distance=3,persistent=false])
B(4,-23,1,minecraft:oak_leaves[distance=2,persistent=false])
B(4,-22,1,minecraft:oak_leaves)
B(4,-21,1,minecraft:oak_leaves[distance=2,persistent=false])
B(4,-20,1,minecraft:oak_leaves)
B(4,-17,1,minecraft:spruce_wood)
B(4,-16,1,minecraft:birch_fence[east=true,north=false,south=false,waterlogged=false,west=true])
B(4,-14,1,minecraft:oak_button[face=wall,facing=east,powered=false])
B(4,-23,2,minecraft:oak_leaves)
B(4,-22,2,minecraft:spruce_wood)
B(4,-21,2,minecraft:sea_lantern)
B(4,-20,2,minecraft:spruce_wood)
B(4,-19,2,minecraft:spruce_wood)
B(4,-18,2,minecraft:spruce_wood)
B(4,-17,2,minecraft:spruce_wood)
B(4,-23,3,minecraft:oak_leaves[distance=2,persistent=false])
B(4,-22,3,minecraft:oak_leaves)
B(4,-21,3,minecraft:oak_leaves[distance=2,persistent=false])
B(4,-20,3,minecraft:oak_leaves)
B(4,-22,4,minecraft:oak_leaves[distance=2,persistent=false])
B(4,-21,4,minecraft:oak_leaves[distance=3,persistent=false])
B(5,-32,-3,minecraft:oak_leaves[distance=2,persistent=false])
B(5,-31,-3,minecraft:oak_leaves[distance=3,persistent=false])
B(5,-22,1,minecraft:oak_leaves[distance=2,persistent=false])
B(5,-21,1,minecraft:oak_leaves[distance=3,persistent=false])
B(5,-17,1,minecraft:birch_fence[east=false,north=false,south=true,waterlogged=false,west=true])
B(5,-16,1,minecraft:birch_fence[east=false,north=false,south=false,waterlogged=false,west=true])
B(5,-23,2,minecraft:oak_leaves[distance=2,persistent=false])
B(5,-22,2,minecraft:oak_leaves)
B(5,-21,2,minecraft:oak_leaves[distance=2,persistent=false])
B(5,-20,2,minecraft:oak_leaves)
B(5,-18,2,minecraft:birch_fence[east=false,north=false,south=false,waterlogged=false,west=true])
B(5,-17,2,minecraft:birch_fence[east=false,north=true,south=false,waterlogged=false,west=true])
B(5,-22,3,minecraft:oak_leaves[distance=2,persistent=false])
B(5,-21,3,minecraft:oak_leaves[distance=3,persistent=false])
B(6,-22,2,minecraft:oak_leaves[distance=2,persistent=false])
B(6,-21,2,minecraft:oak_leaves[distance=3,persistent=false])

#######################################################################
# +-----------------------------------------------------------------+ #
# |                            BO3 checks                           | #
# +-----------------------------------------------------------------+ #
#######################################################################

BlockCheck(0,0,0,otg:stone)

#######################################################################
# +-----------------------------------------------------------------+ #
# |                             Branches                            | #
# +-----------------------------------------------------------------+ #
#######################################################################


#######################################################################
# +-----------------------------------------------------------------+ #
# |                             Entities                            | #
# +-----------------------------------------------------------------+ #
#######################################################################

