
#######################################################################
# +-----------------------------------------------------------------+ #
# |                            BO3 object                           | #
# +-----------------------------------------------------------------+ #
#######################################################################

Author: NLBlackEagle

Description: No description given

Version: 3

SettingsMode: WriteWithoutComments


#######################################################################
# +-----------------------------------------------------------------+ #
# |                          Main settings                          | #
# +-----------------------------------------------------------------+ #
#######################################################################

Tree: false

Frequency: 50

Rarity: 100.0

RotateRandomly: true

SpawnHeight: randomY

SpawnHeightOffset: 0

SpawnHeightVariance: 0

##############################
# Height Limits for the BO3. #
##############################

MinHeight: 50

MaxHeight: 100

######################
# Extrusion settings #
######################

ExtrudeMode: None

ExtrudeThroughBlocks: otg:air

MaxBranchDepth: 10


#######################################################################
# +-----------------------------------------------------------------+ #
# |                      Source block settings                      | #
# +-----------------------------------------------------------------+ #
#######################################################################

SourceBlocks: otg:air,otg:dirt,minecraft:sand,minecraft:grass_block

MaxPercentageOutsideSourceBlock: 45

OutsideSourceBlock: dontPlace

DoReplaceBlocks: true

IsOTGPlus: false


#######################################################################
# +-----------------------------------------------------------------+ #
# |                              Blocks                             | #
# +-----------------------------------------------------------------+ #
#######################################################################

B(-13,0,-12,minecraft:jungle_log[axis=x])
B(-12,0,-13,minecraft:jungle_log[axis=x])
B(-12,0,-12,minecraft:jungle_log[axis=z])
B(-12,1,-12,minecraft:jungle_log[axis=z])
B(-12,0,-11,minecraft:jungle_log[axis=z])
B(-12,0,0,minecraft:jungle_log[axis=z])
B(-12,0,11,minecraft:jungle_log[axis=z])
B(-12,0,12,minecraft:jungle_log[axis=x])
B(-12,0,13,minecraft:jungle_log[axis=z])
B(-11,0,-12,minecraft:jungle_log)
B(-11,0,-11,minecraft:jungle_log[axis=z])
B(-11,0,-3,minecraft:jungle_log[axis=z])
B(-11,1,-3,minecraft:jungle_log[axis=z])
B(-11,0,-2,minecraft:jungle_log[axis=z])
B(-11,0,-1,minecraft:jungle_log[axis=x])
B(-11,0,10,minecraft:jungle_log[axis=x])
B(-11,0,11,minecraft:jungle_log[axis=z])
B(-11,1,11,minecraft:jungle_log[axis=z])
B(-11,0,12,minecraft:jungle_log[axis=x])
B(-10,0,-12,minecraft:jungle_log[axis=z])
B(-10,0,-11,minecraft:jungle_log[axis=z])
B(-10,1,-11,minecraft:jungle_log[axis=z])
B(-10,2,-11,minecraft:jungle_log[axis=x])
B(-10,0,-10,minecraft:jungle_log[axis=z])
B(-10,0,-4,minecraft:jungle_log[axis=z])
B(-10,1,-4,minecraft:jungle_log)
B(-10,2,-4,minecraft:jungle_log[axis=z])
B(-10,3,-4,minecraft:jungle_log[axis=z])
B(-10,31,-4,minecraft:jungle_leaves[distance=2,persistent=false])
B(-10,32,-4,minecraft:jungle_leaves)
B(-10,33,-4,minecraft:jungle_leaves[distance=2,persistent=false])
B(-10,0,-3,minecraft:jungle_log[axis=x])
B(-10,1,-3,minecraft:jungle_log)
B(-10,2,-3,minecraft:jungle_log)
B(-10,0,-2,minecraft:jungle_log)
B(-10,1,-2,minecraft:jungle_log[axis=x])
B(-10,28,-2,minecraft:jungle_leaves[distance=3,persistent=false])
B(-10,29,-2,minecraft:jungle_leaves[distance=2,persistent=false])
B(-10,30,-2,minecraft:jungle_leaves)
B(-10,33,-2,minecraft:jungle_leaves[distance=2,persistent=false])
B(-10,31,-1,minecraft:jungle_leaves)
B(-10,30,0,minecraft:jungle_leaves)
B(-10,1,7,minecraft:jungle_log)
B(-10,0,8,minecraft:jungle_log[axis=x])
B(-10,1,8,minecraft:jungle_log[axis=z])
B(-10,0,9,minecraft:jungle_log[axis=z])
B(-10,0,10,minecraft:jungle_log[axis=x])
B(-10,1,10,minecraft:jungle_log[axis=x])
B(-10,0,11,minecraft:jungle_log[axis=x])
B(-9,0,-12,minecraft:jungle_log[axis=x])
B(-9,1,-12,minecraft:jungle_log)
B(-9,2,-12,minecraft:jungle_log[axis=z])
B(-9,0,-11,minecraft:jungle_log[axis=z])
B(-9,1,-11,minecraft:jungle_log[axis=x])
B(-9,2,-11,minecraft:jungle_log[axis=x])
B(-9,3,-11,minecraft:jungle_log[axis=x])
B(-9,0,-10,minecraft:jungle_log)
B(-9,1,-10,minecraft:jungle_log[axis=x])
B(-9,2,-10,minecraft:jungle_log)
B(-9,0,-9,minecraft:jungle_log[axis=x])
B(-9,1,-9,minecraft:jungle_log[axis=z])
B(-9,2,-9,minecraft:jungle_log[axis=x])
B(-9,4,-9,minecraft:jungle_log[axis=x])
B(-9,5,-9,minecraft:jungle_log)
B(-9,7,-9,minecraft:jungle_log)
B(-9,1,-5,minecraft:jungle_log[axis=z])
B(-9,2,-5,minecraft:jungle_log)
B(-9,3,-5,minecraft:jungle_log[axis=x])
B(-9,5,-5,minecraft:jungle_log[axis=z])
B(-9,6,-5,minecraft:jungle_log[axis=z])
B(-9,31,-5,minecraft:jungle_leaves[distance=2,persistent=false])
B(-9,32,-5,minecraft:jungle_leaves)
B(-9,33,-5,minecraft:jungle_leaves[distance=2,persistent=false])
B(-9,0,-4,minecraft:jungle_log[axis=z])
B(-9,1,-4,minecraft:jungle_log[axis=x])
B(-9,2,-4,minecraft:jungle_log[axis=z])
B(-9,3,-4,minecraft:jungle_log[axis=x])
B(-9,4,-4,minecraft:jungle_log)
B(-9,5,-4,minecraft:jungle_log)
B(-9,30,-4,minecraft:jungle_leaves[distance=2,persistent=false])
B(-9,31,-4,minecraft:jungle_leaves)
B(-9,32,-4,minecraft:jungle_log[axis=z])
B(-9,33,-4,minecraft:jungle_leaves)
B(-9,34,-4,minecraft:jungle_leaves[distance=2,persistent=false])
B(-9,0,-3,minecraft:jungle_log)
B(-9,1,-3,minecraft:jungle_log[axis=x])
B(-9,2,-3,minecraft:jungle_log[axis=z])
B(-9,3,-3,minecraft:jungle_log[axis=x])
B(-9,28,-3,minecraft:jungle_leaves[distance=3,persistent=false])
B(-9,29,-3,minecraft:jungle_leaves[distance=2,persistent=false])
B(-9,30,-3,minecraft:jungle_leaves)
B(-9,31,-3,minecraft:jungle_log[axis=z])
B(-9,32,-3,minecraft:jungle_log[axis=z])
B(-9,33,-3,minecraft:jungle_log[axis=x])
B(-9,1,-2,minecraft:jungle_log)
B(-9,2,-2,minecraft:jungle_log)
B(-9,23,-2,minecraft:jungle_leaves[distance=7,persistent=true])
B(-9,24,-2,minecraft:jungle_leaves[distance=7,persistent=true])
B(-9,25,-2,minecraft:jungle_leaves[distance=5,persistent=false])
B(-9,26,-2,minecraft:jungle_leaves[distance=4,persistent=false])
B(-9,27,-2,minecraft:jungle_leaves[distance=3,persistent=false])
B(-9,28,-2,minecraft:jungle_leaves[distance=2,persistent=false])
B(-9,29,-2,minecraft:jungle_leaves)
B(-9,30,-2,minecraft:jungle_log[axis=x])
B(-9,31,-2,minecraft:jungle_log[axis=z])
B(-9,32,-2,minecraft:jungle_log[axis=z])
B(-9,33,-2,minecraft:jungle_leaves)
B(-9,34,-2,minecraft:jungle_leaves[distance=2,persistent=false])
B(-9,28,-1,minecraft:jungle_leaves)
B(-9,29,-1,minecraft:jungle_log)
B(-9,30,-1,minecraft:jungle_log[axis=z])
B(-9,31,-1,minecraft:jungle_log[axis=z])
B(-9,32,-1,minecraft:jungle_leaves)
B(-9,33,-1,minecraft:jungle_leaves[distance=2,persistent=false])
B(-9,29,0,minecraft:jungle_leaves)
B(-9,30,0,minecraft:jungle_log[axis=x])
B(-9,31,0,minecraft:jungle_leaves)
B(-9,30,1,minecraft:jungle_leaves)
B(-9,1,6,minecraft:jungle_log[axis=x])
B(-9,2,6,minecraft:jungle_log)
B(-9,3,6,minecraft:jungle_log)
B(-9,0,7,minecraft:jungle_log[axis=x])
B(-9,1,7,minecraft:jungle_log[axis=z])
B(-9,2,7,minecraft:jungle_log)
B(-9,0,8,minecraft:jungle_log[axis=x])
B(-9,1,8,minecraft:jungle_log)
B(-9,2,8,minecraft:jungle_log)
B(-9,0,9,minecraft:jungle_log)
B(-9,1,9,minecraft:jungle_log)
B(-9,0,10,minecraft:jungle_log)
B(-8,1,-12,minecraft:jungle_log[axis=x])
B(-8,0,-11,minecraft:jungle_log[axis=x])
B(-8,1,-11,minecraft:jungle_log[axis=z])
B(-8,2,-11,minecraft:jungle_log)
B(-8,0,-10,minecraft:jungle_log[axis=x])
B(-8,1,-10,minecraft:jungle_log)
B(-8,2,-10,minecraft:jungle_log[axis=z])
B(-8,4,-10,minecraft:jungle_log)
B(-8,5,-10,minecraft:jungle_log[axis=x])
B(-8,7,-10,minecraft:jungle_log[axis=z])
B(-8,0,-9,minecraft:jungle_log)
B(-8,1,-9,minecraft:jungle_log[axis=x])
B(-8,2,-9,minecraft:jungle_log[axis=z])
B(-8,3,-9,minecraft:jungle_log)
B(-8,4,-9,minecraft:jungle_log[axis=z])
B(-8,5,-9,minecraft:jungle_log[axis=x])
B(-8,6,-9,minecraft:jungle_log)
B(-8,7,-9,minecraft:jungle_log[axis=x])
B(-8,8,-9,minecraft:jungle_log[axis=z])
B(-8,2,-8,minecraft:jungle_log[axis=x])
B(-8,3,-8,minecraft:jungle_log[axis=x])
B(-8,4,-8,minecraft:jungle_log[axis=x])
B(-8,5,-8,minecraft:jungle_log)
B(-8,7,-8,minecraft:jungle_log[axis=x])
B(-8,4,-7,minecraft:jungle_log[axis=z])
B(-8,7,-7,minecraft:jungle_log[axis=x])
B(-8,9,-7,minecraft:jungle_log)
B(-8,10,-7,minecraft:jungle_log)
B(-8,5,-6,minecraft:jungle_log[axis=x])
B(-8,6,-6,minecraft:jungle_log[axis=x])
B(-8,9,-6,minecraft:jungle_log[axis=x])
B(-8,3,-5,minecraft:jungle_log)
B(-8,4,-5,minecraft:jungle_log[axis=x])
B(-8,5,-5,minecraft:jungle_log)
B(-8,6,-5,minecraft:jungle_log[axis=z])
B(-8,7,-5,minecraft:jungle_log)
B(-8,30,-5,minecraft:jungle_leaves[distance=2,persistent=false])
B(-8,31,-5,minecraft:jungle_leaves)
B(-8,32,-5,minecraft:jungle_leaves)
B(-8,33,-5,minecraft:jungle_leaves)
B(-8,1,-4,minecraft:jungle_log[axis=z])
B(-8,2,-4,minecraft:jungle_log[axis=x])
B(-8,3,-4,minecraft:jungle_log[axis=x])
B(-8,4,-4,minecraft:jungle_log[axis=z])
B(-8,5,-4,minecraft:jungle_log[axis=z])
B(-8,6,-4,minecraft:jungle_log[axis=x])
B(-8,29,-4,minecraft:jungle_leaves[distance=2,persistent=false])
B(-8,30,-4,minecraft:jungle_leaves)
B(-8,31,-4,minecraft:jungle_log)
B(-8,32,-4,minecraft:jungle_log[axis=x])
B(-8,33,-4,minecraft:jungle_log[axis=x])
B(-8,34,-4,minecraft:jungle_leaves)
B(-8,1,-3,minecraft:jungle_log[axis=x])
B(-8,2,-3,minecraft:jungle_log[axis=x])
B(-8,3,-3,minecraft:jungle_log[axis=x])
B(-8,4,-3,minecraft:jungle_log[axis=z])
B(-8,5,-3,minecraft:jungle_log[axis=x])
B(-8,28,-3,minecraft:jungle_leaves[distance=2,persistent=false])
B(-8,29,-3,minecraft:jungle_leaves)
B(-8,30,-3,minecraft:jungle_log[axis=z])
B(-8,31,-3,minecraft:jungle_log[axis=z])
B(-8,32,-3,minecraft:jungle_log[axis=z])
B(-8,33,-3,minecraft:jungle_log[axis=x])
B(-8,34,-3,minecraft:jungle_leaves)
B(-8,28,-2,minecraft:jungle_leaves)
B(-8,29,-2,minecraft:jungle_log[axis=x])
B(-8,30,-2,minecraft:jungle_log)
B(-8,31,-2,minecraft:jungle_log[axis=z])
B(-8,32,-2,minecraft:jungle_log[axis=z])
B(-8,33,-2,minecraft:jungle_log[axis=z])
B(-8,34,-2,minecraft:jungle_leaves)
B(-8,28,-1,minecraft:jungle_log)
B(-8,29,-1,minecraft:jungle_log)
B(-8,30,-1,minecraft:jungle_log[axis=z])
B(-8,31,-1,minecraft:jungle_log[axis=x])
B(-8,32,-1,minecraft:jungle_log)
B(-8,33,-1,minecraft:jungle_leaves)
B(-8,0,0,minecraft:jungle_log)
B(-8,1,0,minecraft:jungle_log)
B(-8,2,0,minecraft:jungle_log[axis=x])
B(-8,28,0,minecraft:jungle_leaves)
B(-8,29,0,minecraft:jungle_log[axis=x])
B(-8,30,0,minecraft:jungle_log)
B(-8,31,0,minecraft:jungle_log)
B(-8,29,1,minecraft:jungle_leaves)
B(-8,30,1,minecraft:jungle_leaves)
B(-8,0,3,minecraft:jungle_log)
B(-8,1,3,minecraft:jungle_log[axis=x])
B(-8,2,5,minecraft:jungle_log[axis=x])
B(-8,3,5,minecraft:jungle_log[axis=x])
B(-8,4,5,minecraft:jungle_log[axis=z])
B(-8,5,5,minecraft:jungle_log)
B(-8,1,6,minecraft:jungle_log)
B(-8,2,6,minecraft:jungle_log)
B(-8,3,6,minecraft:jungle_log)
B(-8,4,6,minecraft:jungle_log[axis=x])
B(-8,0,7,minecraft:jungle_log[axis=z])
B(-8,1,7,minecraft:jungle_log)
B(-8,2,7,minecraft:jungle_log)
B(-8,3,7,minecraft:jungle_log)
B(-8,0,8,minecraft:jungle_log[axis=z])
B(-8,1,8,minecraft:jungle_log[axis=z])
B(-8,2,8,minecraft:jungle_log[axis=z])
B(-7,1,-11,minecraft:jungle_log)
B(-7,0,-10,minecraft:jungle_log)
B(-7,1,-10,minecraft:jungle_log[axis=x])
B(-7,2,-10,minecraft:jungle_log)
B(-7,4,-10,minecraft:jungle_log)
B(-7,5,-10,minecraft:jungle_log)
B(-7,7,-10,minecraft:jungle_log[axis=x])
B(-7,1,-9,minecraft:jungle_log[axis=z])
B(-7,2,-9,minecraft:jungle_log[axis=z])
B(-7,3,-9,minecraft:jungle_log[axis=z])
B(-7,4,-9,minecraft:jungle_log[axis=x])
B(-7,5,-9,minecraft:jungle_log[axis=x])
B(-7,6,-9,minecraft:jungle_log[axis=z])
B(-7,7,-9,minecraft:jungle_log)
B(-7,8,-9,minecraft:jungle_log[axis=x])
B(-7,11,-9,minecraft:jungle_log[axis=x])
B(-7,2,-8,minecraft:jungle_log[axis=z])
B(-7,3,-8,minecraft:jungle_log[axis=z])
B(-7,4,-8,minecraft:jungle_log[axis=z])
B(-7,5,-8,minecraft:jungle_log[axis=z])
B(-7,6,-8,minecraft:jungle_log[axis=z])
B(-7,7,-8,minecraft:jungle_log[axis=z])
B(-7,8,-8,minecraft:jungle_log[axis=z])
B(-7,9,-8,minecraft:jungle_log[axis=x])
B(-7,10,-8,minecraft:jungle_log[axis=z])
B(-7,11,-8,minecraft:jungle_log)
B(-7,12,-8,minecraft:jungle_leaves)
B(-7,3,-7,minecraft:jungle_log[axis=x])
B(-7,4,-7,minecraft:jungle_log[axis=x])
B(-7,5,-7,minecraft:jungle_log[axis=x])
B(-7,6,-7,minecraft:jungle_log[axis=x])
B(-7,7,-7,minecraft:jungle_log[axis=x])
B(-7,8,-7,minecraft:jungle_log[axis=x])
B(-7,9,-7,minecraft:jungle_log[axis=x])
B(-7,10,-7,minecraft:jungle_log[axis=z])
B(-7,11,-7,minecraft:jungle_log)
B(-7,13,-7,minecraft:jungle_leaves[distance=2,persistent=false])
B(-7,5,-6,minecraft:jungle_log[axis=z])
B(-7,6,-6,minecraft:jungle_log[axis=z])
B(-7,7,-6,minecraft:jungle_log[axis=z])
B(-7,8,-6,minecraft:jungle_log[axis=z])
B(-7,9,-6,minecraft:jungle_log[axis=x])
B(-7,10,-6,minecraft:jungle_log)
B(-7,11,-6,minecraft:jungle_log[axis=x])
B(-7,12,-6,minecraft:jungle_log[axis=x])
B(-7,13,-6,minecraft:jungle_leaves)
B(-7,5,-5,minecraft:jungle_log[axis=z])
B(-7,6,-5,minecraft:jungle_log)
B(-7,7,-5,minecraft:jungle_log[axis=z])
B(-7,11,-5,minecraft:jungle_log)
B(-7,31,-5,minecraft:jungle_leaves[distance=2,persistent=false])
B(-7,3,-4,minecraft:jungle_log[axis=x])
B(-7,4,-4,minecraft:jungle_log[axis=z])
B(-7,5,-4,minecraft:jungle_log[axis=x])
B(-7,6,-4,minecraft:jungle_log[axis=x])
B(-7,28,-4,minecraft:jungle_leaves[distance=2,persistent=false])
B(-7,29,-4,minecraft:jungle_leaves[distance=2,persistent=false])
B(-7,30,-4,minecraft:jungle_leaves[distance=2,persistent=false])
B(-7,31,-4,minecraft:jungle_leaves)
B(-7,32,-4,minecraft:jungle_log[axis=x])
B(-7,33,-4,minecraft:jungle_leaves)
B(-7,28,-3,minecraft:jungle_leaves)
B(-7,29,-3,minecraft:jungle_leaves)
B(-7,30,-3,minecraft:jungle_leaves)
B(-7,31,-3,minecraft:jungle_log)
B(-7,32,-3,minecraft:jungle_log)
B(-7,33,-3,minecraft:jungle_log)
B(-7,28,-2,minecraft:jungle_log[axis=x])
B(-7,29,-2,minecraft:jungle_log[axis=x])
B(-7,30,-2,minecraft:jungle_log)
B(-7,31,-2,minecraft:jungle_log[axis=x])
B(-7,32,-2,minecraft:jungle_log[axis=x])
B(-7,33,-2,minecraft:jungle_leaves)
B(-7,28,-1,minecraft:jungle_log)
B(-7,29,-1,minecraft:jungle_log)
B(-7,30,-1,minecraft:jungle_log)
B(-7,31,-1,minecraft:jungle_log[axis=z])
B(-7,32,-1,minecraft:jungle_leaves)
B(-7,2,0,minecraft:jungle_log[axis=x])
B(-7,3,0,minecraft:jungle_log)
B(-7,27,0,minecraft:jungle_leaves)
B(-7,28,0,minecraft:jungle_log[axis=z])
B(-7,29,0,minecraft:jungle_log[axis=z])
B(-7,30,0,minecraft:jungle_log)
B(-7,31,0,minecraft:jungle_leaves)
B(-7,28,1,minecraft:jungle_leaves)
B(-7,29,1,minecraft:jungle_log)
B(-7,30,1,minecraft:jungle_leaves)
B(-7,29,2,minecraft:jungle_leaves)
B(-7,1,3,minecraft:jungle_log)
B(-7,2,3,minecraft:jungle_log)
B(-7,3,3,minecraft:jungle_log[axis=z])
B(-7,31,3,minecraft:jungle_leaves[distance=2,persistent=false])
B(-7,3,4,minecraft:jungle_log[axis=x])
B(-7,4,4,minecraft:jungle_log)
B(-7,5,4,minecraft:jungle_log[axis=x])
B(-7,9,4,minecraft:jungle_log[axis=z])
B(-7,2,5,minecraft:jungle_log[axis=z])
B(-7,3,5,minecraft:jungle_log[axis=z])
B(-7,4,5,minecraft:jungle_log[axis=x])
B(-7,5,5,minecraft:jungle_log[axis=z])
B(-7,6,5,minecraft:jungle_log[axis=x])
B(-7,7,5,minecraft:jungle_log)
B(-7,8,5,minecraft:jungle_log[axis=x])
B(-7,2,6,minecraft:jungle_log[axis=z])
B(-7,3,6,minecraft:jungle_log[axis=z])
B(-7,4,6,minecraft:jungle_log[axis=x])
B(-7,5,6,minecraft:jungle_log[axis=x])
B(-7,1,7,minecraft:jungle_log[axis=z])
B(-7,2,7,minecraft:jungle_log[axis=x])
B(-7,3,7,minecraft:jungle_log)
B(-6,0,-10,minecraft:jungle_log)
B(-6,4,-10,minecraft:jungle_log)
B(-6,8,-10,minecraft:jungle_log)
B(-6,0,-9,minecraft:jungle_log)
B(-6,1,-9,minecraft:jungle_log)
B(-6,2,-9,minecraft:jungle_log)
B(-6,3,-9,minecraft:jungle_log)
B(-6,4,-9,minecraft:jungle_log)
B(-6,5,-9,minecraft:jungle_log)
B(-6,6,-9,minecraft:jungle_log)
B(-6,7,-9,minecraft:jungle_log)
B(-6,8,-9,minecraft:jungle_log)
B(-6,9,-9,minecraft:jungle_log[axis=x])
B(-6,10,-9,minecraft:jungle_log[axis=z])
B(-6,1,-8,minecraft:jungle_log[axis=x])
B(-6,2,-8,minecraft:jungle_log[axis=x])
B(-6,3,-8,minecraft:jungle_log[axis=x])
B(-6,4,-8,minecraft:jungle_log[axis=x])
B(-6,5,-8,minecraft:jungle_log[axis=x])
B(-6,6,-8,minecraft:jungle_log[axis=x])
B(-6,7,-8,minecraft:jungle_log[axis=x])
B(-6,8,-8,minecraft:jungle_log[axis=x])
B(-6,9,-8,minecraft:jungle_log)
B(-6,10,-8,minecraft:jungle_log)
B(-6,11,-8,minecraft:jungle_log[axis=x])
B(-6,13,-8,minecraft:jungle_leaves[distance=2,persistent=false])
B(-6,3,-7,minecraft:jungle_log)
B(-6,4,-7,minecraft:jungle_log)
B(-6,5,-7,minecraft:jungle_log)
B(-6,6,-7,minecraft:jungle_log)
B(-6,7,-7,minecraft:jungle_log)
B(-6,8,-7,minecraft:jungle_log)
B(-6,9,-7,minecraft:jungle_log[axis=z])
B(-6,10,-7,minecraft:jungle_log[axis=x])
B(-6,11,-7,minecraft:jungle_log[axis=z])
B(-6,12,-7,minecraft:jungle_log)
B(-6,13,-7,minecraft:jungle_leaves)
B(-6,14,-7,minecraft:jungle_leaves[distance=2,persistent=false])
B(-6,6,-6,minecraft:jungle_log)
B(-6,9,-6,minecraft:jungle_log[axis=z])
B(-6,10,-6,minecraft:jungle_log[axis=x])
B(-6,11,-6,minecraft:jungle_log[axis=z])
B(-6,12,-6,minecraft:jungle_log[axis=x])
B(-6,13,-6,minecraft:jungle_log[axis=z])
B(-6,14,-6,minecraft:jungle_leaves)
B(-6,6,-5,minecraft:jungle_log[axis=x])
B(-6,10,-5,minecraft:jungle_log[axis=z])
B(-6,11,-5,minecraft:jungle_log)
B(-6,12,-5,minecraft:jungle_log[axis=x])
B(-6,13,-5,minecraft:jungle_leaves)
B(-6,4,-4,minecraft:jungle_log)
B(-6,5,-4,minecraft:jungle_log[axis=x])
B(-6,29,-4,minecraft:jungle_leaves[distance=2,persistent=false])
B(-6,28,-3,minecraft:jungle_leaves[distance=2,persistent=false])
B(-6,29,-3,minecraft:jungle_leaves)
B(-6,30,-3,minecraft:jungle_leaves[distance=2,persistent=false])
B(-6,31,-3,minecraft:jungle_leaves)
B(-6,25,-2,minecraft:jungle_leaves[distance=4,persistent=false])
B(-6,26,-2,minecraft:jungle_leaves[distance=3,persistent=false])
B(-6,27,-2,minecraft:jungle_leaves[distance=2,persistent=false])
B(-6,28,-2,minecraft:jungle_leaves)
B(-6,29,-2,minecraft:jungle_log)
B(-6,30,-2,minecraft:jungle_leaves)
B(-6,31,-2,minecraft:jungle_leaves)
B(-6,4,-1,minecraft:jungle_log[axis=x])
B(-6,28,-1,minecraft:jungle_log[axis=x])
B(-6,29,-1,minecraft:jungle_log[axis=z])
B(-6,30,-1,minecraft:jungle_log)
B(-6,31,-1,minecraft:jungle_leaves)
B(-6,32,-1,minecraft:jungle_leaves[distance=2,persistent=false])
B(-6,3,0,minecraft:jungle_log[axis=x])
B(-6,4,0,minecraft:jungle_log)
B(-6,27,0,minecraft:jungle_leaves)
B(-6,28,0,minecraft:jungle_log[axis=x])
B(-6,29,0,minecraft:jungle_log[axis=x])
B(-6,30,0,minecraft:jungle_log)
B(-6,31,0,minecraft:jungle_leaves)
B(-6,28,1,minecraft:jungle_log)
B(-6,29,1,minecraft:jungle_log[axis=z])
B(-6,30,1,minecraft:jungle_log[axis=x])
B(-6,31,1,minecraft:jungle_leaves)
B(-6,28,2,minecraft:jungle_leaves)
B(-6,29,2,minecraft:jungle_log[axis=x])
B(-6,30,2,minecraft:jungle_leaves)
B(-6,31,2,minecraft:jungle_leaves[distance=2,persistent=false])
B(-6,11,3,minecraft:jungle_log)
B(-6,30,3,minecraft:jungle_leaves)
B(-6,31,3,minecraft:jungle_leaves)
B(-6,32,3,minecraft:jungle_leaves[distance=2,persistent=false])
B(-6,5,4,minecraft:jungle_log)
B(-6,6,4,minecraft:jungle_log)
B(-6,7,4,minecraft:jungle_log)
B(-6,8,4,minecraft:jungle_log[axis=z])
B(-6,9,4,minecraft:jungle_log[axis=x])
B(-6,10,4,minecraft:jungle_log)
B(-6,12,4,minecraft:jungle_log)
B(-6,31,4,minecraft:jungle_leaves[distance=2,persistent=false])
B(-6,3,5,minecraft:jungle_log[axis=z])
B(-6,4,5,minecraft:jungle_log[axis=z])
B(-6,5,5,minecraft:jungle_log)
B(-6,6,5,minecraft:jungle_log[axis=x])
B(-6,7,5,minecraft:jungle_log[axis=x])
B(-6,8,5,minecraft:jungle_log)
B(-6,9,5,minecraft:jungle_log[axis=z])
B(-6,3,6,minecraft:jungle_log[axis=x])
B(-6,5,6,minecraft:jungle_log)
B(-6,6,6,minecraft:jungle_log[axis=x])
B(-6,7,6,minecraft:jungle_log)
B(-6,8,6,minecraft:jungle_log[axis=x])
B(-5,0,-11,minecraft:jungle_log[axis=x])
B(-5,0,-10,minecraft:jungle_log)
B(-5,1,-10,minecraft:jungle_log[axis=x])
B(-5,4,-10,minecraft:jungle_log[axis=x])
B(-5,8,-10,minecraft:jungle_log[axis=z])
B(-5,0,-9,minecraft:jungle_log)
B(-5,1,-9,minecraft:jungle_log)
B(-5,3,-9,minecraft:jungle_log)
B(-5,4,-9,minecraft:jungle_log[axis=x])
B(-5,5,-9,minecraft:jungle_log[axis=z])
B(-5,7,-9,minecraft:jungle_log[axis=z])
B(-5,8,-9,minecraft:jungle_log[axis=x])
B(-5,9,-9,minecraft:jungle_log[axis=z])
B(-5,0,-8,minecraft:jungle_log[axis=z])
B(-5,1,-8,minecraft:jungle_log[axis=x])
B(-5,3,-8,minecraft:jungle_log)
B(-5,4,-8,minecraft:jungle_log[axis=z])
B(-5,5,-8,minecraft:jungle_log[axis=z])
B(-5,7,-8,minecraft:jungle_log[axis=z])
B(-5,8,-8,minecraft:jungle_log[axis=x])
B(-5,10,-8,minecraft:jungle_log[axis=z])
B(-5,6,-7,minecraft:jungle_log[axis=x])
B(-5,9,-7,minecraft:jungle_log[axis=z])
B(-5,10,-7,minecraft:jungle_log[axis=z])
B(-5,11,-7,minecraft:jungle_log[axis=x])
B(-5,12,-7,minecraft:jungle_log)
B(-5,13,-7,minecraft:jungle_log)
B(-5,6,-6,minecraft:jungle_log)
B(-5,7,-6,minecraft:jungle_log)
B(-5,8,-6,minecraft:jungle_log)
B(-5,9,-6,minecraft:jungle_log)
B(-5,10,-6,minecraft:jungle_log)
B(-5,11,-6,minecraft:jungle_log[axis=z])
B(-5,12,-6,minecraft:jungle_log[axis=x])
B(-5,13,-6,minecraft:jungle_log[axis=z])
B(-5,11,-5,minecraft:jungle_log[axis=x])
B(-5,12,-5,minecraft:jungle_log[axis=x])
B(-5,13,-5,minecraft:jungle_log)
B(-5,14,-5,minecraft:jungle_leaves)
B(-5,0,-4,minecraft:jungle_log)
B(-5,1,-4,minecraft:jungle_log)
B(-5,2,-4,minecraft:jungle_log)
B(-5,3,-4,minecraft:jungle_log)
B(-5,4,-4,minecraft:jungle_log[axis=x])
B(-5,12,-4,minecraft:jungle_log[axis=x])
B(-5,13,-4,minecraft:jungle_log[axis=x])
B(-5,14,-4,minecraft:jungle_log[axis=z])
B(-5,15,-4,minecraft:jungle_leaves)
B(-5,13,-3,minecraft:jungle_log[axis=z])
B(-5,29,-3,minecraft:jungle_leaves[distance=2,persistent=false])
B(-5,28,-2,minecraft:jungle_leaves[distance=2,persistent=false])
B(-5,29,-2,minecraft:jungle_leaves)
B(-5,30,-2,minecraft:jungle_leaves[distance=2,persistent=false])
B(-5,4,-1,minecraft:jungle_log[axis=x])
B(-5,5,-1,minecraft:jungle_log[axis=x])
B(-5,28,-1,minecraft:jungle_leaves)
B(-5,29,-1,minecraft:jungle_log[axis=z])
B(-5,31,-1,minecraft:jungle_leaves[distance=2,persistent=false])
B(-5,27,0,minecraft:jungle_leaves)
B(-5,28,0,minecraft:jungle_log[axis=z])
B(-5,29,0,minecraft:jungle_log[axis=x])
B(-5,30,0,minecraft:jungle_log[axis=z])
B(-5,31,0,minecraft:jungle_leaves)
B(-5,28,1,minecraft:jungle_log)
B(-5,29,1,minecraft:jungle_log[axis=x])
B(-5,30,1,minecraft:jungle_log)
B(-5,31,1,minecraft:jungle_leaves)
B(-5,13,2,minecraft:jungle_log)
B(-5,27,2,minecraft:jungle_leaves)
B(-5,28,2,minecraft:jungle_log)
B(-5,29,2,minecraft:jungle_log)
B(-5,30,2,minecraft:jungle_log[axis=z])
B(-5,31,2,minecraft:jungle_leaves)
B(-5,10,3,minecraft:jungle_log[axis=z])
B(-5,11,3,minecraft:jungle_log[axis=z])
B(-5,12,3,minecraft:jungle_log[axis=x])
B(-5,13,3,minecraft:jungle_log[axis=x])
B(-5,14,3,minecraft:jungle_log[axis=z])
B(-5,28,3,minecraft:jungle_leaves)
B(-5,29,3,minecraft:jungle_log)
B(-5,30,3,minecraft:jungle_log)
B(-5,31,3,minecraft:jungle_log[axis=x])
B(-5,32,3,minecraft:jungle_leaves)
B(-5,9,4,minecraft:jungle_log)
B(-5,10,4,minecraft:jungle_log)
B(-5,11,4,minecraft:jungle_log[axis=x])
B(-5,12,4,minecraft:jungle_log[axis=x])
B(-5,13,4,minecraft:jungle_log)
B(-5,14,4,minecraft:jungle_leaves)
B(-5,29,4,minecraft:jungle_leaves)
B(-5,30,4,minecraft:jungle_log[axis=x])
B(-5,31,4,minecraft:jungle_leaves)
B(-5,5,5,minecraft:jungle_log[axis=z])
B(-5,6,5,minecraft:jungle_log[axis=x])
B(-5,7,5,minecraft:jungle_log[axis=x])
B(-5,8,5,minecraft:jungle_log[axis=x])
B(-5,9,5,minecraft:jungle_log)
B(-5,13,5,minecraft:jungle_log)
B(-5,14,6,minecraft:jungle_leaves[distance=7,persistent=true])
B(-4,0,-10,minecraft:jungle_log)
B(-4,0,-9,minecraft:jungle_log)
B(-4,4,-9,minecraft:jungle_log[axis=z])
B(-4,8,-9,minecraft:jungle_log[axis=z])
B(-4,0,-7,minecraft:jungle_log)
B(-4,12,-7,minecraft:jungle_log)
B(-4,11,-6,minecraft:jungle_log[axis=x])
B(-4,12,-6,minecraft:jungle_log)
B(-4,13,-6,minecraft:jungle_log[axis=z])
B(-4,14,-6,minecraft:jungle_leaves)
B(-4,11,-5,minecraft:jungle_log[axis=x])
B(-4,12,-5,minecraft:jungle_log[axis=z])
B(-4,13,-5,minecraft:jungle_log)
B(-4,14,-5,minecraft:jungle_log[axis=z])
B(-4,15,-5,minecraft:jungle_leaves)
B(-4,11,-4,minecraft:jungle_log[axis=z])
B(-4,12,-4,minecraft:jungle_log)
B(-4,13,-4,minecraft:jungle_log[axis=z])
B(-4,14,-4,minecraft:jungle_log[axis=z])
B(-4,15,-4,minecraft:jungle_log)
B(-4,16,-4,minecraft:jungle_leaves)
B(-4,12,-3,minecraft:jungle_log[axis=x])
B(-4,13,-3,minecraft:jungle_log)
B(-4,14,-3,minecraft:jungle_log)
B(-4,15,-3,minecraft:jungle_leaves)
B(-4,28,-3,minecraft:jungle_leaves[distance=3,persistent=false])
B(-4,29,-3,minecraft:jungle_leaves[distance=3,persistent=false])
B(-4,30,-3,minecraft:jungle_leaves[distance=3,persistent=false])
B(-4,16,-2,minecraft:jungle_leaves)
B(-4,28,-2,minecraft:jungle_leaves[distance=2,persistent=false])
B(-4,29,-2,minecraft:jungle_leaves[distance=2,persistent=false])
B(-4,30,-2,minecraft:jungle_leaves[distance=2,persistent=false])
B(-4,0,-1,minecraft:jungle_log)
B(-4,1,-1,minecraft:jungle_log)
B(-4,2,-1,minecraft:jungle_log)
B(-4,3,-1,minecraft:jungle_log)
B(-4,4,-1,minecraft:jungle_log)
B(-4,5,-1,minecraft:jungle_log)
B(-4,6,-1,minecraft:jungle_log)
B(-4,7,-1,minecraft:jungle_log)
B(-4,8,-1,minecraft:jungle_log[axis=x])
B(-4,28,-1,minecraft:jungle_leaves)
B(-4,29,-1,minecraft:jungle_leaves)
B(-4,30,-1,minecraft:jungle_leaves)
B(-4,28,0,minecraft:jungle_log)
B(-4,29,0,minecraft:jungle_log)
B(-4,30,0,minecraft:jungle_log)
B(-4,31,0,minecraft:jungle_leaves)
B(-4,28,1,minecraft:jungle_log[axis=z])
B(-4,29,1,minecraft:jungle_log[axis=z])
B(-4,30,1,minecraft:jungle_log)
B(-4,31,1,minecraft:jungle_leaves)
B(-4,12,2,minecraft:jungle_log[axis=z])
B(-4,13,2,minecraft:jungle_log[axis=z])
B(-4,14,2,minecraft:jungle_log)
B(-4,24,2,minecraft:jungle_leaves[distance=7,persistent=true])
B(-4,25,2,minecraft:jungle_leaves[distance=3,persistent=false])
B(-4,26,2,minecraft:jungle_leaves[distance=2,persistent=false])
B(-4,27,2,minecraft:jungle_leaves)
B(-4,28,2,minecraft:jungle_log)
B(-4,29,2,minecraft:jungle_log[axis=z])
B(-4,30,2,minecraft:jungle_log[axis=z])
B(-4,31,2,minecraft:jungle_log[axis=x])
B(-4,32,2,minecraft:jungle_leaves)
B(-4,11,3,minecraft:jungle_log[axis=x])
B(-4,12,3,minecraft:jungle_log[axis=z])
B(-4,13,3,minecraft:jungle_log)
B(-4,14,3,minecraft:jungle_log)
B(-4,15,3,minecraft:jungle_log[axis=x])
B(-4,16,3,minecraft:jungle_leaves)
B(-4,28,3,minecraft:jungle_log[axis=z])
B(-4,29,3,minecraft:jungle_log[axis=x])
B(-4,30,3,minecraft:jungle_log)
B(-4,31,3,minecraft:jungle_log[axis=x])
B(-4,32,3,minecraft:jungle_log[axis=z])
B(-4,10,4,minecraft:jungle_log)
B(-4,11,4,minecraft:jungle_log[axis=x])
B(-4,12,4,minecraft:jungle_log[axis=x])
B(-4,13,4,minecraft:jungle_log[axis=x])
B(-4,14,4,minecraft:jungle_log)
B(-4,15,4,minecraft:jungle_leaves)
B(-4,28,4,minecraft:jungle_leaves)
B(-4,29,4,minecraft:jungle_log)
B(-4,30,4,minecraft:jungle_log[axis=x])
B(-4,31,4,minecraft:jungle_log[axis=x])
B(-4,32,4,minecraft:jungle_leaves)
B(-4,9,5,minecraft:jungle_log[axis=z])
B(-4,10,5,minecraft:jungle_log[axis=z])
B(-4,11,5,minecraft:jungle_log[axis=x])
B(-4,12,5,minecraft:jungle_log[axis=z])
B(-4,13,5,minecraft:jungle_log[axis=x])
B(-4,14,5,minecraft:jungle_leaves)
B(-4,29,5,minecraft:jungle_leaves)
B(-4,30,5,minecraft:jungle_leaves)
B(-4,31,5,minecraft:jungle_leaves)
B(-4,10,6,minecraft:jungle_log[axis=z])
B(-4,12,6,minecraft:jungle_log)
B(-4,13,6,minecraft:jungle_leaves)
B(-4,3,7,minecraft:jungle_log)
B(-4,4,7,minecraft:jungle_log[axis=x])
B(-4,0,8,minecraft:jungle_log)
B(-4,1,8,minecraft:jungle_log)
B(-4,2,8,minecraft:jungle_log)
B(-4,3,8,minecraft:jungle_log[axis=z])
B(-3,31,-9,minecraft:jungle_leaves[distance=2,persistent=false])
B(-3,29,-8,minecraft:jungle_leaves)
B(-3,30,-8,minecraft:jungle_log[axis=x])
B(-3,31,-8,minecraft:jungle_leaves)
B(-3,32,-8,minecraft:jungle_leaves[distance=2,persistent=false])
B(-3,0,-7,minecraft:jungle_log)
B(-3,1,-7,minecraft:jungle_log[axis=z])
B(-3,29,-7,minecraft:jungle_log)
B(-3,30,-7,minecraft:jungle_log[axis=x])
B(-3,31,-7,minecraft:jungle_log[axis=x])
B(-3,1,-6,minecraft:jungle_log)
B(-3,2,-6,minecraft:jungle_log)
B(-3,3,-6,minecraft:jungle_log[axis=x])
B(-3,12,-6,minecraft:jungle_log)
B(-3,30,-6,minecraft:jungle_log[axis=z])
B(-3,11,-5,minecraft:jungle_log[axis=z])
B(-3,12,-5,minecraft:jungle_log[axis=z])
B(-3,13,-5,minecraft:jungle_log)
B(-3,14,-5,minecraft:jungle_log)
B(-3,15,-5,minecraft:jungle_log[axis=x])
B(-3,12,-4,minecraft:jungle_log[axis=x])
B(-3,13,-4,minecraft:jungle_log)
B(-3,14,-4,minecraft:jungle_log[axis=x])
B(-3,15,-4,minecraft:jungle_log[axis=z])
B(-3,16,-4,minecraft:jungle_log)
B(-3,13,-3,minecraft:jungle_log)
B(-3,14,-3,minecraft:jungle_log)
B(-3,15,-3,minecraft:jungle_log[axis=x])
B(-3,16,-3,minecraft:jungle_log[axis=x])
B(-3,17,-3,minecraft:jungle_leaves)
B(-3,27,-3,minecraft:jungle_leaves[distance=4,persistent=false])
B(-3,28,-3,minecraft:jungle_leaves[distance=3,persistent=false])
B(-3,29,-3,minecraft:jungle_leaves[distance=2,persistent=false])
B(-3,15,-2,minecraft:jungle_log)
B(-3,16,-2,minecraft:jungle_log[axis=z])
B(-3,17,-2,minecraft:jungle_log[axis=x])
B(-3,24,-2,minecraft:jungle_leaves[distance=7,persistent=true])
B(-3,25,-2,minecraft:jungle_leaves[distance=7,persistent=true])
B(-3,26,-2,minecraft:jungle_leaves[distance=4,persistent=false])
B(-3,27,-2,minecraft:jungle_leaves[distance=3,persistent=false])
B(-3,28,-2,minecraft:jungle_leaves[distance=2,persistent=false])
B(-3,29,-2,minecraft:jungle_leaves)
B(-3,30,-2,minecraft:jungle_leaves[distance=2,persistent=false])
B(-3,8,-1,minecraft:jungle_log)
B(-3,9,-1,minecraft:jungle_log[axis=x])
B(-3,16,-1,minecraft:jungle_log[axis=x])
B(-3,28,-1,minecraft:jungle_leaves)
B(-3,29,-1,minecraft:jungle_log)
B(-3,30,-1,minecraft:jungle_leaves)
B(-3,31,-1,minecraft:jungle_leaves[distance=2,persistent=false])
B(-3,28,0,minecraft:jungle_log[axis=z])
B(-3,29,0,minecraft:jungle_log[axis=z])
B(-3,30,0,minecraft:jungle_log[axis=x])
B(-3,31,0,minecraft:jungle_leaves)
B(-3,27,1,minecraft:jungle_leaves)
B(-3,28,1,minecraft:jungle_log[axis=z])
B(-3,29,1,minecraft:jungle_log[axis=z])
B(-3,30,1,minecraft:jungle_log[axis=x])
B(-3,31,1,minecraft:jungle_leaves)
B(-3,32,1,minecraft:jungle_leaves)
B(-3,13,2,minecraft:jungle_log[axis=x])
B(-3,14,2,minecraft:jungle_log)
B(-3,15,2,minecraft:jungle_log)
B(-3,16,2,minecraft:jungle_leaves)
B(-3,28,2,minecraft:jungle_log)
B(-3,29,2,minecraft:jungle_log)
B(-3,30,2,minecraft:jungle_log[axis=x])
B(-3,31,2,minecraft:jungle_log)
B(-3,32,2,minecraft:jungle_log[axis=z])
B(-3,33,2,minecraft:jungle_leaves)
B(-3,12,3,minecraft:jungle_log)
B(-3,13,3,minecraft:jungle_log[axis=z])
B(-3,14,3,minecraft:jungle_log)
B(-3,15,3,minecraft:jungle_log[axis=x])
B(-3,16,3,minecraft:jungle_log[axis=x])
B(-3,17,3,minecraft:jungle_leaves)
B(-3,28,3,minecraft:jungle_leaves)
B(-3,29,3,minecraft:jungle_log[axis=z])
B(-3,30,3,minecraft:jungle_log)
B(-3,31,3,minecraft:jungle_log[axis=z])
B(-3,32,3,minecraft:jungle_log[axis=x])
B(-3,11,4,minecraft:jungle_log[axis=x])
B(-3,12,4,minecraft:jungle_log)
B(-3,13,4,minecraft:jungle_log[axis=z])
B(-3,14,4,minecraft:jungle_log[axis=z])
B(-3,15,4,minecraft:jungle_log)
B(-3,16,4,minecraft:jungle_leaves)
B(-3,26,4,minecraft:jungle_leaves[distance=4,persistent=false])
B(-3,27,4,minecraft:jungle_leaves[distance=3,persistent=false])
B(-3,28,4,minecraft:jungle_leaves[distance=2,persistent=false])
B(-3,29,4,minecraft:jungle_leaves)
B(-3,30,4,minecraft:jungle_log[axis=x])
B(-3,31,4,minecraft:jungle_log[axis=z])
B(-3,32,4,minecraft:jungle_log[axis=z])
B(-3,12,5,minecraft:jungle_log)
B(-3,31,5,minecraft:jungle_log)
B(-3,5,6,minecraft:jungle_log)
B(-3,6,6,minecraft:jungle_log)
B(-3,7,6,minecraft:jungle_log)
B(-3,8,6,minecraft:jungle_log)
B(-3,9,6,minecraft:jungle_log)
B(-3,10,6,minecraft:jungle_log[axis=x])
B(-3,31,6,minecraft:jungle_leaves)
B(-3,4,7,minecraft:jungle_log)
B(-3,5,7,minecraft:jungle_log[axis=z])
B(-2,28,-10,minecraft:jungle_leaves[distance=3,persistent=false])
B(-2,31,-10,minecraft:jungle_leaves[distance=2,persistent=false])
B(-2,29,-9,minecraft:jungle_leaves)
B(-2,30,-9,minecraft:jungle_log[axis=z])
B(-2,31,-9,minecraft:jungle_leaves)
B(-2,32,-9,minecraft:jungle_leaves[distance=2,persistent=false])
B(-2,28,-8,minecraft:jungle_leaves)
B(-2,29,-8,minecraft:jungle_log[axis=z])
B(-2,30,-8,minecraft:jungle_log[axis=x])
B(-2,31,-8,minecraft:jungle_log[axis=x])
B(-2,32,-8,minecraft:jungle_leaves)
B(-2,29,-7,minecraft:jungle_log[axis=x])
B(-2,30,-7,minecraft:jungle_log)
B(-2,31,-7,minecraft:jungle_log)
B(-2,32,-7,minecraft:jungle_log)
B(-2,3,-6,minecraft:jungle_log)
B(-2,4,-6,minecraft:jungle_log)
B(-2,5,-6,minecraft:jungle_log)
B(-2,6,-6,minecraft:jungle_log)
B(-2,7,-6,minecraft:jungle_log[axis=z])
B(-2,29,-6,minecraft:jungle_log[axis=z])
B(-2,30,-6,minecraft:jungle_log[axis=z])
B(-2,31,-6,minecraft:jungle_log[axis=z])
B(-2,32,-6,minecraft:jungle_leaves)
B(-2,33,-6,minecraft:jungle_leaves[distance=2,persistent=false])
B(-2,7,-5,minecraft:jungle_log)
B(-2,8,-5,minecraft:jungle_log)
B(-2,9,-5,minecraft:jungle_log)
B(-2,10,-5,minecraft:jungle_log)
B(-2,11,-5,minecraft:jungle_log)
B(-2,12,-5,minecraft:jungle_log)
B(-2,13,-5,minecraft:jungle_log)
B(-2,14,-5,minecraft:jungle_log)
B(-2,15,-5,minecraft:jungle_log[axis=x])
B(-2,16,-5,minecraft:jungle_log[axis=x])
B(-2,32,-5,minecraft:jungle_leaves[distance=2,persistent=false])
B(-2,13,-4,minecraft:jungle_log[axis=z])
B(-2,14,-4,minecraft:jungle_log[axis=z])
B(-2,15,-4,minecraft:jungle_log)
B(-2,16,-4,minecraft:jungle_log)
B(-2,17,-4,minecraft:jungle_leaves)
B(-2,14,-3,minecraft:jungle_log)
B(-2,15,-3,minecraft:jungle_log[axis=z])
B(-2,16,-3,minecraft:jungle_log[axis=x])
B(-2,17,-3,minecraft:jungle_log[axis=x])
B(-2,18,-3,minecraft:jungle_leaves)
B(-2,27,-3,minecraft:jungle_leaves[distance=3,persistent=false])
B(-2,28,-3,minecraft:jungle_leaves[distance=2,persistent=false])
B(-2,29,-3,minecraft:jungle_leaves)
B(-2,14,-2,minecraft:jungle_log)
B(-2,15,-2,minecraft:jungle_log)
B(-2,16,-2,minecraft:jungle_log[axis=x])
B(-2,17,-2,minecraft:jungle_log[axis=x])
B(-2,27,-2,minecraft:jungle_leaves[distance=2,persistent=false])
B(-2,28,-2,minecraft:jungle_leaves)
B(-2,29,-2,minecraft:jungle_log[axis=x])
B(-2,30,-2,minecraft:jungle_leaves)
B(-2,7,-1,minecraft:jungle_log)
B(-2,8,-1,minecraft:jungle_log)
B(-2,9,-1,minecraft:jungle_log)
B(-2,10,-1,minecraft:jungle_log)
B(-2,11,-1,minecraft:jungle_log)
B(-2,12,-1,minecraft:jungle_log)
B(-2,13,-1,minecraft:jungle_log)
B(-2,14,-1,minecraft:jungle_log)
B(-2,15,-1,minecraft:jungle_log)
B(-2,16,-1,minecraft:jungle_log[axis=z])
B(-2,17,-1,minecraft:jungle_log)
B(-2,27,-1,minecraft:jungle_leaves)
B(-2,28,-1,minecraft:jungle_log[axis=z])
B(-2,29,-1,minecraft:jungle_log)
B(-2,30,-1,minecraft:jungle_log[axis=x])
B(-2,31,-1,minecraft:jungle_leaves)
B(-2,2,0,minecraft:jungle_log)
B(-2,3,0,minecraft:jungle_log)
B(-2,4,0,minecraft:jungle_log)
B(-2,5,0,minecraft:jungle_log)
B(-2,6,0,minecraft:jungle_log)
B(-2,7,0,minecraft:jungle_log[axis=z])
B(-2,16,0,minecraft:jungle_log[axis=z])
B(-2,28,0,minecraft:jungle_log[axis=z])
B(-2,29,0,minecraft:jungle_log)
B(-2,30,0,minecraft:jungle_log[axis=x])
B(-2,31,0,minecraft:jungle_leaves)
B(-2,15,1,minecraft:jungle_log[axis=x])
B(-2,16,1,minecraft:jungle_leaves)
B(-2,28,1,minecraft:jungle_log[axis=x])
B(-2,29,1,minecraft:jungle_log[axis=z])
B(-2,30,1,minecraft:jungle_log)
B(-2,31,1,minecraft:jungle_leaves)
B(-2,8,2,minecraft:jungle_log)
B(-2,9,2,minecraft:jungle_log)
B(-2,10,2,minecraft:jungle_log)
B(-2,11,2,minecraft:jungle_log)
B(-2,12,2,minecraft:jungle_log)
B(-2,13,2,minecraft:jungle_log)
B(-2,14,2,minecraft:jungle_log)
B(-2,15,2,minecraft:jungle_log[axis=z])
B(-2,16,2,minecraft:jungle_log[axis=x])
B(-2,17,2,minecraft:jungle_leaves)
B(-2,28,2,minecraft:jungle_leaves)
B(-2,29,2,minecraft:jungle_log[axis=z])
B(-2,30,2,minecraft:jungle_leaves)
B(-2,31,2,minecraft:jungle_log[axis=z])
B(-2,32,2,minecraft:jungle_leaves)
B(-2,13,3,minecraft:jungle_log)
B(-2,14,3,minecraft:jungle_log)
B(-2,15,3,minecraft:jungle_log)
B(-2,16,3,minecraft:jungle_log[axis=x])
B(-2,29,3,minecraft:jungle_leaves)
B(-2,30,3,minecraft:jungle_log[axis=x])
B(-2,31,3,minecraft:jungle_log)
B(-2,32,3,minecraft:jungle_log)
B(-2,33,3,minecraft:jungle_leaves)
B(-2,14,4,minecraft:jungle_log)
B(-2,15,4,minecraft:jungle_log)
B(-2,16,4,minecraft:jungle_log[axis=x])
B(-2,30,4,minecraft:jungle_log[axis=x])
B(-2,31,4,minecraft:jungle_log)
B(-2,32,4,minecraft:jungle_log[axis=z])
B(-2,30,5,minecraft:jungle_log[axis=x])
B(-2,31,5,minecraft:jungle_log)
B(-2,32,5,minecraft:jungle_log)
B(-2,1,6,minecraft:jungle_log)
B(-2,2,6,minecraft:jungle_log)
B(-2,3,6,minecraft:jungle_log)
B(-2,4,6,minecraft:jungle_log)
B(-2,5,6,minecraft:jungle_log[axis=x])
B(-2,30,6,minecraft:jungle_leaves)
B(-2,31,6,minecraft:jungle_log[axis=z])
B(-2,32,6,minecraft:jungle_leaves)
B(-2,0,7,minecraft:jungle_log)
B(-2,1,7,minecraft:jungle_log[axis=z])
B(-2,31,7,minecraft:jungle_leaves)
B(-1,28,-11,minecraft:jungle_leaves[distance=3,persistent=false])
B(-1,30,-11,minecraft:jungle_leaves)
B(-1,31,-11,minecraft:jungle_leaves[distance=2,persistent=false])
B(-1,22,-10,minecraft:jungle_leaves[distance=7,persistent=true])
B(-1,23,-10,minecraft:jungle_leaves[distance=7,persistent=true])
B(-1,24,-10,minecraft:jungle_leaves[distance=7,persistent=true])
B(-1,25,-10,minecraft:jungle_leaves[distance=7,persistent=true])
B(-1,26,-10,minecraft:jungle_leaves[distance=4,persistent=false])
B(-1,27,-10,minecraft:jungle_leaves[distance=3,persistent=false])
B(-1,28,-10,minecraft:jungle_leaves[distance=2,persistent=false])
B(-1,29,-10,minecraft:jungle_leaves)
B(-1,30,-10,minecraft:jungle_log)
B(-1,31,-10,minecraft:jungle_leaves)
B(-1,32,-10,minecraft:jungle_leaves[distance=2,persistent=false])
B(-1,28,-9,minecraft:jungle_leaves)
B(-1,29,-9,minecraft:jungle_log)
B(-1,30,-9,minecraft:jungle_log[axis=x])
B(-1,31,-9,minecraft:jungle_log)
B(-1,32,-9,minecraft:jungle_leaves)
B(-1,29,-8,minecraft:jungle_log[axis=x])
B(-1,30,-8,minecraft:jungle_log[axis=z])
B(-1,31,-8,minecraft:jungle_log[axis=x])
B(-1,32,-8,minecraft:jungle_log[axis=z])
B(-1,29,-7,minecraft:jungle_log[axis=x])
B(-1,30,-7,minecraft:jungle_log[axis=z])
B(-1,31,-7,minecraft:jungle_log[axis=x])
B(-1,32,-7,minecraft:jungle_log)
B(-1,33,-7,minecraft:jungle_leaves)
B(-1,30,-6,minecraft:jungle_log[axis=x])
B(-1,31,-6,minecraft:jungle_log[axis=z])
B(-1,32,-6,minecraft:jungle_log)
B(-1,33,-6,minecraft:jungle_leaves)
B(-1,15,-5,minecraft:jungle_log[axis=x])
B(-1,31,-5,minecraft:jungle_leaves)
B(-1,32,-5,minecraft:jungle_leaves)
B(-1,33,-5,minecraft:jungle_leaves[distance=2,persistent=false])
B(-1,10,-4,minecraft:jungle_log)
B(-1,11,-4,minecraft:jungle_log)
B(-1,12,-4,minecraft:jungle_log)
B(-1,13,-4,minecraft:jungle_log)
B(-1,14,-4,minecraft:jungle_log[axis=z])
B(-1,15,-4,minecraft:jungle_log[axis=z])
B(-1,16,-4,minecraft:jungle_log[axis=z])
B(-1,14,-3,minecraft:jungle_log[axis=x])
B(-1,15,-3,minecraft:jungle_log[axis=x])
B(-1,16,-3,minecraft:jungle_log[axis=x])
B(-1,17,-3,minecraft:jungle_leaves)
B(-1,28,-3,minecraft:jungle_leaves)
B(-1,30,-3,minecraft:jungle_leaves)
B(-1,15,-2,minecraft:jungle_log)
B(-1,16,-2,minecraft:jungle_log[axis=z])
B(-1,17,-2,minecraft:jungle_log)
B(-1,18,-2,minecraft:jungle_leaves)
B(-1,27,-2,minecraft:jungle_leaves)
B(-1,28,-2,minecraft:jungle_log[axis=z])
B(-1,29,-2,minecraft:jungle_log[axis=z])
B(-1,30,-2,minecraft:jungle_log[axis=x])
B(-1,31,-2,minecraft:jungle_leaves)
B(-1,15,-1,minecraft:jungle_log)
B(-1,16,-1,minecraft:jungle_log)
B(-1,17,-1,minecraft:jungle_log[axis=z])
B(-1,27,-1,minecraft:jungle_log)
B(-1,28,-1,minecraft:jungle_log[axis=x])
B(-1,29,-1,minecraft:jungle_log[axis=z])
B(-1,30,-1,minecraft:jungle_log)
B(-1,31,-1,minecraft:jungle_leaves)
B(-1,0,0,minecraft:jungle_log)
B(-1,1,0,minecraft:jungle_log)
B(-1,2,0,minecraft:jungle_log[axis=x])
B(-1,15,0,minecraft:jungle_log[axis=x])
B(-1,16,0,minecraft:jungle_log)
B(-1,17,0,minecraft:jungle_log[axis=z])
B(-1,18,0,minecraft:jungle_leaves)
B(-1,27,0,minecraft:jungle_leaves)
B(-1,28,0,minecraft:jungle_log)
B(-1,29,0,minecraft:jungle_log[axis=x])
B(-1,30,0,minecraft:jungle_log[axis=x])
B(-1,31,0,minecraft:jungle_leaves)
B(-1,14,1,minecraft:jungle_log[axis=x])
B(-1,15,1,minecraft:jungle_log[axis=x])
B(-1,16,1,minecraft:jungle_log)
B(-1,28,1,minecraft:jungle_leaves)
B(-1,29,1,minecraft:jungle_log[axis=x])
B(-1,30,1,minecraft:jungle_leaves)
B(-1,14,2,minecraft:jungle_log[axis=z])
B(-1,15,2,minecraft:jungle_log)
B(-1,16,2,minecraft:jungle_log[axis=x])
B(-1,17,2,minecraft:jungle_log[axis=x])
B(-1,29,2,minecraft:jungle_leaves)
B(-1,31,2,minecraft:jungle_leaves)
B(-1,32,2,minecraft:jungle_log[axis=z])
B(-1,33,2,minecraft:jungle_leaves)
B(-1,14,3,minecraft:jungle_log[axis=z])
B(-1,15,3,minecraft:jungle_log)
B(-1,16,3,minecraft:jungle_log)
B(-1,31,3,minecraft:jungle_log[axis=z])
B(-1,32,3,minecraft:jungle_log[axis=z])
B(-1,33,3,minecraft:jungle_log)
B(-1,34,3,minecraft:jungle_leaves)
B(-1,0,4,minecraft:jungle_log)
B(-1,1,4,minecraft:jungle_log)
B(-1,2,4,minecraft:jungle_log)
B(-1,3,4,minecraft:jungle_log)
B(-1,4,4,minecraft:jungle_log)
B(-1,5,4,minecraft:jungle_log)
B(-1,6,4,minecraft:jungle_log[axis=x])
B(-1,15,4,minecraft:jungle_log[axis=x])
B(-1,30,4,minecraft:jungle_log[axis=z])
B(-1,31,4,minecraft:jungle_log[axis=x])
B(-1,32,4,minecraft:jungle_log[axis=x])
B(-1,33,4,minecraft:jungle_leaves)
B(-1,30,5,minecraft:jungle_log)
B(-1,31,5,minecraft:jungle_log)
B(-1,32,5,minecraft:jungle_log[axis=x])
B(-1,30,6,minecraft:jungle_log[axis=x])
B(-1,31,6,minecraft:jungle_log[axis=x])
B(-1,32,6,minecraft:jungle_log[axis=z])
B(-1,31,7,minecraft:jungle_leaves)
B(-1,0,11,minecraft:jungle_log[axis=x])
B(0,28,-11,minecraft:jungle_leaves[distance=2,persistent=false])
B(0,29,-11,minecraft:jungle_leaves)
B(0,30,-11,minecraft:jungle_leaves)
B(0,31,-11,minecraft:jungle_leaves)
B(0,32,-11,minecraft:jungle_leaves[distance=2,persistent=false])
B(0,27,-10,minecraft:jungle_leaves[distance=2,persistent=false])
B(0,28,-10,minecraft:jungle_leaves)
B(0,29,-10,minecraft:jungle_log[axis=x])
B(0,30,-10,minecraft:jungle_log[axis=x])
B(0,31,-10,minecraft:jungle_log)
B(0,32,-10,minecraft:jungle_leaves)
B(0,28,-9,minecraft:jungle_log)
B(0,29,-9,minecraft:jungle_log)
B(0,30,-9,minecraft:jungle_log)
B(0,31,-9,minecraft:jungle_log)
B(0,32,-9,minecraft:jungle_leaves)
B(0,27,-8,minecraft:jungle_leaves[distance=2,persistent=false])
B(0,28,-8,minecraft:jungle_leaves)
B(0,29,-8,minecraft:jungle_log[axis=z])
B(0,30,-8,minecraft:jungle_log)
B(0,31,-8,minecraft:jungle_log[axis=x])
B(0,28,-7,minecraft:jungle_leaves[distance=2,persistent=false])
B(0,30,-7,minecraft:jungle_log[axis=x])
B(0,31,-7,minecraft:jungle_log[axis=z])
B(0,32,-7,minecraft:jungle_log[axis=z])
B(0,31,-6,minecraft:jungle_log)
B(0,32,-6,minecraft:jungle_leaves)
B(0,33,-6,minecraft:jungle_leaves[distance=2,persistent=false])
B(0,32,-5,minecraft:jungle_leaves[distance=2,persistent=false])
B(0,3,-3,minecraft:jungle_log)
B(0,4,-3,minecraft:jungle_log)
B(0,5,-3,minecraft:jungle_log)
B(0,6,-3,minecraft:jungle_log)
B(0,7,-3,minecraft:jungle_log[axis=z])
B(0,15,-3,minecraft:jungle_log)
B(0,17,-3,minecraft:jungle_log)
B(0,18,-3,minecraft:jungle_leaves)
B(0,27,-3,minecraft:jungle_leaves)
B(0,29,-3,minecraft:jungle_leaves)
B(0,30,-3,minecraft:jungle_leaves[distance=2,persistent=false])
B(0,31,-3,minecraft:jungle_leaves[distance=3,persistent=false])
B(0,7,-2,minecraft:jungle_log)
B(0,8,-2,minecraft:jungle_log)
B(0,9,-2,minecraft:jungle_log)
B(0,10,-2,minecraft:jungle_log)
B(0,11,-2,minecraft:jungle_log)
B(0,12,-2,minecraft:jungle_log)
B(0,13,-2,minecraft:jungle_log)
B(0,14,-2,minecraft:jungle_log[axis=z])
B(0,15,-2,minecraft:jungle_log[axis=z])
B(0,16,-2,minecraft:jungle_log[axis=z])
B(0,17,-2,minecraft:jungle_log)
B(0,18,-2,minecraft:jungle_log[axis=z])
B(0,19,-2,minecraft:jungle_leaves)
B(0,25,-2,minecraft:jungle_leaves[distance=2,persistent=false])
B(0,26,-2,minecraft:jungle_leaves)
B(0,27,-2,minecraft:jungle_log)
B(0,28,-2,minecraft:jungle_log[axis=x])
B(0,29,-2,minecraft:jungle_log[axis=x])
B(0,30,-2,minecraft:jungle_leaves)
B(0,31,-2,minecraft:jungle_leaves[distance=2,persistent=false])
B(0,15,-1,minecraft:jungle_log[axis=x])
B(0,16,-1,minecraft:jungle_log[axis=x])
B(0,17,-1,minecraft:jungle_log[axis=x])
B(0,18,-1,minecraft:jungle_log)
B(0,19,-1,minecraft:jungle_log)
B(0,26,-1,minecraft:jungle_log[axis=z])
B(0,27,-1,minecraft:jungle_log[axis=z])
B(0,28,-1,minecraft:jungle_log[axis=z])
B(0,29,-1,minecraft:jungle_log[axis=z])
B(0,30,-1,minecraft:jungle_log)
B(0,31,-1,minecraft:jungle_leaves)
B(0,9,0,minecraft:jungle_log)
B(0,10,0,minecraft:jungle_log)
B(0,11,0,minecraft:jungle_log)
B(0,12,0,minecraft:jungle_log)
B(0,13,0,minecraft:jungle_log)
B(0,14,0,minecraft:jungle_log)
B(0,15,0,minecraft:jungle_log)
B(0,16,0,minecraft:jungle_log[axis=x])
B(0,17,0,minecraft:jungle_log[axis=x])
B(0,18,0,minecraft:jungle_log[axis=z])
B(0,19,0,minecraft:jungle_leaves)
B(0,20,0,minecraft:jungle_leaves)
B(0,26,0,minecraft:jungle_leaves)
B(0,27,0,minecraft:jungle_log)
B(0,28,0,minecraft:jungle_log[axis=z])
B(0,29,0,minecraft:jungle_log[axis=z])
B(0,30,0,minecraft:jungle_leaves)
B(0,15,1,minecraft:jungle_log[axis=x])
B(0,16,1,minecraft:jungle_log[axis=z])
B(0,17,1,minecraft:jungle_log)
B(0,18,1,minecraft:jungle_log[axis=z])
B(0,19,1,minecraft:jungle_log[axis=z])
B(0,27,1,minecraft:jungle_leaves)
B(0,28,1,minecraft:jungle_leaves)
B(0,29,1,minecraft:jungle_leaves)
B(0,33,1,minecraft:jungle_leaves)
B(0,14,2,minecraft:jungle_log[axis=z])
B(0,15,2,minecraft:jungle_log[axis=x])
B(0,16,2,minecraft:jungle_log[axis=x])
B(0,17,2,minecraft:jungle_log[axis=z])
B(0,18,2,minecraft:jungle_log[axis=x])
B(0,31,2,minecraft:jungle_log)
B(0,32,2,minecraft:jungle_log[axis=z])
B(0,33,2,minecraft:jungle_log)
B(0,34,2,minecraft:jungle_leaves)
B(0,7,3,minecraft:jungle_log)
B(0,8,3,minecraft:jungle_log)
B(0,9,3,minecraft:jungle_log)
B(0,10,3,minecraft:jungle_log[axis=x])
B(0,15,3,minecraft:jungle_log)
B(0,16,3,minecraft:jungle_log[axis=x])
B(0,17,3,minecraft:jungle_log[axis=z])
B(0,30,3,minecraft:jungle_log)
B(0,31,3,minecraft:jungle_log[axis=z])
B(0,32,3,minecraft:jungle_log[axis=x])
B(0,33,3,minecraft:jungle_log[axis=z])
B(0,6,4,minecraft:jungle_log)
B(0,7,4,minecraft:jungle_log[axis=z])
B(0,30,4,minecraft:jungle_log[axis=x])
B(0,31,4,minecraft:jungle_log)
B(0,32,4,minecraft:jungle_log[axis=z])
B(0,33,4,minecraft:jungle_log)
B(0,30,5,minecraft:jungle_log[axis=x])
B(0,31,5,minecraft:jungle_log)
B(0,32,5,minecraft:jungle_log[axis=x])
B(0,25,6,minecraft:jungle_leaves[distance=7,persistent=true])
B(0,26,6,minecraft:jungle_leaves[distance=5,persistent=false])
B(0,27,6,minecraft:jungle_leaves[distance=4,persistent=false])
B(0,28,6,minecraft:jungle_leaves[distance=3,persistent=false])
B(0,29,6,minecraft:jungle_leaves[distance=2,persistent=false])
B(0,30,6,minecraft:jungle_leaves)
B(0,31,6,minecraft:jungle_log[axis=x])
B(0,32,6,minecraft:jungle_leaves)
B(0,33,6,minecraft:jungle_leaves[distance=2,persistent=false])
B(0,31,7,minecraft:jungle_leaves)
B(0,32,7,minecraft:jungle_leaves[distance=2,persistent=false])
B(0,0,10,minecraft:jungle_log[axis=x])
B(0,0,11,minecraft:jungle_log[axis=x])
B(0,1,11,minecraft:jungle_log[axis=z])
B(0,0,12,minecraft:jungle_log)
B(1,29,-12,minecraft:jungle_leaves)
B(1,28,-11,minecraft:jungle_leaves)
B(1,29,-11,minecraft:jungle_log)
B(1,30,-11,minecraft:jungle_leaves)
B(1,31,-11,minecraft:jungle_leaves[distance=2,persistent=false])
B(1,26,-10,minecraft:jungle_leaves[distance=2,persistent=false])
B(1,27,-10,minecraft:jungle_leaves)
B(1,28,-10,minecraft:jungle_log[axis=x])
B(1,29,-10,minecraft:jungle_log)
B(1,30,-10,minecraft:jungle_log[axis=x])
B(1,31,-10,minecraft:jungle_leaves)
B(1,32,-10,minecraft:jungle_leaves[distance=2,persistent=false])
B(1,27,-9,minecraft:jungle_leaves)
B(1,28,-9,minecraft:jungle_log[axis=x])
B(1,29,-9,minecraft:jungle_log[axis=z])
B(1,30,-9,minecraft:jungle_log[axis=x])
B(1,31,-9,minecraft:jungle_log)
B(1,27,-8,minecraft:jungle_leaves)
B(1,28,-8,minecraft:jungle_log[axis=x])
B(1,29,-8,minecraft:jungle_log[axis=x])
B(1,30,-8,minecraft:jungle_log)
B(1,31,-8,minecraft:jungle_log[axis=z])
B(1,0,-7,minecraft:jungle_log)
B(1,1,-7,minecraft:jungle_log)
B(1,2,-7,minecraft:jungle_log[axis=z])
B(1,27,-7,minecraft:jungle_leaves[distance=2,persistent=false])
B(1,28,-7,minecraft:jungle_leaves)
B(1,29,-7,minecraft:jungle_log[axis=x])
B(1,30,-7,minecraft:jungle_log[axis=x])
B(1,31,-7,minecraft:jungle_log)
B(1,2,-6,minecraft:jungle_log)
B(1,3,-6,minecraft:jungle_log)
B(1,4,-6,minecraft:jungle_log[axis=x])
B(1,15,-4,minecraft:jungle_log[axis=x])
B(1,16,-4,minecraft:jungle_log[axis=x])
B(1,18,-4,minecraft:jungle_log)
B(1,0,-3,minecraft:jungle_log)
B(1,1,-3,minecraft:jungle_log)
B(1,2,-3,minecraft:jungle_log)
B(1,3,-3,minecraft:jungle_log[axis=x])
B(1,14,-3,minecraft:jungle_log[axis=x])
B(1,15,-3,minecraft:jungle_log)
B(1,16,-3,minecraft:jungle_log[axis=z])
B(1,17,-3,minecraft:jungle_log[axis=x])
B(1,18,-3,minecraft:jungle_log[axis=x])
B(1,19,-3,minecraft:jungle_log[axis=z])
B(1,26,-3,minecraft:jungle_leaves)
B(1,27,-3,minecraft:jungle_leaves)
B(1,28,-3,minecraft:jungle_leaves)
B(1,30,-3,minecraft:jungle_leaves[distance=3,persistent=false])
B(1,14,-2,minecraft:jungle_log[axis=x])
B(1,15,-2,minecraft:jungle_log)
B(1,16,-2,minecraft:jungle_log[axis=z])
B(1,17,-2,minecraft:jungle_log[axis=z])
B(1,18,-2,minecraft:jungle_log)
B(1,19,-2,minecraft:jungle_log)
B(1,20,-2,minecraft:jungle_log[axis=z])
B(1,21,-2,minecraft:jungle_log[axis=x])
B(1,26,-2,minecraft:jungle_log[axis=x])
B(1,27,-2,minecraft:jungle_log)
B(1,28,-2,minecraft:jungle_log)
B(1,29,-2,minecraft:jungle_leaves)
B(1,30,-2,minecraft:jungle_leaves[distance=2,persistent=false])
B(1,31,-2,minecraft:jungle_leaves[distance=3,persistent=false])
B(1,14,-1,minecraft:jungle_log[axis=x])
B(1,15,-1,minecraft:jungle_log[axis=z])
B(1,16,-1,minecraft:jungle_log[axis=z])
B(1,17,-1,minecraft:jungle_log)
B(1,18,-1,minecraft:jungle_log[axis=x])
B(1,19,-1,minecraft:jungle_log[axis=x])
B(1,20,-1,minecraft:jungle_log)
B(1,21,-1,minecraft:jungle_log)
B(1,22,-1,minecraft:jungle_log)
B(1,25,-1,minecraft:jungle_log)
B(1,26,-1,minecraft:jungle_log[axis=z])
B(1,27,-1,minecraft:jungle_log[axis=z])
B(1,28,-1,minecraft:jungle_log)
B(1,29,-1,minecraft:jungle_log[axis=z])
B(1,30,-1,minecraft:jungle_leaves)
B(1,15,0,minecraft:jungle_log[axis=z])
B(1,16,0,minecraft:jungle_log)
B(1,17,0,minecraft:jungle_log[axis=z])
B(1,18,0,minecraft:jungle_log)
B(1,19,0,minecraft:jungle_log[axis=x])
B(1,20,0,minecraft:jungle_log[axis=x])
B(1,21,0,minecraft:jungle_log[axis=z])
B(1,22,0,minecraft:jungle_leaves)
B(1,23,0,minecraft:jungle_leaves[distance=2,persistent=false])
B(1,26,0,minecraft:jungle_log)
B(1,27,0,minecraft:jungle_log)
B(1,28,0,minecraft:jungle_log[axis=x])
B(1,16,1,minecraft:jungle_log[axis=x])
B(1,17,1,minecraft:jungle_log[axis=x])
B(1,18,1,minecraft:jungle_log)
B(1,19,1,minecraft:jungle_log)
B(1,20,1,minecraft:jungle_leaves)
B(1,22,1,minecraft:jungle_leaves[distance=2,persistent=false])
B(1,25,1,minecraft:jungle_leaves[distance=2,persistent=false])
B(1,26,1,minecraft:jungle_leaves)
B(1,27,1,minecraft:jungle_leaves)
B(1,28,1,minecraft:jungle_leaves)
B(1,32,1,minecraft:jungle_leaves)
B(1,10,2,minecraft:jungle_log)
B(1,11,2,minecraft:jungle_log)
B(1,12,2,minecraft:jungle_log)
B(1,13,2,minecraft:jungle_log)
B(1,14,2,minecraft:jungle_log)
B(1,15,2,minecraft:jungle_log[axis=z])
B(1,16,2,minecraft:jungle_log)
B(1,17,2,minecraft:jungle_log[axis=z])
B(1,18,2,minecraft:jungle_log[axis=x])
B(1,19,2,minecraft:jungle_log[axis=x])
B(1,26,2,minecraft:jungle_leaves[distance=2,persistent=false])
B(1,31,2,minecraft:jungle_leaves)
B(1,32,2,minecraft:jungle_log[axis=z])
B(1,33,2,minecraft:jungle_leaves)
B(1,10,3,minecraft:jungle_log[axis=z])
B(1,16,3,minecraft:jungle_log[axis=x])
B(1,31,3,minecraft:jungle_log[axis=x])
B(1,32,3,minecraft:jungle_log)
B(1,33,3,minecraft:jungle_log[axis=z])
B(1,0,4,minecraft:jungle_log)
B(1,1,4,minecraft:jungle_log)
B(1,2,4,minecraft:jungle_log)
B(1,3,4,minecraft:jungle_log)
B(1,4,4,minecraft:jungle_log[axis=x])
B(1,30,4,minecraft:jungle_log[axis=z])
B(1,31,4,minecraft:jungle_log[axis=x])
B(1,32,4,minecraft:jungle_log[axis=z])
B(1,33,4,minecraft:jungle_leaves)
B(1,31,5,minecraft:jungle_log[axis=z])
B(1,32,5,minecraft:jungle_leaves)
B(1,31,6,minecraft:jungle_leaves)
B(1,32,6,minecraft:jungle_leaves[distance=2,persistent=false])
B(1,0,8,minecraft:jungle_log[axis=z])
B(1,0,9,minecraft:jungle_log)
B(1,1,9,minecraft:jungle_log)
B(1,0,10,minecraft:jungle_log)
B(1,1,10,minecraft:jungle_log[axis=z])
B(1,0,11,minecraft:jungle_log[axis=z])
B(2,28,-12,minecraft:jungle_leaves)
B(2,29,-12,minecraft:jungle_leaves)
B(2,30,-12,minecraft:jungle_leaves)
B(2,26,-11,minecraft:jungle_leaves[distance=2,persistent=false])
B(2,27,-11,minecraft:jungle_leaves)
B(2,28,-11,minecraft:jungle_log[axis=x])
B(2,29,-11,minecraft:jungle_log[axis=z])
B(2,30,-11,minecraft:jungle_log[axis=z])
B(2,21,-10,minecraft:jungle_leaves[distance=7,persistent=true])
B(2,22,-10,minecraft:jungle_leaves[distance=5,persistent=false])
B(2,23,-10,minecraft:jungle_leaves[distance=4,persistent=false])
B(2,24,-10,minecraft:jungle_leaves[distance=3,persistent=false])
B(2,25,-10,minecraft:jungle_leaves[distance=2,persistent=false])
B(2,26,-10,minecraft:jungle_leaves)
B(2,27,-10,minecraft:jungle_log)
B(2,28,-10,minecraft:jungle_log[axis=z])
B(2,29,-10,minecraft:jungle_log[axis=z])
B(2,30,-10,minecraft:jungle_log[axis=x])
B(2,31,-10,minecraft:jungle_leaves)
B(2,26,-9,minecraft:jungle_log)
B(2,27,-9,minecraft:jungle_log)
B(2,28,-9,minecraft:jungle_log)
B(2,29,-9,minecraft:jungle_log[axis=z])
B(2,30,-9,minecraft:jungle_log)
B(2,25,-8,minecraft:jungle_leaves[distance=2,persistent=false])
B(2,26,-8,minecraft:jungle_leaves)
B(2,27,-8,minecraft:jungle_log[axis=z])
B(2,28,-8,minecraft:jungle_leaves)
B(2,29,-8,minecraft:jungle_log[axis=x])
B(2,30,-8,minecraft:jungle_log[axis=z])
B(2,31,-8,minecraft:jungle_log[axis=z])
B(2,26,-7,minecraft:jungle_leaves[distance=2,persistent=false])
B(2,28,-7,minecraft:jungle_leaves[distance=2,persistent=false])
B(2,30,-7,minecraft:jungle_log)
B(2,4,-6,minecraft:jungle_log)
B(2,5,-6,minecraft:jungle_log)
B(2,6,-6,minecraft:jungle_log)
B(2,7,-6,minecraft:jungle_log)
B(2,8,-6,minecraft:jungle_log[axis=z])
B(2,8,-5,minecraft:jungle_log)
B(2,9,-5,minecraft:jungle_log)
B(2,10,-5,minecraft:jungle_log)
B(2,11,-5,minecraft:jungle_log)
B(2,12,-5,minecraft:jungle_log)
B(2,13,-5,minecraft:jungle_log)
B(2,14,-5,minecraft:jungle_log)
B(2,15,-5,minecraft:jungle_log[axis=z])
B(2,14,-4,minecraft:jungle_log)
B(2,15,-4,minecraft:jungle_log)
B(2,16,-4,minecraft:jungle_log[axis=x])
B(2,17,-4,minecraft:jungle_log)
B(2,18,-4,minecraft:jungle_log)
B(2,19,-4,minecraft:jungle_log)
B(2,25,-4,minecraft:jungle_leaves)
B(2,26,-4,minecraft:jungle_leaves)
B(2,9,-3,minecraft:jungle_log)
B(2,10,-3,minecraft:jungle_log)
B(2,11,-3,minecraft:jungle_log)
B(2,12,-3,minecraft:jungle_log)
B(2,13,-3,minecraft:jungle_log)
B(2,14,-3,minecraft:jungle_log[axis=x])
B(2,15,-3,minecraft:jungle_log[axis=z])
B(2,16,-3,minecraft:jungle_log[axis=x])
B(2,17,-3,minecraft:jungle_log[axis=x])
B(2,18,-3,minecraft:jungle_log)
B(2,19,-3,minecraft:jungle_log[axis=z])
B(2,25,-3,minecraft:jungle_log)
B(2,26,-3,minecraft:jungle_leaves)
B(2,27,-3,minecraft:jungle_leaves)
B(2,28,-3,minecraft:jungle_leaves[distance=2,persistent=false])
B(2,14,-2,minecraft:jungle_log)
B(2,15,-2,minecraft:jungle_log)
B(2,16,-2,minecraft:jungle_log[axis=x])
B(2,17,-2,minecraft:jungle_log[axis=x])
B(2,18,-2,minecraft:jungle_log[axis=x])
B(2,19,-2,minecraft:jungle_log[axis=z])
B(2,20,-2,minecraft:jungle_log[axis=z])
B(2,21,-2,minecraft:jungle_log[axis=z])
B(2,22,-2,minecraft:jungle_log[axis=z])
B(2,24,-2,minecraft:jungle_log)
B(2,25,-2,minecraft:jungle_log[axis=z])
B(2,26,-2,minecraft:jungle_log)
B(2,27,-2,minecraft:jungle_log)
B(2,28,-2,minecraft:jungle_leaves)
B(2,14,-1,minecraft:jungle_log)
B(2,15,-1,minecraft:jungle_log)
B(2,16,-1,minecraft:jungle_log[axis=z])
B(2,17,-1,minecraft:jungle_log)
B(2,18,-1,minecraft:jungle_log[axis=z])
B(2,19,-1,minecraft:jungle_log[axis=z])
B(2,20,-1,minecraft:jungle_log)
B(2,21,-1,minecraft:jungle_log[axis=z])
B(2,22,-1,minecraft:jungle_log[axis=x])
B(2,23,-1,minecraft:jungle_log[axis=z])
B(2,24,-1,minecraft:jungle_log[axis=x])
B(2,25,-1,minecraft:jungle_log[axis=z])
B(2,26,-1,minecraft:jungle_log[axis=x])
B(2,27,-1,minecraft:jungle_log)
B(2,28,-1,minecraft:jungle_log[axis=z])
B(2,10,0,minecraft:jungle_log)
B(2,11,0,minecraft:jungle_log)
B(2,12,0,minecraft:jungle_log)
B(2,13,0,minecraft:jungle_log)
B(2,14,0,minecraft:jungle_log)
B(2,15,0,minecraft:jungle_log)
B(2,16,0,minecraft:jungle_log[axis=z])
B(2,17,0,minecraft:jungle_log)
B(2,18,0,minecraft:jungle_log)
B(2,19,0,minecraft:jungle_log[axis=x])
B(2,20,0,minecraft:jungle_log[axis=x])
B(2,21,0,minecraft:jungle_log)
B(2,22,0,minecraft:jungle_log)
B(2,23,0,minecraft:jungle_leaves)
B(2,24,0,minecraft:jungle_leaves)
B(2,25,0,minecraft:jungle_log[axis=x])
B(2,26,0,minecraft:jungle_log)
B(2,27,0,minecraft:jungle_log[axis=z])
B(2,28,0,minecraft:jungle_leaves)
B(2,15,1,minecraft:jungle_leaves)
B(2,16,1,minecraft:jungle_leaves)
B(2,17,1,minecraft:jungle_log)
B(2,18,1,minecraft:jungle_log)
B(2,19,1,minecraft:jungle_log[axis=x])
B(2,21,1,minecraft:jungle_leaves)
B(2,22,1,minecraft:jungle_leaves)
B(2,23,1,minecraft:jungle_leaves[distance=2,persistent=false])
B(2,24,1,minecraft:jungle_leaves[distance=2,persistent=false])
B(2,25,1,minecraft:jungle_leaves)
B(2,26,1,minecraft:jungle_leaves)
B(2,27,1,minecraft:jungle_leaves)
B(2,17,2,minecraft:jungle_leaves)
B(2,18,2,minecraft:jungle_log)
B(2,25,2,minecraft:jungle_leaves[distance=2,persistent=false])
B(2,26,2,minecraft:jungle_leaves[distance=2,persistent=false])
B(2,27,2,minecraft:jungle_leaves[distance=2,persistent=false])
B(2,32,2,minecraft:jungle_leaves)
B(2,32,3,minecraft:jungle_leaves)
B(2,4,4,minecraft:jungle_log)
B(2,5,4,minecraft:jungle_log)
B(2,6,4,minecraft:jungle_log)
B(2,7,4,minecraft:jungle_log[axis=x])
B(2,32,4,minecraft:jungle_leaves)
B(2,4,6,minecraft:jungle_log)
B(2,5,6,minecraft:jungle_log[axis=x])
B(2,0,7,minecraft:jungle_log[axis=z])
B(2,2,7,minecraft:jungle_log[axis=z])
B(2,3,7,minecraft:jungle_log)
B(2,4,7,minecraft:jungle_log[axis=x])
B(2,0,8,minecraft:jungle_log[axis=x])
B(2,1,8,minecraft:jungle_log[axis=x])
B(2,2,8,minecraft:jungle_log[axis=x])
B(2,0,9,minecraft:jungle_log[axis=x])
B(2,1,9,minecraft:jungle_log[axis=x])
B(2,2,9,minecraft:jungle_log[axis=z])
B(2,0,10,minecraft:jungle_log[axis=x])
B(2,1,10,minecraft:jungle_log[axis=x])
B(3,27,-12,minecraft:jungle_leaves)
B(3,28,-12,minecraft:jungle_leaves)
B(3,29,-12,minecraft:jungle_leaves)
B(3,25,-11,minecraft:jungle_leaves[distance=2,persistent=false])
B(3,26,-11,minecraft:jungle_leaves)
B(3,27,-11,minecraft:jungle_log)
B(3,28,-11,minecraft:jungle_log[axis=z])
B(3,29,-11,minecraft:jungle_log[axis=z])
B(3,30,-11,minecraft:jungle_leaves)
B(3,31,-11,minecraft:jungle_leaves[distance=2,persistent=false])
B(3,25,-10,minecraft:jungle_leaves)
B(3,26,-10,minecraft:jungle_log)
B(3,27,-10,minecraft:jungle_log[axis=x])
B(3,28,-10,minecraft:jungle_log)
B(3,29,-10,minecraft:jungle_log)
B(3,30,-10,minecraft:jungle_log[axis=x])
B(3,31,-10,minecraft:jungle_leaves)
B(3,25,-9,minecraft:jungle_log)
B(3,26,-9,minecraft:jungle_log[axis=x])
B(3,27,-9,minecraft:jungle_log[axis=x])
B(3,28,-9,minecraft:jungle_log[axis=z])
B(3,29,-9,minecraft:jungle_log)
B(3,30,-9,minecraft:jungle_leaves)
B(3,31,-9,minecraft:jungle_leaves[distance=2,persistent=false])
B(3,25,-8,minecraft:jungle_leaves)
B(3,26,-8,minecraft:jungle_log[axis=z])
B(3,27,-8,minecraft:jungle_log[axis=z])
B(3,28,-8,minecraft:jungle_log[axis=z])
B(3,30,-8,minecraft:jungle_leaves)
B(3,25,-7,minecraft:jungle_leaves[distance=2,persistent=false])
B(3,26,-7,minecraft:jungle_leaves)
B(3,27,-7,minecraft:jungle_leaves)
B(3,28,-7,minecraft:jungle_leaves)
B(3,29,-7,minecraft:jungle_leaves[distance=2,persistent=false])
B(3,14,-6,minecraft:jungle_log[axis=x])
B(3,25,-6,minecraft:jungle_leaves)
B(3,26,-6,minecraft:jungle_leaves)
B(3,28,-6,minecraft:jungle_leaves[distance=2,persistent=false])
B(3,13,-5,minecraft:jungle_log)
B(3,14,-5,minecraft:jungle_log[axis=x])
B(3,15,-5,minecraft:jungle_log)
B(3,16,-5,minecraft:jungle_log[axis=x])
B(3,18,-5,minecraft:jungle_leaves)
B(3,19,-5,minecraft:jungle_leaves[distance=2,persistent=false])
B(3,25,-5,minecraft:jungle_log[axis=x])
B(3,26,-5,minecraft:jungle_leaves)
B(3,27,-5,minecraft:jungle_leaves[distance=2,persistent=false])
B(3,14,-4,minecraft:jungle_log)
B(3,15,-4,minecraft:jungle_log[axis=z])
B(3,16,-4,minecraft:jungle_log[axis=z])
B(3,17,-4,minecraft:jungle_log)
B(3,18,-4,minecraft:jungle_log[axis=x])
B(3,19,-4,minecraft:jungle_leaves)
B(3,20,-4,minecraft:jungle_leaves[distance=2,persistent=false])
B(3,24,-4,minecraft:jungle_log)
B(3,25,-4,minecraft:jungle_log)
B(3,26,-4,minecraft:jungle_log)
B(3,27,-4,minecraft:jungle_leaves)
B(3,14,-3,minecraft:jungle_log[axis=z])
B(3,15,-3,minecraft:jungle_log[axis=z])
B(3,16,-3,minecraft:jungle_log)
B(3,17,-3,minecraft:jungle_log[axis=x])
B(3,18,-3,minecraft:jungle_log[axis=z])
B(3,19,-3,minecraft:jungle_log[axis=x])
B(3,24,-3,minecraft:jungle_log[axis=x])
B(3,25,-3,minecraft:jungle_log)
B(3,26,-3,minecraft:jungle_log[axis=z])
B(3,27,-3,minecraft:jungle_leaves)
B(3,28,-3,minecraft:jungle_leaves[distance=2,persistent=false])
B(3,11,-2,minecraft:jungle_log)
B(3,12,-2,minecraft:jungle_log)
B(3,13,-2,minecraft:jungle_log)
B(3,14,-2,minecraft:jungle_log)
B(3,15,-2,minecraft:jungle_log[axis=x])
B(3,16,-2,minecraft:jungle_log[axis=x])
B(3,17,-2,minecraft:jungle_log)
B(3,18,-2,minecraft:jungle_log[axis=x])
B(3,19,-2,minecraft:jungle_log[axis=x])
B(3,20,-2,minecraft:jungle_log[axis=z])
B(3,21,-2,minecraft:jungle_log[axis=x])
B(3,22,-2,minecraft:jungle_log)
B(3,23,-2,minecraft:jungle_log[axis=z])
B(3,24,-2,minecraft:jungle_log)
B(3,25,-2,minecraft:jungle_log)
B(3,26,-2,minecraft:jungle_log[axis=z])
B(3,27,-2,minecraft:jungle_leaves)
B(3,28,-2,minecraft:jungle_leaves[distance=2,persistent=false])
B(3,14,-1,minecraft:jungle_log[axis=x])
B(3,15,-1,minecraft:jungle_log[axis=z])
B(3,16,-1,minecraft:jungle_log[axis=z])
B(3,17,-1,minecraft:jungle_log)
B(3,18,-1,minecraft:jungle_log[axis=z])
B(3,19,-1,minecraft:jungle_log[axis=z])
B(3,20,-1,minecraft:jungle_log)
B(3,21,-1,minecraft:jungle_log)
B(3,22,-1,minecraft:jungle_log[axis=x])
B(3,23,-1,minecraft:jungle_log[axis=z])
B(3,24,-1,minecraft:jungle_log)
B(3,25,-1,minecraft:jungle_log[axis=x])
B(3,26,-1,minecraft:jungle_log[axis=z])
B(3,27,-1,minecraft:jungle_log)
B(3,14,0,minecraft:jungle_log[axis=z])
B(3,15,0,minecraft:jungle_log)
B(3,16,0,minecraft:jungle_log[axis=z])
B(3,17,0,minecraft:jungle_log[axis=z])
B(3,19,0,minecraft:jungle_log[axis=z])
B(3,20,0,minecraft:jungle_log[axis=z])
B(3,21,0,minecraft:jungle_log)
B(3,22,0,minecraft:jungle_log)
B(3,23,0,minecraft:jungle_log[axis=z])
B(3,24,0,minecraft:jungle_log)
B(3,25,0,minecraft:jungle_log[axis=x])
B(3,26,0,minecraft:jungle_log)
B(3,8,1,minecraft:jungle_log)
B(3,9,1,minecraft:jungle_log)
B(3,10,1,minecraft:jungle_log)
B(3,11,1,minecraft:jungle_log)
B(3,12,1,minecraft:jungle_log)
B(3,13,1,minecraft:jungle_log[axis=z])
B(3,14,1,minecraft:jungle_log[axis=z])
B(3,15,1,minecraft:jungle_log[axis=z])
B(3,16,1,minecraft:jungle_leaves)
B(3,17,1,minecraft:jungle_leaves)
B(3,22,1,minecraft:jungle_leaves)
B(3,23,1,minecraft:jungle_leaves)
B(3,24,1,minecraft:jungle_leaves)
B(3,25,1,minecraft:jungle_leaves)
B(3,26,1,minecraft:jungle_leaves)
B(3,27,1,minecraft:jungle_leaves[distance=2,persistent=false])
B(3,13,2,minecraft:jungle_log[axis=z])
B(3,14,2,minecraft:jungle_log[axis=x])
B(3,15,2,minecraft:jungle_leaves)
B(3,26,2,minecraft:jungle_leaves[distance=2,persistent=false])
B(3,7,4,minecraft:jungle_log)
B(3,8,4,minecraft:jungle_log[axis=x])
B(3,4,5,minecraft:jungle_log[axis=z])
B(3,5,5,minecraft:jungle_log)
B(3,6,5,minecraft:jungle_log[axis=x])
B(3,0,6,minecraft:jungle_log[axis=x])
B(3,2,6,minecraft:jungle_log[axis=z])
B(3,3,6,minecraft:jungle_log[axis=z])
B(3,4,6,minecraft:jungle_log)
B(3,5,6,minecraft:jungle_log[axis=x])
B(3,6,6,minecraft:jungle_log[axis=x])
B(3,0,7,minecraft:jungle_log[axis=x])
B(3,1,7,minecraft:jungle_log[axis=x])
B(3,2,7,minecraft:jungle_log[axis=z])
B(3,3,7,minecraft:jungle_log[axis=z])
B(3,4,7,minecraft:jungle_log[axis=x])
B(3,5,7,minecraft:jungle_log)
B(3,0,8,minecraft:jungle_log)
B(3,1,8,minecraft:jungle_log[axis=x])
B(3,2,8,minecraft:jungle_log)
B(3,3,8,minecraft:jungle_log[axis=x])
B(3,4,8,minecraft:jungle_log[axis=z])
B(3,0,9,minecraft:jungle_log[axis=x])
B(3,1,9,minecraft:jungle_log)
B(3,2,9,minecraft:jungle_log[axis=x])
B(4,25,-12,minecraft:jungle_leaves[distance=2,persistent=false])
B(4,28,-12,minecraft:jungle_leaves)
B(4,24,-11,minecraft:jungle_leaves[distance=2,persistent=false])
B(4,25,-11,minecraft:jungle_leaves)
B(4,26,-11,minecraft:jungle_leaves)
B(4,27,-11,minecraft:jungle_leaves)
B(4,28,-11,minecraft:jungle_log[axis=x])
B(4,29,-11,minecraft:jungle_leaves)
B(4,30,-11,minecraft:jungle_leaves[distance=2,persistent=false])
B(4,24,-10,minecraft:jungle_leaves)
B(4,25,-10,minecraft:jungle_log[axis=x])
B(4,26,-10,minecraft:jungle_log)
B(4,27,-10,minecraft:jungle_log)
B(4,28,-10,minecraft:jungle_log[axis=x])
B(4,29,-10,minecraft:jungle_log[axis=z])
B(4,30,-10,minecraft:jungle_leaves)
B(4,31,-10,minecraft:jungle_leaves[distance=2,persistent=false])
B(4,25,-9,minecraft:jungle_log)
B(4,26,-9,minecraft:jungle_log)
B(4,27,-9,minecraft:jungle_log[axis=x])
B(4,28,-9,minecraft:jungle_log[axis=z])
B(4,29,-9,minecraft:jungle_leaves)
B(4,30,-9,minecraft:jungle_leaves[distance=2,persistent=false])
B(4,31,-9,minecraft:jungle_leaves[distance=3,persistent=false])
B(4,24,-8,minecraft:jungle_leaves)
B(4,25,-8,minecraft:jungle_log[axis=z])
B(4,26,-8,minecraft:jungle_log)
B(4,27,-8,minecraft:jungle_log)
B(4,28,-8,minecraft:jungle_leaves)
B(4,29,-8,minecraft:jungle_leaves[distance=2,persistent=false])
B(4,30,-8,minecraft:jungle_leaves[distance=2,persistent=false])
B(4,31,-8,minecraft:jungle_leaves[distance=3,persistent=false])
B(4,25,-7,minecraft:jungle_leaves)
B(4,26,-7,minecraft:jungle_log[axis=z])
B(4,27,-7,minecraft:jungle_leaves)
B(4,28,-7,minecraft:jungle_leaves[distance=2,persistent=false])
B(4,29,-7,minecraft:jungle_leaves[distance=3,persistent=false])
B(4,0,-6,minecraft:jungle_log)
B(4,1,-6,minecraft:jungle_log)
B(4,2,-6,minecraft:jungle_log)
B(4,3,-6,minecraft:jungle_log)
B(4,4,-6,minecraft:jungle_log)
B(4,5,-6,minecraft:jungle_log)
B(4,6,-6,minecraft:jungle_log[axis=x])
B(4,13,-6,minecraft:jungle_log[axis=z])
B(4,14,-6,minecraft:jungle_log[axis=x])
B(4,15,-6,minecraft:jungle_log[axis=z])
B(4,16,-6,minecraft:jungle_leaves)
B(4,24,-6,minecraft:jungle_leaves)
B(4,25,-6,minecraft:jungle_log)
B(4,26,-6,minecraft:jungle_log)
B(4,27,-6,minecraft:jungle_log[axis=z])
B(4,28,-6,minecraft:jungle_leaves)
B(4,29,-6,minecraft:jungle_leaves[distance=2,persistent=false])
B(4,12,-5,minecraft:jungle_log)
B(4,13,-5,minecraft:jungle_log[axis=x])
B(4,14,-5,minecraft:jungle_log[axis=z])
B(4,15,-5,minecraft:jungle_log[axis=x])
B(4,16,-5,minecraft:jungle_log)
B(4,17,-5,minecraft:jungle_leaves)
B(4,24,-5,minecraft:jungle_log[axis=z])
B(4,25,-5,minecraft:jungle_log[axis=x])
B(4,26,-5,minecraft:jungle_log)
B(4,27,-5,minecraft:jungle_leaves)
B(4,28,-5,minecraft:jungle_leaves[distance=2,persistent=false])
B(4,13,-4,minecraft:jungle_log[axis=z])
B(4,14,-4,minecraft:jungle_log)
B(4,15,-4,minecraft:jungle_log[axis=z])
B(4,16,-4,minecraft:jungle_log[axis=z])
B(4,17,-4,minecraft:jungle_log[axis=x])
B(4,18,-4,minecraft:jungle_leaves)
B(4,19,-4,minecraft:jungle_leaves[distance=2,persistent=false])
B(4,24,-4,minecraft:jungle_log)
B(4,25,-4,minecraft:jungle_log)
B(4,26,-4,minecraft:jungle_log)
B(4,27,-4,minecraft:jungle_leaves)
B(4,28,-4,minecraft:jungle_leaves[distance=2,persistent=false])
B(4,0,-3,minecraft:jungle_log)
B(4,1,-3,minecraft:jungle_log)
B(4,2,-3,minecraft:jungle_log)
B(4,3,-3,minecraft:jungle_log)
B(4,4,-3,minecraft:jungle_log)
B(4,5,-3,minecraft:jungle_log[axis=z])
B(4,14,-3,minecraft:jungle_log)
B(4,15,-3,minecraft:jungle_log[axis=z])
B(4,16,-3,minecraft:jungle_log[axis=x])
B(4,17,-3,minecraft:jungle_log[axis=z])
B(4,18,-3,minecraft:jungle_log[axis=x])
B(4,23,-3,minecraft:jungle_log[axis=z])
B(4,24,-3,minecraft:jungle_log[axis=x])
B(4,25,-3,minecraft:jungle_log[axis=z])
B(4,26,-3,minecraft:jungle_log[axis=x])
B(4,27,-3,minecraft:jungle_leaves)
B(4,28,-3,minecraft:jungle_leaves[distance=2,persistent=false])
B(4,5,-2,minecraft:jungle_log)
B(4,6,-2,minecraft:jungle_log)
B(4,7,-2,minecraft:jungle_log)
B(4,8,-2,minecraft:jungle_log)
B(4,9,-2,minecraft:jungle_log)
B(4,10,-2,minecraft:jungle_log)
B(4,11,-2,minecraft:jungle_log[axis=x])
B(4,15,-2,minecraft:jungle_log[axis=x])
B(4,16,-2,minecraft:jungle_log)
B(4,17,-2,minecraft:jungle_log[axis=z])
B(4,22,-2,minecraft:jungle_log[axis=x])
B(4,23,-2,minecraft:jungle_log[axis=z])
B(4,24,-2,minecraft:jungle_log[axis=x])
B(4,25,-2,minecraft:jungle_log[axis=x])
B(4,26,-2,minecraft:jungle_log[axis=z])
B(4,27,-2,minecraft:jungle_leaves)
B(4,28,-2,minecraft:jungle_leaves[distance=2,persistent=false])
B(4,14,-1,minecraft:jungle_log[axis=z])
B(4,15,-1,minecraft:jungle_log)
B(4,16,-1,minecraft:jungle_log)
B(4,17,-1,minecraft:jungle_log[axis=z])
B(4,21,-1,minecraft:jungle_log[axis=z])
B(4,22,-1,minecraft:jungle_log)
B(4,23,-1,minecraft:jungle_log)
B(4,24,-1,minecraft:jungle_log[axis=x])
B(4,25,-1,minecraft:jungle_log[axis=z])
B(4,26,-1,minecraft:jungle_log[axis=x])
B(4,0,0,minecraft:jungle_log[axis=x])
B(4,13,0,minecraft:jungle_log[axis=x])
B(4,14,0,minecraft:jungle_log[axis=x])
B(4,15,0,minecraft:jungle_log[axis=z])
B(4,16,0,minecraft:jungle_log)
B(4,22,0,minecraft:jungle_log)
B(4,23,0,minecraft:jungle_log[axis=x])
B(4,24,0,minecraft:jungle_log[axis=x])
B(4,25,0,minecraft:jungle_log[axis=z])
B(4,26,0,minecraft:jungle_log[axis=z])
B(4,28,0,minecraft:jungle_leaves)
B(4,13,1,minecraft:jungle_log[axis=z])
B(4,14,1,minecraft:jungle_log[axis=z])
B(4,15,1,minecraft:jungle_log[axis=x])
B(4,16,1,minecraft:jungle_log[axis=z])
B(4,24,1,minecraft:jungle_leaves)
B(4,25,1,minecraft:jungle_log[axis=x])
B(4,26,1,minecraft:jungle_leaves)
B(4,28,1,minecraft:jungle_leaves)
B(4,29,1,minecraft:jungle_leaves)
B(4,12,2,minecraft:jungle_log[axis=x])
B(4,13,2,minecraft:jungle_log[axis=z])
B(4,14,2,minecraft:jungle_log[axis=x])
B(4,15,2,minecraft:jungle_log[axis=z])
B(4,16,2,minecraft:jungle_leaves)
B(4,12,3,minecraft:jungle_log[axis=x])
B(4,13,3,minecraft:jungle_log[axis=z])
B(4,14,3,minecraft:jungle_log[axis=z])
B(4,15,3,minecraft:jungle_leaves)
B(4,6,4,minecraft:jungle_log)
B(4,7,4,minecraft:jungle_log[axis=x])
B(4,8,4,minecraft:jungle_log)
B(4,13,4,minecraft:jungle_log[axis=z])
B(4,5,5,minecraft:jungle_log[axis=z])
B(4,6,5,minecraft:jungle_log[axis=x])
B(4,7,5,minecraft:jungle_log)
B(4,8,5,minecraft:jungle_log[axis=x])
B(4,4,6,minecraft:jungle_log[axis=z])
B(4,5,6,minecraft:jungle_log)
B(4,6,6,minecraft:jungle_log)
B(4,7,6,minecraft:jungle_log[axis=z])
B(4,2,7,minecraft:jungle_log[axis=x])
B(4,3,7,minecraft:jungle_log)
B(4,4,7,minecraft:jungle_log[axis=x])
B(4,5,7,minecraft:jungle_log)
B(4,6,7,minecraft:jungle_log[axis=x])
B(4,33,7,minecraft:jungle_leaves)
B(4,2,8,minecraft:jungle_log[axis=x])
B(5,26,-12,minecraft:jungle_leaves[distance=2,persistent=false])
B(5,25,-11,minecraft:jungle_leaves[distance=2,persistent=false])
B(5,26,-11,minecraft:jungle_leaves)
B(5,27,-11,minecraft:jungle_leaves[distance=2,persistent=false])
B(5,25,-10,minecraft:jungle_leaves)
B(5,26,-10,minecraft:jungle_log[axis=z])
B(5,30,-10,minecraft:jungle_leaves[distance=2,persistent=false])
B(5,20,-9,minecraft:jungle_leaves[distance=5,persistent=false])
B(5,21,-9,minecraft:jungle_leaves[distance=4,persistent=false])
B(5,22,-9,minecraft:jungle_leaves[distance=3,persistent=false])
B(5,23,-9,minecraft:jungle_leaves[distance=2,persistent=false])
B(5,24,-9,minecraft:jungle_leaves)
B(5,25,-9,minecraft:jungle_log[axis=x])
B(5,26,-9,minecraft:jungle_log[axis=x])
B(5,27,-9,minecraft:jungle_log[axis=x])
B(5,29,-9,minecraft:jungle_leaves[distance=2,persistent=false])
B(5,30,-9,minecraft:jungle_leaves[distance=3,persistent=false])
B(5,31,-9,minecraft:jungle_leaves[distance=4,persistent=false])
B(5,11,-8,minecraft:jungle_log[axis=z])
B(5,25,-8,minecraft:jungle_log)
B(5,26,-8,minecraft:jungle_log[axis=x])
B(5,27,-8,minecraft:jungle_log)
B(5,28,-8,minecraft:jungle_leaves)
B(5,30,-8,minecraft:jungle_leaves[distance=3,persistent=false])
B(5,10,-7,minecraft:jungle_log)
B(5,11,-7,minecraft:jungle_log)
B(5,12,-7,minecraft:jungle_log[axis=x])
B(5,13,-7,minecraft:jungle_log[axis=z])
B(5,14,-7,minecraft:jungle_leaves)
B(5,24,-7,minecraft:jungle_leaves)
B(5,25,-7,minecraft:jungle_log)
B(5,26,-7,minecraft:jungle_log[axis=z])
B(5,27,-7,minecraft:jungle_log[axis=x])
B(5,28,-7,minecraft:jungle_leaves)
B(5,29,-7,minecraft:jungle_leaves[distance=2,persistent=false])
B(5,6,-6,minecraft:jungle_log)
B(5,7,-6,minecraft:jungle_log)
B(5,8,-6,minecraft:jungle_log)
B(5,9,-6,minecraft:jungle_log)
B(5,10,-6,minecraft:jungle_log)
B(5,11,-6,minecraft:jungle_log)
B(5,12,-6,minecraft:jungle_log[axis=x])
B(5,13,-6,minecraft:jungle_log[axis=z])
B(5,14,-6,minecraft:jungle_log)
B(5,24,-6,minecraft:jungle_log[axis=x])
B(5,25,-6,minecraft:jungle_log[axis=x])
B(5,26,-6,minecraft:jungle_log)
B(5,27,-6,minecraft:jungle_log)
B(5,28,-6,minecraft:jungle_leaves)
B(5,29,-6,minecraft:jungle_leaves[distance=2,persistent=false])
B(5,12,-5,minecraft:jungle_log[axis=x])
B(5,13,-5,minecraft:jungle_log[axis=x])
B(5,14,-5,minecraft:jungle_log)
B(5,15,-5,minecraft:jungle_log[axis=z])
B(5,16,-5,minecraft:jungle_leaves)
B(5,24,-5,minecraft:jungle_log)
B(5,25,-5,minecraft:jungle_log[axis=x])
B(5,26,-5,minecraft:jungle_log[axis=z])
B(5,27,-5,minecraft:jungle_log)
B(5,28,-5,minecraft:jungle_leaves)
B(5,29,-5,minecraft:jungle_leaves[distance=2,persistent=false])
B(5,12,-4,minecraft:jungle_log)
B(5,13,-4,minecraft:jungle_log)
B(5,14,-4,minecraft:jungle_log)
B(5,15,-4,minecraft:jungle_log)
B(5,16,-4,minecraft:jungle_log[axis=x])
B(5,24,-4,minecraft:jungle_log)
B(5,25,-4,minecraft:jungle_log)
B(5,26,-4,minecraft:jungle_log)
B(5,27,-4,minecraft:jungle_leaves)
B(5,13,-3,minecraft:jungle_log)
B(5,14,-3,minecraft:jungle_log)
B(5,15,-3,minecraft:jungle_log[axis=x])
B(5,24,-3,minecraft:jungle_log[axis=x])
B(5,25,-3,minecraft:jungle_log[axis=x])
B(5,26,-3,minecraft:jungle_log[axis=x])
B(5,27,-3,minecraft:jungle_leaves)
B(5,28,-3,minecraft:jungle_leaves[distance=2,persistent=false])
B(5,23,-2,minecraft:jungle_log[axis=x])
B(5,24,-2,minecraft:jungle_log)
B(5,25,-2,minecraft:jungle_log)
B(5,26,-2,minecraft:jungle_leaves)
B(5,27,-2,minecraft:jungle_leaves[distance=2,persistent=false])
B(5,0,-1,minecraft:jungle_log)
B(5,15,-1,minecraft:jungle_log[axis=z])
B(5,22,-1,minecraft:jungle_log)
B(5,23,-1,minecraft:jungle_log[axis=x])
B(5,24,-1,minecraft:jungle_log)
B(5,25,-1,minecraft:jungle_log[axis=x])
B(5,26,-1,minecraft:jungle_log)
B(5,27,-1,minecraft:jungle_leaves)
B(5,28,-1,minecraft:jungle_leaves)
B(5,0,0,minecraft:jungle_log)
B(5,1,0,minecraft:jungle_log)
B(5,7,0,minecraft:jungle_log)
B(5,8,0,minecraft:jungle_log)
B(5,9,0,minecraft:jungle_log)
B(5,10,0,minecraft:jungle_log)
B(5,11,0,minecraft:jungle_log)
B(5,12,0,minecraft:jungle_log)
B(5,13,0,minecraft:jungle_log)
B(5,14,0,minecraft:jungle_log[axis=z])
B(5,15,0,minecraft:jungle_log[axis=z])
B(5,16,0,minecraft:jungle_log[axis=z])
B(5,23,0,minecraft:jungle_log)
B(5,24,0,minecraft:jungle_log[axis=z])
B(5,25,0,minecraft:jungle_log[axis=z])
B(5,26,0,minecraft:jungle_log[axis=x])
B(5,27,0,minecraft:jungle_log[axis=z])
B(5,28,0,minecraft:jungle_log)
B(5,29,0,minecraft:jungle_leaves)
B(5,0,1,minecraft:jungle_log)
B(5,2,1,minecraft:jungle_log[axis=z])
B(5,13,1,minecraft:jungle_log[axis=x])
B(5,14,1,minecraft:jungle_log[axis=z])
B(5,15,1,minecraft:jungle_log[axis=x])
B(5,24,1,minecraft:jungle_log[axis=x])
B(5,25,1,minecraft:jungle_log[axis=x])
B(5,26,1,minecraft:jungle_log[axis=x])
B(5,27,1,minecraft:jungle_log[axis=z])
B(5,28,1,minecraft:jungle_log[axis=x])
B(5,29,1,minecraft:jungle_log)
B(5,30,1,minecraft:jungle_leaves)
B(5,0,2,minecraft:jungle_log[axis=x])
B(5,2,2,minecraft:jungle_log[axis=x])
B(5,4,2,minecraft:jungle_log[axis=x])
B(5,11,2,minecraft:jungle_log[axis=z])
B(5,12,2,minecraft:jungle_log[axis=x])
B(5,13,2,minecraft:jungle_log[axis=z])
B(5,14,2,minecraft:jungle_log)
B(5,15,2,minecraft:jungle_log[axis=z])
B(5,26,2,minecraft:jungle_leaves)
B(5,27,2,minecraft:jungle_log[axis=x])
B(5,28,2,minecraft:jungle_log)
B(5,29,2,minecraft:jungle_leaves)
B(5,30,2,minecraft:jungle_leaves[distance=2,persistent=false])
B(5,0,3,minecraft:jungle_log[axis=x])
B(5,4,3,minecraft:jungle_log[axis=z])
B(5,6,3,minecraft:jungle_log[axis=x])
B(5,7,3,minecraft:jungle_log[axis=x])
B(5,8,3,minecraft:jungle_log[axis=x])
B(5,9,3,minecraft:jungle_log[axis=x])
B(5,10,3,minecraft:jungle_log)
B(5,11,3,minecraft:jungle_log[axis=z])
B(5,12,3,minecraft:jungle_log[axis=x])
B(5,13,3,minecraft:jungle_log)
B(5,14,3,minecraft:jungle_log[axis=x])
B(5,15,3,minecraft:jungle_log[axis=z])
B(5,27,3,minecraft:jungle_leaves)
B(5,6,4,minecraft:jungle_log)
B(5,7,4,minecraft:jungle_log[axis=x])
B(5,8,4,minecraft:jungle_log[axis=z])
B(5,9,4,minecraft:jungle_log[axis=z])
B(5,11,4,minecraft:jungle_log[axis=z])
B(5,12,4,minecraft:jungle_log)
B(5,13,4,minecraft:jungle_log[axis=x])
B(5,14,4,minecraft:jungle_log[axis=z])
B(5,5,5,minecraft:jungle_log[axis=x])
B(5,6,5,minecraft:jungle_log[axis=x])
B(5,7,5,minecraft:jungle_log[axis=x])
B(5,8,5,minecraft:jungle_log[axis=z])
B(5,9,5,minecraft:jungle_log)
B(5,31,5,minecraft:jungle_leaves[distance=2,persistent=false])
B(5,5,6,minecraft:jungle_log[axis=z])
B(5,6,6,minecraft:jungle_log[axis=z])
B(5,7,6,minecraft:jungle_log[axis=x])
B(5,8,6,minecraft:jungle_log[axis=z])
B(5,31,6,minecraft:jungle_leaves)
B(5,32,6,minecraft:jungle_log)
B(5,33,6,minecraft:jungle_leaves)
B(5,31,7,minecraft:jungle_log)
B(5,32,7,minecraft:jungle_log)
B(5,33,7,minecraft:jungle_log[axis=z])
B(5,34,7,minecraft:jungle_leaves)
B(5,32,8,minecraft:jungle_log[axis=x])
B(5,33,8,minecraft:jungle_leaves)
B(6,25,-12,minecraft:jungle_leaves[distance=3,persistent=false])
B(6,26,-12,minecraft:jungle_leaves[distance=2,persistent=false])
B(6,27,-12,minecraft:jungle_leaves[distance=3,persistent=false])
B(6,25,-11,minecraft:jungle_leaves[distance=2,persistent=false])
B(6,26,-11,minecraft:jungle_leaves)
B(6,27,-11,minecraft:jungle_leaves[distance=2,persistent=false])
B(6,25,-10,minecraft:jungle_leaves)
B(6,26,-10,minecraft:jungle_log)
B(6,27,-10,minecraft:jungle_leaves)
B(6,28,-10,minecraft:jungle_leaves[distance=2,persistent=false])
B(6,24,-9,minecraft:jungle_leaves)
B(6,25,-9,minecraft:jungle_log)
B(6,26,-9,minecraft:jungle_log[axis=x])
B(6,27,-9,minecraft:jungle_log)
B(6,28,-9,minecraft:jungle_leaves)
B(6,1,-8,minecraft:jungle_log[axis=z])
B(6,4,-8,minecraft:jungle_log)
B(6,11,-8,minecraft:jungle_log)
B(6,12,-8,minecraft:jungle_log[axis=z])
B(6,14,-8,minecraft:jungle_leaves)
B(6,25,-8,minecraft:jungle_log[axis=z])
B(6,26,-8,minecraft:jungle_log)
B(6,27,-8,minecraft:jungle_log[axis=x])
B(6,28,-8,minecraft:jungle_leaves)
B(6,2,-7,minecraft:jungle_log)
B(6,4,-7,minecraft:jungle_log[axis=x])
B(6,6,-7,minecraft:jungle_log[axis=z])
B(6,7,-7,minecraft:jungle_log[axis=x])
B(6,8,-7,minecraft:jungle_log[axis=z])
B(6,9,-7,minecraft:jungle_log)
B(6,10,-7,minecraft:jungle_log[axis=x])
B(6,11,-7,minecraft:jungle_log[axis=x])
B(6,12,-7,minecraft:jungle_log)
B(6,13,-7,minecraft:jungle_log)
B(6,14,-7,minecraft:jungle_log[axis=z])
B(6,15,-7,minecraft:jungle_leaves)
B(6,25,-7,minecraft:jungle_log[axis=x])
B(6,26,-7,minecraft:jungle_log[axis=x])
B(6,27,-7,minecraft:jungle_log)
B(6,28,-7,minecraft:jungle_leaves)
B(6,10,-6,minecraft:jungle_log[axis=z])
B(6,11,-6,minecraft:jungle_log)
B(6,12,-6,minecraft:jungle_log)
B(6,13,-6,minecraft:jungle_log[axis=x])
B(6,14,-6,minecraft:jungle_log[axis=z])
B(6,24,-6,minecraft:jungle_leaves)
B(6,25,-6,minecraft:jungle_log[axis=z])
B(6,26,-6,minecraft:jungle_log[axis=z])
B(6,27,-6,minecraft:jungle_log)
B(6,28,-6,minecraft:jungle_leaves)
B(6,29,-6,minecraft:jungle_leaves[distance=2,persistent=false])
B(6,11,-5,minecraft:jungle_log[axis=x])
B(6,12,-5,minecraft:jungle_log[axis=z])
B(6,13,-5,minecraft:jungle_log[axis=z])
B(6,14,-5,minecraft:jungle_log)
B(6,24,-5,minecraft:jungle_log[axis=z])
B(6,25,-5,minecraft:jungle_log)
B(6,26,-5,minecraft:jungle_log[axis=x])
B(6,28,-5,minecraft:jungle_leaves[distance=2,persistent=false])
B(6,13,-4,minecraft:jungle_log)
B(6,25,-4,minecraft:jungle_log)
B(6,26,-4,minecraft:jungle_leaves)
B(6,27,-4,minecraft:jungle_leaves[distance=2,persistent=false])
B(6,24,-3,minecraft:jungle_leaves)
B(6,25,-3,minecraft:jungle_leaves)
B(6,26,-3,minecraft:jungle_leaves)
B(6,27,-3,minecraft:jungle_leaves[distance=2,persistent=false])
B(6,23,-2,minecraft:jungle_leaves)
B(6,24,-2,minecraft:jungle_log[axis=x])
B(6,25,-2,minecraft:jungle_leaves)
B(6,26,-2,minecraft:jungle_leaves)
B(6,27,-2,minecraft:jungle_leaves)
B(6,28,-2,minecraft:jungle_leaves[distance=2,persistent=false])
B(6,23,-1,minecraft:jungle_log)
B(6,24,-1,minecraft:jungle_log[axis=z])
B(6,25,-1,minecraft:jungle_log)
B(6,26,-1,minecraft:jungle_log)
B(6,27,-1,minecraft:jungle_log[axis=z])
B(6,28,-1,minecraft:jungle_leaves)
B(6,29,-1,minecraft:jungle_leaves)
B(6,0,0,minecraft:jungle_log[axis=z])
B(6,2,0,minecraft:jungle_log[axis=x])
B(6,3,0,minecraft:jungle_log)
B(6,4,0,minecraft:jungle_log)
B(6,5,0,minecraft:jungle_log)
B(6,6,0,minecraft:jungle_log)
B(6,7,0,minecraft:jungle_log[axis=x])
B(6,24,0,minecraft:jungle_log[axis=x])
B(6,25,0,minecraft:jungle_log)
B(6,26,0,minecraft:jungle_log[axis=x])
B(6,27,0,minecraft:jungle_log[axis=x])
B(6,28,0,minecraft:jungle_log)
B(6,29,0,minecraft:jungle_log[axis=x])
B(6,30,0,minecraft:jungle_leaves)
B(6,0,1,minecraft:jungle_log[axis=x])
B(6,1,1,minecraft:jungle_log[axis=z])
B(6,2,1,minecraft:jungle_log)
B(6,3,1,minecraft:jungle_log)
B(6,4,1,minecraft:jungle_log)
B(6,14,1,minecraft:jungle_log[axis=z])
B(6,25,1,minecraft:jungle_log)
B(6,26,1,minecraft:jungle_log)
B(6,27,1,minecraft:jungle_log[axis=z])
B(6,28,1,minecraft:jungle_log[axis=z])
B(6,29,1,minecraft:jungle_log[axis=z])
B(6,30,1,minecraft:jungle_leaves)
B(6,0,2,minecraft:jungle_log[axis=z])
B(6,1,2,minecraft:jungle_log[axis=x])
B(6,2,2,minecraft:jungle_log[axis=z])
B(6,3,2,minecraft:jungle_log[axis=z])
B(6,4,2,minecraft:jungle_log)
B(6,5,2,minecraft:jungle_log[axis=z])
B(6,6,2,minecraft:jungle_log[axis=z])
B(6,8,2,minecraft:jungle_log[axis=z])
B(6,9,2,minecraft:jungle_log[axis=z])
B(6,10,2,minecraft:jungle_log[axis=z])
B(6,11,2,minecraft:jungle_log[axis=x])
B(6,12,2,minecraft:jungle_log[axis=x])
B(6,13,2,minecraft:jungle_log)
B(6,14,2,minecraft:jungle_log[axis=x])
B(6,15,2,minecraft:jungle_log)
B(6,26,2,minecraft:jungle_log[axis=z])
B(6,27,2,minecraft:jungle_log)
B(6,28,2,minecraft:jungle_log)
B(6,29,2,minecraft:jungle_log)
B(6,30,2,minecraft:jungle_leaves)
B(6,31,2,minecraft:jungle_leaves[distance=2,persistent=false])
B(6,0,3,minecraft:jungle_log[axis=z])
B(6,1,3,minecraft:jungle_log[axis=z])
B(6,2,3,minecraft:jungle_log)
B(6,3,3,minecraft:jungle_log)
B(6,4,3,minecraft:jungle_log[axis=z])
B(6,5,3,minecraft:jungle_log[axis=z])
B(6,6,3,minecraft:jungle_log[axis=x])
B(6,7,3,minecraft:jungle_log[axis=z])
B(6,8,3,minecraft:jungle_log[axis=z])
B(6,9,3,minecraft:jungle_log)
B(6,10,3,minecraft:jungle_log[axis=x])
B(6,11,3,minecraft:jungle_log[axis=z])
B(6,12,3,minecraft:jungle_log[axis=x])
B(6,13,3,minecraft:jungle_log)
B(6,14,3,minecraft:jungle_log)
B(6,26,3,minecraft:jungle_leaves)
B(6,27,3,minecraft:jungle_leaves)
B(6,28,3,minecraft:jungle_log)
B(6,30,3,minecraft:jungle_leaves[distance=2,persistent=false])
B(6,0,4,minecraft:jungle_log)
B(6,4,4,minecraft:jungle_log[axis=z])
B(6,6,4,minecraft:jungle_log)
B(6,7,4,minecraft:jungle_log[axis=x])
B(6,8,4,minecraft:jungle_log[axis=x])
B(6,9,4,minecraft:jungle_log[axis=z])
B(6,11,4,minecraft:jungle_log[axis=z])
B(6,12,4,minecraft:jungle_log[axis=x])
B(6,13,4,minecraft:jungle_log)
B(6,23,4,minecraft:jungle_leaves[distance=5,persistent=false])
B(6,24,4,minecraft:jungle_leaves[distance=4,persistent=false])
B(6,25,4,minecraft:jungle_leaves[distance=3,persistent=false])
B(6,26,4,minecraft:jungle_leaves[distance=2,persistent=false])
B(6,27,4,minecraft:jungle_leaves[distance=2,persistent=false])
B(6,31,4,minecraft:jungle_leaves[distance=2,persistent=false])
B(6,0,5,minecraft:jungle_log[axis=x])
B(6,6,5,minecraft:jungle_log)
B(6,7,5,minecraft:jungle_log[axis=x])
B(6,8,5,minecraft:jungle_log[axis=x])
B(6,12,5,minecraft:jungle_leaves)
B(6,30,5,minecraft:jungle_leaves[distance=2,persistent=false])
B(6,31,5,minecraft:jungle_leaves)
B(6,32,5,minecraft:jungle_leaves)
B(6,30,6,minecraft:jungle_leaves)
B(6,31,6,minecraft:jungle_log)
B(6,32,6,minecraft:jungle_log[axis=z])
B(6,33,6,minecraft:jungle_log)
B(6,30,7,minecraft:jungle_log[axis=z])
B(6,31,7,minecraft:jungle_log[axis=x])
B(6,32,7,minecraft:jungle_log)
B(6,33,7,minecraft:jungle_log[axis=z])
B(6,31,8,minecraft:jungle_log)
B(6,32,8,minecraft:jungle_log[axis=z])
B(6,33,8,minecraft:jungle_log[axis=z])
B(6,32,9,minecraft:jungle_leaves)
B(7,26,-12,minecraft:jungle_leaves)
B(7,0,-11,minecraft:jungle_log)
B(7,1,-11,minecraft:jungle_log)
B(7,2,-11,minecraft:jungle_log)
B(7,3,-11,minecraft:jungle_log[axis=z])
B(7,23,-11,minecraft:jungle_leaves[distance=3,persistent=false])
B(7,24,-11,minecraft:jungle_leaves[distance=2,persistent=false])
B(7,25,-11,minecraft:jungle_leaves)
B(7,26,-11,minecraft:jungle_log[axis=z])
B(7,27,-11,minecraft:jungle_leaves)
B(7,28,-11,minecraft:jungle_leaves[distance=2,persistent=false])
B(7,3,-10,minecraft:jungle_log)
B(7,4,-10,minecraft:jungle_log[axis=z])
B(7,24,-10,minecraft:jungle_leaves)
B(7,25,-10,minecraft:jungle_log)
B(7,26,-10,minecraft:jungle_log[axis=x])
B(7,27,-10,minecraft:jungle_log[axis=z])
B(7,28,-10,minecraft:jungle_leaves)
B(7,1,-9,minecraft:jungle_log)
B(7,4,-9,minecraft:jungle_log)
B(7,25,-9,minecraft:jungle_log[axis=x])
B(7,26,-9,minecraft:jungle_log[axis=z])
B(7,27,-9,minecraft:jungle_log[axis=z])
B(7,28,-9,minecraft:jungle_leaves)
B(7,0,-8,minecraft:jungle_log)
B(7,1,-8,minecraft:jungle_log[axis=z])
B(7,2,-8,minecraft:jungle_log[axis=x])
B(7,3,-8,minecraft:jungle_log[axis=x])
B(7,4,-8,minecraft:jungle_log)
B(7,5,-8,minecraft:jungle_log[axis=z])
B(7,6,-8,minecraft:jungle_log[axis=x])
B(7,7,-8,minecraft:jungle_log)
B(7,8,-8,minecraft:jungle_log)
B(7,10,-8,minecraft:jungle_log[axis=z])
B(7,12,-8,minecraft:jungle_log)
B(7,13,-8,minecraft:jungle_leaves)
B(7,24,-8,minecraft:jungle_leaves)
B(7,25,-8,minecraft:jungle_log)
B(7,26,-8,minecraft:jungle_log)
B(7,27,-8,minecraft:jungle_log)
B(7,28,-8,minecraft:jungle_leaves)
B(7,0,-7,minecraft:jungle_log[axis=x])
B(7,1,-7,minecraft:jungle_log[axis=x])
B(7,2,-7,minecraft:jungle_log[axis=x])
B(7,3,-7,minecraft:jungle_log[axis=x])
B(7,4,-7,minecraft:jungle_log[axis=x])
B(7,5,-7,minecraft:jungle_log[axis=x])
B(7,6,-7,minecraft:jungle_log[axis=x])
B(7,7,-7,minecraft:jungle_log[axis=x])
B(7,8,-7,minecraft:jungle_log[axis=x])
B(7,9,-7,minecraft:jungle_log[axis=z])
B(7,10,-7,minecraft:jungle_log[axis=x])
B(7,11,-7,minecraft:jungle_log[axis=z])
B(7,12,-7,minecraft:jungle_log)
B(7,13,-7,minecraft:jungle_log[axis=z])
B(7,14,-7,minecraft:jungle_leaves)
B(7,24,-7,minecraft:jungle_leaves)
B(7,25,-7,minecraft:jungle_log[axis=z])
B(7,26,-7,minecraft:jungle_log[axis=z])
B(7,27,-7,minecraft:jungle_log[axis=x])
B(7,2,-6,minecraft:jungle_log)
B(7,4,-6,minecraft:jungle_log[axis=z])
B(7,6,-6,minecraft:jungle_log[axis=z])
B(7,7,-6,minecraft:jungle_log)
B(7,8,-6,minecraft:jungle_log)
B(7,9,-6,minecraft:jungle_log[axis=x])
B(7,10,-6,minecraft:jungle_log[axis=x])
B(7,11,-6,minecraft:jungle_log)
B(7,12,-6,minecraft:jungle_log[axis=z])
B(7,13,-6,minecraft:jungle_log)
B(7,14,-6,minecraft:jungle_log[axis=x])
B(7,25,-6,minecraft:jungle_leaves)
B(7,26,-6,minecraft:jungle_log[axis=x])
B(7,27,-6,minecraft:jungle_leaves)
B(7,12,-5,minecraft:jungle_log[axis=z])
B(7,13,-5,minecraft:jungle_log)
B(7,25,-5,minecraft:jungle_leaves)
B(7,26,-5,minecraft:jungle_leaves)
B(7,27,-5,minecraft:jungle_leaves[distance=2,persistent=false])
B(7,7,-4,minecraft:jungle_log)
B(7,8,-4,minecraft:jungle_log)
B(7,9,-4,minecraft:jungle_log)
B(7,10,-4,minecraft:jungle_log)
B(7,11,-4,minecraft:jungle_log)
B(7,12,-4,minecraft:jungle_log[axis=z])
B(7,26,-4,minecraft:jungle_leaves[distance=2,persistent=false])
B(7,0,-3,minecraft:jungle_log)
B(7,1,-3,minecraft:jungle_log)
B(7,2,-3,minecraft:jungle_log)
B(7,3,-3,minecraft:jungle_log)
B(7,4,-3,minecraft:jungle_log)
B(7,5,-3,minecraft:jungle_log)
B(7,6,-3,minecraft:jungle_log)
B(7,7,-3,minecraft:jungle_log[axis=z])
B(7,24,-3,minecraft:jungle_leaves[distance=2,persistent=false])
B(7,25,-3,minecraft:jungle_leaves[distance=2,persistent=false])
B(7,26,-3,minecraft:jungle_leaves[distance=2,persistent=false])
B(7,27,-3,minecraft:jungle_leaves[distance=3,persistent=false])
B(7,20,-2,minecraft:jungle_leaves[distance=5,persistent=false])
B(7,21,-2,minecraft:jungle_leaves[distance=4,persistent=false])
B(7,22,-2,minecraft:jungle_leaves[distance=3,persistent=false])
B(7,23,-2,minecraft:jungle_leaves[distance=2,persistent=false])
B(7,24,-2,minecraft:jungle_leaves)
B(7,25,-2,minecraft:jungle_leaves[distance=2,persistent=false])
B(7,26,-2,minecraft:jungle_leaves)
B(7,27,-2,minecraft:jungle_leaves[distance=2,persistent=false])
B(7,24,-1,minecraft:jungle_leaves)
B(7,25,-1,minecraft:jungle_leaves)
B(7,26,-1,minecraft:jungle_log)
B(7,27,-1,minecraft:jungle_leaves)
B(7,28,-1,minecraft:jungle_leaves)
B(7,29,-1,minecraft:jungle_leaves[distance=2,persistent=false])
B(7,30,-1,minecraft:jungle_leaves[distance=2,persistent=false])
B(7,25,0,minecraft:jungle_log)
B(7,26,0,minecraft:jungle_log[axis=x])
B(7,27,0,minecraft:jungle_log[axis=x])
B(7,28,0,minecraft:jungle_log[axis=z])
B(7,29,0,minecraft:jungle_leaves)
B(7,30,0,minecraft:jungle_leaves[distance=2,persistent=false])
B(7,31,0,minecraft:jungle_leaves[distance=3,persistent=false])
B(7,0,1,minecraft:jungle_log[axis=x])
B(7,2,1,minecraft:jungle_log[axis=z])
B(7,5,1,minecraft:jungle_log[axis=x])
B(7,26,1,minecraft:jungle_log)
B(7,27,1,minecraft:jungle_log[axis=x])
B(7,28,1,minecraft:jungle_log[axis=z])
B(7,29,1,minecraft:jungle_log[axis=x])
B(7,30,1,minecraft:jungle_leaves)
B(7,0,2,minecraft:jungle_log[axis=x])
B(7,1,2,minecraft:jungle_log)
B(7,2,2,minecraft:jungle_log)
B(7,3,2,minecraft:jungle_log)
B(7,4,2,minecraft:jungle_log[axis=z])
B(7,5,2,minecraft:jungle_log)
B(7,6,2,minecraft:jungle_log[axis=z])
B(7,7,2,minecraft:jungle_log[axis=z])
B(7,8,2,minecraft:jungle_log[axis=x])
B(7,11,2,minecraft:jungle_log[axis=x])
B(7,12,2,minecraft:jungle_log)
B(7,13,2,minecraft:jungle_leaves)
B(7,27,2,minecraft:jungle_log[axis=x])
B(7,28,2,minecraft:jungle_log)
B(7,29,2,minecraft:jungle_log[axis=x])
B(7,30,2,minecraft:jungle_log[axis=z])
B(7,31,2,minecraft:jungle_leaves)
B(7,0,3,minecraft:jungle_log[axis=z])
B(7,1,3,minecraft:jungle_log[axis=z])
B(7,2,3,minecraft:jungle_log[axis=z])
B(7,3,3,minecraft:jungle_log[axis=z])
B(7,4,3,minecraft:jungle_log[axis=z])
B(7,5,3,minecraft:jungle_log[axis=z])
B(7,6,3,minecraft:jungle_log[axis=z])
B(7,7,3,minecraft:jungle_log[axis=z])
B(7,8,3,minecraft:jungle_log[axis=z])
B(7,9,3,minecraft:jungle_log)
B(7,10,3,minecraft:jungle_log[axis=z])
B(7,11,3,minecraft:jungle_log[axis=z])
B(7,12,3,minecraft:jungle_log)
B(7,13,3,minecraft:jungle_log)
B(7,14,3,minecraft:jungle_leaves)
B(7,27,3,minecraft:jungle_log)
B(7,28,3,minecraft:jungle_log)
B(7,29,3,minecraft:jungle_log[axis=z])
B(7,30,3,minecraft:jungle_leaves)
B(7,31,3,minecraft:jungle_leaves[distance=2,persistent=false])
B(7,0,4,minecraft:jungle_log)
B(7,1,4,minecraft:jungle_log[axis=x])
B(7,2,4,minecraft:jungle_log)
B(7,3,4,minecraft:jungle_log[axis=x])
B(7,4,4,minecraft:jungle_log)
B(7,5,4,minecraft:jungle_log[axis=z])
B(7,6,4,minecraft:jungle_log)
B(7,7,4,minecraft:jungle_log)
B(7,8,4,minecraft:jungle_log)
B(7,12,4,minecraft:jungle_log[axis=x])
B(7,13,4,minecraft:jungle_leaves)
B(7,28,4,minecraft:jungle_leaves)
B(7,30,4,minecraft:jungle_leaves)
B(7,0,5,minecraft:jungle_log[axis=x])
B(7,1,5,minecraft:jungle_log)
B(7,4,5,minecraft:jungle_log[axis=z])
B(7,13,5,minecraft:jungle_leaves[distance=2,persistent=false])
B(7,31,5,minecraft:jungle_leaves)
B(7,0,6,minecraft:jungle_log)
B(7,30,6,minecraft:jungle_log[axis=z])
B(7,31,6,minecraft:jungle_log[axis=z])
B(7,32,6,minecraft:jungle_log)
B(7,33,6,minecraft:jungle_leaves)
B(7,29,7,minecraft:jungle_log[axis=z])
B(7,30,7,minecraft:jungle_log[axis=x])
B(7,31,7,minecraft:jungle_log[axis=x])
B(7,32,7,minecraft:jungle_log[axis=z])
B(7,33,7,minecraft:jungle_log[axis=x])
B(7,34,7,minecraft:jungle_leaves)
B(7,29,8,minecraft:jungle_leaves)
B(7,30,8,minecraft:jungle_log[axis=z])
B(7,31,8,minecraft:jungle_log[axis=z])
B(7,32,8,minecraft:jungle_log[axis=z])
B(7,33,8,minecraft:jungle_leaves)
B(7,34,8,minecraft:jungle_leaves[distance=2,persistent=false])
B(7,29,9,minecraft:jungle_leaves[distance=2,persistent=false])
B(7,32,9,minecraft:jungle_leaves)
B(7,33,9,minecraft:jungle_leaves[distance=2,persistent=false])
B(8,26,-12,minecraft:jungle_leaves)
B(8,25,-11,minecraft:jungle_log[axis=z])
B(8,26,-11,minecraft:jungle_log)
B(8,27,-11,minecraft:jungle_log)
B(8,24,-10,minecraft:jungle_leaves)
B(8,25,-10,minecraft:jungle_log[axis=z])
B(8,26,-10,minecraft:jungle_log[axis=z])
B(8,27,-10,minecraft:jungle_log[axis=z])
B(8,28,-10,minecraft:jungle_leaves)
B(8,0,-9,minecraft:jungle_log[axis=z])
B(8,1,-9,minecraft:jungle_log)
B(8,2,-9,minecraft:jungle_log[axis=x])
B(8,3,-9,minecraft:jungle_log)
B(8,4,-9,minecraft:jungle_log[axis=x])
B(8,5,-9,minecraft:jungle_log)
B(8,6,-9,minecraft:jungle_log)
B(8,13,-9,minecraft:jungle_leaves[distance=7,persistent=true])
B(8,24,-9,minecraft:jungle_leaves)
B(8,25,-9,minecraft:jungle_log[axis=x])
B(8,26,-9,minecraft:jungle_log)
B(8,27,-9,minecraft:jungle_log)
B(8,0,-8,minecraft:jungle_log)
B(8,1,-8,minecraft:jungle_log[axis=x])
B(8,2,-8,minecraft:jungle_log)
B(8,3,-8,minecraft:jungle_log)
B(8,4,-8,minecraft:jungle_log)
B(8,5,-8,minecraft:jungle_log[axis=z])
B(8,6,-8,minecraft:jungle_log)
B(8,7,-8,minecraft:jungle_log[axis=x])
B(8,8,-8,minecraft:jungle_log)
B(8,10,-8,minecraft:jungle_log[axis=x])
B(8,22,-8,minecraft:jungle_leaves[distance=3,persistent=false])
B(8,23,-8,minecraft:jungle_leaves[distance=2,persistent=false])
B(8,24,-8,minecraft:jungle_leaves)
B(8,25,-8,minecraft:jungle_log)
B(8,26,-8,minecraft:jungle_log)
B(8,27,-8,minecraft:jungle_log[axis=x])
B(8,0,-7,minecraft:jungle_log[axis=x])
B(8,1,-7,minecraft:jungle_log[axis=z])
B(8,2,-7,minecraft:jungle_log)
B(8,3,-7,minecraft:jungle_log[axis=x])
B(8,4,-7,minecraft:jungle_log)
B(8,5,-7,minecraft:jungle_log)
B(8,6,-7,minecraft:jungle_log[axis=x])
B(8,7,-7,minecraft:jungle_log[axis=x])
B(8,8,-7,minecraft:jungle_log)
B(8,9,-7,minecraft:jungle_log[axis=z])
B(8,10,-7,minecraft:jungle_log[axis=x])
B(8,11,-7,minecraft:jungle_log)
B(8,13,-7,minecraft:jungle_leaves)
B(8,25,-7,minecraft:jungle_leaves)
B(8,26,-7,minecraft:jungle_log[axis=z])
B(8,4,-6,minecraft:jungle_log)
B(8,8,-6,minecraft:jungle_log)
B(8,10,-6,minecraft:jungle_log[axis=z])
B(8,25,-6,minecraft:jungle_leaves[distance=2,persistent=false])
B(8,26,-6,minecraft:jungle_leaves)
B(8,27,-6,minecraft:jungle_leaves[distance=2,persistent=false])
B(8,26,-5,minecraft:jungle_leaves[distance=2,persistent=false])
B(8,26,-2,minecraft:jungle_leaves[distance=2,persistent=false])
B(8,25,-1,minecraft:jungle_leaves[distance=2,persistent=false])
B(8,26,-1,minecraft:jungle_leaves)
B(8,27,-1,minecraft:jungle_leaves[distance=2,persistent=false])
B(8,28,-1,minecraft:jungle_leaves[distance=2,persistent=false])
B(8,30,-1,minecraft:jungle_leaves)
B(8,26,0,minecraft:jungle_leaves)
B(8,27,0,minecraft:jungle_leaves)
B(8,28,0,minecraft:jungle_leaves)
B(8,29,0,minecraft:jungle_log)
B(8,30,0,minecraft:jungle_leaves)
B(8,31,0,minecraft:jungle_leaves[distance=2,persistent=false])
B(8,0,1,minecraft:jungle_log[axis=x])
B(8,7,1,minecraft:jungle_log[axis=z])
B(8,28,1,minecraft:jungle_log[axis=z])
B(8,29,1,minecraft:jungle_log[axis=z])
B(8,30,1,minecraft:jungle_log[axis=z])
B(8,31,1,minecraft:jungle_leaves)
B(8,0,2,minecraft:jungle_log[axis=x])
B(8,2,2,minecraft:jungle_log)
B(8,5,2,minecraft:jungle_log[axis=x])
B(8,7,2,minecraft:jungle_log[axis=x])
B(8,8,2,minecraft:jungle_log[axis=z])
B(8,27,2,minecraft:jungle_log)
B(8,28,2,minecraft:jungle_log[axis=x])
B(8,29,2,minecraft:jungle_log[axis=x])
B(8,30,2,minecraft:jungle_log[axis=z])
B(8,0,3,minecraft:jungle_log[axis=x])
B(8,1,3,minecraft:jungle_log[axis=z])
B(8,2,3,minecraft:jungle_log)
B(8,3,3,minecraft:jungle_log[axis=z])
B(8,4,3,minecraft:jungle_log[axis=z])
B(8,5,3,minecraft:jungle_log)
B(8,6,3,minecraft:jungle_log[axis=x])
B(8,7,3,minecraft:jungle_log[axis=z])
B(8,8,3,minecraft:jungle_log)
B(8,11,3,minecraft:jungle_log)
B(8,13,3,minecraft:jungle_leaves)
B(8,28,3,minecraft:jungle_log[axis=x])
B(8,29,3,minecraft:jungle_log[axis=z])
B(8,30,3,minecraft:jungle_log[axis=x])
B(8,0,4,minecraft:jungle_log)
B(8,1,4,minecraft:jungle_log[axis=x])
B(8,2,4,minecraft:jungle_log[axis=x])
B(8,3,4,minecraft:jungle_log)
B(8,4,4,minecraft:jungle_log)
B(8,5,4,minecraft:jungle_log[axis=x])
B(8,6,4,minecraft:jungle_log[axis=x])
B(8,27,4,minecraft:jungle_leaves)
B(8,28,4,minecraft:jungle_log)
B(8,29,4,minecraft:jungle_log[axis=z])
B(8,30,4,minecraft:jungle_log[axis=z])
B(8,31,4,minecraft:jungle_leaves)
B(8,0,5,minecraft:jungle_log[axis=x])
B(8,1,5,minecraft:jungle_log[axis=z])
B(8,2,5,minecraft:jungle_log)
B(8,3,5,minecraft:jungle_log[axis=z])
B(8,4,5,minecraft:jungle_log[axis=z])
B(8,5,5,minecraft:jungle_log)
B(8,28,5,minecraft:jungle_leaves)
B(8,29,5,minecraft:jungle_log[axis=z])
B(8,30,5,minecraft:jungle_log[axis=z])
B(8,31,5,minecraft:jungle_log[axis=z])
B(8,0,6,minecraft:jungle_log)
B(8,1,6,minecraft:jungle_log)
B(8,2,6,minecraft:jungle_log)
B(8,4,6,minecraft:jungle_log[axis=z])
B(8,29,6,minecraft:jungle_log[axis=x])
B(8,30,6,minecraft:jungle_log[axis=x])
B(8,31,6,minecraft:jungle_log[axis=x])
B(8,32,6,minecraft:jungle_leaves)
B(8,29,7,minecraft:jungle_log[axis=z])
B(8,30,7,minecraft:jungle_log[axis=x])
B(8,31,7,minecraft:jungle_log)
B(8,32,7,minecraft:jungle_log[axis=z])
B(8,33,7,minecraft:jungle_leaves)
B(8,28,8,minecraft:jungle_leaves)
B(8,29,8,minecraft:jungle_log)
B(8,30,8,minecraft:jungle_log[axis=z])
B(8,31,8,minecraft:jungle_log[axis=z])
B(8,32,8,minecraft:jungle_leaves)
B(8,33,8,minecraft:jungle_leaves[distance=2,persistent=false])
B(8,24,9,minecraft:jungle_leaves[distance=6,persistent=false])
B(8,25,9,minecraft:jungle_leaves[distance=5,persistent=false])
B(8,26,9,minecraft:jungle_leaves[distance=4,persistent=false])
B(8,27,9,minecraft:jungle_leaves[distance=3,persistent=false])
B(8,28,9,minecraft:jungle_leaves[distance=2,persistent=false])
B(8,29,9,minecraft:jungle_leaves)
B(8,30,9,minecraft:jungle_leaves)
B(8,32,9,minecraft:jungle_leaves[distance=2,persistent=false])
B(8,29,10,minecraft:jungle_leaves[distance=2,persistent=false])
B(9,25,-12,minecraft:jungle_leaves)
B(9,26,-12,minecraft:jungle_leaves)
B(9,27,-12,minecraft:jungle_leaves)
B(9,25,-11,minecraft:jungle_log[axis=x])
B(9,26,-11,minecraft:jungle_log)
B(9,27,-11,minecraft:jungle_log[axis=z])
B(9,28,-11,minecraft:jungle_leaves)
B(9,0,-10,minecraft:jungle_log[axis=z])
B(9,1,-10,minecraft:jungle_log[axis=x])
B(9,2,-10,minecraft:jungle_log[axis=x])
B(9,3,-10,minecraft:jungle_log[axis=z])
B(9,24,-10,minecraft:jungle_leaves)
B(9,25,-10,minecraft:jungle_log[axis=x])
B(9,26,-10,minecraft:jungle_log[axis=z])
B(9,27,-10,minecraft:jungle_log[axis=x])
B(9,29,-10,minecraft:jungle_leaves[distance=2,persistent=false])
B(9,0,-9,minecraft:jungle_log)
B(9,1,-9,minecraft:jungle_log[axis=x])
B(9,2,-9,minecraft:jungle_log)
B(9,3,-9,minecraft:jungle_log[axis=z])
B(9,4,-9,minecraft:jungle_log)
B(9,24,-9,minecraft:jungle_leaves)
B(9,25,-9,minecraft:jungle_log[axis=x])
B(9,26,-9,minecraft:jungle_log)
B(9,27,-9,minecraft:jungle_log[axis=x])
B(9,28,-9,minecraft:jungle_leaves)
B(9,29,-9,minecraft:jungle_leaves)
