
#######################################################################
# +-----------------------------------------------------------------+ #
# |                            BO3 object                           | #
# +-----------------------------------------------------------------+ #
#######################################################################

Author: NLBlackEagle

Description: No description given

Version: 3

SettingsMode: WriteWithoutComments


#######################################################################
# +-----------------------------------------------------------------+ #
# |                          Main settings                          | #
# +-----------------------------------------------------------------+ #
#######################################################################

Tree: true

Frequency: 1

Rarity: 100.0

RotateRandomly: true

SpawnHeight: highestBlock

SpawnHeightOffset: 0

SpawnHeightVariance: 0

##############################
# Height Limits for the BO3. #
##############################

MinHeight: 60

MaxHeight: 77

######################
# Extrusion settings #
######################

ExtrudeMode: None

ExtrudeThroughBlocks: otg:air

MaxBranchDepth: 10


#######################################################################
# +-----------------------------------------------------------------+ #
# |                      Source block settings                      | #
# +-----------------------------------------------------------------+ #
#######################################################################

SourceBlocks: otg:air,otg:dirt,minecraft:sand,minecraft:grass_block

MaxPercentageOutsideSourceBlock: 0

OutsideSourceBlock: placeAnyway

DoReplaceBlocks: true

IsOTGPlus: false


#######################################################################
# +-----------------------------------------------------------------+ #
# |                              Blocks                             | #
# +-----------------------------------------------------------------+ #
#######################################################################

B(-6,11,-2,minecraft:jungle_leaves[distance=7,persistent=true])
B(-5,-2,-6,minecraft:jungle_wood)
B(-5,11,-6,minecraft:jungle_leaves[distance=7,persistent=true])
B(-5,-2,-5,minecraft:jungle_wood)
B(-5,9,-2,minecraft:jungle_leaves[distance=7,persistent=true])
B(-5,12,-2,minecraft:jungle_leaves[distance=7,persistent=true])
B(-5,12,2,minecraft:jungle_leaves[distance=7,persistent=true])
B(-5,-2,3,minecraft:jungle_wood)
B(-5,-2,4,minecraft:jungle_wood)
B(-4,-2,-5,minecraft:jungle_wood)
B(-4,-1,-5,minecraft:jungle_wood)
B(-4,9,-5,minecraft:jungle_leaves[distance=7,persistent=true])
B(-4,11,-5,minecraft:jungle_leaves[distance=7,persistent=true])
B(-4,12,-5,minecraft:jungle_leaves[distance=7,persistent=true])
B(-4,-1,-4,minecraft:jungle_wood)
B(-4,10,-2,minecraft:jungle_leaves[distance=3,persistent=false])
B(-4,12,-2,minecraft:jungle_leaves[distance=7,persistent=true])
B(-4,9,1,minecraft:jungle_leaves[distance=7,persistent=true])
B(-4,10,1,minecraft:jungle_leaves[distance=7,persistent=true])
B(-4,13,1,minecraft:jungle_leaves[distance=7,persistent=true])
B(-4,-1,2,minecraft:jungle_wood)
B(-4,-2,3,minecraft:jungle_wood)
B(-4,-1,3,minecraft:jungle_wood)
B(-3,-1,-4,minecraft:jungle_wood)
B(-3,0,-4,minecraft:jungle_wood)
B(-3,9,-4,minecraft:jungle_leaves[distance=7,persistent=true])
B(-3,10,-4,minecraft:jungle_leaves[distance=7,persistent=true])
B(-3,12,-4,minecraft:jungle_leaves[distance=7,persistent=true])
B(-3,14,-4,minecraft:jungle_leaves[distance=7,persistent=true])
B(-3,-1,-3,minecraft:jungle_wood)
B(-3,0,-3,minecraft:jungle_wood)
B(-3,11,-3,minecraft:jungle_leaves[distance=3,persistent=false])
B(-3,10,-2,minecraft:jungle_leaves[distance=2,persistent=false])
B(-3,13,-2,minecraft:jungle_leaves[distance=4,persistent=false])
B(-3,15,-2,minecraft:jungle_leaves[distance=7,persistent=true])
B(-3,11,-1,minecraft:jungle_leaves[distance=3,persistent=false])
B(-3,10,0,minecraft:jungle_leaves[distance=7,persistent=true])
B(-3,12,0,minecraft:jungle_leaves[distance=7,persistent=true])
B(-3,13,0,minecraft:jungle_leaves[distance=7,persistent=true])
B(-3,-1,1,minecraft:jungle_wood)
B(-3,0,1,minecraft:jungle_wood)
B(-3,1,1,minecraft:jungle_wood)
B(-3,-1,2,minecraft:jungle_wood)
B(-2,12,-5,minecraft:jungle_leaves[distance=7,persistent=true])
B(-2,11,-4,minecraft:jungle_leaves[distance=3,persistent=false])
B(-2,0,-3,minecraft:jungle_wood)
B(-2,8,-3,minecraft:jungle_leaves[distance=7,persistent=true])
B(-2,10,-3,minecraft:jungle_leaves[distance=2,persistent=false])
B(-2,11,-3,minecraft:jungle_leaves[distance=2,persistent=false])
B(-2,12,-3,minecraft:jungle_leaves[distance=3,persistent=false])
B(-2,15,-3,minecraft:jungle_leaves[distance=7,persistent=true])
B(-2,16,-3,minecraft:jungle_leaves[distance=7,persistent=true])
B(-2,0,-2,minecraft:jungle_wood)
B(-2,9,-2,minecraft:jungle_leaves)
B(-2,10,-2,minecraft:jungle_leaves)
B(-2,11,-2,minecraft:jungle_leaves)
B(-2,12,-2,minecraft:jungle_leaves[distance=2,persistent=false])
B(-2,13,-2,minecraft:jungle_leaves[distance=3,persistent=false])
B(-2,0,-1,minecraft:jungle_wood)
B(-2,8,-1,minecraft:jungle_leaves[distance=7,persistent=true])
B(-2,10,-1,minecraft:jungle_leaves[distance=2,persistent=false])
B(-2,11,-1,minecraft:jungle_leaves[distance=2,persistent=false])
B(-2,12,-1,minecraft:jungle_leaves[distance=3,persistent=false])
B(-2,13,-1,minecraft:jungle_leaves[distance=4,persistent=false])
B(-2,14,-1,minecraft:jungle_leaves[distance=5,persistent=false])
B(-2,1,0,minecraft:jungle_wood)
B(-2,11,0,minecraft:jungle_leaves[distance=3,persistent=false])
B(-2,15,0,minecraft:jungle_leaves[distance=7,persistent=true])
B(-2,1,1,minecraft:jungle_wood)
B(-1,8,-7,minecraft:jungle_leaves[distance=7,persistent=true])
B(-1,9,-6,minecraft:jungle_leaves[distance=7,persistent=true])
B(-1,11,-6,minecraft:jungle_leaves[distance=7,persistent=true])
B(-1,9,-5,minecraft:jungle_leaves[distance=7,persistent=true])
B(-1,12,-5,minecraft:jungle_leaves[distance=7,persistent=true])
B(-1,10,-4,minecraft:jungle_leaves[distance=2,persistent=false])
B(-1,12,-4,minecraft:jungle_leaves[distance=3,persistent=false])
B(-1,15,-4,minecraft:jungle_leaves[distance=7,persistent=true])
B(-1,9,-3,minecraft:jungle_leaves)
B(-1,10,-3,minecraft:jungle_leaves)
B(-1,11,-3,minecraft:jungle_leaves)
B(-1,12,-3,minecraft:jungle_leaves[distance=2,persistent=false])
B(-1,13,-3,minecraft:jungle_leaves[distance=3,persistent=false])
B(-1,14,-3,minecraft:jungle_leaves[distance=4,persistent=false])
B(-1,0,-2,minecraft:jungle_wood)
B(-1,6,-2,minecraft:spruce_stairs[facing=south,half=top,shape=straight,waterlogged=false])
B(-1,7,-2,minecraft:jungle_wood)
B(-1,8,-2,minecraft:jungle_wood)
B(-1,9,-2,minecraft:jungle_wood)
B(-1,10,-2,minecraft:jungle_wood)
B(-1,11,-2,minecraft:jungle_wood)
B(-1,12,-2,minecraft:jungle_leaves)
B(-1,13,-2,minecraft:jungle_leaves[distance=2,persistent=false])
B(-1,14,-2,minecraft:jungle_leaves[distance=3,persistent=false])
B(-1,0,-1,minecraft:jungle_wood)
B(-1,1,-1,minecraft:jungle_wood)
B(-1,2,-1,minecraft:spruce_slab)
B(-1,5,-1,minecraft:spruce_stairs[facing=east,half=top,shape=straight,waterlogged=false])
B(-1,6,-1,minecraft:jungle_wood)
B(-1,7,-1,minecraft:spruce_stairs[facing=east,half=bottom,shape=straight,waterlogged=false])
B(-1,10,-1,minecraft:jungle_leaves)
B(-1,11,-1,minecraft:jungle_leaves)
B(-1,12,-1,minecraft:jungle_leaves[distance=2,persistent=false])
B(-1,13,-1,minecraft:jungle_leaves[distance=3,persistent=false])
B(-1,1,0,minecraft:jungle_wood)
B(-1,2,0,minecraft:spruce_stairs[facing=east,half=bottom,shape=straight,waterlogged=false])
B(-1,9,0,minecraft:jungle_leaves[distance=3,persistent=false])
B(-1,10,0,minecraft:jungle_leaves[distance=2,persistent=false])
B(-1,12,0,minecraft:jungle_leaves[distance=3,persistent=false])
B(-1,9,1,minecraft:jungle_leaves[distance=7,persistent=true])
B(-1,12,1,minecraft:jungle_leaves[distance=4,persistent=false])
B(-1,8,2,minecraft:jungle_leaves[distance=7,persistent=true])
B(-1,11,2,minecraft:jungle_leaves[distance=7,persistent=true])
B(-1,11,3,minecraft:jungle_leaves[distance=7,persistent=true])
B(0,14,-5,minecraft:jungle_leaves[distance=7,persistent=true])
B(0,11,-4,minecraft:jungle_leaves[distance=3,persistent=false])
B(0,10,-3,minecraft:jungle_leaves[distance=2,persistent=false])
B(0,11,-3,minecraft:jungle_leaves[distance=2,persistent=false])
B(0,12,-3,minecraft:jungle_leaves[distance=3,persistent=false])
B(0,13,-3,minecraft:jungle_leaves[distance=4,persistent=false])
B(0,9,-2,minecraft:jungle_leaves)
B(0,10,-2,minecraft:jungle_leaves)
B(0,11,-2,minecraft:jungle_leaves)
B(0,12,-2,minecraft:jungle_leaves[distance=2,persistent=false])
B(0,15,-2,minecraft:jungle_leaves[distance=7,persistent=true])
B(0,16,-2,minecraft:jungle_leaves[distance=7,persistent=true])
B(0,1,-1,minecraft:spruce_stairs[facing=west,half=bottom,shape=straight,waterlogged=false])
B(0,3,-1,minecraft:jungle_wood)
B(0,4,-1,minecraft:jungle_wood)
B(0,5,-1,minecraft:jungle_wood)
B(0,6,-1,minecraft:spruce_stairs[facing=west,half=bottom,shape=straight,waterlogged=false])
B(0,9,-1,minecraft:jungle_leaves[distance=2,persistent=false])
B(0,10,-1,minecraft:jungle_leaves[distance=2,persistent=false])
B(0,11,-1,minecraft:jungle_leaves[distance=2,persistent=false])
B(0,12,-1,minecraft:jungle_leaves[distance=3,persistent=false])
B(0,1,0,minecraft:jungle_wood)
B(0,2,0,minecraft:jungle_wood)
B(0,3,0,minecraft:jungle_wood)
B(0,4,0,minecraft:spruce_slab)
B(0,8,0,minecraft:jungle_leaves[distance=7,persistent=true])
B(0,10,0,minecraft:jungle_leaves[distance=3,persistent=false])
B(0,11,0,minecraft:jungle_leaves[distance=3,persistent=false])
B(0,13,0,minecraft:jungle_leaves[distance=7,persistent=true])
B(0,14,0,minecraft:jungle_leaves[distance=7,persistent=true])
B(0,1,1,minecraft:jungle_wood)
B(0,2,1,minecraft:spruce_slab)
B(0,11,2,minecraft:jungle_leaves[distance=7,persistent=true])
B(1,11,-5,minecraft:jungle_leaves[distance=7,persistent=true])
B(1,9,-4,minecraft:jungle_leaves[distance=7,persistent=true])
B(1,10,-4,minecraft:jungle_leaves[distance=7,persistent=true])
B(1,12,-4,minecraft:jungle_leaves[distance=7,persistent=true])
B(1,-1,-3,minecraft:jungle_wood)
B(1,14,-3,minecraft:jungle_leaves[distance=7,persistent=true])
B(1,0,-2,minecraft:jungle_wood)
B(1,8,-2,minecraft:jungle_leaves[distance=7,persistent=true])
B(1,10,-2,minecraft:jungle_leaves[distance=2,persistent=false])
B(1,12,-2,minecraft:jungle_leaves[distance=3,persistent=false])
B(1,13,-2,minecraft:jungle_leaves[distance=4,persistent=false])
B(1,11,-1,minecraft:jungle_leaves[distance=3,persistent=false])
B(1,16,-1,minecraft:jungle_leaves[distance=7,persistent=true])
B(1,1,0,minecraft:spruce_stairs[facing=west,half=top,shape=straight,waterlogged=false])
B(1,2,0,minecraft:jungle_wood)
B(1,3,0,minecraft:spruce_stairs[facing=west,half=bottom,shape=straight,waterlogged=false])
B(1,9,0,minecraft:jungle_leaves[distance=7,persistent=true])
B(1,10,0,minecraft:jungle_leaves[distance=7,persistent=true])
B(1,12,0,minecraft:jungle_leaves[distance=7,persistent=true])
B(1,13,0,minecraft:jungle_leaves[distance=7,persistent=true])
B(1,0,1,minecraft:jungle_wood)
B(1,1,1,minecraft:jungle_wood)
B(2,11,-6,minecraft:jungle_leaves[distance=7,persistent=true])
B(2,-2,-5,minecraft:jungle_wood)
B(2,-1,-5,minecraft:jungle_wood)
B(2,8,-5,minecraft:jungle_leaves[distance=7,persistent=true])
B(2,12,-5,minecraft:jungle_leaves[distance=7,persistent=true])
B(2,-1,-4,minecraft:jungle_wood)
B(2,-1,-3,minecraft:jungle_wood)
B(2,13,-3,minecraft:jungle_leaves[distance=7,persistent=true])
B(2,9,-2,minecraft:jungle_leaves[distance=7,persistent=true])
B(2,13,-2,minecraft:jungle_leaves[distance=7,persistent=true])
B(2,9,1,minecraft:jungle_leaves[distance=7,persistent=true])
B(2,13,1,minecraft:jungle_leaves[distance=7,persistent=true])
B(2,-1,2,minecraft:jungle_wood)
B(2,0,2,minecraft:jungle_wood)
B(2,12,2,minecraft:jungle_leaves[distance=7,persistent=true])
B(2,-1,3,minecraft:jungle_wood)
B(3,10,-6,minecraft:jungle_leaves[distance=7,persistent=true])
B(3,-2,-5,minecraft:jungle_wood)
B(3,9,-2,minecraft:jungle_leaves[distance=7,persistent=true])
B(3,12,-2,minecraft:jungle_leaves[distance=7,persistent=true])
B(3,12,2,minecraft:jungle_leaves[distance=7,persistent=true])
B(3,-2,3,minecraft:jungle_wood)
B(3,-1,3,minecraft:jungle_wood)
B(4,11,-2,minecraft:jungle_leaves[distance=7,persistent=true])
B(4,12,-1,minecraft:jungle_leaves[distance=7,persistent=true])

#######################################################################
# +-----------------------------------------------------------------+ #
# |                            BO3 checks                           | #
# +-----------------------------------------------------------------+ #
#######################################################################

BlockCheck(2,-3,-5,otg:dirt,minecraft:sand,minecraft:grass_block)
BlockCheck(3,-3,-5,otg:dirt,minecraft:sand,minecraft:grass_block)
BlockCheck(3,-3,3,otg:dirt,minecraft:sand,minecraft:grass_block)
BlockCheck(-4,-3,-5,otg:dirt,minecraft:sand,minecraft:grass_block)
BlockCheck(-4,-3,3,otg:dirt,minecraft:sand,minecraft:grass_block)
BlockCheck(-5,-3,-6,otg:dirt,minecraft:sand,minecraft:grass_block)
BlockCheck(-5,-3,-5,otg:dirt,minecraft:sand,minecraft:grass_block)
BlockCheck(-5,-3,3,otg:dirt,minecraft:sand,minecraft:grass_block)
BlockCheck(-5,-3,4,otg:dirt,minecraft:sand,minecraft:grass_block)
BlockCheckNot(0,1,0,Solid)

#######################################################################
# +-----------------------------------------------------------------+ #
# |                             Branches                            | #
# +-----------------------------------------------------------------+ #
#######################################################################


#######################################################################
# +-----------------------------------------------------------------+ #
# |                             Entities                            | #
# +-----------------------------------------------------------------+ #
#######################################################################

