#######################################################################
# +-----------------------------------------------------------------+ #
# |                            BO3 object                           | #
# +-----------------------------------------------------------------+ #
#######################################################################

Author: Bo3 BulkEdit

Description: Converted Schematic - Modified by Bo3BulkEdit

Version: 3

SettingsMode: WriteDisable

#######################################################################
# +-----------------------------------------------------------------+ #
# |                          Main settings                          | #
# +-----------------------------------------------------------------+ #
#######################################################################



Frequency: 0


SpawnHeight: randomY





##############################
# Height Limits for the BO3. #
##############################

MinHeight: 0
MaxHeight: 256

#######################################################################
# +-----------------------------------------------------------------+ #
# |                      Source block settings                      | #
# +-----------------------------------------------------------------+ #
#######################################################################

CanOverride: true
MaxPercentageOutsideSourceBlock: 100
OutsideSourceBlock: placeAnyway

#######################################################################
# +-----------------------------------------------------------------+ #
# |                               OTG+                              | #
# +-----------------------------------------------------------------+ #
#######################################################################

#######################################################################
# +-----------------------------------------------------------------+ #
# |                              Blocks                             | #
# +-----------------------------------------------------------------+ #
#######################################################################

B(3,-4,3,STAINED_GLASS:15)
B(4,-4,3,STAINED_GLASS:15)
B(3,-4,4,STAINED_GLASS:15)
B(4,-4,4,STAINED_GLASS:15)
B(2,-3,2,STAINED_GLASS:15)
B(3,-3,2,STAINED_GLASS:15)
B(2,-3,3,STAINED_GLASS:15)
B(3,-3,3,STAINED_GLASS:15)
B(4,-3,3,STAINED_GLASS:15)
B(3,-3,4,STAINED_GLASS:15)
B(4,-3,4,STAINED_GLASS:15)
B(1,-2,1,STAINED_GLASS:15)
B(2,-2,1,STAINED_GLASS:15)
B(3,-2,1,STAINED_GLASS:15)
B(1,-2,2,STAINED_GLASS:15)
B(2,-2,2,STAINED_GLASS:15)
B(3,-2,2,STAINED_GLASS:15)
B(4,-2,2,STAINED_GLASS:15)
B(1,-2,3,STAINED_GLASS:15)
B(2,-2,3,STAINED_GLASS:15)
B(3,-2,3,STAINED_GLASS:15)
B(4,-2,3,STAINED_GLASS:15)
B(2,-2,4,STAINED_GLASS:15)
B(3,-2,4,STAINED_GLASS:15)
B(0,-1,0,STAINED_GLASS:15)
B(1,-1,0,STAINED_GLASS:15)
B(2,-1,0,STAINED_GLASS:15)
B(3,-1,0,STAINED_GLASS:15)
B(1,-1,1,STAINED_GLASS:15)
B(2,-1,1,STAINED_GLASS:15)
B(3,-1,1,STAINED_GLASS:15)
B(0,-1,2,STAINED_GLASS:15)
B(1,-1,2,STAINED_GLASS:15)
B(2,-1,2,STAINED_GLASS:15)
B(3,-1,2,STAINED_GLASS:15)
B(4,-1,2,STAINED_GLASS:15)
B(0,-1,3,STAINED_GLASS:15)
B(1,-1,3,STAINED_GLASS:15)
B(2,-1,3,STAINED_GLASS:15)
B(3,-1,3,STAINED_GLASS:15)
B(2,-1,4,STAINED_GLASS:15)
B(-1,0,-1,STAINED_GLASS:15)
B(0,0,-1,STAINED_GLASS:15)
B(1,0,-1,STAINED_GLASS:15)
B(2,0,-1,STAINED_GLASS:15)
B(-1,0,0,STAINED_GLASS:15)
B(1,0,0,STAINED_GLASS:15)
B(2,0,0,STAINED_GLASS:15)
B(3,0,0,STAINED_GLASS:15)
B(-1,0,1,STAINED_GLASS:15)
B(0,0,1,STAINED_GLASS:15)
B(1,0,1,STAINED_GLASS:15)
B(2,0,1,SEA_LANTERN)
B(3,0,1,STAINED_GLASS:15)
B(-1,0,2,STAINED_GLASS:15)
B(0,0,2,STAINED_GLASS:15)
B(1,0,2,SEA_LANTERN)
B(2,0,2,STAINED_GLASS:15)
B(3,0,2,STAINED_GLASS:15)
B(0,0,3,STAINED_GLASS:15)
B(1,0,3,STAINED_GLASS:15)
B(2,0,3,STAINED_GLASS:15)
B(3,0,3,STAINED_GLASS:15)
B(0,1,-2,STAINED_GLASS:15)
B(1,1,-2,STAINED_GLASS:15)
B(-1,1,-1,STAINED_GLASS:15)
B(0,1,-1,STAINED_GLASS:15)
B(1,1,-1,STAINED_GLASS:15)
B(2,1,-1,STAINED_GLASS:15)
B(-2,1,0,STAINED_GLASS:15)
B(-1,1,0,STAINED_GLASS:15)
B(0,1,0,STAINED_GLASS:15)
B(1,1,0,SEA_LANTERN)
B(2,1,0,STAINED_GLASS:15)
B(3,1,0,STAINED_GLASS:11)
B(-2,1,1,STAINED_GLASS:15)
B(-1,1,1,STAINED_GLASS:15)
B(0,1,1,SEA_LANTERN)
B(1,1,1,SEA_LANTERN)
B(2,1,1,STAINED_GLASS:15)
B(3,1,1,STAINED_GLASS:15)
B(-1,1,2,STAINED_GLASS:15)
B(0,1,2,STAINED_GLASS:15)
B(1,1,2,BLUE_GLAZED_TERRACOTTA:2)
B(2,1,2,STAINED_GLASS:15)
B(3,1,2,STAINED_GLASS:15)
B(0,1,3,STAINED_GLASS:15)
B(1,1,3,STAINED_GLASS:15)
B(0,2,-3,STAINED_GLASS:11)
B(-1,2,-2,STAINED_GLASS:15)
B(0,2,-2,BLUE_GLAZED_TERRACOTTA:2)
B(1,2,-2,STAINED_GLASS:11)
B(-2,2,-1,STAINED_GLASS:15)
B(-1,2,-1,STAINED_GLASS:15)
B(0,2,-1,SEA_LANTERN)
B(1,2,-1,STAINED_GLASS:15)
B(2,2,-1,STAINED_GLASS:15)
B(-3,2,0,STAINED_GLASS:15)
B(-2,2,0,STAINED_GLASS:15)
B(-1,2,0,SEA_LANTERN)
B(0,2,0,SEA_LANTERN)
B(1,2,0,SEA_LANTERN)
B(2,2,0,STAINED_GLASS:11)
B(3,2,0,STAINED_GLASS:11)
B(-2,2,1,STAINED_GLASS:15)
B(-1,2,1,STAINED_GLASS:15)
B(0,2,1,SEA_LANTERN)
B(1,2,1,STAINED_GLASS:11)
B(2,2,1,STAINED_GLASS:15)
B(-1,2,2,STAINED_GLASS:15)
B(0,2,2,BLUE_GLAZED_TERRACOTTA:2)
B(1,2,2,BLUE_GLAZED_TERRACOTTA:2)
B(0,2,3,STAINED_GLASS:15)
B(-1,3,-3,STAINED_GLASS:11)
B(0,3,-3,STAINED_GLASS:11)
B(-2,3,-2,STAINED_GLASS:15)
B(-1,3,-2,STAINED_GLASS:15)
B(0,3,-2,STAINED_GLASS:11)
B(1,3,-2,STAINED_GLASS:15)
B(-3,3,-1,STAINED_GLASS:15)
B(-2,3,-1,STAINED_GLASS:15)
B(-1,3,-1,SEA_LANTERN)
B(0,3,-1,SEA_LANTERN)
B(1,3,-1,STAINED_GLASS:15)
B(2,3,-1,STAINED_GLASS:11)
B(-3,3,0,STAINED_GLASS:15)
B(-2,3,0,STAINED_GLASS:15)
B(-1,3,0,SEA_LANTERN)
B(0,3,0,SEA_LANTERN)
B(1,3,0,STAINED_GLASS:11)
B(2,3,0,STAINED_GLASS:11)
B(-2,3,1,STAINED_GLASS:15)
B(-1,3,1,STAINED_GLASS:15)
B(0,3,1,STAINED_GLASS:11)
B(1,3,1,STAINED_GLASS:15)
B(-1,3,2,STAINED_GLASS:15)
B(0,3,2,STAINED_GLASS:15)
B(-1,4,-4,STAINED_GLASS:15)
B(-2,4,-3,STAINED_GLASS:15)
B(-1,4,-3,STAINED_GLASS:15)
B(0,4,-3,STAINED_GLASS:11)
B(-3,4,-2,STAINED_GLASS:15)
B(-2,4,-2,STAINED_GLASS:15)
B(-1,4,-2,SEA_LANTERN)
B(0,4,-2,STAINED_GLASS:15)
B(1,4,-2,STAINED_GLASS:15)
B(-4,4,-1,STAINED_GLASS:15)
B(-3,4,-1,STAINED_GLASS:15)
B(-2,4,-1,SEA_LANTERN)
B(-1,4,-1,SEA_LANTERN)
B(0,4,-1,SEA_LANTERN)
B(1,4,-1,STAINED_GLASS:11)
B(2,4,-1,STAINED_GLASS:15)
B(-3,4,0,STAINED_GLASS:15)
B(-2,4,0,STAINED_GLASS:15)
B(-1,4,0,SEA_LANTERN)
B(0,4,0,STAINED_GLASS:11)
B(1,4,0,STAINED_GLASS:15)
B(-2,4,1,STAINED_GLASS:15)
B(-1,4,1,STAINED_GLASS:11)
B(0,4,1,STAINED_GLASS:11)
B(-1,4,2,STAINED_GLASS:15)
B(-2,5,-4,STAINED_GLASS:15)
B(-1,5,-4,STAINED_GLASS:15)
B(-3,5,-3,STAINED_GLASS:15)
B(-2,5,-3,STAINED_GLASS:15)
B(-1,5,-3,BLUE_GLAZED_TERRACOTTA:2)
B(0,5,-3,BLUE_GLAZED_TERRACOTTA:2)
B(-4,5,-2,STAINED_GLASS:15)
B(-3,5,-2,STAINED_GLASS:15)
B(-2,5,-2,SEA_LANTERN)
B(-1,5,-2,SEA_LANTERN)
B(0,5,-2,BLUE_GLAZED_TERRACOTTA:2)
B(1,5,-2,STAINED_GLASS:11)
B(-4,5,-1,STAINED_GLASS:15)
B(-3,5,-1,STAINED_GLASS:15)
B(-2,5,-1,SEA_LANTERN)
B(-1,5,-1,SEA_LANTERN)
B(0,5,-1,STAINED_GLASS:11)
B(1,5,-1,STAINED_GLASS:11)
B(-3,5,0,STAINED_GLASS:11)
B(-2,5,0,STAINED_GLASS:15)
B(-1,5,0,BLUE_GLAZED_TERRACOTTA:2)
B(0,5,0,STAINED_GLASS:15)
B(-2,5,1,STAINED_GLASS:11)
B(-1,5,1,BLUE_GLAZED_TERRACOTTA:2)
B(-2,6,-5,STAINED_GLASS:11)
B(-3,6,-4,STAINED_GLASS:15)
B(-2,6,-4,STAINED_GLASS:11)
B(-1,6,-4,STAINED_GLASS:15)
B(-4,6,-3,STAINED_GLASS:15)
B(-3,6,-3,STAINED_GLASS:15)
B(-2,6,-3,SEA_LANTERN)
B(-1,6,-3,STAINED_GLASS:15)
B(0,6,-3,BLUE_GLAZED_TERRACOTTA:2)
B(-5,6,-2,STAINED_GLASS:15)
B(-4,6,-2,STAINED_GLASS:15)
B(-3,6,-2,SEA_LANTERN)
B(-2,6,-2,SEA_LANTERN)
B(-1,6,-2,SEA_LANTERN)
B(0,6,-2,STAINED_GLASS:11)
B(1,6,-2,STAINED_GLASS:15)
B(-4,6,-1,STAINED_GLASS:15)
B(-3,6,-1,STAINED_GLASS:11)
B(-2,6,-1,SEA_LANTERN)
B(-1,6,-1,STAINED_GLASS:11)
B(0,6,-1,STAINED_GLASS:11)
B(-3,6,0,STAINED_GLASS:11)
B(-2,6,0,STAINED_GLASS:11)
B(-1,6,0,STAINED_GLASS:15)
B(-2,6,1,STAINED_GLASS:11)
B(-3,7,-5,STAINED_GLASS:15)
B(-2,7,-5,STAINED_GLASS:11)
B(-4,7,-4,STAINED_GLASS:15)
B(-3,7,-4,STAINED_GLASS:15)
B(-2,7,-4,STAINED_GLASS:15)
B(-1,7,-4,STAINED_GLASS:15)
B(-5,7,-3,STAINED_GLASS:15)
B(-4,7,-3,STAINED_GLASS:15)
B(-3,7,-3,SEA_LANTERN)
B(-2,7,-3,SEA_LANTERN)
B(-1,7,-3,STAINED_GLASS:15)
B(0,7,-3,BLUE_GLAZED_TERRACOTTA:2)
B(-5,7,-2,STAINED_GLASS:15)
B(-4,7,-2,STAINED_GLASS:15)
B(-3,7,-2,SEA_LANTERN)
B(-2,7,-2,SEA_LANTERN)
B(-1,7,-2,STAINED_GLASS:11)
B(0,7,-2,STAINED_GLASS:15)
B(-4,7,-1,STAINED_GLASS:15)
B(-3,7,-1,STAINED_GLASS:15)
B(-2,7,-1,STAINED_GLASS:15)
B(-1,7,-1,STAINED_GLASS:15)
B(-3,7,0,STAINED_GLASS:11)
B(-2,7,0,STAINED_GLASS:15)
B(-3,8,-6,STAINED_GLASS:11)
B(-4,8,-5,STAINED_GLASS:15)
B(-3,8,-5,STAINED_GLASS:11)
B(-2,8,-5,STAINED_GLASS:15)
B(-5,8,-4,STAINED_GLASS:15)
B(-4,8,-4,STAINED_GLASS:15)
B(-3,8,-4,SEA_LANTERN)
B(-2,8,-4,STAINED_GLASS:15)
B(-1,8,-4,STAINED_GLASS:15)
B(-6,8,-3,STAINED_GLASS:15)
B(-5,8,-3,STAINED_GLASS:15)
B(-4,8,-3,SEA_LANTERN)
B(-3,8,-3,SEA_LANTERN)
B(-2,8,-3,SEA_LANTERN)
B(-1,8,-3,STAINED_GLASS:11)
B(0,8,-3,BLUE_GLAZED_TERRACOTTA:2)
B(-5,8,-2,STAINED_GLASS:15)
B(-4,8,-2,STAINED_GLASS:15)
B(-3,8,-2,SEA_LANTERN)
B(-2,8,-2,STAINED_GLASS:11)
B(-1,8,-2,STAINED_GLASS:11)
B(-4,8,-1,STAINED_GLASS:15)
B(-3,8,-1,STAINED_GLASS:11)
B(-2,8,-1,STAINED_GLASS:15)
B(-3,8,0,STAINED_GLASS:11)
B(-4,9,-6,STAINED_GLASS:15)
B(-3,9,-6,STAINED_GLASS:11)
B(-5,9,-5,STAINED_GLASS:11)
B(-4,9,-5,STAINED_GLASS:11)
B(-3,9,-5,STAINED_GLASS:15)
B(-2,9,-5,STAINED_GLASS:15)
B(-6,9,-4,STAINED_GLASS:15)
B(-5,9,-4,STAINED_GLASS:11)
B(-4,9,-4,SEA_LANTERN)
B(-3,9,-4,SEA_LANTERN)
B(-2,9,-4,STAINED_GLASS:15)
B(-1,9,-4,BLUE_GLAZED_TERRACOTTA:2)
B(-6,9,-3,STAINED_GLASS:15)
B(-5,9,-3,STAINED_GLASS:15)
B(-4,9,-3,SEA_LANTERN)
B(-3,9,-3,SEA_LANTERN)
B(-2,9,-3,STAINED_GLASS:11)
B(-1,9,-3,STAINED_GLASS:15)
B(-5,9,-2,STAINED_GLASS:15)
B(-4,9,-2,STAINED_GLASS:15)
B(-3,9,-2,STAINED_GLASS:11)
B(-2,9,-2,STAINED_GLASS:11)
B(-4,9,-1,BLUE_GLAZED_TERRACOTTA:2)
B(-3,9,-1,STAINED_GLASS:15)
B(-4,10,-7,STAINED_GLASS:15)
B(-5,10,-6,STAINED_GLASS:15)
B(-4,10,-6,STAINED_GLASS:15)
B(-3,10,-6,STAINED_GLASS:15)
B(-6,10,-5,STAINED_GLASS:15)
B(-5,10,-5,STAINED_GLASS:11)
B(-4,10,-5,SEA_LANTERN)
B(-3,10,-5,STAINED_GLASS:15)
B(-2,10,-5,STAINED_GLASS:15)
B(-7,10,-4,STAINED_GLASS:15)
B(-6,10,-4,STAINED_GLASS:15)
B(-5,10,-4,SEA_LANTERN)
B(-4,10,-4,SEA_LANTERN)
B(-3,10,-4,SEA_LANTERN)
B(-2,10,-4,STAINED_GLASS:11)
B(-1,10,-4,BLUE_GLAZED_TERRACOTTA:2)
B(-6,10,-3,STAINED_GLASS:15)
B(-5,10,-3,STAINED_GLASS:15)
B(-4,10,-3,SEA_LANTERN)
B(-3,10,-3,STAINED_GLASS:11)
B(-2,10,-3,STAINED_GLASS:11)
B(-5,10,-2,STAINED_GLASS:15)
B(-4,10,-2,BLUE_GLAZED_TERRACOTTA:2)
B(-3,10,-2,STAINED_GLASS:15)
B(-4,10,-1,BLUE_GLAZED_TERRACOTTA:2)
B(-5,11,-7,STAINED_GLASS:15)
B(-4,11,-7,STAINED_GLASS:15)
B(-6,11,-6,STAINED_GLASS:11)
B(-5,11,-6,STAINED_GLASS:11)
B(-4,11,-6,STAINED_GLASS:15)
B(-3,11,-6,STAINED_GLASS:15)
B(-7,11,-5,STAINED_GLASS:15)
B(-6,11,-5,STAINED_GLASS:11)
B(-5,11,-5,SEA_LANTERN)
B(-4,11,-5,SEA_LANTERN)
B(-3,11,-5,STAINED_GLASS:15)
B(-2,11,-5,BLUE_GLAZED_TERRACOTTA:2)
B(-7,11,-4,STAINED_GLASS:15)
B(-6,11,-4,STAINED_GLASS:15)
B(-5,11,-4,SEA_LANTERN)
B(-4,11,-4,SEA_LANTERN)
B(-3,11,-4,STAINED_GLASS:15)
B(-2,11,-4,STAINED_GLASS:15)
B(-6,11,-3,STAINED_GLASS:15)
B(-5,11,-3,STAINED_GLASS:15)
B(-4,11,-3,STAINED_GLASS:11)
B(-3,11,-3,STAINED_GLASS:15)
B(-5,11,-2,STAINED_GLASS:15)
B(-4,11,-2,STAINED_GLASS:15)
B(-5,12,-7,STAINED_GLASS:15)
B(-4,12,-7,STAINED_GLASS:15)
B(-6,12,-6,STAINED_GLASS:11)
B(-5,12,-6,SEA_LANTERN)
B(-4,12,-6,STAINED_GLASS:15)
B(-3,12,-6,STAINED_GLASS:15)
B(-7,12,-5,STAINED_GLASS:15)
B(-6,12,-5,SEA_LANTERN)
B(-5,12,-5,SEA_LANTERN)
B(-4,12,-5,SEA_LANTERN)
B(-3,12,-5,BLUE_GLAZED_TERRACOTTA:2)
B(-2,12,-5,BLUE_GLAZED_TERRACOTTA:2)
B(-7,12,-4,STAINED_GLASS:15)
B(-6,12,-4,STAINED_GLASS:15)
B(-5,12,-4,SEA_LANTERN)
B(-4,12,-4,STAINED_GLASS:11)
B(-3,12,-4,STAINED_GLASS:15)
B(-6,12,-3,STAINED_GLASS:15)
B(-5,12,-3,STAINED_GLASS:11)
B(-4,12,-3,STAINED_GLASS:11)
B(-5,12,-2,STAINED_GLASS:15)
B(-6,13,-7,STAINED_GLASS:15)
B(-5,13,-7,STAINED_GLASS:15)
B(-4,13,-7,STAINED_GLASS:15)
B(-7,13,-6,STAINED_GLASS:11)
B(-6,13,-6,SEA_LANTERN)
B(-5,13,-6,SEA_LANTERN)
B(-4,13,-6,STAINED_GLASS:15)
B(-3,13,-6,STAINED_GLASS:15)
B(-7,13,-5,STAINED_GLASS:11)
B(-6,13,-5,SEA_LANTERN)
B(-5,13,-5,SEA_LANTERN)
B(-4,13,-5,STAINED_GLASS:11)
B(-3,13,-5,STAINED_GLASS:15)
B(-7,13,-4,STAINED_GLASS:15)
B(-6,13,-4,STAINED_GLASS:15)
B(-5,13,-4,STAINED_GLASS:11)
B(-4,13,-4,STAINED_GLASS:11)
B(-6,13,-3,STAINED_GLASS:15)
B(-5,13,-3,STAINED_GLASS:15)
B(-6,14,-7,STAINED_GLASS:15)
B(-5,14,-7,STAINED_GLASS:15)
B(-7,14,-6,STAINED_GLASS:11)
B(-6,14,-6,SEA_LANTERN)
B(-5,14,-6,STAINED_GLASS:15)
B(-4,14,-6,STAINED_GLASS:11)
B(-7,14,-5,STAINED_GLASS:11)
B(-6,14,-5,STAINED_GLASS:15)
B(-5,14,-5,STAINED_GLASS:15)
B(-4,14,-5,STAINED_GLASS:11)
B(-6,14,-4,STAINED_GLASS:15)
B(-5,14,-4,STAINED_GLASS:15)
B(-6,15,-7,STAINED_GLASS:15)
B(-7,15,-6,STAINED_GLASS:11)
B(-6,15,-6,STAINED_GLASS:15)
B(-5,15,-6,STAINED_GLASS:15)
B(-6,15,-5,STAINED_GLASS:15)
B(-5,15,-5,STAINED_GLASS:15)
B(-6,16,-6,STAINED_GLASS:15)

