#######################################################################
# +-----------------------------------------------------------------+ #
# |                            BO3 object                           | #
# +-----------------------------------------------------------------+ #
#######################################################################

Author: Bo3 BulkEdit

Description: Converted Schematic - Modified by Bo3BulkEdit

Version: 3

SettingsMode: WriteDisable

#######################################################################
# +-----------------------------------------------------------------+ #
# |                          Main settings                          | #
# +-----------------------------------------------------------------+ #
#######################################################################

IsOTGPlus: true
Tree: false
Frequency: 1
Rarity: 100.0
RotateRandomly: false
SpawnHeight: randomY
MaxBranchDepth: 10
ExcludedBiomes: All

##############################
# Height Limits for the BO3. #
##############################

MinHeight: 0
MaxHeight: 255

#######################################################################
# +-----------------------------------------------------------------+ #
# |                      Source block settings                      | #
# +-----------------------------------------------------------------+ #
#######################################################################

CanOverride: true
MaxPercentageOutsideSourceBlock: 100
OutsideSourceBlock: placeAnyway

#######################################################################
# +-----------------------------------------------------------------+ #
# |                               OTG+                              | #
# +-----------------------------------------------------------------+ #
#######################################################################

BO3Group: CeilingCrystals:0

#######################################################################
# +-----------------------------------------------------------------+ #
# |                              Blocks                             | #
# +-----------------------------------------------------------------+ #
#######################################################################

B(0,750,0,AIR)
B(15,750,15,AIR)
B(10,-42,10,STAINED_GLASS:15)
B(11,-42,10,STAINED_GLASS:15)
B(10,-42,11,STAINED_GLASS:15)
B(11,-42,11,STAINED_GLASS:15)
B(8,-41,8,STAINED_GLASS:15)
B(9,-41,8,STAINED_GLASS:15)
B(10,-41,8,STAINED_GLASS:15)
B(8,-41,9,STAINED_GLASS:15)
B(9,-41,9,STAINED_GLASS:15)
B(10,-41,9,STAINED_GLASS:15)
B(11,-41,9,STAINED_GLASS:15)
B(8,-41,10,STAINED_GLASS:15)
B(9,-41,10,STAINED_GLASS:15)
B(10,-41,10,STAINED_GLASS:15)
B(11,-41,10,STAINED_GLASS:15)
B(9,-41,11,STAINED_GLASS:15)
B(10,-41,11,STAINED_GLASS:15)
B(11,-41,11,STAINED_GLASS:15)
B(7,-40,5,STAINED_GLASS:15)
B(8,-40,5,STAINED_GLASS:15)
B(6,-40,6,STAINED_GLASS:15)
B(7,-40,6,STAINED_GLASS:15)
B(8,-40,6,STAINED_GLASS:15)
B(9,-40,6,STAINED_GLASS:15)
B(5,-40,7,STAINED_GLASS:15)
B(6,-40,7,STAINED_GLASS:15)
B(7,-40,7,STAINED_GLASS:15)
B(8,-40,7,STAINED_GLASS:15)
B(9,-40,7,STAINED_GLASS:15)
B(10,-40,7,STAINED_GLASS:15)
B(5,-40,8,STAINED_GLASS:15)
B(6,-40,8,STAINED_GLASS:15)
B(7,-40,8,STAINED_GLASS:15)
B(8,-40,8,STAINED_GLASS:15)
B(9,-40,8,STAINED_GLASS:15)
B(10,-40,8,STAINED_GLASS:15)
B(11,-40,8,STAINED_GLASS:15)
B(6,-40,9,STAINED_GLASS:15)
B(7,-40,9,STAINED_GLASS:15)
B(8,-40,9,STAINED_GLASS:15)
B(10,-40,9,STAINED_GLASS:15)
B(11,-40,9,STAINED_GLASS:15)
B(7,-40,10,STAINED_GLASS:15)
B(8,-40,10,STAINED_GLASS:15)
B(9,-40,10,STAINED_GLASS:15)
B(10,-40,10,STAINED_GLASS:15)
B(8,-40,11,STAINED_GLASS:15)
B(9,-40,11,STAINED_GLASS:15)
B(6,-39,3,STAINED_GLASS:15)
B(7,-39,3,STAINED_GLASS:15)
B(5,-39,4,STAINED_GLASS:15)
B(6,-39,4,STAINED_GLASS:15)
B(7,-39,4,STAINED_GLASS:15)
B(8,-39,4,STAINED_GLASS:15)
B(4,-39,5,STAINED_GLASS:15)
B(5,-39,5,STAINED_GLASS:15)
B(6,-39,5,STAINED_GLASS:15)
B(7,-39,5,STAINED_GLASS:15)
B(8,-39,5,STAINED_GLASS:15)
B(9,-39,5,STAINED_GLASS:15)
B(3,-39,6,STAINED_GLASS:15)
B(4,-39,6,STAINED_GLASS:15)
B(5,-39,6,STAINED_GLASS:15)
B(6,-39,6,SEA_LANTERN)
B(7,-39,6,STAINED_GLASS:15)
B(8,-39,6,STAINED_GLASS:15)
B(9,-39,6,STAINED_GLASS:15)
B(10,-39,6,STAINED_GLASS:15)
B(3,-39,7,STAINED_GLASS:15)
B(4,-39,7,STAINED_GLASS:15)
B(5,-39,7,STAINED_GLASS:15)
B(6,-39,7,STAINED_GLASS:15)
B(7,-39,7,STAINED_GLASS:15)
B(10,-39,7,STAINED_GLASS:15)
B(11,-39,7,STAINED_GLASS:15)
B(4,-39,8,STAINED_GLASS:15)
B(5,-39,8,STAINED_GLASS:15)
B(6,-39,8,STAINED_GLASS:15)
B(10,-39,8,STAINED_GLASS:15)
B(11,-39,8,STAINED_GLASS:15)
B(5,-39,9,STAINED_GLASS:15)
B(6,-39,9,STAINED_GLASS:15)
B(10,-39,9,STAINED_GLASS:15)
B(5,-39,10,STAINED_GLASS:15)
B(6,-39,10,STAINED_GLASS:15)
B(7,-39,10,STAINED_GLASS:15)
B(8,-39,10,STAINED_GLASS:15)
B(9,-39,10,STAINED_GLASS:15)
B(7,-39,11,STAINED_GLASS:15)
B(8,-39,11,STAINED_GLASS:15)
B(5,-38,1,STAINED_GLASS:15)
B(6,-38,1,STAINED_GLASS:15)
B(4,-38,2,STAINED_GLASS:15)
B(5,-38,2,STAINED_GLASS:15)
B(6,-38,2,STAINED_GLASS:15)
B(7,-38,2,STAINED_GLASS:15)
B(8,-38,2,STAINED_GLASS:15)
B(3,-38,3,STAINED_GLASS:15)
B(4,-38,3,STAINED_GLASS:15)
B(5,-38,3,STAINED_GLASS:15)
B(6,-38,3,STAINED_GLASS:15)
B(7,-38,3,STAINED_GLASS:15)
B(8,-38,3,STAINED_GLASS:15)
B(9,-38,3,STAINED_GLASS:15)
B(2,-38,4,STAINED_GLASS:15)
B(3,-38,4,STAINED_GLASS:15)
B(4,-38,4,STAINED_GLASS:15)
B(5,-38,4,STAINED_GLASS:15)
B(6,-38,4,STAINED_GLASS:15)
B(7,-38,4,STAINED_GLASS:15)
B(8,-38,4,STAINED_GLASS:15)
B(9,-38,4,STAINED_GLASS:15)
B(1,-38,5,STAINED_GLASS:15)
B(2,-38,5,STAINED_GLASS:15)
B(3,-38,5,STAINED_GLASS:15)
B(4,-38,5,STAINED_GLASS:15)
B(5,-38,5,STAINED_GLASS:15)
B(6,-38,5,SEA_LANTERN)
B(9,-38,5,STAINED_GLASS:15)
B(10,-38,5,STAINED_GLASS:15)
B(1,-38,6,STAINED_GLASS:15)
B(2,-38,6,STAINED_GLASS:15)
B(3,-38,6,STAINED_GLASS:15)
B(5,-38,6,SEA_LANTERN)
B(6,-38,6,SEA_LANTERN)
B(7,-38,6,SEA_LANTERN)
B(10,-38,6,STAINED_GLASS:15)
B(2,-38,7,STAINED_GLASS:15)
B(3,-38,7,STAINED_GLASS:15)
B(4,-38,7,STAINED_GLASS:15)
B(6,-38,7,SEA_LANTERN)
B(9,-38,7,STAINED_GLASS:15)
B(2,-38,8,STAINED_GLASS:15)
B(3,-38,8,STAINED_GLASS:15)
B(4,-38,8,STAINED_GLASS:15)
B(9,-38,8,STAINED_GLASS:15)
B(10,-38,8,STAINED_GLASS:15)
B(3,-38,9,STAINED_GLASS:15)
B(4,-38,9,STAINED_GLASS:15)
B(5,-38,9,STAINED_GLASS:15)
B(6,-38,9,STAINED_GLASS:15)
B(7,-38,9,STAINED_GLASS:15)
B(8,-38,9,STAINED_GLASS:15)
B(9,-38,9,STAINED_GLASS:15)
B(10,-38,9,STAINED_GLASS:15)
B(5,-38,10,STAINED_GLASS:15)
B(6,-38,10,STAINED_GLASS:15)
B(7,-38,10,STAINED_GLASS:15)
B(9,-38,10,STAINED_GLASS:15)
B(4,-37,0,STAINED_GLASS:15)
B(5,-37,0,STAINED_GLASS:15)
B(3,-37,1,STAINED_GLASS:15)
B(4,-37,1,STAINED_GLASS:15)
B(5,-37,1,STAINED_GLASS:15)
B(6,-37,1,STAINED_GLASS:15)
B(7,-37,1,STAINED_GLASS:15)
B(2,-37,2,STAINED_GLASS:15)
B(3,-37,2,STAINED_GLASS:15)
B(4,-37,2,STAINED_GLASS:15)
B(5,-37,2,STAINED_GLASS:15)
B(6,-37,2,STAINED_GLASS:15)
B(7,-37,2,STAINED_GLASS:15)
B(8,-37,2,STAINED_GLASS:15)
B(1,-37,3,STAINED_GLASS:15)
B(2,-37,3,STAINED_GLASS:15)
B(3,-37,3,STAINED_GLASS:15)
B(4,-37,3,STAINED_GLASS:11)
B(5,-37,3,STAINED_GLASS:10)
B(6,-37,3,STAINED_GLASS:10)
B(7,-37,3,STAINED_GLASS:11)
B(8,-37,3,STAINED_GLASS:15)
B(9,-37,3,STAINED_GLASS:9)
B(0,-37,4,STAINED_GLASS:15)
B(1,-37,4,STAINED_GLASS:15)
B(2,-37,4,STAINED_GLASS:15)
B(3,-37,4,STAINED_GLASS:11)
B(4,-37,4,STAINED_GLASS:10)
B(5,-37,4,STAINED_GLASS:10)
B(6,-37,4,STAINED_GLASS:10)
B(7,-37,4,STAINED_GLASS:10)
B(8,-37,4,STAINED_GLASS:11)
B(9,-37,4,STAINED_GLASS:11)
B(10,-37,4,STAINED_GLASS:15)
B(0,-37,5,STAINED_GLASS:15)
B(1,-37,5,STAINED_GLASS:15)
B(2,-37,5,STAINED_GLASS:11)
B(3,-37,5,STAINED_GLASS:10)
B(4,-37,5,STAINED_GLASS:10)
B(5,-37,5,SEA_LANTERN)
B(6,-37,5,SEA_LANTERN)
B(7,-37,5,STAINED_GLASS:10)
B(8,-37,5,STAINED_GLASS:10)
B(9,-37,5,STAINED_GLASS:11)
B(10,-37,5,STAINED_GLASS:15)
B(1,-37,6,STAINED_GLASS:15)
B(2,-37,6,STAINED_GLASS:15)
B(3,-37,6,STAINED_GLASS:10)
B(4,-37,6,STAINED_GLASS:10)
B(5,-37,6,SEA_LANTERN)
B(6,-37,6,SEA_LANTERN)
B(7,-37,6,STAINED_GLASS:10)
B(8,-37,6,STAINED_GLASS:10)
B(9,-37,6,STAINED_GLASS:11)
B(10,-37,6,STAINED_GLASS:15)
B(1,-37,7,STAINED_GLASS:15)
B(2,-37,7,STAINED_GLASS:15)
B(3,-37,7,STAINED_GLASS:11)
B(4,-37,7,STAINED_GLASS:10)
B(5,-37,7,STAINED_GLASS:10)
B(6,-37,7,STAINED_GLASS:10)
B(7,-37,7,STAINED_GLASS:10)
B(8,-37,7,STAINED_GLASS:11)
B(9,-37,7,STAINED_GLASS:15)
B(2,-37,8,STAINED_GLASS:15)
B(3,-37,8,STAINED_GLASS:15)
B(4,-37,8,STAINED_GLASS:11)
B(5,-37,8,STAINED_GLASS:10)
B(6,-37,8,STAINED_GLASS:10)
B(7,-37,8,STAINED_GLASS:11)
B(8,-37,8,STAINED_GLASS:11)
B(9,-37,8,STAINED_GLASS:15)
B(3,-37,9,STAINED_GLASS:15)
B(4,-37,9,STAINED_GLASS:15)
B(5,-37,9,STAINED_GLASS:11)
B(6,-37,9,STAINED_GLASS:15)
B(7,-37,9,STAINED_GLASS:9)
B(8,-37,9,STAINED_GLASS:15)
B(4,-37,10,STAINED_GLASS:15)
B(5,-37,10,STAINED_GLASS:15)
B(6,-37,10,STAINED_GLASS:15)
B(3,-36,0,STAINED_GLASS:9)
B(4,-36,0,STAINED_GLASS:11)
B(5,-36,0,STAINED_GLASS:9)
B(2,-36,1,STAINED_GLASS:9)
B(3,-36,1,STAINED_GLASS:11)
B(4,-36,1,STAINED_GLASS:9)
B(5,-36,1,STAINED_GLASS:11)
B(6,-36,1,STAINED_GLASS:9)
B(7,-36,1,STAINED_GLASS:9)
B(1,-36,2,STAINED_GLASS:9)
B(2,-36,2,STAINED_GLASS:11)
B(3,-36,2,STAINED_GLASS:9)
B(4,-36,2,STAINED_GLASS:11)
B(5,-36,2,STAINED_GLASS:10)
B(6,-36,2,STAINED_GLASS:11)
B(7,-36,2,STAINED_GLASS:9)
B(8,-36,2,STAINED_GLASS:9)
B(0,-36,3,STAINED_GLASS:9)
B(1,-36,3,STAINED_GLASS:11)
B(2,-36,3,STAINED_GLASS:9)
B(3,-36,3,STAINED_GLASS:11)
B(4,-36,3,STAINED_GLASS:10)
B(5,-36,3,STAINED_GLASS:10)
B(6,-36,3,STAINED_GLASS:10)
B(7,-36,3,STAINED_GLASS:11)
B(8,-36,3,STAINED_GLASS:11)
B(9,-36,3,STAINED_GLASS:15)
B(0,-36,4,STAINED_GLASS:11)
B(1,-36,4,STAINED_GLASS:9)
B(2,-36,4,STAINED_GLASS:11)
B(3,-36,4,STAINED_GLASS:10)
B(4,-36,4,STAINED_GLASS:10)
B(5,-36,4,SEA_LANTERN)
B(6,-36,4,STAINED_GLASS:10)
B(7,-36,4,STAINED_GLASS:10)
B(8,-36,4,STAINED_GLASS:11)
B(9,-36,4,STAINED_GLASS:15)
B(0,-36,5,STAINED_GLASS:9)
B(1,-36,5,STAINED_GLASS:11)
B(2,-36,5,STAINED_GLASS:10)
B(3,-36,5,STAINED_GLASS:10)
B(4,-36,5,SEA_LANTERN)
B(5,-36,5,SEA_LANTERN)
B(6,-36,5,SEA_LANTERN)
B(7,-36,5,STAINED_GLASS:10)
B(8,-36,5,STAINED_GLASS:10)
B(9,-36,5,STAINED_GLASS:11)
B(10,-36,5,STAINED_GLASS:15)
B(1,-36,6,STAINED_GLASS:15)
B(2,-36,6,STAINED_GLASS:11)
B(3,-36,6,STAINED_GLASS:10)
B(4,-36,6,STAINED_GLASS:10)
B(5,-36,6,SEA_LANTERN)
B(6,-36,6,STAINED_GLASS:10)
B(7,-36,6,STAINED_GLASS:10)
B(8,-36,6,STAINED_GLASS:11)
B(9,-36,6,STAINED_GLASS:15)
B(1,-36,7,STAINED_GLASS:15)
B(2,-36,7,STAINED_GLASS:15)
B(3,-36,7,STAINED_GLASS:11)
B(4,-36,7,STAINED_GLASS:10)
B(5,-36,7,STAINED_GLASS:10)
B(6,-36,7,STAINED_GLASS:10)
B(7,-36,7,STAINED_GLASS:11)
B(8,-36,7,STAINED_GLASS:11)
B(9,-36,7,STAINED_GLASS:15)
B(2,-36,8,STAINED_GLASS:15)
B(3,-36,8,STAINED_GLASS:11)
B(4,-36,8,STAINED_GLASS:11)
B(5,-36,8,STAINED_GLASS:10)
B(6,-36,8,STAINED_GLASS:11)
B(7,-36,8,STAINED_GLASS:11)
B(8,-36,8,STAINED_GLASS:15)
B(3,-36,9,STAINED_GLASS:15)
B(4,-36,9,STAINED_GLASS:9)
B(5,-36,9,STAINED_GLASS:11)
B(6,-36,9,STAINED_GLASS:9)
B(7,-36,9,STAINED_GLASS:9)
B(5,-36,10,STAINED_GLASS:9)
B(2,-35,0,STAINED_GLASS:9)
B(3,-35,0,STAINED_GLASS:11)
B(4,-35,0,STAINED_GLASS:9)
B(5,-35,0,STAINED_GLASS:9)
B(6,-35,0,STAINED_GLASS:9)
B(1,-35,1,STAINED_GLASS:9)
B(2,-35,1,STAINED_GLASS:11)
B(3,-35,1,STAINED_GLASS:9)
B(4,-35,1,STAINED_GLASS:11)
B(5,-35,1,STAINED_GLASS:11)
B(6,-35,1,STAINED_GLASS:9)
B(7,-35,1,STAINED_GLASS:9)
B(0,-35,2,STAINED_GLASS:9)
B(1,-35,2,STAINED_GLASS:11)
B(2,-35,2,STAINED_GLASS:9)
B(3,-35,2,STAINED_GLASS:11)
B(4,-35,2,STAINED_GLASS:10)
B(5,-35,2,STAINED_GLASS:10)
B(6,-35,2,STAINED_GLASS:11)
B(7,-35,2,STAINED_GLASS:11)
B(8,-35,2,STAINED_GLASS:9)
B(0,-35,3,STAINED_GLASS:11)
B(1,-35,3,STAINED_GLASS:9)
B(2,-35,3,STAINED_GLASS:11)
B(3,-35,3,STAINED_GLASS:10)
B(4,-35,3,STAINED_GLASS:10)
B(5,-35,3,STAINED_GLASS:10)
B(6,-35,3,STAINED_GLASS:10)
B(7,-35,3,STAINED_GLASS:11)
B(8,-35,3,STAINED_GLASS:11)
B(9,-35,3,STAINED_GLASS:15)
B(0,-35,4,STAINED_GLASS:9)
B(1,-35,4,STAINED_GLASS:11)
B(2,-35,4,STAINED_GLASS:10)
B(3,-35,4,STAINED_GLASS:10)
B(4,-35,4,SEA_LANTERN)
B(5,-35,4,SEA_LANTERN)
B(6,-35,4,STAINED_GLASS:10)
B(7,-35,4,STAINED_GLASS:10)
B(8,-35,4,STAINED_GLASS:11)
B(9,-35,4,STAINED_GLASS:9)
B(0,-35,5,STAINED_GLASS:9)
B(1,-35,5,STAINED_GLASS:11)
B(2,-35,5,STAINED_GLASS:10)
B(3,-35,5,STAINED_GLASS:10)
B(4,-35,5,SEA_LANTERN)
B(5,-35,5,SEA_LANTERN)
B(6,-35,5,STAINED_GLASS:10)
B(7,-35,5,STAINED_GLASS:10)
B(8,-35,5,STAINED_GLASS:11)
B(9,-35,5,STAINED_GLASS:15)
B(0,-35,6,STAINED_GLASS:15)
B(1,-35,6,STAINED_GLASS:15)
B(2,-35,6,STAINED_GLASS:11)
B(3,-35,6,STAINED_GLASS:10)
B(4,-35,6,STAINED_GLASS:10)
B(5,-35,6,STAINED_GLASS:10)
B(6,-35,6,STAINED_GLASS:10)
B(7,-35,6,STAINED_GLASS:11)
B(8,-35,6,STAINED_GLASS:15)
B(1,-35,7,STAINED_GLASS:15)
B(2,-35,7,STAINED_GLASS:11)
B(3,-35,7,STAINED_GLASS:11)
B(4,-35,7,STAINED_GLASS:10)
B(5,-35,7,STAINED_GLASS:10)
B(6,-35,7,STAINED_GLASS:11)
B(7,-35,7,STAINED_GLASS:11)
B(8,-35,7,STAINED_GLASS:15)
B(2,-35,8,STAINED_GLASS:15)
B(3,-35,8,STAINED_GLASS:11)
B(4,-35,8,STAINED_GLASS:11)
B(5,-35,8,STAINED_GLASS:11)
B(6,-35,8,STAINED_GLASS:9)
B(7,-35,8,STAINED_GLASS:15)
B(3,-35,9,STAINED_GLASS:9)
B(4,-35,9,STAINED_GLASS:9)
B(5,-35,9,STAINED_GLASS:9)
B(1,-34,0,STAINED_GLASS:9)
B(2,-34,0,STAINED_GLASS:11)
B(3,-34,0,STAINED_GLASS:9)
B(4,-34,0,STAINED_GLASS:11)
B(5,-34,0,STAINED_GLASS:15)
B(6,-34,0,STAINED_GLASS:15)
B(0,-34,1,STAINED_GLASS:9)
B(1,-34,1,STAINED_GLASS:11)
B(2,-34,1,STAINED_GLASS:9)
B(3,-34,1,STAINED_GLASS:11)
B(4,-34,1,STAINED_GLASS:10)
B(5,-34,1,STAINED_GLASS:11)
B(6,-34,1,STAINED_GLASS:9)
B(7,-34,1,STAINED_GLASS:15)
B(0,-34,2,STAINED_GLASS:11)
B(1,-34,2,STAINED_GLASS:9)
B(2,-34,2,STAINED_GLASS:11)
B(3,-34,2,STAINED_GLASS:10)
B(4,-34,2,STAINED_GLASS:10)
B(5,-34,2,STAINED_GLASS:10)
B(6,-34,2,STAINED_GLASS:11)
B(7,-34,2,STAINED_GLASS:11)
B(8,-34,2,STAINED_GLASS:15)
B(0,-34,3,STAINED_GLASS:9)
B(1,-34,3,STAINED_GLASS:11)
B(2,-34,3,STAINED_GLASS:10)
B(3,-34,3,STAINED_GLASS:10)
B(4,-34,3,SEA_LANTERN)
B(5,-34,3,STAINED_GLASS:10)
B(6,-34,3,STAINED_GLASS:10)
B(7,-34,3,STAINED_GLASS:11)
B(8,-34,3,STAINED_GLASS:15)
B(0,-34,4,STAINED_GLASS:11)
B(1,-34,4,STAINED_GLASS:10)
B(2,-34,4,STAINED_GLASS:10)
B(3,-34,4,SEA_LANTERN)
B(4,-34,4,SEA_LANTERN)
B(5,-34,4,SEA_LANTERN)
B(6,-34,4,STAINED_GLASS:10)
B(7,-34,4,STAINED_GLASS:10)
B(8,-34,4,STAINED_GLASS:11)
B(9,-34,4,STAINED_GLASS:9)
B(0,-34,5,STAINED_GLASS:15)
B(1,-34,5,STAINED_GLASS:11)
B(2,-34,5,STAINED_GLASS:10)
B(3,-34,5,STAINED_GLASS:10)
B(4,-34,5,SEA_LANTERN)
B(5,-34,5,STAINED_GLASS:10)
B(6,-34,5,STAINED_GLASS:10)
B(7,-34,5,STAINED_GLASS:11)
B(8,-34,5,STAINED_GLASS:9)
B(0,-34,6,STAINED_GLASS:15)
B(1,-34,6,STAINED_GLASS:15)
B(2,-34,6,STAINED_GLASS:11)
B(3,-34,6,STAINED_GLASS:10)
B(4,-34,6,STAINED_GLASS:10)
B(5,-34,6,STAINED_GLASS:10)
B(6,-34,6,STAINED_GLASS:11)
B(7,-34,6,STAINED_GLASS:11)
B(8,-34,6,STAINED_GLASS:15)
B(1,-34,7,STAINED_GLASS:15)
B(2,-34,7,STAINED_GLASS:11)
B(3,-34,7,STAINED_GLASS:11)
B(4,-34,7,STAINED_GLASS:10)
B(5,-34,7,STAINED_GLASS:11)
B(6,-34,7,STAINED_GLASS:11)
B(7,-34,7,STAINED_GLASS:15)
B(2,-34,8,STAINED_GLASS:9)
B(3,-34,8,STAINED_GLASS:9)
B(4,-34,8,STAINED_GLASS:11)
B(5,-34,8,STAINED_GLASS:9)
B(6,-34,8,STAINED_GLASS:9)
B(4,-34,9,STAINED_GLASS:9)
B(0,-33,0,STAINED_GLASS:9)
B(1,-33,0,STAINED_GLASS:11)
B(2,-33,0,STAINED_GLASS:9)
B(3,-33,0,STAINED_GLASS:11)
B(4,-33,0,STAINED_GLASS:11)
B(5,-33,0,STAINED_GLASS:15)
B(6,-33,0,STAINED_GLASS:15)
B(0,-33,1,STAINED_GLASS:11)
B(1,-33,1,STAINED_GLASS:9)
B(2,-33,1,STAINED_GLASS:11)
B(3,-33,1,STAINED_GLASS:10)
B(4,-33,1,STAINED_GLASS:10)
B(5,-33,1,STAINED_GLASS:11)
B(6,-33,1,STAINED_GLASS:11)
B(7,-33,1,STAINED_GLASS:15)
B(0,-33,2,STAINED_GLASS:9)
B(1,-33,2,STAINED_GLASS:11)
B(2,-33,2,STAINED_GLASS:10)
B(3,-33,2,STAINED_GLASS:10)
B(4,-33,2,STAINED_GLASS:10)
B(5,-33,2,STAINED_GLASS:10)
B(6,-33,2,STAINED_GLASS:11)
B(7,-33,2,STAINED_GLASS:11)
B(8,-33,2,STAINED_GLASS:9)
B(0,-33,3,STAINED_GLASS:11)
B(1,-33,3,STAINED_GLASS:10)
B(2,-33,3,STAINED_GLASS:10)
B(3,-33,3,SEA_LANTERN)
B(4,-33,3,SEA_LANTERN)
B(5,-33,3,STAINED_GLASS:10)
B(6,-33,3,STAINED_GLASS:10)
B(7,-33,3,STAINED_GLASS:11)
B(8,-33,3,STAINED_GLASS:9)
B(0,-33,4,STAINED_GLASS:11)
B(1,-33,4,STAINED_GLASS:10)
B(2,-33,4,STAINED_GLASS:10)
B(3,-33,4,SEA_LANTERN)
B(4,-33,4,SEA_LANTERN)
B(5,-33,4,STAINED_GLASS:10)
B(6,-33,4,STAINED_GLASS:10)
B(7,-33,4,STAINED_GLASS:11)
B(8,-33,4,STAINED_GLASS:9)
B(0,-33,5,STAINED_GLASS:15)
B(1,-33,5,STAINED_GLASS:11)
B(2,-33,5,STAINED_GLASS:10)
B(3,-33,5,STAINED_GLASS:10)
B(4,-33,5,STAINED_GLASS:10)
B(5,-33,5,STAINED_GLASS:10)
B(6,-33,5,STAINED_GLASS:11)
B(7,-33,5,STAINED_GLASS:15)
B(0,-33,6,STAINED_GLASS:15)
B(1,-33,6,STAINED_GLASS:11)
B(2,-33,6,STAINED_GLASS:11)
B(3,-33,6,STAINED_GLASS:10)
B(4,-33,6,STAINED_GLASS:10)
B(5,-33,6,STAINED_GLASS:11)
B(6,-33,6,STAINED_GLASS:11)
B(7,-33,6,STAINED_GLASS:15)
B(1,-33,7,STAINED_GLASS:15)
B(2,-33,7,STAINED_GLASS:11)
B(3,-33,7,STAINED_GLASS:11)
B(4,-33,7,STAINED_GLASS:11)
B(5,-33,7,STAINED_GLASS:9)
B(6,-33,7,STAINED_GLASS:15)
B(2,-33,8,STAINED_GLASS:9)
B(3,-33,8,STAINED_GLASS:9)
B(4,-33,8,STAINED_GLASS:9)
B(0,-32,0,STAINED_GLASS:11)
B(1,-32,0,STAINED_GLASS:9)
B(2,-32,0,STAINED_GLASS:11)
B(3,-32,0,STAINED_GLASS:10)
B(4,-32,0,STAINED_GLASS:11)
B(5,-32,0,STAINED_GLASS:15)
B(6,-32,0,STAINED_GLASS:15)
B(0,-32,1,STAINED_GLASS:9)
B(1,-32,1,STAINED_GLASS:11)
B(2,-32,1,STAINED_GLASS:10)
B(3,-32,1,STAINED_GLASS:10)
B(4,-32,1,STAINED_GLASS:10)
B(5,-32,1,STAINED_GLASS:11)
B(6,-32,1,STAINED_GLASS:11)
B(7,-32,1,STAINED_GLASS:9)
B(0,-32,2,STAINED_GLASS:11)
B(1,-32,2,STAINED_GLASS:10)
B(2,-32,2,STAINED_GLASS:10)
B(3,-32,2,SEA_LANTERN)
B(4,-32,2,STAINED_GLASS:10)
B(5,-32,2,STAINED_GLASS:10)
B(6,-32,2,STAINED_GLASS:11)
B(7,-32,2,STAINED_GLASS:9)
B(0,-32,3,STAINED_GLASS:10)
B(1,-32,3,STAINED_GLASS:10)
B(2,-32,3,SEA_LANTERN)
B(3,-32,3,SEA_LANTERN)
B(4,-32,3,SEA_LANTERN)
B(5,-32,3,STAINED_GLASS:10)
B(6,-32,3,STAINED_GLASS:10)
B(7,-32,3,STAINED_GLASS:11)
B(8,-32,3,STAINED_GLASS:9)
B(0,-32,4,STAINED_GLASS:11)
B(1,-32,4,STAINED_GLASS:10)
B(2,-32,4,STAINED_GLASS:10)
B(3,-32,4,SEA_LANTERN)
B(4,-32,4,STAINED_GLASS:10)
B(5,-32,4,STAINED_GLASS:10)
B(6,-32,4,STAINED_GLASS:11)
B(7,-32,4,STAINED_GLASS:9)
B(0,-32,5,STAINED_GLASS:15)
B(1,-32,5,STAINED_GLASS:11)
B(2,-32,5,STAINED_GLASS:10)
B(3,-32,5,STAINED_GLASS:10)
B(4,-32,5,STAINED_GLASS:10)
B(5,-32,5,STAINED_GLASS:11)
B(6,-32,5,STAINED_GLASS:11)
B(7,-32,5,STAINED_GLASS:15)
B(0,-32,6,STAINED_GLASS:15)
B(1,-32,6,STAINED_GLASS:11)
B(2,-32,6,STAINED_GLASS:11)
B(3,-32,6,STAINED_GLASS:10)
B(4,-32,6,STAINED_GLASS:11)
B(5,-32,6,STAINED_GLASS:11)
B(6,-32,6,STAINED_GLASS:15)
B(1,-32,7,STAINED_GLASS:15)
B(2,-32,7,STAINED_GLASS:9)
B(3,-32,7,STAINED_GLASS:11)
B(4,-32,7,STAINED_GLASS:9)
B(5,-32,7,STAINED_GLASS:9)
B(3,-32,8,STAINED_GLASS:9)
B(0,-31,0,STAINED_GLASS:9)
B(1,-31,0,STAINED_GLASS:11)
B(2,-31,0,STAINED_GLASS:10)
B(3,-31,0,STAINED_GLASS:10)
B(4,-31,0,STAINED_GLASS:11)
B(5,-31,0,STAINED_GLASS:11)
B(6,-31,0,STAINED_GLASS:9)
B(0,-31,1,STAINED_GLASS:11)
B(1,-31,1,STAINED_GLASS:10)
B(2,-31,1,STAINED_GLASS:10)
B(3,-31,1,STAINED_GLASS:10)
B(4,-31,1,STAINED_GLASS:10)
B(5,-31,1,STAINED_GLASS:11)
B(6,-31,1,STAINED_GLASS:11)
B(7,-31,1,STAINED_GLASS:9)
B(0,-31,2,STAINED_GLASS:10)
B(1,-31,2,STAINED_GLASS:10)
B(2,-31,2,SEA_LANTERN)
B(3,-31,2,SEA_LANTERN)
B(4,-31,2,STAINED_GLASS:10)
B(5,-31,2,STAINED_GLASS:10)
B(6,-31,2,STAINED_GLASS:11)
B(7,-31,2,STAINED_GLASS:9)
B(0,-31,3,STAINED_GLASS:10)
B(1,-31,3,STAINED_GLASS:10)
B(2,-31,3,SEA_LANTERN)
B(3,-31,3,SEA_LANTERN)
B(4,-31,3,STAINED_GLASS:10)
B(5,-31,3,STAINED_GLASS:10)
B(6,-31,3,STAINED_GLASS:11)
B(7,-31,3,STAINED_GLASS:9)
B(0,-31,4,STAINED_GLASS:11)
B(1,-31,4,STAINED_GLASS:10)
B(2,-31,4,STAINED_GLASS:10)
B(3,-31,4,STAINED_GLASS:10)
B(4,-31,4,STAINED_GLASS:10)
B(5,-31,4,STAINED_GLASS:11)
B(6,-31,4,STAINED_GLASS:9)
B(0,-31,5,STAINED_GLASS:11)
B(1,-31,5,STAINED_GLASS:11)
B(2,-31,5,STAINED_GLASS:10)
B(3,-31,5,STAINED_GLASS:10)
B(4,-31,5,STAINED_GLASS:11)
B(5,-31,5,STAINED_GLASS:11)
B(6,-31,5,STAINED_GLASS:15)
B(0,-31,6,STAINED_GLASS:15)
B(1,-31,6,STAINED_GLASS:11)
B(2,-31,6,STAINED_GLASS:11)
B(3,-31,6,STAINED_GLASS:11)
B(4,-31,6,STAINED_GLASS:9)
B(5,-31,6,STAINED_GLASS:9)
B(1,-31,7,STAINED_GLASS:9)
B(2,-31,7,STAINED_GLASS:9)
B(3,-31,7,STAINED_GLASS:9)
B(0,-30,0,STAINED_GLASS:11)
B(1,-30,0,STAINED_GLASS:10)
B(2,-30,0,STAINED_GLASS:10)
B(3,-30,0,STAINED_GLASS:10)
B(4,-30,0,STAINED_GLASS:11)
B(5,-30,0,STAINED_GLASS:11)
B(6,-30,0,STAINED_GLASS:9)
B(0,-30,1,STAINED_GLASS:10)
B(1,-30,1,STAINED_GLASS:10)
B(2,-30,1,SEA_LANTERN)
B(3,-30,1,STAINED_GLASS:10)
B(4,-30,1,STAINED_GLASS:10)
B(5,-30,1,STAINED_GLASS:11)
B(6,-30,1,STAINED_GLASS:9)
B(0,-30,2,STAINED_GLASS:10)
B(1,-30,2,SEA_LANTERN)
B(2,-30,2,SEA_LANTERN)
B(3,-30,2,SEA_LANTERN)
B(4,-30,2,STAINED_GLASS:10)
B(5,-30,2,STAINED_GLASS:10)
B(6,-30,2,STAINED_GLASS:11)
B(7,-30,2,STAINED_GLASS:9)
B(0,-30,3,STAINED_GLASS:10)
B(1,-30,3,STAINED_GLASS:10)
B(2,-30,3,SEA_LANTERN)
B(3,-30,3,STAINED_GLASS:10)
B(4,-30,3,STAINED_GLASS:10)
B(5,-30,3,STAINED_GLASS:11)
B(6,-30,3,STAINED_GLASS:9)
B(0,-30,4,STAINED_GLASS:11)
B(1,-30,4,STAINED_GLASS:10)
B(2,-30,4,STAINED_GLASS:10)
B(3,-30,4,STAINED_GLASS:10)
B(4,-30,4,STAINED_GLASS:11)
B(5,-30,4,STAINED_GLASS:11)
B(6,-30,4,STAINED_GLASS:15)
B(0,-30,5,STAINED_GLASS:11)
B(1,-30,5,STAINED_GLASS:11)
B(2,-30,5,STAINED_GLASS:10)
B(3,-30,5,STAINED_GLASS:11)
B(4,-30,5,STAINED_GLASS:11)
B(5,-30,5,STAINED_GLASS:15)
B(0,-30,6,STAINED_GLASS:15)
B(1,-30,6,STAINED_GLASS:15)
B(2,-30,6,STAINED_GLASS:11)
B(3,-30,6,STAINED_GLASS:9)
B(2,-30,7,STAINED_GLASS:9)
B(0,-29,0,STAINED_GLASS:10)
B(1,-29,0,STAINED_GLASS:10)
B(2,-29,0,STAINED_GLASS:10)
B(3,-29,0,STAINED_GLASS:10)
B(4,-29,0,STAINED_GLASS:11)
B(5,-29,0,STAINED_GLASS:11)
B(6,-29,0,STAINED_GLASS:9)
B(0,-29,1,STAINED_GLASS:10)
B(1,-29,1,SEA_LANTERN)
B(2,-29,1,SEA_LANTERN)
B(3,-29,1,STAINED_GLASS:10)
B(4,-29,1,STAINED_GLASS:10)
B(5,-29,1,STAINED_GLASS:11)
B(6,-29,1,STAINED_GLASS:9)
B(0,-29,2,STAINED_GLASS:10)
B(1,-29,2,SEA_LANTERN)
B(2,-29,2,SEA_LANTERN)
B(3,-29,2,STAINED_GLASS:10)
B(4,-29,2,STAINED_GLASS:10)
B(5,-29,2,STAINED_GLASS:11)
B(6,-29,2,STAINED_GLASS:9)
B(0,-29,3,STAINED_GLASS:10)
B(1,-29,3,STAINED_GLASS:10)
B(2,-29,3,STAINED_GLASS:10)
B(3,-29,3,STAINED_GLASS:10)
B(4,-29,3,STAINED_GLASS:11)
B(5,-29,3,STAINED_GLASS:9)
B(0,-29,4,STAINED_GLASS:11)
B(1,-29,4,STAINED_GLASS:10)
B(2,-29,4,STAINED_GLASS:10)
B(3,-29,4,STAINED_GLASS:11)
B(4,-29,4,STAINED_GLASS:11)
B(5,-29,4,STAINED_GLASS:9)
B(0,-29,5,STAINED_GLASS:11)
B(1,-29,5,STAINED_GLASS:11)
B(2,-29,5,STAINED_GLASS:11)
B(3,-29,5,STAINED_GLASS:9)
B(4,-29,5,STAINED_GLASS:9)
B(0,-29,6,STAINED_GLASS:15)
B(1,-29,6,STAINED_GLASS:15)
B(2,-29,6,STAINED_GLASS:9)
B(0,-28,0,STAINED_GLASS:10)
B(1,-28,0,SEA_LANTERN)
B(2,-28,0,STAINED_GLASS:10)
B(3,-28,0,STAINED_GLASS:10)
B(4,-28,0,STAINED_GLASS:11)
B(5,-28,0,STAINED_GLASS:9)
B(0,-28,1,SEA_LANTERN)
B(1,-28,1,SEA_LANTERN)
B(2,-28,1,SEA_LANTERN)
B(3,-28,1,STAINED_GLASS:10)
B(4,-28,1,STAINED_GLASS:10)
B(5,-28,1,STAINED_GLASS:11)
B(6,-28,1,STAINED_GLASS:9)
B(0,-28,2,STAINED_GLASS:10)
B(1,-28,2,SEA_LANTERN)
B(2,-28,2,STAINED_GLASS:10)
B(3,-28,2,STAINED_GLASS:10)
B(4,-28,2,STAINED_GLASS:11)
B(5,-28,2,STAINED_GLASS:9)
B(0,-28,3,STAINED_GLASS:10)
B(1,-28,3,STAINED_GLASS:10)
B(2,-28,3,STAINED_GLASS:10)
B(3,-28,3,STAINED_GLASS:11)
B(4,-28,3,STAINED_GLASS:11)
B(5,-28,3,STAINED_GLASS:9)
B(0,-28,4,STAINED_GLASS:11)
B(1,-28,4,STAINED_GLASS:10)
B(2,-28,4,STAINED_GLASS:11)
B(3,-28,4,STAINED_GLASS:11)
B(4,-28,4,STAINED_GLASS:9)
B(0,-28,5,STAINED_GLASS:15)
B(1,-28,5,STAINED_GLASS:11)
B(2,-28,5,STAINED_GLASS:9)
B(3,-28,5,STAINED_GLASS:9)
B(1,-28,6,STAINED_GLASS:9)
B(0,-27,0,SEA_LANTERN)
B(1,-27,0,SEA_LANTERN)
B(2,-27,0,STAINED_GLASS:10)
B(3,-27,0,STAINED_GLASS:10)
B(4,-27,0,STAINED_GLASS:11)
B(5,-27,0,STAINED_GLASS:15)
B(0,-27,1,SEA_LANTERN)
B(1,-27,1,SEA_LANTERN)
B(2,-27,1,STAINED_GLASS:10)
B(3,-27,1,STAINED_GLASS:10)
B(4,-27,1,STAINED_GLASS:11)
B(5,-27,1,STAINED_GLASS:15)
B(0,-27,2,STAINED_GLASS:10)
B(1,-27,2,STAINED_GLASS:10)
B(2,-27,2,STAINED_GLASS:10)
B(3,-27,2,STAINED_GLASS:11)
B(4,-27,2,STAINED_GLASS:9)
B(0,-27,3,STAINED_GLASS:10)
B(1,-27,3,STAINED_GLASS:10)
B(2,-27,3,STAINED_GLASS:11)
B(3,-27,3,STAINED_GLASS:11)
B(4,-27,3,STAINED_GLASS:9)
B(0,-27,4,STAINED_GLASS:11)
B(1,-27,4,STAINED_GLASS:11)
B(2,-27,4,STAINED_GLASS:15)
B(3,-27,4,STAINED_GLASS:9)
B(0,-27,5,STAINED_GLASS:15)
B(1,-27,5,STAINED_GLASS:15)
B(0,-26,0,SEA_LANTERN)
B(1,-26,0,SEA_LANTERN)
B(2,-26,0,STAINED_GLASS:10)
B(3,-26,0,STAINED_GLASS:10)
B(4,-26,0,STAINED_GLASS:11)
B(5,-26,0,STAINED_GLASS:15)
B(0,-26,1,SEA_LANTERN)
B(1,-26,1,STAINED_GLASS:10)
B(2,-26,1,STAINED_GLASS:10)
B(3,-26,1,STAINED_GLASS:11)
B(4,-26,1,STAINED_GLASS:15)
B(0,-26,2,STAINED_GLASS:10)
B(1,-26,2,STAINED_GLASS:10)
B(2,-26,2,STAINED_GLASS:11)
B(3,-26,2,STAINED_GLASS:11)
B(4,-26,2,STAINED_GLASS:9)
B(0,-26,3,STAINED_GLASS:10)
B(1,-26,3,STAINED_GLASS:11)
B(2,-26,3,STAINED_GLASS:11)
B(3,-26,3,STAINED_GLASS:9)
B(0,-26,4,STAINED_GLASS:11)
B(1,-26,4,STAINED_GLASS:15)
B(2,-26,4,STAINED_GLASS:15)
B(0,-26,5,STAINED_GLASS:15)
B(0,-25,0,SEA_LANTERN)
B(1,-25,0,STAINED_GLASS:10)
B(2,-25,0,STAINED_GLASS:10)
B(3,-25,0,STAINED_GLASS:11)
B(4,-25,0,STAINED_GLASS:15)
B(0,-25,1,STAINED_GLASS:10)
B(1,-25,1,STAINED_GLASS:10)
B(2,-25,1,STAINED_GLASS:11)
B(3,-25,1,STAINED_GLASS:15)
B(0,-25,2,STAINED_GLASS:10)
B(1,-25,2,STAINED_GLASS:11)
B(2,-25,2,STAINED_GLASS:11)
B(3,-25,2,STAINED_GLASS:9)
B(0,-25,3,STAINED_GLASS:11)
B(1,-25,3,STAINED_GLASS:15)
B(2,-25,3,STAINED_GLASS:9)
B(0,-25,4,STAINED_GLASS:15)
B(0,-24,0,STAINED_GLASS:10)
B(1,-24,0,STAINED_GLASS:10)
B(2,-24,0,STAINED_GLASS:11)
B(3,-24,0,STAINED_GLASS:15)
B(0,-24,1,STAINED_GLASS:10)
B(1,-24,1,STAINED_GLASS:11)
B(2,-24,1,STAINED_GLASS:11)
B(3,-24,1,STAINED_GLASS:9)
B(0,-24,2,STAINED_GLASS:11)
B(1,-24,2,STAINED_GLASS:11)
B(2,-24,2,STAINED_GLASS:9)
B(0,-24,3,STAINED_GLASS:15)
B(1,-24,3,STAINED_GLASS:9)
B(0,-23,0,STAINED_GLASS:10)
B(1,-23,0,STAINED_GLASS:11)
B(2,-23,0,STAINED_GLASS:15)
B(0,-23,1,STAINED_GLASS:11)
B(1,-23,1,STAINED_GLASS:11)
B(2,-23,1,STAINED_GLASS:9)
B(0,-23,2,STAINED_GLASS:9)
B(1,-23,2,STAINED_GLASS:9)
B(0,-22,0,STAINED_GLASS:11)
B(1,-22,0,STAINED_GLASS:11)
B(2,-22,0,STAINED_GLASS:9)
B(0,-22,1,STAINED_GLASS:11)
B(1,-22,1,STAINED_GLASS:9)
B(0,-22,2,STAINED_GLASS:15)
B(0,-21,0,STAINED_GLASS:9)
B(1,-21,0,STAINED_GLASS:15)
B(0,-21,1,STAINED_GLASS:15)
B(0,-20,0,STAINED_GLASS:15)

