
#######################################################################
# +-----------------------------------------------------------------+ #
# |                            BO3 object                           | #
# +-----------------------------------------------------------------+ #
#######################################################################

Author: Bo3 BulkEdit

Description: Converted Schematic - Modified by Bo3BulkEdit

Version: 3

SettingsMode: WriteWithoutComments


#######################################################################
# +-----------------------------------------------------------------+ #
# |                          Main settings                          | #
# +-----------------------------------------------------------------+ #
#######################################################################

Tree: false

Frequency: 1

Rarity: 100.0

RotateRandomly: false

SpawnHeight: randomY

SpawnHeightOffset: 0

SpawnHeightVariance: 0

##############################
# Height Limits for the BO3. #
##############################

MinHeight: 0

MaxHeight: 255

######################
# Extrusion settings #
######################

ExtrudeMode: None

ExtrudeThroughBlocks: minecraft:air

MaxBranchDepth: 20


#######################################################################
# +-----------------------------------------------------------------+ #
# |                      Source block settings                      | #
# +-----------------------------------------------------------------+ #
#######################################################################

SourceBlocks: otg:air

MaxPercentageOutsideSourceBlock: 100

OutsideSourceBlock: placeAnyway

DoReplaceBlocks: true

IsOTGPlus: false


#######################################################################
# +-----------------------------------------------------------------+ #
# |                              Blocks                             | #
# +-----------------------------------------------------------------+ #
#######################################################################

B(-8,52,-8,minecraft:spruce_log[axis=z])
B(-8,53,-8,minecraft:cobblestone)
B(-8,54,-8,minecraft:spruce_planks)
B(-8,55,-8,minecraft:spruce_log[axis=z])
B(-8,56,-8,minecraft:spruce_fence[east=false,north=false,south=true,waterlogged=false,west=false])
B(-8,58,-8,minecraft:spruce_log[axis=z])
B(-8,59,-8,minecraft:cobblestone)
B(-8,60,-8,minecraft:spruce_planks)
B(-8,61,-8,minecraft:spruce_log[axis=z])
B(-8,62,-8,minecraft:spruce_planks)
B(-8,63,-8,minecraft:spruce_slab)
B(-8,0,-7,minecraft:spruce_log)
B(-8,1,-7,minecraft:spruce_log)
B(-8,2,-7,minecraft:spruce_log)
B(-8,3,-7,minecraft:spruce_log)
B(-8,4,-7,minecraft:spruce_log)
B(-8,5,-7,minecraft:spruce_log)
B(-8,6,-7,minecraft:spruce_log)
B(-8,7,-7,minecraft:spruce_log)
B(-8,8,-7,minecraft:spruce_log)
B(-8,9,-7,minecraft:spruce_log)
B(-8,10,-7,minecraft:spruce_log)
B(-8,11,-7,minecraft:spruce_log)
B(-8,12,-7,minecraft:spruce_log)
B(-8,13,-7,minecraft:spruce_log)
B(-8,14,-7,minecraft:spruce_log)
B(-8,15,-7,minecraft:spruce_log)
B(-8,16,-7,minecraft:spruce_log)
B(-8,17,-7,minecraft:spruce_log)
B(-8,18,-7,minecraft:spruce_log)
B(-8,19,-7,minecraft:spruce_log)
B(-8,20,-7,minecraft:spruce_log)
B(-8,21,-7,minecraft:spruce_log)
B(-8,22,-7,minecraft:spruce_log)
B(-8,23,-7,minecraft:spruce_log)
B(-8,24,-7,minecraft:spruce_log)
B(-8,25,-7,minecraft:spruce_log)
B(-8,26,-7,minecraft:spruce_log)
B(-8,27,-7,minecraft:spruce_log)
B(-8,28,-7,minecraft:spruce_log)
B(-8,29,-7,minecraft:spruce_log)
B(-8,30,-7,minecraft:spruce_log)
B(-8,31,-7,minecraft:spruce_log)
B(-8,32,-7,minecraft:spruce_log)
B(-8,33,-7,minecraft:spruce_log)
B(-8,34,-7,minecraft:spruce_log)
B(-8,35,-7,minecraft:spruce_log)
B(-8,36,-7,minecraft:spruce_log)
B(-8,37,-7,minecraft:spruce_log)
B(-8,38,-7,minecraft:spruce_log)
B(-8,39,-7,minecraft:spruce_log)
B(-8,40,-7,minecraft:spruce_log)
B(-8,41,-7,minecraft:spruce_log)
B(-8,42,-7,minecraft:spruce_log)
B(-8,43,-7,minecraft:spruce_log)
B(-8,44,-7,minecraft:spruce_log)
B(-8,45,-7,minecraft:spruce_log)
B(-8,46,-7,minecraft:spruce_log)
B(-8,47,-7,minecraft:spruce_log)
B(-8,48,-7,minecraft:spruce_log)
B(-8,49,-7,minecraft:spruce_log)
B(-8,50,-7,minecraft:spruce_log)
B(-8,51,-7,minecraft:spruce_log)
B(-8,52,-7,minecraft:spruce_log)
B(-8,53,-7,minecraft:spruce_log)
B(-8,54,-7,minecraft:spruce_log)
B(-8,55,-7,minecraft:spruce_log[axis=x])
B(-8,56,-7,minecraft:spruce_log)
B(-8,57,-7,minecraft:spruce_log)
B(-8,58,-7,minecraft:spruce_log)
B(-8,59,-7,minecraft:spruce_log)
B(-8,60,-7,minecraft:spruce_log)
B(-8,61,-7,minecraft:spruce_log)
B(-8,62,-7,minecraft:oak_slab[type=double,waterlogged=false])
B(-8,63,-7,minecraft:oak_slab)
B(-8,52,-6,minecraft:spruce_log[axis=z])
B(-8,53,-6,minecraft:spruce_fence[east=false,north=true,south=true,waterlogged=false,west=false])
B(-8,55,-6,minecraft:spruce_stairs[facing=north,half=top,shape=straight,waterlogged=false])
B(-8,56,-6,minecraft:spruce_slab)
B(-8,58,-6,minecraft:spruce_stairs[facing=north,half=top,shape=straight,waterlogged=false])
B(-8,59,-6,minecraft:spruce_slab)
B(-8,0,-5,minecraft:spruce_log)
B(-8,1,-5,minecraft:spruce_log)
B(-8,2,-5,minecraft:spruce_log)
B(-8,3,-5,minecraft:spruce_log)
B(-8,4,-5,minecraft:spruce_log)
B(-8,5,-5,minecraft:spruce_log)
B(-8,6,-5,minecraft:spruce_log)
B(-8,7,-5,minecraft:spruce_log)
B(-8,8,-5,minecraft:spruce_log)
B(-8,9,-5,minecraft:spruce_log)
B(-8,10,-5,minecraft:spruce_log)
B(-8,11,-5,minecraft:spruce_log)
B(-8,12,-5,minecraft:spruce_log)
B(-8,13,-5,minecraft:spruce_log)
B(-8,14,-5,minecraft:spruce_log)
B(-8,15,-5,minecraft:spruce_log)
B(-8,16,-5,minecraft:spruce_log)
B(-8,17,-5,minecraft:spruce_log)
B(-8,18,-5,minecraft:spruce_log)
B(-8,19,-5,minecraft:spruce_log)
B(-8,20,-5,minecraft:spruce_log)
B(-8,21,-5,minecraft:spruce_log)
B(-8,22,-5,minecraft:spruce_log)
B(-8,23,-5,minecraft:spruce_log)
B(-8,24,-5,minecraft:spruce_log)
B(-8,25,-5,minecraft:spruce_log)
B(-8,26,-5,minecraft:spruce_log)
B(-8,27,-5,minecraft:spruce_log)
B(-8,28,-5,minecraft:spruce_log)
B(-8,29,-5,minecraft:spruce_log)
B(-8,30,-5,minecraft:spruce_log)
B(-8,31,-5,minecraft:spruce_log)
B(-8,32,-5,minecraft:spruce_log)
B(-8,33,-5,minecraft:spruce_log)
B(-8,34,-5,minecraft:spruce_log)
B(-8,35,-5,minecraft:spruce_log)
B(-8,36,-5,minecraft:spruce_log)
B(-8,37,-5,minecraft:spruce_log)
B(-8,38,-5,minecraft:spruce_log)
B(-8,39,-5,minecraft:spruce_log)
B(-8,40,-5,minecraft:spruce_log)
B(-8,41,-5,minecraft:spruce_log)
B(-8,42,-5,minecraft:spruce_log)
B(-8,43,-5,minecraft:spruce_log)
B(-8,44,-5,minecraft:spruce_log)
B(-8,45,-5,minecraft:spruce_log)
B(-8,46,-5,minecraft:spruce_log)
B(-8,47,-5,minecraft:spruce_log)
B(-8,48,-5,minecraft:spruce_log)
B(-8,49,-5,minecraft:spruce_log)
B(-8,50,-5,minecraft:spruce_log)
B(-8,51,-5,minecraft:spruce_log)
B(-8,52,-5,minecraft:spruce_log[axis=z])
B(-8,53,-5,minecraft:spruce_fence[east=false,north=true,south=true,waterlogged=false,west=false])
B(-8,1,-4,minecraft:spruce_log[axis=z])
B(-8,5,-4,minecraft:spruce_log[axis=z])
B(-8,9,-4,minecraft:spruce_log[axis=z])
B(-8,13,-4,minecraft:spruce_log[axis=z])
B(-8,17,-4,minecraft:spruce_log[axis=z])
B(-8,21,-4,minecraft:spruce_log[axis=z])
B(-8,25,-4,minecraft:spruce_log[axis=z])
B(-8,29,-4,minecraft:spruce_log[axis=z])
B(-8,33,-4,minecraft:spruce_log[axis=z])
B(-8,37,-4,minecraft:spruce_log[axis=z])
B(-8,41,-4,minecraft:spruce_log[axis=z])
B(-8,45,-4,minecraft:spruce_log[axis=z])
B(-8,52,-4,minecraft:spruce_log[axis=z])
B(-8,53,-4,minecraft:spruce_fence[east=false,north=true,south=true,waterlogged=false,west=false])
B(-8,54,-4,minecraft:spruce_fence[east=true,north=false,south=false,waterlogged=false,west=false])
B(-8,1,-3,minecraft:spruce_log[axis=z])
B(-8,5,-3,minecraft:spruce_log[axis=z])
B(-8,9,-3,minecraft:spruce_log[axis=z])
B(-8,13,-3,minecraft:spruce_log[axis=z])
B(-8,17,-3,minecraft:spruce_log[axis=z])
B(-8,21,-3,minecraft:spruce_log[axis=z])
B(-8,25,-3,minecraft:spruce_log[axis=z])
B(-8,29,-3,minecraft:spruce_log[axis=z])
B(-8,33,-3,minecraft:spruce_log[axis=z])
B(-8,37,-3,minecraft:spruce_log[axis=z])
B(-8,41,-3,minecraft:spruce_log[axis=z])
B(-8,45,-3,minecraft:spruce_log[axis=z])
B(-8,52,-3,minecraft:spruce_log[axis=z])
B(-8,53,-3,minecraft:spruce_fence[east=false,north=true,south=true,waterlogged=false,west=false])
B(-8,1,-2,minecraft:spruce_log[axis=z])
B(-8,5,-2,minecraft:spruce_log[axis=z])
B(-8,9,-2,minecraft:spruce_log[axis=z])
B(-8,13,-2,minecraft:spruce_log[axis=z])
B(-8,17,-2,minecraft:spruce_log[axis=z])
B(-8,21,-2,minecraft:spruce_log[axis=z])
B(-8,25,-2,minecraft:spruce_log[axis=z])
B(-8,29,-2,minecraft:spruce_log[axis=z])
B(-8,33,-2,minecraft:spruce_log[axis=z])
B(-8,37,-2,minecraft:spruce_log[axis=z])
B(-8,41,-2,minecraft:spruce_log[axis=z])
B(-8,45,-2,minecraft:spruce_log[axis=z])
B(-8,52,-2,minecraft:spruce_log[axis=z])
B(-8,53,-2,minecraft:spruce_fence[east=false,north=true,south=true,waterlogged=false,west=false])
B(-8,56,-2,minecraft:oak_stairs[facing=east,half=top,shape=straight,waterlogged=false])
B(-8,57,-2,minecraft:oak_stairs[facing=west,half=bottom,shape=straight,waterlogged=false])
B(-8,0,-1,minecraft:spruce_log)
B(-8,1,-1,minecraft:spruce_log)
B(-8,2,-1,minecraft:spruce_log)
B(-8,3,-1,minecraft:spruce_log)
B(-8,4,-1,minecraft:spruce_log)
B(-8,5,-1,minecraft:spruce_log)
B(-8,6,-1,minecraft:spruce_log)
B(-8,7,-1,minecraft:spruce_log)
B(-8,8,-1,minecraft:spruce_log)
B(-8,9,-1,minecraft:spruce_log)
B(-8,10,-1,minecraft:spruce_log)
B(-8,11,-1,minecraft:spruce_log)
B(-8,12,-1,minecraft:spruce_log)
B(-8,13,-1,minecraft:spruce_log)
B(-8,14,-1,minecraft:spruce_log)
B(-8,15,-1,minecraft:spruce_log)
B(-8,16,-1,minecraft:spruce_log)
B(-8,17,-1,minecraft:spruce_log)
B(-8,18,-1,minecraft:spruce_log)
B(-8,19,-1,minecraft:spruce_log)
B(-8,20,-1,minecraft:spruce_log)
B(-8,21,-1,minecraft:spruce_log)
B(-8,22,-1,minecraft:spruce_log)
B(-8,23,-1,minecraft:spruce_log)
B(-8,24,-1,minecraft:spruce_log)
B(-8,25,-1,minecraft:spruce_log)
B(-8,26,-1,minecraft:spruce_log)
B(-8,27,-1,minecraft:spruce_log)
B(-8,28,-1,minecraft:spruce_log)
B(-8,29,-1,minecraft:spruce_log)
B(-8,30,-1,minecraft:spruce_log)
B(-8,31,-1,minecraft:spruce_log)
B(-8,32,-1,minecraft:spruce_log)
B(-8,33,-1,minecraft:spruce_log)
B(-8,34,-1,minecraft:spruce_log)
B(-8,35,-1,minecraft:spruce_log)
B(-8,36,-1,minecraft:spruce_log)
B(-8,37,-1,minecraft:spruce_log)
B(-8,38,-1,minecraft:spruce_log)
B(-8,39,-1,minecraft:spruce_log)
B(-8,40,-1,minecraft:spruce_log)
B(-8,41,-1,minecraft:spruce_log)
B(-8,42,-1,minecraft:spruce_log)
B(-8,43,-1,minecraft:spruce_log)
B(-8,44,-1,minecraft:spruce_log)
B(-8,45,-1,minecraft:spruce_log)
B(-8,46,-1,minecraft:spruce_log)
B(-8,47,-1,minecraft:spruce_log)
B(-8,48,-1,minecraft:spruce_log)
B(-8,49,-1,minecraft:spruce_log)
B(-8,50,-1,minecraft:spruce_log)
B(-8,51,-1,minecraft:spruce_log)
B(-8,52,-1,minecraft:spruce_log)
B(-8,53,-1,minecraft:spruce_log)
B(-8,54,-1,minecraft:spruce_log)
B(-8,55,-1,minecraft:spruce_log)
B(-8,56,-1,minecraft:spruce_log)
B(-8,57,-1,minecraft:spruce_stairs[facing=west,half=bottom,shape=straight,waterlogged=false])
B(-7,52,-8,minecraft:oak_slab[type=top,waterlogged=false])
B(-7,53,-8,minecraft:crafting_table)
B(-7,55,-8,minecraft:oak_slab[type=top,waterlogged=false])
B(-7,58,-8,minecraft:oak_slab[type=top,waterlogged=false])
B(-7,61,-8,minecraft:oak_slab[type=double,waterlogged=false])
B(-7,62,-8,minecraft:cobblestone)
B(-7,63,-8,minecraft:spruce_slab[type=double,waterlogged=false])
B(-7,2,-7,minecraft:spruce_log[axis=x])
B(-7,6,-7,minecraft:spruce_log[axis=x])
B(-7,10,-7,minecraft:spruce_log[axis=x])
B(-7,14,-7,minecraft:spruce_log[axis=x])
B(-7,18,-7,minecraft:spruce_log[axis=x])
B(-7,22,-7,minecraft:spruce_log[axis=x])
B(-7,26,-7,minecraft:spruce_log[axis=x])
B(-7,30,-7,minecraft:spruce_log[axis=x])
B(-7,34,-7,minecraft:spruce_log[axis=x])
B(-7,38,-7,minecraft:spruce_log[axis=x])
B(-7,42,-7,minecraft:spruce_log[axis=x])
B(-7,46,-7,minecraft:spruce_log[axis=x])
B(-7,52,-7,minecraft:spruce_log[axis=x])
B(-7,53,-7,minecraft:cobblestone)
B(-7,54,-7,minecraft:spruce_planks)
B(-7,55,-7,minecraft:spruce_log[axis=x])
B(-7,56,-7,minecraft:cobblestone)
B(-7,57,-7,minecraft:spruce_planks)
B(-7,58,-7,minecraft:spruce_log[axis=x])
B(-7,59,-7,minecraft:cobblestone)
B(-7,60,-7,minecraft:spruce_planks)
B(-7,61,-7,minecraft:spruce_log[axis=x])
B(-7,62,-7,minecraft:oak_slab[type=double,waterlogged=false])
B(-7,63,-7,minecraft:oak_slab[type=double,waterlogged=false])
B(-7,55,-6,minecraft:spruce_slab[type=top,waterlogged=false])
B(-7,58,-6,minecraft:spruce_slab[type=top,waterlogged=false])
B(-7,59,-6,minecraft:spruce_fence[east=true,north=true,south=false,waterlogged=false,west=false])
B(-7,54,-4,minecraft:spruce_fence[east=false,north=false,south=false,waterlogged=false,west=true])
B(-7,55,-4,minecraft:torch)
B(-7,56,-2,minecraft:oak_stairs[facing=west,half=bottom,shape=straight,waterlogged=false])
B(-7,50,-1,minecraft:spruce_log[axis=x])
B(-7,51,-1,minecraft:spruce_fence[east=true,north=false,south=false,waterlogged=false,west=true])
B(-7,56,-1,minecraft:oak_stairs[facing=west,half=bottom,shape=straight,waterlogged=false])
B(-6,52,-8,minecraft:oak_slab[type=top,waterlogged=false])
B(-6,53,-8,minecraft:gray_carpet)
B(-6,55,-8,minecraft:oak_slab[type=top,waterlogged=false])
B(-6,58,-8,minecraft:oak_slab[type=top,waterlogged=false])
B(-6,61,-8,minecraft:oak_slab[type=double,waterlogged=false])
B(-6,62,-8,minecraft:cobblestone)
B(-6,63,-8,minecraft:spruce_slab)
B(-6,2,-7,minecraft:spruce_log[axis=x])
B(-6,6,-7,minecraft:spruce_log[axis=x])
B(-6,10,-7,minecraft:spruce_log[axis=x])
B(-6,14,-7,minecraft:spruce_log[axis=x])
B(-6,18,-7,minecraft:spruce_log[axis=x])
B(-6,22,-7,minecraft:spruce_log[axis=x])
B(-6,26,-7,minecraft:spruce_log[axis=x])
B(-6,30,-7,minecraft:spruce_log[axis=x])
B(-6,34,-7,minecraft:spruce_log[axis=x])
B(-6,38,-7,minecraft:spruce_log[axis=x])
B(-6,42,-7,minecraft:spruce_log[axis=x])
B(-6,46,-7,minecraft:spruce_log[axis=x])
B(-6,52,-7,minecraft:spruce_log[axis=x])
B(-6,53,-7,minecraft:cobblestone)
B(-6,54,-7,minecraft:dark_oak_fence[east=true,north=false,south=false,waterlogged=false,west=true])
B(-6,55,-7,minecraft:spruce_log[axis=x])
B(-6,56,-7,minecraft:cobblestone)
B(-6,57,-7,minecraft:dark_oak_fence[east=true,north=false,south=false,waterlogged=false,west=true])
B(-6,58,-7,minecraft:spruce_log[axis=x])
B(-6,59,-7,minecraft:cobblestone)
B(-6,60,-7,minecraft:dark_oak_fence[east=true,north=false,south=false,waterlogged=false,west=true])
B(-6,61,-7,minecraft:spruce_log[axis=x])
B(-6,62,-7,minecraft:oak_slab[type=double,waterlogged=false])
B(-6,63,-7,minecraft:oak_slab)
B(-6,55,-6,minecraft:spruce_slab[type=top,waterlogged=false])
B(-6,58,-6,minecraft:spruce_slab[type=top,waterlogged=false])
B(-6,59,-6,minecraft:spruce_fence[east=true,north=true,south=true,waterlogged=false,west=true])
B(-6,59,-5,minecraft:spruce_fence[east=false,north=true,south=false,waterlogged=false,west=false])
B(-6,60,-5,minecraft:torch)
B(-6,50,-1,minecraft:spruce_log[axis=x])
B(-6,51,-1,minecraft:spruce_fence[east=true,north=false,south=false,waterlogged=false,west=true])
B(-5,52,-8,minecraft:oak_slab[type=top,waterlogged=false])
B(-5,53,-8,minecraft:acacia_fence[east=true,north=false,south=true,waterlogged=false,west=false])
B(-5,54,-8,minecraft:torch)
B(-5,55,-8,minecraft:oak_slab[type=top,waterlogged=false])
B(-5,58,-8,minecraft:oak_slab[type=top,waterlogged=false])
B(-5,59,-8,minecraft:crafting_table)
B(-5,61,-8,minecraft:oak_slab[type=double,waterlogged=false])
B(-5,62,-8,minecraft:spruce_slab[type=double,waterlogged=false])
B(-5,2,-7,minecraft:spruce_log[axis=x])
B(-5,6,-7,minecraft:spruce_log[axis=x])
B(-5,10,-7,minecraft:spruce_log[axis=x])
B(-5,14,-7,minecraft:spruce_log[axis=x])
B(-5,18,-7,minecraft:spruce_log[axis=x])
B(-5,22,-7,minecraft:spruce_log[axis=x])
B(-5,26,-7,minecraft:spruce_log[axis=x])
B(-5,30,-7,minecraft:spruce_log[axis=x])
B(-5,34,-7,minecraft:spruce_log[axis=x])
B(-5,38,-7,minecraft:spruce_log[axis=x])
B(-5,42,-7,minecraft:spruce_log[axis=x])
B(-5,46,-7,minecraft:spruce_log[axis=x])
B(-5,52,-7,minecraft:spruce_log[axis=x])
B(-5,53,-7,minecraft:cobblestone)
B(-5,54,-7,minecraft:spruce_planks)
B(-5,55,-7,minecraft:spruce_log[axis=x])
B(-5,56,-7,minecraft:cobblestone)
B(-5,57,-7,minecraft:spruce_planks)
B(-5,58,-7,minecraft:spruce_log[axis=x])
B(-5,59,-7,minecraft:cobblestone)
B(-5,60,-7,minecraft:spruce_planks)
B(-5,61,-7,minecraft:spruce_log[axis=x])
B(-5,62,-7,minecraft:oak_slab[type=double,waterlogged=false])
B(-5,55,-6,minecraft:spruce_slab[type=top,waterlogged=false])
B(-5,58,-6,minecraft:spruce_slab[type=top,waterlogged=false])
B(-5,59,-6,minecraft:spruce_fence[east=false,north=true,south=false,waterlogged=false,west=true])
B(-5,50,-1,minecraft:spruce_log[axis=x])
B(-5,51,-1,minecraft:spruce_fence[east=true,north=false,south=false,waterlogged=false,west=true])
B(-4,52,-8,minecraft:spruce_log[axis=z])
B(-4,53,-8,minecraft:cobblestone)
B(-4,54,-8,minecraft:cobblestone)
B(-4,55,-8,minecraft:spruce_log[axis=z])
B(-4,56,-8,minecraft:cobblestone)
B(-4,57,-8,minecraft:spruce_planks)
B(-4,58,-8,minecraft:spruce_log[axis=z])
B(-4,59,-8,minecraft:cobblestone)
B(-4,60,-8,minecraft:spruce_planks)
B(-4,61,-8,minecraft:spruce_log[axis=z])
B(-4,62,-8,minecraft:spruce_slab)
B(-4,0,-7,minecraft:spruce_log)
B(-4,1,-7,minecraft:spruce_log)
B(-4,2,-7,minecraft:spruce_log)
B(-4,3,-7,minecraft:spruce_log)
B(-4,4,-7,minecraft:spruce_log)
B(-4,5,-7,minecraft:spruce_log)
B(-4,6,-7,minecraft:spruce_log)
B(-4,7,-7,minecraft:spruce_log)
B(-4,8,-7,minecraft:spruce_log)
B(-4,9,-7,minecraft:spruce_log)
B(-4,10,-7,minecraft:spruce_log)
B(-4,11,-7,minecraft:spruce_log)
B(-4,12,-7,minecraft:spruce_log)
B(-4,13,-7,minecraft:spruce_log)
B(-4,14,-7,minecraft:spruce_log)
B(-4,15,-7,minecraft:spruce_log)
B(-4,16,-7,minecraft:spruce_log)
B(-4,17,-7,minecraft:spruce_log)
B(-4,18,-7,minecraft:spruce_log)
B(-4,19,-7,minecraft:spruce_log)
B(-4,20,-7,minecraft:spruce_log)
B(-4,21,-7,minecraft:spruce_log)
B(-4,22,-7,minecraft:spruce_log)
B(-4,23,-7,minecraft:spruce_log)
B(-4,24,-7,minecraft:spruce_log)
B(-4,25,-7,minecraft:spruce_log)
B(-4,26,-7,minecraft:spruce_log)
B(-4,27,-7,minecraft:spruce_log)
B(-4,28,-7,minecraft:spruce_log)
B(-4,29,-7,minecraft:spruce_log)
B(-4,30,-7,minecraft:spruce_log)
B(-4,31,-7,minecraft:spruce_log)
B(-4,32,-7,minecraft:spruce_log)
B(-4,33,-7,minecraft:spruce_log)
B(-4,34,-7,minecraft:spruce_log)
B(-4,35,-7,minecraft:spruce_log)
B(-4,36,-7,minecraft:spruce_log)
B(-4,37,-7,minecraft:spruce_log)
B(-4,38,-7,minecraft:spruce_log)
B(-4,39,-7,minecraft:spruce_log)
B(-4,40,-7,minecraft:spruce_log)
B(-4,41,-7,minecraft:spruce_log)
B(-4,42,-7,minecraft:spruce_log)
B(-4,43,-7,minecraft:spruce_log)
B(-4,44,-7,minecraft:spruce_log)
B(-4,45,-7,minecraft:spruce_log)
B(-4,46,-7,minecraft:spruce_log)
B(-4,47,-7,minecraft:spruce_log)
B(-4,48,-7,minecraft:spruce_log)
B(-4,49,-7,minecraft:spruce_log)
B(-4,50,-7,minecraft:spruce_log)
B(-4,51,-7,minecraft:spruce_log)
B(-4,52,-7,minecraft:spruce_log)
B(-4,53,-7,minecraft:spruce_log)
B(-4,54,-7,minecraft:spruce_log)
B(-4,55,-7,minecraft:spruce_log)
B(-4,56,-7,minecraft:spruce_log)
B(-4,57,-7,minecraft:spruce_log)
B(-4,58,-7,minecraft:spruce_log)
B(-4,59,-7,minecraft:spruce_log)
B(-4,60,-7,minecraft:spruce_log)
B(-4,61,-7,minecraft:spruce_log)
B(-4,62,-7,minecraft:oak_slab)
B(-4,55,-6,minecraft:spruce_stairs[facing=north,half=top,shape=straight,waterlogged=false])
B(-4,56,-6,minecraft:spruce_slab)
B(-4,58,-6,minecraft:spruce_stairs[facing=north,half=top,shape=straight,waterlogged=false])
B(-4,59,-6,minecraft:spruce_slab)
B(-4,50,-1,minecraft:spruce_log[axis=x])
B(-4,51,-1,minecraft:spruce_fence[east=true,north=false,south=false,waterlogged=false,west=true])
B(-3,51,-8,minecraft:oak_slab[type=top,waterlogged=false])
B(-3,55,-8,minecraft:spruce_slab[type=top,waterlogged=false])
B(-3,58,-8,minecraft:spruce_slab[type=top,waterlogged=false])
B(-3,59,-8,minecraft:spruce_fence[east=false,north=false,south=false,waterlogged=false,west=true])
B(-3,61,-8,minecraft:oak_slab[type=top,waterlogged=false])
B(-3,51,-7,minecraft:spruce_log[axis=x])
B(-3,52,-7,minecraft:spruce_fence[east=true,north=false,south=false,waterlogged=false,west=true])
B(-3,55,-7,minecraft:spruce_stairs[facing=west,half=top,shape=straight,waterlogged=false])
B(-3,56,-7,minecraft:spruce_slab)
B(-3,58,-7,minecraft:spruce_stairs[facing=west,half=top,shape=straight,waterlogged=false])
B(-3,59,-7,minecraft:spruce_slab)
B(-3,61,-7,minecraft:oak_slab[type=top,waterlogged=false])
B(-3,50,-1,minecraft:spruce_log[axis=x])
B(-3,51,-1,minecraft:spruce_fence[east=true,north=false,south=false,waterlogged=false,west=true])
B(-3,52,-1,minecraft:spruce_fence[east=true,north=false,south=false,waterlogged=false,west=false])
B(-2,2,-8,minecraft:spruce_log[axis=z])
B(-2,6,-8,minecraft:spruce_log[axis=z])
B(-2,10,-8,minecraft:spruce_log[axis=z])
B(-2,14,-8,minecraft:spruce_log[axis=z])
B(-2,18,-8,minecraft:spruce_log[axis=z])
B(-2,22,-8,minecraft:spruce_log[axis=z])
B(-2,26,-8,minecraft:spruce_log[axis=z])
B(-2,30,-8,minecraft:spruce_log[axis=z])
B(-2,34,-8,minecraft:spruce_log[axis=z])
B(-2,38,-8,minecraft:spruce_log[axis=z])
B(-2,42,-8,minecraft:spruce_log[axis=z])
B(-2,46,-8,minecraft:spruce_log[axis=z])
B(-2,51,-8,minecraft:oak_slab[type=top,waterlogged=false])
B(-2,0,-7,minecraft:spruce_log)
B(-2,1,-7,minecraft:spruce_log)
B(-2,2,-7,minecraft:spruce_log)
B(-2,3,-7,minecraft:spruce_log)
B(-2,4,-7,minecraft:spruce_log)
B(-2,5,-7,minecraft:spruce_log)
B(-2,6,-7,minecraft:spruce_log)
B(-2,7,-7,minecraft:spruce_log)
B(-2,8,-7,minecraft:spruce_log)
B(-2,9,-7,minecraft:spruce_log)
B(-2,10,-7,minecraft:spruce_log)
B(-2,11,-7,minecraft:spruce_log)
B(-2,12,-7,minecraft:spruce_log)
B(-2,13,-7,minecraft:spruce_log)
B(-2,14,-7,minecraft:spruce_log)
B(-2,15,-7,minecraft:spruce_log)
B(-2,16,-7,minecraft:spruce_log)
B(-2,17,-7,minecraft:spruce_log)
B(-2,18,-7,minecraft:spruce_log)
B(-2,19,-7,minecraft:spruce_log)
B(-2,20,-7,minecraft:spruce_log)
B(-2,21,-7,minecraft:spruce_log)
B(-2,22,-7,minecraft:spruce_log)
B(-2,23,-7,minecraft:spruce_log)
B(-2,24,-7,minecraft:spruce_log)
B(-2,25,-7,minecraft:spruce_log)
B(-2,26,-7,minecraft:spruce_log)
B(-2,27,-7,minecraft:spruce_log)
B(-2,28,-7,minecraft:spruce_log)
B(-2,29,-7,minecraft:spruce_log)
B(-2,30,-7,minecraft:spruce_log)
B(-2,31,-7,minecraft:spruce_log)
B(-2,32,-7,minecraft:spruce_log)
B(-2,33,-7,minecraft:spruce_log)
B(-2,34,-7,minecraft:spruce_log)
B(-2,35,-7,minecraft:spruce_log)
B(-2,36,-7,minecraft:spruce_log)
B(-2,37,-7,minecraft:spruce_log)
B(-2,38,-7,minecraft:spruce_log)
B(-2,39,-7,minecraft:spruce_log)
B(-2,40,-7,minecraft:spruce_log)
B(-2,41,-7,minecraft:spruce_log)
B(-2,42,-7,minecraft:spruce_log)
B(-2,43,-7,minecraft:spruce_log)
B(-2,44,-7,minecraft:spruce_log)
B(-2,45,-7,minecraft:spruce_log)
B(-2,46,-7,minecraft:spruce_log)
B(-2,47,-7,minecraft:spruce_log)
B(-2,48,-7,minecraft:spruce_log)
B(-2,49,-7,minecraft:spruce_log)
B(-2,50,-7,minecraft:spruce_log)
B(-2,51,-7,minecraft:spruce_log)
B(-2,52,-7,minecraft:spruce_log)
B(-2,53,-7,minecraft:smooth_stone_slab)
B(-2,2,-6,minecraft:spruce_log[axis=z])
B(-2,6,-6,minecraft:spruce_log[axis=z])
B(-2,10,-6,minecraft:spruce_log[axis=z])
B(-2,14,-6,minecraft:spruce_log[axis=z])
B(-2,18,-6,minecraft:spruce_log[axis=z])
B(-2,22,-6,minecraft:spruce_log[axis=z])
B(-2,26,-6,minecraft:spruce_log[axis=z])
B(-2,30,-6,minecraft:spruce_log[axis=z])
B(-2,34,-6,minecraft:spruce_log[axis=z])
B(-2,38,-6,minecraft:spruce_log[axis=z])
B(-2,42,-6,minecraft:spruce_log[axis=z])
B(-2,46,-6,minecraft:spruce_log[axis=z])
B(-2,51,-6,minecraft:spruce_log[axis=z])
B(-2,52,-6,minecraft:spruce_fence[east=false,north=true,south=true,waterlogged=false,west=false])
B(-2,2,-5,minecraft:spruce_log[axis=z])
B(-2,6,-5,minecraft:spruce_log[axis=z])
B(-2,10,-5,minecraft:spruce_log[axis=z])
B(-2,14,-5,minecraft:spruce_log[axis=z])
B(-2,18,-5,minecraft:spruce_log[axis=z])
B(-2,22,-5,minecraft:spruce_log[axis=z])
B(-2,26,-5,minecraft:spruce_log[axis=z])
B(-2,30,-5,minecraft:spruce_log[axis=z])
B(-2,34,-5,minecraft:spruce_log[axis=z])
B(-2,38,-5,minecraft:spruce_log[axis=z])
B(-2,42,-5,minecraft:spruce_log[axis=z])
B(-2,46,-5,minecraft:spruce_log[axis=z])
B(-2,51,-5,minecraft:spruce_log[axis=z])
B(-2,52,-5,minecraft:spruce_fence[east=false,north=true,south=true,waterlogged=false,west=false])
B(-2,2,-4,minecraft:spruce_log[axis=z])
B(-2,6,-4,minecraft:spruce_log[axis=z])
B(-2,10,-4,minecraft:spruce_log[axis=z])
B(-2,14,-4,minecraft:spruce_log[axis=z])
B(-2,18,-4,minecraft:spruce_log[axis=z])
B(-2,22,-4,minecraft:spruce_log[axis=z])
B(-2,26,-4,minecraft:spruce_log[axis=z])
B(-2,30,-4,minecraft:spruce_log[axis=z])
B(-2,34,-4,minecraft:spruce_log[axis=z])
B(-2,38,-4,minecraft:spruce_log[axis=z])
B(-2,42,-4,minecraft:spruce_log[axis=z])
B(-2,46,-4,minecraft:spruce_log[axis=z])
B(-2,51,-4,minecraft:spruce_log[axis=z])
B(-2,52,-4,minecraft:spruce_fence[east=false,north=true,south=true,waterlogged=false,west=false])
B(-2,0,-3,minecraft:spruce_log)
B(-2,1,-3,minecraft:spruce_log)
B(-2,2,-3,minecraft:spruce_log)
B(-2,3,-3,minecraft:spruce_log)
B(-2,4,-3,minecraft:spruce_log)
B(-2,5,-3,minecraft:spruce_log)
B(-2,6,-3,minecraft:spruce_log)
B(-2,7,-3,minecraft:spruce_log)
B(-2,8,-3,minecraft:spruce_log)
B(-2,9,-3,minecraft:spruce_log)
B(-2,10,-3,minecraft:spruce_log)
B(-2,11,-3,minecraft:spruce_log)
B(-2,12,-3,minecraft:spruce_log)
B(-2,13,-3,minecraft:spruce_log)
B(-2,14,-3,minecraft:spruce_log)
B(-2,15,-3,minecraft:spruce_log)
B(-2,16,-3,minecraft:spruce_log)
B(-2,17,-3,minecraft:spruce_log)
B(-2,18,-3,minecraft:spruce_log)
B(-2,19,-3,minecraft:spruce_log)
B(-2,20,-3,minecraft:spruce_log)
B(-2,21,-3,minecraft:spruce_log)
B(-2,22,-3,minecraft:spruce_log)
B(-2,23,-3,minecraft:spruce_log)
B(-2,24,-3,minecraft:spruce_log)
B(-2,25,-3,minecraft:spruce_log)
B(-2,26,-3,minecraft:spruce_log)
B(-2,27,-3,minecraft:spruce_log)
B(-2,28,-3,minecraft:spruce_log)
B(-2,29,-3,minecraft:spruce_log)
B(-2,30,-3,minecraft:spruce_log)
B(-2,31,-3,minecraft:spruce_log)
B(-2,32,-3,minecraft:spruce_log)
B(-2,33,-3,minecraft:spruce_log)
B(-2,34,-3,minecraft:spruce_log)
B(-2,35,-3,minecraft:spruce_log)
B(-2,36,-3,minecraft:spruce_log)
B(-2,37,-3,minecraft:spruce_log)
B(-2,38,-3,minecraft:spruce_log)
B(-2,39,-3,minecraft:spruce_log)
B(-2,40,-3,minecraft:spruce_log)
B(-2,41,-3,minecraft:spruce_log)
B(-2,42,-3,minecraft:spruce_log)
B(-2,43,-3,minecraft:spruce_log)
B(-2,44,-3,minecraft:spruce_log)
B(-2,45,-3,minecraft:spruce_log)
B(-2,46,-3,minecraft:spruce_log)
B(-2,47,-3,minecraft:spruce_log)
B(-2,48,-3,minecraft:spruce_log)
B(-2,49,-3,minecraft:spruce_log)
B(-2,50,-3,minecraft:spruce_log)
B(-2,51,-3,minecraft:spruce_log)
B(-2,52,-3,minecraft:spruce_log)
B(-2,53,-3,minecraft:smooth_stone_slab)
B(-2,2,-2,minecraft:spruce_log[axis=z])
B(-2,6,-2,minecraft:spruce_log[axis=z])
B(-2,10,-2,minecraft:spruce_log[axis=z])
B(-2,14,-2,minecraft:spruce_log[axis=z])
B(-2,18,-2,minecraft:spruce_log[axis=z])
B(-2,22,-2,minecraft:spruce_log[axis=z])
B(-2,26,-2,minecraft:spruce_log[axis=z])
B(-2,30,-2,minecraft:spruce_log[axis=z])
B(-2,34,-2,minecraft:spruce_log[axis=z])
B(-2,38,-2,minecraft:spruce_log[axis=z])
B(-2,42,-2,minecraft:spruce_log[axis=z])
B(-2,46,-2,minecraft:spruce_log[axis=z])
B(-2,51,-2,minecraft:spruce_log[axis=z])
B(-2,52,-2,minecraft:spruce_fence[east=false,north=true,south=true,waterlogged=false,west=false])
B(-2,0,-1,minecraft:spruce_log)
B(-2,1,-1,minecraft:spruce_log)
B(-2,2,-1,minecraft:spruce_log)
B(-2,3,-1,minecraft:spruce_log)
B(-2,4,-1,minecraft:spruce_log)
B(-2,5,-1,minecraft:spruce_log)
B(-2,6,-1,minecraft:spruce_log)
B(-2,7,-1,minecraft:spruce_log)
B(-2,8,-1,minecraft:spruce_log)
B(-2,9,-1,minecraft:spruce_log)
B(-2,10,-1,minecraft:spruce_log)
B(-2,11,-1,minecraft:spruce_log)
B(-2,12,-1,minecraft:spruce_log)
B(-2,13,-1,minecraft:spruce_log)
B(-2,14,-1,minecraft:spruce_log)
B(-2,15,-1,minecraft:spruce_log)
B(-2,16,-1,minecraft:spruce_log)
B(-2,17,-1,minecraft:spruce_log)
B(-2,18,-1,minecraft:spruce_log)
B(-2,19,-1,minecraft:spruce_log)
B(-2,20,-1,minecraft:spruce_log)
B(-2,21,-1,minecraft:spruce_log)
B(-2,22,-1,minecraft:spruce_log)
B(-2,23,-1,minecraft:spruce_log)
B(-2,24,-1,minecraft:spruce_log)
B(-2,25,-1,minecraft:spruce_log)
B(-2,26,-1,minecraft:spruce_log)
B(-2,27,-1,minecraft:spruce_log)
B(-2,28,-1,minecraft:spruce_log)
B(-2,29,-1,minecraft:spruce_log)
B(-2,30,-1,minecraft:spruce_log)
B(-2,31,-1,minecraft:spruce_log)
B(-2,32,-1,minecraft:spruce_log)
B(-2,33,-1,minecraft:spruce_log)
B(-2,34,-1,minecraft:spruce_log)
B(-2,35,-1,minecraft:spruce_log)
B(-2,36,-1,minecraft:spruce_log)
B(-2,37,-1,minecraft:spruce_log)
B(-2,38,-1,minecraft:spruce_log)
B(-2,39,-1,minecraft:spruce_log)
B(-2,40,-1,minecraft:spruce_log)
B(-2,41,-1,minecraft:spruce_log)
B(-2,42,-1,minecraft:spruce_log)
B(-2,43,-1,minecraft:spruce_log)
B(-2,44,-1,minecraft:spruce_log)
B(-2,45,-1,minecraft:spruce_log)
B(-2,46,-1,minecraft:spruce_log)
B(-2,47,-1,minecraft:spruce_log)
B(-2,48,-1,minecraft:spruce_log)
B(-2,49,-1,minecraft:spruce_log)
B(-2,50,-1,minecraft:spruce_log)
B(-2,51,-1,minecraft:spruce_log[axis=z])
B(-2,52,-1,minecraft:spruce_fence[east=false,north=true,south=false,waterlogged=false,west=true])
B(-1,51,-8,minecraft:oak_slab[type=top,waterlogged=false])
B(-1,1,-7,minecraft:spruce_log[axis=x])
B(-1,5,-7,minecraft:spruce_log[axis=x])
B(-1,9,-7,minecraft:spruce_log[axis=x])
B(-1,13,-7,minecraft:spruce_log[axis=x])
B(-1,17,-7,minecraft:spruce_log[axis=x])
B(-1,21,-7,minecraft:spruce_log[axis=x])
B(-1,25,-7,minecraft:spruce_log[axis=x])
B(-1,29,-7,minecraft:spruce_log[axis=x])
B(-1,33,-7,minecraft:spruce_log[axis=x])
B(-1,37,-7,minecraft:spruce_log[axis=x])
B(-1,41,-7,minecraft:spruce_log[axis=x])
B(-1,45,-7,minecraft:spruce_log[axis=x])
B(-1,51,-7,minecraft:spruce_log[axis=x])
B(-1,51,-6,minecraft:oak_slab[type=top,waterlogged=false])
B(-1,51,-5,minecraft:oak_slab[type=top,waterlogged=false])
B(-1,56,-5,minecraft:spruce_fence)
B(-1,57,-5,minecraft:torch)
B(-1,51,-4,minecraft:oak_slab[type=top,waterlogged=false])
B(-1,51,-3,minecraft:spruce_log[axis=x])
B(-1,51,-2,minecraft:oak_slab[type=top,waterlogged=false])
B(-1,51,-1,minecraft:oak_slab[type=top,waterlogged=false])
RB(-7,54,-8,minecraft:air,../NBT/Flowers/flower_pot_01.nbt,5,minecraft:air,../NBT/Flowers/flower_pot_02.nbt,5,minecraft:air,../NBT/Flowers/flower_pot_03.nbt,5,minecraft:air,../NBT/Flowers/flower_pot_04.nbt,5,minecraft:air,../NBT/Flowers/flower_pot_05.nbt,5,minecraft:air,../NBT/Flowers/flower_pot_06.nbt,5,minecraft:potted_cactus,../NBT/Flowers/flower_pot_07.nbt,5,minecraft:air,../NBT/Flowers/flower_pot_08.nbt,5,minecraft:air,../NBT/Flowers/flower_pot_09.nbt,5,minecraft:air,../NBT/Flowers/flower_pot_10.nbt,5,minecraft:air,../NBT/Flowers/flower_pot_11.nbt,5,minecraft:air,../NBT/Flowers/flower_pot_12.nbt,5,minecraft:air,../NBT/Flowers/flower_pot_13.nbt,5,minecraft:air,../NBT/Flowers/flower_pot_14.nbt,5,minecraft:air,../NBT/Flowers/flower_pot_15.nbt,5,minecraft:air,../NBT/Flowers/flower_pot_16.nbt,5,minecraft:air,../NBT/Flowers/flower_pot_17.nbt,5,minecraft:potted_brown_mushroom,../NBT/Flowers/flower_pot_18.nbt,5,minecraft:air,../NBT/Flowers/flower_pot_19.nbt,5,minecraft:air,../NBT/Flowers/flower_pot_20.nbt,100)
RB(-7,59,-8,minecraft:air,25,minecraft:chest,../NBT/StructureLoot/JunkChest_1.nbt,15,minecraft:chest,../NBT/StructureLoot/JunkChest_2.nbt,15,minecraft:chest,../NBT/StructureLoot/JunkChest_3.nbt,15,minecraft:chest,../NBT/StructureLoot/JunkChest_4.nbt,15,minecraft:chest,../NBT/StructureLoot/JunkChest_5.nbt,15,minecraft:chest,../NBT/StructureLoot/Common1.nbt,15,minecraft:chest,../NBT/StructureLoot/Common2.nbt,15,minecraft:chest,../NBT/StructureLoot/Common3.nbt,15,minecraft:chest,../NBT/StructureLoot/Common4.nbt,15,minecraft:chest,../NBT/StructureLoot/Common5.nbt,15,minecraft:chest,../NBT/StructureLoot/Common6.nbt,15,minecraft:chest,../NBT/StructureLoot/Common7.nbt,15,minecraft:chest,../NBT/StructureLoot/Common8.nbt,15,minecraft:chest,../NBT/StructureLoot/Common9.nbt,15,minecraft:chest,../NBT/StructureLoot/Common10.nbt,15,minecraft:chest,../NBT/StructureLoot/Common11.nbt,15,minecraft:chest,../NBT/StructureLoot/Common12.nbt,15,minecraft:chest,../NBT/StructureLoot/Common13.nbt,15,minecraft:chest,../NBT/StructureLoot/Common14.nbt,15,minecraft:chest,../NBT/StructureLoot/Common15.nbt,100)

#######################################################################
# +-----------------------------------------------------------------+ #
# |                            BO3 checks                           | #
# +-----------------------------------------------------------------+ #
#######################################################################


#######################################################################
# +-----------------------------------------------------------------+ #
# |                             Branches                            | #
# +-----------------------------------------------------------------+ #
#######################################################################

Branch(-8,0,0,WestPort_5x6,NORTH,100.0)

#######################################################################
# +-----------------------------------------------------------------+ #
# |                             Entities                            | #
# +-----------------------------------------------------------------+ #
#######################################################################

