#######################################################################
# +-----------------------------------------------------------------+ #
# |                            BO3 object                           | #
# +-----------------------------------------------------------------+ #
#######################################################################

Author: Bo3 BulkEdit

Description: Converted Schematic - Modified by Bo3BulkEdit

Version: 3

SettingsMode: WriteDisable

#######################################################################
# +-----------------------------------------------------------------+ #
# |                          Main settings                          | #
# +-----------------------------------------------------------------+ #
#######################################################################



Frequency: 0


SpawnHeight: randomY





##############################
# Height Limits for the BO3. #
##############################

MinHeight: 0
MaxHeight: 256

#######################################################################
# +-----------------------------------------------------------------+ #
# |                      Source block settings                      | #
# +-----------------------------------------------------------------+ #
#######################################################################

CanOverride: true
MaxPercentageOutsideSourceBlock: 100
OutsideSourceBlock: placeAnyway

#######################################################################
# +-----------------------------------------------------------------+ #
# |                               OTG+                              | #
# +-----------------------------------------------------------------+ #
#######################################################################

#######################################################################
# +-----------------------------------------------------------------+ #
# |                              Blocks                             | #
# +-----------------------------------------------------------------+ #
#######################################################################

B(0,750,0,AIR)
B(15,750,15,AIR)
B(14,1,15,STAINED_GLASS:15)
B(13,2,15,STAINED_GLASS:15)
B(14,2,15,STAINED_GLASS:15)
B(12,3,15,STAINED_GLASS:15)
B(13,3,15,STAINED_GLASS:15)
B(14,3,15,STAINED_GLASS:15)
B(13,4,14,STAINED_GLASS:15)
B(12,4,15,STAINED_GLASS:15)
B(13,4,15,STAINED_GLASS:15)
B(14,4,15,STAINED_GLASS:15)
B(11,5,14,STAINED_GLASS:11)
B(12,5,14,STAINED_GLASS:15)
B(13,5,14,STAINED_GLASS:15)
B(10,5,15,STAINED_GLASS:11)
B(11,5,15,STAINED_GLASS:11)
B(12,5,15,STAINED_GLASS:11)
B(13,5,15,STAINED_GLASS:15)
B(14,5,15,STAINED_GLASS:15)
B(11,6,13,STAINED_GLASS:11)
B(10,6,14,STAINED_GLASS:11)
B(11,6,14,STAINED_GLASS:11)
B(12,6,14,STAINED_GLASS:11)
B(13,6,14,STAINED_GLASS:15)
B(9,6,15,STAINED_GLASS:11)
B(10,6,15,STAINED_GLASS:11)
B(11,6,15,STAINED_GLASS:11)
B(12,6,15,STAINED_GLASS:11)
B(13,6,15,STAINED_GLASS:15)
B(14,6,15,STAINED_GLASS:15)
B(11,7,13,STAINED_GLASS:11)
B(12,7,13,STAINED_GLASS:11)
B(10,7,14,STAINED_GLASS:11)
B(11,7,14,STAINED_GLASS:11)
B(12,7,14,STAINED_GLASS:11)
B(13,7,14,STAINED_GLASS:15)
B(9,7,15,STAINED_GLASS:11)
B(10,7,15,STAINED_GLASS:11)
B(11,7,15,STAINED_GLASS:11)
B(12,7,15,STAINED_GLASS:11)
B(13,7,15,STAINED_GLASS:15)
B(14,7,15,STAINED_GLASS:15)
B(11,8,12,STAINED_GLASS:11)
B(10,8,13,STAINED_GLASS:11)
B(11,8,13,STAINED_GLASS:11)
B(12,8,13,STAINED_GLASS:11)
B(9,8,14,STAINED_GLASS:11)
B(10,8,14,STAINED_GLASS:11)
B(11,8,14,STAINED_GLASS:11)
B(12,8,14,STAINED_GLASS:11)
B(13,8,14,STAINED_GLASS:11)
B(8,8,15,STAINED_GLASS:15)
B(9,8,15,STAINED_GLASS:15)
B(10,8,15,STAINED_GLASS:11)
B(11,8,15,STAINED_GLASS:11)
B(12,8,15,STAINED_GLASS:11)
B(13,8,15,STAINED_GLASS:15)
B(14,8,15,STAINED_GLASS:15)
B(10,9,12,STAINED_GLASS:15)
B(11,9,12,STAINED_GLASS:11)
B(9,9,13,STAINED_GLASS:15)
B(10,9,13,STAINED_GLASS:15)
B(11,9,13,STAINED_GLASS:15)
B(12,9,13,STAINED_GLASS:11)
B(8,9,14,STAINED_GLASS:15)
B(9,9,14,STAINED_GLASS:15)
B(10,9,14,STAINED_GLASS:11)
B(11,9,14,STAINED_GLASS:11)
B(12,9,14,STAINED_GLASS:11)
B(13,9,14,STAINED_GLASS:15)
B(8,9,15,STAINED_GLASS:15)
B(9,9,15,STAINED_GLASS:15)
B(10,9,15,STAINED_GLASS:11)
B(11,9,15,STAINED_GLASS:11)
B(12,9,15,STAINED_GLASS:11)
B(13,9,15,STAINED_GLASS:11)
B(14,9,15,STAINED_GLASS:15)
B(10,10,12,STAINED_GLASS:15)
B(11,10,12,STAINED_GLASS:15)
B(9,10,13,STAINED_GLASS:15)
B(10,10,13,STAINED_GLASS:15)
B(11,10,13,STAINED_GLASS:15)
B(12,10,13,STAINED_GLASS:15)
B(8,10,14,STAINED_GLASS:15)
B(9,10,14,STAINED_GLASS:15)
B(10,10,14,STAINED_GLASS:11)
B(11,10,14,STAINED_GLASS:11)
B(12,10,14,STAINED_GLASS:15)
B(13,10,14,STAINED_GLASS:15)
B(7,10,15,STAINED_GLASS:15)
B(8,10,15,STAINED_GLASS:15)
B(9,10,15,STAINED_GLASS:15)
B(10,10,15,STAINED_GLASS:11)
B(11,10,15,STAINED_GLASS:11)
B(12,10,15,SEA_LANTERN)
B(13,10,15,STAINED_GLASS:11)
B(14,10,15,STAINED_GLASS:15)
B(10,11,11,STAINED_GLASS:11)
B(11,11,11,STAINED_GLASS:11)
B(9,11,12,STAINED_GLASS:15)
B(10,11,12,STAINED_GLASS:15)
B(11,11,12,STAINED_GLASS:11)
B(8,11,13,STAINED_GLASS:15)
B(9,11,13,STAINED_GLASS:11)
B(10,11,13,STAINED_GLASS:15)
B(11,11,13,STAINED_GLASS:11)
B(12,11,13,STAINED_GLASS:15)
B(7,11,14,STAINED_GLASS:15)
B(8,11,14,STAINED_GLASS:15)
B(9,11,14,STAINED_GLASS:15)
B(10,11,14,SEA_LANTERN)
B(11,11,14,STAINED_GLASS:11)
B(12,11,14,STAINED_GLASS:15)
B(13,11,14,STAINED_GLASS:15)
B(7,11,15,STAINED_GLASS:15)
B(8,11,15,STAINED_GLASS:15)
B(9,11,15,STAINED_GLASS:11)
B(10,11,15,STAINED_GLASS:11)
B(11,11,15,STAINED_GLASS:11)
B(12,11,15,SEA_LANTERN)
B(13,11,15,STAINED_GLASS:15)
B(14,11,15,STAINED_GLASS:15)
B(9,12,11,STAINED_GLASS:15)
B(10,12,11,STAINED_GLASS:11)
B(11,12,11,STAINED_GLASS:11)
B(8,12,12,STAINED_GLASS:15)
B(9,12,12,STAINED_GLASS:15)
B(10,12,12,STAINED_GLASS:11)
B(11,12,12,STAINED_GLASS:11)
B(7,12,13,STAINED_GLASS:15)
B(8,12,13,STAINED_GLASS:15)
B(9,12,13,STAINED_GLASS:11)
B(10,12,13,STAINED_GLASS:11)
B(11,12,13,STAINED_GLASS:11)
B(12,12,13,STAINED_GLASS:11)
B(7,12,14,STAINED_GLASS:15)
B(8,12,14,STAINED_GLASS:15)
B(9,12,14,STAINED_GLASS:11)
B(10,12,14,SEA_LANTERN)
B(11,12,14,SEA_LANTERN)
B(12,12,14,STAINED_GLASS:11)
B(13,12,14,STAINED_GLASS:15)
B(7,12,15,STAINED_GLASS:15)
B(8,12,15,STAINED_GLASS:15)
B(9,12,15,STAINED_GLASS:11)
B(10,12,15,SEA_LANTERN)
B(11,12,15,SEA_LANTERN)
B(12,12,15,SEA_LANTERN)
B(13,12,15,STAINED_GLASS:15)
B(14,12,15,STAINED_GLASS:15)
B(11,13,10,STAINED_GLASS:11)
B(9,13,11,STAINED_GLASS:15)
B(10,13,11,STAINED_GLASS:11)
B(11,13,11,STAINED_GLASS:11)
B(8,13,12,STAINED_GLASS:15)
B(9,13,12,STAINED_GLASS:15)
B(10,13,12,STAINED_GLASS:11)
B(11,13,12,STAINED_GLASS:11)
B(7,13,13,STAINED_GLASS:15)
B(8,13,13,STAINED_GLASS:15)
B(9,13,13,STAINED_GLASS:11)
B(10,13,13,STAINED_GLASS:11)
B(11,13,13,SEA_LANTERN)
B(12,13,13,STAINED_GLASS:11)
B(6,13,14,STAINED_GLASS:15)
B(7,13,14,STAINED_GLASS:15)
B(8,13,14,STAINED_GLASS:15)
B(9,13,14,STAINED_GLASS:11)
B(10,13,14,SEA_LANTERN)
B(11,13,14,SEA_LANTERN)
B(12,13,14,STAINED_GLASS:11)
B(13,13,14,STAINED_GLASS:15)
B(7,13,15,STAINED_GLASS:15)
B(8,13,15,STAINED_GLASS:15)
B(9,13,15,SEA_LANTERN)
B(10,13,15,SEA_LANTERN)
B(11,13,15,SEA_LANTERN)
B(12,13,15,STAINED_GLASS:11)
B(13,13,15,STAINED_GLASS:15)
B(14,13,15,STAINED_GLASS:15)
B(10,14,10,STAINED_GLASS:15)
B(11,14,10,STAINED_GLASS:11)
B(8,14,11,STAINED_GLASS:15)
B(9,14,11,STAINED_GLASS:15)
B(10,14,11,STAINED_GLASS:11)
B(11,14,11,STAINED_GLASS:11)
B(7,14,12,STAINED_GLASS:15)
B(8,14,12,STAINED_GLASS:15)
B(9,14,12,STAINED_GLASS:15)
B(10,14,12,STAINED_GLASS:11)
B(11,14,12,STAINED_GLASS:11)
B(6,14,13,STAINED_GLASS:15)
B(7,14,13,STAINED_GLASS:15)
B(8,14,13,STAINED_GLASS:15)
B(9,14,13,SEA_LANTERN)
B(10,14,13,STAINED_GLASS:11)
B(11,14,13,SEA_LANTERN)
B(12,14,13,STAINED_GLASS:11)
B(6,14,14,STAINED_GLASS:15)
B(7,14,14,STAINED_GLASS:15)
B(8,14,14,STAINED_GLASS:11)
B(9,14,14,STAINED_GLASS:11)
B(10,14,14,SEA_LANTERN)
B(11,14,14,STAINED_GLASS:11)
B(12,14,14,STAINED_GLASS:15)
B(13,14,14,STAINED_GLASS:15)
B(7,14,15,STAINED_GLASS:15)
B(8,14,15,STAINED_GLASS:15)
B(9,14,15,SEA_LANTERN)
B(10,14,15,STAINED_GLASS:11)
B(11,14,15,STAINED_GLASS:11)
B(12,14,15,STAINED_GLASS:11)
B(13,14,15,STAINED_GLASS:15)
B(14,14,15,STAINED_GLASS:15)
B(9,15,10,STAINED_GLASS:15)
B(10,15,10,STAINED_GLASS:15)
B(11,15,10,STAINED_GLASS:11)
B(7,15,11,STAINED_GLASS:15)
B(8,15,11,STAINED_GLASS:15)
B(9,15,11,STAINED_GLASS:15)
B(10,15,11,STAINED_GLASS:11)
B(11,15,11,STAINED_GLASS:11)
B(6,15,12,STAINED_GLASS:15)
B(7,15,12,STAINED_GLASS:15)
B(8,15,12,STAINED_GLASS:11)
B(9,15,12,STAINED_GLASS:11)
B(10,15,12,STAINED_GLASS:11)
B(11,15,12,STAINED_GLASS:11)
B(6,15,13,STAINED_GLASS:15)
B(7,15,13,STAINED_GLASS:15)
B(8,15,13,STAINED_GLASS:11)
B(9,15,13,SEA_LANTERN)
B(10,15,13,SEA_LANTERN)
B(11,15,13,SEA_LANTERN)
B(12,15,13,STAINED_GLASS:11)
B(6,15,14,STAINED_GLASS:15)
B(7,15,14,STAINED_GLASS:15)
B(8,15,14,STAINED_GLASS:11)
B(9,15,14,SEA_LANTERN)
B(10,15,14,SEA_LANTERN)
B(11,15,14,STAINED_GLASS:11)
B(12,15,14,STAINED_GLASS:15)
B(13,15,14,STAINED_GLASS:15)
B(7,15,15,STAINED_GLASS:15)
B(8,15,15,STAINED_GLASS:11)
B(9,15,15,SEA_LANTERN)
B(10,15,15,STAINED_GLASS:11)
B(11,15,15,STAINED_GLASS:11)
B(12,15,15,STAINED_GLASS:15)
B(13,15,15,STAINED_GLASS:15)
B(14,15,15,STAINED_GLASS:15)
B(10,16,9,STAINED_GLASS:15)
B(9,16,10,STAINED_GLASS:15)
B(10,16,10,STAINED_GLASS:15)
B(11,16,10,STAINED_GLASS:15)
B(7,16,11,STAINED_GLASS:15)
B(8,16,11,STAINED_GLASS:15)
B(9,16,11,STAINED_GLASS:15)
B(10,16,11,STAINED_GLASS:11)
B(11,16,11,STAINED_GLASS:11)
B(5,16,12,STAINED_GLASS:15)
B(6,16,12,STAINED_GLASS:15)
B(7,16,12,STAINED_GLASS:15)
B(8,16,12,STAINED_GLASS:11)
B(9,16,12,STAINED_GLASS:11)
B(10,16,12,SEA_LANTERN)
B(11,16,12,STAINED_GLASS:11)
B(6,16,13,STAINED_GLASS:15)
B(7,16,13,STAINED_GLASS:15)
B(8,16,13,STAINED_GLASS:11)
B(9,16,13,SEA_LANTERN)
B(10,16,13,SEA_LANTERN)
B(11,16,13,STAINED_GLASS:11)
B(12,16,13,STAINED_GLASS:11)
B(6,16,14,STAINED_GLASS:15)
B(7,16,14,STAINED_GLASS:15)
B(8,16,14,SEA_LANTERN)
B(9,16,14,SEA_LANTERN)
B(10,16,14,SEA_LANTERN)
B(11,16,14,STAINED_GLASS:15)
B(12,16,14,STAINED_GLASS:11)
B(13,16,14,STAINED_GLASS:15)
B(7,16,15,STAINED_GLASS:15)
B(8,16,15,STAINED_GLASS:11)
B(9,16,15,STAINED_GLASS:11)
B(10,16,15,STAINED_GLASS:15)
B(11,16,15,STAINED_GLASS:15)
B(12,16,15,STAINED_GLASS:15)
B(13,16,15,STAINED_GLASS:15)
B(9,17,9,STAINED_GLASS:15)
B(10,17,9,STAINED_GLASS:15)
B(8,17,10,STAINED_GLASS:15)
B(9,17,10,STAINED_GLASS:15)
B(10,17,10,STAINED_GLASS:15)
B(11,17,10,STAINED_GLASS:15)
B(5,17,11,STAINED_GLASS:15)
B(6,17,11,STAINED_GLASS:15)
B(7,17,11,STAINED_GLASS:15)
B(8,17,11,STAINED_GLASS:15)
B(9,17,11,STAINED_GLASS:11)
B(10,17,11,STAINED_GLASS:15)
B(11,17,11,STAINED_GLASS:15)
B(5,17,12,STAINED_GLASS:15)
B(6,17,12,STAINED_GLASS:15)
B(7,17,12,STAINED_GLASS:15)
B(8,17,12,SEA_LANTERN)
B(9,17,12,STAINED_GLASS:11)
B(10,17,12,SEA_LANTERN)
B(11,17,12,STAINED_GLASS:11)
B(6,17,13,STAINED_GLASS:15)
B(7,17,13,STAINED_GLASS:11)
B(8,17,13,STAINED_GLASS:11)
B(9,17,13,SEA_LANTERN)
B(10,17,13,STAINED_GLASS:11)
B(11,17,13,STAINED_GLASS:11)
B(12,17,13,STAINED_GLASS:11)
B(6,17,14,STAINED_GLASS:15)
B(7,17,14,STAINED_GLASS:15)
B(8,17,14,SEA_LANTERN)
B(9,17,14,STAINED_GLASS:11)
B(10,17,14,SEA_LANTERN)
B(11,17,14,STAINED_GLASS:15)
B(12,17,14,STAINED_GLASS:11)
B(13,17,14,STAINED_GLASS:11)
B(7,17,15,STAINED_GLASS:15)
B(8,17,15,STAINED_GLASS:15)
B(9,17,15,STAINED_GLASS:11)
B(10,17,15,STAINED_GLASS:15)
B(11,17,15,STAINED_GLASS:15)
B(12,17,15,STAINED_GLASS:15)
B(13,17,15,STAINED_GLASS:15)
B(8,18,9,STAINED_GLASS:15)
B(9,18,9,STAINED_GLASS:15)
B(10,18,9,STAINED_GLASS:15)
B(7,18,10,STAINED_GLASS:15)
B(8,18,10,STAINED_GLASS:15)
B(9,18,10,STAINED_GLASS:15)
B(10,18,10,STAINED_GLASS:11)
B(11,18,10,STAINED_GLASS:11)
B(5,18,11,STAINED_GLASS:15)
B(6,18,11,STAINED_GLASS:15)
B(7,18,11,STAINED_GLASS:11)
B(8,18,11,STAINED_GLASS:11)
B(9,18,11,STAINED_GLASS:11)
B(10,18,11,STAINED_GLASS:11)
B(11,18,11,STAINED_GLASS:11)
B(5,18,12,STAINED_GLASS:15)
B(6,18,12,STAINED_GLASS:15)
B(7,18,12,STAINED_GLASS:11)
B(8,18,12,SEA_LANTERN)
B(9,18,12,SEA_LANTERN)
B(10,18,12,SEA_LANTERN)
B(11,18,12,STAINED_GLASS:11)
B(6,18,13,STAINED_GLASS:11)
B(7,18,13,STAINED_GLASS:11)
B(8,18,13,SEA_LANTERN)
B(9,18,13,SEA_LANTERN)
B(10,18,13,STAINED_GLASS:11)
B(11,18,13,STAINED_GLASS:15)
B(12,18,13,STAINED_GLASS:11)
B(6,18,14,STAINED_GLASS:11)
B(7,18,14,STAINED_GLASS:11)
B(8,18,14,SEA_LANTERN)
B(9,18,14,STAINED_GLASS:11)
B(10,18,14,STAINED_GLASS:11)
B(11,18,14,STAINED_GLASS:15)
B(12,18,14,STAINED_GLASS:11)
B(13,18,14,STAINED_GLASS:15)
B(7,18,15,STAINED_GLASS:15)
B(8,18,15,STAINED_GLASS:11)
B(9,18,15,STAINED_GLASS:15)
B(10,18,15,STAINED_GLASS:15)
B(11,18,15,STAINED_GLASS:15)
B(12,18,15,STAINED_GLASS:15)
B(9,19,8,STAINED_GLASS:15)
B(8,19,9,STAINED_GLASS:15)
B(9,19,9,STAINED_GLASS:15)
B(10,19,9,STAINED_GLASS:11)
B(7,19,10,STAINED_GLASS:15)
B(8,19,10,STAINED_GLASS:15)
B(9,19,10,STAINED_GLASS:15)
B(10,19,10,STAINED_GLASS:11)
B(11,19,10,STAINED_GLASS:11)
B(4,19,11,STAINED_GLASS:15)
B(5,19,11,STAINED_GLASS:15)
B(6,19,11,STAINED_GLASS:15)
B(7,19,11,STAINED_GLASS:11)
B(8,19,11,STAINED_GLASS:11)
B(9,19,11,SEA_LANTERN)
B(10,19,11,STAINED_GLASS:11)
B(11,19,11,STAINED_GLASS:11)
B(5,19,12,STAINED_GLASS:11)
B(6,19,12,STAINED_GLASS:15)
B(7,19,12,STAINED_GLASS:11)
B(8,19,12,SEA_LANTERN)
B(9,19,12,SEA_LANTERN)
B(10,19,12,STAINED_GLASS:11)
B(11,19,12,STAINED_GLASS:15)
B(6,19,13,STAINED_GLASS:11)
B(7,19,13,SEA_LANTERN)
B(8,19,13,SEA_LANTERN)
B(9,19,13,SEA_LANTERN)
B(10,19,13,STAINED_GLASS:15)
B(11,19,13,STAINED_GLASS:15)
B(12,19,13,STAINED_GLASS:15)
B(6,19,14,STAINED_GLASS:11)
B(7,19,14,STAINED_GLASS:11)
B(8,19,14,STAINED_GLASS:11)
B(9,19,14,STAINED_GLASS:15)
B(10,19,14,STAINED_GLASS:11)
B(11,19,14,STAINED_GLASS:15)
B(12,19,14,STAINED_GLASS:15)
B(7,19,15,STAINED_GLASS:11)
B(8,19,15,STAINED_GLASS:11)
B(9,19,15,STAINED_GLASS:11)
B(10,19,15,STAINED_GLASS:15)
B(11,19,15,STAINED_GLASS:15)
B(12,19,15,STAINED_GLASS:15)
B(8,20,8,STAINED_GLASS:15)
B(9,20,8,STAINED_GLASS:15)
B(7,20,9,STAINED_GLASS:15)
B(8,20,9,STAINED_GLASS:15)
B(9,20,9,STAINED_GLASS:15)
B(10,20,9,STAINED_GLASS:11)
B(5,20,10,STAINED_GLASS:15)
B(6,20,10,STAINED_GLASS:15)
B(7,20,10,STAINED_GLASS:15)
B(8,20,10,STAINED_GLASS:15)
B(9,20,10,STAINED_GLASS:11)
B(10,20,10,STAINED_GLASS:11)
B(11,20,10,STAINED_GLASS:11)
B(4,20,11,STAINED_GLASS:15)
B(5,20,11,STAINED_GLASS:15)
B(6,20,11,STAINED_GLASS:15)
B(7,20,11,SEA_LANTERN)
B(8,20,11,STAINED_GLASS:11)
B(9,20,11,SEA_LANTERN)
B(10,20,11,STAINED_GLASS:11)
B(11,20,11,STAINED_GLASS:11)
B(5,20,12,STAINED_GLASS:15)
B(6,20,12,STAINED_GLASS:11)
B(7,20,12,STAINED_GLASS:11)
B(8,20,12,SEA_LANTERN)
B(9,20,12,STAINED_GLASS:11)
B(10,20,12,STAINED_GLASS:11)
B(11,20,12,STAINED_GLASS:15)
B(6,20,13,STAINED_GLASS:11)
B(7,20,13,SEA_LANTERN)
B(8,20,13,STAINED_GLASS:11)
B(9,20,13,SEA_LANTERN)
B(10,20,13,STAINED_GLASS:15)
B(11,20,13,STAINED_GLASS:15)
B(12,20,13,STAINED_GLASS:15)
B(6,20,14,STAINED_GLASS:11)
B(7,20,14,STAINED_GLASS:11)
B(8,20,14,STAINED_GLASS:11)
B(9,20,14,STAINED_GLASS:15)
B(10,20,14,STAINED_GLASS:15)
B(11,20,14,STAINED_GLASS:15)
B(12,20,14,STAINED_GLASS:15)
B(7,20,15,STAINED_GLASS:15)
B(8,20,15,STAINED_GLASS:11)
B(9,20,15,STAINED_GLASS:15)
B(10,20,15,STAINED_GLASS:15)
B(11,20,15,STAINED_GLASS:15)
B(7,21,8,STAINED_GLASS:15)
B(8,21,8,STAINED_GLASS:15)
B(9,21,8,STAINED_GLASS:15)
B(5,21,9,STAINED_GLASS:15)
B(6,21,9,STAINED_GLASS:15)
B(7,21,9,STAINED_GLASS:15)
B(8,21,9,STAINED_GLASS:15)
B(9,21,9,STAINED_GLASS:15)
B(10,21,9,STAINED_GLASS:15)
B(5,21,10,STAINED_GLASS:15)
B(6,21,10,STAINED_GLASS:15)
B(7,21,10,STAINED_GLASS:11)
B(8,21,10,STAINED_GLASS:11)
B(9,21,10,STAINED_GLASS:11)
B(10,21,10,STAINED_GLASS:11)
B(11,21,10,STAINED_GLASS:11)
B(4,21,11,STAINED_GLASS:15)
B(5,21,11,STAINED_GLASS:15)
B(6,21,11,STAINED_GLASS:11)
B(7,21,11,SEA_LANTERN)
B(8,21,11,SEA_LANTERN)
B(9,21,11,SEA_LANTERN)
B(10,21,11,STAINED_GLASS:11)
B(11,21,11,STAINED_GLASS:11)
B(5,21,12,STAINED_GLASS:15)
B(6,21,12,STAINED_GLASS:11)
B(7,21,12,SEA_LANTERN)
B(8,21,12,SEA_LANTERN)
B(9,21,12,STAINED_GLASS:11)
B(10,21,12,STAINED_GLASS:15)
B(11,21,12,STAINED_GLASS:11)
B(6,21,13,STAINED_GLASS:11)
B(7,21,13,SEA_LANTERN)
B(8,21,13,STAINED_GLASS:11)
B(9,21,13,STAINED_GLASS:11)
B(10,21,13,STAINED_GLASS:11)
B(11,21,13,STAINED_GLASS:11)
B(12,21,13,STAINED_GLASS:15)
B(6,21,14,STAINED_GLASS:15)
B(7,21,14,STAINED_GLASS:15)
B(8,21,14,STAINED_GLASS:15)
B(9,21,14,STAINED_GLASS:15)
B(10,21,14,STAINED_GLASS:15)
B(7,21,15,STAINED_GLASS:15)
B(8,21,15,STAINED_GLASS:15)
B(9,21,15,STAINED_GLASS:15)
B(8,22,7,STAINED_GLASS:15)
B(7,22,8,STAINED_GLASS:15)
B(8,22,8,STAINED_GLASS:15)
B(9,22,8,STAINED_GLASS:15)
B(5,22,9,STAINED_GLASS:15)
B(6,22,9,STAINED_GLASS:15)
B(7,22,9,STAINED_GLASS:15)
B(8,22,9,STAINED_GLASS:15)
B(9,22,9,STAINED_GLASS:15)
B(10,22,9,STAINED_GLASS:15)
B(4,22,10,STAINED_GLASS:15)
B(5,22,10,STAINED_GLASS:15)
B(6,22,10,STAINED_GLASS:15)
B(7,22,10,STAINED_GLASS:11)
B(8,22,10,STAINED_GLASS:11)
B(9,22,10,SEA_LANTERN)
B(10,22,10,STAINED_GLASS:11)
B(11,22,10,STAINED_GLASS:11)
B(4,22,11,STAINED_GLASS:15)
B(5,22,11,STAINED_GLASS:11)
B(6,22,11,STAINED_GLASS:11)
B(7,22,11,SEA_LANTERN)
B(8,22,11,SEA_LANTERN)
B(9,22,11,STAINED_GLASS:11)
B(10,22,11,STAINED_GLASS:11)
B(11,22,11,STAINED_GLASS:11)
B(5,22,12,STAINED_GLASS:11)
B(6,22,12,SEA_LANTERN)
B(7,22,12,SEA_LANTERN)
B(8,22,12,SEA_LANTERN)
B(9,22,12,STAINED_GLASS:15)
B(10,22,12,STAINED_GLASS:11)
B(11,22,12,STAINED_GLASS:11)
B(6,22,13,STAINED_GLASS:11)
B(7,22,13,STAINED_GLASS:11)
B(8,22,13,STAINED_GLASS:15)
B(9,22,13,STAINED_GLASS:11)
B(10,22,13,STAINED_GLASS:11)
B(11,22,13,STAINED_GLASS:11)
B(6,22,14,STAINED_GLASS:11)
B(7,22,14,STAINED_GLASS:11)
B(8,22,14,STAINED_GLASS:15)
B(9,22,14,STAINED_GLASS:15)
B(10,22,14,STAINED_GLASS:11)
B(7,22,15,STAINED_GLASS:15)
B(8,22,15,STAINED_GLASS:15)
B(9,22,15,STAINED_GLASS:15)
B(7,23,7,STAINED_GLASS:15)
B(8,23,7,STAINED_GLASS:15)
B(5,23,8,STAINED_GLASS:15)
B(6,23,8,STAINED_GLASS:15)
B(7,23,8,STAINED_GLASS:15)
B(8,23,8,STAINED_GLASS:15)
B(9,23,8,STAINED_GLASS:15)
B(4,23,9,STAINED_GLASS:11)
B(5,23,9,STAINED_GLASS:15)
B(6,23,9,STAINED_GLASS:15)
B(7,23,9,STAINED_GLASS:15)
B(8,23,9,STAINED_GLASS:11)
B(9,23,9,STAINED_GLASS:15)
B(10,23,9,STAINED_GLASS:11)
B(4,23,10,STAINED_GLASS:11)
B(5,23,10,STAINED_GLASS:11)
B(6,23,10,STAINED_GLASS:15)
B(7,23,10,SEA_LANTERN)
B(8,23,10,STAINED_GLASS:11)
B(9,23,10,SEA_LANTERN)
B(10,23,10,STAINED_GLASS:11)
B(11,23,10,STAINED_GLASS:11)
B(4,23,11,STAINED_GLASS:11)
B(5,23,11,STAINED_GLASS:11)
B(6,23,11,STAINED_GLASS:11)
B(7,23,11,SEA_LANTERN)
B(8,23,11,STAINED_GLASS:11)
B(9,23,11,STAINED_GLASS:11)
B(10,23,11,STAINED_GLASS:11)
B(11,23,11,STAINED_GLASS:11)
B(5,23,12,STAINED_GLASS:11)
B(6,23,12,SEA_LANTERN)
B(7,23,12,STAINED_GLASS:11)
B(8,23,12,SEA_LANTERN)
B(9,23,12,STAINED_GLASS:15)
B(10,23,12,STAINED_GLASS:11)
B(11,23,12,STAINED_GLASS:11)
B(6,23,13,STAINED_GLASS:11)
B(7,23,13,STAINED_GLASS:11)
B(8,23,13,STAINED_GLASS:15)
B(9,23,13,STAINED_GLASS:15)
B(10,23,13,STAINED_GLASS:11)
B(6,23,14,STAINED_GLASS:11)
B(7,23,14,STAINED_GLASS:11)
B(8,23,14,STAINED_GLASS:15)
B(9,23,14,STAINED_GLASS:15)
B(7,23,15,STAINED_GLASS:11)
B(8,23,15,STAINED_GLASS:15)
B(5,24,7,STAINED_GLASS:15)
B(6,24,7,STAINED_GLASS:15)
B(7,24,7,STAINED_GLASS:15)
B(8,24,7,STAINED_GLASS:15)
B(4,24,8,STAINED_GLASS:11)
B(5,24,8,STAINED_GLASS:11)
B(6,24,8,STAINED_GLASS:15)
B(7,24,8,STAINED_GLASS:15)
B(8,24,8,STAINED_GLASS:15)
B(9,24,8,STAINED_GLASS:15)
B(4,24,9,STAINED_GLASS:11)
B(5,24,9,STAINED_GLASS:11)
B(6,24,9,STAINED_GLASS:11)
B(7,24,9,STAINED_GLASS:11)
B(8,24,9,STAINED_GLASS:11)
B(9,24,9,STAINED_GLASS:11)
B(10,24,9,STAINED_GLASS:15)
B(4,24,10,STAINED_GLASS:11)
B(5,24,10,STAINED_GLASS:11)
B(6,24,10,STAINED_GLASS:11)
B(7,24,10,SEA_LANTERN)
B(8,24,10,SEA_LANTERN)
B(9,24,10,SEA_LANTERN)
B(10,24,10,STAINED_GLASS:11)
B(11,24,10,STAINED_GLASS:11)
B(4,24,11,STAINED_GLASS:11)
B(5,24,11,STAINED_GLASS:11)
B(6,24,11,SEA_LANTERN)
B(7,24,11,SEA_LANTERN)
B(8,24,11,STAINED_GLASS:11)
B(9,24,11,STAINED_GLASS:15)
B(10,24,11,STAINED_GLASS:11)
B(11,24,11,STAINED_GLASS:11)
B(5,24,12,STAINED_GLASS:11)
B(6,24,12,SEA_LANTERN)
B(7,24,12,STAINED_GLASS:11)
B(8,24,12,STAINED_GLASS:11)
B(9,24,12,STAINED_GLASS:15)
B(10,24,12,STAINED_GLASS:11)
B(6,24,13,STAINED_GLASS:11)
B(7,24,13,STAINED_GLASS:15)
B(8,24,13,STAINED_GLASS:15)
B(9,24,13,STAINED_GLASS:15)
B(6,24,14,STAINED_GLASS:11)
B(7,24,14,STAINED_GLASS:11)
B(8,24,14,STAINED_GLASS:15)
B(7,24,15,STAINED_GLASS:15)
B(7,25,6,STAINED_GLASS:15)
B(5,25,7,STAINED_GLASS:11)
B(6,25,7,STAINED_GLASS:15)
B(7,25,7,STAINED_GLASS:15)
B(8,25,7,STAINED_GLASS:15)
B(4,25,8,STAINED_GLASS:11)
B(5,25,8,STAINED_GLASS:11)
B(6,25,8,STAINED_GLASS:15)
B(7,25,8,STAINED_GLASS:15)
B(8,25,8,STAINED_GLASS:15)
B(9,25,8,STAINED_GLASS:15)
B(3,25,9,STAINED_GLASS:11)
B(4,25,9,STAINED_GLASS:11)
B(5,25,9,STAINED_GLASS:11)
B(6,25,9,STAINED_GLASS:11)
B(7,25,9,STAINED_GLASS:11)
B(8,25,9,SEA_LANTERN)
B(9,25,9,STAINED_GLASS:11)
B(10,25,9,STAINED_GLASS:15)
B(4,25,10,STAINED_GLASS:11)
B(5,25,10,STAINED_GLASS:11)
B(6,25,10,STAINED_GLASS:11)
B(7,25,10,SEA_LANTERN)
B(8,25,10,SEA_LANTERN)
B(9,25,10,STAINED_GLASS:11)
B(10,25,10,STAINED_GLASS:15)
B(11,25,10,STAINED_GLASS:11)
B(4,25,11,STAINED_GLASS:15)
B(5,25,11,STAINED_GLASS:11)
B(6,25,11,SEA_LANTERN)
B(7,25,11,SEA_LANTERN)
B(8,25,11,STAINED_GLASS:15)
B(9,25,11,STAINED_GLASS:11)
B(10,25,11,STAINED_GLASS:11)
B(11,25,11,STAINED_GLASS:11)
B(5,25,12,STAINED_GLASS:11)
B(6,25,12,STAINED_GLASS:11)
B(7,25,12,STAINED_GLASS:15)
B(8,25,12,STAINED_GLASS:11)
B(9,25,12,STAINED_GLASS:11)
B(10,25,12,STAINED_GLASS:11)
B(6,25,13,STAINED_GLASS:11)
B(7,25,13,STAINED_GLASS:15)
B(8,25,13,STAINED_GLASS:15)
B(9,25,13,STAINED_GLASS:11)
B(6,25,14,STAINED_GLASS:15)
B(7,25,14,STAINED_GLASS:15)
B(8,25,14,STAINED_GLASS:15)
B(6,26,5,STAINED_GLASS:15)
B(5,26,6,STAINED_GLASS:11)
B(6,26,6,STAINED_GLASS:15)
B(7,26,6,STAINED_GLASS:15)
B(4,26,7,STAINED_GLASS:11)
B(5,26,7,STAINED_GLASS:11)
B(6,26,7,STAINED_GLASS:15)
B(7,26,7,STAINED_GLASS:15)
B(8,26,7,STAINED_GLASS:15)
B(3,26,8,STAINED_GLASS:11)
B(4,26,8,STAINED_GLASS:11)
B(5,26,8,STAINED_GLASS:11)
B(6,26,8,STAINED_GLASS:15)
B(7,26,8,STAINED_GLASS:11)
B(8,26,8,STAINED_GLASS:15)
B(9,26,8,STAINED_GLASS:15)
B(3,26,9,STAINED_GLASS:15)
B(4,26,9,STAINED_GLASS:11)
B(5,26,9,STAINED_GLASS:11)
B(6,26,9,SEA_LANTERN)
B(7,26,9,STAINED_GLASS:11)
B(8,26,9,SEA_LANTERN)
B(9,26,9,STAINED_GLASS:15)
B(10,26,9,STAINED_GLASS:15)
B(4,26,10,STAINED_GLASS:15)
B(5,26,10,STAINED_GLASS:15)
B(6,26,10,STAINED_GLASS:11)
B(7,26,10,SEA_LANTERN)
B(8,26,10,STAINED_GLASS:11)
B(9,26,10,STAINED_GLASS:11)
B(10,26,10,STAINED_GLASS:11)
B(11,26,10,STAINED_GLASS:11)
B(4,26,11,STAINED_GLASS:15)
B(5,26,11,STAINED_GLASS:15)
B(6,26,11,STAINED_GLASS:11)
B(7,26,11,SEA_LANTERN)
B(8,26,11,STAINED_GLASS:11)
B(9,26,11,STAINED_GLASS:11)
B(10,26,11,STAINED_GLASS:11)
B(11,26,11,STAINED_GLASS:11)
B(5,26,12,STAINED_GLASS:15)
B(6,26,12,STAINED_GLASS:11)
B(7,26,12,STAINED_GLASS:15)
B(8,26,12,STAINED_GLASS:11)
B(9,26,12,STAINED_GLASS:11)
B(6,26,13,STAINED_GLASS:15)
B(7,26,13,STAINED_GLASS:15)
B(8,26,13,STAINED_GLASS:11)
B(6,26,14,STAINED_GLASS:15)
B(7,26,14,STAINED_GLASS:15)
B(5,27,5,STAINED_GLASS:15)
B(6,27,5,STAINED_GLASS:15)
B(4,27,6,STAINED_GLASS:11)
B(5,27,6,STAINED_GLASS:11)
B(6,27,6,STAINED_GLASS:15)
B(7,27,6,STAINED_GLASS:15)
B(3,27,7,STAINED_GLASS:11)
B(4,27,7,STAINED_GLASS:11)
B(5,27,7,STAINED_GLASS:11)
B(6,27,7,STAINED_GLASS:15)
B(7,27,7,STAINED_GLASS:15)
B(8,27,7,STAINED_GLASS:15)
B(3,27,8,STAINED_GLASS:11)
B(4,27,8,STAINED_GLASS:11)
B(5,27,8,STAINED_GLASS:11)
B(6,27,8,STAINED_GLASS:11)
B(7,27,8,STAINED_GLASS:11)
B(8,27,8,STAINED_GLASS:11)
B(9,27,8,STAINED_GLASS:15)
B(3,27,9,STAINED_GLASS:15)
B(4,27,9,STAINED_GLASS:15)
B(5,27,9,STAINED_GLASS:11)
B(6,27,9,SEA_LANTERN)
B(7,27,9,SEA_LANTERN)
B(8,27,9,SEA_LANTERN)
B(9,27,9,STAINED_GLASS:15)
B(10,27,9,STAINED_GLASS:15)
B(4,27,10,STAINED_GLASS:15)
B(5,27,10,STAINED_GLASS:11)
B(6,27,10,SEA_LANTERN)
B(7,27,10,SEA_LANTERN)
B(8,27,10,STAINED_GLASS:11)
B(9,27,10,STAINED_GLASS:15)
B(10,27,10,STAINED_GLASS:15)
B(11,27,10,STAINED_GLASS:11)
B(4,27,11,STAINED_GLASS:15)
B(5,27,11,STAINED_GLASS:15)
B(6,27,11,STAINED_GLASS:11)
B(7,27,11,STAINED_GLASS:11)
B(8,27,11,STAINED_GLASS:11)
B(9,27,11,STAINED_GLASS:11)
B(5,27,12,STAINED_GLASS:15)
B(6,27,12,STAINED_GLASS:15)
B(7,27,12,STAINED_GLASS:11)
B(8,27,12,STAINED_GLASS:11)
B(6,27,13,STAINED_GLASS:15)
B(7,27,13,STAINED_GLASS:15)
B(6,27,14,STAINED_GLASS:15)
B(5,28,5,STAINED_GLASS:11)
B(6,28,5,STAINED_GLASS:15)
B(4,28,6,STAINED_GLASS:11)
B(5,28,6,STAINED_GLASS:11)
B(6,28,6,STAINED_GLASS:15)
B(7,28,6,STAINED_GLASS:15)
B(3,28,7,STAINED_GLASS:11)
B(4,28,7,STAINED_GLASS:11)
B(5,28,7,STAINED_GLASS:11)
B(6,28,7,STAINED_GLASS:15)
B(7,28,7,STAINED_GLASS:15)
B(8,28,7,STAINED_GLASS:15)
B(2,28,8,STAINED_GLASS:15)
B(3,28,8,STAINED_GLASS:11)
B(4,28,8,STAINED_GLASS:15)
B(5,28,8,STAINED_GLASS:11)
B(6,28,8,STAINED_GLASS:11)
B(7,28,8,SEA_LANTERN)
B(8,28,8,STAINED_GLASS:11)
B(9,28,8,STAINED_GLASS:15)
B(3,28,9,STAINED_GLASS:15)
B(4,28,9,STAINED_GLASS:15)
B(5,28,9,SEA_LANTERN)
B(6,28,9,SEA_LANTERN)
B(7,28,9,SEA_LANTERN)
B(8,28,9,STAINED_GLASS:11)
B(9,28,9,STAINED_GLASS:15)
B(10,28,9,STAINED_GLASS:15)
B(4,28,10,STAINED_GLASS:15)
B(5,28,10,STAINED_GLASS:11)
B(6,28,10,SEA_LANTERN)
B(7,28,10,SEA_LANTERN)
B(8,28,10,STAINED_GLASS:11)
B(9,28,10,STAINED_GLASS:15)
B(10,28,10,STAINED_GLASS:15)
B(4,28,11,STAINED_GLASS:15)
B(5,28,11,STAINED_GLASS:15)
B(6,28,11,STAINED_GLASS:11)
B(7,28,11,STAINED_GLASS:11)
B(8,28,11,STAINED_GLASS:11)
B(9,28,11,STAINED_GLASS:11)
B(5,28,12,STAINED_GLASS:15)
B(6,28,12,STAINED_GLASS:11)
B(7,28,12,STAINED_GLASS:11)
B(8,28,12,STAINED_GLASS:11)
B(6,28,13,STAINED_GLASS:15)
B(7,28,13,STAINED_GLASS:11)
B(6,29,4,STAINED_GLASS:11)
B(4,29,5,STAINED_GLASS:11)
B(5,29,5,STAINED_GLASS:11)
B(6,29,5,STAINED_GLASS:15)
B(3,29,6,STAINED_GLASS:11)
B(4,29,6,STAINED_GLASS:11)
B(5,29,6,STAINED_GLASS:11)
B(6,29,6,STAINED_GLASS:15)
B(7,29,6,STAINED_GLASS:15)
B(2,29,7,STAINED_GLASS:15)
B(3,29,7,STAINED_GLASS:15)
B(4,29,7,STAINED_GLASS:11)
B(5,29,7,SEA_LANTERN)
B(6,29,7,STAINED_GLASS:11)
B(7,29,7,STAINED_GLASS:15)
B(8,29,7,STAINED_GLASS:15)
B(2,29,8,STAINED_GLASS:15)
B(3,29,8,STAINED_GLASS:15)
B(4,29,8,STAINED_GLASS:11)
B(5,29,8,STAINED_GLASS:11)
B(6,29,8,STAINED_GLASS:11)
B(7,29,8,SEA_LANTERN)
B(8,29,8,STAINED_GLASS:15)
B(9,29,8,STAINED_GLASS:15)
B(3,29,9,STAINED_GLASS:15)
B(4,29,9,STAINED_GLASS:15)
B(5,29,9,SEA_LANTERN)
B(6,29,9,SEA_LANTERN)
B(7,29,9,STAINED_GLASS:11)
B(8,29,9,STAINED_GLASS:11)
B(9,29,9,STAINED_GLASS:15)
B(10,29,9,STAINED_GLASS:15)
B(4,29,10,STAINED_GLASS:15)
B(5,29,10,STAINED_GLASS:15)
B(6,29,10,STAINED_GLASS:11)
B(7,29,10,SEA_LANTERN)
B(8,29,10,STAINED_GLASS:15)
B(9,29,10,STAINED_GLASS:15)
B(10,29,10,STAINED_GLASS:15)
B(4,29,11,STAINED_GLASS:15)
B(5,29,11,STAINED_GLASS:15)
B(6,29,11,STAINED_GLASS:11)
B(7,29,11,STAINED_GLASS:11)
B(8,29,11,STAINED_GLASS:11)
B(5,29,12,STAINED_GLASS:15)
B(6,29,12,STAINED_GLASS:11)
B(7,29,12,STAINED_GLASS:11)
B(6,29,13,STAINED_GLASS:11)
B(5,30,4,STAINED_GLASS:11)
B(6,30,4,STAINED_GLASS:11)
B(3,30,5,STAINED_GLASS:11)
B(4,30,5,STAINED_GLASS:11)
B(5,30,5,STAINED_GLASS:11)
B(6,30,5,STAINED_GLASS:15)
B(2,30,6,STAINED_GLASS:15)
B(3,30,6,STAINED_GLASS:15)
B(4,30,6,STAINED_GLASS:11)
B(5,30,6,STAINED_GLASS:15)
B(6,30,6,STAINED_GLASS:15)
B(7,30,6,STAINED_GLASS:15)
B(2,30,7,STAINED_GLASS:15)
B(3,30,7,STAINED_GLASS:15)
B(4,30,7,STAINED_GLASS:15)
B(5,30,7,SEA_LANTERN)
B(6,30,7,STAINED_GLASS:11)
B(7,30,7,STAINED_GLASS:11)
B(8,30,7,STAINED_GLASS:15)
B(2,30,8,STAINED_GLASS:15)
B(3,30,8,STAINED_GLASS:15)
B(4,30,8,STAINED_GLASS:11)
B(5,30,8,SEA_LANTERN)
B(6,30,8,SEA_LANTERN)
B(7,30,8,SEA_LANTERN)
B(8,30,8,STAINED_GLASS:15)
B(9,30,8,STAINED_GLASS:15)
B(3,30,9,STAINED_GLASS:15)
B(4,30,9,STAINED_GLASS:11)
B(5,30,9,SEA_LANTERN)
B(6,30,9,SEA_LANTERN)
B(7,30,9,STAINED_GLASS:11)
B(8,30,9,STAINED_GLASS:15)
B(9,30,9,STAINED_GLASS:15)
B(10,30,9,STAINED_GLASS:15)
B(4,30,10,STAINED_GLASS:15)
B(5,30,10,STAINED_GLASS:15)
B(6,30,10,STAINED_GLASS:11)
B(7,30,10,STAINED_GLASS:11)
B(8,30,10,STAINED_GLASS:15)
B(9,30,10,STAINED_GLASS:15)
B(4,30,11,STAINED_GLASS:11)
B(5,30,11,STAINED_GLASS:11)
B(6,30,11,STAINED_GLASS:15)
B(7,30,11,STAINED_GLASS:11)
B(5,30,12,STAINED_GLASS:11)
B(6,30,12,STAINED_GLASS:11)
B(6,31,3,STAINED_GLASS:11)
B(5,31,4,STAINED_GLASS:11)
B(6,31,4,STAINED_GLASS:11)
B(3,31,5,STAINED_GLASS:15)
B(4,31,5,STAINED_GLASS:11)
B(5,31,5,STAINED_GLASS:15)
B(6,31,5,STAINED_GLASS:11)
B(2,31,6,STAINED_GLASS:15)
B(3,31,6,STAINED_GLASS:15)
B(4,31,6,STAINED_GLASS:11)
B(5,31,6,STAINED_GLASS:11)
B(6,31,6,STAINED_GLASS:11)
B(7,31,6,STAINED_GLASS:15)
B(1,31,7,STAINED_GLASS:15)
B(2,31,7,STAINED_GLASS:15)
B(3,31,7,STAINED_GLASS:15)
B(4,31,7,STAINED_GLASS:11)
B(5,31,7,SEA_LANTERN)
B(6,31,7,SEA_LANTERN)
B(7,31,7,STAINED_GLASS:11)
B(8,31,7,STAINED_GLASS:15)
B(2,31,8,STAINED_GLASS:15)
B(3,31,8,STAINED_GLASS:15)
B(4,31,8,SEA_LANTERN)
B(5,31,8,SEA_LANTERN)
B(6,31,8,SEA_LANTERN)
B(7,31,8,STAINED_GLASS:11)
B(8,31,8,STAINED_GLASS:15)
B(9,31,8,STAINED_GLASS:15)
B(3,31,9,STAINED_GLASS:15)
B(4,31,9,STAINED_GLASS:11)
B(5,31,9,STAINED_GLASS:11)
B(6,31,9,SEA_LANTERN)
B(7,31,9,STAINED_GLASS:11)
B(8,31,9,STAINED_GLASS:15)
B(9,31,9,STAINED_GLASS:15)
B(4,31,10,STAINED_GLASS:15)
B(5,31,10,STAINED_GLASS:11)
B(6,31,10,STAINED_GLASS:11)
B(7,31,10,STAINED_GLASS:11)
B(8,31,10,STAINED_GLASS:15)
B(9,31,10,STAINED_GLASS:15)
B(4,31,11,STAINED_GLASS:11)
B(5,31,11,STAINED_GLASS:11)
B(6,31,11,STAINED_GLASS:11)
B(7,31,11,STAINED_GLASS:15)
B(6,31,12,STAINED_GLASS:11)
B(5,32,3,STAINED_GLASS:11)
B(6,32,3,STAINED_GLASS:11)
B(4,32,4,STAINED_GLASS:15)
B(5,32,4,STAINED_GLASS:11)
B(6,32,4,STAINED_GLASS:11)
B(2,32,5,STAINED_GLASS:15)
B(3,32,5,STAINED_GLASS:15)
B(4,32,5,STAINED_GLASS:15)
B(5,32,5,STAINED_GLASS:11)
B(6,32,5,STAINED_GLASS:11)
B(1,32,6,STAINED_GLASS:15)
B(2,32,6,STAINED_GLASS:15)
B(3,32,6,STAINED_GLASS:15)
B(4,32,6,SEA_LANTERN)
B(5,32,6,STAINED_GLASS:11)
B(6,32,6,STAINED_GLASS:11)
B(7,32,6,STAINED_GLASS:11)
B(1,32,7,STAINED_GLASS:15)
B(2,32,7,STAINED_GLASS:15)
B(3,32,7,STAINED_GLASS:11)
B(4,32,7,STAINED_GLASS:11)
B(5,32,7,SEA_LANTERN)
B(6,32,7,SEA_LANTERN)
B(7,32,7,STAINED_GLASS:15)
B(8,32,7,STAINED_GLASS:15)
B(2,32,8,STAINED_GLASS:15)
B(3,32,8,STAINED_GLASS:11)
B(4,32,8,SEA_LANTERN)
B(5,32,8,STAINED_GLASS:11)
B(6,32,8,STAINED_GLASS:11)
B(7,32,8,STAINED_GLASS:11)
B(8,32,8,STAINED_GLASS:15)
B(9,32,8,STAINED_GLASS:15)
B(3,32,9,STAINED_GLASS:11)
B(4,32,9,STAINED_GLASS:11)
B(5,32,9,STAINED_GLASS:11)
B(6,32,9,SEA_LANTERN)
B(7,32,9,STAINED_GLASS:15)
B(8,32,9,STAINED_GLASS:15)
B(9,32,9,STAINED_GLASS:15)
B(4,32,10,STAINED_GLASS:15)
B(5,32,10,STAINED_GLASS:15)
B(6,32,10,STAINED_GLASS:15)
B(7,32,10,STAINED_GLASS:15)
B(8,32,10,STAINED_GLASS:15)
B(4,32,11,STAINED_GLASS:11)
B(5,32,11,STAINED_GLASS:11)
B(6,32,11,STAINED_GLASS:15)
B(4,33,3,STAINED_GLASS:15)
B(5,33,3,STAINED_GLASS:11)
B(6,33,3,STAINED_GLASS:11)
B(3,33,4,STAINED_GLASS:15)
B(4,33,4,STAINED_GLASS:15)
B(5,33,4,STAINED_GLASS:15)
B(6,33,4,STAINED_GLASS:11)
B(1,33,5,STAINED_GLASS:15)
B(2,33,5,STAINED_GLASS:15)
B(3,33,5,STAINED_GLASS:11)
B(4,33,5,STAINED_GLASS:15)
B(5,33,5,STAINED_GLASS:11)
B(6,33,5,STAINED_GLASS:11)
B(1,33,6,STAINED_GLASS:15)
B(2,33,6,STAINED_GLASS:15)
B(3,33,6,STAINED_GLASS:15)
B(4,33,6,SEA_LANTERN)
B(5,33,6,SEA_LANTERN)
B(6,33,6,STAINED_GLASS:11)
B(7,33,6,STAINED_GLASS:15)
B(1,33,7,STAINED_GLASS:15)
B(2,33,7,STAINED_GLASS:15)
B(3,33,7,STAINED_GLASS:11)
B(4,33,7,SEA_LANTERN)
B(5,33,7,SEA_LANTERN)
B(6,33,7,SEA_LANTERN)
B(7,33,7,STAINED_GLASS:15)
B(8,33,7,STAINED_GLASS:15)
B(2,33,8,STAINED_GLASS:11)
B(3,33,8,STAINED_GLASS:11)
B(4,33,8,SEA_LANTERN)
B(5,33,8,STAINED_GLASS:11)
B(6,33,8,STAINED_GLASS:11)
B(7,33,8,STAINED_GLASS:15)
B(8,33,8,STAINED_GLASS:15)
B(9,33,8,STAINED_GLASS:15)
B(3,33,9,STAINED_GLASS:11)
B(4,33,9,STAINED_GLASS:11)
B(5,33,9,STAINED_GLASS:15)
B(6,33,9,STAINED_GLASS:11)
B(7,33,9,STAINED_GLASS:15)
B(8,33,9,STAINED_GLASS:15)
B(4,33,10,STAINED_GLASS:11)
B(5,33,10,STAINED_GLASS:15)
B(6,33,10,STAINED_GLASS:15)
B(7,33,10,STAINED_GLASS:15)
B(4,33,11,STAINED_GLASS:15)
B(5,34,2,STAINED_GLASS:15)
B(4,34,3,STAINED_GLASS:15)
B(5,34,3,STAINED_GLASS:15)
B(6,34,3,STAINED_GLASS:11)
B(3,34,4,STAINED_GLASS:15)
B(4,34,4,STAINED_GLASS:15)
B(5,34,4,STAINED_GLASS:15)
B(6,34,4,STAINED_GLASS:11)
B(0,34,5,STAINED_GLASS:15)
B(1,34,5,STAINED_GLASS:15)
B(2,34,5,STAINED_GLASS:15)
B(3,34,5,STAINED_GLASS:11)
B(4,34,5,STAINED_GLASS:11)
B(5,34,5,SEA_LANTERN)
B(6,34,5,STAINED_GLASS:11)
B(1,34,6,STAINED_GLASS:15)
B(2,34,6,STAINED_GLASS:15)
B(3,34,6,STAINED_GLASS:11)
B(4,34,6,SEA_LANTERN)
B(5,34,6,SEA_LANTERN)
B(6,34,6,STAINED_GLASS:11)
B(7,34,6,STAINED_GLASS:11)
B(1,34,7,STAINED_GLASS:15)
B(2,34,7,STAINED_GLASS:15)
B(3,34,7,SEA_LANTERN)
B(4,34,7,SEA_LANTERN)
B(5,34,7,SEA_LANTERN)
B(6,34,7,STAINED_GLASS:11)
B(7,34,7,STAINED_GLASS:15)
B(8,34,7,STAINED_GLASS:15)
B(2,34,8,STAINED_GLASS:15)
B(3,34,8,STAINED_GLASS:11)
B(4,34,8,STAINED_GLASS:11)
B(5,34,8,STAINED_GLASS:11)
B(6,34,8,STAINED_GLASS:11)
B(7,34,8,STAINED_GLASS:15)
B(8,34,8,STAINED_GLASS:15)
B(3,34,9,STAINED_GLASS:11)
B(4,34,9,STAINED_GLASS:11)
B(5,34,9,STAINED_GLASS:15)
B(6,34,9,STAINED_GLASS:11)
B(7,34,9,STAINED_GLASS:15)
B(8,34,9,STAINED_GLASS:15)
B(4,34,10,STAINED_GLASS:11)
B(5,34,10,STAINED_GLASS:11)
B(6,34,10,STAINED_GLASS:15)
B(7,34,10,STAINED_GLASS:15)
B(4,35,2,STAINED_GLASS:15)
B(5,35,2,STAINED_GLASS:15)
B(3,35,3,STAINED_GLASS:15)
B(4,35,3,STAINED_GLASS:15)
B(5,35,3,STAINED_GLASS:15)
B(6,35,3,STAINED_GLASS:15)
B(2,35,4,STAINED_GLASS:15)
B(3,35,4,STAINED_GLASS:15)
B(4,35,4,STAINED_GLASS:15)
B(5,35,4,STAINED_GLASS:11)
B(6,35,4,STAINED_GLASS:11)
B(0,35,5,STAINED_GLASS:15)
B(1,35,5,STAINED_GLASS:15)
B(2,35,5,STAINED_GLASS:15)
B(3,35,5,SEA_LANTERN)
B(4,35,5,STAINED_GLASS:11)
B(5,35,5,SEA_LANTERN)
B(6,35,5,STAINED_GLASS:11)
B(1,35,6,STAINED_GLASS:15)
B(2,35,6,STAINED_GLASS:11)
B(3,35,6,STAINED_GLASS:11)
B(4,35,6,SEA_LANTERN)
B(5,35,6,STAINED_GLASS:11)
B(6,35,6,STAINED_GLASS:11)
B(7,35,6,STAINED_GLASS:15)
B(1,35,7,STAINED_GLASS:15)
B(2,35,7,STAINED_GLASS:15)
B(3,35,7,SEA_LANTERN)
B(4,35,7,STAINED_GLASS:11)
B(5,35,7,SEA_LANTERN)
B(6,35,7,STAINED_GLASS:11)
B(7,35,7,STAINED_GLASS:15)
B(8,35,7,STAINED_GLASS:15)
B(2,35,8,STAINED_GLASS:15)
B(3,35,8,STAINED_GLASS:11)
B(4,35,8,STAINED_GLASS:11)
B(5,35,8,STAINED_GLASS:15)
B(6,35,8,STAINED_GLASS:15)
B(7,35,8,STAINED_GLASS:15)
B(8,35,8,STAINED_GLASS:15)
B(3,35,9,STAINED_GLASS:11)
B(4,35,9,STAINED_GLASS:11)
B(5,35,9,STAINED_GLASS:11)
B(6,35,9,STAINED_GLASS:15)
B(7,35,9,STAINED_GLASS:15)
B(4,35,10,STAINED_GLASS:11)
B(5,35,10,STAINED_GLASS:11)
B(6,35,10,STAINED_GLASS:15)
B(3,36,2,STAINED_GLASS:15)
B(4,36,2,STAINED_GLASS:15)
B(5,36,2,STAINED_GLASS:15)
B(2,36,3,STAINED_GLASS:15)
B(3,36,3,STAINED_GLASS:15)
B(4,36,3,STAINED_GLASS:15)
B(5,36,3,STAINED_GLASS:15)
B(6,36,3,STAINED_GLASS:15)
B(1,36,4,STAINED_GLASS:15)
B(2,36,4,STAINED_GLASS:15)
B(3,36,4,STAINED_GLASS:11)
B(4,36,4,STAINED_GLASS:15)
B(5,36,4,STAINED_GLASS:11)
B(6,36,4,STAINED_GLASS:11)
B(0,36,5,STAINED_GLASS:15)
B(1,36,5,STAINED_GLASS:15)
B(2,36,5,STAINED_GLASS:15)
B(3,36,5,SEA_LANTERN)
B(4,36,5,SEA_LANTERN)
B(5,36,5,SEA_LANTERN)
B(6,36,5,STAINED_GLASS:11)
B(1,36,6,STAINED_GLASS:15)
B(2,36,6,STAINED_GLASS:11)
B(3,36,6,SEA_LANTERN)
B(4,36,6,SEA_LANTERN)
B(5,36,6,STAINED_GLASS:11)
B(6,36,6,STAINED_GLASS:11)
B(7,36,6,STAINED_GLASS:15)
B(1,36,7,STAINED_GLASS:15)
B(2,36,7,STAINED_GLASS:11)
B(3,36,7,SEA_LANTERN)
B(4,36,7,STAINED_GLASS:11)
B(5,36,7,STAINED_GLASS:11)
B(6,36,7,STAINED_GLASS:15)
B(7,36,7,STAINED_GLASS:15)
B(8,36,7,STAINED_GLASS:15)
B(2,36,8,STAINED_GLASS:11)
B(3,36,8,STAINED_GLASS:11)
B(4,36,8,STAINED_GLASS:11)
B(5,36,8,STAINED_GLASS:15)
B(6,36,8,STAINED_GLASS:15)
B(7,36,8,STAINED_GLASS:15)
B(3,36,9,STAINED_GLASS:11)
B(4,36,9,STAINED_GLASS:11)
B(5,36,9,STAINED_GLASS:15)
B(6,36,9,STAINED_GLASS:15)
B(4,36,10,STAINED_GLASS:11)
B(4,37,1,STAINED_GLASS:15)
B(3,37,2,STAINED_GLASS:15)
B(4,37,2,STAINED_GLASS:15)
B(5,37,2,STAINED_GLASS:15)
B(2,37,3,STAINED_GLASS:15)
B(3,37,3,STAINED_GLASS:15)
B(4,37,3,STAINED_GLASS:15)
B(5,37,3,STAINED_GLASS:15)
B(6,37,3,STAINED_GLASS:11)
B(0,37,4,STAINED_GLASS:15)
B(1,37,4,STAINED_GLASS:15)
B(2,37,4,STAINED_GLASS:15)
B(3,37,4,STAINED_GLASS:11)
B(4,37,4,STAINED_GLASS:11)
B(5,37,4,SEA_LANTERN)
B(6,37,4,STAINED_GLASS:11)
B(0,37,5,STAINED_GLASS:15)
B(1,37,5,STAINED_GLASS:15)
B(2,37,5,STAINED_GLASS:11)
B(3,37,5,SEA_LANTERN)
B(4,37,5,SEA_LANTERN)
B(5,37,5,STAINED_GLASS:11)
B(6,37,5,STAINED_GLASS:11)
B(1,37,6,STAINED_GLASS:15)
B(2,37,6,SEA_LANTERN)
B(3,37,6,SEA_LANTERN)
B(4,37,6,SEA_LANTERN)
B(5,37,6,STAINED_GLASS:11)
B(6,37,6,STAINED_GLASS:11)
B(7,37,6,STAINED_GLASS:11)
B(1,37,7,STAINED_GLASS:15)
B(2,37,7,STAINED_GLASS:11)
B(3,37,7,STAINED_GLASS:11)
B(4,37,7,STAINED_GLASS:11)
B(5,37,7,STAINED_GLASS:11)
B(6,37,7,STAINED_GLASS:15)
B(7,37,7,STAINED_GLASS:15)
B(2,37,8,STAINED_GLASS:11)
B(3,37,8,STAINED_GLASS:11)
B(4,37,8,STAINED_GLASS:11)
B(5,37,8,STAINED_GLASS:15)
B(6,37,8,STAINED_GLASS:15)
B(7,37,8,STAINED_GLASS:15)
B(3,37,9,STAINED_GLASS:11)
B(4,37,9,STAINED_GLASS:11)
B(5,37,9,STAINED_GLASS:15)
B(6,37,9,STAINED_GLASS:15)
B(3,38,1,STAINED_GLASS:15)
B(4,38,1,STAINED_GLASS:15)
B(2,38,2,STAINED_GLASS:15)
B(3,38,2,STAINED_GLASS:15)
B(4,38,2,STAINED_GLASS:15)
B(5,38,2,STAINED_GLASS:15)
B(0,38,3,STAINED_GLASS:15)
B(1,38,3,STAINED_GLASS:15)
B(2,38,3,STAINED_GLASS:15)
B(3,38,3,STAINED_GLASS:15)
B(4,38,3,STAINED_GLASS:11)
B(5,38,3,STAINED_GLASS:15)
B(6,38,3,STAINED_GLASS:15)
B(0,38,4,STAINED_GLASS:15)
B(1,38,4,STAINED_GLASS:15)
B(2,38,4,STAINED_GLASS:15)
B(3,38,4,SEA_LANTERN)
B(4,38,4,STAINED_GLASS:11)
B(5,38,4,SEA_LANTERN)
B(6,38,4,STAINED_GLASS:11)
B(0,38,5,STAINED_GLASS:11)
B(1,38,5,STAINED_GLASS:11)
B(2,38,5,STAINED_GLASS:11)
B(3,38,5,SEA_LANTERN)
B(4,38,5,STAINED_GLASS:11)
B(5,38,5,STAINED_GLASS:11)
B(6,38,5,STAINED_GLASS:11)
B(1,38,6,STAINED_GLASS:11)
B(2,38,6,SEA_LANTERN)
B(3,38,6,STAINED_GLASS:11)
B(4,38,6,SEA_LANTERN)
B(5,38,6,STAINED_GLASS:15)
B(6,38,6,STAINED_GLASS:11)
B(7,38,6,STAINED_GLASS:15)
B(1,38,7,STAINED_GLASS:11)
B(2,38,7,STAINED_GLASS:11)
B(3,38,7,STAINED_GLASS:11)
B(4,38,7,STAINED_GLASS:15)
B(5,38,7,STAINED_GLASS:15)
B(6,38,7,STAINED_GLASS:15)
B(7,38,7,STAINED_GLASS:15)
B(2,38,8,STAINED_GLASS:11)
B(3,38,8,STAINED_GLASS:11)
B(4,38,8,STAINED_GLASS:11)
B(5,38,8,STAINED_GLASS:15)
B(6,38,8,STAINED_GLASS:15)
B(3,38,9,STAINED_GLASS:11)
B(4,38,9,STAINED_GLASS:15)
B(3,39,1,STAINED_GLASS:15)
B(4,39,1,STAINED_GLASS:15)
B(2,39,2,STAINED_GLASS:15)
B(3,39,2,STAINED_GLASS:15)
B(4,39,2,STAINED_GLASS:15)
B(5,39,2,STAINED_GLASS:15)
B(0,39,3,STAINED_GLASS:15)
B(1,39,3,STAINED_GLASS:15)
B(2,39,3,STAINED_GLASS:11)
B(3,39,3,STAINED_GLASS:15)
B(4,39,3,STAINED_GLASS:11)
B(5,39,3,STAINED_GLASS:11)
B(6,39,3,STAINED_GLASS:11)
B(0,39,4,STAINED_GLASS:11)
B(1,39,4,STAINED_GLASS:15)
B(2,39,4,STAINED_GLASS:15)
B(3,39,4,SEA_LANTERN)
B(4,39,4,SEA_LANTERN)
B(5,39,4,SEA_LANTERN)
B(6,39,4,STAINED_GLASS:11)
B(0,39,5,STAINED_GLASS:11)
B(1,39,5,STAINED_GLASS:11)
B(2,39,5,SEA_LANTERN)
B(3,39,5,SEA_LANTERN)
B(4,39,5,STAINED_GLASS:11)
B(5,39,5,STAINED_GLASS:15)
B(6,39,5,STAINED_GLASS:15)
B(1,39,6,STAINED_GLASS:11)
B(2,39,6,SEA_LANTERN)
B(3,39,6,STAINED_GLASS:11)
B(4,39,6,STAINED_GLASS:11)
B(5,39,6,STAINED_GLASS:15)
B(6,39,6,STAINED_GLASS:15)
B(7,39,6,STAINED_GLASS:15)
B(1,39,7,STAINED_GLASS:11)
B(2,39,7,STAINED_GLASS:11)
B(3,39,7,STAINED_GLASS:15)
B(4,39,7,STAINED_GLASS:15)
B(5,39,7,STAINED_GLASS:15)
B(6,39,7,STAINED_GLASS:15)
B(2,39,8,STAINED_GLASS:11)
B(3,39,8,STAINED_GLASS:11)
B(4,39,8,STAINED_GLASS:15)
B(3,39,9,STAINED_GLASS:15)
B(3,40,1,STAINED_GLASS:15)
B(2,40,2,STAINED_GLASS:15)
B(3,40,2,STAINED_GLASS:15)
B(4,40,2,STAINED_GLASS:15)
B(5,40,2,STAINED_GLASS:11)
B(0,40,3,STAINED_GLASS:15)
B(1,40,3,STAINED_GLASS:15)
B(2,40,3,STAINED_GLASS:11)
B(3,40,3,STAINED_GLASS:11)
B(4,40,3,SEA_LANTERN)
B(5,40,3,STAINED_GLASS:11)
B(6,40,3,STAINED_GLASS:11)
B(1,40,4,STAINED_GLASS:15)
B(2,40,4,STAINED_GLASS:11)
B(3,40,4,SEA_LANTERN)
B(4,40,4,SEA_LANTERN)
B(5,40,4,STAINED_GLASS:11)
B(6,40,4,STAINED_GLASS:11)
B(0,40,5,STAINED_GLASS:11)
B(1,40,5,SEA_LANTERN)
B(2,40,5,SEA_LANTERN)
B(3,40,5,SEA_LANTERN)
B(4,40,5,STAINED_GLASS:11)
B(5,40,5,STAINED_GLASS:15)
B(6,40,5,STAINED_GLASS:15)
B(1,40,6,STAINED_GLASS:11)
B(2,40,6,STAINED_GLASS:11)
B(3,40,6,STAINED_GLASS:11)
B(4,40,6,STAINED_GLASS:11)
B(5,40,6,STAINED_GLASS:15)
B(6,40,6,STAINED_GLASS:15)
B(1,40,7,STAINED_GLASS:11)
B(2,40,7,STAINED_GLASS:15)
B(3,40,7,STAINED_GLASS:15)
B(4,40,7,STAINED_GLASS:15)
B(5,40,7,STAINED_GLASS:15)
B(6,40,7,STAINED_GLASS:15)
B(2,40,8,STAINED_GLASS:15)
B(3,40,8,STAINED_GLASS:15)
B(4,40,8,STAINED_GLASS:15)
B(2,41,1,STAINED_GLASS:15)
B(3,41,1,STAINED_GLASS:15)
B(0,41,2,STAINED_GLASS:15)
B(2,41,2,STAINED_GLASS:15)
B(3,41,2,STAINED_GLASS:15)
B(4,41,2,STAINED_GLASS:11)
B(0,41,3,STAINED_GLASS:11)
B(1,41,3,STAINED_GLASS:11)
B(2,41,3,STAINED_GLASS:11)
B(3,41,3,STAINED_GLASS:15)
B(4,41,3,SEA_LANTERN)
B(5,41,3,STAINED_GLASS:11)
B(6,41,3,STAINED_GLASS:11)
B(1,41,4,STAINED_GLASS:11)
B(2,41,4,STAINED_GLASS:11)
B(3,41,4,SEA_LANTERN)
B(4,41,4,STAINED_GLASS:11)
B(5,41,4,STAINED_GLASS:11)
B(6,41,4,STAINED_GLASS:11)
B(1,41,5,SEA_LANTERN)
B(2,41,5,STAINED_GLASS:11)
B(3,41,5,SEA_LANTERN)
B(4,41,5,STAINED_GLASS:15)
B(5,41,5,STAINED_GLASS:15)
B(6,41,5,STAINED_GLASS:11)
B(1,41,6,STAINED_GLASS:11)
B(2,41,6,STAINED_GLASS:11)
B(3,41,6,STAINED_GLASS:15)
B(4,41,6,STAINED_GLASS:11)
B(5,41,6,STAINED_GLASS:15)
B(6,41,6,STAINED_GLASS:11)
B(1,41,7,STAINED_GLASS:15)
B(2,41,7,STAINED_GLASS:15)
B(3,41,7,STAINED_GLASS:15)
B(4,41,7,STAINED_GLASS:15)
B(2,41,8,STAINED_GLASS:15)
B(3,41,8,STAINED_GLASS:15)
B(2,42,1,STAINED_GLASS:15)
B(0,42,2,STAINED_GLASS:11)
B(1,42,2,STAINED_GLASS:11)
B(2,42,2,STAINED_GLASS:15)
B(3,42,2,STAINED_GLASS:15)
B(4,42,2,STAINED_GLASS:15)
B(1,42,3,STAINED_GLASS:11)
B(2,42,3,STAINED_GLASS:11)
B(3,42,3,STAINED_GLASS:11)
B(4,42,3,STAINED_GLASS:11)
B(5,42,3,STAINED_GLASS:11)
B(1,42,4,STAINED_GLASS:11)
B(2,42,4,STAINED_GLASS:11)
B(3,42,4,SEA_LANTERN)
B(4,42,4,STAINED_GLASS:15)
B(5,42,4,STAINED_GLASS:11)
B(6,42,4,STAINED_GLASS:11)
B(1,42,5,STAINED_GLASS:11)
B(2,42,5,STAINED_GLASS:15)
B(3,42,5,STAINED_GLASS:15)
B(4,42,5,STAINED_GLASS:15)
B(5,42,5,STAINED_GLASS:11)
B(1,42,6,STAINED_GLASS:15)
B(2,42,6,STAINED_GLASS:15)
B(3,42,6,STAINED_GLASS:15)
B(4,42,6,STAINED_GLASS:15)
B(2,42,7,STAINED_GLASS:15)
B(3,42,7,STAINED_GLASS:15)
B(2,42,8,STAINED_GLASS:15)
B(0,43,1,STAINED_GLASS:11)
B(1,43,1,STAINED_GLASS:11)
B(2,43,1,STAINED_GLASS:15)
B(0,43,2,STAINED_GLASS:11)
B(1,43,2,STAINED_GLASS:11)
B(2,43,2,STAINED_GLASS:15)
B(3,43,2,STAINED_GLASS:15)
B(1,43,3,STAINED_GLASS:11)
B(2,43,3,STAINED_GLASS:15)
B(3,43,3,STAINED_GLASS:11)
B(4,43,3,STAINED_GLASS:15)
B(5,43,3,STAINED_GLASS:15)
B(1,43,4,STAINED_GLASS:11)
B(2,43,4,STAINED_GLASS:11)
B(3,43,4,SEA_LANTERN)
B(4,43,4,STAINED_GLASS:15)
B(5,43,4,STAINED_GLASS:11)
B(6,43,4,STAINED_GLASS:11)
B(1,43,5,STAINED_GLASS:15)
B(2,43,5,STAINED_GLASS:15)
B(3,43,5,STAINED_GLASS:11)
B(4,43,5,STAINED_GLASS:11)
B(5,43,5,STAINED_GLASS:11)
B(1,43,6,STAINED_GLASS:15)
B(2,43,6,STAINED_GLASS:15)
B(3,43,6,STAINED_GLASS:15)
B(4,43,6,STAINED_GLASS:11)
B(2,43,7,STAINED_GLASS:15)
B(3,43,7,STAINED_GLASS:15)
B(0,44,1,STAINED_GLASS:11)
B(1,44,1,STAINED_GLASS:15)
B(1,44,2,STAINED_GLASS:11)
B(2,44,2,STAINED_GLASS:15)
B(3,44,2,STAINED_GLASS:15)
B(1,44,3,STAINED_GLASS:15)
B(2,44,3,STAINED_GLASS:11)
B(3,44,3,STAINED_GLASS:15)
B(4,44,3,STAINED_GLASS:15)
B(1,44,4,STAINED_GLASS:15)
B(2,44,4,STAINED_GLASS:11)
B(3,44,4,STAINED_GLASS:15)
B(4,44,4,STAINED_GLASS:11)
B(5,44,4,STAINED_GLASS:11)
B(6,44,4,STAINED_GLASS:11)
B(1,44,5,STAINED_GLASS:11)
B(2,44,5,STAINED_GLASS:11)
B(3,44,5,STAINED_GLASS:11)
B(4,44,5,STAINED_GLASS:11)
B(2,44,6,STAINED_GLASS:15)
B(3,44,6,STAINED_GLASS:11)
B(2,44,7,STAINED_GLASS:15)
B(0,45,1,STAINED_GLASS:15)
B(1,45,1,STAINED_GLASS:15)
B(1,45,2,STAINED_GLASS:15)
B(2,45,2,STAINED_GLASS:15)
B(1,45,3,STAINED_GLASS:15)
B(2,45,3,STAINED_GLASS:15)
B(3,45,3,STAINED_GLASS:15)
B(4,45,3,STAINED_GLASS:15)
B(2,45,4,STAINED_GLASS:11)
B(3,45,4,STAINED_GLASS:11)
B(4,45,4,STAINED_GLASS:11)
B(5,45,4,STAINED_GLASS:11)
B(1,45,5,STAINED_GLASS:11)
B(2,45,5,STAINED_GLASS:11)
B(3,45,5,STAINED_GLASS:11)
B(2,45,6,STAINED_GLASS:11)
B(0,46,1,STAINED_GLASS:15)
B(1,46,1,STAINED_GLASS:15)
B(1,46,2,STAINED_GLASS:15)
B(2,46,2,STAINED_GLASS:15)
B(1,46,3,STAINED_GLASS:15)
B(2,46,3,STAINED_GLASS:11)
B(3,46,3,STAINED_GLASS:15)
B(2,46,4,STAINED_GLASS:11)
B(3,46,4,STAINED_GLASS:11)
B(4,46,4,STAINED_GLASS:11)
B(5,46,4,STAINED_GLASS:15)
B(2,46,5,STAINED_GLASS:11)
B(3,46,5,STAINED_GLASS:11)
B(2,46,6,STAINED_GLASS:11)
B(0,47,1,STAINED_GLASS:15)
B(1,47,1,STAINED_GLASS:15)
B(1,47,2,STAINED_GLASS:11)
B(2,47,2,STAINED_GLASS:15)
B(1,47,3,STAINED_GLASS:11)
B(2,47,3,STAINED_GLASS:11)
B(3,47,3,STAINED_GLASS:11)
B(2,47,4,STAINED_GLASS:11)
B(3,47,4,STAINED_GLASS:11)
B(4,47,4,STAINED_GLASS:15)
B(2,47,5,STAINED_GLASS:11)
B(0,48,1,STAINED_GLASS:11)
B(1,48,1,STAINED_GLASS:15)
B(1,48,2,STAINED_GLASS:11)
B(2,48,2,STAINED_GLASS:11)
B(1,48,3,STAINED_GLASS:11)
B(2,48,3,STAINED_GLASS:11)
B(3,48,3,STAINED_GLASS:15)
B(2,48,4,STAINED_GLASS:11)
B(3,48,4,STAINED_GLASS:11)
B(4,48,4,STAINED_GLASS:15)
B(2,48,5,STAINED_GLASS:15)
B(1,49,2,STAINED_GLASS:11)
B(2,49,2,STAINED_GLASS:11)
B(1,49,3,STAINED_GLASS:11)
B(2,49,3,STAINED_GLASS:11)
B(3,49,3,STAINED_GLASS:11)
B(2,49,4,STAINED_GLASS:11)
B(3,49,4,STAINED_GLASS:15)
B(1,50,2,STAINED_GLASS:11)
B(2,50,3,STAINED_GLASS:11)
B(3,50,3,STAINED_GLASS:11)
B(2,50,4,STAINED_GLASS:11)
B(1,51,2,STAINED_GLASS:11)
B(2,51,3,STAINED_GLASS:11)
B(1,52,2,STAINED_GLASS:11)

