#######################################################################
# +-----------------------------------------------------------------+ #
# |                            BO3 object                           | #
# +-----------------------------------------------------------------+ #
#######################################################################

Author: Bo3 BulkEdit

Description: Converted Schematic - Modified by Bo3BulkEdit

Version: 3

SettingsMode: WriteDisable

#######################################################################
# +-----------------------------------------------------------------+ #
# |                          Main settings                          | #
# +-----------------------------------------------------------------+ #
#######################################################################



Frequency: 0


SpawnHeight: randomY





##############################
# Height Limits for the BO3. #
##############################

MinHeight: 0
MaxHeight: 256

#######################################################################
# +-----------------------------------------------------------------+ #
# |                      Source block settings                      | #
# +-----------------------------------------------------------------+ #
#######################################################################

CanOverride: true
MaxPercentageOutsideSourceBlock: 100
OutsideSourceBlock: placeAnyway

#######################################################################
# +-----------------------------------------------------------------+ #
# |                               OTG+                              | #
# +-----------------------------------------------------------------+ #
#######################################################################

#######################################################################
# +-----------------------------------------------------------------+ #
# |                              Blocks                             | #
# +-----------------------------------------------------------------+ #
#######################################################################

B(0,750,0,AIR)
B(15,750,15,AIR)
B(5,-3,11,STAINED_GLASS:15)
B(5,-3,12,STAINED_GLASS:15)
B(5,-3,13,STAINED_GLASS:15)
B(4,-2,7,STAINED_GLASS:15)
B(5,-2,7,STAINED_GLASS:15)
B(4,-2,8,STAINED_GLASS:15)
B(5,-2,8,STAINED_GLASS:15)
B(4,-2,9,STAINED_GLASS:15)
B(5,-2,9,STAINED_GLASS:15)
B(6,-2,9,STAINED_GLASS:15)
B(4,-2,10,STAINED_GLASS:15)
B(5,-2,10,STAINED_GLASS:15)
B(6,-2,10,STAINED_GLASS:15)
B(4,-2,11,STAINED_GLASS:15)
B(5,-2,11,STAINED_GLASS:15)
B(6,-2,11,STAINED_GLASS:15)
B(5,-2,12,STAINED_GLASS:15)
B(5,-2,13,STAINED_GLASS:15)
B(5,-1,4,STAINED_GLASS:15)
B(3,-1,5,STAINED_GLASS:15)
B(4,-1,5,STAINED_GLASS:15)
B(5,-1,5,STAINED_GLASS:15)
B(3,-1,6,STAINED_GLASS:15)
B(4,-1,6,STAINED_GLASS:15)
B(5,-1,6,STAINED_GLASS:15)
B(6,-1,6,STAINED_GLASS:15)
B(7,-1,6,STAINED_GLASS:15)
B(3,-1,7,STAINED_GLASS:15)
B(4,-1,7,STAINED_GLASS:15)
B(5,-1,7,STAINED_GLASS:15)
B(6,-1,7,STAINED_GLASS:15)
B(7,-1,7,STAINED_GLASS:15)
B(4,-1,8,STAINED_GLASS:15)
B(5,-1,8,STAINED_GLASS:15)
B(6,-1,8,STAINED_GLASS:15)
B(4,-1,9,STAINED_GLASS:15)
B(5,-1,9,STAINED_GLASS:15)
B(6,-1,9,STAINED_GLASS:15)
B(4,-1,10,STAINED_GLASS:15)
B(5,-1,10,STAINED_GLASS:15)
B(6,-1,10,STAINED_GLASS:15)
B(4,-1,11,STAINED_GLASS:15)
B(5,-1,11,STAINED_GLASS:15)
B(6,-1,11,STAINED_GLASS:15)
B(5,-1,12,STAINED_GLASS:15)
B(4,0,2,STAINED_GLASS:15)
B(6,0,2,STAINED_GLASS:15)
B(7,0,2,STAINED_GLASS:15)
B(3,0,3,STAINED_GLASS:15)
B(4,0,3,STAINED_GLASS:15)
B(5,0,3,STAINED_GLASS:15)
B(6,0,3,STAINED_GLASS:15)
B(7,0,3,STAINED_GLASS:10)
B(3,0,4,STAINED_GLASS:15)
B(4,0,4,STAINED_GLASS:15)
B(5,0,4,STAINED_GLASS:15)
B(6,0,4,STAINED_GLASS:15)
B(7,0,4,STAINED_GLASS:10)
B(3,0,5,STAINED_GLASS:15)
B(4,0,5,STAINED_GLASS:15)
B(5,0,5,STAINED_GLASS:15)
B(6,0,5,STAINED_GLASS:15)
B(7,0,5,STAINED_GLASS:15)
B(3,0,6,STAINED_GLASS:15)
B(5,0,6,STAINED_GLASS:15)
B(6,0,6,STAINED_GLASS:15)
B(7,0,6,STAINED_GLASS:15)
B(3,0,7,STAINED_GLASS:15)
B(4,0,7,STAINED_GLASS:15)
B(5,0,7,STAINED_GLASS:15)
B(7,0,7,STAINED_GLASS:15)
B(4,0,8,STAINED_GLASS:15)
B(6,0,8,STAINED_GLASS:15)
B(7,0,8,STAINED_GLASS:15)
B(4,0,9,STAINED_GLASS:15)
B(6,0,9,STAINED_GLASS:15)
B(7,0,9,STAINED_GLASS:10)
B(4,0,10,STAINED_GLASS:15)
B(5,0,10,STAINED_GLASS:15)
B(6,0,10,STAINED_GLASS:15)
B(7,0,10,STAINED_GLASS:10)
B(5,0,11,STAINED_GLASS:15)
B(3,1,0,STAINED_GLASS:15)
B(5,1,0,STAINED_GLASS:15)
B(6,1,0,STAINED_GLASS:15)
B(3,1,1,STAINED_GLASS:15)
B(4,1,1,STAINED_GLASS:15)
B(5,1,1,STAINED_GLASS:15)
B(6,1,1,STAINED_GLASS:15)
B(7,1,1,STAINED_GLASS:15)
B(3,1,2,STAINED_GLASS:15)
B(4,1,2,STAINED_GLASS:15)
B(5,1,2,STAINED_GLASS:15)
B(6,1,2,STAINED_GLASS:15)
B(7,1,2,STAINED_GLASS:10)
B(3,1,3,STAINED_GLASS:15)
B(4,1,3,STAINED_GLASS:2)
B(5,1,3,STAINED_GLASS:15)
B(6,1,3,STAINED_GLASS:10)
B(7,1,3,STAINED_GLASS:10)
B(3,1,4,STAINED_GLASS:15)
B(4,1,4,STAINED_GLASS:2)
B(5,1,4,SEA_LANTERN)
B(6,1,4,STAINED_GLASS:2)
B(7,1,4,STAINED_GLASS:10)
B(3,1,5,STAINED_GLASS:15)
B(4,1,5,STAINED_GLASS:15)
B(5,1,5,SEA_LANTERN)
B(6,1,5,STAINED_GLASS:15)
B(7,1,5,STAINED_GLASS:10)
B(3,1,6,STAINED_GLASS:15)
B(4,1,6,STAINED_GLASS:15)
B(5,1,6,SEA_LANTERN)
B(6,1,6,STAINED_GLASS:15)
B(7,1,6,STAINED_GLASS:15)
B(5,1,7,STAINED_GLASS:15)
B(6,1,7,STAINED_GLASS:15)
B(7,1,7,STAINED_GLASS:15)
B(3,1,8,STAINED_GLASS:15)
B(4,1,8,STAINED_GLASS:15)
B(5,1,8,STAINED_GLASS:15)
B(6,1,8,STAINED_GLASS:15)
B(7,1,8,STAINED_GLASS:15)
B(4,1,9,STAINED_GLASS:15)
B(5,1,9,STAINED_GLASS:15)
B(6,1,9,STAINED_GLASS:15)
B(7,1,9,STAINED_GLASS:10)
B(4,1,10,STAINED_GLASS:15)
B(5,1,10,STAINED_GLASS:15)
B(6,1,10,STAINED_GLASS:15)
B(7,1,10,STAINED_GLASS:10)
B(3,2,0,STAINED_GLASS:15)
B(4,2,0,STAINED_GLASS:15)
B(5,2,0,STAINED_GLASS:15)
B(6,2,0,STAINED_GLASS:15)
B(3,2,1,STAINED_GLASS:15)
B(4,2,1,STAINED_GLASS:2)
B(5,2,1,STAINED_GLASS:2)
B(6,2,1,STAINED_GLASS:10)
B(7,2,1,STAINED_GLASS:10)
B(3,2,2,STAINED_GLASS:2)
B(4,2,2,STAINED_GLASS:2)
B(5,2,2,SEA_LANTERN)
B(6,2,2,STAINED_GLASS:2)
B(7,2,2,STAINED_GLASS:10)
B(3,2,3,STAINED_GLASS:15)
B(4,2,3,STAINED_GLASS:15)
B(5,2,3,SEA_LANTERN)
B(6,2,3,STAINED_GLASS:10)
B(7,2,3,STAINED_GLASS:10)
B(3,2,4,STAINED_GLASS:11)
B(4,2,4,SEA_LANTERN)
B(5,2,4,SEA_LANTERN)
B(6,2,4,STAINED_GLASS:15)
B(7,2,4,STAINED_GLASS:10)
B(3,2,5,STAINED_GLASS:11)
B(4,2,5,STAINED_GLASS:15)
B(5,2,5,SEA_LANTERN)
B(6,2,5,STAINED_GLASS:2)
B(7,2,5,STAINED_GLASS:10)
B(4,2,6,STAINED_GLASS:2)
B(5,2,6,STAINED_GLASS:15)
B(6,2,6,STAINED_GLASS:2)
B(7,2,6,STAINED_GLASS:10)
B(3,2,7,STAINED_GLASS:15)
B(4,2,7,STAINED_GLASS:2)
B(5,2,7,STAINED_GLASS:15)
B(6,2,7,STAINED_GLASS:2)
B(7,2,7,STAINED_GLASS:10)
B(3,2,8,STAINED_GLASS:15)
B(4,2,8,STAINED_GLASS:2)
B(5,2,8,STAINED_GLASS:11)
B(6,2,8,STAINED_GLASS:10)
B(7,2,8,STAINED_GLASS:10)
B(4,2,9,STAINED_GLASS:11)
B(5,2,9,STAINED_GLASS:15)
B(6,2,9,STAINED_GLASS:15)
B(3,3,0,STAINED_GLASS:2)
B(4,3,0,STAINED_GLASS:2)
B(5,3,0,SEA_LANTERN)
B(6,3,0,STAINED_GLASS:10)
B(3,3,1,STAINED_GLASS:15)
B(4,3,1,STAINED_GLASS:15)
B(5,3,1,STAINED_GLASS:15)
B(6,3,1,STAINED_GLASS:10)
B(7,3,1,STAINED_GLASS:10)
B(3,3,2,STAINED_GLASS:15)
B(4,3,2,SEA_LANTERN)
B(5,3,2,SEA_LANTERN)
B(6,3,2,STAINED_GLASS:15)
B(7,3,2,STAINED_GLASS:10)
B(3,3,3,STAINED_GLASS:11)
B(4,3,3,STAINED_GLASS:2)
B(5,3,3,STAINED_GLASS:15)
B(6,3,3,STAINED_GLASS:10)
B(7,3,3,STAINED_GLASS:10)
B(3,3,4,STAINED_GLASS:11)
B(4,3,4,STAINED_GLASS:2)
B(5,3,4,STAINED_GLASS:15)
B(6,3,4,STAINED_GLASS:2)
B(7,3,4,STAINED_GLASS:10)
B(3,3,5,STAINED_GLASS:11)
B(4,3,5,STAINED_GLASS:15)
B(5,3,5,STAINED_GLASS:15)
B(6,3,5,STAINED_GLASS:2)
B(7,3,5,STAINED_GLASS:10)
B(4,3,6,STAINED_GLASS:11)
B(5,3,6,STAINED_GLASS:15)
B(6,3,6,STAINED_GLASS:15)
B(7,3,6,STAINED_GLASS:15)
B(3,3,7,STAINED_GLASS:11)
B(4,3,7,STAINED_GLASS:11)
B(5,3,7,STAINED_GLASS:15)
B(6,3,7,STAINED_GLASS:15)
B(7,3,7,STAINED_GLASS:15)
B(4,3,8,STAINED_GLASS:11)
B(3,4,0,STAINED_GLASS:15)
B(4,4,0,STAINED_GLASS:15)
B(5,4,0,SEA_LANTERN)
B(6,4,0,STAINED_GLASS:10)
B(3,4,1,STAINED_GLASS:11)
B(4,4,1,STAINED_GLASS:2)
B(5,4,1,STAINED_GLASS:2)
B(6,4,1,STAINED_GLASS:10)
B(7,4,1,STAINED_GLASS:10)
B(3,4,2,STAINED_GLASS:2)
B(4,4,2,STAINED_GLASS:2)
B(5,4,2,STAINED_GLASS:15)
B(6,4,2,STAINED_GLASS:2)
B(7,4,2,STAINED_GLASS:10)
B(3,4,3,STAINED_GLASS:11)
B(4,4,3,STAINED_GLASS:2)
B(5,4,3,STAINED_GLASS:15)
B(6,4,3,STAINED_GLASS:10)
B(7,4,3,STAINED_GLASS:10)
B(3,4,4,STAINED_GLASS:11)
B(4,4,4,STAINED_GLASS:11)
B(5,4,4,STAINED_GLASS:15)
B(6,4,4,STAINED_GLASS:15)
B(7,4,4,STAINED_GLASS:10)
B(3,4,5,STAINED_GLASS:11)
B(4,4,5,STAINED_GLASS:11)
B(5,4,5,STAINED_GLASS:15)
B(6,4,5,STAINED_GLASS:15)
B(7,4,5,STAINED_GLASS:15)
B(3,5,0,STAINED_GLASS:2)
B(4,5,0,STAINED_GLASS:2)
B(5,5,0,STAINED_GLASS:15)
B(6,5,0,STAINED_GLASS:10)
B(3,5,1,STAINED_GLASS:11)
B(4,5,1,STAINED_GLASS:2)
B(5,5,1,STAINED_GLASS:2)
B(6,5,1,STAINED_GLASS:10)
B(7,5,1,STAINED_GLASS:10)
B(3,5,2,STAINED_GLASS:11)
B(4,5,2,STAINED_GLASS:11)
B(5,5,2,STAINED_GLASS:11)
B(6,5,2,STAINED_GLASS:15)
B(7,5,2,STAINED_GLASS:10)
B(3,5,3,STAINED_GLASS:11)
B(4,5,3,STAINED_GLASS:11)
B(5,5,3,STAINED_GLASS:11)
B(6,5,3,STAINED_GLASS:15)
B(3,6,0,STAINED_GLASS:11)
B(4,6,0,STAINED_GLASS:11)
B(5,6,0,STAINED_GLASS:15)
B(6,6,0,STAINED_GLASS:10)
B(3,6,1,STAINED_GLASS:11)
B(4,6,1,STAINED_GLASS:11)
B(5,6,1,STAINED_GLASS:15)
B(7,6,1,STAINED_GLASS:10)

#######################################################################
# +-----------------------------------------------------------------+ #
# |                             Branches                            | #
# +-----------------------------------------------------------------+ #
#######################################################################

BR(0,0,-16,true,SPIKE-SET-DIAG-THIN-09_0x1,NORTH,100,0)
