Author: Bo3 BulkEdit

Description: Converted Schematic - Modified by Bo3BulkEdit

Version: 3

SettingsMode: WriteDisable

IsOTGPlus: false
Tree: false
Frequency: 1
Rarity: 100
RotateRandomly: false
SpawnHeight: randomY
MaxBranchDepth: 10
ExcludedBiomes: All

MinHeight: 0
MaxHeight: 256

SourceBlocks: AIR
MaxPercentageOutsideSourceBlock: 100
OutsideSourceBlock: placeAnyway

RB(0,0,0,STONEBRICK:1,10,STONEBRICK:2,10,COBBLESTONE,10,MOSSY_COBBLESTONE,10,SMOOTH_BRICK,100)
RB(1,0,0,STONEBRICK:1,10,STONEBRICK:2,10,COBBLESTONE,10,MOSSY_COBBLESTONE,10,SMOOTH_BRICK,100)
RB(2,0,0,STONEBRICK:1,10,STONEBRICK:2,10,COBBLESTONE,10,MOSSY_COBBLESTONE,10,SMOOTH_BRICK,100)
RB(3,0,0,STONEBRICK:1,10,STONEBRICK:2,10,COBBLESTONE,10,MOSSY_COBBLESTONE,10,SMOOTH_BRICK,100)
RB(4,0,0,STONEBRICK:1,10,STONEBRICK:2,10,COBBLESTONE,10,MOSSY_COBBLESTONE,10,SMOOTH_BRICK,100)
RB(5,0,0,STONEBRICK:1,10,STONEBRICK:2,10,COBBLESTONE,10,MOSSY_COBBLESTONE,10,SMOOTH_BRICK,100)
RB(6,0,0,STONEBRICK:1,10,STONEBRICK:2,10,COBBLESTONE,10,MOSSY_COBBLESTONE,10,SMOOTH_BRICK,100)
RB(7,0,0,STONEBRICK:1,10,STONEBRICK:2,10,COBBLESTONE,10,MOSSY_COBBLESTONE,10,SMOOTH_BRICK,100)
RB(0,0,1,STONEBRICK:1,10,STONEBRICK:2,10,COBBLESTONE,10,MOSSY_COBBLESTONE,10,SMOOTH_BRICK,100)
RB(1,0,1,STONEBRICK:1,10,STONEBRICK:2,10,COBBLESTONE,10,MOSSY_COBBLESTONE,10,SMOOTH_BRICK,100)
RB(2,0,1,STONEBRICK:1,10,STONEBRICK:2,10,COBBLESTONE,10,MOSSY_COBBLESTONE,10,SMOOTH_BRICK,100)
RB(3,0,1,STONEBRICK:1,10,STONEBRICK:2,10,COBBLESTONE,10,MOSSY_COBBLESTONE,10,SMOOTH_BRICK,100)
RB(4,0,1,STONEBRICK:1,10,STONEBRICK:2,10,COBBLESTONE,10,MOSSY_COBBLESTONE,10,SMOOTH_BRICK,100)
RB(5,0,1,STONEBRICK:1,10,STONEBRICK:2,10,COBBLESTONE,10,MOSSY_COBBLESTONE,10,SMOOTH_BRICK,100)
RB(6,0,1,STONEBRICK:1,10,STONEBRICK:2,10,COBBLESTONE,10,MOSSY_COBBLESTONE,10,SMOOTH_BRICK,100)
RB(7,0,1,STONEBRICK:1,10,STONEBRICK:2,10,COBBLESTONE,10,MOSSY_COBBLESTONE,10,SMOOTH_BRICK,100)
RB(0,0,2,STONEBRICK:1,10,STONEBRICK:2,10,COBBLESTONE,10,MOSSY_COBBLESTONE,10,SMOOTH_BRICK,100)
RB(1,0,2,STONEBRICK:1,10,STONEBRICK:2,10,COBBLESTONE,10,MOSSY_COBBLESTONE,10,SMOOTH_BRICK,100)
RB(2,0,2,STONEBRICK:1,10,STONEBRICK:2,10,COBBLESTONE,10,MOSSY_COBBLESTONE,10,SMOOTH_BRICK,100)
RB(3,0,2,STONEBRICK:1,10,STONEBRICK:2,10,COBBLESTONE,10,MOSSY_COBBLESTONE,10,SMOOTH_BRICK,100)
RB(4,0,2,STONEBRICK:1,10,STONEBRICK:2,10,COBBLESTONE,10,MOSSY_COBBLESTONE,10,SMOOTH_BRICK,100)
RB(6,0,2,STONEBRICK:1,10,STONEBRICK:2,10,COBBLESTONE,10,MOSSY_COBBLESTONE,10,SMOOTH_BRICK,100)
RB(7,0,2,STONEBRICK:1,10,STONEBRICK:2,10,COBBLESTONE,10,MOSSY_COBBLESTONE,10,SMOOTH_BRICK,100)
RB(0,0,3,STONEBRICK:1,10,STONEBRICK:2,10,COBBLESTONE,10,MOSSY_COBBLESTONE,10,SMOOTH_BRICK,100)
RB(1,0,3,STONEBRICK:1,10,STONEBRICK:2,10,COBBLESTONE,10,MOSSY_COBBLESTONE,10,SMOOTH_BRICK,100)
RB(2,0,3,STONEBRICK:1,10,STONEBRICK:2,10,COBBLESTONE,10,MOSSY_COBBLESTONE,10,SMOOTH_BRICK,100)
RB(3,0,3,STONEBRICK:1,10,STONEBRICK:2,10,COBBLESTONE,10,MOSSY_COBBLESTONE,10,SMOOTH_BRICK,100)
RB(4,0,3,STONEBRICK:1,10,STONEBRICK:2,10,COBBLESTONE,10,MOSSY_COBBLESTONE,10,SMOOTH_BRICK,100)
RB(5,0,3,STONEBRICK:1,10,STONEBRICK:2,10,COBBLESTONE,10,MOSSY_COBBLESTONE,10,SMOOTH_BRICK,100)
RB(6,0,3,STONEBRICK:1,10,STONEBRICK:2,10,COBBLESTONE,10,MOSSY_COBBLESTONE,10,SMOOTH_BRICK,100)
RB(7,0,3,STONEBRICK:1,10,STONEBRICK:2,10,COBBLESTONE,10,MOSSY_COBBLESTONE,10,SMOOTH_BRICK,100)
RB(0,0,4,STONEBRICK:1,10,STONEBRICK:2,10,COBBLESTONE,10,MOSSY_COBBLESTONE,10,SMOOTH_BRICK,100)
RB(1,0,4,STONEBRICK:1,10,STONEBRICK:2,10,COBBLESTONE,10,MOSSY_COBBLESTONE,10,SMOOTH_BRICK,100)
RB(2,0,4,STONEBRICK:1,10,STONEBRICK:2,10,COBBLESTONE,10,MOSSY_COBBLESTONE,10,SMOOTH_BRICK,100)
RB(3,0,4,STONEBRICK:1,10,STONEBRICK:2,10,COBBLESTONE,10,MOSSY_COBBLESTONE,10,SMOOTH_BRICK,100)
RB(4,0,4,STONEBRICK:1,10,STONEBRICK:2,10,COBBLESTONE,10,MOSSY_COBBLESTONE,10,SMOOTH_BRICK,100)
RB(5,0,4,STONEBRICK:1,10,STONEBRICK:2,10,COBBLESTONE,10,MOSSY_COBBLESTONE,10,SMOOTH_BRICK,100)
RB(6,0,4,STONEBRICK:1,10,STONEBRICK:2,10,COBBLESTONE,10,MOSSY_COBBLESTONE,10,SMOOTH_BRICK,100)
RB(7,0,4,STONEBRICK:1,10,STONEBRICK:2,10,COBBLESTONE,10,MOSSY_COBBLESTONE,10,SMOOTH_BRICK,100)
RB(0,0,5,STONEBRICK:1,10,STONEBRICK:2,10,COBBLESTONE,10,MOSSY_COBBLESTONE,10,SMOOTH_BRICK,100)
RB(1,0,5,STONEBRICK:1,10,STONEBRICK:2,10,COBBLESTONE,10,MOSSY_COBBLESTONE,10,SMOOTH_BRICK,100)
RB(2,0,5,STONEBRICK:1,10,STONEBRICK:2,10,COBBLESTONE,10,MOSSY_COBBLESTONE,10,SMOOTH_BRICK,100)
RB(3,0,5,STONEBRICK:1,10,STONEBRICK:2,10,COBBLESTONE,10,MOSSY_COBBLESTONE,10,SMOOTH_BRICK,100)
RB(4,0,5,STONEBRICK:1,10,STONEBRICK:2,10,COBBLESTONE,10,MOSSY_COBBLESTONE,10,SMOOTH_BRICK,100)
RB(5,0,5,STONEBRICK:1,10,STONEBRICK:2,10,COBBLESTONE,10,MOSSY_COBBLESTONE,10,SMOOTH_BRICK,100)
RB(6,0,5,STONEBRICK:1,10,STONEBRICK:2,10,COBBLESTONE,10,MOSSY_COBBLESTONE,10,SMOOTH_BRICK,100)
RB(7,0,5,STONEBRICK:1,10,STONEBRICK:2,10,COBBLESTONE,10,MOSSY_COBBLESTONE,10,SMOOTH_BRICK,100)
RB(0,0,6,STONEBRICK:1,10,STONEBRICK:2,10,COBBLESTONE,10,MOSSY_COBBLESTONE,10,SMOOTH_BRICK,100)
RB(1,0,6,STONEBRICK:1,10,STONEBRICK:2,10,COBBLESTONE,10,MOSSY_COBBLESTONE,10,SMOOTH_BRICK,100)
RB(2,0,6,STONEBRICK:1,10,STONEBRICK:2,10,COBBLESTONE,10,MOSSY_COBBLESTONE,10,SMOOTH_BRICK,100)
RB(3,0,6,STONEBRICK:1,10,STONEBRICK:2,10,COBBLESTONE,10,MOSSY_COBBLESTONE,10,SMOOTH_BRICK,100)
RB(4,0,6,STONEBRICK:1,10,STONEBRICK:2,10,COBBLESTONE,10,MOSSY_COBBLESTONE,10,SMOOTH_BRICK,100)
RB(5,0,6,STONEBRICK:1,10,STONEBRICK:2,10,COBBLESTONE,10,MOSSY_COBBLESTONE,10,SMOOTH_BRICK,100)
RB(6,0,6,STONEBRICK:1,10,STONEBRICK:2,10,COBBLESTONE,10,MOSSY_COBBLESTONE,10,SMOOTH_BRICK,100)
RB(7,0,6,STONEBRICK:1,10,STONEBRICK:2,10,COBBLESTONE,10,MOSSY_COBBLESTONE,10,SMOOTH_BRICK,100)
RB(0,0,7,STONEBRICK:1,10,STONEBRICK:2,10,COBBLESTONE,10,MOSSY_COBBLESTONE,10,SMOOTH_BRICK,100)
RB(1,0,7,STONEBRICK:1,10,STONEBRICK:2,10,COBBLESTONE,10,MOSSY_COBBLESTONE,10,SMOOTH_BRICK,100)
RB(2,0,7,STONEBRICK:1,10,STONEBRICK:2,10,COBBLESTONE,10,MOSSY_COBBLESTONE,10,SMOOTH_BRICK,100)
RB(3,0,7,STONEBRICK:1,10,STONEBRICK:2,10,COBBLESTONE,10,MOSSY_COBBLESTONE,10,SMOOTH_BRICK,100)
RB(4,0,7,STONEBRICK:1,10,STONEBRICK:2,10,COBBLESTONE,10,MOSSY_COBBLESTONE,10,SMOOTH_BRICK,100)
RB(5,0,7,STONEBRICK:1,10,STONEBRICK:2,10,COBBLESTONE,10,MOSSY_COBBLESTONE,10,SMOOTH_BRICK,100)
RB(6,0,7,STONEBRICK:1,10,STONEBRICK:2,10,COBBLESTONE,10,MOSSY_COBBLESTONE,10,SMOOTH_BRICK,100)
RB(7,0,7,STONEBRICK:1,10,STONEBRICK:2,10,COBBLESTONE,10,MOSSY_COBBLESTONE,10,SMOOTH_BRICK,100)
RB(0,1,0,STONEBRICK:1,10,STONEBRICK:2,10,COBBLESTONE,10,MOSSY_COBBLESTONE,10,SMOOTH_BRICK,100)
RB(1,1,0,STONEBRICK:1,10,STONEBRICK:2,10,COBBLESTONE,10,MOSSY_COBBLESTONE,10,SMOOTH_BRICK,100)
RB(2,1,0,STONEBRICK:1,10,STONEBRICK:2,10,COBBLESTONE,10,MOSSY_COBBLESTONE,10,SMOOTH_BRICK,100)
RB(3,1,0,STONEBRICK:1,10,STONEBRICK:2,10,COBBLESTONE,10,MOSSY_COBBLESTONE,10,SMOOTH_BRICK,100)
RB(4,1,0,STONEBRICK:1,10,STONEBRICK:2,10,COBBLESTONE,10,MOSSY_COBBLESTONE,10,SMOOTH_BRICK,100)
RB(5,1,0,STONEBRICK:1,10,STONEBRICK:2,10,COBBLESTONE,10,MOSSY_COBBLESTONE,10,SMOOTH_BRICK,100)
RB(6,1,0,STONEBRICK:1,10,STONEBRICK:2,10,COBBLESTONE,10,MOSSY_COBBLESTONE,10,SMOOTH_BRICK,100)
RB(7,1,0,STONEBRICK:1,10,STONEBRICK:2,10,COBBLESTONE,10,MOSSY_COBBLESTONE,10,SMOOTH_BRICK,100)
RB(0,1,1,STONEBRICK:1,10,STONEBRICK:2,10,COBBLESTONE,10,MOSSY_COBBLESTONE,10,SMOOTH_BRICK,100)
RB(1,1,1,STONEBRICK:1,10,STONEBRICK:2,10,COBBLESTONE,10,MOSSY_COBBLESTONE,10,SMOOTH_BRICK,100)
RB(2,1,1,STONEBRICK:1,10,STONEBRICK:2,10,COBBLESTONE,10,MOSSY_COBBLESTONE,10,SMOOTH_BRICK,100)
RB(3,1,1,STONEBRICK:1,10,STONEBRICK:2,10,COBBLESTONE,10,MOSSY_COBBLESTONE,10,SMOOTH_BRICK,100)
RB(4,1,1,STONEBRICK:1,10,STONEBRICK:2,10,COBBLESTONE,10,MOSSY_COBBLESTONE,10,SMOOTH_BRICK,100)
RB(6,1,1,STONEBRICK:1,10,STONEBRICK:2,10,COBBLESTONE,10,MOSSY_COBBLESTONE,10,SMOOTH_BRICK,100)
RB(7,1,1,STONEBRICK:1,10,STONEBRICK:2,10,COBBLESTONE,10,MOSSY_COBBLESTONE,10,SMOOTH_BRICK,100)
RB(0,1,2,STONEBRICK:1,10,STONEBRICK:2,10,COBBLESTONE,10,MOSSY_COBBLESTONE,10,SMOOTH_BRICK,100)
RB(1,1,2,STONEBRICK:1,10,STONEBRICK:2,10,COBBLESTONE,10,MOSSY_COBBLESTONE,10,SMOOTH_BRICK,100)
RB(2,1,2,STONEBRICK:1,10,STONEBRICK:2,10,COBBLESTONE,10,MOSSY_COBBLESTONE,10,SMOOTH_BRICK,100)
RB(3,1,2,STONEBRICK:1,10,STONEBRICK:2,10,COBBLESTONE,10,MOSSY_COBBLESTONE,10,SMOOTH_BRICK,100)
RB(5,1,2,STONEBRICK:1,10,STONEBRICK:2,10,COBBLESTONE,10,MOSSY_COBBLESTONE,10,SMOOTH_BRICK,100)
RB(7,1,2,STONEBRICK:1,10,STONEBRICK:2,10,COBBLESTONE,10,MOSSY_COBBLESTONE,10,SMOOTH_BRICK,100)
RB(0,1,3,STONEBRICK:1,10,STONEBRICK:2,10,COBBLESTONE,10,MOSSY_COBBLESTONE,10,SMOOTH_BRICK,100)
RB(1,1,3,STONEBRICK:1,10,STONEBRICK:2,10,COBBLESTONE,10,MOSSY_COBBLESTONE,10,SMOOTH_BRICK,100)
RB(2,1,3,STONEBRICK:1,10,STONEBRICK:2,10,COBBLESTONE,10,MOSSY_COBBLESTONE,10,SMOOTH_BRICK,100)
RB(3,1,3,STONEBRICK:1,10,STONEBRICK:2,10,COBBLESTONE,10,MOSSY_COBBLESTONE,10,SMOOTH_BRICK,100)
RB(4,1,3,STONEBRICK:1,10,STONEBRICK:2,10,COBBLESTONE,10,MOSSY_COBBLESTONE,10,SMOOTH_BRICK,100)
RB(6,1,3,STONEBRICK:1,10,STONEBRICK:2,10,COBBLESTONE,10,MOSSY_COBBLESTONE,10,SMOOTH_BRICK,100)
RB(7,1,3,STONEBRICK:1,10,STONEBRICK:2,10,COBBLESTONE,10,MOSSY_COBBLESTONE,10,SMOOTH_BRICK,100)
RB(0,1,4,STONEBRICK:1,10,STONEBRICK:2,10,COBBLESTONE,10,MOSSY_COBBLESTONE,10,SMOOTH_BRICK,100)
RB(1,1,4,STONEBRICK:1,10,STONEBRICK:2,10,COBBLESTONE,10,MOSSY_COBBLESTONE,10,SMOOTH_BRICK,100)
RB(2,1,4,STONEBRICK:1,10,STONEBRICK:2,10,COBBLESTONE,10,MOSSY_COBBLESTONE,10,SMOOTH_BRICK,100)
RB(3,1,4,STONEBRICK:1,10,STONEBRICK:2,10,COBBLESTONE,10,MOSSY_COBBLESTONE,10,SMOOTH_BRICK,100)
RB(4,1,4,STONEBRICK:1,10,STONEBRICK:2,10,COBBLESTONE,10,MOSSY_COBBLESTONE,10,SMOOTH_BRICK,100)
RB(5,1,4,STONEBRICK:1,10,STONEBRICK:2,10,COBBLESTONE,10,MOSSY_COBBLESTONE,10,SMOOTH_BRICK,100)
RB(6,1,4,STONEBRICK:1,10,STONEBRICK:2,10,COBBLESTONE,10,MOSSY_COBBLESTONE,10,SMOOTH_BRICK,100)
RB(7,1,4,STONEBRICK:1,10,STONEBRICK:2,10,COBBLESTONE,10,MOSSY_COBBLESTONE,10,SMOOTH_BRICK,100)
RB(0,1,5,STONEBRICK:1,10,STONEBRICK:2,10,COBBLESTONE,10,MOSSY_COBBLESTONE,10,SMOOTH_BRICK,100)
RB(1,1,5,STONEBRICK:1,10,STONEBRICK:2,10,COBBLESTONE,10,MOSSY_COBBLESTONE,10,SMOOTH_BRICK,100)
RB(2,1,5,STONEBRICK:1,10,STONEBRICK:2,10,COBBLESTONE,10,MOSSY_COBBLESTONE,10,SMOOTH_BRICK,100)
RB(3,1,5,STONEBRICK:1,10,STONEBRICK:2,10,COBBLESTONE,10,MOSSY_COBBLESTONE,10,SMOOTH_BRICK,100)
RB(4,1,5,STONEBRICK:1,10,STONEBRICK:2,10,COBBLESTONE,10,MOSSY_COBBLESTONE,10,SMOOTH_BRICK,100)
RB(5,1,5,STONEBRICK:1,10,STONEBRICK:2,10,COBBLESTONE,10,MOSSY_COBBLESTONE,10,SMOOTH_BRICK,100)
RB(6,1,5,STONEBRICK:1,10,STONEBRICK:2,10,COBBLESTONE,10,MOSSY_COBBLESTONE,10,SMOOTH_BRICK,100)
RB(7,1,5,STONEBRICK:1,10,STONEBRICK:2,10,COBBLESTONE,10,MOSSY_COBBLESTONE,10,SMOOTH_BRICK,100)
RB(0,1,6,STONEBRICK:1,10,STONEBRICK:2,10,COBBLESTONE,10,MOSSY_COBBLESTONE,10,SMOOTH_BRICK,100)
RB(1,1,6,STONEBRICK:1,10,STONEBRICK:2,10,COBBLESTONE,10,MOSSY_COBBLESTONE,10,SMOOTH_BRICK,100)
RB(2,1,6,STONEBRICK:1,10,STONEBRICK:2,10,COBBLESTONE,10,MOSSY_COBBLESTONE,10,SMOOTH_BRICK,100)
RB(3,1,6,STONEBRICK:1,10,STONEBRICK:2,10,COBBLESTONE,10,MOSSY_COBBLESTONE,10,SMOOTH_BRICK,100)
RB(4,1,6,STONEBRICK:1,10,STONEBRICK:2,10,COBBLESTONE,10,MOSSY_COBBLESTONE,10,SMOOTH_BRICK,100)
RB(5,1,6,STONEBRICK:1,10,STONEBRICK:2,10,COBBLESTONE,10,MOSSY_COBBLESTONE,10,SMOOTH_BRICK,100)
RB(6,1,6,STONEBRICK:1,10,STONEBRICK:2,10,COBBLESTONE,10,MOSSY_COBBLESTONE,10,SMOOTH_BRICK,100)
RB(7,1,6,STONEBRICK:1,10,STONEBRICK:2,10,COBBLESTONE,10,MOSSY_COBBLESTONE,10,SMOOTH_BRICK,100)
RB(0,1,7,STONEBRICK:1,10,STONEBRICK:2,10,COBBLESTONE,10,MOSSY_COBBLESTONE,10,SMOOTH_BRICK,100)
RB(1,1,7,STONEBRICK:1,10,STONEBRICK:2,10,COBBLESTONE,10,MOSSY_COBBLESTONE,10,SMOOTH_BRICK,100)
RB(2,1,7,STONEBRICK:1,10,STONEBRICK:2,10,COBBLESTONE,10,MOSSY_COBBLESTONE,10,SMOOTH_BRICK,100)
RB(3,1,7,STONEBRICK:1,10,STONEBRICK:2,10,COBBLESTONE,10,MOSSY_COBBLESTONE,10,SMOOTH_BRICK,100)
RB(4,1,7,STONEBRICK:1,10,STONEBRICK:2,10,COBBLESTONE,10,MOSSY_COBBLESTONE,10,SMOOTH_BRICK,100)
RB(5,1,7,STONEBRICK:1,10,STONEBRICK:2,10,COBBLESTONE,10,MOSSY_COBBLESTONE,10,SMOOTH_BRICK,100)
RB(6,1,7,STONEBRICK:1,10,STONEBRICK:2,10,COBBLESTONE,10,MOSSY_COBBLESTONE,10,SMOOTH_BRICK,100)
RB(7,1,7,STONEBRICK:1,10,STONEBRICK:2,10,COBBLESTONE,10,MOSSY_COBBLESTONE,10,SMOOTH_BRICK,100)
RB(0,2,0,STONEBRICK:1,10,STONEBRICK:2,10,COBBLESTONE,10,MOSSY_COBBLESTONE,10,SMOOTH_BRICK,100)
RB(1,2,0,STONEBRICK:1,10,STONEBRICK:2,10,COBBLESTONE,10,MOSSY_COBBLESTONE,10,SMOOTH_BRICK,100)
RB(2,2,0,STONEBRICK:1,10,STONEBRICK:2,10,COBBLESTONE,10,MOSSY_COBBLESTONE,10,SMOOTH_BRICK,100)
RB(3,2,0,STONEBRICK:1,10,STONEBRICK:2,10,COBBLESTONE,10,MOSSY_COBBLESTONE,10,SMOOTH_BRICK,100)
RB(4,2,0,STONEBRICK:1,10,STONEBRICK:2,10,COBBLESTONE,10,MOSSY_COBBLESTONE,10,SMOOTH_BRICK,100)
RB(5,2,0,STONEBRICK:1,10,STONEBRICK:2,10,COBBLESTONE,10,MOSSY_COBBLESTONE,10,SMOOTH_BRICK,100)
RB(6,2,0,STONEBRICK:1,10,STONEBRICK:2,10,COBBLESTONE,10,MOSSY_COBBLESTONE,10,SMOOTH_BRICK,100)
RB(7,2,0,STONEBRICK:1,10,STONEBRICK:2,10,COBBLESTONE,10,MOSSY_COBBLESTONE,10,SMOOTH_BRICK,100)
RB(0,2,1,STONEBRICK:1,10,STONEBRICK:2,10,COBBLESTONE,10,MOSSY_COBBLESTONE,10,SMOOTH_BRICK,100)
RB(1,2,1,STONEBRICK:1,10,STONEBRICK:2,10,COBBLESTONE,10,MOSSY_COBBLESTONE,10,SMOOTH_BRICK,100)
RB(2,2,1,STONEBRICK:1,10,STONEBRICK:2,10,COBBLESTONE,10,MOSSY_COBBLESTONE,10,SMOOTH_BRICK,100)
RB(3,2,1,STONEBRICK:1,10,STONEBRICK:2,10,COBBLESTONE,10,MOSSY_COBBLESTONE,10,SMOOTH_BRICK,100)
RB(4,2,1,STONEBRICK:1,10,STONEBRICK:2,10,COBBLESTONE,10,MOSSY_COBBLESTONE,10,SMOOTH_BRICK,100)
RB(5,2,1,STONEBRICK:1,10,STONEBRICK:2,10,COBBLESTONE,10,MOSSY_COBBLESTONE,10,SMOOTH_BRICK,100)
RB(6,2,1,STONEBRICK:1,10,STONEBRICK:2,10,COBBLESTONE,10,MOSSY_COBBLESTONE,10,SMOOTH_BRICK,100)
RB(7,2,1,STONEBRICK:1,10,STONEBRICK:2,10,COBBLESTONE,10,MOSSY_COBBLESTONE,10,SMOOTH_BRICK,100)
RB(0,2,2,STONEBRICK:1,10,STONEBRICK:2,10,COBBLESTONE,10,MOSSY_COBBLESTONE,10,SMOOTH_BRICK,100)
RB(1,2,2,STONEBRICK:1,10,STONEBRICK:2,10,COBBLESTONE,10,MOSSY_COBBLESTONE,10,SMOOTH_BRICK,100)
RB(2,2,2,STONEBRICK:1,10,STONEBRICK:2,10,COBBLESTONE,10,MOSSY_COBBLESTONE,10,SMOOTH_BRICK,100)
RB(3,2,2,STONEBRICK:1,10,STONEBRICK:2,10,COBBLESTONE,10,MOSSY_COBBLESTONE,10,SMOOTH_BRICK,100)
RB(4,2,2,STONEBRICK:1,10,STONEBRICK:2,10,COBBLESTONE,10,MOSSY_COBBLESTONE,10,SMOOTH_BRICK,100)
RB(6,2,2,STONEBRICK:1,10,STONEBRICK:2,10,COBBLESTONE,10,MOSSY_COBBLESTONE,10,SMOOTH_BRICK,100)
RB(7,2,2,STONEBRICK:1,10,STONEBRICK:2,10,COBBLESTONE,10,MOSSY_COBBLESTONE,10,SMOOTH_BRICK,100)
RB(0,2,3,STONEBRICK:1,10,STONEBRICK:2,10,COBBLESTONE,10,MOSSY_COBBLESTONE,10,SMOOTH_BRICK,100)
RB(1,2,3,STONEBRICK:1,10,STONEBRICK:2,10,COBBLESTONE,10,MOSSY_COBBLESTONE,10,SMOOTH_BRICK,100)
RB(2,2,3,STONEBRICK:1,10,STONEBRICK:2,10,COBBLESTONE,10,MOSSY_COBBLESTONE,10,SMOOTH_BRICK,100)
RB(3,2,3,STONEBRICK:1,10,STONEBRICK:2,10,COBBLESTONE,10,MOSSY_COBBLESTONE,10,SMOOTH_BRICK,100)
RB(4,2,3,STONEBRICK:1,10,STONEBRICK:2,10,COBBLESTONE,10,MOSSY_COBBLESTONE,10,SMOOTH_BRICK,100)
RB(5,2,3,STONEBRICK:1,10,STONEBRICK:2,10,COBBLESTONE,10,MOSSY_COBBLESTONE,10,SMOOTH_BRICK,100)
RB(6,2,3,STONEBRICK:1,10,STONEBRICK:2,10,COBBLESTONE,10,MOSSY_COBBLESTONE,10,SMOOTH_BRICK,100)
RB(7,2,3,STONEBRICK:1,10,STONEBRICK:2,10,COBBLESTONE,10,MOSSY_COBBLESTONE,10,SMOOTH_BRICK,100)
RB(0,2,4,STONEBRICK:1,10,STONEBRICK:2,10,COBBLESTONE,10,MOSSY_COBBLESTONE,10,SMOOTH_BRICK,100)
RB(1,2,4,STONEBRICK:1,10,STONEBRICK:2,10,COBBLESTONE,10,MOSSY_COBBLESTONE,10,SMOOTH_BRICK,100)
RB(2,2,4,STONEBRICK:1,10,STONEBRICK:2,10,COBBLESTONE,10,MOSSY_COBBLESTONE,10,SMOOTH_BRICK,100)
RB(3,2,4,STONEBRICK:1,10,STONEBRICK:2,10,COBBLESTONE,10,MOSSY_COBBLESTONE,10,SMOOTH_BRICK,100)
RB(4,2,4,STONEBRICK:1,10,STONEBRICK:2,10,COBBLESTONE,10,MOSSY_COBBLESTONE,10,SMOOTH_BRICK,100)
RB(5,2,4,STONEBRICK:1,10,STONEBRICK:2,10,COBBLESTONE,10,MOSSY_COBBLESTONE,10,SMOOTH_BRICK,100)
RB(6,2,4,STONEBRICK:1,10,STONEBRICK:2,10,COBBLESTONE,10,MOSSY_COBBLESTONE,10,SMOOTH_BRICK,100)
RB(7,2,4,STONEBRICK:1,10,STONEBRICK:2,10,COBBLESTONE,10,MOSSY_COBBLESTONE,10,SMOOTH_BRICK,100)
RB(0,2,5,STONEBRICK:1,10,STONEBRICK:2,10,COBBLESTONE,10,MOSSY_COBBLESTONE,10,SMOOTH_BRICK,100)
RB(1,2,5,STONEBRICK:1,10,STONEBRICK:2,10,COBBLESTONE,10,MOSSY_COBBLESTONE,10,SMOOTH_BRICK,100)
RB(2,2,5,STONEBRICK:1,10,STONEBRICK:2,10,COBBLESTONE,10,MOSSY_COBBLESTONE,10,SMOOTH_BRICK,100)
RB(3,2,5,STONEBRICK:1,10,STONEBRICK:2,10,COBBLESTONE,10,MOSSY_COBBLESTONE,10,SMOOTH_BRICK,100)
RB(4,2,5,STONEBRICK:1,10,STONEBRICK:2,10,COBBLESTONE,10,MOSSY_COBBLESTONE,10,SMOOTH_BRICK,100)
RB(5,2,5,STONEBRICK:1,10,STONEBRICK:2,10,COBBLESTONE,10,MOSSY_COBBLESTONE,10,SMOOTH_BRICK,100)
RB(6,2,5,STONEBRICK:1,10,STONEBRICK:2,10,COBBLESTONE,10,MOSSY_COBBLESTONE,10,SMOOTH_BRICK,100)
RB(7,2,5,STONEBRICK:1,10,STONEBRICK:2,10,COBBLESTONE,10,MOSSY_COBBLESTONE,10,SMOOTH_BRICK,100)
RB(0,2,6,STONEBRICK:1,10,STONEBRICK:2,10,COBBLESTONE,10,MOSSY_COBBLESTONE,10,SMOOTH_BRICK,100)
RB(1,2,6,STONEBRICK:1,10,STONEBRICK:2,10,COBBLESTONE,10,MOSSY_COBBLESTONE,10,SMOOTH_BRICK,100)
RB(2,2,6,STONEBRICK:1,10,STONEBRICK:2,10,COBBLESTONE,10,MOSSY_COBBLESTONE,10,SMOOTH_BRICK,100)
RB(3,2,6,STONEBRICK:1,10,STONEBRICK:2,10,COBBLESTONE,10,MOSSY_COBBLESTONE,10,SMOOTH_BRICK,100)
RB(4,2,6,STONEBRICK:1,10,STONEBRICK:2,10,COBBLESTONE,10,MOSSY_COBBLESTONE,10,SMOOTH_BRICK,100)
RB(5,2,6,STONEBRICK:1,10,STONEBRICK:2,10,COBBLESTONE,10,MOSSY_COBBLESTONE,10,SMOOTH_BRICK,100)
RB(6,2,6,STONEBRICK:1,10,STONEBRICK:2,10,COBBLESTONE,10,MOSSY_COBBLESTONE,10,SMOOTH_BRICK,100)
RB(7,2,6,STONEBRICK:1,10,STONEBRICK:2,10,COBBLESTONE,10,MOSSY_COBBLESTONE,10,SMOOTH_BRICK,100)
RB(0,2,7,STONEBRICK:1,10,STONEBRICK:2,10,COBBLESTONE,10,MOSSY_COBBLESTONE,10,SMOOTH_BRICK,100)
RB(1,2,7,STONEBRICK:1,10,STONEBRICK:2,10,COBBLESTONE,10,MOSSY_COBBLESTONE,10,SMOOTH_BRICK,100)
RB(2,2,7,STONEBRICK:1,10,STONEBRICK:2,10,COBBLESTONE,10,MOSSY_COBBLESTONE,10,SMOOTH_BRICK,100)
RB(3,2,7,STONEBRICK:1,10,STONEBRICK:2,10,COBBLESTONE,10,MOSSY_COBBLESTONE,10,SMOOTH_BRICK,100)
RB(4,2,7,STONEBRICK:1,10,STONEBRICK:2,10,COBBLESTONE,10,MOSSY_COBBLESTONE,10,SMOOTH_BRICK,100)
RB(5,2,7,STONEBRICK:1,10,STONEBRICK:2,10,COBBLESTONE,10,MOSSY_COBBLESTONE,10,SMOOTH_BRICK,100)
RB(6,2,7,STONEBRICK:1,10,STONEBRICK:2,10,COBBLESTONE,10,MOSSY_COBBLESTONE,10,SMOOTH_BRICK,100)
RB(7,2,7,STONEBRICK:1,10,STONEBRICK:2,10,COBBLESTONE,10,MOSSY_COBBLESTONE,10,SMOOTH_BRICK,100)
RB(0,3,0,STONEBRICK:1,10,STONEBRICK:2,10,COBBLESTONE,10,MOSSY_COBBLESTONE,10,SMOOTH_BRICK,100)
RB(1,3,0,STONEBRICK:1,10,STONEBRICK:2,10,COBBLESTONE,10,MOSSY_COBBLESTONE,10,SMOOTH_BRICK,100)
RB(2,3,0,STONEBRICK:1,10,STONEBRICK:2,10,COBBLESTONE,10,MOSSY_COBBLESTONE,10,SMOOTH_BRICK,100)
RB(3,3,0,STONEBRICK:1,10,STONEBRICK:2,10,COBBLESTONE,10,MOSSY_COBBLESTONE,10,SMOOTH_BRICK,100)
RB(4,3,0,STONEBRICK:1,10,STONEBRICK:2,10,COBBLESTONE,10,MOSSY_COBBLESTONE,10,SMOOTH_BRICK,100)
RB(5,3,0,STONEBRICK:1,10,STONEBRICK:2,10,COBBLESTONE,10,MOSSY_COBBLESTONE,10,SMOOTH_BRICK,100)
RB(6,3,0,STONEBRICK:1,10,STONEBRICK:2,10,COBBLESTONE,10,MOSSY_COBBLESTONE,10,SMOOTH_BRICK,100)
RB(7,3,0,STONEBRICK:1,10,STONEBRICK:2,10,COBBLESTONE,10,MOSSY_COBBLESTONE,10,SMOOTH_BRICK,100)
RB(0,3,1,STONEBRICK:1,10,STONEBRICK:2,10,COBBLESTONE,10,MOSSY_COBBLESTONE,10,SMOOTH_BRICK,100)
RB(1,3,1,STONEBRICK:1,10,STONEBRICK:2,10,COBBLESTONE,10,MOSSY_COBBLESTONE,10,SMOOTH_BRICK,100)
RB(2,3,1,STONEBRICK:1,10,STONEBRICK:2,10,COBBLESTONE,10,MOSSY_COBBLESTONE,10,SMOOTH_BRICK,100)
RB(3,3,1,STONEBRICK:1,10,STONEBRICK:2,10,COBBLESTONE,10,MOSSY_COBBLESTONE,10,SMOOTH_BRICK,100)
RB(4,3,1,STONEBRICK:1,10,STONEBRICK:2,10,COBBLESTONE,10,MOSSY_COBBLESTONE,10,SMOOTH_BRICK,100)
RB(5,3,1,STONEBRICK:1,10,STONEBRICK:2,10,COBBLESTONE,10,MOSSY_COBBLESTONE,10,SMOOTH_BRICK,100)
RB(6,3,1,STONEBRICK:1,10,STONEBRICK:2,10,COBBLESTONE,10,MOSSY_COBBLESTONE,10,SMOOTH_BRICK,100)
RB(7,3,1,STONEBRICK:1,10,STONEBRICK:2,10,COBBLESTONE,10,MOSSY_COBBLESTONE,10,SMOOTH_BRICK,100)
RB(0,3,2,STONEBRICK:1,10,STONEBRICK:2,10,COBBLESTONE,10,MOSSY_COBBLESTONE,10,SMOOTH_BRICK,100)
RB(1,3,2,STONEBRICK:1,10,STONEBRICK:2,10,COBBLESTONE,10,MOSSY_COBBLESTONE,10,SMOOTH_BRICK,100)
RB(2,3,2,STONEBRICK:1,10,STONEBRICK:2,10,COBBLESTONE,10,MOSSY_COBBLESTONE,10,SMOOTH_BRICK,100)
RB(3,3,2,STONEBRICK:1,10,STONEBRICK:2,10,COBBLESTONE,10,MOSSY_COBBLESTONE,10,SMOOTH_BRICK,100)
RB(4,3,2,STONEBRICK:1,10,STONEBRICK:2,10,COBBLESTONE,10,MOSSY_COBBLESTONE,10,SMOOTH_BRICK,100)
RB(5,3,2,STONEBRICK:1,10,STONEBRICK:2,10,COBBLESTONE,10,MOSSY_COBBLESTONE,10,SMOOTH_BRICK,100)
RB(6,3,2,STONEBRICK:1,10,STONEBRICK:2,10,COBBLESTONE,10,MOSSY_COBBLESTONE,10,SMOOTH_BRICK,100)
RB(7,3,2,STONEBRICK:1,10,STONEBRICK:2,10,COBBLESTONE,10,MOSSY_COBBLESTONE,10,SMOOTH_BRICK,100)
RB(0,3,3,STONEBRICK:1,10,STONEBRICK:2,10,COBBLESTONE,10,MOSSY_COBBLESTONE,10,SMOOTH_BRICK,100)
RB(1,3,3,STONEBRICK:1,10,STONEBRICK:2,10,COBBLESTONE,10,MOSSY_COBBLESTONE,10,SMOOTH_BRICK,100)
RB(2,3,3,STONEBRICK:1,10,STONEBRICK:2,10,COBBLESTONE,10,MOSSY_COBBLESTONE,10,SMOOTH_BRICK,100)
RB(3,3,3,STONEBRICK:1,10,STONEBRICK:2,10,COBBLESTONE,10,MOSSY_COBBLESTONE,10,SMOOTH_BRICK,100)
RB(4,3,3,STONEBRICK:1,10,STONEBRICK:2,10,COBBLESTONE,10,MOSSY_COBBLESTONE,10,SMOOTH_BRICK,100)
RB(5,3,3,STONEBRICK:1,10,STONEBRICK:2,10,COBBLESTONE,10,MOSSY_COBBLESTONE,10,SMOOTH_BRICK,100)
RB(6,3,3,STONEBRICK:1,10,STONEBRICK:2,10,COBBLESTONE,10,MOSSY_COBBLESTONE,10,SMOOTH_BRICK,100)
RB(7,3,3,STONEBRICK:1,10,STONEBRICK:2,10,COBBLESTONE,10,MOSSY_COBBLESTONE,10,SMOOTH_BRICK,100)
RB(0,3,4,STONEBRICK:1,10,STONEBRICK:2,10,COBBLESTONE,10,MOSSY_COBBLESTONE,10,SMOOTH_BRICK,100)
RB(1,3,4,STONEBRICK:1,10,STONEBRICK:2,10,COBBLESTONE,10,MOSSY_COBBLESTONE,10,SMOOTH_BRICK,100)
RB(2,3,4,STONEBRICK:1,10,STONEBRICK:2,10,COBBLESTONE,10,MOSSY_COBBLESTONE,10,SMOOTH_BRICK,100)
RB(3,3,4,STONEBRICK:1,10,STONEBRICK:2,10,COBBLESTONE,10,MOSSY_COBBLESTONE,10,SMOOTH_BRICK,100)
RB(4,3,4,STONEBRICK:1,10,STONEBRICK:2,10,COBBLESTONE,10,MOSSY_COBBLESTONE,10,SMOOTH_BRICK,100)
RB(5,3,4,STONEBRICK:1,10,STONEBRICK:2,10,COBBLESTONE,10,MOSSY_COBBLESTONE,10,SMOOTH_BRICK,100)
RB(6,3,4,STONEBRICK:1,10,STONEBRICK:2,10,COBBLESTONE,10,MOSSY_COBBLESTONE,10,SMOOTH_BRICK,100)
RB(7,3,4,STONEBRICK:1,10,STONEBRICK:2,10,COBBLESTONE,10,MOSSY_COBBLESTONE,10,SMOOTH_BRICK,100)
RB(0,3,5,STONEBRICK:1,10,STONEBRICK:2,10,COBBLESTONE,10,MOSSY_COBBLESTONE,10,SMOOTH_BRICK,100)
RB(1,3,5,STONEBRICK:1,10,STONEBRICK:2,10,COBBLESTONE,10,MOSSY_COBBLESTONE,10,SMOOTH_BRICK,100)
RB(2,3,5,STONEBRICK:1,10,STONEBRICK:2,10,COBBLESTONE,10,MOSSY_COBBLESTONE,10,SMOOTH_BRICK,100)
RB(3,3,5,STONEBRICK:1,10,STONEBRICK:2,10,COBBLESTONE,10,MOSSY_COBBLESTONE,10,SMOOTH_BRICK,100)
RB(4,3,5,STONEBRICK:1,10,STONEBRICK:2,10,COBBLESTONE,10,MOSSY_COBBLESTONE,10,SMOOTH_BRICK,100)
RB(5,3,5,STONEBRICK:1,10,STONEBRICK:2,10,COBBLESTONE,10,MOSSY_COBBLESTONE,10,SMOOTH_BRICK,100)
RB(6,3,5,STONEBRICK:1,10,STONEBRICK:2,10,COBBLESTONE,10,MOSSY_COBBLESTONE,10,SMOOTH_BRICK,100)
RB(7,3,5,STONEBRICK:1,10,STONEBRICK:2,10,COBBLESTONE,10,MOSSY_COBBLESTONE,10,SMOOTH_BRICK,100)
RB(0,3,6,STONEBRICK:1,10,STONEBRICK:2,10,COBBLESTONE,10,MOSSY_COBBLESTONE,10,SMOOTH_BRICK,100)
RB(1,3,6,STONEBRICK:1,10,STONEBRICK:2,10,COBBLESTONE,10,MOSSY_COBBLESTONE,10,SMOOTH_BRICK,100)
RB(2,3,6,STONEBRICK:1,10,STONEBRICK:2,10,COBBLESTONE,10,MOSSY_COBBLESTONE,10,SMOOTH_BRICK,100)
RB(3,3,6,STONEBRICK:1,10,STONEBRICK:2,10,COBBLESTONE,10,MOSSY_COBBLESTONE,10,SMOOTH_BRICK,100)
RB(4,3,6,STONEBRICK:1,10,STONEBRICK:2,10,COBBLESTONE,10,MOSSY_COBBLESTONE,10,SMOOTH_BRICK,100)
RB(5,3,6,STONEBRICK:1,10,STONEBRICK:2,10,COBBLESTONE,10,MOSSY_COBBLESTONE,10,SMOOTH_BRICK,100)
RB(6,3,6,STONEBRICK:1,10,STONEBRICK:2,10,COBBLESTONE,10,MOSSY_COBBLESTONE,10,SMOOTH_BRICK,100)
RB(7,3,6,STONEBRICK:1,10,STONEBRICK:2,10,COBBLESTONE,10,MOSSY_COBBLESTONE,10,SMOOTH_BRICK,100)
RB(0,3,7,STONEBRICK:1,10,STONEBRICK:2,10,COBBLESTONE,10,MOSSY_COBBLESTONE,10,SMOOTH_BRICK,100)
RB(1,3,7,STONEBRICK:1,10,STONEBRICK:2,10,COBBLESTONE,10,MOSSY_COBBLESTONE,10,SMOOTH_BRICK,100)
RB(2,3,7,STONEBRICK:1,10,STONEBRICK:2,10,COBBLESTONE,10,MOSSY_COBBLESTONE,10,SMOOTH_BRICK,100)
RB(3,3,7,STONEBRICK:1,10,STONEBRICK:2,10,COBBLESTONE,10,MOSSY_COBBLESTONE,10,SMOOTH_BRICK,100)
RB(4,3,7,STONEBRICK:1,10,STONEBRICK:2,10,COBBLESTONE,10,MOSSY_COBBLESTONE,10,SMOOTH_BRICK,100)
RB(5,3,7,STONEBRICK:1,10,STONEBRICK:2,10,COBBLESTONE,10,MOSSY_COBBLESTONE,10,SMOOTH_BRICK,100)
RB(6,3,7,STONEBRICK:1,10,STONEBRICK:2,10,COBBLESTONE,10,MOSSY_COBBLESTONE,10,SMOOTH_BRICK,100)
RB(7,3,7,STONEBRICK:1,10,STONEBRICK:2,10,COBBLESTONE,10,MOSSY_COBBLESTONE,10,SMOOTH_BRICK,100)
RB(0,4,0,STONEBRICK:1,10,STONEBRICK:2,10,COBBLESTONE,10,MOSSY_COBBLESTONE,10,SMOOTH_BRICK,100)
RB(1,4,0,STONEBRICK:1,10,STONEBRICK:2,10,COBBLESTONE,10,MOSSY_COBBLESTONE,10,SMOOTH_BRICK,100)
RB(2,4,0,STONEBRICK:1,10,STONEBRICK:2,10,COBBLESTONE,10,MOSSY_COBBLESTONE,10,SMOOTH_BRICK,100)
RB(3,4,0,STONEBRICK:1,10,STONEBRICK:2,10,COBBLESTONE,10,MOSSY_COBBLESTONE,10,SMOOTH_BRICK,100)
RB(4,4,0,STONEBRICK:1,10,STONEBRICK:2,10,COBBLESTONE,10,MOSSY_COBBLESTONE,10,SMOOTH_BRICK,100)
RB(5,4,0,STONEBRICK:1,10,STONEBRICK:2,10,COBBLESTONE,10,MOSSY_COBBLESTONE,10,SMOOTH_BRICK,100)
RB(6,4,0,STONEBRICK:1,10,STONEBRICK:2,10,COBBLESTONE,10,MOSSY_COBBLESTONE,10,SMOOTH_BRICK,100)
RB(7,4,0,STONEBRICK:1,10,STONEBRICK:2,10,COBBLESTONE,10,MOSSY_COBBLESTONE,10,SMOOTH_BRICK,100)
RB(0,4,1,STONEBRICK:1,10,STONEBRICK:2,10,COBBLESTONE,10,MOSSY_COBBLESTONE,10,SMOOTH_BRICK,100)
RB(1,4,1,STONEBRICK:1,10,STONEBRICK:2,10,COBBLESTONE,10,MOSSY_COBBLESTONE,10,SMOOTH_BRICK,100)
RB(2,4,1,STONEBRICK:1,10,STONEBRICK:2,10,COBBLESTONE,10,MOSSY_COBBLESTONE,10,SMOOTH_BRICK,100)
RB(3,4,1,STONEBRICK:1,10,STONEBRICK:2,10,COBBLESTONE,10,MOSSY_COBBLESTONE,10,SMOOTH_BRICK,100)
RB(4,4,1,STONEBRICK:1,10,STONEBRICK:2,10,COBBLESTONE,10,MOSSY_COBBLESTONE,10,SMOOTH_BRICK,100)
RB(5,4,1,STONEBRICK:1,10,STONEBRICK:2,10,COBBLESTONE,10,MOSSY_COBBLESTONE,10,SMOOTH_BRICK,100)
RB(6,4,1,STONEBRICK:1,10,STONEBRICK:2,10,COBBLESTONE,10,MOSSY_COBBLESTONE,10,SMOOTH_BRICK,100)
RB(7,4,1,STONEBRICK:1,10,STONEBRICK:2,10,COBBLESTONE,10,MOSSY_COBBLESTONE,10,SMOOTH_BRICK,100)
RB(0,4,2,STONEBRICK:1,10,STONEBRICK:2,10,COBBLESTONE,10,MOSSY_COBBLESTONE,10,SMOOTH_BRICK,100)
RB(1,4,2,STONEBRICK:1,10,STONEBRICK:2,10,COBBLESTONE,10,MOSSY_COBBLESTONE,10,SMOOTH_BRICK,100)
RB(2,4,2,STONEBRICK:1,10,STONEBRICK:2,10,COBBLESTONE,10,MOSSY_COBBLESTONE,10,SMOOTH_BRICK,100)
RB(3,4,2,STONEBRICK:1,10,STONEBRICK:2,10,COBBLESTONE,10,MOSSY_COBBLESTONE,10,SMOOTH_BRICK,100)
RB(4,4,2,STONEBRICK:1,10,STONEBRICK:2,10,COBBLESTONE,10,MOSSY_COBBLESTONE,10,SMOOTH_BRICK,100)
RB(5,4,2,STONEBRICK:1,10,STONEBRICK:2,10,COBBLESTONE,10,MOSSY_COBBLESTONE,10,SMOOTH_BRICK,100)
RB(6,4,2,STONEBRICK:1,10,STONEBRICK:2,10,COBBLESTONE,10,MOSSY_COBBLESTONE,10,SMOOTH_BRICK,100)
RB(7,4,2,STONEBRICK:1,10,STONEBRICK:2,10,COBBLESTONE,10,MOSSY_COBBLESTONE,10,SMOOTH_BRICK,100)
RB(0,4,3,STONEBRICK:1,10,STONEBRICK:2,10,COBBLESTONE,10,MOSSY_COBBLESTONE,10,SMOOTH_BRICK,100)
RB(1,4,3,STONEBRICK:1,10,STONEBRICK:2,10,COBBLESTONE,10,MOSSY_COBBLESTONE,10,SMOOTH_BRICK,100)
RB(2,4,3,STONEBRICK:1,10,STONEBRICK:2,10,COBBLESTONE,10,MOSSY_COBBLESTONE,10,SMOOTH_BRICK,100)
RB(3,4,3,STONEBRICK:1,10,STONEBRICK:2,10,COBBLESTONE,10,MOSSY_COBBLESTONE,10,SMOOTH_BRICK,100)
RB(4,4,3,STONEBRICK:1,10,STONEBRICK:2,10,COBBLESTONE,10,MOSSY_COBBLESTONE,10,SMOOTH_BRICK,100)
RB(5,4,3,STONEBRICK:1,10,STONEBRICK:2,10,COBBLESTONE,10,MOSSY_COBBLESTONE,10,SMOOTH_BRICK,100)
RB(6,4,3,STONEBRICK:1,10,STONEBRICK:2,10,COBBLESTONE,10,MOSSY_COBBLESTONE,10,SMOOTH_BRICK,100)
RB(7,4,3,STONEBRICK:1,10,STONEBRICK:2,10,COBBLESTONE,10,MOSSY_COBBLESTONE,10,SMOOTH_BRICK,100)
RB(0,4,4,STONEBRICK:1,10,STONEBRICK:2,10,COBBLESTONE,10,MOSSY_COBBLESTONE,10,SMOOTH_BRICK,100)
RB(1,4,4,STONEBRICK:1,10,STONEBRICK:2,10,COBBLESTONE,10,MOSSY_COBBLESTONE,10,SMOOTH_BRICK,100)
RB(2,4,4,STONEBRICK:1,10,STONEBRICK:2,10,COBBLESTONE,10,MOSSY_COBBLESTONE,10,SMOOTH_BRICK,100)
RB(3,4,4,STONEBRICK:1,10,STONEBRICK:2,10,COBBLESTONE,10,MOSSY_COBBLESTONE,10,SMOOTH_BRICK,100)
RB(4,4,4,STONEBRICK:1,10,STONEBRICK:2,10,COBBLESTONE,10,MOSSY_COBBLESTONE,10,SMOOTH_BRICK,100)
RB(5,4,4,STONEBRICK:1,10,STONEBRICK:2,10,COBBLESTONE,10,MOSSY_COBBLESTONE,10,SMOOTH_BRICK,100)
RB(6,4,4,STONEBRICK:1,10,STONEBRICK:2,10,COBBLESTONE,10,MOSSY_COBBLESTONE,10,SMOOTH_BRICK,100)
RB(7,4,4,STONEBRICK:1,10,STONEBRICK:2,10,COBBLESTONE,10,MOSSY_COBBLESTONE,10,SMOOTH_BRICK,100)
RB(0,4,5,STONEBRICK:1,10,STONEBRICK:2,10,COBBLESTONE,10,MOSSY_COBBLESTONE,10,SMOOTH_BRICK,100)
RB(1,4,5,STONEBRICK:1,10,STONEBRICK:2,10,COBBLESTONE,10,MOSSY_COBBLESTONE,10,SMOOTH_BRICK,100)
RB(2,4,5,STONEBRICK:1,10,STONEBRICK:2,10,COBBLESTONE,10,MOSSY_COBBLESTONE,10,SMOOTH_BRICK,100)
RB(3,4,5,STONEBRICK:1,10,STONEBRICK:2,10,COBBLESTONE,10,MOSSY_COBBLESTONE,10,SMOOTH_BRICK,100)
RB(4,4,5,STONEBRICK:1,10,STONEBRICK:2,10,COBBLESTONE,10,MOSSY_COBBLESTONE,10,SMOOTH_BRICK,100)
RB(5,4,5,STONEBRICK:1,10,STONEBRICK:2,10,COBBLESTONE,10,MOSSY_COBBLESTONE,10,SMOOTH_BRICK,100)
RB(6,4,5,STONEBRICK:1,10,STONEBRICK:2,10,COBBLESTONE,10,MOSSY_COBBLESTONE,10,SMOOTH_BRICK,100)
RB(7,4,5,STONEBRICK:1,10,STONEBRICK:2,10,COBBLESTONE,10,MOSSY_COBBLESTONE,10,SMOOTH_BRICK,100)
RB(0,4,6,STONEBRICK:1,10,STONEBRICK:2,10,COBBLESTONE,10,MOSSY_COBBLESTONE,10,SMOOTH_BRICK,100)
RB(1,4,6,STONEBRICK:1,10,STONEBRICK:2,10,COBBLESTONE,10,MOSSY_COBBLESTONE,10,SMOOTH_BRICK,100)
RB(2,4,6,STONEBRICK:1,10,STONEBRICK:2,10,COBBLESTONE,10,MOSSY_COBBLESTONE,10,SMOOTH_BRICK,100)
RB(3,4,6,STONEBRICK:1,10,STONEBRICK:2,10,COBBLESTONE,10,MOSSY_COBBLESTONE,10,SMOOTH_BRICK,100)
RB(4,4,6,STONEBRICK:1,10,STONEBRICK:2,10,COBBLESTONE,10,MOSSY_COBBLESTONE,10,SMOOTH_BRICK,100)
RB(5,4,6,STONEBRICK:1,10,STONEBRICK:2,10,COBBLESTONE,10,MOSSY_COBBLESTONE,10,SMOOTH_BRICK,100)
RB(6,4,6,STONEBRICK:1,10,STONEBRICK:2,10,COBBLESTONE,10,MOSSY_COBBLESTONE,10,SMOOTH_BRICK,100)
RB(7,4,6,STONEBRICK:1,10,STONEBRICK:2,10,COBBLESTONE,10,MOSSY_COBBLESTONE,10,SMOOTH_BRICK,100)
RB(0,4,7,STONEBRICK:1,10,STONEBRICK:2,10,COBBLESTONE,10,MOSSY_COBBLESTONE,10,SMOOTH_BRICK,100)
RB(1,4,7,STONEBRICK:1,10,STONEBRICK:2,10,COBBLESTONE,10,MOSSY_COBBLESTONE,10,SMOOTH_BRICK,100)
RB(2,4,7,STONEBRICK:1,10,STONEBRICK:2,10,COBBLESTONE,10,MOSSY_COBBLESTONE,10,SMOOTH_BRICK,100)
RB(3,4,7,STONEBRICK:1,10,STONEBRICK:2,10,COBBLESTONE,10,MOSSY_COBBLESTONE,10,SMOOTH_BRICK,100)
RB(4,4,7,STONEBRICK:1,10,STONEBRICK:2,10,COBBLESTONE,10,MOSSY_COBBLESTONE,10,SMOOTH_BRICK,100)
RB(5,4,7,STONEBRICK:1,10,STONEBRICK:2,10,COBBLESTONE,10,MOSSY_COBBLESTONE,10,SMOOTH_BRICK,100)
RB(6,4,7,STONEBRICK:1,10,STONEBRICK:2,10,COBBLESTONE,10,MOSSY_COBBLESTONE,10,SMOOTH_BRICK,100)
RB(7,4,7,STONEBRICK:1,10,STONEBRICK:2,10,COBBLESTONE,10,MOSSY_COBBLESTONE,10,SMOOTH_BRICK,100)
RB(0,5,0,STONEBRICK:1,10,STONEBRICK:2,10,COBBLESTONE,10,MOSSY_COBBLESTONE,10,SMOOTH_BRICK,100)
RB(1,5,0,STONEBRICK:1,10,STONEBRICK:2,10,COBBLESTONE,10,MOSSY_COBBLESTONE,10,SMOOTH_BRICK,100)
RB(2,5,0,STONEBRICK:1,10,STONEBRICK:2,10,COBBLESTONE,10,MOSSY_COBBLESTONE,10,SMOOTH_BRICK,100)
RB(3,5,0,STONEBRICK:1,10,STONEBRICK:2,10,COBBLESTONE,10,MOSSY_COBBLESTONE,10,SMOOTH_BRICK,100)
RB(4,5,0,STONEBRICK:1,10,STONEBRICK:2,10,COBBLESTONE,10,MOSSY_COBBLESTONE,10,SMOOTH_BRICK,100)
RB(5,5,0,STONEBRICK:1,10,STONEBRICK:2,10,COBBLESTONE,10,MOSSY_COBBLESTONE,10,SMOOTH_BRICK,100)
RB(6,5,0,STONEBRICK:1,10,STONEBRICK:2,10,COBBLESTONE,10,MOSSY_COBBLESTONE,10,SMOOTH_BRICK,100)
RB(7,5,0,STONEBRICK:1,10,STONEBRICK:2,10,COBBLESTONE,10,MOSSY_COBBLESTONE,10,SMOOTH_BRICK,100)
RB(0,5,1,STONEBRICK:1,10,STONEBRICK:2,10,COBBLESTONE,10,MOSSY_COBBLESTONE,10,SMOOTH_BRICK,100)
RB(1,5,1,STONEBRICK:1,10,STONEBRICK:2,10,COBBLESTONE,10,MOSSY_COBBLESTONE,10,SMOOTH_BRICK,100)
RB(2,5,1,STONEBRICK:1,10,STONEBRICK:2,10,COBBLESTONE,10,MOSSY_COBBLESTONE,10,SMOOTH_BRICK,100)
RB(3,5,1,STONEBRICK:1,10,STONEBRICK:2,10,COBBLESTONE,10,MOSSY_COBBLESTONE,10,SMOOTH_BRICK,100)
RB(4,5,1,STONEBRICK:1,10,STONEBRICK:2,10,COBBLESTONE,10,MOSSY_COBBLESTONE,10,SMOOTH_BRICK,100)
RB(5,5,1,STONEBRICK:1,10,STONEBRICK:2,10,COBBLESTONE,10,MOSSY_COBBLESTONE,10,SMOOTH_BRICK,100)
RB(6,5,1,STONEBRICK:1,10,STONEBRICK:2,10,COBBLESTONE,10,MOSSY_COBBLESTONE,10,SMOOTH_BRICK,100)
RB(7,5,1,STONEBRICK:1,10,STONEBRICK:2,10,COBBLESTONE,10,MOSSY_COBBLESTONE,10,SMOOTH_BRICK,100)
RB(0,5,2,STONEBRICK:1,10,STONEBRICK:2,10,COBBLESTONE,10,MOSSY_COBBLESTONE,10,SMOOTH_BRICK,100)
RB(1,5,2,STONEBRICK:1,10,STONEBRICK:2,10,COBBLESTONE,10,MOSSY_COBBLESTONE,10,SMOOTH_BRICK,100)
RB(2,5,2,STONEBRICK:1,10,STONEBRICK:2,10,COBBLESTONE,10,MOSSY_COBBLESTONE,10,SMOOTH_BRICK,100)
RB(3,5,2,STONEBRICK:1,10,STONEBRICK:2,10,COBBLESTONE,10,MOSSY_COBBLESTONE,10,SMOOTH_BRICK,100)
RB(4,5,2,STONEBRICK:1,10,STONEBRICK:2,10,COBBLESTONE,10,MOSSY_COBBLESTONE,10,SMOOTH_BRICK,100)
RB(5,5,2,STONEBRICK:1,10,STONEBRICK:2,10,COBBLESTONE,10,MOSSY_COBBLESTONE,10,SMOOTH_BRICK,100)
RB(6,5,2,STONEBRICK:1,10,STONEBRICK:2,10,COBBLESTONE,10,MOSSY_COBBLESTONE,10,SMOOTH_BRICK,100)
RB(7,5,2,STONEBRICK:1,10,STONEBRICK:2,10,COBBLESTONE,10,MOSSY_COBBLESTONE,10,SMOOTH_BRICK,100)
RB(0,5,3,STONEBRICK:1,10,STONEBRICK:2,10,COBBLESTONE,10,MOSSY_COBBLESTONE,10,SMOOTH_BRICK,100)
RB(1,5,3,STONEBRICK:1,10,STONEBRICK:2,10,COBBLESTONE,10,MOSSY_COBBLESTONE,10,SMOOTH_BRICK,100)
RB(2,5,3,STONEBRICK:1,10,STONEBRICK:2,10,COBBLESTONE,10,MOSSY_COBBLESTONE,10,SMOOTH_BRICK,100)
RB(3,5,3,STONEBRICK:1,10,STONEBRICK:2,10,COBBLESTONE,10,MOSSY_COBBLESTONE,10,SMOOTH_BRICK,100)
RB(4,5,3,STONEBRICK:1,10,STONEBRICK:2,10,COBBLESTONE,10,MOSSY_COBBLESTONE,10,SMOOTH_BRICK,100)
RB(5,5,3,STONEBRICK:1,10,STONEBRICK:2,10,COBBLESTONE,10,MOSSY_COBBLESTONE,10,SMOOTH_BRICK,100)
RB(6,5,3,STONEBRICK:1,10,STONEBRICK:2,10,COBBLESTONE,10,MOSSY_COBBLESTONE,10,SMOOTH_BRICK,100)
RB(7,5,3,STONEBRICK:1,10,STONEBRICK:2,10,COBBLESTONE,10,MOSSY_COBBLESTONE,10,SMOOTH_BRICK,100)
RB(0,5,4,STONEBRICK:1,10,STONEBRICK:2,10,COBBLESTONE,10,MOSSY_COBBLESTONE,10,SMOOTH_BRICK,100)
RB(1,5,4,STONEBRICK:1,10,STONEBRICK:2,10,COBBLESTONE,10,MOSSY_COBBLESTONE,10,SMOOTH_BRICK,100)
RB(2,5,4,STONEBRICK:1,10,STONEBRICK:2,10,COBBLESTONE,10,MOSSY_COBBLESTONE,10,SMOOTH_BRICK,100)
RB(3,5,4,STONEBRICK:1,10,STONEBRICK:2,10,COBBLESTONE,10,MOSSY_COBBLESTONE,10,SMOOTH_BRICK,100)
RB(4,5,4,STONEBRICK:1,10,STONEBRICK:2,10,COBBLESTONE,10,MOSSY_COBBLESTONE,10,SMOOTH_BRICK,100)
RB(5,5,4,STONEBRICK:1,10,STONEBRICK:2,10,COBBLESTONE,10,MOSSY_COBBLESTONE,10,SMOOTH_BRICK,100)
RB(6,5,4,STONEBRICK:1,10,STONEBRICK:2,10,COBBLESTONE,10,MOSSY_COBBLESTONE,10,SMOOTH_BRICK,100)
RB(7,5,4,STONEBRICK:1,10,STONEBRICK:2,10,COBBLESTONE,10,MOSSY_COBBLESTONE,10,SMOOTH_BRICK,100)
RB(0,5,5,STONEBRICK:1,10,STONEBRICK:2,10,COBBLESTONE,10,MOSSY_COBBLESTONE,10,SMOOTH_BRICK,100)
RB(1,5,5,STONEBRICK:1,10,STONEBRICK:2,10,COBBLESTONE,10,MOSSY_COBBLESTONE,10,SMOOTH_BRICK,100)
RB(2,5,5,STONEBRICK:1,10,STONEBRICK:2,10,COBBLESTONE,10,MOSSY_COBBLESTONE,10,SMOOTH_BRICK,100)
RB(3,5,5,STONEBRICK:1,10,STONEBRICK:2,10,COBBLESTONE,10,MOSSY_COBBLESTONE,10,SMOOTH_BRICK,100)
RB(4,5,5,STONEBRICK:1,10,STONEBRICK:2,10,COBBLESTONE,10,MOSSY_COBBLESTONE,10,SMOOTH_BRICK,100)
RB(5,5,5,STONEBRICK:1,10,STONEBRICK:2,10,COBBLESTONE,10,MOSSY_COBBLESTONE,10,SMOOTH_BRICK,100)
RB(6,5,5,STONEBRICK:1,10,STONEBRICK:2,10,COBBLESTONE,10,MOSSY_COBBLESTONE,10,SMOOTH_BRICK,100)
RB(7,5,5,STONEBRICK:1,10,STONEBRICK:2,10,COBBLESTONE,10,MOSSY_COBBLESTONE,10,SMOOTH_BRICK,100)
RB(0,5,6,STONEBRICK:1,10,STONEBRICK:2,10,COBBLESTONE,10,MOSSY_COBBLESTONE,10,SMOOTH_BRICK,100)
RB(1,5,6,STONEBRICK:1,10,STONEBRICK:2,10,COBBLESTONE,10,MOSSY_COBBLESTONE,10,SMOOTH_BRICK,100)
RB(2,5,6,STONEBRICK:1,10,STONEBRICK:2,10,COBBLESTONE,10,MOSSY_COBBLESTONE,10,SMOOTH_BRICK,100)
RB(3,5,6,STONEBRICK:1,10,STONEBRICK:2,10,COBBLESTONE,10,MOSSY_COBBLESTONE,10,SMOOTH_BRICK,100)
RB(4,5,6,STONEBRICK:1,10,STONEBRICK:2,10,COBBLESTONE,10,MOSSY_COBBLESTONE,10,SMOOTH_BRICK,100)
RB(5,5,6,STONEBRICK:1,10,STONEBRICK:2,10,COBBLESTONE,10,MOSSY_COBBLESTONE,10,SMOOTH_BRICK,100)
RB(6,5,6,STONEBRICK:1,10,STONEBRICK:2,10,COBBLESTONE,10,MOSSY_COBBLESTONE,10,SMOOTH_BRICK,100)
RB(7,5,6,STONEBRICK:1,10,STONEBRICK:2,10,COBBLESTONE,10,MOSSY_COBBLESTONE,10,SMOOTH_BRICK,100)
RB(0,5,7,STONEBRICK:1,10,STONEBRICK:2,10,COBBLESTONE,10,MOSSY_COBBLESTONE,10,SMOOTH_BRICK,100)
RB(1,5,7,STONEBRICK:1,10,STONEBRICK:2,10,COBBLESTONE,10,MOSSY_COBBLESTONE,10,SMOOTH_BRICK,100)
RB(2,5,7,STONEBRICK:1,10,STONEBRICK:2,10,COBBLESTONE,10,MOSSY_COBBLESTONE,10,SMOOTH_BRICK,100)
RB(3,5,7,STONEBRICK:1,10,STONEBRICK:2,10,COBBLESTONE,10,MOSSY_COBBLESTONE,10,SMOOTH_BRICK,100)
RB(4,5,7,STONEBRICK:1,10,STONEBRICK:2,10,COBBLESTONE,10,MOSSY_COBBLESTONE,10,SMOOTH_BRICK,100)
RB(5,5,7,STONEBRICK:1,10,STONEBRICK:2,10,COBBLESTONE,10,MOSSY_COBBLESTONE,10,SMOOTH_BRICK,100)
RB(6,5,7,STONEBRICK:1,10,STONEBRICK:2,10,COBBLESTONE,10,MOSSY_COBBLESTONE,10,SMOOTH_BRICK,100)
RB(7,5,7,STONEBRICK:1,10,STONEBRICK:2,10,COBBLESTONE,10,MOSSY_COBBLESTONE,10,SMOOTH_BRICK,100)
RB(0,6,0,STONEBRICK:1,10,STONEBRICK:2,10,COBBLESTONE,10,MOSSY_COBBLESTONE,10,SMOOTH_BRICK,100)
RB(1,6,0,STONEBRICK:1,10,STONEBRICK:2,10,COBBLESTONE,10,MOSSY_COBBLESTONE,10,SMOOTH_BRICK,100)
RB(2,6,0,STONEBRICK:1,10,STONEBRICK:2,10,COBBLESTONE,10,MOSSY_COBBLESTONE,10,SMOOTH_BRICK,100)
RB(3,6,0,STONEBRICK:1,10,STONEBRICK:2,10,COBBLESTONE,10,MOSSY_COBBLESTONE,10,SMOOTH_BRICK,100)
RB(4,6,0,STONEBRICK:1,10,STONEBRICK:2,10,COBBLESTONE,10,MOSSY_COBBLESTONE,10,SMOOTH_BRICK,100)
RB(5,6,0,STONEBRICK:1,10,STONEBRICK:2,10,COBBLESTONE,10,MOSSY_COBBLESTONE,10,SMOOTH_BRICK,100)
RB(6,6,0,STONEBRICK:1,10,STONEBRICK:2,10,COBBLESTONE,10,MOSSY_COBBLESTONE,10,SMOOTH_BRICK,100)
RB(7,6,0,STONEBRICK:1,10,STONEBRICK:2,10,COBBLESTONE,10,MOSSY_COBBLESTONE,10,SMOOTH_BRICK,100)
RB(0,6,1,STONEBRICK:1,10,STONEBRICK:2,10,COBBLESTONE,10,MOSSY_COBBLESTONE,10,SMOOTH_BRICK,100)
RB(1,6,1,STONEBRICK:1,10,STONEBRICK:2,10,COBBLESTONE,10,MOSSY_COBBLESTONE,10,SMOOTH_BRICK,100)
RB(2,6,1,STONEBRICK:1,10,STONEBRICK:2,10,COBBLESTONE,10,MOSSY_COBBLESTONE,10,SMOOTH_BRICK,100)
RB(3,6,1,STONEBRICK:1,10,STONEBRICK:2,10,COBBLESTONE,10,MOSSY_COBBLESTONE,10,SMOOTH_BRICK,100)
RB(4,6,1,STONEBRICK:1,10,STONEBRICK:2,10,COBBLESTONE,10,MOSSY_COBBLESTONE,10,SMOOTH_BRICK,100)
RB(5,6,1,STONEBRICK:1,10,STONEBRICK:2,10,COBBLESTONE,10,MOSSY_COBBLESTONE,10,SMOOTH_BRICK,100)
RB(6,6,1,STONEBRICK:1,10,STONEBRICK:2,10,COBBLESTONE,10,MOSSY_COBBLESTONE,10,SMOOTH_BRICK,100)
RB(7,6,1,STONEBRICK:1,10,STONEBRICK:2,10,COBBLESTONE,10,MOSSY_COBBLESTONE,10,SMOOTH_BRICK,100)
RB(0,6,2,STONEBRICK:1,10,STONEBRICK:2,10,COBBLESTONE,10,MOSSY_COBBLESTONE,10,SMOOTH_BRICK,100)
RB(1,6,2,STONEBRICK:1,10,STONEBRICK:2,10,COBBLESTONE,10,MOSSY_COBBLESTONE,10,SMOOTH_BRICK,100)
RB(2,6,2,STONEBRICK:1,10,STONEBRICK:2,10,COBBLESTONE,10,MOSSY_COBBLESTONE,10,SMOOTH_BRICK,100)
RB(3,6,2,STONEBRICK:1,10,STONEBRICK:2,10,COBBLESTONE,10,MOSSY_COBBLESTONE,10,SMOOTH_BRICK,100)
RB(4,6,2,STONEBRICK:1,10,STONEBRICK:2,10,COBBLESTONE,10,MOSSY_COBBLESTONE,10,SMOOTH_BRICK,100)
RB(5,6,2,STONEBRICK:1,10,STONEBRICK:2,10,COBBLESTONE,10,MOSSY_COBBLESTONE,10,SMOOTH_BRICK,100)
RB(6,6,2,STONEBRICK:1,10,STONEBRICK:2,10,COBBLESTONE,10,MOSSY_COBBLESTONE,10,SMOOTH_BRICK,100)
RB(7,6,2,STONEBRICK:1,10,STONEBRICK:2,10,COBBLESTONE,10,MOSSY_COBBLESTONE,10,SMOOTH_BRICK,100)
RB(0,6,3,STONEBRICK:1,10,STONEBRICK:2,10,COBBLESTONE,10,MOSSY_COBBLESTONE,10,SMOOTH_BRICK,100)
RB(1,6,3,STONEBRICK:1,10,STONEBRICK:2,10,COBBLESTONE,10,MOSSY_COBBLESTONE,10,SMOOTH_BRICK,100)
RB(2,6,3,STONEBRICK:1,10,STONEBRICK:2,10,COBBLESTONE,10,MOSSY_COBBLESTONE,10,SMOOTH_BRICK,100)
RB(3,6,3,STONEBRICK:1,10,STONEBRICK:2,10,COBBLESTONE,10,MOSSY_COBBLESTONE,10,SMOOTH_BRICK,100)
RB(4,6,3,STONEBRICK:1,10,STONEBRICK:2,10,COBBLESTONE,10,MOSSY_COBBLESTONE,10,SMOOTH_BRICK,100)
RB(5,6,3,STONEBRICK:1,10,STONEBRICK:2,10,COBBLESTONE,10,MOSSY_COBBLESTONE,10,SMOOTH_BRICK,100)
RB(6,6,3,STONEBRICK:1,10,STONEBRICK:2,10,COBBLESTONE,10,MOSSY_COBBLESTONE,10,SMOOTH_BRICK,100)
RB(7,6,3,STONEBRICK:1,10,STONEBRICK:2,10,COBBLESTONE,10,MOSSY_COBBLESTONE,10,SMOOTH_BRICK,100)
RB(0,6,4,STONEBRICK:1,10,STONEBRICK:2,10,COBBLESTONE,10,MOSSY_COBBLESTONE,10,SMOOTH_BRICK,100)
RB(1,6,4,STONEBRICK:1,10,STONEBRICK:2,10,COBBLESTONE,10,MOSSY_COBBLESTONE,10,SMOOTH_BRICK,100)
RB(2,6,4,STONEBRICK:1,10,STONEBRICK:2,10,COBBLESTONE,10,MOSSY_COBBLESTONE,10,SMOOTH_BRICK,100)
RB(3,6,4,STONEBRICK:1,10,STONEBRICK:2,10,COBBLESTONE,10,MOSSY_COBBLESTONE,10,SMOOTH_BRICK,100)
RB(4,6,4,STONEBRICK:1,10,STONEBRICK:2,10,COBBLESTONE,10,MOSSY_COBBLESTONE,10,SMOOTH_BRICK,100)
RB(5,6,4,STONEBRICK:1,10,STONEBRICK:2,10,COBBLESTONE,10,MOSSY_COBBLESTONE,10,SMOOTH_BRICK,100)
RB(6,6,4,STONEBRICK:1,10,STONEBRICK:2,10,COBBLESTONE,10,MOSSY_COBBLESTONE,10,SMOOTH_BRICK,100)
RB(7,6,4,STONEBRICK:1,10,STONEBRICK:2,10,COBBLESTONE,10,MOSSY_COBBLESTONE,10,SMOOTH_BRICK,100)
RB(0,6,5,STONEBRICK:1,10,STONEBRICK:2,10,COBBLESTONE,10,MOSSY_COBBLESTONE,10,SMOOTH_BRICK,100)
RB(1,6,5,STONEBRICK:1,10,STONEBRICK:2,10,COBBLESTONE,10,MOSSY_COBBLESTONE,10,SMOOTH_BRICK,100)
RB(2,6,5,STONEBRICK:1,10,STONEBRICK:2,10,COBBLESTONE,10,MOSSY_COBBLESTONE,10,SMOOTH_BRICK,100)
RB(3,6,5,STONEBRICK:1,10,STONEBRICK:2,10,COBBLESTONE,10,MOSSY_COBBLESTONE,10,SMOOTH_BRICK,100)
RB(4,6,5,STONEBRICK:1,10,STONEBRICK:2,10,COBBLESTONE,10,MOSSY_COBBLESTONE,10,SMOOTH_BRICK,100)
RB(5,6,5,STONEBRICK:1,10,STONEBRICK:2,10,COBBLESTONE,10,MOSSY_COBBLESTONE,10,SMOOTH_BRICK,100)
RB(6,6,5,STONEBRICK:1,10,STONEBRICK:2,10,COBBLESTONE,10,MOSSY_COBBLESTONE,10,SMOOTH_BRICK,100)
RB(7,6,5,STONEBRICK:1,10,STONEBRICK:2,10,COBBLESTONE,10,MOSSY_COBBLESTONE,10,SMOOTH_BRICK,100)
RB(0,6,6,STONEBRICK:1,10,STONEBRICK:2,10,COBBLESTONE,10,MOSSY_COBBLESTONE,10,SMOOTH_BRICK,100)
RB(1,6,6,STONEBRICK:1,10,STONEBRICK:2,10,COBBLESTONE,10,MOSSY_COBBLESTONE,10,SMOOTH_BRICK,100)
RB(2,6,6,STONEBRICK:1,10,STONEBRICK:2,10,COBBLESTONE,10,MOSSY_COBBLESTONE,10,SMOOTH_BRICK,100)
RB(3,6,6,STONEBRICK:1,10,STONEBRICK:2,10,COBBLESTONE,10,MOSSY_COBBLESTONE,10,SMOOTH_BRICK,100)
RB(4,6,6,STONEBRICK:1,10,STONEBRICK:2,10,COBBLESTONE,10,MOSSY_COBBLESTONE,10,SMOOTH_BRICK,100)
RB(5,6,6,STONEBRICK:1,10,STONEBRICK:2,10,COBBLESTONE,10,MOSSY_COBBLESTONE,10,SMOOTH_BRICK,100)
RB(6,6,6,STONEBRICK:1,10,STONEBRICK:2,10,COBBLESTONE,10,MOSSY_COBBLESTONE,10,SMOOTH_BRICK,100)
RB(7,6,6,STONEBRICK:1,10,STONEBRICK:2,10,COBBLESTONE,10,MOSSY_COBBLESTONE,10,SMOOTH_BRICK,100)
RB(0,6,7,STONEBRICK:1,10,STONEBRICK:2,10,COBBLESTONE,10,MOSSY_COBBLESTONE,10,SMOOTH_BRICK,100)
RB(1,6,7,STONEBRICK:1,10,STONEBRICK:2,10,COBBLESTONE,10,MOSSY_COBBLESTONE,10,SMOOTH_BRICK,100)
RB(2,6,7,STONEBRICK:1,10,STONEBRICK:2,10,COBBLESTONE,10,MOSSY_COBBLESTONE,10,SMOOTH_BRICK,100)
RB(3,6,7,STONEBRICK:1,10,STONEBRICK:2,10,COBBLESTONE,10,MOSSY_COBBLESTONE,10,SMOOTH_BRICK,100)
RB(4,6,7,STONEBRICK:1,10,STONEBRICK:2,10,COBBLESTONE,10,MOSSY_COBBLESTONE,10,SMOOTH_BRICK,100)
RB(5,6,7,STONEBRICK:1,10,STONEBRICK:2,10,COBBLESTONE,10,MOSSY_COBBLESTONE,10,SMOOTH_BRICK,100)
RB(6,6,7,STONEBRICK:1,10,STONEBRICK:2,10,COBBLESTONE,10,MOSSY_COBBLESTONE,10,SMOOTH_BRICK,100)
RB(7,6,7,STONEBRICK:1,10,STONEBRICK:2,10,COBBLESTONE,10,MOSSY_COBBLESTONE,10,SMOOTH_BRICK,100)
B(0,7,0,AIR)
B(1,7,0,AIR)
B(2,7,0,AIR)
RB(3,7,0,SKULL:1,./StructureNBT/Skulls/dungeon_skull_01.nbt,6,AIR,9,SKULL:1,./StructureNBT/Skulls/dungeon_skull_02.nbt,12,AIR,15,SKULL:1,./StructureNBT/Skulls/dungeon_skull_03.nbt,18,AIR,21,SKULL:1,./StructureNBT/Skulls/dungeon_skull_04.nbt,24,AIR,27,SKULL:1,./StructureNBT/Skulls/dungeon_skull_05.nbt,30,AIR,33,SKULL:1,./StructureNBT/Skulls/dungeon_skull_06.nbt,36,AIR,39,SKULL:1,./StructureNBT/Skulls/dungeon_skull_07.nbt,42,AIR,45,SKULL:1,./StructureNBT/Skulls/dungeon_skull_08.nbt,48,AIR,51,SKULL:1,./StructureNBT/Skulls/dungeon_skull_09.nbt,54,AIR,57,SKULL:1,./StructureNBT/Skulls/dungeon_skull_10.nbt,60,AIR,63,SKULL:1,./StructureNBT/Skulls/dungeon_skull_11.nbt,66,AIR,69,SKULL:1,./StructureNBT/Skulls/dungeon_skull_12.nbt,72,AIR,75,SKULL:1,./StructureNBT/Skulls/dungeon_skull_13.nbt,78,AIR,81,SKULL:1,./StructureNBT/Skulls/dungeon_skull_14.nbt,84,AIR,87,SKULL:1,./StructureNBT/Skulls/dungeon_skull_15.nbt,90,AIR,93,SKULL:1,./StructureNBT/Skulls/dungeon_skull_16.nbt,96,AIR,100)
B(4,7,0,STONE_BRICK_STAIRS:0)
RB(5,7,0,STONEBRICK:1,10,STONEBRICK:2,10,COBBLESTONE,10,MOSSY_COBBLESTONE,10,SMOOTH_BRICK,100)
RB(6,7,0,STONEBRICK:1,10,STONEBRICK:2,10,COBBLESTONE,10,MOSSY_COBBLESTONE,10,SMOOTH_BRICK,100)
B(7,7,0,STONE_SLAB)
B(0,7,1,AIR)
B(1,7,1,AIR)
B(2,7,1,AIR)
RB(3,7,1,SKULL:1,./StructureNBT/Skulls/dungeon_skull_01.nbt,6,AIR,9,SKULL:1,./StructureNBT/Skulls/dungeon_skull_02.nbt,12,AIR,15,SKULL:1,./StructureNBT/Skulls/dungeon_skull_03.nbt,18,AIR,21,SKULL:1,./StructureNBT/Skulls/dungeon_skull_04.nbt,24,AIR,27,SKULL:1,./StructureNBT/Skulls/dungeon_skull_05.nbt,30,AIR,33,SKULL:1,./StructureNBT/Skulls/dungeon_skull_06.nbt,36,AIR,39,SKULL:1,./StructureNBT/Skulls/dungeon_skull_07.nbt,42,AIR,45,SKULL:1,./StructureNBT/Skulls/dungeon_skull_08.nbt,48,AIR,51,SKULL:1,./StructureNBT/Skulls/dungeon_skull_09.nbt,54,AIR,57,SKULL:1,./StructureNBT/Skulls/dungeon_skull_10.nbt,60,AIR,63,SKULL:1,./StructureNBT/Skulls/dungeon_skull_11.nbt,66,AIR,69,SKULL:1,./StructureNBT/Skulls/dungeon_skull_12.nbt,72,AIR,75,SKULL:1,./StructureNBT/Skulls/dungeon_skull_13.nbt,78,AIR,81,SKULL:1,./StructureNBT/Skulls/dungeon_skull_14.nbt,84,AIR,87,SKULL:1,./StructureNBT/Skulls/dungeon_skull_15.nbt,90,AIR,93,SKULL:1,./StructureNBT/Skulls/dungeon_skull_16.nbt,96,AIR,100)
B(4,7,1,STONE_BRICK_STAIRS:0)
RB(5,7,1,STONEBRICK:1,10,STONEBRICK:2,10,COBBLESTONE,10,MOSSY_COBBLESTONE,10,SMOOTH_BRICK,100)
RB(6,7,1,STONEBRICK:1,10,STONEBRICK:2,10,COBBLESTONE,10,MOSSY_COBBLESTONE,10,SMOOTH_BRICK,100)
B(7,7,1,STONE_SLAB)
B(0,7,2,AIR)
B(1,7,2,AIR)
B(2,7,2,AIR)
RB(3,7,2,SKULL:1,./StructureNBT/Skulls/dungeon_skull_01.nbt,6,AIR,9,SKULL:1,./StructureNBT/Skulls/dungeon_skull_02.nbt,12,AIR,15,SKULL:1,./StructureNBT/Skulls/dungeon_skull_03.nbt,18,AIR,21,SKULL:1,./StructureNBT/Skulls/dungeon_skull_04.nbt,24,AIR,27,SKULL:1,./StructureNBT/Skulls/dungeon_skull_05.nbt,30,AIR,33,SKULL:1,./StructureNBT/Skulls/dungeon_skull_06.nbt,36,AIR,39,SKULL:1,./StructureNBT/Skulls/dungeon_skull_07.nbt,42,AIR,45,SKULL:1,./StructureNBT/Skulls/dungeon_skull_08.nbt,48,AIR,51,SKULL:1,./StructureNBT/Skulls/dungeon_skull_09.nbt,54,AIR,57,SKULL:1,./StructureNBT/Skulls/dungeon_skull_10.nbt,60,AIR,63,SKULL:1,./StructureNBT/Skulls/dungeon_skull_11.nbt,66,AIR,69,SKULL:1,./StructureNBT/Skulls/dungeon_skull_12.nbt,72,AIR,75,SKULL:1,./StructureNBT/Skulls/dungeon_skull_13.nbt,78,AIR,81,SKULL:1,./StructureNBT/Skulls/dungeon_skull_14.nbt,84,AIR,87,SKULL:1,./StructureNBT/Skulls/dungeon_skull_15.nbt,90,AIR,93,SKULL:1,./StructureNBT/Skulls/dungeon_skull_16.nbt,96,AIR,100)
B(4,7,2,STONE_BRICK_STAIRS:0)
RB(5,7,2,STONEBRICK:1,10,STONEBRICK:2,10,COBBLESTONE,10,MOSSY_COBBLESTONE,10,SMOOTH_BRICK,100)
RB(6,7,2,STONEBRICK:1,10,STONEBRICK:2,10,COBBLESTONE,10,MOSSY_COBBLESTONE,10,SMOOTH_BRICK,100)
B(7,7,2,STONE_SLAB)
RB(0,7,3,SKULL:1,./StructureNBT/Skulls/dungeon_skull_01.nbt,6,AIR,9,SKULL:1,./StructureNBT/Skulls/dungeon_skull_02.nbt,12,AIR,15,SKULL:1,./StructureNBT/Skulls/dungeon_skull_03.nbt,18,AIR,21,SKULL:1,./StructureNBT/Skulls/dungeon_skull_04.nbt,24,AIR,27,SKULL:1,./StructureNBT/Skulls/dungeon_skull_05.nbt,30,AIR,33,SKULL:1,./StructureNBT/Skulls/dungeon_skull_06.nbt,36,AIR,39,SKULL:1,./StructureNBT/Skulls/dungeon_skull_07.nbt,42,AIR,45,SKULL:1,./StructureNBT/Skulls/dungeon_skull_08.nbt,48,AIR,51,SKULL:1,./StructureNBT/Skulls/dungeon_skull_09.nbt,54,AIR,57,SKULL:1,./StructureNBT/Skulls/dungeon_skull_10.nbt,60,AIR,63,SKULL:1,./StructureNBT/Skulls/dungeon_skull_11.nbt,66,AIR,69,SKULL:1,./StructureNBT/Skulls/dungeon_skull_12.nbt,72,AIR,75,SKULL:1,./StructureNBT/Skulls/dungeon_skull_13.nbt,78,AIR,81,SKULL:1,./StructureNBT/Skulls/dungeon_skull_14.nbt,84,AIR,87,SKULL:1,./StructureNBT/Skulls/dungeon_skull_15.nbt,90,AIR,93,SKULL:1,./StructureNBT/Skulls/dungeon_skull_16.nbt,96,AIR,100)
B(1,7,3,AIR)
RB(2,7,3,SKULL:1,./StructureNBT/Skulls/dungeon_skull_01.nbt,6,AIR,9,SKULL:1,./StructureNBT/Skulls/dungeon_skull_02.nbt,12,AIR,15,SKULL:1,./StructureNBT/Skulls/dungeon_skull_03.nbt,18,AIR,21,SKULL:1,./StructureNBT/Skulls/dungeon_skull_04.nbt,24,AIR,27,SKULL:1,./StructureNBT/Skulls/dungeon_skull_05.nbt,30,AIR,33,SKULL:1,./StructureNBT/Skulls/dungeon_skull_06.nbt,36,AIR,39,SKULL:1,./StructureNBT/Skulls/dungeon_skull_07.nbt,42,AIR,45,SKULL:1,./StructureNBT/Skulls/dungeon_skull_08.nbt,48,AIR,51,SKULL:1,./StructureNBT/Skulls/dungeon_skull_09.nbt,54,AIR,57,SKULL:1,./StructureNBT/Skulls/dungeon_skull_10.nbt,60,AIR,63,SKULL:1,./StructureNBT/Skulls/dungeon_skull_11.nbt,66,AIR,69,SKULL:1,./StructureNBT/Skulls/dungeon_skull_12.nbt,72,AIR,75,SKULL:1,./StructureNBT/Skulls/dungeon_skull_13.nbt,78,AIR,81,SKULL:1,./StructureNBT/Skulls/dungeon_skull_14.nbt,84,AIR,87,SKULL:1,./StructureNBT/Skulls/dungeon_skull_15.nbt,90,AIR,93,SKULL:1,./StructureNBT/Skulls/dungeon_skull_16.nbt,96,AIR,100)
B(3,7,3,STONE_BRICK_STAIRS:0)
RB(4,7,3,STONEBRICK:1,10,STONEBRICK:2,10,COBBLESTONE,10,MOSSY_COBBLESTONE,10,SMOOTH_BRICK,100)
RB(5,7,3,STONEBRICK:1,10,STONEBRICK:2,10,COBBLESTONE,10,MOSSY_COBBLESTONE,10,SMOOTH_BRICK,100)
RB(6,7,3,STONEBRICK:1,10,STONEBRICK:2,10,COBBLESTONE,10,MOSSY_COBBLESTONE,10,SMOOTH_BRICK,100)
RB(7,7,3,STONEBRICK:1,10,STONEBRICK:2,10,COBBLESTONE,10,MOSSY_COBBLESTONE,10,SMOOTH_BRICK,100)
B(0,7,4,AIR)
B(1,7,4,AIR)
RB(2,7,4,SKULL:1,./StructureNBT/Skulls/dungeon_skull_01.nbt,6,AIR,9,SKULL:1,./StructureNBT/Skulls/dungeon_skull_02.nbt,12,AIR,15,SKULL:1,./StructureNBT/Skulls/dungeon_skull_03.nbt,18,AIR,21,SKULL:1,./StructureNBT/Skulls/dungeon_skull_04.nbt,24,AIR,27,SKULL:1,./StructureNBT/Skulls/dungeon_skull_05.nbt,30,AIR,33,SKULL:1,./StructureNBT/Skulls/dungeon_skull_06.nbt,36,AIR,39,SKULL:1,./StructureNBT/Skulls/dungeon_skull_07.nbt,42,AIR,45,SKULL:1,./StructureNBT/Skulls/dungeon_skull_08.nbt,48,AIR,51,SKULL:1,./StructureNBT/Skulls/dungeon_skull_09.nbt,54,AIR,57,SKULL:1,./StructureNBT/Skulls/dungeon_skull_10.nbt,60,AIR,63,SKULL:1,./StructureNBT/Skulls/dungeon_skull_11.nbt,66,AIR,69,SKULL:1,./StructureNBT/Skulls/dungeon_skull_12.nbt,72,AIR,75,SKULL:1,./StructureNBT/Skulls/dungeon_skull_13.nbt,78,AIR,81,SKULL:1,./StructureNBT/Skulls/dungeon_skull_14.nbt,84,AIR,87,SKULL:1,./StructureNBT/Skulls/dungeon_skull_15.nbt,90,AIR,93,SKULL:1,./StructureNBT/Skulls/dungeon_skull_16.nbt,96,AIR,100)
B(3,7,4,AIR)
RB(4,7,4,STONEBRICK:1,10,STONEBRICK:2,10,COBBLESTONE,10,MOSSY_COBBLESTONE,10,SMOOTH_BRICK,100)
B(5,7,4,LAVA:8)
RB(6,7,4,STONEBRICK:1,10,STONEBRICK:2,10,COBBLESTONE,10,MOSSY_COBBLESTONE,10,SMOOTH_BRICK,100)
B(7,7,4,STONE_SLAB)
B(0,7,5,AIR)
B(1,7,5,AIR)
B(2,7,5,AIR)
B(3,7,5,STONE_BRICK_STAIRS:0)
RB(4,7,5,STONEBRICK:1,10,STONEBRICK:2,10,COBBLESTONE,10,MOSSY_COBBLESTONE,10,SMOOTH_BRICK,100)
RB(5,7,5,STONEBRICK:1,10,STONEBRICK:2,10,COBBLESTONE,10,MOSSY_COBBLESTONE,10,SMOOTH_BRICK,100)
RB(6,7,5,STONEBRICK:1,10,STONEBRICK:2,10,COBBLESTONE,10,MOSSY_COBBLESTONE,10,SMOOTH_BRICK,100)
RB(7,7,5,STONEBRICK:1,10,STONEBRICK:2,10,COBBLESTONE,10,MOSSY_COBBLESTONE,10,SMOOTH_BRICK,100)
B(0,7,6,AIR)
B(1,7,6,AIR)
B(2,7,6,AIR)
RB(3,7,6,SKULL:1,./StructureNBT/Skulls/dungeon_skull_01.nbt,6,AIR,9,SKULL:1,./StructureNBT/Skulls/dungeon_skull_02.nbt,12,AIR,15,SKULL:1,./StructureNBT/Skulls/dungeon_skull_03.nbt,18,AIR,21,SKULL:1,./StructureNBT/Skulls/dungeon_skull_04.nbt,24,AIR,27,SKULL:1,./StructureNBT/Skulls/dungeon_skull_05.nbt,30,AIR,33,SKULL:1,./StructureNBT/Skulls/dungeon_skull_06.nbt,36,AIR,39,SKULL:1,./StructureNBT/Skulls/dungeon_skull_07.nbt,42,AIR,45,SKULL:1,./StructureNBT/Skulls/dungeon_skull_08.nbt,48,AIR,51,SKULL:1,./StructureNBT/Skulls/dungeon_skull_09.nbt,54,AIR,57,SKULL:1,./StructureNBT/Skulls/dungeon_skull_10.nbt,60,AIR,63,SKULL:1,./StructureNBT/Skulls/dungeon_skull_11.nbt,66,AIR,69,SKULL:1,./StructureNBT/Skulls/dungeon_skull_12.nbt,72,AIR,75,SKULL:1,./StructureNBT/Skulls/dungeon_skull_13.nbt,78,AIR,81,SKULL:1,./StructureNBT/Skulls/dungeon_skull_14.nbt,84,AIR,87,SKULL:1,./StructureNBT/Skulls/dungeon_skull_15.nbt,90,AIR,93,SKULL:1,./StructureNBT/Skulls/dungeon_skull_16.nbt,96,AIR,100)
B(4,7,6,STONE_BRICK_STAIRS:0)
RB(5,7,6,STONEBRICK:1,10,STONEBRICK:2,10,COBBLESTONE,10,MOSSY_COBBLESTONE,10,SMOOTH_BRICK,100)
RB(6,7,6,STONEBRICK:1,10,STONEBRICK:2,10,COBBLESTONE,10,MOSSY_COBBLESTONE,10,SMOOTH_BRICK,100)
B(7,7,6,STONE_SLAB)
B(0,7,7,AIR)
B(1,7,7,AIR)
B(2,7,7,AIR)
RB(3,7,7,SKULL:1,./StructureNBT/Skulls/dungeon_skull_01.nbt,6,AIR,9,SKULL:1,./StructureNBT/Skulls/dungeon_skull_02.nbt,12,AIR,15,SKULL:1,./StructureNBT/Skulls/dungeon_skull_03.nbt,18,AIR,21,SKULL:1,./StructureNBT/Skulls/dungeon_skull_04.nbt,24,AIR,27,SKULL:1,./StructureNBT/Skulls/dungeon_skull_05.nbt,30,AIR,33,SKULL:1,./StructureNBT/Skulls/dungeon_skull_06.nbt,36,AIR,39,SKULL:1,./StructureNBT/Skulls/dungeon_skull_07.nbt,42,AIR,45,SKULL:1,./StructureNBT/Skulls/dungeon_skull_08.nbt,48,AIR,51,SKULL:1,./StructureNBT/Skulls/dungeon_skull_09.nbt,54,AIR,57,SKULL:1,./StructureNBT/Skulls/dungeon_skull_10.nbt,60,AIR,63,SKULL:1,./StructureNBT/Skulls/dungeon_skull_11.nbt,66,AIR,69,SKULL:1,./StructureNBT/Skulls/dungeon_skull_12.nbt,72,AIR,75,SKULL:1,./StructureNBT/Skulls/dungeon_skull_13.nbt,78,AIR,81,SKULL:1,./StructureNBT/Skulls/dungeon_skull_14.nbt,84,AIR,87,SKULL:1,./StructureNBT/Skulls/dungeon_skull_15.nbt,90,AIR,93,SKULL:1,./StructureNBT/Skulls/dungeon_skull_16.nbt,96,AIR,100)
B(4,7,7,STONE_BRICK_STAIRS:0)
RB(5,7,7,STONEBRICK:1,10,STONEBRICK:2,10,COBBLESTONE,10,MOSSY_COBBLESTONE,10,SMOOTH_BRICK,100)
RB(6,7,7,STONEBRICK:1,10,STONEBRICK:2,10,COBBLESTONE,10,MOSSY_COBBLESTONE,10,SMOOTH_BRICK,100)
B(7,7,7,STONE_SLAB)
B(0,8,0,AIR)
B(1,8,0,AIR)
B(2,8,0,AIR)
B(3,8,0,AIR)
B(4,8,0,AIR)
B(5,8,0,IRON_BARS)
B(6,8,0,AIR)
B(7,8,0,AIR)
B(0,8,1,AIR)
B(1,8,1,AIR)
B(2,8,1,AIR)
B(3,8,1,AIR)
B(4,8,1,AIR)
B(5,8,1,IRON_BARS)
B(6,8,1,AIR)
B(7,8,1,AIR)
B(0,8,2,AIR)
B(1,8,2,AIR)
B(2,8,2,AIR)
B(3,8,2,AIR)
B(4,8,2,AIR)
B(5,8,2,IRON_BARS)
B(6,8,2,AIR)
B(7,8,2,AIR)
B(0,8,3,AIR)
B(1,8,3,AIR)
B(2,8,3,AIR)
B(3,8,3,AIR)
B(4,8,3,STONE_BRICK_STAIRS:0)
RB(5,8,3,STONEBRICK:1,10,STONEBRICK:2,10,COBBLESTONE,10,MOSSY_COBBLESTONE,10,SMOOTH_BRICK,100)
RB(6,8,3,STONEBRICK:1,10,STONEBRICK:2,10,COBBLESTONE,10,MOSSY_COBBLESTONE,10,SMOOTH_BRICK,100)
RB(7,8,3,STONEBRICK:1,10,STONEBRICK:2,10,COBBLESTONE,10,MOSSY_COBBLESTONE,10,SMOOTH_BRICK,100)
B(0,8,4,AIR)
B(1,8,4,AIR)
B(2,8,4,AIR)
B(3,8,4,AIR)
B(4,8,4,COBBLESTONE_WALL)
B(5,8,4,LAVA:8)
B(6,8,4,COBBLESTONE_WALL)
B(7,8,4,AIR)
B(0,8,5,AIR)
B(1,8,5,AIR)
B(2,8,5,AIR)
B(3,8,5,AIR)
B(4,8,5,STONE_BRICK_STAIRS:0)
RB(5,8,5,STONEBRICK:1,10,STONEBRICK:2,10,COBBLESTONE,10,MOSSY_COBBLESTONE,10,SMOOTH_BRICK,100)
RB(6,8,5,STONEBRICK:1,10,STONEBRICK:2,10,COBBLESTONE,10,MOSSY_COBBLESTONE,10,SMOOTH_BRICK,100)
RB(7,8,5,STONEBRICK:1,10,STONEBRICK:2,10,COBBLESTONE,10,MOSSY_COBBLESTONE,10,SMOOTH_BRICK,100)
B(0,8,6,AIR)
B(1,8,6,AIR)
B(2,8,6,AIR)
B(3,8,6,AIR)
B(4,8,6,AIR)
B(5,8,6,IRON_BARS)
B(6,8,6,AIR)
B(7,8,6,AIR)
B(0,8,7,AIR)
B(1,8,7,AIR)
B(2,8,7,AIR)
B(3,8,7,AIR)
B(4,8,7,AIR)
B(5,8,7,IRON_BARS)
B(6,8,7,AIR)
B(7,8,7,AIR)
B(0,9,0,AIR)
B(1,9,0,AIR)
B(2,9,0,AIR)
B(3,9,0,AIR)
B(4,9,0,AIR)
B(5,9,0,IRON_BARS)
B(6,9,0,AIR)
B(7,9,0,AIR)
B(0,9,1,AIR)
B(1,9,1,AIR)
B(2,9,1,AIR)
B(3,9,1,AIR)
B(4,9,1,AIR)
B(5,9,1,IRON_BARS)
B(6,9,1,AIR)
B(7,9,1,AIR)
B(0,9,2,AIR)
B(1,9,2,AIR)
B(2,9,2,AIR)
B(3,9,2,AIR)
B(4,9,2,AIR)
B(5,9,2,IRON_BARS)
B(6,9,2,AIR)
B(7,9,2,AIR)
B(0,9,3,AIR)
B(1,9,3,AIR)
B(2,9,3,AIR)
B(3,9,3,AIR)
B(4,9,3,STONE_BRICK_STAIRS:4)
RB(5,9,3,STONEBRICK:1,10,STONEBRICK:2,10,COBBLESTONE,10,MOSSY_COBBLESTONE,10,SMOOTH_BRICK,100)
RB(6,9,3,STONEBRICK:1,10,STONEBRICK:2,10,COBBLESTONE,10,MOSSY_COBBLESTONE,10,SMOOTH_BRICK,100)
RB(7,9,3,STONEBRICK:1,10,STONEBRICK:2,10,COBBLESTONE,10,MOSSY_COBBLESTONE,10,SMOOTH_BRICK,100)
B(0,9,4,AIR)
B(1,9,4,AIR)
B(2,9,4,AIR)
B(3,9,4,AIR)
B(4,9,4,COBBLESTONE_WALL)
B(5,9,4,LAVA:8)
B(6,9,4,COBBLESTONE_WALL)
B(7,9,4,AIR)
B(0,9,5,AIR)
B(1,9,5,AIR)
B(2,9,5,AIR)
B(3,9,5,AIR)
B(4,9,5,STONE_BRICK_STAIRS:4)
RB(5,9,5,STONEBRICK:1,10,STONEBRICK:2,10,COBBLESTONE,10,MOSSY_COBBLESTONE,10,SMOOTH_BRICK,100)
RB(6,9,5,STONEBRICK:1,10,STONEBRICK:2,10,COBBLESTONE,10,MOSSY_COBBLESTONE,10,SMOOTH_BRICK,100)
RB(7,9,5,STONEBRICK:1,10,STONEBRICK:2,10,COBBLESTONE,10,MOSSY_COBBLESTONE,10,SMOOTH_BRICK,100)
B(0,9,6,AIR)
B(1,9,6,AIR)
B(2,9,6,AIR)
B(3,9,6,AIR)
B(4,9,6,AIR)
B(5,9,6,IRON_BARS)
B(6,9,6,AIR)
B(7,9,6,AIR)
B(0,9,7,AIR)
B(1,9,7,AIR)
B(2,9,7,AIR)
B(3,9,7,AIR)
B(4,9,7,AIR)
B(5,9,7,IRON_BARS)
B(6,9,7,AIR)
B(7,9,7,AIR)
B(0,10,0,AIR)
B(1,10,0,AIR)
B(2,10,0,AIR)
B(3,10,0,AIR)
RB(4,10,0,WEB,8,AIR,100)
B(5,10,0,IRON_BARS)
RB(6,10,0,WEB,8,AIR,100)
B(7,10,0,AIR)
B(0,10,1,AIR)
B(1,10,1,AIR)
B(2,10,1,AIR)
B(3,10,1,AIR)
RB(4,10,1,WEB,8,AIR,100)
B(5,10,1,IRON_BARS)
RB(6,10,1,WEB,8,AIR,100)
B(7,10,1,AIR)
B(0,10,2,AIR)
B(1,10,2,AIR)
B(2,10,2,AIR)
B(3,10,2,AIR)
B(4,10,2,STONE_BRICK_STAIRS:6)
B(5,10,2,IRON_BARS)
B(6,10,2,STONE_BRICK_STAIRS:6)
B(7,10,2,AIR)
B(0,10,3,AIR)
B(1,10,3,AIR)
B(2,10,3,AIR)
B(3,10,3,STONE_BRICK_STAIRS:4)
RB(4,10,3,STONEBRICK:1,10,STONEBRICK:2,10,COBBLESTONE,10,MOSSY_COBBLESTONE,10,SMOOTH_BRICK,100)
RB(5,10,3,STONEBRICK:1,10,STONEBRICK:2,10,COBBLESTONE,10,MOSSY_COBBLESTONE,10,SMOOTH_BRICK,100)
RB(6,10,3,STONEBRICK:1,10,STONEBRICK:2,10,COBBLESTONE,10,MOSSY_COBBLESTONE,10,SMOOTH_BRICK,100)
RB(7,10,3,STONEBRICK:1,10,STONEBRICK:2,10,COBBLESTONE,10,MOSSY_COBBLESTONE,10,SMOOTH_BRICK,100)
B(0,10,4,AIR)
B(1,10,4,AIR)
B(2,10,4,AIR)
B(3,10,4,STONE_SLAB:8)
RB(4,10,4,STONEBRICK:1,10,STONEBRICK:2,10,COBBLESTONE,10,MOSSY_COBBLESTONE,10,SMOOTH_BRICK,100)
B(5,10,4,LAVA)
B(6,10,4,COBBLESTONE_WALL)
B(7,10,4,AIR)
B(0,10,5,AIR)
B(1,10,5,AIR)
B(2,10,5,AIR)
B(3,10,5,STONE_BRICK_STAIRS:4)
RB(4,10,5,STONEBRICK:1,10,STONEBRICK:2,10,COBBLESTONE,10,MOSSY_COBBLESTONE,10,SMOOTH_BRICK,100)
RB(5,10,5,STONEBRICK:1,10,STONEBRICK:2,10,COBBLESTONE,10,MOSSY_COBBLESTONE,10,SMOOTH_BRICK,100)
RB(6,10,5,STONEBRICK:1,10,STONEBRICK:2,10,COBBLESTONE,10,MOSSY_COBBLESTONE,10,SMOOTH_BRICK,100)
RB(7,10,5,STONEBRICK:1,10,STONEBRICK:2,10,COBBLESTONE,10,MOSSY_COBBLESTONE,10,SMOOTH_BRICK,100)
B(0,10,6,AIR)
B(1,10,6,AIR)
B(2,10,6,AIR)
B(3,10,6,AIR)
B(4,10,6,STONE_BRICK_STAIRS:7)
B(5,10,6,IRON_BARS)
B(6,10,6,STONE_BRICK_STAIRS:7)
B(7,10,6,AIR)
B(0,10,7,AIR)
B(1,10,7,AIR)
B(2,10,7,AIR)
B(3,10,7,AIR)
RB(4,10,7,WEB,8,AIR,100)
B(5,10,7,IRON_BARS)
RB(6,10,7,WEB,8,AIR,100)
B(7,10,7,AIR)
B(0,11,0,AIR)
B(1,11,0,AIR)
B(2,11,0,AIR)
RB(3,11,0,WEB,8,AIR,100)
RB(4,11,0,STONEBRICK:1,10,STONEBRICK:2,10,COBBLESTONE,10,MOSSY_COBBLESTONE,10,SMOOTH_BRICK,100)
RB(5,11,0,STONEBRICK:1,10,STONEBRICK:2,10,COBBLESTONE,10,MOSSY_COBBLESTONE,10,SMOOTH_BRICK,100)
RB(6,11,0,STONEBRICK:1,10,STONEBRICK:2,10,COBBLESTONE,10,MOSSY_COBBLESTONE,10,SMOOTH_BRICK,100)
B(7,11,0,STONE_BRICK_STAIRS:5)
B(0,11,1,AIR)
B(1,11,1,AIR)
B(2,11,1,AIR)
RB(3,11,1,WEB,8,AIR,100)
RB(4,11,1,STONEBRICK:1,10,STONEBRICK:2,10,COBBLESTONE,10,MOSSY_COBBLESTONE,10,SMOOTH_BRICK,100)
RB(5,11,1,STONEBRICK:1,10,STONEBRICK:2,10,COBBLESTONE,10,MOSSY_COBBLESTONE,10,SMOOTH_BRICK,100)
RB(6,11,1,STONEBRICK:1,10,STONEBRICK:2,10,COBBLESTONE,10,MOSSY_COBBLESTONE,10,SMOOTH_BRICK,100)
B(7,11,1,STONE_BRICK_STAIRS:5)
B(0,11,2,AIR)
B(1,11,2,AIR)
B(2,11,2,AIR)
B(3,11,2,STONE_BRICK_STAIRS:6)
RB(4,11,2,STONEBRICK:1,10,STONEBRICK:2,10,COBBLESTONE,10,MOSSY_COBBLESTONE,10,SMOOTH_BRICK,100)
RB(5,11,2,STONEBRICK:1,10,STONEBRICK:2,10,COBBLESTONE,10,MOSSY_COBBLESTONE,10,SMOOTH_BRICK,100)
RB(6,11,2,STONEBRICK:1,10,STONEBRICK:2,10,COBBLESTONE,10,MOSSY_COBBLESTONE,10,SMOOTH_BRICK,100)
B(7,11,2,STONE_BRICK_STAIRS:6)
RB(0,11,3,WEB,8,AIR,100)
RB(1,11,3,WEB,8,AIR,100)
B(2,11,3,STONE_BRICK_STAIRS:4)
RB(3,11,3,STONEBRICK:1,10,STONEBRICK:2,10,COBBLESTONE,10,MOSSY_COBBLESTONE,10,SMOOTH_BRICK,100)
RB(4,11,3,STONEBRICK:1,10,STONEBRICK:2,10,COBBLESTONE,10,MOSSY_COBBLESTONE,10,SMOOTH_BRICK,100)
RB(5,11,3,STONEBRICK:1,10,STONEBRICK:2,10,COBBLESTONE,10,MOSSY_COBBLESTONE,10,SMOOTH_BRICK,100)
RB(6,11,3,STONEBRICK:1,10,STONEBRICK:2,10,COBBLESTONE,10,MOSSY_COBBLESTONE,10,SMOOTH_BRICK,100)
RB(7,11,3,STONEBRICK:1,10,STONEBRICK:2,10,COBBLESTONE,10,MOSSY_COBBLESTONE,10,SMOOTH_BRICK,100)
B(0,11,4,STONE_SLAB:8)
B(1,11,4,STONE_SLAB:8)
B(2,11,4,STONE_SLAB:8)
RB(3,11,4,STONEBRICK:1,10,STONEBRICK:2,10,COBBLESTONE,10,MOSSY_COBBLESTONE,10,SMOOTH_BRICK,100)
RB(4,11,4,STONEBRICK:1,10,STONEBRICK:2,10,COBBLESTONE,10,MOSSY_COBBLESTONE,10,SMOOTH_BRICK,100)
RB(5,11,4,STONEBRICK:1,10,STONEBRICK:2,10,COBBLESTONE,10,MOSSY_COBBLESTONE,10,SMOOTH_BRICK,100)
RB(6,11,4,STONEBRICK:1,10,STONEBRICK:2,10,COBBLESTONE,10,MOSSY_COBBLESTONE,10,SMOOTH_BRICK,100)
B(7,11,4,STONE_BRICK_STAIRS:5)
RB(0,11,5,WEB,8,AIR,100)
RB(1,11,5,WEB,8,AIR,100)
B(2,11,5,STONE_BRICK_STAIRS:4)
RB(3,11,5,STONEBRICK:1,10,STONEBRICK:2,10,COBBLESTONE,10,MOSSY_COBBLESTONE,10,SMOOTH_BRICK,100)
RB(4,11,5,STONEBRICK:1,10,STONEBRICK:2,10,COBBLESTONE,10,MOSSY_COBBLESTONE,10,SMOOTH_BRICK,100)
RB(5,11,5,STONEBRICK:1,10,STONEBRICK:2,10,COBBLESTONE,10,MOSSY_COBBLESTONE,10,SMOOTH_BRICK,100)
RB(6,11,5,STONEBRICK:1,10,STONEBRICK:2,10,COBBLESTONE,10,MOSSY_COBBLESTONE,10,SMOOTH_BRICK,100)
RB(7,11,5,STONEBRICK:1,10,STONEBRICK:2,10,COBBLESTONE,10,MOSSY_COBBLESTONE,10,SMOOTH_BRICK,100)
B(0,11,6,AIR)
B(1,11,6,AIR)
B(2,11,6,STONE_SLAB:8)
B(3,11,6,STONE_BRICK_STAIRS:7)
RB(4,11,6,STONEBRICK:1,10,STONEBRICK:2,10,COBBLESTONE,10,MOSSY_COBBLESTONE,10,SMOOTH_BRICK,100)
RB(5,11,6,STONEBRICK:1,10,STONEBRICK:2,10,COBBLESTONE,10,MOSSY_COBBLESTONE,10,SMOOTH_BRICK,100)
RB(6,11,6,STONEBRICK:1,10,STONEBRICK:2,10,COBBLESTONE,10,MOSSY_COBBLESTONE,10,SMOOTH_BRICK,100)
B(7,11,6,STONE_SLAB:8)
B(0,11,7,AIR)
B(1,11,7,AIR)
B(2,11,7,AIR)
RB(3,11,7,WEB,8,AIR,100)
RB(4,11,7,STONEBRICK:1,10,STONEBRICK:2,10,COBBLESTONE,10,MOSSY_COBBLESTONE,10,SMOOTH_BRICK,100)
RB(5,11,7,STONEBRICK:1,10,STONEBRICK:2,10,COBBLESTONE,10,MOSSY_COBBLESTONE,10,SMOOTH_BRICK,100)
RB(6,11,7,STONEBRICK:1,10,STONEBRICK:2,10,COBBLESTONE,10,MOSSY_COBBLESTONE,10,SMOOTH_BRICK,100)
B(7,11,7,STONE_SLAB:8)
B(0,12,0,AIR)
B(1,12,0,AIR)
B(2,12,0,AIR)
RB(3,12,0,STONEBRICK:1,10,STONEBRICK:2,10,COBBLESTONE,10,MOSSY_COBBLESTONE,10,SMOOTH_BRICK,100)
RB(4,12,0,STONEBRICK:1,10,STONEBRICK:2,10,COBBLESTONE,10,MOSSY_COBBLESTONE,10,SMOOTH_BRICK,100)
RB(5,12,0,STONEBRICK:1,10,STONEBRICK:2,10,COBBLESTONE,10,MOSSY_COBBLESTONE,10,SMOOTH_BRICK,100)
RB(6,12,0,STONEBRICK:1,10,STONEBRICK:2,10,COBBLESTONE,10,MOSSY_COBBLESTONE,10,SMOOTH_BRICK,100)
RB(7,12,0,STONEBRICK:1,10,STONEBRICK:2,10,COBBLESTONE,10,MOSSY_COBBLESTONE,10,SMOOTH_BRICK,100)
B(0,12,1,AIR)
B(1,12,1,AIR)
RB(2,12,1,WEB,8,AIR,100)
RB(3,12,1,STONEBRICK:1,10,STONEBRICK:2,10,COBBLESTONE,10,MOSSY_COBBLESTONE,10,SMOOTH_BRICK,100)
RB(4,12,1,STONEBRICK:1,10,STONEBRICK:2,10,COBBLESTONE,10,MOSSY_COBBLESTONE,10,SMOOTH_BRICK,100)
RB(5,12,1,STONEBRICK:1,10,STONEBRICK:2,10,COBBLESTONE,10,MOSSY_COBBLESTONE,10,SMOOTH_BRICK,100)
RB(6,12,1,STONEBRICK:1,10,STONEBRICK:2,10,COBBLESTONE,10,MOSSY_COBBLESTONE,10,SMOOTH_BRICK,100)
RB(7,12,1,STONEBRICK:1,10,STONEBRICK:2,10,COBBLESTONE,10,MOSSY_COBBLESTONE,10,SMOOTH_BRICK,100)
B(0,12,2,STONE_SLAB:8)
B(1,12,2,STONE_SLAB:8)
B(2,12,2,STONE_BRICK_STAIRS:6)
RB(3,12,2,STONEBRICK:1,10,STONEBRICK:2,10,COBBLESTONE,10,MOSSY_COBBLESTONE,10,SMOOTH_BRICK,100)
RB(4,12,2,STONEBRICK:1,10,STONEBRICK:2,10,COBBLESTONE,10,MOSSY_COBBLESTONE,10,SMOOTH_BRICK,100)
RB(5,12,2,STONEBRICK:1,10,STONEBRICK:2,10,COBBLESTONE,10,MOSSY_COBBLESTONE,10,SMOOTH_BRICK,100)
RB(6,12,2,STONEBRICK:1,10,STONEBRICK:2,10,COBBLESTONE,10,MOSSY_COBBLESTONE,10,SMOOTH_BRICK,100)
RB(7,12,2,STONEBRICK:1,10,STONEBRICK:2,10,COBBLESTONE,10,MOSSY_COBBLESTONE,10,SMOOTH_BRICK,100)
RB(0,12,3,STONEBRICK:1,10,STONEBRICK:2,10,COBBLESTONE,10,MOSSY_COBBLESTONE,10,SMOOTH_BRICK,100)
RB(1,12,3,STONEBRICK:1,10,STONEBRICK:2,10,COBBLESTONE,10,MOSSY_COBBLESTONE,10,SMOOTH_BRICK,100)
RB(2,12,3,STONEBRICK:1,10,STONEBRICK:2,10,COBBLESTONE,10,MOSSY_COBBLESTONE,10,SMOOTH_BRICK,100)
RB(3,12,3,STONEBRICK:1,10,STONEBRICK:2,10,COBBLESTONE,10,MOSSY_COBBLESTONE,10,SMOOTH_BRICK,100)
RB(4,12,3,STONEBRICK:1,10,STONEBRICK:2,10,COBBLESTONE,10,MOSSY_COBBLESTONE,10,SMOOTH_BRICK,100)
RB(5,12,3,STONEBRICK:1,10,STONEBRICK:2,10,COBBLESTONE,10,MOSSY_COBBLESTONE,10,SMOOTH_BRICK,100)
RB(6,12,3,STONEBRICK:1,10,STONEBRICK:2,10,COBBLESTONE,10,MOSSY_COBBLESTONE,10,SMOOTH_BRICK,100)
RB(7,12,3,STONEBRICK:1,10,STONEBRICK:2,10,COBBLESTONE,10,MOSSY_COBBLESTONE,10,SMOOTH_BRICK,100)
B(0,12,4,DOUBLE_STONE_SLAB)
B(1,12,4,DOUBLE_STONE_SLAB)
B(2,12,4,DOUBLE_STONE_SLAB)
RB(3,12,4,STONEBRICK:1,10,STONEBRICK:2,10,COBBLESTONE,10,MOSSY_COBBLESTONE,10,SMOOTH_BRICK,100)
RB(4,12,4,STONEBRICK:1,10,STONEBRICK:2,10,COBBLESTONE,10,MOSSY_COBBLESTONE,10,SMOOTH_BRICK,100)
RB(5,12,4,STONEBRICK:1,10,STONEBRICK:2,10,COBBLESTONE,10,MOSSY_COBBLESTONE,10,SMOOTH_BRICK,100)
RB(6,12,4,STONEBRICK:1,10,STONEBRICK:2,10,COBBLESTONE,10,MOSSY_COBBLESTONE,10,SMOOTH_BRICK,100)
RB(7,12,4,STONEBRICK:1,10,STONEBRICK:2,10,COBBLESTONE,10,MOSSY_COBBLESTONE,10,SMOOTH_BRICK,100)
RB(0,12,5,STONEBRICK:1,10,STONEBRICK:2,10,COBBLESTONE,10,MOSSY_COBBLESTONE,10,SMOOTH_BRICK,100)
RB(1,12,5,STONEBRICK:1,10,STONEBRICK:2,10,COBBLESTONE,10,MOSSY_COBBLESTONE,10,SMOOTH_BRICK,100)
RB(2,12,5,STONEBRICK:1,10,STONEBRICK:2,10,COBBLESTONE,10,MOSSY_COBBLESTONE,10,SMOOTH_BRICK,100)
RB(3,12,5,STONEBRICK:1,10,STONEBRICK:2,10,COBBLESTONE,10,MOSSY_COBBLESTONE,10,SMOOTH_BRICK,100)
RB(4,12,5,STONEBRICK:1,10,STONEBRICK:2,10,COBBLESTONE,10,MOSSY_COBBLESTONE,10,SMOOTH_BRICK,100)
RB(5,12,5,STONEBRICK:1,10,STONEBRICK:2,10,COBBLESTONE,10,MOSSY_COBBLESTONE,10,SMOOTH_BRICK,100)
RB(6,12,5,STONEBRICK:1,10,STONEBRICK:2,10,COBBLESTONE,10,MOSSY_COBBLESTONE,10,SMOOTH_BRICK,100)
RB(7,12,5,STONEBRICK:1,10,STONEBRICK:2,10,COBBLESTONE,10,MOSSY_COBBLESTONE,10,SMOOTH_BRICK,100)
B(0,12,6,DOUBLE_STONE_SLAB)
B(1,12,6,DOUBLE_STONE_SLAB)
RB(2,12,6,STONEBRICK:1,10,STONEBRICK:2,10,COBBLESTONE,10,MOSSY_COBBLESTONE,10,SMOOTH_BRICK,100)
RB(3,12,6,STONEBRICK:1,10,STONEBRICK:2,10,COBBLESTONE,10,MOSSY_COBBLESTONE,10,SMOOTH_BRICK,100)
RB(4,12,6,STONEBRICK:1,10,STONEBRICK:2,10,COBBLESTONE,10,MOSSY_COBBLESTONE,10,SMOOTH_BRICK,100)
RB(5,12,6,STONEBRICK:1,10,STONEBRICK:2,10,COBBLESTONE,10,MOSSY_COBBLESTONE,10,SMOOTH_BRICK,100)
RB(6,12,6,STONEBRICK:1,10,STONEBRICK:2,10,COBBLESTONE,10,MOSSY_COBBLESTONE,10,SMOOTH_BRICK,100)
RB(7,12,6,STONEBRICK:1,10,STONEBRICK:2,10,COBBLESTONE,10,MOSSY_COBBLESTONE,10,SMOOTH_BRICK,100)
B(0,12,7,STONE_SLAB:8)
B(1,12,7,STONE_SLAB:8)
B(2,12,7,STONE_BRICK_STAIRS:4)
RB(3,12,7,STONEBRICK:1,10,STONEBRICK:2,10,COBBLESTONE,10,MOSSY_COBBLESTONE,10,SMOOTH_BRICK,100)
RB(4,12,7,STONEBRICK:1,10,STONEBRICK:2,10,COBBLESTONE,10,MOSSY_COBBLESTONE,10,SMOOTH_BRICK,100)
RB(5,12,7,STONEBRICK:1,10,STONEBRICK:2,10,COBBLESTONE,10,MOSSY_COBBLESTONE,10,SMOOTH_BRICK,100)
RB(6,12,7,STONEBRICK:1,10,STONEBRICK:2,10,COBBLESTONE,10,MOSSY_COBBLESTONE,10,SMOOTH_BRICK,100)
RB(7,12,7,STONEBRICK:1,10,STONEBRICK:2,10,COBBLESTONE,10,MOSSY_COBBLESTONE,10,SMOOTH_BRICK,100)
RB(0,13,0,WEB,8,AIR,100)
RB(1,13,0,WEB,8,AIR,100)
B(2,13,0,STONE_SLAB:8)
RB(3,13,0,STONEBRICK:1,10,STONEBRICK:2,10,COBBLESTONE,10,MOSSY_COBBLESTONE,10,SMOOTH_BRICK,100)
RB(4,13,0,STONEBRICK:1,10,STONEBRICK:2,10,COBBLESTONE,10,MOSSY_COBBLESTONE,10,SMOOTH_BRICK,100)
RB(5,13,0,STONEBRICK:1,10,STONEBRICK:2,10,COBBLESTONE,10,MOSSY_COBBLESTONE,10,SMOOTH_BRICK,100)
RB(6,13,0,STONEBRICK:1,10,STONEBRICK:2,10,COBBLESTONE,10,MOSSY_COBBLESTONE,10,SMOOTH_BRICK,100)
RB(7,13,0,STONEBRICK:1,10,STONEBRICK:2,10,COBBLESTONE,10,MOSSY_COBBLESTONE,10,SMOOTH_BRICK,100)
B(0,13,1,STONE_BRICK_STAIRS:6)
B(1,13,1,STONE_BRICK_STAIRS:6)
RB(2,13,1,STONEBRICK:1,10,STONEBRICK:2,10,COBBLESTONE,10,MOSSY_COBBLESTONE,10,SMOOTH_BRICK,100)
RB(3,13,1,STONEBRICK:1,10,STONEBRICK:2,10,COBBLESTONE,10,MOSSY_COBBLESTONE,10,SMOOTH_BRICK,100)
RB(4,13,1,STONEBRICK:1,10,STONEBRICK:2,10,COBBLESTONE,10,MOSSY_COBBLESTONE,10,SMOOTH_BRICK,100)
RB(5,13,1,STONEBRICK:1,10,STONEBRICK:2,10,COBBLESTONE,10,MOSSY_COBBLESTONE,10,SMOOTH_BRICK,100)
RB(6,13,1,STONEBRICK:1,10,STONEBRICK:2,10,COBBLESTONE,10,MOSSY_COBBLESTONE,10,SMOOTH_BRICK,100)
RB(7,13,1,STONEBRICK:1,10,STONEBRICK:2,10,COBBLESTONE,10,MOSSY_COBBLESTONE,10,SMOOTH_BRICK,100)
RB(0,13,2,STONEBRICK:1,10,STONEBRICK:2,10,COBBLESTONE,10,MOSSY_COBBLESTONE,10,SMOOTH_BRICK,100)
RB(1,13,2,STONEBRICK:1,10,STONEBRICK:2,10,COBBLESTONE,10,MOSSY_COBBLESTONE,10,SMOOTH_BRICK,100)
RB(2,13,2,STONEBRICK:1,10,STONEBRICK:2,10,COBBLESTONE,10,MOSSY_COBBLESTONE,10,SMOOTH_BRICK,100)
RB(3,13,2,STONEBRICK:1,10,STONEBRICK:2,10,COBBLESTONE,10,MOSSY_COBBLESTONE,10,SMOOTH_BRICK,100)
RB(4,13,2,STONEBRICK:1,10,STONEBRICK:2,10,COBBLESTONE,10,MOSSY_COBBLESTONE,10,SMOOTH_BRICK,100)
RB(5,13,2,STONEBRICK:1,10,STONEBRICK:2,10,COBBLESTONE,10,MOSSY_COBBLESTONE,10,SMOOTH_BRICK,100)
RB(6,13,2,STONEBRICK:1,10,STONEBRICK:2,10,COBBLESTONE,10,MOSSY_COBBLESTONE,10,SMOOTH_BRICK,100)
RB(7,13,2,STONEBRICK:1,10,STONEBRICK:2,10,COBBLESTONE,10,MOSSY_COBBLESTONE,10,SMOOTH_BRICK,100)
RB(0,13,3,STONEBRICK:1,10,STONEBRICK:2,10,COBBLESTONE,10,MOSSY_COBBLESTONE,10,SMOOTH_BRICK,100)
RB(1,13,3,STONEBRICK:1,10,STONEBRICK:2,10,COBBLESTONE,10,MOSSY_COBBLESTONE,10,SMOOTH_BRICK,100)
RB(2,13,3,STONEBRICK:1,10,STONEBRICK:2,10,COBBLESTONE,10,MOSSY_COBBLESTONE,10,SMOOTH_BRICK,100)
RB(3,13,3,STONEBRICK:1,10,STONEBRICK:2,10,COBBLESTONE,10,MOSSY_COBBLESTONE,10,SMOOTH_BRICK,100)
RB(4,13,3,STONEBRICK:1,10,STONEBRICK:2,10,COBBLESTONE,10,MOSSY_COBBLESTONE,10,SMOOTH_BRICK,100)
RB(5,13,3,STONEBRICK:1,10,STONEBRICK:2,10,COBBLESTONE,10,MOSSY_COBBLESTONE,10,SMOOTH_BRICK,100)
RB(6,13,3,STONEBRICK:1,10,STONEBRICK:2,10,COBBLESTONE,10,MOSSY_COBBLESTONE,10,SMOOTH_BRICK,100)
RB(7,13,3,STONEBRICK:1,10,STONEBRICK:2,10,COBBLESTONE,10,MOSSY_COBBLESTONE,10,SMOOTH_BRICK,100)
B(0,13,4,AIR)
B(1,13,4,AIR)
B(2,13,4,AIR)
RB(3,13,4,STONEBRICK:1,10,STONEBRICK:2,10,COBBLESTONE,10,MOSSY_COBBLESTONE,10,SMOOTH_BRICK,100)
RB(4,13,4,STONEBRICK:1,10,STONEBRICK:2,10,COBBLESTONE,10,MOSSY_COBBLESTONE,10,SMOOTH_BRICK,100)
RB(5,13,4,STONEBRICK:1,10,STONEBRICK:2,10,COBBLESTONE,10,MOSSY_COBBLESTONE,10,SMOOTH_BRICK,100)
RB(6,13,4,STONEBRICK:1,10,STONEBRICK:2,10,COBBLESTONE,10,MOSSY_COBBLESTONE,10,SMOOTH_BRICK,100)
RB(7,13,4,STONEBRICK:1,10,STONEBRICK:2,10,COBBLESTONE,10,MOSSY_COBBLESTONE,10,SMOOTH_BRICK,100)
RB(0,13,5,STONEBRICK:1,10,STONEBRICK:2,10,COBBLESTONE,10,MOSSY_COBBLESTONE,10,SMOOTH_BRICK,100)
RB(1,13,5,STONEBRICK:1,10,STONEBRICK:2,10,COBBLESTONE,10,MOSSY_COBBLESTONE,10,SMOOTH_BRICK,100)
B(2,13,5,STONE_BRICK_STAIRS:2)
RB(3,13,5,STONEBRICK:1,10,STONEBRICK:2,10,COBBLESTONE,10,MOSSY_COBBLESTONE,10,SMOOTH_BRICK,100)
RB(4,13,5,STONEBRICK:1,10,STONEBRICK:2,10,COBBLESTONE,10,MOSSY_COBBLESTONE,10,SMOOTH_BRICK,100)
RB(5,13,5,STONEBRICK:1,10,STONEBRICK:2,10,COBBLESTONE,10,MOSSY_COBBLESTONE,10,SMOOTH_BRICK,100)
RB(6,13,5,STONEBRICK:1,10,STONEBRICK:2,10,COBBLESTONE,10,MOSSY_COBBLESTONE,10,SMOOTH_BRICK,100)
RB(7,13,5,STONEBRICK:1,10,STONEBRICK:2,10,COBBLESTONE,10,MOSSY_COBBLESTONE,10,SMOOTH_BRICK,100)
RB(0,13,6,STONEBRICK:1,10,STONEBRICK:2,10,COBBLESTONE,10,MOSSY_COBBLESTONE,10,SMOOTH_BRICK,100)
RB(1,13,6,STONEBRICK:1,10,STONEBRICK:2,10,COBBLESTONE,10,MOSSY_COBBLESTONE,10,SMOOTH_BRICK,100)
RB(2,13,6,STONEBRICK:1,10,STONEBRICK:2,10,COBBLESTONE,10,MOSSY_COBBLESTONE,10,SMOOTH_BRICK,100)
RB(3,13,6,STONEBRICK:1,10,STONEBRICK:2,10,COBBLESTONE,10,MOSSY_COBBLESTONE,10,SMOOTH_BRICK,100)
RB(4,13,6,STONEBRICK:1,10,STONEBRICK:2,10,COBBLESTONE,10,MOSSY_COBBLESTONE,10,SMOOTH_BRICK,100)
RB(5,13,6,STONEBRICK:1,10,STONEBRICK:2,10,COBBLESTONE,10,MOSSY_COBBLESTONE,10,SMOOTH_BRICK,100)
RB(6,13,6,STONEBRICK:1,10,STONEBRICK:2,10,COBBLESTONE,10,MOSSY_COBBLESTONE,10,SMOOTH_BRICK,100)
RB(7,13,6,STONEBRICK:1,10,STONEBRICK:2,10,COBBLESTONE,10,MOSSY_COBBLESTONE,10,SMOOTH_BRICK,100)
RB(0,13,7,STONEBRICK:1,10,STONEBRICK:2,10,COBBLESTONE,10,MOSSY_COBBLESTONE,10,SMOOTH_BRICK,100)
RB(1,13,7,STONEBRICK:1,10,STONEBRICK:2,10,COBBLESTONE,10,MOSSY_COBBLESTONE,10,SMOOTH_BRICK,100)
RB(2,13,7,STONEBRICK:1,10,STONEBRICK:2,10,COBBLESTONE,10,MOSSY_COBBLESTONE,10,SMOOTH_BRICK,100)
RB(3,13,7,STONEBRICK:1,10,STONEBRICK:2,10,COBBLESTONE,10,MOSSY_COBBLESTONE,10,SMOOTH_BRICK,100)
RB(4,13,7,STONEBRICK:1,10,STONEBRICK:2,10,COBBLESTONE,10,MOSSY_COBBLESTONE,10,SMOOTH_BRICK,100)
RB(5,13,7,STONEBRICK:1,10,STONEBRICK:2,10,COBBLESTONE,10,MOSSY_COBBLESTONE,10,SMOOTH_BRICK,100)
RB(6,13,7,STONEBRICK:1,10,STONEBRICK:2,10,COBBLESTONE,10,MOSSY_COBBLESTONE,10,SMOOTH_BRICK,100)
RB(7,13,7,STONEBRICK:1,10,STONEBRICK:2,10,COBBLESTONE,10,MOSSY_COBBLESTONE,10,SMOOTH_BRICK,100)
RB(0,14,0,STONEBRICK:1,10,STONEBRICK:2,10,COBBLESTONE,10,MOSSY_COBBLESTONE,10,SMOOTH_BRICK,100)
RB(1,14,0,STONEBRICK:1,10,STONEBRICK:2,10,COBBLESTONE,10,MOSSY_COBBLESTONE,10,SMOOTH_BRICK,100)
RB(2,14,0,STONEBRICK:1,10,STONEBRICK:2,10,COBBLESTONE,10,MOSSY_COBBLESTONE,10,SMOOTH_BRICK,100)
RB(3,14,0,STONEBRICK:1,10,STONEBRICK:2,10,COBBLESTONE,10,MOSSY_COBBLESTONE,10,SMOOTH_BRICK,100)
RB(4,14,0,STONEBRICK:1,10,STONEBRICK:2,10,COBBLESTONE,10,MOSSY_COBBLESTONE,10,SMOOTH_BRICK,100)
B(5,14,0,AIR)
B(6,14,0,AIR)
B(7,14,0,AIR)
RB(0,14,1,STONEBRICK:1,10,STONEBRICK:2,10,COBBLESTONE,10,MOSSY_COBBLESTONE,10,SMOOTH_BRICK,100)
RB(1,14,1,STONEBRICK:1,10,STONEBRICK:2,10,COBBLESTONE,10,MOSSY_COBBLESTONE,10,SMOOTH_BRICK,100)
RB(2,14,1,STONEBRICK:1,10,STONEBRICK:2,10,COBBLESTONE,10,MOSSY_COBBLESTONE,10,SMOOTH_BRICK,100)
RB(3,14,1,STONEBRICK:1,10,STONEBRICK:2,10,COBBLESTONE,10,MOSSY_COBBLESTONE,10,SMOOTH_BRICK,100)
B(4,14,1,STONE_BRICK_STAIRS:1)
B(5,14,1,AIR)
B(6,14,1,AIR)
B(7,14,1,AIR)
RB(0,14,2,STONEBRICK:1,10,STONEBRICK:2,10,COBBLESTONE,10,MOSSY_COBBLESTONE,10,SMOOTH_BRICK,100)
RB(1,14,2,STONEBRICK:1,10,STONEBRICK:2,10,COBBLESTONE,10,MOSSY_COBBLESTONE,10,SMOOTH_BRICK,100)
RB(2,14,2,STONEBRICK:1,10,STONEBRICK:2,10,COBBLESTONE,10,MOSSY_COBBLESTONE,10,SMOOTH_BRICK,100)
RB(3,14,2,STONEBRICK:1,10,STONEBRICK:2,10,COBBLESTONE,10,MOSSY_COBBLESTONE,10,SMOOTH_BRICK,100)
B(4,14,2,STONE_BRICK_STAIRS:1)
B(5,14,2,AIR)
B(6,14,2,AIR)
B(7,14,2,AIR)
RB(0,14,3,STONEBRICK:1,10,STONEBRICK:2,10,COBBLESTONE,10,MOSSY_COBBLESTONE,10,SMOOTH_BRICK,100)
RB(1,14,3,STONEBRICK:1,10,STONEBRICK:2,10,COBBLESTONE,10,MOSSY_COBBLESTONE,10,SMOOTH_BRICK,100)
RB(2,14,3,STONEBRICK:1,10,STONEBRICK:2,10,COBBLESTONE,10,MOSSY_COBBLESTONE,10,SMOOTH_BRICK,100)
RB(3,14,3,STONEBRICK:1,10,STONEBRICK:2,10,COBBLESTONE,10,MOSSY_COBBLESTONE,10,SMOOTH_BRICK,100)
RB(4,14,3,STONEBRICK:1,10,STONEBRICK:2,10,COBBLESTONE,10,MOSSY_COBBLESTONE,10,SMOOTH_BRICK,100)
RB(5,14,3,SKULL:1,./StructureNBT/Skulls/dungeon_skull_01.nbt,6,AIR,9,SKULL:1,./StructureNBT/Skulls/dungeon_skull_02.nbt,12,AIR,15,SKULL:1,./StructureNBT/Skulls/dungeon_skull_03.nbt,18,AIR,21,SKULL:1,./StructureNBT/Skulls/dungeon_skull_04.nbt,24,AIR,27,SKULL:1,./StructureNBT/Skulls/dungeon_skull_05.nbt,30,AIR,33,SKULL:1,./StructureNBT/Skulls/dungeon_skull_06.nbt,36,AIR,39,SKULL:1,./StructureNBT/Skulls/dungeon_skull_07.nbt,42,AIR,45,SKULL:1,./StructureNBT/Skulls/dungeon_skull_08.nbt,48,AIR,51,SKULL:1,./StructureNBT/Skulls/dungeon_skull_09.nbt,54,AIR,57,SKULL:1,./StructureNBT/Skulls/dungeon_skull_10.nbt,60,AIR,63,SKULL:1,./StructureNBT/Skulls/dungeon_skull_11.nbt,66,AIR,69,SKULL:1,./StructureNBT/Skulls/dungeon_skull_12.nbt,72,AIR,75,SKULL:1,./StructureNBT/Skulls/dungeon_skull_13.nbt,78,AIR,81,SKULL:1,./StructureNBT/Skulls/dungeon_skull_14.nbt,84,AIR,87,SKULL:1,./StructureNBT/Skulls/dungeon_skull_15.nbt,90,AIR,93,SKULL:1,./StructureNBT/Skulls/dungeon_skull_16.nbt,96,AIR,100)
B(6,14,3,AIR)
B(7,14,3,AIR)
RB(0,14,4,WEB,8,AIR,100)
B(1,14,4,AIR)
B(2,14,4,AIR)
RB(3,14,4,STONEBRICK:1,10,STONEBRICK:2,10,COBBLESTONE,10,MOSSY_COBBLESTONE,10,SMOOTH_BRICK,100)
RB(4,14,4,STONEBRICK:1,10,STONEBRICK:2,10,COBBLESTONE,10,MOSSY_COBBLESTONE,10,SMOOTH_BRICK,100)
B(5,14,4,STONE_BRICK_STAIRS:1)
B(6,14,4,AIR)
B(7,14,4,AIR)
RB(0,14,5,STONEBRICK:1,10,STONEBRICK:2,10,COBBLESTONE,10,MOSSY_COBBLESTONE,10,SMOOTH_BRICK,100)
RB(1,14,5,STONEBRICK:1,10,STONEBRICK:2,10,COBBLESTONE,10,MOSSY_COBBLESTONE,10,SMOOTH_BRICK,100)
B(2,14,5,AIR)
RB(3,14,5,STONEBRICK:1,10,STONEBRICK:2,10,COBBLESTONE,10,MOSSY_COBBLESTONE,10,SMOOTH_BRICK,100)
RB(4,14,5,STONEBRICK:1,10,STONEBRICK:2,10,COBBLESTONE,10,MOSSY_COBBLESTONE,10,SMOOTH_BRICK,100)
RB(5,14,5,STONEBRICK:1,10,STONEBRICK:2,10,COBBLESTONE,10,MOSSY_COBBLESTONE,10,SMOOTH_BRICK,100)
B(6,14,5,STONE_BRICK_STAIRS:2)
B(7,14,5,AIR)
RB(0,14,6,CHEST:3,./StructureNBT/StructureLoot/JunkChest_1.nbt,5,CHEST:3,./StructureNBT/StructureLoot/JunkChest_2.nbt,5,CHEST:3,./StructureNBT/StructureLoot/JunkChest_3.nbt,15,CHEST:3,./StructureNBT/StructureLoot/JunkChest_4.nbt,15,CHEST:3,./StructureNBT/StructureLoot/JunkChest_5.nbt,15,CHEST:3,./StructureNBT/LoreStoryline/LoreDungeonOne_10.nbt,3,CHEST:3,./StructureNBT/LoreStoryline/LoreDungeonOne_9.nbt,3,CHEST:3,./StructureNBT/LoreStoryline/LoreDungeonOne_8.nbt,3,CHEST:3,./StructureNBT/LoreStoryline/LoreDungeonOne_7.nbt,3,CHEST:3,./StructureNBT/LoreStoryline/LoreDungeonOne_6.nbt,3,CHEST:3,./StructureNBT/LoreStoryline/LoreDungeonOne_5.nbt,3,CHEST:3,./StructureNBT/LoreStoryline/LoreDungeonOne_4.nbt,3,CHEST:3,./StructureNBT/LoreStoryline/LoreDungeonOne_3.nbt,3,CHEST:3,./StructureNBT/LoreStoryline/LoreDungeonOne_2.nbt,3,CHEST:3,./StructureNBT/LoreStoryline/LoreDungeonOne_1.nbt,3,CHEST:3,./StructureNBT/StructureLoot/Common1.nbt,25,CHEST:3,./StructureNBT/StructureLoot/Common2.nbt,25,CHEST:3,./StructureNBT/StructureLoot/Common3.nbt,25,CHEST:3,./StructureNBT/StructureLoot/Common4.nbt,25,CHEST:3,./StructureNBT/StructureLoot/Common5.nbt,25,CHEST:3,./StructureNBT/StructureLoot/Common6.nbt,25,CHEST:3,./StructureNBT/StructureLoot/Common7.nbt,25,CHEST:3,./StructureNBT/StructureLoot/Common8.nbt,25,CHEST:3,./StructureNBT/StructureLoot/Common9.nbt,25,CHEST:3,./StructureNBT/StructureLoot/Common10.nbt,25,CHEST:3,./StructureNBT/StructureLoot/Common11.nbt,25,CHEST:3,./StructureNBT/StructureLoot/Common12.nbt,25,CHEST:3,./StructureNBT/StructureLoot/Common13.nbt,25,CHEST:3,./StructureNBT/StructureLoot/Common14.nbt,25,CHEST:3,./StructureNBT/StructureLoot/Common15.nbt,25,CHEST:3,./StructureNBT/StructureLoot/Rare1.nbt,10,CHEST:3,./StructureNBT/StructureLoot/Rare2.nbt,10,CHEST:3,./StructureNBT/StructureLoot/Rare3.nbt,10,CHEST:3,./StructureNBT/StructureLoot/Rare4.nbt,10,CHEST:3,./StructureNBT/StructureLoot/Rare5.nbt,10,CHEST:3,./StructureNBT/StructureLoot/Rare6.nbt,10,CHEST:3,./StructureNBT/StructureLoot/Rare7.nbt,10,CHEST:3,./StructureNBT/StructureLoot/Rare8.nbt,10,CHEST:3,./StructureNBT/StructureLoot/Rare9.nbt,10,CHEST:3,./StructureNBT/StructureLoot/Rare10.nbt,10,CHEST:3,./StructureNBT/StructureLoot/Rare11.nbt,10,CHEST:3,./StructureNBT/StructureLoot/Rare12.nbt,10,CHEST:3,./StructureNBT/StructureLoot/Rare13.nbt,10,CHEST:3,./StructureNBT/StructureLoot/Rare14.nbt,10,CHEST:3,./StructureNBT/StructureLoot/Rare15.nbt,10,CHEST:3,./StructureNBT/StructureLoot/Epic1.nbt,1,CHEST:3,./StructureNBT/StructureLoot/Epic2.nbt,1,CHEST:3,./StructureNBT/StructureLoot/Epic3.nbt,1,CHEST:3,./StructureNBT/StructureLoot/Epic4.nbt,1,CHEST:3,./StructureNBT/StructureLoot/Epic5.nbt,1,CHEST:3,./StructureNBT/StructureLoot/Epic6.nbt,1,CHEST:3,./StructureNBT/StructureLoot/Epic7.nbt,1,CHEST:3,./StructureNBT/StructureLoot/Epic8.nbt,1,CHEST:3,./StructureNBT/StructureLoot/Epic9.nbt,1,CHEST:3,./StructureNBT/StructureLoot/Epic10.nbt,1,CHEST:3,./StructureNBT/StructureLoot/Epic11.nbt,1,CHEST:3,./StructureNBT/StructureLoot/Epic12.nbt,1,CHEST:3,./StructureNBT/StructureLoot/Epic13.nbt,1,CHEST:3,./StructureNBT/StructureLoot/Epic14.nbt,1,CHEST:3,./StructureNBT/StructureLoot/Epic15.nbt,1,CHEST:3,./StructureNBT/StructureLoot/Common15.nbt,100)
RB(1,14,6,CHEST:3,./StructureNBT/StructureLoot/JunkChest_1.nbt,5,CHEST:3,./StructureNBT/StructureLoot/JunkChest_2.nbt,5,CHEST:3,./StructureNBT/StructureLoot/JunkChest_3.nbt,15,CHEST:3,./StructureNBT/StructureLoot/JunkChest_4.nbt,15,CHEST:3,./StructureNBT/StructureLoot/JunkChest_5.nbt,15,CHEST:3,./StructureNBT/LoreStoryline/LoreDungeonOne_10.nbt,3,CHEST:3,./StructureNBT/LoreStoryline/LoreDungeonOne_9.nbt,3,CHEST:3,./StructureNBT/LoreStoryline/LoreDungeonOne_8.nbt,3,CHEST:3,./StructureNBT/LoreStoryline/LoreDungeonOne_7.nbt,3,CHEST:3,./StructureNBT/LoreStoryline/LoreDungeonOne_6.nbt,3,CHEST:3,./StructureNBT/LoreStoryline/LoreDungeonOne_5.nbt,3,CHEST:3,./StructureNBT/LoreStoryline/LoreDungeonOne_4.nbt,3,CHEST:3,./StructureNBT/LoreStoryline/LoreDungeonOne_3.nbt,3,CHEST:3,./StructureNBT/LoreStoryline/LoreDungeonOne_2.nbt,3,CHEST:3,./StructureNBT/LoreStoryline/LoreDungeonOne_1.nbt,3,CHEST:3,./StructureNBT/StructureLoot/Common1.nbt,25,CHEST:3,./StructureNBT/StructureLoot/Common2.nbt,25,CHEST:3,./StructureNBT/StructureLoot/Common3.nbt,25,CHEST:3,./StructureNBT/StructureLoot/Common4.nbt,25,CHEST:3,./StructureNBT/StructureLoot/Common5.nbt,25,CHEST:3,./StructureNBT/StructureLoot/Common6.nbt,25,CHEST:3,./StructureNBT/StructureLoot/Common7.nbt,25,CHEST:3,./StructureNBT/StructureLoot/Common8.nbt,25,CHEST:3,./StructureNBT/StructureLoot/Common9.nbt,25,CHEST:3,./StructureNBT/StructureLoot/Common10.nbt,25,CHEST:3,./StructureNBT/StructureLoot/Common11.nbt,25,CHEST:3,./StructureNBT/StructureLoot/Common12.nbt,25,CHEST:3,./StructureNBT/StructureLoot/Common13.nbt,25,CHEST:3,./StructureNBT/StructureLoot/Common14.nbt,25,CHEST:3,./StructureNBT/StructureLoot/Common15.nbt,25,CHEST:3,./StructureNBT/StructureLoot/Rare1.nbt,10,CHEST:3,./StructureNBT/StructureLoot/Rare2.nbt,10,CHEST:3,./StructureNBT/StructureLoot/Rare3.nbt,10,CHEST:3,./StructureNBT/StructureLoot/Rare4.nbt,10,CHEST:3,./StructureNBT/StructureLoot/Rare5.nbt,10,CHEST:3,./StructureNBT/StructureLoot/Rare6.nbt,10,CHEST:3,./StructureNBT/StructureLoot/Rare7.nbt,10,CHEST:3,./StructureNBT/StructureLoot/Rare8.nbt,10,CHEST:3,./StructureNBT/StructureLoot/Rare9.nbt,10,CHEST:3,./StructureNBT/StructureLoot/Rare10.nbt,10,CHEST:3,./StructureNBT/StructureLoot/Rare11.nbt,10,CHEST:3,./StructureNBT/StructureLoot/Rare12.nbt,10,CHEST:3,./StructureNBT/StructureLoot/Rare13.nbt,10,CHEST:3,./StructureNBT/StructureLoot/Rare14.nbt,10,CHEST:3,./StructureNBT/StructureLoot/Rare15.nbt,10,CHEST:3,./StructureNBT/StructureLoot/Epic1.nbt,1,CHEST:3,./StructureNBT/StructureLoot/Epic2.nbt,1,CHEST:3,./StructureNBT/StructureLoot/Epic3.nbt,1,CHEST:3,./StructureNBT/StructureLoot/Epic4.nbt,1,CHEST:3,./StructureNBT/StructureLoot/Epic5.nbt,1,CHEST:3,./StructureNBT/StructureLoot/Epic6.nbt,1,CHEST:3,./StructureNBT/StructureLoot/Epic7.nbt,1,CHEST:3,./StructureNBT/StructureLoot/Epic8.nbt,1,CHEST:3,./StructureNBT/StructureLoot/Epic9.nbt,1,CHEST:3,./StructureNBT/StructureLoot/Epic10.nbt,1,CHEST:3,./StructureNBT/StructureLoot/Epic11.nbt,1,CHEST:3,./StructureNBT/StructureLoot/Epic12.nbt,1,CHEST:3,./StructureNBT/StructureLoot/Epic13.nbt,1,CHEST:3,./StructureNBT/StructureLoot/Epic14.nbt,1,CHEST:3,./StructureNBT/StructureLoot/Epic15.nbt,1,CHEST:3,./StructureNBT/StructureLoot/Common15.nbt,100)
B(2,14,6,AIR)
RB(3,14,6,CHEST:3,./StructureNBT/StructureLoot/JunkChest_1.nbt,5,CHEST:3,./StructureNBT/StructureLoot/JunkChest_2.nbt,5,CHEST:3,./StructureNBT/StructureLoot/JunkChest_3.nbt,15,CHEST:3,./StructureNBT/StructureLoot/JunkChest_4.nbt,15,CHEST:3,./StructureNBT/StructureLoot/JunkChest_5.nbt,15,CHEST:3,./StructureNBT/LoreStoryline/LoreDungeonOne_10.nbt,3,CHEST:3,./StructureNBT/LoreStoryline/LoreDungeonOne_9.nbt,3,CHEST:3,./StructureNBT/LoreStoryline/LoreDungeonOne_8.nbt,3,CHEST:3,./StructureNBT/LoreStoryline/LoreDungeonOne_7.nbt,3,CHEST:3,./StructureNBT/LoreStoryline/LoreDungeonOne_6.nbt,3,CHEST:3,./StructureNBT/LoreStoryline/LoreDungeonOne_5.nbt,3,CHEST:3,./StructureNBT/LoreStoryline/LoreDungeonOne_4.nbt,3,CHEST:3,./StructureNBT/LoreStoryline/LoreDungeonOne_3.nbt,3,CHEST:3,./StructureNBT/LoreStoryline/LoreDungeonOne_2.nbt,3,CHEST:3,./StructureNBT/LoreStoryline/LoreDungeonOne_1.nbt,3,CHEST:3,./StructureNBT/StructureLoot/Common1.nbt,25,CHEST:3,./StructureNBT/StructureLoot/Common2.nbt,25,CHEST:3,./StructureNBT/StructureLoot/Common3.nbt,25,CHEST:3,./StructureNBT/StructureLoot/Common4.nbt,25,CHEST:3,./StructureNBT/StructureLoot/Common5.nbt,25,CHEST:3,./StructureNBT/StructureLoot/Common6.nbt,25,CHEST:3,./StructureNBT/StructureLoot/Common7.nbt,25,CHEST:3,./StructureNBT/StructureLoot/Common8.nbt,25,CHEST:3,./StructureNBT/StructureLoot/Common9.nbt,25,CHEST:3,./StructureNBT/StructureLoot/Common10.nbt,25,CHEST:3,./StructureNBT/StructureLoot/Common11.nbt,25,CHEST:3,./StructureNBT/StructureLoot/Common12.nbt,25,CHEST:3,./StructureNBT/StructureLoot/Common13.nbt,25,CHEST:3,./StructureNBT/StructureLoot/Common14.nbt,25,CHEST:3,./StructureNBT/StructureLoot/Common15.nbt,25,CHEST:3,./StructureNBT/StructureLoot/Rare1.nbt,10,CHEST:3,./StructureNBT/StructureLoot/Rare2.nbt,10,CHEST:3,./StructureNBT/StructureLoot/Rare3.nbt,10,CHEST:3,./StructureNBT/StructureLoot/Rare4.nbt,10,CHEST:3,./StructureNBT/StructureLoot/Rare5.nbt,10,CHEST:3,./StructureNBT/StructureLoot/Rare6.nbt,10,CHEST:3,./StructureNBT/StructureLoot/Rare7.nbt,10,CHEST:3,./StructureNBT/StructureLoot/Rare8.nbt,10,CHEST:3,./StructureNBT/StructureLoot/Rare9.nbt,10,CHEST:3,./StructureNBT/StructureLoot/Rare10.nbt,10,CHEST:3,./StructureNBT/StructureLoot/Rare11.nbt,10,CHEST:3,./StructureNBT/StructureLoot/Rare12.nbt,10,CHEST:3,./StructureNBT/StructureLoot/Rare13.nbt,10,CHEST:3,./StructureNBT/StructureLoot/Rare14.nbt,10,CHEST:3,./StructureNBT/StructureLoot/Rare15.nbt,10,CHEST:3,./StructureNBT/StructureLoot/Epic1.nbt,1,CHEST:3,./StructureNBT/StructureLoot/Epic2.nbt,1,CHEST:3,./StructureNBT/StructureLoot/Epic3.nbt,1,CHEST:3,./StructureNBT/StructureLoot/Epic4.nbt,1,CHEST:3,./StructureNBT/StructureLoot/Epic5.nbt,1,CHEST:3,./StructureNBT/StructureLoot/Epic6.nbt,1,CHEST:3,./StructureNBT/StructureLoot/Epic7.nbt,1,CHEST:3,./StructureNBT/StructureLoot/Epic8.nbt,1,CHEST:3,./StructureNBT/StructureLoot/Epic9.nbt,1,CHEST:3,./StructureNBT/StructureLoot/Epic10.nbt,1,CHEST:3,./StructureNBT/StructureLoot/Epic11.nbt,1,CHEST:3,./StructureNBT/StructureLoot/Epic12.nbt,1,CHEST:3,./StructureNBT/StructureLoot/Epic13.nbt,1,CHEST:3,./StructureNBT/StructureLoot/Epic14.nbt,1,CHEST:3,./StructureNBT/StructureLoot/Epic15.nbt,1,CHEST:3,./StructureNBT/StructureLoot/Common15.nbt,100)
RB(4,14,6,CHEST:3,./StructureNBT/StructureLoot/JunkChest_1.nbt,5,CHEST:3,./StructureNBT/StructureLoot/JunkChest_2.nbt,5,CHEST:3,./StructureNBT/StructureLoot/JunkChest_3.nbt,15,CHEST:3,./StructureNBT/StructureLoot/JunkChest_4.nbt,15,CHEST:3,./StructureNBT/StructureLoot/JunkChest_5.nbt,15,CHEST:3,./StructureNBT/LoreStoryline/LoreDungeonOne_10.nbt,3,CHEST:3,./StructureNBT/LoreStoryline/LoreDungeonOne_9.nbt,3,CHEST:3,./StructureNBT/LoreStoryline/LoreDungeonOne_8.nbt,3,CHEST:3,./StructureNBT/LoreStoryline/LoreDungeonOne_7.nbt,3,CHEST:3,./StructureNBT/LoreStoryline/LoreDungeonOne_6.nbt,3,CHEST:3,./StructureNBT/LoreStoryline/LoreDungeonOne_5.nbt,3,CHEST:3,./StructureNBT/LoreStoryline/LoreDungeonOne_4.nbt,3,CHEST:3,./StructureNBT/LoreStoryline/LoreDungeonOne_3.nbt,3,CHEST:3,./StructureNBT/LoreStoryline/LoreDungeonOne_2.nbt,3,CHEST:3,./StructureNBT/LoreStoryline/LoreDungeonOne_1.nbt,3,CHEST:3,./StructureNBT/StructureLoot/Common1.nbt,25,CHEST:3,./StructureNBT/StructureLoot/Common2.nbt,25,CHEST:3,./StructureNBT/StructureLoot/Common3.nbt,25,CHEST:3,./StructureNBT/StructureLoot/Common4.nbt,25,CHEST:3,./StructureNBT/StructureLoot/Common5.nbt,25,CHEST:3,./StructureNBT/StructureLoot/Common6.nbt,25,CHEST:3,./StructureNBT/StructureLoot/Common7.nbt,25,CHEST:3,./StructureNBT/StructureLoot/Common8.nbt,25,CHEST:3,./StructureNBT/StructureLoot/Common9.nbt,25,CHEST:3,./StructureNBT/StructureLoot/Common10.nbt,25,CHEST:3,./StructureNBT/StructureLoot/Common11.nbt,25,CHEST:3,./StructureNBT/StructureLoot/Common12.nbt,25,CHEST:3,./StructureNBT/StructureLoot/Common13.nbt,25,CHEST:3,./StructureNBT/StructureLoot/Common14.nbt,25,CHEST:3,./StructureNBT/StructureLoot/Common15.nbt,25,CHEST:3,./StructureNBT/StructureLoot/Rare1.nbt,10,CHEST:3,./StructureNBT/StructureLoot/Rare2.nbt,10,CHEST:3,./StructureNBT/StructureLoot/Rare3.nbt,10,CHEST:3,./StructureNBT/StructureLoot/Rare4.nbt,10,CHEST:3,./StructureNBT/StructureLoot/Rare5.nbt,10,CHEST:3,./StructureNBT/StructureLoot/Rare6.nbt,10,CHEST:3,./StructureNBT/StructureLoot/Rare7.nbt,10,CHEST:3,./StructureNBT/StructureLoot/Rare8.nbt,10,CHEST:3,./StructureNBT/StructureLoot/Rare9.nbt,10,CHEST:3,./StructureNBT/StructureLoot/Rare10.nbt,10,CHEST:3,./StructureNBT/StructureLoot/Rare11.nbt,10,CHEST:3,./StructureNBT/StructureLoot/Rare12.nbt,10,CHEST:3,./StructureNBT/StructureLoot/Rare13.nbt,10,CHEST:3,./StructureNBT/StructureLoot/Rare14.nbt,10,CHEST:3,./StructureNBT/StructureLoot/Rare15.nbt,10,CHEST:3,./StructureNBT/StructureLoot/Epic1.nbt,1,CHEST:3,./StructureNBT/StructureLoot/Epic2.nbt,1,CHEST:3,./StructureNBT/StructureLoot/Epic3.nbt,1,CHEST:3,./StructureNBT/StructureLoot/Epic4.nbt,1,CHEST:3,./StructureNBT/StructureLoot/Epic5.nbt,1,CHEST:3,./StructureNBT/StructureLoot/Epic6.nbt,1,CHEST:3,./StructureNBT/StructureLoot/Epic7.nbt,1,CHEST:3,./StructureNBT/StructureLoot/Epic8.nbt,1,CHEST:3,./StructureNBT/StructureLoot/Epic9.nbt,1,CHEST:3,./StructureNBT/StructureLoot/Epic10.nbt,1,CHEST:3,./StructureNBT/StructureLoot/Epic11.nbt,1,CHEST:3,./StructureNBT/StructureLoot/Epic12.nbt,1,CHEST:3,./StructureNBT/StructureLoot/Epic13.nbt,1,CHEST:3,./StructureNBT/StructureLoot/Epic14.nbt,1,CHEST:3,./StructureNBT/StructureLoot/Epic15.nbt,1,CHEST:3,./StructureNBT/StructureLoot/Common15.nbt,100)
B(5,14,6,STONE_BRICK_STAIRS:3)
RB(6,14,6,STONEBRICK:1,10,STONEBRICK:2,10,COBBLESTONE,10,MOSSY_COBBLESTONE,10,SMOOTH_BRICK,100)
B(7,14,6,AIR)
B(0,14,7,AIR)
B(1,14,7,AIR)
B(2,14,7,AIR)
B(3,14,7,AIR)
B(4,14,7,AIR)
RB(5,14,7,WEB,8,AIR,100)
B(6,14,7,IRON_BARS)
B(7,14,7,AIR)
RB(0,15,0,STONEBRICK:1,10,STONEBRICK:2,10,COBBLESTONE,10,MOSSY_COBBLESTONE,10,SMOOTH_BRICK,100)
B(1,15,0,STONE_SLAB)
RB(2,15,0,STONEBRICK:1,10,STONEBRICK:2,10,COBBLESTONE,10,MOSSY_COBBLESTONE,10,SMOOTH_BRICK,100)
B(3,15,0,STONE_SLAB)
RB(4,15,0,STONEBRICK:1,10,STONEBRICK:2,10,COBBLESTONE,10,MOSSY_COBBLESTONE,10,SMOOTH_BRICK,100)
B(5,15,0,AIR)
B(6,15,0,AIR)
B(7,15,0,AIR)
B(0,15,1,AIR)
RB(1,15,1,WEB,8,AIR,100)
B(2,15,1,AIR)
B(3,15,1,AIR)
B(4,15,1,AIR)
B(5,15,1,AIR)
B(6,15,1,AIR)
B(7,15,1,AIR)
B(0,15,2,AIR)
B(1,15,2,AIR)
B(2,15,2,AIR)
B(3,15,2,AIR)
B(4,15,2,AIR)
B(5,15,2,AIR)
B(6,15,2,AIR)
B(7,15,2,AIR)
RB(0,15,3,STONEBRICK:1,10,STONEBRICK:2,10,COBBLESTONE,10,MOSSY_COBBLESTONE,10,SMOOTH_BRICK,100)
B(1,15,3,STONE_SLAB)
RB(2,15,3,STONEBRICK:1,10,STONEBRICK:2,10,COBBLESTONE,10,MOSSY_COBBLESTONE,10,SMOOTH_BRICK,100)
B(3,15,3,STONE_SLAB)
RB(4,15,3,STONEBRICK:1,10,STONEBRICK:2,10,COBBLESTONE,10,MOSSY_COBBLESTONE,10,SMOOTH_BRICK,100)
B(5,15,3,AIR)
B(6,15,3,AIR)
B(7,15,3,AIR)
RB(0,15,4,STONEBRICK:1,10,STONEBRICK:2,10,COBBLESTONE,10,MOSSY_COBBLESTONE,10,SMOOTH_BRICK,100)
B(1,15,4,STONE_BRICK_STAIRS:5)
RB(2,15,4,WEB,8,AIR,100)
RB(3,15,4,STONEBRICK:1,10,STONEBRICK:2,10,COBBLESTONE,10,MOSSY_COBBLESTONE,10,SMOOTH_BRICK,100)
RB(4,15,4,STONEBRICK:1,10,STONEBRICK:2,10,COBBLESTONE,10,MOSSY_COBBLESTONE,10,SMOOTH_BRICK,100)
B(5,15,4,AIR)
B(6,15,4,AIR)
B(7,15,4,AIR)
RB(0,15,5,STONEBRICK:1,10,STONEBRICK:2,10,COBBLESTONE,10,MOSSY_COBBLESTONE,10,SMOOTH_BRICK,100)
RB(1,15,5,STONEBRICK:1,10,STONEBRICK:2,10,COBBLESTONE,10,MOSSY_COBBLESTONE,10,SMOOTH_BRICK,100)
RB(2,15,5,WEB,8,AIR,100)
RB(3,15,5,STONEBRICK:1,10,STONEBRICK:2,10,COBBLESTONE,10,MOSSY_COBBLESTONE,10,SMOOTH_BRICK,100)
RB(4,15,5,STONEBRICK:1,10,STONEBRICK:2,10,COBBLESTONE,10,MOSSY_COBBLESTONE,10,SMOOTH_BRICK,100)
RB(5,15,5,STONEBRICK:1,10,STONEBRICK:2,10,COBBLESTONE,10,MOSSY_COBBLESTONE,10,SMOOTH_BRICK,100)
B(6,15,5,AIR)
B(7,15,5,AIR)
B(0,15,6,AIR)
B(1,15,6,AIR)
B(2,15,6,AIR)
B(3,15,6,AIR)
B(4,15,6,AIR)
RB(5,15,6,WEB,8,AIR,100)
RB(6,15,6,STONEBRICK:1,10,STONEBRICK:2,10,COBBLESTONE,10,MOSSY_COBBLESTONE,10,SMOOTH_BRICK,100)
B(7,15,6,AIR)
B(0,15,7,AIR)
B(1,15,7,AIR)
B(2,15,7,AIR)
B(3,15,7,AIR)
B(4,15,7,AIR)
B(5,15,7,AIR)
B(6,15,7,IRON_BARS)
B(7,15,7,AIR)
B(0,16,0,STONE_BRICK_STAIRS:3)
B(1,16,0,AIR)
B(2,16,0,STONE_BRICK_STAIRS:3)
B(3,16,0,AIR)
B(4,16,0,STONE_BRICK_STAIRS:3)
B(5,16,0,AIR)
B(6,16,0,AIR)
B(7,16,0,AIR)
B(0,16,1,AIR)
B(1,16,1,AIR)
B(2,16,1,AIR)
B(3,16,1,AIR)
B(4,16,1,AIR)
B(5,16,1,AIR)
B(6,16,1,AIR)
B(7,16,1,AIR)
B(0,16,2,AIR)
B(1,16,2,AIR)
B(2,16,2,AIR)
B(3,16,2,AIR)
B(4,16,2,AIR)
B(5,16,2,AIR)
B(6,16,2,AIR)
B(7,16,2,AIR)
B(0,16,3,STONE_BRICK_STAIRS:2)
B(1,16,3,AIR)
B(2,16,3,STONE_BRICK_STAIRS:2)
B(3,16,3,AIR)
B(4,16,3,STONE_BRICK_STAIRS:2)
B(5,16,3,AIR)
B(6,16,3,AIR)
B(7,16,3,AIR)
RB(0,16,4,STONEBRICK:1,10,STONEBRICK:2,10,COBBLESTONE,10,MOSSY_COBBLESTONE,10,SMOOTH_BRICK,100)
RB(1,16,4,STONEBRICK:1,10,STONEBRICK:2,10,COBBLESTONE,10,MOSSY_COBBLESTONE,10,SMOOTH_BRICK,100)
RB(2,16,4,STONEBRICK:1,10,STONEBRICK:2,10,COBBLESTONE,10,MOSSY_COBBLESTONE,10,SMOOTH_BRICK,100)
RB(3,16,4,STONEBRICK:1,10,STONEBRICK:2,10,COBBLESTONE,10,MOSSY_COBBLESTONE,10,SMOOTH_BRICK,100)
RB(4,16,4,STONEBRICK:1,10,STONEBRICK:2,10,COBBLESTONE,10,MOSSY_COBBLESTONE,10,SMOOTH_BRICK,100)
B(5,16,4,STONE_BRICK_STAIRS:5)
B(6,16,4,AIR)
B(7,16,4,AIR)
RB(0,16,5,STONEBRICK:1,10,STONEBRICK:2,10,COBBLESTONE,10,MOSSY_COBBLESTONE,10,SMOOTH_BRICK,100)
RB(1,16,5,STONEBRICK:1,10,STONEBRICK:2,10,COBBLESTONE,10,MOSSY_COBBLESTONE,10,SMOOTH_BRICK,100)
RB(2,16,5,STONEBRICK:1,10,STONEBRICK:2,10,COBBLESTONE,10,MOSSY_COBBLESTONE,10,SMOOTH_BRICK,100)
RB(3,16,5,STONEBRICK:1,10,STONEBRICK:2,10,COBBLESTONE,10,MOSSY_COBBLESTONE,10,SMOOTH_BRICK,100)
RB(4,16,5,STONEBRICK:1,10,STONEBRICK:2,10,COBBLESTONE,10,MOSSY_COBBLESTONE,10,SMOOTH_BRICK,100)
RB(5,16,5,STONEBRICK:1,10,STONEBRICK:2,10,COBBLESTONE,10,MOSSY_COBBLESTONE,10,SMOOTH_BRICK,100)
B(6,16,5,STONE_BRICK_STAIRS:6)
B(7,16,5,AIR)
RB(0,16,6,WEB,8,AIR,100)
B(1,16,6,STONE_BRICK_STAIRS:7)
RB(2,16,6,WEB,8,AIR,100)
B(3,16,6,STONE_BRICK_STAIRS:7)
RB(4,16,6,WEB,8,AIR,100)
B(5,16,6,STONE_BRICK_STAIRS:7)
RB(6,16,6,STONEBRICK:1,10,STONEBRICK:2,10,COBBLESTONE,10,MOSSY_COBBLESTONE,10,SMOOTH_BRICK,100)
B(7,16,6,STONE_BRICK_STAIRS:5)
RB(0,16,7,WEB,8,AIR,100)
B(1,16,7,STONE_SLAB:8)
RB(2,16,7,WEB,8,AIR,100)
B(3,16,7,STONE_SLAB:8)
RB(4,16,7,WEB,8,AIR,100)
B(5,16,7,STONE_SLAB:8)
RB(6,16,7,STONEBRICK:1,10,STONEBRICK:2,10,COBBLESTONE,10,MOSSY_COBBLESTONE,10,SMOOTH_BRICK,100)
B(7,16,7,STONE_SLAB:8)
B(0,17,0,AIR)
B(1,17,0,AIR)
B(2,17,0,AIR)
B(3,17,0,AIR)
B(4,17,0,AIR)
B(5,17,0,AIR)
B(6,17,0,AIR)
B(7,17,0,AIR)
B(0,17,1,AIR)
B(1,17,1,AIR)
B(2,17,1,AIR)
B(3,17,1,AIR)
B(4,17,1,AIR)
B(5,17,1,AIR)
B(6,17,1,AIR)
B(7,17,1,AIR)
B(0,17,2,AIR)
B(1,17,2,AIR)
B(2,17,2,AIR)
B(3,17,2,AIR)
B(4,17,2,AIR)
B(5,17,2,AIR)
B(6,17,2,AIR)
B(7,17,2,AIR)
B(0,17,3,AIR)
B(1,17,3,AIR)
B(2,17,3,AIR)
B(3,17,3,AIR)
B(4,17,3,AIR)
B(5,17,3,AIR)
B(6,17,3,AIR)
B(7,17,3,AIR)
RB(0,17,4,STONEBRICK:1,10,STONEBRICK:2,10,COBBLESTONE,10,MOSSY_COBBLESTONE,10,SMOOTH_BRICK,100)
RB(1,17,4,STONEBRICK:1,10,STONEBRICK:2,10,COBBLESTONE,10,MOSSY_COBBLESTONE,10,SMOOTH_BRICK,100)
RB(2,17,4,STONEBRICK:1,10,STONEBRICK:2,10,COBBLESTONE,10,MOSSY_COBBLESTONE,10,SMOOTH_BRICK,100)
RB(3,17,4,STONEBRICK:1,10,STONEBRICK:2,10,COBBLESTONE,10,MOSSY_COBBLESTONE,10,SMOOTH_BRICK,100)
RB(4,17,4,STONEBRICK:1,10,STONEBRICK:2,10,COBBLESTONE,10,MOSSY_COBBLESTONE,10,SMOOTH_BRICK,100)
RB(5,17,4,STONEBRICK:1,10,STONEBRICK:2,10,COBBLESTONE,10,MOSSY_COBBLESTONE,10,SMOOTH_BRICK,100)
B(6,17,4,STONE_SLAB:8)
B(7,17,4,AIR)
RB(0,17,5,STONEBRICK:1,10,STONEBRICK:2,10,COBBLESTONE,10,MOSSY_COBBLESTONE,10,SMOOTH_BRICK,100)
RB(1,17,5,STONEBRICK:1,10,STONEBRICK:2,10,COBBLESTONE,10,MOSSY_COBBLESTONE,10,SMOOTH_BRICK,100)
RB(2,17,5,STONEBRICK:1,10,STONEBRICK:2,10,COBBLESTONE,10,MOSSY_COBBLESTONE,10,SMOOTH_BRICK,100)
RB(3,17,5,STONEBRICK:1,10,STONEBRICK:2,10,COBBLESTONE,10,MOSSY_COBBLESTONE,10,SMOOTH_BRICK,100)
RB(4,17,5,STONEBRICK:1,10,STONEBRICK:2,10,COBBLESTONE,10,MOSSY_COBBLESTONE,10,SMOOTH_BRICK,100)
RB(5,17,5,STONEBRICK:1,10,STONEBRICK:2,10,COBBLESTONE,10,MOSSY_COBBLESTONE,10,SMOOTH_BRICK,100)
RB(6,17,5,STONEBRICK:1,10,STONEBRICK:2,10,COBBLESTONE,10,MOSSY_COBBLESTONE,10,SMOOTH_BRICK,100)
RB(7,17,5,WEB,8,AIR,100)
RB(0,17,6,STONEBRICK:1,10,STONEBRICK:2,10,COBBLESTONE,10,MOSSY_COBBLESTONE,10,SMOOTH_BRICK,100)
RB(1,17,6,STONEBRICK:1,10,STONEBRICK:2,10,COBBLESTONE,10,MOSSY_COBBLESTONE,10,SMOOTH_BRICK,100)
RB(2,17,6,STONEBRICK:1,10,STONEBRICK:2,10,COBBLESTONE,10,MOSSY_COBBLESTONE,10,SMOOTH_BRICK,100)
RB(3,17,6,STONEBRICK:1,10,STONEBRICK:2,10,COBBLESTONE,10,MOSSY_COBBLESTONE,10,SMOOTH_BRICK,100)
RB(4,17,6,STONEBRICK:1,10,STONEBRICK:2,10,COBBLESTONE,10,MOSSY_COBBLESTONE,10,SMOOTH_BRICK,100)
RB(5,17,6,STONEBRICK:1,10,STONEBRICK:2,10,COBBLESTONE,10,MOSSY_COBBLESTONE,10,SMOOTH_BRICK,100)
RB(6,17,6,STONEBRICK:1,10,STONEBRICK:2,10,COBBLESTONE,10,MOSSY_COBBLESTONE,10,SMOOTH_BRICK,100)
RB(7,17,6,STONEBRICK:1,10,STONEBRICK:2,10,COBBLESTONE,10,MOSSY_COBBLESTONE,10,SMOOTH_BRICK,100)
RB(0,17,7,STONEBRICK:1,10,STONEBRICK:2,10,COBBLESTONE,10,MOSSY_COBBLESTONE,10,SMOOTH_BRICK,100)
RB(1,17,7,STONEBRICK:1,10,STONEBRICK:2,10,COBBLESTONE,10,MOSSY_COBBLESTONE,10,SMOOTH_BRICK,100)
RB(2,17,7,STONEBRICK:1,10,STONEBRICK:2,10,COBBLESTONE,10,MOSSY_COBBLESTONE,10,SMOOTH_BRICK,100)
RB(3,17,7,STONEBRICK:1,10,STONEBRICK:2,10,COBBLESTONE,10,MOSSY_COBBLESTONE,10,SMOOTH_BRICK,100)
RB(4,17,7,STONEBRICK:1,10,STONEBRICK:2,10,COBBLESTONE,10,MOSSY_COBBLESTONE,10,SMOOTH_BRICK,100)
RB(5,17,7,STONEBRICK:1,10,STONEBRICK:2,10,COBBLESTONE,10,MOSSY_COBBLESTONE,10,SMOOTH_BRICK,100)
RB(6,17,7,STONEBRICK:1,10,STONEBRICK:2,10,COBBLESTONE,10,MOSSY_COBBLESTONE,10,SMOOTH_BRICK,100)
RB(7,17,7,STONEBRICK:1,10,STONEBRICK:2,10,COBBLESTONE,10,MOSSY_COBBLESTONE,10,SMOOTH_BRICK,100)
B(0,18,0,STONE_BRICK_STAIRS:7)
B(1,18,0,STONE_SLAB:8)
B(2,18,0,STONE_BRICK_STAIRS:7)
B(3,18,0,STONE_SLAB:8)
B(4,18,0,STONE_BRICK_STAIRS:7)
RB(5,18,0,WEB,8,AIR,100)
B(6,18,0,STONE_BRICK_STAIRS:7)
RB(7,18,0,WEB,8,AIR,100)
B(0,18,1,STONE_SLAB:8)
B(1,18,1,STONE_SLAB:8)
B(2,18,1,STONE_SLAB:8)
B(3,18,1,STONE_SLAB:8)
B(4,18,1,STONE_SLAB:8)
RB(5,18,1,WEB,8,AIR,100)
B(6,18,1,AIR)
B(7,18,1,AIR)
B(0,18,2,STONE_SLAB:8)
B(1,18,2,STONE_SLAB:8)
B(2,18,2,STONE_SLAB:8)
B(3,18,2,STONE_SLAB:8)
B(4,18,2,STONE_SLAB:8)
RB(5,18,2,WEB,8,AIR,100)
B(6,18,2,AIR)
B(7,18,2,AIR)
B(0,18,3,STONE_BRICK_STAIRS:6)
B(1,18,3,STONE_SLAB:8)
B(2,18,3,STONE_BRICK_STAIRS:6)
B(3,18,3,STONE_SLAB:8)
B(4,18,3,STONE_BRICK_STAIRS:6)
RB(5,18,3,WEB,8,AIR,100)
B(6,18,3,STONE_BRICK_STAIRS:6)
RB(7,18,3,WEB,8,AIR,100)
RB(0,18,4,STONEBRICK:1,10,STONEBRICK:2,10,COBBLESTONE,10,MOSSY_COBBLESTONE,10,SMOOTH_BRICK,100)
RB(1,18,4,STONEBRICK:1,10,STONEBRICK:2,10,COBBLESTONE,10,MOSSY_COBBLESTONE,10,SMOOTH_BRICK,100)
RB(2,18,4,STONEBRICK:1,10,STONEBRICK:2,10,COBBLESTONE,10,MOSSY_COBBLESTONE,10,SMOOTH_BRICK,100)
RB(3,18,4,STONEBRICK:1,10,STONEBRICK:2,10,COBBLESTONE,10,MOSSY_COBBLESTONE,10,SMOOTH_BRICK,100)
RB(4,18,4,STONEBRICK:1,10,STONEBRICK:2,10,COBBLESTONE,10,MOSSY_COBBLESTONE,10,SMOOTH_BRICK,100)
RB(5,18,4,STONEBRICK:1,10,STONEBRICK:2,10,COBBLESTONE,10,MOSSY_COBBLESTONE,10,SMOOTH_BRICK,100)
RB(6,18,4,STONEBRICK:1,10,STONEBRICK:2,10,COBBLESTONE,10,MOSSY_COBBLESTONE,10,SMOOTH_BRICK,100)
B(7,18,4,STONE_SLAB:8)
RB(0,18,5,STONEBRICK:1,10,STONEBRICK:2,10,COBBLESTONE,10,MOSSY_COBBLESTONE,10,SMOOTH_BRICK,100)
RB(1,18,5,STONEBRICK:1,10,STONEBRICK:2,10,COBBLESTONE,10,MOSSY_COBBLESTONE,10,SMOOTH_BRICK,100)
RB(2,18,5,STONEBRICK:1,10,STONEBRICK:2,10,COBBLESTONE,10,MOSSY_COBBLESTONE,10,SMOOTH_BRICK,100)
RB(3,18,5,STONEBRICK:1,10,STONEBRICK:2,10,COBBLESTONE,10,MOSSY_COBBLESTONE,10,SMOOTH_BRICK,100)
RB(4,18,5,STONEBRICK:1,10,STONEBRICK:2,10,COBBLESTONE,10,MOSSY_COBBLESTONE,10,SMOOTH_BRICK,100)
RB(5,18,5,STONEBRICK:1,10,STONEBRICK:2,10,COBBLESTONE,10,MOSSY_COBBLESTONE,10,SMOOTH_BRICK,100)
RB(6,18,5,STONEBRICK:1,10,STONEBRICK:2,10,COBBLESTONE,10,MOSSY_COBBLESTONE,10,SMOOTH_BRICK,100)
RB(7,18,5,STONEBRICK:1,10,STONEBRICK:2,10,COBBLESTONE,10,MOSSY_COBBLESTONE,10,SMOOTH_BRICK,100)
RB(0,18,6,STONEBRICK:1,10,STONEBRICK:2,10,COBBLESTONE,10,MOSSY_COBBLESTONE,10,SMOOTH_BRICK,100)
RB(1,18,6,STONEBRICK:1,10,STONEBRICK:2,10,COBBLESTONE,10,MOSSY_COBBLESTONE,10,SMOOTH_BRICK,100)
RB(2,18,6,STONEBRICK:1,10,STONEBRICK:2,10,COBBLESTONE,10,MOSSY_COBBLESTONE,10,SMOOTH_BRICK,100)
RB(3,18,6,STONEBRICK:1,10,STONEBRICK:2,10,COBBLESTONE,10,MOSSY_COBBLESTONE,10,SMOOTH_BRICK,100)
RB(4,18,6,STONEBRICK:1,10,STONEBRICK:2,10,COBBLESTONE,10,MOSSY_COBBLESTONE,10,SMOOTH_BRICK,100)
RB(5,18,6,STONEBRICK:1,10,STONEBRICK:2,10,COBBLESTONE,10,MOSSY_COBBLESTONE,10,SMOOTH_BRICK,100)
RB(6,18,6,STONEBRICK:1,10,STONEBRICK:2,10,COBBLESTONE,10,MOSSY_COBBLESTONE,10,SMOOTH_BRICK,100)
RB(7,18,6,STONEBRICK:1,10,STONEBRICK:2,10,COBBLESTONE,10,MOSSY_COBBLESTONE,10,SMOOTH_BRICK,100)
RB(0,18,7,STONEBRICK:1,10,STONEBRICK:2,10,COBBLESTONE,10,MOSSY_COBBLESTONE,10,SMOOTH_BRICK,100)
RB(1,18,7,STONEBRICK:1,10,STONEBRICK:2,10,COBBLESTONE,10,MOSSY_COBBLESTONE,10,SMOOTH_BRICK,100)
RB(2,18,7,STONEBRICK:1,10,STONEBRICK:2,10,COBBLESTONE,10,MOSSY_COBBLESTONE,10,SMOOTH_BRICK,100)
RB(3,18,7,STONEBRICK:1,10,STONEBRICK:2,10,COBBLESTONE,10,MOSSY_COBBLESTONE,10,SMOOTH_BRICK,100)
RB(4,18,7,STONEBRICK:1,10,STONEBRICK:2,10,COBBLESTONE,10,MOSSY_COBBLESTONE,10,SMOOTH_BRICK,100)
RB(5,18,7,STONEBRICK:1,10,STONEBRICK:2,10,COBBLESTONE,10,MOSSY_COBBLESTONE,10,SMOOTH_BRICK,100)
RB(6,18,7,STONEBRICK:1,10,STONEBRICK:2,10,COBBLESTONE,10,MOSSY_COBBLESTONE,10,SMOOTH_BRICK,100)
RB(7,18,7,STONEBRICK:1,10,STONEBRICK:2,10,COBBLESTONE,10,MOSSY_COBBLESTONE,10,SMOOTH_BRICK,100)
