Author: Bo3 BulkEdit

Description: Converted Schematic - Modified by Bo3BulkEdit

Version: 3

SettingsMode: WriteDisable

IsOTGPlus: false
Tree: false
Frequency: 1
Rarity: 100
RotateRandomly: false
SpawnHeight: randomY
MaxBranchDepth: 20
ExcludedBiomes: All

MinHeight: 0
MaxHeight: 256

SourceBlocks: AIR
MaxPercentageOutsideSourceBlock: 100
OutsideSourceBlock: placeAnyway

B(-8,-9,-1,LOG2:13)
B(-7,-9,-1,LOG2:13)
B(-6,-9,-1,LOG2:13)
B(-5,-9,-1,LOG2:13)
B(-4,-9,-1,LOG2:13)
B(-3,-9,-1,LOG2:13)
B(-2,-9,-1,LOG2:13)
B(-1,-9,-1,LOG2:13)
B(-7,-8,-3,LOG2:13)
B(-6,-8,-3,LOG2:13)
B(-5,-8,-3,LOG2:13)
B(-4,-8,-3,LOG2:13)
B(-3,-8,-3,LOG2:13)
B(-2,-8,-3,LOG2:13)
B(-1,-8,-3,LOG2:13)
B(-8,-8,-2,LOG2:13)
B(-7,-8,-2,LOG2:13)
B(-6,-8,-2,LOG2:13)
B(-5,-8,-2,LOG2:13)
B(-4,-8,-2,LOG2:13)
B(-3,-8,-2,LOG2:13)
B(-2,-8,-2,LOG2:13)
B(-1,-8,-2,LOG2:13)
B(-8,-8,-1,LOG2:13)
B(-7,-8,-1,LOG2:13)
B(-6,-8,-1,LOG2:13)
B(-5,-8,-1,COAL_ORE:0)
B(-4,-8,-1,LAPIS_ORE:0)
B(-3,-8,-1,LAPIS_ORE:0)
B(-2,-8,-1,LAPIS_ORE:0)
B(-1,-8,-1,GOLD_ORE:0)
B(-8,-7,-5,LOG2:13)
B(-7,-7,-5,LOG2:13)
B(-6,-7,-5,LOG2:13)
B(-5,-7,-5,LOG2:13)
B(-4,-7,-5,LOG2:13)
B(-3,-7,-5,LOG2:13)
B(-2,-7,-5,LOG2:13)
B(-1,-7,-5,LOG2:13)
B(-8,-7,-4,LOG2:13)
B(-7,-7,-4,LOG2:13)
B(-6,-7,-4,LOG2:13)
B(-5,-7,-4,LOG2:13)
B(-4,-7,-4,LOG2:13)
B(-3,-7,-4,LOG2:13)
B(-2,-7,-4,LOG2:13)
B(-1,-7,-4,LOG2:13)
B(-8,-7,-3,LOG2:13)
B(-7,-7,-3,PLANKS:5)
B(-6,-7,-3,GOLD_ORE:0)
B(-5,-7,-3,IRON_ORE:0)
B(-4,-7,-3,GOLD_ORE:0)
B(-3,-7,-3,LAPIS_ORE:0)
B(-2,-7,-3,GOLD_ORE:0)
B(-1,-7,-3,LAPIS_ORE:0)
B(-8,-7,-2,AIR:0)
B(-7,-7,-2,PLANKS:5)
B(-6,-7,-2,IRON_ORE:0)
B(-5,-7,-2,IRON_ORE:0)
B(-4,-7,-2,IRON_ORE:0)
B(-3,-7,-2,COAL_ORE:0)
B(-2,-7,-2,LAPIS_ORE:0)
B(-1,-7,-2,LAPIS_ORE:0)
B(-8,-7,-1,LADDER:4)
B(-7,-7,-1,PLANKS:5)
B(-6,-7,-1,LADDER:5)
B(-5,-7,-1,AIR:0)
B(-4,-7,-1,CONCRETE:15)
B(-3,-7,-1,COAL_ORE:0)
B(-2,-7,-1,IRON_ORE:0)
B(-1,-7,-1,IRON_ORE:0)
B(-8,-6,-6,LOG2:13)
B(-7,-6,-6,LOG2:13)
B(-6,-6,-6,LOG2:13)
B(-5,-6,-6,LOG2:13)
B(-4,-6,-6,LOG2:13)
B(-3,-6,-6,LOG2:13)
B(-2,-6,-6,LOG2:13)
B(-1,-6,-6,LOG2:13)
B(-8,-6,-5,MELON_BLOCK:0)
B(-7,-6,-5,PLANKS:5)
B(-6,-6,-5,LAPIS_ORE:0)
B(-5,-6,-5,GOLD_ORE:0)
B(-4,-6,-5,LAPIS_ORE:0)
B(-3,-6,-5,LAPIS_ORE:0)
B(-2,-6,-5,LAPIS_ORE:0)
B(-1,-6,-5,GOLD_ORE:0)
B(-8,-6,-4,HAY_BLOCK:0)
B(-7,-6,-4,PLANKS:5)
B(-6,-6,-4,GOLD_ORE:0)
B(-5,-6,-4,LAPIS_ORE:0)
B(-4,-6,-4,IRON_ORE:0)
B(-3,-6,-4,IRON_ORE:0)
B(-2,-6,-4,IRON_ORE:0)
B(-1,-6,-4,IRON_ORE:0)
B(-8,-6,-3,HAY_BLOCK:0)
B(-7,-6,-3,PLANKS:5)
B(-6,-6,-3,IRON_ORE:0)
B(-5,-6,-3,REDSTONE_ORE:0)
B(-4,-6,-3,REDSTONE_ORE:0)
B(-3,-6,-3,COAL_ORE:0)
B(-2,-6,-3,REDSTONE_ORE:0)
B(-1,-6,-3,REDSTONE_ORE:0)
B(-8,-6,-2,AIR:0)
B(-7,-6,-2,PLANKS:5)
B(-6,-6,-2,AIR:0)
B(-5,-6,-2,AIR:0)
B(-4,-6,-2,AIR:0)
B(-3,-6,-2,CONCRETE:15)
B(-2,-6,-2,COAL_ORE:0)
B(-1,-6,-2,COAL_ORE:0)
B(-8,-6,-1,LADDER:4)
B(-7,-6,-1,PLANKS:5)
B(-6,-6,-1,LADDER:5)
B(-5,-6,-1,AIR:0)
B(-4,-6,-1,AIR:0)
B(-3,-6,-1,AIR:0)
B(-2,-6,-1,COAL_ORE:0)
B(-1,-6,-1,COAL_ORE:0)
B(-8,-5,-6,LOG2:13)
B(-7,-5,-6,LOG2:13)
B(-6,-5,-6,LOG2:13)
B(-5,-5,-6,LOG2:13)
B(-4,-5,-6,LOG2:13)
B(-3,-5,-6,LOG2:13)
B(-2,-5,-6,LOG2:13)
B(-1,-5,-6,LOG2:13)
B(-8,-5,-5,MELON_BLOCK:0)
B(-7,-5,-5,PLANKS:5)
B(-6,-5,-5,LAPIS_ORE:0)
B(-5,-5,-5,REDSTONE_ORE:0)
B(-4,-5,-5,REDSTONE_ORE:0)
B(-3,-5,-5,IRON_ORE:0)
B(-2,-5,-5,REDSTONE_ORE:0)
B(-1,-5,-5,IRON_ORE:0)
B(-8,-5,-4,AIR:0)
B(-7,-5,-4,PLANKS:5)
B(-6,-5,-4,REDSTONE_ORE:0)
B(-5,-5,-4,CONCRETE:15)
B(-4,-5,-4,REDSTONE_ORE:0)
B(-3,-5,-4,COAL_ORE:0)
B(-2,-5,-4,COAL_ORE:0)
B(-1,-5,-4,COAL_ORE:0)
B(-8,-5,-3,AIR:0)
B(-7,-5,-3,PLANKS:5)
B(-6,-5,-3,AIR:0)
B(-5,-5,-3,AIR:0)
B(-4,-5,-3,AIR:0)
B(-3,-5,-3,CONCRETE:15)
B(-2,-5,-3,COAL_ORE:0)
B(-1,-5,-3,COAL_ORE:0)
B(-8,-5,-2,AIR:0)
B(-7,-5,-2,PLANKS:5)
B(-6,-5,-2,AIR:0)
B(-5,-5,-2,AIR:0)
B(-4,-5,-2,AIR:0)
B(-3,-5,-2,AIR:0)
B(-2,-5,-2,AIR:0)
B(-1,-5,-2,COAL_ORE:0)
B(-8,-5,-1,LADDER:4)
B(-7,-5,-1,PLANKS:5)
B(-6,-5,-1,LADDER:5)
B(-5,-5,-1,AIR:0)
B(-4,-5,-1,AIR:0)
B(-3,-5,-1,AIR:0)
B(-2,-5,-1,CONCRETE:15)
B(-1,-5,-1,COAL_ORE:0)
B(-8,-4,-7,PLANKS:5)
B(-7,-4,-7,PLANKS:5)
B(-6,-4,-7,PLANKS:5)
B(-5,-4,-7,PLANKS:5)
B(-4,-4,-7,PLANKS:5)
B(-3,-4,-7,PLANKS:5)
B(-2,-4,-7,PLANKS:5)
B(-1,-4,-7,PLANKS:5)
B(-8,-4,-6,PLANKS:5)
B(-7,-4,-6,PLANKS:5)
B(-6,-4,-6,PLANKS:5)
B(-5,-4,-6,PLANKS:5)
B(-4,-4,-6,PLANKS:5)
B(-3,-4,-6,PLANKS:5)
B(-2,-4,-6,PLANKS:5)
B(-1,-4,-6,PLANKS:5)
B(-8,-4,-5,PLANKS:5)
B(-7,-4,-5,PLANKS:5)
B(-6,-4,-5,PLANKS:5)
B(-5,-4,-5,PLANKS:5)
B(-4,-4,-5,PLANKS:5)
B(-3,-4,-5,PLANKS:5)
B(-2,-4,-5,PLANKS:5)
B(-1,-4,-5,PLANKS:5)
B(-8,-4,-4,PLANKS:5)
B(-7,-4,-4,PLANKS:5)
B(-6,-4,-4,PLANKS:5)
B(-5,-4,-4,PLANKS:5)
B(-4,-4,-4,PLANKS:5)
B(-3,-4,-4,PLANKS:5)
B(-2,-4,-4,PLANKS:5)
B(-1,-4,-4,PLANKS:5)
B(-8,-4,-3,PLANKS:5)
B(-7,-4,-3,PLANKS:5)
B(-6,-4,-3,PLANKS:5)
B(-5,-4,-3,PLANKS:5)
B(-4,-4,-3,PLANKS:5)
B(-3,-4,-3,PLANKS:5)
B(-2,-4,-3,PLANKS:5)
B(-1,-4,-3,PLANKS:5)
B(-8,-4,-2,PLANKS:5)
B(-7,-4,-2,PLANKS:5)
B(-6,-4,-2,PLANKS:5)
B(-5,-4,-2,PLANKS:5)
B(-4,-4,-2,PLANKS:5)
B(-3,-4,-2,PLANKS:5)
B(-2,-4,-2,PLANKS:5)
B(-1,-4,-2,PLANKS:5)
B(-8,-4,-1,TRAPDOOR:8)
B(-7,-4,-1,DOUBLE_WOODEN_SLAB:1)
B(-6,-4,-1,TRAPDOOR:8)
B(-5,-4,-1,TRAPDOOR:8)
B(-4,-4,-1,TRAPDOOR:8)
B(-3,-4,-1,TRAPDOOR:8)
B(-2,-4,-1,PLANKS:5)
B(-1,-4,-1,PLANKS:5)
B(-8,-3,-8,TRAPDOOR:8)
B(-5,-3,-8,TRAPDOOR:8)
B(-2,-3,-8,TRAPDOOR:8)
B(-8,-3,-7,DISPENSER:2)
B(-7,-3,-7,PLANKS:5)
B(-6,-3,-7,PLANKS:5)
B(-5,-3,-7,DISPENSER:2)
B(-4,-3,-7,PLANKS:5)
B(-3,-3,-7,PLANKS:5)
B(-2,-3,-7,DISPENSER:2)
B(-1,-3,-7,PLANKS:5)
B(-8,-3,-6,CONCRETE:15)
B(-7,-3,-6,STONE_BUTTON:1)
B(-6,-3,-6,TRIPWIRE_HOOK:0)
B(-5,-3,-6,CONCRETE:15)
B(-4,-3,-6,STONE_BUTTON:1)
B(-3,-3,-6,TRIPWIRE_HOOK:0)
B(-2,-3,-6,CONCRETE:15)
B(-1,-3,-6,STONE_BUTTON:1)
B(-8,-3,-5,DARK_OAK_STAIRS:3)
B(-6,-3,-5,TRIPWIRE:0)
B(-5,-3,-5,DARK_OAK_STAIRS:3)
B(-3,-3,-5,TRIPWIRE:0)
B(-2,-3,-5,DARK_OAK_STAIRS:3)
B(-7,-3,-4,CARPET:12)
B(-5,-3,-4,CARPET:12)
B(-4,-3,-4,CARPET:13)
B(-3,-3,-4,CARPET:12)
B(-2,-3,-4,CARPET:12)
B(-8,-3,-3,STONE_BUTTON:4)
B(-7,-3,-3,STONE_BUTTON:4)
B(-6,-3,-3,STONE_BUTTON:4)
B(-5,-3,-3,CARPET:12)
B(-4,-3,-3,CARPET:12)
B(-3,-3,-3,STONE_BUTTON:4)
B(-2,-3,-3,STONE_BUTTON:4)
B(-1,-3,-3,CARPET:12)
B(-8,-3,-2,PLANKS:2)
B(-7,-3,-2,PLANKS:2)
B(-6,-3,-2,PLANKS:2)
B(-5,-3,-2,STONE_BUTTON:1)
B(-4,-3,-2,STONE_BUTTON:2)
B(-3,-3,-2,PLANKS:2)
B(-2,-3,-2,PLANKS:2)
B(-1,-3,-2,STONE_BUTTON:1)
B(-8,-3,-1,STONE_BUTTON:3)
B(-7,-3,-1,STONE_BUTTON:3)
B(-6,-3,-1,STONE_BUTTON:3)
B(-3,-3,-1,STONE_BUTTON:2)
B(-2,-3,-1,PLANKS:2)
B(-1,-3,-1,STAINED_HARDENED_CLAY:9)
B(-8,-2,-8,WOODEN_BUTTON:4)
B(-7,-2,-8,WOODEN_BUTTON:4)
B(-6,-2,-8,WOODEN_BUTTON:4)
B(-5,-2,-8,WOODEN_BUTTON:4)
B(-4,-2,-8,WOODEN_BUTTON:4)
B(-3,-2,-8,WOODEN_BUTTON:4)
B(-2,-2,-8,WOODEN_BUTTON:4)
B(-1,-2,-8,WOODEN_BUTTON:4)
B(-8,-2,-7,PLANKS:5)
B(-7,-2,-7,PLANKS:5)
B(-6,-2,-7,PLANKS:5)
B(-5,-2,-7,PLANKS:5)
B(-4,-2,-7,PLANKS:5)
B(-3,-2,-7,PLANKS:5)
B(-2,-2,-7,PLANKS:5)
B(-1,-2,-7,PLANKS:5)
B(-8,-2,-6,WOODEN_BUTTON:5)
B(-7,-2,-6,WOODEN_SLAB:5)
B(-6,-2,-6,WOODEN_SLAB:5)
B(-5,-2,-6,WOODEN_BUTTON:5)
B(-4,-2,-6,WOODEN_SLAB:5)
B(-3,-2,-6,WOODEN_SLAB:5)
B(-2,-2,-6,WOODEN_BUTTON:5)
B(-1,-2,-6,WOODEN_SLAB:5)
B(-7,-2,-4,AIR)
B(-8,-2,-2,STONE_BUTTON:5)
B(-7,-2,-2,STONE_BUTTON:5)
B(-6,-2,-2,STONE_BUTTON:5)
B(-3,-2,-2,STONE_BUTTON:5)
B(-2,-2,-2,STONE_BUTTON:5)
B(-2,-2,-1,STONE_BUTTON:5)
B(-1,-2,-1,STAINED_HARDENED_CLAY:9)
B(-8,-1,-7,STAINED_HARDENED_CLAY:9)
B(-7,-1,-7,STAINED_HARDENED_CLAY:9)
B(-6,-1,-7,STAINED_HARDENED_CLAY:9)
B(-5,-1,-7,STAINED_HARDENED_CLAY:9)
B(-4,-1,-7,STAINED_HARDENED_CLAY:9)
B(-3,-1,-7,STAINED_HARDENED_CLAY:9)
B(-2,-1,-7,STAINED_HARDENED_CLAY:9)
B(-1,-1,-7,STAINED_HARDENED_CLAY:9)
B(-8,-1,-6,WOODEN_SLAB:13)
B(-7,-1,-6,WOODEN_SLAB:13)
B(-6,-1,-6,WOODEN_SLAB:13)
B(-5,-1,-6,WOODEN_SLAB:13)
B(-4,-1,-6,WOODEN_SLAB:13)
B(-3,-1,-6,WOODEN_SLAB:13)
B(-2,-1,-6,WOODEN_SLAB:13)
B(-1,-1,-6,WOODEN_SLAB:13)
B(-8,-1,-5,WOODEN_SLAB:13)
B(-7,-1,-5,WOODEN_SLAB:13)
B(-6,-1,-5,WOODEN_SLAB:13)
B(-5,-1,-5,WOODEN_SLAB:13)
B(-4,-1,-5,WOODEN_SLAB:13)
B(-3,-1,-5,WOODEN_SLAB:13)
B(-2,-1,-5,WOODEN_SLAB:13)
B(-1,-1,-5,WOODEN_SLAB:13)
B(-8,-1,-4,WOODEN_SLAB:13)
B(-7,-1,-4,WOODEN_SLAB:13)
B(-6,-1,-4,WOODEN_SLAB:13)
B(-5,-1,-4,WOODEN_SLAB:13)
B(-4,-1,-4,WOODEN_SLAB:13)
B(-3,-1,-4,WOODEN_SLAB:13)
B(-2,-1,-4,WOODEN_SLAB:13)
B(-1,-1,-4,WOODEN_SLAB:13)
B(-8,-1,-3,WOODEN_SLAB:13)
B(-7,-1,-3,WOODEN_SLAB:13)
B(-6,-1,-3,WOODEN_SLAB:13)
B(-5,-1,-3,WOODEN_SLAB:13)
B(-4,-1,-3,WOODEN_SLAB:13)
B(-3,-1,-3,WOODEN_SLAB:13)
B(-2,-1,-3,WOODEN_SLAB:13)
B(-1,-1,-3,WOODEN_SLAB:13)
B(-8,-1,-2,WOODEN_SLAB:13)
B(-7,-1,-2,WOODEN_SLAB:13)
B(-6,-1,-2,WOODEN_SLAB:13)
B(-5,-1,-2,WOODEN_SLAB:13)
B(-4,-1,-2,WOODEN_SLAB:13)
B(-3,-1,-2,WOODEN_SLAB:13)
B(-2,-1,-2,WOODEN_SLAB:13)
B(-1,-1,-2,WOODEN_SLAB:13)
B(-3,-1,-1,WOODEN_SLAB:13)
B(-2,-1,-1,WOODEN_SLAB:13)
B(-1,-1,-1,DOUBLE_WOODEN_SLAB:5)
B(-6,0,-8,DISPENSER:2)
B(-3,0,-8,DISPENSER:2)
B(-7,0,-7,STAINED_HARDENED_CLAY:9)
B(-6,0,-7,CONCRETE:15)
B(-5,0,-7,STAINED_HARDENED_CLAY:9)
B(-4,0,-7,STAINED_HARDENED_CLAY:9)
B(-3,0,-7,CONCRETE:15)
B(-2,0,-7,STAINED_HARDENED_CLAY:9)
B(-1,0,-7,STAINED_HARDENED_CLAY:9)
B(-8,0,-6,STAINED_HARDENED_CLAY:9)
B(-7,0,-6,WOODEN_BUTTON:2)
B(-6,0,-6,DISPENSER:9)
B(-5,0,-6,WOODEN_BUTTON:1)
B(-4,0,-6,WOODEN_BUTTON:2)
B(-3,0,-6,DISPENSER:9)
B(-2,0,-6,WOODEN_BUTTON:1)
B(-1,0,-6,WOODEN_BUTTON:2)
B(-6,0,-5,SPRUCE_STAIRS:3)
B(-3,0,-5,SPRUCE_STAIRS:3)
B(-7,0,-4,STONE_BUTTON:4)
B(-6,0,-4,STONE_BUTTON:4)
B(-5,0,-4,STONE_BUTTON:4)
B(-8,0,-3,STONE_BUTTON:2)
B(-7,0,-3,PLANKS:2)
B(-6,0,-3,PLANKS:2)
B(-5,0,-3,PLANKS:2)
B(-4,0,-3,STONE_BUTTON:1)
B(-3,0,-3,STONE_BUTTON:4)
B(-2,0,-3,STONE_BUTTON:4)
RB(-8,0,-2,CHEST:2,../NBT/StructureLoot/JunkChest_1.nbt,15,CHEST:2,../NBT/StructureLoot/JunkChest_2.nbt,15,CHEST:2,../NBT/StructureLoot/JunkChest_3.nbt,15,CHEST:2,../NBT/StructureLoot/JunkChest_4.nbt,15,CHEST:2,../NBT/StructureLoot/JunkChest_5.nbt,15,CHEST:2,../NBT/StructureLoot/Common1.nbt,15,CHEST:2,../NBT/StructureLoot/Common2.nbt,15,CHEST:2,../NBT/StructureLoot/Common3.nbt,15,CHEST:2,../NBT/StructureLoot/Common4.nbt,15,CHEST:2,../NBT/StructureLoot/Common5.nbt,15,CHEST:2,../NBT/StructureLoot/Common6.nbt,15,CHEST:2,../NBT/StructureLoot/Common7.nbt,15,CHEST:2,../NBT/StructureLoot/Common8.nbt,15,CHEST:2,../NBT/StructureLoot/Common9.nbt,15,CHEST:2,../NBT/StructureLoot/Common10.nbt,15,CHEST:2,../NBT/StructureLoot/Common11.nbt,15,CHEST:2,../NBT/StructureLoot/Common12.nbt,15,CHEST:2,../NBT/StructureLoot/Common13.nbt,15,CHEST:2,../NBT/StructureLoot/Common14.nbt,15,CHEST:2,../NBT/StructureLoot/Common15.nbt,100)
B(-7,0,-2,STONE_BUTTON:3)
B(-6,0,-2,STONE_BUTTON:3)
B(-5,0,-2,STONE_BUTTON:3)
B(-4,0,-2,STONE_BUTTON:2)
B(-3,0,-2,PLANKS:2)
B(-2,0,-2,PLANKS:2)
B(-1,0,-2,DARK_OAK_FENCE:0)
B(-8,0,-1,TRAPDOOR:0)
B(-7,0,-1,TRAPDOOR:0)
B(-6,0,-1,TRAPDOOR:0)
B(-5,0,-1,TRAPDOOR:0)
B(-4,0,-1,TRAPDOOR:0)
B(-3,0,-1,STONE_BUTTON:3)
B(-1,0,-1,DARK_OAK_FENCE:0)
B(-7,1,-7,WOODEN_SLAB:5)
B(-5,1,-7,WOODEN_SLAB:5)
B(-4,1,-7,WOODEN_SLAB:5)
B(-2,1,-7,WOODEN_SLAB:5)
B(-1,1,-7,WOODEN_SLAB:5)
B(-8,1,-6,WOODEN_SLAB:5)
B(-6,1,-6,LEVER:13)
B(-3,1,-6,LEVER:13)
B(-7,1,-3,STONE_BUTTON:5)
B(-6,1,-3,STONE_BUTTON:5)
B(-5,1,-3,STONE_BUTTON:5)
B(-3,1,-2,STONE_BUTTON:5)
B(-2,1,-2,STONE_BUTTON:5)
B(-3,3,-1,WOOL:15)
B(-2,3,-1,WOOL:15)
B(-1,3,-1,SPRUCE_FENCE:0)
B(-7,4,-1,WOOL:15)
B(-6,4,-1,WOOL:15)
B(-5,4,-1,WOOL:15)
B(-4,4,-1,WOOL:15)
B(-3,4,-1,WOOL:15)
B(-6,5,-2,WOOL:15)
B(-5,5,-2,WOOL:15)
B(-4,5,-2,WOOL:15)
B(-8,5,-1,WOOL:15)
B(-7,5,-1,WOOL:15)
B(-3,5,-1,WOOL:15)
B(-4,6,-2,WOOL:15)
B(-3,6,-2,WOOL:15)
B(-7,6,-1,WOOL:15)
B(-6,6,-1,WOOL:15)
B(-5,6,-1,WOOL:15)
B(-5,7,-1,WOOL:15)
B(-4,7,-1,WOOL:15)
B(-3,7,-1,WOOL:15)
B(-3,8,-1,WOOL:15)
B(-2,8,-1,WOOL:15)
B(-2,9,-1,WOOL:15)
B(-8,14,-1,WOOL:15)
B(-4,14,-1,WOOL:15)
B(-8,15,-1,WOOL:15)
B(-7,15,-1,WOOL:15)
B(-6,15,-1,WOOL:15)
B(-5,15,-1,WOOL:15)
B(-4,15,-1,WOOL:15)
B(-8,16,-2,WOOL:15)
B(-7,16,-2,WOOL:15)
B(-6,16,-1,WOOL:15)
B(-5,16,-1,WOOL:15)
B(-1,16,-1,WOOL:15)
B(-8,17,-2,WOOL:15)
B(-7,17,-2,WOOL:15)
B(-6,17,-2,WOOL:15)
B(-5,17,-2,WOOL:15)
B(-1,17,-2,WOOL:15)
B(-1,17,-1,WOOL:15)
B(-8,18,-2,WOOL:15)
B(-7,18,-2,WOOL:15)
B(-6,18,-2,WOOL:15)
B(-5,18,-2,WOOL:15)
B(-1,18,-1,WOOL:15)
B(-6,19,-2,WOOL:15)
B(-5,19,-2,WOOL:15)
B(-4,19,-2,WOOL:15)
B(-8,19,-1,WOOL:15)
B(-7,19,-1,WOOL:15)
B(-3,20,-2,WOOL:15)
B(-7,20,-1,WOOL:15)
B(-6,20,-1,WOOL:15)
B(-5,20,-1,WOOL:15)
B(-4,20,-1,WOOL:15)
B(-5,21,-1,WOOL:15)
B(-4,21,-1,WOOL:15)
B(-3,21,-1,WOOL:15)
B(-3,22,-1,WOOL:15)
B(-2,22,-1,WOOL:15)

E(-7,-2,-4,VINDICATOR,1,../NBT/MOBS/RandomPillager.txt)

BR(-8,0,0,WestPortShipPillager_4x3,NORTH,100)
