
#######################################################################
# +-----------------------------------------------------------------+ #
# |                            BO3 object                           | #
# +-----------------------------------------------------------------+ #
#######################################################################

Author: BO3 BulkEdit (by LanToaster)

Description: This Object was Created with BO3_BulkEdit

Version: 3

SettingsMode: WriteDisable


#######################################################################
# +-----------------------------------------------------------------+ #
# |                          Main settings                          | #
# +-----------------------------------------------------------------+ #
#######################################################################

Tree: false

Frequency: 100

Rarity: 100.0

RotateRandomly: true

SpawnHeight: randomY

SpawnHeightOffset: 0

SpawnHeightVariance: 0

##############################
# Height Limits for the BO3. #
##############################

MinHeight: 82

MaxHeight: 82

######################
# Extrusion settings #
######################

ExtrudeMode: None

ExtrudeThroughBlocks: AIR

MaxBranchDepth: 50

ExcludedBiomes: All


#######################################################################
# +-----------------------------------------------------------------+ #
# |                      Source block settings                      | #
# +-----------------------------------------------------------------+ #
#######################################################################

SourceBlocks: AIR

MaxPercentageOutsideSourceBlock: 100

OutsideSourceBlock: placeAnyway

IsOTGPlus: false

InheritBO3: 

InheritBO3Rotation: NORTH

OverrideChildSettings: true

OverrideParentHeight: false

CanOverride: false

BranchFrequency: 0

BranchFrequencyGroup: 

MustBeBelowOther: false

MustBeInside: 

CannotBeInside: 

ReplacesBO3: 

CanSpawnOnWater: true

SpawnOnWaterOnly: false

SpawnUnderWater: false

SpawnAtWaterLevel: false

HeightOffset: 0

RemoveAir: true

ReplaceAbove: 

ReplaceBelow: 

ReplaceWithBiomeBlocks: true

ReplaceWithGroundBlock: DIRT

ReplaceWithSurfaceBlock: GRASS

SmoothRadius: 0

SmoothHeightOffset: 0

SmoothStartTop: false

SmoothStartWood: false

SmoothingSurfaceBlock: 

SmoothingGroundBlock: 

BO3Group: 

IsSpawnPoint: false


#######################################################################
# +-----------------------------------------------------------------+ #
# |                              Blocks                             | #
# +-----------------------------------------------------------------+ #
#######################################################################

Block(-7,-1,-7,LOG:3)
Block(-3,-1,-7,LOG:3)
Block(0,-1,-7,LOG:3)
Block(5,-1,-7,LOG:3)
Block(-7,-1,-3,LOG:3)
Block(-3,-1,-3,LOG:3)
Block(0,-1,-3,LOG:3)
Block(5,-1,-3,LOG:3)
Block(-7,-1,0,LOG:3)
Block(-3,-1,0,LOG:3)
Block(0,-1,0,LOG:3)
Block(5,-1,0,LOG:3)
Block(-7,-1,4,LOG:3)
Block(-3,-1,4,LOG:3)
Block(0,-1,4,LOG:3)
Block(5,-1,4,LOG:3)
Block(-3,-1,5,BIRCH_WOOD_STAIRS:0)
Block(-2,-1,5,BIRCH_WOOD_STAIRS:5)
Block(-7,0,-7,LOG:3)
Block(-6,0,-7,LOG:7)
Block(-5,0,-7,LOG:7)
Block(-4,0,-7,LOG:7)
Block(-3,0,-7,LOG:3)
Block(-2,0,-7,LOG:7)
Block(-1,0,-7,LOG:7)
Block(0,0,-7,LOG:3)
Block(1,0,-7,LOG:7)
Block(2,0,-7,LOG:7)
Block(3,0,-7,LOG:7)
Block(4,0,-7,LOG:7)
Block(5,0,-7,LOG:3)
Block(-7,0,-6,LOG:11)
Block(-6,0,-6,WOOD_STEP:11)
Block(-5,0,-6,WOOD_STEP:11)
Block(-4,0,-6,WOOD_STEP:11)
Block(-3,0,-6,WOOD_STEP:11)
Block(-2,0,-6,WOOD_STEP:11)
Block(-1,0,-6,WOOD_STEP:11)
Block(0,0,-6,WOOD_STEP:11)
Block(1,0,-6,WOOD_STEP:11)
Block(2,0,-6,WOOD_STEP:11)
Block(3,0,-6,WOOD_STEP:11)
Block(4,0,-6,WOOD_STEP:11)
Block(5,0,-6,LOG:11)
Block(-7,0,-5,LOG:11)
Block(-6,0,-5,WOOD_STEP:11)
Block(-5,0,-5,WOOD_STEP:11)
Block(-4,0,-5,WOOD_STEP:11)
Block(-3,0,-5,WOOD_STEP:11)
Block(-2,0,-5,WOOD_STEP:11)
Block(-1,0,-5,WOOD_STEP:11)
Block(0,0,-5,WOOD_STEP:11)
Block(1,0,-5,WOOD_STEP:11)
Block(2,0,-5,WOOD_STEP:11)
Block(3,0,-5,WOOD_STEP:11)
Block(4,0,-5,WOOD_STEP:11)
Block(5,0,-5,LOG:11)
Block(-7,0,-4,LOG:11)
Block(-6,0,-4,WOOD_STEP:11)
Block(-5,0,-4,WOOD_STEP:11)
Block(-4,0,-4,WOOD_STEP:11)
Block(-3,0,-4,WOOD_STEP:11)
Block(-2,0,-4,WOOD_STEP:11)
Block(-1,0,-4,WOOD_STEP:11)
Block(0,0,-4,WOOD_STEP:11)
Block(1,0,-4,WOOD_STEP:11)
Block(2,0,-4,WOOD_STEP:11)
Block(3,0,-4,WOOD_STEP:11)
Block(4,0,-4,WOOD_STEP:11)
Block(5,0,-4,LOG:11)
Block(-7,0,-3,LOG:3)
Block(-6,0,-3,WOOD_STEP:11)
Block(-5,0,-3,WOOD_STEP:11)
Block(-4,0,-3,WOOD_STEP:11)
Block(-3,0,-3,LOG:3)
Block(-2,0,-3,WOOD_STEP:11)
Block(-1,0,-3,WOOD_STEP:11)
Block(0,0,-3,LOG:3)
Block(1,0,-3,WOOD_STEP:11)
Block(2,0,-3,WOOD_STEP:11)
Block(3,0,-3,WOOD_STEP:11)
Block(4,0,-3,WOOD_STEP:11)
Block(5,0,-3,LOG:3)
Block(-7,0,-2,LOG:11)
Block(-6,0,-2,WOOD_STEP:11)
Block(-5,0,-2,WOOD_STEP:11)
Block(-4,0,-2,WOOD_STEP:11)
Block(-3,0,-2,WOOD_STEP:11)
Block(-2,0,-2,WOOD_STEP:11)
Block(-1,0,-2,WOOD_STEP:11)
Block(0,0,-2,WOOD_STEP:11)
Block(1,0,-2,WOOD_STEP:11)
Block(2,0,-2,WOOD_STEP:11)
Block(3,0,-2,WOOD_STEP:11)
Block(4,0,-2,WOOD_STEP:11)
Block(5,0,-2,LOG:11)
Block(-7,0,-1,LOG:11)
Block(-6,0,-1,WOOD_STEP:11)
Block(-5,0,-1,WOOD_STEP:11)
Block(-4,0,-1,WOOD_STEP:11)
Block(-3,0,-1,WOOD_STEP:11)
Block(-2,0,-1,WOOD_STEP:11)
Block(-1,0,-1,WOOD_STEP:11)
Block(0,0,-1,WOOD_STEP:11)
Block(1,0,-1,WOOD_STEP:11)
Block(2,0,-1,WOOD_STEP:11)
Block(3,0,-1,WOOD_STEP:11)
Block(4,0,-1,WOOD_STEP:11)
Block(5,0,-1,LOG:11)
Block(-7,0,0,LOG:3)
Block(-6,0,0,WOOD_STEP:11)
Block(-5,0,0,WOOD_STEP:11)
Block(-4,0,0,WOOD_STEP:11)
Block(-3,0,0,LOG:3)
Block(-2,0,0,WOOD_STEP:11)
Block(-1,0,0,WOOD_STEP:11)
Block(0,0,0,LOG:3)
Block(1,0,0,WOOD_STEP:11)
Block(2,0,0,WOOD_STEP:11)
Block(3,0,0,WOOD_STEP:11)
Block(4,0,0,WOOD_STEP:11)
Block(5,0,0,LOG:3)
Block(-7,0,1,LOG:11)
Block(-6,0,1,WOOD_STEP:11)
Block(-5,0,1,WOOD_STEP:11)
Block(-4,0,1,WOOD_STEP:11)
Block(-3,0,1,WOOD_STEP:11)
Block(-2,0,1,WOOD_STEP:11)
Block(-1,0,1,WOOD_STEP:11)
Block(0,0,1,WOOD_STEP:11)
Block(1,0,1,WOOD_STEP:11)
Block(2,0,1,WOOD_STEP:11)
Block(3,0,1,WOOD_STEP:11)
Block(4,0,1,WOOD_STEP:11)
Block(5,0,1,LOG:11)
Block(-7,0,2,LOG:11)
Block(-6,0,2,WOOD_STEP:11)
Block(-5,0,2,WOOD_STEP:11)
Block(-4,0,2,WOOD_STEP:11)
Block(-3,0,2,WOOD_STEP:11)
Block(-2,0,2,WOOD_STEP:11)
Block(-1,0,2,WOOD_STEP:11)
Block(0,0,2,WOOD_STEP:11)
Block(1,0,2,WOOD_STEP:11)
Block(2,0,2,WOOD_STEP:11)
Block(3,0,2,WOOD_STEP:11)
Block(4,0,2,WOOD_STEP:11)
Block(5,0,2,LOG:11)
Block(-7,0,3,LOG:11)
Block(-6,0,3,WOOD_STEP:11)
Block(-5,0,3,WOOD_STEP:11)
Block(-4,0,3,WOOD_STEP:11)
Block(-3,0,3,WOOD_STEP:11)
Block(-2,0,3,WOOD_STEP:11)
Block(-1,0,3,WOOD_STEP:11)
Block(0,0,3,WOOD_STEP:11)
Block(1,0,3,WOOD_STEP:11)
Block(2,0,3,WOOD_STEP:11)
Block(3,0,3,WOOD_STEP:11)
Block(4,0,3,WOOD_STEP:11)
Block(5,0,3,LOG:11)
Block(-7,0,4,LOG:3)
Block(-6,0,4,LOG:7)
Block(-5,0,4,LOG:7)
Block(-4,0,4,LOG:7)
Block(-3,0,4,LOG:3)
Block(-2,0,4,LOG:7)
Block(-1,0,4,LOG:7)
Block(0,0,4,LOG:3)
Block(1,0,4,LOG:7)
Block(2,0,4,LOG:7)
Block(3,0,4,LOG:7)
Block(4,0,4,LOG:7)
Block(5,0,4,LOG:3)
Block(-2,0,5,BIRCH_WOOD_STAIRS:0)
Block(-1,0,5,BIRCH_WOOD_STAIRS:5)
Block(-7,1,-7,LOG:3)
Block(-6,1,-7,WOOD_STEP:3)
Block(-5,1,-7,WOOD_STEP:3)
Block(-4,1,-7,WOOD_STEP:3)
Block(-3,1,-7,LOG:3)
Block(-2,1,-7,WOOD_STEP:3)
Block(-1,1,-7,WOOD_STEP:3)
Block(0,1,-7,LOG:3)
Block(1,1,-7,WOOD_STEP:3)
Block(2,1,-7,WOOD_STEP:3)
Block(3,1,-7,WOOD_STEP:3)
Block(4,1,-7,WOOD_STEP:3)
Block(5,1,-7,LOG:3)
Block(-7,1,-6,WOOD_STEP:3)
Block(-6,1,-6,SOIL:7)
Block(-5,1,-6,SOIL:7)
Block(-4,1,-6,SOIL:7)
Block(-3,1,-6,SOIL:7)
Block(-2,1,-6,SOIL:7)
Block(-1,1,-6,SOIL:7)
Block(0,1,-6,SOIL:7)
Block(1,1,-6,SOIL:7)
Block(2,1,-6,SOIL:7)
Block(3,1,-6,SOIL:7)
Block(4,1,-6,SOIL:7)
Block(5,1,-6,WOOD_STEP:3)
Block(-7,1,-5,WOOD_STEP:3)
Block(-6,1,-5,SOIL:7)
Block(-5,1,-5,STATIONARY_WATER)
Block(-4,1,-5,STATIONARY_WATER)
Block(-3,1,-5,STATIONARY_WATER)
Block(-2,1,-5,STATIONARY_WATER)
Block(-1,1,-5,STATIONARY_WATER)
Block(0,1,-5,STATIONARY_WATER)
Block(1,1,-5,STATIONARY_WATER)
Block(2,1,-5,STATIONARY_WATER)
Block(3,1,-5,STATIONARY_WATER)
Block(4,1,-5,SOIL:7)
Block(5,1,-5,WOOD_STEP:3)
Block(-7,1,-4,WOOD_STEP:3)
Block(-6,1,-4,SOIL:7)
Block(-5,1,-4,STATIONARY_WATER)
Block(-4,1,-4,SOIL:7)
Block(-3,1,-4,SOIL:7)
Block(-2,1,-4,SOIL:7)
Block(-1,1,-4,SOIL:7)
Block(0,1,-4,SOIL:7)
Block(1,1,-4,SOIL:7)
Block(2,1,-4,SOIL:7)
Block(3,1,-4,STATIONARY_WATER)
Block(4,1,-4,SOIL:7)
Block(5,1,-4,WOOD_STEP:3)
Block(-7,1,-3,LOG:3)
Block(-6,1,-3,SOIL:7)
Block(-5,1,-3,STATIONARY_WATER)
Block(-4,1,-3,SOIL:7)
Block(-3,1,-3,LOG:3)
Block(-2,1,-3,STATIONARY_WATER:4)
Block(-1,1,-3,STATIONARY_WATER:3)
Block(0,1,-3,LOG:3)
Block(1,1,-3,SOIL:7)
Block(2,1,-3,SOIL:7)
Block(3,1,-3,STATIONARY_WATER)
Block(4,1,-3,SOIL:7)
Block(5,1,-3,LOG:3)
Block(-7,1,-2,WOOD_STEP:3)
Block(-6,1,-2,SOIL:7)
Block(-5,1,-2,STATIONARY_WATER)
Block(-4,1,-2,SOIL:7)
Block(-3,1,-2,STATIONARY_WATER:4)
Block(-2,1,-2,STATIONARY_WATER:3)
Block(-1,1,-2,STATIONARY_WATER:2)
Block(0,1,-2,STATIONARY_WATER:1)
Block(1,1,-2,STATIONARY_WATER)
Block(2,1,-2,STATIONARY_WATER)
Block(3,1,-2,STATIONARY_WATER)
Block(4,1,-2,SOIL:7)
Block(5,1,-2,WOOD_STEP:3)
Block(-7,1,-1,WOOD_STEP:3)
Block(-6,1,-1,SOIL:7)
Block(-5,1,-1,STATIONARY_WATER)
Block(-4,1,-1,SOIL:7)
Block(-3,1,-1,STATIONARY_WATER:4)
Block(-2,1,-1,STATIONARY_WATER:3)
Block(-1,1,-1,STATIONARY_WATER:2)
Block(0,1,-1,STATIONARY_WATER:1)
Block(1,1,-1,STATIONARY_WATER)
Block(2,1,-1,STATIONARY_WATER)
Block(3,1,-1,STATIONARY_WATER)
Block(4,1,-1,SOIL:7)
Block(5,1,-1,WOOD_STEP:3)
Block(-7,1,0,LOG:3)
Block(-6,1,0,SOIL:7)
Block(-5,1,0,STATIONARY_WATER)
Block(-4,1,0,SOIL:7)
Block(-3,1,0,LOG:3)
Block(-2,1,0,STATIONARY_WATER:4)
Block(-1,1,0,STATIONARY_WATER:3)
Block(0,1,0,LOG:3)
Block(1,1,0,SOIL:7)
Block(2,1,0,SOIL:7)
Block(3,1,0,STATIONARY_WATER)
Block(4,1,0,SOIL:7)
Block(5,1,0,LOG:3)
Block(-7,1,1,WOOD_STEP:3)
Block(-6,1,1,SOIL:7)
Block(-5,1,1,STATIONARY_WATER)
Block(-4,1,1,SOIL:7)
Block(-3,1,1,SOIL:7)
Block(-2,1,1,SOIL:7)
Block(-1,1,1,SOIL:7)
Block(0,1,1,SOIL:7)
Block(1,1,1,SOIL:7)
Block(2,1,1,SOIL:7)
Block(3,1,1,STATIONARY_WATER)
Block(4,1,1,SOIL:7)
Block(5,1,1,WOOD_STEP:3)
Block(-7,1,2,WOOD_STEP:3)
Block(-6,1,2,SOIL:7)
Block(-5,1,2,STATIONARY_WATER)
Block(-4,1,2,STATIONARY_WATER)
Block(-3,1,2,STATIONARY_WATER)
Block(-2,1,2,STATIONARY_WATER)
Block(-1,1,2,STATIONARY_WATER)
Block(0,1,2,STATIONARY_WATER)
Block(1,1,2,STATIONARY_WATER)
Block(2,1,2,STATIONARY_WATER)
Block(3,1,2,STATIONARY_WATER)
Block(4,1,2,SOIL:7)
Block(5,1,2,WOOD_STEP:3)
Block(-7,1,3,WOOD_STEP:3)
Block(-6,1,3,SOIL:7)
Block(-5,1,3,SOIL:7)
Block(-4,1,3,SOIL:7)
Block(-3,1,3,SOIL:7)
Block(-2,1,3,SOIL:7)
Block(-1,1,3,SOIL:7)
Block(0,1,3,SOIL:7)
Block(1,1,3,SOIL:7)
Block(2,1,3,SOIL:7)
Block(3,1,3,SOIL:7)
Block(4,1,3,SOIL:7)
Block(5,1,3,WOOD_STEP:3)
Block(-7,1,4,LOG:3)
Block(-6,1,4,WOOD_STEP:3)
Block(-5,1,4,WOOD_STEP:3)
Block(-4,1,4,WOOD_STEP:3)
Block(-3,1,4,LOG:3)
Block(-2,1,4,WOOD_STEP:3)
Block(-1,1,4,WOOD_STEP:3)
Block(0,1,4,LOG:3)
Block(1,1,4,WOOD_STEP:3)
Block(2,1,4,WOOD_STEP:3)
Block(3,1,4,WOOD_STEP:3)
Block(4,1,4,WOOD_STEP:3)
Block(5,1,4,LOG:3)
Block(-1,1,5,WOOD_STEP:2)
Block(-7,2,-7,JUNGLE_FENCE)
Block(-3,2,-7,JUNGLE_FENCE)
Block(0,2,-7,JUNGLE_FENCE)
Block(5,2,-7,JUNGLE_FENCE)
Block(-6,2,-6,CROPS)
Block(-5,2,-6,CROPS:1)
Block(-4,2,-6,CROPS:4)
Block(-3,2,-6,CROPS)
Block(-2,2,-6,CROPS:4)
Block(-1,2,-6,CROPS:3)
Block(0,2,-6,CROPS:7)
Block(1,2,-6,CROPS)
Block(2,2,-6,CROPS:1)
Block(3,2,-6,CROPS:3)
Block(4,2,-6,CROPS)
Block(-6,2,-5,CROPS:1)
Block(4,2,-5,CROPS:2)
Block(-6,2,-4,CROPS:3)
Block(-4,2,-4,MELON_STEM)
Block(-3,2,-4,MELON_STEM:1)
Block(-2,2,-4,MELON_STEM:2)
Block(-1,2,-4,MELON_STEM:3)
Block(0,2,-4,MELON_STEM)
Block(1,2,-4,MELON_STEM:7)
Block(2,2,-4,MELON_STEM:7)
Block(4,2,-4,CROPS)
Block(-7,2,-3,JUNGLE_FENCE)
Block(-6,2,-3,CROPS:6)
Block(-4,2,-3,MELON_STEM:2)
Block(-3,2,-3,LOG:3)
Block(-2,2,-3,JUNGLE_WOOD_STAIRS:2)
Block(-1,2,-3,JUNGLE_WOOD_STAIRS:2)
Block(0,2,-3,LOG:3)
Block(1,2,-3,MELON_STEM:1)
Block(2,2,-3,MELON_STEM:2)
Block(4,2,-3,CROPS:2)
Block(5,2,-3,JUNGLE_FENCE)
Block(-6,2,-2,CROPS:2)
Block(-4,2,-2,MELON_STEM:2)
Block(-3,2,-2,JUNGLE_WOOD_STAIRS:0)
Block(-2,2,-2,CAULDRON)
Block(-1,2,-2,CAULDRON)
Block(0,2,-2,JUNGLE_WOOD_STAIRS:1)
Block(4,2,-2,CROPS:3)
Block(-6,2,-1,CROPS:2)
Block(-4,2,-1,MELON_STEM:7)
Block(-3,2,-1,JUNGLE_WOOD_STAIRS:0)
Block(-2,2,-1,CAULDRON)
Block(-1,2,-1,CAULDRON)
Block(0,2,-1,JUNGLE_WOOD_STAIRS:1)
Block(4,2,-1,CROPS)
Block(-7,2,0,JUNGLE_FENCE)
Block(-6,2,0,CROPS:5)
Block(-4,2,0,MELON_STEM)
Block(-3,2,0,LOG:3)
Block(-2,2,0,JUNGLE_WOOD_STAIRS:0)
Block(-1,2,0,JUNGLE_WOOD_STAIRS:0)
Block(0,2,0,LOG:3)
Block(1,2,0,MELON_STEM:1)
Block(2,2,0,MELON_STEM:1)
Block(4,2,0,CROPS:4)
Block(5,2,0,JUNGLE_FENCE)
Block(-6,2,1,CROPS:2)
Block(-4,2,1,MELON_STEM:7)
Block(-3,2,1,MELON_STEM:1)
Block(-2,2,1,MELON_STEM:2)
Block(-1,2,1,MELON_STEM:3)
Block(0,2,1,MELON_STEM:7)
Block(1,2,1,MELON_STEM:2)
Block(2,2,1,MELON_STEM:7)
Block(4,2,1,CROPS:1)
Block(-6,2,2,CROPS)
Block(4,2,2,CROPS:4)
Block(-6,2,3,CROPS:2)
Block(-5,2,3,CROPS:2)
Block(-4,2,3,CROPS:1)
Block(-3,2,3,CROPS:2)
Block(-2,2,3,CROPS:1)
Block(-1,2,3,CROPS:2)
Block(0,2,3,CROPS:3)
Block(1,2,3,CROPS:4)
Block(2,2,3,CROPS:2)
Block(3,2,3,CROPS:1)
Block(4,2,3,CROPS:3)
Block(-7,2,4,JUNGLE_FENCE)
Block(-3,2,4,JUNGLE_FENCE)
Block(-1,2,4,AIR)
Block(0,2,4,JUNGLE_FENCE)
Block(5,2,4,JUNGLE_FENCE)
Block(-7,3,-7,TORCH)
Block(-3,3,-7,JUNGLE_FENCE)
Block(0,3,-7,JUNGLE_FENCE)
Block(5,3,-7,TORCH)
Block(-7,3,-3,JUNGLE_FENCE)
Block(-3,3,-3,LOG:3)
Block(-2,3,-3,JUNGLE_WOOD_STAIRS:6)
Block(-1,3,-3,JUNGLE_WOOD_STAIRS:6)
Block(0,3,-3,LOG:3)
Block(5,3,-3,JUNGLE_FENCE)
Block(-3,3,-2,JUNGLE_WOOD_STAIRS:4)
Block(-2,3,-2,CAULDRON)
Block(-1,3,-2,CAULDRON)
Block(0,3,-2,JUNGLE_WOOD_STAIRS:5)
Block(-3,3,-1,JUNGLE_WOOD_STAIRS:4)
Block(-2,3,-1,CAULDRON)
Block(-1,3,-1,CAULDRON)
Block(0,3,-1,JUNGLE_WOOD_STAIRS:5)
Block(-7,3,0,JUNGLE_FENCE)
Block(-3,3,0,LOG:3)
Block(-2,3,0,JUNGLE_WOOD_STAIRS:7)
Block(-1,3,0,JUNGLE_WOOD_STAIRS:7)
Block(0,3,0,LOG:3)
Block(5,3,0,JUNGLE_FENCE)
Block(-7,3,4,TORCH)
Block(-3,3,4,JUNGLE_FENCE)
Block(0,3,4,JUNGLE_FENCE)
Block(5,3,4,TORCH)
Block(-3,4,-7,JUNGLE_FENCE)
Block(0,4,-7,JUNGLE_FENCE)
Block(-7,4,-3,JUNGLE_FENCE)
Block(-3,4,-3,LOG:3)
Block(-2,4,-3,JUNGLE_WOOD_STAIRS:2)
Block(-1,4,-3,JUNGLE_WOOD_STAIRS:2)
Block(0,4,-3,LOG:3)
Block(5,4,-3,JUNGLE_FENCE)
Block(-3,4,-2,JUNGLE_WOOD_STAIRS:0)
Block(-2,4,-2,CAULDRON)
Block(-1,4,-2,CAULDRON)
Block(0,4,-2,JUNGLE_WOOD_STAIRS:1)
Block(-3,4,-1,JUNGLE_WOOD_STAIRS:0)
Block(-2,4,-1,CAULDRON)
Block(-1,4,-1,CAULDRON)
Block(0,4,-1,JUNGLE_WOOD_STAIRS:1)
Block(-7,4,0,JUNGLE_FENCE)
Block(-3,4,0,LOG:3)
Block(-2,4,0,JUNGLE_WOOD_STAIRS:0)
Block(-1,4,0,JUNGLE_WOOD_STAIRS:0)
Block(0,4,0,LOG:3)
Block(5,4,0,JUNGLE_FENCE)
Block(-3,4,4,JUNGLE_FENCE)
Block(0,4,4,JUNGLE_FENCE)
Block(-3,5,-7,JUNGLE_FENCE)
Block(0,5,-7,JUNGLE_FENCE)
Block(-3,5,-4,JUNGLE_FENCE)
Block(0,5,-4,JUNGLE_FENCE)
Block(-7,5,-3,JUNGLE_FENCE)
Block(-4,5,-3,JUNGLE_FENCE)
Block(-3,5,-3,LOG:3)
Block(-2,5,-3,JUNGLE_WOOD_STAIRS:6)
Block(-1,5,-3,JUNGLE_WOOD_STAIRS:6)
Block(0,5,-3,LOG:3)
Block(1,5,-3,JUNGLE_FENCE)
Block(5,5,-3,JUNGLE_FENCE)
Block(-3,5,-2,JUNGLE_WOOD_STAIRS:4)
Block(-2,5,-2,CAULDRON)
Block(-1,5,-2,CAULDRON)
Block(0,5,-2,JUNGLE_WOOD_STAIRS:5)
Block(-3,5,-1,JUNGLE_WOOD_STAIRS:4)
Block(-2,5,-1,CAULDRON)
Block(-1,5,-1,CAULDRON)
Block(0,5,-1,JUNGLE_WOOD_STAIRS:5)
Block(-7,5,0,JUNGLE_FENCE)
Block(-4,5,0,JUNGLE_FENCE)
Block(-3,5,0,LOG:3)
Block(-2,5,0,JUNGLE_WOOD_STAIRS:7)
Block(-1,5,0,JUNGLE_WOOD_STAIRS:7)
Block(0,5,0,LOG:3)
Block(1,5,0,JUNGLE_FENCE)
Block(5,5,0,JUNGLE_FENCE)
Block(-3,5,1,JUNGLE_FENCE)
Block(0,5,1,JUNGLE_FENCE)
Block(-3,5,4,JUNGLE_FENCE)
Block(0,5,4,JUNGLE_FENCE)
Block(-3,6,-7,JUNGLE_FENCE)
Block(0,6,-7,JUNGLE_FENCE)
Block(-3,6,-4,TORCH)
Block(0,6,-4,TORCH)
Block(-7,6,-3,JUNGLE_FENCE)
Block(-4,6,-3,TORCH)
Block(-3,6,-3,LOG:3)
Block(-2,6,-3,JUNGLE_WOOD_STAIRS:2)
Block(-1,6,-3,JUNGLE_WOOD_STAIRS:2)
Block(0,6,-3,LOG:3)
Block(1,6,-3,TORCH)
Block(5,6,-3,JUNGLE_FENCE)
Block(-3,6,-2,JUNGLE_WOOD_STAIRS:0)
Block(-2,6,-2,CAULDRON)
Block(-1,6,-2,CAULDRON)
Block(0,6,-2,JUNGLE_WOOD_STAIRS:1)
Block(-3,6,-1,JUNGLE_WOOD_STAIRS:0)
Block(-2,6,-1,CAULDRON)
Block(-1,6,-1,CAULDRON)
Block(0,6,-1,JUNGLE_WOOD_STAIRS:1)
Block(-7,6,0,JUNGLE_FENCE)
Block(-4,6,0,TORCH)
Block(-3,6,0,LOG:3)
Block(-2,6,0,JUNGLE_WOOD_STAIRS:0)
Block(-1,6,0,JUNGLE_WOOD_STAIRS:0)
Block(0,6,0,LOG:3)
Block(1,6,0,TORCH)
Block(5,6,0,JUNGLE_FENCE)
Block(-3,6,1,TORCH)
Block(0,6,1,TORCH)
Block(-3,6,4,JUNGLE_FENCE)
Block(0,6,4,JUNGLE_FENCE)
Block(-3,7,-7,JUNGLE_FENCE)
Block(0,7,-7,JUNGLE_FENCE)
Block(-3,7,-4,JUNGLE_WOOD_STAIRS:6)
Block(0,7,-4,JUNGLE_WOOD_STAIRS:6)
Block(-7,7,-3,JUNGLE_FENCE)
Block(-4,7,-3,JUNGLE_WOOD_STAIRS:4)
Block(-3,7,-3,LOG:3)
Block(-2,7,-3,JUNGLE_WOOD_STAIRS:6)
Block(-1,7,-3,JUNGLE_WOOD_STAIRS:6)
Block(0,7,-3,LOG:3)
Block(1,7,-3,JUNGLE_WOOD_STAIRS:5)
Block(5,7,-3,JUNGLE_FENCE)
Block(-3,7,-2,JUNGLE_WOOD_STAIRS:4)
Block(-2,7,-2,CAULDRON)
Block(-1,7,-2,CAULDRON)
Block(0,7,-2,JUNGLE_WOOD_STAIRS:5)
Block(-3,7,-1,JUNGLE_WOOD_STAIRS:4)
Block(-2,7,-1,CAULDRON)
Block(-1,7,-1,CAULDRON)
Block(0,7,-1,JUNGLE_WOOD_STAIRS:5)
Block(-7,7,0,JUNGLE_FENCE)
Block(-4,7,0,JUNGLE_WOOD_STAIRS:4)
Block(-3,7,0,LOG:3)
Block(-2,7,0,JUNGLE_WOOD_STAIRS:7)
Block(-1,7,0,JUNGLE_WOOD_STAIRS:7)
Block(0,7,0,LOG:3)
Block(1,7,0,JUNGLE_WOOD_STAIRS:5)
Block(5,7,0,JUNGLE_FENCE)
Block(-3,7,1,JUNGLE_WOOD_STAIRS:7)
Block(0,7,1,JUNGLE_WOOD_STAIRS:7)
Block(-3,7,4,JUNGLE_FENCE)
Block(0,7,4,JUNGLE_FENCE)
Block(-3,8,-7,WOOD_DOUBLE_STEP:3)
Block(0,8,-7,WOOD:3)
Block(-3,8,-6,WOOD_STEP:3)
Block(0,8,-6,WOOD_STEP:3)
Block(-3,8,-5,WOOD_STEP:3)
Block(0,8,-5,WOOD_STEP:3)
Block(-3,8,-4,WOOD_STEP:3)
Block(0,8,-4,WOOD_STEP:3)
Block(-7,8,-3,WOOD:3)
Block(-6,8,-3,WOOD_STEP:3)
Block(-5,8,-3,WOOD_STEP:3)
Block(-4,8,-3,WOOD_STEP:3)
Block(-3,8,-3,WOOD_DOUBLE_STEP:3)
Block(-2,8,-3,WOOD_DOUBLE_STEP:3)
Block(-1,8,-3,WOOD_DOUBLE_STEP:3)
Block(0,8,-3,WOOD_DOUBLE_STEP:3)
Block(1,8,-3,WOOD_STEP:3)
Block(2,8,-3,WOOD_STEP:3)
Block(3,8,-3,WOOD_STEP:3)
Block(4,8,-3,WOOD_STEP:3)
Block(5,8,-3,WOOD:3)
Block(-3,8,-2,WOOD_DOUBLE_STEP:3)
Block(-2,8,-2,CAULDRON:3)
Block(-1,8,-2,CAULDRON:3)
Block(0,8,-2,WOOD_DOUBLE_STEP:3)
Block(-3,8,-1,WOOD_DOUBLE_STEP:3)
Block(-2,8,-1,CAULDRON:3)
Block(-1,8,-1,CAULDRON:3)
Block(0,8,-1,WOOD_DOUBLE_STEP:3)
Block(-7,8,0,WOOD:3)
Block(-6,8,0,WOOD_STEP:3)
Block(-5,8,0,WOOD_STEP:3)
Block(-4,8,0,WOOD_STEP:3)
Block(-3,8,0,WOOD_DOUBLE_STEP:3)
Block(-2,8,0,WOOD_DOUBLE_STEP:3)
Block(-1,8,0,WOOD_DOUBLE_STEP:3)
Block(0,8,0,WOOD_DOUBLE_STEP:3)
Block(1,8,0,WOOD_STEP:3)
Block(2,8,0,WOOD_STEP:3)
Block(3,8,0,WOOD_STEP:3)
Block(4,8,0,WOOD_STEP:3)
Block(5,8,0,WOOD:3)
Block(-3,8,1,WOOD_STEP:3)
Block(0,8,1,WOOD_STEP:3)
Block(-3,8,2,WOOD_STEP:3)
Block(0,8,2,WOOD_STEP:3)
Block(-3,8,3,WOOD_STEP:3)
Block(0,8,3,WOOD_STEP:3)
Block(-3,8,4,WOOD:3)
Block(0,8,4,WOOD:3)
Block(-3,9,-7,WOOD:3)
Block(0,9,-7,WOOD:3)
Block(-3,9,-6,WOOD:3)
Block(-2,9,-6,WOOD_STEP:11)
Block(-1,9,-6,WOOD_STEP:11)
Block(0,9,-6,WOOD:3)
Block(-3,9,-5,WOOD:3)
Block(-2,9,-5,WOOD_STEP:11)
Block(-1,9,-5,WOOD_STEP:11)
Block(0,9,-5,WOOD:3)
Block(-3,9,-4,WOOD:3)
Block(-2,9,-4,JUNGLE_WOOD_STAIRS:6)
Block(-1,9,-4,JUNGLE_WOOD_STAIRS:6)
Block(0,9,-4,WOOD:3)
Block(-7,9,-3,WOOD:3)
Block(-6,9,-3,WOOD:3)
Block(-5,9,-3,WOOD:3)
Block(-4,9,-3,WOOD:3)
Block(-3,9,-3,STATIONARY_WATER:11)
Block(-2,9,-3,STATIONARY_WATER:11)
Block(-1,9,-3,STATIONARY_WATER:11)
Block(0,9,-3,STATIONARY_WATER:11)
Block(1,9,-3,WOOD:3)
Block(2,9,-3,WOOD:3)
Block(3,9,-3,WOOD:3)
Block(4,9,-3,WOOD:3)
Block(5,9,-3,WOOD:3)
Block(-6,9,-2,WOOD_STEP:11)
Block(-5,9,-2,WOOD_STEP:11)
Block(-4,9,-2,JUNGLE_WOOD_STAIRS:4)
Block(-3,9,-2,STATIONARY_WATER:11)
Block(-2,9,-2,STATIONARY_WATER:1)
Block(-1,9,-2,STATIONARY_WATER:1)
Block(0,9,-2,STATIONARY_WATER:11)
Block(1,9,-2,JUNGLE_WOOD_STAIRS:5)
Block(2,9,-2,WOOD_STEP:11)
Block(3,9,-2,WOOD_STEP:11)
Block(4,9,-2,WOOD_STEP:11)
Block(-6,9,-1,WOOD_STEP:11)
Block(-5,9,-1,WOOD_STEP:11)
Block(-4,9,-1,JUNGLE_WOOD_STAIRS:4)
Block(-3,9,-1,STATIONARY_WATER:11)
Block(-2,9,-1,STATIONARY_WATER:1)
Block(-1,9,-1,STATIONARY_WATER:1)
Block(0,9,-1,STATIONARY_WATER:11)
Block(1,9,-1,JUNGLE_WOOD_STAIRS:5)
Block(2,9,-1,WOOD_STEP:11)
Block(3,9,-1,WOOD_STEP:11)
Block(4,9,-1,WOOD_STEP:11)
Block(-7,9,0,WOOD:3)
Block(-6,9,0,WOOD:3)
Block(-5,9,0,WOOD:3)
Block(-4,9,0,WOOD:3)
Block(-3,9,0,STATIONARY_WATER:11)
Block(-2,9,0,STATIONARY_WATER:11)
Block(-1,9,0,STATIONARY_WATER:11)
Block(0,9,0,STATIONARY_WATER:11)
Block(1,9,0,WOOD:3)
Block(2,9,0,WOOD:3)
Block(3,9,0,WOOD:3)
Block(4,9,0,WOOD:3)
Block(5,9,0,WOOD:3)
Block(-3,9,1,WOOD:3)
Block(-2,9,1,JUNGLE_WOOD_STAIRS:7)
Block(-1,9,1,JUNGLE_WOOD_STAIRS:7)
Block(0,9,1,WOOD:3)
Block(-3,9,2,WOOD:3)
Block(-2,9,2,WOOD_STEP:11)
Block(-1,9,2,WOOD_STEP:11)
Block(0,9,2,WOOD:3)
Block(-3,9,3,WOOD:3)
Block(-2,9,3,WOOD_STEP:11)
Block(-1,9,3,WOOD_STEP:11)
Block(0,9,3,WOOD:3)
Block(-3,9,4,WOOD:3)
Block(0,9,4,WOOD:3)
Block(-4,10,-7,JUNGLE_WOOD_STAIRS:4)
Block(-3,10,-7,WOOD:3)
Block(-2,10,-7,JUNGLE_WOOD_STAIRS:6)
Block(-1,10,-7,JUNGLE_WOOD_STAIRS:6)
Block(0,10,-7,WOOD:3)
Block(1,10,-7,JUNGLE_WOOD_STAIRS:5)
Block(-4,10,-6,JUNGLE_WOOD_STAIRS:4)
Block(-3,10,-6,STATIONARY_WATER)
Block(-2,10,-6,STATIONARY_WATER)
Block(-1,10,-6,STATIONARY_WATER)
Block(0,10,-6,STATIONARY_WATER)
Block(1,10,-6,JUNGLE_WOOD_STAIRS:5)
Block(-4,10,-5,JUNGLE_WOOD_STAIRS:4)
Block(-3,10,-5,STATIONARY_WATER:1)
Block(-2,10,-5,STATIONARY_WATER:1)
Block(-1,10,-5,STATIONARY_WATER:1)
Block(0,10,-5,STATIONARY_WATER:1)
Block(1,10,-5,JUNGLE_WOOD_STAIRS:5)
Block(-7,10,-4,JUNGLE_WOOD_STAIRS:6)
Block(-6,10,-4,JUNGLE_WOOD_STAIRS:6)
Block(-5,10,-4,JUNGLE_WOOD_STAIRS:6)
Block(-4,10,-4,JUNGLE_WOOD_STAIRS:4)
Block(-3,10,-4,STATIONARY_WATER:2)
Block(-2,10,-4,STATIONARY_WATER:2)
Block(-1,10,-4,STATIONARY_WATER:2)
Block(0,10,-4,STATIONARY_WATER:2)
Block(1,10,-4,JUNGLE_WOOD_STAIRS:6)
Block(2,10,-4,JUNGLE_WOOD_STAIRS:6)
Block(3,10,-4,JUNGLE_WOOD_STAIRS:6)
Block(4,10,-4,JUNGLE_WOOD_STAIRS:6)
Block(5,10,-4,JUNGLE_WOOD_STAIRS:6)
Block(-7,10,-3,WOOD:3)
Block(-6,10,-3,STATIONARY_WATER)
Block(-5,10,-3,STATIONARY_WATER:1)
Block(-4,10,-3,STATIONARY_WATER:2)
Block(-3,10,-3,STATIONARY_WATER:3)
Block(-2,10,-3,STATIONARY_WATER:3)
Block(-1,10,-3,STATIONARY_WATER:3)
Block(0,10,-3,STATIONARY_WATER:3)
Block(1,10,-3,STATIONARY_WATER:2)
Block(2,10,-3,STATIONARY_WATER:1)
Block(3,10,-3,STATIONARY_WATER)
Block(4,10,-3,STATIONARY_WATER)
Block(5,10,-3,WOOD:3)
Block(-7,10,-2,JUNGLE_WOOD_STAIRS:4)
Block(-6,10,-2,STATIONARY_WATER)
Block(-5,10,-2,STATIONARY_WATER:1)
Block(-4,10,-2,STATIONARY_WATER:2)
Block(-3,10,-2,STATIONARY_WATER:3)
Block(0,10,-2,STATIONARY_WATER:3)
Block(1,10,-2,STATIONARY_WATER:2)
Block(2,10,-2,STATIONARY_WATER:1)
Block(3,10,-2,STATIONARY_WATER)
Block(4,10,-2,STATIONARY_WATER)
Block(5,10,-2,JUNGLE_WOOD_STAIRS:5)
Block(-7,10,-1,JUNGLE_WOOD_STAIRS:4)
Block(-6,10,-1,STATIONARY_WATER)
Block(-5,10,-1,STATIONARY_WATER:1)
Block(-4,10,-1,STATIONARY_WATER:2)
Block(-3,10,-1,STATIONARY_WATER:3)
Block(0,10,-1,STATIONARY_WATER:3)
Block(1,10,-1,STATIONARY_WATER:2)
Block(2,10,-1,STATIONARY_WATER:1)
Block(3,10,-1,STATIONARY_WATER)
Block(4,10,-1,STATIONARY_WATER)
Block(5,10,-1,JUNGLE_WOOD_STAIRS:5)
Block(-7,10,0,WOOD:3)
Block(-6,10,0,STATIONARY_WATER)
Block(-5,10,0,STATIONARY_WATER:1)
Block(-4,10,0,STATIONARY_WATER:2)
Block(-3,10,0,STATIONARY_WATER:3)
Block(-2,10,0,STATIONARY_WATER:3)
Block(-1,10,0,STATIONARY_WATER:3)
Block(0,10,0,STATIONARY_WATER:3)
Block(1,10,0,STATIONARY_WATER:3)
Block(2,10,0,STATIONARY_WATER:2)
Block(3,10,0,STATIONARY_WATER:1)
Block(4,10,0,STATIONARY_WATER:1)
Block(5,10,0,WOOD:3)
Block(-7,10,1,JUNGLE_WOOD_STAIRS:7)
Block(-6,10,1,JUNGLE_WOOD_STAIRS:7)
Block(-5,10,1,JUNGLE_WOOD_STAIRS:7)
Block(-4,10,1,JUNGLE_WOOD_STAIRS:7)
Block(-3,10,1,STATIONARY_WATER:2)
Block(-2,10,1,STATIONARY_WATER:2)
Block(-1,10,1,STATIONARY_WATER:2)
Block(0,10,1,STATIONARY_WATER:2)
Block(1,10,1,JUNGLE_WOOD_STAIRS:5)
Block(2,10,1,JUNGLE_WOOD_STAIRS:7)
Block(3,10,1,JUNGLE_WOOD_STAIRS:7)
Block(4,10,1,JUNGLE_WOOD_STAIRS:7)
Block(5,10,1,JUNGLE_WOOD_STAIRS:7)
Block(-4,10,2,JUNGLE_WOOD_STAIRS:4)
Block(-3,10,2,STATIONARY_WATER:1)
Block(-2,10,2,STATIONARY_WATER:1)
Block(-1,10,2,STATIONARY_WATER:1)
Block(0,10,2,STATIONARY_WATER:1)
Block(1,10,2,JUNGLE_WOOD_STAIRS:5)
Block(-4,10,3,JUNGLE_WOOD_STAIRS:4)
Block(-3,10,3,STATIONARY_WATER)
Block(-2,10,3,STATIONARY_WATER)
Block(-1,10,3,STATIONARY_WATER)
Block(0,10,3,STATIONARY_WATER)
Block(1,10,3,JUNGLE_WOOD_STAIRS:5)
Block(-4,10,4,JUNGLE_WOOD_STAIRS:4)
Block(-3,10,4,WOOD:3)
Block(-2,10,4,JUNGLE_WOOD_STAIRS:7)
Block(-1,10,4,JUNGLE_WOOD_STAIRS:7)
Block(0,10,4,WOOD:3)
Block(1,10,4,JUNGLE_WOOD_STAIRS:5)
Block(-4,11,-7,WOOD_STEP:2)
Block(-3,11,-7,WOOD_STEP:2)
Block(-2,11,-7,WOOD_STEP:2)
Block(-1,11,-7,WOOD_STEP:2)
Block(0,11,-7,WOOD_STEP:2)
Block(1,11,-7,WOOD_STEP:2)
Block(-4,11,-6,WOOD_STEP:2)
Block(1,11,-6,WOOD_STEP:2)
Block(-4,11,-5,WOOD_STEP:2)
Block(1,11,-5,WOOD_STEP:2)
Block(-7,11,-4,WOOD_STEP:2)
Block(-6,11,-4,WOOD_STEP:2)
Block(-5,11,-4,WOOD_STEP:2)
Block(-4,11,-4,WOOD_STEP:2)
Block(1,11,-4,WOOD_STEP:2)
Block(2,11,-4,WOOD_STEP:2)
Block(3,11,-4,WOOD_STEP:2)
Block(4,11,-4,WOOD_STEP:2)
Block(5,11,-4,WOOD_STEP:2)
Block(-7,11,-3,WOOD_STEP:2)
Block(5,11,-3,WOOD_STEP:2)
Block(-7,11,-2,WOOD_STEP:2)
Block(5,11,-2,WOOD_STEP:2)
Block(-7,11,-1,WOOD_STEP:2)
Block(5,11,-1,WOOD_STEP:2)
Block(-7,11,0,WOOD_STEP:2)
Block(5,11,0,WOOD_STEP:2)
Block(-7,11,1,WOOD_STEP:2)
Block(-6,11,1,WOOD_STEP:2)
Block(-5,11,1,WOOD_STEP:2)
Block(-4,11,1,WOOD_STEP:2)
Block(1,11,1,WOOD_STEP:2)
Block(2,11,1,WOOD_STEP:2)
Block(3,11,1,WOOD_STEP:2)
Block(4,11,1,WOOD_STEP:2)
Block(5,11,1,WOOD_STEP:2)
Block(-4,11,2,WOOD_STEP:2)
Block(1,11,2,WOOD_STEP:2)
Block(-4,11,3,WOOD_STEP:2)
Block(1,11,3,WOOD_STEP:2)
Block(-4,11,4,WOOD_STEP:2)
Block(-3,11,4,WOOD_STEP:2)
Block(-2,11,4,WOOD_STEP:2)
Block(-1,11,4,WOOD_STEP:2)
Block(0,11,4,WOOD_STEP:2)
Block(1,11,4,WOOD_STEP:2)

#######################################################################
# +-----------------------------------------------------------------+ #
# |                            BO3 checks                           | #
# +-----------------------------------------------------------------+ #
#######################################################################


#######################################################################
# +-----------------------------------------------------------------+ #
# |                             Branches                            | #
# +-----------------------------------------------------------------+ #
#######################################################################


#######################################################################
# +-----------------------------------------------------------------+ #
# |                             Entities                            | #
# +-----------------------------------------------------------------+ #
#######################################################################

Entity(-1,2,4,VILLAGER,1,../JungleNBT/entities/tribalfarmer.txt)

#######################################################################
# +-----------------------------------------------------------------+ #
# |                            Particles                            | #
# +-----------------------------------------------------------------+ #
#######################################################################


#######################################################################
# +-----------------------------------------------------------------+ #
# |                             Spawners                            | #
# +-----------------------------------------------------------------+ #
#######################################################################


#######################################################################
# +-----------------------------------------------------------------+ #
# |                             ModData                             | #
# +-----------------------------------------------------------------+ #
#######################################################################

