
#######################################################################
# +-----------------------------------------------------------------+ #
# |                            BO3 object                           | #
# +-----------------------------------------------------------------+ #
#######################################################################

Author: BO3 BulkEdit (by LanToaster)

Description: This Object was Created with BO3_BulkEdit

Version: 3

SettingsMode: WriteDisable


#######################################################################
# +-----------------------------------------------------------------+ #
# |                          Main settings                          | #
# +-----------------------------------------------------------------+ #
#######################################################################

Tree: false

Frequency: 100

Rarity: 100.0

RotateRandomly: true

SpawnHeight: randomY

SpawnHeightOffset: 0

SpawnHeightVariance: 0

##############################
# Height Limits for the BO3. #
##############################

MinHeight: 82

MaxHeight: 82

######################
# Extrusion settings #
######################

ExtrudeMode: None

ExtrudeThroughBlocks: AIR

MaxBranchDepth: 50

ExcludedBiomes: All


#######################################################################
# +-----------------------------------------------------------------+ #
# |                      Source block settings                      | #
# +-----------------------------------------------------------------+ #
#######################################################################

SourceBlocks: AIR

MaxPercentageOutsideSourceBlock: 100

OutsideSourceBlock: placeAnyway

IsOTGPlus: false

InheritBO3: 

InheritBO3Rotation: NORTH

OverrideChildSettings: true

OverrideParentHeight: false

CanOverride: false

BranchFrequency: 0

BranchFrequencyGroup: 

MustBeBelowOther: false

MustBeInside: 

CannotBeInside: 

ReplacesBO3: 

CanSpawnOnWater: true

SpawnOnWaterOnly: false

SpawnUnderWater: false

SpawnAtWaterLevel: false

HeightOffset: 0

RemoveAir: true

ReplaceAbove: 

ReplaceBelow: 

ReplaceWithBiomeBlocks: true

ReplaceWithGroundBlock: DIRT

ReplaceWithSurfaceBlock: GRASS

SmoothRadius: 0

SmoothHeightOffset: 0

SmoothStartTop: false

SmoothStartWood: false

SmoothingSurfaceBlock: 

SmoothingGroundBlock: 

BO3Group: 

IsSpawnPoint: false


#######################################################################
# +-----------------------------------------------------------------+ #
# |                              Blocks                             | #
# +-----------------------------------------------------------------+ #
#######################################################################

Block(-4,-1,-7,LOG:3)
Block(-2,-1,-7,LOG:3)
Block(-4,-1,-6,SOUL_SAND)
Block(-3,-1,-6,SOUL_SAND)
Block(-4,-1,-5,LOG:3)
Block(-3,-1,-5,SOUL_SAND)
Block(-2,-1,-5,LOG:3)
Block(-5,-1,-4,LOG:3)
Block(-1,-1,-4,LOG:3)
Block(4,-1,-4,LOG:3)
Block(-5,-1,-1,LOG:3)
Block(-1,-1,-1,LOG:3)
Block(4,-1,-1,LOG:3)
Block(-4,-1,1,LOG:3)
Block(-3,-1,2,BIRCH_WOOD_STAIRS:6)
Block(-3,-1,3,BIRCH_WOOD_STAIRS:0)
Block(-1,-1,5,LOG:3)
Block(4,-1,5,LOG:3)
Block(-4,0,-7,LOG:3)
Block(-2,0,-7,LOG:3)
Block(-3,0,-6,SOUL_SAND)
Block(-4,0,-5,LOG:3)
Block(-2,0,-5,LOG:3)
Block(-5,0,-4,LOG:3)
Block(-1,0,-4,LOG:3)
Block(4,0,-4,LOG:3)
Block(-5,0,-1,LOG:3)
Block(-1,0,-1,LOG:3)
Block(4,0,-1,LOG:3)
Block(-4,0,1,LOG:3)
Block(-3,0,1,BIRCH_WOOD_STAIRS:6)
Block(-3,0,2,BIRCH_WOOD_STAIRS:0)
Block(-1,0,5,LOG:3)
Block(4,0,5,LOG:3)
Block(-4,1,-7,LOG:3)
Block(-3,1,-7,HAY_BLOCK)
Block(-2,1,-7,LOG:3)
Block(-4,1,-5,LOG:3)
Block(-2,1,-5,LOG:3)
Block(-5,1,-4,LOG:3)
Block(-1,1,-4,LOG:3)
Block(4,1,-4,LOG:3)
Block(-5,1,-1,LOG:3)
Block(-1,1,-1,LOG:3)
Block(4,1,-1,LOG:3)
Block(-3,1,0,BIRCH_WOOD_STAIRS:6)
Block(-4,1,1,LOG:3)
Block(-3,1,1,BIRCH_WOOD_STAIRS:0)
Block(-1,1,5,LOG:3)
Block(4,1,5,LOG:3)
Block(-4,2,-7,LOG:3)
Block(-3,2,-7,LOG:7)
Block(-2,2,-7,LOG:3)
Block(-4,2,-6,LOG:11)
Block(-3,2,-6,HOPPER)
Block(-2,2,-6,LOG:11)
Block(-4,2,-5,LOG:3)
Block(-3,2,-5,WOOD_STEP:11)
Block(-2,2,-5,LOG:3)
Block(-5,2,-4,LOG:3)
Block(-4,2,-4,LOG:7)
Block(-3,2,-4,LOG:7)
Block(-2,2,-4,LOG:7)
Block(-1,2,-4,LOG:3)
Block(0,2,-4,LOG:7)
Block(1,2,-4,LOG:7)
Block(2,2,-4,LOG:7)
Block(3,2,-4,LOG:7)
Block(4,2,-4,LOG:3)
Block(-5,2,-3,LOG:11)
Block(-4,2,-3,WOOD_STEP:11)
Block(-3,2,-3,WOOD_STEP:11)
Block(-2,2,-3,WOOD_STEP:11)
Block(-1,2,-3,LOG:11)
Block(0,2,-3,WOOD_STEP:11)
Block(1,2,-3,WOOD_STEP:11)
Block(2,2,-3,WOOD_STEP:11)
Block(3,2,-3,WOOD_STEP:11)
Block(4,2,-3,LOG:11)
Block(-5,2,-2,LOG:11)
Block(-4,2,-2,WOOD_STEP:11)
Block(-3,2,-2,WOOD_STEP:11)
Block(-2,2,-2,WOOD_STEP:11)
Block(-1,2,-2,LOG:11)
Block(0,2,-2,WOOD_STEP:11)
Block(1,2,-2,WOOD_STEP:11)
Block(2,2,-2,WOOD_STEP:11)
Block(3,2,-2,WOOD_STEP:11)
Block(4,2,-2,LOG:11)
Block(-5,2,-1,LOG:3)
Block(-4,2,-1,LOG:7)
Block(-3,2,-1,LOG:7)
Block(-2,2,-1,LOG:7)
Block(-1,2,-1,LOG:3)
Block(0,2,-1,LOG:7)
Block(1,2,-1,LOG:7)
Block(2,2,-1,LOG:7)
Block(3,2,-1,LOG:7)
Block(4,2,-1,LOG:3)
Block(-3,2,0,BIRCH_WOOD_STAIRS:0)
Block(-1,2,0,LOG:11)
Block(0,2,0,WOOD_STEP:11)
Block(1,2,0,WOOD_STEP:11)
Block(2,2,0,WOOD_STEP:11)
Block(3,2,0,WOOD_STEP:11)
Block(4,2,0,LOG:11)
Block(-4,2,1,LOG:3)
Block(-1,2,1,LOG:11)
Block(0,2,1,WOOD_STEP:11)
Block(1,2,1,WOOD_STEP:11)
Block(2,2,1,WOOD_STEP:11)
Block(3,2,1,WOOD_STEP:11)
Block(4,2,1,LOG:11)
Block(-1,2,2,LOG:11)
Block(0,2,2,WOOD_STEP:11)
Block(1,2,2,WOOD_STEP:11)
Block(2,2,2,WOOD_STEP:11)
Block(3,2,2,WOOD_STEP:11)
Block(4,2,2,LOG:11)
Block(-1,2,3,LOG:11)
Block(0,2,3,WOOD_STEP:11)
Block(1,2,3,WOOD_STEP:11)
Block(2,2,3,WOOD_STEP:11)
Block(3,2,3,WOOD_STEP:11)
Block(4,2,3,LOG:11)
Block(-1,2,4,LOG:11)
Block(0,2,4,WOOD_STEP:11)
Block(1,2,4,WOOD_STEP:11)
Block(2,2,4,WOOD_STEP:11)
Block(3,2,4,WOOD_STEP:11)
Block(4,2,4,LOG:11)
Block(-1,2,5,LOG:3)
Block(0,2,5,LOG:7)
Block(1,2,5,LOG:7)
Block(2,2,5,LOG:7)
Block(3,2,5,LOG:7)
Block(4,2,5,LOG:3)
Block(-4,3,-7,JUNGLE_FENCE)
Block(-3,3,-7,SPRUCE_DOOR)
Block(-2,3,-7,JUNGLE_FENCE)
Block(-4,3,-6,SPRUCE_DOOR:2)
Block(-2,3,-6,SPRUCE_DOOR:0)
Block(-4,3,-5,JUNGLE_FENCE)
Block(-3,3,-5,SPRUCE_DOOR:1)
Block(-2,3,-5,JUNGLE_FENCE)
Block(-5,3,-4,JUNGLE_FENCE)
Block(-4,3,-4,JUNGLE_FENCE)
Block(-2,3,-4,JUNGLE_FENCE)
Block(-1,3,-4,LOG:3)
Block(0,3,-4,JUNGLE_FENCE)
Block(1,3,-4,JUNGLE_FENCE)
Block(2,3,-4,JUNGLE_FENCE)
Block(3,3,-4,JUNGLE_FENCE)
Block(4,3,-4,LOG:3)
Block(-5,3,-3,JUNGLE_FENCE)
Block(-1,3,-3,JUNGLE_FENCE_GATE:3)
Block(3,3,-3,SPRUCE_WOOD_STAIRS:7)
Block(4,3,-3,JUNGLE_FENCE)
Block(-5,3,-2,JUNGLE_FENCE)
Block(-1,3,-2,JUNGLE_FENCE_GATE:7)
Block(2,3,-2,AIR)
Block(3,3,-2,SPRUCE_WOOD_STAIRS:6)
Block(4,3,-2,JUNGLE_FENCE)
Block(-5,3,-1,JUNGLE_FENCE)
Block(-4,3,-1,JUNGLE_FENCE)
Block(-2,3,-1,JUNGLE_FENCE)
Block(-1,3,-1,LOG:3)
Block(0,3,-1,JUNGLE_FENCE)
Block(3,3,-1,JUNGLE_FENCE)
Block(4,3,-1,LOG:3)
Block(-1,3,0,JUNGLE_FENCE)
Block(0,3,0,BED_BLOCK:10)
Block(3,3,0,BED_BLOCK:10)
Block(4,3,0,JUNGLE_FENCE)
Block(-4,3,1,JUNGLE_FENCE)
Block(-1,3,1,JUNGLE_FENCE)
Block(0,3,1,BED_BLOCK)
Block(3,3,1,BED_BLOCK)
Block(4,3,1,JUNGLE_FENCE)
Block(-1,3,2,JUNGLE_FENCE)
Block(0,3,2,WORKBENCH)
Block(1,3,2,AIR)
Block(3,3,2,CAULDRON:3)
Block(4,3,2,JUNGLE_FENCE)
Block(-1,3,3,JUNGLE_FENCE)
Block(0,3,3,BED_BLOCK:0)
Block(3,3,3,BED_BLOCK:0)
Block(4,3,3,JUNGLE_FENCE)
Block(-1,3,4,JUNGLE_FENCE)
Block(0,3,4,BED_BLOCK:8)
RandomBlock(1,3,4,CHEST:0,../JungleNBT/StructureLoot/JunkChest_1.nbt,25,CHEST:0,../JungleNBT/StructureLoot/JunkChest_2.nbt,25,CHEST:0,../JungleNBT/StructureLoot/JunkChest_3.nbt,25,CHEST:0,../JungleNBT/StructureLoot/JunkChest_4.nbt,25,CHEST:0,../JungleNBT/StructureLoot/JunkChest_5.nbt,25,CHEST:0,../JungleNBT/LoreStoryline/JungleLore05.nbt,2,CHEST:0,../JungleNBT/LoreStoryline/JungleLore04.nbt,2,CHEST:0,../JungleNBT/LoreStoryline/JungleLore03.nbt,2,CHEST:0,../JungleNBT/LoreStoryline/JungleLore02.nbt,2,CHEST:0,../JungleNBT/LoreStoryline/JungleLore01.nbt,2,CHEST:0,../JungleNBT/StructureLoot/Common1.nbt,3,CHEST:0,../JungleNBT/StructureLoot/Common2.nbt,3,CHEST:0,../JungleNBT/StructureLoot/Common3.nbt,3,CHEST:0,../JungleNBT/StructureLoot/Common4.nbt,3,CHEST:0,../JungleNBT/StructureLoot/Common5.nbt,3,CHEST:0,../JungleNBT/StructureLoot/Common5.nbt,3,CHEST:0,../JungleNBT/StructureLoot/Common6.nbt,3,CHEST:0,../JungleNBT/StructureLoot/Common7.nbt,3,CHEST:0,../JungleNBT/StructureLoot/Common8.nbt,3,CHEST:0,../JungleNBT/StructureLoot/Common9.nbt,3,CHEST:0,../JungleNBT/StructureLoot/Common10.nbt,3,CHEST:0,../JungleNBT/StructureLoot/Common11.nbt,3,CHEST:0,../JungleNBT/StructureLoot/Common12.nbt,3,CHEST:0,../JungleNBT/StructureLoot/Common13.nbt,3,CHEST:0,../JungleNBT/StructureLoot/Common14.nbt,3,CHEST:0,../JungleNBT/StructureLoot/Common15.nbt,3,CHEST:0,../JungleNBT/StructureLoot/Rare1.nbt,3,CHEST:0,../JungleNBT/StructureLoot/Rare2.nbt,3,CHEST:0,../JungleNBT/StructureLoot/Rare3.nbt,3,CHEST:0,../JungleNBT/StructureLoot/Rare4.nbt,3,CHEST:0,../JungleNBT/StructureLoot/Rare5.nbt,3,CHEST:0,../JungleNBT/StructureLoot/Rare6.nbt,3,CHEST:0,../JungleNBT/StructureLoot/Rare7.nbt,3,CHEST:0,../JungleNBT/StructureLoot/Rare8.nbt,3,CHEST:0,../JungleNBT/StructureLoot/Rare9.nbt,3,CHEST:0,../JungleNBT/StructureLoot/Rare10.nbt,3,CHEST:0,../JungleNBT/StructureLoot/Rare11.nbt,3,CHEST:0,../JungleNBT/StructureLoot/Rare12.nbt,3,CHEST:0,../JungleNBT/StructureLoot/Rare13.nbt,3,CHEST:0,../JungleNBT/StructureLoot/Rare14.nbt,3,CHEST:0,../JungleNBT/StructureLoot/Rare15.nbt,3,CHEST:0,../JungleNBT/StructureLoot/Epic1.nbt,3,CHEST:0,../JungleNBT/StructureLoot/Epic2.nbt,3,CHEST:0,../JungleNBT/StructureLoot/Epic3.nbt,3,CHEST:0,../JungleNBT/StructureLoot/Epic4.nbt,3,CHEST:0,../JungleNBT/StructureLoot/Epic5.nbt,3,CHEST:0,../JungleNBT/StructureLoot/Epic6.nbt,3,CHEST:0,../JungleNBT/StructureLoot/Epic7.nbt,3,CHEST:0,../JungleNBT/StructureLoot/Epic8.nbt,3,CHEST:0,../JungleNBT/StructureLoot/Epic9.nbt,3,CHEST:0,../JungleNBT/StructureLoot/Epic10.nbt,3,CHEST:0,../JungleNBT/StructureLoot/Epic11.nbt,3,CHEST:0,../JungleNBT/StructureLoot/Epic12.nbt,3,CHEST:0,../JungleNBT/StructureLoot/Epic13.nbt,3,CHEST:0,../JungleNBT/StructureLoot/Epic14.nbt,3,CHEST:0,../JungleNBT/StructureLoot/Epic15.nbt,3,CHEST:0,../JungleNBT/LoreStoryline/JungleLore05.nbt,100)
RandomBlock(2,3,4,CHEST:0,../JungleNBT/StructureLoot/JunkChest_1.nbt,25,CHEST:0,../JungleNBT/StructureLoot/JunkChest_2.nbt,25,CHEST:0,../JungleNBT/StructureLoot/JunkChest_3.nbt,25,CHEST:0,../JungleNBT/StructureLoot/JunkChest_4.nbt,25,CHEST:0,../JungleNBT/StructureLoot/JunkChest_5.nbt,25,CHEST:0,../JungleNBT/LoreStoryline/JungleLore05.nbt,2,CHEST:0,../JungleNBT/LoreStoryline/JungleLore04.nbt,2,CHEST:0,../JungleNBT/LoreStoryline/JungleLore03.nbt,2,CHEST:0,../JungleNBT/LoreStoryline/JungleLore02.nbt,2,CHEST:0,../JungleNBT/LoreStoryline/JungleLore01.nbt,2,CHEST:0,../JungleNBT/StructureLoot/Common1.nbt,3,CHEST:0,../JungleNBT/StructureLoot/Common2.nbt,3,CHEST:0,../JungleNBT/StructureLoot/Common3.nbt,3,CHEST:0,../JungleNBT/StructureLoot/Common4.nbt,3,CHEST:0,../JungleNBT/StructureLoot/Common5.nbt,3,CHEST:0,../JungleNBT/StructureLoot/Common5.nbt,3,CHEST:0,../JungleNBT/StructureLoot/Common6.nbt,3,CHEST:0,../JungleNBT/StructureLoot/Common7.nbt,3,CHEST:0,../JungleNBT/StructureLoot/Common8.nbt,3,CHEST:0,../JungleNBT/StructureLoot/Common9.nbt,3,CHEST:0,../JungleNBT/StructureLoot/Common10.nbt,3,CHEST:0,../JungleNBT/StructureLoot/Common11.nbt,3,CHEST:0,../JungleNBT/StructureLoot/Common12.nbt,3,CHEST:0,../JungleNBT/StructureLoot/Common13.nbt,3,CHEST:0,../JungleNBT/StructureLoot/Common14.nbt,3,CHEST:0,../JungleNBT/StructureLoot/Common15.nbt,3,CHEST:0,../JungleNBT/StructureLoot/Rare1.nbt,3,CHEST:0,../JungleNBT/StructureLoot/Rare2.nbt,3,CHEST:0,../JungleNBT/StructureLoot/Rare3.nbt,3,CHEST:0,../JungleNBT/StructureLoot/Rare4.nbt,3,CHEST:0,../JungleNBT/StructureLoot/Rare5.nbt,3,CHEST:0,../JungleNBT/StructureLoot/Rare6.nbt,3,CHEST:0,../JungleNBT/StructureLoot/Rare7.nbt,3,CHEST:0,../JungleNBT/StructureLoot/Rare8.nbt,3,CHEST:0,../JungleNBT/StructureLoot/Rare9.nbt,3,CHEST:0,../JungleNBT/StructureLoot/Rare10.nbt,3,CHEST:0,../JungleNBT/StructureLoot/Rare11.nbt,3,CHEST:0,../JungleNBT/StructureLoot/Rare12.nbt,3,CHEST:0,../JungleNBT/StructureLoot/Rare13.nbt,3,CHEST:0,../JungleNBT/StructureLoot/Rare14.nbt,3,CHEST:0,../JungleNBT/StructureLoot/Rare15.nbt,3,CHEST:0,../JungleNBT/StructureLoot/Epic1.nbt,3,CHEST:0,../JungleNBT/StructureLoot/Epic2.nbt,3,CHEST:0,../JungleNBT/StructureLoot/Epic3.nbt,3,CHEST:0,../JungleNBT/StructureLoot/Epic4.nbt,3,CHEST:0,../JungleNBT/StructureLoot/Epic5.nbt,3,CHEST:0,../JungleNBT/StructureLoot/Epic6.nbt,3,CHEST:0,../JungleNBT/StructureLoot/Epic7.nbt,3,CHEST:0,../JungleNBT/StructureLoot/Epic8.nbt,3,CHEST:0,../JungleNBT/StructureLoot/Epic9.nbt,3,CHEST:0,../JungleNBT/StructureLoot/Epic10.nbt,3,CHEST:0,../JungleNBT/StructureLoot/Epic11.nbt,3,CHEST:0,../JungleNBT/StructureLoot/Epic12.nbt,3,CHEST:0,../JungleNBT/StructureLoot/Epic13.nbt,3,CHEST:0,../JungleNBT/StructureLoot/Epic14.nbt,3,CHEST:0,../JungleNBT/StructureLoot/Epic15.nbt,3,CHEST:0,../JungleNBT/LoreStoryline/JungleLore05.nbt,100)
Block(3,3,4,BED_BLOCK:8)
Block(4,3,4,JUNGLE_FENCE)
Block(-1,3,5,LOG:3)
Block(0,3,5,JUNGLE_FENCE)
Block(1,3,5,JUNGLE_FENCE)
Block(2,3,5,JUNGLE_FENCE)
Block(3,3,5,JUNGLE_FENCE)
Block(4,3,5,LOG:3)
Block(-4,4,-7,JUNGLE_FENCE)
Block(-3,4,-7,SPRUCE_DOOR:8)
Block(-2,4,-7,JUNGLE_FENCE)
Block(-4,4,-6,SPRUCE_DOOR:9)
Block(-2,4,-6,SPRUCE_DOOR:8)
Block(-4,4,-5,JUNGLE_FENCE)
Block(-3,4,-5,SPRUCE_DOOR:8)
Block(-2,4,-5,JUNGLE_FENCE)
RandomBlock(0,4,-5,WALL_BANNER,../JungleNBT/banners/JungleBanner01.nbt,8,WALL_BANNER,../JungleNBT/banners/JungleBanner02.nbt,8,WALL_BANNER,../JungleNBT/banners/JungleBanner03.nbt,8,WALL_BANNER,../JungleNBT/banners/JungleBanner04.nbt,8,WALL_BANNER,../JungleNBT/banners/JungleBanner05.nbt,8,WALL_BANNER,../JungleNBT/banners/JungleBanner06.nbt,8,WALL_BANNER,../JungleNBT/banners/JungleBanner07.nbt,8,WALL_BANNER,../JungleNBT/banners/JungleBanner08.nbt,8,WALL_BANNER,../JungleNBT/banners/JungleBanner09.nbt,8,WALL_BANNER,../JungleNBT/banners/JungleBanner10.nbt,8,WALL_BANNER,../JungleNBT/banners/JungleBanner11.nbt,8,WALL_BANNER,../JungleNBT/banners/JungleBanner12.nbt,8,WALL_BANNER,../JungleNBT/banners/JungleBanner13.nbt,8,WALL_BANNER,../JungleNBT/banners/JungleBanner14.nbt,8,WALL_BANNER,../JungleNBT/banners/JungleBanner15.nbt,8,WALL_BANNER,../JungleNBT/banners/JungleBanner16.nbt,8,WALL_BANNER,../JungleNBT/banners/JungleBanner17.nbt,8,WALL_BANNER,../JungleNBT/banners/JungleBanner18.nbt,8,WALL_BANNER,../JungleNBT/banners/JungleBanner19.nbt,8,WALL_BANNER,../JungleNBT/banners/JungleBanner20.nbt,100)
RandomBlock(1,4,-5,WALL_BANNER,../JungleNBT/banners/JungleBanner01.nbt,8,WALL_BANNER,../JungleNBT/banners/JungleBanner02.nbt,8,WALL_BANNER,../JungleNBT/banners/JungleBanner03.nbt,8,WALL_BANNER,../JungleNBT/banners/JungleBanner04.nbt,8,WALL_BANNER,../JungleNBT/banners/JungleBanner05.nbt,8,WALL_BANNER,../JungleNBT/banners/JungleBanner06.nbt,8,WALL_BANNER,../JungleNBT/banners/JungleBanner07.nbt,8,WALL_BANNER,../JungleNBT/banners/JungleBanner08.nbt,8,WALL_BANNER,../JungleNBT/banners/JungleBanner09.nbt,8,WALL_BANNER,../JungleNBT/banners/JungleBanner10.nbt,8,WALL_BANNER,../JungleNBT/banners/JungleBanner11.nbt,8,WALL_BANNER,../JungleNBT/banners/JungleBanner12.nbt,8,WALL_BANNER,../JungleNBT/banners/JungleBanner13.nbt,8,WALL_BANNER,../JungleNBT/banners/JungleBanner14.nbt,8,WALL_BANNER,../JungleNBT/banners/JungleBanner15.nbt,8,WALL_BANNER,../JungleNBT/banners/JungleBanner16.nbt,8,WALL_BANNER,../JungleNBT/banners/JungleBanner17.nbt,8,WALL_BANNER,../JungleNBT/banners/JungleBanner18.nbt,8,WALL_BANNER,../JungleNBT/banners/JungleBanner19.nbt,8,WALL_BANNER,../JungleNBT/banners/JungleBanner20.nbt,100)
RandomBlock(2,4,-5,WALL_BANNER,../JungleNBT/banners/JungleBanner01.nbt,8,WALL_BANNER,../JungleNBT/banners/JungleBanner02.nbt,8,WALL_BANNER,../JungleNBT/banners/JungleBanner03.nbt,8,WALL_BANNER,../JungleNBT/banners/JungleBanner04.nbt,8,WALL_BANNER,../JungleNBT/banners/JungleBanner05.nbt,8,WALL_BANNER,../JungleNBT/banners/JungleBanner06.nbt,8,WALL_BANNER,../JungleNBT/banners/JungleBanner07.nbt,8,WALL_BANNER,../JungleNBT/banners/JungleBanner08.nbt,8,WALL_BANNER,../JungleNBT/banners/JungleBanner09.nbt,8,WALL_BANNER,../JungleNBT/banners/JungleBanner10.nbt,8,WALL_BANNER,../JungleNBT/banners/JungleBanner11.nbt,8,WALL_BANNER,../JungleNBT/banners/JungleBanner12.nbt,8,WALL_BANNER,../JungleNBT/banners/JungleBanner13.nbt,8,WALL_BANNER,../JungleNBT/banners/JungleBanner14.nbt,8,WALL_BANNER,../JungleNBT/banners/JungleBanner15.nbt,8,WALL_BANNER,../JungleNBT/banners/JungleBanner16.nbt,8,WALL_BANNER,../JungleNBT/banners/JungleBanner17.nbt,8,WALL_BANNER,../JungleNBT/banners/JungleBanner18.nbt,8,WALL_BANNER,../JungleNBT/banners/JungleBanner19.nbt,8,WALL_BANNER,../JungleNBT/banners/JungleBanner20.nbt,100)
RandomBlock(3,4,-5,WALL_BANNER,../JungleNBT/banners/JungleBanner01.nbt,8,WALL_BANNER,../JungleNBT/banners/JungleBanner02.nbt,8,WALL_BANNER,../JungleNBT/banners/JungleBanner03.nbt,8,WALL_BANNER,../JungleNBT/banners/JungleBanner04.nbt,8,WALL_BANNER,../JungleNBT/banners/JungleBanner05.nbt,8,WALL_BANNER,../JungleNBT/banners/JungleBanner06.nbt,8,WALL_BANNER,../JungleNBT/banners/JungleBanner07.nbt,8,WALL_BANNER,../JungleNBT/banners/JungleBanner08.nbt,8,WALL_BANNER,../JungleNBT/banners/JungleBanner09.nbt,8,WALL_BANNER,../JungleNBT/banners/JungleBanner10.nbt,8,WALL_BANNER,../JungleNBT/banners/JungleBanner11.nbt,8,WALL_BANNER,../JungleNBT/banners/JungleBanner12.nbt,8,WALL_BANNER,../JungleNBT/banners/JungleBanner13.nbt,8,WALL_BANNER,../JungleNBT/banners/JungleBanner14.nbt,8,WALL_BANNER,../JungleNBT/banners/JungleBanner15.nbt,8,WALL_BANNER,../JungleNBT/banners/JungleBanner16.nbt,8,WALL_BANNER,../JungleNBT/banners/JungleBanner17.nbt,8,WALL_BANNER,../JungleNBT/banners/JungleBanner18.nbt,8,WALL_BANNER,../JungleNBT/banners/JungleBanner19.nbt,8,WALL_BANNER,../JungleNBT/banners/JungleBanner20.nbt,100)
Block(-4,4,-4,TORCH)
Block(-2,4,-4,TORCH)
Block(-1,4,-4,LOG:3)
Block(0,4,-4,JUNGLE_FENCE)
Block(1,4,-4,JUNGLE_FENCE)
Block(2,4,-4,JUNGLE_FENCE)
Block(3,4,-4,JUNGLE_FENCE)
Block(4,4,-4,LOG:3)
RandomBlock(-2,4,-3,WALL_BANNER:4,../JungleNBT/banners/JungleBanner01.nbt,8,WALL_BANNER:4,../JungleNBT/banners/JungleBanner02.nbt,8,WALL_BANNER:4,../JungleNBT/banners/JungleBanner03.nbt,8,WALL_BANNER:4,../JungleNBT/banners/JungleBanner04.nbt,8,WALL_BANNER:4,../JungleNBT/banners/JungleBanner05.nbt,8,WALL_BANNER:4,../JungleNBT/banners/JungleBanner06.nbt,8,WALL_BANNER:4,../JungleNBT/banners/JungleBanner07.nbt,8,WALL_BANNER:4,../JungleNBT/banners/JungleBanner08.nbt,8,WALL_BANNER:4,../JungleNBT/banners/JungleBanner09.nbt,8,WALL_BANNER:4,../JungleNBT/banners/JungleBanner10.nbt,8,WALL_BANNER:4,../JungleNBT/banners/JungleBanner11.nbt,8,WALL_BANNER:4,../JungleNBT/banners/JungleBanner12.nbt,8,WALL_BANNER:4,../JungleNBT/banners/JungleBanner13.nbt,8,WALL_BANNER:4,../JungleNBT/banners/JungleBanner14.nbt,8,WALL_BANNER:4,../JungleNBT/banners/JungleBanner15.nbt,8,WALL_BANNER:4,../JungleNBT/banners/JungleBanner16.nbt,8,WALL_BANNER:4,../JungleNBT/banners/JungleBanner17.nbt,8,WALL_BANNER:4,../JungleNBT/banners/JungleBanner18.nbt,8,WALL_BANNER:4,../JungleNBT/banners/JungleBanner19.nbt,8,WALL_BANNER:4,../JungleNBT/banners/JungleBanner20.nbt,100)
Block(-1,4,-3,JUNGLE_FENCE_GATE:3)
RandomBlock(3,4,-3,FLOWER_POT,../JungleNBT/pots/JunglePot01.nbt,10,FLOWER_POT,../JungleNBT/pots/JunglePot02.nbt,10,FLOWER_POT,../JungleNBT/pots/JunglePot03.nbt,10,FLOWER_POT,../JungleNBT/pots/JunglePot04.nbt,10,FLOWER_POT,../JungleNBT/pots/JunglePot05.nbt,10,FLOWER_POT,../JungleNBT/pots/JunglePot06.nbt,10,FLOWER_POT,../JungleNBT/pots/JunglePot07.nbt,10,FLOWER_POT,../JungleNBT/pots/JunglePot08.nbt,100)
Block(4,4,-3,JUNGLE_FENCE)
RandomBlock(5,4,-3,WALL_BANNER:5,../JungleNBT/banners/JungleBanner01.nbt,8,WALL_BANNER:5,../JungleNBT/banners/JungleBanner02.nbt,8,WALL_BANNER:5,../JungleNBT/banners/JungleBanner03.nbt,8,WALL_BANNER:5,../JungleNBT/banners/JungleBanner04.nbt,8,WALL_BANNER:5,../JungleNBT/banners/JungleBanner05.nbt,8,WALL_BANNER:5,../JungleNBT/banners/JungleBanner06.nbt,8,WALL_BANNER:5,../JungleNBT/banners/JungleBanner07.nbt,8,WALL_BANNER:5,../JungleNBT/banners/JungleBanner08.nbt,8,WALL_BANNER:5,../JungleNBT/banners/JungleBanner09.nbt,8,WALL_BANNER:5,../JungleNBT/banners/JungleBanner10.nbt,8,WALL_BANNER:5,../JungleNBT/banners/JungleBanner11.nbt,8,WALL_BANNER:5,../JungleNBT/banners/JungleBanner12.nbt,8,WALL_BANNER:5,../JungleNBT/banners/JungleBanner13.nbt,8,WALL_BANNER:5,../JungleNBT/banners/JungleBanner14.nbt,8,WALL_BANNER:5,../JungleNBT/banners/JungleBanner15.nbt,8,WALL_BANNER:5,../JungleNBT/banners/JungleBanner16.nbt,8,WALL_BANNER:5,../JungleNBT/banners/JungleBanner17.nbt,8,WALL_BANNER:5,../JungleNBT/banners/JungleBanner18.nbt,8,WALL_BANNER:5,../JungleNBT/banners/JungleBanner19.nbt,8,WALL_BANNER:5,../JungleNBT/banners/JungleBanner20.nbt,100)
RandomBlock(-2,4,-2,WALL_BANNER:4,../JungleNBT/banners/JungleBanner01.nbt,8,WALL_BANNER:4,../JungleNBT/banners/JungleBanner02.nbt,8,WALL_BANNER:4,../JungleNBT/banners/JungleBanner03.nbt,8,WALL_BANNER:4,../JungleNBT/banners/JungleBanner04.nbt,8,WALL_BANNER:4,../JungleNBT/banners/JungleBanner05.nbt,8,WALL_BANNER:4,../JungleNBT/banners/JungleBanner06.nbt,8,WALL_BANNER:4,../JungleNBT/banners/JungleBanner07.nbt,8,WALL_BANNER:4,../JungleNBT/banners/JungleBanner08.nbt,8,WALL_BANNER:4,../JungleNBT/banners/JungleBanner09.nbt,8,WALL_BANNER:4,../JungleNBT/banners/JungleBanner10.nbt,8,WALL_BANNER:4,../JungleNBT/banners/JungleBanner11.nbt,8,WALL_BANNER:4,../JungleNBT/banners/JungleBanner12.nbt,8,WALL_BANNER:4,../JungleNBT/banners/JungleBanner13.nbt,8,WALL_BANNER:4,../JungleNBT/banners/JungleBanner14.nbt,8,WALL_BANNER:4,../JungleNBT/banners/JungleBanner15.nbt,8,WALL_BANNER:4,../JungleNBT/banners/JungleBanner16.nbt,8,WALL_BANNER:4,../JungleNBT/banners/JungleBanner17.nbt,8,WALL_BANNER:4,../JungleNBT/banners/JungleBanner18.nbt,8,WALL_BANNER:4,../JungleNBT/banners/JungleBanner19.nbt,8,WALL_BANNER:4,../JungleNBT/banners/JungleBanner20.nbt,100)
Block(-1,4,-2,JUNGLE_FENCE_GATE:7)
Block(4,4,-2,JUNGLE_FENCE)
RandomBlock(5,4,-2,WALL_BANNER:5,../JungleNBT/banners/JungleBanner01.nbt,8,WALL_BANNER:5,../JungleNBT/banners/JungleBanner02.nbt,8,WALL_BANNER:5,../JungleNBT/banners/JungleBanner03.nbt,8,WALL_BANNER:5,../JungleNBT/banners/JungleBanner04.nbt,8,WALL_BANNER:5,../JungleNBT/banners/JungleBanner05.nbt,8,WALL_BANNER:5,../JungleNBT/banners/JungleBanner06.nbt,8,WALL_BANNER:5,../JungleNBT/banners/JungleBanner07.nbt,8,WALL_BANNER:5,../JungleNBT/banners/JungleBanner08.nbt,8,WALL_BANNER:5,../JungleNBT/banners/JungleBanner09.nbt,8,WALL_BANNER:5,../JungleNBT/banners/JungleBanner10.nbt,8,WALL_BANNER:5,../JungleNBT/banners/JungleBanner11.nbt,8,WALL_BANNER:5,../JungleNBT/banners/JungleBanner12.nbt,8,WALL_BANNER:5,../JungleNBT/banners/JungleBanner13.nbt,8,WALL_BANNER:5,../JungleNBT/banners/JungleBanner14.nbt,8,WALL_BANNER:5,../JungleNBT/banners/JungleBanner15.nbt,8,WALL_BANNER:5,../JungleNBT/banners/JungleBanner16.nbt,8,WALL_BANNER:5,../JungleNBT/banners/JungleBanner17.nbt,8,WALL_BANNER:5,../JungleNBT/banners/JungleBanner18.nbt,8,WALL_BANNER:5,../JungleNBT/banners/JungleBanner19.nbt,8,WALL_BANNER:5,../JungleNBT/banners/JungleBanner20.nbt,100)
Block(-4,4,-1,JUNGLE_FENCE)
Block(-2,4,-1,TORCH)
Block(-1,4,-1,LOG:3)
Block(0,4,-1,TORCH)
Block(3,4,-1,TORCH)
Block(4,4,-1,LOG:3)
RandomBlock(-2,4,0,WALL_BANNER:4,../JungleNBT/banners/JungleBanner01.nbt,8,WALL_BANNER:4,../JungleNBT/banners/JungleBanner02.nbt,8,WALL_BANNER:4,../JungleNBT/banners/JungleBanner03.nbt,8,WALL_BANNER:4,../JungleNBT/banners/JungleBanner04.nbt,8,WALL_BANNER:4,../JungleNBT/banners/JungleBanner05.nbt,8,WALL_BANNER:4,../JungleNBT/banners/JungleBanner06.nbt,8,WALL_BANNER:4,../JungleNBT/banners/JungleBanner07.nbt,8,WALL_BANNER:4,../JungleNBT/banners/JungleBanner08.nbt,8,WALL_BANNER:4,../JungleNBT/banners/JungleBanner09.nbt,8,WALL_BANNER:4,../JungleNBT/banners/JungleBanner10.nbt,8,WALL_BANNER:4,../JungleNBT/banners/JungleBanner11.nbt,8,WALL_BANNER:4,../JungleNBT/banners/JungleBanner12.nbt,8,WALL_BANNER:4,../JungleNBT/banners/JungleBanner13.nbt,8,WALL_BANNER:4,../JungleNBT/banners/JungleBanner14.nbt,8,WALL_BANNER:4,../JungleNBT/banners/JungleBanner15.nbt,8,WALL_BANNER:4,../JungleNBT/banners/JungleBanner16.nbt,8,WALL_BANNER:4,../JungleNBT/banners/JungleBanner17.nbt,8,WALL_BANNER:4,../JungleNBT/banners/JungleBanner18.nbt,8,WALL_BANNER:4,../JungleNBT/banners/JungleBanner19.nbt,8,WALL_BANNER:4,../JungleNBT/banners/JungleBanner20.nbt,100)
Block(-1,4,0,JUNGLE_FENCE)
Block(4,4,0,JUNGLE_FENCE)
RandomBlock(5,4,0,WALL_BANNER:5,../JungleNBT/banners/JungleBanner01.nbt,8,WALL_BANNER:5,../JungleNBT/banners/JungleBanner02.nbt,8,WALL_BANNER:5,../JungleNBT/banners/JungleBanner03.nbt,8,WALL_BANNER:5,../JungleNBT/banners/JungleBanner04.nbt,8,WALL_BANNER:5,../JungleNBT/banners/JungleBanner05.nbt,8,WALL_BANNER:5,../JungleNBT/banners/JungleBanner06.nbt,8,WALL_BANNER:5,../JungleNBT/banners/JungleBanner07.nbt,8,WALL_BANNER:5,../JungleNBT/banners/JungleBanner08.nbt,8,WALL_BANNER:5,../JungleNBT/banners/JungleBanner09.nbt,8,WALL_BANNER:5,../JungleNBT/banners/JungleBanner10.nbt,8,WALL_BANNER:5,../JungleNBT/banners/JungleBanner11.nbt,8,WALL_BANNER:5,../JungleNBT/banners/JungleBanner12.nbt,8,WALL_BANNER:5,../JungleNBT/banners/JungleBanner13.nbt,8,WALL_BANNER:5,../JungleNBT/banners/JungleBanner14.nbt,8,WALL_BANNER:5,../JungleNBT/banners/JungleBanner15.nbt,8,WALL_BANNER:5,../JungleNBT/banners/JungleBanner16.nbt,8,WALL_BANNER:5,../JungleNBT/banners/JungleBanner17.nbt,8,WALL_BANNER:5,../JungleNBT/banners/JungleBanner18.nbt,8,WALL_BANNER:5,../JungleNBT/banners/JungleBanner19.nbt,8,WALL_BANNER:5,../JungleNBT/banners/JungleBanner20.nbt,100)
Block(-4,4,1,JUNGLE_FENCE)
RandomBlock(-2,4,1,WALL_BANNER:4,../JungleNBT/banners/JungleBanner01.nbt,8,WALL_BANNER:4,../JungleNBT/banners/JungleBanner02.nbt,8,WALL_BANNER:4,../JungleNBT/banners/JungleBanner03.nbt,8,WALL_BANNER:4,../JungleNBT/banners/JungleBanner04.nbt,8,WALL_BANNER:4,../JungleNBT/banners/JungleBanner05.nbt,8,WALL_BANNER:4,../JungleNBT/banners/JungleBanner06.nbt,8,WALL_BANNER:4,../JungleNBT/banners/JungleBanner07.nbt,8,WALL_BANNER:4,../JungleNBT/banners/JungleBanner08.nbt,8,WALL_BANNER:4,../JungleNBT/banners/JungleBanner09.nbt,8,WALL_BANNER:4,../JungleNBT/banners/JungleBanner10.nbt,8,WALL_BANNER:4,../JungleNBT/banners/JungleBanner11.nbt,8,WALL_BANNER:4,../JungleNBT/banners/JungleBanner12.nbt,8,WALL_BANNER:4,../JungleNBT/banners/JungleBanner13.nbt,8,WALL_BANNER:4,../JungleNBT/banners/JungleBanner14.nbt,8,WALL_BANNER:4,../JungleNBT/banners/JungleBanner15.nbt,8,WALL_BANNER:4,../JungleNBT/banners/JungleBanner16.nbt,8,WALL_BANNER:4,../JungleNBT/banners/JungleBanner17.nbt,8,WALL_BANNER:4,../JungleNBT/banners/JungleBanner18.nbt,8,WALL_BANNER:4,../JungleNBT/banners/JungleBanner19.nbt,8,WALL_BANNER:4,../JungleNBT/banners/JungleBanner20.nbt,100)
Block(-1,4,1,JUNGLE_FENCE)
Block(4,4,1,JUNGLE_FENCE)
RandomBlock(5,4,1,WALL_BANNER:5,../JungleNBT/banners/JungleBanner01.nbt,8,WALL_BANNER:5,../JungleNBT/banners/JungleBanner02.nbt,8,WALL_BANNER:5,../JungleNBT/banners/JungleBanner03.nbt,8,WALL_BANNER:5,../JungleNBT/banners/JungleBanner04.nbt,8,WALL_BANNER:5,../JungleNBT/banners/JungleBanner05.nbt,8,WALL_BANNER:5,../JungleNBT/banners/JungleBanner06.nbt,8,WALL_BANNER:5,../JungleNBT/banners/JungleBanner07.nbt,8,WALL_BANNER:5,../JungleNBT/banners/JungleBanner08.nbt,8,WALL_BANNER:5,../JungleNBT/banners/JungleBanner09.nbt,8,WALL_BANNER:5,../JungleNBT/banners/JungleBanner10.nbt,8,WALL_BANNER:5,../JungleNBT/banners/JungleBanner11.nbt,8,WALL_BANNER:5,../JungleNBT/banners/JungleBanner12.nbt,8,WALL_BANNER:5,../JungleNBT/banners/JungleBanner13.nbt,8,WALL_BANNER:5,../JungleNBT/banners/JungleBanner14.nbt,8,WALL_BANNER:5,../JungleNBT/banners/JungleBanner15.nbt,8,WALL_BANNER:5,../JungleNBT/banners/JungleBanner16.nbt,8,WALL_BANNER:5,../JungleNBT/banners/JungleBanner17.nbt,8,WALL_BANNER:5,../JungleNBT/banners/JungleBanner18.nbt,8,WALL_BANNER:5,../JungleNBT/banners/JungleBanner19.nbt,8,WALL_BANNER:5,../JungleNBT/banners/JungleBanner20.nbt,100)
RandomBlock(-2,4,2,WALL_BANNER:4,../JungleNBT/banners/JungleBanner01.nbt,8,WALL_BANNER:4,../JungleNBT/banners/JungleBanner02.nbt,8,WALL_BANNER:4,../JungleNBT/banners/JungleBanner03.nbt,8,WALL_BANNER:4,../JungleNBT/banners/JungleBanner04.nbt,8,WALL_BANNER:4,../JungleNBT/banners/JungleBanner05.nbt,8,WALL_BANNER:4,../JungleNBT/banners/JungleBanner06.nbt,8,WALL_BANNER:4,../JungleNBT/banners/JungleBanner07.nbt,8,WALL_BANNER:4,../JungleNBT/banners/JungleBanner08.nbt,8,WALL_BANNER:4,../JungleNBT/banners/JungleBanner09.nbt,8,WALL_BANNER:4,../JungleNBT/banners/JungleBanner10.nbt,8,WALL_BANNER:4,../JungleNBT/banners/JungleBanner11.nbt,8,WALL_BANNER:4,../JungleNBT/banners/JungleBanner12.nbt,8,WALL_BANNER:4,../JungleNBT/banners/JungleBanner13.nbt,8,WALL_BANNER:4,../JungleNBT/banners/JungleBanner14.nbt,8,WALL_BANNER:4,../JungleNBT/banners/JungleBanner15.nbt,8,WALL_BANNER:4,../JungleNBT/banners/JungleBanner16.nbt,8,WALL_BANNER:4,../JungleNBT/banners/JungleBanner17.nbt,8,WALL_BANNER:4,../JungleNBT/banners/JungleBanner18.nbt,8,WALL_BANNER:4,../JungleNBT/banners/JungleBanner19.nbt,8,WALL_BANNER:4,../JungleNBT/banners/JungleBanner20.nbt,100)
Block(-1,4,2,JUNGLE_FENCE)
Block(4,4,2,JUNGLE_FENCE)
RandomBlock(5,4,2,WALL_BANNER:5,../JungleNBT/banners/JungleBanner01.nbt,8,WALL_BANNER:5,../JungleNBT/banners/JungleBanner02.nbt,8,WALL_BANNER:5,../JungleNBT/banners/JungleBanner03.nbt,8,WALL_BANNER:5,../JungleNBT/banners/JungleBanner04.nbt,8,WALL_BANNER:5,../JungleNBT/banners/JungleBanner05.nbt,8,WALL_BANNER:5,../JungleNBT/banners/JungleBanner06.nbt,8,WALL_BANNER:5,../JungleNBT/banners/JungleBanner07.nbt,8,WALL_BANNER:5,../JungleNBT/banners/JungleBanner08.nbt,8,WALL_BANNER:5,../JungleNBT/banners/JungleBanner09.nbt,8,WALL_BANNER:5,../JungleNBT/banners/JungleBanner10.nbt,8,WALL_BANNER:5,../JungleNBT/banners/JungleBanner11.nbt,8,WALL_BANNER:5,../JungleNBT/banners/JungleBanner12.nbt,8,WALL_BANNER:5,../JungleNBT/banners/JungleBanner13.nbt,8,WALL_BANNER:5,../JungleNBT/banners/JungleBanner14.nbt,8,WALL_BANNER:5,../JungleNBT/banners/JungleBanner15.nbt,8,WALL_BANNER:5,../JungleNBT/banners/JungleBanner16.nbt,8,WALL_BANNER:5,../JungleNBT/banners/JungleBanner17.nbt,8,WALL_BANNER:5,../JungleNBT/banners/JungleBanner18.nbt,8,WALL_BANNER:5,../JungleNBT/banners/JungleBanner19.nbt,8,WALL_BANNER:5,../JungleNBT/banners/JungleBanner20.nbt,100)
RandomBlock(-2,4,3,WALL_BANNER:4,../JungleNBT/banners/JungleBanner01.nbt,8,WALL_BANNER:4,../JungleNBT/banners/JungleBanner02.nbt,8,WALL_BANNER:4,../JungleNBT/banners/JungleBanner03.nbt,8,WALL_BANNER:4,../JungleNBT/banners/JungleBanner04.nbt,8,WALL_BANNER:4,../JungleNBT/banners/JungleBanner05.nbt,8,WALL_BANNER:4,../JungleNBT/banners/JungleBanner06.nbt,8,WALL_BANNER:4,../JungleNBT/banners/JungleBanner07.nbt,8,WALL_BANNER:4,../JungleNBT/banners/JungleBanner08.nbt,8,WALL_BANNER:4,../JungleNBT/banners/JungleBanner09.nbt,8,WALL_BANNER:4,../JungleNBT/banners/JungleBanner10.nbt,8,WALL_BANNER:4,../JungleNBT/banners/JungleBanner11.nbt,8,WALL_BANNER:4,../JungleNBT/banners/JungleBanner12.nbt,8,WALL_BANNER:4,../JungleNBT/banners/JungleBanner13.nbt,8,WALL_BANNER:4,../JungleNBT/banners/JungleBanner14.nbt,8,WALL_BANNER:4,../JungleNBT/banners/JungleBanner15.nbt,8,WALL_BANNER:4,../JungleNBT/banners/JungleBanner16.nbt,8,WALL_BANNER:4,../JungleNBT/banners/JungleBanner17.nbt,8,WALL_BANNER:4,../JungleNBT/banners/JungleBanner18.nbt,8,WALL_BANNER:4,../JungleNBT/banners/JungleBanner19.nbt,8,WALL_BANNER:4,../JungleNBT/banners/JungleBanner20.nbt,100)
Block(-1,4,3,JUNGLE_FENCE)
Block(4,4,3,JUNGLE_FENCE)
RandomBlock(5,4,3,WALL_BANNER:5,../JungleNBT/banners/JungleBanner01.nbt,8,WALL_BANNER:5,../JungleNBT/banners/JungleBanner02.nbt,8,WALL_BANNER:5,../JungleNBT/banners/JungleBanner03.nbt,8,WALL_BANNER:5,../JungleNBT/banners/JungleBanner04.nbt,8,WALL_BANNER:5,../JungleNBT/banners/JungleBanner05.nbt,8,WALL_BANNER:5,../JungleNBT/banners/JungleBanner06.nbt,8,WALL_BANNER:5,../JungleNBT/banners/JungleBanner07.nbt,8,WALL_BANNER:5,../JungleNBT/banners/JungleBanner08.nbt,8,WALL_BANNER:5,../JungleNBT/banners/JungleBanner09.nbt,8,WALL_BANNER:5,../JungleNBT/banners/JungleBanner10.nbt,8,WALL_BANNER:5,../JungleNBT/banners/JungleBanner11.nbt,8,WALL_BANNER:5,../JungleNBT/banners/JungleBanner12.nbt,8,WALL_BANNER:5,../JungleNBT/banners/JungleBanner13.nbt,8,WALL_BANNER:5,../JungleNBT/banners/JungleBanner14.nbt,8,WALL_BANNER:5,../JungleNBT/banners/JungleBanner15.nbt,8,WALL_BANNER:5,../JungleNBT/banners/JungleBanner16.nbt,8,WALL_BANNER:5,../JungleNBT/banners/JungleBanner17.nbt,8,WALL_BANNER:5,../JungleNBT/banners/JungleBanner18.nbt,8,WALL_BANNER:5,../JungleNBT/banners/JungleBanner19.nbt,8,WALL_BANNER:5,../JungleNBT/banners/JungleBanner20.nbt,100)
RandomBlock(-2,4,4,WALL_BANNER:4,../JungleNBT/banners/JungleBanner01.nbt,8,WALL_BANNER:4,../JungleNBT/banners/JungleBanner02.nbt,8,WALL_BANNER:4,../JungleNBT/banners/JungleBanner03.nbt,8,WALL_BANNER:4,../JungleNBT/banners/JungleBanner04.nbt,8,WALL_BANNER:4,../JungleNBT/banners/JungleBanner05.nbt,8,WALL_BANNER:4,../JungleNBT/banners/JungleBanner06.nbt,8,WALL_BANNER:4,../JungleNBT/banners/JungleBanner07.nbt,8,WALL_BANNER:4,../JungleNBT/banners/JungleBanner08.nbt,8,WALL_BANNER:4,../JungleNBT/banners/JungleBanner09.nbt,8,WALL_BANNER:4,../JungleNBT/banners/JungleBanner10.nbt,8,WALL_BANNER:4,../JungleNBT/banners/JungleBanner11.nbt,8,WALL_BANNER:4,../JungleNBT/banners/JungleBanner12.nbt,8,WALL_BANNER:4,../JungleNBT/banners/JungleBanner13.nbt,8,WALL_BANNER:4,../JungleNBT/banners/JungleBanner14.nbt,8,WALL_BANNER:4,../JungleNBT/banners/JungleBanner15.nbt,8,WALL_BANNER:4,../JungleNBT/banners/JungleBanner16.nbt,8,WALL_BANNER:4,../JungleNBT/banners/JungleBanner17.nbt,8,WALL_BANNER:4,../JungleNBT/banners/JungleBanner18.nbt,8,WALL_BANNER:4,../JungleNBT/banners/JungleBanner19.nbt,8,WALL_BANNER:4,../JungleNBT/banners/JungleBanner20.nbt,100)
Block(-1,4,4,JUNGLE_FENCE)
Block(4,4,4,JUNGLE_FENCE)
RandomBlock(5,4,4,WALL_BANNER:5,../JungleNBT/banners/JungleBanner01.nbt,8,WALL_BANNER:5,../JungleNBT/banners/JungleBanner02.nbt,8,WALL_BANNER:5,../JungleNBT/banners/JungleBanner03.nbt,8,WALL_BANNER:5,../JungleNBT/banners/JungleBanner04.nbt,8,WALL_BANNER:5,../JungleNBT/banners/JungleBanner05.nbt,8,WALL_BANNER:5,../JungleNBT/banners/JungleBanner06.nbt,8,WALL_BANNER:5,../JungleNBT/banners/JungleBanner07.nbt,8,WALL_BANNER:5,../JungleNBT/banners/JungleBanner08.nbt,8,WALL_BANNER:5,../JungleNBT/banners/JungleBanner09.nbt,8,WALL_BANNER:5,../JungleNBT/banners/JungleBanner10.nbt,8,WALL_BANNER:5,../JungleNBT/banners/JungleBanner11.nbt,8,WALL_BANNER:5,../JungleNBT/banners/JungleBanner12.nbt,8,WALL_BANNER:5,../JungleNBT/banners/JungleBanner13.nbt,8,WALL_BANNER:5,../JungleNBT/banners/JungleBanner14.nbt,8,WALL_BANNER:5,../JungleNBT/banners/JungleBanner15.nbt,8,WALL_BANNER:5,../JungleNBT/banners/JungleBanner16.nbt,8,WALL_BANNER:5,../JungleNBT/banners/JungleBanner17.nbt,8,WALL_BANNER:5,../JungleNBT/banners/JungleBanner18.nbt,8,WALL_BANNER:5,../JungleNBT/banners/JungleBanner19.nbt,8,WALL_BANNER:5,../JungleNBT/banners/JungleBanner20.nbt,100)
Block(-1,4,5,LOG:3)
Block(0,4,5,JUNGLE_FENCE)
Block(1,4,5,JUNGLE_FENCE)
Block(2,4,5,JUNGLE_FENCE)
Block(3,4,5,JUNGLE_FENCE)
Block(4,4,5,LOG:3)
RandomBlock(0,4,6,WALL_BANNER:3,../JungleNBT/banners/JungleBanner01.nbt,8,WALL_BANNER:3,../JungleNBT/banners/JungleBanner02.nbt,8,WALL_BANNER:3,../JungleNBT/banners/JungleBanner03.nbt,8,WALL_BANNER:3,../JungleNBT/banners/JungleBanner04.nbt,8,WALL_BANNER:3,../JungleNBT/banners/JungleBanner05.nbt,8,WALL_BANNER:3,../JungleNBT/banners/JungleBanner06.nbt,8,WALL_BANNER:3,../JungleNBT/banners/JungleBanner07.nbt,8,WALL_BANNER:3,../JungleNBT/banners/JungleBanner08.nbt,8,WALL_BANNER:3,../JungleNBT/banners/JungleBanner09.nbt,8,WALL_BANNER:3,../JungleNBT/banners/JungleBanner10.nbt,8,WALL_BANNER:3,../JungleNBT/banners/JungleBanner11.nbt,8,WALL_BANNER:3,../JungleNBT/banners/JungleBanner12.nbt,8,WALL_BANNER:3,../JungleNBT/banners/JungleBanner13.nbt,8,WALL_BANNER:3,../JungleNBT/banners/JungleBanner14.nbt,8,WALL_BANNER:3,../JungleNBT/banners/JungleBanner15.nbt,8,WALL_BANNER:3,../JungleNBT/banners/JungleBanner16.nbt,8,WALL_BANNER:3,../JungleNBT/banners/JungleBanner17.nbt,8,WALL_BANNER:3,../JungleNBT/banners/JungleBanner18.nbt,8,WALL_BANNER:3,../JungleNBT/banners/JungleBanner19.nbt,8,WALL_BANNER:3,../JungleNBT/banners/JungleBanner20.nbt,100)
RandomBlock(1,4,6,WALL_BANNER:3,../JungleNBT/banners/JungleBanner01.nbt,8,WALL_BANNER:3,../JungleNBT/banners/JungleBanner02.nbt,8,WALL_BANNER:3,../JungleNBT/banners/JungleBanner03.nbt,8,WALL_BANNER:3,../JungleNBT/banners/JungleBanner04.nbt,8,WALL_BANNER:3,../JungleNBT/banners/JungleBanner05.nbt,8,WALL_BANNER:3,../JungleNBT/banners/JungleBanner06.nbt,8,WALL_BANNER:3,../JungleNBT/banners/JungleBanner07.nbt,8,WALL_BANNER:3,../JungleNBT/banners/JungleBanner08.nbt,8,WALL_BANNER:3,../JungleNBT/banners/JungleBanner09.nbt,8,WALL_BANNER:3,../JungleNBT/banners/JungleBanner10.nbt,8,WALL_BANNER:3,../JungleNBT/banners/JungleBanner11.nbt,8,WALL_BANNER:3,../JungleNBT/banners/JungleBanner12.nbt,8,WALL_BANNER:3,../JungleNBT/banners/JungleBanner13.nbt,8,WALL_BANNER:3,../JungleNBT/banners/JungleBanner14.nbt,8,WALL_BANNER:3,../JungleNBT/banners/JungleBanner15.nbt,8,WALL_BANNER:3,../JungleNBT/banners/JungleBanner16.nbt,8,WALL_BANNER:3,../JungleNBT/banners/JungleBanner17.nbt,8,WALL_BANNER:3,../JungleNBT/banners/JungleBanner18.nbt,8,WALL_BANNER:3,../JungleNBT/banners/JungleBanner19.nbt,8,WALL_BANNER:3,../JungleNBT/banners/JungleBanner20.nbt,100)
RandomBlock(2,4,6,WALL_BANNER:3,../JungleNBT/banners/JungleBanner01.nbt,8,WALL_BANNER:3,../JungleNBT/banners/JungleBanner02.nbt,8,WALL_BANNER:3,../JungleNBT/banners/JungleBanner03.nbt,8,WALL_BANNER:3,../JungleNBT/banners/JungleBanner04.nbt,8,WALL_BANNER:3,../JungleNBT/banners/JungleBanner05.nbt,8,WALL_BANNER:3,../JungleNBT/banners/JungleBanner06.nbt,8,WALL_BANNER:3,../JungleNBT/banners/JungleBanner07.nbt,8,WALL_BANNER:3,../JungleNBT/banners/JungleBanner08.nbt,8,WALL_BANNER:3,../JungleNBT/banners/JungleBanner09.nbt,8,WALL_BANNER:3,../JungleNBT/banners/JungleBanner10.nbt,8,WALL_BANNER:3,../JungleNBT/banners/JungleBanner11.nbt,8,WALL_BANNER:3,../JungleNBT/banners/JungleBanner12.nbt,8,WALL_BANNER:3,../JungleNBT/banners/JungleBanner13.nbt,8,WALL_BANNER:3,../JungleNBT/banners/JungleBanner14.nbt,8,WALL_BANNER:3,../JungleNBT/banners/JungleBanner15.nbt,8,WALL_BANNER:3,../JungleNBT/banners/JungleBanner16.nbt,8,WALL_BANNER:3,../JungleNBT/banners/JungleBanner17.nbt,8,WALL_BANNER:3,../JungleNBT/banners/JungleBanner18.nbt,8,WALL_BANNER:3,../JungleNBT/banners/JungleBanner19.nbt,8,WALL_BANNER:3,../JungleNBT/banners/JungleBanner20.nbt,100)
RandomBlock(3,4,6,WALL_BANNER:3,../JungleNBT/banners/JungleBanner01.nbt,8,WALL_BANNER:3,../JungleNBT/banners/JungleBanner02.nbt,8,WALL_BANNER:3,../JungleNBT/banners/JungleBanner03.nbt,8,WALL_BANNER:3,../JungleNBT/banners/JungleBanner04.nbt,8,WALL_BANNER:3,../JungleNBT/banners/JungleBanner05.nbt,8,WALL_BANNER:3,../JungleNBT/banners/JungleBanner06.nbt,8,WALL_BANNER:3,../JungleNBT/banners/JungleBanner07.nbt,8,WALL_BANNER:3,../JungleNBT/banners/JungleBanner08.nbt,8,WALL_BANNER:3,../JungleNBT/banners/JungleBanner09.nbt,8,WALL_BANNER:3,../JungleNBT/banners/JungleBanner10.nbt,8,WALL_BANNER:3,../JungleNBT/banners/JungleBanner11.nbt,8,WALL_BANNER:3,../JungleNBT/banners/JungleBanner12.nbt,8,WALL_BANNER:3,../JungleNBT/banners/JungleBanner13.nbt,8,WALL_BANNER:3,../JungleNBT/banners/JungleBanner14.nbt,8,WALL_BANNER:3,../JungleNBT/banners/JungleBanner15.nbt,8,WALL_BANNER:3,../JungleNBT/banners/JungleBanner16.nbt,8,WALL_BANNER:3,../JungleNBT/banners/JungleBanner17.nbt,8,WALL_BANNER:3,../JungleNBT/banners/JungleBanner18.nbt,8,WALL_BANNER:3,../JungleNBT/banners/JungleBanner19.nbt,8,WALL_BANNER:3,../JungleNBT/banners/JungleBanner20.nbt,100)
Block(-4,5,-7,WOOD_STEP:1)
Block(-3,5,-7,WOOD_STEP:2)
Block(-2,5,-7,WOOD_STEP:2)
Block(-4,5,-6,WOOD_STEP:2)
Block(-3,5,-6,WOOD_STEP:2)
Block(-2,5,-6,WOOD_STEP:2)
Block(-4,5,-5,WOOD_STEP:2)
Block(-3,5,-5,WOOD_STEP:2)
Block(-2,5,-5,WOOD_STEP:2)
Block(-4,5,-4,WOOD_STEP:2)
Block(-3,5,-4,WOOD_STEP:9)
Block(-2,5,-4,WOOD_STEP:10)
Block(-1,5,-4,LOG:3)
Block(0,5,-4,LOG:7)
Block(1,5,-4,LOG:7)
Block(2,5,-4,LOG:7)
Block(3,5,-4,LOG:7)
Block(4,5,-4,LOG:3)
Block(-4,5,-3,WOOD_STEP:2)
Block(-3,5,-3,WOOD_STEP:9)
Block(-2,5,-3,WOOD_STEP:9)
Block(-1,5,-3,LOG:11)
Block(0,5,-3,WOOD_STEP:11)
Block(1,5,-3,WOOD_STEP:11)
Block(2,5,-3,WOOD_STEP:11)
Block(3,5,-3,WOOD_STEP:11)
Block(4,5,-3,LOG:11)
Block(-4,5,-2,WOOD_STEP:2)
Block(-3,5,-2,WOOD_STEP:9)
Block(-1,5,-2,LOG:11)
Block(0,5,-2,WOOD_STEP:11)
Block(1,5,-2,WOOD_STEP:11)
Block(2,5,-2,WOOD_STEP:11)
Block(3,5,-2,WOOD_STEP:11)
Block(4,5,-2,LOG:11)
Block(-4,5,-1,WOOD_STEP:1)
Block(-3,5,-1,WOOD_STEP:10)
Block(-1,5,-1,LOG:3)
Block(0,5,-1,LOG:7)
Block(1,5,-1,LOG:7)
Block(2,5,-1,LOG:7)
Block(3,5,-1,LOG:7)
Block(4,5,-1,LOG:3)
Block(-4,5,0,WOOD_STEP:1)
Block(-3,5,0,WOOD_STEP:10)
Block(-2,5,0,WOOD_STEP:10)
Block(-1,5,0,LOG:11)
Block(0,5,0,WOOD_STEP:11)
Block(1,5,0,WOOD_STEP:11)
Block(2,5,0,WOOD_STEP:11)
Block(3,5,0,WOOD_STEP:11)
Block(4,5,0,LOG:11)
Block(-4,5,1,WOOD_STEP:1)
Block(-3,5,1,WOOD_STEP:2)
Block(-2,5,1,WOOD_STEP:2)
Block(-1,5,1,LOG:11)
Block(0,5,1,WOOD_STEP:11)
Block(1,5,1,WOOD_STEP:11)
Block(2,5,1,WOOD_STEP:11)
Block(3,5,1,WOOD_STEP:11)
Block(4,5,1,LOG:11)
Block(-1,5,2,LOG:11)
Block(0,5,2,WOOD_STEP:11)
Block(1,5,2,WOOD_STEP:11)
Block(2,5,2,WOOD_STEP:11)
Block(3,5,2,WOOD_STEP:11)
Block(4,5,2,LOG:11)
Block(-1,5,3,LOG:11)
Block(0,5,3,WOOD_STEP:11)
Block(1,5,3,WOOD_STEP:11)
Block(2,5,3,WOOD_STEP:11)
Block(3,5,3,WOOD_STEP:11)
Block(4,5,3,LOG:11)
Block(-1,5,4,LOG:11)
Block(0,5,4,WOOD_STEP:11)
Block(1,5,4,WOOD_STEP:11)
Block(2,5,4,WOOD_STEP:11)
Block(3,5,4,WOOD_STEP:11)
Block(4,5,4,LOG:11)
Block(-1,5,5,LOG:3)
Block(0,5,5,LOG:7)
Block(1,5,5,LOG:7)
Block(2,5,5,LOG:7)
Block(3,5,5,LOG:7)
Block(4,5,5,LOG:3)
Block(-2,6,-5,WOOD_STEP:1)
Block(-1,6,-5,WOOD_DOUBLE_STEP:1)
Block(0,6,-5,WOOD_STEP:9)
Block(3,6,-5,WOOD_STEP:9)
Block(4,6,-5,WOOD_DOUBLE_STEP:1)
Block(5,6,-5,WOOD_STEP:1)
Block(-2,6,-4,WOOD_STEP:2)
Block(-1,6,-4,LOG:3)
Block(0,6,-4,WOOD_DOUBLE_STEP:2)
Block(1,6,-4,WOOD_DOUBLE_STEP:2)
Block(2,6,-4,WOOD_DOUBLE_STEP:2)
Block(3,6,-4,WOOD_DOUBLE_STEP:2)
Block(4,6,-4,LOG:3)
Block(5,6,-4,WOOD_STEP:2)
Block(-1,6,-3,WOOD_DOUBLE_STEP:2)
Block(4,6,-3,WOOD_STEP:10)
Block(5,6,-3,WOOD_STEP:2)
Block(-2,6,-2,WOOD_STEP:2)
Block(-1,6,-2,WOOD_STEP:1)
Block(0,6,-2,WOOD_DOUBLE_STEP:1)
Block(4,6,-2,WOOD_STEP:10)
Block(5,6,-2,WOOD_STEP:2)
Block(-2,6,-1,WOOD_STEP:2)
Block(-1,6,-1,LOG:3)
Block(0,6,-1,WOOD_DOUBLE_STEP:1)
Block(4,6,-1,LOG:3)
Block(5,6,-1,WOOD_STEP:2)
Block(-2,6,0,WOOD_STEP:2)
Block(-1,6,0,WOOD_STEP:10)
Block(4,6,0,WOOD_STEP:10)
Block(5,6,0,WOOD_STEP:2)
Block(-2,6,1,WOOD_STEP:2)
Block(-1,6,1,WOOD_DOUBLE_STEP:1)
Block(4,6,1,WOOD_STEP:10)
Block(5,6,1,WOOD_STEP:2)
Block(-2,6,2,WOOD_STEP:2)
Block(-1,6,2,WOOD_DOUBLE_STEP:1)
Block(2,6,2,WOOD_STEP:9)
Block(3,6,2,WOOD_STEP:10)
Block(4,6,2,WOOD_STEP:10)
Block(5,6,2,WOOD_STEP:2)
Block(-2,6,3,WOOD_STEP:2)
Block(-1,6,3,WOOD_STEP:10)
Block(2,6,3,WOOD_STEP:9)
Block(3,6,3,WOOD_STEP:10)
Block(4,6,3,WOOD_STEP:1)
Block(5,6,3,WOOD_STEP:2)
Block(-2,6,4,WOOD_STEP:2)
Block(-1,6,4,WOOD_STEP:10)
Block(4,6,4,WOOD_STEP:10)
Block(5,6,4,WOOD_STEP:2)
Block(-2,6,5,WOOD_STEP:2)
Block(-1,6,5,LOG:3)
Block(0,6,5,WOOD_DOUBLE_STEP:2)
Block(1,6,5,WOOD_DOUBLE_STEP:2)
Block(2,6,5,WOOD_DOUBLE_STEP:2)
Block(3,6,5,WOOD_DOUBLE_STEP:2)
Block(4,6,5,LOG:3)
Block(5,6,5,WOOD_STEP:2)
Block(0,7,-5,WOOD_STEP:1)
Block(1,7,-5,WOOD_DOUBLE_STEP:1)
Block(2,7,-5,WOOD_DOUBLE_STEP:1)
Block(3,7,-5,WOOD_STEP:1)
Block(0,7,-4,WOOD_STEP:2)
Block(1,7,-4,WOOD_STEP:1)
Block(2,7,-4,WOOD_DOUBLE_STEP:2)
Block(3,7,-4,WOOD_STEP:2)
Block(0,7,-3,WOOD_STEP:2)
Block(1,7,-3,WOOD_STEP:1)
Block(2,7,-3,WOOD_STEP:10)
Block(3,7,-3,WOOD_STEP:2)
Block(1,7,-2,WOOD_STEP:1)
Block(2,7,-2,WOOD_STEP:10)
Block(3,7,-2,WOOD_STEP:2)
Block(1,7,-1,WOOD_STEP:1)
Block(2,7,-1,WOOD_STEP:10)
Block(3,7,-1,WOOD_STEP:2)
Block(0,7,0,WOOD_STEP:2)
Block(1,7,0,WOOD_STEP:10)
Block(2,7,0,WOOD_STEP:10)
Block(3,7,0,WOOD_STEP:2)
Block(0,7,1,WOOD_STEP:2)
Block(1,7,1,WOOD_STEP:10)
Block(2,7,1,WOOD_STEP:10)
Block(3,7,1,WOOD_STEP:2)
Block(0,7,2,WOOD_STEP:1)
Block(1,7,2,WOOD_STEP:1)
Block(2,7,2,WOOD_STEP:1)
Block(0,7,3,WOOD_STEP:2)
Block(1,7,3,WOOD_STEP:1)
Block(2,7,3,WOOD_STEP:1)
Block(0,7,4,WOOD_STEP:2)
Block(1,7,4,WOOD_STEP:10)
Block(2,7,4,WOOD_STEP:10)
Block(3,7,4,WOOD_STEP:2)
Block(0,7,5,WOOD_STEP:2)
Block(1,7,5,WOOD_DOUBLE_STEP:2)
Block(2,7,5,WOOD_DOUBLE_STEP:2)
Block(3,7,5,WOOD_STEP:2)

#######################################################################
# +-----------------------------------------------------------------+ #
# |                            BO3 checks                           | #
# +-----------------------------------------------------------------+ #
#######################################################################


#######################################################################
# +-----------------------------------------------------------------+ #
# |                             Branches                            | #
# +-----------------------------------------------------------------+ #
#######################################################################


#######################################################################
# +-----------------------------------------------------------------+ #
# |                             Entities                            | #
# +-----------------------------------------------------------------+ #
#######################################################################

Entity(2,3,-2,VILLAGER,1,../JungleNBT/entities/tribalkid.txt)
Entity(1,3,2,VILLAGER,1,../JungleNBT/entities/tribalnative.txt)

#######################################################################
# +-----------------------------------------------------------------+ #
# |                            Particles                            | #
# +-----------------------------------------------------------------+ #
#######################################################################


#######################################################################
# +-----------------------------------------------------------------+ #
# |                             Spawners                            | #
# +-----------------------------------------------------------------+ #
#######################################################################


#######################################################################
# +-----------------------------------------------------------------+ #
# |                             ModData                             | #
# +-----------------------------------------------------------------+ #
#######################################################################

