Author: BO3 BulkEdit (by LanToaster)
Description: This Object was Created with BO3_BulkEdit
Version: 3
SettingsMode: WriteDisable
Tree: false
Frequency: 100
Rarity: 100
RotateRandomly: true
SpawnHeight: randomY
MinHeight: 82
MaxHeight: 82
MaxBranchDepth: 50
ExcludedBiomes: All
SourceBlocks: AIR
MaxPercentageOutsideSourceBlock: 100
OutsideSourceBlock: placeAnyway
Block(-2,-1,-6,GRASS_PATH:0)
Block(1,-1,-6,GRASS_PATH:0)
Block(-3,-1,-5,GRASS_PATH:0)
Block(-2,-1,-5,GRASS_PATH:0)
Block(-1,-1,-5,GRASS_PATH:0)
Block(0,-1,-5,GRASS_PATH:0)
Block(1,-1,-5,GRASS_PATH:0)
Block(2,-1,-5,GRASS_PATH:0)
Block(-4,-1,-4,GRASS_PATH:0)
Block(-3,-1,-4,GRASS_PATH:0)
Block(-2,-1,-4,GRASS_PATH:0)
Block(-1,-1,-4,GRASS_PATH:0)
Block(0,-1,-4,GRASS_PATH:0)
Block(1,-1,-4,GRASS_PATH:0)
Block(2,-1,-4,GRASS_PATH:0)
Block(3,-1,-4,GRASS_PATH:0)
Block(4,-1,-4,GRASS_PATH:0)
Block(-5,-1,-3,GRASS_PATH:0)
Block(-4,-1,-3,COBBLESTONE:0)
Block(-3,-1,-3,GRASS_PATH:0)
Block(-2,-1,-3,GRASS_PATH:0)
Block(-1,-1,-3,COBBLESTONE:0)
Block(0,-1,-3,GRASS_PATH:0)
Block(1,-1,-3,GRASS_PATH:0)
Block(2,-1,-3,COBBLESTONE:0)
Block(3,-1,-3,GRASS_PATH:0)
Block(4,-1,-3,GRASS_PATH:0)
Block(-6,-1,-2,GRASS_PATH:0)
Block(-5,-1,-2,GRASS_PATH:0)
Block(-4,-1,-2,GRASS_PATH:0)
Block(-3,-1,-2,COBBLESTONE:0)
Block(-2,-1,-2,COBBLESTONE:0)
Block(-1,-1,-2,COBBLESTONE:0)
Block(0,-1,-2,COBBLESTONE:0)
Block(1,-1,-2,COBBLESTONE:0)
Block(2,-1,-2,GRASS_PATH:0)
Block(3,-1,-2,GRASS_PATH:0)
Block(-6,-1,-1,GRASS_PATH:0)
Block(-5,-1,-1,GRASS_PATH:0)
Block(-4,-1,-1,GRASS_PATH:0)
Block(-3,-1,-1,COBBLESTONE:0)
Block(-2,-1,-1,LOG:3)
Block(-1,-1,-1,COBBLESTONE:0)
Block(0,-1,-1,LOG:3)
Block(1,-1,-1,COBBLESTONE:0)
Block(2,-1,-1,GRASS_PATH:0)
Block(3,-1,-1,GRASS_PATH:0)
Block(4,-1,-1,GRASS_PATH:0)
Block(-6,-1,0,GRASS_PATH:0)
Block(-5,-1,0,GRASS_PATH:0)
Block(-4,-1,0,COBBLESTONE:0)
Block(-3,-1,0,COBBLESTONE:0)
Block(-2,-1,0,COBBLESTONE:0)
Block(-1,-1,0,COBBLESTONE:0)
Block(0,-1,0,COBBLESTONE:0)
Block(1,-1,0,COBBLESTONE:0)
Block(2,-1,0,COBBLESTONE:0)
Block(3,-1,0,GRASS_PATH:0)
Block(4,-1,0,GRASS_PATH:0)
Block(-6,-1,1,GRASS_PATH:0)
Block(-5,-1,1,GRASS_PATH:0)
Block(-4,-1,1,GRASS_PATH:0)
Block(-3,-1,1,COBBLESTONE:0)
Block(-2,-1,1,LOG:3)
Block(-1,-1,1,COBBLESTONE:0)
Block(0,-1,1,LOG:3)
Block(1,-1,1,COBBLESTONE:0)
Block(2,-1,1,GRASS_PATH:0)
Block(3,-1,1,GRASS_PATH:0)
Block(4,-1,1,GRASS_PATH:0)
Block(-6,-1,2,GRASS_PATH:0)
Block(-5,-1,2,GRASS_PATH:0)
Block(-4,-1,2,GRASS_PATH:0)
Block(-3,-1,2,COBBLESTONE:0)
Block(-2,-1,2,COBBLESTONE:0)
Block(-1,-1,2,COBBLESTONE:0)
Block(0,-1,2,COBBLESTONE:0)
Block(1,-1,2,COBBLESTONE:0)
Block(2,-1,2,GRASS_PATH:0)
Block(3,-1,2,GRASS_PATH:0)
Block(4,-1,2,GRASS_PATH:0)
Block(5,-1,2,GRASS_PATH:0)
Block(-5,-1,3,GRASS_PATH:0)
Block(-4,-1,3,COBBLESTONE:0)
Block(-3,-1,3,GRASS_PATH:0)
Block(-2,-1,3,GRASS_PATH:0)
Block(-1,-1,3,COBBLESTONE:0)
Block(0,-1,3,GRASS_PATH:0)
Block(1,-1,3,GRASS_PATH:0)
Block(2,-1,3,COBBLESTONE:0)
Block(3,-1,3,GRASS_PATH:0)
Block(4,-1,3,GRASS_PATH:0)
Block(-5,-1,4,GRASS_PATH:0)
Block(-4,-1,4,GRASS_PATH:0)
Block(-3,-1,4,GRASS_PATH:0)
Block(-2,-1,4,GRASS_PATH:0)
Block(-1,-1,4,GRASS_PATH:0)
Block(0,-1,4,GRASS_PATH:0)
Block(1,-1,4,GRASS_PATH:0)
Block(2,-1,4,GRASS_PATH:0)
Block(3,-1,4,GRASS_PATH:0)
Block(-4,-1,5,GRASS_PATH:0)
Block(-3,-1,5,GRASS_PATH:0)
Block(-2,-1,5,GRASS_PATH:0)
Block(-1,-1,5,GRASS_PATH:0)
Block(0,-1,5,GRASS_PATH:0)
Block(1,-1,5,GRASS_PATH:0)
Block(2,-1,5,GRASS_PATH:0)
Block(-2,-1,6,GRASS_PATH:0)
Block(-1,-1,6,GRASS_PATH:0)
Block(-4,0,-3,LOG:3)
Block(-1,0,-3,SPRUCE_FENCE:0)
Block(2,0,-3,LOG:3)
Block(-3,0,-1,AIR)
Entity(-3,0,-1,VILLAGER,1,../JungleNBT/entities/tribalnative.txt)
Block(-2,0,-1,LOG:3)
Block(-1,0,-1,CAULDRON:3)
Block(0,0,-1,LOG:3)
Block(1,0,-1,AIR)
Entity(1,0,-1,VILLAGER,1,../JungleNBT/entities/tribalnative.txt)
Block(-4,0,0,SPRUCE_FENCE:0)
Block(-2,0,0,CAULDRON:3)
Block(-1,0,0,HOPPER:0)
Block(0,0,0,CAULDRON:3)
Block(2,0,0,SPRUCE_FENCE:0)
Block(-2,0,1,LOG:3)
Block(-1,0,1,CAULDRON:3)
Block(0,0,1,LOG:3)
Block(0,0,2,AIR)
Entity(0,0,2,VILLAGER,1,../JungleNBT/entities/tribalnative.txt)
Block(-4,0,3,LOG:3)
Block(-1,0,3,SPRUCE_FENCE:0)
Block(2,0,3,LOG:3)
Block(-4,1,-3,LOG:3)
Block(-1,1,-3,SPRUCE_FENCE:0)
Block(2,1,-3,LOG:3)
Block(-2,1,-1,LOG:3)
Block(0,1,-1,LOG:3)
Block(-4,1,0,SPRUCE_FENCE:0)
Block(-1,1,0,COBBLESTONE_WALL:0)
Block(2,1,0,SPRUCE_FENCE:0)
Block(-2,1,1,LOG:3)
Block(0,1,1,LOG:3)
Block(-4,1,3,LOG:3)
Block(-1,1,3,SPRUCE_FENCE:0)
Block(2,1,3,LOG:3)
Block(-4,2,-3,LOG:3)
Block(-1,2,-3,SPRUCE_FENCE:0)
Block(2,2,-3,LOG:3)
Block(-2,2,-1,LOG:3)
Block(0,2,-1,LOG:3)
Block(-4,2,0,SPRUCE_FENCE:0)
Block(-1,2,0,COBBLESTONE_WALL:0)
Block(2,2,0,SPRUCE_FENCE:0)
Block(-2,2,1,LOG:3)
Block(0,2,1,LOG:3)
Block(-4,2,3,LOG:3)
Block(-1,2,3,SPRUCE_FENCE:0)
Block(2,2,3,LOG:3)
Block(-4,3,-3,LOG:3)
Block(-1,3,-3,SPRUCE_FENCE:0)
Block(2,3,-3,LOG:3)
Block(-1,3,-2,OAK_STAIRS:6)
Block(-2,3,-1,LOG:3)
Block(-1,3,-1,STONE_SLAB:0)
Block(0,3,-1,LOG:3)
Block(-4,3,0,SPRUCE_FENCE:0)
Block(-3,3,0,OAK_STAIRS:4)
Block(-2,3,0,STONE_SLAB:0)
Block(-1,3,0,COBBLESTONE_WALL:0)
Block(0,3,0,STONE_SLAB:0)
Block(1,3,0,OAK_STAIRS:5)
Block(2,3,0,SPRUCE_FENCE:0)
Block(-2,3,1,LOG:3)
Block(-1,3,1,STONE_SLAB:0)
Block(0,3,1,LOG:3)
Block(-1,3,2,OAK_STAIRS:7)
Block(-4,3,3,LOG:3)
Block(-1,3,3,SPRUCE_FENCE:0)
Block(2,3,3,LOG:3)
Block(-4,4,-3,LOG:3)
Block(-1,4,-3,SPRUCE_FENCE:0)
Block(2,4,-3,LOG:3)
Block(-1,4,-2,PLANKS:0)
Block(-2,4,-1,LOG:3)
Block(-1,4,-1,STONE_SLAB:0)
Block(0,4,-1,PLANKS:0)
Block(-4,4,0,SPRUCE_FENCE:0)
Block(-3,4,0,PLANKS:0)
Block(-2,4,0,STONE_SLAB:0)
Block(-1,4,0,COBBLESTONE_WALL:0)
Block(0,4,0,STONE_SLAB:0)
Block(1,4,0,PLANKS:0)
Block(2,4,0,SPRUCE_FENCE:0)
Block(-2,4,1,PLANKS:0)
Block(-1,4,1,STONE_SLAB:0)
Block(0,4,1,PLANKS:0)
Block(-1,4,2,PLANKS:0)
Block(-4,4,3,LOG:3)
Block(-1,4,3,SPRUCE_FENCE:0)
Block(2,4,3,LOG:3)
Block(-4,5,-3,COBBLESTONE_WALL:0)
Block(-1,5,-3,HOPPER:0)
Block(2,5,-3,COBBLESTONE_WALL:0)
Block(-2,5,-2,OAK_STAIRS:4)
Block(-1,5,-2,PLANKS:0)
Block(0,5,-2,OAK_STAIRS:5)
Block(-3,5,-1,OAK_STAIRS:6)
Block(-2,5,-1,STONE_SLAB:0)
Block(-1,5,-1,STONE_SLAB:0)
Block(0,5,-1,STONE_SLAB:0)
Block(1,5,-1,OAK_STAIRS:6)
Block(-4,5,0,HOPPER:0)
Block(-3,5,0,PLANKS:0)
Block(-2,5,0,STONE_SLAB:0)
Block(-1,5,0,COBBLESTONE_WALL:0)
Block(0,5,0,STONE_SLAB:0)
Block(1,5,0,PLANKS:0)
Block(2,5,0,HOPPER:0)
Block(-3,5,1,OAK_STAIRS:7)
Block(-2,5,1,STONE_SLAB:0)
Block(-1,5,1,STONE_SLAB:0)
Block(0,5,1,STONE_SLAB:0)
Block(1,5,1,OAK_STAIRS:7)
Block(-2,5,2,OAK_STAIRS:4)
Block(-1,5,2,PLANKS:0)
Block(0,5,2,OAK_STAIRS:5)
Block(-4,5,3,COBBLESTONE_WALL:0)
Block(-1,5,3,HOPPER:0)
Block(2,5,3,COBBLESTONE_WALL:0)
Block(-4,6,-3,COBBLESTONE_WALL:0)
Block(-3,6,-3,WOODEN_SLAB:9)
Block(-2,6,-3,OAK_STAIRS:4)
Block(-1,6,-3,STAINED_HARDENED_CLAY:3)
Block(0,6,-3,OAK_STAIRS:5)
Block(1,6,-3,WOODEN_SLAB:9)
Block(2,6,-3,COBBLESTONE_WALL:0)
Block(-4,6,-2,WOODEN_SLAB:9)
Block(-3,6,-2,DOUBLE_WOODEN_SLAB:1)
Block(-2,6,-2,PLANKS:0)
Block(-1,6,-2,PLANKS:0)
Block(0,6,-2,PLANKS:0)
Block(1,6,-2,DOUBLE_WOODEN_SLAB:1)
Block(2,6,-2,WOODEN_SLAB:9)
Block(-4,6,-1,OAK_STAIRS:6)
Block(-3,6,-1,PLANKS:0)
Block(-2,6,-1,WATER:0)
Block(-1,6,-1,WATER:0)
Block(0,6,-1,WATER:0)
Block(1,6,-1,PLANKS:0)
Block(2,6,-1,OAK_STAIRS:6)
Block(-4,6,0,STAINED_HARDENED_CLAY:3)
Block(-3,6,0,PLANKS:0)
Block(-2,6,0,WATER:0)
Block(-1,6,0,HOPPER:0)
Block(0,6,0,WATER:0)
Block(1,6,0,PLANKS:0)
Block(2,6,0,STAINED_HARDENED_CLAY:3)
Block(-4,6,1,OAK_STAIRS:7)
Block(-3,6,1,PLANKS:0)
Block(-2,6,1,WATER:0)
Block(-1,6,1,WATER:0)
Block(0,6,1,WATER:0)
Block(1,6,1,PLANKS:0)
Block(2,6,1,OAK_STAIRS:7)
Block(-4,6,2,WOODEN_SLAB:9)
Block(-3,6,2,DOUBLE_WOODEN_SLAB:1)
Block(-2,6,2,PLANKS:0)
Block(-1,6,2,PLANKS:0)
Block(0,6,2,PLANKS:0)
Block(1,6,2,DOUBLE_WOODEN_SLAB:1)
Block(2,6,2,WOODEN_SLAB:9)
Block(-4,6,3,COBBLESTONE_WALL:0)
Block(-3,6,3,WOODEN_SLAB:9)
Block(-2,6,3,OAK_STAIRS:4)
Block(-1,6,3,STAINED_HARDENED_CLAY:3)
Block(0,6,3,OAK_STAIRS:5)
Block(1,6,3,WOODEN_SLAB:9)
Block(2,6,3,COBBLESTONE_WALL:0)
RandomBlock(-1,7,-4,WALL_BANNER:2,../JungleNBT/banners/JungleBanner01.nbt,8,WALL_BANNER:2,../JungleNBT/banners/JungleBanner02.nbt,8,WALL_BANNER:2,../JungleNBT/banners/JungleBanner03.nbt,8,WALL_BANNER:2,../JungleNBT/banners/JungleBanner04.nbt,8,WALL_BANNER:2,../JungleNBT/banners/JungleBanner05.nbt,8,WALL_BANNER:2,../JungleNBT/banners/JungleBanner06.nbt,8,WALL_BANNER:2,../JungleNBT/banners/JungleBanner07.nbt,8,WALL_BANNER:2,../JungleNBT/banners/JungleBanner08.nbt,8,WALL_BANNER:2,../JungleNBT/banners/JungleBanner09.nbt,8,WALL_BANNER:2,../JungleNBT/banners/JungleBanner10.nbt,8,WALL_BANNER:2,../JungleNBT/banners/JungleBanner11.nbt,8,WALL_BANNER:2,../JungleNBT/banners/JungleBanner12.nbt,8,WALL_BANNER:2,../JungleNBT/banners/JungleBanner13.nbt,8,WALL_BANNER:2,../JungleNBT/banners/JungleBanner14.nbt,8,WALL_BANNER:2,../JungleNBT/banners/JungleBanner15.nbt,8,WALL_BANNER:2,../JungleNBT/banners/JungleBanner16.nbt,8,WALL_BANNER:2,../JungleNBT/banners/JungleBanner17.nbt,8,WALL_BANNER:2,../JungleNBT/banners/JungleBanner18.nbt,8,WALL_BANNER:2,../JungleNBT/banners/JungleBanner19.nbt,8,WALL_BANNER:2,../JungleNBT/banners/JungleBanner20.nbt,100)
Block(-4,7,-3,COBBLESTONE_WALL:0)
Block(-3,7,-3,STAINED_HARDENED_CLAY:3)
Block(-2,7,-3,STAINED_HARDENED_CLAY:3)
Block(-1,7,-3,STAINED_HARDENED_CLAY:3)
Block(0,7,-3,STAINED_HARDENED_CLAY:3)
Block(1,7,-3,STAINED_HARDENED_CLAY:3)
Block(2,7,-3,COBBLESTONE_WALL:0)
Block(-4,7,-2,STAINED_HARDENED_CLAY:3)
Block(-3,7,-2,STAINED_HARDENED_CLAY:3)
Block(-2,7,-2,WATER:0)
Block(-1,7,-2,WATER:0)
Block(0,7,-2,WATER:0)
Block(1,7,-2,STAINED_HARDENED_CLAY:3)
Block(2,7,-2,STAINED_HARDENED_CLAY:3)
Block(-4,7,-1,STAINED_HARDENED_CLAY:3)
Block(-3,7,-1,WATER:0)
Block(-2,7,-1,WATER:0)
Block(-1,7,-1,WATER:0)
Block(0,7,-1,WATER:0)
Block(1,7,-1,WATER:0)
Block(2,7,-1,STAINED_HARDENED_CLAY:3)
RandomBlock(-5,7,0,WALL_BANNER:4,../JungleNBT/banners/JungleBanner01.nbt,8,WALL_BANNER:4,../JungleNBT/banners/JungleBanner02.nbt,8,WALL_BANNER:4,../JungleNBT/banners/JungleBanner03.nbt,8,WALL_BANNER:4,../JungleNBT/banners/JungleBanner04.nbt,8,WALL_BANNER:4,../JungleNBT/banners/JungleBanner05.nbt,8,WALL_BANNER:4,../JungleNBT/banners/JungleBanner06.nbt,8,WALL_BANNER:4,../JungleNBT/banners/JungleBanner07.nbt,8,WALL_BANNER:4,../JungleNBT/banners/JungleBanner08.nbt,8,WALL_BANNER:4,../JungleNBT/banners/JungleBanner09.nbt,8,WALL_BANNER:4,../JungleNBT/banners/JungleBanner10.nbt,8,WALL_BANNER:4,../JungleNBT/banners/JungleBanner11.nbt,8,WALL_BANNER:4,../JungleNBT/banners/JungleBanner12.nbt,8,WALL_BANNER:4,../JungleNBT/banners/JungleBanner13.nbt,8,WALL_BANNER:4,../JungleNBT/banners/JungleBanner14.nbt,8,WALL_BANNER:4,../JungleNBT/banners/JungleBanner15.nbt,8,WALL_BANNER:4,../JungleNBT/banners/JungleBanner16.nbt,8,WALL_BANNER:4,../JungleNBT/banners/JungleBanner17.nbt,8,WALL_BANNER:4,../JungleNBT/banners/JungleBanner18.nbt,8,WALL_BANNER:4,../JungleNBT/banners/JungleBanner19.nbt,8,WALL_BANNER:4,../JungleNBT/banners/JungleBanner20.nbt,100)
Block(-4,7,0,STAINED_HARDENED_CLAY:3)
Block(-3,7,0,WATER:0)
Block(-2,7,0,WATER:0)
Block(-1,7,0,WATER:0)
Block(0,7,0,WATER:0)
Block(1,7,0,WATER:0)
Block(2,7,0,STAINED_HARDENED_CLAY:3)
RandomBlock(3,7,0,WALL_BANNER:5,../JungleNBT/banners/JungleBanner01.nbt,8,WALL_BANNER:5,../JungleNBT/banners/JungleBanner02.nbt,8,WALL_BANNER:5,../JungleNBT/banners/JungleBanner03.nbt,8,WALL_BANNER:5,../JungleNBT/banners/JungleBanner04.nbt,8,WALL_BANNER:5,../JungleNBT/banners/JungleBanner05.nbt,8,WALL_BANNER:5,../JungleNBT/banners/JungleBanner06.nbt,8,WALL_BANNER:5,../JungleNBT/banners/JungleBanner07.nbt,8,WALL_BANNER:5,../JungleNBT/banners/JungleBanner08.nbt,8,WALL_BANNER:5,../JungleNBT/banners/JungleBanner09.nbt,8,WALL_BANNER:5,../JungleNBT/banners/JungleBanner10.nbt,8,WALL_BANNER:5,../JungleNBT/banners/JungleBanner11.nbt,8,WALL_BANNER:5,../JungleNBT/banners/JungleBanner12.nbt,8,WALL_BANNER:5,../JungleNBT/banners/JungleBanner13.nbt,8,WALL_BANNER:5,../JungleNBT/banners/JungleBanner14.nbt,8,WALL_BANNER:5,../JungleNBT/banners/JungleBanner15.nbt,8,WALL_BANNER:5,../JungleNBT/banners/JungleBanner16.nbt,8,WALL_BANNER:5,../JungleNBT/banners/JungleBanner17.nbt,8,WALL_BANNER:5,../JungleNBT/banners/JungleBanner18.nbt,8,WALL_BANNER:5,../JungleNBT/banners/JungleBanner19.nbt,8,WALL_BANNER:5,../JungleNBT/banners/JungleBanner20.nbt,100)
Block(-4,7,1,STAINED_HARDENED_CLAY:3)
Block(-3,7,1,WATER:0)
Block(-2,7,1,WATER:0)
Block(-1,7,1,WATER:0)
Block(0,7,1,WATER:0)
Block(1,7,1,WATER:0)
Block(2,7,1,STAINED_HARDENED_CLAY:3)
Block(-4,7,2,STAINED_HARDENED_CLAY:3)
Block(-3,7,2,STAINED_HARDENED_CLAY:3)
Block(-2,7,2,WATER:0)
Block(-1,7,2,WATER:0)
Block(0,7,2,WATER:0)
Block(1,7,2,STAINED_HARDENED_CLAY:3)
Block(2,7,2,STAINED_HARDENED_CLAY:3)
Block(-4,7,3,COBBLESTONE_WALL:0)
Block(-3,7,3,STAINED_HARDENED_CLAY:3)
Block(-2,7,3,STAINED_HARDENED_CLAY:3)
Block(-1,7,3,STAINED_HARDENED_CLAY:3)
Block(0,7,3,STAINED_HARDENED_CLAY:3)
Block(1,7,3,STAINED_HARDENED_CLAY:3)
Block(2,7,3,COBBLESTONE_WALL:0)
RandomBlock(-1,7,4,WALL_BANNER:3,../JungleNBT/banners/JungleBanner01.nbt,8,WALL_BANNER:3,../JungleNBT/banners/JungleBanner02.nbt,8,WALL_BANNER:3,../JungleNBT/banners/JungleBanner03.nbt,8,WALL_BANNER:3,../JungleNBT/banners/JungleBanner04.nbt,8,WALL_BANNER:3,../JungleNBT/banners/JungleBanner05.nbt,8,WALL_BANNER:3,../JungleNBT/banners/JungleBanner06.nbt,8,WALL_BANNER:3,../JungleNBT/banners/JungleBanner07.nbt,8,WALL_BANNER:3,../JungleNBT/banners/JungleBanner08.nbt,8,WALL_BANNER:3,../JungleNBT/banners/JungleBanner09.nbt,8,WALL_BANNER:3,../JungleNBT/banners/JungleBanner10.nbt,8,WALL_BANNER:3,../JungleNBT/banners/JungleBanner11.nbt,8,WALL_BANNER:3,../JungleNBT/banners/JungleBanner12.nbt,8,WALL_BANNER:3,../JungleNBT/banners/JungleBanner13.nbt,8,WALL_BANNER:3,../JungleNBT/banners/JungleBanner14.nbt,8,WALL_BANNER:3,../JungleNBT/banners/JungleBanner15.nbt,8,WALL_BANNER:3,../JungleNBT/banners/JungleBanner16.nbt,8,WALL_BANNER:3,../JungleNBT/banners/JungleBanner17.nbt,8,WALL_BANNER:3,../JungleNBT/banners/JungleBanner18.nbt,8,WALL_BANNER:3,../JungleNBT/banners/JungleBanner19.nbt,8,WALL_BANNER:3,../JungleNBT/banners/JungleBanner20.nbt,100)
Block(-4,8,-3,TORCH:5)
Block(-3,8,-3,STAINED_HARDENED_CLAY:3)
Block(-2,8,-3,STAINED_HARDENED_CLAY:3)
Block(-1,8,-3,STAINED_HARDENED_CLAY:3)
Block(0,8,-3,STAINED_HARDENED_CLAY:3)
Block(1,8,-3,STAINED_HARDENED_CLAY:3)
Block(2,8,-3,TORCH:5)
Block(-4,8,-2,STAINED_HARDENED_CLAY:3)
Block(-3,8,-2,STAINED_HARDENED_CLAY:3)
Block(-2,8,-2,WATER:0)
Block(-1,8,-2,WATER:0)
Block(0,8,-2,WATER:0)
Block(1,8,-2,STAINED_HARDENED_CLAY:3)
Block(2,8,-2,STAINED_HARDENED_CLAY:3)
Block(-4,8,-1,STAINED_HARDENED_CLAY:3)
Block(-3,8,-1,WATER:0)
Block(-2,8,-1,WATER:0)
Block(-1,8,-1,WATER:0)
Block(0,8,-1,WATER:0)
Block(1,8,-1,WATER:0)
Block(2,8,-1,STAINED_HARDENED_CLAY:3)
Block(-4,8,0,STAINED_HARDENED_CLAY:3)
Block(-3,8,0,WATER:0)
Block(-2,8,0,WATER:0)
Block(-1,8,0,WATER:0)
Block(0,8,0,WATER:0)
Block(1,8,0,WATER:0)
Block(2,8,0,STAINED_HARDENED_CLAY:3)
Block(-4,8,1,STAINED_HARDENED_CLAY:3)
Block(-3,8,1,WATER:0)
Block(-2,8,1,WATER:0)
Block(-1,8,1,WATER:0)
Block(0,8,1,WATER:0)
Block(1,8,1,WATER:0)
Block(2,8,1,STAINED_HARDENED_CLAY:3)
Block(-4,8,2,STAINED_HARDENED_CLAY:3)
Block(-3,8,2,STAINED_HARDENED_CLAY:3)
Block(-2,8,2,WATER:0)
Block(-1,8,2,WATER:0)
Block(0,8,2,WATER:0)
Block(1,8,2,STAINED_HARDENED_CLAY:3)
Block(2,8,2,STAINED_HARDENED_CLAY:3)
Block(-4,8,3,TORCH:5)
Block(-3,8,3,STAINED_HARDENED_CLAY:3)
Block(-2,8,3,STAINED_HARDENED_CLAY:3)
Block(-1,8,3,STAINED_HARDENED_CLAY:3)
Block(0,8,3,STAINED_HARDENED_CLAY:3)
Block(1,8,3,STAINED_HARDENED_CLAY:3)
Block(2,8,3,TORCH:5)
Block(-3,9,-3,OAK_STAIRS:2)
Block(-2,9,-3,OAK_STAIRS:2)
Block(-1,9,-3,OAK_STAIRS:2)
Block(0,9,-3,OAK_STAIRS:2)
Block(1,9,-3,OAK_STAIRS:2)
Block(-4,9,-2,OAK_STAIRS:2)
Block(-3,9,-2,OAK_STAIRS:0)
Block(-2,9,-2,WATER:0)
Block(-1,9,-2,WATER:0)
Block(0,9,-2,WATER:0)
Block(1,9,-2,OAK_STAIRS:1)
Block(2,9,-2,OAK_STAIRS:2)
Block(-4,9,-1,OAK_STAIRS:0)
Block(-3,9,-1,WATER:0)
Block(-2,9,-1,WATER:0)
Block(-1,9,-1,WATER:0)
Block(0,9,-1,WATER:0)
Block(1,9,-1,WATER:0)
Block(2,9,-1,OAK_STAIRS:1)
Block(-4,9,0,OAK_STAIRS:0)
Block(-3,9,0,WATER:0)
Block(-2,9,0,WATER:0)
Block(-1,9,0,WATER:0)
Block(0,9,0,WATER:0)
Block(1,9,0,WATER:0)
Block(2,9,0,OAK_STAIRS:1)
Block(-4,9,1,OAK_STAIRS:0)
Block(-3,9,1,WATER:0)
Block(-2,9,1,WATER:0)
Block(-1,9,1,WATER:0)
Block(0,9,1,WATER:0)
Block(1,9,1,WATER:0)
Block(2,9,1,OAK_STAIRS:1)
Block(-4,9,2,OAK_STAIRS:0)
Block(-3,9,2,OAK_STAIRS:3)
Block(-2,9,2,WATER:0)
Block(-1,9,2,WATER:0)
Block(0,9,2,WATER:0)
Block(1,9,2,OAK_STAIRS:1)
Block(2,9,2,OAK_STAIRS:3)
Block(-3,9,3,OAK_STAIRS:0)
Block(-2,9,3,OAK_STAIRS:3)
Block(-1,9,3,OAK_STAIRS:3)
Block(0,9,3,OAK_STAIRS:3)
Block(1,9,3,OAK_STAIRS:3)
Block(-2,10,-2,WOODEN_SLAB:1)
Block(-1,10,-2,WOODEN_SLAB:1)
Block(0,10,-2,WOODEN_SLAB:1)
Block(-3,10,-1,WOODEN_SLAB:1)
Block(-2,10,-1,WOODEN_SLAB:1)
Block(-1,10,-1,WOODEN_SLAB:1)
Block(0,10,-1,WOODEN_SLAB:1)
Block(1,10,-1,WOODEN_SLAB:1)
Block(-3,10,0,WOODEN_SLAB:1)
Block(-2,10,0,WOODEN_SLAB:1)
Block(-1,10,0,TRAPDOOR:2)
Block(0,10,0,WOODEN_SLAB:1)
Block(1,10,0,WOODEN_SLAB:1)
Block(-3,10,1,WOODEN_SLAB:1)
Block(-2,10,1,WOODEN_SLAB:1)
Block(-1,10,1,WOODEN_SLAB:1)
Block(0,10,1,WOODEN_SLAB:1)
Block(1,10,1,WOODEN_SLAB:1)
Block(-2,10,2,WOODEN_SLAB:1)
Block(-1,10,2,WOODEN_SLAB:1)
Block(0,10,2,WOODEN_SLAB:1)
