Author: BO3 BulkEdit (by LanToaster)
Description: This Object was Created with BO3_BulkEdit
Version: 3
SettingsMode: WriteDisable
Tree: false
Frequency: 100
Rarity: 100
RotateRandomly: true
SpawnHeight: randomY
MinHeight: 82
MaxHeight: 82
MaxBranchDepth: 50
ExcludedBiomes: All
SourceBlocks: AIR
MaxPercentageOutsideSourceBlock: 100
OutsideSourceBlock: placeAnyway
Block(-1,-1,-8,LOG:3)
Block(-7,-1,-7,LOG:3)
Block(-6,-1,-7,LOG:3)
Block(-5,-1,-7,HARDENED_CLAY:0)
Block(-4,-1,-7,HARDENED_CLAY:0)
Block(-3,-1,-7,HARDENED_CLAY:0)
Block(-2,-1,-7,HARDENED_CLAY:0)
Block(-1,-1,-7,LOG:3)
Block(1,-1,-7,LOG:3)
Block(6,-1,-7,LOG:3)
Block(-6,-1,-6,HARDENED_CLAY:0)
Block(-5,-1,-6,HARDENED_CLAY:0)
Block(-4,-1,-6,HARDENED_CLAY:0)
Block(-3,-1,-6,HARDENED_CLAY:0)
Block(-2,-1,-6,HARDENED_CLAY:0)
Block(-1,-1,-6,HARDENED_CLAY:0)
Block(-6,-1,-5,HARDENED_CLAY:0)
Block(-5,-1,-5,HARDENED_CLAY:0)
Block(-4,-1,-5,STAINED_HARDENED_CLAY:7)
Block(-3,-1,-5,HARDENED_CLAY:0)
Block(-2,-1,-5,STAINED_HARDENED_CLAY:7)
Block(-1,-1,-5,HARDENED_CLAY:0)
Block(-6,-1,-4,HARDENED_CLAY:0)
Block(-5,-1,-4,HARDENED_CLAY:0)
Block(-4,-1,-4,HARDENED_CLAY:0)
Block(-3,-1,-4,STAINED_HARDENED_CLAY:7)
Block(-2,-1,-4,HARDENED_CLAY:0)
Block(-1,-1,-4,HARDENED_CLAY:0)
Block(-6,-1,-3,HARDENED_CLAY:0)
Block(-5,-1,-3,BRICK_BLOCK:0)
Block(-4,-1,-3,HARDENED_CLAY:0)
Block(-3,-1,-3,STAINED_HARDENED_CLAY:7)
Block(-2,-1,-3,STAINED_HARDENED_CLAY:7)
Block(-1,-1,-3,LOG:3)
Block(0,-1,-3,LOG:3)
Block(6,-1,-3,LOG:3)
Block(-6,-1,-2,HARDENED_CLAY:0)
Block(-5,-1,-2,BRICK_BLOCK:0)
Block(-4,-1,-2,BRICK_BLOCK:0)
Block(-3,-1,-2,STAINED_HARDENED_CLAY:7)
Block(-2,-1,-2,BRICK_BLOCK:0)
Block(-1,-1,-2,HARDENED_CLAY:0)
Block(-7,-1,-1,LOG:3)
Block(-6,-1,-1,LOG:3)
Block(-5,-1,-1,HARDENED_CLAY:0)
Block(-4,-1,-1,HARDENED_CLAY:0)
Block(-3,-1,-1,STAINED_HARDENED_CLAY:7)
Block(-2,-1,-1,STAINED_HARDENED_CLAY:7)
Block(-1,-1,-1,HARDENED_CLAY:0)
Block(1,-1,-1,LOG:3)
Block(-6,-1,0,HARDENED_CLAY:0)
Block(-5,-1,0,BRICK_BLOCK:0)
Block(-4,-1,0,HARDENED_CLAY:0)
Block(-3,-1,0,STAINED_HARDENED_CLAY:7)
Block(-2,-1,0,HARDENED_CLAY:0)
Block(-1,-1,0,HARDENED_CLAY:0)
Block(-6,-1,1,HARDENED_CLAY:0)
Block(-5,-1,1,BRICK_BLOCK:0)
Block(-4,-1,1,STAINED_HARDENED_CLAY:7)
Block(-3,-1,1,STAINED_HARDENED_CLAY:7)
Block(-2,-1,1,HARDENED_CLAY:0)
Block(-1,-1,1,HARDENED_CLAY:0)
Block(-6,-1,2,HARDENED_CLAY:0)
Block(-5,-1,2,HARDENED_CLAY:0)
Block(-4,-1,2,HARDENED_CLAY:0)
Block(-3,-1,2,STAINED_HARDENED_CLAY:7)
Block(-2,-1,2,HARDENED_CLAY:0)
Block(-1,-1,2,LOG:3)
Block(0,-1,2,LOG:3)
Block(6,-1,2,LOG:3)
Block(-7,-1,3,LOG:3)
Block(-6,-1,3,LOG:3)
Block(-5,-1,3,BRICK_BLOCK:0)
Block(-4,-1,3,BRICK_BLOCK:0)
Block(-3,-1,3,HARDENED_CLAY:0)
Block(-2,-1,3,BRICK_BLOCK:0)
Block(-1,-1,3,HARDENED_CLAY:0)
Block(-6,-1,4,HARDENED_CLAY:0)
Block(-5,-1,4,HARDENED_CLAY:0)
Block(-4,-1,4,BRICK_BLOCK:0)
Block(-3,-1,4,STAINED_HARDENED_CLAY:7)
Block(-2,-1,4,BRICK_BLOCK:0)
Block(-1,-1,4,HARDENED_CLAY:0)
Block(-6,-1,5,HARDENED_CLAY:0)
Block(-5,-1,5,HARDENED_CLAY:0)
Block(-4,-1,5,HARDENED_CLAY:0)
Block(-3,-1,5,STAINED_HARDENED_CLAY:7)
Block(-2,-1,5,HARDENED_CLAY:0)
Block(-1,-1,5,HARDENED_CLAY:0)
Block(-7,-1,6,LOG:3)
Block(-6,-1,6,LOG:3)
Block(-5,-1,6,HARDENED_CLAY:0)
Block(-4,-1,6,HARDENED_CLAY:0)
Block(-3,-1,6,HARDENED_CLAY:0)
Block(-2,-1,6,HARDENED_CLAY:0)
Block(-1,-1,6,LOG:3)
Block(1,-1,6,LOG:3)
Block(6,-1,6,LOG:3)
Block(-6,-1,7,LOG:3)
Block(-1,-1,7,LOG:3)
Block(-1,0,-8,LOG:3)
Block(-7,0,-7,LOG:3)
Block(-6,0,-7,LOG:3)
Block(-5,0,-7,HARDENED_CLAY:0)
Block(-4,0,-7,STAINED_HARDENED_CLAY:7)
Block(-3,0,-7,STAINED_HARDENED_CLAY:7)
Block(-2,0,-7,STAINED_HARDENED_CLAY:7)
Block(-1,0,-7,LOG:3)
Block(1,0,-7,LOG:3)
Block(6,0,-7,LOG:3)
Block(-6,0,-6,HARDENED_CLAY:0)
Block(-5,0,-6,WATER:0)
Block(-4,0,-6,BRICK_BLOCK:0)
Block(-3,0,-6,WATER:0)
Block(-2,0,-6,WATER:0)
Block(-1,0,-6,HARDENED_CLAY:0)
Block(-6,0,-5,HARDENED_CLAY:0)
Block(-5,0,-5,WATER:0)
Block(-4,0,-5,WOODEN_SLAB:11)
Block(-3,0,-5,WATER:0)
Block(-2,0,-5,WATER:0)
Block(-1,0,-5,HARDENED_CLAY:0)
Block(-6,0,-4,HARDENED_CLAY:0)
Block(-5,0,-4,WATER:0)
Block(-4,0,-4,JUNGLE_STAIRS:6)
Block(-3,0,-4,WATER:0)
Block(-2,0,-4,WATER:0)
Block(-1,0,-4,HARDENED_CLAY:0)
Block(-6,0,-3,STAINED_HARDENED_CLAY:7)
Block(-5,0,-3,WATER:0)
Block(-4,0,-3,DOUBLE_WOODEN_SLAB:3)
Block(-3,0,-3,WATER:0)
Block(-2,0,-3,LOG:3)
Block(-1,0,-3,LOG:3)
Block(0,0,-3,LOG:3)
Block(6,0,-3,LOG:3)
Block(-6,0,-2,HARDENED_CLAY:0)
Block(-5,0,-2,WATER:0)
Block(-4,0,-2,DOUBLE_WOODEN_SLAB:3)
Block(-3,0,-2,WATER:0)
Block(-2,0,-2,WATER:0)
Block(-1,0,-2,HARDENED_CLAY:0)
Block(-7,0,-1,LOG:3)
Block(-6,0,-1,LOG:3)
Block(-5,0,-1,WATER:0)
Block(-4,0,-1,WOODEN_SLAB:3)
Block(-3,0,-1,WATER:0)
Block(-2,0,-1,WATER:0)
Block(-1,0,-1,STAINED_HARDENED_CLAY:7)
Block(1,0,-1,LOG:3)
Block(-6,0,0,HARDENED_CLAY:0)
Block(-5,0,0,WATER:0)
Block(-4,0,0,WOODEN_SLAB:3)
Block(-3,0,0,WATER:0)
Block(-2,0,0,WATER:0)
Block(-1,0,0,HARDENED_CLAY:0)
Block(-6,0,1,STAINED_HARDENED_CLAY:7)
Block(-5,0,1,WATER:0)
Block(-4,0,1,DOUBLE_WOODEN_SLAB:3)
Block(-3,0,1,WATER:0)
Block(-2,0,1,WATER:0)
Block(-1,0,1,HARDENED_CLAY:0)
Block(-6,0,2,HARDENED_CLAY:0)
Block(-5,0,2,WATER:0)
Block(-4,0,2,DOUBLE_WOODEN_SLAB:3)
Block(-3,0,2,WATER:0)
Block(-2,0,2,LOG:3)
Block(-1,0,2,LOG:3)
Block(0,0,2,LOG:3)
Block(6,0,2,LOG:3)
Block(-7,0,3,LOG:3)
Block(-6,0,3,LOG:3)
Block(-5,0,3,WATER:0)
Block(-4,0,3,JUNGLE_STAIRS:7)
Block(-3,0,3,WATER:0)
Block(-2,0,3,WATER:0)
Block(-1,0,3,STAINED_HARDENED_CLAY:7)
Block(-6,0,4,HARDENED_CLAY:0)
Block(-5,0,4,WATER:0)
Block(-4,0,4,WOODEN_SLAB:11)
Block(-3,0,4,WATER:0)
Block(-2,0,4,WATER:0)
Block(-1,0,4,STAINED_HARDENED_CLAY:7)
Block(-6,0,5,HARDENED_CLAY:0)
Block(-5,0,5,WATER:0)
Block(-4,0,5,BRICK_BLOCK:0)
Block(-3,0,5,WATER:0)
Block(-2,0,5,WATER:0)
Block(-1,0,5,HARDENED_CLAY:0)
Block(-7,0,6,LOG:3)
Block(-6,0,6,LOG:3)
Block(-5,0,6,HARDENED_CLAY:0)
Block(-4,0,6,STAINED_HARDENED_CLAY:7)
Block(-3,0,6,STAINED_HARDENED_CLAY:7)
Block(-2,0,6,HARDENED_CLAY:0)
Block(-1,0,6,LOG:3)
Block(1,0,6,LOG:3)
Block(6,0,6,LOG:3)
Block(-6,0,7,LOG:3)
Block(-1,0,7,LOG:3)
Block(-1,1,-8,OAK_STAIRS:2)
Block(-7,1,-7,OAK_STAIRS:0)
Block(-6,1,-7,LOG:3)
Block(-5,1,-7,STAINED_HARDENED_CLAY:7)
Block(-4,1,-7,HARDENED_CLAY:0)
Block(-3,1,-7,HARDENED_CLAY:0)
Block(-2,1,-7,HARDENED_CLAY:0)
Block(-1,1,-7,LOG:3)
Block(1,1,-7,LOG:3)
Block(2,1,-7,OAK_STAIRS:5)
Block(5,1,-7,OAK_STAIRS:4)
Block(6,1,-7,LOG:3)
Block(-6,1,-6,STAINED_HARDENED_CLAY:7)
Block(-4,1,-6,DOUBLE_WOODEN_SLAB:3)
Block(-1,1,-6,HARDENED_CLAY:0)
Block(1,1,-6,OAK_STAIRS:7)
Block(-6,1,-5,HARDENED_CLAY:0)
Block(-4,1,-5,WOODEN_SLAB:3)
Block(-1,1,-5,STAINED_HARDENED_CLAY:7)
Block(-6,1,-4,HARDENED_CLAY:0)
Block(-4,1,-4,WOODEN_SLAB:3)
Block(-1,1,-4,STAINED_HARDENED_CLAY:7)
Block(-6,1,-3,STAINED_HARDENED_CLAY:7)
Block(-4,1,-3,BRICK_BLOCK:0)
Block(-2,1,-3,LOG:3)
Block(-1,1,-3,LOG:3)
Block(0,1,-3,OAK_STAIRS:1)
Block(5,1,-3,OAK_STAIRS:4)
Block(6,1,-3,LOG:3)
Block(-6,1,-2,STAINED_HARDENED_CLAY:7)
Block(-1,1,-2,HARDENED_CLAY:0)
Block(1,1,-2,OAK_STAIRS:6)
Block(-7,1,-1,OAK_STAIRS:0)
Block(-6,1,-1,LOG:3)
Block(-1,1,-1,STAINED_HARDENED_CLAY:7)
Block(1,1,-1,LOG:3)
Block(-6,1,0,HARDENED_CLAY:0)
Block(-1,1,0,STAINED_HARDENED_CLAY:7)
Block(1,1,0,OAK_STAIRS:7)
Block(-6,1,1,HARDENED_CLAY:0)
Block(-1,1,1,STAINED_HARDENED_CLAY:7)
Block(-6,1,2,HARDENED_CLAY:0)
Block(-4,1,2,BRICK_BLOCK:0)
Block(-2,1,2,LOG:3)
Block(-1,1,2,LOG:3)
Block(0,1,2,OAK_STAIRS:1)
Block(5,1,2,OAK_STAIRS:4)
Block(6,1,2,LOG:3)
Block(-7,1,3,OAK_STAIRS:0)
Block(-6,1,3,LOG:3)
Block(-4,1,3,WOODEN_SLAB:3)
Block(-1,1,3,HARDENED_CLAY:0)
Block(-6,1,4,STAINED_HARDENED_CLAY:7)
Block(-4,1,4,WOODEN_SLAB:3)
Block(-1,1,4,HARDENED_CLAY:0)
Block(-6,1,5,HARDENED_CLAY:0)
Block(-4,1,5,DOUBLE_WOODEN_SLAB:3)
Block(-1,1,5,HARDENED_CLAY:0)
Block(1,1,5,OAK_STAIRS:6)
Block(6,1,5,OAK_STAIRS:6)
Block(-7,1,6,OAK_STAIRS:0)
Block(-6,1,6,LOG:3)
Block(-5,1,6,STAINED_HARDENED_CLAY:7)
Block(-4,1,6,STAINED_HARDENED_CLAY:7)
Block(-3,1,6,STAINED_HARDENED_CLAY:7)
Block(-2,1,6,HARDENED_CLAY:0)
Block(-1,1,6,LOG:3)
Block(1,1,6,LOG:3)
Block(2,1,6,OAK_STAIRS:5)
Block(5,1,6,OAK_STAIRS:4)
Block(6,1,6,LOG:3)
Block(-6,1,7,OAK_STAIRS:3)
Block(-1,1,7,OAK_STAIRS:3)
Block(-6,2,-7,WOODEN_SLAB:3)
Block(-5,2,-7,WOODEN_SLAB:3)
Block(-4,2,-7,WOODEN_SLAB:3)
Block(-3,2,-7,WOODEN_SLAB:3)
Block(-2,2,-7,WOODEN_SLAB:3)
Block(-1,2,-7,WOODEN_SLAB:3)
Block(1,2,-7,LOG:3)
Block(2,2,-7,DOUBLE_WOODEN_SLAB:3)
Block(3,2,-7,WOODEN_SLAB:11)
Block(4,2,-7,WOODEN_SLAB:11)
Block(5,2,-7,DOUBLE_WOODEN_SLAB:3)
Block(6,2,-7,LOG:3)
Block(-6,2,-6,WOODEN_SLAB:3)
Block(-4,2,-6,JUNGLE_FENCE:0)
Block(-1,2,-6,WOODEN_SLAB:3)
Block(1,2,-6,LOG:11)
Block(2,2,-6,WOODEN_SLAB:11)
Block(3,2,-6,WOODEN_SLAB:11)
Block(4,2,-6,WOODEN_SLAB:11)
Block(5,2,-6,WOODEN_SLAB:11)
Block(6,2,-6,LOG:11)
Block(-6,2,-5,WOODEN_SLAB:3)
Block(-1,2,-5,WOODEN_SLAB:3)
Block(1,2,-5,LOG:11)
Block(2,2,-5,WOODEN_SLAB:11)
Block(3,2,-5,WOODEN_SLAB:11)
Block(4,2,-5,WOODEN_SLAB:11)
Block(5,2,-5,WOODEN_SLAB:11)
Block(6,2,-5,LOG:11)
Block(-6,2,-4,WOODEN_SLAB:3)
Block(-1,2,-4,WOODEN_SLAB:3)
Block(1,2,-4,LOG:11)
Block(2,2,-4,WOODEN_SLAB:11)
Block(3,2,-4,WOODEN_SLAB:11)
Block(4,2,-4,WOODEN_SLAB:11)
Block(5,2,-4,WOODEN_SLAB:11)
Block(6,2,-4,LOG:11)
Block(-6,2,-3,WOODEN_SLAB:3)
Block(-2,2,-3,OAK_STAIRS:0)
Block(-1,2,-3,DOUBLE_WOODEN_SLAB:3)
Block(0,2,-3,WOODEN_SLAB:11)
Block(1,2,-3,LOG:11)
Block(2,2,-3,LOG:7)
Block(3,2,-3,LOG:7)
Block(4,2,-3,LOG:7)
Block(5,2,-3,LOG:7)
Block(6,2,-3,LOG:3)
Block(-6,2,-2,WOODEN_SLAB:3)
Block(-1,2,-2,WOODEN_SLAB:3)
Block(1,2,-2,LOG:11)
Block(2,2,-2,WOODEN_SLAB:11)
Block(3,2,-2,WOODEN_SLAB:11)
Block(4,2,-2,WOODEN_SLAB:11)
Block(5,2,-2,WOODEN_SLAB:11)
Block(6,2,-2,LOG:11)
Block(-6,2,-1,WOODEN_SLAB:3)
Block(-1,2,-1,WOODEN_SLAB:3)
Block(1,2,-1,LOG:11)
Block(2,2,-1,WOODEN_SLAB:11)
Block(3,2,-1,WOODEN_SLAB:11)
Block(4,2,-1,WOODEN_SLAB:11)
Block(5,2,-1,WOODEN_SLAB:11)
Block(6,2,-1,LOG:11)
Block(-6,2,0,WOODEN_SLAB:3)
Block(-1,2,0,WOODEN_SLAB:3)
Block(1,2,0,LOG:11)
Block(2,2,0,WOODEN_SLAB:11)
Block(3,2,0,WOODEN_SLAB:11)
Block(4,2,0,WOODEN_SLAB:11)
Block(5,2,0,WOODEN_SLAB:11)
Block(6,2,0,LOG:11)
Block(-6,2,1,WOODEN_SLAB:3)
Block(-1,2,1,WOODEN_SLAB:3)
Block(1,2,1,LOG:11)
Block(2,2,1,WOODEN_SLAB:11)
Block(3,2,1,WOODEN_SLAB:11)
Block(4,2,1,WOODEN_SLAB:11)
Block(5,2,1,WOODEN_SLAB:11)
Block(6,2,1,LOG:11)
Block(-6,2,2,WOODEN_SLAB:3)
Block(-2,2,2,OAK_STAIRS:0)
Block(-1,2,2,DOUBLE_WOODEN_SLAB:3)
Block(0,2,2,WOODEN_SLAB:11)
Block(1,2,2,LOG:7)
Block(2,2,2,LOG:7)
Block(3,2,2,LOG:7)
Block(4,2,2,LOG:7)
Block(5,2,2,LOG:7)
Block(6,2,2,LOG:3)
Block(-6,2,3,WOODEN_SLAB:3)
Block(-1,2,3,WOODEN_SLAB:3)
Block(1,2,3,LOG:11)
Block(2,2,3,WOODEN_SLAB:11)
Block(3,2,3,WOODEN_SLAB:11)
Block(4,2,3,WOODEN_SLAB:11)
Block(5,2,3,WOODEN_SLAB:11)
Block(6,2,3,LOG:11)
Block(-6,2,4,WOODEN_SLAB:3)
Block(-1,2,4,WOODEN_SLAB:3)
Block(1,2,4,LOG:11)
Block(2,2,4,WOODEN_SLAB:11)
Block(3,2,4,WOODEN_SLAB:11)
Block(4,2,4,WOODEN_SLAB:11)
Block(5,2,4,WOODEN_SLAB:11)
Block(6,2,4,LOG:11)
Block(-6,2,5,WOODEN_SLAB:3)
Block(-4,2,5,JUNGLE_FENCE:0)
Block(-1,2,5,WOODEN_SLAB:3)
Block(1,2,5,LOG:11)
Block(2,2,5,WOODEN_SLAB:11)
Block(3,2,5,WOODEN_SLAB:11)
Block(4,2,5,WOODEN_SLAB:11)
Block(5,2,5,WOODEN_SLAB:11)
Block(6,2,5,LOG:11)
Block(-6,2,6,WOODEN_SLAB:3)
Block(-5,2,6,WOODEN_SLAB:3)
Block(-4,2,6,WOODEN_SLAB:3)
Block(-3,2,6,WOODEN_SLAB:3)
Block(-2,2,6,WOODEN_SLAB:3)
Block(-1,2,6,WOODEN_SLAB:3)
Block(1,2,6,LOG:3)
Block(2,2,6,DOUBLE_WOODEN_SLAB:3)
Block(3,2,6,WOODEN_SLAB:11)
Block(4,2,6,WOODEN_SLAB:11)
Block(5,2,6,DOUBLE_WOODEN_SLAB:3)
Block(6,2,6,LOG:3)
Block(5,3,-7,AIR)
Block(2,3,-6,AIR)
Block(1,3,-3,LOG:7)
Block(2,3,-3,LOG:7)
Block(3,3,-3,LOG:7)
Block(4,3,-3,LOG:7)
Block(5,3,-3,LOG:7)
Block(6,3,-3,LOG:7)
Block(1,3,-2,WOODEN_SLAB:11)
Block(1,3,-1,WOODEN_SLAB:11)
Block(1,3,0,WOODEN_SLAB:11)
Block(1,3,1,WOODEN_SLAB:11)
Block(1,3,2,LOG:7)
Block(2,3,2,LOG:7)
Block(3,3,2,LOG:7)
Block(4,3,2,LOG:7)
Block(5,3,2,LOG:7)
Block(6,3,2,LOG:7)
Block(2,3,5,AIR)
Block(4,3,6,AIR)
Entity(4,3,6,VILLAGER,1,../JungleNBT/entities/tribalboatbuilder.txt)
Block(1,4,-6,WOODEN_SLAB:11)
Block(3,4,-6,WOODEN_SLAB:11)
Block(5,4,-6,WOODEN_SLAB:11)
Block(1,4,-5,DOUBLE_WOODEN_SLAB:3)
Block(3,4,-5,DOUBLE_WOODEN_SLAB:3)
Block(5,4,-5,WOODEN_SLAB:11)
Block(1,4,-4,WOODEN_SLAB:3)
Block(3,4,-4,WOODEN_SLAB:3)
Block(5,4,-4,WOODEN_SLAB:11)
Block(1,4,-3,WOODEN_SLAB:3)
Block(3,4,-3,WOODEN_SLAB:3)
Block(5,4,-3,WOODEN_SLAB:11)
Block(1,4,-2,WOODEN_SLAB:3)
Block(3,4,-2,WOODEN_SLAB:3)
Block(5,4,-2,WOODEN_SLAB:11)
Block(1,4,-1,BRICK_BLOCK:0)
Block(3,4,-1,WOODEN_SLAB:3)
Block(5,4,-1,WOODEN_SLAB:11)
Block(1,4,0,BRICK_BLOCK:0)
Block(3,4,0,WOODEN_SLAB:3)
Block(5,4,0,WOODEN_SLAB:11)
Block(1,4,1,WOODEN_SLAB:3)
Block(3,4,1,WOODEN_SLAB:3)
Block(5,4,1,WOODEN_SLAB:11)
Block(1,4,2,WOODEN_SLAB:3)
Block(3,4,2,WOODEN_SLAB:3)
Block(5,4,2,WOODEN_SLAB:11)
Block(1,4,3,WOODEN_SLAB:3)
Block(3,4,3,WOODEN_SLAB:3)
Block(5,4,3,WOODEN_SLAB:11)
Block(1,4,4,DOUBLE_WOODEN_SLAB:3)
Block(3,4,4,DOUBLE_WOODEN_SLAB:3)
Block(5,4,4,WOODEN_SLAB:11)
Block(1,4,5,WOODEN_SLAB:11)
Block(3,4,5,WOODEN_SLAB:11)
Block(5,4,5,WOODEN_SLAB:11)
Block(5,5,-4,BRICK_BLOCK:0)
Block(5,5,-3,BRICK_BLOCK:0)
Block(5,5,2,BRICK_BLOCK:0)
Block(5,5,3,BRICK_BLOCK:0)
