Author: BO3 BulkEdit (by LanToaster)
Description: This Object was Created with BO3_BulkEdit
Version: 3
SettingsMode: WriteDisable
Tree: false
Frequency: 100
Rarity: 100
RotateRandomly: true
SpawnHeight: randomY
MinHeight: 82
MaxHeight: 82
MaxBranchDepth: 50
ExcludedBiomes: All
SourceBlocks: AIR
MaxPercentageOutsideSourceBlock: 100
OutsideSourceBlock: placeAnyway
Block(-2,-1,-6,GRASS:0)
Block(-1,-1,-6,GRASS:0)
Block(2,-1,-6,GRASS:0)
Block(3,-1,-6,GRASS:0)
Block(4,-1,-6,GRASS:0)
Block(5,-1,-6,GRASS:0)
Block(-2,-1,-5,GRASS:0)
Block(-1,-1,-5,GRASS:0)
Block(0,-1,-5,GRASS:0)
Block(1,-1,-5,GRASS:0)
Block(2,-1,-5,GRASS:0)
Block(3,-1,-5,GRASS_PATH:0)
Block(4,-1,-5,GRASS:0)
Block(5,-1,-5,GRASS:0)
Block(-5,-1,-4,GRASS:0)
Block(-4,-1,-4,GRASS:0)
Block(-3,-1,-4,GRASS:0)
Block(-2,-1,-4,GRASS_PATH:0)
Block(-1,-1,-4,GRASS:0)
Block(0,-1,-4,DIRT:0)
Block(1,-1,-4,GRASS_PATH:0)
Block(2,-1,-4,GRASS_PATH:0)
Block(3,-1,-4,GRASS_PATH:0)
Block(4,-1,-4,GRASS_PATH:0)
Block(5,-1,-4,GRASS:0)
Block(6,-1,-4,GRASS:0)
Block(-5,-1,-3,GRASS:0)
Block(-4,-1,-3,GRASS:0)
Block(-3,-1,-3,GRASS_PATH:0)
Block(-2,-1,-3,GRASS:0)
Block(-1,-1,-3,GRASS_PATH:0)
Block(0,-1,-3,GRASS_PATH:0)
Block(1,-1,-3,GRASS_PATH:0)
Block(2,-1,-3,GRASS:0)
Block(3,-1,-3,GRASS_PATH:0)
Block(4,-1,-3,DOUBLE_STONE_SLAB:3)
Block(5,-1,-3,GRASS:0)
Block(-4,-1,-2,GRASS:0)
Block(-3,-1,-2,GRASS_PATH:0)
Block(-2,-1,-2,GRASS:0)
Block(-1,-1,-2,GRASS_PATH:0)
Block(0,-1,-2,GRASS:0)
Block(1,-1,-2,GRASS_PATH:0)
Block(2,-1,-2,GRASS:0)
Block(3,-1,-2,GRASS:0)
Block(4,-1,-2,GRASS:0)
Block(5,-1,-2,GRASS:0)
Block(-5,-1,-1,GRASS:0)
Block(-4,-1,-1,GRASS_PATH:0)
Block(-3,-1,-1,GRASS_PATH:0)
Block(-2,-1,-1,DIRT:0)
Block(-1,-1,-1,GRASS:0)
Block(0,-1,-1,DIRT:0)
Block(1,-1,-1,GRASS:0)
Block(2,-1,-1,GRASS:0)
Block(3,-1,-1,DIRT:0)
Block(4,-1,-1,GRASS:0)
Block(-6,-1,0,GRASS:0)
Block(-5,-1,0,GRASS:0)
Block(-4,-1,0,GRASS_PATH:0)
Block(-3,-1,0,GRASS:0)
Block(-2,-1,0,GRASS:0)
Block(-1,-1,0,GRASS:0)
Block(0,-1,0,GRASS:0)
Block(1,-1,0,GRASS:0)
Block(2,-1,0,GRASS:0)
Block(3,-1,0,GRASS_PATH:0)
Block(4,-1,0,GRASS_PATH:0)
Block(5,-1,0,GRASS:0)
Block(-5,-1,1,GRASS:0)
Block(-4,-1,1,GRASS:0)
Block(-3,-1,1,GRASS_PATH:0)
Block(-2,-1,1,GRASS:0)
Block(-1,-1,1,GRASS:0)
Block(0,-1,1,GRASS:0)
Block(1,-1,1,GRASS_PATH:0)
Block(2,-1,1,GRASS_PATH:0)
Block(3,-1,1,GRASS_PATH:0)
Block(4,-1,1,GRASS:0)
Block(5,-1,1,GRASS:0)
Block(-6,-1,2,GRASS:0)
Block(-5,-1,2,GRASS:0)
Block(-4,-1,2,GRASS:0)
Block(-3,-1,2,GRASS:0)
Block(-2,-1,2,GRASS:0)
Block(-1,-1,2,GRASS_PATH:0)
Block(0,-1,2,GRASS_PATH:0)
Block(1,-1,2,GRASS_PATH:0)
Block(2,-1,2,GRASS:0)
Block(3,-1,2,DOUBLE_STONE_SLAB:3)
Block(4,-1,2,GRASS:0)
Block(5,-1,2,GRASS:0)
Block(-5,-1,3,GRASS:0)
Block(-4,-1,3,GRASS:0)
Block(-3,-1,3,DOUBLE_STONE_SLAB:3)
Block(-2,-1,3,GRASS:0)
Block(-1,-1,3,GRASS:0)
Block(0,-1,3,GRASS_PATH:0)
Block(1,-1,3,GRASS:0)
Block(2,-1,3,DIRT:0)
Block(3,-1,3,GRASS:0)
Block(4,-1,3,GRASS:0)
Block(-5,-1,4,GRASS:0)
Block(-4,-1,4,GRASS:0)
Block(-3,-1,4,GRASS:0)
Block(-2,-1,4,DIRT:0)
Block(-1,-1,4,GRASS:0)
Block(0,-1,4,GRASS:0)
Block(1,-1,4,GRASS:0)
Block(3,-1,4,GRASS:0)
Block(-3,-1,5,GRASS:0)
Block(-2,-1,5,GRASS:0)
Block(-1,-1,5,GRASS:0)
Block(0,-1,5,GRASS:0)
Block(3,-1,5,GRASS:0)
Block(4,-1,5,GRASS:0)
Block(0,0,-4,AIR)
Entity(0,0,-4,VILLAGER,1,../JungleNBT/entities/tribalnative.txt)
Block(4,0,-3,JUNGLE_FENCE:0)
Block(0,0,-2,STONE_SLAB:3)
Block(-2,0,-1,AIR)
Block(-1,0,-1,STONE_SLAB:3)
Block(0,0,-1,DOUBLE_STONE_SLAB:3)
Block(1,0,-1,STONE_SLAB:3)
Block(3,0,-1,AIR)
Block(0,0,0,STONE_SLAB:3)
Block(3,0,2,JUNGLE_FENCE:0)
Block(-3,0,3,JUNGLE_FENCE:0)
Block(2,0,3,AIR)
Block(-2,0,4,AIR)
Block(4,1,-3,TORCH:5)
Block(0,1,-2,STONE_BUTTON:4)
Block(-1,1,-1,STONE_BUTTON:2)
Block(0,1,-1,LOG:3)
Block(1,1,-1,STONE_BUTTON:1)
Block(0,1,0,STONE_BUTTON:3)
Block(3,1,2,TORCH:5)
Block(-3,1,3,TORCH:5)
Block(0,2,-2,JUNGLE_FENCE_GATE:3)
Block(-1,2,-1,TRAPDOOR:6)
Block(0,2,-1,BLACK_GLAZED_TERRACOTTA:1)
Block(1,2,-1,TRAPDOOR:7)
Block(0,2,0,JUNGLE_FENCE_GATE:3)
Block(0,3,-3,JUNGLE_FENCE:0)
Block(0,3,-2,JUNGLE_STAIRS:6)
Block(-1,3,-1,STONE_BUTTON:2)
Block(0,3,-1,BLACK_GLAZED_TERRACOTTA:1)
Block(0,3,0,JUNGLE_STAIRS:7)
Block(0,3,1,JUNGLE_FENCE:0)
Block(0,4,-4,TRAPDOOR:4)
Block(0,4,-3,WOODEN_SLAB:1)
Block(0,4,-2,WOODEN_SLAB:1)
Block(-1,4,-1,TRAPDOOR:6)
Block(0,4,-1,BLACK_GLAZED_TERRACOTTA:1)
Block(1,4,-1,TRAPDOOR:7)
Block(0,4,0,WOODEN_SLAB:1)
Block(0,4,1,WOODEN_SLAB:1)
Block(0,4,2,TRAPDOOR:5)
Block(-1,5,-1,STONE_BUTTON:2)
Block(0,5,-1,GRAY_GLAZED_TERRACOTTA:1)
Block(0,6,-4,JUNGLE_FENCE:0)
Block(0,6,-2,JUNGLE_STAIRS:6)
Block(-1,6,-1,STONE_BUTTON:2)
Block(0,6,-1,GRAY_GLAZED_TERRACOTTA:1)
Block(1,6,-1,TRAPDOOR:7)
Block(0,6,0,JUNGLE_STAIRS:7)
Block(0,6,2,JUNGLE_FENCE:0)
Block(0,7,-5,TRAPDOOR:0)
Block(0,7,-4,WOODEN_SLAB:5)
Block(0,7,-3,WOODEN_SLAB:5)
RandomBlock(-1,7,-2,WALL_BANNER:4,../JungleNBT/banners/JungleBanner01.nbt,8,WALL_BANNER:4,../JungleNBT/banners/JungleBanner02.nbt,8,WALL_BANNER:4,../JungleNBT/banners/JungleBanner03.nbt,8,WALL_BANNER:4,../JungleNBT/banners/JungleBanner04.nbt,8,WALL_BANNER:4,../JungleNBT/banners/JungleBanner05.nbt,8,WALL_BANNER:4,../JungleNBT/banners/JungleBanner06.nbt,8,WALL_BANNER:4,../JungleNBT/banners/JungleBanner07.nbt,8,WALL_BANNER:4,../JungleNBT/banners/JungleBanner08.nbt,8,WALL_BANNER:4,../JungleNBT/banners/JungleBanner09.nbt,8,WALL_BANNER:4,../JungleNBT/banners/JungleBanner10.nbt,8,WALL_BANNER:4,../JungleNBT/banners/JungleBanner11.nbt,8,WALL_BANNER:4,../JungleNBT/banners/JungleBanner12.nbt,8,WALL_BANNER:4,../JungleNBT/banners/JungleBanner13.nbt,8,WALL_BANNER:4,../JungleNBT/banners/JungleBanner14.nbt,8,WALL_BANNER:4,../JungleNBT/banners/JungleBanner15.nbt,8,WALL_BANNER:4,../JungleNBT/banners/JungleBanner16.nbt,8,WALL_BANNER:4,../JungleNBT/banners/JungleBanner17.nbt,8,WALL_BANNER:4,../JungleNBT/banners/JungleBanner18.nbt,8,WALL_BANNER:4,../JungleNBT/banners/JungleBanner19.nbt,8,WALL_BANNER:4,../JungleNBT/banners/JungleBanner20.nbt,100)
Block(0,7,-2,DOUBLE_WOODEN_SLAB:5)
RandomBlock(1,7,-2,WALL_BANNER:5,../JungleNBT/banners/JungleBanner01.nbt,8,WALL_BANNER:5,../JungleNBT/banners/JungleBanner02.nbt,8,WALL_BANNER:5,../JungleNBT/banners/JungleBanner03.nbt,8,WALL_BANNER:5,../JungleNBT/banners/JungleBanner04.nbt,8,WALL_BANNER:5,../JungleNBT/banners/JungleBanner05.nbt,8,WALL_BANNER:5,../JungleNBT/banners/JungleBanner06.nbt,8,WALL_BANNER:5,../JungleNBT/banners/JungleBanner07.nbt,8,WALL_BANNER:5,../JungleNBT/banners/JungleBanner08.nbt,8,WALL_BANNER:5,../JungleNBT/banners/JungleBanner09.nbt,8,WALL_BANNER:5,../JungleNBT/banners/JungleBanner10.nbt,8,WALL_BANNER:5,../JungleNBT/banners/JungleBanner11.nbt,8,WALL_BANNER:5,../JungleNBT/banners/JungleBanner12.nbt,8,WALL_BANNER:5,../JungleNBT/banners/JungleBanner13.nbt,8,WALL_BANNER:5,../JungleNBT/banners/JungleBanner14.nbt,8,WALL_BANNER:5,../JungleNBT/banners/JungleBanner15.nbt,8,WALL_BANNER:5,../JungleNBT/banners/JungleBanner16.nbt,8,WALL_BANNER:5,../JungleNBT/banners/JungleBanner17.nbt,8,WALL_BANNER:5,../JungleNBT/banners/JungleBanner18.nbt,8,WALL_BANNER:5,../JungleNBT/banners/JungleBanner19.nbt,8,WALL_BANNER:5,../JungleNBT/banners/JungleBanner20.nbt,100)
Block(-1,7,-1,STONE_BUTTON:2)
Block(0,7,-1,RED_GLAZED_TERRACOTTA:1)
RandomBlock(-1,7,0,WALL_BANNER:4,../JungleNBT/banners/JungleBanner01.nbt,8,WALL_BANNER:4,../JungleNBT/banners/JungleBanner02.nbt,8,WALL_BANNER:4,../JungleNBT/banners/JungleBanner03.nbt,8,WALL_BANNER:4,../JungleNBT/banners/JungleBanner04.nbt,8,WALL_BANNER:4,../JungleNBT/banners/JungleBanner05.nbt,8,WALL_BANNER:4,../JungleNBT/banners/JungleBanner06.nbt,8,WALL_BANNER:4,../JungleNBT/banners/JungleBanner07.nbt,8,WALL_BANNER:4,../JungleNBT/banners/JungleBanner08.nbt,8,WALL_BANNER:4,../JungleNBT/banners/JungleBanner09.nbt,8,WALL_BANNER:4,../JungleNBT/banners/JungleBanner10.nbt,8,WALL_BANNER:4,../JungleNBT/banners/JungleBanner11.nbt,8,WALL_BANNER:4,../JungleNBT/banners/JungleBanner12.nbt,8,WALL_BANNER:4,../JungleNBT/banners/JungleBanner13.nbt,8,WALL_BANNER:4,../JungleNBT/banners/JungleBanner14.nbt,8,WALL_BANNER:4,../JungleNBT/banners/JungleBanner15.nbt,8,WALL_BANNER:4,../JungleNBT/banners/JungleBanner16.nbt,8,WALL_BANNER:4,../JungleNBT/banners/JungleBanner17.nbt,8,WALL_BANNER:4,../JungleNBT/banners/JungleBanner18.nbt,8,WALL_BANNER:4,../JungleNBT/banners/JungleBanner19.nbt,8,WALL_BANNER:4,../JungleNBT/banners/JungleBanner20.nbt,100)
Block(0,7,0,DOUBLE_WOODEN_SLAB:5)
RandomBlock(1,7,0,WALL_BANNER:5,../JungleNBT/banners/JungleBanner01.nbt,8,WALL_BANNER:5,../JungleNBT/banners/JungleBanner02.nbt,8,WALL_BANNER:5,../JungleNBT/banners/JungleBanner03.nbt,8,WALL_BANNER:5,../JungleNBT/banners/JungleBanner04.nbt,8,WALL_BANNER:5,../JungleNBT/banners/JungleBanner05.nbt,8,WALL_BANNER:5,../JungleNBT/banners/JungleBanner06.nbt,8,WALL_BANNER:5,../JungleNBT/banners/JungleBanner07.nbt,8,WALL_BANNER:5,../JungleNBT/banners/JungleBanner08.nbt,8,WALL_BANNER:5,../JungleNBT/banners/JungleBanner09.nbt,8,WALL_BANNER:5,../JungleNBT/banners/JungleBanner10.nbt,8,WALL_BANNER:5,../JungleNBT/banners/JungleBanner11.nbt,8,WALL_BANNER:5,../JungleNBT/banners/JungleBanner12.nbt,8,WALL_BANNER:5,../JungleNBT/banners/JungleBanner13.nbt,8,WALL_BANNER:5,../JungleNBT/banners/JungleBanner14.nbt,8,WALL_BANNER:5,../JungleNBT/banners/JungleBanner15.nbt,8,WALL_BANNER:5,../JungleNBT/banners/JungleBanner16.nbt,8,WALL_BANNER:5,../JungleNBT/banners/JungleBanner17.nbt,8,WALL_BANNER:5,../JungleNBT/banners/JungleBanner18.nbt,8,WALL_BANNER:5,../JungleNBT/banners/JungleBanner19.nbt,8,WALL_BANNER:5,../JungleNBT/banners/JungleBanner20.nbt,100)
Block(0,7,1,WOODEN_SLAB:5)
Block(0,7,2,WOODEN_SLAB:5)
Block(0,7,3,TRAPDOOR:1)
Block(-1,8,-1,TRAPDOOR:6)
Block(0,8,-1,RED_GLAZED_TERRACOTTA:1)
Block(0,9,-1,WOODEN_SLAB:1)
