#######################################################################
# +-----------------------------------------------------------------+ #
# |                            BO3 object                           | #
# +-----------------------------------------------------------------+ #
#######################################################################

# This is the config file of a custom object.
# If you add this object correctly to your BiomeConfigs, it will spawn in the world.

# This is the creator of this BO3 object
Author: BO3 BulkEdit (by LanToaster)

# A short description of this BO3 object
Description: Bo3 spikes created by NLBlackEagle

# The BO3 version, don't change this! It can be used by external applications to do a version check.
Version: 3

# The settings mode, WriteAll, WriteWithoutComments or WriteDisable. See WorldConfig.
SettingsMode: WriteDisable


#######################################################################
# +-----------------------------------------------------------------+ #
# |                          Main settings                          | #
# +-----------------------------------------------------------------+ #
#######################################################################

# This needs to be set to true to spawn the object in the Tree and Sapling resources.
Tree: true

# The frequency of the BO3 from 1 to 200. Tries this many times to spawn this BO3 when using the CustomObject(...) resource.

Frequency: 100

# The rarity of the BO3 from 0 to 100. Each spawn attempt has rarity% chance to succeed when using the CustomObject(...) resource.

Rarity: 100

# If you set this to true, the BO3 will be placed with a random rotation.
RotateRandomly: true

# The spawn height of the BO3 - randomY, highestBlock or highestSolidBlock.
SpawnHeight: randomY

# The height limits for the BO3.
MinHeight: 150

MaxHeight: 160

# Objects can have other objects attacthed to it: branches. Branches can also
# have branches attached to it, which can also have branches, etc. This is the
# maximum branch depth for this objects.
MaxBranchDepth: 10

# When spawned with the UseWorld keyword, this BO3 should NOT spawn in the following biomes.
# If you writer.write the BO3 name directly in the BiomeConfigs, this will be ignored.
ExcludedBiomes: All


#######################################################################
# +-----------------------------------------------------------------+ #
# |                      Source block settings                      | #
# +-----------------------------------------------------------------+ #
#######################################################################

# The block(s) the BO3 should spawn in.
SourceBlocks: AIR

# The maximum percentage of the BO3 that can be outside the SourceBlock.
# The BO3 won't be placed on a location with more blocks outside the SourceBlock than this percentage.
MaxPercentageOutsideSourceBlock: 20

# What to do when a block is about to be placed outside the SourceBlock? (dontPlace, placeAnyway)
OutsideSourceBlock: placeAnyway


#######################################################################
# +-----------------------------------------------------------------+ #
# |                              Blocks                             | #
# +-----------------------------------------------------------------+ #
#######################################################################

# All the blocks used in the BO3 are listed here. Possible blocks:
# Block(x,y,z,id[.data][,nbtfile.nbt)
# RandomBlock(x,y,z,id[:data][,nbtfile.nbt],chance[,id[:data][,nbtfile.nbt],chance[,...]])
# So RandomBlock(0,0,0,CHEST,chest.nbt,50,CHEST,anotherchest.nbt,100) will spawn a chest at
# the BO3 origin, and give it a 50% chance to have the contents of chest.nbt, or, if that
# fails, a 100% percent chance to have the contents of anotherchest.nbt.
Block(-14,0,-15,LOG:13)
Block(2,0,-15,LOG:13)
Block(13,0,-15,LOG:13)
Block(-14,0,-14,LOG:13)
Block(-13,0,-14,LOG:13)
Block(-12,0,-14,LOG:13)
Block(-11,0,-14,LOG:13)
Block(1,0,-14,LOG:13)
Block(2,0,-14,LOG:13)
Block(3,0,-14,LOG:13)
Block(8,0,-14,LOG:13)
Block(12,0,-14,LOG:13)
Block(13,0,-14,LOG:13)
Block(14,0,-14,LOG:13)
Block(-14,0,-13,LOG:13)
Block(-13,0,-13,LOG:13)
Block(-12,0,-13,LOG:13)
Block(-11,0,-13,LOG:13)
Block(-10,0,-13,LOG:13)
Block(1,0,-13,LOG:13)
Block(2,0,-13,LOG:13)
Block(3,0,-13,LOG:13)
Block(8,0,-13,LOG:13)
Block(12,0,-13,LOG:13)
Block(13,0,-13,LOG:13)
Block(-13,0,-12,LOG:13)
Block(-12,0,-12,LOG:13)
Block(-11,0,-12,LOG:13)
Block(-3,0,-12,LOG:13)
Block(1,0,-12,LOG:13)
Block(2,0,-12,LOG:13)
Block(3,0,-12,LOG:13)
Block(2,0,-11,LOG:13)
Block(8,0,-10,LOG:13)
Block(-15,0,-9,LOG:13)
Block(11,0,-7,LOG:13)
Block(5,0,-6,LOG:13)
Block(-14,0,-4,LOG:13)
Block(-13,0,-4,LOG:13)
Block(9,0,-4,LOG:13)
Block(-15,0,-3,LOG:13)
Block(-14,0,-3,LOG:13)
Block(-13,0,-3,LOG:13)
Block(-12,0,-3,LOG:13)
Block(-14,0,-2,LOG:13)
Block(-13,0,-2,LOG:13)
Block(4,0,-2,LOG:13)
Block(14,0,-2,LOG:13)
Block(13,0,-1,LOG:13)
Block(6,0,0,LOG:13)
Block(12,0,0,LOG:13)
Block(13,0,0,LOG:13)
Block(11,0,1,LOG:13)
Block(12,0,1,LOG:13)
Block(13,0,1,LOG:13)
Block(11,0,2,LOG:13)
Block(12,0,2,LOG:13)
Block(-11,0,3,LOG:13)
Block(-8,0,3,LOG:13)
Block(-1,0,4,LOG:13)
Block(2,0,6,LOG:13)
Block(-15,0,8,LOG:13)
Block(-7,0,8,LOG:13)
Block(-4,0,9,LOG:13)
Block(-1,0,9,LOG:13)
Block(0,0,9,LOG:13)
Block(1,0,9,LOG:13)
Block(9,0,9,LOG:13)
Block(10,0,9,LOG:13)
Block(-14,0,10,LOG:13)
Block(-13,0,10,LOG:13)
Block(-1,0,10,LOG:13)
Block(0,0,10,LOG:13)
Block(1,0,10,LOG:13)
Block(2,0,10,LOG:13)
Block(8,0,10,LOG:13)
Block(9,0,10,LOG:13)
Block(10,0,10,LOG:13)
Block(11,0,10,LOG:13)
Block(-15,0,11,LOG:13)
Block(-14,0,11,LOG:13)
Block(-13,0,11,LOG:13)
Block(-12,0,11,LOG:13)
Block(0,0,11,LOG:13)
Block(1,0,11,LOG:13)
Block(2,0,11,LOG:13)
Block(9,0,11,LOG:13)
Block(10,0,11,LOG:13)
Block(11,0,11,LOG:13)
Block(-15,0,12,LOG:13)
Block(-14,0,12,LOG:13)
Block(-13,0,12,LOG:13)
Block(1,0,12,LOG:13)
Block(2,0,12,LOG:13)
Block(10,0,12,LOG:13)
Block(11,0,12,LOG:13)
Block(12,0,12,LOG:13)
Block(-15,0,13,LOG:13)
Block(-14,0,13,LOG:13)
Block(-13,0,13,LOG:13)
Block(11,0,13,LOG:13)
Block(12,0,13,LOG:13)
Block(-14,0,14,LOG:13)
Block(13,1,-15,LOG:13)
Block(-11,1,-14,LOG:13)
Block(2,1,-14,LOG:13)
Block(12,1,-14,LOG:13)
Block(13,1,-14,LOG:13)
Block(14,1,-14,LOG:13)
Block(-13,1,-13,LOG:13)
Block(-12,1,-13,LOG:13)
Block(-11,1,-13,LOG:13)
Block(-10,1,-13,LOG:13)
Block(2,1,-13,LOG:13)
Block(7,1,-13,LOG:13)
Block(8,1,-13,LOG:13)
Block(11,1,-13,LOG:13)
Block(12,1,-13,LOG:13)
Block(13,1,-13,LOG:13)
Block(14,1,-13,LOG:13)
Block(-11,1,-12,LOG:13)
Block(-3,1,-12,LOG:13)
Block(1,1,-12,LOG:13)
Block(2,1,-12,LOG:13)
Block(3,1,-12,LOG:13)
Block(7,1,-12,LOG:13)
Block(12,1,-12,LOG:13)
Block(13,1,-12,LOG:13)
Block(-11,1,-11,LOG:13)
Block(-10,1,-11,LOG:13)
Block(2,1,-11,LOG:13)
Block(8,1,-10,LOG:13)
Block(-15,1,-9,LOG:13)
Block(11,1,-7,LOG:13)
Block(5,1,-6,LOG:13)
Block(-13,1,-4,LOG:13)
Block(9,1,-4,LOG:13)
Block(-14,1,-3,LOG:13)
Block(-13,1,-3,LOG:13)
Block(-12,1,-3,LOG:13)
Block(-13,1,-2,LOG:13)
Block(4,1,-2,LOG:13)
Block(6,1,0,LOG:13)
Block(11,1,0,LOG:13)
Block(12,1,0,LOG:13)
Block(10,1,1,LOG:13)
Block(11,1,1,LOG:13)
Block(12,1,1,LOG:13)
Block(13,1,1,LOG:13)
Block(10,1,2,LOG:13)
Block(11,1,2,LOG:13)
Block(12,1,2,LOG:13)
Block(-11,1,3,LOG:13)
Block(-8,1,3,LOG:13)
Block(9,1,3,LOG:13)
Block(10,1,3,LOG:13)
Block(11,1,3,LOG:13)
Block(-1,1,4,LOG:13)
Block(2,1,6,LOG:13)
Block(-14,1,7,LOG:13)
Block(-15,1,8,LOG:13)
Block(-14,1,8,LOG:13)
Block(-7,1,8,LOG:13)
Block(-1,1,8,LOG:13)
Block(0,1,8,LOG:13)
Block(9,1,8,LOG:13)
Block(-11,1,9,LOG:13)
Block(-10,1,9,LOG:13)
Block(-4,1,9,LOG:13)
Block(-2,1,9,LOG:13)
Block(-1,1,9,LOG:13)
Block(0,1,9,LOG:13)
Block(1,1,9,LOG:13)
Block(8,1,9,LOG:13)
Block(9,1,9,LOG:13)
Block(10,1,9,LOG:13)
Block(-13,1,10,LOG:13)
Block(-12,1,10,LOG:13)
Block(-11,1,10,LOG:13)
Block(-1,1,10,LOG:13)
Block(0,1,10,LOG:13)
Block(1,1,10,LOG:13)
Block(8,1,10,LOG:13)
Block(9,1,10,LOG:13)
Block(10,1,10,LOG:13)
Block(-14,1,11,LOG:13)
Block(-13,1,11,LOG:13)
Block(-12,1,11,LOG:13)
Block(-11,1,11,LOG:13)
Block(0,1,11,LOG:13)
Block(1,1,11,LOG:13)
Block(9,1,11,LOG:13)
Block(10,1,11,LOG:13)
Block(-14,1,12,LOG:13)
Block(-13,1,12,LOG:13)
Block(-12,1,12,LOG:13)
Block(11,1,12,LOG:13)
Block(-14,1,13,LOG:13)
Block(-11,2,-14,LOG:13)
Block(12,2,-14,LOG:13)
Block(13,2,-14,LOG:13)
Block(-12,2,-13,LOG:13)
Block(-11,2,-13,LOG:13)
Block(-10,2,-13,LOG:13)
Block(2,2,-13,LOG:13)
Block(11,2,-13,LOG:13)
Block(12,2,-13,LOG:13)
Block(13,2,-13,LOG:13)
Block(-12,2,-12,LOG:13)
Block(-11,2,-12,LOG:13)
Block(-10,2,-12,LOG:13)
Block(-4,2,-12,LOG:13)
Block(-3,2,-12,LOG:13)
Block(1,2,-12,LOG:13)
Block(2,2,-12,LOG:13)
Block(3,2,-12,LOG:13)
Block(6,2,-12,LOG:13)
Block(7,2,-12,LOG:13)
Block(11,2,-12,LOG:13)
Block(12,2,-12,LOG:13)
Block(13,2,-12,LOG:13)
Block(-12,2,-11,LOG:13)
Block(-11,2,-11,LOG:13)
Block(-10,2,-11,LOG:13)
Block(-9,2,-11,LOG:13)
Block(1,2,-11,LOG:13)
Block(2,2,-11,LOG:13)
Block(3,2,-11,LOG:13)
Block(12,2,-11,LOG:13)
Block(-11,2,-10,LOG:13)
Block(-10,2,-10,LOG:13)
Block(1,2,-10,LOG:13)
Block(2,2,-10,LOG:13)
Block(8,2,-10,LOG:13)
Block(-15,2,-9,LOG:13)
Block(-14,2,-9,LOG:13)
Block(1,2,-9,LOG:13)
Block(-14,2,-8,LOG:13)
Block(-13,2,-8,LOG:13)
Block(11,2,-7,LOG:13)
Block(-4,2,-6,LOG:13)
Block(5,2,-6,LOG:13)
Block(1,2,-5,LOG:13)
Block(-13,2,-4,LOG:13)
Block(-12,2,-4,LOG:13)
Block(9,2,-4,LOG:13)
Block(-14,2,-3,LOG:13)
Block(-13,2,-3,LOG:13)
Block(-12,2,-3,LOG:13)
Block(-11,2,-3,LOG:13)
Block(-13,2,-2,LOG:13)
Block(-12,2,-2,LOG:13)
Block(4,2,-2,LOG:13)
Block(-5,2,0,LOG:13)
Block(6,2,0,LOG:13)
Block(6,2,1,LOG:13)
Block(10,2,1,LOG:13)
Block(11,2,1,LOG:13)
Block(12,2,1,LOG:13)
Block(9,2,2,LOG:13)
Block(10,2,2,LOG:13)
Block(11,2,2,LOG:13)
Block(12,2,2,LOG:13)
Block(-11,2,3,LOG:13)
Block(-8,2,3,LOG:13)
Block(8,2,3,LOG:13)
Block(9,2,3,LOG:13)
Block(10,2,3,LOG:13)
Block(11,2,3,LOG:13)
Block(-8,2,4,LOG:13)
Block(-1,2,4,LOG:13)
Block(0,2,4,LOG:13)
Block(9,2,4,LOG:13)
Block(10,2,4,LOG:13)
Block(-13,2,5,LOG:13)
Block(-13,2,6,LOG:13)
Block(2,2,6,LOG:13)
Block(3,2,6,LOG:13)
Block(-14,2,7,LOG:13)
Block(-13,2,7,LOG:13)
Block(-1,2,7,LOG:13)
Block(-11,2,8,LOG:13)
Block(-10,2,8,LOG:13)
Block(-7,2,8,LOG:13)
Block(-4,2,8,LOG:13)
Block(-2,2,8,LOG:13)
Block(-1,2,8,LOG:13)
Block(0,2,8,LOG:13)
Block(7,2,8,LOG:13)
Block(8,2,8,LOG:13)
Block(9,2,8,LOG:13)
Block(-12,2,9,LOG:13)
Block(-11,2,9,LOG:13)
Block(-10,2,9,LOG:13)
Block(-9,2,9,LOG:13)
Block(-4,2,9,LOG:13)
Block(-2,2,9,LOG:13)
Block(-1,2,9,LOG:13)
Block(0,2,9,LOG:13)
Block(7,2,9,LOG:13)
Block(8,2,9,LOG:13)
Block(9,2,9,LOG:13)
Block(10,2,9,LOG:13)
Block(-13,2,10,LOG:13)
Block(-12,2,10,LOG:13)
Block(-11,2,10,LOG:13)
Block(-10,2,10,LOG:13)
Block(-1,2,10,LOG:13)
Block(0,2,10,LOG:13)
Block(8,2,10,LOG:13)
Block(9,2,10,LOG:13)
Block(-14,2,11,LOG:13)
Block(-13,2,11,LOG:13)
Block(-12,2,11,LOG:13)
Block(-11,2,11,LOG:13)
Block(-13,2,12,LOG:13)
Block(-12,2,12,LOG:13)
Block(-11,3,-13,LOG:13)
Block(11,3,-13,LOG:13)
Block(12,3,-13,LOG:13)
Block(-11,3,-12,LOG:13)
Block(-10,3,-12,LOG:13)
Block(-4,3,-12,LOG:13)
Block(1,3,-12,LOG:13)
Block(2,3,-12,LOG:13)
Block(6,3,-12,LOG:13)
Block(10,3,-12,LOG:13)
Block(11,3,-12,LOG:13)
Block(12,3,-12,LOG:13)
Block(13,3,-12,LOG:13)
Block(-11,3,-11,LOG:13)
Block(-10,3,-11,LOG:13)
Block(-9,3,-11,LOG:13)
Block(0,3,-11,LOG:13)
Block(1,3,-11,LOG:13)
Block(2,3,-11,LOG:13)
Block(3,3,-11,LOG:13)
Block(6,3,-11,LOG:13)
Block(11,3,-11,LOG:13)
Block(12,3,-11,LOG:13)
Block(-10,3,-10,LOG:13)
Block(-9,3,-10,LOG:13)
Block(0,3,-10,LOG:13)
Block(1,3,-10,LOG:13)
Block(2,3,-10,LOG:13)
Block(6,3,-10,LOG:13)
Block(8,3,-10,LOG:13)
Block(0,3,-9,LOG:13)
Block(1,3,-9,LOG:13)
Block(2,3,-9,LOG:13)
Block(-13,3,-8,LOG:13)
Block(1,3,-8,LOG:13)
Block(11,3,-8,LOG:13)
Block(11,3,-7,LOG:13)
Block(-4,3,-6,LOG:13)
Block(5,3,-6,LOG:13)
Block(6,3,-6,LOG:13)
Block(1,3,-5,LOG:13)
Block(-12,3,-4,LOG:13)
Block(8,3,-4,LOG:13)
Block(9,3,-4,LOG:13)
Block(-13,3,-3,LOG:13)
Block(-12,3,-3,LOG:13)
Block(-11,3,-3,LOG:13)
Block(-1,3,-3,LOG:13)
Block(-13,3,-2,LOG:13)
Block(-12,3,-2,LOG:13)
Block(-11,3,-2,LOG:13)
Block(4,3,-2,LOG:13)
Block(-12,3,-1,LOG:13)
Block(-9,3,-1,LOG:13)
Block(-1,3,-1,LOG:13)
Block(-5,3,0,LOG:13)
Block(-2,3,1,LOG:13)
Block(6,3,1,LOG:13)
Block(-11,3,2,LOG:13)
Block(8,3,2,LOG:13)
Block(9,3,2,LOG:13)
Block(10,3,2,LOG:13)
Block(11,3,2,LOG:13)
Block(-13,3,3,LOG:13)
Block(-12,3,3,LOG:13)
Block(-11,3,3,LOG:13)
Block(7,3,3,LOG:13)
Block(8,3,3,LOG:13)
Block(9,3,3,LOG:13)
Block(10,3,3,LOG:13)
Block(-13,3,4,LOG:13)
Block(-8,3,4,LOG:13)
Block(0,3,4,LOG:13)
Block(8,3,4,LOG:13)
Block(9,3,4,LOG:13)
Block(-13,3,5,LOG:13)
Block(-4,3,5,LOG:13)
Block(3,3,6,LOG:13)
Block(-10,3,7,LOG:13)
Block(-2,3,7,LOG:13)
Block(-1,3,7,LOG:13)
Block(7,3,7,LOG:13)
Block(8,3,7,LOG:13)
Block(-11,3,8,LOG:13)
Block(-10,3,8,LOG:13)
Block(-9,3,8,LOG:13)
Block(-7,3,8,LOG:13)
Block(-4,3,8,LOG:13)
Block(-3,3,8,LOG:13)
Block(-2,3,8,LOG:13)
Block(-1,3,8,LOG:13)
Block(0,3,8,LOG:13)
Block(6,3,8,LOG:13)
Block(7,3,8,LOG:13)
Block(8,3,8,LOG:13)
Block(9,3,8,LOG:13)
Block(-11,3,9,LOG:13)
Block(-10,3,9,LOG:13)
Block(-9,3,9,LOG:13)
Block(-2,3,9,LOG:13)
Block(-1,3,9,LOG:13)
Block(7,3,9,LOG:13)
Block(8,3,9,LOG:13)
Block(9,3,9,LOG:13)
Block(-12,3,10,LOG:13)
Block(-11,3,10,LOG:13)
Block(-10,3,10,LOG:13)
Block(8,3,10,LOG:13)
Block(-13,3,11,LOG:13)
Block(-12,3,11,LOG:13)
Block(11,4,-13,LOG:13)
Block(-10,4,-12,LOG:13)
Block(-4,4,-12,LOG:13)
Block(10,4,-12,LOG:13)
Block(11,4,-12,LOG:13)
Block(12,4,-12,LOG:13)
Block(-11,4,-11,LOG:13)
Block(-10,4,-11,LOG:13)
Block(-9,4,-11,LOG:13)
Block(-4,4,-11,LOG:13)
Block(1,4,-11,LOG:13)
Block(2,4,-11,LOG:13)
Block(10,4,-11,LOG:13)
Block(11,4,-11,LOG:13)
Block(12,4,-11,LOG:13)
Block(-11,4,-10,LOG:13)
Block(-10,4,-10,LOG:13)
Block(-9,4,-10,LOG:13)
Block(-8,4,-10,LOG:13)
Block(1,4,-10,LOG:13)
Block(6,4,-10,LOG:13)
Block(8,4,-10,LOG:13)
Block(10,4,-10,LOG:13)
Block(11,4,-10,LOG:13)
Block(-10,4,-9,LOG:13)
Block(-9,4,-9,LOG:13)
Block(0,4,-9,LOG:13)
Block(1,4,-9,LOG:13)
Block(2,4,-9,LOG:13)
Block(8,4,-9,LOG:13)
Block(9,4,-9,LOG:13)
Block(10,4,-9,LOG:13)
Block(-13,4,-8,LOG:13)
Block(0,4,-8,LOG:13)
Block(1,4,-8,LOG:13)
Block(9,4,-8,LOG:13)
Block(11,4,-8,LOG:13)
Block(-13,4,-7,LOG:13)
Block(-12,4,-7,LOG:13)
Block(-4,4,-6,LOG:13)
Block(6,4,-6,LOG:13)
Block(1,4,-5,LOG:13)
Block(6,4,-5,LOG:13)
Block(8,4,-4,LOG:13)
Block(-12,4,-3,LOG:13)
Block(-11,4,-3,LOG:13)
Block(-1,4,-3,LOG:13)
Block(-13,4,-2,LOG:13)
Block(-12,4,-2,LOG:13)
Block(-11,4,-2,LOG:13)
Block(-10,4,-2,LOG:13)
Block(3,4,-2,LOG:13)
Block(4,4,-2,LOG:13)
Block(-12,4,-1,LOG:13)
Block(-11,4,-1,LOG:13)
Block(-9,4,-1,LOG:13)
Block(-1,4,-1,LOG:13)
Block(-5,4,0,LOG:13)
Block(-2,4,1,LOG:13)
Block(6,4,1,LOG:13)
Block(-11,4,2,LOG:13)
Block(8,4,2,LOG:13)
Block(7,4,3,LOG:13)
Block(8,4,3,LOG:13)
Block(9,4,3,LOG:13)
Block(-8,4,4,LOG:13)
Block(-7,4,4,LOG:13)
Block(0,4,4,LOG:13)
Block(8,4,4,LOG:13)
Block(-4,4,5,LOG:13)
Block(-2,4,6,LOG:13)
Block(3,4,6,LOG:13)
Block(7,4,6,LOG:13)
Block(-10,4,7,LOG:13)
Block(-9,4,7,LOG:13)
Block(-3,4,7,LOG:13)
Block(-2,4,7,LOG:13)
Block(-1,4,7,LOG:13)
Block(6,4,7,LOG:13)
Block(7,4,7,LOG:13)
Block(8,4,7,LOG:13)
Block(-11,4,8,LOG:13)
Block(-10,4,8,LOG:13)
Block(-9,4,8,LOG:13)
Block(-8,4,8,LOG:13)
Block(-7,4,8,LOG:13)
Block(-3,4,8,LOG:13)
Block(-2,4,8,LOG:13)
Block(-1,4,8,LOG:13)
Block(6,4,8,LOG:13)
Block(7,4,8,LOG:13)
Block(8,4,8,LOG:13)
Block(-10,4,9,LOG:13)
Block(-9,4,9,LOG:13)
Block(-2,4,9,LOG:13)
Block(7,4,9,LOG:13)
Block(8,4,9,LOG:13)
Block(11,5,-12,LOG:13)
Block(-10,5,-11,LOG:13)
Block(-9,5,-11,LOG:13)
Block(-4,5,-11,LOG:13)
Block(10,5,-11,LOG:13)
Block(11,5,-11,LOG:13)
Block(12,5,-11,LOG:13)
Block(-10,5,-10,LOG:13)
Block(-9,5,-10,LOG:13)
Block(-8,5,-10,LOG:13)
Block(1,5,-10,LOG:13)
Block(5,5,-10,LOG:13)
Block(6,5,-10,LOG:13)
Block(9,5,-10,LOG:13)
Block(10,5,-10,LOG:13)
Block(11,5,-10,LOG:13)
Block(12,5,-10,LOG:13)
Block(-9,5,-9,LOG:13)
Block(0,5,-9,LOG:13)
Block(1,5,-9,LOG:13)
Block(2,5,-9,LOG:13)
Block(5,5,-9,LOG:13)
Block(8,5,-9,LOG:13)
Block(9,5,-9,LOG:13)
Block(10,5,-9,LOG:13)
Block(11,5,-9,LOG:13)
Block(-1,5,-8,LOG:13)
Block(0,5,-8,LOG:13)
Block(1,5,-8,LOG:13)
Block(2,5,-8,LOG:13)
Block(5,5,-8,LOG:13)
Block(8,5,-8,LOG:13)
Block(9,5,-8,LOG:13)
Block(10,5,-8,LOG:13)
Block(11,5,-8,LOG:13)
Block(-12,5,-7,LOG:13)
Block(0,5,-7,LOG:13)
Block(1,5,-7,LOG:13)
Block(8,5,-7,LOG:13)
Block(9,5,-7,LOG:13)
Block(-4,5,-6,LOG:13)
Block(0,5,-6,LOG:13)
Block(1,5,-6,LOG:13)
Block(8,5,-6,LOG:13)
Block(1,5,-5,LOG:13)
Block(6,5,-5,LOG:13)
Block(7,5,-5,LOG:13)
Block(8,5,-4,LOG:13)
Block(-11,5,-3,LOG:13)
Block(-1,5,-3,LOG:13)
Block(-12,5,-2,LOG:13)
Block(-11,5,-2,LOG:13)
Block(-10,5,-2,LOG:13)
Block(3,5,-2,LOG:13)
Block(-11,5,-1,LOG:13)
Block(-9,5,-1,LOG:13)
Block(-1,5,-1,LOG:13)
Block(-5,5,0,LOG:13)
Block(-2,5,1,LOG:13)
Block(6,5,1,LOG:13)
Block(7,5,1,LOG:13)
Block(-11,5,2,LOG:13)
Block(-10,5,2,LOG:13)
Block(7,5,2,LOG:13)
Block(8,5,2,LOG:13)
Block(0,5,3,LOG:13)
Block(6,5,3,LOG:13)
Block(7,5,3,LOG:13)
Block(8,5,3,LOG:13)
Block(9,5,3,LOG:13)
Block(-7,5,4,LOG:13)
Block(0,5,4,LOG:13)
Block(7,5,4,LOG:13)
Block(8,5,4,LOG:13)
Block(-4,5,5,LOG:13)
Block(3,5,5,LOG:13)
Block(7,5,5,LOG:13)
Block(-9,5,6,LOG:13)
Block(-3,5,6,LOG:13)
Block(-2,5,6,LOG:13)
Block(3,5,6,LOG:13)
Block(6,5,6,LOG:13)
Block(7,5,6,LOG:13)
Block(8,5,6,LOG:13)
Block(-10,5,7,LOG:13)
Block(-9,5,7,LOG:13)
Block(-8,5,7,LOG:13)
Block(-4,5,7,LOG:13)
Block(-3,5,7,LOG:13)
Block(-2,5,7,LOG:13)
Block(-1,5,7,LOG:13)
Block(6,5,7,LOG:13)
Block(7,5,7,LOG:13)
Block(8,5,7,LOG:13)
Block(-10,5,8,LOG:13)
Block(-9,5,8,LOG:13)
Block(-8,5,8,LOG:13)
Block(-3,5,8,LOG:13)
Block(-2,5,8,LOG:13)
Block(7,5,8,LOG:13)
Block(-9,5,9,LOG:13)
Block(-9,6,-11,LOG:13)
Block(-8,6,-11,LOG:13)
Block(-5,6,-11,LOG:13)
Block(-4,6,-11,LOG:13)
Block(11,6,-11,LOG:13)
Block(-10,6,-10,LOG:13)
Block(-9,6,-10,LOG:13)
Block(-8,6,-10,LOG:13)
Block(-7,6,-10,LOG:13)
Block(-5,6,-10,LOG:13)
Block(10,6,-10,LOG:13)
Block(11,6,-10,LOG:13)
Block(-9,6,-9,LOG:13)
Block(-8,6,-9,LOG:13)
Block(-7,6,-9,LOG:13)
Block(0,6,-9,LOG:13)
Block(1,6,-9,LOG:13)
Block(9,6,-9,LOG:13)
Block(10,6,-9,LOG:13)
Block(-1,6,-8,LOG:13)
Block(0,6,-8,LOG:13)
Block(1,6,-8,LOG:13)
Block(5,6,-8,LOG:13)
Block(8,6,-8,LOG:13)
Block(9,6,-8,LOG:13)
Block(10,6,-8,LOG:13)
Block(-12,6,-7,LOG:13)
Block(-4,6,-7,LOG:13)
Block(-1,6,-7,LOG:13)
Block(0,6,-7,LOG:13)
Block(1,6,-7,LOG:13)
Block(5,6,-7,LOG:13)
Block(7,6,-7,LOG:13)
Block(8,6,-7,LOG:13)
Block(9,6,-7,LOG:13)
Block(10,6,-7,LOG:13)
Block(-12,6,-6,LOG:13)
Block(-11,6,-6,LOG:13)
Block(-4,6,-6,LOG:13)
Block(-1,6,-6,LOG:13)
Block(0,6,-6,LOG:13)
Block(1,6,-6,LOG:13)
Block(2,6,-6,LOG:13)
Block(7,6,-6,LOG:13)
Block(8,6,-6,LOG:13)
Block(9,6,-6,LOG:13)
Block(-11,6,-5,LOG:13)
Block(0,6,-5,LOG:13)
Block(1,6,-5,LOG:13)
Block(7,6,-5,LOG:13)
Block(8,6,-5,LOG:13)
Block(-2,6,-4,LOG:13)
Block(6,6,-4,LOG:13)
Block(7,6,-4,LOG:13)
Block(8,6,-4,LOG:13)
Block(-11,6,-3,LOG:13)
Block(-10,6,-3,LOG:13)
Block(-2,6,-3,LOG:13)
Block(-1,6,-3,LOG:13)
Block(3,6,-3,LOG:13)
Block(4,6,-3,LOG:13)
Block(-12,6,-2,LOG:13)
Block(-11,6,-2,LOG:13)
Block(-10,6,-2,LOG:13)
Block(-9,6,-2,LOG:13)
Block(3,6,-2,LOG:13)
Block(-12,6,-1,LOG:13)
Block(-11,6,-1,LOG:13)
Block(-10,6,-1,LOG:13)
Block(-9,6,-1,LOG:13)
Block(-1,6,-1,LOG:13)
Block(1,6,-1,LOG:13)
Block(2,6,-1,LOG:13)
Block(-11,6,0,LOG:13)
Block(-6,6,0,LOG:13)
Block(-5,6,0,LOG:13)
Block(-10,6,1,LOG:13)
Block(-3,6,1,LOG:13)
Block(-2,6,1,LOG:13)
Block(3,6,1,LOG:13)
Block(-10,6,2,LOG:13)
Block(3,6,2,LOG:13)
Block(7,6,2,LOG:13)
Block(0,6,3,LOG:13)
Block(4,6,3,LOG:13)
Block(6,6,3,LOG:13)
Block(7,6,3,LOG:13)
Block(8,6,3,LOG:13)
Block(-7,6,4,LOG:13)
Block(5,6,4,LOG:13)
Block(6,6,4,LOG:13)
Block(7,6,4,LOG:13)
Block(8,6,4,LOG:13)
Block(-4,6,5,LOG:13)
Block(-3,6,5,LOG:13)
Block(3,6,5,LOG:13)
Block(5,6,5,LOG:13)
Block(6,6,5,LOG:13)
Block(7,6,5,LOG:13)
Block(-9,6,6,LOG:13)
Block(-8,6,6,LOG:13)
Block(-5,6,6,LOG:13)
Block(-4,6,6,LOG:13)
Block(-3,6,6,LOG:13)
Block(-2,6,6,LOG:13)
Block(5,6,6,LOG:13)
Block(6,6,6,LOG:13)
Block(7,6,6,LOG:13)
Block(8,6,6,LOG:13)
Block(-10,6,7,LOG:13)
Block(-9,6,7,LOG:13)
Block(-8,6,7,LOG:13)
Block(-7,6,7,LOG:13)
Block(-4,6,7,LOG:13)
Block(-3,6,7,LOG:13)
Block(-2,6,7,LOG:13)
Block(6,6,7,LOG:13)
Block(7,6,7,LOG:13)
Block(-9,6,8,LOG:13)
Block(-8,6,8,LOG:13)
Block(-3,6,8,LOG:13)
Block(-8,7,-11,LOG:13)
Block(-9,7,-10,LOG:13)
Block(-8,7,-10,LOG:13)
Block(-7,7,-10,LOG:13)
Block(-5,7,-10,LOG:13)
Block(-9,7,-9,LOG:13)
Block(-8,7,-9,LOG:13)
Block(-7,7,-9,LOG:13)
Block(-6,7,-9,LOG:13)
Block(-8,7,-8,LOG:13)
Block(-7,7,-8,LOG:13)
Block(-5,7,-8,LOG:13)
Block(-4,7,-8,LOG:13)
Block(0,7,-8,LOG:13)
Block(9,7,-8,LOG:13)
Block(-5,7,-7,LOG:13)
Block(-4,7,-7,LOG:13)
Block(-3,7,-7,LOG:13)
Block(0,7,-7,LOG:13)
Block(1,7,-7,LOG:13)
Block(5,7,-7,LOG:13)
Block(6,7,-7,LOG:13)
Block(8,7,-7,LOG:13)
Block(9,7,-7,LOG:13)
Block(-5,7,-6,LOG:13)
Block(-4,7,-6,LOG:13)
Block(-3,7,-6,LOG:13)
Block(0,7,-6,LOG:13)
Block(1,7,-6,LOG:13)
Block(2,7,-6,LOG:13)
Block(7,7,-6,LOG:13)
Block(8,7,-6,LOG:13)
Block(9,7,-6,LOG:13)
Block(-11,7,-5,LOG:13)
Block(-10,7,-5,LOG:13)
Block(-4,7,-5,LOG:13)
Block(-3,7,-5,LOG:13)
Block(-2,7,-5,LOG:13)
Block(-1,7,-5,LOG:13)
Block(0,7,-5,LOG:13)
Block(1,7,-5,LOG:13)
Block(2,7,-5,LOG:13)
Block(6,7,-5,LOG:13)
Block(7,7,-5,LOG:13)
Block(8,7,-5,LOG:13)
Block(9,7,-5,LOG:13)
Block(-10,7,-4,LOG:13)
Block(-3,7,-4,LOG:13)
Block(-2,7,-4,LOG:13)
Block(-1,7,-4,LOG:13)
Block(0,7,-4,LOG:13)
Block(1,7,-4,LOG:13)
Block(3,7,-4,LOG:13)
Block(4,7,-4,LOG:13)
Block(5,7,-4,LOG:13)
Block(6,7,-4,LOG:13)
Block(7,7,-4,LOG:13)
Block(8,7,-4,LOG:13)
Block(-10,7,-3,LOG:13)
Block(-9,7,-3,LOG:13)
Block(-3,7,-3,LOG:13)
Block(-2,7,-3,LOG:13)
Block(-1,7,-3,LOG:13)
Block(0,7,-3,LOG:13)
Block(2,7,-3,LOG:13)
Block(3,7,-3,LOG:13)
Block(4,7,-3,LOG:13)
Block(5,7,-3,LOG:13)
Block(6,7,-3,LOG:13)
Block(7,7,-3,LOG:13)
Block(-11,7,-2,LOG:13)
Block(-10,7,-2,LOG:13)
Block(-9,7,-2,LOG:13)
Block(-8,7,-2,LOG:13)
Block(-2,7,-2,LOG:13)
Block(-1,7,-2,LOG:13)
Block(1,7,-2,LOG:13)
Block(2,7,-2,LOG:13)
Block(3,7,-2,LOG:13)
Block(4,7,-2,LOG:13)
Block(-11,7,-1,LOG:13)
Block(-10,7,-1,LOG:13)
Block(-9,7,-1,LOG:13)
Block(-8,7,-1,LOG:13)
Block(-6,7,-1,LOG:13)
Block(-5,7,-1,LOG:13)
Block(-2,7,-1,LOG:13)
Block(-1,7,-1,LOG:13)
Block(0,7,-1,LOG:13)
Block(1,7,-1,LOG:13)
Block(2,7,-1,LOG:13)
Block(3,7,-1,LOG:13)
Block(-11,7,0,LOG:13)
Block(-10,7,0,LOG:13)
Block(-9,7,0,LOG:13)
Block(-8,7,0,LOG:13)
Block(-7,7,0,LOG:13)
Block(-6,7,0,LOG:13)
Block(-5,7,0,LOG:13)
Block(-4,7,0,LOG:13)
Block(-3,7,0,LOG:13)
Block(-2,7,0,LOG:13)
Block(-1,7,0,LOG:13)
Block(0,7,0,LOG:13)
Block(1,7,0,LOG:13)
Block(2,7,0,LOG:13)
Block(3,7,0,LOG:13)
Block(-10,7,1,LOG:13)
Block(-6,7,1,LOG:13)
Block(-5,7,1,LOG:13)
Block(-4,7,1,LOG:13)
Block(-3,7,1,LOG:13)
Block(-2,7,1,LOG:13)
Block(-1,7,1,LOG:13)
Block(2,7,1,LOG:13)
Block(3,7,1,LOG:13)
Block(4,7,1,LOG:13)
Block(-3,7,2,LOG:13)
Block(-2,7,2,LOG:13)
Block(2,7,2,LOG:13)
Block(3,7,2,LOG:13)
Block(4,7,2,LOG:13)
Block(-3,7,3,LOG:13)
Block(-2,7,3,LOG:13)
Block(0,7,3,LOG:13)
Block(3,7,3,LOG:13)
Block(4,7,3,LOG:13)
Block(5,7,3,LOG:13)
Block(6,7,3,LOG:13)
Block(7,7,3,LOG:13)
Block(-7,7,4,LOG:13)
Block(-4,7,4,LOG:13)
Block(-3,7,4,LOG:13)
Block(4,7,4,LOG:13)
Block(5,7,4,LOG:13)
Block(6,7,4,LOG:13)
Block(7,7,4,LOG:13)
Block(8,7,4,LOG:13)
Block(-5,7,5,LOG:13)
Block(-4,7,5,LOG:13)
Block(-3,7,5,LOG:13)
Block(3,7,5,LOG:13)
Block(4,7,5,LOG:13)
Block(5,7,5,LOG:13)
Block(6,7,5,LOG:13)
Block(7,7,5,LOG:13)
Block(-8,7,6,LOG:13)
Block(-7,7,6,LOG:13)
Block(-6,7,6,LOG:13)
Block(-5,7,6,LOG:13)
Block(-4,7,6,LOG:13)
Block(-3,7,6,LOG:13)
Block(-2,7,6,LOG:13)
Block(5,7,6,LOG:13)
Block(6,7,6,LOG:13)
Block(7,7,6,LOG:13)
Block(-9,7,7,LOG:13)
Block(-8,7,7,LOG:13)
Block(-7,7,7,LOG:13)
Block(-6,7,7,LOG:13)
Block(-5,7,7,LOG:13)
Block(-4,7,7,LOG:13)
Block(-3,7,7,LOG:13)
Block(6,7,7,LOG:13)
Block(-8,7,8,LOG:13)
Block(-7,7,8,LOG:13)
Block(-8,8,-11,LOG:13)
Block(-9,8,-10,LOG:13)
Block(-8,8,-10,LOG:13)
Block(-7,8,-10,LOG:13)
Block(-6,8,-10,LOG:13)
Block(-5,8,-10,LOG:13)
Block(-9,8,-9,LOG:13)
Block(-8,8,-9,LOG:13)
Block(-7,8,-9,LOG:13)
Block(-6,8,-9,LOG:13)
Block(-5,8,-9,LOG:13)
Block(-4,8,-9,LOG:13)
Block(-8,8,-8,LOG:13)
Block(-7,8,-8,LOG:13)
Block(-6,8,-8,LOG:13)
Block(-5,8,-8,LOG:13)
Block(-4,8,-8,LOG:13)
Block(-3,8,-8,LOG:13)
Block(-5,8,-7,LOG:13)
Block(-4,8,-7,LOG:13)
Block(-3,8,-7,LOG:13)
Block(6,8,-7,LOG:13)
Block(7,8,-7,LOG:13)
Block(8,8,-7,LOG:13)
Block(-5,8,-6,LOG:13)
Block(-4,8,-6,LOG:13)
Block(-3,8,-6,LOG:13)
Block(-2,8,-6,LOG:13)
Block(0,8,-6,LOG:13)
Block(1,8,-6,LOG:13)
Block(6,8,-6,LOG:13)
Block(7,8,-6,LOG:13)
Block(8,8,-6,LOG:13)
Block(9,8,-6,LOG:13)
Block(-5,8,-5,LOG:13)
Block(-4,8,-5,LOG:13)
Block(-3,8,-5,LOG:13)
Block(-2,8,-5,LOG:13)
Block(-1,8,-5,LOG:13)
Block(0,8,-5,LOG:13)
Block(1,8,-5,LOG:13)
Block(5,8,-5,LOG:13)
Block(6,8,-5,LOG:13)
Block(7,8,-5,LOG:13)
Block(8,8,-5,LOG:13)
Block(9,8,-5,LOG:13)
Block(-10,8,-4,LOG:13)
Block(-4,8,-4,LOG:13)
Block(-3,8,-4,LOG:13)
Block(-2,8,-4,LOG:13)
Block(-1,8,-4,LOG:13)
Block(0,8,-4,LOG:13)
Block(1,8,-4,LOG:13)
Block(4,8,-4,LOG:13)
Block(5,8,-4,LOG:13)
Block(6,8,-4,LOG:13)
Block(7,8,-4,LOG:13)
Block(8,8,-4,LOG:13)
Block(9,8,-4,LOG:13)
Block(-9,8,-3,LOG:13)
Block(-3,8,-3,LOG:13)
Block(-2,8,-3,LOG:13)
Block(-1,8,-3,LOG:13)
Block(0,8,-3,LOG:13)
Block(1,8,-3,LOG:13)
Block(2,8,-3,LOG:13)
Block(3,8,-3,LOG:13)
Block(4,8,-3,LOG:13)
Block(5,8,-3,LOG:13)
Block(6,8,-3,LOG:13)
Block(7,8,-3,LOG:13)
Block(8,8,-3,LOG:13)
Block(-9,8,-2,LOG:13)
Block(-7,8,-2,LOG:13)
Block(-3,8,-2,LOG:13)
Block(-2,8,-2,LOG:13)
Block(-1,8,-2,LOG:13)
Block(0,8,-2,LOG:13)
Block(1,8,-2,LOG:13)
Block(2,8,-2,LOG:13)
Block(3,8,-2,LOG:13)
Block(4,8,-2,LOG:13)
Block(5,8,-2,LOG:13)
Block(-9,8,-1,LOG:13)
Block(-8,8,-1,LOG:13)
Block(-7,8,-1,LOG:13)
Block(-6,8,-1,LOG:13)
Block(-5,8,-1,LOG:13)
Block(-4,8,-1,LOG:13)
Block(-2,8,-1,LOG:13)
Block(-1,8,-1,LOG:13)
Block(0,8,-1,LOG:13)
Block(1,8,-1,LOG:13)
Block(2,8,-1,LOG:13)
Block(3,8,-1,LOG:13)
Block(-10,8,0,LOG:13)
Block(-9,8,0,LOG:13)
Block(-8,8,0,LOG:13)
Block(-7,8,0,LOG:13)
Block(-6,8,0,LOG:13)
Block(-5,8,0,LOG:13)
Block(-4,8,0,LOG:13)
Block(-3,8,0,LOG:13)
Block(-2,8,0,LOG:13)
Block(-1,8,0,LOG:13)
Block(0,8,0,LOG:13)
Block(1,8,0,LOG:13)
Block(2,8,0,LOG:13)
Block(3,8,0,LOG:13)
Block(-8,8,1,LOG:13)
Block(-7,8,1,LOG:13)
Block(-6,8,1,LOG:13)
Block(-5,8,1,LOG:13)
Block(-4,8,1,LOG:13)
Block(-3,8,1,LOG:13)
Block(-2,8,1,LOG:13)
Block(-1,8,1,LOG:13)
Block(0,8,1,LOG:13)
Block(1,8,1,LOG:13)
Block(2,8,1,LOG:13)
Block(3,8,1,LOG:13)
Block(4,8,1,LOG:13)
Block(-4,8,2,LOG:13)
Block(-3,8,2,LOG:13)
Block(-2,8,2,LOG:13)
Block(-1,8,2,LOG:13)
Block(2,8,2,LOG:13)
Block(3,8,2,LOG:13)
Block(4,8,2,LOG:13)
Block(5,8,2,LOG:13)
Block(-4,8,3,LOG:13)
Block(-3,8,3,LOG:13)
Block(-2,8,3,LOG:13)
Block(-1,8,3,LOG:13)
Block(0,8,3,LOG:13)
Block(2,8,3,LOG:13)
Block(3,8,3,LOG:13)
Block(4,8,3,LOG:13)
Block(5,8,3,LOG:13)
Block(6,8,3,LOG:13)
Block(-7,8,4,LOG:13)
Block(-5,8,4,LOG:13)
Block(-4,8,4,LOG:13)
Block(-3,8,4,LOG:13)
Block(-2,8,4,LOG:13)
Block(4,8,4,LOG:13)
Block(5,8,4,LOG:13)
Block(6,8,4,LOG:13)
Block(7,8,4,LOG:13)
Block(-7,8,5,LOG:13)
Block(-6,8,5,LOG:13)
Block(-5,8,5,LOG:13)
Block(-4,8,5,LOG:13)
Block(-3,8,5,LOG:13)
Block(-2,8,5,LOG:13)
Block(5,8,5,LOG:13)
Block(6,8,5,LOG:13)
Block(7,8,5,LOG:13)
Block(-8,8,6,LOG:13)
Block(-7,8,6,LOG:13)
Block(-6,8,6,LOG:13)
Block(-5,8,6,LOG:13)
Block(-4,8,6,LOG:13)
Block(-3,8,6,LOG:13)
Block(5,8,6,LOG:13)
Block(6,8,6,LOG:13)
Block(-7,8,7,LOG:13)
Block(-6,8,7,LOG:13)
Block(-5,8,7,LOG:13)
Block(-8,9,-10,LOG:13)
Block(-6,9,-10,LOG:13)
Block(-7,9,-9,LOG:13)
Block(-6,9,-9,LOG:13)
Block(-5,9,-9,LOG:13)
Block(-6,9,-8,LOG:13)
Block(-5,9,-8,LOG:13)
Block(-4,9,-8,LOG:13)
Block(-5,9,-7,LOG:13)
Block(-4,9,-7,LOG:13)
Block(-3,9,-7,LOG:13)
Block(8,9,-7,LOG:13)
Block(-4,9,-6,LOG:13)
Block(-3,9,-6,LOG:13)
Block(-2,9,-6,LOG:13)
Block(6,9,-6,LOG:13)
Block(7,9,-6,LOG:13)
Block(8,9,-6,LOG:13)
Block(-4,9,-5,LOG:13)
Block(-3,9,-5,LOG:13)
Block(-2,9,-5,LOG:13)
Block(0,9,-5,LOG:13)
Block(6,9,-5,LOG:13)
Block(7,9,-5,LOG:13)
Block(8,9,-5,LOG:13)
Block(-4,9,-4,LOG:13)
Block(-3,9,-4,LOG:13)
Block(-2,9,-4,LOG:13)
Block(-1,9,-4,LOG:13)
Block(0,9,-4,LOG:13)
Block(3,9,-4,LOG:13)
Block(4,9,-4,LOG:13)
Block(5,9,-4,LOG:13)
Block(6,9,-4,LOG:13)
Block(7,9,-4,LOG:13)
Block(8,9,-4,LOG:13)
Block(-3,9,-3,LOG:13)
Block(-2,9,-3,LOG:13)
Block(-1,9,-3,LOG:13)
Block(0,9,-3,LOG:13)
Block(1,9,-3,LOG:13)
Block(2,9,-3,LOG:13)
Block(3,9,-3,LOG:13)
Block(4,9,-3,LOG:13)
Block(5,9,-3,LOG:13)
Block(6,9,-3,LOG:13)
Block(-3,9,-2,LOG:13)
Block(-2,9,-2,LOG:13)
Block(-1,9,-2,LOG:13)
Block(0,9,-2,LOG:13)
Block(1,9,-2,LOG:13)
Block(2,9,-2,LOG:13)
Block(3,9,-2,LOG:13)
Block(4,9,-2,LOG:13)
Block(5,9,-2,LOG:13)
Block(-7,9,-1,LOG:13)
Block(-6,9,-1,LOG:13)
Block(-5,9,-1,LOG:13)
Block(-4,9,-1,LOG:13)
Block(-3,9,-1,LOG:13)
Block(-2,9,-1,LOG:13)
Block(-1,9,-1,LOG:13)
Block(0,9,-1,LOG:13)
Block(1,9,-1,LOG:13)
Block(2,9,-1,LOG:13)
Block(3,9,-1,LOG:13)
Block(4,9,-1,LOG:13)
Block(-8,9,0,LOG:13)
Block(-7,9,0,LOG:13)
Block(-6,9,0,LOG:13)
Block(-5,9,0,LOG:13)
Block(-4,9,0,LOG:13)
Block(-3,9,0,LOG:13)
Block(-2,9,0,LOG:13)
Block(-1,9,0,LOG:13)
Block(0,9,0,LOG:13)
Block(1,9,0,LOG:13)
Block(2,9,0,LOG:13)
Block(3,9,0,LOG:13)
Block(-7,9,1,LOG:13)
Block(-6,9,1,LOG:13)
Block(-5,9,1,LOG:13)
Block(-4,9,1,LOG:13)
Block(-3,9,1,LOG:13)
Block(-2,9,1,LOG:13)
Block(-1,9,1,LOG:13)
Block(2,9,1,LOG:13)
Block(3,9,1,LOG:13)
Block(4,9,1,LOG:13)
Block(5,9,1,LOG:13)
Block(-4,9,2,LOG:13)
Block(-3,9,2,LOG:13)
Block(-2,9,2,LOG:13)
Block(-1,9,2,LOG:13)
Block(2,9,2,LOG:13)
Block(3,9,2,LOG:13)
Block(4,9,2,LOG:13)
Block(5,9,2,LOG:13)
Block(6,9,2,LOG:13)
Block(-5,9,3,LOG:13)
Block(-4,9,3,LOG:13)
Block(-3,9,3,LOG:13)
Block(-2,9,3,LOG:13)
Block(-1,9,3,LOG:13)
Block(3,9,3,LOG:13)
Block(4,9,3,LOG:13)
Block(5,9,3,LOG:13)
Block(6,9,3,LOG:13)
Block(-6,9,4,LOG:13)
Block(-5,9,4,LOG:13)
Block(-4,9,4,LOG:13)
Block(-3,9,4,LOG:13)
Block(-2,9,4,LOG:13)
Block(4,9,4,LOG:13)
Block(5,9,4,LOG:13)
Block(6,9,4,LOG:13)
Block(-6,9,5,LOG:13)
Block(-5,9,5,LOG:13)
Block(-4,9,5,LOG:13)
Block(-3,9,5,LOG:13)
Block(5,9,5,LOG:13)
Block(6,9,5,LOG:13)
Block(7,9,5,LOG:13)
Block(-7,9,6,LOG:13)
Block(-6,9,6,LOG:13)
Block(-5,9,6,LOG:13)
Block(-4,9,6,LOG:13)
Block(6,9,6,LOG:13)
Block(-6,9,7,LOG:13)
Block(-4,10,-7,LOG:13)
Block(-3,10,-7,LOG:13)
Block(-2,10,-7,LOG:13)
Block(-4,10,-6,LOG:13)
Block(-3,10,-6,LOG:13)
Block(-2,10,-6,LOG:13)
Block(7,10,-6,LOG:13)
Block(-4,10,-5,LOG:13)
Block(-3,10,-5,LOG:13)
Block(-2,10,-5,LOG:13)
Block(-1,10,-5,LOG:13)
Block(6,10,-5,LOG:13)
Block(7,10,-5,LOG:13)
Block(8,10,-5,LOG:13)
Block(-3,10,-4,LOG:13)
Block(-2,10,-4,LOG:13)
Block(-1,10,-4,LOG:13)
Block(2,10,-4,LOG:13)
Block(3,10,-4,LOG:13)
Block(4,10,-4,LOG:13)
Block(5,10,-4,LOG:13)
Block(6,10,-4,LOG:13)
Block(7,10,-4,LOG:13)
Block(-3,10,-3,LOG:13)
Block(-2,10,-3,LOG:13)
Block(-1,10,-3,LOG:13)
Block(0,10,-3,LOG:13)
Block(1,10,-3,LOG:13)
Block(2,10,-3,LOG:13)
Block(3,10,-3,LOG:13)
Block(4,10,-3,LOG:13)
Block(5,10,-3,LOG:13)
Block(6,10,-3,LOG:13)
Block(-2,10,-2,LOG:13)
Block(-1,10,-2,LOG:13)
Block(0,10,-2,LOG:13)
Block(1,10,-2,LOG:13)
Block(2,10,-2,LOG:13)
Block(3,10,-2,LOG:13)
Block(4,10,-2,LOG:13)
Block(5,10,-2,LOG:13)
Block(6,10,-2,LOG:13)
Block(-5,10,-1,LOG:13)
Block(-4,10,-1,LOG:13)
Block(-3,10,-1,LOG:13)
Block(-2,10,-1,LOG:13)
Block(-1,10,-1,LOG:13)
Block(0,10,-1,LOG:13)
Block(1,10,-1,LOG:13)
Block(2,10,-1,LOG:13)
Block(3,10,-1,LOG:13)
Block(-6,10,0,LOG:13)
Block(-5,10,0,LOG:13)
Block(-4,10,0,LOG:13)
Block(-3,10,0,LOG:13)
Block(-2,10,0,LOG:13)
Block(-1,10,0,LOG:13)
Block(0,10,0,LOG:13)
Block(1,10,0,LOG:13)
Block(2,10,0,LOG:13)
Block(3,10,0,LOG:13)
Block(-5,10,1,LOG:13)
Block(-4,10,1,LOG:13)
Block(-3,10,1,LOG:13)
Block(-2,10,1,LOG:13)
Block(-1,10,1,LOG:13)
Block(1,10,1,LOG:13)
Block(2,10,1,LOG:13)
Block(3,10,1,LOG:13)
Block(4,10,1,LOG:13)
Block(-4,10,2,LOG:13)
Block(-3,10,2,LOG:13)
Block(-2,10,2,LOG:13)
Block(-1,10,2,LOG:13)
Block(2,10,2,LOG:13)
Block(3,10,2,LOG:13)
Block(4,10,2,LOG:13)
Block(5,10,2,LOG:13)
Block(-4,10,3,LOG:13)
Block(-3,10,3,LOG:13)
Block(-2,10,3,LOG:13)
Block(4,10,3,LOG:13)
Block(5,10,3,LOG:13)
Block(6,10,3,LOG:13)
Block(-5,10,4,LOG:13)
Block(-4,10,4,LOG:13)
Block(-3,10,4,LOG:13)
Block(-2,10,4,LOG:13)
Block(5,10,4,LOG:13)
Block(-6,10,5,LOG:13)
Block(-5,10,5,LOG:13)
Block(-4,10,5,LOG:13)
Block(-5,10,6,LOG:13)
Block(-3,11,-7,LOG:13)
Block(-4,11,-6,LOG:13)
Block(-3,11,-6,LOG:13)
Block(-2,11,-6,LOG:13)
Block(-3,11,-5,LOG:13)
Block(-2,11,-5,LOG:13)
Block(-1,11,-5,LOG:13)
Block(-3,11,-4,LOG:13)
Block(-2,11,-4,LOG:13)
Block(-1,11,-4,LOG:13)
Block(3,11,-4,LOG:13)
Block(5,11,-4,LOG:13)
Block(-3,11,-3,LOG:13)
Block(-2,11,-3,LOG:13)
Block(-1,11,-3,LOG:13)
Block(0,11,-3,LOG:13)
Block(1,11,-3,LOG:13)
Block(2,11,-3,LOG:13)
Block(3,11,-3,LOG:13)
Block(4,11,-3,LOG:13)
Block(5,11,-3,LOG:13)
Block(6,11,-3,LOG:13)
Block(-2,11,-2,LOG:13)
Block(-1,11,-2,LOG:13)
Block(0,11,-2,LOG:13)
Block(1,11,-2,LOG:13)
Block(2,11,-2,LOG:13)
Block(3,11,-2,LOG:13)
Block(5,11,-2,LOG:13)
Block(-5,11,-1,LOG:13)
Block(-4,11,-1,LOG:13)
Block(-3,11,-1,LOG:13)
Block(-2,11,-1,LOG:13)
Block(-1,11,-1,LOG:13)
Block(0,11,-1,LOG:13)
Block(1,11,-1,LOG:13)
Block(2,11,-1,LOG:13)
Block(3,11,-1,LOG:13)
Block(-5,11,0,LOG:13)
Block(-4,11,0,LOG:13)
Block(-3,11,0,LOG:13)
Block(-2,11,0,LOG:13)
Block(-1,11,0,LOG:13)
Block(0,11,0,LOG:13)
Block(1,11,0,LOG:13)
Block(2,11,0,LOG:13)
Block(3,11,0,LOG:13)
Block(-5,11,1,LOG:13)
Block(-4,11,1,LOG:13)
Block(-3,11,1,LOG:13)
Block(-2,11,1,LOG:13)
Block(-1,11,1,LOG:13)
Block(1,11,1,LOG:13)
Block(2,11,1,LOG:13)
Block(3,11,1,LOG:13)
Block(-4,11,2,LOG:13)
Block(-3,11,2,LOG:13)
Block(-2,11,2,LOG:13)
Block(1,11,2,LOG:13)
Block(2,11,2,LOG:13)
Block(3,11,2,LOG:13)
Block(-4,11,3,LOG:13)
Block(-3,11,3,LOG:13)
Block(-2,11,3,LOG:13)
Block(-3,11,4,LOG:13)
Block(-3,12,-6,LOG:13)
Block(-3,12,-5,LOG:13)
Block(-2,12,-5,LOG:13)
Block(-1,12,-5,LOG:13)
Block(-3,12,-4,LOG:13)
Block(-2,12,-4,LOG:13)
Block(-1,12,-4,LOG:13)
Block(2,12,-4,LOG:13)
Block(-2,12,-3,LOG:13)
Block(-1,12,-3,LOG:13)
Block(0,12,-3,LOG:13)
Block(1,12,-3,LOG:13)
Block(2,12,-3,LOG:13)
Block(3,12,-3,LOG:13)
Block(-2,12,-2,LOG:13)
Block(-1,12,-2,LOG:13)
Block(0,12,-2,LOG:13)
Block(1,12,-2,LOG:13)
Block(2,12,-2,LOG:13)
Block(-4,12,-1,LOG:13)
Block(-2,12,-1,LOG:13)
Block(-1,12,-1,LOG:13)
Block(0,12,-1,LOG:13)
Block(1,12,-1,LOG:13)
Block(2,12,-1,LOG:13)
Block(3,12,-1,LOG:13)
Block(-5,12,0,LOG:13)
Block(-4,12,0,LOG:13)
Block(-3,12,0,LOG:13)
Block(-2,12,0,LOG:13)
Block(-1,12,0,LOG:13)
Block(0,12,0,LOG:13)
Block(1,12,0,LOG:13)
Block(2,12,0,LOG:13)
Block(-4,12,1,LOG:13)
Block(-3,12,1,LOG:13)
Block(-2,12,1,LOG:13)
Block(-1,12,1,LOG:13)
Block(1,12,1,LOG:13)
Block(2,12,1,LOG:13)
Block(3,12,1,LOG:13)
Block(-3,12,2,LOG:13)
Block(-2,12,2,LOG:13)
Block(-1,12,2,LOG:13)
Block(2,12,2,LOG:13)
Block(-3,13,-5,LOG:13)
Block(-2,13,-5,LOG:13)
Block(-1,13,-5,LOG:13)
Block(2,13,-5,LOG:13)
Block(-2,13,-4,LOG:13)
Block(1,13,-4,LOG:13)
Block(2,13,-4,LOG:13)
Block(3,13,-4,LOG:13)
Block(-3,13,-3,LOG:13)
Block(-2,13,-3,LOG:13)
Block(-1,13,-3,LOG:13)
Block(0,13,-3,LOG:13)
Block(1,13,-3,LOG:13)
Block(2,13,-3,LOG:13)
Block(3,13,-3,LOG:13)
Block(-2,13,-2,LOG:13)
Block(-1,13,-2,LOG:13)
Block(0,13,-2,LOG:13)
Block(1,13,-2,LOG:13)
Block(2,13,-2,LOG:13)
Block(3,13,-2,LOG:13)
Block(-3,13,-1,LOG:13)
Block(-2,13,-1,LOG:13)
Block(-1,13,-1,LOG:13)
Block(0,13,-1,LOG:13)
Block(1,13,-1,LOG:13)
Block(2,13,-1,LOG:13)
Block(-3,13,0,LOG:13)
Block(-2,13,0,LOG:13)
Block(-1,13,0,LOG:13)
Block(0,13,0,LOG:13)
Block(1,13,0,LOG:13)
Block(2,13,0,LOG:13)
Block(-3,13,1,LOG:13)
Block(-2,13,1,LOG:13)
Block(-1,13,1,LOG:13)
Block(0,13,1,LOG:13)
Block(1,13,1,LOG:13)
Block(2,13,1,LOG:13)
Block(-2,13,2,LOG:13)

#######################################################################
# +-----------------------------------------------------------------+ #
# |                            BO3 checks                           | #
# +-----------------------------------------------------------------+ #
#######################################################################

# Require a condition at a certain location in order for the BO3 to be spawned.
# BlockCheck(x,y,z,BlockName[,BlockName[,...]]) - one of the blocks must be at the location
# BlockCheckNot(x,y,z,BlockName[,BlockName[,...]]) - all the blocks must not be at the location
# LightCheck(x,y,z,minLightLevel,maxLightLevel) - light must be between min and max (inclusive)

# You can use "Solid" as a BlockName for matching all solid blocks or "All" to match all blocks that aren't air.

# Examples:
#   BlockCheck(0,-1,0,GRASS,DIRT)  Require grass or dirt just below the object
#   BlockCheck(0,-1,0,Solid)       Require any solid block just below the object
#   BlockCheck(0,-1,0,WOOL)        Require any type of wool just below the object
#   BlockCheck(0,-1,0,WOOL:0)      Require white wool just below the object
#   BlockCheckNot(0,-1,0,WOOL:0)   Require that there is no white wool below the object
#   LightCheck(0,0,0,0,1)          Require almost complete darkness just below the object

#######################################################################
# +-----------------------------------------------------------------+ #
# |                             Branches                            | #
# +-----------------------------------------------------------------+ #
#######################################################################

# Branches are objects that will spawn when this object spawns when it is used in
# the CustomStructure resource. Branches can also have branches, making complex
# structures possible. See the wiki for more details.

# Regular Branches spawn each branch with an independent chance of spawning.
# Branch(x,y,z,branchName,rotation,chance[,anotherBranchName,rotation,chance[,...]][IndividualChance])
# branchName - name of the object to spawn.
# rotation - NORTH, SOUTH, EAST or WEST.
# IndividualChance - The chance each branch has to spawn, assumed to be 100 when left blank

# Weighted Branches spawn branches with a dependent chance of spawning.
# WeightedBranch(x,y,z,branchName,rotation,chance[,anotherBranchName,rotation,chance[,...]][MaxChanceOutOf])
# MaxChanceOutOf - The chance all branches have to spawn out of, assumed to be 100 when left blank
BlockCheck(3,0,-15,Solid)
BlockCheck(12,0,-15,Solid)
BlockCheck(-10,0,-14,Solid)
BlockCheck(-15,0,-4,Solid)
BlockCheck(13,0,2,Solid)
BlockCheck(0,0,12,Solid)
BlockCheck(10,0,13,Solid)
BlockCheck(-15,0,14,Solid)
BlockCheck(-1,13,-4,Solid)
BlockCheck(3,13,-1,Solid)
BlockCheck(-1,13,2,Solid)
