#######################################################################
# +-----------------------------------------------------------------+ #
# |                            BO3 object                           | #
# +-----------------------------------------------------------------+ #
#######################################################################

Author: Bo3 BulkEdit

Description: Converted Schematic - Modified by Bo3BulkEdit

Version: 3

SettingsMode: WriteDisable

#######################################################################
# +-----------------------------------------------------------------+ #
# |                          Main settings                          | #
# +-----------------------------------------------------------------+ #
#######################################################################

IsOTGPlus: true
Tree: false
Frequency: 1
Rarity: 100.0
RotateRandomly: false
SpawnHeight: randomY
MaxBranchDepth: 10
ExcludedBiomes: All

##############################
# Height Limits for the BO3. #
##############################

MinHeight: 0
MaxHeight: 255

#######################################################################
# +-----------------------------------------------------------------+ #
# |                      Source block settings                      | #
# +-----------------------------------------------------------------+ #
#######################################################################

CanOverride: true
MaxPercentageOutsideSourceBlock: 100
OutsideSourceBlock: placeAnyway

#######################################################################
# +-----------------------------------------------------------------+ #
# |                               OTG+                              | #
# +-----------------------------------------------------------------+ #
#######################################################################

BO3Group: CeilingCrystals:0

#######################################################################
# +-----------------------------------------------------------------+ #
# |                              Blocks                             | #
# +-----------------------------------------------------------------+ #
#######################################################################

B(0,750,0,AIR)
B(15,750,15,AIR)
B(13,-26,13,STAINED_GLASS:15)
B(14,-26,13,STAINED_GLASS:15)
B(13,-26,14,STAINED_GLASS:15)
B(14,-26,14,STAINED_GLASS:15)
B(11,-25,11,STAINED_GLASS:15)
B(12,-25,11,STAINED_GLASS:15)
B(11,-25,12,STAINED_GLASS:15)
B(12,-25,12,STAINED_GLASS:15)
B(13,-25,12,STAINED_GLASS:15)
B(11,-25,13,STAINED_GLASS:15)
B(12,-25,13,STAINED_GLASS:15)
B(13,-25,13,STAINED_GLASS:15)
B(14,-25,13,STAINED_GLASS:15)
B(12,-25,14,STAINED_GLASS:15)
B(13,-25,14,STAINED_GLASS:15)
B(14,-25,14,STAINED_GLASS:15)
B(10,-24,9,STAINED_GLASS:15)
B(11,-24,9,STAINED_GLASS:15)
B(9,-24,10,STAINED_GLASS:15)
B(10,-24,10,STAINED_GLASS:15)
B(11,-24,10,STAINED_GLASS:15)
B(12,-24,10,STAINED_GLASS:15)
B(9,-24,11,STAINED_GLASS:15)
B(10,-24,11,STAINED_GLASS:15)
B(11,-24,11,STAINED_GLASS:15)
B(12,-24,11,STAINED_GLASS:15)
B(13,-24,11,STAINED_GLASS:15)
B(10,-24,12,STAINED_GLASS:15)
B(11,-24,12,STAINED_GLASS:15)
B(12,-24,12,STAINED_GLASS:15)
B(13,-24,12,STAINED_GLASS:15)
B(14,-24,12,STAINED_GLASS:15)
B(11,-24,13,STAINED_GLASS:15)
B(12,-24,13,STAINED_GLASS:15)
B(13,-24,13,STAINED_GLASS:15)
B(14,-24,13,STAINED_GLASS:15)
B(12,-24,14,STAINED_GLASS:15)
B(13,-24,14,STAINED_GLASS:15)
B(10,-23,7,STAINED_GLASS:15)
B(8,-23,8,STAINED_GLASS:15)
B(10,-23,8,STAINED_GLASS:15)
B(11,-23,8,STAINED_GLASS:15)
B(7,-23,9,STAINED_GLASS:15)
B(8,-23,9,STAINED_GLASS:15)
B(9,-23,9,STAINED_GLASS:15)
B(10,-23,9,STAINED_GLASS:15)
B(11,-23,9,STAINED_GLASS:15)
B(7,-23,10,STAINED_GLASS:15)
B(8,-23,10,STAINED_GLASS:15)
B(9,-23,10,STAINED_GLASS:15)
B(10,-23,10,SEA_LANTERN)
B(11,-23,10,STAINED_GLASS:15)
B(12,-23,10,STAINED_GLASS:15)
B(13,-23,10,STAINED_GLASS:15)
B(8,-23,11,STAINED_GLASS:15)
B(9,-23,11,STAINED_GLASS:15)
B(10,-23,11,STAINED_GLASS:15)
B(11,-23,11,SEA_LANTERN)
B(12,-23,11,STAINED_GLASS:15)
B(13,-23,11,STAINED_GLASS:15)
B(9,-23,12,STAINED_GLASS:15)
B(10,-23,12,STAINED_GLASS:15)
B(13,-23,12,STAINED_GLASS:15)
B(10,-23,13,STAINED_GLASS:15)
B(11,-23,13,STAINED_GLASS:15)
B(12,-23,13,STAINED_GLASS:15)
B(13,-23,13,STAINED_GLASS:15)
B(8,-22,6,STAINED_GLASS:15)
B(9,-22,6,STAINED_GLASS:15)
B(7,-22,7,STAINED_GLASS:15)
B(8,-22,7,STAINED_GLASS:15)
B(9,-22,7,STAINED_GLASS:15)
B(10,-22,7,STAINED_GLASS:15)
B(6,-22,8,STAINED_GLASS:15)
B(7,-22,8,STAINED_GLASS:15)
B(8,-22,8,STAINED_GLASS:15)
B(9,-22,8,STAINED_GLASS:2)
B(10,-22,8,STAINED_GLASS:15)
B(11,-22,8,STAINED_GLASS:15)
B(6,-22,9,STAINED_GLASS:15)
B(7,-22,9,STAINED_GLASS:15)
B(8,-22,9,SEA_LANTERN)
B(9,-22,9,SEA_LANTERN)
B(10,-22,9,STAINED_GLASS:15)
B(11,-22,9,STAINED_GLASS:15)
B(12,-22,9,STAINED_GLASS:15)
B(7,-22,10,STAINED_GLASS:15)
B(8,-22,10,STAINED_GLASS:15)
B(9,-22,10,SEA_LANTERN)
B(10,-22,10,SEA_LANTERN)
B(11,-22,10,STAINED_GLASS:15)
B(12,-22,10,STAINED_GLASS:15)
B(13,-22,10,STAINED_GLASS:15)
B(8,-22,11,STAINED_GLASS:15)
B(9,-22,11,STAINED_GLASS:15)
B(10,-22,11,SEA_LANTERN)
B(11,-22,11,STAINED_GLASS:11)
B(12,-22,11,STAINED_GLASS:2)
B(13,-22,11,STAINED_GLASS:15)
B(9,-22,12,STAINED_GLASS:15)
B(10,-22,12,STAINED_GLASS:15)
B(11,-22,12,STAINED_GLASS:15)
B(12,-22,12,STAINED_GLASS:11)
B(13,-22,12,STAINED_GLASS:15)
B(10,-22,13,STAINED_GLASS:15)
B(11,-22,13,STAINED_GLASS:11)
B(12,-22,13,STAINED_GLASS:15)
B(7,-21,5,STAINED_GLASS:15)
B(8,-21,5,STAINED_GLASS:15)
B(6,-21,6,STAINED_GLASS:15)
B(7,-21,6,STAINED_GLASS:15)
B(8,-21,6,STAINED_GLASS:15)
B(9,-21,6,STAINED_GLASS:11)
B(5,-21,7,STAINED_GLASS:15)
B(6,-21,7,STAINED_GLASS:15)
B(7,-21,7,STAINED_GLASS:15)
B(8,-21,7,STAINED_GLASS:2)
B(9,-21,7,STAINED_GLASS:11)
B(10,-21,7,STAINED_GLASS:15)
B(5,-21,8,STAINED_GLASS:15)
B(6,-21,8,STAINED_GLASS:2)
B(7,-21,8,SEA_LANTERN)
B(8,-21,8,SEA_LANTERN)
B(9,-21,8,STAINED_GLASS:11)
B(10,-21,8,STAINED_GLASS:15)
B(11,-21,8,STAINED_GLASS:15)
B(6,-21,9,STAINED_GLASS:15)
B(7,-21,9,STAINED_GLASS:2)
B(8,-21,9,SEA_LANTERN)
B(9,-21,9,SEA_LANTERN)
B(10,-21,9,STAINED_GLASS:15)
B(11,-21,9,STAINED_GLASS:15)
B(12,-21,9,STAINED_GLASS:11)
B(7,-21,10,STAINED_GLASS:11)
B(8,-21,10,STAINED_GLASS:15)
B(9,-21,10,STAINED_GLASS:11)
B(10,-21,10,STAINED_GLASS:15)
B(11,-21,10,STAINED_GLASS:2)
B(12,-21,10,STAINED_GLASS:11)
B(8,-21,11,STAINED_GLASS:11)
B(9,-21,11,STAINED_GLASS:2)
B(10,-21,11,STAINED_GLASS:15)
B(11,-21,11,STAINED_GLASS:11)
B(12,-21,11,STAINED_GLASS:11)
B(9,-21,12,STAINED_GLASS:11)
B(10,-21,12,STAINED_GLASS:11)
B(11,-21,12,STAINED_GLASS:11)
B(6,-20,4,STAINED_GLASS:11)
B(7,-20,4,STAINED_GLASS:11)
B(5,-20,5,STAINED_GLASS:15)
B(6,-20,5,STAINED_GLASS:11)
B(7,-20,5,STAINED_GLASS:11)
B(8,-20,5,STAINED_GLASS:11)
B(4,-20,6,STAINED_GLASS:15)
B(5,-20,6,STAINED_GLASS:15)
B(6,-20,6,STAINED_GLASS:11)
B(7,-20,6,STAINED_GLASS:2)
B(8,-20,6,STAINED_GLASS:11)
B(9,-20,6,STAINED_GLASS:11)
B(4,-20,7,STAINED_GLASS:15)
B(5,-20,7,STAINED_GLASS:2)
B(6,-20,7,STAINED_GLASS:2)
B(7,-20,7,SEA_LANTERN)
B(8,-20,7,SEA_LANTERN)
B(9,-20,7,STAINED_GLASS:11)
B(10,-20,7,STAINED_GLASS:11)
B(5,-20,8,STAINED_GLASS:15)
B(6,-20,8,STAINED_GLASS:2)
B(7,-20,8,STAINED_GLASS:15)
B(8,-20,8,SEA_LANTERN)
B(9,-20,8,STAINED_GLASS:2)
B(10,-20,8,STAINED_GLASS:11)
B(11,-20,8,STAINED_GLASS:11)
B(6,-20,9,STAINED_GLASS:15)
B(7,-20,9,STAINED_GLASS:15)
B(8,-20,9,STAINED_GLASS:11)
B(9,-20,9,STAINED_GLASS:11)
B(10,-20,9,STAINED_GLASS:2)
B(11,-20,9,STAINED_GLASS:11)
B(7,-20,10,STAINED_GLASS:11)
B(8,-20,10,STAINED_GLASS:2)
B(9,-20,10,STAINED_GLASS:11)
B(10,-20,10,STAINED_GLASS:11)
B(11,-20,10,STAINED_GLASS:11)
B(8,-20,11,STAINED_GLASS:11)
B(9,-20,11,STAINED_GLASS:11)
B(10,-20,11,STAINED_GLASS:11)
B(5,-19,3,STAINED_GLASS:15)
B(6,-19,3,STAINED_GLASS:11)
B(4,-19,4,STAINED_GLASS:15)
B(5,-19,4,STAINED_GLASS:11)
B(6,-19,4,STAINED_GLASS:11)
B(7,-19,4,STAINED_GLASS:11)
B(3,-19,5,STAINED_GLASS:15)
B(4,-19,5,STAINED_GLASS:15)
B(5,-19,5,STAINED_GLASS:11)
B(6,-19,5,STAINED_GLASS:2)
B(7,-19,5,STAINED_GLASS:11)
B(8,-19,5,STAINED_GLASS:11)
B(3,-19,6,STAINED_GLASS:15)
B(4,-19,6,STAINED_GLASS:2)
B(5,-19,6,STAINED_GLASS:2)
B(6,-19,6,SEA_LANTERN)
B(7,-19,6,SEA_LANTERN)
B(8,-19,6,STAINED_GLASS:11)
B(9,-19,6,STAINED_GLASS:11)
B(4,-19,7,STAINED_GLASS:15)
B(5,-19,7,STAINED_GLASS:2)
B(6,-19,7,SEA_LANTERN)
B(7,-19,7,SEA_LANTERN)
B(8,-19,7,STAINED_GLASS:2)
B(9,-19,7,STAINED_GLASS:11)
B(10,-19,7,STAINED_GLASS:11)
B(5,-19,8,STAINED_GLASS:15)
B(6,-19,8,STAINED_GLASS:15)
B(7,-19,8,STAINED_GLASS:15)
B(8,-19,8,STAINED_GLASS:15)
B(9,-19,8,STAINED_GLASS:2)
B(10,-19,8,STAINED_GLASS:11)
B(6,-19,9,STAINED_GLASS:11)
B(7,-19,9,STAINED_GLASS:2)
B(8,-19,9,STAINED_GLASS:11)
B(9,-19,9,STAINED_GLASS:11)
B(10,-19,9,STAINED_GLASS:11)
B(7,-19,10,STAINED_GLASS:11)
B(8,-19,10,STAINED_GLASS:11)
B(9,-19,10,STAINED_GLASS:11)
B(4,-18,2,STAINED_GLASS:15)
B(5,-18,2,STAINED_GLASS:11)
B(3,-18,3,STAINED_GLASS:15)
B(4,-18,3,STAINED_GLASS:15)
B(5,-18,3,STAINED_GLASS:11)
B(6,-18,3,STAINED_GLASS:11)
B(2,-18,4,STAINED_GLASS:15)
B(3,-18,4,STAINED_GLASS:15)
B(4,-18,4,STAINED_GLASS:15)
B(5,-18,4,STAINED_GLASS:2)
B(6,-18,4,STAINED_GLASS:11)
B(7,-18,4,STAINED_GLASS:11)
B(2,-18,5,STAINED_GLASS:15)
B(3,-18,5,STAINED_GLASS:2)
B(4,-18,5,STAINED_GLASS:2)
B(5,-18,5,SEA_LANTERN)
B(6,-18,5,SEA_LANTERN)
B(7,-18,5,STAINED_GLASS:11)
B(8,-18,5,STAINED_GLASS:11)
B(3,-18,6,STAINED_GLASS:15)
B(4,-18,6,STAINED_GLASS:2)
B(5,-18,6,SEA_LANTERN)
B(6,-18,6,SEA_LANTERN)
B(7,-18,6,STAINED_GLASS:2)
B(8,-18,6,STAINED_GLASS:11)
B(9,-18,6,STAINED_GLASS:11)
B(4,-18,7,STAINED_GLASS:15)
B(5,-18,7,SEA_LANTERN)
B(6,-18,7,STAINED_GLASS:2)
B(7,-18,7,STAINED_GLASS:11)
B(8,-18,7,STAINED_GLASS:2)
B(9,-18,7,STAINED_GLASS:11)
B(5,-18,8,STAINED_GLASS:15)
B(6,-18,8,STAINED_GLASS:2)
B(7,-18,8,STAINED_GLASS:15)
B(8,-18,8,STAINED_GLASS:11)
B(9,-18,8,STAINED_GLASS:11)
B(6,-18,9,STAINED_GLASS:11)
B(7,-18,9,STAINED_GLASS:11)
B(8,-18,9,STAINED_GLASS:11)
B(3,-17,1,STAINED_GLASS:11)
B(4,-17,1,STAINED_GLASS:11)
B(2,-17,2,STAINED_GLASS:15)
B(3,-17,2,STAINED_GLASS:11)
B(4,-17,2,STAINED_GLASS:11)
B(5,-17,2,STAINED_GLASS:11)
B(1,-17,3,STAINED_GLASS:15)
B(2,-17,3,STAINED_GLASS:15)
B(3,-17,3,STAINED_GLASS:15)
B(4,-17,3,STAINED_GLASS:2)
B(5,-17,3,STAINED_GLASS:11)
B(6,-17,3,STAINED_GLASS:11)
B(1,-17,4,STAINED_GLASS:15)
B(2,-17,4,STAINED_GLASS:2)
B(3,-17,4,STAINED_GLASS:2)
B(4,-17,4,SEA_LANTERN)
B(5,-17,4,SEA_LANTERN)
B(6,-17,4,STAINED_GLASS:11)
B(7,-17,4,STAINED_GLASS:11)
B(2,-17,5,STAINED_GLASS:15)
B(3,-17,5,STAINED_GLASS:2)
B(4,-17,5,SEA_LANTERN)
B(5,-17,5,SEA_LANTERN)
B(6,-17,5,STAINED_GLASS:2)
B(7,-17,5,STAINED_GLASS:11)
B(8,-17,5,STAINED_GLASS:11)
B(3,-17,6,STAINED_GLASS:15)
B(4,-17,6,STAINED_GLASS:15)
B(5,-17,6,STAINED_GLASS:2)
B(6,-17,6,STAINED_GLASS:11)
B(7,-17,6,STAINED_GLASS:2)
B(8,-17,6,STAINED_GLASS:11)
B(4,-17,7,STAINED_GLASS:15)
B(5,-17,7,STAINED_GLASS:2)
B(6,-17,7,STAINED_GLASS:2)
B(7,-17,7,STAINED_GLASS:11)
B(8,-17,7,STAINED_GLASS:11)
B(5,-17,8,STAINED_GLASS:11)
B(6,-17,8,STAINED_GLASS:11)
B(7,-17,8,STAINED_GLASS:11)
B(2,-16,0,STAINED_GLASS:11)
B(3,-16,0,STAINED_GLASS:11)
B(1,-16,1,STAINED_GLASS:15)
B(2,-16,1,STAINED_GLASS:11)
B(3,-16,1,STAINED_GLASS:11)
B(4,-16,1,STAINED_GLASS:11)
B(0,-16,2,STAINED_GLASS:15)
B(1,-16,2,STAINED_GLASS:15)
B(2,-16,2,STAINED_GLASS:15)
B(3,-16,2,STAINED_GLASS:2)
B(4,-16,2,STAINED_GLASS:11)
B(5,-16,2,STAINED_GLASS:11)
B(0,-16,3,STAINED_GLASS:15)
B(1,-16,3,STAINED_GLASS:2)
B(2,-16,3,STAINED_GLASS:2)
B(3,-16,3,SEA_LANTERN)
B(4,-16,3,SEA_LANTERN)
B(5,-16,3,STAINED_GLASS:11)
B(6,-16,3,STAINED_GLASS:11)
B(1,-16,4,STAINED_GLASS:15)
B(2,-16,4,STAINED_GLASS:2)
B(3,-16,4,SEA_LANTERN)
B(4,-16,4,SEA_LANTERN)
B(5,-16,4,STAINED_GLASS:2)
B(6,-16,4,STAINED_GLASS:11)
B(7,-16,4,STAINED_GLASS:11)
B(2,-16,5,STAINED_GLASS:15)
B(3,-16,5,STAINED_GLASS:15)
B(4,-16,5,STAINED_GLASS:2)
B(5,-16,5,STAINED_GLASS:11)
B(6,-16,5,STAINED_GLASS:2)
B(7,-16,5,STAINED_GLASS:11)
B(3,-16,6,STAINED_GLASS:15)
B(4,-16,6,STAINED_GLASS:2)
B(5,-16,6,STAINED_GLASS:2)
B(6,-16,6,STAINED_GLASS:11)
B(7,-16,6,STAINED_GLASS:11)
B(4,-16,7,STAINED_GLASS:15)
B(5,-16,7,STAINED_GLASS:15)
B(6,-16,7,STAINED_GLASS:11)
B(0,-15,0,STAINED_GLASS:15)
B(1,-15,0,STAINED_GLASS:11)
B(2,-15,0,STAINED_GLASS:2)
B(3,-15,0,STAINED_GLASS:11)
B(0,-15,1,STAINED_GLASS:15)
B(1,-15,1,STAINED_GLASS:15)
B(2,-15,1,STAINED_GLASS:2)
B(3,-15,1,STAINED_GLASS:11)
B(4,-15,1,STAINED_GLASS:11)
B(0,-15,2,STAINED_GLASS:2)
B(1,-15,2,STAINED_GLASS:2)
B(2,-15,2,SEA_LANTERN)
B(3,-15,2,SEA_LANTERN)
B(4,-15,2,STAINED_GLASS:11)
B(5,-15,2,STAINED_GLASS:11)
B(0,-15,3,STAINED_GLASS:15)
B(1,-15,3,STAINED_GLASS:2)
B(2,-15,3,SEA_LANTERN)
B(3,-15,3,SEA_LANTERN)
B(4,-15,3,STAINED_GLASS:2)
B(5,-15,3,STAINED_GLASS:11)
B(6,-15,3,STAINED_GLASS:11)
B(1,-15,4,STAINED_GLASS:15)
B(2,-15,4,SEA_LANTERN)
B(3,-15,4,STAINED_GLASS:2)
B(4,-15,4,STAINED_GLASS:11)
B(5,-15,4,STAINED_GLASS:2)
B(6,-15,4,STAINED_GLASS:11)
B(2,-15,5,STAINED_GLASS:15)
B(3,-15,5,STAINED_GLASS:2)
B(4,-15,5,STAINED_GLASS:2)
B(5,-15,5,STAINED_GLASS:11)
B(6,-15,5,STAINED_GLASS:11)
B(3,-15,6,STAINED_GLASS:15)
B(4,-15,6,STAINED_GLASS:15)
B(5,-15,6,STAINED_GLASS:15)
B(0,-14,0,STAINED_GLASS:11)
B(1,-14,0,STAINED_GLASS:2)
B(2,-14,0,STAINED_GLASS:2)
B(3,-14,0,STAINED_GLASS:11)
B(0,-14,1,STAINED_GLASS:2)
B(1,-14,1,SEA_LANTERN)
B(2,-14,1,SEA_LANTERN)
B(3,-14,1,STAINED_GLASS:11)
B(4,-14,1,STAINED_GLASS:11)
B(0,-14,2,STAINED_GLASS:2)
B(1,-14,2,SEA_LANTERN)
B(2,-14,2,SEA_LANTERN)
B(3,-14,2,STAINED_GLASS:2)
B(4,-14,2,STAINED_GLASS:11)
B(5,-14,2,STAINED_GLASS:11)
B(0,-14,3,STAINED_GLASS:15)
B(1,-14,3,STAINED_GLASS:15)
B(2,-14,3,STAINED_GLASS:2)
B(3,-14,3,STAINED_GLASS:11)
B(4,-14,3,STAINED_GLASS:2)
B(5,-14,3,STAINED_GLASS:11)
B(1,-14,4,STAINED_GLASS:15)
B(2,-14,4,STAINED_GLASS:2)
B(3,-14,4,STAINED_GLASS:2)
B(4,-14,4,STAINED_GLASS:11)
B(5,-14,4,STAINED_GLASS:11)
B(2,-14,5,STAINED_GLASS:15)
B(3,-14,5,STAINED_GLASS:15)
B(4,-14,5,STAINED_GLASS:15)
B(0,-13,0,SEA_LANTERN)
B(1,-13,0,SEA_LANTERN)
B(2,-13,0,STAINED_GLASS:11)
B(3,-13,0,STAINED_GLASS:11)
B(0,-13,1,SEA_LANTERN)
B(1,-13,1,STAINED_GLASS:11)
B(2,-13,1,STAINED_GLASS:2)
B(3,-13,1,STAINED_GLASS:11)
B(4,-13,1,STAINED_GLASS:11)
B(0,-13,2,STAINED_GLASS:15)
B(1,-13,2,STAINED_GLASS:2)
B(2,-13,2,STAINED_GLASS:11)
B(3,-13,2,STAINED_GLASS:2)
B(4,-13,2,STAINED_GLASS:11)
B(0,-13,3,STAINED_GLASS:15)
B(1,-13,3,STAINED_GLASS:2)
B(2,-13,3,STAINED_GLASS:2)
B(3,-13,3,STAINED_GLASS:11)
B(4,-13,3,STAINED_GLASS:11)
B(1,-13,4,STAINED_GLASS:15)
B(2,-13,4,STAINED_GLASS:15)
B(3,-13,4,STAINED_GLASS:15)
B(0,-12,0,SEA_LANTERN)
B(1,-12,0,STAINED_GLASS:2)
B(2,-12,0,STAINED_GLASS:2)
B(3,-12,0,STAINED_GLASS:11)
B(0,-12,1,STAINED_GLASS:2)
B(1,-12,1,STAINED_GLASS:11)
B(2,-12,1,STAINED_GLASS:2)
B(3,-12,1,STAINED_GLASS:11)
B(0,-12,2,STAINED_GLASS:2)
B(1,-12,2,STAINED_GLASS:2)
B(2,-12,2,STAINED_GLASS:11)
B(3,-12,2,STAINED_GLASS:11)
B(0,-12,3,STAINED_GLASS:15)
B(1,-12,3,STAINED_GLASS:15)
B(2,-12,3,STAINED_GLASS:15)
B(0,-11,0,STAINED_GLASS:11)
B(1,-11,0,STAINED_GLASS:2)
B(2,-11,0,STAINED_GLASS:11)
B(0,-11,1,STAINED_GLASS:2)
B(1,-11,1,STAINED_GLASS:15)
B(2,-11,1,STAINED_GLASS:11)
B(0,-11,2,STAINED_GLASS:15)
B(1,-11,2,STAINED_GLASS:15)
B(0,-10,0,STAINED_GLASS:15)
B(1,-10,0,STAINED_GLASS:15)
B(0,-10,1,STAINED_GLASS:15)

