Author: Bo3 BulkEdit

Description: Converted Schematic - Modified by Bo3BulkEdit

Version: 3

SettingsMode: WriteDisable

IsOTGPlus: false
Tree: false
Frequency: 1
Rarity: 100
RotateRandomly: false
SpawnHeight: randomY
MaxBranchDepth: 20
ExcludedBiomes: All

MinHeight: 0
MaxHeight: 256

SourceBlocks: AIR
MaxPercentageOutsideSourceBlock: 100
OutsideSourceBlock: placeAnyway

B(-4,-54,-6,LOG:1)
B(-1,-54,-6,LOG:1)
B(-4,-54,-3,LOG:1)
B(-1,-54,-3,LOG:1)
B(-4,-53,-6,LOG:1)
B(-1,-53,-6,LOG:1)
B(-4,-53,-3,LOG:1)
B(-1,-53,-3,LOG:1)
B(-4,-53,-2,LOG:9)
B(-1,-53,-2,LOG:9)
B(-4,-53,-1,LOG:9)
B(-1,-53,-1,LOG:9)
B(-4,-52,-6,LOG:1)
B(-3,-52,-6,LOG:5)
B(-2,-52,-6,LOG:5)
B(-1,-52,-6,LOG:1)
B(-4,-52,-5,LOG:9)
B(-4,-52,-4,LOG:9)
B(-4,-52,-3,LOG:1)
B(-3,-52,-3,LOG:5)
B(-2,-52,-3,LOG:5)
B(-1,-52,-3,LOG:1)
B(-1,-51,-8,LOG:9)
B(-1,-51,-7,LOG:9)
B(-4,-51,-6,LOG:1)
B(-1,-51,-6,LOG:1)
B(-1,-51,-5,LOG:9)
B(-1,-51,-4,LOG:9)
B(-4,-51,-3,LOG:1)
B(-1,-51,-3,LOG:1)
B(-4,-51,-2,LOG:9)
B(-4,-51,-1,LOG:9)
B(-4,-50,-6,LOG:1)
B(-1,-50,-6,LOG:1)
B(-4,-50,-3,LOG:1)
B(-1,-50,-3,LOG:1)
B(-4,-49,-6,LOG:1)
B(-1,-49,-6,LOG:1)
B(-4,-49,-3,LOG:1)
B(-1,-49,-3,LOG:1)
B(-4,-49,-2,LOG:9)
B(-1,-49,-2,LOG:9)
B(-4,-49,-1,LOG:9)
B(-1,-49,-1,LOG:9)
B(-4,-48,-6,LOG:1)
B(-3,-48,-6,LOG:5)
B(-2,-48,-6,LOG:5)
B(-1,-48,-6,LOG:1)
B(-4,-48,-5,LOG:9)
B(-4,-48,-4,LOG:9)
B(-4,-48,-3,LOG:1)
B(-3,-48,-3,LOG:5)
B(-2,-48,-3,LOG:5)
B(-1,-48,-3,LOG:1)
B(-1,-47,-8,LOG:9)
B(-1,-47,-7,LOG:9)
B(-4,-47,-6,LOG:1)
B(-1,-47,-6,LOG:1)
B(-1,-47,-5,LOG:9)
B(-1,-47,-4,LOG:9)
B(-4,-47,-3,LOG:1)
B(-1,-47,-3,LOG:1)
B(-4,-47,-2,LOG:9)
B(-4,-47,-1,LOG:9)
B(-4,-46,-6,LOG:1)
B(-1,-46,-6,LOG:1)
B(-4,-46,-3,LOG:1)
B(-1,-46,-3,LOG:1)
B(-4,-45,-6,LOG:1)
B(-1,-45,-6,LOG:1)
B(-4,-45,-3,LOG:1)
B(-1,-45,-3,LOG:1)
B(-4,-45,-2,LOG:9)
B(-1,-45,-2,LOG:9)
B(-4,-45,-1,LOG:9)
B(-1,-45,-1,LOG:9)
B(-4,-44,-6,LOG:1)
B(-3,-44,-6,LOG:5)
B(-2,-44,-6,LOG:5)
B(-1,-44,-6,LOG:1)
B(-4,-44,-5,LOG:9)
B(-4,-44,-4,LOG:9)
B(-4,-44,-3,LOG:1)
B(-3,-44,-3,LOG:5)
B(-2,-44,-3,LOG:5)
B(-1,-44,-3,LOG:1)
B(-1,-43,-8,LOG:9)
B(-1,-43,-7,LOG:9)
B(-4,-43,-6,LOG:1)
B(-1,-43,-6,LOG:1)
B(-1,-43,-5,LOG:9)
B(-1,-43,-4,LOG:9)
B(-4,-43,-3,LOG:1)
B(-1,-43,-3,LOG:1)
B(-4,-43,-2,LOG:9)
B(-4,-43,-1,LOG:9)
B(-4,-42,-6,LOG:1)
B(-1,-42,-6,LOG:1)
B(-4,-42,-3,LOG:1)
B(-1,-42,-3,LOG:1)
B(-4,-41,-6,LOG:1)
B(-1,-41,-6,LOG:1)
B(-4,-41,-3,LOG:1)
B(-1,-41,-3,LOG:1)
B(-4,-41,-2,LOG:9)
B(-1,-41,-2,LOG:9)
B(-4,-41,-1,LOG:9)
B(-1,-41,-1,LOG:9)
B(-4,-40,-6,LOG:1)
B(-3,-40,-6,LOG:5)
B(-2,-40,-6,LOG:5)
B(-1,-40,-6,LOG:1)
B(-4,-40,-5,LOG:9)
B(-4,-40,-4,LOG:9)
B(-4,-40,-3,LOG:1)
B(-3,-40,-3,LOG:5)
B(-2,-40,-3,LOG:5)
B(-1,-40,-3,LOG:1)
B(-1,-39,-8,LOG:9)
B(-1,-39,-7,LOG:9)
B(-4,-39,-6,LOG:1)
B(-1,-39,-6,LOG:1)
B(-1,-39,-5,LOG:9)
B(-1,-39,-4,LOG:9)
B(-4,-39,-3,LOG:1)
B(-1,-39,-3,LOG:1)
B(-4,-39,-2,LOG:9)
B(-4,-39,-1,LOG:9)
B(-4,-38,-6,LOG:1)
B(-1,-38,-6,LOG:1)
B(-4,-38,-3,LOG:1)
B(-1,-38,-3,LOG:1)
B(-4,-37,-6,LOG:1)
B(-1,-37,-6,LOG:1)
B(-4,-37,-3,LOG:1)
B(-1,-37,-3,LOG:1)
B(-4,-37,-2,LOG:9)
B(-1,-37,-2,LOG:9)
B(-4,-37,-1,LOG:9)
B(-1,-37,-1,LOG:9)
B(-4,-36,-6,LOG:1)
B(-3,-36,-6,LOG:5)
B(-2,-36,-6,LOG:5)
B(-1,-36,-6,LOG:1)
B(-4,-36,-5,LOG:9)
B(-4,-36,-4,LOG:9)
B(-4,-36,-3,LOG:1)
B(-3,-36,-3,LOG:5)
B(-2,-36,-3,LOG:5)
B(-1,-36,-3,LOG:1)
B(-1,-35,-8,LOG:9)
B(-1,-35,-7,LOG:9)
B(-4,-35,-6,LOG:1)
B(-1,-35,-6,LOG:1)
B(-1,-35,-5,LOG:9)
B(-1,-35,-4,LOG:9)
B(-4,-35,-3,LOG:1)
B(-1,-35,-3,LOG:1)
B(-4,-35,-2,LOG:9)
B(-4,-35,-1,LOG:9)
B(-4,-34,-6,LOG:1)
B(-1,-34,-6,LOG:1)
B(-4,-34,-3,LOG:1)
B(-1,-34,-3,LOG:1)
B(-4,-33,-6,LOG:1)
B(-1,-33,-6,LOG:1)
B(-4,-33,-3,LOG:1)
B(-1,-33,-3,LOG:1)
B(-4,-33,-2,LOG:9)
B(-1,-33,-2,LOG:9)
B(-4,-33,-1,LOG:9)
B(-1,-33,-1,LOG:9)
B(-4,-32,-6,LOG:1)
B(-3,-32,-6,LOG:5)
B(-2,-32,-6,LOG:5)
B(-1,-32,-6,LOG:1)
B(-4,-32,-5,LOG:9)
B(-4,-32,-4,LOG:9)
B(-4,-32,-3,LOG:1)
B(-3,-32,-3,LOG:5)
B(-2,-32,-3,LOG:5)
B(-1,-32,-3,LOG:1)
B(-1,-31,-8,LOG:9)
B(-1,-31,-7,LOG:9)
B(-4,-31,-6,LOG:1)
B(-1,-31,-6,LOG:1)
B(-1,-31,-5,LOG:9)
B(-1,-31,-4,LOG:9)
B(-4,-31,-3,LOG:1)
B(-1,-31,-3,LOG:1)
B(-4,-31,-2,LOG:9)
B(-4,-31,-1,LOG:9)
B(-4,-30,-6,LOG:1)
B(-1,-30,-6,LOG:1)
B(-4,-30,-3,LOG:1)
B(-1,-30,-3,LOG:1)
B(-4,-29,-6,LOG:1)
B(-1,-29,-6,LOG:1)
B(-4,-29,-3,LOG:1)
B(-1,-29,-3,LOG:1)
B(-4,-29,-2,LOG:9)
B(-1,-29,-2,LOG:9)
B(-4,-29,-1,LOG:9)
B(-1,-29,-1,LOG:9)
B(-4,-28,-6,LOG:1)
B(-3,-28,-6,LOG:5)
B(-2,-28,-6,LOG:5)
B(-1,-28,-6,LOG:1)
B(-4,-28,-5,LOG:9)
B(-4,-28,-4,LOG:9)
B(-4,-28,-3,LOG:1)
B(-3,-28,-3,LOG:5)
B(-2,-28,-3,LOG:5)
B(-1,-28,-3,LOG:1)
B(-1,-27,-8,LOG:9)
B(-1,-27,-7,LOG:9)
B(-4,-27,-6,LOG:1)
B(-1,-27,-6,LOG:1)
B(-1,-27,-5,LOG:9)
B(-1,-27,-4,LOG:9)
B(-4,-27,-3,LOG:1)
B(-1,-27,-3,LOG:1)
B(-4,-27,-2,LOG:9)
B(-4,-27,-1,LOG:9)
B(-4,-26,-6,LOG:1)
B(-1,-26,-6,LOG:1)
B(-4,-26,-3,LOG:1)
B(-1,-26,-3,LOG:1)
B(-4,-25,-6,LOG:1)
B(-1,-25,-6,LOG:1)
B(-4,-25,-3,LOG:1)
B(-1,-25,-3,LOG:1)
B(-4,-25,-2,LOG:9)
B(-1,-25,-2,LOG:9)
B(-4,-25,-1,LOG:9)
B(-1,-25,-1,LOG:9)
B(-4,-24,-6,LOG:1)
B(-3,-24,-6,LOG:5)
B(-2,-24,-6,LOG:5)
B(-1,-24,-6,LOG:1)
B(-4,-24,-5,LOG:9)
B(-4,-24,-4,LOG:9)
B(-4,-24,-3,LOG:1)
B(-3,-24,-3,LOG:5)
B(-2,-24,-3,LOG:5)
B(-1,-24,-3,LOG:1)
B(-1,-23,-8,LOG:9)
B(-1,-23,-7,LOG:9)
B(-4,-23,-6,LOG:1)
B(-1,-23,-6,LOG:1)
B(-1,-23,-5,LOG:9)
B(-1,-23,-4,LOG:9)
B(-4,-23,-3,LOG:1)
B(-1,-23,-3,LOG:1)
B(-4,-23,-2,LOG:9)
B(-4,-23,-1,LOG:9)
B(-4,-22,-6,LOG:1)
B(-1,-22,-6,LOG:1)
B(-4,-22,-3,LOG:1)
B(-1,-22,-3,LOG:1)
B(-4,-21,-6,LOG:1)
B(-1,-21,-6,LOG:1)
B(-4,-21,-3,LOG:1)
B(-1,-21,-3,LOG:1)
B(-4,-21,-2,LOG:9)
B(-1,-21,-2,LOG:9)
B(-4,-21,-1,LOG:9)
B(-1,-21,-1,LOG:9)
B(-4,-20,-6,LOG:1)
B(-3,-20,-6,LOG:5)
B(-2,-20,-6,LOG:5)
B(-1,-20,-6,LOG:1)
B(-4,-20,-5,LOG:9)
B(-4,-20,-4,LOG:9)
B(-4,-20,-3,LOG:1)
B(-3,-20,-3,LOG:5)
B(-2,-20,-3,LOG:5)
B(-1,-20,-3,LOG:1)
B(-1,-19,-8,LOG:9)
B(-1,-19,-7,LOG:9)
B(-4,-19,-6,LOG:1)
B(-1,-19,-6,LOG:1)
B(-1,-19,-5,LOG:9)
B(-1,-19,-4,LOG:9)
B(-4,-19,-3,LOG:1)
B(-1,-19,-3,LOG:1)
B(-4,-19,-2,LOG:9)
B(-4,-19,-1,LOG:9)
B(-4,-18,-6,LOG:1)
B(-1,-18,-6,LOG:1)
B(-4,-18,-3,LOG:1)
B(-1,-18,-3,LOG:1)
B(-4,-17,-6,LOG:1)
B(-1,-17,-6,LOG:1)
B(-4,-17,-3,LOG:1)
B(-1,-17,-3,LOG:1)
B(-4,-17,-2,LOG:9)
B(-1,-17,-2,LOG:9)
B(-4,-17,-1,LOG:9)
B(-1,-17,-1,LOG:9)
B(-4,-16,-6,LOG:1)
B(-3,-16,-6,LOG:5)
B(-2,-16,-6,LOG:5)
B(-1,-16,-6,LOG:1)
B(-4,-16,-5,LOG:9)
B(-4,-16,-4,LOG:9)
B(-4,-16,-3,LOG:1)
B(-3,-16,-3,LOG:5)
B(-2,-16,-3,LOG:5)
B(-1,-16,-3,LOG:1)
B(-1,-15,-8,LOG:9)
B(-1,-15,-7,LOG:9)
B(-4,-15,-6,LOG:1)
B(-1,-15,-6,LOG:1)
B(-1,-15,-5,LOG:9)
B(-1,-15,-4,LOG:9)
B(-4,-15,-3,LOG:1)
B(-1,-15,-3,LOG:1)
B(-4,-15,-2,LOG:9)
B(-4,-15,-1,LOG:9)
B(-4,-14,-6,LOG:1)
B(-1,-14,-6,LOG:1)
B(-4,-14,-3,LOG:1)
B(-1,-14,-3,LOG:1)
B(-4,-13,-6,LOG:1)
B(-1,-13,-6,LOG:1)
B(-4,-13,-3,LOG:1)
B(-1,-13,-3,LOG:1)
B(-4,-13,-2,LOG:9)
B(-1,-13,-2,LOG:9)
B(-4,-13,-1,LOG:9)
B(-1,-13,-1,LOG:9)
B(-4,-12,-6,LOG:1)
B(-3,-12,-6,LOG:5)
B(-2,-12,-6,LOG:5)
B(-1,-12,-6,LOG:1)
B(-4,-12,-5,LOG:9)
B(-4,-12,-4,LOG:9)
B(-4,-12,-3,LOG:1)
B(-3,-12,-3,LOG:5)
B(-2,-12,-3,LOG:5)
B(-1,-12,-3,LOG:1)
B(-1,-11,-8,LOG:9)
B(-1,-11,-7,LOG:9)
B(-4,-11,-6,LOG:1)
B(-1,-11,-6,LOG:1)
B(-1,-11,-5,LOG:9)
B(-1,-11,-4,LOG:9)
B(-4,-11,-3,LOG:1)
B(-1,-11,-3,LOG:1)
B(-4,-11,-2,LOG:9)
B(-4,-11,-1,LOG:9)
B(-4,-10,-6,LOG:1)
B(-1,-10,-6,LOG:1)
B(-4,-10,-3,LOG:1)
B(-1,-10,-3,LOG:1)
B(-4,-9,-6,LOG:1)
B(-1,-9,-6,LOG:1)
B(-4,-9,-3,LOG:1)
B(-1,-9,-3,LOG:1)
B(-4,-9,-2,LOG:9)
B(-1,-9,-2,LOG:9)
B(-4,-9,-1,LOG:9)
B(-1,-9,-1,LOG:9)
B(-4,-8,-6,LOG:1)
B(-3,-8,-6,LOG:5)
B(-2,-8,-6,LOG:5)
B(-1,-8,-6,LOG:1)
B(-4,-8,-5,LOG:9)
B(-4,-8,-4,LOG:9)
B(-4,-8,-3,LOG:1)
B(-3,-8,-3,LOG:5)
B(-2,-8,-3,LOG:5)
B(-1,-8,-3,LOG:1)
B(-1,-7,-8,LOG:9)
B(-1,-7,-7,LOG:9)
B(-4,-7,-6,LOG:1)
B(-1,-7,-6,LOG:1)
B(-1,-7,-5,LOG:9)
B(-1,-7,-4,LOG:9)
B(-4,-7,-3,LOG:1)
B(-1,-7,-3,LOG:1)
B(-4,-7,-2,LOG:9)
B(-4,-7,-1,LOG:9)
B(-1,-6,-8,LOG:9)
B(-1,-6,-7,LOG:9)
B(-4,-6,-6,LOG:1)
B(-1,-6,-6,LOG:1)
B(-1,-6,-5,LOG:9)
B(-1,-6,-4,LOG:9)
B(-4,-6,-3,LOG:1)
B(-1,-6,-3,LOG:1)
B(-4,-6,-2,LOG:9)
B(-4,-6,-1,LOG:9)
B(-4,-5,-6,LOG:1)
B(-1,-5,-6,LOG:1)
B(-4,-5,-3,LOG:1)
B(-1,-5,-3,LOG:1)
B(-4,-5,-1,LOG:1)
B(-4,-4,-6,LOG:1)
B(-1,-4,-6,LOG:1)
B(-4,-4,-3,LOG:1)
B(-1,-4,-3,LOG:1)
B(-5,-4,-1,LADDER:4)
B(-4,-4,-1,LOG:1)
B(-1,-3,-8,LOG:9)
B(-4,-3,-7,WOODEN_BUTTON:4)
B(-2,-3,-7,WOODEN_BUTTON:2)
B(-1,-3,-7,LOG:9)
B(-5,-3,-6,WOODEN_BUTTON:2)
B(-4,-3,-6,LOG:1)
B(-3,-3,-6,LOG:5)
B(-2,-3,-6,LOG:5)
B(-1,-3,-6,LOG:1)
B(-4,-3,-5,LOG:9)
B(-3,-3,-5,WOODEN_SLAB:8)
B(-2,-3,-5,WOODEN_SLAB:8)
B(-1,-3,-5,DOUBLE_WOODEN_SLAB:0)
B(-4,-3,-4,LOG:9)
B(-3,-3,-4,WOODEN_SLAB:8)
B(-2,-3,-4,WOODEN_SLAB:8)
B(-1,-3,-4,DOUBLE_WOODEN_SLAB:0)
B(-5,-3,-3,WOODEN_BUTTON:2)
B(-4,-3,-3,LOG:1)
B(-3,-3,-3,DOUBLE_WOODEN_SLAB:0)
B(-2,-3,-3,DOUBLE_WOODEN_SLAB:0)
B(-1,-3,-3,LOG:1)
B(-4,-3,-2,LOG:9)
B(-3,-3,-2,WOODEN_SLAB:8)
B(-2,-3,-2,WOODEN_SLAB:8)
B(-1,-3,-2,DOUBLE_WOODEN_SLAB:0)
B(-5,-3,-1,LADDER:4)
B(-4,-3,-1,LOG:9)
B(-3,-3,-1,WOODEN_SLAB:8)
B(-2,-3,-1,WOODEN_SLAB:8)
B(-1,-3,-1,DOUBLE_WOODEN_SLAB:0)
B(-1,-2,-7,DARK_OAK_STAIRS:2)
B(-4,-2,-6,COBBLESTONE_WALL:0)
B(-3,-2,-6,DARK_OAK_STAIRS:1)
B(-2,-2,-6,DARK_OAK_STAIRS:0)
B(-1,-2,-6,COBBLESTONE_WALL:0)
B(-4,-2,-5,DARK_OAK_STAIRS:3)
B(-4,-2,-4,DARK_OAK_STAIRS:2)
B(-4,-2,-3,COBBLESTONE_WALL:0)
B(-4,-2,-2,DARK_OAK_STAIRS:3)

BR(-8,0,0,WestPortShipAgile_4x1,NORTH,100)
