Author: Bo3 BulkEdit

Description: Converted Schematic - Modified by Bo3BulkEdit

Version: 3

SettingsMode: WriteDisable

IsOTGPlus: false
Tree: false
Frequency: 1
Rarity: 100
RotateRandomly: false
SpawnHeight: randomY
MaxBranchDepth: 20
ExcludedBiomes: All

MinHeight: 0
MaxHeight: 256

SourceBlocks: AIR
MaxPercentageOutsideSourceBlock: 100
OutsideSourceBlock: placeAnyway

B(-8,-6,-8,PLANKS:1)
B(-7,-6,-8,PLANKS:1)
B(-6,-6,-8,PLANKS:1)
B(-5,-6,-8,PLANKS:1)
B(-8,-6,-7,PLANKS:1)
B(-7,-6,-7,PLANKS:1)
B(-8,-5,-8,CAULDRON:3)
B(-7,-5,-8,CAULDRON:3)
B(-6,-5,-8,CAULDRON:3)
B(-5,-5,-8,CAULDRON:3)
B(-4,-5,-8,PLANKS:1)
B(-8,-5,-7,CAULDRON:3)
B(-7,-5,-7,CAULDRON:3)
B(-6,-5,-7,PLANKS:1)
B(-5,-5,-7,PLANKS:1)
B(-8,-5,-6,PLANKS:1)
B(-7,-5,-6,PLANKS:1)
B(-6,-5,-6,PLANKS:1)
B(-8,-4,-8,WOODEN_SLAB:8)
B(-7,-4,-8,WOODEN_SLAB:8)
B(-6,-4,-8,WOODEN_SLAB:8)
B(-5,-4,-8,WOODEN_SLAB:8)
B(-4,-4,-8,PLANKS:1)
B(-8,-4,-7,WOODEN_SLAB:8)
B(-7,-4,-7,WOODEN_SLAB:8)
B(-6,-4,-7,WOODEN_SLAB:8)
B(-5,-4,-7,PLANKS:1)
B(-4,-4,-7,WOODEN_SLAB:9)
B(-8,-4,-6,PLANKS:1)
B(-7,-4,-6,PLANKS:1)
B(-6,-4,-6,PLANKS:1)
B(-5,-4,-6,PLANKS:1)
B(-8,-3,-8,PLANKS:5)
B(-7,-3,-8,WOODEN_SLAB:0)
B(-6,-3,-8,WOODEN_SLAB:0)
B(-5,-3,-8,WOODEN_SLAB:0)
B(-4,-3,-8,WOODEN_SLAB:0)
B(-3,-3,-8,DARK_OAK_STAIRS:5)
B(-8,-3,-7,PLANKS:5)
B(-7,-3,-7,WOODEN_SLAB:0)
B(-6,-3,-7,BED:0)
B(-5,-3,-7,BED:0)
B(-4,-3,-7,WOODEN_SLAB:0)
B(-3,-3,-7,DARK_OAK_STAIRS:5)
B(-8,-3,-6,PLANKS:5)
B(-7,-3,-6,PLANKS:5)
B(-6,-3,-6,BED:8)
B(-5,-3,-6,BED:8)
B(-4,-3,-6,PLANKS:5)
B(-3,-3,-6,DARK_OAK_STAIRS:5)
B(-7,-3,-5,DARK_OAK_STAIRS:4)
B(-6,-3,-5,DARK_OAK_STAIRS:7)
B(-5,-3,-5,DARK_OAK_STAIRS:7)
B(-4,-3,-5,DARK_OAK_STAIRS:7)
B(-3,-3,-5,DARK_OAK_STAIRS:5)
B(-8,-2,-8,PLANKS:0)
B(-3,-2,-8,STAINED_GLASS_PANE:15)
B(-8,-2,-7,PLANKS:0)
B(-3,-2,-7,PLANKS:0)
B(-2,-2,-7,DARK_OAK_FENCE:0)
B(-8,-2,-6,PLANKS:0)
RB(-7,-2,-6,SKULL:1,../NBT/Skulls/dungeon_skull_01.nbt,6,SKULL:1,../NBT/Skulls/dungeon_skull_02.nbt,12,SKULL:1,../NBT/Skulls/dungeon_skull_03.nbt,18,SKULL:1,../NBT/Skulls/dungeon_skull_04.nbt,24,SKULL:1,../NBT/Skulls/dungeon_skull_05.nbt,30,SKULL:1,../NBT/Skulls/dungeon_skull_06.nbt,36,SKULL:1,../NBT/Skulls/dungeon_skull_07.nbt,42,SKULL:1,../NBT/Skulls/dungeon_skull_08.nbt,48,SKULL:1,../NBT/Skulls/dungeon_skull_09.nbt,54,SKULL:1,../NBT/Skulls/dungeon_skull_10.nbt,60,SKULL:1,../NBT/Skulls/dungeon_skull_11.nbt,66,SKULL:1,../NBT/Skulls/dungeon_skull_12.nbt,72,SKULL:1,../NBT/Skulls/dungeon_skull_13.nbt,78,SKULL:1,../NBT/Skulls/dungeon_skull_14.nbt,84,SKULL:1,../NBT/Skulls/dungeon_skull_15.nbt,90,SKULL:1,../NBT/Skulls/dungeon_skull_16.nbt,100)
RB(-4,-2,-6,FLOWER_POT:0,../NBT/Flowers/flower_pot_01.nbt,5,FLOWER_POT:0,../NBT/Flowers/flower_pot_02.nbt,5,FLOWER_POT:0,../NBT/Flowers/flower_pot_03.nbt,5,FLOWER_POT:0,../NBT/Flowers/flower_pot_04.nbt,5,FLOWER_POT:0,../NBT/Flowers/flower_pot_05.nbt,5,FLOWER_POT:0,../NBT/Flowers/flower_pot_06.nbt,5,FLOWER_POT:0,../NBT/Flowers/flower_pot_07.nbt,5,FLOWER_POT:0,../NBT/Flowers/flower_pot_08.nbt,5,FLOWER_POT:0,../NBT/Flowers/flower_pot_09.nbt,5,FLOWER_POT:0,../NBT/Flowers/flower_pot_10.nbt,5,FLOWER_POT:0,../NBT/Flowers/flower_pot_11.nbt,5,FLOWER_POT:0,../NBT/Flowers/flower_pot_12.nbt,5,FLOWER_POT:0,../NBT/Flowers/flower_pot_13.nbt,5,FLOWER_POT:0,../NBT/Flowers/flower_pot_14.nbt,5,FLOWER_POT:0,../NBT/Flowers/flower_pot_15.nbt,5,FLOWER_POT:0,../NBT/Flowers/flower_pot_16.nbt,5,FLOWER_POT:0,../NBT/Flowers/flower_pot_17.nbt,5,FLOWER_POT:0,../NBT/Flowers/flower_pot_18.nbt,5,FLOWER_POT:0,../NBT/Flowers/flower_pot_19.nbt,5,FLOWER_POT:0,../NBT/Flowers/flower_pot_20.nbt,100)
B(-3,-2,-6,STAINED_GLASS_PANE:15)
B(-8,-2,-5,TRAPDOOR:14)
B(-7,-2,-5,PLANKS:0)
B(-6,-2,-5,STAINED_GLASS_PANE:15)
B(-5,-2,-5,PLANKS:0)
B(-4,-2,-5,STAINED_GLASS_PANE:15)
B(-3,-2,-5,PLANKS:0)
B(-2,-2,-5,TRAPDOOR:15)
B(-7,-2,-4,TRAPDOOR:13)
B(-5,-2,-4,TRAPDOOR:13)
B(-3,-2,-4,TRAPDOOR:13)
B(-8,-1,-8,PLANKS:5)
B(-3,-1,-8,PLANKS:5)
B(-2,-1,-8,DARK_OAK_STAIRS:7)
B(-1,-1,-8,WALL_BANNER:5,../NBT/Banners/dearoc_banner.nbt)
B(-8,-1,-7,PLANKS:5)
B(-3,-1,-7,PLANKS:5)
B(-2,-1,-7,FENCE:0)
B(-8,-1,-6,PLANKS:5)
B(-7,-1,-6,WOODEN_SLAB:13)
B(-6,-1,-6,WOODEN_SLAB:13)
B(-5,-1,-6,WOODEN_SLAB:13)
B(-3,-1,-6,PLANKS:5)
B(-7,-1,-5,WOODEN_SLAB:5)
B(-6,-1,-5,WOODEN_SLAB:5)
B(-5,-1,-5,DARK_OAK_STAIRS:0)
B(-4,-1,-5,DARK_OAK_STAIRS:3)
B(-3,-1,-5,PLANKS:5)
B(-2,-1,-5,WOODEN_BUTTON:1)
B(-3,-1,-4,WOODEN_BUTTON:3)
B(-8,0,-8,WOODEN_SLAB:0)
B(-7,0,-8,WOODEN_SLAB:8)
B(-6,0,-8,WOODEN_SLAB:8)
B(-5,0,-8,WOODEN_SLAB:8)
B(-4,0,-8,WOODEN_SLAB:8)
B(-3,0,-8,DOUBLE_WOODEN_SLAB:0)
B(-2,0,-8,PLANKS:5)
B(-1,0,-8,STONE_BUTTON:1)
B(-8,0,-7,WOODEN_SLAB:0)
B(-7,0,-7,DOUBLE_WOODEN_SLAB:0)
B(-6,0,-7,DOUBLE_WOODEN_SLAB:0)
B(-5,0,-7,DOUBLE_WOODEN_SLAB:0)
B(-4,0,-7,WOODEN_SLAB:8)
B(-3,0,-7,PLANKS:5)
B(-2,0,-7,DARK_OAK_STAIRS:1)
B(-8,0,-6,DARK_OAK_STAIRS:5)
B(-7,0,-6,WOODEN_SLAB:13)
B(-6,0,-6,WOODEN_SLAB:13)
B(-5,0,-6,DARK_OAK_STAIRS:4)
B(-4,0,-6,PLANKS:5)
B(-3,0,-6,DARK_OAK_STAIRS:3)
B(-3,0,-5,ANVIL:1)
B(-2,1,-8,PLANKS:5)
B(-1,1,-8,COBBLESTONE_WALL:0)
B(-3,1,-7,PLANKS:5)
B(-2,1,-7,LEVER:11)
B(-8,1,-6,PLANKS:5)
B(-7,1,-6,DARK_OAK_STAIRS:5)
B(-6,1,-6,WOODEN_SLAB:13)
B(-5,1,-6,WOODEN_SLAB:13)
B(-4,1,-6,DARK_OAK_STAIRS:4)
B(-3,1,-6,LEVER:11)
B(-2,2,-8,TRAPDOOR:6)
B(-1,2,-8,REDSTONE_LAMP:0)
B(-1,2,-7,TRAPDOOR:5)
B(-1,3,-8,WOODEN_SLAB:5)

BR(8,0,0,WestPortShipAgile_9x4,NORTH,100)
