#######################################################################
# +-----------------------------------------------------------------+ #
# |                            BO3 object                           | #
# +-----------------------------------------------------------------+ #
#######################################################################

Author: Bo3 BulkEdit

Description: Converted Schematic - Modified by Bo3BulkEdit

Version: 3

SettingsMode: WriteDisable

#######################################################################
# +-----------------------------------------------------------------+ #
# |                          Main settings                          | #
# +-----------------------------------------------------------------+ #
#######################################################################



Frequency: 0


SpawnHeight: randomY





##############################
# Height Limits for the BO3. #
##############################

MinHeight: 0
MaxHeight: 256

#######################################################################
# +-----------------------------------------------------------------+ #
# |                      Source block settings                      | #
# +-----------------------------------------------------------------+ #
#######################################################################

CanOverride: true
MaxPercentageOutsideSourceBlock: 100
OutsideSourceBlock: placeAnyway

#######################################################################
# +-----------------------------------------------------------------+ #
# |                               OTG+                              | #
# +-----------------------------------------------------------------+ #
#######################################################################

#######################################################################
# +-----------------------------------------------------------------+ #
# |                              Blocks                             | #
# +-----------------------------------------------------------------+ #
#######################################################################

B(0,750,0,AIR)
B(15,750,15,AIR)
B(4,2,15,STAINED_GLASS:15)
B(3,3,15,STAINED_GLASS:15)
B(4,3,15,STAINED_GLASS:15)
B(3,4,14,STAINED_GLASS:15)
B(2,4,15,STAINED_GLASS:15)
B(3,4,15,STAINED_GLASS:11)
B(4,4,15,STAINED_GLASS:15)
B(2,5,14,STAINED_GLASS:15)
B(3,5,14,STAINED_GLASS:15)
B(1,5,15,STAINED_GLASS:15)
B(2,5,15,STAINED_GLASS:11)
B(3,5,15,STAINED_GLASS:15)
B(4,5,15,STAINED_GLASS:15)
B(5,5,15,STAINED_GLASS:15)
B(2,6,13,STAINED_GLASS:15)
B(1,6,14,STAINED_GLASS:15)
B(2,6,14,STAINED_GLASS:11)
B(3,6,14,STAINED_GLASS:15)
B(0,6,15,STAINED_GLASS:15)
B(1,6,15,STAINED_GLASS:11)
B(2,6,15,STAINED_GLASS:15)
B(3,6,15,STAINED_GLASS:11)
B(4,6,15,STAINED_GLASS:15)
B(5,6,15,STAINED_GLASS:15)
B(1,7,13,STAINED_GLASS:15)
B(2,7,13,STAINED_GLASS:15)
B(0,7,14,STAINED_GLASS:15)
B(1,7,14,STAINED_GLASS:11)
B(2,7,14,STAINED_GLASS:15)
B(3,7,14,STAINED_GLASS:15)
B(4,7,14,STAINED_GLASS:15)
B(0,7,15,STAINED_GLASS:11)
B(1,7,15,STAINED_GLASS:15)
B(2,7,15,STAINED_GLASS:11)
B(3,7,15,STAINED_GLASS:11)
B(4,7,15,STAINED_GLASS:15)
B(5,7,15,STAINED_GLASS:15)
B(1,8,12,STAINED_GLASS:15)
B(0,8,13,STAINED_GLASS:15)
B(1,8,13,STAINED_GLASS:11)
B(2,8,13,STAINED_GLASS:15)
B(0,8,14,STAINED_GLASS:11)
B(1,8,14,STAINED_GLASS:15)
B(2,8,14,STAINED_GLASS:11)
B(3,8,14,STAINED_GLASS:15)
B(4,8,14,STAINED_GLASS:15)
B(0,8,15,STAINED_GLASS:15)
B(1,8,15,STAINED_GLASS:11)
B(2,8,15,STAINED_GLASS:10)
B(3,8,15,STAINED_GLASS:11)
B(4,8,15,STAINED_GLASS:15)
B(5,8,15,STAINED_GLASS:9)
B(0,9,12,STAINED_GLASS:15)
B(1,9,12,STAINED_GLASS:15)
B(0,9,13,STAINED_GLASS:11)
B(1,9,13,STAINED_GLASS:15)
B(2,9,13,STAINED_GLASS:15)
B(3,9,13,STAINED_GLASS:15)
B(0,9,14,STAINED_GLASS:15)
B(1,9,14,STAINED_GLASS:11)
B(2,9,14,STAINED_GLASS:11)
B(3,9,14,STAINED_GLASS:15)
B(4,9,14,STAINED_GLASS:15)
B(0,9,15,STAINED_GLASS:11)
B(1,9,15,STAINED_GLASS:10)
B(2,9,15,STAINED_GLASS:10)
B(3,9,15,STAINED_GLASS:11)
B(4,9,15,STAINED_GLASS:11)
B(5,9,15,STAINED_GLASS:9)
B(0,10,11,STAINED_GLASS:15)
B(0,10,12,STAINED_GLASS:11)
B(1,10,12,STAINED_GLASS:15)
B(0,10,13,STAINED_GLASS:15)
B(1,10,13,STAINED_GLASS:11)
B(2,10,13,STAINED_GLASS:15)
B(3,10,13,STAINED_GLASS:15)
B(0,10,14,STAINED_GLASS:11)
B(1,10,14,STAINED_GLASS:10)
B(2,10,14,STAINED_GLASS:11)
B(3,10,14,STAINED_GLASS:15)
B(4,10,14,STAINED_GLASS:9)
B(0,10,15,STAINED_GLASS:10)
B(1,10,15,STAINED_GLASS:10)
B(2,10,15,STAINED_GLASS:10)
B(3,10,15,STAINED_GLASS:11)
B(4,10,15,STAINED_GLASS:11)
B(5,10,15,STAINED_GLASS:9)
B(0,11,11,STAINED_GLASS:15)
B(0,11,12,STAINED_GLASS:15)
B(1,11,12,STAINED_GLASS:15)
B(2,11,12,STAINED_GLASS:15)
B(0,11,13,STAINED_GLASS:11)
B(1,11,13,STAINED_GLASS:11)
B(2,11,13,STAINED_GLASS:15)
B(3,11,13,STAINED_GLASS:15)
B(0,11,14,STAINED_GLASS:10)
B(1,11,14,STAINED_GLASS:10)
B(2,11,14,STAINED_GLASS:11)
B(3,11,14,STAINED_GLASS:11)
B(4,11,14,STAINED_GLASS:9)
B(0,11,15,STAINED_GLASS:10)
B(1,11,15,STAINED_GLASS:10)
B(2,11,15,STAINED_GLASS:10)
B(3,11,15,STAINED_GLASS:11)
B(4,11,15,STAINED_GLASS:11)
B(5,11,15,STAINED_GLASS:9)
B(0,12,11,STAINED_GLASS:15)
B(0,12,12,STAINED_GLASS:11)
B(1,12,12,STAINED_GLASS:15)
B(2,12,12,STAINED_GLASS:15)
B(0,12,13,STAINED_GLASS:10)
B(1,12,13,STAINED_GLASS:11)
B(2,12,13,STAINED_GLASS:15)
B(3,12,13,STAINED_GLASS:15)
B(0,12,14,STAINED_GLASS:10)
B(1,12,14,STAINED_GLASS:10)
B(2,12,14,STAINED_GLASS:11)
B(3,12,14,STAINED_GLASS:11)
B(4,12,14,STAINED_GLASS:9)
B(0,12,15,SEA_LANTERN)
B(1,12,15,STAINED_GLASS:10)
B(2,12,15,STAINED_GLASS:10)
B(3,12,15,STAINED_GLASS:11)
B(4,12,15,STAINED_GLASS:9)
B(0,13,11,STAINED_GLASS:15)
B(1,13,11,STAINED_GLASS:15)
B(0,13,12,STAINED_GLASS:11)
B(1,13,12,STAINED_GLASS:15)
B(2,13,12,STAINED_GLASS:15)
B(0,13,13,STAINED_GLASS:10)
B(1,13,13,STAINED_GLASS:11)
B(2,13,13,STAINED_GLASS:11)
B(3,13,13,STAINED_GLASS:9)
B(0,13,14,STAINED_GLASS:10)
B(1,13,14,STAINED_GLASS:10)
B(2,13,14,STAINED_GLASS:11)
B(3,13,14,STAINED_GLASS:11)
B(4,13,14,STAINED_GLASS:9)
B(0,13,15,SEA_LANTERN)
B(1,13,15,STAINED_GLASS:10)
B(2,13,15,STAINED_GLASS:10)
B(3,13,15,STAINED_GLASS:11)
B(4,13,15,STAINED_GLASS:9)
B(0,14,11,STAINED_GLASS:9)
B(1,14,11,STAINED_GLASS:15)
B(0,14,12,STAINED_GLASS:11)
B(1,14,12,STAINED_GLASS:9)
B(2,14,12,STAINED_GLASS:9)
B(0,14,13,STAINED_GLASS:10)
B(1,14,13,STAINED_GLASS:11)
B(2,14,13,STAINED_GLASS:11)
B(3,14,13,STAINED_GLASS:15)
B(0,14,14,STAINED_GLASS:10)
B(1,14,14,STAINED_GLASS:10)
B(2,14,14,STAINED_GLASS:11)
B(3,14,14,STAINED_GLASS:9)
B(0,14,15,SEA_LANTERN)
B(1,14,15,STAINED_GLASS:10)
B(2,14,15,STAINED_GLASS:10)
B(3,14,15,STAINED_GLASS:11)
B(4,14,15,STAINED_GLASS:9)
B(0,15,10,STAINED_GLASS:9)
B(0,15,11,STAINED_GLASS:9)
B(1,15,11,STAINED_GLASS:9)
B(0,15,12,STAINED_GLASS:11)
B(1,15,12,STAINED_GLASS:11)
B(2,15,12,STAINED_GLASS:9)
B(0,15,13,STAINED_GLASS:10)
B(1,15,13,STAINED_GLASS:11)
B(2,15,13,STAINED_GLASS:11)
B(3,15,13,STAINED_GLASS:9)
B(0,15,14,STAINED_GLASS:10)
B(1,15,14,STAINED_GLASS:10)
B(2,15,14,STAINED_GLASS:11)
B(3,15,14,STAINED_GLASS:15)
B(0,15,15,STAINED_GLASS:10)
B(1,15,15,STAINED_GLASS:10)
B(2,15,15,STAINED_GLASS:11)
B(3,15,15,STAINED_GLASS:9)
B(0,16,10,STAINED_GLASS:9)
B(0,16,11,STAINED_GLASS:9)
B(1,16,11,STAINED_GLASS:9)
B(0,16,12,STAINED_GLASS:11)
B(1,16,12,STAINED_GLASS:11)
B(2,16,12,STAINED_GLASS:9)
B(0,16,13,STAINED_GLASS:10)
B(1,16,13,STAINED_GLASS:11)
B(2,16,13,STAINED_GLASS:9)
B(0,16,14,STAINED_GLASS:10)
B(1,16,14,STAINED_GLASS:10)
B(2,16,14,STAINED_GLASS:11)
B(3,16,14,STAINED_GLASS:9)
B(0,16,15,STAINED_GLASS:10)
B(1,16,15,STAINED_GLASS:11)
B(2,16,15,STAINED_GLASS:9)
B(0,17,10,STAINED_GLASS:9)
B(0,17,11,STAINED_GLASS:9)
B(1,17,11,STAINED_GLASS:9)
B(0,17,12,STAINED_GLASS:9)
B(1,17,12,STAINED_GLASS:9)
B(2,17,12,STAINED_GLASS:15)
B(0,17,13,STAINED_GLASS:11)
B(1,17,13,STAINED_GLASS:9)
B(2,17,13,STAINED_GLASS:9)
B(0,17,14,STAINED_GLASS:11)
B(1,17,14,STAINED_GLASS:9)
B(2,17,14,STAINED_GLASS:9)
B(0,17,15,STAINED_GLASS:9)
B(1,17,15,STAINED_GLASS:9)
B(0,18,10,STAINED_GLASS:9)
B(0,18,11,STAINED_GLASS:9)
B(1,18,11,STAINED_GLASS:15)
B(0,18,12,STAINED_GLASS:15)
B(1,18,12,STAINED_GLASS:15)
B(0,18,13,STAINED_GLASS:11)
B(1,18,13,STAINED_GLASS:15)
B(2,18,13,STAINED_GLASS:9)
B(0,18,14,STAINED_GLASS:15)
B(1,18,14,STAINED_GLASS:9)
B(0,18,15,STAINED_GLASS:15)
B(1,18,15,STAINED_GLASS:15)
B(0,19,10,STAINED_GLASS:9)
B(0,19,11,STAINED_GLASS:15)
B(1,19,11,STAINED_GLASS:9)
B(0,19,12,STAINED_GLASS:9)
B(1,19,12,STAINED_GLASS:9)
B(0,19,13,STAINED_GLASS:15)
B(1,19,13,STAINED_GLASS:9)
B(0,19,14,STAINED_GLASS:15)
B(0,19,15,STAINED_GLASS:15)
B(0,20,10,STAINED_GLASS:15)
B(0,20,11,STAINED_GLASS:9)
B(0,20,12,STAINED_GLASS:9)
B(1,20,12,STAINED_GLASS:9)
B(0,20,13,STAINED_GLASS:9)
B(0,20,14,STAINED_GLASS:15)
B(0,21,10,STAINED_GLASS:15)
B(0,21,11,STAINED_GLASS:9)
B(0,21,12,STAINED_GLASS:9)
B(0,22,11,STAINED_GLASS:9)

#######################################################################
# +-----------------------------------------------------------------+ #
# |                             Branches                            | #
# +-----------------------------------------------------------------+ #
#######################################################################

BR(-16,0,0,true,SPIKE-FAT-HUGE-02_0x0,NORTH,100,0)
