
#######################################################################
# +-----------------------------------------------------------------+ #
# |                            BO4 object                           | #
# +-----------------------------------------------------------------+ #
#######################################################################

Author: NLBlackEagle

Description: No description given

SettingsMode: WriteWithoutComments


#######################################################################
# +-----------------------------------------------------------------+ #
# |                          Main settings                          | #
# +-----------------------------------------------------------------+ #
#######################################################################

FixedRotation: 

Frequency: 0

SpawnHeight: highestBlock

UseCenterForHighestBlock: true

##############################
# Height Limits for the BO4. #
##############################

MinHeight: 0

MaxHeight: 255

InheritBO3: 

InheritBO3Rotation: NORTH

OverrideChildSettings: true

OverrideParentHeight: false

CanOverride: false

BranchFrequency: 0

BranchFrequencyGroup: 

MustBeBelowOther: false

MustBeInside: 

CannotBeInside: 

ReplacesBO3: 

MustBeInsideWorldBorders: false

CanSpawnOnWater: true

SpawnOnWaterOnly: false

SpawnUnderWater: false

SpawnAtWaterLevel: false

HeightOffset: 0

RemoveAir: true

ReplaceAbove: 

ReplaceBelow: 

ReplaceWithBiomeBlocks: true

ReplaceWithSurfaceBlock: GRASS

ReplaceWithGroundBlock: DIRT

ReplaceWithStoneBlock: STONE

SmoothRadius: 0

SmoothHeightOffset: 0

SmoothStartTop: false

SmoothStartWood: false

SmoothingSurfaceBlock: 

SmoothingGroundBlock: 

BO3Group: 

IsSpawnPoint: false

DoReplaceBlocks: true


#######################################################################
# +-----------------------------------------------------------------+ #
# |                              Blocks                             | #
# +-----------------------------------------------------------------+ #
#######################################################################

B(-8,27,6,minecraft:andesite)
B(-8,28,6,minecraft:andesite)
B(-8,29,6,minecraft:andesite)
B(-8,30,6,minecraft:andesite)
B(-8,31,6,minecraft:andesite)
B(-8,24,7,minecraft:andesite)
B(-8,25,7,minecraft:andesite)
B(-8,26,7,minecraft:andesite)
B(-8,27,7,minecraft:andesite)
B(-8,28,7,minecraft:andesite)
B(-8,29,7,minecraft:andesite)
B(-8,30,7,minecraft:andesite)
B(-8,31,7,minecraft:andesite)
B(-8,32,7,minecraft:andesite)
B(-8,24,8,minecraft:andesite)
B(-8,25,8,minecraft:andesite)
B(-8,26,8,minecraft:andesite)
B(-8,27,8,minecraft:andesite)
B(-8,28,8,minecraft:andesite)
B(-8,29,8,minecraft:andesite)
B(-8,30,8,minecraft:andesite)
B(-8,31,8,minecraft:andesite)
B(-8,32,8,minecraft:andesite)
B(-7,28,2,minecraft:andesite)
B(-7,29,2,minecraft:andesite)
B(-7,30,2,minecraft:andesite)
B(-7,27,3,minecraft:andesite)
B(-7,28,3,minecraft:andesite)
B(-7,29,3,minecraft:andesite)
B(-7,30,3,minecraft:andesite)
B(-7,31,3,minecraft:andesite)
B(-7,27,4,minecraft:andesite)
B(-7,28,4,minecraft:andesite)
B(-7,29,4,minecraft:andesite)
B(-7,30,4,minecraft:andesite)
B(-7,31,4,minecraft:andesite)
B(-7,26,5,minecraft:andesite)
B(-7,27,5,minecraft:andesite)
B(-7,28,5,minecraft:andesite)
B(-7,29,5,minecraft:andesite)
B(-7,30,5,minecraft:andesite)
B(-7,31,5,minecraft:andesite)
B(-7,25,6,minecraft:andesite)
B(-7,26,6,minecraft:andesite)
B(-7,27,6,minecraft:andesite)
B(-7,28,6,minecraft:andesite)
B(-7,29,6,minecraft:andesite)
B(-7,30,6,minecraft:andesite)
B(-7,31,6,minecraft:andesite)
B(-7,32,6,minecraft:andesite)
B(-7,33,6,minecraft:andesite)
B(-7,34,6,minecraft:andesite)
B(-7,24,7,minecraft:andesite)
B(-7,25,7,minecraft:andesite)
B(-7,26,7,minecraft:andesite)
B(-7,27,7,minecraft:andesite)
B(-7,28,7,minecraft:andesite)
B(-7,29,7,minecraft:andesite)
B(-7,30,7,minecraft:andesite)
B(-7,31,7,minecraft:andesite)
B(-7,32,7,minecraft:andesite)
B(-7,33,7,minecraft:andesite)
B(-7,34,7,minecraft:obsidian)
B(-7,24,8,minecraft:andesite)
B(-7,25,8,minecraft:andesite)
B(-7,26,8,minecraft:andesite)
B(-7,27,8,minecraft:andesite)
B(-7,28,8,minecraft:andesite)
B(-7,29,8,minecraft:andesite)
B(-7,30,8,minecraft:andesite)
B(-7,31,8,minecraft:andesite)
B(-7,32,8,minecraft:andesite)
B(-7,33,8,minecraft:obsidian)
B(-7,34,8,minecraft:obsidian)
B(-6,27,1,minecraft:andesite)
B(-6,28,1,minecraft:andesite)
B(-6,29,1,minecraft:andesite)
B(-6,30,1,minecraft:andesite)
B(-6,31,1,minecraft:andesite)
B(-6,26,2,minecraft:andesite)
B(-6,27,2,minecraft:andesite)
B(-6,28,2,minecraft:andesite)
B(-6,29,2,minecraft:andesite)
B(-6,30,2,minecraft:andesite)
B(-6,31,2,minecraft:andesite)
B(-6,32,2,minecraft:andesite)
B(-6,33,2,minecraft:andesite)
B(-6,26,3,minecraft:andesite)
B(-6,27,3,minecraft:andesite)
B(-6,28,3,minecraft:andesite)
B(-6,29,3,minecraft:andesite)
B(-6,30,3,minecraft:andesite)
B(-6,31,3,minecraft:andesite)
B(-6,32,3,minecraft:andesite)
B(-6,25,4,minecraft:andesite)
B(-6,26,4,minecraft:andesite)
B(-6,27,4,minecraft:andesite)
B(-6,28,4,minecraft:andesite)
B(-6,29,4,minecraft:andesite)
B(-6,30,4,minecraft:andesite)
B(-6,31,4,minecraft:andesite)
B(-6,32,4,minecraft:andesite)
B(-6,33,4,minecraft:andesite)
B(-6,34,4,minecraft:andesite)
B(-6,24,5,minecraft:andesite)
B(-6,25,5,minecraft:andesite)
B(-6,26,5,minecraft:andesite)
B(-6,27,5,minecraft:andesite)
B(-6,28,5,minecraft:andesite)
B(-6,29,5,minecraft:andesite)
B(-6,30,5,minecraft:andesite)
B(-6,31,5,minecraft:andesite)
B(-6,32,5,minecraft:andesite)
B(-6,33,5,minecraft:andesite)
B(-6,23,6,minecraft:andesite)
B(-6,24,6,minecraft:andesite)
B(-6,25,6,minecraft:andesite)
B(-6,26,6,minecraft:andesite)
B(-6,27,6,minecraft:andesite)
B(-6,28,6,minecraft:andesite)
B(-6,29,6,minecraft:andesite)
B(-6,30,6,minecraft:andesite)
B(-6,31,6,minecraft:andesite)
B(-6,32,6,minecraft:andesite)
B(-6,33,6,minecraft:andesite)
B(-6,34,6,minecraft:obsidian)
B(-6,23,7,minecraft:andesite)
B(-6,24,7,minecraft:andesite)
B(-6,25,7,minecraft:andesite)
B(-6,26,7,minecraft:andesite)
B(-6,27,7,minecraft:andesite)
B(-6,28,7,minecraft:andesite)
B(-6,29,7,minecraft:andesite)
B(-6,30,7,minecraft:andesite)
B(-6,31,7,minecraft:andesite)
B(-6,32,7,minecraft:andesite)
B(-6,33,7,minecraft:andesite)
B(-6,34,7,minecraft:obsidian)
B(-6,35,7,minecraft:obsidian)
B(-6,23,8,minecraft:andesite)
B(-6,24,8,minecraft:andesite)
B(-6,25,8,minecraft:andesite)
B(-6,26,8,minecraft:andesite)
B(-6,27,8,minecraft:andesite)
B(-6,28,8,minecraft:andesite)
B(-6,29,8,minecraft:andesite)
B(-6,30,8,minecraft:andesite)
B(-6,31,8,minecraft:andesite)
B(-6,32,8,minecraft:andesite)
B(-6,33,8,minecraft:obsidian)
B(-6,34,8,minecraft:obsidian)
B(-6,35,8,minecraft:obsidian)
B(-5,28,-3,minecraft:andesite)
B(-5,29,-3,minecraft:andesite)
B(-5,30,-3,minecraft:andesite)
B(-5,27,-2,minecraft:andesite)
B(-5,28,-2,minecraft:andesite)
B(-5,29,-2,minecraft:andesite)
B(-5,30,-2,minecraft:andesite)
B(-5,31,-2,minecraft:andesite)
B(-5,27,-1,minecraft:andesite)
B(-5,28,-1,minecraft:andesite)
B(-5,29,-1,minecraft:andesite)
B(-5,30,-1,minecraft:andesite)
B(-5,31,-1,minecraft:andesite)
B(-5,27,0,minecraft:andesite)
B(-5,28,0,minecraft:andesite)
B(-5,29,0,minecraft:andesite)
B(-5,30,0,minecraft:andesite)
B(-5,31,0,minecraft:andesite)
B(-5,26,1,minecraft:andesite)
B(-5,27,1,minecraft:andesite)
B(-5,28,1,minecraft:andesite)
B(-5,29,1,minecraft:andesite)
B(-5,30,1,minecraft:andesite)
B(-5,31,1,minecraft:andesite)
B(-5,32,1,minecraft:andesite)
B(-5,33,1,minecraft:andesite)
B(-5,24,2,minecraft:andesite)
B(-5,25,2,minecraft:andesite)
B(-5,26,2,minecraft:andesite)
B(-5,27,2,minecraft:andesite)
B(-5,28,2,minecraft:andesite)
B(-5,29,2,minecraft:andesite)
B(-5,30,2,minecraft:andesite)
B(-5,31,2,minecraft:andesite)
B(-5,32,2,minecraft:andesite)
B(-5,33,2,minecraft:andesite)
B(-5,34,2,minecraft:andesite)
B(-5,24,3,minecraft:andesite)
B(-5,25,3,minecraft:andesite)
B(-5,26,3,minecraft:andesite)
B(-5,27,3,minecraft:andesite)
B(-5,28,3,minecraft:andesite)
B(-5,29,3,minecraft:andesite)
B(-5,30,3,minecraft:andesite)
B(-5,31,3,minecraft:andesite)
B(-5,32,3,minecraft:andesite)
B(-5,33,3,minecraft:andesite)
B(-5,34,3,minecraft:andesite)
B(-5,24,4,minecraft:andesite)
B(-5,25,4,minecraft:andesite)
B(-5,26,4,minecraft:andesite)
B(-5,27,4,minecraft:andesite)
B(-5,28,4,minecraft:andesite)
B(-5,29,4,minecraft:andesite)
B(-5,30,4,minecraft:andesite)
B(-5,31,4,minecraft:andesite)
B(-5,32,4,minecraft:andesite)
B(-5,33,4,minecraft:andesite)
B(-5,34,4,minecraft:obsidian)
B(-5,24,5,minecraft:andesite)
B(-5,25,5,minecraft:andesite)
B(-5,26,5,minecraft:andesite)
B(-5,27,5,minecraft:andesite)
B(-5,28,5,minecraft:andesite)
B(-5,29,5,minecraft:andesite)
B(-5,30,5,minecraft:andesite)
B(-5,31,5,minecraft:andesite)
B(-5,32,5,minecraft:andesite)
B(-5,33,5,minecraft:andesite)
B(-5,34,5,minecraft:obsidian)
B(-5,35,5,minecraft:obsidian)
B(-5,23,6,minecraft:andesite)
B(-5,24,6,minecraft:andesite)
B(-5,25,6,minecraft:andesite)
B(-5,26,6,minecraft:andesite)
B(-5,27,6,minecraft:andesite)
B(-5,28,6,minecraft:andesite)
B(-5,29,6,minecraft:andesite)
B(-5,30,6,minecraft:andesite)
B(-5,31,6,minecraft:andesite)
B(-5,32,6,minecraft:andesite)
B(-5,33,6,minecraft:andesite)
B(-5,34,6,minecraft:obsidian)
B(-5,35,6,minecraft:obsidian)
B(-5,36,6,minecraft:obsidian)
B(-5,22,7,minecraft:andesite)
B(-5,23,7,minecraft:andesite)
B(-5,24,7,minecraft:andesite)
B(-5,25,7,minecraft:andesite)
B(-5,26,7,minecraft:andesite)
B(-5,27,7,minecraft:andesite)
B(-5,28,7,minecraft:andesite)
B(-5,29,7,minecraft:andesite)
B(-5,30,7,minecraft:andesite)
B(-5,31,7,minecraft:andesite)
B(-5,32,7,minecraft:andesite)
B(-5,33,7,minecraft:andesite)
B(-5,34,7,minecraft:obsidian)
B(-5,35,7,minecraft:obsidian)
B(-5,36,7,minecraft:obsidian)
B(-5,21,8,minecraft:andesite)
B(-5,22,8,minecraft:andesite)
B(-5,23,8,minecraft:andesite)
B(-5,24,8,minecraft:andesite)
B(-5,25,8,minecraft:andesite)
B(-5,26,8,minecraft:andesite)
B(-5,27,8,minecraft:andesite)
B(-5,28,8,minecraft:andesite)
B(-5,29,8,minecraft:andesite)
B(-5,30,8,minecraft:andesite)
B(-5,31,8,minecraft:andesite)
B(-5,32,8,minecraft:andesite)
B(-5,33,8,minecraft:obsidian)
B(-5,34,8,minecraft:obsidian)
B(-5,35,8,minecraft:obsidian)
B(-5,36,8,minecraft:obsidian)
B(-4,27,-4,minecraft:andesite)
B(-4,28,-4,minecraft:andesite)
B(-4,29,-4,minecraft:andesite)
B(-4,30,-4,minecraft:andesite)
B(-4,31,-4,minecraft:andesite)
B(-4,26,-3,minecraft:andesite)
B(-4,27,-3,minecraft:andesite)
B(-4,28,-3,minecraft:andesite)
B(-4,29,-3,minecraft:andesite)
B(-4,30,-3,minecraft:andesite)
B(-4,31,-3,minecraft:andesite)
B(-4,32,-3,minecraft:andesite)
B(-4,26,-2,minecraft:andesite)
B(-4,27,-2,minecraft:andesite)
B(-4,28,-2,minecraft:andesite)
B(-4,29,-2,minecraft:andesite)
B(-4,30,-2,minecraft:andesite)
B(-4,31,-2,minecraft:andesite)
B(-4,32,-2,minecraft:andesite)
B(-4,26,-1,minecraft:andesite)
B(-4,27,-1,minecraft:andesite)
B(-4,28,-1,minecraft:andesite)
B(-4,29,-1,minecraft:andesite)
B(-4,30,-1,minecraft:andesite)
B(-4,31,-1,minecraft:andesite)
B(-4,32,-1,minecraft:andesite)
B(-4,33,-1,minecraft:andesite)
B(-4,24,0,minecraft:andesite)
B(-4,25,0,minecraft:andesite)
B(-4,26,0,minecraft:andesite)
B(-4,27,0,minecraft:andesite)
B(-4,28,0,minecraft:andesite)
B(-4,29,0,minecraft:andesite)
B(-4,30,0,minecraft:andesite)
B(-4,31,0,minecraft:andesite)
B(-4,32,0,minecraft:andesite)
B(-4,33,0,minecraft:andesite)
B(-4,24,1,minecraft:andesite)
B(-4,25,1,minecraft:andesite)
B(-4,26,1,minecraft:andesite)
B(-4,27,1,minecraft:andesite)
B(-4,28,1,minecraft:andesite)
B(-4,29,1,minecraft:andesite)
B(-4,30,1,minecraft:andesite)
B(-4,31,1,minecraft:andesite)
B(-4,32,1,minecraft:andesite)
B(-4,33,1,minecraft:andesite)
B(-4,34,1,minecraft:andesite)
B(-4,24,2,minecraft:andesite)
B(-4,25,2,minecraft:andesite)
B(-4,26,2,minecraft:andesite)
B(-4,27,2,minecraft:andesite)
B(-4,28,2,minecraft:andesite)
B(-4,29,2,minecraft:andesite)
B(-4,30,2,minecraft:andesite)
B(-4,31,2,minecraft:andesite)
B(-4,32,2,minecraft:andesite)
B(-4,33,2,minecraft:andesite)
B(-4,34,2,minecraft:obsidian)
B(-4,35,2,minecraft:obsidian)
B(-4,23,3,minecraft:andesite)
B(-4,24,3,minecraft:andesite)
B(-4,25,3,minecraft:andesite)
B(-4,26,3,minecraft:andesite)
B(-4,27,3,minecraft:andesite)
B(-4,28,3,minecraft:andesite)
B(-4,29,3,minecraft:andesite)
B(-4,30,3,minecraft:andesite)
B(-4,31,3,minecraft:andesite)
B(-4,32,3,minecraft:andesite)
B(-4,33,3,minecraft:andesite)
B(-4,34,3,minecraft:obsidian)
B(-4,35,3,minecraft:obsidian)
B(-4,24,4,minecraft:andesite)
B(-4,25,4,minecraft:andesite)
B(-4,26,4,minecraft:andesite)
B(-4,27,4,minecraft:andesite)
B(-4,28,4,minecraft:andesite)
B(-4,29,4,minecraft:andesite)
B(-4,30,4,minecraft:andesite)
B(-4,31,4,minecraft:andesite)
B(-4,32,4,minecraft:andesite)
B(-4,33,4,minecraft:andesite)
B(-4,34,4,minecraft:obsidian)
B(-4,35,4,minecraft:obsidian)
B(-4,24,5,minecraft:andesite)
B(-4,25,5,minecraft:andesite)
B(-4,26,5,minecraft:andesite)
B(-4,27,5,minecraft:andesite)
B(-4,28,5,minecraft:andesite)
B(-4,29,5,minecraft:andesite)
B(-4,30,5,minecraft:andesite)
B(-4,31,5,minecraft:andesite)
B(-4,32,5,minecraft:andesite)
B(-4,33,5,minecraft:andesite)
B(-4,34,5,minecraft:obsidian)
B(-4,35,5,minecraft:obsidian)
B(-4,36,5,minecraft:obsidian)
B(-4,22,6,minecraft:andesite)
B(-4,23,6,minecraft:andesite)
B(-4,24,6,minecraft:andesite)
B(-4,25,6,minecraft:andesite)
B(-4,26,6,minecraft:andesite)
B(-4,27,6,minecraft:andesite)
B(-4,28,6,minecraft:andesite)
B(-4,29,6,minecraft:andesite)
B(-4,30,6,minecraft:andesite)
B(-4,31,6,minecraft:andesite)
B(-4,32,6,minecraft:andesite)
B(-4,33,6,minecraft:andesite)
B(-4,34,6,minecraft:obsidian)
B(-4,35,6,minecraft:obsidian)
B(-4,36,6,minecraft:obsidian)
B(-4,37,6,minecraft:obsidian)
B(-4,21,7,minecraft:andesite)
B(-4,22,7,minecraft:andesite)
B(-4,23,7,minecraft:andesite)
B(-4,24,7,minecraft:andesite)
B(-4,25,7,minecraft:andesite)
B(-4,26,7,minecraft:andesite)
B(-4,27,7,minecraft:andesite)
B(-4,28,7,minecraft:andesite)
B(-4,29,7,minecraft:andesite)
B(-4,30,7,minecraft:andesite)
B(-4,31,7,minecraft:andesite)
B(-4,32,7,minecraft:andesite)
B(-4,33,7,minecraft:andesite)
B(-4,34,7,minecraft:obsidian)
B(-4,35,7,minecraft:obsidian)
B(-4,36,7,minecraft:obsidian)
B(-4,37,7,minecraft:obsidian)
B(-4,20,8,minecraft:andesite)
B(-4,21,8,minecraft:andesite)
B(-4,22,8,minecraft:andesite)
B(-4,23,8,minecraft:andesite)
B(-4,24,8,minecraft:andesite)
B(-4,25,8,minecraft:andesite)
B(-4,26,8,minecraft:andesite)
B(-4,27,8,minecraft:andesite)
B(-4,28,8,minecraft:andesite)
B(-4,29,8,minecraft:andesite)
B(-4,30,8,minecraft:andesite)
B(-4,31,8,minecraft:andesite)
B(-4,32,8,minecraft:andesite)
B(-4,33,8,minecraft:andesite)
B(-4,34,8,minecraft:obsidian)
B(-4,35,8,minecraft:obsidian)
B(-4,36,8,minecraft:obsidian)
B(-4,37,8,minecraft:obsidian)
B(-3,27,-5,minecraft:andesite)
B(-3,28,-5,minecraft:andesite)
B(-3,29,-5,minecraft:andesite)
B(-3,30,-5,minecraft:andesite)
B(-3,31,-5,minecraft:andesite)
B(-3,26,-4,minecraft:andesite)
B(-3,27,-4,minecraft:andesite)
B(-3,28,-4,minecraft:andesite)
B(-3,29,-4,minecraft:andesite)
B(-3,30,-4,minecraft:andesite)
B(-3,31,-4,minecraft:andesite)
B(-3,32,-4,minecraft:andesite)
B(-3,33,-4,minecraft:andesite)
B(-3,25,-3,minecraft:andesite)
B(-3,26,-3,minecraft:andesite)
B(-3,27,-3,minecraft:andesite)
B(-3,28,-3,minecraft:andesite)
B(-3,29,-3,minecraft:andesite)
B(-3,30,-3,minecraft:andesite)
B(-3,31,-3,minecraft:andesite)
B(-3,32,-3,minecraft:andesite)
B(-3,33,-3,minecraft:andesite)
B(-3,34,-3,minecraft:andesite)
B(-3,24,-2,minecraft:andesite)
B(-3,25,-2,minecraft:andesite)
B(-3,26,-2,minecraft:andesite)
B(-3,27,-2,minecraft:andesite)
B(-3,28,-2,minecraft:andesite)
B(-3,29,-2,minecraft:andesite)
B(-3,30,-2,minecraft:andesite)
B(-3,31,-2,minecraft:andesite)
B(-3,32,-2,minecraft:andesite)
B(-3,33,-2,minecraft:andesite)
B(-3,34,-2,minecraft:andesite)
B(-3,23,-1,minecraft:andesite)
B(-3,24,-1,minecraft:andesite)
B(-3,25,-1,minecraft:andesite)
B(-3,26,-1,minecraft:andesite)
B(-3,27,-1,minecraft:andesite)
B(-3,28,-1,minecraft:andesite)
B(-3,29,-1,minecraft:andesite)
B(-3,30,-1,minecraft:andesite)
B(-3,31,-1,minecraft:andesite)
B(-3,32,-1,minecraft:andesite)
B(-3,33,-1,minecraft:andesite)
B(-3,34,-1,minecraft:andesite)
B(-3,23,0,minecraft:andesite)
B(-3,24,0,minecraft:andesite)
B(-3,25,0,minecraft:andesite)
B(-3,26,0,minecraft:andesite)
B(-3,27,0,minecraft:andesite)
B(-3,28,0,minecraft:andesite)
B(-3,29,0,minecraft:andesite)
B(-3,30,0,minecraft:andesite)
B(-3,31,0,minecraft:andesite)
B(-3,32,0,minecraft:andesite)
B(-3,33,0,minecraft:andesite)
B(-3,34,0,minecraft:andesite)
B(-3,23,1,minecraft:andesite)
B(-3,24,1,minecraft:andesite)
B(-3,25,1,minecraft:andesite)
B(-3,26,1,minecraft:andesite)
B(-3,27,1,minecraft:andesite)
B(-3,28,1,minecraft:andesite)
B(-3,29,1,minecraft:andesite)
B(-3,30,1,minecraft:andesite)
B(-3,31,1,minecraft:andesite)
B(-3,32,1,minecraft:andesite)
B(-3,33,1,minecraft:andesite)
B(-3,34,1,minecraft:andesite)
B(-3,23,2,minecraft:andesite)
B(-3,24,2,minecraft:andesite)
B(-3,25,2,minecraft:andesite)
B(-3,26,2,minecraft:andesite)
B(-3,27,2,minecraft:andesite)
B(-3,28,2,minecraft:andesite)
B(-3,29,2,minecraft:andesite)
B(-3,30,2,minecraft:andesite)
B(-3,31,2,minecraft:andesite)
B(-3,32,2,minecraft:andesite)
B(-3,33,2,minecraft:andesite)
B(-3,34,2,minecraft:obsidian)
B(-3,35,2,minecraft:obsidian)
B(-3,36,2,minecraft:obsidian)
B(-3,22,3,minecraft:andesite)
B(-3,23,3,minecraft:andesite)
B(-3,24,3,minecraft:andesite)
B(-3,25,3,minecraft:andesite)
B(-3,26,3,minecraft:andesite)
B(-3,27,3,minecraft:andesite)
B(-3,28,3,minecraft:andesite)
B(-3,29,3,minecraft:andesite)
B(-3,30,3,minecraft:andesite)
B(-3,31,3,minecraft:andesite)
B(-3,32,3,minecraft:andesite)
B(-3,33,3,minecraft:andesite)
B(-3,34,3,minecraft:obsidian)
B(-3,35,3,minecraft:obsidian)
B(-3,36,3,minecraft:obsidian)
B(-3,23,4,minecraft:andesite)
B(-3,24,4,minecraft:andesite)
B(-3,25,4,minecraft:andesite)
B(-3,26,4,minecraft:andesite)
B(-3,27,4,minecraft:andesite)
B(-3,28,4,minecraft:andesite)
B(-3,29,4,minecraft:andesite)
B(-3,30,4,minecraft:andesite)
B(-3,31,4,minecraft:andesite)
B(-3,32,4,minecraft:andesite)
B(-3,33,4,minecraft:andesite)
B(-3,34,4,minecraft:obsidian)
B(-3,35,4,minecraft:obsidian)
B(-3,36,4,minecraft:obsidian)
B(-3,37,4,minecraft:obsidian)
B(-3,38,4,minecraft:obsidian)
B(-3,23,5,minecraft:andesite)
B(-3,24,5,minecraft:andesite)
B(-3,25,5,minecraft:andesite)
B(-3,26,5,minecraft:andesite)
B(-3,27,5,minecraft:andesite)
B(-3,28,5,minecraft:andesite)
B(-3,29,5,minecraft:andesite)
B(-3,30,5,minecraft:andesite)
B(-3,31,5,minecraft:andesite)
B(-3,32,5,minecraft:andesite)
B(-3,33,5,minecraft:andesite)
B(-3,34,5,minecraft:obsidian)
B(-3,35,5,minecraft:obsidian)
B(-3,36,5,minecraft:obsidian)
B(-3,37,5,minecraft:obsidian)
B(-3,38,5,minecraft:obsidian)
B(-3,39,5,minecraft:andesite)
B(-3,21,6,minecraft:andesite)
B(-3,22,6,minecraft:andesite)
B(-3,23,6,minecraft:andesite)
B(-3,24,6,minecraft:andesite)
B(-3,25,6,minecraft:andesite)
B(-3,26,6,minecraft:andesite)
B(-3,27,6,minecraft:andesite)
B(-3,28,6,minecraft:andesite)
B(-3,29,6,minecraft:andesite)
B(-3,30,6,minecraft:andesite)
B(-3,31,6,minecraft:andesite)
B(-3,32,6,minecraft:andesite)
B(-3,33,6,minecraft:andesite)
B(-3,34,6,minecraft:obsidian)
B(-3,35,6,minecraft:obsidian)
B(-3,36,6,minecraft:obsidian)
B(-3,37,6,minecraft:obsidian)
B(-3,38,6,minecraft:obsidian)
B(-3,39,6,minecraft:andesite)
B(-3,20,7,minecraft:andesite)
B(-3,21,7,minecraft:andesite)
B(-3,22,7,minecraft:andesite)
B(-3,23,7,minecraft:andesite)
B(-3,24,7,minecraft:andesite)
B(-3,25,7,minecraft:andesite)
B(-3,26,7,minecraft:andesite)
B(-3,27,7,minecraft:andesite)
B(-3,28,7,minecraft:andesite)
B(-3,29,7,minecraft:andesite)
B(-3,30,7,minecraft:andesite)
B(-3,31,7,minecraft:andesite)
B(-3,32,7,minecraft:andesite)
B(-3,33,7,minecraft:andesite)
B(-3,34,7,minecraft:andesite)
B(-3,35,7,minecraft:obsidian)
B(-3,36,7,minecraft:obsidian)
B(-3,37,7,minecraft:obsidian)
B(-3,38,7,minecraft:andesite)
B(-3,39,7,minecraft:andesite)
B(-3,20,8,minecraft:andesite)
B(-3,21,8,minecraft:andesite)
B(-3,22,8,minecraft:andesite)
B(-3,23,8,minecraft:andesite)
B(-3,24,8,minecraft:andesite)
B(-3,25,8,minecraft:andesite)
B(-3,26,8,minecraft:andesite)
B(-3,27,8,minecraft:andesite)
B(-3,28,8,minecraft:andesite)
B(-3,29,8,minecraft:andesite)
B(-3,30,8,minecraft:andesite)
B(-3,31,8,minecraft:andesite)
B(-3,32,8,minecraft:andesite)
B(-3,33,8,minecraft:andesite)
B(-3,34,8,minecraft:andesite)
B(-3,35,8,minecraft:obsidian)
B(-3,36,8,minecraft:obsidian)
B(-3,37,8,minecraft:obsidian)
B(-3,38,8,minecraft:andesite)
B(-3,39,8,minecraft:andesite)
B(-3,40,8,minecraft:andesite)
B(-2,28,-7,minecraft:andesite)
B(-2,29,-7,minecraft:andesite)
B(-2,30,-7,minecraft:andesite)
B(-2,27,-6,minecraft:andesite)
B(-2,28,-6,minecraft:andesite)
B(-2,29,-6,minecraft:andesite)
B(-2,30,-6,minecraft:andesite)
B(-2,31,-6,minecraft:andesite)
B(-2,26,-5,minecraft:andesite)
B(-2,27,-5,minecraft:andesite)
B(-2,28,-5,minecraft:andesite)
B(-2,29,-5,minecraft:andesite)
B(-2,30,-5,minecraft:andesite)
B(-2,31,-5,minecraft:andesite)
B(-2,32,-5,minecraft:andesite)
B(-2,33,-5,minecraft:andesite)
B(-2,25,-4,minecraft:andesite)
B(-2,26,-4,minecraft:andesite)
B(-2,27,-4,minecraft:andesite)
B(-2,28,-4,minecraft:andesite)
B(-2,29,-4,minecraft:andesite)
B(-2,30,-4,minecraft:andesite)
B(-2,31,-4,minecraft:andesite)
B(-2,32,-4,minecraft:andesite)
B(-2,33,-4,minecraft:andesite)
B(-2,34,-4,minecraft:andesite)
B(-2,24,-3,minecraft:andesite)
B(-2,25,-3,minecraft:andesite)
B(-2,26,-3,minecraft:andesite)
B(-2,27,-3,minecraft:andesite)
B(-2,28,-3,minecraft:andesite)
B(-2,29,-3,minecraft:andesite)
B(-2,30,-3,minecraft:andesite)
B(-2,31,-3,minecraft:andesite)
B(-2,32,-3,minecraft:andesite)
B(-2,33,-3,minecraft:andesite)
B(-2,34,-3,minecraft:andesite)
B(-2,24,-2,minecraft:andesite)
B(-2,25,-2,minecraft:andesite)
B(-2,26,-2,minecraft:andesite)
B(-2,27,-2,minecraft:andesite)
B(-2,28,-2,minecraft:andesite)
B(-2,29,-2,minecraft:andesite)
B(-2,30,-2,minecraft:andesite)
B(-2,31,-2,minecraft:andesite)
B(-2,32,-2,minecraft:andesite)
B(-2,33,-2,minecraft:andesite)
B(-2,34,-2,minecraft:andesite)
B(-2,22,-1,minecraft:andesite)
B(-2,23,-1,minecraft:andesite)
B(-2,24,-1,minecraft:andesite)
B(-2,25,-1,minecraft:andesite)
B(-2,26,-1,minecraft:andesite)
B(-2,27,-1,minecraft:andesite)
B(-2,28,-1,minecraft:andesite)
B(-2,29,-1,minecraft:andesite)
B(-2,30,-1,minecraft:andesite)
B(-2,31,-1,minecraft:andesite)
B(-2,32,-1,minecraft:andesite)
B(-2,33,-1,minecraft:andesite)
B(-2,34,-1,minecraft:andesite)
B(-2,36,-1,minecraft:obsidian)
B(-2,22,0,minecraft:andesite)
B(-2,23,0,minecraft:andesite)
B(-2,24,0,minecraft:andesite)
B(-2,25,0,minecraft:andesite)
B(-2,26,0,minecraft:andesite)
B(-2,27,0,minecraft:andesite)
B(-2,28,0,minecraft:andesite)
B(-2,29,0,minecraft:andesite)
B(-2,30,0,minecraft:andesite)
B(-2,31,0,minecraft:andesite)
B(-2,32,0,minecraft:andesite)
B(-2,33,0,minecraft:andesite)
B(-2,34,0,minecraft:andesite)
B(-2,35,0,minecraft:obsidian)
B(-2,36,0,minecraft:obsidian)
B(-2,37,0,minecraft:obsidian)
B(-2,22,1,minecraft:andesite)
B(-2,23,1,minecraft:andesite)
B(-2,24,1,minecraft:andesite)
B(-2,25,1,minecraft:andesite)
B(-2,26,1,minecraft:andesite)
B(-2,27,1,minecraft:andesite)
B(-2,28,1,minecraft:andesite)
B(-2,29,1,minecraft:andesite)
B(-2,30,1,minecraft:andesite)
B(-2,31,1,minecraft:andesite)
B(-2,32,1,minecraft:andesite)
B(-2,33,1,minecraft:andesite)
B(-2,34,1,minecraft:andesite)
B(-2,35,1,minecraft:obsidian)
B(-2,36,1,minecraft:obsidian)
B(-2,37,1,minecraft:obsidian)
B(-2,38,1,minecraft:obsidian)
B(-2,22,2,minecraft:andesite)
B(-2,23,2,minecraft:andesite)
B(-2,24,2,minecraft:andesite)
B(-2,25,2,minecraft:andesite)
B(-2,26,2,minecraft:andesite)
B(-2,27,2,minecraft:andesite)
B(-2,28,2,minecraft:andesite)
B(-2,29,2,minecraft:andesite)
B(-2,30,2,minecraft:andesite)
B(-2,31,2,minecraft:andesite)
B(-2,32,2,minecraft:andesite)
B(-2,33,2,minecraft:andesite)
B(-2,34,2,minecraft:obsidian)
B(-2,35,2,minecraft:obsidian)
B(-2,36,2,minecraft:obsidian)
B(-2,37,2,minecraft:obsidian)
B(-2,38,2,minecraft:obsidian)
B(-2,39,2,minecraft:andesite)
B(-2,21,3,minecraft:andesite)
B(-2,22,3,minecraft:andesite)
B(-2,23,3,minecraft:andesite)
B(-2,24,3,minecraft:andesite)
B(-2,25,3,minecraft:andesite)
B(-2,26,3,minecraft:andesite)
B(-2,27,3,minecraft:andesite)
B(-2,28,3,minecraft:andesite)
B(-2,29,3,minecraft:andesite)
B(-2,30,3,minecraft:andesite)
B(-2,31,3,minecraft:andesite)
B(-2,32,3,minecraft:andesite)
B(-2,33,3,minecraft:andesite)
B(-2,34,3,minecraft:obsidian)
B(-2,35,3,minecraft:obsidian)
B(-2,36,3,minecraft:obsidian)
B(-2,37,3,minecraft:obsidian)
B(-2,38,3,minecraft:obsidian)
B(-2,39,3,minecraft:andesite)
B(-2,22,4,minecraft:andesite)
B(-2,23,4,minecraft:andesite)
B(-2,24,4,minecraft:andesite)
B(-2,25,4,minecraft:andesite)
B(-2,26,4,minecraft:andesite)
B(-2,27,4,minecraft:andesite)
B(-2,28,4,minecraft:andesite)
B(-2,29,4,minecraft:andesite)
B(-2,30,4,minecraft:andesite)
B(-2,31,4,minecraft:andesite)
B(-2,32,4,minecraft:andesite)
B(-2,33,4,minecraft:andesite)
B(-2,34,4,minecraft:obsidian)
B(-2,35,4,minecraft:obsidian)
B(-2,36,4,minecraft:obsidian)
B(-2,37,4,minecraft:obsidian)
B(-2,38,4,minecraft:obsidian)
B(-2,39,4,minecraft:andesite)
B(-2,40,4,minecraft:andesite)
B(-2,22,5,minecraft:andesite)
B(-2,23,5,minecraft:andesite)
B(-2,24,5,minecraft:andesite)
B(-2,25,5,minecraft:andesite)
B(-2,26,5,minecraft:andesite)
B(-2,27,5,minecraft:andesite)
B(-2,28,5,minecraft:andesite)
B(-2,29,5,minecraft:stone)
B(-2,30,5,minecraft:stone)
B(-2,31,5,minecraft:andesite)
B(-2,32,5,minecraft:andesite)
B(-2,33,5,minecraft:andesite)
B(-2,34,5,minecraft:andesite)
B(-2,35,5,minecraft:obsidian)
B(-2,36,5,minecraft:obsidian)
B(-2,37,5,minecraft:obsidian)
B(-2,38,5,minecraft:andesite)
B(-2,39,5,minecraft:andesite)
B(-2,40,5,minecraft:andesite)
B(-2,21,6,minecraft:andesite)
B(-2,22,6,minecraft:andesite)
B(-2,23,6,minecraft:andesite)
B(-2,24,6,minecraft:andesite)
B(-2,25,6,minecraft:andesite)
B(-2,26,6,minecraft:andesite)
B(-2,27,6,minecraft:andesite)
B(-2,28,6,minecraft:andesite)
B(-2,29,6,minecraft:stone)
B(-2,30,6,minecraft:stone)
B(-2,31,6,minecraft:andesite)
B(-2,32,6,minecraft:andesite)
B(-2,33,6,minecraft:andesite)
B(-2,34,6,minecraft:andesite)
B(-2,35,6,minecraft:obsidian)
B(-2,36,6,minecraft:obsidian)
B(-2,37,6,minecraft:obsidian)
B(-2,38,6,minecraft:andesite)
B(-2,39,6,minecraft:andesite)
B(-2,20,7,minecraft:andesite)
B(-2,21,7,minecraft:andesite)
B(-2,22,7,minecraft:andesite)
B(-2,23,7,minecraft:andesite)
B(-2,24,7,minecraft:andesite)
B(-2,25,7,minecraft:andesite)
B(-2,26,7,minecraft:andesite)
B(-2,27,7,minecraft:andesite)
B(-2,28,7,minecraft:andesite)
B(-2,29,7,minecraft:stone)
B(-2,30,7,minecraft:stone)
B(-2,31,7,minecraft:andesite)
B(-2,32,7,minecraft:andesite)
B(-2,33,7,minecraft:andesite)
B(-2,34,7,minecraft:andesite)
B(-2,35,7,minecraft:andesite)
B(-2,36,7,minecraft:andesite)
B(-2,37,7,minecraft:andesite)
B(-2,38,7,minecraft:andesite)
B(-2,39,7,minecraft:andesite)
B(-2,40,7,minecraft:andesite)
B(-2,20,8,minecraft:andesite)
B(-2,21,8,minecraft:andesite)
B(-2,22,8,minecraft:andesite)
B(-2,23,8,minecraft:andesite)
B(-2,24,8,minecraft:andesite)
B(-2,25,8,minecraft:andesite)
B(-2,26,8,minecraft:andesite)
B(-2,27,8,minecraft:andesite)
B(-2,28,8,minecraft:stone)
B(-2,29,8,minecraft:stone)
B(-2,30,8,minecraft:stone)
B(-2,31,8,minecraft:andesite)
B(-2,32,8,minecraft:andesite)
B(-2,33,8,minecraft:andesite)
B(-2,34,8,minecraft:andesite)
B(-2,35,8,minecraft:andesite)
B(-2,36,8,minecraft:andesite)
B(-2,37,8,minecraft:andesite)
B(-2,38,8,minecraft:andesite)
B(-2,39,8,minecraft:andesite)
B(-2,40,8,minecraft:andesite)
B(-1,26,-7,minecraft:diorite)
B(-1,27,-7,minecraft:diorite)
B(-1,28,-7,minecraft:diorite)
B(-1,29,-7,minecraft:andesite)
B(-1,30,-7,minecraft:andesite)
B(-1,31,-7,minecraft:andesite)
B(-1,32,-7,minecraft:andesite)
B(-1,26,-6,minecraft:andesite)
B(-1,27,-6,minecraft:andesite)
B(-1,28,-6,minecraft:andesite)
B(-1,29,-6,minecraft:andesite)
B(-1,30,-6,minecraft:andesite)
B(-1,31,-6,minecraft:andesite)
B(-1,32,-6,minecraft:andesite)
B(-1,33,-6,minecraft:andesite)
B(-1,34,-6,minecraft:andesite)
B(-1,26,-5,minecraft:andesite)
B(-1,27,-5,minecraft:andesite)
B(-1,28,-5,minecraft:andesite)
B(-1,29,-5,minecraft:andesite)
B(-1,30,-5,minecraft:andesite)
B(-1,31,-5,minecraft:andesite)
B(-1,32,-5,minecraft:andesite)
B(-1,33,-5,minecraft:andesite)
B(-1,34,-5,minecraft:andesite)
B(-1,24,-4,minecraft:andesite)
B(-1,25,-4,minecraft:andesite)
B(-1,26,-4,minecraft:andesite)
B(-1,27,-4,minecraft:andesite)
B(-1,28,-4,minecraft:andesite)
B(-1,29,-4,minecraft:andesite)
B(-1,30,-4,minecraft:andesite)
B(-1,31,-4,minecraft:andesite)
B(-1,32,-4,minecraft:andesite)
B(-1,33,-4,minecraft:andesite)
B(-1,34,-4,minecraft:andesite)
B(-1,35,-4,minecraft:andesite)
B(-1,24,-3,minecraft:andesite)
B(-1,25,-3,minecraft:andesite)
B(-1,26,-3,minecraft:andesite)
B(-1,27,-3,minecraft:andesite)
B(-1,28,-3,minecraft:andesite)
B(-1,29,-3,minecraft:andesite)
B(-1,30,-3,minecraft:andesite)
B(-1,31,-3,minecraft:andesite)
B(-1,32,-3,minecraft:andesite)
B(-1,33,-3,minecraft:andesite)
B(-1,34,-3,minecraft:andesite)
B(-1,35,-3,minecraft:andesite)
B(-1,36,-3,minecraft:andesite)
B(-1,37,-3,minecraft:obsidian)
B(-1,38,-3,minecraft:obsidian)
B(-1,22,-2,minecraft:andesite)
B(-1,23,-2,minecraft:andesite)
B(-1,24,-2,minecraft:andesite)
B(-1,25,-2,minecraft:andesite)
B(-1,26,-2,minecraft:andesite)
B(-1,27,-2,minecraft:andesite)
B(-1,28,-2,minecraft:andesite)
B(-1,29,-2,minecraft:andesite)
B(-1,30,-2,minecraft:andesite)
B(-1,31,-2,minecraft:andesite)
B(-1,32,-2,minecraft:andesite)
B(-1,33,-2,minecraft:andesite)
B(-1,34,-2,minecraft:andesite)
B(-1,35,-2,minecraft:andesite)
B(-1,36,-2,minecraft:obsidian)
B(-1,37,-2,minecraft:obsidian)
B(-1,38,-2,minecraft:obsidian)
B(-1,39,-2,minecraft:obsidian)
B(-1,21,-1,minecraft:andesite)
B(-1,22,-1,minecraft:andesite)
B(-1,23,-1,minecraft:andesite)
B(-1,24,-1,minecraft:andesite)
B(-1,25,-1,minecraft:andesite)
B(-1,26,-1,minecraft:andesite)
B(-1,27,-1,minecraft:andesite)
B(-1,28,-1,minecraft:andesite)
B(-1,29,-1,minecraft:andesite)
B(-1,30,-1,minecraft:andesite)
B(-1,31,-1,minecraft:andesite)
B(-1,32,-1,minecraft:andesite)
B(-1,33,-1,minecraft:andesite)
B(-1,34,-1,minecraft:andesite)
B(-1,35,-1,minecraft:obsidian)
B(-1,36,-1,minecraft:obsidian)
B(-1,37,-1,minecraft:obsidian)
B(-1,38,-1,minecraft:obsidian)
B(-1,21,0,minecraft:andesite)
B(-1,22,0,minecraft:andesite)
B(-1,23,0,minecraft:andesite)
B(-1,24,0,minecraft:andesite)
B(-1,25,0,minecraft:andesite)
B(-1,26,0,minecraft:andesite)
B(-1,27,0,minecraft:andesite)
B(-1,28,0,minecraft:andesite)
B(-1,29,0,minecraft:andesite)
B(-1,30,0,minecraft:andesite)
B(-1,31,0,minecraft:andesite)
B(-1,32,0,minecraft:andesite)
B(-1,33,0,minecraft:andesite)
B(-1,34,0,minecraft:andesite)
B(-1,35,0,minecraft:obsidian)
B(-1,36,0,minecraft:obsidian)
B(-1,37,0,minecraft:obsidian)
B(-1,38,0,minecraft:obsidian)
B(-1,21,1,minecraft:andesite)
B(-1,22,1,minecraft:andesite)
B(-1,23,1,minecraft:andesite)
B(-1,24,1,minecraft:andesite)
B(-1,25,1,minecraft:andesite)
B(-1,26,1,minecraft:andesite)
B(-1,27,1,minecraft:andesite)
B(-1,28,1,minecraft:andesite)
B(-1,29,1,minecraft:andesite)
B(-1,30,1,minecraft:andesite)
B(-1,31,1,minecraft:andesite)
B(-1,32,1,minecraft:andesite)
B(-1,33,1,minecraft:andesite)
B(-1,34,1,minecraft:andesite)
B(-1,35,1,minecraft:obsidian)
B(-1,36,1,minecraft:obsidian)
B(-1,37,1,minecraft:obsidian)
B(-1,38,1,minecraft:obsidian)
B(-1,39,1,minecraft:obsidian)
B(-1,21,2,minecraft:andesite)
B(-1,22,2,minecraft:andesite)
B(-1,23,2,minecraft:andesite)
B(-1,24,2,minecraft:andesite)
B(-1,25,2,minecraft:andesite)
B(-1,26,2,minecraft:andesite)
B(-1,27,2,minecraft:andesite)
B(-1,28,2,minecraft:andesite)
B(-1,29,2,minecraft:andesite)
B(-1,30,2,minecraft:andesite)
B(-1,31,2,minecraft:andesite)
B(-1,32,2,minecraft:andesite)
B(-1,33,2,minecraft:andesite)
B(-1,34,2,minecraft:andesite)
B(-1,35,2,minecraft:obsidian)
B(-1,36,2,minecraft:obsidian)
B(-1,37,2,minecraft:obsidian)
B(-1,38,2,minecraft:obsidian)
B(-1,39,2,minecraft:andesite)
B(-1,40,2,minecraft:andesite)
B(-1,21,3,minecraft:andesite)
B(-1,22,3,minecraft:andesite)
B(-1,23,3,minecraft:andesite)
B(-1,24,3,minecraft:andesite)
B(-1,25,3,minecraft:andesite)
B(-1,26,3,minecraft:andesite)
B(-1,27,3,minecraft:andesite)
B(-1,28,3,minecraft:andesite)
B(-1,29,3,minecraft:andesite)
B(-1,30,3,minecraft:andesite)
B(-1,31,3,minecraft:andesite)
B(-1,32,3,minecraft:andesite)
B(-1,33,3,minecraft:andesite)
B(-1,34,3,minecraft:andesite)
B(-1,35,3,minecraft:obsidian)
B(-1,36,3,minecraft:obsidian)
B(-1,37,3,minecraft:obsidian)
B(-1,38,3,minecraft:andesite)
B(-1,39,3,minecraft:andesite)
B(-1,40,3,minecraft:andesite)
B(-1,21,4,minecraft:andesite)
B(-1,22,4,minecraft:andesite)
B(-1,23,4,minecraft:andesite)
B(-1,24,4,minecraft:andesite)
B(-1,25,4,minecraft:andesite)
B(-1,26,4,minecraft:andesite)
B(-1,27,4,minecraft:andesite)
B(-1,28,4,minecraft:andesite)
B(-1,29,4,minecraft:stone)
B(-1,30,4,minecraft:andesite)
B(-1,31,4,minecraft:andesite)
B(-1,32,4,minecraft:andesite)
B(-1,33,4,minecraft:andesite)
B(-1,34,4,minecraft:andesite)
B(-1,35,4,minecraft:obsidian)
B(-1,36,4,minecraft:obsidian)
B(-1,37,4,minecraft:obsidian)
B(-1,38,4,minecraft:andesite)
B(-1,39,4,minecraft:andesite)
B(-1,40,4,minecraft:andesite)
B(-1,21,5,minecraft:andesite)
B(-1,22,5,minecraft:andesite)
B(-1,23,5,minecraft:andesite)
B(-1,24,5,minecraft:andesite)
B(-1,25,5,minecraft:andesite)
B(-1,26,5,minecraft:andesite)
B(-1,27,5,minecraft:stone)
B(-1,28,5,minecraft:stone)
B(-1,29,5,minecraft:stone)
B(-1,30,5,minecraft:stone)
B(-1,31,5,minecraft:stone)
B(-1,32,5,minecraft:andesite)
B(-1,33,5,minecraft:andesite)
B(-1,34,5,minecraft:andesite)
B(-1,35,5,minecraft:andesite)
B(-1,36,5,minecraft:andesite)
B(-1,37,5,minecraft:andesite)
B(-1,38,5,minecraft:andesite)
B(-1,39,5,minecraft:andesite)
B(-1,40,5,minecraft:andesite)
B(-1,19,6,minecraft:andesite)
B(-1,20,6,minecraft:andesite)
B(-1,21,6,minecraft:andesite)
B(-1,22,6,minecraft:andesite)
B(-1,23,6,minecraft:andesite)
B(-1,24,6,minecraft:andesite)
B(-1,25,6,minecraft:andesite)
B(-1,26,6,minecraft:andesite)
B(-1,27,6,minecraft:stone)
B(-1,28,6,minecraft:stone)
B(-1,29,6,minecraft:stone)
B(-1,30,6,minecraft:stone)
B(-1,31,6,minecraft:stone)
B(-1,32,6,minecraft:andesite)
B(-1,33,6,minecraft:andesite)
B(-1,34,6,minecraft:andesite)
B(-1,35,6,minecraft:andesite)
B(-1,36,6,minecraft:andesite)
B(-1,37,6,minecraft:andesite)
B(-1,38,6,minecraft:andesite)
B(-1,39,6,minecraft:andesite)
B(-1,40,6,minecraft:andesite)
B(-1,19,7,minecraft:andesite)
B(-1,20,7,minecraft:andesite)
B(-1,21,7,minecraft:andesite)
B(-1,22,7,minecraft:andesite)
B(-1,23,7,minecraft:andesite)
B(-1,24,7,minecraft:andesite)
B(-1,25,7,minecraft:andesite)
B(-1,26,7,minecraft:andesite)
B(-1,27,7,minecraft:stone)
B(-1,28,7,minecraft:stone)
B(-1,29,7,minecraft:stone)
B(-1,30,7,minecraft:stone)
B(-1,31,7,minecraft:stone)
B(-1,32,7,minecraft:andesite)
B(-1,33,7,minecraft:andesite)
B(-1,34,7,minecraft:andesite)
B(-1,35,7,minecraft:andesite)
B(-1,36,7,minecraft:andesite)
B(-1,37,7,minecraft:andesite)
B(-1,38,7,minecraft:andesite)
B(-1,39,7,minecraft:andesite)
B(-1,40,7,minecraft:andesite)
B(-1,18,8,minecraft:andesite)
B(-1,19,8,minecraft:andesite)
B(-1,20,8,minecraft:andesite)
B(-1,21,8,minecraft:andesite)
B(-1,22,8,minecraft:andesite)
B(-1,23,8,minecraft:andesite)
B(-1,24,8,minecraft:andesite)
B(-1,25,8,minecraft:andesite)
B(-1,26,8,minecraft:andesite)
B(-1,27,8,minecraft:stone)
B(-1,28,8,minecraft:stone)
B(-1,29,8,minecraft:stone)
B(-1,30,8,minecraft:stone)
B(-1,31,8,minecraft:stone)
B(-1,32,8,minecraft:stone)
B(-1,33,8,minecraft:andesite)
B(-1,34,8,minecraft:andesite)
B(-1,35,8,minecraft:andesite)
B(-1,36,8,minecraft:andesite)
B(-1,37,8,minecraft:andesite)
B(-1,38,8,minecraft:andesite)
B(-1,39,8,minecraft:andesite)
B(-1,40,8,minecraft:andesite)
B(0,25,-7,minecraft:diorite)
B(0,26,-7,minecraft:diorite)
B(0,27,-7,minecraft:diorite)
B(0,28,-7,minecraft:diorite)
B(0,29,-7,minecraft:diorite)
B(0,30,-7,minecraft:andesite)
B(0,31,-7,minecraft:andesite)
B(0,32,-7,minecraft:andesite)
B(0,33,-7,minecraft:andesite)
B(0,34,-7,minecraft:andesite)
B(0,25,-6,minecraft:diorite)
B(0,26,-6,minecraft:diorite)
B(0,27,-6,minecraft:diorite)
B(0,28,-6,minecraft:diorite)
B(0,29,-6,minecraft:andesite)
B(0,30,-6,minecraft:andesite)
B(0,31,-6,minecraft:andesite)
B(0,32,-6,minecraft:andesite)
B(0,33,-6,minecraft:andesite)
B(0,34,-6,minecraft:andesite)
B(0,35,-6,minecraft:andesite)
B(0,25,-5,minecraft:andesite)
B(0,26,-5,minecraft:andesite)
B(0,27,-5,minecraft:andesite)
B(0,28,-5,minecraft:andesite)
B(0,29,-5,minecraft:andesite)
B(0,30,-5,minecraft:andesite)
B(0,31,-5,minecraft:andesite)
B(0,32,-5,minecraft:andesite)
B(0,33,-5,minecraft:andesite)
B(0,34,-5,minecraft:andesite)
B(0,35,-5,minecraft:andesite)
B(0,23,-4,minecraft:diorite)
B(0,24,-4,minecraft:diorite)
B(0,25,-4,minecraft:andesite)
B(0,26,-4,minecraft:andesite)
B(0,27,-4,minecraft:andesite)
B(0,28,-4,minecraft:andesite)
B(0,29,-4,minecraft:andesite)
B(0,30,-4,minecraft:andesite)
B(0,31,-4,minecraft:andesite)
B(0,32,-4,minecraft:andesite)
B(0,33,-4,minecraft:andesite)
B(0,34,-4,minecraft:andesite)
B(0,35,-4,minecraft:andesite)
B(0,36,-4,minecraft:andesite)
B(0,37,-4,minecraft:obsidian)
B(0,38,-4,minecraft:obsidian)
B(0,22,-3,minecraft:diorite)
B(0,23,-3,minecraft:diorite)
B(0,24,-3,minecraft:andesite)
B(0,25,-3,minecraft:andesite)
B(0,26,-3,minecraft:andesite)
B(0,27,-3,minecraft:andesite)
B(0,28,-3,minecraft:andesite)
B(0,29,-3,minecraft:andesite)
B(0,30,-3,minecraft:andesite)
B(0,31,-3,minecraft:andesite)
B(0,32,-3,minecraft:andesite)
B(0,33,-3,minecraft:andesite)
B(0,34,-3,minecraft:andesite)
B(0,35,-3,minecraft:andesite)
B(0,36,-3,minecraft:andesite)
B(0,37,-3,minecraft:obsidian)
B(0,38,-3,minecraft:obsidian)
B(0,39,-3,minecraft:obsidian)
B(0,21,-2,minecraft:andesite)
B(0,22,-2,minecraft:andesite)
B(0,23,-2,minecraft:andesite)
B(0,24,-2,minecraft:andesite)
B(0,25,-2,minecraft:andesite)
B(0,26,-2,minecraft:andesite)
B(0,27,-2,minecraft:andesite)
B(0,28,-2,minecraft:andesite)
B(0,29,-2,minecraft:andesite)
B(0,30,-2,minecraft:andesite)
B(0,31,-2,minecraft:andesite)
B(0,32,-2,minecraft:andesite)
B(0,33,-2,minecraft:andesite)
B(0,34,-2,minecraft:andesite)
B(0,35,-2,minecraft:andesite)
B(0,36,-2,minecraft:andesite)
B(0,37,-2,minecraft:obsidian)
B(0,38,-2,minecraft:obsidian)
B(0,39,-2,minecraft:obsidian)
B(0,40,-2,minecraft:obsidian)
B(0,20,-1,minecraft:andesite)
B(0,21,-1,minecraft:andesite)
B(0,22,-1,minecraft:andesite)
B(0,23,-1,minecraft:andesite)
B(0,24,-1,minecraft:andesite)
B(0,25,-1,minecraft:andesite)
B(0,26,-1,minecraft:andesite)
B(0,27,-1,minecraft:andesite)
B(0,28,-1,minecraft:andesite)
B(0,29,-1,minecraft:andesite)
B(0,30,-1,minecraft:andesite)
B(0,31,-1,minecraft:andesite)
B(0,32,-1,minecraft:andesite)
B(0,33,-1,minecraft:andesite)
B(0,34,-1,minecraft:andesite)
B(0,35,-1,minecraft:andesite)
B(0,36,-1,minecraft:obsidian)
B(0,37,-1,minecraft:obsidian)
B(0,38,-1,minecraft:obsidian)
B(0,39,-1,minecraft:obsidian)
B(0,20,0,minecraft:andesite)
B(0,21,0,minecraft:andesite)
B(0,22,0,minecraft:andesite)
B(0,23,0,minecraft:andesite)
B(0,24,0,minecraft:andesite)
B(0,25,0,minecraft:andesite)
B(0,26,0,minecraft:andesite)
B(0,27,0,minecraft:andesite)
B(0,28,0,minecraft:andesite)
B(0,29,0,minecraft:andesite)
B(0,30,0,minecraft:andesite)
B(0,31,0,minecraft:andesite)
B(0,32,0,minecraft:andesite)
B(0,33,0,minecraft:andesite)
B(0,34,0,minecraft:andesite)
B(0,35,0,minecraft:andesite)
B(0,36,0,minecraft:obsidian)
B(0,37,0,minecraft:obsidian)
B(0,38,0,minecraft:obsidian)
B(0,39,0,minecraft:obsidian)
B(0,20,1,minecraft:andesite)
B(0,21,1,minecraft:andesite)
B(0,22,1,minecraft:andesite)
B(0,23,1,minecraft:andesite)
B(0,24,1,minecraft:andesite)
B(0,25,1,minecraft:andesite)
B(0,26,1,minecraft:andesite)
B(0,27,1,minecraft:andesite)
B(0,28,1,minecraft:andesite)
B(0,29,1,minecraft:andesite)
B(0,30,1,minecraft:andesite)
B(0,31,1,minecraft:andesite)
B(0,32,1,minecraft:andesite)
B(0,33,1,minecraft:andesite)
B(0,34,1,minecraft:andesite)
B(0,35,1,minecraft:andesite)
B(0,36,1,minecraft:obsidian)
B(0,37,1,minecraft:obsidian)
B(0,38,1,minecraft:obsidian)
B(0,39,1,minecraft:andesite)
B(0,40,1,minecraft:andesite)
B(0,20,2,minecraft:andesite)
B(0,21,2,minecraft:andesite)
B(0,22,2,minecraft:andesite)
B(0,23,2,minecraft:andesite)
B(0,24,2,minecraft:andesite)
B(0,25,2,minecraft:andesite)
B(0,26,2,minecraft:andesite)
B(0,27,2,minecraft:andesite)
B(0,28,2,minecraft:andesite)
B(0,29,2,minecraft:andesite)
B(0,30,2,minecraft:andesite)
B(0,31,2,minecraft:andesite)
B(0,32,2,minecraft:andesite)
B(0,33,2,minecraft:andesite)
B(0,34,2,minecraft:andesite)
B(0,35,2,minecraft:andesite)
B(0,36,2,minecraft:andesite)
B(0,37,2,minecraft:andesite)
B(0,38,2,minecraft:andesite)
B(0,39,2,minecraft:andesite)
B(0,40,2,minecraft:andesite)
B(0,20,3,minecraft:andesite)
B(0,21,3,minecraft:andesite)
B(0,22,3,minecraft:andesite)
B(0,23,3,minecraft:andesite)
B(0,24,3,minecraft:andesite)
B(0,25,3,minecraft:andesite)
B(0,26,3,minecraft:andesite)
B(0,27,3,minecraft:andesite)
B(0,28,3,minecraft:stone)
B(0,29,3,minecraft:stone)
B(0,30,3,minecraft:andesite)
B(0,31,3,minecraft:andesite)
B(0,32,3,minecraft:andesite)
B(0,33,3,minecraft:andesite)
B(0,34,3,minecraft:andesite)
B(0,35,3,minecraft:andesite)
B(0,36,3,minecraft:andesite)
B(0,37,3,minecraft:andesite)
B(0,38,3,minecraft:andesite)
B(0,39,3,minecraft:andesite)
B(0,40,3,minecraft:andesite)
B(0,20,4,minecraft:andesite)
B(0,21,4,minecraft:andesite)
B(0,22,4,minecraft:andesite)
B(0,23,4,minecraft:andesite)
B(0,24,4,minecraft:andesite)
B(0,25,4,minecraft:andesite)
B(0,26,4,minecraft:andesite)
B(0,27,4,minecraft:stone)
B(0,28,4,minecraft:stone)
B(0,29,4,minecraft:stone)
B(0,30,4,minecraft:stone)
B(0,31,4,minecraft:stone)
B(0,32,4,minecraft:stone)
B(0,33,4,minecraft:stone)
B(0,34,4,minecraft:stone)
B(0,35,4,minecraft:andesite)
B(0,36,4,minecraft:andesite)
B(0,37,4,minecraft:andesite)
B(0,38,4,minecraft:andesite)
B(0,39,4,minecraft:andesite)
B(0,40,4,minecraft:andesite)
B(0,19,5,minecraft:andesite)
B(0,20,5,minecraft:andesite)
B(0,21,5,minecraft:andesite)
B(0,22,5,minecraft:andesite)
B(0,23,5,minecraft:andesite)
B(0,24,5,minecraft:andesite)
B(0,25,5,minecraft:andesite)
B(0,26,5,minecraft:andesite)
B(0,27,5,minecraft:stone)
B(0,28,5,minecraft:stone)
B(0,29,5,minecraft:stone)
B(0,30,5,minecraft:stone)
B(0,31,5,minecraft:stone)
B(0,32,5,minecraft:stone)
B(0,33,5,minecraft:stone)
B(0,34,5,minecraft:stone)
B(0,35,5,minecraft:andesite)
B(0,36,5,minecraft:andesite)
B(0,37,5,minecraft:andesite)
B(0,38,5,minecraft:andesite)
B(0,39,5,minecraft:andesite)
B(0,40,5,minecraft:andesite)
B(0,19,6,minecraft:andesite)
B(0,20,6,minecraft:andesite)
B(0,21,6,minecraft:andesite)
B(0,22,6,minecraft:andesite)
B(0,23,6,minecraft:andesite)
B(0,24,6,minecraft:andesite)
B(0,25,6,minecraft:andesite)
B(0,26,6,minecraft:andesite)
B(0,27,6,minecraft:stone)
B(0,28,6,minecraft:stone)
B(0,29,6,minecraft:stone)
B(0,30,6,minecraft:stone)
B(0,31,6,minecraft:stone)
B(0,32,6,minecraft:stone)
B(0,33,6,minecraft:stone)
B(0,34,6,minecraft:stone)
B(0,35,6,minecraft:andesite)
B(0,36,6,minecraft:andesite)
B(0,37,6,minecraft:andesite)
B(0,38,6,minecraft:andesite)
B(0,39,6,minecraft:andesite)
B(0,40,6,minecraft:andesite)
B(0,19,7,minecraft:andesite)
B(0,20,7,minecraft:andesite)
B(0,21,7,minecraft:andesite)
B(0,22,7,minecraft:andesite)
B(0,23,7,minecraft:andesite)
B(0,24,7,minecraft:andesite)
B(0,25,7,minecraft:andesite)
B(0,26,7,minecraft:andesite)
B(0,27,7,minecraft:stone)
B(0,28,7,minecraft:stone)
B(0,29,7,minecraft:stone)
B(0,30,7,minecraft:stone)
B(0,31,7,minecraft:stone)
B(0,32,7,minecraft:stone)
B(0,33,7,minecraft:stone)
B(0,34,7,minecraft:stone)
B(0,35,7,minecraft:stone)
B(0,36,7,minecraft:andesite)
B(0,37,7,minecraft:andesite)
B(0,38,7,minecraft:andesite)
B(0,39,7,minecraft:andesite)
B(0,40,7,minecraft:andesite)
B(0,18,8,minecraft:andesite)
B(0,19,8,minecraft:andesite)
B(0,20,8,minecraft:andesite)
B(0,21,8,minecraft:andesite)
B(0,22,8,minecraft:andesite)
B(0,23,8,minecraft:andesite)
B(0,24,8,minecraft:andesite)
B(0,25,8,minecraft:andesite)
B(0,26,8,minecraft:stone)
B(0,27,8,minecraft:stone)
B(0,28,8,minecraft:stone)
B(0,29,8,minecraft:stone)
B(0,30,8,minecraft:stone)
B(0,31,8,minecraft:stone)
B(0,32,8,minecraft:stone)
B(0,33,8,minecraft:stone)
B(0,34,8,minecraft:stone)
B(0,35,8,minecraft:andesite)
B(0,36,8,minecraft:andesite)
B(0,37,8,minecraft:andesite)
B(0,38,8,minecraft:andesite)
B(0,39,8,minecraft:andesite)
B(0,40,8,minecraft:andesite)
B(0,41,8,minecraft:andesite)
B(1,25,-7,minecraft:diorite)
B(1,26,-7,minecraft:diorite)
B(1,27,-7,minecraft:diorite)
B(1,28,-7,minecraft:diorite)
B(1,29,-7,minecraft:diorite)
B(1,30,-7,minecraft:diorite)
B(1,31,-7,minecraft:andesite)
B(1,32,-7,minecraft:andesite)
B(1,33,-7,minecraft:andesite)
B(1,34,-7,minecraft:andesite)
B(1,35,-7,minecraft:andesite)
B(1,24,-6,minecraft:diorite)
B(1,25,-6,minecraft:diorite)
B(1,26,-6,minecraft:diorite)
B(1,27,-6,minecraft:diorite)
B(1,28,-6,minecraft:diorite)
B(1,29,-6,minecraft:diorite)
B(1,30,-6,minecraft:andesite)
B(1,31,-6,minecraft:andesite)
B(1,32,-6,minecraft:andesite)
B(1,33,-6,minecraft:andesite)
B(1,34,-6,minecraft:andesite)
B(1,35,-6,minecraft:andesite)
B(1,36,-6,minecraft:andesite)
B(1,23,-5,minecraft:diorite)
B(1,24,-5,minecraft:diorite)
B(1,25,-5,minecraft:diorite)
B(1,26,-5,minecraft:diorite)
B(1,27,-5,minecraft:diorite)
B(1,28,-5,minecraft:andesite)
B(1,29,-5,minecraft:andesite)
B(1,30,-5,minecraft:andesite)
B(1,31,-5,minecraft:andesite)
B(1,32,-5,minecraft:andesite)
B(1,33,-5,minecraft:andesite)
B(1,34,-5,minecraft:andesite)
B(1,35,-5,minecraft:andesite)
B(1,36,-5,minecraft:andesite)
B(1,37,-5,minecraft:obsidian)
B(1,38,-5,minecraft:obsidian)
B(1,22,-4,minecraft:diorite)
B(1,23,-4,minecraft:diorite)
B(1,24,-4,minecraft:diorite)
B(1,25,-4,minecraft:diorite)
B(1,26,-4,minecraft:andesite)
B(1,27,-4,minecraft:andesite)
B(1,28,-4,minecraft:andesite)
B(1,29,-4,minecraft:andesite)
B(1,30,-4,minecraft:andesite)
B(1,31,-4,minecraft:andesite)
B(1,32,-4,minecraft:andesite)
B(1,33,-4,minecraft:andesite)
B(1,34,-4,minecraft:andesite)
B(1,35,-4,minecraft:andesite)
B(1,36,-4,minecraft:andesite)
B(1,37,-4,minecraft:obsidian)
B(1,38,-4,minecraft:obsidian)
B(1,39,-4,minecraft:obsidian)
B(1,21,-3,minecraft:diorite)
B(1,22,-3,minecraft:diorite)
B(1,23,-3,minecraft:diorite)
B(1,24,-3,minecraft:diorite)
B(1,25,-3,minecraft:andesite)
B(1,26,-3,minecraft:andesite)
B(1,27,-3,minecraft:andesite)
B(1,28,-3,minecraft:andesite)
B(1,29,-3,minecraft:andesite)
B(1,30,-3,minecraft:andesite)
B(1,31,-3,minecraft:andesite)
B(1,32,-3,minecraft:andesite)
B(1,33,-3,minecraft:andesite)
B(1,34,-3,minecraft:andesite)
B(1,35,-3,minecraft:andesite)
B(1,36,-3,minecraft:andesite)
B(1,37,-3,minecraft:obsidian)
B(1,38,-3,minecraft:obsidian)
B(1,39,-3,minecraft:obsidian)
B(1,40,-3,minecraft:obsidian)
B(1,20,-2,minecraft:diorite)
B(1,21,-2,minecraft:diorite)
B(1,22,-2,minecraft:diorite)
B(1,23,-2,minecraft:diorite)
B(1,24,-2,minecraft:andesite)
B(1,25,-2,minecraft:andesite)
B(1,26,-2,minecraft:andesite)
B(1,27,-2,minecraft:andesite)
B(1,28,-2,minecraft:andesite)
B(1,29,-2,minecraft:andesite)
B(1,30,-2,minecraft:andesite)
B(1,31,-2,minecraft:andesite)
B(1,32,-2,minecraft:andesite)
B(1,33,-2,minecraft:andesite)
B(1,34,-2,minecraft:andesite)
B(1,35,-2,minecraft:andesite)
B(1,36,-2,minecraft:andesite)
B(1,37,-2,minecraft:obsidian)
B(1,38,-2,minecraft:obsidian)
B(1,39,-2,minecraft:obsidian)
B(1,40,-2,minecraft:obsidian)
B(1,19,-1,minecraft:andesite)
B(1,20,-1,minecraft:andesite)
B(1,21,-1,minecraft:andesite)
B(1,22,-1,minecraft:andesite)
B(1,23,-1,minecraft:andesite)
B(1,24,-1,minecraft:andesite)
B(1,25,-1,minecraft:andesite)
B(1,26,-1,minecraft:andesite)
B(1,27,-1,minecraft:andesite)
B(1,28,-1,minecraft:andesite)
B(1,29,-1,minecraft:andesite)
B(1,30,-1,minecraft:andesite)
B(1,31,-1,minecraft:andesite)
B(1,32,-1,minecraft:andesite)
B(1,33,-1,minecraft:andesite)
B(1,34,-1,minecraft:andesite)
B(1,35,-1,minecraft:andesite)
B(1,36,-1,minecraft:andesite)
B(1,37,-1,minecraft:obsidian)
B(1,38,-1,minecraft:obsidian)
B(1,39,-1,minecraft:obsidian)
B(1,40,-1,minecraft:obsidian)
B(1,19,0,minecraft:andesite)
B(1,20,0,minecraft:andesite)
B(1,21,0,minecraft:andesite)
B(1,22,0,minecraft:andesite)
B(1,23,0,minecraft:andesite)
B(1,24,0,minecraft:andesite)
B(1,25,0,minecraft:andesite)
B(1,26,0,minecraft:andesite)
B(1,27,0,minecraft:andesite)
B(1,28,0,minecraft:stone)
B(1,29,0,minecraft:stone)
B(1,30,0,minecraft:andesite)
B(1,31,0,minecraft:andesite)
B(1,32,0,minecraft:andesite)
B(1,33,0,minecraft:andesite)
B(1,34,0,minecraft:andesite)
B(1,35,0,minecraft:andesite)
B(1,36,0,minecraft:andesite)
B(1,37,0,minecraft:andesite)
B(1,38,0,minecraft:obsidian)
B(1,39,0,minecraft:obsidian)
B(1,19,1,minecraft:andesite)
B(1,20,1,minecraft:andesite)
B(1,21,1,minecraft:andesite)
B(1,22,1,minecraft:andesite)
B(1,23,1,minecraft:andesite)
B(1,24,1,minecraft:andesite)
B(1,25,1,minecraft:andesite)
B(1,26,1,minecraft:andesite)
B(1,27,1,minecraft:stone)
B(1,28,1,minecraft:stone)
B(1,29,1,minecraft:stone)
B(1,30,1,minecraft:andesite)
B(1,31,1,minecraft:andesite)
B(1,32,1,minecraft:andesite)
B(1,33,1,minecraft:andesite)
B(1,34,1,minecraft:andesite)
B(1,35,1,minecraft:andesite)
B(1,36,1,minecraft:andesite)
B(1,37,1,minecraft:andesite)
B(1,38,1,minecraft:andesite)
B(1,39,1,minecraft:andesite)
B(1,40,1,minecraft:andesite)
B(1,19,2,minecraft:andesite)
B(1,20,2,minecraft:andesite)
B(1,21,2,minecraft:andesite)
B(1,22,2,minecraft:andesite)
B(1,23,2,minecraft:andesite)
B(1,24,2,minecraft:andesite)
B(1,25,2,minecraft:andesite)
B(1,26,2,minecraft:andesite)
B(1,27,2,minecraft:stone)
B(1,28,2,minecraft:stone)
B(1,29,2,minecraft:stone)
B(1,30,2,minecraft:stone)
B(1,31,2,minecraft:andesite)
B(1,32,2,minecraft:andesite)
B(1,33,2,minecraft:andesite)
B(1,34,2,minecraft:stone)
B(1,35,2,minecraft:andesite)
B(1,36,2,minecraft:andesite)
B(1,37,2,minecraft:andesite)
B(1,38,2,minecraft:andesite)
B(1,39,2,minecraft:andesite)
B(1,40,2,minecraft:andesite)
B(1,19,3,minecraft:andesite)
B(1,20,3,minecraft:andesite)
B(1,21,3,minecraft:andesite)
B(1,22,3,minecraft:andesite)
B(1,23,3,minecraft:andesite)
B(1,24,3,minecraft:andesite)
B(1,25,3,minecraft:andesite)
B(1,26,3,minecraft:andesite)
B(1,27,3,minecraft:stone)
B(1,28,3,minecraft:stone)
B(1,29,3,minecraft:stone)
B(1,30,3,minecraft:stone)
B(1,31,3,minecraft:stone)
B(1,32,3,minecraft:stone)
B(1,33,3,minecraft:stone)
B(1,34,3,minecraft:stone)
B(1,35,3,minecraft:andesite)
B(1,36,3,minecraft:andesite)
B(1,37,3,minecraft:andesite)
B(1,38,3,minecraft:andesite)
B(1,39,3,minecraft:andesite)
B(1,40,3,minecraft:andesite)
B(1,41,3,minecraft:andesite)
B(1,19,4,minecraft:andesite)
B(1,20,4,minecraft:andesite)
B(1,21,4,minecraft:andesite)
B(1,22,4,minecraft:andesite)
B(1,23,4,minecraft:andesite)
B(1,24,4,minecraft:andesite)
B(1,25,4,minecraft:andesite)
B(1,26,4,minecraft:stone)
B(1,27,4,minecraft:stone)
B(1,28,4,minecraft:stone)
B(1,29,4,minecraft:stone)
B(1,30,4,minecraft:stone)
B(1,31,4,minecraft:stone)
B(1,32,4,minecraft:stone)
B(1,33,4,minecraft:stone)
B(1,34,4,minecraft:stone)
B(1,35,4,minecraft:stone)
B(1,36,4,minecraft:andesite)
B(1,37,4,minecraft:andesite)
B(1,38,4,minecraft:andesite)
B(1,39,4,minecraft:andesite)
B(1,40,4,minecraft:andesite)
B(1,41,4,minecraft:andesite)
B(1,19,5,minecraft:andesite)
B(1,20,5,minecraft:andesite)
B(1,21,5,minecraft:andesite)
B(1,22,5,minecraft:andesite)
B(1,23,5,minecraft:andesite)
B(1,24,5,minecraft:andesite)
B(1,25,5,minecraft:andesite)
B(1,26,5,minecraft:stone)
B(1,27,5,minecraft:stone)
B(1,28,5,minecraft:stone)
B(1,29,5,minecraft:stone)
B(1,30,5,minecraft:stone)
B(1,31,5,minecraft:stone)
B(1,32,5,minecraft:stone)
B(1,33,5,minecraft:stone)
B(1,34,5,minecraft:stone)
B(1,35,5,minecraft:stone)
B(1,36,5,minecraft:andesite)
B(1,37,5,minecraft:andesite)
B(1,38,5,minecraft:andesite)
B(1,39,5,minecraft:andesite)
B(1,40,5,minecraft:andesite)
B(1,41,5,minecraft:andesite)
B(1,19,6,minecraft:andesite)
B(1,20,6,minecraft:andesite)
B(1,21,6,minecraft:andesite)
B(1,22,6,minecraft:andesite)
B(1,23,6,minecraft:andesite)
B(1,24,6,minecraft:andesite)
B(1,25,6,minecraft:andesite)
B(1,26,6,minecraft:stone)
B(1,27,6,minecraft:stone)
B(1,28,6,minecraft:stone)
B(1,29,6,minecraft:stone)
B(1,30,6,minecraft:stone)
B(1,31,6,minecraft:stone)
B(1,32,6,minecraft:stone)
B(1,33,6,minecraft:stone)
B(1,34,6,minecraft:stone)
B(1,35,6,minecraft:stone)
B(1,36,6,minecraft:andesite)
B(1,37,6,minecraft:andesite)
B(1,38,6,minecraft:andesite)
B(1,39,6,minecraft:andesite)
B(1,40,6,minecraft:andesite)
B(1,18,7,minecraft:andesite)
B(1,19,7,minecraft:andesite)
B(1,20,7,minecraft:andesite)
B(1,21,7,minecraft:andesite)
B(1,22,7,minecraft:andesite)
B(1,23,7,minecraft:andesite)
B(1,24,7,minecraft:andesite)
B(1,25,7,minecraft:andesite)
B(1,26,7,minecraft:stone)
B(1,27,7,minecraft:stone)
B(1,28,7,minecraft:stone)
B(1,29,7,minecraft:stone)
B(1,30,7,minecraft:stone)
B(1,31,7,minecraft:stone)
B(1,32,7,minecraft:stone)
B(1,33,7,minecraft:stone)
B(1,34,7,minecraft:stone)
B(1,35,7,minecraft:stone)
B(1,36,7,minecraft:andesite)
B(1,37,7,minecraft:andesite)
B(1,38,7,minecraft:andesite)
B(1,39,7,minecraft:andesite)
B(1,40,7,minecraft:andesite)
B(1,41,7,minecraft:andesite)
B(1,18,8,minecraft:andesite)
B(1,19,8,minecraft:andesite)
B(1,20,8,minecraft:andesite)
B(1,21,8,minecraft:andesite)
B(1,22,8,minecraft:andesite)
B(1,23,8,minecraft:andesite)
B(1,24,8,minecraft:andesite)
B(1,25,8,minecraft:andesite)
B(1,26,8,minecraft:stone)
B(1,27,8,minecraft:stone)
B(1,28,8,minecraft:stone)
B(1,29,8,minecraft:stone)
B(1,30,8,minecraft:stone)
B(1,31,8,minecraft:stone)
B(1,32,8,minecraft:stone)
B(1,33,8,minecraft:stone)
B(1,34,8,minecraft:stone)
B(1,35,8,minecraft:stone)
B(1,36,8,minecraft:andesite)
B(1,37,8,minecraft:andesite)
B(1,38,8,minecraft:andesite)
B(1,39,8,minecraft:andesite)
B(1,40,8,minecraft:andesite)
B(1,41,8,minecraft:andesite)
B(1,42,8,minecraft:andesite)
B(2,24,-7,minecraft:diorite)
B(2,25,-7,minecraft:diorite)
B(2,26,-7,minecraft:diorite)
B(2,27,-7,minecraft:diorite)
B(2,28,-7,minecraft:diorite)
B(2,29,-7,minecraft:diorite)
B(2,30,-7,minecraft:diorite)
B(2,31,-7,minecraft:diorite)
B(2,32,-7,minecraft:diorite)
B(2,33,-7,minecraft:andesite)
B(2,34,-7,minecraft:andesite)
B(2,35,-7,minecraft:andesite)
B(2,23,-6,minecraft:diorite)
B(2,24,-6,minecraft:diorite)
B(2,25,-6,minecraft:diorite)
B(2,26,-6,minecraft:diorite)
B(2,27,-6,minecraft:diorite)
B(2,28,-6,minecraft:diorite)
B(2,29,-6,minecraft:diorite)
B(2,30,-6,minecraft:andesite)
B(2,31,-6,minecraft:andesite)
B(2,32,-6,minecraft:andesite)
B(2,33,-6,minecraft:andesite)
B(2,34,-6,minecraft:andesite)
B(2,35,-6,minecraft:andesite)
B(2,22,-5,minecraft:diorite)
B(2,23,-5,minecraft:diorite)
B(2,24,-5,minecraft:diorite)
B(2,25,-5,minecraft:diorite)
B(2,26,-5,minecraft:diorite)
B(2,27,-5,minecraft:diorite)
B(2,28,-5,minecraft:diorite)
B(2,29,-5,minecraft:andesite)
B(2,30,-5,minecraft:andesite)
B(2,31,-5,minecraft:andesite)
B(2,32,-5,minecraft:andesite)
B(2,33,-5,minecraft:andesite)
B(2,34,-5,minecraft:andesite)
B(2,35,-5,minecraft:andesite)
B(2,36,-5,minecraft:andesite)
B(2,37,-5,minecraft:obsidian)
B(2,19,-4,minecraft:diorite)
B(2,20,-4,minecraft:diorite)
B(2,21,-4,minecraft:diorite)
B(2,22,-4,minecraft:diorite)
B(2,23,-4,minecraft:diorite)
B(2,24,-4,minecraft:diorite)
B(2,25,-4,minecraft:diorite)
B(2,26,-4,minecraft:stone)
B(2,27,-4,minecraft:andesite)
B(2,28,-4,minecraft:andesite)
B(2,29,-4,minecraft:andesite)
B(2,30,-4,minecraft:andesite)
B(2,31,-4,minecraft:andesite)
B(2,32,-4,minecraft:andesite)
B(2,33,-4,minecraft:andesite)
B(2,34,-4,minecraft:andesite)
B(2,35,-4,minecraft:andesite)
B(2,36,-4,minecraft:andesite)
B(2,37,-4,minecraft:obsidian)
B(2,38,-4,minecraft:obsidian)
B(2,39,-4,minecraft:obsidian)
B(2,40,-4,minecraft:obsidian)
B(2,19,-3,minecraft:diorite)
B(2,20,-3,minecraft:diorite)
B(2,21,-3,minecraft:diorite)
B(2,22,-3,minecraft:diorite)
B(2,23,-3,minecraft:diorite)
B(2,24,-3,minecraft:diorite)
B(2,25,-3,minecraft:diorite)
B(2,26,-3,minecraft:andesite)
B(2,27,-3,minecraft:andesite)
B(2,28,-3,minecraft:andesite)
B(2,29,-3,minecraft:andesite)
B(2,30,-3,minecraft:andesite)
B(2,31,-3,minecraft:andesite)
B(2,32,-3,minecraft:andesite)
B(2,33,-3,minecraft:andesite)
B(2,34,-3,minecraft:andesite)
B(2,35,-3,minecraft:andesite)
B(2,36,-3,minecraft:andesite)
B(2,37,-3,minecraft:obsidian)
B(2,38,-3,minecraft:obsidian)
B(2,39,-3,minecraft:obsidian)
B(2,40,-3,minecraft:obsidian)
B(2,19,-2,minecraft:diorite)
B(2,20,-2,minecraft:diorite)
B(2,21,-2,minecraft:diorite)
B(2,22,-2,minecraft:diorite)
B(2,23,-2,minecraft:diorite)
B(2,24,-2,minecraft:diorite)
B(2,25,-2,minecraft:andesite)
B(2,26,-2,minecraft:andesite)
B(2,27,-2,minecraft:stone)
B(2,28,-2,minecraft:andesite)
B(2,29,-2,minecraft:andesite)
B(2,30,-2,minecraft:andesite)
B(2,31,-2,minecraft:andesite)
B(2,32,-2,minecraft:andesite)
B(2,33,-2,minecraft:andesite)
B(2,34,-2,minecraft:andesite)
B(2,35,-2,minecraft:andesite)
B(2,36,-2,minecraft:andesite)
B(2,37,-2,minecraft:andesite)
B(2,38,-2,minecraft:obsidian)
B(2,39,-2,minecraft:obsidian)
B(2,40,-2,minecraft:obsidian)
B(2,41,-2,minecraft:andesite)
B(2,19,-1,minecraft:diorite)
B(2,20,-1,minecraft:diorite)
B(2,21,-1,minecraft:diorite)
B(2,22,-1,minecraft:diorite)
B(2,23,-1,minecraft:andesite)
B(2,24,-1,minecraft:andesite)
B(2,25,-1,minecraft:andesite)
B(2,26,-1,minecraft:andesite)
B(2,27,-1,minecraft:stone)
B(2,28,-1,minecraft:stone)
B(2,29,-1,minecraft:stone)
B(2,30,-1,minecraft:stone)
B(2,31,-1,minecraft:stone)
B(2,32,-1,minecraft:stone)
B(2,33,-1,minecraft:stone)
B(2,34,-1,minecraft:andesite)
B(2,35,-1,minecraft:andesite)
B(2,36,-1,minecraft:andesite)
B(2,37,-1,minecraft:andesite)
B(2,38,-1,minecraft:obsidian)
B(2,39,-1,minecraft:obsidian)
B(2,40,-1,minecraft:obsidian)
B(2,41,-1,minecraft:andesite)
B(2,18,0,minecraft:andesite)
B(2,19,0,minecraft:andesite)
B(2,20,0,minecraft:andesite)
B(2,21,0,minecraft:andesite)
B(2,22,0,minecraft:andesite)
B(2,23,0,minecraft:andesite)
B(2,24,0,minecraft:andesite)
B(2,25,0,minecraft:andesite)
B(2,26,0,minecraft:stone)
B(2,27,0,minecraft:stone)
B(2,28,0,minecraft:stone)
B(2,29,0,minecraft:stone)
B(2,30,0,minecraft:stone)
B(2,31,0,minecraft:stone)
B(2,32,0,minecraft:stone)
B(2,33,0,minecraft:stone)
B(2,34,0,minecraft:stone)
B(2,35,0,minecraft:andesite)
B(2,36,0,minecraft:andesite)
B(2,37,0,minecraft:andesite)
B(2,38,0,minecraft:andesite)
B(2,39,0,minecraft:andesite)
B(2,40,0,minecraft:andesite)
B(2,18,1,minecraft:andesite)
B(2,19,1,minecraft:andesite)
B(2,20,1,minecraft:andesite)
B(2,21,1,minecraft:andesite)
B(2,22,1,minecraft:andesite)
B(2,23,1,minecraft:andesite)
B(2,24,1,minecraft:andesite)
B(2,25,1,minecraft:andesite)
B(2,26,1,minecraft:stone)
B(2,27,1,minecraft:stone)
B(2,28,1,minecraft:stone)
B(2,29,1,minecraft:stone)
B(2,30,1,minecraft:stone)
B(2,31,1,minecraft:stone)
B(2,32,1,minecraft:stone)
B(2,33,1,minecraft:stone)
B(2,34,1,minecraft:stone)
B(2,35,1,minecraft:andesite)
B(2,36,1,minecraft:andesite)
B(2,37,1,minecraft:andesite)
B(2,38,1,minecraft:andesite)
B(2,39,1,minecraft:andesite)
B(2,40,1,minecraft:andesite)
B(2,18,2,minecraft:andesite)
B(2,19,2,minecraft:andesite)
B(2,20,2,minecraft:andesite)
B(2,21,2,minecraft:andesite)
B(2,22,2,minecraft:andesite)
B(2,23,2,minecraft:andesite)
B(2,24,2,minecraft:andesite)
B(2,25,2,minecraft:andesite)
B(2,26,2,minecraft:stone)
B(2,27,2,minecraft:stone)
B(2,28,2,minecraft:stone)
B(2,29,2,minecraft:stone)
B(2,30,2,minecraft:stone)
B(2,31,2,minecraft:stone)
B(2,32,2,minecraft:stone)
B(2,33,2,minecraft:stone)
B(2,34,2,minecraft:stone)
B(2,35,2,minecraft:andesite)
B(2,36,2,minecraft:andesite)
B(2,37,2,minecraft:andesite)
B(2,38,2,minecraft:andesite)
B(2,39,2,minecraft:andesite)
B(2,40,2,minecraft:andesite)
B(2,41,2,minecraft:andesite)
B(2,18,3,minecraft:andesite)
B(2,19,3,minecraft:andesite)
B(2,20,3,minecraft:andesite)
B(2,21,3,minecraft:andesite)
B(2,22,3,minecraft:andesite)
B(2,23,3,minecraft:andesite)
B(2,24,3,minecraft:andesite)
B(2,25,3,minecraft:andesite)
B(2,26,3,minecraft:stone)
B(2,27,3,minecraft:stone)
B(2,28,3,minecraft:stone)
B(2,29,3,minecraft:stone)
B(2,30,3,minecraft:stone)
B(2,31,3,minecraft:stone)
B(2,32,3,minecraft:stone)
B(2,33,3,minecraft:stone)
B(2,34,3,minecraft:stone)
B(2,35,3,minecraft:andesite)
B(2,36,3,minecraft:andesite)
B(2,37,3,minecraft:andesite)
B(2,38,3,minecraft:andesite)
B(2,39,3,minecraft:andesite)
B(2,40,3,minecraft:andesite)
B(2,41,3,minecraft:andesite)
B(2,18,4,minecraft:andesite)
B(2,19,4,minecraft:andesite)
B(2,20,4,minecraft:andesite)
B(2,21,4,minecraft:andesite)
B(2,22,4,minecraft:andesite)
B(2,23,4,minecraft:andesite)
B(2,24,4,minecraft:andesite)
B(2,25,4,minecraft:andesite)
B(2,26,4,minecraft:stone)
B(2,27,4,minecraft:stone)
B(2,28,4,minecraft:stone)
B(2,29,4,minecraft:stone)
B(2,30,4,minecraft:stone)
B(2,31,4,minecraft:stone)
B(2,32,4,minecraft:stone)
B(2,33,4,minecraft:stone)
B(2,34,4,minecraft:stone)
B(2,35,4,minecraft:stone)
B(2,36,4,minecraft:andesite)
B(2,37,4,minecraft:andesite)
B(2,38,4,minecraft:andesite)
B(2,39,4,minecraft:andesite)
B(2,40,4,minecraft:andesite)
B(2,41,4,minecraft:andesite)
B(2,18,5,minecraft:andesite)
B(2,19,5,minecraft:andesite)
B(2,20,5,minecraft:andesite)
B(2,21,5,minecraft:andesite)
B(2,22,5,minecraft:andesite)
B(2,23,5,minecraft:andesite)
B(2,24,5,minecraft:andesite)
B(2,25,5,minecraft:stone)
B(2,26,5,minecraft:stone)
B(2,27,5,minecraft:stone)
B(2,28,5,minecraft:stone)
B(2,29,5,minecraft:stone)
B(2,30,5,minecraft:stone)
B(2,31,5,minecraft:stone)
B(2,32,5,minecraft:stone)
B(2,33,5,minecraft:stone)
B(2,34,5,minecraft:stone)
B(2,35,5,minecraft:stone)
B(2,36,5,minecraft:andesite)
B(2,37,5,minecraft:andesite)
B(2,38,5,minecraft:andesite)
B(2,39,5,minecraft:andesite)
B(2,40,5,minecraft:andesite)
B(2,41,5,minecraft:andesite)
B(2,18,6,minecraft:andesite)
B(2,19,6,minecraft:andesite)
B(2,20,6,minecraft:andesite)
B(2,21,6,minecraft:andesite)
B(2,22,6,minecraft:andesite)
B(2,23,6,minecraft:andesite)
B(2,24,6,minecraft:andesite)
B(2,25,6,minecraft:stone)
B(2,26,6,minecraft:stone)
B(2,27,6,minecraft:stone)
B(2,28,6,minecraft:stone)
B(2,29,6,minecraft:stone)
B(2,30,6,minecraft:stone)
B(2,31,6,minecraft:stone)
B(2,32,6,minecraft:stone)
B(2,33,6,minecraft:stone)
B(2,34,6,minecraft:stone)
B(2,35,6,minecraft:stone)
B(2,36,6,minecraft:stone)
B(2,37,6,minecraft:andesite)
B(2,38,6,minecraft:andesite)
B(2,39,6,minecraft:andesite)
B(2,40,6,minecraft:andesite)
B(2,41,6,minecraft:andesite)
B(2,42,6,minecraft:andesite)
B(2,18,7,minecraft:andesite)
B(2,19,7,minecraft:andesite)
B(2,20,7,minecraft:andesite)
B(2,21,7,minecraft:andesite)
B(2,22,7,minecraft:andesite)
B(2,23,7,minecraft:andesite)
B(2,24,7,minecraft:andesite)
B(2,25,7,minecraft:stone)
B(2,26,7,minecraft:stone)
B(2,27,7,minecraft:stone)
B(2,28,7,minecraft:stone)
B(2,29,7,minecraft:stone)
B(2,30,7,minecraft:stone)
B(2,31,7,minecraft:stone)
B(2,32,7,minecraft:stone)
B(2,33,7,minecraft:stone)
B(2,34,7,minecraft:stone)
B(2,35,7,minecraft:stone)
B(2,36,7,minecraft:stone)
B(2,37,7,minecraft:andesite)
B(2,38,7,minecraft:andesite)
B(2,39,7,minecraft:andesite)
B(2,40,7,minecraft:andesite)
B(2,41,7,minecraft:andesite)
B(2,42,7,minecraft:andesite)
B(2,43,7,minecraft:andesite)
B(2,17,8,minecraft:andesite)
B(2,18,8,minecraft:andesite)
B(2,19,8,minecraft:andesite)
B(2,20,8,minecraft:andesite)
B(2,21,8,minecraft:andesite)
B(2,22,8,minecraft:andesite)
B(2,23,8,minecraft:andesite)
B(2,24,8,minecraft:andesite)
B(2,25,8,minecraft:stone)
B(2,26,8,minecraft:stone)
B(2,27,8,minecraft:stone)
B(2,28,8,minecraft:stone)
B(2,29,8,minecraft:stone)
B(2,30,8,minecraft:stone)
B(2,31,8,minecraft:stone)
B(2,32,8,minecraft:stone)
B(2,33,8,minecraft:stone)
B(2,34,8,minecraft:stone)
B(2,35,8,minecraft:stone)
B(2,36,8,minecraft:stone)
B(2,37,8,minecraft:andesite)
B(2,38,8,minecraft:andesite)
B(2,39,8,minecraft:andesite)
B(2,40,8,minecraft:andesite)
B(2,41,8,minecraft:andesite)
B(2,42,8,minecraft:andesite)
B(2,43,8,minecraft:andesite)
B(3,23,-7,minecraft:diorite)
B(3,24,-7,minecraft:diorite)
B(3,25,-7,minecraft:diorite)
B(3,26,-7,minecraft:diorite)
B(3,27,-7,minecraft:diorite)
B(3,28,-7,minecraft:diorite)
B(3,29,-7,minecraft:diorite)
B(3,30,-7,minecraft:diorite)
B(3,31,-7,minecraft:diorite)
B(3,32,-7,minecraft:diorite)
B(3,33,-7,minecraft:diorite)
B(3,34,-7,minecraft:andesite)
B(3,35,-7,minecraft:andesite)
B(3,22,-6,minecraft:diorite)
B(3,23,-6,minecraft:diorite)
B(3,24,-6,minecraft:diorite)
B(3,25,-6,minecraft:diorite)
B(3,26,-6,minecraft:diorite)
B(3,27,-6,minecraft:diorite)
B(3,28,-6,minecraft:diorite)
B(3,29,-6,minecraft:diorite)
B(3,30,-6,minecraft:andesite)
B(3,31,-6,minecraft:andesite)
B(3,32,-6,minecraft:andesite)
B(3,33,-6,minecraft:andesite)
B(3,34,-6,minecraft:andesite)
B(3,35,-6,minecraft:andesite)
B(3,36,-6,minecraft:andesite)
B(3,37,-6,minecraft:obsidian)
B(3,38,-6,minecraft:obsidian)
B(3,21,-5,minecraft:diorite)
B(3,22,-5,minecraft:diorite)
B(3,23,-5,minecraft:diorite)
B(3,24,-5,minecraft:diorite)
B(3,25,-5,minecraft:diorite)
B(3,26,-5,minecraft:diorite)
B(3,27,-5,minecraft:diorite)
B(3,28,-5,minecraft:diorite)
B(3,29,-5,minecraft:andesite)
B(3,30,-5,minecraft:andesite)
B(3,31,-5,minecraft:andesite)
B(3,32,-5,minecraft:andesite)
B(3,33,-5,minecraft:andesite)
B(3,34,-5,minecraft:andesite)
B(3,35,-5,minecraft:andesite)
B(3,36,-5,minecraft:andesite)
B(3,37,-5,minecraft:obsidian)
B(3,38,-5,minecraft:obsidian)
B(3,19,-4,minecraft:diorite)
B(3,20,-4,minecraft:diorite)
B(3,21,-4,minecraft:diorite)
B(3,22,-4,minecraft:diorite)
B(3,23,-4,minecraft:diorite)
B(3,24,-4,minecraft:diorite)
B(3,25,-4,minecraft:diorite)
B(3,26,-4,minecraft:diorite)
B(3,27,-4,minecraft:stone)
B(3,28,-4,minecraft:andesite)
B(3,29,-4,minecraft:andesite)
B(3,30,-4,minecraft:andesite)
B(3,31,-4,minecraft:andesite)
B(3,32,-4,minecraft:andesite)
B(3,33,-4,minecraft:andesite)
B(3,34,-4,minecraft:andesite)
B(3,35,-4,minecraft:andesite)
B(3,36,-4,minecraft:andesite)
B(3,37,-4,minecraft:obsidian)
B(3,38,-4,minecraft:obsidian)
B(3,39,-4,minecraft:obsidian)
B(3,40,-4,minecraft:obsidian)
B(3,19,-3,minecraft:diorite)
B(3,20,-3,minecraft:diorite)
B(3,21,-3,minecraft:diorite)
B(3,22,-3,minecraft:diorite)
B(3,23,-3,minecraft:diorite)
B(3,24,-3,minecraft:diorite)
B(3,25,-3,minecraft:diorite)
B(3,26,-3,minecraft:stone)
B(3,27,-3,minecraft:stone)
B(3,28,-3,minecraft:stone)
B(3,29,-3,minecraft:andesite)
B(3,30,-3,minecraft:andesite)
B(3,31,-3,minecraft:andesite)
B(3,32,-3,minecraft:andesite)
B(3,33,-3,minecraft:andesite)
B(3,34,-3,minecraft:andesite)
B(3,35,-3,minecraft:andesite)
B(3,36,-3,minecraft:andesite)
B(3,37,-3,minecraft:andesite)
B(3,38,-3,minecraft:obsidian)
B(3,39,-3,minecraft:obsidian)
B(3,40,-3,minecraft:obsidian)
B(3,41,-3,minecraft:andesite)
B(3,18,-2,minecraft:diorite)
B(3,19,-2,minecraft:diorite)
B(3,20,-2,minecraft:diorite)
B(3,21,-2,minecraft:diorite)
B(3,22,-2,minecraft:diorite)
B(3,23,-2,minecraft:diorite)
B(3,24,-2,minecraft:diorite)
B(3,25,-2,minecraft:andesite)
B(3,26,-2,minecraft:stone)
B(3,27,-2,minecraft:stone)
B(3,28,-2,minecraft:stone)
B(3,29,-2,minecraft:stone)
B(3,30,-2,minecraft:stone)
B(3,31,-2,minecraft:stone)
B(3,32,-2,minecraft:stone)
B(3,33,-2,minecraft:andesite)
B(3,34,-2,minecraft:andesite)
B(3,35,-2,minecraft:andesite)
B(3,36,-2,minecraft:andesite)
B(3,37,-2,minecraft:andesite)
B(3,38,-2,minecraft:andesite)
B(3,39,-2,minecraft:andesite)
B(3,40,-2,minecraft:andesite)
B(3,41,-2,minecraft:andesite)
B(3,18,-1,minecraft:diorite)
B(3,19,-1,minecraft:diorite)
B(3,20,-1,minecraft:diorite)
B(3,21,-1,minecraft:diorite)
B(3,22,-1,minecraft:diorite)
B(3,23,-1,minecraft:diorite)
B(3,24,-1,minecraft:andesite)
B(3,25,-1,minecraft:andesite)
B(3,26,-1,minecraft:stone)
B(3,27,-1,minecraft:stone)
B(3,28,-1,minecraft:stone)
B(3,29,-1,minecraft:stone)
B(3,30,-1,minecraft:stone)
B(3,31,-1,minecraft:stone)
B(3,32,-1,minecraft:stone)
B(3,33,-1,minecraft:stone)
B(3,34,-1,minecraft:stone)
B(3,35,-1,minecraft:andesite)
B(3,36,-1,minecraft:andesite)
B(3,37,-1,minecraft:andesite)
B(3,38,-1,minecraft:andesite)
B(3,39,-1,minecraft:andesite)
B(3,40,-1,minecraft:andesite)
B(3,41,-1,minecraft:andesite)
B(3,18,0,minecraft:diorite)
B(3,19,0,minecraft:diorite)
B(3,20,0,minecraft:diorite)
B(3,21,0,minecraft:andesite)
B(3,22,0,minecraft:andesite)
B(3,23,0,minecraft:andesite)
B(3,24,0,minecraft:andesite)
B(3,25,0,minecraft:stone)
B(3,26,0,minecraft:stone)
B(3,27,0,minecraft:stone)
B(3,28,0,minecraft:stone)
B(3,29,0,minecraft:stone)
B(3,30,0,minecraft:stone)
B(3,31,0,minecraft:stone)
B(3,32,0,minecraft:stone)
B(3,33,0,minecraft:stone)
B(3,34,0,minecraft:stone)
B(3,35,0,minecraft:andesite)
B(3,36,0,minecraft:andesite)
B(3,37,0,minecraft:andesite)
B(3,38,0,minecraft:andesite)
B(3,39,0,minecraft:andesite)
B(3,40,0,minecraft:andesite)
B(3,41,0,minecraft:andesite)
B(3,18,1,minecraft:andesite)
B(3,19,1,minecraft:andesite)
B(3,20,1,minecraft:andesite)
B(3,21,1,minecraft:andesite)
B(3,22,1,minecraft:andesite)
B(3,23,1,minecraft:andesite)
B(3,24,1,minecraft:andesite)
B(3,25,1,minecraft:stone)
B(3,26,1,minecraft:stone)
B(3,27,1,minecraft:stone)
B(3,28,1,minecraft:stone)
B(3,29,1,minecraft:stone)
B(3,30,1,minecraft:stone)
B(3,31,1,minecraft:stone)
B(3,32,1,minecraft:stone)
B(3,33,1,minecraft:stone)
B(3,34,1,minecraft:stone)
B(3,35,1,minecraft:andesite)
B(3,36,1,minecraft:andesite)
B(3,37,1,minecraft:andesite)
B(3,38,1,minecraft:andesite)
B(3,39,1,minecraft:andesite)
B(3,40,1,minecraft:andesite)
B(3,41,1,minecraft:andesite)
B(3,18,2,minecraft:andesite)
B(3,19,2,minecraft:andesite)
B(3,20,2,minecraft:andesite)
B(3,21,2,minecraft:andesite)
B(3,22,2,minecraft:andesite)
B(3,23,2,minecraft:andesite)
B(3,24,2,minecraft:andesite)
B(3,25,2,minecraft:stone)
B(3,26,2,minecraft:stone)
B(3,27,2,minecraft:stone)
B(3,28,2,minecraft:stone)
B(3,29,2,minecraft:stone)
B(3,30,2,minecraft:stone)
B(3,31,2,minecraft:stone)
B(3,32,2,minecraft:stone)
B(3,33,2,minecraft:stone)
B(3,34,2,minecraft:stone)
B(3,35,2,minecraft:andesite)
B(3,36,2,minecraft:andesite)
B(3,37,2,minecraft:andesite)
B(3,38,2,minecraft:andesite)
B(3,39,2,minecraft:andesite)
B(3,40,2,minecraft:andesite)
B(3,41,2,minecraft:andesite)
B(3,17,3,minecraft:andesite)
B(3,18,3,minecraft:andesite)
B(3,19,3,minecraft:andesite)
B(3,20,3,minecraft:andesite)
B(3,21,3,minecraft:andesite)
B(3,22,3,minecraft:andesite)
B(3,23,3,minecraft:andesite)
B(3,24,3,minecraft:andesite)
B(3,25,3,minecraft:stone)
B(3,26,3,minecraft:stone)
B(3,27,3,minecraft:stone)
B(3,28,3,minecraft:stone)
B(3,29,3,minecraft:stone)
B(3,30,3,minecraft:stone)
B(3,31,3,minecraft:stone)
B(3,32,3,minecraft:stone)
B(3,33,3,minecraft:stone)
B(3,34,3,minecraft:stone)
B(3,35,3,minecraft:stone)
B(3,36,3,minecraft:andesite)
B(3,37,3,minecraft:andesite)
B(3,38,3,minecraft:andesite)
B(3,39,3,minecraft:andesite)
B(3,40,3,minecraft:andesite)
B(3,41,3,minecraft:andesite)
B(3,42,3,minecraft:andesite)
B(3,17,4,minecraft:andesite)
B(3,18,4,minecraft:andesite)
B(3,19,4,minecraft:andesite)
B(3,20,4,minecraft:andesite)
B(3,21,4,minecraft:andesite)
B(3,22,4,minecraft:andesite)
B(3,23,4,minecraft:andesite)
B(3,24,4,minecraft:andesite)
B(3,25,4,minecraft:stone)
B(3,26,4,minecraft:stone)
B(3,27,4,minecraft:stone)
B(3,28,4,minecraft:stone)
B(3,29,4,minecraft:stone)
B(3,30,4,minecraft:stone)
B(3,31,4,minecraft:stone)
B(3,32,4,minecraft:stone)
B(3,33,4,minecraft:stone)
B(3,34,4,minecraft:stone)
B(3,35,4,minecraft:stone)
B(3,36,4,minecraft:andesite)
B(3,37,4,minecraft:andesite)
B(3,38,4,minecraft:andesite)
B(3,39,4,minecraft:andesite)
B(3,40,4,minecraft:andesite)
B(3,41,4,minecraft:andesite)
B(3,42,4,minecraft:andesite)
B(3,18,5,minecraft:andesite)
B(3,19,5,minecraft:andesite)
B(3,20,5,minecraft:andesite)
B(3,21,5,minecraft:andesite)
B(3,22,5,minecraft:andesite)
B(3,23,5,minecraft:andesite)
B(3,24,5,minecraft:stone)
B(3,25,5,minecraft:stone)
B(3,26,5,minecraft:stone)
B(3,27,5,minecraft:stone)
B(3,28,5,minecraft:stone)
B(3,29,5,minecraft:stone)
B(3,30,5,minecraft:stone)
B(3,31,5,minecraft:stone)
B(3,32,5,minecraft:stone)
B(3,33,5,minecraft:stone)
B(3,34,5,minecraft:stone)
B(3,35,5,minecraft:stone)
B(3,36,5,minecraft:andesite)
B(3,37,5,minecraft:andesite)
B(3,38,5,minecraft:andesite)
B(3,39,5,minecraft:andesite)
B(3,40,5,minecraft:andesite)
B(3,41,5,minecraft:andesite)
B(3,42,5,minecraft:andesite)
B(3,18,6,minecraft:andesite)
B(3,19,6,minecraft:andesite)
B(3,20,6,minecraft:andesite)
B(3,21,6,minecraft:andesite)
B(3,22,6,minecraft:andesite)
B(3,23,6,minecraft:andesite)
B(3,24,6,minecraft:stone)
B(3,25,6,minecraft:stone)
B(3,26,6,minecraft:stone)
B(3,27,6,minecraft:stone)
B(3,28,6,minecraft:stone)
B(3,29,6,minecraft:stone)
B(3,30,6,minecraft:stone)
B(3,31,6,minecraft:stone)
B(3,32,6,minecraft:stone)
B(3,33,6,minecraft:stone)
B(3,34,6,minecraft:stone)
B(3,35,6,minecraft:stone)
B(3,36,6,minecraft:stone)
B(3,37,6,minecraft:andesite)
B(3,38,6,minecraft:andesite)
B(3,39,6,minecraft:andesite)
B(3,40,6,minecraft:andesite)
B(3,41,6,minecraft:andesite)
B(3,42,6,minecraft:andesite)
B(3,43,6,minecraft:andesite)
B(3,17,7,minecraft:andesite)
B(3,18,7,minecraft:andesite)
B(3,19,7,minecraft:andesite)
B(3,20,7,minecraft:andesite)
B(3,21,7,minecraft:andesite)
B(3,22,7,minecraft:andesite)
B(3,23,7,minecraft:andesite)
B(3,24,7,minecraft:stone)
B(3,25,7,minecraft:stone)
B(3,26,7,minecraft:stone)
B(3,27,7,minecraft:stone)
B(3,28,7,minecraft:stone)
B(3,29,7,minecraft:stone)
B(3,30,7,minecraft:stone)
B(3,31,7,minecraft:stone)
B(3,32,7,minecraft:stone)
B(3,33,7,minecraft:stone)
B(3,34,7,minecraft:stone)
B(3,35,7,minecraft:stone)
B(3,36,7,minecraft:stone)
B(3,37,7,minecraft:stone)
B(3,38,7,minecraft:andesite)
B(3,39,7,minecraft:andesite)
B(3,40,7,minecraft:andesite)
B(3,41,7,minecraft:andesite)
B(3,42,7,minecraft:andesite)
B(3,43,7,minecraft:andesite)
B(3,44,7,minecraft:andesite)
B(3,16,8,minecraft:andesite)
B(3,17,8,minecraft:andesite)
B(3,18,8,minecraft:andesite)
B(3,19,8,minecraft:andesite)
B(3,20,8,minecraft:andesite)
B(3,21,8,minecraft:andesite)
B(3,22,8,minecraft:andesite)
B(3,23,8,minecraft:andesite)
B(3,24,8,minecraft:stone)
B(3,25,8,minecraft:stone)
B(3,26,8,minecraft:stone)
B(3,27,8,minecraft:stone)
B(3,28,8,minecraft:stone)
B(3,29,8,minecraft:stone)
B(3,30,8,minecraft:stone)
B(3,31,8,minecraft:stone)
B(3,32,8,minecraft:stone)
B(3,33,8,minecraft:stone)
B(3,34,8,minecraft:stone)
B(3,35,8,minecraft:stone)
B(3,36,8,minecraft:stone)
B(3,37,8,minecraft:andesite)
B(3,38,8,minecraft:andesite)
B(3,39,8,minecraft:andesite)
B(3,40,8,minecraft:andesite)
B(3,41,8,minecraft:andesite)
B(3,42,8,minecraft:andesite)
B(3,43,8,minecraft:andesite)
B(3,44,8,minecraft:andesite)
B(4,23,-7,minecraft:diorite)
B(4,24,-7,minecraft:diorite)
B(4,25,-7,minecraft:diorite)
B(4,26,-7,minecraft:diorite)
B(4,27,-7,minecraft:diorite)
B(4,28,-7,minecraft:diorite)
B(4,29,-7,minecraft:diorite)
B(4,30,-7,minecraft:diorite)
B(4,31,-7,minecraft:diorite)
B(4,32,-7,minecraft:diorite)
B(4,33,-7,minecraft:diorite)
B(4,34,-7,minecraft:andesite)
B(4,35,-7,minecraft:andesite)
B(4,36,-7,minecraft:andesite)
B(4,37,-7,minecraft:andesite)
B(4,38,-7,minecraft:obsidian)
B(4,39,-7,minecraft:obsidian)
B(4,21,-6,minecraft:diorite)
B(4,22,-6,minecraft:diorite)
B(4,23,-6,minecraft:diorite)
B(4,24,-6,minecraft:diorite)
B(4,25,-6,minecraft:diorite)
B(4,26,-6,minecraft:diorite)
B(4,27,-6,minecraft:diorite)
B(4,28,-6,minecraft:diorite)
B(4,29,-6,minecraft:diorite)
B(4,30,-6,minecraft:andesite)
B(4,31,-6,minecraft:andesite)
B(4,32,-6,minecraft:andesite)
B(4,33,-6,minecraft:andesite)
B(4,34,-6,minecraft:andesite)
B(4,35,-6,minecraft:andesite)
B(4,36,-6,minecraft:andesite)
B(4,37,-6,minecraft:obsidian)
B(4,38,-6,minecraft:obsidian)
B(4,39,-6,minecraft:obsidian)
B(4,20,-5,minecraft:diorite)
B(4,21,-5,minecraft:diorite)
B(4,22,-5,minecraft:diorite)
B(4,23,-5,minecraft:diorite)
B(4,24,-5,minecraft:diorite)
B(4,25,-5,minecraft:diorite)
B(4,26,-5,minecraft:diorite)
B(4,27,-5,minecraft:diorite)
B(4,28,-5,minecraft:diorite)
B(4,29,-5,minecraft:stone)
B(4,30,-5,minecraft:andesite)
B(4,31,-5,minecraft:andesite)
B(4,32,-5,minecraft:andesite)
B(4,33,-5,minecraft:andesite)
B(4,34,-5,minecraft:andesite)
B(4,35,-5,minecraft:andesite)
B(4,36,-5,minecraft:andesite)
B(4,37,-5,minecraft:obsidian)
B(4,38,-5,minecraft:obsidian)
B(4,39,-5,minecraft:obsidian)
B(4,19,-4,minecraft:diorite)
B(4,20,-4,minecraft:diorite)
B(4,21,-4,minecraft:diorite)
B(4,22,-4,minecraft:diorite)
B(4,23,-4,minecraft:diorite)
B(4,24,-4,minecraft:diorite)
B(4,25,-4,minecraft:diorite)
B(4,26,-4,minecraft:diorite)
B(4,27,-4,minecraft:stone)
B(4,28,-4,minecraft:stone)
B(4,29,-4,minecraft:stone)
B(4,30,-4,minecraft:stone)
B(4,31,-4,minecraft:andesite)
B(4,32,-4,minecraft:andesite)
B(4,33,-4,minecraft:andesite)
B(4,34,-4,minecraft:andesite)
B(4,35,-4,minecraft:andesite)
B(4,36,-4,minecraft:andesite)
B(4,37,-4,minecraft:obsidian)
B(4,38,-4,minecraft:obsidian)
B(4,39,-4,minecraft:obsidian)
B(4,40,-4,minecraft:obsidian)
B(4,18,-3,minecraft:diorite)
B(4,19,-3,minecraft:diorite)
B(4,20,-3,minecraft:diorite)
B(4,21,-3,minecraft:diorite)
B(4,22,-3,minecraft:diorite)
B(4,23,-3,minecraft:diorite)
B(4,24,-3,minecraft:diorite)
B(4,25,-3,minecraft:diorite)
B(4,26,-3,minecraft:stone)
B(4,27,-3,minecraft:stone)
B(4,28,-3,minecraft:stone)
B(4,29,-3,minecraft:stone)
B(4,30,-3,minecraft:stone)
B(4,31,-3,minecraft:stone)
B(4,32,-3,minecraft:stone)
B(4,33,-3,minecraft:andesite)
B(4,34,-3,minecraft:andesite)
B(4,35,-3,minecraft:andesite)
B(4,36,-3,minecraft:andesite)
B(4,37,-3,minecraft:andesite)
B(4,38,-3,minecraft:obsidian)
B(4,39,-3,minecraft:obsidian)
B(4,40,-3,minecraft:obsidian)
B(4,41,-3,minecraft:andesite)
B(4,18,-2,minecraft:diorite)
B(4,19,-2,minecraft:diorite)
B(4,20,-2,minecraft:diorite)
B(4,21,-2,minecraft:diorite)
B(4,22,-2,minecraft:diorite)
B(4,23,-2,minecraft:diorite)
B(4,24,-2,minecraft:diorite)
B(4,25,-2,minecraft:stone)
B(4,26,-2,minecraft:stone)
B(4,27,-2,minecraft:stone)
B(4,28,-2,minecraft:stone)
B(4,29,-2,minecraft:stone)
B(4,30,-2,minecraft:stone)
B(4,31,-2,minecraft:stone)
B(4,32,-2,minecraft:stone)
B(4,33,-2,minecraft:stone)
B(4,34,-2,minecraft:andesite)
B(4,35,-2,minecraft:andesite)
B(4,36,-2,minecraft:andesite)
B(4,37,-2,minecraft:andesite)
B(4,38,-2,minecraft:andesite)
B(4,39,-2,minecraft:andesite)
B(4,40,-2,minecraft:andesite)
B(4,41,-2,minecraft:andesite)
B(4,17,-1,minecraft:diorite)
B(4,18,-1,minecraft:diorite)
B(4,19,-1,minecraft:diorite)
B(4,20,-1,minecraft:diorite)
B(4,21,-1,minecraft:diorite)
B(4,22,-1,minecraft:diorite)
B(4,23,-1,minecraft:diorite)
B(4,24,-1,minecraft:andesite)
B(4,25,-1,minecraft:stone)
B(4,26,-1,minecraft:stone)
B(4,27,-1,minecraft:stone)
B(4,28,-1,minecraft:stone)
B(4,29,-1,minecraft:stone)
B(4,30,-1,minecraft:stone)
B(4,31,-1,minecraft:stone)
B(4,32,-1,minecraft:stone)
B(4,33,-1,minecraft:stone)
B(4,34,-1,minecraft:stone)
B(4,35,-1,minecraft:stone)
B(4,36,-1,minecraft:andesite)
B(4,37,-1,minecraft:andesite)
B(4,38,-1,minecraft:andesite)
B(4,39,-1,minecraft:andesite)
B(4,40,-1,minecraft:andesite)
B(4,41,-1,minecraft:andesite)
B(4,42,-1,minecraft:andesite)
B(4,17,0,minecraft:diorite)
B(4,18,0,minecraft:diorite)
B(4,19,0,minecraft:diorite)
B(4,20,0,minecraft:diorite)
B(4,21,0,minecraft:diorite)
B(4,22,0,minecraft:andesite)
B(4,23,0,minecraft:andesite)
B(4,24,0,minecraft:andesite)
B(4,25,0,minecraft:stone)
B(4,26,0,minecraft:stone)
B(4,27,0,minecraft:stone)
B(4,28,0,minecraft:stone)
B(4,29,0,minecraft:stone)
B(4,30,0,minecraft:stone)
B(4,31,0,minecraft:stone)
B(4,32,0,minecraft:stone)
B(4,33,0,minecraft:stone)
B(4,34,0,minecraft:stone)
B(4,35,0,minecraft:stone)
B(4,36,0,minecraft:andesite)
B(4,37,0,minecraft:andesite)
B(4,38,0,minecraft:andesite)
B(4,39,0,minecraft:andesite)
B(4,40,0,minecraft:andesite)
B(4,41,0,minecraft:andesite)
B(4,42,0,minecraft:andesite)
B(4,17,1,minecraft:diorite)
B(4,18,1,minecraft:diorite)
B(4,19,1,minecraft:diorite)
B(4,20,1,minecraft:andesite)
B(4,21,1,minecraft:andesite)
B(4,22,1,minecraft:andesite)
B(4,23,1,minecraft:andesite)
B(4,24,1,minecraft:stone)
B(4,25,1,minecraft:stone)
B(4,26,1,minecraft:stone)
B(4,27,1,minecraft:stone)
B(4,28,1,minecraft:stone)
B(4,29,1,minecraft:stone)
B(4,30,1,minecraft:stone)
B(4,31,1,minecraft:stone)
B(4,32,1,minecraft:stone)
B(4,33,1,minecraft:stone)
B(4,34,1,minecraft:stone)
B(4,35,1,minecraft:stone)
B(4,36,1,minecraft:andesite)
B(4,37,1,minecraft:andesite)
B(4,38,1,minecraft:andesite)
B(4,39,1,minecraft:andesite)
B(4,40,1,minecraft:andesite)
B(4,41,1,minecraft:andesite)
B(4,42,1,minecraft:andesite)
B(4,17,2,minecraft:andesite)
B(4,18,2,minecraft:andesite)
B(4,19,2,minecraft:andesite)
B(4,20,2,minecraft:andesite)
B(4,21,2,minecraft:andesite)
B(4,22,2,minecraft:andesite)
B(4,23,2,minecraft:andesite)
B(4,24,2,minecraft:stone)
B(4,25,2,minecraft:stone)
B(4,26,2,minecraft:stone)
B(4,27,2,minecraft:stone)
B(4,28,2,minecraft:stone)
B(4,29,2,minecraft:stone)
B(4,30,2,minecraft:stone)
B(4,31,2,minecraft:stone)
B(4,32,2,minecraft:stone)
B(4,33,2,minecraft:stone)
B(4,34,2,minecraft:stone)
B(4,35,2,minecraft:stone)
B(4,36,2,minecraft:andesite)
B(4,37,2,minecraft:andesite)
B(4,38,2,minecraft:andesite)
B(4,39,2,minecraft:andesite)
B(4,40,2,minecraft:andesite)
B(4,41,2,minecraft:andesite)
B(4,42,2,minecraft:andesite)
B(4,43,2,minecraft:andesite)
B(4,17,3,minecraft:andesite)
B(4,18,3,minecraft:andesite)
B(4,19,3,minecraft:andesite)
B(4,20,3,minecraft:andesite)
B(4,21,3,minecraft:andesite)
B(4,22,3,minecraft:andesite)
B(4,23,3,minecraft:andesite)
B(4,24,3,minecraft:stone)
B(4,25,3,minecraft:stone)
B(4,26,3,minecraft:stone)
B(4,27,3,minecraft:stone)
B(4,28,3,minecraft:stone)
B(4,29,3,minecraft:stone)
B(4,30,3,minecraft:stone)
B(4,31,3,minecraft:stone)
B(4,32,3,minecraft:stone)
B(4,33,3,minecraft:stone)
B(4,34,3,minecraft:stone)
B(4,35,3,minecraft:stone)
B(4,36,3,minecraft:andesite)
B(4,37,3,minecraft:andesite)
B(4,38,3,minecraft:andesite)
B(4,39,3,minecraft:andesite)
B(4,40,3,minecraft:andesite)
B(4,41,3,minecraft:andesite)
B(4,42,3,minecraft:andesite)
B(4,43,3,minecraft:andesite)
B(4,17,4,minecraft:andesite)
B(4,18,4,minecraft:andesite)
B(4,19,4,minecraft:andesite)
B(4,20,4,minecraft:andesite)
B(4,21,4,minecraft:andesite)
B(4,22,4,minecraft:andesite)
B(4,23,4,minecraft:stone)
B(4,24,4,minecraft:stone)
B(4,25,4,minecraft:stone)
B(4,26,4,minecraft:stone)
B(4,27,4,minecraft:stone)
B(4,28,4,minecraft:stone)
B(4,29,4,minecraft:stone)
B(4,30,4,minecraft:stone)
B(4,31,4,minecraft:stone)
B(4,32,4,minecraft:stone)
B(4,33,4,minecraft:stone)
B(4,34,4,minecraft:stone)
B(4,35,4,minecraft:stone)
B(4,36,4,minecraft:andesite)
B(4,37,4,minecraft:andesite)
B(4,38,4,minecraft:andesite)
B(4,39,4,minecraft:andesite)
B(4,40,4,minecraft:andesite)
B(4,41,4,minecraft:andesite)
B(4,42,4,minecraft:andesite)
B(4,43,4,minecraft:andesite)
B(4,17,5,minecraft:andesite)
B(4,18,5,minecraft:andesite)
B(4,19,5,minecraft:andesite)
B(4,20,5,minecraft:andesite)
B(4,21,5,minecraft:andesite)
B(4,22,5,minecraft:andesite)
B(4,23,5,minecraft:andesite)
B(4,24,5,minecraft:stone)
B(4,25,5,minecraft:stone)
B(4,26,5,minecraft:stone)
B(4,27,5,minecraft:stone)
B(4,28,5,minecraft:stone)
B(4,29,5,minecraft:stone)
B(4,30,5,minecraft:stone)
B(4,31,5,minecraft:stone)
B(4,32,5,minecraft:stone)
B(4,33,5,minecraft:stone)
B(4,34,5,minecraft:stone)
B(4,35,5,minecraft:stone)
B(4,36,5,minecraft:stone)
B(4,37,5,minecraft:andesite)
B(4,38,5,minecraft:andesite)
B(4,39,5,minecraft:andesite)
B(4,40,5,minecraft:andesite)
B(4,41,5,minecraft:andesite)
B(4,42,5,minecraft:andesite)
B(4,43,5,minecraft:andesite)
B(4,17,6,minecraft:andesite)
B(4,18,6,minecraft:andesite)
B(4,19,6,minecraft:andesite)
B(4,20,6,minecraft:andesite)
B(4,21,6,minecraft:andesite)
B(4,22,6,minecraft:andesite)
B(4,23,6,minecraft:andesite)
B(4,24,6,minecraft:stone)
B(4,25,6,minecraft:stone)
B(4,26,6,minecraft:stone)
B(4,27,6,minecraft:stone)
B(4,28,6,minecraft:stone)
B(4,29,6,minecraft:stone)
B(4,30,6,minecraft:magma_block)
B(4,31,6,minecraft:magma_block)
B(4,32,6,minecraft:magma_block)
B(4,33,6,minecraft:stone)
B(4,34,6,minecraft:stone)
B(4,35,6,minecraft:stone)
B(4,36,6,minecraft:stone)
B(4,37,6,minecraft:andesite)
B(4,38,6,minecraft:andesite)
B(4,39,6,minecraft:andesite)
B(4,40,6,minecraft:andesite)
B(4,41,6,minecraft:andesite)
B(4,42,6,minecraft:andesite)
B(4,43,6,minecraft:andesite)
B(4,44,6,minecraft:andesite)
B(4,16,7,minecraft:andesite)
B(4,17,7,minecraft:andesite)
B(4,18,7,minecraft:andesite)
B(4,19,7,minecraft:andesite)
B(4,20,7,minecraft:andesite)
B(4,21,7,minecraft:andesite)
B(4,22,7,minecraft:andesite)
B(4,23,7,minecraft:andesite)
B(4,24,7,minecraft:stone)
B(4,25,7,minecraft:stone)
B(4,26,7,minecraft:stone)
B(4,27,7,minecraft:stone)
B(4,28,7,minecraft:stone)
B(4,29,7,minecraft:stone)
B(4,30,7,minecraft:magma_block)
B(4,31,7,minecraft:magma_block)
B(4,32,7,minecraft:magma_block)
B(4,33,7,minecraft:stone)
B(4,34,7,minecraft:stone)
B(4,35,7,minecraft:stone)
B(4,36,7,minecraft:stone)
B(4,37,7,minecraft:stone)
B(4,38,7,minecraft:andesite)
B(4,39,7,minecraft:andesite)
B(4,40,7,minecraft:andesite)
B(4,41,7,minecraft:andesite)
B(4,42,7,minecraft:andesite)
B(4,43,7,minecraft:andesite)
B(4,44,7,minecraft:andesite)
B(4,16,8,minecraft:andesite)
B(4,17,8,minecraft:andesite)
B(4,18,8,minecraft:andesite)
B(4,19,8,minecraft:andesite)
B(4,20,8,minecraft:andesite)
B(4,21,8,minecraft:andesite)
B(4,22,8,minecraft:andesite)
B(4,23,8,minecraft:stone)
B(4,24,8,minecraft:stone)
B(4,25,8,minecraft:stone)
B(4,26,8,minecraft:stone)
B(4,27,8,minecraft:stone)
B(4,28,8,minecraft:stone)
B(4,29,8,minecraft:stone)
B(4,30,8,minecraft:magma_block)
B(4,31,8,minecraft:magma_block)
B(4,32,8,minecraft:magma_block)
B(4,33,8,minecraft:stone)
B(4,34,8,minecraft:stone)
B(4,35,8,minecraft:stone)
B(4,36,8,minecraft:stone)
B(4,37,8,minecraft:stone)
B(4,38,8,minecraft:andesite)
B(4,39,8,minecraft:andesite)
B(4,40,8,minecraft:andesite)
B(4,41,8,minecraft:andesite)
B(4,42,8,minecraft:andesite)
B(4,43,8,minecraft:andesite)
B(4,44,8,minecraft:andesite)
B(4,45,8,minecraft:andesite)
B(5,22,-7,minecraft:diorite)
B(5,23,-7,minecraft:diorite)
B(5,24,-7,minecraft:diorite)
B(5,25,-7,minecraft:diorite)
B(5,26,-7,minecraft:diorite)
B(5,27,-7,minecraft:diorite)
B(5,28,-7,minecraft:diorite)
B(5,29,-7,minecraft:diorite)
B(5,30,-7,minecraft:diorite)
B(5,31,-7,minecraft:diorite)
B(5,32,-7,minecraft:diorite)
B(5,33,-7,minecraft:diorite)
B(5,34,-7,minecraft:andesite)
B(5,35,-7,minecraft:andesite)
B(5,36,-7,minecraft:andesite)
B(5,37,-7,minecraft:andesite)
B(5,38,-7,minecraft:obsidian)
B(5,39,-7,minecraft:obsidian)
B(5,20,-6,minecraft:diorite)
B(5,21,-6,minecraft:diorite)
B(5,22,-6,minecraft:diorite)
B(5,23,-6,minecraft:diorite)
B(5,24,-6,minecraft:diorite)
B(5,25,-6,minecraft:diorite)
B(5,26,-6,minecraft:diorite)
B(5,27,-6,minecraft:diorite)
B(5,28,-6,minecraft:diorite)
B(5,29,-6,minecraft:diorite)
B(5,30,-6,minecraft:stone)
B(5,31,-6,minecraft:stone)
B(5,32,-6,minecraft:andesite)
B(5,33,-6,minecraft:andesite)
B(5,34,-6,minecraft:andesite)
B(5,35,-6,minecraft:andesite)
B(5,36,-6,minecraft:andesite)
B(5,37,-6,minecraft:obsidian)
B(5,38,-6,minecraft:obsidian)
B(5,39,-6,minecraft:obsidian)
B(5,40,-6,minecraft:obsidian)
B(5,20,-5,minecraft:diorite)
B(5,21,-5,minecraft:diorite)
B(5,22,-5,minecraft:diorite)
B(5,23,-5,minecraft:diorite)
B(5,24,-5,minecraft:diorite)
B(5,25,-5,minecraft:diorite)
B(5,26,-5,minecraft:diorite)
B(5,27,-5,minecraft:diorite)
B(5,28,-5,minecraft:stone)
B(5,29,-5,minecraft:stone)
B(5,30,-5,minecraft:stone)
B(5,31,-5,minecraft:stone)
B(5,32,-5,minecraft:andesite)
B(5,33,-5,minecraft:andesite)
B(5,34,-5,minecraft:andesite)
B(5,35,-5,minecraft:andesite)
B(5,36,-5,minecraft:andesite)
B(5,37,-5,minecraft:obsidian)
B(5,38,-5,minecraft:obsidian)
B(5,39,-5,minecraft:obsidian)
B(5,40,-5,minecraft:obsidian)
B(5,18,-4,minecraft:diorite)
B(5,19,-4,minecraft:diorite)
B(5,20,-4,minecraft:diorite)
B(5,21,-4,minecraft:diorite)
B(5,22,-4,minecraft:diorite)
B(5,23,-4,minecraft:diorite)
B(5,24,-4,minecraft:diorite)
B(5,25,-4,minecraft:diorite)
B(5,26,-4,minecraft:diorite)
B(5,27,-4,minecraft:stone)
B(5,28,-4,minecraft:stone)
B(5,29,-4,minecraft:stone)
B(5,30,-4,minecraft:stone)
B(5,31,-4,minecraft:stone)
B(5,32,-4,minecraft:stone)
B(5,33,-4,minecraft:andesite)
B(5,34,-4,minecraft:andesite)
B(5,35,-4,minecraft:andesite)
B(5,36,-4,minecraft:andesite)
B(5,37,-4,minecraft:obsidian)
B(5,38,-4,minecraft:obsidian)
B(5,39,-4,minecraft:obsidian)
B(5,40,-4,minecraft:obsidian)
B(5,41,-4,minecraft:obsidian)
B(5,17,-3,minecraft:diorite)
B(5,18,-3,minecraft:diorite)
B(5,19,-3,minecraft:diorite)
B(5,20,-3,minecraft:diorite)
B(5,21,-3,minecraft:diorite)
B(5,22,-3,minecraft:diorite)
B(5,23,-3,minecraft:diorite)
B(5,24,-3,minecraft:diorite)
B(5,25,-3,minecraft:diorite)
B(5,26,-3,minecraft:stone)
B(5,27,-3,minecraft:stone)
B(5,28,-3,minecraft:stone)
B(5,29,-3,minecraft:stone)
B(5,30,-3,minecraft:stone)
B(5,31,-3,minecraft:stone)
B(5,32,-3,minecraft:stone)
B(5,33,-3,minecraft:stone)
B(5,34,-3,minecraft:andesite)
B(5,35,-3,minecraft:andesite)
B(5,36,-3,minecraft:andesite)
B(5,37,-3,minecraft:andesite)
B(5,38,-3,minecraft:obsidian)
B(5,39,-3,minecraft:obsidian)
B(5,40,-3,minecraft:obsidian)
B(5,41,-3,minecraft:andesite)
B(5,17,-2,minecraft:diorite)
B(5,18,-2,minecraft:diorite)
B(5,19,-2,minecraft:diorite)
B(5,20,-2,minecraft:diorite)
B(5,21,-2,minecraft:diorite)
B(5,22,-2,minecraft:diorite)
B(5,23,-2,minecraft:diorite)
B(5,24,-2,minecraft:diorite)
B(5,25,-2,minecraft:stone)
B(5,26,-2,minecraft:stone)
B(5,27,-2,minecraft:stone)
B(5,28,-2,minecraft:stone)
B(5,29,-2,minecraft:stone)
B(5,30,-2,minecraft:stone)
B(5,31,-2,minecraft:stone)
B(5,32,-2,minecraft:stone)
B(5,33,-2,minecraft:stone)
B(5,34,-2,minecraft:stone)
B(5,35,-2,minecraft:andesite)
B(5,36,-2,minecraft:andesite)
B(5,37,-2,minecraft:andesite)
B(5,38,-2,minecraft:andesite)
B(5,39,-2,minecraft:andesite)
B(5,40,-2,minecraft:andesite)
B(5,41,-2,minecraft:andesite)
B(5,42,-2,minecraft:andesite)
B(5,17,-1,minecraft:diorite)
B(5,18,-1,minecraft:diorite)
B(5,19,-1,minecraft:diorite)
B(5,20,-1,minecraft:diorite)
B(5,21,-1,minecraft:diorite)
B(5,22,-1,minecraft:diorite)
B(5,23,-1,minecraft:diorite)
B(5,24,-1,minecraft:stone)
B(5,25,-1,minecraft:stone)
B(5,26,-1,minecraft:stone)
B(5,27,-1,minecraft:stone)
B(5,28,-1,minecraft:stone)
B(5,29,-1,minecraft:stone)
B(5,30,-1,minecraft:stone)
B(5,31,-1,minecraft:stone)
B(5,32,-1,minecraft:stone)
B(5,33,-1,minecraft:stone)
B(5,34,-1,minecraft:stone)
B(5,35,-1,minecraft:stone)
B(5,36,-1,minecraft:stone)
B(5,37,-1,minecraft:andesite)
B(5,38,-1,minecraft:andesite)
B(5,39,-1,minecraft:andesite)
B(5,40,-1,minecraft:andesite)
B(5,41,-1,minecraft:andesite)
B(5,42,-1,minecraft:andesite)
B(5,16,0,minecraft:diorite)
B(5,17,0,minecraft:diorite)
B(5,18,0,minecraft:diorite)
B(5,19,0,minecraft:diorite)
B(5,20,0,minecraft:diorite)
B(5,21,0,minecraft:diorite)
B(5,22,0,minecraft:andesite)
B(5,23,0,minecraft:andesite)
B(5,24,0,minecraft:stone)
B(5,25,0,minecraft:stone)
B(5,26,0,minecraft:stone)
B(5,27,0,minecraft:stone)
B(5,28,0,minecraft:stone)
B(5,29,0,minecraft:stone)
B(5,30,0,minecraft:stone)
B(5,31,0,minecraft:stone)
B(5,32,0,minecraft:stone)
B(5,33,0,minecraft:stone)
B(5,34,0,minecraft:stone)
B(5,35,0,minecraft:stone)
B(5,36,0,minecraft:stone)
B(5,37,0,minecraft:andesite)
B(5,38,0,minecraft:andesite)
B(5,39,0,minecraft:andesite)
B(5,40,0,minecraft:andesite)
B(5,41,0,minecraft:andesite)
B(5,42,0,minecraft:andesite)
B(5,16,1,minecraft:diorite)
B(5,17,1,minecraft:diorite)
B(5,18,1,minecraft:diorite)
B(5,19,1,minecraft:diorite)
B(5,20,1,minecraft:diorite)
B(5,21,1,minecraft:andesite)
B(5,22,1,minecraft:andesite)
B(5,23,1,minecraft:stone)
B(5,24,1,minecraft:stone)
B(5,25,1,minecraft:stone)
B(5,26,1,minecraft:stone)
B(5,27,1,minecraft:stone)
B(5,28,1,minecraft:stone)
B(5,29,1,minecraft:stone)
B(5,30,1,minecraft:stone)
B(5,31,1,minecraft:stone)
B(5,32,1,minecraft:stone)
B(5,33,1,minecraft:stone)
B(5,34,1,minecraft:stone)
B(5,35,1,minecraft:stone)
B(5,36,1,minecraft:stone)
B(5,37,1,minecraft:andesite)
B(5,38,1,minecraft:andesite)
B(5,39,1,minecraft:andesite)
B(5,40,1,minecraft:andesite)
B(5,41,1,minecraft:andesite)
B(5,42,1,minecraft:andesite)
B(5,43,1,minecraft:andesite)
B(5,16,2,minecraft:andesite)
B(5,17,2,minecraft:andesite)
B(5,18,2,minecraft:andesite)
B(5,19,2,minecraft:andesite)
B(5,20,2,minecraft:andesite)
B(5,21,2,minecraft:andesite)
B(5,22,2,minecraft:andesite)
B(5,23,2,minecraft:stone)
B(5,24,2,minecraft:stone)
B(5,25,2,minecraft:stone)
B(5,26,2,minecraft:stone)
B(5,27,2,minecraft:magma_block)
B(5,28,2,minecraft:magma_block)
B(5,29,2,minecraft:obsidian)
B(5,30,2,minecraft:stone)
B(5,31,2,minecraft:stone)
B(5,32,2,minecraft:stone)
B(5,33,2,minecraft:stone)
B(5,34,2,minecraft:stone)
B(5,35,2,minecraft:stone)
B(5,36,2,minecraft:stone)
B(5,37,2,minecraft:andesite)
B(5,38,2,minecraft:andesite)
B(5,39,2,minecraft:andesite)
B(5,40,2,minecraft:andesite)
B(5,41,2,minecraft:andesite)
B(5,42,2,minecraft:andesite)
B(5,43,2,minecraft:andesite)
B(5,44,2,minecraft:andesite)
B(5,16,3,minecraft:andesite)
B(5,17,3,minecraft:andesite)
B(5,18,3,minecraft:andesite)
B(5,19,3,minecraft:andesite)
B(5,20,3,minecraft:andesite)
B(5,21,3,minecraft:andesite)
B(5,22,3,minecraft:andesite)
B(5,23,3,minecraft:stone)
B(5,24,3,minecraft:stone)
B(5,25,3,minecraft:stone)
B(5,26,3,minecraft:stone)
B(5,27,3,minecraft:magma_block)
B(5,28,3,minecraft:obsidian)
B(5,29,3,minecraft:obsidian)
B(5,30,3,minecraft:stone)
B(5,31,3,minecraft:stone)
B(5,32,3,minecraft:stone)
B(5,33,3,minecraft:stone)
B(5,34,3,minecraft:stone)
B(5,35,3,minecraft:stone)
B(5,36,3,minecraft:stone)
B(5,37,3,minecraft:andesite)
B(5,38,3,minecraft:andesite)
B(5,39,3,minecraft:andesite)
B(5,40,3,minecraft:andesite)
B(5,41,3,minecraft:andesite)
B(5,42,3,minecraft:andesite)
B(5,43,3,minecraft:andesite)
B(5,44,3,minecraft:andesite)
B(5,16,4,minecraft:andesite)
B(5,17,4,minecraft:andesite)
B(5,18,4,minecraft:andesite)
B(5,19,4,minecraft:andesite)
B(5,20,4,minecraft:andesite)
B(5,21,4,minecraft:andesite)
B(5,22,4,minecraft:andesite)
B(5,23,4,minecraft:stone)
B(5,24,4,minecraft:stone)
B(5,25,4,minecraft:stone)
B(5,26,4,minecraft:stone)
B(5,27,4,minecraft:magma_block)
B(5,28,4,minecraft:magma_block)
B(5,29,4,minecraft:obsidian)
B(5,30,4,minecraft:stone)
B(5,31,4,minecraft:stone)
B(5,32,4,minecraft:stone)
B(5,33,4,minecraft:stone)
B(5,34,4,minecraft:stone)
B(5,35,4,minecraft:stone)
B(5,36,4,minecraft:stone)
B(5,37,4,minecraft:andesite)
B(5,38,4,minecraft:andesite)
B(5,39,4,minecraft:andesite)
B(5,40,4,minecraft:andesite)
B(5,41,4,minecraft:andesite)
B(5,42,4,minecraft:andesite)
B(5,43,4,minecraft:andesite)
B(5,44,4,minecraft:andesite)
B(5,17,5,minecraft:andesite)
B(5,18,5,minecraft:andesite)
B(5,19,5,minecraft:andesite)
B(5,20,5,minecraft:andesite)
B(5,21,5,minecraft:andesite)
B(5,22,5,minecraft:andesite)
B(5,23,5,minecraft:stone)
B(5,24,5,minecraft:stone)
B(5,25,5,minecraft:stone)
B(5,26,5,minecraft:stone)
B(5,27,5,minecraft:stone)
B(5,28,5,minecraft:stone)
B(5,29,5,minecraft:magma_block)
B(5,30,5,minecraft:magma_block)
B(5,31,5,minecraft:magma_block)
B(5,32,5,minecraft:magma_block)
B(5,33,5,minecraft:magma_block)
B(5,34,5,minecraft:stone)
B(5,35,5,minecraft:stone)
B(5,36,5,minecraft:stone)
B(5,37,5,minecraft:andesite)
B(5,38,5,minecraft:andesite)
B(5,39,5,minecraft:andesite)
B(5,40,5,minecraft:andesite)
B(5,41,5,minecraft:andesite)
B(5,42,5,minecraft:andesite)
B(5,43,5,minecraft:andesite)
B(5,44,5,minecraft:andesite)
B(5,17,6,minecraft:andesite)
B(5,18,6,minecraft:andesite)
B(5,19,6,minecraft:andesite)
B(5,20,6,minecraft:andesite)
B(5,21,6,minecraft:andesite)
B(5,22,6,minecraft:andesite)
B(5,23,6,minecraft:stone)
B(5,24,6,minecraft:stone)
B(5,25,6,minecraft:stone)
B(5,26,6,minecraft:stone)
B(5,27,6,minecraft:stone)
B(5,28,6,minecraft:stone)
B(5,29,6,minecraft:magma_block)
B(5,30,6,minecraft:magma_block)
B(5,31,6,minecraft:magma_block)
B(5,32,6,minecraft:magma_block)
B(5,33,6,minecraft:magma_block)
B(5,34,6,minecraft:stone)
B(5,35,6,minecraft:stone)
B(5,36,6,minecraft:stone)
B(5,37,6,minecraft:stone)
B(5,38,6,minecraft:andesite)
B(5,39,6,minecraft:andesite)
B(5,40,6,minecraft:andesite)
B(5,41,6,minecraft:andesite)
B(5,42,6,minecraft:andesite)
B(5,43,6,minecraft:andesite)
B(5,44,6,minecraft:andesite)
B(5,45,6,minecraft:andesite)
B(5,16,7,minecraft:andesite)
B(5,17,7,minecraft:andesite)
B(5,18,7,minecraft:andesite)
B(5,19,7,minecraft:andesite)
B(5,20,7,minecraft:andesite)
B(5,21,7,minecraft:andesite)
B(5,22,7,minecraft:andesite)
B(5,23,7,minecraft:stone)
B(5,24,7,minecraft:stone)
B(5,25,7,minecraft:stone)
B(5,26,7,minecraft:stone)
B(5,27,7,minecraft:stone)
B(5,28,7,minecraft:stone)
B(5,29,7,minecraft:magma_block)
B(5,30,7,minecraft:magma_block)
B(5,31,7,minecraft:magma_block)
B(5,32,7,minecraft:magma_block)
B(5,33,7,minecraft:magma_block)
B(5,34,7,minecraft:stone)
B(5,35,7,minecraft:stone)
B(5,36,7,minecraft:stone)
B(5,37,7,minecraft:stone)
B(5,38,7,minecraft:stone)
B(5,39,7,minecraft:andesite)
B(5,40,7,minecraft:andesite)
B(5,41,7,minecraft:andesite)
B(5,42,7,minecraft:andesite)
B(5,43,7,minecraft:andesite)
B(5,44,7,minecraft:andesite)
B(5,45,7,minecraft:andesite)
B(5,16,8,minecraft:andesite)
B(5,17,8,minecraft:andesite)
B(5,18,8,minecraft:andesite)
B(5,19,8,minecraft:andesite)
B(5,20,8,minecraft:andesite)
B(5,21,8,minecraft:andesite)
B(5,22,8,minecraft:andesite)
B(5,23,8,minecraft:stone)
B(5,24,8,minecraft:stone)
B(5,25,8,minecraft:stone)
B(5,26,8,minecraft:stone)
B(5,27,8,minecraft:stone)
B(5,28,8,minecraft:stone)
B(5,29,8,minecraft:magma_block)
B(5,30,8,minecraft:magma_block)
B(5,31,8,minecraft:magma_block)
B(5,32,8,minecraft:magma_block)
B(5,33,8,minecraft:magma_block)
B(5,34,8,minecraft:magma_block)
B(5,35,8,minecraft:magma_block)
B(5,36,8,minecraft:magma_block)
B(5,37,8,minecraft:stone)
B(5,38,8,minecraft:stone)
B(5,39,8,minecraft:andesite)
B(5,40,8,minecraft:andesite)
B(5,41,8,minecraft:andesite)
B(5,42,8,minecraft:andesite)
B(5,43,8,minecraft:andesite)
B(5,44,8,minecraft:andesite)
B(5,45,8,minecraft:andesite)
B(6,21,-7,minecraft:diorite)
B(6,22,-7,minecraft:diorite)
B(6,23,-7,minecraft:diorite)
B(6,24,-7,minecraft:diorite)
B(6,25,-7,minecraft:diorite)
B(6,26,-7,minecraft:diorite)
B(6,27,-7,minecraft:diorite)
B(6,28,-7,minecraft:diorite)
B(6,29,-7,minecraft:diorite)
B(6,30,-7,minecraft:diorite)
B(6,31,-7,minecraft:diorite)
B(6,32,-7,minecraft:diorite)
B(6,33,-7,minecraft:diorite)
B(6,34,-7,minecraft:diorite)
B(6,35,-7,minecraft:diorite)
B(6,36,-7,minecraft:diorite)
B(6,37,-7,minecraft:diorite)
B(6,38,-7,minecraft:obsidian)
B(6,39,-7,minecraft:obsidian)
B(6,40,-7,minecraft:obsidian)
B(6,20,-6,minecraft:diorite)
B(6,21,-6,minecraft:diorite)
B(6,22,-6,minecraft:diorite)
B(6,23,-6,minecraft:diorite)
B(6,24,-6,minecraft:diorite)
B(6,25,-6,minecraft:diorite)
B(6,26,-6,minecraft:diorite)
B(6,27,-6,minecraft:diorite)
B(6,28,-6,minecraft:diorite)
B(6,29,-6,minecraft:stone)
B(6,30,-6,minecraft:stone)
B(6,31,-6,minecraft:stone)
B(6,32,-6,minecraft:andesite)
B(6,33,-6,minecraft:andesite)
B(6,34,-6,minecraft:andesite)
B(6,35,-6,minecraft:andesite)
B(6,36,-6,minecraft:andesite)
B(6,37,-6,minecraft:andesite)
B(6,38,-6,minecraft:obsidian)
B(6,39,-6,minecraft:obsidian)
B(6,40,-6,minecraft:obsidian)
B(6,41,-6,minecraft:obsidian)
B(6,19,-5,minecraft:diorite)
B(6,20,-5,minecraft:diorite)
B(6,21,-5,minecraft:diorite)
B(6,22,-5,minecraft:diorite)
B(6,23,-5,minecraft:diorite)
B(6,24,-5,minecraft:diorite)
B(6,25,-5,minecraft:diorite)
B(6,26,-5,minecraft:diorite)
B(6,27,-5,minecraft:stone)
B(6,28,-5,minecraft:stone)
B(6,29,-5,minecraft:stone)
B(6,30,-5,minecraft:stone)
B(6,31,-5,minecraft:stone)
B(6,32,-5,minecraft:stone)
B(6,33,-5,minecraft:andesite)
B(6,34,-5,minecraft:andesite)
B(6,35,-5,minecraft:andesite)
B(6,36,-5,minecraft:andesite)
B(6,37,-5,minecraft:andesite)
B(6,38,-5,minecraft:obsidian)
B(6,39,-5,minecraft:obsidian)
B(6,40,-5,minecraft:obsidian)
B(6,41,-5,minecraft:obsidian)
B(6,18,-4,minecraft:diorite)
B(6,19,-4,minecraft:diorite)
B(6,20,-4,minecraft:diorite)
B(6,21,-4,minecraft:diorite)
B(6,22,-4,minecraft:diorite)
B(6,23,-4,minecraft:diorite)
B(6,24,-4,minecraft:diorite)
B(6,25,-4,minecraft:diorite)
B(6,26,-4,minecraft:stone)
B(6,27,-4,minecraft:stone)
B(6,28,-4,minecraft:stone)
B(6,29,-4,minecraft:stone)
B(6,30,-4,minecraft:stone)
B(6,31,-4,minecraft:stone)
B(6,32,-4,minecraft:stone)
B(6,33,-4,minecraft:andesite)
B(6,34,-4,minecraft:andesite)
B(6,35,-4,minecraft:andesite)
B(6,36,-4,minecraft:andesite)
B(6,37,-4,minecraft:andesite)
B(6,38,-4,minecraft:obsidian)
B(6,39,-4,minecraft:obsidian)
B(6,40,-4,minecraft:obsidian)
B(6,41,-4,minecraft:obsidian)
B(6,42,-4,minecraft:andesite)
B(6,17,-3,minecraft:diorite)
B(6,18,-3,minecraft:diorite)
