
#######################################################################
# +-----------------------------------------------------------------+ #
# |                            BO3 object                           | #
# +-----------------------------------------------------------------+ #
#######################################################################

Author: Bo3 BulkEdit

Description: Converted Schematic - Modified by Bo3BulkEdit

Version: 3

SettingsMode: WriteWithoutComments


#######################################################################
# +-----------------------------------------------------------------+ #
# |                          Main settings                          | #
# +-----------------------------------------------------------------+ #
#######################################################################

Tree: false

Frequency: 1

Rarity: 100.0

RotateRandomly: false

SpawnHeight: randomY

SpawnHeightOffset: 0

SpawnHeightVariance: 0

##############################
# Height Limits for the BO3. #
##############################

MinHeight: 0

MaxHeight: 255

######################
# Extrusion settings #
######################

ExtrudeMode: None

ExtrudeThroughBlocks: minecraft:air

MaxBranchDepth: 10


#######################################################################
# +-----------------------------------------------------------------+ #
# |                      Source block settings                      | #
# +-----------------------------------------------------------------+ #
#######################################################################

SourceBlocks: otg:air

MaxPercentageOutsideSourceBlock: 100

OutsideSourceBlock: placeAnyway

DoReplaceBlocks: true

IsOTGPlus: false


#######################################################################
# +-----------------------------------------------------------------+ #
# |                              Blocks                             | #
# +-----------------------------------------------------------------+ #
#######################################################################

B(0,13,0,minecraft:smooth_stone_slab[type=top,waterlogged=false])
B(0,15,0,minecraft:water)
B(0,16,0,minecraft:water)
B(0,18,0,minecraft:water)
B(0,19,0,minecraft:water)
B(0,22,0,minecraft:stone_brick_stairs[facing=west,half=top,shape=straight,waterlogged=false])
B(0,33,0,minecraft:stone_slab)
B(0,36,0,minecraft:stone_brick_stairs[facing=north,half=top,shape=straight,waterlogged=false])
B(0,37,0,minecraft:stone_slab)
B(0,41,0,minecraft:smooth_stone_slab[type=top,waterlogged=false])
B(0,45,0,minecraft:smooth_stone_slab[type=top,waterlogged=false])
B(0,49,0,minecraft:smooth_stone_slab[type=top,waterlogged=false])
B(0,15,1,minecraft:water)
B(0,16,1,minecraft:water)
B(0,29,1,minecraft:stone_brick_stairs[facing=west,half=bottom,shape=straight,waterlogged=false])
B(0,33,1,minecraft:stone_slab)
B(0,37,1,minecraft:stone_slab)
B(0,45,1,minecraft:smooth_stone_slab[type=top,waterlogged=false])
B(0,49,1,minecraft:smooth_stone_slab[type=top,waterlogged=false])
B(0,12,2,minecraft:stone_brick_stairs[facing=south,half=top,shape=straight,waterlogged=false])
B(0,15,2,minecraft:water)
B(0,16,2,minecraft:water)
B(0,33,2,minecraft:stone_slab)
B(0,41,2,minecraft:stone_brick_stairs[facing=north,half=top,shape=straight,waterlogged=false])
B(0,46,2,minecraft:cobblestone_wall[east=tall,north=none,south=none,up=true,waterlogged=false,west=none])
B(0,47,2,minecraft:iron_bars[east=true,north=false,south=false,waterlogged=false,west=false])
B(0,48,2,minecraft:stone_brick_stairs[facing=west,half=top,shape=straight,waterlogged=false])
B(0,11,3,minecraft:stone_brick_stairs[facing=east,half=top,shape=straight,waterlogged=false])
B(0,15,3,minecraft:water)
B(0,16,3,minecraft:water)
B(0,25,3,minecraft:stone_brick_stairs[facing=east,half=bottom,shape=straight,waterlogged=false])
B(0,33,3,minecraft:stone_slab)
B(0,37,3,minecraft:smooth_stone_slab[type=top,waterlogged=false])
B(0,41,3,minecraft:smooth_stone_slab[type=top,waterlogged=false])
B(0,49,3,minecraft:smooth_stone_slab[type=top,waterlogged=false])
B(0,11,4,minecraft:smooth_stone_slab[type=top,waterlogged=false])
B(0,15,4,minecraft:water)
B(0,16,4,minecraft:water)
B(0,25,4,minecraft:stone_brick_stairs[facing=east,half=bottom,shape=straight,waterlogged=false])
B(0,29,4,minecraft:stone_brick_stairs[facing=east,half=top,shape=straight,waterlogged=false])
B(0,33,4,minecraft:stone_slab)
B(0,37,4,minecraft:smooth_stone_slab[type=top,waterlogged=false])
B(0,41,4,minecraft:smooth_stone_slab[type=top,waterlogged=false])
B(0,49,4,minecraft:smooth_stone_slab[type=top,waterlogged=false])
B(0,11,5,minecraft:stone_brick_stairs[facing=east,half=top,shape=straight,waterlogged=false])
B(0,13,5,minecraft:water)
B(0,14,5,minecraft:water)
B(0,15,5,minecraft:water)
B(0,16,5,minecraft:water)
B(0,25,5,minecraft:stone_brick_stairs[facing=east,half=bottom,shape=straight,waterlogged=false])
B(0,33,5,minecraft:stone_slab)
B(0,37,5,minecraft:smooth_stone_slab[type=top,waterlogged=false])
B(0,41,5,minecraft:stone_brick_stairs[facing=south,half=top,shape=straight,waterlogged=false])
B(0,49,5,minecraft:smooth_stone_slab[type=top,waterlogged=false])
B(0,11,6,minecraft:smooth_stone_slab[type=top,waterlogged=false])
B(0,13,6,minecraft:water)
B(0,14,6,minecraft:water)
B(0,15,6,minecraft:water)
B(0,16,6,minecraft:water)
B(0,25,6,minecraft:stone_brick_stairs[facing=east,half=bottom,shape=straight,waterlogged=false])
B(0,27,6,minecraft:stone_brick_stairs[facing=east,half=top,shape=straight,waterlogged=false])
B(0,30,6,minecraft:stone_brick_stairs[facing=west,half=bottom,shape=straight,waterlogged=false])
B(0,33,6,minecraft:stone_slab)
B(0,49,6,minecraft:smooth_stone_slab[type=top,waterlogged=false])
B(0,12,7,minecraft:stone_brick_stairs[facing=east,half=top,shape=straight,waterlogged=false])
B(0,13,7,minecraft:water)
B(0,14,7,minecraft:water)
B(0,15,7,minecraft:water)
B(0,16,7,minecraft:water)
B(0,25,7,minecraft:stone_brick_stairs[facing=east,half=bottom,shape=straight,waterlogged=false])
B(0,33,7,minecraft:stone_slab)
B(0,37,7,minecraft:smooth_stone_slab[type=top,waterlogged=false])
B(0,38,7,minecraft:stone_slab)
B(0,41,7,minecraft:smooth_stone_slab[type=top,waterlogged=false])
B(0,42,7,minecraft:stone_slab)
B(0,49,7,minecraft:smooth_stone_slab[type=top,waterlogged=false])
B(1,15,0,minecraft:water)
B(1,16,0,minecraft:water)
B(1,18,0,minecraft:water)
B(1,19,0,minecraft:water)
B(1,15,1,minecraft:water)
B(1,16,1,minecraft:water)
B(1,18,1,minecraft:water)
B(1,19,1,minecraft:water)
B(1,20,1,minecraft:stone_brick_stairs[facing=south,half=top,shape=straight,waterlogged=false])
B(1,33,1,minecraft:stone_slab)
B(1,37,1,minecraft:stone_slab)
B(1,40,1,minecraft:stone_brick_stairs[facing=east,half=top,shape=straight,waterlogged=false])
B(1,45,1,minecraft:smooth_stone_slab[type=top,waterlogged=false])
B(1,49,1,minecraft:smooth_stone_slab[type=top,waterlogged=false])
B(1,11,2,minecraft:stone_brick_stairs[facing=south,half=top,shape=straight,waterlogged=false])
B(1,15,2,minecraft:water)
B(1,16,2,minecraft:water)
B(1,18,2,minecraft:water)
B(1,19,2,minecraft:water)
B(1,20,2,minecraft:stone_slab)
B(1,33,2,minecraft:stone_slab)
B(1,41,2,minecraft:smooth_stone_slab[type=top,waterlogged=false])
B(1,44,2,minecraft:stone_brick_stairs[facing=east,half=top,shape=straight,waterlogged=false])
B(1,46,2,minecraft:cobblestone_wall[east=none,north=none,south=none,up=true,waterlogged=false,west=tall])
B(1,47,2,minecraft:iron_bars[east=false,north=false,south=false,waterlogged=false,west=true])
B(1,48,2,minecraft:stone_brick_stairs[facing=east,half=top,shape=straight,waterlogged=false])
B(1,7,3,minecraft:stone_brick_stairs[facing=east,half=bottom,shape=straight,waterlogged=false])
B(1,10,3,minecraft:stone_brick_stairs[facing=east,half=top,shape=straight,waterlogged=false])
B(1,15,3,minecraft:water)
B(1,16,3,minecraft:water)
B(1,18,3,minecraft:water)
B(1,19,3,minecraft:water)
B(1,20,3,minecraft:stone_slab)
B(1,24,3,minecraft:stone_brick_stairs[facing=west,half=top,shape=straight,waterlogged=false])
B(1,33,3,minecraft:stone_slab)
B(1,37,3,minecraft:smooth_stone_slab[type=top,waterlogged=false])
B(1,41,3,minecraft:smooth_stone_slab[type=top,waterlogged=false])
B(1,49,3,minecraft:smooth_stone_slab[type=top,waterlogged=false])
B(1,10,4,minecraft:smooth_stone_slab[type=top,waterlogged=false])
B(1,15,4,minecraft:water)
B(1,16,4,minecraft:water)
B(1,18,4,minecraft:water)
B(1,19,4,minecraft:water)
B(1,20,4,minecraft:stone_slab)
B(1,30,4,minecraft:stone_brick_stairs[facing=west,half=bottom,shape=straight,waterlogged=false])
B(1,33,4,minecraft:stone_slab)
B(1,37,4,minecraft:smooth_stone_slab[type=top,waterlogged=false])
B(1,41,4,minecraft:smooth_stone_slab[type=top,waterlogged=false])
B(1,49,4,minecraft:smooth_stone_slab[type=top,waterlogged=false])
B(1,7,5,minecraft:stone_brick_stairs[facing=east,half=bottom,shape=straight,waterlogged=false])
B(1,10,5,minecraft:stone_brick_stairs[facing=east,half=top,shape=straight,waterlogged=false])
B(1,13,5,minecraft:water)
B(1,14,5,minecraft:water)
B(1,15,5,minecraft:water)
B(1,16,5,minecraft:water)
B(1,18,5,minecraft:water)
B(1,19,5,minecraft:water)
B(1,20,5,minecraft:stone_slab)
B(1,24,5,minecraft:stone_brick_stairs[facing=west,half=top,shape=straight,waterlogged=false])
B(1,33,5,minecraft:stone_slab)
B(1,37,5,minecraft:smooth_stone_slab[type=top,waterlogged=false])
B(1,41,5,minecraft:smooth_stone_slab[type=top,waterlogged=false])
B(1,49,5,minecraft:smooth_stone_slab[type=top,waterlogged=false])
B(1,11,6,minecraft:stone_brick_stairs[facing=north,half=top,shape=straight,waterlogged=false])
B(1,13,6,minecraft:water)
B(1,14,6,minecraft:water)
B(1,15,6,minecraft:water)
B(1,16,6,minecraft:water)
B(1,18,6,minecraft:water)
B(1,19,6,minecraft:water)
B(1,21,6,minecraft:stone_brick_stairs[facing=south,half=bottom,shape=outer_left,waterlogged=false])
B(1,28,6,minecraft:stone_brick_stairs[facing=west,half=bottom,shape=straight,waterlogged=false])
B(1,33,6,minecraft:stone_slab)
B(1,36,6,minecraft:stone_brick_stairs[facing=east,half=top,shape=straight,waterlogged=false])
B(1,49,6,minecraft:smooth_stone_slab[type=top,waterlogged=false])
B(1,13,7,minecraft:water)
B(1,14,7,minecraft:water)
B(1,15,7,minecraft:water)
B(1,16,7,minecraft:water)
B(1,18,7,minecraft:water)
B(1,19,7,minecraft:water)
B(1,20,7,minecraft:stone_brick_stairs[facing=west,half=top,shape=straight,waterlogged=false])
B(1,21,7,minecraft:stone_brick_stairs[facing=east,half=bottom,shape=straight,waterlogged=false])
B(1,24,7,minecraft:stone_brick_stairs[facing=west,half=top,shape=straight,waterlogged=false])
B(1,33,7,minecraft:stone_slab)
B(1,37,7,minecraft:smooth_stone_slab[type=top,waterlogged=false])
B(1,38,7,minecraft:stone_slab)
B(1,41,7,minecraft:smooth_stone_slab[type=top,waterlogged=false])
B(1,42,7,minecraft:stone_slab)
B(1,49,7,minecraft:smooth_stone_slab[type=top,waterlogged=false])
B(2,7,0,minecraft:stone_brick_stairs[facing=east,half=bottom,shape=straight,waterlogged=false])
B(2,8,0,minecraft:stone_slab)
B(2,9,0,minecraft:smooth_stone_slab[type=top,waterlogged=false])
B(2,15,0,minecraft:water)
B(2,16,0,minecraft:water)
B(2,18,0,minecraft:water)
B(2,19,0,minecraft:water)
B(2,7,1,minecraft:stone_brick_stairs[facing=east,half=bottom,shape=straight,waterlogged=false])
B(2,8,1,minecraft:stone_slab)
B(2,9,1,minecraft:smooth_stone_slab[type=top,waterlogged=false])
B(2,15,1,minecraft:water)
B(2,16,1,minecraft:water)
B(2,7,2,minecraft:stone_brick_stairs[facing=east,half=bottom,shape=straight,waterlogged=false])
B(2,8,2,minecraft:stone_slab)
B(2,9,2,minecraft:smooth_stone_slab[type=top,waterlogged=false])
B(2,15,2,minecraft:water)
B(2,16,2,minecraft:water)
B(2,21,2,minecraft:stone_brick_stairs)
B(2,23,2,minecraft:stone_brick_stairs[facing=north,half=top,shape=straight,waterlogged=false])
B(2,8,3,minecraft:stone_brick_stairs[facing=east,half=bottom,shape=straight,waterlogged=false])
B(2,9,3,minecraft:stone_brick_stairs[facing=east,half=top,shape=straight,waterlogged=false])
B(2,15,3,minecraft:water)
B(2,16,3,minecraft:water)
B(2,20,3,minecraft:stone_slab)
B(2,8,4,minecraft:cobblestone_wall)
B(2,9,4,minecraft:cobblestone_wall)
B(2,15,4,minecraft:water)
B(2,16,4,minecraft:water)
B(2,20,4,minecraft:stone_slab)
B(2,33,4,minecraft:stone_slab)
B(2,37,4,minecraft:smooth_stone_slab[type=top,waterlogged=false])
B(2,41,4,minecraft:stone_brick_stairs[facing=east,half=top,shape=straight,waterlogged=false])
B(2,49,4,minecraft:smooth_stone_slab[type=top,waterlogged=false])
B(2,8,5,minecraft:stone_brick_stairs[facing=east,half=bottom,shape=straight,waterlogged=false])
B(2,9,5,minecraft:stone_brick_stairs[facing=east,half=top,shape=straight,waterlogged=false])
B(2,13,5,minecraft:water)
B(2,14,5,minecraft:water)
B(2,15,5,minecraft:water)
B(2,16,5,minecraft:water)
B(2,20,5,minecraft:stone_slab)
B(2,33,5,minecraft:stone_slab)
B(2,37,5,minecraft:smooth_stone_slab[type=top,waterlogged=false])
B(2,41,5,minecraft:smooth_stone_slab[type=top,waterlogged=false])
B(2,49,5,minecraft:smooth_stone_slab[type=top,waterlogged=false])
B(2,10,6,minecraft:stone_brick_stairs[facing=north,half=top,shape=straight,waterlogged=false])
B(2,13,6,minecraft:water)
B(2,14,6,minecraft:water)
B(2,15,6,minecraft:water)
B(2,16,6,minecraft:water)
B(2,21,6,minecraft:stone_brick_stairs[facing=south,half=bottom,shape=straight,waterlogged=false])
B(2,40,6,minecraft:stone_brick_stairs[facing=east,half=top,shape=straight,waterlogged=false])
B(2,49,6,minecraft:smooth_stone_slab[type=top,waterlogged=false])
B(2,13,7,minecraft:water)
B(2,14,7,minecraft:water)
B(2,15,7,minecraft:water)
B(2,16,7,minecraft:water)
B(2,18,7,minecraft:water)
B(2,19,7,minecraft:water)
B(2,20,7,minecraft:water)
B(2,21,7,minecraft:water)
B(2,33,7,minecraft:stone_slab)
B(2,37,7,minecraft:smooth_stone_slab[type=top,waterlogged=false])
B(2,38,7,minecraft:stone_slab)
B(2,41,7,minecraft:smooth_stone_slab[type=top,waterlogged=false])
B(2,42,7,minecraft:stone_slab)
B(2,49,7,minecraft:smooth_stone_slab[type=top,waterlogged=false])
B(3,7,0,minecraft:lava)
B(3,8,0,minecraft:lava)
B(3,9,0,minecraft:lava)
B(3,22,0,minecraft:stone_brick_stairs[facing=south,half=bottom,shape=straight,waterlogged=false])
B(3,7,1,minecraft:lava)
B(3,8,1,minecraft:lava)
B(3,9,1,minecraft:lava)
B(3,20,1,minecraft:stone_brick_stairs[facing=north,half=top,shape=straight,waterlogged=false])
B(3,7,2,minecraft:lava)
B(3,8,2,minecraft:lava)
B(3,9,2,minecraft:lava)
B(3,17,2,minecraft:stone_brick_stairs[facing=south,half=bottom,shape=straight,waterlogged=false])
B(3,18,3,minecraft:stone_brick_stairs[facing=south,half=bottom,shape=straight,waterlogged=false])
B(3,24,3,minecraft:stone_brick_stairs[facing=east,half=top,shape=straight,waterlogged=false])
B(3,8,4,minecraft:lava)
B(3,9,4,minecraft:lava)
B(3,10,4,minecraft:lava)
B(3,19,4,minecraft:stone_brick_stairs[facing=south,half=bottom,shape=straight,waterlogged=false])
B(3,20,5,minecraft:stone_slab)
B(3,24,5,minecraft:stone_brick_stairs[facing=east,half=top,shape=straight,waterlogged=false])
B(3,13,6,minecraft:water)
B(3,14,6,minecraft:water)
B(3,21,6,minecraft:stone_brick_stairs[facing=south,half=bottom,shape=outer_right,waterlogged=false])
B(3,13,7,minecraft:water)
B(3,14,7,minecraft:water)
B(3,21,7,minecraft:stone_brick_stairs[facing=west,half=bottom,shape=straight,waterlogged=false])
B(3,24,7,minecraft:stone_brick_stairs[facing=east,half=top,shape=straight,waterlogged=false])
B(4,27,0,minecraft:stone)
B(4,28,0,minecraft:stone)
B(4,29,0,minecraft:stone)
B(4,27,1,minecraft:stone)
B(4,28,1,minecraft:stone)
B(4,29,1,minecraft:stone)
B(4,27,2,minecraft:stone)
B(4,28,2,minecraft:stone)
B(4,29,2,minecraft:stone)
B(4,16,3,minecraft:stone_brick_stairs)
B(4,15,4,minecraft:stone_brick_stairs)
B(4,15,5,minecraft:stone_slab)
B(4,18,5,minecraft:stone_brick_stairs[facing=west,half=top,shape=straight,waterlogged=false])
B(4,13,6,minecraft:water)
B(4,14,6,minecraft:water)
B(4,13,7,minecraft:water)
B(4,14,7,minecraft:water)
B(4,17,7,minecraft:stone_brick_stairs[facing=west,half=top,shape=straight,waterlogged=false])
B(5,18,0,minecraft:stone_brick_stairs[facing=west,half=top,shape=straight,waterlogged=false])
B(5,27,0,minecraft:stone)
B(5,28,0,minecraft:stone)
B(5,23,1,minecraft:stone_brick_stairs[facing=west,half=top,shape=straight,waterlogged=false])
B(5,27,1,minecraft:stone)
B(5,28,1,minecraft:stone)
B(5,29,1,minecraft:stone)
B(5,27,2,minecraft:stone)
B(5,28,2,minecraft:stone)
B(5,29,2,minecraft:stone)
B(5,23,3,minecraft:stone_brick_stairs[facing=west,half=top,shape=straight,waterlogged=false])
B(5,27,3,minecraft:stone)
B(5,28,3,minecraft:stone)
B(5,29,3,minecraft:stone)
B(5,27,4,minecraft:stone)
B(5,28,4,minecraft:stone)
B(5,29,4,minecraft:stone)
B(5,15,5,minecraft:stone_slab)
B(5,23,5,minecraft:stone_brick_stairs[facing=west,half=top,shape=straight,waterlogged=false])
B(5,27,5,minecraft:stone)
B(5,28,5,minecraft:stone)
B(5,29,5,minecraft:stone)
B(5,13,6,minecraft:water)
B(5,14,6,minecraft:water)
B(5,27,6,minecraft:stone)
B(5,28,6,minecraft:stone)
B(5,29,6,minecraft:stone)
B(5,13,7,minecraft:water)
B(5,14,7,minecraft:water)
B(5,23,7,minecraft:stone_brick_stairs[facing=west,half=top,shape=straight,waterlogged=false])
B(5,27,7,minecraft:stone)
B(5,28,7,minecraft:stone)
B(5,29,7,minecraft:stone)
B(6,18,0,minecraft:stone_brick_stairs[facing=east,half=top,shape=straight,waterlogged=false])
B(6,27,0,minecraft:stone)
B(6,28,0,minecraft:stone)
B(6,23,1,minecraft:stone_brick_stairs[facing=east,half=top,shape=straight,waterlogged=false])
B(6,27,1,minecraft:stone)
B(6,28,1,minecraft:stone)
B(6,27,2,minecraft:stone)
B(6,28,2,minecraft:stone)
B(6,23,3,minecraft:stone_brick_stairs[facing=east,half=top,shape=straight,waterlogged=false])
B(6,27,3,minecraft:stone)
B(6,28,3,minecraft:stone)
B(6,27,4,minecraft:stone)
B(6,28,4,minecraft:stone)
B(6,15,5,minecraft:stone_slab)
B(6,18,5,minecraft:stone_brick_stairs[facing=east,half=top,shape=straight,waterlogged=false])
B(6,23,5,minecraft:stone_brick_stairs[facing=east,half=top,shape=straight,waterlogged=false])
B(6,27,5,minecraft:stone)
B(6,28,5,minecraft:stone)
B(6,13,6,minecraft:water)
B(6,14,6,minecraft:water)
B(6,27,6,minecraft:stone)
B(6,28,6,minecraft:stone)
B(6,13,7,minecraft:water)
B(6,14,7,minecraft:water)
B(6,17,7,minecraft:stone_brick_stairs[facing=east,half=top,shape=straight,waterlogged=false])
B(6,23,7,minecraft:stone_brick_stairs[facing=east,half=top,shape=straight,waterlogged=false])
B(6,27,7,minecraft:stone)
B(6,28,7,minecraft:stone)
B(7,27,0,minecraft:stone)
B(7,27,1,minecraft:stone)
B(7,27,2,minecraft:stone)
B(7,27,3,minecraft:stone)
B(7,27,4,minecraft:stone)
B(7,27,5,minecraft:stone)
B(7,27,6,minecraft:stone)
B(7,27,7,minecraft:stone)
RB(0,0,0,minecraft:mossy_stone_bricks,10,minecraft:cracked_stone_bricks,10,minecraft:cobblestone,10,minecraft:mossy_cobblestone,10,minecraft:stone_bricks,100)
RB(1,0,0,minecraft:mossy_stone_bricks,10,minecraft:cracked_stone_bricks,10,minecraft:cobblestone,10,minecraft:mossy_cobblestone,10,minecraft:stone_bricks,100)
RB(2,0,0,minecraft:mossy_stone_bricks,10,minecraft:cracked_stone_bricks,10,minecraft:cobblestone,10,minecraft:mossy_cobblestone,10,minecraft:stone_bricks,100)
RB(3,0,0,minecraft:mossy_stone_bricks,10,minecraft:cracked_stone_bricks,10,minecraft:cobblestone,10,minecraft:mossy_cobblestone,10,minecraft:stone_bricks,100)
RB(4,0,0,minecraft:mossy_stone_bricks,10,minecraft:cracked_stone_bricks,10,minecraft:cobblestone,10,minecraft:mossy_cobblestone,10,minecraft:stone_bricks,100)
RB(5,0,0,minecraft:mossy_stone_bricks,10,minecraft:cracked_stone_bricks,10,minecraft:cobblestone,10,minecraft:mossy_cobblestone,10,minecraft:stone_bricks,100)
RB(6,0,0,minecraft:mossy_stone_bricks,10,minecraft:cracked_stone_bricks,10,minecraft:cobblestone,10,minecraft:mossy_cobblestone,10,minecraft:stone_bricks,100)
RB(7,0,0,minecraft:mossy_stone_bricks,10,minecraft:cracked_stone_bricks,10,minecraft:cobblestone,10,minecraft:mossy_cobblestone,10,minecraft:stone_bricks,100)
RB(0,0,1,minecraft:mossy_stone_bricks,10,minecraft:cracked_stone_bricks,10,minecraft:cobblestone,10,minecraft:mossy_cobblestone,10,minecraft:stone_bricks,100)
RB(1,0,1,minecraft:mossy_stone_bricks,10,minecraft:cracked_stone_bricks,10,minecraft:cobblestone,10,minecraft:mossy_cobblestone,10,minecraft:stone_bricks,100)
RB(2,0,1,minecraft:mossy_stone_bricks,10,minecraft:cracked_stone_bricks,10,minecraft:cobblestone,10,minecraft:mossy_cobblestone,10,minecraft:stone_bricks,100)
RB(3,0,1,minecraft:mossy_stone_bricks,10,minecraft:cracked_stone_bricks,10,minecraft:cobblestone,10,minecraft:mossy_cobblestone,10,minecraft:stone_bricks,100)
RB(4,0,1,minecraft:mossy_stone_bricks,10,minecraft:cracked_stone_bricks,10,minecraft:cobblestone,10,minecraft:mossy_cobblestone,10,minecraft:stone_bricks,100)
RB(5,0,1,minecraft:mossy_stone_bricks,10,minecraft:cracked_stone_bricks,10,minecraft:cobblestone,10,minecraft:mossy_cobblestone,10,minecraft:stone_bricks,100)
RB(6,0,1,minecraft:mossy_stone_bricks,10,minecraft:cracked_stone_bricks,10,minecraft:cobblestone,10,minecraft:mossy_cobblestone,10,minecraft:stone_bricks,100)
RB(7,0,1,minecraft:mossy_stone_bricks,10,minecraft:cracked_stone_bricks,10,minecraft:cobblestone,10,minecraft:mossy_cobblestone,10,minecraft:stone_bricks,100)
RB(0,0,2,minecraft:mossy_stone_bricks,10,minecraft:cracked_stone_bricks,10,minecraft:cobblestone,10,minecraft:mossy_cobblestone,10,minecraft:stone_bricks,100)
RB(1,0,2,minecraft:mossy_stone_bricks,10,minecraft:cracked_stone_bricks,10,minecraft:cobblestone,10,minecraft:mossy_cobblestone,10,minecraft:stone_bricks,100)
RB(2,0,2,minecraft:mossy_stone_bricks,10,minecraft:cracked_stone_bricks,10,minecraft:cobblestone,10,minecraft:mossy_cobblestone,10,minecraft:stone_bricks,100)
RB(3,0,2,minecraft:mossy_stone_bricks,10,minecraft:cracked_stone_bricks,10,minecraft:cobblestone,10,minecraft:mossy_cobblestone,10,minecraft:stone_bricks,100)
RB(4,0,2,minecraft:mossy_stone_bricks,10,minecraft:cracked_stone_bricks,10,minecraft:cobblestone,10,minecraft:mossy_cobblestone,10,minecraft:stone_bricks,100)
RB(6,0,2,minecraft:mossy_stone_bricks,10,minecraft:cracked_stone_bricks,10,minecraft:cobblestone,10,minecraft:mossy_cobblestone,10,minecraft:stone_bricks,100)
RB(7,0,2,minecraft:mossy_stone_bricks,10,minecraft:cracked_stone_bricks,10,minecraft:cobblestone,10,minecraft:mossy_cobblestone,10,minecraft:stone_bricks,100)
RB(0,0,3,minecraft:mossy_stone_bricks,10,minecraft:cracked_stone_bricks,10,minecraft:cobblestone,10,minecraft:mossy_cobblestone,10,minecraft:stone_bricks,100)
RB(1,0,3,minecraft:mossy_stone_bricks,10,minecraft:cracked_stone_bricks,10,minecraft:cobblestone,10,minecraft:mossy_cobblestone,10,minecraft:stone_bricks,100)
RB(2,0,3,minecraft:mossy_stone_bricks,10,minecraft:cracked_stone_bricks,10,minecraft:cobblestone,10,minecraft:mossy_cobblestone,10,minecraft:stone_bricks,100)
RB(3,0,3,minecraft:mossy_stone_bricks,10,minecraft:cracked_stone_bricks,10,minecraft:cobblestone,10,minecraft:mossy_cobblestone,10,minecraft:stone_bricks,100)
RB(4,0,3,minecraft:mossy_stone_bricks,10,minecraft:cracked_stone_bricks,10,minecraft:cobblestone,10,minecraft:mossy_cobblestone,10,minecraft:stone_bricks,100)
RB(5,0,3,minecraft:mossy_stone_bricks,10,minecraft:cracked_stone_bricks,10,minecraft:cobblestone,10,minecraft:mossy_cobblestone,10,minecraft:stone_bricks,100)
RB(6,0,3,minecraft:mossy_stone_bricks,10,minecraft:cracked_stone_bricks,10,minecraft:cobblestone,10,minecraft:mossy_cobblestone,10,minecraft:stone_bricks,100)
RB(7,0,3,minecraft:mossy_stone_bricks,10,minecraft:cracked_stone_bricks,10,minecraft:cobblestone,10,minecraft:mossy_cobblestone,10,minecraft:stone_bricks,100)
RB(0,0,4,minecraft:mossy_stone_bricks,10,minecraft:cracked_stone_bricks,10,minecraft:cobblestone,10,minecraft:mossy_cobblestone,10,minecraft:stone_bricks,100)
RB(1,0,4,minecraft:mossy_stone_bricks,10,minecraft:cracked_stone_bricks,10,minecraft:cobblestone,10,minecraft:mossy_cobblestone,10,minecraft:stone_bricks,100)
RB(2,0,4,minecraft:mossy_stone_bricks,10,minecraft:cracked_stone_bricks,10,minecraft:cobblestone,10,minecraft:mossy_cobblestone,10,minecraft:stone_bricks,100)
RB(3,0,4,minecraft:mossy_stone_bricks,10,minecraft:cracked_stone_bricks,10,minecraft:cobblestone,10,minecraft:mossy_cobblestone,10,minecraft:stone_bricks,100)
RB(4,0,4,minecraft:mossy_stone_bricks,10,minecraft:cracked_stone_bricks,10,minecraft:cobblestone,10,minecraft:mossy_cobblestone,10,minecraft:stone_bricks,100)
RB(5,0,4,minecraft:mossy_stone_bricks,10,minecraft:cracked_stone_bricks,10,minecraft:cobblestone,10,minecraft:mossy_cobblestone,10,minecraft:stone_bricks,100)
RB(6,0,4,minecraft:mossy_stone_bricks,10,minecraft:cracked_stone_bricks,10,minecraft:cobblestone,10,minecraft:mossy_cobblestone,10,minecraft:stone_bricks,100)
RB(7,0,4,minecraft:mossy_stone_bricks,10,minecraft:cracked_stone_bricks,10,minecraft:cobblestone,10,minecraft:mossy_cobblestone,10,minecraft:stone_bricks,100)
RB(0,0,5,minecraft:mossy_stone_bricks,10,minecraft:cracked_stone_bricks,10,minecraft:cobblestone,10,minecraft:mossy_cobblestone,10,minecraft:stone_bricks,100)
RB(1,0,5,minecraft:mossy_stone_bricks,10,minecraft:cracked_stone_bricks,10,minecraft:cobblestone,10,minecraft:mossy_cobblestone,10,minecraft:stone_bricks,100)
RB(2,0,5,minecraft:mossy_stone_bricks,10,minecraft:cracked_stone_bricks,10,minecraft:cobblestone,10,minecraft:mossy_cobblestone,10,minecraft:stone_bricks,100)
RB(3,0,5,minecraft:mossy_stone_bricks,10,minecraft:cracked_stone_bricks,10,minecraft:cobblestone,10,minecraft:mossy_cobblestone,10,minecraft:stone_bricks,100)
RB(4,0,5,minecraft:mossy_stone_bricks,10,minecraft:cracked_stone_bricks,10,minecraft:cobblestone,10,minecraft:mossy_cobblestone,10,minecraft:stone_bricks,100)
RB(5,0,5,minecraft:mossy_stone_bricks,10,minecraft:cracked_stone_bricks,10,minecraft:cobblestone,10,minecraft:mossy_cobblestone,10,minecraft:stone_bricks,100)
RB(6,0,5,minecraft:mossy_stone_bricks,10,minecraft:cracked_stone_bricks,10,minecraft:cobblestone,10,minecraft:mossy_cobblestone,10,minecraft:stone_bricks,100)
RB(7,0,5,minecraft:mossy_stone_bricks,10,minecraft:cracked_stone_bricks,10,minecraft:cobblestone,10,minecraft:mossy_cobblestone,10,minecraft:stone_bricks,100)
RB(0,0,6,minecraft:mossy_stone_bricks,10,minecraft:cracked_stone_bricks,10,minecraft:cobblestone,10,minecraft:mossy_cobblestone,10,minecraft:stone_bricks,100)
RB(1,0,6,minecraft:mossy_stone_bricks,10,minecraft:cracked_stone_bricks,10,minecraft:cobblestone,10,minecraft:mossy_cobblestone,10,minecraft:stone_bricks,100)
RB(2,0,6,minecraft:mossy_stone_bricks,10,minecraft:cracked_stone_bricks,10,minecraft:cobblestone,10,minecraft:mossy_cobblestone,10,minecraft:stone_bricks,100)
RB(3,0,6,minecraft:mossy_stone_bricks,10,minecraft:cracked_stone_bricks,10,minecraft:cobblestone,10,minecraft:mossy_cobblestone,10,minecraft:stone_bricks,100)
RB(4,0,6,minecraft:mossy_stone_bricks,10,minecraft:cracked_stone_bricks,10,minecraft:cobblestone,10,minecraft:mossy_cobblestone,10,minecraft:stone_bricks,100)
RB(5,0,6,minecraft:mossy_stone_bricks,10,minecraft:cracked_stone_bricks,10,minecraft:cobblestone,10,minecraft:mossy_cobblestone,10,minecraft:stone_bricks,100)
RB(6,0,6,minecraft:mossy_stone_bricks,10,minecraft:cracked_stone_bricks,10,minecraft:cobblestone,10,minecraft:mossy_cobblestone,10,minecraft:stone_bricks,100)
RB(7,0,6,minecraft:mossy_stone_bricks,10,minecraft:cracked_stone_bricks,10,minecraft:cobblestone,10,minecraft:mossy_cobblestone,10,minecraft:stone_bricks,100)
RB(0,0,7,minecraft:mossy_stone_bricks,10,minecraft:cracked_stone_bricks,10,minecraft:cobblestone,10,minecraft:mossy_cobblestone,10,minecraft:stone_bricks,100)
RB(1,0,7,minecraft:mossy_stone_bricks,10,minecraft:cracked_stone_bricks,10,minecraft:cobblestone,10,minecraft:mossy_cobblestone,10,minecraft:stone_bricks,100)
RB(2,0,7,minecraft:mossy_stone_bricks,10,minecraft:cracked_stone_bricks,10,minecraft:cobblestone,10,minecraft:mossy_cobblestone,10,minecraft:stone_bricks,100)
RB(3,0,7,minecraft:mossy_stone_bricks,10,minecraft:cracked_stone_bricks,10,minecraft:cobblestone,10,minecraft:mossy_cobblestone,10,minecraft:stone_bricks,100)
RB(4,0,7,minecraft:mossy_stone_bricks,10,minecraft:cracked_stone_bricks,10,minecraft:cobblestone,10,minecraft:mossy_cobblestone,10,minecraft:stone_bricks,100)
RB(5,0,7,minecraft:mossy_stone_bricks,10,minecraft:cracked_stone_bricks,10,minecraft:cobblestone,10,minecraft:mossy_cobblestone,10,minecraft:stone_bricks,100)
RB(6,0,7,minecraft:mossy_stone_bricks,10,minecraft:cracked_stone_bricks,10,minecraft:cobblestone,10,minecraft:mossy_cobblestone,10,minecraft:stone_bricks,100)
RB(7,0,7,minecraft:mossy_stone_bricks,10,minecraft:cracked_stone_bricks,10,minecraft:cobblestone,10,minecraft:mossy_cobblestone,10,minecraft:stone_bricks,100)
RB(0,1,0,minecraft:mossy_stone_bricks,10,minecraft:cracked_stone_bricks,10,minecraft:cobblestone,10,minecraft:mossy_cobblestone,10,minecraft:stone_bricks,100)
RB(1,1,0,minecraft:mossy_stone_bricks,10,minecraft:cracked_stone_bricks,10,minecraft:cobblestone,10,minecraft:mossy_cobblestone,10,minecraft:stone_bricks,100)
RB(2,1,0,minecraft:mossy_stone_bricks,10,minecraft:cracked_stone_bricks,10,minecraft:cobblestone,10,minecraft:mossy_cobblestone,10,minecraft:stone_bricks,100)
RB(3,1,0,minecraft:mossy_stone_bricks,10,minecraft:cracked_stone_bricks,10,minecraft:cobblestone,10,minecraft:mossy_cobblestone,10,minecraft:stone_bricks,100)
RB(4,1,0,minecraft:mossy_stone_bricks,10,minecraft:cracked_stone_bricks,10,minecraft:cobblestone,10,minecraft:mossy_cobblestone,10,minecraft:stone_bricks,100)
RB(5,1,0,minecraft:mossy_stone_bricks,10,minecraft:cracked_stone_bricks,10,minecraft:cobblestone,10,minecraft:mossy_cobblestone,10,minecraft:stone_bricks,100)
RB(6,1,0,minecraft:mossy_stone_bricks,10,minecraft:cracked_stone_bricks,10,minecraft:cobblestone,10,minecraft:mossy_cobblestone,10,minecraft:stone_bricks,100)
RB(7,1,0,minecraft:mossy_stone_bricks,10,minecraft:cracked_stone_bricks,10,minecraft:cobblestone,10,minecraft:mossy_cobblestone,10,minecraft:stone_bricks,100)
RB(0,1,1,minecraft:mossy_stone_bricks,10,minecraft:cracked_stone_bricks,10,minecraft:cobblestone,10,minecraft:mossy_cobblestone,10,minecraft:stone_bricks,100)
RB(1,1,1,minecraft:mossy_stone_bricks,10,minecraft:cracked_stone_bricks,10,minecraft:cobblestone,10,minecraft:mossy_cobblestone,10,minecraft:stone_bricks,100)
RB(2,1,1,minecraft:mossy_stone_bricks,10,minecraft:cracked_stone_bricks,10,minecraft:cobblestone,10,minecraft:mossy_cobblestone,10,minecraft:stone_bricks,100)
RB(3,1,1,minecraft:mossy_stone_bricks,10,minecraft:cracked_stone_bricks,10,minecraft:cobblestone,10,minecraft:mossy_cobblestone,10,minecraft:stone_bricks,100)
RB(4,1,1,minecraft:mossy_stone_bricks,10,minecraft:cracked_stone_bricks,10,minecraft:cobblestone,10,minecraft:mossy_cobblestone,10,minecraft:stone_bricks,100)
RB(6,1,1,minecraft:mossy_stone_bricks,10,minecraft:cracked_stone_bricks,10,minecraft:cobblestone,10,minecraft:mossy_cobblestone,10,minecraft:stone_bricks,100)
RB(7,1,1,minecraft:mossy_stone_bricks,10,minecraft:cracked_stone_bricks,10,minecraft:cobblestone,10,minecraft:mossy_cobblestone,10,minecraft:stone_bricks,100)
RB(0,1,2,minecraft:mossy_stone_bricks,10,minecraft:cracked_stone_bricks,10,minecraft:cobblestone,10,minecraft:mossy_cobblestone,10,minecraft:stone_bricks,100)
RB(1,1,2,minecraft:mossy_stone_bricks,10,minecraft:cracked_stone_bricks,10,minecraft:cobblestone,10,minecraft:mossy_cobblestone,10,minecraft:stone_bricks,100)
RB(2,1,2,minecraft:mossy_stone_bricks,10,minecraft:cracked_stone_bricks,10,minecraft:cobblestone,10,minecraft:mossy_cobblestone,10,minecraft:stone_bricks,100)
RB(3,1,2,minecraft:mossy_stone_bricks,10,minecraft:cracked_stone_bricks,10,minecraft:cobblestone,10,minecraft:mossy_cobblestone,10,minecraft:stone_bricks,100)
RB(5,1,2,minecraft:mossy_stone_bricks,10,minecraft:cracked_stone_bricks,10,minecraft:cobblestone,10,minecraft:mossy_cobblestone,10,minecraft:stone_bricks,100)
RB(7,1,2,minecraft:mossy_stone_bricks,10,minecraft:cracked_stone_bricks,10,minecraft:cobblestone,10,minecraft:mossy_cobblestone,10,minecraft:stone_bricks,100)
RB(0,1,3,minecraft:mossy_stone_bricks,10,minecraft:cracked_stone_bricks,10,minecraft:cobblestone,10,minecraft:mossy_cobblestone,10,minecraft:stone_bricks,100)
RB(1,1,3,minecraft:mossy_stone_bricks,10,minecraft:cracked_stone_bricks,10,minecraft:cobblestone,10,minecraft:mossy_cobblestone,10,minecraft:stone_bricks,100)
RB(2,1,3,minecraft:mossy_stone_bricks,10,minecraft:cracked_stone_bricks,10,minecraft:cobblestone,10,minecraft:mossy_cobblestone,10,minecraft:stone_bricks,100)
RB(3,1,3,minecraft:mossy_stone_bricks,10,minecraft:cracked_stone_bricks,10,minecraft:cobblestone,10,minecraft:mossy_cobblestone,10,minecraft:stone_bricks,100)
RB(4,1,3,minecraft:mossy_stone_bricks,10,minecraft:cracked_stone_bricks,10,minecraft:cobblestone,10,minecraft:mossy_cobblestone,10,minecraft:stone_bricks,100)
RB(6,1,3,minecraft:mossy_stone_bricks,10,minecraft:cracked_stone_bricks,10,minecraft:cobblestone,10,minecraft:mossy_cobblestone,10,minecraft:stone_bricks,100)
RB(7,1,3,minecraft:mossy_stone_bricks,10,minecraft:cracked_stone_bricks,10,minecraft:cobblestone,10,minecraft:mossy_cobblestone,10,minecraft:stone_bricks,100)
RB(0,1,4,minecraft:mossy_stone_bricks,10,minecraft:cracked_stone_bricks,10,minecraft:cobblestone,10,minecraft:mossy_cobblestone,10,minecraft:stone_bricks,100)
RB(1,1,4,minecraft:mossy_stone_bricks,10,minecraft:cracked_stone_bricks,10,minecraft:cobblestone,10,minecraft:mossy_cobblestone,10,minecraft:stone_bricks,100)
RB(2,1,4,minecraft:mossy_stone_bricks,10,minecraft:cracked_stone_bricks,10,minecraft:cobblestone,10,minecraft:mossy_cobblestone,10,minecraft:stone_bricks,100)
RB(3,1,4,minecraft:mossy_stone_bricks,10,minecraft:cracked_stone_bricks,10,minecraft:cobblestone,10,minecraft:mossy_cobblestone,10,minecraft:stone_bricks,100)
RB(4,1,4,minecraft:mossy_stone_bricks,10,minecraft:cracked_stone_bricks,10,minecraft:cobblestone,10,minecraft:mossy_cobblestone,10,minecraft:stone_bricks,100)
RB(5,1,4,minecraft:mossy_stone_bricks,10,minecraft:cracked_stone_bricks,10,minecraft:cobblestone,10,minecraft:mossy_cobblestone,10,minecraft:stone_bricks,100)
RB(6,1,4,minecraft:mossy_stone_bricks,10,minecraft:cracked_stone_bricks,10,minecraft:cobblestone,10,minecraft:mossy_cobblestone,10,minecraft:stone_bricks,100)
RB(7,1,4,minecraft:mossy_stone_bricks,10,minecraft:cracked_stone_bricks,10,minecraft:cobblestone,10,minecraft:mossy_cobblestone,10,minecraft:stone_bricks,100)
RB(0,1,5,minecraft:mossy_stone_bricks,10,minecraft:cracked_stone_bricks,10,minecraft:cobblestone,10,minecraft:mossy_cobblestone,10,minecraft:stone_bricks,100)
RB(1,1,5,minecraft:mossy_stone_bricks,10,minecraft:cracked_stone_bricks,10,minecraft:cobblestone,10,minecraft:mossy_cobblestone,10,minecraft:stone_bricks,100)
RB(2,1,5,minecraft:mossy_stone_bricks,10,minecraft:cracked_stone_bricks,10,minecraft:cobblestone,10,minecraft:mossy_cobblestone,10,minecraft:stone_bricks,100)
RB(3,1,5,minecraft:mossy_stone_bricks,10,minecraft:cracked_stone_bricks,10,minecraft:cobblestone,10,minecraft:mossy_cobblestone,10,minecraft:stone_bricks,100)
RB(4,1,5,minecraft:mossy_stone_bricks,10,minecraft:cracked_stone_bricks,10,minecraft:cobblestone,10,minecraft:mossy_cobblestone,10,minecraft:stone_bricks,100)
RB(5,1,5,minecraft:mossy_stone_bricks,10,minecraft:cracked_stone_bricks,10,minecraft:cobblestone,10,minecraft:mossy_cobblestone,10,minecraft:stone_bricks,100)
RB(6,1,5,minecraft:mossy_stone_bricks,10,minecraft:cracked_stone_bricks,10,minecraft:cobblestone,10,minecraft:mossy_cobblestone,10,minecraft:stone_bricks,100)
RB(7,1,5,minecraft:mossy_stone_bricks,10,minecraft:cracked_stone_bricks,10,minecraft:cobblestone,10,minecraft:mossy_cobblestone,10,minecraft:stone_bricks,100)
RB(0,1,6,minecraft:mossy_stone_bricks,10,minecraft:cracked_stone_bricks,10,minecraft:cobblestone,10,minecraft:mossy_cobblestone,10,minecraft:stone_bricks,100)
RB(1,1,6,minecraft:mossy_stone_bricks,10,minecraft:cracked_stone_bricks,10,minecraft:cobblestone,10,minecraft:mossy_cobblestone,10,minecraft:stone_bricks,100)
RB(2,1,6,minecraft:mossy_stone_bricks,10,minecraft:cracked_stone_bricks,10,minecraft:cobblestone,10,minecraft:mossy_cobblestone,10,minecraft:stone_bricks,100)
RB(3,1,6,minecraft:mossy_stone_bricks,10,minecraft:cracked_stone_bricks,10,minecraft:cobblestone,10,minecraft:mossy_cobblestone,10,minecraft:stone_bricks,100)
RB(4,1,6,minecraft:mossy_stone_bricks,10,minecraft:cracked_stone_bricks,10,minecraft:cobblestone,10,minecraft:mossy_cobblestone,10,minecraft:stone_bricks,100)
RB(5,1,6,minecraft:mossy_stone_bricks,10,minecraft:cracked_stone_bricks,10,minecraft:cobblestone,10,minecraft:mossy_cobblestone,10,minecraft:stone_bricks,100)
RB(6,1,6,minecraft:mossy_stone_bricks,10,minecraft:cracked_stone_bricks,10,minecraft:cobblestone,10,minecraft:mossy_cobblestone,10,minecraft:stone_bricks,100)
RB(7,1,6,minecraft:mossy_stone_bricks,10,minecraft:cracked_stone_bricks,10,minecraft:cobblestone,10,minecraft:mossy_cobblestone,10,minecraft:stone_bricks,100)
RB(0,1,7,minecraft:mossy_stone_bricks,10,minecraft:cracked_stone_bricks,10,minecraft:cobblestone,10,minecraft:mossy_cobblestone,10,minecraft:stone_bricks,100)
RB(1,1,7,minecraft:mossy_stone_bricks,10,minecraft:cracked_stone_bricks,10,minecraft:cobblestone,10,minecraft:mossy_cobblestone,10,minecraft:stone_bricks,100)
RB(2,1,7,minecraft:mossy_stone_bricks,10,minecraft:cracked_stone_bricks,10,minecraft:cobblestone,10,minecraft:mossy_cobblestone,10,minecraft:stone_bricks,100)
RB(3,1,7,minecraft:mossy_stone_bricks,10,minecraft:cracked_stone_bricks,10,minecraft:cobblestone,10,minecraft:mossy_cobblestone,10,minecraft:stone_bricks,100)
RB(4,1,7,minecraft:mossy_stone_bricks,10,minecraft:cracked_stone_bricks,10,minecraft:cobblestone,10,minecraft:mossy_cobblestone,10,minecraft:stone_bricks,100)
RB(5,1,7,minecraft:mossy_stone_bricks,10,minecraft:cracked_stone_bricks,10,minecraft:cobblestone,10,minecraft:mossy_cobblestone,10,minecraft:stone_bricks,100)
RB(6,1,7,minecraft:mossy_stone_bricks,10,minecraft:cracked_stone_bricks,10,minecraft:cobblestone,10,minecraft:mossy_cobblestone,10,minecraft:stone_bricks,100)
RB(7,1,7,minecraft:mossy_stone_bricks,10,minecraft:cracked_stone_bricks,10,minecraft:cobblestone,10,minecraft:mossy_cobblestone,10,minecraft:stone_bricks,100)
RB(0,2,0,minecraft:mossy_stone_bricks,10,minecraft:cracked_stone_bricks,10,minecraft:cobblestone,10,minecraft:mossy_cobblestone,10,minecraft:stone_bricks,100)
RB(1,2,0,minecraft:mossy_stone_bricks,10,minecraft:cracked_stone_bricks,10,minecraft:cobblestone,10,minecraft:mossy_cobblestone,10,minecraft:stone_bricks,100)
RB(2,2,0,minecraft:mossy_stone_bricks,10,minecraft:cracked_stone_bricks,10,minecraft:cobblestone,10,minecraft:mossy_cobblestone,10,minecraft:stone_bricks,100)
RB(3,2,0,minecraft:mossy_stone_bricks,10,minecraft:cracked_stone_bricks,10,minecraft:cobblestone,10,minecraft:mossy_cobblestone,10,minecraft:stone_bricks,100)
RB(4,2,0,minecraft:mossy_stone_bricks,10,minecraft:cracked_stone_bricks,10,minecraft:cobblestone,10,minecraft:mossy_cobblestone,10,minecraft:stone_bricks,100)
RB(5,2,0,minecraft:mossy_stone_bricks,10,minecraft:cracked_stone_bricks,10,minecraft:cobblestone,10,minecraft:mossy_cobblestone,10,minecraft:stone_bricks,100)
RB(6,2,0,minecraft:mossy_stone_bricks,10,minecraft:cracked_stone_bricks,10,minecraft:cobblestone,10,minecraft:mossy_cobblestone,10,minecraft:stone_bricks,100)
RB(7,2,0,minecraft:mossy_stone_bricks,10,minecraft:cracked_stone_bricks,10,minecraft:cobblestone,10,minecraft:mossy_cobblestone,10,minecraft:stone_bricks,100)
RB(0,2,1,minecraft:mossy_stone_bricks,10,minecraft:cracked_stone_bricks,10,minecraft:cobblestone,10,minecraft:mossy_cobblestone,10,minecraft:stone_bricks,100)
RB(1,2,1,minecraft:mossy_stone_bricks,10,minecraft:cracked_stone_bricks,10,minecraft:cobblestone,10,minecraft:mossy_cobblestone,10,minecraft:stone_bricks,100)
RB(2,2,1,minecraft:mossy_stone_bricks,10,minecraft:cracked_stone_bricks,10,minecraft:cobblestone,10,minecraft:mossy_cobblestone,10,minecraft:stone_bricks,100)
RB(3,2,1,minecraft:mossy_stone_bricks,10,minecraft:cracked_stone_bricks,10,minecraft:cobblestone,10,minecraft:mossy_cobblestone,10,minecraft:stone_bricks,100)
RB(4,2,1,minecraft:mossy_stone_bricks,10,minecraft:cracked_stone_bricks,10,minecraft:cobblestone,10,minecraft:mossy_cobblestone,10,minecraft:stone_bricks,100)
RB(5,2,1,minecraft:mossy_stone_bricks,10,minecraft:cracked_stone_bricks,10,minecraft:cobblestone,10,minecraft:mossy_cobblestone,10,minecraft:stone_bricks,100)
RB(6,2,1,minecraft:mossy_stone_bricks,10,minecraft:cracked_stone_bricks,10,minecraft:cobblestone,10,minecraft:mossy_cobblestone,10,minecraft:stone_bricks,100)
RB(7,2,1,minecraft:mossy_stone_bricks,10,minecraft:cracked_stone_bricks,10,minecraft:cobblestone,10,minecraft:mossy_cobblestone,10,minecraft:stone_bricks,100)
RB(0,2,2,minecraft:mossy_stone_bricks,10,minecraft:cracked_stone_bricks,10,minecraft:cobblestone,10,minecraft:mossy_cobblestone,10,minecraft:stone_bricks,100)
RB(1,2,2,minecraft:mossy_stone_bricks,10,minecraft:cracked_stone_bricks,10,minecraft:cobblestone,10,minecraft:mossy_cobblestone,10,minecraft:stone_bricks,100)
RB(2,2,2,minecraft:mossy_stone_bricks,10,minecraft:cracked_stone_bricks,10,minecraft:cobblestone,10,minecraft:mossy_cobblestone,10,minecraft:stone_bricks,100)
RB(3,2,2,minecraft:mossy_stone_bricks,10,minecraft:cracked_stone_bricks,10,minecraft:cobblestone,10,minecraft:mossy_cobblestone,10,minecraft:stone_bricks,100)
RB(4,2,2,minecraft:mossy_stone_bricks,10,minecraft:cracked_stone_bricks,10,minecraft:cobblestone,10,minecraft:mossy_cobblestone,10,minecraft:stone_bricks,100)
RB(6,2,2,minecraft:mossy_stone_bricks,10,minecraft:cracked_stone_bricks,10,minecraft:cobblestone,10,minecraft:mossy_cobblestone,10,minecraft:stone_bricks,100)
RB(7,2,2,minecraft:mossy_stone_bricks,10,minecraft:cracked_stone_bricks,10,minecraft:cobblestone,10,minecraft:mossy_cobblestone,10,minecraft:stone_bricks,100)
RB(0,2,3,minecraft:mossy_stone_bricks,10,minecraft:cracked_stone_bricks,10,minecraft:cobblestone,10,minecraft:mossy_cobblestone,10,minecraft:stone_bricks,100)
RB(1,2,3,minecraft:mossy_stone_bricks,10,minecraft:cracked_stone_bricks,10,minecraft:cobblestone,10,minecraft:mossy_cobblestone,10,minecraft:stone_bricks,100)
RB(2,2,3,minecraft:mossy_stone_bricks,10,minecraft:cracked_stone_bricks,10,minecraft:cobblestone,10,minecraft:mossy_cobblestone,10,minecraft:stone_bricks,100)
RB(3,2,3,minecraft:mossy_stone_bricks,10,minecraft:cracked_stone_bricks,10,minecraft:cobblestone,10,minecraft:mossy_cobblestone,10,minecraft:stone_bricks,100)
RB(4,2,3,minecraft:mossy_stone_bricks,10,minecraft:cracked_stone_bricks,10,minecraft:cobblestone,10,minecraft:mossy_cobblestone,10,minecraft:stone_bricks,100)
RB(5,2,3,minecraft:mossy_stone_bricks,10,minecraft:cracked_stone_bricks,10,minecraft:cobblestone,10,minecraft:mossy_cobblestone,10,minecraft:stone_bricks,100)
RB(6,2,3,minecraft:mossy_stone_bricks,10,minecraft:cracked_stone_bricks,10,minecraft:cobblestone,10,minecraft:mossy_cobblestone,10,minecraft:stone_bricks,100)
RB(7,2,3,minecraft:mossy_stone_bricks,10,minecraft:cracked_stone_bricks,10,minecraft:cobblestone,10,minecraft:mossy_cobblestone,10,minecraft:stone_bricks,100)
RB(0,2,4,minecraft:mossy_stone_bricks,10,minecraft:cracked_stone_bricks,10,minecraft:cobblestone,10,minecraft:mossy_cobblestone,10,minecraft:stone_bricks,100)
RB(1,2,4,minecraft:mossy_stone_bricks,10,minecraft:cracked_stone_bricks,10,minecraft:cobblestone,10,minecraft:mossy_cobblestone,10,minecraft:stone_bricks,100)
RB(2,2,4,minecraft:mossy_stone_bricks,10,minecraft:cracked_stone_bricks,10,minecraft:cobblestone,10,minecraft:mossy_cobblestone,10,minecraft:stone_bricks,100)
RB(3,2,4,minecraft:mossy_stone_bricks,10,minecraft:cracked_stone_bricks,10,minecraft:cobblestone,10,minecraft:mossy_cobblestone,10,minecraft:stone_bricks,100)
RB(4,2,4,minecraft:mossy_stone_bricks,10,minecraft:cracked_stone_bricks,10,minecraft:cobblestone,10,minecraft:mossy_cobblestone,10,minecraft:stone_bricks,100)
RB(5,2,4,minecraft:mossy_stone_bricks,10,minecraft:cracked_stone_bricks,10,minecraft:cobblestone,10,minecraft:mossy_cobblestone,10,minecraft:stone_bricks,100)
RB(6,2,4,minecraft:mossy_stone_bricks,10,minecraft:cracked_stone_bricks,10,minecraft:cobblestone,10,minecraft:mossy_cobblestone,10,minecraft:stone_bricks,100)
RB(7,2,4,minecraft:mossy_stone_bricks,10,minecraft:cracked_stone_bricks,10,minecraft:cobblestone,10,minecraft:mossy_cobblestone,10,minecraft:stone_bricks,100)
RB(0,2,5,minecraft:mossy_stone_bricks,10,minecraft:cracked_stone_bricks,10,minecraft:cobblestone,10,minecraft:mossy_cobblestone,10,minecraft:stone_bricks,100)
RB(1,2,5,minecraft:mossy_stone_bricks,10,minecraft:cracked_stone_bricks,10,minecraft:cobblestone,10,minecraft:mossy_cobblestone,10,minecraft:stone_bricks,100)
RB(2,2,5,minecraft:mossy_stone_bricks,10,minecraft:cracked_stone_bricks,10,minecraft:cobblestone,10,minecraft:mossy_cobblestone,10,minecraft:stone_bricks,100)
RB(3,2,5,minecraft:mossy_stone_bricks,10,minecraft:cracked_stone_bricks,10,minecraft:cobblestone,10,minecraft:mossy_cobblestone,10,minecraft:stone_bricks,100)
RB(4,2,5,minecraft:mossy_stone_bricks,10,minecraft:cracked_stone_bricks,10,minecraft:cobblestone,10,minecraft:mossy_cobblestone,10,minecraft:stone_bricks,100)
RB(5,2,5,minecraft:mossy_stone_bricks,10,minecraft:cracked_stone_bricks,10,minecraft:cobblestone,10,minecraft:mossy_cobblestone,10,minecraft:stone_bricks,100)
RB(6,2,5,minecraft:mossy_stone_bricks,10,minecraft:cracked_stone_bricks,10,minecraft:cobblestone,10,minecraft:mossy_cobblestone,10,minecraft:stone_bricks,100)
RB(7,2,5,minecraft:mossy_stone_bricks,10,minecraft:cracked_stone_bricks,10,minecraft:cobblestone,10,minecraft:mossy_cobblestone,10,minecraft:stone_bricks,100)
RB(0,2,6,minecraft:mossy_stone_bricks,10,minecraft:cracked_stone_bricks,10,minecraft:cobblestone,10,minecraft:mossy_cobblestone,10,minecraft:stone_bricks,100)
RB(1,2,6,minecraft:mossy_stone_bricks,10,minecraft:cracked_stone_bricks,10,minecraft:cobblestone,10,minecraft:mossy_cobblestone,10,minecraft:stone_bricks,100)
RB(2,2,6,minecraft:mossy_stone_bricks,10,minecraft:cracked_stone_bricks,10,minecraft:cobblestone,10,minecraft:mossy_cobblestone,10,minecraft:stone_bricks,100)
RB(3,2,6,minecraft:mossy_stone_bricks,10,minecraft:cracked_stone_bricks,10,minecraft:cobblestone,10,minecraft:mossy_cobblestone,10,minecraft:stone_bricks,100)
RB(4,2,6,minecraft:mossy_stone_bricks,10,minecraft:cracked_stone_bricks,10,minecraft:cobblestone,10,minecraft:mossy_cobblestone,10,minecraft:stone_bricks,100)
RB(5,2,6,minecraft:mossy_stone_bricks,10,minecraft:cracked_stone_bricks,10,minecraft:cobblestone,10,minecraft:mossy_cobblestone,10,minecraft:stone_bricks,100)
RB(6,2,6,minecraft:mossy_stone_bricks,10,minecraft:cracked_stone_bricks,10,minecraft:cobblestone,10,minecraft:mossy_cobblestone,10,minecraft:stone_bricks,100)
RB(7,2,6,minecraft:mossy_stone_bricks,10,minecraft:cracked_stone_bricks,10,minecraft:cobblestone,10,minecraft:mossy_cobblestone,10,minecraft:stone_bricks,100)
RB(0,2,7,minecraft:mossy_stone_bricks,10,minecraft:cracked_stone_bricks,10,minecraft:cobblestone,10,minecraft:mossy_cobblestone,10,minecraft:stone_bricks,100)
RB(1,2,7,minecraft:mossy_stone_bricks,10,minecraft:cracked_stone_bricks,10,minecraft:cobblestone,10,minecraft:mossy_cobblestone,10,minecraft:stone_bricks,100)
RB(2,2,7,minecraft:mossy_stone_bricks,10,minecraft:cracked_stone_bricks,10,minecraft:cobblestone,10,minecraft:mossy_cobblestone,10,minecraft:stone_bricks,100)
RB(3,2,7,minecraft:mossy_stone_bricks,10,minecraft:cracked_stone_bricks,10,minecraft:cobblestone,10,minecraft:mossy_cobblestone,10,minecraft:stone_bricks,100)
RB(4,2,7,minecraft:mossy_stone_bricks,10,minecraft:cracked_stone_bricks,10,minecraft:cobblestone,10,minecraft:mossy_cobblestone,10,minecraft:stone_bricks,100)
RB(5,2,7,minecraft:mossy_stone_bricks,10,minecraft:cracked_stone_bricks,10,minecraft:cobblestone,10,minecraft:mossy_cobblestone,10,minecraft:stone_bricks,100)
RB(6,2,7,minecraft:mossy_stone_bricks,10,minecraft:cracked_stone_bricks,10,minecraft:cobblestone,10,minecraft:mossy_cobblestone,10,minecraft:stone_bricks,100)
RB(7,2,7,minecraft:mossy_stone_bricks,10,minecraft:cracked_stone_bricks,10,minecraft:cobblestone,10,minecraft:mossy_cobblestone,10,minecraft:stone_bricks,100)
RB(0,3,0,minecraft:mossy_stone_bricks,10,minecraft:cracked_stone_bricks,10,minecraft:cobblestone,10,minecraft:mossy_cobblestone,10,minecraft:stone_bricks,100)
RB(1,3,0,minecraft:mossy_stone_bricks,10,minecraft:cracked_stone_bricks,10,minecraft:cobblestone,10,minecraft:mossy_cobblestone,10,minecraft:stone_bricks,100)
RB(2,3,0,minecraft:mossy_stone_bricks,10,minecraft:cracked_stone_bricks,10,minecraft:cobblestone,10,minecraft:mossy_cobblestone,10,minecraft:stone_bricks,100)
RB(3,3,0,minecraft:mossy_stone_bricks,10,minecraft:cracked_stone_bricks,10,minecraft:cobblestone,10,minecraft:mossy_cobblestone,10,minecraft:stone_bricks,100)
RB(4,3,0,minecraft:mossy_stone_bricks,10,minecraft:cracked_stone_bricks,10,minecraft:cobblestone,10,minecraft:mossy_cobblestone,10,minecraft:stone_bricks,100)
RB(5,3,0,minecraft:mossy_stone_bricks,10,minecraft:cracked_stone_bricks,10,minecraft:cobblestone,10,minecraft:mossy_cobblestone,10,minecraft:stone_bricks,100)
RB(6,3,0,minecraft:mossy_stone_bricks,10,minecraft:cracked_stone_bricks,10,minecraft:cobblestone,10,minecraft:mossy_cobblestone,10,minecraft:stone_bricks,100)
RB(7,3,0,minecraft:mossy_stone_bricks,10,minecraft:cracked_stone_bricks,10,minecraft:cobblestone,10,minecraft:mossy_cobblestone,10,minecraft:stone_bricks,100)
RB(0,3,1,minecraft:mossy_stone_bricks,10,minecraft:cracked_stone_bricks,10,minecraft:cobblestone,10,minecraft:mossy_cobblestone,10,minecraft:stone_bricks,100)
RB(1,3,1,minecraft:mossy_stone_bricks,10,minecraft:cracked_stone_bricks,10,minecraft:cobblestone,10,minecraft:mossy_cobblestone,10,minecraft:stone_bricks,100)
RB(2,3,1,minecraft:mossy_stone_bricks,10,minecraft:cracked_stone_bricks,10,minecraft:cobblestone,10,minecraft:mossy_cobblestone,10,minecraft:stone_bricks,100)
RB(3,3,1,minecraft:mossy_stone_bricks,10,minecraft:cracked_stone_bricks,10,minecraft:cobblestone,10,minecraft:mossy_cobblestone,10,minecraft:stone_bricks,100)
RB(4,3,1,minecraft:mossy_stone_bricks,10,minecraft:cracked_stone_bricks,10,minecraft:cobblestone,10,minecraft:mossy_cobblestone,10,minecraft:stone_bricks,100)
RB(5,3,1,minecraft:mossy_stone_bricks,10,minecraft:cracked_stone_bricks,10,minecraft:cobblestone,10,minecraft:mossy_cobblestone,10,minecraft:stone_bricks,100)
RB(6,3,1,minecraft:mossy_stone_bricks,10,minecraft:cracked_stone_bricks,10,minecraft:cobblestone,10,minecraft:mossy_cobblestone,10,minecraft:stone_bricks,100)
RB(7,3,1,minecraft:mossy_stone_bricks,10,minecraft:cracked_stone_bricks,10,minecraft:cobblestone,10,minecraft:mossy_cobblestone,10,minecraft:stone_bricks,100)
RB(0,3,2,minecraft:mossy_stone_bricks,10,minecraft:cracked_stone_bricks,10,minecraft:cobblestone,10,minecraft:mossy_cobblestone,10,minecraft:stone_bricks,100)
RB(1,3,2,minecraft:mossy_stone_bricks,10,minecraft:cracked_stone_bricks,10,minecraft:cobblestone,10,minecraft:mossy_cobblestone,10,minecraft:stone_bricks,100)
RB(2,3,2,minecraft:mossy_stone_bricks,10,minecraft:cracked_stone_bricks,10,minecraft:cobblestone,10,minecraft:mossy_cobblestone,10,minecraft:stone_bricks,100)
RB(3,3,2,minecraft:mossy_stone_bricks,10,minecraft:cracked_stone_bricks,10,minecraft:cobblestone,10,minecraft:mossy_cobblestone,10,minecraft:stone_bricks,100)
RB(4,3,2,minecraft:mossy_stone_bricks,10,minecraft:cracked_stone_bricks,10,minecraft:cobblestone,10,minecraft:mossy_cobblestone,10,minecraft:stone_bricks,100)
RB(5,3,2,minecraft:mossy_stone_bricks,10,minecraft:cracked_stone_bricks,10,minecraft:cobblestone,10,minecraft:mossy_cobblestone,10,minecraft:stone_bricks,100)
RB(6,3,2,minecraft:mossy_stone_bricks,10,minecraft:cracked_stone_bricks,10,minecraft:cobblestone,10,minecraft:mossy_cobblestone,10,minecraft:stone_bricks,100)
RB(7,3,2,minecraft:mossy_stone_bricks,10,minecraft:cracked_stone_bricks,10,minecraft:cobblestone,10,minecraft:mossy_cobblestone,10,minecraft:stone_bricks,100)
RB(0,3,3,minecraft:mossy_stone_bricks,10,minecraft:cracked_stone_bricks,10,minecraft:cobblestone,10,minecraft:mossy_cobblestone,10,minecraft:stone_bricks,100)
RB(1,3,3,minecraft:mossy_stone_bricks,10,minecraft:cracked_stone_bricks,10,minecraft:cobblestone,10,minecraft:mossy_cobblestone,10,minecraft:stone_bricks,100)
RB(2,3,3,minecraft:mossy_stone_bricks,10,minecraft:cracked_stone_bricks,10,minecraft:cobblestone,10,minecraft:mossy_cobblestone,10,minecraft:stone_bricks,100)
RB(3,3,3,minecraft:mossy_stone_bricks,10,minecraft:cracked_stone_bricks,10,minecraft:cobblestone,10,minecraft:mossy_cobblestone,10,minecraft:stone_bricks,100)
RB(4,3,3,minecraft:mossy_stone_bricks,10,minecraft:cracked_stone_bricks,10,minecraft:cobblestone,10,minecraft:mossy_cobblestone,10,minecraft:stone_bricks,100)
RB(5,3,3,minecraft:mossy_stone_bricks,10,minecraft:cracked_stone_bricks,10,minecraft:cobblestone,10,minecraft:mossy_cobblestone,10,minecraft:stone_bricks,100)
RB(6,3,3,minecraft:mossy_stone_bricks,10,minecraft:cracked_stone_bricks,10,minecraft:cobblestone,10,minecraft:mossy_cobblestone,10,minecraft:stone_bricks,100)
RB(7,3,3,minecraft:mossy_stone_bricks,10,minecraft:cracked_stone_bricks,10,minecraft:cobblestone,10,minecraft:mossy_cobblestone,10,minecraft:stone_bricks,100)
RB(0,3,4,minecraft:mossy_stone_bricks,10,minecraft:cracked_stone_bricks,10,minecraft:cobblestone,10,minecraft:mossy_cobblestone,10,minecraft:stone_bricks,100)
RB(1,3,4,minecraft:mossy_stone_bricks,10,minecraft:cracked_stone_bricks,10,minecraft:cobblestone,10,minecraft:mossy_cobblestone,10,minecraft:stone_bricks,100)
RB(2,3,4,minecraft:mossy_stone_bricks,10,minecraft:cracked_stone_bricks,10,minecraft:cobblestone,10,minecraft:mossy_cobblestone,10,minecraft:stone_bricks,100)
RB(3,3,4,minecraft:mossy_stone_bricks,10,minecraft:cracked_stone_bricks,10,minecraft:cobblestone,10,minecraft:mossy_cobblestone,10,minecraft:stone_bricks,100)
RB(4,3,4,minecraft:mossy_stone_bricks,10,minecraft:cracked_stone_bricks,10,minecraft:cobblestone,10,minecraft:mossy_cobblestone,10,minecraft:stone_bricks,100)
RB(5,3,4,minecraft:mossy_stone_bricks,10,minecraft:cracked_stone_bricks,10,minecraft:cobblestone,10,minecraft:mossy_cobblestone,10,minecraft:stone_bricks,100)
RB(6,3,4,minecraft:mossy_stone_bricks,10,minecraft:cracked_stone_bricks,10,minecraft:cobblestone,10,minecraft:mossy_cobblestone,10,minecraft:stone_bricks,100)
RB(7,3,4,minecraft:mossy_stone_bricks,10,minecraft:cracked_stone_bricks,10,minecraft:cobblestone,10,minecraft:mossy_cobblestone,10,minecraft:stone_bricks,100)
RB(0,3,5,minecraft:mossy_stone_bricks,10,minecraft:cracked_stone_bricks,10,minecraft:cobblestone,10,minecraft:mossy_cobblestone,10,minecraft:stone_bricks,100)
RB(1,3,5,minecraft:mossy_stone_bricks,10,minecraft:cracked_stone_bricks,10,minecraft:cobblestone,10,minecraft:mossy_cobblestone,10,minecraft:stone_bricks,100)
RB(2,3,5,minecraft:mossy_stone_bricks,10,minecraft:cracked_stone_bricks,10,minecraft:cobblestone,10,minecraft:mossy_cobblestone,10,minecraft:stone_bricks,100)
RB(3,3,5,minecraft:mossy_stone_bricks,10,minecraft:cracked_stone_bricks,10,minecraft:cobblestone,10,minecraft:mossy_cobblestone,10,minecraft:stone_bricks,100)
RB(4,3,5,minecraft:mossy_stone_bricks,10,minecraft:cracked_stone_bricks,10,minecraft:cobblestone,10,minecraft:mossy_cobblestone,10,minecraft:stone_bricks,100)
RB(5,3,5,minecraft:mossy_stone_bricks,10,minecraft:cracked_stone_bricks,10,minecraft:cobblestone,10,minecraft:mossy_cobblestone,10,minecraft:stone_bricks,100)
RB(6,3,5,minecraft:mossy_stone_bricks,10,minecraft:cracked_stone_bricks,10,minecraft:cobblestone,10,minecraft:mossy_cobblestone,10,minecraft:stone_bricks,100)
RB(7,3,5,minecraft:mossy_stone_bricks,10,minecraft:cracked_stone_bricks,10,minecraft:cobblestone,10,minecraft:mossy_cobblestone,10,minecraft:stone_bricks,100)
RB(0,3,6,minecraft:mossy_stone_bricks,10,minecraft:cracked_stone_bricks,10,minecraft:cobblestone,10,minecraft:mossy_cobblestone,10,minecraft:stone_bricks,100)
RB(1,3,6,minecraft:mossy_stone_bricks,10,minecraft:cracked_stone_bricks,10,minecraft:cobblestone,10,minecraft:mossy_cobblestone,10,minecraft:stone_bricks,100)
RB(2,3,6,minecraft:mossy_stone_bricks,10,minecraft:cracked_stone_bricks,10,minecraft:cobblestone,10,minecraft:mossy_cobblestone,10,minecraft:stone_bricks,100)
RB(3,3,6,minecraft:mossy_stone_bricks,10,minecraft:cracked_stone_bricks,10,minecraft:cobblestone,10,minecraft:mossy_cobblestone,10,minecraft:stone_bricks,100)
RB(4,3,6,minecraft:mossy_stone_bricks,10,minecraft:cracked_stone_bricks,10,minecraft:cobblestone,10,minecraft:mossy_cobblestone,10,minecraft:stone_bricks,100)
RB(5,3,6,minecraft:mossy_stone_bricks,10,minecraft:cracked_stone_bricks,10,minecraft:cobblestone,10,minecraft:mossy_cobblestone,10,minecraft:stone_bricks,100)
RB(6,3,6,minecraft:mossy_stone_bricks,10,minecraft:cracked_stone_bricks,10,minecraft:cobblestone,10,minecraft:mossy_cobblestone,10,minecraft:stone_bricks,100)
RB(7,3,6,minecraft:mossy_stone_bricks,10,minecraft:cracked_stone_bricks,10,minecraft:cobblestone,10,minecraft:mossy_cobblestone,10,minecraft:stone_bricks,100)
RB(0,3,7,minecraft:mossy_stone_bricks,10,minecraft:cracked_stone_bricks,10,minecraft:cobblestone,10,minecraft:mossy_cobblestone,10,minecraft:stone_bricks,100)
RB(1,3,7,minecraft:mossy_stone_bricks,10,minecraft:cracked_stone_bricks,10,minecraft:cobblestone,10,minecraft:mossy_cobblestone,10,minecraft:stone_bricks,100)
RB(2,3,7,minecraft:mossy_stone_bricks,10,minecraft:cracked_stone_bricks,10,minecraft:cobblestone,10,minecraft:mossy_cobblestone,10,minecraft:stone_bricks,100)
RB(3,3,7,minecraft:mossy_stone_bricks,10,minecraft:cracked_stone_bricks,10,minecraft:cobblestone,10,minecraft:mossy_cobblestone,10,minecraft:stone_bricks,100)
RB(4,3,7,minecraft:mossy_stone_bricks,10,minecraft:cracked_stone_bricks,10,minecraft:cobblestone,10,minecraft:mossy_cobblestone,10,minecraft:stone_bricks,100)
RB(5,3,7,minecraft:mossy_stone_bricks,10,minecraft:cracked_stone_bricks,10,minecraft:cobblestone,10,minecraft:mossy_cobblestone,10,minecraft:stone_bricks,100)
RB(6,3,7,minecraft:mossy_stone_bricks,10,minecraft:cracked_stone_bricks,10,minecraft:cobblestone,10,minecraft:mossy_cobblestone,10,minecraft:stone_bricks,100)
RB(7,3,7,minecraft:mossy_stone_bricks,10,minecraft:cracked_stone_bricks,10,minecraft:cobblestone,10,minecraft:mossy_cobblestone,10,minecraft:stone_bricks,100)
RB(0,4,0,minecraft:mossy_stone_bricks,10,minecraft:cracked_stone_bricks,10,minecraft:cobblestone,10,minecraft:mossy_cobblestone,10,minecraft:stone_bricks,100)
RB(1,4,0,minecraft:mossy_stone_bricks,10,minecraft:cracked_stone_bricks,10,minecraft:cobblestone,10,minecraft:mossy_cobblestone,10,minecraft:stone_bricks,100)
RB(2,4,0,minecraft:mossy_stone_bricks,10,minecraft:cracked_stone_bricks,10,minecraft:cobblestone,10,minecraft:mossy_cobblestone,10,minecraft:stone_bricks,100)
RB(3,4,0,minecraft:mossy_stone_bricks,10,minecraft:cracked_stone_bricks,10,minecraft:cobblestone,10,minecraft:mossy_cobblestone,10,minecraft:stone_bricks,100)
RB(4,4,0,minecraft:mossy_stone_bricks,10,minecraft:cracked_stone_bricks,10,minecraft:cobblestone,10,minecraft:mossy_cobblestone,10,minecraft:stone_bricks,100)
RB(5,4,0,minecraft:mossy_stone_bricks,10,minecraft:cracked_stone_bricks,10,minecraft:cobblestone,10,minecraft:mossy_cobblestone,10,minecraft:stone_bricks,100)
RB(6,4,0,minecraft:mossy_stone_bricks,10,minecraft:cracked_stone_bricks,10,minecraft:cobblestone,10,minecraft:mossy_cobblestone,10,minecraft:stone_bricks,100)
RB(7,4,0,minecraft:mossy_stone_bricks,10,minecraft:cracked_stone_bricks,10,minecraft:cobblestone,10,minecraft:mossy_cobblestone,10,minecraft:stone_bricks,100)
RB(0,4,1,minecraft:mossy_stone_bricks,10,minecraft:cracked_stone_bricks,10,minecraft:cobblestone,10,minecraft:mossy_cobblestone,10,minecraft:stone_bricks,100)
RB(1,4,1,minecraft:mossy_stone_bricks,10,minecraft:cracked_stone_bricks,10,minecraft:cobblestone,10,minecraft:mossy_cobblestone,10,minecraft:stone_bricks,100)
RB(2,4,1,minecraft:mossy_stone_bricks,10,minecraft:cracked_stone_bricks,10,minecraft:cobblestone,10,minecraft:mossy_cobblestone,10,minecraft:stone_bricks,100)
RB(3,4,1,minecraft:mossy_stone_bricks,10,minecraft:cracked_stone_bricks,10,minecraft:cobblestone,10,minecraft:mossy_cobblestone,10,minecraft:stone_bricks,100)
RB(4,4,1,minecraft:mossy_stone_bricks,10,minecraft:cracked_stone_bricks,10,minecraft:cobblestone,10,minecraft:mossy_cobblestone,10,minecraft:stone_bricks,100)
RB(5,4,1,minecraft:mossy_stone_bricks,10,minecraft:cracked_stone_bricks,10,minecraft:cobblestone,10,minecraft:mossy_cobblestone,10,minecraft:stone_bricks,100)
RB(6,4,1,minecraft:mossy_stone_bricks,10,minecraft:cracked_stone_bricks,10,minecraft:cobblestone,10,minecraft:mossy_cobblestone,10,minecraft:stone_bricks,100)
RB(7,4,1,minecraft:mossy_stone_bricks,10,minecraft:cracked_stone_bricks,10,minecraft:cobblestone,10,minecraft:mossy_cobblestone,10,minecraft:stone_bricks,100)
RB(0,4,2,minecraft:mossy_stone_bricks,10,minecraft:cracked_stone_bricks,10,minecraft:cobblestone,10,minecraft:mossy_cobblestone,10,minecraft:stone_bricks,100)
RB(1,4,2,minecraft:mossy_stone_bricks,10,minecraft:cracked_stone_bricks,10,minecraft:cobblestone,10,minecraft:mossy_cobblestone,10,minecraft:stone_bricks,100)
RB(2,4,2,minecraft:mossy_stone_bricks,10,minecraft:cracked_stone_bricks,10,minecraft:cobblestone,10,minecraft:mossy_cobblestone,10,minecraft:stone_bricks,100)
RB(3,4,2,minecraft:mossy_stone_bricks,10,minecraft:cracked_stone_bricks,10,minecraft:cobblestone,10,minecraft:mossy_cobblestone,10,minecraft:stone_bricks,100)
RB(4,4,2,minecraft:mossy_stone_bricks,10,minecraft:cracked_stone_bricks,10,minecraft:cobblestone,10,minecraft:mossy_cobblestone,10,minecraft:stone_bricks,100)
RB(5,4,2,minecraft:mossy_stone_bricks,10,minecraft:cracked_stone_bricks,10,minecraft:cobblestone,10,minecraft:mossy_cobblestone,10,minecraft:stone_bricks,100)
RB(6,4,2,minecraft:mossy_stone_bricks,10,minecraft:cracked_stone_bricks,10,minecraft:cobblestone,10,minecraft:mossy_cobblestone,10,minecraft:stone_bricks,100)
RB(7,4,2,minecraft:mossy_stone_bricks,10,minecraft:cracked_stone_bricks,10,minecraft:cobblestone,10,minecraft:mossy_cobblestone,10,minecraft:stone_bricks,100)
RB(0,4,3,minecraft:mossy_stone_bricks,10,minecraft:cracked_stone_bricks,10,minecraft:cobblestone,10,minecraft:mossy_cobblestone,10,minecraft:stone_bricks,100)
RB(1,4,3,minecraft:mossy_stone_bricks,10,minecraft:cracked_stone_bricks,10,minecraft:cobblestone,10,minecraft:mossy_cobblestone,10,minecraft:stone_bricks,100)
RB(2,4,3,minecraft:mossy_stone_bricks,10,minecraft:cracked_stone_bricks,10,minecraft:cobblestone,10,minecraft:mossy_cobblestone,10,minecraft:stone_bricks,100)
RB(3,4,3,minecraft:mossy_stone_bricks,10,minecraft:cracked_stone_bricks,10,minecraft:cobblestone,10,minecraft:mossy_cobblestone,10,minecraft:stone_bricks,100)
RB(4,4,3,minecraft:mossy_stone_bricks,10,minecraft:cracked_stone_bricks,10,minecraft:cobblestone,10,minecraft:mossy_cobblestone,10,minecraft:stone_bricks,100)
RB(5,4,3,minecraft:mossy_stone_bricks,10,minecraft:cracked_stone_bricks,10,minecraft:cobblestone,10,minecraft:mossy_cobblestone,10,minecraft:stone_bricks,100)
RB(6,4,3,minecraft:mossy_stone_bricks,10,minecraft:cracked_stone_bricks,10,minecraft:cobblestone,10,minecraft:mossy_cobblestone,10,minecraft:stone_bricks,100)
RB(7,4,3,minecraft:mossy_stone_bricks,10,minecraft:cracked_stone_bricks,10,minecraft:cobblestone,10,minecraft:mossy_cobblestone,10,minecraft:stone_bricks,100)
RB(0,4,4,minecraft:mossy_stone_bricks,10,minecraft:cracked_stone_bricks,10,minecraft:cobblestone,10,minecraft:mossy_cobblestone,10,minecraft:stone_bricks,100)
RB(1,4,4,minecraft:mossy_stone_bricks,10,minecraft:cracked_stone_bricks,10,minecraft:cobblestone,10,minecraft:mossy_cobblestone,10,minecraft:stone_bricks,100)
RB(2,4,4,minecraft:mossy_stone_bricks,10,minecraft:cracked_stone_bricks,10,minecraft:cobblestone,10,minecraft:mossy_cobblestone,10,minecraft:stone_bricks,100)
RB(3,4,4,minecraft:mossy_stone_bricks,10,minecraft:cracked_stone_bricks,10,minecraft:cobblestone,10,minecraft:mossy_cobblestone,10,minecraft:stone_bricks,100)
RB(4,4,4,minecraft:mossy_stone_bricks,10,minecraft:cracked_stone_bricks,10,minecraft:cobblestone,10,minecraft:mossy_cobblestone,10,minecraft:stone_bricks,100)
RB(5,4,4,minecraft:mossy_stone_bricks,10,minecraft:cracked_stone_bricks,10,minecraft:cobblestone,10,minecraft:mossy_cobblestone,10,minecraft:stone_bricks,100)
RB(6,4,4,minecraft:mossy_stone_bricks,10,minecraft:cracked_stone_bricks,10,minecraft:cobblestone,10,minecraft:mossy_cobblestone,10,minecraft:stone_bricks,100)
RB(7,4,4,minecraft:mossy_stone_bricks,10,minecraft:cracked_stone_bricks,10,minecraft:cobblestone,10,minecraft:mossy_cobblestone,10,minecraft:stone_bricks,100)
RB(0,4,5,minecraft:mossy_stone_bricks,10,minecraft:cracked_stone_bricks,10,minecraft:cobblestone,10,minecraft:mossy_cobblestone,10,minecraft:stone_bricks,100)
RB(1,4,5,minecraft:mossy_stone_bricks,10,minecraft:cracked_stone_bricks,10,minecraft:cobblestone,10,minecraft:mossy_cobblestone,10,minecraft:stone_bricks,100)
RB(2,4,5,minecraft:mossy_stone_bricks,10,minecraft:cracked_stone_bricks,10,minecraft:cobblestone,10,minecraft:mossy_cobblestone,10,minecraft:stone_bricks,100)
RB(3,4,5,minecraft:mossy_stone_bricks,10,minecraft:cracked_stone_bricks,10,minecraft:cobblestone,10,minecraft:mossy_cobblestone,10,minecraft:stone_bricks,100)
RB(4,4,5,minecraft:mossy_stone_bricks,10,minecraft:cracked_stone_bricks,10,minecraft:cobblestone,10,minecraft:mossy_cobblestone,10,minecraft:stone_bricks,100)
RB(5,4,5,minecraft:mossy_stone_bricks,10,minecraft:cracked_stone_bricks,10,minecraft:cobblestone,10,minecraft:mossy_cobblestone,10,minecraft:stone_bricks,100)
RB(6,4,5,minecraft:mossy_stone_bricks,10,minecraft:cracked_stone_bricks,10,minecraft:cobblestone,10,minecraft:mossy_cobblestone,10,minecraft:stone_bricks,100)
RB(7,4,5,minecraft:mossy_stone_bricks,10,minecraft:cracked_stone_bricks,10,minecraft:cobblestone,10,minecraft:mossy_cobblestone,10,minecraft:stone_bricks,100)
RB(0,4,6,minecraft:mossy_stone_bricks,10,minecraft:cracked_stone_bricks,10,minecraft:cobblestone,10,minecraft:mossy_cobblestone,10,minecraft:stone_bricks,100)
RB(1,4,6,minecraft:mossy_stone_bricks,10,minecraft:cracked_stone_bricks,10,minecraft:cobblestone,10,minecraft:mossy_cobblestone,10,minecraft:stone_bricks,100)
RB(2,4,6,minecraft:mossy_stone_bricks,10,minecraft:cracked_stone_bricks,10,minecraft:cobblestone,10,minecraft:mossy_cobblestone,10,minecraft:stone_bricks,100)
RB(3,4,6,minecraft:mossy_stone_bricks,10,minecraft:cracked_stone_bricks,10,minecraft:cobblestone,10,minecraft:mossy_cobblestone,10,minecraft:stone_bricks,100)
RB(4,4,6,minecraft:mossy_stone_bricks,10,minecraft:cracked_stone_bricks,10,minecraft:cobblestone,10,minecraft:mossy_cobblestone,10,minecraft:stone_bricks,100)
RB(5,4,6,minecraft:mossy_stone_bricks,10,minecraft:cracked_stone_bricks,10,minecraft:cobblestone,10,minecraft:mossy_cobblestone,10,minecraft:stone_bricks,100)
RB(6,4,6,minecraft:mossy_stone_bricks,10,minecraft:cracked_stone_bricks,10,minecraft:cobblestone,10,minecraft:mossy_cobblestone,10,minecraft:stone_bricks,100)
RB(7,4,6,minecraft:mossy_stone_bricks,10,minecraft:cracked_stone_bricks,10,minecraft:cobblestone,10,minecraft:mossy_cobblestone,10,minecraft:stone_bricks,100)
RB(0,4,7,minecraft:mossy_stone_bricks,10,minecraft:cracked_stone_bricks,10,minecraft:cobblestone,10,minecraft:mossy_cobblestone,10,minecraft:stone_bricks,100)
RB(1,4,7,minecraft:mossy_stone_bricks,10,minecraft:cracked_stone_bricks,10,minecraft:cobblestone,10,minecraft:mossy_cobblestone,10,minecraft:stone_bricks,100)
RB(2,4,7,minecraft:mossy_stone_bricks,10,minecraft:cracked_stone_bricks,10,minecraft:cobblestone,10,minecraft:mossy_cobblestone,10,minecraft:stone_bricks,100)
RB(3,4,7,minecraft:mossy_stone_bricks,10,minecraft:cracked_stone_bricks,10,minecraft:cobblestone,10,minecraft:mossy_cobblestone,10,minecraft:stone_bricks,100)
RB(4,4,7,minecraft:mossy_stone_bricks,10,minecraft:cracked_stone_bricks,10,minecraft:cobblestone,10,minecraft:mossy_cobblestone,10,minecraft:stone_bricks,100)
RB(5,4,7,minecraft:mossy_stone_bricks,10,minecraft:cracked_stone_bricks,10,minecraft:cobblestone,10,minecraft:mossy_cobblestone,10,minecraft:stone_bricks,100)
RB(6,4,7,minecraft:mossy_stone_bricks,10,minecraft:cracked_stone_bricks,10,minecraft:cobblestone,10,minecraft:mossy_cobblestone,10,minecraft:stone_bricks,100)
RB(7,4,7,minecraft:mossy_stone_bricks,10,minecraft:cracked_stone_bricks,10,minecraft:cobblestone,10,minecraft:mossy_cobblestone,10,minecraft:stone_bricks,100)
RB(0,5,0,minecraft:mossy_stone_bricks,10,minecraft:cracked_stone_bricks,10,minecraft:cobblestone,10,minecraft:mossy_cobblestone,10,minecraft:stone_bricks,100)
RB(1,5,0,minecraft:mossy_stone_bricks,10,minecraft:cracked_stone_bricks,10,minecraft:cobblestone,10,minecraft:mossy_cobblestone,10,minecraft:stone_bricks,100)
RB(2,5,0,minecraft:mossy_stone_bricks,10,minecraft:cracked_stone_bricks,10,minecraft:cobblestone,10,minecraft:mossy_cobblestone,10,minecraft:stone_bricks,100)
RB(3,5,0,minecraft:mossy_stone_bricks,10,minecraft:cracked_stone_bricks,10,minecraft:cobblestone,10,minecraft:mossy_cobblestone,10,minecraft:stone_bricks,100)
RB(4,5,0,minecraft:mossy_stone_bricks,10,minecraft:cracked_stone_bricks,10,minecraft:cobblestone,10,minecraft:mossy_cobblestone,10,minecraft:stone_bricks,100)
RB(5,5,0,minecraft:mossy_stone_bricks,10,minecraft:cracked_stone_bricks,10,minecraft:cobblestone,10,minecraft:mossy_cobblestone,10,minecraft:stone_bricks,100)
RB(6,5,0,minecraft:mossy_stone_bricks,10,minecraft:cracked_stone_bricks,10,minecraft:cobblestone,10,minecraft:mossy_cobblestone,10,minecraft:stone_bricks,100)
RB(7,5,0,minecraft:mossy_stone_bricks,10,minecraft:cracked_stone_bricks,10,minecraft:cobblestone,10,minecraft:mossy_cobblestone,10,minecraft:stone_bricks,100)
RB(0,5,1,minecraft:mossy_stone_bricks,10,minecraft:cracked_stone_bricks,10,minecraft:cobblestone,10,minecraft:mossy_cobblestone,10,minecraft:stone_bricks,100)
RB(1,5,1,minecraft:mossy_stone_bricks,10,minecraft:cracked_stone_bricks,10,minecraft:cobblestone,10,minecraft:mossy_cobblestone,10,minecraft:stone_bricks,100)
RB(2,5,1,minecraft:mossy_stone_bricks,10,minecraft:cracked_stone_bricks,10,minecraft:cobblestone,10,minecraft:mossy_cobblestone,10,minecraft:stone_bricks,100)
RB(3,5,1,minecraft:mossy_stone_bricks,10,minecraft:cracked_stone_bricks,10,minecraft:cobblestone,10,minecraft:mossy_cobblestone,10,minecraft:stone_bricks,100)
RB(4,5,1,minecraft:mossy_stone_bricks,10,minecraft:cracked_stone_bricks,10,minecraft:cobblestone,10,minecraft:mossy_cobblestone,10,minecraft:stone_bricks,100)
RB(5,5,1,minecraft:mossy_stone_bricks,10,minecraft:cracked_stone_bricks,10,minecraft:cobblestone,10,minecraft:mossy_cobblestone,10,minecraft:stone_bricks,100)
RB(6,5,1,minecraft:mossy_stone_bricks,10,minecraft:cracked_stone_bricks,10,minecraft:cobblestone,10,minecraft:mossy_cobblestone,10,minecraft:stone_bricks,100)
RB(7,5,1,minecraft:mossy_stone_bricks,10,minecraft:cracked_stone_bricks,10,minecraft:cobblestone,10,minecraft:mossy_cobblestone,10,minecraft:stone_bricks,100)
RB(0,5,2,minecraft:mossy_stone_bricks,10,minecraft:cracked_stone_bricks,10,minecraft:cobblestone,10,minecraft:mossy_cobblestone,10,minecraft:stone_bricks,100)
RB(1,5,2,minecraft:mossy_stone_bricks,10,minecraft:cracked_stone_bricks,10,minecraft:cobblestone,10,minecraft:mossy_cobblestone,10,minecraft:stone_bricks,100)
RB(2,5,2,minecraft:mossy_stone_bricks,10,minecraft:cracked_stone_bricks,10,minecraft:cobblestone,10,minecraft:mossy_cobblestone,10,minecraft:stone_bricks,100)
RB(3,5,2,minecraft:mossy_stone_bricks,10,minecraft:cracked_stone_bricks,10,minecraft:cobblestone,10,minecraft:mossy_cobblestone,10,minecraft:stone_bricks,100)
RB(4,5,2,minecraft:mossy_stone_bricks,10,minecraft:cracked_stone_bricks,10,minecraft:cobblestone,10,minecraft:mossy_cobblestone,10,minecraft:stone_bricks,100)
RB(5,5,2,minecraft:mossy_stone_bricks,10,minecraft:cracked_stone_bricks,10,minecraft:cobblestone,10,minecraft:mossy_cobblestone,10,minecraft:stone_bricks,100)
RB(6,5,2,minecraft:mossy_stone_bricks,10,minecraft:cracked_stone_bricks,10,minecraft:cobblestone,10,minecraft:mossy_cobblestone,10,minecraft:stone_bricks,100)
RB(7,5,2,minecraft:mossy_stone_bricks,10,minecraft:cracked_stone_bricks,10,minecraft:cobblestone,10,minecraft:mossy_cobblestone,10,minecraft:stone_bricks,100)
RB(0,5,3,minecraft:mossy_stone_bricks,10,minecraft:cracked_stone_bricks,10,minecraft:cobblestone,10,minecraft:mossy_cobblestone,10,minecraft:stone_bricks,100)
RB(1,5,3,minecraft:mossy_stone_bricks,10,minecraft:cracked_stone_bricks,10,minecraft:cobblestone,10,minecraft:mossy_cobblestone,10,minecraft:stone_bricks,100)
RB(2,5,3,minecraft:mossy_stone_bricks,10,minecraft:cracked_stone_bricks,10,minecraft:cobblestone,10,minecraft:mossy_cobblestone,10,minecraft:stone_bricks,100)
RB(3,5,3,minecraft:mossy_stone_bricks,10,minecraft:cracked_stone_bricks,10,minecraft:cobblestone,10,minecraft:mossy_cobblestone,10,minecraft:stone_bricks,100)
RB(4,5,3,minecraft:mossy_stone_bricks,10,minecraft:cracked_stone_bricks,10,minecraft:cobblestone,10,minecraft:mossy_cobblestone,10,minecraft:stone_bricks,100)
RB(5,5,3,minecraft:mossy_stone_bricks,10,minecraft:cracked_stone_bricks,10,minecraft:cobblestone,10,minecraft:mossy_cobblestone,10,minecraft:stone_bricks,100)
RB(6,5,3,minecraft:mossy_stone_bricks,10,minecraft:cracked_stone_bricks,10,minecraft:cobblestone,10,minecraft:mossy_cobblestone,10,minecraft:stone_bricks,100)
RB(7,5,3,minecraft:mossy_stone_bricks,10,minecraft:cracked_stone_bricks,10,minecraft:cobblestone,10,minecraft:mossy_cobblestone,10,minecraft:stone_bricks,100)
RB(0,5,4,minecraft:mossy_stone_bricks,10,minecraft:cracked_stone_bricks,10,minecraft:cobblestone,10,minecraft:mossy_cobblestone,10,minecraft:stone_bricks,100)
RB(1,5,4,minecraft:mossy_stone_bricks,10,minecraft:cracked_stone_bricks,10,minecraft:cobblestone,10,minecraft:mossy_cobblestone,10,minecraft:stone_bricks,100)
RB(2,5,4,minecraft:mossy_stone_bricks,10,minecraft:cracked_stone_bricks,10,minecraft:cobblestone,10,minecraft:mossy_cobblestone,10,minecraft:stone_bricks,100)
RB(3,5,4,minecraft:mossy_stone_bricks,10,minecraft:cracked_stone_bricks,10,minecraft:cobblestone,10,minecraft:mossy_cobblestone,10,minecraft:stone_bricks,100)
RB(4,5,4,minecraft:mossy_stone_bricks,10,minecraft:cracked_stone_bricks,10,minecraft:cobblestone,10,minecraft:mossy_cobblestone,10,minecraft:stone_bricks,100)
RB(5,5,4,minecraft:mossy_stone_bricks,10,minecraft:cracked_stone_bricks,10,minecraft:cobblestone,10,minecraft:mossy_cobblestone,10,minecraft:stone_bricks,100)
RB(6,5,4,minecraft:mossy_stone_bricks,10,minecraft:cracked_stone_bricks,10,minecraft:cobblestone,10,minecraft:mossy_cobblestone,10,minecraft:stone_bricks,100)
RB(7,5,4,minecraft:mossy_stone_bricks,10,minecraft:cracked_stone_bricks,10,minecraft:cobblestone,10,minecraft:mossy_cobblestone,10,minecraft:stone_bricks,100)
RB(0,5,5,minecraft:mossy_stone_bricks,10,minecraft:cracked_stone_bricks,10,minecraft:cobblestone,10,minecraft:mossy_cobblestone,10,minecraft:stone_bricks,100)
RB(1,5,5,minecraft:mossy_stone_bricks,10,minecraft:cracked_stone_bricks,10,minecraft:cobblestone,10,minecraft:mossy_cobblestone,10,minecraft:stone_bricks,100)
RB(2,5,5,minecraft:mossy_stone_bricks,10,minecraft:cracked_stone_bricks,10,minecraft:cobblestone,10,minecraft:mossy_cobblestone,10,minecraft:stone_bricks,100)
RB(3,5,5,minecraft:mossy_stone_bricks,10,minecraft:cracked_stone_bricks,10,minecraft:cobblestone,10,minecraft:mossy_cobblestone,10,minecraft:stone_bricks,100)
RB(4,5,5,minecraft:mossy_stone_bricks,10,minecraft:cracked_stone_bricks,10,minecraft:cobblestone,10,minecraft:mossy_cobblestone,10,minecraft:stone_bricks,100)
RB(5,5,5,minecraft:mossy_stone_bricks,10,minecraft:cracked_stone_bricks,10,minecraft:cobblestone,10,minecraft:mossy_cobblestone,10,minecraft:stone_bricks,100)
RB(6,5,5,minecraft:mossy_stone_bricks,10,minecraft:cracked_stone_bricks,10,minecraft:cobblestone,10,minecraft:mossy_cobblestone,10,minecraft:stone_bricks,100)
RB(7,5,5,minecraft:mossy_stone_bricks,10,minecraft:cracked_stone_bricks,10,minecraft:cobblestone,10,minecraft:mossy_cobblestone,10,minecraft:stone_bricks,100)
RB(0,5,6,minecraft:mossy_stone_bricks,10,minecraft:cracked_stone_bricks,10,minecraft:cobblestone,10,minecraft:mossy_cobblestone,10,minecraft:stone_bricks,100)
RB(1,5,6,minecraft:mossy_stone_bricks,10,minecraft:cracked_stone_bricks,10,minecraft:cobblestone,10,minecraft:mossy_cobblestone,10,minecraft:stone_bricks,100)
RB(2,5,6,minecraft:mossy_stone_bricks,10,minecraft:cracked_stone_bricks,10,minecraft:cobblestone,10,minecraft:mossy_cobblestone,10,minecraft:stone_bricks,100)
RB(3,5,6,minecraft:mossy_stone_bricks,10,minecraft:cracked_stone_bricks,10,minecraft:cobblestone,10,minecraft:mossy_cobblestone,10,minecraft:stone_bricks,100)
RB(4,5,6,minecraft:mossy_stone_bricks,10,minecraft:cracked_stone_bricks,10,minecraft:cobblestone,10,minecraft:mossy_cobblestone,10,minecraft:stone_bricks,100)
RB(5,5,6,minecraft:mossy_stone_bricks,10,minecraft:cracked_stone_bricks,10,minecraft:cobblestone,10,minecraft:mossy_cobblestone,10,minecraft:stone_bricks,100)
RB(6,5,6,minecraft:mossy_stone_bricks,10,minecraft:cracked_stone_bricks,10,minecraft:cobblestone,10,minecraft:mossy_cobblestone,10,minecraft:stone_bricks,100)
RB(7,5,6,minecraft:mossy_stone_bricks,10,minecraft:cracked_stone_bricks,10,minecraft:cobblestone,10,minecraft:mossy_cobblestone,10,minecraft:stone_bricks,100)
RB(0,5,7,minecraft:mossy_stone_bricks,10,minecraft:cracked_stone_bricks,10,minecraft:cobblestone,10,minecraft:mossy_cobblestone,10,minecraft:stone_bricks,100)
RB(1,5,7,minecraft:mossy_stone_bricks,10,minecraft:cracked_stone_bricks,10,minecraft:cobblestone,10,minecraft:mossy_cobblestone,10,minecraft:stone_bricks,100)
RB(2,5,7,minecraft:mossy_stone_bricks,10,minecraft:cracked_stone_bricks,10,minecraft:cobblestone,10,minecraft:mossy_cobblestone,10,minecraft:stone_bricks,100)
RB(3,5,7,minecraft:mossy_stone_bricks,10,minecraft:cracked_stone_bricks,10,minecraft:cobblestone,10,minecraft:mossy_cobblestone,10,minecraft:stone_bricks,100)
RB(4,5,7,minecraft:mossy_stone_bricks,10,minecraft:cracked_stone_bricks,10,minecraft:cobblestone,10,minecraft:mossy_cobblestone,10,minecraft:stone_bricks,100)
RB(5,5,7,minecraft:mossy_stone_bricks,10,minecraft:cracked_stone_bricks,10,minecraft:cobblestone,10,minecraft:mossy_cobblestone,10,minecraft:stone_bricks,100)
RB(6,5,7,minecraft:mossy_stone_bricks,10,minecraft:cracked_stone_bricks,10,minecraft:cobblestone,10,minecraft:mossy_cobblestone,10,minecraft:stone_bricks,100)
RB(7,5,7,minecraft:mossy_stone_bricks,10,minecraft:cracked_stone_bricks,10,minecraft:cobblestone,10,minecraft:mossy_cobblestone,10,minecraft:stone_bricks,100)
RB(0,6,0,minecraft:mossy_stone_bricks,10,minecraft:cracked_stone_bricks,10,minecraft:cobblestone,10,minecraft:mossy_cobblestone,10,minecraft:stone_bricks,100)
RB(1,6,0,minecraft:mossy_stone_bricks,10,minecraft:cracked_stone_bricks,10,minecraft:cobblestone,10,minecraft:mossy_cobblestone,10,minecraft:stone_bricks,100)
RB(2,6,0,minecraft:mossy_stone_bricks,10,minecraft:cracked_stone_bricks,10,minecraft:cobblestone,10,minecraft:mossy_cobblestone,10,minecraft:stone_bricks,100)
RB(3,6,0,minecraft:mossy_stone_bricks,10,minecraft:cracked_stone_bricks,10,minecraft:cobblestone,10,minecraft:mossy_cobblestone,10,minecraft:stone_bricks,100)
RB(4,6,0,minecraft:mossy_stone_bricks,10,minecraft:cracked_stone_bricks,10,minecraft:cobblestone,10,minecraft:mossy_cobblestone,10,minecraft:stone_bricks,100)
RB(5,6,0,minecraft:mossy_stone_bricks,10,minecraft:cracked_stone_bricks,10,minecraft:cobblestone,10,minecraft:mossy_cobblestone,10,minecraft:stone_bricks,100)
RB(6,6,0,minecraft:mossy_stone_bricks,10,minecraft:cracked_stone_bricks,10,minecraft:cobblestone,10,minecraft:mossy_cobblestone,10,minecraft:stone_bricks,100)
RB(7,6,0,minecraft:mossy_stone_bricks,10,minecraft:cracked_stone_bricks,10,minecraft:cobblestone,10,minecraft:mossy_cobblestone,10,minecraft:stone_bricks,100)
RB(0,6,1,minecraft:mossy_stone_bricks,10,minecraft:cracked_stone_bricks,10,minecraft:cobblestone,10,minecraft:mossy_cobblestone,10,minecraft:stone_bricks,100)
RB(1,6,1,minecraft:mossy_stone_bricks,10,minecraft:cracked_stone_bricks,10,minecraft:cobblestone,10,minecraft:mossy_cobblestone,10,minecraft:stone_bricks,100)
RB(2,6,1,minecraft:mossy_stone_bricks,10,minecraft:cracked_stone_bricks,10,minecraft:cobblestone,10,minecraft:mossy_cobblestone,10,minecraft:stone_bricks,100)
RB(3,6,1,minecraft:mossy_stone_bricks,10,minecraft:cracked_stone_bricks,10,minecraft:cobblestone,10,minecraft:mossy_cobblestone,10,minecraft:stone_bricks,100)
RB(4,6,1,minecraft:mossy_stone_bricks,10,minecraft:cracked_stone_bricks,10,minecraft:cobblestone,10,minecraft:mossy_cobblestone,10,minecraft:stone_bricks,100)
RB(5,6,1,minecraft:mossy_stone_bricks,10,minecraft:cracked_stone_bricks,10,minecraft:cobblestone,10,minecraft:mossy_cobblestone,10,minecraft:stone_bricks,100)
RB(6,6,1,minecraft:mossy_stone_bricks,10,minecraft:cracked_stone_bricks,10,minecraft:cobblestone,10,minecraft:mossy_cobblestone,10,minecraft:stone_bricks,100)
RB(7,6,1,minecraft:mossy_stone_bricks,10,minecraft:cracked_stone_bricks,10,minecraft:cobblestone,10,minecraft:mossy_cobblestone,10,minecraft:stone_bricks,100)
RB(0,6,2,minecraft:mossy_stone_bricks,10,minecraft:cracked_stone_bricks,10,minecraft:cobblestone,10,minecraft:mossy_cobblestone,10,minecraft:stone_bricks,100)
RB(1,6,2,minecraft:mossy_stone_bricks,10,minecraft:cracked_stone_bricks,10,minecraft:cobblestone,10,minecraft:mossy_cobblestone,10,minecraft:stone_bricks,100)
RB(2,6,2,minecraft:mossy_stone_bricks,10,minecraft:cracked_stone_bricks,10,minecraft:cobblestone,10,minecraft:mossy_cobblestone,10,minecraft:stone_bricks,100)
RB(3,6,2,minecraft:mossy_stone_bricks,10,minecraft:cracked_stone_bricks,10,minecraft:cobblestone,10,minecraft:mossy_cobblestone,10,minecraft:stone_bricks,100)
RB(4,6,2,minecraft:mossy_stone_bricks,10,minecraft:cracked_stone_bricks,10,minecraft:cobblestone,10,minecraft:mossy_cobblestone,10,minecraft:stone_bricks,100)
RB(5,6,2,minecraft:mossy_stone_bricks,10,minecraft:cracked_stone_bricks,10,minecraft:cobblestone,10,minecraft:mossy_cobblestone,10,minecraft:stone_bricks,100)
RB(6,6,2,minecraft:mossy_stone_bricks,10,minecraft:cracked_stone_bricks,10,minecraft:cobblestone,10,minecraft:mossy_cobblestone,10,minecraft:stone_bricks,100)
RB(7,6,2,minecraft:mossy_stone_bricks,10,minecraft:cracked_stone_bricks,10,minecraft:cobblestone,10,minecraft:mossy_cobblestone,10,minecraft:stone_bricks,100)
RB(0,6,3,minecraft:mossy_stone_bricks,10,minecraft:cracked_stone_bricks,10,minecraft:cobblestone,10,minecraft:mossy_cobblestone,10,minecraft:stone_bricks,100)
RB(1,6,3,minecraft:mossy_stone_bricks,10,minecraft:cracked_stone_bricks,10,minecraft:cobblestone,10,minecraft:mossy_cobblestone,10,minecraft:stone_bricks,100)
RB(2,6,3,minecraft:mossy_stone_bricks,10,minecraft:cracked_stone_bricks,10,minecraft:cobblestone,10,minecraft:mossy_cobblestone,10,minecraft:stone_bricks,100)
RB(3,6,3,minecraft:mossy_stone_bricks,10,minecraft:cracked_stone_bricks,10,minecraft:cobblestone,10,minecraft:mossy_cobblestone,10,minecraft:stone_bricks,100)
RB(4,6,3,minecraft:mossy_stone_bricks,10,minecraft:cracked_stone_bricks,10,minecraft:cobblestone,10,minecraft:mossy_cobblestone,10,minecraft:stone_bricks,100)
RB(5,6,3,minecraft:mossy_stone_bricks,10,minecraft:cracked_stone_bricks,10,minecraft:cobblestone,10,minecraft:mossy_cobblestone,10,minecraft:stone_bricks,100)
RB(6,6,3,minecraft:mossy_stone_bricks,10,minecraft:cracked_stone_bricks,10,minecraft:cobblestone,10,minecraft:mossy_cobblestone,10,minecraft:stone_bricks,100)
RB(7,6,3,minecraft:mossy_stone_bricks,10,minecraft:cracked_stone_bricks,10,minecraft:cobblestone,10,minecraft:mossy_cobblestone,10,minecraft:stone_bricks,100)
RB(0,6,4,minecraft:mossy_stone_bricks,10,minecraft:cracked_stone_bricks,10,minecraft:cobblestone,10,minecraft:mossy_cobblestone,10,minecraft:stone_bricks,100)
RB(1,6,4,minecraft:mossy_stone_bricks,10,minecraft:cracked_stone_bricks,10,minecraft:cobblestone,10,minecraft:mossy_cobblestone,10,minecraft:stone_bricks,100)
RB(2,6,4,minecraft:mossy_stone_bricks,10,minecraft:cracked_stone_bricks,10,minecraft:cobblestone,10,minecraft:mossy_cobblestone,10,minecraft:stone_bricks,100)
RB(3,6,4,minecraft:mossy_stone_bricks,10,minecraft:cracked_stone_bricks,10,minecraft:cobblestone,10,minecraft:mossy_cobblestone,10,minecraft:stone_bricks,100)
RB(4,6,4,minecraft:mossy_stone_bricks,10,minecraft:cracked_stone_bricks,10,minecraft:cobblestone,10,minecraft:mossy_cobblestone,10,minecraft:stone_bricks,100)
RB(5,6,4,minecraft:mossy_stone_bricks,10,minecraft:cracked_stone_bricks,10,minecraft:cobblestone,10,minecraft:mossy_cobblestone,10,minecraft:stone_bricks,100)
RB(6,6,4,minecraft:mossy_stone_bricks,10,minecraft:cracked_stone_bricks,10,minecraft:cobblestone,10,minecraft:mossy_cobblestone,10,minecraft:stone_bricks,100)
RB(7,6,4,minecraft:mossy_stone_bricks,10,minecraft:cracked_stone_bricks,10,minecraft:cobblestone,10,minecraft:mossy_cobblestone,10,minecraft:stone_bricks,100)
RB(0,6,5,minecraft:mossy_stone_bricks,10,minecraft:cracked_stone_bricks,10,minecraft:cobblestone,10,minecraft:mossy_cobblestone,10,minecraft:stone_bricks,100)
RB(1,6,5,minecraft:mossy_stone_bricks,10,minecraft:cracked_stone_bricks,10,minecraft:cobblestone,10,minecraft:mossy_cobblestone,10,minecraft:stone_bricks,100)
RB(2,6,5,minecraft:mossy_stone_bricks,10,minecraft:cracked_stone_bricks,10,minecraft:cobblestone,10,minecraft:mossy_cobblestone,10,minecraft:stone_bricks,100)
RB(3,6,5,minecraft:mossy_stone_bricks,10,minecraft:cracked_stone_bricks,10,minecraft:cobblestone,10,minecraft:mossy_cobblestone,10,minecraft:stone_bricks,100)
RB(4,6,5,minecraft:mossy_stone_bricks,10,minecraft:cracked_stone_bricks,10,minecraft:cobblestone,10,minecraft:mossy_cobblestone,10,minecraft:stone_bricks,100)
RB(5,6,5,minecraft:mossy_stone_bricks,10,minecraft:cracked_stone_bricks,10,minecraft:cobblestone,10,minecraft:mossy_cobblestone,10,minecraft:stone_bricks,100)
RB(6,6,5,minecraft:mossy_stone_bricks,10,minecraft:cracked_stone_bricks,10,minecraft:cobblestone,10,minecraft:mossy_cobblestone,10,minecraft:stone_bricks,100)
RB(7,6,5,minecraft:mossy_stone_bricks,10,minecraft:cracked_stone_bricks,10,minecraft:cobblestone,10,minecraft:mossy_cobblestone,10,minecraft:stone_bricks,100)
RB(0,6,6,minecraft:mossy_stone_bricks,10,minecraft:cracked_stone_bricks,10,minecraft:cobblestone,10,minecraft:mossy_cobblestone,10,minecraft:stone_bricks,100)
RB(1,6,6,minecraft:mossy_stone_bricks,10,minecraft:cracked_stone_bricks,10,minecraft:cobblestone,10,minecraft:mossy_cobblestone,10,minecraft:stone_bricks,100)
RB(2,6,6,minecraft:mossy_stone_bricks,10,minecraft:cracked_stone_bricks,10,minecraft:cobblestone,10,minecraft:mossy_cobblestone,10,minecraft:stone_bricks,100)
RB(3,6,6,minecraft:mossy_stone_bricks,10,minecraft:cracked_stone_bricks,10,minecraft:cobblestone,10,minecraft:mossy_cobblestone,10,minecraft:stone_bricks,100)
RB(4,6,6,minecraft:mossy_stone_bricks,10,minecraft:cracked_stone_bricks,10,minecraft:cobblestone,10,minecraft:mossy_cobblestone,10,minecraft:stone_bricks,100)
RB(5,6,6,minecraft:mossy_stone_bricks,10,minecraft:cracked_stone_bricks,10,minecraft:cobblestone,10,minecraft:mossy_cobblestone,10,minecraft:stone_bricks,100)
RB(6,6,6,minecraft:mossy_stone_bricks,10,minecraft:cracked_stone_bricks,10,minecraft:cobblestone,10,minecraft:mossy_cobblestone,10,minecraft:stone_bricks,100)
RB(7,6,6,minecraft:mossy_stone_bricks,10,minecraft:cracked_stone_bricks,10,minecraft:cobblestone,10,minecraft:mossy_cobblestone,10,minecraft:stone_bricks,100)
RB(0,6,7,minecraft:mossy_stone_bricks,10,minecraft:cracked_stone_bricks,10,minecraft:cobblestone,10,minecraft:mossy_cobblestone,10,minecraft:stone_bricks,100)
RB(1,6,7,minecraft:mossy_stone_bricks,10,minecraft:cracked_stone_bricks,10,minecraft:cobblestone,10,minecraft:mossy_cobblestone,10,minecraft:stone_bricks,100)
RB(2,6,7,minecraft:mossy_stone_bricks,10,minecraft:cracked_stone_bricks,10,minecraft:cobblestone,10,minecraft:mossy_cobblestone,10,minecraft:stone_bricks,100)
RB(3,6,7,minecraft:mossy_stone_bricks,10,minecraft:cracked_stone_bricks,10,minecraft:cobblestone,10,minecraft:mossy_cobblestone,10,minecraft:stone_bricks,100)
RB(4,6,7,minecraft:mossy_stone_bricks,10,minecraft:cracked_stone_bricks,10,minecraft:cobblestone,10,minecraft:mossy_cobblestone,10,minecraft:stone_bricks,100)
RB(5,6,7,minecraft:mossy_stone_bricks,10,minecraft:cracked_stone_bricks,10,minecraft:cobblestone,10,minecraft:mossy_cobblestone,10,minecraft:stone_bricks,100)
RB(6,6,7,minecraft:mossy_stone_bricks,10,minecraft:cracked_stone_bricks,10,minecraft:cobblestone,10,minecraft:mossy_cobblestone,10,minecraft:stone_bricks,100)
RB(7,6,7,minecraft:mossy_stone_bricks,10,minecraft:cracked_stone_bricks,10,minecraft:cobblestone,10,minecraft:mossy_cobblestone,10,minecraft:stone_bricks,100)
RB(1,7,0,minecraft:skeleton_skull,./StructureNBT/Skulls/dungeon_skull_01.nbt,6,minecraft:air,9,minecraft:skeleton_skull,./StructureNBT/Skulls/dungeon_skull_02.nbt,12,minecraft:air,15,minecraft:skeleton_skull,./StructureNBT/Skulls/dungeon_skull_03.nbt,18,minecraft:air,21,minecraft:skeleton_skull,./StructureNBT/Skulls/dungeon_skull_04.nbt,24,minecraft:air,27,minecraft:skeleton_skull,./StructureNBT/Skulls/dungeon_skull_05.nbt,30,minecraft:air,33,minecraft:skeleton_skull,./StructureNBT/Skulls/dungeon_skull_06.nbt,36,minecraft:air,39,minecraft:skeleton_skull,./StructureNBT/Skulls/dungeon_skull_07.nbt,42,minecraft:air,45,minecraft:skeleton_skull,./StructureNBT/Skulls/dungeon_skull_08.nbt,48,minecraft:air,51,minecraft:skeleton_skull,./StructureNBT/Skulls/dungeon_skull_09.nbt,54,minecraft:air,57,minecraft:skeleton_skull,./StructureNBT/Skulls/dungeon_skull_10.nbt,60,minecraft:air,63,minecraft:skeleton_skull,./StructureNBT/Skulls/dungeon_skull_11.nbt,66,minecraft:air,69,minecraft:skeleton_skull,./StructureNBT/Skulls/dungeon_skull_12.nbt,72,minecraft:air,75,minecraft:skeleton_skull,./StructureNBT/Skulls/dungeon_skull_13.nbt,78,minecraft:air,81,minecraft:skeleton_skull,./StructureNBT/Skulls/dungeon_skull_14.nbt,84,minecraft:air,87,minecraft:skeleton_skull,./StructureNBT/Skulls/dungeon_skull_15.nbt,90,minecraft:air,93,minecraft:skeleton_skull,./StructureNBT/Skulls/dungeon_skull_16.nbt,96,minecraft:air,100)
RB(4,7,0,minecraft:mossy_stone_bricks,10,minecraft:cracked_stone_bricks,10,minecraft:cobblestone,10,minecraft:mossy_cobblestone,10,minecraft:stone_bricks,100)
RB(5,7,0,minecraft:mossy_stone_bricks,10,minecraft:cracked_stone_bricks,10,minecraft:cobblestone,10,minecraft:mossy_cobblestone,10,minecraft:stone_bricks,100)
RB(6,7,0,minecraft:mossy_stone_bricks,10,minecraft:cracked_stone_bricks,10,minecraft:cobblestone,10,minecraft:mossy_cobblestone,10,minecraft:stone_bricks,100)
RB(7,7,0,minecraft:mossy_stone_bricks,10,minecraft:cracked_stone_bricks,10,minecraft:cobblestone,10,minecraft:mossy_cobblestone,10,minecraft:stone_bricks,100)
RB(4,7,1,minecraft:mossy_stone_bricks,10,minecraft:cracked_stone_bricks,10,minecraft:cobblestone,10,minecraft:mossy_cobblestone,10,minecraft:stone_bricks,100)
RB(5,7,1,minecraft:mossy_stone_bricks,10,minecraft:cracked_stone_bricks,10,minecraft:cobblestone,10,minecraft:mossy_cobblestone,10,minecraft:stone_bricks,100)
RB(6,7,1,minecraft:mossy_stone_bricks,10,minecraft:cracked_stone_bricks,10,minecraft:cobblestone,10,minecraft:mossy_cobblestone,10,minecraft:stone_bricks,100)
RB(7,7,1,minecraft:mossy_stone_bricks,10,minecraft:cracked_stone_bricks,10,minecraft:cobblestone,10,minecraft:mossy_cobblestone,10,minecraft:stone_bricks,100)
RB(1,7,2,minecraft:skeleton_skull,./StructureNBT/Skulls/dungeon_skull_01.nbt,6,minecraft:air,9,minecraft:skeleton_skull,./StructureNBT/Skulls/dungeon_skull_02.nbt,12,minecraft:air,15,minecraft:skeleton_skull,./StructureNBT/Skulls/dungeon_skull_03.nbt,18,minecraft:air,21,minecraft:skeleton_skull,./StructureNBT/Skulls/dungeon_skull_04.nbt,24,minecraft:air,27,minecraft:skeleton_skull,./StructureNBT/Skulls/dungeon_skull_05.nbt,30,minecraft:air,33,minecraft:skeleton_skull,./StructureNBT/Skulls/dungeon_skull_06.nbt,36,minecraft:air,39,minecraft:skeleton_skull,./StructureNBT/Skulls/dungeon_skull_07.nbt,42,minecraft:air,45,minecraft:skeleton_skull,./StructureNBT/Skulls/dungeon_skull_08.nbt,48,minecraft:air,51,minecraft:skeleton_skull,./StructureNBT/Skulls/dungeon_skull_09.nbt,54,minecraft:air,57,minecraft:skeleton_skull,./StructureNBT/Skulls/dungeon_skull_10.nbt,60,minecraft:air,63,minecraft:skeleton_skull,./StructureNBT/Skulls/dungeon_skull_11.nbt,66,minecraft:air,69,minecraft:skeleton_skull,./StructureNBT/Skulls/dungeon_skull_12.nbt,72,minecraft:air,75,minecraft:skeleton_skull,./StructureNBT/Skulls/dungeon_skull_13.nbt,78,minecraft:air,81,minecraft:skeleton_skull,./StructureNBT/Skulls/dungeon_skull_14.nbt,84,minecraft:air,87,minecraft:skeleton_skull,./StructureNBT/Skulls/dungeon_skull_15.nbt,90,minecraft:air,93,minecraft:skeleton_skull,./StructureNBT/Skulls/dungeon_skull_16.nbt,96,minecraft:air,100)
RB(4,7,2,minecraft:mossy_stone_bricks,10,minecraft:cracked_stone_bricks,10,minecraft:cobblestone,10,minecraft:mossy_cobblestone,10,minecraft:stone_bricks,100)
RB(5,7,2,minecraft:mossy_stone_bricks,10,minecraft:cracked_stone_bricks,10,minecraft:cobblestone,10,minecraft:mossy_cobblestone,10,minecraft:stone_bricks,100)
RB(6,7,2,minecraft:mossy_stone_bricks,10,minecraft:cracked_stone_bricks,10,minecraft:cobblestone,10,minecraft:mossy_cobblestone,10,minecraft:stone_bricks,100)
RB(7,7,2,minecraft:mossy_stone_bricks,10,minecraft:cracked_stone_bricks,10,minecraft:cobblestone,10,minecraft:mossy_cobblestone,10,minecraft:stone_bricks,100)
RB(2,7,3,minecraft:mossy_stone_bricks,10,minecraft:cracked_stone_bricks,10,minecraft:cobblestone,10,minecraft:mossy_cobblestone,10,minecraft:stone_bricks,100)
RB(3,7,3,minecraft:mossy_stone_bricks,10,minecraft:cracked_stone_bricks,10,minecraft:cobblestone,10,minecraft:mossy_cobblestone,10,minecraft:stone_bricks,100)
RB(4,7,3,minecraft:mossy_stone_bricks,10,minecraft:cracked_stone_bricks,10,minecraft:cobblestone,10,minecraft:mossy_cobblestone,10,minecraft:stone_bricks,100)
RB(5,7,3,minecraft:mossy_stone_bricks,10,minecraft:cracked_stone_bricks,10,minecraft:cobblestone,10,minecraft:mossy_cobblestone,10,minecraft:stone_bricks,100)
RB(6,7,3,minecraft:mossy_stone_bricks,10,minecraft:cracked_stone_bricks,10,minecraft:cobblestone,10,minecraft:mossy_cobblestone,10,minecraft:stone_bricks,100)
RB(7,7,3,minecraft:mossy_stone_bricks,10,minecraft:cracked_stone_bricks,10,minecraft:cobblestone,10,minecraft:mossy_cobblestone,10,minecraft:stone_bricks,100)
RB(2,7,4,minecraft:mossy_stone_bricks,10,minecraft:cracked_stone_bricks,10,minecraft:cobblestone,10,minecraft:mossy_cobblestone,10,minecraft:stone_bricks,100)
RB(3,7,4,minecraft:mossy_stone_bricks,10,minecraft:cracked_stone_bricks,10,minecraft:cobblestone,10,minecraft:mossy_cobblestone,10,minecraft:stone_bricks,100)
RB(4,7,4,minecraft:mossy_stone_bricks,10,minecraft:cracked_stone_bricks,10,minecraft:cobblestone,10,minecraft:mossy_cobblestone,10,minecraft:stone_bricks,100)
RB(5,7,4,minecraft:mossy_stone_bricks,10,minecraft:cracked_stone_bricks,10,minecraft:cobblestone,10,minecraft:mossy_cobblestone,10,minecraft:stone_bricks,100)
RB(6,7,4,minecraft:mossy_stone_bricks,10,minecraft:cracked_stone_bricks,10,minecraft:cobblestone,10,minecraft:mossy_cobblestone,10,minecraft:stone_bricks,100)
RB(7,7,4,minecraft:mossy_stone_bricks,10,minecraft:cracked_stone_bricks,10,minecraft:cobblestone,10,minecraft:mossy_cobblestone,10,minecraft:stone_bricks,100)
RB(0,7,5,minecraft:skeleton_skull,./StructureNBT/Skulls/dungeon_skull_01.nbt,6,minecraft:air,9,minecraft:skeleton_skull,./StructureNBT/Skulls/dungeon_skull_02.nbt,12,minecraft:air,15,minecraft:skeleton_skull,./StructureNBT/Skulls/dungeon_skull_03.nbt,18,minecraft:air,21,minecraft:skeleton_skull,./StructureNBT/Skulls/dungeon_skull_04.nbt,24,minecraft:air,27,minecraft:skeleton_skull,./StructureNBT/Skulls/dungeon_skull_05.nbt,30,minecraft:air,33,minecraft:skeleton_skull,./StructureNBT/Skulls/dungeon_skull_06.nbt,36,minecraft:air,39,minecraft:skeleton_skull,./StructureNBT/Skulls/dungeon_skull_07.nbt,42,minecraft:air,45,minecraft:skeleton_skull,./StructureNBT/Skulls/dungeon_skull_08.nbt,48,minecraft:air,51,minecraft:skeleton_skull,./StructureNBT/Skulls/dungeon_skull_09.nbt,54,minecraft:air,57,minecraft:skeleton_skull,./StructureNBT/Skulls/dungeon_skull_10.nbt,60,minecraft:air,63,minecraft:skeleton_skull,./StructureNBT/Skulls/dungeon_skull_11.nbt,66,minecraft:air,69,minecraft:skeleton_skull,./StructureNBT/Skulls/dungeon_skull_12.nbt,72,minecraft:air,75,minecraft:skeleton_skull,./StructureNBT/Skulls/dungeon_skull_13.nbt,78,minecraft:air,81,minecraft:skeleton_skull,./StructureNBT/Skulls/dungeon_skull_14.nbt,84,minecraft:air,87,minecraft:skeleton_skull,./StructureNBT/Skulls/dungeon_skull_15.nbt,90,minecraft:air,93,minecraft:skeleton_skull,./StructureNBT/Skulls/dungeon_skull_16.nbt,96,minecraft:air,100)
RB(2,7,5,minecraft:mossy_stone_bricks,10,minecraft:cracked_stone_bricks,10,minecraft:cobblestone,10,minecraft:mossy_cobblestone,10,minecraft:stone_bricks,100)
RB(3,7,5,minecraft:mossy_stone_bricks,10,minecraft:cracked_stone_bricks,10,minecraft:cobblestone,10,minecraft:mossy_cobblestone,10,minecraft:stone_bricks,100)
RB(4,7,5,minecraft:mossy_stone_bricks,10,minecraft:cracked_stone_bricks,10,minecraft:cobblestone,10,minecraft:mossy_cobblestone,10,minecraft:stone_bricks,100)
RB(5,7,5,minecraft:mossy_stone_bricks,10,minecraft:cracked_stone_bricks,10,minecraft:cobblestone,10,minecraft:mossy_cobblestone,10,minecraft:stone_bricks,100)
RB(6,7,5,minecraft:mossy_stone_bricks,10,minecraft:cracked_stone_bricks,10,minecraft:cobblestone,10,minecraft:mossy_cobblestone,10,minecraft:stone_bricks,100)
RB(7,7,5,minecraft:mossy_stone_bricks,10,minecraft:cracked_stone_bricks,10,minecraft:cobblestone,10,minecraft:mossy_cobblestone,10,minecraft:stone_bricks,100)
RB(0,7,6,minecraft:skeleton_skull,./StructureNBT/Skulls/dungeon_skull_01.nbt,6,minecraft:air,9,minecraft:skeleton_skull,./StructureNBT/Skulls/dungeon_skull_02.nbt,12,minecraft:air,15,minecraft:skeleton_skull,./StructureNBT/Skulls/dungeon_skull_03.nbt,18,minecraft:air,21,minecraft:skeleton_skull,./StructureNBT/Skulls/dungeon_skull_04.nbt,24,minecraft:air,27,minecraft:skeleton_skull,./StructureNBT/Skulls/dungeon_skull_05.nbt,30,minecraft:air,33,minecraft:skeleton_skull,./StructureNBT/Skulls/dungeon_skull_06.nbt,36,minecraft:air,39,minecraft:skeleton_skull,./StructureNBT/Skulls/dungeon_skull_07.nbt,42,minecraft:air,45,minecraft:skeleton_skull,./StructureNBT/Skulls/dungeon_skull_08.nbt,48,minecraft:air,51,minecraft:skeleton_skull,./StructureNBT/Skulls/dungeon_skull_09.nbt,54,minecraft:air,57,minecraft:skeleton_skull,./StructureNBT/Skulls/dungeon_skull_10.nbt,60,minecraft:air,63,minecraft:skeleton_skull,./StructureNBT/Skulls/dungeon_skull_11.nbt,66,minecraft:air,69,minecraft:skeleton_skull,./StructureNBT/Skulls/dungeon_skull_12.nbt,72,minecraft:air,75,minecraft:skeleton_skull,./StructureNBT/Skulls/dungeon_skull_13.nbt,78,minecraft:air,81,minecraft:skeleton_skull,./StructureNBT/Skulls/dungeon_skull_14.nbt,84,minecraft:air,87,minecraft:skeleton_skull,./StructureNBT/Skulls/dungeon_skull_15.nbt,90,minecraft:air,93,minecraft:skeleton_skull,./StructureNBT/Skulls/dungeon_skull_16.nbt,96,minecraft:air,100)
