
#######################################################################
# +-----------------------------------------------------------------+ #
# |                            BO3 object                           | #
# +-----------------------------------------------------------------+ #
#######################################################################

Author: Bo3 BulkEdit

Description: Converted Schematic - Modified by Bo3BulkEdit

Version: 3

SettingsMode: WriteWithoutComments


#######################################################################
# +-----------------------------------------------------------------+ #
# |                          Main settings                          | #
# +-----------------------------------------------------------------+ #
#######################################################################

Tree: false

Frequency: 1

Rarity: 100.0

RotateRandomly: false

SpawnHeight: randomY

SpawnHeightOffset: 0

SpawnHeightVariance: 0

##############################
# Height Limits for the BO3. #
##############################

MinHeight: 0

MaxHeight: 255

######################
# Extrusion settings #
######################

ExtrudeMode: None

ExtrudeThroughBlocks: minecraft:air

MaxBranchDepth: 10


#######################################################################
# +-----------------------------------------------------------------+ #
# |                      Source block settings                      | #
# +-----------------------------------------------------------------+ #
#######################################################################

SourceBlocks: otg:air

MaxPercentageOutsideSourceBlock: 100

OutsideSourceBlock: placeAnyway

DoReplaceBlocks: true

IsOTGPlus: false


#######################################################################
# +-----------------------------------------------------------------+ #
# |                              Blocks                             | #
# +-----------------------------------------------------------------+ #
#######################################################################

B(0,3,0,minecraft:polished_andesite)
B(0,17,0,minecraft:smooth_stone_slab[type=top,waterlogged=false])
B(0,18,0,minecraft:stone_slab)
B(0,25,0,minecraft:stone_brick_slab)
B(0,3,1,minecraft:polished_andesite)
B(0,18,1,minecraft:stone_slab)
B(0,24,1,minecraft:smooth_stone_slab[type=top,waterlogged=false])
B(0,17,2,minecraft:smooth_stone_slab[type=top,waterlogged=false])
B(0,18,2,minecraft:stone_slab)
B(0,24,2,minecraft:smooth_stone_slab[type=top,waterlogged=false])
B(0,3,3,minecraft:lapis_block)
B(0,17,3,minecraft:smooth_stone_slab[type=top,waterlogged=false])
B(0,18,3,minecraft:stone_slab)
B(0,24,3,minecraft:smooth_stone_slab[type=top,waterlogged=false])
B(0,3,4,minecraft:polished_andesite)
B(0,17,4,minecraft:stone_brick_stairs[facing=east,half=top,shape=straight,waterlogged=false])
B(0,18,4,minecraft:stone_slab)
B(0,24,4,minecraft:smooth_stone_slab[type=top,waterlogged=false])
B(0,12,5,minecraft:smooth_stone_slab[type=top,waterlogged=false])
B(0,14,5,minecraft:stone_brick_stairs)
B(0,15,5,minecraft:iron_bars)
B(0,16,5,minecraft:stone_brick_stairs[facing=north,half=top,shape=straight,waterlogged=false])
B(0,18,5,minecraft:stone_slab)
B(0,24,5,minecraft:smooth_stone_slab[type=top,waterlogged=false])
B(0,4,6,minecraft:stone_brick_stairs[facing=east,half=bottom,shape=straight,waterlogged=false])
B(0,12,6,minecraft:smooth_stone_slab[type=top,waterlogged=false])
B(0,18,6,minecraft:stone_slab)
B(0,24,6,minecraft:smooth_stone_slab[type=top,waterlogged=false])
B(0,26,6,minecraft:stone_slab)
B(0,4,7,minecraft:dark_oak_planks)
B(0,5,7,minecraft:dark_oak_planks)
B(0,6,7,minecraft:dark_oak_stairs[facing=east,half=bottom,shape=straight,waterlogged=false])
B(0,18,7,minecraft:stone_slab)
B(0,24,7,minecraft:smooth_stone_slab[type=top,waterlogged=false])
B(1,17,0,minecraft:stone_brick_stairs[facing=south,half=top,shape=straight,waterlogged=false])
B(1,18,0,minecraft:stone_slab)
B(1,18,1,minecraft:stone_brick_stairs[facing=south,half=bottom,shape=straight,waterlogged=false])
B(1,24,1,minecraft:smooth_stone_slab[type=top,waterlogged=false])
B(1,3,2,minecraft:lapis_block)
B(1,17,2,minecraft:smooth_stone_slab[type=top,waterlogged=false])
B(1,16,3,minecraft:stone_brick_stairs[facing=east,half=top,shape=straight,waterlogged=false])
B(1,24,3,minecraft:stone_brick_stairs[facing=east,half=top,shape=straight,waterlogged=false])
B(1,3,4,minecraft:polished_andesite)
B(1,15,4,minecraft:stone_brick_stairs[facing=east,half=top,shape=straight,waterlogged=false])
B(1,12,5,minecraft:smooth_stone_slab[type=top,waterlogged=false])
B(1,12,6,minecraft:smooth_stone_slab[type=top,waterlogged=false])
B(1,26,7,minecraft:stone_slab)
B(1,53,7,minecraft:stone_brick_stairs[facing=south,half=top,shape=straight,waterlogged=false])
B(1,55,7,minecraft:stone_brick_stairs[facing=south,half=bottom,shape=straight,waterlogged=false])
B(2,3,0,minecraft:lapis_block)
B(2,17,0,minecraft:smooth_stone_slab[type=top,waterlogged=false])
B(2,18,0,minecraft:stone_brick_stairs[facing=east,half=bottom,shape=straight,waterlogged=false])
B(2,3,1,minecraft:lapis_block)
B(2,24,1,minecraft:smooth_stone_slab[type=top,waterlogged=false])
B(2,17,2,minecraft:smooth_stone_slab[type=top,waterlogged=false])
B(2,19,2,minecraft:stone_brick_stairs[facing=south,half=bottom,shape=straight,waterlogged=false])
B(2,25,2,minecraft:stone_brick_slab)
B(2,3,3,minecraft:polished_andesite)
B(2,14,3,minecraft:stone_brick_stairs[facing=east,half=top,shape=straight,waterlogged=false])
B(2,20,3,minecraft:stone_brick_stairs[facing=east,half=bottom,shape=straight,waterlogged=false])
B(2,13,4,minecraft:stone_brick_stairs[facing=east,half=top,shape=straight,waterlogged=false])
B(2,12,5,minecraft:stone_brick_stairs[facing=south,half=top,shape=straight,waterlogged=false])
B(2,19,5,minecraft:stone_brick_stairs[facing=east,half=bottom,shape=straight,waterlogged=false])
B(2,7,6,minecraft:stone_brick_stairs[facing=south,half=bottom,shape=straight,waterlogged=false])
B(2,10,6,minecraft:stone_brick_stairs[facing=south,half=top,shape=straight,waterlogged=false])
B(2,16,6,minecraft:smooth_stone_slab[type=top,waterlogged=false])
B(2,7,7,minecraft:stone_brick_stairs[facing=north,half=top,shape=straight,waterlogged=false])
B(2,16,7,minecraft:smooth_stone_slab[type=top,waterlogged=false])
B(2,36,7,minecraft:smooth_stone_slab[type=top,waterlogged=false])
B(2,37,7,minecraft:cobblestone_wall[east=low,north=none,south=none,up=true,waterlogged=false,west=none])
B(2,38,7,minecraft:iron_bars)
B(2,39,7,minecraft:iron_bars)
B(2,40,7,minecraft:stone_brick_stairs[facing=east,half=bottom,shape=straight,waterlogged=false])
B(3,3,0,minecraft:polished_andesite)
B(3,17,0,minecraft:smooth_stone_slab[type=top,waterlogged=false])
B(3,3,1,minecraft:polished_andesite)
B(3,16,1,minecraft:stone_brick_stairs[facing=east,half=top,shape=straight,waterlogged=false])
B(3,24,1,minecraft:stone_brick_stairs[facing=east,half=top,shape=straight,waterlogged=false])
B(3,3,2,minecraft:polished_andesite)
B(3,15,2,minecraft:stone_brick_stairs[facing=south,half=top,shape=straight,waterlogged=false])
B(3,24,2,minecraft:stone_brick_slab)
B(3,11,3,minecraft:smooth_stone_slab[type=top,waterlogged=false])
B(3,12,3,minecraft:smooth_stone_slab[type=top,waterlogged=false])
B(3,21,3,minecraft:stone_slab)
B(3,23,3,minecraft:stone_brick_stairs[facing=east,half=top,shape=straight,waterlogged=false])
B(3,25,3,minecraft:stone_brick_slab)
B(3,11,4,minecraft:smooth_stone_slab[type=top,waterlogged=false])
B(3,12,4,minecraft:smooth_stone_slab[type=top,waterlogged=false])
B(3,11,5,minecraft:smooth_stone_slab[type=top,waterlogged=false])
B(3,12,5,minecraft:smooth_stone_slab[type=top,waterlogged=false])
B(3,20,5,minecraft:stone_brick_stairs[facing=east,half=bottom,shape=straight,waterlogged=false])
B(3,23,5,minecraft:stone_brick_stairs[facing=east,half=top,shape=straight,waterlogged=false])
B(3,36,5,minecraft:smooth_stone_slab[type=top,waterlogged=false])
B(3,37,5,minecraft:cobblestone_wall[east=low,north=none,south=low,up=true,waterlogged=false,west=none])
B(3,41,5,minecraft:stone_brick_stairs[facing=south,half=top,shape=straight,waterlogged=false])
B(3,42,5,minecraft:stone_slab)
B(3,36,6,minecraft:smooth_stone_slab[type=top,waterlogged=false])
B(3,37,6,minecraft:cobblestone_wall[east=none,north=low,south=low,up=false,waterlogged=false,west=none])
B(3,40,6,minecraft:stone_brick_stairs[facing=south,half=top,shape=straight,waterlogged=false])
B(3,42,6,minecraft:stone_slab)
B(3,11,7,minecraft:stone_brick_stairs[facing=north,half=top,shape=straight,waterlogged=false])
B(3,36,7,minecraft:smooth_stone_slab[type=top,waterlogged=false])
B(3,37,7,minecraft:cobblestone_wall[east=none,north=low,south=none,up=true,waterlogged=false,west=low])
B(4,17,0,minecraft:stone_brick_stairs[facing=south,half=top,shape=straight,waterlogged=false])
B(4,23,0,minecraft:stone_brick_stairs[facing=east,half=top,shape=straight,waterlogged=false])
B(4,14,1,minecraft:stone_brick_stairs[facing=east,half=top,shape=straight,waterlogged=false])
B(4,20,1,minecraft:stone_brick_stairs[facing=east,half=bottom,shape=straight,waterlogged=false])
B(4,23,2,minecraft:stone_brick_stairs[facing=south,half=top,shape=straight,waterlogged=false])
B(4,11,3,minecraft:smooth_stone_slab[type=top,waterlogged=false])
B(4,12,3,minecraft:smooth_stone_slab[type=top,waterlogged=false])
B(4,21,3,minecraft:stone_brick_stairs[facing=east,half=bottom,shape=straight,waterlogged=false])
B(4,22,3,minecraft:stone_brick_stairs[facing=east,half=top,shape=straight,waterlogged=false])
B(4,25,4,minecraft:stone_brick_slab)
B(4,36,4,minecraft:smooth_stone_slab[type=top,waterlogged=false])
B(4,37,4,minecraft:cobblestone_wall[east=low,north=none,south=low,up=true,waterlogged=false,west=none])
B(4,38,4,minecraft:iron_bars)
B(4,39,4,minecraft:iron_bars)
B(4,40,4,minecraft:iron_bars)
B(4,41,4,minecraft:iron_bars)
B(4,43,4,minecraft:stone_slab)
B(4,19,5,minecraft:stone_slab)
B(4,36,5,minecraft:smooth_stone_slab[type=top,waterlogged=false])
B(4,37,5,minecraft:cobblestone_wall[east=none,north=low,south=none,up=true,waterlogged=false,west=low])
B(4,41,5,minecraft:stone_brick_stairs[facing=west,half=top,shape=outer_left,waterlogged=false])
B(4,42,5,minecraft:stone_brick_stairs)
B(4,7,6,minecraft:stone_brick_stairs[facing=south,half=bottom,shape=straight,waterlogged=false])
B(4,10,6,minecraft:stone_brick_stairs[facing=south,half=top,shape=straight,waterlogged=false])
B(4,23,6,minecraft:stone_brick_stairs[facing=north,half=top,shape=straight,waterlogged=false])
B(4,36,6,minecraft:stone_slab)
B(4,44,6,minecraft:stone_slab)
B(4,7,7,minecraft:stone_brick_stairs[facing=north,half=top,shape=straight,waterlogged=false])
B(4,23,7,minecraft:stone_brick_stairs[facing=south,half=top,shape=straight,waterlogged=false])
B(4,36,7,minecraft:stone_slab)
B(4,43,7,minecraft:stone_brick_stairs[facing=east,half=bottom,shape=straight,waterlogged=false])
B(5,12,0,minecraft:smooth_stone_slab[type=top,waterlogged=false])
B(5,15,0,minecraft:stone_brick_stairs[facing=south,half=top,shape=straight,waterlogged=false])
B(5,22,0,minecraft:stone_brick_stairs[facing=south,half=top,shape=straight,waterlogged=false])
B(5,12,1,minecraft:smooth_stone_slab[type=top,waterlogged=false])
B(5,12,2,minecraft:stone_brick_stairs[facing=east,half=top,shape=straight,waterlogged=false])
B(5,11,3,minecraft:smooth_stone_slab[type=top,waterlogged=false])
B(5,12,3,minecraft:smooth_stone_slab[type=top,waterlogged=false])
B(5,36,3,minecraft:smooth_stone_slab[type=top,waterlogged=false])
B(5,37,3,minecraft:cobblestone_wall[east=low,north=none,south=low,up=true,waterlogged=false,west=none])
B(5,41,3,minecraft:stone_brick_stairs[facing=east,half=top,shape=straight,waterlogged=false])
B(5,42,3,minecraft:stone_slab)
B(5,36,4,minecraft:smooth_stone_slab[type=top,waterlogged=false])
B(5,37,4,minecraft:cobblestone_wall[east=none,north=low,south=none,up=true,waterlogged=false,west=low])
B(5,41,4,minecraft:stone_brick_stairs[facing=north,half=top,shape=outer_right,waterlogged=false])
B(5,42,4,minecraft:stone_brick_stairs[facing=west,half=bottom,shape=straight,waterlogged=false])
B(5,11,5,minecraft:stone_brick_stairs[facing=west,half=top,shape=inner_right,waterlogged=false])
B(5,14,5,minecraft:stone_brick_stairs[facing=west,half=bottom,shape=straight,waterlogged=false])
B(5,16,5,minecraft:stone_brick_stairs[facing=west,half=top,shape=straight,waterlogged=false])
B(5,20,5,minecraft:stone_brick_stairs[facing=west,half=bottom,shape=straight,waterlogged=false])
B(5,22,5,minecraft:stone_brick_stairs[facing=west,half=top,shape=straight,waterlogged=false])
B(5,25,5,minecraft:stone_brick_slab)
B(5,36,5,minecraft:stone_slab)
B(5,41,5,minecraft:smooth_stone_slab[type=top,waterlogged=false])
B(5,45,5,minecraft:stone_slab)
B(5,11,6,minecraft:stone_brick_stairs[facing=west,half=top,shape=straight,waterlogged=false])
B(5,35,6,minecraft:smooth_stone_slab[type=top,waterlogged=false])
B(5,36,6,minecraft:stone_slab)
B(5,44,6,minecraft:stone_brick_stairs[facing=east,half=bottom,shape=straight,waterlogged=false])
B(5,11,7,minecraft:stone_brick_stairs[facing=west,half=top,shape=straight,waterlogged=false])
B(5,35,7,minecraft:smooth_stone_slab[type=top,waterlogged=false])
B(5,36,7,minecraft:stone_slab)
B(5,45,7,minecraft:stone_brick_stairs[facing=east,half=bottom,shape=straight,waterlogged=false])
B(6,4,0,minecraft:stone_brick_stairs[facing=south,half=bottom,shape=straight,waterlogged=false])
B(6,12,0,minecraft:smooth_stone_slab[type=top,waterlogged=false])
B(6,14,0,minecraft:iron_bars)
B(6,15,0,minecraft:iron_bars)
B(6,17,0,minecraft:stone_brick_stairs[facing=west,half=bottom,shape=straight,waterlogged=false])
B(6,22,0,minecraft:iron_bars)
B(6,23,0,minecraft:iron_bars)
B(6,24,0,minecraft:iron_bars)
B(6,26,0,minecraft:stone_slab)
B(6,12,1,minecraft:smooth_stone_slab[type=top,waterlogged=false])
B(6,7,2,minecraft:stone_brick_stairs[facing=east,half=bottom,shape=straight,waterlogged=false])
B(6,10,2,minecraft:stone_brick_stairs[facing=east,half=top,shape=straight,waterlogged=false])
B(6,23,2,minecraft:lava)
B(6,36,3,minecraft:smooth_stone_slab[type=top,waterlogged=false])
B(6,37,3,minecraft:cobblestone_wall[east=low,north=none,south=none,up=false,waterlogged=false,west=low])
B(6,40,3,minecraft:stone_brick_stairs[facing=east,half=top,shape=straight,waterlogged=false])
B(6,42,3,minecraft:stone_slab)
B(6,7,4,minecraft:stone_brick_stairs[facing=east,half=bottom,shape=straight,waterlogged=false])
B(6,10,4,minecraft:stone_brick_stairs[facing=east,half=top,shape=straight,waterlogged=false])
B(6,36,4,minecraft:stone_slab)
B(6,44,4,minecraft:stone_slab)
B(6,11,5,minecraft:stone_brick_stairs[facing=north,half=top,shape=straight,waterlogged=false])
B(6,35,5,minecraft:smooth_stone_slab[type=top,waterlogged=false])
B(6,36,5,minecraft:stone_slab)
B(6,44,5,minecraft:stone_brick_stairs[facing=south,half=bottom,shape=straight,waterlogged=false])
B(6,45,5,minecraft:jungle_leaves[distance=7,persistent=true])
B(6,46,5,minecraft:jungle_leaves[distance=7,persistent=true])
B(6,47,5,minecraft:jungle_leaves[distance=7,persistent=true])
B(6,12,6,minecraft:smooth_stone_slab[type=top,waterlogged=false])
B(6,25,6,minecraft:stone_brick_slab)
B(6,35,6,minecraft:smooth_stone_slab[type=top,waterlogged=false])
B(6,36,6,minecraft:stone_slab)
B(6,47,6,minecraft:stone_slab)
B(6,12,7,minecraft:smooth_stone_slab[type=top,waterlogged=false])
B(6,35,7,minecraft:smooth_stone_slab[type=top,waterlogged=false])
B(6,36,7,minecraft:stone_slab)
B(6,46,7,minecraft:stone_brick_stairs[facing=east,half=bottom,shape=straight,waterlogged=false])
B(7,4,0,minecraft:dark_oak_planks)
B(7,5,0,minecraft:dark_oak_planks)
B(7,6,0,minecraft:dark_oak_stairs[facing=south,half=bottom,shape=straight,waterlogged=false])
B(7,22,0,minecraft:stone_brick_stairs[facing=south,half=top,shape=straight,waterlogged=false])
B(7,15,1,minecraft:stone_brick_stairs[facing=west,half=bottom,shape=straight,waterlogged=false])
B(7,21,1,minecraft:stone_brick_stairs[facing=west,half=top,shape=straight,waterlogged=false])
B(7,26,1,minecraft:stone_slab)
B(7,33,1,minecraft:jungle_leaves[distance=7,persistent=true])
B(7,34,1,minecraft:jungle_leaves[distance=7,persistent=true])
B(7,35,1,minecraft:jungle_leaves[distance=7,persistent=true])
B(7,36,1,minecraft:jungle_leaves[distance=7,persistent=true])
B(7,37,1,minecraft:jungle_leaves[distance=7,persistent=true])
B(7,38,1,minecraft:jungle_leaves[distance=7,persistent=true])
B(7,39,1,minecraft:jungle_leaves[distance=7,persistent=true])
B(7,40,1,minecraft:jungle_leaves[distance=7,persistent=true])
B(7,41,1,minecraft:jungle_leaves[distance=7,persistent=true])
B(7,53,1,minecraft:stone_brick_stairs[facing=east,half=top,shape=straight,waterlogged=false])
B(7,55,1,minecraft:stone_brick_stairs[facing=east,half=bottom,shape=straight,waterlogged=false])
B(7,7,2,minecraft:stone_brick_stairs[facing=west,half=top,shape=straight,waterlogged=false])
B(7,15,2,minecraft:cobblestone_wall)
B(7,16,2,minecraft:cobblestone_wall)
B(7,17,2,minecraft:cobblestone_wall)
B(7,18,2,minecraft:cobblestone_wall)
B(7,19,2,minecraft:cobblestone_wall)
B(7,20,2,minecraft:cobblestone_wall)
B(7,21,2,minecraft:cobblestone_wall)
B(7,22,2,minecraft:cobblestone_wall)
B(7,36,2,minecraft:smooth_stone_slab[type=top,waterlogged=false])
B(7,37,2,minecraft:cobblestone_wall[east=none,north=none,south=low,up=true,waterlogged=false,west=none])
B(7,38,2,minecraft:iron_bars)
B(7,39,2,minecraft:iron_bars)
B(7,40,2,minecraft:stone_brick_stairs[facing=south,half=bottom,shape=straight,waterlogged=false])
B(7,41,2,minecraft:jungle_leaves[distance=7,persistent=true])
B(7,11,3,minecraft:stone_brick_stairs[facing=west,half=top,shape=straight,waterlogged=false])
B(7,15,3,minecraft:stone_brick_stairs[facing=west,half=bottom,shape=straight,waterlogged=false])
B(7,21,3,minecraft:stone_brick_stairs[facing=west,half=top,shape=straight,waterlogged=false])
B(7,36,3,minecraft:smooth_stone_slab[type=top,waterlogged=false])
B(7,37,3,minecraft:cobblestone_wall[east=none,north=low,south=none,up=true,waterlogged=false,west=low])
B(7,7,4,minecraft:stone_brick_stairs[facing=west,half=top,shape=straight,waterlogged=false])
B(7,36,4,minecraft:stone_slab)
B(7,43,4,minecraft:stone_brick_stairs[facing=south,half=bottom,shape=straight,waterlogged=false])
B(7,44,4,minecraft:jungle_leaves[distance=7,persistent=true])
B(7,45,4,minecraft:jungle_leaves[distance=7,persistent=true])
B(7,11,5,minecraft:stone_brick_stairs[facing=north,half=top,shape=straight,waterlogged=false])
B(7,23,5,minecraft:stone_brick_stairs[facing=west,half=top,shape=straight,waterlogged=false])
B(7,35,5,minecraft:smooth_stone_slab[type=top,waterlogged=false])
B(7,36,5,minecraft:stone_slab)
B(7,45,5,minecraft:stone_brick_stairs[facing=south,half=bottom,shape=straight,waterlogged=false])
B(7,46,5,minecraft:jungle_leaves[distance=7,persistent=true])
B(7,12,6,minecraft:smooth_stone_slab[type=top,waterlogged=false])
B(7,35,6,minecraft:smooth_stone_slab[type=top,waterlogged=false])
B(7,36,6,minecraft:stone_slab)
B(7,46,6,minecraft:stone_brick_stairs[facing=south,half=bottom,shape=straight,waterlogged=false])
B(7,47,6,minecraft:jungle_leaves[distance=7,persistent=true])
B(7,48,6,minecraft:jungle_leaves[distance=7,persistent=true])
B(7,49,6,minecraft:jungle_leaves[distance=7,persistent=true])
B(7,12,7,minecraft:smooth_stone_slab[type=top,waterlogged=false])
B(7,26,7,minecraft:stone_brick_slab[type=double,waterlogged=false])
B(7,36,7,minecraft:stone_slab)
RB(0,0,0,minecraft:mossy_stone_bricks,10,minecraft:cracked_stone_bricks,10,minecraft:cobblestone,10,minecraft:mossy_cobblestone,10,minecraft:stone_bricks,100)
RB(1,0,0,minecraft:mossy_stone_bricks,10,minecraft:cracked_stone_bricks,10,minecraft:cobblestone,10,minecraft:mossy_cobblestone,10,minecraft:stone_bricks,100)
RB(2,0,0,minecraft:mossy_stone_bricks,10,minecraft:cracked_stone_bricks,10,minecraft:cobblestone,10,minecraft:mossy_cobblestone,10,minecraft:stone_bricks,100)
RB(3,0,0,minecraft:mossy_stone_bricks,10,minecraft:cracked_stone_bricks,10,minecraft:cobblestone,10,minecraft:mossy_cobblestone,10,minecraft:stone_bricks,100)
RB(4,0,0,minecraft:mossy_stone_bricks,10,minecraft:cracked_stone_bricks,10,minecraft:cobblestone,10,minecraft:mossy_cobblestone,10,minecraft:stone_bricks,100)
RB(5,0,0,minecraft:mossy_stone_bricks,10,minecraft:cracked_stone_bricks,10,minecraft:cobblestone,10,minecraft:mossy_cobblestone,10,minecraft:stone_bricks,100)
RB(6,0,0,minecraft:mossy_stone_bricks,10,minecraft:cracked_stone_bricks,10,minecraft:cobblestone,10,minecraft:mossy_cobblestone,10,minecraft:stone_bricks,100)
RB(7,0,0,minecraft:mossy_stone_bricks,10,minecraft:cracked_stone_bricks,10,minecraft:cobblestone,10,minecraft:mossy_cobblestone,10,minecraft:stone_bricks,100)
RB(0,0,1,minecraft:mossy_stone_bricks,10,minecraft:cracked_stone_bricks,10,minecraft:cobblestone,10,minecraft:mossy_cobblestone,10,minecraft:stone_bricks,100)
RB(1,0,1,minecraft:mossy_stone_bricks,10,minecraft:cracked_stone_bricks,10,minecraft:cobblestone,10,minecraft:mossy_cobblestone,10,minecraft:stone_bricks,100)
RB(2,0,1,minecraft:mossy_stone_bricks,10,minecraft:cracked_stone_bricks,10,minecraft:cobblestone,10,minecraft:mossy_cobblestone,10,minecraft:stone_bricks,100)
RB(3,0,1,minecraft:mossy_stone_bricks,10,minecraft:cracked_stone_bricks,10,minecraft:cobblestone,10,minecraft:mossy_cobblestone,10,minecraft:stone_bricks,100)
RB(4,0,1,minecraft:mossy_stone_bricks,10,minecraft:cracked_stone_bricks,10,minecraft:cobblestone,10,minecraft:mossy_cobblestone,10,minecraft:stone_bricks,100)
RB(5,0,1,minecraft:mossy_stone_bricks,10,minecraft:cracked_stone_bricks,10,minecraft:cobblestone,10,minecraft:mossy_cobblestone,10,minecraft:stone_bricks,100)
RB(6,0,1,minecraft:mossy_stone_bricks,10,minecraft:cracked_stone_bricks,10,minecraft:cobblestone,10,minecraft:mossy_cobblestone,10,minecraft:stone_bricks,100)
RB(7,0,1,minecraft:mossy_stone_bricks,10,minecraft:cracked_stone_bricks,10,minecraft:cobblestone,10,minecraft:mossy_cobblestone,10,minecraft:stone_bricks,100)
RB(0,0,2,minecraft:mossy_stone_bricks,10,minecraft:cracked_stone_bricks,10,minecraft:cobblestone,10,minecraft:mossy_cobblestone,10,minecraft:stone_bricks,100)
RB(1,0,2,minecraft:mossy_stone_bricks,10,minecraft:cracked_stone_bricks,10,minecraft:cobblestone,10,minecraft:mossy_cobblestone,10,minecraft:stone_bricks,100)
RB(2,0,2,minecraft:mossy_stone_bricks,10,minecraft:cracked_stone_bricks,10,minecraft:cobblestone,10,minecraft:mossy_cobblestone,10,minecraft:stone_bricks,100)
RB(3,0,2,minecraft:mossy_stone_bricks,10,minecraft:cracked_stone_bricks,10,minecraft:cobblestone,10,minecraft:mossy_cobblestone,10,minecraft:stone_bricks,100)
RB(4,0,2,minecraft:mossy_stone_bricks,10,minecraft:cracked_stone_bricks,10,minecraft:cobblestone,10,minecraft:mossy_cobblestone,10,minecraft:stone_bricks,100)
RB(5,0,2,minecraft:mossy_stone_bricks,10,minecraft:cracked_stone_bricks,10,minecraft:cobblestone,10,minecraft:mossy_cobblestone,10,minecraft:stone_bricks,100)
RB(6,0,2,minecraft:mossy_stone_bricks,10,minecraft:cracked_stone_bricks,10,minecraft:cobblestone,10,minecraft:mossy_cobblestone,10,minecraft:stone_bricks,100)
RB(7,0,2,minecraft:mossy_stone_bricks,10,minecraft:cracked_stone_bricks,10,minecraft:cobblestone,10,minecraft:mossy_cobblestone,10,minecraft:stone_bricks,100)
RB(0,0,3,minecraft:mossy_stone_bricks,10,minecraft:cracked_stone_bricks,10,minecraft:cobblestone,10,minecraft:mossy_cobblestone,10,minecraft:stone_bricks,100)
RB(1,0,3,minecraft:mossy_stone_bricks,10,minecraft:cracked_stone_bricks,10,minecraft:cobblestone,10,minecraft:mossy_cobblestone,10,minecraft:stone_bricks,100)
RB(2,0,3,minecraft:mossy_stone_bricks,10,minecraft:cracked_stone_bricks,10,minecraft:cobblestone,10,minecraft:mossy_cobblestone,10,minecraft:stone_bricks,100)
RB(3,0,3,minecraft:mossy_stone_bricks,10,minecraft:cracked_stone_bricks,10,minecraft:cobblestone,10,minecraft:mossy_cobblestone,10,minecraft:stone_bricks,100)
RB(4,0,3,minecraft:mossy_stone_bricks,10,minecraft:cracked_stone_bricks,10,minecraft:cobblestone,10,minecraft:mossy_cobblestone,10,minecraft:stone_bricks,100)
RB(5,0,3,minecraft:mossy_stone_bricks,10,minecraft:cracked_stone_bricks,10,minecraft:cobblestone,10,minecraft:mossy_cobblestone,10,minecraft:stone_bricks,100)
RB(6,0,3,minecraft:mossy_stone_bricks,10,minecraft:cracked_stone_bricks,10,minecraft:cobblestone,10,minecraft:mossy_cobblestone,10,minecraft:stone_bricks,100)
RB(7,0,3,minecraft:mossy_stone_bricks,10,minecraft:cracked_stone_bricks,10,minecraft:cobblestone,10,minecraft:mossy_cobblestone,10,minecraft:stone_bricks,100)
RB(0,0,4,minecraft:mossy_stone_bricks,10,minecraft:cracked_stone_bricks,10,minecraft:cobblestone,10,minecraft:mossy_cobblestone,10,minecraft:stone_bricks,100)
RB(1,0,4,minecraft:mossy_stone_bricks,10,minecraft:cracked_stone_bricks,10,minecraft:cobblestone,10,minecraft:mossy_cobblestone,10,minecraft:stone_bricks,100)
RB(2,0,4,minecraft:mossy_stone_bricks,10,minecraft:cracked_stone_bricks,10,minecraft:cobblestone,10,minecraft:mossy_cobblestone,10,minecraft:stone_bricks,100)
RB(3,0,4,minecraft:mossy_stone_bricks,10,minecraft:cracked_stone_bricks,10,minecraft:cobblestone,10,minecraft:mossy_cobblestone,10,minecraft:stone_bricks,100)
RB(4,0,4,minecraft:mossy_stone_bricks,10,minecraft:cracked_stone_bricks,10,minecraft:cobblestone,10,minecraft:mossy_cobblestone,10,minecraft:stone_bricks,100)
RB(5,0,4,minecraft:mossy_stone_bricks,10,minecraft:cracked_stone_bricks,10,minecraft:cobblestone,10,minecraft:mossy_cobblestone,10,minecraft:stone_bricks,100)
RB(6,0,4,minecraft:mossy_stone_bricks,10,minecraft:cracked_stone_bricks,10,minecraft:cobblestone,10,minecraft:mossy_cobblestone,10,minecraft:stone_bricks,100)
RB(7,0,4,minecraft:mossy_stone_bricks,10,minecraft:cracked_stone_bricks,10,minecraft:cobblestone,10,minecraft:mossy_cobblestone,10,minecraft:stone_bricks,100)
RB(0,0,5,minecraft:mossy_stone_bricks,10,minecraft:cracked_stone_bricks,10,minecraft:cobblestone,10,minecraft:mossy_cobblestone,10,minecraft:stone_bricks,100)
RB(1,0,5,minecraft:mossy_stone_bricks,10,minecraft:cracked_stone_bricks,10,minecraft:cobblestone,10,minecraft:mossy_cobblestone,10,minecraft:stone_bricks,100)
RB(2,0,5,minecraft:mossy_stone_bricks,10,minecraft:cracked_stone_bricks,10,minecraft:cobblestone,10,minecraft:mossy_cobblestone,10,minecraft:stone_bricks,100)
RB(3,0,5,minecraft:mossy_stone_bricks,10,minecraft:cracked_stone_bricks,10,minecraft:cobblestone,10,minecraft:mossy_cobblestone,10,minecraft:stone_bricks,100)
RB(4,0,5,minecraft:mossy_stone_bricks,10,minecraft:cracked_stone_bricks,10,minecraft:cobblestone,10,minecraft:mossy_cobblestone,10,minecraft:stone_bricks,100)
RB(6,0,5,minecraft:mossy_stone_bricks,10,minecraft:cracked_stone_bricks,10,minecraft:cobblestone,10,minecraft:mossy_cobblestone,10,minecraft:stone_bricks,100)
RB(7,0,5,minecraft:mossy_stone_bricks,10,minecraft:cracked_stone_bricks,10,minecraft:cobblestone,10,minecraft:mossy_cobblestone,10,minecraft:stone_bricks,100)
RB(0,0,6,minecraft:mossy_stone_bricks,10,minecraft:cracked_stone_bricks,10,minecraft:cobblestone,10,minecraft:mossy_cobblestone,10,minecraft:stone_bricks,100)
RB(1,0,6,minecraft:mossy_stone_bricks,10,minecraft:cracked_stone_bricks,10,minecraft:cobblestone,10,minecraft:mossy_cobblestone,10,minecraft:stone_bricks,100)
RB(2,0,6,minecraft:mossy_stone_bricks,10,minecraft:cracked_stone_bricks,10,minecraft:cobblestone,10,minecraft:mossy_cobblestone,10,minecraft:stone_bricks,100)
RB(3,0,6,minecraft:mossy_stone_bricks,10,minecraft:cracked_stone_bricks,10,minecraft:cobblestone,10,minecraft:mossy_cobblestone,10,minecraft:stone_bricks,100)
RB(4,0,6,minecraft:mossy_stone_bricks,10,minecraft:cracked_stone_bricks,10,minecraft:cobblestone,10,minecraft:mossy_cobblestone,10,minecraft:stone_bricks,100)
RB(5,0,6,minecraft:mossy_stone_bricks,10,minecraft:cracked_stone_bricks,10,minecraft:cobblestone,10,minecraft:mossy_cobblestone,10,minecraft:stone_bricks,100)
RB(6,0,6,minecraft:mossy_stone_bricks,10,minecraft:cracked_stone_bricks,10,minecraft:cobblestone,10,minecraft:mossy_cobblestone,10,minecraft:stone_bricks,100)
RB(7,0,6,minecraft:mossy_stone_bricks,10,minecraft:cracked_stone_bricks,10,minecraft:cobblestone,10,minecraft:mossy_cobblestone,10,minecraft:stone_bricks,100)
RB(0,0,7,minecraft:mossy_stone_bricks,10,minecraft:cracked_stone_bricks,10,minecraft:cobblestone,10,minecraft:mossy_cobblestone,10,minecraft:stone_bricks,100)
RB(1,0,7,minecraft:mossy_stone_bricks,10,minecraft:cracked_stone_bricks,10,minecraft:cobblestone,10,minecraft:mossy_cobblestone,10,minecraft:stone_bricks,100)
RB(2,0,7,minecraft:mossy_stone_bricks,10,minecraft:cracked_stone_bricks,10,minecraft:cobblestone,10,minecraft:mossy_cobblestone,10,minecraft:stone_bricks,100)
RB(3,0,7,minecraft:mossy_stone_bricks,10,minecraft:cracked_stone_bricks,10,minecraft:cobblestone,10,minecraft:mossy_cobblestone,10,minecraft:stone_bricks,100)
RB(4,0,7,minecraft:mossy_stone_bricks,10,minecraft:cracked_stone_bricks,10,minecraft:cobblestone,10,minecraft:mossy_cobblestone,10,minecraft:stone_bricks,100)
RB(5,0,7,minecraft:mossy_stone_bricks,10,minecraft:cracked_stone_bricks,10,minecraft:cobblestone,10,minecraft:mossy_cobblestone,10,minecraft:stone_bricks,100)
RB(6,0,7,minecraft:mossy_stone_bricks,10,minecraft:cracked_stone_bricks,10,minecraft:cobblestone,10,minecraft:mossy_cobblestone,10,minecraft:stone_bricks,100)
RB(7,0,7,minecraft:mossy_stone_bricks,10,minecraft:cracked_stone_bricks,10,minecraft:cobblestone,10,minecraft:mossy_cobblestone,10,minecraft:stone_bricks,100)
RB(0,1,0,minecraft:mossy_stone_bricks,10,minecraft:cracked_stone_bricks,10,minecraft:cobblestone,10,minecraft:mossy_cobblestone,10,minecraft:stone_bricks,100)
RB(1,1,0,minecraft:mossy_stone_bricks,10,minecraft:cracked_stone_bricks,10,minecraft:cobblestone,10,minecraft:mossy_cobblestone,10,minecraft:stone_bricks,100)
RB(2,1,0,minecraft:mossy_stone_bricks,10,minecraft:cracked_stone_bricks,10,minecraft:cobblestone,10,minecraft:mossy_cobblestone,10,minecraft:stone_bricks,100)
RB(3,1,0,minecraft:mossy_stone_bricks,10,minecraft:cracked_stone_bricks,10,minecraft:cobblestone,10,minecraft:mossy_cobblestone,10,minecraft:stone_bricks,100)
RB(4,1,0,minecraft:mossy_stone_bricks,10,minecraft:cracked_stone_bricks,10,minecraft:cobblestone,10,minecraft:mossy_cobblestone,10,minecraft:stone_bricks,100)
RB(5,1,0,minecraft:mossy_stone_bricks,10,minecraft:cracked_stone_bricks,10,minecraft:cobblestone,10,minecraft:mossy_cobblestone,10,minecraft:stone_bricks,100)
RB(6,1,0,minecraft:mossy_stone_bricks,10,minecraft:cracked_stone_bricks,10,minecraft:cobblestone,10,minecraft:mossy_cobblestone,10,minecraft:stone_bricks,100)
RB(7,1,0,minecraft:mossy_stone_bricks,10,minecraft:cracked_stone_bricks,10,minecraft:cobblestone,10,minecraft:mossy_cobblestone,10,minecraft:stone_bricks,100)
RB(0,1,1,minecraft:mossy_stone_bricks,10,minecraft:cracked_stone_bricks,10,minecraft:cobblestone,10,minecraft:mossy_cobblestone,10,minecraft:stone_bricks,100)
RB(1,1,1,minecraft:mossy_stone_bricks,10,minecraft:cracked_stone_bricks,10,minecraft:cobblestone,10,minecraft:mossy_cobblestone,10,minecraft:stone_bricks,100)
RB(2,1,1,minecraft:mossy_stone_bricks,10,minecraft:cracked_stone_bricks,10,minecraft:cobblestone,10,minecraft:mossy_cobblestone,10,minecraft:stone_bricks,100)
RB(3,1,1,minecraft:mossy_stone_bricks,10,minecraft:cracked_stone_bricks,10,minecraft:cobblestone,10,minecraft:mossy_cobblestone,10,minecraft:stone_bricks,100)
RB(4,1,1,minecraft:mossy_stone_bricks,10,minecraft:cracked_stone_bricks,10,minecraft:cobblestone,10,minecraft:mossy_cobblestone,10,minecraft:stone_bricks,100)
RB(5,1,1,minecraft:mossy_stone_bricks,10,minecraft:cracked_stone_bricks,10,minecraft:cobblestone,10,minecraft:mossy_cobblestone,10,minecraft:stone_bricks,100)
RB(6,1,1,minecraft:mossy_stone_bricks,10,minecraft:cracked_stone_bricks,10,minecraft:cobblestone,10,minecraft:mossy_cobblestone,10,minecraft:stone_bricks,100)
RB(7,1,1,minecraft:mossy_stone_bricks,10,minecraft:cracked_stone_bricks,10,minecraft:cobblestone,10,minecraft:mossy_cobblestone,10,minecraft:stone_bricks,100)
RB(0,1,2,minecraft:mossy_stone_bricks,10,minecraft:cracked_stone_bricks,10,minecraft:cobblestone,10,minecraft:mossy_cobblestone,10,minecraft:stone_bricks,100)
RB(1,1,2,minecraft:mossy_stone_bricks,10,minecraft:cracked_stone_bricks,10,minecraft:cobblestone,10,minecraft:mossy_cobblestone,10,minecraft:stone_bricks,100)
RB(2,1,2,minecraft:mossy_stone_bricks,10,minecraft:cracked_stone_bricks,10,minecraft:cobblestone,10,minecraft:mossy_cobblestone,10,minecraft:stone_bricks,100)
RB(3,1,2,minecraft:mossy_stone_bricks,10,minecraft:cracked_stone_bricks,10,minecraft:cobblestone,10,minecraft:mossy_cobblestone,10,minecraft:stone_bricks,100)
RB(4,1,2,minecraft:mossy_stone_bricks,10,minecraft:cracked_stone_bricks,10,minecraft:cobblestone,10,minecraft:mossy_cobblestone,10,minecraft:stone_bricks,100)
RB(5,1,2,minecraft:mossy_stone_bricks,10,minecraft:cracked_stone_bricks,10,minecraft:cobblestone,10,minecraft:mossy_cobblestone,10,minecraft:stone_bricks,100)
RB(6,1,2,minecraft:mossy_stone_bricks,10,minecraft:cracked_stone_bricks,10,minecraft:cobblestone,10,minecraft:mossy_cobblestone,10,minecraft:stone_bricks,100)
RB(7,1,2,minecraft:mossy_stone_bricks,10,minecraft:cracked_stone_bricks,10,minecraft:cobblestone,10,minecraft:mossy_cobblestone,10,minecraft:stone_bricks,100)
RB(0,1,3,minecraft:mossy_stone_bricks,10,minecraft:cracked_stone_bricks,10,minecraft:cobblestone,10,minecraft:mossy_cobblestone,10,minecraft:stone_bricks,100)
RB(1,1,3,minecraft:mossy_stone_bricks,10,minecraft:cracked_stone_bricks,10,minecraft:cobblestone,10,minecraft:mossy_cobblestone,10,minecraft:stone_bricks,100)
RB(2,1,3,minecraft:mossy_stone_bricks,10,minecraft:cracked_stone_bricks,10,minecraft:cobblestone,10,minecraft:mossy_cobblestone,10,minecraft:stone_bricks,100)
RB(3,1,3,minecraft:mossy_stone_bricks,10,minecraft:cracked_stone_bricks,10,minecraft:cobblestone,10,minecraft:mossy_cobblestone,10,minecraft:stone_bricks,100)
RB(4,1,3,minecraft:mossy_stone_bricks,10,minecraft:cracked_stone_bricks,10,minecraft:cobblestone,10,minecraft:mossy_cobblestone,10,minecraft:stone_bricks,100)
RB(5,1,3,minecraft:mossy_stone_bricks,10,minecraft:cracked_stone_bricks,10,minecraft:cobblestone,10,minecraft:mossy_cobblestone,10,minecraft:stone_bricks,100)
RB(6,1,3,minecraft:mossy_stone_bricks,10,minecraft:cracked_stone_bricks,10,minecraft:cobblestone,10,minecraft:mossy_cobblestone,10,minecraft:stone_bricks,100)
RB(7,1,3,minecraft:mossy_stone_bricks,10,minecraft:cracked_stone_bricks,10,minecraft:cobblestone,10,minecraft:mossy_cobblestone,10,minecraft:stone_bricks,100)
RB(0,1,4,minecraft:mossy_stone_bricks,10,minecraft:cracked_stone_bricks,10,minecraft:cobblestone,10,minecraft:mossy_cobblestone,10,minecraft:stone_bricks,100)
RB(1,1,4,minecraft:mossy_stone_bricks,10,minecraft:cracked_stone_bricks,10,minecraft:cobblestone,10,minecraft:mossy_cobblestone,10,minecraft:stone_bricks,100)
RB(2,1,4,minecraft:mossy_stone_bricks,10,minecraft:cracked_stone_bricks,10,minecraft:cobblestone,10,minecraft:mossy_cobblestone,10,minecraft:stone_bricks,100)
RB(3,1,4,minecraft:mossy_stone_bricks,10,minecraft:cracked_stone_bricks,10,minecraft:cobblestone,10,minecraft:mossy_cobblestone,10,minecraft:stone_bricks,100)
RB(4,1,4,minecraft:mossy_stone_bricks,10,minecraft:cracked_stone_bricks,10,minecraft:cobblestone,10,minecraft:mossy_cobblestone,10,minecraft:stone_bricks,100)
RB(6,1,4,minecraft:mossy_stone_bricks,10,minecraft:cracked_stone_bricks,10,minecraft:cobblestone,10,minecraft:mossy_cobblestone,10,minecraft:stone_bricks,100)
RB(7,1,4,minecraft:mossy_stone_bricks,10,minecraft:cracked_stone_bricks,10,minecraft:cobblestone,10,minecraft:mossy_cobblestone,10,minecraft:stone_bricks,100)
RB(0,1,5,minecraft:mossy_stone_bricks,10,minecraft:cracked_stone_bricks,10,minecraft:cobblestone,10,minecraft:mossy_cobblestone,10,minecraft:stone_bricks,100)
RB(1,1,5,minecraft:mossy_stone_bricks,10,minecraft:cracked_stone_bricks,10,minecraft:cobblestone,10,minecraft:mossy_cobblestone,10,minecraft:stone_bricks,100)
RB(2,1,5,minecraft:mossy_stone_bricks,10,minecraft:cracked_stone_bricks,10,minecraft:cobblestone,10,minecraft:mossy_cobblestone,10,minecraft:stone_bricks,100)
RB(3,1,5,minecraft:mossy_stone_bricks,10,minecraft:cracked_stone_bricks,10,minecraft:cobblestone,10,minecraft:mossy_cobblestone,10,minecraft:stone_bricks,100)
RB(5,1,5,minecraft:mossy_stone_bricks,10,minecraft:cracked_stone_bricks,10,minecraft:cobblestone,10,minecraft:mossy_cobblestone,10,minecraft:stone_bricks,100)
RB(7,1,5,minecraft:mossy_stone_bricks,10,minecraft:cracked_stone_bricks,10,minecraft:cobblestone,10,minecraft:mossy_cobblestone,10,minecraft:stone_bricks,100)
RB(0,1,6,minecraft:mossy_stone_bricks,10,minecraft:cracked_stone_bricks,10,minecraft:cobblestone,10,minecraft:mossy_cobblestone,10,minecraft:stone_bricks,100)
RB(1,1,6,minecraft:mossy_stone_bricks,10,minecraft:cracked_stone_bricks,10,minecraft:cobblestone,10,minecraft:mossy_cobblestone,10,minecraft:stone_bricks,100)
RB(2,1,6,minecraft:mossy_stone_bricks,10,minecraft:cracked_stone_bricks,10,minecraft:cobblestone,10,minecraft:mossy_cobblestone,10,minecraft:stone_bricks,100)
RB(3,1,6,minecraft:mossy_stone_bricks,10,minecraft:cracked_stone_bricks,10,minecraft:cobblestone,10,minecraft:mossy_cobblestone,10,minecraft:stone_bricks,100)
RB(4,1,6,minecraft:mossy_stone_bricks,10,minecraft:cracked_stone_bricks,10,minecraft:cobblestone,10,minecraft:mossy_cobblestone,10,minecraft:stone_bricks,100)
RB(6,1,6,minecraft:mossy_stone_bricks,10,minecraft:cracked_stone_bricks,10,minecraft:cobblestone,10,minecraft:mossy_cobblestone,10,minecraft:stone_bricks,100)
RB(7,1,6,minecraft:mossy_stone_bricks,10,minecraft:cracked_stone_bricks,10,minecraft:cobblestone,10,minecraft:mossy_cobblestone,10,minecraft:stone_bricks,100)
RB(0,1,7,minecraft:mossy_stone_bricks,10,minecraft:cracked_stone_bricks,10,minecraft:cobblestone,10,minecraft:mossy_cobblestone,10,minecraft:stone_bricks,100)
RB(1,1,7,minecraft:mossy_stone_bricks,10,minecraft:cracked_stone_bricks,10,minecraft:cobblestone,10,minecraft:mossy_cobblestone,10,minecraft:stone_bricks,100)
RB(2,1,7,minecraft:mossy_stone_bricks,10,minecraft:cracked_stone_bricks,10,minecraft:cobblestone,10,minecraft:mossy_cobblestone,10,minecraft:stone_bricks,100)
RB(3,1,7,minecraft:mossy_stone_bricks,10,minecraft:cracked_stone_bricks,10,minecraft:cobblestone,10,minecraft:mossy_cobblestone,10,minecraft:stone_bricks,100)
RB(4,1,7,minecraft:mossy_stone_bricks,10,minecraft:cracked_stone_bricks,10,minecraft:cobblestone,10,minecraft:mossy_cobblestone,10,minecraft:stone_bricks,100)
RB(5,1,7,minecraft:mossy_stone_bricks,10,minecraft:cracked_stone_bricks,10,minecraft:cobblestone,10,minecraft:mossy_cobblestone,10,minecraft:stone_bricks,100)
RB(6,1,7,minecraft:mossy_stone_bricks,10,minecraft:cracked_stone_bricks,10,minecraft:cobblestone,10,minecraft:mossy_cobblestone,10,minecraft:stone_bricks,100)
RB(7,1,7,minecraft:mossy_stone_bricks,10,minecraft:cracked_stone_bricks,10,minecraft:cobblestone,10,minecraft:mossy_cobblestone,10,minecraft:stone_bricks,100)
RB(0,2,0,minecraft:mossy_stone_bricks,10,minecraft:cracked_stone_bricks,10,minecraft:cobblestone,10,minecraft:mossy_cobblestone,10,minecraft:stone_bricks,100)
RB(1,2,0,minecraft:mossy_stone_bricks,10,minecraft:cracked_stone_bricks,10,minecraft:cobblestone,10,minecraft:mossy_cobblestone,10,minecraft:stone_bricks,100)
RB(2,2,0,minecraft:mossy_stone_bricks,10,minecraft:cracked_stone_bricks,10,minecraft:cobblestone,10,minecraft:mossy_cobblestone,10,minecraft:stone_bricks,100)
RB(3,2,0,minecraft:mossy_stone_bricks,10,minecraft:cracked_stone_bricks,10,minecraft:cobblestone,10,minecraft:mossy_cobblestone,10,minecraft:stone_bricks,100)
RB(4,2,0,minecraft:mossy_stone_bricks,10,minecraft:cracked_stone_bricks,10,minecraft:cobblestone,10,minecraft:mossy_cobblestone,10,minecraft:stone_bricks,100)
RB(5,2,0,minecraft:mossy_stone_bricks,10,minecraft:cracked_stone_bricks,10,minecraft:cobblestone,10,minecraft:mossy_cobblestone,10,minecraft:stone_bricks,100)
RB(6,2,0,minecraft:mossy_stone_bricks,10,minecraft:cracked_stone_bricks,10,minecraft:cobblestone,10,minecraft:mossy_cobblestone,10,minecraft:stone_bricks,100)
RB(7,2,0,minecraft:mossy_stone_bricks,10,minecraft:cracked_stone_bricks,10,minecraft:cobblestone,10,minecraft:mossy_cobblestone,10,minecraft:stone_bricks,100)
RB(0,2,1,minecraft:mossy_stone_bricks,10,minecraft:cracked_stone_bricks,10,minecraft:cobblestone,10,minecraft:mossy_cobblestone,10,minecraft:stone_bricks,100)
RB(1,2,1,minecraft:mossy_stone_bricks,10,minecraft:cracked_stone_bricks,10,minecraft:cobblestone,10,minecraft:mossy_cobblestone,10,minecraft:stone_bricks,100)
RB(2,2,1,minecraft:mossy_stone_bricks,10,minecraft:cracked_stone_bricks,10,minecraft:cobblestone,10,minecraft:mossy_cobblestone,10,minecraft:stone_bricks,100)
RB(3,2,1,minecraft:mossy_stone_bricks,10,minecraft:cracked_stone_bricks,10,minecraft:cobblestone,10,minecraft:mossy_cobblestone,10,minecraft:stone_bricks,100)
RB(4,2,1,minecraft:mossy_stone_bricks,10,minecraft:cracked_stone_bricks,10,minecraft:cobblestone,10,minecraft:mossy_cobblestone,10,minecraft:stone_bricks,100)
RB(5,2,1,minecraft:mossy_stone_bricks,10,minecraft:cracked_stone_bricks,10,minecraft:cobblestone,10,minecraft:mossy_cobblestone,10,minecraft:stone_bricks,100)
RB(6,2,1,minecraft:mossy_stone_bricks,10,minecraft:cracked_stone_bricks,10,minecraft:cobblestone,10,minecraft:mossy_cobblestone,10,minecraft:stone_bricks,100)
RB(7,2,1,minecraft:mossy_stone_bricks,10,minecraft:cracked_stone_bricks,10,minecraft:cobblestone,10,minecraft:mossy_cobblestone,10,minecraft:stone_bricks,100)
RB(0,2,2,minecraft:mossy_stone_bricks,10,minecraft:cracked_stone_bricks,10,minecraft:cobblestone,10,minecraft:mossy_cobblestone,10,minecraft:stone_bricks,100)
RB(1,2,2,minecraft:mossy_stone_bricks,10,minecraft:cracked_stone_bricks,10,minecraft:cobblestone,10,minecraft:mossy_cobblestone,10,minecraft:stone_bricks,100)
RB(2,2,2,minecraft:mossy_stone_bricks,10,minecraft:cracked_stone_bricks,10,minecraft:cobblestone,10,minecraft:mossy_cobblestone,10,minecraft:stone_bricks,100)
RB(3,2,2,minecraft:mossy_stone_bricks,10,minecraft:cracked_stone_bricks,10,minecraft:cobblestone,10,minecraft:mossy_cobblestone,10,minecraft:stone_bricks,100)
RB(4,2,2,minecraft:mossy_stone_bricks,10,minecraft:cracked_stone_bricks,10,minecraft:cobblestone,10,minecraft:mossy_cobblestone,10,minecraft:stone_bricks,100)
RB(5,2,2,minecraft:mossy_stone_bricks,10,minecraft:cracked_stone_bricks,10,minecraft:cobblestone,10,minecraft:mossy_cobblestone,10,minecraft:stone_bricks,100)
RB(6,2,2,minecraft:mossy_stone_bricks,10,minecraft:cracked_stone_bricks,10,minecraft:cobblestone,10,minecraft:mossy_cobblestone,10,minecraft:stone_bricks,100)
RB(7,2,2,minecraft:mossy_stone_bricks,10,minecraft:cracked_stone_bricks,10,minecraft:cobblestone,10,minecraft:mossy_cobblestone,10,minecraft:stone_bricks,100)
RB(0,2,3,minecraft:mossy_stone_bricks,10,minecraft:cracked_stone_bricks,10,minecraft:cobblestone,10,minecraft:mossy_cobblestone,10,minecraft:stone_bricks,100)
RB(1,2,3,minecraft:mossy_stone_bricks,10,minecraft:cracked_stone_bricks,10,minecraft:cobblestone,10,minecraft:mossy_cobblestone,10,minecraft:stone_bricks,100)
RB(2,2,3,minecraft:mossy_stone_bricks,10,minecraft:cracked_stone_bricks,10,minecraft:cobblestone,10,minecraft:mossy_cobblestone,10,minecraft:stone_bricks,100)
RB(3,2,3,minecraft:mossy_stone_bricks,10,minecraft:cracked_stone_bricks,10,minecraft:cobblestone,10,minecraft:mossy_cobblestone,10,minecraft:stone_bricks,100)
RB(4,2,3,minecraft:mossy_stone_bricks,10,minecraft:cracked_stone_bricks,10,minecraft:cobblestone,10,minecraft:mossy_cobblestone,10,minecraft:stone_bricks,100)
RB(5,2,3,minecraft:mossy_stone_bricks,10,minecraft:cracked_stone_bricks,10,minecraft:cobblestone,10,minecraft:mossy_cobblestone,10,minecraft:stone_bricks,100)
RB(6,2,3,minecraft:mossy_stone_bricks,10,minecraft:cracked_stone_bricks,10,minecraft:cobblestone,10,minecraft:mossy_cobblestone,10,minecraft:stone_bricks,100)
RB(7,2,3,minecraft:mossy_stone_bricks,10,minecraft:cracked_stone_bricks,10,minecraft:cobblestone,10,minecraft:mossy_cobblestone,10,minecraft:stone_bricks,100)
RB(0,2,4,minecraft:mossy_stone_bricks,10,minecraft:cracked_stone_bricks,10,minecraft:cobblestone,10,minecraft:mossy_cobblestone,10,minecraft:stone_bricks,100)
RB(1,2,4,minecraft:mossy_stone_bricks,10,minecraft:cracked_stone_bricks,10,minecraft:cobblestone,10,minecraft:mossy_cobblestone,10,minecraft:stone_bricks,100)
RB(2,2,4,minecraft:mossy_stone_bricks,10,minecraft:cracked_stone_bricks,10,minecraft:cobblestone,10,minecraft:mossy_cobblestone,10,minecraft:stone_bricks,100)
RB(3,2,4,minecraft:mossy_stone_bricks,10,minecraft:cracked_stone_bricks,10,minecraft:cobblestone,10,minecraft:mossy_cobblestone,10,minecraft:stone_bricks,100)
RB(4,2,4,minecraft:mossy_stone_bricks,10,minecraft:cracked_stone_bricks,10,minecraft:cobblestone,10,minecraft:mossy_cobblestone,10,minecraft:stone_bricks,100)
RB(5,2,4,minecraft:mossy_stone_bricks,10,minecraft:cracked_stone_bricks,10,minecraft:cobblestone,10,minecraft:mossy_cobblestone,10,minecraft:stone_bricks,100)
RB(6,2,4,minecraft:mossy_stone_bricks,10,minecraft:cracked_stone_bricks,10,minecraft:cobblestone,10,minecraft:mossy_cobblestone,10,minecraft:stone_bricks,100)
RB(7,2,4,minecraft:mossy_stone_bricks,10,minecraft:cracked_stone_bricks,10,minecraft:cobblestone,10,minecraft:mossy_cobblestone,10,minecraft:stone_bricks,100)
RB(0,2,5,minecraft:mossy_stone_bricks,10,minecraft:cracked_stone_bricks,10,minecraft:cobblestone,10,minecraft:mossy_cobblestone,10,minecraft:stone_bricks,100)
RB(1,2,5,minecraft:mossy_stone_bricks,10,minecraft:cracked_stone_bricks,10,minecraft:cobblestone,10,minecraft:mossy_cobblestone,10,minecraft:stone_bricks,100)
RB(2,2,5,minecraft:mossy_stone_bricks,10,minecraft:cracked_stone_bricks,10,minecraft:cobblestone,10,minecraft:mossy_cobblestone,10,minecraft:stone_bricks,100)
RB(3,2,5,minecraft:mossy_stone_bricks,10,minecraft:cracked_stone_bricks,10,minecraft:cobblestone,10,minecraft:mossy_cobblestone,10,minecraft:stone_bricks,100)
RB(4,2,5,minecraft:mossy_stone_bricks,10,minecraft:cracked_stone_bricks,10,minecraft:cobblestone,10,minecraft:mossy_cobblestone,10,minecraft:stone_bricks,100)
RB(6,2,5,minecraft:mossy_stone_bricks,10,minecraft:cracked_stone_bricks,10,minecraft:cobblestone,10,minecraft:mossy_cobblestone,10,minecraft:stone_bricks,100)
RB(7,2,5,minecraft:mossy_stone_bricks,10,minecraft:cracked_stone_bricks,10,minecraft:cobblestone,10,minecraft:mossy_cobblestone,10,minecraft:stone_bricks,100)
RB(0,2,6,minecraft:mossy_stone_bricks,10,minecraft:cracked_stone_bricks,10,minecraft:cobblestone,10,minecraft:mossy_cobblestone,10,minecraft:stone_bricks,100)
RB(1,2,6,minecraft:mossy_stone_bricks,10,minecraft:cracked_stone_bricks,10,minecraft:cobblestone,10,minecraft:mossy_cobblestone,10,minecraft:stone_bricks,100)
RB(2,2,6,minecraft:mossy_stone_bricks,10,minecraft:cracked_stone_bricks,10,minecraft:cobblestone,10,minecraft:mossy_cobblestone,10,minecraft:stone_bricks,100)
RB(3,2,6,minecraft:mossy_stone_bricks,10,minecraft:cracked_stone_bricks,10,minecraft:cobblestone,10,minecraft:mossy_cobblestone,10,minecraft:stone_bricks,100)
RB(4,2,6,minecraft:mossy_stone_bricks,10,minecraft:cracked_stone_bricks,10,minecraft:cobblestone,10,minecraft:mossy_cobblestone,10,minecraft:stone_bricks,100)
RB(5,2,6,minecraft:mossy_stone_bricks,10,minecraft:cracked_stone_bricks,10,minecraft:cobblestone,10,minecraft:mossy_cobblestone,10,minecraft:stone_bricks,100)
RB(6,2,6,minecraft:mossy_stone_bricks,10,minecraft:cracked_stone_bricks,10,minecraft:cobblestone,10,minecraft:mossy_cobblestone,10,minecraft:stone_bricks,100)
RB(7,2,6,minecraft:mossy_stone_bricks,10,minecraft:cracked_stone_bricks,10,minecraft:cobblestone,10,minecraft:mossy_cobblestone,10,minecraft:stone_bricks,100)
RB(0,2,7,minecraft:mossy_stone_bricks,10,minecraft:cracked_stone_bricks,10,minecraft:cobblestone,10,minecraft:mossy_cobblestone,10,minecraft:stone_bricks,100)
RB(1,2,7,minecraft:mossy_stone_bricks,10,minecraft:cracked_stone_bricks,10,minecraft:cobblestone,10,minecraft:mossy_cobblestone,10,minecraft:stone_bricks,100)
RB(2,2,7,minecraft:mossy_stone_bricks,10,minecraft:cracked_stone_bricks,10,minecraft:cobblestone,10,minecraft:mossy_cobblestone,10,minecraft:stone_bricks,100)
RB(3,2,7,minecraft:mossy_stone_bricks,10,minecraft:cracked_stone_bricks,10,minecraft:cobblestone,10,minecraft:mossy_cobblestone,10,minecraft:stone_bricks,100)
RB(4,2,7,minecraft:mossy_stone_bricks,10,minecraft:cracked_stone_bricks,10,minecraft:cobblestone,10,minecraft:mossy_cobblestone,10,minecraft:stone_bricks,100)
RB(5,2,7,minecraft:mossy_stone_bricks,10,minecraft:cracked_stone_bricks,10,minecraft:cobblestone,10,minecraft:mossy_cobblestone,10,minecraft:stone_bricks,100)
RB(6,2,7,minecraft:mossy_stone_bricks,10,minecraft:cracked_stone_bricks,10,minecraft:cobblestone,10,minecraft:mossy_cobblestone,10,minecraft:stone_bricks,100)
RB(7,2,7,minecraft:mossy_stone_bricks,10,minecraft:cracked_stone_bricks,10,minecraft:cobblestone,10,minecraft:mossy_cobblestone,10,minecraft:stone_bricks,100)
RB(1,3,0,minecraft:mossy_stone_bricks,10,minecraft:cracked_stone_bricks,10,minecraft:cobblestone,10,minecraft:mossy_cobblestone,10,minecraft:stone_bricks,100)
RB(4,3,0,minecraft:mossy_stone_bricks,10,minecraft:cracked_stone_bricks,10,minecraft:cobblestone,10,minecraft:mossy_cobblestone,10,minecraft:stone_bricks,100)
RB(5,3,0,minecraft:mossy_stone_bricks,10,minecraft:cracked_stone_bricks,10,minecraft:cobblestone,10,minecraft:mossy_cobblestone,10,minecraft:stone_bricks,100)
RB(6,3,0,minecraft:mossy_stone_bricks,10,minecraft:cracked_stone_bricks,10,minecraft:cobblestone,10,minecraft:mossy_cobblestone,10,minecraft:stone_bricks,100)
RB(7,3,0,minecraft:mossy_stone_bricks,10,minecraft:cracked_stone_bricks,10,minecraft:cobblestone,10,minecraft:mossy_cobblestone,10,minecraft:stone_bricks,100)
RB(1,3,1,minecraft:mossy_stone_bricks,10,minecraft:cracked_stone_bricks,10,minecraft:cobblestone,10,minecraft:mossy_cobblestone,10,minecraft:stone_bricks,100)
RB(4,3,1,minecraft:mossy_stone_bricks,10,minecraft:cracked_stone_bricks,10,minecraft:cobblestone,10,minecraft:mossy_cobblestone,10,minecraft:stone_bricks,100)
RB(5,3,1,minecraft:mossy_stone_bricks,10,minecraft:cracked_stone_bricks,10,minecraft:cobblestone,10,minecraft:mossy_cobblestone,10,minecraft:stone_bricks,100)
RB(6,3,1,minecraft:mossy_stone_bricks,10,minecraft:cracked_stone_bricks,10,minecraft:cobblestone,10,minecraft:mossy_cobblestone,10,minecraft:stone_bricks,100)
RB(7,3,1,minecraft:mossy_stone_bricks,10,minecraft:cracked_stone_bricks,10,minecraft:cobblestone,10,minecraft:mossy_cobblestone,10,minecraft:stone_bricks,100)
RB(0,3,2,minecraft:mossy_stone_bricks,10,minecraft:cracked_stone_bricks,10,minecraft:cobblestone,10,minecraft:mossy_cobblestone,10,minecraft:stone_bricks,100)
RB(2,3,2,minecraft:mossy_stone_bricks,10,minecraft:cracked_stone_bricks,10,minecraft:cobblestone,10,minecraft:mossy_cobblestone,10,minecraft:stone_bricks,100)
RB(4,3,2,minecraft:mossy_stone_bricks,10,minecraft:cracked_stone_bricks,10,minecraft:cobblestone,10,minecraft:mossy_cobblestone,10,minecraft:stone_bricks,100)
RB(5,3,2,minecraft:mossy_stone_bricks,10,minecraft:cracked_stone_bricks,10,minecraft:cobblestone,10,minecraft:mossy_cobblestone,10,minecraft:stone_bricks,100)
RB(6,3,2,minecraft:mossy_stone_bricks,10,minecraft:cracked_stone_bricks,10,minecraft:cobblestone,10,minecraft:mossy_cobblestone,10,minecraft:stone_bricks,100)
RB(7,3,2,minecraft:mossy_stone_bricks,10,minecraft:cracked_stone_bricks,10,minecraft:cobblestone,10,minecraft:mossy_cobblestone,10,minecraft:stone_bricks,100)
RB(1,3,3,minecraft:mossy_stone_bricks,10,minecraft:cracked_stone_bricks,10,minecraft:cobblestone,10,minecraft:mossy_cobblestone,10,minecraft:stone_bricks,100)
RB(3,3,3,minecraft:mossy_stone_bricks,10,minecraft:cracked_stone_bricks,10,minecraft:cobblestone,10,minecraft:mossy_cobblestone,10,minecraft:stone_bricks,100)
RB(4,3,3,minecraft:mossy_stone_bricks,10,minecraft:cracked_stone_bricks,10,minecraft:cobblestone,10,minecraft:mossy_cobblestone,10,minecraft:stone_bricks,100)
RB(5,3,3,minecraft:mossy_stone_bricks,10,minecraft:cracked_stone_bricks,10,minecraft:cobblestone,10,minecraft:mossy_cobblestone,10,minecraft:stone_bricks,100)
RB(6,3,3,minecraft:mossy_stone_bricks,10,minecraft:cracked_stone_bricks,10,minecraft:cobblestone,10,minecraft:mossy_cobblestone,10,minecraft:stone_bricks,100)
RB(7,3,3,minecraft:mossy_stone_bricks,10,minecraft:cracked_stone_bricks,10,minecraft:cobblestone,10,minecraft:mossy_cobblestone,10,minecraft:stone_bricks,100)
RB(2,3,4,minecraft:mossy_stone_bricks,10,minecraft:cracked_stone_bricks,10,minecraft:cobblestone,10,minecraft:mossy_cobblestone,10,minecraft:stone_bricks,100)
RB(3,3,4,minecraft:mossy_stone_bricks,10,minecraft:cracked_stone_bricks,10,minecraft:cobblestone,10,minecraft:mossy_cobblestone,10,minecraft:stone_bricks,100)
RB(4,3,4,minecraft:mossy_stone_bricks,10,minecraft:cracked_stone_bricks,10,minecraft:cobblestone,10,minecraft:mossy_cobblestone,10,minecraft:stone_bricks,100)
RB(5,3,4,minecraft:mossy_stone_bricks,10,minecraft:cracked_stone_bricks,10,minecraft:cobblestone,10,minecraft:mossy_cobblestone,10,minecraft:stone_bricks,100)
RB(6,3,4,minecraft:mossy_stone_bricks,10,minecraft:cracked_stone_bricks,10,minecraft:cobblestone,10,minecraft:mossy_cobblestone,10,minecraft:stone_bricks,100)
RB(7,3,4,minecraft:mossy_stone_bricks,10,minecraft:cracked_stone_bricks,10,minecraft:cobblestone,10,minecraft:mossy_cobblestone,10,minecraft:stone_bricks,100)
RB(0,3,5,minecraft:mossy_stone_bricks,10,minecraft:cracked_stone_bricks,10,minecraft:cobblestone,10,minecraft:mossy_cobblestone,10,minecraft:stone_bricks,100)
RB(1,3,5,minecraft:mossy_stone_bricks,10,minecraft:cracked_stone_bricks,10,minecraft:cobblestone,10,minecraft:mossy_cobblestone,10,minecraft:stone_bricks,100)
RB(2,3,5,minecraft:mossy_stone_bricks,10,minecraft:cracked_stone_bricks,10,minecraft:cobblestone,10,minecraft:mossy_cobblestone,10,minecraft:stone_bricks,100)
RB(3,3,5,minecraft:mossy_stone_bricks,10,minecraft:cracked_stone_bricks,10,minecraft:cobblestone,10,minecraft:mossy_cobblestone,10,minecraft:stone_bricks,100)
RB(4,3,5,minecraft:mossy_stone_bricks,10,minecraft:cracked_stone_bricks,10,minecraft:cobblestone,10,minecraft:mossy_cobblestone,10,minecraft:stone_bricks,100)
RB(5,3,5,minecraft:mossy_stone_bricks,10,minecraft:cracked_stone_bricks,10,minecraft:cobblestone,10,minecraft:mossy_cobblestone,10,minecraft:stone_bricks,100)
RB(6,3,5,minecraft:mossy_stone_bricks,10,minecraft:cracked_stone_bricks,10,minecraft:cobblestone,10,minecraft:mossy_cobblestone,10,minecraft:stone_bricks,100)
RB(7,3,5,minecraft:mossy_stone_bricks,10,minecraft:cracked_stone_bricks,10,minecraft:cobblestone,10,minecraft:mossy_cobblestone,10,minecraft:stone_bricks,100)
RB(0,3,6,minecraft:mossy_stone_bricks,10,minecraft:cracked_stone_bricks,10,minecraft:cobblestone,10,minecraft:mossy_cobblestone,10,minecraft:stone_bricks,100)
RB(1,3,6,minecraft:mossy_stone_bricks,10,minecraft:cracked_stone_bricks,10,minecraft:cobblestone,10,minecraft:mossy_cobblestone,10,minecraft:stone_bricks,100)
RB(2,3,6,minecraft:mossy_stone_bricks,10,minecraft:cracked_stone_bricks,10,minecraft:cobblestone,10,minecraft:mossy_cobblestone,10,minecraft:stone_bricks,100)
RB(3,3,6,minecraft:mossy_stone_bricks,10,minecraft:cracked_stone_bricks,10,minecraft:cobblestone,10,minecraft:mossy_cobblestone,10,minecraft:stone_bricks,100)
RB(4,3,6,minecraft:mossy_stone_bricks,10,minecraft:cracked_stone_bricks,10,minecraft:cobblestone,10,minecraft:mossy_cobblestone,10,minecraft:stone_bricks,100)
RB(5,3,6,minecraft:mossy_stone_bricks,10,minecraft:cracked_stone_bricks,10,minecraft:cobblestone,10,minecraft:mossy_cobblestone,10,minecraft:stone_bricks,100)
RB(6,3,6,minecraft:mossy_stone_bricks,10,minecraft:cracked_stone_bricks,10,minecraft:cobblestone,10,minecraft:mossy_cobblestone,10,minecraft:stone_bricks,100)
RB(7,3,6,minecraft:mossy_stone_bricks,10,minecraft:cracked_stone_bricks,10,minecraft:cobblestone,10,minecraft:mossy_cobblestone,10,minecraft:stone_bricks,100)
RB(0,3,7,minecraft:mossy_stone_bricks,10,minecraft:cracked_stone_bricks,10,minecraft:cobblestone,10,minecraft:mossy_cobblestone,10,minecraft:stone_bricks,100)
RB(1,3,7,minecraft:mossy_stone_bricks,10,minecraft:cracked_stone_bricks,10,minecraft:cobblestone,10,minecraft:mossy_cobblestone,10,minecraft:stone_bricks,100)
RB(2,3,7,minecraft:mossy_stone_bricks,10,minecraft:cracked_stone_bricks,10,minecraft:cobblestone,10,minecraft:mossy_cobblestone,10,minecraft:stone_bricks,100)
RB(3,3,7,minecraft:mossy_stone_bricks,10,minecraft:cracked_stone_bricks,10,minecraft:cobblestone,10,minecraft:mossy_cobblestone,10,minecraft:stone_bricks,100)
RB(4,3,7,minecraft:mossy_stone_bricks,10,minecraft:cracked_stone_bricks,10,minecraft:cobblestone,10,minecraft:mossy_cobblestone,10,minecraft:stone_bricks,100)
RB(5,3,7,minecraft:mossy_stone_bricks,10,minecraft:cracked_stone_bricks,10,minecraft:cobblestone,10,minecraft:mossy_cobblestone,10,minecraft:stone_bricks,100)
RB(6,3,7,minecraft:mossy_stone_bricks,10,minecraft:cracked_stone_bricks,10,minecraft:cobblestone,10,minecraft:mossy_cobblestone,10,minecraft:stone_bricks,100)
RB(7,3,7,minecraft:mossy_stone_bricks,10,minecraft:cracked_stone_bricks,10,minecraft:cobblestone,10,minecraft:mossy_cobblestone,10,minecraft:stone_bricks,100)
RB(5,4,2,minecraft:mossy_stone_bricks,10,minecraft:cracked_stone_bricks,10,minecraft:cobblestone,10,minecraft:mossy_cobblestone,10,minecraft:stone_bricks,100)
RB(6,4,2,minecraft:mossy_stone_bricks,10,minecraft:cracked_stone_bricks,10,minecraft:cobblestone,10,minecraft:mossy_cobblestone,10,minecraft:stone_bricks,100)
RB(6,4,4,minecraft:mossy_stone_bricks,10,minecraft:cracked_stone_bricks,10,minecraft:cobblestone,10,minecraft:mossy_cobblestone,10,minecraft:stone_bricks,100)
RB(2,4,6,minecraft:mossy_stone_bricks,10,minecraft:cracked_stone_bricks,10,minecraft:cobblestone,10,minecraft:mossy_cobblestone,10,minecraft:stone_bricks,100)
RB(4,4,6,minecraft:mossy_stone_bricks,10,minecraft:cracked_stone_bricks,10,minecraft:cobblestone,10,minecraft:mossy_cobblestone,10,minecraft:stone_bricks,100)
RB(1,4,7,minecraft:chest,./StructureNBT/StructureLoot/JunkChest_1.nbt,5,minecraft:chest,./StructureNBT/StructureLoot/JunkChest_2.nbt,5,minecraft:chest,./StructureNBT/StructureLoot/JunkChest_3.nbt,15,minecraft:chest,./StructureNBT/StructureLoot/JunkChest_4.nbt,15,minecraft:chest,./StructureNBT/StructureLoot/JunkChest_5.nbt,15,minecraft:chest,./StructureNBT/LoreStoryline/LoreDungeonOne_10.nbt,3,minecraft:chest,./StructureNBT/LoreStoryline/LoreDungeonOne_9.nbt,3,minecraft:chest,./StructureNBT/LoreStoryline/LoreDungeonOne_8.nbt,3,minecraft:chest,./StructureNBT/LoreStoryline/LoreDungeonOne_7.nbt,3,minecraft:chest,./StructureNBT/LoreStoryline/LoreDungeonOne_6.nbt,3,minecraft:chest,./StructureNBT/LoreStoryline/LoreDungeonOne_5.nbt,3,minecraft:chest,./StructureNBT/LoreStoryline/LoreDungeonOne_4.nbt,3,minecraft:chest,./StructureNBT/LoreStoryline/LoreDungeonOne_3.nbt,3,minecraft:chest,./StructureNBT/LoreStoryline/LoreDungeonOne_2.nbt,3,minecraft:chest,./StructureNBT/LoreStoryline/LoreDungeonOne_1.nbt,3,minecraft:chest,./StructureNBT/StructureLoot/Common1.nbt,25,minecraft:chest,./StructureNBT/StructureLoot/Common2.nbt,25,minecraft:chest,./StructureNBT/StructureLoot/Common3.nbt,25,minecraft:chest,./StructureNBT/StructureLoot/Common4.nbt,25,minecraft:chest,./StructureNBT/StructureLoot/Common5.nbt,25,minecraft:chest,./StructureNBT/StructureLoot/Common6.nbt,25,minecraft:chest,./StructureNBT/StructureLoot/Common7.nbt,25,minecraft:chest,./StructureNBT/StructureLoot/Common8.nbt,25,minecraft:chest,./StructureNBT/StructureLoot/Common9.nbt,25,minecraft:chest,./StructureNBT/StructureLoot/Common10.nbt,25,minecraft:chest,./StructureNBT/StructureLoot/Common11.nbt,25,minecraft:chest,./StructureNBT/StructureLoot/Common12.nbt,25,minecraft:chest,./StructureNBT/StructureLoot/Common13.nbt,25,minecraft:chest,./StructureNBT/StructureLoot/Common14.nbt,25,minecraft:chest,./StructureNBT/StructureLoot/Common15.nbt,25,minecraft:chest,./StructureNBT/StructureLoot/Rare1.nbt,10,minecraft:chest,./StructureNBT/StructureLoot/Rare2.nbt,10,minecraft:chest,./StructureNBT/StructureLoot/Rare3.nbt,10,minecraft:chest,./StructureNBT/StructureLoot/Rare4.nbt,10,minecraft:chest,./StructureNBT/StructureLoot/Rare5.nbt,10,minecraft:chest,./StructureNBT/StructureLoot/Rare6.nbt,10,minecraft:chest,./StructureNBT/StructureLoot/Rare7.nbt,10,minecraft:chest,./StructureNBT/StructureLoot/Rare8.nbt,10,minecraft:chest,./StructureNBT/StructureLoot/Rare9.nbt,10,minecraft:chest,./StructureNBT/StructureLoot/Rare10.nbt,10,minecraft:chest,./StructureNBT/StructureLoot/Rare11.nbt,10,minecraft:chest,./StructureNBT/StructureLoot/Rare12.nbt,10,minecraft:chest,./StructureNBT/StructureLoot/Rare13.nbt,10,minecraft:chest,./StructureNBT/StructureLoot/Rare14.nbt,10,minecraft:chest,./StructureNBT/StructureLoot/Rare15.nbt,10,minecraft:chest,./StructureNBT/StructureLoot/Epic1.nbt,1,minecraft:chest,./StructureNBT/StructureLoot/Epic2.nbt,1,minecraft:chest,./StructureNBT/StructureLoot/Epic3.nbt,1,minecraft:chest,./StructureNBT/StructureLoot/Epic4.nbt,1,minecraft:chest,./StructureNBT/StructureLoot/Epic5.nbt,1,minecraft:chest,./StructureNBT/StructureLoot/Epic6.nbt,1,minecraft:chest,./StructureNBT/StructureLoot/Epic7.nbt,1,minecraft:chest,./StructureNBT/StructureLoot/Epic8.nbt,1,minecraft:chest,./StructureNBT/StructureLoot/Epic9.nbt,1,minecraft:chest,./StructureNBT/StructureLoot/Epic10.nbt,1,minecraft:chest,./StructureNBT/StructureLoot/Epic11.nbt,1,minecraft:chest,./StructureNBT/StructureLoot/Epic12.nbt,1,minecraft:chest,./StructureNBT/StructureLoot/Epic13.nbt,1,minecraft:chest,./StructureNBT/StructureLoot/Epic14.nbt,1,minecraft:chest,./StructureNBT/StructureLoot/Epic15.nbt,1,minecraft:chest,./StructureNBT/StructureLoot/Common15.nbt,100)
RB(5,5,2,minecraft:infested_stone,./StructureNBT/Mobs/dungeon01spawner01.nbt,25,minecraft:infested_stone,./StructureNBT/Mobs/dungeon01spawner02.nbt,25,minecraft:infested_stone,./StructureNBT/Mobs/dungeon01spawner03.nbt,100)
RB(6,5,2,minecraft:mossy_stone_bricks,10,minecraft:cracked_stone_bricks,10,minecraft:cobblestone,10,minecraft:mossy_cobblestone,10,minecraft:stone_bricks,100)
RB(6,5,4,minecraft:mossy_stone_bricks,10,minecraft:cracked_stone_bricks,10,minecraft:cobblestone,10,minecraft:mossy_cobblestone,10,minecraft:stone_bricks,100)
RB(2,5,6,minecraft:mossy_stone_bricks,10,minecraft:cracked_stone_bricks,10,minecraft:cobblestone,10,minecraft:mossy_cobblestone,10,minecraft:stone_bricks,100)
RB(4,5,6,minecraft:mossy_stone_bricks,10,minecraft:cracked_stone_bricks,10,minecraft:cobblestone,10,minecraft:mossy_cobblestone,10,minecraft:stone_bricks,100)
RB(6,6,2,minecraft:mossy_stone_bricks,10,minecraft:cracked_stone_bricks,10,minecraft:cobblestone,10,minecraft:mossy_cobblestone,10,minecraft:stone_bricks,100)
RB(6,6,4,minecraft:mossy_stone_bricks,10,minecraft:cracked_stone_bricks,10,minecraft:cobblestone,10,minecraft:mossy_cobblestone,10,minecraft:stone_bricks,100)
B(2,6,5,minecraft:white_wall_banner,./StructureNBT/Banners/dungeon_banner.nbt)
RB(2,6,6,minecraft:mossy_stone_bricks,10,minecraft:cracked_stone_bricks,10,minecraft:cobblestone,10,minecraft:mossy_cobblestone,10,minecraft:stone_bricks,100)
RB(4,6,6,minecraft:mossy_stone_bricks,10,minecraft:cracked_stone_bricks,10,minecraft:cobblestone,10,minecraft:mossy_cobblestone,10,minecraft:stone_bricks,100)
RB(7,8,2,minecraft:mossy_stone_bricks,10,minecraft:cracked_stone_bricks,10,minecraft:cobblestone,10,minecraft:mossy_cobblestone,10,minecraft:stone_bricks,100)
RB(7,8,4,minecraft:mossy_stone_bricks,10,minecraft:cracked_stone_bricks,10,minecraft:cobblestone,10,minecraft:mossy_cobblestone,10,minecraft:stone_bricks,100)
RB(2,8,7,minecraft:mossy_stone_bricks,10,minecraft:cracked_stone_bricks,10,minecraft:cobblestone,10,minecraft:mossy_cobblestone,10,minecraft:stone_bricks,100)
RB(4,8,7,minecraft:mossy_stone_bricks,10,minecraft:cracked_stone_bricks,10,minecraft:cobblestone,10,minecraft:mossy_cobblestone,10,minecraft:stone_bricks,100)
RB(7,9,2,minecraft:mossy_stone_bricks,10,minecraft:cracked_stone_bricks,10,minecraft:cobblestone,10,minecraft:mossy_cobblestone,10,minecraft:stone_bricks,100)
RB(7,9,4,minecraft:mossy_stone_bricks,10,minecraft:cracked_stone_bricks,10,minecraft:cobblestone,10,minecraft:mossy_cobblestone,10,minecraft:stone_bricks,100)
RB(2,9,7,minecraft:mossy_stone_bricks,10,minecraft:cracked_stone_bricks,10,minecraft:cobblestone,10,minecraft:mossy_cobblestone,10,minecraft:stone_bricks,100)
RB(4,9,7,minecraft:mossy_stone_bricks,10,minecraft:cracked_stone_bricks,10,minecraft:cobblestone,10,minecraft:mossy_cobblestone,10,minecraft:stone_bricks,100)
RB(7,10,2,minecraft:mossy_stone_bricks,10,minecraft:cracked_stone_bricks,10,minecraft:cobblestone,10,minecraft:mossy_cobblestone,10,minecraft:stone_bricks,100)
RB(6,10,3,minecraft:cobweb,8,minecraft:air,100)
RB(4,10,4,minecraft:cobweb,8,minecraft:air,100)
RB(5,10,4,minecraft:cobweb,8,minecraft:air,100)
RB(7,10,4,minecraft:mossy_stone_bricks,10,minecraft:cracked_stone_bricks,10,minecraft:cobblestone,10,minecraft:mossy_cobblestone,10,minecraft:stone_bricks,100)
RB(4,10,5,minecraft:cobweb,8,minecraft:air,100)
RB(3,10,6,minecraft:cobweb,8,minecraft:air,100)
RB(2,10,7,minecraft:mossy_stone_bricks,10,minecraft:cracked_stone_bricks,10,minecraft:cobblestone,10,minecraft:mossy_cobblestone,10,minecraft:stone_bricks,100)
RB(4,10,7,minecraft:mossy_stone_bricks,10,minecraft:cracked_stone_bricks,10,minecraft:cobblestone,10,minecraft:mossy_cobblestone,10,minecraft:stone_bricks,100)
RB(7,11,0,minecraft:cobweb,8,minecraft:air,100)
RB(7,11,1,minecraft:cobweb,8,minecraft:air,100)
RB(6,11,2,minecraft:mossy_stone_bricks,10,minecraft:cracked_stone_bricks,10,minecraft:cobblestone,10,minecraft:mossy_cobblestone,10,minecraft:stone_bricks,100)
RB(7,11,2,minecraft:mossy_stone_bricks,10,minecraft:cracked_stone_bricks,10,minecraft:cobblestone,10,minecraft:mossy_cobblestone,10,minecraft:stone_bricks,100)
RB(6,11,3,minecraft:mossy_stone_bricks,10,minecraft:cracked_stone_bricks,10,minecraft:cobblestone,10,minecraft:mossy_cobblestone,10,minecraft:stone_bricks,100)
RB(4,11,4,minecraft:mossy_stone_bricks,10,minecraft:cracked_stone_bricks,10,minecraft:cobblestone,10,minecraft:mossy_cobblestone,10,minecraft:stone_bricks,100)
RB(5,11,4,minecraft:mossy_stone_bricks,10,minecraft:cracked_stone_bricks,10,minecraft:cobblestone,10,minecraft:mossy_cobblestone,10,minecraft:stone_bricks,100)
RB(6,11,4,minecraft:mossy_stone_bricks,10,minecraft:cracked_stone_bricks,10,minecraft:cobblestone,10,minecraft:mossy_cobblestone,10,minecraft:stone_bricks,100)
RB(7,11,4,minecraft:mossy_stone_bricks,10,minecraft:cracked_stone_bricks,10,minecraft:cobblestone,10,minecraft:mossy_cobblestone,10,minecraft:stone_bricks,100)
RB(4,11,5,minecraft:mossy_stone_bricks,10,minecraft:cracked_stone_bricks,10,minecraft:cobblestone,10,minecraft:mossy_cobblestone,10,minecraft:stone_bricks,100)
RB(2,11,6,minecraft:mossy_stone_bricks,10,minecraft:cracked_stone_bricks,10,minecraft:cobblestone,10,minecraft:mossy_cobblestone,10,minecraft:stone_bricks,100)
RB(3,11,6,minecraft:mossy_stone_bricks,10,minecraft:cracked_stone_bricks,10,minecraft:cobblestone,10,minecraft:mossy_cobblestone,10,minecraft:stone_bricks,100)
RB(4,11,6,minecraft:mossy_stone_bricks,10,minecraft:cracked_stone_bricks,10,minecraft:cobblestone,10,minecraft:mossy_cobblestone,10,minecraft:stone_bricks,100)
RB(0,11,7,minecraft:cobweb,8,minecraft:air,100)
RB(1,11,7,minecraft:cobweb,8,minecraft:air,100)
RB(2,11,7,minecraft:mossy_stone_bricks,10,minecraft:cracked_stone_bricks,10,minecraft:cobblestone,10,minecraft:mossy_cobblestone,10,minecraft:stone_bricks,100)
RB(4,11,7,minecraft:mossy_stone_bricks,10,minecraft:cracked_stone_bricks,10,minecraft:cobblestone,10,minecraft:mossy_cobblestone,10,minecraft:stone_bricks,100)
RB(7,12,0,minecraft:mossy_stone_bricks,10,minecraft:cracked_stone_bricks,10,minecraft:cobblestone,10,minecraft:mossy_cobblestone,10,minecraft:stone_bricks,100)
RB(7,12,1,minecraft:mossy_stone_bricks,10,minecraft:cracked_stone_bricks,10,minecraft:cobblestone,10,minecraft:mossy_cobblestone,10,minecraft:stone_bricks,100)
RB(6,12,2,minecraft:mossy_stone_bricks,10,minecraft:cracked_stone_bricks,10,minecraft:cobblestone,10,minecraft:mossy_cobblestone,10,minecraft:stone_bricks,100)
RB(7,12,2,minecraft:mossy_stone_bricks,10,minecraft:cracked_stone_bricks,10,minecraft:cobblestone,10,minecraft:mossy_cobblestone,10,minecraft:stone_bricks,100)
RB(6,12,3,minecraft:mossy_stone_bricks,10,minecraft:cracked_stone_bricks,10,minecraft:cobblestone,10,minecraft:mossy_cobblestone,10,minecraft:stone_bricks,100)
RB(7,12,3,minecraft:mossy_stone_bricks,10,minecraft:cracked_stone_bricks,10,minecraft:cobblestone,10,minecraft:mossy_cobblestone,10,minecraft:stone_bricks,100)
RB(4,12,4,minecraft:mossy_stone_bricks,10,minecraft:cracked_stone_bricks,10,minecraft:cobblestone,10,minecraft:mossy_cobblestone,10,minecraft:stone_bricks,100)
RB(5,12,4,minecraft:mossy_stone_bricks,10,minecraft:cracked_stone_bricks,10,minecraft:cobblestone,10,minecraft:mossy_cobblestone,10,minecraft:stone_bricks,100)
RB(6,12,4,minecraft:mossy_stone_bricks,10,minecraft:cracked_stone_bricks,10,minecraft:cobblestone,10,minecraft:mossy_cobblestone,10,minecraft:stone_bricks,100)
RB(7,12,4,minecraft:mossy_stone_bricks,10,minecraft:cracked_stone_bricks,10,minecraft:cobblestone,10,minecraft:mossy_cobblestone,10,minecraft:stone_bricks,100)
RB(4,12,5,minecraft:mossy_stone_bricks,10,minecraft:cracked_stone_bricks,10,minecraft:cobblestone,10,minecraft:mossy_cobblestone,10,minecraft:stone_bricks,100)
RB(5,12,5,minecraft:mossy_stone_bricks,10,minecraft:cracked_stone_bricks,10,minecraft:cobblestone,10,minecraft:mossy_cobblestone,10,minecraft:stone_bricks,100)
RB(6,12,5,minecraft:mossy_stone_bricks,10,minecraft:cracked_stone_bricks,10,minecraft:cobblestone,10,minecraft:mossy_cobblestone,10,minecraft:stone_bricks,100)
RB(7,12,5,minecraft:mossy_stone_bricks,10,minecraft:cracked_stone_bricks,10,minecraft:cobblestone,10,minecraft:mossy_cobblestone,10,minecraft:stone_bricks,100)
RB(2,12,6,minecraft:mossy_stone_bricks,10,minecraft:cracked_stone_bricks,10,minecraft:cobblestone,10,minecraft:mossy_cobblestone,10,minecraft:stone_bricks,100)
RB(3,12,6,minecraft:mossy_stone_bricks,10,minecraft:cracked_stone_bricks,10,minecraft:cobblestone,10,minecraft:mossy_cobblestone,10,minecraft:stone_bricks,100)
RB(4,12,6,minecraft:mossy_stone_bricks,10,minecraft:cracked_stone_bricks,10,minecraft:cobblestone,10,minecraft:mossy_cobblestone,10,minecraft:stone_bricks,100)
RB(5,12,6,minecraft:mossy_stone_bricks,10,minecraft:cracked_stone_bricks,10,minecraft:cobblestone,10,minecraft:mossy_cobblestone,10,minecraft:stone_bricks,100)
RB(0,12,7,minecraft:mossy_stone_bricks,10,minecraft:cracked_stone_bricks,10,minecraft:cobblestone,10,minecraft:mossy_cobblestone,10,minecraft:stone_bricks,100)
RB(1,12,7,minecraft:mossy_stone_bricks,10,minecraft:cracked_stone_bricks,10,minecraft:cobblestone,10,minecraft:mossy_cobblestone,10,minecraft:stone_bricks,100)
RB(2,12,7,minecraft:mossy_stone_bricks,10,minecraft:cracked_stone_bricks,10,minecraft:cobblestone,10,minecraft:mossy_cobblestone,10,minecraft:stone_bricks,100)
RB(3,12,7,minecraft:mossy_stone_bricks,10,minecraft:cracked_stone_bricks,10,minecraft:cobblestone,10,minecraft:mossy_cobblestone,10,minecraft:stone_bricks,100)
RB(4,12,7,minecraft:mossy_stone_bricks,10,minecraft:cracked_stone_bricks,10,minecraft:cobblestone,10,minecraft:mossy_cobblestone,10,minecraft:stone_bricks,100)
RB(5,12,7,minecraft:mossy_stone_bricks,10,minecraft:cracked_stone_bricks,10,minecraft:cobblestone,10,minecraft:mossy_cobblestone,10,minecraft:stone_bricks,100)
RB(5,13,0,minecraft:mossy_stone_bricks,10,minecraft:cracked_stone_bricks,10,minecraft:cobblestone,10,minecraft:mossy_cobblestone,10,minecraft:stone_bricks,100)
RB(6,13,0,minecraft:mossy_stone_bricks,10,minecraft:cracked_stone_bricks,10,minecraft:cobblestone,10,minecraft:mossy_cobblestone,10,minecraft:stone_bricks,100)
RB(7,13,0,minecraft:mossy_stone_bricks,10,minecraft:cracked_stone_bricks,10,minecraft:cobblestone,10,minecraft:mossy_cobblestone,10,minecraft:stone_bricks,100)
RB(5,13,1,minecraft:mossy_stone_bricks,10,minecraft:cracked_stone_bricks,10,minecraft:cobblestone,10,minecraft:mossy_cobblestone,10,minecraft:stone_bricks,100)
RB(6,13,1,minecraft:mossy_stone_bricks,10,minecraft:cracked_stone_bricks,10,minecraft:cobblestone,10,minecraft:mossy_cobblestone,10,minecraft:stone_bricks,100)
RB(7,13,1,minecraft:mossy_stone_bricks,10,minecraft:cracked_stone_bricks,10,minecraft:cobblestone,10,minecraft:mossy_cobblestone,10,minecraft:stone_bricks,100)
RB(5,13,2,minecraft:mossy_stone_bricks,10,minecraft:cracked_stone_bricks,10,minecraft:cobblestone,10,minecraft:mossy_cobblestone,10,minecraft:stone_bricks,100)
RB(6,13,2,minecraft:mossy_stone_bricks,10,minecraft:cracked_stone_bricks,10,minecraft:cobblestone,10,minecraft:mossy_cobblestone,10,minecraft:stone_bricks,100)
RB(7,13,2,minecraft:mossy_stone_bricks,10,minecraft:cracked_stone_bricks,10,minecraft:cobblestone,10,minecraft:mossy_cobblestone,10,minecraft:stone_bricks,100)
RB(3,13,3,minecraft:mossy_stone_bricks,10,minecraft:cracked_stone_bricks,10,minecraft:cobblestone,10,minecraft:mossy_cobblestone,10,minecraft:stone_bricks,100)
RB(4,13,3,minecraft:mossy_stone_bricks,10,minecraft:cracked_stone_bricks,10,minecraft:cobblestone,10,minecraft:mossy_cobblestone,10,minecraft:stone_bricks,100)
RB(5,13,3,minecraft:mossy_stone_bricks,10,minecraft:cracked_stone_bricks,10,minecraft:cobblestone,10,minecraft:mossy_cobblestone,10,minecraft:stone_bricks,100)
RB(6,13,3,minecraft:mossy_stone_bricks,10,minecraft:cracked_stone_bricks,10,minecraft:cobblestone,10,minecraft:mossy_cobblestone,10,minecraft:stone_bricks,100)
RB(7,13,3,minecraft:mossy_stone_bricks,10,minecraft:cracked_stone_bricks,10,minecraft:cobblestone,10,minecraft:mossy_cobblestone,10,minecraft:stone_bricks,100)
RB(3,13,4,minecraft:mossy_stone_bricks,10,minecraft:cracked_stone_bricks,10,minecraft:cobblestone,10,minecraft:mossy_cobblestone,10,minecraft:stone_bricks,100)
RB(4,13,4,minecraft:mossy_stone_bricks,10,minecraft:cracked_stone_bricks,10,minecraft:cobblestone,10,minecraft:mossy_cobblestone,10,minecraft:stone_bricks,100)
RB(5,13,4,minecraft:mossy_stone_bricks,10,minecraft:cracked_stone_bricks,10,minecraft:cobblestone,10,minecraft:mossy_cobblestone,10,minecraft:stone_bricks,100)
RB(6,13,4,minecraft:mossy_stone_bricks,10,minecraft:cracked_stone_bricks,10,minecraft:cobblestone,10,minecraft:mossy_cobblestone,10,minecraft:stone_bricks,100)
RB(7,13,4,minecraft:mossy_stone_bricks,10,minecraft:cracked_stone_bricks,10,minecraft:cobblestone,10,minecraft:mossy_cobblestone,10,minecraft:stone_bricks,100)
RB(0,13,5,minecraft:mossy_stone_bricks,10,minecraft:cracked_stone_bricks,10,minecraft:cobblestone,10,minecraft:mossy_cobblestone,10,minecraft:stone_bricks,100)
RB(1,13,5,minecraft:mossy_stone_bricks,10,minecraft:cracked_stone_bricks,10,minecraft:cobblestone,10,minecraft:mossy_cobblestone,10,minecraft:stone_bricks,100)
RB(2,13,5,minecraft:mossy_stone_bricks,10,minecraft:cracked_stone_bricks,10,minecraft:cobblestone,10,minecraft:mossy_cobblestone,10,minecraft:stone_bricks,100)
RB(3,13,5,minecraft:mossy_stone_bricks,10,minecraft:cracked_stone_bricks,10,minecraft:cobblestone,10,minecraft:mossy_cobblestone,10,minecraft:stone_bricks,100)
RB(4,13,5,minecraft:mossy_stone_bricks,10,minecraft:cracked_stone_bricks,10,minecraft:cobblestone,10,minecraft:mossy_cobblestone,10,minecraft:stone_bricks,100)
RB(5,13,5,minecraft:mossy_stone_bricks,10,minecraft:cracked_stone_bricks,10,minecraft:cobblestone,10,minecraft:mossy_cobblestone,10,minecraft:stone_bricks,100)
RB(6,13,5,minecraft:mossy_stone_bricks,10,minecraft:cracked_stone_bricks,10,minecraft:cobblestone,10,minecraft:mossy_cobblestone,10,minecraft:stone_bricks,100)
RB(7,13,5,minecraft:mossy_stone_bricks,10,minecraft:cracked_stone_bricks,10,minecraft:cobblestone,10,minecraft:mossy_cobblestone,10,minecraft:stone_bricks,100)
RB(0,13,6,minecraft:mossy_stone_bricks,10,minecraft:cracked_stone_bricks,10,minecraft:cobblestone,10,minecraft:mossy_cobblestone,10,minecraft:stone_bricks,100)
RB(1,13,6,minecraft:mossy_stone_bricks,10,minecraft:cracked_stone_bricks,10,minecraft:cobblestone,10,minecraft:mossy_cobblestone,10,minecraft:stone_bricks,100)
RB(2,13,6,minecraft:mossy_stone_bricks,10,minecraft:cracked_stone_bricks,10,minecraft:cobblestone,10,minecraft:mossy_cobblestone,10,minecraft:stone_bricks,100)
RB(3,13,6,minecraft:mossy_stone_bricks,10,minecraft:cracked_stone_bricks,10,minecraft:cobblestone,10,minecraft:mossy_cobblestone,10,minecraft:stone_bricks,100)
RB(4,13,6,minecraft:mossy_stone_bricks,10,minecraft:cracked_stone_bricks,10,minecraft:cobblestone,10,minecraft:mossy_cobblestone,10,minecraft:stone_bricks,100)
RB(5,13,6,minecraft:mossy_stone_bricks,10,minecraft:cracked_stone_bricks,10,minecraft:cobblestone,10,minecraft:mossy_cobblestone,10,minecraft:stone_bricks,100)
RB(6,13,6,minecraft:mossy_stone_bricks,10,minecraft:cracked_stone_bricks,10,minecraft:cobblestone,10,minecraft:mossy_cobblestone,10,minecraft:stone_bricks,100)
RB(7,13,6,minecraft:mossy_stone_bricks,10,minecraft:cracked_stone_bricks,10,minecraft:cobblestone,10,minecraft:mossy_cobblestone,10,minecraft:stone_bricks,100)
RB(0,13,7,minecraft:mossy_stone_bricks,10,minecraft:cracked_stone_bricks,10,minecraft:cobblestone,10,minecraft:mossy_cobblestone,10,minecraft:stone_bricks,100)
RB(1,13,7,minecraft:mossy_stone_bricks,10,minecraft:cracked_stone_bricks,10,minecraft:cobblestone,10,minecraft:mossy_cobblestone,10,minecraft:stone_bricks,100)
RB(2,13,7,minecraft:mossy_stone_bricks,10,minecraft:cracked_stone_bricks,10,minecraft:cobblestone,10,minecraft:mossy_cobblestone,10,minecraft:stone_bricks,100)
RB(3,13,7,minecraft:mossy_stone_bricks,10,minecraft:cracked_stone_bricks,10,minecraft:cobblestone,10,minecraft:mossy_cobblestone,10,minecraft:stone_bricks,100)
RB(4,13,7,minecraft:mossy_stone_bricks,10,minecraft:cracked_stone_bricks,10,minecraft:cobblestone,10,minecraft:mossy_cobblestone,10,minecraft:stone_bricks,100)
RB(5,13,7,minecraft:mossy_stone_bricks,10,minecraft:cracked_stone_bricks,10,minecraft:cobblestone,10,minecraft:mossy_cobblestone,10,minecraft:stone_bricks,100)
RB(6,13,7,minecraft:mossy_stone_bricks,10,minecraft:cracked_stone_bricks,10,minecraft:cobblestone,10,minecraft:mossy_cobblestone,10,minecraft:stone_bricks,100)
RB(7,13,7,minecraft:mossy_stone_bricks,10,minecraft:cracked_stone_bricks,10,minecraft:cobblestone,10,minecraft:mossy_cobblestone,10,minecraft:stone_bricks,100)
RB(7,14,0,minecraft:skeleton_skull,./StructureNBT/Skulls/dungeon_skull_01.nbt,6,minecraft:air,9,minecraft:skeleton_skull,./StructureNBT/Skulls/dungeon_skull_02.nbt,12,minecraft:air,15,minecraft:skeleton_skull,./StructureNBT/Skulls/dungeon_skull_03.nbt,18,minecraft:air,21,minecraft:skeleton_skull,./StructureNBT/Skulls/dungeon_skull_04.nbt,24,minecraft:air,27,minecraft:skeleton_skull,./StructureNBT/Skulls/dungeon_skull_05.nbt,30,minecraft:air,33,minecraft:skeleton_skull,./StructureNBT/Skulls/dungeon_skull_06.nbt,36,minecraft:air,39,minecraft:skeleton_skull,./StructureNBT/Skulls/dungeon_skull_07.nbt,42,minecraft:air,45,minecraft:skeleton_skull,./StructureNBT/Skulls/dungeon_skull_08.nbt,48,minecraft:air,51,minecraft:skeleton_skull,./StructureNBT/Skulls/dungeon_skull_09.nbt,54,minecraft:air,57,minecraft:skeleton_skull,./StructureNBT/Skulls/dungeon_skull_10.nbt,60,minecraft:air,63,minecraft:skeleton_skull,./StructureNBT/Skulls/dungeon_skull_11.nbt,66,minecraft:air,69,minecraft:skeleton_skull,./StructureNBT/Skulls/dungeon_skull_12.nbt,72,minecraft:air,75,minecraft:skeleton_skull,./StructureNBT/Skulls/dungeon_skull_13.nbt,78,minecraft:air,81,minecraft:skeleton_skull,./StructureNBT/Skulls/dungeon_skull_14.nbt,84,minecraft:air,87,minecraft:skeleton_skull,./StructureNBT/Skulls/dungeon_skull_15.nbt,90,minecraft:air,93,minecraft:skeleton_skull,./StructureNBT/Skulls/dungeon_skull_16.nbt,96,minecraft:air,100)
RB(5,14,1,minecraft:mossy_stone_bricks,10,minecraft:cracked_stone_bricks,10,minecraft:cobblestone,10,minecraft:mossy_cobblestone,10,minecraft:stone_bricks,100)
RB(6,14,1,minecraft:mossy_stone_bricks,10,minecraft:cracked_stone_bricks,10,minecraft:cobblestone,10,minecraft:mossy_cobblestone,10,minecraft:stone_bricks,100)
RB(7,14,1,minecraft:mossy_stone_bricks,10,minecraft:cracked_stone_bricks,10,minecraft:cobblestone,10,minecraft:mossy_cobblestone,10,minecraft:stone_bricks,100)
RB(5,14,2,minecraft:mossy_stone_bricks,10,minecraft:cracked_stone_bricks,10,minecraft:cobblestone,10,minecraft:mossy_cobblestone,10,minecraft:stone_bricks,100)
RB(7,14,2,minecraft:mossy_stone_bricks,10,minecraft:cracked_stone_bricks,10,minecraft:cobblestone,10,minecraft:mossy_cobblestone,10,minecraft:stone_bricks,100)
RB(3,14,3,minecraft:mossy_stone_bricks,10,minecraft:cracked_stone_bricks,10,minecraft:cobblestone,10,minecraft:mossy_cobblestone,10,minecraft:stone_bricks,100)
RB(4,14,3,minecraft:mossy_stone_bricks,10,minecraft:cracked_stone_bricks,10,minecraft:cobblestone,10,minecraft:mossy_cobblestone,10,minecraft:stone_bricks,100)
RB(5,14,3,minecraft:mossy_stone_bricks,10,minecraft:cracked_stone_bricks,10,minecraft:cobblestone,10,minecraft:mossy_cobblestone,10,minecraft:stone_bricks,100)
RB(6,14,3,minecraft:mossy_stone_bricks,10,minecraft:cracked_stone_bricks,10,minecraft:cobblestone,10,minecraft:mossy_cobblestone,10,minecraft:stone_bricks,100)
RB(7,14,3,minecraft:mossy_stone_bricks,10,minecraft:cracked_stone_bricks,10,minecraft:cobblestone,10,minecraft:mossy_cobblestone,10,minecraft:stone_bricks,100)
RB(2,14,4,minecraft:mossy_stone_bricks,10,minecraft:cracked_stone_bricks,10,minecraft:cobblestone,10,minecraft:mossy_cobblestone,10,minecraft:stone_bricks,100)
RB(3,14,4,minecraft:mossy_stone_bricks,10,minecraft:cracked_stone_bricks,10,minecraft:cobblestone,10,minecraft:mossy_cobblestone,10,minecraft:stone_bricks,100)
RB(4,14,4,minecraft:mossy_stone_bricks,10,minecraft:cracked_stone_bricks,10,minecraft:cobblestone,10,minecraft:mossy_cobblestone,10,minecraft:stone_bricks,100)
RB(5,14,4,minecraft:skeleton_skull,./StructureNBT/Skulls/dungeon_skull_01.nbt,6,minecraft:air,9,minecraft:skeleton_skull,./StructureNBT/Skulls/dungeon_skull_02.nbt,12,minecraft:air,15,minecraft:skeleton_skull,./StructureNBT/Skulls/dungeon_skull_03.nbt,18,minecraft:air,21,minecraft:skeleton_skull,./StructureNBT/Skulls/dungeon_skull_04.nbt,24,minecraft:air,27,minecraft:skeleton_skull,./StructureNBT/Skulls/dungeon_skull_05.nbt,30,minecraft:air,33,minecraft:skeleton_skull,./StructureNBT/Skulls/dungeon_skull_06.nbt,36,minecraft:air,39,minecraft:skeleton_skull,./StructureNBT/Skulls/dungeon_skull_07.nbt,42,minecraft:air,45,minecraft:skeleton_skull,./StructureNBT/Skulls/dungeon_skull_08.nbt,48,minecraft:air,51,minecraft:skeleton_skull,./StructureNBT/Skulls/dungeon_skull_09.nbt,54,minecraft:air,57,minecraft:skeleton_skull,./StructureNBT/Skulls/dungeon_skull_10.nbt,60,minecraft:air,63,minecraft:skeleton_skull,./StructureNBT/Skulls/dungeon_skull_11.nbt,66,minecraft:air,69,minecraft:skeleton_skull,./StructureNBT/Skulls/dungeon_skull_12.nbt,72,minecraft:air,75,minecraft:skeleton_skull,./StructureNBT/Skulls/dungeon_skull_13.nbt,78,minecraft:air,81,minecraft:skeleton_skull,./StructureNBT/Skulls/dungeon_skull_14.nbt,84,minecraft:air,87,minecraft:skeleton_skull,./StructureNBT/Skulls/dungeon_skull_15.nbt,90,minecraft:air,93,minecraft:skeleton_skull,./StructureNBT/Skulls/dungeon_skull_16.nbt,96,minecraft:air,100)
RB(6,14,4,minecraft:skeleton_skull,./StructureNBT/Skulls/dungeon_skull_01.nbt,6,minecraft:air,9,minecraft:skeleton_skull,./StructureNBT/Skulls/dungeon_skull_02.nbt,12,minecraft:air,15,minecraft:skeleton_skull,./StructureNBT/Skulls/dungeon_skull_03.nbt,18,minecraft:air,21,minecraft:skeleton_skull,./StructureNBT/Skulls/dungeon_skull_04.nbt,24,minecraft:air,27,minecraft:skeleton_skull,./StructureNBT/Skulls/dungeon_skull_05.nbt,30,minecraft:air,33,minecraft:skeleton_skull,./StructureNBT/Skulls/dungeon_skull_06.nbt,36,minecraft:air,39,minecraft:skeleton_skull,./StructureNBT/Skulls/dungeon_skull_07.nbt,42,minecraft:air,45,minecraft:skeleton_skull,./StructureNBT/Skulls/dungeon_skull_08.nbt,48,minecraft:air,51,minecraft:skeleton_skull,./StructureNBT/Skulls/dungeon_skull_09.nbt,54,minecraft:air,57,minecraft:skeleton_skull,./StructureNBT/Skulls/dungeon_skull_10.nbt,60,minecraft:air,63,minecraft:skeleton_skull,./StructureNBT/Skulls/dungeon_skull_11.nbt,66,minecraft:air,69,minecraft:skeleton_skull,./StructureNBT/Skulls/dungeon_skull_12.nbt,72,minecraft:air,75,minecraft:skeleton_skull,./StructureNBT/Skulls/dungeon_skull_13.nbt,78,minecraft:air,81,minecraft:skeleton_skull,./StructureNBT/Skulls/dungeon_skull_14.nbt,84,minecraft:air,87,minecraft:skeleton_skull,./StructureNBT/Skulls/dungeon_skull_15.nbt,90,minecraft:air,93,minecraft:skeleton_skull,./StructureNBT/Skulls/dungeon_skull_16.nbt,96,minecraft:air,100)
RB(7,14,4,minecraft:skeleton_skull,./StructureNBT/Skulls/dungeon_skull_01.nbt,6,minecraft:air,9,minecraft:skeleton_skull,./StructureNBT/Skulls/dungeon_skull_02.nbt,12,minecraft:air,15,minecraft:skeleton_skull,./StructureNBT/Skulls/dungeon_skull_03.nbt,18,minecraft:air,21,minecraft:skeleton_skull,./StructureNBT/Skulls/dungeon_skull_04.nbt,24,minecraft:air,27,minecraft:skeleton_skull,./StructureNBT/Skulls/dungeon_skull_05.nbt,30,minecraft:air,33,minecraft:skeleton_skull,./StructureNBT/Skulls/dungeon_skull_06.nbt,36,minecraft:air,39,minecraft:skeleton_skull,./StructureNBT/Skulls/dungeon_skull_07.nbt,42,minecraft:air,45,minecraft:skeleton_skull,./StructureNBT/Skulls/dungeon_skull_08.nbt,48,minecraft:air,51,minecraft:skeleton_skull,./StructureNBT/Skulls/dungeon_skull_09.nbt,54,minecraft:air,57,minecraft:skeleton_skull,./StructureNBT/Skulls/dungeon_skull_10.nbt,60,minecraft:air,63,minecraft:skeleton_skull,./StructureNBT/Skulls/dungeon_skull_11.nbt,66,minecraft:air,69,minecraft:skeleton_skull,./StructureNBT/Skulls/dungeon_skull_12.nbt,72,minecraft:air,75,minecraft:skeleton_skull,./StructureNBT/Skulls/dungeon_skull_13.nbt,78,minecraft:air,81,minecraft:skeleton_skull,./StructureNBT/Skulls/dungeon_skull_14.nbt,84,minecraft:air,87,minecraft:skeleton_skull,./StructureNBT/Skulls/dungeon_skull_15.nbt,90,minecraft:air,93,minecraft:skeleton_skull,./StructureNBT/Skulls/dungeon_skull_16.nbt,96,minecraft:air,100)
RB(1,14,5,minecraft:mossy_stone_bricks,10,minecraft:cracked_stone_bricks,10,minecraft:cobblestone,10,minecraft:mossy_cobblestone,10,minecraft:stone_bricks,100)
RB(2,14,5,minecraft:mossy_stone_bricks,10,minecraft:cracked_stone_bricks,10,minecraft:cobblestone,10,minecraft:mossy_cobblestone,10,minecraft:stone_bricks,100)
RB(3,14,5,minecraft:mossy_stone_bricks,10,minecraft:cracked_stone_bricks,10,minecraft:cobblestone,10,minecraft:mossy_cobblestone,10,minecraft:stone_bricks,100)
RB(4,14,5,minecraft:mossy_stone_bricks,10,minecraft:cracked_stone_bricks,10,minecraft:cobblestone,10,minecraft:mossy_cobblestone,10,minecraft:stone_bricks,100)
RB(6,14,5,minecraft:skeleton_skull,./StructureNBT/Skulls/dungeon_skull_01.nbt,6,minecraft:air,9,minecraft:skeleton_skull,./StructureNBT/Skulls/dungeon_skull_02.nbt,12,minecraft:air,15,minecraft:skeleton_skull,./StructureNBT/Skulls/dungeon_skull_03.nbt,18,minecraft:air,21,minecraft:skeleton_skull,./StructureNBT/Skulls/dungeon_skull_04.nbt,24,minecraft:air,27,minecraft:skeleton_skull,./StructureNBT/Skulls/dungeon_skull_05.nbt,30,minecraft:air,33,minecraft:skeleton_skull,./StructureNBT/Skulls/dungeon_skull_06.nbt,36,minecraft:air,39,minecraft:skeleton_skull,./StructureNBT/Skulls/dungeon_skull_07.nbt,42,minecraft:air,45,minecraft:skeleton_skull,./StructureNBT/Skulls/dungeon_skull_08.nbt,48,minecraft:air,51,minecraft:skeleton_skull,./StructureNBT/Skulls/dungeon_skull_09.nbt,54,minecraft:air,57,minecraft:skeleton_skull,./StructureNBT/Skulls/dungeon_skull_10.nbt,60,minecraft:air,63,minecraft:skeleton_skull,./StructureNBT/Skulls/dungeon_skull_11.nbt,66,minecraft:air,69,minecraft:skeleton_skull,./StructureNBT/Skulls/dungeon_skull_12.nbt,72,minecraft:air,75,minecraft:skeleton_skull,./StructureNBT/Skulls/dungeon_skull_13.nbt,78,minecraft:air,81,minecraft:skeleton_skull,./StructureNBT/Skulls/dungeon_skull_14.nbt,84,minecraft:air,87,minecraft:skeleton_skull,./StructureNBT/Skulls/dungeon_skull_15.nbt,90,minecraft:air,93,minecraft:skeleton_skull,./StructureNBT/Skulls/dungeon_skull_16.nbt,96,minecraft:air,100)
RB(4,15,1,minecraft:mossy_stone_bricks,10,minecraft:cracked_stone_bricks,10,minecraft:cobblestone,10,minecraft:mossy_cobblestone,10,minecraft:stone_bricks,100)
RB(5,15,1,minecraft:mossy_stone_bricks,10,minecraft:cracked_stone_bricks,10,minecraft:cobblestone,10,minecraft:mossy_cobblestone,10,minecraft:stone_bricks,100)
RB(6,15,1,minecraft:mossy_stone_bricks,10,minecraft:cracked_stone_bricks,10,minecraft:cobblestone,10,minecraft:mossy_cobblestone,10,minecraft:stone_bricks,100)
RB(5,15,2,minecraft:mossy_stone_bricks,10,minecraft:cracked_stone_bricks,10,minecraft:cobblestone,10,minecraft:mossy_cobblestone,10,minecraft:stone_bricks,100)
RB(2,15,3,minecraft:mossy_stone_bricks,10,minecraft:cracked_stone_bricks,10,minecraft:cobblestone,10,minecraft:mossy_cobblestone,10,minecraft:stone_bricks,100)
RB(3,15,3,minecraft:mossy_stone_bricks,10,minecraft:cracked_stone_bricks,10,minecraft:cobblestone,10,minecraft:mossy_cobblestone,10,minecraft:stone_bricks,100)
RB(4,15,3,minecraft:mossy_stone_bricks,10,minecraft:cracked_stone_bricks,10,minecraft:cobblestone,10,minecraft:mossy_cobblestone,10,minecraft:stone_bricks,100)
RB(5,15,3,minecraft:mossy_stone_bricks,10,minecraft:cracked_stone_bricks,10,minecraft:cobblestone,10,minecraft:mossy_cobblestone,10,minecraft:stone_bricks,100)
RB(6,15,3,minecraft:mossy_stone_bricks,10,minecraft:cracked_stone_bricks,10,minecraft:cobblestone,10,minecraft:mossy_cobblestone,10,minecraft:stone_bricks,100)
RB(2,15,4,minecraft:mossy_stone_bricks,10,minecraft:cracked_stone_bricks,10,minecraft:cobblestone,10,minecraft:mossy_cobblestone,10,minecraft:stone_bricks,100)
RB(3,15,4,minecraft:mossy_stone_bricks,10,minecraft:cracked_stone_bricks,10,minecraft:cobblestone,10,minecraft:mossy_cobblestone,10,minecraft:stone_bricks,100)
RB(4,15,4,minecraft:mossy_stone_bricks,10,minecraft:cracked_stone_bricks,10,minecraft:cobblestone,10,minecraft:mossy_cobblestone,10,minecraft:stone_bricks,100)
RB(1,15,5,minecraft:mossy_stone_bricks,10,minecraft:cracked_stone_bricks,10,minecraft:cobblestone,10,minecraft:mossy_cobblestone,10,minecraft:stone_bricks,100)
RB(2,15,5,minecraft:mossy_stone_bricks,10,minecraft:cracked_stone_bricks,10,minecraft:cobblestone,10,minecraft:mossy_cobblestone,10,minecraft:stone_bricks,100)
RB(3,15,5,minecraft:mossy_stone_bricks,10,minecraft:cracked_stone_bricks,10,minecraft:cobblestone,10,minecraft:mossy_cobblestone,10,minecraft:stone_bricks,100)
RB(4,15,5,minecraft:mossy_stone_bricks,10,minecraft:cracked_stone_bricks,10,minecraft:cobblestone,10,minecraft:mossy_cobblestone,10,minecraft:stone_bricks,100)
RB(2,16,0,minecraft:cobweb,8,minecraft:air,100)
RB(5,16,0,minecraft:mossy_stone_bricks,10,minecraft:cracked_stone_bricks,10,minecraft:cobblestone,10,minecraft:mossy_cobblestone,10,minecraft:stone_bricks,100)
RB(6,16,0,minecraft:mossy_stone_bricks,10,minecraft:cracked_stone_bricks,10,minecraft:cobblestone,10,minecraft:mossy_cobblestone,10,minecraft:stone_bricks,100)
RB(0,16,1,minecraft:cobweb,8,minecraft:air,100)
RB(1,16,1,minecraft:cobweb,8,minecraft:air,100)
RB(2,16,1,minecraft:cobweb,8,minecraft:air,100)
RB(4,16,1,minecraft:mossy_stone_bricks,10,minecraft:cracked_stone_bricks,10,minecraft:cobblestone,10,minecraft:mossy_cobblestone,10,minecraft:stone_bricks,100)
RB(5,16,1,minecraft:mossy_stone_bricks,10,minecraft:cracked_stone_bricks,10,minecraft:cobblestone,10,minecraft:mossy_cobblestone,10,minecraft:stone_bricks,100)
RB(6,16,1,minecraft:mossy_stone_bricks,10,minecraft:cracked_stone_bricks,10,minecraft:cobblestone,10,minecraft:mossy_cobblestone,10,minecraft:stone_bricks,100)
RB(0,16,2,minecraft:cobweb,8,minecraft:air,100)
RB(2,16,2,minecraft:cobweb,8,minecraft:air,100)
RB(3,16,2,minecraft:mossy_stone_bricks,10,minecraft:cracked_stone_bricks,10,minecraft:cobblestone,10,minecraft:mossy_cobblestone,10,minecraft:stone_bricks,100)
RB(5,16,2,minecraft:mossy_stone_bricks,10,minecraft:cracked_stone_bricks,10,minecraft:cobblestone,10,minecraft:mossy_cobblestone,10,minecraft:stone_bricks,100)
RB(2,16,3,minecraft:mossy_stone_bricks,10,minecraft:cracked_stone_bricks,10,minecraft:cobblestone,10,minecraft:mossy_cobblestone,10,minecraft:stone_bricks,100)
RB(3,16,3,minecraft:mossy_stone_bricks,10,minecraft:cracked_stone_bricks,10,minecraft:cobblestone,10,minecraft:mossy_cobblestone,10,minecraft:stone_bricks,100)
RB(4,16,3,minecraft:mossy_stone_bricks,10,minecraft:cracked_stone_bricks,10,minecraft:cobblestone,10,minecraft:mossy_cobblestone,10,minecraft:stone_bricks,100)
RB(5,16,3,minecraft:mossy_stone_bricks,10,minecraft:cracked_stone_bricks,10,minecraft:cobblestone,10,minecraft:mossy_cobblestone,10,minecraft:stone_bricks,100)
RB(6,16,3,minecraft:mossy_stone_bricks,10,minecraft:cracked_stone_bricks,10,minecraft:cobblestone,10,minecraft:mossy_cobblestone,10,minecraft:stone_bricks,100)
RB(1,16,4,minecraft:mossy_stone_bricks,10,minecraft:cracked_stone_bricks,10,minecraft:cobblestone,10,minecraft:mossy_cobblestone,10,minecraft:stone_bricks,100)
RB(2,16,4,minecraft:mossy_stone_bricks,10,minecraft:cracked_stone_bricks,10,minecraft:cobblestone,10,minecraft:mossy_cobblestone,10,minecraft:stone_bricks,100)
RB(3,16,4,minecraft:mossy_stone_bricks,10,minecraft:cracked_stone_bricks,10,minecraft:cobblestone,10,minecraft:mossy_cobblestone,10,minecraft:stone_bricks,100)
RB(4,16,4,minecraft:mossy_stone_bricks,10,minecraft:cracked_stone_bricks,10,minecraft:cobblestone,10,minecraft:mossy_cobblestone,10,minecraft:stone_bricks,100)
RB(1,16,5,minecraft:mossy_stone_bricks,10,minecraft:cracked_stone_bricks,10,minecraft:cobblestone,10,minecraft:mossy_cobblestone,10,minecraft:stone_bricks,100)
RB(2,16,5,minecraft:mossy_stone_bricks,10,minecraft:cracked_stone_bricks,10,minecraft:cobblestone,10,minecraft:mossy_cobblestone,10,minecraft:stone_bricks,100)
RB(3,16,5,minecraft:mossy_stone_bricks,10,minecraft:cracked_stone_bricks,10,minecraft:cobblestone,10,minecraft:mossy_cobblestone,10,minecraft:stone_bricks,100)
RB(4,16,5,minecraft:mossy_stone_bricks,10,minecraft:cracked_stone_bricks,10,minecraft:cobblestone,10,minecraft:mossy_cobblestone,10,minecraft:stone_bricks,100)
RB(3,16,6,minecraft:cobweb,8,minecraft:air,100)
RB(4,16,6,minecraft:cobweb,8,minecraft:air,100)
RB(3,16,7,minecraft:cobweb,8,minecraft:air,100)
RB(4,16,7,minecraft:cobweb,8,minecraft:air,100)
RB(5,17,0,minecraft:mossy_stone_bricks,10,minecraft:cracked_stone_bricks,10,minecraft:cobblestone,10,minecraft:mossy_cobblestone,10,minecraft:stone_bricks,100)
RB(0,17,1,minecraft:mossy_stone_bricks,10,minecraft:cracked_stone_bricks,10,minecraft:cobblestone,10,minecraft:mossy_cobblestone,10,minecraft:stone_bricks,100)
RB(1,17,1,minecraft:mossy_stone_bricks,10,minecraft:cracked_stone_bricks,10,minecraft:cobblestone,10,minecraft:mossy_cobblestone,10,minecraft:stone_bricks,100)
RB(2,17,1,minecraft:mossy_stone_bricks,10,minecraft:cracked_stone_bricks,10,minecraft:cobblestone,10,minecraft:mossy_cobblestone,10,minecraft:stone_bricks,100)
RB(3,17,1,minecraft:mossy_stone_bricks,10,minecraft:cracked_stone_bricks,10,minecraft:cobblestone,10,minecraft:mossy_cobblestone,10,minecraft:stone_bricks,100)
RB(4,17,1,minecraft:mossy_stone_bricks,10,minecraft:cracked_stone_bricks,10,minecraft:cobblestone,10,minecraft:mossy_cobblestone,10,minecraft:stone_bricks,100)
RB(5,17,1,minecraft:mossy_stone_bricks,10,minecraft:cracked_stone_bricks,10,minecraft:cobblestone,10,minecraft:mossy_cobblestone,10,minecraft:stone_bricks,100)
RB(6,17,1,minecraft:mossy_stone_bricks,10,minecraft:cracked_stone_bricks,10,minecraft:cobblestone,10,minecraft:mossy_cobblestone,10,minecraft:stone_bricks,100)
RB(3,17,2,minecraft:mossy_stone_bricks,10,minecraft:cracked_stone_bricks,10,minecraft:cobblestone,10,minecraft:mossy_cobblestone,10,minecraft:stone_bricks,100)
RB(5,17,2,minecraft:mossy_stone_bricks,10,minecraft:cracked_stone_bricks,10,minecraft:cobblestone,10,minecraft:mossy_cobblestone,10,minecraft:stone_bricks,100)
RB(2,17,3,minecraft:mossy_stone_bricks,10,minecraft:cracked_stone_bricks,10,minecraft:cobblestone,10,minecraft:mossy_cobblestone,10,minecraft:stone_bricks,100)
RB(3,17,3,minecraft:mossy_stone_bricks,10,minecraft:cracked_stone_bricks,10,minecraft:cobblestone,10,minecraft:mossy_cobblestone,10,minecraft:stone_bricks,100)
RB(4,17,3,minecraft:mossy_stone_bricks,10,minecraft:cracked_stone_bricks,10,minecraft:cobblestone,10,minecraft:mossy_cobblestone,10,minecraft:stone_bricks,100)
RB(5,17,3,minecraft:mossy_stone_bricks,10,minecraft:cracked_stone_bricks,10,minecraft:cobblestone,10,minecraft:mossy_cobblestone,10,minecraft:stone_bricks,100)
RB(6,17,3,minecraft:mossy_stone_bricks,10,minecraft:cracked_stone_bricks,10,minecraft:cobblestone,10,minecraft:mossy_cobblestone,10,minecraft:stone_bricks,100)
RB(1,17,4,minecraft:mossy_stone_bricks,10,minecraft:cracked_stone_bricks,10,minecraft:cobblestone,10,minecraft:mossy_cobblestone,10,minecraft:stone_bricks,100)
RB(2,17,4,minecraft:mossy_stone_bricks,10,minecraft:cracked_stone_bricks,10,minecraft:cobblestone,10,minecraft:mossy_cobblestone,10,minecraft:stone_bricks,100)
RB(3,17,4,minecraft:mossy_stone_bricks,10,minecraft:cracked_stone_bricks,10,minecraft:cobblestone,10,minecraft:mossy_cobblestone,10,minecraft:stone_bricks,100)
RB(4,17,4,minecraft:mossy_stone_bricks,10,minecraft:cracked_stone_bricks,10,minecraft:cobblestone,10,minecraft:mossy_cobblestone,10,minecraft:stone_bricks,100)
RB(0,17,5,minecraft:mossy_stone_bricks,10,minecraft:cracked_stone_bricks,10,minecraft:cobblestone,10,minecraft:mossy_cobblestone,10,minecraft:stone_bricks,100)
RB(1,17,5,minecraft:mossy_stone_bricks,10,minecraft:cracked_stone_bricks,10,minecraft:cobblestone,10,minecraft:mossy_cobblestone,10,minecraft:stone_bricks,100)
RB(2,17,5,minecraft:mossy_stone_bricks,10,minecraft:cracked_stone_bricks,10,minecraft:cobblestone,10,minecraft:mossy_cobblestone,10,minecraft:stone_bricks,100)
RB(3,17,5,minecraft:mossy_stone_bricks,10,minecraft:cracked_stone_bricks,10,minecraft:cobblestone,10,minecraft:mossy_cobblestone,10,minecraft:stone_bricks,100)
RB(4,17,5,minecraft:mossy_stone_bricks,10,minecraft:cracked_stone_bricks,10,minecraft:cobblestone,10,minecraft:mossy_cobblestone,10,minecraft:stone_bricks,100)
RB(5,17,5,minecraft:mossy_stone_bricks,10,minecraft:cracked_stone_bricks,10,minecraft:cobblestone,10,minecraft:mossy_cobblestone,10,minecraft:stone_bricks,100)
RB(2,17,6,minecraft:mossy_stone_bricks,10,minecraft:cracked_stone_bricks,10,minecraft:cobblestone,10,minecraft:mossy_cobblestone,10,minecraft:stone_bricks,100)
RB(3,17,6,minecraft:mossy_stone_bricks,10,minecraft:cracked_stone_bricks,10,minecraft:cobblestone,10,minecraft:mossy_cobblestone,10,minecraft:stone_bricks,100)
RB(4,17,6,minecraft:mossy_stone_bricks,10,minecraft:cracked_stone_bricks,10,minecraft:cobblestone,10,minecraft:mossy_cobblestone,10,minecraft:stone_bricks,100)
RB(2,17,7,minecraft:mossy_stone_bricks,10,minecraft:cracked_stone_bricks,10,minecraft:cobblestone,10,minecraft:mossy_cobblestone,10,minecraft:stone_bricks,100)
RB(3,17,7,minecraft:mossy_stone_bricks,10,minecraft:cracked_stone_bricks,10,minecraft:cobblestone,10,minecraft:mossy_cobblestone,10,minecraft:stone_bricks,100)
RB(4,17,7,minecraft:mossy_stone_bricks,10,minecraft:cracked_stone_bricks,10,minecraft:cobblestone,10,minecraft:mossy_cobblestone,10,minecraft:stone_bricks,100)
RB(3,18,0,minecraft:mossy_stone_bricks,10,minecraft:cracked_stone_bricks,10,minecraft:cobblestone,10,minecraft:mossy_cobblestone,10,minecraft:stone_bricks,100)
RB(4,18,0,minecraft:mossy_stone_bricks,10,minecraft:cracked_stone_bricks,10,minecraft:cobblestone,10,minecraft:mossy_cobblestone,10,minecraft:stone_bricks,100)
