
#######################################################################
# +-----------------------------------------------------------------+ #
# |                            BO3 object                           | #
# +-----------------------------------------------------------------+ #
#######################################################################

Author: NLBlackEagle

Description: No description given

Version: 3

SettingsMode: WriteDisable


#######################################################################
# +-----------------------------------------------------------------+ #
# |                          Main settings                          | #
# +-----------------------------------------------------------------+ #
#######################################################################

Tree: true

Frequency: 1

Rarity: 100.0

RotateRandomly: true

SpawnHeight: randomY

SpawnHeightOffset: 0

SpawnHeightVariance: 0

##############################
# Height Limits for the BO3. #
##############################

MinHeight: 90

MaxHeight: 77

######################
# Extrusion settings #
######################

ExtrudeMode: None

ExtrudeThroughBlocks: AIR

MaxBranchDepth: 10

ExcludedBiomes: All


#######################################################################
# +-----------------------------------------------------------------+ #
# |                      Source block settings                      | #
# +-----------------------------------------------------------------+ #
#######################################################################

SourceBlocks: AIR,GRASS,DIRT,SAND

MaxPercentageOutsideSourceBlock: 0

OutsideSourceBlock: placeAnyway

IsOTGPlus: false

InheritBO3: 

InheritBO3Rotation: NORTH

OverrideChildSettings: true

OverrideParentHeight: false

CanOverride: false

BranchFrequency: 0

BranchFrequencyGroup: 

MustBeBelowOther: false

MustBeInside: 

CannotBeInside: 

ReplacesBO3: 

CanSpawnOnWater: true

SpawnOnWaterOnly: false

SpawnUnderWater: false

SpawnAtWaterLevel: false

HeightOffset: 0

RemoveAir: true

ReplaceAbove: 

ReplaceBelow: 

ReplaceWithBiomeBlocks: true

ReplaceWithGroundBlock: DIRT

ReplaceWithSurfaceBlock: GRASS

SmoothRadius: 0

SmoothHeightOffset: 0

SmoothStartTop: false

SmoothStartWood: false

SmoothingSurfaceBlock: 

SmoothingGroundBlock: 

BO3Group: 

IsSpawnPoint: false


#######################################################################
# +-----------------------------------------------------------------+ #
# |                              Blocks                             | #
# +-----------------------------------------------------------------+ #
#######################################################################

Block(-11,10,-5,leaves:3)
Block(-11,11,-5,leaves:3)
Block(-10,7,-5,leaves:3)
Block(-10,10,-1,leaves:3)
Block(-10,11,-9,leaves:3)
Block(-10,11,-5,leaves:3)
Block(-10,12,-8,leaves:3)
Block(-10,12,-5,leaves:3)
Block(-9,8,-8,leaves:3)
Block(-9,8,-5,leaves:3)
Block(-9,8,-2,leaves:3)
Block(-9,11,-4,leaves:3)
Block(-9,11,-2,leaves:3)
Block(-9,12,-5,leaves:3)
Block(-9,12,-2,leaves:3)
Block(-9,13,-8,leaves:3)
Block(-9,13,-5,leaves:3)
Block(-9,15,-2,leaves:3)
Block(-8,8,-5,leaves:3)
Block(-8,9,-7,leaves:3)
Block(-8,9,-3,leaves:3)
Block(-8,9,-2,leaves:3)
Block(-8,10,-7,leaves:3)
Block(-8,11,-5,leaves:3)
Block(-8,12,-6,leaves:3)
Block(-8,12,-5,leaves:3)
Block(-8,12,-3,leaves:3)
Block(-8,13,-7,leaves:3)
Block(-8,14,-3,leaves:3)
Block(-8,15,-5,leaves:3)
Block(-8,16,-7,leaves:3)
Block(-7,9,-5,leaves:3)
Block(-7,10,-6,leaves:3)
Block(-7,10,-5,leaves:3)
Block(-7,10,-3,leaves:3)
Block(-7,11,-6,leaves:3)
Block(-7,11,-5,leaves:3)
Block(-7,11,-4,leaves:3)
Block(-7,12,-7,leaves:3)
Block(-7,12,-5,leaves:3)
Block(-7,12,-4,leaves:3)
Block(-7,13,-5,leaves:3)
Block(-7,13,-4,leaves:3)
Block(-7,13,-3,leaves:3)
Block(-7,14,-7,leaves:3)
Block(-7,14,-6,leaves:3)
Block(-7,14,-5,leaves:3)
Block(-7,14,-4,leaves:3)
Block(-7,15,-6,leaves:3)
Block(-6,7,-5,SPRUCE_WOOD_STAIRS:4)
Block(-6,8,-8,leaves:3)
Block(-6,8,-5,LOG:15)
Block(-6,8,-2,leaves:3)
Block(-6,9,-8,leaves:3)
Block(-6,9,-7,leaves:3)
Block(-6,9,-5,LOG:15)
Block(-6,9,-3,leaves:3)
Block(-6,10,-6,leaves:3)
Block(-6,10,-5,LOG:15)
Block(-6,10,-4,leaves:3)
Block(-6,11,-8,leaves:3)
Block(-6,11,-7,leaves:3)
Block(-6,11,-6,leaves:3)
Block(-6,11,-5,leaves:3)
Block(-6,11,-4,leaves:3)
Block(-6,11,-3,leaves:3)
Block(-6,11,-1,leaves:3)
Block(-6,12,-7,leaves:3)
Block(-6,12,-6,leaves:3)
Block(-6,12,-5,leaves:3)
Block(-6,12,-4,leaves:3)
Block(-6,12,-2,leaves:3)
Block(-6,13,-7,leaves:3)
Block(-6,13,-6,leaves:3)
Block(-6,13,-5,leaves:3)
Block(-6,13,-4,leaves:3)
Block(-6,14,-6,leaves:3)
Block(-6,14,-5,leaves:3)
Block(-5,-3,1,LOG:15)
Block(-5,-2,1,LOG:15)
Block(-5,6,-5,LOG:15)
Block(-5,7,-5,LOG:15)
Block(-5,8,-5,WOOD_STEP:1)
Block(-5,9,-6,leaves:3)
Block(-5,9,0,leaves:3)
Block(-5,10,-7,leaves:3)
Block(-5,10,-6,leaves:3)
Block(-5,10,-5,leaves:3)
Block(-5,10,-3,leaves:3)
Block(-5,10,-1,leaves:3)
Block(-5,11,-7,leaves:3)
Block(-5,11,-6,leaves:3)
Block(-5,11,-5,leaves:3)
Block(-5,11,-4,leaves:3)
Block(-5,12,-7,leaves:3)
Block(-5,12,-6,leaves:3)
Block(-5,12,-5,leaves:3)
Block(-5,13,-8,leaves:3)
Block(-5,13,-6,leaves:3)
Block(-5,13,-5,leaves:3)
Block(-5,14,-6,leaves:3)
Block(-5,14,-4,leaves:3)
Block(-5,15,-6,leaves:3)
Block(-5,15,-3,leaves:3)
Block(-4,-2,-5,LOG:15)
Block(-4,-2,1,LOG:15)
Block(-4,-1,-5,LOG:15)
Block(-4,-1,-4,LOG:15)
Block(-4,-1,1,LOG:15)
Block(-4,0,1,LOG:15)
Block(-4,4,-4,WOOD_STEP:9)
Block(-4,5,-4,LOG:15)
Block(-4,6,-4,SPRUCE_WOOD_STAIRS:1)
Block(-4,8,-3,leaves:3)
Block(-4,9,-7,leaves:3)
Block(-4,9,-5,leaves:3)
Block(-4,9,-3,leaves:3)
Block(-4,10,-7,leaves:3)
Block(-4,11,-5,leaves:3)
Block(-4,12,-9,leaves:3)
Block(-4,12,-6,leaves:3)
Block(-4,12,-5,leaves:3)
Block(-4,12,-3,leaves:3)
Block(-4,13,-9,leaves:3)
Block(-4,14,-7,leaves:3)
Block(-4,16,-5,leaves:3)
Block(-3,-1,-4,LOG:15)
Block(-3,-1,-3,LOG:15)
Block(-3,0,1,LOG:15)
Block(-3,3,-3,WOOD_STEP:9)
Block(-3,4,-3,LOG:15)
Block(-3,5,-3,WOOD_STEP:1)
Block(-3,7,-2,leaves:3)
Block(-3,8,-8,leaves:3)
Block(-3,8,-5,leaves:3)
Block(-3,11,-10,leaves:3)
Block(-3,11,-2,leaves:3)
Block(-3,12,-7,leaves:3)
Block(-3,12,-5,leaves:3)
Block(-3,12,-2,leaves:3)
Block(-2,-1,-3,LOG:15)
Block(-2,0,0,LOG:15)
Block(-2,0,1,LOG:15)
Block(-2,1,0,LOG:15)
Block(-2,3,-2,SPRUCE_WOOD_STAIRS:6)
Block(-2,4,-2,LOG:15)
Block(-2,8,-5,leaves:3)
Block(-2,10,-8,leaves:3)
Block(-2,11,-7,leaves:3)
Block(-2,12,-4,leaves:3)
Block(-2,13,-4,leaves:3)
Block(-1,-1,-2,LOG:15)
Block(-1,0,-2,LOG:15)
Block(-1,0,-1,LOG:15)
Block(-1,1,0,LOG:15)
Block(-1,2,-1,SPRUCE_WOOD_STAIRS:6)
Block(-1,2,0,SPRUCE_WOOD_STAIRS:0)
Block(-1,3,-1,LOG:15)
Block(-1,4,-1,WOOD_STEP:1)
Block(-1,10,-5,leaves:3)
Block(-1,11,-5,leaves:3)
Block(-1,12,-4,leaves:3)
Block(0,-3,0,LOG:15)
Block(0,-3,2,LOG:15)
Block(0,-2,0,LOG:15)
Block(0,-2,2,LOG:15)
Block(0,-1,0,LOG:15)
Block(0,-1,1,LOG:15)
Block(0,-1,2,LOG:15)
Block(0,0,0,LOG:15)
Block(0,0,1,LOG:15)
Block(0,0,2,LOG:15)
Block(0,1,-1,LOG:15)
Block(0,1,0,LOG:15)
Block(0,1,1,LOG:15)
Block(0,2,-1,LOG:15)
Block(0,2,0,LOG:15)
Block(0,2,1,WOOD_STEP:1)
Block(0,3,-1,SPRUCE_WOOD_STAIRS:2)
Block(0,3,0,WOOD_STEP:1)
Block(1,-2,0,LOG:15)
Block(1,-1,0,LOG:15)
Block(1,0,-4,LOG:15)
Block(1,0,-3,LOG:15)
Block(1,0,-2,LOG:15)
Block(1,0,0,LOG:15)
Block(1,1,-2,LOG:15)
Block(1,1,-1,LOG:15)
Block(1,1,0,LOG:15)
Block(1,2,0,SPRUCE_WOOD_STAIRS:1)
Block(2,-3,0,LOG:15)
Block(2,-2,0,LOG:15)
Block(2,-1,-6,LOG:15)
Block(2,-1,0,LOG:15)
Block(2,0,-6,LOG:15)
Block(2,0,-5,LOG:15)
Block(2,0,-4,LOG:15)

#######################################################################
# +-----------------------------------------------------------------+ #
# |                            BO3 checks                           | #
# +-----------------------------------------------------------------+ #
#######################################################################
BlockCheck(-5,-4,1,DIRT,GRASS,SAND)
BlockCheck(0,-4,0,DIRT,GRASS,SAND)
BlockCheck(0,-4,2,DIRT,GRASS,SAND)
BlockCheck(2,-4,0,DIRT,GRASS,SAND)
BlockCheckNot(0,1,0,Solid)
BlockCheck(0,-1,0,DIRT,GRASS,SAND)
BlockCheck(0,-2,0,DIRT,GRASS,SAND,STONE)

BlockCheck(1,-2,0,DIRT,GRASS,SAND,STONE)
BlockCheck(0,-2,1,DIRT,GRASS,SAND,STONE)
BlockCheck(0,-2,-1,DIRT,GRASS,SAND,STONE)
BlockCheck(-1,-2,0,DIRT,GRASS,SAND,STONE)

#######################################################################
# +-----------------------------------------------------------------+ #
# |                             Branches                            | #
# +-----------------------------------------------------------------+ #
#######################################################################


#######################################################################
# +-----------------------------------------------------------------+ #
# |                             Entities                            | #
# +-----------------------------------------------------------------+ #
#######################################################################


#######################################################################
# +-----------------------------------------------------------------+ #
# |                            Particles                            | #
# +-----------------------------------------------------------------+ #
#######################################################################


#######################################################################
# +-----------------------------------------------------------------+ #
# |                             Spawners                            | #
# +-----------------------------------------------------------------+ #
#######################################################################


#######################################################################
# +-----------------------------------------------------------------+ #
# |                             ModData                             | #
# +-----------------------------------------------------------------+ #
#######################################################################

