Author: Bo3 BulkEdit

Description: Converted Schematic - Modified by Bo3BulkEdit

Version: 3

SettingsMode: WriteDisable

IsOTGPlus: false
Tree: true
Frequency: 100
Rarity: 100
RotateRandomly: true
SpawnHeight: randomY
MaxBranchDepth: 10
ExcludedBiomes: All

MinHeight: 85
MaxHeight: 150

SourceBlocks: AIR,GRASS,DIRT,SAND,STONE:3,175,31,39
MaxPercentageOutsideSourceBlock: 0

Blockcheck(0,-1,0,STONE:3)

B(0,0,0,BROWN_MUSHROOM_BLOCK:10)
B(0,1,0,BROWN_MUSHROOM_BLOCK:10)
B(0,2,0,BROWN_MUSHROOM_BLOCK:10)
B(0,3,0,BROWN_MUSHROOM_BLOCK:10)
B(-2,4,0,RED_MUSHROOM_BLOCK:1)
B(-1,4,0,RED_MUSHROOM_BLOCK:1)
B(0,4,0,BROWN_MUSHROOM_BLOCK:10)
B(-2,4,1,RED_MUSHROOM_BLOCK:7)
B(-1,4,1,RED_MUSHROOM_BLOCK:1)
B(0,4,1,RED_MUSHROOM_BLOCK:9)
B(-1,4,2,RED_MUSHROOM_BLOCK:7)
B(0,4,2,RED_MUSHROOM_BLOCK:9)
B(0,5,0,BROWN_MUSHROOM_BLOCK:10)
B(0,6,0,BROWN_MUSHROOM_BLOCK:10)
B(0,7,-2,BROWN_MUSHROOM_BLOCK:1)
B(1,7,-2,BROWN_MUSHROOM_BLOCK:3)
B(0,7,-1,BROWN_MUSHROOM_BLOCK:1)
B(1,7,-1,BROWN_MUSHROOM_BLOCK:1)
B(2,7,-1,BROWN_MUSHROOM_BLOCK:3)
B(0,7,0,BROWN_MUSHROOM_BLOCK:10)
B(1,7,0,BROWN_MUSHROOM_BLOCK:9)
B(2,7,0,BROWN_MUSHROOM_BLOCK:9)
B(0,8,0,BROWN_MUSHROOM_BLOCK:10)
B(0,9,0,BROWN_MUSHROOM_BLOCK:10)
B(0,10,0,BROWN_MUSHROOM_BLOCK:10)
B(-1,11,-3,BROWN_MUSHROOM_BLOCK:1)
B(0,11,-3,BROWN_MUSHROOM_BLOCK:1)
B(1,11,-3,BROWN_MUSHROOM_BLOCK:3)
B(-2,11,-2,BROWN_MUSHROOM_BLOCK:1)
B(-1,11,-2,RED_MUSHROOM_BLOCK:1)
B(0,11,-2,BROWN_MUSHROOM_BLOCK:1)
B(1,11,-2,BROWN_MUSHROOM_BLOCK:1)
B(2,11,-2,BROWN_MUSHROOM_BLOCK:3)
B(-3,11,-1,BROWN_MUSHROOM_BLOCK:1)
B(-2,11,-1,BROWN_MUSHROOM_BLOCK:1)
B(-1,11,-1,BROWN_MUSHROOM_BLOCK:1)
B(0,11,-1,BROWN_MUSHROOM_BLOCK:1)
B(1,11,-1,RED_MUSHROOM_BLOCK:1)
B(2,11,-1,BROWN_MUSHROOM_BLOCK:9)
B(3,11,-1,BROWN_MUSHROOM_BLOCK:3)
B(-3,11,0,BROWN_MUSHROOM_BLOCK:1)
B(-2,11,0,RED_MUSHROOM_BLOCK:1)
B(-1,11,0,BROWN_MUSHROOM_BLOCK:1)
B(0,11,0,BROWN_MUSHROOM_BLOCK:1)
B(1,11,0,BROWN_MUSHROOM_BLOCK:1)
B(2,11,0,BROWN_MUSHROOM_BLOCK:9)
B(3,11,0,BROWN_MUSHROOM_BLOCK:9)
B(-3,11,1,BROWN_MUSHROOM_BLOCK:7)
B(-2,11,1,BROWN_MUSHROOM_BLOCK:1)
B(-1,11,1,RED_MUSHROOM_BLOCK:1)
B(0,11,1,BROWN_MUSHROOM_BLOCK:1)
B(1,11,1,BROWN_MUSHROOM_BLOCK:1)
B(2,11,1,BROWN_MUSHROOM_BLOCK:9)
B(3,11,1,BROWN_MUSHROOM_BLOCK:9)
B(-2,11,2,BROWN_MUSHROOM_BLOCK:7)
B(-1,11,2,BROWN_MUSHROOM_BLOCK:1)
B(0,11,2,BROWN_MUSHROOM_BLOCK:1)
B(1,11,2,RED_MUSHROOM_BLOCK:1)
B(2,11,2,BROWN_MUSHROOM_BLOCK:9)
B(-1,11,3,BROWN_MUSHROOM_BLOCK:7)
B(0,11,3,BROWN_MUSHROOM_BLOCK:7)
B(1,11,3,BROWN_MUSHROOM_BLOCK:9)

