


Author: NLBlackEagle

Description: Converted version of the BO2 TreeSwamp08

Version: 3

SettingsMode: WriteDisable



Tree: true

Frequency: 1

Rarity: 100.0

RotateRandomly: true

SpawnHeight: randomY

SpawnHeightOffset: 0

SpawnHeightVariance: 0




MinHeight: 150

MaxHeight: 170




ExtrudeMode: None

ExtrudeThroughBlocks: AIR

MaxBranchDepth: 10

ExcludedBiomes: ALL



SourceBlocks: AIR,GRASS,DIRT,SAND,WATER

MaxPercentageOutsideSourceBlock: 10

OutsideSourceBlock: placeAnyway

IsOTGPlus: false

InheritBO3: 

InheritBO3Rotation: NORTH

OverrideChildSettings: true

OverrideParentHeight: false

CanOverride: false

BranchFrequency: 0

BranchFrequencyGroup: 

MustBeBelowOther: false

MustBeInside: 

CannotBeInside: 

ReplacesBO3: 

CanSpawnOnWater: true

SpawnOnWaterOnly: false

SpawnUnderWater: false

SpawnAtWaterLevel: false

HeightOffset: 0

RemoveAir: true

ReplaceAbove: 

ReplaceBelow: 

ReplaceWithBiomeBlocks: true

ReplaceWithGroundBlock: DIRT

ReplaceWithSurfaceBlock: GRASS

SmoothRadius: 0

SmoothHeightOffset: 0

SmoothStartTop: false

SmoothStartWood: false

SmoothingSurfaceBlock: 

SmoothingGroundBlock: 

BO3Group: 

IsSpawnPoint: false



B(2,7,3,LEAVES)
B(5,6,5,LEAVES)
B(-1,6,3,LEAVES)
B(1,-1,4,LOG)
B(2,5,3,LEAVES)
B(2,6,3,LOG)
B(-1,1,3,LOG:4)
B(2,5,2,LEAVES)
B(2,6,2,LEAVES)
B(2,7,2,LEAVES)
B(5,5,5,LEAVES)
B(-1,-1,-1,LOG)
B(1,5,1,LEAVES)
B(1,4,1,LEAVES)
B(3,5,-3,LEAVES)
B(3,6,-3,LEAVES)
B(1,2,1,LOG)
B(1,1,1,LOG)
B(1,0,1,LOG)
B(1,5,4,LEAVES)
B(1,6,4,LEAVES)
B(0,2,2,LOG)
B(-1,1,0,LOG)
B(-1,0,0,LOG)
B(-1,3,0,LOG)
B(0,1,2,LOG)
B(-1,2,0,LOG)
B(0,0,2,LOG)
B(3,5,1,LOG:4)
B(3,6,1,LEAVES)
B(3,5,0,LEAVES)
B(3,6,0,LEAVES)
B(-1,5,0,LEAVES)
B(-1,6,0,LEAVES)
B(-2,-1,4,LOG)
B(3,4,0,LEAVES)
B(1,8,-6,LEAVES)
B(1,7,-6,LEAVES)
B(1,6,-6,LEAVES)
B(0,5,3,LEAVES)
B(0,6,3,LEAVES)
B(0,6,2,LEAVES)
B(1,7,-7,LEAVES)
B(1,7,-5,LEAVES)
B(1,6,-5,LEAVES)
B(1,0,4,LOG:8)
B(4,-1,4,LOG:8)
B(3,6,5,LEAVES)
B(-2,8,-5,LEAVES)
B(3,5,5,LEAVES)
B(-2,7,-5,LEAVES)
B(-2,7,-7,LEAVES)
B(-2,8,-7,LEAVES)
B(-4,4,2,LOG)
B(2,1,2,LOG)
B(-4,5,2,LEAVES)
B(-1,8,-6,LOG:8)
B(-1,9,-6,LEAVES)
B(4,5,-3,LOG:4)
B(3,0,3,LOG:4)
B(4,7,-2,LEAVES)
B(0,7,-6,LEAVES)
B(1,6,-2,LEAVES)
B(1,3,-1,LOG)
B(0,8,-6,LEAVES)
B(4,7,5,LEAVES)
B(1,7,-2,LEAVES)
B(1,4,-1,LOG)
B(1,5,-2,LOG:8)
B(5,5,6,LEAVES)
B(1,7,-1,LEAVES)
B(4,6,5,LOG)
B(1,5,-1,LOG)
B(1,6,-1,LOG)
B(4,5,5,LOG:8)
B(4,6,-2,LOG:4)
B(4,5,-2,LEAVES)
B(4,7,-3,LEAVES)
B(3,6,-2,LOG:4)
B(-2,5,0,LEAVES)
B(3,7,-2,LEAVES)
B(4,6,-3,LOG:4)
B(1,6,-3,LEAVES)
B(5,6,4,LEAVES)
B(1,2,0,LOG)
B(1,5,-3,LEAVES)
B(1,0,0,LOG:8)
B(3,7,-4,LEAVES)
B(1,5,0,LOG)
B(1,6,0,LOG)
B(3,6,-4,LEAVES)
B(1,3,0,LOG)
B(3,5,-4,LEAVES)
B(1,7,-3,LEAVES)
B(1,4,0,LOG)
B(1,7,-4,LEAVES)
B(1,6,-4,LEAVES)
B(0,0,3,LOG)
B(0,1,3,LOG)
B(-3,5,-2,LEAVES)
B(-2,1,3,LOG:4)
B(3,-1,2,LOG:4)
B(-2,6,3,LEAVES)
B(-2,5,3,LEAVES)
B(0,0,1,LOG)
B(3,6,-6,LEAVES)
B(-3,4,3,LEAVES)
B(0,2,1,LOG)
B(-3,5,3,LEAVES)
B(0,1,1,LOG)
B(0,4,1,LEAVES)
B(0,3,1,LOG)
B(-2,1,4,LOG:8)
B(0,6,1,LEAVES)
B(-2,0,4,LOG)
B(0,5,1,LEAVES)
B(4,5,1,LEAVES)
B(1,7,1,LEAVES)
B(1,6,1,LEAVES)
B(-5,4,3,LEAVES)
B(5,4,-3,LEAVES)
B(5,5,-3,LOG:8)
B(5,6,-3,LEAVES)
B(0,7,-2,LEAVES)
B(3,6,6,LEAVES)
B(-4,4,1,LOG)
B(2,4,1,LEAVES)
B(1,7,0,LEAVES)
B(-4,5,1,LEAVES)
B(0,5,-2,LOG:8)
B(0,6,-2,LEAVES)
B(3,7,4,LEAVES)
B(-2,7,-6,LEAVES)
B(3,6,4,LEAVES)
B(-2,8,-6,LEAVES)
B(-3,8,-6,LEAVES)
B(-4,5,3,LEAVES)
B(-3,7,-6,LEAVES)
B(2,0,3,LOG:4)
B(-4,4,3,LOG)
B(5,6,2,LEAVES)
B(1,0,3,LOG:8)
B(3,5,2,LOG:8)
B(3,6,2,LOG)
B(2,6,0,LEAVES)
B(3,7,2,LEAVES)
B(-1,6,2,LEAVES)
B(5,6,3,LEAVES)
B(-1,7,1,LEAVES)
B(3,6,3,LOG:4)
B(0,2,0,LOG)
B(3,7,3,LEAVES)
B(0,3,0,LOG)
B(-4,4,4,LEAVES)
B(0,0,0,LOG)
B(-3,7,-5,LEAVES)
B(0,1,0,LOG)
B(0,6,0,LOG)
B(0,6,-5,LEAVES)
B(-1,3,1,LOG)
B(1,-1,0,LOG)
B(0,7,0,LEAVES)
B(0,7,-5,LOG:8)
B(2,6,1,LEAVES)
B(0,4,0,LOG)
B(-1,6,1,LEAVES)
B(0,5,0,LOG)
B(2,5,1,LOG:4)
B(3,5,3,LOG:4)
B(-1,0,1,LOG)
B(0,5,-3,LOG:8)
B(1,7,2,LEAVES)
B(4,6,6,LEAVES)
B(1,6,2,LEAVES)
B(-1,2,1,LOG)
B(0,8,-5,LEAVES)
B(-1,1,1,LOG)
B(1,5,2,LEAVES)
B(0,7,-3,LEAVES)
B(-3,5,-1,LEAVES)
B(0,6,-3,LOG:8)
B(5,6,-4,LEAVES)
B(-4,5,0,LEAVES)
B(5,5,-4,LOG)
B(5,4,-4,LOG:8)
B(1,7,3,LEAVES)
B(1,6,3,LOG)
B(4,5,6,LEAVES)
B(1,5,3,LOG:4)
B(3,6,-5,LEAVES)
B(4,5,2,LEAVES)
B(4,7,2,LEAVES)
B(4,6,2,LEAVES)
B(4,5,4,LEAVES)
B(4,6,4,LOG)
B(4,7,4,LEAVES)
B(0,7,-7,LEAVES)
B(0,8,-7,LEAVES)
B(-3,5,2,LEAVES)
B(-3,4,2,LEAVES)
B(-3,4,1,LOG)
B(-3,3,1,LOG)
B(-1,7,-8,LOG:8)
B(-1,8,-8,LOG)
B(-3,5,1,LEAVES)
B(0,3,-1,LOG)
B(0,2,-1,LOG)
B(0,7,-1,LEAVES)
B(0,6,-1,LEAVES)
B(0,5,-1,LOG)
B(0,4,-1,LOG)
B(0,6,4,LEAVES)
B(-3,7,-7,LEAVES)
B(1,1,2,LOG)
B(1,2,2,LOG)
B(1,0,2,LOG)
B(5,6,-2,LEAVES)
B(-5,4,2,LOG)
B(5,5,-2,LEAVES)
B(-5,5,2,LEAVES)
B(4,5,-4,LEAVES)
B(-2,6,-2,LEAVES)
B(4,6,-4,LEAVES)
B(2,6,4,LEAVES)
B(-2,5,-2,LOG:4)
B(0,7,1,LEAVES)
B(2,3,0,LEAVES)
B(3,1,2,LOG)
B(3,6,-1,LEAVES)
B(3,0,2,LOG)
B(2,4,0,LOG)
B(2,6,5,LEAVES)
B(4,4,-4,LEAVES)
B(6,5,-3,LEAVES)
B(2,5,0,LOG)
B(4,6,-1,LEAVES)
B(-2,6,2,LEAVES)
B(-2,5,2,LEAVES)
B(-1,8,-4,LEAVES)
B(-2,4,2,LEAVES)
B(-1,7,-4,LEAVES)
B(-1,6,-4,LEAVES)
B(-2,5,1,LEAVES)
B(-2,4,1,LOG)
B(-2,3,1,LOG)
B(-2,2,1,LOG)
B(-1,8,-5,LEAVES)
B(-2,6,1,LEAVES)
B(0,7,-4,LOG:8)
B(0,-1,3,LOG)
B(-1,5,-2,LOG:4)
B(0,8,-4,LEAVES)
B(-1,6,-2,LEAVES)
B(-1,6,-3,LEAVES)
B(5,5,-5,LEAVES)
B(0,5,-4,LEAVES)
B(-1,7,-3,LEAVES)
B(0,6,-4,LOG:8)
B(5,4,-5,LEAVES)
B(-1,8,-9,LEAVES)
B(4,6,3,LOG:4)
B(-3,5,0,LEAVES)
B(4,7,3,LEAVES)
B(-3,4,0,LOG)
B(4,-2,2,LOG:4)
B(1,-1,2,LOG)
B(4,-1,2,LOG:8)
B(-1,9,-8,LEAVES)
B(0,7,-8,LEAVES)
B(0,8,-8,LEAVES)
B(2,6,-6,LEAVES)
B(-1,7,-7,LEAVES)
B(-1,9,-7,LEAVES)
B(-1,8,-7,LOG:8)
B(-2,7,-8,LEAVES)
B(2,6,-5,LEAVES)
B(-2,8,-8,LEAVES)
B(2,7,-3,LEAVES)
B(0,-1,0,LOG)
B(2,6,-3,LEAVES)
B(2,5,-3,LEAVES)
B(-1,7,-9,LEAVES)
B(5,-2,2,LOG:4)
B(2,6,-4,LEAVES)
B(6,5,-4,LEAVES)
B(6,4,-4,LEAVES)
B(4,5,-5,LEAVES)
B(4,6,-5,LEAVES)
B(-2,5,-1,LEAVES)
B(-2,6,-3,LEAVES)
B(-1,3,-1,LOG)
B(-1,0,-1,LOG)
B(-1,6,-1,LEAVES)
B(2,6,-2,LOG:4)
B(-1,7,-1,LEAVES)
B(-1,4,-1,LOG)
B(2,5,-1,LEAVES)
B(2,7,-2,LEAVES)
B(-1,5,-1,LOG)
B(2,7,-1,LEAVES)
B(2,6,-1,LOG)
B(-2,6,-4,LEAVES)
B(-2,7,-4,LEAVES)
B(4,-1,3,LOG:8)

B(-2,3,-9,VINE:8)
B(-2,4,-9,VINE:8)
B(-2,1,-9,VINE:8)
B(-2,2,-9,VINE:8)
B(-2,7,-9,VINE:8)
B(-2,5,-9,VINE:8)
B(-2,6,-9,VINE:8)
B(1,4,-8,VINE:2)
B(1,5,-8,VINE:2)
B(1,2,-8,VINE:2)
B(1,3,-8,VINE:2)
B(1,1,-8,VINE:2)
B(1,8,-8,VINE:2)
B(1,7,-8,VINE:2)
B(1,6,-8,VINE:2)
B(-1,1,-10,VINE:1)
B(-1,3,-10,VINE:1)
B(-1,2,-10,VINE:1)
B(-1,5,-10,VINE:1)
B(-1,4,-10,VINE:1)
B(-1,7,-10,VINE:1)
B(-1,6,-10,VINE:1)
B(0,4,-9,VINE:1)
B(0,5,-9,VINE:1)
B(0,6,-9,VINE:1)
B(0,7,-9,VINE:1)
B(0,8,-9,VINE:1)
B(0,1,-9,VINE:1)
B(0,3,-9,VINE:1)
B(0,2,-9,VINE:1)



BlockCheck(-3,-2,-3,DIRT,GRASS,CLAY)
BlockCheck(-3,-2,3,DIRT,GRASS,CLAY)
BlockCheck(3,-2,-5,DIRT,GRASS,CLAY)
BlockCheck(3,-2,2,DIRT,GRASS,CLAY)
BlockCheck(2,-2,3,DIRT,GRASS,CLAY)
BlockCheckNot(-3,-2,-3,AIR,STATIONARY_WATER)
BlockCheckNot(-3,-2,3,AIR,STATIONARY_WATER)
BlockCheckNot(3,-2,-5,AIR,STATIONARY_WATER)
BlockCheckNot(3,-2,2,AIR,STATIONARY_WATER)
BlockCheckNot(2,-2,3,AIR,STATIONARY_WATER)

BlockCheckNot(0,0,0,STONE)
BlockCheckNot(0,-1,0,STONE)
BlockCheckNot(0,-2,0,STONE)
BlockCheckNot(0,-3,0,STONE)










