
#
# +-----------------------------------------------------------------+ #
# |                            BO3 object                           | #
# +-----------------------------------------------------------------+ #
#

Author: NLBlackEagle

Description: Bo3 Created by NLBlackEagle - For Dregora

Version: 3

SettingsMode: WriteDisable


#
# +-----------------------------------------------------------------+ #
# |                          Main settings                          | #
# +-----------------------------------------------------------------+ #
#

Tree: false

Frequency: 2

Rarity: 20.0

RotateRandomly: true

SpawnHeight: randomY

SpawnHeightOffset: 0

SpawnHeightVariance: 0


# Height Limits for the BO3. #


MinHeight: 3

MaxHeight: 6


# Extrusion settings #


ExtrudeMode: None

ExtrudeThroughBlocks: air

MaxBranchDepth: 10

ExcludedBiomes: All


#
# +-----------------------------------------------------------------+ #
# |                      Source block settings                      | #
# +-----------------------------------------------------------------+ #
#

SourceBlocks: air

MaxPercentageOutsideSourceBlock: 100

OutsideSourceBlock: placeAnyway


#
# +-----------------------------------------------------------------+ #
# |                              Blocks                             | #
# +-----------------------------------------------------------------+ #
#

B(-3,0,0,obsidian)
B(-3,1,0,obsidian)
B(-3,2,0,obsidian)
B(-3,3,0,obsidian)
B(-3,4,0,obsidian)
B(-3,5,0,obsidian)
B(-3,6,0,obsidian)
B(-3,7,0,prismarine)
B(-3,8,0,prismarine)
B(-2,0,-1,obsidian)
B(-2,0,0,obsidian)
B(-2,0,1,obsidian)
B(-2,1,-1,obsidian)
B(-2,1,0,obsidian)
B(-2,1,1,obsidian)
B(-2,2,-1,obsidian)
B(-2,2,0,obsidian)
B(-2,2,1,obsidian)
B(-2,3,-1,obsidian)
B(-2,3,0,obsidian)
B(-2,3,1,obsidian)
B(-2,4,-1,obsidian)
B(-2,4,0,obsidian)
B(-2,4,1,obsidian)
B(-2,5,-1,obsidian)
B(-2,5,0,obsidian)
B(-2,5,1,obsidian)
B(-2,6,-1,prismarine)
B(-2,6,0,obsidian)
B(-2,6,1,prismarine)
B(-2,7,-1,obsidian)
B(-2,7,0,obsidian)
B(-2,7,1,prismarine)
B(-2,8,0,obsidian)
B(-2,8,1,obsidian)
B(-2,9,0,prismarine)
B(-2,9,1,obsidian)
B(-2,10,0,prismarine)
B(-2,11,0,prismarine)
B(-2,12,0,prismarine)
B(-1,0,-2,obsidian)
B(-1,0,-1,obsidian)
B(-1,0,0,obsidian)
B(-1,0,1,obsidian)
B(-1,0,2,obsidian)
B(-1,1,-2,obsidian)
B(-1,1,-1,obsidian)
B(-1,1,0,obsidian)
B(-1,1,1,obsidian)
B(-1,1,2,obsidian)
B(-1,2,-2,obsidian)
B(-1,2,-1,obsidian)
B(-1,2,0,obsidian)
B(-1,2,1,obsidian)
B(-1,2,2,prismarine)
B(-1,3,-2,obsidian)
B(-1,3,-1,obsidian)
B(-1,3,0,obsidian)
B(-1,3,1,obsidian)
B(-1,3,2,prismarine)
B(-1,4,-2,obsidian)
B(-1,4,-1,prismarine)
B(-1,4,0,obsidian)
B(-1,4,1,obsidian)
B(-1,4,2,prismarine)
B(-1,5,-2,prismarine)
B(-1,5,-1,obsidian)
B(-1,5,0,obsidian)
B(-1,5,1,obsidian)
B(-1,5,2,prismarine)
B(-1,6,-1,obsidian)
B(-1,6,0,obsidian)
B(-1,6,1,obsidian)
B(-1,6,2,prismarine)
B(-1,7,-1,obsidian)
B(-1,7,0,obsidian)
B(-1,7,1,obsidian)
B(-1,8,-1,obsidian)
B(-1,8,0,obsidian)
B(-1,8,1,obsidian)
B(-1,9,-1,obsidian)
B(-1,9,0,obsidian)
B(-1,9,1,obsidian)
B(-1,10,-1,obsidian)
B(-1,10,0,obsidian)
B(-1,10,1,obsidian)
B(-1,11,-1,obsidian)
B(-1,11,0,obsidian)
B(-1,11,1,obsidian)
B(-1,12,0,prismarine)
B(-1,13,0,prismarine)
B(-1,14,0,obsidian)
B(-1,15,0,obsidian)
B(-1,16,0,obsidian)
B(-1,17,0,obsidian)
B(-1,18,0,obsidian)
B(-1,19,0,obsidian)
B(0,0,-1,obsidian)
B(0,0,0,obsidian)
B(0,0,1,obsidian)
B(0,0,2,obsidian)
B(0,1,-1,obsidian)
B(0,1,0,obsidian)
B(0,1,1,obsidian)
B(0,1,2,obsidian)
B(0,2,-1,prismarine)
B(0,2,0,obsidian)
B(0,2,1,obsidian)
B(0,2,2,obsidian)
B(0,3,-1,prismarine)
B(0,3,0,obsidian)
B(0,3,1,obsidian)
B(0,3,2,obsidian)
B(0,4,-1,prismarine)
B(0,4,0,obsidian)
B(0,4,1,obsidian)
B(0,5,-1,obsidian)
B(0,5,0,obsidian)
B(0,5,1,obsidian)
B(0,6,0,obsidian)
B(0,6,1,obsidian)
B(0,7,0,obsidian)
B(0,7,1,obsidian)
B(0,8,0,obsidian)
B(0,9,0,obsidian)
B(1,0,-1,prismarine)
B(1,0,0,obsidian)
B(1,0,1,obsidian)
B(1,1,-1,prismarine)
B(1,1,0,obsidian)
B(1,1,1,obsidian)
B(1,2,-1,prismarine)
B(1,2,0,obsidian)
B(1,2,1,obsidian)
B(1,3,0,obsidian)
B(1,3,1,obsidian)
B(1,4,1,obsidian)
B(2,0,0,obsidian)
B(2,1,0,obsidian)
B(2,2,0,obsidian)

#
# +-----------------------------------------------------------------+ #
# |                            BO3 checks                           | #
# +-----------------------------------------------------------------+ #
#

BlockCheck(0,20,0,air)

#
# +-----------------------------------------------------------------+ #
# |                             Branches                            | #
# +-----------------------------------------------------------------+ #
#

