
#
# +-----------------------------------------------------------------+ #
# |                            BO3 object                           | #
# +-----------------------------------------------------------------+ #
#

Author: NLBlackEagle

Description: Bo3 Created by NLBlackEagle - For Dregora

Version: 3

SettingsMode: WriteDisable


#
# +-----------------------------------------------------------------+ #
# |                          Main settings                          | #
# +-----------------------------------------------------------------+ #
#

Tree: false

Frequency: 2

Rarity: 20.0

RotateRandomly: true

SpawnHeight: randomY

SpawnHeightOffset: 0

SpawnHeightVariance: 0


# Height Limits for the BO3. #


MinHeight: 3

MaxHeight: 6


# Extrusion settings #


ExtrudeMode: None

ExtrudeThroughBlocks: air

MaxBranchDepth: 10

ExcludedBiomes: All


#
# +-----------------------------------------------------------------+ #
# |                      Source block settings                      | #
# +-----------------------------------------------------------------+ #
#

SourceBlocks: air

MaxPercentageOutsideSourceBlock: 100

OutsideSourceBlock: placeAnyway


#
# +-----------------------------------------------------------------+ #
# |                              Blocks                             | #
# +-----------------------------------------------------------------+ #
#

B(-2,0,-1,obsidian)
B(-2,0,0,bedrock)
B(-2,1,-1,obsidian)
B(-2,1,0,bedrock)
B(-2,2,-1,obsidian)
B(-2,2,0,obsidian)
B(-2,3,0,prismarine)
B(-1,0,-2,bedrock)
B(-1,0,-1,obsidian)
B(-1,0,0,obsidian)
B(-1,0,1,obsidian)
B(-1,1,-2,bedrock)
B(-1,1,-1,obsidian)
B(-1,1,0,obsidian)
B(-1,1,1,obsidian)
B(-1,2,-1,obsidian)
B(-1,2,0,obsidian)
B(-1,2,1,obsidian)
B(-1,3,-1,obsidian)
B(-1,3,0,obsidian)
B(-1,4,-1,obsidian)
B(-1,4,0,prismarine)
B(-1,5,0,prismarine)
B(-1,6,0,prismarine)
B(0,0,-1,obsidian)
B(0,0,0,obsidian)
B(0,0,1,obsidian)
B(0,0,2,bedrock)
B(0,1,-1,obsidian)
B(0,1,0,obsidian)
B(0,1,1,obsidian)
B(0,1,2,bedrock)
B(0,2,-1,prismarine)
B(0,2,0,obsidian)
B(0,2,1,obsidian)
B(0,2,2,obsidian)
B(0,3,-1,prismarine)
B(0,3,0,obsidian)
B(0,3,1,obsidian)
B(0,4,-1,prismarine)
B(0,4,0,obsidian)
B(0,4,1,obsidian)
B(0,5,-1,prismarine)
B(0,5,0,obsidian)
B(0,5,1,obsidian)
B(0,6,-1,prismarine)
B(0,6,0,obsidian)
B(0,7,-1,prismarine)
B(0,7,0,prismarine)
B(0,8,-1,obsidian)
B(0,8,0,prismarine)
B(0,9,0,prismarine)
B(0,10,0,prismarine)
B(0,11,0,obsidian)
B(0,12,0,obsidian)
B(0,13,0,obsidian)
B(1,0,0,obsidian)
B(1,0,1,obsidian)
B(1,0,2,obsidian)
B(1,1,0,obsidian)
B(1,1,1,obsidian)
B(1,2,0,prismarine)
B(1,2,1,obsidian)
B(1,3,0,obsidian)
B(1,3,1,obsidian)
B(1,4,0,obsidian)
B(1,5,0,obsidian)
B(1,6,0,obsidian)
B(2,0,1,obsidian)
B(2,1,1,prismarine)

#
# +-----------------------------------------------------------------+ #
# |                            BO3 checks                           | #
# +-----------------------------------------------------------------+ #
#

BlockCheck(0,15,0,air)

#
# +-----------------------------------------------------------------+ #
# |                             Branches                            | #
# +-----------------------------------------------------------------+ #
#

