
#######################################################################
# +-----------------------------------------------------------------+ #
# |                            BO4 object                           | #
# +-----------------------------------------------------------------+ #
#######################################################################

Author: NLBlackEagle

Description: No description given

SettingsMode: WriteWithoutComments


#######################################################################
# +-----------------------------------------------------------------+ #
# |                          Main settings                          | #
# +-----------------------------------------------------------------+ #
#######################################################################

FixedRotation: 

Frequency: 0

SpawnHeight: highestBlock

UseCenterForHighestBlock: true

##############################
# Height Limits for the BO4. #
##############################

MinHeight: 0

MaxHeight: 255

InheritBO3: 

InheritBO3Rotation: NORTH

OverrideChildSettings: true

OverrideParentHeight: false

CanOverride: false

BranchFrequency: 0

BranchFrequencyGroup: 

MustBeBelowOther: false

MustBeInside: 

CannotBeInside: 

ReplacesBO3: 

MustBeInsideWorldBorders: false

CanSpawnOnWater: true

SpawnOnWaterOnly: false

SpawnUnderWater: false

SpawnAtWaterLevel: false

HeightOffset: 0

RemoveAir: true

ReplaceAbove: 

ReplaceBelow: 

ReplaceWithBiomeBlocks: true

ReplaceWithSurfaceBlock: GRASS

ReplaceWithGroundBlock: DIRT

ReplaceWithStoneBlock: STONE

SmoothRadius: 0

SmoothHeightOffset: 0

SmoothStartTop: false

SmoothStartWood: false

SmoothingSurfaceBlock: 

SmoothingGroundBlock: 

BO3Group: 

IsSpawnPoint: false

DoReplaceBlocks: true


#######################################################################
# +-----------------------------------------------------------------+ #
# |                              Blocks                             | #
# +-----------------------------------------------------------------+ #
#######################################################################

B(-8,23,-7,minecraft:diorite)
B(-8,24,-7,minecraft:diorite)
B(-8,25,-7,minecraft:diorite)
B(-8,26,-7,minecraft:diorite)
B(-8,27,-7,minecraft:diorite)
B(-8,28,-7,minecraft:diorite)
B(-8,29,-7,minecraft:obsidian)
B(-8,30,-7,minecraft:andesite)
B(-8,31,-7,minecraft:andesite)
B(-8,32,-7,minecraft:andesite)
B(-8,33,-7,minecraft:diorite)
B(-8,34,-7,minecraft:diorite)
B(-8,35,-7,minecraft:diorite)
B(-8,81,-7,minecraft:obsidian)
B(-8,82,-7,minecraft:obsidian)
B(-8,83,-7,minecraft:obsidian)
B(-8,84,-7,minecraft:obsidian)
B(-8,85,-7,minecraft:obsidian)
B(-8,86,-7,minecraft:obsidian)
B(-8,87,-7,minecraft:obsidian)
B(-8,88,-7,minecraft:obsidian)
B(-8,89,-7,minecraft:obsidian)
B(-8,90,-7,minecraft:obsidian)
B(-8,91,-7,minecraft:magma_block)
B(-8,92,-7,minecraft:magma_block)
B(-8,93,-7,minecraft:magma_block)
B(-8,94,-7,minecraft:magma_block)
B(-8,95,-7,minecraft:magma_block)
B(-8,96,-7,minecraft:magma_block)
B(-8,24,-6,minecraft:diorite)
B(-8,25,-6,minecraft:diorite)
B(-8,26,-6,minecraft:diorite)
B(-8,27,-6,minecraft:diorite)
B(-8,28,-6,minecraft:diorite)
B(-8,29,-6,minecraft:obsidian)
B(-8,30,-6,minecraft:obsidian)
B(-8,31,-6,minecraft:andesite)
B(-8,32,-6,minecraft:diorite)
B(-8,33,-6,minecraft:diorite)
B(-8,34,-6,minecraft:diorite)
B(-8,35,-6,minecraft:diorite)
B(-8,81,-6,minecraft:obsidian)
B(-8,82,-6,minecraft:obsidian)
B(-8,83,-6,minecraft:obsidian)
B(-8,84,-6,minecraft:obsidian)
B(-8,85,-6,minecraft:obsidian)
B(-8,86,-6,minecraft:obsidian)
B(-8,87,-6,minecraft:obsidian)
B(-8,88,-6,minecraft:obsidian)
B(-8,89,-6,minecraft:obsidian)
B(-8,90,-6,minecraft:obsidian)
B(-8,91,-6,minecraft:magma_block)
B(-8,92,-6,minecraft:magma_block)
B(-8,93,-6,minecraft:magma_block)
B(-8,94,-6,minecraft:magma_block)
B(-8,95,-6,minecraft:magma_block)
B(-8,96,-6,minecraft:obsidian)
B(-8,24,-5,minecraft:diorite)
B(-8,25,-5,minecraft:diorite)
B(-8,26,-5,minecraft:diorite)
B(-8,27,-5,minecraft:diorite)
B(-8,28,-5,minecraft:diorite)
B(-8,29,-5,minecraft:obsidian)
B(-8,30,-5,minecraft:obsidian)
B(-8,31,-5,minecraft:obsidian)
B(-8,32,-5,minecraft:diorite)
B(-8,33,-5,minecraft:diorite)
B(-8,34,-5,minecraft:grass_block)
B(-8,81,-5,minecraft:obsidian)
B(-8,82,-5,minecraft:obsidian)
B(-8,83,-5,minecraft:obsidian)
B(-8,84,-5,minecraft:obsidian)
B(-8,85,-5,minecraft:obsidian)
B(-8,86,-5,minecraft:obsidian)
B(-8,87,-5,minecraft:obsidian)
B(-8,88,-5,minecraft:obsidian)
B(-8,89,-5,minecraft:obsidian)
B(-8,90,-5,minecraft:obsidian)
B(-8,91,-5,minecraft:magma_block)
B(-8,92,-5,minecraft:magma_block)
B(-8,93,-5,minecraft:magma_block)
B(-8,94,-5,minecraft:magma_block)
B(-8,95,-5,minecraft:magma_block)
B(-8,96,-5,minecraft:magma_block)
B(-8,97,-5,minecraft:obsidian)
B(-8,25,-4,minecraft:diorite)
B(-8,26,-4,minecraft:diorite)
B(-8,27,-4,minecraft:diorite)
B(-8,28,-4,minecraft:diorite)
B(-8,29,-4,minecraft:diorite)
B(-8,30,-4,minecraft:obsidian)
B(-8,31,-4,minecraft:obsidian)
B(-8,32,-4,minecraft:diorite)
B(-8,33,-4,minecraft:grass_block)
B(-8,81,-4,minecraft:obsidian)
B(-8,82,-4,minecraft:obsidian)
B(-8,83,-4,minecraft:obsidian)
B(-8,84,-4,minecraft:obsidian)
B(-8,85,-4,minecraft:obsidian)
B(-8,86,-4,minecraft:obsidian)
B(-8,87,-4,minecraft:obsidian)
B(-8,88,-4,minecraft:obsidian)
B(-8,89,-4,minecraft:obsidian)
B(-8,90,-4,minecraft:obsidian)
B(-8,91,-4,minecraft:obsidian)
B(-8,92,-4,minecraft:magma_block)
B(-8,93,-4,minecraft:magma_block)
B(-8,94,-4,minecraft:magma_block)
B(-8,95,-4,minecraft:magma_block)
B(-8,96,-4,minecraft:magma_block)
B(-8,25,-3,minecraft:diorite)
B(-8,26,-3,minecraft:diorite)
B(-8,27,-3,minecraft:diorite)
B(-8,28,-3,minecraft:diorite)
B(-8,29,-3,minecraft:obsidian)
B(-8,30,-3,minecraft:obsidian)
B(-8,31,-3,minecraft:obsidian)
B(-8,32,-3,minecraft:grass_block)
B(-8,33,-3,minecraft:water)
B(-8,81,-3,minecraft:obsidian)
B(-8,82,-3,minecraft:obsidian)
B(-8,83,-3,minecraft:obsidian)
B(-8,84,-3,minecraft:obsidian)
B(-8,85,-3,minecraft:obsidian)
B(-8,86,-3,minecraft:obsidian)
B(-8,87,-3,minecraft:obsidian)
B(-8,88,-3,minecraft:obsidian)
B(-8,89,-3,minecraft:obsidian)
B(-8,90,-3,minecraft:obsidian)
B(-8,91,-3,minecraft:obsidian)
B(-8,92,-3,minecraft:magma_block)
B(-8,93,-3,minecraft:magma_block)
B(-8,25,-2,minecraft:diorite)
B(-8,26,-2,minecraft:diorite)
B(-8,27,-2,minecraft:diorite)
B(-8,28,-2,minecraft:diorite)
B(-8,29,-2,minecraft:obsidian)
B(-8,30,-2,minecraft:diorite)
B(-8,31,-2,minecraft:grass_block)
B(-8,32,-2,minecraft:water)
B(-8,33,-2,minecraft:water)
B(-8,80,-2,minecraft:obsidian)
B(-8,81,-2,minecraft:obsidian)
B(-8,82,-2,minecraft:obsidian)
B(-8,83,-2,minecraft:obsidian)
B(-8,84,-2,minecraft:obsidian)
B(-8,85,-2,minecraft:obsidian)
B(-8,86,-2,minecraft:obsidian)
B(-8,87,-2,minecraft:obsidian)
B(-8,88,-2,minecraft:obsidian)
B(-8,89,-2,minecraft:obsidian)
B(-8,90,-2,minecraft:obsidian)
B(-8,91,-2,minecraft:obsidian)
B(-8,92,-2,minecraft:obsidian)
B(-8,93,-2,minecraft:magma_block)
B(-8,94,-2,minecraft:magma_block)
B(-8,25,-1,minecraft:diorite)
B(-8,26,-1,minecraft:diorite)
B(-8,27,-1,minecraft:diorite)
B(-8,28,-1,minecraft:diorite)
B(-8,29,-1,minecraft:diorite)
B(-8,30,-1,minecraft:diorite)
B(-8,31,-1,minecraft:diorite)
B(-8,32,-1,minecraft:grass_block)
B(-8,33,-1,minecraft:water)
B(-8,79,-1,minecraft:obsidian)
B(-8,80,-1,minecraft:obsidian)
B(-8,81,-1,minecraft:obsidian)
B(-8,82,-1,minecraft:obsidian)
B(-8,83,-1,minecraft:obsidian)
B(-8,84,-1,minecraft:obsidian)
B(-8,85,-1,minecraft:obsidian)
B(-8,86,-1,minecraft:obsidian)
B(-8,87,-1,minecraft:obsidian)
B(-8,88,-1,minecraft:obsidian)
B(-8,89,-1,minecraft:obsidian)
B(-8,90,-1,minecraft:obsidian)
B(-8,91,-1,minecraft:obsidian)
B(-8,92,-1,minecraft:obsidian)
B(-8,93,-1,minecraft:magma_block)
B(-8,94,-1,minecraft:magma_block)
B(-8,26,0,minecraft:diorite)
B(-8,27,0,minecraft:diorite)
B(-8,28,0,minecraft:diorite)
B(-8,29,0,minecraft:diorite)
B(-8,30,0,minecraft:diorite)
B(-8,31,0,minecraft:diorite)
B(-8,32,0,minecraft:diorite)
B(-8,33,0,minecraft:water)
B(-8,73,0,minecraft:obsidian)
B(-8,74,0,minecraft:obsidian)
B(-8,75,0,minecraft:obsidian)
B(-8,77,0,minecraft:obsidian)
B(-8,78,0,minecraft:obsidian)
B(-8,79,0,minecraft:obsidian)
B(-8,80,0,minecraft:obsidian)
B(-8,81,0,minecraft:obsidian)
B(-8,82,0,minecraft:obsidian)
B(-8,83,0,minecraft:obsidian)
B(-8,84,0,minecraft:obsidian)
B(-8,85,0,minecraft:obsidian)
B(-8,86,0,minecraft:obsidian)
B(-8,87,0,minecraft:obsidian)
B(-8,88,0,minecraft:obsidian)
B(-8,89,0,minecraft:obsidian)
B(-8,90,0,minecraft:obsidian)
B(-8,91,0,minecraft:obsidian)
B(-8,92,0,minecraft:obsidian)
B(-8,93,0,minecraft:magma_block)
B(-8,27,1,minecraft:diorite)
B(-8,28,1,minecraft:diorite)
B(-8,29,1,minecraft:diorite)
B(-8,30,1,minecraft:diorite)
B(-8,31,1,minecraft:diorite)
B(-8,32,1,minecraft:diorite)
B(-8,33,1,minecraft:water)
B(-8,71,1,minecraft:obsidian)
B(-8,72,1,minecraft:obsidian)
B(-8,73,1,minecraft:obsidian)
B(-8,74,1,minecraft:obsidian)
B(-8,75,1,minecraft:obsidian)
B(-8,76,1,minecraft:obsidian)
B(-8,77,1,minecraft:obsidian)
B(-8,78,1,minecraft:obsidian)
B(-8,79,1,minecraft:obsidian)
B(-8,80,1,minecraft:obsidian)
B(-8,81,1,minecraft:obsidian)
B(-8,82,1,minecraft:obsidian)
B(-8,83,1,minecraft:obsidian)
B(-8,84,1,minecraft:obsidian)
B(-8,85,1,minecraft:obsidian)
B(-8,86,1,minecraft:obsidian)
B(-8,87,1,minecraft:obsidian)
B(-8,88,1,minecraft:obsidian)
B(-8,89,1,minecraft:obsidian)
B(-8,90,1,minecraft:obsidian)
B(-8,91,1,minecraft:obsidian)
B(-8,92,1,minecraft:obsidian)
B(-8,93,1,minecraft:obsidian)
B(-8,27,2,minecraft:diorite)
B(-8,28,2,minecraft:diorite)
B(-8,29,2,minecraft:obsidian)
B(-8,30,2,minecraft:diorite)
B(-8,31,2,minecraft:diorite)
B(-8,32,2,minecraft:diorite)
B(-8,33,2,minecraft:water)
B(-8,70,2,minecraft:obsidian)
B(-8,71,2,minecraft:obsidian)
B(-8,72,2,minecraft:obsidian)
B(-8,73,2,minecraft:obsidian)
B(-8,74,2,minecraft:obsidian)
B(-8,75,2,minecraft:obsidian)
B(-8,76,2,minecraft:obsidian)
B(-8,77,2,minecraft:obsidian)
B(-8,78,2,minecraft:obsidian)
B(-8,79,2,minecraft:obsidian)
B(-8,80,2,minecraft:obsidian)
B(-8,81,2,minecraft:obsidian)
B(-8,82,2,minecraft:obsidian)
B(-8,83,2,minecraft:obsidian)
B(-8,84,2,minecraft:obsidian)
B(-8,85,2,minecraft:obsidian)
B(-8,86,2,minecraft:obsidian)
B(-8,87,2,minecraft:obsidian)
B(-8,88,2,minecraft:obsidian)
B(-8,89,2,minecraft:obsidian)
B(-8,90,2,minecraft:obsidian)
B(-8,91,2,minecraft:obsidian)
B(-8,92,2,minecraft:obsidian)
B(-8,28,3,minecraft:diorite)
B(-8,29,3,minecraft:obsidian)
B(-8,30,3,minecraft:diorite)
B(-8,31,3,minecraft:diorite)
B(-8,32,3,minecraft:diorite)
B(-8,33,3,minecraft:water)
B(-8,69,3,minecraft:obsidian)
B(-8,70,3,minecraft:obsidian)
B(-8,71,3,minecraft:obsidian)
B(-8,72,3,minecraft:obsidian)
B(-8,73,3,minecraft:obsidian)
B(-8,74,3,minecraft:obsidian)
B(-8,75,3,minecraft:obsidian)
B(-8,76,3,minecraft:obsidian)
B(-8,77,3,minecraft:obsidian)
B(-8,78,3,minecraft:obsidian)
B(-8,79,3,minecraft:obsidian)
B(-8,80,3,minecraft:obsidian)
B(-8,81,3,minecraft:obsidian)
B(-8,82,3,minecraft:obsidian)
B(-8,83,3,minecraft:obsidian)
B(-8,84,3,minecraft:obsidian)
B(-8,85,3,minecraft:obsidian)
B(-8,86,3,minecraft:obsidian)
B(-8,87,3,minecraft:obsidian)
B(-8,88,3,minecraft:obsidian)
B(-8,89,3,minecraft:obsidian)
B(-8,90,3,minecraft:obsidian)
B(-8,91,3,minecraft:obsidian)
B(-8,92,3,minecraft:obsidian)
B(-8,28,4,minecraft:diorite)
B(-8,29,4,minecraft:diorite)
B(-8,30,4,minecraft:obsidian)
B(-8,31,4,minecraft:obsidian)
B(-8,32,4,minecraft:obsidian)
B(-8,33,4,minecraft:andesite)
B(-8,68,4,minecraft:obsidian)
B(-8,69,4,minecraft:obsidian)
B(-8,70,4,minecraft:obsidian)
B(-8,71,4,minecraft:obsidian)
B(-8,72,4,minecraft:obsidian)
B(-8,73,4,minecraft:obsidian)
B(-8,74,4,minecraft:obsidian)
B(-8,75,4,minecraft:obsidian)
B(-8,76,4,minecraft:obsidian)
B(-8,77,4,minecraft:obsidian)
B(-8,78,4,minecraft:obsidian)
B(-8,79,4,minecraft:obsidian)
B(-8,80,4,minecraft:obsidian)
B(-8,81,4,minecraft:obsidian)
B(-8,82,4,minecraft:obsidian)
B(-8,83,4,minecraft:obsidian)
B(-8,84,4,minecraft:obsidian)
B(-8,85,4,minecraft:obsidian)
B(-8,86,4,minecraft:obsidian)
B(-8,87,4,minecraft:obsidian)
B(-8,88,4,minecraft:obsidian)
B(-8,89,4,minecraft:obsidian)
B(-8,90,4,minecraft:obsidian)
B(-8,91,4,minecraft:obsidian)
B(-8,92,4,minecraft:obsidian)
B(-8,28,5,minecraft:diorite)
B(-8,29,5,minecraft:diorite)
B(-8,30,5,minecraft:diorite)
B(-8,31,5,minecraft:obsidian)
B(-8,32,5,minecraft:obsidian)
B(-8,33,5,minecraft:andesite)
B(-8,34,5,minecraft:andesite)
B(-8,35,5,minecraft:andesite)
B(-8,68,5,minecraft:obsidian)
B(-8,69,5,minecraft:obsidian)
B(-8,70,5,minecraft:obsidian)
B(-8,71,5,minecraft:obsidian)
B(-8,72,5,minecraft:obsidian)
B(-8,73,5,minecraft:obsidian)
B(-8,74,5,minecraft:obsidian)
B(-8,75,5,minecraft:obsidian)
B(-8,76,5,minecraft:obsidian)
B(-8,77,5,minecraft:obsidian)
B(-8,78,5,minecraft:obsidian)
B(-8,79,5,minecraft:obsidian)
B(-8,80,5,minecraft:obsidian)
B(-8,81,5,minecraft:obsidian)
B(-8,82,5,minecraft:obsidian)
B(-8,83,5,minecraft:obsidian)
B(-8,84,5,minecraft:obsidian)
B(-8,85,5,minecraft:obsidian)
B(-8,86,5,minecraft:obsidian)
B(-8,87,5,minecraft:obsidian)
B(-8,88,5,minecraft:obsidian)
B(-8,89,5,minecraft:obsidian)
B(-8,90,5,minecraft:obsidian)
B(-8,91,5,minecraft:diorite)
B(-8,92,5,minecraft:obsidian)
B(-8,29,6,minecraft:diorite)
B(-8,30,6,minecraft:diorite)
B(-8,31,6,minecraft:diorite)
B(-8,32,6,minecraft:obsidian)
B(-8,33,6,minecraft:andesite)
B(-8,34,6,minecraft:andesite)
B(-8,36,6,minecraft:andesite)
B(-8,68,6,minecraft:obsidian)
B(-8,69,6,minecraft:obsidian)
B(-8,70,6,minecraft:obsidian)
B(-8,71,6,minecraft:obsidian)
B(-8,72,6,minecraft:obsidian)
B(-8,73,6,minecraft:obsidian)
B(-8,74,6,minecraft:obsidian)
B(-8,75,6,minecraft:obsidian)
B(-8,76,6,minecraft:obsidian)
B(-8,77,6,minecraft:obsidian)
B(-8,78,6,minecraft:obsidian)
B(-8,79,6,minecraft:obsidian)
B(-8,80,6,minecraft:obsidian)
B(-8,81,6,minecraft:obsidian)
B(-8,82,6,minecraft:obsidian)
B(-8,83,6,minecraft:obsidian)
B(-8,84,6,minecraft:obsidian)
B(-8,85,6,minecraft:obsidian)
B(-8,86,6,minecraft:obsidian)
B(-8,87,6,minecraft:obsidian)
B(-8,88,6,minecraft:obsidian)
B(-8,89,6,minecraft:obsidian)
B(-8,90,6,minecraft:diorite)
B(-8,91,6,minecraft:diorite)
B(-8,29,7,minecraft:diorite)
B(-8,30,7,minecraft:diorite)
B(-8,31,7,minecraft:diorite)
B(-8,32,7,minecraft:diorite)
B(-8,33,7,minecraft:obsidian)
B(-8,34,7,minecraft:andesite)
B(-8,35,7,minecraft:andesite)
B(-8,36,7,minecraft:andesite)
B(-8,37,7,minecraft:obsidian)
B(-8,67,7,minecraft:obsidian)
B(-8,68,7,minecraft:obsidian)
B(-8,69,7,minecraft:obsidian)
B(-8,70,7,minecraft:obsidian)
B(-8,71,7,minecraft:obsidian)
B(-8,72,7,minecraft:obsidian)
B(-8,73,7,minecraft:obsidian)
B(-8,74,7,minecraft:obsidian)
B(-8,75,7,minecraft:obsidian)
B(-8,76,7,minecraft:obsidian)
B(-8,77,7,minecraft:obsidian)
B(-8,78,7,minecraft:obsidian)
B(-8,79,7,minecraft:obsidian)
B(-8,80,7,minecraft:obsidian)
B(-8,81,7,minecraft:obsidian)
B(-8,82,7,minecraft:obsidian)
B(-8,83,7,minecraft:obsidian)
B(-8,84,7,minecraft:obsidian)
B(-8,85,7,minecraft:obsidian)
B(-8,86,7,minecraft:obsidian)
B(-8,87,7,minecraft:obsidian)
B(-8,88,7,minecraft:obsidian)
B(-8,89,7,minecraft:obsidian)
B(-8,90,7,minecraft:diorite)
B(-8,91,7,minecraft:diorite)
B(-8,29,8,minecraft:diorite)
B(-8,30,8,minecraft:diorite)
B(-8,31,8,minecraft:diorite)
B(-8,32,8,minecraft:diorite)
B(-8,33,8,minecraft:diorite)
B(-8,34,8,minecraft:obsidian)
B(-8,35,8,minecraft:obsidian)
B(-8,36,8,minecraft:obsidian)
B(-8,37,8,minecraft:obsidian)
B(-8,38,8,minecraft:obsidian)
B(-8,66,8,minecraft:obsidian)
B(-8,67,8,minecraft:obsidian)
B(-8,68,8,minecraft:obsidian)
B(-8,69,8,minecraft:obsidian)
B(-8,70,8,minecraft:obsidian)
B(-8,71,8,minecraft:obsidian)
B(-8,72,8,minecraft:obsidian)
B(-8,73,8,minecraft:obsidian)
B(-8,74,8,minecraft:obsidian)
B(-8,75,8,minecraft:obsidian)
B(-8,76,8,minecraft:obsidian)
B(-8,77,8,minecraft:obsidian)
B(-8,78,8,minecraft:obsidian)
B(-8,79,8,minecraft:obsidian)
B(-8,80,8,minecraft:obsidian)
B(-8,81,8,minecraft:obsidian)
B(-8,82,8,minecraft:obsidian)
B(-8,83,8,minecraft:obsidian)
B(-8,84,8,minecraft:obsidian)
B(-8,85,8,minecraft:obsidian)
B(-8,86,8,minecraft:obsidian)
B(-8,87,8,minecraft:obsidian)
B(-8,88,8,minecraft:obsidian)
B(-8,89,8,minecraft:diorite)
B(-8,90,8,minecraft:diorite)
B(-7,23,-7,minecraft:diorite)
B(-7,24,-7,minecraft:diorite)
B(-7,25,-7,minecraft:diorite)
B(-7,26,-7,minecraft:diorite)
B(-7,27,-7,minecraft:diorite)
B(-7,28,-7,minecraft:diorite)
B(-7,29,-7,minecraft:obsidian)
B(-7,30,-7,minecraft:obsidian)
B(-7,31,-7,minecraft:andesite)
B(-7,32,-7,minecraft:andesite)
B(-7,33,-7,minecraft:diorite)
B(-7,34,-7,minecraft:diorite)
B(-7,35,-7,minecraft:diorite)
B(-7,81,-7,minecraft:obsidian)
B(-7,82,-7,minecraft:obsidian)
B(-7,83,-7,minecraft:obsidian)
B(-7,84,-7,minecraft:obsidian)
B(-7,85,-7,minecraft:obsidian)
B(-7,86,-7,minecraft:obsidian)
B(-7,87,-7,minecraft:obsidian)
B(-7,88,-7,minecraft:obsidian)
B(-7,89,-7,minecraft:obsidian)
B(-7,90,-7,minecraft:obsidian)
B(-7,91,-7,minecraft:obsidian)
B(-7,92,-7,minecraft:magma_block)
B(-7,93,-7,minecraft:magma_block)
B(-7,94,-7,minecraft:magma_block)
B(-7,95,-7,minecraft:obsidian)
B(-7,96,-7,minecraft:obsidian)
B(-7,97,-7,minecraft:obsidian)
B(-7,23,-6,minecraft:diorite)
B(-7,24,-6,minecraft:diorite)
B(-7,25,-6,minecraft:diorite)
B(-7,26,-6,minecraft:diorite)
B(-7,27,-6,minecraft:diorite)
B(-7,28,-6,minecraft:diorite)
B(-7,29,-6,minecraft:obsidian)
B(-7,30,-6,minecraft:obsidian)
B(-7,31,-6,minecraft:obsidian)
B(-7,32,-6,minecraft:diorite)
B(-7,33,-6,minecraft:diorite)
B(-7,34,-6,minecraft:diorite)
B(-7,35,-6,minecraft:grass_block)
B(-7,81,-6,minecraft:obsidian)
B(-7,82,-6,minecraft:obsidian)
B(-7,83,-6,minecraft:obsidian)
B(-7,84,-6,minecraft:obsidian)
B(-7,85,-6,minecraft:obsidian)
B(-7,86,-6,minecraft:obsidian)
B(-7,87,-6,minecraft:obsidian)
B(-7,88,-6,minecraft:obsidian)
B(-7,89,-6,minecraft:obsidian)
B(-7,90,-6,minecraft:obsidian)
B(-7,91,-6,minecraft:obsidian)
B(-7,92,-6,minecraft:magma_block)
B(-7,93,-6,minecraft:magma_block)
B(-7,94,-6,minecraft:magma_block)
B(-7,95,-6,minecraft:magma_block)
B(-7,96,-6,minecraft:obsidian)
B(-7,97,-6,minecraft:obsidian)
B(-7,24,-5,minecraft:diorite)
B(-7,25,-5,minecraft:diorite)
B(-7,26,-5,minecraft:diorite)
B(-7,27,-5,minecraft:diorite)
B(-7,28,-5,minecraft:diorite)
B(-7,29,-5,minecraft:obsidian)
B(-7,30,-5,minecraft:obsidian)
B(-7,31,-5,minecraft:obsidian)
B(-7,32,-5,minecraft:diorite)
B(-7,33,-5,minecraft:diorite)
B(-7,34,-5,minecraft:diorite)
B(-7,35,-5,minecraft:grass_block)
B(-7,81,-5,minecraft:obsidian)
B(-7,82,-5,minecraft:obsidian)
B(-7,83,-5,minecraft:obsidian)
B(-7,84,-5,minecraft:obsidian)
B(-7,85,-5,minecraft:obsidian)
B(-7,86,-5,minecraft:obsidian)
B(-7,87,-5,minecraft:obsidian)
B(-7,88,-5,minecraft:obsidian)
B(-7,89,-5,minecraft:obsidian)
B(-7,90,-5,minecraft:obsidian)
B(-7,91,-5,minecraft:obsidian)
B(-7,92,-5,minecraft:magma_block)
B(-7,93,-5,minecraft:magma_block)
B(-7,94,-5,minecraft:magma_block)
B(-7,95,-5,minecraft:magma_block)
B(-7,96,-5,minecraft:magma_block)
B(-7,97,-5,minecraft:obsidian)
B(-7,98,-5,minecraft:obsidian)
B(-7,24,-4,minecraft:diorite)
B(-7,25,-4,minecraft:diorite)
B(-7,26,-4,minecraft:diorite)
B(-7,27,-4,minecraft:diorite)
B(-7,28,-4,minecraft:diorite)
B(-7,29,-4,minecraft:diorite)
B(-7,30,-4,minecraft:obsidian)
B(-7,31,-4,minecraft:obsidian)
B(-7,32,-4,minecraft:diorite)
B(-7,33,-4,minecraft:diorite)
B(-7,34,-4,minecraft:diorite)
B(-7,35,-4,minecraft:grass_block)
B(-7,81,-4,minecraft:obsidian)
B(-7,82,-4,minecraft:obsidian)
B(-7,83,-4,minecraft:obsidian)
B(-7,84,-4,minecraft:obsidian)
B(-7,85,-4,minecraft:obsidian)
B(-7,86,-4,minecraft:obsidian)
B(-7,87,-4,minecraft:obsidian)
B(-7,88,-4,minecraft:obsidian)
B(-7,89,-4,minecraft:obsidian)
B(-7,90,-4,minecraft:obsidian)
B(-7,91,-4,minecraft:obsidian)
B(-7,92,-4,minecraft:magma_block)
B(-7,93,-4,minecraft:magma_block)
B(-7,94,-4,minecraft:magma_block)
B(-7,95,-4,minecraft:magma_block)
B(-7,96,-4,minecraft:magma_block)
B(-7,97,-4,minecraft:obsidian)
B(-7,25,-3,minecraft:diorite)
B(-7,26,-3,minecraft:diorite)
B(-7,27,-3,minecraft:diorite)
B(-7,28,-3,minecraft:diorite)
B(-7,29,-3,minecraft:obsidian)
B(-7,30,-3,minecraft:obsidian)
B(-7,31,-3,minecraft:obsidian)
B(-7,32,-3,minecraft:diorite)
B(-7,33,-3,minecraft:diorite)
B(-7,34,-3,minecraft:grass_block)
B(-7,80,-3,minecraft:obsidian)
B(-7,81,-3,minecraft:obsidian)
B(-7,82,-3,minecraft:obsidian)
B(-7,83,-3,minecraft:obsidian)
B(-7,84,-3,minecraft:obsidian)
B(-7,85,-3,minecraft:obsidian)
B(-7,86,-3,minecraft:obsidian)
B(-7,87,-3,minecraft:obsidian)
B(-7,88,-3,minecraft:obsidian)
B(-7,89,-3,minecraft:obsidian)
B(-7,90,-3,minecraft:obsidian)
B(-7,91,-3,minecraft:obsidian)
B(-7,92,-3,minecraft:magma_block)
B(-7,93,-3,minecraft:magma_block)
B(-7,94,-3,minecraft:magma_block)
B(-7,95,-3,minecraft:magma_block)
B(-7,96,-3,minecraft:magma_block)
B(-7,25,-2,minecraft:diorite)
B(-7,26,-2,minecraft:diorite)
B(-7,27,-2,minecraft:diorite)
B(-7,28,-2,minecraft:diorite)
B(-7,29,-2,minecraft:obsidian)
B(-7,30,-2,minecraft:diorite)
B(-7,31,-2,minecraft:diorite)
B(-7,32,-2,minecraft:diorite)
B(-7,33,-2,minecraft:grass_block)
B(-7,80,-2,minecraft:obsidian)
B(-7,81,-2,minecraft:obsidian)
B(-7,82,-2,minecraft:obsidian)
B(-7,83,-2,minecraft:obsidian)
B(-7,84,-2,minecraft:obsidian)
B(-7,85,-2,minecraft:obsidian)
B(-7,86,-2,minecraft:obsidian)
B(-7,87,-2,minecraft:obsidian)
B(-7,88,-2,minecraft:obsidian)
B(-7,89,-2,minecraft:obsidian)
B(-7,90,-2,minecraft:obsidian)
B(-7,91,-2,minecraft:obsidian)
B(-7,92,-2,minecraft:obsidian)
B(-7,93,-2,minecraft:magma_block)
B(-7,94,-2,minecraft:magma_block)
B(-7,95,-2,minecraft:magma_block)
B(-7,25,-1,minecraft:diorite)
B(-7,26,-1,minecraft:diorite)
B(-7,27,-1,minecraft:diorite)
B(-7,28,-1,minecraft:diorite)
B(-7,29,-1,minecraft:diorite)
B(-7,30,-1,minecraft:diorite)
B(-7,31,-1,minecraft:diorite)
B(-7,32,-1,minecraft:grass_block)
B(-7,33,-1,minecraft:water)
B(-7,79,-1,minecraft:obsidian)
B(-7,80,-1,minecraft:obsidian)
B(-7,81,-1,minecraft:obsidian)
B(-7,82,-1,minecraft:obsidian)
B(-7,83,-1,minecraft:obsidian)
B(-7,84,-1,minecraft:obsidian)
B(-7,85,-1,minecraft:obsidian)
B(-7,86,-1,minecraft:obsidian)
B(-7,87,-1,minecraft:obsidian)
B(-7,88,-1,minecraft:obsidian)
B(-7,89,-1,minecraft:obsidian)
B(-7,90,-1,minecraft:obsidian)
B(-7,91,-1,minecraft:obsidian)
B(-7,92,-1,minecraft:obsidian)
B(-7,93,-1,minecraft:magma_block)
B(-7,94,-1,minecraft:magma_block)
B(-7,95,-1,minecraft:magma_block)
B(-7,26,0,minecraft:diorite)
B(-7,27,0,minecraft:diorite)
B(-7,28,0,minecraft:diorite)
B(-7,29,0,minecraft:diorite)
B(-7,30,0,minecraft:diorite)
B(-7,31,0,minecraft:grass_block)
B(-7,32,0,minecraft:water)
B(-7,33,0,minecraft:water)
B(-7,78,0,minecraft:obsidian)
B(-7,79,0,minecraft:obsidian)
B(-7,80,0,minecraft:obsidian)
B(-7,81,0,minecraft:obsidian)
B(-7,82,0,minecraft:obsidian)
B(-7,83,0,minecraft:obsidian)
B(-7,84,0,minecraft:obsidian)
B(-7,85,0,minecraft:obsidian)
B(-7,86,0,minecraft:obsidian)
B(-7,87,0,minecraft:obsidian)
B(-7,88,0,minecraft:obsidian)
B(-7,89,0,minecraft:obsidian)
B(-7,90,0,minecraft:obsidian)
B(-7,91,0,minecraft:obsidian)
B(-7,92,0,minecraft:obsidian)
B(-7,93,0,minecraft:magma_block)
B(-7,94,0,minecraft:magma_block)
B(-7,26,1,minecraft:diorite)
B(-7,27,1,minecraft:diorite)
B(-7,28,1,minecraft:diorite)
B(-7,29,1,minecraft:diorite)
B(-7,30,1,minecraft:diorite)
B(-7,31,1,minecraft:diorite)
B(-7,32,1,minecraft:water)
B(-7,33,1,minecraft:water)
B(-7,73,1,minecraft:obsidian)
B(-7,77,1,minecraft:obsidian)
B(-7,78,1,minecraft:obsidian)
B(-7,79,1,minecraft:obsidian)
B(-7,80,1,minecraft:obsidian)
B(-7,81,1,minecraft:obsidian)
B(-7,82,1,minecraft:obsidian)
B(-7,83,1,minecraft:obsidian)
B(-7,84,1,minecraft:obsidian)
B(-7,85,1,minecraft:obsidian)
B(-7,86,1,minecraft:obsidian)
B(-7,87,1,minecraft:obsidian)
B(-7,88,1,minecraft:obsidian)
B(-7,89,1,minecraft:obsidian)
B(-7,90,1,minecraft:obsidian)
B(-7,91,1,minecraft:obsidian)
B(-7,92,1,minecraft:obsidian)
B(-7,93,1,minecraft:obsidian)
B(-7,27,2,minecraft:diorite)
B(-7,28,2,minecraft:diorite)
B(-7,29,2,minecraft:diorite)
B(-7,30,2,minecraft:diorite)
B(-7,31,2,minecraft:diorite)
B(-7,32,2,minecraft:diorite)
B(-7,33,2,minecraft:water)
B(-7,72,2,minecraft:obsidian)
B(-7,73,2,minecraft:obsidian)
B(-7,74,2,minecraft:obsidian)
B(-7,76,2,minecraft:obsidian)
B(-7,77,2,minecraft:obsidian)
B(-7,78,2,minecraft:obsidian)
B(-7,79,2,minecraft:obsidian)
B(-7,80,2,minecraft:obsidian)
B(-7,81,2,minecraft:obsidian)
B(-7,82,2,minecraft:obsidian)
B(-7,83,2,minecraft:obsidian)
B(-7,84,2,minecraft:obsidian)
B(-7,85,2,minecraft:obsidian)
B(-7,86,2,minecraft:obsidian)
B(-7,87,2,minecraft:obsidian)
B(-7,88,2,minecraft:obsidian)
B(-7,89,2,minecraft:obsidian)
B(-7,90,2,minecraft:obsidian)
B(-7,91,2,minecraft:obsidian)
B(-7,92,2,minecraft:obsidian)
B(-7,93,2,minecraft:obsidian)
B(-7,28,3,minecraft:diorite)
B(-7,29,3,minecraft:diorite)
B(-7,30,3,minecraft:diorite)
B(-7,31,3,minecraft:diorite)
B(-7,32,3,minecraft:diorite)
B(-7,33,3,minecraft:water)
B(-7,71,3,minecraft:obsidian)
B(-7,72,3,minecraft:obsidian)
B(-7,73,3,minecraft:obsidian)
B(-7,74,3,minecraft:obsidian)
B(-7,75,3,minecraft:obsidian)
B(-7,76,3,minecraft:obsidian)
B(-7,77,3,minecraft:obsidian)
B(-7,78,3,minecraft:obsidian)
B(-7,79,3,minecraft:obsidian)
B(-7,80,3,minecraft:obsidian)
B(-7,81,3,minecraft:obsidian)
B(-7,82,3,minecraft:obsidian)
B(-7,83,3,minecraft:obsidian)
B(-7,84,3,minecraft:obsidian)
B(-7,85,3,minecraft:obsidian)
B(-7,86,3,minecraft:obsidian)
B(-7,87,3,minecraft:obsidian)
B(-7,88,3,minecraft:obsidian)
B(-7,89,3,minecraft:obsidian)
B(-7,90,3,minecraft:obsidian)
B(-7,91,3,minecraft:obsidian)
B(-7,92,3,minecraft:obsidian)
B(-7,93,3,minecraft:obsidian)
B(-7,28,4,minecraft:diorite)
B(-7,29,4,minecraft:obsidian)
B(-7,30,4,minecraft:diorite)
B(-7,31,4,minecraft:diorite)
B(-7,32,4,minecraft:diorite)
B(-7,33,4,minecraft:water)
B(-7,35,4,minecraft:andesite)
B(-7,70,4,minecraft:obsidian)
B(-7,71,4,minecraft:obsidian)
B(-7,72,4,minecraft:obsidian)
B(-7,73,4,minecraft:obsidian)
B(-7,74,4,minecraft:obsidian)
B(-7,75,4,minecraft:obsidian)
B(-7,76,4,minecraft:obsidian)
B(-7,77,4,minecraft:obsidian)
B(-7,78,4,minecraft:obsidian)
B(-7,79,4,minecraft:obsidian)
B(-7,80,4,minecraft:obsidian)
B(-7,81,4,minecraft:obsidian)
B(-7,82,4,minecraft:obsidian)
B(-7,83,4,minecraft:obsidian)
B(-7,84,4,minecraft:obsidian)
B(-7,85,4,minecraft:obsidian)
B(-7,86,4,minecraft:obsidian)
B(-7,87,4,minecraft:obsidian)
B(-7,88,4,minecraft:obsidian)
B(-7,89,4,minecraft:obsidian)
B(-7,90,4,minecraft:obsidian)
B(-7,91,4,minecraft:obsidian)
B(-7,92,4,minecraft:obsidian)
B(-7,29,5,minecraft:obsidian)
B(-7,30,5,minecraft:diorite)
B(-7,31,5,minecraft:diorite)
B(-7,32,5,minecraft:diorite)
B(-7,33,5,minecraft:andesite)
B(-7,34,5,minecraft:andesite)
B(-7,35,5,minecraft:andesite)
B(-7,69,5,minecraft:obsidian)
B(-7,70,5,minecraft:obsidian)
B(-7,71,5,minecraft:obsidian)
B(-7,72,5,minecraft:obsidian)
B(-7,73,5,minecraft:obsidian)
B(-7,74,5,minecraft:obsidian)
B(-7,75,5,minecraft:obsidian)
B(-7,76,5,minecraft:obsidian)
B(-7,77,5,minecraft:obsidian)
B(-7,78,5,minecraft:obsidian)
B(-7,79,5,minecraft:obsidian)
B(-7,80,5,minecraft:obsidian)
B(-7,81,5,minecraft:obsidian)
B(-7,82,5,minecraft:obsidian)
B(-7,83,5,minecraft:obsidian)
B(-7,84,5,minecraft:obsidian)
B(-7,85,5,minecraft:obsidian)
B(-7,86,5,minecraft:obsidian)
B(-7,87,5,minecraft:obsidian)
B(-7,88,5,minecraft:obsidian)
B(-7,89,5,minecraft:obsidian)
B(-7,90,5,minecraft:obsidian)
B(-7,91,5,minecraft:obsidian)
B(-7,92,5,minecraft:obsidian)
B(-7,29,6,minecraft:diorite)
B(-7,30,6,minecraft:diorite)
B(-7,31,6,minecraft:diorite)
B(-7,32,6,minecraft:obsidian)
B(-7,33,6,minecraft:andesite)
B(-7,34,6,minecraft:andesite)
B(-7,35,6,minecraft:andesite)
B(-7,69,6,minecraft:obsidian)
B(-7,70,6,minecraft:obsidian)
B(-7,71,6,minecraft:obsidian)
B(-7,72,6,minecraft:obsidian)
B(-7,73,6,minecraft:obsidian)
B(-7,74,6,minecraft:obsidian)
B(-7,75,6,minecraft:obsidian)
B(-7,76,6,minecraft:obsidian)
B(-7,77,6,minecraft:obsidian)
B(-7,78,6,minecraft:obsidian)
B(-7,79,6,minecraft:obsidian)
B(-7,80,6,minecraft:obsidian)
B(-7,81,6,minecraft:obsidian)
B(-7,82,6,minecraft:obsidian)
B(-7,83,6,minecraft:obsidian)
B(-7,84,6,minecraft:obsidian)
B(-7,85,6,minecraft:obsidian)
B(-7,86,6,minecraft:obsidian)
B(-7,87,6,minecraft:obsidian)
B(-7,88,6,minecraft:obsidian)
B(-7,89,6,minecraft:obsidian)
B(-7,90,6,minecraft:obsidian)
B(-7,91,6,minecraft:diorite)
B(-7,92,6,minecraft:diorite)
B(-7,29,7,minecraft:diorite)
B(-7,30,7,minecraft:diorite)
B(-7,31,7,minecraft:diorite)
B(-7,32,7,minecraft:diorite)
B(-7,33,7,minecraft:obsidian)
B(-7,34,7,minecraft:andesite)
B(-7,35,7,minecraft:andesite)
B(-7,36,7,minecraft:andesite)
B(-7,69,7,minecraft:obsidian)
B(-7,70,7,minecraft:obsidian)
B(-7,71,7,minecraft:obsidian)
B(-7,72,7,minecraft:obsidian)
B(-7,73,7,minecraft:obsidian)
B(-7,74,7,minecraft:obsidian)
B(-7,75,7,minecraft:obsidian)
B(-7,76,7,minecraft:obsidian)
B(-7,77,7,minecraft:obsidian)
B(-7,78,7,minecraft:obsidian)
B(-7,79,7,minecraft:obsidian)
B(-7,80,7,minecraft:obsidian)
B(-7,81,7,minecraft:obsidian)
B(-7,82,7,minecraft:obsidian)
B(-7,83,7,minecraft:obsidian)
B(-7,84,7,minecraft:obsidian)
B(-7,85,7,minecraft:obsidian)
B(-7,86,7,minecraft:obsidian)
B(-7,87,7,minecraft:obsidian)
B(-7,88,7,minecraft:obsidian)
B(-7,89,7,minecraft:obsidian)
B(-7,90,7,minecraft:diorite)
B(-7,91,7,minecraft:diorite)
B(-7,29,8,minecraft:diorite)
B(-7,30,8,minecraft:diorite)
B(-7,31,8,minecraft:diorite)
B(-7,32,8,minecraft:diorite)
B(-7,33,8,minecraft:obsidian)
B(-7,34,8,minecraft:obsidian)
B(-7,35,8,minecraft:obsidian)
B(-7,36,8,minecraft:obsidian)
B(-7,37,8,minecraft:obsidian)
B(-7,38,8,minecraft:obsidian)
B(-7,68,8,minecraft:obsidian)
B(-7,69,8,minecraft:obsidian)
B(-7,70,8,minecraft:obsidian)
B(-7,71,8,minecraft:obsidian)
B(-7,72,8,minecraft:obsidian)
B(-7,73,8,minecraft:obsidian)
B(-7,74,8,minecraft:obsidian)
B(-7,75,8,minecraft:obsidian)
B(-7,76,8,minecraft:obsidian)
B(-7,77,8,minecraft:obsidian)
B(-7,78,8,minecraft:obsidian)
B(-7,79,8,minecraft:obsidian)
B(-7,80,8,minecraft:obsidian)
B(-7,81,8,minecraft:obsidian)
B(-7,82,8,minecraft:obsidian)
B(-7,83,8,minecraft:obsidian)
B(-7,84,8,minecraft:obsidian)
B(-7,85,8,minecraft:obsidian)
B(-7,86,8,minecraft:obsidian)
B(-7,87,8,minecraft:obsidian)
B(-7,88,8,minecraft:obsidian)
B(-7,89,8,minecraft:diorite)
B(-7,90,8,minecraft:diorite)
B(-6,23,-7,minecraft:diorite)
B(-6,24,-7,minecraft:diorite)
B(-6,25,-7,minecraft:diorite)
B(-6,26,-7,minecraft:diorite)
B(-6,27,-7,minecraft:diorite)
B(-6,28,-7,minecraft:diorite)
B(-6,29,-7,minecraft:obsidian)
B(-6,30,-7,minecraft:obsidian)
B(-6,31,-7,minecraft:obsidian)
B(-6,32,-7,minecraft:obsidian)
B(-6,33,-7,minecraft:diorite)
B(-6,34,-7,minecraft:diorite)
B(-6,35,-7,minecraft:diorite)
B(-6,36,-7,minecraft:grass_block)
B(-6,81,-7,minecraft:obsidian)
B(-6,82,-7,minecraft:obsidian)
B(-6,83,-7,minecraft:obsidian)
B(-6,84,-7,minecraft:obsidian)
B(-6,85,-7,minecraft:obsidian)
B(-6,86,-7,minecraft:obsidian)
B(-6,87,-7,minecraft:obsidian)
B(-6,88,-7,minecraft:obsidian)
B(-6,89,-7,minecraft:obsidian)
B(-6,90,-7,minecraft:obsidian)
B(-6,91,-7,minecraft:obsidian)
B(-6,92,-7,minecraft:obsidian)
B(-6,93,-7,minecraft:obsidian)
B(-6,94,-7,minecraft:obsidian)
B(-6,95,-7,minecraft:obsidian)
B(-6,96,-7,minecraft:obsidian)
B(-6,97,-7,minecraft:obsidian)
B(-6,98,-7,minecraft:obsidian)
B(-6,23,-6,minecraft:diorite)
B(-6,24,-6,minecraft:diorite)
B(-6,25,-6,minecraft:diorite)
B(-6,26,-6,minecraft:diorite)
B(-6,27,-6,minecraft:diorite)
B(-6,28,-6,minecraft:diorite)
B(-6,29,-6,minecraft:obsidian)
B(-6,30,-6,minecraft:obsidian)
B(-6,31,-6,minecraft:obsidian)
B(-6,32,-6,minecraft:obsidian)
B(-6,33,-6,minecraft:diorite)
B(-6,34,-6,minecraft:diorite)
B(-6,35,-6,minecraft:diorite)
B(-6,36,-6,minecraft:grass_block)
B(-6,81,-6,minecraft:obsidian)
B(-6,82,-6,minecraft:obsidian)
B(-6,83,-6,minecraft:obsidian)
B(-6,84,-6,minecraft:obsidian)
B(-6,85,-6,minecraft:obsidian)
B(-6,86,-6,minecraft:obsidian)
B(-6,87,-6,minecraft:obsidian)
B(-6,88,-6,minecraft:obsidian)
B(-6,89,-6,minecraft:obsidian)
B(-6,90,-6,minecraft:obsidian)
B(-6,91,-6,minecraft:obsidian)
B(-6,92,-6,minecraft:obsidian)
B(-6,93,-6,minecraft:obsidian)
B(-6,94,-6,minecraft:obsidian)
B(-6,95,-6,minecraft:obsidian)
B(-6,96,-6,minecraft:obsidian)
B(-6,97,-6,minecraft:obsidian)
B(-6,98,-6,minecraft:obsidian)
B(-6,23,-5,minecraft:diorite)
B(-6,24,-5,minecraft:diorite)
B(-6,25,-5,minecraft:diorite)
B(-6,26,-5,minecraft:diorite)
B(-6,27,-5,minecraft:diorite)
B(-6,28,-5,minecraft:diorite)
B(-6,29,-5,minecraft:obsidian)
B(-6,30,-5,minecraft:obsidian)
B(-6,31,-5,minecraft:obsidian)
B(-6,32,-5,minecraft:obsidian)
B(-6,33,-5,minecraft:diorite)
B(-6,34,-5,minecraft:diorite)
B(-6,35,-5,minecraft:diorite)
B(-6,36,-5,minecraft:grass_block)
B(-6,80,-5,minecraft:obsidian)
B(-6,81,-5,minecraft:obsidian)
B(-6,82,-5,minecraft:obsidian)
B(-6,83,-5,minecraft:obsidian)
B(-6,84,-5,minecraft:obsidian)
B(-6,85,-5,minecraft:obsidian)
B(-6,86,-5,minecraft:obsidian)
B(-6,87,-5,minecraft:obsidian)
B(-6,88,-5,minecraft:obsidian)
B(-6,89,-5,minecraft:obsidian)
B(-6,90,-5,minecraft:diorite)
B(-6,91,-5,minecraft:obsidian)
B(-6,92,-5,minecraft:obsidian)
B(-6,93,-5,minecraft:magma_block)
B(-6,94,-5,minecraft:magma_block)
B(-6,95,-5,minecraft:magma_block)
B(-6,96,-5,minecraft:obsidian)
B(-6,97,-5,minecraft:obsidian)
B(-6,98,-5,minecraft:obsidian)
B(-6,99,-5,minecraft:obsidian)
B(-6,24,-4,minecraft:diorite)
B(-6,25,-4,minecraft:diorite)
B(-6,26,-4,minecraft:diorite)
B(-6,27,-4,minecraft:diorite)
B(-6,28,-4,minecraft:diorite)
B(-6,29,-4,minecraft:diorite)
B(-6,30,-4,minecraft:obsidian)
B(-6,31,-4,minecraft:obsidian)
B(-6,32,-4,minecraft:andesite)
B(-6,33,-4,minecraft:diorite)
B(-6,34,-4,minecraft:diorite)
B(-6,35,-4,minecraft:grass_block)
B(-6,79,-4,minecraft:obsidian)
B(-6,80,-4,minecraft:obsidian)
B(-6,81,-4,minecraft:obsidian)
B(-6,82,-4,minecraft:obsidian)
B(-6,83,-4,minecraft:obsidian)
B(-6,84,-4,minecraft:obsidian)
B(-6,85,-4,minecraft:obsidian)
B(-6,86,-4,minecraft:obsidian)
B(-6,87,-4,minecraft:obsidian)
B(-6,88,-4,minecraft:obsidian)
B(-6,89,-4,minecraft:obsidian)
B(-6,90,-4,minecraft:diorite)
B(-6,91,-4,minecraft:obsidian)
B(-6,92,-4,minecraft:obsidian)
B(-6,93,-4,minecraft:magma_block)
B(-6,94,-4,minecraft:magma_block)
B(-6,95,-4,minecraft:magma_block)
B(-6,96,-4,minecraft:magma_block)
B(-6,97,-4,minecraft:obsidian)
B(-6,98,-4,minecraft:obsidian)
B(-6,25,-3,minecraft:diorite)
B(-6,26,-3,minecraft:diorite)
B(-6,27,-3,minecraft:diorite)
B(-6,28,-3,minecraft:diorite)
B(-6,29,-3,minecraft:diorite)
B(-6,30,-3,minecraft:obsidian)
B(-6,31,-3,minecraft:andesite)
B(-6,32,-3,minecraft:diorite)
B(-6,33,-3,minecraft:diorite)
B(-6,34,-3,minecraft:diorite)
B(-6,35,-3,minecraft:grass_block)
B(-6,79,-3,minecraft:obsidian)
B(-6,80,-3,minecraft:obsidian)
B(-6,81,-3,minecraft:obsidian)
B(-6,82,-3,minecraft:obsidian)
B(-6,83,-3,minecraft:obsidian)
B(-6,84,-3,minecraft:obsidian)
B(-6,85,-3,minecraft:obsidian)
B(-6,86,-3,minecraft:obsidian)
B(-6,87,-3,minecraft:obsidian)
B(-6,88,-3,minecraft:obsidian)
B(-6,89,-3,minecraft:obsidian)
B(-6,90,-3,minecraft:obsidian)
B(-6,91,-3,minecraft:obsidian)
B(-6,92,-3,minecraft:obsidian)
B(-6,93,-3,minecraft:magma_block)
B(-6,94,-3,minecraft:magma_block)
B(-6,95,-3,minecraft:magma_block)
B(-6,96,-3,minecraft:magma_block)
B(-6,97,-3,minecraft:magma_block)
B(-6,26,-2,minecraft:diorite)
B(-6,27,-2,minecraft:diorite)
B(-6,28,-2,minecraft:diorite)
B(-6,29,-2,minecraft:diorite)
B(-6,30,-2,minecraft:diorite)
B(-6,31,-2,minecraft:diorite)
B(-6,32,-2,minecraft:diorite)
B(-6,33,-2,minecraft:diorite)
B(-6,34,-2,minecraft:grass_block)
B(-6,78,-2,minecraft:obsidian)
B(-6,79,-2,minecraft:obsidian)
B(-6,80,-2,minecraft:obsidian)
B(-6,81,-2,minecraft:obsidian)
B(-6,82,-2,minecraft:obsidian)
B(-6,83,-2,minecraft:obsidian)
B(-6,84,-2,minecraft:obsidian)
B(-6,85,-2,minecraft:obsidian)
B(-6,86,-2,minecraft:obsidian)
B(-6,87,-2,minecraft:obsidian)
B(-6,88,-2,minecraft:obsidian)
B(-6,89,-2,minecraft:obsidian)
B(-6,90,-2,minecraft:obsidian)
B(-6,91,-2,minecraft:obsidian)
B(-6,92,-2,minecraft:obsidian)
B(-6,93,-2,minecraft:magma_block)
B(-6,94,-2,minecraft:magma_block)
B(-6,95,-2,minecraft:magma_block)
B(-6,96,-2,minecraft:magma_block)
B(-6,26,-1,minecraft:diorite)
B(-6,27,-1,minecraft:diorite)
B(-6,28,-1,minecraft:diorite)
B(-6,29,-1,minecraft:diorite)
B(-6,30,-1,minecraft:diorite)
B(-6,31,-1,minecraft:diorite)
B(-6,32,-1,minecraft:diorite)
B(-6,33,-1,minecraft:grass_block)
B(-6,78,-1,minecraft:obsidian)
B(-6,79,-1,minecraft:obsidian)
B(-6,80,-1,minecraft:obsidian)
B(-6,81,-1,minecraft:obsidian)
B(-6,82,-1,minecraft:obsidian)
B(-6,83,-1,minecraft:obsidian)
B(-6,84,-1,minecraft:obsidian)
B(-6,85,-1,minecraft:obsidian)
B(-6,86,-1,minecraft:obsidian)
B(-6,87,-1,minecraft:obsidian)
B(-6,88,-1,minecraft:obsidian)
B(-6,89,-1,minecraft:obsidian)
B(-6,90,-1,minecraft:obsidian)
B(-6,91,-1,minecraft:obsidian)
B(-6,92,-1,minecraft:obsidian)
B(-6,93,-1,minecraft:magma_block)
B(-6,94,-1,minecraft:magma_block)
B(-6,95,-1,minecraft:magma_block)
B(-6,26,0,minecraft:diorite)
B(-6,27,0,minecraft:diorite)
B(-6,28,0,minecraft:diorite)
B(-6,29,0,minecraft:diorite)
B(-6,30,0,minecraft:diorite)
B(-6,31,0,minecraft:grass_block)
B(-6,32,0,minecraft:water)
B(-6,33,0,minecraft:water)
B(-6,77,0,minecraft:obsidian)
B(-6,78,0,minecraft:obsidian)
B(-6,79,0,minecraft:obsidian)
B(-6,80,0,minecraft:obsidian)
B(-6,81,0,minecraft:obsidian)
B(-6,82,0,minecraft:obsidian)
B(-6,83,0,minecraft:obsidian)
B(-6,84,0,minecraft:obsidian)
B(-6,85,0,minecraft:obsidian)
B(-6,86,0,minecraft:obsidian)
B(-6,87,0,minecraft:obsidian)
B(-6,88,0,minecraft:obsidian)
B(-6,89,0,minecraft:obsidian)
B(-6,90,0,minecraft:obsidian)
B(-6,91,0,minecraft:obsidian)
B(-6,92,0,minecraft:magma_block)
B(-6,93,0,minecraft:magma_block)
B(-6,94,0,minecraft:magma_block)
B(-6,95,0,minecraft:magma_block)
B(-6,26,1,minecraft:diorite)
B(-6,27,1,minecraft:diorite)
B(-6,28,1,minecraft:diorite)
B(-6,29,1,minecraft:diorite)
B(-6,30,1,minecraft:diorite)
B(-6,31,1,minecraft:diorite)
B(-6,32,1,minecraft:water)
B(-6,33,1,minecraft:water)
B(-6,76,1,minecraft:obsidian)
B(-6,77,1,minecraft:obsidian)
B(-6,78,1,minecraft:obsidian)
B(-6,79,1,minecraft:obsidian)
B(-6,80,1,minecraft:obsidian)
B(-6,81,1,minecraft:obsidian)
B(-6,82,1,minecraft:obsidian)
B(-6,83,1,minecraft:obsidian)
B(-6,84,1,minecraft:obsidian)
B(-6,85,1,minecraft:obsidian)
B(-6,86,1,minecraft:obsidian)
B(-6,87,1,minecraft:obsidian)
B(-6,88,1,minecraft:obsidian)
B(-6,89,1,minecraft:obsidian)
B(-6,90,1,minecraft:obsidian)
B(-6,91,1,minecraft:obsidian)
B(-6,92,1,minecraft:magma_block)
B(-6,93,1,minecraft:magma_block)
B(-6,94,1,minecraft:magma_block)
B(-6,27,2,minecraft:diorite)
B(-6,28,2,minecraft:obsidian)
B(-6,29,2,minecraft:diorite)
B(-6,30,2,minecraft:diorite)
B(-6,31,2,minecraft:diorite)
B(-6,32,2,minecraft:water)
B(-6,33,2,minecraft:water)
B(-6,74,2,minecraft:obsidian)
B(-6,75,2,minecraft:obsidian)
B(-6,76,2,minecraft:obsidian)
B(-6,77,2,minecraft:obsidian)
B(-6,78,2,minecraft:obsidian)
B(-6,79,2,minecraft:obsidian)
B(-6,80,2,minecraft:obsidian)
B(-6,81,2,minecraft:obsidian)
B(-6,82,2,minecraft:obsidian)
B(-6,83,2,minecraft:obsidian)
B(-6,84,2,minecraft:obsidian)
B(-6,85,2,minecraft:obsidian)
B(-6,86,2,minecraft:obsidian)
B(-6,87,2,minecraft:obsidian)
B(-6,88,2,minecraft:obsidian)
B(-6,89,2,minecraft:obsidian)
B(-6,90,2,minecraft:obsidian)
B(-6,91,2,minecraft:obsidian)
B(-6,92,2,minecraft:magma_block)
B(-6,93,2,minecraft:magma_block)
B(-6,27,3,minecraft:diorite)
B(-6,28,3,minecraft:obsidian)
B(-6,29,3,minecraft:diorite)
B(-6,30,3,minecraft:diorite)
B(-6,31,3,minecraft:diorite)
B(-6,32,3,minecraft:diorite)
B(-6,33,3,minecraft:water)
B(-6,74,3,minecraft:obsidian)
B(-6,75,3,minecraft:obsidian)
B(-6,76,3,minecraft:obsidian)
B(-6,77,3,minecraft:obsidian)
B(-6,78,3,minecraft:obsidian)
B(-6,79,3,minecraft:obsidian)
B(-6,80,3,minecraft:obsidian)
B(-6,81,3,minecraft:obsidian)
B(-6,82,3,minecraft:obsidian)
B(-6,83,3,minecraft:obsidian)
B(-6,84,3,minecraft:obsidian)
B(-6,85,3,minecraft:obsidian)
B(-6,86,3,minecraft:obsidian)
B(-6,87,3,minecraft:obsidian)
B(-6,88,3,minecraft:obsidian)
B(-6,89,3,minecraft:obsidian)
B(-6,90,3,minecraft:obsidian)
B(-6,91,3,minecraft:obsidian)
B(-6,92,3,minecraft:obsidian)
B(-6,28,4,minecraft:obsidian)
B(-6,29,4,minecraft:diorite)
B(-6,30,4,minecraft:diorite)
B(-6,31,4,minecraft:diorite)
B(-6,32,4,minecraft:diorite)
B(-6,33,4,minecraft:diorite)
B(-6,34,4,minecraft:andesite)
B(-6,35,4,minecraft:andesite)
B(-6,73,4,minecraft:obsidian)
B(-6,74,4,minecraft:obsidian)
B(-6,75,4,minecraft:obsidian)
B(-6,76,4,minecraft:obsidian)
B(-6,77,4,minecraft:obsidian)
B(-6,78,4,minecraft:obsidian)
B(-6,79,4,minecraft:obsidian)
B(-6,80,4,minecraft:obsidian)
B(-6,81,4,minecraft:obsidian)
B(-6,82,4,minecraft:obsidian)
B(-6,83,4,minecraft:obsidian)
B(-6,84,4,minecraft:obsidian)
B(-6,85,4,minecraft:obsidian)
B(-6,86,4,minecraft:obsidian)
B(-6,87,4,minecraft:obsidian)
B(-6,88,4,minecraft:obsidian)
B(-6,89,4,minecraft:obsidian)
B(-6,90,4,minecraft:obsidian)
B(-6,91,4,minecraft:obsidian)
B(-6,92,4,minecraft:obsidian)
B(-6,28,5,minecraft:diorite)
B(-6,29,5,minecraft:diorite)
B(-6,30,5,minecraft:diorite)
B(-6,31,5,minecraft:diorite)
B(-6,32,5,minecraft:diorite)
B(-6,33,5,minecraft:diorite)
B(-6,34,5,minecraft:andesite)
B(-6,35,5,minecraft:andesite)
B(-6,71,5,minecraft:obsidian)
B(-6,72,5,minecraft:obsidian)
B(-6,73,5,minecraft:obsidian)
B(-6,74,5,minecraft:obsidian)
B(-6,75,5,minecraft:obsidian)
B(-6,76,5,minecraft:obsidian)
B(-6,77,5,minecraft:obsidian)
B(-6,78,5,minecraft:obsidian)
B(-6,79,5,minecraft:obsidian)
B(-6,80,5,minecraft:obsidian)
B(-6,81,5,minecraft:obsidian)
B(-6,82,5,minecraft:obsidian)
B(-6,83,5,minecraft:obsidian)
B(-6,84,5,minecraft:obsidian)
B(-6,85,5,minecraft:obsidian)
B(-6,86,5,minecraft:obsidian)
B(-6,87,5,minecraft:obsidian)
B(-6,88,5,minecraft:obsidian)
B(-6,89,5,minecraft:obsidian)
B(-6,90,5,minecraft:obsidian)
B(-6,91,5,minecraft:obsidian)
B(-6,92,5,minecraft:obsidian)
B(-6,29,6,minecraft:diorite)
B(-6,30,6,minecraft:diorite)
B(-6,31,6,minecraft:diorite)
B(-6,32,6,minecraft:diorite)
B(-6,33,6,minecraft:andesite)
B(-6,34,6,minecraft:andesite)
B(-6,35,6,minecraft:andesite)
B(-6,70,6,minecraft:obsidian)
B(-6,71,6,minecraft:obsidian)
B(-6,72,6,minecraft:obsidian)
B(-6,73,6,minecraft:obsidian)
B(-6,74,6,minecraft:obsidian)
B(-6,75,6,minecraft:obsidian)
B(-6,76,6,minecraft:obsidian)
B(-6,77,6,minecraft:obsidian)
B(-6,78,6,minecraft:obsidian)
B(-6,79,6,minecraft:obsidian)
B(-6,80,6,minecraft:obsidian)
B(-6,81,6,minecraft:obsidian)
B(-6,82,6,minecraft:obsidian)
B(-6,83,6,minecraft:obsidian)
B(-6,84,6,minecraft:obsidian)
B(-6,85,6,minecraft:obsidian)
B(-6,86,6,minecraft:obsidian)
B(-6,87,6,minecraft:obsidian)
B(-6,88,6,minecraft:obsidian)
B(-6,89,6,minecraft:obsidian)
B(-6,90,6,minecraft:obsidian)
B(-6,91,6,minecraft:diorite)
B(-6,92,6,minecraft:obsidian)
B(-6,29,7,minecraft:diorite)
B(-6,30,7,minecraft:diorite)
B(-6,31,7,minecraft:diorite)
B(-6,32,7,minecraft:obsidian)
B(-6,33,7,minecraft:obsidian)
B(-6,34,7,minecraft:andesite)
B(-6,35,7,minecraft:andesite)
B(-6,36,7,minecraft:andesite)
B(-6,37,7,minecraft:obsidian)
B(-6,69,7,minecraft:obsidian)
B(-6,70,7,minecraft:obsidian)
B(-6,71,7,minecraft:obsidian)
B(-6,72,7,minecraft:obsidian)
B(-6,73,7,minecraft:obsidian)
B(-6,74,7,minecraft:obsidian)
B(-6,75,7,minecraft:obsidian)
B(-6,76,7,minecraft:obsidian)
B(-6,77,7,minecraft:obsidian)
B(-6,78,7,minecraft:obsidian)
B(-6,79,7,minecraft:obsidian)
B(-6,80,7,minecraft:obsidian)
B(-6,81,7,minecraft:obsidian)
B(-6,82,7,minecraft:obsidian)
B(-6,83,7,minecraft:obsidian)
B(-6,84,7,minecraft:obsidian)
B(-6,85,7,minecraft:obsidian)
B(-6,86,7,minecraft:obsidian)
B(-6,87,7,minecraft:obsidian)
B(-6,88,7,minecraft:obsidian)
B(-6,89,7,minecraft:obsidian)
B(-6,90,7,minecraft:diorite)
B(-6,91,7,minecraft:diorite)
B(-6,29,8,minecraft:diorite)
B(-6,30,8,minecraft:diorite)
B(-6,31,8,minecraft:diorite)
B(-6,32,8,minecraft:obsidian)
B(-6,33,8,minecraft:obsidian)
B(-6,34,8,minecraft:obsidian)
B(-6,35,8,minecraft:obsidian)
B(-6,36,8,minecraft:obsidian)
B(-6,37,8,minecraft:obsidian)
B(-6,38,8,minecraft:obsidian)
B(-6,39,8,minecraft:obsidian)
B(-6,69,8,minecraft:obsidian)
B(-6,70,8,minecraft:obsidian)
B(-6,71,8,minecraft:obsidian)
B(-6,72,8,minecraft:obsidian)
B(-6,73,8,minecraft:obsidian)
B(-6,74,8,minecraft:obsidian)
B(-6,75,8,minecraft:obsidian)
B(-6,76,8,minecraft:obsidian)
B(-6,77,8,minecraft:obsidian)
B(-6,78,8,minecraft:obsidian)
B(-6,79,8,minecraft:obsidian)
B(-6,80,8,minecraft:obsidian)
B(-6,81,8,minecraft:obsidian)
B(-6,82,8,minecraft:obsidian)
B(-6,83,8,minecraft:obsidian)
B(-6,84,8,minecraft:obsidian)
B(-6,85,8,minecraft:obsidian)
B(-6,86,8,minecraft:obsidian)
B(-6,87,8,minecraft:obsidian)
B(-6,88,8,minecraft:obsidian)
B(-6,89,8,minecraft:diorite)
B(-6,90,8,minecraft:diorite)
B(-5,23,-7,minecraft:diorite)
B(-5,24,-7,minecraft:diorite)
B(-5,25,-7,minecraft:diorite)
B(-5,26,-7,minecraft:diorite)
B(-5,27,-7,minecraft:diorite)
B(-5,28,-7,minecraft:diorite)
B(-5,29,-7,minecraft:obsidian)
B(-5,30,-7,minecraft:obsidian)
B(-5,31,-7,minecraft:obsidian)
B(-5,32,-7,minecraft:obsidian)
B(-5,33,-7,minecraft:obsidian)
B(-5,34,-7,minecraft:diorite)
B(-5,35,-7,minecraft:diorite)
B(-5,36,-7,minecraft:diorite)
B(-5,37,-7,minecraft:grass_block)
B(-5,80,-7,minecraft:obsidian)
B(-5,81,-7,minecraft:obsidian)
B(-5,82,-7,minecraft:obsidian)
B(-5,83,-7,minecraft:obsidian)
B(-5,84,-7,minecraft:obsidian)
B(-5,85,-7,minecraft:obsidian)
B(-5,86,-7,minecraft:obsidian)
B(-5,87,-7,minecraft:obsidian)
B(-5,88,-7,minecraft:obsidian)
B(-5,89,-7,minecraft:obsidian)
B(-5,90,-7,minecraft:obsidian)
B(-5,91,-7,minecraft:obsidian)
B(-5,92,-7,minecraft:diorite)
B(-5,93,-7,minecraft:diorite)
B(-5,94,-7,minecraft:obsidian)
B(-5,95,-7,minecraft:obsidian)
B(-5,96,-7,minecraft:obsidian)
B(-5,97,-7,minecraft:obsidian)
B(-5,98,-7,minecraft:obsidian)
B(-5,99,-7,minecraft:obsidian)
B(-5,100,-7,minecraft:obsidian)
B(-5,23,-6,minecraft:diorite)
B(-5,24,-6,minecraft:diorite)
B(-5,25,-6,minecraft:diorite)
B(-5,26,-6,minecraft:diorite)
B(-5,27,-6,minecraft:diorite)
B(-5,28,-6,minecraft:diorite)
B(-5,29,-6,minecraft:obsidian)
B(-5,30,-6,minecraft:obsidian)
B(-5,31,-6,minecraft:obsidian)
B(-5,32,-6,minecraft:obsidian)
B(-5,33,-6,minecraft:obsidian)
B(-5,34,-6,minecraft:diorite)
B(-5,35,-6,minecraft:diorite)
B(-5,36,-6,minecraft:diorite)
B(-5,37,-6,minecraft:grass_block)
B(-5,81,-6,minecraft:obsidian)
B(-5,82,-6,minecraft:obsidian)
B(-5,83,-6,minecraft:obsidian)
B(-5,84,-6,minecraft:obsidian)
B(-5,85,-6,minecraft:obsidian)
B(-5,86,-6,minecraft:obsidian)
B(-5,87,-6,minecraft:obsidian)
B(-5,88,-6,minecraft:obsidian)
B(-5,89,-6,minecraft:obsidian)
B(-5,90,-6,minecraft:obsidian)
B(-5,91,-6,minecraft:diorite)
B(-5,92,-6,minecraft:diorite)
B(-5,93,-6,minecraft:obsidian)
B(-5,94,-6,minecraft:obsidian)
B(-5,95,-6,minecraft:obsidian)
B(-5,96,-6,minecraft:obsidian)
B(-5,97,-6,minecraft:obsidian)
B(-5,98,-6,minecraft:obsidian)
B(-5,99,-6,minecraft:obsidian)
B(-5,100,-6,minecraft:obsidian)
B(-5,23,-5,minecraft:diorite)
B(-5,24,-5,minecraft:diorite)
B(-5,25,-5,minecraft:diorite)
B(-5,26,-5,minecraft:diorite)
B(-5,27,-5,minecraft:diorite)
B(-5,28,-5,minecraft:diorite)
B(-5,29,-5,minecraft:obsidian)
B(-5,30,-5,minecraft:obsidian)
B(-5,31,-5,minecraft:obsidian)
B(-5,32,-5,minecraft:obsidian)
B(-5,33,-5,minecraft:andesite)
B(-5,34,-5,minecraft:diorite)
B(-5,35,-5,minecraft:diorite)
B(-5,36,-5,minecraft:diorite)
B(-5,37,-5,minecraft:grass_block)
B(-5,81,-5,minecraft:obsidian)
B(-5,82,-5,minecraft:obsidian)
B(-5,83,-5,minecraft:obsidian)
B(-5,84,-5,minecraft:obsidian)
B(-5,85,-5,minecraft:obsidian)
B(-5,86,-5,minecraft:obsidian)
B(-5,87,-5,minecraft:obsidian)
B(-5,88,-5,minecraft:obsidian)
B(-5,89,-5,minecraft:obsidian)
B(-5,90,-5,minecraft:obsidian)
B(-5,91,-5,minecraft:diorite)
B(-5,92,-5,minecraft:obsidian)
B(-5,93,-5,minecraft:obsidian)
B(-5,94,-5,minecraft:obsidian)
B(-5,95,-5,minecraft:obsidian)
B(-5,96,-5,minecraft:obsidian)
B(-5,97,-5,minecraft:obsidian)
B(-5,98,-5,minecraft:obsidian)
B(-5,99,-5,minecraft:obsidian)
B(-5,100,-5,minecraft:obsidian)
B(-5,24,-4,minecraft:diorite)
B(-5,25,-4,minecraft:diorite)
B(-5,26,-4,minecraft:diorite)
B(-5,27,-4,minecraft:diorite)
B(-5,28,-4,minecraft:diorite)
B(-5,29,-4,minecraft:diorite)
B(-5,30,-4,minecraft:obsidian)
B(-5,31,-4,minecraft:obsidian)
B(-5,32,-4,minecraft:andesite)
B(-5,33,-4,minecraft:andesite)
B(-5,34,-4,minecraft:andesite)
B(-5,35,-4,minecraft:andesite)
B(-5,36,-4,minecraft:grass_block)
B(-5,80,-4,minecraft:obsidian)
B(-5,81,-4,minecraft:obsidian)
B(-5,82,-4,minecraft:obsidian)
B(-5,83,-4,minecraft:obsidian)
B(-5,84,-4,minecraft:obsidian)
B(-5,85,-4,minecraft:obsidian)
B(-5,86,-4,minecraft:obsidian)
B(-5,87,-4,minecraft:obsidian)
B(-5,88,-4,minecraft:obsidian)
B(-5,89,-4,minecraft:obsidian)
B(-5,90,-4,minecraft:diorite)
B(-5,91,-4,minecraft:obsidian)
B(-5,92,-4,minecraft:obsidian)
B(-5,93,-4,minecraft:obsidian)
B(-5,94,-4,minecraft:obsidian)
B(-5,95,-4,minecraft:obsidian)
B(-5,96,-4,minecraft:obsidian)
B(-5,97,-4,minecraft:obsidian)
B(-5,98,-4,minecraft:obsidian)
B(-5,99,-4,minecraft:obsidian)
B(-5,24,-3,minecraft:diorite)
B(-5,25,-3,minecraft:diorite)
B(-5,26,-3,minecraft:diorite)
B(-5,27,-3,minecraft:diorite)
B(-5,28,-3,minecraft:diorite)
B(-5,29,-3,minecraft:diorite)
B(-5,30,-3,minecraft:obsidian)
B(-5,31,-3,minecraft:andesite)
B(-5,32,-3,minecraft:andesite)
B(-5,33,-3,minecraft:andesite)
B(-5,34,-3,minecraft:grass_block)
B(-5,79,-3,minecraft:obsidian)
B(-5,80,-3,minecraft:obsidian)
B(-5,81,-3,minecraft:obsidian)
B(-5,82,-3,minecraft:obsidian)
B(-5,83,-3,minecraft:obsidian)
B(-5,84,-3,minecraft:obsidian)
B(-5,85,-3,minecraft:obsidian)
B(-5,86,-3,minecraft:obsidian)
B(-5,87,-3,minecraft:obsidian)
B(-5,88,-3,minecraft:obsidian)
B(-5,89,-3,minecraft:obsidian)
B(-5,90,-3,minecraft:diorite)
B(-5,91,-3,minecraft:obsidian)
B(-5,92,-3,minecraft:obsidian)
B(-5,93,-3,minecraft:obsidian)
B(-5,94,-3,minecraft:magma_block)
B(-5,95,-3,minecraft:magma_block)
B(-5,96,-3,minecraft:magma_block)
B(-5,97,-3,minecraft:obsidian)
B(-5,98,-3,minecraft:obsidian)
B(-5,99,-3,minecraft:obsidian)
B(-5,25,-2,minecraft:diorite)
B(-5,26,-2,minecraft:diorite)
B(-5,27,-2,minecraft:diorite)
B(-5,28,-2,minecraft:diorite)
B(-5,29,-2,minecraft:diorite)
B(-5,30,-2,minecraft:obsidian)
B(-5,31,-2,minecraft:andesite)
B(-5,32,-2,minecraft:diorite)
B(-5,33,-2,minecraft:grass_block)
B(-5,78,-2,minecraft:obsidian)
B(-5,79,-2,minecraft:obsidian)
B(-5,80,-2,minecraft:obsidian)
B(-5,81,-2,minecraft:obsidian)
B(-5,82,-2,minecraft:obsidian)
B(-5,83,-2,minecraft:obsidian)
B(-5,84,-2,minecraft:obsidian)
B(-5,85,-2,minecraft:obsidian)
B(-5,86,-2,minecraft:obsidian)
B(-5,87,-2,minecraft:obsidian)
B(-5,88,-2,minecraft:obsidian)
B(-5,89,-2,minecraft:obsidian)
B(-5,90,-2,minecraft:obsidian)
B(-5,91,-2,minecraft:obsidian)
B(-5,92,-2,minecraft:obsidian)
B(-5,93,-2,minecraft:obsidian)
B(-5,94,-2,minecraft:magma_block)
B(-5,95,-2,minecraft:magma_block)
B(-5,96,-2,minecraft:magma_block)
B(-5,97,-2,minecraft:obsidian)
B(-5,98,-2,minecraft:obsidian)
B(-5,99,-2,minecraft:obsidian)
B(-5,26,-1,minecraft:diorite)
B(-5,27,-1,minecraft:diorite)
B(-5,28,-1,minecraft:diorite)
B(-5,29,-1,minecraft:diorite)
B(-5,30,-1,minecraft:diorite)
B(-5,31,-1,minecraft:diorite)
B(-5,32,-1,minecraft:grass_block)
B(-5,33,-1,minecraft:water)
B(-5,78,-1,minecraft:obsidian)
B(-5,79,-1,minecraft:obsidian)
B(-5,80,-1,minecraft:obsidian)
B(-5,81,-1,minecraft:obsidian)
B(-5,82,-1,minecraft:obsidian)
B(-5,83,-1,minecraft:obsidian)
B(-5,84,-1,minecraft:obsidian)
B(-5,85,-1,minecraft:obsidian)
B(-5,86,-1,minecraft:obsidian)
B(-5,87,-1,minecraft:obsidian)
B(-5,88,-1,minecraft:obsidian)
B(-5,89,-1,minecraft:obsidian)
B(-5,90,-1,minecraft:obsidian)
B(-5,91,-1,minecraft:obsidian)
B(-5,92,-1,minecraft:magma_block)
B(-5,93,-1,minecraft:magma_block)
B(-5,94,-1,minecraft:magma_block)
B(-5,95,-1,minecraft:magma_block)
B(-5,96,-1,minecraft:magma_block)
B(-5,97,-1,minecraft:magma_block)
B(-5,26,0,minecraft:diorite)
B(-5,27,0,minecraft:diorite)
B(-5,28,0,minecraft:diorite)
B(-5,29,0,minecraft:diorite)
B(-5,30,0,minecraft:diorite)
B(-5,31,0,minecraft:grass_block)
B(-5,32,0,minecraft:water)
B(-5,33,0,minecraft:water)
B(-5,77,0,minecraft:obsidian)
B(-5,78,0,minecraft:obsidian)
B(-5,79,0,minecraft:obsidian)
B(-5,80,0,minecraft:obsidian)
B(-5,81,0,minecraft:obsidian)
B(-5,82,0,minecraft:obsidian)
B(-5,83,0,minecraft:obsidian)
B(-5,84,0,minecraft:obsidian)
B(-5,85,0,minecraft:obsidian)
B(-5,86,0,minecraft:obsidian)
B(-5,87,0,minecraft:obsidian)
B(-5,88,0,minecraft:obsidian)
B(-5,89,0,minecraft:obsidian)
B(-5,90,0,minecraft:obsidian)
B(-5,91,0,minecraft:magma_block)
B(-5,92,0,minecraft:magma_block)
B(-5,93,0,minecraft:magma_block)
B(-5,94,0,minecraft:magma_block)
B(-5,95,0,minecraft:magma_block)
B(-5,26,1,minecraft:diorite)
B(-5,27,1,minecraft:diorite)
B(-5,28,1,minecraft:diorite)
B(-5,29,1,minecraft:diorite)
B(-5,30,1,minecraft:grass_block)
B(-5,31,1,minecraft:water)
B(-5,32,1,minecraft:water)
B(-5,33,1,minecraft:water)
B(-5,76,1,minecraft:obsidian)
B(-5,77,1,minecraft:obsidian)
B(-5,78,1,minecraft:obsidian)
B(-5,79,1,minecraft:obsidian)
B(-5,80,1,minecraft:obsidian)
B(-5,81,1,minecraft:obsidian)
B(-5,82,1,minecraft:obsidian)
B(-5,83,1,minecraft:obsidian)
B(-5,84,1,minecraft:obsidian)
B(-5,85,1,minecraft:obsidian)
B(-5,86,1,minecraft:obsidian)
B(-5,87,1,minecraft:obsidian)
B(-5,88,1,minecraft:obsidian)
B(-5,89,1,minecraft:obsidian)
B(-5,90,1,minecraft:obsidian)
B(-5,91,1,minecraft:magma_block)
B(-5,92,1,minecraft:magma_block)
B(-5,93,1,minecraft:magma_block)
B(-5,94,1,minecraft:magma_block)
B(-5,26,2,minecraft:diorite)
B(-5,27,2,minecraft:diorite)
B(-5,28,2,minecraft:obsidian)
B(-5,29,2,minecraft:diorite)
B(-5,30,2,minecraft:diorite)
B(-5,31,2,minecraft:diorite)
B(-5,32,2,minecraft:water)
B(-5,33,2,minecraft:water)
B(-5,75,2,minecraft:obsidian)
B(-5,76,2,minecraft:obsidian)
B(-5,77,2,minecraft:obsidian)
B(-5,78,2,minecraft:obsidian)
B(-5,79,2,minecraft:obsidian)
B(-5,80,2,minecraft:obsidian)
B(-5,81,2,minecraft:obsidian)
B(-5,82,2,minecraft:obsidian)
B(-5,83,2,minecraft:obsidian)
B(-5,84,2,minecraft:obsidian)
B(-5,85,2,minecraft:obsidian)
B(-5,86,2,minecraft:obsidian)
B(-5,87,2,minecraft:obsidian)
B(-5,88,2,minecraft:obsidian)
B(-5,89,2,minecraft:obsidian)
B(-5,90,2,minecraft:obsidian)
B(-5,91,2,minecraft:magma_block)
B(-5,92,2,minecraft:magma_block)
B(-5,93,2,minecraft:magma_block)
B(-5,27,3,minecraft:diorite)
B(-5,28,3,minecraft:obsidian)
B(-5,29,3,minecraft:diorite)
B(-5,30,3,minecraft:diorite)
B(-5,31,3,minecraft:diorite)
B(-5,32,3,minecraft:water)
B(-5,33,3,minecraft:water)
B(-5,74,3,minecraft:obsidian)
B(-5,75,3,minecraft:obsidian)
B(-5,76,3,minecraft:obsidian)
B(-5,77,3,minecraft:obsidian)
B(-5,78,3,minecraft:obsidian)
B(-5,79,3,minecraft:obsidian)
B(-5,80,3,minecraft:obsidian)
B(-5,81,3,minecraft:obsidian)
B(-5,82,3,minecraft:obsidian)
B(-5,83,3,minecraft:obsidian)
B(-5,84,3,minecraft:obsidian)
B(-5,85,3,minecraft:obsidian)
B(-5,86,3,minecraft:obsidian)
B(-5,87,3,minecraft:obsidian)
B(-5,88,3,minecraft:obsidian)
B(-5,89,3,minecraft:obsidian)
B(-5,90,3,minecraft:obsidian)
B(-5,91,3,minecraft:obsidian)
B(-5,92,3,minecraft:magma_block)
B(-5,27,4,minecraft:diorite)
B(-5,28,4,minecraft:obsidian)
B(-5,29,4,minecraft:diorite)
B(-5,30,4,minecraft:diorite)
B(-5,31,4,minecraft:diorite)
B(-5,32,4,minecraft:diorite)
B(-5,33,4,minecraft:diorite)
B(-5,34,4,minecraft:diorite)
B(-5,35,4,minecraft:andesite)
B(-5,73,4,minecraft:obsidian)
B(-5,74,4,minecraft:obsidian)
B(-5,75,4,minecraft:obsidian)
B(-5,76,4,minecraft:obsidian)
B(-5,77,4,minecraft:obsidian)
B(-5,78,4,minecraft:obsidian)
B(-5,79,4,minecraft:obsidian)
B(-5,80,4,minecraft:obsidian)
B(-5,81,4,minecraft:obsidian)
B(-5,82,4,minecraft:obsidian)
B(-5,83,4,minecraft:obsidian)
B(-5,84,4,minecraft:obsidian)
B(-5,85,4,minecraft:obsidian)
B(-5,86,4,minecraft:obsidian)
B(-5,87,4,minecraft:obsidian)
B(-5,88,4,minecraft:obsidian)
B(-5,89,4,minecraft:obsidian)
B(-5,90,4,minecraft:obsidian)
B(-5,91,4,minecraft:obsidian)
B(-5,92,4,minecraft:obsidian)
B(-5,28,5,minecraft:diorite)
B(-5,29,5,minecraft:diorite)
B(-5,30,5,minecraft:diorite)
B(-5,31,5,minecraft:diorite)
B(-5,32,5,minecraft:diorite)
B(-5,33,5,minecraft:diorite)
B(-5,34,5,minecraft:andesite)
B(-5,35,5,minecraft:andesite)
B(-5,74,5,minecraft:obsidian)
B(-5,75,5,minecraft:obsidian)
B(-5,76,5,minecraft:obsidian)
B(-5,77,5,minecraft:obsidian)
B(-5,78,5,minecraft:obsidian)
B(-5,79,5,minecraft:obsidian)
B(-5,80,5,minecraft:obsidian)
B(-5,81,5,minecraft:obsidian)
B(-5,82,5,minecraft:obsidian)
B(-5,83,5,minecraft:obsidian)
B(-5,84,5,minecraft:obsidian)
B(-5,85,5,minecraft:obsidian)
B(-5,86,5,minecraft:obsidian)
B(-5,87,5,minecraft:obsidian)
B(-5,88,5,minecraft:obsidian)
B(-5,89,5,minecraft:obsidian)
B(-5,90,5,minecraft:obsidian)
B(-5,91,5,minecraft:obsidian)
B(-5,92,5,minecraft:obsidian)
B(-5,28,6,minecraft:diorite)
B(-5,29,6,minecraft:diorite)
B(-5,30,6,minecraft:diorite)
B(-5,31,6,minecraft:diorite)
B(-5,32,6,minecraft:diorite)
B(-5,33,6,minecraft:andesite)
B(-5,34,6,minecraft:andesite)
B(-5,35,6,minecraft:andesite)
B(-5,74,6,minecraft:obsidian)
B(-5,75,6,minecraft:obsidian)
B(-5,76,6,minecraft:obsidian)
B(-5,77,6,minecraft:obsidian)
B(-5,78,6,minecraft:obsidian)
B(-5,79,6,minecraft:obsidian)
B(-5,80,6,minecraft:obsidian)
B(-5,81,6,minecraft:obsidian)
B(-5,82,6,minecraft:obsidian)
B(-5,83,6,minecraft:obsidian)
B(-5,84,6,minecraft:obsidian)
B(-5,85,6,minecraft:obsidian)
B(-5,86,6,minecraft:obsidian)
B(-5,87,6,minecraft:obsidian)
B(-5,88,6,minecraft:obsidian)
B(-5,89,6,minecraft:obsidian)
B(-5,90,6,minecraft:obsidian)
B(-5,91,6,minecraft:obsidian)
B(-5,29,7,minecraft:diorite)
B(-5,30,7,minecraft:diorite)
B(-5,31,7,minecraft:diorite)
B(-5,32,7,minecraft:obsidian)
B(-5,33,7,minecraft:andesite)
B(-5,34,7,minecraft:andesite)
B(-5,35,7,minecraft:andesite)
B(-5,36,7,minecraft:andesite)
B(-5,37,7,minecraft:andesite)
B(-5,38,7,minecraft:obsidian)
B(-5,39,7,minecraft:obsidian)
B(-5,73,7,minecraft:obsidian)
B(-5,74,7,minecraft:obsidian)
B(-5,75,7,minecraft:obsidian)
B(-5,76,7,minecraft:obsidian)
B(-5,77,7,minecraft:obsidian)
B(-5,78,7,minecraft:obsidian)
B(-5,79,7,minecraft:obsidian)
B(-5,80,7,minecraft:obsidian)
B(-5,81,7,minecraft:obsidian)
B(-5,82,7,minecraft:obsidian)
B(-5,83,7,minecraft:obsidian)
B(-5,84,7,minecraft:obsidian)
B(-5,85,7,minecraft:obsidian)
B(-5,86,7,minecraft:obsidian)
B(-5,87,7,minecraft:obsidian)
B(-5,88,7,minecraft:obsidian)
B(-5,89,7,minecraft:obsidian)
B(-5,90,7,minecraft:diorite)
B(-5,91,7,minecraft:obsidian)
B(-5,29,8,minecraft:diorite)
B(-5,30,8,minecraft:diorite)
B(-5,31,8,minecraft:diorite)
B(-5,32,8,minecraft:obsidian)
B(-5,33,8,minecraft:obsidian)
B(-5,34,8,minecraft:andesite)
B(-5,35,8,minecraft:andesite)
B(-5,36,8,minecraft:andesite)
B(-5,37,8,minecraft:obsidian)
B(-5,38,8,minecraft:obsidian)
B(-5,39,8,minecraft:obsidian)
B(-5,72,8,minecraft:obsidian)
B(-5,73,8,minecraft:obsidian)
B(-5,74,8,minecraft:obsidian)
B(-5,75,8,minecraft:obsidian)
B(-5,76,8,minecraft:obsidian)
B(-5,77,8,minecraft:obsidian)
B(-5,78,8,minecraft:obsidian)
B(-5,79,8,minecraft:obsidian)
B(-5,80,8,minecraft:obsidian)
B(-5,81,8,minecraft:obsidian)
B(-5,82,8,minecraft:obsidian)
B(-5,83,8,minecraft:obsidian)
B(-5,84,8,minecraft:obsidian)
B(-5,85,8,minecraft:obsidian)
B(-5,86,8,minecraft:obsidian)
B(-5,87,8,minecraft:obsidian)
B(-5,88,8,minecraft:obsidian)
B(-5,89,8,minecraft:diorite)
B(-5,90,8,minecraft:diorite)
B(-4,22,-7,minecraft:diorite)
B(-4,23,-7,minecraft:diorite)
B(-4,24,-7,minecraft:diorite)
B(-4,25,-7,minecraft:diorite)
B(-4,26,-7,minecraft:diorite)
B(-4,27,-7,minecraft:diorite)
B(-4,28,-7,minecraft:obsidian)
B(-4,29,-7,minecraft:obsidian)
B(-4,30,-7,minecraft:obsidian)
B(-4,31,-7,minecraft:obsidian)
B(-4,32,-7,minecraft:obsidian)
B(-4,33,-7,minecraft:obsidian)
B(-4,34,-7,minecraft:andesite)
B(-4,35,-7,minecraft:andesite)
B(-4,36,-7,minecraft:andesite)
B(-4,37,-7,minecraft:andesite)
B(-4,38,-7,minecraft:andesite)
B(-4,80,-7,minecraft:obsidian)
B(-4,81,-7,minecraft:obsidian)
B(-4,82,-7,minecraft:obsidian)
B(-4,83,-7,minecraft:obsidian)
B(-4,84,-7,minecraft:obsidian)
B(-4,85,-7,minecraft:obsidian)
B(-4,86,-7,minecraft:obsidian)
B(-4,87,-7,minecraft:obsidian)
B(-4,88,-7,minecraft:obsidian)
B(-4,89,-7,minecraft:obsidian)
B(-4,90,-7,minecraft:obsidian)
B(-4,91,-7,minecraft:obsidian)
B(-4,92,-7,minecraft:obsidian)
B(-4,93,-7,minecraft:diorite)
B(-4,94,-7,minecraft:obsidian)
B(-4,95,-7,minecraft:obsidian)
B(-4,96,-7,minecraft:obsidian)
B(-4,97,-7,minecraft:obsidian)
B(-4,98,-7,minecraft:obsidian)
B(-4,99,-7,minecraft:obsidian)
B(-4,100,-7,minecraft:obsidian)
B(-4,23,-6,minecraft:diorite)
B(-4,24,-6,minecraft:diorite)
B(-4,25,-6,minecraft:diorite)
B(-4,26,-6,minecraft:diorite)
B(-4,27,-6,minecraft:diorite)
B(-4,28,-6,minecraft:obsidian)
B(-4,29,-6,minecraft:obsidian)
B(-4,30,-6,minecraft:obsidian)
B(-4,31,-6,minecraft:obsidian)
B(-4,32,-6,minecraft:obsidian)
B(-4,33,-6,minecraft:obsidian)
B(-4,34,-6,minecraft:andesite)
B(-4,35,-6,minecraft:andesite)
B(-4,36,-6,minecraft:andesite)
B(-4,37,-6,minecraft:grass_block)
B(-4,80,-6,minecraft:obsidian)
B(-4,81,-6,minecraft:obsidian)
B(-4,82,-6,minecraft:obsidian)
B(-4,83,-6,minecraft:obsidian)
B(-4,84,-6,minecraft:obsidian)
B(-4,85,-6,minecraft:obsidian)
B(-4,86,-6,minecraft:obsidian)
B(-4,87,-6,minecraft:obsidian)
B(-4,88,-6,minecraft:obsidian)
B(-4,89,-6,minecraft:obsidian)
B(-4,90,-6,minecraft:obsidian)
B(-4,91,-6,minecraft:obsidian)
B(-4,92,-6,minecraft:diorite)
B(-4,93,-6,minecraft:diorite)
B(-4,94,-6,minecraft:obsidian)
B(-4,95,-6,minecraft:obsidian)
B(-4,96,-6,minecraft:obsidian)
B(-4,97,-6,minecraft:obsidian)
B(-4,98,-6,minecraft:obsidian)
B(-4,99,-6,minecraft:obsidian)
B(-4,100,-6,minecraft:obsidian)
B(-4,23,-5,minecraft:diorite)
B(-4,24,-5,minecraft:diorite)
B(-4,25,-5,minecraft:diorite)
B(-4,26,-5,minecraft:diorite)
B(-4,27,-5,minecraft:diorite)
B(-4,28,-5,minecraft:diorite)
B(-4,29,-5,minecraft:obsidian)
B(-4,30,-5,minecraft:obsidian)
B(-4,31,-5,minecraft:obsidian)
B(-4,32,-5,minecraft:obsidian)
B(-4,33,-5,minecraft:obsidian)
B(-4,34,-5,minecraft:andesite)
B(-4,35,-5,minecraft:andesite)
B(-4,36,-5,minecraft:andesite)
B(-4,37,-5,minecraft:grass_block)
B(-4,80,-5,minecraft:obsidian)
B(-4,81,-5,minecraft:obsidian)
B(-4,82,-5,minecraft:obsidian)
B(-4,83,-5,minecraft:obsidian)
B(-4,84,-5,minecraft:obsidian)
B(-4,85,-5,minecraft:obsidian)
B(-4,86,-5,minecraft:obsidian)
B(-4,87,-5,minecraft:obsidian)
B(-4,88,-5,minecraft:obsidian)
B(-4,89,-5,minecraft:obsidian)
B(-4,90,-5,minecraft:obsidian)
B(-4,91,-5,minecraft:diorite)
B(-4,92,-5,minecraft:diorite)
B(-4,93,-5,minecraft:obsidian)
B(-4,94,-5,minecraft:obsidian)
B(-4,95,-5,minecraft:obsidian)
B(-4,96,-5,minecraft:obsidian)
B(-4,97,-5,minecraft:obsidian)
B(-4,98,-5,minecraft:obsidian)
B(-4,99,-5,minecraft:obsidian)
B(-4,23,-4,minecraft:diorite)
B(-4,24,-4,minecraft:diorite)
B(-4,25,-4,minecraft:diorite)
B(-4,26,-4,minecraft:diorite)
B(-4,27,-4,minecraft:diorite)
B(-4,28,-4,minecraft:diorite)
B(-4,29,-4,minecraft:diorite)
B(-4,30,-4,minecraft:obsidian)
B(-4,31,-4,minecraft:obsidian)
B(-4,32,-4,minecraft:andesite)
B(-4,33,-4,minecraft:andesite)
B(-4,34,-4,minecraft:andesite)
B(-4,35,-4,minecraft:grass_block)
B(-4,80,-4,minecraft:obsidian)
B(-4,81,-4,minecraft:obsidian)
B(-4,82,-4,minecraft:obsidian)
B(-4,83,-4,minecraft:obsidian)
B(-4,84,-4,minecraft:obsidian)
B(-4,85,-4,minecraft:obsidian)
B(-4,86,-4,minecraft:obsidian)
B(-4,87,-4,minecraft:obsidian)
B(-4,88,-4,minecraft:obsidian)
B(-4,89,-4,minecraft:obsidian)
B(-4,90,-4,minecraft:obsidian)
B(-4,91,-4,minecraft:diorite)
B(-4,92,-4,minecraft:obsidian)
B(-4,93,-4,minecraft:obsidian)
B(-4,94,-4,minecraft:obsidian)
B(-4,95,-4,minecraft:obsidian)
B(-4,96,-4,minecraft:obsidian)
B(-4,97,-4,minecraft:obsidian)
B(-4,98,-4,minecraft:obsidian)
B(-4,99,-4,minecraft:obsidian)
B(-4,24,-3,minecraft:diorite)
B(-4,25,-3,minecraft:diorite)
B(-4,26,-3,minecraft:diorite)
B(-4,27,-3,minecraft:diorite)
B(-4,28,-3,minecraft:diorite)
B(-4,29,-3,minecraft:diorite)
B(-4,30,-3,minecraft:obsidian)
B(-4,31,-3,minecraft:andesite)
B(-4,32,-3,minecraft:andesite)
B(-4,33,-3,minecraft:diorite)
B(-4,34,-3,minecraft:grass_block)
B(-4,80,-3,minecraft:obsidian)
B(-4,81,-3,minecraft:obsidian)
B(-4,82,-3,minecraft:obsidian)
B(-4,83,-3,minecraft:obsidian)
B(-4,84,-3,minecraft:obsidian)
B(-4,85,-3,minecraft:obsidian)
B(-4,86,-3,minecraft:obsidian)
B(-4,87,-3,minecraft:obsidian)
B(-4,88,-3,minecraft:obsidian)
B(-4,89,-3,minecraft:obsidian)
B(-4,90,-3,minecraft:obsidian)
B(-4,91,-3,minecraft:obsidian)
B(-4,92,-3,minecraft:obsidian)
B(-4,93,-3,minecraft:obsidian)
B(-4,94,-3,minecraft:obsidian)
B(-4,95,-3,minecraft:obsidian)
B(-4,96,-3,minecraft:obsidian)
B(-4,97,-3,minecraft:obsidian)
B(-4,98,-3,minecraft:obsidian)
B(-4,99,-3,minecraft:obsidian)
B(-4,25,-2,minecraft:diorite)
B(-4,26,-2,minecraft:diorite)
B(-4,27,-2,minecraft:diorite)
B(-4,28,-2,minecraft:diorite)
B(-4,29,-2,minecraft:diorite)
B(-4,30,-2,minecraft:andesite)
B(-4,31,-2,minecraft:diorite)
B(-4,32,-2,minecraft:diorite)
B(-4,33,-2,minecraft:grass_block)
B(-4,79,-2,minecraft:obsidian)
B(-4,80,-2,minecraft:obsidian)
B(-4,81,-2,minecraft:obsidian)
B(-4,82,-2,minecraft:obsidian)
B(-4,83,-2,minecraft:obsidian)
B(-4,84,-2,minecraft:obsidian)
B(-4,85,-2,minecraft:obsidian)
B(-4,86,-2,minecraft:obsidian)
B(-4,87,-2,minecraft:obsidian)
B(-4,88,-2,minecraft:obsidian)
B(-4,89,-2,minecraft:obsidian)
B(-4,90,-2,minecraft:obsidian)
B(-4,91,-2,minecraft:obsidian)
B(-4,92,-2,minecraft:obsidian)
B(-4,93,-2,minecraft:obsidian)
B(-4,94,-2,minecraft:magma_block)
B(-4,95,-2,minecraft:magma_block)
B(-4,96,-2,minecraft:magma_block)
B(-4,97,-2,minecraft:obsidian)
B(-4,98,-2,minecraft:obsidian)
B(-4,99,-2,minecraft:obsidian)
B(-4,25,-1,minecraft:diorite)
B(-4,26,-1,minecraft:diorite)
B(-4,27,-1,minecraft:diorite)
B(-4,28,-1,minecraft:diorite)
B(-4,29,-1,minecraft:diorite)
B(-4,30,-1,minecraft:andesite)
B(-4,31,-1,minecraft:diorite)
B(-4,32,-1,minecraft:grass_block)
B(-4,33,-1,minecraft:water)
B(-4,77,-1,minecraft:obsidian)
B(-4,78,-1,minecraft:obsidian)
B(-4,79,-1,minecraft:obsidian)
B(-4,80,-1,minecraft:obsidian)
B(-4,81,-1,minecraft:obsidian)
B(-4,82,-1,minecraft:obsidian)
B(-4,83,-1,minecraft:obsidian)
B(-4,84,-1,minecraft:obsidian)
B(-4,85,-1,minecraft:obsidian)
B(-4,86,-1,minecraft:obsidian)
B(-4,87,-1,minecraft:obsidian)
B(-4,88,-1,minecraft:obsidian)
B(-4,89,-1,minecraft:obsidian)
B(-4,90,-1,minecraft:obsidian)
B(-4,91,-1,minecraft:obsidian)
B(-4,92,-1,minecraft:magma_block)
B(-4,93,-1,minecraft:magma_block)
B(-4,94,-1,minecraft:magma_block)
B(-4,95,-1,minecraft:magma_block)
B(-4,96,-1,minecraft:magma_block)
B(-4,97,-1,minecraft:magma_block)
B(-4,26,0,minecraft:diorite)
B(-4,27,0,minecraft:diorite)
B(-4,28,0,minecraft:diorite)
B(-4,29,0,minecraft:diorite)
B(-4,30,0,minecraft:diorite)
B(-4,31,0,minecraft:grass_block)
B(-4,32,0,minecraft:water)
B(-4,33,0,minecraft:water)
B(-4,77,0,minecraft:obsidian)
B(-4,78,0,minecraft:obsidian)
B(-4,79,0,minecraft:obsidian)
B(-4,80,0,minecraft:obsidian)
B(-4,81,0,minecraft:obsidian)
B(-4,82,0,minecraft:obsidian)
B(-4,83,0,minecraft:obsidian)
B(-4,84,0,minecraft:obsidian)
B(-4,85,0,minecraft:obsidian)
B(-4,86,0,minecraft:obsidian)
B(-4,87,0,minecraft:obsidian)
B(-4,88,0,minecraft:obsidian)
B(-4,89,0,minecraft:obsidian)
B(-4,90,0,minecraft:obsidian)
B(-4,91,0,minecraft:magma_block)
B(-4,92,0,minecraft:magma_block)
B(-4,93,0,minecraft:magma_block)
B(-4,94,0,minecraft:magma_block)
B(-4,26,1,minecraft:diorite)
B(-4,27,1,minecraft:diorite)
B(-4,28,1,minecraft:diorite)
B(-4,29,1,minecraft:andesite)
B(-4,30,1,minecraft:diorite)
B(-4,31,1,minecraft:grass_block)
B(-4,32,1,minecraft:water)
B(-4,33,1,minecraft:water)
B(-4,77,1,minecraft:obsidian)
B(-4,78,1,minecraft:obsidian)
B(-4,79,1,minecraft:obsidian)
B(-4,80,1,minecraft:obsidian)
B(-4,81,1,minecraft:obsidian)
B(-4,82,1,minecraft:obsidian)
B(-4,83,1,minecraft:obsidian)
B(-4,84,1,minecraft:obsidian)
B(-4,85,1,minecraft:obsidian)
B(-4,86,1,minecraft:obsidian)
B(-4,87,1,minecraft:obsidian)
B(-4,88,1,minecraft:obsidian)
B(-4,89,1,minecraft:obsidian)
B(-4,90,1,minecraft:obsidian)
B(-4,91,1,minecraft:magma_block)
B(-4,92,1,minecraft:magma_block)
B(-4,93,1,minecraft:magma_block)
B(-4,26,2,minecraft:diorite)
B(-4,27,2,minecraft:diorite)
B(-4,28,2,minecraft:obsidian)
B(-4,29,2,minecraft:obsidian)
B(-4,30,2,minecraft:diorite)
B(-4,31,2,minecraft:grass_block)
B(-4,32,2,minecraft:water)
B(-4,33,2,minecraft:water)
B(-4,76,2,minecraft:obsidian)
B(-4,77,2,minecraft:obsidian)
B(-4,78,2,minecraft:obsidian)
B(-4,79,2,minecraft:obsidian)
B(-4,80,2,minecraft:obsidian)
B(-4,81,2,minecraft:obsidian)
B(-4,82,2,minecraft:obsidian)
B(-4,83,2,minecraft:obsidian)
B(-4,84,2,minecraft:obsidian)
B(-4,85,2,minecraft:obsidian)
B(-4,86,2,minecraft:obsidian)
B(-4,87,2,minecraft:obsidian)
B(-4,88,2,minecraft:obsidian)
B(-4,89,2,minecraft:obsidian)
B(-4,90,2,minecraft:obsidian)
B(-4,91,2,minecraft:magma_block)
B(-4,92,2,minecraft:magma_block)
B(-4,93,2,minecraft:magma_block)
B(-4,26,3,minecraft:diorite)
B(-4,27,3,minecraft:diorite)
B(-4,28,3,minecraft:obsidian)
B(-4,29,3,minecraft:diorite)
B(-4,30,3,minecraft:diorite)
B(-4,31,3,minecraft:diorite)
B(-4,32,3,minecraft:diorite)
B(-4,33,3,minecraft:water)
B(-4,75,3,minecraft:obsidian)
B(-4,76,3,minecraft:obsidian)
B(-4,77,3,minecraft:obsidian)
B(-4,78,3,minecraft:obsidian)
B(-4,79,3,minecraft:obsidian)
B(-4,80,3,minecraft:obsidian)
B(-4,81,3,minecraft:obsidian)
B(-4,82,3,minecraft:obsidian)
B(-4,83,3,minecraft:obsidian)
B(-4,84,3,minecraft:obsidian)
B(-4,85,3,minecraft:obsidian)
B(-4,86,3,minecraft:obsidian)
B(-4,87,3,minecraft:obsidian)
B(-4,88,3,minecraft:obsidian)
B(-4,89,3,minecraft:obsidian)
B(-4,90,3,minecraft:obsidian)
B(-4,91,3,minecraft:magma_block)
B(-4,92,3,minecraft:magma_block)
B(-4,27,4,minecraft:diorite)
B(-4,28,4,minecraft:obsidian)
B(-4,29,4,minecraft:diorite)
B(-4,30,4,minecraft:diorite)
B(-4,31,4,minecraft:diorite)
B(-4,32,4,minecraft:diorite)
B(-4,33,4,minecraft:diorite)
B(-4,34,4,minecraft:diorite)
B(-4,74,4,minecraft:obsidian)
B(-4,75,4,minecraft:obsidian)
B(-4,76,4,minecraft:obsidian)
B(-4,77,4,minecraft:obsidian)
B(-4,78,4,minecraft:obsidian)
B(-4,79,4,minecraft:obsidian)
B(-4,80,4,minecraft:obsidian)
B(-4,81,4,minecraft:obsidian)
B(-4,82,4,minecraft:obsidian)
B(-4,83,4,minecraft:obsidian)
B(-4,84,4,minecraft:obsidian)
B(-4,85,4,minecraft:obsidian)
B(-4,86,4,minecraft:obsidian)
B(-4,87,4,minecraft:obsidian)
B(-4,88,4,minecraft:obsidian)
B(-4,89,4,minecraft:obsidian)
B(-4,90,4,minecraft:obsidian)
B(-4,91,4,minecraft:obsidian)
B(-4,92,4,minecraft:magma_block)
B(-4,27,5,minecraft:diorite)
B(-4,28,5,minecraft:diorite)
B(-4,29,5,minecraft:diorite)
B(-4,30,5,minecraft:diorite)
B(-4,31,5,minecraft:diorite)
B(-4,32,5,minecraft:diorite)
B(-4,33,5,minecraft:diorite)
B(-4,34,5,minecraft:andesite)
B(-4,35,5,minecraft:andesite)
B(-4,75,5,minecraft:obsidian)
B(-4,76,5,minecraft:obsidian)
B(-4,77,5,minecraft:obsidian)
B(-4,78,5,minecraft:obsidian)
B(-4,79,5,minecraft:obsidian)
B(-4,80,5,minecraft:obsidian)
B(-4,81,5,minecraft:obsidian)
B(-4,82,5,minecraft:obsidian)
B(-4,83,5,minecraft:obsidian)
B(-4,84,5,minecraft:obsidian)
B(-4,85,5,minecraft:obsidian)
B(-4,86,5,minecraft:obsidian)
B(-4,87,5,minecraft:obsidian)
B(-4,88,5,minecraft:obsidian)
B(-4,89,5,minecraft:obsidian)
B(-4,90,5,minecraft:obsidian)
B(-4,91,5,minecraft:obsidian)
B(-4,92,5,minecraft:obsidian)
B(-4,28,6,minecraft:diorite)
B(-4,29,6,minecraft:diorite)
B(-4,30,6,minecraft:diorite)
B(-4,31,6,minecraft:diorite)
B(-4,32,6,minecraft:diorite)
B(-4,33,6,minecraft:andesite)
B(-4,34,6,minecraft:andesite)
B(-4,35,6,minecraft:andesite)
B(-4,74,6,minecraft:obsidian)
B(-4,75,6,minecraft:obsidian)
B(-4,76,6,minecraft:obsidian)
B(-4,77,6,minecraft:obsidian)
B(-4,78,6,minecraft:obsidian)
B(-4,79,6,minecraft:obsidian)
B(-4,80,6,minecraft:obsidian)
B(-4,81,6,minecraft:obsidian)
B(-4,82,6,minecraft:obsidian)
B(-4,83,6,minecraft:obsidian)
B(-4,84,6,minecraft:obsidian)
B(-4,85,6,minecraft:obsidian)
B(-4,86,6,minecraft:obsidian)
B(-4,87,6,minecraft:obsidian)
B(-4,88,6,minecraft:obsidian)
B(-4,89,6,minecraft:obsidian)
B(-4,90,6,minecraft:obsidian)
B(-4,91,6,minecraft:obsidian)
B(-4,29,7,minecraft:diorite)
B(-4,30,7,minecraft:diorite)
B(-4,31,7,minecraft:diorite)
B(-4,32,7,minecraft:obsidian)
B(-4,33,7,minecraft:andesite)
B(-4,34,7,minecraft:andesite)
B(-4,35,7,minecraft:andesite)
B(-4,36,7,minecraft:andesite)
B(-4,37,7,minecraft:andesite)
B(-4,38,7,minecraft:obsidian)
B(-4,73,7,minecraft:obsidian)
B(-4,74,7,minecraft:obsidian)
B(-4,75,7,minecraft:obsidian)
B(-4,76,7,minecraft:obsidian)
B(-4,77,7,minecraft:obsidian)
B(-4,78,7,minecraft:obsidian)
B(-4,79,7,minecraft:obsidian)
B(-4,80,7,minecraft:obsidian)
B(-4,81,7,minecraft:obsidian)
B(-4,82,7,minecraft:obsidian)
B(-4,83,7,minecraft:obsidian)
B(-4,84,7,minecraft:obsidian)
B(-4,85,7,minecraft:obsidian)
B(-4,86,7,minecraft:obsidian)
B(-4,87,7,minecraft:obsidian)
B(-4,88,7,minecraft:obsidian)
B(-4,89,7,minecraft:obsidian)
B(-4,90,7,minecraft:obsidian)
B(-4,91,7,minecraft:obsidian)
B(-4,29,8,minecraft:diorite)
B(-4,30,8,minecraft:diorite)
B(-4,31,8,minecraft:diorite)
B(-4,32,8,minecraft:diorite)
B(-4,33,8,minecraft:obsidian)
B(-4,34,8,minecraft:andesite)
B(-4,35,8,minecraft:andesite)
B(-4,36,8,minecraft:andesite)
B(-4,37,8,minecraft:obsidian)
B(-4,38,8,minecraft:obsidian)
B(-4,39,8,minecraft:obsidian)
B(-4,73,8,minecraft:obsidian)
B(-4,74,8,minecraft:obsidian)
B(-4,75,8,minecraft:obsidian)
B(-4,76,8,minecraft:obsidian)
B(-4,77,8,minecraft:obsidian)
B(-4,78,8,minecraft:obsidian)
B(-4,79,8,minecraft:obsidian)
B(-4,80,8,minecraft:obsidian)
B(-4,81,8,minecraft:obsidian)
B(-4,82,8,minecraft:obsidian)
B(-4,83,8,minecraft:obsidian)
B(-4,84,8,minecraft:obsidian)
B(-4,85,8,minecraft:obsidian)
B(-4,86,8,minecraft:obsidian)
B(-4,87,8,minecraft:obsidian)
B(-4,88,8,minecraft:obsidian)
B(-4,89,8,minecraft:obsidian)
B(-4,90,8,minecraft:obsidian)
B(-4,91,8,minecraft:obsidian)
B(-3,22,-7,minecraft:diorite)
B(-3,23,-7,minecraft:diorite)
B(-3,24,-7,minecraft:diorite)
B(-3,25,-7,minecraft:diorite)
B(-3,26,-7,minecraft:diorite)
B(-3,27,-7,minecraft:diorite)
B(-3,28,-7,minecraft:obsidian)
B(-3,29,-7,minecraft:obsidian)
B(-3,30,-7,minecraft:obsidian)
B(-3,31,-7,minecraft:obsidian)
B(-3,32,-7,minecraft:obsidian)
B(-3,33,-7,minecraft:obsidian)
B(-3,34,-7,minecraft:obsidian)
B(-3,35,-7,minecraft:andesite)
B(-3,36,-7,minecraft:andesite)
B(-3,37,-7,minecraft:andesite)
B(-3,38,-7,minecraft:andesite)
B(-3,79,-7,minecraft:obsidian)
B(-3,80,-7,minecraft:obsidian)
B(-3,81,-7,minecraft:obsidian)
B(-3,82,-7,minecraft:obsidian)
B(-3,83,-7,minecraft:obsidian)
B(-3,84,-7,minecraft:obsidian)
B(-3,85,-7,minecraft:obsidian)
B(-3,86,-7,minecraft:obsidian)
B(-3,87,-7,minecraft:obsidian)
B(-3,88,-7,minecraft:obsidian)
B(-3,89,-7,minecraft:obsidian)
B(-3,90,-7,minecraft:obsidian)
B(-3,91,-7,minecraft:obsidian)
B(-3,92,-7,minecraft:obsidian)
B(-3,93,-7,minecraft:obsidian)
B(-3,94,-7,minecraft:diorite)
B(-3,95,-7,minecraft:obsidian)
B(-3,96,-7,minecraft:obsidian)
B(-3,97,-7,minecraft:obsidian)
B(-3,98,-7,minecraft:obsidian)
B(-3,99,-7,minecraft:obsidian)
B(-3,100,-7,minecraft:obsidian)
B(-3,101,-7,minecraft:obsidian)
B(-3,22,-6,minecraft:diorite)
B(-3,23,-6,minecraft:diorite)
B(-3,24,-6,minecraft:diorite)
B(-3,25,-6,minecraft:diorite)
B(-3,26,-6,minecraft:diorite)
B(-3,27,-6,minecraft:diorite)
B(-3,28,-6,minecraft:obsidian)
B(-3,29,-6,minecraft:obsidian)
B(-3,30,-6,minecraft:obsidian)
B(-3,31,-6,minecraft:obsidian)
B(-3,32,-6,minecraft:obsidian)
B(-3,33,-6,minecraft:obsidian)
B(-3,34,-6,minecraft:obsidian)
B(-3,35,-6,minecraft:andesite)
B(-3,36,-6,minecraft:andesite)
B(-3,37,-6,minecraft:grass_block)
B(-3,79,-6,minecraft:obsidian)
B(-3,80,-6,minecraft:obsidian)
B(-3,81,-6,minecraft:obsidian)
B(-3,82,-6,minecraft:obsidian)
B(-3,83,-6,minecraft:obsidian)
B(-3,84,-6,minecraft:obsidian)
B(-3,85,-6,minecraft:obsidian)
B(-3,86,-6,minecraft:obsidian)
B(-3,87,-6,minecraft:obsidian)
B(-3,88,-6,minecraft:obsidian)
B(-3,89,-6,minecraft:obsidian)
B(-3,90,-6,minecraft:obsidian)
B(-3,91,-6,minecraft:obsidian)
B(-3,92,-6,minecraft:obsidian)
B(-3,93,-6,minecraft:diorite)
B(-3,94,-6,minecraft:diorite)
B(-3,95,-6,minecraft:obsidian)
B(-3,96,-6,minecraft:obsidian)
B(-3,97,-6,minecraft:obsidian)
B(-3,98,-6,minecraft:obsidian)
B(-3,99,-6,minecraft:obsidian)
B(-3,100,-6,minecraft:obsidian)
B(-3,23,-5,minecraft:diorite)
B(-3,24,-5,minecraft:diorite)
B(-3,25,-5,minecraft:diorite)
B(-3,26,-5,minecraft:diorite)
B(-3,27,-5,minecraft:diorite)
B(-3,28,-5,minecraft:diorite)
B(-3,29,-5,minecraft:obsidian)
B(-3,30,-5,minecraft:obsidian)
B(-3,31,-5,minecraft:obsidian)
B(-3,32,-5,minecraft:obsidian)
B(-3,33,-5,minecraft:obsidian)
B(-3,34,-5,minecraft:obsidian)
B(-3,35,-5,minecraft:andesite)
B(-3,36,-5,minecraft:andesite)
B(-3,37,-5,minecraft:grass_block)
B(-3,79,-5,minecraft:obsidian)
B(-3,80,-5,minecraft:obsidian)
B(-3,81,-5,minecraft:obsidian)
B(-3,82,-5,minecraft:obsidian)
B(-3,83,-5,minecraft:obsidian)
B(-3,84,-5,minecraft:obsidian)
B(-3,85,-5,minecraft:obsidian)
B(-3,86,-5,minecraft:obsidian)
B(-3,87,-5,minecraft:obsidian)
B(-3,88,-5,minecraft:obsidian)
B(-3,89,-5,minecraft:obsidian)
B(-3,90,-5,minecraft:obsidian)
B(-3,91,-5,minecraft:obsidian)
B(-3,92,-5,minecraft:diorite)
B(-3,93,-5,minecraft:diorite)
B(-3,94,-5,minecraft:diorite)
B(-3,95,-5,minecraft:obsidian)
B(-3,96,-5,minecraft:obsidian)
B(-3,97,-5,minecraft:obsidian)
B(-3,98,-5,minecraft:obsidian)
B(-3,99,-5,minecraft:obsidian)
B(-3,100,-5,minecraft:obsidian)
B(-3,23,-4,minecraft:diorite)
B(-3,24,-4,minecraft:diorite)
B(-3,25,-4,minecraft:diorite)
B(-3,26,-4,minecraft:diorite)
B(-3,27,-4,minecraft:diorite)
B(-3,28,-4,minecraft:diorite)
B(-3,29,-4,minecraft:diorite)
B(-3,30,-4,minecraft:obsidian)
B(-3,31,-4,minecraft:obsidian)
B(-3,32,-4,minecraft:obsidian)
B(-3,33,-4,minecraft:diorite)
B(-3,34,-4,minecraft:diorite)
B(-3,35,-4,minecraft:diorite)
B(-3,36,-4,minecraft:grass_block)
B(-3,79,-4,minecraft:obsidian)
B(-3,80,-4,minecraft:obsidian)
B(-3,81,-4,minecraft:obsidian)
B(-3,82,-4,minecraft:obsidian)
B(-3,83,-4,minecraft:obsidian)
B(-3,84,-4,minecraft:obsidian)
B(-3,85,-4,minecraft:obsidian)
B(-3,86,-4,minecraft:obsidian)
B(-3,87,-4,minecraft:obsidian)
B(-3,88,-4,minecraft:obsidian)
B(-3,89,-4,minecraft:obsidian)
B(-3,90,-4,minecraft:obsidian)
B(-3,91,-4,minecraft:obsidian)
B(-3,92,-4,minecraft:diorite)
B(-3,93,-4,minecraft:obsidian)
B(-3,94,-4,minecraft:obsidian)
B(-3,95,-4,minecraft:obsidian)
B(-3,96,-4,minecraft:obsidian)
B(-3,97,-4,minecraft:obsidian)
B(-3,98,-4,minecraft:obsidian)
B(-3,99,-4,minecraft:obsidian)
B(-3,100,-4,minecraft:obsidian)
B(-3,24,-3,minecraft:diorite)
B(-3,25,-3,minecraft:diorite)
B(-3,26,-3,minecraft:diorite)
B(-3,27,-3,minecraft:diorite)
B(-3,28,-3,minecraft:diorite)
B(-3,29,-3,minecraft:diorite)
B(-3,30,-3,minecraft:obsidian)
B(-3,31,-3,minecraft:diorite)
B(-3,32,-3,minecraft:diorite)
B(-3,33,-3,minecraft:diorite)
B(-3,79,-3,minecraft:obsidian)
B(-3,80,-3,minecraft:obsidian)
B(-3,81,-3,minecraft:obsidian)
B(-3,82,-3,minecraft:obsidian)
B(-3,83,-3,minecraft:obsidian)
B(-3,84,-3,minecraft:obsidian)
B(-3,85,-3,minecraft:obsidian)
B(-3,86,-3,minecraft:obsidian)
B(-3,87,-3,minecraft:obsidian)
B(-3,88,-3,minecraft:obsidian)
B(-3,89,-3,minecraft:obsidian)
B(-3,90,-3,minecraft:obsidian)
B(-3,91,-3,minecraft:obsidian)
B(-3,92,-3,minecraft:obsidian)
B(-3,93,-3,minecraft:obsidian)
B(-3,94,-3,minecraft:obsidian)
B(-3,95,-3,minecraft:obsidian)
B(-3,96,-3,minecraft:obsidian)
B(-3,97,-3,minecraft:obsidian)
B(-3,98,-3,minecraft:obsidian)
B(-3,99,-3,minecraft:obsidian)
B(-3,24,-2,minecraft:diorite)
B(-3,25,-2,minecraft:diorite)
B(-3,26,-2,minecraft:diorite)
B(-3,27,-2,minecraft:diorite)
B(-3,28,-2,minecraft:diorite)
B(-3,29,-2,minecraft:diorite)
B(-3,30,-2,minecraft:diorite)
B(-3,31,-2,minecraft:diorite)
B(-3,32,-2,minecraft:diorite)
B(-3,33,-2,minecraft:water)
B(-3,79,-2,minecraft:obsidian)
B(-3,80,-2,minecraft:obsidian)
B(-3,81,-2,minecraft:obsidian)
B(-3,82,-2,minecraft:obsidian)
B(-3,83,-2,minecraft:obsidian)
B(-3,84,-2,minecraft:obsidian)
B(-3,85,-2,minecraft:obsidian)
B(-3,86,-2,minecraft:obsidian)
B(-3,87,-2,minecraft:obsidian)
B(-3,88,-2,minecraft:obsidian)
B(-3,89,-2,minecraft:obsidian)
B(-3,90,-2,minecraft:obsidian)
B(-3,91,-2,minecraft:obsidian)
B(-3,92,-2,minecraft:obsidian)
B(-3,93,-2,minecraft:obsidian)
B(-3,94,-2,minecraft:obsidian)
B(-3,95,-2,minecraft:obsidian)
B(-3,96,-2,minecraft:obsidian)
B(-3,97,-2,minecraft:obsidian)
B(-3,98,-2,minecraft:obsidian)
B(-3,99,-2,minecraft:obsidian)
B(-3,25,-1,minecraft:diorite)
B(-3,26,-1,minecraft:diorite)
B(-3,27,-1,minecraft:diorite)
B(-3,28,-1,minecraft:diorite)
B(-3,29,-1,minecraft:diorite)
B(-3,30,-1,minecraft:diorite)
B(-3,31,-1,minecraft:diorite)
B(-3,32,-1,minecraft:water)
B(-3,33,-1,minecraft:water)
B(-3,78,-1,minecraft:obsidian)
B(-3,79,-1,minecraft:obsidian)
B(-3,80,-1,minecraft:obsidian)
B(-3,81,-1,minecraft:obsidian)
B(-3,82,-1,minecraft:obsidian)
B(-3,83,-1,minecraft:obsidian)
B(-3,84,-1,minecraft:obsidian)
B(-3,85,-1,minecraft:obsidian)
B(-3,86,-1,minecraft:obsidian)
B(-3,87,-1,minecraft:obsidian)
B(-3,88,-1,minecraft:obsidian)
B(-3,89,-1,minecraft:obsidian)
B(-3,90,-1,minecraft:obsidian)
B(-3,91,-1,minecraft:obsidian)
B(-3,92,-1,minecraft:magma_block)
B(-3,93,-1,minecraft:magma_block)
B(-3,94,-1,minecraft:magma_block)
B(-3,95,-1,minecraft:magma_block)
B(-3,96,-1,minecraft:magma_block)
B(-3,97,-1,minecraft:obsidian)
B(-3,98,-1,minecraft:obsidian)
B(-3,25,0,minecraft:diorite)
B(-3,26,0,minecraft:diorite)
B(-3,27,0,minecraft:diorite)
B(-3,28,0,minecraft:diorite)
B(-3,29,0,minecraft:diorite)
B(-3,30,0,minecraft:diorite)
B(-3,31,0,minecraft:grass_block)
B(-3,32,0,minecraft:water)
B(-3,33,0,minecraft:water)
B(-3,77,0,minecraft:obsidian)
B(-3,78,0,minecraft:obsidian)
B(-3,79,0,minecraft:obsidian)
B(-3,80,0,minecraft:obsidian)
B(-3,81,0,minecraft:obsidian)
B(-3,82,0,minecraft:obsidian)
B(-3,83,0,minecraft:obsidian)
B(-3,84,0,minecraft:obsidian)
B(-3,85,0,minecraft:obsidian)
B(-3,86,0,minecraft:obsidian)
B(-3,87,0,minecraft:obsidian)
B(-3,88,0,minecraft:obsidian)
B(-3,89,0,minecraft:obsidian)
B(-3,90,0,minecraft:obsidian)
B(-3,91,0,minecraft:magma_block)
B(-3,92,0,minecraft:magma_block)
B(-3,93,0,minecraft:magma_block)
B(-3,26,1,minecraft:diorite)
B(-3,27,1,minecraft:diorite)
B(-3,28,1,minecraft:diorite)
B(-3,29,1,minecraft:andesite)
B(-3,30,1,minecraft:grass_block)
B(-3,31,1,minecraft:water)
B(-3,32,1,minecraft:water)
B(-3,33,1,minecraft:water)
B(-3,77,1,minecraft:obsidian)
B(-3,78,1,minecraft:obsidian)
B(-3,79,1,minecraft:obsidian)
B(-3,80,1,minecraft:obsidian)
B(-3,81,1,minecraft:obsidian)
B(-3,82,1,minecraft:obsidian)
B(-3,83,1,minecraft:obsidian)
B(-3,84,1,minecraft:obsidian)
B(-3,85,1,minecraft:obsidian)
B(-3,86,1,minecraft:obsidian)
B(-3,87,1,minecraft:obsidian)
B(-3,88,1,minecraft:obsidian)
B(-3,89,1,minecraft:obsidian)
B(-3,90,1,minecraft:obsidian)
B(-3,91,1,minecraft:magma_block)
B(-3,92,1,minecraft:magma_block)
B(-3,93,1,minecraft:magma_block)
B(-3,26,2,minecraft:diorite)
B(-3,27,2,minecraft:diorite)
B(-3,28,2,minecraft:diorite)
B(-3,29,2,minecraft:obsidian)
B(-3,30,2,minecraft:diorite)
B(-3,31,2,minecraft:grass_block)
B(-3,32,2,minecraft:water)
B(-3,33,2,minecraft:water)
B(-3,77,2,minecraft:obsidian)
B(-3,78,2,minecraft:obsidian)
B(-3,79,2,minecraft:obsidian)
B(-3,80,2,minecraft:obsidian)
B(-3,81,2,minecraft:obsidian)
B(-3,82,2,minecraft:obsidian)
B(-3,83,2,minecraft:obsidian)
B(-3,84,2,minecraft:obsidian)
B(-3,85,2,minecraft:obsidian)
B(-3,86,2,minecraft:obsidian)
B(-3,87,2,minecraft:obsidian)
B(-3,88,2,minecraft:obsidian)
B(-3,89,2,minecraft:obsidian)
B(-3,90,2,minecraft:obsidian)
B(-3,91,2,minecraft:magma_block)
B(-3,92,2,minecraft:magma_block)
B(-3,93,2,minecraft:magma_block)
B(-3,26,3,minecraft:diorite)
B(-3,27,3,minecraft:diorite)
B(-3,28,3,minecraft:diorite)
B(-3,29,3,minecraft:obsidian)
B(-3,30,3,minecraft:diorite)
B(-3,31,3,minecraft:diorite)
B(-3,32,3,minecraft:grass_block)
B(-3,33,3,minecraft:water)
B(-3,76,3,minecraft:obsidian)
B(-3,77,3,minecraft:obsidian)
B(-3,78,3,minecraft:obsidian)
B(-3,79,3,minecraft:obsidian)
B(-3,80,3,minecraft:obsidian)
B(-3,81,3,minecraft:obsidian)
B(-3,82,3,minecraft:obsidian)
B(-3,83,3,minecraft:obsidian)
B(-3,84,3,minecraft:obsidian)
B(-3,85,3,minecraft:obsidian)
B(-3,86,3,minecraft:obsidian)
B(-3,87,3,minecraft:obsidian)
B(-3,88,3,minecraft:obsidian)
B(-3,89,3,minecraft:obsidian)
B(-3,90,3,minecraft:obsidian)
B(-3,91,3,minecraft:magma_block)
B(-3,92,3,minecraft:magma_block)
B(-3,27,4,minecraft:diorite)
B(-3,28,4,minecraft:diorite)
B(-3,29,4,minecraft:obsidian)
B(-3,30,4,minecraft:diorite)
B(-3,31,4,minecraft:diorite)
B(-3,32,4,minecraft:diorite)
B(-3,33,4,minecraft:diorite)
B(-3,75,4,minecraft:obsidian)
B(-3,76,4,minecraft:obsidian)
B(-3,77,4,minecraft:obsidian)
B(-3,78,4,minecraft:obsidian)
B(-3,79,4,minecraft:obsidian)
B(-3,80,4,minecraft:obsidian)
B(-3,81,4,minecraft:obsidian)
B(-3,82,4,minecraft:obsidian)
B(-3,83,4,minecraft:obsidian)
B(-3,84,4,minecraft:obsidian)
B(-3,85,4,minecraft:obsidian)
B(-3,86,4,minecraft:obsidian)
B(-3,87,4,minecraft:obsidian)
B(-3,88,4,minecraft:obsidian)
B(-3,89,4,minecraft:obsidian)
B(-3,90,4,minecraft:obsidian)
B(-3,91,4,minecraft:magma_block)
B(-3,92,4,minecraft:magma_block)
B(-3,27,5,minecraft:diorite)
B(-3,28,5,minecraft:diorite)
B(-3,29,5,minecraft:obsidian)
B(-3,30,5,minecraft:diorite)
B(-3,31,5,minecraft:diorite)
B(-3,32,5,minecraft:diorite)
B(-3,33,5,minecraft:diorite)
B(-3,34,5,minecraft:andesite)
B(-3,35,5,minecraft:andesite)
B(-3,75,5,minecraft:obsidian)
B(-3,76,5,minecraft:obsidian)
B(-3,77,5,minecraft:obsidian)
B(-3,78,5,minecraft:obsidian)
B(-3,79,5,minecraft:obsidian)
B(-3,80,5,minecraft:obsidian)
B(-3,81,5,minecraft:obsidian)
B(-3,82,5,minecraft:obsidian)
B(-3,83,5,minecraft:obsidian)
B(-3,84,5,minecraft:obsidian)
B(-3,85,5,minecraft:obsidian)
B(-3,86,5,minecraft:obsidian)
B(-3,87,5,minecraft:obsidian)
B(-3,88,5,minecraft:obsidian)
B(-3,89,5,minecraft:obsidian)
B(-3,90,5,minecraft:obsidian)
B(-3,91,5,minecraft:magma_block)
B(-3,92,5,minecraft:magma_block)
B(-3,27,6,minecraft:diorite)
B(-3,28,6,minecraft:diorite)
B(-3,29,6,minecraft:diorite)
B(-3,30,6,minecraft:diorite)
B(-3,31,6,minecraft:diorite)
B(-3,32,6,minecraft:obsidian)
B(-3,33,6,minecraft:andesite)
B(-3,34,6,minecraft:andesite)
B(-3,35,6,minecraft:andesite)
B(-3,74,6,minecraft:obsidian)
B(-3,75,6,minecraft:obsidian)
B(-3,76,6,minecraft:obsidian)
B(-3,77,6,minecraft:obsidian)
B(-3,78,6,minecraft:obsidian)
B(-3,79,6,minecraft:obsidian)
B(-3,80,6,minecraft:obsidian)
B(-3,81,6,minecraft:obsidian)
B(-3,82,6,minecraft:obsidian)
B(-3,83,6,minecraft:obsidian)
B(-3,84,6,minecraft:obsidian)
B(-3,85,6,minecraft:obsidian)
B(-3,86,6,minecraft:obsidian)
B(-3,87,6,minecraft:obsidian)
B(-3,88,6,minecraft:obsidian)
B(-3,89,6,minecraft:obsidian)
B(-3,90,6,minecraft:obsidian)
B(-3,91,6,minecraft:obsidian)
B(-3,28,7,minecraft:diorite)
B(-3,29,7,minecraft:diorite)
B(-3,30,7,minecraft:diorite)
B(-3,31,7,minecraft:diorite)
B(-3,32,7,minecraft:diorite)
B(-3,33,7,minecraft:andesite)
B(-3,34,7,minecraft:andesite)
B(-3,35,7,minecraft:andesite)
B(-3,36,7,minecraft:andesite)
B(-3,37,7,minecraft:andesite)
B(-3,74,7,minecraft:obsidian)
B(-3,75,7,minecraft:obsidian)
B(-3,76,7,minecraft:obsidian)
B(-3,77,7,minecraft:obsidian)
B(-3,78,7,minecraft:obsidian)
B(-3,79,7,minecraft:obsidian)
B(-3,80,7,minecraft:obsidian)
B(-3,81,7,minecraft:obsidian)
B(-3,82,7,minecraft:obsidian)
B(-3,83,7,minecraft:obsidian)
B(-3,84,7,minecraft:obsidian)
B(-3,85,7,minecraft:obsidian)
B(-3,86,7,minecraft:obsidian)
B(-3,87,7,minecraft:obsidian)
B(-3,88,7,minecraft:obsidian)
B(-3,89,7,minecraft:obsidian)
B(-3,90,7,minecraft:obsidian)
B(-3,91,7,minecraft:obsidian)
B(-3,29,8,minecraft:diorite)
B(-3,30,8,minecraft:diorite)
B(-3,31,8,minecraft:diorite)
B(-3,32,8,minecraft:diorite)
B(-3,33,8,minecraft:obsidian)
B(-3,34,8,minecraft:andesite)
B(-3,35,8,minecraft:andesite)
B(-3,36,8,minecraft:andesite)
B(-3,37,8,minecraft:obsidian)
B(-3,38,8,minecraft:obsidian)
B(-3,73,8,minecraft:obsidian)
B(-3,74,8,minecraft:obsidian)
B(-3,75,8,minecraft:obsidian)
B(-3,76,8,minecraft:obsidian)
B(-3,77,8,minecraft:obsidian)
B(-3,78,8,minecraft:obsidian)
B(-3,79,8,minecraft:obsidian)
B(-3,80,8,minecraft:obsidian)
B(-3,81,8,minecraft:obsidian)
B(-3,82,8,minecraft:obsidian)
B(-3,83,8,minecraft:obsidian)
B(-3,84,8,minecraft:obsidian)
B(-3,85,8,minecraft:obsidian)
B(-3,86,8,minecraft:obsidian)
B(-3,87,8,minecraft:obsidian)
B(-3,88,8,minecraft:obsidian)
B(-3,89,8,minecraft:obsidian)
B(-3,90,8,minecraft:obsidian)
B(-3,91,8,minecraft:obsidian)
B(-2,22,-7,minecraft:diorite)
B(-2,23,-7,minecraft:diorite)
B(-2,24,-7,minecraft:diorite)
B(-2,25,-7,minecraft:diorite)
B(-2,26,-7,minecraft:diorite)
B(-2,27,-7,minecraft:diorite)
B(-2,28,-7,minecraft:obsidian)
B(-2,29,-7,minecraft:obsidian)
B(-2,30,-7,minecraft:obsidian)
B(-2,31,-7,minecraft:obsidian)
B(-2,32,-7,minecraft:obsidian)
B(-2,33,-7,minecraft:obsidian)
B(-2,34,-7,minecraft:obsidian)
B(-2,35,-7,minecraft:obsidian)
B(-2,36,-7,minecraft:andesite)
B(-2,37,-7,minecraft:andesite)
B(-2,38,-7,minecraft:andesite)
B(-2,39,-7,minecraft:andesite)
B(-2,79,-7,minecraft:obsidian)
B(-2,80,-7,minecraft:obsidian)
B(-2,81,-7,minecraft:obsidian)
B(-2,82,-7,minecraft:obsidian)
B(-2,83,-7,minecraft:obsidian)
B(-2,84,-7,minecraft:obsidian)
B(-2,85,-7,minecraft:obsidian)
B(-2,86,-7,minecraft:obsidian)
B(-2,87,-7,minecraft:obsidian)
B(-2,88,-7,minecraft:obsidian)
B(-2,89,-7,minecraft:obsidian)
B(-2,90,-7,minecraft:obsidian)
B(-2,91,-7,minecraft:obsidian)
B(-2,92,-7,minecraft:obsidian)
B(-2,93,-7,minecraft:obsidian)
B(-2,94,-7,minecraft:obsidian)
B(-2,95,-7,minecraft:diorite)
B(-2,96,-7,minecraft:diorite)
B(-2,97,-7,minecraft:obsidian)
B(-2,98,-7,minecraft:obsidian)
B(-2,99,-7,minecraft:obsidian)
B(-2,100,-7,minecraft:diorite)
B(-2,101,-7,minecraft:diorite)
B(-2,22,-6,minecraft:diorite)
B(-2,23,-6,minecraft:diorite)
B(-2,24,-6,minecraft:diorite)
B(-2,25,-6,minecraft:diorite)
B(-2,26,-6,minecraft:diorite)
B(-2,27,-6,minecraft:diorite)
B(-2,28,-6,minecraft:obsidian)
B(-2,29,-6,minecraft:obsidian)
B(-2,30,-6,minecraft:obsidian)
B(-2,31,-6,minecraft:obsidian)
B(-2,32,-6,minecraft:obsidian)
B(-2,33,-6,minecraft:obsidian)
B(-2,34,-6,minecraft:obsidian)
B(-2,35,-6,minecraft:obsidian)
B(-2,36,-6,minecraft:andesite)
B(-2,37,-6,minecraft:andesite)
B(-2,38,-6,minecraft:andesite)
B(-2,79,-6,minecraft:obsidian)
B(-2,80,-6,minecraft:obsidian)
B(-2,81,-6,minecraft:obsidian)
B(-2,82,-6,minecraft:obsidian)
B(-2,83,-6,minecraft:obsidian)
B(-2,84,-6,minecraft:obsidian)
B(-2,85,-6,minecraft:obsidian)
B(-2,86,-6,minecraft:obsidian)
B(-2,87,-6,minecraft:obsidian)
B(-2,88,-6,minecraft:obsidian)
B(-2,89,-6,minecraft:obsidian)
B(-2,90,-6,minecraft:obsidian)
B(-2,91,-6,minecraft:obsidian)
B(-2,92,-6,minecraft:obsidian)
B(-2,93,-6,minecraft:obsidian)
B(-2,94,-6,minecraft:obsidian)
B(-2,95,-6,minecraft:diorite)
B(-2,96,-6,minecraft:obsidian)
B(-2,97,-6,minecraft:obsidian)
B(-2,98,-6,minecraft:obsidian)
B(-2,99,-6,minecraft:obsidian)
B(-2,100,-6,minecraft:obsidian)
B(-2,23,-5,minecraft:diorite)
B(-2,24,-5,minecraft:diorite)
B(-2,25,-5,minecraft:diorite)
B(-2,26,-5,minecraft:diorite)
B(-2,27,-5,minecraft:diorite)
B(-2,28,-5,minecraft:diorite)
B(-2,29,-5,minecraft:obsidian)
B(-2,30,-5,minecraft:obsidian)
B(-2,31,-5,minecraft:obsidian)
B(-2,32,-5,minecraft:obsidian)
B(-2,33,-5,minecraft:obsidian)
B(-2,34,-5,minecraft:obsidian)
B(-2,35,-5,minecraft:andesite)
B(-2,36,-5,minecraft:andesite)
B(-2,37,-5,minecraft:grass_block)
B(-2,79,-5,minecraft:obsidian)
B(-2,80,-5,minecraft:obsidian)
B(-2,81,-5,minecraft:obsidian)
B(-2,82,-5,minecraft:obsidian)
B(-2,83,-5,minecraft:obsidian)
B(-2,84,-5,minecraft:obsidian)
B(-2,85,-5,minecraft:obsidian)
B(-2,86,-5,minecraft:obsidian)
B(-2,87,-5,minecraft:obsidian)
B(-2,88,-5,minecraft:obsidian)
B(-2,89,-5,minecraft:obsidian)
B(-2,90,-5,minecraft:obsidian)
B(-2,91,-5,minecraft:obsidian)
B(-2,92,-5,minecraft:obsidian)
B(-2,93,-5,minecraft:diorite)
B(-2,94,-5,minecraft:diorite)
B(-2,95,-5,minecraft:diorite)
B(-2,96,-5,minecraft:obsidian)
B(-2,97,-5,minecraft:obsidian)
B(-2,98,-5,minecraft:obsidian)
B(-2,99,-5,minecraft:obsidian)
B(-2,100,-5,minecraft:obsidian)
B(-2,101,-5,minecraft:diorite)
B(-2,24,-4,minecraft:diorite)
B(-2,25,-4,minecraft:diorite)
B(-2,26,-4,minecraft:diorite)
B(-2,27,-4,minecraft:diorite)
B(-2,28,-4,minecraft:diorite)
B(-2,29,-4,minecraft:diorite)
B(-2,30,-4,minecraft:obsidian)
B(-2,31,-4,minecraft:obsidian)
B(-2,32,-4,minecraft:obsidian)
B(-2,33,-4,minecraft:diorite)
B(-2,34,-4,minecraft:diorite)
B(-2,35,-4,minecraft:diorite)
B(-2,36,-4,minecraft:andesite)
B(-2,37,-4,minecraft:grass_block)
B(-2,79,-4,minecraft:obsidian)
B(-2,80,-4,minecraft:obsidian)
B(-2,81,-4,minecraft:obsidian)
B(-2,82,-4,minecraft:obsidian)
B(-2,83,-4,minecraft:obsidian)
B(-2,84,-4,minecraft:obsidian)
B(-2,85,-4,minecraft:obsidian)
B(-2,86,-4,minecraft:obsidian)
B(-2,87,-4,minecraft:obsidian)
B(-2,88,-4,minecraft:obsidian)
B(-2,89,-4,minecraft:obsidian)
B(-2,90,-4,minecraft:obsidian)
B(-2,91,-4,minecraft:diorite)
B(-2,92,-4,minecraft:diorite)
B(-2,93,-4,minecraft:diorite)
B(-2,94,-4,minecraft:diorite)
B(-2,95,-4,minecraft:diorite)
B(-2,96,-4,minecraft:obsidian)
B(-2,97,-4,minecraft:obsidian)
B(-2,98,-4,minecraft:obsidian)
B(-2,99,-4,minecraft:obsidian)
B(-2,100,-4,minecraft:obsidian)
B(-2,101,-4,minecraft:diorite)
B(-2,24,-3,minecraft:diorite)
B(-2,25,-3,minecraft:diorite)
B(-2,26,-3,minecraft:diorite)
B(-2,27,-3,minecraft:diorite)
B(-2,28,-3,minecraft:diorite)
B(-2,29,-3,minecraft:diorite)
B(-2,30,-3,minecraft:obsidian)
B(-2,31,-3,minecraft:diorite)
B(-2,32,-3,minecraft:diorite)
B(-2,33,-3,minecraft:diorite)
B(-2,79,-3,minecraft:obsidian)
B(-2,80,-3,minecraft:obsidian)
B(-2,81,-3,minecraft:obsidian)
B(-2,82,-3,minecraft:obsidian)
B(-2,83,-3,minecraft:obsidian)
B(-2,84,-3,minecraft:obsidian)
B(-2,85,-3,minecraft:obsidian)
B(-2,86,-3,minecraft:obsidian)
B(-2,87,-3,minecraft:obsidian)
B(-2,88,-3,minecraft:obsidian)
B(-2,89,-3,minecraft:obsidian)
B(-2,90,-3,minecraft:diorite)
B(-2,91,-3,minecraft:obsidian)
B(-2,92,-3,minecraft:obsidian)
B(-2,93,-3,minecraft:obsidian)
B(-2,94,-3,minecraft:obsidian)
B(-2,95,-3,minecraft:obsidian)
B(-2,96,-3,minecraft:obsidian)
B(-2,97,-3,minecraft:obsidian)
B(-2,98,-3,minecraft:obsidian)
B(-2,99,-3,minecraft:obsidian)
B(-2,100,-3,minecraft:diorite)
B(-2,24,-2,minecraft:diorite)
B(-2,25,-2,minecraft:diorite)
B(-2,26,-2,minecraft:diorite)
B(-2,27,-2,minecraft:diorite)
B(-2,28,-2,minecraft:diorite)
B(-2,29,-2,minecraft:diorite)
B(-2,30,-2,minecraft:diorite)
B(-2,31,-2,minecraft:diorite)
B(-2,32,-2,minecraft:diorite)
B(-2,33,-2,minecraft:water)
B(-2,78,-2,minecraft:obsidian)
B(-2,79,-2,minecraft:obsidian)
B(-2,80,-2,minecraft:obsidian)
B(-2,81,-2,minecraft:obsidian)
B(-2,82,-2,minecraft:obsidian)
B(-2,83,-2,minecraft:obsidian)
B(-2,84,-2,minecraft:obsidian)
B(-2,85,-2,minecraft:obsidian)
B(-2,86,-2,minecraft:obsidian)
B(-2,87,-2,minecraft:obsidian)
B(-2,88,-2,minecraft:obsidian)
B(-2,89,-2,minecraft:obsidian)
B(-2,90,-2,minecraft:obsidian)
B(-2,91,-2,minecraft:obsidian)
B(-2,92,-2,minecraft:obsidian)
B(-2,93,-2,minecraft:obsidian)
B(-2,94,-2,minecraft:obsidian)
B(-2,95,-2,minecraft:obsidian)
B(-2,96,-2,minecraft:obsidian)
B(-2,97,-2,minecraft:obsidian)
B(-2,98,-2,minecraft:diorite)
B(-2,99,-2,minecraft:diorite)
B(-2,25,-1,minecraft:diorite)
B(-2,26,-1,minecraft:diorite)
B(-2,27,-1,minecraft:diorite)
B(-2,28,-1,minecraft:diorite)
B(-2,29,-1,minecraft:diorite)
B(-2,30,-1,minecraft:diorite)
B(-2,31,-1,minecraft:diorite)
B(-2,32,-1,minecraft:water)
B(-2,33,-1,minecraft:water)
B(-2,78,-1,minecraft:obsidian)
B(-2,79,-1,minecraft:obsidian)
B(-2,80,-1,minecraft:obsidian)
B(-2,81,-1,minecraft:obsidian)
B(-2,82,-1,minecraft:obsidian)
B(-2,83,-1,minecraft:obsidian)
B(-2,84,-1,minecraft:obsidian)
B(-2,85,-1,minecraft:obsidian)
B(-2,86,-1,minecraft:obsidian)
B(-2,87,-1,minecraft:obsidian)
B(-2,88,-1,minecraft:obsidian)
B(-2,89,-1,minecraft:obsidian)
B(-2,90,-1,minecraft:obsidian)
B(-2,91,-1,minecraft:obsidian)
B(-2,92,-1,minecraft:obsidian)
B(-2,93,-1,minecraft:obsidian)
B(-2,94,-1,minecraft:obsidian)
B(-2,95,-1,minecraft:obsidian)
B(-2,96,-1,minecraft:obsidian)
B(-2,97,-1,minecraft:obsidian)
B(-2,98,-1,minecraft:obsidian)
B(-2,99,-1,minecraft:diorite)
B(-2,26,0,minecraft:diorite)
B(-2,27,0,minecraft:diorite)
B(-2,28,0,minecraft:diorite)
B(-2,29,0,minecraft:diorite)
B(-2,30,0,minecraft:diorite)
B(-2,31,0,minecraft:diorite)
B(-2,32,0,minecraft:water)
B(-2,33,0,minecraft:water)
B(-2,77,0,minecraft:obsidian)
B(-2,78,0,minecraft:obsidian)
B(-2,79,0,minecraft:obsidian)
B(-2,80,0,minecraft:obsidian)
B(-2,81,0,minecraft:obsidian)
B(-2,82,0,minecraft:obsidian)
B(-2,83,0,minecraft:obsidian)
B(-2,84,0,minecraft:obsidian)
B(-2,85,0,minecraft:obsidian)
B(-2,86,0,minecraft:obsidian)
B(-2,87,0,minecraft:obsidian)
B(-2,88,0,minecraft:obsidian)
B(-2,89,0,minecraft:obsidian)
B(-2,90,0,minecraft:obsidian)
B(-2,91,0,minecraft:obsidian)
B(-2,92,0,minecraft:magma_block)
B(-2,93,0,minecraft:magma_block)
B(-2,26,1,minecraft:diorite)
B(-2,27,1,minecraft:diorite)
B(-2,28,1,minecraft:diorite)
B(-2,29,1,minecraft:diorite)
B(-2,30,1,minecraft:andesite)
B(-2,31,1,minecraft:diorite)
B(-2,32,1,minecraft:water)
B(-2,33,1,minecraft:water)
B(-2,77,1,minecraft:obsidian)
B(-2,78,1,minecraft:obsidian)
B(-2,79,1,minecraft:obsidian)
B(-2,80,1,minecraft:obsidian)
B(-2,81,1,minecraft:obsidian)
B(-2,82,1,minecraft:obsidian)
B(-2,83,1,minecraft:obsidian)
B(-2,84,1,minecraft:obsidian)
B(-2,85,1,minecraft:obsidian)
B(-2,86,1,minecraft:obsidian)
B(-2,87,1,minecraft:obsidian)
B(-2,88,1,minecraft:obsidian)
B(-2,89,1,minecraft:obsidian)
B(-2,90,1,minecraft:obsidian)
B(-2,91,1,minecraft:magma_block)
B(-2,92,1,minecraft:magma_block)
B(-2,93,1,minecraft:magma_block)
B(-2,26,2,minecraft:diorite)
B(-2,27,2,minecraft:diorite)
B(-2,28,2,minecraft:diorite)
B(-2,29,2,minecraft:diorite)
B(-2,30,2,minecraft:andesite)
B(-2,31,2,minecraft:diorite)
B(-2,32,2,minecraft:diorite)
B(-2,33,2,minecraft:water)
B(-2,77,2,minecraft:obsidian)
B(-2,78,2,minecraft:obsidian)
B(-2,79,2,minecraft:obsidian)
B(-2,80,2,minecraft:obsidian)
B(-2,81,2,minecraft:obsidian)
B(-2,82,2,minecraft:obsidian)
B(-2,83,2,minecraft:obsidian)
B(-2,84,2,minecraft:obsidian)
B(-2,85,2,minecraft:obsidian)
B(-2,86,2,minecraft:obsidian)
B(-2,87,2,minecraft:obsidian)
B(-2,88,2,minecraft:obsidian)
B(-2,89,2,minecraft:obsidian)
B(-2,90,2,minecraft:obsidian)
B(-2,91,2,minecraft:magma_block)
B(-2,92,2,minecraft:magma_block)
B(-2,93,2,minecraft:magma_block)
B(-2,27,3,minecraft:diorite)
B(-2,28,3,minecraft:diorite)
B(-2,29,3,minecraft:diorite)
B(-2,30,3,minecraft:obsidian)
B(-2,31,3,minecraft:diorite)
B(-2,32,3,minecraft:diorite)
B(-2,33,3,minecraft:grass_block)
B(-2,76,3,minecraft:obsidian)
B(-2,77,3,minecraft:obsidian)
B(-2,78,3,minecraft:obsidian)
B(-2,79,3,minecraft:obsidian)
B(-2,80,3,minecraft:obsidian)
B(-2,81,3,minecraft:obsidian)
B(-2,82,3,minecraft:obsidian)
B(-2,83,3,minecraft:obsidian)
B(-2,84,3,minecraft:obsidian)
B(-2,85,3,minecraft:obsidian)
B(-2,86,3,minecraft:obsidian)
B(-2,87,3,minecraft:obsidian)
B(-2,88,3,minecraft:obsidian)
B(-2,89,3,minecraft:obsidian)
B(-2,90,3,minecraft:magma_block)
B(-2,91,3,minecraft:magma_block)
B(-2,92,3,minecraft:magma_block)
B(-2,27,4,minecraft:diorite)
B(-2,28,4,minecraft:diorite)
B(-2,29,4,minecraft:diorite)
B(-2,30,4,minecraft:obsidian)
B(-2,31,4,minecraft:diorite)
B(-2,32,4,minecraft:diorite)
B(-2,33,4,minecraft:diorite)
B(-2,34,4,minecraft:diorite)
B(-2,35,4,minecraft:diorite)
B(-2,76,4,minecraft:obsidian)
B(-2,77,4,minecraft:obsidian)
B(-2,78,4,minecraft:obsidian)
B(-2,79,4,minecraft:obsidian)
B(-2,80,4,minecraft:obsidian)
B(-2,81,4,minecraft:obsidian)
B(-2,82,4,minecraft:obsidian)
B(-2,83,4,minecraft:obsidian)
B(-2,84,4,minecraft:obsidian)
B(-2,85,4,minecraft:obsidian)
B(-2,86,4,minecraft:obsidian)
B(-2,87,4,minecraft:obsidian)
B(-2,88,4,minecraft:obsidian)
B(-2,89,4,minecraft:obsidian)
B(-2,90,4,minecraft:magma_block)
B(-2,91,4,minecraft:magma_block)
B(-2,92,4,minecraft:magma_block)
B(-2,27,5,minecraft:diorite)
B(-2,28,5,minecraft:diorite)
B(-2,29,5,minecraft:diorite)
B(-2,30,5,minecraft:diorite)
B(-2,31,5,minecraft:diorite)
B(-2,32,5,minecraft:diorite)
B(-2,33,5,minecraft:andesite)
B(-2,34,5,minecraft:andesite)
B(-2,35,5,minecraft:andesite)
B(-2,36,5,minecraft:andesite)
