
#######################################################################
# +-----------------------------------------------------------------+ #
# |                            BO4 object                           | #
# +-----------------------------------------------------------------+ #
#######################################################################

Author: NLBlackEagle

Description: No description given

SettingsMode: WriteWithoutComments


#######################################################################
# +-----------------------------------------------------------------+ #
# |                          Main settings                          | #
# +-----------------------------------------------------------------+ #
#######################################################################

FixedRotation: 

Frequency: 0

SpawnHeight: highestBlock

UseCenterForHighestBlock: true

##############################
# Height Limits for the BO4. #
##############################

MinHeight: 0

MaxHeight: 255

InheritBO3: 

InheritBO3Rotation: NORTH

OverrideChildSettings: true

OverrideParentHeight: false

CanOverride: false

BranchFrequency: 0

BranchFrequencyGroup: 

MustBeBelowOther: false

MustBeInside: 

CannotBeInside: 

ReplacesBO3: 

MustBeInsideWorldBorders: false

CanSpawnOnWater: true

SpawnOnWaterOnly: false

SpawnUnderWater: false

SpawnAtWaterLevel: false

HeightOffset: 0

RemoveAir: true

ReplaceAbove: 

ReplaceBelow: 

ReplaceWithBiomeBlocks: true

ReplaceWithSurfaceBlock: GRASS

ReplaceWithGroundBlock: DIRT

ReplaceWithStoneBlock: STONE

SmoothRadius: 0

SmoothHeightOffset: 0

SmoothStartTop: false

SmoothStartWood: false

SmoothingSurfaceBlock: 

SmoothingGroundBlock: 

BO3Group: 

IsSpawnPoint: false

DoReplaceBlocks: true


#######################################################################
# +-----------------------------------------------------------------+ #
# |                              Blocks                             | #
# +-----------------------------------------------------------------+ #
#######################################################################

B(-8,16,-7,minecraft:diorite)
B(-8,17,-7,minecraft:diorite)
B(-8,18,-7,minecraft:diorite)
B(-8,19,-7,minecraft:diorite)
B(-8,20,-7,minecraft:diorite)
B(-8,21,-7,minecraft:diorite)
B(-8,22,-7,minecraft:obsidian)
B(-8,23,-7,minecraft:obsidian)
B(-8,24,-7,minecraft:obsidian)
B(-8,25,-7,minecraft:obsidian)
B(-8,26,-7,minecraft:obsidian)
B(-8,27,-7,minecraft:obsidian)
B(-8,28,-7,minecraft:diorite)
B(-8,29,-7,minecraft:diorite)
B(-8,30,-7,minecraft:diorite)
B(-8,31,-7,minecraft:diorite)
B(-8,32,-7,minecraft:diorite)
B(-8,33,-7,minecraft:diorite)
B(-8,44,-7,minecraft:obsidian)
B(-8,45,-7,minecraft:obsidian)
B(-8,46,-7,minecraft:obsidian)
B(-8,47,-7,minecraft:obsidian)
B(-8,48,-7,minecraft:obsidian)
B(-8,49,-7,minecraft:obsidian)
B(-8,50,-7,minecraft:obsidian)
B(-8,51,-7,minecraft:obsidian)
B(-8,52,-7,minecraft:obsidian)
B(-8,53,-7,minecraft:obsidian)
B(-8,63,-7,minecraft:obsidian)
B(-8,64,-7,minecraft:obsidian)
B(-8,65,-7,minecraft:obsidian)
B(-8,66,-7,minecraft:obsidian)
B(-8,67,-7,minecraft:obsidian)
B(-8,68,-7,minecraft:obsidian)
B(-8,69,-7,minecraft:obsidian)
B(-8,70,-7,minecraft:obsidian)
B(-8,71,-7,minecraft:obsidian)
B(-8,72,-7,minecraft:obsidian)
B(-8,73,-7,minecraft:obsidian)
B(-8,74,-7,minecraft:obsidian)
B(-8,75,-7,minecraft:obsidian)
B(-8,76,-7,minecraft:obsidian)
B(-8,77,-7,minecraft:obsidian)
B(-8,78,-7,minecraft:obsidian)
B(-8,79,-7,minecraft:obsidian)
B(-8,80,-7,minecraft:obsidian)
B(-8,81,-7,minecraft:obsidian)
B(-8,82,-7,minecraft:obsidian)
B(-8,83,-7,minecraft:obsidian)
B(-8,84,-7,minecraft:obsidian)
B(-8,85,-7,minecraft:obsidian)
B(-8,86,-7,minecraft:obsidian)
B(-8,87,-7,minecraft:obsidian)
B(-8,88,-7,minecraft:obsidian)
B(-8,89,-7,minecraft:obsidian)
B(-8,90,-7,minecraft:obsidian)
B(-8,91,-7,minecraft:obsidian)
B(-8,92,-7,minecraft:obsidian)
B(-8,93,-7,minecraft:obsidian)
B(-8,94,-7,minecraft:obsidian)
B(-8,95,-7,minecraft:obsidian)
B(-8,96,-7,minecraft:diorite)
B(-8,97,-7,minecraft:diorite)
B(-8,16,-6,minecraft:diorite)
B(-8,17,-6,minecraft:diorite)
B(-8,18,-6,minecraft:diorite)
B(-8,19,-6,minecraft:diorite)
B(-8,20,-6,minecraft:diorite)
B(-8,21,-6,minecraft:obsidian)
B(-8,22,-6,minecraft:obsidian)
B(-8,23,-6,minecraft:obsidian)
B(-8,24,-6,minecraft:obsidian)
B(-8,25,-6,minecraft:obsidian)
B(-8,26,-6,minecraft:obsidian)
B(-8,27,-6,minecraft:diorite)
B(-8,28,-6,minecraft:diorite)
B(-8,29,-6,minecraft:diorite)
B(-8,30,-6,minecraft:diorite)
B(-8,31,-6,minecraft:diorite)
B(-8,32,-6,minecraft:diorite)
B(-8,47,-6,minecraft:obsidian)
B(-8,48,-6,minecraft:obsidian)
B(-8,49,-6,minecraft:obsidian)
B(-8,50,-6,minecraft:obsidian)
B(-8,51,-6,minecraft:obsidian)
B(-8,52,-6,minecraft:obsidian)
B(-8,53,-6,minecraft:obsidian)
B(-8,64,-6,minecraft:obsidian)
B(-8,65,-6,minecraft:obsidian)
B(-8,66,-6,minecraft:obsidian)
B(-8,67,-6,minecraft:obsidian)
B(-8,68,-6,minecraft:obsidian)
B(-8,69,-6,minecraft:obsidian)
B(-8,70,-6,minecraft:obsidian)
B(-8,71,-6,minecraft:obsidian)
B(-8,72,-6,minecraft:obsidian)
B(-8,73,-6,minecraft:obsidian)
B(-8,74,-6,minecraft:obsidian)
B(-8,75,-6,minecraft:obsidian)
B(-8,76,-6,minecraft:obsidian)
B(-8,77,-6,minecraft:obsidian)
B(-8,78,-6,minecraft:obsidian)
B(-8,79,-6,minecraft:obsidian)
B(-8,80,-6,minecraft:obsidian)
B(-8,81,-6,minecraft:obsidian)
B(-8,82,-6,minecraft:obsidian)
B(-8,83,-6,minecraft:obsidian)
B(-8,84,-6,minecraft:obsidian)
B(-8,85,-6,minecraft:obsidian)
B(-8,86,-6,minecraft:obsidian)
B(-8,87,-6,minecraft:obsidian)
B(-8,88,-6,minecraft:obsidian)
B(-8,89,-6,minecraft:obsidian)
B(-8,90,-6,minecraft:obsidian)
B(-8,91,-6,minecraft:obsidian)
B(-8,92,-6,minecraft:obsidian)
B(-8,93,-6,minecraft:obsidian)
B(-8,94,-6,minecraft:obsidian)
B(-8,95,-6,minecraft:obsidian)
B(-8,96,-6,minecraft:diorite)
B(-8,97,-6,minecraft:diorite)
B(-8,15,-5,minecraft:diorite)
B(-8,16,-5,minecraft:diorite)
B(-8,17,-5,minecraft:diorite)
B(-8,18,-5,minecraft:diorite)
B(-8,19,-5,minecraft:diorite)
B(-8,20,-5,minecraft:diorite)
B(-8,21,-5,minecraft:obsidian)
B(-8,22,-5,minecraft:obsidian)
B(-8,23,-5,minecraft:obsidian)
B(-8,24,-5,minecraft:obsidian)
B(-8,25,-5,minecraft:obsidian)
B(-8,26,-5,minecraft:obsidian)
B(-8,27,-5,minecraft:diorite)
B(-8,28,-5,minecraft:diorite)
B(-8,29,-5,minecraft:diorite)
B(-8,30,-5,minecraft:diorite)
B(-8,70,-5,minecraft:obsidian)
B(-8,71,-5,minecraft:obsidian)
B(-8,72,-5,minecraft:obsidian)
B(-8,73,-5,minecraft:obsidian)
B(-8,74,-5,minecraft:obsidian)
B(-8,75,-5,minecraft:obsidian)
B(-8,76,-5,minecraft:obsidian)
B(-8,77,-5,minecraft:obsidian)
B(-8,78,-5,minecraft:obsidian)
B(-8,79,-5,minecraft:obsidian)
B(-8,80,-5,minecraft:obsidian)
B(-8,81,-5,minecraft:obsidian)
B(-8,82,-5,minecraft:obsidian)
B(-8,83,-5,minecraft:obsidian)
B(-8,84,-5,minecraft:obsidian)
B(-8,85,-5,minecraft:obsidian)
B(-8,86,-5,minecraft:obsidian)
B(-8,87,-5,minecraft:obsidian)
B(-8,88,-5,minecraft:obsidian)
B(-8,89,-5,minecraft:obsidian)
B(-8,90,-5,minecraft:obsidian)
B(-8,91,-5,minecraft:obsidian)
B(-8,92,-5,minecraft:obsidian)
B(-8,93,-5,minecraft:obsidian)
B(-8,94,-5,minecraft:obsidian)
B(-8,95,-5,minecraft:diorite)
B(-8,96,-5,minecraft:andesite)
B(-8,15,-4,minecraft:diorite)
B(-8,16,-4,minecraft:diorite)
B(-8,17,-4,minecraft:diorite)
B(-8,18,-4,minecraft:diorite)
B(-8,19,-4,minecraft:diorite)
B(-8,20,-4,minecraft:diorite)
B(-8,21,-4,minecraft:obsidian)
B(-8,22,-4,minecraft:obsidian)
B(-8,23,-4,minecraft:obsidian)
B(-8,24,-4,minecraft:obsidian)
B(-8,25,-4,minecraft:obsidian)
B(-8,26,-4,minecraft:diorite)
B(-8,27,-4,minecraft:diorite)
B(-8,28,-4,minecraft:diorite)
B(-8,29,-4,minecraft:diorite)
B(-8,72,-4,minecraft:obsidian)
B(-8,73,-4,minecraft:obsidian)
B(-8,74,-4,minecraft:obsidian)
B(-8,75,-4,minecraft:obsidian)
B(-8,76,-4,minecraft:obsidian)
B(-8,77,-4,minecraft:obsidian)
B(-8,78,-4,minecraft:obsidian)
B(-8,79,-4,minecraft:obsidian)
B(-8,80,-4,minecraft:obsidian)
B(-8,81,-4,minecraft:obsidian)
B(-8,82,-4,minecraft:obsidian)
B(-8,83,-4,minecraft:obsidian)
B(-8,84,-4,minecraft:obsidian)
B(-8,85,-4,minecraft:obsidian)
B(-8,86,-4,minecraft:obsidian)
B(-8,87,-4,minecraft:obsidian)
B(-8,88,-4,minecraft:obsidian)
B(-8,89,-4,minecraft:obsidian)
B(-8,90,-4,minecraft:obsidian)
B(-8,91,-4,minecraft:obsidian)
B(-8,92,-4,minecraft:obsidian)
B(-8,93,-4,minecraft:obsidian)
B(-8,94,-4,minecraft:obsidian)
B(-8,95,-4,minecraft:diorite)
B(-8,96,-4,minecraft:andesite)
B(-8,15,-3,minecraft:diorite)
B(-8,16,-3,minecraft:diorite)
B(-8,17,-3,minecraft:diorite)
B(-8,18,-3,minecraft:diorite)
B(-8,19,-3,minecraft:diorite)
B(-8,20,-3,minecraft:obsidian)
B(-8,21,-3,minecraft:obsidian)
B(-8,22,-3,minecraft:obsidian)
B(-8,23,-3,minecraft:obsidian)
B(-8,24,-3,minecraft:obsidian)
B(-8,25,-3,minecraft:obsidian)
B(-8,26,-3,minecraft:diorite)
B(-8,27,-3,minecraft:diorite)
B(-8,28,-3,minecraft:diorite)
B(-8,73,-3,minecraft:obsidian)
B(-8,74,-3,minecraft:obsidian)
B(-8,75,-3,minecraft:obsidian)
B(-8,76,-3,minecraft:obsidian)
B(-8,77,-3,minecraft:obsidian)
B(-8,78,-3,minecraft:obsidian)
B(-8,79,-3,minecraft:obsidian)
B(-8,80,-3,minecraft:obsidian)
B(-8,81,-3,minecraft:obsidian)
B(-8,82,-3,minecraft:obsidian)
B(-8,83,-3,minecraft:obsidian)
B(-8,84,-3,minecraft:obsidian)
B(-8,85,-3,minecraft:obsidian)
B(-8,86,-3,minecraft:obsidian)
B(-8,87,-3,minecraft:obsidian)
B(-8,88,-3,minecraft:obsidian)
B(-8,89,-3,minecraft:obsidian)
B(-8,90,-3,minecraft:obsidian)
B(-8,91,-3,minecraft:obsidian)
B(-8,92,-3,minecraft:obsidian)
B(-8,93,-3,minecraft:obsidian)
B(-8,94,-3,minecraft:obsidian)
B(-8,95,-3,minecraft:obsidian)
B(-8,96,-3,minecraft:diorite)
B(-8,97,-3,minecraft:diorite)
B(-8,15,-2,minecraft:diorite)
B(-8,16,-2,minecraft:diorite)
B(-8,17,-2,minecraft:diorite)
B(-8,18,-2,minecraft:diorite)
B(-8,19,-2,minecraft:diorite)
B(-8,20,-2,minecraft:obsidian)
B(-8,21,-2,minecraft:obsidian)
B(-8,22,-2,minecraft:obsidian)
B(-8,23,-2,minecraft:obsidian)
B(-8,24,-2,minecraft:obsidian)
B(-8,25,-2,minecraft:obsidian)
B(-8,26,-2,minecraft:diorite)
B(-8,27,-2,minecraft:diorite)
B(-8,28,-2,minecraft:diorite)
B(-8,75,-2,minecraft:obsidian)
B(-8,76,-2,minecraft:obsidian)
B(-8,77,-2,minecraft:obsidian)
B(-8,78,-2,minecraft:obsidian)
B(-8,79,-2,minecraft:obsidian)
B(-8,80,-2,minecraft:obsidian)
B(-8,81,-2,minecraft:obsidian)
B(-8,82,-2,minecraft:obsidian)
B(-8,83,-2,minecraft:obsidian)
B(-8,84,-2,minecraft:obsidian)
B(-8,85,-2,minecraft:obsidian)
B(-8,86,-2,minecraft:obsidian)
B(-8,87,-2,minecraft:obsidian)
B(-8,88,-2,minecraft:obsidian)
B(-8,89,-2,minecraft:obsidian)
B(-8,90,-2,minecraft:obsidian)
B(-8,91,-2,minecraft:obsidian)
B(-8,92,-2,minecraft:obsidian)
B(-8,93,-2,minecraft:obsidian)
B(-8,94,-2,minecraft:obsidian)
B(-8,95,-2,minecraft:obsidian)
B(-8,96,-2,minecraft:diorite)
B(-8,97,-2,minecraft:diorite)
B(-8,14,-1,minecraft:diorite)
B(-8,15,-1,minecraft:diorite)
B(-8,16,-1,minecraft:diorite)
B(-8,17,-1,minecraft:diorite)
B(-8,18,-1,minecraft:diorite)
B(-8,19,-1,minecraft:diorite)
B(-8,20,-1,minecraft:obsidian)
B(-8,21,-1,minecraft:obsidian)
B(-8,22,-1,minecraft:obsidian)
B(-8,23,-1,minecraft:obsidian)
B(-8,24,-1,minecraft:obsidian)
B(-8,25,-1,minecraft:obsidian)
B(-8,26,-1,minecraft:diorite)
B(-8,27,-1,minecraft:diorite)
B(-8,28,-1,minecraft:diorite)
B(-8,74,-1,minecraft:obsidian)
B(-8,75,-1,minecraft:obsidian)
B(-8,76,-1,minecraft:obsidian)
B(-8,77,-1,minecraft:obsidian)
B(-8,78,-1,minecraft:obsidian)
B(-8,79,-1,minecraft:obsidian)
B(-8,80,-1,minecraft:obsidian)
B(-8,81,-1,minecraft:obsidian)
B(-8,82,-1,minecraft:obsidian)
B(-8,83,-1,minecraft:obsidian)
B(-8,84,-1,minecraft:obsidian)
B(-8,85,-1,minecraft:obsidian)
B(-8,86,-1,minecraft:obsidian)
B(-8,87,-1,minecraft:obsidian)
B(-8,88,-1,minecraft:obsidian)
B(-8,89,-1,minecraft:obsidian)
B(-8,90,-1,minecraft:obsidian)
B(-8,91,-1,minecraft:obsidian)
B(-8,92,-1,minecraft:obsidian)
B(-8,93,-1,minecraft:obsidian)
B(-8,94,-1,minecraft:diorite)
B(-8,95,-1,minecraft:andesite)
B(-8,13,0,minecraft:diorite)
B(-8,14,0,minecraft:diorite)
B(-8,15,0,minecraft:diorite)
B(-8,16,0,minecraft:diorite)
B(-8,17,0,minecraft:diorite)
B(-8,18,0,minecraft:diorite)
B(-8,19,0,minecraft:diorite)
B(-8,20,0,minecraft:obsidian)
B(-8,21,0,minecraft:obsidian)
B(-8,22,0,minecraft:obsidian)
B(-8,23,0,minecraft:obsidian)
B(-8,24,0,minecraft:obsidian)
B(-8,25,0,minecraft:obsidian)
B(-8,26,0,minecraft:diorite)
B(-8,27,0,minecraft:diorite)
B(-8,28,0,minecraft:diorite)
B(-8,71,0,minecraft:obsidian)
B(-8,72,0,minecraft:obsidian)
B(-8,73,0,minecraft:obsidian)
B(-8,74,0,minecraft:obsidian)
B(-8,75,0,minecraft:obsidian)
B(-8,76,0,minecraft:obsidian)
B(-8,77,0,minecraft:obsidian)
B(-8,78,0,minecraft:obsidian)
B(-8,79,0,minecraft:obsidian)
B(-8,80,0,minecraft:obsidian)
B(-8,81,0,minecraft:obsidian)
B(-8,82,0,minecraft:obsidian)
B(-8,83,0,minecraft:obsidian)
B(-8,84,0,minecraft:obsidian)
B(-8,85,0,minecraft:obsidian)
B(-8,86,0,minecraft:obsidian)
B(-8,87,0,minecraft:obsidian)
B(-8,88,0,minecraft:obsidian)
B(-8,89,0,minecraft:obsidian)
B(-8,90,0,minecraft:obsidian)
B(-8,91,0,minecraft:obsidian)
B(-8,92,0,minecraft:obsidian)
B(-8,93,0,minecraft:obsidian)
B(-8,94,0,minecraft:diorite)
B(-8,95,0,minecraft:andesite)
B(-8,12,1,minecraft:diorite)
B(-8,13,1,minecraft:diorite)
B(-8,14,1,minecraft:diorite)
B(-8,15,1,minecraft:diorite)
B(-8,16,1,minecraft:diorite)
B(-8,17,1,minecraft:diorite)
B(-8,18,1,minecraft:diorite)
B(-8,19,1,minecraft:obsidian)
B(-8,20,1,minecraft:obsidian)
B(-8,21,1,minecraft:obsidian)
B(-8,22,1,minecraft:obsidian)
B(-8,23,1,minecraft:obsidian)
B(-8,24,1,minecraft:obsidian)
B(-8,25,1,minecraft:diorite)
B(-8,26,1,minecraft:diorite)
B(-8,27,1,minecraft:diorite)
B(-8,28,1,minecraft:diorite)
B(-8,70,1,minecraft:obsidian)
B(-8,71,1,minecraft:obsidian)
B(-8,72,1,minecraft:obsidian)
B(-8,73,1,minecraft:obsidian)
B(-8,74,1,minecraft:obsidian)
B(-8,75,1,minecraft:obsidian)
B(-8,76,1,minecraft:obsidian)
B(-8,77,1,minecraft:obsidian)
B(-8,78,1,minecraft:obsidian)
B(-8,79,1,minecraft:obsidian)
B(-8,80,1,minecraft:obsidian)
B(-8,81,1,minecraft:obsidian)
B(-8,82,1,minecraft:obsidian)
B(-8,83,1,minecraft:obsidian)
B(-8,84,1,minecraft:obsidian)
B(-8,85,1,minecraft:obsidian)
B(-8,86,1,minecraft:obsidian)
B(-8,87,1,minecraft:obsidian)
B(-8,88,1,minecraft:obsidian)
B(-8,89,1,minecraft:obsidian)
B(-8,90,1,minecraft:obsidian)
B(-8,91,1,minecraft:obsidian)
B(-8,92,1,minecraft:obsidian)
B(-8,93,1,minecraft:diorite)
B(-8,94,1,minecraft:andesite)
B(-8,12,2,minecraft:diorite)
B(-8,13,2,minecraft:diorite)
B(-8,14,2,minecraft:diorite)
B(-8,15,2,minecraft:diorite)
B(-8,16,2,minecraft:diorite)
B(-8,17,2,minecraft:diorite)
B(-8,18,2,minecraft:diorite)
B(-8,19,2,minecraft:obsidian)
B(-8,20,2,minecraft:obsidian)
B(-8,21,2,minecraft:obsidian)
B(-8,22,2,minecraft:obsidian)
B(-8,23,2,minecraft:obsidian)
B(-8,24,2,minecraft:obsidian)
B(-8,25,2,minecraft:diorite)
B(-8,26,2,minecraft:diorite)
B(-8,27,2,minecraft:diorite)
B(-8,28,2,minecraft:diorite)
B(-8,69,2,minecraft:obsidian)
B(-8,70,2,minecraft:obsidian)
B(-8,71,2,minecraft:obsidian)
B(-8,72,2,minecraft:obsidian)
B(-8,73,2,minecraft:obsidian)
B(-8,74,2,minecraft:obsidian)
B(-8,75,2,minecraft:obsidian)
B(-8,76,2,minecraft:obsidian)
B(-8,77,2,minecraft:obsidian)
B(-8,78,2,minecraft:obsidian)
B(-8,79,2,minecraft:obsidian)
B(-8,80,2,minecraft:obsidian)
B(-8,81,2,minecraft:obsidian)
B(-8,82,2,minecraft:obsidian)
B(-8,83,2,minecraft:obsidian)
B(-8,84,2,minecraft:obsidian)
B(-8,85,2,minecraft:obsidian)
B(-8,86,2,minecraft:obsidian)
B(-8,87,2,minecraft:obsidian)
B(-8,88,2,minecraft:obsidian)
B(-8,89,2,minecraft:obsidian)
B(-8,90,2,minecraft:obsidian)
B(-8,91,2,minecraft:obsidian)
B(-8,92,2,minecraft:diorite)
B(-8,93,2,minecraft:andesite)
B(-8,11,3,minecraft:diorite)
B(-8,12,3,minecraft:diorite)
B(-8,13,3,minecraft:diorite)
B(-8,14,3,minecraft:diorite)
B(-8,15,3,minecraft:diorite)
B(-8,16,3,minecraft:diorite)
B(-8,17,3,minecraft:diorite)
B(-8,18,3,minecraft:obsidian)
B(-8,19,3,minecraft:obsidian)
B(-8,20,3,minecraft:obsidian)
B(-8,21,3,minecraft:obsidian)
B(-8,22,3,minecraft:obsidian)
B(-8,23,3,minecraft:obsidian)
B(-8,24,3,minecraft:obsidian)
B(-8,25,3,minecraft:diorite)
B(-8,26,3,minecraft:diorite)
B(-8,27,3,minecraft:diorite)
B(-8,28,3,minecraft:diorite)
B(-8,69,3,minecraft:obsidian)
B(-8,70,3,minecraft:obsidian)
B(-8,71,3,minecraft:obsidian)
B(-8,72,3,minecraft:obsidian)
B(-8,73,3,minecraft:obsidian)
B(-8,74,3,minecraft:obsidian)
B(-8,75,3,minecraft:obsidian)
B(-8,76,3,minecraft:obsidian)
B(-8,77,3,minecraft:obsidian)
B(-8,78,3,minecraft:obsidian)
B(-8,79,3,minecraft:obsidian)
B(-8,80,3,minecraft:obsidian)
B(-8,81,3,minecraft:obsidian)
B(-8,82,3,minecraft:obsidian)
B(-8,83,3,minecraft:obsidian)
B(-8,84,3,minecraft:obsidian)
B(-8,85,3,minecraft:obsidian)
B(-8,86,3,minecraft:obsidian)
B(-8,87,3,minecraft:obsidian)
B(-8,88,3,minecraft:obsidian)
B(-8,89,3,minecraft:obsidian)
B(-8,90,3,minecraft:obsidian)
B(-8,91,3,minecraft:diorite)
B(-8,92,3,minecraft:andesite)
B(-8,11,4,minecraft:diorite)
B(-8,12,4,minecraft:diorite)
B(-8,13,4,minecraft:diorite)
B(-8,14,4,minecraft:diorite)
B(-8,15,4,minecraft:diorite)
B(-8,16,4,minecraft:obsidian)
B(-8,17,4,minecraft:obsidian)
B(-8,18,4,minecraft:obsidian)
B(-8,19,4,minecraft:obsidian)
B(-8,20,4,minecraft:obsidian)
B(-8,21,4,minecraft:obsidian)
B(-8,22,4,minecraft:obsidian)
B(-8,23,4,minecraft:obsidian)
B(-8,24,4,minecraft:obsidian)
B(-8,25,4,minecraft:diorite)
B(-8,26,4,minecraft:diorite)
B(-8,27,4,minecraft:diorite)
B(-8,68,4,minecraft:obsidian)
B(-8,69,4,minecraft:obsidian)
B(-8,70,4,minecraft:obsidian)
B(-8,71,4,minecraft:obsidian)
B(-8,72,4,minecraft:obsidian)
B(-8,73,4,minecraft:obsidian)
B(-8,74,4,minecraft:obsidian)
B(-8,75,4,minecraft:obsidian)
B(-8,76,4,minecraft:obsidian)
B(-8,77,4,minecraft:obsidian)
B(-8,78,4,minecraft:obsidian)
B(-8,79,4,minecraft:obsidian)
B(-8,80,4,minecraft:obsidian)
B(-8,81,4,minecraft:obsidian)
B(-8,82,4,minecraft:obsidian)
B(-8,83,4,minecraft:obsidian)
B(-8,84,4,minecraft:obsidian)
B(-8,85,4,minecraft:obsidian)
B(-8,86,4,minecraft:obsidian)
B(-8,87,4,minecraft:obsidian)
B(-8,88,4,minecraft:obsidian)
B(-8,89,4,minecraft:obsidian)
B(-8,90,4,minecraft:diorite)
B(-8,91,4,minecraft:andesite)
B(-8,11,5,minecraft:diorite)
B(-8,12,5,minecraft:diorite)
B(-8,13,5,minecraft:diorite)
B(-8,14,5,minecraft:diorite)
B(-8,15,5,minecraft:diorite)
B(-8,16,5,minecraft:obsidian)
B(-8,17,5,minecraft:obsidian)
B(-8,18,5,minecraft:obsidian)
B(-8,19,5,minecraft:obsidian)
B(-8,20,5,minecraft:obsidian)
B(-8,21,5,minecraft:obsidian)
B(-8,22,5,minecraft:obsidian)
B(-8,23,5,minecraft:obsidian)
B(-8,24,5,minecraft:obsidian)
B(-8,25,5,minecraft:diorite)
B(-8,26,5,minecraft:diorite)
B(-8,27,5,minecraft:diorite)
B(-8,28,5,minecraft:diorite)
B(-8,68,5,minecraft:obsidian)
B(-8,69,5,minecraft:obsidian)
B(-8,70,5,minecraft:obsidian)
B(-8,71,5,minecraft:obsidian)
B(-8,72,5,minecraft:obsidian)
B(-8,73,5,minecraft:obsidian)
B(-8,74,5,minecraft:obsidian)
B(-8,75,5,minecraft:obsidian)
B(-8,76,5,minecraft:obsidian)
B(-8,77,5,minecraft:obsidian)
B(-8,78,5,minecraft:obsidian)
B(-8,79,5,minecraft:obsidian)
B(-8,80,5,minecraft:obsidian)
B(-8,81,5,minecraft:obsidian)
B(-8,82,5,minecraft:obsidian)
B(-8,83,5,minecraft:obsidian)
B(-8,84,5,minecraft:obsidian)
B(-8,85,5,minecraft:diorite)
B(-8,86,5,minecraft:diorite)
B(-8,87,5,minecraft:diorite)
B(-8,88,5,minecraft:obsidian)
B(-8,89,5,minecraft:obsidian)
B(-8,90,5,minecraft:diorite)
B(-8,91,5,minecraft:andesite)
B(-8,10,6,minecraft:diorite)
B(-8,11,6,minecraft:diorite)
B(-8,12,6,minecraft:diorite)
B(-8,13,6,minecraft:diorite)
B(-8,14,6,minecraft:diorite)
B(-8,15,6,minecraft:diorite)
B(-8,16,6,minecraft:obsidian)
B(-8,17,6,minecraft:obsidian)
B(-8,18,6,minecraft:obsidian)
B(-8,19,6,minecraft:obsidian)
B(-8,20,6,minecraft:obsidian)
B(-8,21,6,minecraft:obsidian)
B(-8,22,6,minecraft:obsidian)
B(-8,23,6,minecraft:obsidian)
B(-8,24,6,minecraft:obsidian)
B(-8,25,6,minecraft:diorite)
B(-8,26,6,minecraft:diorite)
B(-8,27,6,minecraft:diorite)
B(-8,28,6,minecraft:diorite)
B(-8,69,6,minecraft:obsidian)
B(-8,70,6,minecraft:obsidian)
B(-8,71,6,minecraft:obsidian)
B(-8,72,6,minecraft:obsidian)
B(-8,73,6,minecraft:obsidian)
B(-8,74,6,minecraft:obsidian)
B(-8,75,6,minecraft:obsidian)
B(-8,76,6,minecraft:obsidian)
B(-8,77,6,minecraft:obsidian)
B(-8,78,6,minecraft:obsidian)
B(-8,79,6,minecraft:obsidian)
B(-8,80,6,minecraft:obsidian)
B(-8,81,6,minecraft:obsidian)
B(-8,82,6,minecraft:obsidian)
B(-8,83,6,minecraft:diorite)
B(-8,84,6,minecraft:diorite)
B(-8,85,6,minecraft:diorite)
B(-8,86,6,minecraft:diorite)
B(-8,87,6,minecraft:diorite)
B(-8,88,6,minecraft:diorite)
B(-8,89,6,minecraft:diorite)
B(-8,90,6,minecraft:diorite)
B(-8,91,6,minecraft:diorite)
B(-8,10,7,minecraft:diorite)
B(-8,11,7,minecraft:diorite)
B(-8,12,7,minecraft:diorite)
B(-8,13,7,minecraft:diorite)
B(-8,14,7,minecraft:diorite)
B(-8,15,7,minecraft:obsidian)
B(-8,16,7,minecraft:obsidian)
B(-8,17,7,minecraft:obsidian)
B(-8,18,7,minecraft:obsidian)
B(-8,19,7,minecraft:obsidian)
B(-8,20,7,minecraft:obsidian)
B(-8,21,7,minecraft:obsidian)
B(-8,22,7,minecraft:obsidian)
B(-8,23,7,minecraft:obsidian)
B(-8,24,7,minecraft:obsidian)
B(-8,25,7,minecraft:diorite)
B(-8,26,7,minecraft:diorite)
B(-8,27,7,minecraft:diorite)
B(-8,28,7,minecraft:diorite)
B(-8,29,7,minecraft:diorite)
B(-8,69,7,minecraft:obsidian)
B(-8,70,7,minecraft:obsidian)
B(-8,71,7,minecraft:obsidian)
B(-8,72,7,minecraft:obsidian)
B(-8,73,7,minecraft:obsidian)
B(-8,74,7,minecraft:obsidian)
B(-8,75,7,minecraft:obsidian)
B(-8,76,7,minecraft:obsidian)
B(-8,77,7,minecraft:obsidian)
B(-8,78,7,minecraft:obsidian)
B(-8,79,7,minecraft:obsidian)
B(-8,80,7,minecraft:obsidian)
B(-8,81,7,minecraft:obsidian)
B(-8,82,7,minecraft:diorite)
B(-8,83,7,minecraft:diorite)
B(-8,84,7,minecraft:diorite)
B(-8,85,7,minecraft:diorite)
B(-8,86,7,minecraft:diorite)
B(-8,87,7,minecraft:diorite)
B(-8,88,7,minecraft:diorite)
B(-8,89,7,minecraft:diorite)
B(-8,90,7,minecraft:diorite)
B(-8,91,7,minecraft:diorite)
B(-8,9,8,minecraft:diorite)
B(-8,10,8,minecraft:diorite)
B(-8,11,8,minecraft:diorite)
B(-8,12,8,minecraft:diorite)
B(-8,13,8,minecraft:diorite)
B(-8,14,8,minecraft:diorite)
B(-8,15,8,minecraft:obsidian)
B(-8,16,8,minecraft:obsidian)
B(-8,17,8,minecraft:obsidian)
B(-8,18,8,minecraft:obsidian)
B(-8,19,8,minecraft:obsidian)
B(-8,20,8,minecraft:obsidian)
B(-8,21,8,minecraft:obsidian)
B(-8,22,8,minecraft:obsidian)
B(-8,23,8,minecraft:obsidian)
B(-8,24,8,minecraft:obsidian)
B(-8,25,8,minecraft:obsidian)
B(-8,26,8,minecraft:diorite)
B(-8,27,8,minecraft:diorite)
B(-8,28,8,minecraft:diorite)
B(-8,29,8,minecraft:obsidian)
B(-8,68,8,minecraft:obsidian)
B(-8,69,8,minecraft:obsidian)
B(-8,70,8,minecraft:obsidian)
B(-8,71,8,minecraft:obsidian)
B(-8,72,8,minecraft:obsidian)
B(-8,73,8,minecraft:obsidian)
B(-8,74,8,minecraft:obsidian)
B(-8,75,8,minecraft:obsidian)
B(-8,76,8,minecraft:obsidian)
B(-8,77,8,minecraft:obsidian)
B(-8,78,8,minecraft:obsidian)
B(-8,79,8,minecraft:obsidian)
B(-8,80,8,minecraft:obsidian)
B(-8,81,8,minecraft:obsidian)
B(-8,82,8,minecraft:diorite)
B(-8,83,8,minecraft:diorite)
B(-8,84,8,minecraft:diorite)
B(-8,85,8,minecraft:diorite)
B(-8,86,8,minecraft:diorite)
B(-8,87,8,minecraft:diorite)
B(-8,88,8,minecraft:diorite)
B(-8,89,8,minecraft:diorite)
B(-8,90,8,minecraft:diorite)
B(-7,15,-7,minecraft:diorite)
B(-7,16,-7,minecraft:diorite)
B(-7,17,-7,minecraft:diorite)
B(-7,18,-7,minecraft:diorite)
B(-7,19,-7,minecraft:diorite)
B(-7,20,-7,minecraft:diorite)
B(-7,21,-7,minecraft:obsidian)
B(-7,22,-7,minecraft:obsidian)
B(-7,23,-7,minecraft:obsidian)
B(-7,24,-7,minecraft:obsidian)
B(-7,25,-7,minecraft:obsidian)
B(-7,26,-7,minecraft:obsidian)
B(-7,27,-7,minecraft:obsidian)
B(-7,28,-7,minecraft:diorite)
B(-7,29,-7,minecraft:diorite)
B(-7,30,-7,minecraft:diorite)
B(-7,31,-7,minecraft:diorite)
B(-7,32,-7,minecraft:diorite)
B(-7,45,-7,minecraft:obsidian)
B(-7,46,-7,minecraft:obsidian)
B(-7,47,-7,minecraft:obsidian)
B(-7,48,-7,minecraft:obsidian)
B(-7,49,-7,minecraft:obsidian)
B(-7,50,-7,minecraft:obsidian)
B(-7,51,-7,minecraft:obsidian)
B(-7,52,-7,minecraft:obsidian)
B(-7,53,-7,minecraft:obsidian)
B(-7,63,-7,minecraft:obsidian)
B(-7,64,-7,minecraft:obsidian)
B(-7,65,-7,minecraft:obsidian)
B(-7,66,-7,minecraft:obsidian)
B(-7,67,-7,minecraft:obsidian)
B(-7,68,-7,minecraft:obsidian)
B(-7,69,-7,minecraft:obsidian)
B(-7,70,-7,minecraft:obsidian)
B(-7,71,-7,minecraft:obsidian)
B(-7,72,-7,minecraft:obsidian)
B(-7,73,-7,minecraft:obsidian)
B(-7,74,-7,minecraft:obsidian)
B(-7,75,-7,minecraft:obsidian)
B(-7,76,-7,minecraft:obsidian)
B(-7,77,-7,minecraft:obsidian)
B(-7,78,-7,minecraft:obsidian)
B(-7,79,-7,minecraft:obsidian)
B(-7,80,-7,minecraft:obsidian)
B(-7,81,-7,minecraft:obsidian)
B(-7,82,-7,minecraft:obsidian)
B(-7,83,-7,minecraft:obsidian)
B(-7,84,-7,minecraft:obsidian)
B(-7,85,-7,minecraft:obsidian)
B(-7,86,-7,minecraft:obsidian)
B(-7,87,-7,minecraft:obsidian)
B(-7,88,-7,minecraft:obsidian)
B(-7,89,-7,minecraft:obsidian)
B(-7,90,-7,minecraft:obsidian)
B(-7,91,-7,minecraft:obsidian)
B(-7,92,-7,minecraft:obsidian)
B(-7,93,-7,minecraft:obsidian)
B(-7,94,-7,minecraft:obsidian)
B(-7,95,-7,minecraft:obsidian)
B(-7,96,-7,minecraft:diorite)
B(-7,97,-7,minecraft:diorite)
B(-7,15,-6,minecraft:diorite)
B(-7,16,-6,minecraft:diorite)
B(-7,17,-6,minecraft:diorite)
B(-7,18,-6,minecraft:diorite)
B(-7,19,-6,minecraft:diorite)
B(-7,20,-6,minecraft:diorite)
B(-7,21,-6,minecraft:obsidian)
B(-7,22,-6,minecraft:obsidian)
B(-7,23,-6,minecraft:obsidian)
B(-7,24,-6,minecraft:obsidian)
B(-7,25,-6,minecraft:obsidian)
B(-7,26,-6,minecraft:obsidian)
B(-7,27,-6,minecraft:diorite)
B(-7,28,-6,minecraft:diorite)
B(-7,29,-6,minecraft:diorite)
B(-7,30,-6,minecraft:diorite)
B(-7,31,-6,minecraft:diorite)
B(-7,48,-6,minecraft:obsidian)
B(-7,49,-6,minecraft:obsidian)
B(-7,50,-6,minecraft:obsidian)
B(-7,51,-6,minecraft:obsidian)
B(-7,64,-6,minecraft:obsidian)
B(-7,65,-6,minecraft:obsidian)
B(-7,66,-6,minecraft:obsidian)
B(-7,67,-6,minecraft:obsidian)
B(-7,68,-6,minecraft:obsidian)
B(-7,69,-6,minecraft:obsidian)
B(-7,70,-6,minecraft:obsidian)
B(-7,71,-6,minecraft:obsidian)
B(-7,72,-6,minecraft:obsidian)
B(-7,73,-6,minecraft:obsidian)
B(-7,74,-6,minecraft:obsidian)
B(-7,75,-6,minecraft:obsidian)
B(-7,76,-6,minecraft:obsidian)
B(-7,77,-6,minecraft:obsidian)
B(-7,78,-6,minecraft:obsidian)
B(-7,79,-6,minecraft:obsidian)
B(-7,80,-6,minecraft:obsidian)
B(-7,81,-6,minecraft:obsidian)
B(-7,82,-6,minecraft:obsidian)
B(-7,83,-6,minecraft:obsidian)
B(-7,84,-6,minecraft:obsidian)
B(-7,85,-6,minecraft:obsidian)
B(-7,86,-6,minecraft:obsidian)
B(-7,87,-6,minecraft:obsidian)
B(-7,88,-6,minecraft:obsidian)
B(-7,89,-6,minecraft:obsidian)
B(-7,90,-6,minecraft:obsidian)
B(-7,91,-6,minecraft:obsidian)
B(-7,92,-6,minecraft:obsidian)
B(-7,93,-6,minecraft:obsidian)
B(-7,94,-6,minecraft:obsidian)
B(-7,95,-6,minecraft:obsidian)
B(-7,96,-6,minecraft:diorite)
B(-7,97,-6,minecraft:diorite)
B(-7,15,-5,minecraft:diorite)
B(-7,16,-5,minecraft:diorite)
B(-7,17,-5,minecraft:diorite)
B(-7,18,-5,minecraft:diorite)
B(-7,19,-5,minecraft:diorite)
B(-7,20,-5,minecraft:diorite)
B(-7,21,-5,minecraft:obsidian)
B(-7,22,-5,minecraft:obsidian)
B(-7,23,-5,minecraft:obsidian)
B(-7,24,-5,minecraft:obsidian)
B(-7,25,-5,minecraft:obsidian)
B(-7,26,-5,minecraft:obsidian)
B(-7,27,-5,minecraft:diorite)
B(-7,28,-5,minecraft:diorite)
B(-7,29,-5,minecraft:diorite)
B(-7,30,-5,minecraft:diorite)
B(-7,70,-5,minecraft:obsidian)
B(-7,71,-5,minecraft:obsidian)
B(-7,72,-5,minecraft:obsidian)
B(-7,73,-5,minecraft:obsidian)
B(-7,74,-5,minecraft:obsidian)
B(-7,75,-5,minecraft:obsidian)
B(-7,76,-5,minecraft:obsidian)
B(-7,77,-5,minecraft:obsidian)
B(-7,78,-5,minecraft:obsidian)
B(-7,79,-5,minecraft:obsidian)
B(-7,80,-5,minecraft:obsidian)
B(-7,81,-5,minecraft:obsidian)
B(-7,82,-5,minecraft:obsidian)
B(-7,83,-5,minecraft:obsidian)
B(-7,84,-5,minecraft:obsidian)
B(-7,85,-5,minecraft:obsidian)
B(-7,86,-5,minecraft:obsidian)
B(-7,87,-5,minecraft:obsidian)
B(-7,88,-5,minecraft:obsidian)
B(-7,89,-5,minecraft:obsidian)
B(-7,90,-5,minecraft:obsidian)
B(-7,91,-5,minecraft:obsidian)
B(-7,92,-5,minecraft:obsidian)
B(-7,93,-5,minecraft:obsidian)
B(-7,94,-5,minecraft:obsidian)
B(-7,95,-5,minecraft:obsidian)
B(-7,96,-5,minecraft:diorite)
B(-7,97,-5,minecraft:diorite)
B(-7,15,-4,minecraft:diorite)
B(-7,16,-4,minecraft:diorite)
B(-7,17,-4,minecraft:diorite)
B(-7,18,-4,minecraft:diorite)
B(-7,19,-4,minecraft:diorite)
B(-7,20,-4,minecraft:diorite)
B(-7,21,-4,minecraft:obsidian)
B(-7,22,-4,minecraft:obsidian)
B(-7,23,-4,minecraft:obsidian)
B(-7,24,-4,minecraft:obsidian)
B(-7,25,-4,minecraft:obsidian)
B(-7,26,-4,minecraft:obsidian)
B(-7,27,-4,minecraft:diorite)
B(-7,28,-4,minecraft:diorite)
B(-7,29,-4,minecraft:diorite)
B(-7,73,-4,minecraft:obsidian)
B(-7,74,-4,minecraft:obsidian)
B(-7,75,-4,minecraft:obsidian)
B(-7,76,-4,minecraft:obsidian)
B(-7,77,-4,minecraft:obsidian)
B(-7,78,-4,minecraft:obsidian)
B(-7,79,-4,minecraft:obsidian)
B(-7,80,-4,minecraft:obsidian)
B(-7,81,-4,minecraft:obsidian)
B(-7,82,-4,minecraft:obsidian)
B(-7,83,-4,minecraft:obsidian)
B(-7,84,-4,minecraft:obsidian)
B(-7,85,-4,minecraft:obsidian)
B(-7,86,-4,minecraft:obsidian)
B(-7,87,-4,minecraft:obsidian)
B(-7,88,-4,minecraft:obsidian)
B(-7,89,-4,minecraft:obsidian)
B(-7,90,-4,minecraft:obsidian)
B(-7,91,-4,minecraft:obsidian)
B(-7,92,-4,minecraft:obsidian)
B(-7,93,-4,minecraft:obsidian)
B(-7,94,-4,minecraft:obsidian)
B(-7,95,-4,minecraft:diorite)
B(-7,96,-4,minecraft:andesite)
B(-7,15,-3,minecraft:diorite)
B(-7,16,-3,minecraft:diorite)
B(-7,17,-3,minecraft:diorite)
B(-7,18,-3,minecraft:diorite)
B(-7,19,-3,minecraft:diorite)
B(-7,20,-3,minecraft:diorite)
B(-7,21,-3,minecraft:obsidian)
B(-7,22,-3,minecraft:obsidian)
B(-7,23,-3,minecraft:obsidian)
B(-7,24,-3,minecraft:obsidian)
B(-7,25,-3,minecraft:obsidian)
B(-7,26,-3,minecraft:obsidian)
B(-7,27,-3,minecraft:diorite)
B(-7,28,-3,minecraft:diorite)
B(-7,75,-3,minecraft:obsidian)
B(-7,76,-3,minecraft:obsidian)
B(-7,77,-3,minecraft:obsidian)
B(-7,78,-3,minecraft:obsidian)
B(-7,79,-3,minecraft:obsidian)
B(-7,80,-3,minecraft:obsidian)
B(-7,81,-3,minecraft:obsidian)
B(-7,82,-3,minecraft:obsidian)
B(-7,83,-3,minecraft:obsidian)
B(-7,84,-3,minecraft:obsidian)
B(-7,85,-3,minecraft:obsidian)
B(-7,86,-3,minecraft:obsidian)
B(-7,87,-3,minecraft:obsidian)
B(-7,88,-3,minecraft:obsidian)
B(-7,89,-3,minecraft:obsidian)
B(-7,90,-3,minecraft:obsidian)
B(-7,91,-3,minecraft:obsidian)
B(-7,92,-3,minecraft:obsidian)
B(-7,93,-3,minecraft:obsidian)
B(-7,94,-3,minecraft:obsidian)
B(-7,95,-3,minecraft:obsidian)
B(-7,96,-3,minecraft:diorite)
B(-7,97,-3,minecraft:diorite)
B(-7,15,-2,minecraft:diorite)
B(-7,16,-2,minecraft:diorite)
B(-7,17,-2,minecraft:diorite)
B(-7,18,-2,minecraft:diorite)
B(-7,19,-2,minecraft:diorite)
B(-7,20,-2,minecraft:obsidian)
B(-7,21,-2,minecraft:obsidian)
B(-7,22,-2,minecraft:obsidian)
B(-7,23,-2,minecraft:obsidian)
B(-7,24,-2,minecraft:obsidian)
B(-7,25,-2,minecraft:obsidian)
B(-7,26,-2,minecraft:obsidian)
B(-7,27,-2,minecraft:diorite)
B(-7,28,-2,minecraft:diorite)
B(-7,74,-2,minecraft:obsidian)
B(-7,75,-2,minecraft:obsidian)
B(-7,76,-2,minecraft:obsidian)
B(-7,77,-2,minecraft:obsidian)
B(-7,78,-2,minecraft:obsidian)
B(-7,79,-2,minecraft:obsidian)
B(-7,80,-2,minecraft:obsidian)
B(-7,81,-2,minecraft:obsidian)
B(-7,82,-2,minecraft:obsidian)
B(-7,83,-2,minecraft:obsidian)
B(-7,84,-2,minecraft:obsidian)
B(-7,85,-2,minecraft:obsidian)
B(-7,86,-2,minecraft:obsidian)
B(-7,87,-2,minecraft:obsidian)
B(-7,88,-2,minecraft:obsidian)
B(-7,89,-2,minecraft:obsidian)
B(-7,90,-2,minecraft:obsidian)
B(-7,91,-2,minecraft:obsidian)
B(-7,92,-2,minecraft:obsidian)
B(-7,93,-2,minecraft:obsidian)
B(-7,94,-2,minecraft:obsidian)
B(-7,95,-2,minecraft:obsidian)
B(-7,96,-2,minecraft:diorite)
B(-7,97,-2,minecraft:diorite)
B(-7,14,-1,minecraft:diorite)
B(-7,15,-1,minecraft:diorite)
B(-7,16,-1,minecraft:diorite)
B(-7,17,-1,minecraft:diorite)
B(-7,18,-1,minecraft:diorite)
B(-7,19,-1,minecraft:diorite)
B(-7,20,-1,minecraft:obsidian)
B(-7,21,-1,minecraft:obsidian)
B(-7,22,-1,minecraft:obsidian)
B(-7,23,-1,minecraft:obsidian)
B(-7,24,-1,minecraft:obsidian)
B(-7,25,-1,minecraft:obsidian)
B(-7,26,-1,minecraft:diorite)
B(-7,27,-1,minecraft:diorite)
B(-7,28,-1,minecraft:diorite)
B(-7,73,-1,minecraft:obsidian)
B(-7,74,-1,minecraft:obsidian)
B(-7,75,-1,minecraft:obsidian)
B(-7,76,-1,minecraft:obsidian)
B(-7,77,-1,minecraft:obsidian)
B(-7,78,-1,minecraft:obsidian)
B(-7,79,-1,minecraft:obsidian)
B(-7,80,-1,minecraft:obsidian)
B(-7,81,-1,minecraft:obsidian)
B(-7,82,-1,minecraft:obsidian)
B(-7,83,-1,minecraft:obsidian)
B(-7,84,-1,minecraft:obsidian)
B(-7,85,-1,minecraft:obsidian)
B(-7,86,-1,minecraft:obsidian)
B(-7,87,-1,minecraft:obsidian)
B(-7,88,-1,minecraft:obsidian)
B(-7,89,-1,minecraft:obsidian)
B(-7,90,-1,minecraft:obsidian)
B(-7,91,-1,minecraft:obsidian)
B(-7,92,-1,minecraft:obsidian)
B(-7,93,-1,minecraft:obsidian)
B(-7,94,-1,minecraft:obsidian)
B(-7,95,-1,minecraft:diorite)
B(-7,96,-1,minecraft:andesite)
B(-7,13,0,minecraft:diorite)
B(-7,14,0,minecraft:diorite)
B(-7,15,0,minecraft:diorite)
B(-7,16,0,minecraft:diorite)
B(-7,17,0,minecraft:diorite)
B(-7,18,0,minecraft:diorite)
B(-7,19,0,minecraft:diorite)
B(-7,20,0,minecraft:obsidian)
B(-7,21,0,minecraft:obsidian)
B(-7,22,0,minecraft:obsidian)
B(-7,23,0,minecraft:obsidian)
B(-7,24,0,minecraft:obsidian)
B(-7,25,0,minecraft:obsidian)
B(-7,26,0,minecraft:diorite)
B(-7,27,0,minecraft:diorite)
B(-7,72,0,minecraft:obsidian)
B(-7,73,0,minecraft:obsidian)
B(-7,74,0,minecraft:obsidian)
B(-7,75,0,minecraft:obsidian)
B(-7,76,0,minecraft:obsidian)
B(-7,77,0,minecraft:obsidian)
B(-7,78,0,minecraft:obsidian)
B(-7,79,0,minecraft:obsidian)
B(-7,80,0,minecraft:obsidian)
B(-7,81,0,minecraft:obsidian)
B(-7,82,0,minecraft:obsidian)
B(-7,83,0,minecraft:obsidian)
B(-7,84,0,minecraft:obsidian)
B(-7,85,0,minecraft:obsidian)
B(-7,86,0,minecraft:obsidian)
B(-7,87,0,minecraft:obsidian)
B(-7,88,0,minecraft:obsidian)
B(-7,89,0,minecraft:obsidian)
B(-7,90,0,minecraft:obsidian)
B(-7,91,0,minecraft:obsidian)
B(-7,92,0,minecraft:obsidian)
B(-7,93,0,minecraft:obsidian)
B(-7,94,0,minecraft:diorite)
B(-7,95,0,minecraft:andesite)
B(-7,13,1,minecraft:diorite)
B(-7,14,1,minecraft:diorite)
B(-7,15,1,minecraft:diorite)
B(-7,16,1,minecraft:diorite)
B(-7,17,1,minecraft:diorite)
B(-7,18,1,minecraft:diorite)
B(-7,19,1,minecraft:diorite)
B(-7,20,1,minecraft:obsidian)
B(-7,21,1,minecraft:obsidian)
B(-7,22,1,minecraft:obsidian)
B(-7,23,1,minecraft:obsidian)
B(-7,24,1,minecraft:obsidian)
B(-7,25,1,minecraft:diorite)
B(-7,26,1,minecraft:diorite)
B(-7,27,1,minecraft:diorite)
B(-7,28,1,minecraft:diorite)
B(-7,71,1,minecraft:obsidian)
B(-7,72,1,minecraft:obsidian)
B(-7,73,1,minecraft:obsidian)
B(-7,74,1,minecraft:obsidian)
B(-7,75,1,minecraft:obsidian)
B(-7,76,1,minecraft:obsidian)
B(-7,77,1,minecraft:obsidian)
B(-7,78,1,minecraft:obsidian)
B(-7,79,1,minecraft:obsidian)
B(-7,80,1,minecraft:obsidian)
B(-7,81,1,minecraft:obsidian)
B(-7,82,1,minecraft:obsidian)
B(-7,83,1,minecraft:obsidian)
B(-7,84,1,minecraft:obsidian)
B(-7,85,1,minecraft:obsidian)
B(-7,86,1,minecraft:obsidian)
B(-7,87,1,minecraft:obsidian)
B(-7,88,1,minecraft:obsidian)
B(-7,89,1,minecraft:obsidian)
B(-7,90,1,minecraft:obsidian)
B(-7,91,1,minecraft:obsidian)
B(-7,92,1,minecraft:obsidian)
B(-7,93,1,minecraft:obsidian)
B(-7,94,1,minecraft:diorite)
B(-7,95,1,minecraft:andesite)
B(-7,12,2,minecraft:diorite)
B(-7,13,2,minecraft:diorite)
B(-7,14,2,minecraft:diorite)
B(-7,15,2,minecraft:diorite)
B(-7,16,2,minecraft:diorite)
B(-7,17,2,minecraft:diorite)
B(-7,18,2,minecraft:diorite)
B(-7,19,2,minecraft:obsidian)
B(-7,20,2,minecraft:obsidian)
B(-7,21,2,minecraft:obsidian)
B(-7,22,2,minecraft:obsidian)
B(-7,23,2,minecraft:obsidian)
B(-7,24,2,minecraft:obsidian)
B(-7,25,2,minecraft:diorite)
B(-7,26,2,minecraft:diorite)
B(-7,27,2,minecraft:diorite)
B(-7,28,2,minecraft:diorite)
B(-7,70,2,minecraft:obsidian)
B(-7,71,2,minecraft:obsidian)
B(-7,72,2,minecraft:obsidian)
B(-7,73,2,minecraft:obsidian)
B(-7,74,2,minecraft:obsidian)
B(-7,75,2,minecraft:obsidian)
B(-7,76,2,minecraft:obsidian)
B(-7,77,2,minecraft:obsidian)
B(-7,78,2,minecraft:obsidian)
B(-7,79,2,minecraft:obsidian)
B(-7,80,2,minecraft:obsidian)
B(-7,81,2,minecraft:obsidian)
B(-7,82,2,minecraft:obsidian)
B(-7,83,2,minecraft:obsidian)
B(-7,84,2,minecraft:obsidian)
B(-7,85,2,minecraft:obsidian)
B(-7,86,2,minecraft:obsidian)
B(-7,87,2,minecraft:obsidian)
B(-7,88,2,minecraft:obsidian)
B(-7,89,2,minecraft:obsidian)
B(-7,90,2,minecraft:obsidian)
B(-7,91,2,minecraft:obsidian)
B(-7,92,2,minecraft:obsidian)
B(-7,93,2,minecraft:diorite)
B(-7,94,2,minecraft:andesite)
B(-7,11,3,minecraft:diorite)
B(-7,12,3,minecraft:diorite)
B(-7,13,3,minecraft:diorite)
B(-7,14,3,minecraft:diorite)
B(-7,15,3,minecraft:diorite)
B(-7,16,3,minecraft:diorite)
B(-7,17,3,minecraft:diorite)
B(-7,18,3,minecraft:obsidian)
B(-7,19,3,minecraft:obsidian)
B(-7,20,3,minecraft:obsidian)
B(-7,21,3,minecraft:obsidian)
B(-7,22,3,minecraft:obsidian)
B(-7,23,3,minecraft:obsidian)
B(-7,24,3,minecraft:obsidian)
B(-7,25,3,minecraft:diorite)
B(-7,26,3,minecraft:diorite)
B(-7,27,3,minecraft:diorite)
B(-7,69,3,minecraft:obsidian)
B(-7,70,3,minecraft:obsidian)
B(-7,71,3,minecraft:obsidian)
B(-7,72,3,minecraft:obsidian)
B(-7,73,3,minecraft:obsidian)
B(-7,74,3,minecraft:obsidian)
B(-7,75,3,minecraft:obsidian)
B(-7,76,3,minecraft:obsidian)
B(-7,77,3,minecraft:obsidian)
B(-7,78,3,minecraft:obsidian)
B(-7,79,3,minecraft:obsidian)
B(-7,80,3,minecraft:obsidian)
B(-7,81,3,minecraft:obsidian)
B(-7,82,3,minecraft:obsidian)
B(-7,83,3,minecraft:obsidian)
B(-7,84,3,minecraft:obsidian)
B(-7,85,3,minecraft:obsidian)
B(-7,86,3,minecraft:obsidian)
B(-7,87,3,minecraft:obsidian)
B(-7,88,3,minecraft:obsidian)
B(-7,89,3,minecraft:obsidian)
B(-7,90,3,minecraft:obsidian)
B(-7,91,3,minecraft:obsidian)
B(-7,92,3,minecraft:diorite)
B(-7,93,3,minecraft:andesite)
B(-7,11,4,minecraft:diorite)
B(-7,12,4,minecraft:diorite)
B(-7,13,4,minecraft:diorite)
B(-7,14,4,minecraft:diorite)
B(-7,15,4,minecraft:diorite)
B(-7,16,4,minecraft:diorite)
B(-7,17,4,minecraft:obsidian)
B(-7,18,4,minecraft:obsidian)
B(-7,19,4,minecraft:obsidian)
B(-7,20,4,minecraft:obsidian)
B(-7,21,4,minecraft:obsidian)
B(-7,22,4,minecraft:obsidian)
B(-7,23,4,minecraft:obsidian)
B(-7,24,4,minecraft:obsidian)
B(-7,25,4,minecraft:diorite)
B(-7,26,4,minecraft:diorite)
B(-7,27,4,minecraft:diorite)
B(-7,69,4,minecraft:obsidian)
B(-7,70,4,minecraft:obsidian)
B(-7,71,4,minecraft:obsidian)
B(-7,72,4,minecraft:obsidian)
B(-7,73,4,minecraft:obsidian)
B(-7,74,4,minecraft:obsidian)
B(-7,75,4,minecraft:obsidian)
B(-7,76,4,minecraft:obsidian)
B(-7,77,4,minecraft:obsidian)
B(-7,78,4,minecraft:obsidian)
B(-7,79,4,minecraft:obsidian)
B(-7,80,4,minecraft:obsidian)
B(-7,81,4,minecraft:obsidian)
B(-7,82,4,minecraft:obsidian)
B(-7,83,4,minecraft:obsidian)
B(-7,84,4,minecraft:obsidian)
B(-7,85,4,minecraft:obsidian)
B(-7,86,4,minecraft:obsidian)
B(-7,87,4,minecraft:obsidian)
B(-7,88,4,minecraft:obsidian)
B(-7,89,4,minecraft:obsidian)
B(-7,90,4,minecraft:obsidian)
B(-7,91,4,minecraft:diorite)
B(-7,92,4,minecraft:andesite)
B(-7,11,5,minecraft:diorite)
B(-7,12,5,minecraft:diorite)
B(-7,13,5,minecraft:diorite)
B(-7,14,5,minecraft:diorite)
B(-7,15,5,minecraft:diorite)
B(-7,16,5,minecraft:obsidian)
B(-7,17,5,minecraft:obsidian)
B(-7,18,5,minecraft:obsidian)
B(-7,19,5,minecraft:obsidian)
B(-7,20,5,minecraft:obsidian)
B(-7,21,5,minecraft:obsidian)
B(-7,22,5,minecraft:obsidian)
B(-7,23,5,minecraft:obsidian)
B(-7,24,5,minecraft:obsidian)
B(-7,25,5,minecraft:diorite)
B(-7,26,5,minecraft:diorite)
B(-7,27,5,minecraft:diorite)
B(-7,69,5,minecraft:obsidian)
B(-7,70,5,minecraft:obsidian)
B(-7,71,5,minecraft:obsidian)
B(-7,72,5,minecraft:obsidian)
B(-7,73,5,minecraft:obsidian)
B(-7,74,5,minecraft:obsidian)
B(-7,75,5,minecraft:obsidian)
B(-7,76,5,minecraft:obsidian)
B(-7,77,5,minecraft:obsidian)
B(-7,78,5,minecraft:obsidian)
B(-7,79,5,minecraft:obsidian)
B(-7,80,5,minecraft:obsidian)
B(-7,81,5,minecraft:obsidian)
B(-7,82,5,minecraft:obsidian)
B(-7,83,5,minecraft:obsidian)
B(-7,84,5,minecraft:obsidian)
B(-7,85,5,minecraft:obsidian)
B(-7,86,5,minecraft:obsidian)
B(-7,87,5,minecraft:diorite)
B(-7,88,5,minecraft:diorite)
B(-7,89,5,minecraft:diorite)
B(-7,90,5,minecraft:diorite)
B(-7,91,5,minecraft:andesite)
B(-7,10,6,minecraft:diorite)
B(-7,11,6,minecraft:diorite)
B(-7,12,6,minecraft:diorite)
B(-7,13,6,minecraft:diorite)
B(-7,14,6,minecraft:diorite)
B(-7,15,6,minecraft:diorite)
B(-7,16,6,minecraft:obsidian)
B(-7,17,6,minecraft:obsidian)
B(-7,18,6,minecraft:obsidian)
B(-7,19,6,minecraft:obsidian)
B(-7,20,6,minecraft:obsidian)
B(-7,21,6,minecraft:obsidian)
B(-7,22,6,minecraft:obsidian)
B(-7,23,6,minecraft:obsidian)
B(-7,24,6,minecraft:obsidian)
B(-7,25,6,minecraft:diorite)
B(-7,26,6,minecraft:diorite)
B(-7,27,6,minecraft:diorite)
B(-7,28,6,minecraft:diorite)
B(-7,69,6,minecraft:obsidian)
B(-7,70,6,minecraft:obsidian)
B(-7,71,6,minecraft:obsidian)
B(-7,72,6,minecraft:obsidian)
B(-7,73,6,minecraft:obsidian)
B(-7,74,6,minecraft:obsidian)
B(-7,75,6,minecraft:obsidian)
B(-7,76,6,minecraft:obsidian)
B(-7,77,6,minecraft:obsidian)
B(-7,78,6,minecraft:obsidian)
B(-7,79,6,minecraft:obsidian)
B(-7,80,6,minecraft:obsidian)
B(-7,81,6,minecraft:obsidian)
B(-7,82,6,minecraft:obsidian)
B(-7,83,6,minecraft:obsidian)
B(-7,84,6,minecraft:diorite)
B(-7,85,6,minecraft:diorite)
B(-7,86,6,minecraft:diorite)
B(-7,87,6,minecraft:diorite)
B(-7,88,6,minecraft:diorite)
B(-7,89,6,minecraft:diorite)
B(-7,90,6,minecraft:diorite)
B(-7,91,6,minecraft:andesite)
B(-7,10,7,minecraft:diorite)
B(-7,11,7,minecraft:diorite)
B(-7,12,7,minecraft:diorite)
B(-7,13,7,minecraft:diorite)
B(-7,14,7,minecraft:diorite)
B(-7,15,7,minecraft:diorite)
B(-7,16,7,minecraft:obsidian)
B(-7,17,7,minecraft:obsidian)
B(-7,18,7,minecraft:obsidian)
B(-7,19,7,minecraft:obsidian)
B(-7,20,7,minecraft:obsidian)
B(-7,21,7,minecraft:obsidian)
B(-7,22,7,minecraft:obsidian)
B(-7,23,7,minecraft:obsidian)
B(-7,24,7,minecraft:obsidian)
B(-7,25,7,minecraft:diorite)
B(-7,26,7,minecraft:diorite)
B(-7,27,7,minecraft:diorite)
B(-7,28,7,minecraft:diorite)
B(-7,69,7,minecraft:obsidian)
B(-7,70,7,minecraft:obsidian)
B(-7,71,7,minecraft:obsidian)
B(-7,72,7,minecraft:obsidian)
B(-7,73,7,minecraft:obsidian)
B(-7,74,7,minecraft:obsidian)
B(-7,75,7,minecraft:obsidian)
B(-7,76,7,minecraft:obsidian)
B(-7,77,7,minecraft:obsidian)
B(-7,78,7,minecraft:obsidian)
B(-7,79,7,minecraft:obsidian)
B(-7,80,7,minecraft:obsidian)
B(-7,81,7,minecraft:obsidian)
B(-7,82,7,minecraft:obsidian)
B(-7,83,7,minecraft:diorite)
B(-7,84,7,minecraft:diorite)
B(-7,85,7,minecraft:diorite)
B(-7,86,7,minecraft:diorite)
B(-7,87,7,minecraft:diorite)
B(-7,88,7,minecraft:diorite)
B(-7,89,7,minecraft:diorite)
B(-7,90,7,minecraft:diorite)
B(-7,9,8,minecraft:diorite)
B(-7,10,8,minecraft:diorite)
B(-7,11,8,minecraft:diorite)
B(-7,12,8,minecraft:diorite)
B(-7,13,8,minecraft:diorite)
B(-7,14,8,minecraft:diorite)
B(-7,15,8,minecraft:obsidian)
B(-7,16,8,minecraft:obsidian)
B(-7,17,8,minecraft:obsidian)
B(-7,18,8,minecraft:obsidian)
B(-7,19,8,minecraft:obsidian)
B(-7,20,8,minecraft:obsidian)
B(-7,21,8,minecraft:obsidian)
B(-7,22,8,minecraft:obsidian)
B(-7,23,8,minecraft:obsidian)
B(-7,24,8,minecraft:obsidian)
B(-7,25,8,minecraft:obsidian)
B(-7,26,8,minecraft:diorite)
B(-7,27,8,minecraft:diorite)
B(-7,28,8,minecraft:diorite)
B(-7,29,8,minecraft:obsidian)
B(-7,69,8,minecraft:obsidian)
B(-7,70,8,minecraft:obsidian)
B(-7,71,8,minecraft:obsidian)
B(-7,72,8,minecraft:obsidian)
B(-7,73,8,minecraft:obsidian)
B(-7,74,8,minecraft:obsidian)
B(-7,75,8,minecraft:obsidian)
B(-7,76,8,minecraft:obsidian)
B(-7,77,8,minecraft:obsidian)
B(-7,78,8,minecraft:obsidian)
B(-7,79,8,minecraft:obsidian)
B(-7,80,8,minecraft:obsidian)
B(-7,81,8,minecraft:obsidian)
B(-7,82,8,minecraft:diorite)
B(-7,83,8,minecraft:diorite)
B(-7,84,8,minecraft:diorite)
B(-7,85,8,minecraft:diorite)
B(-7,86,8,minecraft:diorite)
B(-7,87,8,minecraft:diorite)
B(-7,88,8,minecraft:diorite)
B(-7,89,8,minecraft:diorite)
B(-7,90,8,minecraft:diorite)
B(-6,15,-7,minecraft:diorite)
B(-6,16,-7,minecraft:diorite)
B(-6,17,-7,minecraft:diorite)
B(-6,18,-7,minecraft:diorite)
B(-6,19,-7,minecraft:diorite)
B(-6,20,-7,minecraft:diorite)
B(-6,21,-7,minecraft:obsidian)
B(-6,22,-7,minecraft:obsidian)
B(-6,23,-7,minecraft:obsidian)
B(-6,24,-7,minecraft:obsidian)
B(-6,25,-7,minecraft:obsidian)
B(-6,26,-7,minecraft:obsidian)
B(-6,27,-7,minecraft:obsidian)
B(-6,28,-7,minecraft:obsidian)
B(-6,29,-7,minecraft:diorite)
B(-6,30,-7,minecraft:diorite)
B(-6,31,-7,minecraft:diorite)
B(-6,32,-7,minecraft:diorite)
B(-6,46,-7,minecraft:obsidian)
B(-6,47,-7,minecraft:obsidian)
B(-6,48,-7,minecraft:obsidian)
B(-6,49,-7,minecraft:obsidian)
B(-6,50,-7,minecraft:obsidian)
B(-6,51,-7,minecraft:obsidian)
B(-6,52,-7,minecraft:obsidian)
B(-6,53,-7,minecraft:obsidian)
B(-6,64,-7,minecraft:obsidian)
B(-6,65,-7,minecraft:obsidian)
B(-6,66,-7,minecraft:obsidian)
B(-6,67,-7,minecraft:obsidian)
B(-6,68,-7,minecraft:obsidian)
B(-6,69,-7,minecraft:obsidian)
B(-6,70,-7,minecraft:obsidian)
B(-6,71,-7,minecraft:obsidian)
B(-6,72,-7,minecraft:obsidian)
B(-6,73,-7,minecraft:obsidian)
B(-6,74,-7,minecraft:obsidian)
B(-6,75,-7,minecraft:obsidian)
B(-6,76,-7,minecraft:obsidian)
B(-6,77,-7,minecraft:obsidian)
B(-6,78,-7,minecraft:obsidian)
B(-6,79,-7,minecraft:obsidian)
B(-6,80,-7,minecraft:obsidian)
B(-6,81,-7,minecraft:obsidian)
B(-6,82,-7,minecraft:obsidian)
B(-6,83,-7,minecraft:obsidian)
B(-6,84,-7,minecraft:obsidian)
B(-6,85,-7,minecraft:obsidian)
B(-6,86,-7,minecraft:obsidian)
B(-6,87,-7,minecraft:obsidian)
B(-6,88,-7,minecraft:obsidian)
B(-6,89,-7,minecraft:obsidian)
B(-6,90,-7,minecraft:obsidian)
B(-6,91,-7,minecraft:obsidian)
B(-6,92,-7,minecraft:obsidian)
B(-6,93,-7,minecraft:obsidian)
B(-6,94,-7,minecraft:obsidian)
B(-6,95,-7,minecraft:obsidian)
B(-6,96,-7,minecraft:diorite)
B(-6,97,-7,minecraft:diorite)
B(-6,15,-6,minecraft:diorite)
B(-6,16,-6,minecraft:diorite)
B(-6,17,-6,minecraft:diorite)
B(-6,18,-6,minecraft:diorite)
B(-6,19,-6,minecraft:diorite)
B(-6,20,-6,minecraft:diorite)
B(-6,21,-6,minecraft:obsidian)
B(-6,22,-6,minecraft:obsidian)
B(-6,23,-6,minecraft:obsidian)
B(-6,24,-6,minecraft:obsidian)
B(-6,25,-6,minecraft:obsidian)
B(-6,26,-6,minecraft:obsidian)
B(-6,27,-6,minecraft:obsidian)
B(-6,28,-6,minecraft:diorite)
B(-6,29,-6,minecraft:diorite)
B(-6,30,-6,minecraft:diorite)
B(-6,31,-6,minecraft:diorite)
B(-6,49,-6,minecraft:obsidian)
B(-6,50,-6,minecraft:obsidian)
B(-6,65,-6,minecraft:obsidian)
B(-6,66,-6,minecraft:obsidian)
B(-6,67,-6,minecraft:obsidian)
B(-6,68,-6,minecraft:obsidian)
B(-6,69,-6,minecraft:obsidian)
B(-6,70,-6,minecraft:obsidian)
B(-6,71,-6,minecraft:obsidian)
B(-6,72,-6,minecraft:obsidian)
B(-6,73,-6,minecraft:obsidian)
B(-6,74,-6,minecraft:obsidian)
B(-6,75,-6,minecraft:obsidian)
B(-6,76,-6,minecraft:obsidian)
B(-6,77,-6,minecraft:obsidian)
B(-6,78,-6,minecraft:obsidian)
B(-6,79,-6,minecraft:obsidian)
B(-6,80,-6,minecraft:obsidian)
B(-6,81,-6,minecraft:obsidian)
B(-6,82,-6,minecraft:obsidian)
B(-6,83,-6,minecraft:obsidian)
B(-6,84,-6,minecraft:obsidian)
B(-6,85,-6,minecraft:obsidian)
B(-6,86,-6,minecraft:obsidian)
B(-6,87,-6,minecraft:obsidian)
B(-6,88,-6,minecraft:obsidian)
B(-6,89,-6,minecraft:obsidian)
B(-6,90,-6,minecraft:obsidian)
B(-6,91,-6,minecraft:obsidian)
B(-6,92,-6,minecraft:obsidian)
B(-6,93,-6,minecraft:obsidian)
B(-6,94,-6,minecraft:obsidian)
B(-6,95,-6,minecraft:obsidian)
B(-6,96,-6,minecraft:diorite)
B(-6,97,-6,minecraft:diorite)
B(-6,15,-5,minecraft:diorite)
B(-6,16,-5,minecraft:diorite)
B(-6,17,-5,minecraft:diorite)
B(-6,18,-5,minecraft:diorite)
B(-6,19,-5,minecraft:diorite)
B(-6,20,-5,minecraft:diorite)
B(-6,21,-5,minecraft:obsidian)
B(-6,22,-5,minecraft:obsidian)
B(-6,23,-5,minecraft:obsidian)
B(-6,24,-5,minecraft:obsidian)
B(-6,25,-5,minecraft:obsidian)
B(-6,26,-5,minecraft:obsidian)
B(-6,27,-5,minecraft:obsidian)
B(-6,28,-5,minecraft:diorite)
B(-6,29,-5,minecraft:diorite)
B(-6,30,-5,minecraft:diorite)
B(-6,71,-5,minecraft:obsidian)
B(-6,72,-5,minecraft:obsidian)
B(-6,73,-5,minecraft:obsidian)
B(-6,74,-5,minecraft:obsidian)
B(-6,75,-5,minecraft:obsidian)
B(-6,76,-5,minecraft:obsidian)
B(-6,77,-5,minecraft:obsidian)
B(-6,78,-5,minecraft:obsidian)
B(-6,79,-5,minecraft:obsidian)
B(-6,80,-5,minecraft:obsidian)
B(-6,81,-5,minecraft:obsidian)
B(-6,82,-5,minecraft:obsidian)
B(-6,83,-5,minecraft:obsidian)
B(-6,84,-5,minecraft:obsidian)
B(-6,85,-5,minecraft:obsidian)
B(-6,86,-5,minecraft:obsidian)
B(-6,87,-5,minecraft:obsidian)
B(-6,88,-5,minecraft:obsidian)
B(-6,89,-5,minecraft:obsidian)
B(-6,90,-5,minecraft:obsidian)
B(-6,91,-5,minecraft:obsidian)
B(-6,92,-5,minecraft:obsidian)
B(-6,93,-5,minecraft:obsidian)
B(-6,94,-5,minecraft:obsidian)
B(-6,95,-5,minecraft:obsidian)
B(-6,96,-5,minecraft:diorite)
B(-6,97,-5,minecraft:diorite)
B(-6,15,-4,minecraft:diorite)
B(-6,16,-4,minecraft:diorite)
B(-6,17,-4,minecraft:diorite)
B(-6,18,-4,minecraft:diorite)
B(-6,19,-4,minecraft:diorite)
B(-6,20,-4,minecraft:diorite)
B(-6,21,-4,minecraft:obsidian)
B(-6,22,-4,minecraft:obsidian)
B(-6,23,-4,minecraft:obsidian)
B(-6,24,-4,minecraft:obsidian)
B(-6,25,-4,minecraft:obsidian)
B(-6,26,-4,minecraft:obsidian)
B(-6,27,-4,minecraft:obsidian)
B(-6,28,-4,minecraft:diorite)
B(-6,29,-4,minecraft:diorite)
B(-6,74,-4,minecraft:obsidian)
B(-6,75,-4,minecraft:obsidian)
B(-6,76,-4,minecraft:obsidian)
B(-6,77,-4,minecraft:obsidian)
B(-6,78,-4,minecraft:obsidian)
B(-6,79,-4,minecraft:obsidian)
B(-6,80,-4,minecraft:obsidian)
B(-6,81,-4,minecraft:obsidian)
B(-6,82,-4,minecraft:obsidian)
B(-6,83,-4,minecraft:obsidian)
B(-6,84,-4,minecraft:obsidian)
B(-6,85,-4,minecraft:obsidian)
B(-6,86,-4,minecraft:obsidian)
B(-6,87,-4,minecraft:obsidian)
B(-6,88,-4,minecraft:obsidian)
B(-6,89,-4,minecraft:obsidian)
B(-6,90,-4,minecraft:obsidian)
B(-6,91,-4,minecraft:obsidian)
B(-6,92,-4,minecraft:obsidian)
B(-6,93,-4,minecraft:obsidian)
B(-6,94,-4,minecraft:obsidian)
B(-6,95,-4,minecraft:diorite)
B(-6,96,-4,minecraft:andesite)
B(-6,15,-3,minecraft:diorite)
B(-6,16,-3,minecraft:diorite)
B(-6,17,-3,minecraft:diorite)
B(-6,18,-3,minecraft:diorite)
B(-6,19,-3,minecraft:diorite)
B(-6,20,-3,minecraft:diorite)
B(-6,21,-3,minecraft:obsidian)
B(-6,22,-3,minecraft:obsidian)
B(-6,23,-3,minecraft:obsidian)
B(-6,24,-3,minecraft:obsidian)
B(-6,25,-3,minecraft:obsidian)
B(-6,26,-3,minecraft:obsidian)
B(-6,27,-3,minecraft:obsidian)
B(-6,28,-3,minecraft:obsidian)
B(-6,75,-3,minecraft:obsidian)
B(-6,76,-3,minecraft:obsidian)
B(-6,77,-3,minecraft:obsidian)
B(-6,78,-3,minecraft:obsidian)
B(-6,79,-3,minecraft:obsidian)
B(-6,80,-3,minecraft:obsidian)
B(-6,81,-3,minecraft:obsidian)
B(-6,82,-3,minecraft:obsidian)
B(-6,83,-3,minecraft:obsidian)
B(-6,84,-3,minecraft:obsidian)
B(-6,85,-3,minecraft:obsidian)
B(-6,86,-3,minecraft:obsidian)
B(-6,87,-3,minecraft:obsidian)
B(-6,88,-3,minecraft:obsidian)
B(-6,89,-3,minecraft:obsidian)
B(-6,90,-3,minecraft:obsidian)
B(-6,91,-3,minecraft:obsidian)
B(-6,92,-3,minecraft:obsidian)
B(-6,93,-3,minecraft:obsidian)
B(-6,94,-3,minecraft:obsidian)
B(-6,95,-3,minecraft:diorite)
B(-6,96,-3,minecraft:andesite)
B(-6,14,-2,minecraft:diorite)
B(-6,15,-2,minecraft:diorite)
B(-6,16,-2,minecraft:diorite)
B(-6,17,-2,minecraft:diorite)
B(-6,18,-2,minecraft:diorite)
B(-6,19,-2,minecraft:diorite)
B(-6,20,-2,minecraft:obsidian)
B(-6,21,-2,minecraft:obsidian)
B(-6,22,-2,minecraft:obsidian)
B(-6,23,-2,minecraft:obsidian)
B(-6,24,-2,minecraft:obsidian)
B(-6,25,-2,minecraft:obsidian)
B(-6,26,-2,minecraft:obsidian)
B(-6,27,-2,minecraft:obsidian)
B(-6,28,-2,minecraft:obsidian)
B(-6,75,-2,minecraft:obsidian)
B(-6,76,-2,minecraft:obsidian)
B(-6,77,-2,minecraft:obsidian)
B(-6,78,-2,minecraft:obsidian)
B(-6,79,-2,minecraft:obsidian)
B(-6,80,-2,minecraft:obsidian)
B(-6,81,-2,minecraft:obsidian)
B(-6,82,-2,minecraft:obsidian)
B(-6,83,-2,minecraft:obsidian)
B(-6,84,-2,minecraft:obsidian)
B(-6,85,-2,minecraft:obsidian)
B(-6,86,-2,minecraft:obsidian)
B(-6,87,-2,minecraft:obsidian)
B(-6,88,-2,minecraft:obsidian)
B(-6,89,-2,minecraft:obsidian)
B(-6,90,-2,minecraft:obsidian)
B(-6,91,-2,minecraft:obsidian)
B(-6,92,-2,minecraft:obsidian)
B(-6,93,-2,minecraft:obsidian)
B(-6,94,-2,minecraft:obsidian)
B(-6,95,-2,minecraft:diorite)
B(-6,96,-2,minecraft:andesite)
B(-6,13,-1,minecraft:diorite)
B(-6,14,-1,minecraft:diorite)
B(-6,15,-1,minecraft:diorite)
B(-6,16,-1,minecraft:diorite)
B(-6,17,-1,minecraft:diorite)
B(-6,18,-1,minecraft:diorite)
B(-6,19,-1,minecraft:diorite)
B(-6,20,-1,minecraft:obsidian)
B(-6,21,-1,minecraft:obsidian)
B(-6,22,-1,minecraft:obsidian)
B(-6,23,-1,minecraft:obsidian)
B(-6,24,-1,minecraft:obsidian)
B(-6,25,-1,minecraft:obsidian)
B(-6,26,-1,minecraft:obsidian)
B(-6,27,-1,minecraft:diorite)
B(-6,28,-1,minecraft:diorite)
B(-6,74,-1,minecraft:obsidian)
B(-6,75,-1,minecraft:obsidian)
B(-6,76,-1,minecraft:obsidian)
B(-6,77,-1,minecraft:obsidian)
B(-6,78,-1,minecraft:obsidian)
B(-6,79,-1,minecraft:obsidian)
B(-6,80,-1,minecraft:obsidian)
B(-6,81,-1,minecraft:obsidian)
B(-6,82,-1,minecraft:obsidian)
B(-6,83,-1,minecraft:obsidian)
B(-6,84,-1,minecraft:obsidian)
B(-6,85,-1,minecraft:obsidian)
B(-6,86,-1,minecraft:obsidian)
B(-6,87,-1,minecraft:obsidian)
B(-6,88,-1,minecraft:obsidian)
B(-6,89,-1,minecraft:obsidian)
B(-6,90,-1,minecraft:obsidian)
B(-6,91,-1,minecraft:obsidian)
B(-6,92,-1,minecraft:obsidian)
B(-6,93,-1,minecraft:obsidian)
B(-6,94,-1,minecraft:obsidian)
B(-6,95,-1,minecraft:diorite)
B(-6,96,-1,minecraft:andesite)
B(-6,13,0,minecraft:diorite)
B(-6,14,0,minecraft:diorite)
B(-6,15,0,minecraft:diorite)
B(-6,16,0,minecraft:diorite)
B(-6,17,0,minecraft:diorite)
B(-6,18,0,minecraft:diorite)
B(-6,19,0,minecraft:diorite)
B(-6,20,0,minecraft:obsidian)
B(-6,21,0,minecraft:obsidian)
B(-6,22,0,minecraft:obsidian)
B(-6,23,0,minecraft:obsidian)
B(-6,24,0,minecraft:obsidian)
B(-6,25,0,minecraft:obsidian)
B(-6,26,0,minecraft:diorite)
B(-6,27,0,minecraft:diorite)
B(-6,73,0,minecraft:obsidian)
B(-6,74,0,minecraft:obsidian)
B(-6,75,0,minecraft:obsidian)
B(-6,76,0,minecraft:obsidian)
B(-6,77,0,minecraft:obsidian)
B(-6,78,0,minecraft:obsidian)
B(-6,79,0,minecraft:obsidian)
B(-6,80,0,minecraft:obsidian)
B(-6,81,0,minecraft:obsidian)
B(-6,82,0,minecraft:obsidian)
B(-6,83,0,minecraft:obsidian)
B(-6,84,0,minecraft:obsidian)
B(-6,85,0,minecraft:obsidian)
B(-6,86,0,minecraft:obsidian)
B(-6,87,0,minecraft:obsidian)
B(-6,88,0,minecraft:obsidian)
B(-6,89,0,minecraft:obsidian)
B(-6,90,0,minecraft:obsidian)
B(-6,91,0,minecraft:obsidian)
B(-6,92,0,minecraft:obsidian)
B(-6,93,0,minecraft:obsidian)
B(-6,94,0,minecraft:diorite)
B(-6,95,0,minecraft:andesite)
B(-6,12,1,minecraft:diorite)
B(-6,13,1,minecraft:diorite)
B(-6,14,1,minecraft:diorite)
B(-6,15,1,minecraft:diorite)
B(-6,16,1,minecraft:diorite)
B(-6,17,1,minecraft:diorite)
B(-6,18,1,minecraft:diorite)
B(-6,19,1,minecraft:diorite)
B(-6,20,1,minecraft:obsidian)
B(-6,21,1,minecraft:obsidian)
B(-6,22,1,minecraft:obsidian)
B(-6,23,1,minecraft:obsidian)
B(-6,24,1,minecraft:obsidian)
B(-6,25,1,minecraft:diorite)
B(-6,26,1,minecraft:diorite)
B(-6,72,1,minecraft:obsidian)
B(-6,73,1,minecraft:obsidian)
B(-6,74,1,minecraft:obsidian)
B(-6,75,1,minecraft:obsidian)
B(-6,76,1,minecraft:obsidian)
B(-6,77,1,minecraft:obsidian)
B(-6,78,1,minecraft:obsidian)
B(-6,79,1,minecraft:obsidian)
B(-6,80,1,minecraft:obsidian)
B(-6,81,1,minecraft:obsidian)
B(-6,82,1,minecraft:obsidian)
B(-6,83,1,minecraft:obsidian)
B(-6,84,1,minecraft:obsidian)
B(-6,85,1,minecraft:obsidian)
B(-6,86,1,minecraft:obsidian)
B(-6,87,1,minecraft:obsidian)
B(-6,88,1,minecraft:obsidian)
B(-6,89,1,minecraft:obsidian)
B(-6,90,1,minecraft:obsidian)
B(-6,91,1,minecraft:obsidian)
B(-6,92,1,minecraft:obsidian)
B(-6,93,1,minecraft:diorite)
B(-6,94,1,minecraft:andesite)
B(-6,11,2,minecraft:diorite)
B(-6,12,2,minecraft:diorite)
B(-6,13,2,minecraft:diorite)
B(-6,14,2,minecraft:diorite)
B(-6,15,2,minecraft:diorite)
B(-6,16,2,minecraft:diorite)
B(-6,17,2,minecraft:diorite)
B(-6,18,2,minecraft:diorite)
B(-6,19,2,minecraft:obsidian)
B(-6,20,2,minecraft:obsidian)
B(-6,21,2,minecraft:obsidian)
B(-6,22,2,minecraft:obsidian)
B(-6,23,2,minecraft:obsidian)
B(-6,24,2,minecraft:obsidian)
B(-6,25,2,minecraft:diorite)
B(-6,26,2,minecraft:diorite)
B(-6,27,2,minecraft:diorite)
B(-6,71,2,minecraft:obsidian)
B(-6,72,2,minecraft:obsidian)
B(-6,73,2,minecraft:obsidian)
B(-6,74,2,minecraft:obsidian)
B(-6,75,2,minecraft:obsidian)
B(-6,76,2,minecraft:obsidian)
B(-6,77,2,minecraft:obsidian)
B(-6,78,2,minecraft:obsidian)
B(-6,79,2,minecraft:obsidian)
B(-6,80,2,minecraft:obsidian)
B(-6,81,2,minecraft:obsidian)
B(-6,82,2,minecraft:obsidian)
B(-6,83,2,minecraft:obsidian)
B(-6,84,2,minecraft:obsidian)
B(-6,85,2,minecraft:obsidian)
B(-6,86,2,minecraft:obsidian)
B(-6,87,2,minecraft:obsidian)
B(-6,88,2,minecraft:obsidian)
B(-6,89,2,minecraft:obsidian)
B(-6,90,2,minecraft:obsidian)
B(-6,91,2,minecraft:obsidian)
B(-6,92,2,minecraft:diorite)
B(-6,93,2,minecraft:andesite)
B(-6,11,3,minecraft:diorite)
B(-6,12,3,minecraft:diorite)
B(-6,13,3,minecraft:diorite)
B(-6,14,3,minecraft:diorite)
B(-6,15,3,minecraft:diorite)
B(-6,16,3,minecraft:diorite)
B(-6,17,3,minecraft:diorite)
B(-6,18,3,minecraft:obsidian)
B(-6,19,3,minecraft:obsidian)
B(-6,20,3,minecraft:obsidian)
B(-6,21,3,minecraft:obsidian)
B(-6,22,3,minecraft:obsidian)
B(-6,23,3,minecraft:obsidian)
B(-6,24,3,minecraft:obsidian)
B(-6,25,3,minecraft:diorite)
B(-6,26,3,minecraft:diorite)
B(-6,27,3,minecraft:diorite)
B(-6,70,3,minecraft:obsidian)
B(-6,71,3,minecraft:obsidian)
B(-6,72,3,minecraft:obsidian)
B(-6,73,3,minecraft:obsidian)
B(-6,74,3,minecraft:obsidian)
B(-6,75,3,minecraft:obsidian)
B(-6,76,3,minecraft:obsidian)
B(-6,77,3,minecraft:obsidian)
B(-6,78,3,minecraft:obsidian)
B(-6,79,3,minecraft:obsidian)
B(-6,80,3,minecraft:obsidian)
B(-6,81,3,minecraft:obsidian)
B(-6,82,3,minecraft:obsidian)
B(-6,83,3,minecraft:obsidian)
B(-6,84,3,minecraft:obsidian)
B(-6,85,3,minecraft:obsidian)
B(-6,86,3,minecraft:obsidian)
B(-6,87,3,minecraft:obsidian)
B(-6,88,3,minecraft:obsidian)
B(-6,89,3,minecraft:obsidian)
B(-6,90,3,minecraft:obsidian)
B(-6,91,3,minecraft:diorite)
B(-6,92,3,minecraft:andesite)
B(-6,11,4,minecraft:diorite)
B(-6,12,4,minecraft:diorite)
B(-6,13,4,minecraft:diorite)
B(-6,14,4,minecraft:diorite)
B(-6,15,4,minecraft:diorite)
B(-6,16,4,minecraft:diorite)
B(-6,17,4,minecraft:obsidian)
B(-6,18,4,minecraft:obsidian)
B(-6,19,4,minecraft:obsidian)
B(-6,20,4,minecraft:obsidian)
B(-6,21,4,minecraft:obsidian)
B(-6,22,4,minecraft:obsidian)
B(-6,23,4,minecraft:obsidian)
B(-6,24,4,minecraft:obsidian)
B(-6,25,4,minecraft:diorite)
B(-6,26,4,minecraft:diorite)
B(-6,69,4,minecraft:obsidian)
B(-6,70,4,minecraft:obsidian)
B(-6,71,4,minecraft:obsidian)
B(-6,72,4,minecraft:obsidian)
B(-6,73,4,minecraft:obsidian)
B(-6,74,4,minecraft:obsidian)
B(-6,75,4,minecraft:obsidian)
B(-6,76,4,minecraft:obsidian)
B(-6,77,4,minecraft:obsidian)
B(-6,78,4,minecraft:obsidian)
B(-6,79,4,minecraft:obsidian)
B(-6,80,4,minecraft:obsidian)
B(-6,81,4,minecraft:obsidian)
B(-6,82,4,minecraft:obsidian)
B(-6,83,4,minecraft:obsidian)
B(-6,84,4,minecraft:obsidian)
B(-6,85,4,minecraft:obsidian)
B(-6,86,4,minecraft:obsidian)
B(-6,87,4,minecraft:obsidian)
B(-6,88,4,minecraft:obsidian)
B(-6,89,4,minecraft:obsidian)
B(-6,90,4,minecraft:diorite)
B(-6,91,4,minecraft:andesite)
B(-6,10,5,minecraft:diorite)
B(-6,11,5,minecraft:diorite)
B(-6,12,5,minecraft:diorite)
B(-6,13,5,minecraft:diorite)
B(-6,14,5,minecraft:diorite)
B(-6,15,5,minecraft:diorite)
B(-6,16,5,minecraft:obsidian)
B(-6,17,5,minecraft:obsidian)
B(-6,18,5,minecraft:obsidian)
B(-6,19,5,minecraft:obsidian)
B(-6,20,5,minecraft:obsidian)
B(-6,21,5,minecraft:obsidian)
B(-6,22,5,minecraft:obsidian)
B(-6,23,5,minecraft:obsidian)
B(-6,24,5,minecraft:obsidian)
B(-6,25,5,minecraft:diorite)
B(-6,26,5,minecraft:diorite)
B(-6,69,5,minecraft:obsidian)
B(-6,70,5,minecraft:obsidian)
B(-6,71,5,minecraft:obsidian)
B(-6,72,5,minecraft:obsidian)
B(-6,73,5,minecraft:obsidian)
B(-6,74,5,minecraft:obsidian)
B(-6,75,5,minecraft:obsidian)
B(-6,76,5,minecraft:obsidian)
B(-6,77,5,minecraft:obsidian)
B(-6,78,5,minecraft:obsidian)
B(-6,79,5,minecraft:obsidian)
B(-6,80,5,minecraft:obsidian)
B(-6,81,5,minecraft:obsidian)
B(-6,82,5,minecraft:obsidian)
B(-6,83,5,minecraft:obsidian)
B(-6,84,5,minecraft:obsidian)
B(-6,85,5,minecraft:obsidian)
B(-6,86,5,minecraft:diorite)
B(-6,87,5,minecraft:diorite)
B(-6,88,5,minecraft:diorite)
B(-6,89,5,minecraft:diorite)
B(-6,90,5,minecraft:diorite)
B(-6,91,5,minecraft:andesite)
B(-6,10,6,minecraft:diorite)
B(-6,11,6,minecraft:diorite)
B(-6,12,6,minecraft:diorite)
B(-6,13,6,minecraft:diorite)
B(-6,14,6,minecraft:diorite)
B(-6,15,6,minecraft:diorite)
B(-6,16,6,minecraft:obsidian)
B(-6,17,6,minecraft:obsidian)
B(-6,18,6,minecraft:obsidian)
B(-6,19,6,minecraft:obsidian)
B(-6,20,6,minecraft:obsidian)
B(-6,21,6,minecraft:obsidian)
B(-6,22,6,minecraft:obsidian)
B(-6,23,6,minecraft:obsidian)
B(-6,24,6,minecraft:obsidian)
B(-6,25,6,minecraft:diorite)
B(-6,26,6,minecraft:diorite)
B(-6,27,6,minecraft:diorite)
B(-6,69,6,minecraft:obsidian)
B(-6,70,6,minecraft:obsidian)
B(-6,71,6,minecraft:obsidian)
B(-6,72,6,minecraft:obsidian)
B(-6,73,6,minecraft:obsidian)
B(-6,74,6,minecraft:obsidian)
B(-6,75,6,minecraft:obsidian)
B(-6,76,6,minecraft:obsidian)
B(-6,77,6,minecraft:obsidian)
B(-6,78,6,minecraft:obsidian)
B(-6,79,6,minecraft:obsidian)
B(-6,80,6,minecraft:obsidian)
B(-6,81,6,minecraft:obsidian)
B(-6,82,6,minecraft:obsidian)
B(-6,83,6,minecraft:obsidian)
B(-6,84,6,minecraft:obsidian)
B(-6,85,6,minecraft:diorite)
B(-6,86,6,minecraft:diorite)
B(-6,87,6,minecraft:diorite)
B(-6,88,6,minecraft:diorite)
B(-6,89,6,minecraft:diorite)
B(-6,90,6,minecraft:andesite)
B(-6,10,7,minecraft:diorite)
B(-6,11,7,minecraft:diorite)
B(-6,12,7,minecraft:diorite)
B(-6,13,7,minecraft:diorite)
B(-6,14,7,minecraft:diorite)
B(-6,15,7,minecraft:diorite)
B(-6,16,7,minecraft:obsidian)
B(-6,17,7,minecraft:obsidian)
B(-6,18,7,minecraft:obsidian)
B(-6,19,7,minecraft:obsidian)
B(-6,20,7,minecraft:obsidian)
B(-6,21,7,minecraft:obsidian)
B(-6,22,7,minecraft:obsidian)
B(-6,23,7,minecraft:obsidian)
B(-6,24,7,minecraft:obsidian)
B(-6,25,7,minecraft:diorite)
B(-6,26,7,minecraft:diorite)
B(-6,27,7,minecraft:diorite)
B(-6,28,7,minecraft:diorite)
B(-6,70,7,minecraft:obsidian)
B(-6,71,7,minecraft:obsidian)
B(-6,72,7,minecraft:obsidian)
B(-6,73,7,minecraft:obsidian)
B(-6,74,7,minecraft:obsidian)
B(-6,75,7,minecraft:obsidian)
B(-6,76,7,minecraft:obsidian)
B(-6,77,7,minecraft:obsidian)
B(-6,78,7,minecraft:obsidian)
B(-6,79,7,minecraft:obsidian)
B(-6,80,7,minecraft:obsidian)
B(-6,81,7,minecraft:obsidian)
B(-6,82,7,minecraft:obsidian)
B(-6,83,7,minecraft:obsidian)
B(-6,84,7,minecraft:diorite)
B(-6,85,7,minecraft:diorite)
B(-6,86,7,minecraft:diorite)
B(-6,87,7,minecraft:diorite)
B(-6,88,7,minecraft:diorite)
B(-6,89,7,minecraft:diorite)
B(-6,90,7,minecraft:andesite)
B(-6,10,8,minecraft:diorite)
B(-6,11,8,minecraft:diorite)
B(-6,12,8,minecraft:diorite)
B(-6,13,8,minecraft:diorite)
B(-6,14,8,minecraft:diorite)
B(-6,15,8,minecraft:obsidian)
B(-6,16,8,minecraft:obsidian)
B(-6,17,8,minecraft:obsidian)
B(-6,18,8,minecraft:obsidian)
B(-6,19,8,minecraft:obsidian)
B(-6,20,8,minecraft:obsidian)
B(-6,21,8,minecraft:obsidian)
B(-6,22,8,minecraft:obsidian)
B(-6,23,8,minecraft:obsidian)
B(-6,24,8,minecraft:obsidian)
B(-6,25,8,minecraft:diorite)
B(-6,26,8,minecraft:diorite)
B(-6,27,8,minecraft:diorite)
B(-6,28,8,minecraft:diorite)
B(-6,29,8,minecraft:diorite)
B(-6,69,8,minecraft:obsidian)
B(-6,70,8,minecraft:obsidian)
B(-6,71,8,minecraft:obsidian)
B(-6,72,8,minecraft:obsidian)
B(-6,73,8,minecraft:obsidian)
B(-6,74,8,minecraft:obsidian)
B(-6,75,8,minecraft:obsidian)
B(-6,76,8,minecraft:obsidian)
B(-6,77,8,minecraft:obsidian)
B(-6,78,8,minecraft:obsidian)
B(-6,79,8,minecraft:obsidian)
B(-6,80,8,minecraft:obsidian)
B(-6,81,8,minecraft:obsidian)
B(-6,82,8,minecraft:obsidian)
B(-6,83,8,minecraft:diorite)
B(-6,84,8,minecraft:diorite)
B(-6,85,8,minecraft:diorite)
B(-6,86,8,minecraft:diorite)
B(-6,87,8,minecraft:diorite)
B(-6,88,8,minecraft:diorite)
B(-6,89,8,minecraft:diorite)
B(-6,90,8,minecraft:diorite)
B(-5,15,-7,minecraft:diorite)
B(-5,16,-7,minecraft:diorite)
B(-5,17,-7,minecraft:diorite)
B(-5,18,-7,minecraft:diorite)
B(-5,19,-7,minecraft:diorite)
B(-5,20,-7,minecraft:diorite)
B(-5,21,-7,minecraft:obsidian)
B(-5,22,-7,minecraft:obsidian)
B(-5,23,-7,minecraft:obsidian)
B(-5,24,-7,minecraft:obsidian)
B(-5,25,-7,minecraft:obsidian)
B(-5,26,-7,minecraft:obsidian)
B(-5,27,-7,minecraft:obsidian)
B(-5,28,-7,minecraft:obsidian)
B(-5,29,-7,minecraft:diorite)
B(-5,30,-7,minecraft:diorite)
B(-5,31,-7,minecraft:diorite)
B(-5,47,-7,minecraft:obsidian)
B(-5,48,-7,minecraft:obsidian)
B(-5,49,-7,minecraft:obsidian)
B(-5,50,-7,minecraft:obsidian)
B(-5,51,-7,minecraft:obsidian)
B(-5,52,-7,minecraft:obsidian)
B(-5,53,-7,minecraft:obsidian)
B(-5,63,-7,minecraft:obsidian)
B(-5,64,-7,minecraft:obsidian)
B(-5,65,-7,minecraft:obsidian)
B(-5,66,-7,minecraft:obsidian)
B(-5,67,-7,minecraft:obsidian)
B(-5,68,-7,minecraft:obsidian)
B(-5,69,-7,minecraft:obsidian)
B(-5,70,-7,minecraft:obsidian)
B(-5,71,-7,minecraft:obsidian)
B(-5,72,-7,minecraft:obsidian)
B(-5,73,-7,minecraft:obsidian)
B(-5,74,-7,minecraft:obsidian)
B(-5,75,-7,minecraft:obsidian)
B(-5,76,-7,minecraft:obsidian)
B(-5,77,-7,minecraft:obsidian)
B(-5,78,-7,minecraft:obsidian)
B(-5,79,-7,minecraft:obsidian)
B(-5,80,-7,minecraft:obsidian)
B(-5,81,-7,minecraft:obsidian)
B(-5,82,-7,minecraft:obsidian)
B(-5,83,-7,minecraft:obsidian)
B(-5,84,-7,minecraft:obsidian)
B(-5,85,-7,minecraft:obsidian)
B(-5,86,-7,minecraft:obsidian)
B(-5,87,-7,minecraft:obsidian)
B(-5,88,-7,minecraft:obsidian)
B(-5,89,-7,minecraft:obsidian)
B(-5,90,-7,minecraft:obsidian)
B(-5,91,-7,minecraft:obsidian)
B(-5,92,-7,minecraft:obsidian)
B(-5,93,-7,minecraft:obsidian)
B(-5,94,-7,minecraft:obsidian)
B(-5,95,-7,minecraft:obsidian)
B(-5,96,-7,minecraft:diorite)
B(-5,97,-7,minecraft:diorite)
B(-5,15,-6,minecraft:diorite)
B(-5,16,-6,minecraft:diorite)
B(-5,17,-6,minecraft:diorite)
B(-5,18,-6,minecraft:diorite)
B(-5,19,-6,minecraft:diorite)
B(-5,20,-6,minecraft:diorite)
B(-5,21,-6,minecraft:obsidian)
B(-5,22,-6,minecraft:obsidian)
B(-5,23,-6,minecraft:obsidian)
B(-5,24,-6,minecraft:obsidian)
B(-5,25,-6,minecraft:obsidian)
B(-5,26,-6,minecraft:obsidian)
B(-5,27,-6,minecraft:obsidian)
B(-5,28,-6,minecraft:obsidian)
B(-5,29,-6,minecraft:diorite)
B(-5,30,-6,minecraft:diorite)
B(-5,65,-6,minecraft:obsidian)
B(-5,66,-6,minecraft:obsidian)
B(-5,67,-6,minecraft:obsidian)
B(-5,68,-6,minecraft:obsidian)
B(-5,69,-6,minecraft:obsidian)
B(-5,70,-6,minecraft:obsidian)
B(-5,71,-6,minecraft:obsidian)
B(-5,72,-6,minecraft:obsidian)
B(-5,73,-6,minecraft:obsidian)
B(-5,74,-6,minecraft:obsidian)
B(-5,75,-6,minecraft:obsidian)
B(-5,76,-6,minecraft:obsidian)
B(-5,77,-6,minecraft:obsidian)
B(-5,78,-6,minecraft:obsidian)
B(-5,79,-6,minecraft:obsidian)
B(-5,80,-6,minecraft:obsidian)
B(-5,81,-6,minecraft:obsidian)
B(-5,82,-6,minecraft:obsidian)
B(-5,83,-6,minecraft:obsidian)
B(-5,84,-6,minecraft:obsidian)
B(-5,85,-6,minecraft:obsidian)
B(-5,86,-6,minecraft:obsidian)
B(-5,87,-6,minecraft:obsidian)
B(-5,88,-6,minecraft:obsidian)
B(-5,89,-6,minecraft:obsidian)
B(-5,90,-6,minecraft:obsidian)
B(-5,91,-6,minecraft:obsidian)
B(-5,92,-6,minecraft:obsidian)
B(-5,93,-6,minecraft:obsidian)
B(-5,94,-6,minecraft:obsidian)
B(-5,95,-6,minecraft:obsidian)
B(-5,96,-6,minecraft:diorite)
B(-5,97,-6,minecraft:diorite)
B(-5,15,-5,minecraft:diorite)
B(-5,16,-5,minecraft:diorite)
B(-5,17,-5,minecraft:diorite)
B(-5,18,-5,minecraft:diorite)
B(-5,19,-5,minecraft:diorite)
B(-5,20,-5,minecraft:diorite)
B(-5,21,-5,minecraft:obsidian)
B(-5,22,-5,minecraft:obsidian)
B(-5,23,-5,minecraft:obsidian)
B(-5,24,-5,minecraft:obsidian)
B(-5,25,-5,minecraft:obsidian)
B(-5,26,-5,minecraft:obsidian)
B(-5,27,-5,minecraft:obsidian)
B(-5,28,-5,minecraft:obsidian)
B(-5,29,-5,minecraft:obsidian)
B(-5,72,-5,minecraft:obsidian)
B(-5,73,-5,minecraft:obsidian)
B(-5,74,-5,minecraft:obsidian)
B(-5,75,-5,minecraft:obsidian)
B(-5,76,-5,minecraft:obsidian)
B(-5,77,-5,minecraft:obsidian)
B(-5,78,-5,minecraft:obsidian)
B(-5,79,-5,minecraft:obsidian)
B(-5,80,-5,minecraft:obsidian)
B(-5,81,-5,minecraft:obsidian)
B(-5,82,-5,minecraft:obsidian)
B(-5,83,-5,minecraft:obsidian)
B(-5,84,-5,minecraft:obsidian)
B(-5,85,-5,minecraft:obsidian)
B(-5,86,-5,minecraft:obsidian)
B(-5,87,-5,minecraft:obsidian)
B(-5,88,-5,minecraft:obsidian)
B(-5,89,-5,minecraft:obsidian)
B(-5,90,-5,minecraft:obsidian)
B(-5,91,-5,minecraft:obsidian)
B(-5,92,-5,minecraft:obsidian)
B(-5,93,-5,minecraft:obsidian)
B(-5,94,-5,minecraft:obsidian)
B(-5,95,-5,minecraft:diorite)
B(-5,96,-5,minecraft:andesite)
B(-5,15,-4,minecraft:diorite)
B(-5,16,-4,minecraft:diorite)
B(-5,17,-4,minecraft:diorite)
B(-5,18,-4,minecraft:diorite)
B(-5,19,-4,minecraft:diorite)
B(-5,20,-4,minecraft:diorite)
B(-5,21,-4,minecraft:obsidian)
B(-5,22,-4,minecraft:obsidian)
B(-5,23,-4,minecraft:obsidian)
B(-5,24,-4,minecraft:obsidian)
B(-5,25,-4,minecraft:obsidian)
B(-5,26,-4,minecraft:obsidian)
B(-5,27,-4,minecraft:obsidian)
B(-5,28,-4,minecraft:obsidian)
B(-5,73,-4,minecraft:obsidian)
B(-5,74,-4,minecraft:obsidian)
B(-5,75,-4,minecraft:obsidian)
B(-5,76,-4,minecraft:obsidian)
B(-5,77,-4,minecraft:obsidian)
B(-5,78,-4,minecraft:obsidian)
B(-5,79,-4,minecraft:obsidian)
B(-5,80,-4,minecraft:obsidian)
B(-5,81,-4,minecraft:obsidian)
B(-5,82,-4,minecraft:obsidian)
B(-5,83,-4,minecraft:obsidian)
B(-5,84,-4,minecraft:obsidian)
B(-5,85,-4,minecraft:obsidian)
B(-5,86,-4,minecraft:obsidian)
B(-5,87,-4,minecraft:obsidian)
B(-5,88,-4,minecraft:obsidian)
B(-5,89,-4,minecraft:obsidian)
B(-5,90,-4,minecraft:obsidian)
B(-5,91,-4,minecraft:obsidian)
B(-5,92,-4,minecraft:obsidian)
B(-5,93,-4,minecraft:obsidian)
B(-5,94,-4,minecraft:obsidian)
B(-5,95,-4,minecraft:diorite)
B(-5,96,-4,minecraft:andesite)
B(-5,14,-3,minecraft:diorite)
B(-5,15,-3,minecraft:diorite)
B(-5,16,-3,minecraft:diorite)
B(-5,17,-3,minecraft:diorite)
B(-5,18,-3,minecraft:diorite)
B(-5,19,-3,minecraft:diorite)
B(-5,20,-3,minecraft:diorite)
B(-5,21,-3,minecraft:obsidian)
B(-5,22,-3,minecraft:obsidian)
B(-5,23,-3,minecraft:obsidian)
B(-5,24,-3,minecraft:obsidian)
B(-5,25,-3,minecraft:obsidian)
B(-5,26,-3,minecraft:obsidian)
B(-5,27,-3,minecraft:obsidian)
B(-5,28,-3,minecraft:obsidian)
B(-5,74,-3,minecraft:obsidian)
B(-5,75,-3,minecraft:obsidian)
B(-5,76,-3,minecraft:obsidian)
B(-5,77,-3,minecraft:obsidian)
B(-5,78,-3,minecraft:obsidian)
B(-5,79,-3,minecraft:obsidian)
B(-5,80,-3,minecraft:obsidian)
B(-5,81,-3,minecraft:obsidian)
B(-5,82,-3,minecraft:obsidian)
B(-5,83,-3,minecraft:obsidian)
B(-5,84,-3,minecraft:obsidian)
B(-5,85,-3,minecraft:obsidian)
B(-5,86,-3,minecraft:obsidian)
B(-5,87,-3,minecraft:obsidian)
B(-5,88,-3,minecraft:obsidian)
B(-5,89,-3,minecraft:obsidian)
B(-5,90,-3,minecraft:obsidian)
B(-5,91,-3,minecraft:obsidian)
B(-5,92,-3,minecraft:obsidian)
B(-5,93,-3,minecraft:obsidian)
B(-5,94,-3,minecraft:obsidian)
B(-5,95,-3,minecraft:diorite)
B(-5,96,-3,minecraft:andesite)
B(-5,13,-2,minecraft:diorite)
B(-5,14,-2,minecraft:diorite)
B(-5,15,-2,minecraft:diorite)
B(-5,16,-2,minecraft:diorite)
B(-5,17,-2,minecraft:diorite)
B(-5,18,-2,minecraft:diorite)
B(-5,19,-2,minecraft:diorite)
B(-5,20,-2,minecraft:obsidian)
B(-5,21,-2,minecraft:obsidian)
B(-5,22,-2,minecraft:obsidian)
B(-5,23,-2,minecraft:obsidian)
B(-5,24,-2,minecraft:obsidian)
B(-5,25,-2,minecraft:obsidian)
B(-5,26,-2,minecraft:obsidian)
B(-5,27,-2,minecraft:obsidian)
B(-5,28,-2,minecraft:obsidian)
B(-5,74,-2,minecraft:obsidian)
B(-5,75,-2,minecraft:obsidian)
B(-5,76,-2,minecraft:obsidian)
B(-5,77,-2,minecraft:obsidian)
B(-5,78,-2,minecraft:obsidian)
B(-5,79,-2,minecraft:obsidian)
B(-5,80,-2,minecraft:obsidian)
B(-5,81,-2,minecraft:obsidian)
B(-5,82,-2,minecraft:obsidian)
B(-5,83,-2,minecraft:obsidian)
B(-5,84,-2,minecraft:obsidian)
B(-5,85,-2,minecraft:obsidian)
B(-5,86,-2,minecraft:obsidian)
B(-5,87,-2,minecraft:obsidian)
B(-5,88,-2,minecraft:obsidian)
B(-5,89,-2,minecraft:obsidian)
B(-5,90,-2,minecraft:obsidian)
B(-5,91,-2,minecraft:obsidian)
B(-5,92,-2,minecraft:obsidian)
B(-5,93,-2,minecraft:obsidian)
B(-5,94,-2,minecraft:obsidian)
B(-5,95,-2,minecraft:diorite)
B(-5,96,-2,minecraft:andesite)
B(-5,13,-1,minecraft:diorite)
B(-5,14,-1,minecraft:diorite)
B(-5,15,-1,minecraft:diorite)
B(-5,16,-1,minecraft:diorite)
B(-5,17,-1,minecraft:diorite)
B(-5,18,-1,minecraft:diorite)
B(-5,19,-1,minecraft:diorite)
B(-5,20,-1,minecraft:obsidian)
B(-5,21,-1,minecraft:obsidian)
B(-5,22,-1,minecraft:obsidian)
B(-5,23,-1,minecraft:obsidian)
B(-5,24,-1,minecraft:obsidian)
B(-5,25,-1,minecraft:obsidian)
B(-5,26,-1,minecraft:obsidian)
B(-5,27,-1,minecraft:obsidian)
B(-5,74,-1,minecraft:obsidian)
B(-5,75,-1,minecraft:obsidian)
B(-5,76,-1,minecraft:obsidian)
B(-5,77,-1,minecraft:obsidian)
B(-5,78,-1,minecraft:obsidian)
B(-5,79,-1,minecraft:obsidian)
B(-5,80,-1,minecraft:obsidian)
B(-5,81,-1,minecraft:obsidian)
B(-5,82,-1,minecraft:obsidian)
B(-5,83,-1,minecraft:obsidian)
B(-5,84,-1,minecraft:obsidian)
B(-5,85,-1,minecraft:obsidian)
B(-5,86,-1,minecraft:obsidian)
B(-5,87,-1,minecraft:obsidian)
B(-5,88,-1,minecraft:obsidian)
B(-5,89,-1,minecraft:obsidian)
B(-5,90,-1,minecraft:obsidian)
B(-5,91,-1,minecraft:obsidian)
B(-5,92,-1,minecraft:obsidian)
B(-5,93,-1,minecraft:obsidian)
B(-5,94,-1,minecraft:obsidian)
B(-5,95,-1,minecraft:diorite)
B(-5,96,-1,minecraft:andesite)
B(-5,12,0,minecraft:diorite)
B(-5,13,0,minecraft:diorite)
B(-5,14,0,minecraft:diorite)
B(-5,15,0,minecraft:diorite)
B(-5,16,0,minecraft:diorite)
B(-5,17,0,minecraft:diorite)
B(-5,18,0,minecraft:diorite)
B(-5,19,0,minecraft:diorite)
B(-5,20,0,minecraft:obsidian)
B(-5,21,0,minecraft:obsidian)
B(-5,22,0,minecraft:obsidian)
B(-5,23,0,minecraft:obsidian)
B(-5,24,0,minecraft:obsidian)
B(-5,25,0,minecraft:obsidian)
B(-5,26,0,minecraft:obsidian)
B(-5,27,0,minecraft:diorite)
B(-5,74,0,minecraft:obsidian)
B(-5,75,0,minecraft:obsidian)
B(-5,76,0,minecraft:obsidian)
B(-5,77,0,minecraft:obsidian)
B(-5,78,0,minecraft:obsidian)
B(-5,79,0,minecraft:obsidian)
B(-5,80,0,minecraft:obsidian)
B(-5,81,0,minecraft:obsidian)
B(-5,82,0,minecraft:obsidian)
B(-5,83,0,minecraft:obsidian)
B(-5,84,0,minecraft:obsidian)
B(-5,85,0,minecraft:obsidian)
B(-5,86,0,minecraft:obsidian)
B(-5,87,0,minecraft:obsidian)
B(-5,88,0,minecraft:obsidian)
B(-5,89,0,minecraft:obsidian)
B(-5,90,0,minecraft:obsidian)
B(-5,91,0,minecraft:obsidian)
B(-5,92,0,minecraft:obsidian)
B(-5,93,0,minecraft:obsidian)
B(-5,94,0,minecraft:diorite)
B(-5,95,0,minecraft:andesite)
B(-5,11,1,minecraft:diorite)
B(-5,12,1,minecraft:diorite)
B(-5,13,1,minecraft:diorite)
B(-5,14,1,minecraft:diorite)
B(-5,15,1,minecraft:diorite)
B(-5,16,1,minecraft:diorite)
B(-5,17,1,minecraft:diorite)
B(-5,18,1,minecraft:diorite)
B(-5,19,1,minecraft:diorite)
B(-5,20,1,minecraft:obsidian)
B(-5,21,1,minecraft:obsidian)
B(-5,22,1,minecraft:obsidian)
B(-5,23,1,minecraft:obsidian)
B(-5,24,1,minecraft:obsidian)
B(-5,25,1,minecraft:obsidian)
B(-5,26,1,minecraft:diorite)
B(-5,73,1,minecraft:obsidian)
B(-5,74,1,minecraft:obsidian)
B(-5,75,1,minecraft:obsidian)
B(-5,76,1,minecraft:obsidian)
B(-5,77,1,minecraft:obsidian)
B(-5,78,1,minecraft:obsidian)
B(-5,79,1,minecraft:obsidian)
B(-5,80,1,minecraft:obsidian)
B(-5,81,1,minecraft:obsidian)
B(-5,82,1,minecraft:obsidian)
B(-5,83,1,minecraft:obsidian)
B(-5,84,1,minecraft:obsidian)
B(-5,85,1,minecraft:obsidian)
B(-5,86,1,minecraft:obsidian)
B(-5,87,1,minecraft:obsidian)
B(-5,88,1,minecraft:obsidian)
B(-5,89,1,minecraft:obsidian)
B(-5,90,1,minecraft:obsidian)
B(-5,91,1,minecraft:obsidian)
B(-5,92,1,minecraft:obsidian)
B(-5,93,1,minecraft:obsidian)
B(-5,94,1,minecraft:diorite)
B(-5,95,1,minecraft:andesite)
B(-5,11,2,minecraft:diorite)
B(-5,12,2,minecraft:diorite)
B(-5,13,2,minecraft:diorite)
B(-5,14,2,minecraft:diorite)
B(-5,15,2,minecraft:diorite)
B(-5,16,2,minecraft:diorite)
B(-5,17,2,minecraft:diorite)
B(-5,18,2,minecraft:diorite)
B(-5,19,2,minecraft:obsidian)
B(-5,20,2,minecraft:obsidian)
B(-5,21,2,minecraft:obsidian)
B(-5,22,2,minecraft:obsidian)
B(-5,23,2,minecraft:obsidian)
B(-5,24,2,minecraft:obsidian)
B(-5,25,2,minecraft:diorite)
B(-5,26,2,minecraft:diorite)
B(-5,72,2,minecraft:obsidian)
B(-5,73,2,minecraft:obsidian)
B(-5,74,2,minecraft:obsidian)
B(-5,75,2,minecraft:obsidian)
B(-5,76,2,minecraft:obsidian)
B(-5,77,2,minecraft:obsidian)
B(-5,78,2,minecraft:obsidian)
B(-5,79,2,minecraft:obsidian)
B(-5,80,2,minecraft:obsidian)
B(-5,81,2,minecraft:obsidian)
B(-5,82,2,minecraft:obsidian)
B(-5,83,2,minecraft:obsidian)
B(-5,84,2,minecraft:obsidian)
B(-5,85,2,minecraft:obsidian)
B(-5,86,2,minecraft:obsidian)
B(-5,87,2,minecraft:obsidian)
B(-5,88,2,minecraft:obsidian)
B(-5,89,2,minecraft:obsidian)
B(-5,90,2,minecraft:obsidian)
B(-5,91,2,minecraft:obsidian)
B(-5,92,2,minecraft:obsidian)
B(-5,93,2,minecraft:diorite)
B(-5,94,2,minecraft:andesite)
B(-5,11,3,minecraft:diorite)
B(-5,12,3,minecraft:diorite)
B(-5,13,3,minecraft:diorite)
B(-5,14,3,minecraft:diorite)
B(-5,15,3,minecraft:diorite)
B(-5,16,3,minecraft:diorite)
B(-5,17,3,minecraft:diorite)
B(-5,18,3,minecraft:obsidian)
B(-5,19,3,minecraft:obsidian)
B(-5,20,3,minecraft:obsidian)
B(-5,21,3,minecraft:obsidian)
B(-5,22,3,minecraft:obsidian)
B(-5,23,3,minecraft:obsidian)
B(-5,24,3,minecraft:obsidian)
B(-5,25,3,minecraft:diorite)
B(-5,26,3,minecraft:diorite)
B(-5,71,3,minecraft:obsidian)
B(-5,72,3,minecraft:obsidian)
B(-5,73,3,minecraft:obsidian)
B(-5,74,3,minecraft:obsidian)
B(-5,75,3,minecraft:obsidian)
B(-5,76,3,minecraft:obsidian)
B(-5,77,3,minecraft:obsidian)
B(-5,78,3,minecraft:obsidian)
B(-5,79,3,minecraft:obsidian)
B(-5,80,3,minecraft:obsidian)
B(-5,81,3,minecraft:obsidian)
B(-5,82,3,minecraft:obsidian)
B(-5,83,3,minecraft:obsidian)
B(-5,84,3,minecraft:obsidian)
B(-5,85,3,minecraft:obsidian)
B(-5,86,3,minecraft:obsidian)
B(-5,87,3,minecraft:obsidian)
B(-5,88,3,minecraft:obsidian)
B(-5,89,3,minecraft:obsidian)
B(-5,90,3,minecraft:obsidian)
B(-5,91,3,minecraft:diorite)
B(-5,92,3,minecraft:andesite)
B(-5,11,4,minecraft:diorite)
B(-5,12,4,minecraft:diorite)
B(-5,13,4,minecraft:diorite)
B(-5,14,4,minecraft:diorite)
B(-5,15,4,minecraft:diorite)
B(-5,16,4,minecraft:diorite)
B(-5,17,4,minecraft:obsidian)
B(-5,18,4,minecraft:obsidian)
B(-5,19,4,minecraft:obsidian)
B(-5,20,4,minecraft:obsidian)
B(-5,21,4,minecraft:obsidian)
B(-5,22,4,minecraft:obsidian)
B(-5,23,4,minecraft:obsidian)
B(-5,24,4,minecraft:obsidian)
B(-5,25,4,minecraft:diorite)
B(-5,26,4,minecraft:diorite)
B(-5,70,4,minecraft:obsidian)
B(-5,71,4,minecraft:obsidian)
B(-5,72,4,minecraft:obsidian)
B(-5,73,4,minecraft:obsidian)
B(-5,74,4,minecraft:obsidian)
B(-5,75,4,minecraft:obsidian)
B(-5,76,4,minecraft:obsidian)
B(-5,77,4,minecraft:obsidian)
B(-5,78,4,minecraft:obsidian)
B(-5,79,4,minecraft:obsidian)
B(-5,80,4,minecraft:obsidian)
B(-5,81,4,minecraft:obsidian)
B(-5,82,4,minecraft:obsidian)
B(-5,83,4,minecraft:obsidian)
B(-5,84,4,minecraft:obsidian)
B(-5,85,4,minecraft:obsidian)
B(-5,86,4,minecraft:obsidian)
B(-5,87,4,minecraft:obsidian)
B(-5,88,4,minecraft:obsidian)
B(-5,89,4,minecraft:obsidian)
B(-5,90,4,minecraft:diorite)
B(-5,91,4,minecraft:andesite)
B(-5,10,5,minecraft:diorite)
B(-5,11,5,minecraft:diorite)
B(-5,12,5,minecraft:diorite)
B(-5,13,5,minecraft:diorite)
B(-5,14,5,minecraft:diorite)
B(-5,15,5,minecraft:diorite)
B(-5,16,5,minecraft:obsidian)
B(-5,17,5,minecraft:obsidian)
B(-5,18,5,minecraft:obsidian)
B(-5,19,5,minecraft:obsidian)
B(-5,20,5,minecraft:obsidian)
B(-5,21,5,minecraft:obsidian)
B(-5,22,5,minecraft:obsidian)
B(-5,23,5,minecraft:obsidian)
B(-5,24,5,minecraft:obsidian)
B(-5,25,5,minecraft:obsidian)
B(-5,26,5,minecraft:diorite)
B(-5,69,5,minecraft:obsidian)
B(-5,70,5,minecraft:obsidian)
B(-5,71,5,minecraft:obsidian)
B(-5,72,5,minecraft:obsidian)
B(-5,73,5,minecraft:obsidian)
B(-5,74,5,minecraft:obsidian)
B(-5,75,5,minecraft:obsidian)
B(-5,76,5,minecraft:obsidian)
B(-5,77,5,minecraft:obsidian)
B(-5,78,5,minecraft:obsidian)
B(-5,79,5,minecraft:obsidian)
B(-5,80,5,minecraft:obsidian)
B(-5,81,5,minecraft:obsidian)
B(-5,82,5,minecraft:obsidian)
B(-5,83,5,minecraft:obsidian)
B(-5,84,5,minecraft:obsidian)
B(-5,85,5,minecraft:obsidian)
B(-5,86,5,minecraft:diorite)
B(-5,87,5,minecraft:diorite)
B(-5,88,5,minecraft:diorite)
B(-5,89,5,minecraft:diorite)
B(-5,90,5,minecraft:andesite)
B(-5,10,6,minecraft:diorite)
B(-5,11,6,minecraft:diorite)
B(-5,12,6,minecraft:diorite)
B(-5,13,6,minecraft:diorite)
B(-5,14,6,minecraft:diorite)
B(-5,15,6,minecraft:diorite)
B(-5,16,6,minecraft:obsidian)
B(-5,17,6,minecraft:obsidian)
B(-5,18,6,minecraft:obsidian)
B(-5,19,6,minecraft:obsidian)
B(-5,20,6,minecraft:obsidian)
B(-5,21,6,minecraft:obsidian)
B(-5,22,6,minecraft:obsidian)
B(-5,23,6,minecraft:obsidian)
B(-5,24,6,minecraft:obsidian)
B(-5,25,6,minecraft:obsidian)
B(-5,26,6,minecraft:diorite)
B(-5,70,6,minecraft:obsidian)
B(-5,71,6,minecraft:obsidian)
B(-5,72,6,minecraft:obsidian)
B(-5,73,6,minecraft:obsidian)
B(-5,74,6,minecraft:obsidian)
B(-5,75,6,minecraft:obsidian)
B(-5,76,6,minecraft:obsidian)
B(-5,77,6,minecraft:obsidian)
B(-5,78,6,minecraft:obsidian)
B(-5,79,6,minecraft:obsidian)
B(-5,80,6,minecraft:obsidian)
B(-5,81,6,minecraft:obsidian)
B(-5,82,6,minecraft:obsidian)
B(-5,83,6,minecraft:obsidian)
B(-5,84,6,minecraft:obsidian)
B(-5,85,6,minecraft:diorite)
B(-5,86,6,minecraft:diorite)
B(-5,87,6,minecraft:diorite)
B(-5,88,6,minecraft:diorite)
B(-5,89,6,minecraft:diorite)
B(-5,90,6,minecraft:diorite)
B(-5,91,6,minecraft:andesite)
B(-5,10,7,minecraft:diorite)
B(-5,11,7,minecraft:diorite)
B(-5,12,7,minecraft:diorite)
B(-5,13,7,minecraft:diorite)
B(-5,14,7,minecraft:diorite)
B(-5,15,7,minecraft:diorite)
B(-5,16,7,minecraft:obsidian)
B(-5,17,7,minecraft:obsidian)
B(-5,18,7,minecraft:obsidian)
B(-5,19,7,minecraft:obsidian)
B(-5,20,7,minecraft:obsidian)
B(-5,21,7,minecraft:obsidian)
B(-5,22,7,minecraft:obsidian)
B(-5,23,7,minecraft:obsidian)
B(-5,24,7,minecraft:obsidian)
B(-5,25,7,minecraft:diorite)
B(-5,26,7,minecraft:diorite)
B(-5,70,7,minecraft:obsidian)
B(-5,71,7,minecraft:obsidian)
B(-5,72,7,minecraft:obsidian)
B(-5,73,7,minecraft:obsidian)
B(-5,74,7,minecraft:obsidian)
B(-5,75,7,minecraft:obsidian)
B(-5,76,7,minecraft:obsidian)
B(-5,77,7,minecraft:obsidian)
B(-5,78,7,minecraft:obsidian)
B(-5,79,7,minecraft:obsidian)
B(-5,80,7,minecraft:obsidian)
B(-5,81,7,minecraft:obsidian)
B(-5,82,7,minecraft:obsidian)
B(-5,83,7,minecraft:obsidian)
B(-5,84,7,minecraft:diorite)
B(-5,85,7,minecraft:diorite)
B(-5,86,7,minecraft:diorite)
B(-5,87,7,minecraft:diorite)
B(-5,88,7,minecraft:diorite)
B(-5,89,7,minecraft:diorite)
B(-5,90,7,minecraft:andesite)
B(-5,10,8,minecraft:diorite)
B(-5,11,8,minecraft:diorite)
B(-5,12,8,minecraft:diorite)
B(-5,13,8,minecraft:diorite)
B(-5,14,8,minecraft:diorite)
B(-5,15,8,minecraft:obsidian)
B(-5,16,8,minecraft:obsidian)
B(-5,17,8,minecraft:obsidian)
B(-5,18,8,minecraft:obsidian)
B(-5,19,8,minecraft:obsidian)
B(-5,20,8,minecraft:obsidian)
B(-5,21,8,minecraft:obsidian)
B(-5,22,8,minecraft:obsidian)
B(-5,23,8,minecraft:obsidian)
B(-5,24,8,minecraft:obsidian)
B(-5,25,8,minecraft:diorite)
B(-5,26,8,minecraft:diorite)
B(-5,27,8,minecraft:diorite)
B(-5,28,8,minecraft:diorite)
B(-5,70,8,minecraft:obsidian)
B(-5,71,8,minecraft:obsidian)
B(-5,72,8,minecraft:obsidian)
B(-5,73,8,minecraft:obsidian)
B(-5,74,8,minecraft:obsidian)
B(-5,75,8,minecraft:obsidian)
B(-5,76,8,minecraft:obsidian)
B(-5,77,8,minecraft:obsidian)
B(-5,78,8,minecraft:obsidian)
B(-5,79,8,minecraft:obsidian)
B(-5,80,8,minecraft:obsidian)
B(-5,81,8,minecraft:obsidian)
B(-5,82,8,minecraft:obsidian)
B(-5,83,8,minecraft:diorite)
B(-5,84,8,minecraft:diorite)
B(-5,85,8,minecraft:diorite)
B(-5,86,8,minecraft:diorite)
B(-5,87,8,minecraft:diorite)
B(-5,88,8,minecraft:diorite)
B(-5,89,8,minecraft:diorite)
B(-5,90,8,minecraft:andesite)
B(-4,15,-7,minecraft:diorite)
B(-4,16,-7,minecraft:diorite)
B(-4,17,-7,minecraft:diorite)
B(-4,18,-7,minecraft:diorite)
B(-4,19,-7,minecraft:diorite)
B(-4,20,-7,minecraft:diorite)
B(-4,21,-7,minecraft:obsidian)
B(-4,22,-7,minecraft:obsidian)
B(-4,23,-7,minecraft:obsidian)
B(-4,24,-7,minecraft:obsidian)
B(-4,25,-7,minecraft:obsidian)
B(-4,26,-7,minecraft:obsidian)
B(-4,27,-7,minecraft:obsidian)
B(-4,28,-7,minecraft:obsidian)
B(-4,29,-7,minecraft:diorite)
B(-4,30,-7,minecraft:diorite)
B(-4,49,-7,minecraft:obsidian)
B(-4,51,-7,minecraft:obsidian)
B(-4,64,-7,minecraft:obsidian)
B(-4,65,-7,minecraft:obsidian)
B(-4,66,-7,minecraft:obsidian)
B(-4,67,-7,minecraft:obsidian)
B(-4,68,-7,minecraft:obsidian)
B(-4,69,-7,minecraft:obsidian)
B(-4,70,-7,minecraft:obsidian)
B(-4,71,-7,minecraft:obsidian)
B(-4,72,-7,minecraft:obsidian)
B(-4,73,-7,minecraft:obsidian)
B(-4,74,-7,minecraft:obsidian)
B(-4,75,-7,minecraft:obsidian)
B(-4,76,-7,minecraft:obsidian)
B(-4,77,-7,minecraft:obsidian)
B(-4,78,-7,minecraft:obsidian)
B(-4,79,-7,minecraft:obsidian)
B(-4,80,-7,minecraft:obsidian)
B(-4,81,-7,minecraft:obsidian)
B(-4,82,-7,minecraft:obsidian)
B(-4,83,-7,minecraft:obsidian)
B(-4,84,-7,minecraft:obsidian)
B(-4,85,-7,minecraft:obsidian)
B(-4,86,-7,minecraft:obsidian)
B(-4,87,-7,minecraft:obsidian)
B(-4,88,-7,minecraft:obsidian)
B(-4,89,-7,minecraft:obsidian)
B(-4,90,-7,minecraft:obsidian)
B(-4,91,-7,minecraft:obsidian)
B(-4,92,-7,minecraft:obsidian)
B(-4,93,-7,minecraft:obsidian)
B(-4,94,-7,minecraft:obsidian)
B(-4,95,-7,minecraft:obsidian)
B(-4,96,-7,minecraft:diorite)
B(-4,97,-7,minecraft:diorite)
B(-4,15,-6,minecraft:diorite)
B(-4,16,-6,minecraft:diorite)
B(-4,17,-6,minecraft:diorite)
B(-4,18,-6,minecraft:diorite)
B(-4,19,-6,minecraft:diorite)
B(-4,20,-6,minecraft:diorite)
B(-4,21,-6,minecraft:obsidian)
B(-4,22,-6,minecraft:obsidian)
B(-4,23,-6,minecraft:obsidian)
B(-4,24,-6,minecraft:obsidian)
B(-4,25,-6,minecraft:obsidian)
B(-4,26,-6,minecraft:obsidian)
B(-4,27,-6,minecraft:obsidian)
B(-4,28,-6,minecraft:obsidian)
B(-4,29,-6,minecraft:diorite)
B(-4,65,-6,minecraft:obsidian)
B(-4,66,-6,minecraft:obsidian)
B(-4,67,-6,minecraft:obsidian)
B(-4,68,-6,minecraft:obsidian)
B(-4,69,-6,minecraft:obsidian)
B(-4,70,-6,minecraft:obsidian)
B(-4,71,-6,minecraft:obsidian)
B(-4,72,-6,minecraft:obsidian)
B(-4,73,-6,minecraft:obsidian)
B(-4,74,-6,minecraft:obsidian)
B(-4,75,-6,minecraft:obsidian)
B(-4,76,-6,minecraft:obsidian)
B(-4,77,-6,minecraft:obsidian)
B(-4,78,-6,minecraft:obsidian)
B(-4,79,-6,minecraft:obsidian)
B(-4,80,-6,minecraft:obsidian)
B(-4,81,-6,minecraft:obsidian)
B(-4,82,-6,minecraft:obsidian)
B(-4,83,-6,minecraft:obsidian)
B(-4,84,-6,minecraft:obsidian)
B(-4,85,-6,minecraft:obsidian)
B(-4,86,-6,minecraft:obsidian)
B(-4,87,-6,minecraft:obsidian)
B(-4,88,-6,minecraft:obsidian)
B(-4,89,-6,minecraft:obsidian)
B(-4,90,-6,minecraft:obsidian)
B(-4,91,-6,minecraft:obsidian)
B(-4,92,-6,minecraft:obsidian)
B(-4,93,-6,minecraft:obsidian)
B(-4,94,-6,minecraft:obsidian)
B(-4,95,-6,minecraft:obsidian)
B(-4,96,-6,minecraft:diorite)
B(-4,97,-6,minecraft:diorite)
B(-4,15,-5,minecraft:diorite)
B(-4,16,-5,minecraft:diorite)
B(-4,17,-5,minecraft:diorite)
B(-4,18,-5,minecraft:diorite)
B(-4,19,-5,minecraft:diorite)
B(-4,20,-5,minecraft:diorite)
B(-4,21,-5,minecraft:obsidian)
B(-4,22,-5,minecraft:obsidian)
B(-4,23,-5,minecraft:obsidian)
B(-4,24,-5,minecraft:obsidian)
B(-4,25,-5,minecraft:obsidian)
B(-4,26,-5,minecraft:obsidian)
B(-4,27,-5,minecraft:obsidian)
B(-4,28,-5,minecraft:obsidian)
B(-4,71,-5,minecraft:obsidian)
B(-4,72,-5,minecraft:obsidian)
B(-4,73,-5,minecraft:obsidian)
B(-4,74,-5,minecraft:obsidian)
B(-4,75,-5,minecraft:obsidian)
B(-4,76,-5,minecraft:obsidian)
B(-4,77,-5,minecraft:obsidian)
B(-4,78,-5,minecraft:obsidian)
B(-4,79,-5,minecraft:obsidian)
B(-4,80,-5,minecraft:obsidian)
B(-4,81,-5,minecraft:obsidian)
B(-4,82,-5,minecraft:obsidian)
B(-4,83,-5,minecraft:obsidian)
B(-4,84,-5,minecraft:obsidian)
B(-4,85,-5,minecraft:obsidian)
B(-4,86,-5,minecraft:obsidian)
B(-4,87,-5,minecraft:obsidian)
B(-4,88,-5,minecraft:obsidian)
B(-4,89,-5,minecraft:obsidian)
B(-4,90,-5,minecraft:obsidian)
B(-4,91,-5,minecraft:obsidian)
B(-4,92,-5,minecraft:obsidian)
B(-4,93,-5,minecraft:obsidian)
B(-4,94,-5,minecraft:obsidian)
B(-4,95,-5,minecraft:obsidian)
B(-4,96,-5,minecraft:diorite)
B(-4,97,-5,minecraft:diorite)
B(-4,15,-4,minecraft:diorite)
B(-4,16,-4,minecraft:diorite)
B(-4,17,-4,minecraft:diorite)
B(-4,18,-4,minecraft:diorite)
B(-4,19,-4,minecraft:diorite)
B(-4,20,-4,minecraft:diorite)
B(-4,21,-4,minecraft:obsidian)
B(-4,22,-4,minecraft:obsidian)
B(-4,23,-4,minecraft:obsidian)
B(-4,24,-4,minecraft:obsidian)
B(-4,25,-4,minecraft:obsidian)
B(-4,26,-4,minecraft:obsidian)
B(-4,27,-4,minecraft:obsidian)
B(-4,28,-4,minecraft:obsidian)
B(-4,72,-4,minecraft:obsidian)
B(-4,73,-4,minecraft:obsidian)
B(-4,74,-4,minecraft:obsidian)
B(-4,75,-4,minecraft:obsidian)
B(-4,76,-4,minecraft:obsidian)
B(-4,77,-4,minecraft:obsidian)
B(-4,78,-4,minecraft:obsidian)
B(-4,79,-4,minecraft:obsidian)
B(-4,80,-4,minecraft:obsidian)
B(-4,81,-4,minecraft:obsidian)
B(-4,82,-4,minecraft:obsidian)
B(-4,83,-4,minecraft:obsidian)
B(-4,84,-4,minecraft:obsidian)
B(-4,85,-4,minecraft:obsidian)
B(-4,86,-4,minecraft:obsidian)
B(-4,87,-4,minecraft:obsidian)
B(-4,88,-4,minecraft:obsidian)
B(-4,89,-4,minecraft:obsidian)
B(-4,90,-4,minecraft:obsidian)
B(-4,91,-4,minecraft:obsidian)
B(-4,92,-4,minecraft:obsidian)
B(-4,93,-4,minecraft:obsidian)
B(-4,94,-4,minecraft:obsidian)
B(-4,95,-4,minecraft:obsidian)
B(-4,96,-4,minecraft:diorite)
B(-4,97,-4,minecraft:diorite)
B(-4,15,-3,minecraft:diorite)
B(-4,16,-3,minecraft:diorite)
B(-4,17,-3,minecraft:diorite)
B(-4,18,-3,minecraft:diorite)
B(-4,19,-3,minecraft:diorite)
B(-4,20,-3,minecraft:obsidian)
B(-4,21,-3,minecraft:obsidian)
B(-4,22,-3,minecraft:obsidian)
B(-4,23,-3,minecraft:obsidian)
B(-4,24,-3,minecraft:obsidian)
B(-4,25,-3,minecraft:obsidian)
B(-4,26,-3,minecraft:obsidian)
B(-4,27,-3,minecraft:obsidian)
B(-4,28,-3,minecraft:obsidian)
B(-4,73,-3,minecraft:obsidian)
B(-4,74,-3,minecraft:obsidian)
B(-4,75,-3,minecraft:obsidian)
B(-4,76,-3,minecraft:obsidian)
B(-4,77,-3,minecraft:obsidian)
B(-4,78,-3,minecraft:obsidian)
B(-4,79,-3,minecraft:obsidian)
B(-4,80,-3,minecraft:obsidian)
B(-4,81,-3,minecraft:obsidian)
B(-4,82,-3,minecraft:obsidian)
B(-4,83,-3,minecraft:obsidian)
B(-4,84,-3,minecraft:obsidian)
B(-4,85,-3,minecraft:obsidian)
B(-4,86,-3,minecraft:obsidian)
B(-4,87,-3,minecraft:obsidian)
B(-4,88,-3,minecraft:obsidian)
B(-4,89,-3,minecraft:obsidian)
B(-4,90,-3,minecraft:obsidian)
B(-4,91,-3,minecraft:obsidian)
B(-4,92,-3,minecraft:obsidian)
B(-4,93,-3,minecraft:obsidian)
B(-4,94,-3,minecraft:obsidian)
B(-4,95,-3,minecraft:diorite)
B(-4,96,-3,minecraft:andesite)
B(-4,14,-2,minecraft:diorite)
B(-4,15,-2,minecraft:diorite)
B(-4,16,-2,minecraft:diorite)
B(-4,17,-2,minecraft:diorite)
B(-4,18,-2,minecraft:diorite)
B(-4,19,-2,minecraft:diorite)
B(-4,20,-2,minecraft:obsidian)
B(-4,21,-2,minecraft:obsidian)
B(-4,22,-2,minecraft:obsidian)
B(-4,23,-2,minecraft:obsidian)
B(-4,24,-2,minecraft:obsidian)
B(-4,25,-2,minecraft:obsidian)
B(-4,26,-2,minecraft:obsidian)
B(-4,27,-2,minecraft:obsidian)
B(-4,74,-2,minecraft:obsidian)
B(-4,75,-2,minecraft:obsidian)
B(-4,76,-2,minecraft:obsidian)
B(-4,77,-2,minecraft:obsidian)
B(-4,78,-2,minecraft:obsidian)
B(-4,79,-2,minecraft:obsidian)
B(-4,80,-2,minecraft:obsidian)
B(-4,81,-2,minecraft:obsidian)
B(-4,82,-2,minecraft:obsidian)
B(-4,83,-2,minecraft:obsidian)
B(-4,84,-2,minecraft:obsidian)
B(-4,85,-2,minecraft:obsidian)
B(-4,86,-2,minecraft:obsidian)
B(-4,87,-2,minecraft:obsidian)
B(-4,88,-2,minecraft:obsidian)
B(-4,89,-2,minecraft:obsidian)
B(-4,90,-2,minecraft:obsidian)
B(-4,91,-2,minecraft:obsidian)
B(-4,92,-2,minecraft:obsidian)
B(-4,93,-2,minecraft:obsidian)
B(-4,94,-2,minecraft:obsidian)
B(-4,95,-2,minecraft:diorite)
B(-4,96,-2,minecraft:andesite)
B(-4,13,-1,minecraft:diorite)
B(-4,14,-1,minecraft:diorite)
B(-4,15,-1,minecraft:diorite)
B(-4,16,-1,minecraft:diorite)
B(-4,17,-1,minecraft:diorite)
B(-4,18,-1,minecraft:diorite)
B(-4,19,-1,minecraft:diorite)
B(-4,20,-1,minecraft:obsidian)
B(-4,21,-1,minecraft:obsidian)
B(-4,22,-1,minecraft:obsidian)
B(-4,23,-1,minecraft:obsidian)
B(-4,24,-1,minecraft:obsidian)
B(-4,25,-1,minecraft:obsidian)
B(-4,26,-1,minecraft:obsidian)
B(-4,27,-1,minecraft:obsidian)
B(-4,74,-1,minecraft:obsidian)
B(-4,75,-1,minecraft:obsidian)
B(-4,76,-1,minecraft:obsidian)
B(-4,77,-1,minecraft:obsidian)
B(-4,78,-1,minecraft:obsidian)
B(-4,79,-1,minecraft:obsidian)
B(-4,80,-1,minecraft:obsidian)
B(-4,81,-1,minecraft:obsidian)
B(-4,82,-1,minecraft:obsidian)
B(-4,83,-1,minecraft:obsidian)
B(-4,84,-1,minecraft:obsidian)
B(-4,85,-1,minecraft:obsidian)
B(-4,86,-1,minecraft:obsidian)
B(-4,87,-1,minecraft:obsidian)
B(-4,88,-1,minecraft:obsidian)
B(-4,89,-1,minecraft:obsidian)
B(-4,90,-1,minecraft:obsidian)
B(-4,91,-1,minecraft:obsidian)
B(-4,92,-1,minecraft:obsidian)
B(-4,93,-1,minecraft:obsidian)
B(-4,94,-1,minecraft:obsidian)
B(-4,95,-1,minecraft:diorite)
B(-4,96,-1,minecraft:andesite)
B(-4,12,0,minecraft:diorite)
B(-4,13,0,minecraft:diorite)
B(-4,14,0,minecraft:diorite)
B(-4,15,0,minecraft:diorite)
B(-4,16,0,minecraft:diorite)
B(-4,17,0,minecraft:diorite)
B(-4,18,0,minecraft:diorite)
B(-4,19,0,minecraft:diorite)
B(-4,20,0,minecraft:obsidian)
B(-4,21,0,minecraft:obsidian)
B(-4,22,0,minecraft:obsidian)
B(-4,23,0,minecraft:obsidian)
B(-4,24,0,minecraft:obsidian)
B(-4,25,0,minecraft:obsidian)
B(-4,26,0,minecraft:obsidian)
B(-4,74,0,minecraft:obsidian)
B(-4,75,0,minecraft:obsidian)
B(-4,76,0,minecraft:obsidian)
B(-4,77,0,minecraft:obsidian)
B(-4,78,0,minecraft:obsidian)
B(-4,79,0,minecraft:obsidian)
B(-4,80,0,minecraft:obsidian)
B(-4,81,0,minecraft:obsidian)
B(-4,82,0,minecraft:obsidian)
B(-4,83,0,minecraft:obsidian)
B(-4,84,0,minecraft:obsidian)
B(-4,85,0,minecraft:obsidian)
B(-4,86,0,minecraft:obsidian)
B(-4,87,0,minecraft:obsidian)
B(-4,88,0,minecraft:obsidian)
B(-4,89,0,minecraft:obsidian)
B(-4,90,0,minecraft:obsidian)
B(-4,91,0,minecraft:obsidian)
B(-4,92,0,minecraft:obsidian)
B(-4,93,0,minecraft:obsidian)
B(-4,94,0,minecraft:diorite)
B(-4,95,0,minecraft:andesite)
B(-4,11,1,minecraft:diorite)
B(-4,12,1,minecraft:diorite)
B(-4,13,1,minecraft:diorite)
B(-4,14,1,minecraft:diorite)
B(-4,15,1,minecraft:diorite)
B(-4,16,1,minecraft:diorite)
B(-4,17,1,minecraft:diorite)
B(-4,18,1,minecraft:diorite)
B(-4,19,1,minecraft:obsidian)
B(-4,20,1,minecraft:obsidian)
B(-4,21,1,minecraft:obsidian)
B(-4,22,1,minecraft:obsidian)
B(-4,23,1,minecraft:obsidian)
B(-4,24,1,minecraft:obsidian)
B(-4,25,1,minecraft:obsidian)
B(-4,74,1,minecraft:obsidian)
B(-4,75,1,minecraft:obsidian)
B(-4,76,1,minecraft:obsidian)
B(-4,77,1,minecraft:obsidian)
B(-4,78,1,minecraft:obsidian)
B(-4,79,1,minecraft:obsidian)
B(-4,80,1,minecraft:obsidian)
B(-4,81,1,minecraft:obsidian)
B(-4,82,1,minecraft:obsidian)
B(-4,83,1,minecraft:obsidian)
B(-4,84,1,minecraft:obsidian)
B(-4,85,1,minecraft:obsidian)
B(-4,86,1,minecraft:obsidian)
B(-4,87,1,minecraft:obsidian)
B(-4,88,1,minecraft:obsidian)
B(-4,89,1,minecraft:obsidian)
B(-4,90,1,minecraft:obsidian)
B(-4,91,1,minecraft:obsidian)
B(-4,92,1,minecraft:obsidian)
B(-4,93,1,minecraft:diorite)
B(-4,94,1,minecraft:andesite)
B(-4,11,2,minecraft:diorite)
B(-4,12,2,minecraft:diorite)
B(-4,13,2,minecraft:diorite)
B(-4,14,2,minecraft:diorite)
B(-4,15,2,minecraft:diorite)
B(-4,16,2,minecraft:diorite)
B(-4,17,2,minecraft:diorite)
B(-4,18,2,minecraft:diorite)
B(-4,19,2,minecraft:obsidian)
B(-4,20,2,minecraft:obsidian)
B(-4,21,2,minecraft:obsidian)
B(-4,22,2,minecraft:obsidian)
B(-4,23,2,minecraft:obsidian)
B(-4,24,2,minecraft:obsidian)
B(-4,25,2,minecraft:obsidian)
B(-4,26,2,minecraft:diorite)
B(-4,73,2,minecraft:obsidian)
B(-4,74,2,minecraft:obsidian)
B(-4,75,2,minecraft:obsidian)
B(-4,76,2,minecraft:obsidian)
B(-4,77,2,minecraft:obsidian)
B(-4,78,2,minecraft:obsidian)
B(-4,79,2,minecraft:obsidian)
B(-4,80,2,minecraft:obsidian)
B(-4,81,2,minecraft:obsidian)
B(-4,82,2,minecraft:obsidian)
B(-4,83,2,minecraft:obsidian)
B(-4,84,2,minecraft:obsidian)
B(-4,85,2,minecraft:obsidian)
B(-4,86,2,minecraft:obsidian)
B(-4,87,2,minecraft:obsidian)
B(-4,88,2,minecraft:obsidian)
B(-4,89,2,minecraft:obsidian)
B(-4,90,2,minecraft:obsidian)
B(-4,91,2,minecraft:obsidian)
B(-4,92,2,minecraft:diorite)
B(-4,93,2,minecraft:andesite)
B(-4,11,3,minecraft:diorite)
B(-4,12,3,minecraft:diorite)
B(-4,13,3,minecraft:diorite)
B(-4,14,3,minecraft:diorite)
B(-4,15,3,minecraft:diorite)
B(-4,16,3,minecraft:diorite)
B(-4,17,3,minecraft:diorite)
B(-4,18,3,minecraft:obsidian)
B(-4,19,3,minecraft:obsidian)
B(-4,20,3,minecraft:obsidian)
B(-4,21,3,minecraft:obsidian)
B(-4,22,3,minecraft:obsidian)
B(-4,23,3,minecraft:obsidian)
B(-4,24,3,minecraft:obsidian)
B(-4,25,3,minecraft:obsidian)
B(-4,26,3,minecraft:diorite)
B(-4,72,3,minecraft:obsidian)
B(-4,73,3,minecraft:obsidian)
B(-4,74,3,minecraft:obsidian)
B(-4,75,3,minecraft:obsidian)
B(-4,76,3,minecraft:obsidian)
B(-4,77,3,minecraft:obsidian)
B(-4,78,3,minecraft:obsidian)
B(-4,79,3,minecraft:obsidian)
B(-4,80,3,minecraft:obsidian)
B(-4,81,3,minecraft:obsidian)
B(-4,82,3,minecraft:obsidian)
B(-4,83,3,minecraft:obsidian)
B(-4,84,3,minecraft:obsidian)
B(-4,85,3,minecraft:obsidian)
B(-4,86,3,minecraft:obsidian)
B(-4,87,3,minecraft:obsidian)
B(-4,88,3,minecraft:obsidian)
B(-4,89,3,minecraft:obsidian)
B(-4,90,3,minecraft:diorite)
B(-4,91,3,minecraft:diorite)
B(-4,92,3,minecraft:andesite)
B(-4,10,4,minecraft:diorite)
B(-4,11,4,minecraft:diorite)
B(-4,12,4,minecraft:diorite)
B(-4,13,4,minecraft:diorite)
B(-4,14,4,minecraft:diorite)
B(-4,15,4,minecraft:diorite)
B(-4,16,4,minecraft:diorite)
B(-4,17,4,minecraft:obsidian)
B(-4,18,4,minecraft:obsidian)
B(-4,19,4,minecraft:obsidian)
B(-4,20,4,minecraft:obsidian)
B(-4,21,4,minecraft:obsidian)
B(-4,22,4,minecraft:obsidian)
B(-4,23,4,minecraft:obsidian)
B(-4,24,4,minecraft:obsidian)
B(-4,25,4,minecraft:obsidian)
B(-4,71,4,minecraft:obsidian)
B(-4,72,4,minecraft:obsidian)
B(-4,73,4,minecraft:obsidian)
B(-4,74,4,minecraft:obsidian)
B(-4,75,4,minecraft:obsidian)
B(-4,76,4,minecraft:obsidian)
B(-4,77,4,minecraft:obsidian)
B(-4,78,4,minecraft:obsidian)
B(-4,79,4,minecraft:obsidian)
B(-4,80,4,minecraft:obsidian)
B(-4,81,4,minecraft:obsidian)
B(-4,82,4,minecraft:obsidian)
B(-4,83,4,minecraft:obsidian)
B(-4,84,4,minecraft:obsidian)
B(-4,85,4,minecraft:obsidian)
B(-4,86,4,minecraft:obsidian)
B(-4,87,4,minecraft:obsidian)
B(-4,88,4,minecraft:obsidian)
B(-4,89,4,minecraft:diorite)
B(-4,90,4,minecraft:diorite)
B(-4,91,4,minecraft:diorite)
B(-4,92,4,minecraft:andesite)
B(-4,10,5,minecraft:diorite)
B(-4,11,5,minecraft:diorite)
B(-4,12,5,minecraft:diorite)
B(-4,13,5,minecraft:diorite)
B(-4,14,5,minecraft:diorite)
B(-4,15,5,minecraft:diorite)
B(-4,16,5,minecraft:obsidian)
B(-4,17,5,minecraft:obsidian)
B(-4,18,5,minecraft:obsidian)
B(-4,19,5,minecraft:obsidian)
B(-4,20,5,minecraft:obsidian)
B(-4,21,5,minecraft:obsidian)
B(-4,22,5,minecraft:obsidian)
B(-4,23,5,minecraft:obsidian)
B(-4,24,5,minecraft:obsidian)
B(-4,25,5,minecraft:obsidian)
B(-4,70,5,minecraft:obsidian)
B(-4,71,5,minecraft:obsidian)
B(-4,72,5,minecraft:obsidian)
B(-4,73,5,minecraft:obsidian)
B(-4,74,5,minecraft:obsidian)
B(-4,75,5,minecraft:obsidian)
B(-4,76,5,minecraft:obsidian)
B(-4,77,5,minecraft:obsidian)
B(-4,78,5,minecraft:obsidian)
B(-4,79,5,minecraft:obsidian)
B(-4,80,5,minecraft:obsidian)
B(-4,81,5,minecraft:obsidian)
B(-4,82,5,minecraft:obsidian)
B(-4,83,5,minecraft:obsidian)
B(-4,84,5,minecraft:obsidian)
B(-4,85,5,minecraft:obsidian)
B(-4,86,5,minecraft:diorite)
B(-4,87,5,minecraft:diorite)
B(-4,88,5,minecraft:diorite)
B(-4,89,5,minecraft:diorite)
B(-4,90,5,minecraft:diorite)
B(-4,91,5,minecraft:andesite)
B(-4,10,6,minecraft:diorite)
B(-4,11,6,minecraft:diorite)
B(-4,12,6,minecraft:diorite)
B(-4,13,6,minecraft:diorite)
B(-4,14,6,minecraft:diorite)
B(-4,15,6,minecraft:diorite)
B(-4,16,6,minecraft:obsidian)
B(-4,17,6,minecraft:obsidian)
B(-4,18,6,minecraft:obsidian)
B(-4,19,6,minecraft:obsidian)
B(-4,20,6,minecraft:obsidian)
B(-4,21,6,minecraft:obsidian)
B(-4,22,6,minecraft:obsidian)
B(-4,23,6,minecraft:obsidian)
B(-4,24,6,minecraft:obsidian)
B(-4,25,6,minecraft:obsidian)
B(-4,70,6,minecraft:obsidian)
B(-4,71,6,minecraft:obsidian)
B(-4,72,6,minecraft:obsidian)
B(-4,73,6,minecraft:obsidian)
B(-4,74,6,minecraft:obsidian)
B(-4,75,6,minecraft:obsidian)
B(-4,76,6,minecraft:obsidian)
B(-4,77,6,minecraft:obsidian)
B(-4,78,6,minecraft:obsidian)
B(-4,79,6,minecraft:obsidian)
B(-4,80,6,minecraft:obsidian)
B(-4,81,6,minecraft:obsidian)
B(-4,82,6,minecraft:obsidian)
B(-4,83,6,minecraft:obsidian)
