
#######################################################################
# +-----------------------------------------------------------------+ #
# |                            BO4 object                           | #
# +-----------------------------------------------------------------+ #
#######################################################################

Author: NLBlackEagle

Description: No description given

SettingsMode: WriteWithoutComments


#######################################################################
# +-----------------------------------------------------------------+ #
# |                          Main settings                          | #
# +-----------------------------------------------------------------+ #
#######################################################################

FixedRotation: 

Frequency: 0

SpawnHeight: highestBlock

UseCenterForHighestBlock: true

##############################
# Height Limits for the BO4. #
##############################

MinHeight: 0

MaxHeight: 255

InheritBO3: 

InheritBO3Rotation: NORTH

OverrideChildSettings: true

OverrideParentHeight: false

CanOverride: false

BranchFrequency: 0

BranchFrequencyGroup: 

MustBeBelowOther: false

MustBeInside: 

CannotBeInside: 

ReplacesBO3: 

MustBeInsideWorldBorders: false

CanSpawnOnWater: true

SpawnOnWaterOnly: false

SpawnUnderWater: false

SpawnAtWaterLevel: false

HeightOffset: 0

RemoveAir: true

ReplaceAbove: 

ReplaceBelow: 

ReplaceWithBiomeBlocks: true

ReplaceWithSurfaceBlock: GRASS

ReplaceWithGroundBlock: DIRT

ReplaceWithStoneBlock: STONE

SmoothRadius: 0

SmoothHeightOffset: 0

SmoothStartTop: false

SmoothStartWood: false

SmoothingSurfaceBlock: 

SmoothingGroundBlock: 

BO3Group: 

IsSpawnPoint: false

DoReplaceBlocks: true


#######################################################################
# +-----------------------------------------------------------------+ #
# |                              Blocks                             | #
# +-----------------------------------------------------------------+ #
#######################################################################

B(-8,21,-7,minecraft:diorite)
B(-8,22,-7,minecraft:diorite)
B(-8,23,-7,minecraft:diorite)
B(-8,24,-7,minecraft:diorite)
B(-8,25,-7,minecraft:diorite)
B(-8,26,-7,minecraft:diorite)
B(-8,27,-7,minecraft:diorite)
B(-8,28,-7,minecraft:diorite)
B(-8,29,-7,minecraft:diorite)
B(-8,30,-7,minecraft:diorite)
B(-8,31,-7,minecraft:diorite)
B(-8,32,-7,minecraft:diorite)
B(-8,33,-7,minecraft:diorite)
B(-8,34,-7,minecraft:diorite)
B(-8,35,-7,minecraft:diorite)
B(-8,37,-7,minecraft:obsidian)
B(-8,87,-7,minecraft:obsidian)
B(-8,88,-7,minecraft:obsidian)
B(-8,89,-7,minecraft:obsidian)
B(-8,90,-7,minecraft:obsidian)
B(-8,91,-7,minecraft:obsidian)
B(-8,92,-7,minecraft:obsidian)
B(-8,93,-7,minecraft:obsidian)
B(-8,94,-7,minecraft:obsidian)
B(-8,95,-7,minecraft:obsidian)
B(-8,96,-7,minecraft:obsidian)
B(-8,97,-7,minecraft:obsidian)
B(-8,98,-7,minecraft:obsidian)
B(-8,99,-7,minecraft:diorite)
B(-8,100,-7,minecraft:andesite)
B(-8,21,-6,minecraft:diorite)
B(-8,22,-6,minecraft:diorite)
B(-8,23,-6,minecraft:diorite)
B(-8,24,-6,minecraft:diorite)
B(-8,25,-6,minecraft:diorite)
B(-8,26,-6,minecraft:diorite)
B(-8,27,-6,minecraft:diorite)
B(-8,28,-6,minecraft:diorite)
B(-8,29,-6,minecraft:diorite)
B(-8,30,-6,minecraft:diorite)
B(-8,31,-6,minecraft:diorite)
B(-8,32,-6,minecraft:diorite)
B(-8,33,-6,minecraft:diorite)
B(-8,34,-6,minecraft:diorite)
B(-8,35,-6,minecraft:diorite)
B(-8,36,-6,minecraft:diorite)
B(-8,37,-6,minecraft:obsidian)
B(-8,87,-6,minecraft:obsidian)
B(-8,88,-6,minecraft:obsidian)
B(-8,89,-6,minecraft:obsidian)
B(-8,90,-6,minecraft:obsidian)
B(-8,91,-6,minecraft:obsidian)
B(-8,92,-6,minecraft:obsidian)
B(-8,93,-6,minecraft:obsidian)
B(-8,94,-6,minecraft:obsidian)
B(-8,95,-6,minecraft:obsidian)
B(-8,96,-6,minecraft:obsidian)
B(-8,97,-6,minecraft:obsidian)
B(-8,98,-6,minecraft:obsidian)
B(-8,99,-6,minecraft:obsidian)
B(-8,100,-6,minecraft:diorite)
B(-8,101,-6,minecraft:andesite)
B(-8,21,-5,minecraft:diorite)
B(-8,22,-5,minecraft:diorite)
B(-8,23,-5,minecraft:diorite)
B(-8,24,-5,minecraft:diorite)
B(-8,25,-5,minecraft:diorite)
B(-8,26,-5,minecraft:diorite)
B(-8,27,-5,minecraft:obsidian)
B(-8,28,-5,minecraft:diorite)
B(-8,29,-5,minecraft:diorite)
B(-8,30,-5,minecraft:diorite)
B(-8,31,-5,minecraft:diorite)
B(-8,32,-5,minecraft:diorite)
B(-8,33,-5,minecraft:diorite)
B(-8,34,-5,minecraft:diorite)
B(-8,35,-5,minecraft:diorite)
B(-8,36,-5,minecraft:diorite)
B(-8,37,-5,minecraft:andesite)
B(-8,87,-5,minecraft:obsidian)
B(-8,88,-5,minecraft:obsidian)
B(-8,89,-5,minecraft:obsidian)
B(-8,90,-5,minecraft:obsidian)
B(-8,91,-5,minecraft:obsidian)
B(-8,92,-5,minecraft:obsidian)
B(-8,93,-5,minecraft:obsidian)
B(-8,94,-5,minecraft:obsidian)
B(-8,95,-5,minecraft:obsidian)
B(-8,96,-5,minecraft:obsidian)
B(-8,97,-5,minecraft:obsidian)
B(-8,98,-5,minecraft:obsidian)
B(-8,99,-5,minecraft:obsidian)
B(-8,100,-5,minecraft:obsidian)
B(-8,101,-5,minecraft:diorite)
B(-8,102,-5,minecraft:andesite)
B(-8,21,-4,minecraft:diorite)
B(-8,22,-4,minecraft:diorite)
B(-8,23,-4,minecraft:diorite)
B(-8,24,-4,minecraft:diorite)
B(-8,25,-4,minecraft:diorite)
B(-8,26,-4,minecraft:diorite)
B(-8,27,-4,minecraft:obsidian)
B(-8,28,-4,minecraft:obsidian)
B(-8,29,-4,minecraft:diorite)
B(-8,30,-4,minecraft:diorite)
B(-8,31,-4,minecraft:diorite)
B(-8,32,-4,minecraft:diorite)
B(-8,33,-4,minecraft:obsidian)
B(-8,34,-4,minecraft:obsidian)
B(-8,35,-4,minecraft:obsidian)
B(-8,36,-4,minecraft:andesite)
B(-8,37,-4,minecraft:andesite)
B(-8,38,-4,minecraft:andesite)
B(-8,87,-4,minecraft:obsidian)
B(-8,88,-4,minecraft:obsidian)
B(-8,89,-4,minecraft:obsidian)
B(-8,90,-4,minecraft:obsidian)
B(-8,91,-4,minecraft:obsidian)
B(-8,92,-4,minecraft:obsidian)
B(-8,93,-4,minecraft:obsidian)
B(-8,94,-4,minecraft:obsidian)
B(-8,95,-4,minecraft:obsidian)
B(-8,96,-4,minecraft:obsidian)
B(-8,97,-4,minecraft:obsidian)
B(-8,98,-4,minecraft:obsidian)
B(-8,99,-4,minecraft:obsidian)
B(-8,100,-4,minecraft:obsidian)
B(-8,101,-4,minecraft:obsidian)
B(-8,102,-4,minecraft:diorite)
B(-8,103,-4,minecraft:diorite)
B(-8,20,-3,minecraft:diorite)
B(-8,21,-3,minecraft:diorite)
B(-8,22,-3,minecraft:diorite)
B(-8,23,-3,minecraft:diorite)
B(-8,24,-3,minecraft:diorite)
B(-8,25,-3,minecraft:diorite)
B(-8,26,-3,minecraft:diorite)
B(-8,27,-3,minecraft:obsidian)
B(-8,28,-3,minecraft:obsidian)
B(-8,29,-3,minecraft:obsidian)
B(-8,30,-3,minecraft:diorite)
B(-8,31,-3,minecraft:diorite)
B(-8,32,-3,minecraft:diorite)
B(-8,33,-3,minecraft:obsidian)
B(-8,34,-3,minecraft:obsidian)
B(-8,35,-3,minecraft:obsidian)
B(-8,36,-3,minecraft:andesite)
B(-8,37,-3,minecraft:andesite)
B(-8,38,-3,minecraft:andesite)
B(-8,86,-3,minecraft:obsidian)
B(-8,87,-3,minecraft:obsidian)
B(-8,88,-3,minecraft:obsidian)
B(-8,89,-3,minecraft:obsidian)
B(-8,90,-3,minecraft:obsidian)
B(-8,91,-3,minecraft:obsidian)
B(-8,92,-3,minecraft:obsidian)
B(-8,93,-3,minecraft:obsidian)
B(-8,94,-3,minecraft:obsidian)
B(-8,95,-3,minecraft:obsidian)
B(-8,96,-3,minecraft:obsidian)
B(-8,97,-3,minecraft:obsidian)
B(-8,98,-3,minecraft:obsidian)
B(-8,99,-3,minecraft:obsidian)
B(-8,100,-3,minecraft:obsidian)
B(-8,101,-3,minecraft:obsidian)
B(-8,102,-3,minecraft:diorite)
B(-8,103,-3,minecraft:diorite)
B(-8,20,-2,minecraft:diorite)
B(-8,21,-2,minecraft:diorite)
B(-8,22,-2,minecraft:diorite)
B(-8,23,-2,minecraft:diorite)
B(-8,24,-2,minecraft:diorite)
B(-8,25,-2,minecraft:diorite)
B(-8,26,-2,minecraft:diorite)
B(-8,27,-2,minecraft:obsidian)
B(-8,28,-2,minecraft:obsidian)
B(-8,29,-2,minecraft:obsidian)
B(-8,30,-2,minecraft:diorite)
B(-8,31,-2,minecraft:diorite)
B(-8,32,-2,minecraft:diorite)
B(-8,33,-2,minecraft:obsidian)
B(-8,34,-2,minecraft:obsidian)
B(-8,35,-2,minecraft:obsidian)
B(-8,36,-2,minecraft:andesite)
B(-8,37,-2,minecraft:andesite)
B(-8,38,-2,minecraft:andesite)
B(-8,39,-2,minecraft:andesite)
B(-8,87,-2,minecraft:obsidian)
B(-8,88,-2,minecraft:obsidian)
B(-8,89,-2,minecraft:obsidian)
B(-8,90,-2,minecraft:obsidian)
B(-8,91,-2,minecraft:obsidian)
B(-8,92,-2,minecraft:obsidian)
B(-8,93,-2,minecraft:obsidian)
B(-8,94,-2,minecraft:obsidian)
B(-8,95,-2,minecraft:obsidian)
B(-8,96,-2,minecraft:obsidian)
B(-8,97,-2,minecraft:diorite)
B(-8,98,-2,minecraft:diorite)
B(-8,99,-2,minecraft:diorite)
B(-8,100,-2,minecraft:diorite)
B(-8,101,-2,minecraft:diorite)
B(-8,102,-2,minecraft:diorite)
B(-8,103,-2,minecraft:diorite)
B(-8,19,-1,minecraft:diorite)
B(-8,20,-1,minecraft:diorite)
B(-8,21,-1,minecraft:diorite)
B(-8,22,-1,minecraft:diorite)
B(-8,23,-1,minecraft:diorite)
B(-8,24,-1,minecraft:diorite)
B(-8,25,-1,minecraft:diorite)
B(-8,26,-1,minecraft:obsidian)
B(-8,27,-1,minecraft:obsidian)
B(-8,28,-1,minecraft:obsidian)
B(-8,29,-1,minecraft:obsidian)
B(-8,30,-1,minecraft:diorite)
B(-8,31,-1,minecraft:diorite)
B(-8,32,-1,minecraft:diorite)
B(-8,33,-1,minecraft:diorite)
B(-8,34,-1,minecraft:obsidian)
B(-8,35,-1,minecraft:obsidian)
B(-8,36,-1,minecraft:andesite)
B(-8,37,-1,minecraft:andesite)
B(-8,38,-1,minecraft:andesite)
B(-8,39,-1,minecraft:andesite)
B(-8,40,-1,minecraft:andesite)
B(-8,86,-1,minecraft:obsidian)
B(-8,87,-1,minecraft:obsidian)
B(-8,88,-1,minecraft:obsidian)
B(-8,89,-1,minecraft:obsidian)
B(-8,90,-1,minecraft:obsidian)
B(-8,91,-1,minecraft:obsidian)
B(-8,92,-1,minecraft:obsidian)
B(-8,93,-1,minecraft:obsidian)
B(-8,94,-1,minecraft:obsidian)
B(-8,95,-1,minecraft:obsidian)
B(-8,96,-1,minecraft:diorite)
B(-8,97,-1,minecraft:diorite)
B(-8,98,-1,minecraft:diorite)
B(-8,99,-1,minecraft:diorite)
B(-8,100,-1,minecraft:diorite)
B(-8,101,-1,minecraft:diorite)
B(-8,102,-1,minecraft:diorite)
B(-8,103,-1,minecraft:diorite)
B(-8,19,0,minecraft:diorite)
B(-8,20,0,minecraft:diorite)
B(-8,21,0,minecraft:diorite)
B(-8,22,0,minecraft:diorite)
B(-8,23,0,minecraft:diorite)
B(-8,24,0,minecraft:diorite)
B(-8,25,0,minecraft:obsidian)
B(-8,26,0,minecraft:obsidian)
B(-8,27,0,minecraft:obsidian)
B(-8,28,0,minecraft:obsidian)
B(-8,29,0,minecraft:obsidian)
B(-8,30,0,minecraft:obsidian)
B(-8,31,0,minecraft:diorite)
B(-8,32,0,minecraft:diorite)
B(-8,33,0,minecraft:diorite)
B(-8,34,0,minecraft:diorite)
B(-8,35,0,minecraft:obsidian)
B(-8,36,0,minecraft:obsidian)
B(-8,37,0,minecraft:andesite)
B(-8,38,0,minecraft:andesite)
B(-8,39,0,minecraft:andesite)
B(-8,40,0,minecraft:andesite)
B(-8,86,0,minecraft:obsidian)
B(-8,87,0,minecraft:obsidian)
B(-8,88,0,minecraft:obsidian)
B(-8,89,0,minecraft:obsidian)
B(-8,90,0,minecraft:obsidian)
B(-8,91,0,minecraft:obsidian)
B(-8,92,0,minecraft:obsidian)
B(-8,93,0,minecraft:obsidian)
B(-8,94,0,minecraft:obsidian)
B(-8,95,0,minecraft:diorite)
B(-8,96,0,minecraft:diorite)
B(-8,97,0,minecraft:diorite)
B(-8,98,0,minecraft:diorite)
B(-8,99,0,minecraft:diorite)
B(-8,100,0,minecraft:diorite)
B(-8,101,0,minecraft:diorite)
B(-8,102,0,minecraft:diorite)
B(-8,103,0,minecraft:diorite)
B(-8,19,1,minecraft:diorite)
B(-8,20,1,minecraft:diorite)
B(-8,21,1,minecraft:diorite)
B(-8,22,1,minecraft:diorite)
B(-8,23,1,minecraft:diorite)
B(-8,24,1,minecraft:obsidian)
B(-8,25,1,minecraft:obsidian)
B(-8,26,1,minecraft:obsidian)
B(-8,27,1,minecraft:obsidian)
B(-8,28,1,minecraft:obsidian)
B(-8,29,1,minecraft:obsidian)
B(-8,30,1,minecraft:obsidian)
B(-8,31,1,minecraft:diorite)
B(-8,32,1,minecraft:diorite)
B(-8,33,1,minecraft:diorite)
B(-8,34,1,minecraft:diorite)
B(-8,35,1,minecraft:obsidian)
B(-8,36,1,minecraft:obsidian)
B(-8,37,1,minecraft:andesite)
B(-8,38,1,minecraft:andesite)
B(-8,39,1,minecraft:andesite)
B(-8,40,1,minecraft:andesite)
B(-8,86,1,minecraft:obsidian)
B(-8,87,1,minecraft:obsidian)
B(-8,88,1,minecraft:obsidian)
B(-8,89,1,minecraft:obsidian)
B(-8,90,1,minecraft:obsidian)
B(-8,91,1,minecraft:obsidian)
B(-8,92,1,minecraft:obsidian)
B(-8,93,1,minecraft:diorite)
B(-8,94,1,minecraft:diorite)
B(-8,95,1,minecraft:diorite)
B(-8,96,1,minecraft:diorite)
B(-8,97,1,minecraft:diorite)
B(-8,98,1,minecraft:diorite)
B(-8,99,1,minecraft:diorite)
B(-8,100,1,minecraft:diorite)
B(-8,101,1,minecraft:diorite)
B(-8,102,1,minecraft:diorite)
B(-8,103,1,minecraft:diorite)
B(-8,19,2,minecraft:diorite)
B(-8,20,2,minecraft:diorite)
B(-8,21,2,minecraft:diorite)
B(-8,22,2,minecraft:diorite)
B(-8,23,2,minecraft:obsidian)
B(-8,24,2,minecraft:obsidian)
B(-8,25,2,minecraft:obsidian)
B(-8,26,2,minecraft:obsidian)
B(-8,27,2,minecraft:obsidian)
B(-8,28,2,minecraft:obsidian)
B(-8,29,2,minecraft:obsidian)
B(-8,30,2,minecraft:obsidian)
B(-8,31,2,minecraft:diorite)
B(-8,32,2,minecraft:diorite)
B(-8,33,2,minecraft:diorite)
B(-8,34,2,minecraft:diorite)
B(-8,35,2,minecraft:obsidian)
B(-8,36,2,minecraft:obsidian)
B(-8,37,2,minecraft:andesite)
B(-8,38,2,minecraft:andesite)
B(-8,39,2,minecraft:andesite)
B(-8,40,2,minecraft:andesite)
B(-8,85,2,minecraft:diorite)
B(-8,86,2,minecraft:diorite)
B(-8,87,2,minecraft:obsidian)
B(-8,88,2,minecraft:obsidian)
B(-8,89,2,minecraft:obsidian)
B(-8,90,2,minecraft:obsidian)
B(-8,91,2,minecraft:obsidian)
B(-8,92,2,minecraft:diorite)
B(-8,93,2,minecraft:diorite)
B(-8,94,2,minecraft:diorite)
B(-8,95,2,minecraft:diorite)
B(-8,96,2,minecraft:diorite)
B(-8,97,2,minecraft:diorite)
B(-8,98,2,minecraft:diorite)
B(-8,99,2,minecraft:diorite)
B(-8,100,2,minecraft:diorite)
B(-8,101,2,minecraft:diorite)
B(-8,102,2,minecraft:andesite)
B(-8,19,3,minecraft:diorite)
B(-8,20,3,minecraft:diorite)
B(-8,21,3,minecraft:diorite)
B(-8,22,3,minecraft:diorite)
B(-8,23,3,minecraft:diorite)
B(-8,24,3,minecraft:obsidian)
B(-8,25,3,minecraft:obsidian)
B(-8,26,3,minecraft:obsidian)
B(-8,27,3,minecraft:obsidian)
B(-8,28,3,minecraft:obsidian)
B(-8,29,3,minecraft:obsidian)
B(-8,30,3,minecraft:obsidian)
B(-8,31,3,minecraft:diorite)
B(-8,32,3,minecraft:diorite)
B(-8,33,3,minecraft:diorite)
B(-8,34,3,minecraft:diorite)
B(-8,35,3,minecraft:obsidian)
B(-8,36,3,minecraft:obsidian)
B(-8,37,3,minecraft:andesite)
B(-8,38,3,minecraft:andesite)
B(-8,39,3,minecraft:andesite)
B(-8,40,3,minecraft:andesite)
B(-8,84,3,minecraft:diorite)
B(-8,85,3,minecraft:diorite)
B(-8,86,3,minecraft:diorite)
B(-8,87,3,minecraft:obsidian)
B(-8,88,3,minecraft:obsidian)
B(-8,89,3,minecraft:obsidian)
B(-8,90,3,minecraft:obsidian)
B(-8,91,3,minecraft:diorite)
B(-8,92,3,minecraft:diorite)
B(-8,93,3,minecraft:diorite)
B(-8,94,3,minecraft:diorite)
B(-8,95,3,minecraft:diorite)
B(-8,96,3,minecraft:diorite)
B(-8,97,3,minecraft:diorite)
B(-8,98,3,minecraft:diorite)
B(-8,99,3,minecraft:andesite)
B(-8,19,4,minecraft:diorite)
B(-8,20,4,minecraft:diorite)
B(-8,21,4,minecraft:diorite)
B(-8,22,4,minecraft:diorite)
B(-8,23,4,minecraft:diorite)
B(-8,24,4,minecraft:diorite)
B(-8,25,4,minecraft:obsidian)
B(-8,26,4,minecraft:obsidian)
B(-8,27,4,minecraft:obsidian)
B(-8,28,4,minecraft:obsidian)
B(-8,29,4,minecraft:obsidian)
B(-8,30,4,minecraft:obsidian)
B(-8,31,4,minecraft:obsidian)
B(-8,32,4,minecraft:diorite)
B(-8,33,4,minecraft:diorite)
B(-8,34,4,minecraft:diorite)
B(-8,35,4,minecraft:obsidian)
B(-8,36,4,minecraft:obsidian)
B(-8,37,4,minecraft:obsidian)
B(-8,38,4,minecraft:andesite)
B(-8,39,4,minecraft:andesite)
B(-8,40,4,minecraft:andesite)
B(-8,83,4,minecraft:diorite)
B(-8,84,4,minecraft:diorite)
B(-8,85,4,minecraft:diorite)
B(-8,86,4,minecraft:diorite)
B(-8,87,4,minecraft:obsidian)
B(-8,88,4,minecraft:obsidian)
B(-8,89,4,minecraft:obsidian)
B(-8,90,4,minecraft:obsidian)
B(-8,91,4,minecraft:diorite)
B(-8,92,4,minecraft:diorite)
B(-8,93,4,minecraft:diorite)
B(-8,94,4,minecraft:diorite)
B(-8,95,4,minecraft:diorite)
B(-8,96,4,minecraft:diorite)
B(-8,97,4,minecraft:andesite)
B(-8,19,5,minecraft:diorite)
B(-8,20,5,minecraft:diorite)
B(-8,21,5,minecraft:diorite)
B(-8,22,5,minecraft:diorite)
B(-8,23,5,minecraft:diorite)
B(-8,24,5,minecraft:diorite)
B(-8,25,5,minecraft:obsidian)
B(-8,26,5,minecraft:obsidian)
B(-8,27,5,minecraft:obsidian)
B(-8,28,5,minecraft:obsidian)
B(-8,29,5,minecraft:obsidian)
B(-8,30,5,minecraft:obsidian)
B(-8,31,5,minecraft:obsidian)
B(-8,32,5,minecraft:obsidian)
B(-8,33,5,minecraft:diorite)
B(-8,34,5,minecraft:diorite)
B(-8,35,5,minecraft:diorite)
B(-8,36,5,minecraft:stone)
B(-8,37,5,minecraft:obsidian)
B(-8,38,5,minecraft:obsidian)
B(-8,39,5,minecraft:andesite)
B(-8,40,5,minecraft:andesite)
B(-8,83,5,minecraft:diorite)
B(-8,84,5,minecraft:diorite)
B(-8,85,5,minecraft:diorite)
B(-8,86,5,minecraft:diorite)
B(-8,87,5,minecraft:obsidian)
B(-8,88,5,minecraft:obsidian)
B(-8,89,5,minecraft:obsidian)
B(-8,90,5,minecraft:obsidian)
B(-8,91,5,minecraft:diorite)
B(-8,92,5,minecraft:diorite)
B(-8,93,5,minecraft:diorite)
B(-8,94,5,minecraft:diorite)
B(-8,95,5,minecraft:diorite)
B(-8,96,5,minecraft:diorite)
B(-8,97,5,minecraft:andesite)
B(-8,18,6,minecraft:diorite)
B(-8,19,6,minecraft:diorite)
B(-8,20,6,minecraft:diorite)
B(-8,21,6,minecraft:diorite)
B(-8,22,6,minecraft:diorite)
B(-8,23,6,minecraft:diorite)
B(-8,24,6,minecraft:diorite)
B(-8,25,6,minecraft:obsidian)
B(-8,26,6,minecraft:obsidian)
B(-8,27,6,minecraft:obsidian)
B(-8,28,6,minecraft:obsidian)
B(-8,29,6,minecraft:obsidian)
B(-8,30,6,minecraft:obsidian)
B(-8,31,6,minecraft:obsidian)
B(-8,32,6,minecraft:obsidian)
B(-8,33,6,minecraft:obsidian)
B(-8,34,6,minecraft:diorite)
B(-8,35,6,minecraft:diorite)
B(-8,36,6,minecraft:diorite)
B(-8,37,6,minecraft:obsidian)
B(-8,38,6,minecraft:obsidian)
B(-8,39,6,minecraft:andesite)
B(-8,40,6,minecraft:andesite)
B(-8,41,6,minecraft:andesite)
B(-8,82,6,minecraft:diorite)
B(-8,83,6,minecraft:diorite)
B(-8,84,6,minecraft:diorite)
B(-8,85,6,minecraft:diorite)
B(-8,86,6,minecraft:diorite)
B(-8,87,6,minecraft:obsidian)
B(-8,88,6,minecraft:obsidian)
B(-8,89,6,minecraft:obsidian)
B(-8,90,6,minecraft:obsidian)
B(-8,91,6,minecraft:diorite)
B(-8,92,6,minecraft:diorite)
B(-8,93,6,minecraft:diorite)
B(-8,94,6,minecraft:diorite)
B(-8,95,6,minecraft:diorite)
B(-8,96,6,minecraft:andesite)
B(-8,16,7,minecraft:diorite)
B(-8,17,7,minecraft:diorite)
B(-8,18,7,minecraft:diorite)
B(-8,19,7,minecraft:diorite)
B(-8,20,7,minecraft:diorite)
B(-8,21,7,minecraft:diorite)
B(-8,22,7,minecraft:diorite)
B(-8,23,7,minecraft:diorite)
B(-8,24,7,minecraft:diorite)
B(-8,25,7,minecraft:obsidian)
B(-8,26,7,minecraft:obsidian)
B(-8,27,7,minecraft:obsidian)
B(-8,28,7,minecraft:obsidian)
B(-8,29,7,minecraft:obsidian)
B(-8,30,7,minecraft:obsidian)
B(-8,31,7,minecraft:obsidian)
B(-8,32,7,minecraft:obsidian)
B(-8,33,7,minecraft:obsidian)
B(-8,34,7,minecraft:obsidian)
B(-8,35,7,minecraft:obsidian)
B(-8,36,7,minecraft:obsidian)
B(-8,37,7,minecraft:obsidian)
B(-8,38,7,minecraft:obsidian)
B(-8,39,7,minecraft:andesite)
B(-8,40,7,minecraft:andesite)
B(-8,41,7,minecraft:andesite)
B(-8,81,7,minecraft:diorite)
B(-8,82,7,minecraft:diorite)
B(-8,83,7,minecraft:diorite)
B(-8,84,7,minecraft:diorite)
B(-8,85,7,minecraft:diorite)
B(-8,86,7,minecraft:obsidian)
B(-8,87,7,minecraft:obsidian)
B(-8,88,7,minecraft:obsidian)
B(-8,89,7,minecraft:obsidian)
B(-8,90,7,minecraft:obsidian)
B(-8,91,7,minecraft:diorite)
B(-8,92,7,minecraft:diorite)
B(-8,93,7,minecraft:diorite)
B(-8,94,7,minecraft:andesite)
B(-8,15,8,minecraft:diorite)
B(-8,16,8,minecraft:diorite)
B(-8,17,8,minecraft:diorite)
B(-8,18,8,minecraft:diorite)
B(-8,19,8,minecraft:diorite)
B(-8,20,8,minecraft:diorite)
B(-8,21,8,minecraft:diorite)
B(-8,22,8,minecraft:diorite)
B(-8,23,8,minecraft:diorite)
B(-8,24,8,minecraft:diorite)
B(-8,25,8,minecraft:obsidian)
B(-8,26,8,minecraft:obsidian)
B(-8,27,8,minecraft:obsidian)
B(-8,28,8,minecraft:obsidian)
B(-8,29,8,minecraft:obsidian)
B(-8,30,8,minecraft:obsidian)
B(-8,31,8,minecraft:obsidian)
B(-8,32,8,minecraft:obsidian)
B(-8,33,8,minecraft:obsidian)
B(-8,34,8,minecraft:obsidian)
B(-8,35,8,minecraft:obsidian)
B(-8,36,8,minecraft:obsidian)
B(-8,37,8,minecraft:obsidian)
B(-8,38,8,minecraft:obsidian)
B(-8,39,8,minecraft:andesite)
B(-8,40,8,minecraft:andesite)
B(-8,41,8,minecraft:andesite)
B(-8,79,8,minecraft:diorite)
B(-8,80,8,minecraft:diorite)
B(-8,81,8,minecraft:diorite)
B(-8,82,8,minecraft:diorite)
B(-8,83,8,minecraft:diorite)
B(-8,84,8,minecraft:obsidian)
B(-8,85,8,minecraft:obsidian)
B(-8,86,8,minecraft:obsidian)
B(-8,87,8,minecraft:obsidian)
B(-8,88,8,minecraft:obsidian)
B(-8,89,8,minecraft:obsidian)
B(-8,90,8,minecraft:obsidian)
B(-8,91,8,minecraft:obsidian)
B(-8,92,8,minecraft:diorite)
B(-8,93,8,minecraft:andesite)
B(-7,21,-7,minecraft:diorite)
B(-7,22,-7,minecraft:diorite)
B(-7,23,-7,minecraft:diorite)
B(-7,24,-7,minecraft:diorite)
B(-7,25,-7,minecraft:diorite)
B(-7,26,-7,minecraft:obsidian)
B(-7,27,-7,minecraft:diorite)
B(-7,28,-7,minecraft:diorite)
B(-7,29,-7,minecraft:diorite)
B(-7,30,-7,minecraft:diorite)
B(-7,31,-7,minecraft:diorite)
B(-7,32,-7,minecraft:diorite)
B(-7,33,-7,minecraft:diorite)
B(-7,34,-7,minecraft:diorite)
B(-7,35,-7,minecraft:diorite)
B(-7,36,-7,minecraft:lava)
B(-7,37,-7,minecraft:lava)
B(-7,87,-7,minecraft:obsidian)
B(-7,88,-7,minecraft:obsidian)
B(-7,89,-7,minecraft:obsidian)
B(-7,90,-7,minecraft:obsidian)
B(-7,91,-7,minecraft:obsidian)
B(-7,92,-7,minecraft:obsidian)
B(-7,93,-7,minecraft:obsidian)
B(-7,94,-7,minecraft:obsidian)
B(-7,95,-7,minecraft:obsidian)
B(-7,96,-7,minecraft:obsidian)
B(-7,97,-7,minecraft:obsidian)
B(-7,98,-7,minecraft:obsidian)
B(-7,99,-7,minecraft:obsidian)
B(-7,100,-7,minecraft:diorite)
B(-7,101,-7,minecraft:andesite)
B(-7,21,-6,minecraft:diorite)
B(-7,22,-6,minecraft:diorite)
B(-7,23,-6,minecraft:diorite)
B(-7,24,-6,minecraft:diorite)
B(-7,25,-6,minecraft:diorite)
B(-7,26,-6,minecraft:obsidian)
B(-7,27,-6,minecraft:obsidian)
B(-7,28,-6,minecraft:diorite)
B(-7,29,-6,minecraft:diorite)
B(-7,30,-6,minecraft:diorite)
B(-7,31,-6,minecraft:diorite)
B(-7,32,-6,minecraft:diorite)
B(-7,33,-6,minecraft:diorite)
B(-7,34,-6,minecraft:diorite)
B(-7,35,-6,minecraft:diorite)
B(-7,36,-6,minecraft:obsidian)
B(-7,37,-6,minecraft:lava)
B(-7,87,-6,minecraft:obsidian)
B(-7,88,-6,minecraft:obsidian)
B(-7,89,-6,minecraft:obsidian)
B(-7,90,-6,minecraft:obsidian)
B(-7,91,-6,minecraft:obsidian)
B(-7,92,-6,minecraft:obsidian)
B(-7,93,-6,minecraft:obsidian)
B(-7,94,-6,minecraft:obsidian)
B(-7,95,-6,minecraft:obsidian)
B(-7,96,-6,minecraft:obsidian)
B(-7,97,-6,minecraft:obsidian)
B(-7,98,-6,minecraft:obsidian)
B(-7,99,-6,minecraft:obsidian)
B(-7,100,-6,minecraft:obsidian)
B(-7,101,-6,minecraft:diorite)
B(-7,102,-6,minecraft:andesite)
B(-7,21,-5,minecraft:diorite)
B(-7,22,-5,minecraft:diorite)
B(-7,23,-5,minecraft:diorite)
B(-7,24,-5,minecraft:diorite)
B(-7,25,-5,minecraft:diorite)
B(-7,26,-5,minecraft:diorite)
B(-7,27,-5,minecraft:obsidian)
B(-7,28,-5,minecraft:obsidian)
B(-7,29,-5,minecraft:diorite)
B(-7,30,-5,minecraft:diorite)
B(-7,31,-5,minecraft:diorite)
B(-7,32,-5,minecraft:diorite)
B(-7,33,-5,minecraft:diorite)
B(-7,34,-5,minecraft:obsidian)
B(-7,35,-5,minecraft:obsidian)
B(-7,36,-5,minecraft:obsidian)
B(-7,37,-5,minecraft:obsidian)
B(-7,87,-5,minecraft:obsidian)
B(-7,88,-5,minecraft:obsidian)
B(-7,89,-5,minecraft:obsidian)
B(-7,90,-5,minecraft:obsidian)
B(-7,91,-5,minecraft:obsidian)
B(-7,92,-5,minecraft:obsidian)
B(-7,93,-5,minecraft:obsidian)
B(-7,94,-5,minecraft:obsidian)
B(-7,95,-5,minecraft:obsidian)
B(-7,96,-5,minecraft:obsidian)
B(-7,97,-5,minecraft:obsidian)
B(-7,98,-5,minecraft:obsidian)
B(-7,99,-5,minecraft:obsidian)
B(-7,100,-5,minecraft:obsidian)
B(-7,101,-5,minecraft:diorite)
B(-7,102,-5,minecraft:andesite)
B(-7,21,-4,minecraft:diorite)
B(-7,22,-4,minecraft:diorite)
B(-7,23,-4,minecraft:diorite)
B(-7,24,-4,minecraft:diorite)
B(-7,25,-4,minecraft:diorite)
B(-7,26,-4,minecraft:diorite)
B(-7,27,-4,minecraft:obsidian)
B(-7,28,-4,minecraft:obsidian)
B(-7,29,-4,minecraft:diorite)
B(-7,30,-4,minecraft:diorite)
B(-7,31,-4,minecraft:diorite)
B(-7,32,-4,minecraft:diorite)
B(-7,33,-4,minecraft:obsidian)
B(-7,34,-4,minecraft:obsidian)
B(-7,35,-4,minecraft:obsidian)
B(-7,36,-4,minecraft:obsidian)
B(-7,37,-4,minecraft:andesite)
B(-7,87,-4,minecraft:obsidian)
B(-7,88,-4,minecraft:obsidian)
B(-7,89,-4,minecraft:obsidian)
B(-7,90,-4,minecraft:obsidian)
B(-7,91,-4,minecraft:obsidian)
B(-7,92,-4,minecraft:obsidian)
B(-7,93,-4,minecraft:obsidian)
B(-7,94,-4,minecraft:obsidian)
B(-7,95,-4,minecraft:obsidian)
B(-7,96,-4,minecraft:obsidian)
B(-7,97,-4,minecraft:obsidian)
B(-7,98,-4,minecraft:obsidian)
B(-7,99,-4,minecraft:obsidian)
B(-7,100,-4,minecraft:obsidian)
B(-7,101,-4,minecraft:obsidian)
B(-7,102,-4,minecraft:diorite)
B(-7,103,-4,minecraft:diorite)
B(-7,21,-3,minecraft:diorite)
B(-7,22,-3,minecraft:diorite)
B(-7,23,-3,minecraft:diorite)
B(-7,24,-3,minecraft:diorite)
B(-7,25,-3,minecraft:diorite)
B(-7,26,-3,minecraft:diorite)
B(-7,27,-3,minecraft:obsidian)
B(-7,28,-3,minecraft:obsidian)
B(-7,29,-3,minecraft:obsidian)
B(-7,30,-3,minecraft:diorite)
B(-7,31,-3,minecraft:diorite)
B(-7,32,-3,minecraft:diorite)
B(-7,33,-3,minecraft:obsidian)
B(-7,34,-3,minecraft:obsidian)
B(-7,35,-3,minecraft:obsidian)
B(-7,36,-3,minecraft:obsidian)
B(-7,37,-3,minecraft:andesite)
B(-7,38,-3,minecraft:andesite)
B(-7,87,-3,minecraft:obsidian)
B(-7,88,-3,minecraft:obsidian)
B(-7,89,-3,minecraft:obsidian)
B(-7,90,-3,minecraft:obsidian)
B(-7,91,-3,minecraft:obsidian)
B(-7,92,-3,minecraft:obsidian)
B(-7,93,-3,minecraft:obsidian)
B(-7,94,-3,minecraft:obsidian)
B(-7,95,-3,minecraft:obsidian)
B(-7,96,-3,minecraft:obsidian)
B(-7,97,-3,minecraft:obsidian)
B(-7,98,-3,minecraft:obsidian)
B(-7,99,-3,minecraft:obsidian)
B(-7,100,-3,minecraft:obsidian)
B(-7,101,-3,minecraft:obsidian)
B(-7,102,-3,minecraft:diorite)
B(-7,103,-3,minecraft:diorite)
B(-7,21,-2,minecraft:diorite)
B(-7,22,-2,minecraft:diorite)
B(-7,23,-2,minecraft:diorite)
B(-7,24,-2,minecraft:diorite)
B(-7,25,-2,minecraft:diorite)
B(-7,26,-2,minecraft:obsidian)
B(-7,27,-2,minecraft:obsidian)
B(-7,28,-2,minecraft:obsidian)
B(-7,29,-2,minecraft:obsidian)
B(-7,30,-2,minecraft:diorite)
B(-7,31,-2,minecraft:diorite)
B(-7,32,-2,minecraft:diorite)
B(-7,33,-2,minecraft:obsidian)
B(-7,34,-2,minecraft:obsidian)
B(-7,35,-2,minecraft:obsidian)
B(-7,36,-2,minecraft:obsidian)
B(-7,37,-2,minecraft:andesite)
B(-7,38,-2,minecraft:andesite)
B(-7,87,-2,minecraft:obsidian)
B(-7,88,-2,minecraft:obsidian)
B(-7,89,-2,minecraft:obsidian)
B(-7,90,-2,minecraft:obsidian)
B(-7,91,-2,minecraft:obsidian)
B(-7,92,-2,minecraft:obsidian)
B(-7,93,-2,minecraft:obsidian)
B(-7,94,-2,minecraft:obsidian)
B(-7,95,-2,minecraft:obsidian)
B(-7,96,-2,minecraft:obsidian)
B(-7,97,-2,minecraft:obsidian)
B(-7,98,-2,minecraft:diorite)
B(-7,99,-2,minecraft:diorite)
B(-7,100,-2,minecraft:diorite)
B(-7,101,-2,minecraft:diorite)
B(-7,102,-2,minecraft:diorite)
B(-7,103,-2,minecraft:diorite)
B(-7,20,-1,minecraft:diorite)
B(-7,21,-1,minecraft:diorite)
B(-7,22,-1,minecraft:diorite)
B(-7,23,-1,minecraft:diorite)
B(-7,24,-1,minecraft:diorite)
B(-7,25,-1,minecraft:diorite)
B(-7,26,-1,minecraft:obsidian)
B(-7,27,-1,minecraft:obsidian)
B(-7,28,-1,minecraft:obsidian)
B(-7,29,-1,minecraft:obsidian)
B(-7,30,-1,minecraft:obsidian)
B(-7,31,-1,minecraft:diorite)
B(-7,32,-1,minecraft:diorite)
B(-7,33,-1,minecraft:diorite)
B(-7,34,-1,minecraft:obsidian)
B(-7,35,-1,minecraft:obsidian)
B(-7,36,-1,minecraft:obsidian)
B(-7,37,-1,minecraft:andesite)
B(-7,38,-1,minecraft:andesite)
B(-7,87,-1,minecraft:obsidian)
B(-7,88,-1,minecraft:obsidian)
B(-7,89,-1,minecraft:obsidian)
B(-7,90,-1,minecraft:obsidian)
B(-7,91,-1,minecraft:obsidian)
B(-7,92,-1,minecraft:obsidian)
B(-7,93,-1,minecraft:obsidian)
B(-7,94,-1,minecraft:obsidian)
B(-7,95,-1,minecraft:obsidian)
B(-7,96,-1,minecraft:diorite)
B(-7,97,-1,minecraft:diorite)
B(-7,98,-1,minecraft:diorite)
B(-7,99,-1,minecraft:diorite)
B(-7,100,-1,minecraft:diorite)
B(-7,101,-1,minecraft:diorite)
B(-7,102,-1,minecraft:diorite)
B(-7,103,-1,minecraft:diorite)
B(-7,19,0,minecraft:diorite)
B(-7,20,0,minecraft:diorite)
B(-7,21,0,minecraft:diorite)
B(-7,22,0,minecraft:diorite)
B(-7,23,0,minecraft:diorite)
B(-7,24,0,minecraft:diorite)
B(-7,25,0,minecraft:obsidian)
B(-7,26,0,minecraft:obsidian)
B(-7,27,0,minecraft:obsidian)
B(-7,28,0,minecraft:obsidian)
B(-7,29,0,minecraft:obsidian)
B(-7,30,0,minecraft:obsidian)
B(-7,31,0,minecraft:diorite)
B(-7,32,0,minecraft:diorite)
B(-7,33,0,minecraft:diorite)
B(-7,34,0,minecraft:diorite)
B(-7,35,0,minecraft:obsidian)
B(-7,36,0,minecraft:obsidian)
B(-7,37,0,minecraft:andesite)
B(-7,38,0,minecraft:andesite)
B(-7,39,0,minecraft:andesite)
B(-7,86,0,minecraft:obsidian)
B(-7,87,0,minecraft:obsidian)
B(-7,88,0,minecraft:obsidian)
B(-7,89,0,minecraft:obsidian)
B(-7,90,0,minecraft:obsidian)
B(-7,91,0,minecraft:obsidian)
B(-7,92,0,minecraft:obsidian)
B(-7,93,0,minecraft:obsidian)
B(-7,94,0,minecraft:diorite)
B(-7,95,0,minecraft:diorite)
B(-7,96,0,minecraft:diorite)
B(-7,97,0,minecraft:diorite)
B(-7,98,0,minecraft:diorite)
B(-7,99,0,minecraft:diorite)
B(-7,100,0,minecraft:diorite)
B(-7,101,0,minecraft:diorite)
B(-7,102,0,minecraft:diorite)
B(-7,103,0,minecraft:diorite)
B(-7,19,1,minecraft:diorite)
B(-7,20,1,minecraft:diorite)
B(-7,21,1,minecraft:diorite)
B(-7,22,1,minecraft:diorite)
B(-7,23,1,minecraft:diorite)
B(-7,24,1,minecraft:obsidian)
B(-7,25,1,minecraft:obsidian)
B(-7,26,1,minecraft:obsidian)
B(-7,27,1,minecraft:obsidian)
B(-7,28,1,minecraft:obsidian)
B(-7,29,1,minecraft:obsidian)
B(-7,30,1,minecraft:obsidian)
B(-7,31,1,minecraft:diorite)
B(-7,32,1,minecraft:diorite)
B(-7,33,1,minecraft:diorite)
B(-7,34,1,minecraft:obsidian)
B(-7,35,1,minecraft:obsidian)
B(-7,36,1,minecraft:obsidian)
B(-7,37,1,minecraft:andesite)
B(-7,38,1,minecraft:andesite)
B(-7,39,1,minecraft:andesite)
B(-7,86,1,minecraft:diorite)
B(-7,87,1,minecraft:diorite)
B(-7,88,1,minecraft:obsidian)
B(-7,89,1,minecraft:obsidian)
B(-7,90,1,minecraft:obsidian)
B(-7,91,1,minecraft:obsidian)
B(-7,92,1,minecraft:diorite)
B(-7,93,1,minecraft:diorite)
B(-7,94,1,minecraft:diorite)
B(-7,95,1,minecraft:diorite)
B(-7,96,1,minecraft:diorite)
B(-7,97,1,minecraft:diorite)
B(-7,98,1,minecraft:diorite)
B(-7,99,1,minecraft:diorite)
B(-7,100,1,minecraft:diorite)
B(-7,101,1,minecraft:diorite)
B(-7,102,1,minecraft:diorite)
B(-7,103,1,minecraft:diorite)
B(-7,19,2,minecraft:diorite)
B(-7,20,2,minecraft:diorite)
B(-7,21,2,minecraft:diorite)
B(-7,22,2,minecraft:diorite)
B(-7,23,2,minecraft:diorite)
B(-7,24,2,minecraft:obsidian)
B(-7,25,2,minecraft:obsidian)
B(-7,26,2,minecraft:obsidian)
B(-7,27,2,minecraft:obsidian)
B(-7,28,2,minecraft:obsidian)
B(-7,29,2,minecraft:obsidian)
B(-7,30,2,minecraft:obsidian)
B(-7,31,2,minecraft:diorite)
B(-7,32,2,minecraft:diorite)
B(-7,33,2,minecraft:diorite)
B(-7,34,2,minecraft:obsidian)
B(-7,35,2,minecraft:obsidian)
B(-7,36,2,minecraft:obsidian)
B(-7,37,2,minecraft:obsidian)
B(-7,38,2,minecraft:andesite)
B(-7,39,2,minecraft:andesite)
B(-7,85,2,minecraft:diorite)
B(-7,86,2,minecraft:diorite)
B(-7,87,2,minecraft:diorite)
B(-7,88,2,minecraft:obsidian)
B(-7,89,2,minecraft:obsidian)
B(-7,90,2,minecraft:obsidian)
B(-7,91,2,minecraft:diorite)
B(-7,92,2,minecraft:diorite)
B(-7,93,2,minecraft:diorite)
B(-7,94,2,minecraft:diorite)
B(-7,95,2,minecraft:diorite)
B(-7,96,2,minecraft:diorite)
B(-7,97,2,minecraft:diorite)
B(-7,98,2,minecraft:diorite)
B(-7,99,2,minecraft:diorite)
B(-7,100,2,minecraft:diorite)
B(-7,101,2,minecraft:diorite)
B(-7,102,2,minecraft:andesite)
B(-7,19,3,minecraft:diorite)
B(-7,20,3,minecraft:diorite)
B(-7,21,3,minecraft:diorite)
B(-7,22,3,minecraft:diorite)
B(-7,23,3,minecraft:diorite)
B(-7,24,3,minecraft:obsidian)
B(-7,25,3,minecraft:obsidian)
B(-7,26,3,minecraft:obsidian)
B(-7,27,3,minecraft:obsidian)
B(-7,28,3,minecraft:obsidian)
B(-7,29,3,minecraft:obsidian)
B(-7,30,3,minecraft:obsidian)
B(-7,31,3,minecraft:diorite)
B(-7,32,3,minecraft:diorite)
B(-7,33,3,minecraft:diorite)
B(-7,34,3,minecraft:obsidian)
B(-7,35,3,minecraft:obsidian)
B(-7,36,3,minecraft:obsidian)
B(-7,37,3,minecraft:obsidian)
B(-7,38,3,minecraft:andesite)
B(-7,39,3,minecraft:andesite)
B(-7,40,3,minecraft:andesite)
B(-7,84,3,minecraft:diorite)
B(-7,85,3,minecraft:diorite)
B(-7,86,3,minecraft:diorite)
B(-7,87,3,minecraft:diorite)
B(-7,88,3,minecraft:obsidian)
B(-7,89,3,minecraft:obsidian)
B(-7,90,3,minecraft:obsidian)
B(-7,91,3,minecraft:diorite)
B(-7,92,3,minecraft:diorite)
B(-7,93,3,minecraft:diorite)
B(-7,94,3,minecraft:diorite)
B(-7,95,3,minecraft:diorite)
B(-7,96,3,minecraft:diorite)
B(-7,97,3,minecraft:diorite)
B(-7,98,3,minecraft:diorite)
B(-7,99,3,minecraft:andesite)
B(-7,19,4,minecraft:diorite)
B(-7,20,4,minecraft:diorite)
B(-7,21,4,minecraft:diorite)
B(-7,22,4,minecraft:diorite)
B(-7,23,4,minecraft:diorite)
B(-7,24,4,minecraft:diorite)
B(-7,25,4,minecraft:obsidian)
B(-7,26,4,minecraft:obsidian)
B(-7,27,4,minecraft:obsidian)
B(-7,28,4,minecraft:obsidian)
B(-7,29,4,minecraft:obsidian)
B(-7,30,4,minecraft:obsidian)
B(-7,31,4,minecraft:obsidian)
B(-7,32,4,minecraft:diorite)
B(-7,33,4,minecraft:diorite)
B(-7,34,4,minecraft:diorite)
B(-7,35,4,minecraft:obsidian)
B(-7,36,4,minecraft:obsidian)
B(-7,37,4,minecraft:obsidian)
B(-7,38,4,minecraft:andesite)
B(-7,39,4,minecraft:andesite)
B(-7,40,4,minecraft:andesite)
B(-7,84,4,minecraft:diorite)
B(-7,85,4,minecraft:diorite)
B(-7,86,4,minecraft:diorite)
B(-7,87,4,minecraft:diorite)
B(-7,88,4,minecraft:obsidian)
B(-7,89,4,minecraft:obsidian)
B(-7,90,4,minecraft:diorite)
B(-7,91,4,minecraft:diorite)
B(-7,92,4,minecraft:diorite)
B(-7,93,4,minecraft:diorite)
B(-7,94,4,minecraft:diorite)
B(-7,95,4,minecraft:diorite)
B(-7,96,4,minecraft:diorite)
B(-7,97,4,minecraft:andesite)
B(-7,19,5,minecraft:diorite)
B(-7,20,5,minecraft:diorite)
B(-7,21,5,minecraft:diorite)
B(-7,22,5,minecraft:diorite)
B(-7,23,5,minecraft:diorite)
B(-7,24,5,minecraft:diorite)
B(-7,25,5,minecraft:obsidian)
B(-7,26,5,minecraft:obsidian)
B(-7,27,5,minecraft:obsidian)
B(-7,28,5,minecraft:obsidian)
B(-7,29,5,minecraft:obsidian)
B(-7,30,5,minecraft:obsidian)
B(-7,31,5,minecraft:obsidian)
B(-7,32,5,minecraft:obsidian)
B(-7,33,5,minecraft:diorite)
B(-7,34,5,minecraft:diorite)
B(-7,35,5,minecraft:diorite)
B(-7,36,5,minecraft:obsidian)
B(-7,37,5,minecraft:obsidian)
B(-7,38,5,minecraft:andesite)
B(-7,39,5,minecraft:andesite)
B(-7,40,5,minecraft:andesite)
B(-7,83,5,minecraft:diorite)
B(-7,84,5,minecraft:diorite)
B(-7,85,5,minecraft:diorite)
B(-7,86,5,minecraft:diorite)
B(-7,87,5,minecraft:obsidian)
B(-7,88,5,minecraft:obsidian)
B(-7,89,5,minecraft:obsidian)
B(-7,90,5,minecraft:diorite)
B(-7,91,5,minecraft:diorite)
B(-7,92,5,minecraft:diorite)
B(-7,93,5,minecraft:diorite)
B(-7,94,5,minecraft:diorite)
B(-7,95,5,minecraft:diorite)
B(-7,96,5,minecraft:andesite)
B(-7,19,6,minecraft:diorite)
B(-7,20,6,minecraft:diorite)
B(-7,21,6,minecraft:diorite)
B(-7,22,6,minecraft:diorite)
B(-7,23,6,minecraft:diorite)
B(-7,24,6,minecraft:diorite)
B(-7,25,6,minecraft:obsidian)
B(-7,26,6,minecraft:obsidian)
B(-7,27,6,minecraft:obsidian)
B(-7,28,6,minecraft:obsidian)
B(-7,29,6,minecraft:obsidian)
B(-7,30,6,minecraft:obsidian)
B(-7,31,6,minecraft:obsidian)
B(-7,32,6,minecraft:obsidian)
B(-7,33,6,minecraft:obsidian)
B(-7,34,6,minecraft:diorite)
B(-7,35,6,minecraft:diorite)
B(-7,36,6,minecraft:diorite)
B(-7,37,6,minecraft:obsidian)
B(-7,38,6,minecraft:obsidian)
B(-7,39,6,minecraft:andesite)
B(-7,40,6,minecraft:andesite)
B(-7,41,6,minecraft:andesite)
B(-7,83,6,minecraft:diorite)
B(-7,84,6,minecraft:diorite)
B(-7,85,6,minecraft:diorite)
B(-7,86,6,minecraft:diorite)
B(-7,87,6,minecraft:obsidian)
B(-7,88,6,minecraft:obsidian)
B(-7,89,6,minecraft:obsidian)
B(-7,90,6,minecraft:diorite)
B(-7,91,6,minecraft:diorite)
B(-7,92,6,minecraft:diorite)
B(-7,93,6,minecraft:diorite)
B(-7,94,6,minecraft:diorite)
B(-7,95,6,minecraft:andesite)
B(-7,17,7,minecraft:diorite)
B(-7,18,7,minecraft:diorite)
B(-7,19,7,minecraft:diorite)
B(-7,20,7,minecraft:diorite)
B(-7,21,7,minecraft:diorite)
B(-7,22,7,minecraft:diorite)
B(-7,23,7,minecraft:diorite)
B(-7,24,7,minecraft:diorite)
B(-7,25,7,minecraft:obsidian)
B(-7,26,7,minecraft:obsidian)
B(-7,27,7,minecraft:obsidian)
B(-7,28,7,minecraft:obsidian)
B(-7,29,7,minecraft:obsidian)
B(-7,30,7,minecraft:obsidian)
B(-7,31,7,minecraft:obsidian)
B(-7,32,7,minecraft:obsidian)
B(-7,33,7,minecraft:obsidian)
B(-7,34,7,minecraft:obsidian)
B(-7,35,7,minecraft:obsidian)
B(-7,36,7,minecraft:obsidian)
B(-7,37,7,minecraft:obsidian)
B(-7,38,7,minecraft:obsidian)
B(-7,39,7,minecraft:andesite)
B(-7,40,7,minecraft:andesite)
B(-7,41,7,minecraft:andesite)
B(-7,82,7,minecraft:diorite)
B(-7,83,7,minecraft:diorite)
B(-7,84,7,minecraft:diorite)
B(-7,85,7,minecraft:diorite)
B(-7,86,7,minecraft:obsidian)
B(-7,87,7,minecraft:obsidian)
B(-7,88,7,minecraft:obsidian)
B(-7,89,7,minecraft:obsidian)
B(-7,90,7,minecraft:obsidian)
B(-7,91,7,minecraft:diorite)
B(-7,92,7,minecraft:diorite)
B(-7,93,7,minecraft:diorite)
B(-7,94,7,minecraft:andesite)
B(-7,16,8,minecraft:diorite)
B(-7,17,8,minecraft:diorite)
B(-7,18,8,minecraft:diorite)
B(-7,19,8,minecraft:diorite)
B(-7,20,8,minecraft:diorite)
B(-7,21,8,minecraft:diorite)
B(-7,22,8,minecraft:diorite)
B(-7,23,8,minecraft:diorite)
B(-7,24,8,minecraft:diorite)
B(-7,25,8,minecraft:obsidian)
B(-7,26,8,minecraft:obsidian)
B(-7,27,8,minecraft:obsidian)
B(-7,28,8,minecraft:obsidian)
B(-7,29,8,minecraft:obsidian)
B(-7,30,8,minecraft:obsidian)
B(-7,31,8,minecraft:obsidian)
B(-7,32,8,minecraft:obsidian)
B(-7,33,8,minecraft:obsidian)
B(-7,34,8,minecraft:obsidian)
B(-7,35,8,minecraft:obsidian)
B(-7,36,8,minecraft:obsidian)
B(-7,37,8,minecraft:obsidian)
B(-7,38,8,minecraft:obsidian)
B(-7,39,8,minecraft:andesite)
B(-7,40,8,minecraft:andesite)
B(-7,41,8,minecraft:andesite)
B(-7,81,8,minecraft:diorite)
B(-7,82,8,minecraft:diorite)
B(-7,83,8,minecraft:obsidian)
B(-7,84,8,minecraft:obsidian)
B(-7,85,8,minecraft:obsidian)
B(-7,86,8,minecraft:obsidian)
B(-7,87,8,minecraft:obsidian)
B(-7,88,8,minecraft:obsidian)
B(-7,89,8,minecraft:obsidian)
B(-7,90,8,minecraft:obsidian)
B(-7,91,8,minecraft:diorite)
B(-7,92,8,minecraft:diorite)
B(-7,93,8,minecraft:andesite)
B(-6,21,-7,minecraft:diorite)
B(-6,22,-7,minecraft:diorite)
B(-6,23,-7,minecraft:diorite)
B(-6,24,-7,minecraft:diorite)
B(-6,25,-7,minecraft:obsidian)
B(-6,26,-7,minecraft:obsidian)
B(-6,27,-7,minecraft:obsidian)
B(-6,28,-7,minecraft:diorite)
B(-6,29,-7,minecraft:diorite)
B(-6,30,-7,minecraft:diorite)
B(-6,31,-7,minecraft:diorite)
B(-6,32,-7,minecraft:obsidian)
B(-6,33,-7,minecraft:diorite)
B(-6,34,-7,minecraft:diorite)
B(-6,35,-7,minecraft:diorite)
B(-6,36,-7,minecraft:lava)
B(-6,37,-7,minecraft:lava)
B(-6,88,-7,minecraft:obsidian)
B(-6,89,-7,minecraft:obsidian)
B(-6,90,-7,minecraft:obsidian)
B(-6,91,-7,minecraft:obsidian)
B(-6,92,-7,minecraft:obsidian)
B(-6,93,-7,minecraft:obsidian)
B(-6,94,-7,minecraft:obsidian)
B(-6,95,-7,minecraft:obsidian)
B(-6,96,-7,minecraft:obsidian)
B(-6,97,-7,minecraft:obsidian)
B(-6,98,-7,minecraft:obsidian)
B(-6,99,-7,minecraft:diorite)
B(-6,100,-7,minecraft:andesite)
B(-6,21,-6,minecraft:diorite)
B(-6,22,-6,minecraft:diorite)
B(-6,23,-6,minecraft:diorite)
B(-6,24,-6,minecraft:diorite)
B(-6,25,-6,minecraft:diorite)
B(-6,26,-6,minecraft:obsidian)
B(-6,27,-6,minecraft:obsidian)
B(-6,28,-6,minecraft:diorite)
B(-6,29,-6,minecraft:diorite)
B(-6,30,-6,minecraft:diorite)
B(-6,31,-6,minecraft:obsidian)
B(-6,32,-6,minecraft:obsidian)
B(-6,33,-6,minecraft:obsidian)
B(-6,34,-6,minecraft:obsidian)
B(-6,35,-6,minecraft:obsidian)
B(-6,36,-6,minecraft:lava)
B(-6,37,-6,minecraft:lava)
B(-6,87,-6,minecraft:obsidian)
B(-6,88,-6,minecraft:obsidian)
B(-6,89,-6,minecraft:obsidian)
B(-6,90,-6,minecraft:obsidian)
B(-6,91,-6,minecraft:obsidian)
B(-6,92,-6,minecraft:obsidian)
B(-6,93,-6,minecraft:obsidian)
B(-6,94,-6,minecraft:obsidian)
B(-6,95,-6,minecraft:obsidian)
B(-6,96,-6,minecraft:obsidian)
B(-6,97,-6,minecraft:obsidian)
B(-6,98,-6,minecraft:obsidian)
B(-6,99,-6,minecraft:obsidian)
B(-6,100,-6,minecraft:diorite)
B(-6,101,-6,minecraft:andesite)
B(-6,21,-5,minecraft:diorite)
B(-6,22,-5,minecraft:diorite)
B(-6,23,-5,minecraft:diorite)
B(-6,24,-5,minecraft:diorite)
B(-6,25,-5,minecraft:diorite)
B(-6,26,-5,minecraft:obsidian)
B(-6,27,-5,minecraft:obsidian)
B(-6,28,-5,minecraft:obsidian)
B(-6,29,-5,minecraft:diorite)
B(-6,30,-5,minecraft:diorite)
B(-6,31,-5,minecraft:diorite)
B(-6,32,-5,minecraft:diorite)
B(-6,33,-5,minecraft:obsidian)
B(-6,34,-5,minecraft:obsidian)
B(-6,35,-5,minecraft:obsidian)
B(-6,36,-5,minecraft:lava)
B(-6,37,-5,minecraft:lava)
B(-6,87,-5,minecraft:obsidian)
B(-6,88,-5,minecraft:obsidian)
B(-6,89,-5,minecraft:obsidian)
B(-6,90,-5,minecraft:obsidian)
B(-6,91,-5,minecraft:obsidian)
B(-6,92,-5,minecraft:obsidian)
B(-6,93,-5,minecraft:obsidian)
B(-6,94,-5,minecraft:obsidian)
B(-6,95,-5,minecraft:obsidian)
B(-6,96,-5,minecraft:obsidian)
B(-6,97,-5,minecraft:obsidian)
B(-6,98,-5,minecraft:obsidian)
B(-6,99,-5,minecraft:obsidian)
B(-6,100,-5,minecraft:obsidian)
B(-6,101,-5,minecraft:diorite)
B(-6,102,-5,minecraft:andesite)
B(-6,21,-4,minecraft:diorite)
B(-6,22,-4,minecraft:diorite)
B(-6,23,-4,minecraft:diorite)
B(-6,24,-4,minecraft:diorite)
B(-6,25,-4,minecraft:diorite)
B(-6,26,-4,minecraft:obsidian)
B(-6,27,-4,minecraft:obsidian)
B(-6,28,-4,minecraft:obsidian)
B(-6,29,-4,minecraft:obsidian)
B(-6,30,-4,minecraft:diorite)
B(-6,31,-4,minecraft:diorite)
B(-6,32,-4,minecraft:diorite)
B(-6,33,-4,minecraft:obsidian)
B(-6,34,-4,minecraft:obsidian)
B(-6,35,-4,minecraft:obsidian)
B(-6,36,-4,minecraft:obsidian)
B(-6,37,-4,minecraft:lava)
B(-6,87,-4,minecraft:obsidian)
B(-6,88,-4,minecraft:obsidian)
B(-6,89,-4,minecraft:obsidian)
B(-6,90,-4,minecraft:obsidian)
B(-6,91,-4,minecraft:obsidian)
B(-6,92,-4,minecraft:obsidian)
B(-6,93,-4,minecraft:obsidian)
B(-6,94,-4,minecraft:obsidian)
B(-6,95,-4,minecraft:obsidian)
B(-6,96,-4,minecraft:obsidian)
B(-6,97,-4,minecraft:obsidian)
B(-6,98,-4,minecraft:obsidian)
B(-6,99,-4,minecraft:obsidian)
B(-6,100,-4,minecraft:obsidian)
B(-6,101,-4,minecraft:diorite)
B(-6,102,-4,minecraft:andesite)
B(-6,21,-3,minecraft:diorite)
B(-6,22,-3,minecraft:diorite)
B(-6,23,-3,minecraft:diorite)
B(-6,24,-3,minecraft:diorite)
B(-6,25,-3,minecraft:diorite)
B(-6,26,-3,minecraft:obsidian)
B(-6,27,-3,minecraft:obsidian)
B(-6,28,-3,minecraft:obsidian)
B(-6,29,-3,minecraft:obsidian)
B(-6,30,-3,minecraft:obsidian)
B(-6,31,-3,minecraft:diorite)
B(-6,32,-3,minecraft:diorite)
B(-6,33,-3,minecraft:obsidian)
B(-6,34,-3,minecraft:obsidian)
B(-6,35,-3,minecraft:obsidian)
B(-6,36,-3,minecraft:obsidian)
B(-6,37,-3,minecraft:obsidian)
B(-6,87,-3,minecraft:obsidian)
B(-6,88,-3,minecraft:obsidian)
B(-6,89,-3,minecraft:obsidian)
B(-6,90,-3,minecraft:obsidian)
B(-6,91,-3,minecraft:obsidian)
B(-6,92,-3,minecraft:obsidian)
B(-6,93,-3,minecraft:obsidian)
B(-6,94,-3,minecraft:obsidian)
B(-6,95,-3,minecraft:obsidian)
B(-6,96,-3,minecraft:obsidian)
B(-6,97,-3,minecraft:obsidian)
B(-6,98,-3,minecraft:obsidian)
B(-6,99,-3,minecraft:diorite)
B(-6,100,-3,minecraft:diorite)
B(-6,101,-3,minecraft:diorite)
B(-6,102,-3,minecraft:diorite)
B(-6,103,-3,minecraft:diorite)
B(-6,21,-2,minecraft:diorite)
B(-6,22,-2,minecraft:diorite)
B(-6,23,-2,minecraft:diorite)
B(-6,24,-2,minecraft:diorite)
B(-6,25,-2,minecraft:diorite)
B(-6,26,-2,minecraft:obsidian)
B(-6,27,-2,minecraft:obsidian)
B(-6,28,-2,minecraft:obsidian)
B(-6,29,-2,minecraft:obsidian)
B(-6,30,-2,minecraft:obsidian)
B(-6,31,-2,minecraft:diorite)
B(-6,32,-2,minecraft:diorite)
B(-6,33,-2,minecraft:obsidian)
B(-6,34,-2,minecraft:obsidian)
B(-6,35,-2,minecraft:obsidian)
B(-6,36,-2,minecraft:obsidian)
B(-6,37,-2,minecraft:obsidian)
B(-6,38,-2,minecraft:andesite)
B(-6,87,-2,minecraft:obsidian)
B(-6,88,-2,minecraft:obsidian)
B(-6,89,-2,minecraft:obsidian)
B(-6,90,-2,minecraft:obsidian)
B(-6,91,-2,minecraft:obsidian)
B(-6,92,-2,minecraft:obsidian)
B(-6,93,-2,minecraft:obsidian)
B(-6,94,-2,minecraft:obsidian)
B(-6,95,-2,minecraft:obsidian)
B(-6,96,-2,minecraft:obsidian)
B(-6,97,-2,minecraft:diorite)
B(-6,98,-2,minecraft:diorite)
B(-6,99,-2,minecraft:diorite)
B(-6,100,-2,minecraft:diorite)
B(-6,101,-2,minecraft:diorite)
B(-6,102,-2,minecraft:diorite)
B(-6,103,-2,minecraft:diorite)
B(-6,21,-1,minecraft:diorite)
B(-6,22,-1,minecraft:diorite)
B(-6,23,-1,minecraft:diorite)
B(-6,24,-1,minecraft:diorite)
B(-6,25,-1,minecraft:diorite)
B(-6,26,-1,minecraft:obsidian)
B(-6,27,-1,minecraft:obsidian)
B(-6,28,-1,minecraft:obsidian)
B(-6,29,-1,minecraft:obsidian)
B(-6,30,-1,minecraft:obsidian)
B(-6,31,-1,minecraft:diorite)
B(-6,32,-1,minecraft:diorite)
B(-6,33,-1,minecraft:diorite)
B(-6,34,-1,minecraft:obsidian)
B(-6,35,-1,minecraft:obsidian)
B(-6,36,-1,minecraft:obsidian)
B(-6,37,-1,minecraft:andesite)
B(-6,38,-1,minecraft:andesite)
B(-6,87,-1,minecraft:obsidian)
B(-6,88,-1,minecraft:obsidian)
B(-6,89,-1,minecraft:obsidian)
B(-6,90,-1,minecraft:obsidian)
B(-6,91,-1,minecraft:obsidian)
B(-6,92,-1,minecraft:obsidian)
B(-6,93,-1,minecraft:obsidian)
B(-6,94,-1,minecraft:obsidian)
B(-6,95,-1,minecraft:obsidian)
B(-6,96,-1,minecraft:diorite)
B(-6,97,-1,minecraft:diorite)
B(-6,98,-1,minecraft:diorite)
B(-6,99,-1,minecraft:diorite)
B(-6,100,-1,minecraft:diorite)
B(-6,101,-1,minecraft:diorite)
B(-6,102,-1,minecraft:diorite)
B(-6,103,-1,minecraft:diorite)
B(-6,20,0,minecraft:diorite)
B(-6,21,0,minecraft:diorite)
B(-6,22,0,minecraft:diorite)
B(-6,23,0,minecraft:diorite)
B(-6,24,0,minecraft:diorite)
B(-6,25,0,minecraft:diorite)
B(-6,26,0,minecraft:obsidian)
B(-6,27,0,minecraft:obsidian)
B(-6,28,0,minecraft:obsidian)
B(-6,29,0,minecraft:obsidian)
B(-6,30,0,minecraft:obsidian)
B(-6,31,0,minecraft:diorite)
B(-6,32,0,minecraft:diorite)
B(-6,33,0,minecraft:diorite)
B(-6,34,0,minecraft:diorite)
B(-6,35,0,minecraft:obsidian)
B(-6,36,0,minecraft:obsidian)
B(-6,37,0,minecraft:andesite)
B(-6,38,0,minecraft:andesite)
B(-6,39,0,minecraft:andesite)
B(-6,86,0,minecraft:diorite)
B(-6,87,0,minecraft:diorite)
B(-6,88,0,minecraft:obsidian)
B(-6,89,0,minecraft:obsidian)
B(-6,90,0,minecraft:obsidian)
B(-6,91,0,minecraft:obsidian)
B(-6,92,0,minecraft:obsidian)
B(-6,93,0,minecraft:diorite)
B(-6,94,0,minecraft:diorite)
B(-6,95,0,minecraft:diorite)
B(-6,96,0,minecraft:diorite)
B(-6,97,0,minecraft:diorite)
B(-6,98,0,minecraft:diorite)
B(-6,99,0,minecraft:diorite)
B(-6,100,0,minecraft:diorite)
B(-6,101,0,minecraft:diorite)
B(-6,102,0,minecraft:diorite)
B(-6,103,0,minecraft:diorite)
B(-6,19,1,minecraft:diorite)
B(-6,20,1,minecraft:diorite)
B(-6,21,1,minecraft:diorite)
B(-6,22,1,minecraft:diorite)
B(-6,23,1,minecraft:diorite)
B(-6,24,1,minecraft:diorite)
B(-6,25,1,minecraft:obsidian)
B(-6,26,1,minecraft:obsidian)
B(-6,27,1,minecraft:obsidian)
B(-6,28,1,minecraft:obsidian)
B(-6,29,1,minecraft:obsidian)
B(-6,30,1,minecraft:obsidian)
B(-6,31,1,minecraft:diorite)
B(-6,32,1,minecraft:diorite)
B(-6,33,1,minecraft:diorite)
B(-6,34,1,minecraft:obsidian)
B(-6,35,1,minecraft:obsidian)
B(-6,36,1,minecraft:obsidian)
B(-6,37,1,minecraft:andesite)
B(-6,38,1,minecraft:andesite)
B(-6,39,1,minecraft:andesite)
B(-6,86,1,minecraft:diorite)
B(-6,87,1,minecraft:diorite)
B(-6,88,1,minecraft:diorite)
B(-6,89,1,minecraft:obsidian)
B(-6,90,1,minecraft:obsidian)
B(-6,91,1,minecraft:obsidian)
B(-6,92,1,minecraft:diorite)
B(-6,93,1,minecraft:diorite)
B(-6,94,1,minecraft:diorite)
B(-6,95,1,minecraft:diorite)
B(-6,96,1,minecraft:diorite)
B(-6,97,1,minecraft:diorite)
B(-6,98,1,minecraft:diorite)
B(-6,99,1,minecraft:diorite)
B(-6,100,1,minecraft:diorite)
B(-6,101,1,minecraft:diorite)
B(-6,102,1,minecraft:diorite)
B(-6,103,1,minecraft:diorite)
B(-6,19,2,minecraft:diorite)
B(-6,20,2,minecraft:diorite)
B(-6,21,2,minecraft:diorite)
B(-6,22,2,minecraft:diorite)
B(-6,23,2,minecraft:diorite)
B(-6,24,2,minecraft:diorite)
B(-6,25,2,minecraft:obsidian)
B(-6,26,2,minecraft:obsidian)
B(-6,27,2,minecraft:obsidian)
B(-6,28,2,minecraft:obsidian)
B(-6,29,2,minecraft:obsidian)
B(-6,30,2,minecraft:obsidian)
B(-6,31,2,minecraft:diorite)
B(-6,32,2,minecraft:diorite)
B(-6,33,2,minecraft:diorite)
B(-6,34,2,minecraft:obsidian)
B(-6,35,2,minecraft:obsidian)
B(-6,36,2,minecraft:obsidian)
B(-6,37,2,minecraft:obsidian)
B(-6,38,2,minecraft:andesite)
B(-6,39,2,minecraft:andesite)
B(-6,40,2,minecraft:andesite)
B(-6,86,2,minecraft:diorite)
B(-6,87,2,minecraft:diorite)
B(-6,88,2,minecraft:diorite)
B(-6,89,2,minecraft:obsidian)
B(-6,90,2,minecraft:obsidian)
B(-6,91,2,minecraft:diorite)
B(-6,92,2,minecraft:diorite)
B(-6,93,2,minecraft:diorite)
B(-6,94,2,minecraft:diorite)
B(-6,95,2,minecraft:diorite)
B(-6,96,2,minecraft:diorite)
B(-6,97,2,minecraft:diorite)
B(-6,98,2,minecraft:diorite)
B(-6,99,2,minecraft:diorite)
B(-6,100,2,minecraft:diorite)
B(-6,101,2,minecraft:diorite)
B(-6,102,2,minecraft:andesite)
B(-6,19,3,minecraft:diorite)
B(-6,20,3,minecraft:diorite)
B(-6,21,3,minecraft:diorite)
B(-6,22,3,minecraft:diorite)
B(-6,23,3,minecraft:diorite)
B(-6,24,3,minecraft:diorite)
B(-6,25,3,minecraft:obsidian)
B(-6,26,3,minecraft:obsidian)
B(-6,27,3,minecraft:obsidian)
B(-6,28,3,minecraft:obsidian)
B(-6,29,3,minecraft:obsidian)
B(-6,30,3,minecraft:obsidian)
B(-6,31,3,minecraft:obsidian)
B(-6,32,3,minecraft:diorite)
B(-6,33,3,minecraft:diorite)
B(-6,34,3,minecraft:obsidian)
B(-6,35,3,minecraft:obsidian)
B(-6,36,3,minecraft:obsidian)
B(-6,37,3,minecraft:obsidian)
B(-6,38,3,minecraft:andesite)
B(-6,39,3,minecraft:andesite)
B(-6,40,3,minecraft:andesite)
B(-6,85,3,minecraft:diorite)
B(-6,86,3,minecraft:diorite)
B(-6,87,3,minecraft:diorite)
B(-6,88,3,minecraft:diorite)
B(-6,89,3,minecraft:obsidian)
B(-6,90,3,minecraft:diorite)
B(-6,91,3,minecraft:diorite)
B(-6,92,3,minecraft:diorite)
B(-6,93,3,minecraft:diorite)
B(-6,94,3,minecraft:diorite)
B(-6,95,3,minecraft:diorite)
B(-6,96,3,minecraft:diorite)
B(-6,97,3,minecraft:diorite)
B(-6,98,3,minecraft:diorite)
B(-6,99,3,minecraft:diorite)
B(-6,100,3,minecraft:andesite)
B(-6,19,4,minecraft:diorite)
B(-6,20,4,minecraft:diorite)
B(-6,21,4,minecraft:diorite)
B(-6,22,4,minecraft:diorite)
B(-6,23,4,minecraft:diorite)
B(-6,24,4,minecraft:diorite)
B(-6,25,4,minecraft:obsidian)
B(-6,26,4,minecraft:obsidian)
B(-6,27,4,minecraft:obsidian)
B(-6,28,4,minecraft:obsidian)
B(-6,29,4,minecraft:obsidian)
B(-6,30,4,minecraft:obsidian)
B(-6,31,4,minecraft:obsidian)
B(-6,32,4,minecraft:diorite)
B(-6,33,4,minecraft:diorite)
B(-6,34,4,minecraft:diorite)
B(-6,35,4,minecraft:obsidian)
B(-6,36,4,minecraft:obsidian)
B(-6,37,4,minecraft:obsidian)
B(-6,38,4,minecraft:andesite)
B(-6,39,4,minecraft:andesite)
B(-6,40,4,minecraft:andesite)
B(-6,84,4,minecraft:diorite)
B(-6,85,4,minecraft:diorite)
B(-6,86,4,minecraft:diorite)
B(-6,87,4,minecraft:diorite)
B(-6,88,4,minecraft:obsidian)
B(-6,89,4,minecraft:obsidian)
B(-6,90,4,minecraft:diorite)
B(-6,91,4,minecraft:diorite)
B(-6,92,4,minecraft:diorite)
B(-6,93,4,minecraft:diorite)
B(-6,94,4,minecraft:diorite)
B(-6,95,4,minecraft:diorite)
B(-6,96,4,minecraft:diorite)
B(-6,97,4,minecraft:andesite)
B(-6,19,5,minecraft:diorite)
B(-6,20,5,minecraft:diorite)
B(-6,21,5,minecraft:diorite)
B(-6,22,5,minecraft:diorite)
B(-6,23,5,minecraft:diorite)
B(-6,24,5,minecraft:diorite)
B(-6,25,5,minecraft:obsidian)
B(-6,26,5,minecraft:obsidian)
B(-6,27,5,minecraft:obsidian)
B(-6,28,5,minecraft:obsidian)
B(-6,29,5,minecraft:obsidian)
B(-6,30,5,minecraft:obsidian)
B(-6,31,5,minecraft:obsidian)
B(-6,32,5,minecraft:obsidian)
B(-6,33,5,minecraft:diorite)
B(-6,34,5,minecraft:diorite)
B(-6,35,5,minecraft:diorite)
B(-6,36,5,minecraft:obsidian)
B(-6,37,5,minecraft:obsidian)
B(-6,38,5,minecraft:andesite)
B(-6,39,5,minecraft:andesite)
B(-6,40,5,minecraft:grass_block)
B(-6,83,5,minecraft:diorite)
B(-6,84,5,minecraft:diorite)
B(-6,85,5,minecraft:diorite)
B(-6,86,5,minecraft:diorite)
B(-6,87,5,minecraft:obsidian)
B(-6,88,5,minecraft:obsidian)
B(-6,89,5,minecraft:obsidian)
B(-6,90,5,minecraft:diorite)
B(-6,91,5,minecraft:diorite)
B(-6,92,5,minecraft:diorite)
B(-6,93,5,minecraft:diorite)
B(-6,94,5,minecraft:diorite)
B(-6,95,5,minecraft:diorite)
B(-6,96,5,minecraft:andesite)
B(-6,19,6,minecraft:diorite)
B(-6,20,6,minecraft:diorite)
B(-6,21,6,minecraft:diorite)
B(-6,22,6,minecraft:diorite)
B(-6,23,6,minecraft:diorite)
B(-6,24,6,minecraft:diorite)
B(-6,25,6,minecraft:obsidian)
B(-6,26,6,minecraft:obsidian)
B(-6,27,6,minecraft:obsidian)
B(-6,28,6,minecraft:obsidian)
B(-6,29,6,minecraft:obsidian)
B(-6,30,6,minecraft:obsidian)
B(-6,31,6,minecraft:obsidian)
B(-6,32,6,minecraft:obsidian)
B(-6,33,6,minecraft:obsidian)
B(-6,34,6,minecraft:obsidian)
B(-6,35,6,minecraft:diorite)
B(-6,36,6,minecraft:diorite)
B(-6,37,6,minecraft:obsidian)
B(-6,38,6,minecraft:obsidian)
B(-6,39,6,minecraft:andesite)
B(-6,40,6,minecraft:andesite)
B(-6,41,6,minecraft:andesite)
B(-6,83,6,minecraft:diorite)
B(-6,84,6,minecraft:diorite)
B(-6,85,6,minecraft:diorite)
B(-6,86,6,minecraft:diorite)
B(-6,87,6,minecraft:obsidian)
B(-6,88,6,minecraft:obsidian)
B(-6,89,6,minecraft:obsidian)
B(-6,90,6,minecraft:diorite)
B(-6,91,6,minecraft:diorite)
B(-6,92,6,minecraft:diorite)
B(-6,93,6,minecraft:diorite)
B(-6,94,6,minecraft:andesite)
B(-6,18,7,minecraft:diorite)
B(-6,19,7,minecraft:diorite)
B(-6,20,7,minecraft:diorite)
B(-6,21,7,minecraft:diorite)
B(-6,22,7,minecraft:diorite)
B(-6,23,7,minecraft:diorite)
B(-6,24,7,minecraft:diorite)
B(-6,25,7,minecraft:obsidian)
B(-6,26,7,minecraft:obsidian)
B(-6,27,7,minecraft:obsidian)
B(-6,28,7,minecraft:obsidian)
B(-6,29,7,minecraft:obsidian)
B(-6,30,7,minecraft:obsidian)
B(-6,31,7,minecraft:obsidian)
B(-6,32,7,minecraft:obsidian)
B(-6,33,7,minecraft:obsidian)
B(-6,34,7,minecraft:obsidian)
B(-6,35,7,minecraft:obsidian)
B(-6,36,7,minecraft:obsidian)
B(-6,37,7,minecraft:obsidian)
B(-6,38,7,minecraft:obsidian)
B(-6,39,7,minecraft:andesite)
B(-6,40,7,minecraft:andesite)
B(-6,41,7,minecraft:grass_block)
B(-6,83,7,minecraft:diorite)
B(-6,84,7,minecraft:diorite)
B(-6,85,7,minecraft:diorite)
B(-6,86,7,minecraft:obsidian)
B(-6,87,7,minecraft:obsidian)
B(-6,88,7,minecraft:obsidian)
B(-6,89,7,minecraft:obsidian)
B(-6,90,7,minecraft:diorite)
B(-6,91,7,minecraft:diorite)
B(-6,92,7,minecraft:diorite)
B(-6,93,7,minecraft:diorite)
B(-6,94,7,minecraft:andesite)
B(-6,17,8,minecraft:diorite)
B(-6,18,8,minecraft:diorite)
B(-6,19,8,minecraft:diorite)
B(-6,20,8,minecraft:diorite)
B(-6,21,8,minecraft:diorite)
B(-6,22,8,minecraft:diorite)
B(-6,23,8,minecraft:diorite)
B(-6,24,8,minecraft:diorite)
B(-6,25,8,minecraft:obsidian)
B(-6,26,8,minecraft:obsidian)
B(-6,27,8,minecraft:obsidian)
B(-6,28,8,minecraft:obsidian)
B(-6,29,8,minecraft:obsidian)
B(-6,30,8,minecraft:obsidian)
B(-6,31,8,minecraft:obsidian)
B(-6,32,8,minecraft:obsidian)
B(-6,33,8,minecraft:obsidian)
B(-6,34,8,minecraft:obsidian)
B(-6,35,8,minecraft:obsidian)
B(-6,36,8,minecraft:obsidian)
B(-6,37,8,minecraft:obsidian)
B(-6,38,8,minecraft:obsidian)
B(-6,39,8,minecraft:andesite)
B(-6,40,8,minecraft:andesite)
B(-6,41,8,minecraft:grass_block)
B(-6,82,8,minecraft:obsidian)
B(-6,83,8,minecraft:obsidian)
B(-6,84,8,minecraft:obsidian)
B(-6,85,8,minecraft:obsidian)
B(-6,86,8,minecraft:obsidian)
B(-6,87,8,minecraft:obsidian)
B(-6,88,8,minecraft:obsidian)
B(-6,89,8,minecraft:obsidian)
B(-6,90,8,minecraft:obsidian)
B(-6,91,8,minecraft:diorite)
B(-6,92,8,minecraft:diorite)
B(-6,93,8,minecraft:andesite)
B(-5,21,-7,minecraft:diorite)
B(-5,22,-7,minecraft:diorite)
B(-5,23,-7,minecraft:diorite)
B(-5,24,-7,minecraft:obsidian)
B(-5,25,-7,minecraft:obsidian)
B(-5,26,-7,minecraft:obsidian)
B(-5,27,-7,minecraft:obsidian)
B(-5,28,-7,minecraft:obsidian)
B(-5,29,-7,minecraft:diorite)
B(-5,30,-7,minecraft:diorite)
B(-5,31,-7,minecraft:diorite)
B(-5,32,-7,minecraft:obsidian)
B(-5,33,-7,minecraft:diorite)
B(-5,34,-7,minecraft:diorite)
B(-5,35,-7,minecraft:diorite)
B(-5,36,-7,minecraft:lava)
B(-5,37,-7,minecraft:lava)
B(-5,88,-7,minecraft:obsidian)
B(-5,89,-7,minecraft:obsidian)
B(-5,90,-7,minecraft:obsidian)
B(-5,91,-7,minecraft:obsidian)
B(-5,92,-7,minecraft:obsidian)
B(-5,93,-7,minecraft:obsidian)
B(-5,94,-7,minecraft:obsidian)
B(-5,95,-7,minecraft:obsidian)
B(-5,96,-7,minecraft:obsidian)
B(-5,97,-7,minecraft:diorite)
B(-5,98,-7,minecraft:andesite)
B(-5,21,-6,minecraft:diorite)
B(-5,22,-6,minecraft:diorite)
B(-5,23,-6,minecraft:diorite)
B(-5,24,-6,minecraft:diorite)
B(-5,25,-6,minecraft:obsidian)
B(-5,26,-6,minecraft:obsidian)
B(-5,27,-6,minecraft:obsidian)
B(-5,28,-6,minecraft:obsidian)
B(-5,29,-6,minecraft:diorite)
B(-5,30,-6,minecraft:diorite)
B(-5,31,-6,minecraft:diorite)
B(-5,32,-6,minecraft:diorite)
B(-5,33,-6,minecraft:obsidian)
B(-5,34,-6,minecraft:obsidian)
B(-5,35,-6,minecraft:obsidian)
B(-5,36,-6,minecraft:lava)
B(-5,37,-6,minecraft:lava)
B(-5,87,-6,minecraft:obsidian)
B(-5,88,-6,minecraft:obsidian)
B(-5,89,-6,minecraft:obsidian)
B(-5,90,-6,minecraft:obsidian)
B(-5,91,-6,minecraft:obsidian)
B(-5,92,-6,minecraft:obsidian)
B(-5,93,-6,minecraft:obsidian)
B(-5,94,-6,minecraft:obsidian)
B(-5,95,-6,minecraft:obsidian)
B(-5,96,-6,minecraft:obsidian)
B(-5,97,-6,minecraft:obsidian)
B(-5,98,-6,minecraft:diorite)
B(-5,99,-6,minecraft:andesite)
B(-5,21,-5,minecraft:diorite)
B(-5,22,-5,minecraft:diorite)
B(-5,23,-5,minecraft:diorite)
B(-5,24,-5,minecraft:diorite)
B(-5,25,-5,minecraft:diorite)
B(-5,26,-5,minecraft:obsidian)
B(-5,27,-5,minecraft:obsidian)
B(-5,28,-5,minecraft:obsidian)
B(-5,29,-5,minecraft:obsidian)
B(-5,30,-5,minecraft:diorite)
B(-5,31,-5,minecraft:diorite)
B(-5,32,-5,minecraft:diorite)
B(-5,33,-5,minecraft:obsidian)
B(-5,34,-5,minecraft:obsidian)
B(-5,35,-5,minecraft:obsidian)
B(-5,36,-5,minecraft:obsidian)
B(-5,37,-5,minecraft:lava)
B(-5,87,-5,minecraft:obsidian)
B(-5,88,-5,minecraft:obsidian)
B(-5,89,-5,minecraft:obsidian)
B(-5,90,-5,minecraft:obsidian)
B(-5,91,-5,minecraft:obsidian)
B(-5,92,-5,minecraft:obsidian)
B(-5,93,-5,minecraft:obsidian)
B(-5,94,-5,minecraft:obsidian)
B(-5,95,-5,minecraft:obsidian)
B(-5,96,-5,minecraft:obsidian)
B(-5,97,-5,minecraft:obsidian)
B(-5,98,-5,minecraft:obsidian)
B(-5,99,-5,minecraft:obsidian)
B(-5,100,-5,minecraft:diorite)
B(-5,101,-5,minecraft:andesite)
B(-5,21,-4,minecraft:diorite)
B(-5,22,-4,minecraft:diorite)
B(-5,23,-4,minecraft:diorite)
B(-5,24,-4,minecraft:diorite)
B(-5,25,-4,minecraft:diorite)
B(-5,26,-4,minecraft:diorite)
B(-5,27,-4,minecraft:obsidian)
B(-5,28,-4,minecraft:obsidian)
B(-5,29,-4,minecraft:obsidian)
B(-5,30,-4,minecraft:obsidian)
B(-5,31,-4,minecraft:diorite)
B(-5,32,-4,minecraft:diorite)
B(-5,33,-4,minecraft:diorite)
B(-5,34,-4,minecraft:obsidian)
B(-5,35,-4,minecraft:obsidian)
B(-5,36,-4,minecraft:obsidian)
B(-5,37,-4,minecraft:lava)
B(-5,87,-4,minecraft:obsidian)
B(-5,88,-4,minecraft:obsidian)
B(-5,89,-4,minecraft:obsidian)
B(-5,90,-4,minecraft:obsidian)
B(-5,91,-4,minecraft:obsidian)
B(-5,92,-4,minecraft:obsidian)
B(-5,93,-4,minecraft:obsidian)
B(-5,94,-4,minecraft:obsidian)
B(-5,95,-4,minecraft:obsidian)
B(-5,96,-4,minecraft:obsidian)
B(-5,97,-4,minecraft:obsidian)
B(-5,98,-4,minecraft:obsidian)
B(-5,99,-4,minecraft:obsidian)
B(-5,100,-4,minecraft:obsidian)
B(-5,101,-4,minecraft:diorite)
B(-5,102,-4,minecraft:andesite)
B(-5,21,-3,minecraft:diorite)
B(-5,22,-3,minecraft:diorite)
B(-5,23,-3,minecraft:diorite)
B(-5,24,-3,minecraft:diorite)
B(-5,25,-3,minecraft:diorite)
B(-5,26,-3,minecraft:diorite)
B(-5,27,-3,minecraft:obsidian)
B(-5,28,-3,minecraft:obsidian)
B(-5,29,-3,minecraft:obsidian)
B(-5,30,-3,minecraft:obsidian)
B(-5,31,-3,minecraft:diorite)
B(-5,32,-3,minecraft:diorite)
B(-5,33,-3,minecraft:diorite)
B(-5,34,-3,minecraft:obsidian)
B(-5,35,-3,minecraft:obsidian)
B(-5,36,-3,minecraft:obsidian)
B(-5,37,-3,minecraft:obsidian)
B(-5,87,-3,minecraft:obsidian)
B(-5,88,-3,minecraft:obsidian)
B(-5,89,-3,minecraft:obsidian)
B(-5,90,-3,minecraft:obsidian)
B(-5,91,-3,minecraft:obsidian)
B(-5,92,-3,minecraft:obsidian)
B(-5,93,-3,minecraft:obsidian)
B(-5,94,-3,minecraft:obsidian)
B(-5,95,-3,minecraft:obsidian)
B(-5,96,-3,minecraft:obsidian)
B(-5,97,-3,minecraft:obsidian)
B(-5,98,-3,minecraft:diorite)
B(-5,99,-3,minecraft:diorite)
B(-5,100,-3,minecraft:diorite)
B(-5,101,-3,minecraft:diorite)
B(-5,102,-3,minecraft:diorite)
B(-5,103,-3,minecraft:diorite)
B(-5,22,-2,minecraft:diorite)
B(-5,23,-2,minecraft:diorite)
B(-5,24,-2,minecraft:diorite)
B(-5,25,-2,minecraft:diorite)
B(-5,26,-2,minecraft:diorite)
B(-5,27,-2,minecraft:obsidian)
B(-5,28,-2,minecraft:obsidian)
B(-5,29,-2,minecraft:obsidian)
B(-5,30,-2,minecraft:obsidian)
B(-5,31,-2,minecraft:diorite)
B(-5,32,-2,minecraft:diorite)
B(-5,33,-2,minecraft:diorite)
B(-5,34,-2,minecraft:obsidian)
B(-5,35,-2,minecraft:obsidian)
B(-5,36,-2,minecraft:obsidian)
B(-5,37,-2,minecraft:obsidian)
B(-5,87,-2,minecraft:obsidian)
B(-5,88,-2,minecraft:obsidian)
B(-5,89,-2,minecraft:obsidian)
B(-5,90,-2,minecraft:obsidian)
B(-5,91,-2,minecraft:obsidian)
B(-5,92,-2,minecraft:obsidian)
B(-5,93,-2,minecraft:obsidian)
B(-5,94,-2,minecraft:obsidian)
B(-5,95,-2,minecraft:obsidian)
B(-5,96,-2,minecraft:diorite)
B(-5,97,-2,minecraft:diorite)
B(-5,98,-2,minecraft:diorite)
B(-5,99,-2,minecraft:diorite)
B(-5,100,-2,minecraft:diorite)
B(-5,101,-2,minecraft:diorite)
B(-5,102,-2,minecraft:diorite)
B(-5,103,-2,minecraft:diorite)
B(-5,21,-1,minecraft:diorite)
B(-5,22,-1,minecraft:diorite)
B(-5,23,-1,minecraft:diorite)
B(-5,24,-1,minecraft:diorite)
B(-5,25,-1,minecraft:diorite)
B(-5,26,-1,minecraft:diorite)
B(-5,27,-1,minecraft:obsidian)
B(-5,28,-1,minecraft:obsidian)
B(-5,29,-1,minecraft:obsidian)
B(-5,30,-1,minecraft:obsidian)
B(-5,31,-1,minecraft:obsidian)
B(-5,32,-1,minecraft:diorite)
B(-5,33,-1,minecraft:diorite)
B(-5,34,-1,minecraft:obsidian)
B(-5,35,-1,minecraft:obsidian)
B(-5,36,-1,minecraft:obsidian)
B(-5,37,-1,minecraft:andesite)
B(-5,38,-1,minecraft:andesite)
B(-5,87,-1,minecraft:obsidian)
B(-5,88,-1,minecraft:obsidian)
B(-5,89,-1,minecraft:obsidian)
B(-5,90,-1,minecraft:obsidian)
B(-5,91,-1,minecraft:obsidian)
B(-5,92,-1,minecraft:obsidian)
B(-5,93,-1,minecraft:obsidian)
B(-5,94,-1,minecraft:obsidian)
B(-5,95,-1,minecraft:diorite)
B(-5,96,-1,minecraft:diorite)
B(-5,97,-1,minecraft:diorite)
B(-5,98,-1,minecraft:diorite)
B(-5,99,-1,minecraft:diorite)
B(-5,100,-1,minecraft:diorite)
B(-5,101,-1,minecraft:diorite)
B(-5,102,-1,minecraft:diorite)
B(-5,103,-1,minecraft:diorite)
B(-5,21,0,minecraft:diorite)
B(-5,22,0,minecraft:diorite)
B(-5,23,0,minecraft:diorite)
B(-5,24,0,minecraft:diorite)
B(-5,25,0,minecraft:diorite)
B(-5,26,0,minecraft:diorite)
B(-5,27,0,minecraft:obsidian)
B(-5,28,0,minecraft:obsidian)
B(-5,29,0,minecraft:obsidian)
B(-5,30,0,minecraft:obsidian)
B(-5,31,0,minecraft:obsidian)
B(-5,32,0,minecraft:diorite)
B(-5,33,0,minecraft:diorite)
B(-5,34,0,minecraft:obsidian)
B(-5,35,0,minecraft:obsidian)
B(-5,36,0,minecraft:obsidian)
B(-5,37,0,minecraft:andesite)
B(-5,38,0,minecraft:andesite)
B(-5,39,0,minecraft:andesite)
B(-5,86,0,minecraft:diorite)
B(-5,87,0,minecraft:diorite)
B(-5,88,0,minecraft:diorite)
B(-5,89,0,minecraft:obsidian)
B(-5,90,0,minecraft:obsidian)
B(-5,91,0,minecraft:obsidian)
B(-5,92,0,minecraft:obsidian)
B(-5,93,0,minecraft:diorite)
B(-5,94,0,minecraft:diorite)
B(-5,95,0,minecraft:diorite)
B(-5,96,0,minecraft:diorite)
B(-5,97,0,minecraft:diorite)
B(-5,98,0,minecraft:diorite)
B(-5,99,0,minecraft:diorite)
B(-5,100,0,minecraft:diorite)
B(-5,101,0,minecraft:diorite)
B(-5,102,0,minecraft:diorite)
B(-5,103,0,minecraft:diorite)
B(-5,21,1,minecraft:diorite)
B(-5,22,1,minecraft:diorite)
B(-5,23,1,minecraft:diorite)
B(-5,24,1,minecraft:diorite)
B(-5,25,1,minecraft:diorite)
B(-5,26,1,minecraft:obsidian)
B(-5,27,1,minecraft:obsidian)
B(-5,28,1,minecraft:obsidian)
B(-5,29,1,minecraft:obsidian)
B(-5,30,1,minecraft:obsidian)
B(-5,31,1,minecraft:obsidian)
B(-5,32,1,minecraft:diorite)
B(-5,33,1,minecraft:diorite)
B(-5,34,1,minecraft:obsidian)
B(-5,35,1,minecraft:obsidian)
B(-5,36,1,minecraft:obsidian)
B(-5,37,1,minecraft:andesite)
B(-5,38,1,minecraft:andesite)
B(-5,39,1,minecraft:andesite)
B(-5,40,1,minecraft:andesite)
B(-5,86,1,minecraft:diorite)
B(-5,87,1,minecraft:diorite)
B(-5,88,1,minecraft:diorite)
B(-5,89,1,minecraft:obsidian)
B(-5,90,1,minecraft:obsidian)
B(-5,91,1,minecraft:obsidian)
B(-5,92,1,minecraft:diorite)
B(-5,93,1,minecraft:diorite)
B(-5,94,1,minecraft:diorite)
B(-5,95,1,minecraft:diorite)
B(-5,96,1,minecraft:diorite)
B(-5,97,1,minecraft:diorite)
B(-5,98,1,minecraft:diorite)
B(-5,99,1,minecraft:diorite)
B(-5,100,1,minecraft:diorite)
B(-5,101,1,minecraft:diorite)
B(-5,102,1,minecraft:andesite)
B(-5,19,2,minecraft:diorite)
B(-5,20,2,minecraft:diorite)
B(-5,21,2,minecraft:diorite)
B(-5,22,2,minecraft:diorite)
B(-5,23,2,minecraft:diorite)
B(-5,24,2,minecraft:diorite)
B(-5,25,2,minecraft:diorite)
B(-5,26,2,minecraft:obsidian)
B(-5,27,2,minecraft:obsidian)
B(-5,28,2,minecraft:obsidian)
B(-5,29,2,minecraft:obsidian)
B(-5,30,2,minecraft:obsidian)
B(-5,31,2,minecraft:obsidian)
B(-5,32,2,minecraft:diorite)
B(-5,33,2,minecraft:diorite)
B(-5,34,2,minecraft:obsidian)
B(-5,35,2,minecraft:obsidian)
B(-5,36,2,minecraft:obsidian)
B(-5,37,2,minecraft:obsidian)
B(-5,38,2,minecraft:andesite)
B(-5,39,2,minecraft:andesite)
B(-5,40,2,minecraft:andesite)
B(-5,86,2,minecraft:diorite)
B(-5,87,2,minecraft:diorite)
B(-5,88,2,minecraft:diorite)
B(-5,89,2,minecraft:obsidian)
B(-5,90,2,minecraft:obsidian)
B(-5,91,2,minecraft:diorite)
B(-5,92,2,minecraft:diorite)
B(-5,93,2,minecraft:diorite)
B(-5,94,2,minecraft:diorite)
B(-5,95,2,minecraft:diorite)
B(-5,96,2,minecraft:diorite)
B(-5,97,2,minecraft:diorite)
B(-5,98,2,minecraft:diorite)
B(-5,99,2,minecraft:diorite)
B(-5,100,2,minecraft:diorite)
B(-5,101,2,minecraft:diorite)
B(-5,102,2,minecraft:andesite)
B(-5,19,3,minecraft:diorite)
B(-5,20,3,minecraft:diorite)
B(-5,21,3,minecraft:diorite)
B(-5,22,3,minecraft:diorite)
B(-5,23,3,minecraft:diorite)
B(-5,24,3,minecraft:diorite)
B(-5,25,3,minecraft:diorite)
B(-5,26,3,minecraft:obsidian)
B(-5,27,3,minecraft:obsidian)
B(-5,28,3,minecraft:obsidian)
B(-5,29,3,minecraft:obsidian)
B(-5,30,3,minecraft:obsidian)
B(-5,31,3,minecraft:obsidian)
B(-5,32,3,minecraft:diorite)
B(-5,33,3,minecraft:diorite)
B(-5,34,3,minecraft:obsidian)
B(-5,35,3,minecraft:obsidian)
B(-5,36,3,minecraft:obsidian)
B(-5,37,3,minecraft:obsidian)
B(-5,38,3,minecraft:andesite)
B(-5,39,3,minecraft:andesite)
B(-5,40,3,minecraft:andesite)
B(-5,86,3,minecraft:diorite)
B(-5,87,3,minecraft:diorite)
B(-5,88,3,minecraft:diorite)
B(-5,89,3,minecraft:obsidian)
B(-5,90,3,minecraft:diorite)
B(-5,91,3,minecraft:diorite)
B(-5,92,3,minecraft:diorite)
B(-5,93,3,minecraft:diorite)
B(-5,94,3,minecraft:diorite)
B(-5,95,3,minecraft:diorite)
B(-5,96,3,minecraft:diorite)
B(-5,97,3,minecraft:diorite)
B(-5,98,3,minecraft:diorite)
B(-5,99,3,minecraft:andesite)
B(-5,19,4,minecraft:diorite)
B(-5,20,4,minecraft:diorite)
B(-5,21,4,minecraft:diorite)
B(-5,22,4,minecraft:diorite)
B(-5,23,4,minecraft:diorite)
B(-5,24,4,minecraft:diorite)
B(-5,25,4,minecraft:obsidian)
B(-5,26,4,minecraft:obsidian)
B(-5,27,4,minecraft:obsidian)
B(-5,28,4,minecraft:obsidian)
B(-5,29,4,minecraft:obsidian)
B(-5,30,4,minecraft:obsidian)
B(-5,31,4,minecraft:obsidian)
B(-5,32,4,minecraft:obsidian)
B(-5,33,4,minecraft:diorite)
B(-5,34,4,minecraft:diorite)
B(-5,35,4,minecraft:obsidian)
B(-5,36,4,minecraft:obsidian)
B(-5,37,4,minecraft:obsidian)
B(-5,38,4,minecraft:andesite)
B(-5,39,4,minecraft:andesite)
B(-5,40,4,minecraft:grass_block)
B(-5,85,4,minecraft:diorite)
B(-5,86,4,minecraft:diorite)
B(-5,87,4,minecraft:diorite)
B(-5,88,4,minecraft:obsidian)
B(-5,89,4,minecraft:obsidian)
B(-5,90,4,minecraft:diorite)
B(-5,91,4,minecraft:diorite)
B(-5,92,4,minecraft:diorite)
B(-5,93,4,minecraft:diorite)
B(-5,94,4,minecraft:diorite)
B(-5,95,4,minecraft:diorite)
B(-5,96,4,minecraft:diorite)
B(-5,97,4,minecraft:andesite)
B(-5,19,5,minecraft:diorite)
B(-5,20,5,minecraft:diorite)
B(-5,21,5,minecraft:diorite)
B(-5,22,5,minecraft:diorite)
B(-5,23,5,minecraft:diorite)
B(-5,24,5,minecraft:diorite)
B(-5,25,5,minecraft:obsidian)
B(-5,26,5,minecraft:obsidian)
B(-5,27,5,minecraft:obsidian)
B(-5,28,5,minecraft:obsidian)
B(-5,29,5,minecraft:obsidian)
B(-5,30,5,minecraft:obsidian)
B(-5,31,5,minecraft:obsidian)
B(-5,32,5,minecraft:obsidian)
B(-5,33,5,minecraft:obsidian)
B(-5,34,5,minecraft:diorite)
B(-5,35,5,minecraft:diorite)
B(-5,36,5,minecraft:obsidian)
B(-5,37,5,minecraft:obsidian)
B(-5,38,5,minecraft:andesite)
B(-5,39,5,minecraft:andesite)
B(-5,40,5,minecraft:grass_block)
B(-5,83,5,minecraft:diorite)
B(-5,84,5,minecraft:diorite)
B(-5,85,5,minecraft:diorite)
B(-5,86,5,minecraft:diorite)
B(-5,87,5,minecraft:obsidian)
B(-5,88,5,minecraft:obsidian)
B(-5,89,5,minecraft:obsidian)
B(-5,90,5,minecraft:diorite)
B(-5,91,5,minecraft:diorite)
B(-5,92,5,minecraft:diorite)
B(-5,93,5,minecraft:diorite)
B(-5,94,5,minecraft:diorite)
B(-5,95,5,minecraft:diorite)
B(-5,96,5,minecraft:andesite)
B(-5,19,6,minecraft:diorite)
B(-5,20,6,minecraft:diorite)
B(-5,21,6,minecraft:diorite)
B(-5,22,6,minecraft:diorite)
B(-5,23,6,minecraft:diorite)
B(-5,24,6,minecraft:diorite)
B(-5,25,6,minecraft:obsidian)
B(-5,26,6,minecraft:obsidian)
B(-5,27,6,minecraft:obsidian)
B(-5,28,6,minecraft:obsidian)
B(-5,29,6,minecraft:obsidian)
B(-5,30,6,minecraft:obsidian)
B(-5,31,6,minecraft:obsidian)
B(-5,32,6,minecraft:obsidian)
B(-5,33,6,minecraft:obsidian)
B(-5,34,6,minecraft:obsidian)
B(-5,35,6,minecraft:obsidian)
B(-5,36,6,minecraft:obsidian)
B(-5,37,6,minecraft:obsidian)
B(-5,38,6,minecraft:obsidian)
B(-5,39,6,minecraft:andesite)
B(-5,40,6,minecraft:andesite)
B(-5,41,6,minecraft:grass_block)
B(-5,83,6,minecraft:diorite)
B(-5,84,6,minecraft:diorite)
B(-5,85,6,minecraft:diorite)
B(-5,86,6,minecraft:obsidian)
B(-5,87,6,minecraft:obsidian)
B(-5,88,6,minecraft:obsidian)
B(-5,89,6,minecraft:obsidian)
B(-5,90,6,minecraft:diorite)
B(-5,91,6,minecraft:diorite)
B(-5,92,6,minecraft:diorite)
B(-5,93,6,minecraft:diorite)
B(-5,94,6,minecraft:andesite)
B(-5,19,7,minecraft:diorite)
B(-5,20,7,minecraft:diorite)
B(-5,21,7,minecraft:diorite)
B(-5,22,7,minecraft:diorite)
B(-5,23,7,minecraft:diorite)
B(-5,24,7,minecraft:diorite)
B(-5,25,7,minecraft:obsidian)
B(-5,26,7,minecraft:obsidian)
B(-5,27,7,minecraft:obsidian)
B(-5,28,7,minecraft:obsidian)
B(-5,29,7,minecraft:obsidian)
B(-5,30,7,minecraft:obsidian)
B(-5,31,7,minecraft:obsidian)
B(-5,32,7,minecraft:obsidian)
B(-5,33,7,minecraft:obsidian)
B(-5,34,7,minecraft:obsidian)
B(-5,35,7,minecraft:obsidian)
B(-5,36,7,minecraft:obsidian)
B(-5,37,7,minecraft:obsidian)
B(-5,38,7,minecraft:obsidian)
B(-5,39,7,minecraft:andesite)
B(-5,40,7,minecraft:andesite)
B(-5,41,7,minecraft:grass_block)
B(-5,82,7,minecraft:obsidian)
B(-5,83,7,minecraft:obsidian)
B(-5,84,7,minecraft:obsidian)
B(-5,85,7,minecraft:obsidian)
B(-5,86,7,minecraft:obsidian)
B(-5,87,7,minecraft:obsidian)
B(-5,88,7,minecraft:obsidian)
B(-5,89,7,minecraft:obsidian)
B(-5,90,7,minecraft:diorite)
B(-5,91,7,minecraft:diorite)
B(-5,92,7,minecraft:diorite)
B(-5,93,7,minecraft:diorite)
B(-5,94,7,minecraft:andesite)
B(-5,16,8,minecraft:diorite)
B(-5,17,8,minecraft:diorite)
B(-5,18,8,minecraft:diorite)
B(-5,19,8,minecraft:diorite)
B(-5,20,8,minecraft:diorite)
B(-5,21,8,minecraft:diorite)
B(-5,22,8,minecraft:diorite)
B(-5,23,8,minecraft:diorite)
B(-5,24,8,minecraft:obsidian)
B(-5,25,8,minecraft:obsidian)
B(-5,26,8,minecraft:obsidian)
B(-5,27,8,minecraft:obsidian)
B(-5,28,8,minecraft:obsidian)
B(-5,29,8,minecraft:obsidian)
B(-5,30,8,minecraft:obsidian)
B(-5,31,8,minecraft:obsidian)
B(-5,32,8,minecraft:obsidian)
B(-5,33,8,minecraft:obsidian)
B(-5,34,8,minecraft:obsidian)
B(-5,35,8,minecraft:obsidian)
B(-5,36,8,minecraft:obsidian)
B(-5,37,8,minecraft:obsidian)
B(-5,38,8,minecraft:obsidian)
B(-5,39,8,minecraft:andesite)
B(-5,40,8,minecraft:andesite)
B(-5,41,8,minecraft:grass_block)
B(-5,82,8,minecraft:obsidian)
B(-5,83,8,minecraft:obsidian)
B(-5,84,8,minecraft:obsidian)
B(-5,85,8,minecraft:obsidian)
B(-5,86,8,minecraft:obsidian)
B(-5,87,8,minecraft:obsidian)
B(-5,88,8,minecraft:obsidian)
B(-5,89,8,minecraft:obsidian)
B(-5,90,8,minecraft:diorite)
B(-5,91,8,minecraft:diorite)
B(-5,92,8,minecraft:diorite)
B(-5,93,8,minecraft:andesite)
B(-4,20,-7,minecraft:diorite)
B(-4,21,-7,minecraft:diorite)
B(-4,22,-7,minecraft:diorite)
B(-4,23,-7,minecraft:diorite)
B(-4,24,-7,minecraft:diorite)
B(-4,25,-7,minecraft:diorite)
B(-4,26,-7,minecraft:obsidian)
B(-4,27,-7,minecraft:obsidian)
B(-4,28,-7,minecraft:obsidian)
B(-4,29,-7,minecraft:obsidian)
B(-4,30,-7,minecraft:diorite)
B(-4,31,-7,minecraft:diorite)
B(-4,32,-7,minecraft:diorite)
B(-4,33,-7,minecraft:diorite)
B(-4,34,-7,minecraft:diorite)
B(-4,35,-7,minecraft:diorite)
B(-4,36,-7,minecraft:lava)
B(-4,37,-7,minecraft:lava)
B(-4,88,-7,minecraft:obsidian)
B(-4,89,-7,minecraft:obsidian)
B(-4,90,-7,minecraft:obsidian)
B(-4,91,-7,minecraft:obsidian)
B(-4,92,-7,minecraft:obsidian)
B(-4,93,-7,minecraft:obsidian)
B(-4,94,-7,minecraft:obsidian)
B(-4,95,-7,minecraft:obsidian)
B(-4,96,-7,minecraft:obsidian)
B(-4,97,-7,minecraft:diorite)
B(-4,98,-7,minecraft:andesite)
B(-4,21,-6,minecraft:diorite)
B(-4,22,-6,minecraft:diorite)
B(-4,23,-6,minecraft:diorite)
B(-4,24,-6,minecraft:diorite)
B(-4,25,-6,minecraft:diorite)
B(-4,26,-6,minecraft:obsidian)
B(-4,27,-6,minecraft:obsidian)
B(-4,28,-6,minecraft:obsidian)
B(-4,29,-6,minecraft:obsidian)
B(-4,30,-6,minecraft:diorite)
B(-4,31,-6,minecraft:diorite)
B(-4,32,-6,minecraft:diorite)
B(-4,33,-6,minecraft:obsidian)
B(-4,34,-6,minecraft:obsidian)
B(-4,35,-6,minecraft:obsidian)
B(-4,36,-6,minecraft:lava)
B(-4,37,-6,minecraft:lava)
B(-4,88,-6,minecraft:obsidian)
B(-4,89,-6,minecraft:obsidian)
B(-4,90,-6,minecraft:obsidian)
B(-4,91,-6,minecraft:obsidian)
B(-4,92,-6,minecraft:obsidian)
B(-4,93,-6,minecraft:obsidian)
B(-4,94,-6,minecraft:obsidian)
B(-4,95,-6,minecraft:obsidian)
B(-4,96,-6,minecraft:obsidian)
B(-4,97,-6,minecraft:diorite)
B(-4,98,-6,minecraft:andesite)
B(-4,21,-5,minecraft:diorite)
B(-4,22,-5,minecraft:diorite)
B(-4,23,-5,minecraft:diorite)
B(-4,24,-5,minecraft:diorite)
B(-4,25,-5,minecraft:diorite)
B(-4,26,-5,minecraft:diorite)
B(-4,27,-5,minecraft:obsidian)
B(-4,28,-5,minecraft:obsidian)
B(-4,29,-5,minecraft:obsidian)
B(-4,30,-5,minecraft:obsidian)
B(-4,31,-5,minecraft:diorite)
B(-4,32,-5,minecraft:diorite)
B(-4,33,-5,minecraft:diorite)
B(-4,34,-5,minecraft:obsidian)
B(-4,35,-5,minecraft:obsidian)
B(-4,36,-5,minecraft:obsidian)
B(-4,37,-5,minecraft:lava)
B(-4,87,-5,minecraft:obsidian)
B(-4,88,-5,minecraft:obsidian)
B(-4,89,-5,minecraft:obsidian)
B(-4,90,-5,minecraft:obsidian)
B(-4,91,-5,minecraft:obsidian)
B(-4,92,-5,minecraft:obsidian)
B(-4,93,-5,minecraft:obsidian)
B(-4,94,-5,minecraft:obsidian)
B(-4,95,-5,minecraft:obsidian)
B(-4,96,-5,minecraft:obsidian)
B(-4,97,-5,minecraft:obsidian)
B(-4,98,-5,minecraft:obsidian)
B(-4,99,-5,minecraft:diorite)
B(-4,100,-5,minecraft:andesite)
B(-4,21,-4,minecraft:diorite)
B(-4,22,-4,minecraft:diorite)
B(-4,23,-4,minecraft:diorite)
B(-4,24,-4,minecraft:diorite)
B(-4,25,-4,minecraft:diorite)
B(-4,26,-4,minecraft:diorite)
B(-4,27,-4,minecraft:obsidian)
B(-4,28,-4,minecraft:obsidian)
B(-4,29,-4,minecraft:obsidian)
B(-4,30,-4,minecraft:obsidian)
B(-4,31,-4,minecraft:diorite)
B(-4,32,-4,minecraft:diorite)
B(-4,33,-4,minecraft:diorite)
B(-4,34,-4,minecraft:obsidian)
B(-4,35,-4,minecraft:obsidian)
B(-4,36,-4,minecraft:obsidian)
B(-4,37,-4,minecraft:lava)
B(-4,87,-4,minecraft:obsidian)
B(-4,88,-4,minecraft:obsidian)
B(-4,89,-4,minecraft:obsidian)
B(-4,90,-4,minecraft:obsidian)
B(-4,91,-4,minecraft:obsidian)
B(-4,92,-4,minecraft:obsidian)
B(-4,93,-4,minecraft:obsidian)
B(-4,94,-4,minecraft:obsidian)
B(-4,95,-4,minecraft:obsidian)
B(-4,96,-4,minecraft:obsidian)
B(-4,97,-4,minecraft:obsidian)
B(-4,98,-4,minecraft:obsidian)
B(-4,99,-4,minecraft:obsidian)
B(-4,100,-4,minecraft:obsidian)
B(-4,101,-4,minecraft:diorite)
B(-4,102,-4,minecraft:andesite)
B(-4,22,-3,minecraft:diorite)
B(-4,23,-3,minecraft:diorite)
B(-4,24,-3,minecraft:diorite)
B(-4,25,-3,minecraft:diorite)
B(-4,26,-3,minecraft:diorite)
B(-4,27,-3,minecraft:diorite)
B(-4,28,-3,minecraft:obsidian)
B(-4,29,-3,minecraft:obsidian)
B(-4,30,-3,minecraft:obsidian)
B(-4,31,-3,minecraft:diorite)
B(-4,32,-3,minecraft:diorite)
B(-4,33,-3,minecraft:diorite)
B(-4,34,-3,minecraft:stone)
B(-4,35,-3,minecraft:obsidian)
B(-4,36,-3,minecraft:obsidian)
B(-4,37,-3,minecraft:lava)
B(-4,87,-3,minecraft:obsidian)
B(-4,88,-3,minecraft:obsidian)
B(-4,89,-3,minecraft:obsidian)
B(-4,90,-3,minecraft:obsidian)
B(-4,91,-3,minecraft:obsidian)
B(-4,92,-3,minecraft:obsidian)
B(-4,93,-3,minecraft:obsidian)
B(-4,94,-3,minecraft:obsidian)
B(-4,95,-3,minecraft:obsidian)
B(-4,96,-3,minecraft:obsidian)
B(-4,97,-3,minecraft:diorite)
B(-4,98,-3,minecraft:diorite)
B(-4,99,-3,minecraft:diorite)
B(-4,100,-3,minecraft:diorite)
B(-4,101,-3,minecraft:diorite)
B(-4,102,-3,minecraft:andesite)
B(-4,22,-2,minecraft:diorite)
B(-4,23,-2,minecraft:diorite)
B(-4,24,-2,minecraft:diorite)
B(-4,25,-2,minecraft:diorite)
B(-4,26,-2,minecraft:diorite)
B(-4,27,-2,minecraft:diorite)
B(-4,28,-2,minecraft:obsidian)
B(-4,29,-2,minecraft:obsidian)
B(-4,30,-2,minecraft:obsidian)
B(-4,31,-2,minecraft:diorite)
B(-4,32,-2,minecraft:diorite)
B(-4,33,-2,minecraft:diorite)
B(-4,34,-2,minecraft:stone)
B(-4,35,-2,minecraft:obsidian)
B(-4,36,-2,minecraft:obsidian)
B(-4,37,-2,minecraft:lava)
B(-4,87,-2,minecraft:obsidian)
B(-4,88,-2,minecraft:obsidian)
B(-4,89,-2,minecraft:obsidian)
B(-4,90,-2,minecraft:obsidian)
B(-4,91,-2,minecraft:obsidian)
B(-4,92,-2,minecraft:obsidian)
B(-4,93,-2,minecraft:obsidian)
B(-4,94,-2,minecraft:obsidian)
B(-4,95,-2,minecraft:obsidian)
B(-4,96,-2,minecraft:diorite)
B(-4,97,-2,minecraft:diorite)
B(-4,98,-2,minecraft:diorite)
B(-4,99,-2,minecraft:diorite)
B(-4,100,-2,minecraft:diorite)
B(-4,101,-2,minecraft:diorite)
B(-4,102,-2,minecraft:diorite)
B(-4,103,-2,minecraft:diorite)
B(-4,22,-1,minecraft:diorite)
B(-4,23,-1,minecraft:diorite)
B(-4,24,-1,minecraft:diorite)
B(-4,25,-1,minecraft:diorite)
B(-4,26,-1,minecraft:diorite)
B(-4,27,-1,minecraft:diorite)
B(-4,28,-1,minecraft:obsidian)
B(-4,29,-1,minecraft:obsidian)
B(-4,30,-1,minecraft:obsidian)
B(-4,31,-1,minecraft:obsidian)
B(-4,32,-1,minecraft:diorite)
B(-4,33,-1,minecraft:diorite)
B(-4,34,-1,minecraft:obsidian)
B(-4,35,-1,minecraft:obsidian)
B(-4,36,-1,minecraft:obsidian)
B(-4,37,-1,minecraft:andesite)
B(-4,87,-1,minecraft:diorite)
B(-4,88,-1,minecraft:diorite)
B(-4,89,-1,minecraft:obsidian)
B(-4,90,-1,minecraft:obsidian)
B(-4,91,-1,minecraft:obsidian)
B(-4,92,-1,minecraft:obsidian)
B(-4,93,-1,minecraft:obsidian)
B(-4,94,-1,minecraft:obsidian)
B(-4,95,-1,minecraft:diorite)
B(-4,96,-1,minecraft:diorite)
B(-4,97,-1,minecraft:diorite)
B(-4,98,-1,minecraft:diorite)
B(-4,99,-1,minecraft:diorite)
B(-4,100,-1,minecraft:diorite)
B(-4,101,-1,minecraft:diorite)
B(-4,102,-1,minecraft:diorite)
B(-4,103,-1,minecraft:diorite)
B(-4,21,0,minecraft:diorite)
B(-4,22,0,minecraft:diorite)
B(-4,23,0,minecraft:diorite)
B(-4,24,0,minecraft:diorite)
B(-4,25,0,minecraft:diorite)
B(-4,26,0,minecraft:diorite)
B(-4,27,0,minecraft:obsidian)
B(-4,28,0,minecraft:obsidian)
B(-4,29,0,minecraft:obsidian)
B(-4,30,0,minecraft:obsidian)
B(-4,31,0,minecraft:obsidian)
B(-4,32,0,minecraft:diorite)
B(-4,33,0,minecraft:diorite)
B(-4,34,0,minecraft:obsidian)
B(-4,35,0,minecraft:obsidian)
B(-4,36,0,minecraft:obsidian)
B(-4,37,0,minecraft:andesite)
B(-4,38,0,minecraft:andesite)
B(-4,87,0,minecraft:diorite)
B(-4,88,0,minecraft:diorite)
B(-4,89,0,minecraft:diorite)
B(-4,90,0,minecraft:obsidian)
B(-4,91,0,minecraft:obsidian)
B(-4,92,0,minecraft:obsidian)
B(-4,93,0,minecraft:diorite)
B(-4,94,0,minecraft:diorite)
B(-4,95,0,minecraft:diorite)
B(-4,96,0,minecraft:diorite)
B(-4,97,0,minecraft:diorite)
B(-4,98,0,minecraft:diorite)
B(-4,99,0,minecraft:diorite)
B(-4,100,0,minecraft:diorite)
B(-4,101,0,minecraft:diorite)
B(-4,102,0,minecraft:andesite)
B(-4,21,1,minecraft:diorite)
B(-4,22,1,minecraft:diorite)
B(-4,23,1,minecraft:diorite)
B(-4,24,1,minecraft:diorite)
B(-4,25,1,minecraft:diorite)
B(-4,26,1,minecraft:diorite)
B(-4,27,1,minecraft:obsidian)
B(-4,28,1,minecraft:obsidian)
B(-4,29,1,minecraft:obsidian)
B(-4,30,1,minecraft:obsidian)
B(-4,31,1,minecraft:obsidian)
B(-4,32,1,minecraft:obsidian)
B(-4,33,1,minecraft:diorite)
B(-4,34,1,minecraft:obsidian)
B(-4,35,1,minecraft:obsidian)
B(-4,36,1,minecraft:obsidian)
B(-4,37,1,minecraft:andesite)
B(-4,38,1,minecraft:andesite)
B(-4,39,1,minecraft:andesite)
B(-4,40,1,minecraft:andesite)
B(-4,86,1,minecraft:diorite)
B(-4,87,1,minecraft:diorite)
B(-4,88,1,minecraft:diorite)
B(-4,89,1,minecraft:diorite)
B(-4,90,1,minecraft:obsidian)
B(-4,91,1,minecraft:obsidian)
B(-4,92,1,minecraft:diorite)
B(-4,93,1,minecraft:diorite)
B(-4,94,1,minecraft:diorite)
B(-4,95,1,minecraft:diorite)
B(-4,96,1,minecraft:diorite)
B(-4,97,1,minecraft:diorite)
B(-4,98,1,minecraft:diorite)
B(-4,99,1,minecraft:diorite)
B(-4,100,1,minecraft:diorite)
B(-4,101,1,minecraft:diorite)
B(-4,102,1,minecraft:andesite)
B(-4,19,2,minecraft:diorite)
B(-4,20,2,minecraft:diorite)
B(-4,21,2,minecraft:diorite)
B(-4,22,2,minecraft:diorite)
B(-4,23,2,minecraft:diorite)
B(-4,24,2,minecraft:diorite)
B(-4,25,2,minecraft:diorite)
B(-4,26,2,minecraft:obsidian)
B(-4,27,2,minecraft:obsidian)
B(-4,28,2,minecraft:obsidian)
B(-4,29,2,minecraft:obsidian)
B(-4,30,2,minecraft:obsidian)
B(-4,31,2,minecraft:obsidian)
B(-4,32,2,minecraft:obsidian)
B(-4,33,2,minecraft:diorite)
B(-4,34,2,minecraft:diorite)
B(-4,35,2,minecraft:obsidian)
B(-4,36,2,minecraft:obsidian)
B(-4,37,2,minecraft:obsidian)
B(-4,38,2,minecraft:andesite)
B(-4,39,2,minecraft:andesite)
B(-4,40,2,minecraft:andesite)
B(-4,86,2,minecraft:diorite)
B(-4,87,2,minecraft:diorite)
B(-4,88,2,minecraft:diorite)
B(-4,89,2,minecraft:diorite)
B(-4,90,2,minecraft:obsidian)
B(-4,91,2,minecraft:diorite)
B(-4,92,2,minecraft:diorite)
B(-4,93,2,minecraft:diorite)
B(-4,94,2,minecraft:diorite)
B(-4,95,2,minecraft:diorite)
B(-4,96,2,minecraft:diorite)
B(-4,97,2,minecraft:diorite)
B(-4,98,2,minecraft:diorite)
B(-4,99,2,minecraft:diorite)
B(-4,100,2,minecraft:diorite)
B(-4,101,2,minecraft:andesite)
B(-4,19,3,minecraft:diorite)
B(-4,20,3,minecraft:diorite)
B(-4,21,3,minecraft:diorite)
B(-4,22,3,minecraft:diorite)
B(-4,23,3,minecraft:diorite)
B(-4,24,3,minecraft:diorite)
B(-4,25,3,minecraft:diorite)
B(-4,26,3,minecraft:obsidian)
B(-4,27,3,minecraft:obsidian)
B(-4,28,3,minecraft:obsidian)
B(-4,29,3,minecraft:obsidian)
B(-4,30,3,minecraft:obsidian)
B(-4,31,3,minecraft:obsidian)
B(-4,32,3,minecraft:obsidian)
B(-4,33,3,minecraft:diorite)
B(-4,34,3,minecraft:diorite)
B(-4,35,3,minecraft:obsidian)
B(-4,36,3,minecraft:obsidian)
B(-4,37,3,minecraft:obsidian)
B(-4,38,3,minecraft:andesite)
B(-4,39,3,minecraft:andesite)
B(-4,40,3,minecraft:andesite)
B(-4,86,3,minecraft:diorite)
B(-4,87,3,minecraft:diorite)
B(-4,88,3,minecraft:diorite)
B(-4,89,3,minecraft:obsidian)
B(-4,90,3,minecraft:diorite)
B(-4,91,3,minecraft:diorite)
B(-4,92,3,minecraft:diorite)
B(-4,93,3,minecraft:diorite)
B(-4,94,3,minecraft:diorite)
B(-4,95,3,minecraft:diorite)
B(-4,96,3,minecraft:diorite)
B(-4,97,3,minecraft:diorite)
B(-4,98,3,minecraft:andesite)
B(-4,19,4,minecraft:diorite)
B(-4,20,4,minecraft:diorite)
B(-4,21,4,minecraft:diorite)
B(-4,22,4,minecraft:diorite)
B(-4,23,4,minecraft:diorite)
B(-4,24,4,minecraft:diorite)
B(-4,25,4,minecraft:diorite)
B(-4,26,4,minecraft:obsidian)
B(-4,27,4,minecraft:obsidian)
B(-4,28,4,minecraft:obsidian)
B(-4,29,4,minecraft:obsidian)
B(-4,30,4,minecraft:obsidian)
B(-4,31,4,minecraft:obsidian)
B(-4,32,4,minecraft:obsidian)
B(-4,33,4,minecraft:obsidian)
B(-4,34,4,minecraft:diorite)
B(-4,35,4,minecraft:obsidian)
B(-4,36,4,minecraft:obsidian)
B(-4,37,4,minecraft:obsidian)
B(-4,38,4,minecraft:obsidian)
B(-4,39,4,minecraft:andesite)
B(-4,40,4,minecraft:grass_block)
B(-4,85,4,minecraft:diorite)
B(-4,86,4,minecraft:diorite)
B(-4,87,4,minecraft:diorite)
B(-4,88,4,minecraft:obsidian)
B(-4,89,4,minecraft:obsidian)
B(-4,90,4,minecraft:diorite)
B(-4,91,4,minecraft:diorite)
B(-4,92,4,minecraft:diorite)
B(-4,93,4,minecraft:diorite)
B(-4,94,4,minecraft:diorite)
B(-4,95,4,minecraft:diorite)
B(-4,96,4,minecraft:diorite)
B(-4,97,4,minecraft:andesite)
B(-4,19,5,minecraft:diorite)
B(-4,20,5,minecraft:diorite)
B(-4,21,5,minecraft:diorite)
B(-4,22,5,minecraft:diorite)
B(-4,23,5,minecraft:diorite)
B(-4,24,5,minecraft:diorite)
B(-4,25,5,minecraft:obsidian)
B(-4,26,5,minecraft:obsidian)
B(-4,27,5,minecraft:obsidian)
B(-4,28,5,minecraft:obsidian)
B(-4,29,5,minecraft:obsidian)
B(-4,30,5,minecraft:obsidian)
B(-4,31,5,minecraft:obsidian)
B(-4,32,5,minecraft:obsidian)
B(-4,33,5,minecraft:obsidian)
B(-4,34,5,minecraft:obsidian)
B(-4,35,5,minecraft:obsidian)
B(-4,36,5,minecraft:obsidian)
B(-4,37,5,minecraft:obsidian)
B(-4,38,5,minecraft:obsidian)
B(-4,39,5,minecraft:andesite)
B(-4,40,5,minecraft:grass_block)
B(-4,84,5,minecraft:diorite)
B(-4,85,5,minecraft:diorite)
B(-4,86,5,minecraft:obsidian)
B(-4,87,5,minecraft:obsidian)
B(-4,88,5,minecraft:obsidian)
B(-4,89,5,minecraft:obsidian)
B(-4,90,5,minecraft:diorite)
B(-4,91,5,minecraft:diorite)
B(-4,92,5,minecraft:diorite)
B(-4,93,5,minecraft:diorite)
B(-4,94,5,minecraft:diorite)
B(-4,95,5,minecraft:diorite)
B(-4,96,5,minecraft:andesite)
B(-4,19,6,minecraft:diorite)
B(-4,20,6,minecraft:diorite)
B(-4,21,6,minecraft:diorite)
B(-4,22,6,minecraft:diorite)
B(-4,23,6,minecraft:diorite)
B(-4,24,6,minecraft:diorite)
B(-4,25,6,minecraft:obsidian)
B(-4,26,6,minecraft:obsidian)
B(-4,27,6,minecraft:obsidian)
B(-4,28,6,minecraft:obsidian)
B(-4,29,6,minecraft:obsidian)
B(-4,30,6,minecraft:obsidian)
B(-4,31,6,minecraft:obsidian)
B(-4,32,6,minecraft:obsidian)
B(-4,33,6,minecraft:obsidian)
B(-4,34,6,minecraft:obsidian)
B(-4,35,6,minecraft:obsidian)
B(-4,36,6,minecraft:obsidian)
B(-4,37,6,minecraft:obsidian)
B(-4,38,6,minecraft:obsidian)
B(-4,39,6,minecraft:obsidian)
B(-4,40,6,minecraft:grass_block)
B(-4,83,6,minecraft:obsidian)
B(-4,84,6,minecraft:obsidian)
B(-4,85,6,minecraft:obsidian)
B(-4,86,6,minecraft:obsidian)
B(-4,87,6,minecraft:obsidian)
B(-4,88,6,minecraft:obsidian)
B(-4,89,6,minecraft:obsidian)
B(-4,90,6,minecraft:diorite)
B(-4,91,6,minecraft:diorite)
B(-4,92,6,minecraft:diorite)
B(-4,93,6,minecraft:diorite)
B(-4,94,6,minecraft:andesite)
B(-4,19,7,minecraft:diorite)
B(-4,20,7,minecraft:diorite)
B(-4,21,7,minecraft:diorite)
B(-4,22,7,minecraft:diorite)
B(-4,23,7,minecraft:diorite)
B(-4,24,7,minecraft:diorite)
B(-4,25,7,minecraft:obsidian)
B(-4,26,7,minecraft:obsidian)
B(-4,27,7,minecraft:obsidian)
B(-4,28,7,minecraft:obsidian)
B(-4,29,7,minecraft:obsidian)
B(-4,30,7,minecraft:obsidian)
B(-4,31,7,minecraft:obsidian)
B(-4,32,7,minecraft:obsidian)
B(-4,33,7,minecraft:obsidian)
B(-4,34,7,minecraft:obsidian)
B(-4,35,7,minecraft:obsidian)
B(-4,36,7,minecraft:obsidian)
B(-4,37,7,minecraft:obsidian)
B(-4,38,7,minecraft:obsidian)
B(-4,39,7,minecraft:obsidian)
B(-4,40,7,minecraft:grass_block)
B(-4,82,7,minecraft:obsidian)
B(-4,83,7,minecraft:obsidian)
B(-4,84,7,minecraft:obsidian)
B(-4,85,7,minecraft:obsidian)
B(-4,86,7,minecraft:obsidian)
B(-4,87,7,minecraft:obsidian)
B(-4,88,7,minecraft:obsidian)
B(-4,89,7,minecraft:diorite)
B(-4,90,7,minecraft:diorite)
B(-4,91,7,minecraft:diorite)
B(-4,92,7,minecraft:diorite)
B(-4,93,7,minecraft:andesite)
B(-4,16,8,minecraft:diorite)
B(-4,17,8,minecraft:diorite)
B(-4,18,8,minecraft:diorite)
B(-4,19,8,minecraft:diorite)
B(-4,20,8,minecraft:diorite)
B(-4,21,8,minecraft:diorite)
B(-4,22,8,minecraft:diorite)
B(-4,23,8,minecraft:diorite)
B(-4,24,8,minecraft:obsidian)
B(-4,25,8,minecraft:obsidian)
B(-4,26,8,minecraft:obsidian)
B(-4,27,8,minecraft:obsidian)
B(-4,28,8,minecraft:obsidian)
B(-4,29,8,minecraft:obsidian)
B(-4,30,8,minecraft:obsidian)
B(-4,31,8,minecraft:obsidian)
B(-4,32,8,minecraft:obsidian)
B(-4,33,8,minecraft:obsidian)
B(-4,34,8,minecraft:obsidian)
B(-4,35,8,minecraft:obsidian)
B(-4,36,8,minecraft:obsidian)
B(-4,37,8,minecraft:obsidian)
B(-4,38,8,minecraft:obsidian)
B(-4,39,8,minecraft:obsidian)
B(-4,40,8,minecraft:andesite)
B(-4,41,8,minecraft:grass_block)
B(-4,81,8,minecraft:obsidian)
B(-4,82,8,minecraft:obsidian)
B(-4,83,8,minecraft:obsidian)
B(-4,84,8,minecraft:obsidian)
B(-4,85,8,minecraft:obsidian)
B(-4,86,8,minecraft:obsidian)
B(-4,87,8,minecraft:obsidian)
B(-4,88,8,minecraft:obsidian)
B(-4,89,8,minecraft:diorite)
B(-4,90,8,minecraft:diorite)
B(-4,91,8,minecraft:diorite)
B(-4,92,8,minecraft:diorite)
B(-4,93,8,minecraft:andesite)
B(-3,19,-7,minecraft:diorite)
B(-3,20,-7,minecraft:diorite)
B(-3,21,-7,minecraft:diorite)
B(-3,22,-7,minecraft:diorite)
B(-3,23,-7,minecraft:diorite)
B(-3,24,-7,minecraft:diorite)
B(-3,25,-7,minecraft:diorite)
B(-3,26,-7,minecraft:diorite)
B(-3,27,-7,minecraft:obsidian)
B(-3,28,-7,minecraft:obsidian)
B(-3,29,-7,minecraft:obsidian)
B(-3,30,-7,minecraft:obsidian)
B(-3,31,-7,minecraft:diorite)
B(-3,32,-7,minecraft:diorite)
B(-3,33,-7,minecraft:diorite)
B(-3,34,-7,minecraft:obsidian)
B(-3,35,-7,minecraft:obsidian)
B(-3,36,-7,minecraft:lava)
B(-3,37,-7,minecraft:lava)
B(-3,88,-7,minecraft:obsidian)
B(-3,89,-7,minecraft:obsidian)
B(-3,90,-7,minecraft:obsidian)
B(-3,91,-7,minecraft:obsidian)
B(-3,92,-7,minecraft:obsidian)
B(-3,93,-7,minecraft:obsidian)
B(-3,94,-7,minecraft:obsidian)
B(-3,95,-7,minecraft:obsidian)
B(-3,96,-7,minecraft:obsidian)
B(-3,97,-7,minecraft:diorite)
B(-3,98,-7,minecraft:andesite)
B(-3,20,-6,minecraft:diorite)
B(-3,21,-6,minecraft:diorite)
B(-3,22,-6,minecraft:diorite)
B(-3,23,-6,minecraft:diorite)
B(-3,24,-6,minecraft:diorite)
B(-3,25,-6,minecraft:diorite)
B(-3,26,-6,minecraft:diorite)
B(-3,27,-6,minecraft:obsidian)
B(-3,28,-6,minecraft:obsidian)
B(-3,29,-6,minecraft:obsidian)
B(-3,30,-6,minecraft:obsidian)
B(-3,31,-6,minecraft:diorite)
B(-3,32,-6,minecraft:diorite)
B(-3,33,-6,minecraft:obsidian)
B(-3,34,-6,minecraft:obsidian)
B(-3,35,-6,minecraft:obsidian)
B(-3,36,-6,minecraft:lava)
B(-3,37,-6,minecraft:lava)
B(-3,88,-6,minecraft:obsidian)
B(-3,89,-6,minecraft:obsidian)
B(-3,90,-6,minecraft:obsidian)
B(-3,91,-6,minecraft:obsidian)
B(-3,92,-6,minecraft:obsidian)
B(-3,93,-6,minecraft:obsidian)
B(-3,94,-6,minecraft:obsidian)
B(-3,95,-6,minecraft:obsidian)
B(-3,96,-6,minecraft:obsidian)
B(-3,97,-6,minecraft:obsidian)
B(-3,98,-6,minecraft:diorite)
B(-3,99,-6,minecraft:andesite)
B(-3,21,-5,minecraft:diorite)
B(-3,22,-5,minecraft:diorite)
B(-3,23,-5,minecraft:diorite)
B(-3,24,-5,minecraft:diorite)
B(-3,25,-5,minecraft:diorite)
B(-3,26,-5,minecraft:diorite)
B(-3,27,-5,minecraft:obsidian)
B(-3,28,-5,minecraft:obsidian)
B(-3,29,-5,minecraft:obsidian)
B(-3,30,-5,minecraft:obsidian)
B(-3,31,-5,minecraft:diorite)
B(-3,32,-5,minecraft:diorite)
B(-3,33,-5,minecraft:diorite)
B(-3,34,-5,minecraft:diorite)
B(-3,35,-5,minecraft:diorite)
B(-3,36,-5,minecraft:diorite)
B(-3,37,-5,minecraft:lava)
B(-3,88,-5,minecraft:obsidian)
B(-3,89,-5,minecraft:obsidian)
B(-3,90,-5,minecraft:obsidian)
B(-3,91,-5,minecraft:obsidian)
B(-3,92,-5,minecraft:obsidian)
B(-3,93,-5,minecraft:obsidian)
B(-3,94,-5,minecraft:obsidian)
B(-3,95,-5,minecraft:obsidian)
B(-3,96,-5,minecraft:obsidian)
B(-3,97,-5,minecraft:obsidian)
B(-3,98,-5,minecraft:diorite)
B(-3,99,-5,minecraft:andesite)
B(-3,22,-4,minecraft:diorite)
B(-3,23,-4,minecraft:diorite)
B(-3,24,-4,minecraft:diorite)
B(-3,25,-4,minecraft:diorite)
B(-3,26,-4,minecraft:diorite)
B(-3,27,-4,minecraft:diorite)
B(-3,28,-4,minecraft:obsidian)
B(-3,29,-4,minecraft:obsidian)
B(-3,30,-4,minecraft:obsidian)
B(-3,31,-4,minecraft:diorite)
B(-3,32,-4,minecraft:diorite)
B(-3,33,-4,minecraft:diorite)
B(-3,34,-4,minecraft:obsidian)
B(-3,35,-4,minecraft:obsidian)
B(-3,36,-4,minecraft:obsidian)
B(-3,37,-4,minecraft:lava)
B(-3,88,-4,minecraft:obsidian)
B(-3,89,-4,minecraft:obsidian)
B(-3,90,-4,minecraft:obsidian)
B(-3,91,-4,minecraft:obsidian)
B(-3,92,-4,minecraft:obsidian)
B(-3,93,-4,minecraft:obsidian)
B(-3,94,-4,minecraft:obsidian)
B(-3,95,-4,minecraft:obsidian)
B(-3,96,-4,minecraft:obsidian)
B(-3,97,-4,minecraft:obsidian)
B(-3,98,-4,minecraft:obsidian)
B(-3,99,-4,minecraft:diorite)
B(-3,100,-4,minecraft:andesite)
B(-3,22,-3,minecraft:diorite)
B(-3,23,-3,minecraft:diorite)
B(-3,24,-3,minecraft:diorite)
B(-3,25,-3,minecraft:diorite)
B(-3,26,-3,minecraft:diorite)
B(-3,27,-3,minecraft:diorite)
B(-3,28,-3,minecraft:obsidian)
B(-3,29,-3,minecraft:obsidian)
B(-3,30,-3,minecraft:obsidian)
B(-3,31,-3,minecraft:diorite)
B(-3,32,-3,minecraft:diorite)
B(-3,33,-3,minecraft:diorite)
B(-3,34,-3,minecraft:obsidian)
B(-3,35,-3,minecraft:obsidian)
B(-3,36,-3,minecraft:obsidian)
B(-3,37,-3,minecraft:lava)
B(-3,88,-3,minecraft:obsidian)
B(-3,89,-3,minecraft:obsidian)
B(-3,90,-3,minecraft:obsidian)
B(-3,91,-3,minecraft:obsidian)
B(-3,92,-3,minecraft:obsidian)
B(-3,93,-3,minecraft:obsidian)
B(-3,94,-3,minecraft:obsidian)
B(-3,95,-3,minecraft:obsidian)
B(-3,96,-3,minecraft:obsidian)
B(-3,97,-3,minecraft:diorite)
B(-3,98,-3,minecraft:diorite)
B(-3,99,-3,minecraft:diorite)
B(-3,100,-3,minecraft:diorite)
B(-3,101,-3,minecraft:diorite)
B(-3,102,-3,minecraft:andesite)
B(-3,22,-2,minecraft:diorite)
B(-3,23,-2,minecraft:diorite)
B(-3,24,-2,minecraft:diorite)
B(-3,25,-2,minecraft:diorite)
B(-3,26,-2,minecraft:diorite)
B(-3,27,-2,minecraft:diorite)
B(-3,28,-2,minecraft:obsidian)
B(-3,29,-2,minecraft:obsidian)
B(-3,30,-2,minecraft:obsidian)
B(-3,31,-2,minecraft:diorite)
B(-3,32,-2,minecraft:diorite)
B(-3,33,-2,minecraft:diorite)
B(-3,34,-2,minecraft:obsidian)
B(-3,35,-2,minecraft:obsidian)
B(-3,36,-2,minecraft:obsidian)
B(-3,37,-2,minecraft:lava)
B(-3,87,-2,minecraft:obsidian)
B(-3,88,-2,minecraft:obsidian)
B(-3,89,-2,minecraft:obsidian)
B(-3,90,-2,minecraft:obsidian)
B(-3,91,-2,minecraft:obsidian)
B(-3,92,-2,minecraft:obsidian)
B(-3,93,-2,minecraft:obsidian)
B(-3,94,-2,minecraft:obsidian)
B(-3,95,-2,minecraft:obsidian)
B(-3,96,-2,minecraft:diorite)
B(-3,97,-2,minecraft:diorite)
B(-3,98,-2,minecraft:diorite)
B(-3,99,-2,minecraft:diorite)
B(-3,100,-2,minecraft:diorite)
B(-3,101,-2,minecraft:diorite)
B(-3,102,-2,minecraft:andesite)
B(-3,22,-1,minecraft:diorite)
B(-3,23,-1,minecraft:diorite)
B(-3,24,-1,minecraft:diorite)
B(-3,25,-1,minecraft:diorite)
B(-3,26,-1,minecraft:diorite)
B(-3,27,-1,minecraft:diorite)
B(-3,28,-1,minecraft:obsidian)
B(-3,29,-1,minecraft:obsidian)
B(-3,30,-1,minecraft:obsidian)
B(-3,31,-1,minecraft:diorite)
B(-3,32,-1,minecraft:diorite)
B(-3,33,-1,minecraft:diorite)
B(-3,34,-1,minecraft:obsidian)
B(-3,35,-1,minecraft:obsidian)
B(-3,36,-1,minecraft:andesite)
B(-3,37,-1,minecraft:andesite)
B(-3,87,-1,minecraft:diorite)
B(-3,88,-1,minecraft:diorite)
B(-3,89,-1,minecraft:obsidian)
B(-3,90,-1,minecraft:obsidian)
B(-3,91,-1,minecraft:obsidian)
B(-3,92,-1,minecraft:obsidian)
B(-3,93,-1,minecraft:obsidian)
B(-3,94,-1,minecraft:obsidian)
B(-3,95,-1,minecraft:diorite)
B(-3,96,-1,minecraft:diorite)
B(-3,97,-1,minecraft:diorite)
B(-3,98,-1,minecraft:diorite)
B(-3,99,-1,minecraft:diorite)
B(-3,100,-1,minecraft:diorite)
B(-3,101,-1,minecraft:diorite)
B(-3,102,-1,minecraft:andesite)
B(-3,22,0,minecraft:diorite)
B(-3,23,0,minecraft:diorite)
B(-3,24,0,minecraft:diorite)
B(-3,25,0,minecraft:diorite)
B(-3,26,0,minecraft:diorite)
B(-3,27,0,minecraft:diorite)
B(-3,28,0,minecraft:obsidian)
B(-3,29,0,minecraft:obsidian)
B(-3,30,0,minecraft:obsidian)
B(-3,31,0,minecraft:obsidian)
B(-3,32,0,minecraft:diorite)
B(-3,33,0,minecraft:diorite)
B(-3,34,0,minecraft:obsidian)
B(-3,35,0,minecraft:obsidian)
B(-3,36,0,minecraft:andesite)
B(-3,37,0,minecraft:andesite)
B(-3,87,0,minecraft:diorite)
B(-3,88,0,minecraft:diorite)
B(-3,89,0,minecraft:diorite)
B(-3,90,0,minecraft:obsidian)
B(-3,91,0,minecraft:obsidian)
B(-3,92,0,minecraft:obsidian)
B(-3,93,0,minecraft:obsidian)
B(-3,94,0,minecraft:diorite)
B(-3,95,0,minecraft:diorite)
B(-3,96,0,minecraft:diorite)
B(-3,97,0,minecraft:diorite)
B(-3,98,0,minecraft:diorite)
B(-3,99,0,minecraft:diorite)
B(-3,100,0,minecraft:diorite)
B(-3,101,0,minecraft:diorite)
B(-3,102,0,minecraft:andesite)
B(-3,21,1,minecraft:diorite)
B(-3,22,1,minecraft:diorite)
B(-3,23,1,minecraft:diorite)
B(-3,24,1,minecraft:diorite)
B(-3,25,1,minecraft:diorite)
B(-3,26,1,minecraft:diorite)
B(-3,27,1,minecraft:obsidian)
B(-3,28,1,minecraft:obsidian)
B(-3,29,1,minecraft:obsidian)
B(-3,30,1,minecraft:obsidian)
B(-3,31,1,minecraft:obsidian)
B(-3,32,1,minecraft:obsidian)
B(-3,33,1,minecraft:diorite)
B(-3,34,1,minecraft:obsidian)
B(-3,35,1,minecraft:obsidian)
B(-3,36,1,minecraft:andesite)
B(-3,37,1,minecraft:andesite)
B(-3,38,1,minecraft:andesite)
B(-3,87,1,minecraft:diorite)
B(-3,88,1,minecraft:diorite)
B(-3,89,1,minecraft:diorite)
B(-3,90,1,minecraft:obsidian)
B(-3,91,1,minecraft:obsidian)
B(-3,92,1,minecraft:diorite)
B(-3,93,1,minecraft:diorite)
B(-3,94,1,minecraft:diorite)
B(-3,95,1,minecraft:diorite)
B(-3,96,1,minecraft:diorite)
B(-3,97,1,minecraft:diorite)
B(-3,98,1,minecraft:diorite)
B(-3,99,1,minecraft:diorite)
B(-3,100,1,minecraft:diorite)
B(-3,101,1,minecraft:andesite)
B(-3,20,2,minecraft:diorite)
B(-3,21,2,minecraft:diorite)
B(-3,22,2,minecraft:diorite)
B(-3,23,2,minecraft:diorite)
B(-3,24,2,minecraft:diorite)
B(-3,25,2,minecraft:diorite)
B(-3,26,2,minecraft:obsidian)
B(-3,27,2,minecraft:obsidian)
B(-3,28,2,minecraft:obsidian)
B(-3,29,2,minecraft:obsidian)
B(-3,30,2,minecraft:obsidian)
B(-3,31,2,minecraft:obsidian)
B(-3,32,2,minecraft:obsidian)
B(-3,33,2,minecraft:obsidian)
B(-3,34,2,minecraft:diorite)
B(-3,35,2,minecraft:obsidian)
B(-3,36,2,minecraft:obsidian)
B(-3,37,2,minecraft:andesite)
B(-3,38,2,minecraft:andesite)
B(-3,39,2,minecraft:andesite)
B(-3,40,2,minecraft:andesite)
B(-3,86,2,minecraft:diorite)
B(-3,87,2,minecraft:diorite)
B(-3,88,2,minecraft:diorite)
B(-3,89,2,minecraft:diorite)
B(-3,90,2,minecraft:obsidian)
B(-3,91,2,minecraft:diorite)
B(-3,92,2,minecraft:diorite)
B(-3,93,2,minecraft:diorite)
B(-3,94,2,minecraft:diorite)
B(-3,95,2,minecraft:diorite)
B(-3,96,2,minecraft:diorite)
B(-3,97,2,minecraft:diorite)
B(-3,98,2,minecraft:diorite)
B(-3,99,2,minecraft:diorite)
B(-3,100,2,minecraft:andesite)
B(-3,19,3,minecraft:diorite)
B(-3,20,3,minecraft:diorite)
B(-3,21,3,minecraft:diorite)
B(-3,22,3,minecraft:diorite)
B(-3,23,3,minecraft:diorite)
B(-3,24,3,minecraft:diorite)
B(-3,25,3,minecraft:diorite)
B(-3,26,3,minecraft:obsidian)
B(-3,27,3,minecraft:obsidian)
B(-3,28,3,minecraft:obsidian)
B(-3,29,3,minecraft:obsidian)
B(-3,30,3,minecraft:obsidian)
B(-3,31,3,minecraft:obsidian)
B(-3,32,3,minecraft:obsidian)
B(-3,33,3,minecraft:obsidian)
B(-3,34,3,minecraft:obsidian)
B(-3,35,3,minecraft:diorite)
B(-3,36,3,minecraft:obsidian)
B(-3,37,3,minecraft:obsidian)
B(-3,38,3,minecraft:andesite)
B(-3,39,3,minecraft:andesite)
B(-3,40,3,minecraft:andesite)
B(-3,86,3,minecraft:diorite)
B(-3,87,3,minecraft:diorite)
B(-3,88,3,minecraft:diorite)
B(-3,89,3,minecraft:obsidian)
B(-3,90,3,minecraft:obsidian)
B(-3,91,3,minecraft:diorite)
B(-3,92,3,minecraft:diorite)
B(-3,93,3,minecraft:diorite)
B(-3,94,3,minecraft:diorite)
B(-3,95,3,minecraft:diorite)
B(-3,96,3,minecraft:diorite)
B(-3,97,3,minecraft:diorite)
B(-3,98,3,minecraft:andesite)
B(-3,19,4,minecraft:diorite)
B(-3,20,4,minecraft:diorite)
B(-3,21,4,minecraft:diorite)
B(-3,22,4,minecraft:diorite)
B(-3,23,4,minecraft:diorite)
B(-3,24,4,minecraft:diorite)
B(-3,25,4,minecraft:diorite)
B(-3,26,4,minecraft:obsidian)
B(-3,27,4,minecraft:obsidian)
B(-3,28,4,minecraft:obsidian)
B(-3,29,4,minecraft:obsidian)
B(-3,30,4,minecraft:obsidian)
B(-3,31,4,minecraft:obsidian)
B(-3,32,4,minecraft:obsidian)
B(-3,33,4,minecraft:obsidian)
B(-3,34,4,minecraft:obsidian)
B(-3,35,4,minecraft:obsidian)
B(-3,36,4,minecraft:obsidian)
B(-3,37,4,minecraft:obsidian)
B(-3,38,4,minecraft:obsidian)
B(-3,39,4,minecraft:andesite)
B(-3,40,4,minecraft:grass_block)
B(-3,86,4,minecraft:obsidian)
B(-3,87,4,minecraft:obsidian)
B(-3,88,4,minecraft:obsidian)
B(-3,89,4,minecraft:obsidian)
B(-3,90,4,minecraft:diorite)
B(-3,91,4,minecraft:diorite)
B(-3,92,4,minecraft:diorite)
B(-3,93,4,minecraft:diorite)
B(-3,94,4,minecraft:diorite)
B(-3,95,4,minecraft:diorite)
B(-3,96,4,minecraft:diorite)
B(-3,97,4,minecraft:andesite)
B(-3,19,5,minecraft:diorite)
B(-3,20,5,minecraft:diorite)
B(-3,21,5,minecraft:diorite)
B(-3,22,5,minecraft:diorite)
B(-3,23,5,minecraft:diorite)
B(-3,24,5,minecraft:diorite)
B(-3,25,5,minecraft:diorite)
B(-3,26,5,minecraft:obsidian)
B(-3,27,5,minecraft:obsidian)
B(-3,28,5,minecraft:obsidian)
B(-3,29,5,minecraft:obsidian)
B(-3,30,5,minecraft:obsidian)
B(-3,31,5,minecraft:obsidian)
B(-3,32,5,minecraft:obsidian)
B(-3,33,5,minecraft:obsidian)
B(-3,34,5,minecraft:obsidian)
B(-3,35,5,minecraft:obsidian)
B(-3,36,5,minecraft:obsidian)
B(-3,37,5,minecraft:obsidian)
B(-3,38,5,minecraft:obsidian)
B(-3,39,5,minecraft:andesite)
B(-3,40,5,minecraft:grass_block)
B(-3,84,5,minecraft:obsidian)
B(-3,85,5,minecraft:obsidian)
B(-3,86,5,minecraft:obsidian)
B(-3,87,5,minecraft:obsidian)
B(-3,88,5,minecraft:obsidian)
B(-3,89,5,minecraft:obsidian)
B(-3,90,5,minecraft:diorite)
B(-3,91,5,minecraft:diorite)
B(-3,92,5,minecraft:diorite)
B(-3,93,5,minecraft:diorite)
B(-3,94,5,minecraft:diorite)
B(-3,95,5,minecraft:andesite)
B(-3,19,6,minecraft:diorite)
B(-3,20,6,minecraft:diorite)
B(-3,21,6,minecraft:diorite)
B(-3,22,6,minecraft:diorite)
B(-3,23,6,minecraft:diorite)
B(-3,24,6,minecraft:diorite)
B(-3,25,6,minecraft:obsidian)
B(-3,26,6,minecraft:obsidian)
B(-3,27,6,minecraft:obsidian)
B(-3,28,6,minecraft:obsidian)
B(-3,29,6,minecraft:obsidian)
