
#######################################################################
# +-----------------------------------------------------------------+ #
# |                            BO4 object                           | #
# +-----------------------------------------------------------------+ #
#######################################################################

Author: NLBlackEagle

Description: No description given

SettingsMode: WriteWithoutComments


#######################################################################
# +-----------------------------------------------------------------+ #
# |                          Main settings                          | #
# +-----------------------------------------------------------------+ #
#######################################################################

Frequency: 0

SpawnHeight: highestBlock

UseCenterForHighestBlock: true

##############################
# Height Limits for the BO4. #
##############################

MinHeight: 0

MaxHeight: 255

InheritBO3: 

InheritBO3Rotation: NORTH

OverrideChildSettings: true

OverrideParentHeight: false

CanOverride: false

BranchFrequency: 0

BranchFrequencyGroup: 

MustBeBelowOther: false

MustBeInside: 

CannotBeInside: 

ReplacesBO3: 

MustBeInsideWorldBorders: false

CanSpawnOnWater: true

SpawnOnWaterOnly: false

SpawnUnderWater: false

SpawnAtWaterLevel: false

HeightOffset: 0

RemoveAir: true

ReplaceAbove: 

ReplaceBelow: 

ReplaceWithBiomeBlocks: true

ReplaceWithSurfaceBlock: GRASS

ReplaceWithGroundBlock: DIRT

ReplaceWithStoneBlock: STONE

SmoothRadius: 0

SmoothHeightOffset: 0

SmoothStartTop: false

SmoothStartWood: false

SmoothingSurfaceBlock: 

SmoothingGroundBlock: 

BO3Group: 

IsSpawnPoint: false

DoReplaceBlocks: true


#######################################################################
# +-----------------------------------------------------------------+ #
# |                              Blocks                             | #
# +-----------------------------------------------------------------+ #
#######################################################################

Block(-8,0,-7,DIRT:0)
Block(-8,0,-6,DIRT:0)
Block(-8,0,-5,DIRT:0)
Block(-8,0,-4,DIRT:0)
Block(-8,0,-3,DIRT:0)
Block(-8,0,-2,DIRT:0)
Block(-8,0,-1,DIRT:0)
Block(-8,0,0,DIRT:0)
Block(-8,0,1,DIRT:0)
Block(-8,0,2,DIRT:0)
Block(-8,0,3,DIRT:0)
Block(-8,0,4,DIRT:0)
Block(-8,0,5,DIRT:0)
Block(-8,0,6,DIRT:0)
Block(-8,0,7,DIRT:0)
Block(-8,0,8,DIRT:0)
Block(-8,1,-7,DIRT:0)
Block(-8,1,-6,DIRT:0)
Block(-8,1,-5,DIRT:0)
Block(-8,1,-4,DIRT:0)
Block(-8,1,-3,DIRT:0)
Block(-8,1,-2,DIRT:0)
Block(-8,1,-1,DIRT:0)
Block(-8,1,0,DIRT:0)
Block(-8,1,1,DIRT:0)
Block(-8,1,2,DIRT:0)
Block(-8,1,3,DIRT:0)
Block(-8,1,4,DIRT:0)
Block(-8,1,5,DIRT:0)
Block(-8,1,6,DIRT:0)
Block(-8,1,7,DIRT:0)
Block(-8,1,8,DIRT:0)
Block(-8,2,-7,DIRT:0)
Block(-8,2,-6,DIRT:0)
Block(-8,2,-5,DIRT:0)
Block(-8,2,-4,DIRT:0)
Block(-8,2,-3,DIRT:0)
Block(-8,2,-2,DIRT:0)
Block(-8,2,-1,DIRT:0)
Block(-8,2,0,DIRT:0)
Block(-8,2,1,DIRT:0)
Block(-8,2,2,DIRT:0)
Block(-8,2,3,DIRT:0)
Block(-8,2,4,DIRT:0)
Block(-8,2,5,DIRT:0)
Block(-8,2,6,DIRT:0)
Block(-8,2,7,DIRT:0)
Block(-8,2,8,DIRT:0)
Block(-8,3,-7,DIRT:0)
Block(-8,3,-6,DIRT:0)
Block(-8,3,-5,DIRT:0)
Block(-8,3,-4,DIRT:0)
Block(-8,3,-3,DIRT:0)
Block(-8,3,-2,DIRT:0)
Block(-8,3,-1,DIRT:0)
Block(-8,3,0,DIRT:0)
Block(-8,3,1,DIRT:0)
Block(-8,3,2,DIRT:0)
Block(-8,3,3,DIRT:0)
Block(-8,3,4,DIRT:0)
Block(-8,3,5,DIRT:0)
Block(-8,3,6,DIRT:0)
Block(-8,3,7,DIRT:0)
Block(-8,3,8,DIRT:0)
Block(-8,4,-7,DIRT:0)
Block(-8,4,-6,DIRT:0)
Block(-8,4,-5,DIRT:0)
Block(-8,4,-4,DIRT:0)
Block(-8,4,-3,DIRT:0)
Block(-8,4,-2,DIRT:0)
Block(-8,4,-1,DIRT:0)
Block(-8,4,0,DIRT:0)
Block(-8,4,1,DIRT:0)
Block(-8,4,2,DIRT:0)
Block(-8,4,3,DIRT:0)
Block(-8,4,4,DIRT:0)
Block(-8,4,5,DIRT:0)
Block(-8,4,6,DIRT:0)
Block(-8,4,7,DIRT:0)
Block(-8,4,8,DIRT:0)
Block(-8,5,-7,DIRT:0)
Block(-8,5,-6,DIRT:0)
Block(-8,5,-5,DIRT:0)
Block(-8,5,-4,DIRT:0)
Block(-8,5,-3,DIRT:0)
Block(-8,5,-2,DIRT:0)
Block(-8,5,-1,DIRT:0)
Block(-8,5,0,DIRT:0)
Block(-8,5,1,DIRT:0)
Block(-8,5,2,DIRT:0)
Block(-8,5,3,DIRT:0)
Block(-8,5,4,DIRT:0)
Block(-8,5,5,DIRT:0)
Block(-8,5,6,DIRT:0)
Block(-8,5,7,DIRT:0)
Block(-8,5,8,DIRT:0)
Block(-8,6,-7,DIRT:0)
Block(-8,6,-6,DIRT:0)
Block(-8,6,-5,DIRT:0)
Block(-8,6,-4,DIRT:0)
Block(-8,6,-3,DIRT:0)
Block(-8,6,-2,DIRT:0)
Block(-8,6,-1,DIRT:0)
Block(-8,6,0,DIRT:0)
Block(-8,6,1,DIRT:0)
Block(-8,6,2,DIRT:0)
Block(-8,6,3,DIRT:0)
Block(-8,6,4,DIRT:0)
Block(-8,6,5,DIRT:0)
Block(-8,6,6,DIRT:0)
Block(-8,6,7,DIRT:0)
Block(-8,6,8,DIRT:0)
Block(-8,7,-7,DIRT:0)
Block(-8,7,-6,DIRT:0)
Block(-8,7,-5,DIRT:0)
Block(-8,7,-4,DIRT:0)
Block(-8,7,-3,DIRT:0)
Block(-8,7,-2,DIRT:0)
Block(-8,7,-1,DIRT:0)
Block(-8,7,0,DIRT:0)
Block(-8,7,1,DIRT:0)
Block(-8,7,2,DIRT:0)
Block(-8,7,3,DIRT:0)
Block(-8,7,4,DIRT:0)
Block(-8,7,5,DIRT:0)
Block(-8,7,6,DIRT:0)
Block(-8,7,7,DIRT:0)
Block(-8,7,8,DIRT:0)
Block(-8,8,-7,DIRT:0)
Block(-8,8,-6,DIRT:0)
Block(-8,8,-5,DIRT:0)
Block(-8,8,-4,DIRT:0)
Block(-8,8,-3,DIRT:0)
Block(-8,8,-2,DIRT:0)
Block(-8,8,-1,DIRT:0)
Block(-8,8,0,DIRT:0)
Block(-8,8,1,DIRT:0)
Block(-8,8,2,DIRT:0)
Block(-8,8,3,DIRT:0)
Block(-8,8,4,DIRT:0)
Block(-8,8,5,DIRT:0)
Block(-8,8,6,DIRT:0)
Block(-8,8,7,DIRT:0)
Block(-8,8,8,DIRT:0)
Block(-8,9,-7,DIRT:0)
Block(-8,9,-6,DIRT:0)
Block(-8,9,-5,DIRT:0)
Block(-8,9,-4,DIRT:0)
Block(-8,9,-3,DIRT:0)
Block(-8,9,-2,DIRT:0)
Block(-8,9,-1,DIRT:0)
Block(-8,9,0,DIRT:0)
Block(-8,9,1,DIRT:0)
Block(-8,9,2,DIRT:0)
Block(-8,9,3,DIRT:0)
Block(-8,9,4,DIRT:0)
Block(-8,9,5,DIRT:0)
Block(-8,9,6,DIRT:0)
Block(-8,9,7,DIRT:0)
Block(-8,9,8,DIRT:0)
Block(-8,10,-7,DIRT:0)
Block(-8,10,-6,DIRT:0)
Block(-8,10,-5,DIRT:0)
Block(-8,10,-4,DIRT:0)
Block(-8,10,-3,DIRT:0)
Block(-8,10,-2,DIRT:0)
Block(-8,10,-1,DIRT:0)
Block(-8,10,0,DIRT:0)
Block(-8,10,1,DIRT:0)
Block(-8,10,2,DIRT:0)
Block(-8,10,3,DIRT:0)
Block(-8,10,4,DIRT:0)
Block(-8,10,5,DIRT:0)
Block(-8,10,6,DIRT:0)
Block(-8,10,7,DIRT:0)
Block(-8,10,8,DIRT:0)
Block(-8,11,-7,DIRT:0)
Block(-8,11,-6,DIRT:0)
Block(-8,11,-5,DIRT:0)
Block(-8,11,-4,DIRT:0)
Block(-8,11,-3,DIRT:0)
Block(-8,11,-2,DIRT:0)
Block(-8,11,-1,DIRT:0)
Block(-8,11,0,DIRT:0)
Block(-8,11,1,DIRT:0)
Block(-8,11,2,DIRT:0)
Block(-8,11,3,DIRT:0)
Block(-8,11,4,DIRT:0)
Block(-8,11,5,DIRT:0)
Block(-8,11,6,DIRT:0)
Block(-8,11,7,DIRT:0)
Block(-8,11,8,DIRT:0)
Block(-8,12,-7,DIRT:0)
Block(-8,12,-6,DIRT:0)
Block(-8,12,-5,DIRT:0)
Block(-8,12,-4,DIRT:0)
Block(-8,12,-3,DIRT:0)
Block(-8,12,-2,DIRT:0)
Block(-8,12,-1,DIRT:0)
Block(-8,12,0,DIRT:0)
Block(-8,12,1,DIRT:0)
Block(-8,12,2,DIRT:0)
Block(-8,12,3,DIRT:0)
Block(-8,12,4,DIRT:0)
Block(-8,12,5,DIRT:0)
Block(-8,12,6,DIRT:0)
Block(-8,12,7,DIRT:0)
Block(-8,12,8,DIRT:0)
Block(-8,13,-7,DIRT:0)
Block(-8,13,-6,DIRT:0)
Block(-8,13,-5,DIRT:0)
Block(-8,13,-4,DIRT:0)
Block(-8,13,-3,DIRT:0)
Block(-8,13,-2,DIRT:0)
Block(-8,13,-1,DIRT:0)
Block(-8,13,0,DIRT:0)
Block(-8,13,1,DIRT:0)
Block(-8,13,2,DIRT:0)
Block(-8,13,3,DIRT:0)
Block(-8,13,4,DIRT:0)
Block(-8,13,5,DIRT:0)
Block(-8,13,6,DIRT:0)
Block(-8,13,7,DIRT:0)
Block(-8,13,8,DIRT:0)
Block(-8,14,-7,DIRT:0)
Block(-8,14,-6,DIRT:0)
Block(-8,14,-5,DIRT:0)
Block(-8,14,-4,DIRT:0)
Block(-8,14,-3,DIRT:0)
Block(-8,14,-2,DIRT:0)
Block(-8,14,-1,DIRT:0)
Block(-8,14,0,DIRT:0)
Block(-8,14,1,DIRT:0)
Block(-8,14,2,DIRT:0)
Block(-8,14,3,DIRT:0)
Block(-8,14,4,DIRT:0)
Block(-8,14,5,DIRT:0)
Block(-8,14,6,DIRT:0)
Block(-8,14,7,DIRT:0)
Block(-8,14,8,DIRT:0)
Block(-8,15,-7,SAND:0)
Block(-8,15,-6,SAND:0)
Block(-8,15,-5,SAND:0)
Block(-8,15,-4,SAND:0)
Block(-8,15,-3,SAND:0)
Block(-8,15,-2,SAND:0)
Block(-8,15,-1,GRASS:0)
Block(-8,15,0,GRASS:0)
Block(-8,15,1,GRASS:0)
Block(-8,15,2,GRASS:0)
Block(-8,15,3,GRASS:0)
Block(-8,15,4,STATIONARY_WATER:0)
Block(-8,15,5,GRASS:0)
Block(-8,15,6,GRASS:0)
Block(-8,15,7,GRASS:0)
Block(-8,15,8,GRASS:0)
Block(-8,16,-7,CONCRETE:8)
Block(-8,16,-6,CONCRETE:8)
Block(-8,16,-5,CONCRETE:8)
Block(-8,17,-7,CONCRETE_POWDER:8)
Block(-8,17,-6,CONCRETE_POWDER:8)
Block(-8,17,-5,CONCRETE_POWDER:8)
Block(-8,18,-7,CONCRETE:8)
Block(-8,18,-6,CONCRETE:7)
Block(-8,18,-5,CONCRETE_POWDER:8)
Block(-8,18,-4,CONCRETE_POWDER:8)
Block(-8,48,-7,STAINED_GLASS:15)
Block(-8,49,-7,STAINED_GLASS:15)
Block(-8,50,-7,STAINED_GLASS:15)
Block(-8,50,-6,CONCRETE:8)
Block(-8,51,-6,STAINED_GLASS:11)
Block(-8,51,-5,STAINED_GLASS:15)
Block(-8,52,-6,STAINED_GLASS:11)
Block(-8,52,-5,STAINED_GLASS:15)
Block(-8,53,-6,STAINED_GLASS:11)
Block(-8,53,-5,STAINED_GLASS:15)
Block(-8,53,-4,CONCRETE:8)
Block(-8,54,-7,STEP:15)
Block(-8,54,-6,STEP:7)
Block(-8,54,-5,STEP:7)
Block(-8,54,-4,STAINED_GLASS:11)
Block(-8,54,-3,STAINED_GLASS:15)
Block(-8,54,-2,CONCRETE:8)
Block(-8,55,-7,DOUBLE_STEP:7)
Block(-8,55,-4,STAINED_GLASS:11)
Block(-8,55,-3,STAINED_GLASS:15)
Block(-8,55,-2,CONCRETE:8)
Block(-8,56,-4,STAINED_GLASS:11)
Block(-8,56,-3,STAINED_GLASS:15)
Block(-8,56,-2,CONCRETE:8)
Block(-8,57,-2,CONCRETE:8)
Block(-8,57,-1,CONCRETE:8)
Block(-8,57,0,CONCRETE:8)
Block(-8,58,-2,CONCRETE_POWDER:8)
Block(-8,58,-1,CONCRETE:8)
Block(-8,58,0,CONCRETE:8)
Block(-8,59,-2,CONCRETE:8)
Block(-8,59,-1,CONCRETE:8)
Block(-8,59,0,CONCRETE:8)
Block(-8,60,-4,STEP:15)
Block(-8,60,-3,STEP:7)
Block(-8,60,-2,STEP:7)
Block(-8,60,-1,STAINED_GLASS:11)
Block(-8,60,0,CONCRETE:7)
Block(-8,61,-4,minecraft:purple_glazed_terracotta:3)
Block(-8,61,-3,minecraft:purple_glazed_terracotta:3)
Block(-8,61,-1,STAINED_GLASS:11)
Block(-8,61,0,CONCRETE:7)
Block(-8,62,-1,STAINED_GLASS:11)
Block(-8,62,0,CONCRETE:7)
Block(-8,63,-1,STAINED_GLASS:11)
Block(-8,63,0,STAINED_GLASS:15)
Block(-8,64,-1,STAINED_GLASS:11)
Block(-8,64,0,STAINED_GLASS:15)
Block(-8,65,-2,STEP:15)
Block(-8,65,-1,STAINED_GLASS:11)
Block(-8,65,0,STAINED_GLASS:15)
Block(-8,66,-3,STEP:7)
Block(-8,66,-2,CONCRETE_POWDER:8)
Block(-8,66,-1,STAINED_GLASS:11)
Block(-8,66,0,STAINED_GLASS:15)
Block(-8,67,-6,STEP:15)
Block(-8,67,-1,STAINED_GLASS:11)
Block(-8,67,0,STAINED_GLASS:15)
Block(-8,68,-7,STEP:7)
Block(-8,68,-1,STAINED_GLASS:11)
Block(-8,68,0,STAINED_GLASS:15)
Block(-8,69,-1,STAINED_GLASS:11)
Block(-8,69,0,CONCRETE_POWDER:8)
Block(-7,0,-7,DIRT:0)
Block(-7,0,-6,DIRT:0)
Block(-7,0,-5,DIRT:0)
Block(-7,0,-4,DIRT:0)
Block(-7,0,-3,DIRT:0)
Block(-7,0,-2,DIRT:0)
Block(-7,0,-1,DIRT:0)
Block(-7,0,0,DIRT:0)
Block(-7,0,1,DIRT:0)
Block(-7,0,2,DIRT:0)
Block(-7,0,3,DIRT:0)
Block(-7,0,4,DIRT:0)
Block(-7,0,5,DIRT:0)
Block(-7,0,6,DIRT:0)
Block(-7,0,7,DIRT:0)
Block(-7,0,8,DIRT:0)
Block(-7,1,-7,DIRT:0)
Block(-7,1,-6,DIRT:0)
Block(-7,1,-5,DIRT:0)
Block(-7,1,-4,DIRT:0)
Block(-7,1,-3,DIRT:0)
Block(-7,1,-2,DIRT:0)
Block(-7,1,-1,DIRT:0)
Block(-7,1,0,DIRT:0)
Block(-7,1,1,DIRT:0)
Block(-7,1,2,DIRT:0)
Block(-7,1,3,DIRT:0)
Block(-7,1,4,DIRT:0)
Block(-7,1,5,DIRT:0)
Block(-7,1,6,DIRT:0)
Block(-7,1,7,DIRT:0)
Block(-7,1,8,DIRT:0)
Block(-7,2,-7,DIRT:0)
Block(-7,2,-6,DIRT:0)
Block(-7,2,-5,DIRT:0)
Block(-7,2,-4,DIRT:0)
Block(-7,2,-3,DIRT:0)
Block(-7,2,-2,DIRT:0)
Block(-7,2,-1,DIRT:0)
Block(-7,2,0,DIRT:0)
Block(-7,2,1,DIRT:0)
Block(-7,2,2,DIRT:0)
Block(-7,2,3,DIRT:0)
Block(-7,2,4,DIRT:0)
Block(-7,2,5,DIRT:0)
Block(-7,2,6,DIRT:0)
Block(-7,2,7,DIRT:0)
Block(-7,2,8,DIRT:0)
Block(-7,3,-7,DIRT:0)
Block(-7,3,-6,DIRT:0)
Block(-7,3,-5,DIRT:0)
Block(-7,3,-4,DIRT:0)
Block(-7,3,-3,DIRT:0)
Block(-7,3,-2,DIRT:0)
Block(-7,3,-1,DIRT:0)
Block(-7,3,0,DIRT:0)
Block(-7,3,1,DIRT:0)
Block(-7,3,2,DIRT:0)
Block(-7,3,3,DIRT:0)
Block(-7,3,4,DIRT:0)
Block(-7,3,5,DIRT:0)
Block(-7,3,6,DIRT:0)
Block(-7,3,7,DIRT:0)
Block(-7,3,8,DIRT:0)
Block(-7,4,-7,DIRT:0)
Block(-7,4,-6,DIRT:0)
Block(-7,4,-5,DIRT:0)
Block(-7,4,-4,DIRT:0)
Block(-7,4,-3,DIRT:0)
Block(-7,4,-2,DIRT:0)
Block(-7,4,-1,DIRT:0)
Block(-7,4,0,DIRT:0)
Block(-7,4,1,DIRT:0)
Block(-7,4,2,DIRT:0)
Block(-7,4,3,DIRT:0)
Block(-7,4,4,DIRT:0)
Block(-7,4,5,DIRT:0)
Block(-7,4,6,DIRT:0)
Block(-7,4,7,DIRT:0)
Block(-7,4,8,DIRT:0)
Block(-7,5,-7,DIRT:0)
Block(-7,5,-6,DIRT:0)
Block(-7,5,-5,DIRT:0)
Block(-7,5,-4,DIRT:0)
Block(-7,5,-3,DIRT:0)
Block(-7,5,-2,DIRT:0)
Block(-7,5,-1,DIRT:0)
Block(-7,5,0,DIRT:0)
Block(-7,5,1,DIRT:0)
Block(-7,5,2,DIRT:0)
Block(-7,5,3,DIRT:0)
Block(-7,5,4,DIRT:0)
Block(-7,5,5,DIRT:0)
Block(-7,5,6,DIRT:0)
Block(-7,5,7,DIRT:0)
Block(-7,5,8,DIRT:0)
Block(-7,6,-7,DIRT:0)
Block(-7,6,-6,DIRT:0)
Block(-7,6,-5,DIRT:0)
Block(-7,6,-4,DIRT:0)
Block(-7,6,-3,DIRT:0)
Block(-7,6,-2,DIRT:0)
Block(-7,6,-1,DIRT:0)
Block(-7,6,0,DIRT:0)
Block(-7,6,1,DIRT:0)
Block(-7,6,2,DIRT:0)
Block(-7,6,3,DIRT:0)
Block(-7,6,4,DIRT:0)
Block(-7,6,5,DIRT:0)
Block(-7,6,6,DIRT:0)
Block(-7,6,7,DIRT:0)
Block(-7,6,8,DIRT:0)
Block(-7,7,-7,DIRT:0)
Block(-7,7,-6,DIRT:0)
Block(-7,7,-5,DIRT:0)
Block(-7,7,-4,DIRT:0)
Block(-7,7,-3,DIRT:0)
Block(-7,7,-2,DIRT:0)
Block(-7,7,-1,DIRT:0)
Block(-7,7,0,DIRT:0)
Block(-7,7,1,DIRT:0)
Block(-7,7,2,DIRT:0)
Block(-7,7,3,DIRT:0)
Block(-7,7,4,DIRT:0)
Block(-7,7,5,DIRT:0)
Block(-7,7,6,DIRT:0)
Block(-7,7,7,DIRT:0)
Block(-7,7,8,DIRT:0)
Block(-7,8,-7,DIRT:0)
Block(-7,8,-6,DIRT:0)
Block(-7,8,-5,DIRT:0)
Block(-7,8,-4,DIRT:0)
Block(-7,8,-3,DIRT:0)
Block(-7,8,-2,DIRT:0)
Block(-7,8,-1,DIRT:0)
Block(-7,8,0,DIRT:0)
Block(-7,8,1,DIRT:0)
Block(-7,8,2,DIRT:0)
Block(-7,8,3,DIRT:0)
Block(-7,8,4,DIRT:0)
Block(-7,8,5,DIRT:0)
Block(-7,8,6,DIRT:0)
Block(-7,8,7,DIRT:0)
Block(-7,8,8,DIRT:0)
Block(-7,9,-7,DIRT:0)
Block(-7,9,-6,DIRT:0)
Block(-7,9,-5,DIRT:0)
Block(-7,9,-4,DIRT:0)
Block(-7,9,-3,DIRT:0)
Block(-7,9,-2,DIRT:0)
Block(-7,9,-1,DIRT:0)
Block(-7,9,0,DIRT:0)
Block(-7,9,1,DIRT:0)
Block(-7,9,2,DIRT:0)
Block(-7,9,3,DIRT:0)
Block(-7,9,4,DIRT:0)
Block(-7,9,5,DIRT:0)
Block(-7,9,6,DIRT:0)
Block(-7,9,7,DIRT:0)
Block(-7,9,8,DIRT:0)
Block(-7,10,-7,DIRT:0)
Block(-7,10,-6,DIRT:0)
Block(-7,10,-5,DIRT:0)
Block(-7,10,-4,DIRT:0)
Block(-7,10,-3,DIRT:0)
Block(-7,10,-2,DIRT:0)
Block(-7,10,-1,DIRT:0)
Block(-7,10,0,DIRT:0)
Block(-7,10,1,DIRT:0)
Block(-7,10,2,DIRT:0)
Block(-7,10,3,DIRT:0)
Block(-7,10,4,DIRT:0)
Block(-7,10,5,DIRT:0)
Block(-7,10,6,DIRT:0)
Block(-7,10,7,DIRT:0)
Block(-7,10,8,DIRT:0)
Block(-7,11,-7,DIRT:0)
Block(-7,11,-6,DIRT:0)
Block(-7,11,-5,DIRT:0)
Block(-7,11,-4,DIRT:0)
Block(-7,11,-3,DIRT:0)
Block(-7,11,-2,DIRT:0)
Block(-7,11,-1,DIRT:0)
Block(-7,11,0,DIRT:0)
Block(-7,11,1,DIRT:0)
Block(-7,11,2,DIRT:0)
Block(-7,11,3,DIRT:0)
Block(-7,11,4,DIRT:0)
Block(-7,11,5,DIRT:0)
Block(-7,11,6,DIRT:0)
Block(-7,11,7,DIRT:0)
Block(-7,11,8,DIRT:0)
Block(-7,12,-7,DIRT:0)
Block(-7,12,-6,DIRT:0)
Block(-7,12,-5,DIRT:0)
Block(-7,12,-4,DIRT:0)
Block(-7,12,-3,DIRT:0)
Block(-7,12,-2,DIRT:0)
Block(-7,12,-1,DIRT:0)
Block(-7,12,0,DIRT:0)
Block(-7,12,1,DIRT:0)
Block(-7,12,2,DIRT:0)
Block(-7,12,3,DIRT:0)
Block(-7,12,4,DIRT:0)
Block(-7,12,5,DIRT:0)
Block(-7,12,6,DIRT:0)
Block(-7,12,7,DIRT:0)
Block(-7,12,8,DIRT:0)
Block(-7,13,-7,DIRT:0)
Block(-7,13,-6,DIRT:0)
Block(-7,13,-5,DIRT:0)
Block(-7,13,-4,DIRT:0)
Block(-7,13,-3,DIRT:0)
Block(-7,13,-2,DIRT:0)
Block(-7,13,-1,DIRT:0)
Block(-7,13,0,DIRT:0)
Block(-7,13,1,DIRT:0)
Block(-7,13,2,DIRT:0)
Block(-7,13,3,DIRT:0)
Block(-7,13,4,DIRT:0)
Block(-7,13,5,DIRT:0)
Block(-7,13,6,DIRT:0)
Block(-7,13,7,DIRT:0)
Block(-7,13,8,DIRT:0)
Block(-7,14,-7,DIRT:0)
Block(-7,14,-6,DIRT:0)
Block(-7,14,-5,DIRT:0)
Block(-7,14,-4,DIRT:0)
Block(-7,14,-3,DIRT:0)
Block(-7,14,-2,DIRT:0)
Block(-7,14,-1,DIRT:0)
Block(-7,14,0,DIRT:0)
Block(-7,14,1,DIRT:0)
Block(-7,14,2,DIRT:0)
Block(-7,14,3,DIRT:0)
Block(-7,14,4,DIRT:0)
Block(-7,14,5,DIRT:0)
Block(-7,14,6,DIRT:0)
Block(-7,14,7,DIRT:0)
Block(-7,14,8,DIRT:0)
Block(-7,15,-7,SAND:0)
Block(-7,15,-6,SAND:0)
Block(-7,15,-5,SAND:0)
Block(-7,15,-4,SAND:0)
Block(-7,15,-3,SAND:0)
Block(-7,15,-2,SAND:0)
Block(-7,15,-1,GRASS:0)
Block(-7,15,0,GRASS:0)
Block(-7,15,1,GRASS:0)
Block(-7,15,2,GRASS:0)
Block(-7,15,3,GRASS:0)
Block(-7,15,4,GRASS:0)
Block(-7,15,5,GRASS:0)
Block(-7,15,6,GRASS:0)
Block(-7,15,7,GRASS:0)
Block(-7,15,8,GRASS:0)
Block(-7,16,-6,CONCRETE:8)
Block(-7,17,-6,CONCRETE_POWDER:8)
Block(-7,18,-7,CONCRETE:8)
Block(-7,18,-6,CONCRETE:7)
Block(-7,18,-5,CONCRETE:8)
Block(-7,48,-7,CONCRETE:7)
Block(-7,49,-7,CONCRETE:7)
Block(-7,50,-7,CONCRETE:7)
Block(-7,51,-7,STAINED_GLASS:11)
Block(-7,51,-6,STAINED_GLASS:15)
Block(-7,51,-5,CONCRETE:8)
Block(-7,52,-7,STAINED_GLASS:11)
Block(-7,52,-6,STAINED_GLASS:15)
Block(-7,52,-5,CONCRETE:8)
Block(-7,53,-7,STAINED_GLASS:11)
Block(-7,53,-6,STAINED_GLASS:15)
Block(-7,53,-5,CONCRETE:8)
Block(-7,54,-7,DOUBLE_STEP:7)
Block(-7,54,-6,DOUBLE_STEP:7)
Block(-7,54,-5,STAINED_GLASS:11)
Block(-7,54,-4,STAINED_GLASS:15)
Block(-7,54,-3,CONCRETE:8)
Block(-7,55,-7,DOUBLE_STEP:7)
Block(-7,55,-5,STAINED_GLASS:11)
Block(-7,55,-4,STAINED_GLASS:15)
Block(-7,55,-3,CONCRETE:8)
Block(-7,56,-5,STAINED_GLASS:11)
Block(-7,56,-4,STAINED_GLASS:15)
Block(-7,56,-3,CONCRETE:8)
Block(-7,57,-3,STAINED_GLASS:11)
Block(-7,57,-2,STAINED_GLASS:15)
Block(-7,57,-1,CONCRETE:8)
Block(-7,58,-3,STAINED_GLASS:11)
Block(-7,58,-2,STAINED_GLASS:15)
Block(-7,58,-1,CONCRETE:8)
Block(-7,59,-3,STAINED_GLASS:11)
Block(-7,59,-2,STAINED_GLASS:15)
Block(-7,59,-1,CONCRETE:8)
Block(-7,60,-3,STEP:7)
Block(-7,60,-2,STEP:7)
Block(-7,60,-1,CONCRETE:8)
Block(-7,60,0,CONCRETE:8)
Block(-7,60,1,CONCRETE:8)
Block(-7,61,-1,CONCRETE:8)
Block(-7,61,0,CONCRETE_POWDER:8)
Block(-7,61,1,CONCRETE:8)
Block(-7,62,-1,CONCRETE_POWDER:8)
Block(-7,62,0,CONCRETE:8)
Block(-7,62,1,CONCRETE:8)
Block(-7,63,0,STAINED_GLASS:11)
Block(-7,63,1,CONCRETE:7)
Block(-7,64,-1,STEP:7)
Block(-7,64,0,STAINED_GLASS:11)
Block(-7,64,1,CONCRETE:7)
Block(-7,65,-2,STEP:15)
Block(-7,65,-1,CONCRETE_POWDER:8)
Block(-7,65,0,STAINED_GLASS:11)
Block(-7,65,1,CONCRETE:7)
Block(-7,66,0,STAINED_GLASS:11)
Block(-7,66,1,CONCRETE:7)
Block(-7,67,-7,STEP:15)
Block(-7,67,-6,STEP:15)
Block(-7,67,0,STAINED_GLASS:11)
Block(-7,67,1,CONCRETE:7)
Block(-7,68,0,STAINED_GLASS:11)
Block(-7,68,1,CONCRETE:7)
Block(-6,0,-7,DIRT:0)
Block(-6,0,-6,DIRT:0)
Block(-6,0,-5,DIRT:0)
Block(-6,0,-4,DIRT:0)
Block(-6,0,-3,DIRT:0)
Block(-6,0,-2,DIRT:0)
Block(-6,0,-1,DIRT:0)
Block(-6,0,0,DIRT:0)
Block(-6,0,1,DIRT:0)
Block(-6,0,2,DIRT:0)
Block(-6,0,3,DIRT:0)
Block(-6,0,4,DIRT:0)
Block(-6,0,5,DIRT:0)
Block(-6,0,6,DIRT:0)
Block(-6,0,7,DIRT:0)
Block(-6,0,8,DIRT:0)
Block(-6,1,-7,DIRT:0)
Block(-6,1,-6,DIRT:0)
Block(-6,1,-5,DIRT:0)
Block(-6,1,-4,DIRT:0)
Block(-6,1,-3,DIRT:0)
Block(-6,1,-2,DIRT:0)
Block(-6,1,-1,DIRT:0)
Block(-6,1,0,DIRT:0)
Block(-6,1,1,DIRT:0)
Block(-6,1,2,DIRT:0)
Block(-6,1,3,DIRT:0)
Block(-6,1,4,DIRT:0)
Block(-6,1,5,DIRT:0)
Block(-6,1,6,DIRT:0)
Block(-6,1,7,DIRT:0)
Block(-6,1,8,DIRT:0)
Block(-6,2,-7,DIRT:0)
Block(-6,2,-6,DIRT:0)
Block(-6,2,-5,DIRT:0)
Block(-6,2,-4,DIRT:0)
Block(-6,2,-3,DIRT:0)
Block(-6,2,-2,DIRT:0)
Block(-6,2,-1,DIRT:0)
Block(-6,2,0,DIRT:0)
Block(-6,2,1,DIRT:0)
Block(-6,2,2,DIRT:0)
Block(-6,2,3,DIRT:0)
Block(-6,2,4,DIRT:0)
Block(-6,2,5,DIRT:0)
Block(-6,2,6,DIRT:0)
Block(-6,2,7,DIRT:0)
Block(-6,2,8,DIRT:0)
Block(-6,3,-7,DIRT:0)
Block(-6,3,-6,DIRT:0)
Block(-6,3,-5,DIRT:0)
Block(-6,3,-4,DIRT:0)
Block(-6,3,-3,DIRT:0)
Block(-6,3,-2,DIRT:0)
Block(-6,3,-1,DIRT:0)
Block(-6,3,0,DIRT:0)
Block(-6,3,1,DIRT:0)
Block(-6,3,2,DIRT:0)
Block(-6,3,3,DIRT:0)
Block(-6,3,4,DIRT:0)
Block(-6,3,5,DIRT:0)
Block(-6,3,6,DIRT:0)
Block(-6,3,7,DIRT:0)
Block(-6,3,8,DIRT:0)
Block(-6,4,-7,DIRT:0)
Block(-6,4,-6,DIRT:0)
Block(-6,4,-5,DIRT:0)
Block(-6,4,-4,DIRT:0)
Block(-6,4,-3,DIRT:0)
Block(-6,4,-2,DIRT:0)
Block(-6,4,-1,DIRT:0)
Block(-6,4,0,DIRT:0)
Block(-6,4,1,DIRT:0)
Block(-6,4,2,DIRT:0)
Block(-6,4,3,DIRT:0)
Block(-6,4,4,DIRT:0)
Block(-6,4,5,DIRT:0)
Block(-6,4,6,DIRT:0)
Block(-6,4,7,DIRT:0)
Block(-6,4,8,DIRT:0)
Block(-6,5,-7,DIRT:0)
Block(-6,5,-6,DIRT:0)
Block(-6,5,-5,DIRT:0)
Block(-6,5,-4,DIRT:0)
Block(-6,5,-3,DIRT:0)
Block(-6,5,-2,DIRT:0)
Block(-6,5,-1,DIRT:0)
Block(-6,5,0,DIRT:0)
Block(-6,5,1,DIRT:0)
Block(-6,5,2,DIRT:0)
Block(-6,5,3,DIRT:0)
Block(-6,5,4,DIRT:0)
Block(-6,5,5,DIRT:0)
Block(-6,5,6,DIRT:0)
Block(-6,5,7,DIRT:0)
Block(-6,5,8,DIRT:0)
Block(-6,6,-7,DIRT:0)
Block(-6,6,-6,DIRT:0)
Block(-6,6,-5,DIRT:0)
Block(-6,6,-4,DIRT:0)
Block(-6,6,-3,DIRT:0)
Block(-6,6,-2,DIRT:0)
Block(-6,6,-1,DIRT:0)
Block(-6,6,0,DIRT:0)
Block(-6,6,1,DIRT:0)
Block(-6,6,2,DIRT:0)
Block(-6,6,3,DIRT:0)
Block(-6,6,4,DIRT:0)
Block(-6,6,5,DIRT:0)
Block(-6,6,6,DIRT:0)
Block(-6,6,7,DIRT:0)
Block(-6,6,8,DIRT:0)
Block(-6,7,-7,DIRT:0)
Block(-6,7,-6,DIRT:0)
Block(-6,7,-5,DIRT:0)
Block(-6,7,-4,DIRT:0)
Block(-6,7,-3,DIRT:0)
Block(-6,7,-2,DIRT:0)
Block(-6,7,-1,DIRT:0)
Block(-6,7,0,DIRT:0)
Block(-6,7,1,DIRT:0)
Block(-6,7,2,DIRT:0)
Block(-6,7,3,DIRT:0)
Block(-6,7,4,DIRT:0)
Block(-6,7,5,DIRT:0)
Block(-6,7,6,DIRT:0)
Block(-6,7,7,DIRT:0)
Block(-6,7,8,DIRT:0)
Block(-6,8,-7,DIRT:0)
Block(-6,8,-6,DIRT:0)
Block(-6,8,-5,DIRT:0)
Block(-6,8,-4,DIRT:0)
Block(-6,8,-3,DIRT:0)
Block(-6,8,-2,DIRT:0)
Block(-6,8,-1,DIRT:0)
Block(-6,8,0,DIRT:0)
Block(-6,8,1,DIRT:0)
Block(-6,8,2,DIRT:0)
Block(-6,8,3,DIRT:0)
Block(-6,8,4,DIRT:0)
Block(-6,8,5,DIRT:0)
Block(-6,8,6,DIRT:0)
Block(-6,8,7,DIRT:0)
Block(-6,8,8,DIRT:0)
Block(-6,9,-7,DIRT:0)
Block(-6,9,-6,DIRT:0)
Block(-6,9,-5,DIRT:0)
Block(-6,9,-4,DIRT:0)
Block(-6,9,-3,DIRT:0)
Block(-6,9,-2,DIRT:0)
Block(-6,9,-1,DIRT:0)
Block(-6,9,0,DIRT:0)
Block(-6,9,1,DIRT:0)
Block(-6,9,2,DIRT:0)
Block(-6,9,3,DIRT:0)
Block(-6,9,4,DIRT:0)
Block(-6,9,5,DIRT:0)
Block(-6,9,6,DIRT:0)
Block(-6,9,7,DIRT:0)
Block(-6,9,8,DIRT:0)
Block(-6,10,-7,DIRT:0)
Block(-6,10,-6,DIRT:0)
Block(-6,10,-5,DIRT:0)
Block(-6,10,-4,DIRT:0)
Block(-6,10,-3,DIRT:0)
Block(-6,10,-2,DIRT:0)
Block(-6,10,-1,DIRT:0)
Block(-6,10,0,DIRT:0)
Block(-6,10,1,DIRT:0)
Block(-6,10,2,DIRT:0)
Block(-6,10,3,DIRT:0)
Block(-6,10,4,DIRT:0)
Block(-6,10,5,DIRT:0)
Block(-6,10,6,DIRT:0)
Block(-6,10,7,DIRT:0)
Block(-6,10,8,DIRT:0)
Block(-6,11,-7,DIRT:0)
Block(-6,11,-6,DIRT:0)
Block(-6,11,-5,DIRT:0)
Block(-6,11,-4,DIRT:0)
Block(-6,11,-3,DIRT:0)
Block(-6,11,-2,DIRT:0)
Block(-6,11,-1,DIRT:0)
Block(-6,11,0,DIRT:0)
Block(-6,11,1,DIRT:0)
Block(-6,11,2,DIRT:0)
Block(-6,11,3,DIRT:0)
Block(-6,11,4,DIRT:0)
Block(-6,11,5,DIRT:0)
Block(-6,11,6,DIRT:0)
Block(-6,11,7,DIRT:0)
Block(-6,11,8,DIRT:0)
Block(-6,12,-7,DIRT:0)
Block(-6,12,-6,DIRT:0)
Block(-6,12,-5,DIRT:0)
Block(-6,12,-4,DIRT:0)
Block(-6,12,-3,DIRT:0)
Block(-6,12,-2,DIRT:0)
Block(-6,12,-1,DIRT:0)
Block(-6,12,0,DIRT:0)
Block(-6,12,1,DIRT:0)
Block(-6,12,2,DIRT:0)
Block(-6,12,3,DIRT:0)
Block(-6,12,4,DIRT:0)
Block(-6,12,5,DIRT:0)
Block(-6,12,6,DIRT:0)
Block(-6,12,7,DIRT:0)
Block(-6,12,8,DIRT:0)
Block(-6,13,-7,DIRT:0)
Block(-6,13,-6,DIRT:0)
Block(-6,13,-5,DIRT:0)
Block(-6,13,-4,DIRT:0)
Block(-6,13,-3,DIRT:0)
Block(-6,13,-2,DIRT:0)
Block(-6,13,-1,DIRT:0)
Block(-6,13,0,DIRT:0)
Block(-6,13,1,DIRT:0)
Block(-6,13,2,DIRT:0)
Block(-6,13,3,DIRT:0)
Block(-6,13,4,DIRT:0)
Block(-6,13,5,DIRT:0)
Block(-6,13,6,DIRT:0)
Block(-6,13,7,DIRT:0)
Block(-6,13,8,DIRT:0)
Block(-6,14,-7,DIRT:0)
Block(-6,14,-6,DIRT:0)
Block(-6,14,-5,DIRT:0)
Block(-6,14,-4,DIRT:0)
Block(-6,14,-3,DIRT:0)
Block(-6,14,-2,DIRT:0)
Block(-6,14,-1,DIRT:0)
Block(-6,14,0,DIRT:0)
Block(-6,14,1,DIRT:0)
Block(-6,14,2,DIRT:0)
Block(-6,14,3,DIRT:0)
Block(-6,14,4,DIRT:0)
Block(-6,14,5,DIRT:0)
Block(-6,14,6,DIRT:0)
Block(-6,14,7,DIRT:0)
Block(-6,14,8,DIRT:0)
Block(-6,15,-7,STAINED_CLAY:7)
Block(-6,15,-6,SAND:0)
Block(-6,15,-5,SAND:0)
Block(-6,15,-4,SAND:0)
Block(-6,15,-3,SAND:0)
Block(-6,15,-2,SAND:0)
Block(-6,15,-1,GRASS:0)
Block(-6,15,0,GRASS:0)
Block(-6,15,1,GRASS:0)
Block(-6,15,2,GRASS:0)
Block(-6,15,3,GRASS:0)
Block(-6,15,4,GRASS:0)
Block(-6,15,5,GRASS:0)
Block(-6,15,6,GRASS:0)
Block(-6,15,7,GRASS:0)
Block(-6,15,8,GRASS:0)
Block(-6,18,-7,CONCRETE:8)
Block(-6,18,-6,CONCRETE:7)
Block(-6,18,-5,CONCRETE_POWDER:8)
Block(-6,51,-7,STAINED_GLASS:15)
Block(-6,52,-7,STAINED_GLASS:15)
Block(-6,53,-7,STAINED_GLASS:15)
Block(-6,53,-6,STAINED_GLASS:15)
Block(-6,54,-7,DOUBLE_STEP:7)
Block(-6,54,-6,STAINED_GLASS:11)
Block(-6,54,-5,STAINED_GLASS:15)
Block(-6,55,-7,DOUBLE_STEP:7)
Block(-6,55,-6,STAINED_GLASS:11)
Block(-6,55,-5,STAINED_GLASS:15)
Block(-6,56,-7,STEP:7)
Block(-6,56,-6,STAINED_GLASS:11)
Block(-6,56,-5,STAINED_GLASS:15)
Block(-6,56,-4,STAINED_GLASS:15)
Block(-6,57,-4,STAINED_GLASS:11)
Block(-6,57,-3,STAINED_GLASS:15)
Block(-6,57,-2,CONCRETE:8)
Block(-6,58,-4,STAINED_GLASS:11)
Block(-6,58,-3,STAINED_GLASS:15)
Block(-6,59,-4,STAINED_GLASS:11)
Block(-6,59,-3,STAINED_GLASS:15)
Block(-6,59,-2,STAINED_GLASS:15)
Block(-6,60,-4,DOUBLE_STEP:7)
Block(-6,60,-3,DOUBLE_STEP:7)
Block(-6,60,-2,STAINED_GLASS:11)
Block(-6,60,-1,STAINED_GLASS:15)
Block(-6,60,0,CONCRETE:8)
Block(-6,61,-4,STEP:7)
Block(-6,61,-3,STEP:7)
Block(-6,61,-2,STAINED_GLASS:11)
Block(-6,61,-1,STAINED_GLASS:15)
Block(-6,61,0,CONCRETE_POWDER:8)
Block(-6,62,-2,STAINED_GLASS:11)
Block(-6,62,-1,STAINED_GLASS:15)
Block(-6,62,0,CONCRETE:8)
Block(-6,63,-1,STEP:7)
Block(-6,63,0,CONCRETE_POWDER:8)
Block(-6,63,1,CONCRETE:8)
Block(-6,63,2,CONCRETE:8)
Block(-6,64,0,CONCRETE:8)
Block(-6,64,1,CONCRETE:8)
Block(-6,64,2,CONCRETE:8)
Block(-6,65,0,CONCRETE_POWDER:8)
Block(-6,65,1,CONCRETE_POWDER:8)
Block(-6,65,2,CONCRETE_POWDER:8)
Block(-6,66,0,CONCRETE:8)
Block(-6,66,1,CONCRETE:8)
Block(-6,66,2,CONCRETE:8)
Block(-6,67,-7,STEP:15)
Block(-6,67,0,CONCRETE:8)
Block(-6,67,1,CONCRETE:8)
Block(-6,67,2,CONCRETE:8)
Block(-6,68,0,CONCRETE:8)
Block(-6,68,1,CONCRETE:8)
Block(-5,0,-7,DIRT:0)
Block(-5,0,-6,DIRT:0)
Block(-5,0,-5,DIRT:0)
Block(-5,0,-4,DIRT:0)
Block(-5,0,-3,DIRT:0)
Block(-5,0,-2,DIRT:0)
Block(-5,0,-1,DIRT:0)
Block(-5,0,0,DIRT:0)
Block(-5,0,1,DIRT:0)
Block(-5,0,2,DIRT:0)
Block(-5,0,3,DIRT:0)
Block(-5,0,4,DIRT:0)
Block(-5,0,5,DIRT:0)
Block(-5,0,6,DIRT:0)
Block(-5,0,7,DIRT:0)
Block(-5,0,8,DIRT:0)
Block(-5,1,-7,DIRT:0)
Block(-5,1,-6,DIRT:0)
Block(-5,1,-5,DIRT:0)
Block(-5,1,-4,DIRT:0)
Block(-5,1,-3,DIRT:0)
Block(-5,1,-2,DIRT:0)
Block(-5,1,-1,DIRT:0)
Block(-5,1,0,DIRT:0)
Block(-5,1,1,DIRT:0)
Block(-5,1,2,DIRT:0)
Block(-5,1,3,DIRT:0)
Block(-5,1,4,DIRT:0)
Block(-5,1,5,DIRT:0)
Block(-5,1,6,DIRT:0)
Block(-5,1,7,DIRT:0)
Block(-5,1,8,DIRT:0)
Block(-5,2,-7,DIRT:0)
Block(-5,2,-6,DIRT:0)
Block(-5,2,-5,DIRT:0)
Block(-5,2,-4,DIRT:0)
Block(-5,2,-3,DIRT:0)
Block(-5,2,-2,DIRT:0)
Block(-5,2,-1,DIRT:0)
Block(-5,2,0,DIRT:0)
Block(-5,2,1,DIRT:0)
Block(-5,2,2,DIRT:0)
Block(-5,2,3,DIRT:0)
Block(-5,2,4,DIRT:0)
Block(-5,2,5,DIRT:0)
Block(-5,2,6,DIRT:0)
Block(-5,2,7,DIRT:0)
Block(-5,2,8,DIRT:0)
Block(-5,3,-7,DIRT:0)
Block(-5,3,-6,DIRT:0)
Block(-5,3,-5,DIRT:0)
Block(-5,3,-4,DIRT:0)
Block(-5,3,-3,DIRT:0)
Block(-5,3,-2,DIRT:0)
Block(-5,3,-1,DIRT:0)
Block(-5,3,0,DIRT:0)
Block(-5,3,1,DIRT:0)
Block(-5,3,2,DIRT:0)
Block(-5,3,3,DIRT:0)
Block(-5,3,4,DIRT:0)
Block(-5,3,5,DIRT:0)
Block(-5,3,6,DIRT:0)
Block(-5,3,7,DIRT:0)
Block(-5,3,8,DIRT:0)
Block(-5,4,-7,DIRT:0)
Block(-5,4,-6,DIRT:0)
Block(-5,4,-5,DIRT:0)
Block(-5,4,-4,DIRT:0)
Block(-5,4,-3,DIRT:0)
Block(-5,4,-2,DIRT:0)
Block(-5,4,-1,DIRT:0)
Block(-5,4,0,DIRT:0)
Block(-5,4,1,DIRT:0)
Block(-5,4,2,DIRT:0)
Block(-5,4,3,DIRT:0)
Block(-5,4,4,DIRT:0)
Block(-5,4,5,DIRT:0)
Block(-5,4,6,DIRT:0)
Block(-5,4,7,DIRT:0)
Block(-5,4,8,DIRT:0)
Block(-5,5,-7,DIRT:0)
Block(-5,5,-6,DIRT:0)
Block(-5,5,-5,DIRT:0)
Block(-5,5,-4,DIRT:0)
Block(-5,5,-3,DIRT:0)
Block(-5,5,-2,DIRT:0)
Block(-5,5,-1,DIRT:0)
Block(-5,5,0,DIRT:0)
Block(-5,5,1,DIRT:0)
Block(-5,5,2,DIRT:0)
Block(-5,5,3,DIRT:0)
Block(-5,5,4,DIRT:0)
Block(-5,5,5,DIRT:0)
Block(-5,5,6,DIRT:0)
Block(-5,5,7,DIRT:0)
Block(-5,5,8,DIRT:0)
Block(-5,6,-7,DIRT:0)
Block(-5,6,-6,DIRT:0)
Block(-5,6,-5,DIRT:0)
Block(-5,6,-4,DIRT:0)
Block(-5,6,-3,DIRT:0)
Block(-5,6,-2,DIRT:0)
Block(-5,6,-1,DIRT:0)
Block(-5,6,0,DIRT:0)
Block(-5,6,1,DIRT:0)
Block(-5,6,2,DIRT:0)
Block(-5,6,3,DIRT:0)
Block(-5,6,4,DIRT:0)
Block(-5,6,5,DIRT:0)
Block(-5,6,6,DIRT:0)
Block(-5,6,7,DIRT:0)
Block(-5,6,8,DIRT:0)
Block(-5,7,-7,DIRT:0)
Block(-5,7,-6,DIRT:0)
Block(-5,7,-5,DIRT:0)
Block(-5,7,-4,DIRT:0)
Block(-5,7,-3,DIRT:0)
Block(-5,7,-2,DIRT:0)
Block(-5,7,-1,DIRT:0)
Block(-5,7,0,DIRT:0)
Block(-5,7,1,DIRT:0)
Block(-5,7,2,DIRT:0)
Block(-5,7,3,DIRT:0)
Block(-5,7,4,DIRT:0)
Block(-5,7,5,DIRT:0)
Block(-5,7,6,DIRT:0)
Block(-5,7,7,DIRT:0)
Block(-5,7,8,DIRT:0)
Block(-5,8,-7,DIRT:0)
Block(-5,8,-6,DIRT:0)
Block(-5,8,-5,DIRT:0)
Block(-5,8,-4,DIRT:0)
Block(-5,8,-3,DIRT:0)
Block(-5,8,-2,DIRT:0)
Block(-5,8,-1,DIRT:0)
Block(-5,8,0,DIRT:0)
Block(-5,8,1,DIRT:0)
Block(-5,8,2,DIRT:0)
Block(-5,8,3,DIRT:0)
Block(-5,8,4,DIRT:0)
Block(-5,8,5,DIRT:0)
Block(-5,8,6,DIRT:0)
Block(-5,8,7,DIRT:0)
Block(-5,8,8,DIRT:0)
Block(-5,9,-7,DIRT:0)
Block(-5,9,-6,DIRT:0)
Block(-5,9,-5,DIRT:0)
Block(-5,9,-4,DIRT:0)
Block(-5,9,-3,DIRT:0)
Block(-5,9,-2,DIRT:0)
Block(-5,9,-1,DIRT:0)
Block(-5,9,0,DIRT:0)
Block(-5,9,1,DIRT:0)
Block(-5,9,2,DIRT:0)
Block(-5,9,3,DIRT:0)
Block(-5,9,4,DIRT:0)
Block(-5,9,5,DIRT:0)
Block(-5,9,6,DIRT:0)
Block(-5,9,7,DIRT:0)
Block(-5,9,8,DIRT:0)
Block(-5,10,-7,DIRT:0)
Block(-5,10,-6,DIRT:0)
Block(-5,10,-5,DIRT:0)
Block(-5,10,-4,DIRT:0)
Block(-5,10,-3,DIRT:0)
Block(-5,10,-2,DIRT:0)
Block(-5,10,-1,DIRT:0)
Block(-5,10,0,DIRT:0)
Block(-5,10,1,DIRT:0)
Block(-5,10,2,DIRT:0)
Block(-5,10,3,DIRT:0)
Block(-5,10,4,DIRT:0)
Block(-5,10,5,DIRT:0)
Block(-5,10,6,DIRT:0)
Block(-5,10,7,DIRT:0)
Block(-5,10,8,DIRT:0)
Block(-5,11,-7,DIRT:0)
Block(-5,11,-6,DIRT:0)
Block(-5,11,-5,DIRT:0)
Block(-5,11,-4,DIRT:0)
Block(-5,11,-3,DIRT:0)
Block(-5,11,-2,DIRT:0)
Block(-5,11,-1,DIRT:0)
Block(-5,11,0,DIRT:0)
Block(-5,11,1,DIRT:0)
Block(-5,11,2,DIRT:0)
Block(-5,11,3,DIRT:0)
Block(-5,11,4,DIRT:0)
Block(-5,11,5,DIRT:0)
Block(-5,11,6,DIRT:0)
Block(-5,11,7,DIRT:0)
Block(-5,11,8,DIRT:0)
Block(-5,12,-7,DIRT:0)
Block(-5,12,-6,DIRT:0)
Block(-5,12,-5,DIRT:0)
Block(-5,12,-4,DIRT:0)
Block(-5,12,-3,DIRT:0)
Block(-5,12,-2,DIRT:0)
Block(-5,12,-1,DIRT:0)
Block(-5,12,0,DIRT:0)
Block(-5,12,1,DIRT:0)
Block(-5,12,2,DIRT:0)
Block(-5,12,3,DIRT:0)
Block(-5,12,4,DIRT:0)
Block(-5,12,5,DIRT:0)
Block(-5,12,6,DIRT:0)
Block(-5,12,7,DIRT:0)
Block(-5,12,8,DIRT:0)
Block(-5,13,-7,DIRT:0)
Block(-5,13,-6,DIRT:0)
Block(-5,13,-5,DIRT:0)
Block(-5,13,-4,DIRT:0)
Block(-5,13,-3,DIRT:0)
Block(-5,13,-2,DIRT:0)
Block(-5,13,-1,DIRT:0)
Block(-5,13,0,DIRT:0)
Block(-5,13,1,DIRT:0)
Block(-5,13,2,DIRT:0)
Block(-5,13,3,DIRT:0)
Block(-5,13,4,DIRT:0)
Block(-5,13,5,DIRT:0)
Block(-5,13,6,DIRT:0)
Block(-5,13,7,DIRT:0)
Block(-5,13,8,DIRT:0)
Block(-5,14,-7,DIRT:0)
Block(-5,14,-6,DIRT:0)
Block(-5,14,-5,DIRT:0)
Block(-5,14,-4,DIRT:0)
Block(-5,14,-3,DIRT:0)
Block(-5,14,-2,DIRT:0)
Block(-5,14,-1,DIRT:0)
Block(-5,14,0,DIRT:0)
Block(-5,14,1,DIRT:0)
Block(-5,14,2,DIRT:0)
Block(-5,14,3,DIRT:0)
Block(-5,14,4,DIRT:0)
Block(-5,14,5,DIRT:0)
Block(-5,14,6,DIRT:0)
Block(-5,14,7,DIRT:0)
Block(-5,14,8,DIRT:0)
Block(-5,15,-7,STAINED_CLAY:7)
Block(-5,15,-6,SAND:0)
Block(-5,15,-5,SAND:0)
Block(-5,15,-4,SAND:0)
Block(-5,15,-3,SAND:0)
Block(-5,15,-2,SAND:0)
Block(-5,15,-1,SAND:0)
Block(-5,15,0,GRASS:0)
Block(-5,15,1,GRASS:0)
Block(-5,15,2,GRASS:0)
Block(-5,15,3,GRASS:0)
Block(-5,15,4,GRASS:0)
Block(-5,15,5,GRASS:0)
Block(-5,15,6,GRASS:0)
Block(-5,15,7,GRASS:0)
Block(-5,15,8,GRASS:0)
Block(-5,18,-7,CONCRETE:8)
Block(-5,18,-6,CONCRETE:7)
Block(-5,18,-5,CONCRETE_POWDER:8)
Block(-5,51,-7,CONCRETE:7)
Block(-5,52,-7,CONCRETE:7)
Block(-5,52,-3,CONCRETE:8)
Block(-5,52,-2,CONCRETE:8)
Block(-5,53,-7,CONCRETE:7)
Block(-5,53,-3,IRON_FENCE:0)
Block(-5,53,-2,CONCRETE:8)
Block(-5,54,-7,STAINED_GLASS:11)
Block(-5,54,-6,STAINED_GLASS:15)
Block(-5,54,-3,IRON_FENCE:0)
Block(-5,54,-2,CONCRETE:8)
Block(-5,55,-7,STAINED_GLASS:11)
Block(-5,55,-6,STAINED_GLASS:15)
Block(-5,55,-3,CONCRETE:8)
Block(-5,55,-2,CONCRETE:8)
Block(-5,56,-7,STAINED_GLASS:11)
Block(-5,56,-6,STAINED_GLASS:15)
Block(-5,56,-5,STAINED_GLASS:15)
Block(-5,56,-3,CONCRETE:8)
Block(-5,56,-2,CONCRETE:8)
Block(-5,57,-5,STAINED_GLASS:11)
Block(-5,57,-4,STAINED_GLASS:15)
Block(-5,57,-3,CONCRETE:8)
Block(-5,57,-2,CONCRETE:8)
Block(-5,58,-5,STAINED_GLASS:11)
Block(-5,58,-4,STAINED_GLASS:15)
Block(-5,58,-3,CONCRETE_POWDER:8)
Block(-5,59,-5,STAINED_GLASS:11)
Block(-5,59,-4,STAINED_GLASS:15)
Block(-5,59,-3,CONCRETE:8)
Block(-5,60,-5,DOUBLE_STEP:7)
Block(-5,60,-4,DOUBLE_STEP:7)
Block(-5,60,-3,STAINED_GLASS:11)
Block(-5,60,-2,STAINED_GLASS:15)
Block(-5,61,-4,DOUBLE_STEP:7)
Block(-5,61,-3,STAINED_GLASS:11)
Block(-5,61,-2,STAINED_GLASS:15)
Block(-5,62,-3,STAINED_GLASS:11)
Block(-5,62,-2,STAINED_GLASS:15)
Block(-5,62,-1,STAINED_GLASS:15)
Block(-5,63,-3,DOUBLE_STEP:7)
Block(-5,63,-2,STEP:7)
Block(-5,63,-1,STAINED_GLASS:11)
Block(-5,63,0,STAINED_GLASS:15)
Block(-5,63,1,CONCRETE_POWDER:8)
Block(-5,64,-3,STEP:7)
Block(-5,64,-1,STAINED_GLASS:11)
Block(-5,64,0,STAINED_GLASS:15)
Block(-5,64,1,CONCRETE:8)
Block(-5,65,-1,STAINED_GLASS:11)
Block(-5,65,0,STAINED_GLASS:15)
Block(-5,65,1,CONCRETE_POWDER:8)
Block(-5,66,1,CONCRETE:8)
Block(-5,67,1,CONCRETE:8)
Block(-4,0,-7,DIRT:0)
Block(-4,0,-6,DIRT:0)
Block(-4,0,-5,DIRT:0)
Block(-4,0,-4,DIRT:0)
Block(-4,0,-3,DIRT:0)
Block(-4,0,-2,STAINED_GLASS_PANE:0)
Block(-4,0,-1,STAINED_GLASS_PANE:0)
Block(-4,0,0,STAINED_GLASS_PANE:0)
Block(-4,0,1,STAINED_GLASS_PANE:0)
Block(-4,0,2,STAINED_GLASS_PANE:0)
Block(-4,0,3,CONCRETE:8)
Block(-4,0,4,CONCRETE:7)
Block(-4,0,5,STAINED_GLASS_PANE:0)
Block(-4,0,6,STAINED_GLASS_PANE:0)
Block(-4,0,7,CONCRETE:8)
Block(-4,0,8,STAINED_GLASS_PANE:0)
Block(-4,1,-7,DIRT:0)
Block(-4,1,-6,DIRT:0)
Block(-4,1,-5,DIRT:0)
Block(-4,1,-4,DIRT:0)
Block(-4,1,-3,DIRT:0)
Block(-4,1,-2,STAINED_GLASS_PANE:0)
Block(-4,1,-1,STAINED_GLASS_PANE:0)
Block(-4,1,0,STAINED_GLASS_PANE:0)
Block(-4,1,1,STAINED_GLASS_PANE:0)
Block(-4,1,2,STAINED_GLASS_PANE:0)
Block(-4,1,3,CONCRETE:8)
Block(-4,1,4,CONCRETE:7)
Block(-4,1,5,STAINED_GLASS_PANE:0)
Block(-4,1,6,STAINED_GLASS_PANE:0)
Block(-4,1,7,CONCRETE:8)
Block(-4,1,8,STAINED_GLASS_PANE:0)
Block(-4,2,-7,DIRT:0)
Block(-4,2,-6,DIRT:0)
Block(-4,2,-5,DIRT:0)
Block(-4,2,-4,DIRT:0)
Block(-4,2,-3,DIRT:0)
Block(-4,2,-2,STAINED_GLASS_PANE:0)
Block(-4,2,-1,STAINED_GLASS_PANE:0)
Block(-4,2,0,STAINED_GLASS_PANE:0)
Block(-4,2,1,STAINED_GLASS_PANE:0)
Block(-4,2,2,CONCRETE:8)
Block(-4,2,3,CONCRETE:7)
Block(-4,2,4,CONCRETE:7)
Block(-4,2,5,STAINED_GLASS_PANE:0)
Block(-4,2,6,STAINED_GLASS_PANE:0)
Block(-4,2,7,CONCRETE:8)
Block(-4,2,8,STAINED_GLASS_PANE:0)
Block(-4,3,-7,DIRT:0)
Block(-4,3,-6,DIRT:0)
Block(-4,3,-5,DIRT:0)
Block(-4,3,-4,DIRT:0)
Block(-4,3,-3,DIRT:0)
Block(-4,3,-2,STAINED_GLASS_PANE:0)
Block(-4,3,-1,STAINED_GLASS_PANE:0)
Block(-4,3,0,STAINED_GLASS_PANE:0)
Block(-4,3,1,STAINED_GLASS_PANE:0)
Block(-4,3,2,CONCRETE:8)
Block(-4,3,3,CONCRETE:7)
Block(-4,3,4,STAINED_GLASS_PANE:0)
Block(-4,3,5,STAINED_GLASS_PANE:0)
Block(-4,3,6,STAINED_GLASS_PANE:0)
Block(-4,3,7,CONCRETE_POWDER:8)
Block(-4,3,8,STAINED_GLASS_PANE:0)
Block(-4,4,-7,DIRT:0)
Block(-4,4,-6,DIRT:0)
Block(-4,4,-5,DIRT:0)
Block(-4,4,-4,DIRT:0)
Block(-4,4,-3,DIRT:0)
Block(-4,4,-2,STAINED_GLASS_PANE:0)
Block(-4,4,-1,STAINED_GLASS_PANE:0)
Block(-4,4,0,STAINED_GLASS_PANE:0)
Block(-4,4,1,CONCRETE:8)
Block(-4,4,2,CONCRETE:7)
Block(-4,4,3,CONCRETE:7)
Block(-4,4,4,STAINED_GLASS_PANE:0)
Block(-4,4,5,STAINED_GLASS_PANE:0)
Block(-4,4,6,STAINED_GLASS_PANE:0)
Block(-4,4,7,CONCRETE:8)
Block(-4,4,8,STAINED_GLASS_PANE:0)
Block(-4,5,-7,DIRT:0)
Block(-4,5,-6,DIRT:0)
Block(-4,5,-5,DIRT:0)
Block(-4,5,-4,DIRT:0)
Block(-4,5,-3,DIRT:0)
Block(-4,5,-2,STAINED_GLASS_PANE:0)
Block(-4,5,-1,STAINED_GLASS_PANE:0)
Block(-4,5,0,STAINED_GLASS_PANE:0)
Block(-4,5,1,CONCRETE_POWDER:8)
Block(-4,5,2,CONCRETE:7)
Block(-4,5,3,STAINED_GLASS_PANE:0)
Block(-4,5,4,STAINED_GLASS_PANE:0)
Block(-4,5,5,STAINED_GLASS_PANE:0)
Block(-4,5,6,STAINED_GLASS_PANE:0)
Block(-4,5,7,CONCRETE:7)
Block(-4,5,8,STAINED_GLASS_PANE:0)
Block(-4,6,-7,DIRT:0)
Block(-4,6,-6,DIRT:0)
Block(-4,6,-5,DIRT:0)
Block(-4,6,-4,DIRT:0)
Block(-4,6,-3,DIRT:0)
Block(-4,6,-2,STAINED_GLASS_PANE:0)
Block(-4,6,-1,STAINED_GLASS_PANE:0)
Block(-4,6,0,CONCRETE_POWDER:8)
Block(-4,6,1,CONCRETE:7)
Block(-4,6,2,CONCRETE:7)
Block(-4,6,3,STAINED_GLASS_PANE:0)
Block(-4,6,4,STAINED_GLASS_PANE:0)
Block(-4,6,5,STAINED_GLASS_PANE:0)
Block(-4,6,6,STAINED_GLASS_PANE:0)
Block(-4,6,7,CONCRETE:7)
Block(-4,6,8,STAINED_GLASS_PANE:0)
Block(-4,7,-7,DIRT:0)
Block(-4,7,-6,DIRT:0)
Block(-4,7,-5,DIRT:0)
Block(-4,7,-4,DIRT:0)
Block(-4,7,-3,DIRT:0)
Block(-4,7,-2,STAINED_GLASS_PANE:0)
Block(-4,7,-1,STAINED_GLASS_PANE:0)
Block(-4,7,0,CONCRETE:8)
Block(-4,7,1,CONCRETE:7)
Block(-4,7,2,STAINED_GLASS_PANE:0)
Block(-4,7,3,STAINED_GLASS_PANE:0)
Block(-4,7,4,STAINED_GLASS_PANE:0)
Block(-4,7,5,STAINED_GLASS_PANE:0)
Block(-4,7,6,CONCRETE_POWDER:8)
Block(-4,7,7,CONCRETE:7)
Block(-4,7,8,CONCRETE:8)
Block(-4,8,-7,DIRT:0)
Block(-4,8,-6,DIRT:0)
Block(-4,8,-5,DIRT:0)
Block(-4,8,-4,DIRT:0)
Block(-4,8,-3,DIRT:0)
Block(-4,8,-2,STAINED_GLASS_PANE:0)
Block(-4,8,-1,CONCRETE:8)
Block(-4,8,0,CONCRETE:7)
Block(-4,8,1,CONCRETE:7)
Block(-4,8,2,STAINED_GLASS_PANE:0)
Block(-4,8,3,STAINED_GLASS_PANE:0)
Block(-4,8,4,STAINED_GLASS_PANE:0)
Block(-4,8,5,STAINED_GLASS_PANE:0)
Block(-4,8,6,CONCRETE:8)
Block(-4,8,7,CONCRETE:7)
Block(-4,8,8,CONCRETE:8)
Block(-4,9,-7,DIRT:0)
Block(-4,9,-6,DIRT:0)
Block(-4,9,-5,DIRT:0)
Block(-4,9,-4,DIRT:0)
Block(-4,9,-3,DIRT:0)
Block(-4,9,-2,STAINED_GLASS_PANE:0)
Block(-4,9,-1,CONCRETE:8)
Block(-4,9,0,CONCRETE:7)
Block(-4,9,1,STAINED_GLASS_PANE:0)
Block(-4,9,2,STAINED_GLASS_PANE:0)
Block(-4,9,3,STAINED_GLASS_PANE:0)
Block(-4,9,4,STAINED_GLASS_PANE:0)
Block(-4,9,5,CONCRETE:7)
Block(-4,9,6,CONCRETE:7)
Block(-4,9,7,CONCRETE:7)
Block(-4,9,8,CONCRETE:7)
Block(-4,10,-7,DIRT:0)
Block(-4,10,-6,DIRT:0)
Block(-4,10,-5,DIRT:0)
Block(-4,10,-4,DIRT:0)
Block(-4,10,-3,DIRT:0)
Block(-4,10,-2,CONCRETE_POWDER:8)
Block(-4,10,-1,CONCRETE:7)
Block(-4,10,0,CONCRETE:7)
Block(-4,10,1,STAINED_GLASS_PANE:0)
Block(-4,10,2,STAINED_GLASS_PANE:0)
Block(-4,10,3,STAINED_GLASS_PANE:0)
Block(-4,10,4,STAINED_GLASS_PANE:0)
Block(-4,10,5,CONCRETE:8)
Block(-4,10,6,CONCRETE:8)
Block(-4,10,7,STAINED_GLASS_PANE:0)
Block(-4,10,8,CONCRETE:7)
Block(-4,11,-7,DIRT:0)
Block(-4,11,-6,DIRT:0)
Block(-4,11,-5,DIRT:0)
Block(-4,11,-4,DIRT:0)
Block(-4,11,-3,DIRT:0)
Block(-4,11,-2,CONCRETE:8)
Block(-4,11,-1,CONCRETE:7)
Block(-4,11,0,STAINED_GLASS_PANE:0)
Block(-4,11,1,STAINED_GLASS_PANE:0)
Block(-4,11,2,STAINED_GLASS_PANE:0)
Block(-4,11,3,STAINED_GLASS_PANE:0)
Block(-4,11,4,CONCRETE:8)
Block(-4,11,5,CONCRETE:8)
Block(-4,11,6,CONCRETE:8)
Block(-4,11,7,STAINED_GLASS_PANE:0)
Block(-4,11,8,CONCRETE:8)
Block(-4,12,-7,DIRT:0)
Block(-4,12,-6,DIRT:0)
Block(-4,12,-5,DIRT:0)
Block(-4,12,-4,DIRT:0)
Block(-4,12,-3,DIRT:0)
Block(-4,12,-2,CONCRETE:8)
Block(-4,12,-1,CONCRETE:7)
Block(-4,12,0,STAINED_GLASS_PANE:15)
Block(-4,12,1,STAINED_GLASS_PANE:15)
Block(-4,12,2,STAINED_GLASS_PANE:15)
Block(-4,12,3,STAINED_GLASS_PANE:15)
Block(-4,12,4,CONCRETE_POWDER:8)
Block(-4,12,5,CONCRETE:8)
Block(-4,12,6,STAINED_GLASS_PANE:0)
Block(-4,12,7,STAINED_GLASS_PANE:0)
Block(-4,12,8,STAINED_GLASS_PANE:0)
Block(-4,13,-7,DIRT:0)
Block(-4,13,-6,DIRT:0)
Block(-4,13,-5,DIRT:0)
Block(-4,13,-4,DIRT:0)
Block(-4,13,-3,DIRT:0)
Block(-4,13,-2,CONCRETE:8)
Block(-4,13,-1,CONCRETE:7)
Block(-4,13,0,STAINED_GLASS_PANE:15)
Block(-4,13,1,STAINED_GLASS_PANE:15)
Block(-4,13,2,STAINED_GLASS_PANE:15)
Block(-4,13,3,STAINED_GLASS_PANE:15)
Block(-4,13,4,CONCRETE_POWDER:8)
Block(-4,13,5,CONCRETE:8)
Block(-4,13,6,STAINED_GLASS_PANE:15)
Block(-4,13,7,STAINED_GLASS_PANE:15)
Block(-4,13,8,STAINED_GLASS_PANE:15)
Block(-4,14,-7,DIRT:0)
Block(-4,14,-6,DIRT:0)
Block(-4,14,-5,DIRT:0)
Block(-4,14,-4,DIRT:0)
Block(-4,14,-3,DIRT:0)
Block(-4,14,-2,CONCRETE:7)
Block(-4,14,-1,CONCRETE:7)
Block(-4,14,0,STAINED_GLASS_PANE:15)
Block(-4,14,1,STAINED_GLASS_PANE:15)
Block(-4,14,2,STAINED_GLASS_PANE:15)
Block(-4,14,3,STAINED_GLASS_PANE:15)
Block(-4,14,4,CONCRETE:8)
Block(-4,14,5,CONCRETE_POWDER:8)
Block(-4,14,6,STAINED_GLASS_PANE:15)
Block(-4,14,7,STAINED_GLASS_PANE:15)
Block(-4,14,8,STAINED_GLASS_PANE:15)
Block(-4,15,-7,STAINED_CLAY:7)
Block(-4,15,-6,SAND:0)
Block(-4,15,-5,SAND:0)
Block(-4,15,-4,SAND:0)
Block(-4,15,-3,SAND:0)
Block(-4,15,-2,CONCRETE:8)
Block(-4,15,-1,CONCRETE:7)
Block(-4,15,0,STAINED_GLASS_PANE:15)
Block(-4,15,1,STAINED_GLASS_PANE:15)
Block(-4,15,2,STAINED_GLASS_PANE:15)
Block(-4,15,3,STAINED_GLASS_PANE:15)
Block(-4,15,4,CONCRETE:8)
Block(-4,15,5,CONCRETE:8)
Block(-4,15,6,STAINED_GLASS_PANE:15)
Block(-4,15,7,STAINED_GLASS_PANE:15)
Block(-4,15,8,STAINED_GLASS_PANE:15)
Block(-4,16,-2,CONCRETE_POWDER:8)
Block(-4,16,-1,CONCRETE:7)
Block(-4,16,0,STAINED_GLASS_PANE:15)
Block(-4,16,1,STAINED_GLASS_PANE:15)
Block(-4,16,2,STAINED_GLASS_PANE:15)
Block(-4,16,3,STAINED_GLASS_PANE:15)
Block(-4,16,4,CONCRETE:8)
Block(-4,16,5,CONCRETE:8)
Block(-4,16,6,STAINED_GLASS_PANE:15)
Block(-4,16,7,STAINED_GLASS_PANE:15)
Block(-4,16,8,STAINED_GLASS_PANE:15)
Block(-4,17,-2,CONCRETE:8)
Block(-4,17,-1,CONCRETE:7)
Block(-4,17,0,STAINED_GLASS_PANE:15)
Block(-4,17,1,STAINED_GLASS_PANE:15)
Block(-4,17,2,STAINED_GLASS_PANE:15)
Block(-4,17,3,STAINED_GLASS_PANE:15)
Block(-4,17,4,CONCRETE:8)
Block(-4,17,5,CONCRETE_POWDER:8)
Block(-4,17,6,STAINED_GLASS_PANE:15)
Block(-4,17,7,STAINED_GLASS_PANE:15)
Block(-4,17,8,STAINED_GLASS_PANE:15)
Block(-4,18,-7,CONCRETE:7)
Block(-4,18,-6,CONCRETE:7)
Block(-4,18,-5,CONCRETE:8)
Block(-4,18,-2,CONCRETE:7)
Block(-4,18,-1,CONCRETE:7)
Block(-4,18,0,STAINED_GLASS_PANE:15)
Block(-4,18,1,STAINED_GLASS_PANE:15)
Block(-4,18,2,STAINED_GLASS_PANE:15)
Block(-4,18,3,STAINED_GLASS_PANE:15)
Block(-4,18,4,CONCRETE:8)
Block(-4,18,5,CONCRETE:8)
Block(-4,18,6,STAINED_GLASS_PANE:15)
Block(-4,18,7,STAINED_GLASS_PANE:15)
Block(-4,18,8,STAINED_GLASS_PANE:15)
Block(-4,19,-2,CONCRETE:8)
Block(-4,19,-1,CONCRETE:8)
Block(-4,19,0,STAINED_GLASS_PANE:15)
Block(-4,19,1,STAINED_GLASS_PANE:15)
Block(-4,19,2,STAINED_GLASS_PANE:15)
Block(-4,19,3,STAINED_GLASS_PANE:15)
Block(-4,19,4,CONCRETE:8)
Block(-4,19,5,CONCRETE:8)
Block(-4,19,6,STAINED_GLASS_PANE:15)
Block(-4,19,7,STAINED_GLASS_PANE:15)
Block(-4,19,8,STAINED_GLASS_PANE:15)
Block(-4,20,-2,CONCRETE:8)
Block(-4,20,-1,CONCRETE:8)
Block(-4,20,0,STAINED_GLASS_PANE:15)
Block(-4,20,1,STAINED_GLASS_PANE:15)
Block(-4,20,2,STAINED_GLASS_PANE:15)
Block(-4,20,3,STAINED_GLASS_PANE:15)
Block(-4,20,4,CONCRETE_POWDER:8)
Block(-4,20,5,CONCRETE:8)
Block(-4,20,6,CONCRETE:8)
Block(-4,20,7,STAINED_GLASS_PANE:15)
Block(-4,20,8,CONCRETE:8)
Block(-4,21,-2,CONCRETE:7)
Block(-4,21,-1,CONCRETE:7)
Block(-4,21,0,CONCRETE_POWDER:8)
Block(-4,21,1,STAINED_GLASS_PANE:15)
Block(-4,21,2,STAINED_GLASS_PANE:15)
Block(-4,21,3,STAINED_GLASS_PANE:15)
Block(-4,21,4,STAINED_GLASS_PANE:15)
Block(-4,21,5,CONCRETE_POWDER:8)
Block(-4,21,6,CONCRETE:8)
Block(-4,21,7,STAINED_GLASS_PANE:15)
Block(-4,21,8,CONCRETE_POWDER:8)
Block(-4,22,-2,STAINED_GLASS_PANE:15)
Block(-4,22,-1,CONCRETE:7)
Block(-4,22,0,CONCRETE:8)
Block(-4,22,1,STAINED_GLASS_PANE:15)
Block(-4,22,2,STAINED_GLASS_PANE:15)
Block(-4,22,3,STAINED_GLASS_PANE:15)
Block(-4,22,4,STAINED_GLASS_PANE:15)
Block(-4,22,5,CONCRETE:8)
Block(-4,22,6,CONCRETE:8)
Block(-4,22,7,CONCRETE:8)
Block(-4,22,8,CONCRETE:8)
Block(-4,23,-2,STAINED_GLASS_PANE:15)
Block(-4,23,-1,CONCRETE:7)
Block(-4,23,0,CONCRETE:7)
Block(-4,23,1,CONCRETE:7)
Block(-4,23,2,STAINED_GLASS_PANE:15)
Block(-4,23,3,STAINED_GLASS_PANE:15)
Block(-4,23,4,STAINED_GLASS_PANE:15)
Block(-4,23,5,STAINED_GLASS_PANE:15)
Block(-4,23,6,CONCRETE:8)
Block(-4,23,7,CONCRETE:8)
Block(-4,23,8,CONCRETE:8)
Block(-4,24,-2,STAINED_GLASS_PANE:15)
Block(-4,24,-1,STAINED_GLASS_PANE:15)
Block(-4,24,0,CONCRETE:8)
Block(-4,24,1,CONCRETE:7)
Block(-4,24,2,STAINED_GLASS_PANE:15)
Block(-4,24,3,STAINED_GLASS_PANE:15)
Block(-4,24,4,STAINED_GLASS_PANE:15)
Block(-4,24,5,STAINED_GLASS_PANE:15)
Block(-4,24,6,CONCRETE_POWDER:8)
Block(-4,24,7,CONCRETE:8)
Block(-4,24,8,CONCRETE:8)
Block(-4,25,-2,STAINED_GLASS_PANE:15)
Block(-4,25,-1,STAINED_GLASS_PANE:15)
Block(-4,25,0,CONCRETE:8)
Block(-4,25,1,CONCRETE:7)
Block(-4,25,2,CONCRETE:7)
Block(-4,25,3,STAINED_GLASS_PANE:15)
Block(-4,25,4,STAINED_GLASS_PANE:15)
Block(-4,25,5,STAINED_GLASS_PANE:15)
Block(-4,25,6,STAINED_GLASS_PANE:15)
Block(-4,25,7,CONCRETE:8)
Block(-4,25,8,STAINED_GLASS_PANE:15)
Block(-4,26,-2,STAINED_GLASS_PANE:15)
Block(-4,26,-1,STAINED_GLASS_PANE:15)
Block(-4,26,0,STAINED_GLASS_PANE:15)
Block(-4,26,1,CONCRETE_POWDER:8)
Block(-4,26,2,CONCRETE:7)
Block(-4,26,3,STAINED_GLASS_PANE:15)
Block(-4,26,4,STAINED_GLASS_PANE:15)
Block(-4,26,5,STAINED_GLASS_PANE:15)
Block(-4,26,6,STAINED_GLASS_PANE:15)
Block(-4,26,7,CONCRETE:8)
Block(-4,26,8,STAINED_GLASS_PANE:15)
Block(-4,27,-2,STAINED_GLASS_PANE:15)
Block(-4,27,-1,STAINED_GLASS_PANE:15)
Block(-4,27,0,STAINED_GLASS_PANE:15)
Block(-4,27,1,CONCRETE_POWDER:8)
Block(-4,27,2,CONCRETE:7)
Block(-4,27,3,CONCRETE:7)
Block(-4,27,4,STAINED_GLASS_PANE:15)
Block(-4,27,5,STAINED_GLASS_PANE:15)
Block(-4,27,6,STAINED_GLASS_PANE:15)
Block(-4,27,7,CONCRETE_POWDER:8)
Block(-4,27,8,STAINED_GLASS_PANE:15)
Block(-4,28,-2,STAINED_GLASS_PANE:15)
Block(-4,28,-1,STAINED_GLASS_PANE:15)
Block(-4,28,0,STAINED_GLASS_PANE:15)
Block(-4,28,1,STAINED_GLASS_PANE:15)
Block(-4,28,2,CONCRETE:8)
Block(-4,28,3,CONCRETE:7)
Block(-4,28,4,STAINED_GLASS_PANE:15)
Block(-4,28,5,STAINED_GLASS_PANE:15)
Block(-4,28,6,STAINED_GLASS_PANE:15)
Block(-4,28,7,CONCRETE:8)
Block(-4,28,8,STAINED_GLASS_PANE:15)
Block(-4,29,-2,STAINED_GLASS_PANE:15)
Block(-4,29,-1,STAINED_GLASS_PANE:15)
Block(-4,29,0,STAINED_GLASS_PANE:15)
Block(-4,29,1,STAINED_GLASS_PANE:15)
Block(-4,29,2,CONCRETE_POWDER:8)
Block(-4,29,3,CONCRETE:7)
Block(-4,29,4,CONCRETE:7)
Block(-4,29,5,STAINED_GLASS_PANE:15)
Block(-4,29,6,STAINED_GLASS_PANE:15)
Block(-4,29,7,CONCRETE:8)
Block(-4,29,8,STAINED_GLASS_PANE:15)
Block(-4,30,-2,STAINED_GLASS_PANE:15)
Block(-4,30,-1,STAINED_GLASS_PANE:15)
Block(-4,30,0,STAINED_GLASS_PANE:15)
Block(-4,30,1,STAINED_GLASS_PANE:15)
Block(-4,30,2,STAINED_GLASS_PANE:15)
Block(-4,30,3,CONCRETE:8)
Block(-4,30,4,CONCRETE:7)
Block(-4,30,5,STAINED_GLASS_PANE:15)
Block(-4,30,6,STAINED_GLASS_PANE:15)
Block(-4,30,7,CONCRETE:8)
Block(-4,30,8,STAINED_GLASS_PANE:15)
Block(-4,31,-2,STAINED_GLASS_PANE:15)
Block(-4,31,-1,STAINED_GLASS_PANE:15)
Block(-4,31,0,STAINED_GLASS_PANE:15)
Block(-4,31,1,STAINED_GLASS_PANE:15)
Block(-4,31,2,STAINED_GLASS_PANE:15)
Block(-4,31,3,CONCRETE:8)
Block(-4,31,4,CONCRETE:7)
Block(-4,31,5,STAINED_GLASS_PANE:15)
Block(-4,31,6,STAINED_GLASS_PANE:15)
Block(-4,31,7,CONCRETE:8)
Block(-4,31,8,STAINED_GLASS_PANE:15)
Block(-4,32,-2,STAINED_GLASS_PANE:15)
Block(-4,32,-1,STAINED_GLASS_PANE:15)
Block(-4,32,0,STAINED_GLASS_PANE:15)
Block(-4,32,1,STAINED_GLASS_PANE:15)
Block(-4,32,2,STAINED_GLASS_PANE:15)
Block(-4,32,3,STAINED_GLASS_PANE:15)
Block(-4,32,4,CONCRETE:7)
Block(-4,32,5,STAINED_GLASS_PANE:15)
Block(-4,32,6,STAINED_GLASS_PANE:15)
Block(-4,32,7,CONCRETE:8)
Block(-4,32,8,STAINED_GLASS_PANE:15)
Block(-4,33,-2,STAINED_GLASS_PANE:15)
Block(-4,33,-1,STAINED_GLASS_PANE:15)
Block(-4,33,0,STAINED_GLASS_PANE:15)
Block(-4,33,1,STAINED_GLASS_PANE:15)
Block(-4,33,2,STAINED_GLASS_PANE:15)
Block(-4,33,3,STAINED_GLASS_PANE:15)
Block(-4,33,4,CONCRETE:7)
Block(-4,33,5,STAINED_GLASS_PANE:15)
Block(-4,33,6,STAINED_GLASS_PANE:15)
Block(-4,33,7,CONCRETE:8)
Block(-4,33,8,STAINED_GLASS_PANE:15)
Block(-4,34,-2,STAINED_GLASS_PANE:15)
Block(-4,34,-1,STAINED_GLASS_PANE:15)
Block(-4,34,0,STAINED_GLASS_PANE:15)
Block(-4,34,1,STAINED_GLASS_PANE:15)
Block(-4,34,2,STAINED_GLASS_PANE:15)
Block(-4,34,3,STAINED_GLASS_PANE:15)
Block(-4,34,4,CONCRETE:7)
Block(-4,34,5,STAINED_GLASS_PANE:15)
Block(-4,34,6,STAINED_GLASS_PANE:15)
Block(-4,34,7,CONCRETE_POWDER:8)
Block(-4,34,8,STAINED_GLASS_PANE:15)
Block(-4,35,-2,STAINED_GLASS_PANE:15)
Block(-4,35,-1,STAINED_GLASS_PANE:15)
Block(-4,35,0,STAINED_GLASS_PANE:15)
Block(-4,35,1,STAINED_GLASS_PANE:15)
Block(-4,35,2,STAINED_GLASS_PANE:15)
Block(-4,35,3,CONCRETE:8)
Block(-4,35,4,CONCRETE:7)
Block(-4,35,5,STAINED_GLASS_PANE:15)
Block(-4,35,6,STAINED_GLASS_PANE:15)
Block(-4,35,7,CONCRETE:8)
Block(-4,35,8,STAINED_GLASS_PANE:15)
Block(-4,36,-2,STAINED_GLASS_PANE:15)
Block(-4,36,-1,STAINED_GLASS_PANE:15)
Block(-4,36,0,STAINED_GLASS_PANE:15)
Block(-4,36,1,STAINED_GLASS_PANE:15)
Block(-4,36,2,STAINED_GLASS_PANE:15)
Block(-4,36,3,CONCRETE_POWDER:8)
Block(-4,36,4,CONCRETE:7)
Block(-4,36,5,STAINED_GLASS_PANE:15)
Block(-4,36,6,STAINED_GLASS_PANE:15)
Block(-4,36,7,CONCRETE:8)
Block(-4,36,8,STAINED_GLASS_PANE:15)
Block(-4,37,-2,STAINED_GLASS_PANE:15)
Block(-4,37,-1,STAINED_GLASS_PANE:15)
Block(-4,37,0,STAINED_GLASS_PANE:15)
Block(-4,37,1,STAINED_GLASS_PANE:15)
Block(-4,37,2,CONCRETE:8)
Block(-4,37,3,CONCRETE:7)
Block(-4,37,4,CONCRETE:7)
Block(-4,37,5,STAINED_GLASS_PANE:15)
Block(-4,37,6,STAINED_GLASS_PANE:15)
Block(-4,37,7,CONCRETE:8)
Block(-4,37,8,STAINED_GLASS_PANE:15)
Block(-4,38,-2,STAINED_GLASS_PANE:15)
Block(-4,38,-1,STAINED_GLASS_PANE:15)
Block(-4,38,0,STAINED_GLASS_PANE:15)
Block(-4,38,1,STAINED_GLASS_PANE:15)
Block(-4,38,2,CONCRETE:8)
Block(-4,38,3,CONCRETE:7)
Block(-4,38,4,STAINED_GLASS_PANE:15)
Block(-4,38,5,STAINED_GLASS_PANE:15)
Block(-4,38,6,STAINED_GLASS_PANE:15)
Block(-4,38,7,CONCRETE:8)
Block(-4,38,8,STAINED_GLASS_PANE:15)
Block(-4,39,-2,STAINED_GLASS_PANE:15)
Block(-4,39,-1,STAINED_GLASS_PANE:15)
Block(-4,39,0,STAINED_GLASS_PANE:15)
Block(-4,39,1,CONCRETE:8)
Block(-4,39,2,CONCRETE:7)
Block(-4,39,3,CONCRETE:7)
Block(-4,39,4,STAINED_GLASS_PANE:15)
Block(-4,39,5,STAINED_GLASS_PANE:15)
Block(-4,39,6,STAINED_GLASS_PANE:15)
Block(-4,39,7,CONCRETE:8)
Block(-4,39,8,STAINED_GLASS_PANE:15)
Block(-4,40,-2,STAINED_GLASS_PANE:15)
Block(-4,40,-1,STAINED_GLASS_PANE:15)
Block(-4,40,0,STAINED_GLASS_PANE:15)
Block(-4,40,1,CONCRETE:8)
Block(-4,40,2,CONCRETE:7)
Block(-4,40,3,STAINED_GLASS_PANE:15)
Block(-4,40,4,STAINED_GLASS_PANE:15)
Block(-4,40,5,STAINED_GLASS_PANE:15)
Block(-4,40,6,STAINED_GLASS_PANE:15)
Block(-4,40,7,CONCRETE:7)
Block(-4,40,8,STAINED_GLASS_PANE:15)
Block(-4,41,-2,STAINED_GLASS_PANE:15)
Block(-4,41,-1,STAINED_GLASS_PANE:15)
Block(-4,41,0,CONCRETE:8)
Block(-4,41,1,CONCRETE:7)
Block(-4,41,2,CONCRETE:7)
Block(-4,41,3,STAINED_GLASS_PANE:15)
Block(-4,41,4,STAINED_GLASS_PANE:15)
Block(-4,41,5,STAINED_GLASS_PANE:15)
Block(-4,41,6,STAINED_GLASS_PANE:15)
Block(-4,41,7,CONCRETE:7)
Block(-4,41,8,STAINED_GLASS_PANE:15)
Block(-4,42,-2,STAINED_GLASS_PANE:15)
Block(-4,42,-1,STAINED_GLASS_PANE:15)
Block(-4,42,0,CONCRETE_POWDER:8)
Block(-4,42,1,CONCRETE:7)
Block(-4,42,2,STAINED_GLASS_PANE:15)
Block(-4,42,3,STAINED_GLASS_PANE:15)
Block(-4,42,4,STAINED_GLASS_PANE:15)
Block(-4,42,5,STAINED_GLASS_PANE:15)
Block(-4,42,6,CONCRETE_POWDER:8)
Block(-4,42,7,CONCRETE:7)
Block(-4,42,8,CONCRETE_POWDER:8)
Block(-4,43,-2,STAINED_GLASS_PANE:15)
Block(-4,43,-1,CONCRETE_POWDER:8)
Block(-4,43,0,CONCRETE:7)
Block(-4,43,1,CONCRETE:7)
Block(-4,43,2,STAINED_GLASS_PANE:15)
Block(-4,43,3,STAINED_GLASS_PANE:15)
Block(-4,43,4,STAINED_GLASS_PANE:15)
Block(-4,43,5,STAINED_GLASS_PANE:15)
Block(-4,43,6,CONCRETE:8)
Block(-4,43,7,CONCRETE:7)
Block(-4,43,8,CONCRETE:8)
Block(-4,44,-2,STAINED_GLASS_PANE:15)
Block(-4,44,-1,CONCRETE_POWDER:8)
Block(-4,44,0,CONCRETE:7)
Block(-4,44,4,STAINED_GLASS_PANE:15)
Block(-4,44,5,CONCRETE:7)
Block(-4,44,6,CONCRETE:7)
Block(-4,44,7,CONCRETE:7)
Block(-4,44,8,CONCRETE:7)
Block(-4,45,-2,CONCRETE:8)
Block(-4,45,-1,CONCRETE:7)
Block(-4,45,0,CONCRETE:7)
Block(-4,45,5,CONCRETE:8)
Block(-4,45,6,CONCRETE:8)
Block(-4,45,8,CONCRETE:7)
Block(-4,46,-2,CONCRETE:8)
Block(-4,46,-1,CONCRETE:7)
Block(-4,46,4,CONCRETE:8)
Block(-4,46,5,CONCRETE:8)
Block(-4,46,6,CONCRETE:8)
Block(-4,46,8,CONCRETE:8)
Block(-4,47,-2,CONCRETE:8)
Block(-4,47,-1,CONCRETE:7)
Block(-4,47,4,CONCRETE:8)
Block(-4,47,5,CONCRETE:8)
Block(-4,48,-2,CONCRETE:8)
Block(-4,48,-1,CONCRETE:7)
Block(-4,48,4,CONCRETE:8)
Block(-4,48,5,CONCRETE_POWDER:8)
Block(-4,49,-2,CONCRETE:7)
Block(-4,49,-1,CONCRETE:7)
Block(-4,49,4,CONCRETE:8)
Block(-4,49,5,CONCRETE:8)
Block(-4,50,-2,CONCRETE:8)
Block(-4,50,-1,CONCRETE:7)
Block(-4,50,4,CONCRETE_POWDER:8)
Block(-4,50,5,CONCRETE:8)
Block(-4,51,-3,IRON_FENCE:0)
Block(-4,51,-2,CONCRETE:8)
Block(-4,51,-1,CONCRETE:7)
Block(-4,51,4,CONCRETE:8)
Block(-4,51,5,CONCRETE:8)
Block(-4,52,-3,IRON_FENCE:0)
Block(-4,52,-2,CONCRETE:8)
Block(-4,52,-1,CONCRETE:7)
Block(-4,52,4,CONCRETE:8)
Block(-4,52,5,CONCRETE:8)
Block(-4,52,8,STAINED_GLASS_PANE:15)
Block(-4,53,-3,CONCRETE:8)
Block(-4,53,-2,CONCRETE:7)
Block(-4,53,-1,CONCRETE:7)
Block(-4,53,4,CONCRETE:8)
Block(-4,53,5,CONCRETE:8)
Block(-4,53,6,STAINED_GLASS_PANE:15)
Block(-4,53,7,STAINED_GLASS_PANE:15)
Block(-4,53,8,STAINED_GLASS_PANE:15)
Block(-4,54,-7,STAINED_GLASS:15)
Block(-4,54,-3,CONCRETE:8)
Block(-4,54,-2,CONCRETE:8)
Block(-4,54,-1,CONCRETE:8)
Block(-4,54,0,STAINED_GLASS_PANE:15)
Block(-4,54,4,CONCRETE:8)
Block(-4,54,5,CONCRETE:8)
Block(-4,54,6,STAINED_GLASS_PANE:15)
Block(-4,54,7,STAINED_GLASS_PANE:15)
Block(-4,54,8,STAINED_GLASS_PANE:15)
Block(-4,55,-7,STAINED_GLASS:15)
Block(-4,55,-3,CONCRETE:8)
Block(-4,55,-2,CONCRETE:8)
Block(-4,55,-1,CONCRETE:8)
Block(-4,55,0,STAINED_GLASS_PANE:15)
Block(-4,55,1,STAINED_GLASS_PANE:15)
Block(-4,55,2,STAINED_GLASS_PANE:15)
Block(-4,55,3,STAINED_GLASS_PANE:15)
Block(-4,55,4,CONCRETE:8)
Block(-4,55,5,CONCRETE:8)
Block(-4,55,6,CONCRETE_POWDER:8)
Block(-4,55,7,STAINED_GLASS_PANE:15)
Block(-4,55,8,CONCRETE_POWDER:8)
Block(-4,56,-7,STAINED_GLASS:15)
Block(-4,56,-6,STAINED_GLASS:15)
Block(-4,56,-3,CONCRETE:8)
Block(-4,56,-2,CONCRETE:7)
Block(-4,56,-1,CONCRETE:7)
Block(-4,56,0,CONCRETE:8)
Block(-4,56,1,STAINED_GLASS_PANE:15)
Block(-4,56,2,STAINED_GLASS_PANE:15)
Block(-4,56,3,STAINED_GLASS_PANE:15)
Block(-4,56,4,STAINED_GLASS_PANE:15)
Block(-4,56,5,CONCRETE:8)
Block(-4,56,6,CONCRETE_POWDER:8)
Block(-4,56,7,STAINED_GLASS_PANE:15)
Block(-4,56,8,CONCRETE:8)
Block(-4,57,-6,STAINED_GLASS:11)
Block(-4,57,-5,STAINED_GLASS:15)
Block(-4,57,-3,IRON_FENCE:0)
Block(-4,57,-2,CONCRETE:8)
Block(-4,57,-1,CONCRETE:7)
Block(-4,57,1,STAINED_GLASS_PANE:15)
Block(-4,57,2,STAINED_GLASS_PANE:15)
Block(-4,57,3,STAINED_GLASS_PANE:15)
Block(-4,57,4,STAINED_GLASS_PANE:15)
Block(-4,57,5,CONCRETE:8)
Block(-4,57,6,CONCRETE:8)
Block(-4,57,7,CONCRETE:8)
Block(-4,57,8,CONCRETE:8)
Block(-4,58,-6,STAINED_GLASS:11)
Block(-4,58,-5,STAINED_GLASS:15)
Block(-4,58,-3,IRON_FENCE:0)
Block(-4,58,-2,STAINED_GLASS_PANE:15)
Block(-4,58,-1,CONCRETE:7)
Block(-4,58,2,STAINED_GLASS_PANE:15)
Block(-4,58,3,STAINED_GLASS_PANE:15)
Block(-4,58,4,STAINED_GLASS_PANE:15)
Block(-4,58,5,STAINED_GLASS_PANE:15)
Block(-4,58,6,CONCRETE:8)
Block(-4,58,7,CONCRETE:8)
Block(-4,58,8,CONCRETE:8)
Block(-4,59,-6,STAINED_GLASS:11)
Block(-4,59,-5,STAINED_GLASS:15)
Block(-4,59,-4,STAINED_GLASS:15)
Block(-4,59,-3,IRON_FENCE:0)
Block(-4,59,-2,STAINED_GLASS_PANE:15)
Block(-4,59,-1,STAINED_GLASS_PANE:15)
Block(-4,59,2,STAINED_GLASS_PANE:15)
Block(-4,59,3,STAINED_GLASS_PANE:15)
Block(-4,59,4,STAINED_GLASS_PANE:15)
Block(-4,59,5,STAINED_GLASS_PANE:15)
Block(-4,59,6,CONCRETE:8)
Block(-4,59,7,CONCRETE:8)
Block(-4,59,8,CONCRETE_POWDER:8)
Block(-4,60,-7,DOUBLE_STEP:7)
Block(-4,60,-6,DOUBLE_STEP:7)
Block(-4,60,-5,DOUBLE_STEP:7)
Block(-4,60,-4,STAINED_GLASS:11)
Block(-4,60,-3,STAINED_GLASS:15)
Block(-4,60,-2,STAINED_GLASS_PANE:15)
Block(-4,60,-1,STAINED_GLASS_PANE:15)
Block(-4,60,2,CONCRETE:7)
Block(-4,60,3,STAINED_GLASS_PANE:15)
Block(-4,60,4,STAINED_GLASS_PANE:15)
Block(-4,60,5,STAINED_GLASS_PANE:15)
Block(-4,60,6,STAINED_GLASS_PANE:15)
Block(-4,60,7,CONCRETE:8)
Block(-4,60,8,STAINED_GLASS_PANE:15)
Block(-4,61,-6,STEP:7)
Block(-4,61,-5,DOUBLE_STEP:7)
Block(-4,61,-4,STAINED_GLASS:11)
Block(-4,61,-3,STAINED_GLASS:15)
Block(-4,61,-2,STAINED_GLASS_PANE:15)
Block(-4,61,-1,STAINED_GLASS_PANE:15)
Block(-4,61,0,STAINED_GLASS_PANE:15)
Block(-4,61,1,CONCRETE:8)
Block(-4,61,2,CONCRETE:7)
Block(-4,61,3,STAINED_GLASS_PANE:15)
Block(-4,61,4,STAINED_GLASS_PANE:15)
Block(-4,61,5,STAINED_GLASS_PANE:15)
Block(-4,61,6,STAINED_GLASS_PANE:15)
Block(-4,61,7,CONCRETE:8)
Block(-4,62,-4,STAINED_GLASS:11)
Block(-4,62,-3,STAINED_GLASS:15)
Block(-4,62,-2,STAINED_GLASS_PANE:15)
Block(-4,62,-1,STAINED_GLASS_PANE:15)
Block(-4,62,0,STAINED_GLASS_PANE:15)
Block(-4,62,1,CONCRETE:8)
Block(-4,62,2,CONCRETE:7)
Block(-4,62,3,CONCRETE:7)
Block(-4,62,4,STAINED_GLASS_PANE:15)
Block(-4,62,5,STAINED_GLASS_PANE:15)
Block(-4,62,6,STAINED_GLASS_PANE:15)
Block(-4,62,7,CONCRETE:8)
Block(-4,63,-4,DOUBLE_STEP:7)
Block(-4,63,-3,DOUBLE_STEP:7)
Block(-4,63,-2,STAINED_GLASS_PANE:15)
Block(-4,63,-1,STAINED_GLASS_PANE:15)
Block(-4,63,0,STAINED_GLASS_PANE:15)
Block(-4,63,1,STAINED_GLASS_PANE:15)
Block(-4,63,2,CONCRETE_POWDER:8)
Block(-4,63,3,CONCRETE:7)
Block(-4,63,4,STAINED_GLASS_PANE:15)
Block(-4,63,5,STAINED_GLASS_PANE:15)
Block(-4,63,6,STAINED_GLASS_PANE:15)
Block(-4,63,7,CONCRETE:8)
Block(-4,64,-4,STEP:7)
Block(-4,64,-3,STEP:7)
Block(-4,64,-2,STAINED_GLASS_PANE:15)
Block(-4,64,-1,STAINED_GLASS_PANE:15)
Block(-4,64,0,STAINED_GLASS_PANE:15)
Block(-4,64,1,STAINED_GLASS_PANE:15)
Block(-4,64,2,CONCRETE:8)
Block(-4,64,3,CONCRETE:7)
Block(-4,64,4,CONCRETE:7)
Block(-4,64,5,STAINED_GLASS_PANE:15)
Block(-4,64,6,STAINED_GLASS_PANE:15)
Block(-4,64,7,CONCRETE_POWDER:8)
Block(-4,65,-2,STAINED_GLASS_PANE:15)
Block(-4,65,-1,STAINED_GLASS_PANE:15)
Block(-4,65,0,STAINED_GLASS_PANE:15)
Block(-4,65,1,STAINED_GLASS_PANE:15)
Block(-4,65,2,STAINED_GLASS_PANE:15)
Block(-4,65,3,CONCRETE:8)
Block(-4,65,4,CONCRETE:7)
Block(-4,65,5,STAINED_GLASS_PANE:15)
Block(-4,65,6,STAINED_GLASS_PANE:15)
Block(-4,65,7,CONCRETE:8)
Block(-4,66,-2,STAINED_GLASS_PANE:15)
Block(-4,66,-1,STAINED_GLASS_PANE:15)
Block(-4,66,0,STAINED_GLASS_PANE:15)
Block(-4,66,1,STAINED_GLASS_PANE:15)
Block(-4,66,2,STAINED_GLASS_PANE:15)
Block(-4,66,3,CONCRETE_POWDER:8)
Block(-4,66,4,CONCRETE:7)
Block(-4,66,5,STAINED_GLASS_PANE:15)
Block(-4,66,6,STAINED_GLASS_PANE:15)
Block(-4,66,7,CONCRETE:8)
Block(-4,66,8,STAINED_GLASS_PANE:15)
Block(-4,67,-2,STAINED_GLASS_PANE:15)
Block(-4,67,-1,STAINED_GLASS_PANE:15)
Block(-4,67,0,STAINED_GLASS_PANE:15)
Block(-4,67,1,STAINED_GLASS_PANE:15)
Block(-4,67,2,STAINED_GLASS_PANE:15)
Block(-4,67,3,STAINED_GLASS_PANE:15)
Block(-4,67,4,CONCRETE:7)
Block(-4,67,5,STAINED_GLASS_PANE:15)
Block(-4,67,6,STAINED_GLASS_PANE:15)
Block(-4,67,7,CONCRETE:8)
Block(-4,67,8,STAINED_GLASS_PANE:15)
Block(-4,68,-2,STAINED_GLASS_PANE:15)
Block(-4,68,-1,STAINED_GLASS_PANE:15)
Block(-4,68,0,STAINED_GLASS_PANE:15)
Block(-4,68,1,STAINED_GLASS_PANE:15)
Block(-4,68,2,STAINED_GLASS_PANE:15)
Block(-4,68,3,STAINED_GLASS_PANE:15)
Block(-4,68,4,CONCRETE:7)
Block(-4,68,5,STAINED_GLASS_PANE:15)
Block(-4,68,6,STAINED_GLASS_PANE:15)
Block(-4,68,7,CONCRETE:8)
Block(-4,68,8,STAINED_GLASS_PANE:15)
Block(-4,69,-2,STAINED_GLASS_PANE:15)
Block(-4,69,-1,STAINED_GLASS_PANE:15)
Block(-4,69,0,STAINED_GLASS_PANE:15)
Block(-4,69,1,STAINED_GLASS_PANE:15)
Block(-4,69,2,STAINED_GLASS_PANE:15)
Block(-4,69,3,STAINED_GLASS_PANE:15)
Block(-4,69,4,CONCRETE:7)
Block(-4,69,5,STAINED_GLASS_PANE:15)
Block(-4,69,6,STAINED_GLASS_PANE:15)
Block(-4,69,7,CONCRETE:8)
Block(-4,69,8,STAINED_GLASS_PANE:15)
Block(-4,70,-2,STAINED_GLASS_PANE:15)
Block(-4,70,-1,STAINED_GLASS_PANE:15)
Block(-4,70,0,STAINED_GLASS_PANE:15)
Block(-4,70,1,STAINED_GLASS_PANE:15)
Block(-4,70,2,STAINED_GLASS_PANE:15)
Block(-4,70,3,CONCRETE:8)
Block(-4,70,4,CONCRETE:7)
Block(-4,70,5,STAINED_GLASS_PANE:15)
Block(-4,70,6,STAINED_GLASS_PANE:15)
Block(-4,70,7,CONCRETE:8)
Block(-4,70,8,STAINED_GLASS_PANE:15)
Block(-4,71,-2,STAINED_GLASS_PANE:15)
Block(-4,71,-1,STAINED_GLASS_PANE:15)
Block(-4,71,0,STAINED_GLASS_PANE:15)
Block(-4,71,1,STAINED_GLASS_PANE:15)
Block(-4,71,2,STAINED_GLASS_PANE:15)
Block(-4,71,3,CONCRETE:8)
Block(-4,71,4,CONCRETE:7)
Block(-4,71,5,STAINED_GLASS_PANE:15)
Block(-4,71,6,STAINED_GLASS_PANE:15)
Block(-4,71,7,CONCRETE:8)
Block(-4,71,8,STAINED_GLASS_PANE:15)
Block(-4,72,-2,STAINED_GLASS_PANE:15)
Block(-4,72,-1,STAINED_GLASS_PANE:15)
Block(-4,72,0,STAINED_GLASS_PANE:15)
Block(-4,72,1,STAINED_GLASS_PANE:15)
Block(-4,72,2,CONCRETE:8)
Block(-4,72,3,CONCRETE:7)
Block(-4,72,4,CONCRETE:7)
Block(-4,72,5,STAINED_GLASS_PANE:15)
Block(-4,72,6,STAINED_GLASS_PANE:15)
Block(-4,72,7,CONCRETE:8)
Block(-4,72,8,STAINED_GLASS_PANE:15)
Block(-4,73,-2,STAINED_GLASS_PANE:15)
Block(-4,73,-1,STAINED_GLASS_PANE:15)
Block(-4,73,0,STAINED_GLASS_PANE:15)
Block(-4,73,1,STAINED_GLASS_PANE:15)
Block(-4,73,2,CONCRETE_POWDER:8)
Block(-4,73,3,CONCRETE:7)
Block(-4,73,4,STAINED_GLASS_PANE:15)
Block(-4,73,5,STAINED_GLASS_PANE:15)
Block(-4,73,6,STAINED_GLASS_PANE:15)
Block(-4,73,7,CONCRETE:8)
Block(-4,73,8,STAINED_GLASS_PANE:15)
Block(-4,74,-2,STAINED_GLASS_PANE:15)
Block(-4,74,-1,STAINED_GLASS_PANE:15)
Block(-4,74,0,STAINED_GLASS_PANE:15)
Block(-4,74,1,CONCRETE:8)
Block(-4,74,2,CONCRETE:7)
Block(-4,74,3,CONCRETE:7)
Block(-4,74,4,STAINED_GLASS_PANE:15)
Block(-4,74,5,STAINED_GLASS_PANE:15)
Block(-4,74,6,STAINED_GLASS_PANE:15)
Block(-4,74,7,CONCRETE_POWDER:8)
Block(-4,74,8,STAINED_GLASS_PANE:15)
Block(-4,75,-2,STAINED_GLASS_PANE:15)
Block(-4,75,-1,STAINED_GLASS_PANE:15)
Block(-4,75,0,STAINED_GLASS_PANE:15)
Block(-4,75,1,CONCRETE_POWDER:8)
Block(-4,75,2,CONCRETE:7)
Block(-4,75,3,STAINED_GLASS_PANE:15)
Block(-4,75,4,STAINED_GLASS_PANE:15)
Block(-4,75,5,STAINED_GLASS_PANE:15)
Block(-4,75,6,STAINED_GLASS_PANE:15)
Block(-4,75,7,CONCRETE:7)
Block(-4,75,8,STAINED_GLASS_PANE:15)
Block(-4,76,-2,STAINED_GLASS_PANE:15)
Block(-4,76,-1,STAINED_GLASS_PANE:15)
Block(-4,76,0,CONCRETE:8)
Block(-4,76,1,CONCRETE:7)
Block(-4,76,2,CONCRETE:7)
Block(-4,76,3,STAINED_GLASS_PANE:15)
Block(-4,76,4,STAINED_GLASS_PANE:15)
Block(-4,76,5,STAINED_GLASS_PANE:15)
Block(-4,76,6,STAINED_GLASS_PANE:15)
Block(-4,76,7,CONCRETE:7)
Block(-4,76,8,STAINED_GLASS_PANE:15)
Block(-4,77,-2,STAINED_GLASS_PANE:15)
Block(-4,77,-1,STAINED_GLASS_PANE:15)
Block(-4,77,0,CONCRETE:8)
Block(-4,77,1,CONCRETE:7)
Block(-4,77,2,STAINED_GLASS_PANE:15)
Block(-4,77,3,STAINED_GLASS_PANE:15)
Block(-4,77,4,STAINED_GLASS_PANE:15)
Block(-4,77,5,STAINED_GLASS_PANE:15)
Block(-4,77,6,CONCRETE:8)
Block(-4,77,7,CONCRETE:7)
Block(-4,77,8,CONCRETE:8)
Block(-4,78,-2,STAINED_GLASS_PANE:15)
Block(-4,78,-1,CONCRETE_POWDER:8)
Block(-4,78,0,CONCRETE:7)
Block(-4,78,1,CONCRETE:7)
Block(-4,78,2,STAINED_GLASS_PANE:15)
Block(-4,78,3,STAINED_GLASS_PANE:15)
Block(-4,78,4,STAINED_GLASS_PANE:15)
Block(-4,78,5,STAINED_GLASS_PANE:15)
Block(-4,78,6,CONCRETE:8)
Block(-4,78,7,CONCRETE:7)
Block(-4,78,8,CONCRETE:8)
Block(-4,79,-2,STAINED_GLASS_PANE:15)
Block(-4,79,-1,CONCRETE:8)
Block(-4,79,0,CONCRETE:7)
Block(-4,79,1,STAINED_GLASS_PANE:15)
Block(-4,79,2,STAINED_GLASS_PANE:15)
Block(-4,79,3,STAINED_GLASS_PANE:15)
Block(-4,79,4,STAINED_GLASS_PANE:15)
Block(-4,79,5,CONCRETE:7)
Block(-4,79,6,CONCRETE:7)
Block(-4,79,7,CONCRETE:7)
Block(-4,79,8,CONCRETE:7)
Block(-4,80,-2,CONCRETE:8)
Block(-4,80,-1,CONCRETE:7)
Block(-4,80,0,CONCRETE:7)
Block(-4,80,1,STAINED_GLASS_PANE:15)
Block(-4,80,2,STAINED_GLASS_PANE:15)
Block(-4,80,3,STAINED_GLASS_PANE:15)
Block(-4,80,4,STAINED_GLASS_PANE:15)
Block(-4,80,5,CONCRETE_POWDER:8)
Block(-4,80,6,CONCRETE_POWDER:8)
Block(-4,80,7,STAINED_GLASS_PANE:15)
Block(-4,80,8,CONCRETE:7)
Block(-4,81,-2,CONCRETE:7)
Block(-4,81,-1,CONCRETE:7)
Block(-4,81,0,STAINED_GLASS_PANE:15)
Block(-4,81,1,STAINED_GLASS_PANE:15)
Block(-4,81,2,STAINED_GLASS_PANE:15)
Block(-4,81,3,STAINED_GLASS_PANE:15)
Block(-4,81,4,CONCRETE:8)
Block(-4,81,5,CONCRETE_POWDER:8)
Block(-4,81,6,CONCRETE:8)
Block(-4,81,7,STAINED_GLASS_PANE:15)
Block(-4,81,8,CONCRETE:8)
Block(-4,82,-2,CONCRETE_POWDER:8)
Block(-4,82,-1,CONCRETE:8)
Block(-4,82,0,STAINED_GLASS_PANE:15)
Block(-4,82,1,STAINED_GLASS_PANE:15)
Block(-4,82,2,STAINED_GLASS_PANE:15)
Block(-4,82,3,STAINED_GLASS_PANE:15)
Block(-4,82,4,CONCRETE:8)
Block(-4,82,5,CONCRETE:8)
Block(-4,82,6,STAINED_GLASS_PANE:15)
Block(-4,82,7,STAINED_GLASS_PANE:15)
Block(-4,82,8,STAINED_GLASS_PANE:15)
Block(-4,83,-2,CONCRETE_POWDER:8)
Block(-4,83,-1,CONCRETE_POWDER:8)
Block(-4,83,0,STAINED_GLASS_PANE:15)
Block(-4,83,1,STAINED_GLASS_PANE:15)
Block(-4,83,2,STAINED_GLASS_PANE:15)
Block(-4,83,3,STAINED_GLASS_PANE:15)
Block(-4,83,4,CONCRETE:8)
Block(-4,83,5,CONCRETE_POWDER:8)
Block(-4,83,6,STAINED_GLASS_PANE:15)
Block(-4,83,7,STAINED_GLASS_PANE:15)
Block(-4,83,8,STAINED_GLASS_PANE:15)
Block(-4,84,-2,CONCRETE:7)
Block(-4,84,-1,CONCRETE:7)
Block(-4,84,0,STAINED_GLASS_PANE:15)
Block(-4,84,1,STAINED_GLASS_PANE:15)
Block(-4,84,2,STAINED_GLASS_PANE:15)
Block(-4,84,3,STAINED_GLASS_PANE:15)
Block(-4,84,4,CONCRETE:8)
Block(-4,84,5,CONCRETE:8)
Block(-4,84,6,STAINED_GLASS_PANE:15)
Block(-4,84,7,STAINED_GLASS_PANE:15)
Block(-4,84,8,STAINED_GLASS_PANE:15)
Block(-4,85,-2,CONCRETE:8)
Block(-4,85,-1,CONCRETE:7)
Block(-4,85,0,STAINED_GLASS_PANE:15)
Block(-4,85,1,STAINED_GLASS_PANE:15)
Block(-4,85,2,STAINED_GLASS_PANE:15)
Block(-4,85,3,STAINED_GLASS_PANE:15)
Block(-4,85,4,CONCRETE_POWDER:8)
Block(-4,85,5,CONCRETE:8)
Block(-4,85,6,STAINED_GLASS_PANE:15)
Block(-4,85,7,STAINED_GLASS_PANE:15)
Block(-4,85,8,STAINED_GLASS_PANE:15)
Block(-4,86,-2,CONCRETE:8)
Block(-4,86,-1,CONCRETE:7)
Block(-4,86,0,STAINED_GLASS_PANE:15)
Block(-4,86,1,STAINED_GLASS_PANE:15)
Block(-4,86,2,STAINED_GLASS_PANE:15)
Block(-4,86,3,STAINED_GLASS_PANE:15)
Block(-4,86,4,CONCRETE_POWDER:8)
Block(-4,86,5,CONCRETE:8)
Block(-4,86,6,STAINED_GLASS_PANE:15)
Block(-4,86,7,STAINED_GLASS_PANE:15)
Block(-4,86,8,STAINED_GLASS_PANE:15)
Block(-4,87,-2,CONCRETE:8)
Block(-4,87,-1,CONCRETE:7)
Block(-4,87,4,CONCRETE:8)
Block(-4,87,5,CONCRETE:8)
Block(-4,88,-2,CONCRETE_POWDER:8)
Block(-4,88,-1,CONCRETE:8)
Block(-4,88,4,CONCRETE_POWDER:8)
Block(-4,88,5,CONCRETE:8)
Block(-3,0,-7,DIRT:0)
Block(-3,0,-6,DIRT:0)
Block(-3,0,-5,DIRT:0)
Block(-3,0,-4,DIRT:0)
Block(-3,0,-3,DIRT:0)
Block(-3,0,-2,STAINED_GLASS_PANE:0)
Block(-3,0,-1,DIRT:0)
Block(-3,0,3,CONCRETE_POWDER:8)
Block(-3,0,4,CONCRETE_POWDER:8)
Block(-3,0,5,CONCRETE:11)
Block(-3,0,6,CONCRETE:11)
Block(-3,0,7,CONCRETE:8)
Block(-3,0,8,CONCRETE:11)
Block(-3,1,-7,DIRT:0)
Block(-3,1,-6,DIRT:0)
Block(-3,1,-5,DIRT:0)
Block(-3,1,-4,DIRT:0)
Block(-3,1,-3,DIRT:0)
Block(-3,1,-2,STAINED_GLASS_PANE:0)
Block(-3,1,-1,STEP:8)
Block(-3,1,0,STEP:8)
Block(-3,1,1,STEP:8)
Block(-3,1,2,STEP:8)
Block(-3,1,3,CONCRETE_POWDER:8)
Block(-3,1,4,CONCRETE:8)
Block(-3,1,5,CONCRETE:8)
Block(-3,1,6,CONCRETE_POWDER:8)
Block(-3,1,7,CONCRETE:8)
Block(-3,1,8,CONCRETE:8)
Block(-3,2,-7,DIRT:0)
Block(-3,2,-6,DIRT:0)
Block(-3,2,-5,DIRT:0)
Block(-3,2,-4,DIRT:0)
Block(-3,2,-3,DIRT:0)
Block(-3,2,-2,STAINED_GLASS_PANE:0)
Block(-3,2,-1,CONCRETE:15)
Block(-3,2,0,CONCRETE:15)
Block(-3,2,1,CONCRETE:15)
Block(-3,2,2,CONCRETE:15)
Block(-3,2,3,CONCRETE:15)
Block(-3,2,4,CONCRETE:15)
Block(-3,2,5,STAINED_GLASS_PANE:3)
Block(-3,2,6,STAINED_GLASS_PANE:3)
Block(-3,2,7,CONCRETE:15)
Block(-3,2,8,STAINED_GLASS_PANE:3)
Block(-3,3,-7,DIRT:0)
Block(-3,3,-6,DIRT:0)
Block(-3,3,-5,DIRT:0)
Block(-3,3,-4,DIRT:0)
Block(-3,3,-3,DIRT:0)
Block(-3,3,-2,STAINED_GLASS_PANE:0)
Block(-3,3,-1,STEP:0)
Block(-3,3,0,STEP:0)
Block(-3,3,1,STEP:0)
Block(-3,3,2,CONCRETE:8)
Block(-3,3,3,CONCRETE_POWDER:8)
Block(-3,3,4,STAINED_GLASS_PANE:3)
Block(-3,3,5,STAINED_GLASS_PANE:3)
Block(-3,3,6,STAINED_GLASS_PANE:3)
Block(-3,3,7,CONCRETE:8)
Block(-3,3,8,STAINED_GLASS_PANE:3)
Block(-3,4,-7,DIRT:0)
Block(-3,4,-6,DIRT:0)
Block(-3,4,-5,DIRT:0)
Block(-3,4,-4,DIRT:0)
Block(-3,4,-3,DIRT:0)
Block(-3,4,-2,STAINED_GLASS_PANE:0)
Block(-3,4,-1,DIRT:0)
Block(-3,4,1,CONCRETE_POWDER:8)
Block(-3,4,2,CONCRETE:8)
Block(-3,4,3,CONCRETE:8)
Block(-3,4,4,STAINED_GLASS_PANE:3)
Block(-3,4,5,STAINED_GLASS_PANE:3)
Block(-3,4,6,STAINED_GLASS_PANE:3)
Block(-3,4,7,CONCRETE:8)
Block(-3,4,8,STAINED_GLASS_PANE:3)
Block(-3,5,-7,DIRT:0)
Block(-3,5,-6,DIRT:0)
Block(-3,5,-5,DIRT:0)
Block(-3,5,-4,DIRT:0)
Block(-3,5,-3,DIRT:0)
Block(-3,5,-2,STAINED_GLASS_PANE:0)
Block(-3,5,-1,DIRT:0)
Block(-3,5,1,CONCRETE:8)
Block(-3,5,2,CONCRETE:8)
Block(-3,5,3,STAINED_GLASS_PANE:3)
Block(-3,5,4,STAINED_GLASS_PANE:3)
Block(-3,5,5,STAINED_GLASS_PANE:3)
Block(-3,5,6,STAINED_GLASS_PANE:3)
Block(-3,5,7,CONCRETE:8)
Block(-3,5,8,STAINED_GLASS_PANE:3)
Block(-3,6,-7,DIRT:0)
Block(-3,6,-6,DIRT:0)
Block(-3,6,-5,DIRT:0)
Block(-3,6,-4,DIRT:0)
Block(-3,6,-3,DIRT:0)
Block(-3,6,-2,STAINED_GLASS_PANE:0)
Block(-3,6,-1,DIRT:0)
Block(-3,6,0,CONCRETE:8)
Block(-3,6,1,CONCRETE:8)
Block(-3,6,2,CONCRETE:8)
Block(-3,6,3,STAINED_GLASS_PANE:3)
Block(-3,6,4,STAINED_GLASS_PANE:3)
Block(-3,6,5,STAINED_GLASS_PANE:3)
Block(-3,6,6,STAINED_GLASS_PANE:3)
Block(-3,6,7,CONCRETE:8)
Block(-3,6,8,STAINED_GLASS_PANE:3)
Block(-3,7,-7,DIRT:0)
Block(-3,7,-6,DIRT:0)
Block(-3,7,-5,DIRT:0)
Block(-3,7,-4,DIRT:0)
Block(-3,7,-3,DIRT:0)
Block(-3,7,-2,STAINED_GLASS_PANE:0)
Block(-3,7,-1,DIRT:0)
Block(-3,7,0,CONCRETE:8)
Block(-3,7,1,CONCRETE:8)
Block(-3,7,2,STAINED_GLASS_PANE:3)
Block(-3,7,3,STAINED_GLASS_PANE:3)
Block(-3,7,4,STAINED_GLASS_PANE:3)
Block(-3,7,5,STAINED_GLASS_PANE:3)
Block(-3,7,6,CONCRETE:8)
Block(-3,7,7,CONCRETE:8)
Block(-3,7,8,CONCRETE:8)
Block(-3,8,-7,DIRT:0)
Block(-3,8,-6,DIRT:0)
Block(-3,8,-5,DIRT:0)
Block(-3,8,-4,DIRT:0)
Block(-3,8,-3,DIRT:0)
Block(-3,8,-2,CONCRETE:7)
Block(-3,8,-1,CONCRETE:8)
Block(-3,8,0,CONCRETE:8)
Block(-3,8,1,CONCRETE:8)
Block(-3,8,2,STAINED_GLASS_PANE:3)
Block(-3,8,3,STAINED_GLASS_PANE:3)
Block(-3,8,4,STAINED_GLASS_PANE:3)
Block(-3,8,5,STAINED_GLASS_PANE:3)
Block(-3,8,6,CONCRETE_POWDER:8)
Block(-3,8,7,CONCRETE:8)
Block(-3,8,8,CONCRETE:8)
Block(-3,9,-7,DIRT:0)
Block(-3,9,-6,DIRT:0)
Block(-3,9,-5,DIRT:0)
Block(-3,9,-4,DIRT:0)
Block(-3,9,-3,DIRT:0)
Block(-3,9,-2,CONCRETE:7)
Block(-3,9,-1,CONCRETE:8)
Block(-3,9,0,CONCRETE:8)
Block(-3,9,1,STAINED_GLASS_PANE:3)
Block(-3,9,2,STAINED_GLASS_PANE:3)
Block(-3,9,3,STAINED_GLASS_PANE:3)
Block(-3,9,4,STAINED_GLASS_PANE:3)
Block(-3,9,5,CONCRETE:8)
Block(-3,9,6,CONCRETE:8)
Block(-3,9,7,CONCRETE:8)
Block(-3,9,8,CONCRETE_POWDER:8)
Block(-3,10,-7,DIRT:0)
Block(-3,10,-6,DIRT:0)
Block(-3,10,-5,DIRT:0)
Block(-3,10,-4,DIRT:0)
Block(-3,10,-3,DIRT:0)
Block(-3,10,-2,CONCRETE:7)
Block(-3,10,-1,CONCRETE:8)
Block(-3,10,0,CONCRETE:8)
Block(-3,10,1,STAINED_GLASS_PANE:3)
Block(-3,10,2,STAINED_GLASS_PANE:3)
Block(-3,10,3,STAINED_GLASS_PANE:3)
Block(-3,10,4,STAINED_GLASS_PANE:3)
Block(-3,10,5,CONCRETE_POWDER:8)
Block(-3,10,6,CONCRETE:8)
Block(-3,10,7,STAINED_GLASS_PANE:3)
Block(-3,10,8,CONCRETE:8)
Block(-3,11,-7,DIRT:0)
Block(-3,11,-6,DIRT:0)
Block(-3,11,-5,DIRT:0)
Block(-3,11,-4,DIRT:0)
Block(-3,11,-3,DIRT:0)
Block(-3,11,-2,CONCRETE:7)
Block(-3,11,-1,CONCRETE:8)
Block(-3,11,0,STAINED_GLASS_PANE:3)
Block(-3,11,1,STAINED_GLASS_PANE:3)
Block(-3,11,2,STAINED_GLASS_PANE:3)
Block(-3,11,3,STAINED_GLASS_PANE:3)
Block(-3,11,4,CONCRETE:8)
Block(-3,11,5,CONCRETE:8)
Block(-3,11,6,CONCRETE:8)
Block(-3,11,7,STAINED_GLASS_PANE:3)
Block(-3,11,8,CONCRETE_POWDER:8)
Block(-3,12,-7,DIRT:0)
Block(-3,12,-6,DIRT:0)
Block(-3,12,-5,DIRT:0)
Block(-3,12,-4,DIRT:0)
Block(-3,12,-3,DIRT:0)
Block(-3,12,-2,CONCRETE:7)
Block(-3,12,-1,CONCRETE_POWDER:8)
Block(-3,12,0,STAINED_GLASS_PANE:3)
Block(-3,12,1,STAINED_GLASS_PANE:3)
Block(-3,12,2,STAINED_GLASS_PANE:3)
Block(-3,12,3,STAINED_GLASS_PANE:3)
Block(-3,12,4,CONCRETE:8)
Block(-3,12,5,CONCRETE:8)
Block(-3,12,6,STAINED_GLASS_PANE:3)
Block(-3,12,7,STAINED_GLASS_PANE:3)
Block(-3,12,8,STAINED_GLASS_PANE:3)
Block(-3,13,-7,DIRT:0)
Block(-3,13,-6,DIRT:0)
Block(-3,13,-5,DIRT:0)
Block(-3,13,-4,DIRT:0)
Block(-3,13,-3,DIRT:0)
Block(-3,13,-2,CONCRETE:7)
Block(-3,13,-1,CONCRETE:8)
Block(-3,13,0,STAINED_GLASS_PANE:3)
Block(-3,13,1,STAINED_GLASS_PANE:3)
Block(-3,13,2,STAINED_GLASS_PANE:3)
Block(-3,13,3,STAINED_GLASS_PANE:3)
Block(-3,13,4,CONCRETE:8)
Block(-3,13,5,CONCRETE:8)
Block(-3,13,6,STAINED_GLASS_PANE:3)
Block(-3,13,7,STAINED_GLASS_PANE:3)
Block(-3,13,8,STAINED_GLASS_PANE:3)
Block(-3,14,-7,DIRT:0)
Block(-3,14,-6,DIRT:0)
Block(-3,14,-5,DIRT:0)
Block(-3,14,-4,DIRT:0)
Block(-3,14,-3,DIRT:0)
Block(-3,14,-2,CONCRETE:7)
Block(-3,14,-1,CONCRETE:8)
Block(-3,14,0,STAINED_GLASS_PANE:3)
Block(-3,14,1,STAINED_GLASS_PANE:3)
Block(-3,14,2,STAINED_GLASS_PANE:3)
Block(-3,14,3,STAINED_GLASS_PANE:3)
Block(-3,14,4,CONCRETE:8)
Block(-3,14,5,CONCRETE:8)
Block(-3,14,6,STAINED_GLASS_PANE:3)
Block(-3,14,7,STAINED_GLASS_PANE:3)
Block(-3,14,8,STAINED_GLASS_PANE:3)
Block(-3,15,-7,SAND:0)
Block(-3,15,-6,SAND:0)
Block(-3,15,-5,SAND:0)
Block(-3,15,-4,SAND:0)
Block(-3,15,-3,SAND:0)
Block(-3,15,-2,CONCRETE_POWDER:8)
Block(-3,15,-1,CONCRETE:8)
Block(-3,15,0,STAINED_GLASS_PANE:3)
Block(-3,15,1,STAINED_GLASS_PANE:3)
Block(-3,15,2,STAINED_GLASS_PANE:3)
Block(-3,15,3,STAINED_GLASS_PANE:3)
Block(-3,15,4,CONCRETE_POWDER:8)
Block(-3,15,5,CONCRETE:8)
Block(-3,15,6,STAINED_GLASS_PANE:3)
Block(-3,15,7,STAINED_GLASS_PANE:3)
Block(-3,15,8,STAINED_GLASS_PANE:3)
Block(-3,16,-2,CONCRETE:8)
Block(-3,16,-1,CONCRETE:8)
Block(-3,16,0,STAINED_GLASS_PANE:3)
Block(-3,16,1,STAINED_GLASS_PANE:3)
Block(-3,16,2,STAINED_GLASS_PANE:3)
Block(-3,16,3,STAINED_GLASS_PANE:3)
Block(-3,16,4,CONCRETE:8)
Block(-3,16,5,CONCRETE_POWDER:8)
Block(-3,16,6,STAINED_GLASS_PANE:3)
Block(-3,16,7,STAINED_GLASS_PANE:3)
Block(-3,16,8,STAINED_GLASS_PANE:3)
Block(-3,17,-2,CONCRETE:8)
Block(-3,17,-1,CONCRETE_POWDER:8)
Block(-3,17,0,STAINED_GLASS_PANE:3)
Block(-3,17,1,STAINED_GLASS_PANE:3)
Block(-3,17,2,STAINED_GLASS_PANE:3)
Block(-3,17,3,STAINED_GLASS_PANE:3)
Block(-3,17,4,CONCRETE_POWDER:8)
Block(-3,17,5,CONCRETE:8)
Block(-3,17,6,STAINED_GLASS_PANE:3)
Block(-3,17,7,STAINED_GLASS_PANE:3)
Block(-3,17,8,STAINED_GLASS_PANE:3)
Block(-3,18,-7,CONCRETE_POWDER:8)
Block(-3,18,-6,CONCRETE:8)
Block(-3,18,-5,CONCRETE_POWDER:8)
Block(-3,18,-2,CONCRETE:7)
Block(-3,18,-1,CONCRETE:8)
Block(-3,18,0,STAINED_GLASS_PANE:3)
Block(-3,18,1,STAINED_GLASS_PANE:3)
Block(-3,18,2,STAINED_GLASS_PANE:3)
Block(-3,18,3,STAINED_GLASS_PANE:3)
Block(-3,18,4,CONCRETE:8)
Block(-3,18,5,CONCRETE:8)
Block(-3,18,6,STAINED_GLASS_PANE:3)
Block(-3,18,7,STAINED_GLASS_PANE:3)
Block(-3,18,8,STAINED_GLASS_PANE:3)
Block(-3,19,-2,CONCRETE:7)
Block(-3,19,-1,CONCRETE:8)
Block(-3,19,0,STAINED_GLASS_PANE:3)
Block(-3,19,1,STAINED_GLASS_PANE:3)
Block(-3,19,2,STAINED_GLASS_PANE:3)
Block(-3,19,3,STAINED_GLASS_PANE:3)
Block(-3,19,4,CONCRETE:8)
Block(-3,19,5,CONCRETE:8)
Block(-3,19,6,STAINED_GLASS_PANE:3)
Block(-3,19,7,STAINED_GLASS_PANE:3)
Block(-3,19,8,STAINED_GLASS_PANE:3)
Block(-3,20,-2,CONCRETE:7)
Block(-3,20,-1,CONCRETE_POWDER:8)
Block(-3,20,0,STAINED_GLASS_PANE:3)
Block(-3,20,1,STAINED_GLASS_PANE:3)
Block(-3,20,2,STAINED_GLASS_PANE:3)
Block(-3,20,3,STAINED_GLASS_PANE:3)
Block(-3,20,4,CONCRETE_POWDER:8)
Block(-3,20,5,CONCRETE:8)
Block(-3,20,6,CONCRETE:8)
Block(-3,20,7,STAINED_GLASS_PANE:3)
Block(-3,20,8,CONCRETE:8)
Block(-3,21,-2,CONCRETE:7)
Block(-3,21,-1,CONCRETE:8)
Block(-3,21,0,CONCRETE:8)
Block(-3,21,1,STAINED_GLASS_PANE:3)
Block(-3,21,2,STAINED_GLASS_PANE:3)
Block(-3,21,3,STAINED_GLASS_PANE:3)
Block(-3,21,4,STAINED_GLASS_PANE:3)
Block(-3,21,5,CONCRETE:8)
Block(-3,21,6,CONCRETE:8)
Block(-3,21,7,STAINED_GLASS_PANE:3)
Block(-3,21,8,CONCRETE_POWDER:8)
Block(-3,22,-2,CONCRETE:8)
Block(-3,22,-1,CONCRETE_POWDER:8)
Block(-3,22,0,CONCRETE:8)
Block(-3,22,1,STAINED_GLASS_PANE:3)
Block(-3,22,2,STAINED_GLASS_PANE:3)
Block(-3,22,3,STAINED_GLASS_PANE:3)
Block(-3,22,4,STAINED_GLASS_PANE:3)
Block(-3,22,5,CONCRETE:8)
Block(-3,22,6,CONCRETE:8)
Block(-3,22,7,CONCRETE_POWDER:8)
Block(-3,22,8,CONCRETE:8)
Block(-3,23,-2,CONCRETE:8)
Block(-3,23,-1,CONCRETE:8)
Block(-3,23,0,CONCRETE:8)
Block(-3,23,1,CONCRETE:8)
Block(-3,23,2,STAINED_GLASS_PANE:3)
Block(-3,23,3,STAINED_GLASS_PANE:3)
Block(-3,23,4,STAINED_GLASS_PANE:3)
Block(-3,23,5,STAINED_GLASS_PANE:3)
Block(-3,23,6,CONCRETE_POWDER:8)
Block(-3,23,7,CONCRETE_POWDER:8)
Block(-3,23,8,CONCRETE_POWDER:8)
Block(-3,24,-2,STAINED_GLASS_PANE:15)
Block(-3,24,0,CONCRETE:8)
Block(-3,24,1,CONCRETE:8)
Block(-3,24,2,STAINED_GLASS_PANE:3)
Block(-3,24,3,STAINED_GLASS_PANE:3)
Block(-3,24,4,STAINED_GLASS_PANE:3)
Block(-3,24,5,STAINED_GLASS_PANE:3)
Block(-3,24,6,CONCRETE:8)
Block(-3,24,7,CONCRETE:8)
Block(-3,24,8,CONCRETE:8)
Block(-3,25,-2,STAINED_GLASS_PANE:15)
Block(-3,25,0,CONCRETE:8)
Block(-3,25,1,CONCRETE:8)
Block(-3,25,2,CONCRETE_POWDER:8)
Block(-3,25,3,STAINED_GLASS_PANE:3)
Block(-3,25,4,STAINED_GLASS_PANE:3)
Block(-3,25,5,STAINED_GLASS_PANE:3)
Block(-3,25,6,STAINED_GLASS_PANE:3)
Block(-3,25,7,CONCRETE:8)
Block(-3,25,8,STAINED_GLASS_PANE:3)
Block(-3,26,-2,STAINED_GLASS_PANE:15)
Block(-3,26,1,CONCRETE_POWDER:8)
Block(-3,26,2,CONCRETE_POWDER:8)
Block(-3,26,3,STAINED_GLASS_PANE:3)
Block(-3,26,4,STAINED_GLASS_PANE:3)
Block(-3,26,5,STAINED_GLASS_PANE:3)
Block(-3,26,6,STAINED_GLASS_PANE:3)
Block(-3,26,7,CONCRETE_POWDER:8)
Block(-3,26,8,STAINED_GLASS_PANE:3)
Block(-3,27,-2,STAINED_GLASS_PANE:15)
Block(-3,27,1,CONCRETE:8)
Block(-3,27,2,CONCRETE:8)
Block(-3,27,3,CONCRETE:8)
Block(-3,27,4,STAINED_GLASS_PANE:3)
Block(-3,27,5,STAINED_GLASS_PANE:3)
Block(-3,27,6,STAINED_GLASS_PANE:3)
Block(-3,27,7,CONCRETE_POWDER:8)
Block(-3,27,8,STAINED_GLASS_PANE:3)
Block(-3,28,-2,STAINED_GLASS_PANE:15)
Block(-3,28,-1,STEP:8)
Block(-3,28,0,STEP:8)
Block(-3,28,1,STEP:8)
Block(-3,28,2,CONCRETE:8)
Block(-3,28,3,CONCRETE:8)
Block(-3,28,4,STAINED_GLASS_PANE:3)
Block(-3,28,5,STAINED_GLASS_PANE:3)
Block(-3,28,6,STAINED_GLASS_PANE:3)
Block(-3,28,7,CONCRETE_POWDER:8)
Block(-3,28,8,STAINED_GLASS_PANE:3)
Block(-3,29,-2,STAINED_GLASS_PANE:15)
Block(-3,29,-1,CONCRETE:15)
Block(-3,29,0,CONCRETE:15)
Block(-3,29,1,CONCRETE:15)
Block(-3,29,2,CONCRETE:15)
Block(-3,29,3,CONCRETE:15)
Block(-3,29,4,CONCRETE:15)
Block(-3,29,5,STAINED_GLASS_PANE:3)
Block(-3,29,6,STAINED_GLASS_PANE:3)
Block(-3,29,7,CONCRETE:15)
Block(-3,29,8,STAINED_GLASS_PANE:3)
Block(-3,30,-2,STAINED_GLASS_PANE:15)
Block(-3,30,-1,STEP:0)
Block(-3,30,0,STEP:0)
Block(-3,30,1,STEP:0)
Block(-3,30,2,STEP:0)
Block(-3,30,3,CONCRETE:8)
Block(-3,30,4,CONCRETE:8)
Block(-3,30,5,CONCRETE:8)
Block(-3,30,6,CONCRETE:8)
Block(-3,30,7,CONCRETE:8)
Block(-3,30,8,CONCRETE:8)
Block(-3,31,-2,STAINED_GLASS_PANE:15)
Block(-3,31,3,CONCRETE:8)
Block(-3,31,4,CONCRETE_POWDER:8)
Block(-3,31,5,CONCRETE:11)
Block(-3,31,6,CONCRETE:11)
Block(-3,31,7,CONCRETE:8)
Block(-3,31,8,CONCRETE:11)
Block(-3,32,-2,STAINED_GLASS_PANE:15)
Block(-3,32,-1,STEP:8)
Block(-3,32,0,STEP:8)
Block(-3,32,1,STEP:8)
Block(-3,32,2,STEP:8)
Block(-3,32,3,STEP:8)
Block(-3,32,4,CONCRETE_POWDER:8)
Block(-3,32,5,CONCRETE:8)
Block(-3,32,6,CONCRETE:8)
Block(-3,32,7,CONCRETE:8)
Block(-3,32,8,CONCRETE:8)
Block(-3,33,-2,STAINED_GLASS_PANE:15)
Block(-3,33,-1,CONCRETE:15)
Block(-3,33,0,CONCRETE:15)
Block(-3,33,1,CONCRETE:15)
Block(-3,33,2,CONCRETE:15)
Block(-3,33,3,CONCRETE:15)
Block(-3,33,4,CONCRETE:15)
Block(-3,33,5,CONCRETE:11)
Block(-3,33,6,CONCRETE:11)
Block(-3,33,7,CONCRETE:15)
Block(-3,33,8,CONCRETE:11)
Block(-3,34,-2,STAINED_GLASS_PANE:15)
Block(-3,34,-1,STEP:0)
Block(-3,34,0,STEP:0)
Block(-3,34,1,STEP:0)
Block(-3,34,2,STEP:0)
Block(-3,34,3,STEP:0)
Block(-3,34,4,CONCRETE:8)
Block(-3,34,5,CONCRETE:8)
Block(-3,34,6,CONCRETE:8)
Block(-3,34,7,CONCRETE:8)
Block(-3,34,8,CONCRETE:8)
Block(-3,35,-2,STAINED_GLASS_PANE:15)
Block(-3,35,3,CONCRETE:8)
Block(-3,35,4,CONCRETE:8)
Block(-3,35,5,CONCRETE:11)
Block(-3,35,6,CONCRETE:11)
Block(-3,35,7,CONCRETE_POWDER:8)
Block(-3,35,8,CONCRETE:11)
Block(-3,36,-2,STAINED_GLASS_PANE:15)
Block(-3,36,-1,STEP:8)
Block(-3,36,0,STEP:8)
Block(-3,36,1,STEP:8)
Block(-3,36,2,STEP:8)
Block(-3,36,3,CONCRETE:8)
Block(-3,36,4,CONCRETE_POWDER:8)
Block(-3,36,5,CONCRETE:8)
Block(-3,36,6,CONCRETE:8)
Block(-3,36,7,CONCRETE:8)
Block(-3,36,8,CONCRETE:8)
Block(-3,37,-2,STAINED_GLASS_PANE:15)
Block(-3,37,-1,CONCRETE:15)
Block(-3,37,0,CONCRETE:15)
Block(-3,37,1,CONCRETE:15)
Block(-3,37,2,CONCRETE:15)
Block(-3,37,3,CONCRETE:15)
Block(-3,37,4,CONCRETE:15)
Block(-3,37,5,STAINED_GLASS_PANE:3)
Block(-3,37,6,STAINED_GLASS_PANE:3)
Block(-3,37,7,CONCRETE:15)
Block(-3,37,8,STAINED_GLASS_PANE:3)
Block(-3,38,-2,STAINED_GLASS_PANE:15)
Block(-3,38,-1,STEP:0)
Block(-3,38,0,STEP:0)
Block(-3,38,1,STEP:0)
Block(-3,38,2,CONCRETE:8)
Block(-3,38,3,CONCRETE:8)
Block(-3,38,4,STAINED_GLASS_PANE:3)
Block(-3,38,5,STAINED_GLASS_PANE:3)
Block(-3,38,6,STAINED_GLASS_PANE:3)
Block(-3,38,7,CONCRETE:8)
Block(-3,38,8,STAINED_GLASS_PANE:3)
Block(-3,39,-2,STAINED_GLASS_PANE:15)
Block(-3,39,1,CONCRETE:8)
Block(-3,39,2,CONCRETE_POWDER:8)
Block(-3,39,3,CONCRETE:8)
Block(-3,39,4,STAINED_GLASS_PANE:3)
Block(-3,39,5,STAINED_GLASS_PANE:3)
Block(-3,39,6,STAINED_GLASS_PANE:3)
Block(-3,39,7,CONCRETE:8)
Block(-3,39,8,STAINED_GLASS_PANE:3)
Block(-3,40,-2,STAINED_GLASS_PANE:15)
Block(-3,40,1,CONCRETE:8)
Block(-3,40,2,CONCRETE_POWDER:8)
Block(-3,40,3,STAINED_GLASS_PANE:3)
Block(-3,40,4,STAINED_GLASS_PANE:3)
Block(-3,40,5,STAINED_GLASS_PANE:3)
Block(-3,40,6,STAINED_GLASS_PANE:3)
Block(-3,40,7,CONCRETE:8)
Block(-3,40,8,STAINED_GLASS_PANE:3)
Block(-3,41,-2,STAINED_GLASS_PANE:15)
Block(-3,41,0,CONCRETE:8)
Block(-3,41,1,CONCRETE:8)
Block(-3,41,2,CONCRETE:8)
Block(-3,41,3,STAINED_GLASS_PANE:3)
Block(-3,41,4,STAINED_GLASS_PANE:3)
Block(-3,41,5,STAINED_GLASS_PANE:3)
Block(-3,41,6,STAINED_GLASS_PANE:3)
Block(-3,41,7,CONCRETE:8)
Block(-3,41,8,STAINED_GLASS_PANE:3)
Block(-3,42,-2,STAINED_GLASS_PANE:15)
Block(-3,42,0,CONCRETE:8)
Block(-3,42,1,CONCRETE_POWDER:8)
Block(-3,42,2,STAINED_GLASS_PANE:3)
Block(-3,42,3,STAINED_GLASS_PANE:3)
Block(-3,42,4,STAINED_GLASS_PANE:3)
Block(-3,42,5,STAINED_GLASS_PANE:3)
Block(-3,42,6,CONCRETE:8)
Block(-3,42,7,CONCRETE:8)
Block(-3,42,8,CONCRETE:8)
Block(-3,43,-2,CONCRETE:7)
Block(-3,43,-1,CONCRETE_POWDER:8)
Block(-3,43,0,CONCRETE:8)
Block(-3,43,1,CONCRETE:8)
Block(-3,43,2,STAINED_GLASS_PANE:3)
Block(-3,43,3,STAINED_GLASS_PANE:3)
Block(-3,43,4,STAINED_GLASS_PANE:3)
Block(-3,43,5,STAINED_GLASS_PANE:3)
Block(-3,43,6,CONCRETE_POWDER:8)
Block(-3,43,7,CONCRETE_POWDER:8)
Block(-3,43,8,CONCRETE_POWDER:8)
Block(-3,44,-2,CONCRETE:7)
Block(-3,44,-1,CONCRETE_POWDER:8)
Block(-3,44,0,CONCRETE_POWDER:8)
Block(-3,44,4,STAINED_GLASS_PANE:3)
Block(-3,44,5,CONCRETE:8)
Block(-3,44,6,CONCRETE:8)
Block(-3,44,7,CONCRETE:8)
Block(-3,44,8,CONCRETE_POWDER:8)
Block(-3,45,-2,CONCRETE:7)
Block(-3,45,-1,CONCRETE:8)
Block(-3,45,0,CONCRETE_POWDER:8)
Block(-3,45,5,CONCRETE:8)
Block(-3,45,6,CONCRETE:8)
Block(-3,45,8,CONCRETE_POWDER:8)
Block(-3,46,-2,CONCRETE:7)
Block(-3,46,-1,CONCRETE:8)
Block(-3,46,4,CONCRETE:8)
Block(-3,46,5,CONCRETE:8)
Block(-3,46,6,CONCRETE_POWDER:8)
Block(-3,46,8,CONCRETE:8)
Block(-3,47,-2,CONCRETE:7)
Block(-3,47,-1,CONCRETE:8)
Block(-3,47,4,CONCRETE_POWDER:8)
Block(-3,47,5,CONCRETE_POWDER:8)
Block(-3,48,-2,CONCRETE:7)
Block(-3,48,-1,CONCRETE:8)
Block(-3,48,4,CONCRETE:8)
Block(-3,48,5,CONCRETE_POWDER:8)
Block(-3,49,-2,CONCRETE:7)
Block(-3,49,-1,CONCRETE:8)
Block(-3,49,4,CONCRETE:8)
Block(-3,49,5,CONCRETE:8)
Block(-3,50,-2,CONCRETE:8)
Block(-3,50,-1,CONCRETE:8)
Block(-3,50,4,CONCRETE:8)
Block(-3,50,5,CONCRETE:8)
Block(-3,51,-2,CONCRETE_POWDER:8)
Block(-3,51,-1,CONCRETE_POWDER:8)
Block(-3,51,4,CONCRETE:8)
Block(-3,51,5,CONCRETE_POWDER:8)
Block(-3,52,-2,CONCRETE_POWDER:8)
Block(-3,52,-1,IRON_FENCE:0)
Block(-3,52,4,CONCRETE:8)
Block(-3,52,5,CONCRETE_POWDER:8)
Block(-3,52,8,STAINED_GLASS_PANE:3)
Block(-3,53,-3,IRON_FENCE:0)
Block(-3,53,-2,CONCRETE:8)
Block(-3,53,-1,IRON_FENCE:0)
Block(-3,53,4,CONCRETE:8)
Block(-3,53,5,CONCRETE_POWDER:8)
Block(-3,53,6,STAINED_GLASS_PANE:3)
Block(-3,53,7,STAINED_GLASS_PANE:3)
Block(-3,53,8,STAINED_GLASS_PANE:3)
Block(-3,54,-7,CONCRETE:8)
Block(-3,54,-2,CONCRETE:8)
Block(-3,54,-1,IRON_FENCE:0)
Block(-3,54,0,STAINED_GLASS_PANE:3)
Block(-3,54,4,CONCRETE_POWDER:8)
Block(-3,54,5,CONCRETE:8)
Block(-3,54,6,STAINED_GLASS_PANE:3)
Block(-3,54,7,STAINED_GLASS_PANE:3)
Block(-3,54,8,STAINED_GLASS_PANE:3)
Block(-3,55,-7,CONCRETE:8)
Block(-3,55,-2,IRON_FENCE:0)
Block(-3,55,0,STAINED_GLASS_PANE:3)
Block(-3,55,1,STAINED_GLASS_PANE:3)
Block(-3,55,2,STAINED_GLASS_PANE:3)
Block(-3,55,3,STAINED_GLASS_PANE:3)
Block(-3,55,4,CONCRETE:8)
Block(-3,55,5,CONCRETE:8)
Block(-3,55,6,CONCRETE_POWDER:8)
Block(-3,55,7,STAINED_GLASS_PANE:3)
Block(-3,55,8,CONCRETE:8)
Block(-3,56,-7,CONCRETE:8)
Block(-3,56,-2,IRON_FENCE:0)
Block(-3,56,0,CONCRETE:8)
Block(-3,56,1,STAINED_GLASS_PANE:3)
Block(-3,56,2,STAINED_GLASS_PANE:3)
Block(-3,56,3,STAINED_GLASS_PANE:3)
Block(-3,56,4,STAINED_GLASS_PANE:3)
Block(-3,56,5,CONCRETE:8)
Block(-3,56,6,CONCRETE_POWDER:8)
Block(-3,56,7,STAINED_GLASS_PANE:3)
Block(-3,56,8,CONCRETE:8)
Block(-3,57,-7,STAINED_GLASS:11)
Block(-3,57,-6,STAINED_GLASS:15)
Block(-3,57,-5,CONCRETE:8)
Block(-3,57,-2,IRON_FENCE:0)
Block(-3,57,1,STAINED_GLASS_PANE:3)
Block(-3,57,2,STAINED_GLASS_PANE:3)
Block(-3,57,3,STAINED_GLASS_PANE:3)
Block(-3,57,4,STAINED_GLASS_PANE:3)
Block(-3,57,5,CONCRETE:8)
Block(-3,57,6,CONCRETE:8)
Block(-3,57,7,CONCRETE:8)
Block(-3,57,8,CONCRETE:8)
Block(-3,58,-7,STAINED_GLASS:11)
Block(-3,58,-6,STAINED_GLASS:15)
Block(-3,58,-5,CONCRETE:8)
Block(-3,58,2,STAINED_GLASS_PANE:3)
Block(-3,58,3,STAINED_GLASS_PANE:3)
Block(-3,58,4,STAINED_GLASS_PANE:3)
Block(-3,58,5,STAINED_GLASS_PANE:3)
Block(-3,58,6,CONCRETE:8)
Block(-3,58,7,CONCRETE:8)
Block(-3,58,8,CONCRETE:8)
Block(-3,59,-7,STAINED_GLASS:11)
Block(-3,59,-6,STAINED_GLASS:15)
Block(-3,59,-5,CONCRETE:8)
Block(-3,59,-2,STAINED_GLASS_PANE:15)
Block(-3,59,2,STAINED_GLASS_PANE:3)
Block(-3,59,3,STAINED_GLASS_PANE:3)
Block(-3,59,4,STAINED_GLASS_PANE:3)
Block(-3,59,5,STAINED_GLASS_PANE:3)
Block(-3,59,6,CONCRETE:8)
Block(-3,59,7,CONCRETE:8)
Block(-3,59,8,CONCRETE:8)
Block(-3,60,-7,DOUBLE_STEP:7)
Block(-3,60,-6,DOUBLE_STEP:7)
Block(-3,60,-5,STAINED_GLASS:11)
Block(-3,60,-4,STAINED_GLASS:15)
Block(-3,60,-3,CONCRETE_POWDER:8)
Block(-3,60,-2,STAINED_GLASS_PANE:15)
Block(-3,60,2,CONCRETE:8)
Block(-3,60,3,STAINED_GLASS_PANE:3)
Block(-3,60,4,STAINED_GLASS_PANE:3)
Block(-3,60,5,STAINED_GLASS_PANE:3)
Block(-3,60,6,STAINED_GLASS_PANE:3)
Block(-3,60,7,CONCRETE:8)
Block(-3,60,8,STAINED_GLASS_PANE:3)
Block(-3,61,-6,DOUBLE_STEP:7)
Block(-3,61,-5,STAINED_GLASS:11)
Block(-3,61,-4,STAINED_GLASS:15)
Block(-3,61,-3,CONCRETE:8)
Block(-3,61,-2,STAINED_GLASS_PANE:15)
Block(-3,61,1,CONCRETE:8)
Block(-3,61,2,CONCRETE_POWDER:8)
Block(-3,61,3,STAINED_GLASS_PANE:3)
Block(-3,61,4,STAINED_GLASS_PANE:3)
Block(-3,61,5,STAINED_GLASS_PANE:3)
Block(-3,61,6,STAINED_GLASS_PANE:3)
Block(-3,61,7,CONCRETE:8)
Block(-3,62,-6,DOUBLE_STEP:7)
Block(-3,62,-5,STAINED_GLASS:11)
Block(-3,62,-4,STAINED_GLASS:15)
Block(-3,62,-3,STAINED_GLASS:15)
Block(-3,62,-2,STAINED_GLASS_PANE:15)
Block(-3,62,1,CONCRETE_POWDER:8)
Block(-3,62,2,CONCRETE:8)
Block(-3,62,3,CONCRETE_POWDER:8)
Block(-3,62,4,STAINED_GLASS_PANE:3)
Block(-3,62,5,STAINED_GLASS_PANE:3)
Block(-3,62,6,STAINED_GLASS_PANE:3)
Block(-3,62,7,CONCRETE:8)
Block(-3,63,-5,STEP:7)
Block(-3,63,-3,STAINED_GLASS:11)
Block(-3,63,-2,STAINED_GLASS_PANE:15)
Block(-3,63,-1,STEP:8)
Block(-3,63,0,STEP:8)
Block(-3,63,1,STEP:8)
Block(-3,63,2,CONCRETE:8)
Block(-3,63,3,CONCRETE_POWDER:8)
Block(-3,63,4,STAINED_GLASS_PANE:3)
Block(-3,63,5,STAINED_GLASS_PANE:3)
Block(-3,63,6,STAINED_GLASS_PANE:3)
Block(-3,63,7,CONCRETE:8)
Block(-3,64,-4,STEP:15)
Block(-3,64,-3,STAINED_GLASS:11)
Block(-3,64,-2,STAINED_GLASS_PANE:15)
Block(-3,64,-1,CONCRETE:15)
Block(-3,64,0,CONCRETE:15)
Block(-3,64,1,CONCRETE:15)
Block(-3,64,2,CONCRETE:15)
Block(-3,64,3,CONCRETE:15)
Block(-3,64,4,CONCRETE:15)
Block(-3,64,5,STAINED_GLASS_PANE:3)
Block(-3,64,6,STAINED_GLASS_PANE:3)
Block(-3,64,7,CONCRETE:15)
Block(-3,65,-3,STAINED_GLASS:11)
Block(-3,65,-2,STAINED_GLASS_PANE:15)
Block(-3,65,-1,STEP:0)
Block(-3,65,0,STEP:0)
Block(-3,65,1,STEP:0)
Block(-3,65,2,STEP:0)
Block(-3,65,3,CONCRETE_POWDER:8)
Block(-3,65,4,CONCRETE:8)
Block(-3,65,5,CONCRETE_POWDER:8)
Block(-3,65,6,CONCRETE:8)
Block(-3,65,7,CONCRETE_POWDER:8)
Block(-3,65,8,CONCRETE:8)
Block(-3,66,-2,STAINED_GLASS_PANE:15)
Block(-3,66,3,CONCRETE:8)
Block(-3,66,4,CONCRETE_POWDER:8)
Block(-3,66,5,CONCRETE:11)
Block(-3,66,6,CONCRETE:11)
Block(-3,66,7,CONCRETE:8)
Block(-3,66,8,CONCRETE:11)
Block(-3,67,-2,STAINED_GLASS_PANE:15)
Block(-3,67,-1,STEP:8)
Block(-3,67,0,STEP:8)
Block(-3,67,1,STEP:8)
Block(-3,67,2,STEP:8)
Block(-3,67,3,STEP:8)
Block(-3,67,4,CONCRETE:8)
Block(-3,67,5,CONCRETE:8)
Block(-3,67,6,CONCRETE:8)
Block(-3,67,7,CONCRETE:8)
Block(-3,67,8,CONCRETE_POWDER:8)
Block(-3,68,-2,STAINED_GLASS_PANE:15)
Block(-3,68,-1,CONCRETE:15)
Block(-3,68,0,CONCRETE:15)
Block(-3,68,1,CONCRETE:15)
Block(-3,68,2,CONCRETE:15)
Block(-3,68,3,CONCRETE:15)
Block(-3,68,4,CONCRETE:15)
Block(-3,68,5,CONCRETE:11)
Block(-3,68,6,CONCRETE:11)
Block(-3,68,7,CONCRETE:15)
Block(-3,68,8,CONCRETE:11)
Block(-3,69,-2,STAINED_GLASS_PANE:15)
Block(-3,69,-1,STEP:0)
Block(-3,69,0,STEP:0)
Block(-3,69,1,STEP:0)
Block(-3,69,2,STEP:0)
Block(-3,69,3,STEP:0)
Block(-3,69,4,CONCRETE:8)
Block(-3,69,5,CONCRETE:8)
Block(-3,69,6,CONCRETE:8)
Block(-3,69,7,CONCRETE:8)
Block(-3,69,8,CONCRETE:8)
Block(-3,70,-2,STAINED_GLASS_PANE:15)
Block(-3,70,3,CONCRETE:8)
Block(-3,70,4,CONCRETE_POWDER:8)
Block(-3,70,5,CONCRETE:11)
Block(-3,70,6,CONCRETE:11)
Block(-3,70,7,CONCRETE:8)
Block(-3,70,8,CONCRETE:11)
Block(-3,71,-2,STAINED_GLASS_PANE:15)
Block(-3,71,-1,STEP:8)
Block(-3,71,0,STEP:8)
Block(-3,71,1,STEP:8)
Block(-3,71,2,STEP:8)
Block(-3,71,3,CONCRETE:8)
Block(-3,71,4,CONCRETE:8)
Block(-3,71,5,CONCRETE:8)
Block(-3,71,6,CONCRETE:8)
Block(-3,71,7,CONCRETE:8)
Block(-3,71,8,CONCRETE_POWDER:8)
Block(-3,72,-2,STAINED_GLASS_PANE:15)
Block(-3,72,-1,CONCRETE:15)
Block(-3,72,0,CONCRETE:15)
Block(-3,72,1,CONCRETE:15)
Block(-3,72,2,CONCRETE:15)
Block(-3,72,3,CONCRETE:15)
Block(-3,72,4,CONCRETE:15)
Block(-3,72,5,STAINED_GLASS_PANE:3)
Block(-3,72,6,STAINED_GLASS_PANE:3)
Block(-3,72,7,CONCRETE:15)
Block(-3,72,8,STAINED_GLASS_PANE:3)
Block(-3,73,-2,STAINED_GLASS_PANE:15)
Block(-3,73,-1,STEP:0)
Block(-3,73,0,STEP:0)
Block(-3,73,1,STEP:0)
Block(-3,73,2,CONCRETE:8)
Block(-3,73,3,CONCRETE_POWDER:8)
Block(-3,73,4,STAINED_GLASS_PANE:3)
Block(-3,73,5,STAINED_GLASS_PANE:3)
Block(-3,73,6,STAINED_GLASS_PANE:3)
Block(-3,73,7,CONCRETE:8)
Block(-3,73,8,STAINED_GLASS_PANE:3)
Block(-3,74,-2,STAINED_GLASS_PANE:15)
Block(-3,74,1,CONCRETE:8)
Block(-3,74,2,CONCRETE:8)
Block(-3,74,3,CONCRETE_POWDER:8)
Block(-3,74,4,STAINED_GLASS_PANE:3)
Block(-3,74,5,STAINED_GLASS_PANE:3)
Block(-3,74,6,STAINED_GLASS_PANE:3)
Block(-3,74,7,CONCRETE:8)
Block(-3,74,8,STAINED_GLASS_PANE:3)
Block(-3,75,-2,STAINED_GLASS_PANE:15)
Block(-3,75,1,CONCRETE:8)
Block(-3,75,2,CONCRETE_POWDER:8)
Block(-3,75,3,STAINED_GLASS_PANE:3)
Block(-3,75,4,STAINED_GLASS_PANE:3)
Block(-3,75,5,STAINED_GLASS_PANE:3)
Block(-3,75,6,STAINED_GLASS_PANE:3)
Block(-3,75,7,CONCRETE_POWDER:8)
Block(-3,75,8,STAINED_GLASS_PANE:3)
Block(-3,76,-2,STAINED_GLASS_PANE:15)
Block(-3,76,0,CONCRETE:8)
Block(-3,76,1,CONCRETE_POWDER:8)
Block(-3,76,2,CONCRETE:8)
Block(-3,76,3,STAINED_GLASS_PANE:3)
Block(-3,76,4,STAINED_GLASS_PANE:3)
Block(-3,76,5,STAINED_GLASS_PANE:3)
Block(-3,76,6,STAINED_GLASS_PANE:3)
Block(-3,76,7,CONCRETE:8)
Block(-3,76,8,STAINED_GLASS_PANE:3)
Block(-3,77,-2,STAINED_GLASS_PANE:15)
Block(-3,77,0,CONCRETE_POWDER:8)
Block(-3,77,1,CONCRETE_POWDER:8)
Block(-3,77,2,STAINED_GLASS_PANE:3)
Block(-3,77,3,STAINED_GLASS_PANE:3)
Block(-3,77,4,STAINED_GLASS_PANE:3)
Block(-3,77,5,STAINED_GLASS_PANE:3)
Block(-3,77,6,CONCRETE:8)
Block(-3,77,7,CONCRETE:8)
Block(-3,77,8,CONCRETE_POWDER:8)
Block(-3,78,-2,CONCRETE:7)
Block(-3,78,-1,CONCRETE:8)
Block(-3,78,0,CONCRETE_POWDER:8)
Block(-3,78,1,CONCRETE:8)
Block(-3,78,2,STAINED_GLASS_PANE:3)
Block(-3,78,3,STAINED_GLASS_PANE:3)
Block(-3,78,4,STAINED_GLASS_PANE:3)
Block(-3,78,5,STAINED_GLASS_PANE:3)
Block(-3,78,6,CONCRETE:8)
Block(-3,78,7,CONCRETE_POWDER:8)
Block(-3,78,8,CONCRETE:8)
Block(-3,79,-2,CONCRETE:7)
Block(-3,79,-1,CONCRETE_POWDER:8)
Block(-3,79,0,CONCRETE_POWDER:8)
Block(-3,79,1,STAINED_GLASS_PANE:3)
Block(-3,79,2,STAINED_GLASS_PANE:3)
Block(-3,79,3,STAINED_GLASS_PANE:3)
Block(-3,79,4,STAINED_GLASS_PANE:3)
Block(-3,79,5,CONCRETE_POWDER:8)
Block(-3,79,6,CONCRETE:8)
Block(-3,79,7,CONCRETE_POWDER:8)
Block(-3,79,8,CONCRETE:8)
Block(-3,80,-2,CONCRETE:7)
Block(-3,80,-1,CONCRETE_POWDER:8)
Block(-3,80,0,CONCRETE:8)
Block(-3,80,1,STAINED_GLASS_PANE:3)
Block(-3,80,2,STAINED_GLASS_PANE:3)
Block(-3,80,3,STAINED_GLASS_PANE:3)
Block(-3,80,4,STAINED_GLASS_PANE:3)
Block(-3,80,5,CONCRETE_POWDER:8)
Block(-3,80,6,CONCRETE:8)
Block(-3,80,7,STAINED_GLASS_PANE:3)
Block(-3,80,8,CONCRETE_POWDER:8)
Block(-3,81,-2,CONCRETE:7)
Block(-3,81,-1,CONCRETE_POWDER:8)
Block(-3,81,0,STAINED_GLASS_PANE:3)
Block(-3,81,1,STAINED_GLASS_PANE:3)
Block(-3,81,2,STAINED_GLASS_PANE:3)
Block(-3,81,3,STAINED_GLASS_PANE:3)
Block(-3,81,4,CONCRETE:8)
Block(-3,81,5,CONCRETE:8)
Block(-3,81,6,CONCRETE:8)
Block(-3,81,7,STAINED_GLASS_PANE:3)
Block(-3,81,8,CONCRETE_POWDER:8)
Block(-3,82,-2,CONCRETE:7)
Block(-3,82,-1,CONCRETE:8)
Block(-3,82,0,STAINED_GLASS_PANE:3)
Block(-3,82,1,STAINED_GLASS_PANE:3)
Block(-3,82,2,STAINED_GLASS_PANE:3)
Block(-3,82,3,STAINED_GLASS_PANE:3)
Block(-3,82,4,CONCRETE_POWDER:8)
Block(-3,82,5,CONCRETE:8)
Block(-3,82,6,STAINED_GLASS_PANE:3)
Block(-3,82,7,STAINED_GLASS_PANE:3)
Block(-3,82,8,STAINED_GLASS_PANE:3)
Block(-3,83,-2,CONCRETE:7)
Block(-3,83,-1,CONCRETE:8)
Block(-3,83,0,STAINED_GLASS_PANE:3)
Block(-3,83,1,STAINED_GLASS_PANE:3)
Block(-3,83,2,STAINED_GLASS_PANE:3)
Block(-3,83,3,STAINED_GLASS_PANE:3)
Block(-3,83,4,CONCRETE:8)
Block(-3,83,5,CONCRETE:8)
Block(-3,83,6,STAINED_GLASS_PANE:3)
Block(-3,83,7,STAINED_GLASS_PANE:3)
Block(-3,83,8,STAINED_GLASS_PANE:3)
Block(-3,84,-2,CONCRETE:7)
Block(-3,84,-1,CONCRETE:8)
Block(-3,84,0,STAINED_GLASS_PANE:3)
Block(-3,84,1,STAINED_GLASS_PANE:3)
Block(-3,84,2,STAINED_GLASS_PANE:3)
Block(-3,84,3,STAINED_GLASS_PANE:3)
Block(-3,84,4,CONCRETE:8)
Block(-3,84,5,CONCRETE:8)
Block(-3,84,6,STAINED_GLASS_PANE:3)
Block(-3,84,7,STAINED_GLASS_PANE:3)
Block(-3,84,8,STAINED_GLASS_PANE:3)
Block(-3,85,-2,CONCRETE:8)
Block(-3,85,-1,CONCRETE:8)
Block(-3,85,0,STAINED_GLASS_PANE:3)
Block(-3,85,1,STAINED_GLASS_PANE:3)
Block(-3,85,2,STAINED_GLASS_PANE:3)
Block(-3,85,3,STAINED_GLASS_PANE:3)
Block(-3,85,4,CONCRETE:8)
Block(-3,85,5,CONCRETE:8)
Block(-3,85,6,STAINED_GLASS_PANE:3)
Block(-3,85,7,STAINED_GLASS_PANE:3)
Block(-3,85,8,STAINED_GLASS_PANE:3)
Block(-3,86,-2,CONCRETE:8)
Block(-3,86,-1,CONCRETE:8)
Block(-3,86,0,STAINED_GLASS_PANE:3)
Block(-3,86,1,STAINED_GLASS_PANE:3)
Block(-3,86,2,STAINED_GLASS_PANE:3)
Block(-3,86,3,STAINED_GLASS_PANE:3)
Block(-3,86,4,CONCRETE_POWDER:8)
Block(-3,86,5,CONCRETE:8)
Block(-3,86,6,STAINED_GLASS_PANE:3)
Block(-3,86,7,STAINED_GLASS_PANE:3)
Block(-3,86,8,STAINED_GLASS_PANE:3)
Block(-3,87,-2,CONCRETE:8)
Block(-3,87,-1,CONCRETE:7)
Block(-3,87,0,STAINED_GLASS:15)
Block(-3,87,1,STAINED_GLASS:15)
Block(-3,87,2,STAINED_GLASS:15)
Block(-3,87,3,STAINED_GLASS:15)
Block(-3,87,4,CONCRETE:8)
Block(-3,87,5,CONCRETE:8)
Block(-3,87,6,STAINED_GLASS:15)
Block(-3,87,7,STAINED_GLASS:15)
Block(-3,87,8,STAINED_GLASS:15)
Block(-3,88,-2,CONCRETE_POWDER:8)
Block(-3,88,-1,CONCRETE_POWDER:8)
Block(-3,88,4,CONCRETE:8)
Block(-3,88,5,CONCRETE:8)
Block(-2,0,-7,DIRT:0)
Block(-2,0,-6,DIRT:0)
Block(-2,0,-5,DIRT:0)
Block(-2,0,-4,DIRT:0)
Block(-2,0,-3,DIRT:0)
Block(-2,0,-2,STAINED_GLASS_PANE:0)
Block(-2,0,0,CONCRETE:15)
Block(-2,0,1,CONCRETE:15)
Block(-2,0,2,CONCRETE:15)
Block(-2,0,3,CONCRETE:8)
Block(-2,0,4,CONCRETE_POWDER:8)
Block(-2,0,5,CONCRETE:8)
Block(-2,0,6,CONCRETE:8)
Block(-2,0,7,CONCRETE_POWDER:8)
Block(-2,0,8,CONCRETE:8)
Block(-2,1,-7,DIRT:0)
Block(-2,1,-6,DIRT:0)
Block(-2,1,-5,DIRT:0)
Block(-2,1,-4,DIRT:0)
Block(-2,1,-3,DIRT:0)
Block(-2,1,-2,STAINED_GLASS_PANE:0)
Block(-2,1,-1,STEP:8)
Block(-2,1,0,CONCRETE:10)
Block(-2,1,1,CONCRETE:10)
Block(-2,1,2,CONCRETE:10)
Block(-2,2,-7,DIRT:0)
Block(-2,2,-6,DIRT:0)
Block(-2,2,-5,DIRT:0)
Block(-2,2,-4,DIRT:0)
Block(-2,2,-3,DIRT:0)
Block(-2,2,-2,STAINED_GLASS_PANE:0)
Block(-2,2,-1,CONCRETE:15)
Block(-2,3,-7,DIRT:0)
Block(-2,3,-6,DIRT:0)
Block(-2,3,-5,DIRT:0)
Block(-2,3,-4,DIRT:0)
Block(-2,3,-3,DIRT:0)
Block(-2,3,-2,STAINED_GLASS_PANE:0)
Block(-2,3,-1,STEP:0)
Block(-2,3,0,CONCRETE:10)
Block(-2,3,1,CONCRETE:10)
Block(-2,4,-7,DIRT:0)
Block(-2,4,-6,DIRT:0)
Block(-2,4,-5,DIRT:0)
Block(-2,4,-4,DIRT:0)
Block(-2,4,-3,DIRT:0)
Block(-2,4,-2,STAINED_GLASS_PANE:0)
Block(-2,4,0,CONCRETE:15)
Block(-2,5,-7,DIRT:0)
Block(-2,5,-6,DIRT:0)
Block(-2,5,-5,DIRT:0)
Block(-2,5,-4,DIRT:0)
Block(-2,5,-3,DIRT:0)
Block(-2,5,-2,STAINED_GLASS_PANE:0)
Block(-2,5,0,CONCRETE:15)
Block(-2,6,-7,DIRT:0)
Block(-2,6,-6,DIRT:0)
Block(-2,6,-5,DIRT:0)
Block(-2,6,-4,DIRT:0)
Block(-2,6,-3,DIRT:0)
Block(-2,6,-2,CONCRETE:8)
Block(-2,6,-1,CONCRETE:8)
Block(-2,7,-7,DIRT:0)
Block(-2,7,-6,DIRT:0)
Block(-2,7,-5,DIRT:0)
Block(-2,7,-4,DIRT:0)
Block(-2,7,-3,DIRT:0)
Block(-2,7,-2,CONCRETE:8)
Block(-2,7,-1,CONCRETE:8)
Block(-2,8,-7,DIRT:0)
Block(-2,8,-6,DIRT:0)
Block(-2,8,-5,DIRT:0)
Block(-2,8,-4,DIRT:0)
Block(-2,8,-3,DIRT:0)
Block(-2,8,-2,CONCRETE:7)
Block(-2,8,-1,CONCRETE:8)
Block(-2,8,7,CONCRETE:8)
Block(-2,9,-7,DIRT:0)
Block(-2,9,-6,DIRT:0)
Block(-2,9,-5,DIRT:0)
Block(-2,9,-4,DIRT:0)
Block(-2,9,-3,DIRT:0)
Block(-2,9,-2,CONCRETE:8)
Block(-2,9,-1,CONCRETE:8)
Block(-2,10,-7,DIRT:0)
Block(-2,10,-6,DIRT:0)
Block(-2,10,-5,DIRT:0)
Block(-2,10,-4,DIRT:0)
Block(-2,10,-3,DIRT:0)
Block(-2,10,-2,CONCRETE:8)
Block(-2,10,-1,CONCRETE:8)
Block(-2,11,-7,DIRT:0)
Block(-2,11,-6,DIRT:0)
Block(-2,11,-5,DIRT:0)
Block(-2,11,-4,DIRT:0)
Block(-2,11,-3,DIRT:0)
Block(-2,11,-2,STAINED_GLASS_PANE:0)
Block(-2,11,-1,STAINED_GLASS_PANE:3)
Block(-2,11,0,STEP:15)
Block(-2,11,1,STEP:15)
Block(-2,11,2,STEP:15)
Block(-2,11,3,STEP:15)
Block(-2,11,4,STEP:15)
Block(-2,11,5,STEP:15)
Block(-2,11,6,STEP:15)
Block(-2,11,7,STEP:15)
Block(-2,11,8,STEP:15)
Block(-2,12,-7,DIRT:0)
Block(-2,12,-6,DIRT:0)
Block(-2,12,-5,DIRT:0)
Block(-2,12,-4,DIRT:0)
Block(-2,12,-3,DIRT:0)
Block(-2,12,-2,STAINED_GLASS_PANE:15)
Block(-2,12,-1,STAINED_GLASS_PANE:3)
Block(-2,13,-7,DIRT:0)
Block(-2,13,-6,DIRT:0)
Block(-2,13,-5,DIRT:0)
Block(-2,13,-4,DIRT:0)
Block(-2,13,-3,DIRT:0)
Block(-2,13,-2,STAINED_GLASS_PANE:15)
Block(-2,13,-1,STAINED_GLASS_PANE:3)
Block(-2,14,-7,DIRT:0)
Block(-2,14,-6,DIRT:0)
Block(-2,14,-5,DIRT:0)
Block(-2,14,-4,DIRT:0)
Block(-2,14,-3,DIRT:0)
Block(-2,14,-2,STAINED_GLASS_PANE:15)
Block(-2,14,-1,STAINED_GLASS_PANE:3)
Block(-2,15,-7,SAND:0)
Block(-2,15,-6,SAND:0)
Block(-2,15,-5,SAND:0)
Block(-2,15,-4,SAND:0)
Block(-2,15,-3,SAND:0)
Block(-2,15,-2,STAINED_GLASS_PANE:15)
Block(-2,15,-1,STAINED_GLASS_PANE:3)
Block(-2,15,0,STEP:7)
Block(-2,15,1,STEP:7)
Block(-2,15,2,STEP:7)
Block(-2,15,3,STEP:7)
Block(-2,15,4,STEP:7)
Block(-2,15,5,STEP:7)
Block(-2,15,6,STEP:7)
Block(-2,15,7,STEP:7)
Block(-2,15,8,STEP:7)
Block(-2,16,-2,STAINED_GLASS_PANE:15)
Block(-2,16,-1,STAINED_GLASS_PANE:3)
Block(-2,17,-2,STAINED_GLASS_PANE:15)
Block(-2,17,-1,STAINED_GLASS_PANE:3)
Block(-2,18,-7,CONCRETE_POWDER:8)
Block(-2,18,-6,CONCRETE:8)
Block(-2,18,-5,CONCRETE:8)
Block(-2,18,-2,STAINED_GLASS_PANE:15)
Block(-2,18,-1,STAINED_GLASS_PANE:3)
Block(-2,18,0,STEP:15)
Block(-2,18,1,STEP:15)
Block(-2,18,2,STEP:15)
Block(-2,18,3,STEP:15)
Block(-2,18,4,STEP:15)
Block(-2,18,5,STEP:15)
Block(-2,18,6,STEP:15)
Block(-2,18,7,STEP:15)
Block(-2,18,8,STEP:15)
Block(-2,19,-2,STAINED_GLASS_PANE:15)
Block(-2,19,-1,STAINED_GLASS_PANE:3)
Block(-2,20,-2,STAINED_GLASS_PANE:15)
Block(-2,20,-1,STAINED_GLASS_PANE:3)
Block(-2,21,-2,CONCRETE:8)
Block(-2,21,-1,CONCRETE_POWDER:8)
Block(-2,22,-2,CONCRETE:8)
Block(-2,22,-1,CONCRETE_POWDER:8)
Block(-2,22,0,STEP:7)
Block(-2,22,1,STEP:7)
Block(-2,22,2,STEP:7)
Block(-2,22,3,STEP:7)
Block(-2,22,4,STEP:7)
Block(-2,22,5,STEP:7)
Block(-2,22,6,STEP:7)
Block(-2,22,7,STEP:7)
Block(-2,22,8,STEP:7)
Block(-2,23,-2,CONCRETE:8)
Block(-2,23,-1,CONCRETE:8)
Block(-2,24,-2,CONCRETE:8)
Block(-2,24,-1,CONCRETE:8)
Block(-2,25,-2,CONCRETE:8)
Block(-2,25,-1,CONCRETE:8)
Block(-2,25,0,STEP:15)
Block(-2,25,1,STEP:15)
Block(-2,25,2,STEP:15)
Block(-2,25,3,STEP:15)
Block(-2,25,4,STEP:15)
Block(-2,25,5,STEP:15)
Block(-2,25,6,STEP:15)
Block(-2,25,7,STEP:15)
Block(-2,25,8,STEP:15)
Block(-2,26,-2,STAINED_GLASS_PANE:15)
Block(-2,26,0,CONCRETE:15)
Block(-2,27,-2,STAINED_GLASS_PANE:15)
Block(-2,27,0,CONCRETE:15)
Block(-2,28,-2,STAINED_GLASS_PANE:15)
Block(-2,28,-1,STEP:8)
Block(-2,28,0,CONCRETE:10)
Block(-2,28,1,CONCRETE:10)
Block(-2,29,-2,STAINED_GLASS_PANE:15)
Block(-2,29,-1,CONCRETE:15)
Block(-2,29,0,STEP:7)
Block(-2,29,1,STEP:7)
Block(-2,29,2,STEP:7)
Block(-2,29,3,STEP:7)
Block(-2,29,4,STEP:7)
Block(-2,29,5,STEP:7)
Block(-2,29,6,STEP:7)
Block(-2,29,7,STEP:7)
Block(-2,29,8,STEP:7)
Block(-2,30,-2,STAINED_GLASS_PANE:15)
Block(-2,30,-1,STEP:0)
Block(-2,30,0,CONCRETE:10)
Block(-2,30,1,CONCRETE:10)
Block(-2,30,2,CONCRETE:10)
Block(-2,31,-2,STAINED_GLASS_PANE:15)
Block(-2,31,0,CONCRETE:15)
Block(-2,31,1,CONCRETE:15)
Block(-2,31,2,CONCRETE:15)
Block(-2,32,-2,STAINED_GLASS_PANE:15)
Block(-2,32,-1,STEP:8)
Block(-2,32,0,CONCRETE:10)
Block(-2,32,1,CONCRETE:10)
Block(-2,32,2,CONCRETE:10)
Block(-2,32,3,CONCRETE:10)
Block(-2,33,-2,STAINED_GLASS_PANE:15)
Block(-2,33,-1,CONCRETE:15)
Block(-2,34,-2,STAINED_GLASS_PANE:15)
Block(-2,34,-1,STEP:0)
Block(-2,34,0,CONCRETE:10)
Block(-2,34,1,CONCRETE:10)
Block(-2,34,2,CONCRETE:10)
Block(-2,34,3,CONCRETE:10)
Block(-2,35,-2,STAINED_GLASS_PANE:15)
Block(-2,35,0,CONCRETE:15)
Block(-2,35,1,CONCRETE:15)
Block(-2,35,2,CONCRETE:15)
Block(-2,36,-2,STAINED_GLASS_PANE:15)
Block(-2,36,-1,STEP:8)
Block(-2,36,0,CONCRETE:10)
Block(-2,36,1,CONCRETE:10)
Block(-2,36,2,CONCRETE:10)
Block(-2,37,-2,STAINED_GLASS_PANE:15)
Block(-2,37,-1,CONCRETE:15)
Block(-2,38,-2,STAINED_GLASS_PANE:15)
Block(-2,38,-1,STEP:0)
Block(-2,38,0,CONCRETE:10)
Block(-2,38,1,CONCRETE:10)
Block(-2,39,-2,STAINED_GLASS_PANE:15)
Block(-2,39,0,CONCRETE:15)
