
#######################################################################
# +-----------------------------------------------------------------+ #
# |                            BO4 object                           | #
# +-----------------------------------------------------------------+ #
#######################################################################

Author: NLBlackEagle

Description: No description given

SettingsMode: WriteWithoutComments


#######################################################################
# +-----------------------------------------------------------------+ #
# |                          Main settings                          | #
# +-----------------------------------------------------------------+ #
#######################################################################

Frequency: 0

SpawnHeight: highestBlock

UseCenterForHighestBlock: true

##############################
# Height Limits for the BO4. #
##############################

MinHeight: 0

MaxHeight: 255

InheritBO3: 

InheritBO3Rotation: NORTH

OverrideChildSettings: true

OverrideParentHeight: false

CanOverride: false

BranchFrequency: 0

BranchFrequencyGroup: 

MustBeBelowOther: false

MustBeInside: 

CannotBeInside: 

ReplacesBO3: 

MustBeInsideWorldBorders: false

CanSpawnOnWater: true

SpawnOnWaterOnly: false

SpawnUnderWater: false

SpawnAtWaterLevel: false

HeightOffset: 0

RemoveAir: true

ReplaceAbove: 

ReplaceBelow: 

ReplaceWithBiomeBlocks: true

ReplaceWithSurfaceBlock: GRASS

ReplaceWithGroundBlock: DIRT

ReplaceWithStoneBlock: STONE

SmoothRadius: 0

SmoothHeightOffset: 0

SmoothStartTop: false

SmoothStartWood: false

SmoothingSurfaceBlock: 

SmoothingGroundBlock: 

BO3Group: 

IsSpawnPoint: false

DoReplaceBlocks: true


#######################################################################
# +-----------------------------------------------------------------+ #
# |                              Blocks                             | #
# +-----------------------------------------------------------------+ #
#######################################################################

Block(-8,0,-7,STONE:0)
Block(-8,0,-6,STONE:0)
Block(-8,0,-5,STONE:0)
Block(-8,0,-4,STONE:0)
Block(-8,0,-3,STONE:0)
Block(-8,0,-2,STONE:0)
Block(-8,0,-1,STONE:0)
Block(-8,0,0,STONE:0)
Block(-8,0,1,STONE:0)
Block(-8,0,2,STONE:0)
Block(-8,0,3,STONE:0)
Block(-8,0,4,STONE:0)
Block(-8,0,5,STONE:0)
Block(-8,0,6,STONE:0)
Block(-8,0,7,SANDSTONE:0)
Block(-8,0,8,STONE:0)
Block(-8,1,-7,STONE:0)
Block(-8,1,-6,STONE:0)
Block(-8,1,-5,STONE:0)
Block(-8,1,-4,STONE:0)
Block(-8,1,-3,STONE:0)
Block(-8,1,-2,STONE:0)
Block(-8,1,-1,STONE:0)
Block(-8,1,0,STONE:0)
Block(-8,1,1,STONE:0)
Block(-8,1,2,STONE:0)
Block(-8,1,3,STATIONARY_WATER:0)
Block(-8,1,4,STATIONARY_WATER:0)
Block(-8,1,5,STATIONARY_WATER:0)
Block(-8,1,6,STATIONARY_WATER:0)
Block(-8,1,7,STATIONARY_WATER:0)
Block(-8,1,8,SANDSTONE:0)
Block(-8,2,-7,GRASS:0)
Block(-8,2,-6,GRASS:0)
Block(-8,2,-5,GRASS:0)
Block(-8,2,-4,GRASS:0)
Block(-8,2,-3,STATIONARY_WATER:0)
Block(-8,2,-2,STONE:0)
Block(-8,2,-1,STATIONARY_WATER:0)
Block(-8,2,0,STATIONARY_WATER:0)
Block(-8,2,1,STATIONARY_WATER:0)
Block(-8,2,2,STATIONARY_WATER:0)
Block(-8,2,3,STATIONARY_WATER:0)
Block(-8,2,4,STATIONARY_WATER:0)
Block(-8,2,5,STATIONARY_WATER:0)
Block(-8,2,6,STATIONARY_WATER:0)
Block(-8,2,7,STATIONARY_WATER:0)
Block(-8,2,8,STATIONARY_WATER:0)
Block(-8,17,-3,STONE:0)
Block(-8,17,-2,STONE:0)
Block(-8,17,4,STONE:0)
Block(-8,18,-7,STONE:0)
Block(-8,18,-6,STONE:0)
Block(-8,18,-5,STONE:0)
Block(-8,18,-4,STONE:0)
Block(-8,18,-3,STONE:0)
Block(-8,18,-2,STONE:0)
Block(-8,18,2,STONE:0)
Block(-8,18,3,STONE:0)
Block(-8,18,4,STONE:0)
Block(-8,19,-7,STONE:0)
Block(-8,19,-6,STONE:0)
Block(-8,19,-5,STONE:0)
Block(-8,19,-4,STONE:0)
Block(-8,19,-3,STONE:0)
Block(-8,19,-2,STONE:0)
Block(-8,19,-1,STONE:0)
Block(-8,19,0,STONE:0)
Block(-8,19,1,STONE:0)
Block(-8,19,2,STONE:0)
Block(-8,19,3,STONE:0)
Block(-8,19,4,STONE:0)
Block(-8,19,5,STONE:0)
Block(-8,20,-7,SANDSTONE:0)
Block(-8,20,-6,SANDSTONE:0)
Block(-8,20,-5,STONE:0)
Block(-8,20,-4,STONE:0)
Block(-8,20,-3,STONE:0)
Block(-8,20,-2,STONE:0)
Block(-8,20,-1,SANDSTONE:0)
Block(-8,20,0,SANDSTONE:0)
Block(-8,20,1,SANDSTONE:0)
Block(-8,20,2,SANDSTONE:0)
Block(-8,20,3,SANDSTONE:0)
Block(-8,20,4,SANDSTONE:0)
Block(-8,20,5,SANDSTONE:0)
Block(-8,20,6,SANDSTONE:0)
Block(-8,21,-7,SANDSTONE:0)
Block(-8,21,-6,SANDSTONE:0)
Block(-8,21,-5,SANDSTONE:0)
Block(-8,21,-4,SANDSTONE:0)
Block(-8,21,-3,SANDSTONE:0)
Block(-8,21,-2,SANDSTONE:0)
Block(-7,0,-7,STONE:0)
Block(-7,0,-6,STONE:0)
Block(-7,0,-5,STONE:0)
Block(-7,0,-4,STONE:0)
Block(-7,0,-3,STONE:0)
Block(-7,0,-2,STONE:0)
Block(-7,0,-1,STONE:0)
Block(-7,0,0,STONE:0)
Block(-7,0,1,STONE:0)
Block(-7,0,2,STONE:0)
Block(-7,0,3,STONE:0)
Block(-7,0,4,STONE:0)
Block(-7,0,5,STONE:0)
Block(-7,0,6,STONE:0)
Block(-7,0,7,STONE:0)
Block(-7,0,8,STONE:0)
Block(-7,1,-7,STONE:0)
Block(-7,1,-6,STONE:0)
Block(-7,1,-5,STONE:0)
Block(-7,1,-4,STONE:0)
Block(-7,1,-3,STONE:0)
Block(-7,1,-2,STONE:0)
Block(-7,1,-1,STONE:0)
Block(-7,1,0,STONE:0)
Block(-7,1,1,STONE:0)
Block(-7,1,2,STONE:0)
Block(-7,1,3,STATIONARY_WATER:0)
Block(-7,1,4,STATIONARY_WATER:0)
Block(-7,1,5,STONE:0)
Block(-7,1,6,STONE:0)
Block(-7,1,7,STONE:0)
Block(-7,1,8,STONE:0)
Block(-7,2,-7,GRASS:0)
Block(-7,2,-6,GRASS:0)
Block(-7,2,-5,GRASS:0)
Block(-7,2,-4,GRASS:0)
Block(-7,2,-3,STATIONARY_WATER:0)
Block(-7,2,-2,STATIONARY_WATER:0)
Block(-7,2,-1,STATIONARY_WATER:0)
Block(-7,2,0,STATIONARY_WATER:0)
Block(-7,2,1,STATIONARY_WATER:0)
Block(-7,2,2,STATIONARY_WATER:0)
Block(-7,2,3,STATIONARY_WATER:0)
Block(-7,2,4,STATIONARY_WATER:0)
Block(-7,2,5,STATIONARY_WATER:0)
Block(-7,2,6,STATIONARY_WATER:0)
Block(-7,2,7,SANDSTONE:0)
Block(-7,2,8,STONE:6)
Block(-7,3,8,STONE:6)
Block(-7,4,8,STONE:6)
Block(-7,5,8,STONE:6)
Block(-7,6,8,STONE:6)
Block(-7,7,8,STONE:6)
Block(-7,8,8,STONE:6)
Block(-7,9,8,STONE:6)
Block(-7,10,8,STONE:6)
Block(-7,11,8,STONE:6)
Block(-7,17,-3,STONE:0)
Block(-7,17,-2,STONE:0)
Block(-7,17,-1,STONE:0)
Block(-7,17,2,STONE:0)
Block(-7,17,3,STONE:0)
Block(-7,17,4,STONE:0)
Block(-7,18,-7,STONE:0)
Block(-7,18,-6,STONE:0)
Block(-7,18,-5,STONE:0)
Block(-7,18,-4,STONE:0)
Block(-7,18,-3,STONE:0)
Block(-7,18,-2,STONE:0)
Block(-7,18,-1,STONE:0)
Block(-7,18,0,STONE:0)
Block(-7,18,1,STONE:0)
Block(-7,18,2,STONE:0)
Block(-7,18,3,STONE:0)
Block(-7,18,4,STONE:0)
Block(-7,18,5,STONE:0)
Block(-7,19,-7,STONE:0)
Block(-7,19,-6,STONE:0)
Block(-7,19,-5,STONE:0)
Block(-7,19,-4,STONE:0)
Block(-7,19,-3,STONE:0)
Block(-7,19,-2,STONE:0)
Block(-7,19,-1,STONE:0)
Block(-7,19,0,STONE:0)
Block(-7,19,1,STONE:0)
Block(-7,19,2,STONE:0)
Block(-7,19,3,STONE:0)
Block(-7,19,4,STONE:0)
Block(-7,19,5,STONE:0)
Block(-7,19,6,SANDSTONE:0)
Block(-7,20,-7,SANDSTONE:0)
Block(-7,20,-6,SANDSTONE:0)
Block(-7,20,-5,STONE:0)
Block(-7,20,-4,STONE:0)
Block(-7,20,-3,STONE:0)
Block(-7,20,-2,STONE:0)
Block(-7,20,-1,STONE:0)
Block(-7,20,0,STONE:0)
Block(-7,20,1,STONE:0)
Block(-7,20,2,STONE:0)
Block(-7,20,3,SANDSTONE:0)
Block(-7,20,4,SANDSTONE:0)
Block(-7,20,5,SANDSTONE:0)
Block(-7,21,-6,SANDSTONE:0)
Block(-7,21,-5,SANDSTONE:0)
Block(-7,21,-4,SANDSTONE:0)
Block(-7,21,-3,SANDSTONE:0)
Block(-7,21,-2,SANDSTONE:0)
Block(-7,21,-1,SANDSTONE:0)
Block(-7,21,0,SANDSTONE:0)
Block(-7,21,1,SANDSTONE:0)
Block(-7,21,2,SANDSTONE:0)
Block(-6,0,-7,STONE:0)
Block(-6,0,-6,STONE:0)
Block(-6,0,-5,STONE:0)
Block(-6,0,-4,STONE:0)
Block(-6,0,-3,STONE:0)
Block(-6,0,-2,STONE:0)
Block(-6,0,-1,STONE:0)
Block(-6,0,0,STONE:0)
Block(-6,0,1,STONE:0)
Block(-6,0,2,STONE:0)
Block(-6,0,3,STONE:0)
Block(-6,0,4,STONE:0)
Block(-6,0,5,STONE:0)
Block(-6,0,6,STONE:0)
Block(-6,0,7,STONE:0)
Block(-6,0,8,STONE:0)
Block(-6,1,-7,STONE:0)
Block(-6,1,-6,STONE:0)
Block(-6,1,-5,STONE:0)
Block(-6,1,-4,STONE:0)
Block(-6,1,-3,STONE:0)
Block(-6,1,-2,STONE:0)
Block(-6,1,-1,STONE:0)
Block(-6,1,0,STONE:0)
Block(-6,1,1,STONE:0)
Block(-6,1,2,STONE:0)
Block(-6,1,3,STONE:0)
Block(-6,1,4,STATIONARY_WATER:0)
Block(-6,1,5,STONE:0)
Block(-6,1,6,STONE:0)
Block(-6,1,7,STONE:0)
Block(-6,1,8,STONE:0)
Block(-6,2,-7,GRASS:0)
Block(-6,2,-6,GRASS:0)
Block(-6,2,-5,GRASS:0)
Block(-6,2,-4,GRASS:0)
Block(-6,2,-3,STATIONARY_WATER:0)
Block(-6,2,-2,STATIONARY_WATER:0)
Block(-6,2,-1,STATIONARY_WATER:0)
Block(-6,2,0,STATIONARY_WATER:0)
Block(-6,2,1,STATIONARY_WATER:0)
Block(-6,2,2,STATIONARY_WATER:0)
Block(-6,2,3,STATIONARY_WATER:0)
Block(-6,2,4,STATIONARY_WATER:0)
Block(-6,2,5,STATIONARY_WATER:0)
Block(-6,2,6,SANDSTONE:0)
Block(-6,2,7,STONE:0)
Block(-6,2,8,STONE:0)
Block(-6,3,7,STONE:0)
Block(-6,3,8,STONE:6)
Block(-6,4,8,STONE:6)
Block(-6,5,8,STONE:6)
Block(-6,6,8,STONE:6)
Block(-6,7,8,STONE:6)
Block(-6,8,8,STONE:6)
Block(-6,9,8,STONE:6)
Block(-6,10,8,STONE:6)
Block(-6,11,8,STONE:6)
Block(-6,17,-7,STONE:0)
Block(-6,17,-6,STONE:0)
Block(-6,17,-5,STONE:0)
Block(-6,17,-3,STONE:0)
Block(-6,17,-2,STONE:0)
Block(-6,17,-1,STONE:0)
Block(-6,18,-7,STONE:0)
Block(-6,18,-6,STONE:0)
Block(-6,18,-5,STONE:0)
Block(-6,18,-4,STONE:0)
Block(-6,18,-3,STONE:0)
Block(-6,18,-2,STONE:0)
Block(-6,18,-1,STONE:0)
Block(-6,18,0,STONE:0)
Block(-6,18,1,STONE:0)
Block(-6,18,2,STONE:0)
Block(-6,18,3,STONE:0)
Block(-6,18,5,SANDSTONE:0)
Block(-6,19,-7,STONE:0)
Block(-6,19,-6,STONE:0)
Block(-6,19,-5,STONE:0)
Block(-6,19,-4,STONE:0)
Block(-6,19,-3,STONE:0)
Block(-6,19,-2,STONE:0)
Block(-6,19,-1,STONE:0)
Block(-6,19,0,STONE:0)
Block(-6,19,1,STONE:0)
Block(-6,19,2,STONE:0)
Block(-6,19,3,STONE:0)
Block(-6,19,4,STONE:0)
Block(-6,20,-7,SANDSTONE:0)
Block(-6,20,-6,SANDSTONE:0)
Block(-6,20,-5,STONE:0)
Block(-6,20,-4,STONE:0)
Block(-6,20,-3,STONE:0)
Block(-6,20,-2,STONE:0)
Block(-6,20,-1,STONE:0)
Block(-6,20,0,STONE:0)
Block(-6,20,1,STONE:0)
Block(-6,20,2,STONE:0)
Block(-6,20,3,STONE:0)
Block(-6,20,4,SANDSTONE:0)
Block(-6,21,-5,SANDSTONE:0)
Block(-6,21,-4,SANDSTONE:0)
Block(-6,21,-3,SANDSTONE:0)
Block(-6,21,-2,SANDSTONE:0)
Block(-6,21,-1,SANDSTONE:0)
Block(-6,21,0,SANDSTONE:0)
Block(-6,21,1,SANDSTONE:0)
Block(-6,21,2,SANDSTONE:0)
Block(-6,21,3,SANDSTONE:0)
Block(-5,0,-7,STONE:0)
Block(-5,0,-6,STONE:0)
Block(-5,0,-5,STONE:0)
Block(-5,0,-4,STONE:0)
Block(-5,0,-3,STONE:0)
Block(-5,0,-2,STONE:0)
Block(-5,0,-1,STONE:0)
Block(-5,0,0,STONE:0)
Block(-5,0,1,STONE:0)
Block(-5,0,2,STONE:0)
Block(-5,0,3,STONE:0)
Block(-5,0,4,STONE:0)
Block(-5,0,5,STONE:0)
Block(-5,0,6,STONE:0)
Block(-5,0,7,STONE:0)
Block(-5,0,8,STONE:0)
Block(-5,1,-7,STONE:0)
Block(-5,1,-6,STONE:0)
Block(-5,1,-5,STONE:0)
Block(-5,1,-4,STONE:0)
Block(-5,1,-3,GRASS:0)
Block(-5,1,-2,STONE:0)
Block(-5,1,-1,STONE:0)
Block(-5,1,0,STONE:0)
Block(-5,1,1,STONE:0)
Block(-5,1,2,STONE:0)
Block(-5,1,3,STONE:0)
Block(-5,1,4,STONE:0)
Block(-5,1,5,STONE:0)
Block(-5,1,6,STONE:0)
Block(-5,1,7,STONE:0)
Block(-5,1,8,STONE:0)
Block(-5,2,-7,GRASS:0)
Block(-5,2,-6,GRASS:0)
Block(-5,2,-5,GRASS:0)
Block(-5,2,-4,GRASS:0)
Block(-5,2,-3,STATIONARY_WATER:0)
Block(-5,2,-2,STATIONARY_WATER:0)
Block(-5,2,-1,STATIONARY_WATER:0)
Block(-5,2,0,STATIONARY_WATER:0)
Block(-5,2,1,STATIONARY_WATER:0)
Block(-5,2,2,STATIONARY_WATER:0)
Block(-5,2,3,STATIONARY_WATER:0)
Block(-5,2,4,STATIONARY_WATER:0)
Block(-5,2,5,SANDSTONE:0)
Block(-5,2,6,STONE:0)
Block(-5,2,7,STONE:0)
Block(-5,2,8,STONE:0)
Block(-5,3,6,SANDSTONE:0)
Block(-5,3,7,STONE:6)
Block(-5,3,8,STONE:6)
Block(-5,4,7,STONE:6)
Block(-5,4,8,STONE:6)
Block(-5,5,7,STONE:6)
Block(-5,5,8,STONE:6)
Block(-5,6,7,STONE:6)
Block(-5,6,8,STONE:6)
Block(-5,7,7,STONE:6)
Block(-5,7,8,STONE:6)
Block(-5,8,7,STONE:6)
Block(-5,8,8,STONE:6)
Block(-5,9,7,STONE:6)
Block(-5,9,8,STONE:6)
Block(-5,10,7,STONE:6)
Block(-5,10,8,STONE:6)
Block(-5,11,7,STONE:6)
Block(-5,11,8,STONE:6)
Block(-5,17,-7,STONE:0)
Block(-5,17,-6,STONE:0)
Block(-5,17,-5,STONE:0)
Block(-5,18,-7,STONE:0)
Block(-5,18,-6,STONE:0)
Block(-5,18,-5,STONE:0)
Block(-5,18,-4,STONE:0)
Block(-5,18,-3,STONE:0)
Block(-5,18,-2,STONE:0)
Block(-5,18,-1,STONE:0)
Block(-5,18,0,STONE:0)
Block(-5,18,1,STONE:0)
Block(-5,18,2,STONE:0)
Block(-5,18,3,STONE:0)
Block(-5,19,-7,STONE:0)
Block(-5,19,-6,STONE:0)
Block(-5,19,-5,STONE:0)
Block(-5,19,-4,STONE:0)
Block(-5,19,-3,STONE:0)
Block(-5,19,-2,STONE:0)
Block(-5,19,-1,STONE:0)
Block(-5,19,0,STONE:0)
Block(-5,19,1,STONE:0)
Block(-5,19,2,STONE:0)
Block(-5,19,3,STONE:0)
Block(-5,20,-7,SANDSTONE:0)
Block(-5,20,-6,SANDSTONE:0)
Block(-5,20,-5,STONE:0)
Block(-5,20,-4,STONE:0)
Block(-5,20,-3,STONE:0)
Block(-5,20,-2,STONE:0)
Block(-5,20,-1,STONE:0)
Block(-5,20,0,STONE:0)
Block(-5,20,1,STONE:0)
Block(-5,20,2,STONE:0)
Block(-5,20,3,STONE:0)
Block(-5,20,4,SANDSTONE:0)
Block(-5,21,-5,SANDSTONE:0)
Block(-5,21,-4,SANDSTONE:0)
Block(-5,21,-3,SANDSTONE:0)
Block(-5,21,-2,SANDSTONE:0)
Block(-5,21,-1,SANDSTONE:0)
Block(-5,21,0,SANDSTONE:0)
Block(-5,21,1,SANDSTONE:0)
Block(-5,21,2,SANDSTONE:0)
Block(-5,21,3,SANDSTONE:0)
Block(-4,0,-7,STONE:0)
Block(-4,0,-6,STONE:0)
Block(-4,0,-5,STONE:0)
Block(-4,0,-4,STONE:0)
Block(-4,0,-3,STONE:0)
Block(-4,0,-2,STONE:0)
Block(-4,0,-1,STONE:0)
Block(-4,0,0,STONE:0)
Block(-4,0,1,STONE:0)
Block(-4,0,2,STONE:0)
Block(-4,0,3,STONE:0)
Block(-4,0,4,STONE:0)
Block(-4,0,5,STONE:0)
Block(-4,0,6,STONE:0)
Block(-4,0,7,STONE:0)
Block(-4,0,8,STONE:0)
Block(-4,1,-7,STONE:0)
Block(-4,1,-6,STONE:0)
Block(-4,1,-5,STONE:0)
Block(-4,1,-4,STONE:0)
Block(-4,1,-3,STONE:0)
Block(-4,1,-2,STONE:0)
Block(-4,1,-1,STONE:0)
Block(-4,1,0,STONE:0)
Block(-4,1,1,STONE:0)
Block(-4,1,2,STONE:0)
Block(-4,1,3,STONE:0)
Block(-4,1,4,STONE:0)
Block(-4,1,5,STONE:0)
Block(-4,1,6,STONE:0)
Block(-4,1,7,STONE:0)
Block(-4,1,8,STONE:0)
Block(-4,2,-7,STONE:0)
Block(-4,2,-6,GRASS:0)
Block(-4,2,-5,GRASS:0)
Block(-4,2,-4,GRASS:0)
Block(-4,2,-3,GRASS:0)
Block(-4,2,-2,STONE:0)
Block(-4,2,-1,STATIONARY_WATER:0)
Block(-4,2,0,STATIONARY_WATER:0)
Block(-4,2,1,STATIONARY_WATER:0)
Block(-4,2,2,STONE:0)
Block(-4,2,3,STONE:0)
Block(-4,2,4,STONE:0)
Block(-4,2,5,SANDSTONE:0)
Block(-4,2,6,STONE:0)
Block(-4,2,7,STONE:0)
Block(-4,2,8,STONE:0)
Block(-4,3,-7,STONE:0)
Block(-4,3,6,SANDSTONE:0)
Block(-4,3,7,STONE:6)
Block(-4,3,8,STONE:6)
Block(-4,4,7,STONE:6)
Block(-4,4,8,STONE:6)
Block(-4,5,7,STONE:6)
Block(-4,5,8,STONE:6)
Block(-4,6,7,STONE:6)
Block(-4,6,8,STONE:6)
Block(-4,7,7,STONE:6)
Block(-4,7,8,STONE:6)
Block(-4,8,7,STONE:6)
Block(-4,8,8,STONE:6)
Block(-4,9,7,STONE:6)
Block(-4,9,8,STONE:6)
Block(-4,10,7,STONE:6)
Block(-4,10,8,STONE:6)
Block(-4,11,7,STONE:6)
Block(-4,11,8,STONE:0)
Block(-4,12,8,STONE:6)
Block(-4,13,8,STONE:6)
Block(-4,14,8,STONE:6)
Block(-4,15,8,STONE:6)
Block(-4,16,8,STONE:6)
Block(-4,17,-7,STONE:0)
Block(-4,17,-6,STONE:0)
Block(-4,17,-5,STONE:0)
Block(-4,17,0,STONE:0)
Block(-4,17,1,STONE:0)
Block(-4,17,2,STONE:0)
Block(-4,17,8,STONE:6)
Block(-4,18,-7,STONE:0)
Block(-4,18,-6,STONE:0)
Block(-4,18,-5,STONE:0)
Block(-4,18,-4,STONE:0)
Block(-4,18,-1,STONE:0)
Block(-4,18,0,STONE:0)
Block(-4,18,1,STONE:0)
Block(-4,18,2,STONE:0)
Block(-4,18,3,STONE:0)
Block(-4,18,8,STONE:6)
Block(-4,19,-7,STONE:0)
Block(-4,19,-6,STONE:0)
Block(-4,19,-5,STONE:0)
Block(-4,19,-4,STONE:0)
Block(-4,19,-3,STONE:0)
Block(-4,19,-2,STONE:0)
Block(-4,19,-1,STONE:0)
Block(-4,19,0,STONE:0)
Block(-4,19,1,STONE:0)
Block(-4,19,2,STONE:0)
Block(-4,19,3,STONE:0)
Block(-4,19,4,STONE:0)
Block(-4,19,8,STONE:6)
Block(-4,20,-7,SANDSTONE:0)
Block(-4,20,-6,SANDSTONE:0)
Block(-4,20,-5,STONE:0)
Block(-4,20,-4,STONE:0)
Block(-4,20,-3,STONE:0)
Block(-4,20,-2,STONE:0)
Block(-4,20,-1,STONE:0)
Block(-4,20,0,STONE:0)
Block(-4,20,1,STONE:0)
Block(-4,20,2,STONE:0)
Block(-4,20,3,STONE:0)
Block(-4,20,4,STONE:0)
Block(-4,20,8,STONE:6)
Block(-4,21,-5,SANDSTONE:0)
Block(-4,21,-4,SANDSTONE:0)
Block(-4,21,-3,SANDSTONE:0)
Block(-4,21,-2,SANDSTONE:0)
Block(-4,21,-1,SANDSTONE:0)
Block(-4,21,0,SANDSTONE:0)
Block(-4,21,1,SANDSTONE:0)
Block(-4,21,2,SANDSTONE:0)
Block(-4,21,3,SANDSTONE:0)
Block(-4,21,4,SANDSTONE:0)
Block(-4,21,8,STONE:6)
Block(-3,0,-7,STONE:0)
Block(-3,0,-6,STONE:0)
Block(-3,0,-5,STONE:0)
Block(-3,0,-4,STONE:0)
Block(-3,0,-3,STONE:0)
Block(-3,0,-2,STONE:0)
Block(-3,0,-1,STONE:0)
Block(-3,0,0,STONE:0)
Block(-3,0,1,STONE:0)
Block(-3,0,2,STONE:0)
Block(-3,0,3,STONE:0)
Block(-3,0,4,STONE:0)
Block(-3,0,5,STONE:0)
Block(-3,0,6,STONE:0)
Block(-3,0,7,STONE:0)
Block(-3,0,8,STONE:0)
Block(-3,1,-7,STONE:0)
Block(-3,1,-6,STONE:0)
Block(-3,1,-5,STONE:0)
Block(-3,1,-4,STONE:0)
Block(-3,1,-3,STONE:0)
Block(-3,1,-2,STONE:0)
Block(-3,1,-1,STONE:0)
Block(-3,1,0,STONE:0)
Block(-3,1,1,STONE:0)
Block(-3,1,2,STONE:0)
Block(-3,1,3,STONE:0)
Block(-3,1,4,STONE:0)
Block(-3,1,5,STONE:0)
Block(-3,1,6,STONE:0)
Block(-3,1,7,STONE:0)
Block(-3,1,8,STONE:0)
Block(-3,2,-7,STONE:0)
Block(-3,2,-6,STONE:0)
Block(-3,2,-5,GRASS:0)
Block(-3,2,-4,GRASS:0)
Block(-3,2,-3,GRASS:0)
Block(-3,2,-2,STONE:0)
Block(-3,2,-1,STONE:0)
Block(-3,2,0,STATIONARY_WATER:0)
Block(-3,2,1,STONE:0)
Block(-3,2,2,STONE:0)
Block(-3,2,3,STONE:0)
Block(-3,2,4,STONE:0)
Block(-3,2,5,STONE:0)
Block(-3,2,6,STONE:0)
Block(-3,2,7,STONE:0)
Block(-3,2,8,STONE:0)
Block(-3,3,-7,STONE:0)
Block(-3,3,-6,STONE:0)
Block(-3,3,5,STONE:0)
Block(-3,3,6,STONE:6)
Block(-3,3,7,STONE:6)
Block(-3,3,8,STONE:0)
Block(-3,4,-7,STONE:0)
Block(-3,4,6,STONE:6)
Block(-3,4,7,STONE:6)
Block(-3,4,8,STONE:6)
Block(-3,5,6,STONE:6)
Block(-3,5,7,STONE:6)
Block(-3,5,8,STONE:6)
Block(-3,6,6,STONE:6)
Block(-3,6,7,STONE:6)
Block(-3,6,8,STONE:6)
Block(-3,7,6,STONE:6)
Block(-3,7,7,STONE:6)
Block(-3,7,8,STONE:6)
Block(-3,8,6,STONE:6)
Block(-3,8,7,STONE:6)
Block(-3,8,8,STONE:6)
Block(-3,9,6,STONE:6)
Block(-3,9,7,STONE:6)
Block(-3,9,8,STONE:6)
Block(-3,10,6,STONE:6)
Block(-3,10,7,STONE:6)
Block(-3,10,8,STONE:6)
Block(-3,11,6,STONE:6)
Block(-3,11,7,STONE:6)
Block(-3,11,8,STONE:6)
Block(-3,16,-7,STONE:0)
Block(-3,16,-5,STONE:0)
Block(-3,17,-7,STONE:0)
Block(-3,17,-6,STONE:0)
Block(-3,17,-5,STONE:0)
Block(-3,17,0,STONE:0)
Block(-3,17,1,STONE:0)
Block(-3,17,2,STONE:0)
Block(-3,18,-7,STONE:0)
Block(-3,18,-6,STONE:0)
Block(-3,18,-5,STONE:0)
Block(-3,18,-1,STONE:0)
Block(-3,18,0,STONE:0)
Block(-3,18,1,STONE:0)
Block(-3,18,2,STONE:0)
Block(-3,18,3,STONE:0)
Block(-3,19,-7,STONE:0)
Block(-3,19,-6,STONE:0)
Block(-3,19,-5,STONE:0)
Block(-3,19,-4,STONE:0)
Block(-3,19,-3,STONE:0)
Block(-3,19,-2,STONE:0)
Block(-3,19,-1,STONE:0)
Block(-3,19,0,STONE:0)
Block(-3,19,1,STONE:0)
Block(-3,19,2,STONE:0)
Block(-3,19,3,STONE:0)
Block(-3,19,4,STONE:0)
Block(-3,20,-7,SANDSTONE:0)
Block(-3,20,-6,STONE:0)
Block(-3,20,-5,STONE:0)
Block(-3,20,-4,STONE:0)
Block(-3,20,-3,STONE:0)
Block(-3,20,-2,STONE:0)
Block(-3,20,-1,STONE:0)
Block(-3,20,0,STONE:0)
Block(-3,20,1,STONE:0)
Block(-3,20,2,STONE:0)
Block(-3,20,3,STONE:0)
Block(-3,20,4,STONE:0)
Block(-3,20,5,SANDSTONE:0)
Block(-3,21,-6,SANDSTONE:0)
Block(-3,21,-5,SANDSTONE:0)
Block(-3,21,-4,SANDSTONE:0)
Block(-3,21,-3,SANDSTONE:0)
Block(-3,21,-2,SANDSTONE:0)
Block(-3,21,-1,SANDSTONE:0)
Block(-3,21,0,SANDSTONE:0)
Block(-3,21,1,SANDSTONE:0)
Block(-3,21,2,SANDSTONE:0)
Block(-3,21,3,SANDSTONE:0)
Block(-3,21,4,SANDSTONE:0)
Block(-3,21,8,STONE:6)
Block(-3,22,8,STEP:0)
Block(-2,0,-7,STONE:0)
Block(-2,0,-6,DIRT:0)
Block(-2,0,-5,DIRT:0)
Block(-2,0,-4,STONE:0)
Block(-2,0,-3,STONE:0)
Block(-2,0,-2,STONE:0)
Block(-2,0,-1,STONE:0)
Block(-2,0,0,STONE:0)
Block(-2,0,1,STONE:0)
Block(-2,0,2,STONE:0)
Block(-2,0,3,STONE:0)
Block(-2,0,4,STONE:0)
Block(-2,0,5,STONE:0)
Block(-2,0,6,STONE:0)
Block(-2,0,7,STONE:0)
Block(-2,0,8,STONE:0)
Block(-2,1,-7,STONE:0)
Block(-2,1,-6,STONE:0)
Block(-2,1,-5,STONE:0)
Block(-2,1,-4,STONE:0)
Block(-2,1,-3,STONE:0)
Block(-2,1,-2,STONE:0)
Block(-2,1,-1,STONE:0)
Block(-2,1,0,STONE:0)
Block(-2,1,1,STONE:0)
Block(-2,1,2,STONE:0)
Block(-2,1,3,STONE:0)
Block(-2,1,4,STONE:0)
Block(-2,1,5,STONE:0)
Block(-2,1,6,STONE:0)
Block(-2,1,7,STONE:0)
Block(-2,1,8,STONE:0)
Block(-2,2,-7,STONE:0)
Block(-2,2,-6,STONE:0)
Block(-2,2,-5,STONE:0)
Block(-2,2,-4,GRASS:0)
Block(-2,2,-3,GRASS:0)
Block(-2,2,-2,STATIONARY_WATER:0)
Block(-2,2,-1,STATIONARY_WATER:0)
Block(-2,2,0,STATIONARY_WATER:0)
Block(-2,2,1,STATIONARY_WATER:0)
Block(-2,2,2,STATIONARY_WATER:0)
Block(-2,2,3,STATIONARY_WATER:0)
Block(-2,2,4,STONE:0)
Block(-2,2,5,SANDSTONE:0)
Block(-2,2,6,STONE:6)
Block(-2,2,7,STONE:6)
Block(-2,2,8,STONE:0)
Block(-2,3,-7,STONE:0)
Block(-2,3,-6,STONE:0)
Block(-2,3,-5,GRASS:0)
Block(-2,3,6,STONE:6)
Block(-2,3,7,STONE:6)
Block(-2,3,8,STONE:6)
Block(-2,4,-7,STONE:0)
Block(-2,4,-6,STONE:0)
Block(-2,4,6,STONE:6)
Block(-2,4,7,STONE:6)
Block(-2,4,8,STONE:6)
Block(-2,5,6,STONE:6)
Block(-2,5,7,STONE:6)
Block(-2,5,8,STONE:6)
Block(-2,6,6,STONE:6)
Block(-2,6,7,STONE:6)
Block(-2,6,8,STONE:6)
Block(-2,7,6,STONE:6)
Block(-2,7,7,STONE:6)
Block(-2,7,8,STONE:6)
Block(-2,8,6,STONE:6)
Block(-2,8,7,STONE:6)
Block(-2,8,8,STONE:6)
Block(-2,9,6,STONE:6)
Block(-2,9,7,STONE:6)
Block(-2,9,8,STONE:6)
Block(-2,10,6,STONE:6)
Block(-2,10,7,STONE:6)
Block(-2,10,8,STONE:0)
Block(-2,11,6,STONE:6)
Block(-2,11,7,STONE:6)
Block(-2,11,8,STONE:0)
Block(-2,12,7,STONE:6)
Block(-2,12,8,COBBLESTONE:0)
Block(-2,13,7,STONE:6)
Block(-2,13,8,COBBLESTONE:0)
Block(-2,14,7,STONE:6)
Block(-2,14,8,COBBLESTONE:0)
Block(-2,15,-7,STONE:0)
Block(-2,15,-6,STONE:0)
Block(-2,15,7,STONE:6)
Block(-2,15,8,COBBLESTONE:0)
Block(-2,16,-7,STONE:0)
Block(-2,16,-6,STONE:0)
Block(-2,16,-5,STONE:0)
Block(-2,16,7,STONE:6)
Block(-2,16,8,COBBLESTONE:0)
Block(-2,17,-7,STONE:0)
Block(-2,17,-6,STONE:0)
Block(-2,17,-5,STONE:0)
Block(-2,17,-4,STONE:0)
Block(-2,17,0,STONE:0)
Block(-2,17,1,STONE:0)
Block(-2,17,2,STONE:0)
Block(-2,17,7,STONE:6)
Block(-2,17,8,COBBLESTONE:0)
Block(-2,18,-7,STONE:0)
Block(-2,18,-6,STONE:0)
Block(-2,18,-5,STONE:0)
Block(-2,18,-4,STONE:0)
Block(-2,18,-3,STONE:0)
Block(-2,18,-1,STONE:0)
Block(-2,18,0,STONE:0)
Block(-2,18,1,STONE:0)
Block(-2,18,2,STONE:0)
Block(-2,18,3,STONE:0)
Block(-2,18,7,STONE:6)
Block(-2,18,8,COBBLESTONE:0)
Block(-2,19,-7,SANDSTONE:0)
Block(-2,19,-6,STONE:0)
Block(-2,19,-5,STONE:0)
Block(-2,19,-4,STONE:0)
Block(-2,19,-3,STONE:0)
Block(-2,19,-2,STONE:0)
Block(-2,19,-1,STONE:0)
Block(-2,19,0,STONE:0)
Block(-2,19,1,STONE:0)
Block(-2,19,2,STONE:0)
Block(-2,19,3,STONE:0)
Block(-2,19,4,STONE:0)
Block(-2,19,7,STONE:6)
Block(-2,19,8,COBBLESTONE:0)
Block(-2,20,-7,SANDSTONE:0)
Block(-2,20,-6,SANDSTONE:0)
Block(-2,20,-5,STONE:0)
Block(-2,20,-4,STONE:0)
Block(-2,20,-3,STONE:0)
Block(-2,20,-2,STONE:0)
Block(-2,20,-1,STONE:0)
Block(-2,20,0,STONE:0)
Block(-2,20,1,STONE:0)
Block(-2,20,2,STONE:0)
Block(-2,20,3,STONE:0)
Block(-2,20,4,STONE:0)
Block(-2,20,7,STONE:6)
Block(-2,20,8,COBBLESTONE:0)
Block(-2,21,-5,SANDSTONE:0)
Block(-2,21,-4,SANDSTONE:0)
Block(-2,21,-3,SANDSTONE:0)
Block(-2,21,-2,SANDSTONE:0)
Block(-2,21,-1,SANDSTONE:0)
Block(-2,21,0,SANDSTONE:0)
Block(-2,21,1,SANDSTONE:0)
Block(-2,21,2,SANDSTONE:0)
Block(-2,21,3,SANDSTONE:0)
Block(-2,21,4,SANDSTONE:0)
Block(-2,21,7,STONE:6)
Block(-2,21,8,COBBLESTONE:0)
Block(-2,22,7,STONE:6)
Block(-2,22,8,COBBLESTONE:0)
Block(-1,0,-7,STONE:0)
Block(-1,0,-6,STONE:0)
Block(-1,0,-5,STONE:0)
Block(-1,0,-4,STONE:0)
Block(-1,0,-3,STONE:0)
Block(-1,0,-2,STONE:0)
Block(-1,0,-1,STONE:0)
Block(-1,0,0,STONE:0)
Block(-1,0,1,STONE:0)
Block(-1,0,2,STONE:0)
Block(-1,0,3,STONE:0)
Block(-1,0,4,STONE:0)
Block(-1,0,5,STONE:0)
Block(-1,0,6,STONE:0)
Block(-1,0,7,STONE:0)
Block(-1,0,8,STONE:0)
Block(-1,1,-7,STONE:0)
Block(-1,1,-6,STONE:0)
Block(-1,1,-5,STONE:0)
Block(-1,1,-4,STONE:0)
Block(-1,1,-3,STONE:0)
Block(-1,1,-2,STONE:0)
Block(-1,1,-1,STATIONARY_WATER:0)
Block(-1,1,0,STATIONARY_WATER:0)
Block(-1,1,1,STATIONARY_WATER:0)
Block(-1,1,2,STATIONARY_WATER:0)
Block(-1,1,3,STATIONARY_WATER:0)
Block(-1,1,4,SANDSTONE:0)
Block(-1,1,5,STONE:0)
Block(-1,1,6,STONE:0)
Block(-1,1,7,STONE:0)
Block(-1,1,8,STONE:0)
Block(-1,2,-7,STONE:0)
Block(-1,2,-6,STONE:0)
Block(-1,2,-5,STONE:0)
Block(-1,2,-4,GRASS:0)
Block(-1,2,-3,GRASS:0)
Block(-1,2,-2,STATIONARY_WATER:0)
Block(-1,2,-1,STATIONARY_WATER:0)
Block(-1,2,0,STATIONARY_WATER:0)
Block(-1,2,1,STATIONARY_WATER:0)
Block(-1,2,2,STATIONARY_WATER:0)
Block(-1,2,3,STATIONARY_WATER:0)
Block(-1,2,4,STATIONARY_WATER:0)
Block(-1,2,5,STATIONARY_WATER:0)
Block(-1,2,6,STONE:6)
Block(-1,2,7,STONE:6)
Block(-1,2,8,STONE:0)
Block(-1,3,-7,STONE:0)
Block(-1,3,-6,STONE:0)
Block(-1,3,-5,GRASS:0)
Block(-1,3,6,STONE:6)
Block(-1,3,7,STONE:6)
Block(-1,3,8,STONE:6)
Block(-1,4,-7,STONE:0)
Block(-1,4,-6,STONE:0)
Block(-1,4,6,STONE:6)
Block(-1,4,7,STONE:6)
Block(-1,4,8,STONE:6)
Block(-1,5,6,STONE:6)
Block(-1,5,7,STONE:6)
Block(-1,5,8,STONE:6)
Block(-1,6,6,STONE:6)
Block(-1,6,7,STONE:6)
Block(-1,6,8,STONE:6)
Block(-1,7,6,STONE:6)
Block(-1,7,7,STONE:6)
Block(-1,7,8,STONE:6)
Block(-1,8,6,STONE:6)
Block(-1,8,7,STONE:6)
Block(-1,8,8,STONE:6)
Block(-1,9,6,STONE:6)
Block(-1,9,7,STONE:6)
Block(-1,9,8,STONE:6)
Block(-1,10,6,STONE:6)
Block(-1,10,7,STONE:6)
Block(-1,10,8,STONE:0)
Block(-1,11,6,STONE:6)
Block(-1,11,7,STONE:6)
Block(-1,11,8,STONE:0)
Block(-1,12,8,COBBLESTONE:0)
Block(-1,13,8,COBBLESTONE:0)
Block(-1,14,-7,STONE:0)
Block(-1,14,8,COBBLESTONE:0)
Block(-1,15,-7,STONE:0)
Block(-1,15,-6,STONE:0)
Block(-1,15,-5,STONE:0)
Block(-1,15,8,COBBLESTONE:0)
Block(-1,16,-7,STONE:0)
Block(-1,16,-6,STONE:0)
Block(-1,16,-5,STONE:0)
Block(-1,16,-4,STONE:0)
Block(-1,16,8,COBBLESTONE:0)
Block(-1,17,-7,STONE:0)
Block(-1,17,-6,STONE:0)
Block(-1,17,-5,STONE:0)
Block(-1,17,-4,STONE:0)
Block(-1,17,-3,STONE:0)
Block(-1,17,8,COBBLESTONE:0)
Block(-1,18,-7,STONE:0)
Block(-1,18,-6,STONE:0)
Block(-1,18,-5,STONE:0)
Block(-1,18,-4,STONE:0)
Block(-1,18,-3,STONE:0)
Block(-1,18,-2,STONE:0)
Block(-1,18,-1,STONE:0)
Block(-1,18,0,STONE:0)
Block(-1,18,1,STONE:0)
Block(-1,18,2,STONE:0)
Block(-1,18,3,STONE:0)
Block(-1,18,8,COBBLESTONE:0)
Block(-1,19,-7,STONE:0)
Block(-1,19,-6,STONE:0)
Block(-1,19,-5,STONE:0)
Block(-1,19,-4,STONE:0)
Block(-1,19,-3,STONE:0)
Block(-1,19,-2,STONE:0)
Block(-1,19,-1,STONE:0)
Block(-1,19,0,STONE:0)
Block(-1,19,1,STONE:0)
Block(-1,19,2,STONE:0)
Block(-1,19,3,STONE:0)
Block(-1,19,8,COBBLESTONE:0)
Block(-1,20,-7,SANDSTONE:0)
Block(-1,20,-6,SANDSTONE:0)
Block(-1,20,-5,STONE:0)
Block(-1,20,-4,STONE:0)
Block(-1,20,-3,STONE:0)
Block(-1,20,-2,STONE:0)
Block(-1,20,-1,STONE:0)
Block(-1,20,0,STONE:0)
Block(-1,20,1,STONE:0)
Block(-1,20,2,STONE:0)
Block(-1,20,3,SANDSTONE:0)
Block(-1,20,8,COBBLESTONE:0)
Block(-1,21,-5,SANDSTONE:0)
Block(-1,21,-4,SANDSTONE:0)
Block(-1,21,-3,SANDSTONE:0)
Block(-1,21,-2,SANDSTONE:0)
Block(-1,21,-1,SANDSTONE:0)
Block(-1,21,0,SANDSTONE:0)
Block(-1,21,1,SANDSTONE:0)
Block(-1,21,2,SANDSTONE:0)
Block(-1,21,8,COBBLESTONE:0)
Block(-1,22,7,STONE:6)
Block(-1,22,8,COBBLESTONE:0)
Block(0,0,-7,STONE:0)
Block(0,0,-6,STONE:0)
Block(0,0,-5,STONE:0)
Block(0,0,-4,STONE:0)
Block(0,0,-3,STONE:0)
Block(0,0,-2,STONE:0)
Block(0,0,-1,STONE:0)
Block(0,0,0,STONE:0)
Block(0,0,1,STONE:0)
Block(0,0,2,SANDSTONE:0)
Block(0,0,3,SANDSTONE:0)
Block(0,0,4,STONE:0)
Block(0,0,5,STONE:0)
Block(0,0,6,STONE:0)
Block(0,0,7,STONE:0)
Block(0,0,8,STONE:0)
Block(0,1,-7,STONE:0)
Block(0,1,-6,STONE:0)
Block(0,1,-5,STONE:0)
Block(0,1,-4,STONE:0)
Block(0,1,-3,STONE:0)
Block(0,1,-2,STONE:0)
Block(0,1,-1,STATIONARY_WATER:0)
Block(0,1,0,STATIONARY_WATER:0)
Block(0,1,1,STATIONARY_WATER:0)
Block(0,1,2,STATIONARY_WATER:0)
Block(0,1,3,STATIONARY_WATER:0)
Block(0,1,4,STATIONARY_WATER:0)
Block(0,1,5,STONE:6)
Block(0,1,6,STONE:6)
Block(0,1,7,STONE:0)
Block(0,1,8,STONE:0)
Block(0,2,-7,STONE:0)
Block(0,2,-6,STONE:0)
Block(0,2,-5,STONE:0)
Block(0,2,-4,GRASS:0)
Block(0,2,-3,GRASS:0)
Block(0,2,-2,STATIONARY_WATER:0)
Block(0,2,-1,STATIONARY_WATER:0)
Block(0,2,0,STATIONARY_WATER:0)
Block(0,2,1,STATIONARY_WATER:0)
Block(0,2,2,STATIONARY_WATER:0)
Block(0,2,3,STATIONARY_WATER:0)
Block(0,2,4,STATIONARY_WATER:0)
Block(0,2,5,STONE:6)
Block(0,2,6,STONE:6)
Block(0,2,7,STONE:6)
Block(0,2,8,STONE:0)
Block(0,3,-7,STONE:0)
Block(0,3,-6,STONE:0)
Block(0,3,-5,GRASS:0)
Block(0,3,5,STONE:6)
Block(0,3,6,STONE:6)
Block(0,3,7,STONE:6)
Block(0,3,8,STONE:6)
Block(0,4,-7,STONE:0)
Block(0,4,-6,STONE:0)
Block(0,4,5,STONE:6)
Block(0,4,6,STONE:6)
Block(0,4,7,STONE:6)
Block(0,4,8,STONE:6)
Block(0,5,-7,STONE:0)
Block(0,5,5,STONE:6)
Block(0,5,6,STONE:6)
Block(0,5,7,STONE:6)
Block(0,5,8,STONE:6)
Block(0,6,5,STONE:6)
Block(0,6,6,STONE:6)
Block(0,6,7,STONE:6)
Block(0,6,8,STONE:0)
Block(0,7,5,STONE:6)
Block(0,7,6,STONE:6)
Block(0,7,7,STONE:6)
Block(0,7,8,STONE:6)
Block(0,8,5,STONE:6)
Block(0,8,6,STONE:6)
Block(0,8,7,STONE:6)
Block(0,8,8,STONE:6)
Block(0,9,5,STONE:6)
Block(0,9,6,STONE:6)
Block(0,9,7,STONE:6)
Block(0,9,8,STONE:6)
Block(0,10,5,STONE:6)
Block(0,10,6,STONE:6)
Block(0,10,7,STONE:6)
Block(0,10,8,STONE:0)
Block(0,11,5,STONE:6)
Block(0,11,6,STONE:6)
Block(0,11,7,STONE:0)
Block(0,11,8,STONE:0)
Block(0,12,7,STONE:6)
Block(0,12,8,COBBLESTONE:0)
Block(0,13,7,STONE:6)
Block(0,13,8,COBBLESTONE:0)
Block(0,14,-7,STONE:0)
Block(0,14,-6,STONE:0)
Block(0,14,7,STONE:6)
Block(0,14,8,COBBLESTONE:0)
Block(0,15,-7,STONE:0)
Block(0,15,-6,STONE:0)
Block(0,15,-5,STONE:0)
Block(0,15,7,STONE:6)
Block(0,15,8,COBBLESTONE:0)
Block(0,16,-7,STONE:0)
Block(0,16,-6,STONE:0)
Block(0,16,-5,STONE:0)
Block(0,16,7,STONE:6)
Block(0,16,8,COBBLESTONE:0)
Block(0,17,-7,STONE:0)
Block(0,17,-6,STONE:0)
Block(0,17,-5,STONE:0)
Block(0,17,-4,STONE:0)
Block(0,17,-3,STONE:0)
Block(0,17,-2,STONE:0)
Block(0,17,-1,STONE:0)
Block(0,17,7,STONE:6)
Block(0,17,8,COBBLESTONE:0)
Block(0,18,-7,STONE:0)
Block(0,18,-6,STONE:0)
Block(0,18,-5,STONE:0)
Block(0,18,-4,STONE:0)
Block(0,18,-3,STONE:0)
Block(0,18,-2,STONE:0)
Block(0,18,-1,STONE:0)
Block(0,18,0,STONE:0)
Block(0,18,1,STONE:0)
Block(0,18,7,STONE:6)
Block(0,18,8,COBBLESTONE:0)
Block(0,19,-7,STONE:0)
Block(0,19,-6,STONE:0)
Block(0,19,-5,STONE:0)
Block(0,19,-4,STONE:0)
Block(0,19,-3,STONE:0)
Block(0,19,-2,STONE:0)
Block(0,19,-1,STONE:0)
Block(0,19,0,STONE:0)
Block(0,19,1,STONE:0)
Block(0,19,7,STONE:6)
Block(0,19,8,COBBLESTONE:0)
Block(0,20,-7,SANDSTONE:0)
Block(0,20,-6,SANDSTONE:0)
Block(0,20,-5,STONE:0)
Block(0,20,-4,STONE:0)
Block(0,20,-3,STONE:0)
Block(0,20,-2,STONE:0)
Block(0,20,-1,STONE:0)
Block(0,20,0,STONE:0)
Block(0,20,1,STONE:0)
Block(0,20,7,STONE:6)
Block(0,20,8,COBBLESTONE:0)
Block(0,21,-5,SANDSTONE:0)
Block(0,21,-4,SANDSTONE:0)
Block(0,21,-3,SANDSTONE:0)
Block(0,21,-2,SANDSTONE:0)
Block(0,21,-1,SANDSTONE:0)
Block(0,21,0,SANDSTONE:0)
Block(0,21,1,SANDSTONE:0)
Block(0,21,7,STONE:6)
Block(0,21,8,COBBLESTONE:0)
Block(0,22,7,STONE:6)
Block(0,22,8,COBBLESTONE:0)
Block(0,23,7,STEP:0)
Block(0,23,8,STEP:0)
Block(1,0,-7,STONE:0)
Block(1,0,-6,STONE:0)
Block(1,0,-5,STONE:0)
Block(1,0,-4,STONE:0)
Block(1,0,-3,STONE:0)
Block(1,0,-2,STONE:0)
Block(1,0,-1,STONE:0)
Block(1,0,0,STONE:0)
Block(1,0,1,STONE:0)
Block(1,0,2,SANDSTONE:0)
Block(1,0,3,STONE:0)
Block(1,0,4,STONE:0)
Block(1,0,5,STONE:0)
Block(1,0,6,STONE:0)
Block(1,0,7,STONE:0)
Block(1,0,8,STONE:0)
Block(1,1,-7,STONE:0)
Block(1,1,-6,STONE:0)
Block(1,1,-5,STONE:0)
Block(1,1,-4,STONE:0)
Block(1,1,-3,STONE:0)
Block(1,1,-2,STONE:0)
Block(1,1,-1,STATIONARY_WATER:0)
Block(1,1,0,STATIONARY_WATER:0)
Block(1,1,1,STATIONARY_WATER:0)
Block(1,1,2,STATIONARY_WATER:0)
Block(1,1,3,STATIONARY_WATER:0)
Block(1,1,4,STATIONARY_WATER:0)
Block(1,1,5,STONE:6)
Block(1,1,6,STONE:6)
Block(1,1,7,STONE:0)
Block(1,1,8,STONE:0)
Block(1,2,-7,STONE:0)
Block(1,2,-6,STONE:0)
Block(1,2,-5,STONE:0)
Block(1,2,-4,GRASS:0)
Block(1,2,-3,GRASS:0)
Block(1,2,-2,STATIONARY_WATER:0)
Block(1,2,-1,STATIONARY_WATER:0)
Block(1,2,0,STATIONARY_WATER:0)
Block(1,2,1,STATIONARY_WATER:0)
Block(1,2,2,STATIONARY_WATER:0)
Block(1,2,3,STATIONARY_WATER:0)
Block(1,2,4,STATIONARY_WATER:0)
Block(1,2,5,STONE:6)
Block(1,2,6,STONE:6)
Block(1,2,7,STONE:6)
Block(1,2,8,STONE:0)
Block(1,3,-7,STONE:0)
Block(1,3,-6,STONE:0)
Block(1,3,-5,GRASS:0)
Block(1,3,5,STONE:6)
Block(1,3,6,STONE:6)
Block(1,3,7,STONE:6)
Block(1,3,8,STONE:0)
Block(1,4,-7,STONE:0)
Block(1,4,-6,STONE:0)
Block(1,4,5,STONE:6)
Block(1,4,6,STONE:6)
Block(1,4,7,STONE:6)
Block(1,4,8,DIRT:0)
Block(1,5,-7,STONE:0)
Block(1,5,5,STONE:6)
Block(1,5,6,STONE:6)
Block(1,5,7,STONE:6)
Block(1,5,8,DIRT:0)
Block(1,6,5,STONE:6)
Block(1,6,6,STONE:6)
Block(1,6,7,STONE:0)
Block(1,6,8,STONE:0)
Block(1,7,5,STONE:6)
Block(1,7,6,STONE:6)
Block(1,7,7,STONE:6)
Block(1,7,8,STONE:0)
Block(1,8,5,STONE:6)
Block(1,8,6,STONE:6)
Block(1,8,7,STONE:6)
Block(1,8,8,STONE:0)
Block(1,9,5,STONE:6)
Block(1,9,6,STONE:6)
Block(1,9,7,STONE:6)
Block(1,9,8,STONE:0)
Block(1,10,5,STONE:6)
Block(1,10,6,STONE:6)
Block(1,10,7,STONE:0)
Block(1,10,8,STONE:0)
Block(1,11,5,STONE:6)
Block(1,11,6,STONE:0)
Block(1,11,7,STONE:0)
Block(1,11,8,STONE:6)
Block(1,12,6,STONE:6)
Block(1,12,7,COBBLESTONE:0)
Block(1,12,8,COBBLESTONE:0)
Block(1,13,6,STONE:6)
Block(1,13,7,COBBLESTONE:0)
Block(1,13,8,COBBLESTONE:0)
Block(1,14,-7,STONE:0)
Block(1,14,-6,STONE:0)
Block(1,14,-5,STONE:0)
Block(1,14,6,STONE:6)
Block(1,14,7,COBBLESTONE:0)
Block(1,14,8,COBBLESTONE:0)
Block(1,15,-7,STONE:0)
Block(1,15,-6,STONE:0)
Block(1,15,-5,STONE:0)
Block(1,15,6,STONE:6)
Block(1,15,7,COBBLESTONE:0)
Block(1,15,8,COBBLESTONE:0)
Block(1,16,-7,STONE:0)
Block(1,16,-6,STONE:0)
Block(1,16,-5,STONE:0)
Block(1,16,6,STONE:6)
Block(1,16,7,COBBLESTONE:0)
Block(1,16,8,COBBLESTONE:0)
Block(1,17,-7,STONE:0)
Block(1,17,-6,STONE:0)
Block(1,17,-5,STONE:0)
Block(1,17,-4,STONE:0)
Block(1,17,-3,STONE:0)
Block(1,17,-2,STONE:0)
Block(1,17,-1,STONE:0)
Block(1,17,6,STONE:6)
Block(1,17,7,COBBLESTONE:0)
Block(1,17,8,COBBLESTONE:0)
Block(1,18,-7,STONE:0)
Block(1,18,-6,STONE:0)
Block(1,18,-5,STONE:0)
Block(1,18,-4,STONE:0)
Block(1,18,-3,STONE:0)
Block(1,18,-2,STONE:0)
Block(1,18,-1,STONE:0)
Block(1,18,0,STONE:0)
Block(1,18,6,STONE:6)
Block(1,18,7,COBBLESTONE:0)
Block(1,18,8,COBBLESTONE:0)
Block(1,19,-7,SANDSTONE:0)
Block(1,19,-6,STONE:0)
Block(1,19,-5,STONE:0)
Block(1,19,-4,STONE:0)
Block(1,19,-3,STONE:0)
Block(1,19,-2,STONE:0)
Block(1,19,-1,STONE:0)
Block(1,19,0,STONE:0)
Block(1,19,1,STONE:0)
Block(1,19,6,STONE:6)
Block(1,19,7,COBBLESTONE:0)
Block(1,19,8,COBBLESTONE:0)
Block(1,20,-7,SANDSTONE:0)
Block(1,20,-6,SANDSTONE:0)
Block(1,20,-5,SANDSTONE:0)
Block(1,20,-4,STONE:0)
Block(1,20,-3,STONE:0)
Block(1,20,-2,STONE:0)
Block(1,20,-1,STONE:0)
Block(1,20,0,STONE:0)
Block(1,20,1,SANDSTONE:0)
Block(1,20,6,STONE:6)
Block(1,20,7,COBBLESTONE:0)
Block(1,20,8,COBBLESTONE:0)
Block(1,21,-4,SANDSTONE:0)
Block(1,21,-3,SANDSTONE:0)
Block(1,21,-2,SANDSTONE:0)
Block(1,21,-1,SANDSTONE:0)
Block(1,21,0,SANDSTONE:0)
Block(1,21,6,STONE:6)
Block(1,21,7,COBBLESTONE:0)
Block(1,21,8,COBBLESTONE:0)
Block(1,22,6,STONE:6)
Block(1,22,7,COBBLESTONE:0)
Block(1,22,8,COBBLESTONE:0)
Block(1,23,6,STONE:6)
Block(1,23,7,COBBLESTONE:0)
Block(1,23,8,COBBLESTONE:0)
Block(2,0,-7,STONE:0)
Block(2,0,-6,STONE:0)
Block(2,0,-5,STONE:0)
Block(2,0,-4,STONE:0)
Block(2,0,-3,STONE:0)
Block(2,0,-2,STONE:0)
Block(2,0,-1,STONE:0)
Block(2,0,0,STONE:0)
Block(2,0,1,SANDSTONE:0)
Block(2,0,2,STONE:0)
Block(2,0,3,STONE:0)
Block(2,0,4,STONE:0)
Block(2,0,5,STONE:0)
Block(2,0,6,STONE:0)
Block(2,0,7,STONE:0)
Block(2,0,8,STONE:0)
Block(2,1,-7,STONE:0)
Block(2,1,-6,STONE:0)
Block(2,1,-5,STONE:0)
Block(2,1,-4,STONE:0)
Block(2,1,-3,STONE:0)
Block(2,1,-2,GRASS:0)
Block(2,1,-1,STONE:0)
Block(2,1,0,STATIONARY_WATER:0)
Block(2,1,1,STATIONARY_WATER:0)
Block(2,1,2,STATIONARY_WATER:0)
Block(2,1,3,STATIONARY_WATER:0)
Block(2,1,4,STONE:6)
Block(2,1,5,STONE:6)
Block(2,1,6,STONE:6)
Block(2,1,7,STONE:0)
Block(2,1,8,STONE:0)
Block(2,2,-7,STONE:0)
Block(2,2,-6,STONE:0)
Block(2,2,-5,STONE:0)
Block(2,2,-4,STONE:0)
Block(2,2,-3,GRASS:0)
Block(2,2,-2,STATIONARY_WATER:0)
Block(2,2,-1,STATIONARY_WATER:0)
Block(2,2,0,STATIONARY_WATER:0)
Block(2,2,1,STATIONARY_WATER:0)
Block(2,2,2,STATIONARY_WATER:0)
Block(2,2,3,STATIONARY_WATER:0)
Block(2,2,4,STONE:6)
Block(2,2,5,STONE:6)
Block(2,2,6,STONE:6)
Block(2,2,7,STONE:6)
Block(2,2,8,STONE:0)
Block(2,3,-7,STONE:0)
Block(2,3,-6,STONE:0)
Block(2,3,-5,GRASS:0)
Block(2,3,-4,GRASS:0)
Block(2,3,4,STONE:6)
Block(2,3,5,STONE:6)
Block(2,3,6,STONE:6)
Block(2,3,7,STONE:6)
Block(2,3,8,STONE:0)
Block(2,4,-7,STONE:0)
Block(2,4,-6,STONE:0)
Block(2,4,4,STONE:6)
Block(2,4,5,STONE:6)
Block(2,4,6,STONE:6)
Block(2,4,7,STONE:6)
Block(2,4,8,STONE:0)
Block(2,5,-7,STONE:0)
Block(2,5,4,STONE:6)
Block(2,5,5,STONE:6)
Block(2,5,6,STONE:6)
Block(2,5,7,STONE:0)
Block(2,5,8,DIRT:0)
Block(2,6,4,STONE:6)
Block(2,6,5,STONE:6)
Block(2,6,6,STONE:6)
Block(2,6,7,STONE:0)
Block(2,6,8,STONE:0)
Block(2,7,4,STONE:6)
Block(2,7,5,STONE:6)
Block(2,7,6,STONE:6)
Block(2,7,7,STONE:6)
Block(2,7,8,STONE:0)
Block(2,8,4,STONE:6)
Block(2,8,5,STONE:6)
Block(2,8,6,STONE:6)
Block(2,8,7,STONE:6)
Block(2,8,8,STONE:0)
Block(2,9,4,STONE:6)
Block(2,9,5,STONE:6)
Block(2,9,6,STONE:6)
Block(2,9,7,STONE:6)
Block(2,9,8,STONE:0)
Block(2,10,4,STONE:6)
Block(2,10,5,STONE:6)
Block(2,10,6,STONE:6)
Block(2,10,7,STONE:0)
Block(2,10,8,STONE:0)
Block(2,11,4,STONE:6)
Block(2,11,5,STONE:6)
Block(2,11,6,STONE:6)
Block(2,11,7,STONE:0)
Block(2,11,8,STONE:6)
Block(2,12,7,COBBLESTONE:0)
Block(2,12,8,COBBLESTONE:0)
Block(2,13,-7,STONE:0)
Block(2,13,7,COBBLESTONE:0)
Block(2,13,8,COBBLESTONE:0)
Block(2,14,-7,STONE:0)
Block(2,14,-6,STONE:0)
Block(2,14,7,COBBLESTONE:0)
Block(2,14,8,COBBLESTONE:0)
Block(2,15,-7,STONE:0)
Block(2,15,-6,STONE:0)
Block(2,15,-5,STONE:0)
Block(2,15,7,COBBLESTONE:0)
Block(2,15,8,COBBLESTONE:0)
Block(2,16,-7,STONE:0)
Block(2,16,-6,STONE:0)
Block(2,16,-5,STONE:0)
Block(2,16,7,COBBLESTONE:0)
Block(2,16,8,COBBLESTONE:0)
Block(2,17,-7,STONE:0)
Block(2,17,-6,STONE:0)
Block(2,17,-5,STONE:0)
Block(2,17,-4,STONE:0)
Block(2,17,-3,STONE:0)
Block(2,17,-2,STONE:0)
Block(2,17,-1,STONE:0)
Block(2,17,7,COBBLESTONE:0)
Block(2,17,8,COBBLESTONE:0)
Block(2,18,-7,STONE:0)
Block(2,18,-6,STONE:0)
Block(2,18,-5,STONE:0)
Block(2,18,-4,STONE:0)
Block(2,18,-3,STONE:0)
Block(2,18,-2,STONE:0)
Block(2,18,-1,STONE:0)
Block(2,18,0,STONE:0)
Block(2,18,7,COBBLESTONE:0)
Block(2,18,8,COBBLESTONE:0)
Block(2,19,-7,SANDSTONE:0)
Block(2,19,-6,SANDSTONE:0)
Block(2,19,-5,STONE:0)
Block(2,19,-4,STONE:0)
Block(2,19,-3,STONE:0)
Block(2,19,-2,STONE:0)
Block(2,19,-1,STONE:0)
Block(2,19,0,STONE:0)
Block(2,19,7,COBBLESTONE:0)
Block(2,19,8,COBBLESTONE:0)
Block(2,20,-7,SANDSTONE:0)
Block(2,20,-6,SANDSTONE:0)
Block(2,20,-5,SANDSTONE:0)
Block(2,20,-4,STONE:0)
Block(2,20,-3,STONE:0)
Block(2,20,-2,STONE:0)
Block(2,20,-1,STONE:0)
Block(2,20,0,SANDSTONE:0)
Block(2,20,7,COBBLESTONE:0)
Block(2,20,8,COBBLESTONE:0)
Block(2,21,-4,SANDSTONE:0)
Block(2,21,-3,SANDSTONE:0)
Block(2,21,-2,SANDSTONE:0)
Block(2,21,-1,SANDSTONE:0)
Block(2,21,7,COBBLESTONE:0)
Block(2,21,8,COBBLESTONE:0)
Block(2,22,7,COBBLESTONE:0)
Block(2,22,8,COBBLESTONE:0)
Block(2,23,6,STONE:6)
Block(2,23,7,COBBLESTONE:0)
Block(2,23,8,COBBLESTONE:0)
Block(2,24,8,STEP:0)
Block(3,0,-7,STONE:0)
Block(3,0,-6,STONE:0)
Block(3,0,-5,STONE:0)
Block(3,0,-4,STONE:0)
Block(3,0,-3,STONE:0)
Block(3,0,-2,STONE:0)
Block(3,0,-1,STONE:0)
Block(3,0,0,STONE:0)
Block(3,0,1,SANDSTONE:0)
Block(3,0,2,STONE:0)
Block(3,0,3,STONE:0)
Block(3,0,4,STONE:0)
Block(3,0,5,STONE:0)
Block(3,0,6,STONE:0)
Block(3,0,7,STONE:0)
Block(3,0,8,STONE:0)
Block(3,1,-7,STONE:0)
Block(3,1,-6,STONE:0)
Block(3,1,-5,STONE:0)
Block(3,1,-4,STONE:0)
Block(3,1,-3,STONE:0)
Block(3,1,-2,STONE:0)
Block(3,1,-1,STONE:0)
Block(3,1,0,STATIONARY_WATER:0)
Block(3,1,1,STATIONARY_WATER:0)
Block(3,1,2,STATIONARY_WATER:0)
Block(3,1,3,STATIONARY_WATER:0)
Block(3,1,4,STONE:6)
Block(3,1,5,STONE:6)
Block(3,1,6,STONE:0)
Block(3,1,7,STONE:0)
Block(3,1,8,STONE:0)
Block(3,2,-7,STONE:0)
Block(3,2,-6,STONE:0)
Block(3,2,-5,STONE:0)
Block(3,2,-4,STONE:0)
Block(3,2,-3,GRASS:0)
Block(3,2,-2,GRASS:0)
Block(3,2,-1,STATIONARY_WATER:0)
Block(3,2,0,STATIONARY_WATER:0)
Block(3,2,1,STATIONARY_WATER:0)
Block(3,2,2,STATIONARY_WATER:0)
Block(3,2,3,STATIONARY_WATER:0)
Block(3,2,4,STONE:6)
Block(3,2,5,STONE:6)
Block(3,2,6,STONE:6)
Block(3,2,7,STONE:0)
Block(3,2,8,STONE:0)
Block(3,3,-7,STONE:0)
Block(3,3,-6,GRASS:0)
Block(3,3,-5,GRASS:0)
Block(3,3,-4,GRASS:0)
Block(3,3,4,STONE:6)
Block(3,3,5,STONE:6)
Block(3,3,6,STONE:6)
Block(3,3,7,STONE:0)
Block(3,3,8,STONE:0)
Block(3,4,-7,STONE:0)
Block(3,4,4,STONE:6)
Block(3,4,5,STONE:6)
Block(3,4,6,STONE:6)
Block(3,4,7,STONE:0)
Block(3,4,8,STONE:0)
Block(3,5,4,STONE:6)
Block(3,5,5,STONE:6)
Block(3,5,6,STONE:6)
Block(3,5,7,STONE:0)
Block(3,5,8,STONE:0)
Block(3,6,4,STONE:6)
Block(3,6,5,STONE:6)
Block(3,6,6,STONE:0)
Block(3,6,7,STONE:0)
Block(3,6,8,DIRT:0)
Block(3,7,4,STONE:6)
Block(3,7,5,STONE:6)
Block(3,7,6,STONE:6)
Block(3,7,7,STONE:0)
Block(3,7,8,STONE:0)
Block(3,8,4,STONE:6)
Block(3,8,5,STONE:6)
Block(3,8,6,STONE:6)
Block(3,8,7,STONE:0)
Block(3,8,8,STONE:0)
Block(3,9,4,STONE:6)
Block(3,9,5,STONE:6)
Block(3,9,6,STONE:6)
Block(3,9,7,STONE:0)
Block(3,9,8,STONE:0)
Block(3,10,4,STONE:6)
Block(3,10,5,STONE:6)
Block(3,10,6,STONE:0)
Block(3,10,7,STONE:0)
Block(3,10,8,STONE:0)
Block(3,11,4,STONE:6)
Block(3,11,5,STONE:0)
Block(3,11,6,STONE:0)
Block(3,11,7,STONE:6)
Block(3,11,8,STONE:6)
Block(3,12,5,STONE:6)
Block(3,12,6,COBBLESTONE:0)
Block(3,12,7,COBBLESTONE:0)
Block(3,12,8,COBBLESTONE:0)
Block(3,13,5,STONE:6)
Block(3,13,6,COBBLESTONE:0)
Block(3,13,7,COBBLESTONE:0)
Block(3,13,8,COBBLESTONE:0)
Block(3,14,5,STONE:6)
Block(3,14,6,COBBLESTONE:0)
Block(3,14,7,COBBLESTONE:0)
Block(3,14,8,COBBLESTONE:0)
Block(3,15,-7,STONE:0)
Block(3,15,5,STONE:6)
Block(3,15,6,COBBLESTONE:0)
Block(3,15,7,COBBLESTONE:0)
Block(3,15,8,COBBLESTONE:0)
Block(3,16,-7,STONE:0)
Block(3,16,-6,STONE:0)
Block(3,16,5,STONE:6)
Block(3,16,6,COBBLESTONE:0)
Block(3,16,7,COBBLESTONE:0)
Block(3,16,8,COBBLESTONE:0)
Block(3,17,-7,STONE:0)
Block(3,17,-6,STONE:0)
Block(3,17,5,STONE:6)
Block(3,17,6,COBBLESTONE:0)
Block(3,17,7,COBBLESTONE:0)
Block(3,17,8,COBBLESTONE:0)
Block(3,18,-7,STONE:0)
Block(3,18,-6,STONE:0)
Block(3,18,-5,STONE:0)
Block(3,18,-4,STONE:0)
Block(3,18,-3,STONE:0)
Block(3,18,-2,STONE:0)
Block(3,18,-1,STONE:0)
Block(3,18,0,STONE:0)
Block(3,18,5,STONE:6)
Block(3,18,6,COBBLESTONE:0)
Block(3,18,7,COBBLESTONE:0)
Block(3,18,8,COBBLESTONE:0)
Block(3,19,-7,SANDSTONE:0)
Block(3,19,-6,SANDSTONE:0)
Block(3,19,-5,SANDSTONE:0)
Block(3,19,-4,STONE:0)
Block(3,19,-3,STONE:0)
Block(3,19,-2,STONE:0)
Block(3,19,-1,STONE:0)
Block(3,19,0,STONE:0)
Block(3,19,5,STONE:6)
Block(3,19,6,COBBLESTONE:0)
Block(3,19,7,COBBLESTONE:0)
Block(3,19,8,COBBLESTONE:0)
Block(3,20,-7,SANDSTONE:0)
Block(3,20,-6,SANDSTONE:0)
Block(3,20,-5,SANDSTONE:0)
Block(3,20,-4,SANDSTONE:0)
Block(3,20,-3,SANDSTONE:0)
Block(3,20,-2,SANDSTONE:0)
Block(3,20,-1,SANDSTONE:0)
Block(3,20,0,SANDSTONE:0)
Block(3,20,5,STONE:6)
Block(3,20,6,COBBLESTONE:0)
Block(3,20,7,COBBLESTONE:0)
Block(3,20,8,COBBLESTONE:0)
Block(3,21,5,STONE:6)
Block(3,21,6,COBBLESTONE:0)
Block(3,21,7,COBBLESTONE:0)
Block(3,21,8,COBBLESTONE:0)
Block(3,22,5,STONE:6)
Block(3,22,6,COBBLESTONE:0)
Block(3,22,7,COBBLESTONE:0)
Block(3,22,8,COBBLESTONE:0)
Block(3,23,5,STONE:6)
Block(3,23,6,COBBLESTONE:0)
Block(3,23,7,COBBLESTONE:0)
Block(3,23,8,COBBLESTONE:0)
Block(3,24,6,STEP:0)
Block(3,24,7,STEP:0)
Block(3,24,8,COBBLESTONE:0)
Block(4,0,-7,STONE:0)
Block(4,0,-6,STONE:0)
Block(4,0,-5,STONE:0)
Block(4,0,-4,STONE:0)
Block(4,0,-3,STONE:0)
Block(4,0,-2,STONE:0)
Block(4,0,-1,STONE:0)
Block(4,0,0,STONE:0)
Block(4,0,1,STONE:0)
Block(4,0,2,STONE:0)
Block(4,0,3,STONE:0)
Block(4,0,4,STONE:0)
Block(4,0,5,STONE:0)
Block(4,0,6,STONE:0)
Block(4,0,7,STONE:0)
Block(4,0,8,STONE:0)
Block(4,1,-7,STONE:0)
Block(4,1,-6,STONE:0)
Block(4,1,-5,STONE:0)
Block(4,1,-4,STONE:0)
Block(4,1,-3,STONE:0)
Block(4,1,-2,STONE:0)
Block(4,1,-1,STONE:0)
Block(4,1,0,SANDSTONE:0)
Block(4,1,1,STONE:0)
Block(4,1,2,STONE:0)
Block(4,1,3,STONE:6)
Block(4,1,4,STONE:0)
Block(4,1,5,STONE:0)
Block(4,1,6,STONE:0)
Block(4,1,7,STONE:0)
Block(4,1,8,STONE:0)
Block(4,2,-7,STONE:0)
Block(4,2,-6,STONE:0)
Block(4,2,-5,STONE:0)
Block(4,2,-4,STONE:0)
Block(4,2,-3,GRASS:0)
Block(4,2,-2,GRASS:0)
Block(4,2,-1,STONE:0)
Block(4,2,0,STATIONARY_WATER:0)
Block(4,2,1,STATIONARY_WATER:0)
Block(4,2,2,STATIONARY_WATER:0)
Block(4,2,3,STONE:6)
Block(4,2,4,STONE:6)
Block(4,2,5,STONE:6)
Block(4,2,6,STONE:0)
Block(4,2,7,STONE:0)
Block(4,2,8,STONE:0)
Block(4,3,-7,GRASS:0)
Block(4,3,-6,GRASS:0)
Block(4,3,-5,GRASS:0)
Block(4,3,-4,GRASS:0)
Block(4,3,3,STONE:6)
Block(4,3,4,STONE:6)
Block(4,3,5,STONE:6)
Block(4,3,6,STONE:6)
Block(4,3,7,STONE:0)
Block(4,3,8,STONE:0)
Block(4,4,3,STONE:6)
Block(4,4,4,STONE:6)
Block(4,4,5,STONE:6)
Block(4,4,6,STONE:6)
Block(4,4,7,STONE:0)
Block(4,4,8,STONE:0)
Block(4,5,3,STONE:6)
Block(4,5,4,STONE:6)
Block(4,5,5,STONE:6)
Block(4,5,6,STONE:6)
Block(4,5,7,STONE:0)
Block(4,5,8,STONE:0)
Block(4,6,3,STONE:6)
Block(4,6,4,STONE:6)
Block(4,6,5,STONE:6)
Block(4,6,6,STONE:0)
Block(4,6,7,STONE:0)
Block(4,6,8,DIRT:0)
Block(4,7,3,STONE:6)
Block(4,7,4,STONE:6)
Block(4,7,5,STONE:6)
Block(4,7,6,STONE:6)
Block(4,7,7,STONE:0)
Block(4,7,8,DIRT:0)
Block(4,8,3,STONE:6)
Block(4,8,4,STONE:6)
Block(4,8,5,STONE:6)
Block(4,8,6,STONE:6)
Block(4,8,7,STONE:0)
Block(4,8,8,STONE:0)
Block(4,9,3,STONE:6)
Block(4,9,4,STONE:6)
Block(4,9,5,STONE:6)
Block(4,9,6,STONE:6)
Block(4,9,7,STONE:0)
Block(4,9,8,STONE:0)
Block(4,10,3,STONE:6)
Block(4,10,4,STONE:6)
Block(4,10,5,STONE:6)
Block(4,10,6,STONE:0)
Block(4,10,7,STONE:0)
Block(4,10,8,STONE:0)
Block(4,11,3,STONE:6)
Block(4,11,4,STONE:6)
Block(4,11,5,STONE:6)
Block(4,11,6,STONE:0)
Block(4,11,7,STONE:6)
Block(4,11,8,STONE:0)
Block(4,12,6,COBBLESTONE:0)
Block(4,12,7,COBBLESTONE:0)
Block(4,12,8,COBBLESTONE:0)
Block(4,13,6,COBBLESTONE:0)
Block(4,13,7,COBBLESTONE:0)
Block(4,13,8,COBBLESTONE:0)
Block(4,14,6,COBBLESTONE:0)
Block(4,14,7,COBBLESTONE:0)
Block(4,14,8,COBBLESTONE:0)
Block(4,15,-7,STONE:0)
Block(4,15,6,COBBLESTONE:0)
Block(4,15,7,COBBLESTONE:0)
Block(4,15,8,COBBLESTONE:0)
Block(4,16,6,COBBLESTONE:0)
Block(4,16,7,COBBLESTONE:0)
Block(4,16,8,COBBLESTONE:0)
Block(4,17,-3,STONE:0)
Block(4,17,6,COBBLESTONE:0)
Block(4,17,7,COBBLESTONE:0)
Block(4,17,8,COBBLESTONE:0)
Block(4,18,-7,STONE:0)
Block(4,18,-6,STONE:0)
Block(4,18,-5,STONE:0)
Block(4,18,-4,STONE:0)
Block(4,18,-3,STONE:0)
Block(4,18,-2,STONE:0)
Block(4,18,6,COBBLESTONE:0)
Block(4,18,7,COBBLESTONE:0)
Block(4,18,8,COBBLESTONE:0)
Block(4,19,-7,SANDSTONE:0)
Block(4,19,-6,SANDSTONE:0)
Block(4,19,-5,SANDSTONE:0)
Block(4,19,-4,STONE:0)
Block(4,19,-3,STONE:0)
Block(4,19,-2,STONE:0)
Block(4,19,-1,STONE:0)
Block(4,19,6,COBBLESTONE:0)
Block(4,19,7,COBBLESTONE:0)
Block(4,19,8,COBBLESTONE:0)
Block(4,20,-7,SANDSTONE:0)
Block(4,20,-6,SANDSTONE:0)
Block(4,20,-5,SANDSTONE:0)
Block(4,20,-4,SANDSTONE:0)
Block(4,20,-3,SANDSTONE:0)
Block(4,20,-2,SANDSTONE:0)
Block(4,20,-1,SANDSTONE:0)
Block(4,20,6,COBBLESTONE:0)
Block(4,20,7,COBBLESTONE:0)
Block(4,20,8,COBBLESTONE:0)
Block(4,21,6,COBBLESTONE:0)
Block(4,21,7,COBBLESTONE:0)
Block(4,21,8,COBBLESTONE:0)
Block(4,22,6,COBBLESTONE:0)
Block(4,22,7,COBBLESTONE:0)
Block(4,22,8,COBBLESTONE:0)
Block(4,23,5,STONE:6)
Block(4,23,6,COBBLESTONE:0)
Block(4,23,7,COBBLESTONE:0)
Block(4,23,8,COBBLESTONE:0)
Block(4,24,5,STEP:0)
Block(4,24,6,COBBLESTONE:0)
Block(4,24,7,COBBLESTONE:0)
Block(4,24,8,COBBLESTONE:0)
Block(5,0,-7,STONE:0)
Block(5,0,-6,STONE:0)
Block(5,0,-5,STONE:0)
Block(5,0,-4,STONE:0)
Block(5,0,-3,STONE:0)
Block(5,0,-2,STONE:0)
Block(5,0,-1,STONE:0)
Block(5,0,0,STONE:0)
Block(5,0,1,STONE:0)
Block(5,0,2,STONE:0)
Block(5,0,3,STONE:0)
Block(5,0,4,STONE:0)
Block(5,0,5,STONE:0)
Block(5,0,6,STONE:0)
Block(5,0,7,STONE:0)
Block(5,0,8,STONE:0)
Block(5,1,-7,STONE:0)
Block(5,1,-6,STONE:0)
Block(5,1,-5,STONE:0)
Block(5,1,-4,STONE:0)
Block(5,1,-3,STONE:0)
Block(5,1,-2,STONE:0)
Block(5,1,-1,STONE:0)
Block(5,1,0,STONE:0)
Block(5,1,1,STONE:0)
Block(5,1,2,STONE:0)
Block(5,1,3,STONE:0)
Block(5,1,4,STONE:0)
Block(5,1,5,STONE:0)
Block(5,1,6,STONE:0)
Block(5,1,7,STONE:0)
Block(5,1,8,STONE:0)
Block(5,2,-7,STONE:0)
Block(5,2,-6,STONE:0)
Block(5,2,-5,GRASS:0)
Block(5,2,-4,GRASS:0)
Block(5,2,-3,GRASS:0)
Block(5,2,-2,STONE:0)
Block(5,2,-1,STONE:0)
Block(5,2,0,SANDSTONE:0)
Block(5,2,1,STATIONARY_WATER:0)
Block(5,2,2,STONE:0)
Block(5,2,3,STONE:0)
Block(5,2,4,STONE:0)
Block(5,2,5,STONE:0)
Block(5,2,6,STONE:0)
Block(5,2,7,STONE:0)
Block(5,2,8,STONE:0)
Block(5,3,-7,GRASS:0)
Block(5,3,-6,GRASS:0)
Block(5,3,3,STONE:6)
Block(5,3,4,STONE:6)
Block(5,3,5,STONE:6)
Block(5,3,6,STONE:0)
Block(5,3,7,STONE:0)
Block(5,3,8,STONE:0)
Block(5,4,3,STONE:6)
Block(5,4,4,STONE:6)
Block(5,4,5,STONE:6)
Block(5,4,6,STONE:0)
Block(5,4,7,STONE:0)
Block(5,4,8,STONE:0)
Block(5,5,3,STONE:6)
Block(5,5,4,STONE:6)
Block(5,5,5,STONE:6)
Block(5,5,6,STONE:0)
Block(5,5,7,STONE:0)
Block(5,5,8,STONE:0)
Block(5,6,3,STONE:6)
Block(5,6,4,STONE:6)
Block(5,6,5,STONE:6)
Block(5,6,6,STONE:0)
Block(5,6,7,STONE:0)
Block(5,6,8,DIRT:0)
Block(5,7,3,STONE:6)
Block(5,7,4,STONE:6)
Block(5,7,5,STONE:6)
Block(5,7,6,STONE:0)
Block(5,7,7,STONE:0)
Block(5,7,8,DIRT:0)
Block(5,8,3,STONE:6)
Block(5,8,4,STONE:6)
Block(5,8,5,STONE:6)
Block(5,8,6,STONE:0)
Block(5,8,7,STONE:0)
Block(5,8,8,STONE:0)
Block(5,9,3,STONE:6)
Block(5,9,4,STONE:6)
Block(5,9,5,STONE:6)
Block(5,9,6,STONE:0)
Block(5,9,7,STONE:0)
Block(5,9,8,STONE:0)
Block(5,10,3,STONE:6)
Block(5,10,4,STONE:6)
Block(5,10,5,STONE:0)
Block(5,10,6,STONE:0)
Block(5,10,7,STONE:0)
Block(5,10,8,STONE:0)
Block(5,11,3,STONE:6)
Block(5,11,4,STONE:0)
Block(5,11,5,STONE:0)
Block(5,11,6,STONE:6)
Block(5,11,7,STONE:6)
Block(5,11,8,STONE:0)
Block(5,12,4,STONE:6)
Block(5,12,5,COBBLESTONE:0)
Block(5,12,6,COBBLESTONE:0)
Block(5,12,7,COBBLESTONE:0)
Block(5,12,8,COBBLESTONE:0)
Block(5,13,4,STONE:6)
Block(5,13,5,COBBLESTONE:0)
Block(5,13,6,COBBLESTONE:0)
Block(5,13,7,COBBLESTONE:0)
Block(5,13,8,COBBLESTONE:0)
Block(5,14,4,STONE:6)
Block(5,14,5,COBBLESTONE:0)
Block(5,14,6,COBBLESTONE:0)
Block(5,14,7,COBBLESTONE:0)
Block(5,14,8,COBBLESTONE:0)
Block(5,15,4,STONE:6)
Block(5,15,5,COBBLESTONE:0)
Block(5,15,6,COBBLESTONE:0)
Block(5,15,7,COBBLESTONE:0)
Block(5,15,8,COBBLESTONE:0)
Block(5,16,4,STONE:6)
Block(5,16,5,COBBLESTONE:0)
Block(5,16,6,COBBLESTONE:0)
Block(5,16,7,COBBLESTONE:0)
Block(5,16,8,COBBLESTONE:0)
Block(5,17,4,STONE:6)
Block(5,17,5,COBBLESTONE:0)
Block(5,17,6,COBBLESTONE:0)
Block(5,17,7,COBBLESTONE:0)
Block(5,17,8,COBBLESTONE:0)
Block(5,18,-7,STONE:0)
Block(5,18,-6,STONE:0)
Block(5,18,-5,STONE:0)
Block(5,18,-4,STONE:0)
Block(5,18,-3,STONE:0)
Block(5,18,-2,STONE:0)
Block(5,18,4,STONE:6)
Block(5,18,5,COBBLESTONE:0)
Block(5,18,6,COBBLESTONE:0)
Block(5,18,7,COBBLESTONE:0)
Block(5,18,8,COBBLESTONE:0)
Block(5,19,-7,SANDSTONE:0)
Block(5,19,-6,SANDSTONE:0)
Block(5,19,-5,SANDSTONE:0)
Block(5,19,-4,STONE:0)
Block(5,19,-3,STONE:0)
Block(5,19,-2,STONE:0)
Block(5,19,-1,STONE:0)
Block(5,19,4,STONE:6)
Block(5,19,5,COBBLESTONE:0)
Block(5,19,6,COBBLESTONE:0)
Block(5,19,7,COBBLESTONE:0)
Block(5,19,8,COBBLESTONE:0)
Block(5,20,-7,SANDSTONE:0)
Block(5,20,-6,SANDSTONE:0)
Block(5,20,-5,SANDSTONE:0)
Block(5,20,-4,SANDSTONE:0)
Block(5,20,-3,SANDSTONE:0)
Block(5,20,-2,SANDSTONE:0)
Block(5,20,-1,SANDSTONE:0)
Block(5,20,4,STONE:6)
Block(5,20,5,COBBLESTONE:0)
Block(5,20,6,COBBLESTONE:0)
Block(5,20,7,COBBLESTONE:0)
Block(5,20,8,COBBLESTONE:0)
Block(5,21,4,STONE:6)
Block(5,21,5,COBBLESTONE:0)
Block(5,21,6,COBBLESTONE:0)
Block(5,21,7,COBBLESTONE:0)
Block(5,21,8,COBBLESTONE:0)
Block(5,22,4,STONE:6)
Block(5,22,5,COBBLESTONE:0)
Block(5,22,6,COBBLESTONE:0)
Block(5,22,7,COBBLESTONE:0)
Block(5,22,8,COBBLESTONE:0)
Block(5,23,4,STONE:6)
Block(5,23,5,COBBLESTONE:0)
Block(5,23,6,COBBLESTONE:0)
Block(5,23,7,COBBLESTONE:0)
Block(5,23,8,COBBLESTONE:0)
Block(5,24,4,STONE:6)
Block(5,24,5,COBBLESTONE:0)
Block(5,24,6,COBBLESTONE:0)
Block(5,24,7,COBBLESTONE:0)
Block(5,24,8,COBBLESTONE:0)
Block(6,0,-7,STONE:0)
Block(6,0,-6,STONE:0)
Block(6,0,-5,STONE:0)
Block(6,0,-4,STONE:0)
Block(6,0,-3,STONE:0)
Block(6,0,-2,STONE:0)
Block(6,0,-1,STONE:0)
Block(6,0,0,STONE:0)
Block(6,0,1,STONE:0)
Block(6,0,2,STONE:0)
Block(6,0,3,STONE:0)
Block(6,0,4,STONE:0)
Block(6,0,5,STONE:0)
Block(6,0,6,STONE:0)
Block(6,0,7,STONE:0)
Block(6,0,8,DIRT:0)
Block(6,1,-7,STONE:0)
Block(6,1,-6,STONE:0)
Block(6,1,-5,STONE:0)
Block(6,1,-4,STONE:0)
Block(6,1,-3,STONE:0)
Block(6,1,-2,STONE:0)
Block(6,1,-1,STONE:0)
Block(6,1,0,STONE:0)
Block(6,1,1,STONE:0)
Block(6,1,2,STONE:0)
Block(6,1,3,STONE:0)
Block(6,1,4,STONE:0)
Block(6,1,5,STONE:0)
Block(6,1,6,STONE:0)
Block(6,1,7,STONE:0)
Block(6,1,8,DIRT:0)
Block(6,2,-7,STONE:0)
Block(6,2,-6,STONE:0)
Block(6,2,-5,GRASS:0)
Block(6,2,-4,STONE:0)
Block(6,2,-3,STONE:0)
Block(6,2,-2,STONE:0)
Block(6,2,-1,STONE:0)
Block(6,2,0,STONE:0)
Block(6,2,1,STONE:0)
Block(6,2,2,STONE:0)
Block(6,2,3,STONE:0)
Block(6,2,4,STONE:0)
Block(6,2,5,STONE:0)
Block(6,2,6,STONE:0)
Block(6,2,7,STONE:0)
Block(6,2,8,STONE:0)
Block(6,3,-7,GRASS:0)
Block(6,3,-6,GRASS:0)
Block(6,3,2,STONE:6)
Block(6,3,3,STONE:6)
Block(6,3,4,STONE:6)
Block(6,3,5,STONE:0)
Block(6,3,6,STONE:0)
Block(6,3,7,STONE:0)
Block(6,3,8,STONE:0)
Block(6,4,2,STONE:6)
Block(6,4,3,STONE:6)
Block(6,4,4,STONE:6)
Block(6,4,5,STONE:6)
Block(6,4,6,STONE:0)
Block(6,4,7,STONE:0)
Block(6,4,8,STONE:0)
Block(6,5,2,STONE:6)
Block(6,5,3,STONE:6)
Block(6,5,4,STONE:6)
Block(6,5,5,STONE:6)
Block(6,5,6,STONE:0)
Block(6,5,7,STONE:0)
Block(6,5,8,DIRT:0)
Block(6,6,2,STONE:6)
Block(6,6,3,STONE:6)
Block(6,6,4,STONE:6)
Block(6,6,5,STONE:6)
Block(6,6,6,STONE:0)
Block(6,6,7,STONE:0)
Block(6,6,8,DIRT:0)
Block(6,7,2,STONE:6)
Block(6,7,3,STONE:6)
Block(6,7,4,STONE:6)
Block(6,7,5,STONE:0)
Block(6,7,6,STONE:0)
Block(6,7,7,STONE:0)
Block(6,7,8,DIRT:0)
Block(6,8,2,STONE:6)
Block(6,8,3,STONE:6)
Block(6,8,4,STONE:6)
Block(6,8,5,STONE:0)
Block(6,8,6,STONE:0)
Block(6,8,7,STONE:0)
Block(6,8,8,DIRT:0)
Block(6,9,2,STONE:6)
Block(6,9,3,STONE:6)
Block(6,9,4,STONE:6)
Block(6,9,5,STONE:0)
Block(6,9,6,STONE:0)
Block(6,9,7,STONE:0)
Block(6,9,8,STONE:0)
Block(6,10,2,STONE:6)
Block(6,10,3,STONE:6)
Block(6,10,4,STONE:0)
Block(6,10,5,STONE:0)
Block(6,10,6,STONE:0)
Block(6,10,7,STONE:0)
Block(6,10,8,STONE:0)
Block(6,11,2,STONE:6)
Block(6,11,3,STONE:6)
Block(6,11,4,STONE:6)
Block(6,11,5,STONE:0)
Block(6,11,6,STONE:6)
Block(6,11,7,STONE:0)
Block(6,11,8,STONE:6)
Block(6,12,5,COBBLESTONE:0)
Block(6,12,6,COBBLESTONE:0)
Block(6,12,7,COBBLESTONE:0)
Block(6,12,8,STONE:6)
Block(6,13,5,COBBLESTONE:0)
Block(6,13,6,COBBLESTONE:0)
Block(6,13,7,COBBLESTONE:0)
Block(6,14,5,COBBLESTONE:0)
Block(6,14,6,COBBLESTONE:0)
Block(6,14,7,COBBLESTONE:0)
Block(6,15,5,COBBLESTONE:0)
Block(6,15,6,COBBLESTONE:0)
Block(6,15,7,COBBLESTONE:0)
Block(6,16,5,COBBLESTONE:0)
Block(6,16,6,COBBLESTONE:0)
Block(6,16,7,COBBLESTONE:0)
Block(6,17,5,COBBLESTONE:0)
Block(6,17,6,COBBLESTONE:0)
Block(6,17,7,COBBLESTONE:0)
Block(6,18,-7,STONE:0)
Block(6,18,-6,STONE:0)
Block(6,18,-3,STONE:0)
Block(6,18,-2,STONE:0)
Block(6,18,5,COBBLESTONE:0)
Block(6,18,6,COBBLESTONE:0)
Block(6,18,7,COBBLESTONE:0)
Block(6,19,-7,SANDSTONE:0)
Block(6,19,-6,SANDSTONE:0)
Block(6,19,-5,STONE:0)
Block(6,19,-4,STONE:0)
Block(6,19,-3,SANDSTONE:0)
Block(6,19,-2,SANDSTONE:0)
Block(6,19,-1,STONE:0)
Block(6,19,5,COBBLESTONE:0)
Block(6,19,6,COBBLESTONE:0)
Block(6,19,7,COBBLESTONE:0)
Block(6,20,-7,SANDSTONE:0)
Block(6,20,-5,SANDSTONE:0)
Block(6,20,-4,SANDSTONE:0)
Block(6,20,-1,SANDSTONE:0)
Block(6,20,5,COBBLESTONE:0)
Block(6,20,6,COBBLESTONE:0)
Block(6,20,7,COBBLESTONE:0)
Block(6,21,5,COBBLESTONE:0)
Block(6,21,6,COBBLESTONE:0)
Block(6,21,7,COBBLESTONE:0)
Block(6,22,5,COBBLESTONE:0)
Block(6,22,6,COBBLESTONE:0)
Block(6,22,7,COBBLESTONE:0)
Block(6,23,5,COBBLESTONE:0)
Block(6,23,6,COBBLESTONE:0)
Block(6,23,7,COBBLESTONE:0)
Block(6,24,4,STONE:6)
Block(6,24,5,COBBLESTONE:0)
Block(6,24,6,COBBLESTONE:0)
Block(6,24,7,COBBLESTONE:0)
Block(6,24,8,STONE:6)
Block(6,25,4,STEP:0)
Block(6,25,5,STEP:0)
Block(6,25,6,STEP:0)
Block(6,25,7,STEP:0)
Block(6,25,8,STEP:0)
Block(7,0,-7,STONE:0)
Block(7,0,-6,STONE:0)
Block(7,0,-5,STONE:0)
Block(7,0,-4,STONE:0)
Block(7,0,-3,STONE:0)
Block(7,0,-2,STONE:0)
Block(7,0,-1,STONE:0)
Block(7,0,0,STONE:0)
Block(7,0,1,STONE:0)
Block(7,0,2,STONE:0)
Block(7,0,3,STONE:0)
Block(7,0,4,STONE:0)
Block(7,0,5,STONE:0)
Block(7,0,6,STONE:0)
Block(7,0,7,DIRT:0)
Block(7,0,8,DIRT:0)
Block(7,1,-7,STONE:0)
Block(7,1,-6,STONE:0)
Block(7,1,-5,SANDSTONE:0)
Block(7,1,-4,SANDSTONE:0)
Block(7,1,-3,SANDSTONE:0)
Block(7,1,-2,STONE:0)
Block(7,1,-1,STONE:0)
Block(7,1,0,STONE:0)
Block(7,1,1,STONE:0)
Block(7,1,2,STONE:0)
Block(7,1,3,STONE:0)
Block(7,1,4,STONE:0)
Block(7,1,5,STONE:0)
Block(7,1,6,STONE:0)
Block(7,1,7,STONE:0)
Block(7,1,8,DIRT:0)
Block(7,2,-7,GRASS:0)
Block(7,2,-6,GRASS:0)
Block(7,2,-5,STATIONARY_WATER:0)
Block(7,2,-4,STATIONARY_WATER:0)
Block(7,2,-3,STATIONARY_WATER:0)
Block(7,2,-2,STONE:0)
Block(7,2,-1,STONE:0)
Block(7,2,0,STONE:0)
Block(7,2,1,STONE:0)
Block(7,2,2,STONE:0)
Block(7,2,3,STONE:0)
Block(7,2,4,STONE:0)
Block(7,2,5,STONE:0)
Block(7,2,6,STONE:0)
Block(7,2,7,STONE:0)
Block(7,2,8,DIRT:0)
Block(7,3,2,STONE:6)
Block(7,3,3,STONE:6)
Block(7,3,4,STONE:0)
Block(7,3,5,STONE:0)
Block(7,3,6,STONE:0)
Block(7,3,7,STONE:0)
Block(7,3,8,DIRT:0)
Block(7,4,2,STONE:6)
Block(7,4,3,STONE:6)
Block(7,4,4,STONE:6)
Block(7,4,5,STONE:0)
Block(7,4,6,STONE:0)
Block(7,4,7,STONE:0)
Block(7,4,8,DIRT:0)
Block(7,5,2,STONE:6)
Block(7,5,3,STONE:6)
Block(7,5,4,STONE:6)
Block(7,5,5,STONE:0)
Block(7,5,6,STONE:0)
Block(7,5,7,STONE:0)
Block(7,5,8,DIRT:0)
Block(7,6,2,STONE:6)
Block(7,6,3,STONE:6)
Block(7,6,4,STONE:6)
Block(7,6,5,STONE:0)
Block(7,6,6,STONE:0)
Block(7,6,7,DIRT:0)
Block(7,6,8,DIRT:0)
Block(7,7,2,STONE:6)
Block(7,7,3,STONE:6)
Block(7,7,4,STONE:6)
Block(7,7,5,STONE:0)
Block(7,7,6,STONE:0)
Block(7,7,7,DIRT:0)
Block(7,7,8,DIRT:0)
Block(7,8,2,STONE:6)
Block(7,8,3,STONE:6)
Block(7,8,4,STONE:6)
Block(7,8,5,STONE:0)
Block(7,8,6,STONE:0)
Block(7,8,7,STONE:0)
Block(7,8,8,DIRT:0)
Block(7,9,2,STONE:6)
Block(7,9,3,STONE:6)
Block(7,9,4,STONE:6)
Block(7,9,5,STONE:0)
Block(7,9,6,STONE:0)
Block(7,9,7,STONE:0)
Block(7,9,8,DIRT:0)
Block(7,10,2,STONE:6)
Block(7,10,3,STONE:6)
Block(7,10,4,STONE:0)
Block(7,10,5,STONE:0)
Block(7,10,6,STONE:0)
Block(7,10,7,STONE:0)
Block(7,10,8,DIRT:0)
Block(7,11,2,STONE:6)
Block(7,11,3,STONE:0)
Block(7,11,4,STONE:0)
Block(7,11,5,STONE:6)
Block(7,11,6,STONE:6)
Block(7,11,7,STONE:0)
Block(7,11,8,DIRT:0)
Block(7,12,3,STONE:6)
Block(7,12,4,COBBLESTONE:0)
Block(7,12,5,COBBLESTONE:0)
Block(7,12,6,COBBLESTONE:0)
Block(7,12,7,COBBLESTONE:0)
Block(7,12,8,STONE:6)
Block(7,13,3,STONE:6)
Block(7,13,4,COBBLESTONE:0)
Block(7,13,5,COBBLESTONE:0)
Block(7,13,6,COBBLESTONE:0)
Block(7,13,7,COBBLESTONE:0)
Block(7,13,8,STONE:6)
Block(7,14,3,STONE:6)
Block(7,14,4,COBBLESTONE:0)
Block(7,14,5,COBBLESTONE:0)
Block(7,14,6,COBBLESTONE:0)
Block(7,14,7,COBBLESTONE:0)
Block(7,14,8,STONE:6)
Block(7,15,3,STONE:6)
Block(7,15,4,COBBLESTONE:0)
Block(7,15,5,COBBLESTONE:0)
Block(7,15,6,COBBLESTONE:0)
Block(7,15,7,COBBLESTONE:0)
Block(7,15,8,STONE:6)
Block(7,16,3,STONE:6)
Block(7,16,4,COBBLESTONE:0)
Block(7,16,5,COBBLESTONE:0)
Block(7,16,6,COBBLESTONE:0)
Block(7,16,7,COBBLESTONE:0)
Block(7,16,8,STONE:6)
Block(7,17,3,STONE:6)
Block(7,17,4,COBBLESTONE:0)
Block(7,17,5,COBBLESTONE:0)
Block(7,17,6,COBBLESTONE:0)
Block(7,17,7,COBBLESTONE:0)
Block(7,17,8,STONE:6)
Block(7,18,-2,STONE:0)
Block(7,18,3,STONE:6)
Block(7,18,4,COBBLESTONE:0)
Block(7,18,5,COBBLESTONE:0)
Block(7,18,6,COBBLESTONE:0)
Block(7,18,7,COBBLESTONE:0)
Block(7,18,8,STONE:6)
Block(7,19,-7,SANDSTONE:0)
Block(7,19,-2,SANDSTONE:0)
Block(7,19,3,STONE:6)
Block(7,19,4,COBBLESTONE:0)
Block(7,19,5,COBBLESTONE:0)
Block(7,19,6,COBBLESTONE:0)
Block(7,19,7,COBBLESTONE:0)
Block(7,19,8,STONE:6)
Block(7,20,3,STONE:6)
Block(7,20,4,COBBLESTONE:0)
Block(7,20,5,COBBLESTONE:0)
Block(7,20,6,COBBLESTONE:0)
Block(7,20,7,COBBLESTONE:0)
Block(7,20,8,STONE:6)
Block(7,21,3,STONE:6)
Block(7,21,4,COBBLESTONE:0)
Block(7,21,5,COBBLESTONE:0)
Block(7,21,6,COBBLESTONE:0)
Block(7,21,7,COBBLESTONE:0)
Block(7,21,8,STONE:6)
Block(7,22,3,STONE:6)
Block(7,22,4,COBBLESTONE:0)
Block(7,22,5,COBBLESTONE:0)
Block(7,22,6,COBBLESTONE:0)
Block(7,22,7,COBBLESTONE:0)
Block(7,22,8,STONE:6)
Block(7,23,3,STONE:6)
Block(7,23,4,COBBLESTONE:0)
Block(7,23,5,COBBLESTONE:0)
Block(7,23,6,COBBLESTONE:0)
Block(7,23,7,COBBLESTONE:0)
Block(7,23,8,STONE:6)
Block(7,24,3,STONE:6)
Block(7,24,4,COBBLESTONE:0)
Block(7,24,5,COBBLESTONE:0)
Block(7,24,6,COBBLESTONE:0)
Block(7,24,7,COBBLESTONE:0)
Block(7,24,8,STONE:6)
Block(7,25,3,STONE:6)
Block(7,25,4,COBBLESTONE:0)
Block(7,25,5,COBBLESTONE:0)
Block(7,25,6,COBBLESTONE:0)
Block(7,25,7,STONE:6)
Block(7,25,8,STEP:0)

#######################################################################
# +-----------------------------------------------------------------+ #
# |                             Branches                            | #
# +-----------------------------------------------------------------+ #
#######################################################################

Branch(0,0,16,true,SpawnHexC12R8,NORTH,100.0,0)

#######################################################################
# +-----------------------------------------------------------------+ #
# |                             Entities                            | #
# +-----------------------------------------------------------------+ #
#######################################################################


#######################################################################
# +-----------------------------------------------------------------+ #
# |                            Particles                            | #
# +-----------------------------------------------------------------+ #
#######################################################################


#######################################################################
# +-----------------------------------------------------------------+ #
# |                             Spawners                            | #
# +-----------------------------------------------------------------+ #
#######################################################################


#######################################################################
# +-----------------------------------------------------------------+ #
# |                             ModData                             | #
# +-----------------------------------------------------------------+ #
#######################################################################

