
#######################################################################
# +-----------------------------------------------------------------+ #
# |                            BO4 object                           | #
# +-----------------------------------------------------------------+ #
#######################################################################

Author: NLBlackEagle

Description: No description given

SettingsMode: WriteWithoutComments


#######################################################################
# +-----------------------------------------------------------------+ #
# |                          Main settings                          | #
# +-----------------------------------------------------------------+ #
#######################################################################

Frequency: 0

SpawnHeight: highestBlock

UseCenterForHighestBlock: true

##############################
# Height Limits for the BO4. #
##############################

MinHeight: 0

MaxHeight: 255

InheritBO3: 

InheritBO3Rotation: NORTH

OverrideChildSettings: true

OverrideParentHeight: false

CanOverride: false

BranchFrequency: 0

BranchFrequencyGroup: 

MustBeBelowOther: false

MustBeInside: 

CannotBeInside: 

ReplacesBO3: 

MustBeInsideWorldBorders: false

CanSpawnOnWater: true

SpawnOnWaterOnly: false

SpawnUnderWater: false

SpawnAtWaterLevel: false

HeightOffset: 0

RemoveAir: true

ReplaceAbove: 

ReplaceBelow: 

ReplaceWithBiomeBlocks: true

ReplaceWithSurfaceBlock: GRASS

ReplaceWithGroundBlock: DIRT

ReplaceWithStoneBlock: STONE

SmoothRadius: 0

SmoothHeightOffset: 0

SmoothStartTop: false

SmoothStartWood: false

SmoothingSurfaceBlock: 

SmoothingGroundBlock: 

BO3Group: 

IsSpawnPoint: false

DoReplaceBlocks: true


#######################################################################
# +-----------------------------------------------------------------+ #
# |                              Blocks                             | #
# +-----------------------------------------------------------------+ #
#######################################################################

Block(-8,0,-7,DIRT:0)
Block(-8,0,-6,DIRT:0)
Block(-8,0,-5,DIRT:0)
Block(-8,0,-4,DIRT:0)
Block(-8,0,-3,DIRT:0)
Block(-8,0,-2,DIRT:0)
Block(-8,0,-1,DIRT:0)
Block(-8,0,0,DIRT:0)
Block(-8,0,1,DIRT:0)
Block(-8,0,2,DIRT:0)
Block(-8,0,3,DIRT:0)
Block(-8,0,4,DIRT:0)
Block(-8,0,5,DIRT:0)
Block(-8,0,6,DIRT:0)
Block(-8,0,7,DIRT:0)
Block(-8,0,8,DIRT:0)
Block(-8,1,-7,DIRT:0)
Block(-8,1,-6,DIRT:0)
Block(-8,1,-5,DIRT:0)
Block(-8,1,-4,DIRT:0)
Block(-8,1,-3,DIRT:0)
Block(-8,1,-2,DIRT:0)
Block(-8,1,-1,DIRT:0)
Block(-8,1,0,DIRT:0)
Block(-8,1,1,DIRT:0)
Block(-8,1,2,DIRT:0)
Block(-8,1,3,DIRT:0)
Block(-8,1,4,DIRT:0)
Block(-8,1,5,DIRT:0)
Block(-8,1,6,DIRT:0)
Block(-8,1,7,DIRT:0)
Block(-8,1,8,DIRT:0)
Block(-8,2,-7,DIRT:0)
Block(-8,2,-6,DIRT:0)
Block(-8,2,-5,DIRT:0)
Block(-8,2,-4,DIRT:0)
Block(-8,2,-3,DIRT:0)
Block(-8,2,-2,DIRT:0)
Block(-8,2,-1,DIRT:0)
Block(-8,2,0,DIRT:0)
Block(-8,2,1,DIRT:0)
Block(-8,2,2,DIRT:0)
Block(-8,2,3,DIRT:0)
Block(-8,2,4,DIRT:0)
Block(-8,2,5,DIRT:0)
Block(-8,2,6,DIRT:0)
Block(-8,2,7,DIRT:0)
Block(-8,2,8,DIRT:0)
Block(-8,3,-7,DIRT:0)
Block(-8,3,-6,DIRT:0)
Block(-8,3,-5,DIRT:0)
Block(-8,3,-4,DIRT:0)
Block(-8,3,-3,DIRT:0)
Block(-8,3,-2,DIRT:0)
Block(-8,3,-1,DIRT:0)
Block(-8,3,0,DIRT:0)
Block(-8,3,1,DIRT:0)
Block(-8,3,2,DIRT:0)
Block(-8,3,3,DIRT:0)
Block(-8,3,4,DIRT:0)
Block(-8,3,5,DIRT:0)
Block(-8,3,6,DIRT:0)
Block(-8,3,7,DIRT:0)
Block(-8,3,8,DIRT:0)
Block(-8,4,-7,DIRT:0)
Block(-8,4,-6,DIRT:0)
Block(-8,4,-5,DIRT:0)
Block(-8,4,-4,DIRT:0)
Block(-8,4,-3,DIRT:0)
Block(-8,4,-2,DIRT:0)
Block(-8,4,-1,DIRT:0)
Block(-8,4,0,DIRT:0)
Block(-8,4,1,DIRT:0)
Block(-8,4,2,DIRT:0)
Block(-8,4,3,DIRT:0)
Block(-8,4,4,DIRT:0)
Block(-8,4,5,GRASS:0)
Block(-8,4,6,DIRT:0)
Block(-8,4,7,DIRT:0)
Block(-8,4,8,DIRT:0)
Block(-8,5,-7,DIRT:0)
Block(-8,5,-6,DIRT:0)
Block(-8,5,-5,DIRT:0)
Block(-8,5,-4,DIRT:0)
Block(-8,5,-3,DIRT:0)
Block(-8,5,-2,GRASS:0)
Block(-8,5,-1,GRASS:0)
Block(-8,5,0,GRASS:0)
Block(-8,5,1,GRASS:0)
Block(-8,5,2,GRASS:0)
Block(-8,5,3,GRASS:0)
Block(-8,5,4,GRASS:0)
Block(-8,5,6,GRASS:0)
Block(-8,5,7,GRASS:0)
Block(-8,5,8,GRASS:0)
Block(-8,6,-7,DIRT:0)
Block(-8,6,-6,DIRT:0)
Block(-8,6,-5,DIRT:0)
Block(-8,6,-4,GRASS:0)
Block(-8,6,-3,GRASS:0)
Block(-8,7,-7,DIRT:0)
Block(-8,7,-6,DIRT:0)
Block(-8,7,-5,GRASS:0)
Block(-8,8,-7,GRASS:0)
Block(-8,8,-6,GRASS:0)
Block(-7,0,-7,DIRT:0)
Block(-7,0,-6,DIRT:0)
Block(-7,0,-5,DIRT:0)
Block(-7,0,-4,DIRT:0)
Block(-7,0,-3,DIRT:0)
Block(-7,0,-2,DIRT:0)
Block(-7,0,-1,DIRT:0)
Block(-7,0,0,DIRT:0)
Block(-7,0,1,DIRT:0)
Block(-7,0,2,DIRT:0)
Block(-7,0,3,DIRT:0)
Block(-7,0,4,DIRT:0)
Block(-7,0,5,DIRT:0)
Block(-7,0,6,DIRT:0)
Block(-7,0,7,DIRT:0)
Block(-7,0,8,DIRT:0)
Block(-7,1,-7,DIRT:0)
Block(-7,1,-6,DIRT:0)
Block(-7,1,-5,DIRT:0)
Block(-7,1,-4,DIRT:0)
Block(-7,1,-3,DIRT:0)
Block(-7,1,-2,DIRT:0)
Block(-7,1,-1,DIRT:0)
Block(-7,1,0,DIRT:0)
Block(-7,1,1,DIRT:0)
Block(-7,1,2,DIRT:0)
Block(-7,1,3,DIRT:0)
Block(-7,1,4,DIRT:0)
Block(-7,1,5,DIRT:0)
Block(-7,1,6,DIRT:0)
Block(-7,1,7,DIRT:0)
Block(-7,1,8,DIRT:0)
Block(-7,2,-7,DIRT:0)
Block(-7,2,-6,DIRT:0)
Block(-7,2,-5,DIRT:0)
Block(-7,2,-4,DIRT:0)
Block(-7,2,-3,DIRT:0)
Block(-7,2,-2,DIRT:0)
Block(-7,2,-1,DIRT:0)
Block(-7,2,0,DIRT:0)
Block(-7,2,1,DIRT:0)
Block(-7,2,2,DIRT:0)
Block(-7,2,3,DIRT:0)
Block(-7,2,4,DIRT:0)
Block(-7,2,5,DIRT:0)
Block(-7,2,6,DIRT:0)
Block(-7,2,7,DIRT:0)
Block(-7,2,8,DIRT:0)
Block(-7,3,-7,DIRT:0)
Block(-7,3,-6,DIRT:0)
Block(-7,3,-5,DIRT:0)
Block(-7,3,-4,DIRT:0)
Block(-7,3,-3,DIRT:0)
Block(-7,3,-2,DIRT:0)
Block(-7,3,-1,DIRT:0)
Block(-7,3,0,DIRT:0)
Block(-7,3,1,DIRT:0)
Block(-7,3,2,DIRT:0)
Block(-7,3,3,DIRT:0)
Block(-7,3,4,DIRT:0)
Block(-7,3,5,DIRT:0)
Block(-7,3,6,DIRT:0)
Block(-7,3,7,DIRT:0)
Block(-7,3,8,DIRT:0)
Block(-7,4,-7,DIRT:0)
Block(-7,4,-6,DIRT:0)
Block(-7,4,-5,DIRT:0)
Block(-7,4,-4,DIRT:0)
Block(-7,4,-3,DIRT:0)
Block(-7,4,-2,DIRT:0)
Block(-7,4,-1,DIRT:0)
Block(-7,4,0,DIRT:0)
Block(-7,4,1,GRASS:0)
Block(-7,4,2,GRASS:0)
Block(-7,4,3,GRASS:0)
Block(-7,4,4,GRASS:0)
Block(-7,4,5,DIRT:0)
Block(-7,4,6,DIRT:0)
Block(-7,4,7,DIRT:0)
Block(-7,4,8,DIRT:0)
Block(-7,5,-7,DIRT:0)
Block(-7,5,-6,DIRT:0)
Block(-7,5,-5,DIRT:0)
Block(-7,5,-4,GRASS:0)
Block(-7,5,-3,GRASS:0)
Block(-7,5,-2,GRASS:0)
Block(-7,5,-1,GRASS:0)
Block(-7,5,0,GRASS:0)
Block(-7,5,5,GRASS:0)
Block(-7,5,6,GRASS:0)
Block(-7,5,7,GRASS:0)
Block(-7,5,8,GRASS:0)
Block(-7,6,-7,DIRT:0)
Block(-7,6,-6,DIRT:0)
Block(-7,6,-5,GRASS:0)
Block(-7,7,-7,DIRT:0)
Block(-7,7,-6,GRASS:0)
Block(-7,8,-7,GRASS:0)
Block(-6,0,-7,DIRT:0)
Block(-6,0,-6,DIRT:0)
Block(-6,0,-5,DIRT:0)
Block(-6,0,-4,DIRT:0)
Block(-6,0,-3,DIRT:0)
Block(-6,0,-2,DIRT:0)
Block(-6,0,-1,DIRT:0)
Block(-6,0,0,DIRT:0)
Block(-6,0,1,DIRT:0)
Block(-6,0,2,DIRT:0)
Block(-6,0,3,DIRT:0)
Block(-6,0,4,DIRT:0)
Block(-6,0,5,DIRT:0)
Block(-6,0,6,DIRT:0)
Block(-6,0,7,DIRT:0)
Block(-6,0,8,DIRT:0)
Block(-6,1,-7,DIRT:0)
Block(-6,1,-6,DIRT:0)
Block(-6,1,-5,DIRT:0)
Block(-6,1,-4,DIRT:0)
Block(-6,1,-3,DIRT:0)
Block(-6,1,-2,DIRT:0)
Block(-6,1,-1,DIRT:0)
Block(-6,1,0,DIRT:0)
Block(-6,1,1,DIRT:0)
Block(-6,1,2,DIRT:0)
Block(-6,1,3,DIRT:0)
Block(-6,1,4,DIRT:0)
Block(-6,1,5,DIRT:0)
Block(-6,1,6,DIRT:0)
Block(-6,1,7,DIRT:0)
Block(-6,1,8,DIRT:0)
Block(-6,2,-7,DIRT:0)
Block(-6,2,-6,DIRT:0)
Block(-6,2,-5,DIRT:0)
Block(-6,2,-4,DIRT:0)
Block(-6,2,-3,DIRT:0)
Block(-6,2,-2,DIRT:0)
Block(-6,2,-1,DIRT:0)
Block(-6,2,0,DIRT:0)
Block(-6,2,1,DIRT:0)
Block(-6,2,2,DIRT:0)
Block(-6,2,3,DIRT:0)
Block(-6,2,4,DIRT:0)
Block(-6,2,5,DIRT:0)
Block(-6,2,6,DIRT:0)
Block(-6,2,7,DIRT:0)
Block(-6,2,8,DIRT:0)
Block(-6,3,-7,DIRT:0)
Block(-6,3,-6,DIRT:0)
Block(-6,3,-5,DIRT:0)
Block(-6,3,-4,DIRT:0)
Block(-6,3,-3,DIRT:0)
Block(-6,3,-2,DIRT:0)
Block(-6,3,-1,DIRT:0)
Block(-6,3,0,DIRT:0)
Block(-6,3,1,DIRT:0)
Block(-6,3,2,DIRT:0)
Block(-6,3,3,DIRT:0)
Block(-6,3,4,DIRT:0)
Block(-6,3,5,DIRT:0)
Block(-6,3,6,DIRT:0)
Block(-6,3,7,DIRT:0)
Block(-6,3,8,DIRT:0)
Block(-6,4,-7,DIRT:0)
Block(-6,4,-6,DIRT:0)
Block(-6,4,-5,DIRT:0)
Block(-6,4,-4,DIRT:0)
Block(-6,4,-3,DIRT:0)
Block(-6,4,-2,DIRT:0)
Block(-6,4,-1,DIRT:0)
Block(-6,4,0,GRASS:0)
Block(-6,4,1,GRASS:0)
Block(-6,4,2,GRASS:0)
Block(-6,4,3,GRASS:0)
Block(-6,4,4,DIRT:0)
Block(-6,4,5,DIRT:0)
Block(-6,4,6,DIRT:0)
Block(-6,4,7,DIRT:0)
Block(-6,4,8,DIRT:0)
Block(-6,5,-7,DIRT:0)
Block(-6,5,-6,DIRT:0)
Block(-6,5,-5,DIRT:0)
Block(-6,5,-4,GRASS:0)
Block(-6,5,-3,DIRT:0)
Block(-6,5,-2,DIRT:0)
Block(-6,5,-1,DIRT:0)
Block(-6,5,4,GRASS:0)
Block(-6,5,5,GRASS:0)
Block(-6,5,6,GRASS:0)
Block(-6,5,7,GRASS:0)
Block(-6,5,8,GRASS:0)
Block(-6,6,-7,DIRT:0)
Block(-6,6,-6,GRASS:0)
Block(-6,6,-5,GRASS:0)
Block(-6,6,-3,GRASS:0)
Block(-6,6,-2,GRASS:0)
Block(-6,6,-1,GRASS:0)
Block(-6,7,-7,GRASS:0)
Block(-5,0,-7,DIRT:0)
Block(-5,0,-6,DIRT:0)
Block(-5,0,-5,DIRT:0)
Block(-5,0,-4,DIRT:0)
Block(-5,0,-3,DIRT:0)
Block(-5,0,-2,DIRT:0)
Block(-5,0,-1,DIRT:0)
Block(-5,0,0,DIRT:0)
Block(-5,0,1,DIRT:0)
Block(-5,0,2,DIRT:0)
Block(-5,0,3,DIRT:0)
Block(-5,0,4,DIRT:0)
Block(-5,0,5,DIRT:0)
Block(-5,0,6,DIRT:0)
Block(-5,0,7,DIRT:0)
Block(-5,0,8,DIRT:0)
Block(-5,1,-7,DIRT:0)
Block(-5,1,-6,DIRT:0)
Block(-5,1,-5,DIRT:0)
Block(-5,1,-4,DIRT:0)
Block(-5,1,-3,DIRT:0)
Block(-5,1,-2,DIRT:0)
Block(-5,1,-1,DIRT:0)
Block(-5,1,0,DIRT:0)
Block(-5,1,1,DIRT:0)
Block(-5,1,2,DIRT:0)
Block(-5,1,3,DIRT:0)
Block(-5,1,4,DIRT:0)
Block(-5,1,5,DIRT:0)
Block(-5,1,6,DIRT:0)
Block(-5,1,7,DIRT:0)
Block(-5,1,8,DIRT:0)
Block(-5,2,-7,DIRT:0)
Block(-5,2,-6,DIRT:0)
Block(-5,2,-5,DIRT:0)
Block(-5,2,-4,DIRT:0)
Block(-5,2,-3,DIRT:0)
Block(-5,2,-2,DIRT:0)
Block(-5,2,-1,DIRT:0)
Block(-5,2,0,DIRT:0)
Block(-5,2,1,DIRT:0)
Block(-5,2,2,DIRT:0)
Block(-5,2,3,DIRT:0)
Block(-5,2,4,DIRT:0)
Block(-5,2,5,DIRT:0)
Block(-5,2,6,DIRT:0)
Block(-5,2,7,DIRT:0)
Block(-5,2,8,GRASS:0)
Block(-5,3,-7,DIRT:0)
Block(-5,3,-6,DIRT:0)
Block(-5,3,-5,DIRT:0)
Block(-5,3,-4,DIRT:0)
Block(-5,3,-3,DIRT:0)
Block(-5,3,-2,DIRT:0)
Block(-5,3,-1,DIRT:0)
Block(-5,3,0,DIRT:0)
Block(-5,3,1,DIRT:0)
Block(-5,3,2,DIRT:0)
Block(-5,3,3,DIRT:0)
Block(-5,3,4,DIRT:0)
Block(-5,3,5,DIRT:0)
Block(-5,3,6,DIRT:0)
Block(-5,3,7,DIRT:0)
Block(-5,4,-7,DIRT:0)
Block(-5,4,-6,DIRT:0)
Block(-5,4,-5,DIRT:0)
Block(-5,4,-4,DIRT:0)
Block(-5,4,-3,DIRT:0)
Block(-5,4,-2,DIRT:0)
Block(-5,4,-1,DIRT:0)
Block(-5,4,0,DIRT:0)
Block(-5,4,1,GRASS:0)
Block(-5,4,2,GRASS:0)
Block(-5,4,3,GRASS:0)
Block(-5,4,4,GRASS:0)
Block(-5,4,5,DIRT:0)
Block(-5,4,6,DIRT:0)
Block(-5,4,7,GRASS:0)
Block(-5,5,-7,DIRT:0)
Block(-5,5,-6,DIRT:0)
Block(-5,5,-5,GRASS:0)
Block(-5,5,-4,DIRT:0)
Block(-5,5,-3,DIRT:0)
Block(-5,5,-2,DIRT:0)
Block(-5,5,-1,DIRT:0)
Block(-5,5,0,GRASS:0)
Block(-5,5,5,GRASS:0)
Block(-5,5,6,GRASS:0)
Block(-5,6,-7,GRASS:0)
Block(-5,6,-6,GRASS:0)
Block(-5,6,-4,GRASS:0)
Block(-5,6,-3,GRASS:0)
Block(-5,6,-2,GRASS:0)
Block(-5,6,-1,GRASS:0)
Block(-4,0,-7,DIRT:0)
Block(-4,0,-6,DIRT:0)
Block(-4,0,-5,DIRT:0)
Block(-4,0,-4,DIRT:0)
Block(-4,0,-3,DIRT:0)
Block(-4,0,-2,DIRT:0)
Block(-4,0,-1,DIRT:0)
Block(-4,0,0,DIRT:0)
Block(-4,0,1,DIRT:0)
Block(-4,0,2,DIRT:0)
Block(-4,0,3,DIRT:0)
Block(-4,0,4,DIRT:0)
Block(-4,0,5,DIRT:0)
Block(-4,0,6,DIRT:0)
Block(-4,0,7,DIRT:0)
Block(-4,0,8,DIRT:0)
Block(-4,1,-7,DIRT:0)
Block(-4,1,-6,DIRT:0)
Block(-4,1,-5,DIRT:0)
Block(-4,1,-4,DIRT:0)
Block(-4,1,-3,DIRT:0)
Block(-4,1,-2,DIRT:0)
Block(-4,1,-1,DIRT:0)
Block(-4,1,0,DIRT:0)
Block(-4,1,1,DIRT:0)
Block(-4,1,2,DIRT:0)
Block(-4,1,3,DIRT:0)
Block(-4,1,4,DIRT:0)
Block(-4,1,5,DIRT:0)
Block(-4,1,6,DIRT:0)
Block(-4,1,7,DIRT:0)
Block(-4,1,8,DIRT:0)
Block(-4,2,-7,DIRT:0)
Block(-4,2,-6,DIRT:0)
Block(-4,2,-5,DIRT:0)
Block(-4,2,-4,DIRT:0)
Block(-4,2,-3,DIRT:0)
Block(-4,2,-2,DIRT:0)
Block(-4,2,-1,DIRT:0)
Block(-4,2,0,DIRT:0)
Block(-4,2,1,DIRT:0)
Block(-4,2,2,DIRT:0)
Block(-4,2,3,DIRT:0)
Block(-4,2,4,DIRT:0)
Block(-4,2,5,DIRT:0)
Block(-4,2,6,DIRT:0)
Block(-4,2,7,DIRT:0)
Block(-4,2,8,GRASS:0)
Block(-4,3,-7,DIRT:0)
Block(-4,3,-6,DIRT:0)
Block(-4,3,-5,DIRT:0)
Block(-4,3,-4,DIRT:0)
Block(-4,3,-3,DIRT:0)
Block(-4,3,-2,DIRT:0)
Block(-4,3,-1,DIRT:0)
Block(-4,3,0,DIRT:0)
Block(-4,3,1,DIRT:0)
Block(-4,3,2,DIRT:0)
Block(-4,3,3,DIRT:0)
Block(-4,3,4,DIRT:0)
Block(-4,3,5,DIRT:0)
Block(-4,3,6,DIRT:0)
Block(-4,3,7,DIRT:0)
Block(-4,4,-7,GRASS:0)
Block(-4,4,-6,DIRT:0)
Block(-4,4,-5,DIRT:0)
Block(-4,4,-4,DIRT:0)
Block(-4,4,-3,DIRT:0)
Block(-4,4,-2,DIRT:0)
Block(-4,4,-1,DIRT:0)
Block(-4,4,0,DIRT:0)
Block(-4,4,1,GRASS:0)
Block(-4,4,2,GRASS:0)
Block(-4,4,3,GRASS:0)
Block(-4,4,4,GRASS:0)
Block(-4,4,5,GRASS:0)
Block(-4,4,6,GRASS:0)
Block(-4,4,7,GRASS:0)
Block(-4,5,-6,GRASS:0)
Block(-4,5,-5,GRASS:0)
Block(-4,5,-4,DIRT:0)
Block(-4,5,-3,DIRT:0)
Block(-4,5,-2,DIRT:0)
Block(-4,5,-1,GRASS:0)
Block(-4,5,0,GRASS:0)
Block(-4,6,-4,GRASS:0)
Block(-4,6,-3,GRASS:0)
Block(-4,6,-2,GRASS:0)
Block(-3,0,-7,DIRT:0)
Block(-3,0,-6,DIRT:0)
Block(-3,0,-5,DIRT:0)
Block(-3,0,-4,DIRT:0)
Block(-3,0,-3,DIRT:0)
Block(-3,0,-2,DIRT:0)
Block(-3,0,-1,DIRT:0)
Block(-3,0,0,DIRT:0)
Block(-3,0,1,DIRT:0)
Block(-3,0,2,DIRT:0)
Block(-3,0,3,DIRT:0)
Block(-3,0,4,DIRT:0)
Block(-3,0,5,DIRT:0)
Block(-3,0,6,DIRT:0)
Block(-3,0,7,DIRT:0)
Block(-3,0,8,DIRT:0)
Block(-3,1,-7,DIRT:0)
Block(-3,1,-6,DIRT:0)
Block(-3,1,-5,DIRT:0)
Block(-3,1,-4,DIRT:0)
Block(-3,1,-3,DIRT:0)
Block(-3,1,-2,DIRT:0)
Block(-3,1,-1,DIRT:0)
Block(-3,1,0,DIRT:0)
Block(-3,1,1,DIRT:0)
Block(-3,1,2,DIRT:0)
Block(-3,1,3,DIRT:0)
Block(-3,1,4,DIRT:0)
Block(-3,1,5,DIRT:0)
Block(-3,1,6,DIRT:0)
Block(-3,1,7,DIRT:0)
Block(-3,1,8,DIRT:0)
Block(-3,2,-7,DIRT:0)
Block(-3,2,-6,DIRT:0)
Block(-3,2,-5,DIRT:0)
Block(-3,2,-4,DIRT:0)
Block(-3,2,-3,DIRT:0)
Block(-3,2,-2,DIRT:0)
Block(-3,2,-1,DIRT:0)
Block(-3,2,0,DIRT:0)
Block(-3,2,1,DIRT:0)
Block(-3,2,2,DIRT:0)
Block(-3,2,3,DIRT:0)
Block(-3,2,4,DIRT:0)
Block(-3,2,5,DIRT:0)
Block(-3,2,6,DIRT:0)
Block(-3,2,7,GRASS:0)
Block(-3,2,8,GRASS:0)
Block(-3,3,-7,DIRT:0)
Block(-3,3,-6,DIRT:0)
Block(-3,3,-5,DIRT:0)
Block(-3,3,-4,DIRT:0)
Block(-3,3,-3,DIRT:0)
Block(-3,3,-2,DIRT:0)
Block(-3,3,-1,DIRT:0)
Block(-3,3,0,DIRT:0)
Block(-3,3,1,DIRT:0)
Block(-3,3,2,DIRT:0)
Block(-3,3,3,DIRT:0)
Block(-3,3,4,DIRT:0)
Block(-3,3,5,DIRT:0)
Block(-3,3,6,DIRT:0)
Block(-3,4,-7,GRASS:0)
Block(-3,4,-6,DIRT:0)
Block(-3,4,-5,DIRT:0)
Block(-3,4,-4,DIRT:0)
Block(-3,4,-3,DIRT:0)
Block(-3,4,-2,DIRT:0)
Block(-3,4,-1,GRASS:0)
Block(-3,4,0,GRASS:0)
Block(-3,4,1,GRASS:0)
Block(-3,4,2,GRASS:0)
Block(-3,4,3,GRASS:0)
Block(-3,4,4,GRASS:0)
Block(-3,4,5,GRASS:0)
Block(-3,4,6,GRASS:0)
Block(-3,5,-6,GRASS:0)
Block(-3,5,-5,GRASS:0)
Block(-3,5,-4,DIRT:0)
Block(-3,5,-3,DIRT:0)
Block(-3,5,-2,GRASS:0)
Block(-3,6,-4,GRASS:0)
Block(-3,6,-3,GRASS:0)
Block(-2,0,-7,DIRT:0)
Block(-2,0,-6,DIRT:0)
Block(-2,0,-5,DIRT:0)
Block(-2,0,-4,DIRT:0)
Block(-2,0,-3,DIRT:0)
Block(-2,0,-2,DIRT:0)
Block(-2,0,-1,DIRT:0)
Block(-2,0,0,DIRT:0)
Block(-2,0,1,DIRT:0)
Block(-2,0,2,DIRT:0)
Block(-2,0,3,DIRT:0)
Block(-2,0,4,DIRT:0)
Block(-2,0,5,DIRT:0)
Block(-2,0,6,DIRT:0)
Block(-2,0,7,DIRT:0)
Block(-2,0,8,DIRT:0)
Block(-2,1,-7,DIRT:0)
Block(-2,1,-6,DIRT:0)
Block(-2,1,-5,DIRT:0)
Block(-2,1,-4,DIRT:0)
Block(-2,1,-3,DIRT:0)
Block(-2,1,-2,DIRT:0)
Block(-2,1,-1,DIRT:0)
Block(-2,1,0,DIRT:0)
Block(-2,1,1,DIRT:0)
Block(-2,1,2,DIRT:0)
Block(-2,1,3,DIRT:0)
Block(-2,1,4,DIRT:0)
Block(-2,1,5,DIRT:0)
Block(-2,1,6,DIRT:0)
Block(-2,1,7,DIRT:0)
Block(-2,1,8,DIRT:0)
Block(-2,2,-7,DIRT:0)
Block(-2,2,-6,DIRT:0)
Block(-2,2,-5,DIRT:0)
Block(-2,2,-4,DIRT:0)
Block(-2,2,-3,DIRT:0)
Block(-2,2,-2,DIRT:0)
Block(-2,2,-1,DIRT:0)
Block(-2,2,0,DIRT:0)
Block(-2,2,1,DIRT:0)
Block(-2,2,2,DIRT:0)
Block(-2,2,3,DIRT:0)
Block(-2,2,4,DIRT:0)
Block(-2,2,5,DIRT:0)
Block(-2,2,6,DIRT:0)
Block(-2,2,7,GRASS:0)
Block(-2,2,8,GRASS:0)
Block(-2,3,-7,GRASS:0)
Block(-2,3,-6,GRASS:0)
Block(-2,3,-5,DIRT:0)
Block(-2,3,-4,DIRT:0)
Block(-2,3,-3,DIRT:0)
Block(-2,3,-2,DIRT:0)
Block(-2,3,-1,DIRT:0)
Block(-2,3,0,GRASS:0)
Block(-2,3,1,DIRT:0)
Block(-2,3,2,DIRT:0)
Block(-2,3,3,DIRT:0)
Block(-2,3,4,DIRT:0)
Block(-2,3,5,DIRT:0)
Block(-2,3,6,GRASS:0)
Block(-2,4,-5,GRASS:0)
Block(-2,4,-4,DIRT:0)
Block(-2,4,-3,DIRT:0)
Block(-2,4,-2,GRASS:0)
Block(-2,4,-1,GRASS:0)
Block(-2,4,1,GRASS:0)
Block(-2,4,2,GRASS:0)
Block(-2,4,3,GRASS:0)
Block(-2,4,4,GRASS:0)
Block(-2,4,5,GRASS:0)
Block(-2,5,-4,GRASS:0)
Block(-2,5,-3,GRASS:0)
Block(-1,0,-7,DIRT:0)
Block(-1,0,-6,DIRT:0)
Block(-1,0,-5,DIRT:0)
Block(-1,0,-4,DIRT:0)
Block(-1,0,-3,DIRT:0)
Block(-1,0,-2,DIRT:0)
Block(-1,0,-1,DIRT:0)
Block(-1,0,0,DIRT:0)
Block(-1,0,1,DIRT:0)
Block(-1,0,2,DIRT:0)
Block(-1,0,3,DIRT:0)
Block(-1,0,4,DIRT:0)
Block(-1,0,5,DIRT:0)
Block(-1,0,6,DIRT:0)
Block(-1,0,7,DIRT:0)
Block(-1,0,8,DIRT:0)
Block(-1,1,-7,DIRT:0)
Block(-1,1,-6,DIRT:0)
Block(-1,1,-5,DIRT:0)
Block(-1,1,-4,DIRT:0)
Block(-1,1,-3,DIRT:0)
Block(-1,1,-2,DIRT:0)
Block(-1,1,-1,DIRT:0)
Block(-1,1,0,DIRT:0)
Block(-1,1,1,DIRT:0)
Block(-1,1,2,DIRT:0)
Block(-1,1,3,DIRT:0)
Block(-1,1,4,DIRT:0)
Block(-1,1,5,DIRT:0)
Block(-1,1,6,DIRT:0)
Block(-1,1,7,DIRT:0)
Block(-1,1,8,DIRT:0)
Block(-1,2,-7,GRASS:0)
Block(-1,2,-6,GRASS:0)
Block(-1,2,-5,GRASS:0)
Block(-1,2,-4,GRASS:0)
Block(-1,2,-3,DIRT:0)
Block(-1,2,-2,DIRT:0)
Block(-1,2,-1,DIRT:0)
Block(-1,2,0,DIRT:0)
Block(-1,2,1,DIRT:0)
Block(-1,2,2,DIRT:0)
Block(-1,2,3,DIRT:0)
Block(-1,2,4,DIRT:0)
Block(-1,2,5,DIRT:0)
Block(-1,2,6,DIRT:0)
Block(-1,2,7,GRASS:0)
Block(-1,2,8,GRASS:0)
Block(-1,3,-3,GRASS:0)
Block(-1,3,-2,GRASS:0)
Block(-1,3,-1,GRASS:0)
Block(-1,3,0,GRASS:0)
Block(-1,3,1,GRASS:0)
Block(-1,3,2,DIRT:0)
Block(-1,3,3,GRASS:0)
Block(-1,3,4,GRASS:0)
Block(-1,3,5,GRASS:0)
Block(-1,3,6,GRASS:0)
Block(-1,4,2,GRASS:0)
Block(0,0,-7,DIRT:0)
Block(0,0,-6,DIRT:0)
Block(0,0,-5,DIRT:0)
Block(0,0,-4,DIRT:0)
Block(0,0,-3,DIRT:0)
Block(0,0,-2,DIRT:0)
Block(0,0,-1,DIRT:0)
Block(0,0,0,DIRT:0)
Block(0,0,1,DIRT:0)
Block(0,0,2,DIRT:0)
Block(0,0,3,DIRT:0)
Block(0,0,4,DIRT:0)
Block(0,0,5,DIRT:0)
Block(0,0,6,DIRT:0)
Block(0,0,7,DIRT:0)
Block(0,0,8,DIRT:0)
Block(0,1,-7,DIRT:0)
Block(0,1,-6,DIRT:0)
Block(0,1,-5,DIRT:0)
Block(0,1,-4,DIRT:0)
Block(0,1,-3,DIRT:0)
Block(0,1,-2,DIRT:0)
Block(0,1,-1,DIRT:0)
Block(0,1,0,DIRT:0)
Block(0,1,1,DIRT:0)
Block(0,1,2,DIRT:0)
Block(0,1,3,DIRT:0)
Block(0,1,4,DIRT:0)
Block(0,1,5,DIRT:0)
Block(0,1,6,DIRT:0)
Block(0,1,7,DIRT:0)
Block(0,1,8,DIRT:0)
Block(0,2,-7,GRASS:0)
Block(0,2,-6,DIRT:0)
Block(0,2,-5,DIRT:0)
Block(0,2,-4,DIRT:0)
Block(0,2,-3,GRASS:0)
Block(0,2,-2,DIRT:0)
Block(0,2,-1,DIRT:0)
Block(0,2,0,DIRT:0)
Block(0,2,1,DIRT:0)
Block(0,2,2,DIRT:0)
Block(0,2,3,DIRT:0)
Block(0,2,4,DIRT:0)
Block(0,2,5,DIRT:0)
Block(0,2,6,GRASS:0)
Block(0,2,7,GRASS:0)
Block(0,2,8,GRASS:0)
Block(0,3,-6,GRASS:0)
Block(0,3,-5,GRASS:0)
Block(0,3,-4,GRASS:0)
Block(0,3,-2,GRASS:0)
Block(0,3,-1,GRASS:0)
Block(0,3,0,GRASS:0)
Block(0,3,1,GRASS:0)
Block(0,3,2,GRASS:0)
Block(0,3,3,GRASS:0)
Block(0,3,4,GRASS:0)
Block(0,3,5,GRASS:0)
Block(1,0,-7,DIRT:0)
Block(1,0,-6,DIRT:0)
Block(1,0,-5,DIRT:0)
Block(1,0,-4,DIRT:0)
Block(1,0,-3,DIRT:0)
Block(1,0,-2,DIRT:0)
Block(1,0,-1,DIRT:0)
Block(1,0,0,DIRT:0)
Block(1,0,1,DIRT:0)
Block(1,0,2,DIRT:0)
Block(1,0,3,DIRT:0)
Block(1,0,4,DIRT:0)
Block(1,0,5,DIRT:0)
Block(1,0,6,DIRT:0)
Block(1,0,7,DIRT:0)
Block(1,0,8,DIRT:0)
Block(1,1,-7,DIRT:0)
Block(1,1,-6,DIRT:0)
Block(1,1,-5,DIRT:0)
Block(1,1,-4,DIRT:0)
Block(1,1,-3,DIRT:0)
Block(1,1,-2,DIRT:0)
Block(1,1,-1,DIRT:0)
Block(1,1,0,DIRT:0)
Block(1,1,1,DIRT:0)
Block(1,1,2,DIRT:0)
Block(1,1,3,DIRT:0)
Block(1,1,4,DIRT:0)
Block(1,1,5,DIRT:0)
Block(1,1,6,DIRT:0)
Block(1,1,7,DIRT:0)
Block(1,1,8,DIRT:0)
Block(1,2,-7,DIRT:0)
Block(1,2,-6,DIRT:0)
Block(1,2,-5,DIRT:0)
Block(1,2,-4,DIRT:0)
Block(1,2,-3,DIRT:0)
Block(1,2,-2,GRASS:0)
Block(1,2,-1,DIRT:0)
Block(1,2,0,DIRT:0)
Block(1,2,1,DIRT:0)
Block(1,2,2,DIRT:0)
Block(1,2,3,DIRT:0)
Block(1,2,4,DIRT:0)
Block(1,2,5,DIRT:0)
Block(1,2,6,DIRT:0)
Block(1,2,7,GRASS:0)
Block(1,2,8,GRASS:0)
Block(1,3,-7,GRASS:0)
Block(1,3,-6,GRASS:0)
Block(1,3,-5,GRASS:0)
Block(1,3,-4,GRASS:0)
Block(1,3,-3,GRASS:0)
Block(1,3,-1,GRASS:0)
Block(1,3,0,GRASS:0)
Block(1,3,1,GRASS:0)
Block(1,3,2,GRASS:0)
Block(1,3,3,GRASS:0)
Block(1,3,4,GRASS:0)
Block(1,3,5,GRASS:0)
Block(1,3,6,GRASS:0)
Block(2,0,-7,DIRT:0)
Block(2,0,-6,DIRT:0)
Block(2,0,-5,DIRT:0)
Block(2,0,-4,DIRT:0)
Block(2,0,-3,DIRT:0)
Block(2,0,-2,DIRT:0)
Block(2,0,-1,DIRT:0)
Block(2,0,0,DIRT:0)
Block(2,0,1,DIRT:0)
Block(2,0,2,DIRT:0)
Block(2,0,3,DIRT:0)
Block(2,0,4,DIRT:0)
Block(2,0,5,DIRT:0)
Block(2,0,6,DIRT:0)
Block(2,0,7,DIRT:0)
Block(2,0,8,DIRT:0)
Block(2,1,-7,DIRT:0)
Block(2,1,-6,DIRT:0)
Block(2,1,-5,DIRT:0)
Block(2,1,-4,DIRT:0)
Block(2,1,-3,DIRT:0)
Block(2,1,-2,DIRT:0)
Block(2,1,-1,DIRT:0)
Block(2,1,0,DIRT:0)
Block(2,1,1,DIRT:0)
Block(2,1,2,DIRT:0)
Block(2,1,3,DIRT:0)
Block(2,1,4,DIRT:0)
Block(2,1,5,DIRT:0)
Block(2,1,6,DIRT:0)
Block(2,1,7,DIRT:0)
Block(2,1,8,DIRT:0)
Block(2,2,-7,DIRT:0)
Block(2,2,-6,DIRT:0)
Block(2,2,-5,DIRT:0)
Block(2,2,-4,DIRT:0)
Block(2,2,-3,DIRT:0)
Block(2,2,-2,DIRT:0)
Block(2,2,-1,DIRT:0)
Block(2,2,0,DIRT:0)
Block(2,2,1,DIRT:0)
Block(2,2,2,DIRT:0)
Block(2,2,3,DIRT:0)
Block(2,2,4,DIRT:0)
Block(2,2,5,DIRT:0)
Block(2,2,6,DIRT:0)
Block(2,2,7,GRASS:0)
Block(2,2,8,GRASS:0)
Block(2,3,-7,GRASS:0)
Block(2,3,-6,GRASS:0)
Block(2,3,-5,GRASS:0)
Block(2,3,-4,GRASS:0)
Block(2,3,-3,GRASS:0)
Block(2,3,-2,GRASS:0)
Block(2,3,-1,GRASS:0)
Block(2,3,0,GRASS:0)
Block(2,3,1,GRASS:0)
Block(2,3,2,GRASS:0)
Block(2,3,3,GRASS:0)
Block(2,3,4,GRASS:0)
Block(2,3,5,GRASS:0)
Block(2,3,6,GRASS:0)
Block(3,0,-7,DIRT:0)
Block(3,0,-6,DIRT:0)
Block(3,0,-5,DIRT:0)
Block(3,0,-4,DIRT:0)
Block(3,0,-3,DIRT:0)
Block(3,0,-2,DIRT:0)
Block(3,0,-1,DIRT:0)
Block(3,0,0,DIRT:0)
Block(3,0,1,DIRT:0)
Block(3,0,2,DIRT:0)
Block(3,0,3,DIRT:0)
Block(3,0,4,DIRT:0)
Block(3,0,5,DIRT:0)
Block(3,0,6,DIRT:0)
Block(3,0,7,DIRT:0)
Block(3,0,8,DIRT:0)
Block(3,1,-7,DIRT:0)
Block(3,1,-6,DIRT:0)
Block(3,1,-5,DIRT:0)
Block(3,1,-4,DIRT:0)
Block(3,1,-3,DIRT:0)
Block(3,1,-2,DIRT:0)
Block(3,1,-1,DIRT:0)
Block(3,1,0,DIRT:0)
Block(3,1,1,DIRT:0)
Block(3,1,2,DIRT:0)
Block(3,1,3,DIRT:0)
Block(3,1,4,DIRT:0)
Block(3,1,5,DIRT:0)
Block(3,1,6,DIRT:0)
Block(3,1,7,DIRT:0)
Block(3,1,8,DIRT:0)
Block(3,2,-7,DIRT:0)
Block(3,2,-6,DIRT:0)
Block(3,2,-5,DIRT:0)
Block(3,2,-4,DIRT:0)
Block(3,2,-3,DIRT:0)
Block(3,2,-2,DIRT:0)
Block(3,2,-1,DIRT:0)
Block(3,2,0,DIRT:0)
Block(3,2,1,DIRT:0)
Block(3,2,2,DIRT:0)
Block(3,2,3,DIRT:0)
Block(3,2,4,DIRT:0)
Block(3,2,5,DIRT:0)
Block(3,2,6,DIRT:0)
Block(3,2,7,DIRT:0)
Block(3,2,8,DIRT:0)
Block(3,3,-7,GRASS:0)
Block(3,3,-6,GRASS:0)
Block(3,3,-5,GRASS:0)
Block(3,3,-4,GRASS:0)
Block(3,3,-3,GRASS:0)
Block(3,3,-2,GRASS:0)
Block(3,3,-1,GRASS:0)
Block(3,3,0,GRASS:0)
Block(3,3,1,GRASS:0)
Block(3,3,2,GRASS:0)
Block(3,3,3,GRASS:0)
Block(3,3,4,GRASS:0)
Block(3,3,5,GRASS:0)
Block(3,3,6,GRASS:0)
Block(3,3,7,GRASS:0)
Block(3,3,8,GRASS:0)
Block(4,0,-7,DIRT:0)
Block(4,0,-6,DIRT:0)
Block(4,0,-5,DIRT:0)
Block(4,0,-4,DIRT:0)
Block(4,0,-3,DIRT:0)
Block(4,0,-2,DIRT:0)
Block(4,0,-1,DIRT:0)
Block(4,0,0,DIRT:0)
Block(4,0,1,DIRT:0)
Block(4,0,2,DIRT:0)
Block(4,0,3,DIRT:0)
Block(4,0,4,DIRT:0)
Block(4,0,5,DIRT:0)
Block(4,0,6,DIRT:0)
Block(4,0,7,DIRT:0)
Block(4,0,8,DIRT:0)
Block(4,1,-7,DIRT:0)
Block(4,1,-6,DIRT:0)
Block(4,1,-5,DIRT:0)
Block(4,1,-4,DIRT:0)
Block(4,1,-3,DIRT:0)
Block(4,1,-2,DIRT:0)
Block(4,1,-1,DIRT:0)
Block(4,1,0,DIRT:0)
Block(4,1,1,DIRT:0)
Block(4,1,2,DIRT:0)
Block(4,1,3,DIRT:0)
Block(4,1,4,DIRT:0)
Block(4,1,5,DIRT:0)
Block(4,1,6,DIRT:0)
Block(4,1,7,DIRT:0)
Block(4,1,8,DIRT:0)
Block(4,2,-7,DIRT:0)
Block(4,2,-6,DIRT:0)
Block(4,2,-5,DIRT:0)
Block(4,2,-4,DIRT:0)
Block(4,2,-3,GRASS:0)
Block(4,2,-2,DIRT:0)
Block(4,2,-1,DIRT:0)
Block(4,2,0,DIRT:0)
Block(4,2,1,DIRT:0)
Block(4,2,2,DIRT:0)
Block(4,2,3,DIRT:0)
Block(4,2,4,DIRT:0)
Block(4,2,5,DIRT:0)
Block(4,2,6,DIRT:0)
Block(4,2,7,DIRT:0)
Block(4,2,8,DIRT:0)
Block(4,3,-7,DIRT:0)
Block(4,3,-6,GRASS:0)
Block(4,3,-5,GRASS:0)
Block(4,3,-4,GRASS:0)
Block(4,3,-2,GRASS:0)
Block(4,3,-1,GRASS:0)
Block(4,3,0,GRASS:0)
Block(4,3,1,GRASS:0)
Block(4,3,2,GRASS:0)
Block(4,3,3,GRASS:0)
Block(4,3,4,GRASS:0)
Block(4,3,5,GRASS:0)
Block(4,3,6,GRASS:0)
Block(4,3,7,DIRT:0)
Block(4,3,8,DIRT:0)
Block(4,4,-7,GRASS:0)
Block(4,4,7,GRASS:0)
Block(4,4,8,DIRT:0)
Block(4,5,8,DIRT:0)
Block(4,6,8,GRASS:0)
Block(5,0,-7,DIRT:0)
Block(5,0,-6,DIRT:0)
Block(5,0,-5,DIRT:0)
Block(5,0,-4,DIRT:0)
Block(5,0,-3,DIRT:0)
Block(5,0,-2,DIRT:0)
Block(5,0,-1,DIRT:0)
Block(5,0,0,DIRT:0)
Block(5,0,1,DIRT:0)
Block(5,0,2,DIRT:0)
Block(5,0,3,DIRT:0)
Block(5,0,4,DIRT:0)
Block(5,0,5,DIRT:0)
Block(5,0,6,DIRT:0)
Block(5,0,7,DIRT:0)
Block(5,0,8,DIRT:0)
Block(5,1,-7,DIRT:0)
Block(5,1,-6,DIRT:0)
Block(5,1,-5,DIRT:0)
Block(5,1,-4,DIRT:0)
Block(5,1,-3,DIRT:0)
Block(5,1,-2,DIRT:0)
Block(5,1,-1,DIRT:0)
Block(5,1,0,DIRT:0)
Block(5,1,1,DIRT:0)
Block(5,1,2,DIRT:0)
Block(5,1,3,DIRT:0)
Block(5,1,4,DIRT:0)
Block(5,1,5,DIRT:0)
Block(5,1,6,DIRT:0)
Block(5,1,7,DIRT:0)
Block(5,1,8,DIRT:0)
Block(5,2,-7,DIRT:0)
Block(5,2,-6,DIRT:0)
Block(5,2,-5,DIRT:0)
Block(5,2,-4,DIRT:0)
Block(5,2,-3,DIRT:0)
Block(5,2,-2,DIRT:0)
Block(5,2,-1,DIRT:0)
Block(5,2,0,DIRT:0)
Block(5,2,1,DIRT:0)
Block(5,2,2,DIRT:0)
Block(5,2,3,DIRT:0)
Block(5,2,4,DIRT:0)
Block(5,2,5,DIRT:0)
Block(5,2,6,DIRT:0)
Block(5,2,7,DIRT:0)
Block(5,2,8,DIRT:0)
Block(5,3,-7,DIRT:0)
Block(5,3,-6,DIRT:0)
Block(5,3,-5,GRASS:0)
Block(5,3,-4,GRASS:0)
Block(5,3,-3,GRASS:0)
Block(5,3,-2,GRASS:0)
Block(5,3,-1,GRASS:0)
Block(5,3,0,GRASS:0)
Block(5,3,1,GRASS:0)
Block(5,3,2,DIRT:0)
Block(5,3,3,DIRT:0)
Block(5,3,4,DIRT:0)
Block(5,3,5,DIRT:0)
Block(5,3,6,DIRT:0)
Block(5,3,7,DIRT:0)
Block(5,3,8,DIRT:0)
Block(5,4,-7,DIRT:0)
Block(5,4,-6,DIRT:0)
Block(5,4,2,GRASS:0)
Block(5,4,3,GRASS:0)
Block(5,4,4,GRASS:0)
Block(5,4,5,GRASS:0)
Block(5,4,6,GRASS:0)
Block(5,4,7,DIRT:0)
Block(5,4,8,DIRT:0)
Block(5,5,-7,GRASS:0)
Block(5,5,-6,GRASS:0)
Block(5,5,7,DIRT:0)
Block(5,5,8,DIRT:0)
Block(5,6,7,GRASS:0)
Block(5,6,8,DIRT:0)
Block(5,7,8,GRASS:0)
Block(6,0,-7,DIRT:0)
Block(6,0,-6,DIRT:0)
Block(6,0,-5,DIRT:0)
Block(6,0,-4,DIRT:0)
Block(6,0,-3,DIRT:0)
Block(6,0,-2,DIRT:0)
Block(6,0,-1,DIRT:0)
Block(6,0,0,DIRT:0)
Block(6,0,1,DIRT:0)
Block(6,0,2,DIRT:0)
Block(6,0,3,DIRT:0)
Block(6,0,4,DIRT:0)
Block(6,0,5,DIRT:0)
Block(6,0,6,DIRT:0)
Block(6,0,7,DIRT:0)
Block(6,0,8,DIRT:0)
Block(6,1,-7,DIRT:0)
Block(6,1,-6,DIRT:0)
Block(6,1,-5,DIRT:0)
Block(6,1,-4,DIRT:0)
Block(6,1,-3,DIRT:0)
Block(6,1,-2,DIRT:0)
Block(6,1,-1,DIRT:0)
Block(6,1,0,DIRT:0)
Block(6,1,1,DIRT:0)
Block(6,1,2,DIRT:0)
Block(6,1,3,DIRT:0)
Block(6,1,4,DIRT:0)
Block(6,1,5,DIRT:0)
Block(6,1,6,DIRT:0)
Block(6,1,7,DIRT:0)
Block(6,1,8,DIRT:0)
Block(6,2,-7,DIRT:0)
Block(6,2,-6,DIRT:0)
Block(6,2,-5,DIRT:0)
Block(6,2,-4,DIRT:0)
Block(6,2,-3,DIRT:0)
Block(6,2,-2,DIRT:0)
Block(6,2,-1,DIRT:0)
Block(6,2,0,DIRT:0)
Block(6,2,1,DIRT:0)
Block(6,2,2,DIRT:0)
Block(6,2,3,DIRT:0)
Block(6,2,4,DIRT:0)
Block(6,2,5,DIRT:0)
Block(6,2,6,DIRT:0)
Block(6,2,7,DIRT:0)
Block(6,2,8,DIRT:0)
Block(6,3,-7,DIRT:0)
Block(6,3,-6,DIRT:0)
Block(6,3,-5,DIRT:0)
Block(6,3,-4,GRASS:0)
Block(6,3,-3,GRASS:0)
Block(6,3,-2,GRASS:0)
Block(6,3,-1,GRASS:0)
Block(6,3,0,GRASS:0)
Block(6,3,1,DIRT:0)
Block(6,3,2,DIRT:0)
Block(6,3,3,DIRT:0)
Block(6,3,4,DIRT:0)
Block(6,3,5,DIRT:0)
Block(6,3,6,DIRT:0)
Block(6,3,7,DIRT:0)
Block(6,3,8,DIRT:0)
Block(6,4,-7,DIRT:0)
Block(6,4,-6,DIRT:0)
Block(6,4,-5,GRASS:0)
Block(6,4,1,GRASS:0)
Block(6,4,2,GRASS:0)
Block(6,4,3,GRASS:0)
Block(6,4,4,GRASS:0)
Block(6,4,5,GRASS:0)
Block(6,4,6,GRASS:0)
Block(6,4,7,DIRT:0)
Block(6,4,8,DIRT:0)
Block(6,5,-7,GRASS:0)
Block(6,5,-6,GRASS:0)
Block(6,5,7,DIRT:0)
Block(6,5,8,DIRT:0)
Block(6,6,7,GRASS:0)
Block(6,6,8,DIRT:0)
Block(6,7,8,DIRT:0)
Block(6,8,8,STONE:6)
Block(6,9,8,STONE:6)
Block(7,0,-7,DIRT:0)
Block(7,0,-6,DIRT:0)
Block(7,0,-5,DIRT:0)
Block(7,0,-4,DIRT:0)
Block(7,0,-3,DIRT:0)
Block(7,0,-2,DIRT:0)
Block(7,0,-1,DIRT:0)
Block(7,0,0,DIRT:0)
Block(7,0,1,DIRT:0)
Block(7,0,2,DIRT:0)
Block(7,0,3,DIRT:0)
Block(7,0,4,DIRT:0)
Block(7,0,5,DIRT:0)
Block(7,0,6,DIRT:0)
Block(7,0,7,DIRT:0)
Block(7,0,8,DIRT:0)
Block(7,1,-7,DIRT:0)
Block(7,1,-6,DIRT:0)
Block(7,1,-5,DIRT:0)
Block(7,1,-4,DIRT:0)
Block(7,1,-3,DIRT:0)
Block(7,1,-2,DIRT:0)
Block(7,1,-1,DIRT:0)
Block(7,1,0,DIRT:0)
Block(7,1,1,DIRT:0)
Block(7,1,2,DIRT:0)
Block(7,1,3,DIRT:0)
Block(7,1,4,DIRT:0)
Block(7,1,5,DIRT:0)
Block(7,1,6,DIRT:0)
Block(7,1,7,DIRT:0)
Block(7,1,8,DIRT:0)
Block(7,2,-7,DIRT:0)
Block(7,2,-6,DIRT:0)
Block(7,2,-5,DIRT:0)
Block(7,2,-4,DIRT:0)
Block(7,2,-3,DIRT:0)
Block(7,2,-2,DIRT:0)
Block(7,2,-1,DIRT:0)
Block(7,2,0,DIRT:0)
Block(7,2,1,DIRT:0)
Block(7,2,2,DIRT:0)
Block(7,2,3,DIRT:0)
Block(7,2,4,DIRT:0)
Block(7,2,5,DIRT:0)
Block(7,2,6,DIRT:0)
Block(7,2,7,DIRT:0)
Block(7,2,8,DIRT:0)
Block(7,3,-7,DIRT:0)
Block(7,3,-6,DIRT:0)
Block(7,3,-5,DIRT:0)
Block(7,3,-4,DIRT:0)
Block(7,3,-3,DIRT:0)
Block(7,3,-2,GRASS:0)
Block(7,3,-1,GRASS:0)
Block(7,3,0,DIRT:0)
Block(7,3,1,DIRT:0)
Block(7,3,2,DIRT:0)
Block(7,3,3,DIRT:0)
Block(7,3,4,DIRT:0)
Block(7,3,5,DIRT:0)
Block(7,3,6,DIRT:0)
Block(7,3,7,DIRT:0)
Block(7,3,8,DIRT:0)
Block(7,4,-7,DIRT:0)
Block(7,4,-6,DIRT:0)
Block(7,4,-5,GRASS:0)
Block(7,4,-4,GRASS:0)
Block(7,4,-3,GRASS:0)
Block(7,4,0,GRASS:0)
Block(7,4,1,GRASS:0)
Block(7,4,2,GRASS:0)
Block(7,4,3,GRASS:0)
Block(7,4,4,GRASS:0)
Block(7,4,5,DIRT:0)
Block(7,4,6,DIRT:0)
Block(7,4,7,DIRT:0)
Block(7,4,8,DIRT:0)
Block(7,5,-7,DIRT:0)
Block(7,5,-6,GRASS:0)
Block(7,5,5,GRASS:0)
Block(7,5,6,DIRT:0)
Block(7,5,7,DIRT:0)
Block(7,5,8,DIRT:0)
Block(7,6,-7,GRASS:0)
Block(7,6,6,GRASS:0)
Block(7,6,7,DIRT:0)
Block(7,6,8,DIRT:0)
Block(7,7,7,GRASS:0)
Block(7,7,8,DIRT:0)
Block(7,8,8,STONE:6)
Block(7,9,8,STONE:6)
Block(7,10,8,STONE:6)
Block(7,11,8,STONE:6)

#######################################################################
# +-----------------------------------------------------------------+ #
# |                             Branches                            | #
# +-----------------------------------------------------------------+ #
#######################################################################

Branch(0,0,-16,true,SpawnHexC7R6,NORTH,100.0,0)

#######################################################################
# +-----------------------------------------------------------------+ #
# |                             Entities                            | #
# +-----------------------------------------------------------------+ #
#######################################################################


#######################################################################
# +-----------------------------------------------------------------+ #
# |                            Particles                            | #
# +-----------------------------------------------------------------+ #
#######################################################################


#######################################################################
# +-----------------------------------------------------------------+ #
# |                             Spawners                            | #
# +-----------------------------------------------------------------+ #
#######################################################################


#######################################################################
# +-----------------------------------------------------------------+ #
# |                             ModData                             | #
# +-----------------------------------------------------------------+ #
#######################################################################

