
#######################################################################
# +-----------------------------------------------------------------+ #
# |                            BO4 object                           | #
# +-----------------------------------------------------------------+ #
#######################################################################

Author: NLBlackEagle

Description: No description given

SettingsMode: WriteWithoutComments


#######################################################################
# +-----------------------------------------------------------------+ #
# |                          Main settings                          | #
# +-----------------------------------------------------------------+ #
#######################################################################

Frequency: 0

SpawnHeight: highestBlock

UseCenterForHighestBlock: true

##############################
# Height Limits for the BO4. #
##############################

MinHeight: 0

MaxHeight: 255

InheritBO3: 

InheritBO3Rotation: NORTH

OverrideChildSettings: true

OverrideParentHeight: false

CanOverride: false

BranchFrequency: 0

BranchFrequencyGroup: 

MustBeBelowOther: false

MustBeInside: 

CannotBeInside: 

ReplacesBO3: 

MustBeInsideWorldBorders: false

CanSpawnOnWater: true

SpawnOnWaterOnly: false

SpawnUnderWater: false

SpawnAtWaterLevel: false

HeightOffset: 0

RemoveAir: true

ReplaceAbove: 

ReplaceBelow: 

ReplaceWithBiomeBlocks: true

ReplaceWithSurfaceBlock: GRASS

ReplaceWithGroundBlock: DIRT

ReplaceWithStoneBlock: STONE

SmoothRadius: 0

SmoothHeightOffset: 0

SmoothStartTop: false

SmoothStartWood: false

SmoothingSurfaceBlock: 

SmoothingGroundBlock: 

BO3Group: 

IsSpawnPoint: false

DoReplaceBlocks: true


#######################################################################
# +-----------------------------------------------------------------+ #
# |                              Blocks                             | #
# +-----------------------------------------------------------------+ #
#######################################################################

Block(-8,0,-7,DIRT:0)
Block(-8,0,-6,DIRT:0)
Block(-8,0,-5,DIRT:0)
Block(-8,0,-4,DIRT:0)
Block(-8,0,-3,DIRT:0)
Block(-8,0,-2,DIRT:0)
Block(-8,0,-1,DIRT:0)
Block(-8,0,0,DIRT:0)
Block(-8,0,1,DIRT:0)
Block(-8,0,2,DIRT:0)
Block(-8,0,3,DIRT:0)
Block(-8,0,4,DIRT:0)
Block(-8,0,5,DIRT:0)
Block(-8,0,6,DIRT:0)
Block(-8,0,7,DIRT:0)
Block(-8,0,8,DIRT:0)
Block(-8,1,-7,SAND:0)
Block(-8,1,-6,SAND:0)
Block(-8,1,-5,SAND:0)
Block(-8,1,-4,SAND:0)
Block(-8,1,-3,SAND:0)
Block(-8,1,-2,SAND:0)
Block(-8,1,-1,SAND:0)
Block(-8,1,0,SAND:0)
Block(-8,1,1,SAND:0)
Block(-8,1,2,SAND:0)
Block(-8,1,3,SAND:0)
Block(-8,1,4,SAND:0)
Block(-8,1,5,SAND:0)
Block(-8,1,6,SAND:0)
Block(-8,1,7,SAND:0)
Block(-8,1,8,SAND:0)
Block(-8,2,-7,SAND:0)
Block(-8,2,-6,SAND:0)
Block(-8,2,-5,SAND:0)
Block(-8,2,-4,SAND:0)
Block(-8,2,-3,SAND:0)
Block(-8,2,-2,SAND:0)
Block(-8,2,-1,SAND:0)
Block(-8,2,0,SAND:0)
Block(-8,2,1,SAND:0)
Block(-8,2,2,SAND:0)
Block(-8,2,3,SAND:0)
Block(-8,2,4,SAND:0)
Block(-8,2,5,SAND:0)
Block(-8,2,6,SAND:0)
Block(-8,2,7,SAND:0)
Block(-8,2,8,SAND:0)
Block(-8,3,-7,STATIONARY_WATER:0)
Block(-8,3,-6,STATIONARY_WATER:0)
Block(-8,3,-5,STATIONARY_WATER:0)
Block(-8,3,-4,SAND:0)
Block(-8,3,-3,SAND:0)
Block(-8,3,-2,SAND:0)
Block(-8,3,-1,SAND:0)
Block(-8,3,0,SAND:0)
Block(-8,3,1,SAND:0)
Block(-8,3,2,SAND:0)
Block(-8,3,3,SAND:0)
Block(-8,3,4,SAND:0)
Block(-8,3,5,SAND:0)
Block(-8,3,6,SAND:0)
Block(-8,3,7,SAND:0)
Block(-8,3,8,SAND:0)
Block(-8,4,-7,STATIONARY_WATER:0)
Block(-8,4,-6,STATIONARY_WATER:0)
Block(-8,4,-5,STATIONARY_WATER:0)
Block(-8,4,-4,STATIONARY_WATER:0)
Block(-8,4,-3,STATIONARY_WATER:0)
Block(-8,4,-2,STATIONARY_WATER:0)
Block(-8,4,-1,STATIONARY_WATER:0)
Block(-8,4,0,STATIONARY_WATER:0)
Block(-8,4,1,STATIONARY_WATER:0)
Block(-8,4,2,STATIONARY_WATER:0)
Block(-8,4,3,STATIONARY_WATER:0)
Block(-8,4,4,STATIONARY_WATER:0)
Block(-8,4,5,STATIONARY_WATER:0)
Block(-8,4,6,STATIONARY_WATER:0)
Block(-8,4,7,STATIONARY_WATER:0)
Block(-8,4,8,STATIONARY_WATER:0)
Block(-8,5,-7,STATIONARY_WATER:0)
Block(-8,5,-6,STATIONARY_WATER:0)
Block(-8,5,-5,STATIONARY_WATER:0)
Block(-8,5,-4,STATIONARY_WATER:0)
Block(-8,5,-3,STATIONARY_WATER:0)
Block(-8,5,-2,STATIONARY_WATER:0)
Block(-8,5,-1,STATIONARY_WATER:0)
Block(-8,5,0,STATIONARY_WATER:0)
Block(-8,5,1,STATIONARY_WATER:0)
Block(-8,5,2,STATIONARY_WATER:0)
Block(-8,5,3,STATIONARY_WATER:0)
Block(-8,5,4,STATIONARY_WATER:0)
Block(-8,5,5,STATIONARY_WATER:0)
Block(-8,5,6,STATIONARY_WATER:0)
Block(-8,5,7,STATIONARY_WATER:0)
Block(-8,5,8,STATIONARY_WATER:0)
Block(-8,6,-7,STATIONARY_WATER:0)
Block(-8,6,-6,STATIONARY_WATER:0)
Block(-8,6,-5,STATIONARY_WATER:0)
Block(-8,6,-4,STATIONARY_WATER:0)
Block(-8,6,-3,STATIONARY_WATER:0)
Block(-8,6,-2,STATIONARY_WATER:0)
Block(-8,6,-1,STATIONARY_WATER:0)
Block(-8,6,0,STATIONARY_WATER:0)
Block(-8,6,1,STATIONARY_WATER:0)
Block(-8,6,2,STATIONARY_WATER:0)
Block(-8,6,3,STATIONARY_WATER:0)
Block(-8,6,4,STATIONARY_WATER:0)
Block(-8,6,5,STATIONARY_WATER:0)
Block(-8,6,6,STATIONARY_WATER:0)
Block(-8,6,7,STATIONARY_WATER:0)
Block(-8,6,8,STATIONARY_WATER:0)
Block(-8,7,-7,STATIONARY_WATER:0)
Block(-8,7,-6,STATIONARY_WATER:0)
Block(-8,7,-5,STATIONARY_WATER:0)
Block(-8,7,-4,STATIONARY_WATER:0)
Block(-8,7,-3,STATIONARY_WATER:0)
Block(-8,7,-2,STATIONARY_WATER:0)
Block(-8,7,-1,STATIONARY_WATER:0)
Block(-8,7,0,STATIONARY_WATER:0)
Block(-8,7,1,STATIONARY_WATER:0)
Block(-8,7,2,STATIONARY_WATER:0)
Block(-8,7,3,STATIONARY_WATER:0)
Block(-8,7,4,STATIONARY_WATER:0)
Block(-8,7,5,STATIONARY_WATER:0)
Block(-8,7,6,STATIONARY_WATER:0)
Block(-8,7,7,STATIONARY_WATER:0)
Block(-8,7,8,STATIONARY_WATER:0)
Block(-8,8,-7,STATIONARY_WATER:0)
Block(-8,8,-6,STATIONARY_WATER:0)
Block(-8,8,-5,STATIONARY_WATER:0)
Block(-8,8,-4,STATIONARY_WATER:0)
Block(-8,8,-3,STATIONARY_WATER:0)
Block(-8,8,-2,STATIONARY_WATER:0)
Block(-8,8,-1,STATIONARY_WATER:0)
Block(-8,8,0,STATIONARY_WATER:0)
Block(-8,8,1,STATIONARY_WATER:0)
Block(-8,8,2,STATIONARY_WATER:0)
Block(-8,8,3,STATIONARY_WATER:0)
Block(-8,8,4,STATIONARY_WATER:0)
Block(-8,8,5,STATIONARY_WATER:0)
Block(-8,8,6,STATIONARY_WATER:0)
Block(-8,8,7,STATIONARY_WATER:0)
Block(-8,8,8,STATIONARY_WATER:0)
Block(-8,9,-7,STATIONARY_WATER:0)
Block(-8,9,-6,STATIONARY_WATER:0)
Block(-8,9,-5,STATIONARY_WATER:0)
Block(-8,9,-4,STATIONARY_WATER:0)
Block(-8,9,-3,STATIONARY_WATER:0)
Block(-8,9,-2,STATIONARY_WATER:0)
Block(-8,9,-1,STATIONARY_WATER:0)
Block(-8,9,0,STATIONARY_WATER:0)
Block(-8,9,1,STATIONARY_WATER:0)
Block(-8,9,2,STATIONARY_WATER:0)
Block(-8,9,3,STATIONARY_WATER:0)
Block(-8,9,4,STATIONARY_WATER:0)
Block(-8,9,5,STATIONARY_WATER:0)
Block(-8,9,6,STATIONARY_WATER:0)
Block(-8,9,7,STATIONARY_WATER:0)
Block(-8,9,8,STATIONARY_WATER:0)
Block(-8,10,-7,STATIONARY_WATER:0)
Block(-8,10,-6,STATIONARY_WATER:0)
Block(-8,10,-5,STATIONARY_WATER:0)
Block(-8,10,-4,STATIONARY_WATER:0)
Block(-8,10,-3,STATIONARY_WATER:0)
Block(-8,10,-2,STATIONARY_WATER:0)
Block(-8,10,-1,STATIONARY_WATER:0)
Block(-8,10,0,STATIONARY_WATER:0)
Block(-8,10,1,STATIONARY_WATER:0)
Block(-8,10,2,STATIONARY_WATER:0)
Block(-8,10,3,STATIONARY_WATER:0)
Block(-8,10,4,STATIONARY_WATER:0)
Block(-8,10,5,STATIONARY_WATER:0)
Block(-8,10,6,STATIONARY_WATER:0)
Block(-8,10,7,STATIONARY_WATER:0)
Block(-8,10,8,STATIONARY_WATER:0)
Block(-8,11,-7,STATIONARY_WATER:0)
Block(-8,11,-6,STATIONARY_WATER:0)
Block(-8,11,-5,STATIONARY_WATER:0)
Block(-8,11,-4,STATIONARY_WATER:0)
Block(-8,11,-3,STATIONARY_WATER:0)
Block(-8,11,-2,STATIONARY_WATER:0)
Block(-8,11,-1,STATIONARY_WATER:0)
Block(-8,11,0,STATIONARY_WATER:0)
Block(-8,11,1,STATIONARY_WATER:0)
Block(-8,11,2,STATIONARY_WATER:0)
Block(-8,11,3,STATIONARY_WATER:0)
Block(-8,11,4,STATIONARY_WATER:0)
Block(-8,11,5,ICE:0)
Block(-8,11,6,ICE:0)
Block(-8,11,7,ICE:0)
Block(-8,11,8,ICE:0)
Block(-8,12,7,ICE:0)
Block(-8,12,8,ICE:0)
Block(-8,13,7,PACKED_ICE:0)
Block(-8,13,8,PACKED_ICE:0)
Block(-7,0,-7,DIRT:0)
Block(-7,0,-6,DIRT:0)
Block(-7,0,-5,DIRT:0)
Block(-7,0,-4,DIRT:0)
Block(-7,0,-3,DIRT:0)
Block(-7,0,-2,DIRT:0)
Block(-7,0,-1,DIRT:0)
Block(-7,0,0,DIRT:0)
Block(-7,0,1,DIRT:0)
Block(-7,0,2,DIRT:0)
Block(-7,0,3,DIRT:0)
Block(-7,0,4,DIRT:0)
Block(-7,0,5,DIRT:0)
Block(-7,0,6,DIRT:0)
Block(-7,0,7,DIRT:0)
Block(-7,0,8,DIRT:0)
Block(-7,1,-7,SAND:0)
Block(-7,1,-6,SAND:0)
Block(-7,1,-5,SAND:0)
Block(-7,1,-4,SAND:0)
Block(-7,1,-3,SAND:0)
Block(-7,1,-2,SAND:0)
Block(-7,1,-1,SAND:0)
Block(-7,1,0,SAND:0)
Block(-7,1,1,SAND:0)
Block(-7,1,2,SAND:0)
Block(-7,1,3,SAND:0)
Block(-7,1,4,SAND:0)
Block(-7,1,5,SAND:0)
Block(-7,1,6,SAND:0)
Block(-7,1,7,SAND:0)
Block(-7,1,8,SAND:0)
Block(-7,2,-7,SAND:0)
Block(-7,2,-6,SAND:0)
Block(-7,2,-5,SAND:0)
Block(-7,2,-4,SAND:0)
Block(-7,2,-3,SAND:0)
Block(-7,2,-2,SAND:0)
Block(-7,2,-1,SAND:0)
Block(-7,2,0,SAND:0)
Block(-7,2,1,SAND:0)
Block(-7,2,2,SAND:0)
Block(-7,2,3,SAND:0)
Block(-7,2,4,SAND:0)
Block(-7,2,5,SAND:0)
Block(-7,2,6,SAND:0)
Block(-7,2,7,SAND:0)
Block(-7,2,8,SAND:0)
Block(-7,3,-7,STATIONARY_WATER:0)
Block(-7,3,-6,STATIONARY_WATER:0)
Block(-7,3,-5,STATIONARY_WATER:0)
Block(-7,3,-4,SAND:0)
Block(-7,3,-3,SAND:0)
Block(-7,3,-2,SAND:0)
Block(-7,3,-1,SAND:0)
Block(-7,3,0,SAND:0)
Block(-7,3,1,SAND:0)
Block(-7,3,2,SAND:0)
Block(-7,3,3,SAND:0)
Block(-7,3,4,SAND:0)
Block(-7,3,5,SAND:0)
Block(-7,3,6,SAND:0)
Block(-7,3,7,SAND:0)
Block(-7,3,8,SAND:0)
Block(-7,4,-7,STATIONARY_WATER:0)
Block(-7,4,-6,STATIONARY_WATER:0)
Block(-7,4,-5,STATIONARY_WATER:0)
Block(-7,4,-4,STATIONARY_WATER:0)
Block(-7,4,-3,STATIONARY_WATER:0)
Block(-7,4,-2,STATIONARY_WATER:0)
Block(-7,4,-1,STATIONARY_WATER:0)
Block(-7,4,0,STATIONARY_WATER:0)
Block(-7,4,1,STATIONARY_WATER:0)
Block(-7,4,2,STATIONARY_WATER:0)
Block(-7,4,3,STATIONARY_WATER:0)
Block(-7,4,4,STATIONARY_WATER:0)
Block(-7,4,5,STATIONARY_WATER:0)
Block(-7,4,6,STATIONARY_WATER:0)
Block(-7,4,7,STATIONARY_WATER:0)
Block(-7,4,8,STATIONARY_WATER:0)
Block(-7,5,-7,STATIONARY_WATER:0)
Block(-7,5,-6,STATIONARY_WATER:0)
Block(-7,5,-5,STATIONARY_WATER:0)
Block(-7,5,-4,STATIONARY_WATER:0)
Block(-7,5,-3,STATIONARY_WATER:0)
Block(-7,5,-2,STATIONARY_WATER:0)
Block(-7,5,-1,STATIONARY_WATER:0)
Block(-7,5,0,STATIONARY_WATER:0)
Block(-7,5,1,STATIONARY_WATER:0)
Block(-7,5,2,STATIONARY_WATER:0)
Block(-7,5,3,STATIONARY_WATER:0)
Block(-7,5,4,STATIONARY_WATER:0)
Block(-7,5,5,STATIONARY_WATER:0)
Block(-7,5,6,STATIONARY_WATER:0)
Block(-7,5,7,STATIONARY_WATER:0)
Block(-7,5,8,STATIONARY_WATER:0)
Block(-7,6,-7,STATIONARY_WATER:0)
Block(-7,6,-6,STATIONARY_WATER:0)
Block(-7,6,-5,STATIONARY_WATER:0)
Block(-7,6,-4,STATIONARY_WATER:0)
Block(-7,6,-3,STATIONARY_WATER:0)
Block(-7,6,-2,STATIONARY_WATER:0)
Block(-7,6,-1,STATIONARY_WATER:0)
Block(-7,6,0,STATIONARY_WATER:0)
Block(-7,6,1,STATIONARY_WATER:0)
Block(-7,6,2,STATIONARY_WATER:0)
Block(-7,6,3,STATIONARY_WATER:0)
Block(-7,6,4,STATIONARY_WATER:0)
Block(-7,6,5,STATIONARY_WATER:0)
Block(-7,6,6,STATIONARY_WATER:0)
Block(-7,6,7,STATIONARY_WATER:0)
Block(-7,6,8,STATIONARY_WATER:0)
Block(-7,7,-7,STATIONARY_WATER:0)
Block(-7,7,-6,STATIONARY_WATER:0)
Block(-7,7,-5,STATIONARY_WATER:0)
Block(-7,7,-4,STATIONARY_WATER:0)
Block(-7,7,-3,STATIONARY_WATER:0)
Block(-7,7,-2,STATIONARY_WATER:0)
Block(-7,7,-1,STATIONARY_WATER:0)
Block(-7,7,0,STATIONARY_WATER:0)
Block(-7,7,1,STATIONARY_WATER:0)
Block(-7,7,2,STATIONARY_WATER:0)
Block(-7,7,3,STATIONARY_WATER:0)
Block(-7,7,4,STATIONARY_WATER:0)
Block(-7,7,5,STATIONARY_WATER:0)
Block(-7,7,6,STATIONARY_WATER:0)
Block(-7,7,7,STATIONARY_WATER:0)
Block(-7,7,8,STATIONARY_WATER:0)
Block(-7,8,-7,STATIONARY_WATER:0)
Block(-7,8,-6,STATIONARY_WATER:0)
Block(-7,8,-5,STATIONARY_WATER:0)
Block(-7,8,-4,STATIONARY_WATER:0)
Block(-7,8,-3,STATIONARY_WATER:0)
Block(-7,8,-2,STATIONARY_WATER:0)
Block(-7,8,-1,STATIONARY_WATER:0)
Block(-7,8,0,STATIONARY_WATER:0)
Block(-7,8,1,STATIONARY_WATER:0)
Block(-7,8,2,STATIONARY_WATER:0)
Block(-7,8,3,STATIONARY_WATER:0)
Block(-7,8,4,STATIONARY_WATER:0)
Block(-7,8,5,STATIONARY_WATER:0)
Block(-7,8,6,STATIONARY_WATER:0)
Block(-7,8,7,STATIONARY_WATER:0)
Block(-7,8,8,STATIONARY_WATER:0)
Block(-7,9,-7,STATIONARY_WATER:0)
Block(-7,9,-6,STATIONARY_WATER:0)
Block(-7,9,-5,STATIONARY_WATER:0)
Block(-7,9,-4,STATIONARY_WATER:0)
Block(-7,9,-3,STATIONARY_WATER:0)
Block(-7,9,-2,STATIONARY_WATER:0)
Block(-7,9,-1,STATIONARY_WATER:0)
Block(-7,9,0,STATIONARY_WATER:0)
Block(-7,9,1,STATIONARY_WATER:0)
Block(-7,9,2,STATIONARY_WATER:0)
Block(-7,9,3,STATIONARY_WATER:0)
Block(-7,9,4,STATIONARY_WATER:0)
Block(-7,9,5,STATIONARY_WATER:0)
Block(-7,9,6,STATIONARY_WATER:0)
Block(-7,9,7,STATIONARY_WATER:0)
Block(-7,9,8,STATIONARY_WATER:0)
Block(-7,10,-7,STATIONARY_WATER:0)
Block(-7,10,-6,STATIONARY_WATER:0)
Block(-7,10,-5,STATIONARY_WATER:0)
Block(-7,10,-4,STATIONARY_WATER:0)
Block(-7,10,-3,STATIONARY_WATER:0)
Block(-7,10,-2,STATIONARY_WATER:0)
Block(-7,10,-1,STATIONARY_WATER:0)
Block(-7,10,0,STATIONARY_WATER:0)
Block(-7,10,1,STATIONARY_WATER:0)
Block(-7,10,2,STATIONARY_WATER:0)
Block(-7,10,3,STATIONARY_WATER:0)
Block(-7,10,4,STATIONARY_WATER:0)
Block(-7,10,5,STATIONARY_WATER:0)
Block(-7,10,6,STATIONARY_WATER:0)
Block(-7,10,7,STATIONARY_WATER:0)
Block(-7,10,8,STATIONARY_WATER:0)
Block(-7,11,-7,STATIONARY_WATER:0)
Block(-7,11,-6,STATIONARY_WATER:0)
Block(-7,11,-5,STATIONARY_WATER:0)
Block(-7,11,-4,STATIONARY_WATER:0)
Block(-7,11,-3,STATIONARY_WATER:0)
Block(-7,11,-2,STATIONARY_WATER:0)
Block(-7,11,-1,STATIONARY_WATER:0)
Block(-7,11,0,STATIONARY_WATER:0)
Block(-7,11,1,STATIONARY_WATER:0)
Block(-7,11,2,STATIONARY_WATER:0)
Block(-7,11,3,STATIONARY_WATER:0)
Block(-7,11,4,STATIONARY_WATER:0)
Block(-7,11,5,STATIONARY_WATER:0)
Block(-7,11,6,ICE:0)
Block(-7,11,7,PACKED_ICE:0)
Block(-7,11,8,PACKED_ICE:0)
Block(-7,12,7,PACKED_ICE:0)
Block(-7,12,8,PACKED_ICE:0)
Block(-7,13,8,PACKED_ICE:0)
Block(-6,0,-7,DIRT:0)
Block(-6,0,-6,DIRT:0)
Block(-6,0,-5,DIRT:0)
Block(-6,0,-4,DIRT:0)
Block(-6,0,-3,DIRT:0)
Block(-6,0,-2,DIRT:0)
Block(-6,0,-1,DIRT:0)
Block(-6,0,0,DIRT:0)
Block(-6,0,1,DIRT:0)
Block(-6,0,2,DIRT:0)
Block(-6,0,3,DIRT:0)
Block(-6,0,4,DIRT:0)
Block(-6,0,5,DIRT:0)
Block(-6,0,6,DIRT:0)
Block(-6,0,7,DIRT:0)
Block(-6,0,8,DIRT:0)
Block(-6,1,-7,SAND:0)
Block(-6,1,-6,SAND:0)
Block(-6,1,-5,SAND:0)
Block(-6,1,-4,SAND:0)
Block(-6,1,-3,SAND:0)
Block(-6,1,-2,SAND:0)
Block(-6,1,-1,SAND:0)
Block(-6,1,0,SAND:0)
Block(-6,1,1,SAND:0)
Block(-6,1,2,SAND:0)
Block(-6,1,3,SAND:0)
Block(-6,1,4,SAND:0)
Block(-6,1,5,SAND:0)
Block(-6,1,6,SAND:0)
Block(-6,1,7,SAND:0)
Block(-6,1,8,SAND:0)
Block(-6,2,-7,SAND:0)
Block(-6,2,-6,SAND:0)
Block(-6,2,-5,SAND:0)
Block(-6,2,-4,SAND:0)
Block(-6,2,-3,SAND:0)
Block(-6,2,-2,SAND:0)
Block(-6,2,-1,SAND:0)
Block(-6,2,0,SAND:0)
Block(-6,2,1,SAND:0)
Block(-6,2,2,SAND:0)
Block(-6,2,3,SAND:0)
Block(-6,2,4,SAND:0)
Block(-6,2,5,SAND:0)
Block(-6,2,6,SAND:0)
Block(-6,2,7,SAND:0)
Block(-6,2,8,SAND:0)
Block(-6,3,-7,STATIONARY_WATER:0)
Block(-6,3,-6,STATIONARY_WATER:0)
Block(-6,3,-5,STATIONARY_WATER:0)
Block(-6,3,-4,STATIONARY_WATER:0)
Block(-6,3,-3,STATIONARY_WATER:0)
Block(-6,3,-2,SAND:0)
Block(-6,3,-1,SAND:0)
Block(-6,3,0,SAND:0)
Block(-6,3,1,SAND:0)
Block(-6,3,2,SAND:0)
Block(-6,3,3,SAND:0)
Block(-6,3,4,SAND:0)
Block(-6,3,5,SAND:0)
Block(-6,3,6,SAND:0)
Block(-6,3,7,SAND:0)
Block(-6,3,8,SAND:0)
Block(-6,4,-7,STATIONARY_WATER:0)
Block(-6,4,-6,STATIONARY_WATER:0)
Block(-6,4,-5,STATIONARY_WATER:0)
Block(-6,4,-4,STATIONARY_WATER:0)
Block(-6,4,-3,STATIONARY_WATER:0)
Block(-6,4,-2,STATIONARY_WATER:0)
Block(-6,4,-1,STATIONARY_WATER:0)
Block(-6,4,0,STATIONARY_WATER:0)
Block(-6,4,1,STATIONARY_WATER:0)
Block(-6,4,2,STATIONARY_WATER:0)
Block(-6,4,3,STATIONARY_WATER:0)
Block(-6,4,4,STATIONARY_WATER:0)
Block(-6,4,5,STATIONARY_WATER:0)
Block(-6,4,6,STATIONARY_WATER:0)
Block(-6,4,7,STATIONARY_WATER:0)
Block(-6,4,8,STATIONARY_WATER:0)
Block(-6,5,-7,STATIONARY_WATER:0)
Block(-6,5,-6,STATIONARY_WATER:0)
Block(-6,5,-5,STATIONARY_WATER:0)
Block(-6,5,-4,STATIONARY_WATER:0)
Block(-6,5,-3,STATIONARY_WATER:0)
Block(-6,5,-2,STATIONARY_WATER:0)
Block(-6,5,-1,STATIONARY_WATER:0)
Block(-6,5,0,STATIONARY_WATER:0)
Block(-6,5,1,STATIONARY_WATER:0)
Block(-6,5,2,STATIONARY_WATER:0)
Block(-6,5,3,STATIONARY_WATER:0)
Block(-6,5,4,STATIONARY_WATER:0)
Block(-6,5,5,STATIONARY_WATER:0)
Block(-6,5,6,STATIONARY_WATER:0)
Block(-6,5,7,STATIONARY_WATER:0)
Block(-6,5,8,STATIONARY_WATER:0)
Block(-6,6,-7,STATIONARY_WATER:0)
Block(-6,6,-6,STATIONARY_WATER:0)
Block(-6,6,-5,STATIONARY_WATER:0)
Block(-6,6,-4,STATIONARY_WATER:0)
Block(-6,6,-3,STATIONARY_WATER:0)
Block(-6,6,-2,STATIONARY_WATER:0)
Block(-6,6,-1,STATIONARY_WATER:0)
Block(-6,6,0,STATIONARY_WATER:0)
Block(-6,6,1,STATIONARY_WATER:0)
Block(-6,6,2,STATIONARY_WATER:0)
Block(-6,6,3,STATIONARY_WATER:0)
Block(-6,6,4,STATIONARY_WATER:0)
Block(-6,6,5,STATIONARY_WATER:0)
Block(-6,6,6,STATIONARY_WATER:0)
Block(-6,6,7,STATIONARY_WATER:0)
Block(-6,6,8,STATIONARY_WATER:0)
Block(-6,7,-7,STATIONARY_WATER:0)
Block(-6,7,-6,STATIONARY_WATER:0)
Block(-6,7,-5,STATIONARY_WATER:0)
Block(-6,7,-4,STATIONARY_WATER:0)
Block(-6,7,-3,STATIONARY_WATER:0)
Block(-6,7,-2,STATIONARY_WATER:0)
Block(-6,7,-1,STATIONARY_WATER:0)
Block(-6,7,0,STATIONARY_WATER:0)
Block(-6,7,1,STATIONARY_WATER:0)
Block(-6,7,2,STATIONARY_WATER:0)
Block(-6,7,3,STATIONARY_WATER:0)
Block(-6,7,4,STATIONARY_WATER:0)
Block(-6,7,5,STATIONARY_WATER:0)
Block(-6,7,6,STATIONARY_WATER:0)
Block(-6,7,7,STATIONARY_WATER:0)
Block(-6,7,8,STATIONARY_WATER:0)
Block(-6,8,-7,STATIONARY_WATER:0)
Block(-6,8,-6,STATIONARY_WATER:0)
Block(-6,8,-5,STATIONARY_WATER:0)
Block(-6,8,-4,STATIONARY_WATER:0)
Block(-6,8,-3,STATIONARY_WATER:0)
Block(-6,8,-2,STATIONARY_WATER:0)
Block(-6,8,-1,STATIONARY_WATER:0)
Block(-6,8,0,STATIONARY_WATER:0)
Block(-6,8,1,STATIONARY_WATER:0)
Block(-6,8,2,STATIONARY_WATER:0)
Block(-6,8,3,STATIONARY_WATER:0)
Block(-6,8,4,STATIONARY_WATER:0)
Block(-6,8,5,STATIONARY_WATER:0)
Block(-6,8,6,STATIONARY_WATER:0)
Block(-6,8,7,STATIONARY_WATER:0)
Block(-6,8,8,STATIONARY_WATER:0)
Block(-6,9,-7,STATIONARY_WATER:0)
Block(-6,9,-6,STATIONARY_WATER:0)
Block(-6,9,-5,STATIONARY_WATER:0)
Block(-6,9,-4,STATIONARY_WATER:0)
Block(-6,9,-3,STATIONARY_WATER:0)
Block(-6,9,-2,STATIONARY_WATER:0)
Block(-6,9,-1,STATIONARY_WATER:0)
Block(-6,9,0,STATIONARY_WATER:0)
Block(-6,9,1,STATIONARY_WATER:0)
Block(-6,9,2,STATIONARY_WATER:0)
Block(-6,9,3,STATIONARY_WATER:0)
Block(-6,9,4,STATIONARY_WATER:0)
Block(-6,9,5,STATIONARY_WATER:0)
Block(-6,9,6,STATIONARY_WATER:0)
Block(-6,9,7,STATIONARY_WATER:0)
Block(-6,9,8,STATIONARY_WATER:0)
Block(-6,10,-7,STATIONARY_WATER:0)
Block(-6,10,-6,STATIONARY_WATER:0)
Block(-6,10,-5,STATIONARY_WATER:0)
Block(-6,10,-4,STATIONARY_WATER:0)
Block(-6,10,-3,STATIONARY_WATER:0)
Block(-6,10,-2,STATIONARY_WATER:0)
Block(-6,10,-1,STATIONARY_WATER:0)
Block(-6,10,0,STATIONARY_WATER:0)
Block(-6,10,1,STATIONARY_WATER:0)
Block(-6,10,2,STATIONARY_WATER:0)
Block(-6,10,3,STATIONARY_WATER:0)
Block(-6,10,4,STATIONARY_WATER:0)
Block(-6,10,5,STATIONARY_WATER:0)
Block(-6,10,6,STATIONARY_WATER:0)
Block(-6,10,7,STATIONARY_WATER:0)
Block(-6,10,8,STATIONARY_WATER:0)
Block(-6,11,-7,STATIONARY_WATER:0)
Block(-6,11,-6,STATIONARY_WATER:0)
Block(-6,11,-5,STATIONARY_WATER:0)
Block(-6,11,-4,STATIONARY_WATER:0)
Block(-6,11,-3,STATIONARY_WATER:0)
Block(-6,11,-2,STATIONARY_WATER:0)
Block(-6,11,-1,STATIONARY_WATER:0)
Block(-6,11,0,STATIONARY_WATER:0)
Block(-6,11,1,STATIONARY_WATER:0)
Block(-6,11,2,STATIONARY_WATER:0)
Block(-6,11,3,STATIONARY_WATER:0)
Block(-6,11,4,STATIONARY_WATER:0)
Block(-6,11,5,STATIONARY_WATER:0)
Block(-6,11,6,STATIONARY_WATER:0)
Block(-6,11,7,PACKED_ICE:0)
Block(-6,11,8,PACKED_ICE:0)
Block(-6,12,8,PACKED_ICE:0)
Block(-5,0,-7,DIRT:0)
Block(-5,0,-6,DIRT:0)
Block(-5,0,-5,DIRT:0)
Block(-5,0,-4,DIRT:0)
Block(-5,0,-3,DIRT:0)
Block(-5,0,-2,DIRT:0)
Block(-5,0,-1,DIRT:0)
Block(-5,0,0,DIRT:0)
Block(-5,0,1,DIRT:0)
Block(-5,0,2,DIRT:0)
Block(-5,0,3,DIRT:0)
Block(-5,0,4,DIRT:0)
Block(-5,0,5,DIRT:0)
Block(-5,0,6,DIRT:0)
Block(-5,0,7,DIRT:0)
Block(-5,0,8,DIRT:0)
Block(-5,1,-7,SAND:0)
Block(-5,1,-6,SAND:0)
Block(-5,1,-5,SAND:0)
Block(-5,1,-4,SAND:0)
Block(-5,1,-3,SAND:0)
Block(-5,1,-2,SAND:0)
Block(-5,1,-1,SAND:0)
Block(-5,1,0,SAND:0)
Block(-5,1,1,SAND:0)
Block(-5,1,2,SAND:0)
Block(-5,1,3,SAND:0)
Block(-5,1,4,SAND:0)
Block(-5,1,5,SAND:0)
Block(-5,1,6,SAND:0)
Block(-5,1,7,SAND:0)
Block(-5,1,8,SAND:0)
Block(-5,2,-7,STATIONARY_WATER:0)
Block(-5,2,-6,SAND:0)
Block(-5,2,-5,SAND:0)
Block(-5,2,-4,SAND:0)
Block(-5,2,-3,SAND:0)
Block(-5,2,-2,SAND:0)
Block(-5,2,-1,SAND:0)
Block(-5,2,0,SAND:0)
Block(-5,2,1,SAND:0)
Block(-5,2,2,SAND:0)
Block(-5,2,3,SAND:0)
Block(-5,2,4,SAND:0)
Block(-5,2,5,SAND:0)
Block(-5,2,6,SAND:0)
Block(-5,2,7,SAND:0)
Block(-5,2,8,SAND:0)
Block(-5,3,-7,STATIONARY_WATER:0)
Block(-5,3,-6,STATIONARY_WATER:0)
Block(-5,3,-5,STATIONARY_WATER:0)
Block(-5,3,-4,STATIONARY_WATER:0)
Block(-5,3,-3,STATIONARY_WATER:0)
Block(-5,3,-2,STATIONARY_WATER:0)
Block(-5,3,-1,SAND:0)
Block(-5,3,0,SAND:0)
Block(-5,3,1,SAND:0)
Block(-5,3,2,SAND:0)
Block(-5,3,3,SAND:0)
Block(-5,3,4,SAND:0)
Block(-5,3,5,SAND:0)
Block(-5,3,6,SAND:0)
Block(-5,3,7,SAND:0)
Block(-5,3,8,SAND:0)
Block(-5,4,-7,STATIONARY_WATER:0)
Block(-5,4,-6,STATIONARY_WATER:0)
Block(-5,4,-5,STATIONARY_WATER:0)
Block(-5,4,-4,STATIONARY_WATER:0)
Block(-5,4,-3,STATIONARY_WATER:0)
Block(-5,4,-2,STATIONARY_WATER:0)
Block(-5,4,-1,STATIONARY_WATER:0)
Block(-5,4,0,STATIONARY_WATER:0)
Block(-5,4,1,STATIONARY_WATER:0)
Block(-5,4,2,STATIONARY_WATER:0)
Block(-5,4,3,STATIONARY_WATER:0)
Block(-5,4,4,STATIONARY_WATER:0)
Block(-5,4,5,STATIONARY_WATER:0)
Block(-5,4,6,STATIONARY_WATER:0)
Block(-5,4,7,STATIONARY_WATER:0)
Block(-5,4,8,STATIONARY_WATER:0)
Block(-5,5,-7,STATIONARY_WATER:0)
Block(-5,5,-6,STATIONARY_WATER:0)
Block(-5,5,-5,STATIONARY_WATER:0)
Block(-5,5,-4,STATIONARY_WATER:0)
Block(-5,5,-3,STATIONARY_WATER:0)
Block(-5,5,-2,STATIONARY_WATER:0)
Block(-5,5,-1,STATIONARY_WATER:0)
Block(-5,5,0,STATIONARY_WATER:0)
Block(-5,5,1,STATIONARY_WATER:0)
Block(-5,5,2,STATIONARY_WATER:0)
Block(-5,5,3,STATIONARY_WATER:0)
Block(-5,5,4,STATIONARY_WATER:0)
Block(-5,5,5,STATIONARY_WATER:0)
Block(-5,5,6,STATIONARY_WATER:0)
Block(-5,5,7,STATIONARY_WATER:0)
Block(-5,5,8,STATIONARY_WATER:0)
Block(-5,6,-7,STATIONARY_WATER:0)
Block(-5,6,-6,STATIONARY_WATER:0)
Block(-5,6,-5,STATIONARY_WATER:0)
Block(-5,6,-4,STATIONARY_WATER:0)
Block(-5,6,-3,STATIONARY_WATER:0)
Block(-5,6,-2,STATIONARY_WATER:0)
Block(-5,6,-1,STATIONARY_WATER:0)
Block(-5,6,0,STATIONARY_WATER:0)
Block(-5,6,1,STATIONARY_WATER:0)
Block(-5,6,2,STATIONARY_WATER:0)
Block(-5,6,3,STATIONARY_WATER:0)
Block(-5,6,4,STATIONARY_WATER:0)
Block(-5,6,5,STATIONARY_WATER:0)
Block(-5,6,6,STATIONARY_WATER:0)
Block(-5,6,7,STATIONARY_WATER:0)
Block(-5,6,8,STATIONARY_WATER:0)
Block(-5,7,-7,STATIONARY_WATER:0)
Block(-5,7,-6,STATIONARY_WATER:0)
Block(-5,7,-5,STATIONARY_WATER:0)
Block(-5,7,-4,STATIONARY_WATER:0)
Block(-5,7,-3,STATIONARY_WATER:0)
Block(-5,7,-2,STATIONARY_WATER:0)
Block(-5,7,-1,STATIONARY_WATER:0)
Block(-5,7,0,STATIONARY_WATER:0)
Block(-5,7,1,STATIONARY_WATER:0)
Block(-5,7,2,STATIONARY_WATER:0)
Block(-5,7,3,STATIONARY_WATER:0)
Block(-5,7,4,STATIONARY_WATER:0)
Block(-5,7,5,STATIONARY_WATER:0)
Block(-5,7,6,STATIONARY_WATER:0)
Block(-5,7,7,STATIONARY_WATER:0)
Block(-5,7,8,STATIONARY_WATER:0)
Block(-5,8,-7,STATIONARY_WATER:0)
Block(-5,8,-6,STATIONARY_WATER:0)
Block(-5,8,-5,STATIONARY_WATER:0)
Block(-5,8,-4,STATIONARY_WATER:0)
Block(-5,8,-3,STATIONARY_WATER:0)
Block(-5,8,-2,STATIONARY_WATER:0)
Block(-5,8,-1,STATIONARY_WATER:0)
Block(-5,8,0,STATIONARY_WATER:0)
Block(-5,8,1,STATIONARY_WATER:0)
Block(-5,8,2,STATIONARY_WATER:0)
Block(-5,8,3,STATIONARY_WATER:0)
Block(-5,8,4,STATIONARY_WATER:0)
Block(-5,8,5,STATIONARY_WATER:0)
Block(-5,8,6,STATIONARY_WATER:0)
Block(-5,8,7,STATIONARY_WATER:0)
Block(-5,8,8,STATIONARY_WATER:0)
Block(-5,9,-7,STATIONARY_WATER:0)
Block(-5,9,-6,STATIONARY_WATER:0)
Block(-5,9,-5,STATIONARY_WATER:0)
Block(-5,9,-4,STATIONARY_WATER:0)
Block(-5,9,-3,STATIONARY_WATER:0)
Block(-5,9,-2,STATIONARY_WATER:0)
Block(-5,9,-1,STATIONARY_WATER:0)
Block(-5,9,0,STATIONARY_WATER:0)
Block(-5,9,1,STATIONARY_WATER:0)
Block(-5,9,2,STATIONARY_WATER:0)
Block(-5,9,3,STATIONARY_WATER:0)
Block(-5,9,4,STATIONARY_WATER:0)
Block(-5,9,5,STATIONARY_WATER:0)
Block(-5,9,6,STATIONARY_WATER:0)
Block(-5,9,7,STATIONARY_WATER:0)
Block(-5,9,8,STATIONARY_WATER:0)
Block(-5,10,-7,STATIONARY_WATER:0)
Block(-5,10,-6,STATIONARY_WATER:0)
Block(-5,10,-5,STATIONARY_WATER:0)
Block(-5,10,-4,STATIONARY_WATER:0)
Block(-5,10,-3,STATIONARY_WATER:0)
Block(-5,10,-2,STATIONARY_WATER:0)
Block(-5,10,-1,STATIONARY_WATER:0)
Block(-5,10,0,STATIONARY_WATER:0)
Block(-5,10,1,STATIONARY_WATER:0)
Block(-5,10,2,STATIONARY_WATER:0)
Block(-5,10,3,STATIONARY_WATER:0)
Block(-5,10,4,STATIONARY_WATER:0)
Block(-5,10,5,STATIONARY_WATER:0)
Block(-5,10,6,STATIONARY_WATER:0)
Block(-5,10,7,STATIONARY_WATER:0)
Block(-5,10,8,STATIONARY_WATER:0)
Block(-5,11,-7,STATIONARY_WATER:0)
Block(-5,11,-6,STATIONARY_WATER:0)
Block(-5,11,-5,STATIONARY_WATER:0)
Block(-5,11,-4,STATIONARY_WATER:0)
Block(-5,11,-3,STATIONARY_WATER:0)
Block(-5,11,-2,STATIONARY_WATER:0)
Block(-5,11,-1,STATIONARY_WATER:0)
Block(-5,11,0,STATIONARY_WATER:0)
Block(-5,11,1,STATIONARY_WATER:0)
Block(-5,11,2,STATIONARY_WATER:0)
Block(-5,11,3,STATIONARY_WATER:0)
Block(-5,11,4,STATIONARY_WATER:0)
Block(-5,11,5,STATIONARY_WATER:0)
Block(-5,11,6,PACKED_ICE:0)
Block(-5,11,7,PACKED_ICE:0)
Block(-5,11,8,PACKED_ICE:0)
Block(-5,12,8,PACKED_ICE:0)
Block(-4,0,-7,DIRT:0)
Block(-4,0,-6,DIRT:0)
Block(-4,0,-5,DIRT:0)
Block(-4,0,-4,DIRT:0)
Block(-4,0,-3,DIRT:0)
Block(-4,0,-2,DIRT:0)
Block(-4,0,-1,DIRT:0)
Block(-4,0,0,DIRT:0)
Block(-4,0,1,DIRT:0)
Block(-4,0,2,DIRT:0)
Block(-4,0,3,DIRT:0)
Block(-4,0,4,DIRT:0)
Block(-4,0,5,DIRT:0)
Block(-4,0,6,DIRT:0)
Block(-4,0,7,DIRT:0)
Block(-4,0,8,DIRT:0)
Block(-4,1,-7,SAND:0)
Block(-4,1,-6,SAND:0)
Block(-4,1,-5,SAND:0)
Block(-4,1,-4,SAND:0)
Block(-4,1,-3,SAND:0)
Block(-4,1,-2,SAND:0)
Block(-4,1,-1,SAND:0)
Block(-4,1,0,SAND:0)
Block(-4,1,1,SAND:0)
Block(-4,1,2,SAND:0)
Block(-4,1,3,SAND:0)
Block(-4,1,4,SAND:0)
Block(-4,1,5,SAND:0)
Block(-4,1,6,SAND:0)
Block(-4,1,7,SAND:0)
Block(-4,1,8,SAND:0)
Block(-4,2,-7,STATIONARY_WATER:0)
Block(-4,2,-6,STATIONARY_WATER:0)
Block(-4,2,-5,SAND:0)
Block(-4,2,-4,SAND:0)
Block(-4,2,-3,SAND:0)
Block(-4,2,-2,SAND:0)
Block(-4,2,-1,SAND:0)
Block(-4,2,0,SAND:0)
Block(-4,2,1,SAND:0)
Block(-4,2,2,SAND:0)
Block(-4,2,3,SAND:0)
Block(-4,2,4,SAND:0)
Block(-4,2,5,SAND:0)
Block(-4,2,6,SAND:0)
Block(-4,2,7,SAND:0)
Block(-4,2,8,SAND:0)
Block(-4,3,-7,STATIONARY_WATER:0)
Block(-4,3,-6,STATIONARY_WATER:0)
Block(-4,3,-5,STATIONARY_WATER:0)
Block(-4,3,-4,STATIONARY_WATER:0)
Block(-4,3,-3,STATIONARY_WATER:0)
Block(-4,3,-2,STATIONARY_WATER:0)
Block(-4,3,-1,STATIONARY_WATER:0)
Block(-4,3,0,SAND:0)
Block(-4,3,1,SAND:0)
Block(-4,3,2,SAND:0)
Block(-4,3,3,SAND:0)
Block(-4,3,4,SAND:0)
Block(-4,3,5,SAND:0)
Block(-4,3,6,SAND:0)
Block(-4,3,7,SAND:0)
Block(-4,3,8,SAND:0)
Block(-4,4,-7,STATIONARY_WATER:0)
Block(-4,4,-6,STATIONARY_WATER:0)
Block(-4,4,-5,STATIONARY_WATER:0)
Block(-4,4,-4,STATIONARY_WATER:0)
Block(-4,4,-3,STATIONARY_WATER:0)
Block(-4,4,-2,STATIONARY_WATER:0)
Block(-4,4,-1,STATIONARY_WATER:0)
Block(-4,4,0,STATIONARY_WATER:0)
Block(-4,4,1,STATIONARY_WATER:0)
Block(-4,4,2,STATIONARY_WATER:0)
Block(-4,4,3,STATIONARY_WATER:0)
Block(-4,4,4,STATIONARY_WATER:0)
Block(-4,4,5,STATIONARY_WATER:0)
Block(-4,4,6,STATIONARY_WATER:0)
Block(-4,4,7,STATIONARY_WATER:0)
Block(-4,4,8,STATIONARY_WATER:0)
Block(-4,5,-7,STATIONARY_WATER:0)
Block(-4,5,-6,STATIONARY_WATER:0)
Block(-4,5,-5,STATIONARY_WATER:0)
Block(-4,5,-4,STATIONARY_WATER:0)
Block(-4,5,-3,STATIONARY_WATER:0)
Block(-4,5,-2,STATIONARY_WATER:0)
Block(-4,5,-1,STATIONARY_WATER:0)
Block(-4,5,0,STATIONARY_WATER:0)
Block(-4,5,1,STATIONARY_WATER:0)
Block(-4,5,2,STATIONARY_WATER:0)
Block(-4,5,3,STATIONARY_WATER:0)
Block(-4,5,4,STATIONARY_WATER:0)
Block(-4,5,5,STATIONARY_WATER:0)
Block(-4,5,6,STATIONARY_WATER:0)
Block(-4,5,7,STATIONARY_WATER:0)
Block(-4,5,8,STATIONARY_WATER:0)
Block(-4,6,-7,STATIONARY_WATER:0)
Block(-4,6,-6,STATIONARY_WATER:0)
Block(-4,6,-5,STATIONARY_WATER:0)
Block(-4,6,-4,STATIONARY_WATER:0)
Block(-4,6,-3,STATIONARY_WATER:0)
Block(-4,6,-2,STATIONARY_WATER:0)
Block(-4,6,-1,STATIONARY_WATER:0)
Block(-4,6,0,STATIONARY_WATER:0)
Block(-4,6,1,STATIONARY_WATER:0)
Block(-4,6,2,STATIONARY_WATER:0)
Block(-4,6,3,STATIONARY_WATER:0)
Block(-4,6,4,STATIONARY_WATER:0)
Block(-4,6,5,STATIONARY_WATER:0)
Block(-4,6,6,STATIONARY_WATER:0)
Block(-4,6,7,STATIONARY_WATER:0)
Block(-4,6,8,STATIONARY_WATER:0)
Block(-4,7,-7,STATIONARY_WATER:0)
Block(-4,7,-6,STATIONARY_WATER:0)
Block(-4,7,-5,STATIONARY_WATER:0)
Block(-4,7,-4,STATIONARY_WATER:0)
Block(-4,7,-3,STATIONARY_WATER:0)
Block(-4,7,-2,STATIONARY_WATER:0)
Block(-4,7,-1,STATIONARY_WATER:0)
Block(-4,7,0,STATIONARY_WATER:0)
Block(-4,7,1,STATIONARY_WATER:0)
Block(-4,7,2,STATIONARY_WATER:0)
Block(-4,7,3,STATIONARY_WATER:0)
Block(-4,7,4,STATIONARY_WATER:0)
Block(-4,7,5,STATIONARY_WATER:0)
Block(-4,7,6,STATIONARY_WATER:0)
Block(-4,7,7,STATIONARY_WATER:0)
Block(-4,7,8,STATIONARY_WATER:0)
Block(-4,8,-7,STATIONARY_WATER:0)
Block(-4,8,-6,STATIONARY_WATER:0)
Block(-4,8,-5,STATIONARY_WATER:0)
Block(-4,8,-4,STATIONARY_WATER:0)
Block(-4,8,-3,STATIONARY_WATER:0)
Block(-4,8,-2,STATIONARY_WATER:0)
Block(-4,8,-1,STATIONARY_WATER:0)
Block(-4,8,0,STATIONARY_WATER:0)
Block(-4,8,1,STATIONARY_WATER:0)
Block(-4,8,2,STATIONARY_WATER:0)
Block(-4,8,3,STATIONARY_WATER:0)
Block(-4,8,4,STATIONARY_WATER:0)
Block(-4,8,5,STATIONARY_WATER:0)
Block(-4,8,6,STATIONARY_WATER:0)
Block(-4,8,7,STATIONARY_WATER:0)
Block(-4,8,8,STATIONARY_WATER:0)
Block(-4,9,-7,STATIONARY_WATER:0)
Block(-4,9,-6,STATIONARY_WATER:0)
Block(-4,9,-5,STATIONARY_WATER:0)
Block(-4,9,-4,STATIONARY_WATER:0)
Block(-4,9,-3,STATIONARY_WATER:0)
Block(-4,9,-2,STATIONARY_WATER:0)
Block(-4,9,-1,STATIONARY_WATER:0)
Block(-4,9,0,STATIONARY_WATER:0)
Block(-4,9,1,STATIONARY_WATER:0)
Block(-4,9,2,STATIONARY_WATER:0)
Block(-4,9,3,STATIONARY_WATER:0)
Block(-4,9,4,STATIONARY_WATER:0)
Block(-4,9,5,STATIONARY_WATER:0)
Block(-4,9,6,STATIONARY_WATER:0)
Block(-4,9,7,STATIONARY_WATER:0)
Block(-4,9,8,STATIONARY_WATER:0)
Block(-4,10,-7,STATIONARY_WATER:0)
Block(-4,10,-6,STATIONARY_WATER:0)
Block(-4,10,-5,STATIONARY_WATER:0)
Block(-4,10,-4,STATIONARY_WATER:0)
Block(-4,10,-3,STATIONARY_WATER:0)
Block(-4,10,-2,STATIONARY_WATER:0)
Block(-4,10,-1,STATIONARY_WATER:0)
Block(-4,10,0,STATIONARY_WATER:0)
Block(-4,10,1,STATIONARY_WATER:0)
Block(-4,10,2,STATIONARY_WATER:0)
Block(-4,10,3,STATIONARY_WATER:0)
Block(-4,10,4,STATIONARY_WATER:0)
Block(-4,10,5,STATIONARY_WATER:0)
Block(-4,10,6,STATIONARY_WATER:0)
Block(-4,10,7,STATIONARY_WATER:0)
Block(-4,10,8,STATIONARY_WATER:0)
Block(-4,11,-7,STATIONARY_WATER:0)
Block(-4,11,-6,STATIONARY_WATER:0)
Block(-4,11,-5,STATIONARY_WATER:0)
Block(-4,11,-4,STATIONARY_WATER:0)
Block(-4,11,-3,STATIONARY_WATER:0)
Block(-4,11,-2,STATIONARY_WATER:0)
Block(-4,11,-1,STATIONARY_WATER:0)
Block(-4,11,0,STATIONARY_WATER:0)
Block(-4,11,1,STATIONARY_WATER:0)
Block(-4,11,2,STATIONARY_WATER:0)
Block(-4,11,3,STATIONARY_WATER:0)
Block(-4,11,4,STATIONARY_WATER:0)
Block(-4,11,5,STATIONARY_WATER:0)
Block(-4,11,6,PACKED_ICE:0)
Block(-4,11,7,PACKED_ICE:0)
Block(-4,11,8,PACKED_ICE:0)
Block(-3,0,-7,DIRT:0)
Block(-3,0,-6,DIRT:0)
Block(-3,0,-5,DIRT:0)
Block(-3,0,-4,DIRT:0)
Block(-3,0,-3,DIRT:0)
Block(-3,0,-2,DIRT:0)
Block(-3,0,-1,DIRT:0)
Block(-3,0,0,DIRT:0)
Block(-3,0,1,DIRT:0)
Block(-3,0,2,DIRT:0)
Block(-3,0,3,DIRT:0)
Block(-3,0,4,DIRT:0)
Block(-3,0,5,DIRT:0)
Block(-3,0,6,DIRT:0)
Block(-3,0,7,DIRT:0)
Block(-3,0,8,DIRT:0)
Block(-3,1,-7,SAND:0)
Block(-3,1,-6,SAND:0)
Block(-3,1,-5,SAND:0)
Block(-3,1,-4,SAND:0)
Block(-3,1,-3,SAND:0)
Block(-3,1,-2,SAND:0)
Block(-3,1,-1,SAND:0)
Block(-3,1,0,SAND:0)
Block(-3,1,1,SAND:0)
Block(-3,1,2,SAND:0)
Block(-3,1,3,SAND:0)
Block(-3,1,4,SAND:0)
Block(-3,1,5,SAND:0)
Block(-3,1,6,SAND:0)
Block(-3,1,7,SAND:0)
Block(-3,1,8,SAND:0)
Block(-3,2,-7,STATIONARY_WATER:0)
Block(-3,2,-6,STATIONARY_WATER:0)
Block(-3,2,-5,STATIONARY_WATER:0)
Block(-3,2,-4,SAND:0)
Block(-3,2,-3,SAND:0)
Block(-3,2,-2,SAND:0)
Block(-3,2,-1,CLAY:0)
Block(-3,2,0,CLAY:0)
Block(-3,2,1,CLAY:0)
Block(-3,2,2,SAND:0)
Block(-3,2,3,SAND:0)
Block(-3,2,4,SAND:0)
Block(-3,2,5,SAND:0)
Block(-3,2,6,SAND:0)
Block(-3,2,7,SAND:0)
Block(-3,2,8,SAND:0)
Block(-3,3,-7,STATIONARY_WATER:0)
Block(-3,3,-6,STATIONARY_WATER:0)
Block(-3,3,-5,STATIONARY_WATER:0)
Block(-3,3,-4,STATIONARY_WATER:0)
Block(-3,3,-3,STATIONARY_WATER:0)
Block(-3,3,-2,STATIONARY_WATER:0)
Block(-3,3,-1,STATIONARY_WATER:0)
Block(-3,3,0,STATIONARY_WATER:0)
Block(-3,3,1,STATIONARY_WATER:0)
Block(-3,3,2,SAND:0)
Block(-3,3,3,SAND:0)
Block(-3,3,4,SAND:0)
Block(-3,3,5,SAND:0)
Block(-3,3,6,SAND:0)
Block(-3,3,7,SAND:0)
Block(-3,3,8,SAND:0)
Block(-3,4,-7,STATIONARY_WATER:0)
Block(-3,4,-6,STATIONARY_WATER:0)
Block(-3,4,-5,STATIONARY_WATER:0)
Block(-3,4,-4,STATIONARY_WATER:0)
Block(-3,4,-3,STATIONARY_WATER:0)
Block(-3,4,-2,STATIONARY_WATER:0)
Block(-3,4,-1,STATIONARY_WATER:0)
Block(-3,4,0,STATIONARY_WATER:0)
Block(-3,4,1,STATIONARY_WATER:0)
Block(-3,4,2,STATIONARY_WATER:0)
Block(-3,4,3,STATIONARY_WATER:0)
Block(-3,4,4,STATIONARY_WATER:0)
Block(-3,4,5,STATIONARY_WATER:0)
Block(-3,4,6,STATIONARY_WATER:0)
Block(-3,4,7,STATIONARY_WATER:0)
Block(-3,4,8,STATIONARY_WATER:0)
Block(-3,5,-7,STATIONARY_WATER:0)
Block(-3,5,-6,STATIONARY_WATER:0)
Block(-3,5,-5,STATIONARY_WATER:0)
Block(-3,5,-4,STATIONARY_WATER:0)
Block(-3,5,-3,STATIONARY_WATER:0)
Block(-3,5,-2,STATIONARY_WATER:0)
Block(-3,5,-1,STATIONARY_WATER:0)
Block(-3,5,0,STATIONARY_WATER:0)
Block(-3,5,1,STATIONARY_WATER:0)
Block(-3,5,2,STATIONARY_WATER:0)
Block(-3,5,3,STATIONARY_WATER:0)
Block(-3,5,4,STATIONARY_WATER:0)
Block(-3,5,5,STATIONARY_WATER:0)
Block(-3,5,6,STATIONARY_WATER:0)
Block(-3,5,7,STATIONARY_WATER:0)
Block(-3,5,8,STATIONARY_WATER:0)
Block(-3,6,-7,STATIONARY_WATER:0)
Block(-3,6,-6,STATIONARY_WATER:0)
Block(-3,6,-5,STATIONARY_WATER:0)
Block(-3,6,-4,STATIONARY_WATER:0)
Block(-3,6,-3,STATIONARY_WATER:0)
Block(-3,6,-2,STATIONARY_WATER:0)
Block(-3,6,-1,STATIONARY_WATER:0)
Block(-3,6,0,STATIONARY_WATER:0)
Block(-3,6,1,STATIONARY_WATER:0)
Block(-3,6,2,STATIONARY_WATER:0)
Block(-3,6,3,STATIONARY_WATER:0)
Block(-3,6,4,STATIONARY_WATER:0)
Block(-3,6,5,STATIONARY_WATER:0)
Block(-3,6,6,STATIONARY_WATER:0)
Block(-3,6,7,STATIONARY_WATER:0)
Block(-3,6,8,STATIONARY_WATER:0)
Block(-3,7,-7,STATIONARY_WATER:0)
Block(-3,7,-6,STATIONARY_WATER:0)
Block(-3,7,-5,STATIONARY_WATER:0)
Block(-3,7,-4,STATIONARY_WATER:0)
Block(-3,7,-3,STATIONARY_WATER:0)
Block(-3,7,-2,STATIONARY_WATER:0)
Block(-3,7,-1,STATIONARY_WATER:0)
Block(-3,7,0,STATIONARY_WATER:0)
Block(-3,7,1,STATIONARY_WATER:0)
Block(-3,7,2,STATIONARY_WATER:0)
Block(-3,7,3,STATIONARY_WATER:0)
Block(-3,7,4,STATIONARY_WATER:0)
Block(-3,7,5,STATIONARY_WATER:0)
Block(-3,7,6,STATIONARY_WATER:0)
Block(-3,7,7,STATIONARY_WATER:0)
Block(-3,7,8,STATIONARY_WATER:0)
Block(-3,8,-7,STATIONARY_WATER:0)
Block(-3,8,-6,STATIONARY_WATER:0)
Block(-3,8,-5,STATIONARY_WATER:0)
Block(-3,8,-4,STATIONARY_WATER:0)
Block(-3,8,-3,STATIONARY_WATER:0)
Block(-3,8,-2,STATIONARY_WATER:0)
Block(-3,8,-1,STATIONARY_WATER:0)
Block(-3,8,0,STATIONARY_WATER:0)
Block(-3,8,1,STATIONARY_WATER:0)
Block(-3,8,2,STATIONARY_WATER:0)
Block(-3,8,3,STATIONARY_WATER:0)
Block(-3,8,4,STATIONARY_WATER:0)
Block(-3,8,5,STATIONARY_WATER:0)
Block(-3,8,6,STATIONARY_WATER:0)
Block(-3,8,7,STATIONARY_WATER:0)
Block(-3,8,8,STATIONARY_WATER:0)
Block(-3,9,-7,STATIONARY_WATER:0)
Block(-3,9,-6,STATIONARY_WATER:0)
Block(-3,9,-5,STATIONARY_WATER:0)
Block(-3,9,-4,STATIONARY_WATER:0)
Block(-3,9,-3,STATIONARY_WATER:0)
Block(-3,9,-2,STATIONARY_WATER:0)
Block(-3,9,-1,STATIONARY_WATER:0)
Block(-3,9,0,STATIONARY_WATER:0)
Block(-3,9,1,STATIONARY_WATER:0)
Block(-3,9,2,STATIONARY_WATER:0)
Block(-3,9,3,STATIONARY_WATER:0)
Block(-3,9,4,STATIONARY_WATER:0)
Block(-3,9,5,STATIONARY_WATER:0)
Block(-3,9,6,STATIONARY_WATER:0)
Block(-3,9,7,STATIONARY_WATER:0)
Block(-3,9,8,STATIONARY_WATER:0)
Block(-3,10,-7,STATIONARY_WATER:0)
Block(-3,10,-6,STATIONARY_WATER:0)
Block(-3,10,-5,STATIONARY_WATER:0)
Block(-3,10,-4,STATIONARY_WATER:0)
Block(-3,10,-3,STATIONARY_WATER:0)
Block(-3,10,-2,STATIONARY_WATER:0)
Block(-3,10,-1,STATIONARY_WATER:0)
Block(-3,10,0,STATIONARY_WATER:0)
Block(-3,10,1,STATIONARY_WATER:0)
Block(-3,10,2,STATIONARY_WATER:0)
Block(-3,10,3,STATIONARY_WATER:0)
Block(-3,10,4,STATIONARY_WATER:0)
Block(-3,10,5,STATIONARY_WATER:0)
Block(-3,10,6,STATIONARY_WATER:0)
Block(-3,10,7,STATIONARY_WATER:0)
Block(-3,10,8,STATIONARY_WATER:0)
Block(-3,11,-7,STATIONARY_WATER:0)
Block(-3,11,-6,STATIONARY_WATER:0)
Block(-3,11,-5,STATIONARY_WATER:0)
Block(-3,11,-4,STATIONARY_WATER:0)
Block(-3,11,-3,STATIONARY_WATER:0)
Block(-3,11,-2,STATIONARY_WATER:0)
Block(-3,11,-1,STATIONARY_WATER:0)
Block(-3,11,0,STATIONARY_WATER:0)
Block(-3,11,1,STATIONARY_WATER:0)
Block(-3,11,2,STATIONARY_WATER:0)
Block(-3,11,3,STATIONARY_WATER:0)
Block(-3,11,4,STATIONARY_WATER:0)
Block(-3,11,5,STATIONARY_WATER:0)
Block(-3,11,6,STATIONARY_WATER:0)
Block(-3,11,7,STATIONARY_WATER:0)
Block(-3,11,8,PACKED_ICE:0)
Block(-2,0,-7,DIRT:0)
Block(-2,0,-6,DIRT:0)
Block(-2,0,-5,DIRT:0)
Block(-2,0,-4,DIRT:0)
Block(-2,0,-3,DIRT:0)
Block(-2,0,-2,DIRT:0)
Block(-2,0,-1,DIRT:0)
Block(-2,0,0,DIRT:0)
Block(-2,0,1,DIRT:0)
Block(-2,0,2,DIRT:0)
Block(-2,0,3,DIRT:0)
Block(-2,0,4,DIRT:0)
Block(-2,0,5,DIRT:0)
Block(-2,0,6,DIRT:0)
Block(-2,0,7,DIRT:0)
Block(-2,0,8,DIRT:0)
Block(-2,1,-7,SAND:0)
Block(-2,1,-6,SAND:0)
Block(-2,1,-5,SAND:0)
Block(-2,1,-4,SAND:0)
Block(-2,1,-3,SAND:0)
Block(-2,1,-2,SAND:0)
Block(-2,1,-1,SAND:0)
Block(-2,1,0,SAND:0)
Block(-2,1,1,SAND:0)
Block(-2,1,2,SAND:0)
Block(-2,1,3,SAND:0)
Block(-2,1,4,SAND:0)
Block(-2,1,5,SAND:0)
Block(-2,1,6,SAND:0)
Block(-2,1,7,SAND:0)
Block(-2,1,8,SAND:0)
Block(-2,2,-7,STATIONARY_WATER:0)
Block(-2,2,-6,STATIONARY_WATER:0)
Block(-2,2,-5,STATIONARY_WATER:0)
Block(-2,2,-4,SAND:0)
Block(-2,2,-3,SAND:0)
Block(-2,2,-2,CLAY:0)
Block(-2,2,-1,CLAY:0)
Block(-2,2,0,CLAY:0)
Block(-2,2,1,CLAY:0)
Block(-2,2,2,CLAY:0)
Block(-2,2,3,CLAY:0)
Block(-2,2,4,SAND:0)
Block(-2,2,5,SAND:0)
Block(-2,2,6,SAND:0)
Block(-2,2,7,SAND:0)
Block(-2,2,8,SAND:0)
Block(-2,3,-7,STATIONARY_WATER:0)
Block(-2,3,-6,STATIONARY_WATER:0)
Block(-2,3,-5,STATIONARY_WATER:0)
Block(-2,3,-4,STATIONARY_WATER:0)
Block(-2,3,-3,STATIONARY_WATER:0)
Block(-2,3,-2,STATIONARY_WATER:0)
Block(-2,3,-1,STATIONARY_WATER:0)
Block(-2,3,0,STATIONARY_WATER:0)
Block(-2,3,1,STATIONARY_WATER:0)
Block(-2,3,2,STATIONARY_WATER:0)
Block(-2,3,3,STATIONARY_WATER:0)
Block(-2,3,4,CLAY:0)
Block(-2,3,5,CLAY:0)
Block(-2,3,6,CLAY:0)
Block(-2,3,7,SAND:0)
Block(-2,3,8,SAND:0)
Block(-2,4,-7,STATIONARY_WATER:0)
Block(-2,4,-6,STATIONARY_WATER:0)
Block(-2,4,-5,STATIONARY_WATER:0)
Block(-2,4,-4,STATIONARY_WATER:0)
Block(-2,4,-3,STATIONARY_WATER:0)
Block(-2,4,-2,STATIONARY_WATER:0)
Block(-2,4,-1,STATIONARY_WATER:0)
Block(-2,4,0,STATIONARY_WATER:0)
Block(-2,4,1,STATIONARY_WATER:0)
Block(-2,4,2,STATIONARY_WATER:0)
Block(-2,4,3,STATIONARY_WATER:0)
Block(-2,4,4,STATIONARY_WATER:0)
Block(-2,4,5,STATIONARY_WATER:0)
Block(-2,4,6,STATIONARY_WATER:0)
Block(-2,4,7,STATIONARY_WATER:0)
Block(-2,4,8,STATIONARY_WATER:0)
Block(-2,5,-7,STATIONARY_WATER:0)
Block(-2,5,-6,STATIONARY_WATER:0)
Block(-2,5,-5,STATIONARY_WATER:0)
Block(-2,5,-4,STATIONARY_WATER:0)
Block(-2,5,-3,STATIONARY_WATER:0)
Block(-2,5,-2,STATIONARY_WATER:0)
Block(-2,5,-1,STATIONARY_WATER:0)
Block(-2,5,0,STATIONARY_WATER:0)
Block(-2,5,1,STATIONARY_WATER:0)
Block(-2,5,2,STATIONARY_WATER:0)
Block(-2,5,3,STATIONARY_WATER:0)
Block(-2,5,4,STATIONARY_WATER:0)
Block(-2,5,5,STATIONARY_WATER:0)
Block(-2,5,6,STATIONARY_WATER:0)
Block(-2,5,7,STATIONARY_WATER:0)
Block(-2,5,8,STATIONARY_WATER:0)
Block(-2,6,-7,STATIONARY_WATER:0)
Block(-2,6,-6,STATIONARY_WATER:0)
Block(-2,6,-5,STATIONARY_WATER:0)
Block(-2,6,-4,STATIONARY_WATER:0)
Block(-2,6,-3,STATIONARY_WATER:0)
Block(-2,6,-2,STATIONARY_WATER:0)
Block(-2,6,-1,STATIONARY_WATER:0)
Block(-2,6,0,STATIONARY_WATER:0)
Block(-2,6,1,STATIONARY_WATER:0)
Block(-2,6,2,STATIONARY_WATER:0)
Block(-2,6,3,STATIONARY_WATER:0)
Block(-2,6,4,STATIONARY_WATER:0)
Block(-2,6,5,STATIONARY_WATER:0)
Block(-2,6,6,STATIONARY_WATER:0)
Block(-2,6,7,STATIONARY_WATER:0)
Block(-2,6,8,STATIONARY_WATER:0)
Block(-2,7,-7,STATIONARY_WATER:0)
Block(-2,7,-6,STATIONARY_WATER:0)
Block(-2,7,-5,STATIONARY_WATER:0)
Block(-2,7,-4,STATIONARY_WATER:0)
Block(-2,7,-3,STATIONARY_WATER:0)
Block(-2,7,-2,STATIONARY_WATER:0)
Block(-2,7,-1,STATIONARY_WATER:0)
Block(-2,7,0,STATIONARY_WATER:0)
Block(-2,7,1,STATIONARY_WATER:0)
Block(-2,7,2,STATIONARY_WATER:0)
Block(-2,7,3,STATIONARY_WATER:0)
Block(-2,7,4,STATIONARY_WATER:0)
Block(-2,7,5,STATIONARY_WATER:0)
Block(-2,7,6,STATIONARY_WATER:0)
Block(-2,7,7,STATIONARY_WATER:0)
Block(-2,7,8,STATIONARY_WATER:0)
Block(-2,8,-7,STATIONARY_WATER:0)
Block(-2,8,-6,STATIONARY_WATER:0)
Block(-2,8,-5,STATIONARY_WATER:0)
Block(-2,8,-4,STATIONARY_WATER:0)
Block(-2,8,-3,STATIONARY_WATER:0)
Block(-2,8,-2,STATIONARY_WATER:0)
Block(-2,8,-1,STATIONARY_WATER:0)
Block(-2,8,0,STATIONARY_WATER:0)
Block(-2,8,1,STATIONARY_WATER:0)
Block(-2,8,2,STATIONARY_WATER:0)
Block(-2,8,3,STATIONARY_WATER:0)
Block(-2,8,4,STATIONARY_WATER:0)
Block(-2,8,5,STATIONARY_WATER:0)
Block(-2,8,6,STATIONARY_WATER:0)
Block(-2,8,7,STATIONARY_WATER:0)
Block(-2,8,8,STATIONARY_WATER:0)
Block(-2,9,-7,STATIONARY_WATER:0)
Block(-2,9,-6,STATIONARY_WATER:0)
Block(-2,9,-5,STATIONARY_WATER:0)
Block(-2,9,-4,STATIONARY_WATER:0)
Block(-2,9,-3,STATIONARY_WATER:0)
Block(-2,9,-2,STATIONARY_WATER:0)
Block(-2,9,-1,STATIONARY_WATER:0)
Block(-2,9,0,STATIONARY_WATER:0)
Block(-2,9,1,STATIONARY_WATER:0)
Block(-2,9,2,STATIONARY_WATER:0)
Block(-2,9,3,STATIONARY_WATER:0)
Block(-2,9,4,STATIONARY_WATER:0)
Block(-2,9,5,STATIONARY_WATER:0)
Block(-2,9,6,STATIONARY_WATER:0)
Block(-2,9,7,STATIONARY_WATER:0)
Block(-2,9,8,STATIONARY_WATER:0)
Block(-2,10,-7,STATIONARY_WATER:0)
Block(-2,10,-6,STATIONARY_WATER:0)
Block(-2,10,-5,STATIONARY_WATER:0)
Block(-2,10,-4,STATIONARY_WATER:0)
Block(-2,10,-3,STATIONARY_WATER:0)
Block(-2,10,-2,STATIONARY_WATER:0)
Block(-2,10,-1,STATIONARY_WATER:0)
Block(-2,10,0,STATIONARY_WATER:0)
Block(-2,10,1,STATIONARY_WATER:0)
Block(-2,10,2,STATIONARY_WATER:0)
Block(-2,10,3,STATIONARY_WATER:0)
Block(-2,10,4,STATIONARY_WATER:0)
Block(-2,10,5,STATIONARY_WATER:0)
Block(-2,10,6,STATIONARY_WATER:0)
Block(-2,10,7,STATIONARY_WATER:0)
Block(-2,10,8,STATIONARY_WATER:0)
Block(-2,11,-7,STATIONARY_WATER:0)
Block(-2,11,-6,STATIONARY_WATER:0)
Block(-2,11,-5,STATIONARY_WATER:0)
Block(-2,11,-4,STATIONARY_WATER:0)
Block(-2,11,-3,STATIONARY_WATER:0)
Block(-2,11,-2,STATIONARY_WATER:0)
Block(-2,11,-1,STATIONARY_WATER:0)
Block(-2,11,0,STATIONARY_WATER:0)
Block(-2,11,1,STATIONARY_WATER:0)
Block(-2,11,2,STATIONARY_WATER:0)
Block(-2,11,3,STATIONARY_WATER:0)
Block(-2,11,4,STATIONARY_WATER:0)
Block(-2,11,5,STATIONARY_WATER:0)
Block(-2,11,6,STATIONARY_WATER:0)
Block(-2,11,7,STATIONARY_WATER:0)
Block(-2,11,8,STATIONARY_WATER:0)
Block(-1,0,-7,STONE:6)
Block(-1,0,-6,DIRT:0)
Block(-1,0,-5,DIRT:0)
Block(-1,0,-4,DIRT:0)
Block(-1,0,-3,DIRT:0)
Block(-1,0,-2,DIRT:0)
Block(-1,0,-1,DIRT:0)
Block(-1,0,0,DIRT:0)
Block(-1,0,1,DIRT:0)
Block(-1,0,2,DIRT:0)
Block(-1,0,3,DIRT:0)
Block(-1,0,4,DIRT:0)
Block(-1,0,5,DIRT:0)
Block(-1,0,6,DIRT:0)
Block(-1,0,7,DIRT:0)
Block(-1,0,8,DIRT:0)
Block(-1,1,-7,SAND:0)
Block(-1,1,-6,SAND:0)
Block(-1,1,-5,SAND:0)
Block(-1,1,-4,SAND:0)
Block(-1,1,-3,SAND:0)
Block(-1,1,-2,SAND:0)
Block(-1,1,-1,SAND:0)
Block(-1,1,0,SAND:0)
Block(-1,1,1,SAND:0)
Block(-1,1,2,SAND:0)
Block(-1,1,3,SAND:0)
Block(-1,1,4,SAND:0)
Block(-1,1,5,SAND:0)
Block(-1,1,6,SAND:0)
Block(-1,1,7,SAND:0)
Block(-1,1,8,SAND:0)
Block(-1,2,-7,STATIONARY_WATER:0)
Block(-1,2,-6,STATIONARY_WATER:0)
Block(-1,2,-5,STATIONARY_WATER:0)
Block(-1,2,-4,SAND:0)
Block(-1,2,-3,SAND:0)
Block(-1,2,-2,CLAY:0)
Block(-1,2,-1,CLAY:0)
Block(-1,2,0,CLAY:0)
Block(-1,2,1,CLAY:0)
Block(-1,2,2,CLAY:0)
Block(-1,2,3,CLAY:0)
Block(-1,2,4,CLAY:0)
Block(-1,2,5,SAND:0)
Block(-1,2,6,SAND:0)
Block(-1,2,7,SAND:0)
Block(-1,2,8,SAND:0)
Block(-1,3,-7,STATIONARY_WATER:0)
Block(-1,3,-6,STATIONARY_WATER:0)
Block(-1,3,-5,STATIONARY_WATER:0)
Block(-1,3,-4,STATIONARY_WATER:0)
Block(-1,3,-3,STATIONARY_WATER:0)
Block(-1,3,-2,STATIONARY_WATER:0)
Block(-1,3,-1,STATIONARY_WATER:0)
Block(-1,3,0,STATIONARY_WATER:0)
Block(-1,3,1,STATIONARY_WATER:0)
Block(-1,3,2,STATIONARY_WATER:0)
Block(-1,3,3,STATIONARY_WATER:0)
Block(-1,3,4,STATIONARY_WATER:0)
Block(-1,3,5,CLAY:0)
Block(-1,3,6,CLAY:0)
Block(-1,3,7,CLAY:0)
Block(-1,3,8,SAND:0)
Block(-1,4,-7,STATIONARY_WATER:0)
Block(-1,4,-6,STATIONARY_WATER:0)
Block(-1,4,-5,STATIONARY_WATER:0)
Block(-1,4,-4,STATIONARY_WATER:0)
Block(-1,4,-3,STATIONARY_WATER:0)
Block(-1,4,-2,STATIONARY_WATER:0)
Block(-1,4,-1,STATIONARY_WATER:0)
Block(-1,4,0,STATIONARY_WATER:0)
Block(-1,4,1,STATIONARY_WATER:0)
Block(-1,4,2,STATIONARY_WATER:0)
Block(-1,4,3,STATIONARY_WATER:0)
Block(-1,4,4,STATIONARY_WATER:0)
Block(-1,4,5,STATIONARY_WATER:0)
Block(-1,4,6,STATIONARY_WATER:0)
Block(-1,4,7,STATIONARY_WATER:0)
Block(-1,4,8,STATIONARY_WATER:0)
Block(-1,5,-7,STATIONARY_WATER:0)
Block(-1,5,-6,STATIONARY_WATER:0)
Block(-1,5,-5,STATIONARY_WATER:0)
Block(-1,5,-4,STATIONARY_WATER:0)
Block(-1,5,-3,STATIONARY_WATER:0)
Block(-1,5,-2,STATIONARY_WATER:0)
Block(-1,5,-1,STATIONARY_WATER:0)
Block(-1,5,0,STATIONARY_WATER:0)
Block(-1,5,1,STATIONARY_WATER:0)
Block(-1,5,2,STATIONARY_WATER:0)
Block(-1,5,3,STATIONARY_WATER:0)
Block(-1,5,4,STATIONARY_WATER:0)
Block(-1,5,5,STATIONARY_WATER:0)
Block(-1,5,6,STATIONARY_WATER:0)
Block(-1,5,7,STATIONARY_WATER:0)
Block(-1,5,8,STATIONARY_WATER:0)
Block(-1,6,-7,STATIONARY_WATER:0)
Block(-1,6,-6,STATIONARY_WATER:0)
Block(-1,6,-5,STATIONARY_WATER:0)
Block(-1,6,-4,STATIONARY_WATER:0)
Block(-1,6,-3,STATIONARY_WATER:0)
Block(-1,6,-2,STATIONARY_WATER:0)
Block(-1,6,-1,STATIONARY_WATER:0)
Block(-1,6,0,STATIONARY_WATER:0)
Block(-1,6,1,STATIONARY_WATER:0)
Block(-1,6,2,STATIONARY_WATER:0)
Block(-1,6,3,STATIONARY_WATER:0)
Block(-1,6,4,STATIONARY_WATER:0)
Block(-1,6,5,STATIONARY_WATER:0)
Block(-1,6,6,STATIONARY_WATER:0)
Block(-1,6,7,STATIONARY_WATER:0)
Block(-1,6,8,STATIONARY_WATER:0)
Block(-1,7,-7,STATIONARY_WATER:0)
Block(-1,7,-6,STATIONARY_WATER:0)
Block(-1,7,-5,STATIONARY_WATER:0)
Block(-1,7,-4,STATIONARY_WATER:0)
Block(-1,7,-3,STATIONARY_WATER:0)
Block(-1,7,-2,STATIONARY_WATER:0)
Block(-1,7,-1,STATIONARY_WATER:0)
Block(-1,7,0,STATIONARY_WATER:0)
Block(-1,7,1,STATIONARY_WATER:0)
Block(-1,7,2,STATIONARY_WATER:0)
Block(-1,7,3,STATIONARY_WATER:0)
Block(-1,7,4,STATIONARY_WATER:0)
Block(-1,7,5,STATIONARY_WATER:0)
Block(-1,7,6,STATIONARY_WATER:0)
Block(-1,7,7,STATIONARY_WATER:0)
Block(-1,7,8,STATIONARY_WATER:0)
Block(-1,8,-7,STATIONARY_WATER:0)
Block(-1,8,-6,STATIONARY_WATER:0)
Block(-1,8,-5,STATIONARY_WATER:0)
Block(-1,8,-4,STATIONARY_WATER:0)
Block(-1,8,-3,STATIONARY_WATER:0)
Block(-1,8,-2,STATIONARY_WATER:0)
Block(-1,8,-1,STATIONARY_WATER:0)
Block(-1,8,0,STATIONARY_WATER:0)
Block(-1,8,1,STATIONARY_WATER:0)
Block(-1,8,2,STATIONARY_WATER:0)
Block(-1,8,3,STATIONARY_WATER:0)
Block(-1,8,4,STATIONARY_WATER:0)
Block(-1,8,5,STATIONARY_WATER:0)
Block(-1,8,6,STATIONARY_WATER:0)
Block(-1,8,7,STATIONARY_WATER:0)
Block(-1,8,8,STATIONARY_WATER:0)
Block(-1,9,-7,STATIONARY_WATER:0)
Block(-1,9,-6,STATIONARY_WATER:0)
Block(-1,9,-5,STATIONARY_WATER:0)
Block(-1,9,-4,STATIONARY_WATER:0)
Block(-1,9,-3,STATIONARY_WATER:0)
Block(-1,9,-2,STATIONARY_WATER:0)
Block(-1,9,-1,STATIONARY_WATER:0)
Block(-1,9,0,STATIONARY_WATER:0)
Block(-1,9,1,STATIONARY_WATER:0)
Block(-1,9,2,STATIONARY_WATER:0)
Block(-1,9,3,STATIONARY_WATER:0)
Block(-1,9,4,STATIONARY_WATER:0)
Block(-1,9,5,STATIONARY_WATER:0)
Block(-1,9,6,STATIONARY_WATER:0)
Block(-1,9,7,STATIONARY_WATER:0)
Block(-1,9,8,STATIONARY_WATER:0)
Block(-1,10,-7,STATIONARY_WATER:0)
Block(-1,10,-6,STATIONARY_WATER:0)
Block(-1,10,-5,STATIONARY_WATER:0)
Block(-1,10,-4,STATIONARY_WATER:0)
Block(-1,10,-3,STATIONARY_WATER:0)
Block(-1,10,-2,STATIONARY_WATER:0)
Block(-1,10,-1,STATIONARY_WATER:0)
Block(-1,10,0,STATIONARY_WATER:0)
Block(-1,10,1,STATIONARY_WATER:0)
Block(-1,10,2,STATIONARY_WATER:0)
Block(-1,10,3,STATIONARY_WATER:0)
Block(-1,10,4,STATIONARY_WATER:0)
Block(-1,10,5,STATIONARY_WATER:0)
Block(-1,10,6,STATIONARY_WATER:0)
Block(-1,10,7,STATIONARY_WATER:0)
Block(-1,10,8,STATIONARY_WATER:0)
Block(-1,11,-7,STATIONARY_WATER:0)
Block(-1,11,-6,STATIONARY_WATER:0)
Block(-1,11,-5,STATIONARY_WATER:0)
Block(-1,11,-4,STATIONARY_WATER:0)
Block(-1,11,-3,STATIONARY_WATER:0)
Block(-1,11,-2,STATIONARY_WATER:0)
Block(-1,11,-1,STATIONARY_WATER:0)
Block(-1,11,0,STATIONARY_WATER:0)
Block(-1,11,1,STATIONARY_WATER:0)
Block(-1,11,2,STATIONARY_WATER:0)
Block(-1,11,3,STATIONARY_WATER:0)
Block(-1,11,4,STATIONARY_WATER:0)
Block(-1,11,5,STATIONARY_WATER:0)
Block(-1,11,6,STATIONARY_WATER:0)
Block(-1,11,7,STATIONARY_WATER:0)
Block(-1,11,8,STATIONARY_WATER:0)
Block(0,0,-7,STONE:6)
Block(0,0,-6,DIRT:0)
Block(0,0,-5,DIRT:0)
Block(0,0,-4,DIRT:0)
Block(0,0,-3,DIRT:0)
Block(0,0,-2,DIRT:0)
Block(0,0,-1,DIRT:0)
Block(0,0,0,DIRT:0)
Block(0,0,1,DIRT:0)
Block(0,0,2,DIRT:0)
Block(0,0,3,DIRT:0)
Block(0,0,4,DIRT:0)
Block(0,0,5,DIRT:0)
Block(0,0,6,DIRT:0)
Block(0,0,7,DIRT:0)
Block(0,0,8,DIRT:0)
Block(0,1,-7,SAND:0)
Block(0,1,-6,SAND:0)
Block(0,1,-5,SAND:0)
Block(0,1,-4,SAND:0)
Block(0,1,-3,SAND:0)
Block(0,1,-2,SAND:0)
Block(0,1,-1,SAND:0)
Block(0,1,0,SAND:0)
Block(0,1,1,SAND:0)
Block(0,1,2,SAND:0)
Block(0,1,3,SAND:0)
Block(0,1,4,SAND:0)
Block(0,1,5,SAND:0)
Block(0,1,6,SAND:0)
Block(0,1,7,SAND:0)
Block(0,1,8,SAND:0)
Block(0,2,-7,STATIONARY_WATER:0)
Block(0,2,-6,STATIONARY_WATER:0)
Block(0,2,-5,STATIONARY_WATER:0)
Block(0,2,-4,STATIONARY_WATER:0)
Block(0,2,-3,SAND:0)
Block(0,2,-2,CLAY:0)
Block(0,2,-1,CLAY:0)
Block(0,2,0,CLAY:0)
Block(0,2,1,CLAY:0)
Block(0,2,2,CLAY:0)
Block(0,2,3,CLAY:0)
Block(0,2,4,CLAY:0)
Block(0,2,5,SAND:0)
Block(0,2,6,SAND:0)
Block(0,2,7,SAND:0)
Block(0,2,8,SAND:0)
Block(0,3,-7,STATIONARY_WATER:0)
Block(0,3,-6,STATIONARY_WATER:0)
Block(0,3,-5,STATIONARY_WATER:0)
Block(0,3,-4,STATIONARY_WATER:0)
Block(0,3,-3,STATIONARY_WATER:0)
Block(0,3,-2,STATIONARY_WATER:0)
Block(0,3,-1,STATIONARY_WATER:0)
Block(0,3,0,STATIONARY_WATER:0)
Block(0,3,1,STATIONARY_WATER:0)
Block(0,3,2,STATIONARY_WATER:0)
Block(0,3,3,STATIONARY_WATER:0)
Block(0,3,4,STATIONARY_WATER:0)
Block(0,3,5,CLAY:0)
Block(0,3,6,CLAY:0)
Block(0,3,7,CLAY:0)
Block(0,3,8,CLAY:0)
Block(0,4,-7,STATIONARY_WATER:0)
Block(0,4,-6,STATIONARY_WATER:0)
Block(0,4,-5,STATIONARY_WATER:0)
Block(0,4,-4,STATIONARY_WATER:0)
Block(0,4,-3,STATIONARY_WATER:0)
Block(0,4,-2,STATIONARY_WATER:0)
Block(0,4,-1,STATIONARY_WATER:0)
Block(0,4,0,STATIONARY_WATER:0)
Block(0,4,1,STATIONARY_WATER:0)
Block(0,4,2,STATIONARY_WATER:0)
Block(0,4,3,STATIONARY_WATER:0)
Block(0,4,4,STATIONARY_WATER:0)
Block(0,4,5,STATIONARY_WATER:0)
Block(0,4,6,STATIONARY_WATER:0)
Block(0,4,7,STATIONARY_WATER:0)
Block(0,4,8,STATIONARY_WATER:0)
Block(0,5,-7,STATIONARY_WATER:0)
Block(0,5,-6,STATIONARY_WATER:0)
Block(0,5,-5,STATIONARY_WATER:0)
Block(0,5,-4,STATIONARY_WATER:0)
Block(0,5,-3,STATIONARY_WATER:0)
Block(0,5,-2,STATIONARY_WATER:0)
Block(0,5,-1,STATIONARY_WATER:0)
Block(0,5,0,STATIONARY_WATER:0)
Block(0,5,1,STATIONARY_WATER:0)
Block(0,5,2,STATIONARY_WATER:0)
Block(0,5,3,STATIONARY_WATER:0)
Block(0,5,4,STATIONARY_WATER:0)
Block(0,5,5,STATIONARY_WATER:0)
Block(0,5,6,STATIONARY_WATER:0)
Block(0,5,7,STATIONARY_WATER:0)
Block(0,5,8,STATIONARY_WATER:0)
Block(0,6,-7,STATIONARY_WATER:0)
Block(0,6,-6,STATIONARY_WATER:0)
Block(0,6,-5,STATIONARY_WATER:0)
Block(0,6,-4,STATIONARY_WATER:0)
Block(0,6,-3,STATIONARY_WATER:0)
Block(0,6,-2,STATIONARY_WATER:0)
Block(0,6,-1,STATIONARY_WATER:0)
Block(0,6,0,STATIONARY_WATER:0)
Block(0,6,1,STATIONARY_WATER:0)
Block(0,6,2,STATIONARY_WATER:0)
Block(0,6,3,STATIONARY_WATER:0)
Block(0,6,4,STATIONARY_WATER:0)
Block(0,6,5,STATIONARY_WATER:0)
Block(0,6,6,STATIONARY_WATER:0)
Block(0,6,7,STATIONARY_WATER:0)
Block(0,6,8,STATIONARY_WATER:0)
Block(0,7,-7,STATIONARY_WATER:0)
Block(0,7,-6,STATIONARY_WATER:0)
Block(0,7,-5,STATIONARY_WATER:0)
Block(0,7,-4,STATIONARY_WATER:0)
Block(0,7,-3,STATIONARY_WATER:0)
Block(0,7,-2,STATIONARY_WATER:0)
Block(0,7,-1,STATIONARY_WATER:0)
Block(0,7,0,STATIONARY_WATER:0)
Block(0,7,1,STATIONARY_WATER:0)
Block(0,7,2,STATIONARY_WATER:0)
Block(0,7,3,STATIONARY_WATER:0)
Block(0,7,4,STATIONARY_WATER:0)
Block(0,7,5,STATIONARY_WATER:0)
Block(0,7,6,STATIONARY_WATER:0)
Block(0,7,7,STATIONARY_WATER:0)
Block(0,7,8,STATIONARY_WATER:0)
Block(0,8,-7,STATIONARY_WATER:0)
Block(0,8,-6,STATIONARY_WATER:0)
Block(0,8,-5,STATIONARY_WATER:0)
Block(0,8,-4,STATIONARY_WATER:0)
Block(0,8,-3,STATIONARY_WATER:0)
Block(0,8,-2,STATIONARY_WATER:0)
Block(0,8,-1,STATIONARY_WATER:0)
Block(0,8,0,STATIONARY_WATER:0)
Block(0,8,1,STATIONARY_WATER:0)
Block(0,8,2,STATIONARY_WATER:0)
Block(0,8,3,STATIONARY_WATER:0)
Block(0,8,4,STATIONARY_WATER:0)
Block(0,8,5,STATIONARY_WATER:0)
Block(0,8,6,STATIONARY_WATER:0)
Block(0,8,7,STATIONARY_WATER:0)
Block(0,8,8,STATIONARY_WATER:0)
Block(0,9,-7,STATIONARY_WATER:0)
Block(0,9,-6,STATIONARY_WATER:0)
Block(0,9,-5,STATIONARY_WATER:0)
Block(0,9,-4,STATIONARY_WATER:0)
Block(0,9,-3,STATIONARY_WATER:0)
Block(0,9,-2,STATIONARY_WATER:0)
Block(0,9,-1,STATIONARY_WATER:0)
Block(0,9,0,STATIONARY_WATER:0)
Block(0,9,1,STATIONARY_WATER:0)
Block(0,9,2,STATIONARY_WATER:0)
Block(0,9,3,STATIONARY_WATER:0)
Block(0,9,4,STATIONARY_WATER:0)
Block(0,9,5,STATIONARY_WATER:0)
Block(0,9,6,STATIONARY_WATER:0)
Block(0,9,7,STATIONARY_WATER:0)
Block(0,9,8,STATIONARY_WATER:0)
Block(0,10,-7,STATIONARY_WATER:0)
Block(0,10,-6,STATIONARY_WATER:0)
Block(0,10,-5,STATIONARY_WATER:0)
Block(0,10,-4,STATIONARY_WATER:0)
Block(0,10,-3,STATIONARY_WATER:0)
Block(0,10,-2,STATIONARY_WATER:0)
Block(0,10,-1,STATIONARY_WATER:0)
Block(0,10,0,STATIONARY_WATER:0)
Block(0,10,1,STATIONARY_WATER:0)
Block(0,10,2,STATIONARY_WATER:0)
Block(0,10,3,STATIONARY_WATER:0)
Block(0,10,4,STATIONARY_WATER:0)
Block(0,10,5,STATIONARY_WATER:0)
Block(0,10,6,STATIONARY_WATER:0)
Block(0,10,7,STATIONARY_WATER:0)
Block(0,10,8,STATIONARY_WATER:0)
Block(0,11,-7,STATIONARY_WATER:0)
Block(0,11,-6,STATIONARY_WATER:0)
Block(0,11,-5,STATIONARY_WATER:0)
Block(0,11,-4,STATIONARY_WATER:0)
Block(0,11,-3,STATIONARY_WATER:0)
Block(0,11,-2,STATIONARY_WATER:0)
Block(0,11,-1,STATIONARY_WATER:0)
Block(0,11,0,STATIONARY_WATER:0)
Block(0,11,1,STATIONARY_WATER:0)
Block(0,11,2,STATIONARY_WATER:0)
Block(0,11,3,STATIONARY_WATER:0)
Block(0,11,4,STATIONARY_WATER:0)
Block(0,11,5,STATIONARY_WATER:0)
Block(0,11,6,STATIONARY_WATER:0)
Block(0,11,7,STATIONARY_WATER:0)
Block(0,11,8,STATIONARY_WATER:0)
Block(1,0,-7,STONE:6)
Block(1,0,-6,DIRT:0)
Block(1,0,-5,DIRT:0)
Block(1,0,-4,DIRT:0)
Block(1,0,-3,DIRT:0)
Block(1,0,-2,DIRT:0)
Block(1,0,-1,DIRT:0)
Block(1,0,0,DIRT:0)
Block(1,0,1,DIRT:0)
Block(1,0,2,DIRT:0)
Block(1,0,3,DIRT:0)
Block(1,0,4,DIRT:0)
Block(1,0,5,DIRT:0)
Block(1,0,6,DIRT:0)
Block(1,0,7,DIRT:0)
Block(1,0,8,DIRT:0)
Block(1,1,-7,SAND:0)
Block(1,1,-6,SAND:0)
Block(1,1,-5,SAND:0)
Block(1,1,-4,SAND:0)
Block(1,1,-3,SAND:0)
Block(1,1,-2,SAND:0)
Block(1,1,-1,CLAY:0)
Block(1,1,0,SAND:0)
Block(1,1,1,SAND:0)
Block(1,1,2,SAND:0)
Block(1,1,3,SAND:0)
Block(1,1,4,SAND:0)
Block(1,1,5,SAND:0)
Block(1,1,6,SAND:0)
Block(1,1,7,SAND:0)
Block(1,1,8,SAND:0)
Block(1,2,-7,STATIONARY_WATER:0)
Block(1,2,-6,STATIONARY_WATER:0)
Block(1,2,-5,STATIONARY_WATER:0)
Block(1,2,-4,STATIONARY_WATER:0)
Block(1,2,-3,STATIONARY_WATER:0)
Block(1,2,-2,STATIONARY_WATER:0)
Block(1,2,-1,STATIONARY_WATER:0)
Block(1,2,0,CLAY:0)
Block(1,2,1,CLAY:0)
Block(1,2,2,CLAY:0)
Block(1,2,3,CLAY:0)
Block(1,2,4,CLAY:0)
Block(1,2,5,SAND:0)
Block(1,2,6,SAND:0)
Block(1,2,7,SAND:0)
Block(1,2,8,SAND:0)
Block(1,3,-7,STATIONARY_WATER:0)
Block(1,3,-6,STATIONARY_WATER:0)
Block(1,3,-5,STATIONARY_WATER:0)
Block(1,3,-4,STATIONARY_WATER:0)
Block(1,3,-3,STATIONARY_WATER:0)
Block(1,3,-2,STATIONARY_WATER:0)
Block(1,3,-1,STATIONARY_WATER:0)
Block(1,3,0,STATIONARY_WATER:0)
Block(1,3,1,STATIONARY_WATER:0)
Block(1,3,2,STATIONARY_WATER:0)
Block(1,3,3,STATIONARY_WATER:0)
Block(1,3,4,STATIONARY_WATER:0)
Block(1,3,5,CLAY:0)
Block(1,3,6,CLAY:0)
Block(1,3,7,CLAY:0)
Block(1,3,8,CLAY:0)
Block(1,4,-7,STATIONARY_WATER:0)
Block(1,4,-6,STATIONARY_WATER:0)
Block(1,4,-5,STATIONARY_WATER:0)
Block(1,4,-4,STATIONARY_WATER:0)
Block(1,4,-3,STATIONARY_WATER:0)
Block(1,4,-2,STATIONARY_WATER:0)
Block(1,4,-1,STATIONARY_WATER:0)
Block(1,4,0,STATIONARY_WATER:0)
Block(1,4,1,STATIONARY_WATER:0)
Block(1,4,2,STATIONARY_WATER:0)
Block(1,4,3,STATIONARY_WATER:0)
Block(1,4,4,STATIONARY_WATER:0)
Block(1,4,5,STATIONARY_WATER:0)
Block(1,4,6,STATIONARY_WATER:0)
Block(1,4,7,STATIONARY_WATER:0)
Block(1,4,8,STATIONARY_WATER:0)
Block(1,5,-7,STATIONARY_WATER:0)
Block(1,5,-6,STATIONARY_WATER:0)
Block(1,5,-5,STATIONARY_WATER:0)
Block(1,5,-4,STATIONARY_WATER:0)
Block(1,5,-3,STATIONARY_WATER:0)
Block(1,5,-2,STATIONARY_WATER:0)
Block(1,5,-1,STATIONARY_WATER:0)
Block(1,5,0,STATIONARY_WATER:0)
Block(1,5,1,STATIONARY_WATER:0)
Block(1,5,2,STATIONARY_WATER:0)
Block(1,5,3,STATIONARY_WATER:0)
Block(1,5,4,STATIONARY_WATER:0)
Block(1,5,5,STATIONARY_WATER:0)
Block(1,5,6,STATIONARY_WATER:0)
Block(1,5,7,STATIONARY_WATER:0)
Block(1,5,8,STATIONARY_WATER:0)
Block(1,6,-7,STATIONARY_WATER:0)
Block(1,6,-6,STATIONARY_WATER:0)
Block(1,6,-5,STATIONARY_WATER:0)
Block(1,6,-4,STATIONARY_WATER:0)
Block(1,6,-3,STATIONARY_WATER:0)
Block(1,6,-2,STATIONARY_WATER:0)
Block(1,6,-1,STATIONARY_WATER:0)
Block(1,6,0,STATIONARY_WATER:0)
Block(1,6,1,STATIONARY_WATER:0)
Block(1,6,2,STATIONARY_WATER:0)
Block(1,6,3,STATIONARY_WATER:0)
Block(1,6,4,STATIONARY_WATER:0)
Block(1,6,5,STATIONARY_WATER:0)
Block(1,6,6,STATIONARY_WATER:0)
Block(1,6,7,STATIONARY_WATER:0)
Block(1,6,8,STATIONARY_WATER:0)
Block(1,7,-7,STATIONARY_WATER:0)
Block(1,7,-6,STATIONARY_WATER:0)
Block(1,7,-5,STATIONARY_WATER:0)
Block(1,7,-4,STATIONARY_WATER:0)
Block(1,7,-3,STATIONARY_WATER:0)
Block(1,7,-2,STATIONARY_WATER:0)
Block(1,7,-1,STATIONARY_WATER:0)
Block(1,7,0,STATIONARY_WATER:0)
Block(1,7,1,STATIONARY_WATER:0)
Block(1,7,2,STATIONARY_WATER:0)
Block(1,7,3,STATIONARY_WATER:0)
Block(1,7,4,STATIONARY_WATER:0)
Block(1,7,5,STATIONARY_WATER:0)
Block(1,7,6,STATIONARY_WATER:0)
Block(1,7,7,STATIONARY_WATER:0)
Block(1,7,8,STATIONARY_WATER:0)
Block(1,8,-7,STATIONARY_WATER:0)
Block(1,8,-6,STATIONARY_WATER:0)
Block(1,8,-5,STATIONARY_WATER:0)
Block(1,8,-4,STATIONARY_WATER:0)
Block(1,8,-3,STATIONARY_WATER:0)
Block(1,8,-2,STATIONARY_WATER:0)
Block(1,8,-1,STATIONARY_WATER:0)
Block(1,8,0,STATIONARY_WATER:0)
Block(1,8,1,STATIONARY_WATER:0)
Block(1,8,2,STATIONARY_WATER:0)
Block(1,8,3,STATIONARY_WATER:0)
Block(1,8,4,STATIONARY_WATER:0)
Block(1,8,5,STATIONARY_WATER:0)
Block(1,8,6,STATIONARY_WATER:0)
Block(1,8,7,STATIONARY_WATER:0)
Block(1,8,8,STATIONARY_WATER:0)
Block(1,9,-7,STATIONARY_WATER:0)
Block(1,9,-6,STATIONARY_WATER:0)
Block(1,9,-5,STATIONARY_WATER:0)
Block(1,9,-4,STATIONARY_WATER:0)
Block(1,9,-3,STATIONARY_WATER:0)
Block(1,9,-2,STATIONARY_WATER:0)
Block(1,9,-1,STATIONARY_WATER:0)
Block(1,9,0,STATIONARY_WATER:0)
Block(1,9,1,STATIONARY_WATER:0)
Block(1,9,2,STATIONARY_WATER:0)
Block(1,9,3,STATIONARY_WATER:0)
Block(1,9,4,STATIONARY_WATER:0)
Block(1,9,5,STATIONARY_WATER:0)
Block(1,9,6,STATIONARY_WATER:0)
Block(1,9,7,STATIONARY_WATER:0)
Block(1,9,8,STATIONARY_WATER:0)
Block(1,10,-7,STATIONARY_WATER:0)
Block(1,10,-6,STATIONARY_WATER:0)
Block(1,10,-5,STATIONARY_WATER:0)
Block(1,10,-4,STATIONARY_WATER:0)
Block(1,10,-3,STATIONARY_WATER:0)
Block(1,10,-2,STATIONARY_WATER:0)
Block(1,10,-1,STATIONARY_WATER:0)
Block(1,10,0,STATIONARY_WATER:0)
Block(1,10,1,STATIONARY_WATER:0)
Block(1,10,2,STATIONARY_WATER:0)
Block(1,10,3,STATIONARY_WATER:0)
Block(1,10,4,STATIONARY_WATER:0)
Block(1,10,5,STATIONARY_WATER:0)
Block(1,10,6,STATIONARY_WATER:0)
Block(1,10,7,STATIONARY_WATER:0)
Block(1,10,8,STATIONARY_WATER:0)
Block(1,11,-7,STATIONARY_WATER:0)
Block(1,11,-6,STATIONARY_WATER:0)
Block(1,11,-5,STATIONARY_WATER:0)
Block(1,11,-4,STATIONARY_WATER:0)
Block(1,11,-3,STATIONARY_WATER:0)
Block(1,11,-2,STATIONARY_WATER:0)
Block(1,11,-1,STATIONARY_WATER:0)
Block(1,11,0,STATIONARY_WATER:0)
Block(1,11,1,STATIONARY_WATER:0)
Block(1,11,2,STATIONARY_WATER:0)
Block(1,11,3,STATIONARY_WATER:0)
Block(1,11,4,STATIONARY_WATER:0)
Block(1,11,5,STATIONARY_WATER:0)
Block(1,11,6,STATIONARY_WATER:0)
Block(1,11,7,STATIONARY_WATER:0)
Block(1,11,8,STATIONARY_WATER:0)
Block(2,0,-7,DIRT:0)
Block(2,0,-6,DIRT:0)
Block(2,0,-5,DIRT:0)
Block(2,0,-4,DIRT:0)
Block(2,0,-3,DIRT:0)
Block(2,0,-2,DIRT:0)
Block(2,0,-1,DIRT:0)
Block(2,0,0,DIRT:0)
Block(2,0,1,DIRT:0)
Block(2,0,2,DIRT:0)
Block(2,0,3,DIRT:0)
Block(2,0,4,DIRT:0)
Block(2,0,5,DIRT:0)
Block(2,0,6,DIRT:0)
Block(2,0,7,DIRT:0)
Block(2,0,8,DIRT:0)
Block(2,1,-7,STONE:6)
Block(2,1,-6,SAND:0)
Block(2,1,-5,SAND:0)
Block(2,1,-4,SAND:0)
Block(2,1,-3,SAND:0)
Block(2,1,-2,SAND:0)
Block(2,1,-1,CLAY:0)
Block(2,1,0,SAND:0)
Block(2,1,1,SAND:0)
Block(2,1,2,SAND:0)
Block(2,1,3,SAND:0)
Block(2,1,4,SAND:0)
Block(2,1,5,SAND:0)
Block(2,1,6,SAND:0)
Block(2,1,7,SAND:0)
Block(2,1,8,SAND:0)
Block(2,2,-7,STONE:6)
Block(2,2,-6,STATIONARY_WATER:0)
Block(2,2,-5,STATIONARY_WATER:0)
Block(2,2,-4,STATIONARY_WATER:0)
Block(2,2,-3,STATIONARY_WATER:0)
Block(2,2,-2,STATIONARY_WATER:0)
Block(2,2,-1,STATIONARY_WATER:0)
Block(2,2,0,CLAY:0)
Block(2,2,1,CLAY:0)
Block(2,2,2,CLAY:0)
Block(2,2,3,CLAY:0)
Block(2,2,4,SAND:0)
Block(2,2,5,SAND:0)
Block(2,2,6,SAND:0)
Block(2,2,7,SAND:0)
Block(2,2,8,SAND:0)
Block(2,3,-7,STONE:6)
Block(2,3,-6,STATIONARY_WATER:0)
Block(2,3,-5,STATIONARY_WATER:0)
Block(2,3,-4,STATIONARY_WATER:0)
Block(2,3,-3,STATIONARY_WATER:0)
Block(2,3,-2,STATIONARY_WATER:0)
Block(2,3,-1,STATIONARY_WATER:0)
Block(2,3,0,STATIONARY_WATER:0)
Block(2,3,1,STATIONARY_WATER:0)
Block(2,3,2,STATIONARY_WATER:0)
Block(2,3,3,STATIONARY_WATER:0)
Block(2,3,4,CLAY:0)
Block(2,3,5,CLAY:0)
Block(2,3,6,CLAY:0)
Block(2,3,7,CLAY:0)
Block(2,3,8,CLAY:0)
Block(2,4,-7,STONE:6)
Block(2,4,-6,STATIONARY_WATER:0)
Block(2,4,-5,STATIONARY_WATER:0)
Block(2,4,-4,STATIONARY_WATER:0)
Block(2,4,-3,STATIONARY_WATER:0)
Block(2,4,-2,STATIONARY_WATER:0)
Block(2,4,-1,STATIONARY_WATER:0)
Block(2,4,0,STATIONARY_WATER:0)
Block(2,4,1,STATIONARY_WATER:0)
Block(2,4,2,STATIONARY_WATER:0)
Block(2,4,3,STATIONARY_WATER:0)
Block(2,4,4,STATIONARY_WATER:0)
Block(2,4,5,STATIONARY_WATER:0)
Block(2,4,6,STATIONARY_WATER:0)
Block(2,4,7,STATIONARY_WATER:0)
Block(2,4,8,STATIONARY_WATER:0)
Block(2,5,-7,STONE:6)
Block(2,5,-6,STATIONARY_WATER:0)
Block(2,5,-5,STATIONARY_WATER:0)
Block(2,5,-4,STATIONARY_WATER:0)
Block(2,5,-3,STATIONARY_WATER:0)
Block(2,5,-2,STATIONARY_WATER:0)
Block(2,5,-1,STATIONARY_WATER:0)
Block(2,5,0,STATIONARY_WATER:0)
Block(2,5,1,STATIONARY_WATER:0)
Block(2,5,2,STATIONARY_WATER:0)
Block(2,5,3,STATIONARY_WATER:0)
Block(2,5,4,STATIONARY_WATER:0)
Block(2,5,5,STATIONARY_WATER:0)
Block(2,5,6,STATIONARY_WATER:0)
Block(2,5,7,STATIONARY_WATER:0)
Block(2,5,8,STATIONARY_WATER:0)
Block(2,6,-7,STONE:6)
Block(2,6,-6,STATIONARY_WATER:0)
Block(2,6,-5,STATIONARY_WATER:0)
Block(2,6,-4,STATIONARY_WATER:0)
Block(2,6,-3,STATIONARY_WATER:0)
Block(2,6,-2,STATIONARY_WATER:0)
Block(2,6,-1,STATIONARY_WATER:0)
Block(2,6,0,STATIONARY_WATER:0)
Block(2,6,1,STATIONARY_WATER:0)
Block(2,6,2,STATIONARY_WATER:0)
Block(2,6,3,STATIONARY_WATER:0)
Block(2,6,4,STATIONARY_WATER:0)
Block(2,6,5,STATIONARY_WATER:0)
Block(2,6,6,STATIONARY_WATER:0)
Block(2,6,7,STATIONARY_WATER:0)
Block(2,6,8,STATIONARY_WATER:0)
Block(2,7,-7,STONE:6)
Block(2,7,-6,STATIONARY_WATER:0)
Block(2,7,-5,STATIONARY_WATER:0)
Block(2,7,-4,STATIONARY_WATER:0)
Block(2,7,-3,STATIONARY_WATER:0)
Block(2,7,-2,STATIONARY_WATER:0)
Block(2,7,-1,STATIONARY_WATER:0)
Block(2,7,0,STATIONARY_WATER:0)
Block(2,7,1,STATIONARY_WATER:0)
Block(2,7,2,STATIONARY_WATER:0)
Block(2,7,3,STATIONARY_WATER:0)
Block(2,7,4,STATIONARY_WATER:0)
Block(2,7,5,STATIONARY_WATER:0)
Block(2,7,6,STATIONARY_WATER:0)
Block(2,7,7,STATIONARY_WATER:0)
Block(2,7,8,STATIONARY_WATER:0)
Block(2,8,-7,STONE:6)
Block(2,8,-6,STATIONARY_WATER:0)
Block(2,8,-5,STATIONARY_WATER:0)
Block(2,8,-4,STATIONARY_WATER:0)
Block(2,8,-3,STATIONARY_WATER:0)
Block(2,8,-2,STATIONARY_WATER:0)
Block(2,8,-1,STATIONARY_WATER:0)
Block(2,8,0,STATIONARY_WATER:0)
Block(2,8,1,STATIONARY_WATER:0)
Block(2,8,2,STATIONARY_WATER:0)
Block(2,8,3,STATIONARY_WATER:0)
Block(2,8,4,STATIONARY_WATER:0)
Block(2,8,5,STATIONARY_WATER:0)
Block(2,8,6,STATIONARY_WATER:0)
Block(2,8,7,STATIONARY_WATER:0)
Block(2,8,8,STATIONARY_WATER:0)
Block(2,9,-7,STONE:6)
Block(2,9,-6,STATIONARY_WATER:0)
Block(2,9,-5,STATIONARY_WATER:0)
Block(2,9,-4,STATIONARY_WATER:0)
Block(2,9,-3,STATIONARY_WATER:0)
Block(2,9,-2,STATIONARY_WATER:0)
Block(2,9,-1,STATIONARY_WATER:0)
Block(2,9,0,STATIONARY_WATER:0)
Block(2,9,1,STATIONARY_WATER:0)
Block(2,9,2,STATIONARY_WATER:0)
Block(2,9,3,STATIONARY_WATER:0)
Block(2,9,4,STATIONARY_WATER:0)
Block(2,9,5,STATIONARY_WATER:0)
Block(2,9,6,STATIONARY_WATER:0)
Block(2,9,7,STATIONARY_WATER:0)
Block(2,9,8,STATIONARY_WATER:0)
Block(2,10,-7,STONE:6)
Block(2,10,-6,STATIONARY_WATER:0)
Block(2,10,-5,STATIONARY_WATER:0)
Block(2,10,-4,STATIONARY_WATER:0)
Block(2,10,-3,STATIONARY_WATER:0)
Block(2,10,-2,STATIONARY_WATER:0)
Block(2,10,-1,STATIONARY_WATER:0)
Block(2,10,0,STATIONARY_WATER:0)
Block(2,10,1,STATIONARY_WATER:0)
Block(2,10,2,STATIONARY_WATER:0)
Block(2,10,3,STATIONARY_WATER:0)
Block(2,10,4,STATIONARY_WATER:0)
Block(2,10,5,STATIONARY_WATER:0)
Block(2,10,6,STATIONARY_WATER:0)
Block(2,10,7,STATIONARY_WATER:0)
Block(2,10,8,STATIONARY_WATER:0)
Block(2,11,-7,STONE:6)
Block(2,11,-6,STATIONARY_WATER:0)
Block(2,11,-5,STATIONARY_WATER:0)
Block(2,11,-4,STATIONARY_WATER:0)
Block(2,11,-3,STATIONARY_WATER:0)
Block(2,11,-2,STATIONARY_WATER:0)
Block(2,11,-1,STATIONARY_WATER:0)
Block(2,11,0,STATIONARY_WATER:0)
Block(2,11,1,STATIONARY_WATER:0)
Block(2,11,2,STATIONARY_WATER:0)
Block(2,11,3,STATIONARY_WATER:0)
Block(2,11,4,STATIONARY_WATER:0)
Block(2,11,5,STATIONARY_WATER:0)
Block(2,11,6,STATIONARY_WATER:0)
Block(2,11,7,STATIONARY_WATER:0)
Block(2,11,8,STATIONARY_WATER:0)
Block(3,0,-7,DIRT:0)
Block(3,0,-6,DIRT:0)
Block(3,0,-5,DIRT:0)
Block(3,0,-4,DIRT:0)
Block(3,0,-3,DIRT:0)
Block(3,0,-2,DIRT:0)
Block(3,0,-1,DIRT:0)
Block(3,0,0,DIRT:0)
Block(3,0,1,DIRT:0)
Block(3,0,2,DIRT:0)
Block(3,0,3,DIRT:0)
Block(3,0,4,DIRT:0)
Block(3,0,5,DIRT:0)
Block(3,0,6,DIRT:0)
Block(3,0,7,DIRT:0)
Block(3,0,8,DIRT:0)
Block(3,1,-7,STONE:6)
Block(3,1,-6,SAND:0)
Block(3,1,-5,SAND:0)
Block(3,1,-4,SAND:0)
Block(3,1,-3,SAND:0)
Block(3,1,-2,SAND:0)
Block(3,1,-1,CLAY:0)
Block(3,1,0,SAND:0)
Block(3,1,1,SAND:0)
Block(3,1,2,SAND:0)
Block(3,1,3,SAND:0)
Block(3,1,4,SAND:0)
Block(3,1,5,SAND:0)
Block(3,1,6,SAND:0)
Block(3,1,7,SAND:0)
Block(3,1,8,SAND:0)
Block(3,2,-7,STONE:6)
Block(3,2,-6,STATIONARY_WATER:0)
Block(3,2,-5,STATIONARY_WATER:0)
Block(3,2,-4,STATIONARY_WATER:0)
Block(3,2,-3,STATIONARY_WATER:0)
Block(3,2,-2,STATIONARY_WATER:0)
Block(3,2,-1,STATIONARY_WATER:0)
Block(3,2,0,CLAY:0)
Block(3,2,1,CLAY:0)
Block(3,2,2,CLAY:0)
Block(3,2,3,CLAY:0)
Block(3,2,4,CLAY:0)
Block(3,2,5,SAND:0)
Block(3,2,6,SAND:0)
Block(3,2,7,SAND:0)
Block(3,2,8,SAND:0)
Block(3,3,-7,STONE:6)
Block(3,3,-6,STATIONARY_WATER:0)
Block(3,3,-5,STATIONARY_WATER:0)
Block(3,3,-4,STATIONARY_WATER:0)
Block(3,3,-3,STATIONARY_WATER:0)
Block(3,3,-2,STATIONARY_WATER:0)
Block(3,3,-1,STATIONARY_WATER:0)
Block(3,3,0,STATIONARY_WATER:0)
Block(3,3,1,STATIONARY_WATER:0)
Block(3,3,2,STATIONARY_WATER:0)
Block(3,3,3,STATIONARY_WATER:0)
Block(3,3,4,STATIONARY_WATER:0)
Block(3,3,5,CLAY:0)
Block(3,3,6,CLAY:0)
Block(3,3,7,CLAY:0)
Block(3,3,8,SAND:0)
Block(3,4,-7,STONE:6)
Block(3,4,-6,STATIONARY_WATER:0)
Block(3,4,-5,STATIONARY_WATER:0)
Block(3,4,-4,STATIONARY_WATER:0)
Block(3,4,-3,STATIONARY_WATER:0)
Block(3,4,-2,STATIONARY_WATER:0)
Block(3,4,-1,STATIONARY_WATER:0)
Block(3,4,0,STATIONARY_WATER:0)
Block(3,4,1,STATIONARY_WATER:0)
Block(3,4,2,STATIONARY_WATER:0)
Block(3,4,3,STATIONARY_WATER:0)
Block(3,4,4,STATIONARY_WATER:0)
Block(3,4,5,STATIONARY_WATER:0)
Block(3,4,6,STATIONARY_WATER:0)
Block(3,4,7,STATIONARY_WATER:0)
Block(3,4,8,STATIONARY_WATER:0)
Block(3,5,-7,STONE:6)
Block(3,5,-6,STATIONARY_WATER:0)
Block(3,5,-5,STATIONARY_WATER:0)
Block(3,5,-4,STATIONARY_WATER:0)
Block(3,5,-3,STATIONARY_WATER:0)
Block(3,5,-2,STATIONARY_WATER:0)
Block(3,5,-1,STATIONARY_WATER:0)
Block(3,5,0,STATIONARY_WATER:0)
Block(3,5,1,STATIONARY_WATER:0)
Block(3,5,2,STATIONARY_WATER:0)
Block(3,5,3,STATIONARY_WATER:0)
Block(3,5,4,STATIONARY_WATER:0)
Block(3,5,5,STATIONARY_WATER:0)
Block(3,5,6,STATIONARY_WATER:0)
Block(3,5,7,STATIONARY_WATER:0)
Block(3,5,8,STATIONARY_WATER:0)
Block(3,6,-7,STONE:6)
Block(3,6,-6,STATIONARY_WATER:0)
Block(3,6,-5,STATIONARY_WATER:0)
Block(3,6,-4,STATIONARY_WATER:0)
Block(3,6,-3,STATIONARY_WATER:0)
Block(3,6,-2,STATIONARY_WATER:0)
Block(3,6,-1,STATIONARY_WATER:0)
Block(3,6,0,STATIONARY_WATER:0)
Block(3,6,1,STATIONARY_WATER:0)
Block(3,6,2,STATIONARY_WATER:0)
Block(3,6,3,STATIONARY_WATER:0)
Block(3,6,4,STATIONARY_WATER:0)
Block(3,6,5,STATIONARY_WATER:0)
Block(3,6,6,STATIONARY_WATER:0)
Block(3,6,7,STATIONARY_WATER:0)
Block(3,6,8,STATIONARY_WATER:0)
Block(3,7,-7,STONE:6)
Block(3,7,-6,STATIONARY_WATER:0)
Block(3,7,-5,STATIONARY_WATER:0)
Block(3,7,-4,STATIONARY_WATER:0)
Block(3,7,-3,STATIONARY_WATER:0)
Block(3,7,-2,STATIONARY_WATER:0)
Block(3,7,-1,STATIONARY_WATER:0)
Block(3,7,0,STATIONARY_WATER:0)
Block(3,7,1,STATIONARY_WATER:0)
Block(3,7,2,STATIONARY_WATER:0)
Block(3,7,3,STATIONARY_WATER:0)
Block(3,7,4,STATIONARY_WATER:0)
Block(3,7,5,STATIONARY_WATER:0)
Block(3,7,6,STATIONARY_WATER:0)
Block(3,7,7,STATIONARY_WATER:0)
Block(3,7,8,STATIONARY_WATER:0)
Block(3,8,-7,STONE:6)
Block(3,8,-6,STATIONARY_WATER:0)
Block(3,8,-5,STATIONARY_WATER:0)
Block(3,8,-4,STATIONARY_WATER:0)
Block(3,8,-3,STATIONARY_WATER:0)
Block(3,8,-2,STATIONARY_WATER:0)
Block(3,8,-1,STATIONARY_WATER:0)
Block(3,8,0,STATIONARY_WATER:0)
Block(3,8,1,STATIONARY_WATER:0)
Block(3,8,2,STATIONARY_WATER:0)
Block(3,8,3,STATIONARY_WATER:0)
Block(3,8,4,STATIONARY_WATER:0)
Block(3,8,5,STATIONARY_WATER:0)
Block(3,8,6,STATIONARY_WATER:0)
Block(3,8,7,STATIONARY_WATER:0)
Block(3,8,8,STATIONARY_WATER:0)
Block(3,9,-7,STONE:6)
Block(3,9,-6,STATIONARY_WATER:0)
Block(3,9,-5,STATIONARY_WATER:0)
Block(3,9,-4,STATIONARY_WATER:0)
Block(3,9,-3,STATIONARY_WATER:0)
Block(3,9,-2,STATIONARY_WATER:0)
Block(3,9,-1,STATIONARY_WATER:0)
Block(3,9,0,STATIONARY_WATER:0)
Block(3,9,1,STATIONARY_WATER:0)
Block(3,9,2,STATIONARY_WATER:0)
Block(3,9,3,STATIONARY_WATER:0)
Block(3,9,4,STATIONARY_WATER:0)
Block(3,9,5,STATIONARY_WATER:0)
Block(3,9,6,STATIONARY_WATER:0)
Block(3,9,7,STATIONARY_WATER:0)
Block(3,9,8,STATIONARY_WATER:0)
Block(3,10,-7,STONE:6)
Block(3,10,-6,STATIONARY_WATER:0)
Block(3,10,-5,STATIONARY_WATER:0)
Block(3,10,-4,STATIONARY_WATER:0)
Block(3,10,-3,STATIONARY_WATER:0)
Block(3,10,-2,STATIONARY_WATER:0)
Block(3,10,-1,STATIONARY_WATER:0)
Block(3,10,0,STATIONARY_WATER:0)
Block(3,10,1,STATIONARY_WATER:0)
Block(3,10,2,STATIONARY_WATER:0)
Block(3,10,3,STATIONARY_WATER:0)
Block(3,10,4,STATIONARY_WATER:0)
Block(3,10,5,STATIONARY_WATER:0)
Block(3,10,6,STATIONARY_WATER:0)
Block(3,10,7,STATIONARY_WATER:0)
Block(3,10,8,STATIONARY_WATER:0)
Block(3,11,-7,STONE:6)
Block(3,11,-6,STATIONARY_WATER:0)
Block(3,11,-5,STATIONARY_WATER:0)
Block(3,11,-4,STATIONARY_WATER:0)
Block(3,11,-3,STATIONARY_WATER:0)
Block(3,11,-2,STATIONARY_WATER:0)
Block(3,11,-1,STATIONARY_WATER:0)
Block(3,11,0,STATIONARY_WATER:0)
Block(3,11,1,STATIONARY_WATER:0)
Block(3,11,2,STATIONARY_WATER:0)
Block(3,11,3,STATIONARY_WATER:0)
Block(3,11,4,STATIONARY_WATER:0)
Block(3,11,5,STATIONARY_WATER:0)
Block(3,11,6,STATIONARY_WATER:0)
Block(3,11,7,STATIONARY_WATER:0)
Block(3,11,8,STATIONARY_WATER:0)
Block(4,0,-7,DIRT:0)
Block(4,0,-6,DIRT:0)
Block(4,0,-5,DIRT:0)
Block(4,0,-4,DIRT:0)
Block(4,0,-3,DIRT:0)
Block(4,0,-2,DIRT:0)
Block(4,0,-1,DIRT:0)
Block(4,0,0,DIRT:0)
Block(4,0,1,DIRT:0)
Block(4,0,2,DIRT:0)
Block(4,0,3,DIRT:0)
Block(4,0,4,DIRT:0)
Block(4,0,5,DIRT:0)
Block(4,0,6,DIRT:0)
Block(4,0,7,DIRT:0)
Block(4,0,8,DIRT:0)
Block(4,1,-7,STONE:6)
Block(4,1,-6,STONE:6)
Block(4,1,-5,SAND:0)
Block(4,1,-4,SAND:0)
Block(4,1,-3,SAND:0)
Block(4,1,-2,SAND:0)
Block(4,1,-1,CLAY:0)
Block(4,1,0,CLAY:0)
Block(4,1,1,SAND:0)
Block(4,1,2,SAND:0)
Block(4,1,3,SAND:0)
Block(4,1,4,SAND:0)
Block(4,1,5,SAND:0)
Block(4,1,6,SAND:0)
Block(4,1,7,SAND:0)
Block(4,1,8,SAND:0)
Block(4,2,-7,STONE:6)
Block(4,2,-6,STONE:6)
Block(4,2,-5,STATIONARY_WATER:0)
Block(4,2,-4,STATIONARY_WATER:0)
Block(4,2,-3,STATIONARY_WATER:0)
Block(4,2,-2,STATIONARY_WATER:0)
Block(4,2,-1,STATIONARY_WATER:0)
Block(4,2,0,STATIONARY_WATER:0)
Block(4,2,1,CLAY:0)
Block(4,2,2,CLAY:0)
Block(4,2,3,CLAY:0)
Block(4,2,4,CLAY:0)
Block(4,2,5,SAND:0)
Block(4,2,6,SAND:0)
Block(4,2,7,SAND:0)
Block(4,2,8,SAND:0)
Block(4,3,-7,STONE:6)
Block(4,3,-6,STONE:6)
Block(4,3,-5,STATIONARY_WATER:0)
Block(4,3,-4,STATIONARY_WATER:0)
Block(4,3,-3,STATIONARY_WATER:0)
Block(4,3,-2,STATIONARY_WATER:0)
Block(4,3,-1,STATIONARY_WATER:0)
Block(4,3,0,STATIONARY_WATER:0)
Block(4,3,1,STATIONARY_WATER:0)
Block(4,3,2,STATIONARY_WATER:0)
Block(4,3,3,STATIONARY_WATER:0)
Block(4,3,4,STATIONARY_WATER:0)
Block(4,3,5,CLAY:0)
Block(4,3,6,CLAY:0)
Block(4,3,7,SAND:0)
Block(4,3,8,SAND:0)
Block(4,4,-7,STONE:6)
Block(4,4,-6,STONE:6)
Block(4,4,-5,STATIONARY_WATER:0)
Block(4,4,-4,STATIONARY_WATER:0)
Block(4,4,-3,STATIONARY_WATER:0)
Block(4,4,-2,STATIONARY_WATER:0)
Block(4,4,-1,STATIONARY_WATER:0)
Block(4,4,0,STATIONARY_WATER:0)
Block(4,4,1,STATIONARY_WATER:0)
Block(4,4,2,STATIONARY_WATER:0)
Block(4,4,3,STATIONARY_WATER:0)
Block(4,4,4,STATIONARY_WATER:0)
Block(4,4,5,STATIONARY_WATER:0)
Block(4,4,6,STATIONARY_WATER:0)
Block(4,4,7,STATIONARY_WATER:0)
Block(4,4,8,STATIONARY_WATER:0)
Block(4,5,-7,STONE:6)
Block(4,5,-6,STONE:6)
Block(4,5,-5,STATIONARY_WATER:0)
Block(4,5,-4,STATIONARY_WATER:0)
Block(4,5,-3,STATIONARY_WATER:0)
Block(4,5,-2,STATIONARY_WATER:0)
Block(4,5,-1,STATIONARY_WATER:0)
Block(4,5,0,STATIONARY_WATER:0)
Block(4,5,1,STATIONARY_WATER:0)
Block(4,5,2,STATIONARY_WATER:0)
Block(4,5,3,STATIONARY_WATER:0)
Block(4,5,4,STATIONARY_WATER:0)
Block(4,5,5,STATIONARY_WATER:0)
Block(4,5,6,STATIONARY_WATER:0)
Block(4,5,7,STATIONARY_WATER:0)
Block(4,5,8,STATIONARY_WATER:0)
Block(4,6,-7,STONE:6)
Block(4,6,-6,STONE:6)
Block(4,6,-5,STATIONARY_WATER:0)
Block(4,6,-4,STATIONARY_WATER:0)
Block(4,6,-3,STATIONARY_WATER:0)
Block(4,6,-2,STATIONARY_WATER:0)
Block(4,6,-1,STATIONARY_WATER:0)
Block(4,6,0,STATIONARY_WATER:0)
Block(4,6,1,STATIONARY_WATER:0)
Block(4,6,2,STATIONARY_WATER:0)
Block(4,6,3,STATIONARY_WATER:0)
Block(4,6,4,STATIONARY_WATER:0)
Block(4,6,5,STATIONARY_WATER:0)
Block(4,6,6,STATIONARY_WATER:0)
Block(4,6,7,STATIONARY_WATER:0)
Block(4,6,8,STATIONARY_WATER:0)
Block(4,7,-7,STONE:6)
Block(4,7,-6,STONE:6)
Block(4,7,-5,STATIONARY_WATER:0)
Block(4,7,-4,STATIONARY_WATER:0)
Block(4,7,-3,STATIONARY_WATER:0)
Block(4,7,-2,STATIONARY_WATER:0)
Block(4,7,-1,STATIONARY_WATER:0)
Block(4,7,0,STATIONARY_WATER:0)
Block(4,7,1,STATIONARY_WATER:0)
Block(4,7,2,STATIONARY_WATER:0)
Block(4,7,3,STATIONARY_WATER:0)
Block(4,7,4,STATIONARY_WATER:0)
Block(4,7,5,STATIONARY_WATER:0)
Block(4,7,6,STATIONARY_WATER:0)
Block(4,7,7,STATIONARY_WATER:0)
Block(4,7,8,STATIONARY_WATER:0)
Block(4,8,-7,STONE:6)
Block(4,8,-6,STONE:6)
Block(4,8,-5,STATIONARY_WATER:0)
Block(4,8,-4,STATIONARY_WATER:0)
Block(4,8,-3,STATIONARY_WATER:0)
Block(4,8,-2,STATIONARY_WATER:0)
Block(4,8,-1,STATIONARY_WATER:0)
Block(4,8,0,STATIONARY_WATER:0)
Block(4,8,1,STATIONARY_WATER:0)
Block(4,8,2,STATIONARY_WATER:0)
Block(4,8,3,STATIONARY_WATER:0)
Block(4,8,4,STATIONARY_WATER:0)
Block(4,8,5,STATIONARY_WATER:0)
Block(4,8,6,STATIONARY_WATER:0)
Block(4,8,7,STATIONARY_WATER:0)
Block(4,8,8,STATIONARY_WATER:0)
Block(4,9,-7,STONE:6)
Block(4,9,-6,STONE:6)
Block(4,9,-5,STATIONARY_WATER:0)
Block(4,9,-4,STATIONARY_WATER:0)
Block(4,9,-3,STATIONARY_WATER:0)
Block(4,9,-2,STATIONARY_WATER:0)
Block(4,9,-1,STATIONARY_WATER:0)
Block(4,9,0,STATIONARY_WATER:0)
Block(4,9,1,STATIONARY_WATER:0)
Block(4,9,2,STATIONARY_WATER:0)
Block(4,9,3,STATIONARY_WATER:0)
Block(4,9,4,STATIONARY_WATER:0)
Block(4,9,5,STATIONARY_WATER:0)
Block(4,9,6,STATIONARY_WATER:0)
Block(4,9,7,STATIONARY_WATER:0)
Block(4,9,8,STATIONARY_WATER:0)
Block(4,10,-7,STONE:6)
Block(4,10,-6,STONE:6)
Block(4,10,-5,STATIONARY_WATER:0)
Block(4,10,-4,STATIONARY_WATER:0)
Block(4,10,-3,STATIONARY_WATER:0)
Block(4,10,-2,STATIONARY_WATER:0)
Block(4,10,-1,STATIONARY_WATER:0)
Block(4,10,0,STATIONARY_WATER:0)
Block(4,10,1,STATIONARY_WATER:0)
Block(4,10,2,STATIONARY_WATER:0)
Block(4,10,3,STATIONARY_WATER:0)
Block(4,10,4,STATIONARY_WATER:0)
Block(4,10,5,STATIONARY_WATER:0)
Block(4,10,6,STATIONARY_WATER:0)
Block(4,10,7,STATIONARY_WATER:0)
Block(4,10,8,STATIONARY_WATER:0)
Block(4,11,-7,STONE:6)
Block(4,11,-6,STONE:6)
Block(4,11,-5,STATIONARY_WATER:0)
Block(4,11,-4,STATIONARY_WATER:0)
Block(4,11,-3,STATIONARY_WATER:0)
Block(4,11,-2,STATIONARY_WATER:0)
Block(4,11,-1,STATIONARY_WATER:0)
Block(4,11,0,STATIONARY_WATER:0)
Block(4,11,1,STATIONARY_WATER:0)
Block(4,11,2,STATIONARY_WATER:0)
Block(4,11,3,STATIONARY_WATER:0)
Block(4,11,4,STATIONARY_WATER:0)
Block(4,11,5,STATIONARY_WATER:0)
Block(4,11,6,STATIONARY_WATER:0)
Block(4,11,7,STATIONARY_WATER:0)
Block(4,11,8,STATIONARY_WATER:0)
Block(5,0,-7,DIRT:0)
Block(5,0,-6,DIRT:0)
Block(5,0,-5,DIRT:0)
Block(5,0,-4,DIRT:0)
Block(5,0,-3,DIRT:0)
Block(5,0,-2,DIRT:0)
Block(5,0,-1,DIRT:0)
Block(5,0,0,DIRT:0)
Block(5,0,1,DIRT:0)
Block(5,0,2,DIRT:0)
Block(5,0,3,DIRT:0)
Block(5,0,4,DIRT:0)
Block(5,0,5,DIRT:0)
Block(5,0,6,DIRT:0)
Block(5,0,7,DIRT:0)
Block(5,0,8,DIRT:0)
Block(5,1,-7,STONE:6)
Block(5,1,-6,STONE:6)
Block(5,1,-5,SAND:0)
Block(5,1,-4,SAND:0)
Block(5,1,-3,SAND:0)
Block(5,1,-2,SAND:0)
Block(5,1,-1,CLAY:0)
Block(5,1,0,SAND:0)
Block(5,1,1,SAND:0)
Block(5,1,2,SAND:0)
Block(5,1,3,SAND:0)
Block(5,1,4,SAND:0)
Block(5,1,5,SAND:0)
Block(5,1,6,SAND:0)
Block(5,1,7,SAND:0)
Block(5,1,8,SAND:0)
Block(5,2,-7,STONE:6)
Block(5,2,-6,STONE:6)
Block(5,2,-5,STATIONARY_WATER:0)
Block(5,2,-4,STATIONARY_WATER:0)
Block(5,2,-3,STATIONARY_WATER:0)
Block(5,2,-2,STATIONARY_WATER:0)
Block(5,2,-1,STATIONARY_WATER:0)
Block(5,2,0,CLAY:0)
Block(5,2,1,CLAY:0)
Block(5,2,2,CLAY:0)
Block(5,2,3,CLAY:0)
Block(5,2,4,SAND:0)
Block(5,2,5,SAND:0)
Block(5,2,6,SAND:0)
Block(5,2,7,SAND:0)
Block(5,2,8,SAND:0)
Block(5,3,-7,STONE:6)
Block(5,3,-6,STONE:6)
Block(5,3,-5,STATIONARY_WATER:0)
Block(5,3,-4,STATIONARY_WATER:0)
Block(5,3,-3,STATIONARY_WATER:0)
Block(5,3,-2,STATIONARY_WATER:0)
Block(5,3,-1,STATIONARY_WATER:0)
Block(5,3,0,STATIONARY_WATER:0)
Block(5,3,1,STATIONARY_WATER:0)
Block(5,3,2,STATIONARY_WATER:0)
Block(5,3,3,STATIONARY_WATER:0)
Block(5,3,4,SAND:0)
Block(5,3,5,SAND:0)
Block(5,3,6,SAND:0)
Block(5,3,7,SAND:0)
Block(5,3,8,SAND:0)
Block(5,4,-7,STONE:6)
Block(5,4,-6,STONE:6)
Block(5,4,-5,STATIONARY_WATER:0)
Block(5,4,-4,STATIONARY_WATER:0)
Block(5,4,-3,STATIONARY_WATER:0)
Block(5,4,-2,STATIONARY_WATER:0)
Block(5,4,-1,STATIONARY_WATER:0)
Block(5,4,0,STATIONARY_WATER:0)
Block(5,4,1,STATIONARY_WATER:0)
Block(5,4,2,STATIONARY_WATER:0)
Block(5,4,3,STATIONARY_WATER:0)
Block(5,4,4,STATIONARY_WATER:0)
Block(5,4,5,STATIONARY_WATER:0)
Block(5,4,6,STATIONARY_WATER:0)
Block(5,4,7,STATIONARY_WATER:0)
Block(5,4,8,STATIONARY_WATER:0)
Block(5,5,-7,STONE:6)
Block(5,5,-6,STONE:6)
Block(5,5,-5,STATIONARY_WATER:0)
Block(5,5,-4,STATIONARY_WATER:0)
Block(5,5,-3,STATIONARY_WATER:0)
Block(5,5,-2,STATIONARY_WATER:0)
Block(5,5,-1,STATIONARY_WATER:0)
Block(5,5,0,STATIONARY_WATER:0)
Block(5,5,1,STATIONARY_WATER:0)
Block(5,5,2,STATIONARY_WATER:0)
Block(5,5,3,STATIONARY_WATER:0)
Block(5,5,4,STATIONARY_WATER:0)
Block(5,5,5,STATIONARY_WATER:0)
Block(5,5,6,STATIONARY_WATER:0)
Block(5,5,7,STATIONARY_WATER:0)
Block(5,5,8,STATIONARY_WATER:0)
Block(5,6,-7,STONE:6)
Block(5,6,-6,STONE:6)
Block(5,6,-5,STATIONARY_WATER:0)
Block(5,6,-4,STATIONARY_WATER:0)
Block(5,6,-3,STATIONARY_WATER:0)
Block(5,6,-2,STATIONARY_WATER:0)
Block(5,6,-1,STATIONARY_WATER:0)
Block(5,6,0,STATIONARY_WATER:0)
Block(5,6,1,STATIONARY_WATER:0)
Block(5,6,2,STATIONARY_WATER:0)
Block(5,6,3,STATIONARY_WATER:0)
Block(5,6,4,STATIONARY_WATER:0)
Block(5,6,5,STATIONARY_WATER:0)
Block(5,6,6,STATIONARY_WATER:0)
Block(5,6,7,STATIONARY_WATER:0)
Block(5,6,8,STATIONARY_WATER:0)
Block(5,7,-7,STONE:6)
Block(5,7,-6,STONE:6)
Block(5,7,-5,STATIONARY_WATER:0)
Block(5,7,-4,STATIONARY_WATER:0)
Block(5,7,-3,STATIONARY_WATER:0)
Block(5,7,-2,STATIONARY_WATER:0)
Block(5,7,-1,STATIONARY_WATER:0)
Block(5,7,0,STATIONARY_WATER:0)
Block(5,7,1,STATIONARY_WATER:0)
Block(5,7,2,STATIONARY_WATER:0)
Block(5,7,3,STATIONARY_WATER:0)
Block(5,7,4,STATIONARY_WATER:0)
Block(5,7,5,STATIONARY_WATER:0)
Block(5,7,6,STATIONARY_WATER:0)
Block(5,7,7,STATIONARY_WATER:0)
Block(5,7,8,STATIONARY_WATER:0)
Block(5,8,-7,STONE:6)
Block(5,8,-6,STONE:6)
Block(5,8,-5,STATIONARY_WATER:0)
Block(5,8,-4,STATIONARY_WATER:0)
Block(5,8,-3,STATIONARY_WATER:0)
Block(5,8,-2,STATIONARY_WATER:0)
Block(5,8,-1,STATIONARY_WATER:0)
Block(5,8,0,STATIONARY_WATER:0)
Block(5,8,1,STATIONARY_WATER:0)
Block(5,8,2,STATIONARY_WATER:0)
Block(5,8,3,STATIONARY_WATER:0)
Block(5,8,4,STATIONARY_WATER:0)
Block(5,8,5,STATIONARY_WATER:0)
Block(5,8,6,STATIONARY_WATER:0)
Block(5,8,7,STATIONARY_WATER:0)
Block(5,8,8,STATIONARY_WATER:0)
Block(5,9,-7,STONE:6)
Block(5,9,-6,STONE:6)
Block(5,9,-5,STATIONARY_WATER:0)
Block(5,9,-4,STATIONARY_WATER:0)
Block(5,9,-3,STATIONARY_WATER:0)
Block(5,9,-2,STATIONARY_WATER:0)
Block(5,9,-1,STATIONARY_WATER:0)
Block(5,9,0,STATIONARY_WATER:0)
Block(5,9,1,STATIONARY_WATER:0)
Block(5,9,2,STATIONARY_WATER:0)
Block(5,9,3,STATIONARY_WATER:0)
Block(5,9,4,STATIONARY_WATER:0)
Block(5,9,5,STATIONARY_WATER:0)
Block(5,9,6,STATIONARY_WATER:0)
Block(5,9,7,STATIONARY_WATER:0)
Block(5,9,8,STATIONARY_WATER:0)
Block(5,10,-7,STONE:6)
Block(5,10,-6,STONE:6)
Block(5,10,-5,STATIONARY_WATER:0)
Block(5,10,-4,STATIONARY_WATER:0)
Block(5,10,-3,STATIONARY_WATER:0)
Block(5,10,-2,STATIONARY_WATER:0)
Block(5,10,-1,STATIONARY_WATER:0)
Block(5,10,0,STATIONARY_WATER:0)
Block(5,10,1,STATIONARY_WATER:0)
Block(5,10,2,STATIONARY_WATER:0)
Block(5,10,3,STATIONARY_WATER:0)
Block(5,10,4,STATIONARY_WATER:0)
Block(5,10,5,STATIONARY_WATER:0)
Block(5,10,6,STATIONARY_WATER:0)
Block(5,10,7,STATIONARY_WATER:0)
Block(5,10,8,STATIONARY_WATER:0)
Block(5,11,-7,STONE:6)
Block(5,11,-6,STONE:6)
Block(5,11,-5,STATIONARY_WATER:0)
Block(5,11,-4,STATIONARY_WATER:0)
Block(5,11,-3,STATIONARY_WATER:0)
Block(5,11,-2,STATIONARY_WATER:0)
Block(5,11,-1,STATIONARY_WATER:0)
Block(5,11,0,STATIONARY_WATER:0)
Block(5,11,1,STATIONARY_WATER:0)
Block(5,11,2,STATIONARY_WATER:0)
Block(5,11,3,STATIONARY_WATER:0)
Block(5,11,4,STATIONARY_WATER:0)
Block(5,11,5,STATIONARY_WATER:0)
Block(5,11,6,STATIONARY_WATER:0)
Block(5,11,7,STATIONARY_WATER:0)
Block(5,11,8,STATIONARY_WATER:0)
Block(5,12,-7,STONE:6)
Block(5,13,-7,STONE:6)
Block(5,14,-7,STONE:6)
Block(5,15,-7,STONE:6)
Block(5,16,-7,STONE:6)
Block(5,17,-7,STONE:6)
Block(5,18,-7,STONE:6)
Block(5,19,-7,STONE:6)
Block(5,20,-7,STONE:6)
Block(5,21,-7,STONE:6)
Block(5,22,-7,STONE:6)
Block(5,23,-7,STONE:6)
Block(5,24,-7,STONE:6)
Block(5,25,-7,STONE:6)
Block(5,26,-7,STONE:6)
Block(5,27,-7,STONE:6)
Block(5,28,-7,STONE:6)
Block(5,29,-7,STONE:6)
Block(5,30,-7,STONE:6)
Block(5,31,-7,STONE:6)
Block(5,32,-7,STONE:6)
Block(5,33,-7,STONE:6)
Block(5,34,-7,STONE:6)
Block(5,35,-7,STONE:6)
Block(6,0,-7,DIRT:0)
Block(6,0,-6,DIRT:0)
Block(6,0,-5,DIRT:0)
Block(6,0,-4,DIRT:0)
Block(6,0,-3,DIRT:0)
Block(6,0,-2,DIRT:0)
Block(6,0,-1,DIRT:0)
Block(6,0,0,DIRT:0)
Block(6,0,1,DIRT:0)
Block(6,0,2,DIRT:0)
Block(6,0,3,DIRT:0)
Block(6,0,4,DIRT:0)
Block(6,0,5,DIRT:0)
Block(6,0,6,DIRT:0)
Block(6,0,7,DIRT:0)
Block(6,0,8,DIRT:0)
Block(6,1,-7,DIRT:0)
Block(6,1,-6,STONE:6)
Block(6,1,-5,STONE:6)
Block(6,1,-4,SAND:0)
Block(6,1,-3,SAND:0)
Block(6,1,-2,SAND:0)
Block(6,1,-1,SAND:0)
Block(6,1,0,SAND:0)
Block(6,1,1,SAND:0)
Block(6,1,2,SAND:0)
Block(6,1,3,SAND:0)
Block(6,1,4,SAND:0)
Block(6,1,5,SAND:0)
Block(6,1,6,SAND:0)
Block(6,1,7,SAND:0)
Block(6,1,8,SAND:0)
Block(6,2,-7,STONE:6)
Block(6,2,-6,STONE:6)
Block(6,2,-5,STONE:6)
Block(6,2,-4,STATIONARY_WATER:0)
Block(6,2,-3,STATIONARY_WATER:0)
Block(6,2,-2,STATIONARY_WATER:0)
Block(6,2,-1,CLAY:0)
Block(6,2,0,CLAY:0)
Block(6,2,1,CLAY:0)
Block(6,2,2,CLAY:0)
Block(6,2,3,CLAY:0)
Block(6,2,4,CLAY:0)
Block(6,2,5,SAND:0)
Block(6,2,6,SAND:0)
Block(6,2,7,SAND:0)
Block(6,2,8,SAND:0)
Block(6,3,-7,STONE:6)
Block(6,3,-6,STONE:6)
Block(6,3,-5,STONE:6)
Block(6,3,-4,STATIONARY_WATER:0)
Block(6,3,-3,STATIONARY_WATER:0)
Block(6,3,-2,STATIONARY_WATER:0)
Block(6,3,-1,STATIONARY_WATER:0)
Block(6,3,0,STATIONARY_WATER:0)
Block(6,3,1,STATIONARY_WATER:0)
Block(6,3,2,STATIONARY_WATER:0)
Block(6,3,3,STATIONARY_WATER:0)
Block(6,3,4,STATIONARY_WATER:0)
Block(6,3,5,SAND:0)
Block(6,3,6,SAND:0)
Block(6,3,7,SAND:0)
Block(6,3,8,SAND:0)
Block(6,4,-7,STONE:6)
Block(6,4,-6,STONE:6)
Block(6,4,-5,STONE:6)
Block(6,4,-4,STATIONARY_WATER:0)
Block(6,4,-3,STATIONARY_WATER:0)
Block(6,4,-2,STATIONARY_WATER:0)
Block(6,4,-1,STATIONARY_WATER:0)
Block(6,4,0,STATIONARY_WATER:0)
Block(6,4,1,STATIONARY_WATER:0)
Block(6,4,2,STATIONARY_WATER:0)
Block(6,4,3,STATIONARY_WATER:0)
Block(6,4,4,STATIONARY_WATER:0)
Block(6,4,5,STATIONARY_WATER:0)
Block(6,4,6,STATIONARY_WATER:0)
Block(6,4,7,STATIONARY_WATER:0)
Block(6,4,8,STATIONARY_WATER:0)
Block(6,5,-7,DIRT:0)
Block(6,5,-6,STONE:6)
Block(6,5,-5,STONE:6)
Block(6,5,-4,STATIONARY_WATER:0)
Block(6,5,-3,STATIONARY_WATER:0)
Block(6,5,-2,STATIONARY_WATER:0)
Block(6,5,-1,STATIONARY_WATER:0)
Block(6,5,0,STATIONARY_WATER:0)
Block(6,5,1,STATIONARY_WATER:0)
Block(6,5,2,STATIONARY_WATER:0)
Block(6,5,3,STATIONARY_WATER:0)
Block(6,5,4,STATIONARY_WATER:0)
Block(6,5,5,STATIONARY_WATER:0)
Block(6,5,6,STATIONARY_WATER:0)
Block(6,5,7,STATIONARY_WATER:0)
Block(6,5,8,STATIONARY_WATER:0)
Block(6,6,-7,STONE:6)
Block(6,6,-6,STONE:6)
Block(6,6,-5,STONE:6)
Block(6,6,-4,STATIONARY_WATER:0)
Block(6,6,-3,STATIONARY_WATER:0)
Block(6,6,-2,STATIONARY_WATER:0)
Block(6,6,-1,STATIONARY_WATER:0)
Block(6,6,0,STATIONARY_WATER:0)
Block(6,6,1,STATIONARY_WATER:0)
Block(6,6,2,STATIONARY_WATER:0)
Block(6,6,3,STATIONARY_WATER:0)
Block(6,6,4,STATIONARY_WATER:0)
Block(6,6,5,STATIONARY_WATER:0)
Block(6,6,6,STATIONARY_WATER:0)
Block(6,6,7,STATIONARY_WATER:0)
Block(6,6,8,STATIONARY_WATER:0)
Block(6,7,-7,STONE:6)
Block(6,7,-6,STONE:6)
Block(6,7,-5,STONE:6)
Block(6,7,-4,STATIONARY_WATER:0)
Block(6,7,-3,STATIONARY_WATER:0)
Block(6,7,-2,STATIONARY_WATER:0)
Block(6,7,-1,STATIONARY_WATER:0)
Block(6,7,0,STATIONARY_WATER:0)
Block(6,7,1,STATIONARY_WATER:0)
Block(6,7,2,STATIONARY_WATER:0)
Block(6,7,3,STATIONARY_WATER:0)
Block(6,7,4,STATIONARY_WATER:0)
Block(6,7,5,STATIONARY_WATER:0)
Block(6,7,6,STATIONARY_WATER:0)
Block(6,7,7,STATIONARY_WATER:0)
Block(6,7,8,STATIONARY_WATER:0)
Block(6,8,-7,STONE:6)
Block(6,8,-6,STONE:6)
Block(6,8,-5,STONE:6)
Block(6,8,-4,STATIONARY_WATER:0)
Block(6,8,-3,STATIONARY_WATER:0)
Block(6,8,-2,STATIONARY_WATER:0)
Block(6,8,-1,STATIONARY_WATER:0)
Block(6,8,0,STATIONARY_WATER:0)
Block(6,8,1,STATIONARY_WATER:0)
Block(6,8,2,STATIONARY_WATER:0)
Block(6,8,3,STATIONARY_WATER:0)
Block(6,8,4,STATIONARY_WATER:0)
Block(6,8,5,STATIONARY_WATER:0)
Block(6,8,6,STATIONARY_WATER:0)
Block(6,8,7,STATIONARY_WATER:0)
Block(6,8,8,STATIONARY_WATER:0)
Block(6,9,-7,STONE:6)
Block(6,9,-6,STONE:6)
Block(6,9,-5,STONE:6)
Block(6,9,-4,STATIONARY_WATER:0)
Block(6,9,-3,STATIONARY_WATER:0)
Block(6,9,-2,STATIONARY_WATER:0)
Block(6,9,-1,STATIONARY_WATER:0)
Block(6,9,0,STATIONARY_WATER:0)
Block(6,9,1,STATIONARY_WATER:0)
Block(6,9,2,STATIONARY_WATER:0)
Block(6,9,3,STATIONARY_WATER:0)
Block(6,9,4,STATIONARY_WATER:0)
Block(6,9,5,STATIONARY_WATER:0)
Block(6,9,6,STATIONARY_WATER:0)
Block(6,9,7,STATIONARY_WATER:0)
Block(6,9,8,STATIONARY_WATER:0)
Block(6,10,-7,STONE:6)
Block(6,10,-6,STONE:6)
Block(6,10,-5,STONE:6)
Block(6,10,-4,STATIONARY_WATER:0)
Block(6,10,-3,STATIONARY_WATER:0)
Block(6,10,-2,STATIONARY_WATER:0)
Block(6,10,-1,STATIONARY_WATER:0)
Block(6,10,0,STATIONARY_WATER:0)
Block(6,10,1,STATIONARY_WATER:0)
Block(6,10,2,STATIONARY_WATER:0)
Block(6,10,3,STATIONARY_WATER:0)
Block(6,10,4,STATIONARY_WATER:0)
Block(6,10,5,STATIONARY_WATER:0)
Block(6,10,6,STATIONARY_WATER:0)
Block(6,10,7,STATIONARY_WATER:0)
Block(6,10,8,STATIONARY_WATER:0)
Block(6,11,-7,STONE:6)
Block(6,11,-6,STONE:6)
Block(6,11,-5,STONE:6)
Block(6,11,-4,STATIONARY_WATER:0)
Block(6,11,-3,STATIONARY_WATER:0)
Block(6,11,-2,STATIONARY_WATER:0)
Block(6,11,-1,STATIONARY_WATER:0)
Block(6,11,0,STATIONARY_WATER:0)
Block(6,11,1,STATIONARY_WATER:0)
Block(6,11,2,STATIONARY_WATER:0)
Block(6,11,3,STATIONARY_WATER:0)
Block(6,11,4,STATIONARY_WATER:0)
Block(6,11,5,STATIONARY_WATER:0)
Block(6,11,6,STATIONARY_WATER:0)
Block(6,11,7,STATIONARY_WATER:0)
Block(6,11,8,STATIONARY_WATER:0)
Block(6,35,-7,STONE:6)
Block(7,0,-7,DIRT:0)
Block(7,0,-6,DIRT:0)
Block(7,0,-5,DIRT:0)
Block(7,0,-4,DIRT:0)
Block(7,0,-3,DIRT:0)
Block(7,0,-2,DIRT:0)
Block(7,0,-1,DIRT:0)
Block(7,0,0,DIRT:0)
Block(7,0,1,DIRT:0)
Block(7,0,2,DIRT:0)
Block(7,0,3,DIRT:0)
Block(7,0,4,DIRT:0)
Block(7,0,5,DIRT:0)
Block(7,0,6,DIRT:0)
Block(7,0,7,DIRT:0)
Block(7,0,8,DIRT:0)
Block(7,1,-7,DIRT:0)
Block(7,1,-6,STONE:6)
Block(7,1,-5,STONE:6)
Block(7,1,-4,SAND:0)
Block(7,1,-3,SAND:0)
Block(7,1,-2,SAND:0)
Block(7,1,-1,SAND:0)
Block(7,1,0,SAND:0)
Block(7,1,1,SAND:0)
Block(7,1,2,SAND:0)
Block(7,1,3,SAND:0)
Block(7,1,4,SAND:0)
Block(7,1,5,SAND:0)
Block(7,1,6,SAND:0)
Block(7,1,7,SAND:0)
Block(7,1,8,SAND:0)
Block(7,2,-7,STONE:6)
Block(7,2,-6,STONE:6)
Block(7,2,-5,STONE:6)
Block(7,2,-4,STATIONARY_WATER:0)
Block(7,2,-3,SAND:0)
Block(7,2,-2,SAND:0)
Block(7,2,-1,CLAY:0)
Block(7,2,0,CLAY:0)
Block(7,2,1,CLAY:0)
Block(7,2,2,CLAY:0)
Block(7,2,3,CLAY:0)
Block(7,2,4,CLAY:0)
Block(7,2,5,SAND:0)
Block(7,2,6,SAND:0)
Block(7,2,7,SAND:0)
Block(7,2,8,SAND:0)
Block(7,3,-7,STONE:6)
Block(7,3,-6,STONE:6)
Block(7,3,-5,STONE:6)
Block(7,3,-4,STATIONARY_WATER:0)
Block(7,3,-3,STATIONARY_WATER:0)
Block(7,3,-2,STATIONARY_WATER:0)
Block(7,3,-1,STATIONARY_WATER:0)
Block(7,3,0,STATIONARY_WATER:0)
Block(7,3,1,STATIONARY_WATER:0)
Block(7,3,2,STATIONARY_WATER:0)
Block(7,3,3,STATIONARY_WATER:0)
Block(7,3,4,STATIONARY_WATER:0)
Block(7,3,5,SAND:0)
Block(7,3,6,SAND:0)
Block(7,3,7,SAND:0)
Block(7,3,8,SAND:0)
Block(7,4,-7,STONE:6)
Block(7,4,-6,STONE:6)
Block(7,4,-5,STONE:6)
Block(7,4,-4,STATIONARY_WATER:0)
Block(7,4,-3,STATIONARY_WATER:0)
Block(7,4,-2,STATIONARY_WATER:0)
Block(7,4,-1,STATIONARY_WATER:0)
Block(7,4,0,STATIONARY_WATER:0)
Block(7,4,1,STATIONARY_WATER:0)
Block(7,4,2,STATIONARY_WATER:0)
Block(7,4,3,STATIONARY_WATER:0)
Block(7,4,4,STATIONARY_WATER:0)
Block(7,4,5,STATIONARY_WATER:0)
Block(7,4,6,STATIONARY_WATER:0)
Block(7,4,7,STATIONARY_WATER:0)
Block(7,4,8,STATIONARY_WATER:0)
Block(7,5,-7,DIRT:0)
Block(7,5,-6,STONE:6)
Block(7,5,-5,STONE:6)
Block(7,5,-4,STATIONARY_WATER:0)
Block(7,5,-3,STATIONARY_WATER:0)
Block(7,5,-2,STATIONARY_WATER:0)
Block(7,5,-1,STATIONARY_WATER:0)
Block(7,5,0,STATIONARY_WATER:0)
Block(7,5,1,STATIONARY_WATER:0)
Block(7,5,2,STATIONARY_WATER:0)
Block(7,5,3,STATIONARY_WATER:0)
Block(7,5,4,STATIONARY_WATER:0)
Block(7,5,5,STATIONARY_WATER:0)
Block(7,5,6,STATIONARY_WATER:0)
Block(7,5,7,STATIONARY_WATER:0)
Block(7,5,8,STATIONARY_WATER:0)
Block(7,6,-7,STONE:6)
Block(7,6,-6,STONE:6)
Block(7,6,-5,STONE:6)
Block(7,6,-4,STATIONARY_WATER:0)
Block(7,6,-3,STATIONARY_WATER:0)
Block(7,6,-2,STATIONARY_WATER:0)
Block(7,6,-1,STATIONARY_WATER:0)
Block(7,6,0,STATIONARY_WATER:0)
Block(7,6,1,STATIONARY_WATER:0)
Block(7,6,2,STATIONARY_WATER:0)
Block(7,6,3,STATIONARY_WATER:0)
Block(7,6,4,STATIONARY_WATER:0)
Block(7,6,5,STATIONARY_WATER:0)
Block(7,6,6,STATIONARY_WATER:0)
Block(7,6,7,STATIONARY_WATER:0)
Block(7,6,8,STATIONARY_WATER:0)
Block(7,7,-7,STONE:6)
Block(7,7,-6,STONE:6)
Block(7,7,-5,STONE:6)
Block(7,7,-4,STATIONARY_WATER:0)
Block(7,7,-3,STATIONARY_WATER:0)
Block(7,7,-2,STATIONARY_WATER:0)
Block(7,7,-1,STATIONARY_WATER:0)
Block(7,7,0,STATIONARY_WATER:0)
Block(7,7,1,STATIONARY_WATER:0)
Block(7,7,2,STATIONARY_WATER:0)
Block(7,7,3,STATIONARY_WATER:0)
Block(7,7,4,STATIONARY_WATER:0)
Block(7,7,5,STATIONARY_WATER:0)
Block(7,7,6,STATIONARY_WATER:0)
Block(7,7,7,STATIONARY_WATER:0)
Block(7,7,8,STATIONARY_WATER:0)
Block(7,8,-7,STONE:6)
Block(7,8,-6,STONE:6)
Block(7,8,-5,STONE:6)
Block(7,8,-4,STATIONARY_WATER:0)
Block(7,8,-3,STATIONARY_WATER:0)
Block(7,8,-2,STATIONARY_WATER:0)
Block(7,8,-1,STATIONARY_WATER:0)
Block(7,8,0,STATIONARY_WATER:0)
Block(7,8,1,STATIONARY_WATER:0)
Block(7,8,2,STATIONARY_WATER:0)
Block(7,8,3,STATIONARY_WATER:0)
Block(7,8,4,STATIONARY_WATER:0)
Block(7,8,5,STATIONARY_WATER:0)
Block(7,8,6,STATIONARY_WATER:0)
Block(7,8,7,STATIONARY_WATER:0)
Block(7,8,8,STATIONARY_WATER:0)
Block(7,9,-7,STONE:6)
Block(7,9,-6,STONE:6)
Block(7,9,-5,STONE:6)
Block(7,9,-4,STATIONARY_WATER:0)
Block(7,9,-3,STATIONARY_WATER:0)
Block(7,9,-2,STATIONARY_WATER:0)
Block(7,9,-1,STATIONARY_WATER:0)
Block(7,9,0,STATIONARY_WATER:0)
Block(7,9,1,STATIONARY_WATER:0)
Block(7,9,2,STATIONARY_WATER:0)
Block(7,9,3,STATIONARY_WATER:0)
Block(7,9,4,STATIONARY_WATER:0)
Block(7,9,5,STATIONARY_WATER:0)
Block(7,9,6,STATIONARY_WATER:0)
Block(7,9,7,STATIONARY_WATER:0)
Block(7,9,8,STATIONARY_WATER:0)
Block(7,10,-7,STONE:6)
Block(7,10,-6,STONE:6)
Block(7,10,-5,STONE:6)
Block(7,10,-4,STATIONARY_WATER:0)
Block(7,10,-3,STATIONARY_WATER:0)
Block(7,10,-2,STATIONARY_WATER:0)
Block(7,10,-1,STATIONARY_WATER:0)
Block(7,10,0,STATIONARY_WATER:0)
Block(7,10,1,STATIONARY_WATER:0)
Block(7,10,2,STATIONARY_WATER:0)
Block(7,10,3,STATIONARY_WATER:0)
Block(7,10,4,STATIONARY_WATER:0)
Block(7,10,5,STATIONARY_WATER:0)
Block(7,10,6,STATIONARY_WATER:0)
Block(7,10,7,STATIONARY_WATER:0)
Block(7,10,8,STATIONARY_WATER:0)
Block(7,11,-7,STONE:6)
Block(7,11,-6,STONE:6)
Block(7,11,-5,STONE:6)
Block(7,11,-4,STATIONARY_WATER:0)
Block(7,11,-3,STATIONARY_WATER:0)
Block(7,11,-2,STATIONARY_WATER:0)
Block(7,11,-1,STATIONARY_WATER:0)
Block(7,11,0,STATIONARY_WATER:0)
Block(7,11,1,STATIONARY_WATER:0)
Block(7,11,2,STATIONARY_WATER:0)
Block(7,11,3,STATIONARY_WATER:0)
Block(7,11,4,STATIONARY_WATER:0)
Block(7,11,5,STATIONARY_WATER:0)
Block(7,11,6,STATIONARY_WATER:0)
Block(7,11,7,STATIONARY_WATER:0)
Block(7,11,8,STATIONARY_WATER:0)
Block(7,12,-7,COBBLESTONE:0)
Block(7,12,-6,STONE:6)
Block(7,13,-7,COBBLESTONE:0)
Block(7,13,-6,STONE:6)
Block(7,14,-7,COBBLESTONE:0)
Block(7,14,-6,STONE:6)
Block(7,15,-7,COBBLESTONE:0)
Block(7,15,-6,STONE:6)
Block(7,16,-7,COBBLESTONE:0)
Block(7,16,-6,STONE:6)
Block(7,17,-7,COBBLESTONE:0)
Block(7,17,-6,STONE:6)
Block(7,18,-7,COBBLESTONE:0)
Block(7,18,-6,STONE:6)
Block(7,19,-7,COBBLESTONE:0)
Block(7,19,-6,STONE:6)
Block(7,20,-7,COBBLESTONE:0)
Block(7,20,-6,STONE:6)
Block(7,21,-7,COBBLESTONE:0)
Block(7,21,-6,STONE:6)
Block(7,22,-7,COBBLESTONE:0)
Block(7,22,-6,STONE:6)
Block(7,23,-7,COBBLESTONE:0)
Block(7,23,-6,STONE:6)
Block(7,24,-7,COBBLESTONE:0)
Block(7,24,-6,STONE:6)
Block(7,25,-7,COBBLESTONE:0)
Block(7,25,-6,STONE:6)
Block(7,26,-7,COBBLESTONE:0)
Block(7,26,-6,STONE:6)
Block(7,27,-7,COBBLESTONE:0)
Block(7,27,-6,STONE:6)
Block(7,28,-7,COBBLESTONE:0)
Block(7,28,-6,STONE:6)
Block(7,29,-7,COBBLESTONE:0)
Block(7,29,-6,STONE:6)
Block(7,30,-7,COBBLESTONE:0)
Block(7,30,-6,STONE:6)
Block(7,31,-7,COBBLESTONE:0)
Block(7,31,-6,STONE:6)
Block(7,32,-7,COBBLESTONE:0)
Block(7,32,-6,STONE:6)
Block(7,33,-7,COBBLESTONE:0)
Block(7,33,-6,STONE:6)
Block(7,34,-7,COBBLESTONE:0)
Block(7,34,-6,STONE:6)
Block(7,35,-7,COBBLESTONE:0)
Block(7,35,-6,STONE:6)
Block(7,36,-7,STEP:0)
Block(7,36,-6,STONE:6)

#######################################################################
# +-----------------------------------------------------------------+ #
# |                             Branches                            | #
# +-----------------------------------------------------------------+ #
#######################################################################

Branch(0,0,16,true,SpawnHexC14R13,NORTH,100.0,0)

#######################################################################
# +-----------------------------------------------------------------+ #
# |                             Entities                            | #
# +-----------------------------------------------------------------+ #
#######################################################################


#######################################################################
# +-----------------------------------------------------------------+ #
# |                            Particles                            | #
# +-----------------------------------------------------------------+ #
#######################################################################


#######################################################################
# +-----------------------------------------------------------------+ #
# |                             Spawners                            | #
# +-----------------------------------------------------------------+ #
#######################################################################


#######################################################################
# +-----------------------------------------------------------------+ #
# |                             ModData                             | #
# +-----------------------------------------------------------------+ #
#######################################################################

