Author: Bo3 BulkEdit

Description: Converted Schematic - Modified by Bo3BulkEdit

Version: 3

SettingsMode: WriteDisable

IsOTGPlus: false
Tree: false
Frequency: 1
Rarity: 100
RotateRandomly: false
SpawnHeight: randomY
MaxBranchDepth: 20
ExcludedBiomes: All

MinHeight: 0
MaxHeight: 256

SourceBlocks: AIR
MaxPercentageOutsideSourceBlock: 100
OutsideSourceBlock: placeAnyway

B(8,-30,-7,PLANKS:1)
B(8,-30,-6,PLANKS:1)
B(8,-30,-5,PLANKS:1)
B(8,-30,-4,PLANKS:1)
B(8,-30,-3,PLANKS:1)
B(8,-30,-2,PLANKS:1)
B(8,-30,-1,PLANKS:1)
B(8,-30,0,PLANKS:1)
B(8,-30,1,PLANKS:1)
B(8,-30,2,PLANKS:1)
B(8,-30,3,PLANKS:1)
B(8,-30,4,PLANKS:1)
B(8,-30,5,PLANKS:1)
B(8,-30,6,PLANKS:1)
B(8,-30,7,PLANKS:1)
B(8,-30,8,PLANKS:1)
B(6,-29,-7,PLANKS:1)
B(7,-29,-7,PLANKS:1)
B(8,-29,-7,PLANKS:1)
B(5,-29,-6,PLANKS:1)
B(6,-29,-6,PLANKS:1)
B(7,-29,-6,PLANKS:1)
B(8,-29,-6,PLANKS:1)
B(5,-29,-5,PLANKS:1)
B(6,-29,-5,PLANKS:1)
B(7,-29,-5,PLANKS:1)
B(8,-29,-5,PLANKS:1)
B(5,-29,-4,PLANKS:1)
B(6,-29,-4,PLANKS:1)
B(7,-29,-4,PLANKS:1)
B(8,-29,-4,PLANKS:1)
B(6,-29,-3,PLANKS:1)
B(7,-29,-3,PLANKS:1)
B(8,-29,-3,PLANKS:1)
B(6,-29,-2,PLANKS:1)
B(7,-29,-2,PLANKS:1)
B(8,-29,-2,PLANKS:1)
B(6,-29,-1,PLANKS:1)
B(7,-29,-1,PLANKS:1)
B(8,-29,-1,PLANKS:1)
B(6,-29,0,PLANKS:1)
B(7,-29,0,PLANKS:1)
B(8,-29,0,PLANKS:1)
B(7,-29,1,PLANKS:1)
B(8,-29,1,PLANKS:1)
B(7,-29,2,PLANKS:1)
B(8,-29,2,PLANKS:1)
B(7,-29,3,PLANKS:1)
B(8,-29,3,PLANKS:1)
B(7,-29,4,PLANKS:1)
B(8,-29,4,PLANKS:1)
B(7,-29,5,PLANKS:1)
B(8,-29,5,PLANKS:1)
B(7,-29,6,PLANKS:1)
B(8,-29,6,PLANKS:1)
B(8,-29,7,PLANKS:1)
B(8,-29,8,PLANKS:1)
B(4,-28,-7,PLANKS:1)
B(5,-28,-7,PLANKS:1)
B(6,-28,-7,IRON_ORE:0)
B(7,-28,-7,CLAY:0)
B(8,-28,-7,AIR:0)
B(4,-28,-6,PLANKS:1)
B(5,-28,-6,EMERALD_ORE:0)
B(6,-28,-6,CLAY:0)
B(7,-28,-6,AIR:0)
B(8,-28,-6,AIR:0)
B(4,-28,-5,PLANKS:1)
B(5,-28,-5,COAL_ORE:0)
B(6,-28,-5,CLAY:0)
B(7,-28,-5,AIR:0)
B(8,-28,-5,AIR:0)
B(4,-28,-4,PLANKS:1)
B(5,-28,-4,AIR:0)
B(6,-28,-4,AIR:0)
B(7,-28,-4,AIR:0)
B(8,-28,-4,AIR:0)
B(4,-28,-3,PLANKS:1)
B(5,-28,-3,PLANKS:1)
B(6,-28,-3,CLAY:0)
B(7,-28,-3,AIR:0)
B(8,-28,-3,AIR:0)
B(4,-28,-2,PLANKS:1)
B(5,-28,-2,PLANKS:1)
B(6,-28,-2,CLAY:0)
B(7,-28,-2,AIR:0)
B(8,-28,-2,AIR:0)
B(4,-28,-1,PLANKS:1)
B(5,-28,-1,PLANKS:1)
B(6,-28,-1,COAL_ORE:0)
B(7,-28,-1,CLAY:0)
B(8,-28,-1,AIR:0)
B(4,-28,0,PLANKS:1)
B(5,-28,0,PLANKS:1)
B(6,-28,0,IRON_ORE:0)
B(7,-28,0,CLAY:0)
B(8,-28,0,AIR:0)
B(4,-28,1,PLANKS:1)
B(5,-28,1,PLANKS:1)
B(6,-28,1,PLANKS:1)
B(7,-28,1,CLAY:0)
B(8,-28,1,AIR:0)
B(4,-28,2,PLANKS:1)
B(5,-28,2,PLANKS:1)
B(6,-28,2,PLANKS:1)
B(7,-28,2,CLAY:0)
B(8,-28,2,AIR:0)
B(4,-28,3,PLANKS:1)
B(5,-28,3,PLANKS:1)
B(6,-28,3,PLANKS:1)
B(7,-28,3,CLAY:0)
B(8,-28,3,AIR:0)
B(4,-28,4,PLANKS:1)
B(5,-28,4,PLANKS:1)
B(6,-28,4,PLANKS:1)
B(7,-28,4,AIR:0)
B(8,-28,4,AIR:0)
B(4,-28,5,PLANKS:1)
B(5,-28,5,PLANKS:1)
B(6,-28,5,PLANKS:1)
B(7,-28,5,AIR:0)
B(8,-28,5,SPRUCE_FENCE:0)
B(4,-28,6,PLANKS:1)
B(5,-28,6,PLANKS:1)
B(6,-28,6,PLANKS:1)
B(7,-28,6,WOODEN_SLAB:0)
B(8,-28,6,LOG:1)
B(5,-28,7,PLANKS:1)
B(6,-28,7,PLANKS:1)
B(7,-28,7,PLANKS:1)
B(8,-28,7,PLANKS:1)
B(5,-28,8,PLANKS:1)
B(6,-28,8,PLANKS:1)
B(7,-28,8,PLANKS:1)
B(8,-28,8,PLANKS:1)
B(3,-27,-7,PLANKS:1)
B(4,-27,-7,LAPIS_ORE:0)
B(5,-27,-7,IRON_ORE:0)
B(6,-27,-7,CLAY:0)
B(7,-27,-7,AIR:0)
B(8,-27,-7,AIR:0)
B(3,-27,-6,PLANKS:1)
B(4,-27,-6,LAPIS_ORE:0)
B(5,-27,-6,COAL_ORE:0)
B(6,-27,-6,CLAY:0)
B(7,-27,-6,AIR:0)
B(8,-27,-6,AIR:0)
B(3,-27,-5,PLANKS:1)
B(4,-27,-5,COAL_ORE:0)
B(5,-27,-5,CLAY:0)
B(6,-27,-5,AIR:0)
B(7,-27,-5,AIR:0)
B(8,-27,-5,AIR:0)
B(3,-27,-4,PLANKS:1)
B(4,-27,-4,CLAY:0)
B(5,-27,-4,AIR:0)
B(6,-27,-4,AIR:0)
B(7,-27,-4,AIR:0)
B(8,-27,-4,AIR:0)
B(3,-27,-3,PLANKS:1)
B(4,-27,-3,IRON_ORE:0)
B(5,-27,-3,CLAY:0)
B(6,-27,-3,AIR:0)
B(7,-27,-3,AIR:0)
B(8,-27,-3,AIR:0)
B(3,-27,-2,PLANKS:1)
B(4,-27,-2,COAL_ORE:0)
B(5,-27,-2,COAL_ORE:0)
B(6,-27,-2,CLAY:0)
B(7,-27,-2,AIR:0)
B(8,-27,-2,AIR:0)
B(3,-27,-1,PLANKS:1)
B(4,-27,-1,IRON_ORE:0)
B(5,-27,-1,COAL_ORE:0)
B(6,-27,-1,CLAY:0)
B(7,-27,-1,AIR:0)
B(8,-27,-1,AIR:0)
B(3,-27,0,PLANKS:1)
B(4,-27,0,IRON_ORE:0)
B(5,-27,0,AIR:0)
B(6,-27,0,AIR:0)
B(7,-27,0,AIR:0)
B(8,-27,0,AIR:0)
B(3,-27,1,PLANKS:1)
B(4,-27,1,AIR:0)
B(5,-27,1,AIR:0)
B(6,-27,1,AIR:0)
B(7,-27,1,AIR:0)
B(8,-27,1,AIR:0)
B(3,-27,2,PLANKS:1)
B(4,-27,2,CLAY:0)
B(5,-27,2,CLAY:0)
RB(6,-27,2,CHEST:5,../NBT/StructureLoot/ShipJunk_1.nbt,15,CHEST:5,../NBT/StructureLoot/ShipJunk_2.nbt,15,CHEST:5,../NBT/StructureLoot/ShipJunk_3.nbt,15,CHEST:5,../NBT/StructureLoot/ShipJunk_4.nbt,15,CHEST:5,../NBT/StructureLoot/ShipJunk_5.nbt,15,CHEST:5,../NBT/StructureLoot/Common1.nbt,15,CHEST:5,../NBT/StructureLoot/Common2.nbt,15,CHEST:5,../NBT/StructureLoot/Common3.nbt,15,CHEST:5,../NBT/StructureLoot/Common4.nbt,15,CHEST:5,../NBT/StructureLoot/Common5.nbt,15,CHEST:5,../NBT/StructureLoot/Common6.nbt,15,CHEST:5,../NBT/StructureLoot/Common7.nbt,15,CHEST:5,../NBT/StructureLoot/Common8.nbt,15,CHEST:5,../NBT/StructureLoot/Common9.nbt,15,CHEST:5,../NBT/StructureLoot/Common10.nbt,15,CHEST:5,../NBT/StructureLoot/Common11.nbt,15,CHEST:5,../NBT/StructureLoot/Common12.nbt,15,CHEST:5,../NBT/StructureLoot/Common13.nbt,15,CHEST:5,../NBT/StructureLoot/Common14.nbt,15,CHEST:5,../NBT/StructureLoot/Common15.nbt,100)
B(7,-27,2,AIR:0)
B(8,-27,2,AIR:0)
B(3,-27,3,PLANKS:1)
B(4,-27,3,COAL_ORE:0)
B(5,-27,3,COAL_ORE:0)
B(6,-27,3,CLAY:0)
B(7,-27,3,AIR:0)
B(8,-27,3,AIR:0)
B(3,-27,4,PLANKS:1)
B(4,-27,4,LAPIS_ORE:0)
B(5,-27,4,IRON_ORE:0)
B(6,-27,4,CLAY:0)
B(7,-27,4,AIR:0)
B(8,-27,4,AIR:0)
B(4,-27,5,PLANKS:1)
B(5,-27,5,LAPIS_ORE:0)
B(6,-27,5,COAL_ORE:0)
B(7,-27,5,AIR:0)
B(8,-27,5,TORCH:5)
B(4,-27,6,PLANKS:1)
B(5,-27,6,PLANKS:1)
B(6,-27,6,PLANKS:1)
B(7,-27,6,AIR:0)
B(8,-27,6,LOG:1)
B(4,-27,7,PLANKS:1)
B(5,-27,7,CAULDRON:3)
B(6,-27,7,CAULDRON:3)
B(7,-27,7,SPRUCE_DOOR:1)
B(8,-27,7,LADDER:3)
B(4,-27,8,PLANKS:1)
B(5,-27,8,CAULDRON:3)
B(6,-27,8,CAULDRON:3)
B(7,-27,8,AIR:0)
B(8,-27,8,AIR:0)
B(3,-26,-7,PLANKS:1)
B(4,-26,-7,CLAY:0)
B(5,-26,-7,CLAY:0)
B(6,-26,-7,AIR:0)
B(7,-26,-7,AIR:0)
B(8,-26,-7,AIR:0)
B(3,-26,-6,PLANKS:1)
B(4,-26,-6,CLAY:0)
B(5,-26,-6,CLAY:0)
B(6,-26,-6,AIR:0)
B(7,-26,-6,AIR:0)
B(8,-26,-6,AIR:0)
B(3,-26,-5,PLANKS:1)
B(4,-26,-5,CLAY:0)
B(5,-26,-5,REDSTONE_ORE:0)
B(6,-26,-5,AIR:0)
B(7,-26,-5,AIR:0)
B(8,-26,-5,AIR:0)
B(3,-26,-4,PLANKS:1)
B(4,-26,-4,AIR:0)
B(5,-26,-4,AIR:0)
B(6,-26,-4,AIR:0)
B(7,-26,-4,AIR:0)
B(8,-26,-4,AIR:0)
B(3,-26,-3,PLANKS:1)
B(4,-26,-3,CLAY:0)
B(5,-26,-3,AIR:0)
B(6,-26,-3,AIR:0)
B(7,-26,-3,AIR:0)
B(8,-26,-3,AIR:0)
B(3,-26,-2,PLANKS:1)
B(4,-26,-2,CLAY:0)
RB(5,-26,-2,CHEST:5,../NBT/StructureLoot/ShipJunk_1.nbt,15,CHEST:5,../NBT/StructureLoot/ShipJunk_2.nbt,15,CHEST:5,../NBT/StructureLoot/ShipJunk_3.nbt,15,CHEST:5,../NBT/StructureLoot/ShipJunk_4.nbt,15,CHEST:5,../NBT/StructureLoot/ShipJunk_5.nbt,15,CHEST:5,../NBT/StructureLoot/Common1.nbt,15,CHEST:5,../NBT/StructureLoot/Common2.nbt,15,CHEST:5,../NBT/StructureLoot/Common3.nbt,15,CHEST:5,../NBT/StructureLoot/Common4.nbt,15,CHEST:5,../NBT/StructureLoot/Common5.nbt,15,CHEST:5,../NBT/StructureLoot/Common6.nbt,15,CHEST:5,../NBT/StructureLoot/Common7.nbt,15,CHEST:5,../NBT/StructureLoot/Common8.nbt,15,CHEST:5,../NBT/StructureLoot/Common9.nbt,15,CHEST:5,../NBT/StructureLoot/Common10.nbt,15,CHEST:5,../NBT/StructureLoot/Common11.nbt,15,CHEST:5,../NBT/StructureLoot/Common12.nbt,15,CHEST:5,../NBT/StructureLoot/Common13.nbt,15,CHEST:5,../NBT/StructureLoot/Common14.nbt,15,CHEST:5,../NBT/StructureLoot/Common15.nbt,100)
B(6,-26,-2,AIR:0)
B(7,-26,-2,AIR:0)
B(8,-26,-2,AIR:0)
B(3,-26,-1,PLANKS:1)
B(4,-26,-1,CLAY:0)
RB(5,-26,-1,CHEST:5,../NBT/StructureLoot/ShipJunk_1.nbt,15,CHEST:5,../NBT/StructureLoot/ShipJunk_2.nbt,15,CHEST:5,../NBT/StructureLoot/ShipJunk_3.nbt,15,CHEST:5,../NBT/StructureLoot/ShipJunk_4.nbt,15,CHEST:5,../NBT/StructureLoot/ShipJunk_5.nbt,15,CHEST:5,../NBT/StructureLoot/Common1.nbt,15,CHEST:5,../NBT/StructureLoot/Common2.nbt,15,CHEST:5,../NBT/StructureLoot/Common3.nbt,15,CHEST:5,../NBT/StructureLoot/Common4.nbt,15,CHEST:5,../NBT/StructureLoot/Common5.nbt,15,CHEST:5,../NBT/StructureLoot/Common6.nbt,15,CHEST:5,../NBT/StructureLoot/Common7.nbt,15,CHEST:5,../NBT/StructureLoot/Common8.nbt,15,CHEST:5,../NBT/StructureLoot/Common9.nbt,15,CHEST:5,../NBT/StructureLoot/Common10.nbt,15,CHEST:5,../NBT/StructureLoot/Common11.nbt,15,CHEST:5,../NBT/StructureLoot/Common12.nbt,15,CHEST:5,../NBT/StructureLoot/Common13.nbt,15,CHEST:5,../NBT/StructureLoot/Common14.nbt,15,CHEST:5,../NBT/StructureLoot/Common15.nbt,100)
B(6,-26,-1,AIR:0)
B(7,-26,-1,AIR:0)
B(8,-26,-1,AIR:0)
B(3,-26,0,PLANKS:1)
B(4,-26,0,AIR:0)
B(5,-26,0,AIR:0)
B(6,-26,0,AIR:0)
B(7,-26,0,AIR:0)
B(8,-26,0,AIR:0)
B(3,-26,1,PLANKS:1)
B(4,-26,1,AIR:0)
B(5,-26,1,AIR:0)
B(6,-26,1,AIR:0)
B(7,-26,1,AIR:0)
B(8,-26,1,AIR:0)
B(3,-26,2,PLANKS:1)
B(4,-26,2,REDSTONE_ORE:0)
B(5,-26,2,AIR:0)
B(6,-26,2,AIR:0)
B(7,-26,2,AIR:0)
B(8,-26,2,AIR:0)
B(3,-26,3,PLANKS:1)
B(4,-26,3,CLAY:0)
B(5,-26,3,CLAY:0)
B(6,-26,3,AIR:0)
B(7,-26,3,AIR:0)
B(8,-26,3,AIR:0)
B(3,-26,4,PLANKS:1)
B(4,-26,4,CLAY:0)
B(5,-26,4,CLAY:0)
B(6,-26,4,AIR:0)
B(7,-26,4,AIR:0)
B(8,-26,4,AIR:0)
B(3,-26,5,PLANKS:1)
B(4,-26,5,IRON_ORE:0)
B(5,-26,5,CLAY:0)
B(6,-26,5,CLAY:0)
B(7,-26,5,AIR:0)
B(8,-26,5,AIR:0)
B(3,-26,6,PLANKS:1)
B(4,-26,6,PLANKS:1)
B(5,-26,6,PLANKS:1)
B(6,-26,6,PLANKS:1)
B(7,-26,6,AIR:0)
B(8,-26,6,LOG:1)
B(3,-26,7,PLANKS:1)
B(4,-26,7,CAULDRON:3)
B(5,-26,7,CAULDRON:3)
B(6,-26,7,AIR:0)
B(7,-26,7,SPRUCE_DOOR:9)
B(8,-26,7,LADDER:3)
B(3,-26,8,PLANKS:1)
B(4,-26,8,CAULDRON:3)
B(5,-26,8,CAULDRON:0)
B(6,-26,8,AIR:0)
B(7,-26,8,AIR:0)
B(8,-26,8,AIR:0)
B(3,-25,-7,PLANKS:5)
B(4,-25,-7,WOODEN_SLAB:8)
B(5,-25,-7,WOODEN_SLAB:8)
B(6,-25,-7,WOODEN_SLAB:8)
B(7,-25,-7,WOODEN_SLAB:8)
B(8,-25,-7,WOODEN_SLAB:8)
B(3,-25,-6,PLANKS:5)
B(4,-25,-6,WOODEN_SLAB:8)
B(5,-25,-6,WOODEN_SLAB:8)
B(6,-25,-6,WOODEN_SLAB:8)
B(7,-25,-6,WOODEN_SLAB:8)
B(8,-25,-6,WOODEN_SLAB:8)
B(3,-25,-5,PLANKS:5)
B(4,-25,-5,WOODEN_SLAB:8)
B(5,-25,-5,WOODEN_SLAB:8)
B(6,-25,-5,WOODEN_SLAB:8)
B(3,-25,-4,PLANKS:5)
B(4,-25,-4,WOODEN_SLAB:8)
B(5,-25,-4,WOODEN_SLAB:8)
B(6,-25,-4,WOODEN_SLAB:8)
B(2,-25,-3,LADDER:4)
B(3,-25,-3,PLANKS:5)
B(4,-25,-3,WOODEN_SLAB:8)
B(5,-25,-3,WOODEN_SLAB:8)
B(6,-25,-3,WOODEN_SLAB:8)
B(3,-25,-2,PLANKS:5)
B(4,-25,-2,WOODEN_SLAB:8)
B(5,-25,-2,WOODEN_SLAB:8)
B(6,-25,-2,WOODEN_SLAB:8)
B(2,-25,-1,LADDER:4)
B(3,-25,-1,PLANKS:5)
B(4,-25,-1,WOODEN_SLAB:8)
B(5,-25,-1,WOODEN_SLAB:8)
B(6,-25,-1,WOODEN_SLAB:8)
B(3,-25,0,PLANKS:5)
B(4,-25,0,WOODEN_SLAB:8)
B(5,-25,0,WOODEN_SLAB:8)
B(6,-25,0,WOODEN_SLAB:8)
B(3,-25,1,PLANKS:5)
B(4,-25,1,WOODEN_SLAB:8)
B(5,-25,1,WOODEN_SLAB:8)
B(6,-25,1,WOODEN_SLAB:8)
B(7,-25,1,WOODEN_SLAB:8)
B(8,-25,1,WOODEN_SLAB:8)
B(3,-25,2,PLANKS:5)
B(4,-25,2,WOODEN_SLAB:8)
B(5,-25,2,WOODEN_SLAB:8)
B(6,-25,2,WOODEN_SLAB:8)
B(7,-25,2,WOODEN_SLAB:8)
B(8,-25,2,WOODEN_SLAB:8)
B(3,-25,3,PLANKS:5)
B(4,-25,3,WOODEN_SLAB:8)
B(5,-25,3,WOODEN_SLAB:8)
B(6,-25,3,WOODEN_SLAB:8)
B(7,-25,3,WOODEN_SLAB:8)
B(8,-25,3,WOODEN_SLAB:8)
B(3,-25,4,PLANKS:5)
B(4,-25,4,WOODEN_SLAB:8)
B(5,-25,4,WOODEN_SLAB:8)
B(6,-25,4,WOODEN_SLAB:8)
B(7,-25,4,WOODEN_SLAB:8)
B(8,-25,4,WOODEN_SLAB:8)
B(3,-25,5,PLANKS:5)
B(4,-25,5,WOODEN_SLAB:8)
B(5,-25,5,WOODEN_SLAB:8)
B(6,-25,5,WOODEN_SLAB:8)
B(7,-25,5,WOODEN_SLAB:8)
B(8,-25,5,WOODEN_SLAB:8)
B(3,-25,6,PLANKS:5)
B(4,-25,6,DOUBLE_WOODEN_SLAB:0)
B(5,-25,6,DOUBLE_WOODEN_SLAB:0)
B(6,-25,6,DOUBLE_WOODEN_SLAB:0)
B(7,-25,6,DOUBLE_WOODEN_SLAB:0)
B(8,-25,6,LOG:1)
B(3,-25,7,PLANKS:5)
B(4,-25,7,WOODEN_SLAB:8)
B(5,-25,7,WOODEN_SLAB:8)
B(6,-25,7,WOODEN_SLAB:8)
B(7,-25,7,WOODEN_SLAB:8)
B(8,-25,7,LADDER:3)
B(3,-25,8,PLANKS:5)
B(4,-25,8,WOODEN_SLAB:8)
B(5,-25,8,WOODEN_SLAB:8)
B(6,-25,8,WOODEN_SLAB:8)
B(7,-25,8,WOODEN_SLAB:8)
B(8,-25,8,WOODEN_SLAB:8)
B(3,-24,-7,PLANKS:5)
B(4,-24,-7,WOODEN_BUTTON:3)
B(7,-24,-7,BED:0)
RB(8,-24,-7,CHEST:2,../NBT/StructureLoot/ShipJunk_1.nbt,15,CHEST:2,../NBT/StructureLoot/ShipJunk_2.nbt,15,CHEST:2,../NBT/StructureLoot/ShipJunk_3.nbt,15,CHEST:2,../NBT/StructureLoot/ShipJunk_4.nbt,15,CHEST:2,../NBT/StructureLoot/ShipJunk_5.nbt,15,CHEST:2,../NBT/StructureLoot/Common1.nbt,15,CHEST:2,../NBT/StructureLoot/Common2.nbt,15,CHEST:2,../NBT/StructureLoot/Common3.nbt,15,CHEST:2,../NBT/StructureLoot/Common4.nbt,15,CHEST:2,../NBT/StructureLoot/Common5.nbt,15,CHEST:2,../NBT/StructureLoot/Common6.nbt,15,CHEST:2,../NBT/StructureLoot/Common7.nbt,15,CHEST:2,../NBT/StructureLoot/Common8.nbt,15,CHEST:2,../NBT/StructureLoot/Common9.nbt,15,CHEST:2,../NBT/StructureLoot/Common10.nbt,15,CHEST:2,../NBT/StructureLoot/Common11.nbt,15,CHEST:2,../NBT/StructureLoot/Common12.nbt,15,CHEST:2,../NBT/StructureLoot/Common13.nbt,15,CHEST:2,../NBT/StructureLoot/Common14.nbt,15,CHEST:2,../NBT/StructureLoot/Common15.nbt,100)
B(3,-24,-6,PLANKS:5)
B(4,-24,-6,WOODEN_BUTTON:4)
B(7,-24,-6,BED:8)
B(8,-24,-6,SPRUCE_FENCE:0)
B(2,-24,-5,DISPENSER:4)
B(3,-24,-5,COAL_BLOCK:0)
B(4,-24,-5,DISPENSER:1)
B(5,-24,-5,SPRUCE_STAIRS:1)
B(7,-24,-5,TRAPDOOR:2)
B(8,-24,-5,WOODEN_SLAB:1)
B(3,-24,-4,PLANKS:5)
B(4,-24,-4,WOODEN_BUTTON:3)
B(7,-24,-4,TRAPDOOR:2)
B(8,-24,-4,WOODEN_SLAB:1)
B(2,-24,-3,LADDER:4)
B(3,-24,-3,PLANKS:5)
B(4,-24,-3,WOODEN_BUTTON:4)
B(7,-24,-3,TRAPDOOR:2)
B(8,-24,-3,WOODEN_SLAB:1)
B(2,-24,-2,DISPENSER:4)
B(3,-24,-2,COAL_BLOCK:0)
B(4,-24,-2,DISPENSER:1)
B(5,-24,-2,SPRUCE_STAIRS:1)
B(7,-24,-2,TRAPDOOR:2)
B(8,-24,-2,WOODEN_SLAB:1)
B(2,-24,-1,LADDER:4)
B(3,-24,-1,PLANKS:5)
B(4,-24,-1,WOODEN_BUTTON:3)
B(7,-24,-1,TRAPDOOR:2)
B(8,-24,-1,WOODEN_SLAB:1)
B(3,-24,0,PLANKS:5)
B(4,-24,0,WOODEN_BUTTON:4)
B(7,-24,0,TRAPDOOR:2)
B(8,-24,0,WOODEN_SLAB:1)
B(2,-24,1,DISPENSER:4)
B(3,-24,1,COAL_BLOCK:0)
B(4,-24,1,DISPENSER:1)
B(5,-24,1,SPRUCE_STAIRS:1)
B(7,-24,1,BED:10)
B(3,-24,2,PLANKS:5)
B(4,-24,2,WOODEN_BUTTON:3)
B(7,-24,2,BED:2)
B(3,-24,3,PLANKS:5)
B(4,-24,3,WOODEN_BUTTON:4)
B(7,-24,3,BED:0)
B(2,-24,4,DISPENSER:4)
B(3,-24,4,COAL_BLOCK:0)
B(4,-24,4,DISPENSER:1)
B(5,-24,4,SPRUCE_STAIRS:1)
B(7,-24,4,BED:8)
RB(8,-24,4,CHEST:2,../NBT/StructureLoot/ShipJunk_1.nbt,15,CHEST:2,../NBT/StructureLoot/ShipJunk_2.nbt,15,CHEST:2,../NBT/StructureLoot/ShipJunk_3.nbt,15,CHEST:2,../NBT/StructureLoot/ShipJunk_4.nbt,15,CHEST:2,../NBT/StructureLoot/ShipJunk_5.nbt,15,CHEST:2,../NBT/StructureLoot/Common1.nbt,15,CHEST:2,../NBT/StructureLoot/Common2.nbt,15,CHEST:2,../NBT/StructureLoot/Common3.nbt,15,CHEST:2,../NBT/StructureLoot/Common4.nbt,15,CHEST:2,../NBT/StructureLoot/Common5.nbt,15,CHEST:2,../NBT/StructureLoot/Common6.nbt,15,CHEST:2,../NBT/StructureLoot/Common7.nbt,15,CHEST:2,../NBT/StructureLoot/Common8.nbt,15,CHEST:2,../NBT/StructureLoot/Common9.nbt,15,CHEST:2,../NBT/StructureLoot/Common10.nbt,15,CHEST:2,../NBT/StructureLoot/Common11.nbt,15,CHEST:2,../NBT/StructureLoot/Common12.nbt,15,CHEST:2,../NBT/StructureLoot/Common13.nbt,15,CHEST:2,../NBT/StructureLoot/Common14.nbt,15,CHEST:2,../NBT/StructureLoot/Common15.nbt,100)
B(3,-24,5,PLANKS:5)
B(4,-24,5,WOODEN_BUTTON:3)
B(7,-24,5,WOODEN_SLAB:5)
B(8,-24,5,DOUBLE_WOODEN_SLAB:0)
B(3,-24,6,PLANKS:5)
B(4,-24,6,WOODEN_BUTTON:4)
B(7,-24,6,WOODEN_SLAB:5)
B(8,-24,6,LOG:1)
B(2,-24,7,DISPENSER:4)
B(3,-24,7,COAL_BLOCK:0)
B(4,-24,7,DISPENSER:1)
B(5,-24,7,SPRUCE_STAIRS:1)
B(7,-24,7,WOODEN_SLAB:5)
B(8,-24,7,TRAPDOOR:1)
B(3,-24,8,PLANKS:5)
B(4,-24,8,WOODEN_BUTTON:3)
B(7,-24,8,WOODEN_SLAB:5)
B(8,-24,8,WOODEN_SLAB:5)
B(3,-23,-7,PLANKS:0)
B(3,-23,-6,PLANKS:0)
B(8,-23,-6,TORCH:5)
B(2,-23,-5,WOODEN_SLAB:8)
B(4,-23,-5,LEVER:6)
B(3,-23,-4,PLANKS:0)
B(2,-23,-3,LADDER:4)
B(3,-23,-3,PLANKS:0)
B(2,-23,-2,WOODEN_SLAB:8)
B(4,-23,-2,LEVER:6)
B(6,-23,-2,AIR)
B(2,-23,-1,LADDER:4)
B(3,-23,-1,PLANKS:0)
B(3,-23,0,PLANKS:0)
B(2,-23,1,WOODEN_SLAB:8)
B(4,-23,1,LEVER:6)
B(3,-23,2,PLANKS:0)
B(3,-23,3,PLANKS:0)
B(2,-23,4,WOODEN_SLAB:8)
B(4,-23,4,LEVER:6)
B(3,-23,5,PLANKS:0)
B(6,-23,5,AIR)
B(8,-23,5,TORCH:5)
B(3,-23,6,PLANKS:0)
B(8,-23,6,LOG:1)
B(2,-23,7,WOODEN_SLAB:8)
B(4,-23,7,LEVER:6)
B(8,-23,7,LADDER:3)
B(3,-23,8,PLANKS:0)
B(2,-22,-7,WOODEN_SLAB:13)
B(3,-22,-7,PLANKS:5)
B(4,-22,-7,WOODEN_SLAB:8)
B(5,-22,-7,WOODEN_SLAB:8)
B(6,-22,-7,WOODEN_SLAB:8)
B(7,-22,-7,WOODEN_SLAB:8)
B(8,-22,-7,WOODEN_SLAB:8)
B(3,-22,-6,PLANKS:5)
B(4,-22,-6,WOODEN_SLAB:8)
B(5,-22,-6,WOODEN_SLAB:8)
B(6,-22,-6,WOODEN_SLAB:8)
B(7,-22,-6,WOODEN_SLAB:8)
B(8,-22,-6,WOODEN_SLAB:8)
B(3,-22,-5,PLANKS:5)
B(4,-22,-5,WOODEN_SLAB:8)
B(5,-22,-5,WOODEN_SLAB:8)
B(6,-22,-5,WOODEN_SLAB:8)
B(7,-22,-5,WOODEN_SLAB:8)
B(8,-22,-5,WOODEN_SLAB:8)
B(3,-22,-4,PLANKS:5)
B(4,-22,-4,WOODEN_SLAB:8)
B(5,-22,-4,WOODEN_SLAB:8)
B(6,-22,-4,WOODEN_SLAB:8)
B(8,-22,-4,WOODEN_SLAB:9)
B(2,-22,-3,LADDER:4)
B(3,-22,-3,PLANKS:5)
B(4,-22,-3,WOODEN_SLAB:8)
B(5,-22,-3,WOODEN_SLAB:8)
B(6,-22,-3,WOODEN_SLAB:8)
B(8,-22,-3,WOODEN_SLAB:9)
B(3,-22,-2,PLANKS:5)
B(4,-22,-2,WOODEN_SLAB:8)
B(5,-22,-2,WOODEN_SLAB:8)
B(6,-22,-2,WOODEN_SLAB:8)
B(8,-22,-2,WOODEN_SLAB:9)
B(2,-22,-1,LADDER:4)
B(3,-22,-1,PLANKS:5)
B(4,-22,-1,WOODEN_SLAB:8)
B(5,-22,-1,WOODEN_SLAB:8)
B(6,-22,-1,WOODEN_SLAB:8)
B(8,-22,-1,WOODEN_SLAB:9)
B(3,-22,0,PLANKS:5)
B(4,-22,0,WOODEN_SLAB:8)
B(5,-22,0,WOODEN_SLAB:8)
B(6,-22,0,WOODEN_SLAB:8)
B(8,-22,0,WOODEN_SLAB:9)
B(3,-22,1,PLANKS:5)
B(4,-22,1,WOODEN_SLAB:8)
B(5,-22,1,WOODEN_SLAB:8)
B(6,-22,1,WOODEN_SLAB:8)
B(7,-22,1,WOODEN_SLAB:8)
B(8,-22,1,WOODEN_SLAB:8)
B(3,-22,2,DARK_OAK_STAIRS:3)
B(4,-22,2,WOODEN_SLAB:8)
B(5,-22,2,WOODEN_SLAB:8)
B(6,-22,2,WOODEN_SLAB:8)
B(7,-22,2,WOODEN_SLAB:8)
B(8,-22,2,WOODEN_SLAB:8)
B(3,-22,3,WOODEN_SLAB:5)
B(4,-22,3,WOODEN_SLAB:8)
B(5,-22,3,WOODEN_SLAB:8)
B(6,-22,3,WOODEN_SLAB:8)
B(7,-22,3,WOODEN_SLAB:8)
B(8,-22,3,WOODEN_SLAB:8)
B(3,-22,4,DARK_OAK_STAIRS:2)
B(4,-22,4,WOODEN_SLAB:8)
B(5,-22,4,WOODEN_SLAB:8)
B(6,-22,4,WOODEN_SLAB:8)
B(7,-22,4,WOODEN_SLAB:8)
B(8,-22,4,WOODEN_SLAB:8)
B(2,-22,5,WOODEN_SLAB:13)
B(3,-22,5,PLANKS:5)
B(4,-22,5,WOODEN_SLAB:8)
B(5,-22,5,WOODEN_SLAB:8)
B(6,-22,5,WOODEN_SLAB:8)
B(7,-22,5,WOODEN_SLAB:8)
B(8,-22,5,WOODEN_SLAB:8)
B(2,-22,6,WOODEN_SLAB:13)
B(3,-22,6,PLANKS:5)
B(4,-22,6,WOODEN_SLAB:8)
B(5,-22,6,WOODEN_SLAB:8)
B(6,-22,6,WOODEN_SLAB:8)
B(7,-22,6,WOODEN_SLAB:8)
B(8,-22,6,LOG:1)
B(2,-22,7,WOODEN_SLAB:13)
B(3,-22,7,PLANKS:5)
B(4,-22,7,WOODEN_SLAB:8)
B(5,-22,7,WOODEN_SLAB:8)
B(6,-22,7,WOODEN_SLAB:8)
B(7,-22,7,WOODEN_SLAB:8)
B(8,-22,7,LADDER:3)
B(2,-22,8,WOODEN_SLAB:13)
B(3,-22,8,PLANKS:5)
B(4,-22,8,WOODEN_SLAB:8)
B(5,-22,8,WOODEN_SLAB:8)
B(6,-22,8,WOODEN_SLAB:8)
B(7,-22,8,WOODEN_SLAB:8)
B(8,-22,8,WOODEN_SLAB:8)
B(2,-21,-7,SPRUCE_FENCE:0)
B(3,-21,-7,PLANKS:5)
RB(4,-21,-7,CHEST:5,../NBT/StructureLoot/ShipJunk_1.nbt,15,CHEST:5,../NBT/StructureLoot/ShipJunk_2.nbt,15,CHEST:5,../NBT/StructureLoot/ShipJunk_3.nbt,15,CHEST:5,../NBT/StructureLoot/ShipJunk_4.nbt,15,CHEST:5,../NBT/StructureLoot/ShipJunk_5.nbt,15,CHEST:5,../NBT/StructureLoot/Common1.nbt,15,CHEST:5,../NBT/StructureLoot/Common2.nbt,15,CHEST:5,../NBT/StructureLoot/Common3.nbt,15,CHEST:5,../NBT/StructureLoot/Common4.nbt,15,CHEST:5,../NBT/StructureLoot/Common5.nbt,15,CHEST:5,../NBT/StructureLoot/Common6.nbt,15,CHEST:5,../NBT/StructureLoot/Common7.nbt,15,CHEST:5,../NBT/StructureLoot/Common8.nbt,15,CHEST:5,../NBT/StructureLoot/Common9.nbt,15,CHEST:5,../NBT/StructureLoot/Common10.nbt,15,CHEST:5,../NBT/StructureLoot/Common11.nbt,15,CHEST:5,../NBT/StructureLoot/Common12.nbt,15,CHEST:5,../NBT/StructureLoot/Common13.nbt,15,CHEST:5,../NBT/StructureLoot/Common14.nbt,15,CHEST:5,../NBT/StructureLoot/Common15.nbt,100)
B(7,-21,-7,STONE_BUTTON:3)
B(8,-21,-7,STONE_BUTTON:3)
B(3,-21,-6,PLANKS:5)
B(3,-21,-5,FENCE:0)
B(4,-21,-5,STONE_BUTTON:4)
B(5,-21,-5,STONE_BUTTON:4)
B(7,-21,-5,SPRUCE_STAIRS:0)
B(3,-21,-4,FENCE:0)
B(4,-21,-4,CRAFTING_TABLE:0)
B(5,-21,-4,CRAFTING_TABLE:0)
B(6,-21,-4,STONE_BUTTON:1)
B(7,-21,-4,TRAPDOOR:2)
B(8,-21,-4,WOODEN_SLAB:1)
B(3,-21,-3,SPRUCE_FENCE_GATE:1)
B(4,-21,-3,CRAFTING_TABLE:0)
B(5,-21,-3,CRAFTING_TABLE:0)
B(6,-21,-3,STONE_BUTTON:1)
B(7,-21,-3,TRAPDOOR:2)
B(8,-21,-3,WOODEN_SLAB:1)
B(3,-21,-2,FENCE:0)
B(4,-21,-2,CRAFTING_TABLE:0)
B(5,-21,-2,CRAFTING_TABLE:0)
B(6,-21,-2,STONE_BUTTON:1)
B(7,-21,-2,TRAPDOOR:2)
B(8,-21,-2,WOODEN_SLAB:1)
B(3,-21,-1,SPRUCE_FENCE_GATE:1)
B(4,-21,-1,CRAFTING_TABLE:0)
B(5,-21,-1,CRAFTING_TABLE:0)
B(6,-21,-1,STONE_BUTTON:1)
B(7,-21,-1,TRAPDOOR:2)
B(8,-21,-1,WOODEN_SLAB:1)
B(3,-21,0,FENCE:0)
B(4,-21,0,STONE_BUTTON:3)
B(5,-21,0,STONE_BUTTON:3)
B(7,-21,0,TRAPDOOR:2)
B(8,-21,0,WOODEN_SLAB:1)
B(3,-21,1,FENCE:0)
B(7,-21,1,SPRUCE_STAIRS:0)
B(3,-21,2,DARK_OAK_STAIRS:7)
B(4,-21,2,FENCE:0)
B(3,-21,3,DARK_OAK_STAIRS:4)
B(7,-21,3,COBBLESTONE_WALL:0)
B(3,-21,4,DARK_OAK_STAIRS:6)
RB(4,-21,4,CHEST:5,../NBT/StructureLoot/ShipJunk_1.nbt,15,CHEST:5,../NBT/StructureLoot/ShipJunk_2.nbt,15,CHEST:5,../NBT/StructureLoot/ShipJunk_3.nbt,15,CHEST:5,../NBT/StructureLoot/ShipJunk_4.nbt,15,CHEST:5,../NBT/StructureLoot/ShipJunk_5.nbt,15,CHEST:5,../NBT/StructureLoot/Common1.nbt,15,CHEST:5,../NBT/StructureLoot/Common2.nbt,15,CHEST:5,../NBT/StructureLoot/Common3.nbt,15,CHEST:5,../NBT/StructureLoot/Common4.nbt,15,CHEST:5,../NBT/StructureLoot/Common5.nbt,15,CHEST:5,../NBT/StructureLoot/Common6.nbt,15,CHEST:5,../NBT/StructureLoot/Common7.nbt,15,CHEST:5,../NBT/StructureLoot/Common8.nbt,15,CHEST:5,../NBT/StructureLoot/Common9.nbt,15,CHEST:5,../NBT/StructureLoot/Common10.nbt,15,CHEST:5,../NBT/StructureLoot/Common11.nbt,15,CHEST:5,../NBT/StructureLoot/Common12.nbt,15,CHEST:5,../NBT/StructureLoot/Common13.nbt,15,CHEST:5,../NBT/StructureLoot/Common14.nbt,15,CHEST:5,../NBT/StructureLoot/Common15.nbt,100)
B(2,-21,5,SPRUCE_FENCE:0)
B(3,-21,5,PLANKS:5)
B(7,-21,5,COBBLESTONE_WALL:0)
B(2,-21,6,SPRUCE_FENCE:0)
B(3,-21,6,PLANKS:5)
B(7,-21,6,WOODEN_SLAB:5)
B(8,-21,6,PLANKS:5)
B(2,-21,7,SPRUCE_FENCE:0)
B(3,-21,7,PLANKS:5)
RB(4,-21,7,CHEST:5,../NBT/StructureLoot/ShipJunk_1.nbt,15,CHEST:5,../NBT/StructureLoot/ShipJunk_2.nbt,15,CHEST:5,../NBT/StructureLoot/ShipJunk_3.nbt,15,CHEST:5,../NBT/StructureLoot/ShipJunk_4.nbt,15,CHEST:5,../NBT/StructureLoot/ShipJunk_5.nbt,15,CHEST:5,../NBT/StructureLoot/Common1.nbt,15,CHEST:5,../NBT/StructureLoot/Common2.nbt,15,CHEST:5,../NBT/StructureLoot/Common3.nbt,15,CHEST:5,../NBT/StructureLoot/Common4.nbt,15,CHEST:5,../NBT/StructureLoot/Common5.nbt,15,CHEST:5,../NBT/StructureLoot/Common6.nbt,15,CHEST:5,../NBT/StructureLoot/Common7.nbt,15,CHEST:5,../NBT/StructureLoot/Common8.nbt,15,CHEST:5,../NBT/StructureLoot/Common9.nbt,15,CHEST:5,../NBT/StructureLoot/Common10.nbt,15,CHEST:5,../NBT/StructureLoot/Common11.nbt,15,CHEST:5,../NBT/StructureLoot/Common12.nbt,15,CHEST:5,../NBT/StructureLoot/Common13.nbt,15,CHEST:5,../NBT/StructureLoot/Common14.nbt,15,CHEST:5,../NBT/StructureLoot/Common15.nbt,100)
B(7,-21,7,WOODEN_SLAB:5)
B(8,-21,7,TRAPDOOR:1)
B(2,-21,8,SPRUCE_FENCE:0)
B(3,-21,8,PLANKS:5)
RB(4,-21,8,CHEST:5,../NBT/StructureLoot/ShipJunk_1.nbt,15,CHEST:5,../NBT/StructureLoot/ShipJunk_2.nbt,15,CHEST:5,../NBT/StructureLoot/ShipJunk_3.nbt,15,CHEST:5,../NBT/StructureLoot/ShipJunk_4.nbt,15,CHEST:5,../NBT/StructureLoot/ShipJunk_5.nbt,15,CHEST:5,../NBT/StructureLoot/Common1.nbt,15,CHEST:5,../NBT/StructureLoot/Common2.nbt,15,CHEST:5,../NBT/StructureLoot/Common3.nbt,15,CHEST:5,../NBT/StructureLoot/Common4.nbt,15,CHEST:5,../NBT/StructureLoot/Common5.nbt,15,CHEST:5,../NBT/StructureLoot/Common6.nbt,15,CHEST:5,../NBT/StructureLoot/Common7.nbt,15,CHEST:5,../NBT/StructureLoot/Common8.nbt,15,CHEST:5,../NBT/StructureLoot/Common9.nbt,15,CHEST:5,../NBT/StructureLoot/Common10.nbt,15,CHEST:5,../NBT/StructureLoot/Common11.nbt,15,CHEST:5,../NBT/StructureLoot/Common12.nbt,15,CHEST:5,../NBT/StructureLoot/Common13.nbt,15,CHEST:5,../NBT/StructureLoot/Common14.nbt,15,CHEST:5,../NBT/StructureLoot/Common15.nbt,100)
B(7,-21,8,WOODEN_SLAB:5)
B(8,-21,8,WOODEN_SLAB:5)
B(2,-20,-7,SPRUCE_FENCE:0)
B(3,-20,-7,SPRUCE_FENCE:0)
B(6,-20,-7,AIR)
B(8,-20,-7,SPRUCE_STAIRS:6)
B(7,-20,-6,WOODEN_SLAB:9)
B(8,-20,-6,DOUBLE_WOODEN_SLAB:1)
B(4,-20,-5,STONE_BUTTON:4)
B(5,-20,-5,STONE_BUTTON:4)
B(7,-20,-5,SPRUCE_STAIRS:4)
B(8,-20,-5,WOODEN_SLAB:1)
B(3,-20,-4,STONE_BUTTON:2)
B(4,-20,-4,CRAFTING_TABLE:0)
B(5,-20,-4,CRAFTING_TABLE:0)
B(6,-20,-4,STONE_BUTTON:1)
B(7,-20,-4,SPRUCE_STAIRS:4)
B(8,-20,-4,WOODEN_SLAB:1)
B(3,-20,-3,STONE_BUTTON:2)
B(4,-20,-3,CRAFTING_TABLE:0)
B(5,-20,-3,CRAFTING_TABLE:0)
B(6,-20,-3,STONE_BUTTON:1)
B(7,-20,-3,SPRUCE_STAIRS:4)
B(8,-20,-3,WOODEN_SLAB:1)
B(3,-20,-2,STONE_BUTTON:2)
B(4,-20,-2,CRAFTING_TABLE:0)
B(5,-20,-2,CRAFTING_TABLE:0)
B(6,-20,-2,STONE_BUTTON:1)
B(7,-20,-2,SPRUCE_STAIRS:4)
B(8,-20,-2,WOODEN_SLAB:1)
B(3,-20,-1,STONE_BUTTON:2)
B(4,-20,-1,CRAFTING_TABLE:0)
B(5,-20,-1,CRAFTING_TABLE:0)
B(6,-20,-1,STONE_BUTTON:1)
B(7,-20,-1,SPRUCE_STAIRS:4)
B(8,-20,-1,WOODEN_SLAB:1)
B(4,-20,0,STONE_BUTTON:3)
B(5,-20,0,STONE_BUTTON:3)
B(7,-20,0,SPRUCE_STAIRS:4)
B(8,-20,0,WOODEN_SLAB:1)
B(7,-20,1,SPRUCE_STAIRS:4)
B(8,-20,1,WOODEN_SLAB:1)
B(4,-20,2,TORCH:5)
B(7,-20,2,WOODEN_SLAB:9)
B(8,-20,2,SPRUCE_STAIRS:7)
B(7,-20,3,FENCE:0)
B(5,-20,4,AIR)
B(2,-20,5,SPRUCE_FENCE:0)
B(3,-20,5,SPRUCE_FENCE:0)
B(7,-20,5,FENCE:0)
B(2,-20,6,SPRUCE_FENCE:0)
B(3,-20,6,SPRUCE_FENCE:0)
B(8,-20,6,PLANKS:5)
B(2,-20,7,SPRUCE_FENCE:0)
B(3,-20,7,SPRUCE_FENCE:0)
B(8,-20,7,LADDER:3)
B(2,-20,8,SPRUCE_FENCE:0)
B(3,-20,8,SPRUCE_FENCE:0)
B(8,-20,8,TRAPDOOR:4)
B(3,-19,-7,SPRUCE_FENCE:0)
B(7,-19,-7,SPRUCE_STAIRS:6)
B(8,-19,-7,WOODEN_SLAB:1)
B(6,-19,-6,WOODEN_BUTTON:2)
B(7,-19,-6,DOUBLE_WOODEN_SLAB:1)
B(8,-19,-6,TRAPDOOR:3)
B(6,-19,-5,WOODEN_BUTTON:2)
B(7,-19,-5,DOUBLE_WOODEN_SLAB:1)
B(4,-19,-4,TRAPDOOR:1)
B(5,-19,-4,TRAPDOOR:1)
B(6,-19,-4,WOODEN_BUTTON:2)
B(7,-19,-4,DOUBLE_WOODEN_SLAB:1)
B(8,-19,-4,TRAPDOOR:3)
B(4,-19,-3,TRAPDOOR:1)
B(5,-19,-3,TRAPDOOR:1)
B(7,-19,-3,WOODEN_SLAB:1)
B(4,-19,-2,TRAPDOOR:0)
B(5,-19,-2,TRAPDOOR:0)
B(7,-19,-2,WOODEN_SLAB:1)
B(8,-19,-2,TRAPDOOR:3)
B(4,-19,-1,TRAPDOOR:0)
B(5,-19,-1,TRAPDOOR:0)
B(7,-19,-1,WOODEN_SLAB:1)
B(7,-19,0,WOODEN_SLAB:1)
B(8,-19,0,TRAPDOOR:3)
B(-2,-19,1,WOOL:0)
B(-1,-19,1,WOOL:0)
B(0,-19,1,WOOL:0)
B(7,-19,1,WOODEN_SLAB:1)
B(-4,-19,2,WOOL:0)
B(-3,-19,2,WOOL:0)
B(1,-19,2,WOOL:15)
B(2,-19,2,WOOL:15)
B(3,-19,2,WOOL:15)
B(7,-19,2,WOODEN_SLAB:1)
B(-4,-19,3,WOOL:0)
B(4,-19,3,WOOL:15)
B(7,-19,3,WOODEN_SLAB:1)
B(8,-19,3,SPRUCE_STAIRS:2)
B(7,-19,4,SPRUCE_STAIRS:0)
B(8,-19,4,PLANKS:5)
B(3,-19,5,SPRUCE_FENCE:0)
B(7,-19,5,WOODEN_SLAB:1)
B(8,-19,5,SPRUCE_STAIRS:3)
B(3,-19,6,SPRUCE_FENCE:0)
B(8,-19,6,LOG_2:1)
B(3,-19,7,SPRUCE_FENCE:0)
B(8,-19,7,LADDER:3)
B(3,-19,8,SPRUCE_FENCE:0)
B(3,-18,-7,SPRUCE_FENCE:0)
B(8,-18,-7,WOOL:0)
B(-2,-18,0,WOOL:0)
B(-1,-18,0,WOOL:0)
B(0,-18,0,WOOL:15)
B(1,-18,0,WOOL:15)
B(-3,-18,1,WOOL:0)
B(1,-18,1,WOOL:15)
B(2,-18,1,WOOL:15)
B(3,-18,1,WOOL:15)
B(4,-18,2,WOOL:15)
B(5,-18,2,WOOL:0)
B(6,-18,3,WOOL:0)
B(7,-18,3,WOOL:0)
B(8,-18,3,WOOL:0)
B(-5,-18,4,WOOL:0)
B(8,-18,4,TRAPDOOR:1)
B(-5,-18,5,WOOL:0)
B(3,-18,5,SPRUCE_FENCE:0)
B(3,-18,6,SPRUCE_FENCE:0)
B(8,-18,6,PLANKS:5)
B(3,-18,7,SPRUCE_FENCE:0)
B(8,-18,7,LADDER:3)
B(3,-18,8,SPRUCE_FENCE:0)
B(8,-18,8,WOODEN_BUTTON:2)
B(8,-17,-7,WOOL:0)
B(8,-17,-4,WOOL:0)
B(8,-17,-3,WOOL:0)
B(-2,-17,-1,WOOL:0)
B(-1,-17,-1,WOOL:15)
B(0,-17,-1,WOOL:15)
B(8,-17,-1,WOOL:0)
B(-3,-17,0,WOOL:0)
B(1,-17,0,WOOL:15)
B(2,-17,0,WOOL:15)
B(3,-17,0,WOOL:0)
B(4,-17,1,WOOL:0)
B(5,-17,1,WOOL:0)
B(6,-17,1,WOOL:0)
B(6,-17,2,WOOL:0)
B(7,-17,2,WOOL:0)
B(8,-17,2,WOOL:0)
B(3,-17,6,SPRUCE_FENCE:0)
B(4,-17,6,SPRUCE_FENCE:0)
B(8,-17,6,LOG_2:1)
B(3,-17,7,SPRUCE_FENCE:0)
B(4,-17,7,SPRUCE_FENCE:0)
B(8,-17,7,LADDER:3)
B(3,-17,8,SPRUCE_FENCE:0)
B(4,-17,8,SPRUCE_FENCE:0)
B(8,-16,-7,SPRUCE_FENCE:0)
B(8,-16,-6,WOOL:0)
B(8,-16,-5,WOOL:0)
B(-2,-16,-1,WOOL:15)
B(-1,-16,-1,WOOL:15)
B(0,-16,-1,WOOL:15)
B(8,-16,-1,WOOL:0)
B(1,-16,0,WOOL:15)
B(2,-16,0,WOOL:15)
B(3,-16,0,WOOL:0)
B(4,-16,1,WOOL:0)
B(5,-16,1,WOOL:0)
B(6,-16,1,WOOL:0)
B(7,-16,1,WOOL:0)
B(8,-16,1,WOOL:0)
B(4,-16,6,SPRUCE_FENCE:0)
B(8,-16,6,LOG_2:1)
B(4,-16,7,SPRUCE_FENCE:0)
B(8,-16,7,LADDER:3)
B(4,-16,8,SPRUCE_FENCE:0)
B(8,-15,-7,SPRUCE_FENCE:0)
B(8,-15,-6,SPRUCE_FENCE:0)
B(8,-15,-5,WOOL:0)
B(8,-15,-4,WOOL:0)
B(8,-15,-2,WOOL:0)
B(-1,-15,-1,WOOL:15)
B(-2,-15,0,WOOL:15)
B(0,-15,0,WOOL:15)
B(1,-15,0,WOOL:0)
B(2,-15,0,WOOL:0)
B(3,-15,1,WOOL:0)
B(4,-15,1,WOOL:0)
B(5,-15,1,WOOL:0)
B(6,-15,1,WOOL:0)
B(7,-15,1,WOOL:0)
B(7,-15,2,WOOL:0)
B(8,-15,2,WOOL:0)
B(4,-15,6,SPRUCE_FENCE:0)
B(5,-15,6,SPRUCE_FENCE:0)
B(8,-15,6,LOG_2:1)
B(4,-15,7,SPRUCE_FENCE:0)
B(5,-15,7,SPRUCE_FENCE:0)
B(8,-15,7,LADDER:3)
B(4,-15,8,SPRUCE_FENCE:0)
B(5,-15,8,SPRUCE_FENCE:0)
B(8,-14,-6,SPRUCE_FENCE:0)
B(8,-14,-5,SPRUCE_FENCE:0)
B(8,-14,-4,WOOL:0)
B(8,-14,-1,WOOL:0)
B(-1,-14,0,WOOL:15)
B(0,-14,0,WOOL:15)
B(-2,-14,1,WOOL:15)
B(1,-14,1,WOOL:0)
B(2,-14,1,WOOL:0)
B(3,-14,1,WOOL:0)
B(-3,-14,2,WOOL:15)
B(4,-14,2,WOOL:0)
B(5,-14,2,WOOL:0)
B(6,-14,2,WOOL:0)
B(7,-14,3,WOOL:0)
B(8,-14,3,WOOL:0)
B(5,-14,6,SPRUCE_FENCE:0)
B(8,-14,6,LOG_2:1)
B(5,-14,7,SPRUCE_FENCE:0)
B(8,-14,7,LADDER:3)
B(5,-14,8,SPRUCE_FENCE:0)
B(8,-13,-5,SPRUCE_FENCE:0)
B(8,-13,-4,SPRUCE_FENCE:0)
B(8,-13,-3,WOOL:0)
B(-1,-13,1,WOOL:15)
B(0,-13,1,WOOL:0)
B(1,-13,1,WOOL:0)
B(-2,-13,2,WOOL:15)
B(-1,-13,2,SPRUCE_FENCE:0)
B(0,-13,2,SPRUCE_FENCE:0)
B(2,-13,2,WOOL:0)
B(3,-13,2,WOOL:0)
B(-3,-13,3,WOOL:15)
B(2,-13,3,SPRUCE_FENCE:0)
B(3,-13,3,SPRUCE_FENCE:0)
B(4,-13,3,WOOL:0)
B(5,-13,3,WOOL:0)
B(-3,-13,4,WOOL:15)
B(4,-13,4,SPRUCE_FENCE:0)
B(5,-13,4,SPRUCE_FENCE:0)
B(5,-13,6,SPRUCE_FENCE:0)
B(6,-13,6,SPRUCE_FENCE:0)
B(8,-13,6,LOG_2:1)
B(5,-13,7,SPRUCE_FENCE:0)
B(6,-13,7,SPRUCE_FENCE:0)
B(8,-13,7,LADDER:3)
B(5,-13,8,SPRUCE_FENCE:0)
B(6,-13,8,SPRUCE_FENCE:0)
B(8,-12,-4,SPRUCE_FENCE:0)
B(8,-12,-3,SPRUCE_FENCE:0)
B(8,-12,-2,WOOL:0)
B(8,-12,-1,WOOL:0)
B(-2,-12,1,WOODEN_BUTTON:4)
B(-1,-12,1,WOODEN_BUTTON:4)
B(0,-12,1,WOODEN_BUTTON:4)
B(-2,-12,2,LOG:5)
B(-1,-12,2,LOG:5)
B(0,-12,2,LOG:5)
B(1,-12,2,WOODEN_BUTTON:4)
B(2,-12,2,WOODEN_BUTTON:4)
B(3,-12,2,WOODEN_BUTTON:4)
B(-2,-12,3,WOODEN_BUTTON:3)
B(-1,-12,3,WOODEN_BUTTON:3)
B(0,-12,3,WOODEN_BUTTON:3)
B(1,-12,3,LOG:5)
B(2,-12,3,LOG:5)
B(3,-12,3,LOG:5)
B(4,-12,3,WOODEN_BUTTON:4)
B(5,-12,3,WOODEN_BUTTON:4)
B(6,-12,3,WOODEN_BUTTON:4)
B(1,-12,4,WOODEN_BUTTON:3)
B(2,-12,4,WOODEN_BUTTON:3)
B(3,-12,4,WOODEN_BUTTON:3)
B(4,-12,4,LOG:5)
B(5,-12,4,LOG:5)
B(6,-12,4,LOG:5)
B(7,-12,4,WOODEN_BUTTON:4)
B(8,-12,4,WOODEN_BUTTON:4)
B(-4,-12,5,WOOL:15)
B(4,-12,5,WOODEN_BUTTON:3)
B(5,-12,5,WOODEN_BUTTON:3)
B(6,-12,5,WOODEN_BUTTON:3)
B(7,-12,5,LOG:5)
B(8,-12,5,PLANKS:5)
B(6,-12,6,SPRUCE_FENCE:0)
B(7,-12,6,WOODEN_BUTTON:3)
B(8,-12,6,PLANKS:5)
B(6,-12,7,SPRUCE_FENCE:0)
B(8,-12,7,LADDER:3)
B(6,-12,8,SPRUCE_FENCE:0)
B(8,-11,-3,SPRUCE_FENCE:0)
B(8,-11,-2,SPRUCE_FENCE:0)
B(8,-11,-1,WOOL:0)
B(8,-11,0,WOOL:0)
B(1,-11,2,WOOL:0)
B(2,-11,2,WOOL:0)
B(3,-11,2,WOOL:0)
B(0,-11,3,WOOL:0)
B(4,-11,3,WOOL:0)
B(5,-11,3,WOOL:0)
B(-1,-11,4,WOOL:0)
B(6,-11,6,SPRUCE_FENCE:0)
B(7,-11,6,SPRUCE_STAIRS:6)
B(8,-11,6,LOG_2:1)
B(6,-11,7,SPRUCE_FENCE:0)
B(7,-11,7,SPRUCE_STAIRS:4)
B(8,-11,7,LADDER:3)
B(6,-11,8,WOODEN_SLAB:9)
B(7,-11,8,SPRUCE_STAIRS:4)
B(8,-11,8,SPRUCE_STAIRS:7)
B(8,-10,-2,SPRUCE_FENCE:0)
B(8,-10,-1,SPRUCE_FENCE:0)
B(8,-10,0,WOOL:0)
B(2,-10,1,WOOL:0)
B(3,-10,1,WOOL:0)
B(8,-10,1,WOOL:0)
B(0,-10,2,WOOL:0)
B(1,-10,2,WOOL:0)
B(4,-10,2,WOOL:15)
B(5,-10,2,WOOL:15)
B(6,-10,2,WOOL:15)
B(7,-10,3,WOOL:15)
B(8,-10,3,WOOL:0)
B(-2,-10,5,WOOL:0)
B(-2,-10,6,WOOL:0)
B(6,-10,6,SPRUCE_FENCE:0)
B(7,-10,6,SPRUCE_FENCE:0)
B(8,-10,6,LOG_2:1)
B(6,-10,7,SPRUCE_FENCE:0)
B(7,-10,7,SPRUCE_FENCE:0)
B(8,-10,7,LADDER:3)
B(6,-10,8,SPRUCE_FENCE:0)
B(7,-10,8,SPRUCE_FENCE:0)
B(8,-10,8,SPRUCE_FENCE:0)
B(8,-9,-7,WOOL:0)
B(8,-9,-3,WOOL:0)
B(8,-9,-1,SPRUCE_FENCE:0)
B(8,-9,0,SPRUCE_FENCE:0)
B(0,-9,1,WOOL:0)
B(1,-9,1,WOOL:0)
B(2,-9,1,WOOL:0)
B(3,-9,1,WOOL:15)
B(4,-9,1,WOOL:15)
B(8,-9,1,SPRUCE_FENCE:0)
B(5,-9,2,WOOL:15)
B(6,-9,2,WOOL:15)
B(7,-9,2,WOOL:15)
B(8,-9,3,WOOL:0)
B(7,-9,6,SPRUCE_FENCE:0)
B(8,-9,6,LOG_2:1)
B(7,-9,7,SPRUCE_FENCE:0)
B(8,-9,7,LADDER:3)
B(7,-9,8,SPRUCE_FENCE:0)
B(8,-8,-7,WOOL:0)
B(8,-8,-2,WOOL:0)
B(8,-8,-1,WOOL:0)
B(1,-8,0,WOOL:0)
B(2,-8,0,WOOL:15)
B(3,-8,0,WOOL:15)
B(8,-8,0,WOOL:0)
B(4,-8,1,WOOL:15)
B(5,-8,1,WOOL:15)
B(8,-8,1,SPRUCE_FENCE:0)
B(6,-8,2,WOOL:15)
B(7,-8,2,WOOL:0)
B(8,-8,2,WOOL:0)
B(8,-8,5,PLANKS:5)
B(7,-8,6,SPRUCE_FENCE:0)
B(8,-8,6,PLANKS:5)
B(7,-8,7,SPRUCE_FENCE:0)
B(8,-8,7,LADDER:3)
B(7,-8,8,SPRUCE_FENCE:0)
B(8,-7,-6,WOOL:0)
B(8,-7,-1,WOOL:0)
B(1,-7,0,WOOL:15)
B(2,-7,0,WOOL:15)
B(3,-7,0,WOOL:15)
B(4,-7,1,WOOL:15)
B(5,-7,1,WOOL:15)
B(6,-7,1,WOOL:0)
B(7,-7,2,WOOL:0)
B(8,-7,2,WOOL:0)
B(8,-7,3,SPRUCE_FENCE:0)
B(7,-7,5,SPRUCE_FENCE:0)
B(8,-7,5,PLANKS:5)
B(7,-7,6,SPRUCE_FENCE:0)
B(8,-7,6,PLANKS:5)
B(7,-7,7,SPRUCE_FENCE:0)
B(8,-7,7,LADDER:3)
B(8,-6,-7,SPRUCE_FENCE:0)
B(8,-6,-5,WOOL:0)
B(8,-6,-2,WOOL:0)
B(1,-6,0,WOOL:15)
B(2,-6,0,WOOL:15)
B(3,-6,0,WOOL:15)
B(4,-6,0,WOOL:15)
B(5,-6,1,WOOL:0)
B(6,-6,1,WOOL:0)
B(7,-6,1,WOOL:0)
B(8,-6,2,WOOL:0)
B(8,-6,3,SPRUCE_FENCE:0)
B(8,-6,4,SPRUCE_FENCE:0)
B(7,-6,5,SPRUCE_FENCE:0)
B(8,-6,5,LOG_2:1)
B(7,-6,6,SPRUCE_FENCE:0)
B(8,-6,6,LADDER:3)
B(8,-5,-7,SPRUCE_FENCE:0)
B(8,-5,-6,SPRUCE_FENCE:0)
B(8,-5,-5,WOOL:0)
B(8,-5,-4,WOOL:0)
B(2,-5,0,WOOL:15)
B(3,-5,0,WOOL:15)
B(0,-5,1,WOOL:15)
B(1,-5,1,WOOL:15)
B(4,-5,1,WOOL:0)
B(5,-5,1,WOOL:0)
B(6,-5,1,WOOL:0)
B(7,-5,2,WOOL:0)
B(8,-5,2,WOOL:0)
B(7,-5,5,SPRUCE_FENCE:0)
B(8,-5,5,LOG_2:1)
B(7,-5,6,SPRUCE_FENCE:0)
B(8,-5,6,LADDER:3)
B(8,-4,-6,SPRUCE_FENCE:0)
B(8,-4,-5,SPRUCE_FENCE:0)
B(8,-4,-4,WOOL:0)
B(8,-4,-3,WOOL:0)
B(1,-4,1,WOOL:15)
B(2,-4,1,WOOL:15)
B(3,-4,1,WOOL:0)
B(4,-4,1,WOOL:0)
B(5,-4,1,WOOL:0)
B(0,-4,2,WOOL:15)
B(6,-4,2,WOOL:0)
B(7,-4,2,WOOL:0)
B(8,-4,3,WOOL:0)
B(7,-4,5,SPRUCE_FENCE:0)
B(8,-4,5,LOG_2:1)
B(7,-4,6,SPRUCE_FENCE:0)
B(8,-4,6,LADDER:3)
B(8,-3,-5,SPRUCE_FENCE:0)
B(8,-3,-4,SPRUCE_FENCE:0)
B(8,-3,-3,WOOL:0)
B(8,-3,-2,WOOL:0)
B(2,-3,1,WOOL:15)
B(3,-3,1,WOOL:0)
B(1,-3,2,WOOL:15)
B(2,-3,2,SPRUCE_FENCE:0)
B(3,-3,2,SPRUCE_FENCE:0)
B(4,-3,2,WOOL:0)
B(5,-3,2,WOOL:0)
B(6,-3,2,WOOL:0)
B(0,-3,3,WOOL:15)
B(4,-3,3,SPRUCE_FENCE:0)
B(5,-3,3,SPRUCE_FENCE:0)
B(6,-3,3,SPRUCE_FENCE:0)
B(-1,-3,4,WOOL:15)
B(-1,-3,5,WOOL:15)
B(7,-3,5,SPRUCE_FENCE:0)
B(8,-3,5,LOG_2:1)
B(-1,-3,6,WOOL:0)
B(7,-3,6,SPRUCE_FENCE:0)
B(8,-3,6,LADDER:3)
B(8,-2,-4,SPRUCE_FENCE:0)
B(8,-2,-3,SPRUCE_FENCE:0)
B(8,-2,-2,WOOL:0)
B(8,-2,-1,WOOL:0)
B(1,-2,1,WOODEN_BUTTON:4)
B(2,-2,1,WOODEN_BUTTON:4)
B(3,-2,1,WOODEN_BUTTON:4)
B(1,-2,2,LOG:5)
B(2,-2,2,LOG:5)
B(3,-2,2,LOG:5)
B(4,-2,2,WOODEN_BUTTON:4)
B(5,-2,2,WOODEN_BUTTON:4)
B(6,-2,2,WOODEN_BUTTON:4)
B(1,-2,3,WOODEN_BUTTON:3)
B(2,-2,3,WOODEN_BUTTON:3)
B(3,-2,3,WOODEN_BUTTON:3)
B(4,-2,3,LOG:5)
B(5,-2,3,LOG:5)
B(6,-2,3,LOG:5)
B(7,-2,3,WOODEN_BUTTON:4)
B(8,-2,3,WOODEN_BUTTON:4)
B(4,-2,4,WOODEN_BUTTON:3)
B(5,-2,4,WOODEN_BUTTON:3)
B(6,-2,4,WOODEN_BUTTON:3)
B(7,-2,4,LOG:5)
B(8,-2,4,PLANKS:5)
B(7,-2,5,SPRUCE_FENCE:0)
B(8,-2,5,PLANKS:5)
B(7,-2,6,SPRUCE_FENCE:0)
B(8,-2,6,LADDER:3)
B(8,-1,-3,SPRUCE_FENCE:0)
B(8,-1,-2,SPRUCE_FENCE:0)
B(8,-1,-1,WOOL:0)
B(2,-1,2,WOOL:0)
B(3,-1,2,WOOL:0)
B(4,-1,2,WOOL:0)
B(5,-1,2,WOOL:0)
B(1,-1,3,WOOL:0)
B(1,-1,4,WOOL:0)
B(7,-1,5,SPRUCE_FENCE:0)
B(8,-1,5,LOG_2:1)
B(8,-1,6,LADDER:3)
B(8,0,-2,SPRUCE_FENCE:0)
B(8,0,-1,SPRUCE_FENCE:0)
B(1,0,1,WOOL:0)
B(2,0,1,WOOL:0)
B(3,0,1,WOOL:0)
B(4,0,1,WOOL:0)
B(5,0,1,WOOL:15)
B(6,0,1,WOOL:15)
B(1,0,2,WOOL:0)
B(2,0,2,WOOL:0)
B(7,0,2,WOOL:15)
B(8,0,2,WOOL:0)
B(0,0,5,WOOL:0)
B(7,0,5,SPRUCE_FENCE:0)
B(8,0,5,LOG_2:1)
B(0,0,6,WOOL:0)
B(8,0,6,LADDER:3)
B(8,1,-1,SPRUCE_FENCE:0)
B(2,1,0,WOOL:0)
B(3,1,0,WOOL:15)
B(4,1,0,WOOL:15)
B(5,1,0,WOOL:15)
B(8,1,0,SPRUCE_FENCE:0)
B(6,1,1,WOOL:15)
B(7,1,1,WOOL:15)
B(8,1,1,WOOL:0)
B(7,1,5,SPRUCE_FENCE:0)
B(8,1,5,LOG_2:1)
B(8,1,6,LADDER:3)
B(3,2,0,WOOL:15)
B(4,2,0,WOOL:15)
B(5,2,0,WOOL:15)
B(6,2,0,WOOL:15)
B(8,2,0,SPRUCE_FENCE:0)
B(7,2,1,WOOL:0)
B(8,2,1,WOOL:0)
B(8,2,2,SPRUCE_FENCE:0)
B(8,2,5,LOG_2:1)
B(8,2,6,LADDER:3)
B(3,3,0,WOOL:15)
B(4,3,0,WOOL:15)
B(5,3,0,WOOL:15)
B(6,3,1,WOOL:0)
B(7,3,1,WOOL:0)
B(8,3,1,WOOL:0)
B(8,3,2,SPRUCE_FENCE:0)
B(8,3,3,SPRUCE_FENCE:0)
B(8,3,5,LOG_2:1)
B(8,3,6,LADDER:3)
B(3,4,0,WOOL:15)
B(2,4,1,WOOL:15)
B(4,4,1,WOOL:15)
B(5,4,1,WOOL:0)
B(6,4,1,WOOL:0)
B(7,4,1,WOOL:0)
B(8,4,2,WOOL:0)
B(8,4,3,SPRUCE_FENCE:0)
B(8,4,4,SPRUCE_FENCE:0)
B(7,4,5,SPRUCE_STAIRS:6)
B(8,4,5,LOG_2:1)
B(7,4,6,SPRUCE_STAIRS:4)
B(8,4,6,LADDER:3)
B(7,4,7,WOODEN_SLAB:9)
B(8,4,7,PLANKS:1)
B(8,5,-7,SPRUCE_FENCE:0)
B(3,5,1,WOOL:15)
B(4,5,1,WOOL:0)
B(5,5,1,WOOL:0)
B(2,5,2,WOOL:15)
B(3,5,2,SPRUCE_FENCE:0)
B(4,5,2,SPRUCE_FENCE:0)
B(5,5,2,SPRUCE_FENCE:0)
B(8,5,4,PLANKS:5)
B(7,5,5,SPRUCE_FENCE:0)
B(8,5,5,PLANKS:5)
B(7,5,6,SPRUCE_FENCE:0)
B(8,5,6,LADDER:3)
B(7,5,7,SPRUCE_FENCE:0)
B(8,5,7,SPRUCE_FENCE:0)
B(8,6,-7,SPRUCE_FENCE:0)
B(8,6,-6,SPRUCE_FENCE:0)
B(8,6,-5,SPRUCE_FENCE:0)
B(3,6,1,WOODEN_BUTTON:4)
B(4,6,1,WOODEN_BUTTON:4)
B(5,6,1,WOODEN_BUTTON:4)
B(2,6,2,WOOL:15)
B(3,6,2,LOG:5)
B(4,6,2,LOG:5)
B(5,6,2,LOG:5)
B(6,6,2,WOODEN_BUTTON:4)
B(7,6,2,WOODEN_BUTTON:4)
B(8,6,2,WOODEN_BUTTON:4)
B(2,6,3,WOOL:15)
B(3,6,3,WOODEN_BUTTON:3)
B(4,6,3,WOODEN_BUTTON:3)
B(5,6,3,WOODEN_BUTTON:3)
B(6,6,3,LOG:5)
B(7,6,3,LOG:5)
B(8,6,3,PLANKS:5)
B(1,6,4,WOOL:15)
B(6,6,4,WOODEN_BUTTON:3)
B(7,6,4,WOODEN_BUTTON:3)
B(8,6,4,PLANKS:5)
B(0,6,5,WOOL:15)
B(8,6,5,PLANKS:5)
B(0,6,6,WOOL:15)
B(8,6,6,LADDER:3)
B(8,7,-5,SPRUCE_FENCE:0)
B(8,7,-4,SPRUCE_FENCE:0)
B(8,7,-3,SPRUCE_FENCE:0)
B(8,7,4,LOG_2:1)
B(8,7,7,SPRUCE_FENCE:0)
B(8,8,-3,SPRUCE_FENCE:0)
B(8,8,-2,SPRUCE_FENCE:0)
B(8,8,-1,SPRUCE_FENCE:0)
B(8,8,4,LOG_2:1)
B(8,8,5,SPRUCE_FENCE:0)
B(8,8,6,SPRUCE_FENCE:0)
B(8,8,7,SPRUCE_FENCE:0)
B(8,9,-1,SPRUCE_FENCE:0)
B(8,9,0,SPRUCE_FENCE:0)
B(8,9,1,SPRUCE_FENCE:0)
B(8,9,4,LOG_2:1)
B(8,10,1,SPRUCE_FENCE:0)
B(8,10,2,SPRUCE_FENCE:0)
B(8,10,3,SPRUCE_FENCE:0)
B(8,10,4,LOG_2:1)
B(8,11,4,LOG_2:1)
B(8,12,4,COBBLESTONE_WALL:0)
B(8,13,4,COBBLESTONE_WALL:0)
B(8,14,4,COBBLESTONE_WALL:0)
B(8,15,4,DARK_OAK_FENCE:0)
B(8,16,4,DARK_OAK_FENCE:0)
B(8,17,3,WOOL:15)
B(8,17,4,DARK_OAK_FENCE:0)
B(8,18,4,DARK_OAK_FENCE:0)
RB(8,19,4,STANDING_BANNER:10,../NBT/Banners/Agil_01.nbt,20,STANDING_BANNER:10,../NBT/Banners/Agil_02.nbt,20,STANDING_BANNER:10,../NBT/Banners/Agil_03.nbt,20,STANDING_BANNER:10,../NBT/Banners/Agil_04.nbt,20,STANDING_BANNER:10,../NBT/Banners/Agil_05.nbt,100)

E(6,-23,-2,VILLAGER,1)
E(6,-23,5,VILLAGER,1)
E(6,-20,-7,VILLAGER,1)
E(5,-20,4,VILLAGER,1)

