Author: Bo3 BulkEdit

Description: Converted Schematic - Modified by Bo3BulkEdit

Version: 3

SettingsMode: WriteDisable

IsOTGPlus: false
Tree: false
Frequency: 1
Rarity: 100
RotateRandomly: false
SpawnHeight: randomY
MaxBranchDepth: 20
ExcludedBiomes: All

MinHeight: 0
MaxHeight: 256

SourceBlocks: AIR
MaxPercentageOutsideSourceBlock: 100
OutsideSourceBlock: placeAnyway

B(-5,-23,3,WOOL:0)
B(-4,-23,4,WOOL:0)
B(-3,-23,4,WOOL:0)
B(-2,-23,5,WOOL:15)
B(-1,-23,6,WOOL:15)
B(-1,-23,7,WOOL:15)
B(-7,-22,3,WOOL:0)
B(-6,-22,3,WOOL:0)
B(-5,-22,3,WOOL:0)
B(-4,-22,4,WOOL:0)
B(-3,-22,4,WOOL:15)
B(-2,-22,5,WOOL:15)
B(-7,-21,2,WOOL:0)
B(-6,-21,2,WOOL:0)
B(-5,-21,3,WOOL:15)
B(-4,-21,3,WOOL:15)
B(-3,-21,3,WOOL:15)
B(-7,-21,7,WOODEN_SLAB:5)
B(-7,-21,8,WOODEN_SLAB:5)
B(-7,-20,2,WOOL:0)
B(-6,-20,3,WOOL:15)
B(-5,-20,3,WOOL:15)
B(-4,-20,3,WOOL:15)
B(-3,-20,4,WOOL:15)
B(-7,-19,3,WOOL:0)
B(-6,-19,3,WOOL:15)
B(-5,-19,3,WOOL:15)
B(-7,-19,4,SPRUCE_FENCE:0)
B(-6,-19,4,SPRUCE_FENCE:0)
B(-4,-19,4,WOOL:15)
B(-3,-19,4,WOOL:15)
B(-4,-19,5,SPRUCE_FENCE:0)
B(-3,-19,5,SPRUCE_FENCE:0)
B(-7,-18,4,WOODEN_SLAB:1)
B(-6,-18,4,WOODEN_SLAB:1)
B(-3,-18,4,WOOL:0)
B(-5,-18,5,WOODEN_SLAB:1)
B(-4,-18,5,WOODEN_SLAB:1)
B(-3,-18,5,WOODEN_SLAB:1)
B(-2,-18,5,WOOL:0)
B(-1,-17,6,WOOL:0)
B(-7,-16,5,WOOL:0)
B(-7,-16,6,WOOL:0)
B(-7,-15,4,WOOL:0)
B(-7,-15,5,WOOL:0)
B(-7,-15,6,WOOL:0)
B(-6,-15,7,WOOL:0)
B(-7,-14,6,WOOL:0)
B(-7,-14,7,WOOL:0)
B(-7,-14,8,WOOL:0)
B(-7,-13,6,WOOL:0)
B(-7,-13,7,WOOL:0)
B(-7,-13,8,WOOL:0)
B(-7,-12,8,WOOL:0)
B(-7,-11,-2,WOOL:0)
B(-7,-11,-1,WOOL:0)
B(-7,-11,0,WOOL:0)
B(-6,-11,1,WOOL:15)
B(-6,-11,2,WOOL:15)
B(-7,-11,8,WOOL:0)
B(-7,-10,-1,WOOL:0)
B(-7,-10,0,WOOL:0)
B(-6,-10,1,WOOL:15)
B(-6,-10,2,WOOL:15)
B(-6,-10,3,WOOL:15)
B(-5,-10,4,WOOL:0)
B(-7,-9,0,WOOL:0)
B(-7,-9,1,WOOL:15)
B(-6,-9,2,WOOL:15)
B(-6,-9,3,WOOL:15)
B(-6,-9,4,WOOL:15)
B(-5,-9,5,WOOL:0)
B(-5,-9,6,WOOL:0)
B(-5,-9,7,WOOL:0)
B(-4,-9,8,WOOL:15)
B(-7,-8,1,WOOL:0)
B(-7,-8,2,WOOL:15)
B(-6,-8,3,WOOL:15)
B(-6,-8,4,WOOL:15)
B(-6,-8,5,WOOL:15)
B(-5,-8,6,WOOL:0)
B(-5,-8,7,WOOL:0)
B(-5,-8,8,WOOL:15)
B(-7,-7,2,WOOL:0)
B(-7,-7,3,WOOL:15)
B(-6,-7,4,WOOL:15)
B(-6,-7,5,WOOL:15)
B(-6,-7,6,WOOL:15)
B(-5,-7,7,WOOL:0)
B(-5,-7,8,WOOL:0)
B(-7,-6,3,WOOL:0)
B(-7,-6,4,WOOL:15)
B(-6,-6,5,WOOL:15)
B(-6,-6,6,WOOL:15)
B(-6,-6,7,WOOL:15)
B(-5,-6,8,WOOL:0)
B(-7,-5,4,WOOL:0)
B(-7,-5,5,WOOL:15)
B(-6,-5,6,WOOL:15)
B(-6,-5,7,WOOL:15)
B(-6,-5,8,WOOL:15)
B(-7,-4,5,WOOL:0)
B(-7,-4,6,WOOL:15)
B(-6,-4,7,WOOL:15)
B(-6,-4,8,WOOL:15)
B(-7,-3,6,WOOL:0)
B(-7,-3,7,WOOL:15)
B(-6,-3,8,WOOL:15)
B(-7,-2,7,WOOL:0)
B(-7,-2,8,WOOL:15)
B(-7,-1,8,WOOL:0)

