Author: Bo3 BulkEdit

Description: Converted Schematic - Modified by Bo3BulkEdit

Version: 3

SettingsMode: WriteDisable

IsOTGPlus: false
Tree: false
Frequency: 1
Rarity: 100
RotateRandomly: false
SpawnHeight: randomY
MaxBranchDepth: 20
ExcludedBiomes: All

MinHeight: 0
MaxHeight: 256

SourceBlocks: AIR
MaxPercentageOutsideSourceBlock: 100
OutsideSourceBlock: placeAnyway

B(0,-21,5,PLANKS:5)
B(0,-21,6,PLANKS:5)
B(-1,-21,7,PLANKS:5)
B(0,-21,7,PLANKS:5)
B(1,-21,7,PLANKS:5)
B(-1,-21,8,PLANKS:5)
B(0,-21,8,PLANKS:5)
B(1,-21,8,PLANKS:5)
B(0,-20,4,PLANKS:5)
B(-1,-20,5,PLANKS:5)
B(0,-20,5,DARK_OAK_STAIRS:3)
B(1,-20,5,PLANKS:5)
B(-1,-20,6,PLANKS:5)
B(0,-20,6,AIR:0)
B(1,-20,6,PLANKS:5)
B(-2,-20,7,PLANKS:5)
B(-1,-20,7,HAY_BLOCK:0)
B(0,-20,7,CARPET:12)
B(1,-20,7,CRAFTING_TABLE:0)
B(2,-20,7,PLANKS:5)
B(-2,-20,8,PLANKS:5)
B(-1,-20,8,HAY_BLOCK:0)
B(0,-20,8,AIR:0)
B(1,-20,8,CRAFTING_TABLE:0)
B(2,-20,8,PLANKS:5)
B(0,-19,3,PLANKS:5)
B(-1,-19,4,PLANKS:5)
B(0,-19,4,LADDER:3)
B(1,-19,4,PLANKS:5)
B(-2,-19,5,PLANKS:5)
B(-1,-19,5,AIR:0)
B(0,-19,5,AIR:0)
B(1,-19,5,HAY_BLOCK:4)
B(2,-19,5,PLANKS:5)
B(-2,-19,6,PLANKS:5)
B(-1,-19,6,AIR:0)
B(0,-19,6,AIR:0)
B(1,-19,6,HAY_BLOCK:4)
B(2,-19,6,PLANKS:5)
B(-2,-19,7,PLANKS:5)
B(-1,-19,7,AIR:0)
B(0,-19,7,AIR:0)
RB(1,-19,7,CHEST:4,../NBT/StructureLoot/ShipJunk_1.nbt,15,CHEST:4,../NBT/StructureLoot/ShipJunk_2.nbt,15,CHEST:4,../NBT/StructureLoot/ShipJunk_3.nbt,15,CHEST:4,../NBT/StructureLoot/ShipJunk_4.nbt,15,CHEST:4,../NBT/StructureLoot/ShipJunk_5.nbt,15,CHEST:4,../NBT/StructureLoot/Common1.nbt,15,CHEST:4,../NBT/StructureLoot/Common2.nbt,15,CHEST:4,../NBT/StructureLoot/Common3.nbt,15,CHEST:4,../NBT/StructureLoot/Common4.nbt,15,CHEST:4,../NBT/StructureLoot/Common5.nbt,15,CHEST:4,../NBT/StructureLoot/Common6.nbt,15,CHEST:4,../NBT/StructureLoot/Common7.nbt,15,CHEST:4,../NBT/StructureLoot/Common8.nbt,15,CHEST:4,../NBT/StructureLoot/Common9.nbt,15,CHEST:4,../NBT/StructureLoot/Common10.nbt,15,CHEST:4,../NBT/StructureLoot/Common11.nbt,15,CHEST:4,../NBT/StructureLoot/Common12.nbt,15,CHEST:4,../NBT/StructureLoot/Common13.nbt,15,CHEST:4,../NBT/StructureLoot/Common14.nbt,15,CHEST:4,../NBT/StructureLoot/Common15.nbt,100)
B(2,-19,7,PLANKS:5)
B(-3,-19,8,PLANKS:5)
B(-2,-19,8,CRAFTING_TABLE:0)
B(-1,-19,8,AIR:0)
B(0,-19,8,AIR:0)
RB(1,-19,8,CHEST:4,../NBT/StructureLoot/ShipJunk_1.nbt,15,CHEST:4,../NBT/StructureLoot/ShipJunk_2.nbt,15,CHEST:4,../NBT/StructureLoot/ShipJunk_3.nbt,15,CHEST:4,../NBT/StructureLoot/ShipJunk_4.nbt,15,CHEST:4,../NBT/StructureLoot/ShipJunk_5.nbt,15,CHEST:4,../NBT/StructureLoot/Common1.nbt,15,CHEST:4,../NBT/StructureLoot/Common2.nbt,15,CHEST:4,../NBT/StructureLoot/Common3.nbt,15,CHEST:4,../NBT/StructureLoot/Common4.nbt,15,CHEST:4,../NBT/StructureLoot/Common5.nbt,15,CHEST:4,../NBT/StructureLoot/Common6.nbt,15,CHEST:4,../NBT/StructureLoot/Common7.nbt,15,CHEST:4,../NBT/StructureLoot/Common8.nbt,15,CHEST:4,../NBT/StructureLoot/Common9.nbt,15,CHEST:4,../NBT/StructureLoot/Common10.nbt,15,CHEST:4,../NBT/StructureLoot/Common11.nbt,15,CHEST:4,../NBT/StructureLoot/Common12.nbt,15,CHEST:4,../NBT/StructureLoot/Common13.nbt,15,CHEST:4,../NBT/StructureLoot/Common14.nbt,15,CHEST:4,../NBT/StructureLoot/Common15.nbt,100)
B(2,-19,8,CRAFTING_TABLE:0)
B(3,-19,8,PLANKS:5)
B(0,-18,2,PLANKS:5)
B(-1,-18,3,PLANKS:5)
B(0,-18,3,LOG:1)
B(1,-18,3,PLANKS:5)
B(-2,-18,4,PLANKS:5)
B(-1,-18,4,AIR:0)
B(0,-18,4,LADDER:3)
B(1,-18,4,HAY_BLOCK:4)
B(2,-18,4,PLANKS:5)
B(-2,-18,5,PLANKS:5)
B(-1,-18,5,AIR:0)
B(0,-18,5,AIR:0)
B(1,-18,5,AIR:0)
B(2,-18,5,PLANKS:5)
B(-2,-18,6,PLANKS:5)
B(-1,-18,6,AIR:0)
B(0,-18,6,AIR:0)
B(1,-18,6,AIR:0)
B(2,-18,6,PLANKS:5)
B(-3,-18,7,PLANKS:5)
B(-2,-18,7,PLANKS:5)
B(-1,-18,7,AIR:0)
B(0,-18,7,AIR:0)
B(1,-18,7,AIR:0)
B(2,-18,7,PLANKS:5)
B(3,-18,7,PLANKS:5)
B(-3,-18,8,PLANKS:5)
B(-2,-18,8,WOODEN_SLAB:9)
B(-1,-18,8,WOODEN_SLAB:8)
B(0,-18,8,WOODEN_SLAB:8)
B(1,-18,8,WOODEN_SLAB:8)
B(2,-18,8,WOODEN_SLAB:9)
B(3,-18,8,PLANKS:5)
B(0,-17,2,PLANKS:5)
B(-1,-17,3,PLANKS:5)
B(0,-17,3,LOG:1)
B(1,-17,3,PLANKS:5)
B(-2,-17,4,PLANKS:5)
B(0,-17,4,LADDER:3)
RB(1,-17,4,CHEST:3,../NBT/StructureLoot/ShipJunk_1.nbt,15,CHEST:3,../NBT/StructureLoot/ShipJunk_2.nbt,15,CHEST:3,../NBT/StructureLoot/ShipJunk_3.nbt,15,CHEST:3,../NBT/StructureLoot/ShipJunk_4.nbt,15,CHEST:3,../NBT/StructureLoot/ShipJunk_5.nbt,15,CHEST:3,../NBT/StructureLoot/Common1.nbt,15,CHEST:3,../NBT/StructureLoot/Common2.nbt,15,CHEST:3,../NBT/StructureLoot/Common3.nbt,15,CHEST:3,../NBT/StructureLoot/Common4.nbt,15,CHEST:3,../NBT/StructureLoot/Common5.nbt,15,CHEST:3,../NBT/StructureLoot/Common6.nbt,15,CHEST:3,../NBT/StructureLoot/Common7.nbt,15,CHEST:3,../NBT/StructureLoot/Common8.nbt,15,CHEST:3,../NBT/StructureLoot/Common9.nbt,15,CHEST:3,../NBT/StructureLoot/Common10.nbt,15,CHEST:3,../NBT/StructureLoot/Common11.nbt,15,CHEST:3,../NBT/StructureLoot/Common12.nbt,15,CHEST:3,../NBT/StructureLoot/Common13.nbt,15,CHEST:3,../NBT/StructureLoot/Common14.nbt,15,CHEST:3,../NBT/StructureLoot/Common15.nbt,100)
B(2,-17,4,PLANKS:5)
B(-2,-17,5,PLANKS:1)
B(2,-17,5,PLANKS:1)
B(-3,-17,6,LADDER:2)
B(-2,-17,6,PLANKS:1)
B(2,-17,6,PLANKS:1)
B(3,-17,6,LADDER:2)
B(-4,-17,7,LADDER:4)
B(-3,-17,7,PLANKS:1)
B(-2,-17,7,PLANKS:5)
B(-1,-17,7,DARK_OAK_STAIRS:5)
RB(0,-17,7,WALL_BANNER:2,../NBT/Banners/small_01.nbt,20,WALL_BANNER:2,../NBT/Banners/small_02.nbt,20,WALL_BANNER:2,../NBT/Banners/small_03.nbt,20,WALL_BANNER:2,../NBT/Banners/small_04.nbt,20,WALL_BANNER:2,../NBT/Banners/small_05.nbt,100)
B(1,-17,7,DARK_OAK_STAIRS:4)
B(2,-17,7,PLANKS:5)
B(3,-17,7,PLANKS:1)
B(4,-17,7,LADDER:5)
B(-4,-17,8,LADDER:4)
B(-3,-17,8,PLANKS:1)
B(-2,-17,8,FENCE:0)
B(-1,-17,8,FENCE:0)
B(0,-17,8,FENCE:0)
B(1,-17,8,FENCE:0)
B(2,-17,8,FENCE:0)
B(3,-17,8,PLANKS:1)
B(4,-17,8,LADDER:5)
B(0,-16,2,PLANKS:5)
B(-1,-16,3,PLANKS:1)
B(0,-16,3,LOG:1)
B(1,-16,3,PLANKS:1)
B(-2,-16,4,PLANKS:1)
B(0,-16,4,LADDER:3)
B(2,-16,4,PLANKS:1)
B(-2,-16,5,PLANKS:5)
B(2,-16,5,PLANKS:5)
B(-2,-16,6,PLANKS:5)
B(2,-16,6,PLANKS:5)
B(-2,-16,7,PLANKS:5)
B(-1,-16,7,PLANKS:5)
B(0,-16,7,PLANKS:5)
B(1,-16,7,PLANKS:5)
B(2,-16,7,PLANKS:5)
B(-3,-16,8,PLANKS:5)
B(-2,-16,8,FENCE:0)
B(-1,-16,8,FENCE:0)
B(0,-16,8,FENCE:0)
B(1,-16,8,FENCE:0)
B(2,-16,8,FENCE:0)
B(3,-16,8,PLANKS:5)
B(-3,-15,-3,WOOL:0)
B(3,-15,-3,WOOL:0)
B(-4,-15,-2,WOOL:0)
B(3,-15,-2,WOOL:0)
B(-4,-15,-1,FENCE:0)
B(-3,-15,-1,FENCE:0)
B(3,-15,-1,FENCE:0)
B(-3,-15,0,FENCE:0)
B(3,-15,0,FENCE:0)
B(-3,-15,1,FENCE:0)
B(-1,-15,2,DARK_OAK_STAIRS:6)
B(0,-15,2,PLANKS:5)
B(1,-15,2,DARK_OAK_STAIRS:6)
B(-1,-15,3,PLANKS:5)
B(0,-15,3,LOG:1)
B(1,-15,3,PLANKS:5)
B(-2,-15,4,PLANKS:5)
B(-1,-15,4,DOUBLE_WOODEN_SLAB:0)
B(0,-15,4,TRAPDOOR:9)
B(1,-15,4,DOUBLE_WOODEN_SLAB:0)
B(2,-15,4,PLANKS:5)
B(-2,-15,5,PLANKS:1)
B(-1,-15,5,DOUBLE_WOODEN_SLAB:0)
B(0,-15,5,DOUBLE_WOODEN_SLAB:0)
B(1,-15,5,DOUBLE_WOODEN_SLAB:0)
B(2,-15,5,PLANKS:1)
B(-2,-15,6,PLANKS:5)
B(-1,-15,6,DOUBLE_WOODEN_SLAB:0)
B(0,-15,6,DOUBLE_WOODEN_SLAB:0)
B(1,-15,6,DOUBLE_WOODEN_SLAB:0)
B(2,-15,6,PLANKS:5)
B(-2,-15,7,PLANKS:5)
B(-1,-15,7,WOODEN_SLAB:0)
B(0,-15,7,WOODEN_SLAB:0)
B(1,-15,7,WOODEN_SLAB:0)
B(2,-15,7,PLANKS:5)
B(-3,-15,8,WOODEN_BUTTON:2)
B(-2,-15,8,PLANKS:1)
B(-1,-15,8,WOODEN_SLAB:0)
B(0,-15,8,WOODEN_SLAB:0)
B(1,-15,8,WOODEN_SLAB:0)
B(2,-15,8,PLANKS:1)
B(3,-15,8,WOODEN_BUTTON:1)
B(-2,-14,-4,WOOL:0)
B(2,-14,-4,WOOL:0)
B(-3,-14,-3,WOOL:0)
B(0,-14,0,WOODEN_SLAB:13)
B(3,-14,0,FENCE:0)
B(-3,-14,1,FENCE:0)
B(-2,-14,1,FENCE:0)
B(-1,-14,1,WOODEN_SLAB:13)
B(0,-14,1,PLANKS:5)
B(1,-14,1,WOODEN_SLAB:13)
B(2,-14,1,FENCE:0)
B(3,-14,1,FENCE:0)
B(-2,-14,2,FENCE:0)
B(-1,-14,2,PLANKS:5)
B(1,-14,2,PLANKS:5)
B(2,-14,2,FENCE:0)
B(-1,-14,3,PLANKS:1)
B(0,-14,3,LOG:1)
B(1,-14,3,PLANKS:1)
B(-2,-14,4,PLANKS:5)
B(-1,-14,4,LEVER:11)
B(0,-14,4,LADDER:3)
B(1,-14,4,LEVER:11)
B(2,-14,4,PLANKS:5)
B(-2,-14,5,PLANKS:1)
B(2,-14,5,PLANKS:1)
B(-2,-14,6,PLANKS:5)
B(2,-14,6,PLANKS:5)
B(-2,-14,7,DARK_OAK_STAIRS:3)
B(2,-14,7,DARK_OAK_STAIRS:3)
B(-2,-14,8,WOODEN_SLAB:5)
B(2,-14,8,WOODEN_SLAB:5)
B(-1,-13,-5,WOOL:0)
B(0,-13,-5,WOOL:14)
B(1,-13,-5,WOOL:0)
B(-2,-13,-4,WOOL:0)
B(2,-13,-4,WOOL:0)
B(0,-13,-1,DARK_OAK_STAIRS:6)
B(-1,-13,0,WOODEN_SLAB:9)
B(0,-13,0,PLANKS:5)
B(1,-13,0,WOODEN_SLAB:9)
B(-1,-13,1,PLANKS:1)
B(1,-13,1,PLANKS:1)
B(-2,-13,2,FENCE:0)
B(-1,-13,2,PLANKS:1)
B(1,-13,2,PLANKS:1)
B(2,-13,2,FENCE:0)
B(-2,-13,3,PLANKS:5)
B(-1,-13,3,LIT_REDSTONE_LAMP:0)
B(0,-13,3,LOG:1)
B(1,-13,3,LIT_REDSTONE_LAMP:0)
B(2,-13,3,PLANKS:5)
B(-2,-13,4,PLANKS:1)
B(0,-13,4,LADDER:3)
B(1,-13,4,AIR)
B(2,-13,4,PLANKS:1)
B(-3,-13,5,FENCE:0)
B(-2,-13,5,PLANKS:1)
B(2,-13,5,PLANKS:1)
B(4,-13,5,FENCE:0)
B(-2,-13,6,PLANKS:5)
B(-1,-13,6,DARK_OAK_STAIRS:5)
B(1,-13,6,DARK_OAK_STAIRS:4)
B(2,-13,6,PLANKS:5)
B(3,-13,6,FENCE:0)
B(4,-13,6,FENCE:0)
B(-1,-12,-5,WOOL:14)
B(0,-12,-5,WOOL:14)
B(-2,-12,-4,WOOL:0)
B(1,-12,-4,WOOL:14)
B(0,-12,-1,PLANKS:5)
B(-1,-12,0,PLANKS:5)
B(0,-12,0,WOODEN_SLAB:8)
B(1,-12,0,PLANKS:5)
B(-2,-12,1,WOODEN_SLAB:13)
B(-1,-12,1,PLANKS:5)
B(0,-12,1,WOODEN_SLAB:8)
B(1,-12,1,PLANKS:5)
B(2,-12,1,WOODEN_SLAB:13)
B(-3,-12,2,WOODEN_BUTTON:2)
B(-2,-12,2,PLANKS:5)
B(-1,-12,2,DOUBLE_WOODEN_SLAB:0)
B(0,-12,2,WOODEN_SLAB:8)
B(1,-12,2,DOUBLE_WOODEN_SLAB:0)
B(2,-12,2,PLANKS:5)
B(3,-12,2,WOODEN_BUTTON:1)
B(-3,-12,3,WOODEN_BUTTON:2)
B(-2,-12,3,PLANKS:5)
B(-1,-12,3,WOODEN_SLAB:8)
B(0,-12,3,LOG:1)
B(1,-12,3,WOODEN_SLAB:8)
B(2,-12,3,PLANKS:5)
B(3,-12,3,WOODEN_BUTTON:1)
B(-5,-12,4,FENCE:0)
B(-4,-12,4,FENCE:0)
B(-3,-12,4,WOODEN_BUTTON:2)
B(-2,-12,4,PLANKS:5)
B(-1,-12,4,WOODEN_SLAB:8)
B(0,-12,4,LADDER:3)
B(1,-12,4,WOODEN_SLAB:8)
B(2,-12,4,PLANKS:5)
B(3,-12,4,WOODEN_BUTTON:1)
B(5,-12,4,FENCE:0)
B(6,-12,4,FENCE:0)
B(-4,-12,5,FENCE:0)
B(-3,-12,5,FENCE:0)
B(-2,-12,5,PLANKS:5)
B(-1,-12,5,WOODEN_SLAB:8)
B(0,-12,5,WOODEN_SLAB:8)
B(1,-12,5,WOODEN_SLAB:8)
B(2,-12,5,PLANKS:5)
B(3,-12,5,WOODEN_BUTTON:1)
B(4,-12,5,FENCE:0)
B(5,-12,5,FENCE:0)
B(-3,-12,6,WOODEN_BUTTON:2)
B(-2,-12,6,PLANKS:5)
B(-1,-12,6,PLANKS:5)
B(0,-12,6,PLANKS:5)
B(1,-12,6,PLANKS:5)
B(2,-12,6,PLANKS:5)
B(3,-12,6,WOODEN_BUTTON:1)
B(-2,-11,-5,WOOL:0)
B(-1,-11,-5,WOOL:0)
B(0,-11,-4,WOOL:14)
B(1,-11,-4,WOOL:0)
B(2,-11,-3,WOOL:0)
B(0,-11,-1,WOODEN_SLAB:13)
B(-1,-11,0,FENCE:0)
B(0,-11,0,DOUBLE_WOODEN_SLAB:5)
B(1,-11,0,FENCE:0)
B(-2,-11,1,FENCE:0)
B(-1,-11,1,FENCE:0)
B(0,-11,1,WOODEN_SLAB:5)
B(1,-11,1,FENCE:0)
B(2,-11,1,FENCE:0)
B(-2,-11,2,FENCE:0)
B(2,-11,2,FENCE:0)
B(-6,-11,3,FENCE:0)
B(-5,-11,3,FENCE:0)
B(-2,-11,3,FENCE:0)
B(0,-11,3,LOG:0)
B(2,-11,3,FENCE:0)
B(-5,-11,4,FENCE:0)
B(-2,-11,4,FENCE:0)
B(0,-11,4,TRAPDOOR:1)
B(2,-11,4,FENCE:0)
B(6,-11,4,WOOL:0)
B(-2,-11,5,FENCE:0)
B(2,-11,5,FENCE:0)
B(-2,-11,6,FENCE:0)
B(-1,-11,6,FENCE:0)
B(0,-11,6,FENCE:0)
B(1,-11,6,FENCE:0)
B(2,-11,6,FENCE:0)
B(-7,-11,8,WOOL:0)
B(-6,-11,8,WOOL:0)
B(-5,-11,8,WOOL:0)
B(-2,-10,-6,WOOL:0)
B(-2,-10,-5,FENCE:0)
B(2,-10,-4,WOOL:0)
B(2,-10,-3,FENCE:0)
B(3,-10,-3,WOOL:0)
B(0,-10,-2,DOUBLE_WOODEN_SLAB:5)
B(3,-10,-2,WOOL:0)
B(0,-10,-1,WOODEN_SLAB:5)
B(-5,-10,0,WOOL:0)
B(-4,-10,0,WOOL:0)
B(-3,-10,0,WOOL:0)
B(-2,-10,0,WOOL:0)
B(-5,-10,1,WOOL:0)
B(-5,-10,2,WOOL:0)
B(2,-10,2,WOOL:0)
B(3,-10,2,WOOL:0)
B(4,-10,2,WOOL:0)
B(-6,-10,3,WOOL:0)
B(0,-10,3,LOG:1)
B(5,-10,3,WOOL:0)
B(-7,-10,7,WOOL:0)
B(-6,-10,7,WOOL:0)
B(-5,-10,7,WOOL:0)
B(-4,-10,8,WOOL:0)
B(-3,-10,8,WOOL:0)
B(-2,-10,8,WOOL:0)
RB(0,-9,-6,WALL_BANNER:2,../NBT/Banners/small_01.nbt,20,WALL_BANNER:2,../NBT/Banners/small_02.nbt,20,WALL_BANNER:2,../NBT/Banners/small_03.nbt,20,WALL_BANNER:2,../NBT/Banners/small_04.nbt,20,WALL_BANNER:2,../NBT/Banners/small_05.nbt,100)
B(-2,-9,-5,WOODEN_SLAB:5)
B(0,-9,-5,WOODEN_SLAB:13)
B(-1,-9,-4,WOODEN_SLAB:5)
B(0,-9,-4,DOUBLE_WOODEN_SLAB:5)
B(1,-9,-4,WOODEN_SLAB:5)
B(0,-9,-3,WOODEN_SLAB:5)
B(2,-9,-3,WOODEN_SLAB:5)
B(-5,-9,-1,WOOL:0)
B(-4,-9,-1,WOOL:0)
B(-3,-9,-1,WOOL:0)
B(-2,-9,-1,WOOL:0)
B(-1,-9,0,WOOL:0)
B(0,-9,0,WOOL:0)
B(1,-9,0,WOOL:0)
B(2,-9,1,WOOL:0)
B(3,-9,1,WOOL:0)
B(4,-9,1,WOOL:0)
B(5,-9,2,WOOL:0)
B(0,-9,3,LOG:1)
B(-7,-9,6,WOOL:0)
B(-6,-9,6,WOOL:0)
B(-5,-9,6,WOOL:0)
B(-4,-9,7,WOOL:0)
B(-3,-9,7,WOOL:0)
B(-2,-9,7,WOOL:0)
B(-1,-9,8,WOOL:14)
B(0,-9,8,WOOL:14)
B(1,-9,8,WOOL:14)
B(0,-8,-7,WOODEN_SLAB:13)
B(0,-8,-6,DOUBLE_WOODEN_SLAB:5)
B(0,-8,-5,WOODEN_SLAB:5)
B(-4,-8,-2,WOOL:0)
B(-3,-8,-2,WOOL:0)
B(-2,-8,-2,WOOL:0)
B(-5,-8,-1,WOOL:0)
B(-1,-8,-1,WOOL:14)
B(0,-8,-1,WOOL:14)
B(1,-8,0,WOOL:14)
B(2,-8,0,WOOL:0)
B(3,-8,0,WOOL:0)
B(4,-8,1,WOOL:0)
B(0,-8,3,LOG:1)
B(-6,-8,6,WOOL:0)
B(-5,-8,6,WOOL:0)
B(-4,-8,6,WOOL:0)
B(-3,-8,7,WOOL:0)
B(-2,-8,7,WOOL:0)
B(-1,-8,7,WOOL:0)
B(0,-8,7,WOOL:14)
B(1,-8,8,WOOL:0)
B(2,-8,8,WOOL:0)
B(3,-8,8,WOOL:0)
B(0,-7,-6,FENCE:0)
B(0,-7,-5,FENCE:0)
B(-4,-7,-2,WOOL:0)
B(-3,-7,-2,WOOL:0)
B(-2,-7,-2,WOOL:14)
B(-1,-7,-1,WOOL:0)
B(0,-7,-1,WOOL:14)
B(1,-7,-1,WOOL:0)
B(2,-7,0,WOOL:14)
B(3,-7,0,WOOL:0)
B(4,-7,0,WOOL:0)
B(0,-7,3,LOG:0)
B(-6,-7,5,WOOL:0)
B(-5,-7,5,WOOL:0)
B(-4,-7,6,WOOL:0)
B(-3,-7,6,WOOL:14)
B(-2,-7,6,WOOL:0)
B(-1,-7,7,WOOL:0)
B(0,-7,7,WOOL:14)
B(1,-7,7,WOOL:0)
B(2,-7,8,WOOL:0)
B(3,-7,8,WOOL:14)
B(4,-7,8,WOOL:0)
B(0,-6,-5,FENCE:0)
B(0,-6,-4,FENCE:0)
B(-4,-6,-2,WOOL:0)
B(-3,-6,-2,WOOL:0)
B(-2,-6,-1,WOOL:14)
B(-1,-6,-1,WOOL:14)
B(0,-6,-1,WOOL:14)
B(1,-6,0,WOOL:14)
B(2,-6,0,WOOL:14)
B(3,-6,0,WOOL:0)
B(4,-6,0,WOOL:0)
B(0,-6,3,LOG:1)
B(-5,-6,5,WOOL:0)
B(-4,-6,6,WOOL:0)
B(-3,-6,6,WOOL:14)
B(-2,-6,6,WOOL:14)
B(-1,-6,7,WOOL:14)
B(0,-6,7,WOOL:14)
B(1,-6,7,WOOL:14)
B(2,-6,7,WOOL:14)
B(3,-6,8,WOOL:14)
B(4,-6,8,WOOL:0)
B(5,-6,8,WOOL:0)
B(0,-5,-4,FENCE:0)
B(0,-5,-3,FENCE:0)
B(-4,-5,-1,WOOL:0)
B(-3,-5,-1,WOOL:0)
B(-2,-5,-1,WOOL:14)
B(-1,-5,-1,WOOL:0)
B(-1,-5,0,WOOL:0)
B(0,-5,0,WOOL:14)
B(1,-5,0,WOOL:0)
B(2,-5,0,WOOL:14)
B(3,-5,1,WOOL:0)
B(4,-5,1,WOOL:0)
B(0,-5,3,LOG:1)
B(-5,-5,5,WOOL:0)
B(-4,-5,6,WOOL:0)
B(-3,-5,6,WOOL:14)
B(-2,-5,6,WOOL:0)
B(-1,-5,7,WOOL:0)
B(0,-5,7,WOOL:14)
B(1,-5,7,WOOL:0)
B(2,-5,7,WOOL:0)
B(3,-5,8,WOOL:14)
B(4,-5,8,WOOL:0)
B(0,-4,-3,FENCE:0)
B(0,-4,-2,FENCE:0)
B(-4,-4,-1,WOOL:0)
B(-3,-4,-1,WOOL:0)
B(-2,-4,-1,WOOL:0)
B(-1,-4,0,WOOL:14)
B(0,-4,0,WOOL:14)
B(1,-4,0,WOOL:14)
B(2,-4,1,WOOL:0)
B(3,-4,1,WOOL:0)
B(4,-4,1,WOOL:0)
B(5,-4,1,WOOL:0)
B(0,-4,3,LOG:1)
B(-6,-4,5,WOOL:0)
B(-5,-4,6,WOOL:0)
B(-4,-4,6,WOOL:0)
B(-3,-4,6,WOOL:0)
B(-2,-4,7,WOOL:0)
B(-1,-4,7,WOOL:0)
B(0,-4,7,WOOL:14)
B(1,-4,8,WOOL:0)
B(2,-4,8,WOOL:0)
B(3,-4,8,WOOL:0)
B(0,-3,-2,FENCE:0)
B(-5,-3,-1,WOOL:0)
B(-4,-3,-1,WOOL:0)
B(0,-3,-1,FENCE:0)
B(-3,-3,0,WOOL:0)
B(-2,-3,0,WOOL:0)
B(-4,-3,1,FENCE:0)
B(-3,-3,1,FENCE:0)
B(-2,-3,1,FENCE:0)
B(2,-3,2,WOOL:0)
B(3,-3,2,WOOL:0)
B(4,-3,2,WOOL:0)
B(5,-3,2,WOOL:0)
B(0,-3,3,LOG:0)
B(2,-3,3,FENCE:0)
B(3,-3,3,FENCE:0)
B(4,-3,3,FENCE:0)
B(-7,-3,6,WOOL:0)
B(-6,-3,6,WOOL:0)
B(-5,-3,6,WOOL:0)
B(-4,-3,7,WOOL:0)
B(-3,-3,7,WOOL:0)
B(-2,-3,7,WOOL:0)
B(-1,-3,8,WOOL:14)
B(0,-3,8,WOOL:14)
B(1,-3,8,WOOL:14)
B(2,-3,8,WOOL:0)
B(0,-2,-1,FENCE:0)
B(-5,-2,0,WOOL:0)
B(-4,-2,0,STONE_BUTTON:4)
B(-3,-2,0,STONE_BUTTON:4)
B(-2,-2,0,STONE_BUTTON:4)
B(0,-2,0,FENCE:0)
B(-5,-2,1,WOOL:0)
B(-4,-2,1,LOG:5)
B(-3,-2,1,LOG:5)
B(-2,-2,1,LOG:5)
B(-1,-2,1,STONE_BUTTON:4)
B(0,-2,1,STONE_BUTTON:4)
B(1,-2,1,STONE_BUTTON:4)
B(-6,-2,2,WOOL:0)
B(-1,-2,2,LOG:5)
B(0,-2,2,LOG:5)
B(1,-2,2,LOG:5)
B(2,-2,2,STONE_BUTTON:4)
B(3,-2,2,STONE_BUTTON:4)
B(4,-2,2,STONE_BUTTON:4)
B(0,-2,3,LOG:1)
B(2,-2,3,LOG:5)
B(3,-2,3,LOG:5)
B(4,-2,3,LOG:5)
B(5,-2,3,WOOL:0)
B(6,-2,4,WOOL:0)
B(6,-2,5,WOOL:0)
B(-7,-2,7,WOOL:0)
B(-6,-2,7,WOOL:0)
B(-5,-2,7,WOOL:0)
B(-6,-2,8,FENCE:0)
B(-5,-2,8,FENCE:0)
B(-4,-2,8,WOOL:0)
B(-3,-2,8,WOOL:0)
B(0,-1,0,FENCE:0)
B(0,-1,1,FENCE:0)
B(0,-1,3,LOG:1)
B(-6,-1,7,STONE_BUTTON:4)
B(-5,-1,7,STONE_BUTTON:4)
B(-7,-1,8,WOOL:0)
B(-6,-1,8,LOG:5)
B(-5,-1,8,LOG:5)
B(-4,-1,8,STONE_BUTTON:4)
B(-3,-1,8,STONE_BUTTON:4)
B(-2,-1,8,STONE_BUTTON:4)
B(0,0,1,FENCE:0)
B(0,0,2,FENCE:0)
B(0,0,3,LOG:1)
B(0,0,4,FENCE:0)
B(0,0,5,FENCE:0)
B(-3,0,7,WOOL:0)
B(-4,0,8,WOOL:0)
B(-2,0,8,WOOL:0)
B(-1,0,8,WOOL:0)
B(0,1,3,DARK_OAK_FENCE:0)
B(0,1,5,FENCE:0)
B(0,1,6,FENCE:0)
B(-3,1,7,WOOL:0)
B(-2,1,7,WOOL:0)
B(-1,1,7,WOOL:0)
B(0,1,8,WOOL:14)
B(1,1,8,WOOL:0)
B(2,1,8,WOOL:0)
B(0,2,3,DARK_OAK_FENCE:0)
B(0,2,6,FENCE:0)
B(-3,2,7,WOOL:0)
B(-2,2,7,WOOL:0)
B(0,2,7,FENCE:0)
B(-1,2,8,WOOL:14)
B(0,2,8,WOOL:14)
B(1,2,8,WOOL:14)
B(0,3,3,DARK_OAK_FENCE:0)
B(-3,3,7,WOOL:0)
B(0,3,7,FENCE:0)
B(-4,3,8,WOOL:0)
B(-2,3,8,WOOL:0)
B(0,3,8,FENCE:0)
RB(0,4,3,STANDING_BANNER:10,../NBT/Banners/small_01.nbt,20,STANDING_BANNER:10,../NBT/Banners/small_02.nbt,20,STANDING_BANNER:10,../NBT/Banners/small_03.nbt,20,STANDING_BANNER:10,../NBT/Banners/small_04.nbt,20,STANDING_BANNER:10,../NBT/Banners/small_05.nbt,100)
B(-3,4,8,STONE_BUTTON:4)
B(-2,4,8,STONE_BUTTON:4)
B(0,4,8,FENCE:0)

E(1,-13,4,VILLAGER,1)

