
#######################################################################
# +-----------------------------------------------------------------+ #
# |                            BO4 object                           | #
# +-----------------------------------------------------------------+ #
#######################################################################

Author: NLBlackEagle

Description: No description given

SettingsMode: WriteWithoutComments


#######################################################################
# +-----------------------------------------------------------------+ #
# |                          Main settings                          | #
# +-----------------------------------------------------------------+ #
#######################################################################

Frequency: 0

SpawnHeight: highestBlock

UseCenterForHighestBlock: true

##############################
# Height Limits for the BO4. #
##############################

MinHeight: 0

MaxHeight: 255

InheritBO3: 

InheritBO3Rotation: NORTH

OverrideChildSettings: true

OverrideParentHeight: false

CanOverride: false

BranchFrequency: 0

BranchFrequencyGroup: 

MustBeBelowOther: false

MustBeInside: 

CannotBeInside: 

ReplacesBO3: 

MustBeInsideWorldBorders: false

CanSpawnOnWater: true

SpawnOnWaterOnly: false

SpawnUnderWater: false

SpawnAtWaterLevel: false

HeightOffset: 0

RemoveAir: true

ReplaceAbove: 

ReplaceBelow: 

ReplaceWithBiomeBlocks: true

ReplaceWithSurfaceBlock: GRASS

ReplaceWithGroundBlock: DIRT

ReplaceWithStoneBlock: STONE

SmoothRadius: 0

SmoothHeightOffset: 0

SmoothStartTop: false

SmoothStartWood: false

SmoothingSurfaceBlock: 

SmoothingGroundBlock: 

BO3Group: 

IsSpawnPoint: false

DoReplaceBlocks: true


#######################################################################
# +-----------------------------------------------------------------+ #
# |                              Blocks                             | #
# +-----------------------------------------------------------------+ #
#######################################################################

Block(-5,53,-7,STONE:5)
Block(-5,53,-6,STONE:5)
Block(-5,53,-5,STONE:5)
Block(-5,54,-7,STONE:5)
Block(-5,54,-6,STONE:5)
Block(-5,54,-5,STONE:5)
Block(-5,54,-4,STONE:5)
Block(-5,55,-7,STONE:5)
Block(-5,55,-6,STONE:5)
Block(-5,55,-5,STONE:5)
Block(-5,55,-4,STONE:5)
Block(-5,56,-7,STONE:5)
Block(-5,56,-6,STONE:5)
Block(-5,56,-5,STONE:5)
Block(-5,56,-4,STONE:5)
Block(-5,57,-7,STONE:5)
Block(-5,57,-6,STONE:5)
Block(-5,57,-5,STONE:5)
Block(-4,52,-7,STONE:5)
Block(-4,52,-6,STONE:5)
Block(-4,52,-5,STONE:5)
Block(-4,52,-4,STONE:5)
Block(-4,52,-3,STONE:5)
Block(-4,52,-2,STONE:5)
Block(-4,52,-1,STONE:5)
Block(-4,52,0,STONE:5)
Block(-4,53,-7,STONE:5)
Block(-4,53,-6,STONE:5)
Block(-4,53,-5,STONE:5)
Block(-4,53,-4,STONE:5)
Block(-4,53,-3,STONE:5)
Block(-4,53,-2,STONE:5)
Block(-4,53,-1,STONE:5)
Block(-4,53,0,STONE:5)
Block(-4,53,1,STONE:5)
Block(-4,54,-7,STONE:5)
Block(-4,54,-6,STONE:5)
Block(-4,54,-5,STONE:5)
Block(-4,54,-4,STONE:5)
Block(-4,54,-3,STONE:5)
Block(-4,54,-2,STONE:5)
Block(-4,54,-1,STONE:5)
Block(-4,54,0,STONE:5)
Block(-4,54,1,STONE:5)
Block(-4,55,-7,STONE:5)
Block(-4,55,-6,STONE:5)
Block(-4,55,-5,STONE:5)
Block(-4,55,-4,STONE:5)
Block(-4,55,-3,STONE:5)
Block(-4,55,-2,STONE:5)
Block(-4,55,-1,STONE:5)
Block(-4,55,0,STONE:5)
Block(-4,55,1,STONE:5)
Block(-4,56,-7,STONE:5)
Block(-4,56,-6,STONE:5)
Block(-4,56,-5,STONE:5)
Block(-4,56,-4,STONE:5)
Block(-4,56,-3,STONE:5)
Block(-4,56,-2,STONE:5)
Block(-4,56,-1,STONE:5)
Block(-4,56,0,STONE:5)
Block(-4,56,1,STONE:3)
Block(-4,57,-7,STONE:5)
Block(-4,57,-6,STONE:5)
Block(-4,57,-5,STONE:5)
Block(-4,57,-4,STONE:5)
Block(-4,57,-3,STONE:5)
Block(-4,57,-2,STONE:5)
Block(-4,57,-1,STONE:3)
Block(-4,57,0,STONE:3)
Block(-4,58,-7,STONE:5)
Block(-4,58,-6,STONE:5)
Block(-4,58,-5,STONE:5)
Block(-4,58,-4,STONE:5)
Block(-3,50,-4,STONE:5)
Block(-3,51,-7,STONE:5)
Block(-3,51,-6,STONE:5)
Block(-3,51,-5,STONE:5)
Block(-3,51,-4,STONE:5)
Block(-3,51,-3,STONE:5)
Block(-3,51,-2,STONE:5)
Block(-3,51,-1,STONE:5)
Block(-3,51,0,STONE:5)
Block(-3,51,1,STONE:5)
Block(-3,52,-7,STONE:5)
Block(-3,52,-6,STONE:5)
Block(-3,52,-5,STONE:5)
Block(-3,52,-4,STONE:5)
Block(-3,52,-3,STONE:5)
Block(-3,52,-2,STONE:5)
Block(-3,52,-1,STONE:5)
Block(-3,52,0,STONE:5)
Block(-3,52,1,STONE:5)
Block(-3,52,2,STONE:5)
Block(-3,53,-7,STONE:5)
Block(-3,53,-6,STONE:5)
Block(-3,53,-5,STONE:5)
Block(-3,53,-4,STONE:5)
Block(-3,53,-3,STONE:5)
Block(-3,53,-2,STONE:5)
Block(-3,53,-1,STONE:5)
Block(-3,53,0,STONE:5)
Block(-3,53,1,STONE:5)
Block(-3,53,2,STONE:5)
Block(-3,53,3,STONE:5)
Block(-3,54,-7,STONE:5)
Block(-3,54,-6,STONE:5)
Block(-3,54,-5,STONE:5)
Block(-3,54,-4,STONE:5)
Block(-3,54,-3,STONE:5)
Block(-3,54,-2,STONE:5)
Block(-3,54,-1,STONE:5)
Block(-3,54,0,STONE:5)
Block(-3,54,1,STONE:5)
Block(-3,54,2,STONE:5)
Block(-3,55,-7,STONE:5)
Block(-3,55,-6,STONE:5)
Block(-3,55,-5,STONE:5)
Block(-3,55,-4,STONE:5)
Block(-3,55,-3,STONE:5)
Block(-3,55,-2,STONE:5)
Block(-3,55,-1,STONE:5)
Block(-3,55,0,STONE:5)
Block(-3,55,1,STONE:3)
Block(-3,55,2,STONE:3)
Block(-3,56,-7,STONE:5)
Block(-3,56,-6,STONE:5)
Block(-3,56,-5,STONE:5)
Block(-3,56,-4,STONE:5)
Block(-3,56,-3,STONE:5)
Block(-3,56,-2,STONE:5)
Block(-3,56,-1,STONE:3)
Block(-3,56,0,STONE:3)
Block(-3,56,1,STONE:3)
Block(-3,56,2,STONE:3)
Block(-3,57,-7,STONE:5)
Block(-3,57,-6,STONE:5)
Block(-3,57,-5,STONE:5)
Block(-3,57,-4,STONE:5)
Block(-3,57,-3,STONE:5)
Block(-3,57,-2,STONE:3)
Block(-3,57,-1,STONE:3)
Block(-3,57,0,STONE:3)
Block(-3,57,1,STONE:3)
Block(-3,57,2,STONE:3)
Block(-3,58,-7,STONE:5)
Block(-3,58,-6,STONE:5)
Block(-3,58,-5,STONE:5)
Block(-3,58,-4,STONE:5)
Block(-3,58,-3,STONE:3)
Block(-3,58,-2,STONE:3)
Block(-3,58,-1,STONE:3)
Block(-3,58,0,STONE:3)
Block(-3,58,1,STONE:3)
Block(-3,59,-7,STONE:5)
Block(-3,59,-6,STONE:5)
Block(-3,59,-5,STONE:5)
Block(-3,59,-4,STONE:5)
Block(-3,59,-3,STONE:3)
Block(-2,49,-4,STONE:5)
Block(-2,49,-1,STONE:5)
Block(-2,50,-6,STONE:5)
Block(-2,50,-5,STONE:5)
Block(-2,50,-4,STONE:5)
Block(-2,50,-3,STONE:5)
Block(-2,50,-2,STONE:5)
Block(-2,50,-1,STONE:5)
Block(-2,50,0,STONE:5)
Block(-2,50,1,STONE:5)
Block(-2,51,-7,STONE:5)
Block(-2,51,-6,STONE:5)
Block(-2,51,-5,STONE:5)
Block(-2,51,-4,STONE:5)
Block(-2,51,-3,STONE:5)
Block(-2,51,-2,STONE:5)
Block(-2,51,-1,STONE:5)
Block(-2,51,0,STONE:5)
Block(-2,51,1,STONE:5)
Block(-2,51,2,STONE:5)
Block(-2,52,-7,STONE:5)
Block(-2,52,-6,STONE:5)
Block(-2,52,-5,STONE:5)
Block(-2,52,-4,STONE:5)
Block(-2,52,-3,STONE:5)
Block(-2,52,-2,STONE:5)
Block(-2,52,-1,STONE:5)
Block(-2,52,0,STONE:5)
Block(-2,52,1,STONE:5)
Block(-2,52,2,STONE:5)
Block(-2,52,3,STONE:5)
Block(-2,52,4,STONE:5)
Block(-2,53,-7,STONE:5)
Block(-2,53,-6,STONE:5)
Block(-2,53,-5,STONE:5)
Block(-2,53,-4,STONE:5)
Block(-2,53,-3,STONE:5)
Block(-2,53,-2,STONE:5)
Block(-2,53,-1,STONE:5)
Block(-2,53,0,STONE:5)
Block(-2,53,1,STONE:5)
Block(-2,53,2,STONE:5)
Block(-2,53,3,STONE:5)
Block(-2,53,4,STONE:5)
Block(-2,53,5,STONE:5)
Block(-2,54,-7,STONE:5)
Block(-2,54,-6,STONE:5)
Block(-2,54,-5,STONE:5)
Block(-2,54,-4,STONE:5)
Block(-2,54,-3,STONE:5)
Block(-2,54,-2,STONE:5)
Block(-2,54,-1,STONE:5)
Block(-2,54,0,STONE:5)
Block(-2,54,1,STONE:5)
Block(-2,54,2,STONE:3)
Block(-2,54,3,STONE:3)
Block(-2,54,4,STONE:3)
Block(-2,54,5,STONE:5)
Block(-2,54,6,STONE:5)
Block(-2,55,-7,STONE:5)
Block(-2,55,-6,STONE:5)
Block(-2,55,-5,STONE:5)
Block(-2,55,-4,STONE:5)
Block(-2,55,-3,STONE:5)
Block(-2,55,-2,STONE:5)
Block(-2,55,-1,STONE:5)
Block(-2,55,0,STONE:3)
Block(-2,55,1,STONE:3)
Block(-2,55,2,STONE:3)
Block(-2,55,3,STONE:3)
Block(-2,55,4,STONE:3)
Block(-2,55,5,STONE:3)
Block(-2,55,6,STONE:3)
Block(-2,56,-7,STONE:5)
Block(-2,56,-6,STONE:5)
Block(-2,56,-5,STONE:5)
Block(-2,56,-4,STONE:5)
Block(-2,56,-3,STONE:5)
Block(-2,56,-2,STONE:3)
Block(-2,56,-1,STONE:3)
Block(-2,56,0,STONE:3)
Block(-2,56,1,STONE:3)
Block(-2,56,2,STONE:3)
Block(-2,56,3,STONE:3)
Block(-2,56,4,STONE:3)
Block(-2,56,5,STONE:3)
Block(-2,56,6,STONE:3)
Block(-2,57,-7,STONE:5)
Block(-2,57,-6,STONE:5)
Block(-2,57,-5,STONE:5)
Block(-2,57,-4,STONE:5)
Block(-2,57,-3,STONE:3)
Block(-2,57,-2,STONE:3)
Block(-2,57,-1,STONE:3)
Block(-2,57,0,STONE:3)
Block(-2,57,1,STONE:3)
Block(-2,57,2,STONE:3)
Block(-2,57,3,STONE:3)
Block(-2,57,4,STONE:3)
Block(-2,57,5,STONE:3)
Block(-2,58,-7,STONE:5)
Block(-2,58,-6,STONE:5)
Block(-2,58,-5,STONE:5)
Block(-2,58,-4,STONE:5)
Block(-2,58,-3,STONE:3)
Block(-2,58,-2,STONE:3)
Block(-2,58,-1,STONE:3)
Block(-2,58,0,STONE:3)
Block(-2,58,1,STONE:3)
Block(-2,58,2,STONE:3)
Block(-2,59,-7,STONE:5)
Block(-2,59,-6,STONE:5)
Block(-2,59,-5,STONE:5)
Block(-2,59,-4,STONE:3)
Block(-2,59,-3,STONE:3)
Block(-2,59,-2,STONE:3)
Block(-2,59,-1,STONE:3)
Block(-2,59,1,STONE:3)
Block(-2,60,-7,STONE:5)
Block(-2,60,-6,STONE:5)
Block(-2,60,-5,STONE:5)
Block(-1,48,-2,STONE:5)
Block(-1,49,-4,STONE:5)
Block(-1,49,-3,STONE:5)
Block(-1,49,-2,STONE:5)
Block(-1,49,-1,STONE:5)
Block(-1,50,-7,STONE:5)
Block(-1,50,-6,STONE:5)
Block(-1,50,-5,STONE:5)
Block(-1,50,-4,STONE:5)
Block(-1,50,-3,STONE:5)
Block(-1,50,-2,STONE:5)
Block(-1,50,-1,STONE:5)
Block(-1,50,0,STONE:5)
Block(-1,50,1,STONE:5)
Block(-1,51,-7,STONE:5)
Block(-1,51,-6,STONE:5)
Block(-1,51,-5,STONE:5)
Block(-1,51,-4,STONE:5)
Block(-1,51,-3,STONE:5)
Block(-1,51,-2,STONE:5)
Block(-1,51,-1,STONE:5)
Block(-1,51,0,STONE:5)
Block(-1,51,1,STONE:5)
Block(-1,51,2,STONE:5)
Block(-1,51,3,STONE:5)
Block(-1,51,4,STONE:5)
Block(-1,52,-7,STONE:5)
Block(-1,52,-6,STONE:5)
Block(-1,52,-5,STONE:5)
Block(-1,52,-4,STONE:5)
Block(-1,52,-3,STONE:5)
Block(-1,52,-2,STONE:5)
Block(-1,52,-1,STONE:5)
Block(-1,52,0,STONE:5)
Block(-1,52,1,STONE:5)
Block(-1,52,2,STONE:5)
Block(-1,52,3,STONE:5)
Block(-1,52,4,STONE:5)
Block(-1,52,5,STONE:5)
Block(-1,52,6,STONE:5)
Block(-1,53,-7,STONE:5)
Block(-1,53,-6,STONE:5)
Block(-1,53,-5,STONE:5)
Block(-1,53,-4,STONE:5)
Block(-1,53,-3,STONE:5)
Block(-1,53,-2,STONE:5)
Block(-1,53,-1,STONE:5)
Block(-1,53,0,STONE:5)
Block(-1,53,1,STONE:5)
Block(-1,53,2,STONE:5)
Block(-1,53,3,STONE:5)
Block(-1,53,4,STONE:5)
Block(-1,53,5,STONE:5)
Block(-1,53,6,STONE:5)
Block(-1,53,7,STONE:5)
Block(-1,54,-7,STONE:5)
Block(-1,54,-6,STONE:5)
Block(-1,54,-5,STONE:5)
Block(-1,54,-4,STONE:5)
Block(-1,54,-3,STONE:5)
Block(-1,54,-2,STONE:5)
Block(-1,54,-1,STONE:5)
Block(-1,54,0,STONE:5)
Block(-1,54,1,STONE:3)
Block(-1,54,2,STONE:3)
Block(-1,54,3,STONE:3)
Block(-1,54,4,STONE:3)
Block(-1,54,5,STONE:3)
Block(-1,54,6,STONE:5)
Block(-1,54,7,STONE:3)
Block(-1,55,-7,STONE:5)
Block(-1,55,-6,STONE:5)
Block(-1,55,-5,STONE:5)
Block(-1,55,-4,STONE:5)
Block(-1,55,-3,STONE:5)
Block(-1,55,-2,STONE:5)
Block(-1,55,-1,STONE:3)
Block(-1,55,0,STONE:3)
Block(-1,55,1,STONE:3)
Block(-1,55,2,STONE:3)
Block(-1,55,3,STONE:3)
Block(-1,55,4,STONE:3)
Block(-1,55,5,STONE:3)
Block(-1,55,6,STONE:3)
Block(-1,55,7,STONE:3)
Block(-1,56,-7,STONE:5)
Block(-1,56,-6,STONE:5)
Block(-1,56,-5,STONE:5)
Block(-1,56,-4,STONE:5)
Block(-1,56,-3,STONE:5)
Block(-1,56,-2,STONE:3)
Block(-1,56,-1,STONE:3)
Block(-1,56,0,STONE:3)
Block(-1,56,1,STONE:3)
Block(-1,56,2,STONE:3)
Block(-1,56,3,STONE:3)
Block(-1,56,4,STONE:3)
Block(-1,56,5,STONE:3)
Block(-1,56,6,STONE:3)
Block(-1,56,7,STONE:3)
Block(-1,57,-7,STONE:5)
Block(-1,57,-6,STONE:5)
Block(-1,57,-5,STONE:5)
Block(-1,57,-4,STONE:5)
Block(-1,57,-3,STONE:3)
Block(-1,57,-2,STONE:3)
Block(-1,57,-1,STONE:3)
Block(-1,57,0,STONE:3)
Block(-1,57,1,STONE:3)
Block(-1,57,2,STONE:3)
Block(-1,57,3,STONE:3)
Block(-1,57,4,STONE:3)
Block(-1,57,5,STONE:3)
Block(-1,57,6,STONE:3)
Block(-1,57,7,STONE:3)
Block(-1,58,-7,STONE:5)
Block(-1,58,-6,STONE:5)
Block(-1,58,-5,STONE:5)
Block(-1,58,-4,STONE:3)
Block(-1,58,-3,STONE:3)
Block(-1,58,-2,STONE:3)
Block(-1,58,-1,STONE:3)
Block(-1,58,0,STONE:3)
Block(-1,58,1,STONE:3)
Block(-1,58,2,STONE:3)
Block(-1,58,3,STONE:3)
Block(-1,58,4,STONE:3)
Block(-1,58,5,STONE:3)
Block(-1,58,6,STONE:3)
Block(-1,59,-7,STONE:5)
Block(-1,59,-6,STONE:5)
Block(-1,59,-5,STONE:5)
Block(-1,59,-4,STONE:3)
Block(-1,59,-3,STONE:3)
Block(-1,59,-2,STONE:3)
Block(-1,59,-1,STONE:3)
Block(-1,59,0,STONE:3)
Block(-1,59,1,STONE:3)
Block(-1,60,-7,STONE:5)
Block(-1,60,-6,STONE:5)
Block(-1,60,-5,STONE:5)
Block(-1,60,-4,STONE:3)
Block(-1,60,-3,STONE:3)
Block(-1,60,-2,STONE:3)
Block(-1,60,-1,STONE:3)
Block(-1,61,-6,STONE:5)
Block(-1,61,-5,STONE:5)
Block(-1,61,-4,STONE:3)
Block(-1,61,-3,STONE:3)
Block(-1,61,-2,STONE:3)
Block(-1,62,-6,STONE:5)
Block(-1,62,-5,STONE:5)
Block(-1,62,-4,STONE:3)
Block(-1,62,-3,STONE:3)
Block(0,48,-3,STONE:5)
Block(0,48,-2,STONE:5)
Block(0,49,-5,STONE:5)
Block(0,49,-4,STONE:5)
Block(0,49,-3,STONE:5)
Block(0,49,-2,STONE:5)
Block(0,49,-1,STONE:5)
Block(0,50,-7,STONE:5)
Block(0,50,-6,STONE:5)
Block(0,50,-5,STONE:5)
Block(0,50,-4,STONE:5)
Block(0,50,-3,STONE:5)
Block(0,50,-2,STONE:5)
Block(0,50,-1,STONE:5)
Block(0,50,0,STONE:5)
Block(0,50,1,STONE:5)
Block(0,50,2,STONE:5)
Block(0,50,3,STONE:5)
Block(0,50,4,STONE:5)
Block(0,51,-7,STONE:5)
Block(0,51,-6,STONE:5)
Block(0,51,-5,STONE:5)
Block(0,51,-4,STONE:5)
Block(0,51,-3,STONE:5)
Block(0,51,-2,STONE:5)
Block(0,51,-1,STONE:5)
Block(0,51,0,STONE:5)
Block(0,51,1,STONE:5)
Block(0,51,2,STONE:5)
Block(0,51,3,STONE:5)
Block(0,51,4,STONE:5)
Block(0,51,5,STONE:5)
Block(0,51,6,STONE:5)
Block(0,52,-7,STONE:5)
Block(0,52,-6,STONE:5)
Block(0,52,-5,STONE:5)
Block(0,52,-4,STONE:5)
Block(0,52,-3,STONE:5)
Block(0,52,-2,STONE:5)
Block(0,52,-1,STONE:5)
Block(0,52,0,STONE:5)
Block(0,52,1,STONE:5)
Block(0,52,2,STONE:5)
Block(0,52,3,STONE:5)
Block(0,52,4,STONE:5)
Block(0,52,5,STONE:5)
Block(0,52,6,STONE:5)
Block(0,52,7,STONE:5)
Block(0,53,-7,STONE:5)
Block(0,53,-6,STONE:5)
Block(0,53,-5,STONE:5)
Block(0,53,-4,STONE:5)
Block(0,53,-3,STONE:5)
Block(0,53,-2,STONE:5)
Block(0,53,-1,STONE:5)
Block(0,53,0,STONE:5)
Block(0,53,1,STONE:5)
Block(0,53,2,STONE:5)
Block(0,53,3,STONE:5)
Block(0,53,4,STONE:5)
Block(0,53,5,STONE:5)
Block(0,53,6,STONE:5)
Block(0,53,7,STONE:5)
Block(0,53,8,STONE:3)
Block(0,54,-7,STONE:5)
Block(0,54,-6,STONE:5)
Block(0,54,-5,STONE:5)
Block(0,54,-4,STONE:5)
Block(0,54,-3,STONE:5)
Block(0,54,-2,STONE:5)
Block(0,54,-1,STONE:5)
Block(0,54,0,STONE:5)
Block(0,54,1,STONE:3)
Block(0,54,2,STONE:3)
Block(0,54,3,STONE:3)
Block(0,54,4,STONE:3)
Block(0,54,5,STONE:3)
Block(0,54,6,STONE:3)
Block(0,54,7,STONE:3)
Block(0,54,8,STONE:3)
Block(0,55,-7,STONE:5)
Block(0,55,-6,STONE:5)
Block(0,55,-5,STONE:5)
Block(0,55,-4,STONE:5)
Block(0,55,-3,STONE:5)
Block(0,55,-2,STONE:5)
Block(0,55,-1,STONE:3)
Block(0,55,0,STONE:3)
Block(0,55,1,STONE:3)
Block(0,55,2,STONE:3)
Block(0,55,3,STONE:3)
Block(0,55,4,STONE:3)
Block(0,55,5,STONE:3)
Block(0,55,6,STONE:3)
Block(0,55,7,STONE:3)
Block(0,55,8,STONE:3)
Block(0,56,-7,STONE:5)
Block(0,56,-6,STONE:5)
Block(0,56,-5,STONE:5)
Block(0,56,-4,STONE:5)
Block(0,56,-3,STONE:5)
Block(0,56,-2,STONE:3)
Block(0,56,-1,STONE:3)
Block(0,56,0,STONE:3)
Block(0,56,1,STONE:3)
Block(0,56,2,STONE:3)
Block(0,56,3,STONE:3)
Block(0,56,4,STONE:3)
Block(0,56,5,STONE:3)
Block(0,56,6,STONE:3)
Block(0,56,7,STONE:3)
Block(0,56,8,STONE:3)
Block(0,57,-7,STONE:5)
Block(0,57,-6,STONE:5)
Block(0,57,-5,STONE:5)
Block(0,57,-4,STONE:5)
Block(0,57,-3,STONE:3)
Block(0,57,-2,STONE:3)
Block(0,57,-1,STONE:3)
Block(0,57,0,STONE:3)
Block(0,57,1,STONE:3)
Block(0,57,2,STONE:3)
Block(0,57,3,STONE:3)
Block(0,57,4,STONE:3)
Block(0,57,5,STONE:3)
Block(0,57,6,STONE:3)
Block(0,57,7,STONE:3)
Block(0,57,8,STONE:3)
Block(0,58,-7,STONE:5)
Block(0,58,-6,STONE:5)
Block(0,58,-5,STONE:5)
Block(0,58,-4,STONE:3)
Block(0,58,-3,STONE:3)
Block(0,58,-2,STONE:3)
Block(0,58,-1,STONE:3)
Block(0,58,0,STONE:3)
Block(0,58,1,STONE:3)
Block(0,58,2,STONE:3)
Block(0,58,3,STONE:3)
Block(0,58,4,STONE:3)
Block(0,58,5,STONE:3)
Block(0,58,6,STONE:3)
Block(0,58,7,STONE:3)
Block(0,59,-7,STONE:5)
Block(0,59,-6,STONE:5)
Block(0,59,-5,STONE:5)
Block(0,59,-4,STONE:3)
Block(0,59,-3,STONE:3)
Block(0,59,-2,STONE:3)
Block(0,59,-1,STONE:3)
Block(0,59,0,STONE:3)
Block(0,59,1,STONE:3)
Block(0,59,2,STONE:3)
Block(0,59,3,STONE:3)
Block(0,59,4,STONE:3)
Block(0,59,5,STONE:3)
Block(0,59,6,STONE:3)
Block(0,60,-7,STONE:5)
Block(0,60,-6,STONE:5)
Block(0,60,-5,STONE:5)
Block(0,60,-4,STONE:3)
Block(0,60,-3,STONE:3)
Block(0,60,-2,STONE:3)
Block(0,60,-1,STONE:3)
Block(0,60,0,STONE:3)
Block(0,60,1,STONE:3)
Block(0,60,4,STONE:3)
Block(0,60,5,STONE:3)
Block(0,61,-6,STONE:5)
Block(0,61,-5,STONE:5)
Block(0,61,-4,STONE:3)
Block(0,61,-3,STONE:3)
Block(0,61,-2,STONE:3)
Block(0,61,-1,STONE:3)
Block(0,61,0,STONE:3)
Block(0,62,-6,STONE:5)
Block(0,62,-5,STONE:5)
Block(0,62,-4,STONE:3)
Block(0,62,-3,STONE:3)
Block(0,62,-2,STONE:3)
Block(0,62,-1,STONE:3)
Block(0,63,-5,STONE:5)
Block(0,63,-4,STONE:5)
Block(0,63,-3,STONE:3)
Block(1,47,-3,STONE:5)
Block(1,48,-5,STONE:5)
Block(1,48,-4,STONE:5)
Block(1,48,-3,STONE:5)
Block(1,48,-2,STONE:5)
Block(1,49,-7,STONE:5)
Block(1,49,-6,STONE:5)
Block(1,49,-5,STONE:5)
Block(1,49,-4,STONE:5)
Block(1,49,-3,STONE:5)
Block(1,49,-2,STONE:5)
Block(1,49,-1,STONE:5)
Block(1,49,0,STONE:5)
Block(1,49,1,STONE:5)
Block(1,49,2,STONE:5)
Block(1,49,3,STONE:5)
Block(1,49,4,STONE:5)
Block(1,50,-7,STONE:5)
Block(1,50,-6,STONE:5)
Block(1,50,-5,STONE:5)
Block(1,50,-4,STONE:5)
Block(1,50,-3,STONE:5)
Block(1,50,-2,STONE:5)
Block(1,50,-1,STONE:5)
Block(1,50,0,STONE:5)
Block(1,50,1,STONE:5)
Block(1,50,2,STONE:5)
Block(1,50,3,STONE:5)
Block(1,50,4,STONE:5)
Block(1,50,5,STONE:5)
Block(1,51,-7,STONE:5)
Block(1,51,-6,STONE:5)
Block(1,51,-5,STONE:5)
Block(1,51,-4,STONE:5)
Block(1,51,-3,STONE:5)
Block(1,51,-2,STONE:5)
Block(1,51,-1,STONE:5)
Block(1,51,0,STONE:5)
Block(1,51,1,STONE:5)
Block(1,51,2,STONE:5)
Block(1,51,3,STONE:5)
Block(1,51,4,STONE:5)
Block(1,51,5,STONE:5)
Block(1,51,6,STONE:5)
Block(1,51,7,STONE:5)
Block(1,51,8,STONE:5)
Block(1,52,-7,STONE:5)
Block(1,52,-6,STONE:5)
Block(1,52,-5,STONE:5)
Block(1,52,-4,STONE:5)
Block(1,52,-3,STONE:5)
Block(1,52,-2,STONE:5)
Block(1,52,-1,STONE:5)
Block(1,52,0,STONE:5)
Block(1,52,1,STONE:5)
Block(1,52,2,STONE:5)
Block(1,52,3,STONE:5)
Block(1,52,4,STONE:5)
Block(1,52,5,STONE:5)
Block(1,52,6,STONE:5)
Block(1,52,7,STONE:5)
Block(1,52,8,STONE:5)
Block(1,53,-7,STONE:5)
Block(1,53,-6,STONE:5)
Block(1,53,-5,STONE:5)
Block(1,53,-4,STONE:5)
Block(1,53,-3,STONE:5)
Block(1,53,-2,STONE:5)
Block(1,53,-1,STONE:5)
Block(1,53,0,STONE:5)
Block(1,53,1,STONE:5)
Block(1,53,2,STONE:5)
Block(1,53,3,STONE:5)
Block(1,53,4,STONE:5)
Block(1,53,5,STONE:5)
Block(1,53,6,STONE:5)
Block(1,53,7,STONE:3)
Block(1,53,8,STONE:3)
Block(1,54,-7,STONE:5)
Block(1,54,-6,STONE:5)
Block(1,54,-5,STONE:5)
Block(1,54,-4,STONE:5)
Block(1,54,-3,STONE:5)
Block(1,54,-2,STONE:5)
Block(1,54,-1,STONE:5)
Block(1,54,0,STONE:5)
Block(1,54,1,STONE:3)
Block(1,54,2,STONE:3)
Block(1,54,3,STONE:3)
Block(1,54,4,STONE:3)
Block(1,54,5,STONE:3)
Block(1,54,6,STONE:3)
Block(1,54,7,STONE:3)
Block(1,54,8,STONE:3)
Block(1,55,-7,STONE:5)
Block(1,55,-6,STONE:5)
Block(1,55,-5,STONE:5)
Block(1,55,-4,STONE:5)
Block(1,55,-3,STONE:5)
Block(1,55,-2,STONE:5)
Block(1,55,-1,STONE:3)
Block(1,55,0,STONE:3)
Block(1,55,1,STONE:3)
Block(1,55,2,STONE:3)
Block(1,55,3,STONE:3)
Block(1,55,4,STONE:3)
Block(1,55,5,STONE:3)
Block(1,55,6,STONE:3)
Block(1,55,7,STONE:3)
Block(1,55,8,STONE:3)
Block(1,56,-7,STONE:5)
Block(1,56,-6,STONE:5)
Block(1,56,-5,STONE:5)
Block(1,56,-4,STONE:5)
Block(1,56,-3,STONE:5)
Block(1,56,-2,STONE:3)
Block(1,56,-1,STONE:3)
Block(1,56,0,STONE:3)
Block(1,56,1,STONE:3)
Block(1,56,2,STONE:3)
Block(1,56,3,STONE:3)
Block(1,56,4,STONE:3)
Block(1,56,5,STONE:3)
Block(1,56,6,STONE:3)
Block(1,56,7,STONE:3)
Block(1,56,8,STONE:3)
Block(1,57,-7,STONE:5)
Block(1,57,-6,STONE:5)
Block(1,57,-5,STONE:5)
Block(1,57,-4,STONE:5)
Block(1,57,-3,STONE:3)
Block(1,57,-2,STONE:3)
Block(1,57,-1,STONE:3)
Block(1,57,0,STONE:3)
Block(1,57,1,STONE:3)
Block(1,57,2,STONE:3)
Block(1,57,3,STONE:3)
Block(1,57,4,STONE:3)
Block(1,57,5,STONE:3)
Block(1,57,6,STONE:3)
Block(1,57,7,STONE:3)
Block(1,57,8,STONE:3)
Block(1,58,-7,STONE:5)
Block(1,58,-6,STONE:5)
Block(1,58,-5,STONE:5)
Block(1,58,-4,STONE:3)
Block(1,58,-3,STONE:3)
Block(1,58,-2,STONE:3)
Block(1,58,-1,STONE:3)
Block(1,58,0,STONE:3)
Block(1,58,1,STONE:3)
Block(1,58,2,STONE:3)
Block(1,58,3,STONE:3)
Block(1,58,4,STONE:3)
Block(1,58,5,STONE:3)
Block(1,58,6,STONE:3)
Block(1,58,7,STONE:3)
Block(1,58,8,STONE:3)
Block(1,59,-7,STONE:5)
Block(1,59,-6,STONE:5)
Block(1,59,-5,STONE:5)
Block(1,59,-4,STONE:3)
Block(1,59,-3,STONE:3)
Block(1,59,-2,STONE:3)
Block(1,59,-1,STONE:3)
Block(1,59,0,STONE:3)
Block(1,59,1,STONE:3)
Block(1,59,2,STONE:3)
Block(1,59,3,STONE:3)
Block(1,59,4,STONE:3)
Block(1,59,5,STONE:3)
Block(1,59,6,STONE:3)
Block(1,59,7,STONE:3)
Block(1,60,-7,STONE:5)
Block(1,60,-6,STONE:5)
Block(1,60,-5,STONE:5)
Block(1,60,-4,STONE:3)
Block(1,60,-3,STONE:3)
Block(1,60,-2,STONE:3)
Block(1,60,-1,STONE:3)
Block(1,60,0,STONE:3)
Block(1,60,1,STONE:3)
Block(1,60,2,STONE:3)
Block(1,60,3,STONE:3)
Block(1,60,4,STONE:3)
Block(1,60,5,STONE:3)
Block(1,60,6,STONE:3)
Block(1,61,-7,STONE:5)
Block(1,61,-6,STONE:5)
Block(1,61,-5,STONE:5)
Block(1,61,-4,STONE:3)
Block(1,61,-3,STONE:3)
Block(1,61,-2,STONE:3)
Block(1,61,-1,STONE:3)
Block(1,61,0,STONE:3)
Block(1,61,1,STONE:3)
Block(1,62,-6,STONE:5)
Block(1,62,-5,STONE:5)
Block(1,62,-4,STONE:3)
Block(1,62,-3,STONE:3)
Block(1,62,-2,STONE:3)
Block(1,62,-1,STONE:3)
Block(1,62,0,STONE:3)
Block(1,63,-6,STONE:5)
Block(1,63,-5,STONE:5)
Block(1,63,-4,STONE:3)
Block(1,63,-3,STONE:3)
Block(1,63,-2,STONE:3)
Block(1,63,-1,STONE:3)
Block(2,47,-5,STONE:5)
Block(2,47,-4,STONE:5)
Block(2,47,-3,STONE:5)
Block(2,48,-6,STONE:5)
Block(2,48,-5,STONE:5)
Block(2,48,-4,STONE:5)
Block(2,48,-3,STONE:5)
Block(2,48,-2,STONE:5)
Block(2,48,-1,STONE:5)
Block(2,48,2,STONE:5)
Block(2,48,8,STONE:5)
Block(2,49,-7,STONE:5)
Block(2,49,-6,STONE:5)
Block(2,49,-5,STONE:5)
Block(2,49,-4,STONE:5)
Block(2,49,-3,STONE:5)
Block(2,49,-2,STONE:5)
Block(2,49,-1,STONE:5)
Block(2,49,0,STONE:5)
Block(2,49,1,STONE:5)
Block(2,49,2,STONE:5)
Block(2,49,3,STONE:5)
Block(2,49,4,STONE:5)
Block(2,49,6,STONE:5)
Block(2,49,7,STONE:5)
Block(2,49,8,STONE:5)
Block(2,50,-7,STONE:5)
Block(2,50,-6,STONE:5)
Block(2,50,-5,STONE:5)
Block(2,50,-4,STONE:5)
Block(2,50,-3,STONE:5)
Block(2,50,-2,STONE:5)
Block(2,50,-1,STONE:5)
Block(2,50,0,STONE:5)
Block(2,50,1,STONE:5)
Block(2,50,2,STONE:5)
Block(2,50,3,STONE:5)
Block(2,50,4,STONE:5)
Block(2,50,5,STONE:5)
Block(2,50,6,STONE:5)
Block(2,50,7,STONE:5)
Block(2,50,8,STONE:5)
Block(2,51,-7,STONE:5)
Block(2,51,-6,STONE:5)
Block(2,51,-5,STONE:5)
Block(2,51,-4,STONE:5)
Block(2,51,-3,STONE:5)
Block(2,51,-2,STONE:5)
Block(2,51,-1,STONE:5)
Block(2,51,0,STONE:5)
Block(2,51,1,STONE:5)
Block(2,51,2,STONE:5)
Block(2,51,3,STONE:5)
Block(2,51,4,STONE:5)
Block(2,51,5,STONE:5)
Block(2,51,6,STONE:5)
Block(2,51,7,STONE:5)
Block(2,51,8,STONE:5)
Block(2,52,-7,STONE:5)
Block(2,52,-6,STONE:5)
Block(2,52,-5,STONE:5)
Block(2,52,-4,STONE:5)
Block(2,52,-3,STONE:5)
Block(2,52,-2,STONE:5)
Block(2,52,-1,STONE:5)
Block(2,52,0,STONE:5)
Block(2,52,1,STONE:5)
Block(2,52,2,STONE:5)
Block(2,52,3,STONE:5)
Block(2,52,4,STONE:5)
Block(2,52,5,STONE:5)
Block(2,52,6,STONE:5)
Block(2,52,7,STONE:5)
Block(2,52,8,STONE:5)
Block(2,53,-7,STONE:5)
Block(2,53,-6,STONE:5)
Block(2,53,-5,STONE:5)
Block(2,53,-4,STONE:5)
Block(2,53,-3,STONE:0)
Block(2,53,-2,STONE:5)
Block(2,53,-1,STONE:5)
Block(2,53,0,STONE:5)
Block(2,53,1,STONE:5)
Block(2,53,2,STONE:5)
Block(2,53,3,STONE:5)
Block(2,53,4,STONE:5)
Block(2,53,5,STONE:5)
Block(2,53,6,STONE:5)
Block(2,53,7,STONE:3)
Block(2,53,8,STONE:3)
Block(2,54,-7,STONE:5)
Block(2,54,-6,STONE:5)
Block(2,54,-5,STONE:5)
Block(2,54,-4,STONE:0)
Block(2,54,-3,STONE:0)
Block(2,54,-2,STONE:0)
Block(2,54,-1,STONE:0)
Block(2,54,0,STONE:5)
Block(2,54,1,STONE:5)
Block(2,54,2,STONE:3)
Block(2,54,3,STONE:3)
Block(2,54,4,STONE:3)
Block(2,54,5,STONE:5)
Block(2,54,6,STONE:3)
Block(2,54,7,STONE:3)
Block(2,54,8,STONE:3)
Block(2,55,-7,STONE:5)
Block(2,55,-6,STONE:5)
Block(2,55,-5,STONE:5)
Block(2,55,-4,STONE:0)
Block(2,55,-3,STONE:0)
Block(2,55,-2,STONE:0)
Block(2,55,-1,STONE:0)
Block(2,55,0,STONE:3)
Block(2,55,1,STONE:3)
Block(2,55,2,STONE:3)
Block(2,55,3,STONE:3)
Block(2,55,4,STONE:3)
Block(2,55,5,STONE:3)
Block(2,55,6,STONE:3)
Block(2,55,7,STONE:3)
Block(2,55,8,STONE:3)
Block(2,56,-7,STONE:5)
Block(2,56,-6,STONE:5)
Block(2,56,-5,STONE:5)
Block(2,56,-4,STONE:5)
Block(2,56,-3,STONE:5)
Block(2,56,-2,STONE:3)
Block(2,56,-1,STONE:3)
Block(2,56,0,STONE:3)
Block(2,56,1,STONE:3)
Block(2,56,2,STONE:3)
Block(2,56,3,STONE:3)
Block(2,56,4,STONE:3)
Block(2,56,5,STONE:3)
Block(2,56,6,STONE:3)
Block(2,56,7,STONE:3)
Block(2,56,8,STONE:3)
Block(2,57,-7,STONE:5)
Block(2,57,-6,STONE:5)
Block(2,57,-5,STONE:5)
Block(2,57,-4,STONE:5)
Block(2,57,-3,STONE:3)
Block(2,57,-2,STONE:3)
Block(2,57,-1,STONE:3)
Block(2,57,0,STONE:3)
Block(2,57,1,STONE:3)
Block(2,57,2,STONE:3)
Block(2,57,3,STONE:3)
Block(2,57,4,STONE:3)
Block(2,57,5,STONE:3)
Block(2,57,6,STONE:3)
Block(2,57,7,STONE:3)
Block(2,57,8,STONE:3)
Block(2,58,-7,STONE:5)
Block(2,58,-6,STONE:5)
Block(2,58,-5,STONE:5)
Block(2,58,-4,STONE:5)
Block(2,58,-3,STONE:3)
Block(2,58,-2,STONE:3)
Block(2,58,-1,STONE:3)
Block(2,58,0,STONE:3)
Block(2,58,1,STONE:3)
Block(2,58,2,STONE:3)
Block(2,58,3,STONE:3)
Block(2,58,4,STONE:3)
Block(2,58,5,STONE:3)
Block(2,58,6,STONE:3)
Block(2,58,7,STONE:3)
Block(2,58,8,STONE:3)
Block(2,59,-7,STONE:5)
Block(2,59,-6,STONE:5)
Block(2,59,-5,STONE:5)
Block(2,59,-4,STONE:3)
Block(2,59,-3,STONE:3)
Block(2,59,-2,STONE:3)
Block(2,59,-1,STONE:3)
Block(2,59,0,STONE:3)
Block(2,59,1,STONE:3)
Block(2,59,2,STONE:3)
Block(2,59,3,STONE:3)
Block(2,59,4,STONE:3)
Block(2,59,5,STONE:3)
Block(2,59,6,STONE:3)
Block(2,59,7,STONE:3)
Block(2,59,8,STONE:3)
Block(2,60,-7,STONE:5)
Block(2,60,-6,STONE:5)
Block(2,60,-5,STONE:5)
Block(2,60,-4,STONE:3)
Block(2,60,-3,STONE:3)
Block(2,60,-2,STONE:3)
Block(2,60,-1,STONE:3)
Block(2,60,0,STONE:3)
Block(2,60,1,STONE:3)
Block(2,60,2,STONE:3)
Block(2,60,3,STONE:3)
Block(2,60,4,STONE:3)
Block(2,60,5,STONE:3)
Block(2,60,6,STONE:3)
Block(2,60,7,STONE:3)
Block(2,61,-7,STONE:5)
Block(2,61,-6,STONE:5)
Block(2,61,-5,STONE:5)
Block(2,61,-4,STONE:3)
Block(2,61,-3,STONE:3)
Block(2,61,-2,STONE:3)
Block(2,61,-1,STONE:3)
Block(2,61,0,STONE:3)
Block(2,61,1,STONE:3)
Block(2,61,2,STONE:3)
Block(2,62,-7,STONE:5)
Block(2,62,-6,STONE:5)
Block(2,62,-5,STONE:5)
Block(2,62,-4,STONE:3)
Block(2,62,-3,STONE:3)
Block(2,62,-2,STONE:3)
Block(2,62,-1,STONE:3)
Block(2,62,0,STONE:3)
Block(2,62,1,STONE:3)
Block(2,63,-7,STONE:5)
Block(2,63,-6,STONE:5)
Block(2,63,-5,STONE:5)
Block(2,63,-4,STONE:3)
Block(2,63,-3,STONE:3)
Block(2,63,-2,STONE:3)
Block(2,63,-1,STONE:3)
Block(2,63,0,STONE:3)
Block(2,64,-6,STONE:5)
Block(2,64,-5,STONE:5)
Block(2,64,-3,STONE:3)
Block(2,64,-2,STONE:3)
Block(2,64,-1,STONE:3)
Block(3,46,-3,STONE:5)
Block(3,47,-5,STONE:5)
Block(3,47,-4,STONE:5)
Block(3,47,-3,STONE:5)
Block(3,47,-2,STONE:5)
Block(3,48,-6,STONE:5)
Block(3,48,-5,STONE:5)
Block(3,48,-4,STONE:5)
Block(3,48,-3,STONE:5)
Block(3,48,-2,STONE:5)
Block(3,48,-1,STONE:5)
Block(3,48,0,STONE:5)
Block(3,48,1,STONE:5)
Block(3,48,2,STONE:5)
Block(3,48,3,STONE:5)
Block(3,48,4,STONE:5)
Block(3,48,8,STONE:5)
Block(3,49,-7,STONE:5)
Block(3,49,-6,STONE:5)
Block(3,49,-5,STONE:5)
Block(3,49,-4,STONE:5)
Block(3,49,-3,STONE:5)
Block(3,49,-2,STONE:5)
Block(3,49,-1,STONE:5)
Block(3,49,0,STONE:5)
Block(3,49,1,STONE:5)
Block(3,49,2,STONE:5)
Block(3,49,3,STONE:5)
Block(3,49,4,STONE:5)
Block(3,49,5,STONE:5)
Block(3,49,6,STONE:5)
Block(3,49,7,STONE:5)
Block(3,49,8,STONE:5)
Block(3,50,-7,STONE:5)
Block(3,50,-6,STONE:5)
Block(3,50,-5,STONE:5)
Block(3,50,-4,STONE:5)
Block(3,50,-3,STONE:5)
Block(3,50,-2,STONE:5)
Block(3,50,-1,STONE:5)
Block(3,50,0,STONE:5)
Block(3,50,1,STONE:5)
Block(3,50,2,STONE:5)
Block(3,50,3,STONE:5)
Block(3,50,4,STONE:5)
Block(3,50,5,STONE:5)
Block(3,50,6,STONE:5)
Block(3,50,7,STONE:5)
Block(3,50,8,STONE:5)
Block(3,51,-7,STONE:5)
Block(3,51,-6,STONE:5)
Block(3,51,-5,STONE:5)
Block(3,51,-4,STONE:5)
Block(3,51,-3,STONE:5)
Block(3,51,-2,STONE:5)
Block(3,51,-1,STONE:5)
Block(3,51,0,STONE:5)
Block(3,51,1,STONE:5)
Block(3,51,2,STONE:5)
Block(3,51,3,STONE:5)
Block(3,51,4,STONE:5)
Block(3,51,5,STONE:5)
Block(3,51,6,STONE:5)
Block(3,51,7,STONE:5)
Block(3,51,8,STONE:5)
Block(3,52,-7,STONE:5)
Block(3,52,-6,STONE:5)
Block(3,52,-5,STONE:5)
Block(3,52,-4,STONE:5)
Block(3,52,-3,STONE:5)
Block(3,52,-2,STONE:5)
Block(3,52,-1,STONE:5)
Block(3,52,0,STONE:5)
Block(3,52,1,STONE:5)
Block(3,52,2,STONE:5)
Block(3,52,3,STONE:5)
Block(3,52,4,STONE:5)
Block(3,52,5,STONE:5)
Block(3,52,6,STONE:5)
Block(3,52,7,STONE:5)
Block(3,52,8,STONE:5)
Block(3,53,-7,STONE:5)
Block(3,53,-6,STONE:5)
Block(3,53,-5,STONE:5)
Block(3,53,-4,STONE:5)
Block(3,53,-3,STONE:0)
Block(3,53,-2,STONE:0)
Block(3,53,-1,STONE:0)
Block(3,53,0,STONE:5)
Block(3,53,1,STONE:5)
Block(3,53,2,STONE:5)
Block(3,53,3,STONE:5)
Block(3,53,4,STONE:5)
Block(3,53,5,STONE:5)
Block(3,53,6,STONE:5)
Block(3,53,7,STONE:3)
Block(3,53,8,STONE:3)
Block(3,54,-7,STONE:5)
Block(3,54,-6,STONE:5)
Block(3,54,-5,STONE:5)
Block(3,54,-4,STONE:0)
Block(3,54,-3,STONE:0)
Block(3,54,-2,STONE:0)
Block(3,54,-1,STONE:0)
Block(3,54,0,STONE:0)
Block(3,54,1,STONE:5)
Block(3,54,2,STONE:5)
Block(3,54,3,STONE:5)
Block(3,54,4,STONE:5)
Block(3,54,5,STONE:5)
Block(3,54,6,STONE:3)
Block(3,54,7,STONE:3)
Block(3,54,8,STONE:3)
Block(3,55,-7,STONE:5)
Block(3,55,-6,STONE:5)
Block(3,55,-5,STONE:0)
Block(3,55,-4,STONE:0)
Block(3,55,-3,STONE:0)
Block(3,55,-2,STONE:0)
Block(3,55,-1,STONE:0)
Block(3,55,0,STONE:0)
Block(3,55,1,STONE:3)
Block(3,55,2,STONE:3)
Block(3,55,3,STONE:3)
Block(3,55,4,STONE:3)
Block(3,55,5,STONE:3)
Block(3,55,6,STONE:3)
Block(3,55,7,STONE:3)
Block(3,55,8,STONE:3)
Block(3,56,-7,STONE:5)
Block(3,56,-6,STONE:5)
Block(3,56,-5,STONE:0)
Block(3,56,-4,STONE:0)
Block(3,56,-3,STONE:0)
Block(3,56,-2,STONE:0)
Block(3,56,-1,STONE:3)
Block(3,56,0,STONE:3)
Block(3,56,1,STONE:3)
Block(3,56,2,STONE:3)
Block(3,56,3,STONE:3)
Block(3,56,4,STONE:3)
Block(3,56,5,STONE:3)
Block(3,56,6,STONE:3)
Block(3,56,7,STONE:3)
Block(3,56,8,STONE:3)
Block(3,57,-7,STONE:5)
Block(3,57,-6,STONE:5)
Block(3,57,-5,STONE:5)
Block(3,57,-4,STONE:5)
Block(3,57,-3,STONE:5)
Block(3,57,-2,STONE:3)
Block(3,57,-1,STONE:3)
Block(3,57,0,STONE:3)
Block(3,57,1,STONE:3)
Block(3,57,2,STONE:3)
Block(3,57,3,STONE:3)
Block(3,57,4,STONE:3)
Block(3,57,5,STONE:3)
Block(3,57,6,STONE:3)
Block(3,57,7,STONE:3)
Block(3,57,8,STONE:3)
Block(3,58,-7,STONE:5)
Block(3,58,-6,STONE:5)
Block(3,58,-5,STONE:5)
Block(3,58,-4,STONE:5)
Block(3,58,-3,STONE:3)
Block(3,58,-2,STONE:3)
Block(3,58,-1,STONE:3)
Block(3,58,0,STONE:3)
Block(3,58,1,STONE:3)
Block(3,58,2,STONE:3)
Block(3,58,3,STONE:3)
Block(3,58,4,STONE:3)
Block(3,58,5,STONE:3)
Block(3,58,6,STONE:3)
Block(3,58,7,STONE:3)
Block(3,58,8,STONE:3)
Block(3,59,-7,STONE:5)
Block(3,59,-6,STONE:5)
Block(3,59,-5,STONE:5)
Block(3,59,-4,STONE:5)
Block(3,59,-3,STONE:3)
Block(3,59,-2,STONE:3)
Block(3,59,-1,STONE:3)
Block(3,59,0,STONE:3)
Block(3,59,1,STONE:3)
Block(3,59,2,STONE:3)
Block(3,59,3,STONE:3)
Block(3,59,4,STONE:3)
Block(3,59,5,STONE:3)
Block(3,59,6,STONE:3)
Block(3,59,7,STONE:3)
Block(3,59,8,STONE:3)
Block(3,60,-7,STONE:5)
Block(3,60,-6,STONE:5)
Block(3,60,-5,STONE:5)
Block(3,60,-4,STONE:5)
Block(3,60,-3,STONE:3)
Block(3,60,-2,STONE:3)
Block(3,60,-1,STONE:3)
Block(3,60,0,STONE:3)
Block(3,60,1,STONE:3)
Block(3,60,2,STONE:3)
Block(3,60,3,STONE:3)
Block(3,60,4,STONE:3)
Block(3,60,5,STONE:3)
Block(3,60,6,STONE:3)
Block(3,61,-7,STONE:5)
Block(3,61,-6,STONE:5)
Block(3,61,-5,STONE:5)
Block(3,61,-4,STONE:3)
Block(3,61,-3,STONE:3)
Block(3,61,-2,STONE:3)
Block(3,61,-1,STONE:3)
Block(3,61,0,STONE:3)
Block(3,61,1,STONE:3)
Block(3,61,2,STONE:3)
Block(3,61,3,STONE:3)
Block(3,61,4,STONE:3)
Block(3,62,-7,STONE:5)
Block(3,62,-6,STONE:5)
Block(3,62,-5,STONE:5)
Block(3,62,-4,STONE:3)
Block(3,62,-3,STONE:3)
Block(3,62,-2,STONE:3)
Block(3,62,-1,STONE:3)
Block(3,62,0,STONE:3)
Block(3,62,1,STONE:3)
Block(3,62,2,STONE:3)
Block(3,63,-7,STONE:5)
Block(3,63,-6,STONE:5)
Block(3,63,-5,STONE:5)
Block(3,63,-4,STONE:3)
Block(3,63,-3,STONE:3)
Block(3,63,-2,STONE:3)
Block(3,63,-1,STONE:3)
Block(3,63,0,STONE:3)
Block(3,63,1,STONE:3)
Block(3,64,-6,STONE:5)
Block(3,64,-5,STONE:5)
Block(3,64,-4,STONE:3)
Block(3,64,-3,STONE:3)
Block(3,64,-2,STONE:3)
Block(3,64,-1,STONE:3)
Block(3,64,0,STONE:3)
Block(3,65,-5,STONE:5)
Block(4,47,-4,STONE:5)
Block(4,47,-3,STONE:5)
Block(4,47,-2,STONE:5)
Block(4,47,-1,STONE:5)
Block(4,47,0,STONE:5)
Block(4,47,2,STONE:5)
Block(4,47,3,STONE:5)
Block(4,47,4,STONE:5)
Block(4,48,-6,STONE:5)
Block(4,48,-5,STONE:5)
Block(4,48,-4,STONE:5)
Block(4,48,-3,STONE:5)
Block(4,48,-2,STONE:5)
Block(4,48,-1,STONE:5)
Block(4,48,0,STONE:5)
Block(4,48,1,STONE:5)
Block(4,48,2,STONE:5)
Block(4,48,3,STONE:5)
Block(4,48,4,STONE:5)
Block(4,48,5,STONE:5)
Block(4,48,7,STONE:5)
Block(4,48,8,STONE:5)
Block(4,49,-7,STONE:5)
Block(4,49,-6,STONE:5)
Block(4,49,-5,STONE:5)
Block(4,49,-4,STONE:5)
Block(4,49,-3,STONE:5)
Block(4,49,-2,STONE:5)
Block(4,49,-1,STONE:5)
Block(4,49,0,STONE:5)
Block(4,49,1,STONE:5)
Block(4,49,2,STONE:5)
Block(4,49,3,STONE:5)
Block(4,49,4,STONE:5)
Block(4,49,5,STONE:5)
Block(4,49,6,STONE:5)
Block(4,49,7,STONE:5)
Block(4,49,8,STONE:5)
Block(4,50,-7,STONE:5)
Block(4,50,-6,STONE:5)
Block(4,50,-5,STONE:5)
Block(4,50,-4,STONE:5)
Block(4,50,-3,STONE:5)
Block(4,50,-2,STONE:5)
Block(4,50,-1,STONE:5)
Block(4,50,0,STONE:5)
Block(4,50,1,STONE:5)
Block(4,50,2,STONE:5)
Block(4,50,3,STONE:5)
Block(4,50,4,STONE:5)
Block(4,50,5,STONE:5)
Block(4,50,6,STONE:5)
Block(4,50,7,STONE:5)
Block(4,50,8,STONE:5)
Block(4,51,-7,STONE:5)
Block(4,51,-6,STONE:5)
Block(4,51,-5,STONE:5)
Block(4,51,-4,STONE:5)
Block(4,51,-3,STONE:5)
Block(4,51,-2,STONE:5)
Block(4,51,-1,STONE:5)
Block(4,51,0,STONE:5)
Block(4,51,1,STONE:5)
Block(4,51,2,STONE:5)
Block(4,51,3,STONE:5)
Block(4,51,4,STONE:5)
Block(4,51,5,STONE:5)
Block(4,51,6,STONE:5)
Block(4,51,7,STONE:5)
Block(4,51,8,STONE:5)
Block(4,52,-7,STONE:5)
Block(4,52,-6,STONE:5)
Block(4,52,-5,STONE:5)
Block(4,52,-4,STONE:5)
Block(4,52,-3,STONE:5)
Block(4,52,-2,STONE:5)
Block(4,52,-1,STONE:5)
Block(4,52,0,STONE:5)
Block(4,52,1,STONE:5)
Block(4,52,2,STONE:5)
Block(4,52,3,STONE:5)
Block(4,52,4,STONE:5)
Block(4,52,5,STONE:5)
Block(4,52,6,STONE:5)
Block(4,52,7,STONE:5)
Block(4,52,8,STONE:5)
Block(4,53,-7,STONE:5)
Block(4,53,-6,STONE:5)
Block(4,53,-5,STONE:5)
Block(4,53,-4,STONE:5)
Block(4,53,-3,STONE:5)
Block(4,53,-2,STONE:5)
Block(4,53,-1,STONE:0)
Block(4,53,0,STONE:0)
Block(4,53,1,STONE:5)
Block(4,53,2,STONE:5)
Block(4,53,3,STONE:5)
Block(4,53,4,STONE:5)
Block(4,53,5,STONE:5)
Block(4,53,6,STONE:5)
Block(4,53,7,STONE:5)
Block(4,53,8,STONE:3)
Block(4,54,-7,STONE:5)
Block(4,54,-6,STONE:5)
Block(4,54,-5,STONE:5)
Block(4,54,-4,STONE:0)
Block(4,54,-3,STONE:0)
Block(4,54,-2,STONE:0)
Block(4,54,-1,STONE:0)
Block(4,54,0,STONE:0)
Block(4,54,1,STONE:0)
Block(4,54,2,STONE:0)
Block(4,54,3,STONE:0)
Block(4,54,4,STONE:0)
Block(4,54,5,STONE:5)
Block(4,54,6,STONE:3)
Block(4,54,7,STONE:3)
Block(4,54,8,STONE:3)
Block(4,55,-7,STONE:5)
Block(4,55,-6,STONE:0)
Block(4,55,-5,STONE:0)
Block(4,55,-4,STONE:0)
Block(4,55,-3,STONE:0)
Block(4,55,-2,STONE:0)
Block(4,55,-1,STONE:0)
Block(4,55,0,STONE:0)
Block(4,55,1,STONE:0)
Block(4,55,2,STONE:0)
Block(4,55,3,STONE:0)
Block(4,55,4,STONE:0)
Block(4,55,5,STONE:3)
Block(4,55,6,STONE:3)
Block(4,55,7,STONE:3)
Block(4,55,8,STONE:3)
Block(4,56,-7,STONE:5)
Block(4,56,-6,STONE:5)
Block(4,56,-5,STONE:0)
Block(4,56,-4,STONE:0)
Block(4,56,-3,STONE:0)
Block(4,56,-2,STONE:0)
Block(4,56,-1,STONE:0)
Block(4,56,0,STONE:0)
Block(4,56,1,STONE:3)
Block(4,56,2,STONE:3)
Block(4,56,3,STONE:3)
Block(4,56,4,STONE:3)
Block(4,56,5,STONE:3)
Block(4,56,6,STONE:3)
Block(4,56,7,STONE:3)
Block(4,56,8,STONE:3)
Block(4,57,-7,STONE:5)
Block(4,57,-6,STONE:5)
Block(4,57,-5,STONE:5)
Block(4,57,-4,STONE:0)
Block(4,57,-3,STONE:0)
Block(4,57,-2,STONE:0)
Block(4,57,-1,STONE:3)
Block(4,57,0,STONE:3)
Block(4,57,1,STONE:3)
Block(4,57,2,STONE:3)
Block(4,57,3,STONE:3)
Block(4,57,4,STONE:3)
Block(4,57,5,STONE:3)
Block(4,57,6,STONE:3)
Block(4,57,7,STONE:3)
Block(4,57,8,STONE:3)
Block(4,58,-7,STONE:5)
Block(4,58,-6,STONE:5)
Block(4,58,-5,STONE:5)
Block(4,58,-4,STONE:5)
Block(4,58,-3,STONE:0)
Block(4,58,-2,STONE:3)
Block(4,58,-1,STONE:3)
Block(4,58,0,STONE:3)
Block(4,58,1,STONE:3)
Block(4,58,2,STONE:3)
Block(4,58,3,STONE:3)
Block(4,58,4,STONE:3)
Block(4,58,5,STONE:3)
Block(4,58,6,STONE:3)
Block(4,58,7,STONE:3)
Block(4,58,8,STONE:3)
Block(4,59,-7,STONE:5)
Block(4,59,-6,STONE:5)
Block(4,59,-5,STONE:5)
Block(4,59,-4,STONE:5)
Block(4,59,-3,STONE:5)
Block(4,59,-2,STONE:3)
Block(4,59,-1,STONE:3)
Block(4,59,0,STONE:3)
Block(4,59,1,STONE:3)
Block(4,59,2,STONE:3)
Block(4,59,3,STONE:3)
Block(4,59,4,STONE:3)
Block(4,59,5,STONE:3)
Block(4,59,6,STONE:3)
Block(4,59,7,STONE:3)
Block(4,59,8,STONE:3)
Block(4,60,-7,STONE:5)
Block(4,60,-6,STONE:5)
Block(4,60,-5,STONE:5)
Block(4,60,-4,STONE:5)
Block(4,60,-3,STONE:3)
Block(4,60,-2,STONE:3)
Block(4,60,-1,STONE:3)
Block(4,60,0,STONE:3)
Block(4,60,1,STONE:3)
Block(4,60,2,STONE:3)
Block(4,60,3,STONE:3)
Block(4,60,4,STONE:3)
Block(4,60,5,STONE:3)
Block(4,60,6,STONE:3)
Block(4,61,-7,STONE:5)
Block(4,61,-6,STONE:5)
Block(4,61,-5,STONE:5)
Block(4,61,-4,STONE:3)
Block(4,61,-3,STONE:3)
Block(4,61,-2,STONE:3)
Block(4,61,-1,STONE:3)
Block(4,61,0,STONE:3)
Block(4,61,1,STONE:3)
Block(4,61,2,STONE:3)
Block(4,61,3,STONE:3)
Block(4,61,4,STONE:3)
Block(4,61,5,STONE:3)
Block(4,62,-7,STONE:5)
Block(4,62,-6,STONE:5)
Block(4,62,-5,STONE:5)
Block(4,62,-4,STONE:3)
Block(4,62,-3,STONE:3)
Block(4,62,-2,STONE:3)
Block(4,62,-1,STONE:3)
Block(4,62,0,STONE:3)
Block(4,62,1,STONE:3)
Block(4,62,2,STONE:3)
Block(4,62,3,STONE:3)
Block(4,62,4,STONE:3)
Block(4,62,5,STONE:3)
Block(4,63,-7,STONE:5)
Block(4,63,-6,STONE:5)
Block(4,63,-5,STONE:5)
Block(4,63,-4,STONE:3)
Block(4,63,-3,STONE:3)
Block(4,63,-2,STONE:3)
Block(4,63,-1,STONE:3)
Block(4,63,0,STONE:3)
Block(4,63,1,STONE:3)
Block(4,63,2,STONE:3)
Block(4,63,4,STONE:3)
Block(4,64,-6,STONE:5)
Block(4,64,-5,STONE:5)
Block(4,64,-4,STONE:3)
Block(4,64,-3,STONE:3)
Block(4,64,-2,STONE:3)
Block(4,64,-1,STONE:3)
Block(4,64,0,STONE:3)
Block(4,65,-5,STONE:5)
Block(4,65,-4,STONE:3)
Block(4,65,-3,STONE:3)
Block(4,65,-2,STONE:3)
Block(4,65,-1,STONE:3)
Block(4,66,-4,STONE:5)
Block(5,46,3,OBSIDIAN:0)
Block(5,47,-3,STONE:5)
Block(5,47,-2,STONE:5)
Block(5,47,-1,STONE:5)
Block(5,47,0,STONE:5)
Block(5,47,2,OBSIDIAN:0)
Block(5,47,3,OBSIDIAN:0)
Block(5,47,4,OBSIDIAN:0)
Block(5,47,5,OBSIDIAN:0)
Block(5,48,-7,STONE:5)
Block(5,48,-6,STONE:5)
Block(5,48,-5,STONE:5)
Block(5,48,-4,STONE:5)
Block(5,48,-3,STONE:5)
Block(5,48,-2,STONE:5)
Block(5,48,-1,STONE:5)
Block(5,48,0,STONE:5)
Block(5,48,1,STONE:5)
Block(5,48,2,STONE:5)
Block(5,48,3,STONE:5)
Block(5,48,4,STONE:5)
Block(5,48,5,STONE:5)
Block(5,48,6,STONE:5)
Block(5,48,7,STONE:5)
Block(5,48,8,STONE:5)
Block(5,49,-7,STONE:5)
Block(5,49,-6,STONE:5)
Block(5,49,-5,STONE:5)
Block(5,49,-4,STONE:5)
Block(5,49,-3,STONE:5)
Block(5,49,-2,STONE:5)
Block(5,49,-1,STONE:5)
Block(5,49,0,STONE:5)
Block(5,49,1,STONE:5)
Block(5,49,2,STONE:5)
Block(5,49,3,STONE:5)
Block(5,49,4,STONE:5)
Block(5,49,5,STONE:5)
Block(5,49,6,STONE:5)
Block(5,49,7,STONE:5)
Block(5,49,8,STONE:5)
Block(5,50,-7,STONE:5)
Block(5,50,-6,STONE:5)
Block(5,50,-5,STONE:5)
Block(5,50,-4,STONE:5)
Block(5,50,-3,STONE:5)
Block(5,50,-2,STONE:5)
Block(5,50,-1,STONE:5)
Block(5,50,0,STONE:5)
Block(5,50,1,STONE:5)
Block(5,50,2,STONE:5)
Block(5,50,3,STONE:5)
Block(5,50,4,STONE:5)
Block(5,50,5,STONE:5)
Block(5,50,6,STONE:5)
Block(5,50,7,STONE:5)
Block(5,50,8,STONE:5)
Block(5,51,-7,STONE:5)
Block(5,51,-6,STONE:5)
Block(5,51,-5,STONE:5)
Block(5,51,-4,STONE:5)
Block(5,51,-3,STONE:5)
Block(5,51,-2,STONE:5)
Block(5,51,-1,STONE:5)
Block(5,51,0,STONE:5)
Block(5,51,1,STONE:5)
Block(5,51,2,STONE:5)
Block(5,51,3,STONE:5)
Block(5,51,4,STONE:5)
Block(5,51,5,STONE:5)
Block(5,51,6,STONE:5)
Block(5,51,7,STONE:5)
Block(5,51,8,STONE:5)
Block(5,52,-7,STONE:5)
Block(5,52,-6,STONE:5)
Block(5,52,-5,STONE:5)
Block(5,52,-4,STONE:5)
Block(5,52,-3,STONE:5)
Block(5,52,-2,STONE:5)
Block(5,52,-1,STONE:5)
Block(5,52,0,STONE:5)
Block(5,52,1,STONE:0)
Block(5,52,2,STONE:5)
Block(5,52,3,STONE:5)
Block(5,52,4,STONE:5)
Block(5,52,5,STONE:5)
Block(5,52,6,STONE:5)
Block(5,52,7,STONE:5)
Block(5,52,8,STONE:5)
Block(5,53,-7,STONE:5)
Block(5,53,-6,STONE:5)
Block(5,53,-5,STONE:5)
Block(5,53,-4,STONE:5)
Block(5,53,-3,STONE:5)
Block(5,53,-2,STONE:5)
Block(5,53,-1,STONE:5)
Block(5,53,0,STONE:0)
Block(5,53,1,STONE:0)
Block(5,53,2,STONE:0)
Block(5,53,3,STONE:0)
Block(5,53,4,STONE:5)
Block(5,53,5,STONE:5)
Block(5,53,6,STONE:5)
Block(5,53,7,STONE:5)
Block(5,53,8,STONE:5)
Block(5,54,-7,STONE:5)
Block(5,54,-6,STONE:5)
Block(5,54,-5,STONE:5)
Block(5,54,-4,STONE:5)
Block(5,54,-3,STONE:0)
Block(5,54,-2,STONE:0)
Block(5,54,-1,STONE:0)
Block(5,54,0,STONE:0)
Block(5,54,1,STONE:0)
Block(5,54,2,STONE:0)
Block(5,54,3,STONE:0)
Block(5,54,4,STONE:0)
Block(5,54,5,STONE:0)
Block(5,54,6,STONE:0)
Block(5,54,7,STONE:3)
Block(5,54,8,STONE:3)
Block(5,55,-7,STONE:5)
Block(5,55,-6,STONE:5)
Block(5,55,-5,STONE:0)
Block(5,55,-4,STONE:0)
Block(5,55,-3,STONE:0)
Block(5,55,-2,STONE:0)
Block(5,55,-1,STONE:0)
Block(5,55,0,STONE:0)
Block(5,55,1,STONE:0)
Block(5,55,2,STONE:0)
Block(5,55,3,STONE:0)
Block(5,55,4,STONE:0)
Block(5,55,5,STONE:0)
Block(5,55,6,STONE:3)
Block(5,55,7,STONE:3)
Block(5,55,8,STONE:3)
Block(5,56,-7,STONE:5)
Block(5,56,-6,STONE:5)
Block(5,56,-5,STONE:0)
Block(5,56,-4,STONE:0)
Block(5,56,-3,STONE:0)
Block(5,56,-2,STONE:0)
Block(5,56,-1,STONE:0)
Block(5,56,0,STONE:0)
Block(5,56,1,STONE:0)
Block(5,56,2,STONE:0)
Block(5,56,3,STONE:0)
Block(5,56,4,STONE:0)
Block(5,56,5,STONE:3)
Block(5,56,6,STONE:3)
Block(5,56,7,STONE:3)
Block(5,56,8,STONE:3)
Block(5,57,-7,STONE:5)
Block(5,57,-6,STONE:5)
Block(5,57,-5,STONE:5)
Block(5,57,-4,STONE:0)
Block(5,57,-3,STONE:0)
Block(5,57,-2,STONE:0)
Block(5,57,-1,STONE:0)
Block(5,57,0,STONE:0)
Block(5,57,1,STONE:0)
Block(5,57,2,STONE:3)
Block(5,57,3,STONE:3)
Block(5,57,4,STONE:3)
Block(5,57,5,STONE:3)
Block(5,57,6,STONE:3)
Block(5,57,7,STONE:3)
Block(5,57,8,STONE:3)
Block(5,58,-7,STONE:5)
Block(5,58,-6,STONE:5)
Block(5,58,-5,STONE:5)
Block(5,58,-4,STONE:5)
Block(5,58,-3,STONE:5)
Block(5,58,-2,STONE:0)
Block(5,58,-1,STONE:0)
Block(5,58,0,STONE:3)
Block(5,58,1,STONE:3)
Block(5,58,2,STONE:3)
Block(5,58,3,STONE:3)
Block(5,58,4,STONE:3)
Block(5,58,5,STONE:3)
Block(5,58,6,STONE:3)
Block(5,58,7,STONE:3)
Block(5,58,8,STONE:3)
Block(5,59,-7,STONE:5)
Block(5,59,-6,STONE:5)
Block(5,59,-5,STONE:5)
Block(5,59,-4,STONE:5)
Block(5,59,-3,STONE:5)
Block(5,59,-2,STONE:3)
Block(5,59,-1,STONE:3)
Block(5,59,0,STONE:3)
Block(5,59,1,STONE:3)
Block(5,59,2,STONE:3)
Block(5,59,3,STONE:3)
Block(5,59,4,STONE:3)
Block(5,59,5,STONE:3)
Block(5,59,6,STONE:3)
Block(5,59,7,STONE:3)
Block(5,59,8,STONE:3)
Block(5,60,-7,STONE:5)
Block(5,60,-6,STONE:5)
Block(5,60,-5,STONE:5)
Block(5,60,-4,STONE:5)
Block(5,60,-3,STONE:3)
Block(5,60,-2,STONE:3)
Block(5,60,-1,STONE:3)
Block(5,60,0,STONE:3)
Block(5,60,1,STONE:3)
Block(5,60,2,STONE:3)
Block(5,60,3,STONE:3)
Block(5,60,4,STONE:3)
Block(5,60,5,STONE:3)
Block(5,60,6,STONE:3)
Block(5,60,7,STONE:3)
Block(5,60,8,STONE:3)
Block(5,61,-7,STONE:5)
Block(5,61,-6,STONE:5)
Block(5,61,-5,STONE:5)
Block(5,61,-4,STONE:5)
Block(5,61,-3,STONE:3)
Block(5,61,-2,STONE:3)
Block(5,61,-1,STONE:3)
Block(5,61,0,STONE:3)
Block(5,61,1,STONE:3)
Block(5,61,2,STONE:3)
Block(5,61,3,STONE:3)
Block(5,61,4,STONE:3)
Block(5,61,5,STONE:3)
Block(5,61,6,STONE:3)
Block(5,61,7,STONE:3)
Block(5,61,8,STONE:3)
Block(5,62,-7,STONE:5)
Block(5,62,-6,STONE:5)
Block(5,62,-5,STONE:5)
Block(5,62,-4,STONE:3)
Block(5,62,-3,STONE:3)
Block(5,62,-2,STONE:3)
Block(5,62,-1,STONE:3)
Block(5,62,0,STONE:3)
Block(5,62,1,STONE:3)
Block(5,62,2,STONE:3)
Block(5,62,3,STONE:3)
Block(5,62,4,STONE:3)
Block(5,62,5,STONE:3)
Block(5,62,6,STONE:3)
Block(5,63,-6,STONE:5)
Block(5,63,-5,STONE:5)
Block(5,63,-4,STONE:3)
Block(5,63,-3,STONE:3)
Block(5,63,-2,STONE:3)
Block(5,63,-1,STONE:3)
Block(5,63,0,STONE:3)
Block(5,63,1,STONE:3)
Block(5,63,2,STONE:3)
Block(5,63,3,STONE:3)
Block(5,63,4,STONE:3)
Block(5,63,5,STONE:3)
Block(5,63,6,STONE:3)
Block(5,64,-6,STONE:5)
Block(5,64,-5,STONE:5)
Block(5,64,-4,STONE:3)
Block(5,64,-3,STONE:3)
Block(5,64,-2,STONE:3)
Block(5,64,-1,STONE:3)
Block(5,64,0,STONE:3)
Block(5,64,1,STONE:3)
Block(5,64,2,STONE:3)
Block(5,64,3,STONE:3)
Block(5,64,4,STONE:3)
Block(5,64,5,STONE:3)
Block(5,64,6,STONE:3)
Block(5,65,-5,STONE:5)
Block(5,65,-4,STONE:5)
Block(5,65,-3,STONE:3)
Block(5,65,-2,STONE:3)
Block(5,65,-1,STONE:3)
Block(5,65,0,STONE:3)
Block(5,65,4,STONE:3)
Block(6,46,2,OBSIDIAN:0)
Block(6,46,3,OBSIDIAN:0)
Block(6,46,4,OBSIDIAN:0)
Block(6,47,-1,STONE:5)
Block(6,47,0,STONE:5)
Block(6,47,1,OBSIDIAN:0)
Block(6,47,2,OBSIDIAN:0)
Block(6,47,3,OBSIDIAN:0)
Block(6,47,4,OBSIDIAN:0)
Block(6,47,5,OBSIDIAN:0)
Block(6,47,6,OBSIDIAN:0)
Block(6,47,7,OBSIDIAN:0)
Block(6,47,8,OBSIDIAN:0)
Block(6,48,-6,STONE:5)
Block(6,48,-3,STONE:5)
Block(6,48,-2,STONE:5)
Block(6,48,-1,STONE:5)
Block(6,48,0,STONE:5)
Block(6,48,1,STONE:5)
Block(6,48,2,OBSIDIAN:0)
Block(6,48,3,OBSIDIAN:0)
Block(6,48,4,OBSIDIAN:0)
Block(6,48,5,OBSIDIAN:0)
Block(6,48,6,OBSIDIAN:0)
Block(6,48,7,OBSIDIAN:0)
Block(6,48,8,OBSIDIAN:0)
Block(6,49,-7,STONE:5)
Block(6,49,-6,STONE:5)
Block(6,49,-5,STONE:5)
Block(6,49,-4,STONE:5)
Block(6,49,-3,STONE:5)
Block(6,49,-2,STONE:5)
Block(6,49,-1,STONE:5)
Block(6,49,0,STONE:5)
Block(6,49,1,STONE:5)
Block(6,49,2,STONE:5)
Block(6,49,3,STONE:5)
Block(6,49,4,STONE:5)
Block(6,49,5,STONE:5)
Block(6,49,6,STONE:5)
Block(6,49,7,STONE:5)
Block(6,49,8,STONE:5)
Block(6,50,-7,STONE:5)
Block(6,50,-6,STONE:5)
Block(6,50,-5,STONE:5)
Block(6,50,-4,STONE:5)
Block(6,50,-3,STONE:5)
Block(6,50,-2,STONE:5)
Block(6,50,-1,STONE:5)
Block(6,50,0,STONE:5)
Block(6,50,1,STONE:5)
Block(6,50,2,STONE:5)
Block(6,50,3,STONE:5)
Block(6,50,4,STONE:5)
Block(6,50,5,STONE:5)
Block(6,50,6,STONE:5)
Block(6,50,7,STONE:5)
Block(6,50,8,STONE:5)
Block(6,51,-7,STONE:5)
Block(6,51,-6,STONE:5)
Block(6,51,-5,STONE:5)
Block(6,51,-4,STONE:5)
Block(6,51,-3,STONE:5)
Block(6,51,-2,STONE:5)
Block(6,51,-1,STONE:5)
Block(6,51,0,STONE:5)
Block(6,51,1,STONE:5)
Block(6,51,2,STONE:0)
Block(6,51,3,STONE:5)
Block(6,51,4,STONE:5)
Block(6,51,5,STONE:5)
Block(6,51,6,STONE:5)
Block(6,51,7,STONE:5)
Block(6,51,8,STONE:5)
Block(6,52,-7,STONE:5)
Block(6,52,-6,STONE:5)
Block(6,52,-5,STONE:5)
Block(6,52,-4,STONE:5)
Block(6,52,-3,STONE:5)
Block(6,52,-2,STONE:5)
Block(6,52,-1,STONE:5)
Block(6,52,0,STONE:5)
Block(6,52,1,STONE:0)
Block(6,52,2,STONE:0)
Block(6,52,3,STONE:0)
Block(6,52,4,STONE:5)
Block(6,52,5,STONE:5)
Block(6,52,6,STONE:5)
Block(6,52,7,STONE:5)
Block(6,52,8,STONE:5)
Block(6,53,-7,STONE:5)
Block(6,53,-6,STONE:5)
Block(6,53,-5,STONE:5)
Block(6,53,-4,STONE:5)
Block(6,53,-3,STONE:5)
Block(6,53,-2,STONE:5)
Block(6,53,-1,STONE:5)
Block(6,53,0,STONE:0)
Block(6,53,1,STONE:0)
Block(6,53,2,STONE:0)
Block(6,53,3,STONE:0)
Block(6,53,4,STONE:0)
Block(6,53,5,STONE:0)
Block(6,53,6,STONE:0)
Block(6,53,7,STONE:5)
Block(6,53,8,STONE:5)
Block(6,54,-7,STONE:5)
Block(6,54,-6,STONE:5)
Block(6,54,-5,STONE:5)
Block(6,54,-4,STONE:5)
Block(6,54,-3,STONE:0)
Block(6,54,-2,STONE:0)
Block(6,54,-1,STONE:0)
Block(6,54,0,STONE:0)
Block(6,54,1,STONE:0)
Block(6,54,2,STONE:0)
Block(6,54,3,STONE:0)
Block(6,54,4,STONE:0)
Block(6,54,5,STONE:0)
Block(6,54,6,STONE:0)
Block(6,54,7,STONE:0)
Block(6,54,8,STONE:0)
Block(6,55,-7,STONE:5)
Block(6,55,-6,STONE:5)
Block(6,55,-5,STONE:5)
Block(6,55,-4,STONE:0)
Block(6,55,-3,STONE:0)
Block(6,55,-2,STONE:0)
Block(6,55,-1,STONE:0)
Block(6,55,0,STONE:0)
Block(6,55,1,STONE:0)
Block(6,55,2,STONE:0)
Block(6,55,3,STONE:0)
Block(6,55,4,STONE:0)
Block(6,55,5,STONE:0)
Block(6,55,6,STONE:0)
Block(6,55,7,STONE:3)
Block(6,55,8,STONE:3)
Block(6,56,-7,STONE:5)
Block(6,56,-6,STONE:5)
Block(6,56,-5,STONE:5)
Block(6,56,-4,STONE:0)
Block(6,56,-3,STONE:0)
Block(6,56,-2,STONE:0)
Block(6,56,-1,STONE:0)
Block(6,56,0,STONE:0)
Block(6,56,1,STONE:0)
Block(6,56,2,STONE:0)
Block(6,56,3,STONE:0)
Block(6,56,4,STONE:0)
Block(6,56,5,STONE:0)
Block(6,56,6,STONE:3)
Block(6,56,7,STONE:3)
Block(6,56,8,STONE:3)
Block(6,57,-7,STONE:5)
Block(6,57,-6,STONE:5)
Block(6,57,-5,STONE:5)
Block(6,57,-4,STONE:5)
Block(6,57,-3,STONE:0)
Block(6,57,-2,STONE:0)
Block(6,57,-1,STONE:0)
Block(6,57,0,STONE:0)
Block(6,57,1,STONE:0)
Block(6,57,2,STONE:0)
Block(6,57,3,STONE:0)
Block(6,57,4,STONE:0)
Block(6,57,5,STONE:0)
Block(6,57,6,STONE:3)
Block(6,57,7,STONE:3)
Block(6,57,8,STONE:3)
Block(6,58,-7,STONE:5)
Block(6,58,-6,STONE:5)
Block(6,58,-5,STONE:5)
Block(6,58,-4,STONE:5)
Block(6,58,-3,STONE:5)
Block(6,58,-2,STONE:0)
Block(6,58,-1,STONE:0)
Block(6,58,0,STONE:0)
Block(6,58,1,STONE:0)
Block(6,58,2,STONE:0)
Block(6,58,3,STONE:0)
Block(6,58,4,STONE:0)
Block(6,58,5,STONE:0)
Block(6,58,6,STONE:3)
Block(6,58,7,STONE:3)
Block(6,58,8,STONE:3)
Block(6,59,-7,STONE:5)
Block(6,59,-6,STONE:5)
Block(6,59,-5,STONE:5)
Block(6,59,-4,STONE:5)
Block(6,59,-3,STONE:5)
Block(6,59,-2,STONE:5)
Block(6,59,-1,STONE:3)
Block(6,59,0,STONE:3)
Block(6,59,1,STONE:3)
Block(6,59,2,STONE:3)
Block(6,59,3,STONE:3)
Block(6,59,4,STONE:0)
Block(6,59,5,STONE:0)
Block(6,59,6,STONE:3)
Block(6,59,7,STONE:3)
Block(6,59,8,STONE:3)
Block(6,60,-7,STONE:5)
Block(6,60,-6,STONE:5)
Block(6,60,-5,STONE:5)
Block(6,60,-4,STONE:5)
Block(6,60,-3,STONE:5)
Block(6,60,-2,STONE:3)
Block(6,60,-1,STONE:3)
Block(6,60,0,STONE:3)
Block(6,60,1,STONE:3)
Block(6,60,2,STONE:3)
Block(6,60,3,STONE:3)
Block(6,60,4,STONE:3)
Block(6,60,5,STONE:3)
Block(6,60,6,STONE:3)
Block(6,60,7,STONE:3)
Block(6,60,8,STONE:3)
Block(6,61,-7,STONE:5)
Block(6,61,-6,STONE:5)
Block(6,61,-5,STONE:5)
Block(6,61,-4,STONE:5)
Block(6,61,-3,STONE:3)
Block(6,61,-2,STONE:3)
Block(6,61,-1,STONE:3)
Block(6,61,0,STONE:3)
Block(6,61,1,STONE:3)
Block(6,61,2,STONE:3)
Block(6,61,3,STONE:3)
Block(6,61,4,STONE:3)
Block(6,61,5,STONE:3)
Block(6,61,6,STONE:3)
Block(6,61,7,STONE:3)
Block(6,61,8,STONE:3)
Block(6,62,-7,STONE:5)
Block(6,62,-6,STONE:5)
Block(6,62,-5,STONE:5)
Block(6,62,-4,STONE:5)
Block(6,62,-3,STONE:3)
Block(6,62,-2,STONE:3)
Block(6,62,-1,STONE:3)
Block(6,62,0,STONE:3)
Block(6,62,1,STONE:3)
Block(6,62,2,STONE:3)
Block(6,62,3,STONE:3)
Block(6,62,4,STONE:3)
Block(6,62,5,STONE:3)
Block(6,62,6,STONE:3)
Block(6,62,7,STONE:3)
Block(6,62,8,STONE:3)
Block(6,63,-5,STONE:5)
Block(6,63,-4,STONE:5)
Block(6,63,-3,STONE:3)
Block(6,63,-2,STONE:3)
Block(6,63,-1,STONE:3)
Block(6,63,0,STONE:3)
Block(6,63,1,STONE:3)
Block(6,63,2,STONE:3)
Block(6,63,3,STONE:3)
Block(6,63,4,STONE:3)
Block(6,63,5,STONE:3)
Block(6,63,6,STONE:3)
Block(6,63,7,STONE:3)
Block(6,64,-5,STONE:5)
Block(6,64,-4,STONE:5)
Block(6,64,-3,STONE:3)
Block(6,64,-2,STONE:3)
Block(6,64,-1,STONE:3)
Block(6,64,0,STONE:3)
Block(6,64,1,STONE:3)
Block(6,64,2,STONE:3)
Block(6,64,3,STONE:3)
Block(6,64,4,STONE:3)
Block(6,64,5,STONE:3)
Block(6,64,6,STONE:3)
Block(6,64,7,STONE:3)
Block(6,65,-2,STONE:3)
Block(6,65,-1,STONE:3)
Block(6,65,0,STONE:3)
Block(6,65,1,STONE:3)
Block(6,65,3,STONE:3)
Block(6,65,4,STONE:3)
Block(6,65,5,STONE:3)
Block(6,65,6,STONE:3)
Block(7,46,1,OBSIDIAN:0)
Block(7,46,2,OBSIDIAN:0)
Block(7,46,3,OBSIDIAN:0)
Block(7,46,4,OBSIDIAN:0)
Block(7,46,5,OBSIDIAN:0)
Block(7,46,6,OBSIDIAN:0)
Block(7,46,7,OBSIDIAN:0)
Block(7,46,8,OBSIDIAN:0)
Block(7,47,-2,STONE:5)
Block(7,47,-1,STONE:5)
Block(7,47,0,STONE:5)
Block(7,47,1,OBSIDIAN:0)
Block(7,47,2,OBSIDIAN:0)
Block(7,47,3,OBSIDIAN:0)
Block(7,47,4,OBSIDIAN:0)
Block(7,47,5,OBSIDIAN:0)
Block(7,47,6,OBSIDIAN:0)
Block(7,47,7,OBSIDIAN:0)
Block(7,47,8,OBSIDIAN:0)
Block(7,48,-3,STONE:5)
Block(7,48,-2,STONE:5)
Block(7,48,-1,STONE:5)
Block(7,48,0,STONE:5)
Block(7,48,1,STONE:5)
Block(7,48,2,OBSIDIAN:0)
Block(7,48,3,OBSIDIAN:0)
Block(7,48,4,OBSIDIAN:0)
Block(7,48,5,OBSIDIAN:0)
Block(7,48,6,OBSIDIAN:0)
Block(7,48,7,OBSIDIAN:0)
Block(7,48,8,OBSIDIAN:0)
Block(7,49,-5,STONE:5)
Block(7,49,-4,STONE:5)
Block(7,49,-3,STONE:5)
Block(7,49,-2,STONE:5)
Block(7,49,-1,STONE:5)
Block(7,49,0,STONE:5)
Block(7,49,1,STONE:5)
Block(7,49,2,STONE:5)
Block(7,49,3,STONE:0)
Block(7,49,4,STONE:5)
Block(7,49,5,STONE:5)
Block(7,49,6,STONE:5)
Block(7,49,7,STONE:5)
Block(7,49,8,OBSIDIAN:0)
Block(7,50,-7,STONE:5)
Block(7,50,-6,STONE:5)
Block(7,50,-5,STONE:5)
Block(7,50,-4,STONE:5)
Block(7,50,-3,STONE:5)
Block(7,50,-2,STONE:5)
Block(7,50,-1,STONE:5)
Block(7,50,0,STONE:5)
Block(7,50,1,STONE:5)
Block(7,50,2,STONE:5)
Block(7,50,3,STONE:0)
Block(7,50,4,STONE:5)
Block(7,50,5,STONE:5)
Block(7,50,6,STONE:5)
Block(7,50,7,STONE:5)
Block(7,50,8,STONE:5)
Block(7,51,-7,STONE:5)
Block(7,51,-6,STONE:5)
Block(7,51,-5,STONE:5)
Block(7,51,-4,STONE:5)
Block(7,51,-3,STONE:5)
Block(7,51,-2,STONE:5)
Block(7,51,-1,STONE:5)
Block(7,51,0,STONE:5)
Block(7,51,1,STONE:5)
Block(7,51,2,STONE:0)
Block(7,51,3,STONE:0)
Block(7,51,4,STONE:0)
Block(7,51,5,STONE:5)
Block(7,51,6,STONE:5)
Block(7,51,7,STONE:5)
Block(7,51,8,STONE:5)
Block(7,52,-7,STONE:5)
Block(7,52,-6,STONE:5)
Block(7,52,-5,STONE:5)
Block(7,52,-4,STONE:5)
Block(7,52,-3,STONE:5)
Block(7,52,-2,STONE:5)
Block(7,52,-1,STONE:5)
Block(7,52,0,STONE:5)
Block(7,52,1,STONE:0)
Block(7,52,2,STONE:0)
Block(7,52,3,STONE:0)
Block(7,52,4,STONE:0)
Block(7,52,5,STONE:0)
Block(7,52,6,STONE:5)
Block(7,52,7,STONE:5)
Block(7,52,8,STONE:5)
Block(7,53,-7,STONE:5)
Block(7,53,-6,STONE:5)
Block(7,53,-5,STONE:5)
Block(7,53,-4,STONE:5)
Block(7,53,-3,STONE:5)
Block(7,53,-2,STONE:5)
Block(7,53,-1,STONE:5)
Block(7,53,0,STONE:0)
Block(7,53,1,STONE:0)
Block(7,53,2,STONE:0)
Block(7,53,3,STONE:0)
Block(7,53,4,STONE:0)
Block(7,53,5,STONE:0)
Block(7,53,6,STONE:0)
Block(7,53,7,STONE:0)
Block(7,53,8,STONE:0)
Block(7,54,-7,STONE:5)
Block(7,54,-6,STONE:5)
Block(7,54,-5,STONE:5)
Block(7,54,-4,STONE:5)
Block(7,54,-3,STONE:0)
Block(7,54,-2,STONE:0)
Block(7,54,-1,STONE:0)
Block(7,54,0,STONE:0)
Block(7,54,1,STONE:0)
Block(7,54,2,STONE:0)
Block(7,54,3,STONE:0)
Block(7,54,4,STONE:0)
Block(7,54,5,STONE:0)
Block(7,54,6,STONE:0)
Block(7,54,7,STONE:0)
Block(7,54,8,STONE:0)
Block(7,55,-7,STONE:5)
Block(7,55,-6,STONE:5)
Block(7,55,-5,STONE:5)
Block(7,55,-4,STONE:0)
Block(7,55,-3,STONE:0)
Block(7,55,-2,STONE:0)
Block(7,55,-1,STONE:0)
Block(7,55,0,STONE:0)
Block(7,55,1,STONE:0)
Block(7,55,2,STONE:0)
Block(7,55,3,STONE:0)
Block(7,55,4,STONE:0)
Block(7,55,5,STONE:0)
Block(7,55,6,STONE:0)
Block(7,55,7,STONE:0)
Block(7,55,8,STONE:0)
Block(7,56,-7,STONE:5)
Block(7,56,-6,STONE:5)
Block(7,56,-5,STONE:5)
Block(7,56,-4,STONE:5)
Block(7,56,-3,STONE:0)
Block(7,56,-2,STONE:0)
Block(7,56,-1,STONE:0)
Block(7,56,0,STONE:0)
Block(7,56,1,STONE:0)
Block(7,56,2,STONE:0)
Block(7,56,3,STONE:0)
Block(7,56,4,STONE:0)
Block(7,56,5,STONE:0)
Block(7,56,6,STONE:0)
Block(7,56,7,STONE:0)
Block(7,56,8,STONE:3)
Block(7,57,-7,STONE:5)
Block(7,57,-6,STONE:5)
Block(7,57,-5,STONE:5)
Block(7,57,-4,STONE:5)
Block(7,57,-3,STONE:0)
Block(7,57,-2,STONE:0)
Block(7,57,-1,STONE:0)
Block(7,57,0,STONE:0)
Block(7,57,1,STONE:0)
Block(7,57,2,STONE:0)
Block(7,57,3,STONE:0)
Block(7,57,4,STONE:0)
Block(7,57,5,STONE:0)
Block(7,57,6,STONE:0)
Block(7,57,7,STONE:3)
Block(7,57,8,STONE:3)
Block(7,58,-7,STONE:5)
Block(7,58,-6,STONE:5)
Block(7,58,-5,STONE:5)
Block(7,58,-4,STONE:5)
Block(7,58,-3,STONE:5)
Block(7,58,-2,STONE:0)
Block(7,58,-1,STONE:0)
Block(7,58,0,STONE:0)
Block(7,58,1,STONE:0)
Block(7,58,2,STONE:0)
Block(7,58,3,STONE:0)
Block(7,58,4,STONE:0)
Block(7,58,5,STONE:0)
Block(7,58,6,STONE:0)
Block(7,58,7,STONE:3)
Block(7,58,8,STONE:3)
Block(7,59,-7,STONE:5)
Block(7,59,-6,STONE:5)
Block(7,59,-5,STONE:5)
Block(7,59,-4,STONE:5)
Block(7,59,-3,STONE:5)
Block(7,59,-2,STONE:5)
Block(7,59,-1,STONE:5)
Block(7,59,0,STONE:0)
Block(7,59,1,STONE:0)
Block(7,59,2,STONE:0)
Block(7,59,3,STONE:0)
Block(7,59,4,STONE:0)
Block(7,59,5,STONE:0)
Block(7,59,6,STONE:0)
Block(7,59,7,STONE:3)
Block(7,59,8,STONE:3)
Block(7,60,-7,STONE:5)
Block(7,60,-6,STONE:5)
Block(7,60,-5,STONE:5)
Block(7,60,-4,STONE:5)
Block(7,60,-3,STONE:5)
Block(7,60,-2,STONE:5)
Block(7,60,-1,STONE:3)
Block(7,60,0,STONE:3)
Block(7,60,1,STONE:3)
Block(7,60,2,STONE:3)
Block(7,60,3,STONE:3)
Block(7,60,4,STONE:0)
Block(7,60,5,STONE:3)
Block(7,60,6,STONE:3)
Block(7,60,7,STONE:3)
Block(7,60,8,STONE:3)
Block(7,61,-7,STONE:5)
Block(7,61,-6,STONE:5)
Block(7,61,-5,STONE:5)
Block(7,61,-4,STONE:5)
Block(7,61,-3,STONE:5)
Block(7,61,-2,STONE:3)
Block(7,61,-1,STONE:3)
Block(7,61,0,STONE:3)
Block(7,61,1,STONE:3)
Block(7,61,2,STONE:3)
Block(7,61,3,STONE:3)
Block(7,61,4,STONE:3)
Block(7,61,5,STONE:3)
Block(7,61,6,STONE:3)
Block(7,61,7,STONE:3)
Block(7,61,8,STONE:3)
Block(7,62,-7,STONE:5)
Block(7,62,-6,STONE:5)
Block(7,62,-5,STONE:5)
Block(7,62,-4,STONE:5)
Block(7,62,-3,STONE:5)
Block(7,62,-2,STONE:3)
Block(7,62,-1,STONE:3)
Block(7,62,0,STONE:3)
Block(7,62,1,STONE:3)
Block(7,62,2,STONE:3)
Block(7,62,3,STONE:3)
Block(7,62,4,STONE:3)
Block(7,62,5,STONE:3)
Block(7,62,6,STONE:3)
Block(7,62,7,STONE:3)
Block(7,62,8,STONE:3)
Block(7,63,-5,STONE:5)
Block(7,63,-4,STONE:5)
Block(7,63,-3,STONE:5)
Block(7,63,-2,STONE:3)
Block(7,63,-1,STONE:3)
Block(7,63,0,STONE:3)
Block(7,63,1,STONE:3)
Block(7,63,2,STONE:3)
Block(7,63,3,STONE:3)
Block(7,63,4,STONE:3)
Block(7,63,5,STONE:3)
Block(7,63,6,STONE:3)
Block(7,63,7,STONE:3)
Block(7,63,8,STONE:3)
Block(7,64,-3,STONE:5)
Block(7,64,-2,STONE:3)
Block(7,64,-1,STONE:3)
Block(7,64,0,STONE:3)
Block(7,64,1,STONE:3)
Block(7,64,2,STONE:3)
Block(7,64,3,STONE:3)
Block(7,64,4,STONE:3)
Block(7,64,5,STONE:3)
Block(7,64,6,STONE:3)
Block(7,64,7,STONE:3)
Block(7,64,8,STONE:3)
Block(7,65,-2,STONE:3)
Block(7,65,-1,STONE:3)
Block(7,65,0,STONE:3)
Block(7,65,1,STONE:3)
Block(7,65,2,STONE:3)
Block(7,65,3,STONE:3)
Block(7,65,4,STONE:3)
Block(7,65,5,STONE:3)
Block(7,65,6,STONE:3)
Block(7,65,7,STONE:3)

#######################################################################
# +-----------------------------------------------------------------+ #
# |                             Branches                            | #
# +-----------------------------------------------------------------+ #
#######################################################################

Branch(0,0,-16,true,Amethyst_MediumC1R0,NORTH,100.0,0)

#######################################################################
# +-----------------------------------------------------------------+ #
# |                             Entities                            | #
# +-----------------------------------------------------------------+ #
#######################################################################


#######################################################################
# +-----------------------------------------------------------------+ #
# |                            Particles                            | #
# +-----------------------------------------------------------------+ #
#######################################################################


#######################################################################
# +-----------------------------------------------------------------+ #
# |                             Spawners                            | #
# +-----------------------------------------------------------------+ #
#######################################################################


#######################################################################
# +-----------------------------------------------------------------+ #
# |                             ModData                             | #
# +-----------------------------------------------------------------+ #
#######################################################################

