#######################################################################
# +-----------------------------------------------------------------+ #
# |                            BO3 object                           | #
# +-----------------------------------------------------------------+ #
#######################################################################

# This is the config file of a custom object.
# If you add this object correctly to your BiomeConfigs, it will spawn in the world.

# This is the creator of this BO3 object
Author: BO3 BulkEdit (by LanToaster)

# A short description of this BO3 object
Description: This Object was Created with BO3_BulkEdit

# The BO3 version, don't change this! It can be used by external applications to do a version check.
Version: 3

# The settings mode, WriteAll, WriteWithoutComments or WriteDisable. See WorldConfig.
SettingsMode: WriteDisable


#######################################################################
# +-----------------------------------------------------------------+ #
# |                          Main settings                          | #
# +-----------------------------------------------------------------+ #
#######################################################################

# This needs to be set to true to spawn the object in the Tree and Sapling resources.
Tree: false

# The frequency of the BO3 from 1 to 200. Tries this many times to spawn this BO3 when using the CustomObject(...) resource.

Frequency: 1

# The rarity of the BO3 from 0 to 100. Each spawn attempt has rarity% chance to succeed when using the CustomObject(...) resource.

Rarity: 100.0

# If you set this to true, the BO3 will be placed with a random rotation.
RotateRandomly: false

# The spawn height of the BO3 - randomY, highestBlock or highestSolidBlock.
SpawnHeight: randomY

# The height limits for the BO3.
MinHeight: 82

MaxHeight: 82

# Objects can have other objects attacthed to it: branches. Branches can also
# have branches attached to it, which can also have branches, etc. This is the
# maximum branch depth for this objects.
MaxBranchDepth: 10

# When spawned with the UseWorld keyword, this BO3 should NOT spawn in the following biomes.
# If you writer.write the BO3 name directly in the BiomeConfigs, this will be ignored.
ExcludedBiomes: All


#######################################################################
# +-----------------------------------------------------------------+ #
# |                      Source block settings                      | #
# +-----------------------------------------------------------------+ #
#######################################################################

# The block(s) the BO3 should spawn in.
SourceBlocks: AIR

# The maximum percentage of the BO3 that can be outside the SourceBlock.
# The BO3 won't be placed on a location with more blocks outside the SourceBlock than this percentage.
MaxPercentageOutsideSourceBlock: 100

# What to do when a block is about to be placed outside the SourceBlock? (dontPlace, placeAnyway)
OutsideSourceBlock: placeAnyway


#######################################################################
# +-----------------------------------------------------------------+ #
# |                              Blocks                             | #
# +-----------------------------------------------------------------+ #
#######################################################################

# All the blocks used in the BO3 are listed here. Possible blocks:
# Block(x,y,z,id[.data][,nbtfile.nbt)
# RandomBlock(x,y,z,id[:data][,nbtfile.nbt],chance[,id[:data][,nbtfile.nbt],chance[,...]])
# So RandomBlock(0,0,0,CHEST:0,chest.nbt,50,CHEST:0,anotherchest.nbt,100) will spawn a chest at
# the BO3 origin, and give it a 50% chance to have the contents of chest.nbt, or, if that
# fails, a 100% percent chance to have the contents of anotherchest.nbt.
Block(-3,-10,-7,LOG:3)
Block(-2,-10,-7,DIRT:0)
Block(-1,-10,-7,DIRT:0)
Block(0,-10,-7,DIRT:0)
Block(1,-10,-7,DIRT:0)
Block(2,-10,-7,DIRT:0)
Block(3,-10,-7,DIRT:0)
Block(4,-10,-7,DIRT:0)
Block(5,-10,-7,DIRT:0)
Block(6,-10,-7,DIRT:0)
Block(7,-10,-7,DIRT:0)
Block(8,-10,-7,DIRT:0)
Block(-2,-10,-6,PLANKS:3)
Block(-1,-10,-6,DIRT:0)
Block(0,-10,-6,DIRT:0)
Block(1,-10,-6,DIRT:0)
Block(2,-10,-6,DIRT:0)
Block(3,-10,-6,DIRT:0)
Block(4,-10,-6,DIRT:0)
Block(5,-10,-6,DIRT:0)
Block(6,-10,-6,DIRT:0)
Block(7,-10,-6,DIRT:0)
Block(8,-10,-6,DIRT:0)
Block(-2,-10,-5,PLANKS:3)
Block(-1,-10,-5,DIRT:0)
Block(0,-10,-5,DIRT:0)
Block(1,-10,-5,DIRT:0)
Block(2,-10,-5,DIRT:0)
Block(3,-10,-5,DIRT:0)
Block(4,-10,-5,DIRT:0)
Block(5,-10,-5,DIRT:0)
Block(6,-10,-5,DIRT:0)
Block(7,-10,-5,DIRT:0)
Block(8,-10,-5,DIRT:0)
Block(-2,-10,-4,PLANKS:3)
Block(-1,-10,-4,DIRT:0)
Block(0,-10,-4,DIRT:0)
Block(1,-10,-4,DIRT:0)
Block(2,-10,-4,DIRT:0)
Block(3,-10,-4,DIRT:0)
Block(4,-10,-4,DIRT:0)
Block(5,-10,-4,DIRT:0)
Block(6,-10,-4,DIRT:0)
Block(7,-10,-4,DIRT:0)
Block(8,-10,-4,DIRT:0)
Block(-1,-10,-3,PLANKS:3)
Block(0,-10,-3,DIRT:0)
Block(1,-10,-3,DIRT:0)
Block(2,-10,-3,DIRT:0)
Block(3,-10,-3,DIRT:0)
Block(4,-10,-3,DIRT:0)
Block(5,-10,-3,DIRT:0)
Block(6,-10,-3,DIRT:0)
Block(7,-10,-3,DIRT:0)
Block(8,-10,-3,DIRT:0)
Block(-1,-10,-2,LOG:3)
Block(0,-10,-2,DIRT:0)
Block(1,-10,-2,DIRT:0)
Block(2,-10,-2,DIRT:0)
Block(3,-10,-2,DIRT:0)
Block(4,-10,-2,DIRT:0)
Block(5,-10,-2,DIRT:0)
Block(6,-10,-2,DIRT:0)
Block(7,-10,-2,DIRT:0)
Block(8,-10,-2,DIRT:0)
Block(-1,-10,-1,PLANKS:3)
Block(0,-10,-1,DIRT:0)
Block(1,-10,-1,DIRT:0)
Block(2,-10,-1,DIRT:0)
Block(3,-10,-1,DIRT:0)
Block(4,-10,-1,DIRT:0)
Block(5,-10,-1,DIRT:0)
Block(6,-10,-1,DIRT:0)
Block(7,-10,-1,DIRT:0)
Block(8,-10,-1,DIRT:0)
Block(-1,-10,0,PLANKS:3)
Block(0,-10,0,DIRT:0)
Block(1,-10,0,DIRT:0)
Block(2,-10,0,DIRT:0)
Block(3,-10,0,DIRT:0)
Block(4,-10,0,DIRT:0)
Block(5,-10,0,DIRT:0)
Block(6,-10,0,DIRT:0)
Block(7,-10,0,DIRT:0)
Block(8,-10,0,DIRT:0)
Block(-1,-10,1,PLANKS:3)
Block(0,-10,1,DIRT:0)
Block(1,-10,1,DIRT:0)
Block(2,-10,1,DIRT:0)
Block(3,-10,1,DIRT:0)
Block(4,-10,1,DIRT:0)
Block(5,-10,1,DIRT:0)
Block(6,-10,1,DIRT:0)
Block(7,-10,1,DIRT:0)
Block(8,-10,1,DIRT:0)
Block(-2,-10,2,LOG:3)
Block(-1,-10,2,DIRT:0)
Block(0,-10,2,DIRT:0)
Block(1,-10,2,DIRT:0)
Block(2,-10,2,DIRT:0)
Block(3,-10,2,DIRT:0)
Block(4,-10,2,DIRT:0)
Block(5,-10,2,DIRT:0)
Block(6,-10,2,DIRT:0)
Block(7,-10,2,DIRT:0)
Block(8,-10,2,DIRT:0)
Block(-2,-10,3,PLANKS:3)
Block(-1,-10,3,DIRT:0)
Block(0,-10,3,DIRT:0)
Block(1,-10,3,DIRT:0)
Block(2,-10,3,DIRT:0)
Block(3,-10,3,DIRT:0)
Block(4,-10,3,DIRT:0)
Block(5,-10,3,DIRT:0)
Block(6,-10,3,DIRT:0)
Block(7,-10,3,DIRT:0)
Block(8,-10,3,DIRT:0)
Block(-3,-10,4,PLANKS:3)
Block(-2,-10,4,DIRT:0)
Block(-1,-10,4,DIRT:0)
Block(0,-10,4,DIRT:0)
Block(1,-10,4,DIRT:0)
Block(2,-10,4,DIRT:0)
Block(3,-10,4,DIRT:0)
Block(4,-10,4,DIRT:0)
Block(5,-10,4,DIRT:0)
Block(6,-10,4,DIRT:0)
Block(7,-10,4,DIRT:0)
Block(8,-10,4,DIRT:0)
Block(-4,-10,5,LOG:3)
Block(-3,-10,5,DIRT:0)
Block(-2,-10,5,DIRT:0)
Block(-1,-10,5,DIRT:0)
Block(0,-10,5,DIRT:0)
Block(1,-10,5,DIRT:0)
Block(2,-10,5,DIRT:0)
Block(3,-10,5,DIRT:0)
Block(4,-10,5,DIRT:0)
Block(5,-10,5,DIRT:0)
Block(6,-10,5,DIRT:0)
Block(7,-10,5,DIRT:0)
Block(8,-10,5,DIRT:0)
Block(-5,-10,6,PLANKS:3)
Block(-4,-10,6,DIRT:0)
Block(-3,-10,6,DIRT:0)
Block(-2,-10,6,DIRT:0)
Block(-1,-10,6,DIRT:0)
Block(0,-10,6,DIRT:0)
Block(1,-10,6,DIRT:0)
Block(2,-10,6,DIRT:0)
Block(3,-10,6,DIRT:0)
Block(4,-10,6,DIRT:0)
Block(5,-10,6,DIRT:0)
Block(6,-10,6,DIRT:0)
Block(7,-10,6,DIRT:0)
Block(8,-10,6,DIRT:0)
Block(-5,-10,7,PLANKS:3)
Block(-4,-10,7,DIRT:0)
Block(-3,-10,7,DIRT:0)
Block(-2,-10,7,DIRT:0)
Block(-1,-10,7,DIRT:0)
Block(0,-10,7,DIRT:0)
Block(1,-10,7,DIRT:0)
Block(2,-10,7,DIRT:0)
Block(3,-10,7,DIRT:0)
Block(4,-10,7,DIRT:0)
Block(5,-10,7,DIRT:0)
Block(6,-10,7,DIRT:0)
Block(7,-10,7,DIRT:0)
Block(8,-10,7,DIRT:0)
Block(-6,-10,8,PLANKS:3)
Block(-5,-10,8,DIRT:0)
Block(-4,-10,8,DIRT:0)
Block(-3,-10,8,DIRT:0)
Block(-2,-10,8,DIRT:0)
Block(-1,-10,8,DIRT:0)
Block(0,-10,8,DIRT:0)
Block(1,-10,8,DIRT:0)
Block(2,-10,8,DIRT:0)
Block(3,-10,8,DIRT:0)
Block(4,-10,8,DIRT:0)
Block(5,-10,8,DIRT:0)
Block(6,-10,8,DIRT:0)
Block(7,-10,8,DIRT:0)
Block(8,-10,8,DIRT:0)
Block(-3,-9,-7,LOG:3)
Block(-2,-9,-7,DIRT:0)
Block(-1,-9,-7,DIRT:0)
Block(0,-9,-7,DIRT:0)
Block(1,-9,-7,DIRT:0)
Block(2,-9,-7,DIRT:0)
Block(3,-9,-7,DIRT:0)
Block(4,-9,-7,DIRT:0)
Block(5,-9,-7,DIRT:0)
Block(6,-9,-7,DIRT:0)
Block(7,-9,-7,DIRT:0)
Block(8,-9,-7,DIRT:0)
Block(-2,-9,-6,PLANKS:3)
Block(-1,-9,-6,DIRT:0)
Block(0,-9,-6,DIRT:0)
Block(1,-9,-6,DIRT:0)
Block(2,-9,-6,DIRT:0)
Block(3,-9,-6,DIRT:0)
Block(4,-9,-6,DIRT:0)
Block(5,-9,-6,DIRT:0)
Block(6,-9,-6,DIRT:0)
Block(7,-9,-6,DIRT:0)
Block(8,-9,-6,DIRT:0)
Block(-2,-9,-5,PLANKS:3)
Block(-1,-9,-5,DIRT:0)
Block(0,-9,-5,DIRT:0)
Block(1,-9,-5,DIRT:0)
Block(2,-9,-5,DIRT:0)
Block(3,-9,-5,DIRT:0)
Block(4,-9,-5,DIRT:0)
Block(5,-9,-5,DIRT:0)
Block(6,-9,-5,DIRT:0)
Block(7,-9,-5,DIRT:0)
Block(8,-9,-5,DIRT:0)
Block(-2,-9,-4,PLANKS:3)
Block(-1,-9,-4,DIRT:0)
Block(0,-9,-4,DIRT:0)
Block(1,-9,-4,DIRT:0)
Block(2,-9,-4,DIRT:0)
Block(3,-9,-4,DIRT:0)
Block(4,-9,-4,DIRT:0)
Block(5,-9,-4,DIRT:0)
Block(6,-9,-4,DIRT:0)
Block(7,-9,-4,DIRT:0)
Block(8,-9,-4,DIRT:0)
Block(-1,-9,-3,PLANKS:3)
Block(0,-9,-3,DIRT:0)
Block(1,-9,-3,DIRT:0)
Block(2,-9,-3,DIRT:0)
Block(3,-9,-3,DIRT:0)
Block(4,-9,-3,DIRT:0)
Block(5,-9,-3,DIRT:0)
Block(6,-9,-3,DIRT:0)
Block(7,-9,-3,DIRT:0)
Block(8,-9,-3,DIRT:0)
Block(-1,-9,-2,LOG:3)
Block(0,-9,-2,DIRT:0)
Block(1,-9,-2,DIRT:0)
Block(2,-9,-2,DIRT:0)
Block(3,-9,-2,DIRT:0)
Block(4,-9,-2,DIRT:0)
Block(5,-9,-2,DIRT:0)
Block(6,-9,-2,DIRT:0)
Block(7,-9,-2,DIRT:0)
Block(8,-9,-2,DIRT:0)
Block(-1,-9,-1,PLANKS:3)
Block(0,-9,-1,DIRT:0)
Block(1,-9,-1,DIRT:0)
Block(2,-9,-1,DIRT:0)
Block(3,-9,-1,DIRT:0)
Block(4,-9,-1,DIRT:0)
Block(5,-9,-1,DIRT:0)
Block(6,-9,-1,DIRT:0)
Block(7,-9,-1,DIRT:0)
Block(8,-9,-1,DIRT:0)
Block(-1,-9,0,PLANKS:3)
Block(0,-9,0,DIRT:0)
Block(1,-9,0,DIRT:0)
Block(2,-9,0,DIRT:0)
Block(3,-9,0,DIRT:0)
Block(4,-9,0,DIRT:0)
Block(5,-9,0,DIRT:0)
Block(6,-9,0,DIRT:0)
Block(7,-9,0,DIRT:0)
Block(8,-9,0,DIRT:0)
Block(-1,-9,1,PLANKS:3)
Block(0,-9,1,DIRT:0)
Block(1,-9,1,DIRT:0)
Block(2,-9,1,DIRT:0)
Block(3,-9,1,DIRT:0)
Block(4,-9,1,DIRT:0)
Block(5,-9,1,DIRT:0)
Block(6,-9,1,DIRT:0)
Block(7,-9,1,DIRT:0)
Block(8,-9,1,DIRT:0)
Block(-2,-9,2,LOG:3)
Block(-1,-9,2,DIRT:0)
Block(0,-9,2,DIRT:0)
Block(1,-9,2,DIRT:0)
Block(2,-9,2,DIRT:0)
Block(3,-9,2,DIRT:0)
Block(4,-9,2,DIRT:0)
Block(5,-9,2,DIRT:0)
Block(6,-9,2,DIRT:0)
Block(7,-9,2,DIRT:0)
Block(8,-9,2,DIRT:0)
Block(-2,-9,3,PLANKS:3)
Block(-1,-9,3,DIRT:0)
Block(0,-9,3,DIRT:0)
Block(1,-9,3,DIRT:0)
Block(2,-9,3,DIRT:0)
Block(3,-9,3,DIRT:0)
Block(4,-9,3,DIRT:0)
Block(5,-9,3,DIRT:0)
Block(6,-9,3,DIRT:0)
Block(7,-9,3,DIRT:0)
Block(8,-9,3,DIRT:0)
Block(-3,-9,4,PLANKS:3)
Block(-2,-9,4,DIRT:0)
Block(-1,-9,4,DIRT:0)
Block(0,-9,4,DIRT:0)
Block(1,-9,4,DIRT:0)
Block(2,-9,4,DIRT:0)
Block(3,-9,4,DIRT:0)
Block(4,-9,4,DIRT:0)
Block(5,-9,4,DIRT:0)
Block(6,-9,4,DIRT:0)
Block(7,-9,4,DIRT:0)
Block(8,-9,4,DIRT:0)
Block(-4,-9,5,LOG:3)
Block(-3,-9,5,DIRT:0)
Block(-2,-9,5,DIRT:0)
Block(-1,-9,5,DIRT:0)
Block(0,-9,5,DIRT:0)
Block(1,-9,5,DIRT:0)
Block(2,-9,5,DIRT:0)
Block(3,-9,5,DIRT:0)
Block(4,-9,5,DIRT:0)
Block(5,-9,5,DIRT:0)
Block(6,-9,5,DIRT:0)
Block(7,-9,5,DIRT:0)
Block(8,-9,5,DIRT:0)
Block(-5,-9,6,PLANKS:3)
Block(-4,-9,6,DIRT:0)
Block(-3,-9,6,DIRT:0)
Block(-2,-9,6,DIRT:0)
Block(-1,-9,6,DIRT:0)
Block(0,-9,6,DIRT:0)
Block(1,-9,6,DIRT:0)
Block(2,-9,6,DIRT:0)
Block(3,-9,6,DIRT:0)
Block(4,-9,6,DIRT:0)
Block(5,-9,6,DIRT:0)
Block(6,-9,6,DIRT:0)
Block(7,-9,6,DIRT:0)
Block(8,-9,6,DIRT:0)
Block(-5,-9,7,PLANKS:3)
Block(-4,-9,7,DIRT:0)
Block(-3,-9,7,DIRT:0)
Block(-2,-9,7,DIRT:0)
Block(-1,-9,7,DIRT:0)
Block(0,-9,7,DIRT:0)
Block(1,-9,7,DIRT:0)
Block(2,-9,7,DIRT:0)
Block(3,-9,7,DIRT:0)
Block(4,-9,7,DIRT:0)
Block(5,-9,7,DIRT:0)
Block(6,-9,7,DIRT:0)
Block(7,-9,7,DIRT:0)
Block(8,-9,7,DIRT:0)
Block(-6,-9,8,PLANKS:3)
Block(-5,-9,8,DIRT:0)
Block(-4,-9,8,DIRT:0)
Block(-3,-9,8,DIRT:0)
Block(-2,-9,8,DIRT:0)
Block(-1,-9,8,DIRT:0)
Block(0,-9,8,DIRT:0)
Block(1,-9,8,DIRT:0)
Block(2,-9,8,DIRT:0)
Block(3,-9,8,DIRT:0)
Block(4,-9,8,DIRT:0)
Block(5,-9,8,DIRT:0)
Block(6,-9,8,DIRT:0)
Block(7,-9,8,DIRT:0)
Block(8,-9,8,DIRT:0)
Block(-3,-8,-7,LOG:3)
Block(-2,-8,-7,DIRT:0)
Block(-1,-8,-7,DIRT:0)
Block(0,-8,-7,DIRT:0)
Block(1,-8,-7,DIRT:0)
Block(2,-8,-7,DIRT:0)
Block(3,-8,-7,DIRT:0)
Block(4,-8,-7,DIRT:0)
Block(5,-8,-7,DIRT:0)
Block(6,-8,-7,DIRT:0)
Block(7,-8,-7,DIRT:0)
Block(8,-8,-7,DIRT:0)
Block(-2,-8,-6,PLANKS:3)
Block(-1,-8,-6,DIRT:0)
Block(0,-8,-6,DIRT:0)
Block(1,-8,-6,DIRT:0)
Block(2,-8,-6,DIRT:0)
Block(3,-8,-6,DIRT:0)
Block(4,-8,-6,DIRT:0)
Block(5,-8,-6,DIRT:0)
Block(6,-8,-6,DIRT:0)
Block(7,-8,-6,DIRT:0)
Block(8,-8,-6,DIRT:0)
Block(-2,-8,-5,PLANKS:3)
Block(-1,-8,-5,DIRT:0)
Block(0,-8,-5,DIRT:0)
Block(1,-8,-5,DIRT:0)
Block(2,-8,-5,DIRT:0)
Block(3,-8,-5,DIRT:0)
Block(4,-8,-5,DIRT:0)
Block(5,-8,-5,DIRT:0)
Block(6,-8,-5,DIRT:0)
Block(7,-8,-5,DIRT:0)
Block(8,-8,-5,DIRT:0)
Block(-2,-8,-4,PLANKS:3)
Block(-1,-8,-4,DIRT:0)
Block(0,-8,-4,DIRT:0)
Block(1,-8,-4,DIRT:0)
Block(2,-8,-4,DIRT:0)
Block(3,-8,-4,DIRT:0)
Block(4,-8,-4,DIRT:0)
Block(5,-8,-4,DIRT:0)
Block(6,-8,-4,DIRT:0)
Block(7,-8,-4,DIRT:0)
Block(8,-8,-4,DIRT:0)
Block(-1,-8,-3,PLANKS:3)
Block(0,-8,-3,DIRT:0)
Block(1,-8,-3,DIRT:0)
Block(2,-8,-3,DIRT:0)
Block(3,-8,-3,DIRT:0)
Block(4,-8,-3,DIRT:0)
Block(5,-8,-3,DIRT:0)
Block(6,-8,-3,DIRT:0)
Block(7,-8,-3,DIRT:0)
Block(8,-8,-3,DIRT:0)
Block(-1,-8,-2,LOG:3)
Block(0,-8,-2,DIRT:0)
Block(1,-8,-2,DIRT:0)
Block(2,-8,-2,DIRT:0)
Block(3,-8,-2,DIRT:0)
Block(4,-8,-2,DIRT:0)
Block(5,-8,-2,DIRT:0)
Block(6,-8,-2,DIRT:0)
Block(7,-8,-2,DIRT:0)
Block(8,-8,-2,DIRT:0)
Block(-1,-8,-1,PLANKS:3)
Block(0,-8,-1,DIRT:0)
Block(1,-8,-1,DIRT:0)
Block(2,-8,-1,DIRT:0)
Block(3,-8,-1,DIRT:0)
Block(4,-8,-1,DIRT:0)
Block(5,-8,-1,DIRT:0)
Block(6,-8,-1,DIRT:0)
Block(7,-8,-1,DIRT:0)
Block(8,-8,-1,DIRT:0)
Block(-1,-8,0,PLANKS:3)
Block(0,-8,0,DIRT:0)
Block(1,-8,0,DIRT:0)
Block(2,-8,0,DIRT:0)
Block(3,-8,0,DIRT:0)
Block(4,-8,0,DIRT:0)
Block(5,-8,0,DIRT:0)
Block(6,-8,0,DIRT:0)
Block(7,-8,0,DIRT:0)
Block(8,-8,0,DIRT:0)
Block(-1,-8,1,PLANKS:3)
Block(0,-8,1,DIRT:0)
Block(1,-8,1,DIRT:0)
Block(2,-8,1,DIRT:0)
Block(3,-8,1,DIRT:0)
Block(4,-8,1,DIRT:0)
Block(5,-8,1,DIRT:0)
Block(6,-8,1,DIRT:0)
Block(7,-8,1,DIRT:0)
Block(8,-8,1,DIRT:0)
Block(-2,-8,2,LOG:3)
Block(-1,-8,2,DIRT:0)
Block(0,-8,2,DIRT:0)
Block(1,-8,2,DIRT:0)
Block(2,-8,2,DIRT:0)
Block(3,-8,2,DIRT:0)
Block(4,-8,2,DIRT:0)
Block(5,-8,2,DIRT:0)
Block(6,-8,2,DIRT:0)
Block(7,-8,2,DIRT:0)
Block(8,-8,2,DIRT:0)
Block(-2,-8,3,PLANKS:3)
Block(-1,-8,3,DIRT:0)
Block(0,-8,3,DIRT:0)
Block(1,-8,3,DIRT:0)
Block(2,-8,3,DIRT:0)
Block(3,-8,3,DIRT:0)
Block(4,-8,3,DIRT:0)
Block(5,-8,3,DIRT:0)
Block(6,-8,3,DIRT:0)
Block(7,-8,3,DIRT:0)
Block(8,-8,3,DIRT:0)
Block(-3,-8,4,PLANKS:3)
Block(-2,-8,4,DIRT:0)
Block(-1,-8,4,DIRT:0)
Block(0,-8,4,DIRT:0)
Block(1,-8,4,DIRT:0)
Block(2,-8,4,DIRT:0)
Block(3,-8,4,DIRT:0)
Block(4,-8,4,DIRT:0)
Block(5,-8,4,DIRT:0)
Block(6,-8,4,DIRT:0)
Block(7,-8,4,DIRT:0)
Block(8,-8,4,DIRT:0)
Block(-4,-8,5,LOG:3)
Block(-3,-8,5,DIRT:0)
Block(-2,-8,5,DIRT:0)
Block(-1,-8,5,DIRT:0)
Block(0,-8,5,DIRT:0)
Block(1,-8,5,DIRT:0)
Block(2,-8,5,DIRT:0)
Block(3,-8,5,DIRT:0)
Block(4,-8,5,DIRT:0)
Block(5,-8,5,DIRT:0)
Block(6,-8,5,DIRT:0)
Block(7,-8,5,DIRT:0)
Block(8,-8,5,DIRT:0)
Block(-5,-8,6,PLANKS:3)
Block(-4,-8,6,DIRT:0)
Block(-3,-8,6,DIRT:0)
Block(-2,-8,6,DIRT:0)
Block(-1,-8,6,DIRT:0)
Block(0,-8,6,DIRT:0)
Block(1,-8,6,DIRT:0)
Block(2,-8,6,DIRT:0)
Block(3,-8,6,DIRT:0)
Block(4,-8,6,DIRT:0)
Block(5,-8,6,DIRT:0)
Block(6,-8,6,DIRT:0)
Block(7,-8,6,DIRT:0)
Block(8,-8,6,DIRT:0)
Block(-5,-8,7,PLANKS:3)
Block(-4,-8,7,DIRT:0)
Block(-3,-8,7,DIRT:0)
Block(-2,-8,7,DIRT:0)
Block(-1,-8,7,DIRT:0)
Block(0,-8,7,DIRT:0)
Block(1,-8,7,DIRT:0)
Block(2,-8,7,DIRT:0)
Block(3,-8,7,DIRT:0)
Block(4,-8,7,DIRT:0)
Block(5,-8,7,DIRT:0)
Block(6,-8,7,DIRT:0)
Block(7,-8,7,DIRT:0)
Block(8,-8,7,DIRT:0)
Block(-6,-8,8,PLANKS:3)
Block(-5,-8,8,DIRT:0)
Block(-4,-8,8,DIRT:0)
Block(-3,-8,8,DIRT:0)
Block(-2,-8,8,DIRT:0)
Block(-1,-8,8,DIRT:0)
Block(0,-8,8,DIRT:0)
Block(1,-8,8,DIRT:0)
Block(2,-8,8,DIRT:0)
Block(3,-8,8,DIRT:0)
Block(4,-8,8,DIRT:0)
Block(5,-8,8,DIRT:0)
Block(6,-8,8,DIRT:0)
Block(7,-8,8,DIRT:0)
Block(8,-8,8,DIRT:0)
Block(-3,-7,-7,LOG:3)
Block(-2,-7,-7,DIRT:0)
Block(-1,-7,-7,DIRT:0)
Block(0,-7,-7,DIRT:0)
Block(1,-7,-7,DIRT:0)
Block(2,-7,-7,DIRT:0)
Block(3,-7,-7,DIRT:0)
Block(4,-7,-7,DIRT:0)
Block(5,-7,-7,DIRT:0)
Block(6,-7,-7,DIRT:0)
Block(7,-7,-7,DIRT:0)
Block(8,-7,-7,DIRT:0)
Block(-2,-7,-6,PLANKS:3)
Block(-1,-7,-6,DIRT:0)
Block(0,-7,-6,DIRT:0)
Block(1,-7,-6,DIRT:0)
Block(2,-7,-6,DIRT:0)
Block(3,-7,-6,DIRT:0)
Block(4,-7,-6,DIRT:0)
Block(5,-7,-6,DIRT:0)
Block(6,-7,-6,DIRT:0)
Block(7,-7,-6,DIRT:0)
Block(8,-7,-6,DIRT:0)
Block(-2,-7,-5,PLANKS:3)
Block(-1,-7,-5,DIRT:0)
Block(0,-7,-5,DIRT:0)
Block(1,-7,-5,DIRT:0)
Block(2,-7,-5,DIRT:0)
Block(3,-7,-5,DIRT:0)
Block(4,-7,-5,DIRT:0)
Block(5,-7,-5,DIRT:0)
Block(6,-7,-5,DIRT:0)
Block(7,-7,-5,DIRT:0)
Block(8,-7,-5,DIRT:0)
Block(-2,-7,-4,PLANKS:3)
Block(-1,-7,-4,DIRT:0)
Block(0,-7,-4,DIRT:0)
Block(1,-7,-4,DIRT:0)
Block(2,-7,-4,DIRT:0)
Block(3,-7,-4,DIRT:0)
Block(4,-7,-4,DIRT:0)
Block(5,-7,-4,DIRT:0)
Block(6,-7,-4,DIRT:0)
Block(7,-7,-4,DIRT:0)
Block(8,-7,-4,DIRT:0)
Block(-1,-7,-3,PLANKS:3)
Block(0,-7,-3,DIRT:0)
Block(1,-7,-3,DIRT:0)
Block(2,-7,-3,DIRT:0)
Block(3,-7,-3,DIRT:0)
Block(4,-7,-3,DIRT:0)
Block(5,-7,-3,DIRT:0)
Block(6,-7,-3,DIRT:0)
Block(7,-7,-3,DIRT:0)
Block(8,-7,-3,DIRT:0)
Block(-1,-7,-2,LOG:3)
Block(0,-7,-2,DIRT:0)
Block(1,-7,-2,DIRT:0)
Block(2,-7,-2,DIRT:0)
Block(3,-7,-2,DIRT:0)
Block(4,-7,-2,DIRT:0)
Block(5,-7,-2,DIRT:0)
Block(6,-7,-2,DIRT:0)
Block(7,-7,-2,DIRT:0)
Block(8,-7,-2,DIRT:0)
Block(-1,-7,-1,PLANKS:3)
Block(0,-7,-1,DIRT:0)
Block(1,-7,-1,DIRT:0)
Block(2,-7,-1,DIRT:0)
Block(3,-7,-1,DIRT:0)
Block(4,-7,-1,DIRT:0)
Block(5,-7,-1,DIRT:0)
Block(6,-7,-1,DIRT:0)
Block(7,-7,-1,DIRT:0)
Block(8,-7,-1,DIRT:0)
Block(-1,-7,0,PLANKS:3)
Block(0,-7,0,DIRT:0)
Block(1,-7,0,DIRT:0)
Block(2,-7,0,DIRT:0)
Block(3,-7,0,DIRT:0)
Block(4,-7,0,DIRT:0)
Block(5,-7,0,DIRT:0)
Block(6,-7,0,DIRT:0)
Block(7,-7,0,DIRT:0)
Block(8,-7,0,DIRT:0)
Block(-1,-7,1,PLANKS:3)
Block(0,-7,1,DIRT:0)
Block(1,-7,1,DIRT:0)
Block(2,-7,1,DIRT:0)
Block(3,-7,1,DIRT:0)
Block(4,-7,1,DIRT:0)
Block(5,-7,1,DIRT:0)
Block(6,-7,1,DIRT:0)
Block(7,-7,1,DIRT:0)
Block(8,-7,1,DIRT:0)
Block(-2,-7,2,LOG:3)
Block(-1,-7,2,DIRT:0)
Block(0,-7,2,DIRT:0)
Block(1,-7,2,DIRT:0)
Block(2,-7,2,DIRT:0)
Block(3,-7,2,DIRT:0)
Block(4,-7,2,DIRT:0)
Block(5,-7,2,DIRT:0)
Block(6,-7,2,DIRT:0)
Block(7,-7,2,DIRT:0)
Block(8,-7,2,DIRT:0)
Block(-2,-7,3,PLANKS:3)
Block(-1,-7,3,DIRT:0)
Block(0,-7,3,DIRT:0)
Block(1,-7,3,DIRT:0)
Block(2,-7,3,DIRT:0)
Block(3,-7,3,DIRT:0)
Block(4,-7,3,DIRT:0)
Block(5,-7,3,DIRT:0)
Block(6,-7,3,DIRT:0)
Block(7,-7,3,DIRT:0)
Block(8,-7,3,DIRT:0)
Block(-3,-7,4,PLANKS:3)
Block(-2,-7,4,DIRT:0)
Block(-1,-7,4,DIRT:0)
Block(0,-7,4,DIRT:0)
Block(1,-7,4,DIRT:0)
Block(2,-7,4,DIRT:0)
Block(3,-7,4,DIRT:0)
Block(4,-7,4,DIRT:0)
Block(5,-7,4,DIRT:0)
Block(6,-7,4,DIRT:0)
Block(7,-7,4,DIRT:0)
Block(8,-7,4,DIRT:0)
Block(-4,-7,5,LOG:3)
Block(-3,-7,5,DIRT:0)
Block(-2,-7,5,DIRT:0)
Block(-1,-7,5,DIRT:0)
Block(0,-7,5,DIRT:0)
Block(1,-7,5,DIRT:0)
Block(2,-7,5,DIRT:0)
Block(3,-7,5,DIRT:0)
Block(4,-7,5,DIRT:0)
Block(5,-7,5,DIRT:0)
Block(6,-7,5,DIRT:0)
Block(7,-7,5,DIRT:0)
Block(8,-7,5,DIRT:0)
Block(-5,-7,6,PLANKS:3)
Block(-4,-7,6,DIRT:0)
Block(-3,-7,6,DIRT:0)
Block(-2,-7,6,DIRT:0)
Block(-1,-7,6,DIRT:0)
Block(0,-7,6,DIRT:0)
Block(1,-7,6,DIRT:0)
Block(2,-7,6,DIRT:0)
Block(3,-7,6,DIRT:0)
Block(4,-7,6,DIRT:0)
Block(5,-7,6,DIRT:0)
Block(6,-7,6,DIRT:0)
Block(7,-7,6,DIRT:0)
Block(8,-7,6,DIRT:0)
Block(-5,-7,7,PLANKS:3)
Block(-4,-7,7,DIRT:0)
Block(-3,-7,7,DIRT:0)
Block(-2,-7,7,DIRT:0)
Block(-1,-7,7,DIRT:0)
Block(0,-7,7,DIRT:0)
Block(1,-7,7,DIRT:0)
Block(2,-7,7,DIRT:0)
Block(3,-7,7,DIRT:0)
Block(4,-7,7,DIRT:0)
Block(5,-7,7,DIRT:0)
Block(6,-7,7,DIRT:0)
Block(7,-7,7,DIRT:0)
Block(8,-7,7,DIRT:0)
Block(-6,-7,8,PLANKS:3)
Block(-5,-7,8,DIRT:0)
Block(-4,-7,8,DIRT:0)
Block(-3,-7,8,DIRT:0)
Block(-2,-7,8,DIRT:0)
Block(-1,-7,8,DIRT:0)
Block(0,-7,8,DIRT:0)
Block(1,-7,8,DIRT:0)
Block(2,-7,8,DIRT:0)
Block(3,-7,8,DIRT:0)
Block(4,-7,8,DIRT:0)
Block(5,-7,8,DIRT:0)
Block(6,-7,8,DIRT:0)
Block(7,-7,8,DIRT:0)
Block(8,-7,8,DIRT:0)
Block(-3,-6,-7,LOG:3)
Block(-2,-6,-7,DIRT:0)
Block(-1,-6,-7,DIRT:0)
Block(0,-6,-7,DIRT:0)
Block(1,-6,-7,DIRT:0)
Block(2,-6,-7,DIRT:0)
Block(3,-6,-7,DIRT:0)
Block(4,-6,-7,DIRT:0)
Block(5,-6,-7,DIRT:0)
Block(6,-6,-7,DIRT:0)
Block(7,-6,-7,DIRT:0)
Block(8,-6,-7,DIRT:0)
Block(-2,-6,-6,PLANKS:3)
Block(-1,-6,-6,DIRT:0)
Block(0,-6,-6,DIRT:0)
Block(1,-6,-6,DIRT:0)
Block(2,-6,-6,DIRT:0)
Block(3,-6,-6,DIRT:0)
Block(4,-6,-6,DIRT:0)
Block(5,-6,-6,DIRT:0)
Block(6,-6,-6,DIRT:0)
Block(7,-6,-6,DIRT:0)
Block(8,-6,-6,DIRT:0)
Block(-2,-6,-5,PLANKS:3)
Block(-1,-6,-5,DIRT:0)
Block(0,-6,-5,DIRT:0)
Block(1,-6,-5,DIRT:0)
Block(2,-6,-5,DIRT:0)
Block(3,-6,-5,DIRT:0)
Block(4,-6,-5,DIRT:0)
Block(5,-6,-5,DIRT:0)
Block(6,-6,-5,DIRT:0)
Block(7,-6,-5,DIRT:0)
Block(8,-6,-5,DIRT:0)
Block(-2,-6,-4,PLANKS:3)
Block(-1,-6,-4,DIRT:0)
Block(0,-6,-4,DIRT:0)
Block(1,-6,-4,DIRT:0)
Block(2,-6,-4,DIRT:0)
Block(3,-6,-4,DIRT:0)
Block(4,-6,-4,DIRT:0)
Block(5,-6,-4,DIRT:0)
Block(6,-6,-4,DIRT:0)
Block(7,-6,-4,DIRT:0)
Block(8,-6,-4,DIRT:0)
Block(-1,-6,-3,PLANKS:3)
Block(0,-6,-3,DIRT:0)
Block(1,-6,-3,DIRT:0)
Block(2,-6,-3,DIRT:0)
Block(3,-6,-3,DIRT:0)
Block(4,-6,-3,DIRT:0)
Block(5,-6,-3,DIRT:0)
Block(6,-6,-3,DIRT:0)
Block(7,-6,-3,DIRT:0)
Block(8,-6,-3,DIRT:0)
Block(-1,-6,-2,LOG:3)
Block(0,-6,-2,DIRT:0)
Block(1,-6,-2,DIRT:0)
Block(2,-6,-2,DIRT:0)
Block(3,-6,-2,DIRT:0)
Block(4,-6,-2,DIRT:0)
Block(5,-6,-2,DIRT:0)
Block(6,-6,-2,DIRT:0)
Block(7,-6,-2,DIRT:0)
Block(8,-6,-2,DIRT:0)
Block(-1,-6,-1,PLANKS:3)
Block(0,-6,-1,DIRT:0)
Block(1,-6,-1,DIRT:0)
Block(2,-6,-1,DIRT:0)
Block(3,-6,-1,DIRT:0)
Block(4,-6,-1,DIRT:0)
Block(5,-6,-1,DIRT:0)
Block(6,-6,-1,DIRT:0)
Block(7,-6,-1,DIRT:0)
Block(8,-6,-1,DIRT:0)
Block(-1,-6,0,PLANKS:3)
Block(0,-6,0,DIRT:0)
Block(1,-6,0,DIRT:0)
Block(2,-6,0,DIRT:0)
Block(3,-6,0,DIRT:0)
Block(4,-6,0,DIRT:0)
Block(5,-6,0,DIRT:0)
Block(6,-6,0,DIRT:0)
Block(7,-6,0,DIRT:0)
Block(8,-6,0,DIRT:0)
Block(-1,-6,1,PLANKS:3)
Block(0,-6,1,DIRT:0)
Block(1,-6,1,DIRT:0)
Block(2,-6,1,DIRT:0)
Block(3,-6,1,DIRT:0)
Block(4,-6,1,DIRT:0)
Block(5,-6,1,DIRT:0)
Block(6,-6,1,DIRT:0)
Block(7,-6,1,DIRT:0)
Block(8,-6,1,DIRT:0)
Block(-2,-6,2,LOG:3)
Block(-1,-6,2,DIRT:0)
Block(0,-6,2,DIRT:0)
Block(1,-6,2,DIRT:0)
Block(2,-6,2,DIRT:0)
Block(3,-6,2,DIRT:0)
Block(4,-6,2,DIRT:0)
Block(5,-6,2,DIRT:0)
Block(6,-6,2,DIRT:0)
Block(7,-6,2,DIRT:0)
Block(8,-6,2,DIRT:0)
Block(-2,-6,3,PLANKS:3)
Block(-1,-6,3,DIRT:0)
Block(0,-6,3,DIRT:0)
Block(1,-6,3,DIRT:0)
Block(2,-6,3,DIRT:0)
Block(3,-6,3,DIRT:0)
Block(4,-6,3,DIRT:0)
Block(5,-6,3,DIRT:0)
Block(6,-6,3,DIRT:0)
Block(7,-6,3,DIRT:0)
Block(8,-6,3,DIRT:0)
Block(-3,-6,4,PLANKS:3)
Block(-2,-6,4,DIRT:0)
Block(-1,-6,4,DIRT:0)
Block(0,-6,4,DIRT:0)
Block(1,-6,4,DIRT:0)
Block(2,-6,4,DIRT:0)
Block(3,-6,4,DIRT:0)
Block(4,-6,4,DIRT:0)
Block(5,-6,4,DIRT:0)
Block(6,-6,4,DIRT:0)
Block(7,-6,4,DIRT:0)
Block(8,-6,4,DIRT:0)
Block(-4,-6,5,LOG:3)
Block(-3,-6,5,DIRT:0)
Block(-2,-6,5,DIRT:0)
Block(-1,-6,5,DIRT:0)
Block(0,-6,5,DIRT:0)
Block(1,-6,5,DIRT:0)
Block(2,-6,5,DIRT:0)
Block(3,-6,5,DIRT:0)
Block(4,-6,5,DIRT:0)
Block(5,-6,5,DIRT:0)
Block(6,-6,5,DIRT:0)
Block(7,-6,5,DIRT:0)
Block(8,-6,5,DIRT:0)
Block(-5,-6,6,PLANKS:3)
Block(-4,-6,6,DIRT:0)
Block(-3,-6,6,DIRT:0)
Block(-2,-6,6,DIRT:0)
Block(-1,-6,6,DIRT:0)
Block(0,-6,6,DIRT:0)
Block(1,-6,6,DIRT:0)
Block(2,-6,6,DIRT:0)
Block(3,-6,6,DIRT:0)
Block(4,-6,6,DIRT:0)
Block(5,-6,6,DIRT:0)
Block(6,-6,6,DIRT:0)
Block(7,-6,6,DIRT:0)
Block(8,-6,6,DIRT:0)
Block(-5,-6,7,PLANKS:3)
Block(-4,-6,7,DIRT:0)
Block(-3,-6,7,DIRT:0)
Block(-2,-6,7,DIRT:0)
Block(-1,-6,7,DIRT:0)
Block(0,-6,7,DIRT:0)
Block(1,-6,7,DIRT:0)
Block(2,-6,7,DIRT:0)
Block(3,-6,7,DIRT:0)
Block(4,-6,7,DIRT:0)
Block(5,-6,7,DIRT:0)
Block(6,-6,7,DIRT:0)
Block(7,-6,7,DIRT:0)
Block(8,-6,7,DIRT:0)
Block(-6,-6,8,PLANKS:3)
Block(-5,-6,8,DIRT:0)
Block(-4,-6,8,DIRT:0)
Block(-3,-6,8,DIRT:0)
Block(-2,-6,8,DIRT:0)
Block(-1,-6,8,DIRT:0)
Block(0,-6,8,DIRT:0)
Block(1,-6,8,DIRT:0)
Block(2,-6,8,DIRT:0)
Block(3,-6,8,DIRT:0)
Block(4,-6,8,DIRT:0)
Block(5,-6,8,DIRT:0)
Block(6,-6,8,DIRT:0)
Block(7,-6,8,DIRT:0)
Block(8,-6,8,DIRT:0)
Block(-3,-5,-7,LOG:3)
Block(-2,-5,-7,DIRT:0)
Block(-1,-5,-7,DIRT:0)
Block(0,-5,-7,DIRT:0)
Block(1,-5,-7,DIRT:0)
Block(2,-5,-7,DIRT:0)
Block(3,-5,-7,DIRT:0)
Block(4,-5,-7,DIRT:0)
Block(5,-5,-7,DIRT:0)
Block(6,-5,-7,DIRT:0)
Block(7,-5,-7,DIRT:0)
Block(8,-5,-7,DIRT:0)
Block(-2,-5,-6,PLANKS:3)
Block(-1,-5,-6,DIRT:0)
Block(0,-5,-6,DIRT:0)
Block(1,-5,-6,DIRT:0)
Block(2,-5,-6,DIRT:0)
Block(3,-5,-6,DIRT:0)
Block(4,-5,-6,DIRT:0)
Block(5,-5,-6,DIRT:0)
Block(6,-5,-6,DIRT:0)
Block(7,-5,-6,DIRT:0)
Block(8,-5,-6,DIRT:0)
Block(-2,-5,-5,PLANKS:3)
Block(-1,-5,-5,DIRT:0)
Block(0,-5,-5,DIRT:0)
Block(1,-5,-5,DIRT:0)
Block(2,-5,-5,DIRT:0)
Block(3,-5,-5,DIRT:0)
Block(4,-5,-5,DIRT:0)
Block(5,-5,-5,DIRT:0)
Block(6,-5,-5,DIRT:0)
Block(7,-5,-5,DIRT:0)
Block(8,-5,-5,DIRT:0)
Block(-2,-5,-4,PLANKS:3)
Block(-1,-5,-4,DIRT:0)
Block(0,-5,-4,DIRT:0)
Block(1,-5,-4,DIRT:0)
Block(2,-5,-4,DIRT:0)
Block(3,-5,-4,DIRT:0)
Block(4,-5,-4,DIRT:0)
Block(5,-5,-4,DIRT:0)
Block(6,-5,-4,DIRT:0)
Block(7,-5,-4,DIRT:0)
Block(8,-5,-4,DIRT:0)
Block(-1,-5,-3,PLANKS:3)
Block(0,-5,-3,DIRT:0)
Block(1,-5,-3,DIRT:0)
Block(2,-5,-3,DIRT:0)
Block(3,-5,-3,DIRT:0)
Block(4,-5,-3,DIRT:0)
Block(5,-5,-3,DIRT:0)
Block(6,-5,-3,DIRT:0)
Block(7,-5,-3,DIRT:0)
Block(8,-5,-3,DIRT:0)
Block(-1,-5,-2,LOG:3)
Block(0,-5,-2,DIRT:0)
Block(1,-5,-2,DIRT:0)
Block(2,-5,-2,DIRT:0)
Block(3,-5,-2,DIRT:0)
Block(4,-5,-2,DIRT:0)
Block(5,-5,-2,DIRT:0)
Block(6,-5,-2,DIRT:0)
Block(7,-5,-2,DIRT:0)
Block(8,-5,-2,DIRT:0)
Block(-1,-5,-1,PLANKS:3)
Block(0,-5,-1,DIRT:0)
Block(1,-5,-1,DIRT:0)
Block(2,-5,-1,DIRT:0)
Block(3,-5,-1,DIRT:0)
Block(4,-5,-1,DIRT:0)
Block(5,-5,-1,DIRT:0)
Block(6,-5,-1,DIRT:0)
Block(7,-5,-1,DIRT:0)
Block(8,-5,-1,DIRT:0)
Block(-1,-5,0,PLANKS:3)
Block(0,-5,0,DIRT:0)
Block(1,-5,0,DIRT:0)
Block(2,-5,0,DIRT:0)
Block(3,-5,0,DIRT:0)
Block(4,-5,0,DIRT:0)
Block(5,-5,0,DIRT:0)
Block(6,-5,0,DIRT:0)
Block(7,-5,0,DIRT:0)
Block(8,-5,0,DIRT:0)
Block(-1,-5,1,PLANKS:3)
Block(0,-5,1,DIRT:0)
Block(1,-5,1,DIRT:0)
Block(2,-5,1,DIRT:0)
Block(3,-5,1,DIRT:0)
Block(4,-5,1,DIRT:0)
Block(5,-5,1,DIRT:0)
Block(6,-5,1,DIRT:0)
Block(7,-5,1,DIRT:0)
Block(8,-5,1,DIRT:0)
Block(-2,-5,2,LOG:3)
Block(-1,-5,2,DIRT:0)
Block(0,-5,2,DIRT:0)
Block(1,-5,2,DIRT:0)
Block(2,-5,2,DIRT:0)
Block(3,-5,2,DIRT:0)
Block(4,-5,2,DIRT:0)
Block(5,-5,2,DIRT:0)
Block(6,-5,2,DIRT:0)
Block(7,-5,2,DIRT:0)
Block(8,-5,2,DIRT:0)
Block(-2,-5,3,PLANKS:3)
Block(-1,-5,3,DIRT:0)
Block(0,-5,3,DIRT:0)
Block(1,-5,3,DIRT:0)
Block(2,-5,3,DIRT:0)
Block(3,-5,3,DIRT:0)
Block(4,-5,3,DIRT:0)
Block(5,-5,3,DIRT:0)
Block(6,-5,3,DIRT:0)
Block(7,-5,3,DIRT:0)
Block(8,-5,3,DIRT:0)
Block(-3,-5,4,PLANKS:3)
Block(-2,-5,4,DIRT:0)
Block(-1,-5,4,DIRT:0)
Block(0,-5,4,DIRT:0)
Block(1,-5,4,DIRT:0)
Block(2,-5,4,DIRT:0)
Block(3,-5,4,DIRT:0)
Block(4,-5,4,DIRT:0)
Block(5,-5,4,DIRT:0)
Block(6,-5,4,DIRT:0)
Block(7,-5,4,DIRT:0)
Block(8,-5,4,DIRT:0)
Block(-4,-5,5,LOG:3)
Block(-3,-5,5,DIRT:0)
Block(-2,-5,5,DIRT:0)
Block(-1,-5,5,DIRT:0)
Block(0,-5,5,DIRT:0)
Block(1,-5,5,DIRT:0)
Block(2,-5,5,DIRT:0)
Block(3,-5,5,DIRT:0)
Block(4,-5,5,DIRT:0)
Block(5,-5,5,DIRT:0)
Block(6,-5,5,DIRT:0)
Block(7,-5,5,DIRT:0)
Block(8,-5,5,DIRT:0)
Block(-5,-5,6,PLANKS:3)
Block(-4,-5,6,DIRT:0)
Block(-3,-5,6,DIRT:0)
Block(-2,-5,6,DIRT:0)
Block(-1,-5,6,DIRT:0)
Block(0,-5,6,DIRT:0)
Block(1,-5,6,DIRT:0)
Block(2,-5,6,DIRT:0)
Block(3,-5,6,DIRT:0)
Block(4,-5,6,DIRT:0)
Block(5,-5,6,DIRT:0)
Block(6,-5,6,DIRT:0)
Block(7,-5,6,DIRT:0)
Block(8,-5,6,DIRT:0)
Block(-5,-5,7,PLANKS:3)
Block(-4,-5,7,DIRT:0)
Block(-3,-5,7,DIRT:0)
Block(-2,-5,7,DIRT:0)
Block(-1,-5,7,DIRT:0)
Block(0,-5,7,DIRT:0)
Block(1,-5,7,DIRT:0)
Block(2,-5,7,DIRT:0)
Block(3,-5,7,DIRT:0)
Block(4,-5,7,DIRT:0)
Block(5,-5,7,DIRT:0)
Block(6,-5,7,DIRT:0)
Block(7,-5,7,DIRT:0)
Block(8,-5,7,DIRT:0)
Block(-6,-5,8,PLANKS:3)
Block(-5,-5,8,DIRT:0)
Block(-4,-5,8,DIRT:0)
Block(-3,-5,8,DIRT:0)
Block(-2,-5,8,DIRT:0)
Block(-1,-5,8,DIRT:0)
Block(0,-5,8,DIRT:0)
Block(1,-5,8,DIRT:0)
Block(2,-5,8,DIRT:0)
Block(3,-5,8,DIRT:0)
Block(4,-5,8,DIRT:0)
Block(5,-5,8,DIRT:0)
Block(6,-5,8,DIRT:0)
Block(7,-5,8,DIRT:0)
Block(8,-5,8,DIRT:0)
Block(-3,-4,-7,LOG:3)
Block(-2,-4,-7,DIRT:0)
Block(-1,-4,-7,DIRT:0)
Block(0,-4,-7,DIRT:0)
Block(1,-4,-7,DIRT:0)
Block(2,-4,-7,DIRT:0)
Block(3,-4,-7,DIRT:0)
Block(4,-4,-7,DIRT:0)
Block(5,-4,-7,DIRT:0)
Block(6,-4,-7,DIRT:0)
Block(7,-4,-7,DIRT:0)
Block(8,-4,-7,DIRT:0)
Block(-2,-4,-6,PLANKS:3)
Block(-1,-4,-6,DIRT:0)
Block(0,-4,-6,DIRT:0)
Block(1,-4,-6,DIRT:0)
Block(2,-4,-6,DIRT:0)
Block(3,-4,-6,DIRT:0)
Block(4,-4,-6,DIRT:0)
Block(5,-4,-6,DIRT:0)
Block(6,-4,-6,DIRT:0)
Block(7,-4,-6,DIRT:0)
Block(8,-4,-6,DIRT:0)
Block(-2,-4,-5,PLANKS:3)
Block(-1,-4,-5,DIRT:0)
Block(0,-4,-5,DIRT:0)
Block(1,-4,-5,DIRT:0)
Block(2,-4,-5,DIRT:0)
Block(3,-4,-5,DIRT:0)
Block(4,-4,-5,DIRT:0)
Block(5,-4,-5,DIRT:0)
Block(6,-4,-5,DIRT:0)
Block(7,-4,-5,DIRT:0)
Block(8,-4,-5,DIRT:0)
Block(-2,-4,-4,PLANKS:3)
Block(-1,-4,-4,DIRT:0)
Block(0,-4,-4,DIRT:0)
Block(1,-4,-4,DIRT:0)
Block(2,-4,-4,DIRT:0)
Block(3,-4,-4,DIRT:0)
Block(4,-4,-4,DIRT:0)
Block(5,-4,-4,DIRT:0)
Block(6,-4,-4,DIRT:0)
Block(7,-4,-4,DIRT:0)
Block(8,-4,-4,DIRT:0)
Block(-1,-4,-3,PLANKS:3)
Block(0,-4,-3,DIRT:0)
Block(1,-4,-3,DIRT:0)
Block(2,-4,-3,DIRT:0)
Block(3,-4,-3,DIRT:0)
Block(4,-4,-3,DIRT:0)
Block(5,-4,-3,DIRT:0)
Block(6,-4,-3,DIRT:0)
Block(7,-4,-3,DIRT:0)
Block(8,-4,-3,DIRT:0)
Block(-1,-4,-2,LOG:3)
Block(0,-4,-2,DIRT:0)
Block(1,-4,-2,DIRT:0)
Block(2,-4,-2,DIRT:0)
Block(3,-4,-2,DIRT:0)
Block(4,-4,-2,DIRT:0)
Block(5,-4,-2,DIRT:0)
Block(6,-4,-2,DIRT:0)
Block(7,-4,-2,DIRT:0)
Block(8,-4,-2,DIRT:0)
Block(-1,-4,-1,PLANKS:3)
Block(0,-4,-1,DIRT:0)
Block(1,-4,-1,DIRT:0)
Block(2,-4,-1,DIRT:0)
Block(3,-4,-1,DIRT:0)
Block(4,-4,-1,DIRT:0)
Block(5,-4,-1,DIRT:0)
Block(6,-4,-1,DIRT:0)
Block(7,-4,-1,DIRT:0)
Block(8,-4,-1,DIRT:0)
Block(-1,-4,0,PLANKS:3)
Block(0,-4,0,DIRT:0)
Block(1,-4,0,DIRT:0)
Block(2,-4,0,DIRT:0)
Block(3,-4,0,DIRT:0)
Block(4,-4,0,DIRT:0)
Block(5,-4,0,DIRT:0)
Block(6,-4,0,DIRT:0)
Block(7,-4,0,DIRT:0)
Block(8,-4,0,DIRT:0)
Block(-1,-4,1,PLANKS:3)
Block(0,-4,1,DIRT:0)
Block(1,-4,1,DIRT:0)
Block(2,-4,1,DIRT:0)
Block(3,-4,1,DIRT:0)
Block(4,-4,1,DIRT:0)
Block(5,-4,1,DIRT:0)
Block(6,-4,1,DIRT:0)
Block(7,-4,1,DIRT:0)
Block(8,-4,1,DIRT:0)
Block(-2,-4,2,LOG:3)
Block(-1,-4,2,DIRT:0)
Block(0,-4,2,DIRT:0)
Block(1,-4,2,DIRT:0)
Block(2,-4,2,DIRT:0)
Block(3,-4,2,DIRT:0)
Block(4,-4,2,DIRT:0)
Block(5,-4,2,DIRT:0)
Block(6,-4,2,DIRT:0)
Block(7,-4,2,DIRT:0)
Block(8,-4,2,DIRT:0)
Block(-2,-4,3,PLANKS:3)
Block(-1,-4,3,DIRT:0)
Block(0,-4,3,DIRT:0)
Block(1,-4,3,DIRT:0)
Block(2,-4,3,DIRT:0)
Block(3,-4,3,DIRT:0)
Block(4,-4,3,DIRT:0)
Block(5,-4,3,DIRT:0)
Block(6,-4,3,DIRT:0)
Block(7,-4,3,DIRT:0)
Block(8,-4,3,DIRT:0)
Block(-3,-4,4,PLANKS:3)
Block(-2,-4,4,DIRT:0)
Block(-1,-4,4,DIRT:0)
Block(0,-4,4,DIRT:0)
Block(1,-4,4,DIRT:0)
Block(2,-4,4,DIRT:0)
Block(3,-4,4,DIRT:0)
Block(4,-4,4,DIRT:0)
Block(5,-4,4,DIRT:0)
Block(6,-4,4,DIRT:0)
Block(7,-4,4,DIRT:0)
Block(8,-4,4,DIRT:0)
Block(-4,-4,5,LOG:3)
Block(-3,-4,5,DIRT:0)
Block(-2,-4,5,DIRT:0)
Block(-1,-4,5,DIRT:0)
Block(0,-4,5,DIRT:0)
Block(1,-4,5,DIRT:0)
Block(2,-4,5,DIRT:0)
Block(3,-4,5,DIRT:0)
Block(4,-4,5,DIRT:0)
Block(5,-4,5,DIRT:0)
Block(6,-4,5,DIRT:0)
Block(7,-4,5,DIRT:0)
Block(8,-4,5,DIRT:0)
Block(-5,-4,6,PLANKS:3)
Block(-4,-4,6,DIRT:0)
Block(-3,-4,6,DIRT:0)
Block(-2,-4,6,DIRT:0)
Block(-1,-4,6,DIRT:0)
Block(0,-4,6,DIRT:0)
Block(1,-4,6,DIRT:0)
Block(2,-4,6,DIRT:0)
Block(3,-4,6,DIRT:0)
Block(4,-4,6,DIRT:0)
Block(5,-4,6,DIRT:0)
Block(6,-4,6,DIRT:0)
Block(7,-4,6,DIRT:0)
Block(8,-4,6,DIRT:0)
Block(-5,-4,7,PLANKS:3)
Block(-4,-4,7,DIRT:0)
Block(-3,-4,7,DIRT:0)
Block(-2,-4,7,DIRT:0)
Block(-1,-4,7,DIRT:0)
Block(0,-4,7,DIRT:0)
Block(1,-4,7,DIRT:0)
Block(2,-4,7,DIRT:0)
Block(3,-4,7,DIRT:0)
Block(4,-4,7,DIRT:0)
Block(5,-4,7,DIRT:0)
Block(6,-4,7,DIRT:0)
Block(7,-4,7,DIRT:0)
Block(8,-4,7,DIRT:0)
Block(-6,-4,8,PLANKS:3)
Block(-5,-4,8,DIRT:0)
Block(-4,-4,8,DIRT:0)
Block(-3,-4,8,DIRT:0)
Block(-2,-4,8,DIRT:0)
Block(-1,-4,8,DIRT:0)
Block(0,-4,8,DIRT:0)
Block(1,-4,8,DIRT:0)
Block(2,-4,8,DIRT:0)
Block(3,-4,8,DIRT:0)
Block(4,-4,8,DIRT:0)
Block(5,-4,8,DIRT:0)
Block(6,-4,8,DIRT:0)
Block(7,-4,8,DIRT:0)
Block(8,-4,8,DIRT:0)
Block(-3,-3,-7,LOG:3)
Block(-2,-3,-7,DIRT:0)
Block(-1,-3,-7,DIRT:0)
Block(0,-3,-7,DIRT:0)
Block(1,-3,-7,DIRT:0)
Block(2,-3,-7,DIRT:0)
Block(3,-3,-7,DIRT:0)
Block(4,-3,-7,DIRT:0)
Block(5,-3,-7,DIRT:0)
Block(6,-3,-7,DIRT:0)
Block(7,-3,-7,DIRT:0)
Block(8,-3,-7,DIRT:0)
Block(-2,-3,-6,PLANKS:3)
Block(-1,-3,-6,DIRT:0)
Block(0,-3,-6,DIRT:0)
Block(1,-3,-6,DIRT:0)
Block(2,-3,-6,DIRT:0)
Block(3,-3,-6,DIRT:0)
Block(4,-3,-6,DIRT:0)
Block(5,-3,-6,DIRT:0)
Block(6,-3,-6,DIRT:0)
Block(7,-3,-6,DIRT:0)
Block(8,-3,-6,DIRT:0)
Block(-2,-3,-5,PLANKS:3)
Block(-1,-3,-5,DIRT:0)
Block(0,-3,-5,DIRT:0)
Block(1,-3,-5,DIRT:0)
Block(2,-3,-5,DIRT:0)
Block(3,-3,-5,DIRT:0)
Block(4,-3,-5,DIRT:0)
Block(5,-3,-5,DIRT:0)
Block(6,-3,-5,DIRT:0)
Block(7,-3,-5,DIRT:0)
Block(8,-3,-5,DIRT:0)
Block(-2,-3,-4,PLANKS:3)
Block(-1,-3,-4,DIRT:0)
Block(0,-3,-4,DIRT:0)
Block(1,-3,-4,DIRT:0)
Block(2,-3,-4,DIRT:0)
Block(3,-3,-4,DIRT:0)
Block(4,-3,-4,DIRT:0)
Block(5,-3,-4,DIRT:0)
Block(6,-3,-4,DIRT:0)
Block(7,-3,-4,DIRT:0)
Block(8,-3,-4,DIRT:0)
Block(-1,-3,-3,PLANKS:3)
Block(0,-3,-3,DIRT:0)
Block(1,-3,-3,DIRT:0)
Block(2,-3,-3,DIRT:0)
Block(3,-3,-3,DIRT:0)
Block(4,-3,-3,DIRT:0)
Block(5,-3,-3,DIRT:0)
Block(6,-3,-3,DIRT:0)
Block(7,-3,-3,DIRT:0)
Block(8,-3,-3,DIRT:0)
Block(-1,-3,-2,LOG:3)
Block(0,-3,-2,DIRT:0)
Block(1,-3,-2,DIRT:0)
Block(2,-3,-2,DIRT:0)
Block(3,-3,-2,DIRT:0)
Block(4,-3,-2,DIRT:0)
Block(5,-3,-2,DIRT:0)
Block(6,-3,-2,DIRT:0)
Block(7,-3,-2,DIRT:0)
Block(8,-3,-2,DIRT:0)
Block(-1,-3,-1,PLANKS:3)
Block(0,-3,-1,DIRT:0)
Block(1,-3,-1,DIRT:0)
Block(2,-3,-1,DIRT:0)
Block(3,-3,-1,DIRT:0)
Block(4,-3,-1,DIRT:0)
Block(5,-3,-1,DIRT:0)
Block(6,-3,-1,DIRT:0)
Block(7,-3,-1,DIRT:0)
Block(8,-3,-1,DIRT:0)
Block(-1,-3,0,PLANKS:3)
Block(0,-3,0,DIRT:0)
Block(1,-3,0,DIRT:0)
Block(2,-3,0,DIRT:0)
Block(3,-3,0,DIRT:0)
Block(4,-3,0,DIRT:0)
Block(5,-3,0,DIRT:0)
Block(6,-3,0,DIRT:0)
Block(7,-3,0,DIRT:0)
Block(8,-3,0,DIRT:0)
Block(-1,-3,1,PLANKS:3)
Block(0,-3,1,DIRT:0)
Block(1,-3,1,DIRT:0)
Block(2,-3,1,DIRT:0)
Block(3,-3,1,DIRT:0)
Block(4,-3,1,DIRT:0)
Block(5,-3,1,DIRT:0)
Block(6,-3,1,DIRT:0)
Block(7,-3,1,DIRT:0)
Block(8,-3,1,DIRT:0)
Block(-2,-3,2,LOG:3)
Block(-1,-3,2,DIRT:0)
Block(0,-3,2,DIRT:0)
Block(1,-3,2,DIRT:0)
Block(2,-3,2,DIRT:0)
Block(3,-3,2,DIRT:0)
Block(4,-3,2,DIRT:0)
Block(5,-3,2,DIRT:0)
Block(6,-3,2,DIRT:0)
Block(7,-3,2,DIRT:0)
Block(8,-3,2,DIRT:0)
Block(-2,-3,3,PLANKS:3)
Block(-1,-3,3,DIRT:0)
Block(0,-3,3,DIRT:0)
Block(1,-3,3,DIRT:0)
Block(2,-3,3,DIRT:0)
Block(3,-3,3,DIRT:0)
Block(4,-3,3,DIRT:0)
Block(5,-3,3,DIRT:0)
Block(6,-3,3,DIRT:0)
Block(7,-3,3,DIRT:0)
Block(8,-3,3,DIRT:0)
Block(-3,-3,4,PLANKS:3)
Block(-2,-3,4,DIRT:0)
Block(-1,-3,4,DIRT:0)
Block(0,-3,4,DIRT:0)
Block(1,-3,4,DIRT:0)
Block(2,-3,4,DIRT:0)
Block(3,-3,4,DIRT:0)
Block(4,-3,4,DIRT:0)
Block(5,-3,4,DIRT:0)
Block(6,-3,4,DIRT:0)
Block(7,-3,4,DIRT:0)
Block(8,-3,4,DIRT:0)
Block(-4,-3,5,LOG:3)
Block(-3,-3,5,DIRT:0)
Block(-2,-3,5,DIRT:0)
Block(-1,-3,5,DIRT:0)
Block(0,-3,5,DIRT:0)
Block(1,-3,5,DIRT:0)
Block(2,-3,5,DIRT:0)
Block(3,-3,5,DIRT:0)
Block(4,-3,5,DIRT:0)
Block(5,-3,5,DIRT:0)
Block(6,-3,5,DIRT:0)
Block(7,-3,5,DIRT:0)
Block(8,-3,5,DIRT:0)
Block(-5,-3,6,PLANKS:3)
Block(-4,-3,6,DIRT:0)
Block(-3,-3,6,DIRT:0)
Block(-2,-3,6,DIRT:0)
Block(-1,-3,6,DIRT:0)
Block(0,-3,6,DIRT:0)
Block(1,-3,6,DIRT:0)
Block(2,-3,6,DIRT:0)
Block(3,-3,6,DIRT:0)
Block(4,-3,6,DIRT:0)
Block(5,-3,6,DIRT:0)
Block(6,-3,6,DIRT:0)
Block(7,-3,6,DIRT:0)
Block(8,-3,6,DIRT:0)
Block(-5,-3,7,PLANKS:3)
Block(-4,-3,7,DIRT:0)
Block(-3,-3,7,DIRT:0)
Block(-2,-3,7,DIRT:0)
Block(-1,-3,7,DIRT:0)
Block(0,-3,7,DIRT:0)
Block(1,-3,7,DIRT:0)
Block(2,-3,7,DIRT:0)
Block(3,-3,7,DIRT:0)
Block(4,-3,7,DIRT:0)
Block(5,-3,7,DIRT:0)
Block(6,-3,7,DIRT:0)
Block(7,-3,7,DIRT:0)
Block(8,-3,7,DIRT:0)
Block(-6,-3,8,PLANKS:3)
Block(-5,-3,8,DIRT:0)
Block(-4,-3,8,DIRT:0)
Block(-3,-3,8,DIRT:0)
Block(-2,-3,8,DIRT:0)
Block(-1,-3,8,DIRT:0)
Block(0,-3,8,DIRT:0)
Block(1,-3,8,DIRT:0)
Block(2,-3,8,DIRT:0)
Block(3,-3,8,DIRT:0)
Block(4,-3,8,DIRT:0)
Block(5,-3,8,DIRT:0)
Block(6,-3,8,DIRT:0)
Block(7,-3,8,DIRT:0)
Block(8,-3,8,DIRT:0)
Block(-3,-2,-7,LOG:3)
Block(-2,-2,-7,DIRT:0)
Block(-1,-2,-7,DIRT:0)
Block(0,-2,-7,DIRT:0)
Block(1,-2,-7,DIRT:0)
Block(2,-2,-7,DIRT:0)
Block(3,-2,-7,DIRT:0)
Block(4,-2,-7,DIRT:0)
Block(5,-2,-7,DIRT:0)
Block(6,-2,-7,DIRT:0)
Block(7,-2,-7,DIRT:0)
Block(8,-2,-7,DIRT:0)
Block(-2,-2,-6,PLANKS:3)
Block(-1,-2,-6,DIRT:0)
Block(0,-2,-6,DIRT:0)
Block(1,-2,-6,DIRT:0)
Block(2,-2,-6,DIRT:0)
Block(3,-2,-6,DIRT:0)
Block(4,-2,-6,DIRT:0)
Block(5,-2,-6,DIRT:0)
Block(6,-2,-6,DIRT:0)
Block(7,-2,-6,DIRT:0)
Block(8,-2,-6,DIRT:0)
Block(-2,-2,-5,PLANKS:3)
Block(-1,-2,-5,DIRT:0)
Block(0,-2,-5,DIRT:0)
Block(1,-2,-5,DIRT:0)
Block(2,-2,-5,DIRT:0)
Block(3,-2,-5,DIRT:0)
Block(4,-2,-5,DIRT:0)
Block(5,-2,-5,DIRT:0)
Block(6,-2,-5,DIRT:0)
Block(7,-2,-5,DIRT:0)
Block(8,-2,-5,DIRT:0)
Block(-2,-2,-4,PLANKS:3)
Block(-1,-2,-4,DIRT:0)
Block(0,-2,-4,DIRT:0)
Block(1,-2,-4,DIRT:0)
Block(2,-2,-4,DIRT:0)
Block(3,-2,-4,DIRT:0)
Block(4,-2,-4,DIRT:0)
Block(5,-2,-4,DIRT:0)
Block(6,-2,-4,DIRT:0)
Block(7,-2,-4,DIRT:0)
Block(8,-2,-4,DIRT:0)
Block(-1,-2,-3,PLANKS:3)
Block(0,-2,-3,DIRT:0)
Block(1,-2,-3,DIRT:0)
Block(2,-2,-3,DIRT:0)
Block(3,-2,-3,DIRT:0)
Block(4,-2,-3,DIRT:0)
Block(5,-2,-3,DIRT:0)
Block(6,-2,-3,DIRT:0)
Block(7,-2,-3,DIRT:0)
Block(8,-2,-3,DIRT:0)
Block(-1,-2,-2,LOG:3)
Block(0,-2,-2,DIRT:0)
Block(1,-2,-2,DIRT:0)
Block(2,-2,-2,DIRT:0)
Block(3,-2,-2,DIRT:0)
Block(4,-2,-2,DIRT:0)
Block(5,-2,-2,DIRT:0)
Block(6,-2,-2,DIRT:0)
Block(7,-2,-2,DIRT:0)
Block(8,-2,-2,DIRT:0)
Block(-1,-2,-1,PLANKS:3)
Block(0,-2,-1,DIRT:0)
Block(1,-2,-1,DIRT:0)
Block(2,-2,-1,DIRT:0)
Block(3,-2,-1,DIRT:0)
Block(4,-2,-1,DIRT:0)
Block(5,-2,-1,DIRT:0)
Block(6,-2,-1,DIRT:0)
Block(7,-2,-1,DIRT:0)
Block(8,-2,-1,DIRT:0)
Block(-1,-2,0,PLANKS:3)
Block(0,-2,0,DIRT:0)
Block(1,-2,0,DIRT:0)
Block(2,-2,0,DIRT:0)
Block(3,-2,0,DIRT:0)
Block(4,-2,0,DIRT:0)
Block(5,-2,0,DIRT:0)
Block(6,-2,0,DIRT:0)
Block(7,-2,0,DIRT:0)
Block(8,-2,0,DIRT:0)
Block(-1,-2,1,PLANKS:3)
Block(0,-2,1,DIRT:0)
Block(1,-2,1,DIRT:0)
Block(2,-2,1,DIRT:0)
Block(3,-2,1,DIRT:0)
Block(4,-2,1,DIRT:0)
Block(5,-2,1,DIRT:0)
Block(6,-2,1,DIRT:0)
Block(7,-2,1,DIRT:0)
Block(8,-2,1,DIRT:0)
Block(-2,-2,2,LOG:3)
Block(-1,-2,2,DIRT:0)
Block(0,-2,2,DIRT:0)
Block(1,-2,2,DIRT:0)
Block(2,-2,2,DIRT:0)
Block(3,-2,2,DIRT:0)
Block(4,-2,2,DIRT:0)
Block(5,-2,2,DIRT:0)
Block(6,-2,2,DIRT:0)
Block(7,-2,2,DIRT:0)
Block(8,-2,2,DIRT:0)
Block(-2,-2,3,PLANKS:3)
Block(-1,-2,3,DIRT:0)
Block(0,-2,3,DIRT:0)
Block(1,-2,3,DIRT:0)
Block(2,-2,3,DIRT:0)
Block(3,-2,3,DIRT:0)
Block(4,-2,3,DIRT:0)
Block(5,-2,3,DIRT:0)
Block(6,-2,3,DIRT:0)
Block(7,-2,3,DIRT:0)
Block(8,-2,3,DIRT:0)
Block(-3,-2,4,PLANKS:3)
Block(-2,-2,4,DIRT:0)
Block(-1,-2,4,DIRT:0)
Block(0,-2,4,DIRT:0)
Block(1,-2,4,DIRT:0)
Block(2,-2,4,DIRT:0)
Block(3,-2,4,DIRT:0)
Block(4,-2,4,DIRT:0)
Block(5,-2,4,DIRT:0)
Block(6,-2,4,DIRT:0)
Block(7,-2,4,DIRT:0)
Block(8,-2,4,DIRT:0)
Block(-4,-2,5,LOG:3)
Block(-3,-2,5,DIRT:0)
Block(-2,-2,5,DIRT:0)
Block(-1,-2,5,DIRT:0)
Block(0,-2,5,DIRT:0)
Block(1,-2,5,DIRT:0)
Block(2,-2,5,DIRT:0)
Block(3,-2,5,DIRT:0)
Block(4,-2,5,DIRT:0)
Block(5,-2,5,DIRT:0)
Block(6,-2,5,DIRT:0)
Block(7,-2,5,DIRT:0)
Block(8,-2,5,DIRT:0)
Block(-5,-2,6,PLANKS:3)
Block(-4,-2,6,DIRT:0)
Block(-3,-2,6,DIRT:0)
Block(-2,-2,6,DIRT:0)
Block(-1,-2,6,DIRT:0)
Block(0,-2,6,DIRT:0)
Block(1,-2,6,DIRT:0)
Block(2,-2,6,DIRT:0)
Block(3,-2,6,DIRT:0)
Block(4,-2,6,DIRT:0)
Block(5,-2,6,DIRT:0)
Block(6,-2,6,DIRT:0)
Block(7,-2,6,DIRT:0)
Block(8,-2,6,DIRT:0)
Block(-5,-2,7,PLANKS:3)
Block(-4,-2,7,DIRT:0)
Block(-3,-2,7,DIRT:0)
Block(-2,-2,7,DIRT:0)
Block(-1,-2,7,DIRT:0)
Block(0,-2,7,DIRT:0)
Block(1,-2,7,DIRT:0)
Block(2,-2,7,DIRT:0)
Block(3,-2,7,DIRT:0)
Block(4,-2,7,DIRT:0)
Block(5,-2,7,DIRT:0)
Block(6,-2,7,DIRT:0)
Block(7,-2,7,DIRT:0)
Block(8,-2,7,DIRT:0)
Block(-6,-2,8,PLANKS:3)
Block(-5,-2,8,DIRT:0)
Block(-4,-2,8,DIRT:0)
Block(-3,-2,8,DIRT:0)
Block(-2,-2,8,DIRT:0)
Block(-1,-2,8,DIRT:0)
Block(0,-2,8,DIRT:0)
Block(1,-2,8,DIRT:0)
Block(2,-2,8,DIRT:0)
Block(3,-2,8,DIRT:0)
Block(4,-2,8,DIRT:0)
Block(5,-2,8,DIRT:0)
Block(6,-2,8,DIRT:0)
Block(7,-2,8,DIRT:0)
Block(8,-2,8,DIRT:0)
Block(-3,-1,-7,LOG:3)
Block(-2,-1,-7,DIRT:0)
Block(-1,-1,-7,DIRT:0)
Block(0,-1,-7,DIRT:0)
Block(1,-1,-7,DIRT:0)
Block(2,-1,-7,DIRT:0)
Block(3,-1,-7,DIRT:0)
Block(4,-1,-7,DIRT:0)
Block(5,-1,-7,DIRT:0)
Block(6,-1,-7,DIRT:0)
Block(7,-1,-7,DIRT:0)
Block(8,-1,-7,DIRT:0)
Block(-2,-1,-6,PLANKS:3)
Block(-1,-1,-6,DIRT:0)
Block(0,-1,-6,DIRT:0)
Block(1,-1,-6,DIRT:0)
Block(2,-1,-6,DIRT:0)
Block(3,-1,-6,DIRT:0)
Block(4,-1,-6,DIRT:0)
Block(5,-1,-6,DIRT:0)
Block(6,-1,-6,DIRT:0)
Block(7,-1,-6,DIRT:0)
Block(8,-1,-6,DIRT:0)
Block(-2,-1,-5,PLANKS:3)
Block(-1,-1,-5,DIRT:0)
Block(0,-1,-5,DIRT:0)
Block(1,-1,-5,DIRT:0)
Block(2,-1,-5,DIRT:0)
Block(3,-1,-5,DIRT:0)
Block(4,-1,-5,DIRT:0)
Block(5,-1,-5,DIRT:0)
Block(6,-1,-5,DIRT:0)
Block(7,-1,-5,DIRT:0)
Block(8,-1,-5,DIRT:0)
Block(-2,-1,-4,PLANKS:3)
Block(-1,-1,-4,DIRT:0)
Block(0,-1,-4,DIRT:0)
Block(1,-1,-4,DIRT:0)
Block(2,-1,-4,DIRT:0)
Block(3,-1,-4,DIRT:0)
Block(4,-1,-4,DIRT:0)
Block(5,-1,-4,DIRT:0)
Block(6,-1,-4,DIRT:0)
Block(7,-1,-4,DIRT:0)
Block(8,-1,-4,DIRT:0)
Block(-1,-1,-3,PLANKS:3)
Block(0,-1,-3,DIRT:0)
Block(1,-1,-3,DIRT:0)
Block(2,-1,-3,DIRT:0)
Block(3,-1,-3,DIRT:0)
Block(4,-1,-3,DIRT:0)
Block(5,-1,-3,DIRT:0)
Block(6,-1,-3,DIRT:0)
Block(7,-1,-3,DIRT:0)
Block(8,-1,-3,DIRT:0)
Block(-1,-1,-2,LOG:3)
Block(0,-1,-2,DIRT:0)
Block(1,-1,-2,DIRT:0)
Block(2,-1,-2,DIRT:0)
Block(3,-1,-2,DIRT:0)
Block(4,-1,-2,DIRT:0)
Block(5,-1,-2,DIRT:0)
Block(6,-1,-2,DIRT:0)
Block(7,-1,-2,DIRT:0)
Block(8,-1,-2,DIRT:0)
Block(-1,-1,-1,PLANKS:3)
Block(0,-1,-1,DIRT:0)
Block(1,-1,-1,DIRT:0)
Block(2,-1,-1,DIRT:0)
Block(3,-1,-1,DIRT:0)
Block(4,-1,-1,DIRT:0)
Block(5,-1,-1,DIRT:0)
Block(6,-1,-1,DIRT:0)
Block(7,-1,-1,DIRT:0)
Block(8,-1,-1,DIRT:0)
Block(-1,-1,0,PLANKS:3)
Block(0,-1,0,DIRT:0)
Block(1,-1,0,DIRT:0)
Block(2,-1,0,DIRT:0)
Block(3,-1,0,DIRT:0)
Block(4,-1,0,DIRT:0)
Block(5,-1,0,DIRT:0)
Block(6,-1,0,DIRT:0)
Block(7,-1,0,DIRT:0)
Block(8,-1,0,DIRT:0)
Block(-1,-1,1,PLANKS:3)
Block(0,-1,1,DIRT:0)
Block(1,-1,1,DIRT:0)
Block(2,-1,1,DIRT:0)
Block(3,-1,1,DIRT:0)
Block(4,-1,1,DIRT:0)
Block(5,-1,1,DIRT:0)
Block(6,-1,1,DIRT:0)
Block(7,-1,1,DIRT:0)
Block(8,-1,1,DIRT:0)
Block(-2,-1,2,LOG:3)
Block(-1,-1,2,DIRT:0)
Block(0,-1,2,DIRT:0)
Block(1,-1,2,DIRT:0)
Block(2,-1,2,DIRT:0)
Block(3,-1,2,DIRT:0)
Block(4,-1,2,DIRT:0)
Block(5,-1,2,DIRT:0)
Block(6,-1,2,DIRT:0)
Block(7,-1,2,DIRT:0)
Block(8,-1,2,DIRT:0)
Block(-2,-1,3,PLANKS:3)
Block(-1,-1,3,DIRT:0)
Block(0,-1,3,DIRT:0)
Block(1,-1,3,DIRT:0)
Block(2,-1,3,DIRT:0)
Block(3,-1,3,DIRT:0)
Block(4,-1,3,DIRT:0)
Block(5,-1,3,DIRT:0)
Block(6,-1,3,DIRT:0)
Block(7,-1,3,DIRT:0)
Block(8,-1,3,DIRT:0)
Block(-3,-1,4,PLANKS:3)
Block(-2,-1,4,DIRT:0)
Block(-1,-1,4,DIRT:0)
Block(0,-1,4,DIRT:0)
Block(1,-1,4,DIRT:0)
Block(2,-1,4,DIRT:0)
Block(3,-1,4,DIRT:0)
Block(4,-1,4,DIRT:0)
Block(5,-1,4,DIRT:0)
Block(6,-1,4,DIRT:0)
Block(7,-1,4,DIRT:0)
Block(8,-1,4,DIRT:0)
Block(-4,-1,5,LOG:3)
Block(-3,-1,5,DIRT:0)
Block(-2,-1,5,DIRT:0)
Block(-1,-1,5,DIRT:0)
Block(0,-1,5,DIRT:0)
Block(1,-1,5,DIRT:0)
Block(2,-1,5,DIRT:0)
Block(3,-1,5,DIRT:0)
Block(4,-1,5,DIRT:0)
Block(5,-1,5,DIRT:0)
Block(6,-1,5,DIRT:0)
Block(7,-1,5,DIRT:0)
Block(8,-1,5,DIRT:0)
Block(-5,-1,6,PLANKS:3)
Block(-4,-1,6,DIRT:0)
Block(-3,-1,6,DIRT:0)
Block(-2,-1,6,DIRT:0)
Block(-1,-1,6,DIRT:0)
Block(0,-1,6,DIRT:0)
Block(1,-1,6,DIRT:0)
Block(2,-1,6,DIRT:0)
Block(3,-1,6,DIRT:0)
Block(4,-1,6,DIRT:0)
Block(5,-1,6,DIRT:0)
Block(6,-1,6,DIRT:0)
Block(7,-1,6,DIRT:0)
Block(8,-1,6,DIRT:0)
Block(-5,-1,7,PLANKS:3)
Block(-4,-1,7,DIRT:0)
Block(-3,-1,7,DIRT:0)
Block(-2,-1,7,DIRT:0)
Block(-1,-1,7,DIRT:0)
Block(0,-1,7,DIRT:0)
Block(1,-1,7,DIRT:0)
Block(2,-1,7,DIRT:0)
Block(3,-1,7,DIRT:0)
Block(4,-1,7,DIRT:0)
Block(5,-1,7,DIRT:0)
Block(6,-1,7,DIRT:0)
Block(7,-1,7,DIRT:0)
Block(8,-1,7,DIRT:0)
Block(-6,-1,8,PLANKS:3)
Block(-5,-1,8,DIRT:0)
Block(-4,-1,8,DIRT:0)
Block(-3,-1,8,DIRT:0)
Block(-2,-1,8,DIRT:0)
Block(-1,-1,8,DIRT:0)
Block(0,-1,8,DIRT:0)
Block(1,-1,8,DIRT:0)
Block(2,-1,8,DIRT:0)
Block(3,-1,8,DIRT:0)
Block(4,-1,8,DIRT:0)
Block(5,-1,8,DIRT:0)
Block(6,-1,8,DIRT:0)
Block(7,-1,8,DIRT:0)
Block(8,-1,8,DIRT:0)
Block(-4,0,-7,SPRUCE_FENCE:0)
Block(-3,0,-7,LOG:3)
Block(-2,0,-7,DIRT:0)
Block(-1,0,-7,DIRT:0)
Block(0,0,-7,DIRT:0)
Block(1,0,-7,DIRT:0)
Block(2,0,-7,DIRT:0)
Block(3,0,-7,DIRT:0)
Block(4,0,-7,DIRT:0)
Block(5,0,-7,DIRT:0)
Block(6,0,-7,DIRT:0)
Block(7,0,-7,DIRT:0)
Block(8,0,-7,DIRT:0)
Block(-3,0,-6,SPRUCE_FENCE:0)
Block(-2,0,-6,PLANKS:3)
Block(-1,0,-6,DIRT:0)
Block(0,0,-6,DIRT:0)
Block(1,0,-6,DIRT:0)
Block(2,0,-6,DIRT:0)
Block(3,0,-6,DIRT:0)
Block(4,0,-6,DIRT:0)
Block(5,0,-6,DIRT:0)
Block(6,0,-6,DIRT:0)
Block(7,0,-6,DIRT:0)
Block(8,0,-6,DIRT:0)
Block(-3,0,-5,SPRUCE_FENCE:0)
Block(-2,0,-5,PLANKS:3)
Block(-1,0,-5,DIRT:0)
Block(0,0,-5,DIRT:0)
Block(1,0,-5,DIRT:0)
Block(2,0,-5,DIRT:0)
Block(3,0,-5,DIRT:0)
Block(4,0,-5,DIRT:0)
Block(5,0,-5,DIRT:0)
Block(6,0,-5,DIRT:0)
Block(7,0,-5,DIRT:0)
Block(8,0,-5,DIRT:0)
Block(-3,0,-4,SPRUCE_FENCE:0)
Block(-2,0,-4,PLANKS:3)
Block(-1,0,-4,DIRT:0)
Block(0,0,-4,DIRT:0)
Block(1,0,-4,DIRT:0)
Block(2,0,-4,DIRT:0)
Block(3,0,-4,DIRT:0)
Block(4,0,-4,DIRT:0)
Block(5,0,-4,DIRT:0)
Block(6,0,-4,DIRT:0)
Block(7,0,-4,DIRT:0)
Block(8,0,-4,DIRT:0)
Block(-1,0,-3,PLANKS:3)
Block(0,0,-3,DIRT:0)
Block(1,0,-3,DIRT:0)
Block(2,0,-3,DIRT:0)
Block(3,0,-3,DIRT:0)
Block(4,0,-3,DIRT:0)
Block(5,0,-3,DIRT:0)
Block(6,0,-3,DIRT:0)
Block(7,0,-3,DIRT:0)
Block(8,0,-3,DIRT:0)
Block(-1,0,-2,LOG:3)
Block(0,0,-2,DIRT:0)
Block(1,0,-2,DIRT:0)
Block(2,0,-2,DIRT:0)
Block(3,0,-2,DIRT:0)
Block(4,0,-2,DIRT:0)
Block(5,0,-2,DIRT:0)
Block(6,0,-2,DIRT:0)
Block(7,0,-2,DIRT:0)
Block(8,0,-2,DIRT:0)
Block(-1,0,-1,PLANKS:3)
Block(0,0,-1,DIRT:0)
Block(1,0,-1,DIRT:0)
Block(2,0,-1,DIRT:0)
Block(3,0,-1,DIRT:0)
Block(4,0,-1,DIRT:0)
Block(5,0,-1,DIRT:0)
Block(6,0,-1,DIRT:0)
Block(7,0,-1,DIRT:0)
Block(8,0,-1,DIRT:0)
Block(-1,0,0,PLANKS:3)
Block(0,0,0,DIRT:0)
Block(1,0,0,DIRT:0)
Block(2,0,0,DIRT:0)
Block(3,0,0,DIRT:0)
Block(4,0,0,DIRT:0)
Block(5,0,0,DIRT:0)
Block(6,0,0,DIRT:0)
Block(7,0,0,DIRT:0)
Block(8,0,0,DIRT:0)
Block(-1,0,1,PLANKS:3)
Block(0,0,1,DIRT:0)
Block(1,0,1,DIRT:0)
Block(2,0,1,DIRT:0)
Block(3,0,1,DIRT:0)
Block(4,0,1,DIRT:0)
Block(5,0,1,DIRT:0)
Block(6,0,1,DIRT:0)
Block(7,0,1,DIRT:0)
Block(8,0,1,DIRT:0)
Block(-3,0,2,SPRUCE_FENCE:0)
Block(-2,0,2,LOG:3)
Block(-1,0,2,DIRT:0)
Block(0,0,2,DIRT:0)
Block(1,0,2,DIRT:0)
Block(2,0,2,DIRT:0)
Block(3,0,2,DIRT:0)
Block(4,0,2,DIRT:0)
Block(5,0,2,DIRT:0)
Block(6,0,2,DIRT:0)
Block(7,0,2,DIRT:0)
Block(8,0,2,DIRT:0)
Block(-3,0,3,SPRUCE_FENCE:0)
Block(-2,0,3,PLANKS:3)
Block(-1,0,3,DIRT:0)
Block(0,0,3,DIRT:0)
Block(1,0,3,DIRT:0)
Block(2,0,3,DIRT:0)
Block(3,0,3,DIRT:0)
Block(4,0,3,DIRT:0)
Block(5,0,3,DIRT:0)
Block(6,0,3,DIRT:0)
Block(7,0,3,DIRT:0)
Block(8,0,3,DIRT:0)
Block(-4,0,4,SPRUCE_FENCE:0)
Block(-3,0,4,PLANKS:3)
Block(-2,0,4,DIRT:0)
Block(-1,0,4,DIRT:0)
Block(0,0,4,DIRT:0)
Block(1,0,4,DIRT:0)
Block(2,0,4,DIRT:0)
Block(3,0,4,DIRT:0)
Block(4,0,4,DIRT:0)
Block(5,0,4,DIRT:0)
Block(6,0,4,DIRT:0)
Block(7,0,4,DIRT:0)
Block(8,0,4,DIRT:0)
Block(-5,0,5,SPRUCE_FENCE:0)
Block(-4,0,5,LOG:3)
Block(-3,0,5,DIRT:0)
Block(-2,0,5,DIRT:0)
Block(-1,0,5,DIRT:0)
Block(0,0,5,DIRT:0)
Block(1,0,5,DIRT:0)
Block(2,0,5,DIRT:0)
Block(3,0,5,DIRT:0)
Block(4,0,5,DIRT:0)
Block(5,0,5,DIRT:0)
Block(6,0,5,DIRT:0)
Block(7,0,5,DIRT:0)
Block(8,0,5,DIRT:0)
Block(-6,0,6,SPRUCE_FENCE:0)
Block(-5,0,6,PLANKS:3)
Block(-4,0,6,DIRT:0)
Block(-3,0,6,DIRT:0)
Block(-2,0,6,DIRT:0)
Block(-1,0,6,DIRT:0)
Block(0,0,6,DIRT:0)
Block(1,0,6,DIRT:0)
Block(2,0,6,DIRT:0)
Block(3,0,6,DIRT:0)
Block(4,0,6,DIRT:0)
Block(5,0,6,DIRT:0)
Block(6,0,6,DIRT:0)
Block(7,0,6,DIRT:0)
Block(8,0,6,DIRT:0)
Block(-7,0,7,SPRUCE_FENCE:0)
Block(-6,0,7,SPRUCE_FENCE:0)
Block(-5,0,7,PLANKS:3)
Block(-4,0,7,DIRT:0)
Block(-3,0,7,DIRT:0)
Block(-2,0,7,DIRT:0)
Block(-1,0,7,DIRT:0)
Block(0,0,7,DIRT:0)
Block(1,0,7,DIRT:0)
Block(2,0,7,DIRT:0)
Block(3,0,7,DIRT:0)
Block(4,0,7,DIRT:0)
Block(5,0,7,DIRT:0)
Block(6,0,7,DIRT:0)
Block(7,0,7,DIRT:0)
Block(8,0,7,DIRT:0)
Block(-7,0,8,SPRUCE_FENCE:0)
Block(-6,0,8,PLANKS:3)
Block(-5,0,8,DIRT:0)
Block(-4,0,8,DIRT:0)
Block(-3,0,8,DIRT:0)
Block(-2,0,8,DIRT:0)
Block(-1,0,8,DIRT:0)
Block(0,0,8,DIRT:0)
Block(1,0,8,DIRT:0)
Block(2,0,8,DIRT:0)
Block(3,0,8,DIRT:0)
Block(4,0,8,DIRT:0)
Block(5,0,8,DIRT:0)
Block(6,0,8,DIRT:0)
Block(7,0,8,DIRT:0)
Block(8,0,8,DIRT:0)
Block(-4,1,-7,SPRUCE_FENCE:0)
Block(-3,1,-7,LOG:3)
Block(-2,1,-7,DIRT:0)
Block(-1,1,-7,DIRT:0)
Block(0,1,-7,DIRT:0)
Block(1,1,-7,DIRT:0)
Block(2,1,-7,DIRT:0)
Block(3,1,-7,DIRT:0)
Block(4,1,-7,DIRT:0)
Block(5,1,-7,DIRT:0)
Block(6,1,-7,DIRT:0)
Block(7,1,-7,DIRT:0)
Block(8,1,-7,DIRT:0)
Block(-3,1,-6,SPRUCE_FENCE:0)
Block(-2,1,-6,PLANKS:3)
Block(-1,1,-6,DIRT:0)
Block(0,1,-6,DIRT:0)
Block(1,1,-6,DIRT:0)
Block(2,1,-6,DIRT:0)
Block(3,1,-6,DIRT:0)
Block(4,1,-6,DIRT:0)
Block(5,1,-6,DIRT:0)
Block(6,1,-6,DIRT:0)
Block(7,1,-6,DIRT:0)
Block(8,1,-6,DIRT:0)
Block(-3,1,-5,SPRUCE_FENCE:0)
Block(-2,1,-5,PLANKS:3)
Block(-1,1,-5,DIRT:0)
Block(0,1,-5,DIRT:0)
Block(1,1,-5,DIRT:0)
Block(2,1,-5,DIRT:0)
Block(3,1,-5,DIRT:0)
Block(4,1,-5,DIRT:0)
Block(5,1,-5,DIRT:0)
Block(6,1,-5,DIRT:0)
Block(7,1,-5,DIRT:0)
Block(8,1,-5,DIRT:0)
Block(-2,1,-4,PLANKS:3)
Block(-1,1,-4,DIRT:0)
Block(0,1,-4,DIRT:0)
Block(1,1,-4,DIRT:0)
Block(2,1,-4,DIRT:0)
Block(3,1,-4,DIRT:0)
Block(4,1,-4,DIRT:0)
Block(5,1,-4,DIRT:0)
Block(6,1,-4,DIRT:0)
Block(7,1,-4,DIRT:0)
Block(8,1,-4,DIRT:0)
Block(-1,1,-3,PLANKS:3)
Block(0,1,-3,DIRT:0)
Block(1,1,-3,DIRT:0)
Block(2,1,-3,DIRT:0)
Block(3,1,-3,DIRT:0)
Block(4,1,-3,DIRT:0)
Block(5,1,-3,DIRT:0)
Block(6,1,-3,DIRT:0)
Block(7,1,-3,DIRT:0)
Block(8,1,-3,DIRT:0)
Block(-1,1,-2,LOG:3)
Block(0,1,-2,DIRT:0)
Block(1,1,-2,DIRT:0)
Block(2,1,-2,DIRT:0)
Block(3,1,-2,DIRT:0)
Block(4,1,-2,DIRT:0)
Block(5,1,-2,DIRT:0)
Block(6,1,-2,DIRT:0)
Block(7,1,-2,DIRT:0)
Block(8,1,-2,DIRT:0)
Block(-1,1,-1,PLANKS:3)
Block(0,1,-1,DIRT:0)
Block(1,1,-1,DIRT:0)
Block(2,1,-1,DIRT:0)
Block(3,1,-1,DIRT:0)
Block(4,1,-1,DIRT:0)
Block(5,1,-1,DIRT:0)
Block(6,1,-1,DIRT:0)
Block(7,1,-1,DIRT:0)
Block(8,1,-1,DIRT:0)
Block(-1,1,0,PLANKS:3)
Block(0,1,0,DIRT:0)
Block(1,1,0,DIRT:0)
Block(2,1,0,DIRT:0)
Block(3,1,0,DIRT:0)
Block(4,1,0,DIRT:0)
Block(5,1,0,DIRT:0)
Block(6,1,0,DIRT:0)
Block(7,1,0,DIRT:0)
Block(8,1,0,DIRT:0)
Block(-1,1,1,PLANKS:3)
Block(0,1,1,DIRT:0)
Block(1,1,1,DIRT:0)
Block(2,1,1,DIRT:0)
Block(3,1,1,DIRT:0)
Block(4,1,1,DIRT:0)
Block(5,1,1,DIRT:0)
Block(6,1,1,DIRT:0)
Block(7,1,1,DIRT:0)
Block(8,1,1,DIRT:0)
Block(-2,1,2,LOG:3)
Block(-1,1,2,DIRT:0)
Block(0,1,2,DIRT:0)
Block(1,1,2,DIRT:0)
Block(2,1,2,DIRT:0)
Block(3,1,2,DIRT:0)
Block(4,1,2,DIRT:0)
Block(5,1,2,DIRT:0)
Block(6,1,2,DIRT:0)
Block(7,1,2,DIRT:0)
Block(8,1,2,DIRT:0)
Block(-3,1,3,SPRUCE_FENCE:0)
Block(-2,1,3,PLANKS:3)
Block(-1,1,3,DIRT:0)
Block(0,1,3,DIRT:0)
Block(1,1,3,DIRT:0)
Block(2,1,3,DIRT:0)
Block(3,1,3,DIRT:0)
Block(4,1,3,DIRT:0)
Block(5,1,3,DIRT:0)
Block(6,1,3,DIRT:0)
Block(7,1,3,DIRT:0)
Block(8,1,3,DIRT:0)
Block(-3,1,4,PLANKS:3)
Block(-2,1,4,DIRT:0)
Block(-1,1,4,DIRT:0)
Block(0,1,4,DIRT:0)
Block(1,1,4,DIRT:0)
Block(2,1,4,DIRT:0)
Block(3,1,4,DIRT:0)
Block(4,1,4,DIRT:0)
Block(5,1,4,DIRT:0)
Block(6,1,4,DIRT:0)
Block(7,1,4,DIRT:0)
Block(8,1,4,DIRT:0)
Block(-4,1,5,LOG:3)
Block(-3,1,5,DIRT:0)
Block(-2,1,5,DIRT:0)
Block(-1,1,5,DIRT:0)
Block(0,1,5,DIRT:0)
Block(1,1,5,DIRT:0)
Block(2,1,5,DIRT:0)
Block(3,1,5,DIRT:0)
Block(4,1,5,DIRT:0)
Block(5,1,5,DIRT:0)
Block(6,1,5,DIRT:0)
Block(7,1,5,DIRT:0)
Block(8,1,5,DIRT:0)
Block(-5,1,6,PLANKS:3)
Block(-4,1,6,DIRT:0)
Block(-3,1,6,DIRT:0)
Block(-2,1,6,DIRT:0)
Block(-1,1,6,DIRT:0)
Block(0,1,6,DIRT:0)
Block(1,1,6,DIRT:0)
Block(2,1,6,DIRT:0)
Block(3,1,6,DIRT:0)
Block(4,1,6,DIRT:0)
Block(5,1,6,DIRT:0)
Block(6,1,6,DIRT:0)
Block(7,1,6,DIRT:0)
Block(8,1,6,DIRT:0)
Block(-7,1,7,SPRUCE_FENCE:0)
Block(-6,1,7,SPRUCE_FENCE:0)
Block(-5,1,7,PLANKS:3)
Block(-4,1,7,DIRT:0)
Block(-3,1,7,DIRT:0)
Block(-2,1,7,DIRT:0)
Block(-1,1,7,DIRT:0)
Block(0,1,7,DIRT:0)
Block(1,1,7,DIRT:0)
Block(2,1,7,DIRT:0)
Block(3,1,7,DIRT:0)
Block(4,1,7,DIRT:0)
Block(5,1,7,DIRT:0)
Block(6,1,7,DIRT:0)
Block(7,1,7,DIRT:0)
Block(8,1,7,DIRT:0)
Block(-6,1,8,PLANKS:3)
Block(-5,1,8,DIRT:0)
Block(-4,1,8,DIRT:0)
Block(-3,1,8,DIRT:0)
Block(-2,1,8,DIRT:0)
Block(-1,1,8,DIRT:0)
Block(0,1,8,DIRT:0)
Block(1,1,8,DIRT:0)
Block(2,1,8,DIRT:0)
Block(3,1,8,DIRT:0)
Block(4,1,8,DIRT:0)
Block(5,1,8,DIRT:0)
Block(6,1,8,DIRT:0)
Block(7,1,8,DIRT:0)
Block(8,1,8,DIRT:0)
Block(-3,2,-7,LOG:3)
Block(-2,2,-7,DIRT:0)
Block(-1,2,-7,DIRT:0)
Block(0,2,-7,DIRT:0)
Block(1,2,-7,DIRT:0)
Block(2,2,-7,DIRT:0)
Block(3,2,-7,DIRT:0)
Block(4,2,-7,DIRT:0)
Block(5,2,-7,DIRT:0)
Block(6,2,-7,DIRT:0)
Block(7,2,-7,DIRT:0)
Block(8,2,-7,DIRT:0)
Block(-3,2,-6,SPRUCE_FENCE:0)
Block(-2,2,-6,PLANKS:3)
Block(-1,2,-6,DIRT:0)
Block(0,2,-6,DIRT:0)
Block(1,2,-6,DIRT:0)
Block(2,2,-6,DIRT:0)
Block(3,2,-6,DIRT:0)
Block(4,2,-6,DIRT:0)
Block(5,2,-6,DIRT:0)
Block(6,2,-6,DIRT:0)
Block(7,2,-6,DIRT:0)
Block(8,2,-6,DIRT:0)
Block(-2,2,-5,PLANKS:3)
Block(-1,2,-5,DIRT:0)
Block(0,2,-5,DIRT:0)
Block(1,2,-5,DIRT:0)
Block(2,2,-5,DIRT:0)
Block(3,2,-5,DIRT:0)
Block(4,2,-5,DIRT:0)
Block(5,2,-5,DIRT:0)
Block(6,2,-5,DIRT:0)
Block(7,2,-5,DIRT:0)
Block(8,2,-5,DIRT:0)
Block(-2,2,-4,PLANKS:3)
Block(-1,2,-4,DIRT:0)
Block(0,2,-4,DIRT:0)
Block(1,2,-4,DIRT:0)
Block(2,2,-4,DIRT:0)
Block(3,2,-4,DIRT:0)
Block(4,2,-4,DIRT:0)
Block(5,2,-4,DIRT:0)
Block(6,2,-4,DIRT:0)
Block(7,2,-4,DIRT:0)
Block(8,2,-4,DIRT:0)
Block(-1,2,-3,PLANKS:3)
Block(0,2,-3,DIRT:0)
Block(1,2,-3,DIRT:0)
Block(2,2,-3,DIRT:0)
Block(3,2,-3,DIRT:0)
Block(4,2,-3,DIRT:0)
Block(5,2,-3,DIRT:0)
Block(6,2,-3,DIRT:0)
Block(7,2,-3,DIRT:0)
Block(8,2,-3,DIRT:0)
Block(-1,2,-2,LOG:3)
Block(0,2,-2,DIRT:0)
Block(1,2,-2,DIRT:0)
Block(2,2,-2,DIRT:0)
Block(3,2,-2,DIRT:0)
Block(4,2,-2,DIRT:0)
Block(5,2,-2,DIRT:0)
Block(6,2,-2,DIRT:0)
Block(7,2,-2,DIRT:0)
Block(8,2,-2,DIRT:0)
Block(-1,2,-1,PLANKS:3)
Block(0,2,-1,DIRT:0)
Block(1,2,-1,DIRT:0)
Block(2,2,-1,DIRT:0)
Block(3,2,-1,DIRT:0)
Block(4,2,-1,DIRT:0)
Block(5,2,-1,DIRT:0)
Block(6,2,-1,DIRT:0)
Block(7,2,-1,DIRT:0)
Block(8,2,-1,DIRT:0)
Block(-1,2,0,PLANKS:3)
Block(0,2,0,DIRT:0)
Block(1,2,0,DIRT:0)
Block(2,2,0,DIRT:0)
Block(3,2,0,DIRT:0)
Block(4,2,0,DIRT:0)
Block(5,2,0,DIRT:0)
Block(6,2,0,DIRT:0)
Block(7,2,0,DIRT:0)
Block(8,2,0,DIRT:0)
Block(-1,2,1,PLANKS:3)
Block(0,2,1,DIRT:0)
Block(1,2,1,DIRT:0)
Block(2,2,1,DIRT:0)
Block(3,2,1,DIRT:0)
Block(4,2,1,DIRT:0)
Block(5,2,1,DIRT:0)
Block(6,2,1,DIRT:0)
Block(7,2,1,DIRT:0)
Block(8,2,1,DIRT:0)
Block(-2,2,2,LOG:3)
Block(-1,2,2,DIRT:0)
Block(0,2,2,DIRT:0)
Block(1,2,2,DIRT:0)
Block(2,2,2,DIRT:0)
Block(3,2,2,DIRT:0)
Block(4,2,2,DIRT:0)
Block(5,2,2,DIRT:0)
Block(6,2,2,DIRT:0)
Block(7,2,2,DIRT:0)
Block(8,2,2,DIRT:0)
Block(-3,2,3,SPRUCE_FENCE:0)
Block(-2,2,3,PLANKS:3)
Block(-1,2,3,DIRT:0)
Block(0,2,3,DIRT:0)
Block(1,2,3,DIRT:0)
Block(2,2,3,DIRT:0)
Block(3,2,3,DIRT:0)
Block(4,2,3,DIRT:0)
Block(5,2,3,DIRT:0)
Block(6,2,3,DIRT:0)
Block(7,2,3,DIRT:0)
Block(8,2,3,DIRT:0)
Block(-3,2,4,PLANKS:3)
Block(-2,2,4,DIRT:0)
Block(-1,2,4,DIRT:0)
Block(0,2,4,DIRT:0)
Block(1,2,4,DIRT:0)
Block(2,2,4,DIRT:0)
Block(3,2,4,DIRT:0)
Block(4,2,4,DIRT:0)
Block(5,2,4,DIRT:0)
Block(6,2,4,DIRT:0)
Block(7,2,4,DIRT:0)
Block(8,2,4,DIRT:0)
Block(-4,2,5,LOG:3)
Block(-3,2,5,DIRT:0)
Block(-2,2,5,DIRT:0)
Block(-1,2,5,DIRT:0)
Block(0,2,5,DIRT:0)
Block(1,2,5,DIRT:0)
Block(2,2,5,DIRT:0)
Block(3,2,5,DIRT:0)
Block(4,2,5,DIRT:0)
Block(5,2,5,DIRT:0)
Block(6,2,5,DIRT:0)
Block(7,2,5,DIRT:0)
Block(8,2,5,DIRT:0)
Block(-5,2,6,PLANKS:3)
Block(-4,2,6,DIRT:0)
Block(-3,2,6,DIRT:0)
Block(-2,2,6,DIRT:0)
Block(-1,2,6,DIRT:0)
Block(0,2,6,DIRT:0)
Block(1,2,6,DIRT:0)
Block(2,2,6,DIRT:0)
Block(3,2,6,DIRT:0)
Block(4,2,6,DIRT:0)
Block(5,2,6,DIRT:0)
Block(6,2,6,DIRT:0)
Block(7,2,6,DIRT:0)
Block(8,2,6,DIRT:0)
Block(-7,2,7,SPRUCE_FENCE:0)
Block(-6,2,7,SPRUCE_FENCE:0)
Block(-5,2,7,PLANKS:3)
Block(-4,2,7,DIRT:0)
Block(-3,2,7,DIRT:0)
Block(-2,2,7,DIRT:0)
Block(-1,2,7,DIRT:0)
Block(0,2,7,DIRT:0)
Block(1,2,7,DIRT:0)
Block(2,2,7,DIRT:0)
Block(3,2,7,DIRT:0)
Block(4,2,7,DIRT:0)
Block(5,2,7,DIRT:0)
Block(6,2,7,DIRT:0)
Block(7,2,7,DIRT:0)
Block(8,2,7,DIRT:0)
Block(-6,2,8,PLANKS:3)
Block(-5,2,8,DIRT:0)
Block(-4,2,8,DIRT:0)
Block(-3,2,8,DIRT:0)
Block(-2,2,8,DIRT:0)
Block(-1,2,8,DIRT:0)
Block(0,2,8,DIRT:0)
Block(1,2,8,DIRT:0)
Block(2,2,8,DIRT:0)
Block(3,2,8,DIRT:0)
Block(4,2,8,DIRT:0)
Block(5,2,8,DIRT:0)
Block(6,2,8,DIRT:0)
Block(7,2,8,DIRT:0)
Block(8,2,8,DIRT:0)
Block(-3,3,-7,LOG:3)
Block(-2,3,-7,DIRT:0)
Block(-1,3,-7,DIRT:0)
Block(0,3,-7,DIRT:0)
Block(1,3,-7,DIRT:0)
Block(2,3,-7,DIRT:0)
Block(3,3,-7,DIRT:0)
Block(4,3,-7,DIRT:0)
Block(5,3,-7,DIRT:0)
Block(6,3,-7,DIRT:0)
Block(7,3,-7,DIRT:0)
Block(8,3,-7,DIRT:0)
Block(-2,3,-6,PLANKS:3)
Block(-1,3,-6,DIRT:0)
Block(0,3,-6,DIRT:0)
Block(1,3,-6,DIRT:0)
Block(2,3,-6,DIRT:0)
Block(3,3,-6,DIRT:0)
Block(4,3,-6,DIRT:0)
Block(5,3,-6,DIRT:0)
Block(6,3,-6,DIRT:0)
Block(7,3,-6,DIRT:0)
Block(8,3,-6,DIRT:0)
Block(-2,3,-5,PLANKS:3)
Block(-1,3,-5,DIRT:0)
Block(0,3,-5,DIRT:0)
Block(1,3,-5,DIRT:0)
Block(2,3,-5,DIRT:0)
Block(3,3,-5,DIRT:0)
Block(4,3,-5,DIRT:0)
Block(5,3,-5,DIRT:0)
Block(6,3,-5,DIRT:0)
Block(7,3,-5,DIRT:0)
Block(8,3,-5,DIRT:0)
Block(-2,3,-4,PLANKS:3)
Block(-1,3,-4,DIRT:0)
Block(0,3,-4,DIRT:0)
Block(1,3,-4,DIRT:0)
Block(2,3,-4,DIRT:0)
Block(3,3,-4,DIRT:0)
Block(4,3,-4,DIRT:0)
Block(5,3,-4,DIRT:0)
Block(6,3,-4,DIRT:0)
Block(7,3,-4,DIRT:0)
Block(8,3,-4,DIRT:0)
Block(-1,3,-3,PLANKS:3)
Block(0,3,-3,DIRT:0)
Block(1,3,-3,DIRT:0)
Block(2,3,-3,DIRT:0)
Block(3,3,-3,DIRT:0)
Block(4,3,-3,DIRT:0)
Block(5,3,-3,DIRT:0)
Block(6,3,-3,DIRT:0)
Block(7,3,-3,DIRT:0)
Block(8,3,-3,DIRT:0)
Block(-1,3,-2,LOG:3)
Block(0,3,-2,DIRT:0)
Block(1,3,-2,DIRT:0)
Block(2,3,-2,DIRT:0)
Block(3,3,-2,DIRT:0)
Block(4,3,-2,DIRT:0)
Block(5,3,-2,DIRT:0)
Block(6,3,-2,DIRT:0)
Block(7,3,-2,DIRT:0)
Block(8,3,-2,DIRT:0)
Block(-1,3,-1,PLANKS:3)
Block(0,3,-1,DIRT:0)
Block(1,3,-1,DIRT:0)
Block(2,3,-1,DIRT:0)
Block(3,3,-1,DIRT:0)
Block(4,3,-1,DIRT:0)
Block(5,3,-1,DIRT:0)
Block(6,3,-1,DIRT:0)
Block(7,3,-1,DIRT:0)
Block(8,3,-1,DIRT:0)
Block(-1,3,0,PLANKS:3)
Block(0,3,0,DIRT:0)
Block(1,3,0,DIRT:0)
Block(2,3,0,DIRT:0)
Block(3,3,0,DIRT:0)
Block(4,3,0,DIRT:0)
Block(5,3,0,DIRT:0)
Block(6,3,0,DIRT:0)
Block(7,3,0,DIRT:0)
Block(8,3,0,DIRT:0)
Block(-1,3,1,PLANKS:3)
Block(0,3,1,DIRT:0)
Block(1,3,1,DIRT:0)
Block(2,3,1,DIRT:0)
Block(3,3,1,DIRT:0)
Block(4,3,1,DIRT:0)
Block(5,3,1,DIRT:0)
Block(6,3,1,DIRT:0)
Block(7,3,1,DIRT:0)
Block(8,3,1,DIRT:0)
Block(-2,3,2,LOG:3)
Block(-1,3,2,DIRT:0)
Block(0,3,2,DIRT:0)
Block(1,3,2,DIRT:0)
Block(2,3,2,DIRT:0)
Block(3,3,2,DIRT:0)
Block(4,3,2,DIRT:0)
Block(5,3,2,DIRT:0)
Block(6,3,2,DIRT:0)
Block(7,3,2,DIRT:0)
Block(8,3,2,DIRT:0)
Block(-2,3,3,PLANKS:3)
Block(-1,3,3,DIRT:0)
Block(0,3,3,DIRT:0)
Block(1,3,3,DIRT:0)
Block(2,3,3,DIRT:0)
Block(3,3,3,DIRT:0)
Block(4,3,3,DIRT:0)
Block(5,3,3,DIRT:0)
Block(6,3,3,DIRT:0)
Block(7,3,3,DIRT:0)
Block(8,3,3,DIRT:0)
Block(-3,3,4,PLANKS:3)
Block(-2,3,4,DIRT:0)
Block(-1,3,4,DIRT:0)
Block(0,3,4,DIRT:0)
Block(1,3,4,DIRT:0)
Block(2,3,4,DIRT:0)
Block(3,3,4,DIRT:0)
Block(4,3,4,DIRT:0)
Block(5,3,4,DIRT:0)
Block(6,3,4,DIRT:0)
Block(7,3,4,DIRT:0)
Block(8,3,4,DIRT:0)
Block(-4,3,5,LOG:3)
Block(-3,3,5,DIRT:0)
Block(-2,3,5,DIRT:0)
Block(-1,3,5,DIRT:0)
Block(0,3,5,DIRT:0)
Block(1,3,5,DIRT:0)
Block(2,3,5,DIRT:0)
Block(3,3,5,DIRT:0)
Block(4,3,5,DIRT:0)
Block(5,3,5,DIRT:0)
Block(6,3,5,DIRT:0)
Block(7,3,5,DIRT:0)
Block(8,3,5,DIRT:0)
Block(-5,3,6,PLANKS:3)
Block(-4,3,6,DIRT:0)
Block(-3,3,6,DIRT:0)
Block(-2,3,6,DIRT:0)
Block(-1,3,6,DIRT:0)
Block(0,3,6,DIRT:0)
Block(1,3,6,DIRT:0)
Block(2,3,6,DIRT:0)
Block(3,3,6,DIRT:0)
Block(4,3,6,DIRT:0)
Block(5,3,6,DIRT:0)
Block(6,3,6,DIRT:0)
Block(7,3,6,DIRT:0)
Block(8,3,6,DIRT:0)
Block(-6,3,7,SPRUCE_FENCE:0)
Block(-5,3,7,PLANKS:3)
Block(-4,3,7,DIRT:0)
Block(-3,3,7,DIRT:0)
Block(-2,3,7,DIRT:0)
Block(-1,3,7,DIRT:0)
Block(0,3,7,DIRT:0)
Block(1,3,7,DIRT:0)
Block(2,3,7,DIRT:0)
Block(3,3,7,DIRT:0)
Block(4,3,7,DIRT:0)
Block(5,3,7,DIRT:0)
Block(6,3,7,DIRT:0)
Block(7,3,7,DIRT:0)
Block(8,3,7,DIRT:0)
Block(-6,3,8,PLANKS:3)
Block(-5,3,8,DIRT:0)
Block(-4,3,8,DIRT:0)
Block(-3,3,8,DIRT:0)
Block(-2,3,8,DIRT:0)
Block(-1,3,8,DIRT:0)
Block(0,3,8,DIRT:0)
Block(1,3,8,DIRT:0)
Block(2,3,8,DIRT:0)
Block(3,3,8,DIRT:0)
Block(4,3,8,DIRT:0)
Block(5,3,8,DIRT:0)
Block(6,3,8,DIRT:0)
Block(7,3,8,DIRT:0)
Block(8,3,8,DIRT:0)
Block(-3,4,-7,LOG:3)
Block(-2,4,-7,GRASS:0)
Block(-1,4,-7,GRASS:0)
Block(0,4,-7,GRASS:0)
Block(1,4,-7,GRASS:0)
Block(2,4,-7,GRASS:0)
Block(3,4,-7,GRASS:0)
Block(4,4,-7,GRASS:0)
Block(5,4,-7,GRASS:0)
Block(6,4,-7,GRASS:0)
Block(7,4,-7,GRASS:0)
Block(8,4,-7,GRASS:0)
Block(-2,4,-6,PLANKS:3)
Block(-1,4,-6,GRASS:0)
Block(0,4,-6,GRASS:0)
Block(1,4,-6,GRASS:0)
Block(2,4,-6,GRASS:0)
Block(3,4,-6,GRASS:0)
Block(4,4,-6,GRASS:0)
Block(5,4,-6,GRASS:0)
Block(6,4,-6,GRASS:0)
Block(7,4,-6,GRASS:0)
Block(8,4,-6,GRASS:0)
Block(-2,4,-5,PLANKS:3)
Block(-1,4,-5,GRASS:0)
Block(0,4,-5,GRASS:0)
Block(1,4,-5,GRASS:0)
Block(2,4,-5,GRASS:0)
Block(3,4,-5,GRASS:0)
Block(4,4,-5,GRASS:0)
Block(5,4,-5,GRASS:0)
Block(6,4,-5,GRASS:0)
Block(7,4,-5,GRASS:0)
Block(8,4,-5,GRASS:0)
Block(-2,4,-4,PLANKS:3)
Block(-1,4,-4,GRASS:0)
Block(0,4,-4,GRASS:0)
Block(1,4,-4,GRASS:0)
Block(2,4,-4,GRASS:0)
Block(3,4,-4,GRASS:0)
Block(4,4,-4,GRASS:0)
Block(5,4,-4,GRASS:0)
Block(6,4,-4,GRASS:0)
Block(7,4,-4,GRASS:0)
Block(8,4,-4,GRASS:0)
Block(-1,4,-3,PLANKS:3)
Block(0,4,-3,GRASS:0)
Block(1,4,-3,GRASS:0)
Block(2,4,-3,GRASS:0)
Block(3,4,-3,GRASS:0)
Block(4,4,-3,GRASS:0)
Block(5,4,-3,GRASS:0)
Block(6,4,-3,GRASS:0)
Block(7,4,-3,GRASS:0)
Block(8,4,-3,GRASS:0)
Block(-1,4,-2,LOG:3)
Block(0,4,-2,GRASS:0)
Block(1,4,-2,GRASS:0)
Block(2,4,-2,GRASS:0)
Block(3,4,-2,GRASS:0)
Block(4,4,-2,GRASS:0)
Block(5,4,-2,GRASS:0)
Block(6,4,-2,GRASS:0)
Block(7,4,-2,GRASS:0)
Block(8,4,-2,GRASS:0)
Block(-1,4,-1,PLANKS:3)
Block(0,4,-1,GRASS:0)
Block(1,4,-1,GRASS:0)
Block(2,4,-1,GRASS:0)
Block(3,4,-1,GRASS:0)
Block(4,4,-1,GRASS:0)
Block(5,4,-1,GRASS:0)
Block(6,4,-1,GRASS:0)
Block(7,4,-1,GRASS:0)
Block(8,4,-1,GRASS:0)
Block(-1,4,0,PLANKS:3)
Block(0,4,0,GRASS:0)
Block(1,4,0,GRASS:0)
Block(2,4,0,GRASS:0)
Block(3,4,0,GRASS:0)
Block(4,4,0,GRASS:0)
Block(5,4,0,GRASS:0)
Block(6,4,0,GRASS:0)
Block(7,4,0,GRASS:0)
Block(8,4,0,GRASS:0)
Block(-1,4,1,PLANKS:3)
Block(0,4,1,GRASS:0)
Block(1,4,1,GRASS:0)
Block(2,4,1,GRASS:0)
Block(3,4,1,GRASS:0)
Block(4,4,1,GRASS:0)
Block(5,4,1,GRASS:0)
Block(6,4,1,GRASS:0)
Block(7,4,1,GRASS:0)
Block(8,4,1,GRASS:0)
Block(-2,4,2,LOG:3)
Block(-1,4,2,GRASS:0)
Block(0,4,2,GRASS:0)
Block(1,4,2,GRASS:0)
Block(2,4,2,GRASS:0)
Block(3,4,2,GRASS:0)
Block(4,4,2,GRASS:0)
Block(5,4,2,GRASS:0)
Block(6,4,2,GRASS:0)
Block(7,4,2,GRASS:0)
Block(8,4,2,GRASS:0)
Block(-2,4,3,PLANKS:3)
Block(-1,4,3,GRASS:0)
Block(0,4,3,GRASS:0)
Block(1,4,3,GRASS:0)
Block(2,4,3,GRASS:0)
Block(3,4,3,GRASS:0)
Block(4,4,3,GRASS:0)
Block(5,4,3,GRASS:0)
Block(6,4,3,GRASS:0)
Block(7,4,3,GRASS:0)
Block(8,4,3,GRASS:0)
Block(-3,4,4,PLANKS:3)
Block(-2,4,4,GRASS:0)
Block(-1,4,4,GRASS:0)
Block(0,4,4,GRASS:0)
Block(1,4,4,GRASS:0)
Block(2,4,4,GRASS:0)
Block(3,4,4,GRASS:0)
Block(4,4,4,GRASS:0)
Block(5,4,4,GRASS:0)
Block(6,4,4,GRASS:0)
Block(7,4,4,GRASS:0)
Block(8,4,4,GRASS:0)
Block(-4,4,5,LOG:3)
Block(-3,4,5,GRASS:0)
Block(-2,4,5,GRASS:0)
Block(-1,4,5,GRASS:0)
Block(0,4,5,GRASS:0)
Block(1,4,5,GRASS:0)
Block(2,4,5,GRASS:0)
Block(3,4,5,GRASS:0)
Block(4,4,5,GRASS:0)
Block(5,4,5,GRASS:0)
Block(6,4,5,GRASS:0)
Block(7,4,5,GRASS:0)
Block(8,4,5,GRASS:0)
Block(-5,4,6,PLANKS:3)
Block(-4,4,6,GRASS:0)
Block(-3,4,6,GRASS:0)
Block(-2,4,6,GRASS:0)
Block(-1,4,6,GRASS:0)
Block(0,4,6,GRASS:0)
Block(1,4,6,GRASS:0)
Block(2,4,6,GRASS:0)
Block(3,4,6,GRASS:0)
Block(4,4,6,GRASS:0)
Block(5,4,6,GRASS:0)
Block(6,4,6,GRASS:0)
Block(7,4,6,GRASS:0)
Block(8,4,6,GRASS:0)
Block(-5,4,7,PLANKS:3)
Block(-4,4,7,GRASS:0)
Block(-3,4,7,GRASS:0)
Block(-2,4,7,GRASS:0)
Block(-1,4,7,GRASS:0)
Block(0,4,7,GRASS:0)
Block(1,4,7,GRASS:0)
Block(2,4,7,GRASS:0)
Block(3,4,7,GRASS:0)
Block(4,4,7,GRASS:0)
Block(5,4,7,GRASS:0)
Block(6,4,7,GRASS:0)
Block(7,4,7,GRASS:0)
Block(8,4,7,GRASS:0)
Block(-6,4,8,PLANKS:3)
Block(-5,4,8,GRASS:0)
Block(-4,4,8,GRASS:0)
Block(-3,4,8,GRASS:0)
Block(-2,4,8,GRASS:0)
Block(-1,4,8,GRASS:0)
Block(0,4,8,GRASS:0)
Block(1,4,8,GRASS:0)
Block(2,4,8,GRASS:0)
Block(3,4,8,GRASS:0)
Block(4,4,8,GRASS:0)
Block(5,4,8,GRASS:0)
Block(6,4,8,GRASS:0)
Block(7,4,8,GRASS:0)
Block(8,4,8,GRASS:0)
Block(-3,5,-7,LOG:3)
Block(-2,5,-6,PLANKS:3)
Block(-2,5,-5,PLANKS:3)
Block(-2,5,-4,PLANKS:3)
Block(-1,5,-3,PLANKS:3)
Block(-1,5,-2,LOG:3)
Block(-1,5,-1,PLANKS:3)
Block(-1,5,0,PLANKS:3)
Block(-1,5,1,PLANKS:3)
Block(-2,5,2,LOG:3)
Block(-2,5,3,PLANKS:3)
Block(-3,5,4,PLANKS:3)
Block(-4,5,5,LOG:3)
Block(-5,5,6,PLANKS:3)
Block(-5,5,7,PLANKS:3)
Block(-6,5,8,PLANKS:3)
Block(-3,6,-7,LOG:3)
Block(-2,6,-6,PLANKS:3)
Block(-2,6,-5,WOODEN_SLAB:3)
Block(-2,6,-4,WOODEN_SLAB:3)
Block(-1,6,-3,PLANKS:3)
Block(-1,6,-2,LOG:3)
Block(-1,6,-1,WOODEN_SLAB:3)
Block(-1,6,0,WOODEN_SLAB:3)
Block(-1,6,1,WOODEN_SLAB:3)
Block(-2,6,2,LOG:3)
Block(-2,6,3,PLANKS:3)
Block(-3,6,4,WOODEN_SLAB:3)
Block(-4,6,5,LOG:3)
Block(-5,6,6,WOODEN_SLAB:3)
Block(-5,6,7,WOODEN_SLAB:3)
Block(-6,6,8,WOODEN_SLAB:3)
RandomBlock(-3,7,-7,STANDING_BANNER:4,../JungleNBT/banners/JungleBanner01.nbt,8,STANDING_BANNER:4,../JungleNBT/banners/JungleBanner02.nbt,8,STANDING_BANNER:4,../JungleNBT/banners/JungleBanner03.nbt,8,STANDING_BANNER:4,../JungleNBT/banners/JungleBanner04.nbt,8,STANDING_BANNER:4,../JungleNBT/banners/JungleBanner05.nbt,8,STANDING_BANNER:4,../JungleNBT/banners/JungleBanner06.nbt,8,STANDING_BANNER:4,../JungleNBT/banners/JungleBanner07.nbt,8,STANDING_BANNER:4,../JungleNBT/banners/JungleBanner08.nbt,8,STANDING_BANNER:4,../JungleNBT/banners/JungleBanner09.nbt,8,STANDING_BANNER:4,../JungleNBT/banners/JungleBanner10.nbt,8,STANDING_BANNER:4,../JungleNBT/banners/JungleBanner11.nbt,8,STANDING_BANNER:4,../JungleNBT/banners/JungleBanner12.nbt,8,STANDING_BANNER:4,../JungleNBT/banners/JungleBanner13.nbt,8,STANDING_BANNER:4,../JungleNBT/banners/JungleBanner14.nbt,8,STANDING_BANNER:4,../JungleNBT/banners/JungleBanner15.nbt,8,STANDING_BANNER:4,../JungleNBT/banners/JungleBanner16.nbt,8,STANDING_BANNER:4,../JungleNBT/banners/JungleBanner17.nbt,8,STANDING_BANNER:4,../JungleNBT/banners/JungleBanner18.nbt,8,STANDING_BANNER:4,../JungleNBT/banners/JungleBanner19.nbt,8,STANDING_BANNER:4,../JungleNBT/banners/JungleBanner20.nbt,100)
RandomBlock(-1,7,-2,STANDING_BANNER:4,../JungleNBT/banners/JungleBanner01.nbt,8,STANDING_BANNER:4,../JungleNBT/banners/JungleBanner02.nbt,8,STANDING_BANNER:4,../JungleNBT/banners/JungleBanner03.nbt,8,STANDING_BANNER:4,../JungleNBT/banners/JungleBanner04.nbt,8,STANDING_BANNER:4,../JungleNBT/banners/JungleBanner05.nbt,8,STANDING_BANNER:4,../JungleNBT/banners/JungleBanner06.nbt,8,STANDING_BANNER:4,../JungleNBT/banners/JungleBanner07.nbt,8,STANDING_BANNER:4,../JungleNBT/banners/JungleBanner08.nbt,8,STANDING_BANNER:4,../JungleNBT/banners/JungleBanner09.nbt,8,STANDING_BANNER:4,../JungleNBT/banners/JungleBanner10.nbt,8,STANDING_BANNER:4,../JungleNBT/banners/JungleBanner11.nbt,8,STANDING_BANNER:4,../JungleNBT/banners/JungleBanner12.nbt,8,STANDING_BANNER:4,../JungleNBT/banners/JungleBanner13.nbt,8,STANDING_BANNER:4,../JungleNBT/banners/JungleBanner14.nbt,8,STANDING_BANNER:4,../JungleNBT/banners/JungleBanner15.nbt,8,STANDING_BANNER:4,../JungleNBT/banners/JungleBanner16.nbt,8,STANDING_BANNER:4,../JungleNBT/banners/JungleBanner17.nbt,8,STANDING_BANNER:4,../JungleNBT/banners/JungleBanner18.nbt,8,STANDING_BANNER:4,../JungleNBT/banners/JungleBanner19.nbt,8,STANDING_BANNER:4,../JungleNBT/banners/JungleBanner20.nbt,100)
RandomBlock(-2,7,2,STANDING_BANNER:4,../JungleNBT/banners/JungleBanner01.nbt,8,STANDING_BANNER:4,../JungleNBT/banners/JungleBanner02.nbt,8,STANDING_BANNER:4,../JungleNBT/banners/JungleBanner03.nbt,8,STANDING_BANNER:4,../JungleNBT/banners/JungleBanner04.nbt,8,STANDING_BANNER:4,../JungleNBT/banners/JungleBanner05.nbt,8,STANDING_BANNER:4,../JungleNBT/banners/JungleBanner06.nbt,8,STANDING_BANNER:4,../JungleNBT/banners/JungleBanner07.nbt,8,STANDING_BANNER:4,../JungleNBT/banners/JungleBanner08.nbt,8,STANDING_BANNER:4,../JungleNBT/banners/JungleBanner09.nbt,8,STANDING_BANNER:4,../JungleNBT/banners/JungleBanner10.nbt,8,STANDING_BANNER:4,../JungleNBT/banners/JungleBanner11.nbt,8,STANDING_BANNER:4,../JungleNBT/banners/JungleBanner12.nbt,8,STANDING_BANNER:4,../JungleNBT/banners/JungleBanner13.nbt,8,STANDING_BANNER:4,../JungleNBT/banners/JungleBanner14.nbt,8,STANDING_BANNER:4,../JungleNBT/banners/JungleBanner15.nbt,8,STANDING_BANNER:4,../JungleNBT/banners/JungleBanner16.nbt,8,STANDING_BANNER:4,../JungleNBT/banners/JungleBanner17.nbt,8,STANDING_BANNER:4,../JungleNBT/banners/JungleBanner18.nbt,8,STANDING_BANNER:4,../JungleNBT/banners/JungleBanner19.nbt,8,STANDING_BANNER:4,../JungleNBT/banners/JungleBanner20.nbt,100)
RandomBlock(-4,7,5,STANDING_BANNER:4,../JungleNBT/banners/JungleBanner01.nbt,8,STANDING_BANNER:4,../JungleNBT/banners/JungleBanner02.nbt,8,STANDING_BANNER:4,../JungleNBT/banners/JungleBanner03.nbt,8,STANDING_BANNER:4,../JungleNBT/banners/JungleBanner04.nbt,8,STANDING_BANNER:4,../JungleNBT/banners/JungleBanner05.nbt,8,STANDING_BANNER:4,../JungleNBT/banners/JungleBanner06.nbt,8,STANDING_BANNER:4,../JungleNBT/banners/JungleBanner07.nbt,8,STANDING_BANNER:4,../JungleNBT/banners/JungleBanner08.nbt,8,STANDING_BANNER:4,../JungleNBT/banners/JungleBanner09.nbt,8,STANDING_BANNER:4,../JungleNBT/banners/JungleBanner10.nbt,8,STANDING_BANNER:4,../JungleNBT/banners/JungleBanner11.nbt,8,STANDING_BANNER:4,../JungleNBT/banners/JungleBanner12.nbt,8,STANDING_BANNER:4,../JungleNBT/banners/JungleBanner13.nbt,8,STANDING_BANNER:4,../JungleNBT/banners/JungleBanner14.nbt,8,STANDING_BANNER:4,../JungleNBT/banners/JungleBanner15.nbt,8,STANDING_BANNER:4,../JungleNBT/banners/JungleBanner16.nbt,8,STANDING_BANNER:4,../JungleNBT/banners/JungleBanner17.nbt,8,STANDING_BANNER:4,../JungleNBT/banners/JungleBanner18.nbt,8,STANDING_BANNER:4,../JungleNBT/banners/JungleBanner19.nbt,8,STANDING_BANNER:4,../JungleNBT/banners/JungleBanner20.nbt,100)
Branch(0,0,-16,JungleVillagePath06_01-02,NORTH,100)
