
#######################################################################
# +-----------------------------------------------------------------+ #
# |                            BO3 object                           | #
# +-----------------------------------------------------------------+ #
#######################################################################

Author: NLBlackEagle

Description: No description given

Version: 3

SettingsMode: WriteWithoutComments


#######################################################################
# +-----------------------------------------------------------------+ #
# |                          Main settings                          | #
# +-----------------------------------------------------------------+ #
#######################################################################

Tree: false

Frequency: 1

Rarity: 90.0

RotateRandomly: true

SpawnHeight: randomY

SpawnHeightOffset: 0

SpawnHeightVariance: 0

##############################
# Height Limits for the BO3. #
##############################

MinHeight: 65

MaxHeight: 90

######################
# Extrusion settings #
######################

ExtrudeMode: None

ExtrudeThroughBlocks: otg:air

MaxBranchDepth: 10


#######################################################################
# +-----------------------------------------------------------------+ #
# |                      Source block settings                      | #
# +-----------------------------------------------------------------+ #
#######################################################################

SourceBlocks: otg:stone,otg:dirt,minecraft:sand,otg:sandstone,otg:stained_clay,otg:air,minecraft:grass_block,minecraft:obsidian,minecraft:coal_ore,minecraft:iron_ore,minecraft:gravel,minecraft:grass,minecraft:sunflower,minecraft:rose_bush,minecraft:stone_bricks,minecraft:skeleton_skull,minecraft:tall_grass,minecraft:cobblestone_wall

MaxPercentageOutsideSourceBlock: 0

OutsideSourceBlock: placeAnyway

DoReplaceBlocks: false

IsOTGPlus: false


#######################################################################
# +-----------------------------------------------------------------+ #
# |                              Blocks                             | #
# +-----------------------------------------------------------------+ #
#######################################################################

B(-9,6,-2,minecraft:polished_andesite)
B(-9,7,-2,minecraft:polished_andesite)
B(-9,8,-2,minecraft:polished_andesite)
B(-9,9,-2,minecraft:polished_andesite)
B(-9,10,-2,minecraft:polished_andesite)
B(-9,11,-2,minecraft:black_glazed_terracotta[facing=west])
B(-9,10,-1,minecraft:smooth_stone_slab)
B(-9,6,0,minecraft:polished_andesite)
B(-9,7,0,minecraft:polished_andesite)
B(-9,8,0,minecraft:polished_andesite)
B(-9,9,0,minecraft:polished_andesite)
B(-9,6,1,minecraft:polished_andesite)
B(-9,7,1,minecraft:polished_andesite)
B(-9,8,1,minecraft:polished_andesite)
B(-9,9,1,minecraft:polished_andesite)
B(-9,10,2,minecraft:smooth_stone_slab)
B(-9,6,3,minecraft:polished_andesite)
B(-9,7,3,minecraft:polished_andesite)
B(-9,8,3,minecraft:polished_andesite)
B(-9,9,3,minecraft:polished_andesite)
B(-9,10,3,minecraft:polished_andesite)
B(-9,11,3,minecraft:black_glazed_terracotta[facing=west])
B(-8,10,-1,minecraft:smooth_stone_slab)
B(-8,6,0,minecraft:polished_andesite)
B(-8,7,0,minecraft:polished_andesite)
B(-8,8,0,minecraft:polished_andesite)
B(-8,9,0,minecraft:stone_brick_stairs[facing=west,half=bottom,shape=straight,waterlogged=false])
B(-8,6,1,minecraft:polished_andesite)
B(-8,7,1,minecraft:polished_andesite)
B(-8,8,1,minecraft:polished_andesite)
B(-8,9,1,minecraft:stone_brick_stairs[facing=west,half=bottom,shape=straight,waterlogged=false])
B(-8,10,2,minecraft:smooth_stone_slab)
B(-7,0,-2,minecraft:cobblestone)
B(-7,1,-2,minecraft:cobblestone)
B(-7,2,-2,minecraft:cobblestone)
B(-7,3,-2,minecraft:cobblestone)
B(-7,4,-2,minecraft:cobblestone)
B(-7,0,-1,minecraft:cobblestone)
B(-7,1,-1,minecraft:cobblestone)
B(-7,2,-1,minecraft:cobblestone)
B(-7,3,-1,minecraft:cobblestone)
B(-7,4,-1,minecraft:cobblestone)
B(-7,10,-1,minecraft:smooth_stone_slab)
B(-7,0,0,minecraft:cobblestone)
B(-7,1,0,minecraft:cobblestone)
B(-7,2,0,minecraft:cobblestone)
B(-7,3,0,minecraft:cobblestone)
B(-7,4,0,minecraft:cobblestone)
B(-7,6,0,minecraft:polished_andesite)
B(-7,7,0,minecraft:polished_andesite)
B(-7,8,0,minecraft:stone_brick_stairs[facing=west,half=bottom,shape=straight,waterlogged=false])
B(-7,0,1,minecraft:cobblestone)
B(-7,1,1,minecraft:cobblestone)
B(-7,2,1,minecraft:cobblestone)
B(-7,3,1,minecraft:cobblestone)
B(-7,4,1,minecraft:cobblestone)
B(-7,6,1,minecraft:polished_andesite)
B(-7,7,1,minecraft:polished_andesite)
B(-7,8,1,minecraft:stone_brick_stairs[facing=west,half=bottom,shape=straight,waterlogged=false])
B(-7,0,2,minecraft:cobblestone)
B(-7,1,2,minecraft:cobblestone)
B(-7,2,2,minecraft:cobblestone)
B(-7,3,2,minecraft:cobblestone)
B(-7,4,2,minecraft:cobblestone)
B(-7,10,2,minecraft:smooth_stone_slab)
B(-7,0,3,minecraft:cobblestone)
B(-7,1,3,minecraft:cobblestone)
B(-7,2,3,minecraft:cobblestone)
B(-7,3,3,minecraft:cobblestone)
B(-7,4,3,minecraft:cobblestone)
B(-6,10,-4,minecraft:smooth_stone_slab)
B(-6,10,-3,minecraft:smooth_stone_slab)
B(-6,0,-2,minecraft:cobblestone)
B(-6,1,-2,minecraft:cobblestone)
B(-6,2,-2,minecraft:cobblestone)
B(-6,3,-2,minecraft:cobblestone)
B(-6,4,-2,minecraft:cobblestone)
B(-6,10,-2,minecraft:smooth_stone_slab)
B(-6,0,-1,minecraft:cobblestone)
B(-6,1,-1,minecraft:cobblestone_stairs[facing=west,half=bottom,shape=straight,waterlogged=false])
B(-6,3,-1,minecraft:cobblestone_stairs[facing=west,half=top,shape=straight,waterlogged=false])
B(-6,4,-1,minecraft:cobblestone)
B(-6,10,-1,minecraft:smooth_stone_slab)
B(-6,0,0,minecraft:cobblestone)
B(-6,2,0,minecraft:cobblestone_stairs[facing=west,half=bottom,shape=straight,waterlogged=false])
B(-6,4,0,minecraft:cobblestone_stairs[facing=west,half=bottom,shape=straight,waterlogged=false])
B(-6,6,0,minecraft:polished_andesite)
B(-6,7,0,minecraft:stone_brick_stairs[facing=west,half=bottom,shape=straight,waterlogged=false])
B(-6,0,1,minecraft:cobblestone)
B(-6,1,1,minecraft:cobblestone_stairs[facing=west,half=bottom,shape=straight,waterlogged=false])
B(-6,3,1,minecraft:cobblestone_stairs[facing=west,half=top,shape=straight,waterlogged=false])
B(-6,4,1,minecraft:cobblestone)
B(-6,6,1,minecraft:polished_andesite)
B(-6,7,1,minecraft:stone_brick_stairs[facing=west,half=bottom,shape=straight,waterlogged=false])
B(-6,0,2,minecraft:cobblestone)
B(-6,2,2,minecraft:cobblestone_stairs[facing=west,half=bottom,shape=straight,waterlogged=false])
B(-6,4,2,minecraft:cobblestone_stairs[facing=west,half=bottom,shape=straight,waterlogged=false])
B(-6,10,2,minecraft:smooth_stone_slab)
B(-6,0,3,minecraft:cobblestone)
B(-6,1,3,minecraft:cobblestone)
B(-6,2,3,minecraft:cobblestone)
B(-6,3,3,minecraft:cobblestone)
B(-6,4,3,minecraft:cobblestone)
B(-6,10,3,minecraft:smooth_stone_slab)
B(-6,10,4,minecraft:smooth_stone_slab)
B(-6,10,5,minecraft:smooth_stone_slab)
B(-5,10,-4,minecraft:smooth_stone_slab)
B(-5,6,-3,minecraft:polished_andesite)
B(-5,7,-3,minecraft:polished_andesite)
B(-5,8,-3,minecraft:polished_andesite)
B(-5,9,-3,minecraft:polished_andesite)
B(-5,10,-3,minecraft:polished_andesite)
B(-5,11,-3,minecraft:black_glazed_terracotta[facing=east])
B(-5,0,-2,minecraft:cobblestone)
B(-5,1,-2,minecraft:cobblestone)
B(-5,2,-2,minecraft:cobblestone)
B(-5,3,-2,minecraft:cobblestone)
B(-5,4,-2,minecraft:cobblestone)
B(-5,6,-2,minecraft:stone_brick_stairs[facing=east,half=bottom,shape=straight,waterlogged=false])
B(-5,0,-1,minecraft:cobblestone)
B(-5,1,-1,minecraft:cobblestone)
B(-5,3,-1,minecraft:cobblestone)
B(-5,4,-1,minecraft:cobblestone)
B(-5,6,-1,minecraft:stone_brick_stairs[facing=east,half=bottom,shape=straight,waterlogged=false])
B(-5,0,0,minecraft:cobblestone)
B(-5,2,0,minecraft:cobblestone)
B(-5,4,0,minecraft:cobblestone)
B(-5,6,0,minecraft:polished_andesite)
B(-5,0,1,minecraft:cobblestone)
B(-5,1,1,minecraft:cobblestone)
B(-5,3,1,minecraft:cobblestone)
B(-5,4,1,minecraft:cobblestone)
B(-5,6,1,minecraft:polished_andesite)
B(-5,0,2,minecraft:cobblestone)
B(-5,2,2,minecraft:cobblestone)
B(-5,4,2,minecraft:cobblestone)
B(-5,6,2,minecraft:stone_brick_stairs[facing=east,half=bottom,shape=straight,waterlogged=false])
B(-5,0,3,minecraft:cobblestone)
B(-5,1,3,minecraft:cobblestone)
B(-5,2,3,minecraft:cobblestone)
B(-5,3,3,minecraft:cobblestone)
B(-5,4,3,minecraft:cobblestone)
B(-5,6,3,minecraft:stone_brick_stairs[facing=east,half=bottom,shape=straight,waterlogged=false])
B(-5,6,4,minecraft:polished_andesite)
B(-5,7,4,minecraft:polished_andesite)
B(-5,8,4,minecraft:polished_andesite)
B(-5,9,4,minecraft:polished_andesite)
B(-5,10,4,minecraft:polished_andesite)
B(-5,11,4,minecraft:black_glazed_terracotta)
B(-5,10,5,minecraft:smooth_stone_slab)
B(-4,0,-5,minecraft:cobblestone)
B(-4,1,-5,minecraft:cobblestone)
B(-4,2,-5,minecraft:cobblestone)
B(-4,3,-5,minecraft:cobblestone)
B(-4,4,-5,minecraft:cobblestone)
B(-4,0,-4,minecraft:cobblestone)
B(-4,1,-4,minecraft:cobblestone)
B(-4,2,-4,minecraft:cobblestone)
B(-4,3,-4,minecraft:cobblestone)
B(-4,4,-4,minecraft:cobblestone)
B(-4,10,-4,minecraft:smooth_stone_slab)
B(-4,0,-3,minecraft:cobblestone)
B(-4,1,-3,minecraft:cobblestone)
B(-4,2,-3,minecraft:cobblestone)
B(-4,3,-3,minecraft:cobblestone)
B(-4,4,-3,minecraft:cobblestone)
B(-4,6,-3,minecraft:stone_brick_stairs[facing=south,half=bottom,shape=straight,waterlogged=false])
B(-4,0,-2,minecraft:polished_andesite)
B(-4,1,-2,minecraft:polished_andesite)
B(-4,2,-2,minecraft:polished_andesite)
B(-4,3,-2,minecraft:polished_andesite)
B(-4,4,-2,minecraft:polished_andesite)
B(-4,5,-2,minecraft:polished_andesite)
B(-4,6,-2,minecraft:polished_andesite)
B(-4,7,-2,minecraft:redstone_wire)
B(-4,0,-1,minecraft:polished_andesite)
B(-4,1,-1,minecraft:polished_andesite)
B(-4,2,-1,minecraft:iron_bars[east=false,north=true,south=true,waterlogged=false,west=false])
B(-4,3,-1,minecraft:polished_andesite)
B(-4,4,-1,minecraft:stone_bricks)
B(-4,5,-1,minecraft:stone_bricks)
B(-4,6,-1,minecraft:polished_andesite)
B(-4,0,0,minecraft:polished_andesite)
B(-4,1,0,minecraft:iron_bars[east=false,north=true,south=true,waterlogged=false,west=false])
B(-4,2,0,minecraft:polished_andesite)
B(-4,3,0,minecraft:iron_bars[east=false,north=true,south=true,waterlogged=false,west=false])
B(-4,4,0,minecraft:stone_bricks)
B(-4,5,0,minecraft:stone_bricks)
B(-4,6,0,minecraft:polished_andesite)
B(-4,0,1,minecraft:polished_andesite)
B(-4,1,1,minecraft:polished_andesite)
B(-4,2,1,minecraft:iron_bars[east=false,north=true,south=true,waterlogged=false,west=false])
B(-4,3,1,minecraft:polished_andesite)
B(-4,4,1,minecraft:stone_bricks)
B(-4,5,1,minecraft:stone_bricks)
B(-4,6,1,minecraft:polished_andesite)
B(-4,0,2,minecraft:polished_andesite)
B(-4,1,2,minecraft:iron_bars[east=false,north=true,south=true,waterlogged=false,west=false])
B(-4,2,2,minecraft:polished_andesite)
B(-4,3,2,minecraft:iron_bars[east=false,north=true,south=true,waterlogged=false,west=false])
B(-4,4,2,minecraft:stone_bricks)
B(-4,5,2,minecraft:stone_bricks)
B(-4,6,2,minecraft:polished_andesite)
B(-4,0,3,minecraft:polished_andesite)
B(-4,1,3,minecraft:polished_andesite)
B(-4,2,3,minecraft:polished_andesite)
B(-4,3,3,minecraft:polished_andesite)
B(-4,4,3,minecraft:polished_andesite)
B(-4,5,3,minecraft:polished_andesite)
B(-4,6,3,minecraft:polished_andesite)
B(-4,0,4,minecraft:cobblestone)
B(-4,1,4,minecraft:cobblestone)
B(-4,2,4,minecraft:cobblestone)
B(-4,3,4,minecraft:cobblestone)
B(-4,4,4,minecraft:cobblestone)
B(-4,6,4,minecraft:stone_brick_stairs)
B(-4,0,5,minecraft:cobblestone)
B(-4,1,5,minecraft:cobblestone)
B(-4,2,5,minecraft:cobblestone)
B(-4,3,5,minecraft:cobblestone)
B(-4,4,5,minecraft:cobblestone)
B(-4,10,5,minecraft:smooth_stone_slab)
B(-4,0,6,minecraft:cobblestone)
B(-4,1,6,minecraft:cobblestone)
B(-4,2,6,minecraft:cobblestone)
B(-4,3,6,minecraft:cobblestone)
B(-4,4,6,minecraft:cobblestone)
B(-3,0,-5,minecraft:cobblestone)
B(-3,1,-5,minecraft:cobblestone)
B(-3,2,-5,minecraft:cobblestone)
B(-3,3,-5,minecraft:cobblestone)
B(-3,4,-5,minecraft:cobblestone)
B(-3,0,-4,minecraft:cobblestone)
B(-3,1,-4,minecraft:cobblestone)
B(-3,3,-4,minecraft:cobblestone_stairs)
B(-3,4,-4,minecraft:cobblestone)
B(-3,10,-4,minecraft:smooth_stone_slab)
B(-3,0,-3,minecraft:cobblestone)
B(-3,1,-3,minecraft:cobblestone)
B(-3,3,-3,minecraft:cobblestone)
B(-3,4,-3,minecraft:cobblestone)
B(-3,6,-3,minecraft:stone_brick_stairs[facing=south,half=bottom,shape=straight,waterlogged=false])
B(-3,0,-2,minecraft:polished_andesite)
B(-3,1,-2,minecraft:polished_andesite)
B(-3,2,-2,minecraft:iron_bars[east=true,north=false,south=false,waterlogged=false,west=true])
B(-3,3,-2,minecraft:polished_andesite)
B(-3,4,-2,minecraft:stone_bricks)
B(-3,5,-2,minecraft:stone_bricks)
B(-3,6,-2,minecraft:polished_andesite)
B(-3,0,-1,minecraft:cobblestone)
B(-3,5,-1,minecraft:pink_concrete)
B(-3,6,-1,minecraft:water)
B(-3,0,0,minecraft:cobblestone)
B(-3,5,0,minecraft:black_terracotta)
B(-3,6,0,minecraft:water)
B(-3,0,1,minecraft:cobblestone)
B(-3,5,1,minecraft:red_terracotta)
B(-3,6,1,minecraft:water)
B(-3,0,2,minecraft:cobblestone)
B(-3,5,2,minecraft:pink_concrete)
B(-3,6,2,minecraft:water)
B(-3,0,3,minecraft:polished_andesite)
B(-3,1,3,minecraft:iron_bars[east=true,north=false,south=false,waterlogged=false,west=true])
B(-3,2,3,minecraft:polished_andesite)
B(-3,3,3,minecraft:iron_bars[east=true,north=false,south=false,waterlogged=false,west=true])
B(-3,4,3,minecraft:stone_bricks)
B(-3,5,3,minecraft:stone_bricks)
B(-3,6,3,minecraft:polished_andesite)
B(-3,0,4,minecraft:cobblestone)
B(-3,2,4,minecraft:cobblestone)
B(-3,4,4,minecraft:cobblestone)
B(-3,6,4,minecraft:stone_brick_stairs)
B(-3,0,5,minecraft:cobblestone)
B(-3,2,5,minecraft:cobblestone_stairs[facing=south,half=bottom,shape=straight,waterlogged=false])
B(-3,4,5,minecraft:cobblestone_stairs[facing=south,half=bottom,shape=straight,waterlogged=false])
B(-3,10,5,minecraft:smooth_stone_slab)
B(-3,0,6,minecraft:cobblestone)
B(-3,1,6,minecraft:cobblestone)
B(-3,2,6,minecraft:cobblestone)
B(-3,3,6,minecraft:cobblestone)
B(-3,4,6,minecraft:cobblestone)
B(-2,0,-5,minecraft:cobblestone)
B(-2,1,-5,minecraft:cobblestone)
B(-2,2,-5,minecraft:cobblestone)
B(-2,3,-5,minecraft:cobblestone)
B(-2,4,-5,minecraft:cobblestone)
B(-2,0,-4,minecraft:cobblestone)
B(-2,2,-4,minecraft:cobblestone_stairs)
B(-2,4,-4,minecraft:cobblestone_stairs)
B(-2,10,-4,minecraft:smooth_stone_slab)
B(-2,0,-3,minecraft:cobblestone)
B(-2,2,-3,minecraft:cobblestone)
B(-2,4,-3,minecraft:cobblestone)
B(-2,6,-3,minecraft:stone_brick_stairs[facing=south,half=bottom,shape=straight,waterlogged=false])
B(-2,0,-2,minecraft:polished_andesite)
B(-2,1,-2,minecraft:iron_bars[east=true,north=false,south=false,waterlogged=false,west=true])
B(-2,2,-2,minecraft:polished_andesite)
B(-2,3,-2,minecraft:iron_bars[east=true,north=false,south=false,waterlogged=false,west=true])
B(-2,4,-2,minecraft:stone_bricks)
B(-2,5,-2,minecraft:stone_bricks)
B(-2,6,-2,minecraft:polished_andesite)
B(-2,0,-1,minecraft:cobblestone)
B(-2,5,-1,minecraft:red_terracotta)
B(-2,6,-1,minecraft:water)
B(-2,0,0,minecraft:cobblestone)
B(-2,5,0,minecraft:black_terracotta)
B(-2,6,0,minecraft:polished_andesite)
B(-2,7,0,minecraft:cobblestone_stairs[facing=south,half=bottom,shape=outer_left,waterlogged=false])
B(-2,8,0,minecraft:smooth_stone_slab)
B(-2,0,1,minecraft:cobblestone)
B(-2,5,1,minecraft:red_glazed_terracotta[facing=east])
B(-2,6,1,minecraft:polished_andesite)
B(-2,7,1,minecraft:cobblestone_stairs[facing=east,half=bottom,shape=outer_left,waterlogged=false])
B(-2,8,1,minecraft:smooth_stone_slab)
B(-2,0,2,minecraft:cobblestone)
B(-2,5,2,minecraft:black_terracotta)
B(-2,6,2,minecraft:water)
B(-2,0,3,minecraft:polished_andesite)
B(-2,1,3,minecraft:polished_andesite)
B(-2,2,3,minecraft:iron_bars[east=true,north=false,south=false,waterlogged=false,west=true])
B(-2,3,3,minecraft:polished_andesite)
B(-2,4,3,minecraft:stone_bricks)
B(-2,5,3,minecraft:stone_bricks)
B(-2,6,3,minecraft:polished_andesite)
B(-2,0,4,minecraft:cobblestone)
B(-2,1,4,minecraft:cobblestone)
B(-2,3,4,minecraft:cobblestone)
B(-2,4,4,minecraft:cobblestone)
B(-2,6,4,minecraft:stone_brick_stairs)
B(-2,0,5,minecraft:cobblestone)
B(-2,1,5,minecraft:cobblestone_stairs[facing=south,half=top,shape=straight,waterlogged=false])
B(-2,2,5,minecraft:cobblestone)
B(-2,3,5,minecraft:cobblestone_stairs[facing=south,half=top,shape=straight,waterlogged=false])
B(-2,4,5,minecraft:cobblestone)
B(-2,10,5,minecraft:smooth_stone_slab)
B(-2,0,6,minecraft:cobblestone)
B(-2,1,6,minecraft:cobblestone)
B(-2,2,6,minecraft:cobblestone)
B(-2,3,6,minecraft:cobblestone)
B(-2,4,6,minecraft:cobblestone)
B(-1,0,-5,minecraft:cobblestone)
B(-1,1,-5,minecraft:cobblestone)
B(-1,2,-5,minecraft:cobblestone)
B(-1,3,-5,minecraft:cobblestone)
B(-1,4,-5,minecraft:cobblestone)
B(-1,0,-4,minecraft:cobblestone)
B(-1,1,-4,minecraft:cobblestone)
B(-1,2,-4,minecraft:cobblestone)
B(-1,3,-4,minecraft:cobblestone_stairs[facing=north,half=top,shape=straight,waterlogged=false])
B(-1,4,-4,minecraft:cobblestone)
B(-1,10,-4,minecraft:smooth_stone_slab)
B(-1,0,-3,minecraft:cobblestone)
B(-1,1,-3,minecraft:cobblestone)
B(-1,3,-3,minecraft:cobblestone)
B(-1,4,-3,minecraft:cobblestone)
B(-1,6,-3,minecraft:stone_brick_stairs[facing=south,half=bottom,shape=straight,waterlogged=false])
B(-1,0,-2,minecraft:polished_andesite)
B(-1,1,-2,minecraft:polished_andesite)
B(-1,2,-2,minecraft:iron_bars[east=true,north=false,south=false,waterlogged=false,west=true])
B(-1,3,-2,minecraft:polished_andesite)
B(-1,4,-2,minecraft:stone_bricks)
B(-1,5,-2,minecraft:stone_bricks)
B(-1,6,-2,minecraft:polished_andesite)
B(-1,0,-1,minecraft:cobblestone)
B(-1,5,-1,minecraft:red_terracotta)
B(-1,6,-1,minecraft:water)
B(-1,0,0,minecraft:cobblestone)
B(-1,5,0,minecraft:black_terracotta)
B(-1,6,0,minecraft:polished_andesite)
B(-1,7,0,minecraft:cobblestone_stairs[facing=south,half=bottom,shape=straight,waterlogged=false])
B(-1,8,0,minecraft:smooth_stone_slab)
B(-1,0,1,minecraft:cobblestone)
B(-1,5,1,minecraft:black_terracotta)
B(-1,6,1,minecraft:polished_andesite)
B(-1,7,1,minecraft:cobblestone_stairs)
B(-1,8,1,minecraft:smooth_stone_slab)
B(-1,0,2,minecraft:cobblestone)
B(-1,5,2,minecraft:red_glazed_terracotta[facing=east])
B(-1,6,2,minecraft:water)
B(-1,0,3,minecraft:polished_andesite)
B(-1,1,3,minecraft:iron_bars[east=true,north=false,south=false,waterlogged=false,west=true])
B(-1,2,3,minecraft:polished_andesite)
B(-1,3,3,minecraft:iron_bars[east=true,north=false,south=false,waterlogged=false,west=true])
B(-1,4,3,minecraft:stone_bricks)
B(-1,5,3,minecraft:stone_bricks)
B(-1,6,3,minecraft:polished_andesite)
B(-1,7,3,minecraft:redstone_wire)
B(-1,0,4,minecraft:cobblestone)
B(-1,2,4,minecraft:cobblestone)
B(-1,4,4,minecraft:cobblestone)
B(-1,6,4,minecraft:stone_brick_stairs)
B(-1,0,5,minecraft:cobblestone)
B(-1,2,5,minecraft:cobblestone_stairs[facing=south,half=bottom,shape=straight,waterlogged=false])
B(-1,4,5,minecraft:cobblestone_stairs[facing=south,half=bottom,shape=straight,waterlogged=false])
B(-1,10,5,minecraft:smooth_stone_slab)
B(-1,0,6,minecraft:cobblestone)
B(-1,1,6,minecraft:cobblestone)
B(-1,2,6,minecraft:cobblestone)
B(-1,3,6,minecraft:cobblestone)
B(-1,4,6,minecraft:cobblestone)
B(0,0,-5,minecraft:cobblestone)
B(0,1,-5,minecraft:cobblestone)
B(0,2,-5,minecraft:cobblestone)
B(0,3,-5,minecraft:cobblestone)
B(0,4,-5,minecraft:cobblestone)
B(0,0,-4,minecraft:cobblestone)
B(0,2,-4,minecraft:cobblestone_stairs)
B(0,4,-4,minecraft:cobblestone_stairs)
B(0,10,-4,minecraft:smooth_stone_slab)
B(0,0,-3,minecraft:cobblestone)
B(0,2,-3,minecraft:cobblestone)
B(0,4,-3,minecraft:cobblestone)
B(0,6,-3,minecraft:stone_brick_stairs[facing=south,half=bottom,shape=straight,waterlogged=false])
B(0,0,-2,minecraft:polished_andesite)
B(0,1,-2,minecraft:iron_bars[east=true,north=false,south=false,waterlogged=false,west=true])
B(0,2,-2,minecraft:polished_andesite)
B(0,3,-2,minecraft:iron_bars[east=true,north=false,south=false,waterlogged=false,west=true])
B(0,4,-2,minecraft:stone_bricks)
B(0,5,-2,minecraft:stone_bricks)
B(0,6,-2,minecraft:polished_andesite)
B(0,7,-2,minecraft:redstone_wire)
B(0,0,-1,minecraft:cobblestone)
B(0,5,-1,minecraft:black_terracotta)
B(0,6,-1,minecraft:water)
B(0,0,0,minecraft:cobblestone)
B(0,5,0,minecraft:pink_concrete)
B(0,6,0,minecraft:polished_andesite)
B(0,7,0,minecraft:cobblestone_stairs[facing=south,half=bottom,shape=straight,waterlogged=false])
B(0,8,0,minecraft:smooth_stone_slab)
B(0,0,1,minecraft:cobblestone)
B(0,5,1,minecraft:black_terracotta)
B(0,6,1,minecraft:polished_andesite)
B(0,7,1,minecraft:cobblestone_stairs)
B(0,8,1,minecraft:smooth_stone_slab)
B(0,0,2,minecraft:cobblestone)
B(0,5,2,minecraft:black_terracotta)
B(0,6,2,minecraft:water)
B(0,0,3,minecraft:polished_andesite)
B(0,1,3,minecraft:polished_andesite)
B(0,2,3,minecraft:iron_bars[east=true,north=false,south=false,waterlogged=false,west=true])
B(0,3,3,minecraft:polished_andesite)
B(0,4,3,minecraft:stone_bricks)
B(0,5,3,minecraft:stone_bricks)
B(0,6,3,minecraft:polished_andesite)
B(0,0,4,minecraft:cobblestone)
B(0,1,4,minecraft:cobblestone)
B(0,3,4,minecraft:cobblestone)
B(0,4,4,minecraft:cobblestone)
B(0,6,4,minecraft:stone_brick_stairs)
B(0,0,5,minecraft:cobblestone)
B(0,1,5,minecraft:cobblestone_stairs[facing=south,half=top,shape=straight,waterlogged=false])
B(0,3,5,minecraft:cobblestone_stairs[facing=south,half=top,shape=straight,waterlogged=false])
B(0,4,5,minecraft:cobblestone)
B(0,10,5,minecraft:smooth_stone_slab)
B(0,0,6,minecraft:cobblestone)
B(0,1,6,minecraft:cobblestone)
B(0,2,6,minecraft:cobblestone)
B(0,3,6,minecraft:cobblestone)
B(0,4,6,minecraft:cobblestone)
B(1,0,-5,minecraft:cobblestone)
B(1,1,-5,minecraft:cobblestone)
B(1,2,-5,minecraft:cobblestone)
B(1,3,-5,minecraft:cobblestone)
B(1,4,-5,minecraft:cobblestone)
B(1,0,-4,minecraft:cobblestone)
B(1,1,-4,minecraft:cobblestone)
B(1,3,-4,minecraft:cobblestone_stairs[facing=north,half=top,shape=straight,waterlogged=false])
B(1,4,-4,minecraft:cobblestone)
B(1,10,-4,minecraft:smooth_stone_slab)
B(1,0,-3,minecraft:cobblestone)
B(1,1,-3,minecraft:cobblestone)
B(1,3,-3,minecraft:cobblestone)
B(1,4,-3,minecraft:cobblestone)
B(1,6,-3,minecraft:stone_brick_stairs[facing=south,half=bottom,shape=straight,waterlogged=false])
B(1,0,-2,minecraft:polished_andesite)
B(1,1,-2,minecraft:polished_andesite)
B(1,2,-2,minecraft:iron_bars[east=true,north=false,south=false,waterlogged=false,west=true])
B(1,3,-2,minecraft:polished_andesite)
B(1,4,-2,minecraft:stone_bricks)
B(1,5,-2,minecraft:stone_bricks)
B(1,6,-2,minecraft:polished_andesite)
B(1,0,-1,minecraft:cobblestone)
B(1,5,-1,minecraft:black_terracotta)
B(1,6,-1,minecraft:water)
B(1,0,0,minecraft:cobblestone)
B(1,5,0,minecraft:pink_concrete)
B(1,6,0,minecraft:polished_andesite)
B(1,7,0,minecraft:cobblestone_stairs[facing=west,half=bottom,shape=outer_left,waterlogged=false])
B(1,8,0,minecraft:smooth_stone_slab)
B(1,0,1,minecraft:cobblestone)
B(1,5,1,minecraft:red_glazed_terracotta[facing=east])
B(1,6,1,minecraft:polished_andesite)
B(1,7,1,minecraft:cobblestone_stairs[facing=north,half=bottom,shape=outer_left,waterlogged=false])
B(1,8,1,minecraft:smooth_stone_slab)
B(1,0,2,minecraft:cobblestone)
B(1,5,2,minecraft:red_terracotta)
B(1,6,2,minecraft:water)
B(1,0,3,minecraft:polished_andesite)
B(1,1,3,minecraft:iron_bars[east=true,north=false,south=false,waterlogged=false,west=true])
B(1,2,3,minecraft:polished_andesite)
B(1,3,3,minecraft:iron_bars[east=true,north=false,south=false,waterlogged=false,west=true])
B(1,4,3,minecraft:stone_bricks)
B(1,5,3,minecraft:stone_bricks)
B(1,6,3,minecraft:polished_andesite)
B(1,0,4,minecraft:cobblestone)
B(1,2,4,minecraft:cobblestone)
B(1,4,4,minecraft:cobblestone)
B(1,6,4,minecraft:stone_brick_stairs)
B(1,0,5,minecraft:cobblestone)
B(1,2,5,minecraft:cobblestone_stairs[facing=south,half=bottom,shape=straight,waterlogged=false])
B(1,4,5,minecraft:cobblestone_stairs[facing=south,half=bottom,shape=straight,waterlogged=false])
B(1,10,5,minecraft:smooth_stone_slab)
B(1,0,6,minecraft:cobblestone)
B(1,1,6,minecraft:cobblestone)
B(1,2,6,minecraft:cobblestone)
B(1,3,6,minecraft:cobblestone)
B(1,4,6,minecraft:cobblestone)
B(2,0,-5,minecraft:cobblestone)
B(2,1,-5,minecraft:cobblestone)
B(2,2,-5,minecraft:cobblestone)
B(2,3,-5,minecraft:cobblestone)
B(2,4,-5,minecraft:cobblestone)
B(2,0,-4,minecraft:cobblestone)
B(2,1,-4,minecraft:tripwire_hook[attached=true,facing=south,powered=false])
B(2,2,-4,minecraft:cobblestone_stairs)
B(2,3,-4,minecraft:cobblestone)
B(2,4,-4,minecraft:cobblestone)
B(2,5,-4,minecraft:redstone_wire[east=side,north=none,power=0,south=side,west=none])
B(2,10,-4,minecraft:smooth_stone_slab)
B(2,0,-3,minecraft:cobblestone)
B(2,1,-3,minecraft:tripwire[attached=true,disarmed=false,east=false,north=false,powered=false,south=false,west=false])
B(2,2,-3,minecraft:cobblestone)
B(2,4,-3,minecraft:cobblestone)
B(2,5,-3,minecraft:redstone_wire[east=none,north=side,power=0,south=side,west=none])
B(2,6,-3,minecraft:stone_brick_stairs[facing=south,half=bottom,shape=straight,waterlogged=false])
B(2,0,-2,minecraft:polished_andesite)
B(2,1,-2,minecraft:tripwire[attached=true,disarmed=false,east=false,north=false,powered=false,south=false,west=false])
B(2,2,-2,minecraft:polished_andesite)
B(2,4,-2,minecraft:polished_andesite)
B(2,5,-2,minecraft:stone_bricks)
B(2,6,-2,minecraft:polished_andesite)
B(2,0,-1,minecraft:cobblestone)
B(2,1,-1,minecraft:tripwire[attached=true,disarmed=false,east=false,north=false,powered=false,south=false,west=false])
B(2,5,-1,minecraft:red_glazed_terracotta[facing=south])
B(2,6,-1,minecraft:water)
B(2,0,0,minecraft:cobblestone)
B(2,1,0,minecraft:tripwire[attached=true,disarmed=false,east=false,north=false,powered=false,south=false,west=false])
B(2,5,0,minecraft:black_terracotta)
B(2,6,0,minecraft:water)
B(2,0,1,minecraft:cobblestone)
B(2,1,1,minecraft:tripwire[attached=true,disarmed=false,east=false,north=false,powered=false,south=false,west=false])
B(2,5,1,minecraft:black_terracotta)
B(2,6,1,minecraft:water)
B(2,0,2,minecraft:cobblestone)
B(2,1,2,minecraft:tripwire_hook[attached=true,facing=north,powered=false])
B(2,5,2,minecraft:black_terracotta)
B(2,6,2,minecraft:water)
B(2,0,3,minecraft:polished_andesite)
B(2,1,3,minecraft:polished_andesite)
B(2,2,3,minecraft:iron_bars[east=true,north=false,south=false,waterlogged=false,west=true])
B(2,3,3,minecraft:polished_andesite)
B(2,4,3,minecraft:stone_bricks)
B(2,5,3,minecraft:stone_bricks)
B(2,6,3,minecraft:polished_andesite)
B(2,0,4,minecraft:cobblestone)
B(2,1,4,minecraft:cobblestone)
B(2,3,4,minecraft:cobblestone)
B(2,4,4,minecraft:cobblestone)
B(2,6,4,minecraft:stone_brick_stairs)
B(2,0,5,minecraft:cobblestone)
B(2,1,5,minecraft:cobblestone_stairs[facing=south,half=top,shape=straight,waterlogged=false])
B(2,3,5,minecraft:cobblestone_stairs[facing=south,half=top,shape=straight,waterlogged=false])
B(2,4,5,minecraft:cobblestone)
B(2,10,5,minecraft:smooth_stone_slab)
B(2,0,6,minecraft:cobblestone)
B(2,1,6,minecraft:cobblestone)
B(2,2,6,minecraft:cobblestone)
B(2,3,6,minecraft:cobblestone)
B(2,4,6,minecraft:cobblestone)
B(3,0,-5,minecraft:cobblestone)
B(3,1,-5,minecraft:redstone_wire[east=side,north=none,power=0,south=none,west=side])
B(3,2,-5,minecraft:cobblestone)
B(3,3,-5,minecraft:cobblestone)
B(3,4,-5,minecraft:cobblestone)
B(3,0,-4,minecraft:cobblestone)
B(3,1,-4,minecraft:cobblestone)
B(3,2,-4,minecraft:cobblestone)
B(3,3,-4,minecraft:cobblestone)
B(3,4,-4,minecraft:cobblestone)
B(3,5,-4,minecraft:redstone_wire[east=side,north=none,power=0,south=none,west=side])
B(3,10,-4,minecraft:smooth_stone_slab)
B(3,0,-3,minecraft:cobblestone)
B(3,1,-3,minecraft:cobblestone)
B(3,2,-3,minecraft:cobblestone)
B(3,3,-3,minecraft:cobblestone)
B(3,4,-3,minecraft:cobblestone)
B(3,6,-3,minecraft:stone_brick_stairs[facing=south,half=bottom,shape=straight,waterlogged=false])
B(3,0,-2,minecraft:polished_andesite)
B(3,1,-2,minecraft:polished_andesite)
B(3,2,-2,minecraft:polished_andesite)
B(3,3,-2,minecraft:polished_andesite)
B(3,4,-2,minecraft:polished_andesite)
B(3,5,-2,minecraft:polished_andesite)
B(3,6,-2,minecraft:polished_andesite)
B(3,0,-1,minecraft:cobblestone)
B(3,1,-1,minecraft:polished_andesite)
B(3,2,-1,minecraft:polished_andesite)
B(3,3,-1,minecraft:polished_andesite)
B(3,4,-1,minecraft:stone_bricks)
B(3,5,-1,minecraft:stone_bricks)
B(3,6,-1,minecraft:polished_andesite)
B(3,0,0,minecraft:cobblestone)
B(3,4,0,minecraft:stone_bricks)
B(3,5,0,minecraft:stone_bricks)
B(3,6,0,minecraft:polished_andesite)
B(3,7,0,minecraft:redstone_wire)
B(3,0,1,minecraft:cobblestone)
B(3,4,1,minecraft:stone_bricks)
B(3,5,1,minecraft:stone_bricks)
B(3,6,1,minecraft:polished_andesite)
B(3,0,2,minecraft:cobblestone)
B(3,1,2,minecraft:polished_andesite)
B(3,2,2,minecraft:polished_andesite)
B(3,3,2,minecraft:polished_andesite)
B(3,4,2,minecraft:stone_bricks)
B(3,5,2,minecraft:stone_bricks)
B(3,6,2,minecraft:polished_andesite)
B(3,0,3,minecraft:polished_andesite)
B(3,1,3,minecraft:redstone_wire[east=none,north=side,power=0,south=side,west=none])
B(3,2,3,minecraft:polished_andesite)
B(3,3,3,minecraft:polished_andesite)
B(3,4,3,minecraft:polished_andesite)
B(3,5,3,minecraft:polished_andesite)
B(3,6,3,minecraft:polished_andesite)
B(3,7,3,minecraft:redstone_wire)
B(3,0,4,minecraft:cobblestone)
B(3,1,4,minecraft:redstone_wire[east=none,north=side,power=0,south=side,west=none])
B(3,2,4,minecraft:cobblestone)
B(3,3,4,minecraft:cobblestone)
B(3,4,4,minecraft:cobblestone)
B(3,6,4,minecraft:stone_brick_stairs)
B(3,0,5,minecraft:cobblestone)
B(3,1,5,minecraft:redstone_wire[east=side,north=side,power=0,south=side,west=none])
B(3,2,5,minecraft:cobblestone)
B(3,3,5,minecraft:cobblestone)
B(3,4,5,minecraft:cobblestone)
B(3,10,5,minecraft:smooth_stone_slab)
B(3,0,6,minecraft:cobblestone)
B(3,1,6,minecraft:redstone_wire[east=side,north=side,power=0,south=none,west=none])
B(3,2,6,minecraft:cobblestone)
B(3,3,6,minecraft:cobblestone)
B(3,4,6,minecraft:cobblestone)
B(4,0,-5,minecraft:cobblestone)
B(4,1,-5,minecraft:redstone_wire[east=none,north=none,power=0,south=side,west=side])
B(4,0,-4,minecraft:cobblestone)
B(4,1,-4,minecraft:redstone_wire[east=none,north=side,power=0,south=side,west=none])
B(4,2,-4,minecraft:cobblestone_slab[type=top,waterlogged=false])
B(4,3,-4,minecraft:redstone_wire[east=none,north=side,power=0,south=side,west=none])
B(4,4,-4,minecraft:cobblestone_slab[type=top,waterlogged=false])
B(4,5,-4,minecraft:redstone_wire[east=none,north=none,power=0,south=side,west=side])
B(4,10,-4,minecraft:smooth_stone_slab)
B(4,0,-3,minecraft:cobblestone)
B(4,1,-3,minecraft:cobblestone_slab[type=top,waterlogged=false])
B(4,2,-3,minecraft:redstone_wire[east=none,north=side,power=0,south=side,west=none])
B(4,3,-3,minecraft:cobblestone_slab[type=top,waterlogged=false])
B(4,4,-3,minecraft:redstone_wire[east=none,north=side,power=0,south=side,west=none])
B(4,5,-3,minecraft:cobblestone_slab[type=top,waterlogged=false])
B(4,6,-3,minecraft:polished_andesite)
B(4,7,-3,minecraft:polished_andesite)
B(4,8,-3,minecraft:polished_andesite)
B(4,9,-3,minecraft:polished_andesite)
B(4,10,-3,minecraft:polished_andesite)
B(4,11,-3,minecraft:black_glazed_terracotta[facing=south])
B(4,0,-2,minecraft:cobblestone)
B(4,1,-2,minecraft:piston[extended=false,facing=south])
B(4,2,-2,minecraft:piston[extended=false,facing=south])
B(4,3,-2,minecraft:piston[extended=false,facing=south])
B(4,6,-2,minecraft:stone_brick_stairs[facing=west,half=bottom,shape=straight,waterlogged=false])
B(4,0,-1,minecraft:polished_andesite)
B(4,1,-1,minecraft:polished_andesite)
B(4,2,-1,minecraft:polished_andesite)
B(4,3,-1,minecraft:polished_andesite)
B(4,4,-1,minecraft:polished_andesite)
B(4,5,-1,minecraft:polished_andesite)
B(4,6,-1,minecraft:stone_brick_stairs[facing=west,half=bottom,shape=straight,waterlogged=false])
B(4,0,0,minecraft:cobblestone)
B(4,3,0,minecraft:wall_torch[facing=south])
B(4,4,0,minecraft:cobblestone_stairs[facing=west,half=top,shape=straight,waterlogged=false])
B(4,5,0,minecraft:polished_andesite)
B(4,6,0,minecraft:stone_brick_stairs[facing=west,half=bottom,shape=straight,waterlogged=false])
B(4,0,1,minecraft:cobblestone)
B(4,3,1,minecraft:wall_torch)
B(4,4,1,minecraft:cobblestone_stairs[facing=west,half=top,shape=straight,waterlogged=false])
B(4,5,1,minecraft:polished_andesite)
B(4,6,1,minecraft:stone_brick_stairs[facing=west,half=bottom,shape=straight,waterlogged=false])
B(4,0,2,minecraft:polished_andesite)
B(4,1,2,minecraft:polished_andesite)
B(4,2,2,minecraft:polished_andesite)
B(4,3,2,minecraft:polished_andesite)
B(4,4,2,minecraft:polished_andesite)
B(4,5,2,minecraft:polished_andesite)
B(4,6,2,minecraft:stone_brick_stairs[facing=west,half=bottom,shape=straight,waterlogged=false])
B(4,0,3,minecraft:cobblestone)
B(4,1,3,minecraft:piston)
B(4,2,3,minecraft:piston)
B(4,3,3,minecraft:piston)
B(4,6,3,minecraft:stone_brick_stairs[facing=west,half=bottom,shape=straight,waterlogged=false])
B(4,0,4,minecraft:cobblestone)
B(4,1,4,minecraft:cobblestone_slab[type=top,waterlogged=false])
B(4,2,4,minecraft:redstone_wire[east=none,north=side,power=0,south=side,west=none])
B(4,3,4,minecraft:cobblestone_slab[type=top,waterlogged=false])
B(4,4,4,minecraft:redstone_wire[east=none,north=side,power=0,south=side,west=none])
B(4,6,4,minecraft:polished_andesite)
B(4,7,4,minecraft:polished_andesite)
B(4,8,4,minecraft:polished_andesite)
B(4,9,4,minecraft:polished_andesite)
B(4,10,4,minecraft:polished_andesite)
B(4,11,4,minecraft:black_glazed_terracotta[facing=south])
B(4,0,5,minecraft:cobblestone)
B(4,1,5,minecraft:redstone_wire[east=none,north=side,power=0,south=side,west=side])
B(4,2,5,minecraft:cobblestone_slab[type=top,waterlogged=false])
B(4,3,5,minecraft:redstone_wire[east=none,north=side,power=0,south=side,west=none])
B(4,4,5,minecraft:cobblestone_slab[type=top,waterlogged=false])
B(4,10,5,minecraft:smooth_stone_slab)
B(4,0,6,minecraft:cobblestone)
B(4,1,6,minecraft:redstone_wire[east=none,north=side,power=0,south=none,west=side])
B(5,10,-4,minecraft:smooth_stone_slab)
B(5,10,-3,minecraft:smooth_stone_slab)
B(5,6,-2,minecraft:stone_brick_slab)
B(5,0,-1,minecraft:polished_andesite)
B(5,1,-1,minecraft:polished_andesite)
B(5,2,-1,minecraft:polished_andesite)
B(5,3,-1,minecraft:polished_andesite)
B(5,4,-1,minecraft:polished_andesite)
B(5,5,-1,minecraft:polished_andesite)
B(5,6,-1,minecraft:stone_brick_stairs[facing=south,half=bottom,shape=outer_left,waterlogged=false])
B(5,7,-1,minecraft:smooth_stone_slab)
B(5,0,0,minecraft:cobblestone)
B(5,1,0,minecraft:cobblestone_stairs[facing=east,half=bottom,shape=straight,waterlogged=false])
B(5,4,0,minecraft:stone_brick_slab[type=top,waterlogged=false])
B(5,5,0,minecraft:polished_andesite)
B(5,6,0,minecraft:stone_brick_stairs[facing=east,half=bottom,shape=straight,waterlogged=false])
B(5,7,0,minecraft:smooth_stone_slab)
B(5,0,1,minecraft:cobblestone)
B(5,1,1,minecraft:cobblestone_stairs[facing=east,half=bottom,shape=straight,waterlogged=false])
B(5,4,1,minecraft:stone_brick_slab[type=top,waterlogged=false])
B(5,5,1,minecraft:polished_andesite)
B(5,6,1,minecraft:stone_brick_stairs[facing=east,half=bottom,shape=straight,waterlogged=false])
B(5,7,1,minecraft:smooth_stone_slab)
B(5,0,2,minecraft:polished_andesite)
B(5,1,2,minecraft:polished_andesite)
B(5,2,2,minecraft:polished_andesite)
B(5,3,2,minecraft:polished_andesite)
B(5,4,2,minecraft:polished_andesite)
B(5,5,2,minecraft:polished_andesite)
B(5,6,2,minecraft:stone_brick_stairs[facing=north,half=bottom,shape=outer_right,waterlogged=false])
B(5,7,2,minecraft:smooth_stone_slab)
B(5,6,3,minecraft:stone_brick_slab)
B(5,10,4,minecraft:smooth_stone_slab)
B(5,10,5,minecraft:smooth_stone_slab)
B(6,10,-3,minecraft:smooth_stone_slab)
B(6,6,-2,minecraft:stone_brick_slab)
B(6,0,-1,minecraft:polished_andesite)
B(6,1,-1,minecraft:polished_andesite)
B(6,2,-1,minecraft:cobblestone_stairs)
B(6,3,-1,minecraft:cobblestone_stairs[facing=north,half=top,shape=straight,waterlogged=false])
B(6,4,-1,minecraft:cobblestone)
B(6,5,-1,minecraft:polished_andesite)
B(6,6,-1,minecraft:stone_brick_stairs[facing=south,half=bottom,shape=straight,waterlogged=false])
B(6,7,-1,minecraft:smooth_stone_slab)
B(6,0,0,minecraft:polished_andesite)
B(6,1,0,minecraft:polished_andesite)
B(6,5,0,minecraft:red_glazed_terracotta[facing=east])
B(6,0,1,minecraft:polished_andesite)
B(6,1,1,minecraft:polished_andesite)
B(6,5,1,minecraft:black_terracotta)
B(6,0,2,minecraft:polished_andesite)
B(6,1,2,minecraft:polished_andesite)
B(6,2,2,minecraft:cobblestone_stairs[facing=south,half=bottom,shape=straight,waterlogged=false])
B(6,3,2,minecraft:cobblestone_stairs[facing=south,half=top,shape=straight,waterlogged=false])
B(6,4,2,minecraft:cobblestone)
B(6,5,2,minecraft:polished_andesite)
B(6,6,2,minecraft:stone_brick_stairs)
B(6,7,2,minecraft:smooth_stone_slab)
B(6,6,3,minecraft:stone_brick_slab)
B(6,10,4,minecraft:smooth_stone_slab)
B(7,10,-3,minecraft:smooth_stone_slab)
B(7,6,-2,minecraft:stone_brick_slab)
B(7,0,-1,minecraft:polished_andesite)
B(7,1,-1,minecraft:polished_andesite)
B(7,2,-1,minecraft:cobblestone_stairs)
B(7,3,-1,minecraft:cobblestone_stairs[facing=north,half=top,shape=straight,waterlogged=false])
B(7,4,-1,minecraft:cobblestone)
B(7,5,-1,minecraft:polished_andesite)
B(7,6,-1,minecraft:stone_brick_stairs[facing=south,half=bottom,shape=straight,waterlogged=false])
B(7,7,-1,minecraft:smooth_stone_slab)
B(7,0,0,minecraft:polished_andesite)
B(7,1,0,minecraft:polished_andesite)
B(7,5,0,minecraft:black_terracotta)
B(7,0,1,minecraft:polished_andesite)
B(7,1,1,minecraft:polished_andesite)
B(7,5,1,minecraft:red_glazed_terracotta)
B(7,0,2,minecraft:polished_andesite)
B(7,1,2,minecraft:polished_andesite)
B(7,2,2,minecraft:cobblestone_stairs[facing=south,half=bottom,shape=straight,waterlogged=false])
B(7,3,2,minecraft:cobblestone_stairs[facing=south,half=top,shape=straight,waterlogged=false])
B(7,4,2,minecraft:cobblestone)
B(7,5,2,minecraft:polished_andesite)
B(7,6,2,minecraft:stone_brick_stairs)
B(7,7,2,minecraft:smooth_stone_slab)
B(7,6,3,minecraft:stone_brick_slab)
B(7,10,4,minecraft:smooth_stone_slab)
B(8,10,-3,minecraft:smooth_stone_slab)
B(8,6,-2,minecraft:stone_brick_slab)
B(8,0,-1,minecraft:polished_andesite)
B(8,1,-1,minecraft:polished_andesite)
B(8,2,-1,minecraft:polished_andesite)
B(8,3,-1,minecraft:polished_andesite)
B(8,4,-1,minecraft:polished_andesite)
B(8,5,-1,minecraft:polished_andesite)
B(8,6,-1,minecraft:stone_brick_stairs[facing=west,half=bottom,shape=outer_left,waterlogged=false])
B(8,7,-1,minecraft:smooth_stone_slab)
B(8,0,0,minecraft:polished_andesite)
B(8,1,0,minecraft:polished_andesite)
B(8,2,0,minecraft:cobblestone_stairs[facing=east,half=bottom,shape=straight,waterlogged=false])
B(8,3,0,minecraft:cobblestone_stairs[facing=east,half=top,shape=straight,waterlogged=false])
B(8,4,0,minecraft:cobblestone)
B(8,5,0,minecraft:polished_andesite)
B(8,6,0,minecraft:stone_brick_stairs[facing=west,half=bottom,shape=straight,waterlogged=false])
B(8,7,0,minecraft:smooth_stone_slab)
B(8,0,1,minecraft:polished_andesite)
B(8,1,1,minecraft:polished_andesite)
B(8,2,1,minecraft:cobblestone_stairs[facing=east,half=bottom,shape=straight,waterlogged=false])
B(8,3,1,minecraft:cobblestone_stairs[facing=east,half=top,shape=straight,waterlogged=false])
B(8,4,1,minecraft:cobblestone)
B(8,5,1,minecraft:polished_andesite)
B(8,6,1,minecraft:stone_brick_stairs[facing=west,half=bottom,shape=straight,waterlogged=false])
B(8,7,1,minecraft:smooth_stone_slab)
B(8,0,2,minecraft:polished_andesite)
B(8,1,2,minecraft:polished_andesite)
B(8,2,2,minecraft:polished_andesite)
B(8,3,2,minecraft:polished_andesite)
B(8,4,2,minecraft:polished_andesite)
B(8,5,2,minecraft:polished_andesite)
B(8,6,2,minecraft:stone_brick_stairs[facing=north,half=bottom,shape=outer_left,waterlogged=false])
B(8,7,2,minecraft:smooth_stone_slab)
B(8,6,3,minecraft:stone_brick_slab)
B(8,10,4,minecraft:smooth_stone_slab)
B(9,10,-3,minecraft:smooth_stone_slab)
B(9,6,-2,minecraft:stone_brick_slab)
B(9,6,-1,minecraft:stone_brick_slab)
B(9,6,0,minecraft:stone_brick_slab)
B(9,6,1,minecraft:stone_brick_slab)
B(9,6,2,minecraft:stone_brick_slab)
B(9,6,3,minecraft:stone_brick_slab)
B(9,10,4,minecraft:smooth_stone_slab)
B(10,10,-3,minecraft:smooth_stone_slab)
B(10,10,-2,minecraft:smooth_stone_slab)
B(10,10,-1,minecraft:smooth_stone_slab)
B(10,10,0,minecraft:smooth_stone_slab)
B(10,10,1,minecraft:smooth_stone_slab)
B(10,10,2,minecraft:smooth_stone_slab)
B(10,10,3,minecraft:smooth_stone_slab)
B(10,10,4,minecraft:smooth_stone_slab)
RB(-9,6,-1,minecraft:red_stained_glass,15,minecraft:pink_concrete,25,minecraft:red_concrete,25,minecraft:red_glazed_terracotta[facing=south],30,minecraft:black_terracotta,50,minecraft:black_terracotta,100)
RB(-9,6,2,minecraft:red_stained_glass,15,minecraft:pink_concrete,25,minecraft:red_concrete,25,minecraft:red_glazed_terracotta[facing=south],30,minecraft:black_terracotta,50,minecraft:black_terracotta,100)
RB(-9,7,-1,minecraft:red_stained_glass,15,minecraft:pink_concrete,25,minecraft:red_concrete,25,minecraft:red_glazed_terracotta[facing=south],30,minecraft:black_terracotta,50,minecraft:black_terracotta,100)
RB(-9,7,2,minecraft:red_stained_glass,15,minecraft:pink_concrete,25,minecraft:red_concrete,25,minecraft:red_glazed_terracotta[facing=south],30,minecraft:black_terracotta,50,minecraft:black_terracotta,100)
RB(-9,8,-1,minecraft:red_stained_glass,15,minecraft:pink_concrete,25,minecraft:red_concrete,25,minecraft:red_glazed_terracotta[facing=south],30,minecraft:black_terracotta,50,minecraft:black_terracotta,100)
RB(-9,8,2,minecraft:red_stained_glass,15,minecraft:pink_concrete,25,minecraft:red_concrete,25,minecraft:red_glazed_terracotta[facing=south],30,minecraft:black_terracotta,50,minecraft:black_terracotta,100)
RB(-9,9,-1,minecraft:red_stained_glass,15,minecraft:pink_concrete,25,minecraft:red_concrete,25,minecraft:red_glazed_terracotta[facing=south],30,minecraft:black_terracotta,50,minecraft:black_terracotta,100)
RB(-9,9,2,minecraft:red_stained_glass,15,minecraft:pink_concrete,25,minecraft:red_concrete,25,minecraft:red_glazed_terracotta[facing=south],30,minecraft:black_terracotta,50,minecraft:black_terracotta,100)
RB(-8,6,-1,minecraft:red_stained_glass,15,minecraft:pink_concrete,25,minecraft:red_concrete,25,minecraft:red_glazed_terracotta[facing=south],30,minecraft:black_terracotta,50,minecraft:black_terracotta,100)
RB(-8,6,2,minecraft:red_stained_glass,15,minecraft:pink_concrete,25,minecraft:red_concrete,25,minecraft:red_glazed_terracotta[facing=south],30,minecraft:black_terracotta,50,minecraft:black_terracotta,100)
RB(-8,7,-1,minecraft:red_stained_glass,15,minecraft:pink_concrete,25,minecraft:red_concrete,25,minecraft:red_glazed_terracotta[facing=south],30,minecraft:black_terracotta,50,minecraft:black_terracotta,100)
RB(-8,7,2,minecraft:red_stained_glass,15,minecraft:pink_concrete,25,minecraft:red_concrete,25,minecraft:red_glazed_terracotta[facing=south],30,minecraft:black_terracotta,50,minecraft:black_terracotta,100)
RB(-8,8,-1,minecraft:red_stained_glass,15,minecraft:pink_concrete,25,minecraft:red_concrete,25,minecraft:red_glazed_terracotta[facing=south],30,minecraft:black_terracotta,50,minecraft:black_terracotta,100)
RB(-8,8,2,minecraft:red_stained_glass,15,minecraft:pink_concrete,25,minecraft:red_concrete,25,minecraft:red_glazed_terracotta[facing=south],30,minecraft:black_terracotta,50,minecraft:black_terracotta,100)
RB(-8,9,-1,minecraft:red_stained_glass,15,minecraft:pink_concrete,25,minecraft:red_concrete,25,minecraft:red_glazed_terracotta[facing=south],30,minecraft:black_terracotta,50,minecraft:black_terracotta,100)
RB(-8,9,2,minecraft:red_stained_glass,15,minecraft:pink_concrete,25,minecraft:red_concrete,25,minecraft:red_glazed_terracotta[facing=south],30,minecraft:black_terracotta,50,minecraft:black_terracotta,100)
RB(-7,6,-1,minecraft:red_stained_glass,15,minecraft:pink_concrete,25,minecraft:red_concrete,25,minecraft:red_glazed_terracotta[facing=south],30,minecraft:black_terracotta,50,minecraft:black_terracotta,100)
RB(-7,6,2,minecraft:red_stained_glass,15,minecraft:pink_concrete,25,minecraft:red_concrete,25,minecraft:red_glazed_terracotta[facing=south],30,minecraft:black_terracotta,50,minecraft:black_terracotta,100)
RB(-7,7,-1,minecraft:red_stained_glass,15,minecraft:pink_concrete,25,minecraft:red_concrete,25,minecraft:red_glazed_terracotta[facing=south],30,minecraft:black_terracotta,50,minecraft:black_terracotta,100)
RB(-7,7,2,minecraft:red_stained_glass,15,minecraft:pink_concrete,25,minecraft:red_concrete,25,minecraft:red_glazed_terracotta[facing=south],30,minecraft:black_terracotta,50,minecraft:black_terracotta,100)
RB(-7,8,-1,minecraft:red_stained_glass,15,minecraft:pink_concrete,25,minecraft:red_concrete,25,minecraft:red_glazed_terracotta[facing=south],30,minecraft:black_terracotta,50,minecraft:black_terracotta,100)
RB(-7,8,2,minecraft:red_stained_glass,15,minecraft:pink_concrete,25,minecraft:red_concrete,25,minecraft:red_glazed_terracotta[facing=south],30,minecraft:black_terracotta,50,minecraft:black_terracotta,100)
RB(-7,9,-1,minecraft:red_stained_glass,15,minecraft:pink_concrete,25,minecraft:red_concrete,25,minecraft:red_glazed_terracotta[facing=south],30,minecraft:black_terracotta,50,minecraft:black_terracotta,100)
RB(-7,9,2,minecraft:red_stained_glass,15,minecraft:pink_concrete,25,minecraft:red_concrete,25,minecraft:red_glazed_terracotta[facing=south],30,minecraft:black_terracotta,50,minecraft:black_terracotta,100)
RB(-6,6,-4,minecraft:red_stained_glass,15,minecraft:pink_concrete,25,minecraft:red_concrete,25,minecraft:red_glazed_terracotta[facing=south],30,minecraft:black_terracotta,50,minecraft:black_terracotta,100)
RB(-6,6,-3,minecraft:red_stained_glass,15,minecraft:pink_concrete,25,minecraft:red_concrete,25,minecraft:red_glazed_terracotta[facing=south],30,minecraft:black_terracotta,50,minecraft:black_terracotta,100)
RB(-6,6,-2,minecraft:red_stained_glass,15,minecraft:pink_concrete,25,minecraft:red_concrete,25,minecraft:red_glazed_terracotta[facing=south],30,minecraft:black_terracotta,50,minecraft:black_terracotta,100)
RB(-6,6,-1,minecraft:red_stained_glass,15,minecraft:pink_concrete,25,minecraft:red_concrete,25,minecraft:red_glazed_terracotta[facing=south],30,minecraft:black_terracotta,50,minecraft:black_terracotta,100)
RB(-6,6,2,minecraft:red_stained_glass,15,minecraft:pink_concrete,25,minecraft:red_concrete,25,minecraft:red_glazed_terracotta[facing=south],30,minecraft:black_terracotta,50,minecraft:black_terracotta,100)
RB(-6,6,3,minecraft:red_stained_glass,15,minecraft:pink_concrete,25,minecraft:red_concrete,25,minecraft:red_glazed_terracotta[facing=south],30,minecraft:black_terracotta,50,minecraft:black_terracotta,100)
RB(-6,6,4,minecraft:red_stained_glass,15,minecraft:pink_concrete,25,minecraft:red_concrete,25,minecraft:red_glazed_terracotta[facing=south],30,minecraft:black_terracotta,50,minecraft:black_terracotta,100)
RB(-6,6,5,minecraft:red_stained_glass,15,minecraft:pink_concrete,25,minecraft:red_concrete,25,minecraft:red_glazed_terracotta[facing=south],30,minecraft:black_terracotta,50,minecraft:black_terracotta,100)
RB(-6,7,-4,minecraft:red_stained_glass,15,minecraft:pink_concrete,25,minecraft:red_concrete,25,minecraft:red_glazed_terracotta[facing=south],30,minecraft:black_terracotta,50,minecraft:black_terracotta,100)
RB(-6,7,-3,minecraft:red_stained_glass,15,minecraft:pink_concrete,25,minecraft:red_concrete,25,minecraft:red_glazed_terracotta[facing=south],30,minecraft:black_terracotta,50,minecraft:black_terracotta,100)
RB(-6,7,-2,minecraft:red_stained_glass,15,minecraft:pink_concrete,25,minecraft:red_concrete,25,minecraft:red_glazed_terracotta[facing=south],30,minecraft:black_terracotta,50,minecraft:black_terracotta,100)
RB(-6,7,-1,minecraft:red_stained_glass,15,minecraft:pink_concrete,25,minecraft:red_concrete,25,minecraft:red_glazed_terracotta[facing=south],30,minecraft:black_terracotta,50,minecraft:black_terracotta,100)
RB(-6,7,2,minecraft:red_stained_glass,15,minecraft:pink_concrete,25,minecraft:red_concrete,25,minecraft:red_glazed_terracotta[facing=south],30,minecraft:black_terracotta,50,minecraft:black_terracotta,100)
RB(-6,7,3,minecraft:red_stained_glass,15,minecraft:pink_concrete,25,minecraft:red_concrete,25,minecraft:red_glazed_terracotta[facing=south],30,minecraft:black_terracotta,50,minecraft:black_terracotta,100)
RB(-6,7,4,minecraft:red_stained_glass,15,minecraft:pink_concrete,25,minecraft:red_concrete,25,minecraft:red_glazed_terracotta[facing=south],30,minecraft:black_terracotta,50,minecraft:black_terracotta,100)
RB(-6,7,5,minecraft:red_stained_glass,15,minecraft:pink_concrete,25,minecraft:red_concrete,25,minecraft:red_glazed_terracotta[facing=south],30,minecraft:black_terracotta,50,minecraft:black_terracotta,100)
RB(-6,8,-4,minecraft:red_stained_glass,15,minecraft:pink_concrete,25,minecraft:red_concrete,25,minecraft:red_glazed_terracotta[facing=south],30,minecraft:black_terracotta,50,minecraft:black_terracotta,100)
RB(-6,8,-3,minecraft:red_stained_glass,15,minecraft:pink_concrete,25,minecraft:red_concrete,25,minecraft:red_glazed_terracotta[facing=south],30,minecraft:black_terracotta,50,minecraft:black_terracotta,100)
RB(-6,8,-2,minecraft:red_stained_glass,15,minecraft:pink_concrete,25,minecraft:red_concrete,25,minecraft:red_glazed_terracotta[facing=south],30,minecraft:black_terracotta,50,minecraft:black_terracotta,100)
RB(-6,8,-1,minecraft:red_stained_glass,15,minecraft:pink_concrete,25,minecraft:red_concrete,25,minecraft:red_glazed_terracotta[facing=south],30,minecraft:black_terracotta,50,minecraft:black_terracotta,100)
RB(-6,8,2,minecraft:red_stained_glass,15,minecraft:pink_concrete,25,minecraft:red_concrete,25,minecraft:red_glazed_terracotta[facing=south],30,minecraft:black_terracotta,50,minecraft:black_terracotta,100)
RB(-6,8,3,minecraft:red_stained_glass,15,minecraft:pink_concrete,25,minecraft:red_concrete,25,minecraft:red_glazed_terracotta[facing=south],30,minecraft:black_terracotta,50,minecraft:black_terracotta,100)
RB(-6,8,4,minecraft:red_stained_glass,15,minecraft:pink_concrete,25,minecraft:red_concrete,25,minecraft:red_glazed_terracotta[facing=south],30,minecraft:black_terracotta,50,minecraft:black_terracotta,100)
RB(-6,8,5,minecraft:red_stained_glass,15,minecraft:pink_concrete,25,minecraft:red_concrete,25,minecraft:red_glazed_terracotta[facing=south],30,minecraft:black_terracotta,50,minecraft:black_terracotta,100)
RB(-6,9,-4,minecraft:red_stained_glass,15,minecraft:pink_concrete,25,minecraft:red_concrete,25,minecraft:red_glazed_terracotta[facing=south],30,minecraft:black_terracotta,50,minecraft:black_terracotta,100)
RB(-6,9,-3,minecraft:red_stained_glass,15,minecraft:pink_concrete,25,minecraft:red_concrete,25,minecraft:red_glazed_terracotta[facing=south],30,minecraft:black_terracotta,50,minecraft:black_terracotta,100)
RB(-6,9,-2,minecraft:red_stained_glass,15,minecraft:pink_concrete,25,minecraft:red_concrete,25,minecraft:red_glazed_terracotta[facing=south],30,minecraft:black_terracotta,50,minecraft:black_terracotta,100)
RB(-6,9,-1,minecraft:red_stained_glass,15,minecraft:pink_concrete,25,minecraft:red_concrete,25,minecraft:red_glazed_terracotta[facing=south],30,minecraft:black_terracotta,50,minecraft:black_terracotta,100)
RB(-6,9,2,minecraft:red_stained_glass,15,minecraft:pink_concrete,25,minecraft:red_concrete,25,minecraft:red_glazed_terracotta[facing=south],30,minecraft:black_terracotta,50,minecraft:black_terracotta,100)
RB(-6,9,3,minecraft:red_stained_glass,15,minecraft:pink_concrete,25,minecraft:red_concrete,25,minecraft:red_glazed_terracotta[facing=south],30,minecraft:black_terracotta,50,minecraft:black_terracotta,100)
RB(-6,9,4,minecraft:red_stained_glass,15,minecraft:pink_concrete,25,minecraft:red_concrete,25,minecraft:red_glazed_terracotta[facing=south],30,minecraft:black_terracotta,50,minecraft:black_terracotta,100)
RB(-6,9,5,minecraft:red_stained_glass,15,minecraft:pink_concrete,25,minecraft:red_concrete,25,minecraft:red_glazed_terracotta[facing=south],30,minecraft:black_terracotta,50,minecraft:black_terracotta,100)
RB(-5,6,-4,minecraft:red_stained_glass,15,minecraft:pink_concrete,25,minecraft:red_concrete,25,minecraft:red_glazed_terracotta[facing=south],30,minecraft:black_terracotta,50,minecraft:black_terracotta,100)
RB(-5,6,5,minecraft:red_stained_glass,15,minecraft:pink_concrete,25,minecraft:red_concrete,25,minecraft:red_glazed_terracotta[facing=south],30,minecraft:black_terracotta,50,minecraft:black_terracotta,100)
RB(-5,7,-4,minecraft:red_stained_glass,15,minecraft:pink_concrete,25,minecraft:red_concrete,25,minecraft:red_glazed_terracotta[facing=south],30,minecraft:black_terracotta,50,minecraft:black_terracotta,100)
RB(-5,7,5,minecraft:red_stained_glass,15,minecraft:pink_concrete,25,minecraft:red_concrete,25,minecraft:red_glazed_terracotta[facing=south],30,minecraft:black_terracotta,50,minecraft:black_terracotta,100)
RB(-5,8,-4,minecraft:red_stained_glass,15,minecraft:pink_concrete,25,minecraft:red_concrete,25,minecraft:red_glazed_terracotta[facing=south],30,minecraft:black_terracotta,50,minecraft:black_terracotta,100)
RB(-5,8,5,minecraft:red_stained_glass,15,minecraft:pink_concrete,25,minecraft:red_concrete,25,minecraft:red_glazed_terracotta[facing=south],30,minecraft:black_terracotta,50,minecraft:black_terracotta,100)
RB(-5,9,-4,minecraft:red_stained_glass,15,minecraft:pink_concrete,25,minecraft:red_concrete,25,minecraft:red_glazed_terracotta[facing=south],30,minecraft:black_terracotta,50,minecraft:black_terracotta,100)
RB(-5,9,5,minecraft:red_stained_glass,15,minecraft:pink_concrete,25,minecraft:red_concrete,25,minecraft:red_glazed_terracotta[facing=south],30,minecraft:black_terracotta,50,minecraft:black_terracotta,100)
RB(-4,6,-4,minecraft:red_stained_glass,15,minecraft:pink_concrete,25,minecraft:red_concrete,25,minecraft:red_glazed_terracotta[facing=south],30,minecraft:black_terracotta,50,minecraft:black_terracotta,100)
RB(-4,6,5,minecraft:red_stained_glass,15,minecraft:pink_concrete,25,minecraft:red_concrete,25,minecraft:red_glazed_terracotta[facing=south],30,minecraft:black_terracotta,50,minecraft:black_terracotta,100)
RB(-4,7,-4,minecraft:red_stained_glass,15,minecraft:pink_concrete,25,minecraft:red_concrete,25,minecraft:red_glazed_terracotta[facing=south],30,minecraft:black_terracotta,50,minecraft:black_terracotta,100)
RB(-4,7,5,minecraft:red_stained_glass,15,minecraft:pink_concrete,25,minecraft:red_concrete,25,minecraft:red_glazed_terracotta[facing=south],30,minecraft:black_terracotta,50,minecraft:black_terracotta,100)
RB(-4,8,-4,minecraft:red_stained_glass,15,minecraft:pink_concrete,25,minecraft:red_concrete,25,minecraft:red_glazed_terracotta[facing=south],30,minecraft:black_terracotta,50,minecraft:black_terracotta,100)
RB(-4,8,5,minecraft:red_stained_glass,15,minecraft:pink_concrete,25,minecraft:red_concrete,25,minecraft:red_glazed_terracotta[facing=south],30,minecraft:black_terracotta,50,minecraft:black_terracotta,100)
RB(-4,9,-4,minecraft:red_stained_glass,15,minecraft:pink_concrete,25,minecraft:red_concrete,25,minecraft:red_glazed_terracotta[facing=south],30,minecraft:black_terracotta,50,minecraft:black_terracotta,100)
RB(-4,9,5,minecraft:red_stained_glass,15,minecraft:pink_concrete,25,minecraft:red_concrete,25,minecraft:red_glazed_terracotta[facing=south],30,minecraft:black_terracotta,50,minecraft:black_terracotta,100)
RB(-3,6,-4,minecraft:red_stained_glass,15,minecraft:pink_concrete,25,minecraft:red_concrete,25,minecraft:red_glazed_terracotta[facing=south],30,minecraft:black_terracotta,50,minecraft:black_terracotta,100)
RB(-3,6,5,minecraft:red_stained_glass,15,minecraft:pink_concrete,25,minecraft:red_concrete,25,minecraft:red_glazed_terracotta[facing=south],30,minecraft:black_terracotta,50,minecraft:black_terracotta,100)
RB(-3,7,-4,minecraft:red_stained_glass,15,minecraft:pink_concrete,25,minecraft:red_concrete,25,minecraft:red_glazed_terracotta[facing=south],30,minecraft:black_terracotta,50,minecraft:black_terracotta,100)
RB(-3,7,5,minecraft:red_stained_glass,15,minecraft:pink_concrete,25,minecraft:red_concrete,25,minecraft:red_glazed_terracotta[facing=south],30,minecraft:black_terracotta,50,minecraft:black_terracotta,100)
RB(-3,8,-4,minecraft:red_stained_glass,15,minecraft:pink_concrete,25,minecraft:red_concrete,25,minecraft:red_glazed_terracotta[facing=south],30,minecraft:black_terracotta,50,minecraft:black_terracotta,100)
RB(-3,8,5,minecraft:red_stained_glass,15,minecraft:pink_concrete,25,minecraft:red_concrete,25,minecraft:red_glazed_terracotta[facing=south],30,minecraft:black_terracotta,50,minecraft:black_terracotta,100)
RB(-3,9,-4,minecraft:red_stained_glass,15,minecraft:pink_concrete,25,minecraft:red_concrete,25,minecraft:red_glazed_terracotta[facing=south],30,minecraft:black_terracotta,50,minecraft:black_terracotta,100)
RB(-3,9,5,minecraft:red_stained_glass,15,minecraft:pink_concrete,25,minecraft:red_concrete,25,minecraft:red_glazed_terracotta[facing=south],30,minecraft:black_terracotta,50,minecraft:black_terracotta,100)
RB(-2,6,-4,minecraft:red_stained_glass,15,minecraft:pink_concrete,25,minecraft:red_concrete,25,minecraft:red_glazed_terracotta[facing=south],30,minecraft:black_terracotta,50,minecraft:black_terracotta,100)
RB(-2,6,5,minecraft:red_stained_glass,15,minecraft:pink_concrete,25,minecraft:red_concrete,25,minecraft:red_glazed_terracotta[facing=south],30,minecraft:black_terracotta,50,minecraft:black_terracotta,100)
RB(-2,7,-4,minecraft:red_stained_glass,15,minecraft:pink_concrete,25,minecraft:red_concrete,25,minecraft:red_glazed_terracotta[facing=south],30,minecraft:black_terracotta,50,minecraft:black_terracotta,100)
RB(-2,7,5,minecraft:red_stained_glass,15,minecraft:pink_concrete,25,minecraft:red_concrete,25,minecraft:red_glazed_terracotta[facing=south],30,minecraft:black_terracotta,50,minecraft:black_terracotta,100)
RB(-2,8,-4,minecraft:red_stained_glass,15,minecraft:pink_concrete,25,minecraft:red_concrete,25,minecraft:red_glazed_terracotta[facing=south],30,minecraft:black_terracotta,50,minecraft:black_terracotta,100)
RB(-2,8,5,minecraft:red_stained_glass,15,minecraft:pink_concrete,25,minecraft:red_concrete,25,minecraft:red_glazed_terracotta[facing=south],30,minecraft:black_terracotta,50,minecraft:black_terracotta,100)
RB(-2,9,-4,minecraft:red_stained_glass,15,minecraft:pink_concrete,25,minecraft:red_concrete,25,minecraft:red_glazed_terracotta[facing=south],30,minecraft:black_terracotta,50,minecraft:black_terracotta,100)
RB(-2,9,5,minecraft:red_stained_glass,15,minecraft:pink_concrete,25,minecraft:red_concrete,25,minecraft:red_glazed_terracotta[facing=south],30,minecraft:black_terracotta,50,minecraft:black_terracotta,100)
RB(-1,6,-4,minecraft:red_stained_glass,15,minecraft:pink_concrete,25,minecraft:red_concrete,25,minecraft:red_glazed_terracotta[facing=south],30,minecraft:black_terracotta,50,minecraft:black_terracotta,100)
RB(-1,6,5,minecraft:red_stained_glass,15,minecraft:pink_concrete,25,minecraft:red_concrete,25,minecraft:red_glazed_terracotta[facing=south],30,minecraft:black_terracotta,50,minecraft:black_terracotta,100)
RB(-1,7,-4,minecraft:red_stained_glass,15,minecraft:pink_concrete,25,minecraft:red_concrete,25,minecraft:red_glazed_terracotta[facing=south],30,minecraft:black_terracotta,50,minecraft:black_terracotta,100)
RB(-1,7,5,minecraft:red_stained_glass,15,minecraft:pink_concrete,25,minecraft:red_concrete,25,minecraft:red_glazed_terracotta[facing=south],30,minecraft:black_terracotta,50,minecraft:black_terracotta,100)
RB(-1,8,-4,minecraft:red_stained_glass,15,minecraft:pink_concrete,25,minecraft:red_concrete,25,minecraft:red_glazed_terracotta[facing=south],30,minecraft:black_terracotta,50,minecraft:black_terracotta,100)
RB(-1,8,5,minecraft:red_stained_glass,15,minecraft:pink_concrete,25,minecraft:red_concrete,25,minecraft:red_glazed_terracotta[facing=south],30,minecraft:black_terracotta,50,minecraft:black_terracotta,100)
RB(-1,9,-4,minecraft:red_stained_glass,15,minecraft:pink_concrete,25,minecraft:red_concrete,25,minecraft:red_glazed_terracotta[facing=south],30,minecraft:black_terracotta,50,minecraft:black_terracotta,100)
RB(-1,9,5,minecraft:red_stained_glass,15,minecraft:pink_concrete,25,minecraft:red_concrete,25,minecraft:red_glazed_terracotta[facing=south],30,minecraft:black_terracotta,50,minecraft:black_terracotta,100)
RB(0,6,-4,minecraft:red_stained_glass,15,minecraft:pink_concrete,25,minecraft:red_concrete,25,minecraft:red_glazed_terracotta[facing=south],30,minecraft:black_terracotta,50,minecraft:black_terracotta,100)
RB(0,6,5,minecraft:red_stained_glass,15,minecraft:pink_concrete,25,minecraft:red_concrete,25,minecraft:red_glazed_terracotta[facing=south],30,minecraft:black_terracotta,50,minecraft:black_terracotta,100)
RB(0,7,-4,minecraft:red_stained_glass,15,minecraft:pink_concrete,25,minecraft:red_concrete,25,minecraft:red_glazed_terracotta[facing=south],30,minecraft:black_terracotta,50,minecraft:black_terracotta,100)
RB(0,7,5,minecraft:red_stained_glass,15,minecraft:pink_concrete,25,minecraft:red_concrete,25,minecraft:red_glazed_terracotta[facing=south],30,minecraft:black_terracotta,50,minecraft:black_terracotta,100)
RB(0,8,-4,minecraft:red_stained_glass,15,minecraft:pink_concrete,25,minecraft:red_concrete,25,minecraft:red_glazed_terracotta[facing=south],30,minecraft:black_terracotta,50,minecraft:black_terracotta,100)
RB(0,8,5,minecraft:red_stained_glass,15,minecraft:pink_concrete,25,minecraft:red_concrete,25,minecraft:red_glazed_terracotta[facing=south],30,minecraft:black_terracotta,50,minecraft:black_terracotta,100)
RB(0,9,-4,minecraft:red_stained_glass,15,minecraft:pink_concrete,25,minecraft:red_concrete,25,minecraft:red_glazed_terracotta[facing=south],30,minecraft:black_terracotta,50,minecraft:black_terracotta,100)
RB(0,9,5,minecraft:red_stained_glass,15,minecraft:pink_concrete,25,minecraft:red_concrete,25,minecraft:red_glazed_terracotta[facing=south],30,minecraft:black_terracotta,50,minecraft:black_terracotta,100)
RB(1,6,-4,minecraft:red_stained_glass,15,minecraft:pink_concrete,25,minecraft:red_concrete,25,minecraft:red_glazed_terracotta[facing=south],30,minecraft:black_terracotta,50,minecraft:black_terracotta,100)
RB(1,6,5,minecraft:red_stained_glass,15,minecraft:pink_concrete,25,minecraft:red_concrete,25,minecraft:red_glazed_terracotta[facing=south],30,minecraft:black_terracotta,50,minecraft:black_terracotta,100)
RB(1,7,-4,minecraft:red_stained_glass,15,minecraft:pink_concrete,25,minecraft:red_concrete,25,minecraft:red_glazed_terracotta[facing=south],30,minecraft:black_terracotta,50,minecraft:black_terracotta,100)
RB(1,7,5,minecraft:red_stained_glass,15,minecraft:pink_concrete,25,minecraft:red_concrete,25,minecraft:red_glazed_terracotta[facing=south],30,minecraft:black_terracotta,50,minecraft:black_terracotta,100)
RB(1,8,-4,minecraft:red_stained_glass,15,minecraft:pink_concrete,25,minecraft:red_concrete,25,minecraft:red_glazed_terracotta[facing=south],30,minecraft:black_terracotta,50,minecraft:black_terracotta,100)
RB(1,8,5,minecraft:red_stained_glass,15,minecraft:pink_concrete,25,minecraft:red_concrete,25,minecraft:red_glazed_terracotta[facing=south],30,minecraft:black_terracotta,50,minecraft:black_terracotta,100)
RB(1,9,-4,minecraft:red_stained_glass,15,minecraft:pink_concrete,25,minecraft:red_concrete,25,minecraft:red_glazed_terracotta[facing=south],30,minecraft:black_terracotta,50,minecraft:black_terracotta,100)
RB(1,9,5,minecraft:red_stained_glass,15,minecraft:pink_concrete,25,minecraft:red_concrete,25,minecraft:red_glazed_terracotta[facing=south],30,minecraft:black_terracotta,50,minecraft:black_terracotta,100)
RB(2,6,-4,minecraft:red_stained_glass,15,minecraft:pink_concrete,25,minecraft:red_concrete,25,minecraft:red_glazed_terracotta[facing=south],30,minecraft:black_terracotta,50,minecraft:black_terracotta,100)
RB(2,6,5,minecraft:red_stained_glass,15,minecraft:pink_concrete,25,minecraft:red_concrete,25,minecraft:red_glazed_terracotta[facing=south],30,minecraft:black_terracotta,50,minecraft:black_terracotta,100)
RB(2,7,-4,minecraft:red_stained_glass,15,minecraft:pink_concrete,25,minecraft:red_concrete,25,minecraft:red_glazed_terracotta[facing=south],30,minecraft:black_terracotta,50,minecraft:black_terracotta,100)
RB(2,7,5,minecraft:red_stained_glass,15,minecraft:pink_concrete,25,minecraft:red_concrete,25,minecraft:red_glazed_terracotta[facing=south],30,minecraft:black_terracotta,50,minecraft:black_terracotta,100)
RB(2,8,-4,minecraft:red_stained_glass,15,minecraft:pink_concrete,25,minecraft:red_concrete,25,minecraft:red_glazed_terracotta[facing=south],30,minecraft:black_terracotta,50,minecraft:black_terracotta,100)
RB(2,8,5,minecraft:red_stained_glass,15,minecraft:pink_concrete,25,minecraft:red_concrete,25,minecraft:red_glazed_terracotta[facing=south],30,minecraft:black_terracotta,50,minecraft:black_terracotta,100)
RB(2,9,-4,minecraft:red_stained_glass,15,minecraft:pink_concrete,25,minecraft:red_concrete,25,minecraft:red_glazed_terracotta[facing=south],30,minecraft:black_terracotta,50,minecraft:black_terracotta,100)
RB(2,9,5,minecraft:red_stained_glass,15,minecraft:pink_concrete,25,minecraft:red_concrete,25,minecraft:red_glazed_terracotta[facing=south],30,minecraft:black_terracotta,50,minecraft:black_terracotta,100)
RB(3,6,-4,minecraft:red_stained_glass,15,minecraft:pink_concrete,25,minecraft:red_concrete,25,minecraft:red_glazed_terracotta[facing=south],30,minecraft:black_terracotta,50,minecraft:black_terracotta,100)
RB(3,6,5,minecraft:red_stained_glass,15,minecraft:pink_concrete,25,minecraft:red_concrete,25,minecraft:red_glazed_terracotta[facing=south],30,minecraft:black_terracotta,50,minecraft:black_terracotta,100)
RB(3,7,-4,minecraft:red_stained_glass,15,minecraft:pink_concrete,25,minecraft:red_concrete,25,minecraft:red_glazed_terracotta[facing=south],30,minecraft:black_terracotta,50,minecraft:black_terracotta,100)
RB(3,7,5,minecraft:red_stained_glass,15,minecraft:pink_concrete,25,minecraft:red_concrete,25,minecraft:red_glazed_terracotta[facing=south],30,minecraft:black_terracotta,50,minecraft:black_terracotta,100)
RB(3,8,-4,minecraft:red_stained_glass,15,minecraft:pink_concrete,25,minecraft:red_concrete,25,minecraft:red_glazed_terracotta[facing=south],30,minecraft:black_terracotta,50,minecraft:black_terracotta,100)
RB(3,8,5,minecraft:red_stained_glass,15,minecraft:pink_concrete,25,minecraft:red_concrete,25,minecraft:red_glazed_terracotta[facing=south],30,minecraft:black_terracotta,50,minecraft:black_terracotta,100)
RB(3,9,-4,minecraft:red_stained_glass,15,minecraft:pink_concrete,25,minecraft:red_concrete,25,minecraft:red_glazed_terracotta[facing=south],30,minecraft:black_terracotta,50,minecraft:black_terracotta,100)
RB(3,9,5,minecraft:red_stained_glass,15,minecraft:pink_concrete,25,minecraft:red_concrete,25,minecraft:red_glazed_terracotta[facing=south],30,minecraft:black_terracotta,50,minecraft:black_terracotta,100)
RB(4,6,-4,minecraft:red_stained_glass,15,minecraft:pink_concrete,25,minecraft:red_concrete,25,minecraft:red_glazed_terracotta[facing=south],30,minecraft:black_terracotta,50,minecraft:black_terracotta,100)
RB(4,6,5,minecraft:red_stained_glass,15,minecraft:pink_concrete,25,minecraft:red_concrete,25,minecraft:red_glazed_terracotta[facing=south],30,minecraft:black_terracotta,50,minecraft:black_terracotta,100)
RB(4,7,-4,minecraft:red_stained_glass,15,minecraft:pink_concrete,25,minecraft:red_concrete,25,minecraft:red_glazed_terracotta[facing=south],30,minecraft:black_terracotta,50,minecraft:black_terracotta,100)
RB(4,7,5,minecraft:red_stained_glass,15,minecraft:pink_concrete,25,minecraft:red_concrete,25,minecraft:red_glazed_terracotta[facing=south],30,minecraft:black_terracotta,50,minecraft:black_terracotta,100)
RB(4,8,-4,minecraft:red_stained_glass,15,minecraft:pink_concrete,25,minecraft:red_concrete,25,minecraft:red_glazed_terracotta[facing=south],30,minecraft:black_terracotta,50,minecraft:black_terracotta,100)
RB(4,8,5,minecraft:red_stained_glass,15,minecraft:pink_concrete,25,minecraft:red_concrete,25,minecraft:red_glazed_terracotta[facing=south],30,minecraft:black_terracotta,50,minecraft:black_terracotta,100)
RB(4,9,-4,minecraft:red_stained_glass,15,minecraft:pink_concrete,25,minecraft:red_concrete,25,minecraft:red_glazed_terracotta[facing=south],30,minecraft:black_terracotta,50,minecraft:black_terracotta,100)
RB(4,9,5,minecraft:red_stained_glass,15,minecraft:pink_concrete,25,minecraft:red_concrete,25,minecraft:red_glazed_terracotta[facing=south],30,minecraft:black_terracotta,50,minecraft:black_terracotta,100)
RB(5,6,-4,minecraft:red_stained_glass,15,minecraft:pink_concrete,25,minecraft:red_concrete,25,minecraft:red_glazed_terracotta[facing=south],30,minecraft:black_terracotta,50,minecraft:black_terracotta,100)
RB(5,6,-3,minecraft:red_stained_glass,15,minecraft:pink_concrete,25,minecraft:red_concrete,25,minecraft:red_glazed_terracotta[facing=south],30,minecraft:black_terracotta,50,minecraft:black_terracotta,100)
RB(5,6,4,minecraft:red_stained_glass,15,minecraft:pink_concrete,25,minecraft:red_concrete,25,minecraft:red_glazed_terracotta[facing=south],30,minecraft:black_terracotta,50,minecraft:black_terracotta,100)
RB(5,6,5,minecraft:red_stained_glass,15,minecraft:pink_concrete,25,minecraft:red_concrete,25,minecraft:red_glazed_terracotta[facing=south],30,minecraft:black_terracotta,50,minecraft:black_terracotta,100)
RB(5,7,-4,minecraft:red_stained_glass,15,minecraft:pink_concrete,25,minecraft:red_concrete,25,minecraft:red_glazed_terracotta[facing=south],30,minecraft:black_terracotta,50,minecraft:black_terracotta,100)
RB(5,7,-3,minecraft:red_stained_glass,15,minecraft:pink_concrete,25,minecraft:red_concrete,25,minecraft:red_glazed_terracotta[facing=south],30,minecraft:black_terracotta,50,minecraft:black_terracotta,100)
RB(5,7,4,minecraft:red_stained_glass,15,minecraft:pink_concrete,25,minecraft:red_concrete,25,minecraft:red_glazed_terracotta[facing=south],30,minecraft:black_terracotta,50,minecraft:black_terracotta,100)
RB(5,7,5,minecraft:red_stained_glass,15,minecraft:pink_concrete,25,minecraft:red_concrete,25,minecraft:red_glazed_terracotta[facing=south],30,minecraft:black_terracotta,50,minecraft:black_terracotta,100)
RB(5,8,-4,minecraft:red_stained_glass,15,minecraft:pink_concrete,25,minecraft:red_concrete,25,minecraft:red_glazed_terracotta[facing=south],30,minecraft:black_terracotta,50,minecraft:black_terracotta,100)
RB(5,8,-3,minecraft:red_stained_glass,15,minecraft:pink_concrete,25,minecraft:red_concrete,25,minecraft:red_glazed_terracotta[facing=south],30,minecraft:black_terracotta,50,minecraft:black_terracotta,100)
RB(5,8,4,minecraft:red_stained_glass,15,minecraft:pink_concrete,25,minecraft:red_concrete,25,minecraft:red_glazed_terracotta[facing=south],30,minecraft:black_terracotta,50,minecraft:black_terracotta,100)
RB(5,8,5,minecraft:red_stained_glass,15,minecraft:pink_concrete,25,minecraft:red_concrete,25,minecraft:red_glazed_terracotta[facing=south],30,minecraft:black_terracotta,50,minecraft:black_terracotta,100)
RB(5,9,-4,minecraft:red_stained_glass,15,minecraft:pink_concrete,25,minecraft:red_concrete,25,minecraft:red_glazed_terracotta[facing=south],30,minecraft:black_terracotta,50,minecraft:black_terracotta,100)
RB(5,9,-3,minecraft:red_stained_glass,15,minecraft:pink_concrete,25,minecraft:red_concrete,25,minecraft:red_glazed_terracotta[facing=south],30,minecraft:black_terracotta,50,minecraft:black_terracotta,100)
RB(5,9,4,minecraft:red_stained_glass,15,minecraft:pink_concrete,25,minecraft:red_concrete,25,minecraft:red_glazed_terracotta[facing=south],30,minecraft:black_terracotta,50,minecraft:black_terracotta,100)
RB(5,9,5,minecraft:red_stained_glass,15,minecraft:pink_concrete,25,minecraft:red_concrete,25,minecraft:red_glazed_terracotta[facing=south],30,minecraft:black_terracotta,50,minecraft:black_terracotta,100)
RB(6,6,-3,minecraft:red_stained_glass,15,minecraft:pink_concrete,25,minecraft:red_concrete,25,minecraft:red_glazed_terracotta[facing=south],30,minecraft:black_terracotta,50,minecraft:black_terracotta,100)
RB(6,6,4,minecraft:red_stained_glass,15,minecraft:pink_concrete,25,minecraft:red_concrete,25,minecraft:red_glazed_terracotta[facing=south],30,minecraft:black_terracotta,50,minecraft:black_terracotta,100)
RB(6,7,-3,minecraft:red_stained_glass,15,minecraft:pink_concrete,25,minecraft:red_concrete,25,minecraft:red_glazed_terracotta[facing=south],30,minecraft:black_terracotta,50,minecraft:black_terracotta,100)
RB(6,7,4,minecraft:red_stained_glass,15,minecraft:pink_concrete,25,minecraft:red_concrete,25,minecraft:red_glazed_terracotta[facing=south],30,minecraft:black_terracotta,50,minecraft:black_terracotta,100)
RB(6,8,-3,minecraft:red_stained_glass,15,minecraft:pink_concrete,25,minecraft:red_concrete,25,minecraft:red_glazed_terracotta[facing=south],30,minecraft:black_terracotta,50,minecraft:black_terracotta,100)
RB(6,8,4,minecraft:red_stained_glass,15,minecraft:pink_concrete,25,minecraft:red_concrete,25,minecraft:red_glazed_terracotta[facing=south],30,minecraft:black_terracotta,50,minecraft:black_terracotta,100)
RB(6,9,-3,minecraft:red_stained_glass,15,minecraft:pink_concrete,25,minecraft:red_concrete,25,minecraft:red_glazed_terracotta[facing=south],30,minecraft:black_terracotta,50,minecraft:black_terracotta,100)
RB(6,9,4,minecraft:red_stained_glass,15,minecraft:pink_concrete,25,minecraft:red_concrete,25,minecraft:red_glazed_terracotta[facing=south],30,minecraft:black_terracotta,50,minecraft:black_terracotta,100)
RB(7,6,-3,minecraft:red_stained_glass,15,minecraft:pink_concrete,25,minecraft:red_concrete,25,minecraft:red_glazed_terracotta[facing=south],30,minecraft:black_terracotta,50,minecraft:black_terracotta,100)
RB(7,6,4,minecraft:red_stained_glass,15,minecraft:pink_concrete,25,minecraft:red_concrete,25,minecraft:red_glazed_terracotta[facing=south],30,minecraft:black_terracotta,50,minecraft:black_terracotta,100)
RB(7,7,-3,minecraft:red_stained_glass,15,minecraft:pink_concrete,25,minecraft:red_concrete,25,minecraft:red_glazed_terracotta[facing=south],30,minecraft:black_terracotta,50,minecraft:black_terracotta,100)
RB(7,7,4,minecraft:red_stained_glass,15,minecraft:pink_concrete,25,minecraft:red_concrete,25,minecraft:red_glazed_terracotta[facing=south],30,minecraft:black_terracotta,50,minecraft:black_terracotta,100)
RB(7,8,-3,minecraft:red_stained_glass,15,minecraft:pink_concrete,25,minecraft:red_concrete,25,minecraft:red_glazed_terracotta[facing=south],30,minecraft:black_terracotta,50,minecraft:black_terracotta,100)
RB(7,8,4,minecraft:red_stained_glass,15,minecraft:pink_concrete,25,minecraft:red_concrete,25,minecraft:red_glazed_terracotta[facing=south],30,minecraft:black_terracotta,50,minecraft:black_terracotta,100)
RB(7,9,-3,minecraft:red_stained_glass,15,minecraft:pink_concrete,25,minecraft:red_concrete,25,minecraft:red_glazed_terracotta[facing=south],30,minecraft:black_terracotta,50,minecraft:black_terracotta,100)
RB(7,9,4,minecraft:red_stained_glass,15,minecraft:pink_concrete,25,minecraft:red_concrete,25,minecraft:red_glazed_terracotta[facing=south],30,minecraft:black_terracotta,50,minecraft:black_terracotta,100)
RB(8,6,-3,minecraft:red_stained_glass,15,minecraft:pink_concrete,25,minecraft:red_concrete,25,minecraft:red_glazed_terracotta[facing=south],30,minecraft:black_terracotta,50,minecraft:black_terracotta,100)
RB(8,6,4,minecraft:red_stained_glass,15,minecraft:pink_concrete,25,minecraft:red_concrete,25,minecraft:red_glazed_terracotta[facing=south],30,minecraft:black_terracotta,50,minecraft:black_terracotta,100)
RB(8,7,-3,minecraft:red_stained_glass,15,minecraft:pink_concrete,25,minecraft:red_concrete,25,minecraft:red_glazed_terracotta[facing=south],30,minecraft:black_terracotta,50,minecraft:black_terracotta,100)
RB(8,7,4,minecraft:red_stained_glass,15,minecraft:pink_concrete,25,minecraft:red_concrete,25,minecraft:red_glazed_terracotta[facing=south],30,minecraft:black_terracotta,50,minecraft:black_terracotta,100)
RB(8,8,-3,minecraft:red_stained_glass,15,minecraft:pink_concrete,25,minecraft:red_concrete,25,minecraft:red_glazed_terracotta[facing=south],30,minecraft:black_terracotta,50,minecraft:black_terracotta,100)
RB(8,8,4,minecraft:red_stained_glass,15,minecraft:pink_concrete,25,minecraft:red_concrete,25,minecraft:red_glazed_terracotta[facing=south],30,minecraft:black_terracotta,50,minecraft:black_terracotta,100)
RB(8,9,-3,minecraft:red_stained_glass,15,minecraft:pink_concrete,25,minecraft:red_concrete,25,minecraft:red_glazed_terracotta[facing=south],30,minecraft:black_terracotta,50,minecraft:black_terracotta,100)
RB(8,9,4,minecraft:red_stained_glass,15,minecraft:pink_concrete,25,minecraft:red_concrete,25,minecraft:red_glazed_terracotta[facing=south],30,minecraft:black_terracotta,50,minecraft:black_terracotta,100)
RB(9,6,-3,minecraft:red_stained_glass,15,minecraft:pink_concrete,25,minecraft:red_concrete,25,minecraft:red_glazed_terracotta[facing=south],30,minecraft:black_terracotta,50,minecraft:black_terracotta,100)
RB(9,6,4,minecraft:red_stained_glass,15,minecraft:pink_concrete,25,minecraft:red_concrete,25,minecraft:red_glazed_terracotta[facing=south],30,minecraft:black_terracotta,50,minecraft:black_terracotta,100)
RB(9,7,-3,minecraft:red_stained_glass,15,minecraft:pink_concrete,25,minecraft:red_concrete,25,minecraft:red_glazed_terracotta[facing=south],30,minecraft:black_terracotta,50,minecraft:black_terracotta,100)
RB(9,7,4,minecraft:red_stained_glass,15,minecraft:pink_concrete,25,minecraft:red_concrete,25,minecraft:red_glazed_terracotta[facing=south],30,minecraft:black_terracotta,50,minecraft:black_terracotta,100)
RB(9,8,-3,minecraft:red_stained_glass,15,minecraft:pink_concrete,25,minecraft:red_concrete,25,minecraft:red_glazed_terracotta[facing=south],30,minecraft:black_terracotta,50,minecraft:black_terracotta,100)
RB(9,8,4,minecraft:red_stained_glass,15,minecraft:pink_concrete,25,minecraft:red_concrete,25,minecraft:red_glazed_terracotta[facing=south],30,minecraft:black_terracotta,50,minecraft:black_terracotta,100)
RB(9,9,-3,minecraft:red_stained_glass,15,minecraft:pink_concrete,25,minecraft:red_concrete,25,minecraft:red_glazed_terracotta[facing=south],30,minecraft:black_terracotta,50,minecraft:black_terracotta,100)
RB(9,9,4,minecraft:red_stained_glass,15,minecraft:pink_concrete,25,minecraft:red_concrete,25,minecraft:red_glazed_terracotta[facing=south],30,minecraft:black_terracotta,50,minecraft:black_terracotta,100)
RB(10,6,-3,minecraft:red_stained_glass,15,minecraft:pink_concrete,25,minecraft:red_concrete,25,minecraft:red_glazed_terracotta[facing=south],30,minecraft:black_terracotta,50,minecraft:black_terracotta,100)
RB(10,6,-2,minecraft:red_stained_glass,15,minecraft:pink_concrete,25,minecraft:red_concrete,25,minecraft:red_glazed_terracotta[facing=south],30,minecraft:black_terracotta,50,minecraft:black_terracotta,100)
RB(10,6,-1,minecraft:red_stained_glass,15,minecraft:pink_concrete,25,minecraft:red_concrete,25,minecraft:red_glazed_terracotta[facing=south],30,minecraft:black_terracotta,50,minecraft:black_terracotta,100)
RB(10,6,0,minecraft:red_stained_glass,15,minecraft:pink_concrete,25,minecraft:red_concrete,25,minecraft:red_glazed_terracotta[facing=south],30,minecraft:black_terracotta,50,minecraft:black_terracotta,100)
RB(10,6,1,minecraft:red_stained_glass,15,minecraft:pink_concrete,25,minecraft:red_concrete,25,minecraft:red_glazed_terracotta[facing=south],30,minecraft:black_terracotta,50,minecraft:black_terracotta,100)
RB(10,6,2,minecraft:red_stained_glass,15,minecraft:pink_concrete,25,minecraft:red_concrete,25,minecraft:red_glazed_terracotta[facing=south],30,minecraft:black_terracotta,50,minecraft:black_terracotta,100)
RB(10,6,3,minecraft:red_stained_glass,15,minecraft:pink_concrete,25,minecraft:red_concrete,25,minecraft:red_glazed_terracotta[facing=south],30,minecraft:black_terracotta,50,minecraft:black_terracotta,100)
RB(10,6,4,minecraft:red_stained_glass,15,minecraft:pink_concrete,25,minecraft:red_concrete,25,minecraft:red_glazed_terracotta[facing=south],30,minecraft:black_terracotta,50,minecraft:black_terracotta,100)
RB(10,7,-3,minecraft:red_stained_glass,15,minecraft:pink_concrete,25,minecraft:red_concrete,25,minecraft:red_glazed_terracotta[facing=south],30,minecraft:black_terracotta,50,minecraft:black_terracotta,100)
RB(10,7,-2,minecraft:red_stained_glass,15,minecraft:pink_concrete,25,minecraft:red_concrete,25,minecraft:red_glazed_terracotta[facing=south],30,minecraft:black_terracotta,50,minecraft:black_terracotta,100)
RB(10,7,-1,minecraft:red_stained_glass,15,minecraft:pink_concrete,25,minecraft:red_concrete,25,minecraft:red_glazed_terracotta[facing=south],30,minecraft:black_terracotta,50,minecraft:black_terracotta,100)
RB(10,7,0,minecraft:red_stained_glass,15,minecraft:pink_concrete,25,minecraft:red_concrete,25,minecraft:red_glazed_terracotta[facing=south],30,minecraft:black_terracotta,50,minecraft:black_terracotta,100)
RB(10,7,1,minecraft:red_stained_glass,15,minecraft:pink_concrete,25,minecraft:red_concrete,25,minecraft:red_glazed_terracotta[facing=south],30,minecraft:black_terracotta,50,minecraft:black_terracotta,100)
RB(10,7,2,minecraft:red_stained_glass,15,minecraft:pink_concrete,25,minecraft:red_concrete,25,minecraft:red_glazed_terracotta[facing=south],30,minecraft:black_terracotta,50,minecraft:black_terracotta,100)
RB(10,7,3,minecraft:red_stained_glass,15,minecraft:pink_concrete,25,minecraft:red_concrete,25,minecraft:red_glazed_terracotta[facing=south],30,minecraft:black_terracotta,50,minecraft:black_terracotta,100)
RB(10,7,4,minecraft:red_stained_glass,15,minecraft:pink_concrete,25,minecraft:red_concrete,25,minecraft:red_glazed_terracotta[facing=south],30,minecraft:black_terracotta,50,minecraft:black_terracotta,100)
RB(10,8,-3,minecraft:red_stained_glass,15,minecraft:pink_concrete,25,minecraft:red_concrete,25,minecraft:red_glazed_terracotta[facing=south],30,minecraft:black_terracotta,50,minecraft:black_terracotta,100)
RB(10,8,-2,minecraft:red_stained_glass,15,minecraft:pink_concrete,25,minecraft:red_concrete,25,minecraft:red_glazed_terracotta[facing=south],30,minecraft:black_terracotta,50,minecraft:black_terracotta,100)
RB(10,8,-1,minecraft:red_stained_glass,15,minecraft:pink_concrete,25,minecraft:red_concrete,25,minecraft:red_glazed_terracotta[facing=south],30,minecraft:black_terracotta,50,minecraft:black_terracotta,100)
RB(10,8,0,minecraft:red_stained_glass,15,minecraft:pink_concrete,25,minecraft:red_concrete,25,minecraft:red_glazed_terracotta[facing=south],30,minecraft:black_terracotta,50,minecraft:black_terracotta,100)
RB(10,8,1,minecraft:red_stained_glass,15,minecraft:pink_concrete,25,minecraft:red_concrete,25,minecraft:red_glazed_terracotta[facing=south],30,minecraft:black_terracotta,50,minecraft:black_terracotta,100)
RB(10,8,2,minecraft:red_stained_glass,15,minecraft:pink_concrete,25,minecraft:red_concrete,25,minecraft:red_glazed_terracotta[facing=south],30,minecraft:black_terracotta,50,minecraft:black_terracotta,100)
RB(10,8,3,minecraft:red_stained_glass,15,minecraft:pink_concrete,25,minecraft:red_concrete,25,minecraft:red_glazed_terracotta[facing=south],30,minecraft:black_terracotta,50,minecraft:black_terracotta,100)
RB(10,8,4,minecraft:red_stained_glass,15,minecraft:pink_concrete,25,minecraft:red_concrete,25,minecraft:red_glazed_terracotta[facing=south],30,minecraft:black_terracotta,50,minecraft:black_terracotta,100)
RB(10,9,-3,minecraft:red_stained_glass,15,minecraft:pink_concrete,25,minecraft:red_concrete,25,minecraft:red_glazed_terracotta[facing=south],30,minecraft:black_terracotta,50,minecraft:black_terracotta,100)
RB(10,9,-2,minecraft:red_stained_glass,15,minecraft:pink_concrete,25,minecraft:red_concrete,25,minecraft:red_glazed_terracotta[facing=south],30,minecraft:black_terracotta,50,minecraft:black_terracotta,100)
RB(10,9,-1,minecraft:red_stained_glass,15,minecraft:pink_concrete,25,minecraft:red_concrete,25,minecraft:red_glazed_terracotta[facing=south],30,minecraft:black_terracotta,50,minecraft:black_terracotta,100)
RB(10,9,0,minecraft:red_stained_glass,15,minecraft:pink_concrete,25,minecraft:red_concrete,25,minecraft:red_glazed_terracotta[facing=south],30,minecraft:black_terracotta,50,minecraft:black_terracotta,100)
RB(10,9,1,minecraft:red_stained_glass,15,minecraft:pink_concrete,25,minecraft:red_concrete,25,minecraft:red_glazed_terracotta[facing=south],30,minecraft:black_terracotta,50,minecraft:black_terracotta,100)
RB(10,9,2,minecraft:red_stained_glass,15,minecraft:pink_concrete,25,minecraft:red_concrete,25,minecraft:red_glazed_terracotta[facing=south],30,minecraft:black_terracotta,50,minecraft:black_terracotta,100)
RB(10,9,3,minecraft:red_stained_glass,15,minecraft:pink_concrete,25,minecraft:red_concrete,25,minecraft:red_glazed_terracotta[facing=south],30,minecraft:black_terracotta,50,minecraft:black_terracotta,100)
RB(10,9,4,minecraft:red_stained_glass,15,minecraft:pink_concrete,25,minecraft:red_concrete,25,minecraft:red_glazed_terracotta[facing=south],30,minecraft:black_terracotta,50,minecraft:black_terracotta,100)
RB(-5,1,0,minecraft:skeleton_skull,NBT/Skulls/dungeon_skull_01.nbt,6,minecraft:air,9,minecraft:skeleton_skull,NBT/Skulls/dungeon_skull_02.nbt,12,minecraft:air,15,minecraft:skeleton_skull,NBT/Skulls/dungeon_skull_03.nbt,18,minecraft:air,21,minecraft:skeleton_skull,NBT/Skulls/dungeon_skull_04.nbt,24,minecraft:air,27,minecraft:skeleton_skull,NBT/Skulls/dungeon_skull_05.nbt,30,minecraft:air,33,minecraft:skeleton_skull,NBT/Skulls/dungeon_skull_06.nbt,36,minecraft:air,39,minecraft:skeleton_skull,NBT/Skulls/dungeon_skull_07.nbt,42,minecraft:air,45,minecraft:skeleton_skull,NBT/Skulls/dungeon_skull_08.nbt,48,minecraft:air,51,minecraft:skeleton_skull,NBT/Skulls/dungeon_skull_09.nbt,54,minecraft:air,57,minecraft:skeleton_skull,NBT/Skulls/dungeon_skull_10.nbt,60,minecraft:air,63,minecraft:skeleton_skull,NBT/Skulls/dungeon_skull_11.nbt,66,minecraft:air,69,minecraft:skeleton_skull,NBT/Skulls/dungeon_skull_12.nbt,72,minecraft:air,75,minecraft:skeleton_skull,NBT/Skulls/dungeon_skull_13.nbt,78,minecraft:air,81,minecraft:skeleton_skull,NBT/Skulls/dungeon_skull_14.nbt,84,minecraft:air,87,minecraft:skeleton_skull,NBT/Skulls/dungeon_skull_15.nbt,90,minecraft:air,93,minecraft:skeleton_skull,NBT/Skulls/dungeon_skull_16.nbt,96,minecraft:air,100)
RB(-5,1,2,minecraft:skeleton_skull,NBT/Skulls/dungeon_skull_01.nbt,6,minecraft:air,9,minecraft:skeleton_skull,NBT/Skulls/dungeon_skull_02.nbt,12,minecraft:air,15,minecraft:skeleton_skull,NBT/Skulls/dungeon_skull_03.nbt,18,minecraft:air,21,minecraft:skeleton_skull,NBT/Skulls/dungeon_skull_04.nbt,24,minecraft:air,27,minecraft:skeleton_skull,NBT/Skulls/dungeon_skull_05.nbt,30,minecraft:air,33,minecraft:skeleton_skull,NBT/Skulls/dungeon_skull_06.nbt,36,minecraft:air,39,minecraft:skeleton_skull,NBT/Skulls/dungeon_skull_07.nbt,42,minecraft:air,45,minecraft:skeleton_skull,NBT/Skulls/dungeon_skull_08.nbt,48,minecraft:air,51,minecraft:skeleton_skull,NBT/Skulls/dungeon_skull_09.nbt,54,minecraft:air,57,minecraft:skeleton_skull,NBT/Skulls/dungeon_skull_10.nbt,60,minecraft:air,63,minecraft:skeleton_skull,NBT/Skulls/dungeon_skull_11.nbt,66,minecraft:air,69,minecraft:skeleton_skull,NBT/Skulls/dungeon_skull_12.nbt,72,minecraft:air,75,minecraft:skeleton_skull,NBT/Skulls/dungeon_skull_13.nbt,78,minecraft:air,81,minecraft:skeleton_skull,NBT/Skulls/dungeon_skull_14.nbt,84,minecraft:air,87,minecraft:skeleton_skull,NBT/Skulls/dungeon_skull_15.nbt,90,minecraft:air,93,minecraft:skeleton_skull,NBT/Skulls/dungeon_skull_16.nbt,96,minecraft:air,100)
RB(-5,2,-1,minecraft:skeleton_skull,NBT/Skulls/dungeon_skull_01.nbt,6,minecraft:air,9,minecraft:skeleton_skull,NBT/Skulls/dungeon_skull_02.nbt,12,minecraft:air,15,minecraft:skeleton_skull,NBT/Skulls/dungeon_skull_03.nbt,18,minecraft:air,21,minecraft:skeleton_skull,NBT/Skulls/dungeon_skull_04.nbt,24,minecraft:air,27,minecraft:skeleton_skull,NBT/Skulls/dungeon_skull_05.nbt,30,minecraft:air,33,minecraft:skeleton_skull,NBT/Skulls/dungeon_skull_06.nbt,36,minecraft:air,39,minecraft:skeleton_skull,NBT/Skulls/dungeon_skull_07.nbt,42,minecraft:air,45,minecraft:skeleton_skull,NBT/Skulls/dungeon_skull_08.nbt,48,minecraft:air,51,minecraft:skeleton_skull,NBT/Skulls/dungeon_skull_09.nbt,54,minecraft:air,57,minecraft:skeleton_skull,NBT/Skulls/dungeon_skull_10.nbt,60,minecraft:air,63,minecraft:skeleton_skull,NBT/Skulls/dungeon_skull_11.nbt,66,minecraft:air,69,minecraft:skeleton_skull,NBT/Skulls/dungeon_skull_12.nbt,72,minecraft:air,75,minecraft:skeleton_skull,NBT/Skulls/dungeon_skull_13.nbt,78,minecraft:air,81,minecraft:skeleton_skull,NBT/Skulls/dungeon_skull_14.nbt,84,minecraft:air,87,minecraft:skeleton_skull,NBT/Skulls/dungeon_skull_15.nbt,90,minecraft:air,93,minecraft:skeleton_skull,NBT/Skulls/dungeon_skull_16.nbt,96,minecraft:air,100)
RB(-5,2,1,minecraft:skeleton_skull,NBT/Skulls/dungeon_skull_01.nbt,6,minecraft:air,9,minecraft:skeleton_skull,NBT/Skulls/dungeon_skull_02.nbt,12,minecraft:air,15,minecraft:skeleton_skull,NBT/Skulls/dungeon_skull_03.nbt,18,minecraft:air,21,minecraft:skeleton_skull,NBT/Skulls/dungeon_skull_04.nbt,24,minecraft:air,27,minecraft:skeleton_skull,NBT/Skulls/dungeon_skull_05.nbt,30,minecraft:air,33,minecraft:skeleton_skull,NBT/Skulls/dungeon_skull_06.nbt,36,minecraft:air,39,minecraft:skeleton_skull,NBT/Skulls/dungeon_skull_07.nbt,42,minecraft:air,45,minecraft:skeleton_skull,NBT/Skulls/dungeon_skull_08.nbt,48,minecraft:air,51,minecraft:skeleton_skull,NBT/Skulls/dungeon_skull_09.nbt,54,minecraft:air,57,minecraft:skeleton_skull,NBT/Skulls/dungeon_skull_10.nbt,60,minecraft:air,63,minecraft:skeleton_skull,NBT/Skulls/dungeon_skull_11.nbt,66,minecraft:air,69,minecraft:skeleton_skull,NBT/Skulls/dungeon_skull_12.nbt,72,minecraft:air,75,minecraft:skeleton_skull,NBT/Skulls/dungeon_skull_13.nbt,78,minecraft:air,81,minecraft:skeleton_skull,NBT/Skulls/dungeon_skull_14.nbt,84,minecraft:air,87,minecraft:skeleton_skull,NBT/Skulls/dungeon_skull_15.nbt,90,minecraft:air,93,minecraft:skeleton_skull,NBT/Skulls/dungeon_skull_16.nbt,96,minecraft:air,100)
RB(-5,3,0,minecraft:skeleton_skull,NBT/Skulls/dungeon_skull_01.nbt,6,minecraft:air,9,minecraft:skeleton_skull,NBT/Skulls/dungeon_skull_02.nbt,12,minecraft:air,15,minecraft:skeleton_skull,NBT/Skulls/dungeon_skull_03.nbt,18,minecraft:air,21,minecraft:skeleton_skull,NBT/Skulls/dungeon_skull_04.nbt,24,minecraft:air,27,minecraft:skeleton_skull,NBT/Skulls/dungeon_skull_05.nbt,30,minecraft:air,33,minecraft:skeleton_skull,NBT/Skulls/dungeon_skull_06.nbt,36,minecraft:air,39,minecraft:skeleton_skull,NBT/Skulls/dungeon_skull_07.nbt,42,minecraft:air,45,minecraft:skeleton_skull,NBT/Skulls/dungeon_skull_08.nbt,48,minecraft:air,51,minecraft:skeleton_skull,NBT/Skulls/dungeon_skull_09.nbt,54,minecraft:air,57,minecraft:skeleton_skull,NBT/Skulls/dungeon_skull_10.nbt,60,minecraft:air,63,minecraft:skeleton_skull,NBT/Skulls/dungeon_skull_11.nbt,66,minecraft:air,69,minecraft:skeleton_skull,NBT/Skulls/dungeon_skull_12.nbt,72,minecraft:air,75,minecraft:skeleton_skull,NBT/Skulls/dungeon_skull_13.nbt,78,minecraft:air,81,minecraft:skeleton_skull,NBT/Skulls/dungeon_skull_14.nbt,84,minecraft:air,87,minecraft:skeleton_skull,NBT/Skulls/dungeon_skull_15.nbt,90,minecraft:air,93,minecraft:skeleton_skull,NBT/Skulls/dungeon_skull_16.nbt,96,minecraft:air,100)
RB(-5,3,2,minecraft:skeleton_skull,NBT/Skulls/dungeon_skull_01.nbt,6,minecraft:air,9,minecraft:skeleton_skull,NBT/Skulls/dungeon_skull_02.nbt,12,minecraft:air,15,minecraft:skeleton_skull,NBT/Skulls/dungeon_skull_03.nbt,18,minecraft:air,21,minecraft:skeleton_skull,NBT/Skulls/dungeon_skull_04.nbt,24,minecraft:air,27,minecraft:skeleton_skull,NBT/Skulls/dungeon_skull_05.nbt,30,minecraft:air,33,minecraft:skeleton_skull,NBT/Skulls/dungeon_skull_06.nbt,36,minecraft:air,39,minecraft:skeleton_skull,NBT/Skulls/dungeon_skull_07.nbt,42,minecraft:air,45,minecraft:skeleton_skull,NBT/Skulls/dungeon_skull_08.nbt,48,minecraft:air,51,minecraft:skeleton_skull,NBT/Skulls/dungeon_skull_09.nbt,54,minecraft:air,57,minecraft:skeleton_skull,NBT/Skulls/dungeon_skull_10.nbt,60,minecraft:air,63,minecraft:skeleton_skull,NBT/Skulls/dungeon_skull_11.nbt,66,minecraft:air,69,minecraft:skeleton_skull,NBT/Skulls/dungeon_skull_12.nbt,72,minecraft:air,75,minecraft:skeleton_skull,NBT/Skulls/dungeon_skull_13.nbt,78,minecraft:air,81,minecraft:skeleton_skull,NBT/Skulls/dungeon_skull_14.nbt,84,minecraft:air,87,minecraft:skeleton_skull,NBT/Skulls/dungeon_skull_15.nbt,90,minecraft:air,93,minecraft:skeleton_skull,NBT/Skulls/dungeon_skull_16.nbt,96,minecraft:air,100)
RB(-3,1,4,minecraft:skeleton_skull,NBT/Skulls/dungeon_skull_01.nbt,6,minecraft:air,9,minecraft:skeleton_skull,NBT/Skulls/dungeon_skull_02.nbt,12,minecraft:air,15,minecraft:skeleton_skull,NBT/Skulls/dungeon_skull_03.nbt,18,minecraft:air,21,minecraft:skeleton_skull,NBT/Skulls/dungeon_skull_04.nbt,24,minecraft:air,27,minecraft:skeleton_skull,NBT/Skulls/dungeon_skull_05.nbt,30,minecraft:air,33,minecraft:skeleton_skull,NBT/Skulls/dungeon_skull_06.nbt,36,minecraft:air,39,minecraft:skeleton_skull,NBT/Skulls/dungeon_skull_07.nbt,42,minecraft:air,45,minecraft:skeleton_skull,NBT/Skulls/dungeon_skull_08.nbt,48,minecraft:air,51,minecraft:skeleton_skull,NBT/Skulls/dungeon_skull_09.nbt,54,minecraft:air,57,minecraft:skeleton_skull,NBT/Skulls/dungeon_skull_10.nbt,60,minecraft:air,63,minecraft:skeleton_skull,NBT/Skulls/dungeon_skull_11.nbt,66,minecraft:air,69,minecraft:skeleton_skull,NBT/Skulls/dungeon_skull_12.nbt,72,minecraft:air,75,minecraft:skeleton_skull,NBT/Skulls/dungeon_skull_13.nbt,78,minecraft:air,81,minecraft:skeleton_skull,NBT/Skulls/dungeon_skull_14.nbt,84,minecraft:air,87,minecraft:skeleton_skull,NBT/Skulls/dungeon_skull_15.nbt,90,minecraft:air,93,minecraft:skeleton_skull,NBT/Skulls/dungeon_skull_16.nbt,96,minecraft:air,100)
RB(-3,2,-3,minecraft:skeleton_skull,NBT/Skulls/dungeon_skull_01.nbt,6,minecraft:air,9,minecraft:skeleton_skull,NBT/Skulls/dungeon_skull_02.nbt,12,minecraft:air,15,minecraft:skeleton_skull,NBT/Skulls/dungeon_skull_03.nbt,18,minecraft:air,21,minecraft:skeleton_skull,NBT/Skulls/dungeon_skull_04.nbt,24,minecraft:air,27,minecraft:skeleton_skull,NBT/Skulls/dungeon_skull_05.nbt,30,minecraft:air,33,minecraft:skeleton_skull,NBT/Skulls/dungeon_skull_06.nbt,36,minecraft:air,39,minecraft:skeleton_skull,NBT/Skulls/dungeon_skull_07.nbt,42,minecraft:air,45,minecraft:skeleton_skull,NBT/Skulls/dungeon_skull_08.nbt,48,minecraft:air,51,minecraft:skeleton_skull,NBT/Skulls/dungeon_skull_09.nbt,54,minecraft:air,57,minecraft:skeleton_skull,NBT/Skulls/dungeon_skull_10.nbt,60,minecraft:air,63,minecraft:skeleton_skull,NBT/Skulls/dungeon_skull_11.nbt,66,minecraft:air,69,minecraft:skeleton_skull,NBT/Skulls/dungeon_skull_12.nbt,72,minecraft:air,75,minecraft:skeleton_skull,NBT/Skulls/dungeon_skull_13.nbt,78,minecraft:air,81,minecraft:skeleton_skull,NBT/Skulls/dungeon_skull_14.nbt,84,minecraft:air,87,minecraft:skeleton_skull,NBT/Skulls/dungeon_skull_15.nbt,90,minecraft:air,93,minecraft:skeleton_skull,NBT/Skulls/dungeon_skull_16.nbt,96,minecraft:air,100)
RB(-3,3,4,minecraft:skeleton_skull,NBT/Skulls/dungeon_skull_01.nbt,6,minecraft:air,9,minecraft:skeleton_skull,NBT/Skulls/dungeon_skull_02.nbt,12,minecraft:air,15,minecraft:skeleton_skull,NBT/Skulls/dungeon_skull_03.nbt,18,minecraft:air,21,minecraft:skeleton_skull,NBT/Skulls/dungeon_skull_04.nbt,24,minecraft:air,27,minecraft:skeleton_skull,NBT/Skulls/dungeon_skull_05.nbt,30,minecraft:air,33,minecraft:skeleton_skull,NBT/Skulls/dungeon_skull_06.nbt,36,minecraft:air,39,minecraft:skeleton_skull,NBT/Skulls/dungeon_skull_07.nbt,42,minecraft:air,45,minecraft:skeleton_skull,NBT/Skulls/dungeon_skull_08.nbt,48,minecraft:air,51,minecraft:skeleton_skull,NBT/Skulls/dungeon_skull_09.nbt,54,minecraft:air,57,minecraft:skeleton_skull,NBT/Skulls/dungeon_skull_10.nbt,60,minecraft:air,63,minecraft:skeleton_skull,NBT/Skulls/dungeon_skull_11.nbt,66,minecraft:air,69,minecraft:skeleton_skull,NBT/Skulls/dungeon_skull_12.nbt,72,minecraft:air,75,minecraft:skeleton_skull,NBT/Skulls/dungeon_skull_13.nbt,78,minecraft:air,81,minecraft:skeleton_skull,NBT/Skulls/dungeon_skull_14.nbt,84,minecraft:air,87,minecraft:skeleton_skull,NBT/Skulls/dungeon_skull_15.nbt,90,minecraft:air,93,minecraft:skeleton_skull,NBT/Skulls/dungeon_skull_16.nbt,96,minecraft:air,100)
RB(-2,1,-3,minecraft:skeleton_skull,NBT/Skulls/dungeon_skull_01.nbt,6,minecraft:air,9,minecraft:skeleton_skull,NBT/Skulls/dungeon_skull_02.nbt,12,minecraft:air,15,minecraft:skeleton_skull,NBT/Skulls/dungeon_skull_03.nbt,18,minecraft:air,21,minecraft:skeleton_skull,NBT/Skulls/dungeon_skull_04.nbt,24,minecraft:air,27,minecraft:skeleton_skull,NBT/Skulls/dungeon_skull_05.nbt,30,minecraft:air,33,minecraft:skeleton_skull,NBT/Skulls/dungeon_skull_06.nbt,36,minecraft:air,39,minecraft:skeleton_skull,NBT/Skulls/dungeon_skull_07.nbt,42,minecraft:air,45,minecraft:skeleton_skull,NBT/Skulls/dungeon_skull_08.nbt,48,minecraft:air,51,minecraft:skeleton_skull,NBT/Skulls/dungeon_skull_09.nbt,54,minecraft:air,57,minecraft:skeleton_skull,NBT/Skulls/dungeon_skull_10.nbt,60,minecraft:air,63,minecraft:skeleton_skull,NBT/Skulls/dungeon_skull_11.nbt,66,minecraft:air,69,minecraft:skeleton_skull,NBT/Skulls/dungeon_skull_12.nbt,72,minecraft:air,75,minecraft:skeleton_skull,NBT/Skulls/dungeon_skull_13.nbt,78,minecraft:air,81,minecraft:skeleton_skull,NBT/Skulls/dungeon_skull_14.nbt,84,minecraft:air,87,minecraft:skeleton_skull,NBT/Skulls/dungeon_skull_15.nbt,90,minecraft:air,93,minecraft:skeleton_skull,NBT/Skulls/dungeon_skull_16.nbt,96,minecraft:air,100)
RB(-2,3,-3,minecraft:skeleton_skull,NBT/Skulls/dungeon_skull_01.nbt,6,minecraft:air,9,minecraft:skeleton_skull,NBT/Skulls/dungeon_skull_02.nbt,12,minecraft:air,15,minecraft:skeleton_skull,NBT/Skulls/dungeon_skull_03.nbt,18,minecraft:air,21,minecraft:skeleton_skull,NBT/Skulls/dungeon_skull_04.nbt,24,minecraft:air,27,minecraft:skeleton_skull,NBT/Skulls/dungeon_skull_05.nbt,30,minecraft:air,33,minecraft:skeleton_skull,NBT/Skulls/dungeon_skull_06.nbt,36,minecraft:air,39,minecraft:skeleton_skull,NBT/Skulls/dungeon_skull_07.nbt,42,minecraft:air,45,minecraft:skeleton_skull,NBT/Skulls/dungeon_skull_08.nbt,48,minecraft:air,51,minecraft:skeleton_skull,NBT/Skulls/dungeon_skull_09.nbt,54,minecraft:air,57,minecraft:skeleton_skull,NBT/Skulls/dungeon_skull_10.nbt,60,minecraft:air,63,minecraft:skeleton_skull,NBT/Skulls/dungeon_skull_11.nbt,66,minecraft:air,69,minecraft:skeleton_skull,NBT/Skulls/dungeon_skull_12.nbt,72,minecraft:air,75,minecraft:skeleton_skull,NBT/Skulls/dungeon_skull_13.nbt,78,minecraft:air,81,minecraft:skeleton_skull,NBT/Skulls/dungeon_skull_14.nbt,84,minecraft:air,87,minecraft:skeleton_skull,NBT/Skulls/dungeon_skull_15.nbt,90,minecraft:air,93,minecraft:skeleton_skull,NBT/Skulls/dungeon_skull_16.nbt,96,minecraft:air,100)
RB(-1,1,4,minecraft:skeleton_skull,NBT/Skulls/dungeon_skull_01.nbt,6,minecraft:air,9,minecraft:skeleton_skull,NBT/Skulls/dungeon_skull_02.nbt,12,minecraft:air,15,minecraft:skeleton_skull,NBT/Skulls/dungeon_skull_03.nbt,18,minecraft:air,21,minecraft:skeleton_skull,NBT/Skulls/dungeon_skull_04.nbt,24,minecraft:air,27,minecraft:skeleton_skull,NBT/Skulls/dungeon_skull_05.nbt,30,minecraft:air,33,minecraft:skeleton_skull,NBT/Skulls/dungeon_skull_06.nbt,36,minecraft:air,39,minecraft:skeleton_skull,NBT/Skulls/dungeon_skull_07.nbt,42,minecraft:air,45,minecraft:skeleton_skull,NBT/Skulls/dungeon_skull_08.nbt,48,minecraft:air,51,minecraft:skeleton_skull,NBT/Skulls/dungeon_skull_09.nbt,54,minecraft:air,57,minecraft:skeleton_skull,NBT/Skulls/dungeon_skull_10.nbt,60,minecraft:air,63,minecraft:skeleton_skull,NBT/Skulls/dungeon_skull_11.nbt,66,minecraft:air,69,minecraft:skeleton_skull,NBT/Skulls/dungeon_skull_12.nbt,72,minecraft:air,75,minecraft:skeleton_skull,NBT/Skulls/dungeon_skull_13.nbt,78,minecraft:air,81,minecraft:skeleton_skull,NBT/Skulls/dungeon_skull_14.nbt,84,minecraft:air,87,minecraft:skeleton_skull,NBT/Skulls/dungeon_skull_15.nbt,90,minecraft:air,93,minecraft:skeleton_skull,NBT/Skulls/dungeon_skull_16.nbt,96,minecraft:air,100)
