#######################################################################
# +-----------------------------------------------------------------+ #
# |                            BO3 object                           | #
# +-----------------------------------------------------------------+ #
#######################################################################

# This is the config file of a custom object.
# If you add this object correctly to your BiomeConfigs, it will spawn in the world.

# This is the creator of this BO3 object
Author: BO3 BulkEdit (by LanToaster)

# A short description of this BO3 object
Description: This Object was Created with BO3_BulkEdit

# The BO3 version, don't change this! It can be used by external applications to do a version check.
Version: 3

# The settings mode, WriteAll, WriteWithoutComments or WriteDisable. See WorldConfig.
SettingsMode: WriteDisable


#######################################################################
# +-----------------------------------------------------------------+ #
# |                          Main settings                          | #
# +-----------------------------------------------------------------+ #
#######################################################################

# This needs to be set to true to spawn the object in the Tree and Sapling resources.
Tree: false

# The frequency of the BO3 from 1 to 200. Tries this many times to spawn this BO3 when using the CustomObject(...) resource.

Frequency: 1

# The rarity of the BO3 from 0 to 100. Each spawn attempt has rarity% chance to succeed when using the CustomObject(...) resource.

Rarity: 100.0

# If you set this to true, the BO3 will be placed with a random rotation.
RotateRandomly: false

# The spawn height of the BO3 - randomY, highestBlock or highestSolidBlock.
SpawnHeight: highestBlock

# The height limits for the BO3.
MinHeight: 0

MaxHeight: 256

# Objects can have other objects attacthed to it: branches. Branches can also
# have branches attached to it, which can also have branches, etc. This is the
# maximum branch depth for this objects.
MaxBranchDepth: 10

# When spawned with the UseWorld keyword, this BO3 should NOT spawn in the following biomes.
# If you writer.write the BO3 name directly in the BiomeConfigs, this will be ignored.
ExcludedBiomes: All


#######################################################################
# +-----------------------------------------------------------------+ #
# |                      Source block settings                      | #
# +-----------------------------------------------------------------+ #
#######################################################################

# The block(s) the BO3 should spawn in.
SourceBlocks: AIR

# The maximum percentage of the BO3 that can be outside the SourceBlock.
# The BO3 won't be placed on a location with more blocks outside the SourceBlock than this percentage.
MaxPercentageOutsideSourceBlock: 100

# What to do when a block is about to be placed outside the SourceBlock? (dontPlace, placeAnyway)
OutsideSourceBlock: placeAnyway


#######################################################################
# +-----------------------------------------------------------------+ #
# |                              Blocks                             | #
# +-----------------------------------------------------------------+ #
#######################################################################

# All the blocks used in the BO3 are listed here. Possible blocks:
# Block(x,y,z,id[.data][,nbtfile.nbt)
# RandomBlock(x,y,z,id[:data][,nbtfile.nbt],chance[,id[:data][,nbtfile.nbt],chance[,...]])
# So RandomBlock(0,0,0,CHEST,chest.nbt,50,CHEST,anotherchest.nbt,100) will spawn a chest at
# the BO3 origin, and give it a 50% chance to have the contents of chest.nbt, or, if that
# fails, a 100% percent chance to have the contents of anotherchest.nbt.
Block(0,0,-3,STAINED_GLASS:9)
Block(1,0,-3,STAINED_GLASS:9)
Block(-2,0,-2,STAINED_GLASS:15)
Block(-1,0,-2,STAINED_GLASS:15)
Block(0,0,-2,STAINED_GLASS:9)
Block(1,0,-2,STAINED_GLASS:9)
Block(-3,0,-1,STAINED_GLASS:15)
Block(-2,0,-1,STAINED_GLASS:15)
Block(-1,0,-1,STAINED_GLASS:15)
Block(0,0,-1,STAINED_GLASS:15)
Block(1,0,-1,STAINED_GLASS:15)
Block(2,0,-1,STAINED_GLASS:9)
Block(-2,0,0,STAINED_GLASS:15)
Block(-1,0,0,STAINED_GLASS:15)
Block(1,0,0,STAINED_GLASS:9)
Block(2,0,0,STAINED_GLASS:15)
Block(-1,0,1,STAINED_GLASS:9)
Block(0,0,1,STAINED_GLASS:9)
Block(1,0,1,STAINED_GLASS:9)
Block(2,0,1,STAINED_GLASS:15)
Block(-1,0,2,STAINED_GLASS:11)
Block(-1,1,-5,STAINED_GLASS:15)
Block(0,1,-5,STAINED_GLASS:15)
Block(-4,1,-4,STAINED_GLASS:15)
Block(-3,1,-4,STAINED_GLASS:15)
Block(-2,1,-4,STAINED_GLASS:15)
Block(-1,1,-4,STAINED_GLASS:9)
Block(0,1,-4,STAINED_GLASS:9)
Block(1,1,-4,STAINED_GLASS:9)
Block(-3,1,-3,STAINED_GLASS:15)
Block(-2,1,-3,STAINED_GLASS:15)
Block(-1,1,-3,STAINED_GLASS:9)
Block(0,1,-3,STAINED_GLASS:9)
Block(1,1,-3,STAINED_GLASS:9)
Block(-3,1,-2,STAINED_GLASS:15)
Block(-2,1,-2,STAINED_GLASS:15)
Block(-1,1,-2,STAINED_GLASS:15)
Block(0,1,-2,STAINED_GLASS:9)
Block(1,1,-2,STAINED_GLASS:9)
Block(-3,1,-1,STAINED_GLASS:15)
Block(-2,1,-1,STAINED_GLASS:9)
Block(-1,1,-1,SEA_LANTERN:0)
Block(0,1,-1,STAINED_GLASS:9)
Block(1,1,-1,STAINED_GLASS:9)
Block(2,1,-1,STAINED_GLASS:11)
Block(-2,1,0,STAINED_GLASS:15)
Block(-1,1,0,SEA_LANTERN:0)
Block(0,1,0,SEA_LANTERN:0)
Block(1,1,0,SEA_LANTERN:0)
Block(2,1,0,STAINED_GLASS:15)
Block(-1,1,1,SEA_LANTERN:0)
Block(0,1,1,SEA_LANTERN:0)
Block(1,1,1,SEA_LANTERN:0)
Block(2,1,1,STAINED_GLASS:15)
Block(-1,1,2,SEA_LANTERN:0)
Block(0,1,2,STAINED_GLASS:9)
Block(-2,2,-7,STAINED_GLASS:15)
Block(-1,2,-7,STAINED_GLASS:15)
Block(-4,2,-6,STAINED_GLASS:15)
Block(-3,2,-6,STAINED_GLASS:15)
Block(-2,2,-6,STAINED_GLASS:15)
Block(-1,2,-6,STAINED_GLASS:15)
Block(-4,2,-5,STAINED_GLASS:15)
Block(-3,2,-5,STAINED_GLASS:15)
Block(-2,2,-5,STAINED_GLASS:15)
Block(-1,2,-5,STAINED_GLASS:15)
Block(0,2,-5,STAINED_GLASS:9)
Block(-4,2,-4,STAINED_GLASS:15)
Block(-3,2,-4,STAINED_GLASS:15)
Block(-2,2,-4,SEA_LANTERN:0)
Block(-1,2,-4,STAINED_GLASS:9)
Block(0,2,-4,STAINED_GLASS:9)
Block(1,2,-4,STAINED_GLASS:9)
Block(-3,2,-3,STAINED_GLASS:9)
Block(-2,2,-3,SEA_LANTERN:0)
Block(-1,2,-3,STAINED_GLASS:9)
Block(0,2,-3,STAINED_GLASS:9)
Block(1,2,-3,STAINED_GLASS:11)
Block(-3,2,-2,STAINED_GLASS:15)
Block(-2,2,-2,STAINED_GLASS:10)
Block(-1,2,-2,SEA_LANTERN:0)
Block(0,2,-2,STAINED_GLASS:15)
Block(1,2,-2,STAINED_GLASS:11)
Block(-3,2,-1,STAINED_GLASS:15)
Block(-2,2,-1,SEA_LANTERN:0)
Block(-1,2,-1,SEA_LANTERN:0)
Block(0,2,-1,STAINED_GLASS:15)
Block(1,2,-1,STAINED_GLASS:15)
Block(2,2,-1,STAINED_GLASS:11)
Block(-2,2,0,STAINED_GLASS:15)
Block(-1,2,0,SEA_LANTERN:0)
Block(0,2,0,SEA_LANTERN:0)
Block(1,2,0,STAINED_GLASS:11)
Block(2,2,0,STAINED_GLASS:15)
Block(-1,2,1,STAINED_GLASS:10)
Block(0,2,1,SEA_LANTERN:0)
Block(1,2,1,SEA_LANTERN:0)
Block(2,2,1,STAINED_GLASS:15)
Block(-1,2,2,STAINED_GLASS:9)
Block(0,2,2,STAINED_GLASS:15)
Block(2,2,2,STAINED_GLASS:11)
Block(-6,3,-7,STAINED_GLASS:15)
Block(-5,3,-7,STAINED_GLASS:15)
Block(-4,3,-7,STAINED_GLASS:15)
Block(-3,3,-7,STAINED_GLASS:15)
Block(-2,3,-7,STAINED_GLASS:15)
Block(-1,3,-7,STAINED_GLASS:15)
Block(-5,3,-6,STAINED_GLASS:15)
Block(-4,3,-6,STAINED_GLASS:15)
Block(-3,3,-6,STAINED_GLASS:15)
Block(-2,3,-6,STAINED_GLASS:9)
Block(-1,3,-6,STAINED_GLASS:15)
Block(-4,3,-5,STAINED_GLASS:15)
Block(-3,3,-5,STAINED_GLASS:15)
Block(-2,3,-5,SEA_LANTERN:0)
Block(-1,3,-5,STAINED_GLASS:9)
Block(0,3,-5,STAINED_GLASS:11)
Block(-4,3,-4,STAINED_GLASS:15)
Block(-3,3,-4,SEA_LANTERN:0)
Block(-2,3,-4,SEA_LANTERN:0)
Block(-1,3,-4,SEA_LANTERN:0)
Block(0,3,-4,STAINED_GLASS:11)
Block(1,3,-4,STAINED_GLASS:11)
Block(-3,3,-3,STAINED_GLASS:15)
Block(-2,3,-3,SEA_LANTERN:0)
Block(-1,3,-3,SEA_LANTERN:0)
Block(0,3,-3,STAINED_GLASS:11)
Block(1,3,-3,STAINED_GLASS:11)
Block(-3,3,-2,STAINED_GLASS:15)
Block(-2,3,-2,STAINED_GLASS:15)
Block(-1,3,-2,SEA_LANTERN:0)
Block(0,3,-2,STAINED_GLASS:10)
Block(1,3,-2,STAINED_GLASS:15)
Block(-3,3,-1,STAINED_GLASS:15)
Block(-2,3,-1,STAINED_GLASS:10)
Block(-1,3,-1,SEA_LANTERN:0)
Block(0,3,-1,STAINED_GLASS:10)
Block(1,3,-1,STAINED_GLASS:10)
Block(2,3,-1,STAINED_GLASS:15)
Block(-2,3,0,STAINED_GLASS:15)
Block(-1,3,0,STAINED_GLASS:15)
Block(0,3,0,STAINED_GLASS:15)
Block(1,3,0,STAINED_GLASS:15)
Block(2,3,0,STAINED_GLASS:15)
Block(-1,3,1,STAINED_GLASS:10)
Block(0,3,1,STAINED_GLASS:15)
Block(1,3,1,STAINED_GLASS:15)
Block(2,3,1,STAINED_GLASS:15)
Block(-1,3,2,STAINED_GLASS:15)
Block(0,3,2,STAINED_GLASS:15)
Block(2,3,2,STAINED_GLASS:15)
Block(-6,4,-7,STAINED_GLASS:15)
Block(-5,4,-7,STAINED_GLASS:9)
Block(-4,4,-7,STAINED_GLASS:9)
Block(-3,4,-7,STAINED_GLASS:9)
Block(-2,4,-7,STAINED_GLASS:15)
Block(-1,4,-7,STAINED_GLASS:15)
Block(-5,4,-6,STAINED_GLASS:10)
Block(-4,4,-6,STAINED_GLASS:9)
Block(-3,4,-6,SEA_LANTERN:0)
Block(-2,4,-6,SEA_LANTERN:0)
Block(-1,4,-6,STAINED_GLASS:11)
Block(-4,4,-5,STAINED_GLASS:10)
Block(-3,4,-5,SEA_LANTERN:0)
Block(-2,4,-5,SEA_LANTERN:0)
Block(-1,4,-5,SEA_LANTERN:0)
Block(0,4,-5,STAINED_GLASS:11)
Block(-4,4,-4,STAINED_GLASS:15)
Block(-3,4,-4,STAINED_GLASS:15)
Block(-2,4,-4,SEA_LANTERN:0)
Block(-1,4,-4,STAINED_GLASS:11)
Block(0,4,-4,STAINED_GLASS:11)
Block(1,4,-4,STAINED_GLASS:11)
Block(-3,4,-3,STAINED_GLASS:10)
Block(-2,4,-3,SEA_LANTERN:0)
Block(-1,4,-3,STAINED_GLASS:11)
Block(0,4,-3,STAINED_GLASS:11)
Block(1,4,-3,STAINED_GLASS:11)
Block(-3,4,-2,STAINED_GLASS:15)
Block(-2,4,-2,STAINED_GLASS:10)
Block(-1,4,-2,SEA_LANTERN:0)
Block(0,4,-2,STAINED_GLASS:10)
Block(1,4,-2,STAINED_GLASS:15)
Block(-3,4,-1,STAINED_GLASS:15)
Block(-2,4,-1,STAINED_GLASS:15)
Block(-1,4,-1,STAINED_GLASS:15)
Block(0,4,-1,STAINED_GLASS:15)
Block(1,4,-1,STAINED_GLASS:15)
Block(2,4,-1,STAINED_GLASS:15)
Block(-2,4,0,STAINED_GLASS:15)
Block(-1,4,0,STAINED_GLASS:15)
Block(0,4,0,STAINED_GLASS:15)
Block(-1,4,1,STAINED_GLASS:15)
Block(-6,5,-7,STAINED_GLASS:10)
Block(-5,5,-7,STAINED_GLASS:10)
Block(-4,5,-7,SEA_LANTERN:0)
Block(-3,5,-7,SEA_LANTERN:0)
Block(-2,5,-7,STAINED_GLASS:11)
Block(-1,5,-7,STAINED_GLASS:11)
Block(-5,5,-6,STAINED_GLASS:10)
Block(-4,5,-6,STAINED_GLASS:10)
Block(-3,5,-6,SEA_LANTERN:0)
Block(-2,5,-6,STAINED_GLASS:10)
Block(-1,5,-6,STAINED_GLASS:11)
Block(-4,5,-5,STAINED_GLASS:10)
Block(-3,5,-5,SEA_LANTERN:0)
Block(-2,5,-5,SEA_LANTERN:0)
Block(-1,5,-5,STAINED_GLASS:10)
Block(0,5,-5,STAINED_GLASS:11)
Block(-4,5,-4,STAINED_GLASS:10)
Block(-3,5,-4,STAINED_GLASS:10)
Block(-2,5,-4,STAINED_GLASS:15)
Block(-1,5,-4,STAINED_GLASS:11)
Block(0,5,-4,STAINED_GLASS:11)
Block(1,5,-4,STAINED_GLASS:11)
Block(-3,5,-3,STAINED_GLASS:10)
Block(-2,5,-3,STAINED_GLASS:15)
Block(-1,5,-3,STAINED_GLASS:11)
Block(0,5,-3,STAINED_GLASS:11)
Block(1,5,-3,STAINED_GLASS:11)
Block(-3,5,-2,STAINED_GLASS:15)
Block(-2,5,-2,STAINED_GLASS:15)
Block(-1,5,-2,STAINED_GLASS:15)
Block(0,5,-2,STAINED_GLASS:11)
Block(-3,5,-1,STAINED_GLASS:15)
Block(-6,6,-7,STAINED_GLASS:10)
Block(-5,6,-7,STAINED_GLASS:10)
Block(-4,6,-7,STAINED_GLASS:11)
Block(-3,6,-7,STAINED_GLASS:10)
Block(-2,6,-7,STAINED_GLASS:11)
Block(-1,6,-7,STAINED_GLASS:11)
Block(-5,6,-6,STAINED_GLASS:10)
Block(-4,6,-6,STAINED_GLASS:10)
Block(-3,6,-6,SEA_LANTERN:0)
Block(-2,6,-6,STAINED_GLASS:10)
Block(-1,6,-6,STAINED_GLASS:11)
Block(-4,6,-5,STAINED_GLASS:10)
Block(-3,6,-5,SEA_LANTERN:0)
Block(-2,6,-5,STAINED_GLASS:11)
Block(-1,6,-5,STAINED_GLASS:11)
Block(0,6,-5,STAINED_GLASS:11)
Block(-4,6,-4,STAINED_GLASS:10)
Block(-3,6,-4,STAINED_GLASS:10)
Block(-2,6,-4,STAINED_GLASS:11)
Block(-3,6,-3,STAINED_GLASS:15)
Block(-6,7,-7,STAINED_GLASS:11)
Block(-5,7,-7,STAINED_GLASS:10)
Block(-4,7,-7,STAINED_GLASS:11)
Block(-3,7,-7,STAINED_GLASS:11)
Block(-2,7,-7,STAINED_GLASS:11)
Block(-1,7,-7,STAINED_GLASS:11)
Block(-5,7,-6,STAINED_GLASS:11)
Block(-4,7,-6,STAINED_GLASS:11)
Block(-3,7,-6,STAINED_GLASS:11)
Block(-2,7,-6,STAINED_GLASS:11)
Block(-4,7,-5,STAINED_GLASS:10)
Block(-3,7,-5,STAINED_GLASS:11)
Block(-6,8,-7,STAINED_GLASS:11)
Block(-5,8,-7,STAINED_GLASS:11)
Branch(-16,0,0,spike-IL-20_00-03,NORTH,100)
Branch(0,0,-16,spike-IL-20_01-02,NORTH,100)
