#######################################################################
# +-----------------------------------------------------------------+ #
# |                            BO3 object                           | #
# +-----------------------------------------------------------------+ #
#######################################################################

Author: Bo3 BulkEdit

Description: Converted Schematic - Modified by Bo3BulkEdit

Version: 3

SettingsMode: WriteDisable

#######################################################################
# +-----------------------------------------------------------------+ #
# |                          Main settings                          | #
# +-----------------------------------------------------------------+ #
#######################################################################

IsOTGPlus: true
Tree: false
Frequency: 1
Rarity: 100.0
RotateRandomly: false
SpawnHeight: randomY
MaxBranchDepth: 10
ExcludedBiomes: All

##############################
# Height Limits for the BO3. #
##############################

MinHeight: 0
MaxHeight: 255

#######################################################################
# +-----------------------------------------------------------------+ #
# |                      Source block settings                      | #
# +-----------------------------------------------------------------+ #
#######################################################################

CanOverride: true
MaxPercentageOutsideSourceBlock: 100
OutsideSourceBlock: placeAnyway

#######################################################################
# +-----------------------------------------------------------------+ #
# |                               OTG+                              | #
# +-----------------------------------------------------------------+ #
#######################################################################

BO3Group: CeilingCrystals:0

#######################################################################
# +-----------------------------------------------------------------+ #
# |                              Blocks                             | #
# +-----------------------------------------------------------------+ #
#######################################################################

B(0,750,0,AIR)
B(15,750,15,AIR)
B(15,-22,2,STAINED_GLASS:15)
B(15,-22,3,STAINED_GLASS:15)
B(15,-21,1,STAINED_GLASS:15)
B(15,-21,2,STAINED_GLASS:15)
B(15,-21,3,STAINED_GLASS:15)
B(14,-20,0,STAINED_GLASS:15)
B(15,-20,0,STAINED_GLASS:15)
B(14,-20,1,STAINED_GLASS:15)
B(15,-20,1,STAINED_GLASS:15)
B(14,-20,2,STAINED_GLASS:15)
B(15,-20,2,STAINED_GLASS:15)
B(15,-20,3,STAINED_GLASS:15)
B(13,-19,0,STAINED_GLASS:15)
B(14,-19,0,STAINED_GLASS:15)
B(15,-19,0,STAINED_GLASS:15)
B(13,-19,1,STAINED_GLASS:15)
B(14,-19,1,STAINED_GLASS:15)
B(15,-19,1,STAINED_GLASS:15)
B(14,-19,2,STAINED_GLASS:15)
B(15,-19,2,STAINED_GLASS:15)
B(15,-19,3,STAINED_GLASS:15)
B(12,-18,0,STAINED_GLASS:15)
B(13,-18,0,STAINED_GLASS:15)
B(14,-18,0,STAINED_GLASS:15)
B(15,-18,0,STAINED_GLASS:10)
B(13,-18,1,STAINED_GLASS:15)
B(14,-18,1,STAINED_GLASS:15)
B(15,-18,1,STAINED_GLASS:10)
B(14,-18,2,STAINED_GLASS:15)
B(15,-18,2,STAINED_GLASS:10)
B(15,-18,3,STAINED_GLASS:15)
B(12,-17,0,STAINED_GLASS:15)
B(13,-17,0,STAINED_GLASS:15)
B(14,-17,0,STAINED_GLASS:10)
B(15,-17,0,SEA_LANTERN)
B(13,-17,1,STAINED_GLASS:15)
B(14,-17,1,STAINED_GLASS:10)
B(15,-17,1,SEA_LANTERN)
B(14,-17,2,STAINED_GLASS:15)
B(15,-17,2,STAINED_GLASS:10)
B(15,-17,3,STAINED_GLASS:15)
B(12,-16,0,STAINED_GLASS:15)
B(13,-16,0,STAINED_GLASS:15)
B(14,-16,0,SEA_LANTERN)
B(15,-16,0,SEA_LANTERN)
B(13,-16,1,STAINED_GLASS:15)
B(14,-16,1,STAINED_GLASS:10)
B(15,-16,1,STAINED_GLASS:10)
B(14,-16,2,STAINED_GLASS:15)
B(15,-16,2,STAINED_GLASS:15)
B(15,-16,3,STAINED_GLASS:15)
B(12,-15,0,STAINED_GLASS:15)
B(13,-15,0,STAINED_GLASS:10)
B(14,-15,0,STAINED_GLASS:10)
B(15,-15,0,STAINED_GLASS:10)
B(13,-15,1,STAINED_GLASS:15)
B(14,-15,1,STAINED_GLASS:15)
B(15,-15,1,STAINED_GLASS:15)
B(14,-15,2,STAINED_GLASS:15)
B(15,-15,2,STAINED_GLASS:15)
B(15,-15,3,STAINED_GLASS:15)
B(12,-14,0,STAINED_GLASS:15)
B(13,-14,0,STAINED_GLASS:15)
B(14,-14,0,STAINED_GLASS:10)
B(15,-14,0,STAINED_GLASS:15)
B(13,-14,1,STAINED_GLASS:15)
B(14,-14,1,STAINED_GLASS:15)
B(15,-14,1,STAINED_GLASS:15)
B(14,-14,2,STAINED_GLASS:15)
B(15,-14,2,STAINED_GLASS:15)
B(12,-13,0,STAINED_GLASS:15)
B(13,-13,0,STAINED_GLASS:15)
B(14,-13,0,STAINED_GLASS:15)
B(15,-13,0,STAINED_GLASS:15)
B(13,-13,1,STAINED_GLASS:15)
B(14,-13,1,STAINED_GLASS:15)
B(15,-13,1,STAINED_GLASS:15)
B(12,-12,0,STAINED_GLASS:15)
B(13,-12,0,STAINED_GLASS:15)
B(14,-12,0,STAINED_GLASS:15)
B(15,-12,0,STAINED_GLASS:15)
B(13,-12,1,STAINED_GLASS:15)
B(14,-12,1,STAINED_GLASS:15)
B(12,-11,0,STAINED_GLASS:15)
B(13,-11,0,STAINED_GLASS:15)

#######################################################################
# +-----------------------------------------------------------------+ #
# |                             Branches                            | #
# +-----------------------------------------------------------------+ #
#######################################################################

BR(16,0,0,true,CEILING_SPIKE-THIN-DIAG-MED-02_1x1,NORTH,100,0)
