
#######################################################################
# +-----------------------------------------------------------------+ #
# |                            BO3 object                           | #
# +-----------------------------------------------------------------+ #
#######################################################################

Author: BO3 BulkEdit (by LanToaster)

Description: This Object was Created with BO3_BulkEdit

Version: 3

SettingsMode: WriteWithoutComments


#######################################################################
# +-----------------------------------------------------------------+ #
# |                          Main settings                          | #
# +-----------------------------------------------------------------+ #
#######################################################################

Tree: false

Frequency: 1

Rarity: 100.0

RotateRandomly: false

SpawnHeight: randomY

SpawnHeightOffset: 0

SpawnHeightVariance: 0

##############################
# Height Limits for the BO3. #
##############################

MinHeight: 82

MaxHeight: 82

######################
# Extrusion settings #
######################

ExtrudeMode: None

ExtrudeThroughBlocks: minecraft:air

MaxBranchDepth: 10


#######################################################################
# +-----------------------------------------------------------------+ #
# |                      Source block settings                      | #
# +-----------------------------------------------------------------+ #
#######################################################################

SourceBlocks: otg:air

MaxPercentageOutsideSourceBlock: 100

OutsideSourceBlock: placeAnyway

DoReplaceBlocks: true

IsOTGPlus: false


#######################################################################
# +-----------------------------------------------------------------+ #
# |                              Blocks                             | #
# +-----------------------------------------------------------------+ #
#######################################################################

B(-7,0,2,minecraft:spruce_fence[east=false,north=false,south=true,waterlogged=false,west=false])
B(-7,-10,3,minecraft:jungle_planks)
B(-7,-9,3,minecraft:jungle_planks)
B(-7,-8,3,minecraft:jungle_planks)
B(-7,-7,3,minecraft:jungle_planks)
B(-7,-6,3,minecraft:jungle_planks)
B(-7,-5,3,minecraft:jungle_planks)
B(-7,-4,3,minecraft:jungle_planks)
B(-7,-3,3,minecraft:jungle_planks)
B(-7,-2,3,minecraft:jungle_planks)
B(-7,-1,3,minecraft:jungle_planks)
B(-7,0,3,minecraft:jungle_planks)
B(-7,1,3,minecraft:jungle_planks)
B(-7,2,3,minecraft:jungle_planks)
B(-7,3,3,minecraft:jungle_planks)
B(-7,1,4,minecraft:jungle_slab[type=top,waterlogged=false])
B(-7,1,5,minecraft:jungle_slab[type=top,waterlogged=false])
B(-6,-10,3,minecraft:jungle_log)
B(-6,-9,3,minecraft:jungle_log)
B(-6,-8,3,minecraft:jungle_log)
B(-6,-7,3,minecraft:jungle_log)
B(-6,-6,3,minecraft:jungle_log)
B(-6,-5,3,minecraft:jungle_log)
B(-6,-4,3,minecraft:jungle_log)
B(-6,-3,3,minecraft:jungle_log)
B(-6,-2,3,minecraft:jungle_log)
B(-6,-1,3,minecraft:jungle_log)
B(-6,0,3,minecraft:jungle_log)
B(-6,1,3,minecraft:jungle_log)
B(-6,2,3,minecraft:jungle_log)
B(-6,3,3,minecraft:jungle_log)
B(-6,4,3,minecraft:jungle_log)
B(-6,1,4,minecraft:jungle_log[axis=z])
B(-6,2,4,minecraft:jungle_slab)
B(-6,1,5,minecraft:jungle_log[axis=z])
B(-6,2,5,minecraft:jungle_slab)
B(-6,1,6,minecraft:jungle_log[axis=z])
B(-6,2,6,minecraft:jungle_slab)
B(-6,-10,7,minecraft:jungle_log)
B(-6,-9,7,minecraft:jungle_log)
B(-6,-8,7,minecraft:jungle_log)
B(-6,-7,7,minecraft:jungle_log)
B(-6,-6,7,minecraft:jungle_log)
B(-6,-5,7,minecraft:jungle_log)
B(-6,-4,7,minecraft:jungle_log)
B(-6,-3,7,minecraft:jungle_log)
B(-6,-2,7,minecraft:jungle_log)
B(-6,-1,7,minecraft:jungle_log)
B(-6,0,7,minecraft:jungle_log)
B(-6,1,7,minecraft:jungle_log[axis=z])
B(-5,0,3,minecraft:spruce_fence[east=false,north=false,south=true,waterlogged=false,west=true])
B(-5,1,3,minecraft:spruce_fence[east=false,north=false,south=true,waterlogged=false,west=true])
B(-5,-10,4,minecraft:jungle_planks)
B(-5,-9,4,minecraft:jungle_planks)
B(-5,-8,4,minecraft:jungle_planks)
B(-5,-7,4,minecraft:jungle_planks)
B(-5,-6,4,minecraft:jungle_planks)
B(-5,-5,4,minecraft:jungle_planks)
B(-5,-4,4,minecraft:jungle_planks)
B(-5,-3,4,minecraft:jungle_planks)
B(-5,-2,4,minecraft:jungle_planks)
B(-5,-1,4,minecraft:jungle_planks)
B(-5,0,4,minecraft:jungle_planks)
B(-5,1,4,minecraft:jungle_planks)
B(-5,2,4,minecraft:jungle_planks)
B(-5,3,4,minecraft:jungle_planks)
B(-5,1,5,minecraft:jungle_slab[type=top,waterlogged=false])
B(-5,1,6,minecraft:jungle_stairs[facing=south,half=top,shape=straight,waterlogged=false])
B(-5,0,7,minecraft:jungle_stairs[facing=south,half=top,shape=straight,waterlogged=false])
B(-5,1,7,minecraft:jungle_stairs)
B(-5,0,8,minecraft:jungle_stairs)
B(-4,0,4,minecraft:spruce_fence[east=false,north=false,south=true,waterlogged=false,west=true])
B(-4,-10,5,minecraft:jungle_planks)
B(-4,-9,5,minecraft:jungle_planks)
B(-4,-8,5,minecraft:jungle_planks)
B(-4,-7,5,minecraft:jungle_planks)
B(-4,-6,5,minecraft:jungle_planks)
B(-4,-5,5,minecraft:jungle_planks)
B(-4,-4,5,minecraft:jungle_planks)
B(-4,-3,5,minecraft:jungle_planks)
B(-4,-2,5,minecraft:jungle_planks)
B(-4,-1,5,minecraft:jungle_planks)
B(-4,0,5,minecraft:jungle_planks)
B(-4,1,5,minecraft:jungle_planks)
B(-4,2,5,minecraft:jungle_planks)
B(-4,3,5,minecraft:spruce_fence)
B(-4,1,6,minecraft:jungle_slab[type=top,waterlogged=false])
B(-3,-10,5,minecraft:jungle_planks)
B(-3,-9,5,minecraft:jungle_planks)
B(-3,-8,5,minecraft:jungle_planks)
B(-3,-7,5,minecraft:jungle_planks)
B(-3,-6,5,minecraft:jungle_planks)
B(-3,-5,5,minecraft:jungle_planks)
B(-3,-4,5,minecraft:jungle_planks)
B(-3,-3,5,minecraft:jungle_planks)
B(-3,-2,5,minecraft:jungle_planks)
B(-3,-1,5,minecraft:jungle_planks)
B(-3,0,5,minecraft:jungle_planks)
B(-3,1,5,minecraft:jungle_planks)
B(-3,2,5,minecraft:spruce_fence[east=false,north=false,south=false,waterlogged=false,west=true])
B(-3,1,6,minecraft:jungle_slab[type=top,waterlogged=false])
B(-3,1,7,minecraft:jungle_slab[type=top,waterlogged=false])
B(-2,0,5,minecraft:spruce_fence[east=true,north=false,south=true,waterlogged=false,west=true])
B(-2,1,5,minecraft:spruce_fence[east=true,north=false,south=true,waterlogged=false,west=true])
B(-2,-10,6,minecraft:jungle_planks)
B(-2,-9,6,minecraft:jungle_planks)
B(-2,-8,6,minecraft:jungle_planks)
B(-2,-7,6,minecraft:jungle_planks)
B(-2,-6,6,minecraft:jungle_planks)
B(-2,-5,6,minecraft:jungle_planks)
B(-2,-4,6,minecraft:jungle_planks)
B(-2,-3,6,minecraft:jungle_planks)
B(-2,-2,6,minecraft:jungle_planks)
B(-2,-1,6,minecraft:jungle_planks)
B(-2,0,6,minecraft:jungle_planks)
B(-2,1,6,minecraft:jungle_planks)
B(-2,2,6,minecraft:spruce_fence)
B(-2,1,7,minecraft:jungle_slab[type=top,waterlogged=false])
B(-1,0,4,minecraft:spruce_fence[east=false,north=false,south=true,waterlogged=false,west=false])
B(-1,-10,5,minecraft:jungle_planks)
B(-1,-9,5,minecraft:jungle_planks)
B(-1,-8,5,minecraft:jungle_planks)
B(-1,-7,5,minecraft:jungle_planks)
B(-1,-6,5,minecraft:jungle_planks)
B(-1,-5,5,minecraft:jungle_planks)
B(-1,-4,5,minecraft:jungle_planks)
B(-1,-3,5,minecraft:jungle_planks)
B(-1,-2,5,minecraft:jungle_planks)
B(-1,-1,5,minecraft:jungle_planks)
B(-1,0,5,minecraft:jungle_planks)
B(-1,1,5,minecraft:jungle_planks)
B(-1,2,5,minecraft:spruce_fence[east=true,north=false,south=false,waterlogged=false,west=false])
B(-1,1,6,minecraft:jungle_slab[type=top,waterlogged=false])
B(-1,1,7,minecraft:jungle_slab[type=top,waterlogged=false])
B(0,-10,5,minecraft:jungle_planks)
B(0,-9,5,minecraft:jungle_planks)
B(0,-8,5,minecraft:jungle_planks)
B(0,-7,5,minecraft:jungle_planks)
B(0,-6,5,minecraft:jungle_planks)
B(0,-5,5,minecraft:jungle_planks)
B(0,-4,5,minecraft:jungle_planks)
B(0,-3,5,minecraft:jungle_planks)
B(0,-2,5,minecraft:jungle_planks)
B(0,-1,5,minecraft:jungle_planks)
B(0,0,5,minecraft:jungle_planks)
B(0,1,5,minecraft:jungle_planks)
B(0,2,5,minecraft:jungle_planks)
B(0,3,5,minecraft:spruce_fence[east=true,north=false,south=false,waterlogged=false,west=false])
B(0,1,6,minecraft:jungle_slab[type=top,waterlogged=false])
B(0,2,6,minecraft:jungle_slab)
B(0,-10,7,minecraft:jungle_log)
B(0,-9,7,minecraft:jungle_log)
B(0,-8,7,minecraft:jungle_log)
B(0,-7,7,minecraft:jungle_log)
B(0,-6,7,minecraft:jungle_log)
B(0,-5,7,minecraft:jungle_log)
B(0,-4,7,minecraft:jungle_log)
B(0,-3,7,minecraft:jungle_log)
B(0,-2,7,minecraft:jungle_log)
B(0,-1,7,minecraft:jungle_log)
B(0,0,7,minecraft:jungle_log)
B(0,1,7,minecraft:jungle_log[axis=x])
B(1,0,4,minecraft:spruce_fence[east=false,north=false,south=true,waterlogged=false,west=false])
B(1,-10,5,minecraft:jungle_planks)
B(1,-9,5,minecraft:jungle_planks)
B(1,-8,5,minecraft:jungle_planks)
B(1,-7,5,minecraft:jungle_planks)
B(1,-6,5,minecraft:jungle_planks)
B(1,-5,5,minecraft:jungle_planks)
B(1,-4,5,minecraft:jungle_planks)
B(1,-3,5,minecraft:jungle_planks)
B(1,-2,5,minecraft:jungle_planks)
B(1,-1,5,minecraft:jungle_planks)
B(1,0,5,minecraft:jungle_planks)
B(1,1,5,minecraft:jungle_planks)
B(1,2,5,minecraft:jungle_planks)
B(1,3,5,minecraft:jungle_planks)
B(1,2,6,minecraft:jungle_slab)
B(1,1,7,minecraft:jungle_log[axis=x])
B(1,2,7,minecraft:jungle_slab)
B(2,0,5,minecraft:spruce_fence[east=false,north=false,south=true,waterlogged=false,west=true])
B(2,-10,6,minecraft:jungle_planks)
B(2,-9,6,minecraft:jungle_planks)
B(2,-8,6,minecraft:jungle_planks)
B(2,-7,6,minecraft:jungle_planks)
B(2,-6,6,minecraft:jungle_planks)
B(2,-5,6,minecraft:jungle_planks)
B(2,-4,6,minecraft:jungle_planks)
B(2,-3,6,minecraft:jungle_planks)
B(2,-2,6,minecraft:jungle_planks)
B(2,-1,6,minecraft:jungle_planks)
B(2,0,6,minecraft:jungle_planks)
B(2,1,6,minecraft:jungle_planks)
B(2,2,6,minecraft:jungle_planks)
B(2,3,6,minecraft:jungle_planks)
B(2,1,7,minecraft:jungle_log[axis=x])
B(2,2,7,minecraft:jungle_slab)
B(3,0,6,minecraft:spruce_fence[east=false,north=false,south=true,waterlogged=false,west=true])
B(3,-10,7,minecraft:jungle_log)
B(3,-9,7,minecraft:jungle_log)
B(3,-8,7,minecraft:jungle_log)
B(3,-7,7,minecraft:jungle_log)
B(3,-6,7,minecraft:jungle_log)
B(3,-5,7,minecraft:jungle_log)
B(3,-4,7,minecraft:jungle_log)
B(3,-3,7,minecraft:jungle_log)
B(3,-2,7,minecraft:jungle_log)
B(3,-1,7,minecraft:jungle_log)
B(3,0,7,minecraft:jungle_log)
B(3,1,7,minecraft:jungle_log)
B(3,2,7,minecraft:jungle_log)
B(3,3,7,minecraft:jungle_log)
B(3,4,7,minecraft:jungle_log)
B(4,0,7,minecraft:spruce_fence[east=false,north=false,south=false,waterlogged=false,west=true])
B(5,-1,8,minecraft:grass_path)
B(6,-1,8,minecraft:grass_path)
B(7,-1,8,minecraft:grass_path)
RB(-6,4,2,minecraft:white_wall_banner,../JungleNBT/banners/JungleBanner01.nbt,8,minecraft:white_wall_banner,../JungleNBT/banners/JungleBanner02.nbt,8,minecraft:white_wall_banner,../JungleNBT/banners/JungleBanner03.nbt,8,minecraft:white_wall_banner,../JungleNBT/banners/JungleBanner04.nbt,8,minecraft:white_wall_banner,../JungleNBT/banners/JungleBanner05.nbt,8,minecraft:white_wall_banner,../JungleNBT/banners/JungleBanner06.nbt,8,minecraft:white_wall_banner,../JungleNBT/banners/JungleBanner07.nbt,8,minecraft:white_wall_banner,../JungleNBT/banners/JungleBanner08.nbt,8,minecraft:white_wall_banner,../JungleNBT/banners/JungleBanner09.nbt,8,minecraft:white_wall_banner,../JungleNBT/banners/JungleBanner10.nbt,8,minecraft:white_wall_banner,../JungleNBT/banners/JungleBanner11.nbt,8,minecraft:white_wall_banner,../JungleNBT/banners/JungleBanner12.nbt,8,minecraft:white_wall_banner,../JungleNBT/banners/JungleBanner13.nbt,8,minecraft:white_wall_banner,../JungleNBT/banners/JungleBanner14.nbt,8,minecraft:white_wall_banner,../JungleNBT/banners/JungleBanner15.nbt,8,minecraft:white_wall_banner,../JungleNBT/banners/JungleBanner16.nbt,8,minecraft:white_wall_banner,../JungleNBT/banners/JungleBanner17.nbt,8,minecraft:white_wall_banner,../JungleNBT/banners/JungleBanner18.nbt,8,minecraft:white_wall_banner,../JungleNBT/banners/JungleBanner19.nbt,8,minecraft:white_wall_banner,../JungleNBT/banners/JungleBanner20.nbt,100)
RB(-5,4,3,minecraft:white_wall_banner[facing=east],../JungleNBT/banners/JungleBanner01.nbt,8,minecraft:white_wall_banner[facing=east],../JungleNBT/banners/JungleBanner02.nbt,8,minecraft:white_wall_banner[facing=east],../JungleNBT/banners/JungleBanner03.nbt,8,minecraft:white_wall_banner[facing=east],../JungleNBT/banners/JungleBanner04.nbt,8,minecraft:white_wall_banner[facing=east],../JungleNBT/banners/JungleBanner05.nbt,8,minecraft:white_wall_banner[facing=east],../JungleNBT/banners/JungleBanner06.nbt,8,minecraft:white_wall_banner[facing=east],../JungleNBT/banners/JungleBanner07.nbt,8,minecraft:white_wall_banner[facing=east],../JungleNBT/banners/JungleBanner08.nbt,8,minecraft:white_wall_banner[facing=east],../JungleNBT/banners/JungleBanner09.nbt,8,minecraft:white_wall_banner[facing=east],../JungleNBT/banners/JungleBanner10.nbt,8,minecraft:white_wall_banner[facing=east],../JungleNBT/banners/JungleBanner11.nbt,8,minecraft:white_wall_banner[facing=east],../JungleNBT/banners/JungleBanner12.nbt,8,minecraft:white_wall_banner[facing=east],../JungleNBT/banners/JungleBanner13.nbt,8,minecraft:white_wall_banner[facing=east],../JungleNBT/banners/JungleBanner14.nbt,8,minecraft:white_wall_banner[facing=east],../JungleNBT/banners/JungleBanner15.nbt,8,minecraft:white_wall_banner[facing=east],../JungleNBT/banners/JungleBanner16.nbt,8,minecraft:white_wall_banner[facing=east],../JungleNBT/banners/JungleBanner17.nbt,8,minecraft:white_wall_banner[facing=east],../JungleNBT/banners/JungleBanner18.nbt,8,minecraft:white_wall_banner[facing=east],../JungleNBT/banners/JungleBanner19.nbt,8,minecraft:white_wall_banner[facing=east],../JungleNBT/banners/JungleBanner20.nbt,100)
RB(3,4,6,minecraft:white_wall_banner,../JungleNBT/banners/JungleBanner01.nbt,8,minecraft:white_wall_banner,../JungleNBT/banners/JungleBanner02.nbt,8,minecraft:white_wall_banner,../JungleNBT/banners/JungleBanner03.nbt,8,minecraft:white_wall_banner,../JungleNBT/banners/JungleBanner04.nbt,8,minecraft:white_wall_banner,../JungleNBT/banners/JungleBanner05.nbt,8,minecraft:white_wall_banner,../JungleNBT/banners/JungleBanner06.nbt,8,minecraft:white_wall_banner,../JungleNBT/banners/JungleBanner07.nbt,8,minecraft:white_wall_banner,../JungleNBT/banners/JungleBanner08.nbt,8,minecraft:white_wall_banner,../JungleNBT/banners/JungleBanner09.nbt,8,minecraft:white_wall_banner,../JungleNBT/banners/JungleBanner10.nbt,8,minecraft:white_wall_banner,../JungleNBT/banners/JungleBanner11.nbt,8,minecraft:white_wall_banner,../JungleNBT/banners/JungleBanner12.nbt,8,minecraft:white_wall_banner,../JungleNBT/banners/JungleBanner13.nbt,8,minecraft:white_wall_banner,../JungleNBT/banners/JungleBanner14.nbt,8,minecraft:white_wall_banner,../JungleNBT/banners/JungleBanner15.nbt,8,minecraft:white_wall_banner,../JungleNBT/banners/JungleBanner16.nbt,8,minecraft:white_wall_banner,../JungleNBT/banners/JungleBanner17.nbt,8,minecraft:white_wall_banner,../JungleNBT/banners/JungleBanner18.nbt,8,minecraft:white_wall_banner,../JungleNBT/banners/JungleBanner19.nbt,8,minecraft:white_wall_banner,../JungleNBT/banners/JungleBanner20.nbt,100)
RB(4,4,7,minecraft:white_wall_banner[facing=east],../JungleNBT/banners/JungleBanner01.nbt,8,minecraft:white_wall_banner[facing=east],../JungleNBT/banners/JungleBanner02.nbt,8,minecraft:white_wall_banner[facing=east],../JungleNBT/banners/JungleBanner03.nbt,8,minecraft:white_wall_banner[facing=east],../JungleNBT/banners/JungleBanner04.nbt,8,minecraft:white_wall_banner[facing=east],../JungleNBT/banners/JungleBanner05.nbt,8,minecraft:white_wall_banner[facing=east],../JungleNBT/banners/JungleBanner06.nbt,8,minecraft:white_wall_banner[facing=east],../JungleNBT/banners/JungleBanner07.nbt,8,minecraft:white_wall_banner[facing=east],../JungleNBT/banners/JungleBanner08.nbt,8,minecraft:white_wall_banner[facing=east],../JungleNBT/banners/JungleBanner09.nbt,8,minecraft:white_wall_banner[facing=east],../JungleNBT/banners/JungleBanner10.nbt,8,minecraft:white_wall_banner[facing=east],../JungleNBT/banners/JungleBanner11.nbt,8,minecraft:white_wall_banner[facing=east],../JungleNBT/banners/JungleBanner12.nbt,8,minecraft:white_wall_banner[facing=east],../JungleNBT/banners/JungleBanner13.nbt,8,minecraft:white_wall_banner[facing=east],../JungleNBT/banners/JungleBanner14.nbt,8,minecraft:white_wall_banner[facing=east],../JungleNBT/banners/JungleBanner15.nbt,8,minecraft:white_wall_banner[facing=east],../JungleNBT/banners/JungleBanner16.nbt,8,minecraft:white_wall_banner[facing=east],../JungleNBT/banners/JungleBanner17.nbt,8,minecraft:white_wall_banner[facing=east],../JungleNBT/banners/JungleBanner18.nbt,8,minecraft:white_wall_banner[facing=east],../JungleNBT/banners/JungleBanner19.nbt,8,minecraft:white_wall_banner[facing=east],../JungleNBT/banners/JungleBanner20.nbt,100)

#######################################################################
# +-----------------------------------------------------------------+ #
# |                            BO3 checks                           | #
# +-----------------------------------------------------------------+ #
#######################################################################


#######################################################################
# +-----------------------------------------------------------------+ #
# |                             Branches                            | #
# +-----------------------------------------------------------------+ #
#######################################################################

Branch(0,0,-16,JungleVillagePath01_07-00,NORTH,100.0)

#######################################################################
# +-----------------------------------------------------------------+ #
# |                             Entities                            | #
# +-----------------------------------------------------------------+ #
#######################################################################

