#######################################################################
# +-----------------------------------------------------------------+ #
# |                            BO3 object                           | #
# +-----------------------------------------------------------------+ #
#######################################################################

Author: Bo3 BulkEdit

Description: Converted Schematic - Modified by Bo3BulkEdit

Version: 3

SettingsMode: WriteDisable

#######################################################################
# +-----------------------------------------------------------------+ #
# |                          Main settings                          | #
# +-----------------------------------------------------------------+ #
#######################################################################

IsOTGPlus: true
Tree: false
Frequency: 1
Rarity: 100.0
RotateRandomly: false
SpawnHeight: randomY
MaxBranchDepth: 10
ExcludedBiomes: All

##############################
# Height Limits for the BO3. #
##############################

MinHeight: 0
MaxHeight: 255

#######################################################################
# +-----------------------------------------------------------------+ #
# |                      Source block settings                      | #
# +-----------------------------------------------------------------+ #
#######################################################################

CanOverride: true
MaxPercentageOutsideSourceBlock: 100
OutsideSourceBlock: placeAnyway

#######################################################################
# +-----------------------------------------------------------------+ #
# |                               OTG+                              | #
# +-----------------------------------------------------------------+ #
#######################################################################

BO3Group: CeilingCrystals:0

#######################################################################
# +-----------------------------------------------------------------+ #
# |                              Blocks                             | #
# +-----------------------------------------------------------------+ #
#######################################################################

B(0,750,0,AIR)
B(15,750,15,AIR)
B(15,-31,3,STAINED_GLASS:10)
B(15,-31,4,STAINED_GLASS:10)
B(15,-31,5,STAINED_GLASS:15)
B(15,-31,6,STAINED_GLASS:15)
B(14,-30,3,STAINED_GLASS:10)
B(15,-30,3,STAINED_GLASS:10)
B(15,-30,4,STAINED_GLASS:15)
B(13,-30,5,STAINED_GLASS:15)
B(14,-30,5,STAINED_GLASS:15)
B(15,-30,5,STAINED_GLASS:15)
B(14,-30,6,STAINED_GLASS:15)
B(15,-30,6,STAINED_GLASS:15)
B(15,-30,7,STAINED_GLASS:15)
B(15,-30,8,STAINED_GLASS:15)
B(15,-29,0,STAINED_GLASS:15)
B(13,-29,1,STAINED_GLASS:9)
B(15,-29,1,STAINED_GLASS:15)
B(13,-29,2,STAINED_GLASS:15)
B(14,-29,2,STAINED_GLASS:15)
B(15,-29,2,STAINED_GLASS:15)
B(12,-29,3,STAINED_GLASS:15)
B(13,-29,3,STAINED_GLASS:15)
B(14,-29,3,STAINED_GLASS:15)
B(15,-29,3,STAINED_GLASS:15)
B(11,-29,4,STAINED_GLASS:15)
B(12,-29,4,STAINED_GLASS:15)
B(13,-29,4,STAINED_GLASS:15)
B(14,-29,4,STAINED_GLASS:15)
B(15,-29,4,STAINED_GLASS:15)
B(12,-29,5,STAINED_GLASS:15)
B(13,-29,5,STAINED_GLASS:15)
B(14,-29,5,STAINED_GLASS:15)
B(15,-29,5,STAINED_GLASS:15)
B(13,-29,6,STAINED_GLASS:15)
B(14,-29,6,STAINED_GLASS:15)
B(15,-29,6,STAINED_GLASS:15)
B(13,-29,7,STAINED_GLASS:15)
B(14,-29,7,STAINED_GLASS:15)
B(15,-29,7,STAINED_GLASS:15)
B(14,-29,8,STAINED_GLASS:15)
B(15,-29,8,STAINED_GLASS:15)
B(12,-28,0,STAINED_GLASS:15)
B(13,-28,0,STAINED_GLASS:15)
B(14,-28,0,STAINED_GLASS:15)
B(10,-28,1,STAINED_GLASS:15)
B(12,-28,1,STAINED_GLASS:15)
B(13,-28,1,STAINED_GLASS:15)
B(14,-28,1,STAINED_GLASS:15)
B(15,-28,1,STAINED_GLASS:15)
B(11,-28,2,STAINED_GLASS:15)
B(12,-28,2,STAINED_GLASS:15)
B(13,-28,2,STAINED_GLASS:15)
B(14,-28,2,STAINED_GLASS:15)
B(15,-28,2,SEA_LANTERN)
B(10,-28,3,STAINED_GLASS:15)
B(11,-28,3,STAINED_GLASS:15)
B(12,-28,3,STAINED_GLASS:15)
B(13,-28,3,STAINED_GLASS:15)
B(14,-28,3,SEA_LANTERN)
B(15,-28,3,SEA_LANTERN)
B(11,-28,4,STAINED_GLASS:15)
B(12,-28,4,STAINED_GLASS:15)
B(13,-28,4,STAINED_GLASS:15)
B(14,-28,4,SEA_LANTERN)
B(15,-28,4,SEA_LANTERN)
B(11,-28,5,STAINED_GLASS:15)
B(12,-28,5,STAINED_GLASS:15)
B(13,-28,5,STAINED_GLASS:15)
B(14,-28,5,STAINED_GLASS:15)
B(15,-28,5,STAINED_GLASS:15)
B(11,-28,6,STAINED_GLASS:15)
B(12,-28,6,STAINED_GLASS:15)
B(13,-28,6,STAINED_GLASS:15)
B(14,-28,6,STAINED_GLASS:10)
B(15,-28,6,STAINED_GLASS:10)
B(12,-28,7,STAINED_GLASS:15)
B(13,-28,7,STAINED_GLASS:15)
B(14,-28,7,STAINED_GLASS:15)
B(15,-28,7,STAINED_GLASS:15)
B(14,-28,8,STAINED_GLASS:15)
B(15,-28,8,STAINED_GLASS:15)
B(9,-27,0,STAINED_GLASS:15)
B(10,-27,0,STAINED_GLASS:15)
B(11,-27,0,STAINED_GLASS:15)
B(12,-27,0,STAINED_GLASS:15)
B(13,-27,0,STAINED_GLASS:15)
B(14,-27,0,STAINED_GLASS:10)
B(15,-27,0,STAINED_GLASS:10)
B(9,-27,1,STAINED_GLASS:15)
B(10,-27,1,STAINED_GLASS:11)
B(11,-27,1,STAINED_GLASS:15)
B(12,-27,1,STAINED_GLASS:15)
B(13,-27,1,STAINED_GLASS:10)
B(14,-27,1,STAINED_GLASS:10)
B(15,-27,1,STAINED_GLASS:10)
B(10,-27,2,STAINED_GLASS:15)
B(11,-27,2,STAINED_GLASS:11)
B(12,-27,2,STAINED_GLASS:10)
B(13,-27,2,STAINED_GLASS:10)
B(14,-27,2,SEA_LANTERN)
B(15,-27,2,SEA_LANTERN)
B(10,-27,3,STAINED_GLASS:15)
B(11,-27,3,STAINED_GLASS:15)
B(12,-27,3,STAINED_GLASS:15)
B(13,-27,3,STAINED_GLASS:10)
B(14,-27,3,SEA_LANTERN)
B(15,-27,3,SEA_LANTERN)
B(10,-27,4,STAINED_GLASS:15)
B(11,-27,4,STAINED_GLASS:15)
B(12,-27,4,STAINED_GLASS:15)
B(13,-27,4,STAINED_GLASS:15)
B(14,-27,4,STAINED_GLASS:10)
B(15,-27,4,SEA_LANTERN)
B(10,-27,5,STAINED_GLASS:15)
B(11,-27,5,STAINED_GLASS:15)
B(12,-27,5,STAINED_GLASS:11)
B(13,-27,5,STAINED_GLASS:10)
B(14,-27,5,STAINED_GLASS:10)
B(15,-27,5,STAINED_GLASS:10)
B(11,-27,6,STAINED_GLASS:15)
B(12,-27,6,STAINED_GLASS:15)
B(13,-27,6,STAINED_GLASS:11)
B(14,-27,6,STAINED_GLASS:11)
B(15,-27,6,STAINED_GLASS:11)
B(12,-27,7,STAINED_GLASS:15)
B(13,-27,7,STAINED_GLASS:15)
B(14,-27,7,STAINED_GLASS:15)
B(15,-27,7,STAINED_GLASS:15)
B(8,-26,0,STAINED_GLASS:15)
B(9,-26,0,STAINED_GLASS:11)
B(10,-26,0,STAINED_GLASS:11)
B(11,-26,0,STAINED_GLASS:15)
B(12,-26,0,STAINED_GLASS:11)
B(13,-26,0,STAINED_GLASS:10)
B(14,-26,0,STAINED_GLASS:10)
B(15,-26,0,STAINED_GLASS:10)
B(9,-26,1,STAINED_GLASS:9)
B(10,-26,1,STAINED_GLASS:9)
B(11,-26,1,STAINED_GLASS:11)
B(12,-26,1,STAINED_GLASS:10)
B(13,-26,1,STAINED_GLASS:10)
B(14,-26,1,SEA_LANTERN)
B(15,-26,1,STAINED_GLASS:10)
B(10,-26,2,STAINED_GLASS:11)
B(11,-26,2,STAINED_GLASS:15)
B(12,-26,2,STAINED_GLASS:10)
B(13,-26,2,SEA_LANTERN)
B(14,-26,2,SEA_LANTERN)
B(15,-26,2,SEA_LANTERN)
B(10,-26,3,STAINED_GLASS:9)
B(11,-26,3,STAINED_GLASS:15)
B(12,-26,3,STAINED_GLASS:15)
B(13,-26,3,STAINED_GLASS:10)
B(14,-26,3,SEA_LANTERN)
B(15,-26,3,SEA_LANTERN)
B(10,-26,4,STAINED_GLASS:9)
B(11,-26,4,STAINED_GLASS:9)
B(12,-26,4,STAINED_GLASS:11)
B(13,-26,4,STAINED_GLASS:10)
B(14,-26,4,STAINED_GLASS:10)
B(15,-26,4,STAINED_GLASS:10)
B(10,-26,5,STAINED_GLASS:15)
B(11,-26,5,STAINED_GLASS:11)
B(12,-26,5,STAINED_GLASS:11)
B(13,-26,5,STAINED_GLASS:10)
B(14,-26,5,STAINED_GLASS:11)
B(15,-26,5,STAINED_GLASS:11)
B(11,-26,6,STAINED_GLASS:15)
B(12,-26,6,STAINED_GLASS:9)
B(13,-26,6,STAINED_GLASS:11)
B(14,-26,6,STAINED_GLASS:9)
B(15,-26,6,STAINED_GLASS:11)
B(13,-26,7,STAINED_GLASS:9)
B(15,-26,7,STAINED_GLASS:15)
B(8,-25,0,STAINED_GLASS:15)
B(9,-25,0,STAINED_GLASS:15)
B(10,-25,0,STAINED_GLASS:15)
B(11,-25,0,STAINED_GLASS:11)
B(12,-25,0,STAINED_GLASS:10)
B(13,-25,0,STAINED_GLASS:10)
B(14,-25,0,STAINED_GLASS:10)
B(15,-25,0,STAINED_GLASS:10)
B(9,-25,1,STAINED_GLASS:9)
B(10,-25,1,STAINED_GLASS:11)
B(11,-25,1,STAINED_GLASS:10)
B(12,-25,1,STAINED_GLASS:10)
B(13,-25,1,SEA_LANTERN)
B(14,-25,1,SEA_LANTERN)
B(15,-25,1,STAINED_GLASS:10)
B(9,-25,2,STAINED_GLASS:9)
B(10,-25,2,STAINED_GLASS:15)
B(11,-25,2,STAINED_GLASS:15)
B(12,-25,2,STAINED_GLASS:10)
B(13,-25,2,SEA_LANTERN)
B(14,-25,2,SEA_LANTERN)
B(15,-25,2,STAINED_GLASS:10)
B(10,-25,3,STAINED_GLASS:9)
B(11,-25,3,STAINED_GLASS:11)
B(12,-25,3,STAINED_GLASS:10)
B(13,-25,3,STAINED_GLASS:10)
B(14,-25,3,STAINED_GLASS:10)
B(15,-25,3,STAINED_GLASS:10)
B(10,-25,4,STAINED_GLASS:9)
B(11,-25,4,STAINED_GLASS:11)
B(12,-25,4,STAINED_GLASS:11)
B(13,-25,4,STAINED_GLASS:10)
B(14,-25,4,STAINED_GLASS:10)
B(15,-25,4,STAINED_GLASS:10)
B(10,-25,5,STAINED_GLASS:15)
B(11,-25,5,STAINED_GLASS:11)
B(12,-25,5,STAINED_GLASS:11)
B(13,-25,5,STAINED_GLASS:11)
B(14,-25,5,STAINED_GLASS:9)
B(15,-25,5,STAINED_GLASS:11)
B(11,-25,6,STAINED_GLASS:15)
B(12,-25,6,STAINED_GLASS:9)
B(13,-25,6,STAINED_GLASS:9)
B(15,-25,6,STAINED_GLASS:15)
B(8,-24,0,STAINED_GLASS:15)
B(9,-24,0,STAINED_GLASS:11)
B(10,-24,0,STAINED_GLASS:11)
B(11,-24,0,STAINED_GLASS:10)
B(12,-24,0,STAINED_GLASS:10)
B(13,-24,0,SEA_LANTERN)
B(14,-24,0,STAINED_GLASS:10)
B(15,-24,0,STAINED_GLASS:10)
B(9,-24,1,STAINED_GLASS:9)
B(10,-24,1,STAINED_GLASS:10)
B(11,-24,1,STAINED_GLASS:10)
B(12,-24,1,SEA_LANTERN)
B(13,-24,1,SEA_LANTERN)
B(14,-24,1,SEA_LANTERN)
B(15,-24,1,STAINED_GLASS:10)
B(9,-24,2,STAINED_GLASS:9)
B(10,-24,2,STAINED_GLASS:11)
B(11,-24,2,STAINED_GLASS:10)
B(12,-24,2,STAINED_GLASS:10)
B(13,-24,2,SEA_LANTERN)
B(14,-24,2,STAINED_GLASS:10)
B(15,-24,2,STAINED_GLASS:10)
B(10,-24,3,STAINED_GLASS:9)
B(11,-24,3,STAINED_GLASS:11)
B(12,-24,3,STAINED_GLASS:10)
B(13,-24,3,STAINED_GLASS:10)
B(14,-24,3,STAINED_GLASS:10)
B(15,-24,3,STAINED_GLASS:10)
B(10,-24,4,STAINED_GLASS:15)
B(11,-24,4,STAINED_GLASS:11)
B(12,-24,4,STAINED_GLASS:11)
B(13,-24,4,STAINED_GLASS:10)
B(14,-24,4,STAINED_GLASS:11)
B(15,-24,4,STAINED_GLASS:11)
B(10,-24,5,STAINED_GLASS:15)
B(11,-24,5,STAINED_GLASS:15)
B(12,-24,5,STAINED_GLASS:11)
B(13,-24,5,STAINED_GLASS:9)
B(14,-24,5,STAINED_GLASS:9)
B(15,-24,5,STAINED_GLASS:15)
B(12,-24,6,STAINED_GLASS:9)
B(8,-23,0,STAINED_GLASS:9)
B(9,-23,0,STAINED_GLASS:11)
B(10,-23,0,STAINED_GLASS:10)
B(11,-23,0,STAINED_GLASS:10)
B(12,-23,0,SEA_LANTERN)
B(13,-23,0,SEA_LANTERN)
B(14,-23,0,STAINED_GLASS:10)
B(15,-23,0,STAINED_GLASS:10)
B(8,-23,1,STAINED_GLASS:9)
B(9,-23,1,STAINED_GLASS:9)
B(10,-23,1,STAINED_GLASS:10)
B(11,-23,1,STAINED_GLASS:10)
B(12,-23,1,SEA_LANTERN)
B(13,-23,1,SEA_LANTERN)
B(14,-23,1,STAINED_GLASS:10)
B(15,-23,1,STAINED_GLASS:10)
B(9,-23,2,STAINED_GLASS:15)
B(10,-23,2,STAINED_GLASS:11)
B(11,-23,2,STAINED_GLASS:10)
B(12,-23,2,STAINED_GLASS:10)
B(13,-23,2,STAINED_GLASS:10)
B(14,-23,2,STAINED_GLASS:10)
B(15,-23,2,STAINED_GLASS:11)
B(10,-23,3,STAINED_GLASS:11)
B(11,-23,3,STAINED_GLASS:11)
B(12,-23,3,STAINED_GLASS:10)
B(13,-23,3,STAINED_GLASS:10)
B(14,-23,3,STAINED_GLASS:11)
B(15,-23,3,STAINED_GLASS:11)
B(10,-23,4,STAINED_GLASS:15)
B(11,-23,4,STAINED_GLASS:11)
B(12,-23,4,STAINED_GLASS:11)
B(13,-23,4,STAINED_GLASS:11)
B(14,-23,4,STAINED_GLASS:9)
B(15,-23,4,STAINED_GLASS:11)
B(10,-23,5,STAINED_GLASS:15)
B(11,-23,5,STAINED_GLASS:15)
B(12,-23,5,STAINED_GLASS:9)
B(8,-22,0,STAINED_GLASS:9)
B(9,-22,0,STAINED_GLASS:11)
B(10,-22,0,STAINED_GLASS:10)
B(11,-22,0,SEA_LANTERN)
B(12,-22,0,SEA_LANTERN)
B(13,-22,0,SEA_LANTERN)
B(14,-22,0,STAINED_GLASS:10)
B(15,-22,0,STAINED_GLASS:10)
B(8,-22,1,STAINED_GLASS:9)
B(9,-22,1,STAINED_GLASS:9)
B(10,-22,1,STAINED_GLASS:10)
B(11,-22,1,STAINED_GLASS:10)
B(12,-22,1,SEA_LANTERN)
B(13,-22,1,STAINED_GLASS:10)
B(14,-22,1,STAINED_GLASS:10)
B(15,-22,1,STAINED_GLASS:11)
B(9,-22,2,STAINED_GLASS:9)
B(10,-22,2,STAINED_GLASS:11)
B(11,-22,2,STAINED_GLASS:10)
B(12,-22,2,STAINED_GLASS:10)
B(13,-22,2,STAINED_GLASS:10)
B(14,-22,2,STAINED_GLASS:11)
B(15,-22,2,STAINED_GLASS:11)
B(10,-22,3,STAINED_GLASS:11)
B(11,-22,3,STAINED_GLASS:11)
B(12,-22,3,STAINED_GLASS:10)
B(13,-22,3,STAINED_GLASS:11)
B(14,-22,3,STAINED_GLASS:11)
B(15,-22,3,STAINED_GLASS:11)
B(10,-22,4,STAINED_GLASS:15)
B(11,-22,4,STAINED_GLASS:15)
B(12,-22,4,STAINED_GLASS:11)
B(13,-22,4,STAINED_GLASS:9)
B(14,-22,4,STAINED_GLASS:9)
B(15,-22,4,STAINED_GLASS:9)
B(11,-22,5,STAINED_GLASS:15)
B(7,-21,0,STAINED_GLASS:9)
B(8,-21,0,STAINED_GLASS:9)
B(9,-21,0,STAINED_GLASS:11)
B(10,-21,0,STAINED_GLASS:10)
B(11,-21,0,SEA_LANTERN)
B(12,-21,0,SEA_LANTERN)
B(13,-21,0,STAINED_GLASS:10)
B(14,-21,0,STAINED_GLASS:10)
B(15,-21,0,STAINED_GLASS:11)
B(8,-21,1,STAINED_GLASS:9)
B(9,-21,1,STAINED_GLASS:11)
B(10,-21,1,STAINED_GLASS:10)
B(11,-21,1,STAINED_GLASS:10)
B(12,-21,1,STAINED_GLASS:10)
B(13,-21,1,STAINED_GLASS:10)
B(14,-21,1,STAINED_GLASS:11)
B(15,-21,1,STAINED_GLASS:15)
B(9,-21,2,STAINED_GLASS:9)
B(10,-21,2,STAINED_GLASS:11)
B(11,-21,2,STAINED_GLASS:10)
B(12,-21,2,STAINED_GLASS:10)
B(13,-21,2,STAINED_GLASS:11)
B(14,-21,2,STAINED_GLASS:11)
B(15,-21,2,STAINED_GLASS:15)
B(10,-21,3,STAINED_GLASS:11)
B(11,-21,3,STAINED_GLASS:11)
B(12,-21,3,STAINED_GLASS:11)
B(13,-21,3,STAINED_GLASS:9)
B(14,-21,3,STAINED_GLASS:9)
B(15,-21,3,STAINED_GLASS:15)
B(10,-21,4,STAINED_GLASS:15)
B(11,-21,4,STAINED_GLASS:15)
B(12,-21,4,STAINED_GLASS:15)
B(7,-20,0,STAINED_GLASS:9)
B(8,-20,0,STAINED_GLASS:9)
B(9,-20,0,STAINED_GLASS:9)
B(10,-20,0,STAINED_GLASS:11)
B(11,-20,0,SEA_LANTERN)
B(12,-20,0,STAINED_GLASS:11)
B(13,-20,0,STAINED_GLASS:11)
B(14,-20,0,STAINED_GLASS:15)
B(15,-20,0,STAINED_GLASS:15)
B(8,-20,1,STAINED_GLASS:15)
B(9,-20,1,STAINED_GLASS:15)
B(10,-20,1,STAINED_GLASS:11)
B(11,-20,1,STAINED_GLASS:11)
B(12,-20,1,STAINED_GLASS:11)
B(13,-20,1,STAINED_GLASS:15)
B(14,-20,1,STAINED_GLASS:15)
B(15,-20,1,STAINED_GLASS:15)
B(9,-20,2,STAINED_GLASS:15)
B(10,-20,2,STAINED_GLASS:15)
B(11,-20,2,STAINED_GLASS:11)
B(12,-20,2,STAINED_GLASS:15)
B(13,-20,2,STAINED_GLASS:15)
B(14,-20,2,STAINED_GLASS:15)
B(10,-20,3,STAINED_GLASS:15)
B(11,-20,3,STAINED_GLASS:11)
B(12,-20,3,STAINED_GLASS:9)
B(11,-20,4,STAINED_GLASS:15)
B(7,-19,0,STAINED_GLASS:9)
B(8,-19,0,STAINED_GLASS:9)
B(9,-19,0,STAINED_GLASS:9)
B(10,-19,0,STAINED_GLASS:11)
B(11,-19,0,STAINED_GLASS:11)
B(12,-19,0,STAINED_GLASS:11)
B(13,-19,0,STAINED_GLASS:9)
B(14,-19,0,STAINED_GLASS:15)
B(8,-19,1,STAINED_GLASS:15)
B(9,-19,1,STAINED_GLASS:9)
B(10,-19,1,STAINED_GLASS:11)
B(11,-19,1,STAINED_GLASS:11)
B(12,-19,1,STAINED_GLASS:15)
B(13,-19,1,STAINED_GLASS:15)
B(14,-19,1,STAINED_GLASS:15)
B(9,-19,2,STAINED_GLASS:15)
B(10,-19,2,STAINED_GLASS:15)
B(11,-19,2,STAINED_GLASS:9)
B(12,-19,2,STAINED_GLASS:15)
B(13,-19,2,STAINED_GLASS:15)
B(10,-19,3,STAINED_GLASS:15)
B(11,-19,3,STAINED_GLASS:15)
B(7,-18,0,STAINED_GLASS:15)
B(8,-18,0,STAINED_GLASS:15)
B(9,-18,0,STAINED_GLASS:9)
B(10,-18,0,STAINED_GLASS:11)
B(11,-18,0,STAINED_GLASS:11)
B(12,-18,0,STAINED_GLASS:9)
B(13,-18,0,STAINED_GLASS:9)
B(14,-18,0,STAINED_GLASS:15)
B(8,-18,1,STAINED_GLASS:15)
B(9,-18,1,STAINED_GLASS:15)
B(10,-18,1,STAINED_GLASS:11)
B(11,-18,1,STAINED_GLASS:9)
B(12,-18,1,STAINED_GLASS:9)
B(13,-18,1,STAINED_GLASS:15)
B(10,-18,2,STAINED_GLASS:9)
B(11,-18,2,STAINED_GLASS:15)
B(12,-18,2,STAINED_GLASS:15)
B(10,-18,3,STAINED_GLASS:15)
B(7,-17,0,STAINED_GLASS:9)
B(8,-17,0,STAINED_GLASS:15)
B(9,-17,0,STAINED_GLASS:9)
B(10,-17,0,STAINED_GLASS:11)
B(11,-17,0,STAINED_GLASS:15)
B(12,-17,0,STAINED_GLASS:9)
B(13,-17,0,STAINED_GLASS:9)
B(8,-17,1,STAINED_GLASS:15)
B(9,-17,1,STAINED_GLASS:15)
B(10,-17,1,STAINED_GLASS:15)
B(11,-17,1,STAINED_GLASS:15)
B(12,-17,1,STAINED_GLASS:15)
B(10,-17,2,STAINED_GLASS:15)
B(7,-16,0,STAINED_GLASS:15)
B(8,-16,0,STAINED_GLASS:15)
B(9,-16,0,STAINED_GLASS:9)
B(10,-16,0,STAINED_GLASS:15)
B(11,-16,0,STAINED_GLASS:15)
B(12,-16,0,STAINED_GLASS:9)
B(9,-16,1,STAINED_GLASS:15)
B(10,-16,1,STAINED_GLASS:15)
B(11,-16,1,STAINED_GLASS:15)
B(7,-15,0,STAINED_GLASS:15)
B(8,-15,0,STAINED_GLASS:15)
B(9,-15,0,STAINED_GLASS:15)
B(10,-15,0,STAINED_GLASS:15)
B(11,-15,0,STAINED_GLASS:9)
B(8,-14,0,STAINED_GLASS:15)
B(10,-14,0,STAINED_GLASS:9)

#######################################################################
# +-----------------------------------------------------------------+ #
# |                             Branches                            | #
# +-----------------------------------------------------------------+ #
#######################################################################

BR(16,0,0,true,CEILING_SPIKE-SET-FAT-MED-03_1x1,NORTH,100,0)
