
#######################################################################
# +-----------------------------------------------------------------+ #
# |                            BO4 object                           | #
# +-----------------------------------------------------------------+ #
#######################################################################

Author: NLBlackEagle

Description: No description given

SettingsMode: WriteWithoutComments


#######################################################################
# +-----------------------------------------------------------------+ #
# |                          Main settings                          | #
# +-----------------------------------------------------------------+ #
#######################################################################

FixedRotation: 

Frequency: 0

SpawnHeight: highestBlock

UseCenterForHighestBlock: true

##############################
# Height Limits for the BO4. #
##############################

MinHeight: 0

MaxHeight: 255

InheritBO3: 

InheritBO3Rotation: NORTH

OverrideChildSettings: true

OverrideParentHeight: false

CanOverride: false

BranchFrequency: 0

BranchFrequencyGroup: 

MustBeBelowOther: false

MustBeInside: 

CannotBeInside: 

ReplacesBO3: 

MustBeInsideWorldBorders: false

CanSpawnOnWater: true

SpawnOnWaterOnly: false

SpawnUnderWater: false

SpawnAtWaterLevel: false

HeightOffset: 0

RemoveAir: true

ReplaceAbove: 

ReplaceBelow: 

ReplaceWithBiomeBlocks: true

ReplaceWithSurfaceBlock: GRASS

ReplaceWithGroundBlock: DIRT

ReplaceWithStoneBlock: STONE

SmoothRadius: 0

SmoothHeightOffset: 0

SmoothStartTop: false

SmoothStartWood: false

SmoothingSurfaceBlock: 

SmoothingGroundBlock: 

BO3Group: 

IsSpawnPoint: false

DoReplaceBlocks: true


#######################################################################
# +-----------------------------------------------------------------+ #
# |                              Blocks                             | #
# +-----------------------------------------------------------------+ #
#######################################################################

B(-8,57,5,minecraft:diorite)
B(-8,57,6,minecraft:diorite)
B(-8,57,7,minecraft:diorite)
B(-8,57,8,minecraft:diorite)
B(-8,58,5,minecraft:diorite)
B(-8,58,6,minecraft:diorite)
B(-8,58,7,minecraft:diorite)
B(-8,58,8,minecraft:diorite)
B(-8,59,5,minecraft:diorite)
B(-8,59,6,minecraft:diorite)
B(-8,59,7,minecraft:diorite)
B(-8,59,8,minecraft:diorite)
B(-8,60,5,minecraft:andesite)
B(-8,60,6,minecraft:diorite)
B(-8,60,7,minecraft:diorite)
B(-8,60,8,minecraft:diorite)
B(-8,61,6,minecraft:diorite)
B(-8,61,7,minecraft:diorite)
B(-8,61,8,minecraft:diorite)
B(-8,62,6,minecraft:diorite)
B(-8,62,7,minecraft:diorite)
B(-8,62,8,minecraft:diorite)
B(-8,63,6,minecraft:diorite)
B(-8,63,7,minecraft:diorite)
B(-8,63,8,minecraft:diorite)
B(-8,64,6,minecraft:diorite)
B(-8,64,7,minecraft:diorite)
B(-8,64,8,minecraft:diorite)
B(-8,65,6,minecraft:diorite)
B(-8,65,7,minecraft:diorite)
B(-8,65,8,minecraft:diorite)
B(-8,66,6,minecraft:diorite)
B(-8,66,7,minecraft:diorite)
B(-8,66,8,minecraft:diorite)
B(-8,67,6,minecraft:diorite)
B(-8,67,7,minecraft:diorite)
B(-8,67,8,minecraft:diorite)
B(-8,68,6,minecraft:andesite)
B(-8,68,7,minecraft:diorite)
B(-8,68,8,minecraft:diorite)
B(-8,69,7,minecraft:andesite)
B(-8,69,8,minecraft:diorite)
B(-8,70,8,minecraft:andesite)
B(-7,57,7,minecraft:diorite)
B(-7,57,8,minecraft:diorite)
B(-7,58,6,minecraft:diorite)
B(-7,58,7,minecraft:diorite)
B(-7,58,8,minecraft:diorite)
B(-7,59,6,minecraft:diorite)
B(-7,59,7,minecraft:diorite)
B(-7,59,8,minecraft:diorite)
B(-7,60,5,minecraft:andesite)
B(-7,60,6,minecraft:diorite)
B(-7,60,7,minecraft:diorite)
B(-7,60,8,minecraft:diorite)
B(-7,61,6,minecraft:diorite)
B(-7,61,7,minecraft:diorite)
B(-7,61,8,minecraft:diorite)
B(-7,62,6,minecraft:diorite)
B(-7,62,7,minecraft:diorite)
B(-7,62,8,minecraft:diorite)
B(-7,63,6,minecraft:diorite)
B(-7,63,7,minecraft:diorite)
B(-7,63,8,minecraft:diorite)
B(-7,64,6,minecraft:diorite)
B(-7,64,7,minecraft:diorite)
B(-7,64,8,minecraft:diorite)
B(-7,65,6,minecraft:diorite)
B(-7,65,7,minecraft:diorite)
B(-7,65,8,minecraft:diorite)
B(-7,66,6,minecraft:diorite)
B(-7,66,7,minecraft:diorite)
B(-7,66,8,minecraft:diorite)
B(-7,67,6,minecraft:diorite)
B(-7,67,7,minecraft:diorite)
B(-7,67,8,minecraft:diorite)
B(-7,68,6,minecraft:andesite)
B(-7,68,7,minecraft:diorite)
B(-7,68,8,minecraft:diorite)
B(-7,69,7,minecraft:andesite)
B(-7,69,8,minecraft:diorite)
B(-7,70,8,minecraft:andesite)
B(-6,57,8,minecraft:diorite)
B(-6,58,7,minecraft:diorite)
B(-6,58,8,minecraft:diorite)
B(-6,59,7,minecraft:diorite)
B(-6,59,8,minecraft:diorite)
B(-6,60,6,minecraft:diorite)
B(-6,60,7,minecraft:diorite)
B(-6,60,8,minecraft:diorite)
B(-6,61,6,minecraft:diorite)
B(-6,61,7,minecraft:diorite)
B(-6,61,8,minecraft:diorite)
B(-6,62,6,minecraft:diorite)
B(-6,62,7,minecraft:diorite)
B(-6,62,8,minecraft:diorite)
B(-6,63,6,minecraft:diorite)
B(-6,63,7,minecraft:diorite)
B(-6,63,8,minecraft:diorite)
B(-6,64,6,minecraft:diorite)
B(-6,64,7,minecraft:diorite)
B(-6,64,8,minecraft:diorite)
B(-6,65,6,minecraft:diorite)
B(-6,65,7,minecraft:diorite)
B(-6,65,8,minecraft:diorite)
B(-6,66,6,minecraft:diorite)
B(-6,66,7,minecraft:diorite)
B(-6,66,8,minecraft:diorite)
B(-6,67,6,minecraft:diorite)
B(-6,67,7,minecraft:diorite)
B(-6,67,8,minecraft:diorite)
B(-6,68,6,minecraft:diorite)
B(-6,68,7,minecraft:diorite)
B(-6,68,8,minecraft:diorite)
B(-6,69,6,minecraft:diorite)
B(-6,69,7,minecraft:diorite)
B(-6,69,8,minecraft:diorite)
B(-6,70,6,minecraft:andesite)
B(-6,70,7,minecraft:diorite)
B(-6,70,8,minecraft:diorite)
B(-6,71,7,minecraft:andesite)
B(-6,71,8,minecraft:diorite)
B(-6,72,8,minecraft:andesite)
B(-5,58,8,minecraft:diorite)
B(-5,59,8,minecraft:diorite)
B(-5,60,6,minecraft:diorite)
B(-5,60,7,minecraft:diorite)
B(-5,60,8,minecraft:diorite)
B(-5,61,5,minecraft:andesite)
B(-5,61,6,minecraft:diorite)
B(-5,61,7,minecraft:diorite)
B(-5,61,8,minecraft:diorite)
B(-5,62,6,minecraft:diorite)
B(-5,62,7,minecraft:diorite)
B(-5,62,8,minecraft:diorite)
B(-5,63,6,minecraft:diorite)
B(-5,63,7,minecraft:diorite)
B(-5,63,8,minecraft:diorite)
B(-5,64,6,minecraft:diorite)
B(-5,64,7,minecraft:diorite)
B(-5,64,8,minecraft:diorite)
B(-5,65,6,minecraft:diorite)
B(-5,65,7,minecraft:diorite)
B(-5,65,8,minecraft:diorite)
B(-5,66,6,minecraft:diorite)
B(-5,66,7,minecraft:diorite)
B(-5,66,8,minecraft:diorite)
B(-5,67,6,minecraft:diorite)
B(-5,67,7,minecraft:diorite)
B(-5,67,8,minecraft:diorite)
B(-5,68,6,minecraft:diorite)
B(-5,68,7,minecraft:diorite)
B(-5,68,8,minecraft:diorite)
B(-5,69,6,minecraft:diorite)
B(-5,69,7,minecraft:diorite)
B(-5,69,8,minecraft:diorite)
B(-5,70,6,minecraft:andesite)
B(-5,70,7,minecraft:diorite)
B(-5,70,8,minecraft:diorite)
B(-5,71,7,minecraft:diorite)
B(-5,71,8,minecraft:obsidian)
B(-5,72,7,minecraft:andesite)
B(-5,72,8,minecraft:diorite)
B(-5,73,8,minecraft:andesite)
B(-4,59,7,minecraft:diorite)
B(-4,59,8,minecraft:diorite)
B(-4,60,6,minecraft:diorite)
B(-4,60,7,minecraft:diorite)
B(-4,60,8,minecraft:diorite)
B(-4,61,5,minecraft:andesite)
B(-4,61,6,minecraft:diorite)
B(-4,61,7,minecraft:diorite)
B(-4,61,8,minecraft:diorite)
B(-4,62,6,minecraft:diorite)
B(-4,62,7,minecraft:diorite)
B(-4,62,8,minecraft:diorite)
B(-4,63,6,minecraft:diorite)
B(-4,63,7,minecraft:diorite)
B(-4,63,8,minecraft:diorite)
B(-4,64,6,minecraft:diorite)
B(-4,64,7,minecraft:diorite)
B(-4,64,8,minecraft:diorite)
B(-4,65,6,minecraft:diorite)
B(-4,65,7,minecraft:diorite)
B(-4,65,8,minecraft:diorite)
B(-4,66,6,minecraft:diorite)
B(-4,66,7,minecraft:diorite)
B(-4,66,8,minecraft:diorite)
B(-4,67,6,minecraft:diorite)
B(-4,67,7,minecraft:diorite)
B(-4,67,8,minecraft:diorite)
B(-4,68,6,minecraft:diorite)
B(-4,68,7,minecraft:diorite)
B(-4,68,8,minecraft:diorite)
B(-4,69,6,minecraft:diorite)
B(-4,69,7,minecraft:diorite)
B(-4,69,8,minecraft:diorite)
B(-4,70,6,minecraft:diorite)
B(-4,70,7,minecraft:diorite)
B(-4,70,8,minecraft:diorite)
B(-4,71,6,minecraft:andesite)
B(-4,71,7,minecraft:diorite)
B(-4,71,8,minecraft:obsidian)
B(-4,72,7,minecraft:andesite)
B(-4,72,8,minecraft:diorite)
B(-4,73,8,minecraft:andesite)
B(-3,60,8,minecraft:diorite)
B(-3,61,6,minecraft:diorite)
B(-3,61,7,minecraft:diorite)
B(-3,61,8,minecraft:diorite)
B(-3,62,6,minecraft:diorite)
B(-3,62,7,minecraft:diorite)
B(-3,62,8,minecraft:diorite)
B(-3,63,6,minecraft:diorite)
B(-3,63,7,minecraft:diorite)
B(-3,63,8,minecraft:diorite)
B(-3,64,6,minecraft:diorite)
B(-3,64,7,minecraft:diorite)
B(-3,64,8,minecraft:diorite)
B(-3,65,6,minecraft:diorite)
B(-3,65,7,minecraft:diorite)
B(-3,65,8,minecraft:diorite)
B(-3,66,6,minecraft:diorite)
B(-3,66,7,minecraft:diorite)
B(-3,66,8,minecraft:diorite)
B(-3,67,6,minecraft:diorite)
B(-3,67,7,minecraft:diorite)
B(-3,67,8,minecraft:diorite)
B(-3,68,6,minecraft:diorite)
B(-3,68,7,minecraft:diorite)
B(-3,68,8,minecraft:diorite)
B(-3,69,6,minecraft:diorite)
B(-3,69,7,minecraft:diorite)
B(-3,69,8,minecraft:diorite)
B(-3,70,6,minecraft:andesite)
B(-3,70,7,minecraft:diorite)
B(-3,70,8,minecraft:diorite)
B(-3,71,7,minecraft:diorite)
B(-3,71,8,minecraft:diorite)
B(-3,72,7,minecraft:andesite)
B(-3,72,8,minecraft:diorite)
B(-3,73,8,minecraft:andesite)
B(-2,61,7,minecraft:diorite)
B(-2,61,8,minecraft:diorite)
B(-2,62,7,minecraft:diorite)
B(-2,62,8,minecraft:diorite)
B(-2,63,6,minecraft:diorite)
B(-2,63,7,minecraft:diorite)
B(-2,63,8,minecraft:diorite)
B(-2,64,6,minecraft:diorite)
B(-2,64,7,minecraft:diorite)
B(-2,64,8,minecraft:diorite)
B(-2,65,6,minecraft:diorite)
B(-2,65,7,minecraft:diorite)
B(-2,65,8,minecraft:diorite)
B(-2,66,6,minecraft:diorite)
B(-2,66,7,minecraft:diorite)
B(-2,66,8,minecraft:diorite)
B(-2,67,6,minecraft:diorite)
B(-2,67,7,minecraft:diorite)
B(-2,67,8,minecraft:diorite)
B(-2,68,6,minecraft:diorite)
B(-2,68,7,minecraft:diorite)
B(-2,68,8,minecraft:diorite)
B(-2,69,6,minecraft:diorite)
B(-2,69,7,minecraft:diorite)
B(-2,69,8,minecraft:diorite)
B(-2,70,6,minecraft:andesite)
B(-2,70,7,minecraft:diorite)
B(-2,70,8,minecraft:diorite)
B(-2,71,7,minecraft:andesite)
B(-2,71,8,minecraft:diorite)
B(-2,72,8,minecraft:andesite)
B(-1,61,8,minecraft:diorite)
B(-1,62,8,minecraft:diorite)
B(-1,63,7,minecraft:diorite)
B(-1,63,8,minecraft:diorite)
B(-1,64,7,minecraft:diorite)
B(-1,64,8,minecraft:diorite)
B(-1,65,6,minecraft:diorite)
B(-1,65,7,minecraft:diorite)
B(-1,65,8,minecraft:diorite)
B(-1,66,6,minecraft:diorite)
B(-1,66,7,minecraft:diorite)
B(-1,66,8,minecraft:diorite)
B(-1,67,6,minecraft:diorite)
B(-1,67,7,minecraft:diorite)
B(-1,67,8,minecraft:diorite)
B(-1,68,6,minecraft:diorite)
B(-1,68,7,minecraft:diorite)
B(-1,68,8,minecraft:diorite)
B(-1,69,6,minecraft:diorite)
B(-1,69,7,minecraft:diorite)
B(-1,69,8,minecraft:diorite)
B(-1,70,6,minecraft:andesite)
B(-1,70,7,minecraft:diorite)
B(-1,70,8,minecraft:diorite)
B(-1,71,7,minecraft:diorite)
B(-1,71,8,minecraft:diorite)
B(-1,72,7,minecraft:andesite)
B(-1,72,8,minecraft:diorite)
B(-1,73,8,minecraft:andesite)
B(0,63,8,minecraft:diorite)
B(0,64,7,minecraft:diorite)
B(0,64,8,minecraft:diorite)
B(0,65,7,minecraft:diorite)
B(0,65,8,minecraft:diorite)
B(0,66,6,minecraft:diorite)
B(0,66,7,minecraft:diorite)
B(0,66,8,minecraft:diorite)
B(0,67,6,minecraft:diorite)
B(0,67,7,minecraft:diorite)
B(0,67,8,minecraft:diorite)
B(0,68,6,minecraft:diorite)
B(0,68,7,minecraft:diorite)
B(0,68,8,minecraft:diorite)
B(0,69,6,minecraft:diorite)
B(0,69,7,minecraft:diorite)
B(0,69,8,minecraft:diorite)
B(0,70,6,minecraft:andesite)
B(0,70,7,minecraft:diorite)
B(0,70,8,minecraft:diorite)
B(0,71,7,minecraft:diorite)
B(0,71,8,minecraft:obsidian)
B(0,72,7,minecraft:andesite)
B(0,72,8,minecraft:diorite)
B(0,73,8,minecraft:andesite)
B(1,63,8,minecraft:diorite)
B(1,64,7,minecraft:diorite)
B(1,64,8,minecraft:diorite)
B(1,65,7,minecraft:diorite)
B(1,65,8,minecraft:diorite)
B(1,66,7,minecraft:diorite)
B(1,66,8,minecraft:diorite)
B(1,67,6,minecraft:diorite)
B(1,67,7,minecraft:diorite)
B(1,67,8,minecraft:diorite)
B(1,68,6,minecraft:diorite)
B(1,68,7,minecraft:diorite)
B(1,68,8,minecraft:diorite)
B(1,69,6,minecraft:diorite)
B(1,69,7,minecraft:diorite)
B(1,69,8,minecraft:diorite)
B(1,70,6,minecraft:andesite)
B(1,70,7,minecraft:andesite)
B(1,70,8,minecraft:diorite)
B(1,71,8,minecraft:andesite)
B(2,63,8,minecraft:diorite)
B(2,64,8,minecraft:diorite)
B(2,65,7,minecraft:diorite)
B(2,65,8,minecraft:diorite)
B(2,66,7,minecraft:diorite)
B(2,66,8,minecraft:diorite)
B(2,67,6,minecraft:diorite)
B(2,67,7,minecraft:diorite)
B(2,67,8,minecraft:diorite)
B(2,68,8,minecraft:diorite)
B(2,69,6,minecraft:andesite)
B(2,69,7,minecraft:andesite)
B(2,69,8,minecraft:diorite)
B(2,70,8,minecraft:andesite)
B(3,66,8,minecraft:diorite)
B(3,67,8,minecraft:diorite)
B(3,68,8,minecraft:andesite)
B(4,66,8,minecraft:diorite)
B(4,68,8,minecraft:diorite)
B(4,69,8,minecraft:andesite)

#######################################################################
# +-----------------------------------------------------------------+ #
# |                             Branches                            | #
# +-----------------------------------------------------------------+ #
#######################################################################

Branch(-16,0,0,true,Amethyst_BigC6R1,NORTH,100.0,0)

#######################################################################
# +-----------------------------------------------------------------+ #
# |                             Entities                            | #
# +-----------------------------------------------------------------+ #
#######################################################################

