
#######################################################################
# +-----------------------------------------------------------------+ #
# |                            BO4 object                           | #
# +-----------------------------------------------------------------+ #
#######################################################################

Author: NLBlackEagle

Description: No description given

SettingsMode: WriteWithoutComments


#######################################################################
# +-----------------------------------------------------------------+ #
# |                          Main settings                          | #
# +-----------------------------------------------------------------+ #
#######################################################################

Frequency: 0

SpawnHeight: highestBlock

UseCenterForHighestBlock: true

##############################
# Height Limits for the BO4. #
##############################

MinHeight: 0

MaxHeight: 255

InheritBO3: 

InheritBO3Rotation: NORTH

OverrideChildSettings: true

OverrideParentHeight: false

CanOverride: false

BranchFrequency: 0

BranchFrequencyGroup: 

MustBeBelowOther: false

MustBeInside: 

CannotBeInside: 

ReplacesBO3: 

MustBeInsideWorldBorders: false

CanSpawnOnWater: true

SpawnOnWaterOnly: false

SpawnUnderWater: false

SpawnAtWaterLevel: false

HeightOffset: 0

RemoveAir: true

ReplaceAbove: 

ReplaceBelow: 

ReplaceWithBiomeBlocks: true

ReplaceWithSurfaceBlock: GRASS

ReplaceWithGroundBlock: DIRT

ReplaceWithStoneBlock: STONE

SmoothRadius: 0

SmoothHeightOffset: 0

SmoothStartTop: false

SmoothStartWood: false

SmoothingSurfaceBlock: 

SmoothingGroundBlock: 

BO3Group: 

IsSpawnPoint: false

DoReplaceBlocks: true


#######################################################################
# +-----------------------------------------------------------------+ #
# |                              Blocks                             | #
# +-----------------------------------------------------------------+ #
#######################################################################

Block(-8,25,-7,STONE:3)
Block(-8,26,-7,STONE:3)
Block(-8,27,-7,STONE:3)
Block(-8,27,-6,STONE:3)
Block(-8,28,-7,STONE:3)
Block(-8,28,-6,STONE:3)
Block(-8,28,-5,STONE:3)
Block(-8,29,-7,STONE:3)
Block(-8,29,-6,STONE:3)
Block(-8,29,-5,STONE:3)
Block(-8,29,-4,STONE:3)
Block(-8,30,-7,STONE:3)
Block(-8,30,-6,STONE:3)
Block(-8,30,-5,STONE:3)
Block(-8,30,-4,STONE:3)
Block(-8,30,-3,STONE:3)
Block(-8,31,-7,STONE:3)
Block(-8,31,-6,STONE:3)
Block(-8,31,-5,STONE:3)
Block(-8,31,-4,STONE:3)
Block(-8,31,-3,STONE:3)
Block(-8,31,-2,STONE:3)
Block(-8,31,-1,STONE:3)
Block(-8,31,0,STONE:3)
Block(-8,31,1,STONE:3)
Block(-8,32,-7,STONE:3)
Block(-8,32,-6,STONE:3)
Block(-8,32,-5,STONE:3)
Block(-8,32,-4,STONE:3)
Block(-8,32,-3,STONE:3)
Block(-8,32,-2,STONE:3)
Block(-8,32,-1,STONE:3)
Block(-8,32,0,STONE:3)
Block(-8,32,1,STONE:3)
Block(-8,32,2,STONE:3)
Block(-8,33,-7,STONE:3)
Block(-8,33,-6,STONE:3)
Block(-8,33,-5,STONE:3)
Block(-8,33,-4,STONE:3)
Block(-8,33,-3,STONE:3)
Block(-8,33,-2,STONE:3)
Block(-8,33,-1,STONE:3)
Block(-8,33,0,STONE:3)
Block(-8,33,1,STONE:3)
Block(-8,33,2,STONE:3)
Block(-8,34,-7,OBSIDIAN:0)
Block(-8,34,-6,STONE:3)
Block(-8,34,-5,STONE:3)
Block(-8,34,-4,STONE:3)
Block(-8,34,-3,STONE:3)
Block(-8,34,-2,STONE:3)
Block(-8,34,-1,STONE:3)
Block(-8,34,0,STONE:3)
Block(-8,34,1,STONE:3)
Block(-8,34,2,STONE:3)
Block(-8,35,-7,OBSIDIAN:0)
Block(-8,35,-6,OBSIDIAN:0)
Block(-8,35,-5,OBSIDIAN:0)
Block(-8,35,-4,OBSIDIAN:0)
Block(-8,35,-3,STONE:3)
Block(-8,35,-2,STONE:3)
Block(-8,35,-1,STONE:3)
Block(-8,35,0,STONE:3)
Block(-8,35,1,STONE:3)
Block(-8,35,2,STONE:3)
Block(-8,36,-7,OBSIDIAN:0)
Block(-8,36,-6,OBSIDIAN:0)
Block(-8,36,-5,OBSIDIAN:0)
Block(-8,36,-4,OBSIDIAN:0)
Block(-8,36,-3,STONE:3)
Block(-8,36,-2,STONE:3)
Block(-8,36,-1,STONE:3)
Block(-8,36,0,STONE:3)
Block(-8,36,1,STONE:3)
Block(-8,36,2,STONE:3)
Block(-8,36,3,STONE:3)
Block(-8,37,-7,OBSIDIAN:0)
Block(-8,37,-6,OBSIDIAN:0)
Block(-8,37,-5,OBSIDIAN:0)
Block(-8,37,-4,OBSIDIAN:0)
Block(-8,37,-3,OBSIDIAN:0)
Block(-8,37,-2,STONE:3)
Block(-8,37,-1,STONE:3)
Block(-8,37,0,STONE:3)
Block(-8,37,1,STONE:3)
Block(-8,37,2,STONE:3)
Block(-8,37,3,STONE:3)
Block(-8,38,-7,OBSIDIAN:0)
Block(-8,38,-6,OBSIDIAN:0)
Block(-8,38,-5,OBSIDIAN:0)
Block(-8,38,-4,OBSIDIAN:0)
Block(-8,38,-3,OBSIDIAN:0)
Block(-8,38,-2,STONE:3)
Block(-8,38,-1,STONE:3)
Block(-8,38,0,STONE:3)
Block(-8,38,1,STONE:3)
Block(-8,38,2,STONE:3)
Block(-8,38,3,STONE:3)
Block(-8,39,-7,OBSIDIAN:0)
Block(-8,39,-6,OBSIDIAN:0)
Block(-8,39,-5,OBSIDIAN:0)
Block(-8,39,-4,OBSIDIAN:0)
Block(-8,39,-3,OBSIDIAN:0)
Block(-8,39,-2,STONE:3)
Block(-8,39,-1,STONE:3)
Block(-8,39,0,STONE:3)
Block(-8,39,1,STONE:3)
Block(-8,39,2,STONE:3)
Block(-8,39,3,STONE:3)
Block(-8,40,-7,OBSIDIAN:0)
Block(-8,40,-6,OBSIDIAN:0)
Block(-8,40,-5,OBSIDIAN:0)
Block(-8,40,-4,OBSIDIAN:0)
Block(-8,40,-3,OBSIDIAN:0)
Block(-8,40,-2,STONE:3)
Block(-8,40,-1,STONE:3)
Block(-8,40,0,STONE:3)
Block(-8,40,1,STONE:3)
Block(-8,40,2,STONE:3)
Block(-8,40,3,STONE:3)
Block(-8,41,-7,OBSIDIAN:0)
Block(-8,41,-6,OBSIDIAN:0)
Block(-8,41,-5,OBSIDIAN:0)
Block(-8,41,-4,OBSIDIAN:0)
Block(-8,41,-3,OBSIDIAN:0)
Block(-8,41,-2,OBSIDIAN:0)
Block(-8,41,-1,STONE:3)
Block(-8,41,0,STONE:3)
Block(-8,41,1,STONE:3)
Block(-8,41,2,STONE:3)
Block(-8,41,3,STONE:3)
Block(-8,42,-7,OBSIDIAN:0)
Block(-8,42,-6,OBSIDIAN:0)
Block(-8,42,-5,OBSIDIAN:0)
Block(-8,42,-4,OBSIDIAN:0)
Block(-8,42,-3,OBSIDIAN:0)
Block(-8,42,-2,OBSIDIAN:0)
Block(-8,42,-1,STONE:3)
Block(-8,42,0,STONE:3)
Block(-8,42,1,STONE:3)
Block(-8,42,2,STONE:3)
Block(-8,42,3,STONE:3)
Block(-8,42,4,STONE:3)
Block(-8,43,-7,OBSIDIAN:0)
Block(-8,43,-6,OBSIDIAN:0)
Block(-8,43,-5,OBSIDIAN:0)
Block(-8,43,-4,OBSIDIAN:0)
Block(-8,43,-3,OBSIDIAN:0)
Block(-8,43,-2,STONE:3)
Block(-8,43,-1,STONE:3)
Block(-8,43,0,STONE:3)
Block(-8,43,1,STONE:3)
Block(-8,43,2,STONE:3)
Block(-8,43,3,STONE:3)
Block(-8,43,4,STONE:3)
Block(-8,44,-7,OBSIDIAN:0)
Block(-8,44,-6,OBSIDIAN:0)
Block(-8,44,-5,OBSIDIAN:0)
Block(-8,44,-4,OBSIDIAN:0)
Block(-8,44,-3,OBSIDIAN:0)
Block(-8,44,-2,STONE:3)
Block(-8,44,-1,STONE:3)
Block(-8,44,0,STONE:3)
Block(-8,44,1,STONE:3)
Block(-8,44,2,STONE:3)
Block(-8,44,3,STONE:3)
Block(-8,44,4,STONE:3)
Block(-8,45,-7,OBSIDIAN:0)
Block(-8,45,-6,OBSIDIAN:0)
Block(-8,45,-5,OBSIDIAN:0)
Block(-8,45,-4,OBSIDIAN:0)
Block(-8,45,-3,OBSIDIAN:0)
Block(-8,45,-2,STONE:3)
Block(-8,45,-1,STONE:3)
Block(-8,45,0,STONE:3)
Block(-8,45,1,STONE:3)
Block(-8,45,2,STONE:3)
Block(-8,45,3,STONE:3)
Block(-8,46,-7,OBSIDIAN:0)
Block(-8,46,-6,OBSIDIAN:0)
Block(-8,46,-5,OBSIDIAN:0)
Block(-8,46,-4,OBSIDIAN:0)
Block(-8,46,-3,OBSIDIAN:0)
Block(-8,46,-2,OBSIDIAN:0)
Block(-8,46,-1,STONE:3)
Block(-8,46,0,STONE:3)
Block(-8,46,1,STONE:3)
Block(-8,46,2,STONE:3)
Block(-8,46,3,STONE:3)
Block(-8,47,-7,OBSIDIAN:0)
Block(-8,47,-6,OBSIDIAN:0)
Block(-8,47,-5,OBSIDIAN:0)
Block(-8,47,-4,OBSIDIAN:0)
Block(-8,47,-3,OBSIDIAN:0)
Block(-8,47,-2,OBSIDIAN:0)
Block(-8,47,-1,STONE:3)
Block(-8,47,0,STONE:3)
Block(-8,47,1,STONE:3)
Block(-8,47,2,STONE:3)
Block(-8,47,3,STONE:3)
Block(-8,48,-7,OBSIDIAN:0)
Block(-8,48,-6,OBSIDIAN:0)
Block(-8,48,-5,OBSIDIAN:0)
Block(-8,48,-4,OBSIDIAN:0)
Block(-8,48,-3,OBSIDIAN:0)
Block(-8,48,-2,OBSIDIAN:0)
Block(-8,48,-1,OBSIDIAN:0)
Block(-8,48,0,STONE:3)
Block(-8,48,1,STONE:3)
Block(-8,48,2,STONE:3)
Block(-8,48,3,STONE:3)
Block(-8,49,-7,OBSIDIAN:0)
Block(-8,49,-6,OBSIDIAN:0)
Block(-8,49,-5,OBSIDIAN:0)
Block(-8,49,-4,OBSIDIAN:0)
Block(-8,49,-3,OBSIDIAN:0)
Block(-8,49,-2,OBSIDIAN:0)
Block(-8,49,-1,OBSIDIAN:0)
Block(-8,49,0,STONE:3)
Block(-8,49,1,STONE:3)
Block(-8,49,2,STONE:3)
Block(-8,49,3,STONE:3)
Block(-8,50,-7,OBSIDIAN:0)
Block(-8,50,-6,OBSIDIAN:0)
Block(-8,50,-5,OBSIDIAN:0)
Block(-8,50,-4,OBSIDIAN:0)
Block(-8,50,-3,OBSIDIAN:0)
Block(-8,50,-2,OBSIDIAN:0)
Block(-8,50,-1,OBSIDIAN:0)
Block(-8,50,0,STONE:3)
Block(-8,50,1,STONE:3)
Block(-8,50,2,STONE:3)
Block(-8,50,3,STONE:3)
Block(-8,51,-7,OBSIDIAN:0)
Block(-8,51,-6,OBSIDIAN:0)
Block(-8,51,-5,OBSIDIAN:0)
Block(-8,51,-4,OBSIDIAN:0)
Block(-8,51,-3,OBSIDIAN:0)
Block(-8,51,-2,OBSIDIAN:0)
Block(-8,51,-1,STONE:3)
Block(-8,51,0,STONE:3)
Block(-8,51,1,STONE:3)
Block(-8,51,2,STONE:3)
Block(-8,51,3,STONE:3)
Block(-8,52,-7,OBSIDIAN:0)
Block(-8,52,-6,OBSIDIAN:0)
Block(-8,52,-5,OBSIDIAN:0)
Block(-8,52,-4,OBSIDIAN:0)
Block(-8,52,-3,OBSIDIAN:0)
Block(-8,52,-2,OBSIDIAN:0)
Block(-8,52,-1,STONE:3)
Block(-8,52,0,STONE:3)
Block(-8,52,1,STONE:3)
Block(-8,52,2,STONE:3)
Block(-8,52,3,STONE:3)
Block(-8,52,4,STONE:3)
Block(-8,53,-7,OBSIDIAN:0)
Block(-8,53,-6,OBSIDIAN:0)
Block(-8,53,-5,OBSIDIAN:0)
Block(-8,53,-4,STONE:3)
Block(-8,53,-3,STONE:3)
Block(-8,53,-2,STONE:3)
Block(-8,53,-1,STONE:3)
Block(-8,53,0,STONE:3)
Block(-8,53,1,STONE:3)
Block(-8,53,2,STONE:3)
Block(-8,53,3,STONE:3)
Block(-8,53,4,STONE:3)
Block(-8,54,-7,OBSIDIAN:0)
Block(-8,54,-6,STONE:3)
Block(-8,54,-5,STONE:3)
Block(-8,54,-4,STONE:3)
Block(-8,54,-3,STONE:3)
Block(-8,54,-2,STONE:3)
Block(-8,54,-1,STONE:3)
Block(-8,54,0,STONE:3)
Block(-8,54,1,STONE:3)
Block(-8,54,2,STONE:3)
Block(-8,54,3,STONE:3)
Block(-8,55,-7,STONE:3)
Block(-8,55,-6,STONE:3)
Block(-8,55,-5,STONE:3)
Block(-8,55,-4,STONE:3)
Block(-8,55,-3,STONE:3)
Block(-8,55,-2,STONE:3)
Block(-8,55,-1,STONE:3)
Block(-8,55,0,STONE:3)
Block(-8,55,1,STONE:3)
Block(-8,55,2,STONE:3)
Block(-8,55,3,STONE:3)
Block(-8,56,-7,STONE:3)
Block(-8,56,-6,STONE:3)
Block(-8,56,-5,STONE:3)
Block(-8,56,-4,STONE:3)
Block(-8,56,-3,STONE:3)
Block(-8,56,-2,STONE:3)
Block(-8,56,-1,STONE:3)
Block(-8,56,0,STONE:3)
Block(-8,56,1,STONE:3)
Block(-8,56,2,STONE:3)
Block(-8,56,3,STONE:3)
Block(-8,57,-7,STONE:3)
Block(-8,57,-6,STONE:3)
Block(-8,57,-5,STONE:3)
Block(-8,57,-4,STONE:3)
Block(-8,57,-3,STONE:3)
Block(-8,57,-2,STONE:3)
Block(-8,57,-1,STONE:3)
Block(-8,57,0,STONE:3)
Block(-8,57,1,STONE:3)
Block(-8,57,2,STONE:3)
Block(-8,58,-7,STONE:3)
Block(-8,58,-6,STONE:3)
Block(-8,58,-5,STONE:3)
Block(-8,58,-4,STONE:3)
Block(-8,58,-3,STONE:3)
Block(-8,59,-7,STONE:3)
Block(-8,59,-6,STONE:3)
Block(-8,59,-5,STONE:3)
Block(-8,59,-4,STONE:3)
Block(-8,59,-3,STONE:3)
Block(-8,60,-7,STONE:3)
Block(-8,60,-6,STONE:3)
Block(-8,60,-5,STONE:3)
Block(-8,60,-4,STONE:3)
Block(-8,61,-7,OBSIDIAN:0)
Block(-8,61,-6,STONE:3)
Block(-8,61,-5,STONE:3)
Block(-8,61,-4,STONE:3)
Block(-8,62,-6,STONE:3)
Block(-8,62,-5,STONE:3)
Block(-7,25,-7,STONE:3)
Block(-7,25,-6,STONE:3)
Block(-7,26,-7,STONE:3)
Block(-7,26,-6,STONE:3)
Block(-7,27,-7,STONE:3)
Block(-7,27,-6,STONE:3)
Block(-7,27,-5,STONE:3)
Block(-7,28,-7,STONE:3)
Block(-7,28,-6,STONE:3)
Block(-7,28,-5,STONE:3)
Block(-7,29,-7,STONE:3)
Block(-7,29,-6,STONE:3)
Block(-7,29,-5,STONE:3)
Block(-7,29,-4,STONE:3)
Block(-7,29,-3,STONE:3)
Block(-7,30,-7,STONE:3)
Block(-7,30,-6,STONE:3)
Block(-7,30,-5,STONE:3)
Block(-7,30,-4,STONE:3)
Block(-7,30,-3,STONE:3)
Block(-7,30,-2,STONE:3)
Block(-7,31,-7,STONE:3)
Block(-7,31,-6,STONE:3)
Block(-7,31,-5,STONE:3)
Block(-7,31,-4,STONE:3)
Block(-7,31,-3,STONE:3)
Block(-7,31,-2,STONE:3)
Block(-7,31,-1,STONE:3)
Block(-7,31,0,STONE:3)
Block(-7,32,-7,STONE:3)
Block(-7,32,-6,STONE:3)
Block(-7,32,-5,STONE:3)
Block(-7,32,-4,STONE:3)
Block(-7,32,-3,STONE:3)
Block(-7,32,-2,STONE:3)
Block(-7,32,-1,STONE:3)
Block(-7,32,0,STONE:3)
Block(-7,32,1,STONE:3)
Block(-7,33,-7,STONE:3)
Block(-7,33,-6,STONE:3)
Block(-7,33,-5,STONE:3)
Block(-7,33,-4,STONE:3)
Block(-7,33,-3,STONE:3)
Block(-7,33,-2,STONE:3)
Block(-7,33,-1,STONE:3)
Block(-7,33,0,STONE:3)
Block(-7,33,1,STONE:3)
Block(-7,33,2,STONE:3)
Block(-7,34,-7,OBSIDIAN:0)
Block(-7,34,-6,STONE:3)
Block(-7,34,-5,STONE:3)
Block(-7,34,-4,STONE:3)
Block(-7,34,-3,STONE:3)
Block(-7,34,-2,STONE:3)
Block(-7,34,-1,STONE:3)
Block(-7,34,0,STONE:3)
Block(-7,34,1,STONE:3)
Block(-7,34,2,STONE:3)
Block(-7,35,-7,OBSIDIAN:0)
Block(-7,35,-6,OBSIDIAN:0)
Block(-7,35,-5,OBSIDIAN:0)
Block(-7,35,-4,OBSIDIAN:0)
Block(-7,35,-3,STONE:3)
Block(-7,35,-2,STONE:3)
Block(-7,35,-1,STONE:3)
Block(-7,35,0,STONE:3)
Block(-7,35,1,STONE:3)
Block(-7,35,2,STONE:3)
Block(-7,36,-7,OBSIDIAN:0)
Block(-7,36,-6,OBSIDIAN:0)
Block(-7,36,-5,OBSIDIAN:0)
Block(-7,36,-4,OBSIDIAN:0)
Block(-7,36,-3,STONE:3)
Block(-7,36,-2,STONE:3)
Block(-7,36,-1,STONE:3)
Block(-7,36,0,STONE:3)
Block(-7,36,1,STONE:3)
Block(-7,36,2,STONE:3)
Block(-7,37,-7,OBSIDIAN:0)
Block(-7,37,-6,OBSIDIAN:0)
Block(-7,37,-5,OBSIDIAN:0)
Block(-7,37,-4,OBSIDIAN:0)
Block(-7,37,-3,OBSIDIAN:0)
Block(-7,37,-2,STONE:3)
Block(-7,37,-1,STONE:3)
Block(-7,37,0,STONE:3)
Block(-7,37,1,STONE:3)
Block(-7,37,2,STONE:3)
Block(-7,37,3,STONE:3)
Block(-7,38,-7,OBSIDIAN:0)
Block(-7,38,-6,OBSIDIAN:0)
Block(-7,38,-5,OBSIDIAN:0)
Block(-7,38,-4,OBSIDIAN:0)
Block(-7,38,-3,OBSIDIAN:0)
Block(-7,38,-2,STONE:3)
Block(-7,38,-1,STONE:3)
Block(-7,38,0,STONE:3)
Block(-7,38,1,STONE:3)
Block(-7,38,2,STONE:3)
Block(-7,38,3,STONE:3)
Block(-7,39,-7,OBSIDIAN:0)
Block(-7,39,-6,OBSIDIAN:0)
Block(-7,39,-5,OBSIDIAN:0)
Block(-7,39,-4,OBSIDIAN:0)
Block(-7,39,-3,OBSIDIAN:0)
Block(-7,39,-2,STONE:3)
Block(-7,39,-1,STONE:3)
Block(-7,39,0,STONE:3)
Block(-7,39,1,STONE:3)
Block(-7,39,2,STONE:3)
Block(-7,39,3,STONE:3)
Block(-7,40,-7,OBSIDIAN:0)
Block(-7,40,-6,OBSIDIAN:0)
Block(-7,40,-5,OBSIDIAN:0)
Block(-7,40,-4,OBSIDIAN:0)
Block(-7,40,-3,OBSIDIAN:0)
Block(-7,40,-2,STONE:3)
Block(-7,40,-1,STONE:3)
Block(-7,40,0,STONE:3)
Block(-7,40,1,STONE:3)
Block(-7,40,2,STONE:3)
Block(-7,40,3,STONE:3)
Block(-7,41,-7,OBSIDIAN:0)
Block(-7,41,-6,OBSIDIAN:0)
Block(-7,41,-5,OBSIDIAN:0)
Block(-7,41,-4,OBSIDIAN:0)
Block(-7,41,-3,OBSIDIAN:0)
Block(-7,41,-2,STONE:3)
Block(-7,41,-1,STONE:3)
Block(-7,41,0,STONE:3)
Block(-7,41,1,STONE:3)
Block(-7,41,2,STONE:3)
Block(-7,41,3,STONE:3)
Block(-7,42,-7,OBSIDIAN:0)
Block(-7,42,-6,OBSIDIAN:0)
Block(-7,42,-5,OBSIDIAN:0)
Block(-7,42,-4,OBSIDIAN:0)
Block(-7,42,-3,OBSIDIAN:0)
Block(-7,42,-2,STONE:3)
Block(-7,42,-1,STONE:3)
Block(-7,42,0,STONE:3)
Block(-7,42,1,STONE:3)
Block(-7,42,2,STONE:3)
Block(-7,42,3,STONE:3)
Block(-7,43,-7,OBSIDIAN:0)
Block(-7,43,-6,OBSIDIAN:0)
Block(-7,43,-5,OBSIDIAN:0)
Block(-7,43,-4,OBSIDIAN:0)
Block(-7,43,-3,OBSIDIAN:0)
Block(-7,43,-2,OBSIDIAN:0)
Block(-7,43,-1,STONE:3)
Block(-7,43,0,STONE:3)
Block(-7,43,1,STONE:3)
Block(-7,43,2,STONE:3)
Block(-7,43,3,STONE:3)
Block(-7,43,4,STONE:3)
Block(-7,44,-7,OBSIDIAN:0)
Block(-7,44,-6,OBSIDIAN:0)
Block(-7,44,-5,OBSIDIAN:0)
Block(-7,44,-4,OBSIDIAN:0)
Block(-7,44,-3,OBSIDIAN:0)
Block(-7,44,-2,OBSIDIAN:0)
Block(-7,44,-1,STONE:3)
Block(-7,44,0,STONE:3)
Block(-7,44,1,STONE:3)
Block(-7,44,2,STONE:3)
Block(-7,44,3,STONE:3)
Block(-7,44,4,STONE:3)
Block(-7,45,-7,OBSIDIAN:0)
Block(-7,45,-6,OBSIDIAN:0)
Block(-7,45,-5,OBSIDIAN:0)
Block(-7,45,-4,OBSIDIAN:0)
Block(-7,45,-3,OBSIDIAN:0)
Block(-7,45,-2,OBSIDIAN:0)
Block(-7,45,-1,STONE:3)
Block(-7,45,0,STONE:3)
Block(-7,45,1,STONE:3)
Block(-7,45,2,STONE:3)
Block(-7,45,3,STONE:3)
Block(-7,45,4,STONE:3)
Block(-7,46,-7,OBSIDIAN:0)
Block(-7,46,-6,OBSIDIAN:0)
Block(-7,46,-5,OBSIDIAN:0)
Block(-7,46,-4,OBSIDIAN:0)
Block(-7,46,-3,OBSIDIAN:0)
Block(-7,46,-2,OBSIDIAN:0)
Block(-7,46,-1,STONE:3)
Block(-7,46,0,STONE:3)
Block(-7,46,1,STONE:3)
Block(-7,46,2,STONE:3)
Block(-7,46,3,STONE:3)
Block(-7,47,-7,OBSIDIAN:0)
Block(-7,47,-6,OBSIDIAN:0)
Block(-7,47,-5,OBSIDIAN:0)
Block(-7,47,-4,OBSIDIAN:0)
Block(-7,47,-3,OBSIDIAN:0)
Block(-7,47,-2,OBSIDIAN:0)
Block(-7,47,-1,STONE:3)
Block(-7,47,0,STONE:3)
Block(-7,47,1,STONE:3)
Block(-7,47,2,STONE:3)
Block(-7,47,3,STONE:3)
Block(-7,48,-7,OBSIDIAN:0)
Block(-7,48,-6,OBSIDIAN:0)
Block(-7,48,-5,OBSIDIAN:0)
Block(-7,48,-4,OBSIDIAN:0)
Block(-7,48,-3,OBSIDIAN:0)
Block(-7,48,-2,OBSIDIAN:0)
Block(-7,48,-1,STONE:3)
Block(-7,48,0,STONE:3)
Block(-7,48,1,STONE:3)
Block(-7,48,2,STONE:3)
Block(-7,48,3,STONE:3)
Block(-7,49,-7,OBSIDIAN:0)
Block(-7,49,-6,OBSIDIAN:0)
Block(-7,49,-5,OBSIDIAN:0)
Block(-7,49,-4,OBSIDIAN:0)
Block(-7,49,-3,OBSIDIAN:0)
Block(-7,49,-2,OBSIDIAN:0)
Block(-7,49,-1,OBSIDIAN:0)
Block(-7,49,0,STONE:3)
Block(-7,49,1,STONE:3)
Block(-7,49,2,STONE:3)
Block(-7,49,3,STONE:3)
Block(-7,49,4,STONE:3)
Block(-7,50,-7,OBSIDIAN:0)
Block(-7,50,-6,OBSIDIAN:0)
Block(-7,50,-5,OBSIDIAN:0)
Block(-7,50,-4,OBSIDIAN:0)
Block(-7,50,-3,OBSIDIAN:0)
Block(-7,50,-2,OBSIDIAN:0)
Block(-7,50,-1,OBSIDIAN:0)
Block(-7,50,0,OBSIDIAN:0)
Block(-7,50,1,STONE:3)
Block(-7,50,2,STONE:3)
Block(-7,50,3,STONE:3)
Block(-7,50,4,STONE:3)
Block(-7,51,-7,OBSIDIAN:0)
Block(-7,51,-6,OBSIDIAN:0)
Block(-7,51,-5,OBSIDIAN:0)
Block(-7,51,-4,OBSIDIAN:0)
Block(-7,51,-3,OBSIDIAN:0)
Block(-7,51,-2,OBSIDIAN:0)
Block(-7,51,-1,OBSIDIAN:0)
Block(-7,51,0,STONE:3)
Block(-7,51,1,STONE:3)
Block(-7,51,2,STONE:3)
Block(-7,51,3,STONE:3)
Block(-7,51,4,STONE:3)
Block(-7,52,-7,OBSIDIAN:0)
Block(-7,52,-6,OBSIDIAN:0)
Block(-7,52,-5,OBSIDIAN:0)
Block(-7,52,-4,OBSIDIAN:0)
Block(-7,52,-3,OBSIDIAN:0)
Block(-7,52,-2,OBSIDIAN:0)
Block(-7,52,-1,STONE:3)
Block(-7,52,0,STONE:3)
Block(-7,52,1,STONE:3)
Block(-7,52,2,STONE:3)
Block(-7,52,3,STONE:3)
Block(-7,52,4,STONE:3)
Block(-7,53,-7,OBSIDIAN:0)
Block(-7,53,-6,OBSIDIAN:0)
Block(-7,53,-5,OBSIDIAN:0)
Block(-7,53,-4,OBSIDIAN:0)
Block(-7,53,-3,OBSIDIAN:0)
Block(-7,53,-2,OBSIDIAN:0)
Block(-7,53,-1,STONE:3)
Block(-7,53,0,STONE:3)
Block(-7,53,1,STONE:3)
Block(-7,53,2,STONE:3)
Block(-7,53,3,STONE:3)
Block(-7,53,4,STONE:3)
Block(-7,53,5,STONE:3)
Block(-7,54,-7,OBSIDIAN:0)
Block(-7,54,-6,OBSIDIAN:0)
Block(-7,54,-5,STONE:3)
Block(-7,54,-4,STONE:3)
Block(-7,54,-3,STONE:3)
Block(-7,54,-2,STONE:3)
Block(-7,54,-1,STONE:3)
Block(-7,54,0,STONE:3)
Block(-7,54,1,STONE:3)
Block(-7,54,2,STONE:3)
Block(-7,54,3,STONE:3)
Block(-7,54,4,STONE:3)
Block(-7,55,-7,OBSIDIAN:0)
Block(-7,55,-6,STONE:3)
Block(-7,55,-5,STONE:3)
Block(-7,55,-4,STONE:3)
Block(-7,55,-3,STONE:3)
Block(-7,55,-2,STONE:3)
Block(-7,55,-1,STONE:3)
Block(-7,55,0,STONE:3)
Block(-7,55,1,STONE:3)
Block(-7,55,2,STONE:3)
Block(-7,55,3,STONE:3)
Block(-7,55,4,STONE:3)
Block(-7,56,-7,STONE:3)
Block(-7,56,-6,STONE:3)
Block(-7,56,-5,STONE:3)
Block(-7,56,-4,STONE:3)
Block(-7,56,-3,STONE:3)
Block(-7,56,-2,STONE:3)
Block(-7,56,-1,STONE:3)
Block(-7,56,0,STONE:3)
Block(-7,56,1,STONE:3)
Block(-7,56,2,STONE:3)
Block(-7,56,3,STONE:3)
Block(-7,57,-7,STONE:3)
Block(-7,57,-6,STONE:3)
Block(-7,57,-5,STONE:3)
Block(-7,57,-4,STONE:3)
Block(-7,57,-3,STONE:3)
Block(-7,57,-2,STONE:3)
Block(-7,57,-1,STONE:3)
Block(-7,57,0,STONE:3)
Block(-7,57,1,STONE:3)
Block(-7,57,2,STONE:3)
Block(-7,58,-7,STONE:3)
Block(-7,58,-6,STONE:3)
Block(-7,58,-5,STONE:3)
Block(-7,58,-4,STONE:3)
Block(-7,58,-3,STONE:3)
Block(-7,58,0,STONE:3)
Block(-7,59,-7,OBSIDIAN:0)
Block(-7,59,-6,STONE:3)
Block(-7,59,-5,STONE:3)
Block(-7,59,-4,STONE:3)
Block(-7,60,-7,OBSIDIAN:0)
Block(-7,60,-6,OBSIDIAN:0)
Block(-7,60,-5,STONE:3)
Block(-7,60,-4,STONE:3)
Block(-7,61,-7,OBSIDIAN:0)
Block(-7,61,-6,OBSIDIAN:0)
Block(-7,61,-5,STONE:3)
Block(-6,25,-7,STONE:3)
Block(-6,25,-6,STONE:3)
Block(-6,26,-7,STONE:3)
Block(-6,26,-6,STONE:3)
Block(-6,27,-7,STONE:3)
Block(-6,27,-6,STONE:3)
Block(-6,27,-5,STONE:3)
Block(-6,28,-7,STONE:3)
Block(-6,28,-6,STONE:3)
Block(-6,28,-5,STONE:3)
Block(-6,28,-4,STONE:3)
Block(-6,29,-7,STONE:3)
Block(-6,29,-6,STONE:3)
Block(-6,29,-5,STONE:3)
Block(-6,29,-4,STONE:3)
Block(-6,29,-3,STONE:3)
Block(-6,29,-2,STONE:3)
Block(-6,30,-7,STONE:3)
Block(-6,30,-6,STONE:3)
Block(-6,30,-5,STONE:3)
Block(-6,30,-4,STONE:3)
Block(-6,30,-3,STONE:3)
Block(-6,30,-2,STONE:3)
Block(-6,31,-7,STONE:3)
Block(-6,31,-6,STONE:3)
Block(-6,31,-5,STONE:3)
Block(-6,31,-4,STONE:3)
Block(-6,31,-3,STONE:3)
Block(-6,31,-2,STONE:3)
Block(-6,31,-1,STONE:3)
Block(-6,32,-7,STONE:3)
Block(-6,32,-6,STONE:3)
Block(-6,32,-5,STONE:3)
Block(-6,32,-4,STONE:3)
Block(-6,32,-3,STONE:3)
Block(-6,32,-2,STONE:3)
Block(-6,32,-1,STONE:3)
Block(-6,32,0,STONE:3)
Block(-6,33,-7,STONE:3)
Block(-6,33,-6,STONE:3)
Block(-6,33,-5,STONE:3)
Block(-6,33,-4,STONE:3)
Block(-6,33,-3,STONE:3)
Block(-6,33,-2,STONE:3)
Block(-6,33,-1,STONE:3)
Block(-6,33,0,STONE:3)
Block(-6,33,1,STONE:3)
Block(-6,34,-7,OBSIDIAN:0)
Block(-6,34,-6,OBSIDIAN:0)
Block(-6,34,-5,STONE:3)
Block(-6,34,-4,STONE:3)
Block(-6,34,-3,STONE:3)
Block(-6,34,-2,STONE:3)
Block(-6,34,-1,STONE:3)
Block(-6,34,0,STONE:3)
Block(-6,34,1,STONE:3)
Block(-6,34,2,STONE:3)
Block(-6,35,-7,OBSIDIAN:0)
Block(-6,35,-6,OBSIDIAN:0)
Block(-6,35,-5,OBSIDIAN:0)
Block(-6,35,-4,STONE:3)
Block(-6,35,-3,STONE:3)
Block(-6,35,-2,STONE:3)
Block(-6,35,-1,STONE:3)
Block(-6,35,0,STONE:3)
Block(-6,35,1,STONE:3)
Block(-6,35,2,STONE:3)
Block(-6,36,-7,OBSIDIAN:0)
Block(-6,36,-6,OBSIDIAN:0)
Block(-6,36,-5,OBSIDIAN:0)
Block(-6,36,-4,STONE:3)
Block(-6,36,-3,STONE:3)
Block(-6,36,-2,STONE:3)
Block(-6,36,-1,STONE:3)
Block(-6,36,0,STONE:3)
Block(-6,36,1,STONE:3)
Block(-6,37,-7,OBSIDIAN:0)
Block(-6,37,-6,OBSIDIAN:0)
Block(-6,37,-5,OBSIDIAN:0)
Block(-6,37,-4,OBSIDIAN:0)
Block(-6,37,-3,STONE:3)
Block(-6,37,-2,STONE:3)
Block(-6,37,-1,STONE:3)
Block(-6,37,0,STONE:3)
Block(-6,37,1,STONE:3)
Block(-6,37,2,STONE:3)
Block(-6,38,-7,OBSIDIAN:0)
Block(-6,38,-6,OBSIDIAN:0)
Block(-6,38,-5,OBSIDIAN:0)
Block(-6,38,-4,OBSIDIAN:0)
Block(-6,38,-3,STONE:3)
Block(-6,38,-2,STONE:3)
Block(-6,38,-1,STONE:3)
Block(-6,38,0,STONE:3)
Block(-6,38,1,STONE:3)
Block(-6,38,2,STONE:3)
Block(-6,39,-7,OBSIDIAN:0)
Block(-6,39,-6,OBSIDIAN:0)
Block(-6,39,-5,OBSIDIAN:0)
Block(-6,39,-4,OBSIDIAN:0)
Block(-6,39,-3,STONE:3)
Block(-6,39,-2,STONE:3)
Block(-6,39,-1,STONE:3)
Block(-6,39,0,STONE:3)
Block(-6,39,1,STONE:3)
Block(-6,39,2,STONE:3)
Block(-6,39,3,STONE:3)
Block(-6,40,-7,OBSIDIAN:0)
Block(-6,40,-6,OBSIDIAN:0)
Block(-6,40,-5,OBSIDIAN:0)
Block(-6,40,-4,OBSIDIAN:0)
Block(-6,40,-3,STONE:3)
Block(-6,40,-2,STONE:3)
Block(-6,40,-1,STONE:3)
Block(-6,40,0,STONE:3)
Block(-6,40,1,STONE:3)
Block(-6,40,2,STONE:3)
Block(-6,40,3,STONE:3)
Block(-6,41,-7,OBSIDIAN:0)
Block(-6,41,-6,OBSIDIAN:0)
Block(-6,41,-5,OBSIDIAN:0)
Block(-6,41,-4,OBSIDIAN:0)
Block(-6,41,-3,STONE:3)
Block(-6,41,-2,STONE:3)
Block(-6,41,-1,STONE:3)
Block(-6,41,0,STONE:3)
Block(-6,41,1,STONE:3)
Block(-6,41,2,STONE:3)
Block(-6,41,3,STONE:3)
Block(-6,42,-7,OBSIDIAN:0)
Block(-6,42,-6,OBSIDIAN:0)
Block(-6,42,-5,OBSIDIAN:0)
Block(-6,42,-4,OBSIDIAN:0)
Block(-6,42,-3,STONE:3)
Block(-6,42,-2,STONE:3)
Block(-6,42,-1,STONE:3)
Block(-6,42,0,STONE:3)
Block(-6,42,1,STONE:3)
Block(-6,42,2,STONE:3)
Block(-6,42,3,STONE:3)
Block(-6,43,-7,OBSIDIAN:0)
Block(-6,43,-6,OBSIDIAN:0)
Block(-6,43,-5,OBSIDIAN:0)
Block(-6,43,-4,OBSIDIAN:0)
Block(-6,43,-3,OBSIDIAN:0)
Block(-6,43,-2,STONE:3)
Block(-6,43,-1,STONE:3)
Block(-6,43,0,STONE:3)
Block(-6,43,1,STONE:3)
Block(-6,43,2,STONE:3)
Block(-6,43,3,STONE:3)
Block(-6,44,-7,OBSIDIAN:0)
Block(-6,44,-6,OBSIDIAN:0)
Block(-6,44,-5,OBSIDIAN:0)
Block(-6,44,-4,OBSIDIAN:0)
Block(-6,44,-3,OBSIDIAN:0)
Block(-6,44,-2,OBSIDIAN:0)
Block(-6,44,-1,STONE:3)
Block(-6,44,0,STONE:3)
Block(-6,44,1,STONE:3)
Block(-6,44,2,STONE:3)
Block(-6,44,3,STONE:3)
Block(-6,45,-7,OBSIDIAN:0)
Block(-6,45,-6,OBSIDIAN:0)
Block(-6,45,-5,OBSIDIAN:0)
Block(-6,45,-4,OBSIDIAN:0)
Block(-6,45,-3,OBSIDIAN:0)
Block(-6,45,-2,OBSIDIAN:0)
Block(-6,45,-1,STONE:3)
Block(-6,45,0,STONE:3)
Block(-6,45,1,STONE:3)
Block(-6,45,2,STONE:3)
Block(-6,45,3,STONE:3)
Block(-6,45,4,STONE:3)
Block(-6,46,-7,OBSIDIAN:0)
Block(-6,46,-6,OBSIDIAN:0)
Block(-6,46,-5,OBSIDIAN:0)
Block(-6,46,-4,OBSIDIAN:0)
Block(-6,46,-3,OBSIDIAN:0)
Block(-6,46,-2,OBSIDIAN:0)
Block(-6,46,-1,STONE:3)
Block(-6,46,0,STONE:3)
Block(-6,46,1,STONE:3)
Block(-6,46,2,STONE:3)
Block(-6,46,3,STONE:3)
Block(-6,46,4,STONE:3)
Block(-6,47,-7,OBSIDIAN:0)
Block(-6,47,-6,OBSIDIAN:0)
Block(-6,47,-5,OBSIDIAN:0)
Block(-6,47,-4,OBSIDIAN:0)
Block(-6,47,-3,OBSIDIAN:0)
Block(-6,47,-2,OBSIDIAN:0)
Block(-6,47,-1,STONE:3)
Block(-6,47,0,STONE:3)
Block(-6,47,1,STONE:3)
Block(-6,47,2,STONE:3)
Block(-6,47,3,STONE:3)
Block(-6,47,4,STONE:3)
Block(-6,48,-7,OBSIDIAN:0)
Block(-6,48,-6,OBSIDIAN:0)
Block(-6,48,-5,OBSIDIAN:0)
Block(-6,48,-4,OBSIDIAN:0)
Block(-6,48,-3,OBSIDIAN:0)
Block(-6,48,-2,OBSIDIAN:0)
Block(-6,48,-1,STONE:3)
Block(-6,48,0,STONE:3)
Block(-6,48,1,STONE:3)
Block(-6,48,2,STONE:3)
Block(-6,48,3,STONE:3)
Block(-6,48,4,STONE:3)
Block(-6,49,-7,OBSIDIAN:0)
Block(-6,49,-6,OBSIDIAN:0)
Block(-6,49,-5,OBSIDIAN:0)
Block(-6,49,-4,OBSIDIAN:0)
Block(-6,49,-3,OBSIDIAN:0)
Block(-6,49,-2,OBSIDIAN:0)
Block(-6,49,-1,OBSIDIAN:0)
Block(-6,49,0,STONE:3)
Block(-6,49,1,STONE:3)
Block(-6,49,2,STONE:3)
Block(-6,49,3,STONE:3)
Block(-6,49,4,STONE:3)
Block(-6,50,-7,OBSIDIAN:0)
Block(-6,50,-6,OBSIDIAN:0)
Block(-6,50,-5,OBSIDIAN:0)
Block(-6,50,-4,OBSIDIAN:0)
Block(-6,50,-3,OBSIDIAN:0)
Block(-6,50,-2,OBSIDIAN:0)
Block(-6,50,-1,OBSIDIAN:0)
Block(-6,50,0,OBSIDIAN:0)
Block(-6,50,1,STONE:3)
Block(-6,50,2,STONE:3)
Block(-6,50,3,STONE:3)
Block(-6,50,4,STONE:3)
Block(-6,51,-7,OBSIDIAN:0)
Block(-6,51,-6,OBSIDIAN:0)
Block(-6,51,-5,OBSIDIAN:0)
Block(-6,51,-4,OBSIDIAN:0)
Block(-6,51,-3,OBSIDIAN:0)
Block(-6,51,-2,OBSIDIAN:0)
Block(-6,51,-1,OBSIDIAN:0)
Block(-6,51,0,OBSIDIAN:0)
Block(-6,51,1,STONE:3)
Block(-6,51,2,STONE:3)
Block(-6,51,3,STONE:3)
Block(-6,51,4,STONE:3)
Block(-6,52,-7,OBSIDIAN:0)
Block(-6,52,-6,OBSIDIAN:0)
Block(-6,52,-5,OBSIDIAN:0)
Block(-6,52,-4,OBSIDIAN:0)
Block(-6,52,-3,OBSIDIAN:0)
Block(-6,52,-2,OBSIDIAN:0)
Block(-6,52,-1,OBSIDIAN:0)
Block(-6,52,0,STONE:3)
Block(-6,52,1,STONE:3)
Block(-6,52,2,STONE:3)
Block(-6,52,3,STONE:3)
Block(-6,52,4,STONE:3)
Block(-6,53,-7,OBSIDIAN:0)
Block(-6,53,-6,OBSIDIAN:0)
Block(-6,53,-5,OBSIDIAN:0)
Block(-6,53,-4,OBSIDIAN:0)
Block(-6,53,-3,OBSIDIAN:0)
Block(-6,53,-2,OBSIDIAN:0)
Block(-6,53,-1,STONE:3)
Block(-6,53,0,STONE:3)
Block(-6,53,1,STONE:3)
Block(-6,53,2,STONE:3)
Block(-6,53,3,STONE:3)
Block(-6,53,4,STONE:3)
Block(-6,53,5,STONE:3)
Block(-6,54,-7,OBSIDIAN:0)
Block(-6,54,-6,OBSIDIAN:0)
Block(-6,54,-5,OBSIDIAN:0)
Block(-6,54,-4,OBSIDIAN:0)
Block(-6,54,-3,OBSIDIAN:0)
Block(-6,54,-2,OBSIDIAN:0)
Block(-6,54,-1,STONE:3)
Block(-6,54,0,STONE:3)
Block(-6,54,1,STONE:3)
Block(-6,54,2,STONE:3)
Block(-6,54,3,STONE:3)
Block(-6,54,4,STONE:3)
Block(-6,54,5,STONE:3)
Block(-6,55,-7,OBSIDIAN:0)
Block(-6,55,-6,OBSIDIAN:0)
Block(-6,55,-5,STONE:3)
Block(-6,55,-4,STONE:3)
Block(-6,55,-3,STONE:3)
Block(-6,55,-2,STONE:3)
Block(-6,55,-1,STONE:3)
Block(-6,55,0,STONE:3)
Block(-6,55,1,STONE:3)
Block(-6,55,2,STONE:3)
Block(-6,55,3,STONE:3)
Block(-6,55,4,STONE:3)
Block(-6,56,-7,OBSIDIAN:0)
Block(-6,56,-6,STONE:3)
Block(-6,56,-5,STONE:3)
Block(-6,56,-4,STONE:3)
Block(-6,56,-3,STONE:3)
Block(-6,56,-2,STONE:3)
Block(-6,56,-1,STONE:3)
Block(-6,56,0,STONE:3)
Block(-6,56,1,STONE:3)
Block(-6,56,2,STONE:3)
Block(-6,56,3,STONE:3)
Block(-6,56,4,STONE:3)
Block(-6,57,-7,STONE:3)
Block(-6,57,-6,STONE:3)
Block(-6,57,-5,STONE:3)
Block(-6,57,-4,STONE:3)
Block(-6,57,-3,STONE:3)
Block(-6,57,-2,STONE:3)
Block(-6,57,-1,STONE:3)
Block(-6,57,0,STONE:3)
Block(-6,57,1,STONE:3)
Block(-6,57,2,STONE:3)
Block(-6,58,-7,OBSIDIAN:0)
Block(-6,58,-6,STONE:3)
Block(-6,58,-5,OBSIDIAN:0)
Block(-6,58,-4,OBSIDIAN:0)
Block(-6,58,-3,OBSIDIAN:0)
Block(-6,58,-2,STONE:3)
Block(-6,58,-1,STONE:3)
Block(-6,58,0,STONE:3)
Block(-6,58,1,STONE:3)
Block(-6,59,-7,OBSIDIAN:0)
Block(-6,59,-6,OBSIDIAN:0)
Block(-6,59,-5,OBSIDIAN:0)
Block(-6,59,-4,OBSIDIAN:0)
Block(-6,60,-7,OBSIDIAN:0)
Block(-6,60,-6,OBSIDIAN:0)
Block(-6,60,-5,OBSIDIAN:0)
Block(-6,61,-6,OBSIDIAN:0)
Block(-5,24,-7,STONE:3)
Block(-5,25,-7,STONE:3)
Block(-5,25,-6,STONE:3)
Block(-5,26,-7,STONE:3)
Block(-5,26,-6,STONE:3)
Block(-5,26,-5,STONE:3)
Block(-5,27,-7,STONE:3)
Block(-5,27,-6,STONE:3)
Block(-5,27,-5,STONE:3)
Block(-5,27,-4,STONE:3)
Block(-5,28,-7,STONE:3)
Block(-5,28,-6,STONE:3)
Block(-5,28,-5,STONE:3)
Block(-5,28,-4,STONE:3)
Block(-5,29,-7,STONE:3)
Block(-5,29,-6,STONE:3)
Block(-5,29,-5,STONE:3)
Block(-5,29,-4,STONE:3)
Block(-5,29,-3,STONE:3)
Block(-5,30,-7,STONE:3)
Block(-5,30,-6,STONE:3)
Block(-5,30,-5,STONE:3)
Block(-5,30,-4,STONE:3)
Block(-5,30,-3,STONE:3)
Block(-5,30,-2,STONE:3)
Block(-5,31,-7,STONE:3)
Block(-5,31,-6,STONE:3)
Block(-5,31,-5,STONE:3)
Block(-5,31,-4,STONE:3)
Block(-5,31,-3,STONE:3)
Block(-5,31,-2,STONE:3)
Block(-5,31,-1,STONE:3)
Block(-5,32,-7,STONE:3)
Block(-5,32,-6,STONE:3)
Block(-5,32,-5,STONE:3)
Block(-5,32,-4,STONE:3)
Block(-5,32,-3,STONE:3)
Block(-5,32,-2,STONE:3)
Block(-5,32,-1,STONE:3)
Block(-5,32,0,STONE:3)
Block(-5,33,-7,OBSIDIAN:0)
Block(-5,33,-6,STONE:3)
Block(-5,33,-5,STONE:3)
Block(-5,33,-4,STONE:3)
Block(-5,33,-3,STONE:3)
Block(-5,33,-2,STONE:3)
Block(-5,33,-1,STONE:3)
Block(-5,33,0,STONE:3)
Block(-5,34,-7,OBSIDIAN:0)
Block(-5,34,-6,OBSIDIAN:0)
Block(-5,34,-5,STONE:3)
Block(-5,34,-4,STONE:3)
Block(-5,34,-3,STONE:3)
Block(-5,34,-2,STONE:3)
Block(-5,34,-1,STONE:3)
Block(-5,34,0,STONE:3)
Block(-5,34,1,STONE:3)
Block(-5,35,-7,OBSIDIAN:0)
Block(-5,35,-6,OBSIDIAN:0)
Block(-5,35,-5,STONE:3)
Block(-5,35,-4,STONE:3)
Block(-5,35,-3,STONE:3)
Block(-5,35,-2,STONE:3)
Block(-5,35,-1,STONE:3)
Block(-5,35,0,STONE:3)
Block(-5,35,1,STONE:3)
Block(-5,36,-7,OBSIDIAN:0)
Block(-5,36,-6,OBSIDIAN:0)
Block(-5,36,-5,OBSIDIAN:0)
Block(-5,36,-4,STONE:3)
Block(-5,36,-3,STONE:3)
Block(-5,36,-2,STONE:3)
Block(-5,36,-1,STONE:3)
Block(-5,36,0,STONE:3)
Block(-5,36,1,STONE:3)
Block(-5,37,-7,OBSIDIAN:0)
Block(-5,37,-6,OBSIDIAN:0)
Block(-5,37,-5,OBSIDIAN:0)
Block(-5,37,-4,STONE:3)
Block(-5,37,-3,STONE:3)
Block(-5,37,-2,STONE:3)
Block(-5,37,-1,STONE:3)
Block(-5,37,0,STONE:3)
Block(-5,37,1,STONE:3)
Block(-5,38,-7,OBSIDIAN:0)
Block(-5,38,-6,OBSIDIAN:0)
Block(-5,38,-5,OBSIDIAN:0)
Block(-5,38,-4,OBSIDIAN:0)
Block(-5,38,-3,STONE:3)
Block(-5,38,-2,STONE:3)
Block(-5,38,-1,STONE:3)
Block(-5,38,0,STONE:3)
Block(-5,38,1,STONE:3)
Block(-5,39,-7,OBSIDIAN:0)
Block(-5,39,-6,OBSIDIAN:0)
Block(-5,39,-5,OBSIDIAN:0)
Block(-5,39,-4,STONE:3)
Block(-5,39,-3,STONE:3)
Block(-5,39,-2,STONE:3)
Block(-5,39,-1,STONE:3)
Block(-5,39,0,STONE:3)
Block(-5,39,1,STONE:3)
Block(-5,39,2,STONE:3)
Block(-5,40,-7,OBSIDIAN:0)
Block(-5,40,-6,OBSIDIAN:0)
Block(-5,40,-5,OBSIDIAN:0)
Block(-5,40,-4,STONE:3)
Block(-5,40,-3,STONE:3)
Block(-5,40,-2,STONE:3)
Block(-5,40,-1,STONE:3)
Block(-5,40,0,STONE:3)
Block(-5,40,1,STONE:3)
Block(-5,40,2,STONE:3)
Block(-5,41,-7,OBSIDIAN:0)
Block(-5,41,-6,OBSIDIAN:0)
Block(-5,41,-5,OBSIDIAN:0)
Block(-5,41,-4,STONE:3)
Block(-5,41,-3,STONE:3)
Block(-5,41,-2,STONE:3)
Block(-5,41,-1,STONE:3)
Block(-5,41,0,STONE:3)
Block(-5,41,1,STONE:3)
Block(-5,41,2,STONE:3)
Block(-5,41,3,STONE:3)
Block(-5,42,-7,OBSIDIAN:0)
Block(-5,42,-6,OBSIDIAN:0)
Block(-5,42,-5,OBSIDIAN:0)
Block(-5,42,-4,OBSIDIAN:0)
Block(-5,42,-3,STONE:3)
Block(-5,42,-2,STONE:3)
Block(-5,42,-1,STONE:3)
Block(-5,42,0,STONE:3)
Block(-5,42,1,STONE:3)
Block(-5,42,2,STONE:3)
Block(-5,42,3,STONE:3)
Block(-5,43,-7,OBSIDIAN:0)
Block(-5,43,-6,OBSIDIAN:0)
Block(-5,43,-5,OBSIDIAN:0)
Block(-5,43,-4,OBSIDIAN:0)
Block(-5,43,-3,STONE:3)
Block(-5,43,-2,STONE:3)
Block(-5,43,-1,STONE:3)
Block(-5,43,0,STONE:3)
Block(-5,43,1,STONE:3)
Block(-5,43,2,STONE:3)
Block(-5,43,3,STONE:3)
Block(-5,44,-7,OBSIDIAN:0)
Block(-5,44,-6,OBSIDIAN:0)
Block(-5,44,-5,OBSIDIAN:0)
Block(-5,44,-4,OBSIDIAN:0)
Block(-5,44,-3,OBSIDIAN:0)
Block(-5,44,-2,STONE:3)
Block(-5,44,-1,STONE:3)
Block(-5,44,0,STONE:3)
Block(-5,44,1,STONE:3)
Block(-5,44,2,STONE:3)
Block(-5,44,3,STONE:3)
Block(-5,45,-7,OBSIDIAN:0)
Block(-5,45,-6,OBSIDIAN:0)
Block(-5,45,-5,OBSIDIAN:0)
Block(-5,45,-4,OBSIDIAN:0)
Block(-5,45,-3,OBSIDIAN:0)
Block(-5,45,-2,OBSIDIAN:0)
Block(-5,45,-1,STONE:3)
Block(-5,45,0,STONE:3)
Block(-5,45,1,STONE:3)
Block(-5,45,2,STONE:3)
Block(-5,45,3,STONE:3)
Block(-5,46,-7,OBSIDIAN:0)
Block(-5,46,-6,OBSIDIAN:0)
Block(-5,46,-5,OBSIDIAN:0)
Block(-5,46,-4,OBSIDIAN:0)
Block(-5,46,-3,OBSIDIAN:0)
Block(-5,46,-2,OBSIDIAN:0)
Block(-5,46,-1,STONE:3)
Block(-5,46,0,STONE:3)
Block(-5,46,1,STONE:3)
Block(-5,46,2,STONE:3)
Block(-5,46,3,STONE:3)
Block(-5,46,4,STONE:3)
Block(-5,47,-7,OBSIDIAN:0)
Block(-5,47,-6,OBSIDIAN:0)
Block(-5,47,-5,OBSIDIAN:0)
Block(-5,47,-4,OBSIDIAN:0)
Block(-5,47,-3,OBSIDIAN:0)
Block(-5,47,-2,OBSIDIAN:0)
Block(-5,47,-1,STONE:3)
Block(-5,47,0,STONE:3)
Block(-5,47,1,STONE:3)
Block(-5,47,2,STONE:3)
Block(-5,47,3,STONE:3)
Block(-5,47,4,STONE:3)
Block(-5,48,-7,OBSIDIAN:0)
Block(-5,48,-6,OBSIDIAN:0)
Block(-5,48,-5,OBSIDIAN:0)
Block(-5,48,-4,OBSIDIAN:0)
Block(-5,48,-3,OBSIDIAN:0)
Block(-5,48,-2,OBSIDIAN:0)
Block(-5,48,-1,STONE:3)
Block(-5,48,0,STONE:3)
Block(-5,48,1,STONE:3)
Block(-5,48,2,STONE:3)
Block(-5,48,3,STONE:3)
Block(-5,48,4,STONE:3)
Block(-5,49,-7,OBSIDIAN:0)
Block(-5,49,-6,OBSIDIAN:0)
Block(-5,49,-5,OBSIDIAN:0)
Block(-5,49,-4,OBSIDIAN:0)
Block(-5,49,-3,OBSIDIAN:0)
Block(-5,49,-2,OBSIDIAN:0)
Block(-5,49,-1,OBSIDIAN:0)
Block(-5,49,0,STONE:3)
Block(-5,49,1,STONE:3)
Block(-5,49,2,STONE:3)
Block(-5,49,3,STONE:3)
Block(-5,49,4,STONE:3)
Block(-5,50,-7,OBSIDIAN:0)
Block(-5,50,-6,OBSIDIAN:0)
Block(-5,50,-5,OBSIDIAN:0)
Block(-5,50,-4,OBSIDIAN:0)
Block(-5,50,-3,OBSIDIAN:0)
Block(-5,50,-2,OBSIDIAN:0)
Block(-5,50,-1,OBSIDIAN:0)
Block(-5,50,0,OBSIDIAN:0)
Block(-5,50,1,STONE:3)
Block(-5,50,2,STONE:3)
Block(-5,50,3,STONE:3)
Block(-5,50,4,STONE:3)
Block(-5,50,5,STONE:3)
Block(-5,51,-7,OBSIDIAN:0)
Block(-5,51,-6,OBSIDIAN:0)
Block(-5,51,-5,OBSIDIAN:0)
Block(-5,51,-4,OBSIDIAN:0)
Block(-5,51,-3,OBSIDIAN:0)
Block(-5,51,-2,OBSIDIAN:0)
Block(-5,51,-1,OBSIDIAN:0)
Block(-5,51,0,OBSIDIAN:0)
Block(-5,51,1,STONE:3)
Block(-5,51,2,STONE:3)
Block(-5,51,3,STONE:3)
Block(-5,51,4,STONE:3)
Block(-5,51,5,STONE:3)
Block(-5,52,-7,OBSIDIAN:0)
Block(-5,52,-6,OBSIDIAN:0)
Block(-5,52,-5,OBSIDIAN:0)
Block(-5,52,-4,OBSIDIAN:0)
Block(-5,52,-3,OBSIDIAN:0)
Block(-5,52,-2,OBSIDIAN:0)
Block(-5,52,-1,OBSIDIAN:0)
Block(-5,52,0,STONE:3)
Block(-5,52,1,STONE:3)
Block(-5,52,2,STONE:3)
Block(-5,52,3,STONE:3)
Block(-5,52,4,STONE:3)
Block(-5,52,5,STONE:3)
Block(-5,53,-7,OBSIDIAN:0)
Block(-5,53,-6,OBSIDIAN:0)
Block(-5,53,-5,OBSIDIAN:0)
Block(-5,53,-4,OBSIDIAN:0)
Block(-5,53,-3,OBSIDIAN:0)
Block(-5,53,-2,OBSIDIAN:0)
Block(-5,53,-1,OBSIDIAN:0)
Block(-5,53,0,STONE:3)
Block(-5,53,1,STONE:3)
Block(-5,53,2,STONE:3)
Block(-5,53,3,STONE:3)
Block(-5,53,4,STONE:3)
Block(-5,53,5,STONE:3)
Block(-5,54,-7,OBSIDIAN:0)
Block(-5,54,-6,OBSIDIAN:0)
Block(-5,54,-5,OBSIDIAN:0)
Block(-5,54,-4,OBSIDIAN:0)
Block(-5,54,-3,OBSIDIAN:0)
Block(-5,54,-2,OBSIDIAN:0)
Block(-5,54,-1,STONE:3)
Block(-5,54,0,STONE:3)
Block(-5,54,1,STONE:3)
Block(-5,54,2,STONE:3)
Block(-5,54,3,STONE:3)
Block(-5,54,4,STONE:3)
Block(-5,54,5,STONE:3)
Block(-5,55,-7,OBSIDIAN:0)
Block(-5,55,-6,OBSIDIAN:0)
Block(-5,55,-5,OBSIDIAN:0)
Block(-5,55,-4,OBSIDIAN:0)
Block(-5,55,-3,OBSIDIAN:0)
Block(-5,55,-2,OBSIDIAN:0)
Block(-5,55,-1,STONE:3)
Block(-5,55,0,STONE:3)
Block(-5,55,1,STONE:3)
Block(-5,55,2,STONE:3)
Block(-5,55,3,STONE:3)
Block(-5,55,4,STONE:3)
Block(-5,55,5,STONE:3)
Block(-5,56,-7,OBSIDIAN:0)
Block(-5,56,-6,OBSIDIAN:0)
Block(-5,56,-5,OBSIDIAN:0)
Block(-5,56,-4,STONE:3)
Block(-5,56,-3,STONE:3)
Block(-5,56,-2,STONE:3)
Block(-5,56,-1,STONE:3)
Block(-5,56,0,STONE:3)
Block(-5,56,1,STONE:3)
Block(-5,56,2,STONE:3)
Block(-5,56,3,STONE:3)
Block(-5,56,4,STONE:3)
Block(-5,57,-7,OBSIDIAN:0)
Block(-5,57,-6,OBSIDIAN:0)
Block(-5,57,-5,OBSIDIAN:0)
Block(-5,57,-4,OBSIDIAN:0)
Block(-5,57,-3,OBSIDIAN:0)
Block(-5,57,-2,OBSIDIAN:0)
Block(-5,57,-1,STONE:3)
Block(-5,57,0,STONE:3)
Block(-5,57,1,STONE:3)
Block(-5,57,2,STONE:3)
Block(-5,57,3,STONE:3)
Block(-5,57,4,STONE:3)
Block(-5,58,-7,OBSIDIAN:0)
Block(-5,58,-6,OBSIDIAN:0)
Block(-5,58,-5,OBSIDIAN:0)
Block(-5,58,-4,OBSIDIAN:0)
Block(-5,58,-3,OBSIDIAN:0)
Block(-5,58,-2,OBSIDIAN:0)
Block(-5,58,-1,OBSIDIAN:0)
Block(-5,58,0,STONE:3)
Block(-5,58,1,STONE:3)
Block(-5,58,2,STONE:3)
Block(-5,59,-7,OBSIDIAN:0)
Block(-5,59,-6,OBSIDIAN:0)
Block(-5,59,-5,OBSIDIAN:0)
Block(-5,60,-7,OBSIDIAN:0)
Block(-4,24,-7,STONE:3)
Block(-4,25,-7,STONE:3)
Block(-4,25,-6,STONE:3)
Block(-4,25,-5,STONE:3)
Block(-4,26,-7,STONE:3)
Block(-4,26,-6,STONE:3)
Block(-4,26,-5,STONE:3)
Block(-4,27,-7,STONE:3)
Block(-4,27,-6,STONE:3)
Block(-4,27,-5,STONE:3)
Block(-4,27,-4,STONE:3)
Block(-4,28,-7,STONE:3)
Block(-4,28,-6,STONE:3)
Block(-4,28,-5,STONE:3)
Block(-4,28,-4,STONE:3)
Block(-4,29,-7,STONE:3)
Block(-4,29,-6,STONE:3)
Block(-4,29,-5,STONE:3)
Block(-4,29,-4,STONE:3)
Block(-4,29,-3,STONE:3)
Block(-4,30,-7,STONE:3)
Block(-4,30,-6,STONE:3)
Block(-4,30,-5,STONE:3)
Block(-4,30,-4,STONE:3)
Block(-4,30,-3,STONE:3)
Block(-4,30,-2,STONE:3)
Block(-4,31,-7,STONE:3)
Block(-4,31,-6,STONE:3)
Block(-4,31,-5,STONE:3)
Block(-4,31,-4,STONE:3)
Block(-4,31,-3,STONE:3)
Block(-4,31,-2,STONE:3)
Block(-4,31,-1,STONE:3)
Block(-4,32,-7,OBSIDIAN:0)
Block(-4,32,-6,STONE:3)
Block(-4,32,-5,STONE:3)
Block(-4,32,-4,STONE:3)
Block(-4,32,-3,STONE:3)
Block(-4,32,-2,STONE:3)
Block(-4,32,-1,STONE:3)
Block(-4,33,-7,OBSIDIAN:0)
Block(-4,33,-6,OBSIDIAN:0)
Block(-4,33,-5,STONE:3)
Block(-4,33,-4,STONE:3)
Block(-4,33,-3,STONE:3)
Block(-4,33,-2,STONE:3)
Block(-4,33,-1,STONE:3)
Block(-4,33,0,STONE:3)
Block(-4,34,-7,OBSIDIAN:0)
Block(-4,34,-6,OBSIDIAN:0)
Block(-4,34,-5,STONE:3)
Block(-4,34,-4,STONE:3)
Block(-4,34,-3,STONE:3)
Block(-4,34,-2,STONE:3)
Block(-4,34,-1,STONE:3)
Block(-4,34,0,STONE:3)
Block(-4,35,-7,OBSIDIAN:0)
Block(-4,35,-6,OBSIDIAN:0)
Block(-4,35,-5,STONE:3)
Block(-4,35,-4,STONE:3)
Block(-4,35,-3,STONE:3)
Block(-4,35,-2,STONE:3)
Block(-4,35,-1,STONE:3)
Block(-4,35,0,STONE:3)
Block(-4,35,1,STONE:3)
Block(-4,36,-7,OBSIDIAN:0)
Block(-4,36,-6,OBSIDIAN:0)
Block(-4,36,-5,STONE:3)
Block(-4,36,-4,STONE:3)
Block(-4,36,-3,STONE:3)
Block(-4,36,-2,STONE:3)
Block(-4,36,-1,STONE:3)
Block(-4,36,0,STONE:3)
Block(-4,36,1,STONE:3)
Block(-4,37,-7,OBSIDIAN:0)
Block(-4,37,-6,OBSIDIAN:0)
Block(-4,37,-5,OBSIDIAN:0)
Block(-4,37,-4,STONE:3)
Block(-4,37,-3,STONE:3)
Block(-4,37,-2,STONE:3)
Block(-4,37,-1,STONE:3)
Block(-4,37,0,STONE:3)
Block(-4,38,-7,OBSIDIAN:0)
Block(-4,38,-6,OBSIDIAN:0)
Block(-4,38,-5,OBSIDIAN:0)
Block(-4,38,-4,STONE:3)
Block(-4,38,-3,STONE:3)
Block(-4,38,-2,STONE:3)
Block(-4,38,-1,STONE:3)
Block(-4,38,0,STONE:3)
Block(-4,38,1,STONE:3)
Block(-4,39,-7,OBSIDIAN:0)
Block(-4,39,-6,OBSIDIAN:0)
Block(-4,39,-5,OBSIDIAN:0)
Block(-4,39,-4,STONE:3)
Block(-4,39,-3,STONE:3)
Block(-4,39,-2,STONE:3)
Block(-4,39,-1,STONE:3)
Block(-4,39,0,STONE:3)
Block(-4,39,1,STONE:3)
Block(-4,40,-7,OBSIDIAN:0)
Block(-4,40,-6,OBSIDIAN:0)
Block(-4,40,-5,OBSIDIAN:0)
Block(-4,40,-4,STONE:3)
Block(-4,40,-3,STONE:3)
Block(-4,40,-2,STONE:3)
Block(-4,40,-1,STONE:3)
Block(-4,40,0,STONE:3)
Block(-4,40,1,STONE:3)
Block(-4,40,2,STONE:3)
Block(-4,41,-7,OBSIDIAN:0)
Block(-4,41,-6,OBSIDIAN:0)
Block(-4,41,-5,OBSIDIAN:0)
Block(-4,41,-4,STONE:3)
Block(-4,41,-3,STONE:3)
Block(-4,41,-2,STONE:3)
Block(-4,41,-1,STONE:3)
Block(-4,41,0,STONE:3)
Block(-4,41,1,STONE:3)
Block(-4,41,2,STONE:3)
Block(-4,41,3,STONE:3)
Block(-4,42,-7,OBSIDIAN:0)
Block(-4,42,-6,OBSIDIAN:0)
Block(-4,42,-5,OBSIDIAN:0)
Block(-4,42,-4,STONE:3)
Block(-4,42,-3,STONE:3)
Block(-4,42,-2,STONE:3)
Block(-4,42,-1,STONE:3)
Block(-4,42,0,STONE:3)
Block(-4,42,1,STONE:3)
Block(-4,42,2,STONE:3)
Block(-4,42,3,STONE:3)
Block(-4,43,-7,OBSIDIAN:0)
Block(-4,43,-6,OBSIDIAN:0)
Block(-4,43,-5,OBSIDIAN:0)
Block(-4,43,-4,OBSIDIAN:0)
Block(-4,43,-3,STONE:3)
Block(-4,43,-2,STONE:3)
Block(-4,43,-1,STONE:3)
Block(-4,43,0,STONE:3)
Block(-4,43,1,STONE:3)
Block(-4,43,2,STONE:3)
Block(-4,43,3,STONE:3)
Block(-4,44,-7,OBSIDIAN:0)
Block(-4,44,-6,OBSIDIAN:0)
Block(-4,44,-5,OBSIDIAN:0)
Block(-4,44,-4,OBSIDIAN:0)
Block(-4,44,-3,OBSIDIAN:0)
Block(-4,44,-2,STONE:3)
Block(-4,44,-1,STONE:3)
Block(-4,44,0,STONE:3)
Block(-4,44,1,STONE:3)
Block(-4,44,2,STONE:3)
Block(-4,44,3,STONE:3)
Block(-4,44,4,STONE:3)
Block(-4,45,-7,OBSIDIAN:0)
Block(-4,45,-6,OBSIDIAN:0)
Block(-4,45,-5,OBSIDIAN:0)
Block(-4,45,-4,OBSIDIAN:0)
Block(-4,45,-3,OBSIDIAN:0)
Block(-4,45,-2,OBSIDIAN:0)
Block(-4,45,-1,STONE:3)
Block(-4,45,0,STONE:3)
Block(-4,45,1,STONE:3)
Block(-4,45,2,STONE:3)
Block(-4,45,3,STONE:3)
Block(-4,45,4,STONE:3)
Block(-4,46,-7,OBSIDIAN:0)
Block(-4,46,-6,OBSIDIAN:0)
Block(-4,46,-5,OBSIDIAN:0)
Block(-4,46,-4,OBSIDIAN:0)
Block(-4,46,-3,OBSIDIAN:0)
Block(-4,46,-2,OBSIDIAN:0)
Block(-4,46,-1,STONE:3)
Block(-4,46,0,STONE:3)
Block(-4,46,1,STONE:3)
Block(-4,46,2,STONE:3)
Block(-4,46,3,STONE:3)
Block(-4,46,4,STONE:3)
Block(-4,47,-7,OBSIDIAN:0)
Block(-4,47,-6,OBSIDIAN:0)
Block(-4,47,-5,OBSIDIAN:0)
Block(-4,47,-4,OBSIDIAN:0)
Block(-4,47,-3,OBSIDIAN:0)
Block(-4,47,-2,OBSIDIAN:0)
Block(-4,47,-1,STONE:3)
Block(-4,47,0,STONE:3)
Block(-4,47,1,STONE:3)
Block(-4,47,2,STONE:3)
Block(-4,47,3,STONE:3)
Block(-4,47,4,STONE:3)
Block(-4,48,-7,OBSIDIAN:0)
Block(-4,48,-6,OBSIDIAN:0)
Block(-4,48,-5,OBSIDIAN:0)
Block(-4,48,-4,OBSIDIAN:0)
Block(-4,48,-3,OBSIDIAN:0)
Block(-4,48,-2,OBSIDIAN:0)
Block(-4,48,-1,STONE:3)
Block(-4,48,0,STONE:3)
Block(-4,48,1,STONE:3)
Block(-4,48,2,STONE:3)
Block(-4,48,3,STONE:3)
Block(-4,48,4,STONE:3)
Block(-4,49,-7,OBSIDIAN:0)
Block(-4,49,-6,OBSIDIAN:0)
Block(-4,49,-5,OBSIDIAN:0)
Block(-4,49,-4,OBSIDIAN:0)
Block(-4,49,-3,OBSIDIAN:0)
Block(-4,49,-2,OBSIDIAN:0)
Block(-4,49,-1,OBSIDIAN:0)
Block(-4,49,0,STONE:3)
Block(-4,49,1,STONE:3)
Block(-4,49,2,STONE:3)
Block(-4,49,3,STONE:3)
Block(-4,49,4,STONE:3)
Block(-4,49,5,STONE:3)
Block(-4,50,-7,OBSIDIAN:0)
Block(-4,50,-6,OBSIDIAN:0)
Block(-4,50,-5,OBSIDIAN:0)
Block(-4,50,-4,OBSIDIAN:0)
Block(-4,50,-3,OBSIDIAN:0)
Block(-4,50,-2,OBSIDIAN:0)
Block(-4,50,-1,OBSIDIAN:0)
Block(-4,50,0,OBSIDIAN:0)
Block(-4,50,1,STONE:3)
Block(-4,50,2,STONE:3)
Block(-4,50,3,STONE:3)
Block(-4,50,4,STONE:3)
Block(-4,50,5,STONE:3)
Block(-4,51,-7,OBSIDIAN:0)
Block(-4,51,-6,OBSIDIAN:0)
Block(-4,51,-5,OBSIDIAN:0)
Block(-4,51,-4,OBSIDIAN:0)
Block(-4,51,-3,OBSIDIAN:0)
Block(-4,51,-2,OBSIDIAN:0)
Block(-4,51,-1,OBSIDIAN:0)
Block(-4,51,0,OBSIDIAN:0)
Block(-4,51,1,STONE:3)
Block(-4,51,2,STONE:3)
Block(-4,51,3,STONE:3)
Block(-4,51,4,STONE:3)
Block(-4,51,5,STONE:3)
Block(-4,52,-7,OBSIDIAN:0)
Block(-4,52,-6,OBSIDIAN:0)
Block(-4,52,-5,OBSIDIAN:0)
Block(-4,52,-4,OBSIDIAN:0)
Block(-4,52,-3,OBSIDIAN:0)
Block(-4,52,-2,OBSIDIAN:0)
Block(-4,52,-1,OBSIDIAN:0)
Block(-4,52,0,OBSIDIAN:0)
Block(-4,52,1,STONE:3)
Block(-4,52,2,STONE:3)
Block(-4,52,3,STONE:3)
Block(-4,52,4,STONE:3)
Block(-4,52,5,STONE:3)
Block(-4,53,-7,OBSIDIAN:0)
Block(-4,53,-6,OBSIDIAN:0)
Block(-4,53,-5,OBSIDIAN:0)
Block(-4,53,-4,OBSIDIAN:0)
Block(-4,53,-3,OBSIDIAN:0)
Block(-4,53,-2,OBSIDIAN:0)
Block(-4,53,-1,OBSIDIAN:0)
Block(-4,53,0,STONE:3)
Block(-4,53,1,STONE:3)
Block(-4,53,2,STONE:3)
Block(-4,53,3,STONE:3)
Block(-4,53,4,STONE:3)
Block(-4,53,5,STONE:3)
Block(-4,54,-7,OBSIDIAN:0)
Block(-4,54,-6,OBSIDIAN:0)
Block(-4,54,-5,OBSIDIAN:0)
Block(-4,54,-4,OBSIDIAN:0)
Block(-4,54,-3,OBSIDIAN:0)
Block(-4,54,-2,OBSIDIAN:0)
Block(-4,54,-1,OBSIDIAN:0)
Block(-4,54,0,STONE:3)
Block(-4,54,1,STONE:3)
Block(-4,54,2,STONE:3)
Block(-4,54,3,STONE:3)
Block(-4,54,4,STONE:3)
Block(-4,54,5,STONE:3)
Block(-4,54,6,STONE:3)
Block(-4,55,-7,OBSIDIAN:0)
Block(-4,55,-6,OBSIDIAN:0)
Block(-4,55,-5,OBSIDIAN:0)
Block(-4,55,-4,OBSIDIAN:0)
Block(-4,55,-3,OBSIDIAN:0)
Block(-4,55,-2,OBSIDIAN:0)
Block(-4,55,-1,OBSIDIAN:0)
Block(-4,55,0,STONE:3)
Block(-4,55,1,STONE:3)
Block(-4,55,2,STONE:3)
Block(-4,55,3,STONE:3)
Block(-4,55,4,STONE:3)
Block(-4,55,5,STONE:3)
Block(-4,56,-7,OBSIDIAN:0)
Block(-4,56,-6,OBSIDIAN:0)
Block(-4,56,-5,OBSIDIAN:0)
Block(-4,56,-4,OBSIDIAN:0)
Block(-4,56,-3,OBSIDIAN:0)
Block(-4,56,-2,OBSIDIAN:0)
Block(-4,56,-1,OBSIDIAN:0)
Block(-4,56,0,STONE:3)
Block(-4,56,1,STONE:3)
Block(-4,56,2,STONE:3)
Block(-4,56,3,STONE:3)
Block(-4,56,4,STONE:3)
Block(-4,56,5,STONE:3)
Block(-4,57,-7,OBSIDIAN:0)
Block(-4,57,-6,OBSIDIAN:0)
Block(-4,57,-5,OBSIDIAN:0)
Block(-4,57,-4,OBSIDIAN:0)
Block(-4,57,-3,OBSIDIAN:0)
Block(-4,57,-2,OBSIDIAN:0)
Block(-4,57,-1,OBSIDIAN:0)
Block(-4,57,0,STONE:3)
Block(-4,57,1,STONE:3)
Block(-4,57,2,STONE:3)
Block(-4,57,3,STONE:3)
Block(-4,57,4,STONE:3)
Block(-4,58,-7,OBSIDIAN:0)
Block(-4,58,-6,OBSIDIAN:0)
Block(-4,58,-5,OBSIDIAN:0)
Block(-4,58,-4,OBSIDIAN:0)
Block(-4,58,-3,OBSIDIAN:0)
Block(-4,58,-2,OBSIDIAN:0)
Block(-4,58,-1,OBSIDIAN:0)
Block(-4,58,0,OBSIDIAN:0)
Block(-4,58,1,STONE:3)
Block(-4,58,2,STONE:3)
Block(-4,58,3,STONE:3)
Block(-4,59,-7,OBSIDIAN:0)
Block(-4,59,-6,OBSIDIAN:0)
Block(-4,59,-5,OBSIDIAN:0)
Block(-4,60,-7,OBSIDIAN:0)
Block(-3,23,-7,STONE:3)
Block(-3,24,-7,STONE:3)
Block(-3,24,-6,STONE:3)
Block(-3,25,-7,STONE:3)
Block(-3,25,-6,STONE:3)
Block(-3,25,-5,STONE:3)
Block(-3,26,-7,STONE:3)
Block(-3,26,-6,STONE:3)
Block(-3,26,-5,STONE:3)
Block(-3,27,-7,STONE:3)
Block(-3,27,-6,STONE:3)
Block(-3,27,-5,STONE:3)
Block(-3,27,-4,STONE:3)
Block(-3,28,-7,STONE:3)
Block(-3,28,-6,STONE:3)
Block(-3,28,-5,STONE:3)
Block(-3,28,-4,STONE:3)
Block(-3,28,-3,STONE:3)
Block(-3,29,-7,STONE:3)
Block(-3,29,-6,STONE:3)
Block(-3,29,-5,STONE:3)
Block(-3,29,-4,STONE:3)
Block(-3,29,-3,STONE:3)
Block(-3,30,-7,STONE:3)
Block(-3,30,-6,STONE:3)
Block(-3,30,-5,STONE:3)
Block(-3,30,-4,STONE:3)
Block(-3,30,-3,STONE:3)
Block(-3,30,-2,STONE:3)
Block(-3,31,-7,STONE:3)
Block(-3,31,-6,STONE:3)
Block(-3,31,-5,STONE:3)
Block(-3,31,-4,STONE:3)
Block(-3,31,-3,STONE:3)
Block(-3,31,-2,STONE:3)
Block(-3,31,-1,STONE:3)
Block(-3,32,-7,OBSIDIAN:0)
Block(-3,32,-6,STONE:3)
Block(-3,32,-5,STONE:3)
Block(-3,32,-4,STONE:3)
Block(-3,32,-3,STONE:3)
Block(-3,32,-2,STONE:3)
Block(-3,32,-1,STONE:3)
Block(-3,33,-7,OBSIDIAN:0)
Block(-3,33,-6,STONE:3)
Block(-3,33,-5,STONE:3)
Block(-3,33,-4,STONE:3)
Block(-3,33,-3,STONE:3)
Block(-3,33,-2,STONE:3)
Block(-3,33,-1,STONE:3)
Block(-3,34,-7,OBSIDIAN:0)
Block(-3,34,-6,OBSIDIAN:0)
Block(-3,34,-5,STONE:3)
Block(-3,34,-4,STONE:3)
Block(-3,34,-3,STONE:3)
Block(-3,34,-2,STONE:3)
Block(-3,34,-1,STONE:3)
Block(-3,34,0,STONE:3)
Block(-3,35,-7,OBSIDIAN:0)
Block(-3,35,-6,OBSIDIAN:0)
Block(-3,35,-5,STONE:3)
Block(-3,35,-4,STONE:3)
Block(-3,35,-3,STONE:3)
Block(-3,35,-2,STONE:3)
Block(-3,35,-1,STONE:3)
Block(-3,35,0,STONE:3)
Block(-3,36,-7,OBSIDIAN:0)
Block(-3,36,-6,OBSIDIAN:0)
Block(-3,36,-5,STONE:3)
Block(-3,36,-4,STONE:3)
Block(-3,36,-3,STONE:3)
Block(-3,36,-2,STONE:3)
Block(-3,36,-1,STONE:3)
Block(-3,36,0,STONE:3)
Block(-3,37,-7,OBSIDIAN:0)
Block(-3,37,-6,OBSIDIAN:0)
Block(-3,37,-5,OBSIDIAN:0)
Block(-3,37,-4,STONE:3)
Block(-3,37,-3,STONE:3)
Block(-3,37,-2,STONE:3)
Block(-3,37,-1,STONE:3)
Block(-3,37,0,STONE:3)
Block(-3,38,-7,OBSIDIAN:0)
Block(-3,38,-6,OBSIDIAN:0)
Block(-3,38,-5,OBSIDIAN:0)
Block(-3,38,-4,STONE:3)
Block(-3,38,-3,STONE:3)
Block(-3,38,-2,STONE:3)
Block(-3,38,-1,STONE:3)
Block(-3,38,0,STONE:3)
Block(-3,39,-7,OBSIDIAN:0)
Block(-3,39,-6,OBSIDIAN:0)
Block(-3,39,-5,OBSIDIAN:0)
Block(-3,39,-4,STONE:3)
Block(-3,39,-3,STONE:3)
Block(-3,39,-2,STONE:3)
Block(-3,39,-1,STONE:3)
Block(-3,39,0,STONE:3)
Block(-3,39,1,STONE:3)
Block(-3,40,-7,OBSIDIAN:0)
Block(-3,40,-6,OBSIDIAN:0)
Block(-3,40,-5,OBSIDIAN:0)
Block(-3,40,-4,STONE:3)
Block(-3,40,-3,STONE:3)
Block(-3,40,-2,STONE:3)
Block(-3,40,-1,STONE:3)
Block(-3,40,0,STONE:3)
Block(-3,40,1,STONE:3)
Block(-3,41,-7,OBSIDIAN:0)
Block(-3,41,-6,OBSIDIAN:0)
Block(-3,41,-5,OBSIDIAN:0)
Block(-3,41,-4,STONE:3)
Block(-3,41,-3,STONE:3)
Block(-3,41,-2,STONE:3)
Block(-3,41,-1,STONE:3)
Block(-3,41,0,STONE:3)
Block(-3,41,1,STONE:3)
Block(-3,42,-7,OBSIDIAN:0)
Block(-3,42,-6,OBSIDIAN:0)
Block(-3,42,-5,OBSIDIAN:0)
Block(-3,42,-4,STONE:3)
Block(-3,42,-3,STONE:3)
Block(-3,42,-2,STONE:3)
Block(-3,42,-1,STONE:3)
Block(-3,42,0,STONE:3)
Block(-3,42,1,STONE:3)
Block(-3,42,2,STONE:3)
Block(-3,43,-7,OBSIDIAN:0)
Block(-3,43,-6,OBSIDIAN:0)
Block(-3,43,-5,OBSIDIAN:0)
Block(-3,43,-4,STONE:3)
Block(-3,43,-3,STONE:3)
Block(-3,43,-2,STONE:3)
Block(-3,43,-1,STONE:3)
Block(-3,43,0,STONE:3)
Block(-3,43,1,STONE:3)
Block(-3,43,2,STONE:3)
Block(-3,44,-7,OBSIDIAN:0)
Block(-3,44,-6,OBSIDIAN:0)
Block(-3,44,-5,OBSIDIAN:0)
Block(-3,44,-4,OBSIDIAN:0)
Block(-3,44,-3,STONE:3)
Block(-3,44,-2,STONE:3)
Block(-3,44,-1,STONE:3)
Block(-3,44,0,STONE:3)
Block(-3,44,1,STONE:3)
Block(-3,44,2,STONE:3)
Block(-3,44,3,STONE:3)
Block(-3,45,-7,OBSIDIAN:0)
Block(-3,45,-6,OBSIDIAN:0)
Block(-3,45,-5,OBSIDIAN:0)
Block(-3,45,-4,OBSIDIAN:0)
Block(-3,45,-3,OBSIDIAN:0)
Block(-3,45,-2,OBSIDIAN:0)
Block(-3,45,-1,STONE:3)
Block(-3,45,0,STONE:3)
Block(-3,45,1,STONE:3)
Block(-3,45,2,STONE:3)
Block(-3,45,3,STONE:3)
Block(-3,45,4,STONE:3)
Block(-3,46,-7,OBSIDIAN:0)
Block(-3,46,-6,OBSIDIAN:0)
Block(-3,46,-5,OBSIDIAN:0)
Block(-3,46,-4,OBSIDIAN:0)
Block(-3,46,-3,OBSIDIAN:0)
Block(-3,46,-2,OBSIDIAN:0)
Block(-3,46,-1,STONE:3)
Block(-3,46,0,STONE:3)
Block(-3,46,1,STONE:3)
Block(-3,46,2,STONE:3)
Block(-3,46,3,STONE:3)
Block(-3,46,4,STONE:3)
Block(-3,47,-7,OBSIDIAN:0)
Block(-3,47,-6,OBSIDIAN:0)
Block(-3,47,-5,OBSIDIAN:0)
Block(-3,47,-4,OBSIDIAN:0)
Block(-3,47,-3,OBSIDIAN:0)
Block(-3,47,-2,OBSIDIAN:0)
Block(-3,47,-1,STONE:3)
Block(-3,47,0,STONE:3)
Block(-3,47,1,STONE:3)
Block(-3,47,2,STONE:3)
Block(-3,47,3,STONE:3)
Block(-3,47,4,STONE:3)
Block(-3,48,-7,OBSIDIAN:0)
Block(-3,48,-6,OBSIDIAN:0)
Block(-3,48,-5,OBSIDIAN:0)
Block(-3,48,-4,OBSIDIAN:0)
Block(-3,48,-3,OBSIDIAN:0)
Block(-3,48,-2,OBSIDIAN:0)
Block(-3,48,-1,STONE:3)
Block(-3,48,0,STONE:3)
Block(-3,48,1,STONE:3)
Block(-3,48,2,STONE:3)
Block(-3,48,3,STONE:3)
Block(-3,48,4,STONE:3)
Block(-3,49,-7,OBSIDIAN:0)
Block(-3,49,-6,OBSIDIAN:0)
Block(-3,49,-5,OBSIDIAN:0)
Block(-3,49,-4,OBSIDIAN:0)
Block(-3,49,-3,OBSIDIAN:0)
Block(-3,49,-2,OBSIDIAN:0)
Block(-3,49,-1,OBSIDIAN:0)
Block(-3,49,0,STONE:3)
Block(-3,49,1,STONE:3)
Block(-3,49,2,STONE:3)
Block(-3,49,3,STONE:3)
Block(-3,49,4,STONE:3)
Block(-3,49,5,STONE:3)
Block(-3,50,-7,OBSIDIAN:0)
Block(-3,50,-6,OBSIDIAN:0)
Block(-3,50,-5,OBSIDIAN:0)
Block(-3,50,-4,OBSIDIAN:0)
Block(-3,50,-3,OBSIDIAN:0)
Block(-3,50,-2,OBSIDIAN:0)
Block(-3,50,-1,OBSIDIAN:0)
Block(-3,50,0,OBSIDIAN:0)
Block(-3,50,1,STONE:3)
Block(-3,50,2,STONE:3)
Block(-3,50,3,STONE:3)
Block(-3,50,4,STONE:3)
Block(-3,50,5,STONE:3)
Block(-3,51,-7,OBSIDIAN:0)
Block(-3,51,-6,OBSIDIAN:0)
Block(-3,51,-5,OBSIDIAN:0)
Block(-3,51,-4,OBSIDIAN:0)
Block(-3,51,-3,OBSIDIAN:0)
Block(-3,51,-2,OBSIDIAN:0)
Block(-3,51,-1,OBSIDIAN:0)
Block(-3,51,0,OBSIDIAN:0)
Block(-3,51,1,STONE:3)
Block(-3,51,2,STONE:3)
Block(-3,51,3,STONE:3)
Block(-3,51,4,STONE:3)
Block(-3,51,5,STONE:3)
Block(-3,52,-7,OBSIDIAN:0)
Block(-3,52,-6,OBSIDIAN:0)
Block(-3,52,-5,OBSIDIAN:0)
Block(-3,52,-4,OBSIDIAN:0)
Block(-3,52,-3,OBSIDIAN:0)
Block(-3,52,-2,OBSIDIAN:0)
Block(-3,52,-1,OBSIDIAN:0)
Block(-3,52,0,OBSIDIAN:0)
Block(-3,52,1,STONE:3)
Block(-3,52,2,STONE:3)
Block(-3,52,3,STONE:3)
Block(-3,52,4,STONE:3)
Block(-3,52,5,STONE:3)
Block(-3,52,6,STONE:3)
Block(-3,53,-7,OBSIDIAN:0)
Block(-3,53,-6,OBSIDIAN:0)
Block(-3,53,-5,OBSIDIAN:0)
Block(-3,53,-4,OBSIDIAN:0)
Block(-3,53,-3,OBSIDIAN:0)
Block(-3,53,-2,OBSIDIAN:0)
Block(-3,53,-1,OBSIDIAN:0)
Block(-3,53,0,OBSIDIAN:0)
Block(-3,53,1,STONE:3)
Block(-3,53,2,STONE:3)
Block(-3,53,3,STONE:3)
Block(-3,53,4,STONE:3)
Block(-3,53,5,STONE:3)
Block(-3,53,6,STONE:3)
Block(-3,54,-7,OBSIDIAN:0)
Block(-3,54,-6,OBSIDIAN:0)
Block(-3,54,-5,OBSIDIAN:0)
Block(-3,54,-4,OBSIDIAN:0)
Block(-3,54,-3,OBSIDIAN:0)
Block(-3,54,-2,OBSIDIAN:0)
Block(-3,54,-1,OBSIDIAN:0)
Block(-3,54,0,OBSIDIAN:0)
Block(-3,54,1,STONE:3)
Block(-3,54,2,STONE:3)
Block(-3,54,3,STONE:3)
Block(-3,54,4,STONE:3)
Block(-3,54,5,STONE:3)
Block(-3,54,6,STONE:3)
Block(-3,55,-7,OBSIDIAN:0)
Block(-3,55,-6,OBSIDIAN:0)
Block(-3,55,-5,OBSIDIAN:0)
Block(-3,55,-4,OBSIDIAN:0)
Block(-3,55,-3,OBSIDIAN:0)
Block(-3,55,-2,OBSIDIAN:0)
Block(-3,55,-1,OBSIDIAN:0)
Block(-3,55,0,OBSIDIAN:0)
Block(-3,55,1,STONE:3)
Block(-3,55,2,STONE:3)
Block(-3,55,3,STONE:3)
Block(-3,55,4,STONE:3)
Block(-3,55,5,STONE:3)
Block(-3,55,6,STONE:3)
Block(-3,56,-7,OBSIDIAN:0)
Block(-3,56,-6,OBSIDIAN:0)
Block(-3,56,-5,OBSIDIAN:0)
Block(-3,56,-4,OBSIDIAN:0)
Block(-3,56,-3,OBSIDIAN:0)
Block(-3,56,-2,OBSIDIAN:0)
Block(-3,56,-1,OBSIDIAN:0)
Block(-3,56,0,OBSIDIAN:0)
Block(-3,56,1,STONE:3)
Block(-3,56,2,STONE:3)
Block(-3,56,3,STONE:3)
Block(-3,56,4,STONE:3)
Block(-3,56,5,STONE:3)
Block(-3,57,-7,OBSIDIAN:0)
Block(-3,57,-6,OBSIDIAN:0)
Block(-3,57,-5,OBSIDIAN:0)
Block(-3,57,-4,OBSIDIAN:0)
Block(-3,57,-3,OBSIDIAN:0)
Block(-3,57,-2,OBSIDIAN:0)
Block(-3,57,-1,OBSIDIAN:0)
Block(-3,57,0,OBSIDIAN:0)
Block(-3,57,1,STONE:3)
Block(-3,57,2,STONE:3)
Block(-3,57,3,STONE:3)
Block(-3,57,4,STONE:3)
Block(-3,57,5,STONE:3)
Block(-3,58,-7,OBSIDIAN:0)
Block(-3,58,-6,OBSIDIAN:0)
Block(-3,58,-5,OBSIDIAN:0)
Block(-3,58,-4,OBSIDIAN:0)
Block(-3,58,-3,OBSIDIAN:0)
Block(-3,58,-2,OBSIDIAN:0)
Block(-3,58,-1,OBSIDIAN:0)
Block(-3,58,0,OBSIDIAN:0)
Block(-3,58,1,STONE:3)
Block(-3,58,2,STONE:3)
Block(-3,58,3,STONE:3)
Block(-3,58,4,STONE:3)
Block(-3,59,-7,OBSIDIAN:0)
Block(-3,59,-6,OBSIDIAN:0)
Block(-3,59,-5,OBSIDIAN:0)
Block(-3,59,-3,OBSIDIAN:0)
Block(-3,59,-2,OBSIDIAN:0)
Block(-3,59,-1,OBSIDIAN:0)
Block(-3,59,0,OBSIDIAN:0)
Block(-3,60,-7,MAGMA:0)
Block(-2,23,-7,STONE:3)
Block(-2,24,-7,STONE:3)
Block(-2,24,-6,STONE:3)
Block(-2,25,-7,STONE:3)
Block(-2,25,-6,STONE:3)
Block(-2,25,-5,STONE:3)
Block(-2,26,-7,STONE:3)
Block(-2,26,-6,STONE:3)
Block(-2,26,-5,STONE:3)
Block(-2,26,-4,STONE:3)
Block(-2,27,-7,STONE:3)
Block(-2,27,-6,STONE:3)
Block(-2,27,-5,STONE:3)
Block(-2,27,-4,STONE:3)
Block(-2,28,-7,STONE:3)
Block(-2,28,-6,STONE:3)
Block(-2,28,-5,STONE:3)
Block(-2,28,-4,STONE:3)
Block(-2,28,-3,STONE:3)
Block(-2,29,-7,STONE:3)
Block(-2,29,-6,STONE:3)
Block(-2,29,-5,STONE:3)
Block(-2,29,-4,STONE:3)
Block(-2,29,-3,STONE:3)
Block(-2,30,-7,STONE:3)
Block(-2,30,-6,STONE:3)
Block(-2,30,-5,STONE:3)
Block(-2,30,-4,STONE:3)
Block(-2,30,-3,STONE:3)
Block(-2,30,-2,STONE:3)
Block(-2,31,-7,STONE:3)
Block(-2,31,-6,STONE:3)
Block(-2,31,-5,STONE:3)
Block(-2,31,-4,STONE:3)
Block(-2,31,-3,STONE:3)
Block(-2,31,-2,STONE:3)
Block(-2,31,-1,STONE:3)
Block(-2,32,-7,STONE:3)
Block(-2,32,-6,STONE:3)
Block(-2,32,-5,STONE:3)
Block(-2,32,-4,STONE:3)
Block(-2,32,-3,STONE:3)
Block(-2,32,-2,STONE:3)
Block(-2,32,-1,STONE:3)
Block(-2,33,-7,STONE:3)
Block(-2,33,-6,STONE:3)
Block(-2,33,-5,STONE:3)
Block(-2,33,-4,STONE:3)
Block(-2,33,-3,STONE:3)
Block(-2,33,-2,STONE:3)
Block(-2,33,-1,STONE:3)
Block(-2,34,-7,OBSIDIAN:0)
Block(-2,34,-6,STONE:3)
Block(-2,34,-5,STONE:3)
Block(-2,34,-4,STONE:3)
Block(-2,34,-3,STONE:3)
Block(-2,34,-2,STONE:3)
Block(-2,34,-1,STONE:3)
Block(-2,34,0,STONE:3)
Block(-2,35,-7,OBSIDIAN:0)
Block(-2,35,-6,OBSIDIAN:0)
Block(-2,35,-5,STONE:3)
Block(-2,35,-4,STONE:3)
Block(-2,35,-3,STONE:3)
Block(-2,35,-2,STONE:3)
Block(-2,35,-1,STONE:3)
Block(-2,35,0,STONE:3)
Block(-2,36,-7,OBSIDIAN:0)
Block(-2,36,-6,OBSIDIAN:0)
Block(-2,36,-5,STONE:3)
Block(-2,36,-4,STONE:3)
Block(-2,36,-3,STONE:3)
Block(-2,36,-2,STONE:3)
Block(-2,36,-1,STONE:3)
Block(-2,36,0,STONE:3)
Block(-2,37,-7,OBSIDIAN:0)
Block(-2,37,-6,OBSIDIAN:0)
Block(-2,37,-5,OBSIDIAN:0)
Block(-2,37,-4,STONE:3)
Block(-2,37,-3,STONE:3)
Block(-2,37,-2,STONE:3)
Block(-2,37,-1,STONE:3)
Block(-2,37,0,STONE:3)
Block(-2,38,-7,OBSIDIAN:0)
Block(-2,38,-6,OBSIDIAN:0)
Block(-2,38,-5,OBSIDIAN:0)
Block(-2,38,-4,STONE:3)
Block(-2,38,-3,STONE:3)
Block(-2,38,-2,STONE:3)
Block(-2,38,-1,STONE:3)
Block(-2,38,0,STONE:3)
Block(-2,39,-7,OBSIDIAN:0)
Block(-2,39,-6,OBSIDIAN:0)
Block(-2,39,-5,STONE:3)
Block(-2,39,-4,STONE:3)
Block(-2,39,-3,STONE:3)
Block(-2,39,-2,STONE:3)
Block(-2,39,-1,STONE:3)
Block(-2,39,0,STONE:3)
Block(-2,40,-7,OBSIDIAN:0)
Block(-2,40,-6,OBSIDIAN:0)
Block(-2,40,-5,STONE:3)
Block(-2,40,-4,STONE:3)
Block(-2,40,-3,STONE:3)
Block(-2,40,-2,STONE:3)
Block(-2,40,-1,STONE:3)
Block(-2,40,0,STONE:3)
Block(-2,41,-7,OBSIDIAN:0)
Block(-2,41,-6,OBSIDIAN:0)
Block(-2,41,-5,STONE:3)
Block(-2,41,-4,STONE:3)
Block(-2,41,-3,STONE:3)
Block(-2,41,-2,STONE:3)
Block(-2,41,-1,STONE:3)
Block(-2,41,0,STONE:3)
Block(-2,41,1,STONE:3)
Block(-2,42,-7,OBSIDIAN:0)
Block(-2,42,-6,OBSIDIAN:0)
Block(-2,42,-5,STONE:3)
Block(-2,42,-4,STONE:3)
Block(-2,42,-3,STONE:3)
Block(-2,42,-2,STONE:3)
Block(-2,42,-1,STONE:3)
Block(-2,42,0,STONE:3)
Block(-2,42,1,STONE:3)
Block(-2,42,2,STONE:3)
Block(-2,43,-7,OBSIDIAN:0)
Block(-2,43,-6,OBSIDIAN:0)
Block(-2,43,-5,STONE:3)
Block(-2,43,-4,STONE:3)
Block(-2,43,-3,STONE:3)
Block(-2,43,-2,STONE:3)
Block(-2,43,-1,STONE:3)
Block(-2,43,0,STONE:3)
Block(-2,43,1,STONE:3)
Block(-2,43,2,STONE:3)
Block(-2,43,3,STONE:3)
Block(-2,44,-7,OBSIDIAN:0)
Block(-2,44,-6,OBSIDIAN:0)
Block(-2,44,-5,OBSIDIAN:0)
Block(-2,44,-4,STONE:3)
Block(-2,44,-3,STONE:3)
Block(-2,44,-2,STONE:3)
Block(-2,44,-1,STONE:3)
Block(-2,44,0,STONE:3)
Block(-2,44,1,STONE:3)
Block(-2,44,2,STONE:3)
Block(-2,44,3,STONE:3)
Block(-2,44,4,STONE:3)
Block(-2,45,-7,OBSIDIAN:0)
Block(-2,45,-6,OBSIDIAN:0)
Block(-2,45,-5,OBSIDIAN:0)
Block(-2,45,-4,OBSIDIAN:0)
Block(-2,45,-3,STONE:3)
Block(-2,45,-2,STONE:3)
Block(-2,45,-1,STONE:3)
Block(-2,45,0,STONE:3)
Block(-2,45,1,STONE:3)
Block(-2,45,2,STONE:3)
Block(-2,45,3,STONE:3)
Block(-2,45,4,STONE:3)
Block(-2,46,-7,OBSIDIAN:0)
Block(-2,46,-6,OBSIDIAN:0)
Block(-2,46,-5,OBSIDIAN:0)
Block(-2,46,-4,OBSIDIAN:0)
Block(-2,46,-3,OBSIDIAN:0)
Block(-2,46,-2,OBSIDIAN:0)
Block(-2,46,-1,STONE:3)
Block(-2,46,0,STONE:3)
Block(-2,46,1,STONE:3)
Block(-2,46,2,STONE:3)
Block(-2,46,3,STONE:3)
Block(-2,46,4,STONE:3)
Block(-2,47,-7,OBSIDIAN:0)
Block(-2,47,-6,OBSIDIAN:0)
Block(-2,47,-5,OBSIDIAN:0)
Block(-2,47,-4,OBSIDIAN:0)
Block(-2,47,-3,OBSIDIAN:0)
Block(-2,47,-2,OBSIDIAN:0)
Block(-2,47,-1,STONE:3)
Block(-2,47,0,STONE:3)
Block(-2,47,1,STONE:3)
Block(-2,47,2,STONE:3)
Block(-2,47,3,STONE:3)
Block(-2,47,4,STONE:3)
Block(-2,48,-7,OBSIDIAN:0)
Block(-2,48,-6,OBSIDIAN:0)
Block(-2,48,-5,OBSIDIAN:0)
Block(-2,48,-4,OBSIDIAN:0)
Block(-2,48,-3,OBSIDIAN:0)
Block(-2,48,-2,OBSIDIAN:0)
Block(-2,48,-1,OBSIDIAN:0)
Block(-2,48,0,STONE:3)
Block(-2,48,1,STONE:3)
Block(-2,48,2,STONE:3)
Block(-2,48,3,STONE:3)
Block(-2,48,4,STONE:3)
Block(-2,49,-7,OBSIDIAN:0)
Block(-2,49,-6,OBSIDIAN:0)
Block(-2,49,-5,OBSIDIAN:0)
Block(-2,49,-4,OBSIDIAN:0)
Block(-2,49,-3,OBSIDIAN:0)
Block(-2,49,-2,OBSIDIAN:0)
Block(-2,49,-1,OBSIDIAN:0)
Block(-2,49,0,STONE:3)
Block(-2,49,1,STONE:3)
Block(-2,49,2,STONE:3)
Block(-2,49,3,STONE:3)
Block(-2,49,4,STONE:3)
Block(-2,49,5,STONE:3)
Block(-2,50,-7,OBSIDIAN:0)
Block(-2,50,-6,OBSIDIAN:0)
Block(-2,50,-5,OBSIDIAN:0)
Block(-2,50,-4,OBSIDIAN:0)
Block(-2,50,-3,OBSIDIAN:0)
Block(-2,50,-2,OBSIDIAN:0)
Block(-2,50,-1,OBSIDIAN:0)
Block(-2,50,0,OBSIDIAN:0)
Block(-2,50,1,STONE:3)
Block(-2,50,2,STONE:3)
Block(-2,50,3,STONE:3)
Block(-2,50,4,STONE:3)
Block(-2,50,5,STONE:3)
Block(-2,51,-7,OBSIDIAN:0)
Block(-2,51,-6,OBSIDIAN:0)
Block(-2,51,-5,OBSIDIAN:0)
Block(-2,51,-4,OBSIDIAN:0)
Block(-2,51,-3,OBSIDIAN:0)
Block(-2,51,-2,OBSIDIAN:0)
Block(-2,51,-1,OBSIDIAN:0)
Block(-2,51,0,OBSIDIAN:0)
Block(-2,51,1,STONE:3)
Block(-2,51,2,STONE:3)
Block(-2,51,3,STONE:3)
Block(-2,51,4,STONE:3)
Block(-2,51,5,STONE:3)
Block(-2,51,6,STONE:3)
Block(-2,52,-7,OBSIDIAN:0)
Block(-2,52,-6,OBSIDIAN:0)
Block(-2,52,-5,OBSIDIAN:0)
Block(-2,52,-4,OBSIDIAN:0)
Block(-2,52,-3,OBSIDIAN:0)
Block(-2,52,-2,OBSIDIAN:0)
Block(-2,52,-1,OBSIDIAN:0)
Block(-2,52,0,OBSIDIAN:0)
Block(-2,52,1,STONE:3)
Block(-2,52,2,STONE:3)
Block(-2,52,3,STONE:3)
Block(-2,52,4,STONE:3)
Block(-2,52,5,STONE:3)
Block(-2,52,6,STONE:3)
Block(-2,53,-7,OBSIDIAN:0)
Block(-2,53,-6,OBSIDIAN:0)
Block(-2,53,-5,OBSIDIAN:0)
Block(-2,53,-4,OBSIDIAN:0)
Block(-2,53,-3,OBSIDIAN:0)
Block(-2,53,-2,OBSIDIAN:0)
Block(-2,53,-1,OBSIDIAN:0)
Block(-2,53,0,OBSIDIAN:0)
Block(-2,53,1,STONE:3)
Block(-2,53,2,STONE:3)
Block(-2,53,3,STONE:3)
Block(-2,53,4,STONE:3)
Block(-2,53,5,STONE:3)
Block(-2,53,6,STONE:3)
Block(-2,54,-7,OBSIDIAN:0)
Block(-2,54,-6,OBSIDIAN:0)
Block(-2,54,-5,OBSIDIAN:0)
Block(-2,54,-4,OBSIDIAN:0)
Block(-2,54,-3,OBSIDIAN:0)
Block(-2,54,-2,OBSIDIAN:0)
Block(-2,54,-1,OBSIDIAN:0)
Block(-2,54,0,OBSIDIAN:0)
Block(-2,54,1,OBSIDIAN:0)
Block(-2,54,2,STONE:3)
Block(-2,54,3,STONE:3)
Block(-2,54,4,STONE:3)
Block(-2,54,5,STONE:3)
Block(-2,54,6,STONE:3)
Block(-2,55,-7,OBSIDIAN:0)
Block(-2,55,-6,OBSIDIAN:0)
Block(-2,55,-5,OBSIDIAN:0)
Block(-2,55,-4,OBSIDIAN:0)
Block(-2,55,-3,OBSIDIAN:0)
Block(-2,55,-2,OBSIDIAN:0)
Block(-2,55,-1,OBSIDIAN:0)
Block(-2,55,0,OBSIDIAN:0)
Block(-2,55,1,OBSIDIAN:0)
Block(-2,55,2,STONE:3)
Block(-2,55,3,STONE:3)
Block(-2,55,4,STONE:3)
Block(-2,55,5,STONE:3)
Block(-2,55,6,STONE:3)
Block(-2,56,-7,OBSIDIAN:0)
Block(-2,56,-6,OBSIDIAN:0)
Block(-2,56,-5,OBSIDIAN:0)
Block(-2,56,-4,OBSIDIAN:0)
Block(-2,56,-3,OBSIDIAN:0)
Block(-2,56,-2,OBSIDIAN:0)
Block(-2,56,-1,OBSIDIAN:0)
Block(-2,56,0,OBSIDIAN:0)
Block(-2,56,1,OBSIDIAN:0)
Block(-2,56,2,STONE:3)
Block(-2,56,3,STONE:3)
Block(-2,56,4,STONE:3)
Block(-2,56,5,STONE:3)
Block(-2,56,6,STONE:3)
Block(-2,57,-7,OBSIDIAN:0)
Block(-2,57,-6,OBSIDIAN:0)
Block(-2,57,-5,OBSIDIAN:0)
Block(-2,57,-4,OBSIDIAN:0)
Block(-2,57,-3,OBSIDIAN:0)
Block(-2,57,-2,OBSIDIAN:0)
Block(-2,57,-1,OBSIDIAN:0)
Block(-2,57,0,OBSIDIAN:0)
Block(-2,57,1,OBSIDIAN:0)
Block(-2,57,2,STONE:3)
Block(-2,57,3,STONE:3)
Block(-2,57,4,STONE:3)
Block(-2,57,5,STONE:3)
Block(-2,58,-7,OBSIDIAN:0)
Block(-2,58,-6,OBSIDIAN:0)
Block(-2,58,-5,OBSIDIAN:0)
Block(-2,58,-4,OBSIDIAN:0)
Block(-2,58,-3,OBSIDIAN:0)
Block(-2,58,-2,OBSIDIAN:0)
Block(-2,58,-1,OBSIDIAN:0)
Block(-2,58,0,OBSIDIAN:0)
Block(-2,58,1,OBSIDIAN:0)
Block(-2,58,2,STONE:3)
Block(-2,58,3,STONE:3)
Block(-2,58,4,STONE:3)
Block(-2,58,5,STONE:3)
Block(-2,59,-7,MAGMA:0)
Block(-2,59,-6,MAGMA:0)
Block(-2,59,-5,MAGMA:0)
Block(-2,59,-4,OBSIDIAN:0)
Block(-2,59,-3,OBSIDIAN:0)
Block(-2,59,-2,OBSIDIAN:0)
Block(-2,59,-1,OBSIDIAN:0)
Block(-2,59,0,OBSIDIAN:0)
Block(-2,59,1,OBSIDIAN:0)
Block(-2,60,-7,MAGMA:0)
Block(-2,60,-5,MAGMA:0)
Block(-1,23,-7,STONE:3)
Block(-1,23,-6,STONE:3)
Block(-1,24,-7,STONE:3)
Block(-1,24,-6,STONE:3)
Block(-1,25,-7,STONE:3)
Block(-1,25,-6,STONE:3)
Block(-1,25,-5,STONE:3)
Block(-1,26,-7,STONE:3)
Block(-1,26,-6,STONE:3)
Block(-1,26,-5,STONE:3)
Block(-1,26,-4,STONE:3)
Block(-1,27,-7,STONE:3)
Block(-1,27,-6,STONE:3)
Block(-1,27,-5,STONE:3)
Block(-1,27,-4,STONE:3)
Block(-1,28,-7,STONE:3)
Block(-1,28,-6,STONE:3)
Block(-1,28,-5,STONE:3)
Block(-1,28,-4,STONE:3)
Block(-1,28,-3,STONE:3)
Block(-1,29,-7,STONE:3)
Block(-1,29,-6,STONE:3)
Block(-1,29,-5,STONE:3)
Block(-1,29,-4,STONE:3)
Block(-1,29,-3,STONE:3)
Block(-1,30,-7,STONE:3)
Block(-1,30,-6,STONE:3)
Block(-1,30,-5,STONE:3)
Block(-1,30,-4,STONE:3)
Block(-1,30,-3,STONE:3)
Block(-1,30,-2,STONE:3)
Block(-1,31,-7,STONE:3)
Block(-1,31,-6,STONE:3)
Block(-1,31,-5,STONE:3)
Block(-1,31,-4,STONE:3)
Block(-1,31,-3,STONE:3)
Block(-1,31,-2,STONE:3)
Block(-1,31,-1,STONE:3)
Block(-1,32,-7,STONE:3)
Block(-1,32,-6,STONE:3)
Block(-1,32,-5,STONE:3)
Block(-1,32,-4,STONE:3)
Block(-1,32,-3,STONE:3)
Block(-1,32,-2,STONE:3)
Block(-1,32,-1,STONE:3)
Block(-1,33,-7,STONE:3)
Block(-1,33,-6,STONE:3)
Block(-1,33,-5,STONE:3)
Block(-1,33,-4,STONE:3)
Block(-1,33,-3,STONE:3)
Block(-1,33,-2,STONE:3)
Block(-1,33,-1,STONE:3)
Block(-1,34,-7,STONE:3)
Block(-1,34,-6,STONE:3)
Block(-1,34,-5,STONE:3)
Block(-1,34,-4,STONE:3)
Block(-1,34,-3,STONE:3)
Block(-1,34,-2,STONE:3)
Block(-1,34,-1,STONE:3)
Block(-1,35,-7,OBSIDIAN:0)
Block(-1,35,-6,STONE:3)
Block(-1,35,-5,STONE:3)
Block(-1,35,-4,STONE:3)
Block(-1,35,-3,STONE:3)
Block(-1,35,-2,STONE:3)
Block(-1,35,-1,STONE:3)
Block(-1,36,-7,OBSIDIAN:0)
Block(-1,36,-6,OBSIDIAN:0)
Block(-1,36,-5,STONE:3)
Block(-1,36,-4,STONE:3)
Block(-1,36,-3,STONE:3)
Block(-1,36,-2,STONE:3)
Block(-1,36,-1,STONE:3)
Block(-1,37,-7,OBSIDIAN:0)
Block(-1,37,-6,OBSIDIAN:0)
Block(-1,37,-5,OBSIDIAN:0)
Block(-1,37,-4,STONE:3)
Block(-1,37,-3,STONE:3)
Block(-1,37,-2,STONE:3)
Block(-1,37,-1,STONE:3)
Block(-1,37,0,STONE:3)
Block(-1,38,-7,OBSIDIAN:0)
Block(-1,38,-6,OBSIDIAN:0)
Block(-1,38,-5,STONE:3)
Block(-1,38,-4,STONE:3)
Block(-1,38,-3,STONE:3)
Block(-1,38,-2,STONE:3)
Block(-1,38,-1,STONE:3)
Block(-1,39,-7,OBSIDIAN:0)
Block(-1,39,-6,OBSIDIAN:0)
Block(-1,39,-5,STONE:3)
Block(-1,39,-4,STONE:3)
Block(-1,39,-3,STONE:3)
Block(-1,39,-2,STONE:3)
Block(-1,39,-1,STONE:3)
Block(-1,40,-7,OBSIDIAN:0)
Block(-1,40,-6,STONE:3)
Block(-1,40,-5,STONE:3)
Block(-1,40,-4,STONE:3)
Block(-1,40,-3,STONE:3)
Block(-1,40,-2,STONE:3)
Block(-1,40,-1,STONE:3)
Block(-1,40,0,STONE:3)
Block(-1,41,-7,OBSIDIAN:0)
Block(-1,41,-6,STONE:3)
Block(-1,41,-5,STONE:3)
Block(-1,41,-4,STONE:3)
Block(-1,41,-3,STONE:3)
Block(-1,41,-2,STONE:3)
Block(-1,41,-1,STONE:3)
Block(-1,41,0,STONE:3)
Block(-1,42,-7,OBSIDIAN:0)
Block(-1,42,-6,STONE:3)
Block(-1,42,-5,STONE:3)
Block(-1,42,-4,STONE:3)
Block(-1,42,-3,STONE:3)
Block(-1,42,-2,STONE:3)
Block(-1,42,-1,STONE:3)
Block(-1,42,0,STONE:3)
Block(-1,42,1,STONE:3)
Block(-1,42,2,STONE:3)
Block(-1,43,-7,OBSIDIAN:0)
Block(-1,43,-6,OBSIDIAN:0)
Block(-1,43,-5,STONE:3)
Block(-1,43,-4,STONE:3)
Block(-1,43,-3,STONE:3)
Block(-1,43,-2,STONE:3)
Block(-1,43,-1,STONE:3)
Block(-1,43,0,STONE:3)
Block(-1,43,1,STONE:3)
Block(-1,43,2,STONE:3)
Block(-1,43,3,STONE:3)
Block(-1,44,-7,OBSIDIAN:0)
Block(-1,44,-6,OBSIDIAN:0)
Block(-1,44,-5,STONE:3)
Block(-1,44,-4,STONE:3)
Block(-1,44,-3,STONE:3)
Block(-1,44,-2,STONE:3)
Block(-1,44,-1,STONE:3)
Block(-1,44,0,STONE:3)
Block(-1,44,1,STONE:3)
Block(-1,44,2,STONE:3)
Block(-1,44,3,STONE:3)
Block(-1,45,-7,OBSIDIAN:0)
Block(-1,45,-6,OBSIDIAN:0)
Block(-1,45,-5,OBSIDIAN:0)
Block(-1,45,-4,STONE:3)
Block(-1,45,-3,STONE:3)
Block(-1,45,-2,STONE:3)
Block(-1,45,-1,STONE:3)
Block(-1,45,0,STONE:3)
Block(-1,45,1,STONE:3)
Block(-1,45,2,STONE:3)
Block(-1,45,3,STONE:3)
Block(-1,45,4,STONE:3)
Block(-1,46,-7,OBSIDIAN:0)
Block(-1,46,-6,OBSIDIAN:0)
Block(-1,46,-5,OBSIDIAN:0)
Block(-1,46,-4,OBSIDIAN:0)
Block(-1,46,-3,OBSIDIAN:0)
Block(-1,46,-2,STONE:3)
Block(-1,46,-1,STONE:3)
Block(-1,46,0,STONE:3)
Block(-1,46,1,STONE:3)
Block(-1,46,2,STONE:3)
Block(-1,46,3,STONE:3)
Block(-1,46,4,STONE:3)
Block(-1,47,-7,OBSIDIAN:0)
Block(-1,47,-6,OBSIDIAN:0)
Block(-1,47,-5,OBSIDIAN:0)
Block(-1,47,-4,OBSIDIAN:0)
Block(-1,47,-3,OBSIDIAN:0)
Block(-1,47,-2,OBSIDIAN:0)
Block(-1,47,-1,OBSIDIAN:0)
Block(-1,47,0,STONE:3)
Block(-1,47,1,STONE:3)
Block(-1,47,2,STONE:3)
Block(-1,47,3,STONE:3)
Block(-1,47,4,STONE:3)
Block(-1,48,-7,OBSIDIAN:0)
Block(-1,48,-6,OBSIDIAN:0)
Block(-1,48,-5,OBSIDIAN:0)
Block(-1,48,-4,OBSIDIAN:0)
Block(-1,48,-3,OBSIDIAN:0)
Block(-1,48,-2,OBSIDIAN:0)
Block(-1,48,-1,OBSIDIAN:0)
Block(-1,48,0,STONE:3)
Block(-1,48,1,STONE:3)
Block(-1,48,2,STONE:3)
Block(-1,48,3,STONE:3)
Block(-1,48,4,STONE:3)
Block(-1,48,5,STONE:3)
Block(-1,49,-7,OBSIDIAN:0)
Block(-1,49,-6,OBSIDIAN:0)
Block(-1,49,-5,OBSIDIAN:0)
Block(-1,49,-4,OBSIDIAN:0)
Block(-1,49,-3,OBSIDIAN:0)
Block(-1,49,-2,OBSIDIAN:0)
Block(-1,49,-1,OBSIDIAN:0)
Block(-1,49,0,OBSIDIAN:0)
Block(-1,49,1,STONE:3)
Block(-1,49,2,STONE:3)
Block(-1,49,3,STONE:3)
Block(-1,49,4,STONE:3)
Block(-1,49,5,STONE:3)
Block(-1,50,-7,OBSIDIAN:0)
Block(-1,50,-6,OBSIDIAN:0)
Block(-1,50,-5,OBSIDIAN:0)
Block(-1,50,-4,OBSIDIAN:0)
Block(-1,50,-3,OBSIDIAN:0)
Block(-1,50,-2,OBSIDIAN:0)
Block(-1,50,-1,OBSIDIAN:0)
Block(-1,50,0,OBSIDIAN:0)
Block(-1,50,1,STONE:3)
Block(-1,50,2,STONE:3)
Block(-1,50,3,STONE:3)
Block(-1,50,4,STONE:3)
Block(-1,50,5,STONE:3)
Block(-1,51,-7,OBSIDIAN:0)
Block(-1,51,-6,OBSIDIAN:0)
Block(-1,51,-5,OBSIDIAN:0)
Block(-1,51,-4,OBSIDIAN:0)
Block(-1,51,-3,OBSIDIAN:0)
Block(-1,51,-2,OBSIDIAN:0)
Block(-1,51,-1,OBSIDIAN:0)
Block(-1,51,0,OBSIDIAN:0)
Block(-1,51,1,STONE:3)
Block(-1,51,2,STONE:3)
Block(-1,51,3,STONE:3)
Block(-1,51,4,STONE:3)
Block(-1,51,5,STONE:3)
Block(-1,51,6,STONE:3)
Block(-1,52,-7,OBSIDIAN:0)
Block(-1,52,-6,OBSIDIAN:0)
Block(-1,52,-5,OBSIDIAN:0)
Block(-1,52,-4,OBSIDIAN:0)
Block(-1,52,-3,OBSIDIAN:0)
Block(-1,52,-2,OBSIDIAN:0)
Block(-1,52,-1,OBSIDIAN:0)
Block(-1,52,0,OBSIDIAN:0)
Block(-1,52,1,STONE:3)
Block(-1,52,2,STONE:3)
Block(-1,52,3,STONE:3)
Block(-1,52,4,STONE:3)
Block(-1,52,5,STONE:3)
Block(-1,52,6,STONE:3)
Block(-1,53,-7,OBSIDIAN:0)
Block(-1,53,-6,OBSIDIAN:0)
Block(-1,53,-5,OBSIDIAN:0)
Block(-1,53,-4,OBSIDIAN:0)
Block(-1,53,-3,OBSIDIAN:0)
Block(-1,53,-2,OBSIDIAN:0)
Block(-1,53,-1,OBSIDIAN:0)
Block(-1,53,0,OBSIDIAN:0)
Block(-1,53,1,STONE:3)
Block(-1,53,2,STONE:3)
Block(-1,53,3,STONE:3)
Block(-1,53,4,STONE:3)
Block(-1,53,5,STONE:3)
Block(-1,53,6,STONE:3)
Block(-1,54,-7,OBSIDIAN:0)
Block(-1,54,-6,OBSIDIAN:0)
Block(-1,54,-5,OBSIDIAN:0)
Block(-1,54,-4,OBSIDIAN:0)
Block(-1,54,-3,OBSIDIAN:0)
Block(-1,54,-2,OBSIDIAN:0)
Block(-1,54,-1,OBSIDIAN:0)
Block(-1,54,0,OBSIDIAN:0)
Block(-1,54,1,STONE:3)
Block(-1,54,2,STONE:3)
Block(-1,54,3,STONE:3)
Block(-1,54,4,STONE:3)
Block(-1,54,5,STONE:3)
Block(-1,54,6,STONE:3)
Block(-1,55,-7,OBSIDIAN:0)
Block(-1,55,-6,OBSIDIAN:0)
Block(-1,55,-5,OBSIDIAN:0)
Block(-1,55,-4,OBSIDIAN:0)
Block(-1,55,-3,OBSIDIAN:0)
Block(-1,55,-2,OBSIDIAN:0)
Block(-1,55,-1,OBSIDIAN:0)
Block(-1,55,0,OBSIDIAN:0)
Block(-1,55,1,OBSIDIAN:0)
Block(-1,55,2,STONE:3)
Block(-1,55,3,STONE:3)
Block(-1,55,4,STONE:3)
Block(-1,55,5,STONE:3)
Block(-1,55,6,STONE:3)
Block(-1,56,-7,OBSIDIAN:0)
Block(-1,56,-6,OBSIDIAN:0)
Block(-1,56,-5,OBSIDIAN:0)
Block(-1,56,-4,OBSIDIAN:0)
Block(-1,56,-3,OBSIDIAN:0)
Block(-1,56,-2,OBSIDIAN:0)
Block(-1,56,-1,OBSIDIAN:0)
Block(-1,56,0,OBSIDIAN:0)
Block(-1,56,1,OBSIDIAN:0)
Block(-1,56,2,STONE:3)
Block(-1,56,3,STONE:3)
Block(-1,56,4,STONE:3)
Block(-1,56,5,STONE:3)
Block(-1,56,6,STONE:3)
Block(-1,57,-7,OBSIDIAN:0)
Block(-1,57,-6,OBSIDIAN:0)
Block(-1,57,-5,OBSIDIAN:0)
Block(-1,57,-4,OBSIDIAN:0)
Block(-1,57,-3,OBSIDIAN:0)
Block(-1,57,-2,OBSIDIAN:0)
Block(-1,57,-1,OBSIDIAN:0)
Block(-1,57,0,OBSIDIAN:0)
Block(-1,57,1,OBSIDIAN:0)
Block(-1,57,2,STONE:3)
Block(-1,57,3,STONE:3)
Block(-1,57,4,STONE:3)
Block(-1,57,5,STONE:3)
Block(-1,57,6,STONE:3)
Block(-1,58,-7,OBSIDIAN:0)
Block(-1,58,-6,OBSIDIAN:0)
Block(-1,58,-5,OBSIDIAN:0)
Block(-1,58,-4,OBSIDIAN:0)
Block(-1,58,-3,OBSIDIAN:0)
Block(-1,58,-2,OBSIDIAN:0)
Block(-1,58,-1,OBSIDIAN:0)
Block(-1,58,0,OBSIDIAN:0)
Block(-1,58,1,OBSIDIAN:0)
Block(-1,58,2,OBSIDIAN:0)
Block(-1,58,3,STONE:3)
Block(-1,58,4,STONE:3)
Block(-1,58,5,STONE:3)
Block(-1,59,-7,MAGMA:0)
Block(-1,59,-6,MAGMA:0)
Block(-1,59,-5,MAGMA:0)
Block(-1,59,-4,MAGMA:0)
Block(-1,59,-3,MAGMA:0)
Block(-1,59,-2,OBSIDIAN:0)
Block(-1,59,-1,OBSIDIAN:0)
Block(-1,59,0,OBSIDIAN:0)
Block(-1,59,1,OBSIDIAN:0)
Block(-1,59,3,STONE:3)
Block(-1,60,-7,MAGMA:0)
Block(-1,60,-6,MAGMA:0)
Block(-1,60,-5,MAGMA:0)
Block(-1,60,-4,MAGMA:0)
Block(-1,60,-2,MAGMA:0)
Block(-1,61,-7,MAGMA:0)
Block(-1,61,-6,MAGMA:0)
Block(0,22,-7,STONE:3)
Block(0,23,-7,STONE:3)
Block(0,24,-7,STONE:3)
Block(0,24,-6,STONE:3)
Block(0,25,-7,STONE:3)
Block(0,25,-6,STONE:3)
Block(0,26,-7,STONE:3)
Block(0,26,-6,STONE:3)
Block(0,26,-5,STONE:3)
Block(0,27,-7,STONE:3)
Block(0,27,-6,STONE:3)
Block(0,27,-5,STONE:3)
Block(0,27,-4,STONE:3)
Block(0,28,-7,STONE:3)
Block(0,28,-6,STONE:3)
Block(0,28,-5,STONE:3)
Block(0,28,-4,STONE:3)
Block(0,29,-7,STONE:3)
Block(0,29,-6,STONE:3)
Block(0,29,-5,STONE:3)
Block(0,29,-4,STONE:3)
Block(0,29,-3,STONE:3)
Block(0,30,-7,STONE:3)
Block(0,30,-6,STONE:3)
Block(0,30,-5,STONE:3)
Block(0,30,-4,STONE:3)
Block(0,30,-3,STONE:3)
Block(0,31,-7,STONE:3)
Block(0,31,-6,STONE:3)
Block(0,31,-5,STONE:3)
Block(0,31,-4,STONE:3)
Block(0,31,-3,STONE:3)
Block(0,31,-2,STONE:3)
Block(0,32,-7,STONE:3)
Block(0,32,-6,STONE:3)
Block(0,32,-5,STONE:3)
Block(0,32,-4,STONE:3)
Block(0,32,-3,STONE:3)
Block(0,32,-2,STONE:3)
Block(0,32,-1,STONE:3)
Block(0,33,-7,STONE:3)
Block(0,33,-6,STONE:3)
Block(0,33,-5,STONE:3)
Block(0,33,-4,STONE:3)
Block(0,33,-3,STONE:3)
Block(0,33,-2,STONE:3)
Block(0,33,-1,STONE:3)
Block(0,34,-7,STONE:3)
Block(0,34,-6,STONE:3)
Block(0,34,-5,STONE:3)
Block(0,34,-4,STONE:3)
Block(0,34,-3,STONE:3)
Block(0,34,-2,STONE:3)
Block(0,34,-1,STONE:3)
Block(0,35,-7,OBSIDIAN:0)
Block(0,35,-6,STONE:3)
Block(0,35,-5,STONE:3)
Block(0,35,-4,STONE:3)
Block(0,35,-3,STONE:3)
Block(0,35,-2,STONE:3)
Block(0,35,-1,STONE:3)
Block(0,36,-7,OBSIDIAN:0)
Block(0,36,-6,STONE:3)
Block(0,36,-5,STONE:3)
Block(0,36,-4,STONE:3)
Block(0,36,-3,STONE:3)
Block(0,36,-2,STONE:3)
Block(0,36,-1,STONE:3)
Block(0,37,-7,OBSIDIAN:0)
Block(0,37,-6,OBSIDIAN:0)
Block(0,37,-5,STONE:3)
Block(0,37,-4,STONE:3)
Block(0,37,-3,STONE:3)
Block(0,37,-2,STONE:3)
Block(0,37,-1,STONE:3)
Block(0,38,-7,OBSIDIAN:0)
Block(0,38,-6,OBSIDIAN:0)
Block(0,38,-5,STONE:3)
Block(0,38,-4,STONE:3)
Block(0,38,-3,STONE:3)
Block(0,38,-2,STONE:3)
Block(0,39,-7,OBSIDIAN:0)
Block(0,39,-6,STONE:3)
Block(0,39,-5,STONE:3)
Block(0,39,-4,STONE:3)
Block(0,39,-3,STONE:3)
Block(0,39,-2,STONE:3)
Block(0,39,-1,STONE:3)
Block(0,40,-7,OBSIDIAN:0)
Block(0,40,-6,STONE:3)
Block(0,40,-5,STONE:3)
Block(0,40,-4,STONE:3)
Block(0,40,-3,STONE:3)
Block(0,40,-2,STONE:3)
Block(0,40,-1,STONE:3)
Block(0,40,0,STONE:3)
Block(0,41,-7,OBSIDIAN:0)
Block(0,41,-6,STONE:3)
Block(0,41,-5,STONE:3)
Block(0,41,-4,STONE:3)
Block(0,41,-3,STONE:3)
Block(0,41,-2,STONE:3)
Block(0,41,-1,STONE:3)
Block(0,41,0,STONE:3)
Block(0,42,-7,OBSIDIAN:0)
Block(0,42,-6,STONE:3)
Block(0,42,-5,STONE:3)
Block(0,42,-4,STONE:3)
Block(0,42,-3,STONE:3)
Block(0,42,-2,STONE:3)
Block(0,42,-1,STONE:3)
Block(0,42,0,STONE:3)
Block(0,42,1,STONE:3)
Block(0,43,-7,OBSIDIAN:0)
Block(0,43,-6,STONE:3)
Block(0,43,-5,STONE:3)
Block(0,43,-4,STONE:3)
Block(0,43,-3,STONE:3)
Block(0,43,-2,STONE:3)
Block(0,43,-1,STONE:3)
Block(0,43,0,STONE:3)
Block(0,43,1,STONE:3)
Block(0,43,2,STONE:3)
Block(0,44,-7,OBSIDIAN:0)
Block(0,44,-6,OBSIDIAN:0)
Block(0,44,-5,STONE:3)
Block(0,44,-4,STONE:3)
Block(0,44,-3,STONE:3)
Block(0,44,-2,STONE:3)
Block(0,44,-1,STONE:3)
Block(0,44,0,STONE:3)
Block(0,44,1,STONE:3)
Block(0,44,2,STONE:3)
Block(0,44,3,STONE:3)
Block(0,45,-7,OBSIDIAN:0)
Block(0,45,-6,OBSIDIAN:0)
Block(0,45,-5,OBSIDIAN:0)
Block(0,45,-4,STONE:3)
Block(0,45,-3,STONE:3)
Block(0,45,-2,STONE:3)
Block(0,45,-1,STONE:3)
Block(0,45,0,STONE:3)
Block(0,45,1,STONE:3)
Block(0,45,2,STONE:3)
Block(0,45,3,STONE:3)
Block(0,45,4,STONE:3)
Block(0,46,-7,OBSIDIAN:0)
Block(0,46,-6,OBSIDIAN:0)
Block(0,46,-5,OBSIDIAN:0)
Block(0,46,-4,OBSIDIAN:0)
Block(0,46,-3,STONE:3)
Block(0,46,-2,STONE:3)
Block(0,46,-1,STONE:3)
Block(0,46,0,STONE:3)
Block(0,46,1,STONE:3)
Block(0,46,2,STONE:3)
Block(0,46,3,STONE:3)
Block(0,46,4,STONE:3)
Block(0,47,-7,OBSIDIAN:0)
Block(0,47,-6,OBSIDIAN:0)
Block(0,47,-5,OBSIDIAN:0)
Block(0,47,-4,OBSIDIAN:0)
Block(0,47,-3,OBSIDIAN:0)
Block(0,47,-2,OBSIDIAN:0)
Block(0,47,-1,OBSIDIAN:0)
Block(0,47,0,OBSIDIAN:0)
Block(0,47,1,STONE:3)
Block(0,47,2,STONE:3)
Block(0,47,3,STONE:3)
Block(0,47,4,STONE:3)
Block(0,47,5,STONE:3)
Block(0,48,-7,OBSIDIAN:0)
Block(0,48,-6,OBSIDIAN:0)
Block(0,48,-5,OBSIDIAN:0)
Block(0,48,-4,OBSIDIAN:0)
Block(0,48,-3,OBSIDIAN:0)
Block(0,48,-2,OBSIDIAN:0)
Block(0,48,-1,OBSIDIAN:0)
Block(0,48,0,OBSIDIAN:0)
Block(0,48,1,STONE:3)
Block(0,48,2,STONE:3)
Block(0,48,3,STONE:3)
Block(0,48,4,STONE:3)
Block(0,48,5,STONE:3)
Block(0,49,-7,OBSIDIAN:0)
Block(0,49,-6,OBSIDIAN:0)
Block(0,49,-5,OBSIDIAN:0)
Block(0,49,-4,OBSIDIAN:0)
Block(0,49,-3,OBSIDIAN:0)
Block(0,49,-2,OBSIDIAN:0)
Block(0,49,-1,OBSIDIAN:0)
Block(0,49,0,OBSIDIAN:0)
Block(0,49,1,STONE:3)
Block(0,49,2,STONE:3)
Block(0,49,3,STONE:3)
Block(0,49,4,STONE:3)
Block(0,49,5,STONE:3)
Block(0,49,6,STONE:3)
Block(0,50,-7,OBSIDIAN:0)
Block(0,50,-6,OBSIDIAN:0)
Block(0,50,-5,OBSIDIAN:0)
Block(0,50,-4,OBSIDIAN:0)
Block(0,50,-3,OBSIDIAN:0)
Block(0,50,-2,OBSIDIAN:0)
Block(0,50,-1,OBSIDIAN:0)
Block(0,50,0,OBSIDIAN:0)
Block(0,50,1,STONE:3)
Block(0,50,2,STONE:3)
Block(0,50,3,STONE:3)
Block(0,50,4,STONE:3)
Block(0,50,5,STONE:3)
Block(0,50,6,STONE:3)
Block(0,51,-7,OBSIDIAN:0)
Block(0,51,-6,OBSIDIAN:0)
Block(0,51,-5,OBSIDIAN:0)
Block(0,51,-4,OBSIDIAN:0)
Block(0,51,-3,OBSIDIAN:0)
Block(0,51,-2,OBSIDIAN:0)
Block(0,51,-1,OBSIDIAN:0)
Block(0,51,0,OBSIDIAN:0)
Block(0,51,1,STONE:3)
Block(0,51,2,STONE:3)
Block(0,51,3,STONE:3)
Block(0,51,4,STONE:3)
Block(0,51,5,STONE:3)
Block(0,51,6,STONE:3)
Block(0,52,-7,OBSIDIAN:0)
Block(0,52,-6,OBSIDIAN:0)
Block(0,52,-5,OBSIDIAN:0)
Block(0,52,-4,OBSIDIAN:0)
Block(0,52,-3,OBSIDIAN:0)
Block(0,52,-2,OBSIDIAN:0)
Block(0,52,-1,OBSIDIAN:0)
Block(0,52,0,OBSIDIAN:0)
Block(0,52,1,STONE:3)
Block(0,52,2,STONE:3)
Block(0,52,3,STONE:3)
Block(0,52,4,STONE:3)
Block(0,52,5,STONE:3)
Block(0,52,6,STONE:3)
Block(0,53,-7,OBSIDIAN:0)
Block(0,53,-6,OBSIDIAN:0)
Block(0,53,-5,OBSIDIAN:0)
Block(0,53,-4,OBSIDIAN:0)
Block(0,53,-3,OBSIDIAN:0)
Block(0,53,-2,OBSIDIAN:0)
Block(0,53,-1,OBSIDIAN:0)
Block(0,53,0,OBSIDIAN:0)
Block(0,53,1,STONE:3)
Block(0,53,2,STONE:3)
Block(0,53,3,STONE:3)
Block(0,53,4,STONE:3)
Block(0,53,5,STONE:3)
Block(0,53,6,STONE:3)
Block(0,54,-7,OBSIDIAN:0)
Block(0,54,-6,OBSIDIAN:0)
Block(0,54,-5,OBSIDIAN:0)
Block(0,54,-4,OBSIDIAN:0)
Block(0,54,-3,OBSIDIAN:0)
Block(0,54,-2,OBSIDIAN:0)
Block(0,54,-1,OBSIDIAN:0)
Block(0,54,0,OBSIDIAN:0)
Block(0,54,1,STONE:3)
Block(0,54,2,STONE:3)
Block(0,54,3,STONE:3)
Block(0,54,4,STONE:3)
Block(0,54,5,STONE:3)
Block(0,54,6,STONE:3)
Block(0,55,-7,OBSIDIAN:0)
Block(0,55,-6,OBSIDIAN:0)
Block(0,55,-5,OBSIDIAN:0)
Block(0,55,-4,OBSIDIAN:0)
Block(0,55,-3,OBSIDIAN:0)
Block(0,55,-2,OBSIDIAN:0)
Block(0,55,-1,OBSIDIAN:0)
Block(0,55,0,OBSIDIAN:0)
Block(0,55,1,OBSIDIAN:0)
Block(0,55,2,STONE:3)
Block(0,55,3,STONE:3)
Block(0,55,4,STONE:3)
Block(0,55,5,STONE:3)
Block(0,55,6,STONE:3)
Block(0,56,-7,OBSIDIAN:0)
Block(0,56,-6,OBSIDIAN:0)
Block(0,56,-5,OBSIDIAN:0)
Block(0,56,-4,OBSIDIAN:0)
Block(0,56,-3,OBSIDIAN:0)
Block(0,56,-2,OBSIDIAN:0)
Block(0,56,-1,OBSIDIAN:0)
Block(0,56,0,OBSIDIAN:0)
Block(0,56,1,STONE:3)
Block(0,56,2,STONE:3)
Block(0,56,3,STONE:3)
Block(0,56,4,STONE:3)
Block(0,56,5,STONE:3)
Block(0,56,6,STONE:3)
Block(0,57,-7,OBSIDIAN:0)
Block(0,57,-6,OBSIDIAN:0)
Block(0,57,-5,OBSIDIAN:0)
Block(0,57,-4,OBSIDIAN:0)
Block(0,57,-3,OBSIDIAN:0)
Block(0,57,-2,OBSIDIAN:0)
Block(0,57,-1,OBSIDIAN:0)
Block(0,57,0,OBSIDIAN:0)
Block(0,57,1,OBSIDIAN:0)
Block(0,57,2,STONE:3)
Block(0,57,3,STONE:3)
Block(0,57,4,STONE:3)
Block(0,57,5,STONE:3)
Block(0,57,6,STONE:3)
Block(0,58,-7,OBSIDIAN:0)
Block(0,58,-6,OBSIDIAN:0)
Block(0,58,-5,OBSIDIAN:0)
Block(0,58,-4,OBSIDIAN:0)
Block(0,58,-3,OBSIDIAN:0)
Block(0,58,-2,OBSIDIAN:0)
Block(0,58,-1,OBSIDIAN:0)
Block(0,58,0,OBSIDIAN:0)
Block(0,58,1,OBSIDIAN:0)
Block(0,58,2,OBSIDIAN:0)
Block(0,58,3,STONE:3)
Block(0,58,4,STONE:3)
Block(0,58,5,STONE:3)
Block(0,58,6,STONE:3)
Block(0,59,-7,MAGMA:0)
Block(0,59,-6,MAGMA:0)
Block(0,59,-5,MAGMA:0)
Block(0,59,-4,MAGMA:0)
Block(0,59,-3,MAGMA:0)
Block(0,59,-2,MAGMA:0)
Block(0,59,-1,MAGMA:0)
Block(0,59,0,OBSIDIAN:0)
Block(0,59,1,OBSIDIAN:0)
Block(0,59,2,OBSIDIAN:0)
Block(0,59,3,OBSIDIAN:0)
Block(0,59,4,STONE:3)
Block(0,60,-7,MAGMA:0)
Block(0,60,-6,MAGMA:0)
Block(0,60,-5,MAGMA:0)
Block(0,60,-4,MAGMA:0)
Block(0,60,-3,MAGMA:0)
Block(0,60,-2,MAGMA:0)
Block(0,60,-1,MAGMA:0)
Block(0,60,0,MAGMA:0)
Block(0,61,-7,MAGMA:0)
Block(0,61,-6,MAGMA:0)
Block(0,61,-5,MAGMA:0)
Block(0,61,-4,MAGMA:0)
Block(0,61,-3,MAGMA:0)
Block(0,62,-7,MAGMA:0)
Block(0,62,-6,MAGMA:0)
Block(1,22,-7,STONE:3)
Block(1,23,-7,STONE:3)
Block(1,23,-6,STONE:3)
Block(1,24,-7,STONE:3)
Block(1,24,-6,STONE:3)
Block(1,25,-7,STONE:3)
Block(1,25,-6,STONE:3)
Block(1,26,-7,STONE:3)
Block(1,26,-6,STONE:3)
Block(1,26,-5,STONE:3)
Block(1,27,-7,STONE:3)
Block(1,27,-6,STONE:3)
Block(1,27,-5,STONE:3)
Block(1,27,-4,STONE:3)
Block(1,28,-7,STONE:3)
Block(1,28,-6,STONE:3)
Block(1,28,-5,STONE:3)
Block(1,28,-4,STONE:3)
Block(1,29,-7,STONE:3)
Block(1,29,-6,STONE:3)
Block(1,29,-5,STONE:3)
Block(1,29,-4,STONE:3)
Block(1,29,-3,STONE:3)
Block(1,30,-7,STONE:3)
Block(1,30,-6,STONE:3)
Block(1,30,-5,STONE:3)
Block(1,30,-4,STONE:3)
Block(1,30,-3,STONE:3)
Block(1,31,-7,STONE:3)
Block(1,31,-6,STONE:3)
Block(1,31,-5,STONE:3)
Block(1,31,-4,STONE:3)
Block(1,31,-3,STONE:3)
Block(1,32,-7,STONE:3)
Block(1,32,-6,STONE:3)
Block(1,32,-5,STONE:3)
Block(1,32,-4,STONE:3)
Block(1,32,-3,STONE:3)
Block(1,32,-2,STONE:3)
Block(1,33,-7,STONE:3)
Block(1,33,-6,STONE:3)
Block(1,33,-5,STONE:3)
Block(1,33,-4,STONE:3)
Block(1,33,-3,STONE:3)
Block(1,33,-2,STONE:3)
Block(1,33,-1,STONE:3)
Block(1,34,-7,STONE:3)
Block(1,34,-6,STONE:3)
Block(1,34,-5,STONE:3)
Block(1,34,-4,STONE:3)
Block(1,34,-3,STONE:3)
Block(1,34,-2,STONE:3)
Block(1,35,-7,STONE:3)
Block(1,35,-6,STONE:3)
Block(1,35,-5,STONE:3)
Block(1,35,-4,STONE:3)
Block(1,35,-3,STONE:3)
Block(1,35,-2,STONE:3)
Block(1,36,-7,STONE:3)
Block(1,36,-6,STONE:3)
Block(1,36,-5,STONE:3)
Block(1,36,-4,STONE:3)
Block(1,36,-3,STONE:3)
Block(1,36,-2,STONE:3)
Block(1,37,-7,STONE:3)
Block(1,37,-6,STONE:3)
Block(1,37,-5,STONE:3)
Block(1,37,-4,STONE:3)
Block(1,37,-3,STONE:3)
Block(1,37,-2,STONE:3)
Block(1,38,-7,OBSIDIAN:0)
Block(1,38,-6,STONE:3)
Block(1,38,-5,STONE:3)
Block(1,38,-4,STONE:3)
Block(1,38,-3,STONE:3)
Block(1,38,-2,STONE:3)
Block(1,39,-7,OBSIDIAN:0)
Block(1,39,-6,STONE:3)
Block(1,39,-5,STONE:3)
Block(1,39,-4,STONE:3)
Block(1,39,-3,STONE:3)
Block(1,39,-2,STONE:3)
Block(1,39,-1,STONE:3)
Block(1,40,-7,OBSIDIAN:0)
Block(1,40,-6,STONE:3)
Block(1,40,-5,STONE:3)
Block(1,40,-4,STONE:3)
Block(1,40,-3,STONE:3)
Block(1,40,-2,STONE:3)
Block(1,40,-1,STONE:3)
Block(1,41,-7,OBSIDIAN:0)
Block(1,41,-6,STONE:3)
Block(1,41,-5,STONE:3)
Block(1,41,-4,STONE:3)
Block(1,41,-3,STONE:3)
Block(1,41,-2,STONE:3)
Block(1,41,-1,STONE:3)
Block(1,42,-7,OBSIDIAN:0)
Block(1,42,-6,STONE:3)
Block(1,42,-5,STONE:3)
Block(1,42,-4,STONE:3)
Block(1,42,-3,STONE:3)
Block(1,42,-2,STONE:3)
Block(1,42,-1,STONE:3)
Block(1,42,0,STONE:3)
Block(1,43,-7,OBSIDIAN:0)
Block(1,43,-6,STONE:3)
Block(1,43,-5,STONE:3)
Block(1,43,-4,STONE:3)
Block(1,43,-3,STONE:3)
Block(1,43,-2,STONE:3)
Block(1,43,-1,STONE:3)
Block(1,43,0,STONE:3)
Block(1,43,1,STONE:3)
Block(1,44,-7,OBSIDIAN:0)
Block(1,44,-6,OBSIDIAN:0)
Block(1,44,-5,STONE:3)
Block(1,44,-4,STONE:3)
Block(1,44,-3,STONE:3)
Block(1,44,-2,STONE:3)
Block(1,44,-1,STONE:3)
Block(1,44,0,STONE:3)
Block(1,44,1,STONE:3)
Block(1,44,2,STONE:3)
Block(1,45,-7,OBSIDIAN:0)
Block(1,45,-6,OBSIDIAN:0)
Block(1,45,-5,OBSIDIAN:0)
Block(1,45,-4,STONE:3)
Block(1,45,-3,STONE:3)
Block(1,45,-2,STONE:3)
Block(1,45,-1,STONE:3)
Block(1,45,0,STONE:3)
Block(1,45,1,STONE:3)
Block(1,45,2,STONE:3)
Block(1,45,3,STONE:3)
Block(1,45,4,STONE:3)
Block(1,46,-7,OBSIDIAN:0)
Block(1,46,-6,OBSIDIAN:0)
Block(1,46,-5,OBSIDIAN:0)
Block(1,46,-4,OBSIDIAN:0)
Block(1,46,-3,STONE:3)
Block(1,46,-2,STONE:3)
Block(1,46,-1,STONE:3)
Block(1,46,0,STONE:3)
Block(1,46,1,STONE:3)
Block(1,46,2,STONE:3)
Block(1,46,3,STONE:3)
Block(1,46,4,STONE:3)
Block(1,47,-7,OBSIDIAN:0)
Block(1,47,-6,OBSIDIAN:0)
Block(1,47,-5,OBSIDIAN:0)
Block(1,47,-4,OBSIDIAN:0)
Block(1,47,-3,OBSIDIAN:0)
Block(1,47,-2,OBSIDIAN:0)
Block(1,47,-1,OBSIDIAN:0)
Block(1,47,0,OBSIDIAN:0)
Block(1,47,1,STONE:3)
Block(1,47,2,STONE:3)
Block(1,47,3,STONE:3)
Block(1,47,4,STONE:3)
Block(1,47,5,STONE:3)
Block(1,48,-7,OBSIDIAN:0)
Block(1,48,-6,OBSIDIAN:0)
Block(1,48,-5,OBSIDIAN:0)
Block(1,48,-4,OBSIDIAN:0)
Block(1,48,-3,OBSIDIAN:0)
Block(1,48,-2,OBSIDIAN:0)
Block(1,48,-1,OBSIDIAN:0)
Block(1,48,0,OBSIDIAN:0)
Block(1,48,1,STONE:3)
Block(1,48,2,STONE:3)
Block(1,48,3,STONE:3)
Block(1,48,4,STONE:3)
Block(1,48,5,STONE:3)
Block(1,48,6,STONE:3)
Block(1,49,-7,OBSIDIAN:0)
Block(1,49,-6,OBSIDIAN:0)
Block(1,49,-5,OBSIDIAN:0)
Block(1,49,-4,OBSIDIAN:0)
Block(1,49,-3,OBSIDIAN:0)
Block(1,49,-2,OBSIDIAN:0)
Block(1,49,-1,OBSIDIAN:0)
Block(1,49,0,OBSIDIAN:0)
Block(1,49,1,STONE:3)
Block(1,49,2,STONE:3)
Block(1,49,3,STONE:3)
Block(1,49,4,STONE:3)
Block(1,49,5,STONE:3)
Block(1,49,6,STONE:3)
Block(1,50,-7,OBSIDIAN:0)
Block(1,50,-6,OBSIDIAN:0)
Block(1,50,-5,OBSIDIAN:0)
Block(1,50,-4,OBSIDIAN:0)
Block(1,50,-3,OBSIDIAN:0)
Block(1,50,-2,OBSIDIAN:0)
Block(1,50,-1,OBSIDIAN:0)
Block(1,50,0,OBSIDIAN:0)
Block(1,50,1,STONE:3)
Block(1,50,2,STONE:3)
Block(1,50,3,STONE:3)
Block(1,50,4,STONE:3)
Block(1,50,5,STONE:3)
Block(1,50,6,STONE:3)
Block(1,51,-7,OBSIDIAN:0)
Block(1,51,-6,OBSIDIAN:0)
Block(1,51,-5,OBSIDIAN:0)
Block(1,51,-4,OBSIDIAN:0)
Block(1,51,-3,OBSIDIAN:0)
Block(1,51,-2,OBSIDIAN:0)
Block(1,51,-1,OBSIDIAN:0)
Block(1,51,0,OBSIDIAN:0)
Block(1,51,1,STONE:3)
Block(1,51,2,STONE:3)
Block(1,51,3,STONE:3)
Block(1,51,4,STONE:3)
Block(1,51,5,STONE:3)
Block(1,51,6,STONE:3)
Block(1,52,-7,OBSIDIAN:0)
Block(1,52,-6,OBSIDIAN:0)
Block(1,52,-5,OBSIDIAN:0)
Block(1,52,-4,OBSIDIAN:0)
Block(1,52,-3,OBSIDIAN:0)
Block(1,52,-2,OBSIDIAN:0)
Block(1,52,-1,OBSIDIAN:0)
Block(1,52,0,OBSIDIAN:0)
Block(1,52,1,STONE:3)
Block(1,52,2,STONE:3)
Block(1,52,3,STONE:3)
Block(1,52,4,STONE:3)
Block(1,52,5,STONE:3)
Block(1,52,6,STONE:3)
Block(1,53,-7,OBSIDIAN:0)
Block(1,53,-6,OBSIDIAN:0)
Block(1,53,-5,OBSIDIAN:0)
Block(1,53,-4,OBSIDIAN:0)
Block(1,53,-3,OBSIDIAN:0)
Block(1,53,-2,OBSIDIAN:0)
Block(1,53,-1,OBSIDIAN:0)
Block(1,53,0,OBSIDIAN:0)
Block(1,53,1,STONE:3)
Block(1,53,2,STONE:3)
Block(1,53,3,STONE:3)
Block(1,53,4,STONE:3)
Block(1,53,5,STONE:3)
Block(1,53,6,STONE:3)
Block(1,54,-7,OBSIDIAN:0)
Block(1,54,-6,OBSIDIAN:0)
Block(1,54,-5,OBSIDIAN:0)
Block(1,54,-4,OBSIDIAN:0)
Block(1,54,-3,OBSIDIAN:0)
Block(1,54,-2,OBSIDIAN:0)
Block(1,54,-1,OBSIDIAN:0)
Block(1,54,0,OBSIDIAN:0)
Block(1,54,1,STONE:3)
Block(1,54,2,STONE:3)
Block(1,54,3,STONE:3)
Block(1,54,4,STONE:3)
Block(1,54,5,STONE:3)
Block(1,54,6,STONE:3)
Block(1,55,-7,OBSIDIAN:0)
Block(1,55,-6,OBSIDIAN:0)
Block(1,55,-5,OBSIDIAN:0)
Block(1,55,-4,OBSIDIAN:0)
Block(1,55,-3,OBSIDIAN:0)
Block(1,55,-2,OBSIDIAN:0)
Block(1,55,-1,OBSIDIAN:0)
Block(1,55,0,OBSIDIAN:0)
Block(1,55,1,OBSIDIAN:0)
Block(1,55,2,STONE:3)
Block(1,55,3,STONE:3)
Block(1,55,4,STONE:3)
Block(1,55,5,STONE:3)
Block(1,55,6,STONE:3)
Block(1,56,-7,OBSIDIAN:0)
Block(1,56,-6,OBSIDIAN:0)
Block(1,56,-5,OBSIDIAN:0)
Block(1,56,-4,OBSIDIAN:0)
Block(1,56,-3,OBSIDIAN:0)
Block(1,56,-2,OBSIDIAN:0)
Block(1,56,-1,OBSIDIAN:0)
Block(1,56,0,OBSIDIAN:0)
Block(1,56,1,STONE:3)
Block(1,56,2,STONE:3)
Block(1,56,3,STONE:3)
Block(1,56,4,STONE:3)
Block(1,56,5,STONE:3)
Block(1,56,6,STONE:3)
Block(1,57,-7,OBSIDIAN:0)
Block(1,57,-6,OBSIDIAN:0)
Block(1,57,-5,OBSIDIAN:0)
Block(1,57,-4,OBSIDIAN:0)
Block(1,57,-3,OBSIDIAN:0)
Block(1,57,-2,OBSIDIAN:0)
Block(1,57,-1,OBSIDIAN:0)
Block(1,57,0,OBSIDIAN:0)
Block(1,57,1,OBSIDIAN:0)
Block(1,57,2,STONE:3)
Block(1,57,3,STONE:3)
Block(1,57,4,STONE:3)
Block(1,57,5,STONE:3)
Block(1,57,6,STONE:3)
Block(1,58,-7,OBSIDIAN:0)
Block(1,58,-6,OBSIDIAN:0)
Block(1,58,-5,OBSIDIAN:0)
Block(1,58,-4,OBSIDIAN:0)
Block(1,58,-3,OBSIDIAN:0)
Block(1,58,-2,OBSIDIAN:0)
Block(1,58,-1,OBSIDIAN:0)
Block(1,58,0,OBSIDIAN:0)
Block(1,58,1,OBSIDIAN:0)
Block(1,58,2,OBSIDIAN:0)
Block(1,58,3,STONE:3)
Block(1,58,4,STONE:3)
Block(1,58,5,STONE:3)
Block(1,58,6,STONE:3)
Block(1,59,-7,OBSIDIAN:0)
Block(1,59,-6,OBSIDIAN:0)
Block(1,59,-5,MAGMA:0)
Block(1,59,-4,MAGMA:0)
Block(1,59,-3,MAGMA:0)
Block(1,59,-2,MAGMA:0)
Block(1,59,-1,MAGMA:0)
Block(1,59,0,MAGMA:0)
Block(1,59,1,OBSIDIAN:0)
Block(1,59,2,OBSIDIAN:0)
Block(1,59,3,OBSIDIAN:0)
Block(1,59,4,STONE:3)
Block(1,59,5,STONE:3)
Block(1,60,-7,MAGMA:0)
Block(1,60,-6,MAGMA:0)
Block(1,60,-5,MAGMA:0)
Block(1,60,-4,MAGMA:0)
Block(1,60,-3,MAGMA:0)
Block(1,60,-2,MAGMA:0)
Block(1,60,-1,MAGMA:0)
Block(1,60,0,MAGMA:0)
Block(1,61,-7,MAGMA:0)
Block(1,61,-6,MAGMA:0)
Block(1,61,-5,MAGMA:0)
Block(1,61,-4,MAGMA:0)
Block(1,61,-3,MAGMA:0)
Block(1,61,-2,MAGMA:0)
Block(1,61,-1,MAGMA:0)
Block(1,62,-7,MAGMA:0)
Block(1,62,-6,MAGMA:0)
Block(1,62,-5,MAGMA:0)
Block(1,62,-3,MAGMA:0)
Block(1,62,-2,MAGMA:0)
Block(1,63,-7,OBSIDIAN:0)
Block(1,63,-6,OBSIDIAN:0)
Block(2,22,-7,STONE:3)
Block(2,23,-7,STONE:3)
Block(2,24,-7,STONE:3)
Block(2,24,-6,STONE:3)
Block(2,25,-7,STONE:3)
Block(2,25,-6,STONE:3)
Block(2,26,-7,STONE:3)
Block(2,26,-6,STONE:3)
Block(2,27,-7,STONE:3)
Block(2,27,-6,STONE:3)
Block(2,27,-5,STONE:3)
Block(2,28,-7,STONE:3)
Block(2,28,-6,STONE:3)
Block(2,28,-5,STONE:3)
Block(2,28,-4,STONE:3)
Block(2,29,-7,STONE:3)
Block(2,29,-6,STONE:3)
Block(2,29,-5,STONE:3)
Block(2,29,-4,STONE:3)
Block(2,30,-7,STONE:3)
Block(2,30,-6,STONE:3)
Block(2,30,-5,STONE:3)
Block(2,30,-4,STONE:3)
Block(2,31,-7,STONE:3)
Block(2,31,-6,STONE:3)
Block(2,31,-5,STONE:3)
Block(2,31,-4,STONE:3)
Block(2,31,-3,STONE:3)
Block(2,32,-7,STONE:3)
Block(2,32,-6,STONE:3)
Block(2,32,-5,STONE:3)
Block(2,32,-4,STONE:3)
Block(2,32,-3,STONE:3)
Block(2,33,-7,STONE:3)
Block(2,33,-6,STONE:3)
Block(2,33,-5,STONE:3)
Block(2,33,-4,STONE:3)
Block(2,33,-3,STONE:3)
Block(2,33,-2,STONE:3)
Block(2,34,-7,STONE:3)
Block(2,34,-6,STONE:3)
Block(2,34,-5,STONE:3)
Block(2,34,-4,STONE:3)
Block(2,34,-3,STONE:3)
Block(2,34,-2,STONE:3)
Block(2,35,-7,STONE:3)
Block(2,35,-6,STONE:3)
Block(2,35,-5,STONE:3)
Block(2,35,-4,STONE:3)
Block(2,35,-3,STONE:3)
Block(2,36,-7,STONE:3)
Block(2,36,-6,STONE:3)
Block(2,36,-5,STONE:3)
Block(2,36,-4,STONE:3)
Block(2,36,-3,STONE:3)
Block(2,36,-2,STONE:3)
Block(2,37,-7,STONE:3)
Block(2,37,-6,STONE:3)
Block(2,37,-5,STONE:3)
Block(2,37,-4,STONE:3)
Block(2,37,-3,STONE:3)
Block(2,37,-2,STONE:3)
Block(2,38,-7,STONE:3)
Block(2,38,-6,STONE:3)
Block(2,38,-5,STONE:3)
Block(2,38,-4,STONE:3)
Block(2,38,-3,STONE:3)
Block(2,38,-2,STONE:3)
Block(2,39,-7,OBSIDIAN:0)
Block(2,39,-6,STONE:3)
Block(2,39,-5,STONE:3)
Block(2,39,-4,STONE:3)
Block(2,39,-3,STONE:3)
Block(2,39,-2,STONE:3)
Block(2,40,-7,OBSIDIAN:0)
Block(2,40,-6,STONE:3)
Block(2,40,-5,STONE:3)
Block(2,40,-4,STONE:3)
Block(2,40,-3,STONE:3)
Block(2,40,-2,STONE:3)
Block(2,41,-7,OBSIDIAN:0)
Block(2,41,-6,STONE:3)
Block(2,41,-5,STONE:3)
Block(2,41,-4,STONE:3)
Block(2,41,-3,STONE:3)
Block(2,41,-2,STONE:3)
Block(2,41,-1,STONE:3)
Block(2,42,-7,OBSIDIAN:0)
Block(2,42,-6,STONE:3)
Block(2,42,-5,STONE:3)
Block(2,42,-4,STONE:3)
Block(2,42,-3,STONE:3)
Block(2,42,-2,STONE:3)
Block(2,42,-1,STONE:3)
Block(2,42,0,STONE:3)
Block(2,43,-7,OBSIDIAN:0)
Block(2,43,-6,STONE:3)
Block(2,43,-5,STONE:3)
Block(2,43,-4,STONE:3)
Block(2,43,-3,STONE:3)
Block(2,43,-2,STONE:3)
Block(2,43,-1,STONE:3)
Block(2,43,0,STONE:3)
Block(2,44,-7,OBSIDIAN:0)
Block(2,44,-6,OBSIDIAN:0)
Block(2,44,-5,STONE:3)
Block(2,44,-4,STONE:3)
Block(2,44,-3,STONE:3)
Block(2,44,-2,STONE:3)
Block(2,44,-1,STONE:3)
Block(2,44,0,STONE:3)
Block(2,44,2,STONE:3)
Block(2,45,-7,OBSIDIAN:0)
Block(2,45,-6,OBSIDIAN:0)
Block(2,45,-5,OBSIDIAN:0)
Block(2,45,-4,STONE:3)
Block(2,45,-3,STONE:3)
Block(2,45,-2,STONE:3)
Block(2,45,-1,STONE:3)
Block(2,45,0,STONE:3)
Block(2,45,1,STONE:3)
Block(2,45,2,STONE:3)
Block(2,45,3,STONE:3)
Block(2,45,4,STONE:3)
Block(2,46,-7,OBSIDIAN:0)
Block(2,46,-6,OBSIDIAN:0)
Block(2,46,-5,OBSIDIAN:0)
Block(2,46,-4,OBSIDIAN:0)
Block(2,46,-3,STONE:3)
Block(2,46,-2,STONE:3)
Block(2,46,-1,STONE:3)
Block(2,46,0,STONE:3)
Block(2,46,1,STONE:3)
Block(2,46,2,STONE:3)
Block(2,46,3,STONE:3)
Block(2,46,4,STONE:3)
Block(2,46,5,STONE:3)
Block(2,47,-7,OBSIDIAN:0)
Block(2,47,-6,OBSIDIAN:0)
Block(2,47,-5,OBSIDIAN:0)
Block(2,47,-4,OBSIDIAN:0)
Block(2,47,-3,OBSIDIAN:0)
Block(2,47,-2,OBSIDIAN:0)
Block(2,47,-1,OBSIDIAN:0)
Block(2,47,0,STONE:3)
Block(2,47,1,STONE:3)
Block(2,47,2,STONE:3)
Block(2,47,3,STONE:3)
Block(2,47,4,STONE:3)
Block(2,47,5,STONE:3)
Block(2,47,6,STONE:3)
Block(2,48,-7,OBSIDIAN:0)
Block(2,48,-6,OBSIDIAN:0)
Block(2,48,-5,OBSIDIAN:0)
Block(2,48,-4,OBSIDIAN:0)
Block(2,48,-3,OBSIDIAN:0)
Block(2,48,-2,OBSIDIAN:0)
Block(2,48,-1,OBSIDIAN:0)
Block(2,48,0,OBSIDIAN:0)
Block(2,48,1,STONE:3)
Block(2,48,2,STONE:3)
Block(2,48,3,STONE:3)
Block(2,48,4,STONE:3)
Block(2,48,5,STONE:3)
Block(2,48,6,STONE:3)
Block(2,49,-7,OBSIDIAN:0)
Block(2,49,-6,OBSIDIAN:0)
Block(2,49,-5,OBSIDIAN:0)
Block(2,49,-4,OBSIDIAN:0)
Block(2,49,-3,OBSIDIAN:0)
Block(2,49,-2,OBSIDIAN:0)
Block(2,49,-1,OBSIDIAN:0)
Block(2,49,0,OBSIDIAN:0)
Block(2,49,1,STONE:3)
Block(2,49,2,STONE:3)
Block(2,49,3,STONE:3)
Block(2,49,4,STONE:3)
Block(2,49,5,STONE:3)
Block(2,49,6,STONE:3)
Block(2,50,-7,OBSIDIAN:0)
Block(2,50,-6,OBSIDIAN:0)
Block(2,50,-5,OBSIDIAN:0)
Block(2,50,-4,OBSIDIAN:0)
Block(2,50,-3,OBSIDIAN:0)
Block(2,50,-2,OBSIDIAN:0)
Block(2,50,-1,OBSIDIAN:0)
Block(2,50,0,OBSIDIAN:0)
Block(2,50,1,STONE:3)
Block(2,50,2,STONE:3)
Block(2,50,3,STONE:3)
Block(2,50,4,STONE:3)
Block(2,50,5,STONE:3)
Block(2,50,6,STONE:3)
Block(2,51,-7,OBSIDIAN:0)
Block(2,51,-6,OBSIDIAN:0)
Block(2,51,-5,OBSIDIAN:0)
Block(2,51,-4,OBSIDIAN:0)
Block(2,51,-3,OBSIDIAN:0)
Block(2,51,-2,OBSIDIAN:0)
Block(2,51,-1,OBSIDIAN:0)
Block(2,51,0,OBSIDIAN:0)
Block(2,51,1,STONE:3)
Block(2,51,2,STONE:3)
Block(2,51,3,STONE:3)
Block(2,51,4,STONE:3)
Block(2,51,5,STONE:3)
Block(2,51,6,STONE:3)
Block(2,52,-7,OBSIDIAN:0)
Block(2,52,-6,OBSIDIAN:0)
Block(2,52,-5,OBSIDIAN:0)
Block(2,52,-4,OBSIDIAN:0)
Block(2,52,-3,OBSIDIAN:0)
Block(2,52,-2,OBSIDIAN:0)
Block(2,52,-1,OBSIDIAN:0)
Block(2,52,0,OBSIDIAN:0)
Block(2,52,1,STONE:3)
Block(2,52,2,STONE:3)
Block(2,52,3,STONE:3)
Block(2,52,4,STONE:3)
Block(2,52,5,STONE:3)
Block(2,52,6,STONE:3)
Block(2,53,-7,OBSIDIAN:0)
Block(2,53,-6,OBSIDIAN:0)
Block(2,53,-5,OBSIDIAN:0)
Block(2,53,-4,OBSIDIAN:0)
Block(2,53,-3,OBSIDIAN:0)
Block(2,53,-2,OBSIDIAN:0)
Block(2,53,-1,OBSIDIAN:0)
Block(2,53,0,OBSIDIAN:0)
Block(2,53,1,STONE:3)
Block(2,53,2,STONE:3)
Block(2,53,3,STONE:3)
Block(2,53,4,STONE:3)
Block(2,53,5,STONE:3)
Block(2,53,6,STONE:3)
Block(2,54,-7,OBSIDIAN:0)
Block(2,54,-6,OBSIDIAN:0)
Block(2,54,-5,OBSIDIAN:0)
Block(2,54,-4,OBSIDIAN:0)
Block(2,54,-3,OBSIDIAN:0)
Block(2,54,-2,OBSIDIAN:0)
Block(2,54,-1,OBSIDIAN:0)
Block(2,54,0,OBSIDIAN:0)
Block(2,54,1,OBSIDIAN:0)
Block(2,54,2,STONE:3)
Block(2,54,3,STONE:3)
Block(2,54,4,STONE:3)
Block(2,54,5,STONE:3)
Block(2,54,6,STONE:3)
Block(2,55,-7,OBSIDIAN:0)
Block(2,55,-6,OBSIDIAN:0)
Block(2,55,-5,OBSIDIAN:0)
Block(2,55,-4,OBSIDIAN:0)
Block(2,55,-3,OBSIDIAN:0)
Block(2,55,-2,OBSIDIAN:0)
Block(2,55,-1,OBSIDIAN:0)
Block(2,55,0,OBSIDIAN:0)
Block(2,55,1,OBSIDIAN:0)
Block(2,55,2,STONE:3)
Block(2,55,3,STONE:3)
Block(2,55,4,STONE:3)
Block(2,55,5,STONE:3)
Block(2,55,6,STONE:3)
Block(2,56,-7,OBSIDIAN:0)
Block(2,56,-6,OBSIDIAN:0)
Block(2,56,-5,OBSIDIAN:0)
Block(2,56,-4,OBSIDIAN:0)
Block(2,56,-3,OBSIDIAN:0)
Block(2,56,-2,OBSIDIAN:0)
Block(2,56,-1,OBSIDIAN:0)
Block(2,56,0,OBSIDIAN:0)
Block(2,56,1,STONE:3)
Block(2,56,2,STONE:3)
Block(2,56,3,STONE:3)
Block(2,56,4,STONE:3)
Block(2,56,5,STONE:3)
Block(2,56,6,STONE:3)
Block(2,57,-7,OBSIDIAN:0)
Block(2,57,-6,OBSIDIAN:0)
Block(2,57,-5,OBSIDIAN:0)
Block(2,57,-4,OBSIDIAN:0)
Block(2,57,-3,OBSIDIAN:0)
Block(2,57,-2,OBSIDIAN:0)
Block(2,57,-1,OBSIDIAN:0)
Block(2,57,0,OBSIDIAN:0)
Block(2,57,1,OBSIDIAN:0)
Block(2,57,2,OBSIDIAN:0)
Block(2,57,3,STONE:3)
Block(2,57,4,STONE:3)
Block(2,57,5,STONE:3)
Block(2,57,6,STONE:3)
Block(2,58,-7,OBSIDIAN:0)
Block(2,58,-6,OBSIDIAN:0)
Block(2,58,-5,OBSIDIAN:0)
Block(2,58,-4,OBSIDIAN:0)
Block(2,58,-3,OBSIDIAN:0)
Block(2,58,-2,OBSIDIAN:0)
Block(2,58,-1,OBSIDIAN:0)
Block(2,58,0,OBSIDIAN:0)
Block(2,58,1,OBSIDIAN:0)
Block(2,58,2,OBSIDIAN:0)
Block(2,58,3,OBSIDIAN:0)
Block(2,58,4,STONE:3)
Block(2,58,5,STONE:3)
Block(2,58,6,STONE:3)
Block(2,59,-7,OBSIDIAN:0)
Block(2,59,-6,OBSIDIAN:0)
Block(2,59,-5,OBSIDIAN:0)
Block(2,59,-4,OBSIDIAN:0)
Block(2,59,-3,MAGMA:0)
Block(2,59,-2,MAGMA:0)
Block(2,59,-1,MAGMA:0)
Block(2,59,0,MAGMA:0)
Block(2,59,1,OBSIDIAN:0)
Block(2,59,2,OBSIDIAN:0)
Block(2,59,3,OBSIDIAN:0)
Block(2,59,4,STONE:3)
Block(2,59,5,STONE:3)
Block(2,59,6,STONE:3)
Block(2,60,-7,OBSIDIAN:0)
Block(2,60,-6,OBSIDIAN:0)
Block(2,60,-5,MAGMA:0)
Block(2,60,-4,MAGMA:0)
Block(2,60,-3,MAGMA:0)
Block(2,60,-2,MAGMA:0)
Block(2,60,-1,MAGMA:0)
Block(2,60,0,MAGMA:0)
Block(2,60,1,MAGMA:0)
Block(2,61,-7,OBSIDIAN:0)
Block(2,61,-6,OBSIDIAN:0)
Block(2,61,-5,MAGMA:0)
Block(2,61,-4,MAGMA:0)
Block(2,61,-3,MAGMA:0)
Block(2,61,-2,MAGMA:0)
Block(2,61,-1,MAGMA:0)
Block(2,62,-7,OBSIDIAN:0)
Block(2,62,-6,OBSIDIAN:0)
Block(2,62,-5,MAGMA:0)
Block(2,62,-4,MAGMA:0)
Block(2,62,-3,MAGMA:0)
Block(2,62,-2,MAGMA:0)
Block(2,63,-7,OBSIDIAN:0)
Block(2,63,-6,OBSIDIAN:0)
Block(2,63,-5,OBSIDIAN:0)
Block(2,64,-7,OBSIDIAN:0)
Block(3,22,-7,STONE:3)
Block(3,23,-7,STONE:3)
Block(3,24,-7,STONE:3)
Block(3,25,-7,STONE:3)
Block(3,25,-6,STONE:3)
Block(3,26,-7,STONE:3)
Block(3,26,-6,STONE:3)
Block(3,27,-7,STONE:3)
Block(3,27,-6,STONE:3)
Block(3,27,-5,STONE:3)
Block(3,28,-7,STONE:3)
Block(3,28,-6,STONE:3)
Block(3,28,-5,STONE:3)
Block(3,29,-7,STONE:3)
Block(3,29,-6,STONE:3)
Block(3,29,-5,STONE:3)
Block(3,29,-4,STONE:3)
Block(3,30,-7,STONE:3)
Block(3,30,-6,STONE:3)
Block(3,30,-5,STONE:3)
Block(3,30,-4,STONE:3)
Block(3,31,-7,STONE:3)
Block(3,31,-6,STONE:3)
Block(3,31,-5,STONE:3)
Block(3,31,-4,STONE:3)
Block(3,32,-7,STONE:3)
Block(3,32,-6,STONE:3)
Block(3,32,-5,STONE:3)
Block(3,32,-4,STONE:3)
Block(3,33,-7,STONE:3)
Block(3,33,-6,STONE:3)
Block(3,33,-5,STONE:3)
Block(3,33,-4,STONE:3)
Block(3,33,-3,STONE:3)
Block(3,34,-7,STONE:3)
Block(3,34,-6,STONE:3)
Block(3,34,-5,STONE:3)
Block(3,34,-4,STONE:3)
Block(3,34,-3,STONE:3)
Block(3,35,-7,STONE:3)
Block(3,35,-6,STONE:3)
Block(3,35,-5,STONE:3)
Block(3,35,-4,STONE:3)
Block(3,35,-3,STONE:3)
Block(3,36,-7,STONE:3)
Block(3,36,-6,STONE:3)
Block(3,36,-5,STONE:3)
Block(3,36,-4,STONE:3)
Block(3,36,-3,STONE:3)
Block(3,37,-7,STONE:3)
Block(3,37,-6,STONE:3)
Block(3,37,-5,STONE:3)
Block(3,37,-4,STONE:3)
Block(3,37,-3,STONE:3)
Block(3,38,-7,STONE:3)
Block(3,38,-6,STONE:3)
Block(3,38,-5,STONE:3)
Block(3,38,-4,STONE:3)
Block(3,38,-3,STONE:3)
Block(3,39,-7,STONE:3)
Block(3,39,-6,STONE:3)
Block(3,39,-5,STONE:3)
Block(3,39,-4,STONE:3)
Block(3,39,-3,STONE:3)
Block(3,40,-7,STONE:3)
Block(3,40,-6,STONE:3)
Block(3,40,-5,STONE:3)
Block(3,40,-4,STONE:3)
Block(3,40,-3,STONE:3)
Block(3,40,-2,STONE:3)
Block(3,41,-7,STONE:3)
Block(3,41,-6,STONE:3)
Block(3,41,-5,STONE:3)
Block(3,41,-4,STONE:3)
Block(3,41,-3,STONE:3)
Block(3,41,-2,STONE:3)
Block(3,42,-7,STONE:3)
Block(3,42,-6,STONE:3)
Block(3,42,-5,STONE:3)
Block(3,42,-4,STONE:3)
Block(3,42,-3,STONE:3)
Block(3,42,-2,STONE:3)
Block(3,42,-1,STONE:3)
Block(3,42,0,STONE:3)
Block(3,43,-7,OBSIDIAN:0)
Block(3,43,-6,STONE:3)
Block(3,43,-5,STONE:3)
Block(3,43,-4,STONE:3)
Block(3,43,-3,STONE:3)
Block(3,43,-2,STONE:3)
Block(3,43,-1,STONE:3)
Block(3,43,0,STONE:3)
Block(3,44,-7,OBSIDIAN:0)
Block(3,44,-6,STONE:3)
Block(3,44,-5,STONE:3)
Block(3,44,-4,STONE:3)
Block(3,44,-3,STONE:3)
Block(3,44,-2,STONE:3)
Block(3,44,-1,STONE:3)
Block(3,44,0,STONE:3)
Block(3,44,2,STONE:3)
Block(3,44,3,STONE:3)
Block(3,45,-7,OBSIDIAN:0)
Block(3,45,-6,OBSIDIAN:0)
Block(3,45,-5,STONE:3)
Block(3,45,-4,STONE:3)
Block(3,45,-3,STONE:3)
Block(3,45,-2,STONE:3)
Block(3,45,-1,STONE:3)
Block(3,45,0,STONE:3)
Block(3,45,1,STONE:3)
Block(3,45,2,STONE:3)
Block(3,45,3,STONE:3)
Block(3,45,4,STONE:3)
Block(3,46,-7,OBSIDIAN:0)
Block(3,46,-6,OBSIDIAN:0)
Block(3,46,-5,OBSIDIAN:0)
Block(3,46,-4,OBSIDIAN:0)
Block(3,46,-3,STONE:3)
Block(3,46,-2,STONE:3)
Block(3,46,-1,STONE:3)
Block(3,46,0,STONE:3)
Block(3,46,1,STONE:3)
Block(3,46,2,STONE:3)
Block(3,46,3,STONE:3)
Block(3,46,4,STONE:3)
Block(3,46,5,STONE:3)
Block(3,47,-7,OBSIDIAN:0)
Block(3,47,-6,OBSIDIAN:0)
Block(3,47,-5,OBSIDIAN:0)
Block(3,47,-4,OBSIDIAN:0)
Block(3,47,-3,OBSIDIAN:0)
Block(3,47,-2,OBSIDIAN:0)
Block(3,47,-1,STONE:3)
Block(3,47,0,STONE:3)
Block(3,47,1,STONE:3)
Block(3,47,2,STONE:3)
Block(3,47,3,STONE:3)
Block(3,47,4,STONE:3)
Block(3,47,5,STONE:3)
Block(3,47,6,STONE:3)
Block(3,48,-7,OBSIDIAN:0)
Block(3,48,-6,OBSIDIAN:0)
Block(3,48,-5,OBSIDIAN:0)
Block(3,48,-4,OBSIDIAN:0)
Block(3,48,-3,OBSIDIAN:0)
Block(3,48,-2,OBSIDIAN:0)
Block(3,48,-1,STONE:3)
Block(3,48,0,STONE:3)
Block(3,48,1,STONE:3)
Block(3,48,2,STONE:3)
Block(3,48,3,STONE:3)
Block(3,48,4,STONE:3)
Block(3,48,5,STONE:3)
Block(3,48,6,STONE:3)
Block(3,49,-7,OBSIDIAN:0)
Block(3,49,-6,OBSIDIAN:0)
Block(3,49,-5,OBSIDIAN:0)
Block(3,49,-4,OBSIDIAN:0)
Block(3,49,-3,OBSIDIAN:0)
Block(3,49,-2,OBSIDIAN:0)
Block(3,49,-1,OBSIDIAN:0)
Block(3,49,0,STONE:3)
Block(3,49,1,STONE:3)
Block(3,49,2,STONE:3)
Block(3,49,3,STONE:3)
Block(3,49,4,STONE:3)
Block(3,49,5,STONE:3)
Block(3,49,6,STONE:3)
Block(3,50,-7,OBSIDIAN:0)
Block(3,50,-6,OBSIDIAN:0)
Block(3,50,-5,OBSIDIAN:0)
Block(3,50,-4,OBSIDIAN:0)
Block(3,50,-3,OBSIDIAN:0)
Block(3,50,-2,OBSIDIAN:0)
Block(3,50,-1,OBSIDIAN:0)
Block(3,50,0,OBSIDIAN:0)
Block(3,50,1,OBSIDIAN:0)
Block(3,50,2,STONE:3)
Block(3,50,3,STONE:3)
Block(3,50,4,STONE:3)
Block(3,50,5,STONE:3)
Block(3,50,6,STONE:3)
Block(3,51,-7,OBSIDIAN:0)
Block(3,51,-6,OBSIDIAN:0)
Block(3,51,-5,OBSIDIAN:0)
Block(3,51,-4,OBSIDIAN:0)
Block(3,51,-3,OBSIDIAN:0)
Block(3,51,-2,OBSIDIAN:0)
Block(3,51,-1,OBSIDIAN:0)
Block(3,51,0,OBSIDIAN:0)
Block(3,51,1,OBSIDIAN:0)
Block(3,51,2,STONE:3)
Block(3,51,3,STONE:3)
Block(3,51,4,STONE:3)
Block(3,51,5,STONE:3)
Block(3,51,6,STONE:3)
Block(3,52,-7,OBSIDIAN:0)
Block(3,52,-6,OBSIDIAN:0)
Block(3,52,-5,OBSIDIAN:0)
Block(3,52,-4,OBSIDIAN:0)
Block(3,52,-3,OBSIDIAN:0)
Block(3,52,-2,OBSIDIAN:0)
Block(3,52,-1,OBSIDIAN:0)
Block(3,52,0,OBSIDIAN:0)
Block(3,52,1,OBSIDIAN:0)
Block(3,52,2,STONE:3)
Block(3,52,3,STONE:3)
Block(3,52,4,STONE:3)
Block(3,52,5,STONE:3)
Block(3,52,6,STONE:3)
Block(3,53,-7,OBSIDIAN:0)
Block(3,53,-6,OBSIDIAN:0)
Block(3,53,-5,OBSIDIAN:0)
Block(3,53,-4,OBSIDIAN:0)
Block(3,53,-3,OBSIDIAN:0)
Block(3,53,-2,OBSIDIAN:0)
Block(3,53,-1,OBSIDIAN:0)
Block(3,53,0,OBSIDIAN:0)
Block(3,53,1,OBSIDIAN:0)
Block(3,53,2,STONE:3)
Block(3,53,3,STONE:3)
Block(3,53,4,STONE:3)
Block(3,53,5,STONE:3)
Block(3,53,6,STONE:3)
Block(3,54,-7,OBSIDIAN:0)
Block(3,54,-6,OBSIDIAN:0)
Block(3,54,-5,OBSIDIAN:0)
Block(3,54,-4,OBSIDIAN:0)
Block(3,54,-3,OBSIDIAN:0)
Block(3,54,-2,OBSIDIAN:0)
Block(3,54,-1,OBSIDIAN:0)
Block(3,54,0,OBSIDIAN:0)
Block(3,54,1,OBSIDIAN:0)
Block(3,54,2,STONE:3)
Block(3,54,3,STONE:3)
Block(3,54,4,STONE:3)
Block(3,54,5,STONE:3)
Block(3,54,6,STONE:3)
Block(3,55,-7,OBSIDIAN:0)
Block(3,55,-6,OBSIDIAN:0)
Block(3,55,-5,OBSIDIAN:0)
Block(3,55,-4,OBSIDIAN:0)
Block(3,55,-3,OBSIDIAN:0)
Block(3,55,-2,OBSIDIAN:0)
Block(3,55,-1,OBSIDIAN:0)
Block(3,55,0,OBSIDIAN:0)
Block(3,55,1,OBSIDIAN:0)
Block(3,55,2,STONE:3)
Block(3,55,3,STONE:3)
Block(3,55,4,STONE:3)
Block(3,55,5,STONE:3)
Block(3,55,6,STONE:3)
Block(3,56,-7,OBSIDIAN:0)
Block(3,56,-6,OBSIDIAN:0)
Block(3,56,-5,OBSIDIAN:0)
Block(3,56,-4,OBSIDIAN:0)
