
#######################################################################
# +-----------------------------------------------------------------+ #
# |                            BO4 object                           | #
# +-----------------------------------------------------------------+ #
#######################################################################

Author: NLBlackEagle

Description: No description given

SettingsMode: WriteWithoutComments


#######################################################################
# +-----------------------------------------------------------------+ #
# |                          Main settings                          | #
# +-----------------------------------------------------------------+ #
#######################################################################

Frequency: 0

SpawnHeight: highestBlock

UseCenterForHighestBlock: true

##############################
# Height Limits for the BO4. #
##############################

MinHeight: 0

MaxHeight: 255

InheritBO3: 

InheritBO3Rotation: NORTH

OverrideChildSettings: true

OverrideParentHeight: false

CanOverride: false

BranchFrequency: 0

BranchFrequencyGroup: 

MustBeBelowOther: false

MustBeInside: 

CannotBeInside: 

ReplacesBO3: 

MustBeInsideWorldBorders: false

CanSpawnOnWater: true

SpawnOnWaterOnly: false

SpawnUnderWater: false

SpawnAtWaterLevel: false

HeightOffset: 0

RemoveAir: true

ReplaceAbove: 

ReplaceBelow: 

ReplaceWithBiomeBlocks: true

ReplaceWithSurfaceBlock: GRASS

ReplaceWithGroundBlock: DIRT

ReplaceWithStoneBlock: STONE

SmoothRadius: 0

SmoothHeightOffset: 0

SmoothStartTop: false

SmoothStartWood: false

SmoothingSurfaceBlock: 

SmoothingGroundBlock: 

BO3Group: 

IsSpawnPoint: false

DoReplaceBlocks: true


#######################################################################
# +-----------------------------------------------------------------+ #
# |                              Blocks                             | #
# +-----------------------------------------------------------------+ #
#######################################################################

Block(-8,12,5,OBSIDIAN:0)
Block(-8,12,6,OBSIDIAN:0)
Block(-8,12,7,MAGMA:0)
Block(-8,13,1,STONE:3)
Block(-8,13,2,STONE:3)
Block(-8,13,3,STONE:3)
Block(-8,13,4,STONE:3)
Block(-8,13,5,OBSIDIAN:0)
Block(-8,13,6,OBSIDIAN:0)
Block(-8,13,7,MAGMA:0)
Block(-8,13,8,MAGMA:0)
Block(-8,14,-4,STONE:3)
Block(-8,14,-3,STONE:3)
Block(-8,14,-2,STONE:3)
Block(-8,14,-1,STONE:3)
Block(-8,14,0,STONE:3)
Block(-8,14,1,STONE:3)
Block(-8,14,2,STONE:3)
Block(-8,14,3,STONE:3)
Block(-8,14,4,STONE:3)
Block(-8,14,5,OBSIDIAN:0)
Block(-8,14,6,OBSIDIAN:0)
Block(-8,14,7,MAGMA:0)
Block(-8,14,8,MAGMA:0)
Block(-8,15,-7,STONE:3)
Block(-8,15,-6,STONE:3)
Block(-8,15,-5,STONE:3)
Block(-8,15,-4,STONE:3)
Block(-8,15,-3,STONE:3)
Block(-8,15,-2,STONE:3)
Block(-8,15,-1,STONE:3)
Block(-8,15,0,STONE:3)
Block(-8,15,1,STONE:3)
Block(-8,15,2,STONE:3)
Block(-8,15,3,STONE:3)
Block(-8,15,4,STONE:3)
Block(-8,15,5,OBSIDIAN:0)
Block(-8,15,6,OBSIDIAN:0)
Block(-8,15,7,OBSIDIAN:0)
Block(-8,15,8,MAGMA:0)
Block(-8,16,-7,STONE:3)
Block(-8,16,-6,STONE:3)
Block(-8,16,-5,STONE:3)
Block(-8,16,-4,STONE:3)
Block(-8,16,-3,STONE:3)
Block(-8,16,-2,STONE:3)
Block(-8,16,-1,STONE:3)
Block(-8,16,0,STONE:3)
Block(-8,16,1,STONE:3)
Block(-8,16,2,STONE:3)
Block(-8,16,3,STONE:3)
Block(-8,16,4,STONE:3)
Block(-8,16,5,OBSIDIAN:0)
Block(-8,16,6,OBSIDIAN:0)
Block(-8,16,7,OBSIDIAN:0)
Block(-8,16,8,OBSIDIAN:0)
Block(-8,17,-7,STONE:3)
Block(-8,17,-6,STONE:3)
Block(-8,17,-5,STONE:3)
Block(-8,17,-4,STONE:3)
Block(-8,17,-3,STONE:3)
Block(-8,17,-2,STONE:3)
Block(-8,17,-1,STONE:3)
Block(-8,17,0,STONE:3)
Block(-8,17,1,STONE:3)
Block(-8,17,2,STONE:3)
Block(-8,17,3,STONE:3)
Block(-8,17,4,STONE:3)
Block(-8,17,5,STONE:3)
Block(-8,17,6,OBSIDIAN:0)
Block(-8,17,7,OBSIDIAN:0)
Block(-8,17,8,OBSIDIAN:0)
Block(-8,18,-7,STONE:3)
Block(-8,18,-6,STONE:3)
Block(-8,18,-5,STONE:3)
Block(-8,18,-4,STONE:3)
Block(-8,18,-3,STONE:3)
Block(-8,18,-2,STONE:3)
Block(-8,18,-1,STONE:3)
Block(-8,18,0,STONE:3)
Block(-8,18,1,STONE:3)
Block(-8,18,2,STONE:3)
Block(-8,18,3,STONE:3)
Block(-8,18,4,STONE:3)
Block(-8,18,5,STONE:3)
Block(-8,18,6,OBSIDIAN:0)
Block(-8,18,7,OBSIDIAN:0)
Block(-8,18,8,OBSIDIAN:0)
Block(-8,19,-7,STONE:3)
Block(-8,19,-6,STONE:3)
Block(-8,19,-5,STONE:3)
Block(-8,19,-4,STONE:3)
Block(-8,19,-3,STONE:3)
Block(-8,19,-2,STONE:3)
Block(-8,19,-1,STONE:3)
Block(-8,19,0,STONE:3)
Block(-8,19,1,STONE:3)
Block(-8,19,2,STONE:3)
Block(-8,19,3,STONE:3)
Block(-8,19,4,STONE:3)
Block(-8,19,5,OBSIDIAN:0)
Block(-8,19,6,OBSIDIAN:0)
Block(-8,19,7,OBSIDIAN:0)
Block(-8,19,8,OBSIDIAN:0)
Block(-8,20,-7,STONE:3)
Block(-8,20,-6,STONE:3)
Block(-8,20,-5,STONE:3)
Block(-8,20,-4,STONE:3)
Block(-8,20,-3,OBSIDIAN:0)
Block(-8,20,-2,OBSIDIAN:0)
Block(-8,20,-1,OBSIDIAN:0)
Block(-8,20,0,OBSIDIAN:0)
Block(-8,20,1,OBSIDIAN:0)
Block(-8,20,2,OBSIDIAN:0)
Block(-8,20,3,OBSIDIAN:0)
Block(-8,20,4,OBSIDIAN:0)
Block(-8,20,5,OBSIDIAN:0)
Block(-8,20,6,OBSIDIAN:0)
Block(-8,20,7,OBSIDIAN:0)
Block(-8,20,8,OBSIDIAN:0)
Block(-8,21,-7,STONE:3)
Block(-8,21,-6,STONE:3)
Block(-8,21,-5,STONE:3)
Block(-8,21,-4,OBSIDIAN:0)
Block(-8,21,-3,OBSIDIAN:0)
Block(-8,21,-2,OBSIDIAN:0)
Block(-8,21,-1,OBSIDIAN:0)
Block(-8,21,0,OBSIDIAN:0)
Block(-8,21,1,OBSIDIAN:0)
Block(-8,21,2,OBSIDIAN:0)
Block(-8,21,3,OBSIDIAN:0)
Block(-8,21,4,OBSIDIAN:0)
Block(-8,21,5,OBSIDIAN:0)
Block(-8,21,6,OBSIDIAN:0)
Block(-8,21,7,OBSIDIAN:0)
Block(-8,21,8,OBSIDIAN:0)
Block(-8,22,-7,STONE:3)
Block(-8,22,-6,STONE:3)
Block(-8,22,-5,OBSIDIAN:0)
Block(-8,22,-4,OBSIDIAN:0)
Block(-8,22,-3,OBSIDIAN:0)
Block(-8,22,-2,OBSIDIAN:0)
Block(-8,22,-1,OBSIDIAN:0)
Block(-8,22,0,OBSIDIAN:0)
Block(-8,22,1,OBSIDIAN:0)
Block(-8,22,2,OBSIDIAN:0)
Block(-8,22,3,OBSIDIAN:0)
Block(-8,22,4,OBSIDIAN:0)
Block(-8,22,5,OBSIDIAN:0)
Block(-8,22,6,OBSIDIAN:0)
Block(-8,22,7,OBSIDIAN:0)
Block(-8,22,8,OBSIDIAN:0)
Block(-8,23,-7,STONE:3)
Block(-8,23,-6,OBSIDIAN:0)
Block(-8,23,-5,OBSIDIAN:0)
Block(-8,23,-4,OBSIDIAN:0)
Block(-8,23,-3,OBSIDIAN:0)
Block(-8,23,-2,OBSIDIAN:0)
Block(-8,23,-1,OBSIDIAN:0)
Block(-8,23,0,OBSIDIAN:0)
Block(-8,23,1,OBSIDIAN:0)
Block(-8,23,2,OBSIDIAN:0)
Block(-8,23,3,OBSIDIAN:0)
Block(-8,23,4,OBSIDIAN:0)
Block(-8,23,5,OBSIDIAN:0)
Block(-8,23,6,OBSIDIAN:0)
Block(-8,23,7,OBSIDIAN:0)
Block(-8,23,8,OBSIDIAN:0)
Block(-8,24,-7,OBSIDIAN:0)
Block(-8,24,-6,OBSIDIAN:0)
Block(-8,24,-5,OBSIDIAN:0)
Block(-8,24,-4,OBSIDIAN:0)
Block(-8,24,-3,OBSIDIAN:0)
Block(-8,24,-2,OBSIDIAN:0)
Block(-8,24,-1,OBSIDIAN:0)
Block(-8,24,0,OBSIDIAN:0)
Block(-8,24,1,OBSIDIAN:0)
Block(-8,24,2,OBSIDIAN:0)
Block(-8,24,3,OBSIDIAN:0)
Block(-8,24,4,OBSIDIAN:0)
Block(-8,24,5,OBSIDIAN:0)
Block(-8,24,6,OBSIDIAN:0)
Block(-8,24,7,OBSIDIAN:0)
Block(-8,24,8,OBSIDIAN:0)
Block(-8,25,-7,OBSIDIAN:0)
Block(-8,25,-6,OBSIDIAN:0)
Block(-8,25,-5,OBSIDIAN:0)
Block(-8,25,-4,OBSIDIAN:0)
Block(-8,25,-3,OBSIDIAN:0)
Block(-8,25,-2,OBSIDIAN:0)
Block(-8,25,-1,OBSIDIAN:0)
Block(-8,25,0,OBSIDIAN:0)
Block(-8,25,1,OBSIDIAN:0)
Block(-8,25,2,OBSIDIAN:0)
Block(-8,25,3,OBSIDIAN:0)
Block(-8,25,4,OBSIDIAN:0)
Block(-8,25,5,OBSIDIAN:0)
Block(-8,25,6,OBSIDIAN:0)
Block(-8,25,7,OBSIDIAN:0)
Block(-8,25,8,OBSIDIAN:0)
Block(-8,26,-7,OBSIDIAN:0)
Block(-8,26,-6,OBSIDIAN:0)
Block(-8,26,-5,OBSIDIAN:0)
Block(-8,26,-4,OBSIDIAN:0)
Block(-8,26,-3,OBSIDIAN:0)
Block(-8,26,-2,OBSIDIAN:0)
Block(-8,26,-1,OBSIDIAN:0)
Block(-8,26,0,OBSIDIAN:0)
Block(-8,26,1,OBSIDIAN:0)
Block(-8,26,2,OBSIDIAN:0)
Block(-8,26,3,OBSIDIAN:0)
Block(-8,26,4,OBSIDIAN:0)
Block(-8,26,5,OBSIDIAN:0)
Block(-8,26,6,OBSIDIAN:0)
Block(-8,26,7,OBSIDIAN:0)
Block(-8,26,8,OBSIDIAN:0)
Block(-8,27,-7,OBSIDIAN:0)
Block(-8,27,-6,OBSIDIAN:0)
Block(-8,27,-5,OBSIDIAN:0)
Block(-8,27,-4,OBSIDIAN:0)
Block(-8,27,-3,OBSIDIAN:0)
Block(-8,27,-2,OBSIDIAN:0)
Block(-8,27,-1,OBSIDIAN:0)
Block(-8,27,0,OBSIDIAN:0)
Block(-8,27,1,OBSIDIAN:0)
Block(-8,27,2,OBSIDIAN:0)
Block(-8,27,3,OBSIDIAN:0)
Block(-8,27,4,OBSIDIAN:0)
Block(-8,27,5,OBSIDIAN:0)
Block(-8,27,6,OBSIDIAN:0)
Block(-8,27,7,OBSIDIAN:0)
Block(-8,27,8,OBSIDIAN:0)
Block(-8,28,-7,OBSIDIAN:0)
Block(-8,28,-6,OBSIDIAN:0)
Block(-8,28,-5,OBSIDIAN:0)
Block(-8,28,-4,OBSIDIAN:0)
Block(-8,28,-3,OBSIDIAN:0)
Block(-8,28,-2,OBSIDIAN:0)
Block(-8,28,-1,OBSIDIAN:0)
Block(-8,28,0,OBSIDIAN:0)
Block(-8,28,1,OBSIDIAN:0)
Block(-8,28,2,OBSIDIAN:0)
Block(-8,28,3,OBSIDIAN:0)
Block(-8,28,4,OBSIDIAN:0)
Block(-8,28,5,OBSIDIAN:0)
Block(-8,28,6,OBSIDIAN:0)
Block(-8,28,7,OBSIDIAN:0)
Block(-8,28,8,OBSIDIAN:0)
Block(-8,29,-7,OBSIDIAN:0)
Block(-8,29,-6,OBSIDIAN:0)
Block(-8,29,-5,OBSIDIAN:0)
Block(-8,29,-4,OBSIDIAN:0)
Block(-8,29,-3,OBSIDIAN:0)
Block(-8,29,-2,OBSIDIAN:0)
Block(-8,29,-1,OBSIDIAN:0)
Block(-8,29,0,OBSIDIAN:0)
Block(-8,29,1,OBSIDIAN:0)
Block(-8,29,2,OBSIDIAN:0)
Block(-8,29,3,OBSIDIAN:0)
Block(-8,29,4,OBSIDIAN:0)
Block(-8,29,5,OBSIDIAN:0)
Block(-8,29,6,OBSIDIAN:0)
Block(-8,29,7,OBSIDIAN:0)
Block(-8,29,8,OBSIDIAN:0)
Block(-8,30,-7,OBSIDIAN:0)
Block(-8,30,-6,OBSIDIAN:0)
Block(-8,30,-5,OBSIDIAN:0)
Block(-8,30,-4,OBSIDIAN:0)
Block(-8,30,-3,OBSIDIAN:0)
Block(-8,30,-2,OBSIDIAN:0)
Block(-8,30,-1,OBSIDIAN:0)
Block(-8,30,0,OBSIDIAN:0)
Block(-8,30,1,OBSIDIAN:0)
Block(-8,30,2,OBSIDIAN:0)
Block(-8,30,3,OBSIDIAN:0)
Block(-8,30,4,OBSIDIAN:0)
Block(-8,30,5,OBSIDIAN:0)
Block(-8,30,6,OBSIDIAN:0)
Block(-8,30,7,OBSIDIAN:0)
Block(-8,30,8,OBSIDIAN:0)
Block(-8,31,-7,OBSIDIAN:0)
Block(-8,31,-6,OBSIDIAN:0)
Block(-8,31,-5,OBSIDIAN:0)
Block(-8,31,-4,OBSIDIAN:0)
Block(-8,31,-3,OBSIDIAN:0)
Block(-8,31,-2,OBSIDIAN:0)
Block(-8,31,-1,OBSIDIAN:0)
Block(-8,31,0,OBSIDIAN:0)
Block(-8,31,1,OBSIDIAN:0)
Block(-8,31,2,OBSIDIAN:0)
Block(-8,31,3,OBSIDIAN:0)
Block(-8,31,4,OBSIDIAN:0)
Block(-8,31,5,OBSIDIAN:0)
Block(-8,31,6,OBSIDIAN:0)
Block(-8,31,7,OBSIDIAN:0)
Block(-8,31,8,OBSIDIAN:0)
Block(-8,32,-7,OBSIDIAN:0)
Block(-8,32,-6,OBSIDIAN:0)
Block(-8,32,-5,OBSIDIAN:0)
Block(-8,32,-4,OBSIDIAN:0)
Block(-8,32,-3,OBSIDIAN:0)
Block(-8,32,-2,OBSIDIAN:0)
Block(-8,32,-1,OBSIDIAN:0)
Block(-8,32,0,OBSIDIAN:0)
Block(-8,32,1,OBSIDIAN:0)
Block(-8,32,2,OBSIDIAN:0)
Block(-8,32,3,OBSIDIAN:0)
Block(-8,32,4,OBSIDIAN:0)
Block(-8,32,5,OBSIDIAN:0)
Block(-8,32,6,OBSIDIAN:0)
Block(-8,32,7,OBSIDIAN:0)
Block(-8,32,8,OBSIDIAN:0)
Block(-8,33,-7,OBSIDIAN:0)
Block(-8,33,-6,OBSIDIAN:0)
Block(-8,33,-5,OBSIDIAN:0)
Block(-8,33,-4,OBSIDIAN:0)
Block(-8,33,-3,OBSIDIAN:0)
Block(-8,33,-2,OBSIDIAN:0)
Block(-8,33,-1,OBSIDIAN:0)
Block(-8,33,0,OBSIDIAN:0)
Block(-8,33,1,OBSIDIAN:0)
Block(-8,33,2,OBSIDIAN:0)
Block(-8,33,3,OBSIDIAN:0)
Block(-8,33,4,OBSIDIAN:0)
Block(-8,33,5,OBSIDIAN:0)
Block(-8,33,6,OBSIDIAN:0)
Block(-8,33,7,OBSIDIAN:0)
Block(-8,33,8,OBSIDIAN:0)
Block(-8,34,-7,OBSIDIAN:0)
Block(-8,34,-6,OBSIDIAN:0)
Block(-8,34,-5,OBSIDIAN:0)
Block(-8,34,-4,OBSIDIAN:0)
Block(-8,34,-3,OBSIDIAN:0)
Block(-8,34,-2,OBSIDIAN:0)
Block(-8,34,-1,OBSIDIAN:0)
Block(-8,34,0,OBSIDIAN:0)
Block(-8,34,1,OBSIDIAN:0)
Block(-8,34,2,OBSIDIAN:0)
Block(-8,34,3,OBSIDIAN:0)
Block(-8,34,4,OBSIDIAN:0)
Block(-8,34,5,OBSIDIAN:0)
Block(-8,34,6,STONE:5)
Block(-8,34,7,STONE:5)
Block(-8,34,8,STONE:5)
Block(-8,35,-7,OBSIDIAN:0)
Block(-8,35,-6,OBSIDIAN:0)
Block(-8,35,-5,OBSIDIAN:0)
Block(-8,35,-4,OBSIDIAN:0)
Block(-8,35,-3,OBSIDIAN:0)
Block(-8,35,-2,OBSIDIAN:0)
Block(-8,35,-1,OBSIDIAN:0)
Block(-8,35,0,OBSIDIAN:0)
Block(-8,35,1,OBSIDIAN:0)
Block(-8,35,2,OBSIDIAN:0)
Block(-8,35,3,OBSIDIAN:0)
Block(-8,35,4,OBSIDIAN:0)
Block(-8,35,5,STONE:5)
Block(-8,35,6,STONE:5)
Block(-8,35,7,STONE:5)
Block(-8,36,-7,OBSIDIAN:0)
Block(-8,36,-6,OBSIDIAN:0)
Block(-8,36,-5,OBSIDIAN:0)
Block(-8,36,-4,OBSIDIAN:0)
Block(-8,36,-3,OBSIDIAN:0)
Block(-8,36,-2,OBSIDIAN:0)
Block(-8,36,-1,OBSIDIAN:0)
Block(-8,36,0,OBSIDIAN:0)
Block(-8,36,1,OBSIDIAN:0)
Block(-8,36,2,OBSIDIAN:0)
Block(-8,36,3,STONE:3)
Block(-8,36,4,STONE:3)
Block(-8,36,5,STONE:3)
Block(-8,36,6,STONE:5)
Block(-8,36,7,STONE:5)
Block(-8,37,-7,OBSIDIAN:0)
Block(-8,37,-6,OBSIDIAN:0)
Block(-8,37,-5,OBSIDIAN:0)
Block(-8,37,-4,OBSIDIAN:0)
Block(-8,37,-3,OBSIDIAN:0)
Block(-8,37,-2,OBSIDIAN:0)
Block(-8,37,-1,STONE:5)
Block(-8,37,0,STONE:5)
Block(-8,37,1,STONE:3)
Block(-8,37,2,STONE:3)
Block(-8,37,3,STONE:3)
Block(-8,37,4,STONE:3)
Block(-8,37,5,STONE:3)
Block(-8,37,6,STONE:5)
Block(-8,38,-7,OBSIDIAN:0)
Block(-8,38,-6,OBSIDIAN:0)
Block(-8,38,-5,STONE:5)
Block(-8,38,-4,STONE:5)
Block(-8,38,-3,STONE:5)
Block(-8,38,-2,STONE:3)
Block(-8,38,-1,STONE:3)
Block(-8,38,0,STONE:3)
Block(-8,38,1,STONE:3)
Block(-8,38,2,STONE:3)
Block(-8,38,3,STONE:3)
Block(-8,38,4,STONE:3)
Block(-8,38,5,STONE:3)
Block(-8,39,-7,STONE:5)
Block(-8,39,-6,STONE:5)
Block(-8,39,-5,STONE:5)
Block(-8,39,-4,STONE:5)
Block(-8,39,-3,STONE:5)
Block(-8,39,-2,STONE:3)
Block(-8,39,-1,STONE:3)
Block(-8,39,0,STONE:3)
Block(-8,39,1,STONE:3)
Block(-8,39,2,STONE:3)
Block(-8,39,3,STONE:3)
Block(-8,39,4,STONE:3)
Block(-8,40,-7,STONE:5)
Block(-8,40,-6,STONE:5)
Block(-8,40,-5,STONE:5)
Block(-8,40,-4,STONE:5)
Block(-8,41,-7,STONE:5)
Block(-8,41,-6,STONE:5)
Block(-8,77,-6,OBSIDIAN:0)
Block(-8,77,-5,OBSIDIAN:0)
Block(-8,77,-4,OBSIDIAN:0)
Block(-8,77,-3,OBSIDIAN:0)
Block(-8,77,-2,OBSIDIAN:0)
Block(-8,77,-1,OBSIDIAN:0)
Block(-8,77,5,OBSIDIAN:0)
Block(-8,77,8,OBSIDIAN:0)
Block(-8,78,-7,STONE:3)
Block(-8,78,-6,OBSIDIAN:0)
Block(-8,78,-5,OBSIDIAN:0)
Block(-8,78,-4,OBSIDIAN:0)
Block(-8,78,-3,OBSIDIAN:0)
Block(-8,78,-2,OBSIDIAN:0)
Block(-8,78,-1,OBSIDIAN:0)
Block(-8,78,0,OBSIDIAN:0)
Block(-8,78,1,OBSIDIAN:0)
Block(-8,78,2,OBSIDIAN:0)
Block(-8,78,3,OBSIDIAN:0)
Block(-8,78,4,OBSIDIAN:0)
Block(-8,78,5,OBSIDIAN:0)
Block(-8,78,6,OBSIDIAN:0)
Block(-8,78,7,OBSIDIAN:0)
Block(-8,78,8,OBSIDIAN:0)
Block(-8,79,-7,STONE:3)
Block(-8,79,-6,OBSIDIAN:0)
Block(-8,79,-5,OBSIDIAN:0)
Block(-8,79,-4,OBSIDIAN:0)
Block(-8,79,-3,OBSIDIAN:0)
Block(-8,79,-2,OBSIDIAN:0)
Block(-8,79,-1,OBSIDIAN:0)
Block(-8,79,0,OBSIDIAN:0)
Block(-8,79,1,OBSIDIAN:0)
Block(-8,79,2,OBSIDIAN:0)
Block(-8,79,3,OBSIDIAN:0)
Block(-8,79,4,OBSIDIAN:0)
Block(-8,79,5,OBSIDIAN:0)
Block(-8,79,6,OBSIDIAN:0)
Block(-8,79,7,OBSIDIAN:0)
Block(-8,79,8,OBSIDIAN:0)
Block(-8,80,-7,STONE:3)
Block(-8,80,-6,OBSIDIAN:0)
Block(-8,80,-5,OBSIDIAN:0)
Block(-8,80,-4,OBSIDIAN:0)
Block(-8,80,-3,OBSIDIAN:0)
Block(-8,80,-2,OBSIDIAN:0)
Block(-8,80,-1,OBSIDIAN:0)
Block(-8,80,0,OBSIDIAN:0)
Block(-8,80,1,OBSIDIAN:0)
Block(-8,80,2,OBSIDIAN:0)
Block(-8,80,3,OBSIDIAN:0)
Block(-8,80,4,OBSIDIAN:0)
Block(-8,80,5,OBSIDIAN:0)
Block(-8,80,6,OBSIDIAN:0)
Block(-8,80,7,OBSIDIAN:0)
Block(-8,80,8,OBSIDIAN:0)
Block(-8,81,-7,STONE:3)
Block(-8,81,-6,OBSIDIAN:0)
Block(-8,81,-5,OBSIDIAN:0)
Block(-8,81,-4,OBSIDIAN:0)
Block(-8,81,-3,OBSIDIAN:0)
Block(-8,81,-2,OBSIDIAN:0)
Block(-8,81,-1,OBSIDIAN:0)
Block(-8,81,0,OBSIDIAN:0)
Block(-8,81,1,OBSIDIAN:0)
Block(-8,81,2,OBSIDIAN:0)
Block(-8,81,3,OBSIDIAN:0)
Block(-8,81,4,OBSIDIAN:0)
Block(-8,81,5,OBSIDIAN:0)
Block(-8,81,6,OBSIDIAN:0)
Block(-8,81,7,OBSIDIAN:0)
Block(-8,81,8,OBSIDIAN:0)
Block(-8,82,-7,STONE:3)
Block(-8,82,-6,OBSIDIAN:0)
Block(-8,82,-5,OBSIDIAN:0)
Block(-8,82,-4,OBSIDIAN:0)
Block(-8,82,-3,OBSIDIAN:0)
Block(-8,82,-2,OBSIDIAN:0)
Block(-8,82,-1,OBSIDIAN:0)
Block(-8,82,0,OBSIDIAN:0)
Block(-8,82,1,OBSIDIAN:0)
Block(-8,82,2,OBSIDIAN:0)
Block(-8,82,3,OBSIDIAN:0)
Block(-8,82,4,OBSIDIAN:0)
Block(-8,82,5,OBSIDIAN:0)
Block(-8,82,6,OBSIDIAN:0)
Block(-8,82,7,OBSIDIAN:0)
Block(-8,82,8,OBSIDIAN:0)
Block(-8,83,-7,OBSIDIAN:0)
Block(-8,83,-6,OBSIDIAN:0)
Block(-8,83,-5,OBSIDIAN:0)
Block(-8,83,-4,OBSIDIAN:0)
Block(-8,83,-3,OBSIDIAN:0)
Block(-8,83,-2,OBSIDIAN:0)
Block(-8,83,-1,OBSIDIAN:0)
Block(-8,83,0,OBSIDIAN:0)
Block(-8,83,1,OBSIDIAN:0)
Block(-8,83,2,OBSIDIAN:0)
Block(-8,83,3,OBSIDIAN:0)
Block(-8,83,4,OBSIDIAN:0)
Block(-8,83,5,OBSIDIAN:0)
Block(-8,83,6,OBSIDIAN:0)
Block(-8,83,7,OBSIDIAN:0)
Block(-8,83,8,OBSIDIAN:0)
Block(-8,84,-7,OBSIDIAN:0)
Block(-8,84,-6,OBSIDIAN:0)
Block(-8,84,-5,OBSIDIAN:0)
Block(-8,84,-4,OBSIDIAN:0)
Block(-8,84,-3,OBSIDIAN:0)
Block(-8,84,-2,OBSIDIAN:0)
Block(-8,84,-1,OBSIDIAN:0)
Block(-8,84,0,OBSIDIAN:0)
Block(-8,84,1,OBSIDIAN:0)
Block(-8,84,2,OBSIDIAN:0)
Block(-8,84,3,OBSIDIAN:0)
Block(-8,84,4,OBSIDIAN:0)
Block(-8,84,5,OBSIDIAN:0)
Block(-8,84,6,OBSIDIAN:0)
Block(-8,84,7,OBSIDIAN:0)
Block(-8,84,8,OBSIDIAN:0)
Block(-8,85,-7,OBSIDIAN:0)
Block(-8,85,-6,OBSIDIAN:0)
Block(-8,85,-5,OBSIDIAN:0)
Block(-8,85,-4,OBSIDIAN:0)
Block(-8,85,-3,OBSIDIAN:0)
Block(-8,85,-2,OBSIDIAN:0)
Block(-8,85,-1,OBSIDIAN:0)
Block(-8,85,0,OBSIDIAN:0)
Block(-8,85,1,OBSIDIAN:0)
Block(-8,85,2,OBSIDIAN:0)
Block(-8,85,3,OBSIDIAN:0)
Block(-8,85,4,OBSIDIAN:0)
Block(-8,85,5,OBSIDIAN:0)
Block(-8,85,6,OBSIDIAN:0)
Block(-8,85,7,OBSIDIAN:0)
Block(-8,85,8,OBSIDIAN:0)
Block(-8,86,-7,OBSIDIAN:0)
Block(-8,86,-6,OBSIDIAN:0)
Block(-8,86,-5,OBSIDIAN:0)
Block(-8,86,-4,OBSIDIAN:0)
Block(-8,86,-3,OBSIDIAN:0)
Block(-8,86,-2,OBSIDIAN:0)
Block(-8,86,-1,OBSIDIAN:0)
Block(-8,86,0,OBSIDIAN:0)
Block(-8,86,1,OBSIDIAN:0)
Block(-8,86,2,OBSIDIAN:0)
Block(-8,86,3,OBSIDIAN:0)
Block(-8,86,4,OBSIDIAN:0)
Block(-8,86,5,OBSIDIAN:0)
Block(-8,86,6,OBSIDIAN:0)
Block(-8,86,7,OBSIDIAN:0)
Block(-8,86,8,OBSIDIAN:0)
Block(-8,87,-7,OBSIDIAN:0)
Block(-8,87,-6,OBSIDIAN:0)
Block(-8,87,-5,OBSIDIAN:0)
Block(-8,87,-4,OBSIDIAN:0)
Block(-8,87,-3,OBSIDIAN:0)
Block(-8,87,-2,STONE:3)
Block(-8,87,-1,STONE:3)
Block(-8,87,0,STONE:3)
Block(-8,87,1,STONE:3)
Block(-8,87,2,STONE:3)
Block(-8,87,3,OBSIDIAN:0)
Block(-8,87,4,OBSIDIAN:0)
Block(-8,87,5,OBSIDIAN:0)
Block(-8,87,6,OBSIDIAN:0)
Block(-8,87,7,OBSIDIAN:0)
Block(-8,87,8,OBSIDIAN:0)
Block(-8,88,-7,OBSIDIAN:0)
Block(-8,88,-6,OBSIDIAN:0)
Block(-8,88,-5,OBSIDIAN:0)
Block(-8,88,-4,OBSIDIAN:0)
Block(-8,88,-3,STONE:3)
Block(-8,88,-2,STONE:5)
Block(-8,88,-1,STONE:5)
Block(-8,88,0,STONE:5)
Block(-8,88,1,STONE:5)
Block(-8,88,2,STONE:5)
Block(-8,88,3,STONE:3)
Block(-8,88,4,STONE:3)
Block(-8,88,5,STONE:3)
Block(-8,88,6,STONE:3)
Block(-8,88,7,STONE:3)
Block(-8,88,8,STONE:3)
Block(-8,89,-7,OBSIDIAN:0)
Block(-8,89,-6,OBSIDIAN:0)
Block(-8,89,-5,STONE:3)
Block(-8,89,-4,STONE:3)
Block(-8,89,-3,STONE:5)
Block(-8,89,3,STONE:5)
Block(-8,89,4,STONE:5)
Block(-8,89,5,STONE:5)
Block(-8,89,6,STONE:5)
Block(-8,89,7,STONE:5)
Block(-8,89,8,STONE:5)
Block(-8,90,-7,OBSIDIAN:0)
Block(-8,90,-6,STONE:3)
Block(-8,90,-5,STONE:5)
Block(-8,90,-4,STONE:5)
Block(-8,91,-7,STONE:3)
Block(-8,91,-6,STONE:5)
Block(-8,92,-7,STONE:5)
Block(-7,12,6,OBSIDIAN:0)
Block(-7,13,3,STONE:3)
Block(-7,13,4,STONE:3)
Block(-7,13,5,OBSIDIAN:0)
Block(-7,13,6,OBSIDIAN:0)
Block(-7,13,7,MAGMA:0)
Block(-7,13,8,MAGMA:0)
Block(-7,14,-3,STONE:3)
Block(-7,14,-2,STONE:3)
Block(-7,14,-1,STONE:3)
Block(-7,14,0,STONE:3)
Block(-7,14,1,STONE:3)
Block(-7,14,2,STONE:3)
Block(-7,14,3,STONE:3)
Block(-7,14,4,STONE:3)
Block(-7,14,5,OBSIDIAN:0)
Block(-7,14,6,OBSIDIAN:0)
Block(-7,14,7,MAGMA:0)
Block(-7,14,8,MAGMA:0)
Block(-7,15,-7,STONE:3)
Block(-7,15,-6,STONE:3)
Block(-7,15,-5,STONE:3)
Block(-7,15,-4,STONE:3)
Block(-7,15,-3,STONE:3)
Block(-7,15,-2,STONE:3)
Block(-7,15,-1,STONE:3)
Block(-7,15,0,STONE:3)
Block(-7,15,1,STONE:3)
Block(-7,15,2,STONE:3)
Block(-7,15,3,STONE:3)
Block(-7,15,4,STONE:3)
Block(-7,15,5,OBSIDIAN:0)
Block(-7,15,6,OBSIDIAN:0)
Block(-7,15,7,MAGMA:0)
Block(-7,15,8,MAGMA:0)
Block(-7,16,-7,STONE:3)
Block(-7,16,-6,STONE:3)
Block(-7,16,-5,STONE:3)
Block(-7,16,-4,STONE:3)
Block(-7,16,-3,STONE:3)
Block(-7,16,-2,STONE:3)
Block(-7,16,-1,STONE:3)
Block(-7,16,0,STONE:3)
Block(-7,16,1,STONE:3)
Block(-7,16,2,STONE:3)
Block(-7,16,3,STONE:3)
Block(-7,16,4,STONE:3)
Block(-7,16,5,OBSIDIAN:0)
Block(-7,16,6,OBSIDIAN:0)
Block(-7,16,7,OBSIDIAN:0)
Block(-7,16,8,MAGMA:0)
Block(-7,17,-7,STONE:3)
Block(-7,17,-6,STONE:3)
Block(-7,17,-5,STONE:3)
Block(-7,17,-4,STONE:3)
Block(-7,17,-3,STONE:3)
Block(-7,17,-2,STONE:3)
Block(-7,17,-1,STONE:3)
Block(-7,17,0,STONE:3)
Block(-7,17,1,STONE:3)
Block(-7,17,2,STONE:3)
Block(-7,17,3,STONE:3)
Block(-7,17,4,STONE:3)
Block(-7,17,5,STONE:3)
Block(-7,17,6,OBSIDIAN:0)
Block(-7,17,7,OBSIDIAN:0)
Block(-7,17,8,OBSIDIAN:0)
Block(-7,18,-7,STONE:3)
Block(-7,18,-6,STONE:3)
Block(-7,18,-5,STONE:3)
Block(-7,18,-4,STONE:3)
Block(-7,18,-3,STONE:3)
Block(-7,18,-2,STONE:3)
Block(-7,18,-1,STONE:3)
Block(-7,18,0,STONE:3)
Block(-7,18,1,STONE:3)
Block(-7,18,2,STONE:3)
Block(-7,18,3,STONE:3)
Block(-7,18,4,STONE:3)
Block(-7,18,5,STONE:3)
Block(-7,18,6,OBSIDIAN:0)
Block(-7,18,7,OBSIDIAN:0)
Block(-7,18,8,OBSIDIAN:0)
Block(-7,19,-7,STONE:3)
Block(-7,19,-6,STONE:3)
Block(-7,19,-5,STONE:3)
Block(-7,19,-4,STONE:3)
Block(-7,19,-3,STONE:3)
Block(-7,19,-2,STONE:3)
Block(-7,19,-1,STONE:3)
Block(-7,19,0,STONE:3)
Block(-7,19,1,STONE:3)
Block(-7,19,2,STONE:3)
Block(-7,19,3,STONE:3)
Block(-7,19,4,STONE:3)
Block(-7,19,5,OBSIDIAN:0)
Block(-7,19,6,OBSIDIAN:0)
Block(-7,19,7,OBSIDIAN:0)
Block(-7,19,8,OBSIDIAN:0)
Block(-7,20,-7,STONE:3)
Block(-7,20,-6,STONE:3)
Block(-7,20,-5,STONE:3)
Block(-7,20,-4,STONE:3)
Block(-7,20,-3,OBSIDIAN:0)
Block(-7,20,-2,OBSIDIAN:0)
Block(-7,20,-1,OBSIDIAN:0)
Block(-7,20,0,OBSIDIAN:0)
Block(-7,20,1,OBSIDIAN:0)
Block(-7,20,2,OBSIDIAN:0)
Block(-7,20,3,OBSIDIAN:0)
Block(-7,20,4,OBSIDIAN:0)
Block(-7,20,5,OBSIDIAN:0)
Block(-7,20,6,OBSIDIAN:0)
Block(-7,20,7,OBSIDIAN:0)
Block(-7,20,8,OBSIDIAN:0)
Block(-7,21,-7,STONE:3)
Block(-7,21,-6,STONE:3)
Block(-7,21,-5,STONE:3)
Block(-7,21,-4,OBSIDIAN:0)
Block(-7,21,-3,OBSIDIAN:0)
Block(-7,21,-2,OBSIDIAN:0)
Block(-7,21,-1,OBSIDIAN:0)
Block(-7,21,0,OBSIDIAN:0)
Block(-7,21,1,OBSIDIAN:0)
Block(-7,21,2,OBSIDIAN:0)
Block(-7,21,3,OBSIDIAN:0)
Block(-7,21,4,OBSIDIAN:0)
Block(-7,21,5,OBSIDIAN:0)
Block(-7,21,6,OBSIDIAN:0)
Block(-7,21,7,OBSIDIAN:0)
Block(-7,21,8,OBSIDIAN:0)
Block(-7,22,-7,STONE:3)
Block(-7,22,-6,STONE:3)
Block(-7,22,-5,OBSIDIAN:0)
Block(-7,22,-4,OBSIDIAN:0)
Block(-7,22,-3,OBSIDIAN:0)
Block(-7,22,-2,OBSIDIAN:0)
Block(-7,22,-1,OBSIDIAN:0)
Block(-7,22,0,OBSIDIAN:0)
Block(-7,22,1,OBSIDIAN:0)
Block(-7,22,2,OBSIDIAN:0)
Block(-7,22,3,OBSIDIAN:0)
Block(-7,22,4,OBSIDIAN:0)
Block(-7,22,5,OBSIDIAN:0)
Block(-7,22,6,OBSIDIAN:0)
Block(-7,22,7,OBSIDIAN:0)
Block(-7,22,8,OBSIDIAN:0)
Block(-7,23,-7,STONE:3)
Block(-7,23,-6,OBSIDIAN:0)
Block(-7,23,-5,OBSIDIAN:0)
Block(-7,23,-4,OBSIDIAN:0)
Block(-7,23,-3,OBSIDIAN:0)
Block(-7,23,-2,OBSIDIAN:0)
Block(-7,23,-1,OBSIDIAN:0)
Block(-7,23,0,OBSIDIAN:0)
Block(-7,23,1,OBSIDIAN:0)
Block(-7,23,2,OBSIDIAN:0)
Block(-7,23,3,OBSIDIAN:0)
Block(-7,23,4,OBSIDIAN:0)
Block(-7,23,5,OBSIDIAN:0)
Block(-7,23,6,OBSIDIAN:0)
Block(-7,23,7,OBSIDIAN:0)
Block(-7,23,8,OBSIDIAN:0)
Block(-7,24,-7,OBSIDIAN:0)
Block(-7,24,-6,OBSIDIAN:0)
Block(-7,24,-5,OBSIDIAN:0)
Block(-7,24,-4,OBSIDIAN:0)
Block(-7,24,-3,OBSIDIAN:0)
Block(-7,24,-2,OBSIDIAN:0)
Block(-7,24,-1,OBSIDIAN:0)
Block(-7,24,0,OBSIDIAN:0)
Block(-7,24,1,OBSIDIAN:0)
Block(-7,24,2,OBSIDIAN:0)
Block(-7,24,3,OBSIDIAN:0)
Block(-7,24,4,OBSIDIAN:0)
Block(-7,24,5,OBSIDIAN:0)
Block(-7,24,6,OBSIDIAN:0)
Block(-7,24,7,OBSIDIAN:0)
Block(-7,24,8,OBSIDIAN:0)
Block(-7,25,-7,OBSIDIAN:0)
Block(-7,25,-6,OBSIDIAN:0)
Block(-7,25,-5,OBSIDIAN:0)
Block(-7,25,-4,OBSIDIAN:0)
Block(-7,25,-3,OBSIDIAN:0)
Block(-7,25,-2,OBSIDIAN:0)
Block(-7,25,-1,OBSIDIAN:0)
Block(-7,25,0,OBSIDIAN:0)
Block(-7,25,1,OBSIDIAN:0)
Block(-7,25,2,OBSIDIAN:0)
Block(-7,25,3,OBSIDIAN:0)
Block(-7,25,4,OBSIDIAN:0)
Block(-7,25,5,OBSIDIAN:0)
Block(-7,25,6,OBSIDIAN:0)
Block(-7,25,7,OBSIDIAN:0)
Block(-7,25,8,OBSIDIAN:0)
Block(-7,26,-7,OBSIDIAN:0)
Block(-7,26,-6,OBSIDIAN:0)
Block(-7,26,-5,OBSIDIAN:0)
Block(-7,26,-4,OBSIDIAN:0)
Block(-7,26,-3,OBSIDIAN:0)
Block(-7,26,-2,OBSIDIAN:0)
Block(-7,26,-1,OBSIDIAN:0)
Block(-7,26,0,OBSIDIAN:0)
Block(-7,26,1,OBSIDIAN:0)
Block(-7,26,2,OBSIDIAN:0)
Block(-7,26,3,OBSIDIAN:0)
Block(-7,26,4,OBSIDIAN:0)
Block(-7,26,5,OBSIDIAN:0)
Block(-7,26,6,OBSIDIAN:0)
Block(-7,26,7,OBSIDIAN:0)
Block(-7,26,8,OBSIDIAN:0)
Block(-7,27,-7,OBSIDIAN:0)
Block(-7,27,-6,OBSIDIAN:0)
Block(-7,27,-5,OBSIDIAN:0)
Block(-7,27,-4,OBSIDIAN:0)
Block(-7,27,-3,OBSIDIAN:0)
Block(-7,27,-2,OBSIDIAN:0)
Block(-7,27,-1,OBSIDIAN:0)
Block(-7,27,0,OBSIDIAN:0)
Block(-7,27,1,OBSIDIAN:0)
Block(-7,27,2,OBSIDIAN:0)
Block(-7,27,3,OBSIDIAN:0)
Block(-7,27,4,OBSIDIAN:0)
Block(-7,27,5,OBSIDIAN:0)
Block(-7,27,6,OBSIDIAN:0)
Block(-7,27,7,OBSIDIAN:0)
Block(-7,27,8,OBSIDIAN:0)
Block(-7,28,-7,OBSIDIAN:0)
Block(-7,28,-6,OBSIDIAN:0)
Block(-7,28,-5,OBSIDIAN:0)
Block(-7,28,-4,OBSIDIAN:0)
Block(-7,28,-3,OBSIDIAN:0)
Block(-7,28,-2,OBSIDIAN:0)
Block(-7,28,-1,OBSIDIAN:0)
Block(-7,28,0,OBSIDIAN:0)
Block(-7,28,1,OBSIDIAN:0)
Block(-7,28,2,OBSIDIAN:0)
Block(-7,28,3,OBSIDIAN:0)
Block(-7,28,4,OBSIDIAN:0)
Block(-7,28,5,OBSIDIAN:0)
Block(-7,28,6,OBSIDIAN:0)
Block(-7,28,7,OBSIDIAN:0)
Block(-7,28,8,OBSIDIAN:0)
Block(-7,29,-7,OBSIDIAN:0)
Block(-7,29,-6,OBSIDIAN:0)
Block(-7,29,-5,OBSIDIAN:0)
Block(-7,29,-4,OBSIDIAN:0)
Block(-7,29,-3,OBSIDIAN:0)
Block(-7,29,-2,OBSIDIAN:0)
Block(-7,29,-1,OBSIDIAN:0)
Block(-7,29,0,OBSIDIAN:0)
Block(-7,29,1,OBSIDIAN:0)
Block(-7,29,2,OBSIDIAN:0)
Block(-7,29,3,OBSIDIAN:0)
Block(-7,29,4,OBSIDIAN:0)
Block(-7,29,5,OBSIDIAN:0)
Block(-7,29,6,OBSIDIAN:0)
Block(-7,29,7,OBSIDIAN:0)
Block(-7,29,8,OBSIDIAN:0)
Block(-7,30,-7,OBSIDIAN:0)
Block(-7,30,-6,OBSIDIAN:0)
Block(-7,30,-5,OBSIDIAN:0)
Block(-7,30,-4,OBSIDIAN:0)
Block(-7,30,-3,OBSIDIAN:0)
Block(-7,30,-2,OBSIDIAN:0)
Block(-7,30,-1,OBSIDIAN:0)
Block(-7,30,0,OBSIDIAN:0)
Block(-7,30,1,OBSIDIAN:0)
Block(-7,30,2,OBSIDIAN:0)
Block(-7,30,3,OBSIDIAN:0)
Block(-7,30,4,OBSIDIAN:0)
Block(-7,30,5,OBSIDIAN:0)
Block(-7,30,6,OBSIDIAN:0)
Block(-7,30,7,OBSIDIAN:0)
Block(-7,30,8,OBSIDIAN:0)
Block(-7,31,-7,OBSIDIAN:0)
Block(-7,31,-6,OBSIDIAN:0)
Block(-7,31,-5,OBSIDIAN:0)
Block(-7,31,-4,OBSIDIAN:0)
Block(-7,31,-3,OBSIDIAN:0)
Block(-7,31,-2,OBSIDIAN:0)
Block(-7,31,-1,OBSIDIAN:0)
Block(-7,31,0,OBSIDIAN:0)
Block(-7,31,1,OBSIDIAN:0)
Block(-7,31,2,OBSIDIAN:0)
Block(-7,31,3,OBSIDIAN:0)
Block(-7,31,4,OBSIDIAN:0)
Block(-7,31,5,OBSIDIAN:0)
Block(-7,31,6,OBSIDIAN:0)
Block(-7,31,7,OBSIDIAN:0)
Block(-7,31,8,OBSIDIAN:0)
Block(-7,32,-7,OBSIDIAN:0)
Block(-7,32,-6,OBSIDIAN:0)
Block(-7,32,-5,OBSIDIAN:0)
Block(-7,32,-4,OBSIDIAN:0)
Block(-7,32,-3,OBSIDIAN:0)
Block(-7,32,-2,OBSIDIAN:0)
Block(-7,32,-1,OBSIDIAN:0)
Block(-7,32,0,OBSIDIAN:0)
Block(-7,32,1,OBSIDIAN:0)
Block(-7,32,2,OBSIDIAN:0)
Block(-7,32,3,OBSIDIAN:0)
Block(-7,32,4,OBSIDIAN:0)
Block(-7,32,5,OBSIDIAN:0)
Block(-7,32,6,OBSIDIAN:0)
Block(-7,32,7,OBSIDIAN:0)
Block(-7,32,8,OBSIDIAN:0)
Block(-7,33,-7,OBSIDIAN:0)
Block(-7,33,-6,OBSIDIAN:0)
Block(-7,33,-5,OBSIDIAN:0)
Block(-7,33,-4,OBSIDIAN:0)
Block(-7,33,-3,OBSIDIAN:0)
Block(-7,33,-2,OBSIDIAN:0)
Block(-7,33,-1,OBSIDIAN:0)
Block(-7,33,0,OBSIDIAN:0)
Block(-7,33,1,OBSIDIAN:0)
Block(-7,33,2,OBSIDIAN:0)
Block(-7,33,3,OBSIDIAN:0)
Block(-7,33,4,OBSIDIAN:0)
Block(-7,33,5,OBSIDIAN:0)
Block(-7,33,6,OBSIDIAN:0)
Block(-7,33,7,OBSIDIAN:0)
Block(-7,33,8,OBSIDIAN:0)
Block(-7,34,-7,OBSIDIAN:0)
Block(-7,34,-6,OBSIDIAN:0)
Block(-7,34,-5,OBSIDIAN:0)
Block(-7,34,-4,OBSIDIAN:0)
Block(-7,34,-3,OBSIDIAN:0)
Block(-7,34,-2,OBSIDIAN:0)
Block(-7,34,-1,OBSIDIAN:0)
Block(-7,34,0,OBSIDIAN:0)
Block(-7,34,1,OBSIDIAN:0)
Block(-7,34,2,OBSIDIAN:0)
Block(-7,34,3,OBSIDIAN:0)
Block(-7,34,4,OBSIDIAN:0)
Block(-7,34,5,OBSIDIAN:0)
Block(-7,34,6,STONE:5)
Block(-7,34,7,STONE:5)
Block(-7,34,8,STONE:5)
Block(-7,35,-7,OBSIDIAN:0)
Block(-7,35,-6,OBSIDIAN:0)
Block(-7,35,-5,OBSIDIAN:0)
Block(-7,35,-4,OBSIDIAN:0)
Block(-7,35,-3,OBSIDIAN:0)
Block(-7,35,-2,OBSIDIAN:0)
Block(-7,35,-1,OBSIDIAN:0)
Block(-7,35,0,OBSIDIAN:0)
Block(-7,35,1,OBSIDIAN:0)
Block(-7,35,2,OBSIDIAN:0)
Block(-7,35,3,OBSIDIAN:0)
Block(-7,35,4,OBSIDIAN:0)
Block(-7,35,5,STONE:5)
Block(-7,35,6,STONE:5)
Block(-7,35,7,STONE:5)
Block(-7,35,8,STONE:5)
Block(-7,36,-7,OBSIDIAN:0)
Block(-7,36,-6,OBSIDIAN:0)
Block(-7,36,-5,OBSIDIAN:0)
Block(-7,36,-4,OBSIDIAN:0)
Block(-7,36,-3,OBSIDIAN:0)
Block(-7,36,-2,OBSIDIAN:0)
Block(-7,36,-1,OBSIDIAN:0)
Block(-7,36,0,OBSIDIAN:0)
Block(-7,36,1,OBSIDIAN:0)
Block(-7,36,2,OBSIDIAN:0)
Block(-7,36,3,OBSIDIAN:0)
Block(-7,36,4,STONE:5)
Block(-7,36,5,STONE:5)
Block(-7,36,6,STONE:5)
Block(-7,36,7,STONE:5)
Block(-7,36,8,STONE:5)
Block(-7,37,-7,OBSIDIAN:0)
Block(-7,37,-6,OBSIDIAN:0)
Block(-7,37,-5,OBSIDIAN:0)
Block(-7,37,-4,OBSIDIAN:0)
Block(-7,37,-3,OBSIDIAN:0)
Block(-7,37,-2,OBSIDIAN:0)
Block(-7,37,-1,STONE:5)
Block(-7,37,0,STONE:5)
Block(-7,37,1,STONE:3)
Block(-7,37,2,STONE:3)
Block(-7,37,3,STONE:3)
Block(-7,37,4,STONE:5)
Block(-7,37,5,STONE:5)
Block(-7,37,6,STONE:5)
Block(-7,37,7,STONE:5)
Block(-7,38,-7,OBSIDIAN:0)
Block(-7,38,-6,OBSIDIAN:0)
Block(-7,38,-5,OBSIDIAN:0)
Block(-7,38,-4,OBSIDIAN:0)
Block(-7,38,-3,OBSIDIAN:0)
Block(-7,38,-2,STONE:5)
Block(-7,38,-1,STONE:5)
Block(-7,38,0,STONE:3)
Block(-7,38,1,STONE:3)
Block(-7,38,2,STONE:3)
Block(-7,38,3,STONE:3)
Block(-7,38,4,STONE:3)
Block(-7,38,5,STONE:5)
Block(-7,38,6,STONE:5)
Block(-7,38,7,STONE:5)
Block(-7,39,-7,STONE:5)
Block(-7,39,-6,STONE:5)
Block(-7,39,-5,STONE:5)
Block(-7,39,-4,STONE:5)
Block(-7,39,-3,STONE:5)
Block(-7,39,-2,STONE:5)
Block(-7,39,-1,STONE:5)
Block(-7,39,0,STONE:3)
Block(-7,39,1,STONE:3)
Block(-7,39,2,STONE:3)
Block(-7,39,3,STONE:3)
Block(-7,39,4,STONE:3)
Block(-7,39,5,STONE:5)
Block(-7,40,-7,STONE:5)
Block(-7,40,-6,STONE:5)
Block(-7,40,-5,STONE:5)
Block(-7,40,-4,STONE:5)
Block(-7,41,-7,STONE:5)
Block(-7,41,-6,STONE:5)
Block(-7,41,-5,STONE:5)
Block(-7,77,-4,OBSIDIAN:0)
Block(-7,77,-3,OBSIDIAN:0)
Block(-7,77,-2,OBSIDIAN:0)
Block(-7,77,3,OBSIDIAN:0)
Block(-7,77,4,OBSIDIAN:0)
Block(-7,77,5,OBSIDIAN:0)
Block(-7,77,6,OBSIDIAN:0)
Block(-7,77,7,OBSIDIAN:0)
Block(-7,77,8,OBSIDIAN:0)
Block(-7,78,-6,OBSIDIAN:0)
Block(-7,78,-5,OBSIDIAN:0)
Block(-7,78,-4,OBSIDIAN:0)
Block(-7,78,-3,OBSIDIAN:0)
Block(-7,78,-2,OBSIDIAN:0)
Block(-7,78,-1,OBSIDIAN:0)
Block(-7,78,0,OBSIDIAN:0)
Block(-7,78,1,OBSIDIAN:0)
Block(-7,78,2,OBSIDIAN:0)
Block(-7,78,3,OBSIDIAN:0)
Block(-7,78,4,OBSIDIAN:0)
Block(-7,78,5,OBSIDIAN:0)
Block(-7,78,6,OBSIDIAN:0)
Block(-7,78,7,OBSIDIAN:0)
Block(-7,78,8,OBSIDIAN:0)
Block(-7,79,-7,OBSIDIAN:0)
Block(-7,79,-6,OBSIDIAN:0)
Block(-7,79,-5,OBSIDIAN:0)
Block(-7,79,-4,OBSIDIAN:0)
Block(-7,79,-3,OBSIDIAN:0)
Block(-7,79,-2,OBSIDIAN:0)
Block(-7,79,-1,OBSIDIAN:0)
Block(-7,79,0,OBSIDIAN:0)
Block(-7,79,1,OBSIDIAN:0)
Block(-7,79,2,OBSIDIAN:0)
Block(-7,79,3,OBSIDIAN:0)
Block(-7,79,4,OBSIDIAN:0)
Block(-7,79,5,OBSIDIAN:0)
Block(-7,79,6,OBSIDIAN:0)
Block(-7,79,7,OBSIDIAN:0)
Block(-7,79,8,OBSIDIAN:0)
Block(-7,80,-7,OBSIDIAN:0)
Block(-7,80,-6,OBSIDIAN:0)
Block(-7,80,-5,OBSIDIAN:0)
Block(-7,80,-4,OBSIDIAN:0)
Block(-7,80,-3,OBSIDIAN:0)
Block(-7,80,-2,OBSIDIAN:0)
Block(-7,80,-1,OBSIDIAN:0)
Block(-7,80,0,OBSIDIAN:0)
Block(-7,80,1,OBSIDIAN:0)
Block(-7,80,2,OBSIDIAN:0)
Block(-7,80,3,OBSIDIAN:0)
Block(-7,80,4,OBSIDIAN:0)
Block(-7,80,5,OBSIDIAN:0)
Block(-7,80,6,OBSIDIAN:0)
Block(-7,80,7,OBSIDIAN:0)
Block(-7,80,8,OBSIDIAN:0)
Block(-7,81,-7,OBSIDIAN:0)
Block(-7,81,-6,OBSIDIAN:0)
Block(-7,81,-5,OBSIDIAN:0)
Block(-7,81,-4,OBSIDIAN:0)
Block(-7,81,-3,OBSIDIAN:0)
Block(-7,81,-2,OBSIDIAN:0)
Block(-7,81,-1,OBSIDIAN:0)
Block(-7,81,0,OBSIDIAN:0)
Block(-7,81,1,OBSIDIAN:0)
Block(-7,81,2,OBSIDIAN:0)
Block(-7,81,3,OBSIDIAN:0)
Block(-7,81,4,OBSIDIAN:0)
Block(-7,81,5,OBSIDIAN:0)
Block(-7,81,6,OBSIDIAN:0)
Block(-7,81,7,OBSIDIAN:0)
Block(-7,81,8,OBSIDIAN:0)
Block(-7,82,-7,OBSIDIAN:0)
Block(-7,82,-6,OBSIDIAN:0)
Block(-7,82,-5,OBSIDIAN:0)
Block(-7,82,-4,OBSIDIAN:0)
Block(-7,82,-3,OBSIDIAN:0)
Block(-7,82,-2,OBSIDIAN:0)
Block(-7,82,-1,OBSIDIAN:0)
Block(-7,82,0,OBSIDIAN:0)
Block(-7,82,1,OBSIDIAN:0)
Block(-7,82,2,OBSIDIAN:0)
Block(-7,82,3,OBSIDIAN:0)
Block(-7,82,4,OBSIDIAN:0)
Block(-7,82,5,OBSIDIAN:0)
Block(-7,82,6,OBSIDIAN:0)
Block(-7,82,7,OBSIDIAN:0)
Block(-7,82,8,OBSIDIAN:0)
Block(-7,83,-7,OBSIDIAN:0)
Block(-7,83,-6,OBSIDIAN:0)
Block(-7,83,-5,OBSIDIAN:0)
Block(-7,83,-4,OBSIDIAN:0)
Block(-7,83,-3,OBSIDIAN:0)
Block(-7,83,-2,OBSIDIAN:0)
Block(-7,83,-1,OBSIDIAN:0)
Block(-7,83,0,OBSIDIAN:0)
Block(-7,83,1,OBSIDIAN:0)
Block(-7,83,2,OBSIDIAN:0)
Block(-7,83,3,OBSIDIAN:0)
Block(-7,83,4,OBSIDIAN:0)
Block(-7,83,5,OBSIDIAN:0)
Block(-7,83,6,OBSIDIAN:0)
Block(-7,83,7,OBSIDIAN:0)
Block(-7,83,8,OBSIDIAN:0)
Block(-7,84,-7,OBSIDIAN:0)
Block(-7,84,-6,OBSIDIAN:0)
Block(-7,84,-5,OBSIDIAN:0)
Block(-7,84,-4,OBSIDIAN:0)
Block(-7,84,-3,OBSIDIAN:0)
Block(-7,84,-2,OBSIDIAN:0)
Block(-7,84,-1,OBSIDIAN:0)
Block(-7,84,0,OBSIDIAN:0)
Block(-7,84,1,OBSIDIAN:0)
Block(-7,84,2,OBSIDIAN:0)
Block(-7,84,3,OBSIDIAN:0)
Block(-7,84,4,OBSIDIAN:0)
Block(-7,84,5,OBSIDIAN:0)
Block(-7,84,6,OBSIDIAN:0)
Block(-7,84,7,OBSIDIAN:0)
Block(-7,84,8,OBSIDIAN:0)
Block(-7,85,-7,OBSIDIAN:0)
Block(-7,85,-6,OBSIDIAN:0)
Block(-7,85,-5,OBSIDIAN:0)
Block(-7,85,-4,OBSIDIAN:0)
Block(-7,85,-3,OBSIDIAN:0)
Block(-7,85,-2,OBSIDIAN:0)
Block(-7,85,-1,OBSIDIAN:0)
Block(-7,85,0,OBSIDIAN:0)
Block(-7,85,1,OBSIDIAN:0)
Block(-7,85,2,OBSIDIAN:0)
Block(-7,85,3,OBSIDIAN:0)
Block(-7,85,4,OBSIDIAN:0)
Block(-7,85,5,OBSIDIAN:0)
Block(-7,85,6,OBSIDIAN:0)
Block(-7,85,7,OBSIDIAN:0)
Block(-7,85,8,OBSIDIAN:0)
Block(-7,86,-7,OBSIDIAN:0)
Block(-7,86,-6,OBSIDIAN:0)
Block(-7,86,-5,OBSIDIAN:0)
Block(-7,86,-4,OBSIDIAN:0)
Block(-7,86,-3,OBSIDIAN:0)
Block(-7,86,-2,OBSIDIAN:0)
Block(-7,86,-1,OBSIDIAN:0)
Block(-7,86,0,OBSIDIAN:0)
Block(-7,86,1,OBSIDIAN:0)
Block(-7,86,2,OBSIDIAN:0)
Block(-7,86,3,OBSIDIAN:0)
Block(-7,86,4,OBSIDIAN:0)
Block(-7,86,5,OBSIDIAN:0)
Block(-7,86,6,OBSIDIAN:0)
Block(-7,86,7,OBSIDIAN:0)
Block(-7,86,8,OBSIDIAN:0)
Block(-7,87,-7,OBSIDIAN:0)
Block(-7,87,-6,OBSIDIAN:0)
Block(-7,87,-5,OBSIDIAN:0)
Block(-7,87,-4,OBSIDIAN:0)
Block(-7,87,-3,OBSIDIAN:0)
Block(-7,87,-2,OBSIDIAN:0)
Block(-7,87,-1,OBSIDIAN:0)
Block(-7,87,0,STONE:3)
Block(-7,87,1,STONE:3)
Block(-7,87,2,STONE:3)
Block(-7,87,3,OBSIDIAN:0)
Block(-7,87,4,OBSIDIAN:0)
Block(-7,87,5,OBSIDIAN:0)
Block(-7,87,6,OBSIDIAN:0)
Block(-7,87,7,OBSIDIAN:0)
Block(-7,87,8,OBSIDIAN:0)
Block(-7,88,-7,OBSIDIAN:0)
Block(-7,88,-6,OBSIDIAN:0)
Block(-7,88,-5,OBSIDIAN:0)
Block(-7,88,-4,OBSIDIAN:0)
Block(-7,88,-3,OBSIDIAN:0)
Block(-7,88,-2,STONE:3)
Block(-7,88,-1,STONE:3)
Block(-7,88,0,STONE:5)
Block(-7,88,1,STONE:5)
Block(-7,88,2,STONE:5)
Block(-7,88,3,STONE:3)
Block(-7,88,4,STONE:3)
Block(-7,88,5,STONE:3)
Block(-7,88,6,STONE:3)
Block(-7,88,7,STONE:3)
Block(-7,88,8,OBSIDIAN:0)
Block(-7,89,-7,OBSIDIAN:0)
Block(-7,89,-6,OBSIDIAN:0)
Block(-7,89,-5,OBSIDIAN:0)
Block(-7,89,-4,STONE:3)
Block(-7,89,-3,STONE:3)
Block(-7,89,-2,STONE:5)
Block(-7,89,-1,STONE:5)
Block(-7,89,3,STONE:5)
Block(-7,89,4,STONE:5)
Block(-7,89,5,STONE:5)
Block(-7,89,6,STONE:5)
Block(-7,89,7,STONE:5)
Block(-7,89,8,STONE:5)
Block(-7,90,-7,OBSIDIAN:0)
Block(-7,90,-6,STONE:3)
Block(-7,90,-5,STONE:3)
Block(-7,90,-4,STONE:5)
Block(-7,90,-3,STONE:5)
Block(-7,91,-7,OBSIDIAN:0)
Block(-7,91,-6,STONE:5)
Block(-7,91,-5,STONE:5)
Block(-7,92,-7,STONE:3)
Block(-7,93,-7,STONE:5)
Block(-6,13,5,OBSIDIAN:0)
Block(-6,13,6,OBSIDIAN:0)
Block(-6,13,7,MAGMA:0)
Block(-6,14,-2,STONE:3)
Block(-6,14,-1,STONE:3)
Block(-6,14,0,STONE:3)
Block(-6,14,1,STONE:3)
Block(-6,14,2,STONE:3)
Block(-6,14,3,STONE:3)
Block(-6,14,4,STONE:3)
Block(-6,14,5,OBSIDIAN:0)
Block(-6,14,6,OBSIDIAN:0)
Block(-6,14,7,MAGMA:0)
Block(-6,14,8,MAGMA:0)
Block(-6,15,-7,STONE:3)
Block(-6,15,-6,STONE:3)
Block(-6,15,-5,STONE:3)
Block(-6,15,-4,STONE:3)
Block(-6,15,-3,STONE:3)
Block(-6,15,-2,STONE:3)
Block(-6,15,-1,STONE:3)
Block(-6,15,0,STONE:3)
Block(-6,15,1,STONE:3)
Block(-6,15,2,STONE:3)
Block(-6,15,3,STONE:3)
Block(-6,15,4,STONE:3)
Block(-6,15,5,OBSIDIAN:0)
Block(-6,15,6,OBSIDIAN:0)
Block(-6,15,7,MAGMA:0)
Block(-6,15,8,MAGMA:0)
Block(-6,16,-7,STONE:3)
Block(-6,16,-6,STONE:3)
Block(-6,16,-5,STONE:3)
Block(-6,16,-4,STONE:3)
Block(-6,16,-3,STONE:3)
Block(-6,16,-2,STONE:3)
Block(-6,16,-1,STONE:3)
Block(-6,16,0,STONE:3)
Block(-6,16,1,STONE:3)
Block(-6,16,2,STONE:3)
Block(-6,16,3,STONE:3)
Block(-6,16,4,STONE:3)
Block(-6,16,5,OBSIDIAN:0)
Block(-6,16,6,OBSIDIAN:0)
Block(-6,16,7,OBSIDIAN:0)
Block(-6,16,8,MAGMA:0)
Block(-6,17,-7,STONE:3)
Block(-6,17,-6,STONE:3)
Block(-6,17,-5,STONE:3)
Block(-6,17,-4,STONE:3)
Block(-6,17,-3,STONE:3)
Block(-6,17,-2,STONE:3)
Block(-6,17,-1,STONE:3)
Block(-6,17,0,STONE:3)
Block(-6,17,1,STONE:3)
Block(-6,17,2,STONE:3)
Block(-6,17,3,STONE:3)
Block(-6,17,4,STONE:3)
Block(-6,17,5,OBSIDIAN:0)
Block(-6,17,6,OBSIDIAN:0)
Block(-6,17,7,OBSIDIAN:0)
Block(-6,17,8,OBSIDIAN:0)
Block(-6,18,-7,STONE:3)
Block(-6,18,-6,STONE:3)
Block(-6,18,-5,STONE:3)
Block(-6,18,-4,STONE:3)
Block(-6,18,-3,STONE:3)
Block(-6,18,-2,STONE:3)
Block(-6,18,-1,STONE:3)
Block(-6,18,0,STONE:3)
Block(-6,18,1,STONE:3)
Block(-6,18,2,STONE:3)
Block(-6,18,3,STONE:3)
Block(-6,18,4,STONE:3)
Block(-6,18,5,STONE:3)
Block(-6,18,6,OBSIDIAN:0)
Block(-6,18,7,OBSIDIAN:0)
Block(-6,18,8,OBSIDIAN:0)
Block(-6,19,-7,STONE:3)
Block(-6,19,-6,STONE:3)
Block(-6,19,-5,STONE:3)
Block(-6,19,-4,STONE:3)
Block(-6,19,-3,STONE:3)
Block(-6,19,-2,STONE:3)
Block(-6,19,-1,STONE:3)
Block(-6,19,0,STONE:3)
Block(-6,19,1,STONE:3)
Block(-6,19,2,STONE:3)
Block(-6,19,3,STONE:3)
Block(-6,19,4,STONE:3)
Block(-6,19,5,OBSIDIAN:0)
Block(-6,19,6,OBSIDIAN:0)
Block(-6,19,7,OBSIDIAN:0)
Block(-6,19,8,OBSIDIAN:0)
Block(-6,20,-7,STONE:3)
Block(-6,20,-6,STONE:3)
Block(-6,20,-5,STONE:3)
Block(-6,20,-4,STONE:3)
Block(-6,20,-3,OBSIDIAN:0)
Block(-6,20,-2,OBSIDIAN:0)
Block(-6,20,-1,OBSIDIAN:0)
Block(-6,20,0,OBSIDIAN:0)
Block(-6,20,1,OBSIDIAN:0)
Block(-6,20,2,OBSIDIAN:0)
Block(-6,20,3,OBSIDIAN:0)
Block(-6,20,4,OBSIDIAN:0)
Block(-6,20,5,OBSIDIAN:0)
Block(-6,20,6,OBSIDIAN:0)
Block(-6,20,7,OBSIDIAN:0)
Block(-6,20,8,OBSIDIAN:0)
Block(-6,21,-7,STONE:3)
Block(-6,21,-6,STONE:3)
Block(-6,21,-5,STONE:3)
Block(-6,21,-4,OBSIDIAN:0)
Block(-6,21,-3,OBSIDIAN:0)
Block(-6,21,-2,OBSIDIAN:0)
Block(-6,21,-1,OBSIDIAN:0)
Block(-6,21,0,OBSIDIAN:0)
Block(-6,21,1,OBSIDIAN:0)
Block(-6,21,2,OBSIDIAN:0)
Block(-6,21,3,OBSIDIAN:0)
Block(-6,21,4,OBSIDIAN:0)
Block(-6,21,5,OBSIDIAN:0)
Block(-6,21,6,OBSIDIAN:0)
Block(-6,21,7,OBSIDIAN:0)
Block(-6,21,8,OBSIDIAN:0)
Block(-6,22,-7,STONE:3)
Block(-6,22,-6,STONE:3)
Block(-6,22,-5,OBSIDIAN:0)
Block(-6,22,-4,OBSIDIAN:0)
Block(-6,22,-3,OBSIDIAN:0)
Block(-6,22,-2,OBSIDIAN:0)
Block(-6,22,-1,OBSIDIAN:0)
Block(-6,22,0,OBSIDIAN:0)
Block(-6,22,1,OBSIDIAN:0)
Block(-6,22,2,OBSIDIAN:0)
Block(-6,22,3,OBSIDIAN:0)
Block(-6,22,4,OBSIDIAN:0)
Block(-6,22,5,OBSIDIAN:0)
Block(-6,22,6,OBSIDIAN:0)
Block(-6,22,7,OBSIDIAN:0)
Block(-6,22,8,OBSIDIAN:0)
Block(-6,23,-7,STONE:3)
Block(-6,23,-6,OBSIDIAN:0)
Block(-6,23,-5,OBSIDIAN:0)
Block(-6,23,-4,OBSIDIAN:0)
Block(-6,23,-3,OBSIDIAN:0)
Block(-6,23,-2,OBSIDIAN:0)
Block(-6,23,-1,OBSIDIAN:0)
Block(-6,23,0,OBSIDIAN:0)
Block(-6,23,1,OBSIDIAN:0)
Block(-6,23,2,OBSIDIAN:0)
Block(-6,23,3,OBSIDIAN:0)
Block(-6,23,4,OBSIDIAN:0)
Block(-6,23,5,OBSIDIAN:0)
Block(-6,23,6,OBSIDIAN:0)
Block(-6,23,7,OBSIDIAN:0)
Block(-6,23,8,OBSIDIAN:0)
Block(-6,24,-7,OBSIDIAN:0)
Block(-6,24,-6,OBSIDIAN:0)
Block(-6,24,-5,OBSIDIAN:0)
Block(-6,24,-4,OBSIDIAN:0)
Block(-6,24,-3,OBSIDIAN:0)
Block(-6,24,-2,OBSIDIAN:0)
Block(-6,24,-1,OBSIDIAN:0)
Block(-6,24,0,OBSIDIAN:0)
Block(-6,24,1,OBSIDIAN:0)
Block(-6,24,2,OBSIDIAN:0)
Block(-6,24,3,OBSIDIAN:0)
Block(-6,24,4,OBSIDIAN:0)
Block(-6,24,5,OBSIDIAN:0)
Block(-6,24,6,OBSIDIAN:0)
Block(-6,24,7,OBSIDIAN:0)
Block(-6,24,8,OBSIDIAN:0)
Block(-6,25,-7,OBSIDIAN:0)
Block(-6,25,-6,OBSIDIAN:0)
Block(-6,25,-5,OBSIDIAN:0)
Block(-6,25,-4,OBSIDIAN:0)
Block(-6,25,-3,OBSIDIAN:0)
Block(-6,25,-2,OBSIDIAN:0)
Block(-6,25,-1,OBSIDIAN:0)
Block(-6,25,0,OBSIDIAN:0)
Block(-6,25,1,OBSIDIAN:0)
Block(-6,25,2,OBSIDIAN:0)
Block(-6,25,3,OBSIDIAN:0)
Block(-6,25,4,OBSIDIAN:0)
Block(-6,25,5,OBSIDIAN:0)
Block(-6,25,6,OBSIDIAN:0)
Block(-6,25,7,OBSIDIAN:0)
Block(-6,25,8,OBSIDIAN:0)
Block(-6,26,-7,OBSIDIAN:0)
Block(-6,26,-6,OBSIDIAN:0)
Block(-6,26,-5,OBSIDIAN:0)
Block(-6,26,-4,OBSIDIAN:0)
Block(-6,26,-3,OBSIDIAN:0)
Block(-6,26,-2,OBSIDIAN:0)
Block(-6,26,-1,OBSIDIAN:0)
Block(-6,26,0,OBSIDIAN:0)
Block(-6,26,1,OBSIDIAN:0)
Block(-6,26,2,OBSIDIAN:0)
Block(-6,26,3,OBSIDIAN:0)
Block(-6,26,4,OBSIDIAN:0)
Block(-6,26,5,OBSIDIAN:0)
Block(-6,26,6,OBSIDIAN:0)
Block(-6,26,7,OBSIDIAN:0)
Block(-6,26,8,OBSIDIAN:0)
Block(-6,27,-7,OBSIDIAN:0)
Block(-6,27,-6,OBSIDIAN:0)
Block(-6,27,-5,OBSIDIAN:0)
Block(-6,27,-4,OBSIDIAN:0)
Block(-6,27,-3,OBSIDIAN:0)
Block(-6,27,-2,OBSIDIAN:0)
Block(-6,27,-1,OBSIDIAN:0)
Block(-6,27,0,OBSIDIAN:0)
Block(-6,27,1,OBSIDIAN:0)
Block(-6,27,2,OBSIDIAN:0)
Block(-6,27,3,OBSIDIAN:0)
Block(-6,27,4,OBSIDIAN:0)
Block(-6,27,5,OBSIDIAN:0)
Block(-6,27,6,OBSIDIAN:0)
Block(-6,27,7,OBSIDIAN:0)
Block(-6,27,8,OBSIDIAN:0)
Block(-6,28,-7,OBSIDIAN:0)
Block(-6,28,-6,OBSIDIAN:0)
Block(-6,28,-5,OBSIDIAN:0)
Block(-6,28,-4,OBSIDIAN:0)
Block(-6,28,-3,OBSIDIAN:0)
Block(-6,28,-2,OBSIDIAN:0)
Block(-6,28,-1,OBSIDIAN:0)
Block(-6,28,0,OBSIDIAN:0)
Block(-6,28,1,OBSIDIAN:0)
Block(-6,28,2,OBSIDIAN:0)
Block(-6,28,3,OBSIDIAN:0)
Block(-6,28,4,OBSIDIAN:0)
Block(-6,28,5,OBSIDIAN:0)
Block(-6,28,6,OBSIDIAN:0)
Block(-6,28,7,OBSIDIAN:0)
Block(-6,28,8,OBSIDIAN:0)
Block(-6,29,-7,OBSIDIAN:0)
Block(-6,29,-6,OBSIDIAN:0)
Block(-6,29,-5,OBSIDIAN:0)
Block(-6,29,-4,OBSIDIAN:0)
Block(-6,29,-3,OBSIDIAN:0)
Block(-6,29,-2,OBSIDIAN:0)
Block(-6,29,-1,OBSIDIAN:0)
Block(-6,29,0,OBSIDIAN:0)
Block(-6,29,1,OBSIDIAN:0)
Block(-6,29,2,OBSIDIAN:0)
Block(-6,29,3,OBSIDIAN:0)
Block(-6,29,4,OBSIDIAN:0)
Block(-6,29,5,OBSIDIAN:0)
Block(-6,29,6,OBSIDIAN:0)
Block(-6,29,7,OBSIDIAN:0)
Block(-6,29,8,OBSIDIAN:0)
Block(-6,30,-7,OBSIDIAN:0)
Block(-6,30,-6,OBSIDIAN:0)
Block(-6,30,-5,OBSIDIAN:0)
Block(-6,30,-4,OBSIDIAN:0)
Block(-6,30,-3,OBSIDIAN:0)
Block(-6,30,-2,OBSIDIAN:0)
Block(-6,30,-1,OBSIDIAN:0)
Block(-6,30,0,OBSIDIAN:0)
Block(-6,30,1,OBSIDIAN:0)
Block(-6,30,2,OBSIDIAN:0)
Block(-6,30,3,OBSIDIAN:0)
Block(-6,30,4,OBSIDIAN:0)
Block(-6,30,5,OBSIDIAN:0)
Block(-6,30,6,OBSIDIAN:0)
Block(-6,30,7,OBSIDIAN:0)
Block(-6,30,8,OBSIDIAN:0)
Block(-6,31,-7,OBSIDIAN:0)
Block(-6,31,-6,OBSIDIAN:0)
Block(-6,31,-5,OBSIDIAN:0)
Block(-6,31,-4,OBSIDIAN:0)
Block(-6,31,-3,OBSIDIAN:0)
Block(-6,31,-2,OBSIDIAN:0)
Block(-6,31,-1,OBSIDIAN:0)
Block(-6,31,0,OBSIDIAN:0)
Block(-6,31,1,OBSIDIAN:0)
Block(-6,31,2,OBSIDIAN:0)
Block(-6,31,3,OBSIDIAN:0)
Block(-6,31,4,OBSIDIAN:0)
Block(-6,31,5,OBSIDIAN:0)
Block(-6,31,6,OBSIDIAN:0)
Block(-6,31,7,OBSIDIAN:0)
Block(-6,31,8,OBSIDIAN:0)
Block(-6,32,-7,OBSIDIAN:0)
Block(-6,32,-6,OBSIDIAN:0)
Block(-6,32,-5,OBSIDIAN:0)
Block(-6,32,-4,OBSIDIAN:0)
Block(-6,32,-3,OBSIDIAN:0)
Block(-6,32,-2,OBSIDIAN:0)
Block(-6,32,-1,OBSIDIAN:0)
Block(-6,32,0,OBSIDIAN:0)
Block(-6,32,1,OBSIDIAN:0)
Block(-6,32,2,OBSIDIAN:0)
Block(-6,32,3,OBSIDIAN:0)
Block(-6,32,4,OBSIDIAN:0)
Block(-6,32,5,OBSIDIAN:0)
Block(-6,32,6,OBSIDIAN:0)
Block(-6,32,7,OBSIDIAN:0)
Block(-6,32,8,OBSIDIAN:0)
Block(-6,33,-7,OBSIDIAN:0)
Block(-6,33,-6,OBSIDIAN:0)
Block(-6,33,-5,OBSIDIAN:0)
Block(-6,33,-4,OBSIDIAN:0)
Block(-6,33,-3,OBSIDIAN:0)
Block(-6,33,-2,OBSIDIAN:0)
Block(-6,33,-1,OBSIDIAN:0)
Block(-6,33,0,OBSIDIAN:0)
Block(-6,33,1,OBSIDIAN:0)
Block(-6,33,2,OBSIDIAN:0)
Block(-6,33,3,OBSIDIAN:0)
Block(-6,33,4,OBSIDIAN:0)
Block(-6,33,5,OBSIDIAN:0)
Block(-6,33,6,OBSIDIAN:0)
Block(-6,33,7,OBSIDIAN:0)
Block(-6,33,8,OBSIDIAN:0)
Block(-6,34,-7,OBSIDIAN:0)
Block(-6,34,-6,OBSIDIAN:0)
Block(-6,34,-5,OBSIDIAN:0)
Block(-6,34,-4,OBSIDIAN:0)
Block(-6,34,-3,OBSIDIAN:0)
Block(-6,34,-2,OBSIDIAN:0)
Block(-6,34,-1,OBSIDIAN:0)
Block(-6,34,0,OBSIDIAN:0)
Block(-6,34,1,OBSIDIAN:0)
Block(-6,34,2,OBSIDIAN:0)
Block(-6,34,3,OBSIDIAN:0)
Block(-6,34,4,OBSIDIAN:0)
Block(-6,34,5,OBSIDIAN:0)
Block(-6,34,6,OBSIDIAN:0)
Block(-6,34,7,OBSIDIAN:0)
Block(-6,34,8,OBSIDIAN:0)
Block(-6,35,-7,OBSIDIAN:0)
Block(-6,35,-6,OBSIDIAN:0)
Block(-6,35,-5,OBSIDIAN:0)
Block(-6,35,-4,OBSIDIAN:0)
Block(-6,35,-3,OBSIDIAN:0)
Block(-6,35,-2,OBSIDIAN:0)
Block(-6,35,-1,OBSIDIAN:0)
Block(-6,35,0,OBSIDIAN:0)
Block(-6,35,1,OBSIDIAN:0)
Block(-6,35,2,OBSIDIAN:0)
Block(-6,35,3,OBSIDIAN:0)
Block(-6,35,4,OBSIDIAN:0)
Block(-6,35,5,OBSIDIAN:0)
Block(-6,35,6,STONE:5)
Block(-6,35,7,STONE:5)
Block(-6,35,8,STONE:5)
Block(-6,36,-7,OBSIDIAN:0)
Block(-6,36,-6,OBSIDIAN:0)
Block(-6,36,-5,OBSIDIAN:0)
Block(-6,36,-4,OBSIDIAN:0)
Block(-6,36,-3,OBSIDIAN:0)
Block(-6,36,-2,OBSIDIAN:0)
Block(-6,36,-1,OBSIDIAN:0)
Block(-6,36,0,OBSIDIAN:0)
Block(-6,36,1,OBSIDIAN:0)
Block(-6,36,2,OBSIDIAN:0)
Block(-6,36,3,STONE:5)
Block(-6,36,4,STONE:5)
Block(-6,36,5,STONE:5)
Block(-6,36,6,STONE:5)
Block(-6,36,7,STONE:5)
Block(-6,36,8,STONE:5)
Block(-6,37,-7,OBSIDIAN:0)
Block(-6,37,-6,OBSIDIAN:0)
Block(-6,37,-5,OBSIDIAN:0)
Block(-6,37,-4,OBSIDIAN:0)
Block(-6,37,-3,OBSIDIAN:0)
Block(-6,37,-2,OBSIDIAN:0)
Block(-6,37,-1,STONE:5)
Block(-6,37,0,STONE:5)
Block(-6,37,1,STONE:3)
Block(-6,37,2,STONE:3)
Block(-6,37,3,STONE:3)
Block(-6,37,4,STONE:5)
Block(-6,37,5,STONE:5)
Block(-6,37,6,STONE:5)
Block(-6,37,7,STONE:5)
Block(-6,37,8,STONE:5)
Block(-6,38,-7,OBSIDIAN:0)
Block(-6,38,-6,OBSIDIAN:0)
Block(-6,38,-5,OBSIDIAN:0)
Block(-6,38,-4,STONE:5)
Block(-6,38,-3,STONE:5)
Block(-6,38,-2,STONE:5)
Block(-6,38,-1,STONE:5)
Block(-6,38,0,STONE:3)
Block(-6,38,1,STONE:3)
Block(-6,38,2,STONE:3)
Block(-6,38,3,STONE:3)
Block(-6,38,4,STONE:3)
Block(-6,38,5,STONE:5)
Block(-6,38,6,STONE:5)
Block(-6,38,7,STONE:5)
Block(-6,38,8,STONE:5)
Block(-6,39,-7,OBSIDIAN:0)
Block(-6,39,-6,STONE:5)
Block(-6,39,-5,STONE:5)
Block(-6,39,-4,STONE:5)
Block(-6,39,-3,STONE:5)
Block(-6,39,-2,STONE:5)
Block(-6,39,-1,STONE:5)
Block(-6,39,0,STONE:3)
Block(-6,39,1,STONE:3)
Block(-6,39,2,STONE:3)
Block(-6,39,3,STONE:3)
Block(-6,39,4,STONE:3)
Block(-6,40,-7,STONE:5)
Block(-6,40,-6,STONE:5)
Block(-6,40,-5,STONE:5)
Block(-6,40,-4,STONE:5)
Block(-6,40,-3,STONE:5)
Block(-6,41,-7,GRASS:0)
Block(-6,41,-6,STONE:5)
Block(-6,41,-5,STONE:5)
Block(-6,76,5,OBSIDIAN:0)
Block(-6,76,6,OBSIDIAN:0)
Block(-6,76,7,OBSIDIAN:0)
Block(-6,76,8,OBSIDIAN:0)
Block(-6,77,1,OBSIDIAN:0)
Block(-6,77,3,OBSIDIAN:0)
Block(-6,77,4,OBSIDIAN:0)
Block(-6,77,5,OBSIDIAN:0)
Block(-6,77,6,OBSIDIAN:0)
Block(-6,77,7,OBSIDIAN:0)
Block(-6,77,8,OBSIDIAN:0)
Block(-6,78,-5,OBSIDIAN:0)
Block(-6,78,-4,OBSIDIAN:0)
Block(-6,78,-3,OBSIDIAN:0)
Block(-6,78,-2,OBSIDIAN:0)
Block(-6,78,-1,OBSIDIAN:0)
Block(-6,78,0,OBSIDIAN:0)
Block(-6,78,1,OBSIDIAN:0)
Block(-6,78,2,OBSIDIAN:0)
Block(-6,78,3,OBSIDIAN:0)
Block(-6,78,4,OBSIDIAN:0)
Block(-6,78,5,OBSIDIAN:0)
Block(-6,78,6,OBSIDIAN:0)
Block(-6,78,7,OBSIDIAN:0)
Block(-6,78,8,OBSIDIAN:0)
Block(-6,79,-6,OBSIDIAN:0)
Block(-6,79,-5,OBSIDIAN:0)
Block(-6,79,-4,OBSIDIAN:0)
Block(-6,79,-3,OBSIDIAN:0)
Block(-6,79,-2,OBSIDIAN:0)
Block(-6,79,-1,OBSIDIAN:0)
Block(-6,79,0,OBSIDIAN:0)
Block(-6,79,1,OBSIDIAN:0)
Block(-6,79,2,OBSIDIAN:0)
Block(-6,79,3,OBSIDIAN:0)
Block(-6,79,4,OBSIDIAN:0)
Block(-6,79,5,OBSIDIAN:0)
Block(-6,79,6,OBSIDIAN:0)
Block(-6,79,7,OBSIDIAN:0)
Block(-6,79,8,OBSIDIAN:0)
Block(-6,80,-7,OBSIDIAN:0)
Block(-6,80,-6,OBSIDIAN:0)
Block(-6,80,-5,OBSIDIAN:0)
Block(-6,80,-4,OBSIDIAN:0)
Block(-6,80,-3,OBSIDIAN:0)
Block(-6,80,-2,OBSIDIAN:0)
Block(-6,80,-1,OBSIDIAN:0)
Block(-6,80,0,OBSIDIAN:0)
Block(-6,80,1,OBSIDIAN:0)
Block(-6,80,2,OBSIDIAN:0)
Block(-6,80,3,OBSIDIAN:0)
Block(-6,80,4,OBSIDIAN:0)
Block(-6,80,5,OBSIDIAN:0)
Block(-6,80,6,OBSIDIAN:0)
Block(-6,80,7,OBSIDIAN:0)
Block(-6,80,8,OBSIDIAN:0)
Block(-6,81,-7,OBSIDIAN:0)
Block(-6,81,-6,OBSIDIAN:0)
Block(-6,81,-5,OBSIDIAN:0)
Block(-6,81,-4,OBSIDIAN:0)
Block(-6,81,-3,OBSIDIAN:0)
Block(-6,81,-2,OBSIDIAN:0)
Block(-6,81,-1,OBSIDIAN:0)
Block(-6,81,0,OBSIDIAN:0)
Block(-6,81,1,OBSIDIAN:0)
Block(-6,81,2,OBSIDIAN:0)
Block(-6,81,3,OBSIDIAN:0)
Block(-6,81,4,OBSIDIAN:0)
Block(-6,81,5,OBSIDIAN:0)
Block(-6,81,6,OBSIDIAN:0)
Block(-6,81,7,OBSIDIAN:0)
Block(-6,81,8,OBSIDIAN:0)
Block(-6,82,-7,OBSIDIAN:0)
Block(-6,82,-6,OBSIDIAN:0)
Block(-6,82,-5,OBSIDIAN:0)
Block(-6,82,-4,OBSIDIAN:0)
Block(-6,82,-3,OBSIDIAN:0)
Block(-6,82,-2,OBSIDIAN:0)
Block(-6,82,-1,OBSIDIAN:0)
Block(-6,82,0,OBSIDIAN:0)
Block(-6,82,1,OBSIDIAN:0)
Block(-6,82,2,OBSIDIAN:0)
Block(-6,82,3,OBSIDIAN:0)
Block(-6,82,4,OBSIDIAN:0)
Block(-6,82,5,OBSIDIAN:0)
Block(-6,82,6,OBSIDIAN:0)
Block(-6,82,7,OBSIDIAN:0)
Block(-6,82,8,OBSIDIAN:0)
Block(-6,83,-7,OBSIDIAN:0)
Block(-6,83,-6,OBSIDIAN:0)
Block(-6,83,-5,OBSIDIAN:0)
Block(-6,83,-4,OBSIDIAN:0)
Block(-6,83,-3,OBSIDIAN:0)
Block(-6,83,-2,OBSIDIAN:0)
Block(-6,83,-1,OBSIDIAN:0)
Block(-6,83,0,OBSIDIAN:0)
Block(-6,83,1,OBSIDIAN:0)
Block(-6,83,2,OBSIDIAN:0)
Block(-6,83,3,OBSIDIAN:0)
Block(-6,83,4,OBSIDIAN:0)
Block(-6,83,5,OBSIDIAN:0)
Block(-6,83,6,OBSIDIAN:0)
Block(-6,83,7,OBSIDIAN:0)
Block(-6,83,8,OBSIDIAN:0)
Block(-6,84,-7,OBSIDIAN:0)
Block(-6,84,-6,OBSIDIAN:0)
Block(-6,84,-5,OBSIDIAN:0)
Block(-6,84,-4,OBSIDIAN:0)
Block(-6,84,-3,OBSIDIAN:0)
Block(-6,84,-2,OBSIDIAN:0)
Block(-6,84,-1,OBSIDIAN:0)
Block(-6,84,0,OBSIDIAN:0)
Block(-6,84,1,OBSIDIAN:0)
Block(-6,84,2,OBSIDIAN:0)
Block(-6,84,3,OBSIDIAN:0)
Block(-6,84,4,OBSIDIAN:0)
Block(-6,84,5,OBSIDIAN:0)
Block(-6,84,6,OBSIDIAN:0)
Block(-6,84,7,OBSIDIAN:0)
Block(-6,84,8,OBSIDIAN:0)
Block(-6,85,-7,OBSIDIAN:0)
Block(-6,85,-6,OBSIDIAN:0)
Block(-6,85,-5,OBSIDIAN:0)
Block(-6,85,-4,OBSIDIAN:0)
Block(-6,85,-3,OBSIDIAN:0)
Block(-6,85,-2,OBSIDIAN:0)
Block(-6,85,-1,OBSIDIAN:0)
Block(-6,85,0,OBSIDIAN:0)
Block(-6,85,1,OBSIDIAN:0)
Block(-6,85,2,OBSIDIAN:0)
Block(-6,85,3,OBSIDIAN:0)
Block(-6,85,4,OBSIDIAN:0)
Block(-6,85,5,OBSIDIAN:0)
Block(-6,85,6,OBSIDIAN:0)
Block(-6,85,7,OBSIDIAN:0)
Block(-6,85,8,OBSIDIAN:0)
Block(-6,86,-7,OBSIDIAN:0)
Block(-6,86,-6,OBSIDIAN:0)
Block(-6,86,-5,OBSIDIAN:0)
Block(-6,86,-4,OBSIDIAN:0)
Block(-6,86,-3,OBSIDIAN:0)
Block(-6,86,-2,OBSIDIAN:0)
Block(-6,86,-1,OBSIDIAN:0)
Block(-6,86,0,OBSIDIAN:0)
Block(-6,86,1,OBSIDIAN:0)
Block(-6,86,2,OBSIDIAN:0)
Block(-6,86,3,OBSIDIAN:0)
Block(-6,86,4,OBSIDIAN:0)
Block(-6,86,5,OBSIDIAN:0)
Block(-6,86,6,OBSIDIAN:0)
Block(-6,86,7,OBSIDIAN:0)
Block(-6,86,8,OBSIDIAN:0)
Block(-6,87,-7,OBSIDIAN:0)
Block(-6,87,-6,OBSIDIAN:0)
Block(-6,87,-5,OBSIDIAN:0)
Block(-6,87,-4,OBSIDIAN:0)
Block(-6,87,-3,OBSIDIAN:0)
Block(-6,87,-2,OBSIDIAN:0)
Block(-6,87,-1,OBSIDIAN:0)
Block(-6,87,0,OBSIDIAN:0)
Block(-6,87,1,STONE:3)
Block(-6,87,2,STONE:3)
Block(-6,87,3,STONE:3)
Block(-6,87,4,OBSIDIAN:0)
Block(-6,87,5,OBSIDIAN:0)
Block(-6,87,6,STONE:3)
Block(-6,87,7,STONE:3)
Block(-6,87,8,OBSIDIAN:0)
Block(-6,88,-7,OBSIDIAN:0)
Block(-6,88,-6,OBSIDIAN:0)
Block(-6,88,-5,OBSIDIAN:0)
Block(-6,88,-4,OBSIDIAN:0)
Block(-6,88,-3,OBSIDIAN:0)
Block(-6,88,-2,OBSIDIAN:0)
Block(-6,88,-1,OBSIDIAN:0)
Block(-6,88,0,STONE:3)
Block(-6,88,1,STONE:5)
Block(-6,88,2,STONE:5)
Block(-6,88,3,STONE:5)
Block(-6,88,4,STONE:3)
Block(-6,88,5,STONE:3)
Block(-6,88,6,STONE:5)
Block(-6,88,7,STONE:5)
Block(-6,88,8,OBSIDIAN:0)
Block(-6,89,-7,OBSIDIAN:0)
Block(-6,89,-6,OBSIDIAN:0)
Block(-6,89,-5,OBSIDIAN:0)
Block(-6,89,-4,OBSIDIAN:0)
Block(-6,89,-3,OBSIDIAN:0)
Block(-6,89,-2,STONE:3)
Block(-6,89,-1,STONE:3)
Block(-6,89,0,STONE:5)
Block(-6,89,4,STONE:5)
Block(-6,89,5,STONE:5)
Block(-6,90,-7,OBSIDIAN:0)
Block(-6,90,-6,OBSIDIAN:0)
Block(-6,90,-5,STONE:3)
Block(-6,90,-4,STONE:3)
Block(-6,90,-3,STONE:3)
Block(-6,90,-2,STONE:5)
Block(-6,90,-1,STONE:5)
Block(-6,91,-7,STONE:3)
Block(-6,91,-6,STONE:3)
Block(-6,91,-5,STONE:5)
Block(-6,91,-4,STONE:5)
Block(-6,91,-3,STONE:5)
Block(-6,92,-7,STONE:5)
Block(-6,92,-6,STONE:5)
Block(-5,13,6,MAGMA:0)
Block(-5,14,0,STONE:3)
Block(-5,14,1,STONE:3)
Block(-5,14,2,STONE:3)
Block(-5,14,3,STONE:3)
Block(-5,14,4,OBSIDIAN:0)
Block(-5,14,5,OBSIDIAN:0)
Block(-5,14,6,MAGMA:0)
Block(-5,14,7,MAGMA:0)
Block(-5,14,8,MAGMA:0)
Block(-5,15,-7,STONE:3)
Block(-5,15,-6,STONE:3)
Block(-5,15,-5,STONE:3)
Block(-5,15,-4,STONE:3)
Block(-5,15,-3,STONE:3)
Block(-5,15,-2,STONE:3)
Block(-5,15,-1,STONE:3)
Block(-5,15,0,STONE:3)
Block(-5,15,1,STONE:3)
Block(-5,15,2,STONE:3)
Block(-5,15,3,STONE:3)
Block(-5,15,4,OBSIDIAN:0)
Block(-5,15,5,OBSIDIAN:0)
Block(-5,15,6,MAGMA:0)
Block(-5,15,7,MAGMA:0)
Block(-5,15,8,MAGMA:0)
Block(-5,16,-7,STONE:3)
Block(-5,16,-6,STONE:3)
Block(-5,16,-5,STONE:3)
Block(-5,16,-4,STONE:3)
Block(-5,16,-3,STONE:3)
Block(-5,16,-2,STONE:3)
Block(-5,16,-1,STONE:3)
Block(-5,16,0,STONE:3)
Block(-5,16,1,STONE:3)
Block(-5,16,2,STONE:3)
Block(-5,16,3,STONE:3)
Block(-5,16,4,OBSIDIAN:0)
Block(-5,16,5,OBSIDIAN:0)
Block(-5,16,6,OBSIDIAN:0)
Block(-5,16,7,MAGMA:0)
Block(-5,16,8,MAGMA:0)
Block(-5,17,-7,STONE:3)
Block(-5,17,-6,STONE:3)
Block(-5,17,-5,STONE:3)
Block(-5,17,-4,STONE:3)
Block(-5,17,-3,STONE:3)
Block(-5,17,-2,STONE:3)
Block(-5,17,-1,STONE:3)
Block(-5,17,0,STONE:3)
Block(-5,17,1,STONE:3)
Block(-5,17,2,STONE:3)
Block(-5,17,3,STONE:3)
Block(-5,17,4,STONE:3)
Block(-5,17,5,OBSIDIAN:0)
Block(-5,17,6,OBSIDIAN:0)
Block(-5,17,7,OBSIDIAN:0)
Block(-5,17,8,OBSIDIAN:0)
Block(-5,18,-7,STONE:3)
Block(-5,18,-6,STONE:3)
Block(-5,18,-5,STONE:3)
Block(-5,18,-4,STONE:3)
Block(-5,18,-3,STONE:3)
Block(-5,18,-2,STONE:3)
Block(-5,18,-1,STONE:3)
Block(-5,18,0,STONE:3)
Block(-5,18,1,STONE:3)
Block(-5,18,2,STONE:3)
Block(-5,18,3,STONE:3)
Block(-5,18,4,STONE:3)
Block(-5,18,5,OBSIDIAN:0)
Block(-5,18,6,OBSIDIAN:0)
Block(-5,18,7,OBSIDIAN:0)
Block(-5,18,8,OBSIDIAN:0)
Block(-5,19,-7,STONE:3)
Block(-5,19,-6,STONE:3)
Block(-5,19,-5,STONE:3)
Block(-5,19,-4,STONE:3)
Block(-5,19,-3,STONE:3)
Block(-5,19,-2,OBSIDIAN:0)
Block(-5,19,-1,OBSIDIAN:0)
Block(-5,19,0,OBSIDIAN:0)
Block(-5,19,1,STONE:3)
Block(-5,19,2,STONE:3)
Block(-5,19,3,STONE:3)
Block(-5,19,4,OBSIDIAN:0)
Block(-5,19,5,OBSIDIAN:0)
Block(-5,19,6,OBSIDIAN:0)
Block(-5,19,7,OBSIDIAN:0)
Block(-5,19,8,OBSIDIAN:0)
Block(-5,20,-7,STONE:3)
Block(-5,20,-6,STONE:3)
Block(-5,20,-5,STONE:3)
Block(-5,20,-4,OBSIDIAN:0)
Block(-5,20,-3,OBSIDIAN:0)
Block(-5,20,-2,OBSIDIAN:0)
Block(-5,20,-1,OBSIDIAN:0)
Block(-5,20,0,OBSIDIAN:0)
Block(-5,20,1,OBSIDIAN:0)
Block(-5,20,2,OBSIDIAN:0)
Block(-5,20,3,OBSIDIAN:0)
Block(-5,20,4,OBSIDIAN:0)
Block(-5,20,5,OBSIDIAN:0)
Block(-5,20,6,OBSIDIAN:0)
Block(-5,20,7,OBSIDIAN:0)
Block(-5,20,8,OBSIDIAN:0)
Block(-5,21,-7,STONE:3)
Block(-5,21,-6,STONE:3)
Block(-5,21,-5,OBSIDIAN:0)
Block(-5,21,-4,OBSIDIAN:0)
Block(-5,21,-3,OBSIDIAN:0)
Block(-5,21,-2,OBSIDIAN:0)
Block(-5,21,-1,OBSIDIAN:0)
Block(-5,21,0,OBSIDIAN:0)
Block(-5,21,1,OBSIDIAN:0)
Block(-5,21,2,OBSIDIAN:0)
Block(-5,21,3,OBSIDIAN:0)
Block(-5,21,4,OBSIDIAN:0)
Block(-5,21,5,OBSIDIAN:0)
Block(-5,21,6,OBSIDIAN:0)
Block(-5,21,7,OBSIDIAN:0)
Block(-5,21,8,OBSIDIAN:0)
Block(-5,22,-7,STONE:3)
Block(-5,22,-6,STONE:3)
Block(-5,22,-5,OBSIDIAN:0)
Block(-5,22,-4,OBSIDIAN:0)
Block(-5,22,-3,OBSIDIAN:0)
Block(-5,22,-2,OBSIDIAN:0)
Block(-5,22,-1,OBSIDIAN:0)
Block(-5,22,0,OBSIDIAN:0)
Block(-5,22,1,OBSIDIAN:0)
Block(-5,22,2,OBSIDIAN:0)
Block(-5,22,3,OBSIDIAN:0)
Block(-5,22,4,OBSIDIAN:0)
Block(-5,22,5,OBSIDIAN:0)
Block(-5,22,6,OBSIDIAN:0)
Block(-5,22,7,OBSIDIAN:0)
Block(-5,22,8,OBSIDIAN:0)
Block(-5,23,-7,STONE:3)
Block(-5,23,-6,OBSIDIAN:0)
Block(-5,23,-5,OBSIDIAN:0)
Block(-5,23,-4,OBSIDIAN:0)
Block(-5,23,-3,OBSIDIAN:0)
Block(-5,23,-2,OBSIDIAN:0)
Block(-5,23,-1,OBSIDIAN:0)
Block(-5,23,0,OBSIDIAN:0)
Block(-5,23,1,OBSIDIAN:0)
Block(-5,23,2,OBSIDIAN:0)
Block(-5,23,3,OBSIDIAN:0)
Block(-5,23,4,OBSIDIAN:0)
Block(-5,23,5,OBSIDIAN:0)
Block(-5,23,6,OBSIDIAN:0)
Block(-5,23,7,OBSIDIAN:0)
Block(-5,23,8,OBSIDIAN:0)
Block(-5,24,-7,OBSIDIAN:0)
Block(-5,24,-6,OBSIDIAN:0)
Block(-5,24,-5,OBSIDIAN:0)
Block(-5,24,-4,OBSIDIAN:0)
Block(-5,24,-3,OBSIDIAN:0)
Block(-5,24,-2,OBSIDIAN:0)
Block(-5,24,-1,OBSIDIAN:0)
Block(-5,24,0,OBSIDIAN:0)
Block(-5,24,1,OBSIDIAN:0)
Block(-5,24,2,OBSIDIAN:0)
Block(-5,24,3,OBSIDIAN:0)
Block(-5,24,4,OBSIDIAN:0)
Block(-5,24,5,OBSIDIAN:0)
Block(-5,24,6,OBSIDIAN:0)
Block(-5,24,7,OBSIDIAN:0)
Block(-5,24,8,OBSIDIAN:0)
Block(-5,25,-7,OBSIDIAN:0)
Block(-5,25,-6,OBSIDIAN:0)
Block(-5,25,-5,OBSIDIAN:0)
Block(-5,25,-4,OBSIDIAN:0)
Block(-5,25,-3,OBSIDIAN:0)
Block(-5,25,-2,OBSIDIAN:0)
Block(-5,25,-1,OBSIDIAN:0)
Block(-5,25,0,OBSIDIAN:0)
Block(-5,25,1,OBSIDIAN:0)
Block(-5,25,2,OBSIDIAN:0)
Block(-5,25,3,OBSIDIAN:0)
Block(-5,25,4,OBSIDIAN:0)
Block(-5,25,5,OBSIDIAN:0)
Block(-5,25,6,OBSIDIAN:0)
Block(-5,25,7,OBSIDIAN:0)
Block(-5,25,8,OBSIDIAN:0)
Block(-5,26,-7,OBSIDIAN:0)
Block(-5,26,-6,OBSIDIAN:0)
Block(-5,26,-5,OBSIDIAN:0)
Block(-5,26,-4,OBSIDIAN:0)
Block(-5,26,-3,OBSIDIAN:0)
Block(-5,26,-2,OBSIDIAN:0)
Block(-5,26,-1,OBSIDIAN:0)
Block(-5,26,0,OBSIDIAN:0)
Block(-5,26,1,OBSIDIAN:0)
Block(-5,26,2,OBSIDIAN:0)
Block(-5,26,3,OBSIDIAN:0)
Block(-5,26,4,OBSIDIAN:0)
Block(-5,26,5,OBSIDIAN:0)
Block(-5,26,6,OBSIDIAN:0)
Block(-5,26,7,OBSIDIAN:0)
Block(-5,26,8,OBSIDIAN:0)
Block(-5,27,-7,OBSIDIAN:0)
Block(-5,27,-6,OBSIDIAN:0)
Block(-5,27,-5,OBSIDIAN:0)
Block(-5,27,-4,OBSIDIAN:0)
Block(-5,27,-3,OBSIDIAN:0)
Block(-5,27,-2,OBSIDIAN:0)
Block(-5,27,-1,OBSIDIAN:0)
Block(-5,27,0,OBSIDIAN:0)
Block(-5,27,1,OBSIDIAN:0)
Block(-5,27,2,OBSIDIAN:0)
Block(-5,27,3,OBSIDIAN:0)
Block(-5,27,4,OBSIDIAN:0)
Block(-5,27,5,OBSIDIAN:0)
Block(-5,27,6,OBSIDIAN:0)
Block(-5,27,7,OBSIDIAN:0)
Block(-5,27,8,OBSIDIAN:0)
Block(-5,28,-7,OBSIDIAN:0)
Block(-5,28,-6,OBSIDIAN:0)
Block(-5,28,-5,OBSIDIAN:0)
Block(-5,28,-4,OBSIDIAN:0)
Block(-5,28,-3,OBSIDIAN:0)
Block(-5,28,-2,OBSIDIAN:0)
Block(-5,28,-1,OBSIDIAN:0)
Block(-5,28,0,OBSIDIAN:0)
Block(-5,28,1,OBSIDIAN:0)
Block(-5,28,2,OBSIDIAN:0)
Block(-5,28,3,OBSIDIAN:0)
Block(-5,28,4,OBSIDIAN:0)
Block(-5,28,5,OBSIDIAN:0)
Block(-5,28,6,OBSIDIAN:0)
Block(-5,28,7,OBSIDIAN:0)
Block(-5,28,8,OBSIDIAN:0)
Block(-5,29,-7,OBSIDIAN:0)
Block(-5,29,-6,OBSIDIAN:0)
Block(-5,29,-5,OBSIDIAN:0)
Block(-5,29,-4,OBSIDIAN:0)
Block(-5,29,-3,OBSIDIAN:0)
Block(-5,29,-2,OBSIDIAN:0)
Block(-5,29,-1,OBSIDIAN:0)
Block(-5,29,0,OBSIDIAN:0)
Block(-5,29,1,OBSIDIAN:0)
Block(-5,29,2,OBSIDIAN:0)
Block(-5,29,3,OBSIDIAN:0)
Block(-5,29,4,OBSIDIAN:0)
Block(-5,29,5,OBSIDIAN:0)
Block(-5,29,6,OBSIDIAN:0)
Block(-5,29,7,OBSIDIAN:0)
Block(-5,29,8,OBSIDIAN:0)
Block(-5,30,-7,OBSIDIAN:0)
Block(-5,30,-6,OBSIDIAN:0)
Block(-5,30,-5,OBSIDIAN:0)
Block(-5,30,-4,OBSIDIAN:0)
Block(-5,30,-3,OBSIDIAN:0)
Block(-5,30,-2,OBSIDIAN:0)
Block(-5,30,-1,OBSIDIAN:0)
Block(-5,30,0,OBSIDIAN:0)
Block(-5,30,1,OBSIDIAN:0)
Block(-5,30,2,OBSIDIAN:0)
Block(-5,30,3,OBSIDIAN:0)
Block(-5,30,4,OBSIDIAN:0)
Block(-5,30,5,OBSIDIAN:0)
Block(-5,30,6,OBSIDIAN:0)
Block(-5,30,7,OBSIDIAN:0)
Block(-5,30,8,OBSIDIAN:0)
Block(-5,31,-7,OBSIDIAN:0)
Block(-5,31,-6,OBSIDIAN:0)
Block(-5,31,-5,OBSIDIAN:0)
Block(-5,31,-4,OBSIDIAN:0)
Block(-5,31,-3,OBSIDIAN:0)
Block(-5,31,-2,OBSIDIAN:0)
Block(-5,31,-1,OBSIDIAN:0)
Block(-5,31,0,OBSIDIAN:0)
Block(-5,31,1,OBSIDIAN:0)
Block(-5,31,2,OBSIDIAN:0)
Block(-5,31,3,OBSIDIAN:0)
Block(-5,31,4,OBSIDIAN:0)
Block(-5,31,5,OBSIDIAN:0)
Block(-5,31,6,OBSIDIAN:0)
Block(-5,31,7,OBSIDIAN:0)
Block(-5,31,8,OBSIDIAN:0)
Block(-5,32,-7,OBSIDIAN:0)
Block(-5,32,-6,OBSIDIAN:0)
Block(-5,32,-5,OBSIDIAN:0)
Block(-5,32,-4,OBSIDIAN:0)
Block(-5,32,-3,OBSIDIAN:0)
Block(-5,32,-2,OBSIDIAN:0)
Block(-5,32,-1,OBSIDIAN:0)
Block(-5,32,0,OBSIDIAN:0)
Block(-5,32,1,OBSIDIAN:0)
Block(-5,32,2,OBSIDIAN:0)
Block(-5,32,3,OBSIDIAN:0)
Block(-5,32,4,OBSIDIAN:0)
Block(-5,32,5,OBSIDIAN:0)
Block(-5,32,6,OBSIDIAN:0)
Block(-5,32,7,OBSIDIAN:0)
Block(-5,32,8,OBSIDIAN:0)
Block(-5,33,-7,OBSIDIAN:0)
Block(-5,33,-6,OBSIDIAN:0)
Block(-5,33,-5,OBSIDIAN:0)
Block(-5,33,-4,OBSIDIAN:0)
Block(-5,33,-3,OBSIDIAN:0)
Block(-5,33,-2,OBSIDIAN:0)
Block(-5,33,-1,OBSIDIAN:0)
Block(-5,33,0,OBSIDIAN:0)
Block(-5,33,1,OBSIDIAN:0)
Block(-5,33,2,OBSIDIAN:0)
Block(-5,33,3,OBSIDIAN:0)
Block(-5,33,4,OBSIDIAN:0)
Block(-5,33,5,OBSIDIAN:0)
Block(-5,33,6,OBSIDIAN:0)
Block(-5,33,7,OBSIDIAN:0)
Block(-5,33,8,OBSIDIAN:0)
Block(-5,34,-7,OBSIDIAN:0)
Block(-5,34,-6,OBSIDIAN:0)
Block(-5,34,-5,OBSIDIAN:0)
Block(-5,34,-4,OBSIDIAN:0)
Block(-5,34,-3,OBSIDIAN:0)
Block(-5,34,-2,OBSIDIAN:0)
Block(-5,34,-1,OBSIDIAN:0)
Block(-5,34,0,OBSIDIAN:0)
Block(-5,34,1,OBSIDIAN:0)
Block(-5,34,2,OBSIDIAN:0)
Block(-5,34,3,OBSIDIAN:0)
Block(-5,34,4,OBSIDIAN:0)
Block(-5,34,5,OBSIDIAN:0)
Block(-5,34,6,OBSIDIAN:0)
Block(-5,34,7,OBSIDIAN:0)
Block(-5,34,8,OBSIDIAN:0)
Block(-5,35,-7,OBSIDIAN:0)
Block(-5,35,-6,OBSIDIAN:0)
Block(-5,35,-5,OBSIDIAN:0)
Block(-5,35,-4,OBSIDIAN:0)
Block(-5,35,-3,OBSIDIAN:0)
Block(-5,35,-2,OBSIDIAN:0)
Block(-5,35,-1,OBSIDIAN:0)
Block(-5,35,0,OBSIDIAN:0)
Block(-5,35,1,OBSIDIAN:0)
Block(-5,35,2,OBSIDIAN:0)
Block(-5,35,3,OBSIDIAN:0)
Block(-5,35,4,OBSIDIAN:0)
Block(-5,35,5,OBSIDIAN:0)
Block(-5,35,6,OBSIDIAN:0)
Block(-5,35,7,OBSIDIAN:0)
Block(-5,35,8,OBSIDIAN:0)
Block(-5,36,-7,OBSIDIAN:0)
Block(-5,36,-6,OBSIDIAN:0)
Block(-5,36,-5,OBSIDIAN:0)
Block(-5,36,-4,OBSIDIAN:0)
Block(-5,36,-3,OBSIDIAN:0)
Block(-5,36,-2,OBSIDIAN:0)
Block(-5,36,-1,OBSIDIAN:0)
Block(-5,36,0,OBSIDIAN:0)
Block(-5,36,1,OBSIDIAN:0)
Block(-5,36,2,OBSIDIAN:0)
Block(-5,36,3,STONE:5)
Block(-5,36,4,STONE:5)
Block(-5,36,5,STONE:5)
Block(-5,36,6,STONE:5)
Block(-5,36,7,STONE:5)
Block(-5,36,8,STONE:5)
Block(-5,37,-7,OBSIDIAN:0)
Block(-5,37,-6,OBSIDIAN:0)
Block(-5,37,-5,OBSIDIAN:0)
Block(-5,37,-4,OBSIDIAN:0)
Block(-5,37,-3,OBSIDIAN:0)
Block(-5,37,-2,OBSIDIAN:0)
Block(-5,37,-1,STONE:5)
Block(-5,37,0,STONE:5)
Block(-5,37,1,STONE:3)
Block(-5,37,2,STONE:3)
Block(-5,37,3,STONE:3)
Block(-5,37,4,STONE:5)
Block(-5,37,5,STONE:5)
Block(-5,37,6,STONE:5)
Block(-5,37,7,STONE:5)
Block(-5,37,8,STONE:5)
Block(-5,38,-7,OBSIDIAN:0)
Block(-5,38,-6,OBSIDIAN:0)
Block(-5,38,-5,OBSIDIAN:0)
Block(-5,38,-4,STONE:5)
Block(-5,38,-3,STONE:5)
Block(-5,38,-2,STONE:5)
Block(-5,38,-1,STONE:5)
Block(-5,38,0,STONE:3)
Block(-5,38,1,STONE:3)
Block(-5,38,2,STONE:3)
Block(-5,38,3,STONE:3)
Block(-5,38,4,STONE:3)
Block(-5,38,5,STONE:5)
Block(-5,38,6,STONE:5)
Block(-5,38,7,STONE:5)
Block(-5,38,8,STONE:5)
Block(-5,39,-7,OBSIDIAN:0)
Block(-5,39,-6,OBSIDIAN:0)
Block(-5,39,-5,STONE:5)
Block(-5,39,-4,STONE:5)
Block(-5,39,-3,STONE:5)
Block(-5,39,-2,STONE:5)
Block(-5,39,-1,STONE:5)
Block(-5,39,0,STONE:3)
Block(-5,39,1,STONE:3)
Block(-5,39,2,STONE:3)
Block(-5,39,3,STONE:3)
Block(-5,39,6,STONE:5)
Block(-5,39,7,STONE:5)
Block(-5,39,8,STONE:5)
Block(-5,40,-7,STONE:5)
Block(-5,40,-6,STONE:5)
Block(-5,40,-5,STONE:5)
Block(-5,40,-4,STONE:5)
Block(-5,40,-3,STONE:5)
Block(-5,40,-2,STONE:5)
Block(-5,40,-1,STONE:5)
Block(-5,41,-7,GRASS:0)
Block(-5,41,-6,GRASS:0)
Block(-5,41,-5,GRASS:0)
Block(-5,41,-4,STONE:5)
Block(-5,74,5,OBSIDIAN:0)
Block(-5,74,6,OBSIDIAN:0)
Block(-5,74,7,OBSIDIAN:0)
Block(-5,75,4,OBSIDIAN:0)
Block(-5,75,5,OBSIDIAN:0)
Block(-5,75,6,OBSIDIAN:0)
Block(-5,75,7,OBSIDIAN:0)
Block(-5,75,8,OBSIDIAN:0)
Block(-5,76,3,OBSIDIAN:0)
Block(-5,76,4,OBSIDIAN:0)
Block(-5,76,5,OBSIDIAN:0)
Block(-5,76,6,OBSIDIAN:0)
Block(-5,76,7,OBSIDIAN:0)
Block(-5,76,8,OBSIDIAN:0)
Block(-5,77,-3,OBSIDIAN:0)
Block(-5,77,-2,OBSIDIAN:0)
Block(-5,77,-1,OBSIDIAN:0)
Block(-5,77,0,OBSIDIAN:0)
Block(-5,77,1,OBSIDIAN:0)
Block(-5,77,2,OBSIDIAN:0)
Block(-5,77,3,OBSIDIAN:0)
Block(-5,77,4,OBSIDIAN:0)
Block(-5,77,5,OBSIDIAN:0)
Block(-5,77,6,OBSIDIAN:0)
Block(-5,77,7,OBSIDIAN:0)
Block(-5,77,8,OBSIDIAN:0)
Block(-5,78,-5,OBSIDIAN:0)
Block(-5,78,-4,OBSIDIAN:0)
Block(-5,78,-3,OBSIDIAN:0)
Block(-5,78,-2,OBSIDIAN:0)
Block(-5,78,-1,OBSIDIAN:0)
Block(-5,78,0,OBSIDIAN:0)
Block(-5,78,1,OBSIDIAN:0)
Block(-5,78,2,OBSIDIAN:0)
Block(-5,78,3,OBSIDIAN:0)
Block(-5,78,4,OBSIDIAN:0)
Block(-5,78,5,OBSIDIAN:0)
Block(-5,78,6,OBSIDIAN:0)
Block(-5,78,7,OBSIDIAN:0)
Block(-5,78,8,OBSIDIAN:0)
Block(-5,79,-5,OBSIDIAN:0)
Block(-5,79,-4,OBSIDIAN:0)
Block(-5,79,-3,OBSIDIAN:0)
Block(-5,79,-2,OBSIDIAN:0)
Block(-5,79,-1,OBSIDIAN:0)
Block(-5,79,0,OBSIDIAN:0)
Block(-5,79,1,OBSIDIAN:0)
Block(-5,79,2,OBSIDIAN:0)
Block(-5,79,3,OBSIDIAN:0)
Block(-5,79,4,OBSIDIAN:0)
Block(-5,79,5,OBSIDIAN:0)
Block(-5,79,6,OBSIDIAN:0)
Block(-5,79,7,OBSIDIAN:0)
Block(-5,79,8,OBSIDIAN:0)
Block(-5,80,-6,OBSIDIAN:0)
Block(-5,80,-5,OBSIDIAN:0)
Block(-5,80,-4,OBSIDIAN:0)
Block(-5,80,-3,OBSIDIAN:0)
Block(-5,80,-2,OBSIDIAN:0)
Block(-5,80,-1,OBSIDIAN:0)
Block(-5,80,0,OBSIDIAN:0)
Block(-5,80,1,OBSIDIAN:0)
Block(-5,80,2,OBSIDIAN:0)
Block(-5,80,3,OBSIDIAN:0)
Block(-5,80,4,OBSIDIAN:0)
Block(-5,80,5,OBSIDIAN:0)
Block(-5,80,6,OBSIDIAN:0)
Block(-5,80,7,OBSIDIAN:0)
Block(-5,80,8,OBSIDIAN:0)
Block(-5,81,-7,OBSIDIAN:0)
Block(-5,81,-6,OBSIDIAN:0)
Block(-5,81,-5,OBSIDIAN:0)
Block(-5,81,-4,OBSIDIAN:0)
Block(-5,81,-3,OBSIDIAN:0)
Block(-5,81,-2,OBSIDIAN:0)
Block(-5,81,-1,OBSIDIAN:0)
Block(-5,81,0,OBSIDIAN:0)
Block(-5,81,1,OBSIDIAN:0)
Block(-5,81,2,OBSIDIAN:0)
Block(-5,81,3,OBSIDIAN:0)
Block(-5,81,4,OBSIDIAN:0)
Block(-5,81,5,OBSIDIAN:0)
Block(-5,81,6,OBSIDIAN:0)
Block(-5,81,7,OBSIDIAN:0)
Block(-5,81,8,OBSIDIAN:0)
Block(-5,82,-7,OBSIDIAN:0)
Block(-5,82,-6,OBSIDIAN:0)
Block(-5,82,-5,OBSIDIAN:0)
Block(-5,82,-4,OBSIDIAN:0)
Block(-5,82,-3,OBSIDIAN:0)
Block(-5,82,-2,OBSIDIAN:0)
Block(-5,82,-1,OBSIDIAN:0)
Block(-5,82,0,OBSIDIAN:0)
Block(-5,82,1,OBSIDIAN:0)
Block(-5,82,2,OBSIDIAN:0)
Block(-5,82,3,OBSIDIAN:0)
Block(-5,82,4,OBSIDIAN:0)
Block(-5,82,5,OBSIDIAN:0)
Block(-5,82,6,OBSIDIAN:0)
Block(-5,82,7,OBSIDIAN:0)
Block(-5,82,8,OBSIDIAN:0)
Block(-5,83,-7,OBSIDIAN:0)
Block(-5,83,-6,OBSIDIAN:0)
Block(-5,83,-5,OBSIDIAN:0)
Block(-5,83,-4,OBSIDIAN:0)
Block(-5,83,-3,OBSIDIAN:0)
Block(-5,83,-2,OBSIDIAN:0)
Block(-5,83,-1,OBSIDIAN:0)
Block(-5,83,0,OBSIDIAN:0)
Block(-5,83,1,OBSIDIAN:0)
Block(-5,83,2,OBSIDIAN:0)
Block(-5,83,3,OBSIDIAN:0)
Block(-5,83,4,OBSIDIAN:0)
Block(-5,83,5,OBSIDIAN:0)
Block(-5,83,6,OBSIDIAN:0)
Block(-5,83,7,OBSIDIAN:0)
Block(-5,83,8,OBSIDIAN:0)
Block(-5,84,-7,OBSIDIAN:0)
Block(-5,84,-6,OBSIDIAN:0)
Block(-5,84,-5,OBSIDIAN:0)
Block(-5,84,-4,OBSIDIAN:0)
Block(-5,84,-3,OBSIDIAN:0)
Block(-5,84,-2,OBSIDIAN:0)
Block(-5,84,-1,OBSIDIAN:0)
Block(-5,84,0,OBSIDIAN:0)
Block(-5,84,1,OBSIDIAN:0)
Block(-5,84,2,OBSIDIAN:0)
Block(-5,84,3,OBSIDIAN:0)
Block(-5,84,4,OBSIDIAN:0)
Block(-5,84,5,OBSIDIAN:0)
Block(-5,84,6,OBSIDIAN:0)
Block(-5,84,7,OBSIDIAN:0)
Block(-5,84,8,OBSIDIAN:0)
Block(-5,85,-7,OBSIDIAN:0)
Block(-5,85,-6,OBSIDIAN:0)
Block(-5,85,-5,OBSIDIAN:0)
Block(-5,85,-4,OBSIDIAN:0)
Block(-5,85,-3,OBSIDIAN:0)
Block(-5,85,-2,OBSIDIAN:0)
Block(-5,85,-1,OBSIDIAN:0)
Block(-5,85,0,OBSIDIAN:0)
Block(-5,85,1,OBSIDIAN:0)
Block(-5,85,2,OBSIDIAN:0)
Block(-5,85,3,OBSIDIAN:0)
Block(-5,85,4,OBSIDIAN:0)
Block(-5,85,5,OBSIDIAN:0)
Block(-5,85,6,OBSIDIAN:0)
Block(-5,85,7,OBSIDIAN:0)
Block(-5,85,8,OBSIDIAN:0)
Block(-5,86,-7,OBSIDIAN:0)
Block(-5,86,-6,OBSIDIAN:0)
Block(-5,86,-5,OBSIDIAN:0)
Block(-5,86,-4,OBSIDIAN:0)
Block(-5,86,-3,OBSIDIAN:0)
Block(-5,86,-2,OBSIDIAN:0)
Block(-5,86,-1,OBSIDIAN:0)
Block(-5,86,0,OBSIDIAN:0)
Block(-5,86,1,OBSIDIAN:0)
Block(-5,86,2,OBSIDIAN:0)
Block(-5,86,3,OBSIDIAN:0)
Block(-5,86,4,OBSIDIAN:0)
Block(-5,86,5,OBSIDIAN:0)
Block(-5,86,6,OBSIDIAN:0)
Block(-5,86,7,OBSIDIAN:0)
Block(-5,86,8,OBSIDIAN:0)
Block(-5,87,-7,OBSIDIAN:0)
Block(-5,87,-6,OBSIDIAN:0)
Block(-5,87,-5,OBSIDIAN:0)
Block(-5,87,-4,OBSIDIAN:0)
Block(-5,87,-3,OBSIDIAN:0)
Block(-5,87,-2,OBSIDIAN:0)
Block(-5,87,-1,OBSIDIAN:0)
Block(-5,87,0,OBSIDIAN:0)
Block(-5,87,1,OBSIDIAN:0)
Block(-5,87,2,OBSIDIAN:0)
Block(-5,87,3,STONE:3)
Block(-5,87,4,OBSIDIAN:0)
Block(-5,87,5,OBSIDIAN:0)
Block(-5,87,6,STONE:5)
Block(-5,87,7,OBSIDIAN:0)
Block(-5,87,8,OBSIDIAN:0)
Block(-5,88,-7,OBSIDIAN:0)
Block(-5,88,-6,OBSIDIAN:0)
Block(-5,88,-5,OBSIDIAN:0)
Block(-5,88,-4,OBSIDIAN:0)
Block(-5,88,-3,OBSIDIAN:0)
Block(-5,88,-2,OBSIDIAN:0)
Block(-5,88,-1,OBSIDIAN:0)
Block(-5,88,0,OBSIDIAN:0)
Block(-5,88,1,STONE:3)
Block(-5,88,2,STONE:3)
Block(-5,88,3,STONE:5)
Block(-5,88,4,STONE:5)
Block(-5,88,5,STONE:5)
Block(-5,89,-7,OBSIDIAN:0)
Block(-5,89,-6,OBSIDIAN:0)
Block(-5,89,-5,OBSIDIAN:0)
Block(-5,89,-4,OBSIDIAN:0)
Block(-5,89,-3,OBSIDIAN:0)
Block(-5,89,-2,OBSIDIAN:0)
Block(-5,89,-1,OBSIDIAN:0)
Block(-5,89,0,STONE:3)
Block(-5,89,1,STONE:5)
Block(-5,89,2,STONE:5)
Block(-5,90,-7,STONE:3)
Block(-5,90,-6,STONE:3)
Block(-5,90,-5,STONE:3)
Block(-5,90,-4,STONE:3)
Block(-5,90,-3,STONE:3)
Block(-5,90,-2,STONE:3)
Block(-5,90,-1,STONE:3)
Block(-5,90,0,STONE:5)
Block(-5,91,-7,STONE:3)
Block(-5,91,-6,STONE:5)
Block(-5,91,-5,STONE:5)
Block(-5,91,-4,STONE:5)
Block(-5,91,-3,STONE:5)
Block(-5,91,-2,STONE:5)
Block(-5,91,-1,STONE:5)
Block(-5,92,-7,STONE:5)
Block(-4,14,0,STONE:3)
Block(-4,14,1,STONE:3)
Block(-4,14,2,STONE:3)
Block(-4,14,3,STONE:3)
Block(-4,14,4,OBSIDIAN:0)
Block(-4,14,5,OBSIDIAN:0)
Block(-4,14,6,MAGMA:0)
Block(-4,14,7,MAGMA:0)
Block(-4,14,8,MAGMA:0)
Block(-4,15,-7,STONE:3)
Block(-4,15,-6,STONE:3)
Block(-4,15,-5,STONE:3)
Block(-4,15,-4,STONE:3)
Block(-4,15,-3,STONE:3)
Block(-4,15,-2,STONE:3)
Block(-4,15,-1,STONE:3)
Block(-4,15,0,STONE:3)
Block(-4,15,1,STONE:3)
Block(-4,15,2,STONE:3)
Block(-4,15,3,STONE:3)
Block(-4,15,4,OBSIDIAN:0)
Block(-4,15,5,OBSIDIAN:0)
Block(-4,15,6,MAGMA:0)
Block(-4,15,7,MAGMA:0)
Block(-4,15,8,MAGMA:0)
Block(-4,16,-7,STONE:3)
Block(-4,16,-6,STONE:3)
Block(-4,16,-5,STONE:3)
Block(-4,16,-4,STONE:3)
Block(-4,16,-3,STONE:3)
Block(-4,16,-2,STONE:3)
Block(-4,16,-1,STONE:3)
Block(-4,16,0,STONE:3)
Block(-4,16,1,STONE:3)
Block(-4,16,2,STONE:3)
Block(-4,16,3,STONE:3)
Block(-4,16,4,OBSIDIAN:0)
Block(-4,16,5,OBSIDIAN:0)
Block(-4,16,6,OBSIDIAN:0)
Block(-4,16,7,MAGMA:0)
Block(-4,16,8,MAGMA:0)
Block(-4,17,-7,STONE:3)
Block(-4,17,-6,STONE:3)
Block(-4,17,-5,STONE:3)
Block(-4,17,-4,STONE:3)
Block(-4,17,-3,STONE:3)
Block(-4,17,-2,STONE:3)
Block(-4,17,-1,STONE:3)
Block(-4,17,0,STONE:3)
Block(-4,17,1,STONE:3)
Block(-4,17,2,STONE:3)
Block(-4,17,3,STONE:3)
Block(-4,17,4,OBSIDIAN:0)
Block(-4,17,5,OBSIDIAN:0)
Block(-4,17,6,OBSIDIAN:0)
Block(-4,17,7,OBSIDIAN:0)
Block(-4,17,8,MAGMA:0)
Block(-4,18,-7,STONE:3)
Block(-4,18,-6,STONE:3)
Block(-4,18,-5,STONE:3)
Block(-4,18,-4,STONE:3)
Block(-4,18,-3,STONE:3)
Block(-4,18,-2,STONE:3)
Block(-4,18,-1,STONE:3)
Block(-4,18,0,STONE:3)
Block(-4,18,1,STONE:3)
Block(-4,18,2,STONE:3)
Block(-4,18,3,STONE:3)
Block(-4,18,4,STONE:3)
Block(-4,18,5,OBSIDIAN:0)
Block(-4,18,6,OBSIDIAN:0)
Block(-4,18,7,OBSIDIAN:0)
Block(-4,18,8,OBSIDIAN:0)
Block(-4,19,-7,STONE:3)
Block(-4,19,-6,STONE:3)
Block(-4,19,-5,STONE:3)
Block(-4,19,-4,STONE:3)
Block(-4,19,-3,OBSIDIAN:0)
Block(-4,19,-2,OBSIDIAN:0)
Block(-4,19,-1,STONE:3)
Block(-4,19,0,STONE:3)
Block(-4,19,1,STONE:3)
Block(-4,19,2,STONE:3)
Block(-4,19,3,STONE:3)
Block(-4,19,4,STONE:3)
Block(-4,19,5,OBSIDIAN:0)
Block(-4,19,6,OBSIDIAN:0)
Block(-4,19,7,OBSIDIAN:0)
Block(-4,19,8,OBSIDIAN:0)
Block(-4,20,-7,STONE:3)
Block(-4,20,-6,STONE:3)
Block(-4,20,-5,OBSIDIAN:0)
Block(-4,20,-4,OBSIDIAN:0)
Block(-4,20,-3,OBSIDIAN:0)
Block(-4,20,-2,OBSIDIAN:0)
Block(-4,20,-1,OBSIDIAN:0)
Block(-4,20,0,OBSIDIAN:0)
Block(-4,20,1,OBSIDIAN:0)
Block(-4,20,2,OBSIDIAN:0)
Block(-4,20,3,OBSIDIAN:0)
Block(-4,20,4,OBSIDIAN:0)
Block(-4,20,5,OBSIDIAN:0)
Block(-4,20,6,OBSIDIAN:0)
Block(-4,20,7,OBSIDIAN:0)
Block(-4,20,8,OBSIDIAN:0)
Block(-4,21,-7,STONE:3)
Block(-4,21,-6,STONE:3)
Block(-4,21,-5,OBSIDIAN:0)
Block(-4,21,-4,OBSIDIAN:0)
Block(-4,21,-3,OBSIDIAN:0)
Block(-4,21,-2,OBSIDIAN:0)
Block(-4,21,-1,OBSIDIAN:0)
Block(-4,21,0,OBSIDIAN:0)
Block(-4,21,1,OBSIDIAN:0)
Block(-4,21,2,OBSIDIAN:0)
Block(-4,21,3,OBSIDIAN:0)
Block(-4,21,4,OBSIDIAN:0)
Block(-4,21,5,OBSIDIAN:0)
Block(-4,21,6,OBSIDIAN:0)
Block(-4,21,7,OBSIDIAN:0)
Block(-4,21,8,OBSIDIAN:0)
Block(-4,22,-7,STONE:3)
Block(-4,22,-6,OBSIDIAN:0)
Block(-4,22,-5,OBSIDIAN:0)
Block(-4,22,-4,OBSIDIAN:0)
Block(-4,22,-3,OBSIDIAN:0)
Block(-4,22,-2,OBSIDIAN:0)
Block(-4,22,-1,OBSIDIAN:0)
Block(-4,22,0,OBSIDIAN:0)
Block(-4,22,1,OBSIDIAN:0)
Block(-4,22,2,OBSIDIAN:0)
Block(-4,22,3,OBSIDIAN:0)
Block(-4,22,4,OBSIDIAN:0)
Block(-4,22,5,OBSIDIAN:0)
Block(-4,22,6,OBSIDIAN:0)
Block(-4,22,7,OBSIDIAN:0)
Block(-4,22,8,OBSIDIAN:0)
Block(-4,23,-7,OBSIDIAN:0)
Block(-4,23,-6,OBSIDIAN:0)
Block(-4,23,-5,OBSIDIAN:0)
Block(-4,23,-4,OBSIDIAN:0)
Block(-4,23,-3,OBSIDIAN:0)
Block(-4,23,-2,OBSIDIAN:0)
Block(-4,23,-1,OBSIDIAN:0)
Block(-4,23,0,OBSIDIAN:0)
Block(-4,23,1,OBSIDIAN:0)
Block(-4,23,2,OBSIDIAN:0)
Block(-4,23,3,OBSIDIAN:0)
Block(-4,23,4,OBSIDIAN:0)
Block(-4,23,5,OBSIDIAN:0)
Block(-4,23,6,OBSIDIAN:0)
Block(-4,23,7,OBSIDIAN:0)
Block(-4,23,8,OBSIDIAN:0)
Block(-4,24,-7,OBSIDIAN:0)
Block(-4,24,-6,OBSIDIAN:0)
Block(-4,24,-5,OBSIDIAN:0)
Block(-4,24,-4,OBSIDIAN:0)
Block(-4,24,-3,OBSIDIAN:0)
Block(-4,24,-2,OBSIDIAN:0)
Block(-4,24,-1,OBSIDIAN:0)
Block(-4,24,0,OBSIDIAN:0)
Block(-4,24,1,OBSIDIAN:0)
Block(-4,24,2,OBSIDIAN:0)
Block(-4,24,3,OBSIDIAN:0)
Block(-4,24,4,OBSIDIAN:0)
Block(-4,24,5,OBSIDIAN:0)
Block(-4,24,6,OBSIDIAN:0)
Block(-4,24,7,OBSIDIAN:0)
Block(-4,24,8,OBSIDIAN:0)
Block(-4,25,-7,OBSIDIAN:0)
Block(-4,25,-6,OBSIDIAN:0)
Block(-4,25,-5,OBSIDIAN:0)
Block(-4,25,-4,OBSIDIAN:0)
Block(-4,25,-3,OBSIDIAN:0)
Block(-4,25,-2,OBSIDIAN:0)
Block(-4,25,-1,OBSIDIAN:0)
Block(-4,25,0,OBSIDIAN:0)
Block(-4,25,1,OBSIDIAN:0)
Block(-4,25,2,OBSIDIAN:0)
Block(-4,25,3,OBSIDIAN:0)
Block(-4,25,4,OBSIDIAN:0)
Block(-4,25,5,OBSIDIAN:0)
Block(-4,25,6,OBSIDIAN:0)
Block(-4,25,7,OBSIDIAN:0)
Block(-4,25,8,OBSIDIAN:0)
Block(-4,26,-7,OBSIDIAN:0)
Block(-4,26,-6,OBSIDIAN:0)
Block(-4,26,-5,OBSIDIAN:0)
Block(-4,26,-4,OBSIDIAN:0)
Block(-4,26,-3,OBSIDIAN:0)
Block(-4,26,-2,OBSIDIAN:0)
Block(-4,26,-1,OBSIDIAN:0)
Block(-4,26,0,OBSIDIAN:0)
Block(-4,26,1,OBSIDIAN:0)
Block(-4,26,2,OBSIDIAN:0)
Block(-4,26,3,OBSIDIAN:0)
Block(-4,26,4,OBSIDIAN:0)
Block(-4,26,5,OBSIDIAN:0)
Block(-4,26,6,OBSIDIAN:0)
Block(-4,26,7,OBSIDIAN:0)
Block(-4,26,8,OBSIDIAN:0)
Block(-4,27,-7,OBSIDIAN:0)
Block(-4,27,-6,OBSIDIAN:0)
Block(-4,27,-5,OBSIDIAN:0)
Block(-4,27,-4,OBSIDIAN:0)
Block(-4,27,-3,OBSIDIAN:0)
Block(-4,27,-2,OBSIDIAN:0)
Block(-4,27,-1,OBSIDIAN:0)
Block(-4,27,0,OBSIDIAN:0)
Block(-4,27,1,OBSIDIAN:0)
Block(-4,27,2,OBSIDIAN:0)
Block(-4,27,3,OBSIDIAN:0)
Block(-4,27,4,OBSIDIAN:0)
Block(-4,27,5,OBSIDIAN:0)
Block(-4,27,6,OBSIDIAN:0)
Block(-4,27,7,OBSIDIAN:0)
Block(-4,27,8,OBSIDIAN:0)
Block(-4,28,-7,OBSIDIAN:0)
Block(-4,28,-6,OBSIDIAN:0)
Block(-4,28,-5,OBSIDIAN:0)
Block(-4,28,-4,OBSIDIAN:0)
Block(-4,28,-3,OBSIDIAN:0)
Block(-4,28,-2,OBSIDIAN:0)
Block(-4,28,-1,OBSIDIAN:0)
Block(-4,28,0,OBSIDIAN:0)
Block(-4,28,1,OBSIDIAN:0)
Block(-4,28,2,OBSIDIAN:0)
Block(-4,28,3,OBSIDIAN:0)
Block(-4,28,4,OBSIDIAN:0)
Block(-4,28,5,OBSIDIAN:0)
Block(-4,28,6,OBSIDIAN:0)
Block(-4,28,7,OBSIDIAN:0)
Block(-4,28,8,OBSIDIAN:0)
Block(-4,29,-7,OBSIDIAN:0)
Block(-4,29,-6,OBSIDIAN:0)
Block(-4,29,-5,OBSIDIAN:0)
Block(-4,29,-4,OBSIDIAN:0)
Block(-4,29,-3,OBSIDIAN:0)
Block(-4,29,-2,OBSIDIAN:0)
Block(-4,29,-1,OBSIDIAN:0)
Block(-4,29,0,OBSIDIAN:0)
Block(-4,29,1,OBSIDIAN:0)
Block(-4,29,2,OBSIDIAN:0)
Block(-4,29,3,OBSIDIAN:0)
Block(-4,29,4,OBSIDIAN:0)
Block(-4,29,5,OBSIDIAN:0)
Block(-4,29,6,OBSIDIAN:0)
Block(-4,29,7,OBSIDIAN:0)
Block(-4,29,8,OBSIDIAN:0)
Block(-4,30,-7,OBSIDIAN:0)
Block(-4,30,-6,OBSIDIAN:0)
Block(-4,30,-5,OBSIDIAN:0)
Block(-4,30,-4,OBSIDIAN:0)
Block(-4,30,-3,OBSIDIAN:0)
Block(-4,30,-2,OBSIDIAN:0)
Block(-4,30,-1,OBSIDIAN:0)
Block(-4,30,0,OBSIDIAN:0)
Block(-4,30,1,OBSIDIAN:0)
Block(-4,30,2,OBSIDIAN:0)
Block(-4,30,3,OBSIDIAN:0)
Block(-4,30,4,OBSIDIAN:0)
Block(-4,30,5,OBSIDIAN:0)
Block(-4,30,6,OBSIDIAN:0)
Block(-4,30,7,OBSIDIAN:0)
Block(-4,30,8,OBSIDIAN:0)
Block(-4,31,-7,OBSIDIAN:0)
Block(-4,31,-6,OBSIDIAN:0)
Block(-4,31,-5,OBSIDIAN:0)
Block(-4,31,-4,OBSIDIAN:0)
Block(-4,31,-3,OBSIDIAN:0)
Block(-4,31,-2,OBSIDIAN:0)
Block(-4,31,-1,OBSIDIAN:0)
Block(-4,31,0,OBSIDIAN:0)
Block(-4,31,1,OBSIDIAN:0)
Block(-4,31,2,OBSIDIAN:0)
Block(-4,31,3,OBSIDIAN:0)
Block(-4,31,4,OBSIDIAN:0)
Block(-4,31,5,OBSIDIAN:0)
Block(-4,31,6,OBSIDIAN:0)
Block(-4,31,7,OBSIDIAN:0)
Block(-4,31,8,OBSIDIAN:0)
Block(-4,32,-7,OBSIDIAN:0)
Block(-4,32,-6,OBSIDIAN:0)
Block(-4,32,-5,OBSIDIAN:0)
Block(-4,32,-4,OBSIDIAN:0)
Block(-4,32,-3,OBSIDIAN:0)
Block(-4,32,-2,OBSIDIAN:0)
Block(-4,32,-1,OBSIDIAN:0)
Block(-4,32,0,OBSIDIAN:0)
Block(-4,32,1,OBSIDIAN:0)
Block(-4,32,2,OBSIDIAN:0)
Block(-4,32,3,OBSIDIAN:0)
Block(-4,32,4,OBSIDIAN:0)
Block(-4,32,5,OBSIDIAN:0)
Block(-4,32,6,OBSIDIAN:0)
Block(-4,32,7,OBSIDIAN:0)
Block(-4,32,8,OBSIDIAN:0)
Block(-4,33,-7,OBSIDIAN:0)
Block(-4,33,-6,OBSIDIAN:0)
Block(-4,33,-5,OBSIDIAN:0)
Block(-4,33,-4,OBSIDIAN:0)
Block(-4,33,-3,OBSIDIAN:0)
Block(-4,33,-2,OBSIDIAN:0)
Block(-4,33,-1,OBSIDIAN:0)
Block(-4,33,0,OBSIDIAN:0)
Block(-4,33,1,OBSIDIAN:0)
Block(-4,33,2,OBSIDIAN:0)
Block(-4,33,3,OBSIDIAN:0)
Block(-4,33,4,OBSIDIAN:0)
Block(-4,33,5,OBSIDIAN:0)
Block(-4,33,6,OBSIDIAN:0)
Block(-4,33,7,OBSIDIAN:0)
Block(-4,33,8,OBSIDIAN:0)
Block(-4,34,-7,OBSIDIAN:0)
Block(-4,34,-6,OBSIDIAN:0)
Block(-4,34,-5,OBSIDIAN:0)
Block(-4,34,-4,OBSIDIAN:0)
Block(-4,34,-3,OBSIDIAN:0)
Block(-4,34,-2,OBSIDIAN:0)
Block(-4,34,-1,OBSIDIAN:0)
Block(-4,34,0,OBSIDIAN:0)
Block(-4,34,1,OBSIDIAN:0)
Block(-4,34,2,OBSIDIAN:0)
Block(-4,34,3,OBSIDIAN:0)
Block(-4,34,4,OBSIDIAN:0)
Block(-4,34,5,OBSIDIAN:0)
Block(-4,34,6,OBSIDIAN:0)
Block(-4,34,7,OBSIDIAN:0)
Block(-4,34,8,OBSIDIAN:0)
Block(-4,35,-7,OBSIDIAN:0)
Block(-4,35,-6,OBSIDIAN:0)
Block(-4,35,-5,OBSIDIAN:0)
Block(-4,35,-4,OBSIDIAN:0)
Block(-4,35,-3,OBSIDIAN:0)
Block(-4,35,-2,OBSIDIAN:0)
Block(-4,35,-1,OBSIDIAN:0)
Block(-4,35,0,OBSIDIAN:0)
Block(-4,35,1,OBSIDIAN:0)
Block(-4,35,2,OBSIDIAN:0)
Block(-4,35,3,OBSIDIAN:0)
Block(-4,35,4,OBSIDIAN:0)
Block(-4,35,5,OBSIDIAN:0)
Block(-4,35,6,OBSIDIAN:0)
Block(-4,35,7,OBSIDIAN:0)
Block(-4,35,8,OBSIDIAN:0)
Block(-4,36,-7,OBSIDIAN:0)
Block(-4,36,-6,OBSIDIAN:0)
Block(-4,36,-5,OBSIDIAN:0)
Block(-4,36,-4,OBSIDIAN:0)
Block(-4,36,-3,OBSIDIAN:0)
Block(-4,36,-2,OBSIDIAN:0)
Block(-4,36,-1,OBSIDIAN:0)
Block(-4,36,0,OBSIDIAN:0)
Block(-4,36,1,OBSIDIAN:0)
Block(-4,36,2,OBSIDIAN:0)
Block(-4,36,3,STONE:5)
Block(-4,36,4,STONE:5)
Block(-4,36,5,STONE:5)
Block(-4,36,6,OBSIDIAN:0)
Block(-4,36,7,OBSIDIAN:0)
Block(-4,36,8,OBSIDIAN:0)
Block(-4,37,-7,OBSIDIAN:0)
Block(-4,37,-6,OBSIDIAN:0)
Block(-4,37,-5,OBSIDIAN:0)
Block(-4,37,-4,OBSIDIAN:0)
Block(-4,37,-3,OBSIDIAN:0)
Block(-4,37,-2,OBSIDIAN:0)
Block(-4,37,-1,OBSIDIAN:0)
Block(-4,37,0,STONE:5)
Block(-4,37,1,STONE:3)
Block(-4,37,2,STONE:3)
Block(-4,37,3,STONE:3)
Block(-4,37,4,STONE:5)
Block(-4,37,5,STONE:5)
Block(-4,37,6,STONE:5)
Block(-4,37,7,STONE:5)
Block(-4,37,8,STONE:5)
Block(-4,38,-7,OBSIDIAN:0)
Block(-4,38,-6,OBSIDIAN:0)
Block(-4,38,-5,OBSIDIAN:0)
Block(-4,38,-4,STONE:5)
Block(-4,38,-3,STONE:5)
Block(-4,38,-2,STONE:5)
Block(-4,38,-1,STONE:5)
Block(-4,38,0,STONE:3)
Block(-4,38,1,STONE:3)
Block(-4,38,2,STONE:3)
Block(-4,38,3,STONE:3)
Block(-4,38,4,STONE:3)
Block(-4,38,5,STONE:5)
Block(-4,38,6,STONE:5)
Block(-4,38,7,STONE:5)
Block(-4,38,8,STONE:5)
Block(-4,39,-7,OBSIDIAN:0)
Block(-4,39,-6,OBSIDIAN:0)
Block(-4,39,-5,STONE:5)
Block(-4,39,-4,STONE:5)
Block(-4,39,-3,STONE:5)
Block(-4,39,-2,STONE:5)
Block(-4,39,-1,STONE:5)
Block(-4,39,0,STONE:3)
Block(-4,39,1,STONE:3)
Block(-4,39,2,STONE:3)
Block(-4,39,3,STONE:3)
Block(-4,39,5,STONE:5)
Block(-4,39,6,STONE:5)
Block(-4,39,7,STONE:5)
Block(-4,39,8,STONE:5)
Block(-4,40,-7,OBSIDIAN:0)
Block(-4,40,-6,OBSIDIAN:0)
Block(-4,40,-5,STONE:5)
Block(-4,40,-4,STONE:5)
Block(-4,40,-3,STONE:5)
Block(-4,40,-2,STONE:5)
Block(-4,40,-1,STONE:5)
Block(-4,41,-7,GRASS:0)
Block(-4,41,-6,GRASS:0)
Block(-4,41,-5,GRASS:0)
Block(-4,41,-4,GRASS:0)
Block(-4,74,4,OBSIDIAN:0)
Block(-4,74,5,OBSIDIAN:0)
Block(-4,74,6,OBSIDIAN:0)
Block(-4,74,7,OBSIDIAN:0)
Block(-4,74,8,OBSIDIAN:0)
Block(-4,75,2,OBSIDIAN:0)
Block(-4,75,3,OBSIDIAN:0)
Block(-4,75,4,OBSIDIAN:0)
Block(-4,75,5,OBSIDIAN:0)
Block(-4,75,6,OBSIDIAN:0)
Block(-4,75,7,OBSIDIAN:0)
Block(-4,75,8,OBSIDIAN:0)
Block(-4,76,-2,OBSIDIAN:0)
Block(-4,76,-1,OBSIDIAN:0)
Block(-4,76,0,OBSIDIAN:0)
Block(-4,76,1,OBSIDIAN:0)
Block(-4,76,2,OBSIDIAN:0)
Block(-4,76,3,OBSIDIAN:0)
Block(-4,76,4,OBSIDIAN:0)
Block(-4,76,5,OBSIDIAN:0)
Block(-4,76,6,OBSIDIAN:0)
Block(-4,76,7,OBSIDIAN:0)
Block(-4,76,8,OBSIDIAN:0)
Block(-4,77,-4,OBSIDIAN:0)
Block(-4,77,-3,OBSIDIAN:0)
Block(-4,77,-2,OBSIDIAN:0)
Block(-4,77,-1,OBSIDIAN:0)
Block(-4,77,0,OBSIDIAN:0)
Block(-4,77,1,OBSIDIAN:0)
Block(-4,77,2,OBSIDIAN:0)
Block(-4,77,3,OBSIDIAN:0)
Block(-4,77,4,OBSIDIAN:0)
Block(-4,77,5,OBSIDIAN:0)
Block(-4,77,6,OBSIDIAN:0)
Block(-4,77,7,OBSIDIAN:0)
Block(-4,77,8,OBSIDIAN:0)
Block(-4,78,-5,OBSIDIAN:0)
Block(-4,78,-4,OBSIDIAN:0)
Block(-4,78,-3,OBSIDIAN:0)
Block(-4,78,-2,OBSIDIAN:0)
Block(-4,78,-1,OBSIDIAN:0)
Block(-4,78,0,OBSIDIAN:0)
Block(-4,78,1,OBSIDIAN:0)
Block(-4,78,2,OBSIDIAN:0)
Block(-4,78,3,OBSIDIAN:0)
Block(-4,78,4,OBSIDIAN:0)
Block(-4,78,5,OBSIDIAN:0)
Block(-4,78,6,OBSIDIAN:0)
Block(-4,78,7,OBSIDIAN:0)
Block(-4,78,8,OBSIDIAN:0)
Block(-4,79,-6,OBSIDIAN:0)
Block(-4,79,-5,OBSIDIAN:0)
Block(-4,79,-4,OBSIDIAN:0)
Block(-4,79,-3,OBSIDIAN:0)
Block(-4,79,-2,OBSIDIAN:0)
Block(-4,79,-1,OBSIDIAN:0)
Block(-4,79,0,OBSIDIAN:0)
Block(-4,79,1,OBSIDIAN:0)
Block(-4,79,2,OBSIDIAN:0)
Block(-4,79,3,OBSIDIAN:0)
Block(-4,79,4,OBSIDIAN:0)
Block(-4,79,5,OBSIDIAN:0)
Block(-4,79,6,OBSIDIAN:0)
Block(-4,79,7,OBSIDIAN:0)
Block(-4,79,8,OBSIDIAN:0)
Block(-4,80,-6,OBSIDIAN:0)
Block(-4,80,-5,OBSIDIAN:0)
Block(-4,80,-4,OBSIDIAN:0)
Block(-4,80,-3,OBSIDIAN:0)
Block(-4,80,-2,OBSIDIAN:0)
Block(-4,80,-1,OBSIDIAN:0)
Block(-4,80,0,OBSIDIAN:0)
Block(-4,80,1,OBSIDIAN:0)
Block(-4,80,2,OBSIDIAN:0)
Block(-4,80,3,OBSIDIAN:0)
Block(-4,80,4,OBSIDIAN:0)
Block(-4,80,5,OBSIDIAN:0)
Block(-4,80,6,OBSIDIAN:0)
Block(-4,80,7,OBSIDIAN:0)
Block(-4,80,8,OBSIDIAN:0)
Block(-4,81,-7,OBSIDIAN:0)
Block(-4,81,-6,OBSIDIAN:0)
Block(-4,81,-5,OBSIDIAN:0)
Block(-4,81,-4,OBSIDIAN:0)
Block(-4,81,-3,OBSIDIAN:0)
Block(-4,81,-2,OBSIDIAN:0)
Block(-4,81,-1,OBSIDIAN:0)
Block(-4,81,0,OBSIDIAN:0)
Block(-4,81,1,OBSIDIAN:0)
Block(-4,81,2,OBSIDIAN:0)
Block(-4,81,3,OBSIDIAN:0)
Block(-4,81,4,OBSIDIAN:0)
Block(-4,81,5,OBSIDIAN:0)
Block(-4,81,6,OBSIDIAN:0)
Block(-4,81,7,OBSIDIAN:0)
Block(-4,81,8,OBSIDIAN:0)
Block(-4,82,-7,OBSIDIAN:0)
Block(-4,82,-6,OBSIDIAN:0)
Block(-4,82,-5,OBSIDIAN:0)
Block(-4,82,-4,OBSIDIAN:0)
Block(-4,82,-3,OBSIDIAN:0)
Block(-4,82,-2,OBSIDIAN:0)
Block(-4,82,-1,OBSIDIAN:0)
Block(-4,82,0,OBSIDIAN:0)
Block(-4,82,1,OBSIDIAN:0)
Block(-4,82,2,OBSIDIAN:0)
Block(-4,82,3,OBSIDIAN:0)
Block(-4,82,4,OBSIDIAN:0)
Block(-4,82,5,OBSIDIAN:0)
Block(-4,82,6,OBSIDIAN:0)
Block(-4,82,7,OBSIDIAN:0)
Block(-4,82,8,OBSIDIAN:0)
Block(-4,83,-7,OBSIDIAN:0)
Block(-4,83,-6,OBSIDIAN:0)
Block(-4,83,-5,OBSIDIAN:0)
Block(-4,83,-4,OBSIDIAN:0)
Block(-4,83,-3,OBSIDIAN:0)
Block(-4,83,-2,OBSIDIAN:0)
Block(-4,83,-1,OBSIDIAN:0)
Block(-4,83,0,OBSIDIAN:0)
Block(-4,83,1,OBSIDIAN:0)
Block(-4,83,2,OBSIDIAN:0)
Block(-4,83,3,OBSIDIAN:0)
Block(-4,83,4,OBSIDIAN:0)
Block(-4,83,5,OBSIDIAN:0)
Block(-4,83,6,OBSIDIAN:0)
Block(-4,83,7,OBSIDIAN:0)
Block(-4,83,8,OBSIDIAN:0)
Block(-4,84,-7,OBSIDIAN:0)
Block(-4,84,-6,OBSIDIAN:0)
Block(-4,84,-5,OBSIDIAN:0)
Block(-4,84,-4,OBSIDIAN:0)
Block(-4,84,-3,OBSIDIAN:0)
Block(-4,84,-2,OBSIDIAN:0)
Block(-4,84,-1,OBSIDIAN:0)
Block(-4,84,0,OBSIDIAN:0)
Block(-4,84,1,OBSIDIAN:0)
Block(-4,84,2,OBSIDIAN:0)
Block(-4,84,3,OBSIDIAN:0)
Block(-4,84,4,OBSIDIAN:0)
Block(-4,84,5,OBSIDIAN:0)
Block(-4,84,6,OBSIDIAN:0)
Block(-4,84,7,OBSIDIAN:0)
Block(-4,84,8,OBSIDIAN:0)
Block(-4,85,-7,OBSIDIAN:0)
Block(-4,85,-6,OBSIDIAN:0)
Block(-4,85,-5,OBSIDIAN:0)
Block(-4,85,-4,OBSIDIAN:0)
Block(-4,85,-3,OBSIDIAN:0)
Block(-4,85,-2,OBSIDIAN:0)
Block(-4,85,-1,OBSIDIAN:0)
Block(-4,85,0,OBSIDIAN:0)
Block(-4,85,1,OBSIDIAN:0)
Block(-4,85,2,OBSIDIAN:0)
Block(-4,85,3,OBSIDIAN:0)
Block(-4,85,4,OBSIDIAN:0)
Block(-4,85,5,OBSIDIAN:0)
Block(-4,85,6,OBSIDIAN:0)
Block(-4,85,7,OBSIDIAN:0)
Block(-4,85,8,OBSIDIAN:0)
Block(-4,86,-7,OBSIDIAN:0)
Block(-4,86,-6,OBSIDIAN:0)
Block(-4,86,-5,OBSIDIAN:0)
Block(-4,86,-4,OBSIDIAN:0)
Block(-4,86,-3,OBSIDIAN:0)
Block(-4,86,-2,OBSIDIAN:0)
Block(-4,86,-1,OBSIDIAN:0)
Block(-4,86,0,OBSIDIAN:0)
Block(-4,86,1,OBSIDIAN:0)
Block(-4,86,2,OBSIDIAN:0)
Block(-4,86,3,OBSIDIAN:0)
Block(-4,86,4,OBSIDIAN:0)
Block(-4,86,5,OBSIDIAN:0)
Block(-4,86,6,OBSIDIAN:0)
Block(-4,86,8,OBSIDIAN:0)
Block(-4,87,-7,OBSIDIAN:0)
Block(-4,87,-6,OBSIDIAN:0)
Block(-4,87,-5,OBSIDIAN:0)
Block(-4,87,-4,OBSIDIAN:0)
Block(-4,87,-3,OBSIDIAN:0)
Block(-4,87,-2,OBSIDIAN:0)
Block(-4,87,-1,OBSIDIAN:0)
Block(-4,87,0,OBSIDIAN:0)
Block(-4,87,1,OBSIDIAN:0)
Block(-4,87,2,OBSIDIAN:0)
Block(-4,87,3,OBSIDIAN:0)
Block(-4,87,4,OBSIDIAN:0)
Block(-4,87,5,OBSIDIAN:0)
Block(-4,88,-7,OBSIDIAN:0)
Block(-4,88,-6,OBSIDIAN:0)
Block(-4,88,-5,OBSIDIAN:0)
Block(-4,88,-4,OBSIDIAN:0)
Block(-4,88,-3,OBSIDIAN:0)
Block(-4,88,-2,OBSIDIAN:0)
Block(-4,88,-1,OBSIDIAN:0)
Block(-4,88,0,OBSIDIAN:0)
Block(-4,88,1,OBSIDIAN:0)
Block(-4,88,2,OBSIDIAN:0)
Block(-4,88,3,OBSIDIAN:0)
Block(-4,88,4,STONE:5)
Block(-4,89,-7,STONE:3)
Block(-4,89,-6,STONE:3)
Block(-4,89,-5,STONE:3)
Block(-4,89,-4,OBSIDIAN:0)
Block(-4,89,-3,OBSIDIAN:0)
Block(-4,89,-2,OBSIDIAN:0)
Block(-4,89,-1,OBSIDIAN:0)
Block(-4,89,0,OBSIDIAN:0)
Block(-4,89,1,STONE:3)
Block(-4,89,2,STONE:3)
Block(-4,89,3,STONE:5)
Block(-4,90,-7,STONE:3)
Block(-4,90,-6,STONE:3)
Block(-4,90,-5,STONE:3)
Block(-4,90,-4,STONE:3)
Block(-4,90,-3,STONE:3)
Block(-4,90,-2,STONE:3)
Block(-4,90,-1,STONE:3)
Block(-4,90,0,STONE:3)
Block(-4,90,1,STONE:5)
Block(-4,90,2,STONE:5)
Block(-4,91,-7,STONE:3)
Block(-4,91,-6,STONE:3)
Block(-4,91,-5,STONE:5)
Block(-4,91,-4,STONE:5)
Block(-4,91,-3,STONE:5)
Block(-4,91,-2,STONE:5)
Block(-4,91,-1,STONE:5)
Block(-4,91,0,STONE:5)
Block(-4,92,-7,STONE:5)
Block(-4,92,-6,STONE:5)
Block(-3,14,1,STONE:3)
Block(-3,14,2,STONE:3)
Block(-3,14,3,OBSIDIAN:0)
Block(-3,14,4,OBSIDIAN:0)
Block(-3,14,5,OBSIDIAN:0)
Block(-3,14,6,MAGMA:0)
Block(-3,14,7,MAGMA:0)
Block(-3,14,8,MAGMA:0)
Block(-3,15,-7,STONE:3)
Block(-3,15,-6,STONE:3)
Block(-3,15,-5,STONE:3)
Block(-3,15,-4,STONE:3)
Block(-3,15,-3,STONE:3)
Block(-3,15,-2,STONE:3)
Block(-3,15,-1,STONE:3)
Block(-3,15,0,STONE:3)
Block(-3,15,1,STONE:3)
Block(-3,15,2,STONE:3)
Block(-3,15,3,OBSIDIAN:0)
Block(-3,15,4,OBSIDIAN:0)
Block(-3,15,5,OBSIDIAN:0)
Block(-3,15,6,MAGMA:0)
Block(-3,15,7,MAGMA:0)
Block(-3,15,8,MAGMA:0)
Block(-3,16,-7,STONE:3)
Block(-3,16,-6,STONE:3)
Block(-3,16,-5,STONE:3)
Block(-3,16,-4,STONE:3)
Block(-3,16,-3,STONE:3)
Block(-3,16,-2,STONE:3)
Block(-3,16,-1,STONE:3)
Block(-3,16,0,STONE:3)
Block(-3,16,1,STONE:3)
Block(-3,16,2,STONE:3)
Block(-3,16,3,OBSIDIAN:0)
Block(-3,16,4,OBSIDIAN:0)
Block(-3,16,5,OBSIDIAN:0)
Block(-3,16,6,OBSIDIAN:0)
Block(-3,16,7,MAGMA:0)
Block(-3,16,8,MAGMA:0)
Block(-3,17,-7,STONE:3)
Block(-3,17,-6,STONE:3)
Block(-3,17,-5,STONE:3)
Block(-3,17,-4,STONE:3)
Block(-3,17,-3,STONE:3)
Block(-3,17,-2,STONE:3)
Block(-3,17,-1,STONE:3)
Block(-3,17,0,STONE:3)
Block(-3,17,1,STONE:3)
Block(-3,17,2,STONE:3)
Block(-3,17,3,STONE:3)
Block(-3,17,4,OBSIDIAN:0)
Block(-3,17,5,OBSIDIAN:0)
Block(-3,17,6,OBSIDIAN:0)
Block(-3,17,7,MAGMA:0)
Block(-3,17,8,MAGMA:0)
Block(-3,18,-7,STONE:3)
Block(-3,18,-6,STONE:3)
Block(-3,18,-5,STONE:3)
Block(-3,18,-4,STONE:3)
Block(-3,18,-3,STONE:3)
Block(-3,18,-2,STONE:3)
Block(-3,18,-1,STONE:3)
Block(-3,18,0,STONE:3)
Block(-3,18,1,STONE:3)
Block(-3,18,2,STONE:3)
Block(-3,18,3,STONE:3)
Block(-3,18,4,OBSIDIAN:0)
Block(-3,18,5,OBSIDIAN:0)
Block(-3,18,6,OBSIDIAN:0)
Block(-3,18,7,OBSIDIAN:0)
Block(-3,18,8,MAGMA:0)
Block(-3,19,-7,STONE:3)
Block(-3,19,-6,STONE:3)
Block(-3,19,-5,OBSIDIAN:0)
Block(-3,19,-4,OBSIDIAN:0)
Block(-3,19,-3,OBSIDIAN:0)
Block(-3,19,-2,STONE:3)
Block(-3,19,-1,STONE:3)
Block(-3,19,0,STONE:3)
Block(-3,19,1,STONE:3)
Block(-3,19,2,STONE:3)
Block(-3,19,3,STONE:3)
Block(-3,19,4,STONE:3)
Block(-3,19,5,OBSIDIAN:0)
Block(-3,19,6,OBSIDIAN:0)
Block(-3,19,7,OBSIDIAN:0)
Block(-3,19,8,OBSIDIAN:0)
Block(-3,20,-7,STONE:3)
Block(-3,20,-6,STONE:3)
Block(-3,20,-5,OBSIDIAN:0)
Block(-3,20,-4,OBSIDIAN:0)
Block(-3,20,-3,OBSIDIAN:0)
Block(-3,20,-2,OBSIDIAN:0)
Block(-3,20,-1,OBSIDIAN:0)
Block(-3,20,0,STONE:3)
Block(-3,20,1,STONE:3)
Block(-3,20,2,STONE:3)
Block(-3,20,3,OBSIDIAN:0)
Block(-3,20,4,OBSIDIAN:0)
Block(-3,20,5,OBSIDIAN:0)
Block(-3,20,6,OBSIDIAN:0)
Block(-3,20,7,OBSIDIAN:0)
Block(-3,20,8,OBSIDIAN:0)
Block(-3,21,-7,STONE:3)
Block(-3,21,-6,STONE:3)
Block(-3,21,-5,OBSIDIAN:0)
Block(-3,21,-4,OBSIDIAN:0)
Block(-3,21,-3,OBSIDIAN:0)
Block(-3,21,-2,OBSIDIAN:0)
Block(-3,21,-1,OBSIDIAN:0)
Block(-3,21,0,OBSIDIAN:0)
Block(-3,21,1,OBSIDIAN:0)
Block(-3,21,2,OBSIDIAN:0)
Block(-3,21,3,OBSIDIAN:0)
Block(-3,21,4,OBSIDIAN:0)
Block(-3,21,5,OBSIDIAN:0)
Block(-3,21,6,OBSIDIAN:0)
Block(-3,21,7,OBSIDIAN:0)
Block(-3,21,8,STONE:3)
Block(-3,22,-7,STONE:3)
Block(-3,22,-6,OBSIDIAN:0)
Block(-3,22,-5,OBSIDIAN:0)
Block(-3,22,-4,OBSIDIAN:0)
Block(-3,22,-3,OBSIDIAN:0)
Block(-3,22,-2,OBSIDIAN:0)
Block(-3,22,-1,OBSIDIAN:0)
Block(-3,22,0,OBSIDIAN:0)
Block(-3,22,1,OBSIDIAN:0)
Block(-3,22,2,OBSIDIAN:0)
Block(-3,22,3,OBSIDIAN:0)
Block(-3,22,4,OBSIDIAN:0)
Block(-3,22,5,OBSIDIAN:0)
Block(-3,22,6,OBSIDIAN:0)
Block(-3,22,7,OBSIDIAN:0)
Block(-3,22,8,OBSIDIAN:0)
Block(-3,23,-7,OBSIDIAN:0)
Block(-3,23,-6,OBSIDIAN:0)
Block(-3,23,-5,OBSIDIAN:0)
Block(-3,23,-4,OBSIDIAN:0)
Block(-3,23,-3,OBSIDIAN:0)
Block(-3,23,-2,OBSIDIAN:0)
Block(-3,23,-1,OBSIDIAN:0)
Block(-3,23,0,OBSIDIAN:0)
Block(-3,23,1,OBSIDIAN:0)
Block(-3,23,2,OBSIDIAN:0)
Block(-3,23,3,OBSIDIAN:0)
Block(-3,23,4,OBSIDIAN:0)
Block(-3,23,5,OBSIDIAN:0)
Block(-3,23,6,OBSIDIAN:0)
Block(-3,23,7,OBSIDIAN:0)
Block(-3,23,8,OBSIDIAN:0)
Block(-3,24,-7,OBSIDIAN:0)
Block(-3,24,-6,OBSIDIAN:0)
Block(-3,24,-5,OBSIDIAN:0)
Block(-3,24,-4,OBSIDIAN:0)
Block(-3,24,-3,OBSIDIAN:0)
Block(-3,24,-2,OBSIDIAN:0)
Block(-3,24,-1,OBSIDIAN:0)
Block(-3,24,0,OBSIDIAN:0)
Block(-3,24,1,OBSIDIAN:0)
Block(-3,24,2,OBSIDIAN:0)
Block(-3,24,3,OBSIDIAN:0)
Block(-3,24,4,OBSIDIAN:0)
Block(-3,24,5,OBSIDIAN:0)
Block(-3,24,6,OBSIDIAN:0)
Block(-3,24,7,OBSIDIAN:0)
Block(-3,24,8,OBSIDIAN:0)
Block(-3,25,-7,OBSIDIAN:0)
Block(-3,25,-6,OBSIDIAN:0)
Block(-3,25,-5,OBSIDIAN:0)
Block(-3,25,-4,OBSIDIAN:0)
Block(-3,25,-3,OBSIDIAN:0)
Block(-3,25,-2,OBSIDIAN:0)
Block(-3,25,-1,OBSIDIAN:0)
Block(-3,25,0,OBSIDIAN:0)
Block(-3,25,1,OBSIDIAN:0)
Block(-3,25,2,OBSIDIAN:0)
Block(-3,25,3,OBSIDIAN:0)
Block(-3,25,4,OBSIDIAN:0)
Block(-3,25,5,OBSIDIAN:0)
Block(-3,25,6,OBSIDIAN:0)
Block(-3,25,7,OBSIDIAN:0)
Block(-3,25,8,OBSIDIAN:0)
Block(-3,26,-7,OBSIDIAN:0)
Block(-3,26,-6,OBSIDIAN:0)
Block(-3,26,-5,OBSIDIAN:0)
Block(-3,26,-4,OBSIDIAN:0)
Block(-3,26,-3,OBSIDIAN:0)
Block(-3,26,-2,OBSIDIAN:0)
Block(-3,26,-1,OBSIDIAN:0)
Block(-3,26,0,OBSIDIAN:0)
Block(-3,26,1,OBSIDIAN:0)
Block(-3,26,2,OBSIDIAN:0)
Block(-3,26,3,OBSIDIAN:0)
Block(-3,26,4,OBSIDIAN:0)
Block(-3,26,5,OBSIDIAN:0)
Block(-3,26,6,OBSIDIAN:0)
Block(-3,26,7,OBSIDIAN:0)
Block(-3,26,8,OBSIDIAN:0)
Block(-3,27,-7,OBSIDIAN:0)
Block(-3,27,-6,OBSIDIAN:0)
Block(-3,27,-5,OBSIDIAN:0)
Block(-3,27,-4,OBSIDIAN:0)
Block(-3,27,-3,OBSIDIAN:0)
Block(-3,27,-2,OBSIDIAN:0)
Block(-3,27,-1,OBSIDIAN:0)
Block(-3,27,0,OBSIDIAN:0)
Block(-3,27,1,OBSIDIAN:0)
Block(-3,27,2,OBSIDIAN:0)
Block(-3,27,3,OBSIDIAN:0)
Block(-3,27,4,OBSIDIAN:0)
Block(-3,27,5,OBSIDIAN:0)
Block(-3,27,6,OBSIDIAN:0)
Block(-3,27,7,OBSIDIAN:0)
Block(-3,27,8,OBSIDIAN:0)
Block(-3,28,-7,OBSIDIAN:0)
Block(-3,28,-6,OBSIDIAN:0)
Block(-3,28,-5,OBSIDIAN:0)
Block(-3,28,-4,OBSIDIAN:0)
Block(-3,28,-3,OBSIDIAN:0)
Block(-3,28,-2,OBSIDIAN:0)
Block(-3,28,-1,OBSIDIAN:0)
Block(-3,28,0,OBSIDIAN:0)
Block(-3,28,1,OBSIDIAN:0)
Block(-3,28,2,OBSIDIAN:0)
Block(-3,28,3,OBSIDIAN:0)
Block(-3,28,4,OBSIDIAN:0)
Block(-3,28,5,OBSIDIAN:0)
Block(-3,28,6,OBSIDIAN:0)
Block(-3,28,7,OBSIDIAN:0)
Block(-3,28,8,OBSIDIAN:0)
Block(-3,29,-7,OBSIDIAN:0)
Block(-3,29,-6,OBSIDIAN:0)
Block(-3,29,-5,OBSIDIAN:0)
Block(-3,29,-4,OBSIDIAN:0)
Block(-3,29,-3,OBSIDIAN:0)
Block(-3,29,-2,OBSIDIAN:0)
Block(-3,29,-1,OBSIDIAN:0)
Block(-3,29,0,OBSIDIAN:0)
Block(-3,29,1,OBSIDIAN:0)
Block(-3,29,2,OBSIDIAN:0)
Block(-3,29,3,OBSIDIAN:0)
Block(-3,29,4,OBSIDIAN:0)
Block(-3,29,5,OBSIDIAN:0)
Block(-3,29,6,OBSIDIAN:0)
Block(-3,29,7,OBSIDIAN:0)
Block(-3,29,8,OBSIDIAN:0)
Block(-3,30,-7,OBSIDIAN:0)
Block(-3,30,-6,OBSIDIAN:0)
Block(-3,30,-5,OBSIDIAN:0)
Block(-3,30,-4,OBSIDIAN:0)
Block(-3,30,-3,OBSIDIAN:0)
Block(-3,30,-2,OBSIDIAN:0)
Block(-3,30,-1,OBSIDIAN:0)
Block(-3,30,0,OBSIDIAN:0)
Block(-3,30,1,OBSIDIAN:0)
Block(-3,30,2,OBSIDIAN:0)
Block(-3,30,3,OBSIDIAN:0)
Block(-3,30,4,OBSIDIAN:0)
Block(-3,30,5,OBSIDIAN:0)
Block(-3,30,6,OBSIDIAN:0)
Block(-3,30,7,OBSIDIAN:0)
Block(-3,30,8,OBSIDIAN:0)
Block(-3,31,-7,OBSIDIAN:0)
Block(-3,31,-6,OBSIDIAN:0)
Block(-3,31,-5,OBSIDIAN:0)
Block(-3,31,-4,OBSIDIAN:0)
Block(-3,31,-3,OBSIDIAN:0)
Block(-3,31,-2,OBSIDIAN:0)
Block(-3,31,-1,OBSIDIAN:0)
Block(-3,31,0,OBSIDIAN:0)
Block(-3,31,1,OBSIDIAN:0)
Block(-3,31,2,OBSIDIAN:0)
Block(-3,31,3,OBSIDIAN:0)
Block(-3,31,4,OBSIDIAN:0)
Block(-3,31,5,OBSIDIAN:0)
Block(-3,31,6,OBSIDIAN:0)
Block(-3,31,7,OBSIDIAN:0)
Block(-3,31,8,OBSIDIAN:0)
Block(-3,32,-7,OBSIDIAN:0)
Block(-3,32,-6,OBSIDIAN:0)
Block(-3,32,-5,OBSIDIAN:0)
Block(-3,32,-4,OBSIDIAN:0)
Block(-3,32,-3,OBSIDIAN:0)
Block(-3,32,-2,OBSIDIAN:0)
Block(-3,32,-1,OBSIDIAN:0)
Block(-3,32,0,OBSIDIAN:0)
Block(-3,32,1,OBSIDIAN:0)
Block(-3,32,2,OBSIDIAN:0)
Block(-3,32,3,OBSIDIAN:0)
Block(-3,32,4,OBSIDIAN:0)
Block(-3,32,5,OBSIDIAN:0)
Block(-3,32,6,OBSIDIAN:0)
Block(-3,32,7,OBSIDIAN:0)
Block(-3,32,8,OBSIDIAN:0)
Block(-3,33,-7,OBSIDIAN:0)
Block(-3,33,-6,OBSIDIAN:0)
Block(-3,33,-5,OBSIDIAN:0)
Block(-3,33,-4,OBSIDIAN:0)
Block(-3,33,-3,OBSIDIAN:0)
Block(-3,33,-2,OBSIDIAN:0)
Block(-3,33,-1,OBSIDIAN:0)
Block(-3,33,0,OBSIDIAN:0)
Block(-3,33,1,OBSIDIAN:0)
Block(-3,33,2,OBSIDIAN:0)
Block(-3,33,3,OBSIDIAN:0)
Block(-3,33,4,OBSIDIAN:0)
Block(-3,33,5,OBSIDIAN:0)
Block(-3,33,6,OBSIDIAN:0)
Block(-3,33,7,OBSIDIAN:0)
Block(-3,33,8,OBSIDIAN:0)
Block(-3,34,-7,OBSIDIAN:0)
Block(-3,34,-6,OBSIDIAN:0)
Block(-3,34,-5,OBSIDIAN:0)
Block(-3,34,-4,OBSIDIAN:0)
Block(-3,34,-3,OBSIDIAN:0)
Block(-3,34,-2,OBSIDIAN:0)
Block(-3,34,-1,OBSIDIAN:0)
Block(-3,34,0,OBSIDIAN:0)
Block(-3,34,1,OBSIDIAN:0)
Block(-3,34,2,OBSIDIAN:0)
Block(-3,34,3,OBSIDIAN:0)
Block(-3,34,4,OBSIDIAN:0)
Block(-3,34,5,OBSIDIAN:0)
Block(-3,34,6,OBSIDIAN:0)
Block(-3,34,7,OBSIDIAN:0)
Block(-3,34,8,OBSIDIAN:0)
Block(-3,35,-7,OBSIDIAN:0)
Block(-3,35,-6,OBSIDIAN:0)
Block(-3,35,-5,OBSIDIAN:0)
Block(-3,35,-4,OBSIDIAN:0)
Block(-3,35,-3,OBSIDIAN:0)
Block(-3,35,-2,OBSIDIAN:0)
Block(-3,35,-1,OBSIDIAN:0)
Block(-3,35,0,OBSIDIAN:0)
Block(-3,35,1,OBSIDIAN:0)
Block(-3,35,2,OBSIDIAN:0)
Block(-3,35,3,OBSIDIAN:0)
Block(-3,35,4,OBSIDIAN:0)
Block(-3,35,5,OBSIDIAN:0)
Block(-3,35,6,OBSIDIAN:0)
Block(-3,35,7,OBSIDIAN:0)
Block(-3,35,8,OBSIDIAN:0)
Block(-3,36,-7,OBSIDIAN:0)
Block(-3,36,-6,OBSIDIAN:0)
Block(-3,36,-5,OBSIDIAN:0)
Block(-3,36,-4,OBSIDIAN:0)
Block(-3,36,-3,OBSIDIAN:0)
Block(-3,36,-2,OBSIDIAN:0)
Block(-3,36,-1,OBSIDIAN:0)
Block(-3,36,0,OBSIDIAN:0)
Block(-3,36,1,OBSIDIAN:0)
Block(-3,36,2,OBSIDIAN:0)
Block(-3,36,3,OBSIDIAN:0)
Block(-3,36,4,OBSIDIAN:0)
Block(-3,36,5,OBSIDIAN:0)
Block(-3,36,6,OBSIDIAN:0)
Block(-3,36,7,OBSIDIAN:0)
Block(-3,36,8,OBSIDIAN:0)
Block(-3,37,-7,OBSIDIAN:0)
Block(-3,37,-6,OBSIDIAN:0)
Block(-3,37,-5,OBSIDIAN:0)
Block(-3,37,-4,OBSIDIAN:0)
Block(-3,37,-3,OBSIDIAN:0)
Block(-3,37,-2,OBSIDIAN:0)
Block(-3,37,-1,OBSIDIAN:0)
Block(-3,37,0,STONE:5)
Block(-3,37,1,STONE:5)
Block(-3,37,2,STONE:5)
Block(-3,37,3,STONE:5)
Block(-3,37,4,STONE:5)
Block(-3,37,5,STONE:5)
Block(-3,37,6,STONE:5)
Block(-3,37,7,STONE:5)
Block(-3,37,8,STONE:5)
Block(-3,38,-7,OBSIDIAN:0)
Block(-3,38,-6,OBSIDIAN:0)
Block(-3,38,-5,OBSIDIAN:0)
Block(-3,38,-4,OBSIDIAN:0)
Block(-3,38,-3,OBSIDIAN:0)
Block(-3,38,-2,STONE:5)
Block(-3,38,-1,STONE:5)
Block(-3,38,0,STONE:5)
Block(-3,38,1,STONE:3)
Block(-3,38,2,STONE:3)
Block(-3,38,3,STONE:3)
Block(-3,38,4,STONE:5)
Block(-3,38,5,STONE:5)
Block(-3,38,6,STONE:5)
Block(-3,38,7,STONE:5)
Block(-3,38,8,STONE:5)
Block(-3,39,-7,OBSIDIAN:0)
Block(-3,39,-6,OBSIDIAN:0)
Block(-3,39,-5,OBSIDIAN:0)
Block(-3,39,-4,STONE:5)
Block(-3,39,-3,STONE:5)
Block(-3,39,-2,STONE:5)
Block(-3,39,-1,STONE:5)
Block(-3,39,0,STONE:3)
Block(-3,39,1,STONE:3)
Block(-3,39,2,STONE:3)
Block(-3,39,3,STONE:3)
Block(-3,39,4,STONE:3)
Block(-3,39,5,STONE:5)
Block(-3,39,6,STONE:5)
Block(-3,39,7,STONE:5)
Block(-3,39,8,STONE:5)
Block(-3,40,-7,OBSIDIAN:0)
Block(-3,40,-6,OBSIDIAN:0)
Block(-3,40,-5,OBSIDIAN:0)
Block(-3,40,-4,STONE:5)
Block(-3,40,-3,STONE:5)
Block(-3,40,-2,STONE:5)
Block(-3,40,-1,STONE:5)
Block(-3,40,0,STONE:3)
Block(-3,40,1,STONE:3)
Block(-3,40,2,STONE:3)
Block(-3,41,-7,GRASS:0)
Block(-3,41,-6,OBSIDIAN:0)
Block(-3,41,-5,OBSIDIAN:0)
Block(-3,41,-4,GRASS:0)
Block(-3,41,-3,GRASS:0)
Block(-3,41,-2,STONE:5)
Block(-3,41,-1,STONE:5)
Block(-3,41,0,STONE:3)
Block(-3,42,-6,GRASS:0)
Block(-3,42,-5,GRASS:0)
Block(-3,42,-2,STONE:5)
Block(-3,73,3,OBSIDIAN:0)
Block(-3,74,0,OBSIDIAN:0)
Block(-3,74,1,OBSIDIAN:0)
Block(-3,74,2,OBSIDIAN:0)
Block(-3,74,3,OBSIDIAN:0)
Block(-3,74,4,OBSIDIAN:0)
Block(-3,74,5,OBSIDIAN:0)
Block(-3,74,6,OBSIDIAN:0)
Block(-3,74,7,OBSIDIAN:0)
Block(-3,74,8,OBSIDIAN:0)
Block(-3,75,0,OBSIDIAN:0)
Block(-3,75,1,OBSIDIAN:0)
Block(-3,75,2,OBSIDIAN:0)
Block(-3,75,3,OBSIDIAN:0)
Block(-3,75,4,OBSIDIAN:0)
Block(-3,75,5,OBSIDIAN:0)
Block(-3,75,6,OBSIDIAN:0)
Block(-3,75,7,OBSIDIAN:0)
Block(-3,75,8,OBSIDIAN:0)
Block(-3,76,-3,OBSIDIAN:0)
Block(-3,76,-2,OBSIDIAN:0)
Block(-3,76,-1,OBSIDIAN:0)
Block(-3,76,0,OBSIDIAN:0)
Block(-3,76,1,OBSIDIAN:0)
Block(-3,76,2,OBSIDIAN:0)
Block(-3,76,3,OBSIDIAN:0)
Block(-3,76,4,OBSIDIAN:0)
Block(-3,76,5,OBSIDIAN:0)
Block(-3,76,6,OBSIDIAN:0)
Block(-3,76,7,OBSIDIAN:0)
Block(-3,76,8,OBSIDIAN:0)
Block(-3,77,-4,OBSIDIAN:0)
Block(-3,77,-3,OBSIDIAN:0)
Block(-3,77,-2,OBSIDIAN:0)
Block(-3,77,-1,OBSIDIAN:0)
Block(-3,77,0,OBSIDIAN:0)
Block(-3,77,1,OBSIDIAN:0)
Block(-3,77,2,OBSIDIAN:0)
Block(-3,77,3,OBSIDIAN:0)
Block(-3,77,4,OBSIDIAN:0)
Block(-3,77,5,OBSIDIAN:0)
Block(-3,77,6,OBSIDIAN:0)
Block(-3,77,7,OBSIDIAN:0)
Block(-3,77,8,OBSIDIAN:0)
Block(-3,78,-5,OBSIDIAN:0)
Block(-3,78,-4,OBSIDIAN:0)
Block(-3,78,-3,OBSIDIAN:0)
Block(-3,78,-2,OBSIDIAN:0)
Block(-3,78,-1,OBSIDIAN:0)
Block(-3,78,0,OBSIDIAN:0)
Block(-3,78,1,OBSIDIAN:0)
Block(-3,78,2,OBSIDIAN:0)
Block(-3,78,3,OBSIDIAN:0)
Block(-3,78,4,OBSIDIAN:0)
Block(-3,78,5,OBSIDIAN:0)
Block(-3,78,6,OBSIDIAN:0)
Block(-3,78,7,OBSIDIAN:0)
Block(-3,78,8,OBSIDIAN:0)
Block(-3,79,-6,OBSIDIAN:0)
Block(-3,79,-5,OBSIDIAN:0)
Block(-3,79,-4,OBSIDIAN:0)
Block(-3,79,-3,OBSIDIAN:0)
Block(-3,79,-2,OBSIDIAN:0)
Block(-3,79,-1,OBSIDIAN:0)
Block(-3,79,0,OBSIDIAN:0)
Block(-3,79,1,OBSIDIAN:0)
Block(-3,79,2,OBSIDIAN:0)
Block(-3,79,3,OBSIDIAN:0)
Block(-3,79,4,OBSIDIAN:0)
Block(-3,79,5,OBSIDIAN:0)
Block(-3,79,6,OBSIDIAN:0)
Block(-3,79,7,OBSIDIAN:0)
Block(-3,79,8,OBSIDIAN:0)
Block(-3,80,-6,OBSIDIAN:0)
Block(-3,80,-5,OBSIDIAN:0)
Block(-3,80,-4,OBSIDIAN:0)
Block(-3,80,-3,OBSIDIAN:0)
Block(-3,80,-2,OBSIDIAN:0)
Block(-3,80,-1,OBSIDIAN:0)
Block(-3,80,0,OBSIDIAN:0)
Block(-3,80,1,OBSIDIAN:0)
Block(-3,80,2,OBSIDIAN:0)
Block(-3,80,3,OBSIDIAN:0)
Block(-3,80,4,OBSIDIAN:0)
Block(-3,80,5,OBSIDIAN:0)
Block(-3,80,6,OBSIDIAN:0)
Block(-3,80,7,OBSIDIAN:0)
Block(-3,80,8,OBSIDIAN:0)
Block(-3,81,-7,OBSIDIAN:0)
Block(-3,81,-6,OBSIDIAN:0)
Block(-3,81,-5,OBSIDIAN:0)
Block(-3,81,-4,OBSIDIAN:0)
Block(-3,81,-3,OBSIDIAN:0)
Block(-3,81,-2,OBSIDIAN:0)
Block(-3,81,-1,OBSIDIAN:0)
Block(-3,81,0,OBSIDIAN:0)
Block(-3,81,1,OBSIDIAN:0)
Block(-3,81,2,OBSIDIAN:0)
Block(-3,81,3,OBSIDIAN:0)
Block(-3,81,4,OBSIDIAN:0)
Block(-3,81,5,OBSIDIAN:0)
Block(-3,81,6,OBSIDIAN:0)
Block(-3,81,7,OBSIDIAN:0)
Block(-3,81,8,OBSIDIAN:0)
Block(-3,82,-7,OBSIDIAN:0)
Block(-3,82,-6,OBSIDIAN:0)
Block(-3,82,-5,OBSIDIAN:0)
Block(-3,82,-4,OBSIDIAN:0)
Block(-3,82,-3,OBSIDIAN:0)
Block(-3,82,-2,OBSIDIAN:0)
Block(-3,82,-1,OBSIDIAN:0)
Block(-3,82,0,OBSIDIAN:0)
Block(-3,82,1,OBSIDIAN:0)
Block(-3,82,2,OBSIDIAN:0)
Block(-3,82,3,OBSIDIAN:0)
Block(-3,82,4,OBSIDIAN:0)
Block(-3,82,5,OBSIDIAN:0)
Block(-3,82,6,OBSIDIAN:0)
Block(-3,82,7,OBSIDIAN:0)
Block(-3,82,8,OBSIDIAN:0)
Block(-3,83,-7,OBSIDIAN:0)
Block(-3,83,-6,OBSIDIAN:0)
Block(-3,83,-5,OBSIDIAN:0)
Block(-3,83,-4,OBSIDIAN:0)
Block(-3,83,-3,OBSIDIAN:0)
Block(-3,83,-2,OBSIDIAN:0)
Block(-3,83,-1,OBSIDIAN:0)
Block(-3,83,0,OBSIDIAN:0)
Block(-3,83,1,OBSIDIAN:0)
Block(-3,83,2,OBSIDIAN:0)
Block(-3,83,3,OBSIDIAN:0)
Block(-3,83,4,OBSIDIAN:0)
Block(-3,83,5,OBSIDIAN:0)
Block(-3,83,6,OBSIDIAN:0)
Block(-3,83,7,OBSIDIAN:0)
Block(-3,83,8,OBSIDIAN:0)
Block(-3,84,-7,OBSIDIAN:0)
Block(-3,84,-6,OBSIDIAN:0)
Block(-3,84,-5,OBSIDIAN:0)
Block(-3,84,-4,OBSIDIAN:0)
Block(-3,84,-3,OBSIDIAN:0)
Block(-3,84,-2,OBSIDIAN:0)
Block(-3,84,-1,OBSIDIAN:0)
Block(-3,84,0,OBSIDIAN:0)
Block(-3,84,1,OBSIDIAN:0)
Block(-3,84,2,OBSIDIAN:0)
Block(-3,84,3,OBSIDIAN:0)
Block(-3,84,4,OBSIDIAN:0)
Block(-3,84,5,OBSIDIAN:0)
Block(-3,84,6,OBSIDIAN:0)
Block(-3,84,7,OBSIDIAN:0)
Block(-3,84,8,OBSIDIAN:0)
Block(-3,85,-7,OBSIDIAN:0)
Block(-3,85,-6,OBSIDIAN:0)
Block(-3,85,-5,OBSIDIAN:0)
Block(-3,85,-4,OBSIDIAN:0)
Block(-3,85,-3,OBSIDIAN:0)
Block(-3,85,-2,OBSIDIAN:0)
Block(-3,85,-1,OBSIDIAN:0)
Block(-3,85,0,OBSIDIAN:0)
Block(-3,85,1,OBSIDIAN:0)
Block(-3,85,2,OBSIDIAN:0)
Block(-3,85,3,OBSIDIAN:0)
Block(-3,85,4,OBSIDIAN:0)
Block(-3,85,5,OBSIDIAN:0)
Block(-3,85,6,OBSIDIAN:0)
Block(-3,85,7,OBSIDIAN:0)
Block(-3,85,8,OBSIDIAN:0)
Block(-3,86,-7,OBSIDIAN:0)
Block(-3,86,-6,OBSIDIAN:0)
Block(-3,86,-5,OBSIDIAN:0)
Block(-3,86,-4,OBSIDIAN:0)
Block(-3,86,-3,OBSIDIAN:0)
Block(-3,86,-2,OBSIDIAN:0)
Block(-3,86,-1,OBSIDIAN:0)
Block(-3,86,0,OBSIDIAN:0)
Block(-3,86,1,OBSIDIAN:0)
Block(-3,86,2,OBSIDIAN:0)
Block(-3,86,3,OBSIDIAN:0)
Block(-3,86,4,OBSIDIAN:0)
Block(-3,86,5,OBSIDIAN:0)
Block(-3,86,6,OBSIDIAN:0)
Block(-3,86,8,OBSIDIAN:0)
Block(-3,87,-7,OBSIDIAN:0)
Block(-3,87,-6,OBSIDIAN:0)
Block(-3,87,-5,OBSIDIAN:0)
Block(-3,87,-4,OBSIDIAN:0)
Block(-3,87,-3,OBSIDIAN:0)
Block(-3,87,-2,OBSIDIAN:0)
Block(-3,87,-1,OBSIDIAN:0)
Block(-3,87,0,OBSIDIAN:0)
Block(-3,87,1,OBSIDIAN:0)
Block(-3,87,2,OBSIDIAN:0)
Block(-3,87,3,OBSIDIAN:0)
Block(-3,87,4,OBSIDIAN:0)
Block(-3,87,5,OBSIDIAN:0)
Block(-3,88,-7,STONE:3)
Block(-3,88,-6,STONE:3)
Block(-3,88,-5,OBSIDIAN:0)
Block(-3,88,-4,OBSIDIAN:0)
Block(-3,88,-3,OBSIDIAN:0)
Block(-3,88,-2,OBSIDIAN:0)
Block(-3,88,-1,OBSIDIAN:0)
Block(-3,88,0,OBSIDIAN:0)
Block(-3,88,1,OBSIDIAN:0)
Block(-3,88,2,OBSIDIAN:0)
Block(-3,88,3,OBSIDIAN:0)
Block(-3,88,4,OBSIDIAN:0)
Block(-3,89,-7,STONE:3)
Block(-3,89,-6,STONE:3)
Block(-3,89,-5,STONE:3)
Block(-3,89,-4,STONE:3)
Block(-3,89,-3,OBSIDIAN:0)
Block(-3,89,-2,OBSIDIAN:0)
