
#######################################################################
# +-----------------------------------------------------------------+ #
# |                            BO4 object                           | #
# +-----------------------------------------------------------------+ #
#######################################################################

Author: NLBlackEagle

Description: No description given

SettingsMode: WriteWithoutComments


#######################################################################
# +-----------------------------------------------------------------+ #
# |                          Main settings                          | #
# +-----------------------------------------------------------------+ #
#######################################################################

Frequency: 0

SpawnHeight: highestBlock

UseCenterForHighestBlock: true

##############################
# Height Limits for the BO4. #
##############################

MinHeight: 0

MaxHeight: 255

InheritBO3: 

InheritBO3Rotation: NORTH

OverrideChildSettings: true

OverrideParentHeight: false

CanOverride: false

BranchFrequency: 0

BranchFrequencyGroup: 

MustBeBelowOther: false

MustBeInside: 

CannotBeInside: 

ReplacesBO3: 

MustBeInsideWorldBorders: false

CanSpawnOnWater: true

SpawnOnWaterOnly: false

SpawnUnderWater: false

SpawnAtWaterLevel: false

HeightOffset: 0

RemoveAir: true

ReplaceAbove: 

ReplaceBelow: 

ReplaceWithBiomeBlocks: true

ReplaceWithSurfaceBlock: GRASS

ReplaceWithGroundBlock: DIRT

ReplaceWithStoneBlock: STONE

SmoothRadius: 0

SmoothHeightOffset: 0

SmoothStartTop: false

SmoothStartWood: false

SmoothingSurfaceBlock: 

SmoothingGroundBlock: 

BO3Group: 

IsSpawnPoint: false

DoReplaceBlocks: true


#######################################################################
# +-----------------------------------------------------------------+ #
# |                              Blocks                             | #
# +-----------------------------------------------------------------+ #
#######################################################################

Block(-1,64,8,STONE:3)
Block(-1,65,7,STONE:3)
Block(-1,65,8,STONE:3)
Block(-1,66,8,STONE:3)
Block(0,54,8,STONE:3)
Block(0,61,8,STONE:3)
Block(0,62,8,STONE:3)
Block(0,63,8,STONE:3)
Block(0,64,7,STONE:3)
Block(0,64,8,STONE:3)
Block(0,65,6,STONE:3)
Block(0,65,7,STONE:3)
Block(0,65,8,STONE:3)
Block(0,66,5,STONE:3)
Block(0,66,6,STONE:3)
Block(0,66,7,STONE:3)
Block(0,66,8,STONE:3)
Block(0,67,6,STONE:3)
Block(0,67,7,STONE:3)
Block(0,67,8,STONE:3)
Block(0,68,7,STONE:3)
Block(0,68,8,STONE:3)
Block(0,69,8,STONE:3)
Block(0,70,7,STONE:3)
Block(0,70,8,STONE:3)
Block(0,71,7,STONE:3)
Block(0,71,8,STONE:3)
Block(0,72,7,STONE:3)
Block(0,72,8,STONE:3)
Block(0,73,8,STONE:3)
Block(1,53,8,STONE:3)
Block(1,54,8,STONE:3)
Block(1,61,7,STONE:3)
Block(1,61,8,STONE:3)
Block(1,62,6,STONE:3)
Block(1,62,7,STONE:3)
Block(1,62,8,STONE:3)
Block(1,63,6,STONE:3)
Block(1,63,7,STONE:3)
Block(1,63,8,STONE:3)
Block(1,64,5,STONE:3)
Block(1,64,6,STONE:3)
Block(1,64,7,STONE:3)
Block(1,64,8,STONE:3)
Block(1,65,5,STONE:3)
Block(1,65,6,STONE:3)
Block(1,65,7,STONE:3)
Block(1,65,8,STONE:3)
Block(1,66,4,STONE:3)
Block(1,66,5,STONE:3)
Block(1,66,6,STONE:3)
Block(1,66,7,STONE:3)
Block(1,66,8,STONE:3)
Block(1,67,5,STONE:3)
Block(1,67,6,STONE:3)
Block(1,67,7,STONE:3)
Block(1,67,8,STONE:3)
Block(1,68,6,STONE:3)
Block(1,68,7,STONE:3)
Block(1,68,8,STONE:3)
Block(1,69,7,STONE:3)
Block(1,69,8,STONE:3)
Block(1,70,6,STONE:3)
Block(1,70,7,STONE:3)
Block(1,70,8,STONE:3)
Block(1,71,5,STONE:3)
Block(1,71,6,STONE:3)
Block(1,71,7,STONE:3)
Block(1,71,8,STONE:3)
Block(1,72,4,STONE:3)
Block(1,72,5,STONE:3)
Block(1,72,6,STONE:3)
Block(1,72,7,STONE:3)
Block(1,72,8,STONE:3)
Block(1,73,3,STONE:3)
Block(1,73,4,STONE:3)
Block(1,73,5,STONE:3)
Block(1,73,6,STONE:3)
Block(1,73,7,STONE:3)
Block(1,73,8,STONE:3)
Block(1,74,2,STONE:3)
Block(1,74,3,STONE:3)
Block(1,74,4,STONE:3)
Block(1,74,6,STONE:3)
Block(1,74,7,STONE:3)
Block(1,74,8,STONE:3)
Block(1,75,2,STONE:3)
Block(1,75,3,STONE:3)
Block(1,75,7,STONE:3)
Block(1,75,8,STONE:3)
Block(1,76,2,STONE:3)
Block(1,76,8,STONE:3)
Block(2,51,8,STONE:3)
Block(2,52,8,STONE:3)
Block(2,53,8,STONE:3)
Block(2,54,8,STONE:3)
Block(2,55,8,STONE:3)
Block(2,56,8,STONE:3)
Block(2,58,8,STONE:3)
Block(2,59,7,STONE:3)
Block(2,59,8,STONE:3)
Block(2,60,7,STONE:3)
Block(2,60,8,STONE:3)
Block(2,61,6,STONE:3)
Block(2,61,7,STONE:3)
Block(2,61,8,STONE:3)
Block(2,62,5,STONE:3)
Block(2,62,6,STONE:3)
Block(2,62,7,STONE:3)
Block(2,62,8,STONE:3)
Block(2,63,4,STONE:3)
Block(2,63,5,STONE:3)
Block(2,63,6,STONE:3)
Block(2,63,7,STONE:3)
Block(2,63,8,STONE:3)
Block(2,64,4,STONE:3)
Block(2,64,5,STONE:3)
Block(2,64,6,STONE:3)
Block(2,64,7,STONE:3)
Block(2,64,8,STONE:3)
Block(2,65,4,STONE:3)
Block(2,65,5,STONE:3)
Block(2,65,6,STONE:3)
Block(2,65,7,STONE:3)
Block(2,65,8,STONE:3)
Block(2,66,3,STONE:3)
Block(2,66,4,STONE:3)
Block(2,66,5,STONE:3)
Block(2,66,6,STONE:3)
Block(2,66,7,STONE:3)
Block(2,66,8,STONE:3)
Block(2,67,4,STONE:3)
Block(2,67,5,STONE:3)
Block(2,67,6,STONE:3)
Block(2,67,7,STONE:3)
Block(2,67,8,STONE:3)
Block(2,68,6,STONE:3)
Block(2,68,7,STONE:3)
Block(2,68,8,STONE:3)
Block(2,69,5,STONE:3)
Block(2,69,6,STONE:3)
Block(2,69,7,STONE:3)
Block(2,69,8,STONE:3)
Block(2,70,4,STONE:3)
Block(2,70,5,STONE:3)
Block(2,70,6,STONE:3)
Block(2,70,7,STONE:3)
Block(2,70,8,STONE:3)
Block(2,71,3,STONE:3)
Block(2,71,4,STONE:3)
Block(2,71,5,STONE:3)
Block(2,71,6,STONE:3)
Block(2,71,7,STONE:3)
Block(2,71,8,STONE:3)
Block(2,72,3,STONE:3)
Block(2,72,4,STONE:3)
Block(2,72,5,STONE:3)
Block(2,72,6,STONE:3)
Block(2,72,7,STONE:3)
Block(2,72,8,STONE:3)
Block(2,73,2,STONE:3)
Block(2,73,3,STONE:3)
Block(2,73,4,STONE:3)
Block(2,73,5,STONE:3)
Block(2,73,6,STONE:3)
Block(2,73,7,STONE:3)
Block(2,73,8,STONE:3)
Block(2,74,1,STONE:3)
Block(2,74,2,STONE:3)
Block(2,74,3,STONE:3)
Block(2,74,4,STONE:3)
Block(2,74,5,STONE:3)
Block(2,74,6,STONE:3)
Block(2,74,7,STONE:3)
Block(2,74,8,STONE:3)
Block(2,75,2,STONE:3)
Block(2,75,3,STONE:3)
Block(2,75,4,STONE:3)
Block(2,75,5,STONE:3)
Block(2,75,6,STONE:3)
Block(2,75,7,STONE:3)
Block(2,75,8,STONE:3)
Block(2,76,1,STONE:3)
Block(2,76,2,STONE:3)
Block(2,76,3,STONE:3)
Block(2,76,4,STONE:3)
Block(2,76,6,STONE:3)
Block(2,76,7,STONE:3)
Block(2,76,8,STONE:3)
Block(2,77,7,STONE:3)
Block(2,77,8,STONE:3)
Block(2,78,8,STONE:3)
Block(3,49,7,STONE:3)
Block(3,49,8,OBSIDIAN:0)
Block(3,50,7,STONE:3)
Block(3,50,8,OBSIDIAN:0)
Block(3,51,6,STONE:3)
Block(3,51,7,STONE:3)
Block(3,51,8,STONE:3)
Block(3,52,7,STONE:3)
Block(3,52,8,STONE:3)
Block(3,53,7,STONE:3)
Block(3,53,8,STONE:3)
Block(3,54,8,STONE:3)
Block(3,55,8,STONE:3)
Block(3,56,8,STONE:3)
Block(3,57,8,STONE:3)
Block(3,58,6,STONE:3)
Block(3,58,7,STONE:3)
Block(3,58,8,STONE:3)
Block(3,59,6,STONE:3)
Block(3,59,7,STONE:3)
Block(3,59,8,STONE:3)
Block(3,60,6,STONE:3)
Block(3,60,7,STONE:3)
Block(3,60,8,STONE:3)
Block(3,61,5,STONE:3)
Block(3,61,6,STONE:3)
Block(3,61,7,STONE:3)
Block(3,61,8,STONE:3)
Block(3,62,4,STONE:3)
Block(3,62,5,STONE:3)
Block(3,62,6,STONE:3)
Block(3,62,7,STONE:3)
Block(3,62,8,STONE:3)
Block(3,63,3,STONE:3)
Block(3,63,4,STONE:3)
Block(3,63,5,STONE:3)
Block(3,63,6,STONE:3)
Block(3,63,7,STONE:3)
Block(3,63,8,STONE:3)
Block(3,64,3,STONE:3)
Block(3,64,4,STONE:3)
Block(3,64,5,STONE:3)
Block(3,64,6,STONE:3)
Block(3,64,7,STONE:3)
Block(3,64,8,STONE:3)
Block(3,65,3,STONE:3)
Block(3,65,4,STONE:3)
Block(3,65,5,STONE:3)
Block(3,65,6,STONE:3)
Block(3,65,7,STONE:3)
Block(3,65,8,STONE:3)
Block(3,66,2,STONE:3)
Block(3,66,3,STONE:3)
Block(3,66,4,STONE:3)
Block(3,66,5,STONE:3)
Block(3,66,6,STONE:3)
Block(3,66,7,STONE:3)
Block(3,66,8,STONE:3)
Block(3,67,4,STONE:3)
Block(3,67,5,STONE:3)
Block(3,67,6,STONE:3)
Block(3,67,7,STONE:3)
Block(3,67,8,STONE:3)
Block(3,68,5,STONE:3)
Block(3,68,6,STONE:3)
Block(3,68,7,STONE:3)
Block(3,68,8,STONE:3)
Block(3,69,4,STONE:3)
Block(3,69,5,STONE:3)
Block(3,69,6,STONE:3)
Block(3,69,7,STONE:3)
Block(3,69,8,STONE:3)
Block(3,70,3,STONE:3)
Block(3,70,4,STONE:3)
Block(3,70,5,STONE:3)
Block(3,70,6,STONE:3)
Block(3,70,7,STONE:3)
Block(3,70,8,STONE:3)
Block(3,71,3,STONE:3)
Block(3,71,4,STONE:3)
Block(3,71,5,STONE:3)
Block(3,71,6,STONE:3)
Block(3,71,7,STONE:3)
Block(3,71,8,STONE:3)
Block(3,72,2,STONE:3)
Block(3,72,3,STONE:3)
Block(3,72,4,STONE:3)
Block(3,72,5,STONE:3)
Block(3,72,6,STONE:3)
Block(3,72,7,STONE:3)
Block(3,72,8,STONE:3)
Block(3,73,2,STONE:3)
Block(3,73,3,STONE:3)
Block(3,73,4,STONE:3)
Block(3,73,5,STONE:3)
Block(3,73,6,STONE:3)
Block(3,73,7,STONE:3)
Block(3,73,8,STONE:3)
Block(3,74,1,STONE:3)
Block(3,74,2,STONE:3)
Block(3,74,3,STONE:3)
Block(3,74,4,STONE:3)
Block(3,74,5,STONE:3)
Block(3,74,6,STONE:3)
Block(3,74,7,STONE:3)
Block(3,74,8,STONE:3)
Block(3,75,0,STONE:3)
Block(3,75,1,STONE:3)
Block(3,75,2,STONE:3)
Block(3,75,3,STONE:3)
Block(3,75,4,STONE:3)
Block(3,75,5,STONE:3)
Block(3,75,6,STONE:3)
Block(3,75,7,STONE:3)
Block(3,75,8,STONE:3)
Block(3,76,0,STONE:3)
Block(3,76,1,STONE:3)
Block(3,76,2,STONE:3)
Block(3,76,3,STONE:3)
Block(3,76,4,STONE:3)
Block(3,76,5,STONE:3)
Block(3,76,6,STONE:3)
Block(3,76,7,STONE:3)
Block(3,76,8,STONE:3)
Block(3,77,1,STONE:3)
Block(3,77,2,STONE:3)
Block(3,77,3,STONE:3)
Block(3,77,4,STONE:3)
Block(3,77,5,STONE:3)
Block(3,77,6,STONE:3)
Block(3,77,7,STONE:3)
Block(3,77,8,STONE:3)
Block(3,78,2,STONE:3)
Block(3,78,3,STONE:3)
Block(3,78,4,STONE:3)
Block(3,78,6,STONE:3)
Block(3,78,7,STONE:3)
Block(3,78,8,STONE:3)
Block(3,79,7,STONE:3)
Block(3,79,8,STONE:3)
Block(3,80,8,STONE:3)
Block(3,81,8,STONE:3)
Block(4,48,8,OBSIDIAN:0)
Block(4,49,6,STONE:3)
Block(4,49,7,STONE:3)
Block(4,49,8,OBSIDIAN:0)
Block(4,50,6,STONE:3)
Block(4,50,7,STONE:3)
Block(4,50,8,STONE:3)
Block(4,51,6,STONE:3)
Block(4,51,7,STONE:3)
Block(4,51,8,STONE:3)
Block(4,52,6,STONE:3)
Block(4,52,7,STONE:3)
Block(4,52,8,STONE:3)
Block(4,53,6,STONE:3)
Block(4,53,7,STONE:3)
Block(4,53,8,STONE:3)
Block(4,54,6,STONE:3)
Block(4,54,7,STONE:3)
Block(4,54,8,STONE:3)
Block(4,55,7,STONE:3)
Block(4,55,8,STONE:3)
Block(4,56,6,STONE:3)
Block(4,56,7,STONE:3)
Block(4,56,8,STONE:3)
Block(4,57,6,STONE:3)
Block(4,57,7,STONE:3)
Block(4,57,8,STONE:3)
Block(4,58,5,STONE:3)
Block(4,58,6,STONE:3)
Block(4,58,7,STONE:3)
Block(4,58,8,STONE:3)
Block(4,59,5,STONE:3)
Block(4,59,6,STONE:3)
Block(4,59,7,STONE:3)
Block(4,59,8,STONE:3)
Block(4,60,5,STONE:3)
Block(4,60,6,STONE:3)
Block(4,60,7,STONE:3)
Block(4,60,8,STONE:3)
Block(4,61,4,STONE:3)
Block(4,61,5,STONE:3)
Block(4,61,6,STONE:3)
Block(4,61,7,STONE:3)
Block(4,61,8,STONE:3)
Block(4,62,3,STONE:3)
Block(4,62,4,STONE:3)
Block(4,62,5,STONE:3)
Block(4,62,6,STONE:3)
Block(4,62,7,STONE:3)
Block(4,62,8,STONE:3)
Block(4,63,2,STONE:3)
Block(4,63,3,STONE:3)
Block(4,63,4,STONE:3)
Block(4,63,5,STONE:3)
Block(4,63,6,STONE:3)
Block(4,63,7,STONE:3)
Block(4,63,8,STONE:3)
Block(4,64,2,STONE:3)
Block(4,64,3,STONE:3)
Block(4,64,4,STONE:3)
Block(4,64,5,STONE:3)
Block(4,64,6,STONE:3)
Block(4,64,7,STONE:3)
Block(4,64,8,STONE:3)
Block(4,65,2,STONE:3)
Block(4,65,3,STONE:3)
Block(4,65,4,STONE:3)
Block(4,65,5,STONE:3)
Block(4,65,6,STONE:3)
Block(4,65,7,STONE:3)
Block(4,65,8,STONE:3)
Block(4,66,1,STONE:3)
Block(4,66,2,STONE:3)
Block(4,66,3,STONE:3)
Block(4,66,4,STONE:3)
Block(4,66,5,STONE:3)
Block(4,66,6,STONE:3)
Block(4,66,7,STONE:3)
Block(4,66,8,STONE:3)
Block(4,67,3,STONE:3)
Block(4,67,4,STONE:3)
Block(4,67,5,STONE:3)
Block(4,67,6,STONE:3)
Block(4,67,7,STONE:3)
Block(4,67,8,STONE:3)
Block(4,68,4,STONE:3)
Block(4,68,5,STONE:3)
Block(4,68,6,STONE:3)
Block(4,68,7,STONE:3)
Block(4,68,8,STONE:3)
Block(4,69,3,STONE:3)
Block(4,69,4,STONE:3)
Block(4,69,5,STONE:3)
Block(4,69,6,STONE:3)
Block(4,69,7,STONE:3)
Block(4,69,8,STONE:3)
Block(4,70,3,STONE:3)
Block(4,70,4,STONE:3)
Block(4,70,5,STONE:3)
Block(4,70,6,STONE:3)
Block(4,70,7,STONE:3)
Block(4,70,8,STONE:3)
Block(4,71,2,STONE:3)
Block(4,71,3,STONE:3)
Block(4,71,4,STONE:3)
Block(4,71,5,STONE:3)
Block(4,71,6,STONE:3)
Block(4,71,7,STONE:3)
Block(4,71,8,STONE:3)
Block(4,72,2,STONE:3)
Block(4,72,3,STONE:3)
Block(4,72,4,STONE:3)
Block(4,72,5,STONE:3)
Block(4,72,6,STONE:3)
Block(4,72,7,STONE:3)
Block(4,72,8,STONE:3)
Block(4,73,1,STONE:3)
Block(4,73,2,STONE:3)
Block(4,73,3,STONE:3)
Block(4,73,4,STONE:3)
Block(4,73,5,STONE:3)
Block(4,73,6,STONE:3)
Block(4,73,7,STONE:3)
Block(4,73,8,STONE:3)
Block(4,74,0,STONE:3)
Block(4,74,1,STONE:3)
Block(4,74,2,STONE:3)
Block(4,74,3,STONE:3)
Block(4,74,4,STONE:3)
Block(4,74,5,STONE:3)
Block(4,74,6,STONE:3)
Block(4,74,7,STONE:3)
Block(4,74,8,STONE:3)
Block(4,75,-1,STONE:3)
Block(4,75,0,STONE:3)
Block(4,75,1,STONE:3)
Block(4,75,2,STONE:3)
Block(4,75,3,STONE:3)
Block(4,75,4,STONE:3)
Block(4,75,5,STONE:3)
Block(4,75,6,STONE:3)
Block(4,75,7,STONE:3)
Block(4,75,8,STONE:3)
Block(4,76,-1,STONE:3)
Block(4,76,0,STONE:3)
Block(4,76,1,STONE:3)
Block(4,76,2,STONE:3)
Block(4,76,3,STONE:3)
Block(4,76,4,STONE:3)
Block(4,76,5,STONE:3)
Block(4,76,6,STONE:3)
Block(4,76,7,STONE:3)
Block(4,76,8,STONE:3)
Block(4,77,-1,STONE:3)
Block(4,77,0,STONE:3)
Block(4,77,1,STONE:3)
Block(4,77,2,STONE:3)
Block(4,77,3,STONE:3)
Block(4,77,4,STONE:3)
Block(4,77,5,STONE:3)
Block(4,77,6,STONE:3)
Block(4,77,7,STONE:3)
Block(4,77,8,STONE:3)
Block(4,78,0,STONE:3)
Block(4,78,1,STONE:3)
Block(4,78,2,STONE:3)
Block(4,78,3,STONE:3)
Block(4,78,4,STONE:3)
Block(4,78,5,STONE:3)
Block(4,78,6,STONE:3)
Block(4,78,7,STONE:3)
Block(4,78,8,STONE:3)
Block(4,79,2,STONE:3)
Block(4,79,3,STONE:3)
Block(4,79,4,STONE:3)
Block(4,79,5,STONE:3)
Block(4,79,6,STONE:3)
Block(4,79,7,STONE:3)
Block(4,79,8,STONE:3)
Block(4,80,2,STONE:3)
Block(4,80,3,STONE:3)
Block(4,80,4,STONE:3)
Block(4,80,5,STONE:3)
Block(4,80,6,STONE:3)
Block(4,80,7,STONE:3)
Block(4,80,8,STONE:3)
Block(4,81,2,STONE:3)
Block(4,81,3,STONE:3)
Block(4,81,6,STONE:3)
Block(4,81,7,STONE:3)
Block(4,81,8,STONE:3)
Block(4,82,7,STONE:3)
Block(4,82,8,STONE:3)
Block(4,83,7,STONE:3)
Block(4,83,8,STONE:3)
Block(5,46,8,OBSIDIAN:0)
Block(5,47,7,OBSIDIAN:0)
Block(5,47,8,OBSIDIAN:0)
Block(5,48,7,STONE:3)
Block(5,48,8,OBSIDIAN:0)
Block(5,49,4,STONE:3)
Block(5,49,5,STONE:3)
Block(5,49,6,STONE:3)
Block(5,49,7,STONE:3)
Block(5,49,8,STONE:3)
Block(5,50,5,STONE:3)
Block(5,50,6,STONE:3)
Block(5,50,7,STONE:3)
Block(5,50,8,STONE:3)
Block(5,51,6,STONE:3)
Block(5,51,7,STONE:3)
Block(5,51,8,STONE:3)
Block(5,52,5,STONE:3)
Block(5,52,6,STONE:3)
Block(5,52,7,STONE:3)
Block(5,52,8,STONE:3)
Block(5,53,5,STONE:3)
Block(5,53,6,STONE:3)
Block(5,53,7,STONE:3)
Block(5,53,8,STONE:3)
Block(5,54,6,STONE:3)
Block(5,54,7,STONE:3)
Block(5,54,8,STONE:3)
Block(5,55,6,STONE:3)
Block(5,55,7,STONE:3)
Block(5,55,8,STONE:3)
Block(5,56,6,STONE:3)
Block(5,56,7,STONE:3)
Block(5,56,8,STONE:3)
Block(5,57,5,STONE:3)
Block(5,57,6,STONE:3)
Block(5,57,7,STONE:3)
Block(5,57,8,STONE:3)
Block(5,58,5,STONE:3)
Block(5,58,6,STONE:3)
Block(5,58,7,STONE:3)
Block(5,58,8,STONE:3)
Block(5,59,4,STONE:3)
Block(5,59,5,STONE:3)
Block(5,59,6,STONE:3)
Block(5,59,7,STONE:3)
Block(5,59,8,STONE:3)
Block(5,60,4,STONE:3)
Block(5,60,5,STONE:3)
Block(5,60,6,STONE:3)
Block(5,60,7,STONE:3)
Block(5,60,8,STONE:3)
Block(5,61,3,STONE:3)
Block(5,61,4,STONE:3)
Block(5,61,5,STONE:3)
Block(5,61,6,STONE:3)
Block(5,61,7,STONE:3)
Block(5,61,8,STONE:3)
Block(5,62,2,STONE:3)
Block(5,62,3,STONE:3)
Block(5,62,4,STONE:3)
Block(5,62,5,STONE:3)
Block(5,62,6,STONE:3)
Block(5,62,7,STONE:3)
Block(5,62,8,STONE:3)
Block(5,63,1,STONE:3)
Block(5,63,2,STONE:3)
Block(5,63,3,STONE:3)
Block(5,63,4,STONE:3)
Block(5,63,5,STONE:3)
Block(5,63,6,STONE:3)
Block(5,63,7,STONE:3)
Block(5,63,8,STONE:3)
Block(5,64,1,STONE:3)
Block(5,64,2,STONE:3)
Block(5,64,3,STONE:3)
Block(5,64,4,STONE:3)
Block(5,64,5,STONE:3)
Block(5,64,6,STONE:3)
Block(5,64,7,STONE:3)
Block(5,64,8,STONE:3)
Block(5,65,1,STONE:3)
Block(5,65,2,STONE:3)
Block(5,65,3,STONE:3)
Block(5,65,4,STONE:3)
Block(5,65,5,STONE:3)
Block(5,65,6,STONE:3)
Block(5,65,7,STONE:3)
Block(5,65,8,STONE:3)
Block(5,66,0,STONE:3)
Block(5,66,1,STONE:3)
Block(5,66,2,STONE:3)
Block(5,66,3,STONE:3)
Block(5,66,4,STONE:3)
Block(5,66,5,STONE:3)
Block(5,66,6,STONE:3)
Block(5,66,7,OBSIDIAN:0)
Block(5,66,8,OBSIDIAN:0)
Block(5,67,2,STONE:3)
Block(5,67,3,STONE:3)
Block(5,67,4,STONE:3)
Block(5,67,5,STONE:3)
Block(5,67,6,STONE:3)
Block(5,67,7,STONE:3)
Block(5,67,8,OBSIDIAN:0)
Block(5,68,3,STONE:3)
Block(5,68,4,STONE:3)
Block(5,68,5,STONE:3)
Block(5,68,6,STONE:3)
Block(5,68,7,STONE:3)
Block(5,68,8,STONE:3)
Block(5,69,2,STONE:3)
Block(5,69,3,STONE:3)
Block(5,69,4,STONE:3)
Block(5,69,5,STONE:3)
Block(5,69,6,STONE:3)
Block(5,69,7,STONE:3)
Block(5,69,8,STONE:3)
Block(5,70,2,STONE:3)
Block(5,70,3,STONE:3)
Block(5,70,4,STONE:3)
Block(5,70,5,STONE:3)
Block(5,70,6,STONE:3)
Block(5,70,7,STONE:3)
Block(5,70,8,STONE:3)
Block(5,71,2,STONE:3)
Block(5,71,3,STONE:3)
Block(5,71,4,STONE:3)
Block(5,71,5,STONE:3)
Block(5,71,6,STONE:3)
Block(5,71,7,STONE:3)
Block(5,71,8,STONE:3)
Block(5,72,1,STONE:3)
Block(5,72,2,STONE:3)
Block(5,72,3,STONE:3)
Block(5,72,4,STONE:3)
Block(5,72,5,STONE:3)
Block(5,72,6,STONE:3)
Block(5,72,7,STONE:3)
Block(5,72,8,STONE:3)
Block(5,73,0,STONE:3)
Block(5,73,1,STONE:3)
Block(5,73,2,STONE:3)
Block(5,73,3,STONE:3)
Block(5,73,4,STONE:3)
Block(5,73,5,STONE:3)
Block(5,73,6,STONE:3)
Block(5,73,7,STONE:3)
Block(5,73,8,STONE:3)
Block(5,74,-1,STONE:3)
Block(5,74,0,STONE:3)
Block(5,74,1,STONE:3)
Block(5,74,2,STONE:3)
Block(5,74,3,STONE:3)
Block(5,74,4,STONE:3)
Block(5,74,5,STONE:3)
Block(5,74,6,STONE:3)
Block(5,74,7,STONE:3)
Block(5,74,8,STONE:3)
Block(5,75,-2,STONE:3)
Block(5,75,-1,STONE:3)
Block(5,75,0,STONE:3)
Block(5,75,1,STONE:3)
Block(5,75,2,STONE:3)
Block(5,75,3,STONE:3)
Block(5,75,4,STONE:3)
Block(5,75,5,STONE:3)
Block(5,75,6,OBSIDIAN:0)
Block(5,75,7,OBSIDIAN:0)
Block(5,75,8,OBSIDIAN:0)
Block(5,76,-2,STONE:3)
Block(5,76,-1,STONE:3)
Block(5,76,0,STONE:3)
Block(5,76,1,STONE:3)
Block(5,76,2,STONE:3)
Block(5,76,3,STONE:3)
Block(5,76,4,STONE:3)
Block(5,76,5,STONE:3)
Block(5,76,6,STONE:3)
Block(5,76,7,STONE:3)
Block(5,76,8,STONE:3)
Block(5,77,-2,STONE:3)
Block(5,77,-1,STONE:3)
Block(5,77,0,STONE:3)
Block(5,77,1,STONE:3)
Block(5,77,2,STONE:3)
Block(5,77,3,STONE:3)
Block(5,77,4,STONE:3)
Block(5,77,5,STONE:3)
Block(5,77,6,STONE:3)
Block(5,77,7,STONE:3)
Block(5,77,8,STONE:3)
Block(5,78,-2,STONE:3)
Block(5,78,-1,STONE:3)
Block(5,78,0,STONE:3)
Block(5,78,1,STONE:3)
Block(5,78,2,STONE:3)
Block(5,78,3,STONE:3)
Block(5,78,4,STONE:3)
Block(5,78,5,STONE:3)
Block(5,78,6,STONE:3)
Block(5,78,7,STONE:3)
Block(5,78,8,STONE:3)
Block(5,79,-1,STONE:3)
Block(5,79,0,STONE:3)
Block(5,79,1,STONE:3)
Block(5,79,2,STONE:3)
Block(5,79,3,STONE:3)
Block(5,79,4,STONE:3)
Block(5,79,5,STONE:3)
Block(5,79,6,STONE:3)
Block(5,79,7,STONE:3)
Block(5,79,8,STONE:3)
Block(5,80,0,STONE:3)
Block(5,80,1,STONE:3)
Block(5,80,2,STONE:3)
Block(5,80,3,STONE:3)
Block(5,80,4,STONE:3)
Block(5,80,5,STONE:3)
Block(5,80,6,STONE:3)
Block(5,80,7,STONE:3)
Block(5,80,8,STONE:3)
Block(5,81,1,STONE:3)
Block(5,81,2,STONE:3)
Block(5,81,3,STONE:3)
Block(5,81,4,STONE:3)
Block(5,81,5,STONE:3)
Block(5,81,6,STONE:3)
Block(5,81,7,STONE:3)
Block(5,81,8,STONE:3)
Block(5,82,1,STONE:3)
Block(5,82,2,STONE:3)
Block(5,82,3,STONE:3)
Block(5,82,4,STONE:3)
Block(5,82,5,STONE:3)
Block(5,82,6,STONE:3)
Block(5,82,7,STONE:3)
Block(5,82,8,STONE:3)
Block(5,83,4,STONE:3)
Block(5,83,5,STONE:3)
Block(5,83,6,STONE:3)
Block(5,83,7,STONE:3)
Block(5,83,8,STONE:3)
Block(5,84,5,STONE:3)
Block(5,84,6,STONE:3)
Block(5,84,7,STONE:3)
Block(5,84,8,STONE:3)
Block(5,85,0,STONE:3)
Block(5,85,3,STONE:3)
Block(5,85,4,STONE:3)
Block(5,85,5,STONE:3)
Block(5,86,-1,STONE:3)
Block(5,86,0,STONE:3)
Block(5,86,3,STONE:3)
Block(5,87,-1,STONE:3)
Block(5,87,0,STONE:3)
Block(6,45,7,OBSIDIAN:0)
Block(6,45,8,OBSIDIAN:0)
Block(6,46,6,OBSIDIAN:0)
Block(6,46,7,OBSIDIAN:0)
Block(6,46,8,OBSIDIAN:0)
Block(6,47,5,STONE:3)
Block(6,47,6,STONE:3)
Block(6,47,7,OBSIDIAN:0)
Block(6,47,8,OBSIDIAN:0)
Block(6,48,4,STONE:3)
Block(6,48,5,STONE:3)
Block(6,48,6,STONE:3)
Block(6,48,7,STONE:3)
Block(6,48,8,OBSIDIAN:0)
Block(6,49,4,STONE:3)
Block(6,49,5,STONE:3)
Block(6,49,6,STONE:3)
Block(6,49,7,STONE:3)
Block(6,49,8,STONE:3)
Block(6,50,4,STONE:3)
Block(6,50,5,STONE:3)
Block(6,50,6,STONE:3)
Block(6,50,7,STONE:3)
Block(6,50,8,STONE:3)
Block(6,51,4,STONE:3)
Block(6,51,5,STONE:3)
Block(6,51,6,STONE:3)
Block(6,51,7,STONE:3)
Block(6,51,8,STONE:3)
Block(6,52,5,STONE:3)
Block(6,52,6,STONE:3)
Block(6,52,7,STONE:3)
Block(6,52,8,STONE:3)
Block(6,53,5,STONE:3)
Block(6,53,6,STONE:3)
Block(6,53,7,STONE:3)
Block(6,53,8,STONE:3)
Block(6,54,5,STONE:3)
Block(6,54,6,STONE:3)
Block(6,54,7,STONE:3)
Block(6,54,8,STONE:3)
Block(6,55,6,STONE:3)
Block(6,55,7,STONE:3)
Block(6,55,8,STONE:3)
Block(6,56,5,STONE:3)
Block(6,56,6,STONE:3)
Block(6,56,7,STONE:3)
Block(6,56,8,STONE:3)
Block(6,57,5,STONE:3)
Block(6,57,6,STONE:3)
Block(6,57,7,STONE:3)
Block(6,57,8,STONE:3)
Block(6,58,4,STONE:3)
Block(6,58,5,STONE:3)
Block(6,58,6,STONE:3)
Block(6,58,7,STONE:3)
Block(6,58,8,STONE:3)
Block(6,59,3,STONE:3)
Block(6,59,4,STONE:3)
Block(6,59,5,STONE:3)
Block(6,59,6,STONE:3)
Block(6,59,7,STONE:3)
Block(6,59,8,STONE:3)
Block(6,60,3,STONE:3)
Block(6,60,4,STONE:3)
Block(6,60,5,STONE:3)
Block(6,60,6,STONE:3)
Block(6,60,7,STONE:3)
Block(6,60,8,STONE:3)
Block(6,61,2,STONE:3)
Block(6,61,3,STONE:3)
Block(6,61,4,STONE:3)
Block(6,61,5,STONE:3)
Block(6,61,6,STONE:3)
Block(6,61,7,STONE:3)
Block(6,61,8,STONE:3)
Block(6,62,1,STONE:3)
Block(6,62,2,STONE:3)
Block(6,62,3,STONE:3)
Block(6,62,4,STONE:3)
Block(6,62,5,STONE:3)
Block(6,62,6,STONE:3)
Block(6,62,7,STONE:3)
Block(6,62,8,STONE:3)
Block(6,63,0,STONE:3)
Block(6,63,1,STONE:3)
Block(6,63,2,STONE:3)
Block(6,63,3,STONE:3)
Block(6,63,4,STONE:3)
Block(6,63,5,STONE:3)
Block(6,63,6,STONE:3)
Block(6,63,7,STONE:3)
Block(6,63,8,STONE:3)
Block(6,64,0,STONE:3)
Block(6,64,1,STONE:3)
Block(6,64,2,STONE:3)
Block(6,64,3,STONE:3)
Block(6,64,4,STONE:3)
Block(6,64,5,STONE:3)
Block(6,64,6,STONE:3)
Block(6,64,7,STONE:3)
Block(6,64,8,OBSIDIAN:0)
Block(6,65,0,STONE:3)
Block(6,65,1,STONE:3)
Block(6,65,2,STONE:3)
Block(6,65,3,STONE:3)
Block(6,65,4,STONE:3)
Block(6,65,5,STONE:3)
Block(6,65,6,STONE:3)
Block(6,65,7,OBSIDIAN:0)
Block(6,65,8,OBSIDIAN:0)
Block(6,66,1,STONE:3)
Block(6,66,2,STONE:3)
Block(6,66,3,STONE:3)
Block(6,66,4,STONE:3)
Block(6,66,5,STONE:3)
Block(6,66,6,STONE:3)
Block(6,66,7,OBSIDIAN:0)
Block(6,66,8,OBSIDIAN:0)
Block(6,67,1,STONE:3)
Block(6,67,2,STONE:3)
Block(6,67,3,STONE:3)
Block(6,67,4,STONE:3)
Block(6,67,5,STONE:3)
Block(6,67,6,STONE:3)
Block(6,67,7,OBSIDIAN:0)
Block(6,67,8,OBSIDIAN:0)
Block(6,68,2,STONE:3)
Block(6,68,3,STONE:3)
Block(6,68,4,STONE:3)
Block(6,68,5,STONE:3)
Block(6,68,6,STONE:3)
Block(6,68,7,STONE:3)
Block(6,68,8,OBSIDIAN:0)
Block(6,69,2,STONE:3)
Block(6,69,3,STONE:3)
Block(6,69,4,STONE:3)
Block(6,69,5,STONE:3)
Block(6,69,6,STONE:3)
Block(6,69,7,STONE:3)
Block(6,69,8,OBSIDIAN:0)
Block(6,70,2,STONE:3)
Block(6,70,3,STONE:3)
Block(6,70,4,STONE:3)
Block(6,70,5,STONE:3)
Block(6,70,6,STONE:3)
Block(6,70,7,STONE:3)
Block(6,70,8,OBSIDIAN:0)
Block(6,71,1,STONE:3)
Block(6,71,2,STONE:3)
Block(6,71,3,STONE:3)
Block(6,71,4,STONE:3)
Block(6,71,5,STONE:3)
Block(6,71,6,STONE:3)
Block(6,71,7,STONE:3)
Block(6,71,8,OBSIDIAN:0)
Block(6,72,0,STONE:3)
Block(6,72,1,STONE:3)
Block(6,72,2,STONE:3)
Block(6,72,3,STONE:3)
Block(6,72,4,STONE:3)
Block(6,72,5,STONE:3)
Block(6,72,6,STONE:3)
Block(6,72,7,STONE:3)
Block(6,72,8,OBSIDIAN:0)
Block(6,73,-1,STONE:3)
Block(6,73,0,STONE:3)
Block(6,73,1,STONE:3)
Block(6,73,2,STONE:3)
Block(6,73,3,STONE:3)
Block(6,73,4,STONE:3)
Block(6,73,5,STONE:3)
Block(6,73,6,STONE:3)
Block(6,73,7,OBSIDIAN:0)
Block(6,73,8,OBSIDIAN:0)
Block(6,74,-2,STONE:3)
Block(6,74,-1,STONE:3)
Block(6,74,0,STONE:3)
Block(6,74,1,STONE:3)
Block(6,74,2,STONE:3)
Block(6,74,3,STONE:3)
Block(6,74,4,STONE:3)
Block(6,74,5,STONE:3)
Block(6,74,6,STONE:3)
Block(6,74,7,OBSIDIAN:0)
Block(6,74,8,OBSIDIAN:0)
Block(6,75,-3,STONE:3)
Block(6,75,-2,STONE:3)
Block(6,75,-1,STONE:3)
Block(6,75,0,STONE:3)
Block(6,75,1,STONE:3)
Block(6,75,2,STONE:3)
Block(6,75,3,STONE:3)
Block(6,75,4,STONE:3)
Block(6,75,5,STONE:3)
Block(6,75,6,OBSIDIAN:0)
Block(6,75,7,OBSIDIAN:0)
Block(6,75,8,OBSIDIAN:0)
Block(6,76,-3,STONE:3)
Block(6,76,-2,STONE:3)
Block(6,76,-1,STONE:3)
Block(6,76,0,STONE:3)
Block(6,76,1,STONE:3)
Block(6,76,2,STONE:3)
Block(6,76,3,STONE:3)
Block(6,76,4,STONE:3)
Block(6,76,5,OBSIDIAN:0)
Block(6,76,6,OBSIDIAN:0)
Block(6,76,7,OBSIDIAN:0)
Block(6,76,8,OBSIDIAN:0)
Block(6,77,-4,STONE:3)
Block(6,77,-3,STONE:3)
Block(6,77,-2,STONE:3)
Block(6,77,-1,STONE:3)
Block(6,77,0,STONE:3)
Block(6,77,1,STONE:3)
Block(6,77,2,STONE:3)
Block(6,77,3,STONE:3)
Block(6,77,4,STONE:3)
Block(6,77,5,STONE:3)
Block(6,77,6,STONE:3)
Block(6,77,7,STONE:3)
Block(6,77,8,STONE:3)
Block(6,78,-4,STONE:3)
Block(6,78,-3,STONE:3)
Block(6,78,-2,STONE:3)
Block(6,78,-1,STONE:3)
Block(6,78,0,STONE:3)
Block(6,78,1,STONE:3)
Block(6,78,2,STONE:3)
Block(6,78,3,STONE:3)
Block(6,78,4,STONE:3)
Block(6,78,5,STONE:3)
Block(6,78,6,STONE:3)
Block(6,78,7,STONE:3)
Block(6,78,8,STONE:3)
Block(6,79,-3,STONE:3)
Block(6,79,-2,STONE:3)
Block(6,79,-1,STONE:3)
Block(6,79,0,STONE:3)
Block(6,79,1,STONE:3)
Block(6,79,2,STONE:3)
Block(6,79,3,STONE:3)
Block(6,79,4,STONE:3)
Block(6,79,5,STONE:3)
Block(6,79,6,STONE:3)
Block(6,79,7,STONE:3)
Block(6,79,8,STONE:3)
Block(6,80,-2,STONE:3)
Block(6,80,-1,STONE:3)
Block(6,80,0,STONE:3)
Block(6,80,1,STONE:3)
Block(6,80,2,STONE:3)
Block(6,80,3,STONE:3)
Block(6,80,4,STONE:3)
Block(6,80,5,STONE:3)
Block(6,80,6,STONE:3)
Block(6,80,7,STONE:3)
Block(6,80,8,STONE:3)
Block(6,81,-1,STONE:3)
Block(6,81,0,STONE:3)
Block(6,81,1,STONE:3)
Block(6,81,2,STONE:3)
Block(6,81,3,STONE:3)
Block(6,81,4,STONE:3)
Block(6,81,5,STONE:3)
Block(6,81,6,STONE:3)
Block(6,81,7,STONE:3)
Block(6,81,8,STONE:3)
Block(6,82,-1,STONE:3)
Block(6,82,0,STONE:3)
Block(6,82,1,STONE:3)
Block(6,82,2,STONE:3)
Block(6,82,3,STONE:3)
Block(6,82,4,STONE:3)
Block(6,82,5,STONE:3)
Block(6,82,6,STONE:3)
Block(6,82,7,STONE:3)
Block(6,82,8,STONE:3)
Block(6,83,-1,STONE:3)
Block(6,83,0,STONE:3)
Block(6,83,1,STONE:3)
Block(6,83,2,STONE:3)
Block(6,83,3,STONE:3)
Block(6,83,4,STONE:3)
Block(6,83,5,STONE:3)
Block(6,83,6,STONE:3)
Block(6,83,7,STONE:3)
Block(6,83,8,STONE:3)
Block(6,84,-1,STONE:3)
Block(6,84,0,STONE:3)
Block(6,84,1,STONE:3)
Block(6,84,2,STONE:3)
Block(6,84,3,STONE:3)
Block(6,84,4,STONE:3)
Block(6,84,5,STONE:3)
Block(6,84,6,STONE:3)
Block(6,84,7,STONE:3)
Block(6,84,8,OBSIDIAN:0)
Block(6,85,-1,STONE:3)
Block(6,85,0,STONE:3)
Block(6,85,1,STONE:3)
Block(6,85,2,STONE:3)
Block(6,85,3,STONE:3)
Block(6,85,4,STONE:3)
Block(6,85,5,STONE:3)
Block(6,85,6,STONE:3)
Block(6,85,7,STONE:3)
Block(6,85,8,OBSIDIAN:0)
Block(6,86,-2,STONE:3)
Block(6,86,-1,STONE:3)
Block(6,86,0,STONE:3)
Block(6,86,1,STONE:3)
Block(6,86,2,STONE:3)
Block(6,86,3,STONE:3)
Block(6,86,4,STONE:3)
Block(6,86,5,STONE:3)
Block(6,86,7,STONE:3)
Block(6,86,8,OBSIDIAN:0)
Block(6,87,-3,STONE:3)
Block(6,87,-2,STONE:3)
Block(6,87,-1,STONE:3)
Block(6,87,0,STONE:3)
Block(6,87,1,STONE:3)
Block(6,87,3,STONE:3)
Block(6,88,-1,STONE:3)
Block(6,88,0,STONE:3)
Block(7,34,8,MAGMA:0)
Block(7,35,7,MAGMA:0)
Block(7,35,8,MAGMA:0)
Block(7,36,6,MAGMA:0)
Block(7,36,7,MAGMA:0)
Block(7,36,8,MAGMA:0)
Block(7,37,5,OBSIDIAN:0)
Block(7,37,6,MAGMA:0)
Block(7,37,7,MAGMA:0)
Block(7,37,8,MAGMA:0)
Block(7,38,4,OBSIDIAN:0)
Block(7,38,5,OBSIDIAN:0)
Block(7,38,6,OBSIDIAN:0)
Block(7,38,7,OBSIDIAN:0)
Block(7,38,8,MAGMA:0)
Block(7,39,3,STONE:3)
Block(7,39,4,OBSIDIAN:0)
Block(7,39,5,OBSIDIAN:0)
Block(7,39,6,OBSIDIAN:0)
Block(7,39,7,OBSIDIAN:0)
Block(7,39,8,MAGMA:0)
Block(7,40,3,STONE:3)
Block(7,40,4,OBSIDIAN:0)
Block(7,40,5,OBSIDIAN:0)
Block(7,40,6,OBSIDIAN:0)
Block(7,40,7,OBSIDIAN:0)
Block(7,40,8,MAGMA:0)
Block(7,41,3,STONE:3)
Block(7,41,4,OBSIDIAN:0)
Block(7,41,5,OBSIDIAN:0)
Block(7,41,6,OBSIDIAN:0)
Block(7,41,7,OBSIDIAN:0)
Block(7,41,8,OBSIDIAN:0)
Block(7,42,5,OBSIDIAN:0)
Block(7,42,6,OBSIDIAN:0)
Block(7,42,7,OBSIDIAN:0)
Block(7,42,8,OBSIDIAN:0)
Block(7,43,6,OBSIDIAN:0)
Block(7,43,7,OBSIDIAN:0)
Block(7,43,8,OBSIDIAN:0)
Block(7,44,5,OBSIDIAN:0)
Block(7,44,6,OBSIDIAN:0)
Block(7,44,7,OBSIDIAN:0)
Block(7,44,8,OBSIDIAN:0)
Block(7,45,5,OBSIDIAN:0)
Block(7,45,6,OBSIDIAN:0)
Block(7,45,7,OBSIDIAN:0)
Block(7,45,8,OBSIDIAN:0)
Block(7,46,4,STONE:3)
Block(7,46,5,STONE:3)
Block(7,46,6,OBSIDIAN:0)
Block(7,46,7,OBSIDIAN:0)
Block(7,46,8,OBSIDIAN:0)
Block(7,47,3,STONE:3)
Block(7,47,4,STONE:3)
Block(7,47,5,STONE:3)
Block(7,47,6,STONE:3)
Block(7,47,7,OBSIDIAN:0)
Block(7,47,8,OBSIDIAN:0)
Block(7,48,3,STONE:3)
Block(7,48,4,STONE:3)
Block(7,48,5,STONE:3)
Block(7,48,6,STONE:3)
Block(7,48,7,STONE:3)
Block(7,48,8,OBSIDIAN:0)
Block(7,49,3,STONE:3)
Block(7,49,4,STONE:3)
Block(7,49,5,STONE:3)
Block(7,49,6,STONE:3)
Block(7,49,7,STONE:3)
Block(7,49,8,STONE:3)
Block(7,50,4,STONE:3)
Block(7,50,5,STONE:3)
Block(7,50,6,STONE:3)
Block(7,50,7,STONE:3)
Block(7,50,8,STONE:3)
Block(7,51,4,STONE:3)
Block(7,51,5,STONE:3)
Block(7,51,6,STONE:3)
Block(7,51,7,STONE:3)
Block(7,51,8,STONE:3)
Block(7,52,4,STONE:3)
Block(7,52,5,STONE:3)
Block(7,52,6,STONE:3)
Block(7,52,7,STONE:3)
Block(7,52,8,STONE:3)
Block(7,53,4,STONE:3)
Block(7,53,5,STONE:3)
Block(7,53,6,STONE:3)
Block(7,53,7,STONE:3)
Block(7,53,8,STONE:3)
Block(7,54,5,STONE:3)
Block(7,54,6,STONE:3)
Block(7,54,7,STONE:3)
Block(7,54,8,STONE:3)
Block(7,55,5,STONE:3)
Block(7,55,6,STONE:3)
Block(7,55,7,STONE:3)
Block(7,55,8,STONE:3)
Block(7,56,5,STONE:3)
Block(7,56,6,STONE:3)
Block(7,56,7,STONE:3)
Block(7,56,8,STONE:3)
Block(7,57,5,STONE:3)
Block(7,57,6,STONE:3)
Block(7,57,7,STONE:3)
Block(7,57,8,STONE:3)
Block(7,58,4,STONE:3)
Block(7,58,5,STONE:3)
Block(7,58,6,STONE:3)
Block(7,58,7,STONE:3)
Block(7,58,8,STONE:3)
Block(7,59,3,STONE:3)
Block(7,59,4,STONE:3)
Block(7,59,5,STONE:3)
Block(7,59,6,STONE:3)
Block(7,59,7,STONE:3)
Block(7,59,8,STONE:3)
Block(7,60,3,STONE:3)
Block(7,60,4,STONE:3)
Block(7,60,5,STONE:3)
Block(7,60,6,STONE:3)
Block(7,60,7,STONE:3)
Block(7,60,8,STONE:3)
Block(7,61,1,STONE:3)
Block(7,61,2,STONE:3)
Block(7,61,3,STONE:3)
Block(7,61,4,STONE:3)
Block(7,61,5,STONE:3)
Block(7,61,6,STONE:3)
Block(7,61,7,STONE:3)
Block(7,61,8,STONE:3)
Block(7,62,0,STONE:3)
Block(7,62,1,STONE:3)
Block(7,62,2,STONE:3)
Block(7,62,3,STONE:3)
Block(7,62,4,STONE:3)
Block(7,62,5,STONE:3)
Block(7,62,6,STONE:3)
Block(7,62,7,STONE:3)
Block(7,62,8,OBSIDIAN:0)
Block(7,63,0,STONE:3)
Block(7,63,1,STONE:3)
Block(7,63,2,STONE:3)
Block(7,63,3,STONE:3)
Block(7,63,4,STONE:3)
Block(7,63,5,STONE:3)
Block(7,63,6,STONE:3)
Block(7,63,7,OBSIDIAN:0)
Block(7,63,8,OBSIDIAN:0)
Block(7,64,0,STONE:3)
Block(7,64,1,STONE:3)
Block(7,64,2,STONE:3)
Block(7,64,3,STONE:3)
Block(7,64,4,STONE:3)
Block(7,64,5,STONE:3)
Block(7,64,6,STONE:3)
Block(7,64,7,OBSIDIAN:0)
Block(7,64,8,OBSIDIAN:0)
Block(7,65,0,STONE:3)
Block(7,65,1,STONE:3)
Block(7,65,2,STONE:3)
Block(7,65,3,STONE:3)
Block(7,65,4,STONE:3)
Block(7,65,5,STONE:3)
Block(7,65,6,STONE:3)
Block(7,65,7,OBSIDIAN:0)
Block(7,65,8,OBSIDIAN:0)
Block(7,66,1,STONE:3)
Block(7,66,2,STONE:3)
Block(7,66,3,STONE:3)
Block(7,66,4,STONE:3)
Block(7,66,5,STONE:3)
Block(7,66,6,OBSIDIAN:0)
Block(7,66,7,OBSIDIAN:0)
Block(7,66,8,OBSIDIAN:0)
Block(7,67,1,STONE:3)
Block(7,67,2,STONE:3)
Block(7,67,3,STONE:3)
Block(7,67,4,STONE:3)
Block(7,67,5,OBSIDIAN:0)
Block(7,67,6,OBSIDIAN:0)
Block(7,67,7,OBSIDIAN:0)
Block(7,67,8,OBSIDIAN:0)
Block(7,68,1,STONE:3)
Block(7,68,2,STONE:3)
Block(7,68,3,STONE:3)
Block(7,68,4,STONE:3)
Block(7,68,5,STONE:3)
Block(7,68,6,OBSIDIAN:0)
Block(7,68,7,OBSIDIAN:0)
Block(7,68,8,OBSIDIAN:0)
Block(7,69,1,STONE:3)
Block(7,69,2,STONE:3)
Block(7,69,3,STONE:3)
Block(7,69,4,STONE:3)
Block(7,69,5,STONE:3)
Block(7,69,6,STONE:3)
Block(7,69,7,OBSIDIAN:0)
Block(7,69,8,OBSIDIAN:0)
Block(7,70,1,STONE:3)
Block(7,70,2,STONE:3)
Block(7,70,3,STONE:3)
Block(7,70,4,STONE:3)
Block(7,70,5,STONE:3)
Block(7,70,6,STONE:3)
Block(7,70,7,OBSIDIAN:0)
Block(7,70,8,OBSIDIAN:0)
Block(7,71,0,STONE:3)
Block(7,71,1,STONE:3)
Block(7,71,2,STONE:3)
Block(7,71,3,STONE:3)
Block(7,71,4,STONE:3)
Block(7,71,5,STONE:3)
Block(7,71,6,STONE:3)
Block(7,71,7,OBSIDIAN:0)
Block(7,71,8,OBSIDIAN:0)
Block(7,72,-1,STONE:3)
Block(7,72,0,STONE:3)
Block(7,72,1,STONE:3)
Block(7,72,2,STONE:3)
Block(7,72,3,STONE:3)
Block(7,72,4,STONE:3)
Block(7,72,5,STONE:3)
Block(7,72,6,STONE:3)
Block(7,72,7,OBSIDIAN:0)
Block(7,72,8,OBSIDIAN:0)
Block(7,73,-2,STONE:3)
Block(7,73,-1,STONE:3)
Block(7,73,0,STONE:3)
Block(7,73,1,STONE:3)
Block(7,73,2,STONE:3)
Block(7,73,3,STONE:3)
Block(7,73,4,STONE:3)
Block(7,73,5,STONE:3)
Block(7,73,6,STONE:3)
Block(7,73,7,OBSIDIAN:0)
Block(7,73,8,OBSIDIAN:0)
Block(7,74,-4,STONE:3)
Block(7,74,-3,STONE:3)
Block(7,74,-2,STONE:3)
Block(7,74,-1,STONE:3)
Block(7,74,0,STONE:3)
Block(7,74,1,STONE:3)
Block(7,74,2,STONE:3)
Block(7,74,3,STONE:3)
Block(7,74,4,STONE:3)
Block(7,74,5,STONE:3)
Block(7,74,6,OBSIDIAN:0)
Block(7,74,7,OBSIDIAN:0)
Block(7,74,8,OBSIDIAN:0)
Block(7,75,-4,STONE:3)
Block(7,75,-3,STONE:3)
Block(7,75,-2,STONE:3)
Block(7,75,-1,STONE:3)
Block(7,75,0,STONE:3)
Block(7,75,1,STONE:3)
Block(7,75,2,STONE:3)
Block(7,75,3,STONE:3)
Block(7,75,4,STONE:3)
Block(7,75,5,STONE:3)
Block(7,75,6,OBSIDIAN:0)
Block(7,75,7,OBSIDIAN:0)
Block(7,75,8,OBSIDIAN:0)
Block(7,76,-5,STONE:3)
Block(7,76,-4,STONE:3)
Block(7,76,-3,STONE:3)
Block(7,76,-2,STONE:3)
Block(7,76,-1,STONE:3)
Block(7,76,0,STONE:3)
Block(7,76,1,STONE:3)
Block(7,76,2,STONE:3)
Block(7,76,3,STONE:3)
Block(7,76,4,STONE:3)
Block(7,76,5,OBSIDIAN:0)
Block(7,76,6,OBSIDIAN:0)
Block(7,76,7,OBSIDIAN:0)
Block(7,76,8,OBSIDIAN:0)
Block(7,77,-4,STONE:3)
Block(7,77,-3,STONE:3)
Block(7,77,-2,STONE:3)
Block(7,77,-1,STONE:3)
Block(7,77,0,STONE:3)
Block(7,77,1,STONE:3)
Block(7,77,2,STONE:3)
Block(7,77,3,OBSIDIAN:0)
Block(7,77,4,OBSIDIAN:0)
Block(7,77,5,OBSIDIAN:0)
Block(7,77,6,OBSIDIAN:0)
Block(7,77,7,OBSIDIAN:0)
Block(7,77,8,OBSIDIAN:0)
Block(7,78,-4,STONE:3)
Block(7,78,-3,STONE:3)
Block(7,78,-2,STONE:3)
Block(7,78,-1,STONE:3)
Block(7,78,0,STONE:3)
Block(7,78,1,STONE:3)
Block(7,78,2,OBSIDIAN:0)
Block(7,78,3,STONE:3)
Block(7,78,4,STONE:3)
Block(7,78,5,STONE:3)
Block(7,78,6,STONE:3)
Block(7,78,7,OBSIDIAN:0)
Block(7,78,8,OBSIDIAN:0)
Block(7,79,-5,STONE:3)
Block(7,79,-4,STONE:3)
Block(7,79,-3,STONE:3)
Block(7,79,-2,STONE:3)
Block(7,79,-1,STONE:3)
Block(7,79,0,STONE:3)
Block(7,79,1,STONE:3)
Block(7,79,2,STONE:3)
Block(7,79,3,STONE:3)
Block(7,79,4,STONE:3)
Block(7,79,5,STONE:3)
Block(7,79,6,STONE:3)
Block(7,79,7,OBSIDIAN:0)
Block(7,79,8,OBSIDIAN:0)
Block(7,80,-4,STONE:3)
Block(7,80,-3,STONE:3)
Block(7,80,-2,STONE:3)
Block(7,80,-1,STONE:3)
Block(7,80,0,STONE:3)
Block(7,80,1,STONE:3)
Block(7,80,2,STONE:3)
Block(7,80,3,STONE:3)
Block(7,80,4,STONE:3)
Block(7,80,5,STONE:3)
Block(7,80,6,STONE:3)
Block(7,80,7,OBSIDIAN:0)
Block(7,80,8,OBSIDIAN:0)
Block(7,81,-3,STONE:3)
Block(7,81,-2,STONE:3)
Block(7,81,-1,STONE:3)
Block(7,81,0,STONE:3)
Block(7,81,1,STONE:3)
Block(7,81,2,STONE:3)
Block(7,81,3,STONE:3)
Block(7,81,4,STONE:3)
Block(7,81,5,STONE:3)
Block(7,81,6,STONE:3)
Block(7,81,7,OBSIDIAN:0)
Block(7,81,8,OBSIDIAN:0)
Block(7,82,-3,STONE:3)
Block(7,82,-2,STONE:3)
Block(7,82,-1,STONE:3)
Block(7,82,0,STONE:3)
Block(7,82,1,STONE:3)
Block(7,82,2,STONE:3)
Block(7,82,3,STONE:3)
Block(7,82,4,STONE:3)
Block(7,82,5,STONE:3)
Block(7,82,6,STONE:3)
Block(7,82,7,OBSIDIAN:0)
Block(7,82,8,STONE:3)
Block(7,83,-2,STONE:3)
Block(7,83,-1,STONE:3)
Block(7,83,0,STONE:3)
Block(7,83,1,STONE:3)
Block(7,83,2,STONE:3)
Block(7,83,3,STONE:3)
Block(7,83,4,STONE:3)
Block(7,83,5,STONE:3)
Block(7,83,6,STONE:3)
Block(7,83,7,STONE:3)
Block(7,83,8,STONE:3)
Block(7,84,-2,STONE:3)
Block(7,84,-1,STONE:3)
Block(7,84,0,STONE:3)
Block(7,84,1,STONE:3)
Block(7,84,2,STONE:3)
Block(7,84,3,STONE:3)
Block(7,84,4,STONE:3)
Block(7,84,5,STONE:3)
Block(7,84,6,STONE:3)
Block(7,84,7,STONE:3)
Block(7,84,8,OBSIDIAN:0)
Block(7,85,-4,STONE:3)
Block(7,85,-3,STONE:3)
Block(7,85,-2,STONE:3)
Block(7,85,-1,STONE:3)
Block(7,85,0,STONE:3)
Block(7,85,1,STONE:3)
Block(7,85,2,STONE:3)
Block(7,85,3,STONE:3)
Block(7,85,4,STONE:3)
Block(7,85,5,STONE:3)
Block(7,85,6,STONE:3)
Block(7,85,7,STONE:3)
Block(7,85,8,OBSIDIAN:0)
Block(7,86,-3,STONE:3)
Block(7,86,-2,STONE:3)
Block(7,86,-1,STONE:3)
Block(7,86,0,STONE:3)
Block(7,86,1,STONE:3)
Block(7,86,2,STONE:3)
Block(7,86,3,STONE:3)
Block(7,86,4,STONE:3)
Block(7,86,5,STONE:3)
Block(7,86,6,STONE:3)
Block(7,86,7,OBSIDIAN:0)
Block(7,86,8,OBSIDIAN:0)
Block(7,87,-3,STONE:3)
Block(7,87,-2,STONE:3)
Block(7,87,-1,STONE:3)
Block(7,87,0,STONE:3)
Block(7,87,1,STONE:3)
Block(7,87,2,STONE:3)
Block(7,87,3,STONE:3)
Block(7,87,4,STONE:3)
Block(7,87,5,STONE:3)
Block(7,87,6,STONE:3)
Block(7,87,7,OBSIDIAN:0)
Block(7,87,8,OBSIDIAN:0)
Block(7,88,-3,STONE:3)
Block(7,88,-2,STONE:3)
Block(7,88,-1,STONE:3)
Block(7,88,0,STONE:3)
Block(7,88,6,STONE:3)
Block(7,88,7,OBSIDIAN:0)
Block(7,88,8,OBSIDIAN:0)
Block(7,89,-1,STONE:3)
Block(7,89,0,STONE:3)
Block(7,90,0,STONE:3)

#######################################################################
# +-----------------------------------------------------------------+ #
# |                             Branches                            | #
# +-----------------------------------------------------------------+ #
#######################################################################

Branch(16,0,0,true,Amethyst_BigC2R3,NORTH,100.0,0)

#######################################################################
# +-----------------------------------------------------------------+ #
# |                             Entities                            | #
# +-----------------------------------------------------------------+ #
#######################################################################


#######################################################################
# +-----------------------------------------------------------------+ #
# |                            Particles                            | #
# +-----------------------------------------------------------------+ #
#######################################################################


#######################################################################
# +-----------------------------------------------------------------+ #
# |                             Spawners                            | #
# +-----------------------------------------------------------------+ #
#######################################################################


#######################################################################
# +-----------------------------------------------------------------+ #
# |                             ModData                             | #
# +-----------------------------------------------------------------+ #
#######################################################################

