
#######################################################################
# +-----------------------------------------------------------------+ #
# |                            BO4 object                           | #
# +-----------------------------------------------------------------+ #
#######################################################################

Author: NLBlackEagle

Description: No description given

SettingsMode: WriteWithoutComments


#######################################################################
# +-----------------------------------------------------------------+ #
# |                          Main settings                          | #
# +-----------------------------------------------------------------+ #
#######################################################################

Frequency: 0

SpawnHeight: highestBlock

UseCenterForHighestBlock: true

##############################
# Height Limits for the BO4. #
##############################

MinHeight: 0

MaxHeight: 255

InheritBO3: 

InheritBO3Rotation: NORTH

OverrideChildSettings: true

OverrideParentHeight: false

CanOverride: false

BranchFrequency: 0

BranchFrequencyGroup: 

MustBeBelowOther: false

MustBeInside: 

CannotBeInside: 

ReplacesBO3: 

MustBeInsideWorldBorders: false

CanSpawnOnWater: true

SpawnOnWaterOnly: false

SpawnUnderWater: false

SpawnAtWaterLevel: false

HeightOffset: 0

RemoveAir: true

ReplaceAbove: 

ReplaceBelow: 

ReplaceWithBiomeBlocks: true

ReplaceWithSurfaceBlock: GRASS

ReplaceWithGroundBlock: DIRT

ReplaceWithStoneBlock: STONE

SmoothRadius: 0

SmoothHeightOffset: 0

SmoothStartTop: false

SmoothStartWood: false

SmoothingSurfaceBlock: 

SmoothingGroundBlock: 

BO3Group: 

IsSpawnPoint: false

DoReplaceBlocks: true


#######################################################################
# +-----------------------------------------------------------------+ #
# |                              Blocks                             | #
# +-----------------------------------------------------------------+ #
#######################################################################

Block(-8,18,8,OBSIDIAN:0)
Block(-8,19,6,OBSIDIAN:0)
Block(-8,19,7,OBSIDIAN:0)
Block(-8,19,8,OBSIDIAN:0)
Block(-8,20,4,STONE:3)
Block(-8,20,5,STONE:3)
Block(-8,20,6,OBSIDIAN:0)
Block(-8,20,7,OBSIDIAN:0)
Block(-8,20,8,OBSIDIAN:0)
Block(-8,21,0,STONE:3)
Block(-8,21,1,STONE:3)
Block(-8,21,2,STONE:3)
Block(-8,21,3,STONE:3)
Block(-8,21,4,STONE:3)
Block(-8,21,5,STONE:3)
Block(-8,21,6,STONE:3)
Block(-8,21,7,OBSIDIAN:0)
Block(-8,21,8,OBSIDIAN:0)
Block(-8,22,-1,STONE:3)
Block(-8,22,0,STONE:3)
Block(-8,22,1,STONE:3)
Block(-8,22,2,STONE:3)
Block(-8,22,3,STONE:3)
Block(-8,22,4,STONE:3)
Block(-8,22,5,STONE:3)
Block(-8,22,6,STONE:3)
Block(-8,22,7,STONE:3)
Block(-8,22,8,STONE:3)
Block(-8,23,-1,STONE:3)
Block(-8,23,0,STONE:3)
Block(-8,23,1,STONE:3)
Block(-8,23,2,STONE:3)
Block(-8,23,3,STONE:3)
Block(-8,23,4,STONE:3)
Block(-8,23,5,STONE:3)
Block(-8,23,6,STONE:3)
Block(-8,23,7,STONE:3)
Block(-8,23,8,STONE:3)
Block(-8,24,-1,STONE:3)
Block(-8,24,0,STONE:3)
Block(-8,24,1,STONE:3)
Block(-8,24,2,STONE:3)
Block(-8,24,3,STONE:3)
Block(-8,24,4,STONE:3)
Block(-8,24,5,STONE:3)
Block(-8,24,6,OBSIDIAN:0)
Block(-8,24,7,OBSIDIAN:0)
Block(-8,24,8,OBSIDIAN:0)
Block(-8,25,-2,STONE:3)
Block(-8,25,-1,STONE:3)
Block(-8,25,0,STONE:3)
Block(-8,25,1,STONE:3)
Block(-8,25,2,STONE:3)
Block(-8,25,3,STONE:3)
Block(-8,25,4,STONE:3)
Block(-8,25,5,STONE:3)
Block(-8,25,6,OBSIDIAN:0)
Block(-8,25,7,OBSIDIAN:0)
Block(-8,25,8,OBSIDIAN:0)
Block(-8,26,-4,STONE:3)
Block(-8,26,-3,STONE:3)
Block(-8,26,-2,STONE:3)
Block(-8,26,-1,STONE:3)
Block(-8,26,0,STONE:3)
Block(-8,26,1,STONE:3)
Block(-8,26,2,STONE:3)
Block(-8,26,3,STONE:3)
Block(-8,26,4,STONE:3)
Block(-8,26,5,STONE:3)
Block(-8,26,6,OBSIDIAN:0)
Block(-8,26,7,OBSIDIAN:0)
Block(-8,26,8,OBSIDIAN:0)
Block(-8,27,-5,STONE:3)
Block(-8,27,-4,STONE:3)
Block(-8,27,-3,STONE:3)
Block(-8,27,-2,STONE:3)
Block(-8,27,-1,STONE:3)
Block(-8,27,0,STONE:3)
Block(-8,27,1,STONE:3)
Block(-8,27,2,STONE:3)
Block(-8,27,3,STONE:3)
Block(-8,27,4,STONE:3)
Block(-8,27,5,STONE:3)
Block(-8,27,6,OBSIDIAN:0)
Block(-8,27,7,OBSIDIAN:0)
Block(-8,27,8,OBSIDIAN:0)
Block(-8,28,-6,STONE:3)
Block(-8,28,-5,STONE:3)
Block(-8,28,-4,STONE:3)
Block(-8,28,-3,STONE:3)
Block(-8,28,-2,STONE:3)
Block(-8,28,-1,STONE:3)
Block(-8,28,0,STONE:3)
Block(-8,28,1,STONE:3)
Block(-8,28,2,STONE:3)
Block(-8,28,3,STONE:3)
Block(-8,28,4,STONE:3)
Block(-8,28,5,STONE:3)
Block(-8,28,6,OBSIDIAN:0)
Block(-8,28,7,OBSIDIAN:0)
Block(-8,28,8,OBSIDIAN:0)
Block(-8,29,-6,STONE:3)
Block(-8,29,-5,STONE:3)
Block(-8,29,-4,STONE:3)
Block(-8,29,-3,STONE:3)
Block(-8,29,-2,STONE:3)
Block(-8,29,-1,STONE:3)
Block(-8,29,0,STONE:3)
Block(-8,29,1,STONE:3)
Block(-8,29,2,STONE:3)
Block(-8,29,3,STONE:3)
Block(-8,29,4,STONE:3)
Block(-8,29,5,OBSIDIAN:0)
Block(-8,29,6,OBSIDIAN:0)
Block(-8,29,7,OBSIDIAN:0)
Block(-8,29,8,OBSIDIAN:0)
Block(-8,30,-7,STONE:3)
Block(-8,30,-6,STONE:3)
Block(-8,30,-5,STONE:3)
Block(-8,30,-4,STONE:3)
Block(-8,30,-3,STONE:3)
Block(-8,30,-2,STONE:3)
Block(-8,30,-1,STONE:3)
Block(-8,30,0,STONE:3)
Block(-8,30,1,OBSIDIAN:0)
Block(-8,30,2,OBSIDIAN:0)
Block(-8,30,3,OBSIDIAN:0)
Block(-8,30,4,OBSIDIAN:0)
Block(-8,30,5,OBSIDIAN:0)
Block(-8,30,6,OBSIDIAN:0)
Block(-8,30,7,OBSIDIAN:0)
Block(-8,30,8,STONE:3)
Block(-8,31,-7,STONE:3)
Block(-8,31,-6,STONE:3)
Block(-8,31,-5,STONE:3)
Block(-8,31,-4,STONE:3)
Block(-8,31,-3,STONE:3)
Block(-8,31,-2,STONE:3)
Block(-8,31,-1,OBSIDIAN:0)
Block(-8,31,0,OBSIDIAN:0)
Block(-8,31,1,OBSIDIAN:0)
Block(-8,31,2,OBSIDIAN:0)
Block(-8,31,3,OBSIDIAN:0)
Block(-8,31,4,OBSIDIAN:0)
Block(-8,31,5,OBSIDIAN:0)
Block(-8,31,6,OBSIDIAN:0)
Block(-8,31,7,STONE:3)
Block(-8,31,8,STONE:3)
Block(-8,32,-7,STONE:3)
Block(-8,32,-6,STONE:3)
Block(-8,32,-5,STONE:3)
Block(-8,32,-4,STONE:3)
Block(-8,32,-3,OBSIDIAN:0)
Block(-8,32,-2,OBSIDIAN:0)
Block(-8,32,-1,OBSIDIAN:0)
Block(-8,32,0,OBSIDIAN:0)
Block(-8,32,1,OBSIDIAN:0)
Block(-8,32,2,OBSIDIAN:0)
Block(-8,32,3,OBSIDIAN:0)
Block(-8,32,4,OBSIDIAN:0)
Block(-8,32,5,STONE:3)
Block(-8,32,6,STONE:3)
Block(-8,32,7,STONE:3)
Block(-8,32,8,STONE:3)
Block(-8,33,-7,STONE:3)
Block(-8,33,-6,STONE:3)
Block(-8,33,-5,STONE:3)
Block(-8,33,-4,OBSIDIAN:0)
Block(-8,33,-3,OBSIDIAN:0)
Block(-8,33,-2,OBSIDIAN:0)
Block(-8,33,-1,OBSIDIAN:0)
Block(-8,33,0,OBSIDIAN:0)
Block(-8,33,1,OBSIDIAN:0)
Block(-8,33,2,OBSIDIAN:0)
Block(-8,33,3,OBSIDIAN:0)
Block(-8,33,4,STONE:3)
Block(-8,33,5,STONE:3)
Block(-8,33,6,STONE:3)
Block(-8,33,7,STONE:3)
Block(-8,33,8,STONE:3)
Block(-8,34,-7,STONE:3)
Block(-8,34,-6,STONE:3)
Block(-8,34,-5,STONE:3)
Block(-8,34,-4,OBSIDIAN:0)
Block(-8,34,-3,OBSIDIAN:0)
Block(-8,34,-2,OBSIDIAN:0)
Block(-8,34,-1,OBSIDIAN:0)
Block(-8,34,0,OBSIDIAN:0)
Block(-8,34,1,OBSIDIAN:0)
Block(-8,34,2,OBSIDIAN:0)
Block(-8,34,3,STONE:3)
Block(-8,34,4,STONE:3)
Block(-8,34,5,STONE:3)
Block(-8,34,6,STONE:3)
Block(-8,34,7,STONE:3)
Block(-8,34,8,STONE:3)
Block(-8,35,-7,STONE:3)
Block(-8,35,-6,STONE:3)
Block(-8,35,-5,STONE:3)
Block(-8,35,-4,OBSIDIAN:0)
Block(-8,35,-3,OBSIDIAN:0)
Block(-8,35,-2,OBSIDIAN:0)
Block(-8,35,-1,OBSIDIAN:0)
Block(-8,35,0,OBSIDIAN:0)
Block(-8,35,1,OBSIDIAN:0)
Block(-8,35,2,OBSIDIAN:0)
Block(-8,35,3,STONE:3)
Block(-8,35,4,STONE:3)
Block(-8,35,5,STONE:3)
Block(-8,35,6,STONE:3)
Block(-8,35,7,STONE:3)
Block(-8,35,8,STONE:3)
Block(-8,36,-7,STONE:3)
Block(-8,36,-6,STONE:3)
Block(-8,36,-5,OBSIDIAN:0)
Block(-8,36,-4,OBSIDIAN:0)
Block(-8,36,-3,OBSIDIAN:0)
Block(-8,36,-2,OBSIDIAN:0)
Block(-8,36,-1,OBSIDIAN:0)
Block(-8,36,0,OBSIDIAN:0)
Block(-8,36,1,OBSIDIAN:0)
Block(-8,36,2,OBSIDIAN:0)
Block(-8,36,3,STONE:3)
Block(-8,36,4,STONE:3)
Block(-8,36,5,STONE:3)
Block(-8,36,6,OBSIDIAN:0)
Block(-8,36,7,STONE:3)
Block(-8,36,8,STONE:3)
Block(-8,37,-7,STONE:3)
Block(-8,37,-6,STONE:3)
Block(-8,37,-5,OBSIDIAN:0)
Block(-8,37,-4,OBSIDIAN:0)
Block(-8,37,-3,OBSIDIAN:0)
Block(-8,37,-2,OBSIDIAN:0)
Block(-8,37,-1,OBSIDIAN:0)
Block(-8,37,0,OBSIDIAN:0)
Block(-8,37,1,OBSIDIAN:0)
Block(-8,37,2,OBSIDIAN:0)
Block(-8,37,3,OBSIDIAN:0)
Block(-8,37,4,OBSIDIAN:0)
Block(-8,37,5,OBSIDIAN:0)
Block(-8,37,6,STONE:3)
Block(-8,37,7,STONE:3)
Block(-8,37,8,STONE:3)
Block(-8,38,-7,STONE:3)
Block(-8,38,-6,STONE:3)
Block(-8,38,-5,STONE:3)
Block(-8,38,-4,OBSIDIAN:0)
Block(-8,38,-3,OBSIDIAN:0)
Block(-8,38,-2,OBSIDIAN:0)
Block(-8,38,-1,OBSIDIAN:0)
Block(-8,38,0,OBSIDIAN:0)
Block(-8,38,1,OBSIDIAN:0)
Block(-8,38,2,OBSIDIAN:0)
Block(-8,38,3,OBSIDIAN:0)
Block(-8,38,4,OBSIDIAN:0)
Block(-8,38,5,OBSIDIAN:0)
Block(-8,38,6,STONE:3)
Block(-8,38,7,STONE:3)
Block(-8,38,8,STONE:3)
Block(-8,39,-7,STONE:3)
Block(-8,39,-6,STONE:3)
Block(-8,39,-5,STONE:3)
Block(-8,39,-4,OBSIDIAN:0)
Block(-8,39,-3,OBSIDIAN:0)
Block(-8,39,-2,OBSIDIAN:0)
Block(-8,39,-1,OBSIDIAN:0)
Block(-8,39,0,OBSIDIAN:0)
Block(-8,39,1,OBSIDIAN:0)
Block(-8,39,2,OBSIDIAN:0)
Block(-8,39,3,OBSIDIAN:0)
Block(-8,39,4,OBSIDIAN:0)
Block(-8,39,5,OBSIDIAN:0)
Block(-8,40,-7,STONE:3)
Block(-8,40,-6,STONE:3)
Block(-8,40,-5,STONE:3)
Block(-8,40,-4,OBSIDIAN:0)
Block(-8,40,-3,OBSIDIAN:0)
Block(-8,40,-2,OBSIDIAN:0)
Block(-8,40,-1,OBSIDIAN:0)
Block(-8,40,0,OBSIDIAN:0)
Block(-8,40,1,OBSIDIAN:0)
Block(-8,40,2,OBSIDIAN:0)
Block(-8,40,3,OBSIDIAN:0)
Block(-8,40,4,OBSIDIAN:0)
Block(-8,41,-7,STONE:3)
Block(-8,41,-6,STONE:3)
Block(-8,41,-5,STONE:3)
Block(-8,41,-4,OBSIDIAN:0)
Block(-8,41,-3,OBSIDIAN:0)
Block(-8,41,-2,OBSIDIAN:0)
Block(-8,41,-1,OBSIDIAN:0)
Block(-8,41,0,OBSIDIAN:0)
Block(-8,41,1,OBSIDIAN:0)
Block(-8,41,2,OBSIDIAN:0)
Block(-8,41,3,OBSIDIAN:0)
Block(-8,42,-7,STONE:3)
Block(-8,42,-6,STONE:3)
Block(-8,42,-5,STONE:3)
Block(-8,42,-4,OBSIDIAN:0)
Block(-8,42,-3,OBSIDIAN:0)
Block(-8,42,-2,OBSIDIAN:0)
Block(-8,42,-1,OBSIDIAN:0)
Block(-8,42,0,OBSIDIAN:0)
Block(-8,42,1,OBSIDIAN:0)
Block(-8,42,2,OBSIDIAN:0)
Block(-8,43,-7,STONE:3)
Block(-8,43,-6,STONE:3)
Block(-8,43,-5,STONE:3)
Block(-8,43,-4,OBSIDIAN:0)
Block(-8,43,-3,OBSIDIAN:0)
Block(-8,43,-2,OBSIDIAN:0)
Block(-8,43,-1,OBSIDIAN:0)
Block(-8,43,0,OBSIDIAN:0)
Block(-8,43,1,OBSIDIAN:0)
Block(-8,43,2,OBSIDIAN:0)
Block(-8,44,-7,STONE:3)
Block(-8,44,-6,STONE:3)
Block(-8,44,-5,OBSIDIAN:0)
Block(-8,44,-4,OBSIDIAN:0)
Block(-8,44,-3,OBSIDIAN:0)
Block(-8,44,-2,OBSIDIAN:0)
Block(-8,44,-1,OBSIDIAN:0)
Block(-8,44,0,OBSIDIAN:0)
Block(-8,44,1,OBSIDIAN:0)
Block(-8,44,2,OBSIDIAN:0)
Block(-8,45,-7,STONE:3)
Block(-8,45,-6,STONE:3)
Block(-8,45,-5,OBSIDIAN:0)
Block(-8,45,-4,OBSIDIAN:0)
Block(-8,45,-3,OBSIDIAN:0)
Block(-8,45,-2,OBSIDIAN:0)
Block(-8,45,-1,OBSIDIAN:0)
Block(-8,45,0,OBSIDIAN:0)
Block(-8,46,-7,STONE:3)
Block(-8,46,-6,STONE:3)
Block(-8,46,-5,OBSIDIAN:0)
Block(-8,46,-4,OBSIDIAN:0)
Block(-8,46,-3,OBSIDIAN:0)
Block(-8,46,-2,OBSIDIAN:0)
Block(-8,46,-1,OBSIDIAN:0)
Block(-8,47,-7,STONE:3)
Block(-8,47,-6,STONE:3)
Block(-8,47,-5,OBSIDIAN:0)
Block(-8,47,-4,OBSIDIAN:0)
Block(-8,47,-3,OBSIDIAN:0)
Block(-8,47,-2,OBSIDIAN:0)
Block(-8,47,-1,OBSIDIAN:0)
Block(-8,48,-7,STONE:3)
Block(-8,48,-6,STONE:3)
Block(-8,48,-5,STONE:3)
Block(-8,48,-4,OBSIDIAN:0)
Block(-8,48,-3,OBSIDIAN:0)
Block(-8,48,-2,OBSIDIAN:0)
Block(-8,49,-7,STONE:3)
Block(-8,49,-6,STONE:3)
Block(-8,49,-5,STONE:3)
Block(-8,49,-4,OBSIDIAN:0)
Block(-8,49,-3,OBSIDIAN:0)
Block(-8,49,-2,OBSIDIAN:0)
Block(-8,50,-7,STONE:3)
Block(-8,50,-6,STONE:3)
Block(-8,50,-5,OBSIDIAN:0)
Block(-8,50,-4,OBSIDIAN:0)
Block(-8,50,-3,OBSIDIAN:0)
Block(-8,51,-7,STONE:3)
Block(-8,51,-6,STONE:3)
Block(-8,51,-5,OBSIDIAN:0)
Block(-8,51,-4,OBSIDIAN:0)
Block(-8,51,-3,OBSIDIAN:0)
Block(-8,51,-2,OBSIDIAN:0)
Block(-8,52,-7,OBSIDIAN:0)
Block(-8,52,-6,STONE:3)
Block(-8,52,-5,STONE:3)
Block(-8,52,-4,OBSIDIAN:0)
Block(-8,52,-3,OBSIDIAN:0)
Block(-8,52,-2,OBSIDIAN:0)
Block(-8,53,-7,OBSIDIAN:0)
Block(-8,53,-6,OBSIDIAN:0)
Block(-8,53,-5,STONE:3)
Block(-8,53,-4,OBSIDIAN:0)
Block(-8,53,-3,OBSIDIAN:0)
Block(-8,53,-2,OBSIDIAN:0)
Block(-8,54,-7,OBSIDIAN:0)
Block(-8,54,-6,OBSIDIAN:0)
Block(-8,54,-5,STONE:3)
Block(-8,54,-4,OBSIDIAN:0)
Block(-8,54,-3,OBSIDIAN:0)
Block(-8,54,-2,OBSIDIAN:0)
Block(-8,55,-7,OBSIDIAN:0)
Block(-8,55,-6,OBSIDIAN:0)
Block(-8,55,-5,OBSIDIAN:0)
Block(-8,55,-4,OBSIDIAN:0)
Block(-8,55,-3,OBSIDIAN:0)
Block(-8,55,-2,OBSIDIAN:0)
Block(-8,56,-7,OBSIDIAN:0)
Block(-8,56,-6,OBSIDIAN:0)
Block(-8,56,-5,OBSIDIAN:0)
Block(-8,56,-4,OBSIDIAN:0)
Block(-8,56,-3,OBSIDIAN:0)
Block(-8,56,-2,OBSIDIAN:0)
Block(-8,57,-7,OBSIDIAN:0)
Block(-8,57,-6,OBSIDIAN:0)
Block(-8,57,-5,OBSIDIAN:0)
Block(-8,57,-4,OBSIDIAN:0)
Block(-8,57,-3,OBSIDIAN:0)
Block(-8,57,-2,OBSIDIAN:0)
Block(-8,58,-7,OBSIDIAN:0)
Block(-8,58,-6,OBSIDIAN:0)
Block(-8,58,-5,OBSIDIAN:0)
Block(-8,58,-4,OBSIDIAN:0)
Block(-8,58,-3,OBSIDIAN:0)
Block(-8,59,-7,OBSIDIAN:0)
Block(-8,59,-6,OBSIDIAN:0)
Block(-8,59,-5,OBSIDIAN:0)
Block(-8,59,-4,OBSIDIAN:0)
Block(-8,60,-7,OBSIDIAN:0)
Block(-8,60,-6,STONE:3)
Block(-8,60,-5,OBSIDIAN:0)
Block(-8,60,-4,OBSIDIAN:0)
Block(-8,61,-7,STONE:3)
Block(-8,61,-6,STONE:3)
Block(-8,61,-5,OBSIDIAN:0)
Block(-8,61,-4,STONE:3)
Block(-8,62,-7,STONE:3)
Block(-8,62,-6,STONE:3)
Block(-8,62,-5,OBSIDIAN:0)
Block(-8,62,-4,STONE:3)
Block(-8,62,-3,STONE:3)
Block(-8,63,-7,STONE:3)
Block(-8,63,-6,STONE:3)
Block(-8,63,-5,OBSIDIAN:0)
Block(-8,63,-4,STONE:3)
Block(-8,63,-3,STONE:3)
Block(-8,63,-2,STONE:3)
Block(-8,64,-7,STONE:3)
Block(-8,64,-6,STONE:3)
Block(-8,64,-5,OBSIDIAN:0)
Block(-8,64,-4,STONE:3)
Block(-8,64,-3,STONE:3)
Block(-8,64,-2,STONE:3)
Block(-8,64,-1,STONE:3)
Block(-8,65,-7,STONE:3)
Block(-8,65,-6,STONE:3)
Block(-8,65,-5,OBSIDIAN:0)
Block(-8,65,-4,OBSIDIAN:0)
Block(-8,65,-3,STONE:3)
Block(-8,65,-2,STONE:3)
Block(-8,65,-1,STONE:3)
Block(-8,66,-7,STONE:3)
Block(-8,66,-6,STONE:3)
Block(-8,66,-5,OBSIDIAN:0)
Block(-8,66,-4,OBSIDIAN:0)
Block(-8,66,-3,OBSIDIAN:0)
Block(-8,66,-2,OBSIDIAN:0)
Block(-8,66,-1,OBSIDIAN:0)
Block(-8,67,-7,STONE:3)
Block(-8,67,-6,STONE:3)
Block(-8,67,-5,OBSIDIAN:0)
Block(-8,67,-4,OBSIDIAN:0)
Block(-8,67,-3,OBSIDIAN:0)
Block(-8,67,-2,OBSIDIAN:0)
Block(-8,68,-7,STONE:3)
Block(-8,68,-6,STONE:3)
Block(-8,68,-5,OBSIDIAN:0)
Block(-8,68,-4,OBSIDIAN:0)
Block(-8,68,-3,OBSIDIAN:0)
Block(-8,68,-2,OBSIDIAN:0)
Block(-8,69,-7,STONE:5)
Block(-8,69,-6,STONE:3)
Block(-8,69,-5,STONE:3)
Block(-8,69,-4,OBSIDIAN:0)
Block(-8,69,-3,OBSIDIAN:0)
Block(-8,69,-2,OBSIDIAN:0)
Block(-8,69,-1,OBSIDIAN:0)
Block(-8,70,-6,STONE:3)
Block(-8,70,-5,STONE:3)
Block(-8,70,-4,OBSIDIAN:0)
Block(-8,70,-3,OBSIDIAN:0)
Block(-8,70,-2,OBSIDIAN:0)
Block(-8,71,-6,STONE:3)
Block(-8,71,-5,STONE:3)
Block(-8,71,-4,OBSIDIAN:0)
Block(-8,71,-3,OBSIDIAN:0)
Block(-8,71,-2,OBSIDIAN:0)
Block(-8,72,-6,STONE:3)
Block(-8,72,-5,OBSIDIAN:0)
Block(-8,72,-4,OBSIDIAN:0)
Block(-8,72,-3,OBSIDIAN:0)
Block(-8,72,-2,OBSIDIAN:0)
Block(-8,73,-6,STONE:3)
Block(-8,73,-5,STONE:3)
Block(-8,73,-4,OBSIDIAN:0)
Block(-8,73,-3,OBSIDIAN:0)
Block(-8,73,-2,OBSIDIAN:0)
Block(-8,74,-6,STONE:5)
Block(-8,74,-5,STONE:3)
Block(-8,74,-4,STONE:3)
Block(-8,74,-3,OBSIDIAN:0)
Block(-8,74,-2,OBSIDIAN:0)
Block(-8,74,-1,OBSIDIAN:0)
Block(-8,75,-5,STONE:3)
Block(-8,75,-4,STONE:3)
Block(-8,75,-3,OBSIDIAN:0)
Block(-8,75,-2,OBSIDIAN:0)
Block(-8,75,-1,OBSIDIAN:0)
Block(-8,76,-5,STONE:3)
Block(-8,76,-4,STONE:3)
Block(-8,76,-3,OBSIDIAN:0)
Block(-8,76,-2,OBSIDIAN:0)
Block(-8,76,-1,OBSIDIAN:0)
Block(-8,76,0,OBSIDIAN:0)
Block(-8,76,1,OBSIDIAN:0)
Block(-8,77,-5,STONE:3)
Block(-8,77,-4,OBSIDIAN:0)
Block(-8,77,-3,OBSIDIAN:0)
Block(-8,77,-2,OBSIDIAN:0)
Block(-8,77,-1,OBSIDIAN:0)
Block(-8,77,0,OBSIDIAN:0)
Block(-8,77,1,OBSIDIAN:0)
Block(-8,77,2,OBSIDIAN:0)
Block(-8,78,-4,STONE:3)
Block(-8,78,-3,OBSIDIAN:0)
Block(-8,78,-2,OBSIDIAN:0)
Block(-8,78,-1,OBSIDIAN:0)
Block(-8,78,0,OBSIDIAN:0)
Block(-8,78,1,OBSIDIAN:0)
Block(-8,78,2,OBSIDIAN:0)
Block(-8,79,-5,STONE:5)
Block(-8,79,-4,STONE:3)
Block(-8,79,-3,OBSIDIAN:0)
Block(-8,79,-2,OBSIDIAN:0)
Block(-8,79,-1,OBSIDIAN:0)
Block(-8,79,0,OBSIDIAN:0)
Block(-8,79,1,OBSIDIAN:0)
Block(-8,79,2,OBSIDIAN:0)
Block(-8,79,3,OBSIDIAN:0)
Block(-8,80,-4,STONE:5)
Block(-8,80,-3,STONE:3)
Block(-8,80,-2,STONE:3)
Block(-8,80,-1,OBSIDIAN:0)
Block(-8,80,0,OBSIDIAN:0)
Block(-8,80,1,OBSIDIAN:0)
Block(-8,80,2,OBSIDIAN:0)
Block(-8,80,3,OBSIDIAN:0)
Block(-8,81,-3,STONE:5)
Block(-8,81,-2,STONE:3)
Block(-8,81,-1,STONE:3)
Block(-8,81,0,OBSIDIAN:0)
Block(-8,81,1,OBSIDIAN:0)
Block(-8,81,2,OBSIDIAN:0)
Block(-8,81,3,OBSIDIAN:0)
Block(-8,81,4,OBSIDIAN:0)
Block(-8,81,5,OBSIDIAN:0)
Block(-8,81,6,OBSIDIAN:0)
Block(-8,82,-2,STONE:5)
Block(-8,82,-1,STONE:5)
Block(-8,82,0,STONE:3)
Block(-8,82,1,STONE:3)
Block(-8,82,2,OBSIDIAN:0)
Block(-8,82,3,OBSIDIAN:0)
Block(-8,82,4,OBSIDIAN:0)
Block(-8,82,5,OBSIDIAN:0)
Block(-8,82,6,OBSIDIAN:0)
Block(-8,83,0,STONE:5)
Block(-8,83,1,STONE:5)
Block(-8,83,2,STONE:3)
Block(-8,83,3,OBSIDIAN:0)
Block(-8,83,4,OBSIDIAN:0)
Block(-8,83,5,OBSIDIAN:0)
Block(-8,83,6,OBSIDIAN:0)
Block(-8,84,2,STONE:3)
Block(-8,84,3,STONE:3)
Block(-8,84,4,OBSIDIAN:0)
Block(-8,84,5,OBSIDIAN:0)
Block(-8,84,6,OBSIDIAN:0)
Block(-8,84,7,OBSIDIAN:0)
Block(-8,85,2,STONE:5)
Block(-8,85,3,STONE:3)
Block(-8,85,4,STONE:3)
Block(-8,85,5,STONE:3)
Block(-8,85,6,OBSIDIAN:0)
Block(-8,85,7,OBSIDIAN:0)
Block(-8,85,8,OBSIDIAN:0)
Block(-8,86,3,STONE:5)
Block(-8,86,4,STONE:3)
Block(-8,86,5,STONE:3)
Block(-8,86,6,OBSIDIAN:0)
Block(-8,86,7,OBSIDIAN:0)
Block(-8,86,8,OBSIDIAN:0)
Block(-8,87,4,STONE:5)
Block(-8,87,5,STONE:3)
Block(-8,87,6,STONE:3)
Block(-8,87,7,OBSIDIAN:0)
Block(-8,87,8,OBSIDIAN:0)
Block(-8,88,5,STONE:5)
Block(-8,88,6,STONE:3)
Block(-8,88,7,STONE:3)
Block(-8,88,8,OBSIDIAN:0)
Block(-8,89,6,STONE:3)
Block(-8,89,7,STONE:3)
Block(-8,89,8,STONE:3)
Block(-8,90,7,STONE:3)
Block(-8,90,8,STONE:3)
Block(-7,19,7,OBSIDIAN:0)
Block(-7,19,8,OBSIDIAN:0)
Block(-7,20,4,STONE:3)
Block(-7,20,5,STONE:3)
Block(-7,20,6,OBSIDIAN:0)
Block(-7,20,7,OBSIDIAN:0)
Block(-7,20,8,OBSIDIAN:0)
Block(-7,21,3,STONE:3)
Block(-7,21,4,STONE:3)
Block(-7,21,5,STONE:3)
Block(-7,21,6,STONE:3)
Block(-7,21,7,STONE:3)
Block(-7,21,8,OBSIDIAN:0)
Block(-7,22,1,STONE:3)
Block(-7,22,2,STONE:3)
Block(-7,22,3,STONE:3)
Block(-7,22,4,STONE:3)
Block(-7,22,5,STONE:3)
Block(-7,22,6,STONE:3)
Block(-7,22,7,STONE:3)
Block(-7,22,8,STONE:3)
Block(-7,23,0,STONE:3)
Block(-7,23,1,STONE:3)
Block(-7,23,2,STONE:3)
Block(-7,23,3,STONE:3)
Block(-7,23,4,STONE:3)
Block(-7,23,5,STONE:3)
Block(-7,23,6,STONE:3)
Block(-7,23,7,STONE:3)
Block(-7,23,8,STONE:3)
Block(-7,24,0,STONE:3)
Block(-7,24,1,STONE:3)
Block(-7,24,2,STONE:3)
Block(-7,24,3,STONE:3)
Block(-7,24,4,STONE:3)
Block(-7,24,5,STONE:3)
Block(-7,24,6,STONE:3)
Block(-7,24,7,STONE:3)
Block(-7,24,8,STONE:3)
Block(-7,25,-2,STONE:3)
Block(-7,25,-1,STONE:3)
Block(-7,25,0,STONE:3)
Block(-7,25,1,STONE:3)
Block(-7,25,2,STONE:3)
Block(-7,25,3,STONE:3)
Block(-7,25,4,STONE:3)
Block(-7,25,5,STONE:3)
Block(-7,25,6,STONE:3)
Block(-7,25,7,OBSIDIAN:0)
Block(-7,25,8,OBSIDIAN:0)
Block(-7,26,-3,STONE:3)
Block(-7,26,-2,STONE:3)
Block(-7,26,-1,STONE:3)
Block(-7,26,0,STONE:3)
Block(-7,26,1,STONE:3)
Block(-7,26,2,STONE:3)
Block(-7,26,3,STONE:3)
Block(-7,26,4,STONE:3)
Block(-7,26,5,STONE:3)
Block(-7,26,6,STONE:3)
Block(-7,26,7,OBSIDIAN:0)
Block(-7,26,8,OBSIDIAN:0)
Block(-7,27,-5,STONE:3)
Block(-7,27,-4,STONE:3)
Block(-7,27,-3,STONE:3)
Block(-7,27,-2,STONE:3)
Block(-7,27,-1,STONE:3)
Block(-7,27,0,STONE:3)
Block(-7,27,1,STONE:3)
Block(-7,27,2,STONE:3)
Block(-7,27,3,STONE:3)
Block(-7,27,4,STONE:3)
Block(-7,27,5,STONE:3)
Block(-7,27,6,STONE:3)
Block(-7,27,7,OBSIDIAN:0)
Block(-7,27,8,OBSIDIAN:0)
Block(-7,28,-5,STONE:3)
Block(-7,28,-4,STONE:3)
Block(-7,28,-3,STONE:3)
Block(-7,28,-2,STONE:3)
Block(-7,28,-1,STONE:3)
Block(-7,28,0,STONE:3)
Block(-7,28,1,STONE:3)
Block(-7,28,2,STONE:3)
Block(-7,28,3,STONE:3)
Block(-7,28,4,STONE:3)
Block(-7,28,5,STONE:3)
Block(-7,28,6,STONE:3)
Block(-7,28,7,OBSIDIAN:0)
Block(-7,28,8,OBSIDIAN:0)
Block(-7,29,-6,STONE:3)
Block(-7,29,-5,STONE:3)
Block(-7,29,-4,STONE:3)
Block(-7,29,-3,STONE:3)
Block(-7,29,-2,STONE:3)
Block(-7,29,-1,STONE:3)
Block(-7,29,0,STONE:3)
Block(-7,29,1,STONE:3)
Block(-7,29,2,STONE:3)
Block(-7,29,3,STONE:3)
Block(-7,29,4,STONE:3)
Block(-7,29,5,STONE:3)
Block(-7,29,6,OBSIDIAN:0)
Block(-7,29,7,OBSIDIAN:0)
Block(-7,29,8,OBSIDIAN:0)
Block(-7,30,-7,STONE:3)
Block(-7,30,-6,STONE:3)
Block(-7,30,-5,STONE:3)
Block(-7,30,-4,STONE:3)
Block(-7,30,-3,STONE:3)
Block(-7,30,-2,STONE:3)
Block(-7,30,-1,STONE:3)
Block(-7,30,0,STONE:3)
Block(-7,30,1,STONE:3)
Block(-7,30,2,STONE:3)
Block(-7,30,3,STONE:3)
Block(-7,30,4,STONE:3)
Block(-7,30,5,OBSIDIAN:0)
Block(-7,30,6,OBSIDIAN:0)
Block(-7,30,7,OBSIDIAN:0)
Block(-7,30,8,OBSIDIAN:0)
Block(-7,31,-7,STONE:3)
Block(-7,31,-6,STONE:3)
Block(-7,31,-5,STONE:3)
Block(-7,31,-4,STONE:3)
Block(-7,31,-3,STONE:3)
Block(-7,31,-2,STONE:3)
Block(-7,31,-1,STONE:3)
Block(-7,31,0,OBSIDIAN:0)
Block(-7,31,1,OBSIDIAN:0)
Block(-7,31,2,OBSIDIAN:0)
Block(-7,31,3,OBSIDIAN:0)
Block(-7,31,4,OBSIDIAN:0)
Block(-7,31,5,OBSIDIAN:0)
Block(-7,31,6,OBSIDIAN:0)
Block(-7,31,7,OBSIDIAN:0)
Block(-7,31,8,STONE:3)
Block(-7,32,-7,STONE:3)
Block(-7,32,-6,STONE:3)
Block(-7,32,-5,STONE:3)
Block(-7,32,-4,STONE:3)
Block(-7,32,-3,STONE:3)
Block(-7,32,-2,STONE:3)
Block(-7,32,-1,STONE:3)
Block(-7,32,0,OBSIDIAN:0)
Block(-7,32,1,OBSIDIAN:0)
Block(-7,32,2,OBSIDIAN:0)
Block(-7,32,3,OBSIDIAN:0)
Block(-7,32,4,OBSIDIAN:0)
Block(-7,32,5,OBSIDIAN:0)
Block(-7,32,6,OBSIDIAN:0)
Block(-7,32,7,STONE:3)
Block(-7,32,8,STONE:3)
Block(-7,33,-7,STONE:3)
Block(-7,33,-6,STONE:3)
Block(-7,33,-5,STONE:3)
Block(-7,33,-4,STONE:3)
Block(-7,33,-3,STONE:3)
Block(-7,33,-2,STONE:3)
Block(-7,33,-1,STONE:3)
Block(-7,33,0,OBSIDIAN:0)
Block(-7,33,1,OBSIDIAN:0)
Block(-7,33,2,OBSIDIAN:0)
Block(-7,33,3,OBSIDIAN:0)
Block(-7,33,4,STONE:3)
Block(-7,33,5,STONE:3)
Block(-7,33,6,STONE:3)
Block(-7,33,7,STONE:3)
Block(-7,33,8,STONE:3)
Block(-7,34,-7,STONE:3)
Block(-7,34,-6,STONE:3)
Block(-7,34,-5,STONE:3)
Block(-7,34,-4,STONE:3)
Block(-7,34,-3,STONE:3)
Block(-7,34,-2,STONE:3)
Block(-7,34,-1,STONE:3)
Block(-7,34,0,OBSIDIAN:0)
Block(-7,34,1,OBSIDIAN:0)
Block(-7,34,2,OBSIDIAN:0)
Block(-7,34,3,STONE:3)
Block(-7,34,4,STONE:3)
Block(-7,34,5,STONE:3)
Block(-7,34,6,STONE:5)
Block(-7,34,7,STONE:5)
Block(-7,34,8,STONE:3)
Block(-7,35,-7,STONE:3)
Block(-7,35,-6,STONE:3)
Block(-7,35,-5,STONE:3)
Block(-7,35,-4,STONE:3)
Block(-7,35,-3,STONE:3)
Block(-7,35,-2,STONE:3)
Block(-7,35,-1,OBSIDIAN:0)
Block(-7,35,0,OBSIDIAN:0)
Block(-7,35,1,OBSIDIAN:0)
Block(-7,35,2,STONE:3)
Block(-7,35,3,STONE:3)
Block(-7,35,4,STONE:3)
Block(-7,35,5,STONE:3)
Block(-7,35,6,STONE:3)
Block(-7,35,7,STONE:3)
Block(-7,35,8,STONE:3)
Block(-7,36,-7,STONE:3)
Block(-7,36,-6,STONE:3)
Block(-7,36,-5,STONE:3)
Block(-7,36,-4,OBSIDIAN:0)
Block(-7,36,-3,OBSIDIAN:0)
Block(-7,36,-2,OBSIDIAN:0)
Block(-7,36,-1,OBSIDIAN:0)
Block(-7,36,0,OBSIDIAN:0)
Block(-7,36,1,OBSIDIAN:0)
Block(-7,36,2,STONE:3)
Block(-7,36,3,STONE:3)
Block(-7,36,4,STONE:3)
Block(-7,36,5,STONE:3)
Block(-7,36,6,OBSIDIAN:0)
Block(-7,36,7,STONE:3)
Block(-7,36,8,STONE:3)
Block(-7,37,-7,STONE:3)
Block(-7,37,-6,STONE:3)
Block(-7,37,-5,OBSIDIAN:0)
Block(-7,37,-4,OBSIDIAN:0)
Block(-7,37,-3,OBSIDIAN:0)
Block(-7,37,-2,OBSIDIAN:0)
Block(-7,37,-1,OBSIDIAN:0)
Block(-7,37,0,OBSIDIAN:0)
Block(-7,37,1,OBSIDIAN:0)
Block(-7,37,2,STONE:3)
Block(-7,37,3,STONE:3)
Block(-7,37,4,STONE:3)
Block(-7,37,5,OBSIDIAN:0)
Block(-7,37,6,STONE:3)
Block(-7,37,7,STONE:3)
Block(-7,37,8,STONE:3)
Block(-7,38,-7,STONE:3)
Block(-7,38,-6,STONE:3)
Block(-7,38,-5,STONE:3)
Block(-7,38,-4,OBSIDIAN:0)
Block(-7,38,-3,OBSIDIAN:0)
Block(-7,38,-2,OBSIDIAN:0)
Block(-7,38,-1,OBSIDIAN:0)
Block(-7,38,0,OBSIDIAN:0)
Block(-7,38,1,OBSIDIAN:0)
Block(-7,38,2,OBSIDIAN:0)
Block(-7,38,3,STONE:3)
Block(-7,38,4,OBSIDIAN:0)
Block(-7,38,5,OBSIDIAN:0)
Block(-7,38,6,STONE:3)
Block(-7,38,7,STONE:3)
Block(-7,38,8,STONE:3)
Block(-7,39,-7,STONE:3)
Block(-7,39,-6,STONE:3)
Block(-7,39,-5,STONE:3)
Block(-7,39,-4,OBSIDIAN:0)
Block(-7,39,-3,OBSIDIAN:0)
Block(-7,39,-2,OBSIDIAN:0)
Block(-7,39,-1,OBSIDIAN:0)
Block(-7,39,0,OBSIDIAN:0)
Block(-7,39,1,OBSIDIAN:0)
Block(-7,39,2,OBSIDIAN:0)
Block(-7,39,3,OBSIDIAN:0)
Block(-7,39,4,OBSIDIAN:0)
Block(-7,39,5,OBSIDIAN:0)
Block(-7,39,6,STONE:3)
Block(-7,40,-7,STONE:3)
Block(-7,40,-6,STONE:3)
Block(-7,40,-5,STONE:3)
Block(-7,40,-4,STONE:3)
Block(-7,40,-3,OBSIDIAN:0)
Block(-7,40,-2,OBSIDIAN:0)
Block(-7,40,-1,OBSIDIAN:0)
Block(-7,40,0,OBSIDIAN:0)
Block(-7,40,1,OBSIDIAN:0)
Block(-7,40,2,OBSIDIAN:0)
Block(-7,40,3,OBSIDIAN:0)
Block(-7,40,4,OBSIDIAN:0)
Block(-7,41,-7,STONE:3)
Block(-7,41,-6,STONE:3)
Block(-7,41,-5,STONE:3)
Block(-7,41,-4,STONE:3)
Block(-7,41,-3,OBSIDIAN:0)
Block(-7,41,-2,OBSIDIAN:0)
Block(-7,41,-1,OBSIDIAN:0)
Block(-7,41,0,OBSIDIAN:0)
Block(-7,41,1,OBSIDIAN:0)
Block(-7,41,2,OBSIDIAN:0)
Block(-7,41,3,OBSIDIAN:0)
Block(-7,41,4,OBSIDIAN:0)
Block(-7,42,-7,STONE:3)
Block(-7,42,-6,STONE:3)
Block(-7,42,-5,STONE:3)
Block(-7,42,-4,STONE:3)
Block(-7,42,-3,OBSIDIAN:0)
Block(-7,42,-2,OBSIDIAN:0)
Block(-7,42,-1,OBSIDIAN:0)
Block(-7,42,0,OBSIDIAN:0)
Block(-7,42,1,OBSIDIAN:0)
Block(-7,42,2,OBSIDIAN:0)
Block(-7,42,3,OBSIDIAN:0)
Block(-7,43,-7,STONE:3)
Block(-7,43,-6,STONE:3)
Block(-7,43,-5,STONE:3)
Block(-7,43,-4,OBSIDIAN:0)
Block(-7,43,-3,OBSIDIAN:0)
Block(-7,43,-2,OBSIDIAN:0)
Block(-7,43,-1,OBSIDIAN:0)
Block(-7,43,0,OBSIDIAN:0)
Block(-7,43,1,OBSIDIAN:0)
Block(-7,43,2,OBSIDIAN:0)
Block(-7,44,-7,STONE:3)
Block(-7,44,-6,STONE:3)
Block(-7,44,-5,STONE:3)
Block(-7,44,-4,OBSIDIAN:0)
Block(-7,44,-3,OBSIDIAN:0)
Block(-7,44,-2,OBSIDIAN:0)
Block(-7,44,-1,OBSIDIAN:0)
Block(-7,44,0,OBSIDIAN:0)
Block(-7,44,1,OBSIDIAN:0)
Block(-7,44,2,OBSIDIAN:0)
Block(-7,45,-7,STONE:3)
Block(-7,45,-6,STONE:3)
Block(-7,45,-5,STONE:3)
Block(-7,45,-4,OBSIDIAN:0)
Block(-7,45,-3,OBSIDIAN:0)
Block(-7,45,-2,OBSIDIAN:0)
Block(-7,45,-1,OBSIDIAN:0)
Block(-7,45,0,OBSIDIAN:0)
Block(-7,45,1,OBSIDIAN:0)
Block(-7,46,-7,STONE:3)
Block(-7,46,-6,STONE:3)
Block(-7,46,-5,STONE:3)
Block(-7,46,-4,OBSIDIAN:0)
Block(-7,46,-3,OBSIDIAN:0)
Block(-7,46,-2,OBSIDIAN:0)
Block(-7,46,-1,OBSIDIAN:0)
Block(-7,46,0,OBSIDIAN:0)
Block(-7,47,-7,STONE:3)
Block(-7,47,-6,STONE:3)
Block(-7,47,-5,STONE:3)
Block(-7,47,-4,OBSIDIAN:0)
Block(-7,47,-3,OBSIDIAN:0)
Block(-7,47,-2,OBSIDIAN:0)
Block(-7,47,-1,OBSIDIAN:0)
Block(-7,48,-7,STONE:3)
Block(-7,48,-6,STONE:3)
Block(-7,48,-5,STONE:3)
Block(-7,48,-4,OBSIDIAN:0)
Block(-7,48,-3,OBSIDIAN:0)
Block(-7,48,-2,OBSIDIAN:0)
Block(-7,48,-1,OBSIDIAN:0)
Block(-7,49,-7,STONE:3)
Block(-7,49,-6,STONE:3)
Block(-7,49,-5,STONE:3)
Block(-7,49,-4,STONE:3)
Block(-7,49,-3,OBSIDIAN:0)
Block(-7,49,-2,OBSIDIAN:0)
Block(-7,49,-1,OBSIDIAN:0)
Block(-7,50,-7,STONE:3)
Block(-7,50,-6,STONE:3)
Block(-7,50,-5,STONE:3)
Block(-7,50,-4,OBSIDIAN:0)
Block(-7,50,-3,OBSIDIAN:0)
Block(-7,50,-2,OBSIDIAN:0)
Block(-7,50,-1,OBSIDIAN:0)
Block(-7,51,-7,STONE:3)
Block(-7,51,-6,STONE:3)
Block(-7,51,-5,OBSIDIAN:0)
Block(-7,51,-4,OBSIDIAN:0)
Block(-7,51,-3,OBSIDIAN:0)
Block(-7,51,-2,OBSIDIAN:0)
Block(-7,52,-7,OBSIDIAN:0)
Block(-7,52,-6,STONE:3)
Block(-7,52,-5,STONE:3)
Block(-7,52,-4,OBSIDIAN:0)
Block(-7,52,-3,OBSIDIAN:0)
Block(-7,52,-2,OBSIDIAN:0)
Block(-7,53,-7,OBSIDIAN:0)
Block(-7,53,-6,OBSIDIAN:0)
Block(-7,53,-5,STONE:3)
Block(-7,53,-4,OBSIDIAN:0)
Block(-7,53,-3,OBSIDIAN:0)
Block(-7,53,-2,OBSIDIAN:0)
Block(-7,54,-7,OBSIDIAN:0)
Block(-7,54,-6,OBSIDIAN:0)
Block(-7,54,-5,OBSIDIAN:0)
Block(-7,54,-4,OBSIDIAN:0)
Block(-7,54,-3,OBSIDIAN:0)
Block(-7,54,-2,OBSIDIAN:0)
Block(-7,55,-7,OBSIDIAN:0)
Block(-7,55,-6,OBSIDIAN:0)
Block(-7,55,-5,OBSIDIAN:0)
Block(-7,55,-4,OBSIDIAN:0)
Block(-7,55,-3,OBSIDIAN:0)
Block(-7,55,-2,OBSIDIAN:0)
Block(-7,56,-7,OBSIDIAN:0)
Block(-7,56,-6,OBSIDIAN:0)
Block(-7,56,-5,OBSIDIAN:0)
Block(-7,56,-4,OBSIDIAN:0)
Block(-7,56,-3,OBSIDIAN:0)
Block(-7,56,-2,OBSIDIAN:0)
Block(-7,57,-7,OBSIDIAN:0)
Block(-7,57,-6,OBSIDIAN:0)
Block(-7,57,-5,OBSIDIAN:0)
Block(-7,57,-4,OBSIDIAN:0)
Block(-7,57,-3,OBSIDIAN:0)
Block(-7,57,-2,OBSIDIAN:0)
Block(-7,58,-7,OBSIDIAN:0)
Block(-7,58,-6,OBSIDIAN:0)
Block(-7,58,-5,OBSIDIAN:0)
Block(-7,58,-4,OBSIDIAN:0)
Block(-7,58,-3,OBSIDIAN:0)
Block(-7,59,-7,OBSIDIAN:0)
Block(-7,59,-6,OBSIDIAN:0)
Block(-7,59,-5,OBSIDIAN:0)
Block(-7,59,-4,OBSIDIAN:0)
Block(-7,60,-7,OBSIDIAN:0)
Block(-7,60,-6,STONE:3)
Block(-7,60,-5,OBSIDIAN:0)
Block(-7,60,-4,OBSIDIAN:0)
Block(-7,61,-7,STONE:3)
Block(-7,61,-6,STONE:3)
Block(-7,61,-5,OBSIDIAN:0)
Block(-7,61,-4,STONE:3)
Block(-7,62,-7,STONE:3)
Block(-7,62,-6,STONE:3)
Block(-7,62,-5,STONE:3)
Block(-7,62,-4,STONE:3)
Block(-7,63,-7,STONE:3)
Block(-7,63,-6,STONE:3)
Block(-7,63,-5,STONE:3)
Block(-7,63,-4,STONE:3)
Block(-7,63,-3,STONE:3)
Block(-7,63,-2,STONE:3)
Block(-7,64,-7,STONE:3)
Block(-7,64,-6,STONE:3)
Block(-7,64,-5,STONE:3)
Block(-7,64,-4,STONE:3)
Block(-7,64,-3,STONE:3)
Block(-7,64,-2,STONE:3)
Block(-7,65,-7,STONE:3)
Block(-7,65,-6,STONE:3)
Block(-7,65,-5,OBSIDIAN:0)
Block(-7,65,-4,STONE:3)
Block(-7,65,-3,STONE:3)
Block(-7,65,-2,STONE:3)
Block(-7,66,-7,STONE:3)
Block(-7,66,-6,STONE:3)
Block(-7,66,-5,OBSIDIAN:0)
Block(-7,66,-4,OBSIDIAN:0)
Block(-7,66,-3,OBSIDIAN:0)
Block(-7,66,-2,OBSIDIAN:0)
Block(-7,67,-7,STONE:3)
Block(-7,67,-6,STONE:3)
Block(-7,67,-5,OBSIDIAN:0)
Block(-7,67,-4,OBSIDIAN:0)
Block(-7,67,-3,OBSIDIAN:0)
Block(-7,67,-2,OBSIDIAN:0)
Block(-7,68,-7,STONE:3)
Block(-7,68,-6,OBSIDIAN:0)
Block(-7,68,-5,OBSIDIAN:0)
Block(-7,68,-4,OBSIDIAN:0)
Block(-7,68,-3,OBSIDIAN:0)
Block(-7,68,-2,OBSIDIAN:0)
Block(-7,68,-1,OBSIDIAN:0)
Block(-7,69,-7,STONE:5)
Block(-7,69,-6,STONE:3)
Block(-7,69,-5,STONE:3)
Block(-7,69,-4,OBSIDIAN:0)
Block(-7,69,-3,OBSIDIAN:0)
Block(-7,69,-2,OBSIDIAN:0)
Block(-7,69,-1,OBSIDIAN:0)
Block(-7,70,-6,STONE:3)
Block(-7,70,-5,STONE:3)
Block(-7,70,-4,OBSIDIAN:0)
Block(-7,70,-3,OBSIDIAN:0)
Block(-7,71,-6,STONE:3)
Block(-7,71,-5,STONE:3)
Block(-7,71,-4,OBSIDIAN:0)
Block(-7,71,-3,OBSIDIAN:0)
Block(-7,72,-6,STONE:3)
Block(-7,72,-5,STONE:3)
Block(-7,72,-4,OBSIDIAN:0)
Block(-7,72,-3,OBSIDIAN:0)
Block(-7,73,-6,STONE:3)
Block(-7,73,-5,OBSIDIAN:0)
Block(-7,73,-4,OBSIDIAN:0)
Block(-7,73,-3,OBSIDIAN:0)
Block(-7,73,-2,OBSIDIAN:0)
Block(-7,74,-6,STONE:3)
Block(-7,74,-5,STONE:3)
Block(-7,74,-4,OBSIDIAN:0)
Block(-7,74,-3,OBSIDIAN:0)
Block(-7,74,-2,OBSIDIAN:0)
Block(-7,74,-1,OBSIDIAN:0)
Block(-7,75,-6,STONE:5)
Block(-7,75,-5,STONE:3)
Block(-7,75,-4,STONE:3)
Block(-7,75,-3,OBSIDIAN:0)
Block(-7,75,-2,OBSIDIAN:0)
Block(-7,75,-1,OBSIDIAN:0)
Block(-7,76,-5,STONE:3)
Block(-7,76,-4,OBSIDIAN:0)
Block(-7,76,-3,OBSIDIAN:0)
Block(-7,76,-2,OBSIDIAN:0)
Block(-7,76,-1,OBSIDIAN:0)
Block(-7,76,0,OBSIDIAN:0)
Block(-7,77,-5,STONE:3)
Block(-7,77,-4,OBSIDIAN:0)
Block(-7,77,-3,OBSIDIAN:0)
Block(-7,77,-2,OBSIDIAN:0)
Block(-7,77,-1,OBSIDIAN:0)
Block(-7,77,0,OBSIDIAN:0)
Block(-7,77,1,OBSIDIAN:0)
Block(-7,77,2,OBSIDIAN:0)
Block(-7,78,-5,STONE:5)
Block(-7,78,-4,STONE:3)
Block(-7,78,-3,OBSIDIAN:0)
Block(-7,78,-2,OBSIDIAN:0)
Block(-7,78,-1,OBSIDIAN:0)
Block(-7,78,0,OBSIDIAN:0)
Block(-7,78,1,OBSIDIAN:0)
Block(-7,78,2,OBSIDIAN:0)
Block(-7,79,-4,STONE:3)
Block(-7,79,-3,STONE:3)
Block(-7,79,-2,OBSIDIAN:0)
Block(-7,79,-1,OBSIDIAN:0)
Block(-7,79,0,OBSIDIAN:0)
Block(-7,79,1,OBSIDIAN:0)
Block(-7,79,2,OBSIDIAN:0)
Block(-7,79,3,OBSIDIAN:0)
Block(-7,80,-4,STONE:5)
Block(-7,80,-3,STONE:3)
Block(-7,80,-2,OBSIDIAN:0)
Block(-7,80,-1,OBSIDIAN:0)
Block(-7,80,0,OBSIDIAN:0)
Block(-7,80,1,OBSIDIAN:0)
Block(-7,80,2,OBSIDIAN:0)
Block(-7,80,3,OBSIDIAN:0)
Block(-7,81,-3,STONE:5)
Block(-7,81,-2,STONE:3)
Block(-7,81,-1,STONE:3)
Block(-7,81,0,OBSIDIAN:0)
Block(-7,81,1,OBSIDIAN:0)
Block(-7,81,2,OBSIDIAN:0)
Block(-7,81,3,OBSIDIAN:0)
Block(-7,81,4,OBSIDIAN:0)
Block(-7,81,5,OBSIDIAN:0)
Block(-7,82,-2,STONE:5)
Block(-7,82,-1,STONE:3)
Block(-7,82,0,STONE:3)
Block(-7,82,1,STONE:3)
Block(-7,82,2,OBSIDIAN:0)
Block(-7,82,3,OBSIDIAN:0)
Block(-7,82,4,OBSIDIAN:0)
Block(-7,82,5,OBSIDIAN:0)
Block(-7,83,-1,STONE:5)
Block(-7,83,0,STONE:5)
Block(-7,83,1,STONE:3)
Block(-7,83,2,STONE:3)
Block(-7,83,3,OBSIDIAN:0)
Block(-7,83,4,OBSIDIAN:0)
Block(-7,83,5,OBSIDIAN:0)
Block(-7,83,6,OBSIDIAN:0)
Block(-7,84,1,STONE:3)
Block(-7,84,2,STONE:3)
Block(-7,84,3,OBSIDIAN:0)
Block(-7,84,4,OBSIDIAN:0)
Block(-7,84,5,OBSIDIAN:0)
Block(-7,84,6,OBSIDIAN:0)
Block(-7,85,1,STONE:5)
Block(-7,85,2,STONE:3)
Block(-7,85,3,STONE:3)
Block(-7,85,4,OBSIDIAN:0)
Block(-7,85,5,OBSIDIAN:0)
Block(-7,85,6,OBSIDIAN:0)
Block(-7,85,7,OBSIDIAN:0)
Block(-7,86,2,STONE:5)
Block(-7,86,3,STONE:5)
Block(-7,86,4,STONE:3)
Block(-7,86,5,STONE:3)
Block(-7,86,6,STONE:3)
Block(-7,86,7,OBSIDIAN:0)
Block(-7,86,8,OBSIDIAN:0)
Block(-7,87,4,STONE:5)
Block(-7,87,5,STONE:3)
Block(-7,87,6,STONE:3)
Block(-7,87,7,OBSIDIAN:0)
Block(-7,87,8,OBSIDIAN:0)
Block(-7,88,5,STONE:5)
Block(-7,88,6,STONE:3)
Block(-7,88,7,STONE:3)
Block(-7,88,8,OBSIDIAN:0)
Block(-7,89,6,STONE:3)
Block(-7,89,7,STONE:3)
Block(-7,89,8,STONE:3)
Block(-7,90,7,STONE:3)
Block(-7,90,8,STONE:3)
Block(-6,19,8,OBSIDIAN:0)
Block(-6,20,4,STONE:3)
Block(-6,20,5,STONE:3)
Block(-6,20,6,STONE:3)
Block(-6,20,7,OBSIDIAN:0)
Block(-6,20,8,OBSIDIAN:0)
Block(-6,21,4,STONE:3)
Block(-6,21,5,STONE:3)
Block(-6,21,6,STONE:3)
Block(-6,21,7,STONE:3)
Block(-6,21,8,STONE:3)
Block(-6,22,3,STONE:3)
Block(-6,22,4,STONE:3)
Block(-6,22,5,STONE:3)
Block(-6,22,6,STONE:3)
Block(-6,22,7,STONE:3)
Block(-6,22,8,STONE:3)
Block(-6,23,2,STONE:3)
Block(-6,23,3,STONE:3)
Block(-6,23,4,STONE:3)
Block(-6,23,5,STONE:3)
Block(-6,23,6,STONE:3)
Block(-6,23,7,STONE:3)
Block(-6,23,8,STONE:3)
Block(-6,24,2,STONE:3)
Block(-6,24,3,STONE:3)
Block(-6,24,4,STONE:3)
Block(-6,24,5,STONE:3)
Block(-6,24,6,STONE:3)
Block(-6,24,7,STONE:3)
Block(-6,24,8,STONE:3)
Block(-6,25,-2,STONE:3)
Block(-6,25,-1,STONE:3)
Block(-6,25,0,STONE:3)
Block(-6,25,1,STONE:3)
Block(-6,25,2,STONE:3)
Block(-6,25,3,STONE:3)
Block(-6,25,4,STONE:3)
Block(-6,25,5,STONE:3)
Block(-6,25,6,STONE:3)
Block(-6,25,7,STONE:3)
Block(-6,25,8,STONE:3)
Block(-6,26,-3,STONE:3)
Block(-6,26,-2,STONE:3)
Block(-6,26,-1,STONE:3)
Block(-6,26,0,STONE:3)
Block(-6,26,1,STONE:3)
Block(-6,26,2,STONE:3)
Block(-6,26,3,STONE:3)
Block(-6,26,4,STONE:3)
Block(-6,26,5,STONE:3)
Block(-6,26,6,STONE:3)
Block(-6,26,7,STONE:3)
Block(-6,26,8,OBSIDIAN:0)
Block(-6,27,-4,STONE:3)
Block(-6,27,-3,STONE:3)
Block(-6,27,-2,STONE:3)
Block(-6,27,-1,STONE:3)
Block(-6,27,0,STONE:3)
Block(-6,27,1,STONE:3)
Block(-6,27,2,STONE:3)
Block(-6,27,3,STONE:3)
Block(-6,27,4,STONE:3)
Block(-6,27,5,STONE:3)
Block(-6,27,6,STONE:3)
Block(-6,27,7,STONE:3)
Block(-6,27,8,OBSIDIAN:0)
Block(-6,28,-5,STONE:3)
Block(-6,28,-4,STONE:3)
Block(-6,28,-3,STONE:3)
Block(-6,28,-2,STONE:3)
Block(-6,28,-1,STONE:3)
Block(-6,28,0,STONE:3)
Block(-6,28,1,STONE:3)
Block(-6,28,2,STONE:3)
Block(-6,28,3,STONE:3)
Block(-6,28,4,STONE:3)
Block(-6,28,5,STONE:3)
Block(-6,28,6,STONE:3)
Block(-6,28,7,OBSIDIAN:0)
Block(-6,28,8,OBSIDIAN:0)
Block(-6,29,-5,STONE:3)
Block(-6,29,-4,STONE:3)
Block(-6,29,-3,STONE:3)
Block(-6,29,-2,STONE:3)
Block(-6,29,-1,STONE:3)
Block(-6,29,0,STONE:3)
Block(-6,29,1,STONE:3)
Block(-6,29,2,STONE:3)
Block(-6,29,3,STONE:3)
Block(-6,29,4,STONE:3)
Block(-6,29,5,STONE:3)
Block(-6,29,6,STONE:3)
Block(-6,29,7,OBSIDIAN:0)
Block(-6,29,8,OBSIDIAN:0)
Block(-6,30,-6,STONE:3)
Block(-6,30,-5,STONE:3)
Block(-6,30,-4,STONE:3)
Block(-6,30,-3,STONE:3)
Block(-6,30,-2,STONE:3)
Block(-6,30,-1,STONE:3)
Block(-6,30,0,STONE:3)
Block(-6,30,1,STONE:3)
Block(-6,30,2,STONE:3)
Block(-6,30,3,STONE:3)
Block(-6,30,4,STONE:3)
Block(-6,30,5,STONE:3)
Block(-6,30,6,OBSIDIAN:0)
Block(-6,30,7,OBSIDIAN:0)
Block(-6,30,8,OBSIDIAN:0)
Block(-6,31,-7,STONE:3)
Block(-6,31,-6,STONE:3)
Block(-6,31,-5,STONE:3)
Block(-6,31,-4,STONE:3)
Block(-6,31,-3,STONE:3)
Block(-6,31,-2,STONE:3)
Block(-6,31,-1,STONE:3)
Block(-6,31,0,STONE:3)
Block(-6,31,1,STONE:3)
Block(-6,31,2,STONE:3)
Block(-6,31,3,STONE:3)
Block(-6,31,4,OBSIDIAN:0)
Block(-6,31,5,OBSIDIAN:0)
Block(-6,31,6,OBSIDIAN:0)
Block(-6,31,7,OBSIDIAN:0)
Block(-6,31,8,OBSIDIAN:0)
Block(-6,32,-7,STONE:3)
Block(-6,32,-6,STONE:3)
Block(-6,32,-5,STONE:3)
Block(-6,32,-4,STONE:3)
Block(-6,32,-3,STONE:3)
Block(-6,32,-2,STONE:3)
Block(-6,32,-1,STONE:3)
Block(-6,32,0,STONE:3)
Block(-6,32,1,OBSIDIAN:0)
Block(-6,32,2,OBSIDIAN:0)
Block(-6,32,3,OBSIDIAN:0)
Block(-6,32,4,OBSIDIAN:0)
Block(-6,32,5,OBSIDIAN:0)
Block(-6,32,6,OBSIDIAN:0)
Block(-6,32,7,OBSIDIAN:0)
Block(-6,32,8,OBSIDIAN:0)
Block(-6,33,-7,STONE:3)
Block(-6,33,-6,STONE:3)
Block(-6,33,-5,STONE:3)
Block(-6,33,-4,STONE:3)
Block(-6,33,-3,STONE:3)
Block(-6,33,-2,STONE:3)
Block(-6,33,-1,STONE:3)
Block(-6,33,0,STONE:3)
Block(-6,33,1,OBSIDIAN:0)
Block(-6,33,2,OBSIDIAN:0)
Block(-6,33,3,OBSIDIAN:0)
Block(-6,33,4,STONE:3)
Block(-6,33,5,STONE:3)
Block(-6,33,6,STONE:3)
Block(-6,33,7,OBSIDIAN:0)
Block(-6,33,8,OBSIDIAN:0)
Block(-6,34,-7,STONE:3)
Block(-6,34,-6,STONE:3)
Block(-6,34,-5,STONE:3)
Block(-6,34,-4,STONE:3)
Block(-6,34,-3,STONE:3)
Block(-6,34,-2,STONE:3)
Block(-6,34,-1,STONE:3)
Block(-6,34,0,STONE:3)
Block(-6,34,1,OBSIDIAN:0)
Block(-6,34,2,OBSIDIAN:0)
Block(-6,34,3,STONE:3)
Block(-6,34,4,STONE:3)
Block(-6,34,5,STONE:3)
Block(-6,34,6,STONE:5)
Block(-6,34,7,STONE:3)
Block(-6,34,8,OBSIDIAN:0)
Block(-6,35,-7,STONE:3)
Block(-6,35,-6,STONE:3)
Block(-6,35,-5,STONE:3)
Block(-6,35,-4,STONE:3)
Block(-6,35,-3,STONE:3)
Block(-6,35,-2,STONE:3)
Block(-6,35,-1,STONE:3)
Block(-6,35,0,STONE:3)
Block(-6,35,1,OBSIDIAN:0)
Block(-6,35,2,STONE:3)
Block(-6,35,3,STONE:3)
Block(-6,35,4,STONE:3)
Block(-6,35,5,STONE:5)
Block(-6,35,6,STONE:5)
Block(-6,35,7,STONE:5)
Block(-6,35,8,OBSIDIAN:0)
Block(-6,36,-7,STONE:3)
Block(-6,36,-6,STONE:3)
Block(-6,36,-5,STONE:3)
Block(-6,36,-4,STONE:3)
Block(-6,36,-3,STONE:3)
Block(-6,36,-2,STONE:3)
Block(-6,36,-1,STONE:3)
Block(-6,36,0,OBSIDIAN:0)
Block(-6,36,1,OBSIDIAN:0)
Block(-6,36,2,STONE:3)
Block(-6,36,3,STONE:3)
Block(-6,36,4,STONE:3)
Block(-6,36,5,STONE:5)
Block(-6,36,6,OBSIDIAN:0)
Block(-6,36,7,OBSIDIAN:0)
Block(-6,36,8,OBSIDIAN:0)
Block(-6,37,-7,STONE:3)
Block(-6,37,-6,STONE:3)
Block(-6,37,-5,STONE:3)
Block(-6,37,-4,OBSIDIAN:0)
Block(-6,37,-3,OBSIDIAN:0)
Block(-6,37,-2,OBSIDIAN:0)
Block(-6,37,-1,OBSIDIAN:0)
Block(-6,37,0,OBSIDIAN:0)
Block(-6,37,1,OBSIDIAN:0)
Block(-6,37,2,STONE:3)
Block(-6,37,3,STONE:3)
Block(-6,37,4,STONE:3)
Block(-6,37,5,OBSIDIAN:0)
Block(-6,37,6,OBSIDIAN:0)
Block(-6,37,7,STONE:3)
Block(-6,37,8,STONE:3)
Block(-6,38,-7,STONE:3)
Block(-6,38,-6,STONE:3)
Block(-6,38,-5,STONE:3)
Block(-6,38,-4,STONE:3)
Block(-6,38,-3,OBSIDIAN:0)
Block(-6,38,-2,OBSIDIAN:0)
Block(-6,38,-1,OBSIDIAN:0)
Block(-6,38,0,OBSIDIAN:0)
Block(-6,38,1,OBSIDIAN:0)
Block(-6,38,2,OBSIDIAN:0)
Block(-6,38,3,STONE:3)
Block(-6,38,4,OBSIDIAN:0)
Block(-6,38,5,OBSIDIAN:0)
Block(-6,38,6,STONE:3)
Block(-6,38,7,STONE:3)
Block(-6,38,8,STONE:3)
Block(-6,39,-7,STONE:3)
Block(-6,39,-6,STONE:3)
Block(-6,39,-5,STONE:3)
Block(-6,39,-4,STONE:3)
Block(-6,39,-3,STONE:3)
Block(-6,39,-2,OBSIDIAN:0)
Block(-6,39,-1,OBSIDIAN:0)
Block(-6,39,0,OBSIDIAN:0)
Block(-6,39,1,OBSIDIAN:0)
Block(-6,39,2,OBSIDIAN:0)
Block(-6,39,3,OBSIDIAN:0)
Block(-6,39,4,OBSIDIAN:0)
Block(-6,39,5,OBSIDIAN:0)
Block(-6,39,6,STONE:3)
Block(-6,39,7,STONE:3)
Block(-6,40,-7,STONE:3)
Block(-6,40,-6,STONE:3)
Block(-6,40,-5,STONE:3)
Block(-6,40,-4,STONE:3)
Block(-6,40,-3,STONE:3)
Block(-6,40,-2,OBSIDIAN:0)
Block(-6,40,-1,OBSIDIAN:0)
Block(-6,40,0,OBSIDIAN:0)
Block(-6,40,1,OBSIDIAN:0)
Block(-6,40,2,OBSIDIAN:0)
Block(-6,40,3,OBSIDIAN:0)
Block(-6,40,4,OBSIDIAN:0)
Block(-6,40,5,OBSIDIAN:0)
Block(-6,40,6,STONE:3)
Block(-6,41,-7,STONE:3)
Block(-6,41,-6,STONE:3)
Block(-6,41,-5,STONE:3)
Block(-6,41,-4,STONE:3)
Block(-6,41,-3,STONE:3)
Block(-6,41,-2,OBSIDIAN:0)
Block(-6,41,-1,OBSIDIAN:0)
Block(-6,41,0,OBSIDIAN:0)
Block(-6,41,1,OBSIDIAN:0)
Block(-6,41,2,OBSIDIAN:0)
Block(-6,41,3,OBSIDIAN:0)
Block(-6,41,4,OBSIDIAN:0)
Block(-6,41,5,OBSIDIAN:0)
Block(-6,42,-7,STONE:3)
Block(-6,42,-6,STONE:3)
Block(-6,42,-5,STONE:3)
Block(-6,42,-4,STONE:3)
Block(-6,42,-3,STONE:3)
Block(-6,42,-2,OBSIDIAN:0)
Block(-6,42,-1,OBSIDIAN:0)
Block(-6,42,0,OBSIDIAN:0)
Block(-6,42,1,OBSIDIAN:0)
Block(-6,42,2,OBSIDIAN:0)
Block(-6,42,3,OBSIDIAN:0)
Block(-6,42,4,OBSIDIAN:0)
Block(-6,43,-7,STONE:3)
Block(-6,43,-6,STONE:3)
Block(-6,43,-5,STONE:3)
Block(-6,43,-4,STONE:3)
Block(-6,43,-3,STONE:3)
Block(-6,43,-2,OBSIDIAN:0)
Block(-6,43,-1,OBSIDIAN:0)
Block(-6,43,0,OBSIDIAN:0)
Block(-6,43,1,OBSIDIAN:0)
Block(-6,43,2,OBSIDIAN:0)
Block(-6,43,3,OBSIDIAN:0)
Block(-6,44,-7,STONE:3)
Block(-6,44,-6,STONE:3)
Block(-6,44,-5,STONE:3)
Block(-6,44,-4,STONE:3)
Block(-6,44,-3,OBSIDIAN:0)
Block(-6,44,-2,OBSIDIAN:0)
Block(-6,44,-1,OBSIDIAN:0)
Block(-6,44,0,OBSIDIAN:0)
Block(-6,44,1,OBSIDIAN:0)
Block(-6,44,2,OBSIDIAN:0)
Block(-6,45,-7,STONE:3)
Block(-6,45,-6,STONE:3)
Block(-6,45,-5,STONE:3)
Block(-6,45,-4,STONE:3)
Block(-6,45,-3,OBSIDIAN:0)
Block(-6,45,-2,OBSIDIAN:0)
Block(-6,45,-1,OBSIDIAN:0)
Block(-6,45,0,OBSIDIAN:0)
Block(-6,45,1,OBSIDIAN:0)
Block(-6,46,-7,STONE:3)
Block(-6,46,-6,STONE:3)
Block(-6,46,-5,STONE:3)
Block(-6,46,-4,STONE:3)
Block(-6,46,-3,OBSIDIAN:0)
Block(-6,46,-2,OBSIDIAN:0)
Block(-6,46,-1,OBSIDIAN:0)
Block(-6,46,0,OBSIDIAN:0)
Block(-6,47,-7,STONE:3)
Block(-6,47,-6,STONE:3)
Block(-6,47,-5,STONE:3)
Block(-6,47,-4,STONE:3)
Block(-6,47,-3,OBSIDIAN:0)
Block(-6,47,-2,OBSIDIAN:0)
Block(-6,47,-1,OBSIDIAN:0)
Block(-6,48,-7,STONE:3)
Block(-6,48,-6,STONE:3)
Block(-6,48,-5,STONE:3)
Block(-6,48,-4,STONE:3)
Block(-6,48,-3,OBSIDIAN:0)
Block(-6,48,-2,OBSIDIAN:0)
Block(-6,48,-1,OBSIDIAN:0)
Block(-6,49,-7,STONE:3)
Block(-6,49,-6,STONE:3)
Block(-6,49,-5,STONE:3)
Block(-6,49,-4,STONE:3)
Block(-6,49,-3,OBSIDIAN:0)
Block(-6,49,-2,OBSIDIAN:0)
Block(-6,49,-1,OBSIDIAN:0)
Block(-6,50,-7,STONE:3)
Block(-6,50,-6,STONE:3)
Block(-6,50,-5,STONE:3)
Block(-6,50,-4,STONE:3)
Block(-6,50,-3,OBSIDIAN:0)
Block(-6,50,-2,OBSIDIAN:0)
Block(-6,50,-1,OBSIDIAN:0)
Block(-6,51,-7,OBSIDIAN:0)
Block(-6,51,-6,STONE:3)
Block(-6,51,-5,STONE:3)
Block(-6,51,-4,OBSIDIAN:0)
Block(-6,51,-3,OBSIDIAN:0)
Block(-6,51,-2,OBSIDIAN:0)
Block(-6,51,-1,OBSIDIAN:0)
Block(-6,52,-7,OBSIDIAN:0)
Block(-6,52,-6,OBSIDIAN:0)
Block(-6,52,-5,OBSIDIAN:0)
Block(-6,52,-4,OBSIDIAN:0)
Block(-6,52,-3,OBSIDIAN:0)
Block(-6,52,-2,OBSIDIAN:0)
Block(-6,52,-1,OBSIDIAN:0)
Block(-6,53,-7,OBSIDIAN:0)
Block(-6,53,-6,OBSIDIAN:0)
Block(-6,53,-5,OBSIDIAN:0)
Block(-6,53,-4,OBSIDIAN:0)
Block(-6,53,-3,OBSIDIAN:0)
Block(-6,53,-2,OBSIDIAN:0)
Block(-6,54,-7,OBSIDIAN:0)
Block(-6,54,-6,OBSIDIAN:0)
Block(-6,54,-5,OBSIDIAN:0)
Block(-6,54,-4,OBSIDIAN:0)
Block(-6,54,-3,OBSIDIAN:0)
Block(-6,54,-2,OBSIDIAN:0)
Block(-6,55,-7,OBSIDIAN:0)
Block(-6,55,-6,OBSIDIAN:0)
Block(-6,55,-5,OBSIDIAN:0)
Block(-6,55,-4,OBSIDIAN:0)
Block(-6,55,-3,OBSIDIAN:0)
Block(-6,55,-2,OBSIDIAN:0)
Block(-6,56,-7,OBSIDIAN:0)
Block(-6,56,-6,OBSIDIAN:0)
Block(-6,56,-5,OBSIDIAN:0)
Block(-6,56,-4,OBSIDIAN:0)
Block(-6,56,-3,OBSIDIAN:0)
Block(-6,56,-2,OBSIDIAN:0)
Block(-6,57,-7,OBSIDIAN:0)
Block(-6,57,-6,OBSIDIAN:0)
Block(-6,57,-5,OBSIDIAN:0)
Block(-6,57,-4,OBSIDIAN:0)
Block(-6,57,-3,OBSIDIAN:0)
Block(-6,57,-2,OBSIDIAN:0)
Block(-6,58,-7,OBSIDIAN:0)
Block(-6,58,-6,OBSIDIAN:0)
Block(-6,58,-5,OBSIDIAN:0)
Block(-6,58,-4,OBSIDIAN:0)
Block(-6,58,-3,OBSIDIAN:0)
Block(-6,59,-7,OBSIDIAN:0)
Block(-6,59,-6,OBSIDIAN:0)
Block(-6,59,-5,OBSIDIAN:0)
Block(-6,59,-4,OBSIDIAN:0)
Block(-6,60,-7,OBSIDIAN:0)
Block(-6,60,-6,STONE:3)
Block(-6,60,-5,OBSIDIAN:0)
Block(-6,60,-4,OBSIDIAN:0)
Block(-6,61,-7,STONE:3)
Block(-6,61,-6,OBSIDIAN:0)
Block(-6,61,-5,OBSIDIAN:0)
Block(-6,61,-4,STONE:3)
Block(-6,62,-7,STONE:3)
Block(-6,62,-6,OBSIDIAN:0)
Block(-6,62,-5,STONE:3)
Block(-6,62,-4,STONE:3)
Block(-6,63,-7,STONE:3)
Block(-6,63,-6,OBSIDIAN:0)
Block(-6,63,-5,STONE:3)
Block(-6,63,-4,STONE:3)
Block(-6,63,-3,STONE:3)
Block(-6,64,-7,STONE:3)
Block(-6,64,-6,STONE:3)
Block(-6,64,-5,STONE:3)
Block(-6,64,-4,STONE:3)
Block(-6,64,-3,STONE:3)
Block(-6,65,-7,STONE:3)
Block(-6,65,-6,STONE:3)
Block(-6,65,-5,OBSIDIAN:0)
Block(-6,65,-4,STONE:3)
Block(-6,65,-3,STONE:3)
Block(-6,66,-7,STONE:3)
Block(-6,66,-6,STONE:3)
Block(-6,66,-5,OBSIDIAN:0)
Block(-6,66,-4,OBSIDIAN:0)
Block(-6,66,-3,OBSIDIAN:0)
Block(-6,67,-7,STONE:3)
Block(-6,67,-6,STONE:3)
Block(-6,67,-5,OBSIDIAN:0)
Block(-6,67,-4,OBSIDIAN:0)
Block(-6,67,-3,OBSIDIAN:0)
Block(-6,67,-2,OBSIDIAN:0)
Block(-6,68,-7,STONE:3)
Block(-6,68,-6,OBSIDIAN:0)
Block(-6,68,-5,OBSIDIAN:0)
Block(-6,68,-4,OBSIDIAN:0)
Block(-6,68,-3,OBSIDIAN:0)
Block(-6,68,-2,OBSIDIAN:0)
Block(-6,69,-7,STONE:3)
Block(-6,69,-6,STONE:3)
Block(-6,69,-5,OBSIDIAN:0)
Block(-6,69,-4,OBSIDIAN:0)
Block(-6,69,-3,OBSIDIAN:0)
Block(-6,70,-7,STONE:5)
Block(-6,70,-6,STONE:3)
Block(-6,70,-5,STONE:3)
Block(-6,70,-4,OBSIDIAN:0)
Block(-6,70,-3,OBSIDIAN:0)
Block(-6,71,-6,STONE:3)
Block(-6,71,-5,STONE:3)
Block(-6,71,-4,OBSIDIAN:0)
Block(-6,71,-3,OBSIDIAN:0)
Block(-6,72,-6,STONE:3)
Block(-6,72,-5,OBSIDIAN:0)
Block(-6,72,-4,OBSIDIAN:0)
Block(-6,72,-3,OBSIDIAN:0)
Block(-6,73,-6,STONE:3)
Block(-6,73,-5,OBSIDIAN:0)
Block(-6,73,-4,OBSIDIAN:0)
Block(-6,73,-3,OBSIDIAN:0)
Block(-6,74,-6,STONE:3)
Block(-6,74,-5,OBSIDIAN:0)
Block(-6,74,-4,OBSIDIAN:0)
Block(-6,74,-3,OBSIDIAN:0)
Block(-6,74,-2,OBSIDIAN:0)
Block(-6,74,-1,OBSIDIAN:0)
Block(-6,75,-6,STONE:3)
Block(-6,75,-5,OBSIDIAN:0)
Block(-6,75,-4,OBSIDIAN:0)
Block(-6,75,-3,OBSIDIAN:0)
Block(-6,75,-2,OBSIDIAN:0)
Block(-6,75,-1,OBSIDIAN:0)
Block(-6,75,0,OBSIDIAN:0)
Block(-6,76,-6,STONE:5)
Block(-6,76,-5,STONE:3)
Block(-6,76,-4,OBSIDIAN:0)
Block(-6,76,-3,OBSIDIAN:0)
Block(-6,76,-2,OBSIDIAN:0)
Block(-6,76,-1,OBSIDIAN:0)
Block(-6,76,0,OBSIDIAN:0)
Block(-6,76,1,OBSIDIAN:0)
Block(-6,77,-5,STONE:3)
Block(-6,77,-4,STONE:3)
Block(-6,77,-3,OBSIDIAN:0)
Block(-6,77,-2,OBSIDIAN:0)
Block(-6,77,-1,OBSIDIAN:0)
Block(-6,77,0,OBSIDIAN:0)
Block(-6,77,1,OBSIDIAN:0)
Block(-6,77,2,OBSIDIAN:0)
Block(-6,78,-5,STONE:5)
Block(-6,78,-4,STONE:3)
Block(-6,78,-3,OBSIDIAN:0)
Block(-6,78,-2,OBSIDIAN:0)
Block(-6,78,-1,OBSIDIAN:0)
Block(-6,78,0,OBSIDIAN:0)
Block(-6,78,1,OBSIDIAN:0)
Block(-6,78,2,OBSIDIAN:0)
Block(-6,78,3,OBSIDIAN:0)
Block(-6,79,-4,STONE:3)
Block(-6,79,-3,STONE:3)
Block(-6,79,-2,OBSIDIAN:0)
Block(-6,79,-1,OBSIDIAN:0)
Block(-6,79,0,OBSIDIAN:0)
Block(-6,79,1,OBSIDIAN:0)
Block(-6,79,2,OBSIDIAN:0)
Block(-6,79,3,OBSIDIAN:0)
Block(-6,80,-4,STONE:5)
Block(-6,80,-3,STONE:3)
Block(-6,80,-2,STONE:3)
Block(-6,80,-1,OBSIDIAN:0)
Block(-6,80,0,OBSIDIAN:0)
Block(-6,80,1,OBSIDIAN:0)
Block(-6,80,2,OBSIDIAN:0)
Block(-6,80,3,OBSIDIAN:0)
Block(-6,80,4,OBSIDIAN:0)
Block(-6,81,-3,STONE:5)
Block(-6,81,-2,STONE:3)
Block(-6,81,-1,OBSIDIAN:0)
Block(-6,81,0,OBSIDIAN:0)
Block(-6,81,1,OBSIDIAN:0)
Block(-6,81,2,OBSIDIAN:0)
Block(-6,81,3,OBSIDIAN:0)
Block(-6,81,4,OBSIDIAN:0)
Block(-6,82,-2,STONE:5)
Block(-6,82,-1,STONE:3)
Block(-6,82,0,STONE:3)
Block(-6,82,1,OBSIDIAN:0)
Block(-6,82,2,OBSIDIAN:0)
Block(-6,82,3,OBSIDIAN:0)
Block(-6,82,4,OBSIDIAN:0)
Block(-6,83,-1,STONE:5)
Block(-6,83,0,STONE:3)
Block(-6,83,1,STONE:3)
Block(-6,83,2,OBSIDIAN:0)
Block(-6,83,3,OBSIDIAN:0)
Block(-6,83,4,OBSIDIAN:0)
Block(-6,83,5,OBSIDIAN:0)
Block(-6,84,0,STONE:3)
Block(-6,84,1,STONE:3)
Block(-6,84,2,STONE:3)
Block(-6,84,3,OBSIDIAN:0)
Block(-6,84,4,OBSIDIAN:0)
Block(-6,84,5,OBSIDIAN:0)
Block(-6,84,6,OBSIDIAN:0)
Block(-6,85,0,STONE:5)
Block(-6,85,1,STONE:5)
Block(-6,85,2,STONE:3)
Block(-6,85,3,OBSIDIAN:0)
Block(-6,85,4,OBSIDIAN:0)
Block(-6,85,5,OBSIDIAN:0)
Block(-6,85,6,OBSIDIAN:0)
Block(-6,86,2,STONE:5)
Block(-6,86,3,STONE:3)
Block(-6,86,4,OBSIDIAN:0)
Block(-6,86,5,OBSIDIAN:0)
Block(-6,86,6,OBSIDIAN:0)
Block(-6,86,7,OBSIDIAN:0)
Block(-6,86,8,OBSIDIAN:0)
Block(-6,87,3,STONE:5)
Block(-6,87,4,STONE:3)
Block(-6,87,5,STONE:3)
Block(-6,87,6,STONE:3)
Block(-6,87,7,OBSIDIAN:0)
Block(-6,87,8,OBSIDIAN:0)
Block(-6,88,4,STONE:5)
Block(-6,88,5,STONE:3)
Block(-6,88,6,STONE:3)
Block(-6,88,7,OBSIDIAN:0)
Block(-6,88,8,OBSIDIAN:0)
Block(-6,89,5,STONE:3)
Block(-6,89,6,STONE:3)
Block(-6,89,7,STONE:3)
Block(-6,89,8,STONE:3)
Block(-6,90,7,STONE:3)
Block(-6,90,8,STONE:3)
Block(-6,91,8,STONE:3)
Block(-5,19,8,OBSIDIAN:0)
Block(-5,20,5,STONE:3)
Block(-5,20,6,STONE:3)
Block(-5,20,7,STONE:3)
Block(-5,20,8,OBSIDIAN:0)
Block(-5,21,4,STONE:3)
Block(-5,21,5,STONE:3)
Block(-5,21,6,STONE:3)
Block(-5,21,7,STONE:3)
Block(-5,21,8,STONE:3)
Block(-5,22,3,STONE:3)
Block(-5,22,4,STONE:3)
Block(-5,22,5,STONE:3)
Block(-5,22,6,STONE:3)
Block(-5,22,7,STONE:3)
Block(-5,22,8,STONE:3)
Block(-5,23,3,STONE:3)
Block(-5,23,4,STONE:3)
Block(-5,23,5,STONE:3)
Block(-5,23,6,STONE:3)
Block(-5,23,7,STONE:3)
Block(-5,23,8,STONE:3)
Block(-5,24,2,STONE:3)
Block(-5,24,3,STONE:3)
Block(-5,24,4,STONE:3)
Block(-5,24,5,STONE:3)
Block(-5,24,6,STONE:3)
Block(-5,24,7,STONE:3)
Block(-5,24,8,STONE:3)
Block(-5,25,-1,STONE:3)
Block(-5,25,0,STONE:3)
Block(-5,25,1,STONE:3)
Block(-5,25,2,STONE:3)
Block(-5,25,3,STONE:3)
Block(-5,25,4,STONE:3)
Block(-5,25,5,STONE:3)
Block(-5,25,6,STONE:3)
Block(-5,25,7,STONE:3)
Block(-5,25,8,STONE:3)
Block(-5,26,-3,STONE:3)
Block(-5,26,-2,STONE:3)
Block(-5,26,-1,STONE:3)
Block(-5,26,0,STONE:3)
Block(-5,26,1,STONE:3)
Block(-5,26,2,STONE:3)
Block(-5,26,3,STONE:3)
Block(-5,26,4,STONE:3)
Block(-5,26,5,STONE:3)
Block(-5,26,6,STONE:3)
Block(-5,26,7,STONE:3)
Block(-5,26,8,STONE:3)
Block(-5,27,-4,STONE:3)
Block(-5,27,-3,STONE:3)
Block(-5,27,-2,STONE:3)
Block(-5,27,-1,STONE:3)
Block(-5,27,0,STONE:3)
Block(-5,27,1,STONE:3)
Block(-5,27,2,STONE:3)
Block(-5,27,3,STONE:3)
Block(-5,27,4,STONE:3)
Block(-5,27,5,STONE:3)
Block(-5,27,6,STONE:3)
Block(-5,27,7,STONE:3)
Block(-5,27,8,OBSIDIAN:0)
Block(-5,28,-5,STONE:3)
Block(-5,28,-4,STONE:3)
Block(-5,28,-3,STONE:3)
Block(-5,28,-2,STONE:3)
Block(-5,28,-1,STONE:3)
Block(-5,28,0,STONE:3)
Block(-5,28,1,STONE:3)
Block(-5,28,2,STONE:3)
Block(-5,28,3,STONE:3)
Block(-5,28,4,STONE:3)
Block(-5,28,5,STONE:3)
Block(-5,28,6,STONE:3)
Block(-5,28,7,STONE:3)
Block(-5,28,8,OBSIDIAN:0)
Block(-5,29,-5,STONE:3)
Block(-5,29,-4,STONE:3)
Block(-5,29,-3,STONE:3)
Block(-5,29,-2,STONE:3)
Block(-5,29,-1,STONE:3)
Block(-5,29,0,STONE:3)
Block(-5,29,1,STONE:3)
Block(-5,29,2,STONE:3)
Block(-5,29,3,STONE:3)
Block(-5,29,4,STONE:3)
Block(-5,29,5,STONE:3)
Block(-5,29,6,STONE:3)
Block(-5,29,7,OBSIDIAN:0)
Block(-5,29,8,OBSIDIAN:0)
Block(-5,30,-6,STONE:3)
Block(-5,30,-5,STONE:3)
Block(-5,30,-4,STONE:3)
Block(-5,30,-3,STONE:3)
Block(-5,30,-2,STONE:3)
Block(-5,30,-1,STONE:3)
Block(-5,30,0,STONE:3)
Block(-5,30,1,STONE:3)
Block(-5,30,2,STONE:3)
Block(-5,30,3,STONE:3)
Block(-5,30,4,STONE:3)
Block(-5,30,5,STONE:3)
Block(-5,30,6,OBSIDIAN:0)
Block(-5,30,7,OBSIDIAN:0)
Block(-5,30,8,OBSIDIAN:0)
Block(-5,31,-7,STONE:3)
Block(-5,31,-6,STONE:3)
Block(-5,31,-5,STONE:3)
Block(-5,31,-4,STONE:3)
Block(-5,31,-3,STONE:3)
Block(-5,31,-2,STONE:3)
Block(-5,31,-1,STONE:3)
Block(-5,31,0,STONE:3)
Block(-5,31,1,STONE:3)
Block(-5,31,2,STONE:3)
Block(-5,31,3,STONE:3)
Block(-5,31,4,STONE:3)
Block(-5,31,5,OBSIDIAN:0)
Block(-5,31,6,OBSIDIAN:0)
Block(-5,31,7,OBSIDIAN:0)
Block(-5,31,8,OBSIDIAN:0)
Block(-5,32,-7,STONE:3)
Block(-5,32,-6,STONE:3)
Block(-5,32,-5,STONE:3)
Block(-5,32,-4,STONE:3)
Block(-5,32,-3,STONE:3)
Block(-5,32,-2,STONE:3)
Block(-5,32,-1,STONE:3)
Block(-5,32,0,STONE:3)
Block(-5,32,1,STONE:3)
Block(-5,32,2,OBSIDIAN:0)
Block(-5,32,3,OBSIDIAN:0)
Block(-5,32,4,OBSIDIAN:0)
Block(-5,32,5,OBSIDIAN:0)
Block(-5,32,6,OBSIDIAN:0)
Block(-5,32,7,OBSIDIAN:0)
Block(-5,32,8,OBSIDIAN:0)
Block(-5,33,-7,STONE:3)
Block(-5,33,-6,STONE:3)
Block(-5,33,-5,STONE:3)
Block(-5,33,-4,STONE:3)
Block(-5,33,-3,STONE:3)
Block(-5,33,-2,STONE:3)
Block(-5,33,-1,STONE:3)
Block(-5,33,0,STONE:3)
Block(-5,33,1,STONE:3)
Block(-5,33,2,OBSIDIAN:0)
Block(-5,33,3,OBSIDIAN:0)
Block(-5,33,4,OBSIDIAN:0)
Block(-5,33,5,OBSIDIAN:0)
Block(-5,33,6,OBSIDIAN:0)
Block(-5,33,7,OBSIDIAN:0)
Block(-5,33,8,OBSIDIAN:0)
Block(-5,34,-7,STONE:3)
Block(-5,34,-6,STONE:3)
Block(-5,34,-5,STONE:3)
Block(-5,34,-4,STONE:3)
Block(-5,34,-3,STONE:3)
Block(-5,34,-2,STONE:3)
Block(-5,34,-1,STONE:3)
Block(-5,34,0,STONE:3)
Block(-5,34,1,STONE:3)
Block(-5,34,2,OBSIDIAN:0)
Block(-5,34,3,STONE:3)
Block(-5,34,4,STONE:3)
Block(-5,34,5,STONE:3)
Block(-5,34,6,STONE:3)
Block(-5,34,7,OBSIDIAN:0)
Block(-5,34,8,OBSIDIAN:0)
Block(-5,35,-7,STONE:3)
Block(-5,35,-6,STONE:3)
Block(-5,35,-5,STONE:3)
Block(-5,35,-4,STONE:3)
Block(-5,35,-3,STONE:3)
Block(-5,35,-2,STONE:3)
Block(-5,35,-1,STONE:3)
Block(-5,35,0,STONE:3)
Block(-5,35,1,STONE:3)
Block(-5,35,2,STONE:3)
Block(-5,35,3,STONE:3)
Block(-5,35,4,STONE:3)
Block(-5,35,5,STONE:3)
Block(-5,35,6,STONE:3)
Block(-5,35,7,OBSIDIAN:0)
Block(-5,35,8,OBSIDIAN:0)
Block(-5,36,-7,STONE:3)
Block(-5,36,-6,STONE:3)
Block(-5,36,-5,STONE:3)
Block(-5,36,-4,STONE:3)
Block(-5,36,-3,STONE:3)
Block(-5,36,-2,STONE:3)
Block(-5,36,-1,STONE:3)
Block(-5,36,0,STONE:3)
Block(-5,36,1,OBSIDIAN:0)
Block(-5,36,2,STONE:3)
Block(-5,36,3,STONE:3)
Block(-5,36,4,STONE:3)
Block(-5,36,5,STONE:3)
Block(-5,36,6,STONE:3)
Block(-5,36,7,OBSIDIAN:0)
Block(-5,36,8,OBSIDIAN:0)
Block(-5,37,-7,STONE:3)
Block(-5,37,-6,STONE:3)
Block(-5,37,-5,STONE:3)
Block(-5,37,-4,STONE:3)
Block(-5,37,-3,STONE:3)
Block(-5,37,-2,STONE:3)
Block(-5,37,-1,STONE:3)
Block(-5,37,0,OBSIDIAN:0)
Block(-5,37,1,OBSIDIAN:0)
Block(-5,37,2,STONE:3)
Block(-5,37,3,STONE:3)
Block(-5,37,4,STONE:3)
Block(-5,37,5,STONE:3)
Block(-5,37,6,OBSIDIAN:0)
Block(-5,37,7,STONE:3)
Block(-5,37,8,STONE:3)
Block(-5,38,-7,STONE:3)
Block(-5,38,-6,STONE:3)
Block(-5,38,-5,STONE:3)
Block(-5,38,-4,STONE:3)
Block(-5,38,-3,STONE:3)
Block(-5,38,-2,OBSIDIAN:0)
Block(-5,38,-1,OBSIDIAN:0)
Block(-5,38,0,OBSIDIAN:0)
Block(-5,38,1,OBSIDIAN:0)
Block(-5,38,2,OBSIDIAN:0)
Block(-5,38,3,STONE:3)
Block(-5,38,4,OBSIDIAN:0)
Block(-5,38,5,OBSIDIAN:0)
Block(-5,38,6,STONE:3)
Block(-5,38,7,STONE:3)
Block(-5,38,8,STONE:3)
Block(-5,39,-7,STONE:3)
Block(-5,39,-6,STONE:3)
Block(-5,39,-5,STONE:3)
Block(-5,39,-4,STONE:3)
Block(-5,39,-3,STONE:3)
Block(-5,39,-2,STONE:3)
Block(-5,39,-1,OBSIDIAN:0)
Block(-5,39,0,OBSIDIAN:0)
Block(-5,39,1,OBSIDIAN:0)
Block(-5,39,2,OBSIDIAN:0)
Block(-5,39,3,OBSIDIAN:0)
Block(-5,39,4,OBSIDIAN:0)
Block(-5,39,5,OBSIDIAN:0)
Block(-5,39,6,STONE:3)
Block(-5,39,7,STONE:3)
Block(-5,39,8,STONE:3)
Block(-5,40,-7,STONE:3)
Block(-5,40,-6,STONE:3)
Block(-5,40,-5,STONE:3)
Block(-5,40,-4,STONE:3)
Block(-5,40,-3,STONE:3)
Block(-5,40,-2,STONE:3)
Block(-5,40,-1,OBSIDIAN:0)
Block(-5,40,0,OBSIDIAN:0)
Block(-5,40,1,OBSIDIAN:0)
Block(-5,40,2,OBSIDIAN:0)
Block(-5,40,3,OBSIDIAN:0)
Block(-5,40,4,OBSIDIAN:0)
Block(-5,40,5,OBSIDIAN:0)
Block(-5,40,6,STONE:3)
Block(-5,40,7,STONE:3)
Block(-5,40,8,STONE:3)
Block(-5,41,-7,STONE:3)
Block(-5,41,-6,STONE:3)
Block(-5,41,-5,STONE:3)
Block(-5,41,-4,STONE:3)
Block(-5,41,-3,STONE:3)
Block(-5,41,-2,STONE:3)
Block(-5,41,-1,OBSIDIAN:0)
Block(-5,41,0,OBSIDIAN:0)
Block(-5,41,1,OBSIDIAN:0)
Block(-5,41,2,OBSIDIAN:0)
Block(-5,41,3,OBSIDIAN:0)
Block(-5,41,4,OBSIDIAN:0)
Block(-5,41,5,OBSIDIAN:0)
Block(-5,41,6,STONE:3)
Block(-5,41,7,STONE:3)
Block(-5,42,-7,STONE:3)
Block(-5,42,-6,STONE:3)
Block(-5,42,-5,STONE:3)
Block(-5,42,-4,STONE:3)
Block(-5,42,-3,STONE:3)
Block(-5,42,-2,STONE:3)
Block(-5,42,-1,OBSIDIAN:0)
Block(-5,42,0,OBSIDIAN:0)
Block(-5,42,1,OBSIDIAN:0)
Block(-5,42,2,OBSIDIAN:0)
Block(-5,42,3,OBSIDIAN:0)
Block(-5,42,4,OBSIDIAN:0)
Block(-5,42,5,OBSIDIAN:0)
Block(-5,43,-7,STONE:3)
Block(-5,43,-6,STONE:3)
Block(-5,43,-5,STONE:3)
Block(-5,43,-4,STONE:3)
Block(-5,43,-3,STONE:3)
Block(-5,43,-2,STONE:3)
Block(-5,43,-1,OBSIDIAN:0)
Block(-5,43,0,OBSIDIAN:0)
Block(-5,43,1,OBSIDIAN:0)
Block(-5,43,2,OBSIDIAN:0)
Block(-5,43,3,OBSIDIAN:0)
Block(-5,43,4,OBSIDIAN:0)
Block(-5,43,5,OBSIDIAN:0)
Block(-5,44,-7,STONE:3)
Block(-5,44,-6,STONE:3)
Block(-5,44,-5,STONE:3)
Block(-5,44,-4,STONE:3)
Block(-5,44,-3,STONE:3)
Block(-5,44,-2,OBSIDIAN:0)
Block(-5,44,-1,OBSIDIAN:0)
Block(-5,44,0,OBSIDIAN:0)
Block(-5,44,1,OBSIDIAN:0)
Block(-5,44,2,OBSIDIAN:0)
Block(-5,44,3,OBSIDIAN:0)
Block(-5,44,4,OBSIDIAN:0)
Block(-5,45,-7,STONE:3)
Block(-5,45,-6,STONE:3)
Block(-5,45,-5,STONE:3)
Block(-5,45,-4,STONE:3)
Block(-5,45,-3,STONE:3)
Block(-5,45,-2,OBSIDIAN:0)
Block(-5,45,-1,OBSIDIAN:0)
Block(-5,45,0,OBSIDIAN:0)
Block(-5,45,1,OBSIDIAN:0)
Block(-5,45,2,OBSIDIAN:0)
Block(-5,46,-7,STONE:3)
Block(-5,46,-6,STONE:3)
Block(-5,46,-5,STONE:3)
Block(-5,46,-4,STONE:3)
Block(-5,46,-3,OBSIDIAN:0)
Block(-5,46,-2,OBSIDIAN:0)
Block(-5,46,-1,OBSIDIAN:0)
Block(-5,46,0,OBSIDIAN:0)
Block(-5,47,-7,STONE:3)
Block(-5,47,-6,STONE:3)
Block(-5,47,-5,STONE:3)
Block(-5,47,-4,OBSIDIAN:0)
Block(-5,47,-3,OBSIDIAN:0)
Block(-5,47,-2,OBSIDIAN:0)
Block(-5,47,-1,OBSIDIAN:0)
Block(-5,48,-7,STONE:3)
Block(-5,48,-6,STONE:3)
Block(-5,48,-5,STONE:3)
Block(-5,48,-4,OBSIDIAN:0)
Block(-5,48,-3,OBSIDIAN:0)
Block(-5,48,-2,OBSIDIAN:0)
Block(-5,48,-1,OBSIDIAN:0)
Block(-5,49,-7,STONE:3)
Block(-5,49,-6,STONE:3)
Block(-5,49,-5,STONE:3)
Block(-5,49,-4,OBSIDIAN:0)
Block(-5,49,-3,OBSIDIAN:0)
Block(-5,49,-2,OBSIDIAN:0)
Block(-5,49,-1,OBSIDIAN:0)
Block(-5,50,-7,OBSIDIAN:0)
Block(-5,50,-6,STONE:3)
Block(-5,50,-5,STONE:3)
Block(-5,50,-4,OBSIDIAN:0)
Block(-5,50,-3,OBSIDIAN:0)
Block(-5,50,-2,OBSIDIAN:0)
Block(-5,50,-1,OBSIDIAN:0)
Block(-5,51,-7,OBSIDIAN:0)
Block(-5,51,-6,OBSIDIAN:0)
Block(-5,51,-5,STONE:3)
Block(-5,51,-4,OBSIDIAN:0)
Block(-5,51,-3,OBSIDIAN:0)
Block(-5,51,-2,OBSIDIAN:0)
Block(-5,51,-1,OBSIDIAN:0)
Block(-5,52,-7,OBSIDIAN:0)
Block(-5,52,-6,OBSIDIAN:0)
Block(-5,52,-5,OBSIDIAN:0)
Block(-5,52,-4,OBSIDIAN:0)
Block(-5,52,-3,OBSIDIAN:0)
Block(-5,52,-2,OBSIDIAN:0)
Block(-5,52,-1,OBSIDIAN:0)
Block(-5,53,-7,OBSIDIAN:0)
Block(-5,53,-6,OBSIDIAN:0)
Block(-5,53,-5,OBSIDIAN:0)
Block(-5,53,-4,OBSIDIAN:0)
Block(-5,53,-3,OBSIDIAN:0)
Block(-5,53,-2,OBSIDIAN:0)
Block(-5,54,-7,OBSIDIAN:0)
Block(-5,54,-6,OBSIDIAN:0)
Block(-5,54,-5,OBSIDIAN:0)
Block(-5,54,-4,OBSIDIAN:0)
Block(-5,54,-3,OBSIDIAN:0)
Block(-5,54,-2,OBSIDIAN:0)
Block(-5,55,-7,OBSIDIAN:0)
Block(-5,55,-6,OBSIDIAN:0)
Block(-5,55,-5,OBSIDIAN:0)
Block(-5,55,-4,OBSIDIAN:0)
Block(-5,55,-3,OBSIDIAN:0)
Block(-5,55,-2,OBSIDIAN:0)
Block(-5,56,-7,OBSIDIAN:0)
Block(-5,56,-6,OBSIDIAN:0)
Block(-5,56,-5,OBSIDIAN:0)
Block(-5,56,-4,OBSIDIAN:0)
Block(-5,56,-3,OBSIDIAN:0)
Block(-5,56,-2,OBSIDIAN:0)
Block(-5,57,-7,OBSIDIAN:0)
Block(-5,57,-6,OBSIDIAN:0)
Block(-5,57,-5,OBSIDIAN:0)
Block(-5,57,-4,OBSIDIAN:0)
Block(-5,57,-3,OBSIDIAN:0)
Block(-5,58,-7,OBSIDIAN:0)
Block(-5,58,-6,OBSIDIAN:0)
Block(-5,58,-5,OBSIDIAN:0)
Block(-5,58,-4,OBSIDIAN:0)
Block(-5,58,-3,OBSIDIAN:0)
Block(-5,59,-7,OBSIDIAN:0)
Block(-5,59,-6,OBSIDIAN:0)
Block(-5,59,-5,OBSIDIAN:0)
Block(-5,59,-4,OBSIDIAN:0)
Block(-5,59,-3,OBSIDIAN:0)
Block(-5,60,-7,OBSIDIAN:0)
Block(-5,60,-6,STONE:3)
Block(-5,60,-5,OBSIDIAN:0)
Block(-5,60,-4,OBSIDIAN:0)
Block(-5,60,-3,OBSIDIAN:0)
Block(-5,61,-7,STONE:3)
Block(-5,61,-6,STONE:3)
Block(-5,61,-5,OBSIDIAN:0)
Block(-5,61,-4,STONE:3)
Block(-5,61,-3,STONE:3)
Block(-5,62,-7,STONE:3)
Block(-5,62,-6,OBSIDIAN:0)
Block(-5,62,-5,STONE:3)
Block(-5,62,-4,STONE:3)
Block(-5,62,-3,STONE:3)
Block(-5,63,-7,OBSIDIAN:0)
Block(-5,63,-6,OBSIDIAN:0)
Block(-5,63,-5,STONE:3)
Block(-5,63,-4,STONE:3)
Block(-5,63,-3,STONE:3)
Block(-5,64,-7,STONE:3)
Block(-5,64,-6,OBSIDIAN:0)
Block(-5,64,-5,STONE:3)
Block(-5,64,-4,STONE:3)
Block(-5,64,-3,STONE:3)
Block(-5,65,-7,STONE:3)
Block(-5,65,-6,STONE:3)
Block(-5,65,-5,OBSIDIAN:0)
Block(-5,65,-4,STONE:3)
Block(-5,65,-3,STONE:3)
Block(-5,66,-7,STONE:3)
Block(-5,66,-6,STONE:3)
Block(-5,66,-5,OBSIDIAN:0)
Block(-5,66,-4,OBSIDIAN:0)
Block(-5,66,-3,OBSIDIAN:0)
Block(-5,67,-7,STONE:3)
Block(-5,67,-6,STONE:3)
Block(-5,67,-5,OBSIDIAN:0)
Block(-5,67,-4,OBSIDIAN:0)
Block(-5,67,-3,OBSIDIAN:0)
Block(-5,68,-7,STONE:3)
Block(-5,68,-6,OBSIDIAN:0)
Block(-5,68,-5,OBSIDIAN:0)
Block(-5,68,-4,OBSIDIAN:0)
Block(-5,68,-3,OBSIDIAN:0)
Block(-5,69,-7,STONE:3)
Block(-5,69,-6,OBSIDIAN:0)
Block(-5,69,-5,OBSIDIAN:0)
Block(-5,69,-4,OBSIDIAN:0)
Block(-5,69,-3,OBSIDIAN:0)
Block(-5,70,-7,STONE:3)
Block(-5,70,-6,OBSIDIAN:0)
Block(-5,70,-5,OBSIDIAN:0)
Block(-5,70,-4,OBSIDIAN:0)
Block(-5,70,-3,OBSIDIAN:0)
Block(-5,71,-7,STONE:5)
Block(-5,71,-6,STONE:3)
Block(-5,71,-5,OBSIDIAN:0)
Block(-5,71,-4,OBSIDIAN:0)
Block(-5,71,-3,OBSIDIAN:0)
Block(-5,72,-6,STONE:3)
Block(-5,72,-5,OBSIDIAN:0)
Block(-5,72,-4,OBSIDIAN:0)
Block(-5,72,-3,OBSIDIAN:0)
Block(-5,73,-6,STONE:3)
Block(-5,73,-5,OBSIDIAN:0)
Block(-5,73,-4,OBSIDIAN:0)
Block(-5,73,-3,OBSIDIAN:0)
Block(-5,74,-6,STONE:3)
Block(-5,74,-5,STONE:3)
Block(-5,74,-4,OBSIDIAN:0)
Block(-5,74,-3,OBSIDIAN:0)
Block(-5,74,-2,OBSIDIAN:0)
Block(-5,74,-1,OBSIDIAN:0)
Block(-5,75,-6,STONE:5)
Block(-5,75,-5,STONE:3)
Block(-5,75,-4,STONE:3)
Block(-5,75,-3,OBSIDIAN:0)
Block(-5,75,-2,OBSIDIAN:0)
Block(-5,75,-1,OBSIDIAN:0)
Block(-5,75,0,OBSIDIAN:0)
Block(-5,75,1,OBSIDIAN:0)
Block(-5,76,-5,STONE:3)
Block(-5,76,-4,STONE:3)
Block(-5,76,-3,OBSIDIAN:0)
Block(-5,76,-2,OBSIDIAN:0)
Block(-5,76,-1,OBSIDIAN:0)
Block(-5,76,0,OBSIDIAN:0)
Block(-5,76,1,OBSIDIAN:0)
Block(-5,76,2,OBSIDIAN:0)
Block(-5,77,-5,STONE:5)
Block(-5,77,-4,STONE:3)
Block(-5,77,-3,STONE:3)
Block(-5,77,-2,OBSIDIAN:0)
Block(-5,77,-1,OBSIDIAN:0)
Block(-5,77,0,OBSIDIAN:0)
Block(-5,77,1,OBSIDIAN:0)
Block(-5,77,2,OBSIDIAN:0)
Block(-5,77,3,OBSIDIAN:0)
Block(-5,78,-4,STONE:3)
Block(-5,78,-3,STONE:3)
Block(-5,78,-2,STONE:3)
Block(-5,78,-1,OBSIDIAN:0)
Block(-5,78,0,OBSIDIAN:0)
Block(-5,78,1,OBSIDIAN:0)
Block(-5,78,2,OBSIDIAN:0)
Block(-5,78,3,OBSIDIAN:0)
Block(-5,79,-4,STONE:3)
Block(-5,79,-3,STONE:3)
Block(-5,79,-2,STONE:3)
Block(-5,79,-1,OBSIDIAN:0)
Block(-5,79,0,OBSIDIAN:0)
Block(-5,79,1,OBSIDIAN:0)
Block(-5,79,2,OBSIDIAN:0)
Block(-5,79,3,OBSIDIAN:0)
Block(-5,80,-4,STONE:5)
Block(-5,80,-3,STONE:3)
Block(-5,80,-2,STONE:3)
Block(-5,80,-1,OBSIDIAN:0)
Block(-5,80,0,OBSIDIAN:0)
Block(-5,80,1,OBSIDIAN:0)
Block(-5,80,2,OBSIDIAN:0)
Block(-5,80,3,OBSIDIAN:0)
Block(-5,80,4,OBSIDIAN:0)
Block(-5,81,-3,STONE:5)
Block(-5,81,-2,STONE:3)
Block(-5,81,-1,OBSIDIAN:0)
Block(-5,81,0,OBSIDIAN:0)
Block(-5,81,1,OBSIDIAN:0)
Block(-5,81,2,OBSIDIAN:0)
Block(-5,81,3,OBSIDIAN:0)
Block(-5,81,4,OBSIDIAN:0)
Block(-5,81,5,OBSIDIAN:0)
Block(-5,82,-2,STONE:5)
Block(-5,82,-1,STONE:3)
Block(-5,82,0,OBSIDIAN:0)
Block(-5,82,1,OBSIDIAN:0)
Block(-5,82,2,OBSIDIAN:0)
Block(-5,82,3,OBSIDIAN:0)
Block(-5,82,4,OBSIDIAN:0)
Block(-5,82,5,OBSIDIAN:0)
Block(-5,83,-1,STONE:3)
Block(-5,83,0,STONE:3)
Block(-5,83,1,OBSIDIAN:0)
Block(-5,83,2,OBSIDIAN:0)
Block(-5,83,3,OBSIDIAN:0)
Block(-5,83,4,OBSIDIAN:0)
Block(-5,83,5,OBSIDIAN:0)
Block(-5,84,-1,STONE:3)
Block(-5,84,0,STONE:3)
Block(-5,84,1,OBSIDIAN:0)
Block(-5,84,2,OBSIDIAN:0)
Block(-5,84,3,OBSIDIAN:0)
Block(-5,84,4,OBSIDIAN:0)
Block(-5,84,5,OBSIDIAN:0)
Block(-5,85,-1,STONE:3)
Block(-5,85,0,STONE:3)
Block(-5,85,1,STONE:3)
Block(-5,85,2,STONE:3)
Block(-5,85,3,OBSIDIAN:0)
Block(-5,85,4,OBSIDIAN:0)
Block(-5,85,5,OBSIDIAN:0)
Block(-5,85,6,OBSIDIAN:0)
Block(-5,85,7,OBSIDIAN:0)
Block(-5,86,0,STONE:3)
Block(-5,86,1,STONE:3)
Block(-5,86,2,STONE:3)
Block(-5,86,3,STONE:3)
Block(-5,86,4,OBSIDIAN:0)
Block(-5,86,5,OBSIDIAN:0)
Block(-5,86,6,OBSIDIAN:0)
Block(-5,86,7,OBSIDIAN:0)
Block(-5,86,8,OBSIDIAN:0)
Block(-5,87,-1,STONE:5)
Block(-5,87,0,STONE:5)
Block(-5,87,1,STONE:5)
Block(-5,87,2,STONE:3)
Block(-5,87,3,STONE:3)
Block(-5,87,4,STONE:3)
Block(-5,87,5,OBSIDIAN:0)
Block(-5,87,6,OBSIDIAN:0)
Block(-5,87,7,OBSIDIAN:0)
Block(-5,87,8,OBSIDIAN:0)
Block(-5,88,2,STONE:5)
Block(-5,88,3,STONE:3)
Block(-5,88,4,STONE:3)
Block(-5,88,5,STONE:3)
Block(-5,88,6,STONE:3)
Block(-5,88,7,STONE:3)
Block(-5,88,8,STONE:3)
Block(-5,89,3,STONE:3)
Block(-5,89,4,STONE:3)
Block(-5,89,5,STONE:3)
Block(-5,89,6,STONE:3)
Block(-5,89,7,STONE:3)
Block(-5,89,8,STONE:3)
Block(-5,90,6,STONE:3)
Block(-5,90,7,STONE:3)
Block(-5,90,8,STONE:3)
Block(-5,91,7,STONE:3)
Block(-5,91,8,STONE:3)
Block(-5,92,7,STONE:3)
Block(-5,92,8,STONE:3)
Block(-5,93,8,STONE:3)
Block(-4,20,6,STONE:3)
Block(-4,20,7,STONE:3)
Block(-4,20,8,OBSIDIAN:0)
Block(-4,21,6,STONE:3)
Block(-4,21,7,STONE:3)
Block(-4,21,8,STONE:3)
Block(-4,22,5,STONE:3)
Block(-4,22,6,STONE:3)
Block(-4,22,7,STONE:3)
Block(-4,22,8,STONE:3)
Block(-4,23,4,STONE:3)
Block(-4,23,5,STONE:3)
Block(-4,23,6,STONE:3)
Block(-4,23,7,STONE:3)
Block(-4,23,8,STONE:3)
Block(-4,24,3,STONE:3)
Block(-4,24,4,STONE:3)
Block(-4,24,5,STONE:3)
Block(-4,24,6,STONE:3)
Block(-4,24,7,STONE:3)
Block(-4,24,8,STONE:3)
Block(-4,25,3,STONE:3)
Block(-4,25,4,STONE:3)
Block(-4,25,5,STONE:3)
Block(-4,25,6,STONE:3)
Block(-4,25,7,STONE:3)
Block(-4,25,8,STONE:3)
Block(-4,26,-2,STONE:3)
Block(-4,26,-1,STONE:3)
Block(-4,26,0,STONE:3)
Block(-4,26,1,STONE:3)
Block(-4,26,2,STONE:3)
Block(-4,26,3,STONE:3)
Block(-4,26,4,STONE:3)
Block(-4,26,5,STONE:3)
Block(-4,26,6,STONE:3)
Block(-4,26,7,STONE:3)
Block(-4,26,8,STONE:3)
Block(-4,27,-3,STONE:3)
Block(-4,27,-2,STONE:3)
Block(-4,27,-1,STONE:3)
Block(-4,27,0,STONE:3)
Block(-4,27,1,STONE:3)
Block(-4,27,2,STONE:3)
Block(-4,27,3,STONE:3)
Block(-4,27,4,STONE:3)
Block(-4,27,5,STONE:3)
Block(-4,27,6,STONE:3)
Block(-4,27,7,STONE:3)
Block(-4,27,8,STONE:3)
Block(-4,28,-4,STONE:3)
Block(-4,28,-3,STONE:3)
Block(-4,28,-2,STONE:3)
Block(-4,28,-1,STONE:3)
Block(-4,28,0,STONE:3)
Block(-4,28,1,STONE:3)
Block(-4,28,2,STONE:3)
Block(-4,28,3,STONE:3)
Block(-4,28,4,STONE:3)
Block(-4,28,5,STONE:3)
Block(-4,28,6,STONE:3)
Block(-4,28,7,STONE:3)
Block(-4,28,8,STONE:3)
Block(-4,29,-4,STONE:3)
Block(-4,29,-3,STONE:3)
Block(-4,29,-2,STONE:3)
Block(-4,29,-1,STONE:3)
Block(-4,29,0,STONE:3)
Block(-4,29,1,STONE:3)
Block(-4,29,2,STONE:3)
Block(-4,29,3,STONE:3)
Block(-4,29,4,STONE:3)
Block(-4,29,5,STONE:3)
Block(-4,29,6,STONE:3)
Block(-4,29,7,STONE:3)
Block(-4,29,8,OBSIDIAN:0)
Block(-4,30,-5,STONE:3)
Block(-4,30,-4,STONE:3)
Block(-4,30,-3,STONE:3)
Block(-4,30,-2,STONE:3)
Block(-4,30,-1,STONE:3)
Block(-4,30,0,STONE:3)
Block(-4,30,1,STONE:3)
Block(-4,30,2,STONE:3)
Block(-4,30,3,STONE:3)
Block(-4,30,4,STONE:3)
Block(-4,30,5,STONE:3)
Block(-4,30,6,OBSIDIAN:0)
Block(-4,30,7,OBSIDIAN:0)
Block(-4,30,8,OBSIDIAN:0)
Block(-4,31,-6,STONE:3)
Block(-4,31,-5,STONE:3)
Block(-4,31,-4,STONE:3)
Block(-4,31,-3,STONE:3)
Block(-4,31,-2,STONE:3)
Block(-4,31,-1,STONE:3)
Block(-4,31,0,STONE:3)
Block(-4,31,1,STONE:3)
Block(-4,31,2,STONE:3)
Block(-4,31,3,STONE:3)
Block(-4,31,4,STONE:3)
Block(-4,31,5,OBSIDIAN:0)
Block(-4,31,6,OBSIDIAN:0)
Block(-4,31,7,OBSIDIAN:0)
Block(-4,31,8,OBSIDIAN:0)
Block(-4,32,-7,STONE:3)
Block(-4,32,-6,STONE:3)
Block(-4,32,-5,STONE:3)
Block(-4,32,-4,STONE:3)
Block(-4,32,-3,STONE:3)
Block(-4,32,-2,STONE:3)
Block(-4,32,-1,STONE:3)
Block(-4,32,0,STONE:3)
Block(-4,32,1,STONE:3)
Block(-4,32,2,STONE:3)
Block(-4,32,3,OBSIDIAN:0)
Block(-4,32,4,OBSIDIAN:0)
Block(-4,32,5,OBSIDIAN:0)
Block(-4,32,6,OBSIDIAN:0)
Block(-4,32,7,OBSIDIAN:0)
Block(-4,32,8,OBSIDIAN:0)
Block(-4,33,-7,STONE:3)
Block(-4,33,-6,STONE:3)
Block(-4,33,-5,STONE:3)
Block(-4,33,-4,STONE:3)
Block(-4,33,-3,STONE:3)
Block(-4,33,-2,STONE:3)
Block(-4,33,-1,STONE:3)
Block(-4,33,0,STONE:3)
Block(-4,33,1,STONE:3)
Block(-4,33,2,STONE:3)
Block(-4,33,3,OBSIDIAN:0)
Block(-4,33,4,OBSIDIAN:0)
Block(-4,33,5,OBSIDIAN:0)
Block(-4,33,6,OBSIDIAN:0)
Block(-4,33,7,OBSIDIAN:0)
Block(-4,33,8,OBSIDIAN:0)
Block(-4,34,-7,STONE:3)
Block(-4,34,-6,STONE:3)
Block(-4,34,-5,STONE:3)
Block(-4,34,-4,STONE:3)
Block(-4,34,-3,STONE:3)
Block(-4,34,-2,STONE:3)
Block(-4,34,-1,STONE:3)
Block(-4,34,0,STONE:3)
Block(-4,34,1,STONE:3)
Block(-4,34,2,STONE:3)
Block(-4,34,3,OBSIDIAN:0)
Block(-4,34,4,OBSIDIAN:0)
Block(-4,34,5,OBSIDIAN:0)
Block(-4,34,6,OBSIDIAN:0)
Block(-4,34,7,OBSIDIAN:0)
Block(-4,34,8,OBSIDIAN:0)
Block(-4,35,-7,STONE:3)
Block(-4,35,-6,STONE:3)
Block(-4,35,-5,STONE:3)
Block(-4,35,-4,STONE:3)
Block(-4,35,-3,STONE:3)
Block(-4,35,-2,STONE:3)
Block(-4,35,-1,STONE:3)
Block(-4,35,0,STONE:3)
Block(-4,35,1,STONE:3)
Block(-4,35,2,OBSIDIAN:0)
Block(-4,35,3,STONE:3)
Block(-4,35,4,STONE:3)
Block(-4,35,5,STONE:3)
Block(-4,35,6,OBSIDIAN:0)
Block(-4,35,7,OBSIDIAN:0)
Block(-4,35,8,OBSIDIAN:0)
Block(-4,36,-7,STONE:3)
Block(-4,36,-6,STONE:3)
Block(-4,36,-5,STONE:3)
Block(-4,36,-4,STONE:3)
Block(-4,36,-3,STONE:3)
Block(-4,36,-2,STONE:3)
Block(-4,36,-1,STONE:3)
Block(-4,36,0,STONE:3)
Block(-4,36,1,STONE:3)
Block(-4,36,2,OBSIDIAN:0)
Block(-4,36,3,STONE:3)
Block(-4,36,4,STONE:3)
Block(-4,36,5,STONE:3)
Block(-4,36,6,STONE:3)
Block(-4,36,7,OBSIDIAN:0)
Block(-4,36,8,OBSIDIAN:0)
Block(-4,37,-7,STONE:3)
Block(-4,37,-6,STONE:3)
Block(-4,37,-5,STONE:3)
Block(-4,37,-4,STONE:3)
Block(-4,37,-3,STONE:3)
Block(-4,37,-2,STONE:3)
Block(-4,37,-1,STONE:3)
Block(-4,37,0,STONE:3)
Block(-4,37,1,OBSIDIAN:0)
Block(-4,37,2,OBSIDIAN:0)
Block(-4,37,3,STONE:3)
Block(-4,37,4,STONE:3)
Block(-4,37,5,STONE:3)
Block(-4,37,6,STONE:3)
Block(-4,37,7,STONE:3)
Block(-4,37,8,STONE:3)
Block(-4,38,-7,STONE:3)
Block(-4,38,-6,STONE:3)
Block(-4,38,-5,STONE:3)
Block(-4,38,-4,STONE:3)
Block(-4,38,-3,STONE:3)
Block(-4,38,-2,STONE:3)
Block(-4,38,-1,OBSIDIAN:0)
Block(-4,38,0,OBSIDIAN:0)
Block(-4,38,1,OBSIDIAN:0)
Block(-4,38,2,OBSIDIAN:0)
Block(-4,38,3,STONE:3)
Block(-4,38,4,STONE:3)
Block(-4,38,5,STONE:3)
Block(-4,38,6,STONE:3)
Block(-4,38,7,STONE:3)
Block(-4,38,8,STONE:3)
Block(-4,39,-7,STONE:3)
Block(-4,39,-6,STONE:3)
Block(-4,39,-5,STONE:3)
Block(-4,39,-4,STONE:3)
Block(-4,39,-3,STONE:3)
Block(-4,39,-2,STONE:3)
Block(-4,39,-1,OBSIDIAN:0)
Block(-4,39,0,OBSIDIAN:0)
Block(-4,39,1,OBSIDIAN:0)
Block(-4,39,2,OBSIDIAN:0)
Block(-4,39,3,STONE:3)
Block(-4,39,4,OBSIDIAN:0)
Block(-4,39,5,OBSIDIAN:0)
Block(-4,39,6,STONE:3)
Block(-4,39,7,STONE:3)
Block(-4,39,8,STONE:3)
Block(-4,40,-7,STONE:3)
Block(-4,40,-6,STONE:3)
Block(-4,40,-5,STONE:3)
Block(-4,40,-4,STONE:3)
Block(-4,40,-3,STONE:3)
Block(-4,40,-2,STONE:3)
Block(-4,40,-1,STONE:3)
Block(-4,40,0,OBSIDIAN:0)
Block(-4,40,1,OBSIDIAN:0)
Block(-4,40,2,OBSIDIAN:0)
Block(-4,40,3,OBSIDIAN:0)
Block(-4,40,4,OBSIDIAN:0)
Block(-4,40,5,OBSIDIAN:0)
Block(-4,40,6,STONE:3)
Block(-4,40,7,STONE:3)
Block(-4,40,8,STONE:3)
Block(-4,41,-7,STONE:3)
Block(-4,41,-6,STONE:3)
Block(-4,41,-5,STONE:3)
Block(-4,41,-4,STONE:3)
Block(-4,41,-3,STONE:3)
Block(-4,41,-2,STONE:3)
Block(-4,41,-1,STONE:3)
Block(-4,41,0,OBSIDIAN:0)
Block(-4,41,1,OBSIDIAN:0)
Block(-4,41,2,OBSIDIAN:0)
Block(-4,41,3,OBSIDIAN:0)
Block(-4,41,4,OBSIDIAN:0)
Block(-4,41,5,OBSIDIAN:0)
Block(-4,41,6,STONE:3)
Block(-4,41,7,STONE:3)
Block(-4,41,8,STONE:3)
Block(-4,42,-7,STONE:3)
Block(-4,42,-6,STONE:3)
Block(-4,42,-5,STONE:3)
Block(-4,42,-4,STONE:3)
Block(-4,42,-3,STONE:3)
Block(-4,42,-2,STONE:3)
Block(-4,42,-1,STONE:3)
Block(-4,42,0,OBSIDIAN:0)
Block(-4,42,1,OBSIDIAN:0)
Block(-4,42,2,OBSIDIAN:0)
Block(-4,42,3,OBSIDIAN:0)
Block(-4,42,4,OBSIDIAN:0)
Block(-4,42,5,OBSIDIAN:0)
Block(-4,42,6,STONE:3)
Block(-4,42,7,STONE:3)
Block(-4,43,-7,STONE:3)
Block(-4,43,-6,STONE:3)
Block(-4,43,-5,STONE:3)
Block(-4,43,-4,STONE:3)
Block(-4,43,-3,STONE:3)
Block(-4,43,-2,STONE:3)
Block(-4,43,-1,OBSIDIAN:0)
Block(-4,43,0,OBSIDIAN:0)
Block(-4,43,1,OBSIDIAN:0)
Block(-4,43,2,OBSIDIAN:0)
Block(-4,43,3,OBSIDIAN:0)
Block(-4,43,4,OBSIDIAN:0)
Block(-4,43,5,OBSIDIAN:0)
Block(-4,43,6,STONE:3)
Block(-4,44,-7,STONE:3)
Block(-4,44,-6,STONE:3)
Block(-4,44,-5,STONE:3)
Block(-4,44,-4,STONE:3)
Block(-4,44,-3,STONE:3)
Block(-4,44,-2,OBSIDIAN:0)
Block(-4,44,-1,OBSIDIAN:0)
Block(-4,44,0,OBSIDIAN:0)
Block(-4,44,1,OBSIDIAN:0)
Block(-4,44,2,OBSIDIAN:0)
Block(-4,44,3,OBSIDIAN:0)
Block(-4,44,4,OBSIDIAN:0)
Block(-4,44,5,OBSIDIAN:0)
Block(-4,44,6,STONE:3)
Block(-4,45,-7,STONE:3)
Block(-4,45,-6,STONE:3)
Block(-4,45,-5,STONE:3)
Block(-4,45,-4,STONE:3)
Block(-4,45,-3,STONE:3)
Block(-4,45,-2,OBSIDIAN:0)
Block(-4,45,-1,OBSIDIAN:0)
Block(-4,45,0,OBSIDIAN:0)
Block(-4,45,1,OBSIDIAN:0)
Block(-4,45,2,OBSIDIAN:0)
Block(-4,45,3,OBSIDIAN:0)
Block(-4,45,4,OBSIDIAN:0)
Block(-4,46,-7,STONE:3)
Block(-4,46,-6,STONE:3)
Block(-4,46,-5,STONE:3)
Block(-4,46,-4,STONE:3)
Block(-4,46,-3,OBSIDIAN:0)
Block(-4,46,-2,OBSIDIAN:0)
Block(-4,46,-1,OBSIDIAN:0)
Block(-4,47,-7,STONE:3)
Block(-4,47,-6,STONE:3)
Block(-4,47,-5,STONE:3)
Block(-4,47,-4,OBSIDIAN:0)
Block(-4,47,-3,OBSIDIAN:0)
Block(-4,47,-2,OBSIDIAN:0)
Block(-4,47,-1,OBSIDIAN:0)
Block(-4,48,-7,STONE:3)
Block(-4,48,-6,STONE:3)
Block(-4,48,-5,STONE:3)
Block(-4,48,-4,OBSIDIAN:0)
Block(-4,48,-3,OBSIDIAN:0)
Block(-4,48,-2,OBSIDIAN:0)
Block(-4,48,-1,OBSIDIAN:0)
Block(-4,49,-7,STONE:3)
Block(-4,49,-6,STONE:3)
Block(-4,49,-5,STONE:3)
Block(-4,49,-4,OBSIDIAN:0)
Block(-4,49,-3,OBSIDIAN:0)
Block(-4,49,-2,OBSIDIAN:0)
Block(-4,49,-1,OBSIDIAN:0)
Block(-4,50,-7,OBSIDIAN:0)
Block(-4,50,-6,STONE:3)
Block(-4,50,-5,STONE:3)
Block(-4,50,-4,OBSIDIAN:0)
Block(-4,50,-3,OBSIDIAN:0)
Block(-4,50,-2,OBSIDIAN:0)
Block(-4,50,-1,OBSIDIAN:0)
Block(-4,51,-7,OBSIDIAN:0)
Block(-4,51,-6,OBSIDIAN:0)
Block(-4,51,-5,STONE:3)
Block(-4,51,-4,OBSIDIAN:0)
Block(-4,51,-3,OBSIDIAN:0)
Block(-4,51,-2,OBSIDIAN:0)
Block(-4,51,-1,OBSIDIAN:0)
Block(-4,52,-7,OBSIDIAN:0)
Block(-4,52,-6,OBSIDIAN:0)
Block(-4,52,-5,OBSIDIAN:0)
Block(-4,52,-4,OBSIDIAN:0)
Block(-4,52,-3,OBSIDIAN:0)
Block(-4,52,-2,OBSIDIAN:0)
Block(-4,53,-7,OBSIDIAN:0)
Block(-4,53,-6,OBSIDIAN:0)
Block(-4,53,-5,OBSIDIAN:0)
Block(-4,53,-4,OBSIDIAN:0)
Block(-4,53,-3,OBSIDIAN:0)
Block(-4,53,-2,OBSIDIAN:0)
Block(-4,54,-7,OBSIDIAN:0)
Block(-4,54,-6,OBSIDIAN:0)
Block(-4,54,-5,OBSIDIAN:0)
Block(-4,54,-4,OBSIDIAN:0)
Block(-4,54,-3,OBSIDIAN:0)
Block(-4,54,-2,OBSIDIAN:0)
Block(-4,55,-7,OBSIDIAN:0)
Block(-4,55,-6,OBSIDIAN:0)
Block(-4,55,-5,OBSIDIAN:0)
Block(-4,55,-4,OBSIDIAN:0)
Block(-4,55,-3,OBSIDIAN:0)
Block(-4,55,-2,OBSIDIAN:0)
Block(-4,56,-7,OBSIDIAN:0)
Block(-4,56,-6,OBSIDIAN:0)
Block(-4,56,-5,OBSIDIAN:0)
Block(-4,56,-4,OBSIDIAN:0)
Block(-4,56,-3,OBSIDIAN:0)
Block(-4,57,-7,OBSIDIAN:0)
Block(-4,57,-6,OBSIDIAN:0)
Block(-4,57,-5,OBSIDIAN:0)
Block(-4,57,-4,OBSIDIAN:0)
Block(-4,57,-3,OBSIDIAN:0)
Block(-4,58,-7,OBSIDIAN:0)
Block(-4,58,-6,OBSIDIAN:0)
Block(-4,58,-5,OBSIDIAN:0)
Block(-4,58,-4,OBSIDIAN:0)
Block(-4,58,-3,OBSIDIAN:0)
Block(-4,59,-7,OBSIDIAN:0)
Block(-4,59,-6,OBSIDIAN:0)
Block(-4,59,-5,OBSIDIAN:0)
Block(-4,59,-4,OBSIDIAN:0)
Block(-4,59,-3,OBSIDIAN:0)
Block(-4,59,-2,OBSIDIAN:0)
Block(-4,60,-7,OBSIDIAN:0)
Block(-4,60,-6,STONE:3)
Block(-4,60,-5,OBSIDIAN:0)
Block(-4,60,-4,OBSIDIAN:0)
Block(-4,60,-3,OBSIDIAN:0)
Block(-4,60,-2,OBSIDIAN:0)
Block(-4,61,-7,STONE:3)
Block(-4,61,-6,STONE:3)
Block(-4,61,-5,OBSIDIAN:0)
Block(-4,61,-4,STONE:3)
Block(-4,61,-3,STONE:3)
Block(-4,61,-2,STONE:3)
Block(-4,62,-7,STONE:3)
Block(-4,62,-6,OBSIDIAN:0)
Block(-4,62,-5,STONE:3)
Block(-4,62,-4,STONE:3)
Block(-4,62,-3,STONE:3)
Block(-4,62,-2,STONE:3)
Block(-4,63,-7,STONE:3)
Block(-4,63,-6,OBSIDIAN:0)
Block(-4,63,-5,STONE:3)
Block(-4,63,-4,STONE:3)
Block(-4,63,-3,STONE:3)
Block(-4,64,-7,STONE:3)
Block(-4,64,-6,OBSIDIAN:0)
Block(-4,64,-5,STONE:3)
Block(-4,64,-4,STONE:3)
Block(-4,64,-3,STONE:3)
Block(-4,65,-7,STONE:3)
Block(-4,65,-6,OBSIDIAN:0)
Block(-4,65,-5,OBSIDIAN:0)
Block(-4,65,-4,STONE:3)
Block(-4,65,-3,STONE:3)
Block(-4,65,-2,STONE:3)
Block(-4,66,-7,STONE:3)
Block(-4,66,-6,OBSIDIAN:0)
Block(-4,66,-5,OBSIDIAN:0)
Block(-4,66,-4,OBSIDIAN:0)
Block(-4,66,-3,OBSIDIAN:0)
Block(-4,66,-2,OBSIDIAN:0)
Block(-4,67,-7,STONE:3)
Block(-4,67,-6,OBSIDIAN:0)
Block(-4,67,-5,OBSIDIAN:0)
Block(-4,67,-4,OBSIDIAN:0)
Block(-4,67,-3,OBSIDIAN:0)
Block(-4,68,-7,STONE:3)
Block(-4,68,-6,OBSIDIAN:0)
Block(-4,68,-5,OBSIDIAN:0)
Block(-4,68,-4,OBSIDIAN:0)
Block(-4,68,-3,OBSIDIAN:0)
Block(-4,69,-7,STONE:3)
Block(-4,69,-6,OBSIDIAN:0)
Block(-4,69,-5,OBSIDIAN:0)
Block(-4,69,-4,OBSIDIAN:0)
Block(-4,69,-3,OBSIDIAN:0)
Block(-4,70,-7,STONE:3)
Block(-4,70,-6,OBSIDIAN:0)
Block(-4,70,-5,OBSIDIAN:0)
Block(-4,70,-4,OBSIDIAN:0)
Block(-4,70,-3,OBSIDIAN:0)
Block(-4,71,-7,STONE:3)
Block(-4,71,-6,STONE:3)
Block(-4,71,-5,OBSIDIAN:0)
Block(-4,71,-4,OBSIDIAN:0)
Block(-4,71,-3,OBSIDIAN:0)
Block(-4,72,-7,STONE:5)
Block(-4,72,-6,STONE:3)
Block(-4,72,-5,STONE:3)
Block(-4,72,-4,OBSIDIAN:0)
Block(-4,72,-3,OBSIDIAN:0)
Block(-4,73,-6,STONE:3)
Block(-4,73,-5,STONE:3)
Block(-4,73,-4,OBSIDIAN:0)
Block(-4,73,-3,OBSIDIAN:0)
Block(-4,74,-6,STONE:5)
Block(-4,74,-5,STONE:3)
Block(-4,74,-4,STONE:3)
Block(-4,74,-3,OBSIDIAN:0)
Block(-4,74,-2,OBSIDIAN:0)
Block(-4,74,-1,OBSIDIAN:0)
Block(-4,75,-5,STONE:3)
Block(-4,75,-4,STONE:3)
Block(-4,75,-3,OBSIDIAN:0)
Block(-4,75,-2,OBSIDIAN:0)
Block(-4,75,-1,OBSIDIAN:0)
Block(-4,75,0,OBSIDIAN:0)
Block(-4,75,1,OBSIDIAN:0)
Block(-4,76,-5,STONE:5)
Block(-4,76,-4,STONE:3)
Block(-4,76,-3,OBSIDIAN:0)
Block(-4,76,-2,OBSIDIAN:0)
Block(-4,76,-1,OBSIDIAN:0)
Block(-4,76,0,OBSIDIAN:0)
Block(-4,76,1,OBSIDIAN:0)
Block(-4,76,2,OBSIDIAN:0)
Block(-4,77,-4,STONE:3)
Block(-4,77,-3,STONE:3)
Block(-4,77,-2,STONE:3)
Block(-4,77,-1,OBSIDIAN:0)
Block(-4,77,0,OBSIDIAN:0)
Block(-4,77,1,OBSIDIAN:0)
Block(-4,77,2,OBSIDIAN:0)
Block(-4,78,-4,STONE:5)
Block(-4,78,-3,STONE:3)
Block(-4,78,-2,STONE:3)
Block(-4,78,-1,OBSIDIAN:0)
Block(-4,78,0,OBSIDIAN:0)
Block(-4,78,1,OBSIDIAN:0)
Block(-4,78,2,OBSIDIAN:0)
Block(-4,78,3,OBSIDIAN:0)
Block(-4,79,-3,STONE:3)
Block(-4,79,-2,STONE:3)
Block(-4,79,-1,OBSIDIAN:0)
Block(-4,79,0,OBSIDIAN:0)
Block(-4,79,1,OBSIDIAN:0)
Block(-4,79,2,OBSIDIAN:0)
Block(-4,79,3,OBSIDIAN:0)
Block(-4,79,4,OBSIDIAN:0)
Block(-4,80,-3,STONE:3)
Block(-4,80,-2,STONE:3)
Block(-4,80,-1,OBSIDIAN:0)
Block(-4,80,0,OBSIDIAN:0)
Block(-4,80,1,OBSIDIAN:0)
Block(-4,80,2,OBSIDIAN:0)
Block(-4,80,3,OBSIDIAN:0)
Block(-4,80,4,OBSIDIAN:0)
Block(-4,80,5,OBSIDIAN:0)
Block(-4,81,-3,STONE:5)
Block(-4,81,-2,OBSIDIAN:0)
Block(-4,81,-1,OBSIDIAN:0)
Block(-4,81,0,OBSIDIAN:0)
Block(-4,81,1,OBSIDIAN:0)
Block(-4,81,2,OBSIDIAN:0)
Block(-4,81,3,OBSIDIAN:0)
Block(-4,81,4,OBSIDIAN:0)
Block(-4,81,5,OBSIDIAN:0)
Block(-4,82,-2,STONE:3)
Block(-4,82,-1,STONE:3)
Block(-4,82,0,OBSIDIAN:0)
Block(-4,82,1,OBSIDIAN:0)
Block(-4,82,2,OBSIDIAN:0)
Block(-4,82,3,OBSIDIAN:0)
Block(-4,82,4,OBSIDIAN:0)
Block(-4,82,5,OBSIDIAN:0)
Block(-4,83,-2,STONE:5)
Block(-4,83,-1,STONE:3)
Block(-4,83,0,OBSIDIAN:0)
Block(-4,83,1,OBSIDIAN:0)
Block(-4,83,2,OBSIDIAN:0)
Block(-4,83,3,OBSIDIAN:0)
Block(-4,83,4,OBSIDIAN:0)
Block(-4,83,5,OBSIDIAN:0)
Block(-4,83,6,OBSIDIAN:0)
Block(-4,84,-1,STONE:3)
Block(-4,84,0,STONE:3)
Block(-4,84,1,STONE:3)
Block(-4,84,2,OBSIDIAN:0)
Block(-4,84,3,OBSIDIAN:0)
Block(-4,84,4,OBSIDIAN:0)
Block(-4,84,5,OBSIDIAN:0)
Block(-4,84,6,OBSIDIAN:0)
Block(-4,84,7,OBSIDIAN:0)
Block(-4,85,-1,STONE:3)
Block(-4,85,0,STONE:3)
Block(-4,85,1,STONE:3)
Block(-4,85,2,STONE:3)
Block(-4,85,3,OBSIDIAN:0)
Block(-4,85,4,OBSIDIAN:0)
Block(-4,85,5,OBSIDIAN:0)
Block(-4,85,6,OBSIDIAN:0)
Block(-4,85,7,OBSIDIAN:0)
Block(-4,85,8,OBSIDIAN:0)
Block(-4,86,-1,STONE:3)
Block(-4,86,0,STONE:3)
Block(-4,86,1,STONE:3)
Block(-4,86,2,STONE:3)
Block(-4,86,3,STONE:3)
Block(-4,86,4,OBSIDIAN:0)
Block(-4,86,5,OBSIDIAN:0)
Block(-4,86,6,OBSIDIAN:0)
Block(-4,86,7,OBSIDIAN:0)
Block(-4,86,8,OBSIDIAN:0)
Block(-4,87,-1,STONE:3)
Block(-4,87,0,STONE:3)
Block(-4,87,1,STONE:3)
Block(-4,87,2,STONE:3)
Block(-4,87,3,STONE:3)
Block(-4,87,4,STONE:3)
Block(-4,87,5,OBSIDIAN:0)
Block(-4,87,6,OBSIDIAN:0)
Block(-4,87,7,OBSIDIAN:0)
Block(-4,87,8,STONE:3)
Block(-4,88,-1,STONE:5)
Block(-4,88,0,STONE:5)
Block(-4,88,1,STONE:5)
Block(-4,88,2,STONE:3)
Block(-4,88,3,STONE:3)
Block(-4,88,4,STONE:3)
Block(-4,88,5,STONE:3)
Block(-4,88,6,STONE:3)
Block(-4,88,7,STONE:3)
Block(-4,88,8,STONE:3)
Block(-4,89,2,STONE:3)
Block(-4,89,3,STONE:3)
Block(-4,89,4,STONE:3)
Block(-4,89,5,STONE:3)
Block(-4,89,6,STONE:3)
Block(-4,89,7,STONE:3)
Block(-4,89,8,STONE:3)
Block(-4,90,4,STONE:3)
Block(-4,90,5,STONE:3)
Block(-4,90,6,STONE:3)
Block(-4,90,7,STONE:3)
Block(-4,90,8,STONE:3)
Block(-4,91,6,STONE:3)
Block(-4,91,7,STONE:3)
Block(-4,91,8,STONE:3)
Block(-4,92,6,STONE:3)
Block(-4,92,7,STONE:3)
Block(-4,92,8,STONE:3)
Block(-4,93,7,STONE:3)
Block(-4,93,8,STONE:3)
Block(-4,94,8,STONE:3)
Block(-3,21,8,STONE:3)
Block(-3,22,6,STONE:3)
Block(-3,22,7,STONE:3)
Block(-3,22,8,STONE:3)
Block(-3,23,5,STONE:3)
Block(-3,23,6,STONE:3)
Block(-3,23,7,STONE:3)
Block(-3,23,8,STONE:3)
Block(-3,24,4,STONE:3)
Block(-3,24,5,STONE:3)
Block(-3,24,6,STONE:3)
Block(-3,24,7,STONE:3)
Block(-3,24,8,STONE:3)
Block(-3,25,4,STONE:3)
Block(-3,25,5,STONE:3)
Block(-3,25,6,STONE:3)
Block(-3,25,7,STONE:3)
Block(-3,25,8,STONE:3)
Block(-3,26,3,STONE:3)
Block(-3,26,4,STONE:3)
Block(-3,26,5,STONE:3)
Block(-3,26,6,STONE:3)
Block(-3,26,7,STONE:3)
Block(-3,26,8,STONE:3)
Block(-3,27,-2,STONE:3)
Block(-3,27,-1,STONE:3)
Block(-3,27,0,STONE:3)
Block(-3,27,1,STONE:3)
Block(-3,27,2,STONE:3)
Block(-3,27,3,STONE:3)
Block(-3,27,4,STONE:3)
Block(-3,27,5,STONE:3)
Block(-3,27,6,STONE:3)
Block(-3,27,7,STONE:3)
Block(-3,27,8,STONE:3)
Block(-3,28,-3,STONE:3)
Block(-3,28,-2,STONE:3)
Block(-3,28,-1,STONE:3)
Block(-3,28,0,STONE:3)
Block(-3,28,1,STONE:3)
Block(-3,28,2,STONE:3)
Block(-3,28,3,STONE:3)
Block(-3,28,4,STONE:3)
Block(-3,28,5,STONE:3)
Block(-3,28,6,STONE:3)
Block(-3,28,7,STONE:3)
Block(-3,28,8,STONE:3)
Block(-3,29,-3,STONE:3)
Block(-3,29,-2,STONE:3)
Block(-3,29,-1,STONE:3)
Block(-3,29,0,STONE:3)
Block(-3,29,1,STONE:3)
Block(-3,29,2,STONE:3)
Block(-3,29,3,STONE:3)
Block(-3,29,4,STONE:3)
Block(-3,29,5,STONE:3)
Block(-3,29,6,STONE:3)
Block(-3,29,7,STONE:3)
Block(-3,29,8,STONE:3)
Block(-3,30,-3,STONE:3)
Block(-3,30,-2,STONE:3)
Block(-3,30,-1,STONE:3)
Block(-3,30,0,STONE:3)
Block(-3,30,1,STONE:3)
Block(-3,30,2,STONE:3)
Block(-3,30,3,STONE:3)
Block(-3,30,4,STONE:3)
Block(-3,30,5,STONE:3)
Block(-3,30,6,STONE:3)
Block(-3,30,7,STONE:3)
Block(-3,30,8,OBSIDIAN:0)
Block(-3,31,-4,STONE:3)
Block(-3,31,-3,STONE:3)
Block(-3,31,-2,STONE:3)
Block(-3,31,-1,STONE:3)
Block(-3,31,0,STONE:3)
Block(-3,31,1,STONE:3)
Block(-3,31,2,STONE:3)
Block(-3,31,3,STONE:3)
Block(-3,31,4,STONE:3)
Block(-3,31,5,OBSIDIAN:0)
Block(-3,31,6,OBSIDIAN:0)
Block(-3,31,7,OBSIDIAN:0)
Block(-3,31,8,OBSIDIAN:0)
Block(-3,32,-7,STONE:3)
Block(-3,32,-6,STONE:3)
Block(-3,32,-5,STONE:3)
Block(-3,32,-4,STONE:3)
Block(-3,32,-3,STONE:3)
Block(-3,32,-2,STONE:3)
Block(-3,32,-1,STONE:3)
Block(-3,32,0,STONE:3)
Block(-3,32,1,STONE:3)
Block(-3,32,2,STONE:3)
Block(-3,32,3,OBSIDIAN:0)
Block(-3,32,4,OBSIDIAN:0)
Block(-3,32,5,OBSIDIAN:0)
Block(-3,32,6,OBSIDIAN:0)
Block(-3,32,7,OBSIDIAN:0)
Block(-3,32,8,OBSIDIAN:0)
Block(-3,33,-7,STONE:3)
Block(-3,33,-6,STONE:3)
Block(-3,33,-5,STONE:3)
Block(-3,33,-4,STONE:3)
Block(-3,33,-3,STONE:3)
Block(-3,33,-2,STONE:3)
Block(-3,33,-1,STONE:3)
Block(-3,33,0,STONE:3)
Block(-3,33,1,STONE:3)
Block(-3,33,2,STONE:3)
Block(-3,33,3,OBSIDIAN:0)
Block(-3,33,4,OBSIDIAN:0)
Block(-3,33,5,OBSIDIAN:0)
Block(-3,33,6,OBSIDIAN:0)
Block(-3,33,7,OBSIDIAN:0)
Block(-3,33,8,OBSIDIAN:0)
Block(-3,34,-7,STONE:3)
Block(-3,34,-6,STONE:3)
Block(-3,34,-5,STONE:3)
Block(-3,34,-4,STONE:3)
Block(-3,34,-3,STONE:3)
Block(-3,34,-2,STONE:3)
Block(-3,34,-1,STONE:3)
Block(-3,34,0,STONE:3)
Block(-3,34,1,STONE:3)
Block(-3,34,2,STONE:3)
Block(-3,34,3,OBSIDIAN:0)
Block(-3,34,4,OBSIDIAN:0)
Block(-3,34,5,OBSIDIAN:0)
Block(-3,34,6,OBSIDIAN:0)
Block(-3,34,7,OBSIDIAN:0)
Block(-3,34,8,OBSIDIAN:0)
Block(-3,35,-7,STONE:3)
Block(-3,35,-6,STONE:3)
Block(-3,35,-5,STONE:3)
Block(-3,35,-4,STONE:3)
Block(-3,35,-3,STONE:3)
Block(-3,35,-2,STONE:3)
Block(-3,35,-1,STONE:3)
Block(-3,35,0,STONE:3)
Block(-3,35,1,STONE:3)
Block(-3,35,2,STONE:3)
Block(-3,35,3,OBSIDIAN:0)
Block(-3,35,4,OBSIDIAN:0)
Block(-3,35,5,OBSIDIAN:0)
Block(-3,35,6,OBSIDIAN:0)
Block(-3,35,7,OBSIDIAN:0)
Block(-3,35,8,OBSIDIAN:0)
Block(-3,36,-7,STONE:3)
Block(-3,36,-6,STONE:3)
Block(-3,36,-5,STONE:3)
Block(-3,36,-4,STONE:3)
Block(-3,36,-3,STONE:3)
Block(-3,36,-2,STONE:3)
Block(-3,36,-1,STONE:3)
Block(-3,36,0,STONE:3)
Block(-3,36,1,STONE:3)
Block(-3,36,2,OBSIDIAN:0)
Block(-3,36,3,OBSIDIAN:0)
Block(-3,36,4,OBSIDIAN:0)
Block(-3,36,5,OBSIDIAN:0)
Block(-3,36,6,OBSIDIAN:0)
Block(-3,36,7,OBSIDIAN:0)
Block(-3,36,8,OBSIDIAN:0)
Block(-3,37,-7,STONE:3)
Block(-3,37,-6,STONE:3)
Block(-3,37,-5,STONE:3)
Block(-3,37,-4,STONE:3)
Block(-3,37,-3,STONE:3)
Block(-3,37,-2,STONE:3)
Block(-3,37,-1,STONE:3)
Block(-3,37,0,STONE:3)
Block(-3,37,1,OBSIDIAN:0)
Block(-3,37,2,OBSIDIAN:0)
Block(-3,37,3,OBSIDIAN:0)
Block(-3,37,4,STONE:3)
Block(-3,37,5,STONE:3)
Block(-3,37,6,STONE:3)
Block(-3,37,7,STONE:3)
Block(-3,37,8,OBSIDIAN:0)
Block(-3,38,-7,STONE:3)
Block(-3,38,-6,STONE:3)
Block(-3,38,-5,STONE:3)
Block(-3,38,-4,STONE:3)
Block(-3,38,-3,STONE:3)
Block(-3,38,-2,STONE:3)
Block(-3,38,-1,STONE:3)
Block(-3,38,0,OBSIDIAN:0)
Block(-3,38,1,OBSIDIAN:0)
Block(-3,38,2,OBSIDIAN:0)
Block(-3,38,3,OBSIDIAN:0)
Block(-3,38,4,STONE:3)
Block(-3,38,5,STONE:3)
Block(-3,38,6,STONE:3)
Block(-3,38,7,STONE:3)
Block(-3,38,8,STONE:3)
Block(-3,39,-7,STONE:3)
Block(-3,39,-6,STONE:3)
Block(-3,39,-5,STONE:3)
Block(-3,39,-4,STONE:3)
Block(-3,39,-3,STONE:3)
Block(-3,39,-2,STONE:3)
Block(-3,39,-1,STONE:3)
Block(-3,39,0,OBSIDIAN:0)
Block(-3,39,1,OBSIDIAN:0)
Block(-3,39,2,OBSIDIAN:0)
Block(-3,39,3,OBSIDIAN:0)
Block(-3,39,4,STONE:3)
Block(-3,39,5,STONE:3)
Block(-3,39,6,OBSIDIAN:0)
Block(-3,39,7,STONE:3)
Block(-3,39,8,STONE:3)
Block(-3,40,-7,STONE:3)
Block(-3,40,-6,STONE:3)
Block(-3,40,-5,STONE:3)
Block(-3,40,-4,STONE:3)
Block(-3,40,-3,STONE:3)
Block(-3,40,-2,STONE:3)
Block(-3,40,-1,STONE:3)
Block(-3,40,0,OBSIDIAN:0)
Block(-3,40,1,OBSIDIAN:0)
Block(-3,40,2,OBSIDIAN:0)
Block(-3,40,3,OBSIDIAN:0)
Block(-3,40,4,STONE:3)
Block(-3,40,5,STONE:3)
Block(-3,40,6,STONE:3)
Block(-3,40,7,STONE:3)
Block(-3,40,8,STONE:3)
Block(-3,41,-7,STONE:3)
Block(-3,41,-6,STONE:3)
Block(-3,41,-5,STONE:3)
Block(-3,41,-4,STONE:3)
Block(-3,41,-3,STONE:3)
Block(-3,41,-2,STONE:3)
Block(-3,41,-1,STONE:3)
Block(-3,41,0,OBSIDIAN:0)
Block(-3,41,1,OBSIDIAN:0)
Block(-3,41,2,OBSIDIAN:0)
Block(-3,41,3,OBSIDIAN:0)
Block(-3,41,4,STONE:3)
Block(-3,41,5,OBSIDIAN:0)
Block(-3,41,6,STONE:3)
Block(-3,41,7,STONE:3)
Block(-3,41,8,STONE:3)
Block(-3,42,-7,STONE:3)
Block(-3,42,-6,STONE:3)
Block(-3,42,-5,STONE:3)
Block(-3,42,-4,STONE:3)
Block(-3,42,-3,STONE:3)
Block(-3,42,-2,STONE:3)
Block(-3,42,-1,STONE:3)
Block(-3,42,0,OBSIDIAN:0)
Block(-3,42,1,OBSIDIAN:0)
Block(-3,42,2,OBSIDIAN:0)
Block(-3,42,3,OBSIDIAN:0)
Block(-3,42,4,OBSIDIAN:0)
Block(-3,42,5,STONE:3)
Block(-3,42,6,STONE:3)
Block(-3,42,7,STONE:3)
Block(-3,43,-7,STONE:3)
Block(-3,43,-6,STONE:3)
Block(-3,43,-5,STONE:3)
Block(-3,43,-4,STONE:3)
Block(-3,43,-3,STONE:3)
Block(-3,43,-2,STONE:3)
Block(-3,43,-1,OBSIDIAN:0)
Block(-3,43,0,OBSIDIAN:0)
Block(-3,43,1,OBSIDIAN:0)
Block(-3,43,2,OBSIDIAN:0)
Block(-3,43,3,OBSIDIAN:0)
Block(-3,43,4,OBSIDIAN:0)
Block(-3,43,5,STONE:3)
Block(-3,43,6,STONE:3)
Block(-3,43,7,STONE:3)
Block(-3,44,-7,STONE:3)
Block(-3,44,-6,STONE:3)
Block(-3,44,-5,STONE:3)
Block(-3,44,-4,STONE:3)
Block(-3,44,-3,STONE:3)
Block(-3,44,-2,OBSIDIAN:0)
Block(-3,44,-1,OBSIDIAN:0)
Block(-3,44,0,OBSIDIAN:0)
Block(-3,44,1,OBSIDIAN:0)
Block(-3,44,2,OBSIDIAN:0)
Block(-3,44,3,OBSIDIAN:0)
Block(-3,44,4,OBSIDIAN:0)
Block(-3,44,5,STONE:3)
Block(-3,44,6,STONE:3)
Block(-3,45,-7,STONE:3)
Block(-3,45,-6,STONE:3)
Block(-3,45,-5,STONE:3)
Block(-3,45,-4,STONE:3)
Block(-3,45,-3,STONE:3)
Block(-3,45,-2,OBSIDIAN:0)
Block(-3,45,-1,OBSIDIAN:0)
Block(-3,45,0,OBSIDIAN:0)
Block(-3,45,1,OBSIDIAN:0)
Block(-3,45,2,OBSIDIAN:0)
Block(-3,45,3,OBSIDIAN:0)
Block(-3,45,4,OBSIDIAN:0)
Block(-3,45,5,OBSIDIAN:0)
Block(-3,46,-7,STONE:3)
Block(-3,46,-6,STONE:3)
Block(-3,46,-5,STONE:3)
Block(-3,46,-4,STONE:3)
Block(-3,46,-3,OBSIDIAN:0)
Block(-3,46,-2,OBSIDIAN:0)
Block(-3,46,-1,OBSIDIAN:0)
Block(-3,46,0,OBSIDIAN:0)
Block(-3,47,-7,STONE:3)
Block(-3,47,-6,STONE:3)
Block(-3,47,-5,STONE:3)
Block(-3,47,-4,OBSIDIAN:0)
Block(-3,47,-3,OBSIDIAN:0)
Block(-3,47,-2,OBSIDIAN:0)
Block(-3,47,-1,OBSIDIAN:0)
Block(-3,48,-7,STONE:3)
Block(-3,48,-6,STONE:3)
Block(-3,48,-5,STONE:3)
Block(-3,48,-4,OBSIDIAN:0)
Block(-3,48,-3,OBSIDIAN:0)
Block(-3,48,-2,OBSIDIAN:0)
Block(-3,48,-1,OBSIDIAN:0)
Block(-3,49,-7,STONE:3)
Block(-3,49,-6,STONE:3)
Block(-3,49,-5,STONE:3)
Block(-3,49,-4,OBSIDIAN:0)
Block(-3,49,-3,OBSIDIAN:0)
Block(-3,49,-2,OBSIDIAN:0)
Block(-3,49,-1,OBSIDIAN:0)
Block(-3,50,-7,OBSIDIAN:0)
Block(-3,50,-6,STONE:3)
Block(-3,50,-5,STONE:3)
Block(-3,50,-4,OBSIDIAN:0)
Block(-3,50,-3,OBSIDIAN:0)
Block(-3,50,-2,OBSIDIAN:0)
Block(-3,50,-1,OBSIDIAN:0)
Block(-3,51,-7,OBSIDIAN:0)
Block(-3,51,-6,OBSIDIAN:0)
Block(-3,51,-5,STONE:3)
Block(-3,51,-4,OBSIDIAN:0)
Block(-3,51,-3,OBSIDIAN:0)
Block(-3,51,-2,OBSIDIAN:0)
Block(-3,51,-1,OBSIDIAN:0)
Block(-3,52,-7,OBSIDIAN:0)
Block(-3,52,-6,OBSIDIAN:0)
Block(-3,52,-5,OBSIDIAN:0)
Block(-3,52,-4,OBSIDIAN:0)
Block(-3,52,-3,OBSIDIAN:0)
Block(-3,52,-2,OBSIDIAN:0)
Block(-3,53,-7,OBSIDIAN:0)
Block(-3,53,-6,OBSIDIAN:0)
Block(-3,53,-5,OBSIDIAN:0)
Block(-3,53,-4,OBSIDIAN:0)
Block(-3,53,-3,OBSIDIAN:0)
Block(-3,54,-7,OBSIDIAN:0)
Block(-3,54,-6,OBSIDIAN:0)
Block(-3,54,-5,OBSIDIAN:0)
Block(-3,54,-4,OBSIDIAN:0)
Block(-3,54,-3,OBSIDIAN:0)
Block(-3,55,-7,OBSIDIAN:0)
Block(-3,55,-6,OBSIDIAN:0)
Block(-3,55,-5,OBSIDIAN:0)
Block(-3,55,-4,OBSIDIAN:0)
Block(-3,55,-3,OBSIDIAN:0)
Block(-3,56,-7,OBSIDIAN:0)
Block(-3,56,-6,OBSIDIAN:0)
Block(-3,56,-5,OBSIDIAN:0)
Block(-3,56,-4,OBSIDIAN:0)
Block(-3,56,-3,OBSIDIAN:0)
Block(-3,57,-7,OBSIDIAN:0)
Block(-3,57,-6,OBSIDIAN:0)
Block(-3,57,-5,OBSIDIAN:0)
Block(-3,57,-4,OBSIDIAN:0)
Block(-3,57,-3,OBSIDIAN:0)
Block(-3,58,-7,OBSIDIAN:0)
Block(-3,58,-6,OBSIDIAN:0)
Block(-3,58,-5,OBSIDIAN:0)
Block(-3,58,-4,OBSIDIAN:0)
Block(-3,58,-3,OBSIDIAN:0)
Block(-3,58,-2,OBSIDIAN:0)
Block(-3,59,-7,OBSIDIAN:0)
Block(-3,59,-6,STONE:3)
Block(-3,59,-5,OBSIDIAN:0)
Block(-3,59,-4,OBSIDIAN:0)
Block(-3,59,-3,OBSIDIAN:0)
Block(-3,59,-2,OBSIDIAN:0)
Block(-3,60,-7,STONE:3)
Block(-3,60,-6,STONE:3)
Block(-3,60,-5,OBSIDIAN:0)
Block(-3,60,-4,OBSIDIAN:0)
Block(-3,60,-3,OBSIDIAN:0)
Block(-3,60,-2,OBSIDIAN:0)
Block(-3,61,-7,STONE:3)
Block(-3,61,-6,STONE:3)
Block(-3,61,-5,OBSIDIAN:0)
Block(-3,61,-4,STONE:3)
Block(-3,61,-3,STONE:3)
Block(-3,61,-2,STONE:3)
Block(-3,62,-7,STONE:3)
Block(-3,62,-6,OBSIDIAN:0)
Block(-3,62,-5,STONE:3)
Block(-3,62,-4,STONE:3)
Block(-3,62,-3,STONE:3)
Block(-3,62,-2,STONE:3)
Block(-3,63,-7,STONE:3)
Block(-3,63,-6,OBSIDIAN:0)
Block(-3,63,-5,STONE:3)
Block(-3,63,-4,STONE:3)
Block(-3,63,-3,STONE:3)
Block(-3,64,-7,STONE:3)
Block(-3,64,-6,OBSIDIAN:0)
Block(-3,64,-5,STONE:3)
Block(-3,64,-4,STONE:3)
Block(-3,64,-3,STONE:3)
Block(-3,64,-2,STONE:3)
Block(-3,65,-7,STONE:3)
Block(-3,65,-6,OBSIDIAN:0)
Block(-3,65,-5,OBSIDIAN:0)
Block(-3,65,-4,STONE:3)
Block(-3,65,-3,STONE:3)
Block(-3,65,-2,STONE:3)
Block(-3,66,-7,STONE:3)
Block(-3,66,-6,OBSIDIAN:0)
Block(-3,66,-5,OBSIDIAN:0)
Block(-3,66,-4,OBSIDIAN:0)
Block(-3,66,-3,OBSIDIAN:0)
Block(-3,67,-7,STONE:3)
Block(-3,67,-6,OBSIDIAN:0)
Block(-3,67,-5,OBSIDIAN:0)
Block(-3,67,-4,OBSIDIAN:0)
Block(-3,67,-3,OBSIDIAN:0)
Block(-3,68,-7,STONE:3)
Block(-3,68,-6,OBSIDIAN:0)
Block(-3,68,-5,OBSIDIAN:0)
Block(-3,68,-4,OBSIDIAN:0)
Block(-3,68,-3,OBSIDIAN:0)
Block(-3,69,-7,STONE:3)
Block(-3,69,-6,OBSIDIAN:0)
Block(-3,69,-5,OBSIDIAN:0)
Block(-3,69,-4,OBSIDIAN:0)
Block(-3,69,-3,OBSIDIAN:0)
Block(-3,70,-7,STONE:3)
Block(-3,70,-6,OBSIDIAN:0)
Block(-3,70,-5,OBSIDIAN:0)
Block(-3,70,-4,OBSIDIAN:0)
Block(-3,70,-3,OBSIDIAN:0)
Block(-3,71,-7,STONE:3)
Block(-3,71,-6,STONE:3)
Block(-3,71,-5,OBSIDIAN:0)
Block(-3,71,-4,OBSIDIAN:0)
Block(-3,71,-3,OBSIDIAN:0)
Block(-3,72,-7,STONE:5)
Block(-3,72,-6,STONE:3)
Block(-3,72,-5,STONE:3)
Block(-3,72,-4,OBSIDIAN:0)
Block(-3,72,-3,OBSIDIAN:0)
Block(-3,73,-6,STONE:5)
Block(-3,73,-5,STONE:3)
Block(-3,73,-4,OBSIDIAN:0)
Block(-3,73,-3,OBSIDIAN:0)
Block(-3,74,-5,STONE:3)
Block(-3,74,-4,STONE:3)
Block(-3,74,-3,OBSIDIAN:0)
Block(-3,74,-2,OBSIDIAN:0)
Block(-3,75,-5,STONE:5)
Block(-3,75,-4,STONE:3)
Block(-3,75,-3,OBSIDIAN:0)
Block(-3,75,-2,OBSIDIAN:0)
Block(-3,75,-1,OBSIDIAN:0)
Block(-3,75,0,OBSIDIAN:0)
Block(-3,75,1,OBSIDIAN:0)
Block(-3,76,-4,STONE:3)
Block(-3,76,-3,OBSIDIAN:0)
Block(-3,76,-2,OBSIDIAN:0)
Block(-3,76,-1,OBSIDIAN:0)
Block(-3,76,0,OBSIDIAN:0)
Block(-3,76,1,OBSIDIAN:0)
Block(-3,76,2,OBSIDIAN:0)
Block(-3,77,-4,STONE:5)
Block(-3,77,-3,STONE:3)
Block(-3,77,-2,STONE:3)
Block(-3,77,-1,OBSIDIAN:0)
Block(-3,77,0,OBSIDIAN:0)
Block(-3,77,1,OBSIDIAN:0)
Block(-3,77,2,OBSIDIAN:0)
Block(-3,78,-3,STONE:3)
Block(-3,78,-2,STONE:3)
Block(-3,78,-1,OBSIDIAN:0)
Block(-3,78,0,OBSIDIAN:0)
Block(-3,78,1,OBSIDIAN:0)
Block(-3,78,2,OBSIDIAN:0)
Block(-3,78,3,OBSIDIAN:0)
Block(-3,79,-3,STONE:3)
Block(-3,79,-2,STONE:3)
Block(-3,79,-1,OBSIDIAN:0)
Block(-3,79,0,OBSIDIAN:0)
Block(-3,79,1,OBSIDIAN:0)
Block(-3,79,2,OBSIDIAN:0)
Block(-3,79,3,OBSIDIAN:0)
Block(-3,79,4,OBSIDIAN:0)
Block(-3,79,5,OBSIDIAN:0)
Block(-3,80,-3,STONE:3)
Block(-3,80,-2,STONE:3)
Block(-3,80,-1,OBSIDIAN:0)
Block(-3,80,0,OBSIDIAN:0)
Block(-3,80,1,OBSIDIAN:0)
Block(-3,80,2,OBSIDIAN:0)
Block(-3,80,3,OBSIDIAN:0)
Block(-3,80,4,OBSIDIAN:0)
Block(-3,80,5,OBSIDIAN:0)
Block(-3,81,-3,STONE:3)
Block(-3,81,-2,STONE:3)
Block(-3,81,-1,OBSIDIAN:0)
Block(-3,81,0,OBSIDIAN:0)
Block(-3,81,1,OBSIDIAN:0)
Block(-3,81,2,OBSIDIAN:0)
Block(-3,81,3,OBSIDIAN:0)
Block(-3,81,4,OBSIDIAN:0)
Block(-3,81,5,OBSIDIAN:0)
Block(-3,82,-3,STONE:5)
Block(-3,82,-2,STONE:3)
Block(-3,82,-1,STONE:3)
Block(-3,82,0,STONE:3)
Block(-3,82,1,OBSIDIAN:0)
Block(-3,82,2,OBSIDIAN:0)
Block(-3,82,3,OBSIDIAN:0)
Block(-3,82,4,OBSIDIAN:0)
Block(-3,82,5,OBSIDIAN:0)
Block(-3,82,6,OBSIDIAN:0)
Block(-3,83,-2,STONE:3)
Block(-3,83,-1,STONE:3)
Block(-3,83,0,STONE:3)
Block(-3,83,1,STONE:3)
Block(-3,83,2,STONE:3)
Block(-3,83,3,OBSIDIAN:0)
Block(-3,83,4,OBSIDIAN:0)
Block(-3,83,5,OBSIDIAN:0)
Block(-3,83,6,OBSIDIAN:0)
Block(-3,84,-2,STONE:3)
Block(-3,84,-1,STONE:3)
Block(-3,84,0,STONE:3)
Block(-3,84,1,STONE:3)
Block(-3,84,2,STONE:3)
Block(-3,84,3,OBSIDIAN:0)
Block(-3,84,4,OBSIDIAN:0)
Block(-3,84,5,OBSIDIAN:0)
Block(-3,84,6,OBSIDIAN:0)
Block(-3,84,7,OBSIDIAN:0)
Block(-3,85,-2,STONE:3)
Block(-3,85,-1,STONE:3)
Block(-3,85,0,STONE:3)
Block(-3,85,1,STONE:3)
Block(-3,85,2,STONE:3)
Block(-3,85,3,OBSIDIAN:0)
Block(-3,85,4,OBSIDIAN:0)
Block(-3,85,5,OBSIDIAN:0)
Block(-3,85,6,OBSIDIAN:0)
Block(-3,85,7,OBSIDIAN:0)
Block(-3,85,8,OBSIDIAN:0)
Block(-3,86,-2,STONE:5)
Block(-3,86,-1,STONE:3)
Block(-3,86,0,STONE:3)
Block(-3,86,1,STONE:3)
Block(-3,86,2,STONE:3)
Block(-3,86,3,STONE:3)
Block(-3,86,4,OBSIDIAN:0)
Block(-3,86,5,OBSIDIAN:0)
Block(-3,86,6,OBSIDIAN:0)
Block(-3,86,7,OBSIDIAN:0)
Block(-3,86,8,OBSIDIAN:0)
Block(-3,87,-1,STONE:3)
Block(-3,87,0,STONE:3)
Block(-3,87,1,STONE:3)
Block(-3,87,2,STONE:3)
Block(-3,87,3,STONE:3)
Block(-3,87,4,STONE:3)
Block(-3,87,5,OBSIDIAN:0)
Block(-3,87,6,OBSIDIAN:0)
Block(-3,87,7,OBSIDIAN:0)
Block(-3,87,8,STONE:3)
Block(-3,88,-1,STONE:5)
Block(-3,88,0,STONE:5)
Block(-3,88,1,STONE:3)
Block(-3,88,2,STONE:3)
Block(-3,88,3,STONE:3)
Block(-3,88,4,STONE:3)
Block(-3,88,5,STONE:3)
Block(-3,88,6,STONE:3)
Block(-3,88,7,STONE:3)
Block(-3,88,8,STONE:3)
Block(-3,89,1,STONE:3)
Block(-3,89,2,STONE:3)
Block(-3,89,3,STONE:3)
Block(-3,89,4,STONE:3)
Block(-3,89,5,STONE:3)
Block(-3,89,6,STONE:3)
Block(-3,89,7,STONE:3)
Block(-3,89,8,STONE:3)
Block(-3,90,4,STONE:3)
Block(-3,90,5,STONE:3)
Block(-3,90,6,STONE:3)
Block(-3,90,7,STONE:3)
Block(-3,90,8,STONE:3)
Block(-3,91,5,STONE:3)
Block(-3,91,6,STONE:3)
Block(-3,91,7,STONE:3)
Block(-3,91,8,STONE:3)
Block(-3,92,6,STONE:3)
Block(-3,92,7,STONE:3)
Block(-3,92,8,STONE:3)
Block(-3,93,7,STONE:3)
Block(-3,93,8,STONE:3)
Block(-3,94,8,STONE:3)
Block(-2,22,8,STONE:3)
Block(-2,23,6,STONE:3)
Block(-2,23,7,STONE:3)
Block(-2,23,8,STONE:3)
Block(-2,24,5,STONE:3)
Block(-2,24,6,STONE:3)
Block(-2,24,7,STONE:3)
Block(-2,24,8,STONE:3)
Block(-2,25,4,STONE:3)
Block(-2,25,5,STONE:3)
Block(-2,25,6,STONE:3)
Block(-2,25,7,STONE:3)
Block(-2,25,8,STONE:3)
Block(-2,26,4,STONE:3)
Block(-2,26,5,STONE:3)
Block(-2,26,6,STONE:3)
Block(-2,26,7,STONE:3)
Block(-2,26,8,STONE:3)
Block(-2,27,0,STONE:3)
Block(-2,27,1,STONE:3)
Block(-2,27,2,STONE:3)
Block(-2,27,3,STONE:3)
Block(-2,27,4,STONE:3)
Block(-2,27,5,STONE:3)
Block(-2,27,6,STONE:3)
Block(-2,27,7,STONE:3)
Block(-2,27,8,STONE:3)
Block(-2,28,-1,STONE:3)
Block(-2,28,0,STONE:3)
Block(-2,28,1,STONE:3)
Block(-2,28,2,STONE:3)
Block(-2,28,3,STONE:3)
Block(-2,28,4,STONE:3)
Block(-2,28,5,STONE:3)
Block(-2,28,6,STONE:3)
Block(-2,28,7,STONE:3)
Block(-2,28,8,STONE:3)
Block(-2,29,-2,STONE:3)
Block(-2,29,-1,STONE:3)
Block(-2,29,0,STONE:3)
Block(-2,29,1,STONE:3)
Block(-2,29,2,STONE:3)
Block(-2,29,3,STONE:3)
Block(-2,29,4,STONE:3)
Block(-2,29,5,STONE:3)
Block(-2,29,6,STONE:3)
Block(-2,29,7,STONE:3)
Block(-2,29,8,STONE:3)
Block(-2,30,-3,STONE:3)
Block(-2,30,-2,STONE:3)
Block(-2,30,-1,STONE:3)
Block(-2,30,0,STONE:3)
Block(-2,30,1,STONE:3)
Block(-2,30,2,STONE:3)
Block(-2,30,3,STONE:3)
Block(-2,30,4,STONE:3)
Block(-2,30,5,STONE:3)
Block(-2,30,6,STONE:3)
Block(-2,30,7,STONE:3)
Block(-2,30,8,STONE:3)
Block(-2,31,-3,STONE:3)
Block(-2,31,-2,STONE:3)
Block(-2,31,-1,STONE:3)
Block(-2,31,0,STONE:3)
Block(-2,31,1,STONE:3)
Block(-2,31,2,STONE:3)
Block(-2,31,3,STONE:3)
Block(-2,31,4,STONE:3)
Block(-2,31,5,STONE:3)
Block(-2,31,6,STONE:3)
Block(-2,31,7,OBSIDIAN:0)
Block(-2,31,8,OBSIDIAN:0)
Block(-2,32,-3,STONE:3)
Block(-2,32,-2,STONE:3)
Block(-2,32,-1,STONE:3)
Block(-2,32,0,STONE:3)
Block(-2,32,1,STONE:3)
Block(-2,32,2,STONE:3)
Block(-2,32,3,STONE:3)
Block(-2,32,4,OBSIDIAN:0)
Block(-2,32,5,OBSIDIAN:0)
Block(-2,32,6,OBSIDIAN:0)
Block(-2,32,7,OBSIDIAN:0)
Block(-2,32,8,OBSIDIAN:0)
Block(-2,33,-3,STONE:3)
Block(-2,33,-2,STONE:3)
Block(-2,33,-1,STONE:3)
Block(-2,33,0,STONE:3)
Block(-2,33,1,STONE:3)
Block(-2,33,2,STONE:3)
Block(-2,33,3,STONE:3)
Block(-2,33,4,OBSIDIAN:0)
Block(-2,33,5,OBSIDIAN:0)
Block(-2,33,6,OBSIDIAN:0)
Block(-2,33,7,OBSIDIAN:0)
Block(-2,33,8,OBSIDIAN:0)
Block(-2,34,-6,STONE:3)
Block(-2,34,-5,STONE:3)
Block(-2,34,-4,STONE:3)
Block(-2,34,-3,STONE:3)
Block(-2,34,-2,STONE:3)
Block(-2,34,-1,STONE:3)
Block(-2,34,0,STONE:3)
Block(-2,34,1,STONE:3)
Block(-2,34,2,STONE:3)
Block(-2,34,3,STONE:3)
Block(-2,34,4,OBSIDIAN:0)
Block(-2,34,5,OBSIDIAN:0)
Block(-2,34,6,OBSIDIAN:0)
Block(-2,34,7,OBSIDIAN:0)
Block(-2,34,8,OBSIDIAN:0)
Block(-2,35,-7,STONE:3)
Block(-2,35,-6,STONE:3)
Block(-2,35,-5,STONE:3)
Block(-2,35,-4,STONE:3)
Block(-2,35,-3,STONE:3)
Block(-2,35,-2,STONE:3)
Block(-2,35,-1,STONE:3)
Block(-2,35,0,STONE:3)
Block(-2,35,1,STONE:3)
Block(-2,35,2,STONE:3)
Block(-2,35,3,OBSIDIAN:0)
Block(-2,35,4,OBSIDIAN:0)
Block(-2,35,5,OBSIDIAN:0)
Block(-2,35,6,OBSIDIAN:0)
Block(-2,35,7,OBSIDIAN:0)
Block(-2,35,8,OBSIDIAN:0)
Block(-2,36,-7,STONE:3)
Block(-2,36,-6,STONE:3)
Block(-2,36,-5,STONE:3)
Block(-2,36,-4,STONE:3)
Block(-2,36,-3,STONE:3)
Block(-2,36,-2,STONE:3)
Block(-2,36,-1,STONE:3)
Block(-2,36,0,STONE:3)
Block(-2,36,1,STONE:3)
Block(-2,36,2,OBSIDIAN:0)
Block(-2,36,3,OBSIDIAN:0)
Block(-2,36,4,OBSIDIAN:0)
Block(-2,36,5,OBSIDIAN:0)
Block(-2,36,6,OBSIDIAN:0)
Block(-2,36,7,OBSIDIAN:0)
Block(-2,36,8,OBSIDIAN:0)
Block(-2,37,-7,STONE:3)
Block(-2,37,-6,STONE:3)
Block(-2,37,-5,STONE:3)
Block(-2,37,-4,STONE:3)
Block(-2,37,-3,STONE:3)
Block(-2,37,-2,STONE:3)
Block(-2,37,-1,STONE:3)
Block(-2,37,0,STONE:3)
Block(-2,37,1,OBSIDIAN:0)
Block(-2,37,2,OBSIDIAN:0)
Block(-2,37,3,OBSIDIAN:0)
Block(-2,37,4,OBSIDIAN:0)
Block(-2,37,5,OBSIDIAN:0)
Block(-2,37,6,OBSIDIAN:0)
Block(-2,37,7,OBSIDIAN:0)
Block(-2,37,8,OBSIDIAN:0)
Block(-2,38,-6,STONE:3)
Block(-2,38,-5,STONE:3)
Block(-2,38,-4,STONE:3)
Block(-2,38,-3,STONE:3)
Block(-2,38,-2,STONE:3)
Block(-2,38,-1,STONE:3)
Block(-2,38,0,OBSIDIAN:0)
Block(-2,38,1,OBSIDIAN:0)
Block(-2,38,2,OBSIDIAN:0)
Block(-2,38,3,OBSIDIAN:0)
Block(-2,38,4,OBSIDIAN:0)
Block(-2,38,5,STONE:3)
Block(-2,38,6,STONE:3)
Block(-2,38,7,STONE:3)
Block(-2,38,8,OBSIDIAN:0)
Block(-2,39,-6,STONE:3)
Block(-2,39,-5,STONE:3)
Block(-2,39,-4,STONE:3)
Block(-2,39,-3,STONE:3)
Block(-2,39,-2,STONE:3)
Block(-2,39,-1,STONE:3)
Block(-2,39,0,OBSIDIAN:0)
Block(-2,39,1,OBSIDIAN:0)
Block(-2,39,2,OBSIDIAN:0)
Block(-2,39,3,OBSIDIAN:0)
Block(-2,39,4,OBSIDIAN:0)
Block(-2,39,5,STONE:3)
Block(-2,39,6,STONE:3)
Block(-2,39,7,STONE:3)
Block(-2,39,8,STONE:3)
Block(-2,40,-6,STONE:3)
Block(-2,40,-5,STONE:3)
Block(-2,40,-4,STONE:3)
Block(-2,40,-3,STONE:3)
Block(-2,40,-2,STONE:3)
Block(-2,40,-1,STONE:3)
Block(-2,40,0,OBSIDIAN:0)
Block(-2,40,1,OBSIDIAN:0)
Block(-2,40,2,OBSIDIAN:0)
Block(-2,40,3,OBSIDIAN:0)
Block(-2,40,4,STONE:3)
Block(-2,40,5,STONE:3)
Block(-2,40,6,STONE:3)
Block(-2,40,7,STONE:3)
Block(-2,40,8,STONE:3)
Block(-2,41,-6,STONE:3)
Block(-2,41,-5,STONE:3)
Block(-2,41,-4,STONE:3)
Block(-2,41,-3,STONE:3)
Block(-2,41,-2,STONE:3)
Block(-2,41,-1,STONE:3)
Block(-2,41,0,OBSIDIAN:0)
Block(-2,41,1,OBSIDIAN:0)
Block(-2,41,2,OBSIDIAN:0)
Block(-2,41,3,OBSIDIAN:0)
Block(-2,41,4,STONE:3)
Block(-2,41,5,OBSIDIAN:0)
Block(-2,41,6,STONE:3)
Block(-2,41,7,STONE:3)
Block(-2,41,8,STONE:3)
Block(-2,42,-6,STONE:3)
Block(-2,42,-5,STONE:3)
Block(-2,42,-4,STONE:3)
Block(-2,42,-3,STONE:3)
Block(-2,42,-2,STONE:3)
Block(-2,42,-1,STONE:3)
Block(-2,42,0,OBSIDIAN:0)
Block(-2,42,1,OBSIDIAN:0)
Block(-2,42,2,OBSIDIAN:0)
Block(-2,42,3,OBSIDIAN:0)
Block(-2,42,4,STONE:3)
Block(-2,42,5,STONE:3)
Block(-2,42,6,STONE:3)
Block(-2,42,7,STONE:3)
Block(-2,43,-6,STONE:3)
Block(-2,43,-5,STONE:3)
Block(-2,43,-4,STONE:3)
Block(-2,43,-3,STONE:3)
Block(-2,43,-2,STONE:3)
Block(-2,43,-1,OBSIDIAN:0)
Block(-2,43,0,OBSIDIAN:0)
Block(-2,43,1,OBSIDIAN:0)
Block(-2,43,2,OBSIDIAN:0)
Block(-2,43,3,OBSIDIAN:0)
Block(-2,43,4,STONE:3)
Block(-2,43,5,STONE:3)
Block(-2,43,6,STONE:3)
Block(-2,43,7,STONE:3)
Block(-2,44,-7,STONE:3)
Block(-2,44,-6,STONE:3)
Block(-2,44,-5,STONE:3)
Block(-2,44,-4,STONE:3)
Block(-2,44,-3,STONE:3)
Block(-2,44,-2,OBSIDIAN:0)
Block(-2,44,-1,OBSIDIAN:0)
Block(-2,44,0,OBSIDIAN:0)
Block(-2,44,1,OBSIDIAN:0)
Block(-2,44,2,OBSIDIAN:0)
Block(-2,44,3,OBSIDIAN:0)
Block(-2,44,4,OBSIDIAN:0)
Block(-2,44,5,STONE:3)
Block(-2,44,6,STONE:3)
Block(-2,45,-7,STONE:3)
Block(-2,45,-6,STONE:3)
Block(-2,45,-5,STONE:3)
Block(-2,45,-4,STONE:3)
Block(-2,45,-3,STONE:3)
Block(-2,45,-2,OBSIDIAN:0)
Block(-2,45,-1,OBSIDIAN:0)
Block(-2,45,0,OBSIDIAN:0)
Block(-2,45,1,OBSIDIAN:0)
Block(-2,45,2,OBSIDIAN:0)
Block(-2,45,3,OBSIDIAN:0)
Block(-2,45,4,OBSIDIAN:0)
