
#######################################################################
# +-----------------------------------------------------------------+ #
# |                            BO4 object                           | #
# +-----------------------------------------------------------------+ #
#######################################################################

Author: NLBlackEagle

Description: No description given

SettingsMode: WriteWithoutComments


#######################################################################
# +-----------------------------------------------------------------+ #
# |                          Main settings                          | #
# +-----------------------------------------------------------------+ #
#######################################################################

Frequency: 0

SpawnHeight: highestBlock

UseCenterForHighestBlock: true

##############################
# Height Limits for the BO4. #
##############################

MinHeight: 0

MaxHeight: 255

InheritBO3: 

InheritBO3Rotation: NORTH

OverrideChildSettings: true

OverrideParentHeight: false

CanOverride: false

BranchFrequency: 0

BranchFrequencyGroup: 

MustBeBelowOther: false

MustBeInside: 

CannotBeInside: 

ReplacesBO3: 

MustBeInsideWorldBorders: false

CanSpawnOnWater: true

SpawnOnWaterOnly: false

SpawnUnderWater: false

SpawnAtWaterLevel: false

HeightOffset: 0

RemoveAir: true

ReplaceAbove: 

ReplaceBelow: 

ReplaceWithBiomeBlocks: true

ReplaceWithSurfaceBlock: GRASS

ReplaceWithGroundBlock: DIRT

ReplaceWithStoneBlock: STONE

SmoothRadius: 0

SmoothHeightOffset: 0

SmoothStartTop: false

SmoothStartWood: false

SmoothingSurfaceBlock: 

SmoothingGroundBlock: 

BO3Group: 

IsSpawnPoint: false

DoReplaceBlocks: true


#######################################################################
# +-----------------------------------------------------------------+ #
# |                              Blocks                             | #
# +-----------------------------------------------------------------+ #
#######################################################################

Block(-2,34,-7,STONE:3)
Block(-1,33,-7,STONE:3)
Block(-1,34,-7,STONE:3)
Block(-1,35,-7,STONE:3)
Block(-1,36,-7,STONE:3)
Block(0,32,-7,STONE:3)
Block(0,33,-7,STONE:3)
Block(0,34,-7,STONE:3)
Block(0,35,-7,STONE:3)
Block(0,36,-7,STONE:3)
Block(0,36,-6,STONE:3)
Block(0,37,-7,STONE:3)
Block(0,37,-6,STONE:3)
Block(0,38,-7,STONE:3)
Block(1,31,-7,STONE:3)
Block(1,32,-7,STONE:3)
Block(1,32,-6,STONE:3)
Block(1,33,-7,STONE:3)
Block(1,33,-6,STONE:3)
Block(1,34,-7,STONE:3)
Block(1,35,-7,STONE:3)
Block(1,35,-6,STONE:3)
Block(1,36,-7,STONE:3)
Block(1,36,-6,STONE:3)
Block(1,37,-7,STONE:3)
Block(1,37,-6,STONE:3)
Block(1,37,-5,STONE:3)
Block(1,38,-7,STONE:3)
Block(1,39,-7,STONE:3)
Block(1,40,-7,STONE:5)
Block(2,29,-7,STONE:3)
Block(2,30,-7,STONE:3)
Block(2,30,-6,STONE:3)
Block(2,31,-7,STONE:3)
Block(2,31,-6,STONE:3)
Block(2,31,-5,STONE:3)
Block(2,32,-7,STONE:3)
Block(2,32,-6,STONE:3)
Block(2,32,-5,STONE:3)
Block(2,33,-7,STONE:3)
Block(2,33,-6,STONE:3)
Block(2,33,-5,STONE:3)
Block(2,34,-7,STONE:3)
Block(2,34,-6,STONE:3)
Block(2,35,-7,STONE:3)
Block(2,35,-6,STONE:3)
Block(2,36,-7,STONE:3)
Block(2,36,-6,STONE:3)
Block(2,36,-5,STONE:3)
Block(2,37,-7,STONE:3)
Block(2,37,-6,STONE:3)
Block(2,37,-5,STONE:3)
Block(2,38,-7,STONE:3)
Block(2,38,-6,STONE:3)
Block(2,39,-7,STONE:3)
Block(2,39,-6,STONE:3)
Block(2,39,-5,STONE:5)
Block(2,40,-7,STONE:3)
Block(2,40,-6,STONE:5)
Block(2,41,-7,STONE:5)
Block(3,28,-7,STONE:3)
Block(3,29,-7,STONE:3)
Block(3,29,-6,STONE:3)
Block(3,30,-7,STONE:3)
Block(3,30,-6,STONE:3)
Block(3,30,-5,STONE:3)
Block(3,31,-7,STONE:3)
Block(3,31,-6,STONE:3)
Block(3,31,-5,STONE:3)
Block(3,31,-4,STONE:3)
Block(3,32,-7,STONE:3)
Block(3,32,-6,STONE:3)
Block(3,32,-5,STONE:3)
Block(3,32,-4,STONE:5)
Block(3,33,-7,STONE:3)
Block(3,33,-6,STONE:3)
Block(3,33,-5,STONE:3)
Block(3,34,-7,STONE:3)
Block(3,34,-6,STONE:3)
Block(3,34,-5,STONE:3)
Block(3,35,-7,STONE:3)
Block(3,35,-6,STONE:3)
Block(3,35,-5,STONE:3)
Block(3,36,-7,STONE:3)
Block(3,36,-6,STONE:3)
Block(3,36,-5,STONE:3)
Block(3,37,-7,STONE:3)
Block(3,37,-6,STONE:3)
Block(3,37,-5,STONE:3)
Block(3,38,-7,STONE:3)
Block(3,38,-6,STONE:3)
Block(3,38,-5,STONE:3)
Block(3,39,-7,STONE:3)
Block(3,39,-6,STONE:3)
Block(3,39,-5,STONE:3)
Block(3,40,-7,STONE:3)
Block(3,40,-6,STONE:3)
Block(3,40,-5,STONE:3)
Block(3,41,-7,STONE:5)
Block(3,41,-6,STONE:5)
Block(3,41,-5,STONE:5)
Block(4,25,-7,STONE:3)
Block(4,26,-7,STONE:3)
Block(4,26,-6,STONE:3)
Block(4,26,-5,STONE:3)
Block(4,27,-7,STONE:3)
Block(4,27,-6,STONE:3)
Block(4,27,-5,STONE:3)
Block(4,27,-4,STONE:3)
Block(4,28,-7,STONE:3)
Block(4,28,-6,STONE:3)
Block(4,28,-5,STONE:3)
Block(4,28,-4,STONE:3)
Block(4,29,-7,STONE:3)
Block(4,29,-6,STONE:3)
Block(4,29,-5,STONE:3)
Block(4,29,-4,STONE:3)
Block(4,30,-7,STONE:3)
Block(4,30,-6,STONE:3)
Block(4,30,-5,STONE:3)
Block(4,30,-4,STONE:3)
Block(4,30,-3,STONE:3)
Block(4,31,-7,STONE:3)
Block(4,31,-6,STONE:3)
Block(4,31,-5,STONE:3)
Block(4,31,-4,STONE:3)
Block(4,31,-3,STONE:3)
Block(4,32,-7,STONE:3)
Block(4,32,-6,STONE:3)
Block(4,32,-5,STONE:3)
Block(4,32,-4,STONE:3)
Block(4,32,-3,STONE:5)
Block(4,33,-7,STONE:3)
Block(4,33,-6,STONE:3)
Block(4,33,-5,STONE:3)
Block(4,33,-4,STONE:3)
Block(4,34,-7,STONE:3)
Block(4,34,-6,STONE:3)
Block(4,34,-5,STONE:3)
Block(4,35,-7,STONE:3)
Block(4,35,-6,STONE:3)
Block(4,35,-5,STONE:3)
Block(4,36,-7,STONE:3)
Block(4,36,-6,STONE:3)
Block(4,36,-5,STONE:3)
Block(4,36,-4,STONE:3)
Block(4,37,-7,STONE:3)
Block(4,37,-6,STONE:3)
Block(4,37,-5,STONE:3)
Block(4,37,-4,STONE:3)
Block(4,38,-7,STONE:3)
Block(4,38,-6,STONE:3)
Block(4,38,-5,STONE:3)
Block(4,38,-4,STONE:3)
Block(4,39,-7,STONE:3)
Block(4,39,-6,STONE:3)
Block(4,39,-5,STONE:3)
Block(4,39,-4,STONE:3)
Block(4,40,-7,STONE:3)
Block(4,40,-6,STONE:3)
Block(4,40,-5,STONE:3)
Block(4,40,-4,STONE:5)
Block(4,41,-7,STONE:3)
Block(4,41,-6,STONE:5)
Block(4,41,-5,STONE:5)
Block(4,42,-7,STONE:5)
Block(5,25,-7,STONE:3)
Block(5,25,-6,STONE:3)
Block(5,26,-7,STONE:3)
Block(5,26,-6,STONE:3)
Block(5,26,-5,STONE:3)
Block(5,26,-4,STONE:3)
Block(5,27,-7,STONE:3)
Block(5,27,-6,STONE:3)
Block(5,27,-5,STONE:3)
Block(5,27,-4,STONE:3)
Block(5,28,-7,STONE:3)
Block(5,28,-6,STONE:3)
Block(5,28,-5,STONE:3)
Block(5,28,-4,STONE:3)
Block(5,29,-7,STONE:3)
Block(5,29,-6,STONE:3)
Block(5,29,-5,STONE:3)
Block(5,29,-4,STONE:3)
Block(5,29,-3,STONE:3)
Block(5,30,-7,STONE:3)
Block(5,30,-6,STONE:3)
Block(5,30,-5,STONE:3)
Block(5,30,-4,STONE:3)
Block(5,30,-3,STONE:3)
Block(5,31,-7,STONE:3)
Block(5,31,-6,STONE:3)
Block(5,31,-5,STONE:3)
Block(5,31,-4,STONE:3)
Block(5,31,-3,STONE:3)
Block(5,32,-7,STONE:3)
Block(5,32,-6,STONE:3)
Block(5,32,-5,STONE:3)
Block(5,32,-4,STONE:3)
Block(5,32,-3,STONE:3)
Block(5,33,-7,STONE:3)
Block(5,33,-6,STONE:3)
Block(5,33,-5,STONE:3)
Block(5,33,-4,STONE:3)
Block(5,33,-3,STONE:3)
Block(5,34,-7,STONE:3)
Block(5,34,-6,STONE:3)
Block(5,34,-5,STONE:3)
Block(5,34,-4,STONE:3)
Block(5,35,-7,STONE:3)
Block(5,35,-6,STONE:3)
Block(5,35,-5,STONE:3)
Block(5,35,-4,STONE:3)
Block(5,36,-7,STONE:3)
Block(5,36,-6,STONE:3)
Block(5,36,-5,STONE:3)
Block(5,36,-4,STONE:3)
Block(5,37,-7,STONE:3)
Block(5,37,-6,STONE:3)
Block(5,37,-5,STONE:3)
Block(5,37,-4,STONE:3)
Block(5,37,-3,STONE:3)
Block(5,38,-7,STONE:3)
Block(5,38,-6,STONE:3)
Block(5,38,-5,STONE:3)
Block(5,38,-4,STONE:3)
Block(5,39,-7,STONE:3)
Block(5,39,-6,STONE:3)
Block(5,39,-5,STONE:3)
Block(5,39,-4,STONE:3)
Block(5,39,-3,STONE:3)
Block(5,40,-7,STONE:3)
Block(5,40,-6,STONE:3)
Block(5,40,-5,STONE:3)
Block(5,40,-4,STONE:3)
Block(5,40,-3,STONE:5)
Block(5,41,-7,STONE:3)
Block(5,41,-6,STONE:3)
Block(5,41,-5,STONE:3)
Block(5,41,-4,STONE:3)
Block(5,42,-7,STONE:3)
Block(5,42,-6,STONE:3)
Block(5,42,-5,STONE:5)
Block(5,42,-4,STONE:5)
Block(5,43,-7,STONE:3)
Block(5,43,-6,STONE:5)
Block(5,46,-7,STONE:5)
Block(6,24,-7,STONE:3)
Block(6,24,-6,STONE:3)
Block(6,25,-7,STONE:3)
Block(6,25,-6,STONE:3)
Block(6,25,-5,STONE:3)
Block(6,25,-4,STONE:3)
Block(6,26,-7,STONE:3)
Block(6,26,-6,STONE:3)
Block(6,26,-5,STONE:3)
Block(6,26,-4,STONE:3)
Block(6,27,-7,STONE:3)
Block(6,27,-6,STONE:3)
Block(6,27,-5,STONE:3)
Block(6,27,-4,STONE:3)
Block(6,27,-3,STONE:3)
Block(6,28,-7,STONE:3)
Block(6,28,-6,STONE:3)
Block(6,28,-5,STONE:3)
Block(6,28,-4,STONE:3)
Block(6,28,-3,STONE:3)
Block(6,29,-7,STONE:3)
Block(6,29,-6,STONE:3)
Block(6,29,-5,STONE:3)
Block(6,29,-4,STONE:3)
Block(6,29,-3,STONE:3)
Block(6,30,-7,STONE:3)
Block(6,30,-6,STONE:3)
Block(6,30,-5,STONE:3)
Block(6,30,-4,STONE:3)
Block(6,30,-3,STONE:3)
Block(6,31,-7,STONE:3)
Block(6,31,-6,STONE:3)
Block(6,31,-5,STONE:3)
Block(6,31,-4,STONE:3)
Block(6,31,-3,STONE:3)
Block(6,32,-7,STONE:3)
Block(6,32,-6,STONE:3)
Block(6,32,-5,STONE:3)
Block(6,32,-4,STONE:3)
Block(6,32,-3,STONE:3)
Block(6,33,-7,STONE:3)
Block(6,33,-6,STONE:3)
Block(6,33,-5,STONE:3)
Block(6,33,-4,STONE:3)
Block(6,33,-3,STONE:3)
Block(6,34,-7,STONE:3)
Block(6,34,-6,STONE:3)
Block(6,34,-5,STONE:3)
Block(6,34,-4,STONE:3)
Block(6,34,-3,STONE:3)
Block(6,35,-7,STONE:3)
Block(6,35,-6,STONE:3)
Block(6,35,-5,STONE:3)
Block(6,35,-4,STONE:3)
Block(6,36,-7,STONE:3)
Block(6,36,-6,STONE:3)
Block(6,36,-5,STONE:3)
Block(6,36,-4,STONE:3)
Block(6,36,-3,STONE:3)
Block(6,37,-7,STONE:3)
Block(6,37,-6,STONE:3)
Block(6,37,-5,STONE:3)
Block(6,37,-4,STONE:3)
Block(6,37,-3,STONE:3)
Block(6,38,-7,STONE:3)
Block(6,38,-6,STONE:3)
Block(6,38,-5,STONE:3)
Block(6,38,-4,STONE:3)
Block(6,38,-3,STONE:3)
Block(6,39,-7,STONE:3)
Block(6,39,-6,STONE:3)
Block(6,39,-5,STONE:3)
Block(6,39,-4,STONE:3)
Block(6,39,-3,STONE:3)
Block(6,40,-7,STONE:3)
Block(6,40,-6,STONE:3)
Block(6,40,-5,STONE:3)
Block(6,40,-4,STONE:3)
Block(6,40,-3,STONE:3)
Block(6,41,-7,STONE:3)
Block(6,41,-6,STONE:3)
Block(6,41,-5,STONE:3)
Block(6,41,-4,STONE:3)
Block(6,41,-3,STONE:3)
Block(6,42,-7,STONE:3)
Block(6,42,-6,STONE:3)
Block(6,42,-5,STONE:3)
Block(6,42,-4,STONE:3)
Block(6,42,-3,STONE:5)
Block(6,43,-7,STONE:3)
Block(6,43,-6,STONE:3)
Block(6,43,-5,STONE:5)
Block(6,43,-4,STONE:5)
Block(6,44,-7,STONE:3)
Block(6,44,-6,STONE:3)
Block(6,45,-7,STONE:3)
Block(6,46,-7,STONE:3)
Block(6,46,-6,STONE:5)
Block(6,47,-7,STONE:3)
Block(6,48,-7,STONE:5)
Block(7,22,-7,STONE:3)
Block(7,23,-7,STONE:3)
Block(7,23,-6,STONE:3)
Block(7,24,-7,STONE:3)
Block(7,24,-6,STONE:3)
Block(7,24,-5,STONE:3)
Block(7,25,-7,STONE:3)
Block(7,25,-6,STONE:3)
Block(7,25,-5,STONE:3)
Block(7,25,-4,STONE:3)
Block(7,26,-7,STONE:3)
Block(7,26,-6,STONE:3)
Block(7,26,-5,STONE:3)
Block(7,26,-4,STONE:3)
Block(7,26,-3,STONE:3)
Block(7,27,-7,STONE:3)
Block(7,27,-6,STONE:3)
Block(7,27,-5,STONE:3)
Block(7,27,-4,STONE:3)
Block(7,27,-3,STONE:3)
Block(7,28,-7,STONE:3)
Block(7,28,-6,STONE:3)
Block(7,28,-5,STONE:3)
Block(7,28,-4,STONE:3)
Block(7,28,-3,STONE:3)
Block(7,29,-7,STONE:3)
Block(7,29,-6,STONE:3)
Block(7,29,-5,STONE:3)
Block(7,29,-4,STONE:3)
Block(7,29,-3,STONE:3)
Block(7,30,-7,STONE:3)
Block(7,30,-6,STONE:3)
Block(7,30,-5,STONE:3)
Block(7,30,-4,STONE:3)
Block(7,30,-3,STONE:3)
Block(7,31,-7,STONE:3)
Block(7,31,-6,STONE:3)
Block(7,31,-5,STONE:3)
Block(7,31,-4,STONE:3)
Block(7,31,-3,STONE:3)
Block(7,32,-7,STONE:3)
Block(7,32,-6,STONE:3)
Block(7,32,-5,STONE:3)
Block(7,32,-4,STONE:3)
Block(7,32,-3,STONE:3)
Block(7,33,-7,STONE:3)
Block(7,33,-6,STONE:3)
Block(7,33,-5,STONE:3)
Block(7,33,-4,STONE:3)
Block(7,33,-3,STONE:3)
Block(7,34,-7,STONE:3)
Block(7,34,-6,STONE:3)
Block(7,34,-5,STONE:3)
Block(7,34,-4,STONE:3)
Block(7,34,-3,STONE:3)
Block(7,35,-7,STONE:3)
Block(7,35,-6,STONE:3)
Block(7,35,-5,STONE:3)
Block(7,35,-4,STONE:3)
Block(7,35,-3,STONE:3)
Block(7,36,-7,STONE:3)
Block(7,36,-6,STONE:3)
Block(7,36,-5,STONE:3)
Block(7,36,-4,STONE:3)
Block(7,36,-3,STONE:3)
Block(7,37,-7,STONE:3)
Block(7,37,-6,STONE:3)
Block(7,37,-5,STONE:3)
Block(7,37,-4,STONE:3)
Block(7,37,-3,STONE:3)
Block(7,38,-7,STONE:3)
Block(7,38,-6,STONE:3)
Block(7,38,-5,STONE:3)
Block(7,38,-4,STONE:3)
Block(7,38,-3,STONE:3)
Block(7,39,-7,STONE:3)
Block(7,39,-6,STONE:3)
Block(7,39,-5,STONE:3)
Block(7,39,-4,STONE:3)
Block(7,39,-3,STONE:3)
Block(7,40,-7,STONE:3)
Block(7,40,-6,STONE:3)
Block(7,40,-5,STONE:3)
Block(7,40,-4,STONE:3)
Block(7,40,-3,STONE:3)
Block(7,40,-2,STONE:5)
Block(7,41,-7,STONE:3)
Block(7,41,-6,STONE:3)
Block(7,41,-5,STONE:3)
Block(7,41,-4,STONE:3)
Block(7,41,-3,STONE:3)
Block(7,42,-7,STONE:3)
Block(7,42,-6,STONE:3)
Block(7,42,-5,STONE:3)
Block(7,42,-4,STONE:3)
Block(7,42,-3,STONE:3)
Block(7,43,-7,STONE:3)
Block(7,43,-6,STONE:3)
Block(7,43,-5,STONE:3)
Block(7,43,-4,STONE:3)
Block(7,43,-3,STONE:5)
Block(7,44,-7,STONE:3)
Block(7,44,-6,STONE:3)
Block(7,44,-5,STONE:3)
Block(7,44,-4,STONE:3)
Block(7,45,-7,STONE:3)
Block(7,45,-6,STONE:3)
Block(7,45,-5,STONE:3)
Block(7,45,-4,STONE:5)
Block(7,46,-7,STONE:3)
Block(7,46,-6,STONE:3)
Block(7,46,-5,STONE:5)
Block(7,47,-7,STONE:3)
Block(7,47,-6,STONE:3)
Block(7,48,-7,STONE:3)
Block(7,48,-6,STONE:5)
Block(7,49,-7,STONE:5)

#######################################################################
# +-----------------------------------------------------------------+ #
# |                             Branches                            | #
# +-----------------------------------------------------------------+ #
#######################################################################


#######################################################################
# +-----------------------------------------------------------------+ #
# |                             Entities                            | #
# +-----------------------------------------------------------------+ #
#######################################################################


#######################################################################
# +-----------------------------------------------------------------+ #
# |                            Particles                            | #
# +-----------------------------------------------------------------+ #
#######################################################################


#######################################################################
# +-----------------------------------------------------------------+ #
# |                             Spawners                            | #
# +-----------------------------------------------------------------+ #
#######################################################################


#######################################################################
# +-----------------------------------------------------------------+ #
# |                             ModData                             | #
# +-----------------------------------------------------------------+ #
#######################################################################

