
#######################################################################
# +-----------------------------------------------------------------+ #
# |                            BO4 object                           | #
# +-----------------------------------------------------------------+ #
#######################################################################

Author: NLBlackEagle

Description: No description given

SettingsMode: WriteWithoutComments


#######################################################################
# +-----------------------------------------------------------------+ #
# |                          Main settings                          | #
# +-----------------------------------------------------------------+ #
#######################################################################

FixedRotation: 

Frequency: 0

SpawnHeight: highestBlock

UseCenterForHighestBlock: true

##############################
# Height Limits for the BO4. #
##############################

MinHeight: 0

MaxHeight: 255

InheritBO3: 

InheritBO3Rotation: NORTH

OverrideChildSettings: true

OverrideParentHeight: false

CanOverride: false

BranchFrequency: 0

BranchFrequencyGroup: 

MustBeBelowOther: false

MustBeInside: 

CannotBeInside: 

ReplacesBO3: 

MustBeInsideWorldBorders: false

CanSpawnOnWater: true

SpawnOnWaterOnly: false

SpawnUnderWater: false

SpawnAtWaterLevel: false

HeightOffset: 0

RemoveAir: true

ReplaceAbove: 

ReplaceBelow: 

ReplaceWithBiomeBlocks: true

ReplaceWithSurfaceBlock: GRASS

ReplaceWithGroundBlock: DIRT

ReplaceWithStoneBlock: STONE

SmoothRadius: 0

SmoothHeightOffset: 0

SmoothStartTop: false

SmoothStartWood: false

SmoothingSurfaceBlock: 

SmoothingGroundBlock: 

BO3Group: 

IsSpawnPoint: false

DoReplaceBlocks: true


#######################################################################
# +-----------------------------------------------------------------+ #
# |                              Blocks                             | #
# +-----------------------------------------------------------------+ #
#######################################################################

B(-8,32,8,minecraft:diorite)
B(-8,33,7,minecraft:diorite)
B(-8,33,8,minecraft:diorite)
B(-8,34,3,minecraft:diorite)
B(-8,34,4,minecraft:diorite)
B(-8,34,5,minecraft:diorite)
B(-8,34,6,minecraft:diorite)
B(-8,34,7,minecraft:diorite)
B(-8,34,8,minecraft:diorite)
B(-8,35,3,minecraft:diorite)
B(-8,35,4,minecraft:diorite)
B(-8,35,5,minecraft:diorite)
B(-8,35,6,minecraft:diorite)
B(-8,35,7,minecraft:diorite)
B(-8,35,8,minecraft:diorite)
B(-8,36,2,minecraft:diorite)
B(-8,36,3,minecraft:diorite)
B(-8,36,4,minecraft:diorite)
B(-8,36,5,minecraft:diorite)
B(-8,36,6,minecraft:diorite)
B(-8,36,7,minecraft:diorite)
B(-8,36,8,minecraft:diorite)
B(-8,37,2,minecraft:diorite)
B(-8,37,3,minecraft:diorite)
B(-8,37,4,minecraft:diorite)
B(-8,37,5,minecraft:diorite)
B(-8,37,6,minecraft:diorite)
B(-8,37,7,minecraft:diorite)
B(-8,37,8,minecraft:diorite)
B(-8,38,1,minecraft:diorite)
B(-8,38,2,minecraft:diorite)
B(-8,38,3,minecraft:diorite)
B(-8,38,4,minecraft:diorite)
B(-8,38,5,minecraft:diorite)
B(-8,38,6,minecraft:diorite)
B(-8,38,7,minecraft:diorite)
B(-8,38,8,minecraft:diorite)
B(-8,39,1,minecraft:diorite)
B(-8,39,2,minecraft:diorite)
B(-8,39,3,minecraft:diorite)
B(-8,39,4,minecraft:diorite)
B(-8,39,5,minecraft:diorite)
B(-8,39,6,minecraft:diorite)
B(-8,39,7,minecraft:diorite)
B(-8,39,8,minecraft:diorite)
B(-8,40,2,minecraft:diorite)
B(-8,40,3,minecraft:diorite)
B(-8,40,4,minecraft:diorite)
B(-8,40,5,minecraft:diorite)
B(-8,40,6,minecraft:diorite)
B(-8,40,7,minecraft:diorite)
B(-8,40,8,minecraft:diorite)
B(-8,41,1,minecraft:diorite)
B(-8,41,2,minecraft:diorite)
B(-8,41,3,minecraft:diorite)
B(-8,41,4,minecraft:diorite)
B(-8,41,5,minecraft:diorite)
B(-8,41,6,minecraft:diorite)
B(-8,41,7,minecraft:diorite)
B(-8,41,8,minecraft:diorite)
B(-8,42,1,minecraft:diorite)
B(-8,42,2,minecraft:diorite)
B(-8,42,3,minecraft:diorite)
B(-8,42,4,minecraft:diorite)
B(-8,42,5,minecraft:diorite)
B(-8,42,6,minecraft:diorite)
B(-8,42,7,minecraft:diorite)
B(-8,42,8,minecraft:obsidian)
B(-8,43,0,minecraft:diorite)
B(-8,43,1,minecraft:diorite)
B(-8,43,2,minecraft:diorite)
B(-8,43,3,minecraft:diorite)
B(-8,43,4,minecraft:diorite)
B(-8,43,5,minecraft:diorite)
B(-8,43,6,minecraft:diorite)
B(-8,43,7,minecraft:diorite)
B(-8,43,8,minecraft:obsidian)
B(-8,44,0,minecraft:diorite)
B(-8,44,1,minecraft:diorite)
B(-8,44,2,minecraft:diorite)
B(-8,44,3,minecraft:diorite)
B(-8,44,4,minecraft:diorite)
B(-8,44,5,minecraft:obsidian)
B(-8,44,6,minecraft:obsidian)
B(-8,44,7,minecraft:obsidian)
B(-8,44,8,minecraft:obsidian)
B(-8,45,-1,minecraft:diorite)
B(-8,45,0,minecraft:diorite)
B(-8,45,1,minecraft:diorite)
B(-8,45,2,minecraft:diorite)
B(-8,45,3,minecraft:diorite)
B(-8,45,4,minecraft:diorite)
B(-8,45,5,minecraft:obsidian)
B(-8,45,6,minecraft:obsidian)
B(-8,45,7,minecraft:obsidian)
B(-8,45,8,minecraft:obsidian)
B(-8,46,-3,minecraft:diorite)
B(-8,46,-2,minecraft:diorite)
B(-8,46,-1,minecraft:diorite)
B(-8,46,0,minecraft:diorite)
B(-8,46,1,minecraft:diorite)
B(-8,46,2,minecraft:diorite)
B(-8,46,3,minecraft:diorite)
B(-8,46,4,minecraft:diorite)
B(-8,46,5,minecraft:diorite)
B(-8,46,6,minecraft:diorite)
B(-8,46,7,minecraft:obsidian)
B(-8,46,8,minecraft:obsidian)
B(-8,47,-4,minecraft:obsidian)
B(-8,47,-3,minecraft:obsidian)
B(-8,47,-2,minecraft:obsidian)
B(-8,47,-1,minecraft:diorite)
B(-8,47,0,minecraft:diorite)
B(-8,47,1,minecraft:diorite)
B(-8,47,2,minecraft:diorite)
B(-8,47,3,minecraft:diorite)
B(-8,47,4,minecraft:diorite)
B(-8,47,5,minecraft:diorite)
B(-8,47,6,minecraft:andesite)
B(-8,47,7,minecraft:diorite)
B(-8,47,8,minecraft:obsidian)
B(-8,48,-4,minecraft:magma_block)
B(-8,48,-3,minecraft:magma_block)
B(-8,48,-2,minecraft:magma_block)
B(-8,48,-1,minecraft:obsidian)
B(-8,48,0,minecraft:obsidian)
B(-8,48,1,minecraft:obsidian)
B(-8,48,2,minecraft:obsidian)
B(-8,48,3,minecraft:diorite)
B(-8,48,4,minecraft:diorite)
B(-8,49,-5,minecraft:magma_block)
B(-8,49,-4,minecraft:magma_block)
B(-8,49,-3,minecraft:magma_block)
B(-8,49,-2,minecraft:magma_block)
B(-8,49,-1,minecraft:magma_block)
B(-8,49,0,minecraft:obsidian)
B(-8,49,1,minecraft:obsidian)
B(-8,49,2,minecraft:obsidian)
B(-8,49,3,minecraft:diorite)
B(-8,49,4,minecraft:diorite)
B(-8,50,-4,minecraft:magma_block)
B(-8,50,-3,minecraft:magma_block)
B(-8,50,-2,minecraft:magma_block)
B(-8,50,-1,minecraft:magma_block)
B(-8,50,0,minecraft:obsidian)
B(-8,50,1,minecraft:obsidian)
B(-8,50,2,minecraft:obsidian)
B(-8,50,3,minecraft:diorite)
B(-8,50,4,minecraft:diorite)
B(-8,51,-3,minecraft:magma_block)
B(-8,51,-2,minecraft:magma_block)
B(-8,51,-1,minecraft:magma_block)
B(-8,51,0,minecraft:obsidian)
B(-8,51,1,minecraft:obsidian)
B(-8,51,2,minecraft:obsidian)
B(-8,51,3,minecraft:obsidian)
B(-8,52,-3,minecraft:magma_block)
B(-8,52,-2,minecraft:magma_block)
B(-8,52,-1,minecraft:obsidian)
B(-8,52,0,minecraft:obsidian)
B(-8,52,1,minecraft:obsidian)
B(-8,53,-4,minecraft:obsidian)
B(-8,53,-3,minecraft:obsidian)
B(-8,53,-2,minecraft:obsidian)
B(-8,53,-1,minecraft:obsidian)
B(-8,53,0,minecraft:obsidian)
B(-8,53,1,minecraft:obsidian)
B(-8,54,-4,minecraft:obsidian)
B(-8,54,-3,minecraft:obsidian)
B(-8,54,-2,minecraft:obsidian)
B(-8,54,-1,minecraft:obsidian)
B(-8,54,0,minecraft:obsidian)
B(-8,55,-5,minecraft:obsidian)
B(-8,55,-4,minecraft:obsidian)
B(-8,55,-3,minecraft:obsidian)
B(-8,55,-2,minecraft:obsidian)
B(-8,55,-1,minecraft:obsidian)
B(-8,55,0,minecraft:obsidian)
B(-8,56,-6,minecraft:obsidian)
B(-8,56,-5,minecraft:obsidian)
B(-8,56,-4,minecraft:obsidian)
B(-8,56,-3,minecraft:obsidian)
B(-8,56,-2,minecraft:obsidian)
B(-8,56,-1,minecraft:obsidian)
B(-8,56,0,minecraft:obsidian)
B(-8,56,1,minecraft:obsidian)
B(-8,57,-7,minecraft:diorite)
B(-8,57,-6,minecraft:obsidian)
B(-8,57,-5,minecraft:obsidian)
B(-8,57,-4,minecraft:obsidian)
B(-8,57,-3,minecraft:obsidian)
B(-8,57,-2,minecraft:obsidian)
B(-8,57,-1,minecraft:obsidian)
B(-8,57,0,minecraft:obsidian)
B(-8,58,-7,minecraft:diorite)
B(-8,58,-6,minecraft:diorite)
B(-8,58,-5,minecraft:obsidian)
B(-8,58,-4,minecraft:obsidian)
B(-8,58,-3,minecraft:obsidian)
B(-8,58,-2,minecraft:obsidian)
B(-8,58,-1,minecraft:obsidian)
B(-8,59,-7,minecraft:diorite)
B(-8,59,-6,minecraft:diorite)
B(-8,59,-5,minecraft:obsidian)
B(-8,59,-4,minecraft:obsidian)
B(-8,59,-3,minecraft:obsidian)
B(-8,59,-2,minecraft:diorite)
B(-8,60,-7,minecraft:diorite)
B(-8,60,-6,minecraft:diorite)
B(-8,60,-5,minecraft:obsidian)
B(-8,60,-4,minecraft:obsidian)
B(-8,60,-3,minecraft:diorite)
B(-8,60,-2,minecraft:diorite)
B(-8,60,-1,minecraft:diorite)
B(-8,60,0,minecraft:diorite)
B(-8,61,-7,minecraft:diorite)
B(-8,61,-6,minecraft:diorite)
B(-8,61,-5,minecraft:diorite)
B(-8,61,-4,minecraft:obsidian)
B(-8,61,-3,minecraft:diorite)
B(-8,61,-2,minecraft:diorite)
B(-8,61,-1,minecraft:diorite)
B(-8,61,0,minecraft:diorite)
B(-8,61,1,minecraft:diorite)
B(-8,62,-7,minecraft:diorite)
B(-8,62,-6,minecraft:diorite)
B(-8,62,-5,minecraft:obsidian)
B(-8,62,-4,minecraft:obsidian)
B(-8,62,-3,minecraft:diorite)
B(-8,62,-2,minecraft:diorite)
B(-8,62,-1,minecraft:diorite)
B(-8,62,0,minecraft:diorite)
B(-8,62,1,minecraft:diorite)
B(-8,63,-7,minecraft:diorite)
B(-8,63,-6,minecraft:diorite)
B(-8,63,-5,minecraft:obsidian)
B(-8,63,-4,minecraft:obsidian)
B(-8,63,-3,minecraft:obsidian)
B(-8,63,-2,minecraft:diorite)
B(-8,63,-1,minecraft:diorite)
B(-8,63,0,minecraft:diorite)
B(-8,63,1,minecraft:obsidian)
B(-8,64,-7,minecraft:diorite)
B(-8,64,-6,minecraft:diorite)
B(-8,64,-5,minecraft:diorite)
B(-8,64,-4,minecraft:obsidian)
B(-8,64,-3,minecraft:obsidian)
B(-8,64,-2,minecraft:obsidian)
B(-8,64,-1,minecraft:obsidian)
B(-8,64,0,minecraft:obsidian)
B(-8,64,1,minecraft:obsidian)
B(-8,65,-7,minecraft:diorite)
B(-8,65,-6,minecraft:diorite)
B(-8,65,-5,minecraft:diorite)
B(-8,65,-4,minecraft:obsidian)
B(-8,65,-3,minecraft:obsidian)
B(-8,65,-2,minecraft:obsidian)
B(-8,65,-1,minecraft:diorite)
B(-8,65,0,minecraft:diorite)
B(-8,65,1,minecraft:diorite)
B(-8,66,-7,minecraft:diorite)
B(-8,66,-6,minecraft:diorite)
B(-8,66,-5,minecraft:diorite)
B(-8,66,-4,minecraft:obsidian)
B(-8,66,-3,minecraft:obsidian)
B(-8,66,-2,minecraft:obsidian)
B(-8,66,-1,minecraft:diorite)
B(-8,66,0,minecraft:diorite)
B(-8,66,1,minecraft:diorite)
B(-8,67,-7,minecraft:diorite)
B(-8,67,-6,minecraft:diorite)
B(-8,67,-5,minecraft:diorite)
B(-8,67,-4,minecraft:obsidian)
B(-8,67,-3,minecraft:obsidian)
B(-8,67,-2,minecraft:obsidian)
B(-8,67,-1,minecraft:diorite)
B(-8,67,0,minecraft:diorite)
B(-8,68,-7,minecraft:diorite)
B(-8,68,-6,minecraft:diorite)
B(-8,68,-5,minecraft:diorite)
B(-8,68,-4,minecraft:obsidian)
B(-8,68,-3,minecraft:obsidian)
B(-8,68,-2,minecraft:obsidian)
B(-8,68,-1,minecraft:obsidian)
B(-8,68,0,minecraft:obsidian)
B(-8,68,1,minecraft:obsidian)
B(-8,69,-7,minecraft:diorite)
B(-8,69,-6,minecraft:diorite)
B(-8,69,-5,minecraft:obsidian)
B(-8,69,-4,minecraft:obsidian)
B(-8,69,-3,minecraft:diorite)
B(-8,69,-2,minecraft:diorite)
B(-8,69,-1,minecraft:andesite)
B(-8,69,0,minecraft:obsidian)
B(-8,69,1,minecraft:obsidian)
B(-8,70,-7,minecraft:diorite)
B(-8,70,-6,minecraft:diorite)
B(-8,70,-5,minecraft:obsidian)
B(-8,70,-4,minecraft:diorite)
B(-8,70,-3,minecraft:diorite)
B(-8,70,-2,minecraft:diorite)
B(-8,70,0,minecraft:diorite)
B(-8,71,-7,minecraft:andesite)
B(-8,71,-6,minecraft:diorite)
B(-8,71,-5,minecraft:obsidian)
B(-8,71,-4,minecraft:diorite)
B(-8,71,-3,minecraft:diorite)
B(-8,71,-2,minecraft:diorite)
B(-8,71,0,minecraft:diorite)
B(-8,71,1,minecraft:obsidian)
B(-8,72,-6,minecraft:diorite)
B(-8,72,-5,minecraft:obsidian)
B(-8,72,-4,minecraft:diorite)
B(-8,72,-3,minecraft:diorite)
B(-8,72,-2,minecraft:diorite)
B(-8,72,-1,minecraft:diorite)
B(-8,72,0,minecraft:diorite)
B(-8,72,1,minecraft:diorite)
B(-8,72,2,minecraft:diorite)
B(-8,73,-6,minecraft:andesite)
B(-8,73,-5,minecraft:diorite)
B(-8,73,-4,minecraft:diorite)
B(-8,73,-3,minecraft:diorite)
B(-8,73,-2,minecraft:diorite)
B(-8,73,-1,minecraft:diorite)
B(-8,73,0,minecraft:obsidian)
B(-8,73,1,minecraft:diorite)
B(-8,73,2,minecraft:diorite)
B(-8,73,3,minecraft:diorite)
B(-8,74,-5,minecraft:diorite)
B(-8,74,-4,minecraft:diorite)
B(-8,74,-3,minecraft:obsidian)
B(-8,74,-2,minecraft:obsidian)
B(-8,74,-1,minecraft:obsidian)
B(-8,74,0,minecraft:obsidian)
B(-8,74,1,minecraft:diorite)
B(-8,74,2,minecraft:diorite)
B(-8,74,3,minecraft:diorite)
B(-8,74,4,minecraft:diorite)
B(-8,75,-5,minecraft:andesite)
B(-8,75,-4,minecraft:diorite)
B(-8,75,-3,minecraft:diorite)
B(-8,75,-2,minecraft:obsidian)
B(-8,75,-1,minecraft:obsidian)
B(-8,75,0,minecraft:obsidian)
B(-8,75,1,minecraft:obsidian)
B(-8,75,2,minecraft:diorite)
B(-8,75,3,minecraft:diorite)
B(-8,75,4,minecraft:diorite)
B(-8,75,5,minecraft:diorite)
B(-8,76,-4,minecraft:diorite)
B(-8,76,-3,minecraft:diorite)
B(-8,76,-2,minecraft:obsidian)
B(-8,76,-1,minecraft:obsidian)
B(-8,76,0,minecraft:obsidian)
B(-8,76,1,minecraft:obsidian)
B(-8,76,2,minecraft:diorite)
B(-8,76,3,minecraft:diorite)
B(-8,76,4,minecraft:diorite)
B(-8,76,5,minecraft:diorite)
B(-8,77,-4,minecraft:diorite)
B(-8,77,-3,minecraft:diorite)
B(-8,77,-2,minecraft:diorite)
B(-8,77,-1,minecraft:obsidian)
B(-8,77,0,minecraft:obsidian)
B(-8,77,1,minecraft:obsidian)
B(-8,77,2,minecraft:diorite)
B(-8,77,3,minecraft:diorite)
B(-8,77,4,minecraft:diorite)
B(-8,77,5,minecraft:diorite)
B(-8,78,-4,minecraft:andesite)
B(-8,78,-3,minecraft:diorite)
B(-8,78,-2,minecraft:obsidian)
B(-8,78,-1,minecraft:obsidian)
B(-8,78,0,minecraft:obsidian)
B(-8,78,1,minecraft:obsidian)
B(-8,78,2,minecraft:obsidian)
B(-8,78,3,minecraft:obsidian)
B(-8,78,4,minecraft:diorite)
B(-8,78,5,minecraft:diorite)
B(-8,78,6,minecraft:diorite)
B(-8,79,-3,minecraft:diorite)
B(-8,79,-2,minecraft:diorite)
B(-8,79,-1,minecraft:obsidian)
B(-8,79,0,minecraft:obsidian)
B(-8,79,1,minecraft:obsidian)
B(-8,79,2,minecraft:obsidian)
B(-8,79,3,minecraft:obsidian)
B(-8,79,4,minecraft:obsidian)
B(-8,79,5,minecraft:obsidian)
B(-8,79,6,minecraft:diorite)
B(-8,79,7,minecraft:diorite)
B(-8,80,-3,minecraft:diorite)
B(-8,80,-2,minecraft:diorite)
B(-8,80,-1,minecraft:diorite)
B(-8,80,0,minecraft:diorite)
B(-8,80,1,minecraft:diorite)
B(-8,80,2,minecraft:obsidian)
B(-8,80,3,minecraft:obsidian)
B(-8,80,4,minecraft:obsidian)
B(-8,80,5,minecraft:obsidian)
B(-8,80,6,minecraft:obsidian)
B(-8,80,7,minecraft:diorite)
B(-8,80,8,minecraft:diorite)
B(-8,81,-3,minecraft:diorite)
B(-8,81,-2,minecraft:diorite)
B(-8,81,-1,minecraft:diorite)
B(-8,81,0,minecraft:diorite)
B(-8,81,1,minecraft:diorite)
B(-8,81,2,minecraft:diorite)
B(-8,81,3,minecraft:diorite)
B(-8,81,4,minecraft:obsidian)
B(-8,81,5,minecraft:obsidian)
B(-8,81,6,minecraft:obsidian)
B(-8,81,7,minecraft:diorite)
B(-8,81,8,minecraft:diorite)
B(-8,82,-2,minecraft:andesite)
B(-8,82,-1,minecraft:diorite)
B(-8,82,0,minecraft:diorite)
B(-8,82,1,minecraft:diorite)
B(-8,82,2,minecraft:diorite)
B(-8,82,3,minecraft:diorite)
B(-8,82,4,minecraft:diorite)
B(-8,82,5,minecraft:obsidian)
B(-8,82,6,minecraft:obsidian)
B(-8,82,7,minecraft:obsidian)
B(-8,82,8,minecraft:diorite)
B(-8,83,-1,minecraft:diorite)
B(-8,83,0,minecraft:diorite)
B(-8,83,1,minecraft:diorite)
B(-8,83,2,minecraft:diorite)
B(-8,83,3,minecraft:diorite)
B(-8,83,4,minecraft:diorite)
B(-8,83,5,minecraft:diorite)
B(-8,83,6,minecraft:obsidian)
B(-8,83,7,minecraft:obsidian)
B(-8,83,8,minecraft:obsidian)
B(-8,84,-1,minecraft:andesite)
B(-8,84,0,minecraft:diorite)
B(-8,84,1,minecraft:diorite)
B(-8,84,2,minecraft:diorite)
B(-8,84,3,minecraft:diorite)
B(-8,84,4,minecraft:diorite)
B(-8,84,5,minecraft:diorite)
B(-8,84,6,minecraft:diorite)
B(-8,84,7,minecraft:obsidian)
B(-8,84,8,minecraft:obsidian)
B(-8,85,0,minecraft:andesite)
B(-8,85,1,minecraft:diorite)
B(-8,85,2,minecraft:diorite)
B(-8,85,3,minecraft:diorite)
B(-8,85,4,minecraft:diorite)
B(-8,85,5,minecraft:diorite)
B(-8,85,6,minecraft:diorite)
B(-8,85,7,minecraft:diorite)
B(-8,85,8,minecraft:obsidian)
B(-8,86,1,minecraft:diorite)
B(-8,86,2,minecraft:diorite)
B(-8,86,3,minecraft:diorite)
B(-8,86,4,minecraft:diorite)
B(-8,86,5,minecraft:diorite)
B(-8,86,6,minecraft:diorite)
B(-8,86,7,minecraft:diorite)
B(-8,86,8,minecraft:obsidian)
B(-8,87,1,minecraft:diorite)
B(-8,87,2,minecraft:diorite)
B(-8,87,3,minecraft:diorite)
B(-8,87,4,minecraft:diorite)
B(-8,87,5,minecraft:diorite)
B(-8,87,6,minecraft:diorite)
B(-8,87,7,minecraft:diorite)
B(-8,87,8,minecraft:obsidian)
B(-8,88,1,minecraft:andesite)
B(-8,88,2,minecraft:diorite)
B(-8,88,3,minecraft:diorite)
B(-8,88,4,minecraft:diorite)
B(-8,88,5,minecraft:diorite)
B(-8,88,6,minecraft:diorite)
B(-8,88,7,minecraft:obsidian)
B(-8,88,8,minecraft:obsidian)
B(-8,89,2,minecraft:andesite)
B(-8,89,3,minecraft:diorite)
B(-8,89,4,minecraft:diorite)
B(-8,89,5,minecraft:diorite)
B(-8,89,6,minecraft:diorite)
B(-8,89,7,minecraft:obsidian)
B(-8,89,8,minecraft:diorite)
B(-8,90,3,minecraft:andesite)
B(-8,90,4,minecraft:andesite)
B(-8,90,5,minecraft:andesite)
B(-8,90,6,minecraft:andesite)
B(-8,90,7,minecraft:diorite)
B(-8,90,8,minecraft:diorite)
B(-8,91,7,minecraft:andesite)
B(-8,91,8,minecraft:andesite)
B(-7,32,8,minecraft:diorite)
B(-7,33,7,minecraft:diorite)
B(-7,33,8,minecraft:diorite)
B(-7,34,4,minecraft:diorite)
B(-7,34,5,minecraft:diorite)
B(-7,34,6,minecraft:diorite)
B(-7,34,7,minecraft:diorite)
B(-7,34,8,minecraft:diorite)
B(-7,35,4,minecraft:diorite)
B(-7,35,5,minecraft:diorite)
B(-7,35,6,minecraft:diorite)
B(-7,35,7,minecraft:diorite)
B(-7,35,8,minecraft:diorite)
B(-7,36,3,minecraft:diorite)
B(-7,36,4,minecraft:diorite)
B(-7,36,5,minecraft:diorite)
B(-7,36,6,minecraft:diorite)
B(-7,36,7,minecraft:diorite)
B(-7,36,8,minecraft:diorite)
B(-7,37,2,minecraft:diorite)
B(-7,37,3,minecraft:diorite)
B(-7,37,4,minecraft:diorite)
B(-7,37,5,minecraft:diorite)
B(-7,37,6,minecraft:diorite)
B(-7,37,7,minecraft:diorite)
B(-7,37,8,minecraft:diorite)
B(-7,38,2,minecraft:diorite)
B(-7,38,3,minecraft:diorite)
B(-7,38,4,minecraft:diorite)
B(-7,38,5,minecraft:diorite)
B(-7,38,6,minecraft:diorite)
B(-7,38,7,minecraft:diorite)
B(-7,38,8,minecraft:diorite)
B(-7,39,3,minecraft:diorite)
B(-7,39,4,minecraft:diorite)
B(-7,39,5,minecraft:diorite)
B(-7,39,6,minecraft:diorite)
B(-7,39,7,minecraft:diorite)
B(-7,39,8,minecraft:diorite)
B(-7,40,2,minecraft:diorite)
B(-7,40,3,minecraft:diorite)
B(-7,40,4,minecraft:diorite)
B(-7,40,5,minecraft:diorite)
B(-7,40,6,minecraft:diorite)
B(-7,40,7,minecraft:diorite)
B(-7,40,8,minecraft:diorite)
B(-7,41,2,minecraft:diorite)
B(-7,41,3,minecraft:diorite)
B(-7,41,4,minecraft:diorite)
B(-7,41,5,minecraft:diorite)
B(-7,41,6,minecraft:diorite)
B(-7,41,7,minecraft:diorite)
B(-7,41,8,minecraft:diorite)
B(-7,42,2,minecraft:diorite)
B(-7,42,3,minecraft:diorite)
B(-7,42,4,minecraft:diorite)
B(-7,42,5,minecraft:diorite)
B(-7,42,6,minecraft:diorite)
B(-7,42,7,minecraft:diorite)
B(-7,42,8,minecraft:diorite)
B(-7,43,1,minecraft:diorite)
B(-7,43,2,minecraft:diorite)
B(-7,43,3,minecraft:diorite)
B(-7,43,4,minecraft:diorite)
B(-7,43,5,minecraft:diorite)
B(-7,43,6,minecraft:diorite)
B(-7,43,7,minecraft:diorite)
B(-7,43,8,minecraft:obsidian)
B(-7,44,1,minecraft:diorite)
B(-7,44,2,minecraft:diorite)
B(-7,44,3,minecraft:diorite)
B(-7,44,4,minecraft:diorite)
B(-7,44,5,minecraft:diorite)
B(-7,44,6,minecraft:diorite)
B(-7,44,7,minecraft:obsidian)
B(-7,44,8,minecraft:obsidian)
B(-7,45,0,minecraft:diorite)
B(-7,45,1,minecraft:diorite)
B(-7,45,2,minecraft:diorite)
B(-7,45,3,minecraft:diorite)
B(-7,45,4,minecraft:diorite)
B(-7,45,5,minecraft:diorite)
B(-7,45,6,minecraft:obsidian)
B(-7,45,7,minecraft:obsidian)
B(-7,45,8,minecraft:obsidian)
B(-7,46,-1,minecraft:diorite)
B(-7,46,0,minecraft:diorite)
B(-7,46,1,minecraft:diorite)
B(-7,46,2,minecraft:diorite)
B(-7,46,3,minecraft:diorite)
B(-7,46,4,minecraft:diorite)
B(-7,46,5,minecraft:obsidian)
B(-7,46,6,minecraft:obsidian)
B(-7,46,7,minecraft:obsidian)
B(-7,46,8,minecraft:obsidian)
B(-7,47,-4,minecraft:obsidian)
B(-7,47,-3,minecraft:obsidian)
B(-7,47,-2,minecraft:diorite)
B(-7,47,-1,minecraft:diorite)
B(-7,47,0,minecraft:diorite)
B(-7,47,1,minecraft:diorite)
B(-7,47,2,minecraft:diorite)
B(-7,47,3,minecraft:diorite)
B(-7,47,4,minecraft:diorite)
B(-7,47,5,minecraft:diorite)
B(-7,47,6,minecraft:diorite)
B(-7,47,7,minecraft:obsidian)
B(-7,47,8,minecraft:obsidian)
B(-7,48,-4,minecraft:magma_block)
B(-7,48,-3,minecraft:magma_block)
B(-7,48,-2,minecraft:magma_block)
B(-7,48,-1,minecraft:obsidian)
B(-7,48,0,minecraft:diorite)
B(-7,48,1,minecraft:diorite)
B(-7,48,2,minecraft:diorite)
B(-7,48,3,minecraft:diorite)
B(-7,48,4,minecraft:diorite)
B(-7,48,5,minecraft:diorite)
B(-7,48,6,minecraft:andesite)
B(-7,48,7,minecraft:andesite)
B(-7,48,8,minecraft:obsidian)
B(-7,49,-4,minecraft:magma_block)
B(-7,49,-3,minecraft:magma_block)
B(-7,49,-2,minecraft:magma_block)
B(-7,49,-1,minecraft:magma_block)
B(-7,49,0,minecraft:obsidian)
B(-7,49,1,minecraft:obsidian)
B(-7,49,2,minecraft:obsidian)
B(-7,49,3,minecraft:diorite)
B(-7,49,4,minecraft:diorite)
B(-7,49,5,minecraft:andesite)
B(-7,50,-3,minecraft:magma_block)
B(-7,50,-2,minecraft:magma_block)
B(-7,50,-1,minecraft:magma_block)
B(-7,50,0,minecraft:obsidian)
B(-7,50,1,minecraft:obsidian)
B(-7,50,2,minecraft:obsidian)
B(-7,50,3,minecraft:diorite)
B(-7,50,4,minecraft:diorite)
B(-7,51,-3,minecraft:magma_block)
B(-7,51,-2,minecraft:magma_block)
B(-7,51,-1,minecraft:magma_block)
B(-7,51,0,minecraft:obsidian)
B(-7,51,1,minecraft:obsidian)
B(-7,51,2,minecraft:obsidian)
B(-7,51,3,minecraft:obsidian)
B(-7,52,-3,minecraft:magma_block)
B(-7,52,-2,minecraft:magma_block)
B(-7,52,-1,minecraft:magma_block)
B(-7,52,0,minecraft:obsidian)
B(-7,52,1,minecraft:obsidian)
B(-7,52,2,minecraft:obsidian)
B(-7,52,3,minecraft:obsidian)
B(-7,53,-3,minecraft:obsidian)
B(-7,53,-2,minecraft:obsidian)
B(-7,53,-1,minecraft:obsidian)
B(-7,53,0,minecraft:obsidian)
B(-7,53,1,minecraft:obsidian)
B(-7,54,-3,minecraft:obsidian)
B(-7,54,-2,minecraft:obsidian)
B(-7,54,-1,minecraft:obsidian)
B(-7,54,0,minecraft:obsidian)
B(-7,54,1,minecraft:obsidian)
B(-7,55,-4,minecraft:obsidian)
B(-7,55,-3,minecraft:obsidian)
B(-7,55,-2,minecraft:obsidian)
B(-7,55,-1,minecraft:obsidian)
B(-7,55,0,minecraft:obsidian)
B(-7,55,1,minecraft:obsidian)
B(-7,55,2,minecraft:obsidian)
B(-7,56,-6,minecraft:obsidian)
B(-7,56,-5,minecraft:obsidian)
B(-7,56,-4,minecraft:obsidian)
B(-7,56,-3,minecraft:obsidian)
B(-7,56,-2,minecraft:obsidian)
B(-7,56,-1,minecraft:obsidian)
B(-7,56,0,minecraft:obsidian)
B(-7,56,1,minecraft:obsidian)
B(-7,56,2,minecraft:obsidian)
B(-7,57,-7,minecraft:diorite)
B(-7,57,-6,minecraft:diorite)
B(-7,57,-5,minecraft:obsidian)
B(-7,57,-4,minecraft:obsidian)
B(-7,57,-3,minecraft:obsidian)
B(-7,57,-2,minecraft:obsidian)
B(-7,57,-1,minecraft:obsidian)
B(-7,57,0,minecraft:obsidian)
B(-7,57,1,minecraft:diorite)
B(-7,57,2,minecraft:diorite)
B(-7,57,3,minecraft:diorite)
B(-7,58,-7,minecraft:diorite)
B(-7,58,-6,minecraft:diorite)
B(-7,58,-5,minecraft:obsidian)
B(-7,58,-4,minecraft:obsidian)
B(-7,58,-3,minecraft:obsidian)
B(-7,58,-2,minecraft:obsidian)
B(-7,58,-1,minecraft:obsidian)
B(-7,58,0,minecraft:diorite)
B(-7,58,1,minecraft:diorite)
B(-7,58,2,minecraft:diorite)
B(-7,59,-7,minecraft:diorite)
B(-7,59,-6,minecraft:diorite)
B(-7,59,-5,minecraft:diorite)
B(-7,59,-4,minecraft:obsidian)
B(-7,59,-3,minecraft:obsidian)
B(-7,59,-2,minecraft:obsidian)
B(-7,59,-1,minecraft:diorite)
B(-7,59,0,minecraft:diorite)
B(-7,59,1,minecraft:diorite)
B(-7,60,-7,minecraft:diorite)
B(-7,60,-6,minecraft:diorite)
B(-7,60,-5,minecraft:diorite)
B(-7,60,-4,minecraft:obsidian)
B(-7,60,-3,minecraft:obsidian)
B(-7,60,-2,minecraft:diorite)
B(-7,60,-1,minecraft:diorite)
B(-7,60,0,minecraft:diorite)
B(-7,60,1,minecraft:diorite)
B(-7,61,-7,minecraft:diorite)
B(-7,61,-6,minecraft:diorite)
B(-7,61,-5,minecraft:diorite)
B(-7,61,-4,minecraft:obsidian)
B(-7,61,-3,minecraft:obsidian)
B(-7,61,-2,minecraft:diorite)
B(-7,61,-1,minecraft:diorite)
B(-7,61,0,minecraft:diorite)
B(-7,61,1,minecraft:diorite)
B(-7,62,-7,minecraft:diorite)
B(-7,62,-6,minecraft:diorite)
B(-7,62,-5,minecraft:diorite)
B(-7,62,-4,minecraft:obsidian)
B(-7,62,-3,minecraft:obsidian)
B(-7,62,-2,minecraft:diorite)
B(-7,62,-1,minecraft:diorite)
B(-7,62,0,minecraft:diorite)
B(-7,62,1,minecraft:diorite)
B(-7,63,-7,minecraft:diorite)
B(-7,63,-6,minecraft:diorite)
B(-7,63,-5,minecraft:obsidian)
B(-7,63,-4,minecraft:obsidian)
B(-7,63,-3,minecraft:obsidian)
B(-7,63,-2,minecraft:obsidian)
B(-7,63,-1,minecraft:obsidian)
B(-7,63,0,minecraft:obsidian)
B(-7,63,1,minecraft:obsidian)
B(-7,64,-7,minecraft:diorite)
B(-7,64,-6,minecraft:diorite)
B(-7,64,-5,minecraft:obsidian)
B(-7,64,-4,minecraft:obsidian)
B(-7,64,-3,minecraft:obsidian)
B(-7,64,-2,minecraft:obsidian)
B(-7,64,-1,minecraft:obsidian)
B(-7,64,0,minecraft:obsidian)
B(-7,64,1,minecraft:obsidian)
B(-7,65,-7,minecraft:diorite)
B(-7,65,-6,minecraft:diorite)
B(-7,65,-5,minecraft:diorite)
B(-7,65,-4,minecraft:obsidian)
B(-7,65,-3,minecraft:obsidian)
B(-7,65,-2,minecraft:obsidian)
B(-7,65,-1,minecraft:obsidian)
B(-7,65,0,minecraft:obsidian)
B(-7,65,1,minecraft:obsidian)
B(-7,66,-7,minecraft:diorite)
B(-7,66,-6,minecraft:diorite)
B(-7,66,-5,minecraft:diorite)
B(-7,66,-4,minecraft:obsidian)
B(-7,66,-3,minecraft:obsidian)
B(-7,66,-2,minecraft:obsidian)
B(-7,66,-1,minecraft:obsidian)
B(-7,66,0,minecraft:obsidian)
B(-7,66,1,minecraft:obsidian)
B(-7,67,-7,minecraft:diorite)
B(-7,67,-6,minecraft:diorite)
B(-7,67,-5,minecraft:diorite)
B(-7,67,-4,minecraft:obsidian)
B(-7,67,-3,minecraft:obsidian)
B(-7,67,-2,minecraft:obsidian)
B(-7,67,-1,minecraft:obsidian)
B(-7,67,0,minecraft:obsidian)
B(-7,67,1,minecraft:obsidian)
B(-7,68,-7,minecraft:diorite)
B(-7,68,-6,minecraft:diorite)
B(-7,68,-5,minecraft:obsidian)
B(-7,68,-4,minecraft:obsidian)
B(-7,68,-3,minecraft:obsidian)
B(-7,68,-2,minecraft:obsidian)
B(-7,68,-1,minecraft:obsidian)
B(-7,68,0,minecraft:obsidian)
B(-7,68,1,minecraft:obsidian)
B(-7,68,2,minecraft:obsidian)
B(-7,69,-7,minecraft:diorite)
B(-7,69,-6,minecraft:diorite)
B(-7,69,-5,minecraft:obsidian)
B(-7,69,-4,minecraft:obsidian)
B(-7,69,-3,minecraft:diorite)
B(-7,69,-2,minecraft:diorite)
B(-7,69,-1,minecraft:diorite)
B(-7,69,0,minecraft:obsidian)
B(-7,69,1,minecraft:obsidian)
B(-7,69,2,minecraft:obsidian)
B(-7,70,-7,minecraft:diorite)
B(-7,70,-6,minecraft:obsidian)
B(-7,70,-5,minecraft:obsidian)
B(-7,70,-4,minecraft:diorite)
B(-7,70,-3,minecraft:diorite)
B(-7,70,-2,minecraft:diorite)
B(-7,70,-1,minecraft:diorite)
B(-7,70,0,minecraft:diorite)
B(-7,70,1,minecraft:obsidian)
B(-7,70,2,minecraft:obsidian)
B(-7,71,-7,minecraft:diorite)
B(-7,71,-6,minecraft:diorite)
B(-7,71,-5,minecraft:diorite)
B(-7,71,-4,minecraft:diorite)
B(-7,71,-3,minecraft:diorite)
B(-7,71,-2,minecraft:diorite)
B(-7,71,-1,minecraft:diorite)
B(-7,71,0,minecraft:diorite)
B(-7,71,1,minecraft:obsidian)
B(-7,71,2,minecraft:obsidian)
B(-7,71,3,minecraft:obsidian)
B(-7,72,-7,minecraft:andesite)
B(-7,72,-6,minecraft:diorite)
B(-7,72,-5,minecraft:diorite)
B(-7,72,-4,minecraft:diorite)
B(-7,72,-3,minecraft:diorite)
B(-7,72,-2,minecraft:diorite)
B(-7,72,-1,minecraft:diorite)
B(-7,72,0,minecraft:diorite)
B(-7,72,1,minecraft:obsidian)
B(-7,72,2,minecraft:diorite)
B(-7,72,3,minecraft:diorite)
B(-7,73,-6,minecraft:andesite)
B(-7,73,-5,minecraft:diorite)
B(-7,73,-4,minecraft:obsidian)
B(-7,73,-3,minecraft:diorite)
B(-7,73,-2,minecraft:diorite)
B(-7,73,-1,minecraft:diorite)
B(-7,73,0,minecraft:obsidian)
B(-7,73,1,minecraft:obsidian)
B(-7,73,2,minecraft:diorite)
B(-7,73,3,minecraft:diorite)
B(-7,74,-5,minecraft:andesite)
B(-7,74,-4,minecraft:diorite)
B(-7,74,-3,minecraft:diorite)
B(-7,74,-2,minecraft:obsidian)
B(-7,74,-1,minecraft:obsidian)
B(-7,74,0,minecraft:obsidian)
B(-7,74,1,minecraft:obsidian)
B(-7,74,2,minecraft:diorite)
B(-7,74,3,minecraft:diorite)
B(-7,75,-4,minecraft:diorite)
B(-7,75,-3,minecraft:diorite)
B(-7,75,-2,minecraft:obsidian)
B(-7,75,-1,minecraft:obsidian)
B(-7,75,0,minecraft:obsidian)
B(-7,75,1,minecraft:diorite)
B(-7,75,2,minecraft:diorite)
B(-7,75,3,minecraft:diorite)
B(-7,75,4,minecraft:diorite)
B(-7,76,-4,minecraft:diorite)
B(-7,76,-3,minecraft:diorite)
B(-7,76,-2,minecraft:obsidian)
B(-7,76,-1,minecraft:obsidian)
B(-7,76,0,minecraft:obsidian)
B(-7,76,1,minecraft:diorite)
B(-7,76,2,minecraft:diorite)
B(-7,76,3,minecraft:diorite)
B(-7,76,4,minecraft:diorite)
B(-7,77,-4,minecraft:diorite)
B(-7,77,-3,minecraft:diorite)
B(-7,77,-2,minecraft:diorite)
B(-7,77,-1,minecraft:obsidian)
B(-7,77,0,minecraft:obsidian)
B(-7,77,1,minecraft:diorite)
B(-7,77,2,minecraft:diorite)
B(-7,77,3,minecraft:diorite)
B(-7,77,4,minecraft:diorite)
B(-7,77,5,minecraft:diorite)
B(-7,78,-4,minecraft:andesite)
B(-7,78,-3,minecraft:diorite)
B(-7,78,-2,minecraft:diorite)
B(-7,78,-1,minecraft:diorite)
B(-7,78,0,minecraft:obsidian)
B(-7,78,1,minecraft:obsidian)
B(-7,78,2,minecraft:diorite)
B(-7,78,3,minecraft:diorite)
B(-7,78,4,minecraft:diorite)
B(-7,78,5,minecraft:diorite)
B(-7,78,6,minecraft:diorite)
B(-7,79,-3,minecraft:diorite)
B(-7,79,-2,minecraft:diorite)
B(-7,79,-1,minecraft:diorite)
B(-7,79,0,minecraft:diorite)
B(-7,79,1,minecraft:obsidian)
B(-7,79,2,minecraft:obsidian)
B(-7,79,3,minecraft:obsidian)
B(-7,79,4,minecraft:diorite)
B(-7,79,5,minecraft:diorite)
B(-7,79,6,minecraft:diorite)
B(-7,79,7,minecraft:diorite)
B(-7,79,8,minecraft:diorite)
B(-7,80,-3,minecraft:diorite)
B(-7,80,-2,minecraft:diorite)
B(-7,80,-1,minecraft:diorite)
B(-7,80,0,minecraft:diorite)
B(-7,80,1,minecraft:diorite)
B(-7,80,2,minecraft:diorite)
B(-7,80,3,minecraft:diorite)
B(-7,80,4,minecraft:obsidian)
B(-7,80,5,minecraft:obsidian)
B(-7,80,6,minecraft:diorite)
B(-7,80,7,minecraft:diorite)
B(-7,80,8,minecraft:diorite)
B(-7,81,-3,minecraft:diorite)
B(-7,81,-2,minecraft:diorite)
B(-7,81,-1,minecraft:diorite)
B(-7,81,0,minecraft:diorite)
B(-7,81,1,minecraft:diorite)
B(-7,81,2,minecraft:diorite)
B(-7,81,3,minecraft:diorite)
B(-7,81,4,minecraft:obsidian)
B(-7,81,5,minecraft:obsidian)
B(-7,81,6,minecraft:obsidian)
B(-7,81,7,minecraft:diorite)
B(-7,81,8,minecraft:diorite)
B(-7,82,-2,minecraft:andesite)
B(-7,82,-1,minecraft:diorite)
B(-7,82,0,minecraft:diorite)
B(-7,82,1,minecraft:diorite)
B(-7,82,2,minecraft:diorite)
B(-7,82,3,minecraft:diorite)
B(-7,82,4,minecraft:diorite)
B(-7,82,5,minecraft:diorite)
B(-7,82,6,minecraft:obsidian)
B(-7,82,7,minecraft:obsidian)
B(-7,82,8,minecraft:diorite)
B(-7,83,-1,minecraft:andesite)
B(-7,83,0,minecraft:diorite)
B(-7,83,1,minecraft:diorite)
B(-7,83,2,minecraft:diorite)
B(-7,83,3,minecraft:diorite)
B(-7,83,4,minecraft:diorite)
B(-7,83,5,minecraft:diorite)
B(-7,83,6,minecraft:diorite)
B(-7,83,7,minecraft:diorite)
B(-7,83,8,minecraft:obsidian)
B(-7,84,0,minecraft:andesite)
B(-7,84,1,minecraft:diorite)
B(-7,84,2,minecraft:diorite)
B(-7,84,3,minecraft:diorite)
B(-7,84,4,minecraft:diorite)
B(-7,84,5,minecraft:diorite)
B(-7,84,6,minecraft:diorite)
B(-7,84,7,minecraft:diorite)
B(-7,84,8,minecraft:diorite)
B(-7,85,1,minecraft:diorite)
B(-7,85,2,minecraft:diorite)
B(-7,85,3,minecraft:diorite)
B(-7,85,4,minecraft:diorite)
B(-7,85,5,minecraft:diorite)
B(-7,85,6,minecraft:diorite)
B(-7,85,7,minecraft:diorite)
B(-7,85,8,minecraft:diorite)
B(-7,86,2,minecraft:diorite)
B(-7,86,3,minecraft:diorite)
B(-7,86,4,minecraft:diorite)
B(-7,86,5,minecraft:diorite)
B(-7,86,6,minecraft:diorite)
B(-7,86,7,minecraft:diorite)
B(-7,86,8,minecraft:diorite)
B(-7,87,1,minecraft:diorite)
B(-7,87,2,minecraft:diorite)
B(-7,87,3,minecraft:diorite)
B(-7,87,4,minecraft:diorite)
B(-7,87,5,minecraft:diorite)
B(-7,87,6,minecraft:diorite)
B(-7,87,7,minecraft:diorite)
B(-7,87,8,minecraft:diorite)
B(-7,88,1,minecraft:andesite)
B(-7,88,2,minecraft:diorite)
B(-7,88,3,minecraft:diorite)
B(-7,88,4,minecraft:diorite)
B(-7,88,5,minecraft:diorite)
B(-7,88,6,minecraft:diorite)
B(-7,88,7,minecraft:diorite)
B(-7,88,8,minecraft:diorite)
B(-7,89,2,minecraft:andesite)
B(-7,89,3,minecraft:andesite)
B(-7,89,4,minecraft:diorite)
B(-7,89,5,minecraft:diorite)
B(-7,89,6,minecraft:diorite)
B(-7,89,7,minecraft:diorite)
B(-7,89,8,minecraft:obsidian)
B(-7,90,4,minecraft:andesite)
B(-7,90,5,minecraft:andesite)
B(-7,90,6,minecraft:andesite)
B(-7,90,7,minecraft:andesite)
B(-7,90,8,minecraft:diorite)
B(-7,91,8,minecraft:andesite)
B(-6,32,8,minecraft:diorite)
B(-6,33,7,minecraft:diorite)
B(-6,33,8,minecraft:diorite)
B(-6,34,4,minecraft:diorite)
B(-6,34,5,minecraft:diorite)
B(-6,34,6,minecraft:diorite)
B(-6,34,7,minecraft:diorite)
B(-6,34,8,minecraft:diorite)
B(-6,35,4,minecraft:diorite)
B(-6,35,5,minecraft:diorite)
B(-6,35,6,minecraft:diorite)
B(-6,35,7,minecraft:diorite)
B(-6,35,8,minecraft:diorite)
B(-6,36,4,minecraft:diorite)
B(-6,36,5,minecraft:diorite)
B(-6,36,6,minecraft:diorite)
B(-6,36,7,minecraft:diorite)
B(-6,36,8,minecraft:diorite)
B(-6,37,4,minecraft:diorite)
B(-6,37,5,minecraft:diorite)
B(-6,37,6,minecraft:diorite)
B(-6,37,7,minecraft:diorite)
B(-6,37,8,minecraft:diorite)
B(-6,38,4,minecraft:diorite)
B(-6,38,5,minecraft:diorite)
B(-6,38,6,minecraft:diorite)
B(-6,38,7,minecraft:diorite)
B(-6,38,8,minecraft:diorite)
B(-6,39,3,minecraft:diorite)
B(-6,39,4,minecraft:diorite)
B(-6,39,5,minecraft:diorite)
B(-6,39,6,minecraft:diorite)
B(-6,39,7,minecraft:diorite)
B(-6,39,8,minecraft:diorite)
B(-6,40,3,minecraft:diorite)
B(-6,40,4,minecraft:diorite)
B(-6,40,5,minecraft:diorite)
B(-6,40,6,minecraft:diorite)
B(-6,40,7,minecraft:diorite)
B(-6,40,8,minecraft:diorite)
B(-6,41,2,minecraft:diorite)
B(-6,41,3,minecraft:diorite)
B(-6,41,4,minecraft:diorite)
B(-6,41,5,minecraft:diorite)
B(-6,41,6,minecraft:diorite)
B(-6,41,7,minecraft:diorite)
B(-6,41,8,minecraft:diorite)
B(-6,42,2,minecraft:diorite)
B(-6,42,3,minecraft:diorite)
B(-6,42,4,minecraft:diorite)
B(-6,42,5,minecraft:diorite)
B(-6,42,6,minecraft:diorite)
B(-6,42,7,minecraft:diorite)
B(-6,42,8,minecraft:diorite)
B(-6,43,1,minecraft:diorite)
B(-6,43,2,minecraft:diorite)
B(-6,43,3,minecraft:diorite)
B(-6,43,4,minecraft:diorite)
B(-6,43,5,minecraft:diorite)
B(-6,43,6,minecraft:diorite)
B(-6,43,7,minecraft:diorite)
B(-6,43,8,minecraft:obsidian)
B(-6,44,1,minecraft:diorite)
B(-6,44,2,minecraft:diorite)
B(-6,44,3,minecraft:diorite)
B(-6,44,4,minecraft:diorite)
B(-6,44,5,minecraft:diorite)
B(-6,44,6,minecraft:diorite)
B(-6,44,7,minecraft:diorite)
B(-6,44,8,minecraft:obsidian)
B(-6,45,1,minecraft:diorite)
B(-6,45,2,minecraft:diorite)
B(-6,45,3,minecraft:diorite)
B(-6,45,4,minecraft:diorite)
B(-6,45,5,minecraft:diorite)
B(-6,45,6,minecraft:obsidian)
B(-6,45,7,minecraft:obsidian)
B(-6,45,8,minecraft:obsidian)
B(-6,46,-1,minecraft:diorite)
B(-6,46,0,minecraft:diorite)
B(-6,46,1,minecraft:diorite)
B(-6,46,2,minecraft:diorite)
B(-6,46,3,minecraft:diorite)
B(-6,46,4,minecraft:diorite)
B(-6,46,5,minecraft:diorite)
B(-6,46,6,minecraft:obsidian)
B(-6,46,7,minecraft:obsidian)
B(-6,46,8,minecraft:obsidian)
B(-6,47,-1,minecraft:obsidian)
B(-6,47,0,minecraft:obsidian)
B(-6,47,1,minecraft:diorite)
B(-6,47,2,minecraft:diorite)
B(-6,47,3,minecraft:diorite)
B(-6,47,4,minecraft:diorite)
B(-6,47,5,minecraft:diorite)
B(-6,47,6,minecraft:diorite)
B(-6,47,7,minecraft:obsidian)
B(-6,47,8,minecraft:obsidian)
B(-6,48,-4,minecraft:magma_block)
B(-6,48,-3,minecraft:magma_block)
B(-6,48,-2,minecraft:magma_block)
B(-6,48,-1,minecraft:obsidian)
B(-6,48,0,minecraft:obsidian)
B(-6,48,1,minecraft:obsidian)
B(-6,48,2,minecraft:diorite)
B(-6,48,3,minecraft:diorite)
B(-6,48,4,minecraft:diorite)
B(-6,48,5,minecraft:diorite)
B(-6,48,6,minecraft:diorite)
B(-6,48,7,minecraft:diorite)
B(-6,48,8,minecraft:obsidian)
B(-6,49,-3,minecraft:magma_block)
B(-6,49,-2,minecraft:magma_block)
B(-6,49,-1,minecraft:magma_block)
B(-6,49,0,minecraft:obsidian)
B(-6,49,1,minecraft:obsidian)
B(-6,49,2,minecraft:obsidian)
B(-6,49,3,minecraft:diorite)
B(-6,49,4,minecraft:diorite)
B(-6,49,5,minecraft:diorite)
B(-6,49,6,minecraft:diorite)
B(-6,49,7,minecraft:diorite)
B(-6,49,8,minecraft:obsidian)
B(-6,50,-3,minecraft:magma_block)
B(-6,50,-2,minecraft:magma_block)
B(-6,50,-1,minecraft:magma_block)
B(-6,50,0,minecraft:magma_block)
B(-6,50,1,minecraft:obsidian)
B(-6,50,2,minecraft:obsidian)
B(-6,50,3,minecraft:diorite)
B(-6,50,4,minecraft:diorite)
B(-6,50,5,minecraft:diorite)
B(-6,50,6,minecraft:diorite)
B(-6,50,7,minecraft:andesite)
B(-6,51,-2,minecraft:magma_block)
B(-6,51,-1,minecraft:magma_block)
B(-6,51,0,minecraft:magma_block)
B(-6,51,1,minecraft:obsidian)
B(-6,51,2,minecraft:obsidian)
B(-6,51,3,minecraft:obsidian)
B(-6,51,4,minecraft:diorite)
B(-6,51,5,minecraft:diorite)
B(-6,51,6,minecraft:diorite)
B(-6,52,-2,minecraft:magma_block)
B(-6,52,-1,minecraft:magma_block)
B(-6,52,0,minecraft:magma_block)
B(-6,52,1,minecraft:obsidian)
B(-6,52,2,minecraft:obsidian)
B(-6,52,3,minecraft:obsidian)
B(-6,52,4,minecraft:diorite)
B(-6,52,5,minecraft:diorite)
B(-6,52,6,minecraft:andesite)
B(-6,53,-3,minecraft:magma_block)
B(-6,53,-2,minecraft:magma_block)
B(-6,53,-1,minecraft:magma_block)
B(-6,53,0,minecraft:obsidian)
B(-6,53,1,minecraft:obsidian)
B(-6,53,2,minecraft:obsidian)
B(-6,53,3,minecraft:obsidian)
B(-6,53,4,minecraft:diorite)
B(-6,53,5,minecraft:diorite)
B(-6,54,-4,minecraft:obsidian)
B(-6,54,-3,minecraft:obsidian)
B(-6,54,-2,minecraft:obsidian)
B(-6,54,-1,minecraft:obsidian)
B(-6,54,0,minecraft:obsidian)
B(-6,54,1,minecraft:obsidian)
B(-6,54,2,minecraft:obsidian)
B(-6,54,3,minecraft:obsidian)
B(-6,54,4,minecraft:diorite)
B(-6,54,5,minecraft:andesite)
B(-6,55,-4,minecraft:obsidian)
B(-6,55,-3,minecraft:obsidian)
B(-6,55,-2,minecraft:obsidian)
B(-6,55,-1,minecraft:obsidian)
B(-6,55,0,minecraft:obsidian)
B(-6,55,1,minecraft:obsidian)
B(-6,55,2,minecraft:obsidian)
B(-6,55,3,minecraft:obsidian)
B(-6,55,4,minecraft:diorite)
B(-6,56,-5,minecraft:obsidian)
B(-6,56,-4,minecraft:obsidian)
B(-6,56,-3,minecraft:obsidian)
B(-6,56,-2,minecraft:obsidian)
B(-6,56,-1,minecraft:obsidian)
B(-6,56,0,minecraft:obsidian)
B(-6,56,1,minecraft:obsidian)
B(-6,56,2,minecraft:obsidian)
B(-6,56,3,minecraft:obsidian)
B(-6,56,4,minecraft:diorite)
B(-6,57,-7,minecraft:diorite)
B(-6,57,-6,minecraft:diorite)
B(-6,57,-5,minecraft:diorite)
B(-6,57,-4,minecraft:obsidian)
B(-6,57,-3,minecraft:obsidian)
B(-6,57,-2,minecraft:obsidian)
B(-6,57,-1,minecraft:obsidian)
B(-6,57,0,minecraft:obsidian)
B(-6,57,1,minecraft:diorite)
B(-6,57,2,minecraft:diorite)
B(-6,57,3,minecraft:diorite)
B(-6,58,-7,minecraft:diorite)
B(-6,58,-6,minecraft:diorite)
B(-6,58,-5,minecraft:diorite)
B(-6,58,-4,minecraft:obsidian)
B(-6,58,-3,minecraft:obsidian)
B(-6,58,-2,minecraft:obsidian)
B(-6,58,-1,minecraft:obsidian)
B(-6,58,0,minecraft:diorite)
B(-6,58,1,minecraft:diorite)
B(-6,58,2,minecraft:diorite)
B(-6,58,3,minecraft:diorite)
B(-6,59,-7,minecraft:diorite)
B(-6,59,-6,minecraft:diorite)
B(-6,59,-5,minecraft:diorite)
B(-6,59,-4,minecraft:obsidian)
B(-6,59,-3,minecraft:obsidian)
B(-6,59,-2,minecraft:obsidian)
B(-6,59,-1,minecraft:diorite)
B(-6,59,0,minecraft:diorite)
B(-6,59,1,minecraft:diorite)
B(-6,59,2,minecraft:diorite)
B(-6,60,-7,minecraft:diorite)
B(-6,60,-6,minecraft:diorite)
B(-6,60,-5,minecraft:diorite)
B(-6,60,-4,minecraft:diorite)
B(-6,60,-3,minecraft:obsidian)
B(-6,60,-2,minecraft:obsidian)
B(-6,60,-1,minecraft:diorite)
B(-6,60,0,minecraft:diorite)
B(-6,60,1,minecraft:diorite)
B(-6,60,2,minecraft:diorite)
B(-6,61,-7,minecraft:diorite)
B(-6,61,-6,minecraft:diorite)
B(-6,61,-5,minecraft:diorite)
B(-6,61,-4,minecraft:diorite)
B(-6,61,-3,minecraft:obsidian)
B(-6,61,-2,minecraft:obsidian)
B(-6,61,-1,minecraft:diorite)
B(-6,61,0,minecraft:diorite)
B(-6,61,1,minecraft:diorite)
B(-6,62,-7,minecraft:diorite)
B(-6,62,-6,minecraft:diorite)
B(-6,62,-5,minecraft:diorite)
B(-6,62,-4,minecraft:diorite)
B(-6,62,-3,minecraft:obsidian)
B(-6,62,-2,minecraft:obsidian)
B(-6,62,-1,minecraft:obsidian)
B(-6,62,0,minecraft:diorite)
B(-6,62,1,minecraft:diorite)
B(-6,63,-7,minecraft:diorite)
B(-6,63,-6,minecraft:diorite)
B(-6,63,-5,minecraft:diorite)
B(-6,63,-4,minecraft:obsidian)
B(-6,63,-3,minecraft:obsidian)
B(-6,63,-2,minecraft:obsidian)
B(-6,63,-1,minecraft:obsidian)
B(-6,63,0,minecraft:obsidian)
B(-6,63,1,minecraft:obsidian)
B(-6,64,-7,minecraft:diorite)
B(-6,64,-6,minecraft:diorite)
B(-6,64,-5,minecraft:obsidian)
B(-6,64,-4,minecraft:obsidian)
B(-6,64,-3,minecraft:obsidian)
B(-6,64,-2,minecraft:obsidian)
B(-6,64,-1,minecraft:obsidian)
B(-6,64,0,minecraft:obsidian)
B(-6,64,1,minecraft:obsidian)
B(-6,65,-7,minecraft:diorite)
B(-6,65,-6,minecraft:diorite)
B(-6,65,-5,minecraft:obsidian)
B(-6,65,-4,minecraft:obsidian)
B(-6,65,-3,minecraft:obsidian)
B(-6,65,-2,minecraft:obsidian)
B(-6,65,-1,minecraft:obsidian)
B(-6,65,0,minecraft:obsidian)
B(-6,65,1,minecraft:obsidian)
B(-6,66,-7,minecraft:diorite)
B(-6,66,-6,minecraft:diorite)
B(-6,66,-5,minecraft:obsidian)
B(-6,66,-4,minecraft:obsidian)
B(-6,66,-3,minecraft:obsidian)
B(-6,66,-2,minecraft:obsidian)
B(-6,66,-1,minecraft:obsidian)
B(-6,66,0,minecraft:obsidian)
B(-6,66,1,minecraft:obsidian)
B(-6,66,2,minecraft:obsidian)
B(-6,67,-7,minecraft:diorite)
B(-6,67,-6,minecraft:diorite)
B(-6,67,-5,minecraft:obsidian)
B(-6,67,-4,minecraft:obsidian)
B(-6,67,-3,minecraft:obsidian)
B(-6,67,-2,minecraft:obsidian)
B(-6,67,-1,minecraft:obsidian)
B(-6,67,0,minecraft:obsidian)
B(-6,67,1,minecraft:obsidian)
B(-6,67,2,minecraft:obsidian)
B(-6,68,-7,minecraft:diorite)
B(-6,68,-6,minecraft:diorite)
B(-6,68,-5,minecraft:obsidian)
B(-6,68,-4,minecraft:obsidian)
B(-6,68,-3,minecraft:obsidian)
B(-6,68,-2,minecraft:obsidian)
B(-6,68,-1,minecraft:obsidian)
B(-6,68,0,minecraft:obsidian)
B(-6,68,1,minecraft:obsidian)
B(-6,68,2,minecraft:obsidian)
B(-6,69,-7,minecraft:diorite)
B(-6,69,-6,minecraft:obsidian)
B(-6,69,-5,minecraft:obsidian)
B(-6,69,-4,minecraft:obsidian)
B(-6,69,-3,minecraft:obsidian)
B(-6,69,-2,minecraft:obsidian)
B(-6,69,-1,minecraft:obsidian)
B(-6,69,0,minecraft:obsidian)
B(-6,69,1,minecraft:obsidian)
B(-6,69,2,minecraft:obsidian)
B(-6,69,3,minecraft:obsidian)
B(-6,70,-7,minecraft:obsidian)
B(-6,70,-6,minecraft:obsidian)
B(-6,70,-5,minecraft:obsidian)
B(-6,70,-4,minecraft:obsidian)
B(-6,70,-3,minecraft:diorite)
B(-6,70,-2,minecraft:diorite)
B(-6,70,-1,minecraft:diorite)
B(-6,70,0,minecraft:obsidian)
B(-6,70,1,minecraft:obsidian)
B(-6,70,2,minecraft:obsidian)
B(-6,70,3,minecraft:obsidian)
B(-6,71,-7,minecraft:obsidian)
B(-6,71,-6,minecraft:obsidian)
B(-6,71,-5,minecraft:obsidian)
B(-6,71,-4,minecraft:obsidian)
B(-6,71,-3,minecraft:diorite)
B(-6,71,-2,minecraft:diorite)
B(-6,71,-1,minecraft:diorite)
B(-6,71,0,minecraft:obsidian)
B(-6,71,1,minecraft:obsidian)
B(-6,71,2,minecraft:obsidian)
B(-6,71,3,minecraft:obsidian)
B(-6,72,-7,minecraft:diorite)
B(-6,72,-6,minecraft:diorite)
B(-6,72,-5,minecraft:diorite)
B(-6,72,-4,minecraft:diorite)
B(-6,72,-3,minecraft:diorite)
B(-6,72,-2,minecraft:diorite)
B(-6,72,-1,minecraft:diorite)
B(-6,72,0,minecraft:obsidian)
B(-6,72,1,minecraft:obsidian)
B(-6,72,2,minecraft:obsidian)
B(-6,72,3,minecraft:obsidian)
B(-6,73,-7,minecraft:andesite)
B(-6,73,-6,minecraft:diorite)
B(-6,73,-5,minecraft:diorite)
B(-6,73,-4,minecraft:diorite)
B(-6,73,-3,minecraft:obsidian)
B(-6,73,-2,minecraft:obsidian)
B(-6,73,-1,minecraft:obsidian)
B(-6,73,0,minecraft:obsidian)
B(-6,73,1,minecraft:obsidian)
B(-6,73,2,minecraft:obsidian)
B(-6,73,3,minecraft:diorite)
B(-6,73,4,minecraft:diorite)
B(-6,74,-6,minecraft:andesite)
B(-6,74,-5,minecraft:diorite)
B(-6,74,-4,minecraft:diorite)
B(-6,74,-3,minecraft:obsidian)
B(-6,74,-2,minecraft:obsidian)
B(-6,74,-1,minecraft:obsidian)
B(-6,74,0,minecraft:obsidian)
B(-6,74,1,minecraft:obsidian)
B(-6,74,2,minecraft:diorite)
B(-6,74,3,minecraft:diorite)
B(-6,74,4,minecraft:andesite)
B(-6,75,-5,minecraft:andesite)
B(-6,75,-4,minecraft:diorite)
B(-6,75,-3,minecraft:diorite)
B(-6,75,-2,minecraft:obsidian)
B(-6,75,-1,minecraft:obsidian)
B(-6,75,0,minecraft:obsidian)
B(-6,75,1,minecraft:diorite)
B(-6,75,2,minecraft:diorite)
B(-6,75,3,minecraft:diorite)
B(-6,76,-4,minecraft:diorite)
B(-6,76,-3,minecraft:diorite)
B(-6,76,-2,minecraft:obsidian)
B(-6,76,-1,minecraft:obsidian)
B(-6,76,0,minecraft:obsidian)
B(-6,76,1,minecraft:diorite)
B(-6,76,2,minecraft:diorite)
B(-6,76,3,minecraft:diorite)
B(-6,77,-4,minecraft:andesite)
B(-6,77,-3,minecraft:diorite)
B(-6,77,-2,minecraft:diorite)
B(-6,77,-1,minecraft:obsidian)
B(-6,77,0,minecraft:obsidian)
B(-6,77,1,minecraft:diorite)
B(-6,77,2,minecraft:diorite)
B(-6,77,3,minecraft:diorite)
B(-6,77,4,minecraft:diorite)
B(-6,77,5,minecraft:diorite)
B(-6,77,6,minecraft:diorite)
B(-6,78,-3,minecraft:diorite)
B(-6,78,-2,minecraft:diorite)
B(-6,78,-1,minecraft:diorite)
B(-6,78,0,minecraft:obsidian)
B(-6,78,1,minecraft:obsidian)
B(-6,78,2,minecraft:diorite)
B(-6,78,3,minecraft:diorite)
B(-6,78,4,minecraft:diorite)
B(-6,78,5,minecraft:diorite)
B(-6,78,6,minecraft:diorite)
B(-6,78,7,minecraft:diorite)
B(-6,79,-3,minecraft:diorite)
B(-6,79,-2,minecraft:diorite)
B(-6,79,-1,minecraft:diorite)
B(-6,79,0,minecraft:diorite)
B(-6,79,1,minecraft:diorite)
B(-6,79,2,minecraft:diorite)
B(-6,79,3,minecraft:diorite)
B(-6,79,4,minecraft:diorite)
B(-6,79,5,minecraft:diorite)
B(-6,79,6,minecraft:diorite)
B(-6,79,7,minecraft:diorite)
B(-6,79,8,minecraft:diorite)
B(-6,80,-3,minecraft:diorite)
B(-6,80,-2,minecraft:diorite)
B(-6,80,-1,minecraft:diorite)
B(-6,80,0,minecraft:diorite)
B(-6,80,1,minecraft:diorite)
B(-6,80,2,minecraft:diorite)
B(-6,80,3,minecraft:diorite)
B(-6,80,4,minecraft:obsidian)
B(-6,80,5,minecraft:obsidian)
B(-6,80,6,minecraft:diorite)
B(-6,80,7,minecraft:diorite)
B(-6,80,8,minecraft:diorite)
B(-6,81,-3,minecraft:diorite)
B(-6,81,-2,minecraft:diorite)
B(-6,81,-1,minecraft:diorite)
B(-6,81,0,minecraft:diorite)
B(-6,81,1,minecraft:diorite)
B(-6,81,2,minecraft:diorite)
B(-6,81,3,minecraft:diorite)
B(-6,81,4,minecraft:diorite)
B(-6,81,5,minecraft:obsidian)
B(-6,81,6,minecraft:obsidian)
B(-6,81,7,minecraft:diorite)
B(-6,81,8,minecraft:diorite)
B(-6,82,-3,minecraft:diorite)
B(-6,82,-2,minecraft:diorite)
B(-6,82,-1,minecraft:diorite)
B(-6,82,0,minecraft:diorite)
B(-6,82,1,minecraft:diorite)
B(-6,82,2,minecraft:diorite)
B(-6,82,3,minecraft:diorite)
B(-6,82,4,minecraft:diorite)
B(-6,82,5,minecraft:diorite)
B(-6,82,6,minecraft:diorite)
B(-6,82,7,minecraft:diorite)
B(-6,82,8,minecraft:diorite)
B(-6,83,-2,minecraft:andesite)
B(-6,83,-1,minecraft:diorite)
B(-6,83,0,minecraft:diorite)
B(-6,83,1,minecraft:diorite)
B(-6,83,2,minecraft:diorite)
B(-6,83,3,minecraft:diorite)
B(-6,83,4,minecraft:diorite)
B(-6,83,5,minecraft:diorite)
B(-6,83,6,minecraft:diorite)
B(-6,83,7,minecraft:diorite)
B(-6,83,8,minecraft:diorite)
B(-6,84,-1,minecraft:andesite)
B(-6,84,0,minecraft:andesite)
B(-6,84,1,minecraft:andesite)
B(-6,84,2,minecraft:diorite)
B(-6,84,3,minecraft:diorite)
B(-6,84,4,minecraft:diorite)
B(-6,84,5,minecraft:diorite)
B(-6,84,6,minecraft:diorite)
B(-6,84,7,minecraft:diorite)
B(-6,84,8,minecraft:diorite)
B(-6,85,2,minecraft:diorite)
B(-6,85,3,minecraft:diorite)
B(-6,85,4,minecraft:diorite)
B(-6,85,5,minecraft:diorite)
B(-6,85,6,minecraft:diorite)
B(-6,85,7,minecraft:diorite)
B(-6,85,8,minecraft:diorite)
B(-6,86,2,minecraft:diorite)
B(-6,86,3,minecraft:diorite)
B(-6,86,4,minecraft:diorite)
B(-6,86,5,minecraft:diorite)
B(-6,86,6,minecraft:diorite)
B(-6,86,7,minecraft:diorite)
B(-6,86,8,minecraft:diorite)
B(-6,87,2,minecraft:diorite)
B(-6,87,3,minecraft:diorite)
B(-6,87,4,minecraft:diorite)
B(-6,87,5,minecraft:diorite)
B(-6,87,6,minecraft:diorite)
B(-6,87,7,minecraft:diorite)
B(-6,87,8,minecraft:diorite)
B(-6,88,2,minecraft:andesite)
B(-6,88,3,minecraft:diorite)
B(-6,88,4,minecraft:diorite)
B(-6,88,5,minecraft:diorite)
B(-6,88,6,minecraft:diorite)
B(-6,88,7,minecraft:diorite)
B(-6,88,8,minecraft:diorite)
B(-6,89,3,minecraft:andesite)
B(-6,89,4,minecraft:andesite)
B(-6,89,5,minecraft:diorite)
B(-6,89,6,minecraft:diorite)
B(-6,89,7,minecraft:diorite)
B(-6,89,8,minecraft:diorite)
B(-6,90,5,minecraft:andesite)
B(-6,90,6,minecraft:andesite)
B(-6,90,7,minecraft:andesite)
B(-6,90,8,minecraft:diorite)
B(-6,91,8,minecraft:andesite)
B(-5,33,8,minecraft:diorite)
B(-5,34,5,minecraft:diorite)
B(-5,34,6,minecraft:diorite)
B(-5,34,7,minecraft:diorite)
B(-5,34,8,minecraft:diorite)
B(-5,35,4,minecraft:diorite)
B(-5,35,5,minecraft:diorite)
B(-5,35,6,minecraft:diorite)
B(-5,35,7,minecraft:diorite)
B(-5,35,8,minecraft:diorite)
B(-5,36,5,minecraft:diorite)
B(-5,36,6,minecraft:diorite)
B(-5,36,7,minecraft:diorite)
B(-5,36,8,minecraft:diorite)
B(-5,37,5,minecraft:diorite)
B(-5,37,6,minecraft:diorite)
B(-5,37,7,minecraft:diorite)
B(-5,37,8,minecraft:diorite)
B(-5,38,4,minecraft:diorite)
B(-5,38,5,minecraft:diorite)
B(-5,38,6,minecraft:diorite)
B(-5,38,7,minecraft:diorite)
B(-5,38,8,minecraft:diorite)
B(-5,39,4,minecraft:diorite)
B(-5,39,5,minecraft:diorite)
B(-5,39,6,minecraft:diorite)
B(-5,39,7,minecraft:diorite)
B(-5,39,8,minecraft:diorite)
B(-5,40,3,minecraft:diorite)
B(-5,40,4,minecraft:diorite)
B(-5,40,5,minecraft:diorite)
B(-5,40,6,minecraft:diorite)
B(-5,40,7,minecraft:diorite)
B(-5,40,8,minecraft:diorite)
B(-5,41,2,minecraft:diorite)
B(-5,41,3,minecraft:diorite)
B(-5,41,4,minecraft:diorite)
B(-5,41,5,minecraft:diorite)
B(-5,41,6,minecraft:diorite)
B(-5,41,7,minecraft:diorite)
B(-5,41,8,minecraft:diorite)
B(-5,42,2,minecraft:diorite)
B(-5,42,3,minecraft:diorite)
B(-5,42,4,minecraft:diorite)
B(-5,42,5,minecraft:diorite)
B(-5,42,6,minecraft:diorite)
B(-5,42,7,minecraft:diorite)
B(-5,42,8,minecraft:diorite)
B(-5,43,1,minecraft:diorite)
B(-5,43,2,minecraft:diorite)
B(-5,43,3,minecraft:diorite)
B(-5,43,4,minecraft:diorite)
B(-5,43,5,minecraft:diorite)
B(-5,43,6,minecraft:diorite)
B(-5,43,7,minecraft:diorite)
B(-5,43,8,minecraft:obsidian)
B(-5,44,0,minecraft:diorite)
B(-5,44,1,minecraft:diorite)
B(-5,44,2,minecraft:diorite)
B(-5,44,3,minecraft:diorite)
B(-5,44,4,minecraft:diorite)
B(-5,44,5,minecraft:diorite)
B(-5,44,6,minecraft:diorite)
B(-5,44,7,minecraft:diorite)
B(-5,44,8,minecraft:obsidian)
B(-5,45,0,minecraft:diorite)
B(-5,45,1,minecraft:diorite)
B(-5,45,2,minecraft:diorite)
B(-5,45,3,minecraft:diorite)
B(-5,45,4,minecraft:diorite)
B(-5,45,5,minecraft:diorite)
B(-5,45,6,minecraft:diorite)
B(-5,45,7,minecraft:obsidian)
B(-5,45,8,minecraft:obsidian)
B(-5,46,0,minecraft:obsidian)
B(-5,46,1,minecraft:diorite)
B(-5,46,2,minecraft:diorite)
B(-5,46,3,minecraft:diorite)
B(-5,46,4,minecraft:diorite)
B(-5,46,5,minecraft:diorite)
B(-5,46,6,minecraft:obsidian)
B(-5,46,7,minecraft:obsidian)
B(-5,46,8,minecraft:obsidian)
B(-5,47,-1,minecraft:obsidian)
B(-5,47,0,minecraft:obsidian)
B(-5,47,1,minecraft:obsidian)
B(-5,47,2,minecraft:diorite)
B(-5,47,3,minecraft:diorite)
B(-5,47,4,minecraft:diorite)
B(-5,47,5,minecraft:obsidian)
B(-5,47,6,minecraft:obsidian)
B(-5,47,7,minecraft:obsidian)
B(-5,47,8,minecraft:obsidian)
B(-5,48,-2,minecraft:magma_block)
B(-5,48,-1,minecraft:obsidian)
B(-5,48,0,minecraft:obsidian)
B(-5,48,1,minecraft:obsidian)
B(-5,48,2,minecraft:obsidian)
B(-5,48,3,minecraft:diorite)
B(-5,48,4,minecraft:diorite)
B(-5,48,5,minecraft:diorite)
B(-5,48,6,minecraft:diorite)
B(-5,48,7,minecraft:obsidian)
B(-5,48,8,minecraft:obsidian)
B(-5,49,-3,minecraft:magma_block)
B(-5,49,-2,minecraft:magma_block)
B(-5,49,-1,minecraft:magma_block)
B(-5,49,0,minecraft:obsidian)
B(-5,49,1,minecraft:obsidian)
B(-5,49,2,minecraft:obsidian)
B(-5,49,3,minecraft:obsidian)
B(-5,49,4,minecraft:diorite)
B(-5,49,5,minecraft:diorite)
B(-5,49,6,minecraft:diorite)
B(-5,49,7,minecraft:obsidian)
B(-5,49,8,minecraft:obsidian)
B(-5,50,-2,minecraft:magma_block)
B(-5,50,-1,minecraft:magma_block)
B(-5,50,0,minecraft:magma_block)
B(-5,50,1,minecraft:obsidian)
B(-5,50,2,minecraft:obsidian)
B(-5,50,3,minecraft:obsidian)
B(-5,50,4,minecraft:diorite)
B(-5,50,5,minecraft:diorite)
B(-5,50,6,minecraft:diorite)
B(-5,50,7,minecraft:diorite)
B(-5,50,8,minecraft:obsidian)
B(-5,51,-2,minecraft:magma_block)
B(-5,51,-1,minecraft:magma_block)
B(-5,51,0,minecraft:magma_block)
B(-5,51,1,minecraft:obsidian)
B(-5,51,2,minecraft:obsidian)
B(-5,51,3,minecraft:obsidian)
B(-5,51,4,minecraft:diorite)
B(-5,51,5,minecraft:diorite)
B(-5,51,6,minecraft:diorite)
B(-5,51,7,minecraft:diorite)
B(-5,52,-3,minecraft:magma_block)
B(-5,52,-2,minecraft:magma_block)
B(-5,52,-1,minecraft:magma_block)
B(-5,52,0,minecraft:magma_block)
B(-5,52,1,minecraft:obsidian)
B(-5,52,2,minecraft:obsidian)
B(-5,52,3,minecraft:obsidian)
B(-5,52,4,minecraft:diorite)
B(-5,52,5,minecraft:diorite)
B(-5,52,6,minecraft:diorite)
B(-5,52,7,minecraft:andesite)
B(-5,53,-3,minecraft:magma_block)
B(-5,53,-2,minecraft:magma_block)
B(-5,53,-1,minecraft:magma_block)
B(-5,53,0,minecraft:obsidian)
B(-5,53,1,minecraft:obsidian)
B(-5,53,2,minecraft:obsidian)
B(-5,53,3,minecraft:obsidian)
B(-5,53,4,minecraft:diorite)
B(-5,53,5,minecraft:diorite)
B(-5,53,6,minecraft:diorite)
B(-5,54,-3,minecraft:obsidian)
B(-5,54,-2,minecraft:obsidian)
B(-5,54,-1,minecraft:obsidian)
B(-5,54,0,minecraft:obsidian)
B(-5,54,1,minecraft:obsidian)
B(-5,54,2,minecraft:obsidian)
B(-5,54,3,minecraft:obsidian)
B(-5,54,4,minecraft:diorite)
B(-5,54,5,minecraft:diorite)
B(-5,54,6,minecraft:diorite)
B(-5,55,-4,minecraft:obsidian)
B(-5,55,-3,minecraft:obsidian)
B(-5,55,-2,minecraft:obsidian)
B(-5,55,-1,minecraft:obsidian)
B(-5,55,0,minecraft:obsidian)
B(-5,55,1,minecraft:obsidian)
B(-5,55,2,minecraft:obsidian)
B(-5,55,3,minecraft:obsidian)
B(-5,55,4,minecraft:diorite)
B(-5,55,5,minecraft:diorite)
B(-5,56,-5,minecraft:diorite)
B(-5,56,-4,minecraft:diorite)
B(-5,56,-3,minecraft:obsidian)
B(-5,56,-2,minecraft:obsidian)
B(-5,56,-1,minecraft:obsidian)
B(-5,56,0,minecraft:obsidian)
B(-5,56,1,minecraft:obsidian)
B(-5,56,2,minecraft:obsidian)
B(-5,56,3,minecraft:diorite)
B(-5,56,4,minecraft:diorite)
B(-5,56,5,minecraft:andesite)
B(-5,56,6,minecraft:andesite)
B(-5,57,-7,minecraft:diorite)
B(-5,57,-6,minecraft:diorite)
B(-5,57,-5,minecraft:diorite)
B(-5,57,-4,minecraft:diorite)
B(-5,57,-3,minecraft:obsidian)
B(-5,57,-2,minecraft:obsidian)
B(-5,57,-1,minecraft:obsidian)
B(-5,57,0,minecraft:obsidian)
B(-5,57,1,minecraft:diorite)
B(-5,57,2,minecraft:diorite)
B(-5,57,3,minecraft:diorite)
B(-5,58,-7,minecraft:diorite)
B(-5,58,-6,minecraft:diorite)
B(-5,58,-5,minecraft:diorite)
B(-5,58,-4,minecraft:diorite)
B(-5,58,-3,minecraft:obsidian)
B(-5,58,-2,minecraft:obsidian)
B(-5,58,-1,minecraft:obsidian)
B(-5,58,0,minecraft:diorite)
B(-5,58,1,minecraft:diorite)
B(-5,58,2,minecraft:diorite)
B(-5,58,3,minecraft:diorite)
B(-5,59,-7,minecraft:diorite)
B(-5,59,-6,minecraft:diorite)
B(-5,59,-5,minecraft:diorite)
B(-5,59,-4,minecraft:diorite)
B(-5,59,-3,minecraft:diorite)
B(-5,59,-2,minecraft:diorite)
B(-5,59,-1,minecraft:obsidian)
B(-5,59,0,minecraft:diorite)
B(-5,59,1,minecraft:diorite)
B(-5,59,2,minecraft:diorite)
B(-5,59,3,minecraft:diorite)
B(-5,60,-7,minecraft:diorite)
B(-5,60,-6,minecraft:diorite)
B(-5,60,-5,minecraft:diorite)
B(-5,60,-4,minecraft:diorite)
B(-5,60,-3,minecraft:diorite)
B(-5,60,-2,minecraft:obsidian)
B(-5,60,-1,minecraft:obsidian)
B(-5,60,0,minecraft:diorite)
B(-5,60,1,minecraft:diorite)
B(-5,60,2,minecraft:diorite)
B(-5,61,-7,minecraft:diorite)
B(-5,61,-6,minecraft:diorite)
B(-5,61,-5,minecraft:diorite)
B(-5,61,-4,minecraft:diorite)
B(-5,61,-3,minecraft:diorite)
B(-5,61,-2,minecraft:obsidian)
B(-5,61,-1,minecraft:obsidian)
B(-5,61,0,minecraft:diorite)
B(-5,61,1,minecraft:diorite)
B(-5,61,2,minecraft:diorite)
B(-5,62,-7,minecraft:diorite)
B(-5,62,-6,minecraft:diorite)
B(-5,62,-5,minecraft:diorite)
B(-5,62,-4,minecraft:diorite)
B(-5,62,-3,minecraft:obsidian)
B(-5,62,-2,minecraft:obsidian)
B(-5,62,-1,minecraft:obsidian)
B(-5,62,0,minecraft:obsidian)
B(-5,62,1,minecraft:obsidian)
B(-5,62,2,minecraft:obsidian)
B(-5,63,-7,minecraft:diorite)
B(-5,63,-6,minecraft:diorite)
B(-5,63,-5,minecraft:diorite)
B(-5,63,-4,minecraft:obsidian)
B(-5,63,-3,minecraft:obsidian)
B(-5,63,-2,minecraft:obsidian)
B(-5,63,-1,minecraft:obsidian)
B(-5,63,0,minecraft:obsidian)
B(-5,63,1,minecraft:obsidian)
B(-5,63,2,minecraft:obsidian)
B(-5,64,-7,minecraft:diorite)
B(-5,64,-6,minecraft:diorite)
B(-5,64,-5,minecraft:obsidian)
B(-5,64,-4,minecraft:obsidian)
B(-5,64,-3,minecraft:obsidian)
B(-5,64,-2,minecraft:obsidian)
B(-5,64,-1,minecraft:obsidian)
B(-5,64,0,minecraft:obsidian)
B(-5,64,1,minecraft:obsidian)
B(-5,64,2,minecraft:obsidian)
B(-5,65,-7,minecraft:diorite)
B(-5,65,-6,minecraft:diorite)
B(-5,65,-5,minecraft:obsidian)
B(-5,65,-4,minecraft:obsidian)
B(-5,65,-3,minecraft:obsidian)
B(-5,65,-2,minecraft:obsidian)
B(-5,65,-1,minecraft:obsidian)
B(-5,65,0,minecraft:obsidian)
B(-5,65,1,minecraft:obsidian)
B(-5,65,2,minecraft:obsidian)
B(-5,66,-7,minecraft:diorite)
B(-5,66,-6,minecraft:diorite)
B(-5,66,-5,minecraft:obsidian)
B(-5,66,-4,minecraft:obsidian)
B(-5,66,-3,minecraft:obsidian)
B(-5,66,-2,minecraft:obsidian)
B(-5,66,-1,minecraft:obsidian)
B(-5,66,0,minecraft:obsidian)
B(-5,66,1,minecraft:obsidian)
B(-5,66,2,minecraft:obsidian)
B(-5,67,-7,minecraft:diorite)
B(-5,67,-6,minecraft:diorite)
B(-5,67,-5,minecraft:obsidian)
B(-5,67,-4,minecraft:obsidian)
B(-5,67,-3,minecraft:obsidian)
B(-5,67,-2,minecraft:obsidian)
B(-5,67,-1,minecraft:obsidian)
B(-5,67,0,minecraft:obsidian)
B(-5,67,1,minecraft:obsidian)
B(-5,67,2,minecraft:obsidian)
B(-5,68,-7,minecraft:diorite)
B(-5,68,-6,minecraft:diorite)
B(-5,68,-5,minecraft:obsidian)
B(-5,68,-4,minecraft:obsidian)
B(-5,68,-3,minecraft:obsidian)
B(-5,68,-2,minecraft:obsidian)
B(-5,68,-1,minecraft:obsidian)
B(-5,68,0,minecraft:obsidian)
B(-5,68,1,minecraft:obsidian)
B(-5,68,2,minecraft:obsidian)
B(-5,68,3,minecraft:obsidian)
B(-5,69,-7,minecraft:diorite)
B(-5,69,-6,minecraft:obsidian)
B(-5,69,-5,minecraft:obsidian)
B(-5,69,-4,minecraft:obsidian)
B(-5,69,-3,minecraft:obsidian)
B(-5,69,-2,minecraft:obsidian)
B(-5,69,-1,minecraft:obsidian)
B(-5,69,0,minecraft:obsidian)
B(-5,69,1,minecraft:obsidian)
B(-5,69,2,minecraft:obsidian)
B(-5,69,3,minecraft:obsidian)
B(-5,70,-7,minecraft:obsidian)
B(-5,70,-6,minecraft:obsidian)
B(-5,70,-5,minecraft:obsidian)
B(-5,70,-4,minecraft:obsidian)
B(-5,70,-3,minecraft:obsidian)
B(-5,70,-2,minecraft:obsidian)
B(-5,70,-1,minecraft:obsidian)
B(-5,70,0,minecraft:obsidian)
B(-5,70,1,minecraft:obsidian)
B(-5,70,2,minecraft:obsidian)
B(-5,70,3,minecraft:obsidian)
B(-5,71,-7,minecraft:obsidian)
B(-5,71,-6,minecraft:obsidian)
B(-5,71,-5,minecraft:obsidian)
B(-5,71,-4,minecraft:obsidian)
B(-5,71,-3,minecraft:obsidian)
B(-5,71,-2,minecraft:obsidian)
B(-5,71,-1,minecraft:obsidian)
B(-5,71,0,minecraft:obsidian)
B(-5,71,1,minecraft:obsidian)
B(-5,71,2,minecraft:obsidian)
B(-5,71,3,minecraft:obsidian)
B(-5,72,-7,minecraft:obsidian)
B(-5,72,-6,minecraft:obsidian)
B(-5,72,-5,minecraft:obsidian)
B(-5,72,-4,minecraft:obsidian)
B(-5,72,-3,minecraft:obsidian)
B(-5,72,-2,minecraft:obsidian)
B(-5,72,-1,minecraft:obsidian)
B(-5,72,0,minecraft:obsidian)
B(-5,72,1,minecraft:obsidian)
B(-5,72,2,minecraft:obsidian)
B(-5,72,3,minecraft:obsidian)
B(-5,72,4,minecraft:obsidian)
B(-5,73,-7,minecraft:diorite)
B(-5,73,-6,minecraft:diorite)
B(-5,73,-5,minecraft:diorite)
B(-5,73,-4,minecraft:diorite)
B(-5,73,-3,minecraft:obsidian)
B(-5,73,-2,minecraft:obsidian)
B(-5,73,-1,minecraft:obsidian)
B(-5,73,0,minecraft:obsidian)
B(-5,73,1,minecraft:obsidian)
B(-5,73,2,minecraft:obsidian)
B(-5,73,3,minecraft:obsidian)
B(-5,73,4,minecraft:obsidian)
B(-5,74,-7,minecraft:andesite)
B(-5,74,-6,minecraft:diorite)
B(-5,74,-5,minecraft:diorite)
B(-5,74,-4,minecraft:diorite)
B(-5,74,-3,minecraft:diorite)
B(-5,74,-2,minecraft:obsidian)
B(-5,74,-1,minecraft:obsidian)
B(-5,74,0,minecraft:obsidian)
B(-5,74,1,minecraft:obsidian)
B(-5,74,2,minecraft:diorite)
B(-5,74,3,minecraft:diorite)
B(-5,74,4,minecraft:diorite)
B(-5,75,-6,minecraft:andesite)
B(-5,75,-5,minecraft:andesite)
B(-5,75,-4,minecraft:diorite)
B(-5,75,-3,minecraft:diorite)
B(-5,75,-2,minecraft:obsidian)
B(-5,75,-1,minecraft:obsidian)
B(-5,75,0,minecraft:obsidian)
B(-5,75,1,minecraft:diorite)
B(-5,75,2,minecraft:diorite)
B(-5,75,3,minecraft:diorite)
B(-5,76,-4,minecraft:andesite)
B(-5,76,-3,minecraft:diorite)
B(-5,76,-2,minecraft:obsidian)
B(-5,76,-1,minecraft:obsidian)
B(-5,76,0,minecraft:obsidian)
B(-5,76,1,minecraft:diorite)
B(-5,76,2,minecraft:diorite)
B(-5,76,3,minecraft:diorite)
B(-5,76,4,minecraft:diorite)
B(-5,77,-3,minecraft:diorite)
B(-5,77,-2,minecraft:diorite)
B(-5,77,-1,minecraft:obsidian)
B(-5,77,0,minecraft:obsidian)
B(-5,77,1,minecraft:diorite)
B(-5,77,2,minecraft:diorite)
B(-5,77,3,minecraft:diorite)
B(-5,77,4,minecraft:diorite)
B(-5,77,5,minecraft:diorite)
B(-5,77,6,minecraft:diorite)
B(-5,77,7,minecraft:diorite)
B(-5,78,-3,minecraft:andesite)
B(-5,78,-2,minecraft:diorite)
B(-5,78,-1,minecraft:diorite)
B(-5,78,0,minecraft:obsidian)
B(-5,78,1,minecraft:obsidian)
B(-5,78,2,minecraft:diorite)
B(-5,78,3,minecraft:diorite)
B(-5,78,4,minecraft:diorite)
B(-5,78,5,minecraft:diorite)
B(-5,78,6,minecraft:diorite)
B(-5,78,7,minecraft:diorite)
B(-5,78,8,minecraft:diorite)
B(-5,79,-2,minecraft:diorite)
B(-5,79,-1,minecraft:diorite)
B(-5,79,0,minecraft:diorite)
B(-5,79,1,minecraft:diorite)
B(-5,79,2,minecraft:diorite)
B(-5,79,3,minecraft:diorite)
B(-5,79,4,minecraft:diorite)
B(-5,79,5,minecraft:diorite)
B(-5,79,6,minecraft:diorite)
B(-5,79,7,minecraft:diorite)
B(-5,79,8,minecraft:diorite)
B(-5,80,-2,minecraft:diorite)
B(-5,80,-1,minecraft:diorite)
B(-5,80,0,minecraft:diorite)
B(-5,80,1,minecraft:diorite)
B(-5,80,2,minecraft:diorite)
B(-5,80,3,minecraft:diorite)
B(-5,80,4,minecraft:obsidian)
B(-5,80,5,minecraft:obsidian)
B(-5,80,6,minecraft:diorite)
B(-5,80,7,minecraft:diorite)
B(-5,80,8,minecraft:diorite)
B(-5,81,-3,minecraft:diorite)
B(-5,81,-2,minecraft:diorite)
B(-5,81,-1,minecraft:diorite)
B(-5,81,0,minecraft:diorite)
B(-5,81,1,minecraft:diorite)
B(-5,81,2,minecraft:diorite)
B(-5,81,3,minecraft:diorite)
B(-5,81,4,minecraft:diorite)
B(-5,81,5,minecraft:diorite)
B(-5,81,6,minecraft:diorite)
B(-5,81,7,minecraft:obsidian)
B(-5,81,8,minecraft:diorite)
B(-5,82,-2,minecraft:andesite)
B(-5,82,-1,minecraft:diorite)
B(-5,82,0,minecraft:diorite)
B(-5,82,1,minecraft:diorite)
B(-5,82,2,minecraft:diorite)
B(-5,82,3,minecraft:diorite)
B(-5,82,4,minecraft:diorite)
B(-5,82,5,minecraft:diorite)
B(-5,82,6,minecraft:diorite)
B(-5,82,7,minecraft:diorite)
B(-5,82,8,minecraft:diorite)
B(-5,83,-1,minecraft:andesite)
B(-5,83,0,minecraft:diorite)
B(-5,83,1,minecraft:diorite)
B(-5,83,2,minecraft:diorite)
B(-5,83,3,minecraft:diorite)
B(-5,83,4,minecraft:diorite)
B(-5,83,5,minecraft:diorite)
B(-5,83,6,minecraft:diorite)
B(-5,83,7,minecraft:diorite)
B(-5,83,8,minecraft:diorite)
B(-5,84,0,minecraft:andesite)
B(-5,84,1,minecraft:diorite)
B(-5,84,2,minecraft:diorite)
B(-5,84,3,minecraft:diorite)
B(-5,84,4,minecraft:diorite)
B(-5,84,5,minecraft:diorite)
B(-5,84,6,minecraft:diorite)
B(-5,84,7,minecraft:diorite)
B(-5,84,8,minecraft:diorite)
B(-5,85,1,minecraft:diorite)
B(-5,85,2,minecraft:diorite)
B(-5,85,3,minecraft:diorite)
B(-5,85,4,minecraft:diorite)
B(-5,85,5,minecraft:diorite)
B(-5,85,6,minecraft:diorite)
B(-5,85,7,minecraft:diorite)
B(-5,85,8,minecraft:diorite)
B(-5,86,1,minecraft:andesite)
B(-5,86,2,minecraft:andesite)
B(-5,86,3,minecraft:diorite)
B(-5,86,4,minecraft:diorite)
B(-5,86,5,minecraft:diorite)
B(-5,86,6,minecraft:diorite)
B(-5,86,7,minecraft:diorite)
B(-5,86,8,minecraft:diorite)
B(-5,87,3,minecraft:diorite)
B(-5,87,4,minecraft:diorite)
B(-5,87,5,minecraft:diorite)
B(-5,87,6,minecraft:diorite)
B(-5,87,7,minecraft:diorite)
B(-5,87,8,minecraft:diorite)
B(-5,88,3,minecraft:andesite)
B(-5,88,4,minecraft:andesite)
B(-5,88,5,minecraft:diorite)
B(-5,88,6,minecraft:diorite)
B(-5,88,7,minecraft:diorite)
B(-5,88,8,minecraft:diorite)
B(-5,89,5,minecraft:andesite)
B(-5,89,6,minecraft:andesite)
B(-5,89,7,minecraft:diorite)
B(-5,89,8,minecraft:diorite)
B(-5,90,7,minecraft:andesite)
B(-5,90,8,minecraft:andesite)
B(-4,34,5,minecraft:diorite)
B(-4,34,6,minecraft:diorite)
B(-4,34,7,minecraft:diorite)
B(-4,34,8,minecraft:diorite)
B(-4,35,5,minecraft:diorite)
B(-4,35,6,minecraft:diorite)
B(-4,35,7,minecraft:diorite)
B(-4,35,8,minecraft:diorite)
B(-4,36,5,minecraft:diorite)
B(-4,36,6,minecraft:diorite)
B(-4,36,7,minecraft:diorite)
B(-4,36,8,minecraft:diorite)
B(-4,37,5,minecraft:diorite)
B(-4,37,6,minecraft:diorite)
B(-4,37,7,minecraft:diorite)
B(-4,37,8,minecraft:diorite)
B(-4,38,5,minecraft:diorite)
B(-4,38,6,minecraft:diorite)
B(-4,38,7,minecraft:diorite)
B(-4,38,8,minecraft:diorite)
B(-4,39,4,minecraft:diorite)
B(-4,39,5,minecraft:diorite)
B(-4,39,6,minecraft:diorite)
B(-4,39,7,minecraft:diorite)
B(-4,39,8,minecraft:diorite)
B(-4,40,3,minecraft:diorite)
B(-4,40,4,minecraft:diorite)
B(-4,40,5,minecraft:diorite)
B(-4,40,6,minecraft:diorite)
B(-4,40,7,minecraft:diorite)
B(-4,40,8,minecraft:diorite)
B(-4,41,2,minecraft:diorite)
B(-4,41,3,minecraft:diorite)
B(-4,41,4,minecraft:diorite)
B(-4,41,5,minecraft:diorite)
B(-4,41,6,minecraft:diorite)
B(-4,41,7,minecraft:diorite)
B(-4,41,8,minecraft:diorite)
B(-4,42,2,minecraft:diorite)
B(-4,42,3,minecraft:diorite)
B(-4,42,4,minecraft:diorite)
B(-4,42,5,minecraft:diorite)
B(-4,42,6,minecraft:diorite)
B(-4,42,7,minecraft:diorite)
B(-4,42,8,minecraft:diorite)
B(-4,43,1,minecraft:diorite)
B(-4,43,2,minecraft:diorite)
B(-4,43,3,minecraft:diorite)
B(-4,43,4,minecraft:diorite)
B(-4,43,5,minecraft:diorite)
B(-4,43,6,minecraft:diorite)
B(-4,43,7,minecraft:diorite)
B(-4,43,8,minecraft:obsidian)
B(-4,44,0,minecraft:diorite)
B(-4,44,1,minecraft:diorite)
B(-4,44,2,minecraft:diorite)
B(-4,44,3,minecraft:diorite)
B(-4,44,4,minecraft:diorite)
B(-4,44,5,minecraft:diorite)
B(-4,44,6,minecraft:diorite)
B(-4,44,7,minecraft:diorite)
B(-4,44,8,minecraft:obsidian)
B(-4,45,0,minecraft:diorite)
B(-4,45,1,minecraft:diorite)
B(-4,45,2,minecraft:diorite)
B(-4,45,3,minecraft:diorite)
B(-4,45,4,minecraft:diorite)
B(-4,45,5,minecraft:diorite)
B(-4,45,6,minecraft:diorite)
B(-4,45,7,minecraft:diorite)
B(-4,45,8,minecraft:obsidian)
B(-4,46,0,minecraft:obsidian)
B(-4,46,1,minecraft:obsidian)
B(-4,46,2,minecraft:diorite)
B(-4,46,3,minecraft:diorite)
B(-4,46,4,minecraft:diorite)
B(-4,46,5,minecraft:diorite)
B(-4,46,6,minecraft:diorite)
B(-4,46,7,minecraft:obsidian)
B(-4,46,8,minecraft:obsidian)
B(-4,47,-1,minecraft:obsidian)
B(-4,47,0,minecraft:obsidian)
B(-4,47,1,minecraft:obsidian)
B(-4,47,2,minecraft:obsidian)
B(-4,47,3,minecraft:diorite)
B(-4,47,4,minecraft:diorite)
B(-4,47,5,minecraft:diorite)
B(-4,47,6,minecraft:obsidian)
B(-4,47,7,minecraft:obsidian)
B(-4,47,8,minecraft:obsidian)
B(-4,48,-1,minecraft:obsidian)
B(-4,48,0,minecraft:obsidian)
B(-4,48,1,minecraft:obsidian)
B(-4,48,2,minecraft:obsidian)
B(-4,48,3,minecraft:diorite)
B(-4,48,4,minecraft:obsidian)
B(-4,48,5,minecraft:obsidian)
B(-4,48,6,minecraft:obsidian)
B(-4,48,7,minecraft:obsidian)
B(-4,48,8,minecraft:obsidian)
B(-4,49,-2,minecraft:magma_block)
B(-4,49,-1,minecraft:magma_block)
B(-4,49,0,minecraft:magma_block)
B(-4,49,1,minecraft:obsidian)
B(-4,49,2,minecraft:obsidian)
B(-4,49,3,minecraft:obsidian)
B(-4,49,4,minecraft:obsidian)
B(-4,49,5,minecraft:obsidian)
B(-4,49,6,minecraft:obsidian)
B(-4,49,7,minecraft:obsidian)
B(-4,49,8,minecraft:obsidian)
B(-4,50,-2,minecraft:magma_block)
B(-4,50,-1,minecraft:magma_block)
B(-4,50,0,minecraft:magma_block)
B(-4,50,1,minecraft:magma_block)
B(-4,50,2,minecraft:obsidian)
B(-4,50,3,minecraft:obsidian)
B(-4,50,4,minecraft:obsidian)
B(-4,50,5,minecraft:obsidian)
B(-4,50,6,minecraft:obsidian)
B(-4,50,7,minecraft:obsidian)
B(-4,50,8,minecraft:obsidian)
B(-4,51,-2,minecraft:magma_block)
B(-4,51,-1,minecraft:magma_block)
B(-4,51,0,minecraft:magma_block)
B(-4,51,1,minecraft:magma_block)
B(-4,51,2,minecraft:obsidian)
B(-4,51,3,minecraft:obsidian)
B(-4,51,4,minecraft:obsidian)
B(-4,51,5,minecraft:diorite)
B(-4,51,6,minecraft:diorite)
B(-4,51,7,minecraft:diorite)
B(-4,51,8,minecraft:obsidian)
B(-4,52,-2,minecraft:magma_block)
B(-4,52,-1,minecraft:magma_block)
B(-4,52,0,minecraft:magma_block)
B(-4,52,1,minecraft:magma_block)
B(-4,52,2,minecraft:obsidian)
B(-4,52,3,minecraft:obsidian)
B(-4,52,4,minecraft:obsidian)
B(-4,52,5,minecraft:diorite)
B(-4,52,6,minecraft:diorite)
B(-4,52,7,minecraft:diorite)
B(-4,52,8,minecraft:obsidian)
B(-4,53,-3,minecraft:magma_block)
B(-4,53,-2,minecraft:magma_block)
B(-4,53,-1,minecraft:magma_block)
B(-4,53,0,minecraft:magma_block)
B(-4,53,1,minecraft:obsidian)
B(-4,53,2,minecraft:obsidian)
B(-4,53,3,minecraft:obsidian)
B(-4,53,4,minecraft:diorite)
B(-4,53,5,minecraft:diorite)
B(-4,53,6,minecraft:diorite)
B(-4,53,7,minecraft:diorite)
B(-4,54,-3,minecraft:obsidian)
B(-4,54,-2,minecraft:obsidian)
B(-4,54,-1,minecraft:obsidian)
B(-4,54,0,minecraft:obsidian)
B(-4,54,1,minecraft:obsidian)
B(-4,54,2,minecraft:obsidian)
B(-4,54,3,minecraft:obsidian)
B(-4,54,4,minecraft:diorite)
B(-4,54,5,minecraft:diorite)
B(-4,54,6,minecraft:diorite)
B(-4,54,7,minecraft:diorite)
B(-4,55,-4,minecraft:diorite)
B(-4,55,-3,minecraft:obsidian)
B(-4,55,-2,minecraft:obsidian)
B(-4,55,-1,minecraft:obsidian)
B(-4,55,0,minecraft:obsidian)
B(-4,55,1,minecraft:obsidian)
B(-4,55,2,minecraft:obsidian)
B(-4,55,3,minecraft:obsidian)
B(-4,55,4,minecraft:diorite)
B(-4,55,5,minecraft:diorite)
B(-4,55,6,minecraft:diorite)
B(-4,55,7,minecraft:diorite)
B(-4,56,-5,minecraft:diorite)
B(-4,56,-4,minecraft:diorite)
B(-4,56,-3,minecraft:diorite)
B(-4,56,-2,minecraft:diorite)
B(-4,56,-1,minecraft:diorite)
B(-4,56,0,minecraft:obsidian)
B(-4,56,1,minecraft:obsidian)
B(-4,56,2,minecraft:obsidian)
B(-4,56,3,minecraft:diorite)
B(-4,56,4,minecraft:diorite)
B(-4,56,5,minecraft:andesite)
B(-4,56,6,minecraft:andesite)
B(-4,56,7,minecraft:diorite)
B(-4,56,8,minecraft:diorite)
B(-4,57,-6,minecraft:diorite)
B(-4,57,-5,minecraft:diorite)
B(-4,57,-4,minecraft:diorite)
B(-4,57,-3,minecraft:diorite)
B(-4,57,-2,minecraft:diorite)
B(-4,57,-1,minecraft:diorite)
B(-4,57,0,minecraft:obsidian)
B(-4,57,1,minecraft:obsidian)
B(-4,57,2,minecraft:diorite)
B(-4,57,3,minecraft:diorite)
B(-4,57,4,minecraft:diorite)
B(-4,57,7,minecraft:diorite)
B(-4,58,-7,minecraft:diorite)
B(-4,58,-6,minecraft:diorite)
B(-4,58,-5,minecraft:diorite)
B(-4,58,-4,minecraft:diorite)
B(-4,58,-3,minecraft:diorite)
B(-4,58,-2,minecraft:diorite)
B(-4,58,-1,minecraft:diorite)
B(-4,58,0,minecraft:obsidian)
B(-4,58,1,minecraft:diorite)
B(-4,58,2,minecraft:diorite)
B(-4,58,3,minecraft:diorite)
B(-4,58,4,minecraft:diorite)
B(-4,59,-7,minecraft:diorite)
B(-4,59,-6,minecraft:diorite)
B(-4,59,-5,minecraft:diorite)
B(-4,59,-4,minecraft:diorite)
B(-4,59,-3,minecraft:diorite)
B(-4,59,-2,minecraft:diorite)
B(-4,59,-1,minecraft:diorite)
B(-4,59,0,minecraft:obsidian)
B(-4,59,1,minecraft:diorite)
B(-4,59,2,minecraft:diorite)
B(-4,59,3,minecraft:diorite)
B(-4,60,-7,minecraft:diorite)
B(-4,60,-6,minecraft:diorite)
B(-4,60,-5,minecraft:diorite)
B(-4,60,-4,minecraft:diorite)
B(-4,60,-3,minecraft:diorite)
B(-4,60,-2,minecraft:diorite)
B(-4,60,-1,minecraft:obsidian)
B(-4,60,0,minecraft:obsidian)
B(-4,60,1,minecraft:diorite)
B(-4,60,2,minecraft:diorite)
B(-4,60,3,minecraft:diorite)
B(-4,61,-7,minecraft:diorite)
B(-4,61,-6,minecraft:diorite)
B(-4,61,-5,minecraft:diorite)
B(-4,61,-4,minecraft:diorite)
B(-4,61,-3,minecraft:diorite)
B(-4,61,-2,minecraft:diorite)
B(-4,61,-1,minecraft:obsidian)
B(-4,61,0,minecraft:obsidian)
B(-4,61,1,minecraft:obsidian)
B(-4,61,2,minecraft:diorite)
B(-4,62,-7,minecraft:diorite)
B(-4,62,-6,minecraft:diorite)
B(-4,62,-5,minecraft:diorite)
B(-4,62,-4,minecraft:diorite)
B(-4,62,-3,minecraft:diorite)
B(-4,62,-2,minecraft:diorite)
B(-4,62,-1,minecraft:obsidian)
B(-4,62,0,minecraft:obsidian)
B(-4,62,1,minecraft:obsidian)
B(-4,62,2,minecraft:obsidian)
B(-4,62,3,minecraft:obsidian)
B(-4,63,-7,minecraft:diorite)
B(-4,63,-6,minecraft:diorite)
B(-4,63,-5,minecraft:diorite)
B(-4,63,-4,minecraft:diorite)
B(-4,63,-3,minecraft:diorite)
B(-4,63,-2,minecraft:obsidian)
B(-4,63,-1,minecraft:obsidian)
B(-4,63,0,minecraft:obsidian)
B(-4,63,1,minecraft:obsidian)
B(-4,63,2,minecraft:obsidian)
B(-4,63,3,minecraft:obsidian)
B(-4,63,4,minecraft:obsidian)
B(-4,64,-7,minecraft:diorite)
B(-4,64,-6,minecraft:diorite)
B(-4,64,-5,minecraft:obsidian)
B(-4,64,-4,minecraft:obsidian)
B(-4,64,-3,minecraft:obsidian)
B(-4,64,-2,minecraft:obsidian)
B(-4,64,-1,minecraft:obsidian)
B(-4,64,0,minecraft:obsidian)
B(-4,64,1,minecraft:obsidian)
B(-4,64,2,minecraft:obsidian)
B(-4,64,3,minecraft:obsidian)
B(-4,64,4,minecraft:obsidian)
B(-4,65,-7,minecraft:diorite)
B(-4,65,-6,minecraft:diorite)
B(-4,65,-5,minecraft:diorite)
B(-4,65,-4,minecraft:obsidian)
B(-4,65,-3,minecraft:obsidian)
B(-4,65,-2,minecraft:obsidian)
B(-4,65,-1,minecraft:obsidian)
B(-4,65,0,minecraft:obsidian)
B(-4,65,1,minecraft:obsidian)
B(-4,65,2,minecraft:obsidian)
B(-4,66,-7,minecraft:diorite)
B(-4,66,-6,minecraft:diorite)
B(-4,66,-5,minecraft:diorite)
B(-4,66,-4,minecraft:obsidian)
B(-4,66,-3,minecraft:obsidian)
B(-4,66,-2,minecraft:obsidian)
B(-4,66,-1,minecraft:obsidian)
B(-4,66,0,minecraft:obsidian)
B(-4,66,1,minecraft:obsidian)
B(-4,66,2,minecraft:obsidian)
B(-4,66,3,minecraft:obsidian)
B(-4,67,-7,minecraft:diorite)
B(-4,67,-6,minecraft:diorite)
B(-4,67,-5,minecraft:diorite)
B(-4,67,-4,minecraft:obsidian)
B(-4,67,-3,minecraft:obsidian)
B(-4,67,-2,minecraft:obsidian)
B(-4,67,-1,minecraft:obsidian)
B(-4,67,0,minecraft:obsidian)
B(-4,67,1,minecraft:obsidian)
B(-4,67,2,minecraft:obsidian)
B(-4,67,3,minecraft:obsidian)
B(-4,68,-7,minecraft:diorite)
B(-4,68,-6,minecraft:diorite)
B(-4,68,-5,minecraft:obsidian)
B(-4,68,-4,minecraft:obsidian)
B(-4,68,-3,minecraft:obsidian)
B(-4,68,-2,minecraft:obsidian)
B(-4,68,-1,minecraft:obsidian)
B(-4,68,0,minecraft:obsidian)
B(-4,68,1,minecraft:obsidian)
B(-4,68,2,minecraft:obsidian)
B(-4,68,3,minecraft:obsidian)
B(-4,69,-7,minecraft:diorite)
B(-4,69,-6,minecraft:diorite)
B(-4,69,-5,minecraft:obsidian)
B(-4,69,-4,minecraft:obsidian)
B(-4,69,-3,minecraft:obsidian)
B(-4,69,-2,minecraft:obsidian)
B(-4,69,-1,minecraft:obsidian)
B(-4,69,0,minecraft:obsidian)
B(-4,69,1,minecraft:obsidian)
B(-4,69,2,minecraft:obsidian)
B(-4,69,3,minecraft:obsidian)
B(-4,70,-7,minecraft:diorite)
B(-4,70,-6,minecraft:obsidian)
B(-4,70,-5,minecraft:obsidian)
B(-4,70,-4,minecraft:obsidian)
B(-4,70,-3,minecraft:obsidian)
B(-4,70,-2,minecraft:obsidian)
B(-4,70,-1,minecraft:obsidian)
B(-4,70,0,minecraft:obsidian)
B(-4,70,1,minecraft:obsidian)
B(-4,70,2,minecraft:obsidian)
B(-4,70,3,minecraft:obsidian)
B(-4,71,-7,minecraft:obsidian)
B(-4,71,-6,minecraft:obsidian)
B(-4,71,-5,minecraft:obsidian)
B(-4,71,-4,minecraft:obsidian)
B(-4,71,-3,minecraft:obsidian)
B(-4,71,-2,minecraft:obsidian)
B(-4,71,-1,minecraft:obsidian)
B(-4,71,0,minecraft:obsidian)
B(-4,71,1,minecraft:obsidian)
B(-4,71,2,minecraft:obsidian)
B(-4,71,3,minecraft:obsidian)
B(-4,72,-7,minecraft:obsidian)
B(-4,72,-6,minecraft:obsidian)
B(-4,72,-5,minecraft:obsidian)
B(-4,72,-4,minecraft:obsidian)
B(-4,72,-3,minecraft:obsidian)
B(-4,72,-2,minecraft:obsidian)
B(-4,72,-1,minecraft:obsidian)
B(-4,72,0,minecraft:obsidian)
B(-4,72,1,minecraft:obsidian)
B(-4,72,2,minecraft:obsidian)
B(-4,72,3,minecraft:obsidian)
B(-4,72,4,minecraft:obsidian)
B(-4,73,-7,minecraft:diorite)
B(-4,73,-6,minecraft:obsidian)
B(-4,73,-5,minecraft:obsidian)
B(-4,73,-4,minecraft:obsidian)
B(-4,73,-3,minecraft:obsidian)
B(-4,73,-2,minecraft:obsidian)
B(-4,73,-1,minecraft:obsidian)
B(-4,73,0,minecraft:obsidian)
B(-4,73,1,minecraft:obsidian)
B(-4,73,2,minecraft:obsidian)
B(-4,73,3,minecraft:obsidian)
B(-4,73,4,minecraft:obsidian)
B(-4,74,-7,minecraft:andesite)
B(-4,74,-6,minecraft:diorite)
B(-4,74,-5,minecraft:diorite)
B(-4,74,-4,minecraft:diorite)
B(-4,74,-3,minecraft:diorite)
B(-4,74,-2,minecraft:diorite)
B(-4,74,-1,minecraft:obsidian)
B(-4,74,0,minecraft:obsidian)
B(-4,74,1,minecraft:obsidian)
B(-4,74,2,minecraft:obsidian)
B(-4,74,3,minecraft:obsidian)
B(-4,74,4,minecraft:andesite)
B(-4,75,-6,minecraft:andesite)
B(-4,75,-5,minecraft:andesite)
B(-4,75,-4,minecraft:andesite)
B(-4,75,-3,minecraft:diorite)
B(-4,75,-2,minecraft:diorite)
B(-4,75,-1,minecraft:obsidian)
B(-4,75,0,minecraft:obsidian)
B(-4,75,1,minecraft:obsidian)
B(-4,75,2,minecraft:diorite)
B(-4,75,3,minecraft:diorite)
B(-4,76,-3,minecraft:diorite)
B(-4,76,-2,minecraft:diorite)
B(-4,76,-1,minecraft:obsidian)
B(-4,76,0,minecraft:obsidian)
B(-4,76,1,minecraft:obsidian)
B(-4,76,2,minecraft:diorite)
B(-4,76,3,minecraft:diorite)
B(-4,76,7,minecraft:obsidian)
B(-4,77,-3,minecraft:andesite)
B(-4,77,-2,minecraft:diorite)
B(-4,77,-1,minecraft:obsidian)
B(-4,77,0,minecraft:obsidian)
B(-4,77,1,minecraft:obsidian)
B(-4,77,2,minecraft:diorite)
B(-4,77,3,minecraft:diorite)
B(-4,77,4,minecraft:diorite)
B(-4,77,5,minecraft:diorite)
B(-4,77,6,minecraft:diorite)
B(-4,77,7,minecraft:diorite)
B(-4,77,8,minecraft:diorite)
B(-4,78,-2,minecraft:diorite)
B(-4,78,-1,minecraft:diorite)
B(-4,78,0,minecraft:diorite)
B(-4,78,1,minecraft:diorite)
B(-4,78,2,minecraft:diorite)
B(-4,78,3,minecraft:diorite)
B(-4,78,4,minecraft:diorite)
B(-4,78,5,minecraft:diorite)
B(-4,78,6,minecraft:diorite)
B(-4,78,7,minecraft:diorite)
B(-4,78,8,minecraft:diorite)
B(-4,79,-2,minecraft:diorite)
B(-4,79,-1,minecraft:diorite)
B(-4,79,0,minecraft:diorite)
B(-4,79,1,minecraft:diorite)
B(-4,79,2,minecraft:diorite)
B(-4,79,3,minecraft:diorite)
B(-4,79,4,minecraft:obsidian)
B(-4,79,5,minecraft:obsidian)
B(-4,79,6,minecraft:diorite)
B(-4,79,7,minecraft:diorite)
B(-4,79,8,minecraft:diorite)
B(-4,80,-2,minecraft:diorite)
B(-4,80,-1,minecraft:diorite)
B(-4,80,0,minecraft:diorite)
B(-4,80,1,minecraft:diorite)
B(-4,80,2,minecraft:diorite)
B(-4,80,3,minecraft:diorite)
B(-4,80,4,minecraft:obsidian)
B(-4,80,5,minecraft:obsidian)
B(-4,80,6,minecraft:obsidian)
B(-4,80,7,minecraft:obsidian)
B(-4,80,8,minecraft:obsidian)
B(-4,81,-3,minecraft:diorite)
B(-4,81,-2,minecraft:diorite)
B(-4,81,-1,minecraft:diorite)
B(-4,81,0,minecraft:diorite)
B(-4,81,1,minecraft:diorite)
B(-4,81,2,minecraft:diorite)
B(-4,81,3,minecraft:diorite)
B(-4,81,4,minecraft:diorite)
B(-4,81,5,minecraft:diorite)
B(-4,81,6,minecraft:diorite)
B(-4,81,7,minecraft:diorite)
B(-4,81,8,minecraft:obsidian)
B(-4,82,-2,minecraft:andesite)
B(-4,82,-1,minecraft:diorite)
B(-4,82,0,minecraft:diorite)
B(-4,82,1,minecraft:diorite)
B(-4,82,2,minecraft:diorite)
B(-4,82,3,minecraft:diorite)
B(-4,82,4,minecraft:diorite)
B(-4,82,5,minecraft:diorite)
B(-4,82,6,minecraft:diorite)
B(-4,82,7,minecraft:diorite)
B(-4,82,8,minecraft:diorite)
B(-4,83,-1,minecraft:andesite)
B(-4,83,0,minecraft:diorite)
B(-4,83,1,minecraft:diorite)
B(-4,83,2,minecraft:diorite)
B(-4,83,3,minecraft:diorite)
B(-4,83,4,minecraft:diorite)
B(-4,83,5,minecraft:diorite)
B(-4,83,6,minecraft:diorite)
B(-4,83,7,minecraft:diorite)
B(-4,83,8,minecraft:diorite)
B(-4,84,0,minecraft:andesite)
B(-4,84,1,minecraft:diorite)
B(-4,84,2,minecraft:diorite)
B(-4,84,3,minecraft:diorite)
B(-4,84,4,minecraft:diorite)
B(-4,84,5,minecraft:diorite)
B(-4,84,6,minecraft:diorite)
B(-4,84,7,minecraft:diorite)
B(-4,84,8,minecraft:diorite)
B(-4,85,1,minecraft:andesite)
B(-4,85,2,minecraft:andesite)
B(-4,85,3,minecraft:diorite)
B(-4,85,4,minecraft:diorite)
B(-4,85,5,minecraft:diorite)
B(-4,85,6,minecraft:diorite)
B(-4,85,7,minecraft:diorite)
B(-4,85,8,minecraft:diorite)
B(-4,86,3,minecraft:andesite)
B(-4,86,4,minecraft:diorite)
B(-4,86,5,minecraft:diorite)
B(-4,86,6,minecraft:diorite)
B(-4,86,7,minecraft:diorite)
B(-4,86,8,minecraft:diorite)
B(-4,87,4,minecraft:andesite)
B(-4,87,5,minecraft:diorite)
B(-4,87,6,minecraft:diorite)
B(-4,87,7,minecraft:diorite)
B(-4,87,8,minecraft:diorite)
B(-4,88,5,minecraft:andesite)
B(-4,88,6,minecraft:diorite)
B(-4,88,7,minecraft:diorite)
B(-4,88,8,minecraft:diorite)
B(-4,89,6,minecraft:andesite)
B(-4,89,7,minecraft:andesite)
B(-4,89,8,minecraft:diorite)
B(-4,90,8,minecraft:andesite)
B(-3,34,5,minecraft:diorite)
B(-3,34,6,minecraft:diorite)
B(-3,34,7,minecraft:diorite)
B(-3,34,8,minecraft:diorite)
B(-3,35,5,minecraft:diorite)
B(-3,35,6,minecraft:diorite)
B(-3,35,7,minecraft:diorite)
B(-3,35,8,minecraft:diorite)
B(-3,36,6,minecraft:diorite)
B(-3,36,7,minecraft:diorite)
B(-3,36,8,minecraft:diorite)
B(-3,37,5,minecraft:diorite)
B(-3,37,6,minecraft:diorite)
B(-3,37,7,minecraft:diorite)
B(-3,37,8,minecraft:diorite)
B(-3,38,5,minecraft:diorite)
B(-3,38,6,minecraft:diorite)
B(-3,38,7,minecraft:diorite)
B(-3,38,8,minecraft:diorite)
B(-3,39,4,minecraft:diorite)
B(-3,39,5,minecraft:diorite)
B(-3,39,6,minecraft:diorite)
B(-3,39,7,minecraft:diorite)
B(-3,39,8,minecraft:diorite)
B(-3,40,3,minecraft:diorite)
B(-3,40,4,minecraft:diorite)
B(-3,40,5,minecraft:diorite)
B(-3,40,6,minecraft:diorite)
B(-3,40,7,minecraft:diorite)
B(-3,40,8,minecraft:diorite)
B(-3,41,2,minecraft:diorite)
B(-3,41,3,minecraft:diorite)
B(-3,41,4,minecraft:diorite)
B(-3,41,5,minecraft:diorite)
B(-3,41,6,minecraft:diorite)
B(-3,41,7,minecraft:diorite)
B(-3,41,8,minecraft:diorite)
B(-3,42,2,minecraft:diorite)
B(-3,42,3,minecraft:diorite)
B(-3,42,4,minecraft:diorite)
B(-3,42,5,minecraft:diorite)
B(-3,42,6,minecraft:diorite)
B(-3,42,7,minecraft:diorite)
B(-3,42,8,minecraft:diorite)
B(-3,43,2,minecraft:diorite)
B(-3,43,3,minecraft:diorite)
B(-3,43,4,minecraft:diorite)
B(-3,43,5,minecraft:diorite)
B(-3,43,6,minecraft:diorite)
B(-3,43,7,minecraft:diorite)
B(-3,43,8,minecraft:diorite)
B(-3,44,1,minecraft:diorite)
B(-3,44,2,minecraft:diorite)
B(-3,44,3,minecraft:diorite)
B(-3,44,4,minecraft:diorite)
B(-3,44,5,minecraft:diorite)
B(-3,44,6,minecraft:diorite)
B(-3,44,7,minecraft:diorite)
B(-3,44,8,minecraft:diorite)
B(-3,45,0,minecraft:obsidian)
B(-3,45,1,minecraft:obsidian)
B(-3,45,2,minecraft:obsidian)
B(-3,45,3,minecraft:diorite)
B(-3,45,4,minecraft:diorite)
B(-3,45,5,minecraft:diorite)
B(-3,45,6,minecraft:diorite)
B(-3,45,7,minecraft:diorite)
B(-3,45,8,minecraft:obsidian)
B(-3,46,0,minecraft:obsidian)
B(-3,46,1,minecraft:obsidian)
B(-3,46,2,minecraft:obsidian)
B(-3,46,3,minecraft:obsidian)
B(-3,46,4,minecraft:diorite)
B(-3,46,5,minecraft:diorite)
B(-3,46,6,minecraft:diorite)
B(-3,46,7,minecraft:diorite)
B(-3,46,8,minecraft:obsidian)
B(-3,47,0,minecraft:obsidian)
B(-3,47,1,minecraft:obsidian)
B(-3,47,2,minecraft:obsidian)
B(-3,47,3,minecraft:obsidian)
B(-3,47,4,minecraft:diorite)
B(-3,47,5,minecraft:diorite)
B(-3,47,6,minecraft:diorite)
B(-3,47,7,minecraft:obsidian)
B(-3,47,8,minecraft:obsidian)
B(-3,48,-1,minecraft:magma_block)
B(-3,48,0,minecraft:obsidian)
B(-3,48,1,minecraft:obsidian)
B(-3,48,2,minecraft:obsidian)
B(-3,48,3,minecraft:obsidian)
B(-3,48,4,minecraft:diorite)
B(-3,48,5,minecraft:obsidian)
B(-3,48,6,minecraft:obsidian)
B(-3,48,7,minecraft:obsidian)
B(-3,48,8,minecraft:obsidian)
B(-3,49,-2,minecraft:magma_block)
B(-3,49,-1,minecraft:magma_block)
B(-3,49,0,minecraft:magma_block)
B(-3,49,1,minecraft:obsidian)
B(-3,49,2,minecraft:obsidian)
B(-3,49,3,minecraft:obsidian)
B(-3,49,4,minecraft:obsidian)
B(-3,49,5,minecraft:obsidian)
B(-3,49,6,minecraft:obsidian)
B(-3,49,7,minecraft:obsidian)
B(-3,49,8,minecraft:obsidian)
B(-3,50,-2,minecraft:magma_block)
B(-3,50,-1,minecraft:magma_block)
B(-3,50,0,minecraft:magma_block)
B(-3,50,1,minecraft:magma_block)
B(-3,50,2,minecraft:obsidian)
B(-3,50,3,minecraft:obsidian)
B(-3,50,4,minecraft:obsidian)
B(-3,50,5,minecraft:obsidian)
B(-3,50,6,minecraft:obsidian)
B(-3,50,7,minecraft:obsidian)
B(-3,50,8,minecraft:obsidian)
B(-3,51,-1,minecraft:magma_block)
B(-3,51,0,minecraft:magma_block)
B(-3,51,1,minecraft:magma_block)
B(-3,51,2,minecraft:obsidian)
B(-3,51,3,minecraft:obsidian)
B(-3,51,4,minecraft:obsidian)
B(-3,51,5,minecraft:obsidian)
B(-3,51,6,minecraft:obsidian)
B(-3,51,7,minecraft:obsidian)
B(-3,51,8,minecraft:obsidian)
B(-3,52,-1,minecraft:magma_block)
B(-3,52,0,minecraft:magma_block)
B(-3,52,1,minecraft:magma_block)
B(-3,52,2,minecraft:obsidian)
B(-3,52,3,minecraft:obsidian)
B(-3,52,4,minecraft:obsidian)
B(-3,52,5,minecraft:obsidian)
B(-3,52,6,minecraft:obsidian)
B(-3,52,7,minecraft:obsidian)
B(-3,52,8,minecraft:obsidian)
B(-3,53,-1,minecraft:magma_block)
B(-3,53,0,minecraft:magma_block)
B(-3,53,1,minecraft:obsidian)
B(-3,53,2,minecraft:obsidian)
B(-3,53,3,minecraft:obsidian)
B(-3,53,4,minecraft:obsidian)
B(-3,53,5,minecraft:diorite)
B(-3,53,6,minecraft:diorite)
B(-3,53,7,minecraft:diorite)
B(-3,53,8,minecraft:obsidian)
B(-3,54,-2,minecraft:obsidian)
B(-3,54,-1,minecraft:obsidian)
B(-3,54,0,minecraft:obsidian)
B(-3,54,1,minecraft:obsidian)
B(-3,54,2,minecraft:diorite)
B(-3,54,3,minecraft:obsidian)
B(-3,54,4,minecraft:obsidian)
B(-3,54,5,minecraft:diorite)
B(-3,54,6,minecraft:diorite)
B(-3,54,7,minecraft:diorite)
B(-3,54,8,minecraft:obsidian)
B(-3,55,-3,minecraft:obsidian)
B(-3,55,-2,minecraft:obsidian)
B(-3,55,-1,minecraft:obsidian)
B(-3,55,0,minecraft:obsidian)
B(-3,55,1,minecraft:diorite)
B(-3,55,2,minecraft:obsidian)
B(-3,55,3,minecraft:obsidian)
B(-3,55,4,minecraft:obsidian)
B(-3,55,5,minecraft:diorite)
B(-3,55,6,minecraft:diorite)
B(-3,55,7,minecraft:diorite)
B(-3,55,8,minecraft:obsidian)
B(-3,56,-3,minecraft:diorite)
B(-3,56,-2,minecraft:diorite)
B(-3,56,-1,minecraft:diorite)
B(-3,56,0,minecraft:diorite)
B(-3,56,1,minecraft:diorite)
B(-3,56,2,minecraft:obsidian)
B(-3,56,3,minecraft:diorite)
B(-3,56,4,minecraft:diorite)
B(-3,56,5,minecraft:diorite)
B(-3,56,6,minecraft:diorite)
B(-3,56,7,minecraft:diorite)
B(-3,56,8,minecraft:obsidian)
B(-3,57,-4,minecraft:diorite)
B(-3,57,-3,minecraft:diorite)
B(-3,57,-2,minecraft:diorite)
B(-3,57,-1,minecraft:diorite)
B(-3,57,0,minecraft:diorite)
B(-3,57,1,minecraft:diorite)
B(-3,57,2,minecraft:diorite)
B(-3,57,3,minecraft:diorite)
B(-3,57,4,minecraft:diorite)
B(-3,57,5,minecraft:diorite)
B(-3,57,6,minecraft:diorite)
B(-3,57,7,minecraft:diorite)
B(-3,57,8,minecraft:obsidian)
B(-3,58,-6,minecraft:diorite)
B(-3,58,-5,minecraft:diorite)
B(-3,58,-4,minecraft:diorite)
B(-3,58,-3,minecraft:diorite)
B(-3,58,-2,minecraft:diorite)
B(-3,58,-1,minecraft:diorite)
B(-3,58,0,minecraft:diorite)
B(-3,58,1,minecraft:diorite)
B(-3,58,2,minecraft:diorite)
B(-3,58,3,minecraft:diorite)
B(-3,58,4,minecraft:diorite)
B(-3,58,5,minecraft:diorite)
B(-3,58,6,minecraft:andesite)
B(-3,59,-7,minecraft:diorite)
B(-3,59,-6,minecraft:diorite)
B(-3,59,-5,minecraft:diorite)
B(-3,59,-4,minecraft:diorite)
B(-3,59,-3,minecraft:diorite)
B(-3,59,-2,minecraft:diorite)
B(-3,59,-1,minecraft:diorite)
B(-3,59,0,minecraft:diorite)
B(-3,59,1,minecraft:obsidian)
B(-3,59,2,minecraft:diorite)
B(-3,59,3,minecraft:diorite)
B(-3,59,4,minecraft:diorite)
B(-3,60,-7,minecraft:diorite)
B(-3,60,-6,minecraft:diorite)
B(-3,60,-5,minecraft:diorite)
B(-3,60,-4,minecraft:diorite)
B(-3,60,-3,minecraft:diorite)
B(-3,60,-2,minecraft:diorite)
B(-3,60,-1,minecraft:diorite)
B(-3,60,0,minecraft:obsidian)
B(-3,60,1,minecraft:obsidian)
B(-3,60,2,minecraft:diorite)
B(-3,60,3,minecraft:diorite)
B(-3,61,-7,minecraft:diorite)
B(-3,61,-6,minecraft:diorite)
B(-3,61,-5,minecraft:diorite)
B(-3,61,-4,minecraft:diorite)
B(-3,61,-3,minecraft:diorite)
B(-3,61,-2,minecraft:diorite)
B(-3,61,-1,minecraft:diorite)
B(-3,61,0,minecraft:obsidian)
B(-3,61,1,minecraft:obsidian)
B(-3,61,2,minecraft:obsidian)
B(-3,61,3,minecraft:obsidian)
B(-3,61,4,minecraft:obsidian)
B(-3,62,-7,minecraft:diorite)
B(-3,62,-6,minecraft:diorite)
B(-3,62,-5,minecraft:diorite)
B(-3,62,-4,minecraft:diorite)
B(-3,62,-3,minecraft:diorite)
B(-3,62,-2,minecraft:diorite)
B(-3,62,-1,minecraft:diorite)
B(-3,62,0,minecraft:obsidian)
B(-3,62,1,minecraft:obsidian)
B(-3,62,2,minecraft:obsidian)
B(-3,62,3,minecraft:obsidian)
B(-3,62,4,minecraft:obsidian)
B(-3,62,5,minecraft:obsidian)
B(-3,63,-7,minecraft:diorite)
B(-3,63,-6,minecraft:diorite)
B(-3,63,-5,minecraft:diorite)
B(-3,63,-4,minecraft:diorite)
B(-3,63,-3,minecraft:diorite)
B(-3,63,-2,minecraft:diorite)
B(-3,63,-1,minecraft:obsidian)
B(-3,63,0,minecraft:obsidian)
B(-3,63,1,minecraft:obsidian)
B(-3,63,2,minecraft:obsidian)
B(-3,63,3,minecraft:obsidian)
B(-3,63,4,minecraft:obsidian)
B(-3,63,5,minecraft:obsidian)
B(-3,64,-7,minecraft:diorite)
B(-3,64,-6,minecraft:diorite)
B(-3,64,-5,minecraft:diorite)
B(-3,64,-4,minecraft:diorite)
B(-3,64,-3,minecraft:diorite)
B(-3,64,-2,minecraft:obsidian)
B(-3,64,-1,minecraft:obsidian)
B(-3,64,0,minecraft:obsidian)
B(-3,64,1,minecraft:obsidian)
B(-3,64,2,minecraft:obsidian)
B(-3,64,3,minecraft:obsidian)
B(-3,64,4,minecraft:obsidian)
B(-3,64,5,minecraft:obsidian)
B(-3,65,-7,minecraft:diorite)
B(-3,65,-6,minecraft:diorite)
B(-3,65,-5,minecraft:diorite)
B(-3,65,-4,minecraft:obsidian)
B(-3,65,-3,minecraft:obsidian)
B(-3,65,-2,minecraft:obsidian)
B(-3,65,-1,minecraft:obsidian)
B(-3,65,0,minecraft:obsidian)
B(-3,65,1,minecraft:obsidian)
B(-3,65,2,minecraft:obsidian)
B(-3,65,3,minecraft:obsidian)
B(-3,65,4,minecraft:obsidian)
B(-3,65,5,minecraft:obsidian)
B(-3,66,-7,minecraft:diorite)
B(-3,66,-6,minecraft:diorite)
B(-3,66,-5,minecraft:diorite)
B(-3,66,-4,minecraft:obsidian)
B(-3,66,-3,minecraft:obsidian)
B(-3,66,-2,minecraft:obsidian)
B(-3,66,-1,minecraft:obsidian)
B(-3,66,0,minecraft:obsidian)
B(-3,66,1,minecraft:obsidian)
B(-3,66,2,minecraft:obsidian)
B(-3,66,3,minecraft:obsidian)
B(-3,66,4,minecraft:obsidian)
B(-3,67,-7,minecraft:diorite)
B(-3,67,-6,minecraft:diorite)
B(-3,67,-5,minecraft:diorite)
B(-3,67,-4,minecraft:obsidian)
B(-3,67,-3,minecraft:obsidian)
B(-3,67,-2,minecraft:obsidian)
B(-3,67,-1,minecraft:obsidian)
B(-3,67,0,minecraft:obsidian)
B(-3,67,1,minecraft:obsidian)
B(-3,67,2,minecraft:obsidian)
B(-3,67,3,minecraft:obsidian)
B(-3,67,4,minecraft:obsidian)
B(-3,68,-7,minecraft:diorite)
B(-3,68,-6,minecraft:diorite)
B(-3,68,-5,minecraft:diorite)
B(-3,68,-4,minecraft:obsidian)
B(-3,68,-3,minecraft:obsidian)
B(-3,68,-2,minecraft:obsidian)
B(-3,68,-1,minecraft:obsidian)
B(-3,68,0,minecraft:obsidian)
B(-3,68,1,minecraft:obsidian)
B(-3,68,2,minecraft:obsidian)
B(-3,68,3,minecraft:obsidian)
B(-3,68,4,minecraft:obsidian)
B(-3,69,-7,minecraft:diorite)
B(-3,69,-6,minecraft:diorite)
B(-3,69,-5,minecraft:obsidian)
B(-3,69,-4,minecraft:obsidian)
B(-3,69,-3,minecraft:obsidian)
B(-3,69,-2,minecraft:obsidian)
B(-3,69,-1,minecraft:obsidian)
B(-3,69,0,minecraft:obsidian)
B(-3,69,1,minecraft:obsidian)
B(-3,69,2,minecraft:obsidian)
B(-3,69,3,minecraft:obsidian)
B(-3,69,4,minecraft:obsidian)
B(-3,70,-7,minecraft:diorite)
B(-3,70,-6,minecraft:obsidian)
B(-3,70,-5,minecraft:obsidian)
B(-3,70,-4,minecraft:obsidian)
B(-3,70,-3,minecraft:obsidian)
B(-3,70,-2,minecraft:obsidian)
B(-3,70,-1,minecraft:obsidian)
B(-3,70,0,minecraft:obsidian)
B(-3,70,1,minecraft:obsidian)
B(-3,70,2,minecraft:obsidian)
B(-3,70,3,minecraft:obsidian)
B(-3,70,4,minecraft:obsidian)
B(-3,71,-7,minecraft:obsidian)
B(-3,71,-6,minecraft:obsidian)
B(-3,71,-5,minecraft:obsidian)
B(-3,71,-4,minecraft:obsidian)
B(-3,71,-3,minecraft:obsidian)
B(-3,71,-2,minecraft:obsidian)
B(-3,71,-1,minecraft:obsidian)
B(-3,71,0,minecraft:obsidian)
B(-3,71,1,minecraft:obsidian)
B(-3,71,2,minecraft:obsidian)
B(-3,71,3,minecraft:obsidian)
B(-3,71,4,minecraft:obsidian)
B(-3,72,-7,minecraft:obsidian)
B(-3,72,-6,minecraft:obsidian)
B(-3,72,-5,minecraft:obsidian)
B(-3,72,-4,minecraft:obsidian)
B(-3,72,-3,minecraft:obsidian)
B(-3,72,-2,minecraft:obsidian)
B(-3,72,-1,minecraft:obsidian)
B(-3,72,0,minecraft:obsidian)
B(-3,72,1,minecraft:obsidian)
B(-3,72,2,minecraft:obsidian)
B(-3,72,3,minecraft:obsidian)
B(-3,72,4,minecraft:obsidian)
B(-3,73,-7,minecraft:diorite)
B(-3,73,-6,minecraft:diorite)
B(-3,73,-5,minecraft:diorite)
B(-3,73,-4,minecraft:obsidian)
B(-3,73,-3,minecraft:obsidian)
B(-3,73,-2,minecraft:obsidian)
B(-3,73,-1,minecraft:obsidian)
B(-3,73,0,minecraft:obsidian)
B(-3,73,1,minecraft:obsidian)
B(-3,73,2,minecraft:obsidian)
B(-3,73,3,minecraft:obsidian)
B(-3,73,4,minecraft:obsidian)
B(-3,73,5,minecraft:obsidian)
B(-3,74,-7,minecraft:andesite)
B(-3,74,-6,minecraft:andesite)
B(-3,74,-5,minecraft:andesite)
B(-3,74,-4,minecraft:diorite)
B(-3,74,-3,minecraft:diorite)
B(-3,74,-2,minecraft:diorite)
B(-3,74,-1,minecraft:diorite)
B(-3,74,0,minecraft:obsidian)
B(-3,74,1,minecraft:obsidian)
B(-3,74,2,minecraft:obsidian)
B(-3,74,3,minecraft:obsidian)
B(-3,74,4,minecraft:obsidian)
B(-3,74,5,minecraft:obsidian)
B(-3,75,-4,minecraft:andesite)
B(-3,75,-3,minecraft:andesite)
B(-3,75,-2,minecraft:diorite)
B(-3,75,-1,minecraft:diorite)
B(-3,75,0,minecraft:obsidian)
B(-3,75,1,minecraft:obsidian)
B(-3,75,2,minecraft:obsidian)
B(-3,75,3,minecraft:obsidian)
B(-3,75,4,minecraft:obsidian)
B(-3,76,-2,minecraft:andesite)
B(-3,76,-1,minecraft:diorite)
B(-3,76,0,minecraft:obsidian)
B(-3,76,1,minecraft:obsidian)
B(-3,76,2,minecraft:obsidian)
B(-3,76,3,minecraft:obsidian)
B(-3,76,4,minecraft:obsidian)
B(-3,76,5,minecraft:obsidian)
B(-3,76,7,minecraft:obsidian)
B(-3,76,8,minecraft:obsidian)
B(-3,77,-1,minecraft:diorite)
B(-3,77,0,minecraft:diorite)
B(-3,77,1,minecraft:diorite)
B(-3,77,2,minecraft:diorite)
B(-3,77,3,minecraft:obsidian)
B(-3,77,4,minecraft:obsidian)
B(-3,77,5,minecraft:obsidian)
B(-3,77,6,minecraft:obsidian)
B(-3,77,7,minecraft:obsidian)
B(-3,77,8,minecraft:obsidian)
B(-3,78,-1,minecraft:andesite)
B(-3,78,0,minecraft:diorite)
B(-3,78,1,minecraft:diorite)
B(-3,78,2,minecraft:diorite)
B(-3,78,3,minecraft:diorite)
B(-3,78,4,minecraft:obsidian)
B(-3,78,5,minecraft:obsidian)
B(-3,78,6,minecraft:obsidian)
B(-3,78,7,minecraft:obsidian)
B(-3,78,8,minecraft:obsidian)
B(-3,79,0,minecraft:diorite)
B(-3,79,1,minecraft:diorite)
B(-3,79,2,minecraft:diorite)
B(-3,79,3,minecraft:diorite)
B(-3,79,4,minecraft:obsidian)
B(-3,79,5,minecraft:obsidian)
B(-3,79,6,minecraft:obsidian)
B(-3,79,7,minecraft:obsidian)
B(-3,79,8,minecraft:obsidian)
B(-3,80,-1,minecraft:diorite)
B(-3,80,0,minecraft:diorite)
B(-3,80,1,minecraft:diorite)
B(-3,80,2,minecraft:diorite)
B(-3,80,3,minecraft:diorite)
B(-3,80,4,minecraft:obsidian)
B(-3,80,5,minecraft:obsidian)
B(-3,80,6,minecraft:obsidian)
B(-3,80,7,minecraft:obsidian)
B(-3,80,8,minecraft:obsidian)
B(-3,81,-2,minecraft:diorite)
B(-3,81,-1,minecraft:diorite)
B(-3,81,0,minecraft:diorite)
B(-3,81,1,minecraft:diorite)
B(-3,81,2,minecraft:diorite)
B(-3,81,3,minecraft:diorite)
B(-3,81,4,minecraft:diorite)
B(-3,81,5,minecraft:diorite)
B(-3,81,6,minecraft:diorite)
B(-3,81,7,minecraft:diorite)
B(-3,81,8,minecraft:obsidian)
B(-3,82,-1,minecraft:andesite)
B(-3,82,0,minecraft:diorite)
B(-3,82,1,minecraft:diorite)
B(-3,82,2,minecraft:diorite)
B(-3,82,3,minecraft:diorite)
B(-3,82,4,minecraft:diorite)
B(-3,82,5,minecraft:diorite)
B(-3,82,6,minecraft:diorite)
B(-3,82,7,minecraft:diorite)
B(-3,82,8,minecraft:diorite)
B(-3,83,0,minecraft:andesite)
B(-3,83,1,minecraft:diorite)
B(-3,83,2,minecraft:diorite)
B(-3,83,3,minecraft:diorite)
B(-3,83,4,minecraft:diorite)
B(-3,83,5,minecraft:diorite)
B(-3,83,6,minecraft:diorite)
B(-3,83,7,minecraft:diorite)
B(-3,83,8,minecraft:diorite)
B(-3,84,1,minecraft:andesite)
B(-3,84,2,minecraft:andesite)
B(-3,84,3,minecraft:diorite)
B(-3,84,4,minecraft:diorite)
B(-3,84,5,minecraft:diorite)
B(-3,84,6,minecraft:diorite)
B(-3,84,7,minecraft:diorite)
B(-3,84,8,minecraft:diorite)
B(-3,85,3,minecraft:andesite)
B(-3,85,4,minecraft:diorite)
B(-3,85,5,minecraft:diorite)
B(-3,85,6,minecraft:diorite)
B(-3,85,7,minecraft:diorite)
B(-3,85,8,minecraft:diorite)
B(-3,86,4,minecraft:andesite)
B(-3,86,5,minecraft:diorite)
B(-3,86,6,minecraft:diorite)
B(-3,86,7,minecraft:diorite)
B(-3,86,8,minecraft:diorite)
B(-3,87,5,minecraft:andesite)
B(-3,87,6,minecraft:diorite)
B(-3,87,7,minecraft:diorite)
B(-3,87,8,minecraft:diorite)
B(-3,88,6,minecraft:andesite)
B(-3,88,7,minecraft:diorite)
B(-3,88,8,minecraft:diorite)
B(-3,89,7,minecraft:andesite)
B(-3,89,8,minecraft:andesite)
B(-2,34,6,minecraft:diorite)
B(-2,34,7,minecraft:diorite)
B(-2,34,8,minecraft:diorite)
B(-2,35,6,minecraft:diorite)
B(-2,35,7,minecraft:diorite)
B(-2,35,8,minecraft:diorite)
B(-2,36,7,minecraft:diorite)
B(-2,36,8,minecraft:diorite)
B(-2,37,6,minecraft:diorite)
B(-2,37,7,minecraft:diorite)
B(-2,37,8,minecraft:diorite)
B(-2,38,5,minecraft:diorite)
B(-2,38,6,minecraft:diorite)
B(-2,38,7,minecraft:diorite)
B(-2,38,8,minecraft:diorite)
B(-2,39,4,minecraft:diorite)
B(-2,39,5,minecraft:diorite)
B(-2,39,6,minecraft:diorite)
B(-2,39,7,minecraft:obsidian)
B(-2,39,8,minecraft:obsidian)
B(-2,40,3,minecraft:diorite)
B(-2,40,4,minecraft:diorite)
B(-2,40,5,minecraft:diorite)
B(-2,40,6,minecraft:obsidian)
B(-2,40,7,minecraft:obsidian)
B(-2,40,8,minecraft:obsidian)
B(-2,41,2,minecraft:diorite)
B(-2,41,3,minecraft:diorite)
B(-2,41,4,minecraft:diorite)
B(-2,41,5,minecraft:diorite)
B(-2,41,6,minecraft:obsidian)
B(-2,41,7,minecraft:obsidian)
B(-2,41,8,minecraft:obsidian)
B(-2,42,2,minecraft:diorite)
B(-2,42,3,minecraft:diorite)
B(-2,42,4,minecraft:diorite)
B(-2,42,5,minecraft:diorite)
B(-2,42,6,minecraft:obsidian)
B(-2,42,7,minecraft:obsidian)
B(-2,42,8,minecraft:obsidian)
B(-2,43,2,minecraft:diorite)
B(-2,43,3,minecraft:diorite)
B(-2,43,4,minecraft:diorite)
B(-2,43,5,minecraft:diorite)
B(-2,43,6,minecraft:diorite)
B(-2,43,7,minecraft:obsidian)
B(-2,43,8,minecraft:obsidian)
B(-2,44,2,minecraft:obsidian)
B(-2,44,3,minecraft:obsidian)
B(-2,44,4,minecraft:diorite)
B(-2,44,5,minecraft:diorite)
B(-2,44,6,minecraft:diorite)
B(-2,44,7,minecraft:diorite)
B(-2,44,8,minecraft:diorite)
B(-2,45,1,minecraft:obsidian)
B(-2,45,2,minecraft:obsidian)
B(-2,45,3,minecraft:obsidian)
B(-2,45,4,minecraft:obsidian)
B(-2,45,5,minecraft:diorite)
B(-2,45,6,minecraft:diorite)
B(-2,45,7,minecraft:diorite)
B(-2,45,8,minecraft:diorite)
B(-2,46,0,minecraft:obsidian)
B(-2,46,1,minecraft:obsidian)
B(-2,46,2,minecraft:obsidian)
B(-2,46,3,minecraft:obsidian)
B(-2,46,4,minecraft:obsidian)
B(-2,46,5,minecraft:diorite)
B(-2,46,6,minecraft:diorite)
B(-2,46,7,minecraft:diorite)
B(-2,46,8,minecraft:obsidian)
B(-2,47,0,minecraft:obsidian)
B(-2,47,1,minecraft:obsidian)
B(-2,47,2,minecraft:obsidian)
B(-2,47,3,minecraft:obsidian)
B(-2,47,4,minecraft:obsidian)
B(-2,47,5,minecraft:diorite)
B(-2,47,6,minecraft:diorite)
B(-2,47,7,minecraft:obsidian)
B(-2,47,8,minecraft:obsidian)
B(-2,48,-1,minecraft:magma_block)
B(-2,48,0,minecraft:magma_block)
B(-2,48,1,minecraft:magma_block)
B(-2,48,2,minecraft:obsidian)
B(-2,48,3,minecraft:obsidian)
B(-2,48,4,minecraft:obsidian)
B(-2,48,5,minecraft:diorite)
B(-2,48,6,minecraft:obsidian)
B(-2,48,7,minecraft:obsidian)
B(-2,48,8,minecraft:obsidian)
B(-2,49,-2,minecraft:magma_block)
B(-2,49,-1,minecraft:magma_block)
B(-2,49,0,minecraft:magma_block)
B(-2,49,1,minecraft:magma_block)
B(-2,49,2,minecraft:obsidian)
B(-2,49,3,minecraft:obsidian)
B(-2,49,4,minecraft:obsidian)
B(-2,49,5,minecraft:obsidian)
B(-2,49,6,minecraft:obsidian)
B(-2,49,7,minecraft:obsidian)
B(-2,49,8,minecraft:obsidian)
B(-2,50,-2,minecraft:magma_block)
B(-2,50,-1,minecraft:magma_block)
B(-2,50,0,minecraft:magma_block)
B(-2,50,1,minecraft:magma_block)
B(-2,50,2,minecraft:obsidian)
B(-2,50,3,minecraft:obsidian)
B(-2,50,4,minecraft:diorite)
B(-2,50,5,minecraft:obsidian)
B(-2,50,6,minecraft:obsidian)
B(-2,50,7,minecraft:obsidian)
B(-2,50,8,minecraft:obsidian)
B(-2,51,-1,minecraft:magma_block)
B(-2,51,0,minecraft:magma_block)
B(-2,51,1,minecraft:magma_block)
B(-2,51,2,minecraft:obsidian)
B(-2,51,3,minecraft:obsidian)
B(-2,51,4,minecraft:diorite)
B(-2,51,5,minecraft:obsidian)
B(-2,51,6,minecraft:obsidian)
B(-2,51,7,minecraft:obsidian)
B(-2,51,8,minecraft:obsidian)
B(-2,52,0,minecraft:magma_block)
B(-2,52,1,minecraft:magma_block)
B(-2,52,2,minecraft:obsidian)
B(-2,52,3,minecraft:obsidian)
B(-2,52,4,minecraft:obsidian)
B(-2,52,5,minecraft:obsidian)
B(-2,52,6,minecraft:obsidian)
B(-2,52,7,minecraft:obsidian)
B(-2,52,8,minecraft:obsidian)
B(-2,53,0,minecraft:magma_block)
B(-2,53,1,minecraft:obsidian)
B(-2,53,2,minecraft:obsidian)
B(-2,53,3,minecraft:obsidian)
B(-2,53,4,minecraft:obsidian)
B(-2,53,5,minecraft:obsidian)
B(-2,53,6,minecraft:obsidian)
B(-2,53,7,minecraft:obsidian)
B(-2,53,8,minecraft:obsidian)
B(-2,54,-2,minecraft:obsidian)
B(-2,54,-1,minecraft:obsidian)
B(-2,54,0,minecraft:obsidian)
B(-2,54,1,minecraft:obsidian)
B(-2,54,2,minecraft:diorite)
B(-2,54,3,minecraft:obsidian)
B(-2,54,4,minecraft:obsidian)
B(-2,54,5,minecraft:obsidian)
B(-2,54,6,minecraft:obsidian)
B(-2,54,7,minecraft:obsidian)
B(-2,54,8,minecraft:obsidian)
B(-2,55,-3,minecraft:obsidian)
B(-2,55,-2,minecraft:obsidian)
B(-2,55,-1,minecraft:obsidian)
B(-2,55,0,minecraft:obsidian)
B(-2,55,1,minecraft:diorite)
B(-2,55,2,minecraft:diorite)
B(-2,55,3,minecraft:obsidian)
B(-2,55,4,minecraft:obsidian)
B(-2,55,5,minecraft:obsidian)
B(-2,55,6,minecraft:obsidian)
B(-2,55,7,minecraft:obsidian)
B(-2,55,8,minecraft:obsidian)
B(-2,56,-3,minecraft:diorite)
B(-2,56,-2,minecraft:diorite)
B(-2,56,-1,minecraft:diorite)
B(-2,56,0,minecraft:diorite)
B(-2,56,1,minecraft:diorite)
B(-2,56,2,minecraft:diorite)
B(-2,56,3,minecraft:obsidian)
B(-2,56,4,minecraft:obsidian)
B(-2,56,5,minecraft:obsidian)
B(-2,56,6,minecraft:obsidian)
B(-2,56,7,minecraft:obsidian)
B(-2,56,8,minecraft:obsidian)
B(-2,57,-4,minecraft:diorite)
B(-2,57,-3,minecraft:diorite)
B(-2,57,-2,minecraft:diorite)
B(-2,57,-1,minecraft:diorite)
B(-2,57,0,minecraft:diorite)
B(-2,57,1,minecraft:diorite)
B(-2,57,2,minecraft:diorite)
B(-2,57,3,minecraft:diorite)
B(-2,57,4,minecraft:diorite)
