
#######################################################################
# +-----------------------------------------------------------------+ #
# |                            BO4 object                           | #
# +-----------------------------------------------------------------+ #
#######################################################################

Author: NLBlackEagle

Description: No description given

SettingsMode: WriteWithoutComments


#######################################################################
# +-----------------------------------------------------------------+ #
# |                          Main settings                          | #
# +-----------------------------------------------------------------+ #
#######################################################################

Frequency: 0

SpawnHeight: highestBlock

UseCenterForHighestBlock: true

##############################
# Height Limits for the BO4. #
##############################

MinHeight: 0

MaxHeight: 255

InheritBO3: 

InheritBO3Rotation: NORTH

OverrideChildSettings: true

OverrideParentHeight: false

CanOverride: false

BranchFrequency: 0

BranchFrequencyGroup: 

MustBeBelowOther: false

MustBeInside: 

CannotBeInside: 

ReplacesBO3: 

MustBeInsideWorldBorders: false

CanSpawnOnWater: true

SpawnOnWaterOnly: false

SpawnUnderWater: false

SpawnAtWaterLevel: false

HeightOffset: 0

RemoveAir: true

ReplaceAbove: 

ReplaceBelow: 

ReplaceWithBiomeBlocks: true

ReplaceWithSurfaceBlock: GRASS

ReplaceWithGroundBlock: DIRT

ReplaceWithStoneBlock: STONE

SmoothRadius: 0

SmoothHeightOffset: 0

SmoothStartTop: false

SmoothStartWood: false

SmoothingSurfaceBlock: 

SmoothingGroundBlock: 

BO3Group: 

IsSpawnPoint: false

DoReplaceBlocks: true


#######################################################################
# +-----------------------------------------------------------------+ #
# |                              Blocks                             | #
# +-----------------------------------------------------------------+ #
#######################################################################

Block(-8,8,8,STONE:3)
Block(-8,9,2,STONE:3)
Block(-8,9,3,STONE:3)
Block(-8,9,4,STONE:3)
Block(-8,9,5,STONE:3)
Block(-8,9,6,STONE:3)
Block(-8,9,7,STONE:3)
Block(-8,9,8,STONE:3)
Block(-8,10,-3,STONE:3)
Block(-8,10,-2,STONE:3)
Block(-8,10,-1,STONE:3)
Block(-8,10,0,STONE:3)
Block(-8,10,1,STONE:3)
Block(-8,10,2,STONE:3)
Block(-8,10,3,STONE:3)
Block(-8,10,4,STONE:3)
Block(-8,10,5,STONE:3)
Block(-8,10,6,STONE:3)
Block(-8,10,7,STONE:3)
Block(-8,10,8,STONE:3)
Block(-8,11,-4,STONE:3)
Block(-8,11,-3,STONE:3)
Block(-8,11,-2,STONE:3)
Block(-8,11,-1,STONE:3)
Block(-8,11,0,STONE:3)
Block(-8,11,1,STONE:3)
Block(-8,11,2,STONE:3)
Block(-8,11,3,STONE:3)
Block(-8,11,4,STONE:3)
Block(-8,11,5,STONE:3)
Block(-8,11,6,STONE:3)
Block(-8,11,7,STONE:3)
Block(-8,11,8,STONE:3)
Block(-8,12,-7,STONE:3)
Block(-8,12,-6,STONE:3)
Block(-8,12,-5,STONE:3)
Block(-8,12,-4,STONE:3)
Block(-8,12,-3,STONE:3)
Block(-8,12,-2,STONE:3)
Block(-8,12,-1,STONE:3)
Block(-8,12,0,STONE:3)
Block(-8,12,1,STONE:3)
Block(-8,12,2,STONE:3)
Block(-8,12,3,STONE:3)
Block(-8,12,4,STONE:3)
Block(-8,12,5,STONE:3)
Block(-8,12,6,STONE:3)
Block(-8,12,7,STONE:3)
Block(-8,12,8,STONE:3)
Block(-8,13,-7,STONE:3)
Block(-8,13,-6,STONE:3)
Block(-8,13,-5,STONE:3)
Block(-8,13,-4,STONE:3)
Block(-8,13,-3,STONE:3)
Block(-8,13,-2,STONE:3)
Block(-8,13,-1,STONE:3)
Block(-8,13,0,STONE:3)
Block(-8,13,1,STONE:3)
Block(-8,13,2,STONE:3)
Block(-8,13,3,STONE:3)
Block(-8,13,4,STONE:3)
Block(-8,13,5,STONE:3)
Block(-8,13,6,STONE:3)
Block(-8,13,7,STONE:3)
Block(-8,13,8,STONE:3)
Block(-8,14,-7,STONE:3)
Block(-8,14,-6,STONE:3)
Block(-8,14,-5,STONE:3)
Block(-8,14,-4,STONE:3)
Block(-8,14,-3,STONE:3)
Block(-8,14,-2,STONE:3)
Block(-8,14,-1,STONE:3)
Block(-8,14,0,STONE:3)
Block(-8,14,1,STONE:3)
Block(-8,14,2,OBSIDIAN:0)
Block(-8,14,3,OBSIDIAN:0)
Block(-8,14,4,STONE:3)
Block(-8,14,5,STONE:3)
Block(-8,14,6,STONE:3)
Block(-8,14,7,STONE:3)
Block(-8,14,8,STONE:3)
Block(-8,15,-7,STONE:3)
Block(-8,15,-6,STONE:3)
Block(-8,15,-5,STONE:3)
Block(-8,15,-4,STONE:3)
Block(-8,15,-3,STONE:3)
Block(-8,15,-2,STONE:3)
Block(-8,15,-1,STONE:3)
Block(-8,15,0,STONE:3)
Block(-8,15,1,OBSIDIAN:0)
Block(-8,15,2,OBSIDIAN:0)
Block(-8,15,3,OBSIDIAN:0)
Block(-8,15,4,OBSIDIAN:0)
Block(-8,15,5,OBSIDIAN:0)
Block(-8,15,6,OBSIDIAN:0)
Block(-8,15,7,OBSIDIAN:0)
Block(-8,15,8,OBSIDIAN:0)
Block(-8,16,-7,STONE:3)
Block(-8,16,-6,STONE:3)
Block(-8,16,-5,STONE:3)
Block(-8,16,-4,STONE:3)
Block(-8,16,-3,STONE:3)
Block(-8,16,-2,STONE:3)
Block(-8,16,-1,STONE:3)
Block(-8,16,0,STONE:3)
Block(-8,16,1,OBSIDIAN:0)
Block(-8,16,2,OBSIDIAN:0)
Block(-8,16,3,OBSIDIAN:0)
Block(-8,16,4,OBSIDIAN:0)
Block(-8,16,5,OBSIDIAN:0)
Block(-8,16,6,OBSIDIAN:0)
Block(-8,16,7,OBSIDIAN:0)
Block(-8,16,8,OBSIDIAN:0)
Block(-8,17,-7,OBSIDIAN:0)
Block(-8,17,-6,STONE:3)
Block(-8,17,-5,STONE:3)
Block(-8,17,-4,STONE:3)
Block(-8,17,-3,STONE:3)
Block(-8,17,-2,STONE:3)
Block(-8,17,-1,STONE:3)
Block(-8,17,0,OBSIDIAN:0)
Block(-8,17,1,OBSIDIAN:0)
Block(-8,17,2,OBSIDIAN:0)
Block(-8,17,3,OBSIDIAN:0)
Block(-8,17,4,OBSIDIAN:0)
Block(-8,17,5,OBSIDIAN:0)
Block(-8,17,6,OBSIDIAN:0)
Block(-8,17,7,OBSIDIAN:0)
Block(-8,17,8,OBSIDIAN:0)
Block(-8,18,-7,OBSIDIAN:0)
Block(-8,18,-6,OBSIDIAN:0)
Block(-8,18,-5,OBSIDIAN:0)
Block(-8,18,-4,OBSIDIAN:0)
Block(-8,18,-3,OBSIDIAN:0)
Block(-8,18,-2,OBSIDIAN:0)
Block(-8,18,-1,OBSIDIAN:0)
Block(-8,18,0,OBSIDIAN:0)
Block(-8,18,1,OBSIDIAN:0)
Block(-8,18,2,OBSIDIAN:0)
Block(-8,18,3,OBSIDIAN:0)
Block(-8,18,4,OBSIDIAN:0)
Block(-8,18,5,OBSIDIAN:0)
Block(-8,18,6,OBSIDIAN:0)
Block(-8,18,7,OBSIDIAN:0)
Block(-8,18,8,OBSIDIAN:0)
Block(-8,19,-7,OBSIDIAN:0)
Block(-8,19,-6,OBSIDIAN:0)
Block(-8,19,-5,OBSIDIAN:0)
Block(-8,19,-4,OBSIDIAN:0)
Block(-8,19,-3,OBSIDIAN:0)
Block(-8,19,-2,OBSIDIAN:0)
Block(-8,19,-1,OBSIDIAN:0)
Block(-8,19,0,OBSIDIAN:0)
Block(-8,19,1,OBSIDIAN:0)
Block(-8,19,2,OBSIDIAN:0)
Block(-8,19,3,OBSIDIAN:0)
Block(-8,19,4,OBSIDIAN:0)
Block(-8,19,5,OBSIDIAN:0)
Block(-8,19,6,OBSIDIAN:0)
Block(-8,19,7,OBSIDIAN:0)
Block(-8,19,8,OBSIDIAN:0)
Block(-8,20,-7,OBSIDIAN:0)
Block(-8,20,-6,OBSIDIAN:0)
Block(-8,20,-5,OBSIDIAN:0)
Block(-8,20,-4,OBSIDIAN:0)
Block(-8,20,-3,OBSIDIAN:0)
Block(-8,20,-2,OBSIDIAN:0)
Block(-8,20,-1,OBSIDIAN:0)
Block(-8,20,0,OBSIDIAN:0)
Block(-8,20,1,OBSIDIAN:0)
Block(-8,20,2,OBSIDIAN:0)
Block(-8,20,3,OBSIDIAN:0)
Block(-8,20,4,OBSIDIAN:0)
Block(-8,20,5,OBSIDIAN:0)
Block(-8,20,6,OBSIDIAN:0)
Block(-8,20,7,OBSIDIAN:0)
Block(-8,20,8,OBSIDIAN:0)
Block(-8,21,-7,OBSIDIAN:0)
Block(-8,21,-6,OBSIDIAN:0)
Block(-8,21,-5,OBSIDIAN:0)
Block(-8,21,-4,OBSIDIAN:0)
Block(-8,21,-3,OBSIDIAN:0)
Block(-8,21,-2,OBSIDIAN:0)
Block(-8,21,-1,OBSIDIAN:0)
Block(-8,21,0,OBSIDIAN:0)
Block(-8,21,1,OBSIDIAN:0)
Block(-8,21,2,OBSIDIAN:0)
Block(-8,21,3,OBSIDIAN:0)
Block(-8,21,4,OBSIDIAN:0)
Block(-8,21,5,OBSIDIAN:0)
Block(-8,21,6,OBSIDIAN:0)
Block(-8,21,7,OBSIDIAN:0)
Block(-8,21,8,OBSIDIAN:0)
Block(-8,22,-7,OBSIDIAN:0)
Block(-8,22,-6,OBSIDIAN:0)
Block(-8,22,-5,OBSIDIAN:0)
Block(-8,22,-4,STONE:3)
Block(-8,22,-3,STONE:3)
Block(-8,22,-2,STONE:3)
Block(-8,22,-1,STONE:3)
Block(-8,22,0,OBSIDIAN:0)
Block(-8,22,1,OBSIDIAN:0)
Block(-8,22,2,OBSIDIAN:0)
Block(-8,22,3,OBSIDIAN:0)
Block(-8,22,4,OBSIDIAN:0)
Block(-8,22,5,OBSIDIAN:0)
Block(-8,22,6,OBSIDIAN:0)
Block(-8,22,7,OBSIDIAN:0)
Block(-8,22,8,OBSIDIAN:0)
Block(-8,23,-7,OBSIDIAN:0)
Block(-8,23,-6,OBSIDIAN:0)
Block(-8,23,-5,STONE:3)
Block(-8,23,-4,STATIONARY_LAVA:0)
Block(-8,23,-3,STATIONARY_LAVA:0)
Block(-8,23,-2,STATIONARY_LAVA:0)
Block(-8,23,-1,STATIONARY_LAVA:0)
Block(-8,23,0,STATIONARY_LAVA:0)
Block(-8,23,1,STATIONARY_LAVA:0)
Block(-8,23,2,STATIONARY_LAVA:0)
Block(-8,23,3,STATIONARY_LAVA:0)
Block(-8,23,4,STATIONARY_LAVA:0)
Block(-8,23,5,STATIONARY_LAVA:0)
Block(-8,23,6,STATIONARY_LAVA:0)
Block(-8,23,7,STATIONARY_LAVA:0)
Block(-8,23,8,OBSIDIAN:0)
Block(-8,24,-7,OBSIDIAN:0)
Block(-8,24,-6,OBSIDIAN:0)
Block(-8,25,-7,OBSIDIAN:0)
Block(-8,25,-6,OBSIDIAN:0)
Block(-8,25,-5,STONE:3)
Block(-8,26,-7,OBSIDIAN:0)
Block(-8,26,-6,OBSIDIAN:0)
Block(-8,26,-5,OBSIDIAN:0)
Block(-8,27,-7,OBSIDIAN:0)
Block(-8,27,-6,OBSIDIAN:0)
Block(-8,73,-1,OBSIDIAN:0)
Block(-8,73,0,OBSIDIAN:0)
Block(-8,73,1,OBSIDIAN:0)
Block(-8,73,2,OBSIDIAN:0)
Block(-8,73,3,OBSIDIAN:0)
Block(-8,73,4,OBSIDIAN:0)
Block(-8,73,5,OBSIDIAN:0)
Block(-8,73,6,OBSIDIAN:0)
Block(-8,73,7,OBSIDIAN:0)
Block(-8,74,-5,OBSIDIAN:0)
Block(-8,74,-4,OBSIDIAN:0)
Block(-8,74,-3,OBSIDIAN:0)
Block(-8,74,-2,OBSIDIAN:0)
Block(-8,74,-1,OBSIDIAN:0)
Block(-8,74,0,OBSIDIAN:0)
Block(-8,74,1,OBSIDIAN:0)
Block(-8,74,2,OBSIDIAN:0)
Block(-8,74,3,OBSIDIAN:0)
Block(-8,74,4,OBSIDIAN:0)
Block(-8,74,5,OBSIDIAN:0)
Block(-8,74,6,OBSIDIAN:0)
Block(-8,74,7,OBSIDIAN:0)
Block(-8,74,8,OBSIDIAN:0)
Block(-8,75,-7,OBSIDIAN:0)
Block(-8,75,-6,OBSIDIAN:0)
Block(-8,75,-5,OBSIDIAN:0)
Block(-8,75,-4,OBSIDIAN:0)
Block(-8,75,-3,OBSIDIAN:0)
Block(-8,75,-2,OBSIDIAN:0)
Block(-8,75,-1,OBSIDIAN:0)
Block(-8,75,0,OBSIDIAN:0)
Block(-8,75,1,OBSIDIAN:0)
Block(-8,75,2,OBSIDIAN:0)
Block(-8,75,3,OBSIDIAN:0)
Block(-8,75,4,OBSIDIAN:0)
Block(-8,75,5,OBSIDIAN:0)
Block(-8,75,6,OBSIDIAN:0)
Block(-8,75,7,OBSIDIAN:0)
Block(-8,75,8,OBSIDIAN:0)
Block(-8,76,-7,OBSIDIAN:0)
Block(-8,76,-6,OBSIDIAN:0)
Block(-8,76,-5,OBSIDIAN:0)
Block(-8,76,-4,OBSIDIAN:0)
Block(-8,76,-3,OBSIDIAN:0)
Block(-8,76,-2,OBSIDIAN:0)
Block(-8,76,-1,OBSIDIAN:0)
Block(-8,76,0,OBSIDIAN:0)
Block(-8,76,1,OBSIDIAN:0)
Block(-8,76,2,OBSIDIAN:0)
Block(-8,76,3,OBSIDIAN:0)
Block(-8,76,4,OBSIDIAN:0)
Block(-8,76,5,OBSIDIAN:0)
Block(-8,76,6,OBSIDIAN:0)
Block(-8,76,7,OBSIDIAN:0)
Block(-8,76,8,OBSIDIAN:0)
Block(-8,77,-7,OBSIDIAN:0)
Block(-8,77,-6,OBSIDIAN:0)
Block(-8,77,-5,OBSIDIAN:0)
Block(-8,77,-4,OBSIDIAN:0)
Block(-8,77,-3,OBSIDIAN:0)
Block(-8,77,-2,OBSIDIAN:0)
Block(-8,77,-1,OBSIDIAN:0)
Block(-8,77,0,OBSIDIAN:0)
Block(-8,77,1,OBSIDIAN:0)
Block(-8,77,2,OBSIDIAN:0)
Block(-8,77,3,OBSIDIAN:0)
Block(-8,77,4,OBSIDIAN:0)
Block(-8,77,5,OBSIDIAN:0)
Block(-8,77,6,OBSIDIAN:0)
Block(-8,77,7,OBSIDIAN:0)
Block(-8,77,8,OBSIDIAN:0)
Block(-8,78,-7,OBSIDIAN:0)
Block(-8,78,-6,OBSIDIAN:0)
Block(-8,78,-5,OBSIDIAN:0)
Block(-8,78,-4,OBSIDIAN:0)
Block(-8,78,-3,OBSIDIAN:0)
Block(-8,78,-2,OBSIDIAN:0)
Block(-8,78,-1,OBSIDIAN:0)
Block(-8,78,0,OBSIDIAN:0)
Block(-8,78,1,OBSIDIAN:0)
Block(-8,78,2,OBSIDIAN:0)
Block(-8,78,3,OBSIDIAN:0)
Block(-8,78,4,OBSIDIAN:0)
Block(-8,78,5,OBSIDIAN:0)
Block(-8,78,6,OBSIDIAN:0)
Block(-8,78,7,OBSIDIAN:0)
Block(-8,78,8,OBSIDIAN:0)
Block(-8,79,-7,OBSIDIAN:0)
Block(-8,79,-6,OBSIDIAN:0)
Block(-8,79,-5,OBSIDIAN:0)
Block(-8,79,-4,OBSIDIAN:0)
Block(-8,79,-3,OBSIDIAN:0)
Block(-8,79,-2,OBSIDIAN:0)
Block(-8,79,-1,OBSIDIAN:0)
Block(-8,79,0,OBSIDIAN:0)
Block(-8,79,1,OBSIDIAN:0)
Block(-8,79,2,OBSIDIAN:0)
Block(-8,79,3,OBSIDIAN:0)
Block(-8,79,4,OBSIDIAN:0)
Block(-8,79,5,OBSIDIAN:0)
Block(-8,79,6,OBSIDIAN:0)
Block(-8,79,7,OBSIDIAN:0)
Block(-8,79,8,OBSIDIAN:0)
Block(-8,80,-7,OBSIDIAN:0)
Block(-8,80,-6,OBSIDIAN:0)
Block(-8,80,-5,OBSIDIAN:0)
Block(-8,80,-4,OBSIDIAN:0)
Block(-8,80,-3,OBSIDIAN:0)
Block(-8,80,-2,OBSIDIAN:0)
Block(-8,80,-1,OBSIDIAN:0)
Block(-8,80,0,OBSIDIAN:0)
Block(-8,80,1,OBSIDIAN:0)
Block(-8,80,2,OBSIDIAN:0)
Block(-8,80,3,OBSIDIAN:0)
Block(-8,80,4,OBSIDIAN:0)
Block(-8,80,5,OBSIDIAN:0)
Block(-8,80,6,OBSIDIAN:0)
Block(-8,80,7,OBSIDIAN:0)
Block(-8,80,8,OBSIDIAN:0)
Block(-8,81,-7,OBSIDIAN:0)
Block(-8,81,-6,OBSIDIAN:0)
Block(-8,81,-5,OBSIDIAN:0)
Block(-8,81,-4,OBSIDIAN:0)
Block(-8,81,-3,OBSIDIAN:0)
Block(-8,81,-2,OBSIDIAN:0)
Block(-8,81,-1,OBSIDIAN:0)
Block(-8,81,0,OBSIDIAN:0)
Block(-8,81,1,OBSIDIAN:0)
Block(-8,81,2,OBSIDIAN:0)
Block(-8,81,3,OBSIDIAN:0)
Block(-8,81,4,OBSIDIAN:0)
Block(-8,81,5,OBSIDIAN:0)
Block(-8,81,6,OBSIDIAN:0)
Block(-8,81,7,OBSIDIAN:0)
Block(-8,81,8,OBSIDIAN:0)
Block(-8,82,-7,OBSIDIAN:0)
Block(-8,82,-6,OBSIDIAN:0)
Block(-8,82,-5,OBSIDIAN:0)
Block(-8,82,-4,OBSIDIAN:0)
Block(-8,82,-3,OBSIDIAN:0)
Block(-8,82,-2,OBSIDIAN:0)
Block(-8,82,-1,OBSIDIAN:0)
Block(-8,82,0,OBSIDIAN:0)
Block(-8,82,1,OBSIDIAN:0)
Block(-8,82,2,OBSIDIAN:0)
Block(-8,82,3,OBSIDIAN:0)
Block(-8,82,4,OBSIDIAN:0)
Block(-8,82,5,OBSIDIAN:0)
Block(-8,82,6,OBSIDIAN:0)
Block(-8,82,7,OBSIDIAN:0)
Block(-8,82,8,OBSIDIAN:0)
Block(-8,83,-7,OBSIDIAN:0)
Block(-8,83,-6,OBSIDIAN:0)
Block(-8,83,-5,OBSIDIAN:0)
Block(-8,83,-4,OBSIDIAN:0)
Block(-8,83,-3,OBSIDIAN:0)
Block(-8,83,-2,OBSIDIAN:0)
Block(-8,83,-1,OBSIDIAN:0)
Block(-8,83,0,OBSIDIAN:0)
Block(-8,83,1,OBSIDIAN:0)
Block(-8,83,2,OBSIDIAN:0)
Block(-8,83,3,OBSIDIAN:0)
Block(-8,83,4,OBSIDIAN:0)
Block(-8,83,5,OBSIDIAN:0)
Block(-8,83,6,OBSIDIAN:0)
Block(-8,83,7,OBSIDIAN:0)
Block(-8,83,8,OBSIDIAN:0)
Block(-8,84,-7,OBSIDIAN:0)
Block(-8,84,-6,OBSIDIAN:0)
Block(-8,84,-5,OBSIDIAN:0)
Block(-8,84,-4,OBSIDIAN:0)
Block(-8,84,-3,OBSIDIAN:0)
Block(-8,84,-2,OBSIDIAN:0)
Block(-8,84,-1,OBSIDIAN:0)
Block(-8,84,0,OBSIDIAN:0)
Block(-8,84,1,OBSIDIAN:0)
Block(-8,84,2,OBSIDIAN:0)
Block(-8,84,3,OBSIDIAN:0)
Block(-8,84,4,OBSIDIAN:0)
Block(-8,84,5,OBSIDIAN:0)
Block(-8,84,6,OBSIDIAN:0)
Block(-8,84,7,OBSIDIAN:0)
Block(-8,84,8,OBSIDIAN:0)
Block(-8,85,-7,OBSIDIAN:0)
Block(-8,85,-6,OBSIDIAN:0)
Block(-8,85,-5,OBSIDIAN:0)
Block(-8,85,-4,OBSIDIAN:0)
Block(-8,85,-3,OBSIDIAN:0)
Block(-8,85,-2,OBSIDIAN:0)
Block(-8,85,-1,OBSIDIAN:0)
Block(-8,85,0,OBSIDIAN:0)
Block(-8,85,1,OBSIDIAN:0)
Block(-8,85,2,OBSIDIAN:0)
Block(-8,85,3,OBSIDIAN:0)
Block(-8,85,4,OBSIDIAN:0)
Block(-8,85,5,OBSIDIAN:0)
Block(-8,85,6,OBSIDIAN:0)
Block(-8,85,7,OBSIDIAN:0)
Block(-8,85,8,OBSIDIAN:0)
Block(-8,86,-7,OBSIDIAN:0)
Block(-8,86,-6,OBSIDIAN:0)
Block(-8,86,-5,OBSIDIAN:0)
Block(-8,86,-4,OBSIDIAN:0)
Block(-8,86,-3,OBSIDIAN:0)
Block(-8,86,-2,OBSIDIAN:0)
Block(-8,86,-1,OBSIDIAN:0)
Block(-8,86,0,OBSIDIAN:0)
Block(-8,86,1,OBSIDIAN:0)
Block(-8,86,2,OBSIDIAN:0)
Block(-8,86,3,OBSIDIAN:0)
Block(-8,86,4,OBSIDIAN:0)
Block(-8,86,5,OBSIDIAN:0)
Block(-8,86,6,OBSIDIAN:0)
Block(-8,86,7,OBSIDIAN:0)
Block(-8,86,8,OBSIDIAN:0)
Block(-8,87,-7,OBSIDIAN:0)
Block(-8,87,-6,OBSIDIAN:0)
Block(-8,87,-5,OBSIDIAN:0)
Block(-8,87,-4,OBSIDIAN:0)
Block(-8,87,-3,OBSIDIAN:0)
Block(-8,87,-2,OBSIDIAN:0)
Block(-8,87,-1,OBSIDIAN:0)
Block(-8,87,0,OBSIDIAN:0)
Block(-8,87,1,OBSIDIAN:0)
Block(-8,87,2,OBSIDIAN:0)
Block(-8,87,3,OBSIDIAN:0)
Block(-8,87,4,OBSIDIAN:0)
Block(-8,87,5,OBSIDIAN:0)
Block(-8,87,6,OBSIDIAN:0)
Block(-8,87,7,OBSIDIAN:0)
Block(-8,87,8,OBSIDIAN:0)
Block(-8,88,-7,OBSIDIAN:0)
Block(-8,88,-6,OBSIDIAN:0)
Block(-8,88,-5,OBSIDIAN:0)
Block(-8,88,-4,OBSIDIAN:0)
Block(-8,88,-3,OBSIDIAN:0)
Block(-8,88,-2,OBSIDIAN:0)
Block(-8,88,-1,OBSIDIAN:0)
Block(-8,88,0,OBSIDIAN:0)
Block(-8,88,1,OBSIDIAN:0)
Block(-8,88,2,OBSIDIAN:0)
Block(-8,88,3,OBSIDIAN:0)
Block(-8,88,4,OBSIDIAN:0)
Block(-8,88,5,OBSIDIAN:0)
Block(-8,88,6,OBSIDIAN:0)
Block(-8,88,7,OBSIDIAN:0)
Block(-8,88,8,OBSIDIAN:0)
Block(-8,89,-7,OBSIDIAN:0)
Block(-8,89,-6,OBSIDIAN:0)
Block(-8,89,-5,OBSIDIAN:0)
Block(-8,89,-4,OBSIDIAN:0)
Block(-8,89,-3,OBSIDIAN:0)
Block(-8,89,-2,OBSIDIAN:0)
Block(-8,89,-1,OBSIDIAN:0)
Block(-8,89,0,OBSIDIAN:0)
Block(-8,89,1,OBSIDIAN:0)
Block(-8,89,2,OBSIDIAN:0)
Block(-8,89,3,OBSIDIAN:0)
Block(-8,89,4,OBSIDIAN:0)
Block(-8,89,5,OBSIDIAN:0)
Block(-8,89,6,STONE:3)
Block(-8,89,7,STONE:3)
Block(-8,89,8,STONE:3)
Block(-8,90,-7,OBSIDIAN:0)
Block(-8,90,-6,OBSIDIAN:0)
Block(-8,90,-5,OBSIDIAN:0)
Block(-8,90,-4,OBSIDIAN:0)
Block(-8,90,-3,OBSIDIAN:0)
Block(-8,90,-2,OBSIDIAN:0)
Block(-8,90,-1,OBSIDIAN:0)
Block(-8,90,0,OBSIDIAN:0)
Block(-8,90,1,OBSIDIAN:0)
Block(-8,90,2,OBSIDIAN:0)
Block(-8,90,3,OBSIDIAN:0)
Block(-8,90,4,OBSIDIAN:0)
Block(-8,90,5,STONE:3)
Block(-8,90,6,STONE:3)
Block(-8,90,7,STONE:3)
Block(-8,90,8,STONE:3)
Block(-8,91,-7,OBSIDIAN:0)
Block(-8,91,-6,OBSIDIAN:0)
Block(-8,91,-5,OBSIDIAN:0)
Block(-8,91,-4,OBSIDIAN:0)
Block(-8,91,-3,OBSIDIAN:0)
Block(-8,91,-2,OBSIDIAN:0)
Block(-8,91,-1,OBSIDIAN:0)
Block(-8,91,0,OBSIDIAN:0)
Block(-8,91,1,OBSIDIAN:0)
Block(-8,91,2,OBSIDIAN:0)
Block(-8,91,3,OBSIDIAN:0)
Block(-8,91,4,OBSIDIAN:0)
Block(-8,91,5,STONE:3)
Block(-8,91,6,STONE:3)
Block(-8,91,7,STONE:3)
Block(-8,91,8,STONE:3)
Block(-8,92,-7,OBSIDIAN:0)
Block(-8,92,-6,OBSIDIAN:0)
Block(-8,92,-5,OBSIDIAN:0)
Block(-8,92,-4,OBSIDIAN:0)
Block(-8,92,-3,OBSIDIAN:0)
Block(-8,92,-2,OBSIDIAN:0)
Block(-8,92,-1,OBSIDIAN:0)
Block(-8,92,0,OBSIDIAN:0)
Block(-8,92,1,OBSIDIAN:0)
Block(-8,92,2,OBSIDIAN:0)
Block(-8,92,3,OBSIDIAN:0)
Block(-8,92,4,STONE:3)
Block(-8,92,5,STONE:5)
Block(-8,92,6,STONE:3)
Block(-8,92,7,STONE:3)
Block(-8,92,8,STONE:3)
Block(-8,93,-7,OBSIDIAN:0)
Block(-8,93,-6,OBSIDIAN:0)
Block(-8,93,-5,OBSIDIAN:0)
Block(-8,93,-4,OBSIDIAN:0)
Block(-8,93,-3,OBSIDIAN:0)
Block(-8,93,-2,OBSIDIAN:0)
Block(-8,93,-1,OBSIDIAN:0)
Block(-8,93,0,OBSIDIAN:0)
Block(-8,93,1,OBSIDIAN:0)
Block(-8,93,2,OBSIDIAN:0)
Block(-8,93,3,OBSIDIAN:0)
Block(-8,93,4,STONE:5)
Block(-8,94,-7,OBSIDIAN:0)
Block(-8,94,-6,OBSIDIAN:0)
Block(-8,94,-5,OBSIDIAN:0)
Block(-8,94,-4,OBSIDIAN:0)
Block(-8,94,-3,OBSIDIAN:0)
Block(-8,94,-2,OBSIDIAN:0)
Block(-8,94,-1,OBSIDIAN:0)
Block(-8,94,0,OBSIDIAN:0)
Block(-8,94,1,OBSIDIAN:0)
Block(-8,94,2,OBSIDIAN:0)
Block(-8,94,3,STONE:3)
Block(-8,95,-7,OBSIDIAN:0)
Block(-8,95,-6,OBSIDIAN:0)
Block(-8,95,-5,OBSIDIAN:0)
Block(-8,95,-4,OBSIDIAN:0)
Block(-8,95,-3,OBSIDIAN:0)
Block(-8,95,-2,OBSIDIAN:0)
Block(-8,95,-1,OBSIDIAN:0)
Block(-8,95,0,OBSIDIAN:0)
Block(-8,95,1,OBSIDIAN:0)
Block(-8,95,2,STONE:3)
Block(-8,95,3,STONE:5)
Block(-8,96,-7,OBSIDIAN:0)
Block(-8,96,-6,OBSIDIAN:0)
Block(-8,96,-5,OBSIDIAN:0)
Block(-8,96,-4,OBSIDIAN:0)
Block(-8,96,-3,OBSIDIAN:0)
Block(-8,96,-2,OBSIDIAN:0)
Block(-8,96,-1,OBSIDIAN:0)
Block(-8,96,0,STONE:3)
Block(-8,96,1,STONE:3)
Block(-8,96,2,STONE:5)
Block(-8,97,-7,OBSIDIAN:0)
Block(-8,97,-6,OBSIDIAN:0)
Block(-8,97,-5,OBSIDIAN:0)
Block(-8,97,-4,OBSIDIAN:0)
Block(-8,97,-3,OBSIDIAN:0)
Block(-8,97,-2,OBSIDIAN:0)
Block(-8,97,-1,OBSIDIAN:0)
Block(-8,97,0,STONE:5)
Block(-8,97,1,STONE:3)
Block(-8,98,-7,OBSIDIAN:0)
Block(-8,98,-6,OBSIDIAN:0)
Block(-8,98,-5,OBSIDIAN:0)
Block(-8,98,-4,OBSIDIAN:0)
Block(-8,98,-3,OBSIDIAN:0)
Block(-8,98,-2,OBSIDIAN:0)
Block(-8,98,-1,STONE:3)
Block(-8,99,-7,OBSIDIAN:0)
Block(-8,99,-6,OBSIDIAN:0)
Block(-8,99,-5,OBSIDIAN:0)
Block(-8,99,-4,OBSIDIAN:0)
Block(-8,99,-3,OBSIDIAN:0)
Block(-8,99,-2,STONE:3)
Block(-8,99,-1,STONE:5)
Block(-8,100,-7,STONE:3)
Block(-8,100,-6,STONE:3)
Block(-8,100,-5,STONE:3)
Block(-8,100,-4,STONE:3)
Block(-8,100,-3,STONE:3)
Block(-8,100,-2,STONE:5)
Block(-8,101,-7,STONE:3)
Block(-8,101,-6,STONE:5)
Block(-8,101,-5,STONE:5)
Block(-8,101,-4,STONE:5)
Block(-8,101,-3,STONE:5)
Block(-7,9,3,STONE:3)
Block(-7,9,4,STONE:3)
Block(-7,9,5,STONE:3)
Block(-7,9,6,STONE:3)
Block(-7,9,7,STONE:3)
Block(-7,9,8,STONE:3)
Block(-7,10,-2,STONE:3)
Block(-7,10,-1,STONE:3)
Block(-7,10,0,STONE:3)
Block(-7,10,1,STONE:3)
Block(-7,10,2,STONE:3)
Block(-7,10,3,STONE:3)
Block(-7,10,4,STONE:3)
Block(-7,10,5,STONE:3)
Block(-7,10,6,STONE:3)
Block(-7,10,7,STONE:3)
Block(-7,10,8,STONE:3)
Block(-7,11,-4,STONE:3)
Block(-7,11,-3,STONE:3)
Block(-7,11,-2,STONE:3)
Block(-7,11,-1,STONE:3)
Block(-7,11,0,STONE:3)
Block(-7,11,1,STONE:3)
Block(-7,11,2,STONE:3)
Block(-7,11,3,STONE:3)
Block(-7,11,4,STONE:3)
Block(-7,11,5,STONE:3)
Block(-7,11,6,STONE:3)
Block(-7,11,7,STONE:3)
Block(-7,11,8,STONE:3)
Block(-7,12,-7,STONE:3)
Block(-7,12,-6,STONE:3)
Block(-7,12,-5,STONE:3)
Block(-7,12,-4,STONE:3)
Block(-7,12,-3,STONE:3)
Block(-7,12,-2,STONE:3)
Block(-7,12,-1,STONE:3)
Block(-7,12,0,STONE:3)
Block(-7,12,1,STONE:3)
Block(-7,12,2,STONE:3)
Block(-7,12,3,STONE:3)
Block(-7,12,4,STONE:3)
Block(-7,12,5,STONE:3)
Block(-7,12,6,STONE:3)
Block(-7,12,7,STONE:3)
Block(-7,12,8,STONE:3)
Block(-7,13,-7,STONE:3)
Block(-7,13,-6,STONE:3)
Block(-7,13,-5,STONE:3)
Block(-7,13,-4,STONE:3)
Block(-7,13,-3,STONE:3)
Block(-7,13,-2,STONE:3)
Block(-7,13,-1,STONE:3)
Block(-7,13,0,STONE:3)
Block(-7,13,1,STONE:3)
Block(-7,13,2,STONE:3)
Block(-7,13,3,STONE:3)
Block(-7,13,4,STONE:3)
Block(-7,13,5,STONE:3)
Block(-7,13,6,STONE:3)
Block(-7,13,7,STONE:3)
Block(-7,13,8,STONE:3)
Block(-7,14,-7,STONE:3)
Block(-7,14,-6,STONE:3)
Block(-7,14,-5,STONE:3)
Block(-7,14,-4,STONE:3)
Block(-7,14,-3,STONE:3)
Block(-7,14,-2,STONE:3)
Block(-7,14,-1,STONE:3)
Block(-7,14,0,STONE:3)
Block(-7,14,1,STONE:3)
Block(-7,14,2,OBSIDIAN:0)
Block(-7,14,3,OBSIDIAN:0)
Block(-7,14,4,STONE:3)
Block(-7,14,5,STONE:3)
Block(-7,14,6,STONE:3)
Block(-7,14,7,STONE:3)
Block(-7,14,8,OBSIDIAN:0)
Block(-7,15,-7,STONE:3)
Block(-7,15,-6,STONE:3)
Block(-7,15,-5,STONE:3)
Block(-7,15,-4,STONE:3)
Block(-7,15,-3,STONE:3)
Block(-7,15,-2,STONE:3)
Block(-7,15,-1,STONE:3)
Block(-7,15,0,STONE:3)
Block(-7,15,1,OBSIDIAN:0)
Block(-7,15,2,OBSIDIAN:0)
Block(-7,15,3,OBSIDIAN:0)
Block(-7,15,4,OBSIDIAN:0)
Block(-7,15,5,OBSIDIAN:0)
Block(-7,15,6,OBSIDIAN:0)
Block(-7,15,7,OBSIDIAN:0)
Block(-7,15,8,OBSIDIAN:0)
Block(-7,16,-7,STONE:3)
Block(-7,16,-6,STONE:3)
Block(-7,16,-5,STONE:3)
Block(-7,16,-4,STONE:3)
Block(-7,16,-3,STONE:3)
Block(-7,16,-2,STONE:3)
Block(-7,16,-1,OBSIDIAN:0)
Block(-7,16,0,OBSIDIAN:0)
Block(-7,16,1,OBSIDIAN:0)
Block(-7,16,2,OBSIDIAN:0)
Block(-7,16,3,OBSIDIAN:0)
Block(-7,16,4,OBSIDIAN:0)
Block(-7,16,5,OBSIDIAN:0)
Block(-7,16,6,OBSIDIAN:0)
Block(-7,16,7,OBSIDIAN:0)
Block(-7,16,8,OBSIDIAN:0)
Block(-7,17,-7,OBSIDIAN:0)
Block(-7,17,-6,OBSIDIAN:0)
Block(-7,17,-5,OBSIDIAN:0)
Block(-7,17,-4,OBSIDIAN:0)
Block(-7,17,-3,OBSIDIAN:0)
Block(-7,17,-2,OBSIDIAN:0)
Block(-7,17,-1,OBSIDIAN:0)
Block(-7,17,0,OBSIDIAN:0)
Block(-7,17,1,OBSIDIAN:0)
Block(-7,17,2,OBSIDIAN:0)
Block(-7,17,3,OBSIDIAN:0)
Block(-7,17,4,OBSIDIAN:0)
Block(-7,17,5,OBSIDIAN:0)
Block(-7,17,6,OBSIDIAN:0)
Block(-7,17,7,OBSIDIAN:0)
Block(-7,17,8,OBSIDIAN:0)
Block(-7,18,-7,OBSIDIAN:0)
Block(-7,18,-6,OBSIDIAN:0)
Block(-7,18,-5,OBSIDIAN:0)
Block(-7,18,-4,OBSIDIAN:0)
Block(-7,18,-3,OBSIDIAN:0)
Block(-7,18,-2,OBSIDIAN:0)
Block(-7,18,-1,OBSIDIAN:0)
Block(-7,18,0,OBSIDIAN:0)
Block(-7,18,1,OBSIDIAN:0)
Block(-7,18,2,OBSIDIAN:0)
Block(-7,18,3,OBSIDIAN:0)
Block(-7,18,4,OBSIDIAN:0)
Block(-7,18,5,OBSIDIAN:0)
Block(-7,18,6,OBSIDIAN:0)
Block(-7,18,7,OBSIDIAN:0)
Block(-7,18,8,OBSIDIAN:0)
Block(-7,19,-7,OBSIDIAN:0)
Block(-7,19,-6,OBSIDIAN:0)
Block(-7,19,-5,OBSIDIAN:0)
Block(-7,19,-4,OBSIDIAN:0)
Block(-7,19,-3,OBSIDIAN:0)
Block(-7,19,-2,OBSIDIAN:0)
Block(-7,19,-1,OBSIDIAN:0)
Block(-7,19,0,OBSIDIAN:0)
Block(-7,19,1,OBSIDIAN:0)
Block(-7,19,2,OBSIDIAN:0)
Block(-7,19,3,OBSIDIAN:0)
Block(-7,19,4,OBSIDIAN:0)
Block(-7,19,5,OBSIDIAN:0)
Block(-7,19,6,OBSIDIAN:0)
Block(-7,19,7,OBSIDIAN:0)
Block(-7,19,8,OBSIDIAN:0)
Block(-7,20,-7,OBSIDIAN:0)
Block(-7,20,-6,OBSIDIAN:0)
Block(-7,20,-5,OBSIDIAN:0)
Block(-7,20,-4,OBSIDIAN:0)
Block(-7,20,-3,OBSIDIAN:0)
Block(-7,20,-2,OBSIDIAN:0)
Block(-7,20,-1,OBSIDIAN:0)
Block(-7,20,0,OBSIDIAN:0)
Block(-7,20,1,OBSIDIAN:0)
Block(-7,20,2,OBSIDIAN:0)
Block(-7,20,3,OBSIDIAN:0)
Block(-7,20,4,OBSIDIAN:0)
Block(-7,20,5,OBSIDIAN:0)
Block(-7,20,6,OBSIDIAN:0)
Block(-7,20,7,OBSIDIAN:0)
Block(-7,20,8,OBSIDIAN:0)
Block(-7,21,-7,OBSIDIAN:0)
Block(-7,21,-6,OBSIDIAN:0)
Block(-7,21,-5,OBSIDIAN:0)
Block(-7,21,-4,OBSIDIAN:0)
Block(-7,21,-3,OBSIDIAN:0)
Block(-7,21,-2,OBSIDIAN:0)
Block(-7,21,-1,OBSIDIAN:0)
Block(-7,21,0,OBSIDIAN:0)
Block(-7,21,1,OBSIDIAN:0)
Block(-7,21,2,OBSIDIAN:0)
Block(-7,21,3,OBSIDIAN:0)
Block(-7,21,4,OBSIDIAN:0)
Block(-7,21,5,OBSIDIAN:0)
Block(-7,21,6,OBSIDIAN:0)
Block(-7,21,7,OBSIDIAN:0)
Block(-7,21,8,OBSIDIAN:0)
Block(-7,22,-7,OBSIDIAN:0)
Block(-7,22,-6,OBSIDIAN:0)
Block(-7,22,-5,STONE:3)
Block(-7,22,-4,STONE:3)
Block(-7,22,-3,STONE:3)
Block(-7,22,-2,STONE:3)
Block(-7,22,-1,OBSIDIAN:0)
Block(-7,22,0,OBSIDIAN:0)
Block(-7,22,1,OBSIDIAN:0)
Block(-7,22,2,OBSIDIAN:0)
Block(-7,22,3,OBSIDIAN:0)
Block(-7,22,4,OBSIDIAN:0)
Block(-7,22,5,OBSIDIAN:0)
Block(-7,22,6,OBSIDIAN:0)
Block(-7,22,7,OBSIDIAN:0)
Block(-7,22,8,OBSIDIAN:0)
Block(-7,23,-7,OBSIDIAN:0)
Block(-7,23,-6,STONE:3)
Block(-7,23,-5,STONE:3)
Block(-7,23,-4,STATIONARY_LAVA:0)
Block(-7,23,-3,STATIONARY_LAVA:0)
Block(-7,23,-2,STATIONARY_LAVA:0)
Block(-7,23,-1,STATIONARY_LAVA:0)
Block(-7,23,0,STATIONARY_LAVA:0)
Block(-7,23,1,STATIONARY_LAVA:0)
Block(-7,23,2,STATIONARY_LAVA:0)
Block(-7,23,3,STATIONARY_LAVA:0)
Block(-7,23,4,STATIONARY_LAVA:0)
Block(-7,23,5,OBSIDIAN:0)
Block(-7,23,6,OBSIDIAN:0)
Block(-7,23,7,STONE:5)
Block(-7,23,8,STONE:5)
Block(-7,24,-7,OBSIDIAN:0)
Block(-7,24,-6,STONE:3)
Block(-7,24,5,OBSIDIAN:0)
Block(-7,24,6,STONE:5)
Block(-7,24,7,STONE:5)
Block(-7,24,8,STONE:5)
Block(-7,25,-7,OBSIDIAN:0)
Block(-7,25,-6,STONE:3)
Block(-7,25,8,STONE:5)
Block(-7,26,-7,OBSIDIAN:0)
Block(-7,26,-6,OBSIDIAN:0)
Block(-7,27,-7,OBSIDIAN:0)
Block(-7,73,-3,OBSIDIAN:0)
Block(-7,73,-2,OBSIDIAN:0)
Block(-7,73,-1,OBSIDIAN:0)
Block(-7,73,0,OBSIDIAN:0)
Block(-7,73,1,OBSIDIAN:0)
Block(-7,73,2,OBSIDIAN:0)
Block(-7,73,3,OBSIDIAN:0)
Block(-7,73,4,OBSIDIAN:0)
Block(-7,73,5,OBSIDIAN:0)
Block(-7,73,6,OBSIDIAN:0)
Block(-7,73,7,OBSIDIAN:0)
Block(-7,74,-6,OBSIDIAN:0)
Block(-7,74,-5,OBSIDIAN:0)
Block(-7,74,-4,OBSIDIAN:0)
Block(-7,74,-3,OBSIDIAN:0)
Block(-7,74,-2,OBSIDIAN:0)
Block(-7,74,-1,OBSIDIAN:0)
Block(-7,74,0,OBSIDIAN:0)
Block(-7,74,1,OBSIDIAN:0)
Block(-7,74,2,OBSIDIAN:0)
Block(-7,74,3,OBSIDIAN:0)
Block(-7,74,4,OBSIDIAN:0)
Block(-7,74,5,OBSIDIAN:0)
Block(-7,74,6,OBSIDIAN:0)
Block(-7,74,7,OBSIDIAN:0)
Block(-7,74,8,OBSIDIAN:0)
Block(-7,75,-7,OBSIDIAN:0)
Block(-7,75,-6,OBSIDIAN:0)
Block(-7,75,-5,OBSIDIAN:0)
Block(-7,75,-4,OBSIDIAN:0)
Block(-7,75,-3,OBSIDIAN:0)
Block(-7,75,-2,OBSIDIAN:0)
Block(-7,75,-1,OBSIDIAN:0)
Block(-7,75,0,OBSIDIAN:0)
Block(-7,75,1,OBSIDIAN:0)
Block(-7,75,2,OBSIDIAN:0)
Block(-7,75,3,OBSIDIAN:0)
Block(-7,75,4,OBSIDIAN:0)
Block(-7,75,5,OBSIDIAN:0)
Block(-7,75,6,OBSIDIAN:0)
Block(-7,75,7,OBSIDIAN:0)
Block(-7,75,8,OBSIDIAN:0)
Block(-7,76,-7,OBSIDIAN:0)
Block(-7,76,-6,OBSIDIAN:0)
Block(-7,76,-5,OBSIDIAN:0)
Block(-7,76,-4,OBSIDIAN:0)
Block(-7,76,-3,OBSIDIAN:0)
Block(-7,76,-2,OBSIDIAN:0)
Block(-7,76,-1,OBSIDIAN:0)
Block(-7,76,0,OBSIDIAN:0)
Block(-7,76,1,OBSIDIAN:0)
Block(-7,76,2,OBSIDIAN:0)
Block(-7,76,3,OBSIDIAN:0)
Block(-7,76,4,OBSIDIAN:0)
Block(-7,76,5,OBSIDIAN:0)
Block(-7,76,6,OBSIDIAN:0)
Block(-7,76,7,OBSIDIAN:0)
Block(-7,76,8,OBSIDIAN:0)
Block(-7,77,-7,OBSIDIAN:0)
Block(-7,77,-6,OBSIDIAN:0)
Block(-7,77,-5,OBSIDIAN:0)
Block(-7,77,-4,OBSIDIAN:0)
Block(-7,77,-3,OBSIDIAN:0)
Block(-7,77,-2,OBSIDIAN:0)
Block(-7,77,-1,OBSIDIAN:0)
Block(-7,77,0,OBSIDIAN:0)
Block(-7,77,1,OBSIDIAN:0)
Block(-7,77,2,OBSIDIAN:0)
Block(-7,77,3,OBSIDIAN:0)
Block(-7,77,4,OBSIDIAN:0)
Block(-7,77,5,OBSIDIAN:0)
Block(-7,77,6,OBSIDIAN:0)
Block(-7,77,7,OBSIDIAN:0)
Block(-7,77,8,OBSIDIAN:0)
Block(-7,78,-7,OBSIDIAN:0)
Block(-7,78,-6,OBSIDIAN:0)
Block(-7,78,-5,OBSIDIAN:0)
Block(-7,78,-4,OBSIDIAN:0)
Block(-7,78,-3,OBSIDIAN:0)
Block(-7,78,-2,OBSIDIAN:0)
Block(-7,78,-1,OBSIDIAN:0)
Block(-7,78,0,OBSIDIAN:0)
Block(-7,78,1,OBSIDIAN:0)
Block(-7,78,2,OBSIDIAN:0)
Block(-7,78,3,OBSIDIAN:0)
Block(-7,78,4,OBSIDIAN:0)
Block(-7,78,5,OBSIDIAN:0)
Block(-7,78,6,OBSIDIAN:0)
Block(-7,78,7,OBSIDIAN:0)
Block(-7,78,8,OBSIDIAN:0)
Block(-7,79,-7,OBSIDIAN:0)
Block(-7,79,-6,OBSIDIAN:0)
Block(-7,79,-5,OBSIDIAN:0)
Block(-7,79,-4,OBSIDIAN:0)
Block(-7,79,-3,OBSIDIAN:0)
Block(-7,79,-2,OBSIDIAN:0)
Block(-7,79,-1,OBSIDIAN:0)
Block(-7,79,0,OBSIDIAN:0)
Block(-7,79,1,OBSIDIAN:0)
Block(-7,79,2,OBSIDIAN:0)
Block(-7,79,3,OBSIDIAN:0)
Block(-7,79,4,OBSIDIAN:0)
Block(-7,79,5,OBSIDIAN:0)
Block(-7,79,6,OBSIDIAN:0)
Block(-7,79,7,OBSIDIAN:0)
Block(-7,79,8,OBSIDIAN:0)
Block(-7,80,-7,OBSIDIAN:0)
Block(-7,80,-6,OBSIDIAN:0)
Block(-7,80,-5,OBSIDIAN:0)
Block(-7,80,-4,OBSIDIAN:0)
Block(-7,80,-3,OBSIDIAN:0)
Block(-7,80,-2,OBSIDIAN:0)
Block(-7,80,-1,OBSIDIAN:0)
Block(-7,80,0,OBSIDIAN:0)
Block(-7,80,1,OBSIDIAN:0)
Block(-7,80,2,OBSIDIAN:0)
Block(-7,80,3,OBSIDIAN:0)
Block(-7,80,4,OBSIDIAN:0)
Block(-7,80,5,OBSIDIAN:0)
Block(-7,80,6,OBSIDIAN:0)
Block(-7,80,7,OBSIDIAN:0)
Block(-7,80,8,OBSIDIAN:0)
Block(-7,81,-7,OBSIDIAN:0)
Block(-7,81,-6,OBSIDIAN:0)
Block(-7,81,-5,OBSIDIAN:0)
Block(-7,81,-4,OBSIDIAN:0)
Block(-7,81,-3,OBSIDIAN:0)
Block(-7,81,-2,OBSIDIAN:0)
Block(-7,81,-1,OBSIDIAN:0)
Block(-7,81,0,OBSIDIAN:0)
Block(-7,81,1,OBSIDIAN:0)
Block(-7,81,2,OBSIDIAN:0)
Block(-7,81,3,OBSIDIAN:0)
Block(-7,81,4,OBSIDIAN:0)
Block(-7,81,5,OBSIDIAN:0)
Block(-7,81,6,OBSIDIAN:0)
Block(-7,81,7,OBSIDIAN:0)
Block(-7,81,8,OBSIDIAN:0)
Block(-7,82,-7,OBSIDIAN:0)
Block(-7,82,-6,OBSIDIAN:0)
Block(-7,82,-5,OBSIDIAN:0)
Block(-7,82,-4,OBSIDIAN:0)
Block(-7,82,-3,OBSIDIAN:0)
Block(-7,82,-2,OBSIDIAN:0)
Block(-7,82,-1,OBSIDIAN:0)
Block(-7,82,0,OBSIDIAN:0)
Block(-7,82,1,OBSIDIAN:0)
Block(-7,82,2,OBSIDIAN:0)
Block(-7,82,3,OBSIDIAN:0)
Block(-7,82,4,OBSIDIAN:0)
Block(-7,82,5,OBSIDIAN:0)
Block(-7,82,6,OBSIDIAN:0)
Block(-7,82,7,OBSIDIAN:0)
Block(-7,82,8,OBSIDIAN:0)
Block(-7,83,-7,OBSIDIAN:0)
Block(-7,83,-6,OBSIDIAN:0)
Block(-7,83,-5,OBSIDIAN:0)
Block(-7,83,-4,OBSIDIAN:0)
Block(-7,83,-3,OBSIDIAN:0)
Block(-7,83,-2,OBSIDIAN:0)
Block(-7,83,-1,OBSIDIAN:0)
Block(-7,83,0,OBSIDIAN:0)
Block(-7,83,1,OBSIDIAN:0)
Block(-7,83,2,OBSIDIAN:0)
Block(-7,83,3,OBSIDIAN:0)
Block(-7,83,4,OBSIDIAN:0)
Block(-7,83,5,OBSIDIAN:0)
Block(-7,83,6,OBSIDIAN:0)
Block(-7,83,7,OBSIDIAN:0)
Block(-7,83,8,OBSIDIAN:0)
Block(-7,84,-7,OBSIDIAN:0)
Block(-7,84,-6,OBSIDIAN:0)
Block(-7,84,-5,OBSIDIAN:0)
Block(-7,84,-4,OBSIDIAN:0)
Block(-7,84,-3,OBSIDIAN:0)
Block(-7,84,-2,OBSIDIAN:0)
Block(-7,84,-1,OBSIDIAN:0)
Block(-7,84,0,OBSIDIAN:0)
Block(-7,84,1,OBSIDIAN:0)
Block(-7,84,2,OBSIDIAN:0)
Block(-7,84,3,OBSIDIAN:0)
Block(-7,84,4,OBSIDIAN:0)
Block(-7,84,5,OBSIDIAN:0)
Block(-7,84,6,OBSIDIAN:0)
Block(-7,84,7,OBSIDIAN:0)
Block(-7,84,8,OBSIDIAN:0)
Block(-7,85,-7,OBSIDIAN:0)
Block(-7,85,-6,OBSIDIAN:0)
Block(-7,85,-5,OBSIDIAN:0)
Block(-7,85,-4,OBSIDIAN:0)
Block(-7,85,-3,OBSIDIAN:0)
Block(-7,85,-2,OBSIDIAN:0)
Block(-7,85,-1,OBSIDIAN:0)
Block(-7,85,0,OBSIDIAN:0)
Block(-7,85,1,OBSIDIAN:0)
Block(-7,85,2,OBSIDIAN:0)
Block(-7,85,3,OBSIDIAN:0)
Block(-7,85,4,OBSIDIAN:0)
Block(-7,85,5,OBSIDIAN:0)
Block(-7,85,6,OBSIDIAN:0)
Block(-7,85,7,OBSIDIAN:0)
Block(-7,85,8,OBSIDIAN:0)
Block(-7,86,-7,OBSIDIAN:0)
Block(-7,86,-6,OBSIDIAN:0)
Block(-7,86,-5,OBSIDIAN:0)
Block(-7,86,-4,OBSIDIAN:0)
Block(-7,86,-3,OBSIDIAN:0)
Block(-7,86,-2,OBSIDIAN:0)
Block(-7,86,-1,OBSIDIAN:0)
Block(-7,86,0,OBSIDIAN:0)
Block(-7,86,1,OBSIDIAN:0)
Block(-7,86,2,OBSIDIAN:0)
Block(-7,86,3,OBSIDIAN:0)
Block(-7,86,4,OBSIDIAN:0)
Block(-7,86,5,OBSIDIAN:0)
Block(-7,86,6,OBSIDIAN:0)
Block(-7,86,7,OBSIDIAN:0)
Block(-7,86,8,OBSIDIAN:0)
Block(-7,87,-7,OBSIDIAN:0)
Block(-7,87,-6,OBSIDIAN:0)
Block(-7,87,-5,OBSIDIAN:0)
Block(-7,87,-4,OBSIDIAN:0)
Block(-7,87,-3,OBSIDIAN:0)
Block(-7,87,-2,OBSIDIAN:0)
Block(-7,87,-1,OBSIDIAN:0)
Block(-7,87,0,OBSIDIAN:0)
Block(-7,87,1,OBSIDIAN:0)
Block(-7,87,2,OBSIDIAN:0)
Block(-7,87,3,OBSIDIAN:0)
Block(-7,87,4,OBSIDIAN:0)
Block(-7,87,5,OBSIDIAN:0)
Block(-7,87,6,OBSIDIAN:0)
Block(-7,87,7,OBSIDIAN:0)
Block(-7,87,8,OBSIDIAN:0)
Block(-7,88,-7,OBSIDIAN:0)
Block(-7,88,-6,OBSIDIAN:0)
Block(-7,88,-5,OBSIDIAN:0)
Block(-7,88,-4,OBSIDIAN:0)
Block(-7,88,-3,OBSIDIAN:0)
Block(-7,88,-2,OBSIDIAN:0)
Block(-7,88,-1,OBSIDIAN:0)
Block(-7,88,0,OBSIDIAN:0)
Block(-7,88,1,OBSIDIAN:0)
Block(-7,88,2,OBSIDIAN:0)
Block(-7,88,3,OBSIDIAN:0)
Block(-7,88,4,OBSIDIAN:0)
Block(-7,88,5,OBSIDIAN:0)
Block(-7,88,6,STONE:3)
Block(-7,88,7,STONE:3)
Block(-7,88,8,STONE:3)
Block(-7,89,-7,OBSIDIAN:0)
Block(-7,89,-6,OBSIDIAN:0)
Block(-7,89,-5,OBSIDIAN:0)
Block(-7,89,-4,OBSIDIAN:0)
Block(-7,89,-3,OBSIDIAN:0)
Block(-7,89,-2,OBSIDIAN:0)
Block(-7,89,-1,OBSIDIAN:0)
Block(-7,89,0,OBSIDIAN:0)
Block(-7,89,1,OBSIDIAN:0)
Block(-7,89,2,OBSIDIAN:0)
Block(-7,89,3,OBSIDIAN:0)
Block(-7,89,4,OBSIDIAN:0)
Block(-7,89,5,STONE:3)
Block(-7,89,6,STONE:3)
Block(-7,89,7,STONE:3)
Block(-7,89,8,STONE:3)
Block(-7,90,-7,OBSIDIAN:0)
Block(-7,90,-6,OBSIDIAN:0)
Block(-7,90,-5,OBSIDIAN:0)
Block(-7,90,-4,OBSIDIAN:0)
Block(-7,90,-3,OBSIDIAN:0)
Block(-7,90,-2,OBSIDIAN:0)
Block(-7,90,-1,OBSIDIAN:0)
Block(-7,90,0,OBSIDIAN:0)
Block(-7,90,1,OBSIDIAN:0)
Block(-7,90,2,OBSIDIAN:0)
Block(-7,90,3,OBSIDIAN:0)
Block(-7,90,4,STONE:3)
Block(-7,90,5,STONE:3)
Block(-7,90,6,STONE:3)
Block(-7,90,7,STONE:3)
Block(-7,90,8,STONE:3)
Block(-7,91,-7,OBSIDIAN:0)
Block(-7,91,-6,OBSIDIAN:0)
Block(-7,91,-5,OBSIDIAN:0)
Block(-7,91,-4,OBSIDIAN:0)
Block(-7,91,-3,OBSIDIAN:0)
Block(-7,91,-2,OBSIDIAN:0)
Block(-7,91,-1,OBSIDIAN:0)
Block(-7,91,0,OBSIDIAN:0)
Block(-7,91,1,OBSIDIAN:0)
Block(-7,91,2,OBSIDIAN:0)
Block(-7,91,3,OBSIDIAN:0)
Block(-7,91,4,STONE:3)
Block(-7,91,5,STONE:3)
Block(-7,91,6,STONE:3)
Block(-7,91,7,STONE:3)
Block(-7,91,8,STONE:3)
Block(-7,92,-7,OBSIDIAN:0)
Block(-7,92,-6,OBSIDIAN:0)
Block(-7,92,-5,OBSIDIAN:0)
Block(-7,92,-4,OBSIDIAN:0)
Block(-7,92,-3,OBSIDIAN:0)
Block(-7,92,-2,OBSIDIAN:0)
Block(-7,92,-1,OBSIDIAN:0)
Block(-7,92,0,OBSIDIAN:0)
Block(-7,92,1,OBSIDIAN:0)
Block(-7,92,2,OBSIDIAN:0)
Block(-7,92,3,STONE:3)
Block(-7,92,4,STONE:3)
Block(-7,92,5,STONE:3)
Block(-7,92,6,STONE:3)
Block(-7,92,7,STONE:3)
Block(-7,92,8,STONE:3)
Block(-7,93,-7,OBSIDIAN:0)
Block(-7,93,-6,OBSIDIAN:0)
Block(-7,93,-5,OBSIDIAN:0)
Block(-7,93,-4,OBSIDIAN:0)
Block(-7,93,-3,OBSIDIAN:0)
Block(-7,93,-2,OBSIDIAN:0)
Block(-7,93,-1,OBSIDIAN:0)
Block(-7,93,0,OBSIDIAN:0)
Block(-7,93,1,OBSIDIAN:0)
Block(-7,93,2,STONE:3)
Block(-7,93,3,STONE:3)
Block(-7,93,4,STONE:5)
Block(-7,93,5,STONE:3)
Block(-7,94,-7,OBSIDIAN:0)
Block(-7,94,-6,OBSIDIAN:0)
Block(-7,94,-5,OBSIDIAN:0)
Block(-7,94,-4,OBSIDIAN:0)
Block(-7,94,-3,OBSIDIAN:0)
Block(-7,94,-2,OBSIDIAN:0)
Block(-7,94,-1,OBSIDIAN:0)
Block(-7,94,0,OBSIDIAN:0)
Block(-7,94,1,OBSIDIAN:0)
Block(-7,94,2,STONE:3)
Block(-7,94,3,STONE:3)
Block(-7,95,-7,OBSIDIAN:0)
Block(-7,95,-6,OBSIDIAN:0)
Block(-7,95,-5,OBSIDIAN:0)
Block(-7,95,-4,OBSIDIAN:0)
Block(-7,95,-3,OBSIDIAN:0)
Block(-7,95,-2,OBSIDIAN:0)
Block(-7,95,-1,OBSIDIAN:0)
Block(-7,95,0,OBSIDIAN:0)
Block(-7,95,1,OBSIDIAN:0)
Block(-7,95,2,STONE:3)
Block(-7,95,3,STONE:5)
Block(-7,96,-7,OBSIDIAN:0)
Block(-7,96,-6,OBSIDIAN:0)
Block(-7,96,-5,OBSIDIAN:0)
Block(-7,96,-4,OBSIDIAN:0)
Block(-7,96,-3,OBSIDIAN:0)
Block(-7,96,-2,OBSIDIAN:0)
Block(-7,96,-1,OBSIDIAN:0)
Block(-7,96,0,OBSIDIAN:0)
Block(-7,96,1,OBSIDIAN:0)
Block(-7,96,2,STONE:5)
Block(-7,97,-7,OBSIDIAN:0)
Block(-7,97,-6,OBSIDIAN:0)
Block(-7,97,-5,OBSIDIAN:0)
Block(-7,97,-4,OBSIDIAN:0)
Block(-7,97,-3,OBSIDIAN:0)
Block(-7,97,-2,OBSIDIAN:0)
Block(-7,97,-1,OBSIDIAN:0)
Block(-7,97,0,OBSIDIAN:0)
Block(-7,97,1,STONE:3)
Block(-7,98,-7,OBSIDIAN:0)
Block(-7,98,-6,OBSIDIAN:0)
Block(-7,98,-5,OBSIDIAN:0)
Block(-7,98,-4,OBSIDIAN:0)
Block(-7,98,-3,OBSIDIAN:0)
Block(-7,98,-2,OBSIDIAN:0)
Block(-7,98,-1,STONE:3)
Block(-7,98,0,STONE:3)
Block(-7,98,1,STONE:5)
Block(-7,99,-7,OBSIDIAN:0)
Block(-7,99,-6,OBSIDIAN:0)
Block(-7,99,-5,OBSIDIAN:0)
Block(-7,99,-4,OBSIDIAN:0)
Block(-7,99,-3,STONE:3)
Block(-7,99,-2,STONE:3)
Block(-7,99,-1,STONE:5)
Block(-7,99,0,STONE:5)
Block(-7,100,-7,STONE:3)
Block(-7,100,-6,STONE:3)
Block(-7,100,-5,STONE:3)
Block(-7,100,-4,STONE:3)
Block(-7,100,-3,STONE:5)
Block(-7,100,-2,STONE:5)
Block(-7,101,-7,STONE:5)
Block(-7,101,-6,STONE:5)
Block(-7,101,-5,STONE:5)
Block(-7,101,-4,STONE:5)
Block(-6,9,4,STONE:3)
Block(-6,9,5,STONE:3)
Block(-6,9,6,STONE:3)
Block(-6,9,7,STONE:3)
Block(-6,9,8,STONE:3)
Block(-6,10,-3,STONE:3)
Block(-6,10,-2,STONE:3)
Block(-6,10,-1,STONE:3)
Block(-6,10,0,STONE:3)
Block(-6,10,1,STONE:3)
Block(-6,10,2,STONE:3)
Block(-6,10,3,STONE:3)
Block(-6,10,4,STONE:3)
Block(-6,10,5,STONE:3)
Block(-6,10,6,STONE:3)
Block(-6,10,7,STONE:3)
Block(-6,10,8,STONE:3)
Block(-6,11,-5,STONE:3)
Block(-6,11,-4,STONE:3)
Block(-6,11,-3,STONE:3)
Block(-6,11,-2,STONE:3)
Block(-6,11,-1,STONE:3)
Block(-6,11,0,STONE:3)
Block(-6,11,1,STONE:3)
Block(-6,11,2,STONE:3)
Block(-6,11,3,STONE:3)
Block(-6,11,4,STONE:3)
Block(-6,11,5,STONE:3)
Block(-6,11,6,STONE:3)
Block(-6,11,7,STONE:3)
Block(-6,11,8,STONE:3)
Block(-6,12,-7,STONE:3)
Block(-6,12,-6,STONE:3)
Block(-6,12,-5,STONE:3)
Block(-6,12,-4,STONE:3)
Block(-6,12,-3,STONE:3)
Block(-6,12,-2,STONE:3)
Block(-6,12,-1,STONE:3)
Block(-6,12,0,STONE:3)
Block(-6,12,1,STONE:3)
Block(-6,12,2,STONE:3)
Block(-6,12,3,STONE:3)
Block(-6,12,4,STONE:3)
Block(-6,12,5,STONE:3)
Block(-6,12,6,STONE:3)
Block(-6,12,7,STONE:3)
Block(-6,12,8,STONE:3)
Block(-6,13,-7,STONE:3)
Block(-6,13,-6,STONE:3)
Block(-6,13,-5,STONE:3)
Block(-6,13,-4,STONE:3)
Block(-6,13,-3,STONE:3)
Block(-6,13,-2,STONE:3)
Block(-6,13,-1,STONE:3)
Block(-6,13,0,STONE:3)
Block(-6,13,1,STONE:3)
Block(-6,13,2,STONE:3)
Block(-6,13,3,STONE:3)
Block(-6,13,4,STONE:3)
Block(-6,13,5,STONE:3)
Block(-6,13,6,STONE:3)
Block(-6,13,7,STONE:3)
Block(-6,13,8,STONE:3)
Block(-6,14,-7,STONE:3)
Block(-6,14,-6,STONE:3)
Block(-6,14,-5,STONE:3)
Block(-6,14,-4,STONE:3)
Block(-6,14,-3,STONE:3)
Block(-6,14,-2,STONE:3)
Block(-6,14,-1,STONE:3)
Block(-6,14,0,STONE:3)
Block(-6,14,1,STONE:3)
Block(-6,14,2,OBSIDIAN:0)
Block(-6,14,3,STONE:3)
Block(-6,14,4,STONE:3)
Block(-6,14,5,STONE:3)
Block(-6,14,6,STONE:3)
Block(-6,14,7,STONE:3)
Block(-6,14,8,OBSIDIAN:0)
Block(-6,15,-7,STONE:3)
Block(-6,15,-6,STONE:3)
Block(-6,15,-5,STONE:3)
Block(-6,15,-4,STONE:3)
Block(-6,15,-3,STONE:3)
Block(-6,15,-2,STONE:3)
Block(-6,15,-1,STONE:3)
Block(-6,15,0,STONE:3)
Block(-6,15,1,OBSIDIAN:0)
Block(-6,15,2,OBSIDIAN:0)
Block(-6,15,3,OBSIDIAN:0)
Block(-6,15,4,OBSIDIAN:0)
Block(-6,15,5,OBSIDIAN:0)
Block(-6,15,6,OBSIDIAN:0)
Block(-6,15,7,OBSIDIAN:0)
Block(-6,15,8,OBSIDIAN:0)
Block(-6,16,-7,STONE:3)
Block(-6,16,-6,OBSIDIAN:0)
Block(-6,16,-5,OBSIDIAN:0)
Block(-6,16,-4,OBSIDIAN:0)
Block(-6,16,-3,OBSIDIAN:0)
Block(-6,16,-2,OBSIDIAN:0)
Block(-6,16,-1,OBSIDIAN:0)
Block(-6,16,0,OBSIDIAN:0)
Block(-6,16,1,OBSIDIAN:0)
Block(-6,16,2,OBSIDIAN:0)
Block(-6,16,3,OBSIDIAN:0)
Block(-6,16,4,OBSIDIAN:0)
Block(-6,16,5,OBSIDIAN:0)
Block(-6,16,6,OBSIDIAN:0)
Block(-6,16,7,OBSIDIAN:0)
Block(-6,16,8,OBSIDIAN:0)
Block(-6,17,-7,STONE:3)
Block(-6,17,-6,OBSIDIAN:0)
Block(-6,17,-5,OBSIDIAN:0)
Block(-6,17,-4,OBSIDIAN:0)
Block(-6,17,-3,OBSIDIAN:0)
Block(-6,17,-2,OBSIDIAN:0)
Block(-6,17,-1,OBSIDIAN:0)
Block(-6,17,0,OBSIDIAN:0)
Block(-6,17,1,OBSIDIAN:0)
Block(-6,17,2,OBSIDIAN:0)
Block(-6,17,3,OBSIDIAN:0)
Block(-6,17,4,OBSIDIAN:0)
Block(-6,17,5,OBSIDIAN:0)
Block(-6,17,6,OBSIDIAN:0)
Block(-6,17,7,OBSIDIAN:0)
Block(-6,17,8,OBSIDIAN:0)
Block(-6,18,-7,OBSIDIAN:0)
Block(-6,18,-6,OBSIDIAN:0)
Block(-6,18,-5,OBSIDIAN:0)
Block(-6,18,-4,OBSIDIAN:0)
Block(-6,18,-3,OBSIDIAN:0)
Block(-6,18,-2,OBSIDIAN:0)
Block(-6,18,-1,OBSIDIAN:0)
Block(-6,18,0,OBSIDIAN:0)
Block(-6,18,1,OBSIDIAN:0)
Block(-6,18,2,OBSIDIAN:0)
Block(-6,18,3,OBSIDIAN:0)
Block(-6,18,4,OBSIDIAN:0)
Block(-6,18,5,OBSIDIAN:0)
Block(-6,18,6,OBSIDIAN:0)
Block(-6,18,7,OBSIDIAN:0)
Block(-6,18,8,OBSIDIAN:0)
Block(-6,19,-7,OBSIDIAN:0)
Block(-6,19,-6,OBSIDIAN:0)
Block(-6,19,-5,OBSIDIAN:0)
Block(-6,19,-4,OBSIDIAN:0)
Block(-6,19,-3,OBSIDIAN:0)
Block(-6,19,-2,OBSIDIAN:0)
Block(-6,19,-1,OBSIDIAN:0)
Block(-6,19,0,OBSIDIAN:0)
Block(-6,19,1,OBSIDIAN:0)
Block(-6,19,2,OBSIDIAN:0)
Block(-6,19,3,OBSIDIAN:0)
Block(-6,19,4,OBSIDIAN:0)
Block(-6,19,5,OBSIDIAN:0)
Block(-6,19,6,OBSIDIAN:0)
Block(-6,19,7,OBSIDIAN:0)
Block(-6,19,8,OBSIDIAN:0)
Block(-6,20,-7,OBSIDIAN:0)
Block(-6,20,-6,OBSIDIAN:0)
Block(-6,20,-5,OBSIDIAN:0)
Block(-6,20,-4,OBSIDIAN:0)
Block(-6,20,-3,OBSIDIAN:0)
Block(-6,20,-2,OBSIDIAN:0)
Block(-6,20,-1,OBSIDIAN:0)
Block(-6,20,0,OBSIDIAN:0)
Block(-6,20,1,OBSIDIAN:0)
Block(-6,20,2,OBSIDIAN:0)
Block(-6,20,3,OBSIDIAN:0)
Block(-6,20,4,OBSIDIAN:0)
Block(-6,20,5,OBSIDIAN:0)
Block(-6,20,6,OBSIDIAN:0)
Block(-6,20,7,OBSIDIAN:0)
Block(-6,20,8,OBSIDIAN:0)
Block(-6,21,-7,OBSIDIAN:0)
Block(-6,21,-6,OBSIDIAN:0)
Block(-6,21,-5,OBSIDIAN:0)
Block(-6,21,-4,OBSIDIAN:0)
Block(-6,21,-3,OBSIDIAN:0)
Block(-6,21,-2,OBSIDIAN:0)
Block(-6,21,-1,OBSIDIAN:0)
Block(-6,21,0,OBSIDIAN:0)
Block(-6,21,1,OBSIDIAN:0)
Block(-6,21,2,OBSIDIAN:0)
Block(-6,21,3,OBSIDIAN:0)
Block(-6,21,4,OBSIDIAN:0)
Block(-6,21,5,OBSIDIAN:0)
Block(-6,21,6,OBSIDIAN:0)
Block(-6,21,7,OBSIDIAN:0)
Block(-6,21,8,OBSIDIAN:0)
Block(-6,22,-7,OBSIDIAN:0)
Block(-6,22,-6,OBSIDIAN:0)
Block(-6,22,-5,STONE:3)
Block(-6,22,-4,STONE:3)
Block(-6,22,-3,STONE:3)
Block(-6,22,-2,STONE:3)
Block(-6,22,-1,OBSIDIAN:0)
Block(-6,22,0,OBSIDIAN:0)
Block(-6,22,1,OBSIDIAN:0)
Block(-6,22,2,OBSIDIAN:0)
Block(-6,22,3,OBSIDIAN:0)
Block(-6,22,4,OBSIDIAN:0)
Block(-6,22,5,OBSIDIAN:0)
Block(-6,22,6,OBSIDIAN:0)
Block(-6,22,7,OBSIDIAN:0)
Block(-6,22,8,OBSIDIAN:0)
Block(-6,23,-7,OBSIDIAN:0)
Block(-6,23,-6,STATIONARY_LAVA:0)
Block(-6,23,-5,STATIONARY_LAVA:0)
Block(-6,23,-4,STATIONARY_LAVA:0)
Block(-6,23,-3,STATIONARY_LAVA:0)
Block(-6,23,-2,STATIONARY_LAVA:0)
Block(-6,23,-1,STATIONARY_LAVA:0)
Block(-6,23,0,STATIONARY_LAVA:0)
Block(-6,23,1,STATIONARY_LAVA:0)
Block(-6,23,2,STATIONARY_LAVA:0)
Block(-6,23,3,OBSIDIAN:0)
Block(-6,23,4,OBSIDIAN:0)
Block(-6,23,5,OBSIDIAN:0)
Block(-6,23,6,STONE:5)
Block(-6,23,7,STONE:5)
Block(-6,23,8,STONE:5)
Block(-6,24,-7,OBSIDIAN:0)
Block(-6,24,3,OBSIDIAN:0)
Block(-6,24,4,OBSIDIAN:0)
Block(-6,24,5,STONE:5)
Block(-6,24,6,STONE:5)
Block(-6,24,7,STONE:5)
Block(-6,24,8,STONE:5)
Block(-6,25,-7,OBSIDIAN:0)
Block(-6,25,7,STONE:5)
Block(-6,25,8,STONE:5)
Block(-6,26,-7,OBSIDIAN:0)
Block(-6,26,-6,OBSIDIAN:0)
Block(-6,27,-7,OBSIDIAN:0)
Block(-6,73,-4,OBSIDIAN:0)
Block(-6,73,-3,OBSIDIAN:0)
Block(-6,73,-2,OBSIDIAN:0)
Block(-6,73,-1,OBSIDIAN:0)
Block(-6,73,0,OBSIDIAN:0)
Block(-6,73,1,OBSIDIAN:0)
Block(-6,73,2,OBSIDIAN:0)
Block(-6,73,3,OBSIDIAN:0)
Block(-6,73,4,OBSIDIAN:0)
Block(-6,73,5,OBSIDIAN:0)
Block(-6,73,6,OBSIDIAN:0)
Block(-6,73,7,OBSIDIAN:0)
Block(-6,73,8,OBSIDIAN:0)
Block(-6,74,-7,OBSIDIAN:0)
Block(-6,74,-6,OBSIDIAN:0)
Block(-6,74,-5,OBSIDIAN:0)
Block(-6,74,-4,OBSIDIAN:0)
Block(-6,74,-3,OBSIDIAN:0)
Block(-6,74,-2,OBSIDIAN:0)
Block(-6,74,-1,OBSIDIAN:0)
Block(-6,74,0,OBSIDIAN:0)
Block(-6,74,1,OBSIDIAN:0)
Block(-6,74,2,OBSIDIAN:0)
Block(-6,74,3,OBSIDIAN:0)
Block(-6,74,4,OBSIDIAN:0)
Block(-6,74,5,OBSIDIAN:0)
Block(-6,74,6,OBSIDIAN:0)
Block(-6,74,7,OBSIDIAN:0)
Block(-6,74,8,OBSIDIAN:0)
Block(-6,75,-7,OBSIDIAN:0)
Block(-6,75,-6,OBSIDIAN:0)
Block(-6,75,-5,OBSIDIAN:0)
Block(-6,75,-4,OBSIDIAN:0)
Block(-6,75,-3,OBSIDIAN:0)
Block(-6,75,-2,OBSIDIAN:0)
Block(-6,75,-1,OBSIDIAN:0)
Block(-6,75,0,OBSIDIAN:0)
Block(-6,75,1,OBSIDIAN:0)
Block(-6,75,2,OBSIDIAN:0)
Block(-6,75,3,OBSIDIAN:0)
Block(-6,75,4,OBSIDIAN:0)
Block(-6,75,5,OBSIDIAN:0)
Block(-6,75,6,OBSIDIAN:0)
Block(-6,75,7,OBSIDIAN:0)
Block(-6,75,8,OBSIDIAN:0)
Block(-6,76,-7,OBSIDIAN:0)
Block(-6,76,-6,OBSIDIAN:0)
Block(-6,76,-5,OBSIDIAN:0)
Block(-6,76,-4,OBSIDIAN:0)
Block(-6,76,-3,OBSIDIAN:0)
Block(-6,76,-2,OBSIDIAN:0)
Block(-6,76,-1,OBSIDIAN:0)
Block(-6,76,0,OBSIDIAN:0)
Block(-6,76,1,OBSIDIAN:0)
Block(-6,76,2,OBSIDIAN:0)
Block(-6,76,3,OBSIDIAN:0)
Block(-6,76,4,OBSIDIAN:0)
Block(-6,76,5,OBSIDIAN:0)
Block(-6,76,6,OBSIDIAN:0)
Block(-6,76,7,OBSIDIAN:0)
Block(-6,76,8,OBSIDIAN:0)
Block(-6,77,-7,OBSIDIAN:0)
Block(-6,77,-6,OBSIDIAN:0)
Block(-6,77,-5,OBSIDIAN:0)
Block(-6,77,-4,OBSIDIAN:0)
Block(-6,77,-3,OBSIDIAN:0)
Block(-6,77,-2,OBSIDIAN:0)
Block(-6,77,-1,OBSIDIAN:0)
Block(-6,77,0,OBSIDIAN:0)
Block(-6,77,1,OBSIDIAN:0)
Block(-6,77,2,OBSIDIAN:0)
Block(-6,77,3,OBSIDIAN:0)
Block(-6,77,4,OBSIDIAN:0)
Block(-6,77,5,OBSIDIAN:0)
Block(-6,77,6,OBSIDIAN:0)
Block(-6,77,7,OBSIDIAN:0)
Block(-6,77,8,OBSIDIAN:0)
Block(-6,78,-7,OBSIDIAN:0)
Block(-6,78,-6,OBSIDIAN:0)
Block(-6,78,-5,OBSIDIAN:0)
Block(-6,78,-4,OBSIDIAN:0)
Block(-6,78,-3,OBSIDIAN:0)
Block(-6,78,-2,OBSIDIAN:0)
Block(-6,78,-1,OBSIDIAN:0)
Block(-6,78,0,OBSIDIAN:0)
Block(-6,78,1,OBSIDIAN:0)
Block(-6,78,2,OBSIDIAN:0)
Block(-6,78,3,OBSIDIAN:0)
Block(-6,78,4,OBSIDIAN:0)
Block(-6,78,5,OBSIDIAN:0)
Block(-6,78,6,OBSIDIAN:0)
Block(-6,78,7,OBSIDIAN:0)
Block(-6,78,8,OBSIDIAN:0)
Block(-6,79,-7,OBSIDIAN:0)
Block(-6,79,-6,OBSIDIAN:0)
Block(-6,79,-5,OBSIDIAN:0)
Block(-6,79,-4,OBSIDIAN:0)
Block(-6,79,-3,OBSIDIAN:0)
Block(-6,79,-2,OBSIDIAN:0)
Block(-6,79,-1,OBSIDIAN:0)
Block(-6,79,0,OBSIDIAN:0)
Block(-6,79,1,OBSIDIAN:0)
Block(-6,79,2,OBSIDIAN:0)
Block(-6,79,3,OBSIDIAN:0)
Block(-6,79,4,OBSIDIAN:0)
Block(-6,79,5,OBSIDIAN:0)
Block(-6,79,6,OBSIDIAN:0)
Block(-6,79,7,OBSIDIAN:0)
Block(-6,79,8,OBSIDIAN:0)
Block(-6,80,-7,OBSIDIAN:0)
Block(-6,80,-6,OBSIDIAN:0)
Block(-6,80,-5,OBSIDIAN:0)
Block(-6,80,-4,OBSIDIAN:0)
Block(-6,80,-3,OBSIDIAN:0)
Block(-6,80,-2,OBSIDIAN:0)
Block(-6,80,-1,OBSIDIAN:0)
Block(-6,80,0,OBSIDIAN:0)
Block(-6,80,1,OBSIDIAN:0)
Block(-6,80,2,OBSIDIAN:0)
Block(-6,80,3,OBSIDIAN:0)
Block(-6,80,4,OBSIDIAN:0)
Block(-6,80,5,OBSIDIAN:0)
Block(-6,80,6,OBSIDIAN:0)
Block(-6,80,7,OBSIDIAN:0)
Block(-6,80,8,OBSIDIAN:0)
Block(-6,81,-7,OBSIDIAN:0)
Block(-6,81,-6,OBSIDIAN:0)
Block(-6,81,-5,OBSIDIAN:0)
Block(-6,81,-4,OBSIDIAN:0)
Block(-6,81,-3,OBSIDIAN:0)
Block(-6,81,-2,OBSIDIAN:0)
Block(-6,81,-1,OBSIDIAN:0)
Block(-6,81,0,OBSIDIAN:0)
Block(-6,81,1,OBSIDIAN:0)
Block(-6,81,2,OBSIDIAN:0)
Block(-6,81,3,OBSIDIAN:0)
Block(-6,81,4,OBSIDIAN:0)
Block(-6,81,5,OBSIDIAN:0)
Block(-6,81,6,OBSIDIAN:0)
Block(-6,81,7,OBSIDIAN:0)
Block(-6,81,8,OBSIDIAN:0)
Block(-6,82,-7,OBSIDIAN:0)
Block(-6,82,-6,OBSIDIAN:0)
Block(-6,82,-5,OBSIDIAN:0)
Block(-6,82,-4,OBSIDIAN:0)
Block(-6,82,-3,OBSIDIAN:0)
Block(-6,82,-2,OBSIDIAN:0)
Block(-6,82,-1,OBSIDIAN:0)
Block(-6,82,0,OBSIDIAN:0)
Block(-6,82,1,OBSIDIAN:0)
Block(-6,82,2,OBSIDIAN:0)
Block(-6,82,3,OBSIDIAN:0)
Block(-6,82,4,OBSIDIAN:0)
Block(-6,82,5,OBSIDIAN:0)
Block(-6,82,6,OBSIDIAN:0)
Block(-6,82,7,OBSIDIAN:0)
Block(-6,82,8,OBSIDIAN:0)
Block(-6,83,-7,OBSIDIAN:0)
Block(-6,83,-6,OBSIDIAN:0)
Block(-6,83,-5,OBSIDIAN:0)
Block(-6,83,-4,OBSIDIAN:0)
Block(-6,83,-3,OBSIDIAN:0)
Block(-6,83,-2,OBSIDIAN:0)
Block(-6,83,-1,OBSIDIAN:0)
Block(-6,83,0,OBSIDIAN:0)
Block(-6,83,1,OBSIDIAN:0)
Block(-6,83,2,OBSIDIAN:0)
Block(-6,83,3,OBSIDIAN:0)
Block(-6,83,4,OBSIDIAN:0)
Block(-6,83,5,OBSIDIAN:0)
Block(-6,83,6,OBSIDIAN:0)
Block(-6,83,7,OBSIDIAN:0)
Block(-6,83,8,OBSIDIAN:0)
Block(-6,84,-7,OBSIDIAN:0)
Block(-6,84,-6,OBSIDIAN:0)
Block(-6,84,-5,OBSIDIAN:0)
Block(-6,84,-4,OBSIDIAN:0)
Block(-6,84,-3,OBSIDIAN:0)
Block(-6,84,-2,OBSIDIAN:0)
Block(-6,84,-1,OBSIDIAN:0)
Block(-6,84,0,OBSIDIAN:0)
Block(-6,84,1,OBSIDIAN:0)
Block(-6,84,2,OBSIDIAN:0)
Block(-6,84,3,OBSIDIAN:0)
Block(-6,84,4,OBSIDIAN:0)
Block(-6,84,5,OBSIDIAN:0)
Block(-6,84,6,OBSIDIAN:0)
Block(-6,84,7,OBSIDIAN:0)
Block(-6,84,8,OBSIDIAN:0)
Block(-6,85,-7,OBSIDIAN:0)
Block(-6,85,-6,OBSIDIAN:0)
Block(-6,85,-5,OBSIDIAN:0)
Block(-6,85,-4,OBSIDIAN:0)
Block(-6,85,-3,OBSIDIAN:0)
Block(-6,85,-2,OBSIDIAN:0)
Block(-6,85,-1,OBSIDIAN:0)
Block(-6,85,0,OBSIDIAN:0)
Block(-6,85,1,OBSIDIAN:0)
Block(-6,85,2,OBSIDIAN:0)
Block(-6,85,3,OBSIDIAN:0)
Block(-6,85,4,OBSIDIAN:0)
Block(-6,85,5,OBSIDIAN:0)
Block(-6,85,6,OBSIDIAN:0)
Block(-6,85,7,OBSIDIAN:0)
Block(-6,85,8,OBSIDIAN:0)
Block(-6,86,-7,OBSIDIAN:0)
Block(-6,86,-6,OBSIDIAN:0)
Block(-6,86,-5,OBSIDIAN:0)
Block(-6,86,-4,OBSIDIAN:0)
Block(-6,86,-3,OBSIDIAN:0)
Block(-6,86,-2,OBSIDIAN:0)
Block(-6,86,-1,OBSIDIAN:0)
Block(-6,86,0,OBSIDIAN:0)
Block(-6,86,1,OBSIDIAN:0)
Block(-6,86,2,OBSIDIAN:0)
Block(-6,86,3,OBSIDIAN:0)
Block(-6,86,4,OBSIDIAN:0)
Block(-6,86,5,OBSIDIAN:0)
Block(-6,86,6,OBSIDIAN:0)
Block(-6,86,7,OBSIDIAN:0)
Block(-6,86,8,OBSIDIAN:0)
Block(-6,87,-7,OBSIDIAN:0)
Block(-6,87,-6,OBSIDIAN:0)
Block(-6,87,-5,OBSIDIAN:0)
Block(-6,87,-4,OBSIDIAN:0)
Block(-6,87,-3,OBSIDIAN:0)
Block(-6,87,-2,OBSIDIAN:0)
Block(-6,87,-1,OBSIDIAN:0)
Block(-6,87,0,OBSIDIAN:0)
Block(-6,87,1,OBSIDIAN:0)
Block(-6,87,2,OBSIDIAN:0)
Block(-6,87,3,OBSIDIAN:0)
Block(-6,87,4,OBSIDIAN:0)
Block(-6,87,5,OBSIDIAN:0)
Block(-6,87,6,OBSIDIAN:0)
Block(-6,87,7,STONE:3)
Block(-6,87,8,STONE:3)
Block(-6,88,-7,OBSIDIAN:0)
Block(-6,88,-6,OBSIDIAN:0)
Block(-6,88,-5,OBSIDIAN:0)
Block(-6,88,-4,OBSIDIAN:0)
Block(-6,88,-3,OBSIDIAN:0)
Block(-6,88,-2,OBSIDIAN:0)
Block(-6,88,-1,OBSIDIAN:0)
Block(-6,88,0,OBSIDIAN:0)
Block(-6,88,1,OBSIDIAN:0)
Block(-6,88,2,OBSIDIAN:0)
Block(-6,88,3,OBSIDIAN:0)
Block(-6,88,4,OBSIDIAN:0)
Block(-6,88,5,STONE:3)
Block(-6,88,6,STONE:3)
Block(-6,88,7,STONE:3)
Block(-6,88,8,STONE:3)
Block(-6,89,-7,OBSIDIAN:0)
Block(-6,89,-6,OBSIDIAN:0)
Block(-6,89,-5,OBSIDIAN:0)
Block(-6,89,-4,OBSIDIAN:0)
Block(-6,89,-3,OBSIDIAN:0)
Block(-6,89,-2,OBSIDIAN:0)
Block(-6,89,-1,OBSIDIAN:0)
Block(-6,89,0,OBSIDIAN:0)
Block(-6,89,1,OBSIDIAN:0)
Block(-6,89,2,OBSIDIAN:0)
Block(-6,89,3,OBSIDIAN:0)
Block(-6,89,4,STONE:3)
Block(-6,89,5,STONE:3)
Block(-6,89,6,STONE:3)
Block(-6,89,7,STONE:3)
Block(-6,89,8,STONE:3)
Block(-6,90,-7,OBSIDIAN:0)
Block(-6,90,-6,OBSIDIAN:0)
Block(-6,90,-5,OBSIDIAN:0)
Block(-6,90,-4,OBSIDIAN:0)
Block(-6,90,-3,OBSIDIAN:0)
Block(-6,90,-2,OBSIDIAN:0)
Block(-6,90,-1,OBSIDIAN:0)
Block(-6,90,0,OBSIDIAN:0)
Block(-6,90,1,OBSIDIAN:0)
Block(-6,90,2,OBSIDIAN:0)
Block(-6,90,3,OBSIDIAN:0)
Block(-6,90,4,STONE:3)
Block(-6,90,5,STONE:3)
Block(-6,90,6,STONE:3)
Block(-6,90,7,STONE:3)
Block(-6,90,8,STONE:3)
Block(-6,91,-7,OBSIDIAN:0)
Block(-6,91,-6,OBSIDIAN:0)
Block(-6,91,-5,OBSIDIAN:0)
Block(-6,91,-4,OBSIDIAN:0)
Block(-6,91,-3,OBSIDIAN:0)
Block(-6,91,-2,OBSIDIAN:0)
Block(-6,91,-1,OBSIDIAN:0)
Block(-6,91,0,OBSIDIAN:0)
Block(-6,91,1,OBSIDIAN:0)
Block(-6,91,2,STONE:3)
Block(-6,91,3,STONE:3)
Block(-6,91,4,STONE:3)
Block(-6,91,5,STONE:3)
Block(-6,91,6,STONE:3)
Block(-6,91,7,STONE:3)
Block(-6,91,8,STONE:3)
Block(-6,92,-7,OBSIDIAN:0)
Block(-6,92,-6,OBSIDIAN:0)
Block(-6,92,-5,OBSIDIAN:0)
Block(-6,92,-4,OBSIDIAN:0)
Block(-6,92,-3,OBSIDIAN:0)
Block(-6,92,-2,OBSIDIAN:0)
Block(-6,92,-1,OBSIDIAN:0)
Block(-6,92,0,OBSIDIAN:0)
Block(-6,92,1,STONE:3)
Block(-6,92,2,STONE:3)
Block(-6,92,3,STONE:3)
Block(-6,92,4,STONE:3)
Block(-6,92,5,STONE:3)
Block(-6,92,6,STONE:3)
Block(-6,92,7,STONE:3)
Block(-6,92,8,STONE:3)
Block(-6,93,-7,OBSIDIAN:0)
Block(-6,93,-6,OBSIDIAN:0)
Block(-6,93,-5,OBSIDIAN:0)
Block(-6,93,-4,OBSIDIAN:0)
Block(-6,93,-3,OBSIDIAN:0)
Block(-6,93,-2,OBSIDIAN:0)
Block(-6,93,-1,OBSIDIAN:0)
Block(-6,93,0,OBSIDIAN:0)
Block(-6,93,1,STONE:3)
Block(-6,93,2,STONE:3)
Block(-6,93,3,STONE:5)
Block(-6,93,4,STONE:3)
Block(-6,93,5,STONE:3)
Block(-6,94,-7,OBSIDIAN:0)
Block(-6,94,-6,OBSIDIAN:0)
Block(-6,94,-5,OBSIDIAN:0)
Block(-6,94,-4,OBSIDIAN:0)
Block(-6,94,-3,OBSIDIAN:0)
Block(-6,94,-2,OBSIDIAN:0)
Block(-6,94,-1,OBSIDIAN:0)
Block(-6,94,0,OBSIDIAN:0)
Block(-6,94,1,STONE:3)
Block(-6,94,2,STONE:3)
Block(-6,95,-7,OBSIDIAN:0)
Block(-6,95,-6,OBSIDIAN:0)
Block(-6,95,-5,OBSIDIAN:0)
Block(-6,95,-4,OBSIDIAN:0)
Block(-6,95,-3,OBSIDIAN:0)
Block(-6,95,-2,OBSIDIAN:0)
Block(-6,95,-1,OBSIDIAN:0)
Block(-6,95,0,OBSIDIAN:0)
Block(-6,95,1,STONE:3)
Block(-6,95,2,STONE:5)
Block(-6,96,-7,STONE:3)
Block(-6,96,-6,OBSIDIAN:0)
Block(-6,96,-5,OBSIDIAN:0)
Block(-6,96,-4,OBSIDIAN:0)
Block(-6,96,-3,OBSIDIAN:0)
Block(-6,96,-2,OBSIDIAN:0)
Block(-6,96,-1,OBSIDIAN:0)
Block(-6,96,0,OBSIDIAN:0)
Block(-6,96,1,STONE:3)
Block(-6,97,-7,STONE:3)
Block(-6,97,-6,OBSIDIAN:0)
Block(-6,97,-5,OBSIDIAN:0)
Block(-6,97,-4,OBSIDIAN:0)
Block(-6,97,-3,OBSIDIAN:0)
Block(-6,97,-2,OBSIDIAN:0)
Block(-6,97,-1,OBSIDIAN:0)
Block(-6,97,0,STONE:3)
Block(-6,97,1,STONE:5)
Block(-6,98,-7,STONE:3)
Block(-6,98,-6,OBSIDIAN:0)
Block(-6,98,-5,OBSIDIAN:0)
Block(-6,98,-4,OBSIDIAN:0)
Block(-6,98,-3,OBSIDIAN:0)
Block(-6,98,-2,OBSIDIAN:0)
Block(-6,98,-1,STONE:3)
Block(-6,98,0,STONE:5)
Block(-6,99,-7,STONE:3)
Block(-6,99,-6,OBSIDIAN:0)
Block(-6,99,-5,OBSIDIAN:0)
Block(-6,99,-4,STONE:3)
Block(-6,99,-3,STONE:3)
Block(-6,99,-2,STONE:3)
Block(-6,99,-1,STONE:5)
Block(-6,100,-7,STONE:3)
Block(-6,100,-6,STONE:3)
Block(-6,100,-5,STONE:3)
Block(-6,100,-4,STONE:5)
Block(-6,100,-3,STONE:5)
Block(-6,100,-2,STONE:5)
Block(-6,101,-7,STONE:5)
Block(-6,101,-6,STONE:5)
Block(-6,101,-5,STONE:5)
Block(-5,9,5,STONE:3)
Block(-5,9,6,STONE:3)
Block(-5,9,7,STONE:3)
Block(-5,9,8,STONE:3)
Block(-5,10,-2,STONE:3)
Block(-5,10,-1,STONE:3)
Block(-5,10,0,STONE:3)
Block(-5,10,1,STONE:3)
Block(-5,10,2,STONE:3)
Block(-5,10,3,STONE:3)
Block(-5,10,4,STONE:3)
Block(-5,10,5,STONE:3)
Block(-5,10,6,STONE:3)
Block(-5,10,7,STONE:3)
Block(-5,10,8,STONE:3)
Block(-5,11,-5,STONE:3)
Block(-5,11,-4,STONE:3)
Block(-5,11,-3,STONE:3)
Block(-5,11,-2,STONE:3)
Block(-5,11,-1,STONE:3)
Block(-5,11,0,STONE:3)
Block(-5,11,1,STONE:3)
Block(-5,11,2,STONE:3)
Block(-5,11,3,STONE:3)
Block(-5,11,4,STONE:3)
Block(-5,11,5,STONE:3)
Block(-5,11,6,STONE:3)
Block(-5,11,7,STONE:3)
Block(-5,11,8,STONE:3)
Block(-5,12,-6,STONE:3)
Block(-5,12,-5,STONE:3)
Block(-5,12,-4,STONE:3)
Block(-5,12,-3,STONE:3)
Block(-5,12,-2,STONE:3)
Block(-5,12,-1,STONE:3)
Block(-5,12,0,STONE:3)
Block(-5,12,1,STONE:3)
Block(-5,12,2,STONE:3)
Block(-5,12,3,STONE:3)
Block(-5,12,4,STONE:3)
Block(-5,12,5,STONE:3)
Block(-5,12,6,STONE:3)
Block(-5,12,7,STONE:3)
Block(-5,12,8,STONE:3)
Block(-5,13,-7,STONE:3)
Block(-5,13,-6,STONE:3)
Block(-5,13,-5,STONE:3)
Block(-5,13,-4,STONE:3)
Block(-5,13,-3,STONE:3)
Block(-5,13,-2,STONE:3)
Block(-5,13,-1,STONE:3)
Block(-5,13,0,STONE:3)
Block(-5,13,1,STONE:3)
Block(-5,13,2,STONE:3)
Block(-5,13,3,STONE:3)
Block(-5,13,4,STONE:3)
Block(-5,13,5,STONE:3)
Block(-5,13,6,STONE:3)
Block(-5,13,7,STONE:3)
Block(-5,13,8,STONE:3)
Block(-5,14,-7,STONE:3)
Block(-5,14,-6,STONE:3)
Block(-5,14,-5,STONE:3)
Block(-5,14,-4,STONE:3)
Block(-5,14,-3,STONE:3)
Block(-5,14,-2,STONE:3)
Block(-5,14,-1,STONE:3)
Block(-5,14,0,STONE:3)
Block(-5,14,1,STONE:3)
Block(-5,14,2,OBSIDIAN:0)
Block(-5,14,3,STONE:3)
Block(-5,14,4,STONE:3)
Block(-5,14,5,STONE:3)
Block(-5,14,6,STONE:3)
Block(-5,14,7,STONE:3)
Block(-5,14,8,OBSIDIAN:0)
Block(-5,15,-7,STONE:3)
Block(-5,15,-6,STONE:3)
Block(-5,15,-5,OBSIDIAN:0)
Block(-5,15,-4,STONE:3)
Block(-5,15,-3,STONE:3)
Block(-5,15,-2,STONE:3)
Block(-5,15,-1,STONE:3)
Block(-5,15,0,STONE:3)
Block(-5,15,1,OBSIDIAN:0)
Block(-5,15,2,OBSIDIAN:0)
Block(-5,15,3,OBSIDIAN:0)
Block(-5,15,4,OBSIDIAN:0)
Block(-5,15,5,OBSIDIAN:0)
Block(-5,15,6,OBSIDIAN:0)
Block(-5,15,7,OBSIDIAN:0)
Block(-5,15,8,OBSIDIAN:0)
Block(-5,16,-7,STONE:3)
Block(-5,16,-6,OBSIDIAN:0)
Block(-5,16,-5,OBSIDIAN:0)
Block(-5,16,-4,OBSIDIAN:0)
Block(-5,16,-3,OBSIDIAN:0)
Block(-5,16,-2,OBSIDIAN:0)
Block(-5,16,-1,OBSIDIAN:0)
Block(-5,16,0,OBSIDIAN:0)
Block(-5,16,1,OBSIDIAN:0)
Block(-5,16,2,OBSIDIAN:0)
Block(-5,16,3,OBSIDIAN:0)
Block(-5,16,4,OBSIDIAN:0)
Block(-5,16,5,OBSIDIAN:0)
Block(-5,16,6,OBSIDIAN:0)
Block(-5,16,7,OBSIDIAN:0)
Block(-5,16,8,OBSIDIAN:0)
Block(-5,17,-7,STONE:3)
Block(-5,17,-6,OBSIDIAN:0)
Block(-5,17,-5,OBSIDIAN:0)
Block(-5,17,-4,OBSIDIAN:0)
Block(-5,17,-3,OBSIDIAN:0)
Block(-5,17,-2,OBSIDIAN:0)
Block(-5,17,-1,OBSIDIAN:0)
Block(-5,17,0,OBSIDIAN:0)
Block(-5,17,1,OBSIDIAN:0)
Block(-5,17,2,OBSIDIAN:0)
Block(-5,17,3,OBSIDIAN:0)
Block(-5,17,4,OBSIDIAN:0)
Block(-5,17,5,OBSIDIAN:0)
Block(-5,17,6,OBSIDIAN:0)
Block(-5,17,7,OBSIDIAN:0)
Block(-5,17,8,OBSIDIAN:0)
Block(-5,18,-7,OBSIDIAN:0)
Block(-5,18,-6,OBSIDIAN:0)
Block(-5,18,-5,OBSIDIAN:0)
Block(-5,18,-4,OBSIDIAN:0)
Block(-5,18,-3,OBSIDIAN:0)
Block(-5,18,-2,OBSIDIAN:0)
Block(-5,18,-1,OBSIDIAN:0)
Block(-5,18,0,OBSIDIAN:0)
Block(-5,18,1,OBSIDIAN:0)
Block(-5,18,2,OBSIDIAN:0)
Block(-5,18,3,OBSIDIAN:0)
Block(-5,18,4,OBSIDIAN:0)
Block(-5,18,5,OBSIDIAN:0)
Block(-5,18,6,OBSIDIAN:0)
Block(-5,18,7,OBSIDIAN:0)
Block(-5,18,8,OBSIDIAN:0)
Block(-5,19,-7,OBSIDIAN:0)
Block(-5,19,-6,OBSIDIAN:0)
Block(-5,19,-5,OBSIDIAN:0)
Block(-5,19,-4,OBSIDIAN:0)
Block(-5,19,-3,OBSIDIAN:0)
Block(-5,19,-2,OBSIDIAN:0)
Block(-5,19,-1,OBSIDIAN:0)
Block(-5,19,0,OBSIDIAN:0)
Block(-5,19,1,OBSIDIAN:0)
Block(-5,19,2,OBSIDIAN:0)
Block(-5,19,3,OBSIDIAN:0)
Block(-5,19,4,OBSIDIAN:0)
Block(-5,19,5,OBSIDIAN:0)
Block(-5,19,6,OBSIDIAN:0)
Block(-5,19,7,OBSIDIAN:0)
Block(-5,19,8,OBSIDIAN:0)
Block(-5,20,-7,OBSIDIAN:0)
Block(-5,20,-6,OBSIDIAN:0)
Block(-5,20,-5,OBSIDIAN:0)
Block(-5,20,-4,OBSIDIAN:0)
Block(-5,20,-3,OBSIDIAN:0)
Block(-5,20,-2,OBSIDIAN:0)
Block(-5,20,-1,OBSIDIAN:0)
Block(-5,20,0,OBSIDIAN:0)
Block(-5,20,1,OBSIDIAN:0)
Block(-5,20,2,OBSIDIAN:0)
Block(-5,20,3,OBSIDIAN:0)
Block(-5,20,4,OBSIDIAN:0)
Block(-5,20,5,OBSIDIAN:0)
Block(-5,20,6,OBSIDIAN:0)
Block(-5,20,7,OBSIDIAN:0)
Block(-5,20,8,OBSIDIAN:0)
Block(-5,21,-7,OBSIDIAN:0)
Block(-5,21,-6,OBSIDIAN:0)
Block(-5,21,-5,OBSIDIAN:0)
Block(-5,21,-4,OBSIDIAN:0)
Block(-5,21,-3,OBSIDIAN:0)
Block(-5,21,-2,OBSIDIAN:0)
Block(-5,21,-1,OBSIDIAN:0)
Block(-5,21,0,OBSIDIAN:0)
Block(-5,21,1,OBSIDIAN:0)
Block(-5,21,2,OBSIDIAN:0)
Block(-5,21,3,OBSIDIAN:0)
Block(-5,21,4,OBSIDIAN:0)
Block(-5,21,5,OBSIDIAN:0)
Block(-5,21,6,OBSIDIAN:0)
Block(-5,21,7,OBSIDIAN:0)
Block(-5,21,8,OBSIDIAN:0)
Block(-5,22,-7,OBSIDIAN:0)
Block(-5,22,-6,OBSIDIAN:0)
Block(-5,22,-5,STONE:3)
Block(-5,22,-4,STONE:3)
Block(-5,22,-3,STONE:3)
Block(-5,22,-2,OBSIDIAN:0)
Block(-5,22,-1,OBSIDIAN:0)
Block(-5,22,0,OBSIDIAN:0)
Block(-5,22,1,OBSIDIAN:0)
Block(-5,22,2,OBSIDIAN:0)
Block(-5,22,3,OBSIDIAN:0)
Block(-5,22,4,OBSIDIAN:0)
Block(-5,22,5,OBSIDIAN:0)
Block(-5,22,6,OBSIDIAN:0)
Block(-5,22,7,OBSIDIAN:0)
Block(-5,22,8,OBSIDIAN:0)
Block(-5,23,-7,OBSIDIAN:0)
Block(-5,23,-6,STATIONARY_LAVA:0)
Block(-5,23,-5,STATIONARY_LAVA:0)
Block(-5,23,-4,STATIONARY_LAVA:0)
Block(-5,23,-3,STATIONARY_LAVA:0)
Block(-5,23,-2,STATIONARY_LAVA:0)
Block(-5,23,-1,STATIONARY_LAVA:0)
Block(-5,23,0,STATIONARY_LAVA:0)
Block(-5,23,1,OBSIDIAN:0)
Block(-5,23,2,OBSIDIAN:0)
Block(-5,23,3,OBSIDIAN:0)
Block(-5,23,4,OBSIDIAN:0)
Block(-5,23,5,OBSIDIAN:0)
Block(-5,23,6,STONE:5)
Block(-5,23,7,STONE:5)
Block(-5,23,8,STONE:5)
Block(-5,24,3,OBSIDIAN:0)
Block(-5,24,4,OBSIDIAN:0)
Block(-5,24,5,STONE:5)
Block(-5,24,6,STONE:5)
Block(-5,24,7,STONE:5)
Block(-5,24,8,STONE:5)
Block(-5,25,3,OBSIDIAN:0)
Block(-5,25,4,STONE:5)
Block(-5,25,5,STONE:5)
Block(-5,25,6,STONE:5)
Block(-5,25,7,STONE:5)
Block(-5,25,8,STONE:5)
Block(-5,26,-7,OBSIDIAN:0)
Block(-5,26,8,STONE:5)
Block(-5,73,-5,OBSIDIAN:0)
Block(-5,73,-4,OBSIDIAN:0)
Block(-5,73,-3,OBSIDIAN:0)
Block(-5,73,-2,OBSIDIAN:0)
Block(-5,73,-1,OBSIDIAN:0)
Block(-5,73,0,OBSIDIAN:0)
Block(-5,73,1,OBSIDIAN:0)
Block(-5,73,2,OBSIDIAN:0)
Block(-5,73,3,OBSIDIAN:0)
Block(-5,73,4,OBSIDIAN:0)
Block(-5,73,5,OBSIDIAN:0)
Block(-5,73,6,OBSIDIAN:0)
Block(-5,73,7,OBSIDIAN:0)
Block(-5,73,8,OBSIDIAN:0)
Block(-5,74,-7,OBSIDIAN:0)
Block(-5,74,-6,OBSIDIAN:0)
Block(-5,74,-5,OBSIDIAN:0)
Block(-5,74,-4,OBSIDIAN:0)
Block(-5,74,-3,OBSIDIAN:0)
Block(-5,74,-2,OBSIDIAN:0)
Block(-5,74,-1,OBSIDIAN:0)
Block(-5,74,0,OBSIDIAN:0)
Block(-5,74,1,OBSIDIAN:0)
Block(-5,74,2,OBSIDIAN:0)
Block(-5,74,3,OBSIDIAN:0)
Block(-5,74,4,OBSIDIAN:0)
Block(-5,74,5,OBSIDIAN:0)
Block(-5,74,6,OBSIDIAN:0)
Block(-5,74,7,OBSIDIAN:0)
Block(-5,74,8,OBSIDIAN:0)
Block(-5,75,-7,OBSIDIAN:0)
Block(-5,75,-6,OBSIDIAN:0)
Block(-5,75,-5,OBSIDIAN:0)
Block(-5,75,-4,OBSIDIAN:0)
Block(-5,75,-3,OBSIDIAN:0)
Block(-5,75,-2,OBSIDIAN:0)
Block(-5,75,-1,OBSIDIAN:0)
Block(-5,75,0,OBSIDIAN:0)
Block(-5,75,1,OBSIDIAN:0)
Block(-5,75,2,OBSIDIAN:0)
Block(-5,75,3,OBSIDIAN:0)
Block(-5,75,4,OBSIDIAN:0)
Block(-5,75,5,OBSIDIAN:0)
Block(-5,75,6,OBSIDIAN:0)
Block(-5,75,7,OBSIDIAN:0)
Block(-5,75,8,OBSIDIAN:0)
Block(-5,76,-7,OBSIDIAN:0)
Block(-5,76,-6,OBSIDIAN:0)
Block(-5,76,-5,OBSIDIAN:0)
Block(-5,76,-4,OBSIDIAN:0)
Block(-5,76,-3,OBSIDIAN:0)
Block(-5,76,-2,OBSIDIAN:0)
Block(-5,76,-1,OBSIDIAN:0)
Block(-5,76,0,OBSIDIAN:0)
Block(-5,76,1,OBSIDIAN:0)
Block(-5,76,2,OBSIDIAN:0)
Block(-5,76,3,OBSIDIAN:0)
Block(-5,76,4,OBSIDIAN:0)
Block(-5,76,5,OBSIDIAN:0)
Block(-5,76,6,OBSIDIAN:0)
Block(-5,76,7,OBSIDIAN:0)
Block(-5,76,8,OBSIDIAN:0)
Block(-5,77,-7,OBSIDIAN:0)
Block(-5,77,-6,OBSIDIAN:0)
Block(-5,77,-5,OBSIDIAN:0)
Block(-5,77,-4,OBSIDIAN:0)
Block(-5,77,-3,OBSIDIAN:0)
Block(-5,77,-2,OBSIDIAN:0)
Block(-5,77,-1,OBSIDIAN:0)
Block(-5,77,0,OBSIDIAN:0)
Block(-5,77,1,OBSIDIAN:0)
Block(-5,77,2,OBSIDIAN:0)
Block(-5,77,3,OBSIDIAN:0)
Block(-5,77,4,OBSIDIAN:0)
Block(-5,77,5,OBSIDIAN:0)
Block(-5,77,6,OBSIDIAN:0)
Block(-5,77,7,OBSIDIAN:0)
Block(-5,77,8,OBSIDIAN:0)
Block(-5,78,-7,OBSIDIAN:0)
Block(-5,78,-6,OBSIDIAN:0)
Block(-5,78,-5,OBSIDIAN:0)
Block(-5,78,-4,OBSIDIAN:0)
Block(-5,78,-3,OBSIDIAN:0)
Block(-5,78,-2,OBSIDIAN:0)
Block(-5,78,-1,OBSIDIAN:0)
Block(-5,78,0,OBSIDIAN:0)
Block(-5,78,1,OBSIDIAN:0)
Block(-5,78,2,OBSIDIAN:0)
Block(-5,78,3,OBSIDIAN:0)
Block(-5,78,4,OBSIDIAN:0)
Block(-5,78,5,OBSIDIAN:0)
Block(-5,78,6,OBSIDIAN:0)
Block(-5,78,7,OBSIDIAN:0)
Block(-5,78,8,OBSIDIAN:0)
Block(-5,79,-7,OBSIDIAN:0)
Block(-5,79,-6,OBSIDIAN:0)
Block(-5,79,-5,OBSIDIAN:0)
Block(-5,79,-4,OBSIDIAN:0)
Block(-5,79,-3,OBSIDIAN:0)
Block(-5,79,-2,OBSIDIAN:0)
Block(-5,79,-1,OBSIDIAN:0)
Block(-5,79,0,OBSIDIAN:0)
Block(-5,79,1,OBSIDIAN:0)
Block(-5,79,2,OBSIDIAN:0)
Block(-5,79,3,OBSIDIAN:0)
Block(-5,79,4,OBSIDIAN:0)
Block(-5,79,5,OBSIDIAN:0)
Block(-5,79,6,OBSIDIAN:0)
Block(-5,79,7,OBSIDIAN:0)
Block(-5,79,8,OBSIDIAN:0)
Block(-5,80,-7,OBSIDIAN:0)
Block(-5,80,-6,OBSIDIAN:0)
Block(-5,80,-5,OBSIDIAN:0)
Block(-5,80,-4,OBSIDIAN:0)
Block(-5,80,-3,OBSIDIAN:0)
Block(-5,80,-2,OBSIDIAN:0)
Block(-5,80,-1,OBSIDIAN:0)
Block(-5,80,0,OBSIDIAN:0)
Block(-5,80,1,OBSIDIAN:0)
Block(-5,80,2,OBSIDIAN:0)
Block(-5,80,3,OBSIDIAN:0)
Block(-5,80,4,OBSIDIAN:0)
Block(-5,80,5,OBSIDIAN:0)
Block(-5,80,6,OBSIDIAN:0)
Block(-5,80,7,OBSIDIAN:0)
Block(-5,80,8,OBSIDIAN:0)
Block(-5,81,-7,OBSIDIAN:0)
Block(-5,81,-6,OBSIDIAN:0)
Block(-5,81,-5,OBSIDIAN:0)
Block(-5,81,-4,OBSIDIAN:0)
Block(-5,81,-3,OBSIDIAN:0)
Block(-5,81,-2,OBSIDIAN:0)
Block(-5,81,-1,OBSIDIAN:0)
Block(-5,81,0,OBSIDIAN:0)
Block(-5,81,1,OBSIDIAN:0)
Block(-5,81,2,OBSIDIAN:0)
Block(-5,81,3,OBSIDIAN:0)
Block(-5,81,4,OBSIDIAN:0)
Block(-5,81,5,OBSIDIAN:0)
Block(-5,81,6,OBSIDIAN:0)
Block(-5,81,7,OBSIDIAN:0)
Block(-5,81,8,OBSIDIAN:0)
Block(-5,82,-7,OBSIDIAN:0)
Block(-5,82,-6,OBSIDIAN:0)
Block(-5,82,-5,OBSIDIAN:0)
Block(-5,82,-4,OBSIDIAN:0)
Block(-5,82,-3,OBSIDIAN:0)
Block(-5,82,-2,OBSIDIAN:0)
Block(-5,82,-1,OBSIDIAN:0)
Block(-5,82,0,OBSIDIAN:0)
Block(-5,82,1,OBSIDIAN:0)
Block(-5,82,2,OBSIDIAN:0)
Block(-5,82,3,OBSIDIAN:0)
Block(-5,82,4,OBSIDIAN:0)
Block(-5,82,5,OBSIDIAN:0)
Block(-5,82,6,OBSIDIAN:0)
Block(-5,82,7,OBSIDIAN:0)
Block(-5,82,8,OBSIDIAN:0)
Block(-5,83,-7,OBSIDIAN:0)
Block(-5,83,-6,OBSIDIAN:0)
Block(-5,83,-5,OBSIDIAN:0)
Block(-5,83,-4,OBSIDIAN:0)
Block(-5,83,-3,OBSIDIAN:0)
Block(-5,83,-2,OBSIDIAN:0)
Block(-5,83,-1,OBSIDIAN:0)
Block(-5,83,0,OBSIDIAN:0)
Block(-5,83,1,OBSIDIAN:0)
Block(-5,83,2,OBSIDIAN:0)
Block(-5,83,3,OBSIDIAN:0)
Block(-5,83,4,OBSIDIAN:0)
Block(-5,83,5,OBSIDIAN:0)
Block(-5,83,6,OBSIDIAN:0)
Block(-5,83,7,OBSIDIAN:0)
Block(-5,83,8,OBSIDIAN:0)
Block(-5,84,-7,OBSIDIAN:0)
Block(-5,84,-6,OBSIDIAN:0)
Block(-5,84,-5,OBSIDIAN:0)
Block(-5,84,-4,OBSIDIAN:0)
Block(-5,84,-3,OBSIDIAN:0)
Block(-5,84,-2,OBSIDIAN:0)
Block(-5,84,-1,OBSIDIAN:0)
Block(-5,84,0,OBSIDIAN:0)
Block(-5,84,1,OBSIDIAN:0)
Block(-5,84,2,OBSIDIAN:0)
Block(-5,84,3,OBSIDIAN:0)
Block(-5,84,4,OBSIDIAN:0)
Block(-5,84,5,OBSIDIAN:0)
Block(-5,84,6,OBSIDIAN:0)
Block(-5,84,7,OBSIDIAN:0)
Block(-5,84,8,OBSIDIAN:0)
Block(-5,85,-7,OBSIDIAN:0)
Block(-5,85,-6,OBSIDIAN:0)
Block(-5,85,-5,OBSIDIAN:0)
Block(-5,85,-4,OBSIDIAN:0)
Block(-5,85,-3,OBSIDIAN:0)
Block(-5,85,-2,OBSIDIAN:0)
Block(-5,85,-1,OBSIDIAN:0)
Block(-5,85,0,OBSIDIAN:0)
Block(-5,85,1,OBSIDIAN:0)
Block(-5,85,2,OBSIDIAN:0)
Block(-5,85,3,OBSIDIAN:0)
Block(-5,85,4,OBSIDIAN:0)
Block(-5,85,5,OBSIDIAN:0)
Block(-5,85,6,OBSIDIAN:0)
Block(-5,85,7,OBSIDIAN:0)
Block(-5,85,8,OBSIDIAN:0)
Block(-5,86,-7,OBSIDIAN:0)
Block(-5,86,-6,OBSIDIAN:0)
Block(-5,86,-5,OBSIDIAN:0)
Block(-5,86,-4,OBSIDIAN:0)
Block(-5,86,-3,OBSIDIAN:0)
Block(-5,86,-2,OBSIDIAN:0)
Block(-5,86,-1,OBSIDIAN:0)
Block(-5,86,0,OBSIDIAN:0)
Block(-5,86,1,OBSIDIAN:0)
Block(-5,86,2,OBSIDIAN:0)
Block(-5,86,3,OBSIDIAN:0)
Block(-5,86,4,OBSIDIAN:0)
Block(-5,86,5,OBSIDIAN:0)
Block(-5,86,6,OBSIDIAN:0)
Block(-5,86,7,OBSIDIAN:0)
Block(-5,86,8,OBSIDIAN:0)
Block(-5,87,-7,OBSIDIAN:0)
Block(-5,87,-6,OBSIDIAN:0)
Block(-5,87,-5,OBSIDIAN:0)
Block(-5,87,-4,OBSIDIAN:0)
Block(-5,87,-3,OBSIDIAN:0)
Block(-5,87,-2,OBSIDIAN:0)
Block(-5,87,-1,OBSIDIAN:0)
Block(-5,87,0,OBSIDIAN:0)
Block(-5,87,1,OBSIDIAN:0)
Block(-5,87,2,OBSIDIAN:0)
Block(-5,87,3,OBSIDIAN:0)
Block(-5,87,4,OBSIDIAN:0)
Block(-5,87,5,OBSIDIAN:0)
Block(-5,87,6,STONE:3)
Block(-5,87,7,STONE:3)
Block(-5,87,8,STONE:3)
Block(-5,88,-7,OBSIDIAN:0)
Block(-5,88,-6,OBSIDIAN:0)
Block(-5,88,-5,OBSIDIAN:0)
Block(-5,88,-4,OBSIDIAN:0)
Block(-5,88,-3,OBSIDIAN:0)
Block(-5,88,-2,OBSIDIAN:0)
Block(-5,88,-1,OBSIDIAN:0)
Block(-5,88,0,OBSIDIAN:0)
Block(-5,88,1,OBSIDIAN:0)
Block(-5,88,2,OBSIDIAN:0)
Block(-5,88,3,OBSIDIAN:0)
Block(-5,88,4,OBSIDIAN:0)
Block(-5,88,5,STONE:3)
Block(-5,88,6,STONE:3)
Block(-5,88,7,STONE:3)
Block(-5,88,8,STONE:3)
Block(-5,89,-7,OBSIDIAN:0)
Block(-5,89,-6,OBSIDIAN:0)
Block(-5,89,-5,OBSIDIAN:0)
Block(-5,89,-4,OBSIDIAN:0)
Block(-5,89,-3,OBSIDIAN:0)
Block(-5,89,-2,OBSIDIAN:0)
Block(-5,89,-1,OBSIDIAN:0)
Block(-5,89,0,OBSIDIAN:0)
Block(-5,89,1,OBSIDIAN:0)
Block(-5,89,2,OBSIDIAN:0)
Block(-5,89,3,OBSIDIAN:0)
Block(-5,89,4,STONE:3)
Block(-5,89,5,STONE:3)
Block(-5,89,6,STONE:3)
Block(-5,89,7,STONE:3)
Block(-5,89,8,STONE:3)
Block(-5,90,-7,OBSIDIAN:0)
Block(-5,90,-6,OBSIDIAN:0)
Block(-5,90,-5,OBSIDIAN:0)
Block(-5,90,-4,OBSIDIAN:0)
Block(-5,90,-3,OBSIDIAN:0)
Block(-5,90,-2,OBSIDIAN:0)
Block(-5,90,-1,OBSIDIAN:0)
Block(-5,90,0,OBSIDIAN:0)
Block(-5,90,1,OBSIDIAN:0)
Block(-5,90,2,STONE:3)
Block(-5,90,3,STONE:3)
Block(-5,90,4,STONE:3)
Block(-5,90,5,STONE:3)
Block(-5,90,6,STONE:3)
Block(-5,90,7,STONE:3)
Block(-5,90,8,STONE:3)
Block(-5,91,-7,OBSIDIAN:0)
Block(-5,91,-6,OBSIDIAN:0)
Block(-5,91,-5,OBSIDIAN:0)
Block(-5,91,-4,OBSIDIAN:0)
Block(-5,91,-3,OBSIDIAN:0)
Block(-5,91,-2,OBSIDIAN:0)
Block(-5,91,-1,OBSIDIAN:0)
Block(-5,91,0,OBSIDIAN:0)
Block(-5,91,1,STONE:3)
Block(-5,91,2,STONE:3)
Block(-5,91,3,STONE:3)
Block(-5,91,4,STONE:3)
Block(-5,91,5,STONE:3)
Block(-5,91,6,STONE:3)
Block(-5,91,7,STONE:3)
Block(-5,91,8,STONE:3)
Block(-5,92,-7,OBSIDIAN:0)
Block(-5,92,-6,OBSIDIAN:0)
Block(-5,92,-5,OBSIDIAN:0)
Block(-5,92,-4,OBSIDIAN:0)
Block(-5,92,-3,OBSIDIAN:0)
Block(-5,92,-2,OBSIDIAN:0)
Block(-5,92,-1,OBSIDIAN:0)
Block(-5,92,0,STONE:3)
Block(-5,92,1,STONE:3)
Block(-5,92,2,STONE:3)
Block(-5,92,3,STONE:3)
Block(-5,92,4,STONE:3)
Block(-5,92,5,STONE:3)
Block(-5,92,6,STONE:3)
Block(-5,92,7,STONE:3)
Block(-5,93,-7,OBSIDIAN:0)
Block(-5,93,-6,OBSIDIAN:0)
Block(-5,93,-5,OBSIDIAN:0)
Block(-5,93,-4,OBSIDIAN:0)
Block(-5,93,-3,OBSIDIAN:0)
Block(-5,93,-2,OBSIDIAN:0)
Block(-5,93,-1,OBSIDIAN:0)
Block(-5,93,0,STONE:3)
Block(-5,93,1,STONE:3)
Block(-5,93,2,STONE:3)
Block(-5,93,3,STONE:3)
Block(-5,93,4,STONE:5)
Block(-5,94,-7,OBSIDIAN:0)
Block(-5,94,-6,OBSIDIAN:0)
Block(-5,94,-5,OBSIDIAN:0)
Block(-5,94,-4,OBSIDIAN:0)
Block(-5,94,-3,OBSIDIAN:0)
Block(-5,94,-2,OBSIDIAN:0)
Block(-5,94,-1,OBSIDIAN:0)
Block(-5,94,0,STONE:3)
Block(-5,94,1,STONE:3)
Block(-5,94,2,STONE:3)
Block(-5,94,3,STONE:5)
Block(-5,95,-7,STONE:3)
Block(-5,95,-6,OBSIDIAN:0)
Block(-5,95,-5,OBSIDIAN:0)
Block(-5,95,-4,OBSIDIAN:0)
Block(-5,95,-3,OBSIDIAN:0)
Block(-5,95,-2,OBSIDIAN:0)
Block(-5,95,-1,OBSIDIAN:0)
Block(-5,95,0,STONE:3)
Block(-5,95,1,STONE:3)
Block(-5,95,2,STONE:5)
Block(-5,96,-7,STONE:3)
Block(-5,96,-6,STONE:3)
Block(-5,96,-5,OBSIDIAN:0)
Block(-5,96,-4,OBSIDIAN:0)
Block(-5,96,-3,OBSIDIAN:0)
Block(-5,96,-2,OBSIDIAN:0)
Block(-5,96,-1,OBSIDIAN:0)
Block(-5,96,0,STONE:3)
Block(-5,96,1,STONE:3)
Block(-5,97,-7,STONE:3)
Block(-5,97,-6,STONE:3)
Block(-5,97,-5,OBSIDIAN:0)
Block(-5,97,-4,OBSIDIAN:0)
Block(-5,97,-3,OBSIDIAN:0)
Block(-5,97,-2,OBSIDIAN:0)
Block(-5,97,-1,OBSIDIAN:0)
Block(-5,97,0,STONE:3)
Block(-5,97,1,STONE:5)
Block(-5,98,-7,STONE:3)
Block(-5,98,-6,STONE:3)
Block(-5,98,-5,OBSIDIAN:0)
Block(-5,98,-4,OBSIDIAN:0)
Block(-5,98,-3,OBSIDIAN:0)
Block(-5,98,-2,OBSIDIAN:0)
Block(-5,98,-1,STONE:3)
Block(-5,98,0,STONE:5)
Block(-5,99,-7,STONE:3)
Block(-5,99,-6,STONE:3)
Block(-5,99,-5,OBSIDIAN:0)
Block(-5,99,-4,STONE:3)
Block(-5,99,-3,STONE:3)
Block(-5,99,-2,STONE:3)
Block(-5,99,-1,STONE:5)
Block(-5,100,-7,STONE:3)
Block(-5,100,-6,STONE:5)
Block(-5,100,-5,STONE:3)
Block(-5,100,-4,STONE:5)
Block(-5,100,-3,STONE:5)
Block(-5,100,-2,STONE:5)
Block(-5,101,-7,STONE:5)
Block(-5,101,-5,STONE:5)
Block(-4,9,6,STONE:3)
Block(-4,9,7,STONE:3)
Block(-4,9,8,STONE:3)
Block(-4,10,-1,STONE:3)
Block(-4,10,0,STONE:3)
Block(-4,10,1,STONE:3)
Block(-4,10,2,STONE:3)
Block(-4,10,3,STONE:3)
Block(-4,10,4,STONE:3)
Block(-4,10,5,STONE:3)
Block(-4,10,6,STONE:3)
Block(-4,10,7,STONE:3)
Block(-4,10,8,STONE:3)
Block(-4,11,-5,STONE:3)
Block(-4,11,-4,STONE:3)
Block(-4,11,-3,STONE:3)
Block(-4,11,-2,STONE:3)
Block(-4,11,-1,STONE:3)
Block(-4,11,0,STONE:3)
Block(-4,11,1,STONE:3)
Block(-4,11,2,STONE:3)
Block(-4,11,3,STONE:3)
Block(-4,11,4,STONE:3)
Block(-4,11,5,STONE:3)
Block(-4,11,6,STONE:3)
Block(-4,11,7,STONE:3)
Block(-4,11,8,STONE:3)
Block(-4,12,-7,STONE:3)
Block(-4,12,-6,STONE:3)
Block(-4,12,-5,STONE:3)
Block(-4,12,-4,STONE:3)
Block(-4,12,-3,STONE:3)
Block(-4,12,-2,STONE:3)
Block(-4,12,-1,STONE:3)
Block(-4,12,0,STONE:3)
Block(-4,12,1,STONE:3)
Block(-4,12,2,STONE:3)
Block(-4,12,3,STONE:3)
Block(-4,12,4,STONE:3)
Block(-4,12,5,STONE:3)
Block(-4,12,6,STONE:3)
Block(-4,12,7,STONE:3)
Block(-4,12,8,STONE:3)
Block(-4,13,-7,STONE:3)
Block(-4,13,-6,STONE:3)
Block(-4,13,-5,STONE:3)
Block(-4,13,-4,STONE:3)
Block(-4,13,-3,STONE:3)
Block(-4,13,-2,STONE:3)
Block(-4,13,-1,STONE:3)
Block(-4,13,0,STONE:3)
Block(-4,13,1,STONE:3)
Block(-4,13,2,STONE:3)
Block(-4,13,3,STONE:3)
Block(-4,13,4,STONE:3)
Block(-4,13,5,STONE:3)
Block(-4,13,6,STONE:3)
Block(-4,13,7,STONE:3)
Block(-4,13,8,STONE:3)
Block(-4,14,-7,STONE:3)
Block(-4,14,-6,STONE:3)
Block(-4,14,-5,STONE:3)
Block(-4,14,-4,STONE:3)
Block(-4,14,-3,STONE:3)
Block(-4,14,-2,STONE:3)
Block(-4,14,-1,STONE:3)
Block(-4,14,0,STONE:3)
Block(-4,14,1,STONE:3)
Block(-4,14,2,OBSIDIAN:0)
Block(-4,14,3,STONE:3)
Block(-4,14,4,STONE:3)
Block(-4,14,5,STONE:3)
Block(-4,14,6,STONE:3)
Block(-4,14,7,STONE:3)
Block(-4,14,8,OBSIDIAN:0)
Block(-4,15,-7,STONE:3)
Block(-4,15,-6,STONE:3)
Block(-4,15,-5,STONE:3)
Block(-4,15,-4,STONE:3)
Block(-4,15,-3,STONE:3)
Block(-4,15,-2,STONE:3)
Block(-4,15,-1,STONE:3)
Block(-4,15,0,STONE:3)
Block(-4,15,1,OBSIDIAN:0)
Block(-4,15,2,OBSIDIAN:0)
Block(-4,15,3,OBSIDIAN:0)
Block(-4,15,4,OBSIDIAN:0)
Block(-4,15,5,OBSIDIAN:0)
Block(-4,15,6,OBSIDIAN:0)
Block(-4,15,7,OBSIDIAN:0)
Block(-4,15,8,OBSIDIAN:0)
Block(-4,16,-7,STONE:3)
Block(-4,16,-6,STONE:3)
Block(-4,16,-5,OBSIDIAN:0)
Block(-4,16,-4,OBSIDIAN:0)
Block(-4,16,-3,OBSIDIAN:0)
Block(-4,16,-2,OBSIDIAN:0)
Block(-4,16,-1,OBSIDIAN:0)
Block(-4,16,0,OBSIDIAN:0)
Block(-4,16,1,OBSIDIAN:0)
Block(-4,16,2,OBSIDIAN:0)
Block(-4,16,3,OBSIDIAN:0)
Block(-4,16,4,OBSIDIAN:0)
Block(-4,16,5,OBSIDIAN:0)
Block(-4,16,6,OBSIDIAN:0)
Block(-4,16,7,OBSIDIAN:0)
Block(-4,16,8,OBSIDIAN:0)
Block(-4,17,-7,STONE:3)
Block(-4,17,-6,OBSIDIAN:0)
Block(-4,17,-5,OBSIDIAN:0)
Block(-4,17,-4,OBSIDIAN:0)
Block(-4,17,-3,OBSIDIAN:0)
Block(-4,17,-2,OBSIDIAN:0)
Block(-4,17,-1,OBSIDIAN:0)
Block(-4,17,0,OBSIDIAN:0)
Block(-4,17,1,OBSIDIAN:0)
Block(-4,17,2,OBSIDIAN:0)
Block(-4,17,3,OBSIDIAN:0)
Block(-4,17,4,OBSIDIAN:0)
Block(-4,17,5,OBSIDIAN:0)
Block(-4,17,6,OBSIDIAN:0)
Block(-4,17,7,OBSIDIAN:0)
Block(-4,17,8,OBSIDIAN:0)
Block(-4,18,-7,OBSIDIAN:0)
Block(-4,18,-6,OBSIDIAN:0)
Block(-4,18,-5,OBSIDIAN:0)
Block(-4,18,-4,OBSIDIAN:0)
Block(-4,18,-3,OBSIDIAN:0)
Block(-4,18,-2,OBSIDIAN:0)
Block(-4,18,-1,OBSIDIAN:0)
Block(-4,18,0,OBSIDIAN:0)
Block(-4,18,1,OBSIDIAN:0)
Block(-4,18,2,OBSIDIAN:0)
Block(-4,18,3,OBSIDIAN:0)
Block(-4,18,4,OBSIDIAN:0)
Block(-4,18,5,OBSIDIAN:0)
Block(-4,18,6,OBSIDIAN:0)
Block(-4,18,7,OBSIDIAN:0)
Block(-4,18,8,OBSIDIAN:0)
Block(-4,19,-7,OBSIDIAN:0)
Block(-4,19,-6,OBSIDIAN:0)
Block(-4,19,-5,OBSIDIAN:0)
Block(-4,19,-4,OBSIDIAN:0)
Block(-4,19,-3,OBSIDIAN:0)
Block(-4,19,-2,OBSIDIAN:0)
Block(-4,19,-1,OBSIDIAN:0)
Block(-4,19,0,OBSIDIAN:0)
Block(-4,19,1,OBSIDIAN:0)
Block(-4,19,2,OBSIDIAN:0)
Block(-4,19,3,OBSIDIAN:0)
Block(-4,19,4,OBSIDIAN:0)
Block(-4,19,5,OBSIDIAN:0)
Block(-4,19,6,OBSIDIAN:0)
Block(-4,19,7,OBSIDIAN:0)
Block(-4,19,8,OBSIDIAN:0)
Block(-4,20,-7,OBSIDIAN:0)
Block(-4,20,-6,OBSIDIAN:0)
Block(-4,20,-5,OBSIDIAN:0)
Block(-4,20,-4,OBSIDIAN:0)
Block(-4,20,-3,OBSIDIAN:0)
Block(-4,20,-2,OBSIDIAN:0)
Block(-4,20,-1,OBSIDIAN:0)
Block(-4,20,0,OBSIDIAN:0)
Block(-4,20,1,OBSIDIAN:0)
Block(-4,20,2,OBSIDIAN:0)
Block(-4,20,3,OBSIDIAN:0)
Block(-4,20,4,OBSIDIAN:0)
Block(-4,20,5,OBSIDIAN:0)
Block(-4,20,6,OBSIDIAN:0)
Block(-4,20,7,OBSIDIAN:0)
Block(-4,20,8,OBSIDIAN:0)
Block(-4,21,-7,OBSIDIAN:0)
Block(-4,21,-6,OBSIDIAN:0)
Block(-4,21,-5,OBSIDIAN:0)
Block(-4,21,-4,OBSIDIAN:0)
Block(-4,21,-3,OBSIDIAN:0)
Block(-4,21,-2,OBSIDIAN:0)
Block(-4,21,-1,OBSIDIAN:0)
Block(-4,21,0,OBSIDIAN:0)
Block(-4,21,1,OBSIDIAN:0)
Block(-4,21,2,OBSIDIAN:0)
Block(-4,21,3,OBSIDIAN:0)
Block(-4,21,4,OBSIDIAN:0)
Block(-4,21,5,OBSIDIAN:0)
Block(-4,21,6,OBSIDIAN:0)
Block(-4,21,7,OBSIDIAN:0)
Block(-4,21,8,OBSIDIAN:0)
Block(-4,22,-7,OBSIDIAN:0)
Block(-4,22,-6,STONE:3)
Block(-4,22,-5,STONE:3)
Block(-4,22,-4,STONE:3)
Block(-4,22,-3,OBSIDIAN:0)
Block(-4,22,-2,OBSIDIAN:0)
Block(-4,22,-1,OBSIDIAN:0)
Block(-4,22,0,OBSIDIAN:0)
Block(-4,22,1,OBSIDIAN:0)
Block(-4,22,2,OBSIDIAN:0)
Block(-4,22,3,OBSIDIAN:0)
Block(-4,22,4,OBSIDIAN:0)
Block(-4,22,5,OBSIDIAN:0)
Block(-4,22,6,OBSIDIAN:0)
Block(-4,22,7,OBSIDIAN:0)
Block(-4,22,8,OBSIDIAN:0)
Block(-4,23,-7,STATIONARY_LAVA:0)
Block(-4,23,-6,STATIONARY_LAVA:0)
Block(-4,23,-5,STATIONARY_LAVA:0)
Block(-4,23,-4,STATIONARY_LAVA:0)
Block(-4,23,-3,STATIONARY_LAVA:0)
Block(-4,23,-2,STATIONARY_LAVA:0)
Block(-4,23,-1,STATIONARY_LAVA:0)
Block(-4,23,0,OBSIDIAN:0)
Block(-4,23,1,OBSIDIAN:0)
Block(-4,23,2,OBSIDIAN:0)
Block(-4,23,3,OBSIDIAN:0)
Block(-4,23,4,OBSIDIAN:0)
Block(-4,23,5,OBSIDIAN:0)
Block(-4,23,6,STONE:5)
Block(-4,23,7,STONE:5)
Block(-4,23,8,STONE:5)
Block(-4,24,1,OBSIDIAN:0)
Block(-4,24,2,OBSIDIAN:0)
Block(-4,24,3,OBSIDIAN:0)
Block(-4,24,4,STONE:5)
Block(-4,24,5,STONE:5)
Block(-4,24,6,STONE:5)
Block(-4,24,7,STONE:5)
Block(-4,24,8,STONE:5)
Block(-4,25,2,OBSIDIAN:0)
Block(-4,25,3,STONE:5)
Block(-4,25,4,STONE:5)
Block(-4,25,5,STONE:5)
Block(-4,25,6,GRASS:0)
Block(-4,25,7,STONE:5)
Block(-4,25,8,STONE:5)
Block(-4,26,4,STONE:5)
Block(-4,26,7,GRASS:0)
Block(-4,26,8,GRASS:0)
Block(-4,73,-7,OBSIDIAN:0)
Block(-4,73,-6,OBSIDIAN:0)
Block(-4,73,-5,OBSIDIAN:0)
Block(-4,73,-4,OBSIDIAN:0)
Block(-4,73,-3,OBSIDIAN:0)
Block(-4,73,-2,OBSIDIAN:0)
Block(-4,73,-1,OBSIDIAN:0)
Block(-4,73,0,OBSIDIAN:0)
Block(-4,73,1,OBSIDIAN:0)
Block(-4,73,2,OBSIDIAN:0)
Block(-4,73,3,OBSIDIAN:0)
Block(-4,73,4,OBSIDIAN:0)
Block(-4,73,5,OBSIDIAN:0)
Block(-4,73,6,OBSIDIAN:0)
Block(-4,73,7,OBSIDIAN:0)
Block(-4,73,8,OBSIDIAN:0)
Block(-4,74,-7,OBSIDIAN:0)
Block(-4,74,-6,OBSIDIAN:0)
Block(-4,74,-5,OBSIDIAN:0)
Block(-4,74,-4,OBSIDIAN:0)
Block(-4,74,-3,OBSIDIAN:0)
Block(-4,74,-2,OBSIDIAN:0)
Block(-4,74,-1,OBSIDIAN:0)
Block(-4,74,0,OBSIDIAN:0)
Block(-4,74,1,OBSIDIAN:0)
Block(-4,74,2,OBSIDIAN:0)
Block(-4,74,3,OBSIDIAN:0)
Block(-4,74,4,OBSIDIAN:0)
Block(-4,74,5,OBSIDIAN:0)
Block(-4,74,6,OBSIDIAN:0)
Block(-4,74,7,OBSIDIAN:0)
Block(-4,74,8,OBSIDIAN:0)
Block(-4,75,-7,OBSIDIAN:0)
Block(-4,75,-6,OBSIDIAN:0)
Block(-4,75,-5,OBSIDIAN:0)
Block(-4,75,-4,OBSIDIAN:0)
Block(-4,75,-3,OBSIDIAN:0)
Block(-4,75,-2,OBSIDIAN:0)
Block(-4,75,-1,OBSIDIAN:0)
Block(-4,75,0,OBSIDIAN:0)
Block(-4,75,1,OBSIDIAN:0)
Block(-4,75,2,OBSIDIAN:0)
Block(-4,75,3,OBSIDIAN:0)
Block(-4,75,4,OBSIDIAN:0)
Block(-4,75,5,OBSIDIAN:0)
Block(-4,75,6,OBSIDIAN:0)
Block(-4,75,7,OBSIDIAN:0)
Block(-4,75,8,OBSIDIAN:0)
Block(-4,76,-7,OBSIDIAN:0)
Block(-4,76,-6,OBSIDIAN:0)
Block(-4,76,-5,OBSIDIAN:0)
Block(-4,76,-4,OBSIDIAN:0)
Block(-4,76,-3,OBSIDIAN:0)
Block(-4,76,-2,OBSIDIAN:0)
Block(-4,76,-1,OBSIDIAN:0)
Block(-4,76,0,OBSIDIAN:0)
Block(-4,76,1,OBSIDIAN:0)
Block(-4,76,2,OBSIDIAN:0)
Block(-4,76,3,OBSIDIAN:0)
Block(-4,76,4,OBSIDIAN:0)
Block(-4,76,5,OBSIDIAN:0)
Block(-4,76,6,OBSIDIAN:0)
Block(-4,76,7,OBSIDIAN:0)
Block(-4,76,8,OBSIDIAN:0)
Block(-4,77,-7,OBSIDIAN:0)
Block(-4,77,-6,OBSIDIAN:0)
Block(-4,77,-5,OBSIDIAN:0)
Block(-4,77,-4,OBSIDIAN:0)
Block(-4,77,-3,OBSIDIAN:0)
Block(-4,77,-2,OBSIDIAN:0)
Block(-4,77,-1,OBSIDIAN:0)
Block(-4,77,0,OBSIDIAN:0)
Block(-4,77,1,OBSIDIAN:0)
Block(-4,77,2,OBSIDIAN:0)
Block(-4,77,3,OBSIDIAN:0)
Block(-4,77,4,OBSIDIAN:0)
Block(-4,77,5,OBSIDIAN:0)
Block(-4,77,6,OBSIDIAN:0)
Block(-4,77,7,OBSIDIAN:0)
Block(-4,77,8,OBSIDIAN:0)
Block(-4,78,-7,OBSIDIAN:0)
Block(-4,78,-6,OBSIDIAN:0)
Block(-4,78,-5,OBSIDIAN:0)
Block(-4,78,-4,OBSIDIAN:0)
Block(-4,78,-3,OBSIDIAN:0)
Block(-4,78,-2,OBSIDIAN:0)
Block(-4,78,-1,OBSIDIAN:0)
Block(-4,78,0,OBSIDIAN:0)
Block(-4,78,1,OBSIDIAN:0)
Block(-4,78,2,OBSIDIAN:0)
Block(-4,78,3,OBSIDIAN:0)
Block(-4,78,4,OBSIDIAN:0)
Block(-4,78,5,OBSIDIAN:0)
Block(-4,78,6,OBSIDIAN:0)
Block(-4,78,7,OBSIDIAN:0)
Block(-4,78,8,OBSIDIAN:0)
Block(-4,79,-7,OBSIDIAN:0)
Block(-4,79,-6,OBSIDIAN:0)
Block(-4,79,-5,OBSIDIAN:0)
Block(-4,79,-4,OBSIDIAN:0)
Block(-4,79,-3,OBSIDIAN:0)
Block(-4,79,-2,OBSIDIAN:0)
Block(-4,79,-1,OBSIDIAN:0)
Block(-4,79,0,OBSIDIAN:0)
Block(-4,79,1,OBSIDIAN:0)
Block(-4,79,2,OBSIDIAN:0)
Block(-4,79,3,OBSIDIAN:0)
Block(-4,79,4,OBSIDIAN:0)
Block(-4,79,5,OBSIDIAN:0)
Block(-4,79,6,OBSIDIAN:0)
Block(-4,79,7,OBSIDIAN:0)
Block(-4,79,8,OBSIDIAN:0)
Block(-4,80,-7,OBSIDIAN:0)
Block(-4,80,-6,OBSIDIAN:0)
Block(-4,80,-5,OBSIDIAN:0)
Block(-4,80,-4,OBSIDIAN:0)
Block(-4,80,-3,OBSIDIAN:0)
Block(-4,80,-2,OBSIDIAN:0)
Block(-4,80,-1,OBSIDIAN:0)
Block(-4,80,0,OBSIDIAN:0)
Block(-4,80,1,OBSIDIAN:0)
Block(-4,80,2,OBSIDIAN:0)
Block(-4,80,3,OBSIDIAN:0)
Block(-4,80,4,OBSIDIAN:0)
Block(-4,80,5,OBSIDIAN:0)
Block(-4,80,6,OBSIDIAN:0)
Block(-4,80,7,OBSIDIAN:0)
Block(-4,80,8,OBSIDIAN:0)
Block(-4,81,-7,OBSIDIAN:0)
Block(-4,81,-6,OBSIDIAN:0)
Block(-4,81,-5,OBSIDIAN:0)
Block(-4,81,-4,OBSIDIAN:0)
Block(-4,81,-3,OBSIDIAN:0)
Block(-4,81,-2,OBSIDIAN:0)
Block(-4,81,-1,OBSIDIAN:0)
Block(-4,81,0,OBSIDIAN:0)
Block(-4,81,1,OBSIDIAN:0)
Block(-4,81,2,OBSIDIAN:0)
Block(-4,81,3,OBSIDIAN:0)
Block(-4,81,4,OBSIDIAN:0)
Block(-4,81,5,OBSIDIAN:0)
Block(-4,81,6,OBSIDIAN:0)
Block(-4,81,7,OBSIDIAN:0)
Block(-4,81,8,OBSIDIAN:0)
Block(-4,82,-7,OBSIDIAN:0)
Block(-4,82,-6,OBSIDIAN:0)
Block(-4,82,-5,OBSIDIAN:0)
Block(-4,82,-4,OBSIDIAN:0)
Block(-4,82,-3,OBSIDIAN:0)
Block(-4,82,-2,OBSIDIAN:0)
Block(-4,82,-1,OBSIDIAN:0)
Block(-4,82,0,OBSIDIAN:0)
Block(-4,82,1,OBSIDIAN:0)
Block(-4,82,2,OBSIDIAN:0)
Block(-4,82,3,OBSIDIAN:0)
Block(-4,82,4,OBSIDIAN:0)
Block(-4,82,5,OBSIDIAN:0)
Block(-4,82,6,OBSIDIAN:0)
Block(-4,82,7,OBSIDIAN:0)
Block(-4,82,8,OBSIDIAN:0)
Block(-4,83,-7,OBSIDIAN:0)
Block(-4,83,-6,OBSIDIAN:0)
Block(-4,83,-5,OBSIDIAN:0)
Block(-4,83,-4,OBSIDIAN:0)
Block(-4,83,-3,OBSIDIAN:0)
Block(-4,83,-2,OBSIDIAN:0)
Block(-4,83,-1,OBSIDIAN:0)
Block(-4,83,0,OBSIDIAN:0)
Block(-4,83,1,OBSIDIAN:0)
Block(-4,83,2,OBSIDIAN:0)
Block(-4,83,3,OBSIDIAN:0)
Block(-4,83,4,OBSIDIAN:0)
Block(-4,83,5,OBSIDIAN:0)
Block(-4,83,6,OBSIDIAN:0)
Block(-4,83,7,OBSIDIAN:0)
Block(-4,83,8,OBSIDIAN:0)
Block(-4,84,-7,OBSIDIAN:0)
Block(-4,84,-6,OBSIDIAN:0)
Block(-4,84,-5,OBSIDIAN:0)
Block(-4,84,-4,OBSIDIAN:0)
Block(-4,84,-3,OBSIDIAN:0)
Block(-4,84,-2,OBSIDIAN:0)
Block(-4,84,-1,OBSIDIAN:0)
Block(-4,84,0,OBSIDIAN:0)
Block(-4,84,1,OBSIDIAN:0)
Block(-4,84,2,OBSIDIAN:0)
Block(-4,84,3,OBSIDIAN:0)
Block(-4,84,4,OBSIDIAN:0)
Block(-4,84,5,OBSIDIAN:0)
Block(-4,84,6,OBSIDIAN:0)
Block(-4,84,7,OBSIDIAN:0)
Block(-4,84,8,OBSIDIAN:0)
Block(-4,85,-7,OBSIDIAN:0)
Block(-4,85,-6,OBSIDIAN:0)
Block(-4,85,-5,OBSIDIAN:0)
Block(-4,85,-4,OBSIDIAN:0)
Block(-4,85,-3,OBSIDIAN:0)
Block(-4,85,-2,OBSIDIAN:0)
Block(-4,85,-1,OBSIDIAN:0)
Block(-4,85,0,OBSIDIAN:0)
Block(-4,85,1,OBSIDIAN:0)
Block(-4,85,2,OBSIDIAN:0)
Block(-4,85,3,OBSIDIAN:0)
Block(-4,85,4,OBSIDIAN:0)
Block(-4,85,5,OBSIDIAN:0)
Block(-4,85,6,OBSIDIAN:0)
Block(-4,85,7,OBSIDIAN:0)
Block(-4,85,8,OBSIDIAN:0)
Block(-4,86,-7,OBSIDIAN:0)
Block(-4,86,-6,OBSIDIAN:0)
Block(-4,86,-5,OBSIDIAN:0)
Block(-4,86,-4,OBSIDIAN:0)
Block(-4,86,-3,OBSIDIAN:0)
Block(-4,86,-2,OBSIDIAN:0)
Block(-4,86,-1,OBSIDIAN:0)
Block(-4,86,0,OBSIDIAN:0)
Block(-4,86,1,OBSIDIAN:0)
Block(-4,86,2,OBSIDIAN:0)
Block(-4,86,3,OBSIDIAN:0)
Block(-4,86,4,OBSIDIAN:0)
Block(-4,86,5,OBSIDIAN:0)
Block(-4,86,6,OBSIDIAN:0)
Block(-4,86,7,OBSIDIAN:0)
Block(-4,86,8,OBSIDIAN:0)
Block(-4,87,-7,OBSIDIAN:0)
Block(-4,87,-6,OBSIDIAN:0)
Block(-4,87,-5,OBSIDIAN:0)
Block(-4,87,-4,OBSIDIAN:0)
Block(-4,87,-3,OBSIDIAN:0)
Block(-4,87,-2,OBSIDIAN:0)
Block(-4,87,-1,OBSIDIAN:0)
Block(-4,87,0,OBSIDIAN:0)
Block(-4,87,1,OBSIDIAN:0)
Block(-4,87,2,OBSIDIAN:0)
Block(-4,87,3,OBSIDIAN:0)
Block(-4,87,4,OBSIDIAN:0)
Block(-4,87,5,OBSIDIAN:0)
Block(-4,87,6,STONE:3)
Block(-4,87,7,STONE:3)
Block(-4,87,8,STONE:3)
Block(-4,88,-7,OBSIDIAN:0)
Block(-4,88,-6,OBSIDIAN:0)
Block(-4,88,-5,OBSIDIAN:0)
Block(-4,88,-4,OBSIDIAN:0)
Block(-4,88,-3,OBSIDIAN:0)
Block(-4,88,-2,OBSIDIAN:0)
Block(-4,88,-1,OBSIDIAN:0)
Block(-4,88,0,OBSIDIAN:0)
Block(-4,88,1,OBSIDIAN:0)
Block(-4,88,2,OBSIDIAN:0)
Block(-4,88,3,OBSIDIAN:0)
Block(-4,88,4,OBSIDIAN:0)
Block(-4,88,5,STONE:3)
Block(-4,88,6,STONE:3)
Block(-4,88,7,STONE:3)
Block(-4,88,8,STONE:3)
Block(-4,89,-7,OBSIDIAN:0)
Block(-4,89,-6,OBSIDIAN:0)
Block(-4,89,-5,OBSIDIAN:0)
Block(-4,89,-4,OBSIDIAN:0)
Block(-4,89,-3,OBSIDIAN:0)
Block(-4,89,-2,OBSIDIAN:0)
Block(-4,89,-1,OBSIDIAN:0)
Block(-4,89,0,OBSIDIAN:0)
Block(-4,89,1,OBSIDIAN:0)
Block(-4,89,2,OBSIDIAN:0)
Block(-4,89,3,STONE:3)
Block(-4,89,4,STONE:3)
Block(-4,89,5,STONE:3)
Block(-4,89,6,STONE:3)
Block(-4,89,7,STONE:3)
Block(-4,89,8,STONE:3)
Block(-4,90,-7,OBSIDIAN:0)
Block(-4,90,-6,OBSIDIAN:0)
Block(-4,90,-5,OBSIDIAN:0)
Block(-4,90,-4,OBSIDIAN:0)
Block(-4,90,-3,OBSIDIAN:0)
Block(-4,90,-2,OBSIDIAN:0)
Block(-4,90,-1,OBSIDIAN:0)
Block(-4,90,0,OBSIDIAN:0)
Block(-4,90,1,STONE:3)
Block(-4,90,2,STONE:3)
Block(-4,90,3,STONE:3)
Block(-4,90,4,STONE:3)
Block(-4,90,5,STONE:3)
Block(-4,90,6,STONE:3)
Block(-4,90,7,STONE:3)
Block(-4,90,8,STONE:3)
Block(-4,91,-7,OBSIDIAN:0)
Block(-4,91,-6,OBSIDIAN:0)
Block(-4,91,-5,OBSIDIAN:0)
Block(-4,91,-4,OBSIDIAN:0)
Block(-4,91,-3,OBSIDIAN:0)
Block(-4,91,-2,OBSIDIAN:0)
Block(-4,91,-1,OBSIDIAN:0)
Block(-4,91,0,STONE:3)
Block(-4,91,1,STONE:3)
Block(-4,91,2,STONE:3)
Block(-4,91,3,STONE:3)
Block(-4,91,4,STONE:3)
Block(-4,91,5,STONE:3)
Block(-4,91,6,STONE:3)
Block(-4,91,7,STONE:3)
Block(-4,91,8,STONE:3)
Block(-4,92,-7,OBSIDIAN:0)
Block(-4,92,-6,OBSIDIAN:0)
Block(-4,92,-5,OBSIDIAN:0)
Block(-4,92,-4,OBSIDIAN:0)
Block(-4,92,-3,OBSIDIAN:0)
Block(-4,92,-2,OBSIDIAN:0)
Block(-4,92,-1,OBSIDIAN:0)
Block(-4,92,0,STONE:3)
Block(-4,92,1,STONE:3)
Block(-4,92,2,STONE:3)
Block(-4,92,3,STONE:3)
Block(-4,92,4,STONE:3)
Block(-4,92,5,STONE:5)
Block(-4,92,6,STONE:3)
Block(-4,92,7,STONE:3)
Block(-4,92,8,STONE:3)
Block(-4,93,-7,OBSIDIAN:0)
Block(-4,93,-6,OBSIDIAN:0)
Block(-4,93,-5,OBSIDIAN:0)
Block(-4,93,-4,OBSIDIAN:0)
Block(-4,93,-3,OBSIDIAN:0)
Block(-4,93,-2,OBSIDIAN:0)
Block(-4,93,-1,STONE:3)
Block(-4,93,0,STONE:3)
Block(-4,93,1,STONE:3)
Block(-4,93,2,STONE:3)
Block(-4,93,3,STONE:5)
Block(-4,93,4,STONE:5)
Block(-4,94,-7,STONE:3)
Block(-4,94,-6,OBSIDIAN:0)
Block(-4,94,-5,OBSIDIAN:0)
Block(-4,94,-4,OBSIDIAN:0)
Block(-4,94,-3,OBSIDIAN:0)
Block(-4,94,-2,OBSIDIAN:0)
Block(-4,94,-1,STONE:3)
Block(-4,94,0,STONE:3)
Block(-4,94,1,STONE:3)
Block(-4,94,2,STONE:5)
Block(-4,95,-7,STONE:3)
Block(-4,95,-6,STONE:3)
Block(-4,95,-5,OBSIDIAN:0)
Block(-4,95,-4,OBSIDIAN:0)
Block(-4,95,-3,OBSIDIAN:0)
Block(-4,95,-2,OBSIDIAN:0)
Block(-4,95,-1,STONE:3)
Block(-4,95,0,STONE:3)
Block(-4,95,1,STONE:3)
Block(-4,96,-7,STONE:3)
Block(-4,96,-6,STONE:3)
Block(-4,96,-5,OBSIDIAN:0)
Block(-4,96,-4,OBSIDIAN:0)
Block(-4,96,-3,OBSIDIAN:0)
Block(-4,96,-2,OBSIDIAN:0)
Block(-4,96,-1,OBSIDIAN:0)
Block(-4,96,0,STONE:3)
Block(-4,96,1,STONE:5)
Block(-4,97,-7,STONE:3)
Block(-4,97,-6,STONE:3)
Block(-4,97,-5,STONE:3)
Block(-4,97,-4,OBSIDIAN:0)
Block(-4,97,-3,OBSIDIAN:0)
Block(-4,97,-2,OBSIDIAN:0)
Block(-4,97,-1,OBSIDIAN:0)
Block(-4,97,0,STONE:3)
Block(-4,98,-7,STONE:3)
Block(-4,98,-6,STONE:3)
Block(-4,98,-5,STONE:3)
Block(-4,98,-4,OBSIDIAN:0)
Block(-4,98,-3,OBSIDIAN:0)
Block(-4,98,-2,OBSIDIAN:0)
Block(-4,98,-1,STONE:3)
Block(-4,98,0,STONE:5)
Block(-4,99,-7,STONE:3)
Block(-4,99,-6,STONE:3)
Block(-4,99,-5,STONE:3)
Block(-4,99,-4,STONE:3)
Block(-4,99,-3,STONE:3)
Block(-4,99,-2,STONE:3)
Block(-4,99,-1,STONE:5)
Block(-4,100,-7,STONE:3)
Block(-4,100,-6,STONE:5)
Block(-4,100,-5,STONE:5)
Block(-4,100,-4,STONE:5)
Block(-4,100,-3,STONE:5)
Block(-4,100,-2,STONE:5)
Block(-4,101,-7,STONE:5)
Block(-3,9,6,STONE:3)
Block(-3,9,7,STONE:3)
Block(-3,9,8,STONE:3)
Block(-3,10,-1,STONE:3)
Block(-3,10,0,STONE:3)
Block(-3,10,1,STONE:3)
Block(-3,10,2,STONE:3)
Block(-3,10,3,STONE:3)
Block(-3,10,4,STONE:3)
Block(-3,10,5,STONE:3)
Block(-3,10,6,STONE:3)
Block(-3,10,7,STONE:3)
Block(-3,10,8,STONE:3)
Block(-3,11,-6,STONE:3)
Block(-3,11,-5,STONE:3)
Block(-3,11,-4,STONE:3)
Block(-3,11,-3,STONE:3)
Block(-3,11,-2,STONE:3)
Block(-3,11,-1,STONE:3)
Block(-3,11,0,STONE:3)
Block(-3,11,1,STONE:3)
Block(-3,11,2,STONE:3)
Block(-3,11,3,STONE:3)
Block(-3,11,4,STONE:3)
Block(-3,11,5,STONE:3)
Block(-3,11,6,STONE:3)
Block(-3,11,7,STONE:3)
Block(-3,11,8,STONE:3)
Block(-3,12,-7,STONE:3)
Block(-3,12,-6,STONE:3)
Block(-3,12,-5,STONE:3)
Block(-3,12,-4,STONE:3)
Block(-3,12,-3,STONE:3)
Block(-3,12,-2,STONE:3)
Block(-3,12,-1,STONE:3)
Block(-3,12,0,STONE:3)
Block(-3,12,1,STONE:3)
Block(-3,12,2,STONE:3)
Block(-3,12,3,STONE:3)
Block(-3,12,4,STONE:3)
Block(-3,12,5,STONE:3)
Block(-3,12,6,STONE:3)
Block(-3,12,7,STONE:3)
Block(-3,12,8,STONE:3)
Block(-3,13,-7,STONE:3)
Block(-3,13,-6,STONE:3)
Block(-3,13,-5,STONE:3)
Block(-3,13,-4,STONE:3)
Block(-3,13,-3,STONE:3)
Block(-3,13,-2,STONE:3)
Block(-3,13,-1,STONE:3)
Block(-3,13,0,STONE:3)
Block(-3,13,1,STONE:3)
Block(-3,13,2,STONE:3)
Block(-3,13,3,STONE:3)
Block(-3,13,4,STONE:3)
Block(-3,13,5,STONE:3)
Block(-3,13,6,STONE:3)
Block(-3,13,7,STONE:3)
Block(-3,13,8,STONE:3)
Block(-3,14,-7,STONE:3)
Block(-3,14,-6,STONE:3)
Block(-3,14,-5,STONE:3)
Block(-3,14,-4,STONE:3)
Block(-3,14,-3,STONE:3)
Block(-3,14,-2,STONE:3)
Block(-3,14,-1,STONE:3)
Block(-3,14,0,STONE:3)
Block(-3,14,1,STONE:3)
Block(-3,14,2,OBSIDIAN:0)
Block(-3,14,3,STONE:3)
Block(-3,14,4,STONE:3)
Block(-3,14,5,STONE:3)
Block(-3,14,6,STONE:3)
Block(-3,14,7,STONE:3)
Block(-3,14,8,OBSIDIAN:0)
Block(-3,15,-7,STONE:3)
Block(-3,15,-6,STONE:3)
Block(-3,15,-5,STONE:3)
Block(-3,15,-4,STONE:3)
Block(-3,15,-3,STONE:3)
Block(-3,15,-2,STONE:3)
Block(-3,15,-1,STONE:3)
Block(-3,15,0,OBSIDIAN:0)
Block(-3,15,1,OBSIDIAN:0)
Block(-3,15,2,OBSIDIAN:0)
Block(-3,15,3,OBSIDIAN:0)
Block(-3,15,4,OBSIDIAN:0)
Block(-3,15,5,OBSIDIAN:0)
Block(-3,15,6,OBSIDIAN:0)
Block(-3,15,7,OBSIDIAN:0)
Block(-3,15,8,OBSIDIAN:0)
Block(-3,16,-7,STONE:3)
Block(-3,16,-6,STONE:3)
Block(-3,16,-5,STONE:3)
Block(-3,16,-4,STONE:3)
Block(-3,16,-3,STONE:3)
Block(-3,16,-2,OBSIDIAN:0)
Block(-3,16,-1,OBSIDIAN:0)
Block(-3,16,0,OBSIDIAN:0)
Block(-3,16,1,OBSIDIAN:0)
Block(-3,16,2,OBSIDIAN:0)
Block(-3,16,3,OBSIDIAN:0)
Block(-3,16,4,OBSIDIAN:0)
Block(-3,16,5,OBSIDIAN:0)
Block(-3,16,6,OBSIDIAN:0)
Block(-3,16,7,OBSIDIAN:0)
Block(-3,16,8,OBSIDIAN:0)
Block(-3,17,-7,STONE:3)
Block(-3,17,-6,OBSIDIAN:0)
Block(-3,17,-5,OBSIDIAN:0)
Block(-3,17,-4,OBSIDIAN:0)
Block(-3,17,-3,OBSIDIAN:0)
Block(-3,17,-2,OBSIDIAN:0)
Block(-3,17,-1,OBSIDIAN:0)
Block(-3,17,0,OBSIDIAN:0)
Block(-3,17,1,OBSIDIAN:0)
Block(-3,17,2,OBSIDIAN:0)
Block(-3,17,3,OBSIDIAN:0)
Block(-3,17,4,OBSIDIAN:0)
Block(-3,17,5,OBSIDIAN:0)
Block(-3,17,6,OBSIDIAN:0)
Block(-3,17,7,OBSIDIAN:0)
Block(-3,17,8,OBSIDIAN:0)
Block(-3,18,-7,OBSIDIAN:0)
Block(-3,18,-6,OBSIDIAN:0)
Block(-3,18,-5,OBSIDIAN:0)
Block(-3,18,-4,OBSIDIAN:0)
Block(-3,18,-3,OBSIDIAN:0)
Block(-3,18,-2,OBSIDIAN:0)
Block(-3,18,-1,OBSIDIAN:0)
Block(-3,18,0,OBSIDIAN:0)
Block(-3,18,1,OBSIDIAN:0)
Block(-3,18,2,OBSIDIAN:0)
Block(-3,18,3,OBSIDIAN:0)
Block(-3,18,4,OBSIDIAN:0)
Block(-3,18,5,OBSIDIAN:0)
Block(-3,18,6,OBSIDIAN:0)
Block(-3,18,7,OBSIDIAN:0)
Block(-3,18,8,OBSIDIAN:0)
Block(-3,19,-7,OBSIDIAN:0)
Block(-3,19,-6,OBSIDIAN:0)
Block(-3,19,-5,OBSIDIAN:0)
Block(-3,19,-4,OBSIDIAN:0)
Block(-3,19,-3,OBSIDIAN:0)
Block(-3,19,-2,OBSIDIAN:0)
Block(-3,19,-1,OBSIDIAN:0)
Block(-3,19,0,OBSIDIAN:0)
Block(-3,19,1,OBSIDIAN:0)
Block(-3,19,2,OBSIDIAN:0)
Block(-3,19,3,OBSIDIAN:0)
Block(-3,19,4,OBSIDIAN:0)
Block(-3,19,5,OBSIDIAN:0)
Block(-3,19,6,OBSIDIAN:0)
Block(-3,19,7,OBSIDIAN:0)
Block(-3,19,8,OBSIDIAN:0)
Block(-3,20,-7,OBSIDIAN:0)
Block(-3,20,-6,OBSIDIAN:0)
Block(-3,20,-5,OBSIDIAN:0)
Block(-3,20,-4,OBSIDIAN:0)
Block(-3,20,-3,OBSIDIAN:0)
Block(-3,20,-2,OBSIDIAN:0)
Block(-3,20,-1,OBSIDIAN:0)
Block(-3,20,0,OBSIDIAN:0)
Block(-3,20,1,OBSIDIAN:0)
Block(-3,20,2,OBSIDIAN:0)
Block(-3,20,3,OBSIDIAN:0)
Block(-3,20,4,OBSIDIAN:0)
Block(-3,20,5,OBSIDIAN:0)
Block(-3,20,6,OBSIDIAN:0)
Block(-3,20,7,OBSIDIAN:0)
Block(-3,20,8,OBSIDIAN:0)
Block(-3,21,-7,OBSIDIAN:0)
Block(-3,21,-6,OBSIDIAN:0)
Block(-3,21,-5,OBSIDIAN:0)
Block(-3,21,-4,OBSIDIAN:0)
Block(-3,21,-3,OBSIDIAN:0)
Block(-3,21,-2,OBSIDIAN:0)
Block(-3,21,-1,OBSIDIAN:0)
Block(-3,21,0,OBSIDIAN:0)
Block(-3,21,1,OBSIDIAN:0)
Block(-3,21,2,OBSIDIAN:0)
Block(-3,21,3,OBSIDIAN:0)
Block(-3,21,4,OBSIDIAN:0)
Block(-3,21,5,OBSIDIAN:0)
Block(-3,21,6,OBSIDIAN:0)
Block(-3,21,7,OBSIDIAN:0)
Block(-3,21,8,OBSIDIAN:0)
Block(-3,22,-7,OBSIDIAN:0)
Block(-3,22,-6,STONE:3)
Block(-3,22,-5,STONE:3)
Block(-3,22,-4,STONE:3)
Block(-3,22,-3,OBSIDIAN:0)
Block(-3,22,-2,OBSIDIAN:0)
Block(-3,22,-1,OBSIDIAN:0)
Block(-3,22,0,OBSIDIAN:0)
Block(-3,22,1,OBSIDIAN:0)
Block(-3,22,2,OBSIDIAN:0)
Block(-3,22,3,OBSIDIAN:0)
Block(-3,22,4,OBSIDIAN:0)
Block(-3,22,5,OBSIDIAN:0)
Block(-3,22,6,OBSIDIAN:0)
Block(-3,22,7,OBSIDIAN:0)
Block(-3,22,8,OBSIDIAN:0)
Block(-3,23,-7,STATIONARY_LAVA:0)
Block(-3,23,-6,STATIONARY_LAVA:0)
Block(-3,23,-5,STATIONARY_LAVA:0)
Block(-3,23,-4,STATIONARY_LAVA:0)
Block(-3,23,-3,STATIONARY_LAVA:0)
Block(-3,23,-2,STATIONARY_LAVA:0)
Block(-3,23,-1,OBSIDIAN:0)
Block(-3,23,0,OBSIDIAN:0)
Block(-3,23,1,OBSIDIAN:0)
Block(-3,23,2,OBSIDIAN:0)
Block(-3,23,3,OBSIDIAN:0)
Block(-3,23,4,OBSIDIAN:0)
Block(-3,23,5,OBSIDIAN:0)
Block(-3,23,6,OBSIDIAN:0)
Block(-3,23,7,OBSIDIAN:0)
Block(-3,23,8,OBSIDIAN:0)
Block(-3,24,0,OBSIDIAN:0)
Block(-3,24,1,OBSIDIAN:0)
Block(-3,24,2,OBSIDIAN:0)
Block(-3,24,3,OBSIDIAN:0)
Block(-3,24,4,STONE:5)
Block(-3,24,5,STONE:5)
Block(-3,24,6,STONE:5)
Block(-3,24,7,STONE:5)
Block(-3,24,8,STONE:5)
Block(-3,25,1,STONE:5)
Block(-3,25,2,STONE:5)
Block(-3,25,3,STONE:5)
Block(-3,25,4,STONE:5)
Block(-3,25,5,STONE:5)
Block(-3,25,6,STONE:5)
Block(-3,25,7,STONE:5)
Block(-3,25,8,STONE:5)
Block(-3,26,4,STONE:5)
Block(-3,26,5,GRASS:0)
Block(-3,26,6,GRASS:0)
Block(-3,26,7,GRASS:0)
Block(-3,26,8,STONE:5)
Block(-3,27,8,GRASS:0)
Block(-3,73,-6,OBSIDIAN:0)
Block(-3,73,-5,OBSIDIAN:0)
Block(-3,73,-4,OBSIDIAN:0)
Block(-3,73,-3,OBSIDIAN:0)
Block(-3,73,-2,OBSIDIAN:0)
Block(-3,73,-1,OBSIDIAN:0)
Block(-3,73,0,OBSIDIAN:0)
Block(-3,73,1,OBSIDIAN:0)
Block(-3,73,2,OBSIDIAN:0)
Block(-3,73,3,OBSIDIAN:0)
Block(-3,73,4,OBSIDIAN:0)
Block(-3,73,5,OBSIDIAN:0)
Block(-3,73,6,OBSIDIAN:0)
Block(-3,73,7,OBSIDIAN:0)
Block(-3,73,8,OBSIDIAN:0)
Block(-3,74,-7,OBSIDIAN:0)
Block(-3,74,-6,OBSIDIAN:0)
Block(-3,74,-5,OBSIDIAN:0)
Block(-3,74,-4,OBSIDIAN:0)
Block(-3,74,-3,OBSIDIAN:0)
Block(-3,74,-2,OBSIDIAN:0)
Block(-3,74,-1,OBSIDIAN:0)
Block(-3,74,0,OBSIDIAN:0)
Block(-3,74,1,OBSIDIAN:0)
Block(-3,74,2,OBSIDIAN:0)
Block(-3,74,3,OBSIDIAN:0)
Block(-3,74,4,OBSIDIAN:0)
Block(-3,74,5,OBSIDIAN:0)
Block(-3,74,6,OBSIDIAN:0)
Block(-3,74,7,OBSIDIAN:0)
Block(-3,74,8,OBSIDIAN:0)
Block(-3,75,-7,OBSIDIAN:0)
Block(-3,75,-6,OBSIDIAN:0)
Block(-3,75,-5,OBSIDIAN:0)
Block(-3,75,-4,OBSIDIAN:0)
Block(-3,75,-3,OBSIDIAN:0)
Block(-3,75,-2,OBSIDIAN:0)
Block(-3,75,-1,OBSIDIAN:0)
Block(-3,75,0,OBSIDIAN:0)
Block(-3,75,1,OBSIDIAN:0)
Block(-3,75,2,OBSIDIAN:0)
Block(-3,75,3,OBSIDIAN:0)
Block(-3,75,4,OBSIDIAN:0)
Block(-3,75,5,OBSIDIAN:0)
Block(-3,75,6,OBSIDIAN:0)
Block(-3,75,7,OBSIDIAN:0)
Block(-3,75,8,OBSIDIAN:0)
Block(-3,76,-7,OBSIDIAN:0)
Block(-3,76,-6,OBSIDIAN:0)
Block(-3,76,-5,OBSIDIAN:0)
Block(-3,76,-4,OBSIDIAN:0)
Block(-3,76,-3,OBSIDIAN:0)
Block(-3,76,-2,OBSIDIAN:0)
Block(-3,76,-1,OBSIDIAN:0)
Block(-3,76,0,OBSIDIAN:0)
Block(-3,76,1,OBSIDIAN:0)
Block(-3,76,2,OBSIDIAN:0)
Block(-3,76,3,OBSIDIAN:0)
Block(-3,76,4,OBSIDIAN:0)
Block(-3,76,5,OBSIDIAN:0)
Block(-3,76,6,OBSIDIAN:0)
Block(-3,76,7,OBSIDIAN:0)
Block(-3,76,8,OBSIDIAN:0)
Block(-3,77,-7,OBSIDIAN:0)
Block(-3,77,-6,OBSIDIAN:0)
Block(-3,77,-5,OBSIDIAN:0)
Block(-3,77,-4,OBSIDIAN:0)
Block(-3,77,-3,OBSIDIAN:0)
Block(-3,77,-2,OBSIDIAN:0)
Block(-3,77,-1,OBSIDIAN:0)
Block(-3,77,0,OBSIDIAN:0)
Block(-3,77,1,OBSIDIAN:0)
Block(-3,77,2,OBSIDIAN:0)
Block(-3,77,3,OBSIDIAN:0)
Block(-3,77,4,OBSIDIAN:0)
Block(-3,77,5,OBSIDIAN:0)
Block(-3,77,6,OBSIDIAN:0)
Block(-3,77,7,OBSIDIAN:0)
Block(-3,77,8,OBSIDIAN:0)
Block(-3,78,-7,OBSIDIAN:0)
Block(-3,78,-6,OBSIDIAN:0)
Block(-3,78,-5,OBSIDIAN:0)
Block(-3,78,-4,OBSIDIAN:0)
Block(-3,78,-3,OBSIDIAN:0)
Block(-3,78,-2,OBSIDIAN:0)
Block(-3,78,-1,OBSIDIAN:0)
Block(-3,78,0,OBSIDIAN:0)
Block(-3,78,1,OBSIDIAN:0)
Block(-3,78,2,OBSIDIAN:0)
Block(-3,78,3,OBSIDIAN:0)
Block(-3,78,4,OBSIDIAN:0)
Block(-3,78,5,OBSIDIAN:0)
Block(-3,78,6,OBSIDIAN:0)
Block(-3,78,7,OBSIDIAN:0)
Block(-3,78,8,OBSIDIAN:0)
Block(-3,79,-7,OBSIDIAN:0)
Block(-3,79,-6,OBSIDIAN:0)
Block(-3,79,-5,OBSIDIAN:0)
Block(-3,79,-4,OBSIDIAN:0)
Block(-3,79,-3,OBSIDIAN:0)
Block(-3,79,-2,OBSIDIAN:0)
Block(-3,79,-1,OBSIDIAN:0)
Block(-3,79,0,OBSIDIAN:0)
Block(-3,79,1,OBSIDIAN:0)
Block(-3,79,2,OBSIDIAN:0)
Block(-3,79,3,OBSIDIAN:0)
Block(-3,79,4,OBSIDIAN:0)
Block(-3,79,5,OBSIDIAN:0)
Block(-3,79,6,OBSIDIAN:0)
Block(-3,79,7,OBSIDIAN:0)
Block(-3,79,8,OBSIDIAN:0)
Block(-3,80,-7,OBSIDIAN:0)
Block(-3,80,-6,OBSIDIAN:0)
Block(-3,80,-5,OBSIDIAN:0)
Block(-3,80,-4,OBSIDIAN:0)
Block(-3,80,-3,OBSIDIAN:0)
Block(-3,80,-2,OBSIDIAN:0)
Block(-3,80,-1,OBSIDIAN:0)
Block(-3,80,0,OBSIDIAN:0)
Block(-3,80,1,OBSIDIAN:0)
Block(-3,80,2,OBSIDIAN:0)
Block(-3,80,3,OBSIDIAN:0)
Block(-3,80,4,OBSIDIAN:0)
Block(-3,80,5,OBSIDIAN:0)
Block(-3,80,6,OBSIDIAN:0)
Block(-3,80,7,OBSIDIAN:0)
Block(-3,80,8,OBSIDIAN:0)
Block(-3,81,-7,OBSIDIAN:0)
Block(-3,81,-6,OBSIDIAN:0)
Block(-3,81,-5,OBSIDIAN:0)
Block(-3,81,-4,OBSIDIAN:0)
Block(-3,81,-3,OBSIDIAN:0)
Block(-3,81,-2,OBSIDIAN:0)
Block(-3,81,-1,OBSIDIAN:0)
Block(-3,81,0,OBSIDIAN:0)
Block(-3,81,1,OBSIDIAN:0)
Block(-3,81,2,OBSIDIAN:0)
Block(-3,81,3,OBSIDIAN:0)
Block(-3,81,4,OBSIDIAN:0)
Block(-3,81,5,OBSIDIAN:0)
Block(-3,81,6,OBSIDIAN:0)
Block(-3,81,7,OBSIDIAN:0)
Block(-3,81,8,OBSIDIAN:0)
Block(-3,82,-7,OBSIDIAN:0)
Block(-3,82,-6,OBSIDIAN:0)
Block(-3,82,-5,OBSIDIAN:0)
Block(-3,82,-4,OBSIDIAN:0)
Block(-3,82,-3,OBSIDIAN:0)
Block(-3,82,-2,OBSIDIAN:0)
Block(-3,82,-1,OBSIDIAN:0)
Block(-3,82,0,OBSIDIAN:0)
Block(-3,82,1,OBSIDIAN:0)
Block(-3,82,2,OBSIDIAN:0)
Block(-3,82,3,OBSIDIAN:0)
Block(-3,82,4,OBSIDIAN:0)
Block(-3,82,5,OBSIDIAN:0)
Block(-3,82,6,OBSIDIAN:0)
Block(-3,82,7,OBSIDIAN:0)
Block(-3,82,8,OBSIDIAN:0)
Block(-3,83,-7,OBSIDIAN:0)
Block(-3,83,-6,OBSIDIAN:0)
Block(-3,83,-5,OBSIDIAN:0)
Block(-3,83,-4,OBSIDIAN:0)
Block(-3,83,-3,OBSIDIAN:0)
Block(-3,83,-2,OBSIDIAN:0)
Block(-3,83,-1,OBSIDIAN:0)
Block(-3,83,0,OBSIDIAN:0)
Block(-3,83,1,OBSIDIAN:0)
Block(-3,83,2,OBSIDIAN:0)
Block(-3,83,3,OBSIDIAN:0)
Block(-3,83,4,OBSIDIAN:0)
Block(-3,83,5,OBSIDIAN:0)
Block(-3,83,6,OBSIDIAN:0)
Block(-3,83,7,OBSIDIAN:0)
Block(-3,83,8,OBSIDIAN:0)
Block(-3,84,-7,OBSIDIAN:0)
Block(-3,84,-6,OBSIDIAN:0)
Block(-3,84,-5,OBSIDIAN:0)
Block(-3,84,-4,OBSIDIAN:0)
Block(-3,84,-3,OBSIDIAN:0)
Block(-3,84,-2,OBSIDIAN:0)
Block(-3,84,-1,OBSIDIAN:0)
Block(-3,84,0,OBSIDIAN:0)
Block(-3,84,1,OBSIDIAN:0)
Block(-3,84,2,OBSIDIAN:0)
Block(-3,84,3,OBSIDIAN:0)
Block(-3,84,4,OBSIDIAN:0)
Block(-3,84,5,OBSIDIAN:0)
Block(-3,84,6,OBSIDIAN:0)
Block(-3,84,7,OBSIDIAN:0)
Block(-3,84,8,OBSIDIAN:0)
Block(-3,85,-7,OBSIDIAN:0)
Block(-3,85,-6,OBSIDIAN:0)
Block(-3,85,-5,OBSIDIAN:0)
Block(-3,85,-4,OBSIDIAN:0)
Block(-3,85,-3,OBSIDIAN:0)
Block(-3,85,-2,OBSIDIAN:0)
Block(-3,85,-1,OBSIDIAN:0)
Block(-3,85,0,OBSIDIAN:0)
Block(-3,85,1,OBSIDIAN:0)
Block(-3,85,2,OBSIDIAN:0)
Block(-3,85,3,OBSIDIAN:0)
Block(-3,85,4,OBSIDIAN:0)
Block(-3,85,5,OBSIDIAN:0)
Block(-3,85,6,OBSIDIAN:0)
Block(-3,85,7,OBSIDIAN:0)
Block(-3,85,8,OBSIDIAN:0)
Block(-3,86,-7,OBSIDIAN:0)
Block(-3,86,-6,OBSIDIAN:0)
Block(-3,86,-5,OBSIDIAN:0)
Block(-3,86,-4,OBSIDIAN:0)
Block(-3,86,-3,OBSIDIAN:0)
Block(-3,86,-2,OBSIDIAN:0)
Block(-3,86,-1,OBSIDIAN:0)
Block(-3,86,0,OBSIDIAN:0)
Block(-3,86,1,OBSIDIAN:0)
Block(-3,86,2,OBSIDIAN:0)
Block(-3,86,3,OBSIDIAN:0)
Block(-3,86,4,OBSIDIAN:0)
Block(-3,86,5,OBSIDIAN:0)
Block(-3,86,6,OBSIDIAN:0)
Block(-3,86,7,OBSIDIAN:0)
Block(-3,86,8,OBSIDIAN:0)
Block(-3,87,-7,OBSIDIAN:0)
Block(-3,87,-6,OBSIDIAN:0)
Block(-3,87,-5,OBSIDIAN:0)
Block(-3,87,-4,OBSIDIAN:0)
Block(-3,87,-3,OBSIDIAN:0)
Block(-3,87,-2,OBSIDIAN:0)
Block(-3,87,-1,OBSIDIAN:0)
Block(-3,87,0,OBSIDIAN:0)
Block(-3,87,1,OBSIDIAN:0)
Block(-3,87,2,OBSIDIAN:0)
Block(-3,87,3,OBSIDIAN:0)
Block(-3,87,4,OBSIDIAN:0)
Block(-3,87,5,OBSIDIAN:0)
Block(-3,87,6,STONE:3)
Block(-3,87,7,STONE:3)
Block(-3,87,8,STONE:3)
Block(-3,88,-7,OBSIDIAN:0)
Block(-3,88,-6,OBSIDIAN:0)
Block(-3,88,-5,OBSIDIAN:0)
Block(-3,88,-4,OBSIDIAN:0)
Block(-3,88,-3,OBSIDIAN:0)
Block(-3,88,-2,OBSIDIAN:0)
Block(-3,88,-1,OBSIDIAN:0)
Block(-3,88,0,OBSIDIAN:0)
Block(-3,88,1,OBSIDIAN:0)
Block(-3,88,2,OBSIDIAN:0)
Block(-3,88,3,OBSIDIAN:0)
Block(-3,88,4,OBSIDIAN:0)
Block(-3,88,5,STONE:3)
Block(-3,88,6,STONE:3)
Block(-3,88,7,STONE:3)
Block(-3,88,8,STONE:3)
Block(-3,89,-7,OBSIDIAN:0)
Block(-3,89,-6,OBSIDIAN:0)
Block(-3,89,-5,OBSIDIAN:0)
Block(-3,89,-4,OBSIDIAN:0)
Block(-3,89,-3,OBSIDIAN:0)
Block(-3,89,-2,OBSIDIAN:0)
Block(-3,89,-1,OBSIDIAN:0)
Block(-3,89,0,OBSIDIAN:0)
Block(-3,89,1,OBSIDIAN:0)
Block(-3,89,2,STONE:3)
Block(-3,89,3,STONE:3)
Block(-3,89,4,STONE:3)
Block(-3,89,5,STONE:3)
Block(-3,89,6,STONE:3)
Block(-3,89,7,STONE:3)
Block(-3,89,8,STONE:3)
Block(-3,90,-7,OBSIDIAN:0)
Block(-3,90,-6,OBSIDIAN:0)
Block(-3,90,-5,OBSIDIAN:0)
Block(-3,90,-4,OBSIDIAN:0)
Block(-3,90,-3,OBSIDIAN:0)
Block(-3,90,-2,OBSIDIAN:0)
Block(-3,90,-1,OBSIDIAN:0)
Block(-3,90,0,OBSIDIAN:0)
Block(-3,90,1,STONE:3)
Block(-3,90,2,STONE:3)
Block(-3,90,3,STONE:3)
Block(-3,90,4,STONE:3)
Block(-3,90,5,STONE:3)
Block(-3,90,6,STONE:3)
Block(-3,90,7,STONE:3)
Block(-3,90,8,STONE:3)
Block(-3,91,-7,OBSIDIAN:0)
Block(-3,91,-6,OBSIDIAN:0)
Block(-3,91,-5,OBSIDIAN:0)
Block(-3,91,-4,OBSIDIAN:0)
Block(-3,91,-3,OBSIDIAN:0)
Block(-3,91,-2,OBSIDIAN:0)
Block(-3,91,-1,OBSIDIAN:0)
Block(-3,91,0,STONE:3)
Block(-3,91,1,STONE:3)
Block(-3,91,2,STONE:3)
Block(-3,91,3,STONE:3)
Block(-3,91,4,STONE:3)
Block(-3,91,5,STONE:3)
Block(-3,91,6,STONE:3)
Block(-3,91,7,STONE:3)
Block(-3,91,8,STONE:3)
Block(-3,92,-7,OBSIDIAN:0)
Block(-3,92,-6,OBSIDIAN:0)
Block(-3,92,-5,OBSIDIAN:0)
Block(-3,92,-4,OBSIDIAN:0)
Block(-3,92,-3,OBSIDIAN:0)
Block(-3,92,-2,OBSIDIAN:0)
Block(-3,92,-1,STONE:3)
Block(-3,92,0,STONE:3)
Block(-3,92,1,STONE:3)
Block(-3,92,2,STONE:3)
Block(-3,92,3,STONE:3)
Block(-3,92,4,STONE:3)
Block(-3,92,5,STONE:5)
Block(-3,92,6,STONE:5)
Block(-3,92,7,STONE:3)
Block(-3,92,8,STONE:3)
Block(-3,93,-7,OBSIDIAN:0)
Block(-3,93,-6,OBSIDIAN:0)
Block(-3,93,-5,OBSIDIAN:0)
Block(-3,93,-4,OBSIDIAN:0)
Block(-3,93,-3,OBSIDIAN:0)
Block(-3,93,-2,OBSIDIAN:0)
Block(-3,93,-1,STONE:3)
Block(-3,93,0,STONE:3)
Block(-3,93,1,STONE:3)
Block(-3,93,2,STONE:3)
Block(-3,93,3,STONE:3)
Block(-3,93,4,STONE:5)
Block(-3,94,-7,STONE:3)
Block(-3,94,-6,OBSIDIAN:0)
Block(-3,94,-5,OBSIDIAN:0)
Block(-3,94,-4,OBSIDIAN:0)
Block(-3,94,-3,OBSIDIAN:0)
Block(-3,94,-2,OBSIDIAN:0)
Block(-3,94,-1,STONE:3)
Block(-3,94,0,STONE:3)
Block(-3,94,1,STONE:3)
Block(-3,94,2,STONE:3)
Block(-3,94,3,STONE:5)
Block(-3,95,-7,STONE:3)
Block(-3,95,-6,STONE:3)
Block(-3,95,-5,OBSIDIAN:0)
Block(-3,95,-4,OBSIDIAN:0)
Block(-3,95,-3,OBSIDIAN:0)
Block(-3,95,-2,OBSIDIAN:0)
Block(-3,95,-1,STONE:3)
Block(-3,95,0,STONE:3)
Block(-3,95,1,STONE:3)
Block(-3,95,2,STONE:5)
Block(-3,96,-7,STONE:3)
Block(-3,96,-6,STONE:3)
Block(-3,96,-5,STONE:3)
Block(-3,96,-4,OBSIDIAN:0)
Block(-3,96,-3,OBSIDIAN:0)
Block(-3,96,-2,OBSIDIAN:0)
Block(-3,96,-1,STONE:3)
Block(-3,96,0,STONE:3)
Block(-3,96,1,STONE:5)
Block(-3,97,-7,STONE:3)
Block(-3,97,-6,STONE:3)
Block(-3,97,-5,STONE:3)
Block(-3,97,-4,OBSIDIAN:0)
Block(-3,97,-3,OBSIDIAN:0)
Block(-3,97,-2,OBSIDIAN:0)
Block(-3,97,-1,OBSIDIAN:0)
Block(-3,97,0,STONE:3)
Block(-3,98,-7,STONE:3)
Block(-3,98,-6,STONE:3)
Block(-3,98,-5,STONE:3)
Block(-3,98,-4,OBSIDIAN:0)
Block(-3,98,-3,OBSIDIAN:0)
Block(-3,98,-2,OBSIDIAN:0)
Block(-3,98,-1,STONE:3)
Block(-3,98,0,STONE:5)
Block(-3,99,-7,STONE:3)
Block(-3,99,-6,STONE:3)
Block(-3,99,-5,STONE:3)
Block(-3,99,-4,STONE:3)
Block(-3,99,-3,OBSIDIAN:0)
Block(-3,99,-2,STONE:3)
Block(-3,99,-1,STONE:5)
Block(-3,100,-7,STONE:5)
Block(-3,100,-6,STONE:5)
Block(-3,100,-5,STONE:5)
Block(-3,100,-4,STONE:5)
Block(-3,100,-3,STONE:3)
Block(-3,100,-2,STONE:5)
Block(-3,101,-3,STONE:5)
Block(-2,9,7,STONE:3)
Block(-2,9,8,STONE:3)
Block(-2,10,0,STONE:3)
Block(-2,10,1,STONE:3)
Block(-2,10,2,STONE:3)
Block(-2,10,3,STONE:3)
Block(-2,10,4,STONE:3)
Block(-2,10,5,STONE:3)
Block(-2,10,6,STONE:3)
Block(-2,10,7,STONE:3)
Block(-2,10,8,STONE:3)
Block(-2,11,-7,STONE:3)
Block(-2,11,-6,STONE:3)
Block(-2,11,-5,STONE:3)
Block(-2,11,-4,STONE:3)
Block(-2,11,-3,STONE:3)
Block(-2,11,-2,STONE:3)
Block(-2,11,-1,STONE:3)
Block(-2,11,0,STONE:3)
Block(-2,11,1,STONE:3)
Block(-2,11,2,STONE:3)
Block(-2,11,3,STONE:3)
Block(-2,11,4,STONE:3)
Block(-2,11,5,STONE:3)
Block(-2,11,6,STONE:3)
Block(-2,11,7,STONE:3)
Block(-2,11,8,STONE:3)
Block(-2,12,-7,STONE:3)
Block(-2,12,-6,STONE:3)
Block(-2,12,-5,STONE:3)
Block(-2,12,-4,STONE:3)
Block(-2,12,-3,STONE:3)
Block(-2,12,-2,STONE:3)
Block(-2,12,-1,STONE:3)
Block(-2,12,0,STONE:3)
Block(-2,12,1,STONE:3)
Block(-2,12,2,STONE:3)
