
#######################################################################
# +-----------------------------------------------------------------+ #
# |                            BO4 object                           | #
# +-----------------------------------------------------------------+ #
#######################################################################

Author: NLBlackEagle

Description: No description given

SettingsMode: WriteWithoutComments


#######################################################################
# +-----------------------------------------------------------------+ #
# |                          Main settings                          | #
# +-----------------------------------------------------------------+ #
#######################################################################

Frequency: 0

SpawnHeight: highestBlock

UseCenterForHighestBlock: true

##############################
# Height Limits for the BO4. #
##############################

MinHeight: 0

MaxHeight: 255

InheritBO3: 

InheritBO3Rotation: NORTH

OverrideChildSettings: true

OverrideParentHeight: false

CanOverride: false

BranchFrequency: 0

BranchFrequencyGroup: 

MustBeBelowOther: false

MustBeInside: 

CannotBeInside: 

ReplacesBO3: 

MustBeInsideWorldBorders: false

CanSpawnOnWater: true

SpawnOnWaterOnly: false

SpawnUnderWater: false

SpawnAtWaterLevel: false

HeightOffset: 0

RemoveAir: true

ReplaceAbove: 

ReplaceBelow: 

ReplaceWithBiomeBlocks: true

ReplaceWithSurfaceBlock: GRASS

ReplaceWithGroundBlock: DIRT

ReplaceWithStoneBlock: STONE

SmoothRadius: 0

SmoothHeightOffset: 0

SmoothStartTop: false

SmoothStartWood: false

SmoothingSurfaceBlock: 

SmoothingGroundBlock: 

BO3Group: 

IsSpawnPoint: false

DoReplaceBlocks: true


#######################################################################
# +-----------------------------------------------------------------+ #
# |                              Blocks                             | #
# +-----------------------------------------------------------------+ #
#######################################################################

Block(-8,23,-7,STONE:3)
Block(-8,24,-7,STONE:3)
Block(-8,24,-6,STONE:3)
Block(-8,24,-5,STONE:3)
Block(-8,25,-7,STONE:3)
Block(-8,25,-6,STONE:3)
Block(-8,25,-5,STONE:3)
Block(-8,25,-4,STONE:3)
Block(-8,25,-3,STONE:3)
Block(-8,25,-2,STONE:3)
Block(-8,25,-1,STONE:3)
Block(-8,26,-7,STONE:3)
Block(-8,26,-6,STONE:3)
Block(-8,26,-5,STONE:3)
Block(-8,26,-4,STONE:3)
Block(-8,26,-3,STONE:3)
Block(-8,26,-2,STONE:3)
Block(-8,26,-1,STONE:3)
Block(-8,26,0,STONE:3)
Block(-8,27,-7,STONE:3)
Block(-8,27,-6,STONE:3)
Block(-8,27,-5,STONE:3)
Block(-8,27,-4,STONE:3)
Block(-8,27,-3,STONE:3)
Block(-8,27,-2,STONE:3)
Block(-8,27,-1,STONE:3)
Block(-8,27,0,STONE:3)
Block(-8,27,1,STONE:3)
Block(-8,27,2,STONE:3)
Block(-8,28,-7,STONE:3)
Block(-8,28,-6,STONE:3)
Block(-8,28,-5,STONE:3)
Block(-8,28,-4,STONE:3)
Block(-8,28,-3,STONE:3)
Block(-8,28,-2,STONE:3)
Block(-8,28,-1,STONE:3)
Block(-8,28,0,STONE:3)
Block(-8,28,1,STONE:3)
Block(-8,28,2,STONE:3)
Block(-8,28,3,STONE:3)
Block(-8,28,4,STONE:3)
Block(-8,28,5,STONE:3)
Block(-8,29,-7,OBSIDIAN:0)
Block(-8,29,-6,OBSIDIAN:0)
Block(-8,29,-5,OBSIDIAN:0)
Block(-8,29,-4,STONE:3)
Block(-8,29,-3,OBSIDIAN:0)
Block(-8,29,-2,OBSIDIAN:0)
Block(-8,29,-1,STONE:3)
Block(-8,29,0,STONE:3)
Block(-8,29,1,STONE:3)
Block(-8,29,2,OBSIDIAN:0)
Block(-8,29,3,OBSIDIAN:0)
Block(-8,29,4,STONE:3)
Block(-8,29,5,STONE:3)
Block(-8,29,6,STONE:3)
Block(-8,29,7,STONE:3)
Block(-8,29,8,STONE:3)
Block(-8,30,-7,STONE:5)
Block(-8,30,-6,OBSIDIAN:0)
Block(-8,30,-5,OBSIDIAN:0)
Block(-8,30,-4,OBSIDIAN:0)
Block(-8,30,-3,OBSIDIAN:0)
Block(-8,30,-2,STONE:3)
Block(-8,30,-1,STONE:3)
Block(-8,30,0,STONE:3)
Block(-8,30,1,STONE:3)
Block(-8,30,2,STONE:3)
Block(-8,30,3,STONE:3)
Block(-8,30,4,OBSIDIAN:0)
Block(-8,30,5,STONE:3)
Block(-8,30,6,STONE:3)
Block(-8,30,7,STONE:3)
Block(-8,30,8,STONE:3)
Block(-8,31,-7,STONE:5)
Block(-8,31,-6,STONE:5)
Block(-8,31,-5,OBSIDIAN:0)
Block(-8,31,-4,OBSIDIAN:0)
Block(-8,31,-3,OBSIDIAN:0)
Block(-8,31,-2,GRASS:0)
Block(-8,31,-1,STONE:3)
Block(-8,31,0,STONE:3)
Block(-8,31,1,STONE:3)
Block(-8,31,2,STONE:3)
Block(-8,31,3,STONE:3)
Block(-8,31,4,OBSIDIAN:0)
Block(-8,31,5,OBSIDIAN:0)
Block(-8,31,6,STONE:3)
Block(-8,31,7,STONE:3)
Block(-8,31,8,STONE:3)
Block(-8,32,-7,STONE:5)
Block(-8,32,-6,STONE:3)
Block(-8,32,-5,STONE:3)
Block(-8,32,-4,STONE:3)
Block(-8,32,-3,GRASS:0)
Block(-8,32,-2,STATIONARY_WATER:0)
Block(-8,32,-1,GRASS:0)
Block(-8,32,0,STONE:3)
Block(-8,32,1,STONE:3)
Block(-8,32,2,STONE:3)
Block(-8,32,3,STONE:3)
Block(-8,32,4,OBSIDIAN:0)
Block(-8,32,5,OBSIDIAN:0)
Block(-8,32,6,OBSIDIAN:0)
Block(-8,32,7,STONE:3)
Block(-8,32,8,STONE:3)
Block(-8,33,-7,STONE:3)
Block(-8,33,-6,STONE:3)
Block(-8,33,-5,STONE:3)
Block(-8,33,-4,GRASS:0)
Block(-8,33,-3,STATIONARY_WATER:0)
Block(-8,33,-2,STATIONARY_WATER:0)
Block(-8,33,-1,STATIONARY_WATER:0)
Block(-8,33,0,STATIONARY_WATER:0)
Block(-8,33,1,STATIONARY_WATER:0)
Block(-8,33,2,STATIONARY_WATER:0)
Block(-8,33,3,STATIONARY_WATER:0)
Block(-8,33,4,STONE:5)
Block(-8,33,5,STONE:5)
Block(-8,33,6,STONE:5)
Block(-8,33,7,OBSIDIAN:0)
Block(-8,33,8,STONE:3)
Block(-8,34,-7,STONE:3)
Block(-8,34,-6,STONE:3)
Block(-8,34,-5,GRASS:0)
Block(-8,34,5,STONE:5)
Block(-8,34,6,STONE:5)
Block(-8,34,7,STONE:5)
Block(-8,34,8,OBSIDIAN:0)
Block(-8,35,-7,STONE:3)
Block(-8,35,-6,STONE:3)
Block(-8,35,5,STONE:5)
Block(-8,35,7,STONE:5)
Block(-8,35,8,OBSIDIAN:0)
Block(-8,36,6,STONE:5)
Block(-8,36,7,STONE:5)
Block(-8,36,8,OBSIDIAN:0)
Block(-8,37,7,OBSIDIAN:0)
Block(-8,37,8,OBSIDIAN:0)
Block(-8,38,8,OBSIDIAN:0)
Block(-8,66,8,OBSIDIAN:0)
Block(-8,67,7,OBSIDIAN:0)
Block(-8,67,8,OBSIDIAN:0)
Block(-8,68,4,OBSIDIAN:0)
Block(-8,68,5,OBSIDIAN:0)
Block(-8,68,6,OBSIDIAN:0)
Block(-8,68,7,OBSIDIAN:0)
Block(-8,68,8,OBSIDIAN:0)
Block(-8,69,3,OBSIDIAN:0)
Block(-8,69,4,OBSIDIAN:0)
Block(-8,69,5,OBSIDIAN:0)
Block(-8,69,6,OBSIDIAN:0)
Block(-8,69,7,OBSIDIAN:0)
Block(-8,69,8,OBSIDIAN:0)
Block(-8,70,2,OBSIDIAN:0)
Block(-8,70,3,OBSIDIAN:0)
Block(-8,70,4,OBSIDIAN:0)
Block(-8,70,5,OBSIDIAN:0)
Block(-8,70,6,OBSIDIAN:0)
Block(-8,70,7,OBSIDIAN:0)
Block(-8,70,8,OBSIDIAN:0)
Block(-8,71,1,OBSIDIAN:0)
Block(-8,71,2,OBSIDIAN:0)
Block(-8,71,3,OBSIDIAN:0)
Block(-8,71,4,OBSIDIAN:0)
Block(-8,71,5,OBSIDIAN:0)
Block(-8,71,6,OBSIDIAN:0)
Block(-8,71,7,OBSIDIAN:0)
Block(-8,71,8,OBSIDIAN:0)
Block(-8,72,1,OBSIDIAN:0)
Block(-8,72,2,OBSIDIAN:0)
Block(-8,72,3,OBSIDIAN:0)
Block(-8,72,4,OBSIDIAN:0)
Block(-8,72,5,OBSIDIAN:0)
Block(-8,72,6,OBSIDIAN:0)
Block(-8,72,7,OBSIDIAN:0)
Block(-8,72,8,OBSIDIAN:0)
Block(-8,73,0,OBSIDIAN:0)
Block(-8,73,1,OBSIDIAN:0)
Block(-8,73,2,OBSIDIAN:0)
Block(-8,73,3,OBSIDIAN:0)
Block(-8,73,4,OBSIDIAN:0)
Block(-8,73,5,OBSIDIAN:0)
Block(-8,73,6,OBSIDIAN:0)
Block(-8,73,7,OBSIDIAN:0)
Block(-8,73,8,OBSIDIAN:0)
Block(-8,74,0,OBSIDIAN:0)
Block(-8,74,1,OBSIDIAN:0)
Block(-8,74,2,OBSIDIAN:0)
Block(-8,74,3,OBSIDIAN:0)
Block(-8,74,4,OBSIDIAN:0)
Block(-8,74,5,OBSIDIAN:0)
Block(-8,74,6,OBSIDIAN:0)
Block(-8,74,7,OBSIDIAN:0)
Block(-8,74,8,OBSIDIAN:0)
Block(-8,75,0,OBSIDIAN:0)
Block(-8,75,1,OBSIDIAN:0)
Block(-8,75,2,OBSIDIAN:0)
Block(-8,75,3,OBSIDIAN:0)
Block(-8,75,4,OBSIDIAN:0)
Block(-8,75,5,OBSIDIAN:0)
Block(-8,75,6,OBSIDIAN:0)
Block(-8,75,7,OBSIDIAN:0)
Block(-8,75,8,OBSIDIAN:0)
Block(-8,76,1,OBSIDIAN:0)
Block(-8,76,2,OBSIDIAN:0)
Block(-8,76,3,OBSIDIAN:0)
Block(-8,76,4,OBSIDIAN:0)
Block(-8,76,5,OBSIDIAN:0)
Block(-8,76,6,OBSIDIAN:0)
Block(-8,76,7,OBSIDIAN:0)
Block(-8,76,8,OBSIDIAN:0)
Block(-8,77,0,OBSIDIAN:0)
Block(-8,77,1,OBSIDIAN:0)
Block(-8,77,2,OBSIDIAN:0)
Block(-8,77,3,OBSIDIAN:0)
Block(-8,77,4,OBSIDIAN:0)
Block(-8,77,5,OBSIDIAN:0)
Block(-8,77,6,OBSIDIAN:0)
Block(-8,77,7,OBSIDIAN:0)
Block(-8,77,8,OBSIDIAN:0)
Block(-8,78,0,OBSIDIAN:0)
Block(-8,78,1,OBSIDIAN:0)
Block(-8,78,2,OBSIDIAN:0)
Block(-8,78,3,OBSIDIAN:0)
Block(-8,78,4,OBSIDIAN:0)
Block(-8,78,5,OBSIDIAN:0)
Block(-8,78,6,OBSIDIAN:0)
Block(-8,78,7,OBSIDIAN:0)
Block(-8,78,8,OBSIDIAN:0)
Block(-8,79,-1,OBSIDIAN:0)
Block(-8,79,0,OBSIDIAN:0)
Block(-8,79,1,OBSIDIAN:0)
Block(-8,79,2,OBSIDIAN:0)
Block(-8,79,3,OBSIDIAN:0)
Block(-8,79,4,OBSIDIAN:0)
Block(-8,79,5,OBSIDIAN:0)
Block(-8,79,6,OBSIDIAN:0)
Block(-8,79,7,OBSIDIAN:0)
Block(-8,79,8,OBSIDIAN:0)
Block(-8,80,-2,OBSIDIAN:0)
Block(-8,80,-1,OBSIDIAN:0)
Block(-8,80,0,OBSIDIAN:0)
Block(-8,80,1,OBSIDIAN:0)
Block(-8,80,2,OBSIDIAN:0)
Block(-8,80,3,OBSIDIAN:0)
Block(-8,80,4,OBSIDIAN:0)
Block(-8,80,5,OBSIDIAN:0)
Block(-8,80,6,OBSIDIAN:0)
Block(-8,80,7,OBSIDIAN:0)
Block(-8,80,8,OBSIDIAN:0)
Block(-8,81,-7,OBSIDIAN:0)
Block(-8,81,-6,OBSIDIAN:0)
Block(-8,81,-5,OBSIDIAN:0)
Block(-8,81,-4,OBSIDIAN:0)
Block(-8,81,-3,OBSIDIAN:0)
Block(-8,81,-2,OBSIDIAN:0)
Block(-8,81,-1,OBSIDIAN:0)
Block(-8,81,0,OBSIDIAN:0)
Block(-8,81,1,OBSIDIAN:0)
Block(-8,81,2,OBSIDIAN:0)
Block(-8,81,3,OBSIDIAN:0)
Block(-8,81,4,OBSIDIAN:0)
Block(-8,81,5,OBSIDIAN:0)
Block(-8,81,6,OBSIDIAN:0)
Block(-8,81,7,OBSIDIAN:0)
Block(-8,81,8,OBSIDIAN:0)
Block(-8,82,-7,OBSIDIAN:0)
Block(-8,82,-6,OBSIDIAN:0)
Block(-8,82,-5,OBSIDIAN:0)
Block(-8,82,-4,OBSIDIAN:0)
Block(-8,82,-3,OBSIDIAN:0)
Block(-8,82,-2,OBSIDIAN:0)
Block(-8,82,-1,OBSIDIAN:0)
Block(-8,82,0,OBSIDIAN:0)
Block(-8,82,1,OBSIDIAN:0)
Block(-8,82,2,OBSIDIAN:0)
Block(-8,82,3,OBSIDIAN:0)
Block(-8,82,4,OBSIDIAN:0)
Block(-8,82,5,OBSIDIAN:0)
Block(-8,82,6,OBSIDIAN:0)
Block(-8,82,7,OBSIDIAN:0)
Block(-8,82,8,OBSIDIAN:0)
Block(-8,83,-7,OBSIDIAN:0)
Block(-8,83,-6,OBSIDIAN:0)
Block(-8,83,-5,OBSIDIAN:0)
Block(-8,83,-4,OBSIDIAN:0)
Block(-8,83,-3,OBSIDIAN:0)
Block(-8,83,-2,OBSIDIAN:0)
Block(-8,83,-1,OBSIDIAN:0)
Block(-8,83,0,OBSIDIAN:0)
Block(-8,83,1,OBSIDIAN:0)
Block(-8,83,2,OBSIDIAN:0)
Block(-8,83,3,OBSIDIAN:0)
Block(-8,83,4,OBSIDIAN:0)
Block(-8,83,5,OBSIDIAN:0)
Block(-8,83,6,OBSIDIAN:0)
Block(-8,83,7,OBSIDIAN:0)
Block(-8,83,8,OBSIDIAN:0)
Block(-8,84,-7,OBSIDIAN:0)
Block(-8,84,-6,OBSIDIAN:0)
Block(-8,84,-5,OBSIDIAN:0)
Block(-8,84,-4,OBSIDIAN:0)
Block(-8,84,-3,OBSIDIAN:0)
Block(-8,84,-2,OBSIDIAN:0)
Block(-8,84,-1,OBSIDIAN:0)
Block(-8,84,0,OBSIDIAN:0)
Block(-8,84,1,OBSIDIAN:0)
Block(-8,84,2,OBSIDIAN:0)
Block(-8,84,3,OBSIDIAN:0)
Block(-8,84,4,OBSIDIAN:0)
Block(-8,84,5,OBSIDIAN:0)
Block(-8,84,6,OBSIDIAN:0)
Block(-8,84,7,OBSIDIAN:0)
Block(-8,84,8,OBSIDIAN:0)
Block(-8,85,-7,OBSIDIAN:0)
Block(-8,85,-6,OBSIDIAN:0)
Block(-8,85,-5,OBSIDIAN:0)
Block(-8,85,-4,OBSIDIAN:0)
Block(-8,85,-3,OBSIDIAN:0)
Block(-8,85,-2,OBSIDIAN:0)
Block(-8,85,-1,OBSIDIAN:0)
Block(-8,85,0,OBSIDIAN:0)
Block(-8,85,1,OBSIDIAN:0)
Block(-8,85,2,OBSIDIAN:0)
Block(-8,85,3,OBSIDIAN:0)
Block(-8,85,4,OBSIDIAN:0)
Block(-8,85,5,OBSIDIAN:0)
Block(-8,85,6,OBSIDIAN:0)
Block(-8,85,7,OBSIDIAN:0)
Block(-8,85,8,OBSIDIAN:0)
Block(-8,86,-7,OBSIDIAN:0)
Block(-8,86,-6,OBSIDIAN:0)
Block(-8,86,-5,OBSIDIAN:0)
Block(-8,86,-4,OBSIDIAN:0)
Block(-8,86,-3,OBSIDIAN:0)
Block(-8,86,-2,OBSIDIAN:0)
Block(-8,86,-1,OBSIDIAN:0)
Block(-8,86,0,OBSIDIAN:0)
Block(-8,86,1,OBSIDIAN:0)
Block(-8,86,2,OBSIDIAN:0)
Block(-8,86,3,OBSIDIAN:0)
Block(-8,86,4,OBSIDIAN:0)
Block(-8,86,5,OBSIDIAN:0)
Block(-8,86,6,OBSIDIAN:0)
Block(-8,86,7,OBSIDIAN:0)
Block(-8,86,8,OBSIDIAN:0)
Block(-8,87,-7,OBSIDIAN:0)
Block(-8,87,-6,OBSIDIAN:0)
Block(-8,87,-5,OBSIDIAN:0)
Block(-8,87,-4,OBSIDIAN:0)
Block(-8,87,-3,OBSIDIAN:0)
Block(-8,87,-2,OBSIDIAN:0)
Block(-8,87,-1,OBSIDIAN:0)
Block(-8,87,0,OBSIDIAN:0)
Block(-8,87,1,OBSIDIAN:0)
Block(-8,87,2,OBSIDIAN:0)
Block(-8,87,3,OBSIDIAN:0)
Block(-8,87,4,OBSIDIAN:0)
Block(-8,87,5,OBSIDIAN:0)
Block(-8,87,6,OBSIDIAN:0)
Block(-8,87,7,OBSIDIAN:0)
Block(-8,87,8,OBSIDIAN:0)
Block(-8,88,-7,OBSIDIAN:0)
Block(-8,88,-6,OBSIDIAN:0)
Block(-8,88,-5,OBSIDIAN:0)
Block(-8,88,-4,OBSIDIAN:0)
Block(-8,88,-3,OBSIDIAN:0)
Block(-8,88,-2,OBSIDIAN:0)
Block(-8,88,-1,OBSIDIAN:0)
Block(-8,88,0,OBSIDIAN:0)
Block(-8,88,1,OBSIDIAN:0)
Block(-8,88,2,OBSIDIAN:0)
Block(-8,88,3,OBSIDIAN:0)
Block(-8,88,4,OBSIDIAN:0)
Block(-8,88,5,OBSIDIAN:0)
Block(-8,88,6,OBSIDIAN:0)
Block(-8,88,7,OBSIDIAN:0)
Block(-8,88,8,OBSIDIAN:0)
Block(-8,89,-7,OBSIDIAN:0)
Block(-8,89,-6,OBSIDIAN:0)
Block(-8,89,-5,OBSIDIAN:0)
Block(-8,89,-4,OBSIDIAN:0)
Block(-8,89,-3,OBSIDIAN:0)
Block(-8,89,-2,OBSIDIAN:0)
Block(-8,89,-1,OBSIDIAN:0)
Block(-8,89,0,OBSIDIAN:0)
Block(-8,89,1,OBSIDIAN:0)
Block(-8,89,2,OBSIDIAN:0)
Block(-8,89,3,OBSIDIAN:0)
Block(-8,89,4,OBSIDIAN:0)
Block(-8,89,5,OBSIDIAN:0)
Block(-8,89,6,OBSIDIAN:0)
Block(-8,89,7,OBSIDIAN:0)
Block(-8,89,8,STONE:3)
Block(-8,90,-7,OBSIDIAN:0)
Block(-8,90,-6,OBSIDIAN:0)
Block(-8,90,-5,OBSIDIAN:0)
Block(-8,90,-4,OBSIDIAN:0)
Block(-8,90,-3,OBSIDIAN:0)
Block(-8,90,-2,OBSIDIAN:0)
Block(-8,90,-1,OBSIDIAN:0)
Block(-8,90,0,OBSIDIAN:0)
Block(-8,90,1,OBSIDIAN:0)
Block(-8,90,2,OBSIDIAN:0)
Block(-8,90,3,OBSIDIAN:0)
Block(-8,90,4,OBSIDIAN:0)
Block(-8,90,5,OBSIDIAN:0)
Block(-8,90,6,STONE:3)
Block(-8,90,7,STONE:3)
Block(-8,90,8,STONE:3)
Block(-8,91,-7,MAGMA:0)
Block(-8,91,-6,MAGMA:0)
Block(-8,91,-5,MAGMA:0)
Block(-8,91,-4,OBSIDIAN:0)
Block(-8,91,-3,OBSIDIAN:0)
Block(-8,91,-2,OBSIDIAN:0)
Block(-8,91,-1,OBSIDIAN:0)
Block(-8,91,0,OBSIDIAN:0)
Block(-8,91,1,OBSIDIAN:0)
Block(-8,91,2,OBSIDIAN:0)
Block(-8,91,3,OBSIDIAN:0)
Block(-8,91,4,OBSIDIAN:0)
Block(-8,91,5,STONE:3)
Block(-8,91,6,STONE:3)
Block(-8,91,7,STONE:3)
Block(-8,92,-7,MAGMA:0)
Block(-8,92,-6,MAGMA:0)
Block(-8,92,-5,MAGMA:0)
Block(-8,92,-4,MAGMA:0)
Block(-8,92,-3,MAGMA:0)
Block(-8,92,-2,OBSIDIAN:0)
Block(-8,92,-1,OBSIDIAN:0)
Block(-8,92,0,OBSIDIAN:0)
Block(-8,92,1,OBSIDIAN:0)
Block(-8,92,2,OBSIDIAN:0)
Block(-8,92,3,OBSIDIAN:0)
Block(-8,92,4,OBSIDIAN:0)
Block(-8,92,5,OBSIDIAN:0)
Block(-8,93,-7,MAGMA:0)
Block(-8,93,-6,MAGMA:0)
Block(-8,93,-5,MAGMA:0)
Block(-8,93,-4,MAGMA:0)
Block(-8,93,-3,MAGMA:0)
Block(-8,93,-2,MAGMA:0)
Block(-8,93,-1,MAGMA:0)
Block(-8,93,0,MAGMA:0)
Block(-8,93,1,OBSIDIAN:0)
Block(-8,94,-7,MAGMA:0)
Block(-8,94,-6,MAGMA:0)
Block(-8,94,-5,MAGMA:0)
Block(-8,94,-4,MAGMA:0)
Block(-8,94,-2,MAGMA:0)
Block(-8,94,-1,MAGMA:0)
Block(-8,95,-7,MAGMA:0)
Block(-8,95,-6,MAGMA:0)
Block(-8,95,-5,MAGMA:0)
Block(-8,95,-4,MAGMA:0)
Block(-8,96,-7,MAGMA:0)
Block(-8,96,-6,OBSIDIAN:0)
Block(-8,96,-5,MAGMA:0)
Block(-8,96,-4,MAGMA:0)
Block(-8,97,-5,OBSIDIAN:0)
Block(-7,23,-7,STONE:3)
Block(-7,23,-6,STONE:3)
Block(-7,24,-7,STONE:3)
Block(-7,24,-6,STONE:3)
Block(-7,24,-5,STONE:3)
Block(-7,24,-4,STONE:3)
Block(-7,25,-7,STONE:3)
Block(-7,25,-6,STONE:3)
Block(-7,25,-5,STONE:3)
Block(-7,25,-4,STONE:3)
Block(-7,25,-3,STONE:3)
Block(-7,25,-2,STONE:3)
Block(-7,25,-1,STONE:3)
Block(-7,26,-7,STONE:3)
Block(-7,26,-6,STONE:3)
Block(-7,26,-5,STONE:3)
Block(-7,26,-4,STONE:3)
Block(-7,26,-3,STONE:3)
Block(-7,26,-2,STONE:3)
Block(-7,26,-1,STONE:3)
Block(-7,26,0,STONE:3)
Block(-7,26,1,STONE:3)
Block(-7,27,-7,STONE:3)
Block(-7,27,-6,STONE:3)
Block(-7,27,-5,STONE:3)
Block(-7,27,-4,STONE:3)
Block(-7,27,-3,STONE:3)
Block(-7,27,-2,STONE:3)
Block(-7,27,-1,STONE:3)
Block(-7,27,0,STONE:3)
Block(-7,27,1,STONE:3)
Block(-7,27,2,STONE:3)
Block(-7,28,-7,STONE:3)
Block(-7,28,-6,STONE:3)
Block(-7,28,-5,STONE:3)
Block(-7,28,-4,STONE:3)
Block(-7,28,-3,STONE:3)
Block(-7,28,-2,STONE:3)
Block(-7,28,-1,STONE:3)
Block(-7,28,0,STONE:3)
Block(-7,28,1,STONE:3)
Block(-7,28,2,STONE:3)
Block(-7,28,3,STONE:3)
Block(-7,28,4,STONE:3)
Block(-7,29,-7,OBSIDIAN:0)
Block(-7,29,-6,OBSIDIAN:0)
Block(-7,29,-5,OBSIDIAN:0)
Block(-7,29,-4,STONE:3)
Block(-7,29,-3,OBSIDIAN:0)
Block(-7,29,-2,OBSIDIAN:0)
Block(-7,29,-1,STONE:3)
Block(-7,29,0,STONE:3)
Block(-7,29,1,STONE:3)
Block(-7,29,2,STONE:3)
Block(-7,29,3,STONE:3)
Block(-7,29,4,OBSIDIAN:0)
Block(-7,29,5,OBSIDIAN:0)
Block(-7,29,6,STONE:3)
Block(-7,29,7,STONE:3)
Block(-7,29,8,STONE:3)
Block(-7,30,-7,OBSIDIAN:0)
Block(-7,30,-6,OBSIDIAN:0)
Block(-7,30,-5,OBSIDIAN:0)
Block(-7,30,-4,OBSIDIAN:0)
Block(-7,30,-3,OBSIDIAN:0)
Block(-7,30,-2,STONE:3)
Block(-7,30,-1,STONE:3)
Block(-7,30,0,STONE:3)
Block(-7,30,1,STONE:3)
Block(-7,30,2,STONE:3)
Block(-7,30,3,STONE:3)
Block(-7,30,4,STONE:3)
Block(-7,30,5,STONE:3)
Block(-7,30,6,STONE:3)
Block(-7,30,7,STONE:3)
Block(-7,30,8,STONE:3)
Block(-7,31,-7,STONE:5)
Block(-7,31,-6,OBSIDIAN:0)
Block(-7,31,-5,OBSIDIAN:0)
Block(-7,31,-4,OBSIDIAN:0)
Block(-7,31,-3,OBSIDIAN:0)
Block(-7,31,-2,STONE:3)
Block(-7,31,-1,STONE:3)
Block(-7,31,0,GRASS:0)
Block(-7,31,1,STONE:3)
Block(-7,31,2,STONE:3)
Block(-7,31,3,STONE:3)
Block(-7,31,4,STONE:3)
Block(-7,31,5,STONE:3)
Block(-7,31,6,STONE:3)
Block(-7,31,7,STONE:3)
Block(-7,31,8,STONE:3)
Block(-7,32,-7,STONE:5)
Block(-7,32,-6,STONE:3)
Block(-7,32,-5,STONE:3)
Block(-7,32,-4,STONE:3)
Block(-7,32,-3,STONE:3)
Block(-7,32,-2,STONE:3)
Block(-7,32,-1,GRASS:0)
Block(-7,32,0,STATIONARY_WATER:0)
Block(-7,32,1,STATIONARY_WATER:0)
Block(-7,32,2,STONE:3)
Block(-7,32,3,STONE:3)
Block(-7,32,4,STONE:3)
Block(-7,32,5,STONE:3)
Block(-7,32,6,OBSIDIAN:0)
Block(-7,32,7,STONE:3)
Block(-7,32,8,STONE:3)
Block(-7,33,-7,STONE:3)
Block(-7,33,-6,STONE:3)
Block(-7,33,-5,STONE:3)
Block(-7,33,-4,STONE:3)
Block(-7,33,-3,STONE:3)
Block(-7,33,-2,GRASS:0)
Block(-7,33,-1,STATIONARY_WATER:0)
Block(-7,33,0,STATIONARY_WATER:0)
Block(-7,33,1,STATIONARY_WATER:0)
Block(-7,33,2,STATIONARY_WATER:0)
Block(-7,33,3,STATIONARY_WATER:0)
Block(-7,33,4,STATIONARY_WATER:0)
Block(-7,33,5,STONE:5)
Block(-7,33,6,STONE:5)
Block(-7,33,7,OBSIDIAN:0)
Block(-7,33,8,OBSIDIAN:0)
Block(-7,34,-7,STONE:3)
Block(-7,34,-6,STONE:3)
Block(-7,34,-5,STONE:3)
Block(-7,34,-4,STONE:3)
Block(-7,34,-3,GRASS:0)
Block(-7,34,5,STONE:5)
Block(-7,34,6,STONE:5)
Block(-7,34,7,STONE:5)
Block(-7,34,8,OBSIDIAN:0)
Block(-7,35,-7,STONE:3)
Block(-7,35,-6,GRASS:0)
Block(-7,35,-5,GRASS:0)
Block(-7,35,-4,GRASS:0)
Block(-7,35,4,STONE:5)
Block(-7,35,5,STONE:5)
Block(-7,35,6,STONE:5)
Block(-7,35,7,STONE:5)
Block(-7,35,8,OBSIDIAN:0)
Block(-7,36,7,STONE:5)
Block(-7,36,8,OBSIDIAN:0)
Block(-7,37,8,OBSIDIAN:0)
Block(-7,38,8,OBSIDIAN:0)
Block(-7,68,8,OBSIDIAN:0)
Block(-7,69,5,OBSIDIAN:0)
Block(-7,69,6,OBSIDIAN:0)
Block(-7,69,7,OBSIDIAN:0)
Block(-7,69,8,OBSIDIAN:0)
Block(-7,70,4,OBSIDIAN:0)
Block(-7,70,5,OBSIDIAN:0)
Block(-7,70,6,OBSIDIAN:0)
Block(-7,70,7,OBSIDIAN:0)
Block(-7,70,8,OBSIDIAN:0)
Block(-7,71,3,OBSIDIAN:0)
Block(-7,71,4,OBSIDIAN:0)
Block(-7,71,5,OBSIDIAN:0)
Block(-7,71,6,OBSIDIAN:0)
Block(-7,71,7,OBSIDIAN:0)
Block(-7,71,8,OBSIDIAN:0)
Block(-7,72,2,OBSIDIAN:0)
Block(-7,72,3,OBSIDIAN:0)
Block(-7,72,4,OBSIDIAN:0)
Block(-7,72,5,OBSIDIAN:0)
Block(-7,72,6,OBSIDIAN:0)
Block(-7,72,7,OBSIDIAN:0)
Block(-7,72,8,OBSIDIAN:0)
Block(-7,73,1,OBSIDIAN:0)
Block(-7,73,2,OBSIDIAN:0)
Block(-7,73,3,OBSIDIAN:0)
Block(-7,73,4,OBSIDIAN:0)
Block(-7,73,5,OBSIDIAN:0)
Block(-7,73,6,OBSIDIAN:0)
Block(-7,73,7,OBSIDIAN:0)
Block(-7,73,8,OBSIDIAN:0)
Block(-7,74,2,OBSIDIAN:0)
Block(-7,74,3,OBSIDIAN:0)
Block(-7,74,4,OBSIDIAN:0)
Block(-7,74,5,OBSIDIAN:0)
Block(-7,74,6,OBSIDIAN:0)
Block(-7,74,7,OBSIDIAN:0)
Block(-7,74,8,OBSIDIAN:0)
Block(-7,75,3,OBSIDIAN:0)
Block(-7,75,4,OBSIDIAN:0)
Block(-7,75,5,OBSIDIAN:0)
Block(-7,75,6,OBSIDIAN:0)
Block(-7,75,7,OBSIDIAN:0)
Block(-7,75,8,OBSIDIAN:0)
Block(-7,76,2,OBSIDIAN:0)
Block(-7,76,3,OBSIDIAN:0)
Block(-7,76,4,OBSIDIAN:0)
Block(-7,76,5,OBSIDIAN:0)
Block(-7,76,6,OBSIDIAN:0)
Block(-7,76,7,OBSIDIAN:0)
Block(-7,76,8,OBSIDIAN:0)
Block(-7,77,1,OBSIDIAN:0)
Block(-7,77,2,OBSIDIAN:0)
Block(-7,77,3,OBSIDIAN:0)
Block(-7,77,4,OBSIDIAN:0)
Block(-7,77,5,OBSIDIAN:0)
Block(-7,77,6,OBSIDIAN:0)
Block(-7,77,7,OBSIDIAN:0)
Block(-7,77,8,OBSIDIAN:0)
Block(-7,78,0,OBSIDIAN:0)
Block(-7,78,1,OBSIDIAN:0)
Block(-7,78,2,OBSIDIAN:0)
Block(-7,78,3,OBSIDIAN:0)
Block(-7,78,4,OBSIDIAN:0)
Block(-7,78,5,OBSIDIAN:0)
Block(-7,78,6,OBSIDIAN:0)
Block(-7,78,7,OBSIDIAN:0)
Block(-7,78,8,OBSIDIAN:0)
Block(-7,79,-1,OBSIDIAN:0)
Block(-7,79,0,OBSIDIAN:0)
Block(-7,79,1,OBSIDIAN:0)
Block(-7,79,2,OBSIDIAN:0)
Block(-7,79,3,OBSIDIAN:0)
Block(-7,79,4,OBSIDIAN:0)
Block(-7,79,5,OBSIDIAN:0)
Block(-7,79,6,OBSIDIAN:0)
Block(-7,79,7,OBSIDIAN:0)
Block(-7,79,8,OBSIDIAN:0)
Block(-7,80,-3,OBSIDIAN:0)
Block(-7,80,-2,OBSIDIAN:0)
Block(-7,80,-1,OBSIDIAN:0)
Block(-7,80,0,OBSIDIAN:0)
Block(-7,80,1,OBSIDIAN:0)
Block(-7,80,2,OBSIDIAN:0)
Block(-7,80,3,OBSIDIAN:0)
Block(-7,80,4,OBSIDIAN:0)
Block(-7,80,5,OBSIDIAN:0)
Block(-7,80,6,OBSIDIAN:0)
Block(-7,80,7,OBSIDIAN:0)
Block(-7,80,8,OBSIDIAN:0)
Block(-7,81,-7,OBSIDIAN:0)
Block(-7,81,-6,OBSIDIAN:0)
Block(-7,81,-5,OBSIDIAN:0)
Block(-7,81,-4,OBSIDIAN:0)
Block(-7,81,-3,OBSIDIAN:0)
Block(-7,81,-2,OBSIDIAN:0)
Block(-7,81,-1,OBSIDIAN:0)
Block(-7,81,0,OBSIDIAN:0)
Block(-7,81,1,OBSIDIAN:0)
Block(-7,81,2,OBSIDIAN:0)
Block(-7,81,3,OBSIDIAN:0)
Block(-7,81,4,OBSIDIAN:0)
Block(-7,81,5,OBSIDIAN:0)
Block(-7,81,6,OBSIDIAN:0)
Block(-7,81,7,OBSIDIAN:0)
Block(-7,81,8,OBSIDIAN:0)
Block(-7,82,-7,OBSIDIAN:0)
Block(-7,82,-6,OBSIDIAN:0)
Block(-7,82,-5,OBSIDIAN:0)
Block(-7,82,-4,OBSIDIAN:0)
Block(-7,82,-3,OBSIDIAN:0)
Block(-7,82,-2,OBSIDIAN:0)
Block(-7,82,-1,OBSIDIAN:0)
Block(-7,82,0,OBSIDIAN:0)
Block(-7,82,1,OBSIDIAN:0)
Block(-7,82,2,OBSIDIAN:0)
Block(-7,82,3,OBSIDIAN:0)
Block(-7,82,4,OBSIDIAN:0)
Block(-7,82,5,OBSIDIAN:0)
Block(-7,82,6,OBSIDIAN:0)
Block(-7,82,7,OBSIDIAN:0)
Block(-7,82,8,OBSIDIAN:0)
Block(-7,83,-7,OBSIDIAN:0)
Block(-7,83,-6,OBSIDIAN:0)
Block(-7,83,-5,OBSIDIAN:0)
Block(-7,83,-4,OBSIDIAN:0)
Block(-7,83,-3,OBSIDIAN:0)
Block(-7,83,-2,OBSIDIAN:0)
Block(-7,83,-1,OBSIDIAN:0)
Block(-7,83,0,OBSIDIAN:0)
Block(-7,83,1,OBSIDIAN:0)
Block(-7,83,2,OBSIDIAN:0)
Block(-7,83,3,OBSIDIAN:0)
Block(-7,83,4,OBSIDIAN:0)
Block(-7,83,5,OBSIDIAN:0)
Block(-7,83,6,OBSIDIAN:0)
Block(-7,83,7,OBSIDIAN:0)
Block(-7,83,8,OBSIDIAN:0)
Block(-7,84,-7,OBSIDIAN:0)
Block(-7,84,-6,OBSIDIAN:0)
Block(-7,84,-5,OBSIDIAN:0)
Block(-7,84,-4,OBSIDIAN:0)
Block(-7,84,-3,OBSIDIAN:0)
Block(-7,84,-2,OBSIDIAN:0)
Block(-7,84,-1,OBSIDIAN:0)
Block(-7,84,0,OBSIDIAN:0)
Block(-7,84,1,OBSIDIAN:0)
Block(-7,84,2,OBSIDIAN:0)
Block(-7,84,3,OBSIDIAN:0)
Block(-7,84,4,OBSIDIAN:0)
Block(-7,84,5,OBSIDIAN:0)
Block(-7,84,6,OBSIDIAN:0)
Block(-7,84,7,OBSIDIAN:0)
Block(-7,84,8,OBSIDIAN:0)
Block(-7,85,-7,OBSIDIAN:0)
Block(-7,85,-6,OBSIDIAN:0)
Block(-7,85,-5,OBSIDIAN:0)
Block(-7,85,-4,OBSIDIAN:0)
Block(-7,85,-3,OBSIDIAN:0)
Block(-7,85,-2,OBSIDIAN:0)
Block(-7,85,-1,OBSIDIAN:0)
Block(-7,85,0,OBSIDIAN:0)
Block(-7,85,1,OBSIDIAN:0)
Block(-7,85,2,OBSIDIAN:0)
Block(-7,85,3,OBSIDIAN:0)
Block(-7,85,4,OBSIDIAN:0)
Block(-7,85,5,OBSIDIAN:0)
Block(-7,85,6,OBSIDIAN:0)
Block(-7,85,7,OBSIDIAN:0)
Block(-7,85,8,OBSIDIAN:0)
Block(-7,86,-7,OBSIDIAN:0)
Block(-7,86,-6,OBSIDIAN:0)
Block(-7,86,-5,OBSIDIAN:0)
Block(-7,86,-4,OBSIDIAN:0)
Block(-7,86,-3,OBSIDIAN:0)
Block(-7,86,-2,OBSIDIAN:0)
Block(-7,86,-1,OBSIDIAN:0)
Block(-7,86,0,OBSIDIAN:0)
Block(-7,86,1,OBSIDIAN:0)
Block(-7,86,2,OBSIDIAN:0)
Block(-7,86,3,OBSIDIAN:0)
Block(-7,86,4,OBSIDIAN:0)
Block(-7,86,5,OBSIDIAN:0)
Block(-7,86,6,OBSIDIAN:0)
Block(-7,86,7,OBSIDIAN:0)
Block(-7,86,8,OBSIDIAN:0)
Block(-7,87,-7,OBSIDIAN:0)
Block(-7,87,-6,OBSIDIAN:0)
Block(-7,87,-5,OBSIDIAN:0)
Block(-7,87,-4,OBSIDIAN:0)
Block(-7,87,-3,OBSIDIAN:0)
Block(-7,87,-2,OBSIDIAN:0)
Block(-7,87,-1,OBSIDIAN:0)
Block(-7,87,0,OBSIDIAN:0)
Block(-7,87,1,OBSIDIAN:0)
Block(-7,87,2,OBSIDIAN:0)
Block(-7,87,3,OBSIDIAN:0)
Block(-7,87,4,OBSIDIAN:0)
Block(-7,87,5,OBSIDIAN:0)
Block(-7,87,6,OBSIDIAN:0)
Block(-7,87,7,OBSIDIAN:0)
Block(-7,87,8,OBSIDIAN:0)
Block(-7,88,-7,OBSIDIAN:0)
Block(-7,88,-6,OBSIDIAN:0)
Block(-7,88,-5,OBSIDIAN:0)
Block(-7,88,-4,OBSIDIAN:0)
Block(-7,88,-3,OBSIDIAN:0)
Block(-7,88,-2,OBSIDIAN:0)
Block(-7,88,-1,OBSIDIAN:0)
Block(-7,88,0,OBSIDIAN:0)
Block(-7,88,1,OBSIDIAN:0)
Block(-7,88,2,OBSIDIAN:0)
Block(-7,88,3,OBSIDIAN:0)
Block(-7,88,4,OBSIDIAN:0)
Block(-7,88,5,OBSIDIAN:0)
Block(-7,88,6,OBSIDIAN:0)
Block(-7,88,7,OBSIDIAN:0)
Block(-7,88,8,OBSIDIAN:0)
Block(-7,89,-7,OBSIDIAN:0)
Block(-7,89,-6,OBSIDIAN:0)
Block(-7,89,-5,OBSIDIAN:0)
Block(-7,89,-4,OBSIDIAN:0)
Block(-7,89,-3,OBSIDIAN:0)
Block(-7,89,-2,OBSIDIAN:0)
Block(-7,89,-1,OBSIDIAN:0)
Block(-7,89,0,OBSIDIAN:0)
Block(-7,89,1,OBSIDIAN:0)
Block(-7,89,2,OBSIDIAN:0)
Block(-7,89,3,OBSIDIAN:0)
Block(-7,89,4,OBSIDIAN:0)
Block(-7,89,5,OBSIDIAN:0)
Block(-7,89,6,OBSIDIAN:0)
Block(-7,89,7,OBSIDIAN:0)
Block(-7,89,8,STONE:3)
Block(-7,90,-7,OBSIDIAN:0)
Block(-7,90,-6,OBSIDIAN:0)
Block(-7,90,-5,OBSIDIAN:0)
Block(-7,90,-4,OBSIDIAN:0)
Block(-7,90,-3,OBSIDIAN:0)
Block(-7,90,-2,OBSIDIAN:0)
Block(-7,90,-1,OBSIDIAN:0)
Block(-7,90,0,OBSIDIAN:0)
Block(-7,90,1,OBSIDIAN:0)
Block(-7,90,2,OBSIDIAN:0)
Block(-7,90,3,OBSIDIAN:0)
Block(-7,90,4,OBSIDIAN:0)
Block(-7,90,5,OBSIDIAN:0)
Block(-7,90,6,OBSIDIAN:0)
Block(-7,90,7,STONE:3)
Block(-7,90,8,STONE:3)
Block(-7,91,-7,OBSIDIAN:0)
Block(-7,91,-6,OBSIDIAN:0)
Block(-7,91,-5,OBSIDIAN:0)
Block(-7,91,-4,OBSIDIAN:0)
Block(-7,91,-3,OBSIDIAN:0)
Block(-7,91,-2,OBSIDIAN:0)
Block(-7,91,-1,OBSIDIAN:0)
Block(-7,91,0,OBSIDIAN:0)
Block(-7,91,1,OBSIDIAN:0)
Block(-7,91,2,OBSIDIAN:0)
Block(-7,91,3,OBSIDIAN:0)
Block(-7,91,4,OBSIDIAN:0)
Block(-7,91,5,OBSIDIAN:0)
Block(-7,91,6,STONE:3)
Block(-7,91,7,STONE:3)
Block(-7,92,-7,MAGMA:0)
Block(-7,92,-6,MAGMA:0)
Block(-7,92,-5,MAGMA:0)
Block(-7,92,-4,MAGMA:0)
Block(-7,92,-3,MAGMA:0)
Block(-7,92,-2,OBSIDIAN:0)
Block(-7,92,-1,OBSIDIAN:0)
Block(-7,92,0,OBSIDIAN:0)
Block(-7,92,1,OBSIDIAN:0)
Block(-7,92,2,OBSIDIAN:0)
Block(-7,92,3,OBSIDIAN:0)
Block(-7,92,4,OBSIDIAN:0)
Block(-7,92,5,OBSIDIAN:0)
Block(-7,92,6,STONE:3)
Block(-7,93,-7,MAGMA:0)
Block(-7,93,-6,MAGMA:0)
Block(-7,93,-5,MAGMA:0)
Block(-7,93,-4,MAGMA:0)
Block(-7,93,-3,MAGMA:0)
Block(-7,93,-2,MAGMA:0)
Block(-7,93,-1,MAGMA:0)
Block(-7,93,0,MAGMA:0)
Block(-7,93,1,OBSIDIAN:0)
Block(-7,93,2,OBSIDIAN:0)
Block(-7,93,3,OBSIDIAN:0)
Block(-7,94,-7,MAGMA:0)
Block(-7,94,-6,MAGMA:0)
Block(-7,94,-5,MAGMA:0)
Block(-7,94,-4,MAGMA:0)
Block(-7,94,-3,MAGMA:0)
Block(-7,94,-2,MAGMA:0)
Block(-7,94,-1,MAGMA:0)
Block(-7,94,0,MAGMA:0)
Block(-7,95,-7,OBSIDIAN:0)
Block(-7,95,-6,MAGMA:0)
Block(-7,95,-5,MAGMA:0)
Block(-7,95,-4,MAGMA:0)
Block(-7,95,-3,MAGMA:0)
Block(-7,95,-2,MAGMA:0)
Block(-7,95,-1,MAGMA:0)
Block(-7,96,-7,OBSIDIAN:0)
Block(-7,96,-6,OBSIDIAN:0)
Block(-7,96,-5,MAGMA:0)
Block(-7,96,-4,MAGMA:0)
Block(-7,96,-3,MAGMA:0)
Block(-7,97,-7,OBSIDIAN:0)
Block(-7,97,-6,OBSIDIAN:0)
Block(-7,97,-5,OBSIDIAN:0)
Block(-7,97,-4,OBSIDIAN:0)
Block(-7,98,-5,OBSIDIAN:0)
Block(-6,23,-7,STONE:3)
Block(-6,23,-6,STONE:3)
Block(-6,23,-5,STONE:3)
Block(-6,24,-7,STONE:3)
Block(-6,24,-6,STONE:3)
Block(-6,24,-5,STONE:3)
Block(-6,24,-4,STONE:3)
Block(-6,25,-7,STONE:3)
Block(-6,25,-6,STONE:3)
Block(-6,25,-5,STONE:3)
Block(-6,25,-4,STONE:3)
Block(-6,25,-3,STONE:3)
Block(-6,26,-7,STONE:3)
Block(-6,26,-6,STONE:3)
Block(-6,26,-5,STONE:3)
Block(-6,26,-4,STONE:3)
Block(-6,26,-3,STONE:3)
Block(-6,26,-2,STONE:3)
Block(-6,26,-1,STONE:3)
Block(-6,26,0,STONE:3)
Block(-6,26,1,STONE:3)
Block(-6,27,-7,STONE:3)
Block(-6,27,-6,STONE:3)
Block(-6,27,-5,STONE:3)
Block(-6,27,-4,STONE:3)
Block(-6,27,-3,STONE:3)
Block(-6,27,-2,STONE:3)
Block(-6,27,-1,STONE:3)
Block(-6,27,0,STONE:3)
Block(-6,27,1,STONE:3)
Block(-6,27,2,STONE:3)
Block(-6,27,3,STONE:3)
Block(-6,28,-7,STONE:3)
Block(-6,28,-6,STONE:3)
Block(-6,28,-5,STONE:3)
Block(-6,28,-4,STONE:3)
Block(-6,28,-3,STONE:3)
Block(-6,28,-2,STONE:3)
Block(-6,28,-1,STONE:3)
Block(-6,28,0,STONE:3)
Block(-6,28,1,STONE:3)
Block(-6,28,2,OBSIDIAN:0)
Block(-6,28,3,OBSIDIAN:0)
Block(-6,28,4,OBSIDIAN:0)
Block(-6,28,5,STONE:3)
Block(-6,29,-7,OBSIDIAN:0)
Block(-6,29,-6,OBSIDIAN:0)
Block(-6,29,-5,OBSIDIAN:0)
Block(-6,29,-4,STONE:3)
Block(-6,29,-3,STONE:3)
Block(-6,29,-2,STONE:3)
Block(-6,29,-1,STONE:3)
Block(-6,29,0,STONE:3)
Block(-6,29,1,STONE:3)
Block(-6,29,2,STONE:3)
Block(-6,29,3,STONE:3)
Block(-6,29,4,STONE:3)
Block(-6,29,5,STONE:3)
Block(-6,29,6,STONE:3)
Block(-6,29,7,STONE:3)
Block(-6,29,8,STONE:3)
Block(-6,30,-7,OBSIDIAN:0)
Block(-6,30,-6,OBSIDIAN:0)
Block(-6,30,-5,OBSIDIAN:0)
Block(-6,30,-4,OBSIDIAN:0)
Block(-6,30,-3,OBSIDIAN:0)
Block(-6,30,-2,STONE:3)
Block(-6,30,-1,STONE:3)
Block(-6,30,0,STONE:3)
Block(-6,30,1,STONE:3)
Block(-6,30,2,STONE:3)
Block(-6,30,3,STONE:3)
Block(-6,30,4,STONE:3)
Block(-6,30,5,STONE:3)
Block(-6,30,6,STONE:3)
Block(-6,30,7,STONE:3)
Block(-6,30,8,STONE:3)
Block(-6,31,-7,OBSIDIAN:0)
Block(-6,31,-6,OBSIDIAN:0)
Block(-6,31,-5,OBSIDIAN:0)
Block(-6,31,-4,OBSIDIAN:0)
Block(-6,31,-3,STONE:5)
Block(-6,31,-2,STONE:3)
Block(-6,31,-1,STONE:3)
Block(-6,31,0,GRASS:0)
Block(-6,31,1,STONE:3)
Block(-6,31,2,STONE:3)
Block(-6,31,3,STONE:3)
Block(-6,31,4,STONE:3)
Block(-6,31,5,STONE:3)
Block(-6,31,6,STONE:3)
Block(-6,31,7,STONE:3)
Block(-6,31,8,STONE:3)
Block(-6,32,-7,OBSIDIAN:0)
Block(-6,32,-6,OBSIDIAN:0)
Block(-6,32,-5,OBSIDIAN:0)
Block(-6,32,-4,STONE:5)
Block(-6,32,-3,STONE:3)
Block(-6,32,-2,STONE:3)
Block(-6,32,-1,STONE:3)
Block(-6,32,0,STATIONARY_WATER:0)
Block(-6,32,1,STATIONARY_WATER:0)
Block(-6,32,2,STATIONARY_WATER:0)
Block(-6,32,3,STONE:3)
Block(-6,32,4,STONE:3)
Block(-6,32,5,STONE:3)
Block(-6,32,6,STONE:3)
Block(-6,32,7,OBSIDIAN:0)
Block(-6,32,8,OBSIDIAN:0)
Block(-6,33,-7,STONE:3)
Block(-6,33,-6,STONE:3)
Block(-6,33,-5,STONE:3)
Block(-6,33,-4,STONE:3)
Block(-6,33,-3,STONE:3)
Block(-6,33,-2,STONE:3)
Block(-6,33,-1,GRASS:0)
Block(-6,33,0,STATIONARY_WATER:0)
Block(-6,33,1,STATIONARY_WATER:0)
Block(-6,33,2,STATIONARY_WATER:0)
Block(-6,33,3,STATIONARY_WATER:0)
Block(-6,33,4,STONE:3)
Block(-6,33,5,STONE:3)
Block(-6,33,6,STONE:5)
Block(-6,33,7,OBSIDIAN:0)
Block(-6,33,8,OBSIDIAN:0)
Block(-6,34,-7,STONE:3)
Block(-6,34,-6,STONE:3)
Block(-6,34,-5,STONE:3)
Block(-6,34,-4,STONE:3)
Block(-6,34,-3,STONE:3)
Block(-6,34,-2,GRASS:0)
Block(-6,34,4,STONE:5)
Block(-6,34,5,STONE:5)
Block(-6,34,6,STONE:5)
Block(-6,34,7,STONE:5)
Block(-6,34,8,OBSIDIAN:0)
Block(-6,35,-7,STONE:3)
Block(-6,35,-6,STONE:3)
Block(-6,35,-5,STONE:3)
Block(-6,35,-4,GRASS:0)
Block(-6,35,-3,GRASS:0)
Block(-6,35,4,STONE:5)
Block(-6,35,5,STONE:5)
Block(-6,35,6,STONE:5)
Block(-6,35,7,STONE:5)
Block(-6,35,8,OBSIDIAN:0)
Block(-6,36,-7,GRASS:0)
Block(-6,36,-6,GRASS:0)
Block(-6,36,-5,GRASS:0)
Block(-6,36,7,STONE:5)
Block(-6,36,8,OBSIDIAN:0)
Block(-6,37,7,OBSIDIAN:0)
Block(-6,37,8,OBSIDIAN:0)
Block(-6,38,8,OBSIDIAN:0)
Block(-6,39,8,OBSIDIAN:0)
Block(-6,69,7,OBSIDIAN:0)
Block(-6,69,8,OBSIDIAN:0)
Block(-6,70,6,OBSIDIAN:0)
Block(-6,70,7,OBSIDIAN:0)
Block(-6,70,8,OBSIDIAN:0)
Block(-6,71,5,OBSIDIAN:0)
Block(-6,71,6,OBSIDIAN:0)
Block(-6,71,7,OBSIDIAN:0)
Block(-6,71,8,OBSIDIAN:0)
Block(-6,72,5,OBSIDIAN:0)
Block(-6,72,6,OBSIDIAN:0)
Block(-6,72,7,OBSIDIAN:0)
Block(-6,72,8,OBSIDIAN:0)
Block(-6,73,4,OBSIDIAN:0)
Block(-6,73,5,OBSIDIAN:0)
Block(-6,73,6,OBSIDIAN:0)
Block(-6,73,7,OBSIDIAN:0)
Block(-6,73,8,OBSIDIAN:0)
Block(-6,74,2,OBSIDIAN:0)
Block(-6,74,3,OBSIDIAN:0)
Block(-6,74,4,OBSIDIAN:0)
Block(-6,74,5,OBSIDIAN:0)
Block(-6,74,6,OBSIDIAN:0)
Block(-6,74,7,OBSIDIAN:0)
Block(-6,74,8,OBSIDIAN:0)
Block(-6,75,2,OBSIDIAN:0)
Block(-6,75,3,OBSIDIAN:0)
Block(-6,75,4,OBSIDIAN:0)
Block(-6,75,5,OBSIDIAN:0)
Block(-6,75,6,OBSIDIAN:0)
Block(-6,75,7,OBSIDIAN:0)
Block(-6,75,8,OBSIDIAN:0)
Block(-6,76,1,OBSIDIAN:0)
Block(-6,76,2,OBSIDIAN:0)
Block(-6,76,3,OBSIDIAN:0)
Block(-6,76,4,OBSIDIAN:0)
Block(-6,76,5,OBSIDIAN:0)
Block(-6,76,6,OBSIDIAN:0)
Block(-6,76,7,OBSIDIAN:0)
Block(-6,76,8,OBSIDIAN:0)
Block(-6,77,0,OBSIDIAN:0)
Block(-6,77,1,OBSIDIAN:0)
Block(-6,77,2,OBSIDIAN:0)
Block(-6,77,3,OBSIDIAN:0)
Block(-6,77,4,OBSIDIAN:0)
Block(-6,77,5,OBSIDIAN:0)
Block(-6,77,6,OBSIDIAN:0)
Block(-6,77,7,OBSIDIAN:0)
Block(-6,77,8,OBSIDIAN:0)
Block(-6,78,-2,OBSIDIAN:0)
Block(-6,78,-1,OBSIDIAN:0)
Block(-6,78,0,OBSIDIAN:0)
Block(-6,78,1,OBSIDIAN:0)
Block(-6,78,2,OBSIDIAN:0)
Block(-6,78,3,OBSIDIAN:0)
Block(-6,78,4,OBSIDIAN:0)
Block(-6,78,5,OBSIDIAN:0)
Block(-6,78,6,OBSIDIAN:0)
Block(-6,78,7,OBSIDIAN:0)
Block(-6,78,8,OBSIDIAN:0)
Block(-6,79,-4,OBSIDIAN:0)
Block(-6,79,-3,OBSIDIAN:0)
Block(-6,79,-2,OBSIDIAN:0)
Block(-6,79,-1,OBSIDIAN:0)
Block(-6,79,0,OBSIDIAN:0)
Block(-6,79,1,OBSIDIAN:0)
Block(-6,79,2,OBSIDIAN:0)
Block(-6,79,3,OBSIDIAN:0)
Block(-6,79,4,OBSIDIAN:0)
Block(-6,79,5,OBSIDIAN:0)
Block(-6,79,6,OBSIDIAN:0)
Block(-6,79,7,OBSIDIAN:0)
Block(-6,79,8,OBSIDIAN:0)
Block(-6,80,-5,OBSIDIAN:0)
Block(-6,80,-4,OBSIDIAN:0)
Block(-6,80,-3,OBSIDIAN:0)
Block(-6,80,-2,OBSIDIAN:0)
Block(-6,80,-1,OBSIDIAN:0)
Block(-6,80,0,OBSIDIAN:0)
Block(-6,80,1,OBSIDIAN:0)
Block(-6,80,2,OBSIDIAN:0)
Block(-6,80,3,OBSIDIAN:0)
Block(-6,80,4,OBSIDIAN:0)
Block(-6,80,5,OBSIDIAN:0)
Block(-6,80,6,OBSIDIAN:0)
Block(-6,80,7,OBSIDIAN:0)
Block(-6,80,8,OBSIDIAN:0)
Block(-6,81,-7,OBSIDIAN:0)
Block(-6,81,-6,OBSIDIAN:0)
Block(-6,81,-5,OBSIDIAN:0)
Block(-6,81,-4,OBSIDIAN:0)
Block(-6,81,-3,OBSIDIAN:0)
Block(-6,81,-2,OBSIDIAN:0)
Block(-6,81,-1,OBSIDIAN:0)
Block(-6,81,0,OBSIDIAN:0)
Block(-6,81,1,OBSIDIAN:0)
Block(-6,81,2,OBSIDIAN:0)
Block(-6,81,3,OBSIDIAN:0)
Block(-6,81,4,OBSIDIAN:0)
Block(-6,81,5,OBSIDIAN:0)
Block(-6,81,6,OBSIDIAN:0)
Block(-6,81,7,OBSIDIAN:0)
Block(-6,81,8,OBSIDIAN:0)
Block(-6,82,-7,OBSIDIAN:0)
Block(-6,82,-6,OBSIDIAN:0)
Block(-6,82,-5,OBSIDIAN:0)
Block(-6,82,-4,OBSIDIAN:0)
Block(-6,82,-3,OBSIDIAN:0)
Block(-6,82,-2,OBSIDIAN:0)
Block(-6,82,-1,OBSIDIAN:0)
Block(-6,82,0,OBSIDIAN:0)
Block(-6,82,1,OBSIDIAN:0)
Block(-6,82,2,OBSIDIAN:0)
Block(-6,82,3,OBSIDIAN:0)
Block(-6,82,4,OBSIDIAN:0)
Block(-6,82,5,OBSIDIAN:0)
Block(-6,82,6,OBSIDIAN:0)
Block(-6,82,7,OBSIDIAN:0)
Block(-6,82,8,OBSIDIAN:0)
Block(-6,83,-7,OBSIDIAN:0)
Block(-6,83,-6,OBSIDIAN:0)
Block(-6,83,-5,OBSIDIAN:0)
Block(-6,83,-4,OBSIDIAN:0)
Block(-6,83,-3,OBSIDIAN:0)
Block(-6,83,-2,OBSIDIAN:0)
Block(-6,83,-1,OBSIDIAN:0)
Block(-6,83,0,OBSIDIAN:0)
Block(-6,83,1,OBSIDIAN:0)
Block(-6,83,2,OBSIDIAN:0)
Block(-6,83,3,OBSIDIAN:0)
Block(-6,83,4,OBSIDIAN:0)
Block(-6,83,5,OBSIDIAN:0)
Block(-6,83,6,OBSIDIAN:0)
Block(-6,83,7,OBSIDIAN:0)
Block(-6,83,8,OBSIDIAN:0)
Block(-6,84,-7,OBSIDIAN:0)
Block(-6,84,-6,OBSIDIAN:0)
Block(-6,84,-5,OBSIDIAN:0)
Block(-6,84,-4,OBSIDIAN:0)
Block(-6,84,-3,OBSIDIAN:0)
Block(-6,84,-2,OBSIDIAN:0)
Block(-6,84,-1,OBSIDIAN:0)
Block(-6,84,0,OBSIDIAN:0)
Block(-6,84,1,OBSIDIAN:0)
Block(-6,84,2,OBSIDIAN:0)
Block(-6,84,3,OBSIDIAN:0)
Block(-6,84,4,OBSIDIAN:0)
Block(-6,84,5,OBSIDIAN:0)
Block(-6,84,6,OBSIDIAN:0)
Block(-6,84,7,OBSIDIAN:0)
Block(-6,84,8,OBSIDIAN:0)
Block(-6,85,-7,OBSIDIAN:0)
Block(-6,85,-6,OBSIDIAN:0)
Block(-6,85,-5,OBSIDIAN:0)
Block(-6,85,-4,OBSIDIAN:0)
Block(-6,85,-3,OBSIDIAN:0)
Block(-6,85,-2,OBSIDIAN:0)
Block(-6,85,-1,OBSIDIAN:0)
Block(-6,85,0,OBSIDIAN:0)
Block(-6,85,1,OBSIDIAN:0)
Block(-6,85,2,OBSIDIAN:0)
Block(-6,85,3,OBSIDIAN:0)
Block(-6,85,4,OBSIDIAN:0)
Block(-6,85,5,OBSIDIAN:0)
Block(-6,85,6,OBSIDIAN:0)
Block(-6,85,7,OBSIDIAN:0)
Block(-6,85,8,OBSIDIAN:0)
Block(-6,86,-7,OBSIDIAN:0)
Block(-6,86,-6,OBSIDIAN:0)
Block(-6,86,-5,OBSIDIAN:0)
Block(-6,86,-4,OBSIDIAN:0)
Block(-6,86,-3,OBSIDIAN:0)
Block(-6,86,-2,OBSIDIAN:0)
Block(-6,86,-1,OBSIDIAN:0)
Block(-6,86,0,OBSIDIAN:0)
Block(-6,86,1,OBSIDIAN:0)
Block(-6,86,2,OBSIDIAN:0)
Block(-6,86,3,OBSIDIAN:0)
Block(-6,86,4,OBSIDIAN:0)
Block(-6,86,5,OBSIDIAN:0)
Block(-6,86,6,OBSIDIAN:0)
Block(-6,86,7,OBSIDIAN:0)
Block(-6,86,8,OBSIDIAN:0)
Block(-6,87,-7,OBSIDIAN:0)
Block(-6,87,-6,OBSIDIAN:0)
Block(-6,87,-5,OBSIDIAN:0)
Block(-6,87,-4,OBSIDIAN:0)
Block(-6,87,-3,OBSIDIAN:0)
Block(-6,87,-2,OBSIDIAN:0)
Block(-6,87,-1,OBSIDIAN:0)
Block(-6,87,0,OBSIDIAN:0)
Block(-6,87,1,OBSIDIAN:0)
Block(-6,87,2,OBSIDIAN:0)
Block(-6,87,3,OBSIDIAN:0)
Block(-6,87,4,OBSIDIAN:0)
Block(-6,87,5,OBSIDIAN:0)
Block(-6,87,6,OBSIDIAN:0)
Block(-6,87,7,OBSIDIAN:0)
Block(-6,87,8,OBSIDIAN:0)
Block(-6,88,-7,OBSIDIAN:0)
Block(-6,88,-6,OBSIDIAN:0)
Block(-6,88,-5,OBSIDIAN:0)
Block(-6,88,-4,OBSIDIAN:0)
Block(-6,88,-3,OBSIDIAN:0)
Block(-6,88,-2,OBSIDIAN:0)
Block(-6,88,-1,OBSIDIAN:0)
Block(-6,88,0,OBSIDIAN:0)
Block(-6,88,1,OBSIDIAN:0)
Block(-6,88,2,OBSIDIAN:0)
Block(-6,88,3,OBSIDIAN:0)
Block(-6,88,4,OBSIDIAN:0)
Block(-6,88,5,OBSIDIAN:0)
Block(-6,88,6,OBSIDIAN:0)
Block(-6,88,7,OBSIDIAN:0)
Block(-6,88,8,OBSIDIAN:0)
Block(-6,89,-7,OBSIDIAN:0)
Block(-6,89,-6,OBSIDIAN:0)
Block(-6,89,-5,OBSIDIAN:0)
Block(-6,89,-4,OBSIDIAN:0)
Block(-6,89,-3,OBSIDIAN:0)
Block(-6,89,-2,OBSIDIAN:0)
Block(-6,89,-1,OBSIDIAN:0)
Block(-6,89,0,OBSIDIAN:0)
Block(-6,89,1,OBSIDIAN:0)
Block(-6,89,2,OBSIDIAN:0)
Block(-6,89,3,OBSIDIAN:0)
Block(-6,89,4,OBSIDIAN:0)
Block(-6,89,5,OBSIDIAN:0)
Block(-6,89,6,OBSIDIAN:0)
Block(-6,89,7,OBSIDIAN:0)
Block(-6,89,8,STONE:3)
Block(-6,90,-7,OBSIDIAN:0)
Block(-6,90,-6,OBSIDIAN:0)
Block(-6,90,-5,STONE:3)
Block(-6,90,-4,STONE:3)
Block(-6,90,-3,OBSIDIAN:0)
Block(-6,90,-2,OBSIDIAN:0)
Block(-6,90,-1,OBSIDIAN:0)
Block(-6,90,0,OBSIDIAN:0)
Block(-6,90,1,OBSIDIAN:0)
Block(-6,90,2,OBSIDIAN:0)
Block(-6,90,3,OBSIDIAN:0)
Block(-6,90,4,OBSIDIAN:0)
Block(-6,90,5,OBSIDIAN:0)
Block(-6,90,6,OBSIDIAN:0)
Block(-6,90,7,STONE:3)
Block(-6,90,8,STONE:3)
Block(-6,91,-7,OBSIDIAN:0)
Block(-6,91,-6,OBSIDIAN:0)
Block(-6,91,-5,OBSIDIAN:0)
Block(-6,91,-4,OBSIDIAN:0)
Block(-6,91,-3,OBSIDIAN:0)
Block(-6,91,-2,OBSIDIAN:0)
Block(-6,91,-1,OBSIDIAN:0)
Block(-6,91,0,OBSIDIAN:0)
Block(-6,91,1,OBSIDIAN:0)
Block(-6,91,2,OBSIDIAN:0)
Block(-6,91,3,OBSIDIAN:0)
Block(-6,91,4,OBSIDIAN:0)
Block(-6,91,5,OBSIDIAN:0)
Block(-6,91,6,STONE:3)
Block(-6,91,7,STONE:3)
Block(-6,92,-7,OBSIDIAN:0)
Block(-6,92,-6,OBSIDIAN:0)
Block(-6,92,-5,OBSIDIAN:0)
Block(-6,92,-4,OBSIDIAN:0)
Block(-6,92,-3,OBSIDIAN:0)
Block(-6,92,-2,OBSIDIAN:0)
Block(-6,92,-1,OBSIDIAN:0)
Block(-6,92,0,MAGMA:0)
Block(-6,92,1,MAGMA:0)
Block(-6,92,2,MAGMA:0)
Block(-6,92,3,OBSIDIAN:0)
Block(-6,92,4,OBSIDIAN:0)
Block(-6,92,5,OBSIDIAN:0)
Block(-6,92,6,OBSIDIAN:0)
Block(-6,93,-7,OBSIDIAN:0)
Block(-6,93,-6,OBSIDIAN:0)
Block(-6,93,-5,MAGMA:0)
Block(-6,93,-4,MAGMA:0)
Block(-6,93,-3,MAGMA:0)
Block(-6,93,-2,MAGMA:0)
Block(-6,93,-1,MAGMA:0)
Block(-6,93,0,MAGMA:0)
Block(-6,93,1,MAGMA:0)
Block(-6,93,2,MAGMA:0)
Block(-6,94,-7,OBSIDIAN:0)
Block(-6,94,-6,OBSIDIAN:0)
Block(-6,94,-5,MAGMA:0)
Block(-6,94,-4,MAGMA:0)
Block(-6,94,-3,MAGMA:0)
Block(-6,94,-2,MAGMA:0)
Block(-6,94,-1,MAGMA:0)
Block(-6,94,0,MAGMA:0)
Block(-6,94,1,MAGMA:0)
Block(-6,95,-7,OBSIDIAN:0)
Block(-6,95,-6,OBSIDIAN:0)
Block(-6,95,-5,MAGMA:0)
Block(-6,95,-4,MAGMA:0)
Block(-6,95,-3,MAGMA:0)
Block(-6,95,-2,MAGMA:0)
Block(-6,95,-1,MAGMA:0)
Block(-6,95,0,MAGMA:0)
Block(-6,96,-7,OBSIDIAN:0)
Block(-6,96,-6,OBSIDIAN:0)
Block(-6,96,-5,OBSIDIAN:0)
Block(-6,96,-4,MAGMA:0)
Block(-6,96,-3,MAGMA:0)
Block(-6,96,-2,MAGMA:0)
Block(-6,97,-7,OBSIDIAN:0)
Block(-6,97,-6,OBSIDIAN:0)
Block(-6,97,-5,OBSIDIAN:0)
Block(-6,97,-4,OBSIDIAN:0)
Block(-6,97,-3,MAGMA:0)
Block(-6,98,-7,OBSIDIAN:0)
Block(-6,98,-6,OBSIDIAN:0)
Block(-6,98,-5,OBSIDIAN:0)
Block(-6,98,-4,OBSIDIAN:0)
Block(-6,99,-5,OBSIDIAN:0)
Block(-5,23,-7,STONE:3)
Block(-5,23,-6,STONE:3)
Block(-5,23,-5,STONE:3)
Block(-5,24,-7,STONE:3)
Block(-5,24,-6,STONE:3)
Block(-5,24,-5,STONE:3)
Block(-5,24,-4,STONE:3)
Block(-5,24,-3,STONE:3)
Block(-5,25,-7,STONE:3)
Block(-5,25,-6,STONE:3)
Block(-5,25,-5,STONE:3)
Block(-5,25,-4,STONE:3)
Block(-5,25,-3,STONE:3)
Block(-5,25,-2,STONE:3)
Block(-5,26,-7,STONE:3)
Block(-5,26,-6,STONE:3)
Block(-5,26,-5,STONE:3)
Block(-5,26,-4,STONE:3)
Block(-5,26,-3,STONE:3)
Block(-5,26,-2,STONE:3)
Block(-5,26,-1,STONE:3)
Block(-5,26,0,STONE:3)
Block(-5,26,1,STONE:3)
Block(-5,26,2,STONE:3)
Block(-5,27,-7,STONE:3)
Block(-5,27,-6,STONE:3)
Block(-5,27,-5,STONE:3)
Block(-5,27,-4,STONE:3)
Block(-5,27,-3,STONE:3)
Block(-5,27,-2,STONE:3)
Block(-5,27,-1,STONE:3)
Block(-5,27,0,STONE:3)
Block(-5,27,1,STONE:3)
Block(-5,27,2,STONE:3)
Block(-5,27,3,STONE:3)
Block(-5,27,4,STONE:3)
Block(-5,28,-7,STONE:3)
Block(-5,28,-6,STONE:3)
Block(-5,28,-5,STONE:3)
Block(-5,28,-4,STONE:3)
Block(-5,28,-3,STONE:3)
Block(-5,28,-2,STONE:3)
Block(-5,28,-1,STONE:3)
Block(-5,28,0,STONE:3)
Block(-5,28,1,STONE:3)
Block(-5,28,2,OBSIDIAN:0)
Block(-5,28,3,OBSIDIAN:0)
Block(-5,28,4,OBSIDIAN:0)
Block(-5,28,5,STONE:3)
Block(-5,28,6,STONE:3)
Block(-5,29,-7,OBSIDIAN:0)
Block(-5,29,-6,OBSIDIAN:0)
Block(-5,29,-5,OBSIDIAN:0)
Block(-5,29,-4,STONE:3)
Block(-5,29,-3,STONE:3)
Block(-5,29,-2,STONE:3)
Block(-5,29,-1,STONE:3)
Block(-5,29,0,STONE:3)
Block(-5,29,1,STONE:3)
Block(-5,29,2,STONE:3)
Block(-5,29,3,STONE:3)
Block(-5,29,4,STONE:3)
Block(-5,29,5,STONE:3)
Block(-5,29,6,STONE:3)
Block(-5,29,7,STONE:3)
Block(-5,29,8,STONE:3)
Block(-5,30,-7,OBSIDIAN:0)
Block(-5,30,-6,OBSIDIAN:0)
Block(-5,30,-5,OBSIDIAN:0)
Block(-5,30,-4,OBSIDIAN:0)
Block(-5,30,-3,OBSIDIAN:0)
Block(-5,30,-2,OBSIDIAN:0)
Block(-5,30,-1,STONE:3)
Block(-5,30,0,STONE:3)
Block(-5,30,1,GRASS:0)
Block(-5,30,2,STONE:3)
Block(-5,30,3,STONE:3)
Block(-5,30,4,STONE:3)
Block(-5,30,5,STONE:3)
Block(-5,30,6,STONE:3)
Block(-5,30,7,STONE:3)
Block(-5,30,8,STONE:3)
Block(-5,31,-7,OBSIDIAN:0)
Block(-5,31,-6,OBSIDIAN:0)
Block(-5,31,-5,OBSIDIAN:0)
Block(-5,31,-4,OBSIDIAN:0)
Block(-5,31,-3,STONE:5)
Block(-5,31,-2,STONE:5)
Block(-5,31,-1,STONE:3)
Block(-5,31,0,GRASS:0)
Block(-5,31,1,STATIONARY_WATER:0)
Block(-5,31,2,STONE:3)
Block(-5,31,3,STONE:3)
Block(-5,31,4,STONE:3)
Block(-5,31,5,STONE:3)
Block(-5,31,6,STONE:3)
Block(-5,31,7,STONE:3)
Block(-5,31,8,STONE:3)
Block(-5,32,-7,OBSIDIAN:0)
Block(-5,32,-6,OBSIDIAN:0)
Block(-5,32,-5,OBSIDIAN:0)
Block(-5,32,-4,STONE:5)
Block(-5,32,-3,STONE:5)
Block(-5,32,-2,STONE:3)
Block(-5,32,-1,GRASS:0)
Block(-5,32,0,STATIONARY_WATER:0)
Block(-5,32,1,STATIONARY_WATER:0)
Block(-5,32,2,STATIONARY_WATER:0)
Block(-5,32,3,STATIONARY_WATER:0)
Block(-5,32,4,STONE:3)
Block(-5,32,5,STONE:3)
Block(-5,32,6,STONE:3)
Block(-5,32,7,OBSIDIAN:0)
Block(-5,32,8,OBSIDIAN:0)
Block(-5,33,-7,OBSIDIAN:0)
Block(-5,33,-6,OBSIDIAN:0)
Block(-5,33,-5,STONE:5)
Block(-5,33,-4,STONE:5)
Block(-5,33,-3,STONE:5)
Block(-5,33,-2,GRASS:0)
Block(-5,33,-1,STATIONARY_WATER:0)
Block(-5,33,0,STATIONARY_WATER:0)
Block(-5,33,1,STATIONARY_WATER:0)
Block(-5,33,2,STATIONARY_WATER:0)
Block(-5,33,3,STATIONARY_WATER:0)
Block(-5,33,4,STONE:3)
Block(-5,33,5,STONE:3)
Block(-5,33,6,STONE:5)
Block(-5,33,7,STONE:5)
Block(-5,33,8,OBSIDIAN:0)
Block(-5,34,-7,STONE:3)
Block(-5,34,-6,STONE:3)
Block(-5,34,-5,STONE:3)
Block(-5,34,-4,STONE:5)
Block(-5,34,-3,GRASS:0)
Block(-5,34,4,STONE:3)
Block(-5,34,5,STONE:5)
Block(-5,34,6,STONE:5)
Block(-5,34,7,STONE:5)
Block(-5,34,8,STONE:5)
Block(-5,35,-7,STONE:3)
Block(-5,35,-6,STONE:3)
Block(-5,35,-5,STONE:3)
Block(-5,35,-4,STONE:5)
Block(-5,35,4,STONE:5)
Block(-5,35,5,STONE:5)
Block(-5,35,6,STONE:5)
Block(-5,35,7,STONE:5)
Block(-5,35,8,STONE:5)
Block(-5,36,-7,STONE:3)
Block(-5,36,-6,STONE:3)
Block(-5,36,-5,STONE:3)
Block(-5,36,-4,GRASS:0)
Block(-5,36,7,STONE:5)
Block(-5,36,8,STONE:5)
Block(-5,37,-7,GRASS:0)
Block(-5,37,-6,GRASS:0)
Block(-5,37,-5,GRASS:0)
Block(-5,37,7,STONE:5)
Block(-5,37,8,OBSIDIAN:0)
Block(-5,38,7,OBSIDIAN:0)
Block(-5,38,8,OBSIDIAN:0)
Block(-5,39,7,OBSIDIAN:0)
Block(-5,39,8,OBSIDIAN:0)
Block(-5,72,8,OBSIDIAN:0)
Block(-5,73,4,OBSIDIAN:0)
Block(-5,73,7,OBSIDIAN:0)
Block(-5,73,8,OBSIDIAN:0)
Block(-5,74,3,OBSIDIAN:0)
Block(-5,74,4,OBSIDIAN:0)
Block(-5,74,5,OBSIDIAN:0)
Block(-5,74,6,OBSIDIAN:0)
Block(-5,74,7,OBSIDIAN:0)
Block(-5,74,8,OBSIDIAN:0)
Block(-5,75,2,OBSIDIAN:0)
Block(-5,75,3,OBSIDIAN:0)
Block(-5,75,4,OBSIDIAN:0)
Block(-5,75,5,OBSIDIAN:0)
Block(-5,75,6,OBSIDIAN:0)
Block(-5,75,7,OBSIDIAN:0)
Block(-5,75,8,OBSIDIAN:0)
Block(-5,76,1,OBSIDIAN:0)
Block(-5,76,2,OBSIDIAN:0)
Block(-5,76,3,OBSIDIAN:0)
Block(-5,76,4,OBSIDIAN:0)
Block(-5,76,5,OBSIDIAN:0)
Block(-5,76,6,OBSIDIAN:0)
Block(-5,76,7,OBSIDIAN:0)
Block(-5,76,8,OBSIDIAN:0)
Block(-5,77,0,OBSIDIAN:0)
Block(-5,77,1,OBSIDIAN:0)
Block(-5,77,2,OBSIDIAN:0)
Block(-5,77,3,OBSIDIAN:0)
Block(-5,77,4,OBSIDIAN:0)
Block(-5,77,5,OBSIDIAN:0)
Block(-5,77,6,OBSIDIAN:0)
Block(-5,77,7,OBSIDIAN:0)
Block(-5,77,8,OBSIDIAN:0)
Block(-5,78,-2,OBSIDIAN:0)
Block(-5,78,-1,OBSIDIAN:0)
Block(-5,78,0,OBSIDIAN:0)
Block(-5,78,1,OBSIDIAN:0)
Block(-5,78,2,OBSIDIAN:0)
Block(-5,78,3,OBSIDIAN:0)
Block(-5,78,4,OBSIDIAN:0)
Block(-5,78,5,OBSIDIAN:0)
Block(-5,78,6,OBSIDIAN:0)
Block(-5,78,7,OBSIDIAN:0)
Block(-5,78,8,OBSIDIAN:0)
Block(-5,79,-3,OBSIDIAN:0)
Block(-5,79,-2,OBSIDIAN:0)
Block(-5,79,-1,OBSIDIAN:0)
Block(-5,79,0,OBSIDIAN:0)
Block(-5,79,1,OBSIDIAN:0)
Block(-5,79,2,OBSIDIAN:0)
Block(-5,79,3,OBSIDIAN:0)
Block(-5,79,4,OBSIDIAN:0)
Block(-5,79,5,OBSIDIAN:0)
Block(-5,79,6,OBSIDIAN:0)
Block(-5,79,7,OBSIDIAN:0)
Block(-5,79,8,OBSIDIAN:0)
Block(-5,80,-7,OBSIDIAN:0)
Block(-5,80,-4,OBSIDIAN:0)
Block(-5,80,-3,OBSIDIAN:0)
Block(-5,80,-2,OBSIDIAN:0)
Block(-5,80,-1,OBSIDIAN:0)
Block(-5,80,0,OBSIDIAN:0)
Block(-5,80,1,OBSIDIAN:0)
Block(-5,80,2,OBSIDIAN:0)
Block(-5,80,3,OBSIDIAN:0)
Block(-5,80,4,OBSIDIAN:0)
Block(-5,80,5,OBSIDIAN:0)
Block(-5,80,6,OBSIDIAN:0)
Block(-5,80,7,OBSIDIAN:0)
Block(-5,80,8,OBSIDIAN:0)
Block(-5,81,-7,OBSIDIAN:0)
Block(-5,81,-6,OBSIDIAN:0)
Block(-5,81,-5,OBSIDIAN:0)
Block(-5,81,-4,OBSIDIAN:0)
Block(-5,81,-3,OBSIDIAN:0)
Block(-5,81,-2,OBSIDIAN:0)
Block(-5,81,-1,OBSIDIAN:0)
Block(-5,81,0,OBSIDIAN:0)
Block(-5,81,1,OBSIDIAN:0)
Block(-5,81,2,OBSIDIAN:0)
Block(-5,81,3,OBSIDIAN:0)
Block(-5,81,4,OBSIDIAN:0)
Block(-5,81,5,OBSIDIAN:0)
Block(-5,81,6,OBSIDIAN:0)
Block(-5,81,7,OBSIDIAN:0)
Block(-5,81,8,OBSIDIAN:0)
Block(-5,82,-7,OBSIDIAN:0)
Block(-5,82,-6,OBSIDIAN:0)
Block(-5,82,-5,OBSIDIAN:0)
Block(-5,82,-4,OBSIDIAN:0)
Block(-5,82,-3,OBSIDIAN:0)
Block(-5,82,-2,OBSIDIAN:0)
Block(-5,82,-1,OBSIDIAN:0)
Block(-5,82,0,OBSIDIAN:0)
Block(-5,82,1,OBSIDIAN:0)
Block(-5,82,2,OBSIDIAN:0)
Block(-5,82,3,OBSIDIAN:0)
Block(-5,82,4,OBSIDIAN:0)
Block(-5,82,5,OBSIDIAN:0)
Block(-5,82,6,OBSIDIAN:0)
Block(-5,82,7,OBSIDIAN:0)
Block(-5,82,8,OBSIDIAN:0)
Block(-5,83,-7,OBSIDIAN:0)
Block(-5,83,-6,OBSIDIAN:0)
Block(-5,83,-5,OBSIDIAN:0)
Block(-5,83,-4,OBSIDIAN:0)
Block(-5,83,-3,OBSIDIAN:0)
Block(-5,83,-2,OBSIDIAN:0)
Block(-5,83,-1,OBSIDIAN:0)
Block(-5,83,0,OBSIDIAN:0)
Block(-5,83,1,OBSIDIAN:0)
Block(-5,83,2,OBSIDIAN:0)
Block(-5,83,3,OBSIDIAN:0)
Block(-5,83,4,OBSIDIAN:0)
Block(-5,83,5,OBSIDIAN:0)
Block(-5,83,6,OBSIDIAN:0)
Block(-5,83,7,OBSIDIAN:0)
Block(-5,83,8,OBSIDIAN:0)
Block(-5,84,-7,OBSIDIAN:0)
Block(-5,84,-6,OBSIDIAN:0)
Block(-5,84,-5,OBSIDIAN:0)
Block(-5,84,-4,OBSIDIAN:0)
Block(-5,84,-3,OBSIDIAN:0)
Block(-5,84,-2,OBSIDIAN:0)
Block(-5,84,-1,OBSIDIAN:0)
Block(-5,84,0,OBSIDIAN:0)
Block(-5,84,1,OBSIDIAN:0)
Block(-5,84,2,OBSIDIAN:0)
Block(-5,84,3,OBSIDIAN:0)
Block(-5,84,4,OBSIDIAN:0)
Block(-5,84,5,OBSIDIAN:0)
Block(-5,84,6,OBSIDIAN:0)
Block(-5,84,7,OBSIDIAN:0)
Block(-5,84,8,OBSIDIAN:0)
Block(-5,85,-7,OBSIDIAN:0)
Block(-5,85,-6,OBSIDIAN:0)
Block(-5,85,-5,OBSIDIAN:0)
Block(-5,85,-4,OBSIDIAN:0)
Block(-5,85,-3,OBSIDIAN:0)
Block(-5,85,-2,OBSIDIAN:0)
Block(-5,85,-1,OBSIDIAN:0)
Block(-5,85,0,OBSIDIAN:0)
Block(-5,85,1,OBSIDIAN:0)
Block(-5,85,2,OBSIDIAN:0)
Block(-5,85,3,OBSIDIAN:0)
Block(-5,85,4,OBSIDIAN:0)
Block(-5,85,5,OBSIDIAN:0)
Block(-5,85,6,OBSIDIAN:0)
Block(-5,85,7,OBSIDIAN:0)
Block(-5,85,8,OBSIDIAN:0)
Block(-5,86,-7,OBSIDIAN:0)
Block(-5,86,-6,OBSIDIAN:0)
Block(-5,86,-5,OBSIDIAN:0)
Block(-5,86,-4,OBSIDIAN:0)
Block(-5,86,-3,OBSIDIAN:0)
Block(-5,86,-2,OBSIDIAN:0)
Block(-5,86,-1,OBSIDIAN:0)
Block(-5,86,0,OBSIDIAN:0)
Block(-5,86,1,OBSIDIAN:0)
Block(-5,86,2,OBSIDIAN:0)
Block(-5,86,3,OBSIDIAN:0)
Block(-5,86,4,OBSIDIAN:0)
Block(-5,86,5,OBSIDIAN:0)
Block(-5,86,6,OBSIDIAN:0)
Block(-5,86,7,OBSIDIAN:0)
Block(-5,86,8,OBSIDIAN:0)
Block(-5,87,-7,OBSIDIAN:0)
Block(-5,87,-6,OBSIDIAN:0)
Block(-5,87,-5,OBSIDIAN:0)
Block(-5,87,-4,OBSIDIAN:0)
Block(-5,87,-3,OBSIDIAN:0)
Block(-5,87,-2,OBSIDIAN:0)
Block(-5,87,-1,OBSIDIAN:0)
Block(-5,87,0,OBSIDIAN:0)
Block(-5,87,1,OBSIDIAN:0)
Block(-5,87,2,OBSIDIAN:0)
Block(-5,87,3,OBSIDIAN:0)
Block(-5,87,4,OBSIDIAN:0)
Block(-5,87,5,OBSIDIAN:0)
Block(-5,87,6,OBSIDIAN:0)
Block(-5,87,7,OBSIDIAN:0)
Block(-5,87,8,OBSIDIAN:0)
Block(-5,88,-7,OBSIDIAN:0)
Block(-5,88,-6,OBSIDIAN:0)
Block(-5,88,-5,OBSIDIAN:0)
Block(-5,88,-4,OBSIDIAN:0)
Block(-5,88,-3,OBSIDIAN:0)
Block(-5,88,-2,OBSIDIAN:0)
Block(-5,88,-1,OBSIDIAN:0)
Block(-5,88,0,OBSIDIAN:0)
Block(-5,88,1,OBSIDIAN:0)
Block(-5,88,2,OBSIDIAN:0)
Block(-5,88,3,OBSIDIAN:0)
Block(-5,88,4,OBSIDIAN:0)
Block(-5,88,5,OBSIDIAN:0)
Block(-5,88,6,OBSIDIAN:0)
Block(-5,88,7,OBSIDIAN:0)
Block(-5,88,8,OBSIDIAN:0)
Block(-5,89,-7,OBSIDIAN:0)
Block(-5,89,-6,OBSIDIAN:0)
Block(-5,89,-5,OBSIDIAN:0)
Block(-5,89,-4,OBSIDIAN:0)
Block(-5,89,-3,OBSIDIAN:0)
Block(-5,89,-2,OBSIDIAN:0)
Block(-5,89,-1,OBSIDIAN:0)
Block(-5,89,0,OBSIDIAN:0)
Block(-5,89,1,OBSIDIAN:0)
Block(-5,89,2,OBSIDIAN:0)
Block(-5,89,3,OBSIDIAN:0)
Block(-5,89,4,OBSIDIAN:0)
Block(-5,89,5,OBSIDIAN:0)
Block(-5,89,6,OBSIDIAN:0)
Block(-5,89,7,OBSIDIAN:0)
Block(-5,89,8,STONE:3)
Block(-5,90,-7,OBSIDIAN:0)
Block(-5,90,-6,OBSIDIAN:0)
Block(-5,90,-5,OBSIDIAN:0)
Block(-5,90,-4,STONE:3)
Block(-5,90,-3,STONE:3)
Block(-5,90,-2,OBSIDIAN:0)
Block(-5,90,-1,OBSIDIAN:0)
Block(-5,90,0,OBSIDIAN:0)
Block(-5,90,1,OBSIDIAN:0)
Block(-5,90,2,OBSIDIAN:0)
Block(-5,90,3,OBSIDIAN:0)
Block(-5,90,4,OBSIDIAN:0)
Block(-5,90,5,OBSIDIAN:0)
Block(-5,90,6,OBSIDIAN:0)
Block(-5,90,7,STONE:3)
Block(-5,90,8,STONE:3)
Block(-5,91,-7,OBSIDIAN:0)
Block(-5,91,-6,STONE:3)
Block(-5,91,-5,STONE:3)
Block(-5,91,-4,OBSIDIAN:0)
Block(-5,91,-3,OBSIDIAN:0)
Block(-5,91,-2,OBSIDIAN:0)
Block(-5,91,-1,OBSIDIAN:0)
Block(-5,91,0,MAGMA:0)
Block(-5,91,1,MAGMA:0)
Block(-5,91,2,MAGMA:0)
Block(-5,91,3,OBSIDIAN:0)
Block(-5,91,4,OBSIDIAN:0)
Block(-5,91,5,OBSIDIAN:0)
Block(-5,91,6,OBSIDIAN:0)
Block(-5,91,7,OBSIDIAN:0)
Block(-5,92,-7,STONE:3)
Block(-5,92,-6,STONE:3)
Block(-5,92,-5,OBSIDIAN:0)
Block(-5,92,-4,OBSIDIAN:0)
Block(-5,92,-3,OBSIDIAN:0)
Block(-5,92,-2,OBSIDIAN:0)
Block(-5,92,-1,MAGMA:0)
Block(-5,92,0,MAGMA:0)
Block(-5,92,1,MAGMA:0)
Block(-5,92,2,MAGMA:0)
Block(-5,92,3,MAGMA:0)
Block(-5,92,4,OBSIDIAN:0)
Block(-5,92,5,OBSIDIAN:0)
Block(-5,93,-7,STONE:3)
Block(-5,93,-6,OBSIDIAN:0)
Block(-5,93,-5,OBSIDIAN:0)
Block(-5,93,-4,OBSIDIAN:0)
Block(-5,93,-3,OBSIDIAN:0)
Block(-5,93,-2,OBSIDIAN:0)
Block(-5,93,-1,MAGMA:0)
Block(-5,93,0,MAGMA:0)
Block(-5,93,1,MAGMA:0)
Block(-5,93,2,MAGMA:0)
Block(-5,94,-7,OBSIDIAN:0)
Block(-5,94,-6,OBSIDIAN:0)
Block(-5,94,-5,OBSIDIAN:0)
Block(-5,94,-4,OBSIDIAN:0)
Block(-5,94,-3,MAGMA:0)
Block(-5,94,-2,MAGMA:0)
Block(-5,94,-1,MAGMA:0)
Block(-5,94,0,MAGMA:0)
Block(-5,94,1,MAGMA:0)
Block(-5,95,-7,OBSIDIAN:0)
Block(-5,95,-6,OBSIDIAN:0)
Block(-5,95,-5,OBSIDIAN:0)
Block(-5,95,-4,OBSIDIAN:0)
Block(-5,95,-3,MAGMA:0)
Block(-5,95,-2,MAGMA:0)
Block(-5,95,-1,MAGMA:0)
Block(-5,95,0,MAGMA:0)
Block(-5,96,-7,OBSIDIAN:0)
Block(-5,96,-6,OBSIDIAN:0)
Block(-5,96,-5,OBSIDIAN:0)
Block(-5,96,-4,OBSIDIAN:0)
Block(-5,96,-3,MAGMA:0)
Block(-5,96,-2,MAGMA:0)
Block(-5,96,-1,MAGMA:0)
Block(-5,97,-7,OBSIDIAN:0)
Block(-5,97,-6,OBSIDIAN:0)
Block(-5,97,-5,OBSIDIAN:0)
Block(-5,97,-4,OBSIDIAN:0)
Block(-5,97,-3,OBSIDIAN:0)
Block(-5,97,-2,OBSIDIAN:0)
Block(-5,97,-1,MAGMA:0)
Block(-5,98,-7,OBSIDIAN:0)
Block(-5,98,-6,OBSIDIAN:0)
Block(-5,98,-5,OBSIDIAN:0)
Block(-5,98,-4,OBSIDIAN:0)
Block(-5,98,-3,OBSIDIAN:0)
Block(-5,98,-2,OBSIDIAN:0)
Block(-5,99,-7,OBSIDIAN:0)
Block(-5,99,-6,OBSIDIAN:0)
Block(-5,99,-5,OBSIDIAN:0)
Block(-5,99,-4,OBSIDIAN:0)
Block(-5,99,-3,OBSIDIAN:0)
Block(-5,99,-2,OBSIDIAN:0)
Block(-5,100,-7,OBSIDIAN:0)
Block(-5,100,-6,OBSIDIAN:0)
Block(-5,100,-5,OBSIDIAN:0)
Block(-4,22,-7,STONE:3)
Block(-4,23,-7,STONE:3)
Block(-4,23,-6,STONE:3)
Block(-4,23,-5,STONE:3)
Block(-4,23,-4,STONE:3)
Block(-4,24,-7,STONE:3)
Block(-4,24,-6,STONE:3)
Block(-4,24,-5,STONE:3)
Block(-4,24,-4,STONE:3)
Block(-4,24,-3,STONE:3)
Block(-4,25,-7,STONE:3)
Block(-4,25,-6,STONE:3)
Block(-4,25,-5,STONE:3)
Block(-4,25,-4,STONE:3)
Block(-4,25,-3,STONE:3)
Block(-4,25,-2,STONE:3)
Block(-4,25,-1,STONE:3)
Block(-4,26,-7,STONE:3)
Block(-4,26,-6,STONE:3)
Block(-4,26,-5,STONE:3)
Block(-4,26,-4,STONE:3)
Block(-4,26,-3,STONE:3)
Block(-4,26,-2,STONE:3)
Block(-4,26,-1,STONE:3)
Block(-4,26,0,STONE:3)
Block(-4,26,1,STONE:3)
Block(-4,26,2,STONE:3)
Block(-4,26,3,STONE:3)
Block(-4,27,-7,STONE:3)
Block(-4,27,-6,STONE:3)
Block(-4,27,-5,STONE:3)
Block(-4,27,-4,STONE:3)
Block(-4,27,-3,STONE:3)
Block(-4,27,-2,STONE:3)
Block(-4,27,-1,STONE:3)
Block(-4,27,0,STONE:3)
Block(-4,27,1,STONE:3)
Block(-4,27,2,STONE:3)
Block(-4,27,3,STONE:3)
Block(-4,27,4,STONE:3)
Block(-4,27,5,STONE:3)
Block(-4,28,-7,OBSIDIAN:0)
Block(-4,28,-6,OBSIDIAN:0)
Block(-4,28,-5,STONE:3)
Block(-4,28,-4,STONE:3)
Block(-4,28,-3,STONE:3)
Block(-4,28,-2,STONE:3)
Block(-4,28,-1,STONE:3)
Block(-4,28,0,STONE:3)
Block(-4,28,1,STONE:3)
Block(-4,28,2,OBSIDIAN:0)
Block(-4,28,3,OBSIDIAN:0)
Block(-4,28,4,OBSIDIAN:0)
Block(-4,28,5,STONE:3)
Block(-4,28,6,STONE:3)
Block(-4,29,-7,OBSIDIAN:0)
Block(-4,29,-6,OBSIDIAN:0)
Block(-4,29,-5,OBSIDIAN:0)
Block(-4,29,-4,STONE:3)
Block(-4,29,-3,STONE:3)
Block(-4,29,-2,STONE:3)
Block(-4,29,-1,STONE:3)
Block(-4,29,0,STONE:3)
Block(-4,29,1,STONE:5)
Block(-4,29,2,OBSIDIAN:0)
Block(-4,29,3,STONE:3)
Block(-4,29,4,STONE:3)
Block(-4,29,5,STONE:3)
Block(-4,29,6,STONE:3)
Block(-4,29,7,STONE:3)
Block(-4,29,8,STONE:3)
Block(-4,30,-7,OBSIDIAN:0)
Block(-4,30,-6,OBSIDIAN:0)
Block(-4,30,-5,OBSIDIAN:0)
Block(-4,30,-4,OBSIDIAN:0)
Block(-4,30,-3,OBSIDIAN:0)
Block(-4,30,-2,STONE:5)
Block(-4,30,-1,STONE:5)
Block(-4,30,0,STONE:3)
Block(-4,30,1,STONE:3)
Block(-4,30,2,STONE:3)
Block(-4,30,3,STONE:3)
Block(-4,30,4,STONE:3)
Block(-4,30,5,STONE:3)
Block(-4,30,6,STONE:3)
Block(-4,30,7,STONE:3)
Block(-4,30,8,STONE:3)
Block(-4,31,-7,OBSIDIAN:0)
Block(-4,31,-6,OBSIDIAN:0)
Block(-4,31,-5,OBSIDIAN:0)
Block(-4,31,-4,OBSIDIAN:0)
Block(-4,31,-3,STONE:5)
Block(-4,31,-2,STONE:3)
Block(-4,31,-1,STONE:3)
Block(-4,31,0,GRASS:0)
Block(-4,31,1,GRASS:0)
Block(-4,31,2,GRASS:0)
Block(-4,31,3,STONE:3)
Block(-4,31,4,STONE:3)
Block(-4,31,5,STONE:3)
Block(-4,31,6,STONE:3)
Block(-4,31,7,STONE:3)
Block(-4,31,8,STONE:3)
Block(-4,32,-7,OBSIDIAN:0)
Block(-4,32,-6,OBSIDIAN:0)
Block(-4,32,-5,OBSIDIAN:0)
Block(-4,32,-4,STONE:5)
Block(-4,32,-3,STONE:5)
Block(-4,32,-2,STONE:3)
Block(-4,32,-1,GRASS:0)
Block(-4,32,0,STATIONARY_WATER:0)
Block(-4,32,1,STATIONARY_WATER:0)
Block(-4,32,2,STATIONARY_WATER:0)
Block(-4,32,3,STONE:3)
Block(-4,32,4,STONE:3)
Block(-4,32,5,STONE:3)
Block(-4,32,6,STONE:3)
Block(-4,32,7,OBSIDIAN:0)
Block(-4,32,8,STONE:3)
Block(-4,33,-7,OBSIDIAN:0)
Block(-4,33,-6,OBSIDIAN:0)
Block(-4,33,-5,OBSIDIAN:0)
Block(-4,33,-4,STONE:5)
Block(-4,33,-3,STONE:3)
Block(-4,33,-2,GRASS:0)
Block(-4,33,-1,STATIONARY_WATER:0)
Block(-4,33,0,STATIONARY_WATER:0)
Block(-4,33,1,STATIONARY_WATER:0)
Block(-4,33,2,STATIONARY_WATER:0)
Block(-4,33,3,STATIONARY_WATER:0)
Block(-4,33,4,STONE:3)
Block(-4,33,5,STONE:3)
Block(-4,33,6,STONE:5)
Block(-4,33,7,STONE:5)
Block(-4,33,8,OBSIDIAN:0)
Block(-4,34,-7,STONE:5)
Block(-4,34,-6,STONE:5)
Block(-4,34,-5,STONE:5)
Block(-4,34,-4,STONE:5)
Block(-4,34,-3,GRASS:0)
Block(-4,34,4,STONE:3)
Block(-4,34,5,STONE:5)
Block(-4,34,6,STONE:5)
Block(-4,34,7,STONE:5)
Block(-4,34,8,STONE:5)
Block(-4,35,-7,STONE:5)
Block(-4,35,-6,STONE:5)
Block(-4,35,-5,STONE:5)
Block(-4,35,-4,GRASS:0)
Block(-4,35,5,STONE:5)
Block(-4,35,6,STONE:5)
Block(-4,35,7,STONE:5)
Block(-4,35,8,STONE:5)
Block(-4,36,-7,STONE:5)
Block(-4,36,-6,STONE:5)
Block(-4,36,-5,STONE:5)
Block(-4,36,7,STONE:5)
Block(-4,36,8,STONE:5)
Block(-4,37,-7,STONE:5)
Block(-4,37,-6,GRASS:0)
Block(-4,37,-5,GRASS:0)
Block(-4,37,7,STONE:5)
Block(-4,37,8,OBSIDIAN:0)
Block(-4,38,-7,STONE:5)
Block(-4,38,7,OBSIDIAN:0)
Block(-4,38,8,OBSIDIAN:0)
Block(-4,39,8,OBSIDIAN:0)
Block(-4,73,7,OBSIDIAN:0)
Block(-4,73,8,OBSIDIAN:0)
Block(-4,74,4,OBSIDIAN:0)
Block(-4,74,6,OBSIDIAN:0)
Block(-4,74,7,OBSIDIAN:0)
Block(-4,74,8,OBSIDIAN:0)
Block(-4,75,3,OBSIDIAN:0)
Block(-4,75,4,OBSIDIAN:0)
Block(-4,75,5,OBSIDIAN:0)
Block(-4,75,6,OBSIDIAN:0)
Block(-4,75,7,OBSIDIAN:0)
Block(-4,75,8,OBSIDIAN:0)
Block(-4,76,2,OBSIDIAN:0)
Block(-4,76,3,OBSIDIAN:0)
Block(-4,76,4,OBSIDIAN:0)
Block(-4,76,5,OBSIDIAN:0)
Block(-4,76,6,OBSIDIAN:0)
Block(-4,76,7,OBSIDIAN:0)
Block(-4,76,8,OBSIDIAN:0)
Block(-4,77,-1,OBSIDIAN:0)
Block(-4,77,0,OBSIDIAN:0)
Block(-4,77,1,OBSIDIAN:0)
Block(-4,77,2,OBSIDIAN:0)
Block(-4,77,3,OBSIDIAN:0)
Block(-4,77,4,OBSIDIAN:0)
Block(-4,77,5,OBSIDIAN:0)
Block(-4,77,6,OBSIDIAN:0)
Block(-4,77,7,OBSIDIAN:0)
Block(-4,77,8,OBSIDIAN:0)
Block(-4,78,-1,OBSIDIAN:0)
Block(-4,78,0,OBSIDIAN:0)
Block(-4,78,1,OBSIDIAN:0)
Block(-4,78,2,OBSIDIAN:0)
Block(-4,78,3,OBSIDIAN:0)
Block(-4,78,4,OBSIDIAN:0)
Block(-4,78,5,OBSIDIAN:0)
Block(-4,78,6,OBSIDIAN:0)
Block(-4,78,7,OBSIDIAN:0)
Block(-4,78,8,OBSIDIAN:0)
Block(-4,79,-2,OBSIDIAN:0)
Block(-4,79,-1,OBSIDIAN:0)
Block(-4,79,0,OBSIDIAN:0)
Block(-4,79,1,OBSIDIAN:0)
Block(-4,79,2,OBSIDIAN:0)
Block(-4,79,3,OBSIDIAN:0)
Block(-4,79,4,OBSIDIAN:0)
Block(-4,79,5,OBSIDIAN:0)
Block(-4,79,6,OBSIDIAN:0)
Block(-4,79,7,OBSIDIAN:0)
Block(-4,79,8,OBSIDIAN:0)
Block(-4,80,-7,OBSIDIAN:0)
Block(-4,80,-6,OBSIDIAN:0)
Block(-4,80,-5,OBSIDIAN:0)
Block(-4,80,-4,OBSIDIAN:0)
Block(-4,80,-3,OBSIDIAN:0)
Block(-4,80,-2,OBSIDIAN:0)
Block(-4,80,-1,OBSIDIAN:0)
Block(-4,80,0,OBSIDIAN:0)
Block(-4,80,1,OBSIDIAN:0)
Block(-4,80,2,OBSIDIAN:0)
Block(-4,80,3,OBSIDIAN:0)
Block(-4,80,4,OBSIDIAN:0)
Block(-4,80,5,OBSIDIAN:0)
Block(-4,80,6,OBSIDIAN:0)
Block(-4,80,7,OBSIDIAN:0)
Block(-4,80,8,OBSIDIAN:0)
Block(-4,81,-7,OBSIDIAN:0)
Block(-4,81,-6,OBSIDIAN:0)
Block(-4,81,-5,OBSIDIAN:0)
Block(-4,81,-4,OBSIDIAN:0)
Block(-4,81,-3,OBSIDIAN:0)
Block(-4,81,-2,OBSIDIAN:0)
Block(-4,81,-1,OBSIDIAN:0)
Block(-4,81,0,OBSIDIAN:0)
Block(-4,81,1,OBSIDIAN:0)
Block(-4,81,2,OBSIDIAN:0)
Block(-4,81,3,OBSIDIAN:0)
Block(-4,81,4,OBSIDIAN:0)
Block(-4,81,5,OBSIDIAN:0)
Block(-4,81,6,OBSIDIAN:0)
Block(-4,81,7,OBSIDIAN:0)
Block(-4,81,8,OBSIDIAN:0)
Block(-4,82,-7,OBSIDIAN:0)
Block(-4,82,-6,OBSIDIAN:0)
Block(-4,82,-5,OBSIDIAN:0)
Block(-4,82,-4,OBSIDIAN:0)
Block(-4,82,-3,OBSIDIAN:0)
Block(-4,82,-2,OBSIDIAN:0)
Block(-4,82,-1,OBSIDIAN:0)
Block(-4,82,0,OBSIDIAN:0)
Block(-4,82,1,OBSIDIAN:0)
Block(-4,82,2,OBSIDIAN:0)
Block(-4,82,3,OBSIDIAN:0)
Block(-4,82,4,OBSIDIAN:0)
Block(-4,82,5,OBSIDIAN:0)
Block(-4,82,6,OBSIDIAN:0)
Block(-4,82,7,OBSIDIAN:0)
Block(-4,82,8,OBSIDIAN:0)
Block(-4,83,-7,OBSIDIAN:0)
Block(-4,83,-6,OBSIDIAN:0)
Block(-4,83,-5,OBSIDIAN:0)
Block(-4,83,-4,OBSIDIAN:0)
Block(-4,83,-3,OBSIDIAN:0)
Block(-4,83,-2,OBSIDIAN:0)
Block(-4,83,-1,OBSIDIAN:0)
Block(-4,83,0,OBSIDIAN:0)
Block(-4,83,1,OBSIDIAN:0)
Block(-4,83,2,OBSIDIAN:0)
Block(-4,83,3,OBSIDIAN:0)
Block(-4,83,4,OBSIDIAN:0)
Block(-4,83,5,OBSIDIAN:0)
Block(-4,83,6,OBSIDIAN:0)
Block(-4,83,7,OBSIDIAN:0)
Block(-4,83,8,OBSIDIAN:0)
Block(-4,84,-7,OBSIDIAN:0)
Block(-4,84,-6,OBSIDIAN:0)
Block(-4,84,-5,OBSIDIAN:0)
Block(-4,84,-4,OBSIDIAN:0)
Block(-4,84,-3,OBSIDIAN:0)
Block(-4,84,-2,OBSIDIAN:0)
Block(-4,84,-1,OBSIDIAN:0)
Block(-4,84,0,OBSIDIAN:0)
Block(-4,84,1,OBSIDIAN:0)
Block(-4,84,2,OBSIDIAN:0)
Block(-4,84,3,OBSIDIAN:0)
Block(-4,84,4,OBSIDIAN:0)
Block(-4,84,5,OBSIDIAN:0)
Block(-4,84,6,OBSIDIAN:0)
Block(-4,84,7,OBSIDIAN:0)
Block(-4,84,8,OBSIDIAN:0)
Block(-4,85,-7,OBSIDIAN:0)
Block(-4,85,-6,OBSIDIAN:0)
Block(-4,85,-5,OBSIDIAN:0)
Block(-4,85,-4,OBSIDIAN:0)
Block(-4,85,-3,OBSIDIAN:0)
Block(-4,85,-2,OBSIDIAN:0)
Block(-4,85,-1,OBSIDIAN:0)
Block(-4,85,0,OBSIDIAN:0)
Block(-4,85,1,OBSIDIAN:0)
Block(-4,85,2,OBSIDIAN:0)
Block(-4,85,3,OBSIDIAN:0)
Block(-4,85,4,OBSIDIAN:0)
Block(-4,85,5,OBSIDIAN:0)
Block(-4,85,6,OBSIDIAN:0)
Block(-4,85,7,OBSIDIAN:0)
Block(-4,85,8,OBSIDIAN:0)
Block(-4,86,-7,OBSIDIAN:0)
Block(-4,86,-6,OBSIDIAN:0)
Block(-4,86,-5,OBSIDIAN:0)
Block(-4,86,-4,OBSIDIAN:0)
Block(-4,86,-3,OBSIDIAN:0)
Block(-4,86,-2,OBSIDIAN:0)
Block(-4,86,-1,OBSIDIAN:0)
Block(-4,86,0,OBSIDIAN:0)
Block(-4,86,1,OBSIDIAN:0)
Block(-4,86,2,OBSIDIAN:0)
Block(-4,86,3,OBSIDIAN:0)
Block(-4,86,4,OBSIDIAN:0)
Block(-4,86,5,OBSIDIAN:0)
Block(-4,86,6,OBSIDIAN:0)
Block(-4,86,7,OBSIDIAN:0)
Block(-4,86,8,OBSIDIAN:0)
Block(-4,87,-7,OBSIDIAN:0)
Block(-4,87,-6,OBSIDIAN:0)
Block(-4,87,-5,OBSIDIAN:0)
Block(-4,87,-4,OBSIDIAN:0)
Block(-4,87,-3,OBSIDIAN:0)
Block(-4,87,-2,OBSIDIAN:0)
Block(-4,87,-1,OBSIDIAN:0)
Block(-4,87,0,OBSIDIAN:0)
Block(-4,87,1,OBSIDIAN:0)
Block(-4,87,2,OBSIDIAN:0)
Block(-4,87,3,OBSIDIAN:0)
Block(-4,87,4,OBSIDIAN:0)
Block(-4,87,5,OBSIDIAN:0)
Block(-4,87,6,OBSIDIAN:0)
Block(-4,87,7,OBSIDIAN:0)
Block(-4,87,8,OBSIDIAN:0)
Block(-4,88,-7,OBSIDIAN:0)
Block(-4,88,-6,OBSIDIAN:0)
Block(-4,88,-5,OBSIDIAN:0)
Block(-4,88,-4,OBSIDIAN:0)
Block(-4,88,-3,OBSIDIAN:0)
Block(-4,88,-2,OBSIDIAN:0)
Block(-4,88,-1,OBSIDIAN:0)
Block(-4,88,0,OBSIDIAN:0)
Block(-4,88,1,OBSIDIAN:0)
Block(-4,88,2,OBSIDIAN:0)
Block(-4,88,3,OBSIDIAN:0)
Block(-4,88,4,OBSIDIAN:0)
Block(-4,88,5,OBSIDIAN:0)
Block(-4,88,6,OBSIDIAN:0)
Block(-4,88,7,OBSIDIAN:0)
Block(-4,88,8,OBSIDIAN:0)
Block(-4,89,-7,OBSIDIAN:0)
Block(-4,89,-6,OBSIDIAN:0)
Block(-4,89,-5,OBSIDIAN:0)
Block(-4,89,-4,OBSIDIAN:0)
Block(-4,89,-3,OBSIDIAN:0)
Block(-4,89,-2,OBSIDIAN:0)
Block(-4,89,-1,OBSIDIAN:0)
Block(-4,89,0,OBSIDIAN:0)
Block(-4,89,1,OBSIDIAN:0)
Block(-4,89,2,OBSIDIAN:0)
Block(-4,89,3,OBSIDIAN:0)
Block(-4,89,4,OBSIDIAN:0)
Block(-4,89,5,OBSIDIAN:0)
Block(-4,89,6,OBSIDIAN:0)
Block(-4,89,7,OBSIDIAN:0)
Block(-4,89,8,OBSIDIAN:0)
Block(-4,90,-7,OBSIDIAN:0)
Block(-4,90,-6,OBSIDIAN:0)
Block(-4,90,-5,OBSIDIAN:0)
Block(-4,90,-4,OBSIDIAN:0)
Block(-4,90,-3,OBSIDIAN:0)
Block(-4,90,-2,OBSIDIAN:0)
Block(-4,90,-1,OBSIDIAN:0)
Block(-4,90,0,OBSIDIAN:0)
Block(-4,90,1,OBSIDIAN:0)
Block(-4,90,2,OBSIDIAN:0)
Block(-4,90,3,OBSIDIAN:0)
Block(-4,90,4,OBSIDIAN:0)
Block(-4,90,5,OBSIDIAN:0)
Block(-4,90,6,OBSIDIAN:0)
Block(-4,90,7,OBSIDIAN:0)
Block(-4,90,8,OBSIDIAN:0)
Block(-4,91,-7,OBSIDIAN:0)
Block(-4,91,-6,OBSIDIAN:0)
Block(-4,91,-5,STONE:3)
Block(-4,91,-4,STONE:3)
Block(-4,91,-3,OBSIDIAN:0)
Block(-4,91,-2,OBSIDIAN:0)
Block(-4,91,-1,OBSIDIAN:0)
Block(-4,91,0,MAGMA:0)
Block(-4,91,1,MAGMA:0)
Block(-4,91,2,MAGMA:0)
Block(-4,91,3,MAGMA:0)
Block(-4,91,4,OBSIDIAN:0)
Block(-4,91,5,OBSIDIAN:0)
Block(-4,91,6,OBSIDIAN:0)
Block(-4,91,7,OBSIDIAN:0)
Block(-4,91,8,OBSIDIAN:0)
Block(-4,92,-7,OBSIDIAN:0)
Block(-4,92,-6,STONE:3)
Block(-4,92,-5,STONE:3)
Block(-4,92,-4,OBSIDIAN:0)
Block(-4,92,-3,OBSIDIAN:0)
Block(-4,92,-2,OBSIDIAN:0)
Block(-4,92,-1,MAGMA:0)
Block(-4,92,0,MAGMA:0)
Block(-4,92,1,MAGMA:0)
Block(-4,92,2,MAGMA:0)
Block(-4,92,3,MAGMA:0)
Block(-4,92,4,MAGMA:0)
Block(-4,92,5,OBSIDIAN:0)
Block(-4,93,-7,STONE:3)
Block(-4,93,-6,STONE:3)
Block(-4,93,-5,OBSIDIAN:0)
Block(-4,93,-4,OBSIDIAN:0)
Block(-4,93,-3,OBSIDIAN:0)
Block(-4,93,-2,OBSIDIAN:0)
Block(-4,93,-1,MAGMA:0)
Block(-4,93,0,MAGMA:0)
Block(-4,93,1,MAGMA:0)
Block(-4,93,2,MAGMA:0)
Block(-4,94,-7,OBSIDIAN:0)
Block(-4,94,-6,OBSIDIAN:0)
Block(-4,94,-5,OBSIDIAN:0)
Block(-4,94,-4,OBSIDIAN:0)
Block(-4,94,-3,OBSIDIAN:0)
Block(-4,94,-2,MAGMA:0)
Block(-4,94,-1,MAGMA:0)
Block(-4,94,0,MAGMA:0)
Block(-4,95,-7,OBSIDIAN:0)
Block(-4,95,-6,OBSIDIAN:0)
Block(-4,95,-5,OBSIDIAN:0)
Block(-4,95,-4,OBSIDIAN:0)
Block(-4,95,-3,OBSIDIAN:0)
Block(-4,95,-2,MAGMA:0)
Block(-4,95,-1,MAGMA:0)
Block(-4,96,-7,OBSIDIAN:0)
Block(-4,96,-6,OBSIDIAN:0)
Block(-4,96,-5,OBSIDIAN:0)
Block(-4,96,-4,OBSIDIAN:0)
Block(-4,96,-3,OBSIDIAN:0)
Block(-4,96,-2,MAGMA:0)
Block(-4,96,-1,MAGMA:0)
Block(-4,97,-7,OBSIDIAN:0)
Block(-4,97,-6,OBSIDIAN:0)
Block(-4,97,-5,OBSIDIAN:0)
Block(-4,97,-4,OBSIDIAN:0)
Block(-4,97,-3,OBSIDIAN:0)
Block(-4,97,-2,OBSIDIAN:0)
Block(-4,97,-1,MAGMA:0)
Block(-4,98,-7,OBSIDIAN:0)
Block(-4,98,-6,OBSIDIAN:0)
Block(-4,98,-5,OBSIDIAN:0)
Block(-4,98,-4,OBSIDIAN:0)
Block(-4,98,-3,OBSIDIAN:0)
Block(-4,98,-2,OBSIDIAN:0)
Block(-4,99,-7,OBSIDIAN:0)
Block(-4,99,-6,OBSIDIAN:0)
Block(-4,99,-5,OBSIDIAN:0)
Block(-4,99,-4,OBSIDIAN:0)
Block(-4,99,-3,OBSIDIAN:0)
Block(-4,99,-2,OBSIDIAN:0)
Block(-4,100,-7,OBSIDIAN:0)
Block(-4,100,-6,OBSIDIAN:0)
Block(-3,22,-7,STONE:3)
Block(-3,22,-6,STONE:3)
Block(-3,23,-7,STONE:3)
Block(-3,23,-6,STONE:3)
Block(-3,23,-5,STONE:3)
Block(-3,23,-4,STONE:3)
Block(-3,24,-7,STONE:3)
Block(-3,24,-6,STONE:3)
Block(-3,24,-5,STONE:3)
Block(-3,24,-4,STONE:3)
Block(-3,24,-3,STONE:3)
Block(-3,24,-2,STONE:3)
Block(-3,25,-7,STONE:3)
Block(-3,25,-6,STONE:3)
Block(-3,25,-5,STONE:3)
Block(-3,25,-4,STONE:3)
Block(-3,25,-3,STONE:3)
Block(-3,25,-2,STONE:3)
Block(-3,25,-1,STONE:3)
Block(-3,25,0,STONE:3)
Block(-3,26,-7,STONE:3)
Block(-3,26,-6,STONE:3)
Block(-3,26,-5,STONE:3)
Block(-3,26,-4,STONE:3)
Block(-3,26,-3,STONE:3)
Block(-3,26,-2,STONE:3)
Block(-3,26,-1,STONE:3)
Block(-3,26,0,STONE:3)
Block(-3,26,1,STONE:3)
Block(-3,26,2,STONE:3)
Block(-3,26,3,STONE:3)
Block(-3,27,-7,STONE:3)
Block(-3,27,-6,STONE:3)
Block(-3,27,-5,STONE:3)
Block(-3,27,-4,STONE:3)
Block(-3,27,-3,STONE:3)
Block(-3,27,-2,STONE:3)
Block(-3,27,-1,STONE:3)
Block(-3,27,0,STONE:3)
Block(-3,27,1,STONE:3)
Block(-3,27,2,STONE:3)
Block(-3,27,3,STONE:3)
Block(-3,27,4,STONE:3)
Block(-3,27,5,STONE:3)
Block(-3,27,6,STONE:3)
Block(-3,28,-7,OBSIDIAN:0)
Block(-3,28,-6,OBSIDIAN:0)
Block(-3,28,-5,STONE:3)
Block(-3,28,-4,STONE:3)
Block(-3,28,-3,STONE:3)
Block(-3,28,-2,STONE:3)
Block(-3,28,-1,STONE:3)
Block(-3,28,0,STONE:3)
Block(-3,28,1,STONE:3)
Block(-3,28,2,STONE:3)
Block(-3,28,3,STONE:3)
Block(-3,28,4,STONE:3)
Block(-3,28,5,STONE:3)
Block(-3,28,6,STONE:3)
Block(-3,28,7,STONE:3)
Block(-3,29,-7,OBSIDIAN:0)
Block(-3,29,-6,OBSIDIAN:0)
Block(-3,29,-5,OBSIDIAN:0)
Block(-3,29,-4,STONE:3)
Block(-3,29,-3,STONE:3)
Block(-3,29,-2,STONE:3)
Block(-3,29,-1,STONE:3)
Block(-3,29,0,STONE:3)
Block(-3,29,1,STONE:5)
Block(-3,29,2,OBSIDIAN:0)
Block(-3,29,3,OBSIDIAN:0)
Block(-3,29,4,OBSIDIAN:0)
Block(-3,29,5,OBSIDIAN:0)
Block(-3,29,6,STONE:3)
Block(-3,29,7,STONE:3)
Block(-3,29,8,STONE:3)
Block(-3,30,-7,OBSIDIAN:0)
Block(-3,30,-6,OBSIDIAN:0)
Block(-3,30,-5,OBSIDIAN:0)
Block(-3,30,-4,OBSIDIAN:0)
Block(-3,30,-3,OBSIDIAN:0)
Block(-3,30,-2,STONE:3)
Block(-3,30,-1,STONE:3)
Block(-3,30,0,STONE:3)
Block(-3,30,1,GRASS:0)
Block(-3,30,2,STONE:3)
Block(-3,30,3,STONE:3)
Block(-3,30,4,STONE:3)
Block(-3,30,5,STONE:3)
Block(-3,30,6,STONE:3)
Block(-3,30,7,STONE:3)
Block(-3,30,8,STONE:3)
Block(-3,31,-7,OBSIDIAN:0)
Block(-3,31,-6,OBSIDIAN:0)
Block(-3,31,-5,OBSIDIAN:0)
Block(-3,31,-4,OBSIDIAN:0)
Block(-3,31,-3,STONE:3)
Block(-3,31,-2,STONE:3)
Block(-3,31,-1,STONE:3)
Block(-3,31,0,GRASS:0)
Block(-3,31,1,STATIONARY_WATER:0)
Block(-3,31,2,GRASS:0)
Block(-3,31,3,STONE:3)
Block(-3,31,4,STONE:3)
Block(-3,31,5,STONE:3)
Block(-3,31,6,STONE:3)
Block(-3,31,7,STONE:3)
Block(-3,31,8,STONE:3)
Block(-3,32,-7,OBSIDIAN:0)
Block(-3,32,-6,OBSIDIAN:0)
Block(-3,32,-5,OBSIDIAN:0)
Block(-3,32,-4,OBSIDIAN:0)
Block(-3,32,-3,STONE:3)
Block(-3,32,-2,STONE:3)
Block(-3,32,-1,STATIONARY_WATER:0)
Block(-3,32,0,STATIONARY_WATER:0)
Block(-3,32,1,STATIONARY_WATER:0)
Block(-3,32,2,STATIONARY_WATER:0)
Block(-3,32,3,GRASS:0)
Block(-3,32,4,STONE:3)
Block(-3,32,5,STONE:3)
Block(-3,32,6,OBSIDIAN:0)
Block(-3,32,7,STONE:3)
Block(-3,32,8,STONE:3)
Block(-3,33,-7,OBSIDIAN:0)
Block(-3,33,-6,OBSIDIAN:0)
Block(-3,33,-5,OBSIDIAN:0)
Block(-3,33,-4,STONE:3)
Block(-3,33,-3,STONE:3)
Block(-3,33,-2,STATIONARY_WATER:0)
Block(-3,33,-1,STATIONARY_WATER:0)
Block(-3,33,0,STATIONARY_WATER:0)
Block(-3,33,1,STATIONARY_WATER:0)
Block(-3,33,2,STATIONARY_WATER:0)
Block(-3,33,3,STATIONARY_WATER:0)
Block(-3,33,4,STONE:3)
Block(-3,33,5,STONE:3)
Block(-3,33,6,STONE:5)
Block(-3,33,7,STONE:5)
Block(-3,33,8,OBSIDIAN:0)
Block(-3,34,-7,OBSIDIAN:0)
Block(-3,34,-6,OBSIDIAN:0)
Block(-3,34,-5,OBSIDIAN:0)
Block(-3,34,-4,STONE:3)
Block(-3,34,5,STONE:5)
Block(-3,34,6,STONE:5)
Block(-3,34,7,STONE:5)
Block(-3,34,8,STONE:5)
Block(-3,35,-7,STONE:5)
Block(-3,35,-6,STONE:5)
Block(-3,35,-5,STONE:5)
Block(-3,35,-4,STONE:3)
Block(-3,35,5,STONE:5)
Block(-3,35,6,STONE:5)
Block(-3,35,7,STONE:5)
Block(-3,35,8,STONE:5)
Block(-3,36,-7,STONE:5)
Block(-3,36,-6,STONE:5)
Block(-3,36,-5,STONE:5)
Block(-3,36,-4,GRASS:0)
Block(-3,36,7,STONE:5)
Block(-3,36,8,STONE:5)
Block(-3,37,-7,STONE:5)
Block(-3,37,-6,GRASS:0)
Block(-3,37,-5,GRASS:0)
Block(-3,37,7,STONE:5)
Block(-3,37,8,OBSIDIAN:0)
Block(-3,38,-7,STONE:5)
Block(-3,38,8,OBSIDIAN:0)
Block(-3,73,8,OBSIDIAN:0)
Block(-3,74,6,OBSIDIAN:0)
Block(-3,74,7,OBSIDIAN:0)
Block(-3,74,8,OBSIDIAN:0)
Block(-3,75,4,OBSIDIAN:0)
Block(-3,75,5,OBSIDIAN:0)
Block(-3,75,6,OBSIDIAN:0)
Block(-3,75,7,OBSIDIAN:0)
Block(-3,75,8,OBSIDIAN:0)
Block(-3,76,3,OBSIDIAN:0)
Block(-3,76,4,OBSIDIAN:0)
Block(-3,76,5,OBSIDIAN:0)
Block(-3,76,6,OBSIDIAN:0)
Block(-3,76,7,OBSIDIAN:0)
Block(-3,76,8,OBSIDIAN:0)
Block(-3,77,0,OBSIDIAN:0)
Block(-3,77,1,OBSIDIAN:0)
Block(-3,77,2,OBSIDIAN:0)
Block(-3,77,3,OBSIDIAN:0)
Block(-3,77,4,OBSIDIAN:0)
Block(-3,77,5,OBSIDIAN:0)
Block(-3,77,6,OBSIDIAN:0)
Block(-3,77,7,OBSIDIAN:0)
Block(-3,77,8,OBSIDIAN:0)
Block(-3,78,-1,OBSIDIAN:0)
Block(-3,78,0,OBSIDIAN:0)
Block(-3,78,1,OBSIDIAN:0)
Block(-3,78,2,OBSIDIAN:0)
Block(-3,78,3,OBSIDIAN:0)
Block(-3,78,4,OBSIDIAN:0)
Block(-3,78,5,OBSIDIAN:0)
Block(-3,78,6,OBSIDIAN:0)
Block(-3,78,7,OBSIDIAN:0)
Block(-3,78,8,OBSIDIAN:0)
Block(-3,79,-7,OBSIDIAN:0)
Block(-3,79,-6,OBSIDIAN:0)
Block(-3,79,-5,OBSIDIAN:0)
Block(-3,79,-4,OBSIDIAN:0)
Block(-3,79,-3,OBSIDIAN:0)
Block(-3,79,-2,OBSIDIAN:0)
Block(-3,79,-1,OBSIDIAN:0)
Block(-3,79,0,OBSIDIAN:0)
Block(-3,79,1,OBSIDIAN:0)
Block(-3,79,2,OBSIDIAN:0)
Block(-3,79,3,OBSIDIAN:0)
Block(-3,79,4,OBSIDIAN:0)
Block(-3,79,5,OBSIDIAN:0)
Block(-3,79,6,OBSIDIAN:0)
Block(-3,79,7,OBSIDIAN:0)
Block(-3,79,8,OBSIDIAN:0)
Block(-3,80,-7,OBSIDIAN:0)
Block(-3,80,-6,OBSIDIAN:0)
Block(-3,80,-5,OBSIDIAN:0)
Block(-3,80,-4,OBSIDIAN:0)
Block(-3,80,-3,OBSIDIAN:0)
Block(-3,80,-2,OBSIDIAN:0)
Block(-3,80,-1,OBSIDIAN:0)
Block(-3,80,0,OBSIDIAN:0)
Block(-3,80,1,OBSIDIAN:0)
Block(-3,80,2,OBSIDIAN:0)
Block(-3,80,3,OBSIDIAN:0)
Block(-3,80,4,OBSIDIAN:0)
Block(-3,80,5,OBSIDIAN:0)
Block(-3,80,6,OBSIDIAN:0)
Block(-3,80,7,OBSIDIAN:0)
Block(-3,80,8,OBSIDIAN:0)
Block(-3,81,-7,OBSIDIAN:0)
Block(-3,81,-6,OBSIDIAN:0)
Block(-3,81,-5,OBSIDIAN:0)
Block(-3,81,-4,OBSIDIAN:0)
Block(-3,81,-3,OBSIDIAN:0)
Block(-3,81,-2,OBSIDIAN:0)
Block(-3,81,-1,OBSIDIAN:0)
Block(-3,81,0,OBSIDIAN:0)
Block(-3,81,1,OBSIDIAN:0)
Block(-3,81,2,OBSIDIAN:0)
Block(-3,81,3,OBSIDIAN:0)
Block(-3,81,4,OBSIDIAN:0)
Block(-3,81,5,OBSIDIAN:0)
Block(-3,81,6,OBSIDIAN:0)
Block(-3,81,7,OBSIDIAN:0)
Block(-3,81,8,OBSIDIAN:0)
Block(-3,82,-7,OBSIDIAN:0)
Block(-3,82,-6,OBSIDIAN:0)
Block(-3,82,-5,OBSIDIAN:0)
Block(-3,82,-4,OBSIDIAN:0)
Block(-3,82,-3,OBSIDIAN:0)
Block(-3,82,-2,OBSIDIAN:0)
Block(-3,82,-1,OBSIDIAN:0)
Block(-3,82,0,OBSIDIAN:0)
Block(-3,82,1,OBSIDIAN:0)
Block(-3,82,2,OBSIDIAN:0)
Block(-3,82,3,OBSIDIAN:0)
Block(-3,82,4,OBSIDIAN:0)
Block(-3,82,5,OBSIDIAN:0)
Block(-3,82,6,OBSIDIAN:0)
Block(-3,82,7,OBSIDIAN:0)
Block(-3,82,8,OBSIDIAN:0)
Block(-3,83,-7,OBSIDIAN:0)
Block(-3,83,-6,OBSIDIAN:0)
Block(-3,83,-5,OBSIDIAN:0)
Block(-3,83,-4,OBSIDIAN:0)
Block(-3,83,-3,OBSIDIAN:0)
Block(-3,83,-2,OBSIDIAN:0)
Block(-3,83,-1,OBSIDIAN:0)
Block(-3,83,0,OBSIDIAN:0)
Block(-3,83,1,OBSIDIAN:0)
Block(-3,83,2,OBSIDIAN:0)
Block(-3,83,3,OBSIDIAN:0)
Block(-3,83,4,OBSIDIAN:0)
Block(-3,83,5,OBSIDIAN:0)
Block(-3,83,6,OBSIDIAN:0)
Block(-3,83,7,OBSIDIAN:0)
Block(-3,83,8,OBSIDIAN:0)
Block(-3,84,-7,OBSIDIAN:0)
Block(-3,84,-6,OBSIDIAN:0)
Block(-3,84,-5,OBSIDIAN:0)
Block(-3,84,-4,OBSIDIAN:0)
Block(-3,84,-3,OBSIDIAN:0)
Block(-3,84,-2,OBSIDIAN:0)
Block(-3,84,-1,OBSIDIAN:0)
Block(-3,84,0,OBSIDIAN:0)
Block(-3,84,1,OBSIDIAN:0)
Block(-3,84,2,OBSIDIAN:0)
Block(-3,84,3,OBSIDIAN:0)
Block(-3,84,4,OBSIDIAN:0)
Block(-3,84,5,OBSIDIAN:0)
Block(-3,84,6,OBSIDIAN:0)
Block(-3,84,7,OBSIDIAN:0)
Block(-3,84,8,OBSIDIAN:0)
Block(-3,85,-7,OBSIDIAN:0)
Block(-3,85,-6,OBSIDIAN:0)
Block(-3,85,-5,OBSIDIAN:0)
Block(-3,85,-4,OBSIDIAN:0)
Block(-3,85,-3,OBSIDIAN:0)
Block(-3,85,-2,OBSIDIAN:0)
Block(-3,85,-1,OBSIDIAN:0)
Block(-3,85,0,OBSIDIAN:0)
Block(-3,85,1,OBSIDIAN:0)
Block(-3,85,2,OBSIDIAN:0)
Block(-3,85,3,OBSIDIAN:0)
Block(-3,85,4,OBSIDIAN:0)
Block(-3,85,5,OBSIDIAN:0)
Block(-3,85,6,OBSIDIAN:0)
Block(-3,85,7,OBSIDIAN:0)
Block(-3,85,8,OBSIDIAN:0)
Block(-3,86,-7,OBSIDIAN:0)
Block(-3,86,-6,OBSIDIAN:0)
Block(-3,86,-5,OBSIDIAN:0)
Block(-3,86,-4,OBSIDIAN:0)
Block(-3,86,-3,OBSIDIAN:0)
Block(-3,86,-2,OBSIDIAN:0)
Block(-3,86,-1,OBSIDIAN:0)
Block(-3,86,0,OBSIDIAN:0)
Block(-3,86,1,OBSIDIAN:0)
Block(-3,86,2,OBSIDIAN:0)
Block(-3,86,3,OBSIDIAN:0)
Block(-3,86,4,OBSIDIAN:0)
Block(-3,86,5,OBSIDIAN:0)
Block(-3,86,6,OBSIDIAN:0)
Block(-3,86,7,OBSIDIAN:0)
Block(-3,86,8,OBSIDIAN:0)
Block(-3,87,-7,OBSIDIAN:0)
Block(-3,87,-6,OBSIDIAN:0)
Block(-3,87,-5,OBSIDIAN:0)
Block(-3,87,-4,OBSIDIAN:0)
Block(-3,87,-3,OBSIDIAN:0)
Block(-3,87,-2,OBSIDIAN:0)
Block(-3,87,-1,OBSIDIAN:0)
Block(-3,87,0,OBSIDIAN:0)
Block(-3,87,1,OBSIDIAN:0)
Block(-3,87,2,OBSIDIAN:0)
Block(-3,87,3,OBSIDIAN:0)
Block(-3,87,4,OBSIDIAN:0)
Block(-3,87,5,OBSIDIAN:0)
Block(-3,87,6,OBSIDIAN:0)
Block(-3,87,7,OBSIDIAN:0)
Block(-3,87,8,OBSIDIAN:0)
Block(-3,88,-7,OBSIDIAN:0)
Block(-3,88,-6,OBSIDIAN:0)
Block(-3,88,-5,OBSIDIAN:0)
Block(-3,88,-4,OBSIDIAN:0)
Block(-3,88,-3,OBSIDIAN:0)
Block(-3,88,-2,OBSIDIAN:0)
Block(-3,88,-1,OBSIDIAN:0)
Block(-3,88,0,OBSIDIAN:0)
Block(-3,88,1,OBSIDIAN:0)
Block(-3,88,2,OBSIDIAN:0)
Block(-3,88,3,OBSIDIAN:0)
Block(-3,88,4,OBSIDIAN:0)
Block(-3,88,5,OBSIDIAN:0)
Block(-3,88,6,OBSIDIAN:0)
Block(-3,88,7,OBSIDIAN:0)
Block(-3,88,8,OBSIDIAN:0)
Block(-3,89,-7,OBSIDIAN:0)
Block(-3,89,-6,OBSIDIAN:0)
Block(-3,89,-5,OBSIDIAN:0)
Block(-3,89,-4,OBSIDIAN:0)
Block(-3,89,-3,OBSIDIAN:0)
Block(-3,89,-2,OBSIDIAN:0)
Block(-3,89,-1,OBSIDIAN:0)
Block(-3,89,0,OBSIDIAN:0)
Block(-3,89,1,OBSIDIAN:0)
Block(-3,89,2,OBSIDIAN:0)
Block(-3,89,3,OBSIDIAN:0)
Block(-3,89,4,OBSIDIAN:0)
Block(-3,89,5,OBSIDIAN:0)
Block(-3,89,6,OBSIDIAN:0)
Block(-3,89,7,OBSIDIAN:0)
Block(-3,89,8,OBSIDIAN:0)
Block(-3,90,-7,OBSIDIAN:0)
Block(-3,90,-6,OBSIDIAN:0)
Block(-3,90,-5,OBSIDIAN:0)
Block(-3,90,-4,OBSIDIAN:0)
Block(-3,90,-3,OBSIDIAN:0)
Block(-3,90,-2,OBSIDIAN:0)
Block(-3,90,-1,OBSIDIAN:0)
Block(-3,90,0,OBSIDIAN:0)
Block(-3,90,1,OBSIDIAN:0)
Block(-3,90,2,OBSIDIAN:0)
Block(-3,90,3,OBSIDIAN:0)
Block(-3,90,4,OBSIDIAN:0)
Block(-3,90,5,OBSIDIAN:0)
Block(-3,90,6,OBSIDIAN:0)
Block(-3,90,7,OBSIDIAN:0)
Block(-3,90,8,OBSIDIAN:0)
Block(-3,91,-7,OBSIDIAN:0)
Block(-3,91,-6,OBSIDIAN:0)
Block(-3,91,-5,OBSIDIAN:0)
Block(-3,91,-4,OBSIDIAN:0)
Block(-3,91,-3,OBSIDIAN:0)
Block(-3,91,-2,OBSIDIAN:0)
Block(-3,91,-1,OBSIDIAN:0)
Block(-3,91,0,MAGMA:0)
Block(-3,91,1,MAGMA:0)
Block(-3,91,2,MAGMA:0)
Block(-3,91,3,MAGMA:0)
Block(-3,91,4,MAGMA:0)
Block(-3,91,5,MAGMA:0)
Block(-3,91,6,OBSIDIAN:0)
Block(-3,91,7,OBSIDIAN:0)
Block(-3,91,8,OBSIDIAN:0)
Block(-3,92,-7,OBSIDIAN:0)
Block(-3,92,-6,OBSIDIAN:0)
Block(-3,92,-5,STONE:3)
Block(-3,92,-4,STONE:3)
Block(-3,92,-3,OBSIDIAN:0)
Block(-3,92,-2,OBSIDIAN:0)
Block(-3,92,-1,MAGMA:0)
Block(-3,92,0,MAGMA:0)
Block(-3,92,1,MAGMA:0)
Block(-3,92,2,MAGMA:0)
Block(-3,92,3,MAGMA:0)
Block(-3,92,4,MAGMA:0)
Block(-3,92,5,MAGMA:0)
Block(-3,93,-7,OBSIDIAN:0)
Block(-3,93,-6,STONE:3)
Block(-3,93,-5,STONE:3)
Block(-3,93,-4,OBSIDIAN:0)
Block(-3,93,-3,OBSIDIAN:0)
Block(-3,93,-2,OBSIDIAN:0)
Block(-3,93,-1,MAGMA:0)
Block(-3,93,0,MAGMA:0)
Block(-3,93,1,MAGMA:0)
Block(-3,93,2,MAGMA:0)
Block(-3,94,-7,STONE:3)
Block(-3,94,-6,STONE:3)
Block(-3,94,-5,STONE:3)
Block(-3,94,-4,OBSIDIAN:0)
Block(-3,94,-3,OBSIDIAN:0)
Block(-3,94,-2,OBSIDIAN:0)
Block(-3,94,-1,MAGMA:0)
Block(-3,95,-7,OBSIDIAN:0)
Block(-3,95,-6,OBSIDIAN:0)
Block(-3,95,-5,OBSIDIAN:0)
Block(-3,95,-4,OBSIDIAN:0)
Block(-3,95,-3,OBSIDIAN:0)
Block(-3,95,-2,OBSIDIAN:0)
Block(-3,95,-1,MAGMA:0)
Block(-3,96,-7,OBSIDIAN:0)
Block(-3,96,-6,OBSIDIAN:0)
Block(-3,96,-5,OBSIDIAN:0)
Block(-3,96,-4,OBSIDIAN:0)
Block(-3,96,-3,OBSIDIAN:0)
Block(-3,96,-2,OBSIDIAN:0)
Block(-3,96,-1,MAGMA:0)
Block(-3,97,-7,OBSIDIAN:0)
Block(-3,97,-6,OBSIDIAN:0)
Block(-3,97,-5,OBSIDIAN:0)
Block(-3,97,-4,OBSIDIAN:0)
Block(-3,97,-3,OBSIDIAN:0)
Block(-3,97,-2,OBSIDIAN:0)
Block(-3,97,-1,OBSIDIAN:0)
Block(-3,98,-7,OBSIDIAN:0)
Block(-3,98,-6,OBSIDIAN:0)
Block(-3,98,-5,OBSIDIAN:0)
Block(-3,98,-4,OBSIDIAN:0)
Block(-3,98,-3,OBSIDIAN:0)
Block(-3,98,-2,OBSIDIAN:0)
Block(-3,98,-1,OBSIDIAN:0)
Block(-3,99,-7,OBSIDIAN:0)
Block(-3,99,-6,OBSIDIAN:0)
Block(-3,99,-5,OBSIDIAN:0)
Block(-3,99,-4,OBSIDIAN:0)
Block(-3,99,-3,OBSIDIAN:0)
Block(-3,99,-2,OBSIDIAN:0)
Block(-3,100,-7,OBSIDIAN:0)
Block(-3,100,-6,OBSIDIAN:0)
Block(-3,100,-5,OBSIDIAN:0)
Block(-3,100,-4,OBSIDIAN:0)
Block(-3,101,-7,OBSIDIAN:0)
Block(-2,22,-7,STONE:3)
Block(-2,22,-6,STONE:3)
Block(-2,23,-7,STONE:3)
Block(-2,23,-6,STONE:3)
Block(-2,23,-5,STONE:3)
Block(-2,24,-7,STONE:3)
Block(-2,24,-6,STONE:3)
Block(-2,24,-5,STONE:3)
Block(-2,24,-4,STONE:3)
Block(-2,24,-3,STONE:3)
Block(-2,24,-2,STONE:3)
Block(-2,25,-7,STONE:3)
Block(-2,25,-6,STONE:3)
Block(-2,25,-5,STONE:3)
Block(-2,25,-4,STONE:3)
Block(-2,25,-3,STONE:3)
Block(-2,25,-2,STONE:3)
Block(-2,25,-1,STONE:3)
Block(-2,26,-7,STONE:3)
Block(-2,26,-6,STONE:3)
Block(-2,26,-5,STONE:3)
Block(-2,26,-4,STONE:3)
Block(-2,26,-3,STONE:3)
Block(-2,26,-2,STONE:3)
Block(-2,26,-1,STONE:3)
Block(-2,26,0,STONE:3)
Block(-2,26,1,STONE:3)
Block(-2,26,2,STONE:3)
Block(-2,27,-7,STONE:3)
Block(-2,27,-6,STONE:3)
Block(-2,27,-5,STONE:3)
Block(-2,27,-4,STONE:3)
Block(-2,27,-3,STONE:3)
Block(-2,27,-2,STONE:3)
Block(-2,27,-1,STONE:3)
Block(-2,27,0,STONE:3)
Block(-2,27,1,STONE:3)
Block(-2,27,2,STONE:3)
Block(-2,27,3,STONE:3)
Block(-2,27,4,STONE:3)
Block(-2,27,5,STONE:3)
Block(-2,27,6,STONE:3)
Block(-2,27,7,STONE:3)
Block(-2,27,8,STONE:3)
Block(-2,28,-7,OBSIDIAN:0)
Block(-2,28,-6,OBSIDIAN:0)
Block(-2,28,-5,STONE:3)
Block(-2,28,-4,STONE:3)
Block(-2,28,-3,STONE:3)
Block(-2,28,-2,STONE:3)
Block(-2,28,-1,STONE:3)
Block(-2,28,0,STONE:3)
Block(-2,28,1,STONE:3)
Block(-2,28,2,STONE:3)
Block(-2,28,3,STONE:3)
Block(-2,28,4,STONE:3)
Block(-2,28,5,STONE:3)
Block(-2,28,6,STONE:3)
Block(-2,28,7,STONE:3)
Block(-2,28,8,STONE:3)
Block(-2,29,-7,OBSIDIAN:0)
Block(-2,29,-6,OBSIDIAN:0)
Block(-2,29,-5,OBSIDIAN:0)
Block(-2,29,-4,STONE:3)
Block(-2,29,-3,STONE:3)
Block(-2,29,-2,STONE:3)
Block(-2,29,-1,STONE:3)
Block(-2,29,0,STONE:3)
Block(-2,29,1,STONE:3)
Block(-2,29,2,STONE:3)
Block(-2,29,3,STONE:3)
Block(-2,29,4,STONE:3)
Block(-2,29,5,STONE:3)
Block(-2,29,6,STONE:3)
Block(-2,29,7,STONE:3)
Block(-2,29,8,STONE:3)
Block(-2,30,-7,OBSIDIAN:0)
Block(-2,30,-6,OBSIDIAN:0)
Block(-2,30,-5,OBSIDIAN:0)
Block(-2,30,-4,OBSIDIAN:0)
Block(-2,30,-3,OBSIDIAN:0)
Block(-2,30,-2,STONE:3)
Block(-2,30,-1,STONE:3)
Block(-2,30,0,STONE:3)
Block(-2,30,1,STONE:5)
Block(-2,30,2,STONE:5)
Block(-2,30,3,OBSIDIAN:0)
Block(-2,30,4,OBSIDIAN:0)
Block(-2,30,5,STONE:3)
Block(-2,30,6,STONE:3)
Block(-2,30,7,STONE:3)
Block(-2,30,8,STONE:3)
Block(-2,31,-7,OBSIDIAN:0)
Block(-2,31,-6,OBSIDIAN:0)
Block(-2,31,-5,OBSIDIAN:0)
Block(-2,31,-4,OBSIDIAN:0)
Block(-2,31,-3,STONE:3)
Block(-2,31,-2,STONE:3)
Block(-2,31,-1,STONE:3)
Block(-2,31,0,STONE:3)
Block(-2,31,1,STONE:3)
Block(-2,31,2,STONE:3)
Block(-2,31,3,STONE:3)
Block(-2,31,4,STONE:3)
Block(-2,31,5,STONE:3)
Block(-2,31,6,STONE:3)
Block(-2,31,7,STONE:3)
Block(-2,31,8,STONE:3)
Block(-2,32,-7,OBSIDIAN:0)
Block(-2,32,-6,OBSIDIAN:0)
Block(-2,32,-5,OBSIDIAN:0)
Block(-2,32,-4,OBSIDIAN:0)
Block(-2,32,-3,STONE:3)
Block(-2,32,-2,STONE:3)
Block(-2,32,-1,STATIONARY_WATER:0)
Block(-2,32,0,STATIONARY_WATER:0)
Block(-2,32,1,STATIONARY_WATER:0)
Block(-2,32,2,STONE:3)
Block(-2,32,3,STONE:3)
Block(-2,32,4,STONE:3)
Block(-2,32,5,STONE:3)
Block(-2,32,6,STONE:3)
Block(-2,32,7,STONE:3)
Block(-2,32,8,STONE:3)
Block(-2,33,-7,OBSIDIAN:0)
Block(-2,33,-6,OBSIDIAN:0)
Block(-2,33,-5,OBSIDIAN:0)
Block(-2,33,-4,STONE:3)
Block(-2,33,-3,STONE:3)
Block(-2,33,-2,STATIONARY_WATER:0)
Block(-2,33,-1,STATIONARY_WATER:0)
Block(-2,33,0,STATIONARY_WATER:0)
Block(-2,33,1,STATIONARY_WATER:0)
Block(-2,33,2,STATIONARY_WATER:0)
Block(-2,33,3,GRASS:0)
Block(-2,33,4,STONE:3)
Block(-2,33,5,STONE:5)
Block(-2,33,6,OBSIDIAN:0)
Block(-2,33,7,OBSIDIAN:0)
Block(-2,33,8,OBSIDIAN:0)
Block(-2,34,-7,OBSIDIAN:0)
Block(-2,34,-6,OBSIDIAN:0)
Block(-2,34,-5,OBSIDIAN:0)
Block(-2,34,-4,STONE:3)
Block(-2,34,4,STONE:3)
Block(-2,34,5,STONE:5)
Block(-2,34,6,STONE:5)
Block(-2,34,7,STONE:5)
Block(-2,34,8,OBSIDIAN:0)
Block(-2,35,-7,OBSIDIAN:0)
Block(-2,35,-6,OBSIDIAN:0)
Block(-2,35,-5,STONE:5)
Block(-2,35,-4,STONE:3)
Block(-2,35,4,STONE:3)
Block(-2,35,5,STONE:5)
Block(-2,35,6,STONE:5)
Block(-2,35,7,STONE:5)
Block(-2,35,8,OBSIDIAN:0)
Block(-2,36,-7,STONE:5)
Block(-2,36,-6,STONE:5)
Block(-2,36,-5,STONE:5)
Block(-2,36,-4,STONE:5)
Block(-2,36,5,STONE:5)
Block(-2,36,6,STONE:5)
Block(-2,36,7,STONE:5)
Block(-2,36,8,OBSIDIAN:0)
Block(-2,37,-7,STONE:5)
Block(-2,37,-6,STONE:5)
Block(-2,37,-5,GRASS:0)
Block(-2,37,-4,GRASS:0)
Block(-2,37,5,STONE:5)
Block(-2,37,6,STONE:5)
Block(-2,37,7,STONE:5)
Block(-2,37,8,OBSIDIAN:0)
Block(-2,38,-7,STONE:5)
Block(-2,38,-6,STONE:5)
Block(-2,38,8,OBSIDIAN:0)
Block(-2,39,-7,STONE:5)
Block(-2,74,7,OBSIDIAN:0)
Block(-2,74,8,OBSIDIAN:0)
Block(-2,75,6,OBSIDIAN:0)
Block(-2,75,7,OBSIDIAN:0)
Block(-2,75,8,OBSIDIAN:0)
Block(-2,76,3,OBSIDIAN:0)
Block(-2,76,4,OBSIDIAN:0)
Block(-2,76,5,OBSIDIAN:0)
Block(-2,76,6,OBSIDIAN:0)
Block(-2,76,7,OBSIDIAN:0)
Block(-2,76,8,OBSIDIAN:0)
Block(-2,77,0,OBSIDIAN:0)
Block(-2,77,1,OBSIDIAN:0)
Block(-2,77,2,OBSIDIAN:0)
Block(-2,77,3,OBSIDIAN:0)
Block(-2,77,4,OBSIDIAN:0)
Block(-2,77,5,OBSIDIAN:0)
Block(-2,77,6,OBSIDIAN:0)
Block(-2,77,7,OBSIDIAN:0)
Block(-2,77,8,OBSIDIAN:0)
Block(-2,78,-2,OBSIDIAN:0)
Block(-2,78,-1,OBSIDIAN:0)
Block(-2,78,0,OBSIDIAN:0)
Block(-2,78,1,OBSIDIAN:0)
Block(-2,78,2,OBSIDIAN:0)
Block(-2,78,3,OBSIDIAN:0)
Block(-2,78,4,OBSIDIAN:0)
Block(-2,78,5,OBSIDIAN:0)
Block(-2,78,6,OBSIDIAN:0)
Block(-2,78,7,OBSIDIAN:0)
Block(-2,78,8,OBSIDIAN:0)
Block(-2,79,-7,OBSIDIAN:0)
Block(-2,79,-6,OBSIDIAN:0)
Block(-2,79,-5,OBSIDIAN:0)
Block(-2,79,-4,OBSIDIAN:0)
Block(-2,79,-3,OBSIDIAN:0)
Block(-2,79,-2,OBSIDIAN:0)
Block(-2,79,-1,OBSIDIAN:0)
Block(-2,79,0,OBSIDIAN:0)
Block(-2,79,1,OBSIDIAN:0)
Block(-2,79,2,OBSIDIAN:0)
Block(-2,79,3,OBSIDIAN:0)
Block(-2,79,4,OBSIDIAN:0)
Block(-2,79,5,OBSIDIAN:0)
Block(-2,79,6,OBSIDIAN:0)
Block(-2,79,7,OBSIDIAN:0)
Block(-2,79,8,OBSIDIAN:0)
Block(-2,80,-7,OBSIDIAN:0)
Block(-2,80,-6,OBSIDIAN:0)
Block(-2,80,-5,OBSIDIAN:0)
Block(-2,80,-4,OBSIDIAN:0)
Block(-2,80,-3,OBSIDIAN:0)
Block(-2,80,-2,OBSIDIAN:0)
Block(-2,80,-1,OBSIDIAN:0)
Block(-2,80,0,OBSIDIAN:0)
Block(-2,80,1,OBSIDIAN:0)
Block(-2,80,2,OBSIDIAN:0)
Block(-2,80,3,OBSIDIAN:0)
Block(-2,80,4,OBSIDIAN:0)
Block(-2,80,5,OBSIDIAN:0)
Block(-2,80,6,OBSIDIAN:0)
Block(-2,80,7,OBSIDIAN:0)
Block(-2,80,8,OBSIDIAN:0)
Block(-2,81,-7,OBSIDIAN:0)
Block(-2,81,-6,OBSIDIAN:0)
Block(-2,81,-5,OBSIDIAN:0)
Block(-2,81,-4,OBSIDIAN:0)
Block(-2,81,-3,OBSIDIAN:0)
Block(-2,81,-2,OBSIDIAN:0)
Block(-2,81,-1,OBSIDIAN:0)
Block(-2,81,0,OBSIDIAN:0)
Block(-2,81,1,OBSIDIAN:0)
Block(-2,81,2,OBSIDIAN:0)
Block(-2,81,3,OBSIDIAN:0)
Block(-2,81,4,OBSIDIAN:0)
Block(-2,81,5,OBSIDIAN:0)
Block(-2,81,6,OBSIDIAN:0)
Block(-2,81,7,OBSIDIAN:0)
Block(-2,81,8,OBSIDIAN:0)
Block(-2,82,-7,OBSIDIAN:0)
Block(-2,82,-6,OBSIDIAN:0)
Block(-2,82,-5,OBSIDIAN:0)
Block(-2,82,-4,OBSIDIAN:0)
Block(-2,82,-3,OBSIDIAN:0)
Block(-2,82,-2,OBSIDIAN:0)
Block(-2,82,-1,OBSIDIAN:0)
Block(-2,82,0,OBSIDIAN:0)
Block(-2,82,1,OBSIDIAN:0)
Block(-2,82,2,OBSIDIAN:0)
Block(-2,82,3,OBSIDIAN:0)
Block(-2,82,4,OBSIDIAN:0)
Block(-2,82,5,OBSIDIAN:0)
Block(-2,82,6,OBSIDIAN:0)
Block(-2,82,7,OBSIDIAN:0)
Block(-2,82,8,OBSIDIAN:0)
Block(-2,83,-7,OBSIDIAN:0)
Block(-2,83,-6,OBSIDIAN:0)
Block(-2,83,-5,OBSIDIAN:0)
Block(-2,83,-4,OBSIDIAN:0)
Block(-2,83,-3,OBSIDIAN:0)
Block(-2,83,-2,OBSIDIAN:0)
Block(-2,83,-1,OBSIDIAN:0)
Block(-2,83,0,OBSIDIAN:0)
Block(-2,83,1,OBSIDIAN:0)
Block(-2,83,2,OBSIDIAN:0)
Block(-2,83,3,OBSIDIAN:0)
Block(-2,83,4,OBSIDIAN:0)
Block(-2,83,5,OBSIDIAN:0)
Block(-2,83,6,OBSIDIAN:0)
Block(-2,83,7,OBSIDIAN:0)
Block(-2,83,8,OBSIDIAN:0)
Block(-2,84,-7,OBSIDIAN:0)
Block(-2,84,-6,OBSIDIAN:0)
Block(-2,84,-5,OBSIDIAN:0)
Block(-2,84,-4,OBSIDIAN:0)
Block(-2,84,-3,OBSIDIAN:0)
Block(-2,84,-2,OBSIDIAN:0)
Block(-2,84,-1,OBSIDIAN:0)
Block(-2,84,0,OBSIDIAN:0)
Block(-2,84,1,OBSIDIAN:0)
Block(-2,84,2,OBSIDIAN:0)
Block(-2,84,3,OBSIDIAN:0)
Block(-2,84,4,OBSIDIAN:0)
Block(-2,84,5,OBSIDIAN:0)
Block(-2,84,6,OBSIDIAN:0)
Block(-2,84,7,OBSIDIAN:0)
Block(-2,84,8,OBSIDIAN:0)
Block(-2,85,-7,OBSIDIAN:0)
Block(-2,85,-6,OBSIDIAN:0)
Block(-2,85,-5,OBSIDIAN:0)
Block(-2,85,-4,OBSIDIAN:0)
Block(-2,85,-3,OBSIDIAN:0)
Block(-2,85,-2,OBSIDIAN:0)
Block(-2,85,-1,OBSIDIAN:0)
Block(-2,85,0,OBSIDIAN:0)
Block(-2,85,1,OBSIDIAN:0)
Block(-2,85,2,OBSIDIAN:0)
Block(-2,85,3,OBSIDIAN:0)
Block(-2,85,4,OBSIDIAN:0)
Block(-2,85,5,OBSIDIAN:0)
Block(-2,85,6,OBSIDIAN:0)
Block(-2,85,7,OBSIDIAN:0)
Block(-2,85,8,OBSIDIAN:0)
Block(-2,86,-7,OBSIDIAN:0)
Block(-2,86,-6,OBSIDIAN:0)
Block(-2,86,-5,OBSIDIAN:0)
Block(-2,86,-4,OBSIDIAN:0)
Block(-2,86,-3,OBSIDIAN:0)
Block(-2,86,-2,OBSIDIAN:0)
Block(-2,86,-1,OBSIDIAN:0)
Block(-2,86,0,OBSIDIAN:0)
Block(-2,86,1,OBSIDIAN:0)
Block(-2,86,2,OBSIDIAN:0)
Block(-2,86,3,OBSIDIAN:0)
Block(-2,86,4,OBSIDIAN:0)
Block(-2,86,5,OBSIDIAN:0)
Block(-2,86,6,OBSIDIAN:0)
Block(-2,86,7,OBSIDIAN:0)
Block(-2,86,8,OBSIDIAN:0)
Block(-2,87,-7,OBSIDIAN:0)
Block(-2,87,-6,OBSIDIAN:0)
Block(-2,87,-5,OBSIDIAN:0)
Block(-2,87,-4,OBSIDIAN:0)
Block(-2,87,-3,OBSIDIAN:0)
Block(-2,87,-2,OBSIDIAN:0)
Block(-2,87,-1,OBSIDIAN:0)
Block(-2,87,0,OBSIDIAN:0)
Block(-2,87,1,OBSIDIAN:0)
Block(-2,87,2,OBSIDIAN:0)
Block(-2,87,3,OBSIDIAN:0)
Block(-2,87,4,OBSIDIAN:0)
Block(-2,87,5,OBSIDIAN:0)
Block(-2,87,6,OBSIDIAN:0)
Block(-2,87,7,OBSIDIAN:0)
Block(-2,87,8,OBSIDIAN:0)
Block(-2,88,-7,OBSIDIAN:0)
Block(-2,88,-6,OBSIDIAN:0)
Block(-2,88,-5,OBSIDIAN:0)
Block(-2,88,-4,OBSIDIAN:0)
Block(-2,88,-3,OBSIDIAN:0)
Block(-2,88,-2,OBSIDIAN:0)
Block(-2,88,-1,OBSIDIAN:0)
Block(-2,88,0,OBSIDIAN:0)
Block(-2,88,1,OBSIDIAN:0)
Block(-2,88,2,OBSIDIAN:0)
Block(-2,88,3,OBSIDIAN:0)
Block(-2,88,4,OBSIDIAN:0)
Block(-2,88,5,OBSIDIAN:0)
Block(-2,88,6,OBSIDIAN:0)
Block(-2,88,7,OBSIDIAN:0)
Block(-2,88,8,OBSIDIAN:0)
Block(-2,89,-7,OBSIDIAN:0)
Block(-2,89,-6,OBSIDIAN:0)
Block(-2,89,-5,OBSIDIAN:0)
Block(-2,89,-4,OBSIDIAN:0)
Block(-2,89,-3,OBSIDIAN:0)
Block(-2,89,-2,OBSIDIAN:0)
Block(-2,89,-1,OBSIDIAN:0)
Block(-2,89,0,OBSIDIAN:0)
Block(-2,89,1,OBSIDIAN:0)
Block(-2,89,2,OBSIDIAN:0)
Block(-2,89,3,OBSIDIAN:0)
Block(-2,89,4,OBSIDIAN:0)
Block(-2,89,5,OBSIDIAN:0)
Block(-2,89,6,OBSIDIAN:0)
Block(-2,89,7,OBSIDIAN:0)
Block(-2,89,8,OBSIDIAN:0)
Block(-2,90,-7,OBSIDIAN:0)
Block(-2,90,-6,OBSIDIAN:0)
Block(-2,90,-5,OBSIDIAN:0)
Block(-2,90,-4,OBSIDIAN:0)
Block(-2,90,-3,STONE:3)
Block(-2,90,-2,OBSIDIAN:0)
Block(-2,90,-1,OBSIDIAN:0)
Block(-2,90,0,OBSIDIAN:0)
Block(-2,90,1,OBSIDIAN:0)
Block(-2,90,2,OBSIDIAN:0)
Block(-2,90,3,MAGMA:0)
Block(-2,90,4,MAGMA:0)
Block(-2,90,5,MAGMA:0)
Block(-2,90,6,OBSIDIAN:0)
Block(-2,90,7,OBSIDIAN:0)
Block(-2,90,8,OBSIDIAN:0)
Block(-2,91,-7,OBSIDIAN:0)
Block(-2,91,-6,OBSIDIAN:0)
Block(-2,91,-5,OBSIDIAN:0)
Block(-2,91,-4,STONE:3)
Block(-2,91,-3,OBSIDIAN:0)
Block(-2,91,-2,OBSIDIAN:0)
Block(-2,91,-1,OBSIDIAN:0)
Block(-2,91,0,OBSIDIAN:0)
Block(-2,91,1,MAGMA:0)
Block(-2,91,2,MAGMA:0)
Block(-2,91,3,MAGMA:0)
Block(-2,91,4,MAGMA:0)
Block(-2,91,5,MAGMA:0)
Block(-2,91,6,MAGMA:0)
Block(-2,91,7,OBSIDIAN:0)
Block(-2,92,-7,OBSIDIAN:0)
Block(-2,92,-6,OBSIDIAN:0)
Block(-2,92,-5,OBSIDIAN:0)
Block(-2,92,-4,STONE:3)
Block(-2,92,-3,OBSIDIAN:0)
Block(-2,92,-2,OBSIDIAN:0)
Block(-2,92,-1,OBSIDIAN:0)
Block(-2,92,0,MAGMA:0)
Block(-2,92,1,MAGMA:0)
Block(-2,92,2,MAGMA:0)
Block(-2,92,3,MAGMA:0)
Block(-2,92,4,MAGMA:0)
Block(-2,92,5,MAGMA:0)
Block(-2,93,-7,OBSIDIAN:0)
Block(-2,93,-6,OBSIDIAN:0)
Block(-2,93,-5,STONE:3)
Block(-2,93,-4,STONE:3)
Block(-2,93,-3,OBSIDIAN:0)
Block(-2,93,-2,OBSIDIAN:0)
Block(-2,93,-1,OBSIDIAN:0)
Block(-2,93,0,MAGMA:0)
Block(-2,93,1,MAGMA:0)
Block(-2,93,2,MAGMA:0)
Block(-2,94,-7,OBSIDIAN:0)
Block(-2,94,-6,OBSIDIAN:0)
Block(-2,94,-5,STONE:3)
Block(-2,94,-4,STONE:3)
Block(-2,94,-3,OBSIDIAN:0)
Block(-2,94,-2,OBSIDIAN:0)
Block(-2,94,-1,OBSIDIAN:0)
Block(-2,95,-7,STONE:3)
Block(-2,95,-6,STONE:3)
Block(-2,95,-5,STONE:3)
Block(-2,95,-4,STONE:3)
Block(-2,95,-3,OBSIDIAN:0)
Block(-2,95,-2,OBSIDIAN:0)
Block(-2,95,-1,OBSIDIAN:0)
Block(-2,96,-7,STONE:3)
Block(-2,96,-6,OBSIDIAN:0)
Block(-2,96,-5,OBSIDIAN:0)
Block(-2,96,-4,OBSIDIAN:0)
Block(-2,96,-3,OBSIDIAN:0)
Block(-2,96,-2,OBSIDIAN:0)
Block(-2,96,-1,OBSIDIAN:0)
Block(-2,97,-7,OBSIDIAN:0)
Block(-2,97,-6,OBSIDIAN:0)
Block(-2,97,-5,OBSIDIAN:0)
Block(-2,97,-4,OBSIDIAN:0)
Block(-2,97,-3,OBSIDIAN:0)
Block(-2,97,-2,OBSIDIAN:0)
Block(-2,97,-1,OBSIDIAN:0)
Block(-2,98,-7,OBSIDIAN:0)
Block(-2,98,-6,OBSIDIAN:0)
Block(-2,98,-5,OBSIDIAN:0)
Block(-2,98,-4,OBSIDIAN:0)
Block(-2,98,-3,OBSIDIAN:0)
Block(-2,98,-2,STONE:3)
Block(-2,98,-1,OBSIDIAN:0)
Block(-2,99,-7,OBSIDIAN:0)
Block(-2,99,-6,OBSIDIAN:0)
Block(-2,99,-5,OBSIDIAN:0)
Block(-2,99,-4,OBSIDIAN:0)
Block(-2,99,-3,OBSIDIAN:0)
Block(-2,99,-2,STONE:3)
Block(-2,99,-1,STONE:3)
Block(-2,100,-7,STONE:3)
Block(-2,100,-6,OBSIDIAN:0)
Block(-2,100,-5,OBSIDIAN:0)
Block(-2,100,-4,OBSIDIAN:0)
Block(-2,100,-3,STONE:3)
Block(-2,101,-7,STONE:3)
Block(-2,101,-5,STONE:3)
Block(-2,101,-4,STONE:3)
Block(-1,22,-7,STONE:3)
Block(-1,23,-7,STONE:3)
Block(-1,23,-6,STONE:3)
Block(-1,24,-7,STONE:3)
Block(-1,24,-6,STONE:3)
Block(-1,24,-5,STONE:3)
Block(-1,24,-4,STONE:3)
Block(-1,24,-3,STONE:3)
Block(-1,25,-7,STONE:3)
Block(-1,25,-6,STONE:3)
Block(-1,25,-5,STONE:3)
Block(-1,25,-4,STONE:3)
Block(-1,25,-3,STONE:3)
Block(-1,25,-2,STONE:3)
Block(-1,26,-7,STONE:3)
Block(-1,26,-6,STONE:3)
Block(-1,26,-5,STONE:3)
Block(-1,26,-4,STONE:3)
Block(-1,26,-3,STONE:3)
Block(-1,26,-2,STONE:3)
Block(-1,26,-1,STONE:3)
Block(-1,26,0,STONE:3)
Block(-1,26,1,STONE:3)
Block(-1,26,2,STONE:3)
Block(-1,26,3,STONE:3)
Block(-1,27,-7,STONE:3)
Block(-1,27,-6,STONE:3)
Block(-1,27,-5,STONE:3)
Block(-1,27,-4,STONE:3)
Block(-1,27,-3,STONE:3)
Block(-1,27,-2,STONE:3)
Block(-1,27,-1,STONE:3)
Block(-1,27,0,STONE:3)
Block(-1,27,1,STONE:3)
Block(-1,27,2,STONE:3)
Block(-1,27,3,STONE:3)
Block(-1,27,4,STONE:3)
Block(-1,27,5,STONE:3)
Block(-1,27,6,STONE:3)
Block(-1,27,7,STONE:3)
Block(-1,27,8,STONE:3)
Block(-1,28,-7,OBSIDIAN:0)
Block(-1,28,-6,OBSIDIAN:0)
Block(-1,28,-5,OBSIDIAN:0)
Block(-1,28,-4,STONE:3)
Block(-1,28,-3,STONE:3)
Block(-1,28,-2,STONE:3)
Block(-1,28,-1,STONE:3)
Block(-1,28,0,STONE:3)
Block(-1,28,1,STONE:3)
Block(-1,28,2,STONE:3)
Block(-1,28,3,STONE:3)
Block(-1,28,4,STONE:3)
Block(-1,28,5,STONE:3)
Block(-1,28,6,STONE:3)
Block(-1,28,7,STONE:3)
Block(-1,28,8,STONE:3)
Block(-1,29,-7,OBSIDIAN:0)
Block(-1,29,-6,OBSIDIAN:0)
Block(-1,29,-5,OBSIDIAN:0)
Block(-1,29,-4,OBSIDIAN:0)
Block(-1,29,-3,STONE:3)
Block(-1,29,-2,STONE:3)
Block(-1,29,-1,STONE:3)
Block(-1,29,0,STONE:3)
Block(-1,29,1,STONE:3)
Block(-1,29,2,STONE:3)
Block(-1,29,3,STONE:3)
Block(-1,29,4,STONE:3)
Block(-1,29,5,STONE:3)
Block(-1,29,6,STONE:3)
Block(-1,29,7,STONE:3)
Block(-1,29,8,STONE:3)
Block(-1,30,-7,OBSIDIAN:0)
Block(-1,30,-6,OBSIDIAN:0)
Block(-1,30,-5,OBSIDIAN:0)
Block(-1,30,-4,OBSIDIAN:0)
Block(-1,30,-3,OBSIDIAN:0)
Block(-1,30,-2,STONE:3)
Block(-1,30,-1,STONE:3)
Block(-1,30,0,STONE:3)
Block(-1,30,1,STONE:5)
Block(-1,30,2,OBSIDIAN:0)
Block(-1,30,3,STONE:3)
Block(-1,30,4,STONE:3)
Block(-1,30,5,STONE:3)
Block(-1,30,6,STONE:3)
Block(-1,30,7,STONE:3)
Block(-1,30,8,STONE:3)
Block(-1,31,-7,OBSIDIAN:0)
Block(-1,31,-6,OBSIDIAN:0)
Block(-1,31,-5,OBSIDIAN:0)
Block(-1,31,-4,OBSIDIAN:0)
Block(-1,31,-3,STONE:3)
Block(-1,31,-2,STONE:3)
Block(-1,31,-1,STONE:3)
Block(-1,31,0,STONE:3)
Block(-1,31,1,STONE:3)
Block(-1,31,2,STONE:3)
Block(-1,31,3,STONE:3)
Block(-1,31,4,STONE:3)
Block(-1,31,5,STONE:3)
Block(-1,31,6,STONE:3)
Block(-1,31,7,STONE:3)
Block(-1,31,8,STONE:3)
Block(-1,32,-7,OBSIDIAN:0)
Block(-1,32,-6,OBSIDIAN:0)
Block(-1,32,-5,OBSIDIAN:0)
Block(-1,32,-4,OBSIDIAN:0)
Block(-1,32,-3,STONE:3)
Block(-1,32,-2,STONE:3)
Block(-1,32,-1,STONE:3)
Block(-1,32,0,STONE:3)
Block(-1,32,1,STATIONARY_WATER:0)
Block(-1,32,2,STONE:3)
Block(-1,32,3,STONE:3)
Block(-1,32,4,STONE:3)
Block(-1,32,5,STONE:3)
Block(-1,32,6,STONE:3)
Block(-1,32,7,STONE:3)
Block(-1,32,8,STONE:3)
Block(-1,33,-7,OBSIDIAN:0)
Block(-1,33,-6,OBSIDIAN:0)
Block(-1,33,-5,OBSIDIAN:0)
Block(-1,33,-4,STONE:3)
Block(-1,33,-3,STONE:3)
Block(-1,33,-2,STATIONARY_WATER:0)
Block(-1,33,-1,STATIONARY_WATER:0)
Block(-1,33,0,STATIONARY_WATER:0)
Block(-1,33,1,STATIONARY_WATER:0)
Block(-1,33,2,STATIONARY_WATER:0)
Block(-1,33,3,STONE:3)
Block(-1,33,4,STONE:3)
Block(-1,33,5,STONE:5)
Block(-1,33,6,OBSIDIAN:0)
Block(-1,33,7,OBSIDIAN:0)
Block(-1,33,8,OBSIDIAN:0)
Block(-1,34,-7,STONE:5)
Block(-1,34,-6,STONE:5)
Block(-1,34,-5,STONE:5)
Block(-1,34,-4,STONE:3)
Block(-1,34,-3,STONE:3)
Block(-1,34,4,STONE:3)
Block(-1,34,5,STONE:5)
Block(-1,34,6,OBSIDIAN:0)
Block(-1,34,7,OBSIDIAN:0)
Block(-1,34,8,OBSIDIAN:0)
Block(-1,35,-7,STONE:5)
Block(-1,35,-6,STONE:5)
Block(-1,35,-5,STONE:5)
Block(-1,35,-4,STONE:3)
Block(-1,35,4,STONE:3)
Block(-1,35,5,STONE:5)
Block(-1,35,6,STONE:5)
Block(-1,35,7,OBSIDIAN:0)
Block(-1,35,8,OBSIDIAN:0)
Block(-1,36,-7,STONE:5)
Block(-1,36,-6,STONE:5)
Block(-1,36,-5,STONE:5)
Block(-1,36,-4,GRASS:0)
Block(-1,36,4,STONE:3)
Block(-1,36,5,STONE:5)
Block(-1,36,6,STONE:5)
Block(-1,36,7,STONE:5)
Block(-1,36,8,OBSIDIAN:0)
Block(-1,37,-7,STONE:5)
Block(-1,37,-6,STONE:5)
Block(-1,37,-5,GRASS:0)
Block(-1,37,4,STONE:5)
Block(-1,37,5,STONE:5)
Block(-1,37,6,STONE:5)
Block(-1,37,7,STONE:5)
Block(-1,37,8,OBSIDIAN:0)
Block(-1,38,-7,GRASS:0)
Block(-1,38,-6,STONE:5)
Block(-1,38,6,STONE:5)
Block(-1,38,7,STONE:5)
Block(-1,38,8,OBSIDIAN:0)
Block(-1,74,7,OBSIDIAN:0)
Block(-1,74,8,OBSIDIAN:0)
Block(-1,75,5,OBSIDIAN:0)
Block(-1,75,6,OBSIDIAN:0)
Block(-1,75,7,OBSIDIAN:0)
Block(-1,75,8,OBSIDIAN:0)
Block(-1,76,1,OBSIDIAN:0)
Block(-1,76,2,OBSIDIAN:0)
Block(-1,76,3,OBSIDIAN:0)
Block(-1,76,4,OBSIDIAN:0)
Block(-1,76,5,OBSIDIAN:0)
Block(-1,76,6,OBSIDIAN:0)
Block(-1,76,7,OBSIDIAN:0)
Block(-1,76,8,OBSIDIAN:0)
Block(-1,77,-3,OBSIDIAN:0)
Block(-1,77,-2,OBSIDIAN:0)
Block(-1,77,0,OBSIDIAN:0)
Block(-1,77,1,OBSIDIAN:0)
Block(-1,77,2,OBSIDIAN:0)
Block(-1,77,3,OBSIDIAN:0)
Block(-1,77,4,OBSIDIAN:0)
Block(-1,77,5,OBSIDIAN:0)
Block(-1,77,6,OBSIDIAN:0)
Block(-1,77,7,OBSIDIAN:0)
Block(-1,77,8,OBSIDIAN:0)
Block(-1,78,-7,OBSIDIAN:0)
Block(-1,78,-6,OBSIDIAN:0)
Block(-1,78,-5,OBSIDIAN:0)
Block(-1,78,-4,OBSIDIAN:0)
Block(-1,78,-3,OBSIDIAN:0)
Block(-1,78,-2,OBSIDIAN:0)
Block(-1,78,-1,OBSIDIAN:0)
Block(-1,78,0,OBSIDIAN:0)
Block(-1,78,1,OBSIDIAN:0)
Block(-1,78,2,OBSIDIAN:0)
Block(-1,78,3,OBSIDIAN:0)
Block(-1,78,4,OBSIDIAN:0)
Block(-1,78,5,OBSIDIAN:0)
Block(-1,78,6,OBSIDIAN:0)
Block(-1,78,7,OBSIDIAN:0)
Block(-1,78,8,OBSIDIAN:0)
Block(-1,79,-7,OBSIDIAN:0)
Block(-1,79,-6,OBSIDIAN:0)
Block(-1,79,-5,OBSIDIAN:0)
Block(-1,79,-4,OBSIDIAN:0)
Block(-1,79,-3,OBSIDIAN:0)
Block(-1,79,-2,OBSIDIAN:0)
Block(-1,79,-1,OBSIDIAN:0)
Block(-1,79,0,OBSIDIAN:0)
Block(-1,79,1,OBSIDIAN:0)
Block(-1,79,2,OBSIDIAN:0)
Block(-1,79,3,OBSIDIAN:0)
Block(-1,79,4,OBSIDIAN:0)
Block(-1,79,5,OBSIDIAN:0)
Block(-1,79,6,OBSIDIAN:0)
Block(-1,79,7,OBSIDIAN:0)
Block(-1,79,8,OBSIDIAN:0)
Block(-1,80,-7,OBSIDIAN:0)
Block(-1,80,-6,OBSIDIAN:0)
Block(-1,80,-5,OBSIDIAN:0)
Block(-1,80,-4,OBSIDIAN:0)
Block(-1,80,-3,OBSIDIAN:0)
Block(-1,80,-2,OBSIDIAN:0)
Block(-1,80,-1,OBSIDIAN:0)
Block(-1,80,0,OBSIDIAN:0)
Block(-1,80,1,OBSIDIAN:0)
Block(-1,80,2,OBSIDIAN:0)
Block(-1,80,3,OBSIDIAN:0)
Block(-1,80,4,OBSIDIAN:0)
Block(-1,80,5,OBSIDIAN:0)
Block(-1,80,6,OBSIDIAN:0)
Block(-1,80,7,OBSIDIAN:0)
Block(-1,80,8,OBSIDIAN:0)
Block(-1,81,-7,OBSIDIAN:0)
Block(-1,81,-6,OBSIDIAN:0)
Block(-1,81,-5,OBSIDIAN:0)
Block(-1,81,-4,OBSIDIAN:0)
Block(-1,81,-3,OBSIDIAN:0)
Block(-1,81,-2,OBSIDIAN:0)
Block(-1,81,-1,OBSIDIAN:0)
Block(-1,81,0,OBSIDIAN:0)
Block(-1,81,1,OBSIDIAN:0)
Block(-1,81,2,OBSIDIAN:0)
Block(-1,81,3,OBSIDIAN:0)
Block(-1,81,4,OBSIDIAN:0)
Block(-1,81,5,OBSIDIAN:0)
Block(-1,81,6,OBSIDIAN:0)
Block(-1,81,7,OBSIDIAN:0)
Block(-1,81,8,OBSIDIAN:0)
Block(-1,82,-7,OBSIDIAN:0)
Block(-1,82,-6,OBSIDIAN:0)
Block(-1,82,-5,OBSIDIAN:0)
Block(-1,82,-4,OBSIDIAN:0)
Block(-1,82,-3,OBSIDIAN:0)
Block(-1,82,-2,OBSIDIAN:0)
Block(-1,82,-1,OBSIDIAN:0)
Block(-1,82,0,OBSIDIAN:0)
Block(-1,82,1,OBSIDIAN:0)
Block(-1,82,2,OBSIDIAN:0)
Block(-1,82,3,OBSIDIAN:0)
Block(-1,82,4,OBSIDIAN:0)
Block(-1,82,5,OBSIDIAN:0)
Block(-1,82,6,OBSIDIAN:0)
Block(-1,82,7,OBSIDIAN:0)
Block(-1,82,8,OBSIDIAN:0)
Block(-1,83,-7,OBSIDIAN:0)
Block(-1,83,-6,OBSIDIAN:0)
Block(-1,83,-5,OBSIDIAN:0)
Block(-1,83,-4,OBSIDIAN:0)
Block(-1,83,-3,OBSIDIAN:0)
Block(-1,83,-2,OBSIDIAN:0)
Block(-1,83,-1,OBSIDIAN:0)
Block(-1,83,0,OBSIDIAN:0)
Block(-1,83,1,OBSIDIAN:0)
Block(-1,83,2,OBSIDIAN:0)
Block(-1,83,3,OBSIDIAN:0)
Block(-1,83,4,OBSIDIAN:0)
Block(-1,83,5,OBSIDIAN:0)
Block(-1,83,6,OBSIDIAN:0)
Block(-1,83,7,OBSIDIAN:0)
Block(-1,83,8,OBSIDIAN:0)
Block(-1,84,-7,OBSIDIAN:0)
Block(-1,84,-6,OBSIDIAN:0)
Block(-1,84,-5,OBSIDIAN:0)
Block(-1,84,-4,OBSIDIAN:0)
Block(-1,84,-3,OBSIDIAN:0)
Block(-1,84,-2,OBSIDIAN:0)
Block(-1,84,-1,OBSIDIAN:0)
Block(-1,84,0,OBSIDIAN:0)
Block(-1,84,1,OBSIDIAN:0)
Block(-1,84,2,OBSIDIAN:0)
Block(-1,84,3,OBSIDIAN:0)
Block(-1,84,4,OBSIDIAN:0)
Block(-1,84,5,OBSIDIAN:0)
Block(-1,84,6,OBSIDIAN:0)
Block(-1,84,7,OBSIDIAN:0)
Block(-1,84,8,OBSIDIAN:0)
Block(-1,85,-7,OBSIDIAN:0)
Block(-1,85,-6,OBSIDIAN:0)
Block(-1,85,-5,OBSIDIAN:0)
Block(-1,85,-4,OBSIDIAN:0)
Block(-1,85,-3,OBSIDIAN:0)
Block(-1,85,-2,OBSIDIAN:0)
Block(-1,85,-1,OBSIDIAN:0)
Block(-1,85,0,OBSIDIAN:0)
Block(-1,85,1,OBSIDIAN:0)
Block(-1,85,2,OBSIDIAN:0)
Block(-1,85,3,OBSIDIAN:0)
Block(-1,85,4,OBSIDIAN:0)
Block(-1,85,5,OBSIDIAN:0)
Block(-1,85,6,OBSIDIAN:0)
Block(-1,85,7,OBSIDIAN:0)
Block(-1,85,8,OBSIDIAN:0)
Block(-1,86,-7,OBSIDIAN:0)
Block(-1,86,-6,OBSIDIAN:0)
Block(-1,86,-5,OBSIDIAN:0)
Block(-1,86,-4,OBSIDIAN:0)
Block(-1,86,-3,OBSIDIAN:0)
Block(-1,86,-2,OBSIDIAN:0)
Block(-1,86,-1,OBSIDIAN:0)
Block(-1,86,0,OBSIDIAN:0)
Block(-1,86,1,OBSIDIAN:0)
Block(-1,86,2,OBSIDIAN:0)
Block(-1,86,3,OBSIDIAN:0)
Block(-1,86,4,OBSIDIAN:0)
Block(-1,86,5,OBSIDIAN:0)
Block(-1,86,6,OBSIDIAN:0)
Block(-1,86,7,OBSIDIAN:0)
Block(-1,86,8,OBSIDIAN:0)
Block(-1,87,-7,OBSIDIAN:0)
Block(-1,87,-6,OBSIDIAN:0)
Block(-1,87,-5,OBSIDIAN:0)
Block(-1,87,-4,OBSIDIAN:0)
Block(-1,87,-3,OBSIDIAN:0)
Block(-1,87,-2,OBSIDIAN:0)
Block(-1,87,-1,OBSIDIAN:0)
Block(-1,87,0,OBSIDIAN:0)
Block(-1,87,1,OBSIDIAN:0)
Block(-1,87,2,OBSIDIAN:0)
Block(-1,87,3,OBSIDIAN:0)
Block(-1,87,4,OBSIDIAN:0)
Block(-1,87,5,OBSIDIAN:0)
Block(-1,87,6,OBSIDIAN:0)
Block(-1,87,7,OBSIDIAN:0)
Block(-1,87,8,OBSIDIAN:0)
Block(-1,88,-7,OBSIDIAN:0)
Block(-1,88,-6,OBSIDIAN:0)
Block(-1,88,-5,OBSIDIAN:0)
Block(-1,88,-4,OBSIDIAN:0)
Block(-1,88,-3,OBSIDIAN:0)
Block(-1,88,-2,OBSIDIAN:0)
Block(-1,88,-1,OBSIDIAN:0)
Block(-1,88,0,OBSIDIAN:0)
Block(-1,88,1,OBSIDIAN:0)
Block(-1,88,2,OBSIDIAN:0)
Block(-1,88,3,OBSIDIAN:0)
Block(-1,88,4,OBSIDIAN:0)
Block(-1,88,5,OBSIDIAN:0)
Block(-1,88,6,OBSIDIAN:0)
Block(-1,88,7,OBSIDIAN:0)
Block(-1,88,8,OBSIDIAN:0)
Block(-1,89,-7,OBSIDIAN:0)
Block(-1,89,-6,OBSIDIAN:0)
Block(-1,89,-5,OBSIDIAN:0)
Block(-1,89,-4,OBSIDIAN:0)
Block(-1,89,-3,OBSIDIAN:0)
Block(-1,89,-2,STONE:3)
Block(-1,89,-1,OBSIDIAN:0)
Block(-1,89,0,OBSIDIAN:0)
Block(-1,89,1,OBSIDIAN:0)
Block(-1,89,2,OBSIDIAN:0)
Block(-1,89,3,OBSIDIAN:0)
Block(-1,89,4,OBSIDIAN:0)
Block(-1,89,5,OBSIDIAN:0)
Block(-1,89,6,OBSIDIAN:0)
Block(-1,89,7,OBSIDIAN:0)
Block(-1,89,8,OBSIDIAN:0)
Block(-1,90,-7,OBSIDIAN:0)
Block(-1,90,-6,OBSIDIAN:0)
Block(-1,90,-5,OBSIDIAN:0)
Block(-1,90,-4,OBSIDIAN:0)
Block(-1,90,-3,STONE:3)
Block(-1,90,-2,OBSIDIAN:0)
Block(-1,90,-1,OBSIDIAN:0)
Block(-1,90,0,OBSIDIAN:0)
Block(-1,90,1,OBSIDIAN:0)
Block(-1,90,2,OBSIDIAN:0)
Block(-1,90,3,MAGMA:0)
Block(-1,90,4,MAGMA:0)
Block(-1,90,5,MAGMA:0)
Block(-1,90,6,MAGMA:0)
Block(-1,90,7,OBSIDIAN:0)
Block(-1,90,8,OBSIDIAN:0)
Block(-1,91,-7,OBSIDIAN:0)
Block(-1,91,-6,OBSIDIAN:0)
Block(-1,91,-5,OBSIDIAN:0)
Block(-1,91,-4,STONE:3)
Block(-1,91,-3,OBSIDIAN:0)
Block(-1,91,-2,OBSIDIAN:0)
Block(-1,91,-1,OBSIDIAN:0)
Block(-1,91,0,OBSIDIAN:0)
Block(-1,91,1,OBSIDIAN:0)
Block(-1,91,2,MAGMA:0)
Block(-1,91,3,MAGMA:0)
Block(-1,91,4,MAGMA:0)
Block(-1,91,5,MAGMA:0)
Block(-1,91,6,MAGMA:0)
Block(-1,91,7,MAGMA:0)
Block(-1,92,-7,OBSIDIAN:0)
Block(-1,92,-6,OBSIDIAN:0)
Block(-1,92,-5,STONE:3)
Block(-1,92,-4,STONE:3)
Block(-1,92,-3,OBSIDIAN:0)
Block(-1,92,-2,OBSIDIAN:0)
Block(-1,92,-1,OBSIDIAN:0)
Block(-1,92,0,OBSIDIAN:0)
Block(-1,92,1,MAGMA:0)
Block(-1,92,2,MAGMA:0)
Block(-1,92,3,MAGMA:0)
Block(-1,92,4,MAGMA:0)
Block(-1,92,5,MAGMA:0)
Block(-1,92,6,MAGMA:0)
Block(-1,93,-7,OBSIDIAN:0)
Block(-1,93,-6,OBSIDIAN:0)
Block(-1,93,-5,STONE:3)
Block(-1,93,-4,STONE:3)
Block(-1,93,-3,OBSIDIAN:0)
Block(-1,93,-2,OBSIDIAN:0)
Block(-1,93,-1,OBSIDIAN:0)
Block(-1,93,0,OBSIDIAN:0)
Block(-1,93,1,MAGMA:0)
Block(-1,93,2,MAGMA:0)
Block(-1,93,3,MAGMA:0)
Block(-1,94,-7,OBSIDIAN:0)
Block(-1,94,-6,OBSIDIAN:0)
Block(-1,94,-5,STONE:3)
Block(-1,94,-4,STONE:3)
Block(-1,94,-3,OBSIDIAN:0)
Block(-1,94,-2,OBSIDIAN:0)
Block(-1,94,-1,OBSIDIAN:0)
Block(-1,94,0,OBSIDIAN:0)
Block(-1,95,-7,OBSIDIAN:0)
Block(-1,95,-6,OBSIDIAN:0)
Block(-1,95,-5,STONE:3)
Block(-1,95,-4,STONE:3)
Block(-1,95,-3,OBSIDIAN:0)
Block(-1,95,-2,OBSIDIAN:0)
Block(-1,95,-1,OBSIDIAN:0)
Block(-1,95,0,OBSIDIAN:0)
Block(-1,96,-7,STONE:3)
Block(-1,96,-6,STONE:3)
Block(-1,96,-5,STONE:3)
Block(-1,96,-4,STONE:3)
Block(-1,96,-3,STONE:3)
Block(-1,96,-2,OBSIDIAN:0)
Block(-1,96,-1,OBSIDIAN:0)
Block(-1,96,0,OBSIDIAN:0)
Block(-1,97,-7,STONE:3)
Block(-1,97,-6,STONE:3)
Block(-1,97,-5,STONE:3)
Block(-1,97,-4,STONE:3)
Block(-1,97,-3,STONE:3)
Block(-1,97,-2,STONE:3)
Block(-1,97,-1,OBSIDIAN:0)
Block(-1,97,0,OBSIDIAN:0)
Block(-1,98,-7,STONE:3)
Block(-1,98,-6,STONE:3)
Block(-1,98,-5,STONE:3)
Block(-1,98,-4,STONE:3)
Block(-1,98,-3,STONE:3)
Block(-1,98,-2,STONE:3)
Block(-1,98,-1,STONE:3)
Block(-1,98,0,OBSIDIAN:0)
Block(-1,99,-7,STONE:3)
Block(-1,99,-6,STONE:3)
Block(-1,99,-5,STONE:3)
Block(-1,99,-4,STONE:3)
Block(-1,99,-3,STONE:3)
Block(-1,99,-2,STONE:3)
Block(-1,99,-1,STONE:3)
Block(-1,100,-7,STONE:3)
Block(-1,100,-6,STONE:3)
Block(-1,100,-5,STONE:3)
