
#######################################################################
# +-----------------------------------------------------------------+ #
# |                            BO4 object                           | #
# +-----------------------------------------------------------------+ #
#######################################################################

Author: NLBlackEagle

Description: No description given

SettingsMode: WriteWithoutComments


#######################################################################
# +-----------------------------------------------------------------+ #
# |                          Main settings                          | #
# +-----------------------------------------------------------------+ #
#######################################################################

FixedRotation: 

Frequency: 0

SpawnHeight: highestBlock

UseCenterForHighestBlock: true

##############################
# Height Limits for the BO4. #
##############################

MinHeight: 0

MaxHeight: 255

InheritBO3: 

InheritBO3Rotation: NORTH

OverrideChildSettings: true

OverrideParentHeight: false

CanOverride: false

BranchFrequency: 0

BranchFrequencyGroup: 

MustBeBelowOther: false

MustBeInside: 

CannotBeInside: 

ReplacesBO3: 

MustBeInsideWorldBorders: false

CanSpawnOnWater: true

SpawnOnWaterOnly: false

SpawnUnderWater: false

SpawnAtWaterLevel: false

HeightOffset: 0

RemoveAir: true

ReplaceAbove: 

ReplaceBelow: 

ReplaceWithBiomeBlocks: true

ReplaceWithSurfaceBlock: GRASS

ReplaceWithGroundBlock: DIRT

ReplaceWithStoneBlock: STONE

SmoothRadius: 0

SmoothHeightOffset: 0

SmoothStartTop: false

SmoothStartWood: false

SmoothingSurfaceBlock: 

SmoothingGroundBlock: 

BO3Group: 

IsSpawnPoint: false

DoReplaceBlocks: true


#######################################################################
# +-----------------------------------------------------------------+ #
# |                              Blocks                             | #
# +-----------------------------------------------------------------+ #
#######################################################################

B(-8,2,-2,minecraft:diorite)
B(-8,2,-1,minecraft:diorite)
B(-8,2,0,minecraft:diorite)
B(-8,2,1,minecraft:diorite)
B(-8,2,2,minecraft:obsidian)
B(-8,2,3,minecraft:obsidian)
B(-8,2,4,minecraft:magma_block)
B(-8,2,5,minecraft:magma_block)
B(-8,3,-3,minecraft:diorite)
B(-8,3,-2,minecraft:diorite)
B(-8,3,-1,minecraft:diorite)
B(-8,3,0,minecraft:diorite)
B(-8,3,1,minecraft:diorite)
B(-8,3,2,minecraft:obsidian)
B(-8,3,3,minecraft:obsidian)
B(-8,3,4,minecraft:magma_block)
B(-8,3,5,minecraft:magma_block)
B(-8,3,6,minecraft:magma_block)
B(-8,3,7,minecraft:magma_block)
B(-8,3,8,minecraft:magma_block)
B(-8,4,-7,minecraft:diorite)
B(-8,4,-6,minecraft:diorite)
B(-8,4,-5,minecraft:diorite)
B(-8,4,-4,minecraft:diorite)
B(-8,4,-3,minecraft:diorite)
B(-8,4,-2,minecraft:diorite)
B(-8,4,-1,minecraft:diorite)
B(-8,4,0,minecraft:diorite)
B(-8,4,1,minecraft:diorite)
B(-8,4,2,minecraft:obsidian)
B(-8,4,3,minecraft:obsidian)
B(-8,4,4,minecraft:obsidian)
B(-8,4,5,minecraft:magma_block)
B(-8,4,6,minecraft:magma_block)
B(-8,4,7,minecraft:magma_block)
B(-8,4,8,minecraft:magma_block)
B(-8,5,-7,minecraft:diorite)
B(-8,5,-6,minecraft:diorite)
B(-8,5,-5,minecraft:diorite)
B(-8,5,-4,minecraft:diorite)
B(-8,5,-3,minecraft:diorite)
B(-8,5,-2,minecraft:diorite)
B(-8,5,-1,minecraft:diorite)
B(-8,5,0,minecraft:diorite)
B(-8,5,1,minecraft:diorite)
B(-8,5,2,minecraft:diorite)
B(-8,5,3,minecraft:obsidian)
B(-8,5,4,minecraft:obsidian)
B(-8,5,5,minecraft:obsidian)
B(-8,5,6,minecraft:obsidian)
B(-8,5,7,minecraft:obsidian)
B(-8,5,8,minecraft:obsidian)
B(-8,6,-7,minecraft:diorite)
B(-8,6,-6,minecraft:diorite)
B(-8,6,-5,minecraft:diorite)
B(-8,6,-4,minecraft:diorite)
B(-8,6,-3,minecraft:diorite)
B(-8,6,-2,minecraft:diorite)
B(-8,6,-1,minecraft:diorite)
B(-8,6,0,minecraft:diorite)
B(-8,6,1,minecraft:diorite)
B(-8,6,2,minecraft:diorite)
B(-8,6,3,minecraft:obsidian)
B(-8,6,4,minecraft:obsidian)
B(-8,6,5,minecraft:obsidian)
B(-8,6,6,minecraft:obsidian)
B(-8,6,7,minecraft:obsidian)
B(-8,6,8,minecraft:obsidian)
B(-8,7,-7,minecraft:diorite)
B(-8,7,-6,minecraft:diorite)
B(-8,7,-5,minecraft:diorite)
B(-8,7,-4,minecraft:diorite)
B(-8,7,-3,minecraft:diorite)
B(-8,7,-2,minecraft:diorite)
B(-8,7,-1,minecraft:diorite)
B(-8,7,0,minecraft:diorite)
B(-8,7,1,minecraft:diorite)
B(-8,7,2,minecraft:obsidian)
B(-8,7,3,minecraft:obsidian)
B(-8,7,4,minecraft:obsidian)
B(-8,7,5,minecraft:obsidian)
B(-8,7,6,minecraft:obsidian)
B(-8,7,7,minecraft:obsidian)
B(-8,7,8,minecraft:obsidian)
B(-8,8,-7,minecraft:diorite)
B(-8,8,-6,minecraft:diorite)
B(-8,8,-5,minecraft:diorite)
B(-8,8,-4,minecraft:diorite)
B(-8,8,-3,minecraft:diorite)
B(-8,8,-2,minecraft:diorite)
B(-8,8,-1,minecraft:diorite)
B(-8,8,0,minecraft:diorite)
B(-8,8,1,minecraft:obsidian)
B(-8,8,2,minecraft:obsidian)
B(-8,8,3,minecraft:obsidian)
B(-8,8,4,minecraft:obsidian)
B(-8,8,5,minecraft:obsidian)
B(-8,8,6,minecraft:obsidian)
B(-8,8,7,minecraft:diorite)
B(-8,8,8,minecraft:diorite)
B(-8,9,-7,minecraft:diorite)
B(-8,9,-6,minecraft:diorite)
B(-8,9,-5,minecraft:obsidian)
B(-8,9,-4,minecraft:obsidian)
B(-8,9,-3,minecraft:obsidian)
B(-8,9,-2,minecraft:obsidian)
B(-8,9,-1,minecraft:obsidian)
B(-8,9,0,minecraft:obsidian)
B(-8,9,1,minecraft:obsidian)
B(-8,9,2,minecraft:obsidian)
B(-8,9,3,minecraft:obsidian)
B(-8,9,4,minecraft:obsidian)
B(-8,9,5,minecraft:obsidian)
B(-8,9,6,minecraft:obsidian)
B(-8,9,7,minecraft:obsidian)
B(-8,9,8,minecraft:obsidian)
B(-8,10,-7,minecraft:obsidian)
B(-8,10,-6,minecraft:obsidian)
B(-8,10,-5,minecraft:obsidian)
B(-8,10,-4,minecraft:obsidian)
B(-8,10,-3,minecraft:obsidian)
B(-8,10,-2,minecraft:obsidian)
B(-8,10,-1,minecraft:obsidian)
B(-8,10,0,minecraft:obsidian)
B(-8,10,1,minecraft:obsidian)
B(-8,10,2,minecraft:obsidian)
B(-8,10,3,minecraft:obsidian)
B(-8,10,4,minecraft:obsidian)
B(-8,10,5,minecraft:obsidian)
B(-8,10,6,minecraft:obsidian)
B(-8,10,7,minecraft:obsidian)
B(-8,10,8,minecraft:obsidian)
B(-8,11,-7,minecraft:obsidian)
B(-8,11,-6,minecraft:obsidian)
B(-8,11,-5,minecraft:obsidian)
B(-8,11,-4,minecraft:obsidian)
B(-8,11,-3,minecraft:obsidian)
B(-8,11,-2,minecraft:obsidian)
B(-8,11,-1,minecraft:obsidian)
B(-8,11,0,minecraft:obsidian)
B(-8,11,1,minecraft:obsidian)
B(-8,11,2,minecraft:obsidian)
B(-8,11,3,minecraft:obsidian)
B(-8,11,4,minecraft:obsidian)
B(-8,11,5,minecraft:obsidian)
B(-8,11,6,minecraft:obsidian)
B(-8,11,7,minecraft:obsidian)
B(-8,11,8,minecraft:obsidian)
B(-8,12,-7,minecraft:obsidian)
B(-8,12,-6,minecraft:obsidian)
B(-8,12,-5,minecraft:obsidian)
B(-8,12,-4,minecraft:obsidian)
B(-8,12,-3,minecraft:obsidian)
B(-8,12,-2,minecraft:obsidian)
B(-8,12,-1,minecraft:obsidian)
B(-8,12,0,minecraft:obsidian)
B(-8,12,1,minecraft:obsidian)
B(-8,12,2,minecraft:obsidian)
B(-8,12,3,minecraft:obsidian)
B(-8,12,4,minecraft:obsidian)
B(-8,12,5,minecraft:obsidian)
B(-8,12,6,minecraft:obsidian)
B(-8,12,7,minecraft:obsidian)
B(-8,12,8,minecraft:obsidian)
B(-8,13,-7,minecraft:obsidian)
B(-8,13,-6,minecraft:obsidian)
B(-8,13,-5,minecraft:obsidian)
B(-8,13,-4,minecraft:obsidian)
B(-8,13,-3,minecraft:obsidian)
B(-8,13,-2,minecraft:obsidian)
B(-8,13,-1,minecraft:obsidian)
B(-8,13,0,minecraft:obsidian)
B(-8,13,1,minecraft:obsidian)
B(-8,13,2,minecraft:obsidian)
B(-8,13,3,minecraft:obsidian)
B(-8,13,4,minecraft:obsidian)
B(-8,13,5,minecraft:obsidian)
B(-8,13,6,minecraft:obsidian)
B(-8,13,7,minecraft:obsidian)
B(-8,13,8,minecraft:obsidian)
B(-8,14,-7,minecraft:obsidian)
B(-8,14,-6,minecraft:obsidian)
B(-8,14,-5,minecraft:diorite)
B(-8,14,-4,minecraft:diorite)
B(-8,14,-3,minecraft:diorite)
B(-8,14,-2,minecraft:diorite)
B(-8,14,-1,minecraft:obsidian)
B(-8,14,0,minecraft:obsidian)
B(-8,14,1,minecraft:obsidian)
B(-8,14,2,minecraft:obsidian)
B(-8,14,3,minecraft:obsidian)
B(-8,14,4,minecraft:obsidian)
B(-8,14,5,minecraft:obsidian)
B(-8,14,6,minecraft:obsidian)
B(-8,14,7,minecraft:obsidian)
B(-8,14,8,minecraft:obsidian)
B(-8,15,-7,minecraft:obsidian)
B(-8,15,-6,minecraft:obsidian)
B(-8,15,-5,minecraft:diorite)
B(-8,15,-4,minecraft:diorite)
B(-8,15,-3,minecraft:diorite)
B(-8,15,-2,minecraft:diorite)
B(-8,15,-1,minecraft:obsidian)
B(-8,15,0,minecraft:obsidian)
B(-8,15,1,minecraft:obsidian)
B(-8,15,2,minecraft:obsidian)
B(-8,15,3,minecraft:obsidian)
B(-8,15,4,minecraft:obsidian)
B(-8,15,5,minecraft:obsidian)
B(-8,15,6,minecraft:obsidian)
B(-8,15,7,minecraft:obsidian)
B(-8,15,8,minecraft:obsidian)
B(-8,16,-7,minecraft:obsidian)
B(-8,16,-6,minecraft:obsidian)
B(-8,16,-5,minecraft:diorite)
B(-8,16,-4,minecraft:diorite)
B(-8,16,-3,minecraft:diorite)
B(-8,16,-2,minecraft:diorite)
B(-8,16,-1,minecraft:obsidian)
B(-8,16,0,minecraft:obsidian)
B(-8,16,1,minecraft:obsidian)
B(-8,16,2,minecraft:obsidian)
B(-8,16,3,minecraft:obsidian)
B(-8,16,4,minecraft:obsidian)
B(-8,16,5,minecraft:obsidian)
B(-8,16,6,minecraft:obsidian)
B(-8,16,7,minecraft:obsidian)
B(-8,16,8,minecraft:obsidian)
B(-8,17,-7,minecraft:obsidian)
B(-8,17,-4,minecraft:obsidian)
B(-8,17,-3,minecraft:obsidian)
B(-8,17,2,minecraft:obsidian)
B(-8,17,3,minecraft:obsidian)
B(-8,17,4,minecraft:obsidian)
B(-8,17,5,minecraft:obsidian)
B(-8,17,6,minecraft:obsidian)
B(-8,17,7,minecraft:obsidian)
B(-8,17,8,minecraft:obsidian)
B(-8,18,3,minecraft:obsidian)
B(-8,18,4,minecraft:obsidian)
B(-8,18,5,minecraft:obsidian)
B(-8,18,6,minecraft:obsidian)
B(-8,18,7,minecraft:obsidian)
B(-8,18,8,minecraft:obsidian)
B(-8,19,3,minecraft:obsidian)
B(-8,19,4,minecraft:obsidian)
B(-8,19,5,minecraft:obsidian)
B(-8,19,6,minecraft:obsidian)
B(-8,19,7,minecraft:obsidian)
B(-8,19,8,minecraft:obsidian)
B(-8,20,4,minecraft:obsidian)
B(-8,20,5,minecraft:obsidian)
B(-8,20,6,minecraft:obsidian)
B(-8,20,7,minecraft:obsidian)
B(-8,20,8,minecraft:obsidian)
B(-8,21,5,minecraft:obsidian)
B(-8,21,6,minecraft:obsidian)
B(-8,21,7,minecraft:obsidian)
B(-8,21,8,minecraft:obsidian)
B(-8,22,5,minecraft:diorite)
B(-8,22,6,minecraft:diorite)
B(-8,22,7,minecraft:obsidian)
B(-8,22,8,minecraft:obsidian)
B(-8,23,6,minecraft:diorite)
B(-8,23,7,minecraft:diorite)
B(-8,23,8,minecraft:obsidian)
B(-8,24,6,minecraft:diorite)
B(-8,24,7,minecraft:diorite)
B(-8,24,8,minecraft:diorite)
B(-8,25,6,minecraft:diorite)
B(-8,25,7,minecraft:diorite)
B(-8,25,8,minecraft:diorite)
B(-8,26,7,minecraft:diorite)
B(-8,26,8,minecraft:diorite)
B(-8,27,8,minecraft:obsidian)
B(-8,28,8,minecraft:obsidian)
B(-8,29,8,minecraft:diorite)
B(-8,30,8,minecraft:diorite)
B(-8,57,7,minecraft:obsidian)
B(-8,57,8,minecraft:obsidian)
B(-8,58,-7,minecraft:obsidian)
B(-8,58,-6,minecraft:obsidian)
B(-8,58,-5,minecraft:obsidian)
B(-8,58,-4,minecraft:obsidian)
B(-8,58,-3,minecraft:obsidian)
B(-8,58,-2,minecraft:obsidian)
B(-8,58,-1,minecraft:obsidian)
B(-8,58,0,minecraft:obsidian)
B(-8,58,3,minecraft:obsidian)
B(-8,58,4,minecraft:obsidian)
B(-8,58,5,minecraft:obsidian)
B(-8,58,6,minecraft:obsidian)
B(-8,58,7,minecraft:obsidian)
B(-8,58,8,minecraft:obsidian)
B(-8,59,-7,minecraft:obsidian)
B(-8,59,-6,minecraft:obsidian)
B(-8,59,-5,minecraft:obsidian)
B(-8,59,-4,minecraft:obsidian)
B(-8,59,-3,minecraft:obsidian)
B(-8,59,-2,minecraft:obsidian)
B(-8,59,-1,minecraft:obsidian)
B(-8,59,0,minecraft:obsidian)
B(-8,59,1,minecraft:obsidian)
B(-8,59,2,minecraft:obsidian)
B(-8,59,3,minecraft:obsidian)
B(-8,59,4,minecraft:obsidian)
B(-8,59,5,minecraft:obsidian)
B(-8,59,6,minecraft:obsidian)
B(-8,59,7,minecraft:obsidian)
B(-8,59,8,minecraft:obsidian)
B(-8,60,-7,minecraft:obsidian)
B(-8,60,-6,minecraft:obsidian)
B(-8,60,-5,minecraft:obsidian)
B(-8,60,-4,minecraft:obsidian)
B(-8,60,-3,minecraft:obsidian)
B(-8,60,-2,minecraft:obsidian)
B(-8,60,-1,minecraft:obsidian)
B(-8,60,0,minecraft:obsidian)
B(-8,60,1,minecraft:obsidian)
B(-8,60,2,minecraft:obsidian)
B(-8,60,3,minecraft:obsidian)
B(-8,60,4,minecraft:obsidian)
B(-8,60,5,minecraft:obsidian)
B(-8,60,6,minecraft:obsidian)
B(-8,60,7,minecraft:obsidian)
B(-8,60,8,minecraft:obsidian)
B(-8,61,-7,minecraft:obsidian)
B(-8,61,-6,minecraft:obsidian)
B(-8,61,-5,minecraft:obsidian)
B(-8,61,-4,minecraft:obsidian)
B(-8,61,-3,minecraft:obsidian)
B(-8,61,-2,minecraft:obsidian)
B(-8,61,-1,minecraft:obsidian)
B(-8,61,0,minecraft:obsidian)
B(-8,61,1,minecraft:obsidian)
B(-8,61,2,minecraft:obsidian)
B(-8,61,3,minecraft:obsidian)
B(-8,61,4,minecraft:obsidian)
B(-8,61,5,minecraft:obsidian)
B(-8,61,6,minecraft:obsidian)
B(-8,61,7,minecraft:obsidian)
B(-8,61,8,minecraft:obsidian)
B(-8,62,-7,minecraft:obsidian)
B(-8,62,-6,minecraft:obsidian)
B(-8,62,-5,minecraft:obsidian)
B(-8,62,-4,minecraft:obsidian)
B(-8,62,-3,minecraft:obsidian)
B(-8,62,-2,minecraft:obsidian)
B(-8,62,-1,minecraft:obsidian)
B(-8,62,0,minecraft:obsidian)
B(-8,62,1,minecraft:obsidian)
B(-8,62,2,minecraft:obsidian)
B(-8,62,3,minecraft:obsidian)
B(-8,62,4,minecraft:obsidian)
B(-8,62,5,minecraft:obsidian)
B(-8,62,6,minecraft:obsidian)
B(-8,62,7,minecraft:obsidian)
B(-8,62,8,minecraft:obsidian)
B(-8,63,-7,minecraft:obsidian)
B(-8,63,-6,minecraft:obsidian)
B(-8,63,-5,minecraft:obsidian)
B(-8,63,-4,minecraft:obsidian)
B(-8,63,-3,minecraft:obsidian)
B(-8,63,-2,minecraft:obsidian)
B(-8,63,-1,minecraft:obsidian)
B(-8,63,0,minecraft:obsidian)
B(-8,63,1,minecraft:obsidian)
B(-8,63,2,minecraft:obsidian)
B(-8,63,3,minecraft:obsidian)
B(-8,63,4,minecraft:obsidian)
B(-8,63,5,minecraft:obsidian)
B(-8,63,6,minecraft:obsidian)
B(-8,63,7,minecraft:obsidian)
B(-8,63,8,minecraft:obsidian)
B(-8,64,-7,minecraft:obsidian)
B(-8,64,-6,minecraft:obsidian)
B(-8,64,-5,minecraft:obsidian)
B(-8,64,-4,minecraft:obsidian)
B(-8,64,-3,minecraft:obsidian)
B(-8,64,-2,minecraft:obsidian)
B(-8,64,-1,minecraft:obsidian)
B(-8,64,0,minecraft:obsidian)
B(-8,64,1,minecraft:obsidian)
B(-8,64,2,minecraft:obsidian)
B(-8,64,3,minecraft:obsidian)
B(-8,64,4,minecraft:obsidian)
B(-8,64,5,minecraft:obsidian)
B(-8,64,6,minecraft:obsidian)
B(-8,64,7,minecraft:obsidian)
B(-8,64,8,minecraft:obsidian)
B(-8,65,-7,minecraft:obsidian)
B(-8,65,-6,minecraft:obsidian)
B(-8,65,-5,minecraft:obsidian)
B(-8,65,-4,minecraft:obsidian)
B(-8,65,-3,minecraft:obsidian)
B(-8,65,-2,minecraft:obsidian)
B(-8,65,-1,minecraft:obsidian)
B(-8,65,0,minecraft:obsidian)
B(-8,65,1,minecraft:obsidian)
B(-8,65,2,minecraft:obsidian)
B(-8,65,3,minecraft:obsidian)
B(-8,65,4,minecraft:obsidian)
B(-8,65,5,minecraft:obsidian)
B(-8,65,6,minecraft:obsidian)
B(-8,65,7,minecraft:obsidian)
B(-8,65,8,minecraft:obsidian)
B(-8,66,-7,minecraft:obsidian)
B(-8,66,-6,minecraft:obsidian)
B(-8,66,-5,minecraft:obsidian)
B(-8,66,-4,minecraft:obsidian)
B(-8,66,-3,minecraft:obsidian)
B(-8,66,-2,minecraft:obsidian)
B(-8,66,-1,minecraft:obsidian)
B(-8,66,0,minecraft:obsidian)
B(-8,66,1,minecraft:obsidian)
B(-8,66,2,minecraft:obsidian)
B(-8,66,3,minecraft:obsidian)
B(-8,66,4,minecraft:obsidian)
B(-8,66,5,minecraft:obsidian)
B(-8,66,6,minecraft:obsidian)
B(-8,66,7,minecraft:obsidian)
B(-8,66,8,minecraft:obsidian)
B(-8,67,-7,minecraft:obsidian)
B(-8,67,-6,minecraft:obsidian)
B(-8,67,-5,minecraft:obsidian)
B(-8,67,-4,minecraft:obsidian)
B(-8,67,-3,minecraft:obsidian)
B(-8,67,-2,minecraft:obsidian)
B(-8,67,-1,minecraft:obsidian)
B(-8,67,0,minecraft:obsidian)
B(-8,67,1,minecraft:obsidian)
B(-8,67,2,minecraft:obsidian)
B(-8,67,3,minecraft:obsidian)
B(-8,67,4,minecraft:obsidian)
B(-8,67,5,minecraft:obsidian)
B(-8,67,6,minecraft:obsidian)
B(-8,67,7,minecraft:obsidian)
B(-8,67,8,minecraft:obsidian)
B(-8,68,-7,minecraft:obsidian)
B(-8,68,-6,minecraft:obsidian)
B(-8,68,-5,minecraft:obsidian)
B(-8,68,-4,minecraft:obsidian)
B(-8,68,-3,minecraft:obsidian)
B(-8,68,-2,minecraft:obsidian)
B(-8,68,-1,minecraft:obsidian)
B(-8,68,0,minecraft:obsidian)
B(-8,68,1,minecraft:obsidian)
B(-8,68,2,minecraft:obsidian)
B(-8,68,3,minecraft:obsidian)
B(-8,68,4,minecraft:obsidian)
B(-8,68,5,minecraft:obsidian)
B(-8,68,6,minecraft:obsidian)
B(-8,68,7,minecraft:obsidian)
B(-8,68,8,minecraft:obsidian)
B(-8,69,-7,minecraft:obsidian)
B(-8,69,-6,minecraft:obsidian)
B(-8,69,-5,minecraft:obsidian)
B(-8,69,-4,minecraft:obsidian)
B(-8,69,-3,minecraft:obsidian)
B(-8,69,-2,minecraft:obsidian)
B(-8,69,-1,minecraft:obsidian)
B(-8,69,0,minecraft:obsidian)
B(-8,69,1,minecraft:obsidian)
B(-8,69,2,minecraft:obsidian)
B(-8,69,3,minecraft:obsidian)
B(-8,69,4,minecraft:obsidian)
B(-8,69,5,minecraft:obsidian)
B(-8,69,6,minecraft:magma_block)
B(-8,69,7,minecraft:magma_block)
B(-8,69,8,minecraft:magma_block)
B(-8,70,-7,minecraft:obsidian)
B(-8,70,-6,minecraft:obsidian)
B(-8,70,-5,minecraft:obsidian)
B(-8,70,-4,minecraft:obsidian)
B(-8,70,-3,minecraft:obsidian)
B(-8,70,-2,minecraft:obsidian)
B(-8,70,-1,minecraft:obsidian)
B(-8,70,0,minecraft:obsidian)
B(-8,70,1,minecraft:obsidian)
B(-8,70,2,minecraft:obsidian)
B(-8,70,3,minecraft:obsidian)
B(-8,70,4,minecraft:obsidian)
B(-8,70,5,minecraft:magma_block)
B(-8,70,6,minecraft:magma_block)
B(-8,70,7,minecraft:magma_block)
B(-8,70,8,minecraft:magma_block)
B(-8,71,-7,minecraft:obsidian)
B(-8,71,-6,minecraft:obsidian)
B(-8,71,-5,minecraft:obsidian)
B(-8,71,-4,minecraft:obsidian)
B(-8,71,-3,minecraft:obsidian)
B(-8,71,-2,minecraft:obsidian)
B(-8,71,-1,minecraft:obsidian)
B(-8,71,0,minecraft:andesite)
B(-8,71,1,minecraft:obsidian)
B(-8,71,2,minecraft:obsidian)
B(-8,71,3,minecraft:obsidian)
B(-8,71,4,minecraft:obsidian)
B(-8,71,5,minecraft:magma_block)
B(-8,71,6,minecraft:magma_block)
B(-8,71,7,minecraft:magma_block)
B(-8,71,8,minecraft:magma_block)
B(-8,72,-7,minecraft:obsidian)
B(-8,72,-6,minecraft:obsidian)
B(-8,72,-5,minecraft:obsidian)
B(-8,72,-4,minecraft:obsidian)
B(-8,72,-3,minecraft:diorite)
B(-8,72,-2,minecraft:diorite)
B(-8,72,-1,minecraft:andesite)
B(-8,72,1,minecraft:obsidian)
B(-8,72,2,minecraft:obsidian)
B(-8,72,4,minecraft:obsidian)
B(-8,72,5,minecraft:magma_block)
B(-8,72,6,minecraft:magma_block)
B(-8,72,7,minecraft:magma_block)
B(-8,72,8,minecraft:magma_block)
B(-8,73,-7,minecraft:obsidian)
B(-8,73,-6,minecraft:obsidian)
B(-8,73,-5,minecraft:diorite)
B(-8,73,-4,minecraft:diorite)
B(-8,73,-3,minecraft:andesite)
B(-8,73,-2,minecraft:andesite)
B(-8,74,-7,minecraft:diorite)
B(-8,74,-6,minecraft:diorite)
B(-8,74,-5,minecraft:diorite)
B(-8,74,-4,minecraft:andesite)
B(-8,75,-7,minecraft:diorite)
B(-8,75,-6,minecraft:andesite)
B(-8,75,-5,minecraft:andesite)
B(-8,76,-7,minecraft:diorite)
B(-8,77,-7,minecraft:andesite)
B(-7,2,-2,minecraft:diorite)
B(-7,2,-1,minecraft:diorite)
B(-7,2,0,minecraft:diorite)
B(-7,2,1,minecraft:diorite)
B(-7,2,2,minecraft:obsidian)
B(-7,2,3,minecraft:obsidian)
B(-7,2,4,minecraft:obsidian)
B(-7,2,5,minecraft:magma_block)
B(-7,3,-3,minecraft:diorite)
B(-7,3,-2,minecraft:diorite)
B(-7,3,-1,minecraft:diorite)
B(-7,3,0,minecraft:diorite)
B(-7,3,1,minecraft:diorite)
B(-7,3,2,minecraft:obsidian)
B(-7,3,3,minecraft:obsidian)
B(-7,3,4,minecraft:obsidian)
B(-7,3,5,minecraft:magma_block)
B(-7,3,6,minecraft:magma_block)
B(-7,3,7,minecraft:magma_block)
B(-7,3,8,minecraft:magma_block)
B(-7,4,-7,minecraft:diorite)
B(-7,4,-6,minecraft:diorite)
B(-7,4,-5,minecraft:diorite)
B(-7,4,-4,minecraft:diorite)
B(-7,4,-3,minecraft:diorite)
B(-7,4,-2,minecraft:diorite)
B(-7,4,-1,minecraft:diorite)
B(-7,4,0,minecraft:diorite)
B(-7,4,1,minecraft:diorite)
B(-7,4,2,minecraft:diorite)
B(-7,4,3,minecraft:obsidian)
B(-7,4,4,minecraft:obsidian)
B(-7,4,5,minecraft:obsidian)
B(-7,4,6,minecraft:obsidian)
B(-7,4,7,minecraft:obsidian)
B(-7,4,8,minecraft:obsidian)
B(-7,5,-7,minecraft:diorite)
B(-7,5,-6,minecraft:diorite)
B(-7,5,-5,minecraft:diorite)
B(-7,5,-4,minecraft:diorite)
B(-7,5,-3,minecraft:diorite)
B(-7,5,-2,minecraft:diorite)
B(-7,5,-1,minecraft:diorite)
B(-7,5,0,minecraft:diorite)
B(-7,5,1,minecraft:diorite)
B(-7,5,2,minecraft:diorite)
B(-7,5,3,minecraft:obsidian)
B(-7,5,4,minecraft:obsidian)
B(-7,5,5,minecraft:obsidian)
B(-7,5,6,minecraft:obsidian)
B(-7,5,7,minecraft:obsidian)
B(-7,5,8,minecraft:obsidian)
B(-7,6,-7,minecraft:diorite)
B(-7,6,-6,minecraft:diorite)
B(-7,6,-5,minecraft:diorite)
B(-7,6,-4,minecraft:diorite)
B(-7,6,-3,minecraft:diorite)
B(-7,6,-2,minecraft:diorite)
B(-7,6,-1,minecraft:diorite)
B(-7,6,0,minecraft:diorite)
B(-7,6,1,minecraft:diorite)
B(-7,6,2,minecraft:diorite)
B(-7,6,3,minecraft:obsidian)
B(-7,6,4,minecraft:obsidian)
B(-7,6,5,minecraft:obsidian)
B(-7,6,6,minecraft:obsidian)
B(-7,6,7,minecraft:obsidian)
B(-7,6,8,minecraft:obsidian)
B(-7,7,-7,minecraft:diorite)
B(-7,7,-6,minecraft:diorite)
B(-7,7,-5,minecraft:diorite)
B(-7,7,-4,minecraft:diorite)
B(-7,7,-3,minecraft:diorite)
B(-7,7,-2,minecraft:diorite)
B(-7,7,-1,minecraft:diorite)
B(-7,7,0,minecraft:diorite)
B(-7,7,1,minecraft:diorite)
B(-7,7,2,minecraft:obsidian)
B(-7,7,3,minecraft:obsidian)
B(-7,7,4,minecraft:obsidian)
B(-7,7,5,minecraft:diorite)
B(-7,7,6,minecraft:obsidian)
B(-7,7,7,minecraft:obsidian)
B(-7,7,8,minecraft:obsidian)
B(-7,8,-7,minecraft:diorite)
B(-7,8,-6,minecraft:diorite)
B(-7,8,-5,minecraft:diorite)
B(-7,8,-4,minecraft:diorite)
B(-7,8,-3,minecraft:diorite)
B(-7,8,-2,minecraft:diorite)
B(-7,8,-1,minecraft:diorite)
B(-7,8,0,minecraft:obsidian)
B(-7,8,1,minecraft:obsidian)
B(-7,8,2,minecraft:obsidian)
B(-7,8,3,minecraft:obsidian)
B(-7,8,4,minecraft:obsidian)
B(-7,8,5,minecraft:obsidian)
B(-7,8,6,minecraft:obsidian)
B(-7,8,7,minecraft:diorite)
B(-7,8,8,minecraft:diorite)
B(-7,9,-7,minecraft:diorite)
B(-7,9,-6,minecraft:obsidian)
B(-7,9,-5,minecraft:obsidian)
B(-7,9,-4,minecraft:obsidian)
B(-7,9,-3,minecraft:obsidian)
B(-7,9,-2,minecraft:obsidian)
B(-7,9,-1,minecraft:obsidian)
B(-7,9,0,minecraft:obsidian)
B(-7,9,1,minecraft:obsidian)
B(-7,9,2,minecraft:obsidian)
B(-7,9,3,minecraft:obsidian)
B(-7,9,4,minecraft:obsidian)
B(-7,9,5,minecraft:obsidian)
B(-7,9,6,minecraft:obsidian)
B(-7,9,7,minecraft:obsidian)
B(-7,9,8,minecraft:obsidian)
B(-7,10,-7,minecraft:obsidian)
B(-7,10,-6,minecraft:obsidian)
B(-7,10,-5,minecraft:obsidian)
B(-7,10,-4,minecraft:obsidian)
B(-7,10,-3,minecraft:obsidian)
B(-7,10,-2,minecraft:obsidian)
B(-7,10,-1,minecraft:obsidian)
B(-7,10,0,minecraft:obsidian)
B(-7,10,1,minecraft:obsidian)
B(-7,10,2,minecraft:obsidian)
B(-7,10,3,minecraft:obsidian)
B(-7,10,4,minecraft:obsidian)
B(-7,10,5,minecraft:obsidian)
B(-7,10,6,minecraft:obsidian)
B(-7,10,7,minecraft:obsidian)
B(-7,10,8,minecraft:obsidian)
B(-7,11,-7,minecraft:obsidian)
B(-7,11,-6,minecraft:obsidian)
B(-7,11,-5,minecraft:obsidian)
B(-7,11,-4,minecraft:obsidian)
B(-7,11,-3,minecraft:obsidian)
B(-7,11,-2,minecraft:obsidian)
B(-7,11,-1,minecraft:obsidian)
B(-7,11,0,minecraft:obsidian)
B(-7,11,1,minecraft:obsidian)
B(-7,11,2,minecraft:obsidian)
B(-7,11,3,minecraft:obsidian)
B(-7,11,4,minecraft:obsidian)
B(-7,11,5,minecraft:obsidian)
B(-7,11,6,minecraft:obsidian)
B(-7,11,7,minecraft:obsidian)
B(-7,11,8,minecraft:obsidian)
B(-7,12,-7,minecraft:obsidian)
B(-7,12,-6,minecraft:obsidian)
B(-7,12,-5,minecraft:obsidian)
B(-7,12,-4,minecraft:obsidian)
B(-7,12,-3,minecraft:obsidian)
B(-7,12,-2,minecraft:obsidian)
B(-7,12,-1,minecraft:obsidian)
B(-7,12,0,minecraft:obsidian)
B(-7,12,1,minecraft:obsidian)
B(-7,12,2,minecraft:obsidian)
B(-7,12,3,minecraft:obsidian)
B(-7,12,4,minecraft:obsidian)
B(-7,12,5,minecraft:obsidian)
B(-7,12,6,minecraft:obsidian)
B(-7,12,7,minecraft:obsidian)
B(-7,12,8,minecraft:obsidian)
B(-7,13,-7,minecraft:obsidian)
B(-7,13,-6,minecraft:obsidian)
B(-7,13,-5,minecraft:diorite)
B(-7,13,-4,minecraft:diorite)
B(-7,13,-3,minecraft:diorite)
B(-7,13,-2,minecraft:diorite)
B(-7,13,-1,minecraft:obsidian)
B(-7,13,0,minecraft:obsidian)
B(-7,13,1,minecraft:obsidian)
B(-7,13,2,minecraft:obsidian)
B(-7,13,3,minecraft:obsidian)
B(-7,13,4,minecraft:obsidian)
B(-7,13,5,minecraft:obsidian)
B(-7,13,6,minecraft:obsidian)
B(-7,13,7,minecraft:obsidian)
B(-7,13,8,minecraft:obsidian)
B(-7,14,-7,minecraft:obsidian)
B(-7,14,-6,minecraft:diorite)
B(-7,14,-5,minecraft:diorite)
B(-7,14,-4,minecraft:diorite)
B(-7,14,-3,minecraft:diorite)
B(-7,14,-2,minecraft:diorite)
B(-7,14,-1,minecraft:diorite)
B(-7,14,0,minecraft:obsidian)
B(-7,14,1,minecraft:obsidian)
B(-7,14,2,minecraft:obsidian)
B(-7,14,3,minecraft:obsidian)
B(-7,14,4,minecraft:obsidian)
B(-7,14,5,minecraft:obsidian)
B(-7,14,6,minecraft:obsidian)
B(-7,14,7,minecraft:obsidian)
B(-7,14,8,minecraft:obsidian)
B(-7,15,-7,minecraft:obsidian)
B(-7,15,-6,minecraft:diorite)
B(-7,15,-5,minecraft:diorite)
B(-7,15,-4,minecraft:diorite)
B(-7,15,-3,minecraft:diorite)
B(-7,15,-2,minecraft:diorite)
B(-7,15,-1,minecraft:diorite)
B(-7,15,0,minecraft:diorite)
B(-7,15,1,minecraft:diorite)
B(-7,15,2,minecraft:obsidian)
B(-7,15,3,minecraft:obsidian)
B(-7,15,4,minecraft:obsidian)
B(-7,15,5,minecraft:obsidian)
B(-7,15,6,minecraft:obsidian)
B(-7,15,7,minecraft:obsidian)
B(-7,15,8,minecraft:obsidian)
B(-7,16,-7,minecraft:obsidian)
B(-7,16,-6,minecraft:diorite)
B(-7,16,-5,minecraft:diorite)
B(-7,16,-4,minecraft:diorite)
B(-7,16,-3,minecraft:diorite)
B(-7,16,-2,minecraft:diorite)
B(-7,16,-1,minecraft:diorite)
B(-7,16,0,minecraft:lava)
B(-7,16,1,minecraft:lava)
B(-7,16,2,minecraft:obsidian)
B(-7,16,3,minecraft:obsidian)
B(-7,16,4,minecraft:obsidian)
B(-7,16,5,minecraft:obsidian)
B(-7,16,6,minecraft:obsidian)
B(-7,16,7,minecraft:obsidian)
B(-7,16,8,minecraft:obsidian)
B(-7,17,-7,minecraft:diorite)
B(-7,17,-6,minecraft:diorite)
B(-7,17,3,minecraft:obsidian)
B(-7,17,4,minecraft:obsidian)
B(-7,17,5,minecraft:obsidian)
B(-7,17,6,minecraft:obsidian)
B(-7,17,7,minecraft:obsidian)
B(-7,17,8,minecraft:obsidian)
B(-7,18,4,minecraft:obsidian)
B(-7,18,5,minecraft:obsidian)
B(-7,18,6,minecraft:obsidian)
B(-7,18,7,minecraft:obsidian)
B(-7,18,8,minecraft:obsidian)
B(-7,19,5,minecraft:diorite)
B(-7,19,6,minecraft:obsidian)
B(-7,19,7,minecraft:obsidian)
B(-7,19,8,minecraft:obsidian)
B(-7,20,5,minecraft:diorite)
B(-7,20,6,minecraft:obsidian)
B(-7,20,7,minecraft:obsidian)
B(-7,20,8,minecraft:obsidian)
B(-7,21,5,minecraft:diorite)
B(-7,21,6,minecraft:diorite)
B(-7,21,7,minecraft:obsidian)
B(-7,21,8,minecraft:obsidian)
B(-7,22,5,minecraft:diorite)
B(-7,22,6,minecraft:diorite)
B(-7,22,7,minecraft:diorite)
B(-7,22,8,minecraft:obsidian)
B(-7,23,5,minecraft:diorite)
B(-7,23,6,minecraft:diorite)
B(-7,23,7,minecraft:diorite)
B(-7,23,8,minecraft:obsidian)
B(-7,24,6,minecraft:diorite)
B(-7,24,7,minecraft:diorite)
B(-7,24,8,minecraft:diorite)
B(-7,25,7,minecraft:diorite)
B(-7,25,8,minecraft:diorite)
B(-7,26,7,minecraft:diorite)
B(-7,26,8,minecraft:diorite)
B(-7,27,8,minecraft:obsidian)
B(-7,28,8,minecraft:obsidian)
B(-7,29,8,minecraft:obsidian)
B(-7,57,8,minecraft:obsidian)
B(-7,58,-5,minecraft:obsidian)
B(-7,58,-4,minecraft:obsidian)
B(-7,58,-3,minecraft:obsidian)
B(-7,58,-2,minecraft:obsidian)
B(-7,58,-1,minecraft:obsidian)
B(-7,58,4,minecraft:obsidian)
B(-7,58,5,minecraft:obsidian)
B(-7,58,6,minecraft:obsidian)
B(-7,58,7,minecraft:obsidian)
B(-7,58,8,minecraft:obsidian)
B(-7,59,-7,minecraft:obsidian)
B(-7,59,-6,minecraft:obsidian)
B(-7,59,-5,minecraft:obsidian)
B(-7,59,-4,minecraft:obsidian)
B(-7,59,-3,minecraft:obsidian)
B(-7,59,-2,minecraft:obsidian)
B(-7,59,-1,minecraft:obsidian)
B(-7,59,0,minecraft:obsidian)
B(-7,59,1,minecraft:obsidian)
B(-7,59,2,minecraft:obsidian)
B(-7,59,3,minecraft:obsidian)
B(-7,59,4,minecraft:obsidian)
B(-7,59,5,minecraft:obsidian)
B(-7,59,6,minecraft:obsidian)
B(-7,59,7,minecraft:obsidian)
B(-7,59,8,minecraft:obsidian)
B(-7,60,-7,minecraft:obsidian)
B(-7,60,-6,minecraft:obsidian)
B(-7,60,-5,minecraft:obsidian)
B(-7,60,-4,minecraft:obsidian)
B(-7,60,-3,minecraft:obsidian)
B(-7,60,-2,minecraft:obsidian)
B(-7,60,-1,minecraft:obsidian)
B(-7,60,0,minecraft:obsidian)
B(-7,60,1,minecraft:obsidian)
B(-7,60,2,minecraft:obsidian)
B(-7,60,3,minecraft:obsidian)
B(-7,60,4,minecraft:obsidian)
B(-7,60,5,minecraft:obsidian)
B(-7,60,6,minecraft:obsidian)
B(-7,60,7,minecraft:obsidian)
B(-7,60,8,minecraft:obsidian)
B(-7,61,-7,minecraft:obsidian)
B(-7,61,-6,minecraft:obsidian)
B(-7,61,-5,minecraft:obsidian)
B(-7,61,-4,minecraft:obsidian)
B(-7,61,-3,minecraft:obsidian)
B(-7,61,-2,minecraft:obsidian)
B(-7,61,-1,minecraft:obsidian)
B(-7,61,0,minecraft:obsidian)
B(-7,61,1,minecraft:obsidian)
B(-7,61,2,minecraft:obsidian)
B(-7,61,3,minecraft:obsidian)
B(-7,61,4,minecraft:obsidian)
B(-7,61,5,minecraft:obsidian)
B(-7,61,6,minecraft:obsidian)
B(-7,61,7,minecraft:obsidian)
B(-7,61,8,minecraft:obsidian)
B(-7,62,-7,minecraft:obsidian)
B(-7,62,-6,minecraft:obsidian)
B(-7,62,-5,minecraft:obsidian)
B(-7,62,-4,minecraft:obsidian)
B(-7,62,-3,minecraft:obsidian)
B(-7,62,-2,minecraft:obsidian)
B(-7,62,-1,minecraft:obsidian)
B(-7,62,0,minecraft:obsidian)
B(-7,62,1,minecraft:obsidian)
B(-7,62,2,minecraft:obsidian)
B(-7,62,3,minecraft:obsidian)
B(-7,62,4,minecraft:obsidian)
B(-7,62,5,minecraft:obsidian)
B(-7,62,6,minecraft:obsidian)
B(-7,62,7,minecraft:obsidian)
B(-7,62,8,minecraft:obsidian)
B(-7,63,-7,minecraft:obsidian)
B(-7,63,-6,minecraft:obsidian)
B(-7,63,-5,minecraft:obsidian)
B(-7,63,-4,minecraft:obsidian)
B(-7,63,-3,minecraft:obsidian)
B(-7,63,-2,minecraft:obsidian)
B(-7,63,-1,minecraft:obsidian)
B(-7,63,0,minecraft:obsidian)
B(-7,63,1,minecraft:obsidian)
B(-7,63,2,minecraft:obsidian)
B(-7,63,3,minecraft:obsidian)
B(-7,63,4,minecraft:obsidian)
B(-7,63,5,minecraft:obsidian)
B(-7,63,6,minecraft:obsidian)
B(-7,63,7,minecraft:obsidian)
B(-7,63,8,minecraft:obsidian)
B(-7,64,-7,minecraft:obsidian)
B(-7,64,-6,minecraft:obsidian)
B(-7,64,-5,minecraft:obsidian)
B(-7,64,-4,minecraft:obsidian)
B(-7,64,-3,minecraft:obsidian)
B(-7,64,-2,minecraft:obsidian)
B(-7,64,-1,minecraft:obsidian)
B(-7,64,0,minecraft:obsidian)
B(-7,64,1,minecraft:obsidian)
B(-7,64,2,minecraft:obsidian)
B(-7,64,3,minecraft:obsidian)
B(-7,64,4,minecraft:obsidian)
B(-7,64,5,minecraft:obsidian)
B(-7,64,6,minecraft:obsidian)
B(-7,64,7,minecraft:obsidian)
B(-7,64,8,minecraft:obsidian)
B(-7,65,-7,minecraft:obsidian)
B(-7,65,-6,minecraft:obsidian)
B(-7,65,-5,minecraft:obsidian)
B(-7,65,-4,minecraft:obsidian)
B(-7,65,-3,minecraft:obsidian)
B(-7,65,-2,minecraft:obsidian)
B(-7,65,-1,minecraft:obsidian)
B(-7,65,0,minecraft:obsidian)
B(-7,65,1,minecraft:obsidian)
B(-7,65,2,minecraft:obsidian)
B(-7,65,3,minecraft:obsidian)
B(-7,65,4,minecraft:obsidian)
B(-7,65,5,minecraft:obsidian)
B(-7,65,6,minecraft:obsidian)
B(-7,65,7,minecraft:obsidian)
B(-7,65,8,minecraft:obsidian)
B(-7,66,-7,minecraft:obsidian)
B(-7,66,-6,minecraft:obsidian)
B(-7,66,-5,minecraft:obsidian)
B(-7,66,-4,minecraft:obsidian)
B(-7,66,-3,minecraft:obsidian)
B(-7,66,-2,minecraft:obsidian)
B(-7,66,-1,minecraft:obsidian)
B(-7,66,0,minecraft:obsidian)
B(-7,66,1,minecraft:obsidian)
B(-7,66,2,minecraft:obsidian)
B(-7,66,3,minecraft:obsidian)
B(-7,66,4,minecraft:obsidian)
B(-7,66,5,minecraft:obsidian)
B(-7,66,6,minecraft:obsidian)
B(-7,66,7,minecraft:obsidian)
B(-7,66,8,minecraft:obsidian)
B(-7,67,-7,minecraft:obsidian)
B(-7,67,-6,minecraft:obsidian)
B(-7,67,-5,minecraft:obsidian)
B(-7,67,-4,minecraft:obsidian)
B(-7,67,-3,minecraft:obsidian)
B(-7,67,-2,minecraft:obsidian)
B(-7,67,-1,minecraft:obsidian)
B(-7,67,0,minecraft:obsidian)
B(-7,67,1,minecraft:obsidian)
B(-7,67,2,minecraft:obsidian)
B(-7,67,3,minecraft:obsidian)
B(-7,67,4,minecraft:obsidian)
B(-7,67,5,minecraft:obsidian)
B(-7,67,6,minecraft:obsidian)
B(-7,67,7,minecraft:obsidian)
B(-7,67,8,minecraft:obsidian)
B(-7,68,-7,minecraft:obsidian)
B(-7,68,-6,minecraft:obsidian)
B(-7,68,-5,minecraft:obsidian)
B(-7,68,-4,minecraft:obsidian)
B(-7,68,-3,minecraft:obsidian)
B(-7,68,-2,minecraft:obsidian)
B(-7,68,-1,minecraft:obsidian)
B(-7,68,0,minecraft:obsidian)
B(-7,68,1,minecraft:obsidian)
B(-7,68,2,minecraft:obsidian)
B(-7,68,3,minecraft:obsidian)
B(-7,68,4,minecraft:obsidian)
B(-7,68,5,minecraft:obsidian)
B(-7,68,6,minecraft:obsidian)
B(-7,68,7,minecraft:obsidian)
B(-7,68,8,minecraft:obsidian)
B(-7,69,-7,minecraft:obsidian)
B(-7,69,-6,minecraft:obsidian)
B(-7,69,-5,minecraft:obsidian)
B(-7,69,-4,minecraft:obsidian)
B(-7,69,-3,minecraft:obsidian)
B(-7,69,-2,minecraft:obsidian)
B(-7,69,-1,minecraft:obsidian)
B(-7,69,0,minecraft:obsidian)
B(-7,69,1,minecraft:obsidian)
B(-7,69,2,minecraft:obsidian)
B(-7,69,3,minecraft:obsidian)
B(-7,69,4,minecraft:obsidian)
B(-7,69,5,minecraft:obsidian)
B(-7,69,6,minecraft:obsidian)
B(-7,69,7,minecraft:obsidian)
B(-7,69,8,minecraft:obsidian)
B(-7,70,-7,minecraft:obsidian)
B(-7,70,-6,minecraft:obsidian)
B(-7,70,-5,minecraft:obsidian)
B(-7,70,-4,minecraft:obsidian)
B(-7,70,-3,minecraft:obsidian)
B(-7,70,-2,minecraft:obsidian)
B(-7,70,-1,minecraft:obsidian)
B(-7,70,0,minecraft:obsidian)
B(-7,70,1,minecraft:obsidian)
B(-7,70,2,minecraft:obsidian)
B(-7,70,3,minecraft:obsidian)
B(-7,70,4,minecraft:obsidian)
B(-7,70,5,minecraft:obsidian)
B(-7,70,6,minecraft:magma_block)
B(-7,70,7,minecraft:magma_block)
B(-7,70,8,minecraft:magma_block)
B(-7,71,-7,minecraft:obsidian)
B(-7,71,-6,minecraft:obsidian)
B(-7,71,-5,minecraft:obsidian)
B(-7,71,-4,minecraft:obsidian)
B(-7,71,-3,minecraft:diorite)
B(-7,71,-2,minecraft:diorite)
B(-7,71,-1,minecraft:diorite)
B(-7,71,0,minecraft:obsidian)
B(-7,71,1,minecraft:obsidian)
B(-7,71,2,minecraft:obsidian)
B(-7,71,3,minecraft:obsidian)
B(-7,71,4,minecraft:obsidian)
B(-7,71,5,minecraft:obsidian)
B(-7,71,6,minecraft:magma_block)
B(-7,71,7,minecraft:magma_block)
B(-7,71,8,minecraft:magma_block)
B(-7,72,-7,minecraft:obsidian)
B(-7,72,-6,minecraft:diorite)
B(-7,72,-5,minecraft:diorite)
B(-7,72,-4,minecraft:diorite)
B(-7,72,-3,minecraft:diorite)
B(-7,72,-2,minecraft:diorite)
B(-7,72,-1,minecraft:diorite)
B(-7,72,0,minecraft:obsidian)
B(-7,72,1,minecraft:obsidian)
B(-7,72,2,minecraft:obsidian)
B(-7,72,3,minecraft:obsidian)
B(-7,72,4,minecraft:obsidian)
B(-7,72,5,minecraft:obsidian)
B(-7,72,6,minecraft:magma_block)
B(-7,72,7,minecraft:magma_block)
B(-7,72,8,minecraft:magma_block)
B(-7,73,-7,minecraft:diorite)
B(-7,73,-6,minecraft:diorite)
B(-7,73,-5,minecraft:diorite)
B(-7,73,-4,minecraft:diorite)
B(-7,73,-3,minecraft:andesite)
B(-7,73,-2,minecraft:andesite)
B(-7,73,-1,minecraft:andesite)
B(-7,73,0,minecraft:andesite)
B(-7,73,1,minecraft:obsidian)
B(-7,74,-7,minecraft:diorite)
B(-7,74,-6,minecraft:diorite)
B(-7,74,-5,minecraft:diorite)
B(-7,74,-4,minecraft:andesite)
B(-7,75,-7,minecraft:diorite)
B(-7,75,-6,minecraft:andesite)
B(-7,75,-5,minecraft:andesite)
B(-7,76,-7,minecraft:diorite)
B(-7,77,-7,minecraft:andesite)
B(-6,2,-1,minecraft:diorite)
B(-6,2,0,minecraft:diorite)
B(-6,2,1,minecraft:diorite)
B(-6,2,2,minecraft:diorite)
B(-6,2,3,minecraft:obsidian)
B(-6,2,4,minecraft:obsidian)
B(-6,2,5,minecraft:magma_block)
B(-6,3,-7,minecraft:diorite)
B(-6,3,-6,minecraft:diorite)
B(-6,3,-3,minecraft:diorite)
B(-6,3,-2,minecraft:diorite)
B(-6,3,-1,minecraft:diorite)
B(-6,3,0,minecraft:diorite)
B(-6,3,1,minecraft:diorite)
B(-6,3,2,minecraft:diorite)
B(-6,3,3,minecraft:obsidian)
B(-6,3,4,minecraft:obsidian)
B(-6,3,5,minecraft:magma_block)
B(-6,3,6,minecraft:magma_block)
B(-6,3,7,minecraft:magma_block)
B(-6,3,8,minecraft:obsidian)
B(-6,4,-7,minecraft:diorite)
B(-6,4,-6,minecraft:diorite)
B(-6,4,-5,minecraft:diorite)
B(-6,4,-4,minecraft:diorite)
B(-6,4,-3,minecraft:diorite)
B(-6,4,-2,minecraft:diorite)
B(-6,4,-1,minecraft:diorite)
B(-6,4,0,minecraft:diorite)
B(-6,4,1,minecraft:diorite)
B(-6,4,2,minecraft:diorite)
B(-6,4,3,minecraft:obsidian)
B(-6,4,4,minecraft:obsidian)
B(-6,4,5,minecraft:obsidian)
B(-6,4,6,minecraft:obsidian)
B(-6,4,7,minecraft:obsidian)
B(-6,4,8,minecraft:obsidian)
B(-6,5,-7,minecraft:diorite)
B(-6,5,-6,minecraft:diorite)
B(-6,5,-5,minecraft:diorite)
B(-6,5,-4,minecraft:diorite)
B(-6,5,-3,minecraft:diorite)
B(-6,5,-2,minecraft:diorite)
B(-6,5,-1,minecraft:diorite)
B(-6,5,0,minecraft:diorite)
B(-6,5,1,minecraft:diorite)
B(-6,5,2,minecraft:diorite)
B(-6,5,3,minecraft:diorite)
B(-6,5,4,minecraft:obsidian)
B(-6,5,5,minecraft:obsidian)
B(-6,5,6,minecraft:obsidian)
B(-6,5,7,minecraft:obsidian)
B(-6,5,8,minecraft:obsidian)
B(-6,6,-7,minecraft:diorite)
B(-6,6,-6,minecraft:diorite)
B(-6,6,-5,minecraft:diorite)
B(-6,6,-4,minecraft:diorite)
B(-6,6,-3,minecraft:diorite)
B(-6,6,-2,minecraft:diorite)
B(-6,6,-1,minecraft:diorite)
B(-6,6,0,minecraft:diorite)
B(-6,6,1,minecraft:diorite)
B(-6,6,2,minecraft:diorite)
B(-6,6,3,minecraft:obsidian)
B(-6,6,4,minecraft:diorite)
B(-6,6,5,minecraft:obsidian)
B(-6,6,6,minecraft:obsidian)
B(-6,6,7,minecraft:obsidian)
B(-6,6,8,minecraft:obsidian)
B(-6,7,-7,minecraft:diorite)
B(-6,7,-6,minecraft:diorite)
B(-6,7,-5,minecraft:diorite)
B(-6,7,-4,minecraft:diorite)
B(-6,7,-3,minecraft:diorite)
B(-6,7,-2,minecraft:diorite)
B(-6,7,-1,minecraft:diorite)
B(-6,7,0,minecraft:diorite)
B(-6,7,1,minecraft:diorite)
B(-6,7,2,minecraft:obsidian)
B(-6,7,3,minecraft:obsidian)
B(-6,7,4,minecraft:obsidian)
B(-6,7,5,minecraft:diorite)
B(-6,7,6,minecraft:diorite)
B(-6,7,7,minecraft:obsidian)
B(-6,7,8,minecraft:obsidian)
B(-6,8,-7,minecraft:diorite)
B(-6,8,-6,minecraft:diorite)
B(-6,8,-5,minecraft:diorite)
B(-6,8,-4,minecraft:diorite)
B(-6,8,-3,minecraft:diorite)
B(-6,8,-2,minecraft:diorite)
B(-6,8,-1,minecraft:diorite)
B(-6,8,0,minecraft:obsidian)
B(-6,8,1,minecraft:obsidian)
B(-6,8,2,minecraft:obsidian)
B(-6,8,3,minecraft:obsidian)
B(-6,8,4,minecraft:obsidian)
B(-6,8,5,minecraft:obsidian)
B(-6,8,6,minecraft:diorite)
B(-6,8,7,minecraft:diorite)
B(-6,8,8,minecraft:diorite)
B(-6,9,-7,minecraft:diorite)
B(-6,9,-6,minecraft:obsidian)
B(-6,9,-5,minecraft:obsidian)
B(-6,9,-4,minecraft:obsidian)
B(-6,9,-3,minecraft:obsidian)
B(-6,9,-2,minecraft:obsidian)
B(-6,9,-1,minecraft:obsidian)
B(-6,9,0,minecraft:obsidian)
B(-6,9,1,minecraft:obsidian)
B(-6,9,2,minecraft:obsidian)
B(-6,9,3,minecraft:obsidian)
B(-6,9,4,minecraft:obsidian)
B(-6,9,5,minecraft:obsidian)
B(-6,9,6,minecraft:obsidian)
B(-6,9,7,minecraft:obsidian)
B(-6,9,8,minecraft:obsidian)
B(-6,10,-7,minecraft:obsidian)
B(-6,10,-6,minecraft:obsidian)
B(-6,10,-5,minecraft:obsidian)
B(-6,10,-4,minecraft:obsidian)
B(-6,10,-3,minecraft:obsidian)
B(-6,10,-2,minecraft:obsidian)
B(-6,10,-1,minecraft:obsidian)
B(-6,10,0,minecraft:obsidian)
B(-6,10,1,minecraft:obsidian)
B(-6,10,2,minecraft:obsidian)
B(-6,10,3,minecraft:obsidian)
B(-6,10,4,minecraft:obsidian)
B(-6,10,5,minecraft:obsidian)
B(-6,10,6,minecraft:obsidian)
B(-6,10,7,minecraft:obsidian)
B(-6,10,8,minecraft:obsidian)
B(-6,11,-7,minecraft:obsidian)
B(-6,11,-6,minecraft:obsidian)
B(-6,11,-5,minecraft:obsidian)
B(-6,11,-4,minecraft:obsidian)
B(-6,11,-3,minecraft:obsidian)
B(-6,11,-2,minecraft:obsidian)
B(-6,11,-1,minecraft:obsidian)
B(-6,11,0,minecraft:obsidian)
B(-6,11,1,minecraft:obsidian)
B(-6,11,2,minecraft:obsidian)
B(-6,11,3,minecraft:obsidian)
B(-6,11,4,minecraft:obsidian)
B(-6,11,5,minecraft:obsidian)
B(-6,11,6,minecraft:obsidian)
B(-6,11,7,minecraft:obsidian)
B(-6,11,8,minecraft:obsidian)
B(-6,12,-7,minecraft:obsidian)
B(-6,12,-6,minecraft:obsidian)
B(-6,12,-5,minecraft:obsidian)
B(-6,12,-4,minecraft:obsidian)
B(-6,12,-3,minecraft:obsidian)
B(-6,12,-2,minecraft:obsidian)
B(-6,12,-1,minecraft:obsidian)
B(-6,12,0,minecraft:obsidian)
B(-6,12,1,minecraft:obsidian)
B(-6,12,2,minecraft:obsidian)
B(-6,12,3,minecraft:obsidian)
B(-6,12,4,minecraft:obsidian)
B(-6,12,5,minecraft:obsidian)
B(-6,12,6,minecraft:obsidian)
B(-6,12,7,minecraft:obsidian)
B(-6,12,8,minecraft:obsidian)
B(-6,13,-7,minecraft:obsidian)
B(-6,13,-6,minecraft:obsidian)
B(-6,13,-5,minecraft:diorite)
B(-6,13,-4,minecraft:diorite)
B(-6,13,-3,minecraft:diorite)
B(-6,13,-2,minecraft:diorite)
B(-6,13,-1,minecraft:obsidian)
B(-6,13,0,minecraft:obsidian)
B(-6,13,1,minecraft:obsidian)
B(-6,13,2,minecraft:obsidian)
B(-6,13,3,minecraft:obsidian)
B(-6,13,4,minecraft:obsidian)
B(-6,13,5,minecraft:obsidian)
B(-6,13,6,minecraft:obsidian)
B(-6,13,7,minecraft:obsidian)
B(-6,13,8,minecraft:obsidian)
B(-6,14,-7,minecraft:obsidian)
B(-6,14,-6,minecraft:diorite)
B(-6,14,-5,minecraft:diorite)
B(-6,14,-4,minecraft:diorite)
B(-6,14,-3,minecraft:diorite)
B(-6,14,-2,minecraft:diorite)
B(-6,14,-1,minecraft:diorite)
B(-6,14,0,minecraft:diorite)
B(-6,14,1,minecraft:diorite)
B(-6,14,2,minecraft:obsidian)
B(-6,14,3,minecraft:obsidian)
B(-6,14,4,minecraft:obsidian)
B(-6,14,5,minecraft:obsidian)
B(-6,14,6,minecraft:obsidian)
B(-6,14,7,minecraft:obsidian)
B(-6,14,8,minecraft:obsidian)
B(-6,15,-7,minecraft:obsidian)
B(-6,15,-6,minecraft:diorite)
B(-6,15,-5,minecraft:diorite)
B(-6,15,-4,minecraft:diorite)
B(-6,15,-3,minecraft:diorite)
B(-6,15,-2,minecraft:diorite)
B(-6,15,-1,minecraft:diorite)
B(-6,15,0,minecraft:diorite)
B(-6,15,1,minecraft:diorite)
B(-6,15,2,minecraft:diorite)
B(-6,15,3,minecraft:obsidian)
B(-6,15,4,minecraft:obsidian)
B(-6,15,5,minecraft:obsidian)
B(-6,15,6,minecraft:obsidian)
B(-6,15,7,minecraft:obsidian)
B(-6,15,8,minecraft:obsidian)
B(-6,16,-7,minecraft:diorite)
B(-6,16,-6,minecraft:diorite)
B(-6,16,-5,minecraft:diorite)
B(-6,16,-4,minecraft:lava)
B(-6,16,-3,minecraft:lava)
B(-6,16,-2,minecraft:lava)
B(-6,16,-1,minecraft:lava)
B(-6,16,0,minecraft:lava)
B(-6,16,1,minecraft:diorite)
B(-6,16,2,minecraft:diorite)
B(-6,16,3,minecraft:obsidian)
B(-6,16,4,minecraft:obsidian)
B(-6,16,5,minecraft:obsidian)
B(-6,16,6,minecraft:obsidian)
B(-6,16,7,minecraft:obsidian)
B(-6,16,8,minecraft:obsidian)
B(-6,17,-7,minecraft:diorite)
B(-6,17,-6,minecraft:diorite)
B(-6,17,2,minecraft:diorite)
B(-6,17,3,minecraft:obsidian)
B(-6,17,4,minecraft:obsidian)
B(-6,17,5,minecraft:obsidian)
B(-6,17,6,minecraft:obsidian)
B(-6,17,7,minecraft:obsidian)
B(-6,17,8,minecraft:obsidian)
B(-6,18,3,minecraft:diorite)
B(-6,18,4,minecraft:diorite)
B(-6,18,5,minecraft:diorite)
B(-6,18,6,minecraft:obsidian)
B(-6,18,7,minecraft:obsidian)
B(-6,18,8,minecraft:obsidian)
B(-6,19,4,minecraft:diorite)
B(-6,19,5,minecraft:diorite)
B(-6,19,6,minecraft:diorite)
B(-6,19,7,minecraft:obsidian)
B(-6,19,8,minecraft:obsidian)
B(-6,20,5,minecraft:diorite)
B(-6,20,6,minecraft:diorite)
B(-6,20,7,minecraft:obsidian)
B(-6,20,8,minecraft:obsidian)
B(-6,21,5,minecraft:diorite)
B(-6,21,6,minecraft:diorite)
B(-6,21,7,minecraft:obsidian)
B(-6,21,8,minecraft:obsidian)
B(-6,22,5,minecraft:diorite)
B(-6,22,6,minecraft:diorite)
B(-6,22,7,minecraft:diorite)
B(-6,22,8,minecraft:obsidian)
B(-6,23,5,minecraft:diorite)
B(-6,23,6,minecraft:diorite)
B(-6,23,7,minecraft:diorite)
B(-6,23,8,minecraft:obsidian)
B(-6,24,6,minecraft:diorite)
B(-6,24,7,minecraft:diorite)
B(-6,24,8,minecraft:obsidian)
B(-6,25,7,minecraft:diorite)
B(-6,25,8,minecraft:obsidian)
B(-6,26,8,minecraft:obsidian)
B(-6,27,8,minecraft:obsidian)
B(-6,28,8,minecraft:obsidian)
B(-6,58,-4,minecraft:obsidian)
B(-6,58,-3,minecraft:obsidian)
B(-6,58,-2,minecraft:obsidian)
B(-6,58,6,minecraft:obsidian)
B(-6,58,7,minecraft:obsidian)
B(-6,58,8,minecraft:diorite)
B(-6,59,-7,minecraft:obsidian)
B(-6,59,-6,minecraft:obsidian)
B(-6,59,-5,minecraft:obsidian)
B(-6,59,-4,minecraft:obsidian)
B(-6,59,-3,minecraft:obsidian)
B(-6,59,-2,minecraft:obsidian)
B(-6,59,-1,minecraft:obsidian)
B(-6,59,0,minecraft:obsidian)
B(-6,59,4,minecraft:obsidian)
B(-6,59,5,minecraft:obsidian)
B(-6,59,6,minecraft:obsidian)
B(-6,59,7,minecraft:obsidian)
B(-6,59,8,minecraft:diorite)
B(-6,60,-7,minecraft:obsidian)
B(-6,60,-6,minecraft:obsidian)
B(-6,60,-5,minecraft:obsidian)
B(-6,60,-4,minecraft:obsidian)
B(-6,60,-3,minecraft:obsidian)
B(-6,60,-2,minecraft:obsidian)
B(-6,60,-1,minecraft:obsidian)
B(-6,60,0,minecraft:obsidian)
B(-6,60,1,minecraft:obsidian)
B(-6,60,2,minecraft:obsidian)
B(-6,60,3,minecraft:obsidian)
B(-6,60,4,minecraft:obsidian)
B(-6,60,5,minecraft:obsidian)
B(-6,60,6,minecraft:obsidian)
B(-6,60,7,minecraft:obsidian)
B(-6,60,8,minecraft:diorite)
B(-6,61,-7,minecraft:obsidian)
B(-6,61,-6,minecraft:obsidian)
B(-6,61,-5,minecraft:obsidian)
B(-6,61,-4,minecraft:obsidian)
B(-6,61,-3,minecraft:obsidian)
B(-6,61,-2,minecraft:obsidian)
B(-6,61,-1,minecraft:obsidian)
B(-6,61,0,minecraft:obsidian)
B(-6,61,1,minecraft:obsidian)
B(-6,61,2,minecraft:obsidian)
B(-6,61,3,minecraft:obsidian)
B(-6,61,4,minecraft:obsidian)
B(-6,61,5,minecraft:obsidian)
B(-6,61,6,minecraft:obsidian)
B(-6,61,7,minecraft:obsidian)
B(-6,61,8,minecraft:obsidian)
B(-6,62,-7,minecraft:obsidian)
B(-6,62,-6,minecraft:obsidian)
B(-6,62,-5,minecraft:obsidian)
B(-6,62,-4,minecraft:obsidian)
B(-6,62,-3,minecraft:obsidian)
B(-6,62,-2,minecraft:obsidian)
B(-6,62,-1,minecraft:obsidian)
B(-6,62,0,minecraft:obsidian)
B(-6,62,1,minecraft:obsidian)
B(-6,62,2,minecraft:obsidian)
B(-6,62,3,minecraft:obsidian)
B(-6,62,4,minecraft:obsidian)
B(-6,62,5,minecraft:obsidian)
B(-6,62,6,minecraft:obsidian)
B(-6,62,7,minecraft:obsidian)
B(-6,62,8,minecraft:obsidian)
B(-6,63,-7,minecraft:obsidian)
B(-6,63,-6,minecraft:obsidian)
B(-6,63,-5,minecraft:obsidian)
B(-6,63,-4,minecraft:obsidian)
B(-6,63,-3,minecraft:obsidian)
B(-6,63,-2,minecraft:obsidian)
B(-6,63,-1,minecraft:obsidian)
B(-6,63,0,minecraft:obsidian)
B(-6,63,1,minecraft:obsidian)
B(-6,63,2,minecraft:obsidian)
B(-6,63,3,minecraft:obsidian)
B(-6,63,4,minecraft:obsidian)
B(-6,63,5,minecraft:obsidian)
B(-6,63,6,minecraft:obsidian)
B(-6,63,7,minecraft:obsidian)
B(-6,63,8,minecraft:obsidian)
B(-6,64,-7,minecraft:obsidian)
B(-6,64,-6,minecraft:obsidian)
B(-6,64,-5,minecraft:obsidian)
B(-6,64,-4,minecraft:obsidian)
B(-6,64,-3,minecraft:obsidian)
B(-6,64,-2,minecraft:obsidian)
B(-6,64,-1,minecraft:obsidian)
B(-6,64,0,minecraft:obsidian)
B(-6,64,1,minecraft:obsidian)
B(-6,64,2,minecraft:obsidian)
B(-6,64,3,minecraft:obsidian)
B(-6,64,4,minecraft:obsidian)
B(-6,64,5,minecraft:obsidian)
B(-6,64,6,minecraft:obsidian)
B(-6,64,7,minecraft:obsidian)
B(-6,64,8,minecraft:obsidian)
B(-6,65,-7,minecraft:obsidian)
B(-6,65,-6,minecraft:obsidian)
B(-6,65,-5,minecraft:obsidian)
B(-6,65,-4,minecraft:obsidian)
B(-6,65,-3,minecraft:obsidian)
B(-6,65,-2,minecraft:obsidian)
B(-6,65,-1,minecraft:obsidian)
B(-6,65,0,minecraft:obsidian)
B(-6,65,1,minecraft:obsidian)
B(-6,65,2,minecraft:obsidian)
B(-6,65,3,minecraft:obsidian)
B(-6,65,4,minecraft:obsidian)
B(-6,65,5,minecraft:obsidian)
B(-6,65,6,minecraft:obsidian)
B(-6,65,7,minecraft:obsidian)
B(-6,65,8,minecraft:obsidian)
B(-6,66,-7,minecraft:obsidian)
B(-6,66,-6,minecraft:obsidian)
B(-6,66,-5,minecraft:obsidian)
B(-6,66,-4,minecraft:obsidian)
B(-6,66,-3,minecraft:obsidian)
B(-6,66,-2,minecraft:obsidian)
B(-6,66,-1,minecraft:obsidian)
B(-6,66,0,minecraft:obsidian)
B(-6,66,1,minecraft:obsidian)
B(-6,66,2,minecraft:obsidian)
B(-6,66,3,minecraft:obsidian)
B(-6,66,4,minecraft:obsidian)
B(-6,66,5,minecraft:obsidian)
B(-6,66,6,minecraft:obsidian)
B(-6,66,7,minecraft:obsidian)
B(-6,66,8,minecraft:obsidian)
B(-6,67,-7,minecraft:obsidian)
B(-6,67,-6,minecraft:obsidian)
B(-6,67,-5,minecraft:obsidian)
B(-6,67,-4,minecraft:obsidian)
B(-6,67,-3,minecraft:obsidian)
B(-6,67,-2,minecraft:obsidian)
B(-6,67,-1,minecraft:obsidian)
B(-6,67,0,minecraft:obsidian)
B(-6,67,1,minecraft:obsidian)
B(-6,67,2,minecraft:obsidian)
B(-6,67,3,minecraft:obsidian)
B(-6,67,4,minecraft:obsidian)
B(-6,67,5,minecraft:obsidian)
B(-6,67,6,minecraft:obsidian)
B(-6,67,7,minecraft:obsidian)
B(-6,67,8,minecraft:obsidian)
B(-6,68,-7,minecraft:obsidian)
B(-6,68,-6,minecraft:obsidian)
B(-6,68,-5,minecraft:obsidian)
B(-6,68,-4,minecraft:obsidian)
B(-6,68,-3,minecraft:obsidian)
B(-6,68,-2,minecraft:obsidian)
B(-6,68,-1,minecraft:obsidian)
B(-6,68,0,minecraft:obsidian)
B(-6,68,1,minecraft:obsidian)
B(-6,68,2,minecraft:obsidian)
B(-6,68,3,minecraft:obsidian)
B(-6,68,4,minecraft:obsidian)
B(-6,68,5,minecraft:obsidian)
B(-6,68,6,minecraft:obsidian)
B(-6,68,7,minecraft:obsidian)
B(-6,68,8,minecraft:obsidian)
B(-6,69,-7,minecraft:obsidian)
B(-6,69,-6,minecraft:obsidian)
B(-6,69,-5,minecraft:obsidian)
B(-6,69,-4,minecraft:obsidian)
B(-6,69,-3,minecraft:obsidian)
B(-6,69,-2,minecraft:obsidian)
B(-6,69,-1,minecraft:obsidian)
B(-6,69,0,minecraft:obsidian)
B(-6,69,1,minecraft:obsidian)
B(-6,69,2,minecraft:obsidian)
B(-6,69,3,minecraft:obsidian)
B(-6,69,4,minecraft:obsidian)
B(-6,69,5,minecraft:obsidian)
B(-6,69,6,minecraft:obsidian)
B(-6,69,7,minecraft:obsidian)
B(-6,69,8,minecraft:obsidian)
B(-6,70,-7,minecraft:obsidian)
B(-6,70,-6,minecraft:obsidian)
B(-6,70,-5,minecraft:obsidian)
B(-6,70,-4,minecraft:obsidian)
B(-6,70,-3,minecraft:obsidian)
B(-6,70,-2,minecraft:diorite)
B(-6,70,-1,minecraft:diorite)
B(-6,70,0,minecraft:obsidian)
B(-6,70,1,minecraft:obsidian)
B(-6,70,2,minecraft:obsidian)
B(-6,70,3,minecraft:obsidian)
B(-6,70,4,minecraft:obsidian)
B(-6,70,5,minecraft:obsidian)
B(-6,70,6,minecraft:obsidian)
B(-6,70,7,minecraft:magma_block)
B(-6,70,8,minecraft:magma_block)
B(-6,71,-7,minecraft:obsidian)
B(-6,71,-6,minecraft:diorite)
B(-6,71,-5,minecraft:diorite)
B(-6,71,-4,minecraft:diorite)
B(-6,71,-3,minecraft:diorite)
B(-6,71,-2,minecraft:diorite)
B(-6,71,-1,minecraft:diorite)
B(-6,71,0,minecraft:obsidian)
B(-6,71,1,minecraft:obsidian)
B(-6,71,2,minecraft:obsidian)
B(-6,71,3,minecraft:obsidian)
B(-6,71,4,minecraft:obsidian)
B(-6,71,5,minecraft:obsidian)
B(-6,71,6,minecraft:magma_block)
B(-6,71,7,minecraft:magma_block)
B(-6,71,8,minecraft:magma_block)
B(-6,72,-7,minecraft:diorite)
B(-6,72,-6,minecraft:diorite)
B(-6,72,-5,minecraft:diorite)
B(-6,72,-4,minecraft:diorite)
B(-6,72,-3,minecraft:diorite)
B(-6,72,-2,minecraft:diorite)
B(-6,72,-1,minecraft:diorite)
B(-6,72,0,minecraft:obsidian)
B(-6,72,1,minecraft:obsidian)
B(-6,72,2,minecraft:obsidian)
B(-6,72,3,minecraft:obsidian)
B(-6,72,4,minecraft:obsidian)
B(-6,72,5,minecraft:obsidian)
B(-6,72,6,minecraft:magma_block)
B(-6,72,7,minecraft:magma_block)
B(-6,72,8,minecraft:magma_block)
B(-6,73,-7,minecraft:diorite)
B(-6,73,-6,minecraft:diorite)
B(-6,73,-5,minecraft:diorite)
B(-6,73,-4,minecraft:diorite)
B(-6,73,-3,minecraft:andesite)
B(-6,73,-2,minecraft:diorite)
B(-6,73,-1,minecraft:andesite)
B(-6,73,0,minecraft:diorite)
B(-6,73,1,minecraft:obsidian)
B(-6,73,2,minecraft:obsidian)
B(-6,73,3,minecraft:obsidian)
B(-6,73,4,minecraft:obsidian)
B(-6,74,-7,minecraft:diorite)
B(-6,74,-6,minecraft:diorite)
B(-6,74,-5,minecraft:diorite)
B(-6,74,-4,minecraft:andesite)
B(-6,74,-2,minecraft:andesite)
B(-6,74,0,minecraft:andesite)
B(-6,74,1,minecraft:obsidian)
B(-6,74,2,minecraft:obsidian)
B(-6,74,3,minecraft:obsidian)
B(-6,75,-7,minecraft:diorite)
B(-6,75,-6,minecraft:andesite)
B(-6,75,-5,minecraft:andesite)
B(-6,75,1,minecraft:diorite)
B(-6,76,-7,minecraft:andesite)
B(-5,2,-1,minecraft:diorite)
B(-5,2,0,minecraft:diorite)
B(-5,2,1,minecraft:diorite)
B(-5,2,2,minecraft:diorite)
B(-5,2,3,minecraft:obsidian)
B(-5,2,4,minecraft:magma_block)
B(-5,2,5,minecraft:magma_block)
B(-5,2,6,minecraft:magma_block)
B(-5,2,7,minecraft:magma_block)
B(-5,3,-7,minecraft:diorite)
B(-5,3,-6,minecraft:diorite)
B(-5,3,-5,minecraft:diorite)
B(-5,3,-3,minecraft:diorite)
B(-5,3,-2,minecraft:diorite)
B(-5,3,-1,minecraft:diorite)
B(-5,3,0,minecraft:diorite)
B(-5,3,1,minecraft:diorite)
B(-5,3,2,minecraft:diorite)
B(-5,3,3,minecraft:obsidian)
B(-5,3,4,minecraft:magma_block)
B(-5,3,5,minecraft:magma_block)
B(-5,3,6,minecraft:magma_block)
B(-5,3,7,minecraft:magma_block)
B(-5,3,8,minecraft:magma_block)
B(-5,4,-7,minecraft:diorite)
B(-5,4,-6,minecraft:diorite)
B(-5,4,-5,minecraft:diorite)
B(-5,4,-4,minecraft:diorite)
B(-5,4,-3,minecraft:diorite)
B(-5,4,-2,minecraft:diorite)
B(-5,4,-1,minecraft:diorite)
B(-5,4,0,minecraft:diorite)
B(-5,4,1,minecraft:diorite)
B(-5,4,2,minecraft:diorite)
B(-5,4,3,minecraft:obsidian)
B(-5,4,4,minecraft:obsidian)
B(-5,4,5,minecraft:magma_block)
B(-5,4,6,minecraft:magma_block)
B(-5,4,7,minecraft:magma_block)
B(-5,4,8,minecraft:obsidian)
B(-5,5,-7,minecraft:diorite)
B(-5,5,-6,minecraft:diorite)
B(-5,5,-5,minecraft:diorite)
B(-5,5,-4,minecraft:diorite)
B(-5,5,-3,minecraft:diorite)
B(-5,5,-2,minecraft:diorite)
B(-5,5,-1,minecraft:diorite)
B(-5,5,0,minecraft:diorite)
B(-5,5,1,minecraft:diorite)
B(-5,5,2,minecraft:diorite)
B(-5,5,3,minecraft:diorite)
B(-5,5,4,minecraft:obsidian)
B(-5,5,5,minecraft:obsidian)
B(-5,5,6,minecraft:obsidian)
B(-5,5,7,minecraft:obsidian)
B(-5,5,8,minecraft:obsidian)
B(-5,6,-7,minecraft:diorite)
B(-5,6,-6,minecraft:diorite)
B(-5,6,-5,minecraft:diorite)
B(-5,6,-4,minecraft:diorite)
B(-5,6,-3,minecraft:diorite)
B(-5,6,-2,minecraft:diorite)
B(-5,6,-1,minecraft:diorite)
B(-5,6,0,minecraft:diorite)
B(-5,6,1,minecraft:diorite)
B(-5,6,2,minecraft:diorite)
B(-5,6,3,minecraft:diorite)
B(-5,6,4,minecraft:diorite)
B(-5,6,5,minecraft:obsidian)
B(-5,6,6,minecraft:obsidian)
B(-5,6,7,minecraft:obsidian)
B(-5,6,8,minecraft:obsidian)
B(-5,7,-7,minecraft:diorite)
B(-5,7,-6,minecraft:diorite)
B(-5,7,-5,minecraft:diorite)
B(-5,7,-4,minecraft:diorite)
B(-5,7,-3,minecraft:diorite)
B(-5,7,-2,minecraft:diorite)
B(-5,7,-1,minecraft:diorite)
B(-5,7,0,minecraft:diorite)
B(-5,7,1,minecraft:diorite)
B(-5,7,2,minecraft:obsidian)
B(-5,7,3,minecraft:obsidian)
B(-5,7,4,minecraft:obsidian)
B(-5,7,5,minecraft:diorite)
B(-5,7,6,minecraft:obsidian)
B(-5,7,7,minecraft:obsidian)
B(-5,7,8,minecraft:obsidian)
B(-5,8,-7,minecraft:diorite)
B(-5,8,-6,minecraft:diorite)
B(-5,8,-5,minecraft:diorite)
B(-5,8,-4,minecraft:diorite)
B(-5,8,-3,minecraft:diorite)
B(-5,8,-2,minecraft:diorite)
B(-5,8,-1,minecraft:obsidian)
B(-5,8,0,minecraft:obsidian)
B(-5,8,1,minecraft:obsidian)
B(-5,8,2,minecraft:obsidian)
B(-5,8,3,minecraft:obsidian)
B(-5,8,4,minecraft:obsidian)
B(-5,8,5,minecraft:obsidian)
B(-5,8,6,minecraft:diorite)
B(-5,8,7,minecraft:diorite)
B(-5,8,8,minecraft:diorite)
B(-5,9,-7,minecraft:obsidian)
B(-5,9,-6,minecraft:obsidian)
B(-5,9,-5,minecraft:obsidian)
B(-5,9,-4,minecraft:obsidian)
B(-5,9,-3,minecraft:obsidian)
B(-5,9,-2,minecraft:obsidian)
B(-5,9,-1,minecraft:obsidian)
B(-5,9,0,minecraft:obsidian)
B(-5,9,1,minecraft:obsidian)
B(-5,9,2,minecraft:obsidian)
B(-5,9,3,minecraft:obsidian)
B(-5,9,4,minecraft:obsidian)
B(-5,9,5,minecraft:obsidian)
B(-5,9,6,minecraft:obsidian)
B(-5,9,7,minecraft:obsidian)
B(-5,9,8,minecraft:obsidian)
B(-5,10,-7,minecraft:obsidian)
B(-5,10,-6,minecraft:obsidian)
B(-5,10,-5,minecraft:obsidian)
B(-5,10,-4,minecraft:obsidian)
B(-5,10,-3,minecraft:obsidian)
B(-5,10,-2,minecraft:obsidian)
B(-5,10,-1,minecraft:obsidian)
B(-5,10,0,minecraft:obsidian)
B(-5,10,1,minecraft:obsidian)
B(-5,10,2,minecraft:obsidian)
B(-5,10,3,minecraft:obsidian)
B(-5,10,4,minecraft:obsidian)
B(-5,10,5,minecraft:obsidian)
B(-5,10,6,minecraft:obsidian)
B(-5,10,7,minecraft:obsidian)
B(-5,10,8,minecraft:obsidian)
B(-5,11,-7,minecraft:obsidian)
B(-5,11,-6,minecraft:obsidian)
B(-5,11,-5,minecraft:obsidian)
B(-5,11,-4,minecraft:obsidian)
B(-5,11,-3,minecraft:obsidian)
B(-5,11,-2,minecraft:obsidian)
B(-5,11,-1,minecraft:obsidian)
B(-5,11,0,minecraft:obsidian)
B(-5,11,1,minecraft:obsidian)
B(-5,11,2,minecraft:obsidian)
B(-5,11,3,minecraft:obsidian)
B(-5,11,4,minecraft:obsidian)
B(-5,11,5,minecraft:obsidian)
B(-5,11,6,minecraft:obsidian)
B(-5,11,7,minecraft:obsidian)
B(-5,11,8,minecraft:obsidian)
B(-5,12,-7,minecraft:obsidian)
B(-5,12,-6,minecraft:obsidian)
B(-5,12,-5,minecraft:obsidian)
B(-5,12,-4,minecraft:obsidian)
B(-5,12,-3,minecraft:obsidian)
B(-5,12,-2,minecraft:obsidian)
B(-5,12,-1,minecraft:obsidian)
B(-5,12,0,minecraft:obsidian)
B(-5,12,1,minecraft:obsidian)
B(-5,12,2,minecraft:obsidian)
B(-5,12,3,minecraft:obsidian)
B(-5,12,4,minecraft:obsidian)
B(-5,12,5,minecraft:obsidian)
B(-5,12,6,minecraft:obsidian)
B(-5,12,7,minecraft:obsidian)
B(-5,12,8,minecraft:obsidian)
B(-5,13,-7,minecraft:obsidian)
B(-5,13,-6,minecraft:obsidian)
B(-5,13,-5,minecraft:diorite)
B(-5,13,-4,minecraft:diorite)
B(-5,13,-3,minecraft:diorite)
B(-5,13,-2,minecraft:diorite)
B(-5,13,-1,minecraft:obsidian)
B(-5,13,0,minecraft:obsidian)
B(-5,13,1,minecraft:obsidian)
B(-5,13,2,minecraft:obsidian)
B(-5,13,3,minecraft:obsidian)
B(-5,13,4,minecraft:obsidian)
B(-5,13,5,minecraft:obsidian)
B(-5,13,6,minecraft:obsidian)
B(-5,13,7,minecraft:obsidian)
B(-5,13,8,minecraft:obsidian)
B(-5,14,-7,minecraft:obsidian)
B(-5,14,-6,minecraft:diorite)
B(-5,14,-5,minecraft:diorite)
B(-5,14,-4,minecraft:diorite)
B(-5,14,-3,minecraft:diorite)
B(-5,14,-2,minecraft:diorite)
B(-5,14,-1,minecraft:diorite)
B(-5,14,0,minecraft:diorite)
B(-5,14,1,minecraft:diorite)
B(-5,14,2,minecraft:obsidian)
B(-5,14,3,minecraft:obsidian)
B(-5,14,4,minecraft:obsidian)
B(-5,14,5,minecraft:obsidian)
B(-5,14,6,minecraft:obsidian)
B(-5,14,7,minecraft:obsidian)
B(-5,14,8,minecraft:obsidian)
B(-5,15,-7,minecraft:obsidian)
B(-5,15,-6,minecraft:diorite)
B(-5,15,-5,minecraft:diorite)
B(-5,15,-4,minecraft:diorite)
B(-5,15,-3,minecraft:diorite)
B(-5,15,-2,minecraft:diorite)
B(-5,15,-1,minecraft:diorite)
B(-5,15,0,minecraft:diorite)
B(-5,15,1,minecraft:diorite)
B(-5,15,2,minecraft:diorite)
B(-5,15,3,minecraft:obsidian)
B(-5,15,4,minecraft:obsidian)
B(-5,15,5,minecraft:obsidian)
B(-5,15,6,minecraft:obsidian)
B(-5,15,7,minecraft:obsidian)
B(-5,15,8,minecraft:obsidian)
B(-5,16,-7,minecraft:diorite)
B(-5,16,-6,minecraft:diorite)
B(-5,16,-5,minecraft:diorite)
B(-5,16,-4,minecraft:lava)
B(-5,16,-3,minecraft:lava)
B(-5,16,-2,minecraft:lava)
B(-5,16,-1,minecraft:lava)
B(-5,16,0,minecraft:diorite)
B(-5,16,1,minecraft:diorite)
B(-5,16,2,minecraft:diorite)
B(-5,16,3,minecraft:obsidian)
B(-5,16,4,minecraft:obsidian)
B(-5,16,5,minecraft:obsidian)
B(-5,16,6,minecraft:obsidian)
B(-5,16,7,minecraft:obsidian)
B(-5,16,8,minecraft:obsidian)
B(-5,17,-7,minecraft:diorite)
B(-5,17,-6,minecraft:diorite)
B(-5,17,1,minecraft:diorite)
B(-5,17,2,minecraft:diorite)
B(-5,17,3,minecraft:diorite)
B(-5,17,4,minecraft:obsidian)
B(-5,17,5,minecraft:obsidian)
B(-5,17,6,minecraft:obsidian)
B(-5,17,7,minecraft:obsidian)
B(-5,17,8,minecraft:obsidian)
B(-5,18,-7,minecraft:diorite)
B(-5,18,2,minecraft:diorite)
B(-5,18,3,minecraft:diorite)
B(-5,18,4,minecraft:diorite)
B(-5,18,5,minecraft:diorite)
B(-5,18,6,minecraft:obsidian)
B(-5,18,7,minecraft:obsidian)
B(-5,18,8,minecraft:obsidian)
B(-5,19,3,minecraft:diorite)
B(-5,19,4,minecraft:diorite)
B(-5,19,5,minecraft:diorite)
B(-5,19,6,minecraft:diorite)
B(-5,19,7,minecraft:obsidian)
B(-5,19,8,minecraft:obsidian)
B(-5,20,4,minecraft:diorite)
B(-5,20,5,minecraft:diorite)
B(-5,20,6,minecraft:diorite)
B(-5,20,7,minecraft:obsidian)
B(-5,20,8,minecraft:obsidian)
B(-5,21,5,minecraft:diorite)
B(-5,21,6,minecraft:diorite)
B(-5,21,7,minecraft:obsidian)
B(-5,21,8,minecraft:obsidian)
B(-5,22,5,minecraft:diorite)
B(-5,22,6,minecraft:diorite)
B(-5,22,7,minecraft:diorite)
B(-5,22,8,minecraft:obsidian)
B(-5,23,6,minecraft:diorite)
B(-5,23,7,minecraft:diorite)
B(-5,23,8,minecraft:obsidian)
B(-5,24,7,minecraft:diorite)
B(-5,24,8,minecraft:obsidian)
B(-5,25,8,minecraft:obsidian)
B(-5,26,8,minecraft:obsidian)
B(-5,58,7,minecraft:diorite)
B(-5,58,8,minecraft:diorite)
B(-5,59,-6,minecraft:obsidian)
B(-5,59,-4,minecraft:obsidian)
B(-5,59,-3,minecraft:obsidian)
B(-5,59,-2,minecraft:obsidian)
B(-5,59,-1,minecraft:obsidian)
B(-5,59,6,minecraft:obsidian)
B(-5,59,7,minecraft:diorite)
B(-5,59,8,minecraft:diorite)
B(-5,60,-7,minecraft:obsidian)
B(-5,60,-6,minecraft:obsidian)
B(-5,60,-5,minecraft:obsidian)
B(-5,60,-4,minecraft:obsidian)
B(-5,60,-3,minecraft:obsidian)
B(-5,60,-2,minecraft:obsidian)
B(-5,60,-1,minecraft:obsidian)
B(-5,60,0,minecraft:obsidian)
B(-5,60,1,minecraft:obsidian)
B(-5,60,2,minecraft:obsidian)
B(-5,60,3,minecraft:obsidian)
B(-5,60,4,minecraft:obsidian)
B(-5,60,5,minecraft:obsidian)
B(-5,60,6,minecraft:obsidian)
B(-5,60,7,minecraft:diorite)
B(-5,60,8,minecraft:diorite)
B(-5,61,-7,minecraft:obsidian)
B(-5,61,-6,minecraft:obsidian)
B(-5,61,-5,minecraft:obsidian)
B(-5,61,-4,minecraft:obsidian)
B(-5,61,-3,minecraft:obsidian)
B(-5,61,-2,minecraft:obsidian)
B(-5,61,-1,minecraft:obsidian)
B(-5,61,0,minecraft:obsidian)
B(-5,61,1,minecraft:obsidian)
B(-5,61,2,minecraft:obsidian)
B(-5,61,3,minecraft:obsidian)
B(-5,61,4,minecraft:obsidian)
B(-5,61,5,minecraft:obsidian)
B(-5,61,6,minecraft:obsidian)
B(-5,61,7,minecraft:obsidian)
B(-5,61,8,minecraft:diorite)
B(-5,62,-7,minecraft:obsidian)
B(-5,62,-6,minecraft:obsidian)
B(-5,62,-5,minecraft:obsidian)
B(-5,62,-4,minecraft:obsidian)
B(-5,62,-3,minecraft:obsidian)
B(-5,62,-2,minecraft:obsidian)
B(-5,62,-1,minecraft:obsidian)
B(-5,62,0,minecraft:obsidian)
B(-5,62,1,minecraft:obsidian)
B(-5,62,2,minecraft:obsidian)
B(-5,62,3,minecraft:obsidian)
B(-5,62,4,minecraft:obsidian)
B(-5,62,5,minecraft:obsidian)
B(-5,62,6,minecraft:obsidian)
B(-5,62,7,minecraft:obsidian)
B(-5,62,8,minecraft:obsidian)
B(-5,63,-7,minecraft:obsidian)
B(-5,63,-6,minecraft:obsidian)
B(-5,63,-5,minecraft:obsidian)
B(-5,63,-4,minecraft:obsidian)
B(-5,63,-3,minecraft:obsidian)
B(-5,63,-2,minecraft:obsidian)
B(-5,63,-1,minecraft:obsidian)
B(-5,63,0,minecraft:obsidian)
B(-5,63,1,minecraft:obsidian)
B(-5,63,2,minecraft:obsidian)
B(-5,63,3,minecraft:obsidian)
B(-5,63,4,minecraft:obsidian)
B(-5,63,5,minecraft:obsidian)
B(-5,63,6,minecraft:obsidian)
B(-5,63,7,minecraft:obsidian)
B(-5,63,8,minecraft:obsidian)
B(-5,64,-7,minecraft:obsidian)
B(-5,64,-6,minecraft:obsidian)
B(-5,64,-5,minecraft:obsidian)
B(-5,64,-4,minecraft:obsidian)
B(-5,64,-3,minecraft:obsidian)
B(-5,64,-2,minecraft:obsidian)
B(-5,64,-1,minecraft:obsidian)
B(-5,64,0,minecraft:obsidian)
B(-5,64,1,minecraft:obsidian)
B(-5,64,2,minecraft:obsidian)
B(-5,64,3,minecraft:obsidian)
B(-5,64,4,minecraft:obsidian)
B(-5,64,5,minecraft:obsidian)
B(-5,64,6,minecraft:obsidian)
B(-5,64,7,minecraft:obsidian)
B(-5,64,8,minecraft:obsidian)
B(-5,65,-7,minecraft:obsidian)
B(-5,65,-6,minecraft:obsidian)
B(-5,65,-5,minecraft:obsidian)
B(-5,65,-4,minecraft:obsidian)
B(-5,65,-3,minecraft:obsidian)
B(-5,65,-2,minecraft:obsidian)
B(-5,65,-1,minecraft:obsidian)
B(-5,65,0,minecraft:obsidian)
B(-5,65,1,minecraft:obsidian)
B(-5,65,2,minecraft:obsidian)
B(-5,65,3,minecraft:obsidian)
B(-5,65,4,minecraft:obsidian)
B(-5,65,5,minecraft:obsidian)
B(-5,65,6,minecraft:obsidian)
B(-5,65,7,minecraft:obsidian)
B(-5,65,8,minecraft:obsidian)
B(-5,66,-7,minecraft:obsidian)
B(-5,66,-6,minecraft:obsidian)
B(-5,66,-5,minecraft:obsidian)
B(-5,66,-4,minecraft:obsidian)
B(-5,66,-3,minecraft:obsidian)
B(-5,66,-2,minecraft:obsidian)
B(-5,66,-1,minecraft:obsidian)
B(-5,66,0,minecraft:obsidian)
B(-5,66,1,minecraft:obsidian)
B(-5,66,2,minecraft:obsidian)
B(-5,66,3,minecraft:obsidian)
B(-5,66,4,minecraft:obsidian)
B(-5,66,5,minecraft:obsidian)
B(-5,66,6,minecraft:obsidian)
B(-5,66,7,minecraft:obsidian)
B(-5,66,8,minecraft:obsidian)
B(-5,67,-7,minecraft:obsidian)
B(-5,67,-6,minecraft:obsidian)
B(-5,67,-5,minecraft:obsidian)
B(-5,67,-4,minecraft:obsidian)
B(-5,67,-3,minecraft:obsidian)
B(-5,67,-2,minecraft:obsidian)
B(-5,67,-1,minecraft:obsidian)
B(-5,67,0,minecraft:obsidian)
B(-5,67,1,minecraft:obsidian)
B(-5,67,2,minecraft:obsidian)
B(-5,67,3,minecraft:obsidian)
B(-5,67,4,minecraft:obsidian)
B(-5,67,5,minecraft:obsidian)
B(-5,67,6,minecraft:obsidian)
B(-5,67,7,minecraft:obsidian)
B(-5,67,8,minecraft:obsidian)
B(-5,68,-7,minecraft:obsidian)
B(-5,68,-6,minecraft:obsidian)
B(-5,68,-5,minecraft:obsidian)
B(-5,68,-4,minecraft:obsidian)
B(-5,68,-3,minecraft:obsidian)
B(-5,68,-2,minecraft:obsidian)
B(-5,68,-1,minecraft:obsidian)
B(-5,68,0,minecraft:obsidian)
B(-5,68,1,minecraft:obsidian)
B(-5,68,2,minecraft:obsidian)
B(-5,68,3,minecraft:obsidian)
B(-5,68,4,minecraft:obsidian)
B(-5,68,5,minecraft:obsidian)
B(-5,68,6,minecraft:obsidian)
B(-5,68,7,minecraft:obsidian)
B(-5,68,8,minecraft:obsidian)
B(-5,69,-7,minecraft:obsidian)
B(-5,69,-6,minecraft:obsidian)
B(-5,69,-5,minecraft:obsidian)
B(-5,69,-4,minecraft:obsidian)
B(-5,69,-3,minecraft:obsidian)
B(-5,69,-2,minecraft:obsidian)
B(-5,69,-1,minecraft:obsidian)
B(-5,69,0,minecraft:obsidian)
B(-5,69,1,minecraft:obsidian)
B(-5,69,2,minecraft:obsidian)
B(-5,69,3,minecraft:obsidian)
B(-5,69,4,minecraft:obsidian)
B(-5,69,5,minecraft:obsidian)
B(-5,69,6,minecraft:obsidian)
B(-5,69,7,minecraft:obsidian)
B(-5,69,8,minecraft:obsidian)
B(-5,70,-7,minecraft:obsidian)
B(-5,70,-6,minecraft:obsidian)
B(-5,70,-5,minecraft:diorite)
B(-5,70,-4,minecraft:diorite)
B(-5,70,-3,minecraft:diorite)
B(-5,70,-2,minecraft:diorite)
B(-5,70,-1,minecraft:diorite)
B(-5,70,0,minecraft:diorite)
B(-5,70,1,minecraft:obsidian)
B(-5,70,2,minecraft:obsidian)
B(-5,70,3,minecraft:obsidian)
B(-5,70,4,minecraft:obsidian)
B(-5,70,5,minecraft:obsidian)
B(-5,70,6,minecraft:obsidian)
B(-5,70,7,minecraft:obsidian)
B(-5,70,8,minecraft:obsidian)
B(-5,71,-7,minecraft:diorite)
B(-5,71,-6,minecraft:diorite)
B(-5,71,-5,minecraft:diorite)
B(-5,71,-4,minecraft:diorite)
B(-5,71,-3,minecraft:diorite)
B(-5,71,-2,minecraft:diorite)
B(-5,71,-1,minecraft:diorite)
B(-5,71,0,minecraft:diorite)
B(-5,71,1,minecraft:obsidian)
B(-5,71,2,minecraft:obsidian)
B(-5,71,3,minecraft:obsidian)
B(-5,71,4,minecraft:obsidian)
B(-5,71,5,minecraft:obsidian)
B(-5,71,6,minecraft:obsidian)
B(-5,71,7,minecraft:magma_block)
B(-5,71,8,minecraft:magma_block)
B(-5,72,-7,minecraft:diorite)
B(-5,72,-6,minecraft:diorite)
B(-5,72,-5,minecraft:diorite)
B(-5,72,-4,minecraft:diorite)
B(-5,72,-3,minecraft:diorite)
B(-5,72,-2,minecraft:diorite)
B(-5,72,-1,minecraft:diorite)
B(-5,72,0,minecraft:diorite)
B(-5,72,1,minecraft:obsidian)
B(-5,72,2,minecraft:obsidian)
B(-5,72,3,minecraft:obsidian)
B(-5,72,4,minecraft:obsidian)
B(-5,72,5,minecraft:obsidian)
B(-5,72,6,minecraft:obsidian)
B(-5,72,7,minecraft:magma_block)
B(-5,72,8,minecraft:magma_block)
B(-5,73,-7,minecraft:diorite)
B(-5,73,-6,minecraft:diorite)
B(-5,73,-5,minecraft:diorite)
B(-5,73,-4,minecraft:diorite)
B(-5,73,-3,minecraft:andesite)
B(-5,73,-2,minecraft:diorite)
B(-5,73,-1,minecraft:diorite)
B(-5,73,0,minecraft:diorite)
B(-5,73,1,minecraft:obsidian)
B(-5,73,2,minecraft:obsidian)
B(-5,73,3,minecraft:obsidian)
B(-5,73,4,minecraft:obsidian)
B(-5,73,5,minecraft:obsidian)
B(-5,73,8,minecraft:magma_block)
B(-5,74,-7,minecraft:diorite)
B(-5,74,-6,minecraft:diorite)
B(-5,74,-5,minecraft:diorite)
B(-5,74,-4,minecraft:andesite)
B(-5,74,-2,minecraft:andesite)
B(-5,74,-1,minecraft:andesite)
B(-5,74,0,minecraft:diorite)
B(-5,74,1,minecraft:diorite)
B(-5,74,2,minecraft:obsidian)
B(-5,74,3,minecraft:obsidian)
B(-5,74,4,minecraft:obsidian)
B(-5,75,-7,minecraft:diorite)
B(-5,75,-6,minecraft:diorite)
B(-5,75,-5,minecraft:andesite)
B(-5,75,0,minecraft:andesite)
B(-5,75,1,minecraft:diorite)
B(-5,75,2,minecraft:diorite)
B(-5,75,3,minecraft:obsidian)
B(-5,76,-7,minecraft:diorite)
B(-5,76,-6,minecraft:andesite)
B(-5,76,1,minecraft:diorite)
B(-5,77,-7,minecraft:andesite)
B(-4,2,-1,minecraft:diorite)
B(-4,2,0,minecraft:diorite)
B(-4,2,1,minecraft:diorite)
B(-4,2,2,minecraft:diorite)
B(-4,2,3,minecraft:obsidian)
B(-4,2,4,minecraft:magma_block)
B(-4,2,5,minecraft:magma_block)
B(-4,2,6,minecraft:magma_block)
B(-4,2,7,minecraft:magma_block)
B(-4,2,8,minecraft:magma_block)
B(-4,3,-7,minecraft:diorite)
B(-4,3,-6,minecraft:diorite)
B(-4,3,-5,minecraft:diorite)
B(-4,3,-3,minecraft:diorite)
B(-4,3,-2,minecraft:diorite)
B(-4,3,-1,minecraft:diorite)
B(-4,3,0,minecraft:diorite)
B(-4,3,1,minecraft:diorite)
B(-4,3,2,minecraft:diorite)
B(-4,3,3,minecraft:obsidian)
B(-4,3,4,minecraft:magma_block)
B(-4,3,5,minecraft:magma_block)
B(-4,3,6,minecraft:magma_block)
B(-4,3,7,minecraft:magma_block)
B(-4,3,8,minecraft:magma_block)
B(-4,4,-7,minecraft:diorite)
B(-4,4,-6,minecraft:diorite)
B(-4,4,-5,minecraft:diorite)
B(-4,4,-4,minecraft:diorite)
B(-4,4,-3,minecraft:diorite)
B(-4,4,-2,minecraft:diorite)
B(-4,4,-1,minecraft:diorite)
B(-4,4,0,minecraft:diorite)
B(-4,4,1,minecraft:diorite)
B(-4,4,2,minecraft:diorite)
B(-4,4,3,minecraft:obsidian)
B(-4,4,4,minecraft:obsidian)
B(-4,4,5,minecraft:magma_block)
B(-4,4,6,minecraft:magma_block)
B(-4,4,7,minecraft:magma_block)
B(-4,4,8,minecraft:obsidian)
B(-4,5,-7,minecraft:diorite)
B(-4,5,-6,minecraft:diorite)
B(-4,5,-5,minecraft:diorite)
B(-4,5,-4,minecraft:diorite)
B(-4,5,-3,minecraft:diorite)
B(-4,5,-2,minecraft:diorite)
B(-4,5,-1,minecraft:diorite)
B(-4,5,0,minecraft:diorite)
B(-4,5,1,minecraft:diorite)
B(-4,5,2,minecraft:diorite)
B(-4,5,3,minecraft:diorite)
B(-4,5,4,minecraft:obsidian)
B(-4,5,5,minecraft:obsidian)
B(-4,5,6,minecraft:obsidian)
B(-4,5,7,minecraft:obsidian)
B(-4,5,8,minecraft:obsidian)
B(-4,6,-7,minecraft:diorite)
B(-4,6,-6,minecraft:diorite)
B(-4,6,-5,minecraft:diorite)
B(-4,6,-4,minecraft:diorite)
B(-4,6,-3,minecraft:diorite)
B(-4,6,-2,minecraft:diorite)
B(-4,6,-1,minecraft:diorite)
B(-4,6,0,minecraft:diorite)
B(-4,6,1,minecraft:diorite)
B(-4,6,2,minecraft:diorite)
B(-4,6,3,minecraft:diorite)
B(-4,6,4,minecraft:diorite)
B(-4,6,5,minecraft:obsidian)
B(-4,6,6,minecraft:obsidian)
B(-4,6,7,minecraft:obsidian)
B(-4,6,8,minecraft:obsidian)
B(-4,7,-7,minecraft:diorite)
B(-4,7,-6,minecraft:diorite)
B(-4,7,-5,minecraft:diorite)
B(-4,7,-4,minecraft:diorite)
B(-4,7,-3,minecraft:diorite)
B(-4,7,-2,minecraft:diorite)
B(-4,7,-1,minecraft:diorite)
B(-4,7,0,minecraft:diorite)
B(-4,7,1,minecraft:diorite)
B(-4,7,2,minecraft:diorite)
B(-4,7,3,minecraft:obsidian)
B(-4,7,4,minecraft:obsidian)
B(-4,7,5,minecraft:diorite)
B(-4,7,6,minecraft:obsidian)
B(-4,7,7,minecraft:obsidian)
B(-4,7,8,minecraft:obsidian)
B(-4,8,-7,minecraft:diorite)
B(-4,8,-6,minecraft:diorite)
B(-4,8,-5,minecraft:diorite)
B(-4,8,-4,minecraft:obsidian)
B(-4,8,-3,minecraft:obsidian)
B(-4,8,-2,minecraft:obsidian)
B(-4,8,-1,minecraft:obsidian)
B(-4,8,0,minecraft:obsidian)
B(-4,8,1,minecraft:obsidian)
B(-4,8,2,minecraft:obsidian)
B(-4,8,3,minecraft:obsidian)
B(-4,8,4,minecraft:obsidian)
B(-4,8,5,minecraft:obsidian)
B(-4,8,6,minecraft:diorite)
B(-4,8,7,minecraft:diorite)
B(-4,8,8,minecraft:diorite)
B(-4,9,-7,minecraft:obsidian)
B(-4,9,-6,minecraft:obsidian)
B(-4,9,-5,minecraft:obsidian)
B(-4,9,-4,minecraft:obsidian)
B(-4,9,-3,minecraft:obsidian)
B(-4,9,-2,minecraft:obsidian)
B(-4,9,-1,minecraft:obsidian)
B(-4,9,0,minecraft:obsidian)
B(-4,9,1,minecraft:obsidian)
B(-4,9,2,minecraft:obsidian)
B(-4,9,3,minecraft:obsidian)
B(-4,9,4,minecraft:obsidian)
B(-4,9,5,minecraft:obsidian)
B(-4,9,6,minecraft:obsidian)
B(-4,9,7,minecraft:obsidian)
B(-4,9,8,minecraft:obsidian)
B(-4,10,-7,minecraft:obsidian)
B(-4,10,-6,minecraft:obsidian)
B(-4,10,-5,minecraft:obsidian)
B(-4,10,-4,minecraft:obsidian)
B(-4,10,-3,minecraft:obsidian)
B(-4,10,-2,minecraft:obsidian)
B(-4,10,-1,minecraft:obsidian)
B(-4,10,0,minecraft:obsidian)
B(-4,10,1,minecraft:obsidian)
B(-4,10,2,minecraft:obsidian)
B(-4,10,3,minecraft:obsidian)
B(-4,10,4,minecraft:obsidian)
B(-4,10,5,minecraft:obsidian)
B(-4,10,6,minecraft:obsidian)
B(-4,10,7,minecraft:obsidian)
B(-4,10,8,minecraft:obsidian)
B(-4,11,-7,minecraft:obsidian)
B(-4,11,-6,minecraft:obsidian)
B(-4,11,-5,minecraft:obsidian)
B(-4,11,-4,minecraft:obsidian)
B(-4,11,-3,minecraft:obsidian)
B(-4,11,-2,minecraft:obsidian)
B(-4,11,-1,minecraft:obsidian)
B(-4,11,0,minecraft:obsidian)
B(-4,11,1,minecraft:obsidian)
B(-4,11,2,minecraft:obsidian)
B(-4,11,3,minecraft:obsidian)
B(-4,11,4,minecraft:obsidian)
B(-4,11,5,minecraft:obsidian)
B(-4,11,6,minecraft:obsidian)
B(-4,11,7,minecraft:obsidian)
B(-4,11,8,minecraft:obsidian)
B(-4,12,-7,minecraft:obsidian)
B(-4,12,-6,minecraft:obsidian)
B(-4,12,-5,minecraft:obsidian)
B(-4,12,-4,minecraft:obsidian)
B(-4,12,-3,minecraft:obsidian)
B(-4,12,-2,minecraft:obsidian)
B(-4,12,-1,minecraft:obsidian)
B(-4,12,0,minecraft:obsidian)
B(-4,12,1,minecraft:obsidian)
B(-4,12,2,minecraft:obsidian)
B(-4,12,3,minecraft:obsidian)
B(-4,12,4,minecraft:obsidian)
B(-4,12,5,minecraft:obsidian)
B(-4,12,6,minecraft:obsidian)
B(-4,12,7,minecraft:obsidian)
B(-4,12,8,minecraft:obsidian)
B(-4,13,-7,minecraft:obsidian)
B(-4,13,-6,minecraft:obsidian)
B(-4,13,-5,minecraft:obsidian)
B(-4,13,-4,minecraft:obsidian)
B(-4,13,-3,minecraft:obsidian)
B(-4,13,-2,minecraft:obsidian)
B(-4,13,-1,minecraft:obsidian)
B(-4,13,0,minecraft:obsidian)
B(-4,13,1,minecraft:obsidian)
B(-4,13,2,minecraft:obsidian)
B(-4,13,3,minecraft:obsidian)
B(-4,13,4,minecraft:obsidian)
B(-4,13,5,minecraft:obsidian)
B(-4,13,6,minecraft:obsidian)
B(-4,13,7,minecraft:obsidian)
B(-4,13,8,minecraft:obsidian)
B(-4,14,-7,minecraft:obsidian)
B(-4,14,-6,minecraft:obsidian)
B(-4,14,-5,minecraft:diorite)
B(-4,14,-4,minecraft:diorite)
B(-4,14,-3,minecraft:diorite)
B(-4,14,-2,minecraft:diorite)
B(-4,14,-1,minecraft:diorite)
B(-4,14,0,minecraft:diorite)
B(-4,14,1,minecraft:diorite)
B(-4,14,2,minecraft:obsidian)
B(-4,14,3,minecraft:obsidian)
B(-4,14,4,minecraft:obsidian)
B(-4,14,5,minecraft:obsidian)
B(-4,14,6,minecraft:obsidian)
B(-4,14,7,minecraft:obsidian)
B(-4,14,8,minecraft:obsidian)
B(-4,15,-7,minecraft:obsidian)
B(-4,15,-6,minecraft:obsidian)
B(-4,15,-5,minecraft:diorite)
B(-4,15,-4,minecraft:diorite)
B(-4,15,-3,minecraft:diorite)
B(-4,15,-2,minecraft:diorite)
B(-4,15,-1,minecraft:diorite)
B(-4,15,0,minecraft:diorite)
B(-4,15,1,minecraft:diorite)
B(-4,15,2,minecraft:diorite)
B(-4,15,3,minecraft:obsidian)
B(-4,15,4,minecraft:obsidian)
B(-4,15,5,minecraft:obsidian)
B(-4,15,6,minecraft:obsidian)
B(-4,15,7,minecraft:obsidian)
B(-4,15,8,minecraft:obsidian)
B(-4,16,-7,minecraft:diorite)
B(-4,16,-6,minecraft:diorite)
B(-4,16,-5,minecraft:lava)
B(-4,16,-4,minecraft:lava)
B(-4,16,-3,minecraft:lava)
B(-4,16,-2,minecraft:lava)
B(-4,16,-1,minecraft:diorite)
B(-4,16,0,minecraft:diorite)
B(-4,16,1,minecraft:diorite)
B(-4,16,2,minecraft:diorite)
B(-4,16,3,minecraft:obsidian)
B(-4,16,4,minecraft:obsidian)
B(-4,16,5,minecraft:obsidian)
B(-4,16,6,minecraft:obsidian)
B(-4,16,7,minecraft:obsidian)
B(-4,16,8,minecraft:obsidian)
B(-4,17,-7,minecraft:diorite)
B(-4,17,0,minecraft:diorite)
B(-4,17,1,minecraft:diorite)
B(-4,17,2,minecraft:diorite)
B(-4,17,3,minecraft:diorite)
B(-4,17,4,minecraft:obsidian)
B(-4,17,5,minecraft:obsidian)
B(-4,17,6,minecraft:obsidian)
B(-4,17,7,minecraft:obsidian)
B(-4,17,8,minecraft:obsidian)
B(-4,18,1,minecraft:diorite)
B(-4,18,2,minecraft:diorite)
B(-4,18,3,minecraft:diorite)
B(-4,18,4,minecraft:diorite)
B(-4,18,5,minecraft:diorite)
B(-4,18,6,minecraft:obsidian)
B(-4,18,7,minecraft:obsidian)
B(-4,18,8,minecraft:obsidian)
B(-4,19,2,minecraft:diorite)
B(-4,19,3,minecraft:diorite)
B(-4,19,4,minecraft:diorite)
B(-4,19,5,minecraft:diorite)
B(-4,19,6,minecraft:diorite)
B(-4,19,7,minecraft:obsidian)
B(-4,19,8,minecraft:obsidian)
B(-4,20,3,minecraft:diorite)
B(-4,20,4,minecraft:diorite)
B(-4,20,5,minecraft:diorite)
B(-4,20,6,minecraft:diorite)
B(-4,20,7,minecraft:obsidian)
B(-4,20,8,minecraft:obsidian)
B(-4,21,4,minecraft:diorite)
B(-4,21,5,minecraft:diorite)
B(-4,21,6,minecraft:diorite)
B(-4,21,7,minecraft:obsidian)
B(-4,21,8,minecraft:obsidian)
B(-4,22,5,minecraft:diorite)
B(-4,22,6,minecraft:diorite)
B(-4,22,7,minecraft:obsidian)
B(-4,22,8,minecraft:obsidian)
B(-4,23,6,minecraft:diorite)
B(-4,23,7,minecraft:obsidian)
B(-4,23,8,minecraft:obsidian)
B(-4,24,7,minecraft:obsidian)
B(-4,24,8,minecraft:obsidian)
B(-4,25,8,minecraft:obsidian)
B(-4,59,7,minecraft:diorite)
B(-4,59,8,minecraft:diorite)
B(-4,60,-6,minecraft:obsidian)
B(-4,60,-4,minecraft:obsidian)
B(-4,60,-3,minecraft:obsidian)
B(-4,60,-2,minecraft:obsidian)
B(-4,60,-1,minecraft:obsidian)
B(-4,60,0,minecraft:obsidian)
B(-4,60,1,minecraft:obsidian)
B(-4,60,2,minecraft:obsidian)
B(-4,60,3,minecraft:obsidian)
B(-4,60,4,minecraft:obsidian)
B(-4,60,5,minecraft:obsidian)
B(-4,60,6,minecraft:diorite)
B(-4,60,7,minecraft:diorite)
B(-4,60,8,minecraft:diorite)
B(-4,61,-7,minecraft:obsidian)
B(-4,61,-6,minecraft:obsidian)
B(-4,61,-5,minecraft:obsidian)
B(-4,61,-4,minecraft:obsidian)
B(-4,61,-3,minecraft:obsidian)
B(-4,61,-2,minecraft:obsidian)
B(-4,61,-1,minecraft:obsidian)
B(-4,61,0,minecraft:obsidian)
B(-4,61,1,minecraft:obsidian)
B(-4,61,2,minecraft:obsidian)
B(-4,61,3,minecraft:obsidian)
B(-4,61,4,minecraft:obsidian)
B(-4,61,5,minecraft:obsidian)
B(-4,61,6,minecraft:diorite)
B(-4,61,7,minecraft:diorite)
B(-4,61,8,minecraft:diorite)
B(-4,62,-7,minecraft:obsidian)
B(-4,62,-6,minecraft:obsidian)
B(-4,62,-5,minecraft:obsidian)
B(-4,62,-4,minecraft:obsidian)
B(-4,62,-3,minecraft:obsidian)
B(-4,62,-2,minecraft:obsidian)
B(-4,62,-1,minecraft:obsidian)
B(-4,62,0,minecraft:obsidian)
B(-4,62,1,minecraft:obsidian)
B(-4,62,2,minecraft:obsidian)
B(-4,62,3,minecraft:obsidian)
B(-4,62,4,minecraft:obsidian)
B(-4,62,5,minecraft:obsidian)
B(-4,62,6,minecraft:obsidian)
B(-4,62,7,minecraft:obsidian)
B(-4,62,8,minecraft:obsidian)
B(-4,63,-7,minecraft:obsidian)
B(-4,63,-6,minecraft:obsidian)
B(-4,63,-5,minecraft:obsidian)
B(-4,63,-4,minecraft:obsidian)
B(-4,63,-3,minecraft:obsidian)
B(-4,63,-2,minecraft:obsidian)
B(-4,63,-1,minecraft:obsidian)
B(-4,63,0,minecraft:obsidian)
B(-4,63,1,minecraft:obsidian)
B(-4,63,2,minecraft:obsidian)
B(-4,63,3,minecraft:obsidian)
B(-4,63,4,minecraft:obsidian)
B(-4,63,5,minecraft:obsidian)
B(-4,63,6,minecraft:obsidian)
B(-4,63,7,minecraft:obsidian)
B(-4,63,8,minecraft:obsidian)
B(-4,64,-7,minecraft:obsidian)
B(-4,64,-6,minecraft:obsidian)
B(-4,64,-5,minecraft:obsidian)
B(-4,64,-4,minecraft:obsidian)
B(-4,64,-3,minecraft:obsidian)
B(-4,64,-2,minecraft:obsidian)
B(-4,64,-1,minecraft:obsidian)
B(-4,64,0,minecraft:obsidian)
B(-4,64,1,minecraft:obsidian)
B(-4,64,2,minecraft:obsidian)
B(-4,64,3,minecraft:obsidian)
B(-4,64,4,minecraft:obsidian)
B(-4,64,5,minecraft:obsidian)
B(-4,64,6,minecraft:obsidian)
B(-4,64,7,minecraft:obsidian)
B(-4,64,8,minecraft:obsidian)
B(-4,65,-7,minecraft:obsidian)
B(-4,65,-6,minecraft:obsidian)
B(-4,65,-5,minecraft:obsidian)
B(-4,65,-4,minecraft:obsidian)
B(-4,65,-3,minecraft:obsidian)
B(-4,65,-2,minecraft:obsidian)
B(-4,65,-1,minecraft:obsidian)
B(-4,65,0,minecraft:obsidian)
B(-4,65,1,minecraft:obsidian)
B(-4,65,2,minecraft:obsidian)
B(-4,65,3,minecraft:obsidian)
B(-4,65,4,minecraft:obsidian)
B(-4,65,5,minecraft:obsidian)
B(-4,65,6,minecraft:obsidian)
B(-4,65,7,minecraft:obsidian)
B(-4,65,8,minecraft:obsidian)
B(-4,66,-7,minecraft:obsidian)
B(-4,66,-6,minecraft:obsidian)
B(-4,66,-5,minecraft:obsidian)
B(-4,66,-4,minecraft:obsidian)
B(-4,66,-3,minecraft:obsidian)
B(-4,66,-2,minecraft:obsidian)
B(-4,66,-1,minecraft:obsidian)
B(-4,66,0,minecraft:obsidian)
B(-4,66,1,minecraft:obsidian)
B(-4,66,2,minecraft:obsidian)
B(-4,66,3,minecraft:obsidian)
B(-4,66,4,minecraft:obsidian)
B(-4,66,5,minecraft:obsidian)
B(-4,66,6,minecraft:obsidian)
B(-4,66,7,minecraft:obsidian)
B(-4,66,8,minecraft:obsidian)
B(-4,67,-7,minecraft:obsidian)
B(-4,67,-6,minecraft:obsidian)
B(-4,67,-5,minecraft:obsidian)
B(-4,67,-4,minecraft:obsidian)
B(-4,67,-3,minecraft:obsidian)
B(-4,67,-2,minecraft:obsidian)
B(-4,67,-1,minecraft:obsidian)
B(-4,67,0,minecraft:obsidian)
B(-4,67,1,minecraft:obsidian)
B(-4,67,2,minecraft:obsidian)
B(-4,67,3,minecraft:obsidian)
B(-4,67,4,minecraft:obsidian)
B(-4,67,5,minecraft:obsidian)
B(-4,67,6,minecraft:obsidian)
B(-4,67,7,minecraft:obsidian)
B(-4,67,8,minecraft:obsidian)
B(-4,68,-7,minecraft:obsidian)
B(-4,68,-6,minecraft:obsidian)
B(-4,68,-5,minecraft:obsidian)
B(-4,68,-4,minecraft:obsidian)
B(-4,68,-3,minecraft:obsidian)
B(-4,68,-2,minecraft:obsidian)
B(-4,68,-1,minecraft:obsidian)
B(-4,68,0,minecraft:obsidian)
B(-4,68,1,minecraft:obsidian)
B(-4,68,2,minecraft:obsidian)
B(-4,68,3,minecraft:obsidian)
B(-4,68,4,minecraft:obsidian)
B(-4,68,5,minecraft:obsidian)
B(-4,68,6,minecraft:obsidian)
B(-4,68,7,minecraft:obsidian)
B(-4,68,8,minecraft:obsidian)
B(-4,69,-7,minecraft:obsidian)
B(-4,69,-6,minecraft:obsidian)
B(-4,69,-5,minecraft:obsidian)
B(-4,69,-4,minecraft:obsidian)
B(-4,69,-3,minecraft:obsidian)
B(-4,69,-2,minecraft:obsidian)
B(-4,69,-1,minecraft:obsidian)
B(-4,69,0,minecraft:obsidian)
B(-4,69,1,minecraft:obsidian)
B(-4,69,2,minecraft:obsidian)
B(-4,69,3,minecraft:obsidian)
B(-4,69,4,minecraft:obsidian)
B(-4,69,5,minecraft:obsidian)
B(-4,69,6,minecraft:obsidian)
B(-4,69,7,minecraft:obsidian)
B(-4,69,8,minecraft:obsidian)
B(-4,70,-7,minecraft:obsidian)
B(-4,70,-6,minecraft:diorite)
B(-4,70,-5,minecraft:diorite)
B(-4,70,-4,minecraft:diorite)
B(-4,70,-3,minecraft:diorite)
B(-4,70,-2,minecraft:diorite)
B(-4,70,-1,minecraft:diorite)
B(-4,70,0,minecraft:diorite)
B(-4,70,1,minecraft:diorite)
B(-4,70,2,minecraft:obsidian)
B(-4,70,3,minecraft:obsidian)
B(-4,70,4,minecraft:obsidian)
B(-4,70,5,minecraft:obsidian)
B(-4,70,6,minecraft:obsidian)
B(-4,70,7,minecraft:obsidian)
B(-4,70,8,minecraft:obsidian)
B(-4,71,-7,minecraft:diorite)
B(-4,71,-6,minecraft:diorite)
B(-4,71,-5,minecraft:diorite)
B(-4,71,-4,minecraft:diorite)
B(-4,71,-3,minecraft:diorite)
B(-4,71,-2,minecraft:diorite)
B(-4,71,-1,minecraft:diorite)
B(-4,71,0,minecraft:diorite)
B(-4,71,1,minecraft:diorite)
B(-4,71,2,minecraft:obsidian)
B(-4,71,3,minecraft:obsidian)
B(-4,71,4,minecraft:obsidian)
B(-4,71,5,minecraft:obsidian)
B(-4,71,6,minecraft:obsidian)
B(-4,71,7,minecraft:obsidian)
B(-4,71,8,minecraft:obsidian)
B(-4,72,-7,minecraft:diorite)
B(-4,72,-6,minecraft:diorite)
B(-4,72,-5,minecraft:diorite)
B(-4,72,-4,minecraft:diorite)
B(-4,72,-3,minecraft:diorite)
B(-4,72,-2,minecraft:diorite)
B(-4,72,-1,minecraft:diorite)
B(-4,72,0,minecraft:diorite)
B(-4,72,1,minecraft:diorite)
B(-4,72,2,minecraft:obsidian)
B(-4,72,3,minecraft:obsidian)
B(-4,72,4,minecraft:obsidian)
B(-4,72,5,minecraft:obsidian)
B(-4,72,6,minecraft:obsidian)
B(-4,72,7,minecraft:obsidian)
B(-4,72,8,minecraft:obsidian)
B(-4,73,-7,minecraft:diorite)
B(-4,73,-6,minecraft:diorite)
B(-4,73,-5,minecraft:diorite)
B(-4,73,-4,minecraft:diorite)
B(-4,73,-3,minecraft:diorite)
B(-4,73,-2,minecraft:diorite)
B(-4,73,-1,minecraft:diorite)
B(-4,73,0,minecraft:diorite)
B(-4,73,1,minecraft:diorite)
B(-4,73,2,minecraft:obsidian)
B(-4,73,3,minecraft:obsidian)
B(-4,73,4,minecraft:obsidian)
B(-4,73,5,minecraft:obsidian)
B(-4,73,6,minecraft:obsidian)
B(-4,73,7,minecraft:obsidian)
B(-4,73,8,minecraft:obsidian)
B(-4,74,-7,minecraft:diorite)
B(-4,74,-6,minecraft:diorite)
B(-4,74,-5,minecraft:diorite)
B(-4,74,-4,minecraft:andesite)
B(-4,74,-3,minecraft:andesite)
B(-4,74,-2,minecraft:andesite)
B(-4,74,-1,minecraft:diorite)
B(-4,74,0,minecraft:diorite)
B(-4,74,1,minecraft:diorite)
B(-4,74,2,minecraft:diorite)
B(-4,74,3,minecraft:obsidian)
B(-4,74,4,minecraft:obsidian)
B(-4,74,5,minecraft:obsidian)
B(-4,75,-7,minecraft:diorite)
B(-4,75,-6,minecraft:diorite)
B(-4,75,-5,minecraft:diorite)
B(-4,75,-1,minecraft:andesite)
B(-4,75,0,minecraft:diorite)
B(-4,75,1,minecraft:diorite)
B(-4,75,2,minecraft:diorite)
B(-4,75,3,minecraft:diorite)
B(-4,75,4,minecraft:andesite)
B(-4,76,-7,minecraft:diorite)
B(-4,76,-6,minecraft:andesite)
B(-4,76,-5,minecraft:andesite)
B(-4,76,0,minecraft:andesite)
B(-4,76,1,minecraft:diorite)
B(-4,76,2,minecraft:andesite)
B(-4,76,3,minecraft:andesite)
B(-4,77,-7,minecraft:andesite)
B(-4,77,1,minecraft:andesite)
B(-3,2,0,minecraft:diorite)
B(-3,2,1,minecraft:diorite)
B(-3,2,2,minecraft:diorite)
B(-3,2,3,minecraft:obsidian)
B(-3,2,4,minecraft:magma_block)
B(-3,2,5,minecraft:magma_block)
B(-3,2,6,minecraft:magma_block)
B(-3,2,7,minecraft:magma_block)
B(-3,2,8,minecraft:magma_block)
B(-3,3,-7,minecraft:diorite)
B(-3,3,-6,minecraft:diorite)
B(-3,3,-5,minecraft:diorite)
B(-3,3,-4,minecraft:diorite)
B(-3,3,-3,minecraft:diorite)
B(-3,3,-2,minecraft:diorite)
B(-3,3,-1,minecraft:diorite)
B(-3,3,0,minecraft:diorite)
B(-3,3,1,minecraft:diorite)
B(-3,3,2,minecraft:diorite)
B(-3,3,3,minecraft:obsidian)
B(-3,3,4,minecraft:magma_block)
B(-3,3,5,minecraft:magma_block)
B(-3,3,6,minecraft:magma_block)
B(-3,3,7,minecraft:magma_block)
B(-3,3,8,minecraft:magma_block)
B(-3,4,-7,minecraft:diorite)
B(-3,4,-6,minecraft:diorite)
B(-3,4,-5,minecraft:diorite)
B(-3,4,-4,minecraft:diorite)
B(-3,4,-3,minecraft:diorite)
B(-3,4,-2,minecraft:diorite)
B(-3,4,-1,minecraft:diorite)
B(-3,4,0,minecraft:diorite)
B(-3,4,1,minecraft:diorite)
B(-3,4,2,minecraft:diorite)
B(-3,4,3,minecraft:obsidian)
B(-3,4,4,minecraft:obsidian)
B(-3,4,5,minecraft:magma_block)
B(-3,4,6,minecraft:magma_block)
B(-3,4,7,minecraft:magma_block)
B(-3,4,8,minecraft:magma_block)
B(-3,5,-7,minecraft:diorite)
B(-3,5,-6,minecraft:diorite)
B(-3,5,-5,minecraft:diorite)
B(-3,5,-4,minecraft:diorite)
B(-3,5,-3,minecraft:diorite)
B(-3,5,-2,minecraft:diorite)
B(-3,5,-1,minecraft:diorite)
B(-3,5,0,minecraft:diorite)
B(-3,5,1,minecraft:diorite)
B(-3,5,2,minecraft:diorite)
B(-3,5,3,minecraft:diorite)
B(-3,5,4,minecraft:obsidian)
B(-3,5,5,minecraft:obsidian)
B(-3,5,6,minecraft:obsidian)
B(-3,5,7,minecraft:obsidian)
B(-3,5,8,minecraft:obsidian)
B(-3,6,-7,minecraft:diorite)
B(-3,6,-6,minecraft:diorite)
B(-3,6,-5,minecraft:diorite)
B(-3,6,-4,minecraft:diorite)
B(-3,6,-3,minecraft:diorite)
B(-3,6,-2,minecraft:diorite)
B(-3,6,-1,minecraft:diorite)
B(-3,6,0,minecraft:diorite)
B(-3,6,1,minecraft:diorite)
B(-3,6,2,minecraft:diorite)
B(-3,6,3,minecraft:diorite)
B(-3,6,4,minecraft:diorite)
B(-3,6,5,minecraft:obsidian)
B(-3,6,6,minecraft:obsidian)
B(-3,6,7,minecraft:obsidian)
B(-3,6,8,minecraft:obsidian)
B(-3,7,-7,minecraft:diorite)
B(-3,7,-6,minecraft:diorite)
B(-3,7,-5,minecraft:diorite)
B(-3,7,-4,minecraft:diorite)
B(-3,7,-3,minecraft:diorite)
B(-3,7,-2,minecraft:diorite)
B(-3,7,-1,minecraft:diorite)
B(-3,7,0,minecraft:diorite)
B(-3,7,1,minecraft:diorite)
B(-3,7,2,minecraft:diorite)
B(-3,7,3,minecraft:obsidian)
B(-3,7,4,minecraft:obsidian)
B(-3,7,5,minecraft:diorite)
B(-3,7,6,minecraft:obsidian)
B(-3,7,7,minecraft:obsidian)
B(-3,7,8,minecraft:obsidian)
B(-3,8,-7,minecraft:diorite)
B(-3,8,-6,minecraft:diorite)
B(-3,8,-5,minecraft:diorite)
B(-3,8,-4,minecraft:obsidian)
B(-3,8,-3,minecraft:obsidian)
B(-3,8,-2,minecraft:obsidian)
B(-3,8,-1,minecraft:obsidian)
B(-3,8,0,minecraft:obsidian)
B(-3,8,1,minecraft:obsidian)
B(-3,8,2,minecraft:obsidian)
B(-3,8,3,minecraft:obsidian)
B(-3,8,4,minecraft:obsidian)
B(-3,8,5,minecraft:obsidian)
B(-3,8,6,minecraft:obsidian)
B(-3,8,7,minecraft:diorite)
B(-3,8,8,minecraft:diorite)
B(-3,9,-7,minecraft:obsidian)
B(-3,9,-6,minecraft:obsidian)
B(-3,9,-5,minecraft:obsidian)
B(-3,9,-4,minecraft:obsidian)
B(-3,9,-3,minecraft:obsidian)
B(-3,9,-2,minecraft:obsidian)
B(-3,9,-1,minecraft:obsidian)
B(-3,9,0,minecraft:obsidian)
B(-3,9,1,minecraft:obsidian)
B(-3,9,2,minecraft:obsidian)
B(-3,9,3,minecraft:obsidian)
B(-3,9,4,minecraft:obsidian)
B(-3,9,5,minecraft:obsidian)
B(-3,9,6,minecraft:obsidian)
B(-3,9,7,minecraft:obsidian)
B(-3,9,8,minecraft:obsidian)
B(-3,10,-7,minecraft:obsidian)
B(-3,10,-6,minecraft:obsidian)
B(-3,10,-5,minecraft:obsidian)
B(-3,10,-4,minecraft:obsidian)
B(-3,10,-3,minecraft:obsidian)
B(-3,10,-2,minecraft:obsidian)
B(-3,10,-1,minecraft:obsidian)
B(-3,10,0,minecraft:obsidian)
B(-3,10,1,minecraft:obsidian)
B(-3,10,2,minecraft:obsidian)
B(-3,10,3,minecraft:obsidian)
B(-3,10,4,minecraft:obsidian)
B(-3,10,5,minecraft:obsidian)
B(-3,10,6,minecraft:obsidian)
B(-3,10,7,minecraft:obsidian)
B(-3,10,8,minecraft:obsidian)
B(-3,11,-7,minecraft:obsidian)
B(-3,11,-6,minecraft:obsidian)
B(-3,11,-5,minecraft:obsidian)
B(-3,11,-4,minecraft:obsidian)
B(-3,11,-3,minecraft:obsidian)
B(-3,11,-2,minecraft:obsidian)
B(-3,11,-1,minecraft:obsidian)
B(-3,11,0,minecraft:obsidian)
B(-3,11,1,minecraft:obsidian)
B(-3,11,2,minecraft:obsidian)
B(-3,11,3,minecraft:obsidian)
B(-3,11,4,minecraft:obsidian)
B(-3,11,5,minecraft:obsidian)
B(-3,11,6,minecraft:obsidian)
B(-3,11,7,minecraft:obsidian)
B(-3,11,8,minecraft:obsidian)
B(-3,12,-7,minecraft:obsidian)
B(-3,12,-6,minecraft:obsidian)
B(-3,12,-5,minecraft:obsidian)
B(-3,12,-4,minecraft:obsidian)
B(-3,12,-3,minecraft:obsidian)
B(-3,12,-2,minecraft:obsidian)
B(-3,12,-1,minecraft:obsidian)
B(-3,12,0,minecraft:obsidian)
B(-3,12,1,minecraft:obsidian)
B(-3,12,2,minecraft:obsidian)
B(-3,12,3,minecraft:obsidian)
B(-3,12,4,minecraft:obsidian)
B(-3,12,5,minecraft:obsidian)
B(-3,12,6,minecraft:obsidian)
B(-3,12,7,minecraft:obsidian)
B(-3,12,8,minecraft:obsidian)
B(-3,13,-7,minecraft:obsidian)
B(-3,13,-6,minecraft:obsidian)
B(-3,13,-5,minecraft:obsidian)
B(-3,13,-4,minecraft:obsidian)
B(-3,13,-3,minecraft:obsidian)
B(-3,13,-2,minecraft:obsidian)
B(-3,13,-1,minecraft:obsidian)
B(-3,13,0,minecraft:obsidian)
B(-3,13,1,minecraft:obsidian)
B(-3,13,2,minecraft:obsidian)
B(-3,13,3,minecraft:obsidian)
B(-3,13,4,minecraft:obsidian)
B(-3,13,5,minecraft:obsidian)
B(-3,13,6,minecraft:obsidian)
B(-3,13,7,minecraft:obsidian)
B(-3,13,8,minecraft:obsidian)
B(-3,14,-7,minecraft:obsidian)
B(-3,14,-6,minecraft:obsidian)
B(-3,14,-5,minecraft:obsidian)
B(-3,14,-4,minecraft:obsidian)
B(-3,14,-3,minecraft:obsidian)
B(-3,14,-2,minecraft:obsidian)
B(-3,14,-1,minecraft:obsidian)
B(-3,14,0,minecraft:obsidian)
B(-3,14,1,minecraft:obsidian)
B(-3,14,2,minecraft:obsidian)
B(-3,14,3,minecraft:obsidian)
B(-3,14,4,minecraft:obsidian)
B(-3,14,5,minecraft:obsidian)
B(-3,14,6,minecraft:obsidian)
B(-3,14,7,minecraft:obsidian)
B(-3,14,8,minecraft:obsidian)
B(-3,15,-7,minecraft:obsidian)
B(-3,15,-6,minecraft:obsidian)
B(-3,15,-5,minecraft:obsidian)
B(-3,15,-4,minecraft:obsidian)
B(-3,15,-3,minecraft:obsidian)
B(-3,15,-2,minecraft:obsidian)
B(-3,15,-1,minecraft:diorite)
B(-3,15,0,minecraft:diorite)
B(-3,15,1,minecraft:diorite)
B(-3,15,2,minecraft:obsidian)
B(-3,15,3,minecraft:obsidian)
B(-3,15,4,minecraft:obsidian)
B(-3,15,5,minecraft:obsidian)
B(-3,15,6,minecraft:obsidian)
B(-3,15,7,minecraft:obsidian)
B(-3,15,8,minecraft:obsidian)
B(-3,16,-7,minecraft:lava)
B(-3,16,-6,minecraft:lava)
B(-3,16,-5,minecraft:lava)
B(-3,16,-4,minecraft:lava)
B(-3,16,-3,minecraft:lava)
B(-3,16,-2,minecraft:lava)
B(-3,16,-1,minecraft:lava)
B(-3,16,0,minecraft:diorite)
B(-3,16,1,minecraft:diorite)
B(-3,16,2,minecraft:diorite)
B(-3,16,3,minecraft:obsidian)
B(-3,16,4,minecraft:obsidian)
B(-3,16,5,minecraft:obsidian)
B(-3,16,6,minecraft:obsidian)
B(-3,16,7,minecraft:obsidian)
B(-3,16,8,minecraft:obsidian)
B(-3,17,1,minecraft:diorite)
B(-3,17,2,minecraft:diorite)
B(-3,17,3,minecraft:diorite)
B(-3,17,4,minecraft:obsidian)
B(-3,17,5,minecraft:obsidian)
B(-3,17,6,minecraft:obsidian)
B(-3,17,7,minecraft:obsidian)
B(-3,17,8,minecraft:obsidian)
B(-3,18,2,minecraft:diorite)
B(-3,18,3,minecraft:diorite)
B(-3,18,4,minecraft:diorite)
B(-3,18,5,minecraft:obsidian)
B(-3,18,6,minecraft:obsidian)
B(-3,18,7,minecraft:obsidian)
B(-3,18,8,minecraft:obsidian)
B(-3,19,3,minecraft:diorite)
B(-3,19,4,minecraft:diorite)
B(-3,19,5,minecraft:diorite)
B(-3,19,6,minecraft:obsidian)
B(-3,19,7,minecraft:obsidian)
B(-3,19,8,minecraft:obsidian)
B(-3,20,4,minecraft:diorite)
B(-3,20,5,minecraft:diorite)
B(-3,20,6,minecraft:obsidian)
B(-3,20,7,minecraft:obsidian)
B(-3,20,8,minecraft:obsidian)
B(-3,21,5,minecraft:diorite)
B(-3,21,6,minecraft:obsidian)
B(-3,21,7,minecraft:obsidian)
B(-3,21,8,minecraft:obsidian)
B(-3,22,6,minecraft:obsidian)
B(-3,22,7,minecraft:obsidian)
B(-3,22,8,minecraft:obsidian)
B(-3,23,7,minecraft:obsidian)
B(-3,23,8,minecraft:obsidian)
B(-3,24,8,minecraft:obsidian)
B(-3,59,8,minecraft:diorite)
B(-3,60,0,minecraft:obsidian)
B(-3,60,1,minecraft:obsidian)
B(-3,60,2,minecraft:obsidian)
B(-3,60,3,minecraft:obsidian)
B(-3,60,6,minecraft:diorite)
B(-3,60,7,minecraft:diorite)
B(-3,60,8,minecraft:diorite)
B(-3,61,-7,minecraft:obsidian)
B(-3,61,-6,minecraft:obsidian)
B(-3,61,-5,minecraft:obsidian)
B(-3,61,-4,minecraft:obsidian)
B(-3,61,-3,minecraft:obsidian)
B(-3,61,-2,minecraft:obsidian)
B(-3,61,-1,minecraft:obsidian)
B(-3,61,0,minecraft:obsidian)
B(-3,61,1,minecraft:obsidian)
B(-3,61,2,minecraft:obsidian)
B(-3,61,3,minecraft:obsidian)
B(-3,61,4,minecraft:diorite)
B(-3,61,5,minecraft:diorite)
B(-3,61,6,minecraft:diorite)
B(-3,61,7,minecraft:diorite)
B(-3,61,8,minecraft:diorite)
B(-3,62,-7,minecraft:obsidian)
B(-3,62,-6,minecraft:obsidian)
B(-3,62,-5,minecraft:obsidian)
B(-3,62,-4,minecraft:obsidian)
B(-3,62,-3,minecraft:obsidian)
B(-3,62,-2,minecraft:obsidian)
B(-3,62,-1,minecraft:obsidian)
B(-3,62,0,minecraft:obsidian)
B(-3,62,1,minecraft:obsidian)
B(-3,62,2,minecraft:obsidian)
B(-3,62,3,minecraft:obsidian)
B(-3,62,4,minecraft:diorite)
B(-3,62,5,minecraft:diorite)
B(-3,62,6,minecraft:diorite)
B(-3,62,7,minecraft:diorite)
B(-3,62,8,minecraft:diorite)
B(-3,63,-7,minecraft:obsidian)
B(-3,63,-6,minecraft:obsidian)
B(-3,63,-5,minecraft:obsidian)
B(-3,63,-4,minecraft:obsidian)
B(-3,63,-3,minecraft:obsidian)
B(-3,63,-2,minecraft:obsidian)
B(-3,63,-1,minecraft:obsidian)
B(-3,63,0,minecraft:obsidian)
B(-3,63,1,minecraft:obsidian)
B(-3,63,2,minecraft:obsidian)
B(-3,63,3,minecraft:obsidian)
B(-3,63,4,minecraft:obsidian)
B(-3,63,5,minecraft:obsidian)
B(-3,63,6,minecraft:obsidian)
B(-3,63,7,minecraft:obsidian)
B(-3,63,8,minecraft:obsidian)
B(-3,64,-7,minecraft:obsidian)
B(-3,64,-6,minecraft:obsidian)
B(-3,64,-5,minecraft:obsidian)
B(-3,64,-4,minecraft:obsidian)
B(-3,64,-3,minecraft:obsidian)
B(-3,64,-2,minecraft:obsidian)
B(-3,64,-1,minecraft:obsidian)
B(-3,64,0,minecraft:obsidian)
B(-3,64,1,minecraft:obsidian)
B(-3,64,2,minecraft:obsidian)
B(-3,64,3,minecraft:obsidian)
B(-3,64,4,minecraft:obsidian)
B(-3,64,5,minecraft:obsidian)
B(-3,64,6,minecraft:obsidian)
B(-3,64,7,minecraft:obsidian)
B(-3,64,8,minecraft:obsidian)
B(-3,65,-7,minecraft:obsidian)
B(-3,65,-6,minecraft:obsidian)
B(-3,65,-5,minecraft:obsidian)
B(-3,65,-4,minecraft:obsidian)
B(-3,65,-3,minecraft:obsidian)
B(-3,65,-2,minecraft:obsidian)
B(-3,65,-1,minecraft:obsidian)
B(-3,65,0,minecraft:obsidian)
B(-3,65,1,minecraft:obsidian)
B(-3,65,2,minecraft:obsidian)
B(-3,65,3,minecraft:obsidian)
B(-3,65,4,minecraft:obsidian)
B(-3,65,5,minecraft:obsidian)
B(-3,65,6,minecraft:obsidian)
B(-3,65,7,minecraft:obsidian)
B(-3,65,8,minecraft:obsidian)
B(-3,66,-7,minecraft:obsidian)
B(-3,66,-6,minecraft:obsidian)
B(-3,66,-5,minecraft:obsidian)
B(-3,66,-4,minecraft:obsidian)
B(-3,66,-3,minecraft:obsidian)
B(-3,66,-2,minecraft:obsidian)
B(-3,66,-1,minecraft:obsidian)
B(-3,66,0,minecraft:obsidian)
B(-3,66,1,minecraft:obsidian)
B(-3,66,2,minecraft:obsidian)
B(-3,66,3,minecraft:obsidian)
B(-3,66,4,minecraft:obsidian)
B(-3,66,5,minecraft:obsidian)
B(-3,66,6,minecraft:obsidian)
B(-3,66,7,minecraft:obsidian)
B(-3,66,8,minecraft:obsidian)
B(-3,67,-7,minecraft:obsidian)
B(-3,67,-6,minecraft:obsidian)
B(-3,67,-5,minecraft:obsidian)
B(-3,67,-4,minecraft:obsidian)
B(-3,67,-3,minecraft:obsidian)
B(-3,67,-2,minecraft:obsidian)
B(-3,67,-1,minecraft:obsidian)
B(-3,67,0,minecraft:obsidian)
B(-3,67,1,minecraft:obsidian)
B(-3,67,2,minecraft:obsidian)
B(-3,67,3,minecraft:obsidian)
B(-3,67,4,minecraft:obsidian)
B(-3,67,5,minecraft:obsidian)
B(-3,67,6,minecraft:obsidian)
B(-3,67,7,minecraft:obsidian)
B(-3,67,8,minecraft:obsidian)
B(-3,68,-7,minecraft:obsidian)
B(-3,68,-6,minecraft:obsidian)
B(-3,68,-5,minecraft:obsidian)
B(-3,68,-4,minecraft:obsidian)
B(-3,68,-3,minecraft:obsidian)
B(-3,68,-2,minecraft:obsidian)
B(-3,68,-1,minecraft:obsidian)
B(-3,68,0,minecraft:obsidian)
B(-3,68,1,minecraft:obsidian)
B(-3,68,2,minecraft:obsidian)
B(-3,68,3,minecraft:obsidian)
B(-3,68,4,minecraft:obsidian)
B(-3,68,5,minecraft:obsidian)
B(-3,68,6,minecraft:obsidian)
B(-3,68,7,minecraft:obsidian)
B(-3,68,8,minecraft:obsidian)
B(-3,69,-7,minecraft:obsidian)
B(-3,69,-6,minecraft:obsidian)
B(-3,69,-5,minecraft:obsidian)
B(-3,69,-4,minecraft:obsidian)
B(-3,69,-3,minecraft:obsidian)
B(-3,69,-2,minecraft:obsidian)
B(-3,69,-1,minecraft:obsidian)
B(-3,69,0,minecraft:obsidian)
B(-3,69,1,minecraft:obsidian)
B(-3,69,2,minecraft:obsidian)
B(-3,69,3,minecraft:diorite)
B(-3,69,4,minecraft:obsidian)
B(-3,69,5,minecraft:obsidian)
B(-3,69,6,minecraft:obsidian)
B(-3,69,7,minecraft:obsidian)
B(-3,69,8,minecraft:obsidian)
B(-3,70,-7,minecraft:obsidian)
B(-3,70,-6,minecraft:diorite)
B(-3,70,-5,minecraft:diorite)
B(-3,70,-4,minecraft:diorite)
B(-3,70,-3,minecraft:diorite)
B(-3,70,-2,minecraft:diorite)
B(-3,70,-1,minecraft:diorite)
B(-3,70,0,minecraft:diorite)
B(-3,70,1,minecraft:diorite)
B(-3,70,2,minecraft:diorite)
B(-3,70,3,minecraft:obsidian)
B(-3,70,4,minecraft:obsidian)
B(-3,70,5,minecraft:obsidian)
B(-3,70,6,minecraft:obsidian)
B(-3,70,7,minecraft:obsidian)
B(-3,70,8,minecraft:obsidian)
B(-3,71,-7,minecraft:diorite)
B(-3,71,-6,minecraft:diorite)
B(-3,71,-5,minecraft:diorite)
B(-3,71,-4,minecraft:diorite)
B(-3,71,-3,minecraft:diorite)
B(-3,71,-2,minecraft:diorite)
B(-3,71,-1,minecraft:diorite)
B(-3,71,0,minecraft:diorite)
B(-3,71,1,minecraft:diorite)
B(-3,71,2,minecraft:diorite)
B(-3,71,3,minecraft:obsidian)
B(-3,71,4,minecraft:obsidian)
B(-3,71,5,minecraft:obsidian)
B(-3,71,6,minecraft:obsidian)
B(-3,71,7,minecraft:obsidian)
B(-3,71,8,minecraft:obsidian)
B(-3,72,-7,minecraft:diorite)
B(-3,72,-6,minecraft:diorite)
B(-3,72,-5,minecraft:diorite)
B(-3,72,-4,minecraft:diorite)
B(-3,72,-3,minecraft:diorite)
B(-3,72,-2,minecraft:diorite)
B(-3,72,-1,minecraft:diorite)
B(-3,72,0,minecraft:diorite)
B(-3,72,1,minecraft:diorite)
B(-3,72,2,minecraft:diorite)
B(-3,72,3,minecraft:obsidian)
B(-3,72,4,minecraft:obsidian)
B(-3,72,5,minecraft:obsidian)
B(-3,72,6,minecraft:obsidian)
B(-3,72,7,minecraft:obsidian)
B(-3,72,8,minecraft:obsidian)
B(-3,73,-7,minecraft:diorite)
B(-3,73,-6,minecraft:diorite)
B(-3,73,-5,minecraft:diorite)
B(-3,73,-4,minecraft:diorite)
B(-3,73,-3,minecraft:diorite)
B(-3,73,-2,minecraft:diorite)
B(-3,73,-1,minecraft:diorite)
B(-3,73,0,minecraft:diorite)
B(-3,73,1,minecraft:diorite)
B(-3,73,2,minecraft:diorite)
B(-3,73,3,minecraft:diorite)
B(-3,73,4,minecraft:obsidian)
B(-3,73,5,minecraft:obsidian)
B(-3,73,6,minecraft:obsidian)
B(-3,73,7,minecraft:obsidian)
B(-3,73,8,minecraft:obsidian)
B(-3,74,-7,minecraft:diorite)
B(-3,74,-6,minecraft:diorite)
B(-3,74,-5,minecraft:diorite)
B(-3,74,-4,minecraft:diorite)
B(-3,74,-3,minecraft:diorite)
B(-3,74,-2,minecraft:diorite)
B(-3,74,-1,minecraft:diorite)
B(-3,74,0,minecraft:diorite)
B(-3,74,1,minecraft:diorite)
B(-3,74,2,minecraft:diorite)
B(-3,74,3,minecraft:diorite)
B(-3,74,4,minecraft:diorite)
B(-3,74,5,minecraft:diorite)
B(-3,74,6,minecraft:obsidian)
B(-3,74,7,minecraft:obsidian)
B(-3,74,8,minecraft:obsidian)
B(-3,75,-7,minecraft:diorite)
B(-3,75,-6,minecraft:diorite)
B(-3,75,-5,minecraft:diorite)
B(-3,75,-4,minecraft:diorite)
B(-3,75,-3,minecraft:diorite)
B(-3,75,-2,minecraft:diorite)
B(-3,75,-1,minecraft:diorite)
B(-3,75,0,minecraft:diorite)
B(-3,75,1,minecraft:diorite)
B(-3,75,2,minecraft:diorite)
B(-3,75,3,minecraft:diorite)
B(-3,75,4,minecraft:diorite)
B(-3,75,5,minecraft:diorite)
B(-3,75,6,minecraft:diorite)
B(-3,76,-7,minecraft:diorite)
B(-3,76,-6,minecraft:andesite)
B(-3,76,-5,minecraft:diorite)
B(-3,76,-4,minecraft:diorite)
B(-3,76,-3,minecraft:diorite)
B(-3,76,-2,minecraft:diorite)
B(-3,76,-1,minecraft:diorite)
B(-3,76,0,minecraft:diorite)
B(-3,76,1,minecraft:diorite)
B(-3,76,2,minecraft:diorite)
B(-3,76,3,minecraft:diorite)
B(-3,76,4,minecraft:diorite)
B(-3,76,5,minecraft:andesite)
B(-3,77,-7,minecraft:andesite)
B(-3,77,-5,minecraft:andesite)
B(-3,77,-4,minecraft:andesite)
B(-3,77,-3,minecraft:andesite)
B(-3,77,-2,minecraft:diorite)
B(-3,77,-1,minecraft:andesite)
B(-3,77,0,minecraft:andesite)
B(-3,77,1,minecraft:diorite)
B(-3,77,2,minecraft:andesite)
B(-3,77,3,minecraft:andesite)
B(-3,77,4,minecraft:andesite)
B(-3,78,-2,minecraft:andesite)
B(-3,78,1,minecraft:andesite)
B(-2,2,-3,minecraft:diorite)
B(-2,2,-2,minecraft:diorite)
B(-2,2,-1,minecraft:diorite)
B(-2,2,0,minecraft:diorite)
B(-2,2,2,minecraft:diorite)
B(-2,2,3,minecraft:obsidian)
B(-2,2,4,minecraft:magma_block)
B(-2,2,5,minecraft:magma_block)
B(-2,2,6,minecraft:magma_block)
B(-2,2,7,minecraft:magma_block)
B(-2,2,8,minecraft:magma_block)
B(-2,3,-7,minecraft:diorite)
B(-2,3,-6,minecraft:diorite)
B(-2,3,-5,minecraft:diorite)
B(-2,3,-4,minecraft:diorite)
B(-2,3,-3,minecraft:diorite)
B(-2,3,-2,minecraft:diorite)
B(-2,3,-1,minecraft:diorite)
B(-2,3,0,minecraft:diorite)
B(-2,3,1,minecraft:diorite)
B(-2,3,2,minecraft:diorite)
B(-2,3,3,minecraft:obsidian)
B(-2,3,4,minecraft:magma_block)
B(-2,3,5,minecraft:magma_block)
B(-2,3,6,minecraft:magma_block)
B(-2,3,7,minecraft:magma_block)
B(-2,3,8,minecraft:magma_block)
B(-2,4,-7,minecraft:diorite)
B(-2,4,-6,minecraft:diorite)
B(-2,4,-5,minecraft:diorite)
B(-2,4,-4,minecraft:diorite)
B(-2,4,-3,minecraft:diorite)
B(-2,4,-2,minecraft:diorite)
B(-2,4,-1,minecraft:diorite)
B(-2,4,0,minecraft:diorite)
B(-2,4,1,minecraft:diorite)
B(-2,4,2,minecraft:diorite)
B(-2,4,3,minecraft:obsidian)
B(-2,4,4,minecraft:obsidian)
B(-2,4,5,minecraft:magma_block)
B(-2,4,6,minecraft:magma_block)
B(-2,4,7,minecraft:magma_block)
B(-2,4,8,minecraft:magma_block)
B(-2,5,-7,minecraft:diorite)
B(-2,5,-6,minecraft:diorite)
B(-2,5,-5,minecraft:diorite)
B(-2,5,-4,minecraft:diorite)
B(-2,5,-3,minecraft:diorite)
B(-2,5,-2,minecraft:diorite)
B(-2,5,-1,minecraft:diorite)
B(-2,5,0,minecraft:diorite)
B(-2,5,1,minecraft:diorite)
B(-2,5,2,minecraft:diorite)
B(-2,5,3,minecraft:diorite)
B(-2,5,4,minecraft:obsidian)
B(-2,5,5,minecraft:obsidian)
B(-2,5,6,minecraft:obsidian)
B(-2,5,7,minecraft:obsidian)
B(-2,5,8,minecraft:obsidian)
B(-2,6,-7,minecraft:diorite)
B(-2,6,-6,minecraft:diorite)
B(-2,6,-5,minecraft:diorite)
B(-2,6,-4,minecraft:diorite)
B(-2,6,-3,minecraft:diorite)
B(-2,6,-2,minecraft:diorite)
B(-2,6,-1,minecraft:diorite)
B(-2,6,0,minecraft:diorite)
B(-2,6,1,minecraft:diorite)
B(-2,6,2,minecraft:diorite)
B(-2,6,3,minecraft:diorite)
B(-2,6,4,minecraft:diorite)
B(-2,6,5,minecraft:obsidian)
B(-2,6,6,minecraft:obsidian)
B(-2,6,7,minecraft:obsidian)
B(-2,6,8,minecraft:obsidian)
B(-2,7,-7,minecraft:diorite)
B(-2,7,-6,minecraft:diorite)
B(-2,7,-5,minecraft:diorite)
B(-2,7,-4,minecraft:diorite)
B(-2,7,-3,minecraft:obsidian)
