
#######################################################################
# +-----------------------------------------------------------------+ #
# |                            BO4 object                           | #
# +-----------------------------------------------------------------+ #
#######################################################################

Author: NLBlackEagle

Description: No description given

SettingsMode: WriteWithoutComments


#######################################################################
# +-----------------------------------------------------------------+ #
# |                          Main settings                          | #
# +-----------------------------------------------------------------+ #
#######################################################################

FixedRotation: 

Frequency: 0

SpawnHeight: highestBlock

UseCenterForHighestBlock: true

##############################
# Height Limits for the BO4. #
##############################

MinHeight: 0

MaxHeight: 255

InheritBO3: 

InheritBO3Rotation: NORTH

OverrideChildSettings: true

OverrideParentHeight: false

CanOverride: false

BranchFrequency: 0

BranchFrequencyGroup: 

MustBeBelowOther: false

MustBeInside: 

CannotBeInside: 

ReplacesBO3: 

MustBeInsideWorldBorders: false

CanSpawnOnWater: true

SpawnOnWaterOnly: false

SpawnUnderWater: false

SpawnAtWaterLevel: false

HeightOffset: 0

RemoveAir: true

ReplaceAbove: 

ReplaceBelow: 

ReplaceWithBiomeBlocks: true

ReplaceWithSurfaceBlock: GRASS

ReplaceWithGroundBlock: DIRT

ReplaceWithStoneBlock: STONE

SmoothRadius: 0

SmoothHeightOffset: 0

SmoothStartTop: false

SmoothStartWood: false

SmoothingSurfaceBlock: 

SmoothingGroundBlock: 

BO3Group: 

IsSpawnPoint: false

DoReplaceBlocks: true


#######################################################################
# +-----------------------------------------------------------------+ #
# |                              Blocks                             | #
# +-----------------------------------------------------------------+ #
#######################################################################

B(-8,14,-3,minecraft:magma_block)
B(-8,14,-2,minecraft:magma_block)
B(-8,14,-1,minecraft:magma_block)
B(-8,14,0,minecraft:magma_block)
B(-8,14,1,minecraft:magma_block)
B(-8,14,2,minecraft:magma_block)
B(-8,14,3,minecraft:obsidian)
B(-8,14,4,minecraft:obsidian)
B(-8,14,5,minecraft:obsidian)
B(-8,14,6,minecraft:obsidian)
B(-8,14,7,minecraft:diorite)
B(-8,14,8,minecraft:diorite)
B(-8,15,-7,minecraft:diorite)
B(-8,15,-6,minecraft:obsidian)
B(-8,15,-5,minecraft:obsidian)
B(-8,15,-4,minecraft:obsidian)
B(-8,15,-3,minecraft:magma_block)
B(-8,15,-2,minecraft:magma_block)
B(-8,15,-1,minecraft:magma_block)
B(-8,15,0,minecraft:magma_block)
B(-8,15,1,minecraft:magma_block)
B(-8,15,2,minecraft:magma_block)
B(-8,15,3,minecraft:obsidian)
B(-8,15,4,minecraft:obsidian)
B(-8,15,5,minecraft:obsidian)
B(-8,15,6,minecraft:obsidian)
B(-8,15,7,minecraft:diorite)
B(-8,15,8,minecraft:diorite)
B(-8,16,-7,minecraft:diorite)
B(-8,16,-6,minecraft:diorite)
B(-8,16,-5,minecraft:obsidian)
B(-8,16,-4,minecraft:obsidian)
B(-8,16,-3,minecraft:obsidian)
B(-8,16,-2,minecraft:magma_block)
B(-8,16,-1,minecraft:magma_block)
B(-8,16,0,minecraft:magma_block)
B(-8,16,1,minecraft:magma_block)
B(-8,16,2,minecraft:obsidian)
B(-8,16,3,minecraft:obsidian)
B(-8,16,4,minecraft:obsidian)
B(-8,16,5,minecraft:obsidian)
B(-8,16,6,minecraft:obsidian)
B(-8,16,7,minecraft:diorite)
B(-8,16,8,minecraft:diorite)
B(-8,17,-7,minecraft:diorite)
B(-8,17,-6,minecraft:diorite)
B(-8,17,-5,minecraft:obsidian)
B(-8,17,-4,minecraft:obsidian)
B(-8,17,-3,minecraft:obsidian)
B(-8,17,-2,minecraft:obsidian)
B(-8,17,-1,minecraft:obsidian)
B(-8,17,0,minecraft:obsidian)
B(-8,17,1,minecraft:obsidian)
B(-8,17,2,minecraft:obsidian)
B(-8,17,3,minecraft:obsidian)
B(-8,17,4,minecraft:obsidian)
B(-8,17,5,minecraft:obsidian)
B(-8,17,6,minecraft:diorite)
B(-8,17,7,minecraft:diorite)
B(-8,17,8,minecraft:diorite)
B(-8,18,-7,minecraft:diorite)
B(-8,18,-6,minecraft:diorite)
B(-8,18,-5,minecraft:diorite)
B(-8,18,-4,minecraft:obsidian)
B(-8,18,-3,minecraft:obsidian)
B(-8,18,-2,minecraft:obsidian)
B(-8,18,-1,minecraft:obsidian)
B(-8,18,0,minecraft:obsidian)
B(-8,18,1,minecraft:obsidian)
B(-8,18,2,minecraft:obsidian)
B(-8,18,3,minecraft:obsidian)
B(-8,18,4,minecraft:obsidian)
B(-8,18,5,minecraft:diorite)
B(-8,18,6,minecraft:diorite)
B(-8,18,7,minecraft:diorite)
B(-8,18,8,minecraft:obsidian)
B(-8,19,-7,minecraft:diorite)
B(-8,19,-6,minecraft:obsidian)
B(-8,19,-5,minecraft:obsidian)
B(-8,19,-4,minecraft:diorite)
B(-8,19,-3,minecraft:diorite)
B(-8,19,-2,minecraft:obsidian)
B(-8,19,-1,minecraft:obsidian)
B(-8,19,0,minecraft:obsidian)
B(-8,19,1,minecraft:obsidian)
B(-8,19,2,minecraft:obsidian)
B(-8,19,3,minecraft:obsidian)
B(-8,19,4,minecraft:diorite)
B(-8,19,5,minecraft:diorite)
B(-8,19,6,minecraft:obsidian)
B(-8,19,7,minecraft:obsidian)
B(-8,19,8,minecraft:obsidian)
B(-8,20,-7,minecraft:obsidian)
B(-8,20,-6,minecraft:obsidian)
B(-8,20,-5,minecraft:obsidian)
B(-8,20,-4,minecraft:obsidian)
B(-8,20,-3,minecraft:obsidian)
B(-8,20,-2,minecraft:obsidian)
B(-8,20,-1,minecraft:obsidian)
B(-8,20,0,minecraft:obsidian)
B(-8,20,1,minecraft:obsidian)
B(-8,20,2,minecraft:obsidian)
B(-8,20,3,minecraft:obsidian)
B(-8,20,4,minecraft:obsidian)
B(-8,20,5,minecraft:obsidian)
B(-8,20,6,minecraft:obsidian)
B(-8,20,7,minecraft:obsidian)
B(-8,20,8,minecraft:obsidian)
B(-8,21,-7,minecraft:obsidian)
B(-8,21,-6,minecraft:obsidian)
B(-8,21,-5,minecraft:obsidian)
B(-8,21,-4,minecraft:obsidian)
B(-8,21,-3,minecraft:obsidian)
B(-8,21,-2,minecraft:obsidian)
B(-8,21,-1,minecraft:obsidian)
B(-8,21,0,minecraft:obsidian)
B(-8,21,1,minecraft:obsidian)
B(-8,21,2,minecraft:obsidian)
B(-8,21,3,minecraft:obsidian)
B(-8,21,4,minecraft:obsidian)
B(-8,21,5,minecraft:obsidian)
B(-8,21,6,minecraft:obsidian)
B(-8,21,7,minecraft:obsidian)
B(-8,21,8,minecraft:obsidian)
B(-8,22,-7,minecraft:obsidian)
B(-8,22,-6,minecraft:obsidian)
B(-8,22,-5,minecraft:obsidian)
B(-8,22,-4,minecraft:obsidian)
B(-8,22,-3,minecraft:obsidian)
B(-8,22,-2,minecraft:obsidian)
B(-8,22,-1,minecraft:obsidian)
B(-8,22,0,minecraft:obsidian)
B(-8,22,1,minecraft:obsidian)
B(-8,22,2,minecraft:obsidian)
B(-8,22,3,minecraft:obsidian)
B(-8,22,4,minecraft:obsidian)
B(-8,22,5,minecraft:obsidian)
B(-8,22,6,minecraft:obsidian)
B(-8,22,7,minecraft:obsidian)
B(-8,22,8,minecraft:obsidian)
B(-8,23,-7,minecraft:obsidian)
B(-8,23,-6,minecraft:obsidian)
B(-8,23,-5,minecraft:obsidian)
B(-8,23,-4,minecraft:obsidian)
B(-8,23,-3,minecraft:obsidian)
B(-8,23,-2,minecraft:obsidian)
B(-8,23,-1,minecraft:obsidian)
B(-8,23,0,minecraft:obsidian)
B(-8,23,1,minecraft:obsidian)
B(-8,23,2,minecraft:obsidian)
B(-8,23,3,minecraft:obsidian)
B(-8,23,4,minecraft:obsidian)
B(-8,23,5,minecraft:obsidian)
B(-8,23,6,minecraft:obsidian)
B(-8,23,7,minecraft:obsidian)
B(-8,23,8,minecraft:obsidian)
B(-8,24,-7,minecraft:obsidian)
B(-8,24,-6,minecraft:obsidian)
B(-8,24,-5,minecraft:obsidian)
B(-8,24,-4,minecraft:obsidian)
B(-8,24,-3,minecraft:obsidian)
B(-8,24,-2,minecraft:obsidian)
B(-8,24,-1,minecraft:obsidian)
B(-8,24,0,minecraft:obsidian)
B(-8,24,1,minecraft:obsidian)
B(-8,24,2,minecraft:obsidian)
B(-8,24,3,minecraft:obsidian)
B(-8,24,4,minecraft:obsidian)
B(-8,24,5,minecraft:obsidian)
B(-8,24,6,minecraft:obsidian)
B(-8,24,7,minecraft:obsidian)
B(-8,24,8,minecraft:obsidian)
B(-8,25,-7,minecraft:obsidian)
B(-8,25,-6,minecraft:obsidian)
B(-8,25,-5,minecraft:obsidian)
B(-8,25,-4,minecraft:obsidian)
B(-8,25,-3,minecraft:obsidian)
B(-8,25,-2,minecraft:obsidian)
B(-8,25,-1,minecraft:obsidian)
B(-8,25,0,minecraft:obsidian)
B(-8,25,1,minecraft:obsidian)
B(-8,25,2,minecraft:obsidian)
B(-8,25,3,minecraft:obsidian)
B(-8,25,4,minecraft:obsidian)
B(-8,25,5,minecraft:obsidian)
B(-8,25,6,minecraft:obsidian)
B(-8,25,7,minecraft:obsidian)
B(-8,25,8,minecraft:obsidian)
B(-8,26,-7,minecraft:obsidian)
B(-8,26,-6,minecraft:obsidian)
B(-8,26,-5,minecraft:obsidian)
B(-8,26,-4,minecraft:obsidian)
B(-8,26,-3,minecraft:obsidian)
B(-8,26,-2,minecraft:obsidian)
B(-8,26,-1,minecraft:obsidian)
B(-8,26,0,minecraft:obsidian)
B(-8,26,1,minecraft:obsidian)
B(-8,26,2,minecraft:obsidian)
B(-8,26,3,minecraft:obsidian)
B(-8,26,4,minecraft:obsidian)
B(-8,26,5,minecraft:obsidian)
B(-8,26,6,minecraft:obsidian)
B(-8,26,7,minecraft:obsidian)
B(-8,26,8,minecraft:lava)
B(-8,27,-7,minecraft:obsidian)
B(-8,27,-6,minecraft:obsidian)
B(-8,27,-5,minecraft:obsidian)
B(-8,27,-4,minecraft:obsidian)
B(-8,27,-3,minecraft:obsidian)
B(-8,27,-2,minecraft:obsidian)
B(-8,27,-1,minecraft:obsidian)
B(-8,27,0,minecraft:obsidian)
B(-8,27,1,minecraft:obsidian)
B(-8,27,2,minecraft:obsidian)
B(-8,27,3,minecraft:obsidian)
B(-8,27,4,minecraft:obsidian)
B(-8,27,5,minecraft:lava)
B(-8,27,6,minecraft:lava)
B(-8,27,7,minecraft:lava)
B(-8,27,8,minecraft:lava)
B(-8,28,-7,minecraft:obsidian)
B(-8,28,-6,minecraft:obsidian)
B(-8,28,-5,minecraft:obsidian)
B(-8,28,-4,minecraft:obsidian)
B(-8,28,-3,minecraft:obsidian)
B(-8,28,-2,minecraft:obsidian)
B(-8,28,-1,minecraft:obsidian)
B(-8,28,0,minecraft:obsidian)
B(-8,28,1,minecraft:obsidian)
B(-8,28,2,minecraft:obsidian)
B(-8,28,3,minecraft:obsidian)
B(-8,28,4,minecraft:obsidian)
B(-8,29,-7,minecraft:obsidian)
B(-8,29,-6,minecraft:obsidian)
B(-8,29,-5,minecraft:obsidian)
B(-8,29,-4,minecraft:obsidian)
B(-8,29,-3,minecraft:obsidian)
B(-8,29,-2,minecraft:obsidian)
B(-8,29,-1,minecraft:obsidian)
B(-8,29,0,minecraft:lava)
B(-8,29,1,minecraft:lava)
B(-8,29,2,minecraft:lava)
B(-8,29,3,minecraft:lava)
B(-8,30,-7,minecraft:obsidian)
B(-8,30,-6,minecraft:obsidian)
B(-8,30,-5,minecraft:obsidian)
B(-8,30,-4,minecraft:obsidian)
B(-8,30,-3,minecraft:obsidian)
B(-8,30,-2,minecraft:obsidian)
B(-8,30,-1,minecraft:obsidian)
B(-8,30,0,minecraft:lava)
B(-8,31,-7,minecraft:obsidian)
B(-8,31,-6,minecraft:obsidian)
B(-8,31,-5,minecraft:obsidian)
B(-8,31,-4,minecraft:obsidian)
B(-8,31,-3,minecraft:obsidian)
B(-8,31,-2,minecraft:obsidian)
B(-8,31,-1,minecraft:lava)
B(-8,31,0,minecraft:lava)
B(-8,32,-7,minecraft:obsidian)
B(-8,32,-6,minecraft:obsidian)
B(-8,32,-5,minecraft:diorite)
B(-8,32,-4,minecraft:lava)
B(-8,32,-3,minecraft:lava)
B(-8,32,-2,minecraft:lava)
B(-8,32,-1,minecraft:lava)
B(-8,33,-7,minecraft:obsidian)
B(-8,33,-6,minecraft:lava)
B(-8,33,-5,minecraft:lava)
B(-8,33,-4,minecraft:lava)
B(-8,34,-7,minecraft:lava)
B(-8,34,-6,minecraft:lava)
B(-8,35,-7,minecraft:lava)
B(-8,90,8,minecraft:diorite)
B(-8,91,8,minecraft:diorite)
B(-8,92,8,minecraft:diorite)
B(-8,93,-7,minecraft:obsidian)
B(-8,93,8,minecraft:diorite)
B(-8,94,-7,minecraft:obsidian)
B(-8,94,-6,minecraft:obsidian)
B(-8,95,-7,minecraft:obsidian)
B(-8,95,-6,minecraft:obsidian)
B(-8,95,8,minecraft:obsidian)
B(-8,96,-7,minecraft:obsidian)
B(-8,96,-6,minecraft:obsidian)
B(-8,96,7,minecraft:obsidian)
B(-8,96,8,minecraft:obsidian)
B(-8,97,-7,minecraft:obsidian)
B(-8,97,-6,minecraft:obsidian)
B(-8,97,-4,minecraft:obsidian)
B(-8,97,-3,minecraft:obsidian)
B(-8,97,6,minecraft:obsidian)
B(-8,97,7,minecraft:obsidian)
B(-8,97,8,minecraft:obsidian)
B(-8,98,-7,minecraft:obsidian)
B(-8,98,-6,minecraft:obsidian)
B(-8,98,-5,minecraft:obsidian)
B(-8,98,-4,minecraft:obsidian)
B(-8,98,-3,minecraft:obsidian)
B(-8,98,6,minecraft:obsidian)
B(-8,98,7,minecraft:obsidian)
B(-8,98,8,minecraft:obsidian)
B(-8,99,-7,minecraft:obsidian)
B(-8,99,-6,minecraft:obsidian)
B(-8,99,-5,minecraft:obsidian)
B(-8,99,-4,minecraft:obsidian)
B(-8,99,-3,minecraft:obsidian)
B(-8,99,5,minecraft:obsidian)
B(-8,99,6,minecraft:obsidian)
B(-8,99,7,minecraft:obsidian)
B(-8,99,8,minecraft:obsidian)
B(-8,100,-7,minecraft:obsidian)
B(-8,100,-6,minecraft:obsidian)
B(-8,100,-5,minecraft:obsidian)
B(-8,100,-4,minecraft:obsidian)
B(-8,100,-3,minecraft:obsidian)
B(-8,100,5,minecraft:obsidian)
B(-8,100,6,minecraft:obsidian)
B(-8,100,7,minecraft:obsidian)
B(-8,100,8,minecraft:obsidian)
B(-8,101,-7,minecraft:obsidian)
B(-8,101,-6,minecraft:obsidian)
B(-8,101,-5,minecraft:obsidian)
B(-8,101,-4,minecraft:obsidian)
B(-8,101,-3,minecraft:obsidian)
B(-8,101,-2,minecraft:obsidian)
B(-8,101,0,minecraft:obsidian)
B(-8,101,1,minecraft:obsidian)
B(-8,101,2,minecraft:obsidian)
B(-8,101,5,minecraft:obsidian)
B(-8,101,6,minecraft:obsidian)
B(-8,101,7,minecraft:obsidian)
B(-8,101,8,minecraft:obsidian)
B(-8,102,-6,minecraft:obsidian)
B(-8,102,-5,minecraft:obsidian)
B(-8,102,-4,minecraft:obsidian)
B(-8,102,-3,minecraft:obsidian)
B(-8,102,-2,minecraft:obsidian)
B(-8,102,-1,minecraft:obsidian)
B(-8,102,0,minecraft:obsidian)
B(-8,102,1,minecraft:obsidian)
B(-8,102,2,minecraft:obsidian)
B(-8,102,3,minecraft:obsidian)
B(-8,102,4,minecraft:obsidian)
B(-8,102,5,minecraft:obsidian)
B(-8,102,6,minecraft:obsidian)
B(-8,102,7,minecraft:obsidian)
B(-8,102,8,minecraft:obsidian)
B(-8,103,-7,minecraft:obsidian)
B(-8,103,-6,minecraft:obsidian)
B(-8,103,-5,minecraft:obsidian)
B(-8,103,-4,minecraft:obsidian)
B(-8,103,-3,minecraft:obsidian)
B(-8,103,-2,minecraft:obsidian)
B(-8,103,-1,minecraft:obsidian)
B(-8,103,0,minecraft:obsidian)
B(-8,103,1,minecraft:obsidian)
B(-8,103,2,minecraft:obsidian)
B(-8,103,3,minecraft:obsidian)
B(-8,103,4,minecraft:obsidian)
B(-8,103,5,minecraft:obsidian)
B(-8,103,6,minecraft:obsidian)
B(-8,103,7,minecraft:obsidian)
B(-8,103,8,minecraft:diorite)
B(-8,104,-7,minecraft:obsidian)
B(-8,104,-6,minecraft:obsidian)
B(-8,104,-5,minecraft:obsidian)
B(-8,104,-4,minecraft:obsidian)
B(-8,104,-3,minecraft:obsidian)
B(-8,104,-2,minecraft:obsidian)
B(-8,104,-1,minecraft:obsidian)
B(-8,104,0,minecraft:obsidian)
B(-8,104,1,minecraft:obsidian)
B(-8,104,2,minecraft:obsidian)
B(-8,104,3,minecraft:obsidian)
B(-8,104,4,minecraft:obsidian)
B(-8,104,5,minecraft:obsidian)
B(-8,104,6,minecraft:obsidian)
B(-8,104,7,minecraft:obsidian)
B(-8,104,8,minecraft:diorite)
B(-8,105,-7,minecraft:obsidian)
B(-8,105,-6,minecraft:obsidian)
B(-8,105,-5,minecraft:obsidian)
B(-8,105,-4,minecraft:obsidian)
B(-8,105,-3,minecraft:obsidian)
B(-8,105,-2,minecraft:obsidian)
B(-8,105,-1,minecraft:obsidian)
B(-8,105,0,minecraft:obsidian)
B(-8,105,1,minecraft:obsidian)
B(-8,105,2,minecraft:obsidian)
B(-8,105,3,minecraft:obsidian)
B(-8,105,4,minecraft:obsidian)
B(-8,105,5,minecraft:obsidian)
B(-8,105,6,minecraft:obsidian)
B(-8,105,7,minecraft:obsidian)
B(-8,105,8,minecraft:diorite)
B(-8,106,-7,minecraft:obsidian)
B(-8,106,-6,minecraft:obsidian)
B(-8,106,-5,minecraft:obsidian)
B(-8,106,-4,minecraft:obsidian)
B(-8,106,-3,minecraft:obsidian)
B(-8,106,-2,minecraft:obsidian)
B(-8,106,-1,minecraft:obsidian)
B(-8,106,0,minecraft:obsidian)
B(-8,106,1,minecraft:obsidian)
B(-8,106,2,minecraft:obsidian)
B(-8,106,3,minecraft:obsidian)
B(-8,106,4,minecraft:obsidian)
B(-8,106,5,minecraft:obsidian)
B(-8,106,6,minecraft:obsidian)
B(-8,106,7,minecraft:diorite)
B(-8,106,8,minecraft:diorite)
B(-8,107,-7,minecraft:obsidian)
B(-8,107,-6,minecraft:obsidian)
B(-8,107,-5,minecraft:obsidian)
B(-8,107,-4,minecraft:obsidian)
B(-8,107,-3,minecraft:obsidian)
B(-8,107,-2,minecraft:obsidian)
B(-8,107,-1,minecraft:obsidian)
B(-8,107,0,minecraft:obsidian)
B(-8,107,1,minecraft:obsidian)
B(-8,107,2,minecraft:obsidian)
B(-8,107,3,minecraft:obsidian)
B(-8,107,4,minecraft:obsidian)
B(-8,107,5,minecraft:obsidian)
B(-8,107,6,minecraft:obsidian)
B(-8,107,7,minecraft:diorite)
B(-8,107,8,minecraft:diorite)
B(-8,108,-7,minecraft:obsidian)
B(-8,108,-6,minecraft:obsidian)
B(-8,108,-5,minecraft:obsidian)
B(-8,108,-4,minecraft:obsidian)
B(-8,108,-3,minecraft:obsidian)
B(-8,108,-2,minecraft:obsidian)
B(-8,108,-1,minecraft:obsidian)
B(-8,108,0,minecraft:obsidian)
B(-8,108,1,minecraft:obsidian)
B(-8,108,2,minecraft:obsidian)
B(-8,108,3,minecraft:obsidian)
B(-8,108,4,minecraft:obsidian)
B(-8,108,5,minecraft:obsidian)
B(-8,108,6,minecraft:obsidian)
B(-8,108,7,minecraft:diorite)
B(-8,108,8,minecraft:diorite)
B(-8,109,-7,minecraft:obsidian)
B(-8,109,-6,minecraft:obsidian)
B(-8,109,-5,minecraft:obsidian)
B(-8,109,-4,minecraft:obsidian)
B(-8,109,-3,minecraft:obsidian)
B(-8,109,-2,minecraft:obsidian)
B(-8,109,-1,minecraft:obsidian)
B(-8,109,0,minecraft:obsidian)
B(-8,109,1,minecraft:obsidian)
B(-8,109,2,minecraft:obsidian)
B(-8,109,3,minecraft:obsidian)
B(-8,109,4,minecraft:obsidian)
B(-8,109,5,minecraft:obsidian)
B(-8,109,6,minecraft:diorite)
B(-8,109,7,minecraft:diorite)
B(-8,109,8,minecraft:diorite)
B(-8,110,-7,minecraft:obsidian)
B(-8,110,-6,minecraft:obsidian)
B(-8,110,-5,minecraft:obsidian)
B(-8,110,-4,minecraft:obsidian)
B(-8,110,-3,minecraft:obsidian)
B(-8,110,-2,minecraft:obsidian)
B(-8,110,-1,minecraft:obsidian)
B(-8,110,0,minecraft:obsidian)
B(-8,110,1,minecraft:obsidian)
B(-8,110,2,minecraft:obsidian)
B(-8,110,3,minecraft:obsidian)
B(-8,110,4,minecraft:obsidian)
B(-8,110,5,minecraft:diorite)
B(-8,110,6,minecraft:andesite)
B(-8,110,7,minecraft:andesite)
B(-8,110,8,minecraft:andesite)
B(-8,111,-7,minecraft:obsidian)
B(-8,111,-6,minecraft:obsidian)
B(-8,111,-5,minecraft:obsidian)
B(-8,111,-4,minecraft:obsidian)
B(-8,111,-3,minecraft:obsidian)
B(-8,111,-2,minecraft:obsidian)
B(-8,111,-1,minecraft:obsidian)
B(-8,111,0,minecraft:obsidian)
B(-8,111,1,minecraft:obsidian)
B(-8,111,2,minecraft:obsidian)
B(-8,111,3,minecraft:obsidian)
B(-8,111,4,minecraft:diorite)
B(-8,111,5,minecraft:andesite)
B(-8,112,-7,minecraft:obsidian)
B(-8,112,-6,minecraft:obsidian)
B(-8,112,-5,minecraft:obsidian)
B(-8,112,-4,minecraft:obsidian)
B(-8,112,-3,minecraft:obsidian)
B(-8,112,-2,minecraft:obsidian)
B(-8,112,-1,minecraft:obsidian)
B(-8,112,0,minecraft:obsidian)
B(-8,112,1,minecraft:obsidian)
B(-8,112,2,minecraft:obsidian)
B(-8,112,3,minecraft:diorite)
B(-8,112,4,minecraft:andesite)
B(-8,113,-7,minecraft:obsidian)
B(-8,113,-6,minecraft:obsidian)
B(-8,113,-5,minecraft:obsidian)
B(-8,113,-4,minecraft:obsidian)
B(-8,113,-3,minecraft:obsidian)
B(-8,113,-2,minecraft:obsidian)
B(-8,113,-1,minecraft:obsidian)
B(-8,113,0,minecraft:obsidian)
B(-8,113,1,minecraft:obsidian)
B(-8,113,2,minecraft:obsidian)
B(-8,113,3,minecraft:andesite)
B(-8,114,-7,minecraft:obsidian)
B(-8,114,-6,minecraft:obsidian)
B(-8,114,-5,minecraft:obsidian)
B(-8,114,-4,minecraft:obsidian)
B(-8,114,-3,minecraft:obsidian)
B(-8,114,-2,minecraft:andesite)
B(-8,114,-1,minecraft:andesite)
B(-8,114,0,minecraft:andesite)
B(-8,114,1,minecraft:andesite)
B(-8,114,2,minecraft:andesite)
B(-8,115,-7,minecraft:andesite)
B(-8,115,-6,minecraft:andesite)
B(-8,115,-5,minecraft:andesite)
B(-8,115,-4,minecraft:andesite)
B(-8,115,-3,minecraft:andesite)
B(-7,13,8,minecraft:diorite)
B(-7,14,-3,minecraft:magma_block)
B(-7,14,-2,minecraft:magma_block)
B(-7,14,-1,minecraft:magma_block)
B(-7,14,0,minecraft:magma_block)
B(-7,14,1,minecraft:magma_block)
B(-7,14,2,minecraft:magma_block)
B(-7,14,3,minecraft:magma_block)
B(-7,14,4,minecraft:obsidian)
B(-7,14,5,minecraft:obsidian)
B(-7,14,6,minecraft:obsidian)
B(-7,14,7,minecraft:diorite)
B(-7,14,8,minecraft:diorite)
B(-7,15,-7,minecraft:diorite)
B(-7,15,-6,minecraft:diorite)
B(-7,15,-5,minecraft:obsidian)
B(-7,15,-4,minecraft:obsidian)
B(-7,15,-3,minecraft:magma_block)
B(-7,15,-2,minecraft:magma_block)
B(-7,15,-1,minecraft:magma_block)
B(-7,15,0,minecraft:magma_block)
B(-7,15,1,minecraft:magma_block)
B(-7,15,2,minecraft:magma_block)
B(-7,15,3,minecraft:magma_block)
B(-7,15,4,minecraft:obsidian)
B(-7,15,5,minecraft:obsidian)
B(-7,15,6,minecraft:obsidian)
B(-7,15,7,minecraft:diorite)
B(-7,15,8,minecraft:diorite)
B(-7,16,-7,minecraft:diorite)
B(-7,16,-6,minecraft:diorite)
B(-7,16,-5,minecraft:obsidian)
B(-7,16,-4,minecraft:obsidian)
B(-7,16,-3,minecraft:obsidian)
B(-7,16,-2,minecraft:magma_block)
B(-7,16,-1,minecraft:magma_block)
B(-7,16,0,minecraft:magma_block)
B(-7,16,1,minecraft:magma_block)
B(-7,16,2,minecraft:magma_block)
B(-7,16,3,minecraft:obsidian)
B(-7,16,4,minecraft:obsidian)
B(-7,16,5,minecraft:obsidian)
B(-7,16,6,minecraft:obsidian)
B(-7,16,7,minecraft:diorite)
B(-7,16,8,minecraft:diorite)
B(-7,17,-7,minecraft:diorite)
B(-7,17,-6,minecraft:diorite)
B(-7,17,-5,minecraft:diorite)
B(-7,17,-4,minecraft:obsidian)
B(-7,17,-3,minecraft:obsidian)
B(-7,17,-2,minecraft:obsidian)
B(-7,17,-1,minecraft:obsidian)
B(-7,17,0,minecraft:obsidian)
B(-7,17,1,minecraft:obsidian)
B(-7,17,2,minecraft:obsidian)
B(-7,17,3,minecraft:obsidian)
B(-7,17,4,minecraft:obsidian)
B(-7,17,5,minecraft:obsidian)
B(-7,17,6,minecraft:diorite)
B(-7,17,7,minecraft:diorite)
B(-7,17,8,minecraft:diorite)
B(-7,18,-7,minecraft:diorite)
B(-7,18,-6,minecraft:diorite)
B(-7,18,-5,minecraft:diorite)
B(-7,18,-4,minecraft:diorite)
B(-7,18,-3,minecraft:obsidian)
B(-7,18,-2,minecraft:obsidian)
B(-7,18,-1,minecraft:obsidian)
B(-7,18,0,minecraft:obsidian)
B(-7,18,1,minecraft:obsidian)
B(-7,18,2,minecraft:obsidian)
B(-7,18,3,minecraft:obsidian)
B(-7,18,4,minecraft:obsidian)
B(-7,18,5,minecraft:diorite)
B(-7,18,6,minecraft:diorite)
B(-7,18,7,minecraft:obsidian)
B(-7,18,8,minecraft:obsidian)
B(-7,19,-7,minecraft:diorite)
B(-7,19,-6,minecraft:diorite)
B(-7,19,-5,minecraft:diorite)
B(-7,19,-4,minecraft:diorite)
B(-7,19,-3,minecraft:obsidian)
B(-7,19,-2,minecraft:obsidian)
B(-7,19,-1,minecraft:obsidian)
B(-7,19,0,minecraft:obsidian)
B(-7,19,1,minecraft:obsidian)
B(-7,19,2,minecraft:obsidian)
B(-7,19,3,minecraft:obsidian)
B(-7,19,4,minecraft:diorite)
B(-7,19,5,minecraft:diorite)
B(-7,19,6,minecraft:obsidian)
B(-7,19,7,minecraft:obsidian)
B(-7,19,8,minecraft:obsidian)
B(-7,20,-7,minecraft:obsidian)
B(-7,20,-6,minecraft:obsidian)
B(-7,20,-5,minecraft:obsidian)
B(-7,20,-4,minecraft:obsidian)
B(-7,20,-3,minecraft:obsidian)
B(-7,20,-2,minecraft:obsidian)
B(-7,20,-1,minecraft:obsidian)
B(-7,20,0,minecraft:obsidian)
B(-7,20,1,minecraft:obsidian)
B(-7,20,2,minecraft:obsidian)
B(-7,20,3,minecraft:obsidian)
B(-7,20,4,minecraft:obsidian)
B(-7,20,5,minecraft:obsidian)
B(-7,20,6,minecraft:obsidian)
B(-7,20,7,minecraft:obsidian)
B(-7,20,8,minecraft:obsidian)
B(-7,21,-7,minecraft:obsidian)
B(-7,21,-6,minecraft:obsidian)
B(-7,21,-5,minecraft:obsidian)
B(-7,21,-4,minecraft:obsidian)
B(-7,21,-3,minecraft:obsidian)
B(-7,21,-2,minecraft:obsidian)
B(-7,21,-1,minecraft:obsidian)
B(-7,21,0,minecraft:obsidian)
B(-7,21,1,minecraft:obsidian)
B(-7,21,2,minecraft:obsidian)
B(-7,21,3,minecraft:obsidian)
B(-7,21,4,minecraft:obsidian)
B(-7,21,5,minecraft:obsidian)
B(-7,21,6,minecraft:obsidian)
B(-7,21,7,minecraft:obsidian)
B(-7,21,8,minecraft:obsidian)
B(-7,22,-7,minecraft:obsidian)
B(-7,22,-6,minecraft:obsidian)
B(-7,22,-5,minecraft:obsidian)
B(-7,22,-4,minecraft:obsidian)
B(-7,22,-3,minecraft:obsidian)
B(-7,22,-2,minecraft:obsidian)
B(-7,22,-1,minecraft:obsidian)
B(-7,22,0,minecraft:obsidian)
B(-7,22,1,minecraft:obsidian)
B(-7,22,2,minecraft:obsidian)
B(-7,22,3,minecraft:obsidian)
B(-7,22,4,minecraft:obsidian)
B(-7,22,5,minecraft:obsidian)
B(-7,22,6,minecraft:obsidian)
B(-7,22,7,minecraft:obsidian)
B(-7,22,8,minecraft:obsidian)
B(-7,23,-7,minecraft:obsidian)
B(-7,23,-6,minecraft:obsidian)
B(-7,23,-5,minecraft:obsidian)
B(-7,23,-4,minecraft:obsidian)
B(-7,23,-3,minecraft:obsidian)
B(-7,23,-2,minecraft:obsidian)
B(-7,23,-1,minecraft:obsidian)
B(-7,23,0,minecraft:obsidian)
B(-7,23,1,minecraft:obsidian)
B(-7,23,2,minecraft:obsidian)
B(-7,23,3,minecraft:obsidian)
B(-7,23,4,minecraft:obsidian)
B(-7,23,5,minecraft:obsidian)
B(-7,23,6,minecraft:obsidian)
B(-7,23,7,minecraft:obsidian)
B(-7,23,8,minecraft:obsidian)
B(-7,24,-7,minecraft:obsidian)
B(-7,24,-6,minecraft:obsidian)
B(-7,24,-5,minecraft:obsidian)
B(-7,24,-4,minecraft:obsidian)
B(-7,24,-3,minecraft:obsidian)
B(-7,24,-2,minecraft:obsidian)
B(-7,24,-1,minecraft:obsidian)
B(-7,24,0,minecraft:obsidian)
B(-7,24,1,minecraft:obsidian)
B(-7,24,2,minecraft:obsidian)
B(-7,24,3,minecraft:obsidian)
B(-7,24,4,minecraft:obsidian)
B(-7,24,5,minecraft:obsidian)
B(-7,24,6,minecraft:obsidian)
B(-7,24,7,minecraft:obsidian)
B(-7,24,8,minecraft:obsidian)
B(-7,25,-7,minecraft:obsidian)
B(-7,25,-6,minecraft:obsidian)
B(-7,25,-5,minecraft:obsidian)
B(-7,25,-4,minecraft:obsidian)
B(-7,25,-3,minecraft:obsidian)
B(-7,25,-2,minecraft:obsidian)
B(-7,25,-1,minecraft:obsidian)
B(-7,25,0,minecraft:obsidian)
B(-7,25,1,minecraft:obsidian)
B(-7,25,2,minecraft:obsidian)
B(-7,25,3,minecraft:obsidian)
B(-7,25,4,minecraft:obsidian)
B(-7,25,5,minecraft:obsidian)
B(-7,25,6,minecraft:obsidian)
B(-7,25,7,minecraft:obsidian)
B(-7,25,8,minecraft:lava)
B(-7,26,-7,minecraft:obsidian)
B(-7,26,-6,minecraft:obsidian)
B(-7,26,-5,minecraft:obsidian)
B(-7,26,-4,minecraft:obsidian)
B(-7,26,-3,minecraft:obsidian)
B(-7,26,-2,minecraft:obsidian)
B(-7,26,-1,minecraft:obsidian)
B(-7,26,0,minecraft:obsidian)
B(-7,26,1,minecraft:obsidian)
B(-7,26,2,minecraft:obsidian)
B(-7,26,3,minecraft:obsidian)
B(-7,26,4,minecraft:obsidian)
B(-7,26,5,minecraft:obsidian)
B(-7,26,6,minecraft:lava)
B(-7,26,7,minecraft:lava)
B(-7,26,8,minecraft:lava)
B(-7,27,-7,minecraft:obsidian)
B(-7,27,-6,minecraft:obsidian)
B(-7,27,-5,minecraft:obsidian)
B(-7,27,-4,minecraft:obsidian)
B(-7,27,-3,minecraft:obsidian)
B(-7,27,-2,minecraft:obsidian)
B(-7,27,-1,minecraft:obsidian)
B(-7,27,0,minecraft:obsidian)
B(-7,27,1,minecraft:obsidian)
B(-7,27,2,minecraft:obsidian)
B(-7,27,3,minecraft:obsidian)
B(-7,27,4,minecraft:lava)
B(-7,27,5,minecraft:lava)
B(-7,27,6,minecraft:lava)
B(-7,27,7,minecraft:lava)
B(-7,27,8,minecraft:lava)
B(-7,28,-7,minecraft:obsidian)
B(-7,28,-6,minecraft:obsidian)
B(-7,28,-5,minecraft:obsidian)
B(-7,28,-4,minecraft:obsidian)
B(-7,28,-3,minecraft:obsidian)
B(-7,28,-2,minecraft:obsidian)
B(-7,28,-1,minecraft:obsidian)
B(-7,28,0,minecraft:obsidian)
B(-7,28,1,minecraft:obsidian)
B(-7,28,2,minecraft:obsidian)
B(-7,28,3,minecraft:lava)
B(-7,28,4,minecraft:lava)
B(-7,29,-7,minecraft:obsidian)
B(-7,29,-6,minecraft:obsidian)
B(-7,29,-5,minecraft:obsidian)
B(-7,29,-4,minecraft:obsidian)
B(-7,29,-3,minecraft:obsidian)
B(-7,29,-2,minecraft:obsidian)
B(-7,29,-1,minecraft:obsidian)
B(-7,29,0,minecraft:lava)
B(-7,29,1,minecraft:lava)
B(-7,29,2,minecraft:lava)
B(-7,29,3,minecraft:lava)
B(-7,30,-7,minecraft:obsidian)
B(-7,30,-6,minecraft:obsidian)
B(-7,30,-5,minecraft:obsidian)
B(-7,30,-4,minecraft:obsidian)
B(-7,30,-3,minecraft:obsidian)
B(-7,30,-2,minecraft:obsidian)
B(-7,30,-1,minecraft:obsidian)
B(-7,30,0,minecraft:lava)
B(-7,31,-7,minecraft:obsidian)
B(-7,31,-6,minecraft:obsidian)
B(-7,31,-5,minecraft:obsidian)
B(-7,31,-4,minecraft:obsidian)
B(-7,31,-3,minecraft:obsidian)
B(-7,31,-2,minecraft:obsidian)
B(-7,31,-1,minecraft:lava)
B(-7,31,0,minecraft:lava)
B(-7,32,-7,minecraft:obsidian)
B(-7,32,-6,minecraft:obsidian)
B(-7,32,-5,minecraft:diorite)
B(-7,32,-4,minecraft:lava)
B(-7,32,-3,minecraft:lava)
B(-7,32,-2,minecraft:lava)
B(-7,32,-1,minecraft:lava)
B(-7,33,-7,minecraft:obsidian)
B(-7,33,-6,minecraft:lava)
B(-7,33,-5,minecraft:lava)
B(-7,33,-4,minecraft:lava)
B(-7,34,-7,minecraft:lava)
B(-7,34,-6,minecraft:lava)
B(-7,35,-7,minecraft:lava)
B(-7,93,8,minecraft:diorite)
B(-7,94,8,minecraft:diorite)
B(-7,95,8,minecraft:diorite)
B(-7,96,8,minecraft:obsidian)
B(-7,97,7,minecraft:obsidian)
B(-7,97,8,minecraft:obsidian)
B(-7,98,5,minecraft:obsidian)
B(-7,98,6,minecraft:obsidian)
B(-7,98,7,minecraft:obsidian)
B(-7,98,8,minecraft:obsidian)
B(-7,99,5,minecraft:obsidian)
B(-7,99,6,minecraft:obsidian)
B(-7,99,7,minecraft:obsidian)
B(-7,99,8,minecraft:obsidian)
B(-7,100,4,minecraft:obsidian)
B(-7,100,5,minecraft:obsidian)
B(-7,100,6,minecraft:obsidian)
B(-7,100,7,minecraft:obsidian)
B(-7,100,8,minecraft:obsidian)
B(-7,101,-1,minecraft:obsidian)
B(-7,101,0,minecraft:obsidian)
B(-7,101,1,minecraft:obsidian)
B(-7,101,2,minecraft:obsidian)
B(-7,101,4,minecraft:obsidian)
B(-7,101,5,minecraft:obsidian)
B(-7,101,6,minecraft:obsidian)
B(-7,101,7,minecraft:obsidian)
B(-7,101,8,minecraft:obsidian)
B(-7,102,-5,minecraft:obsidian)
B(-7,102,-4,minecraft:obsidian)
B(-7,102,-3,minecraft:obsidian)
B(-7,102,-2,minecraft:obsidian)
B(-7,102,-1,minecraft:obsidian)
B(-7,102,0,minecraft:obsidian)
B(-7,102,1,minecraft:obsidian)
B(-7,102,2,minecraft:obsidian)
B(-7,102,3,minecraft:obsidian)
B(-7,102,4,minecraft:obsidian)
B(-7,102,5,minecraft:obsidian)
B(-7,102,6,minecraft:obsidian)
B(-7,102,7,minecraft:obsidian)
B(-7,102,8,minecraft:obsidian)
B(-7,103,-6,minecraft:obsidian)
B(-7,103,-5,minecraft:obsidian)
B(-7,103,-4,minecraft:obsidian)
B(-7,103,-3,minecraft:obsidian)
B(-7,103,-2,minecraft:obsidian)
B(-7,103,-1,minecraft:obsidian)
B(-7,103,0,minecraft:obsidian)
B(-7,103,1,minecraft:obsidian)
B(-7,103,2,minecraft:obsidian)
B(-7,103,3,minecraft:obsidian)
B(-7,103,4,minecraft:obsidian)
B(-7,103,5,minecraft:obsidian)
B(-7,103,6,minecraft:obsidian)
B(-7,103,7,minecraft:obsidian)
B(-7,103,8,minecraft:diorite)
B(-7,104,-6,minecraft:obsidian)
B(-7,104,-5,minecraft:obsidian)
B(-7,104,-4,minecraft:obsidian)
B(-7,104,-3,minecraft:obsidian)
B(-7,104,-2,minecraft:obsidian)
B(-7,104,-1,minecraft:obsidian)
B(-7,104,0,minecraft:obsidian)
B(-7,104,1,minecraft:obsidian)
B(-7,104,2,minecraft:obsidian)
B(-7,104,3,minecraft:obsidian)
B(-7,104,4,minecraft:obsidian)
B(-7,104,5,minecraft:obsidian)
B(-7,104,6,minecraft:obsidian)
B(-7,104,7,minecraft:obsidian)
B(-7,104,8,minecraft:diorite)
B(-7,105,-7,minecraft:obsidian)
B(-7,105,-6,minecraft:obsidian)
B(-7,105,-5,minecraft:obsidian)
B(-7,105,-4,minecraft:obsidian)
B(-7,105,-3,minecraft:obsidian)
B(-7,105,-2,minecraft:obsidian)
B(-7,105,-1,minecraft:obsidian)
B(-7,105,0,minecraft:obsidian)
B(-7,105,1,minecraft:obsidian)
B(-7,105,2,minecraft:obsidian)
B(-7,105,3,minecraft:obsidian)
B(-7,105,4,minecraft:obsidian)
B(-7,105,5,minecraft:obsidian)
B(-7,105,6,minecraft:obsidian)
B(-7,105,7,minecraft:obsidian)
B(-7,105,8,minecraft:diorite)
B(-7,106,-7,minecraft:obsidian)
B(-7,106,-6,minecraft:obsidian)
B(-7,106,-5,minecraft:obsidian)
B(-7,106,-4,minecraft:obsidian)
B(-7,106,-3,minecraft:obsidian)
B(-7,106,-2,minecraft:obsidian)
B(-7,106,-1,minecraft:obsidian)
B(-7,106,0,minecraft:obsidian)
B(-7,106,1,minecraft:obsidian)
B(-7,106,2,minecraft:obsidian)
B(-7,106,3,minecraft:obsidian)
B(-7,106,4,minecraft:obsidian)
B(-7,106,5,minecraft:obsidian)
B(-7,106,6,minecraft:obsidian)
B(-7,106,7,minecraft:diorite)
B(-7,106,8,minecraft:diorite)
B(-7,107,-7,minecraft:obsidian)
B(-7,107,-6,minecraft:obsidian)
B(-7,107,-5,minecraft:obsidian)
B(-7,107,-4,minecraft:obsidian)
B(-7,107,-3,minecraft:obsidian)
B(-7,107,-2,minecraft:obsidian)
B(-7,107,-1,minecraft:obsidian)
B(-7,107,0,minecraft:obsidian)
B(-7,107,1,minecraft:obsidian)
B(-7,107,2,minecraft:obsidian)
B(-7,107,3,minecraft:obsidian)
B(-7,107,4,minecraft:obsidian)
B(-7,107,5,minecraft:obsidian)
B(-7,107,6,minecraft:obsidian)
B(-7,107,7,minecraft:diorite)
B(-7,107,8,minecraft:diorite)
B(-7,108,-7,minecraft:obsidian)
B(-7,108,-6,minecraft:obsidian)
B(-7,108,-5,minecraft:obsidian)
B(-7,108,-4,minecraft:obsidian)
B(-7,108,-3,minecraft:obsidian)
B(-7,108,-2,minecraft:obsidian)
B(-7,108,-1,minecraft:obsidian)
B(-7,108,0,minecraft:obsidian)
B(-7,108,1,minecraft:obsidian)
B(-7,108,2,minecraft:obsidian)
B(-7,108,3,minecraft:obsidian)
B(-7,108,4,minecraft:obsidian)
B(-7,108,5,minecraft:obsidian)
B(-7,108,6,minecraft:obsidian)
B(-7,108,7,minecraft:diorite)
B(-7,108,8,minecraft:diorite)
B(-7,109,-7,minecraft:obsidian)
B(-7,109,-6,minecraft:obsidian)
B(-7,109,-5,minecraft:obsidian)
B(-7,109,-4,minecraft:obsidian)
B(-7,109,-3,minecraft:obsidian)
B(-7,109,-2,minecraft:obsidian)
B(-7,109,-1,minecraft:obsidian)
B(-7,109,0,minecraft:obsidian)
B(-7,109,1,minecraft:obsidian)
B(-7,109,2,minecraft:obsidian)
B(-7,109,3,minecraft:obsidian)
B(-7,109,4,minecraft:obsidian)
B(-7,109,5,minecraft:obsidian)
B(-7,109,6,minecraft:obsidian)
B(-7,109,7,minecraft:diorite)
B(-7,109,8,minecraft:diorite)
B(-7,110,-7,minecraft:obsidian)
B(-7,110,-6,minecraft:obsidian)
B(-7,110,-5,minecraft:obsidian)
B(-7,110,-4,minecraft:obsidian)
B(-7,110,-3,minecraft:obsidian)
B(-7,110,-2,minecraft:obsidian)
B(-7,110,-1,minecraft:obsidian)
B(-7,110,0,minecraft:obsidian)
B(-7,110,1,minecraft:obsidian)
B(-7,110,2,minecraft:obsidian)
B(-7,110,3,minecraft:obsidian)
B(-7,110,4,minecraft:obsidian)
B(-7,110,5,minecraft:diorite)
B(-7,110,6,minecraft:diorite)
B(-7,110,7,minecraft:andesite)
B(-7,110,8,minecraft:andesite)
B(-7,111,-7,minecraft:obsidian)
B(-7,111,-6,minecraft:obsidian)
B(-7,111,-5,minecraft:obsidian)
B(-7,111,-4,minecraft:obsidian)
B(-7,111,-3,minecraft:obsidian)
B(-7,111,-2,minecraft:obsidian)
B(-7,111,-1,minecraft:obsidian)
B(-7,111,0,minecraft:obsidian)
B(-7,111,1,minecraft:obsidian)
B(-7,111,2,minecraft:obsidian)
B(-7,111,3,minecraft:obsidian)
B(-7,111,4,minecraft:obsidian)
B(-7,111,5,minecraft:andesite)
B(-7,111,6,minecraft:andesite)
B(-7,112,-7,minecraft:obsidian)
B(-7,112,-6,minecraft:obsidian)
B(-7,112,-5,minecraft:obsidian)
B(-7,112,-4,minecraft:obsidian)
B(-7,112,-3,minecraft:obsidian)
B(-7,112,-2,minecraft:obsidian)
B(-7,112,-1,minecraft:obsidian)
B(-7,112,0,minecraft:obsidian)
B(-7,112,1,minecraft:obsidian)
B(-7,112,2,minecraft:obsidian)
B(-7,112,3,minecraft:obsidian)
B(-7,112,4,minecraft:diorite)
B(-7,113,-7,minecraft:obsidian)
B(-7,113,-6,minecraft:obsidian)
B(-7,113,-5,minecraft:obsidian)
B(-7,113,-4,minecraft:obsidian)
B(-7,113,-3,minecraft:obsidian)
B(-7,113,-2,minecraft:obsidian)
B(-7,113,-1,minecraft:obsidian)
B(-7,113,0,minecraft:obsidian)
B(-7,113,1,minecraft:obsidian)
B(-7,113,2,minecraft:obsidian)
B(-7,113,3,minecraft:obsidian)
B(-7,113,4,minecraft:andesite)
B(-7,114,-7,minecraft:obsidian)
B(-7,114,-6,minecraft:obsidian)
B(-7,114,-5,minecraft:obsidian)
B(-7,114,-4,minecraft:obsidian)
B(-7,114,-3,minecraft:andesite)
B(-7,114,-2,minecraft:andesite)
B(-7,114,-1,minecraft:obsidian)
B(-7,114,0,minecraft:obsidian)
B(-7,114,1,minecraft:obsidian)
B(-7,114,2,minecraft:andesite)
B(-7,114,3,minecraft:andesite)
B(-7,115,-7,minecraft:andesite)
B(-7,115,-6,minecraft:andesite)
B(-7,115,-5,minecraft:andesite)
B(-7,115,-4,minecraft:andesite)
B(-7,115,-1,minecraft:andesite)
B(-7,115,0,minecraft:andesite)
B(-7,115,1,minecraft:diorite)
B(-6,12,8,minecraft:diorite)
B(-6,13,7,minecraft:diorite)
B(-6,13,8,minecraft:diorite)
B(-6,14,-3,minecraft:obsidian)
B(-6,14,-2,minecraft:magma_block)
B(-6,14,-1,minecraft:magma_block)
B(-6,14,0,minecraft:magma_block)
B(-6,14,1,minecraft:magma_block)
B(-6,14,2,minecraft:magma_block)
B(-6,14,3,minecraft:magma_block)
B(-6,14,4,minecraft:obsidian)
B(-6,14,5,minecraft:obsidian)
B(-6,14,6,minecraft:obsidian)
B(-6,14,7,minecraft:diorite)
B(-6,14,8,minecraft:diorite)
B(-6,15,-7,minecraft:diorite)
B(-6,15,-6,minecraft:diorite)
B(-6,15,-5,minecraft:diorite)
B(-6,15,-4,minecraft:obsidian)
B(-6,15,-3,minecraft:obsidian)
B(-6,15,-2,minecraft:magma_block)
B(-6,15,-1,minecraft:magma_block)
B(-6,15,0,minecraft:magma_block)
B(-6,15,1,minecraft:magma_block)
B(-6,15,2,minecraft:magma_block)
B(-6,15,3,minecraft:magma_block)
B(-6,15,4,minecraft:obsidian)
B(-6,15,5,minecraft:obsidian)
B(-6,15,6,minecraft:obsidian)
B(-6,15,7,minecraft:diorite)
B(-6,15,8,minecraft:diorite)
B(-6,16,-7,minecraft:diorite)
B(-6,16,-6,minecraft:diorite)
B(-6,16,-5,minecraft:diorite)
B(-6,16,-4,minecraft:obsidian)
B(-6,16,-3,minecraft:obsidian)
B(-6,16,-2,minecraft:obsidian)
B(-6,16,-1,minecraft:magma_block)
B(-6,16,0,minecraft:magma_block)
B(-6,16,1,minecraft:magma_block)
B(-6,16,2,minecraft:magma_block)
B(-6,16,3,minecraft:obsidian)
B(-6,16,4,minecraft:obsidian)
B(-6,16,5,minecraft:obsidian)
B(-6,16,6,minecraft:obsidian)
B(-6,16,7,minecraft:diorite)
B(-6,16,8,minecraft:diorite)
B(-6,17,-7,minecraft:diorite)
B(-6,17,-6,minecraft:diorite)
B(-6,17,-5,minecraft:diorite)
B(-6,17,-4,minecraft:diorite)
B(-6,17,-3,minecraft:obsidian)
B(-6,17,-2,minecraft:obsidian)
B(-6,17,-1,minecraft:obsidian)
B(-6,17,0,minecraft:obsidian)
B(-6,17,1,minecraft:obsidian)
B(-6,17,2,minecraft:obsidian)
B(-6,17,3,minecraft:obsidian)
B(-6,17,4,minecraft:obsidian)
B(-6,17,5,minecraft:obsidian)
B(-6,17,6,minecraft:diorite)
B(-6,17,7,minecraft:diorite)
B(-6,17,8,minecraft:diorite)
B(-6,18,-7,minecraft:diorite)
B(-6,18,-6,minecraft:diorite)
B(-6,18,-5,minecraft:diorite)
B(-6,18,-4,minecraft:diorite)
B(-6,18,-3,minecraft:diorite)
B(-6,18,-2,minecraft:obsidian)
B(-6,18,-1,minecraft:obsidian)
B(-6,18,0,minecraft:obsidian)
B(-6,18,1,minecraft:obsidian)
B(-6,18,2,minecraft:obsidian)
B(-6,18,3,minecraft:obsidian)
B(-6,18,4,minecraft:obsidian)
B(-6,18,5,minecraft:diorite)
B(-6,18,6,minecraft:diorite)
B(-6,18,7,minecraft:diorite)
B(-6,18,8,minecraft:obsidian)
B(-6,19,-7,minecraft:diorite)
B(-6,19,-6,minecraft:diorite)
B(-6,19,-5,minecraft:diorite)
B(-6,19,-4,minecraft:diorite)
B(-6,19,-3,minecraft:diorite)
B(-6,19,-2,minecraft:obsidian)
B(-6,19,-1,minecraft:obsidian)
B(-6,19,0,minecraft:obsidian)
B(-6,19,1,minecraft:obsidian)
B(-6,19,2,minecraft:obsidian)
B(-6,19,3,minecraft:obsidian)
B(-6,19,4,minecraft:diorite)
B(-6,19,5,minecraft:diorite)
B(-6,19,6,minecraft:obsidian)
B(-6,19,7,minecraft:obsidian)
B(-6,19,8,minecraft:obsidian)
B(-6,20,-7,minecraft:diorite)
B(-6,20,-6,minecraft:diorite)
B(-6,20,-5,minecraft:diorite)
B(-6,20,-4,minecraft:obsidian)
B(-6,20,-3,minecraft:obsidian)
B(-6,20,-2,minecraft:obsidian)
B(-6,20,-1,minecraft:obsidian)
B(-6,20,0,minecraft:obsidian)
B(-6,20,1,minecraft:obsidian)
B(-6,20,2,minecraft:obsidian)
B(-6,20,3,minecraft:obsidian)
B(-6,20,4,minecraft:obsidian)
B(-6,20,5,minecraft:obsidian)
B(-6,20,6,minecraft:obsidian)
B(-6,20,7,minecraft:obsidian)
B(-6,20,8,minecraft:obsidian)
B(-6,21,-7,minecraft:obsidian)
B(-6,21,-6,minecraft:obsidian)
B(-6,21,-5,minecraft:obsidian)
B(-6,21,-4,minecraft:obsidian)
B(-6,21,-3,minecraft:obsidian)
B(-6,21,-2,minecraft:obsidian)
B(-6,21,-1,minecraft:obsidian)
B(-6,21,0,minecraft:obsidian)
B(-6,21,1,minecraft:obsidian)
B(-6,21,2,minecraft:obsidian)
B(-6,21,3,minecraft:obsidian)
B(-6,21,4,minecraft:obsidian)
B(-6,21,5,minecraft:obsidian)
B(-6,21,6,minecraft:obsidian)
B(-6,21,7,minecraft:obsidian)
B(-6,21,8,minecraft:obsidian)
B(-6,22,-7,minecraft:obsidian)
B(-6,22,-6,minecraft:obsidian)
B(-6,22,-5,minecraft:obsidian)
B(-6,22,-4,minecraft:obsidian)
B(-6,22,-3,minecraft:obsidian)
B(-6,22,-2,minecraft:obsidian)
B(-6,22,-1,minecraft:obsidian)
B(-6,22,0,minecraft:obsidian)
B(-6,22,1,minecraft:obsidian)
B(-6,22,2,minecraft:obsidian)
B(-6,22,3,minecraft:obsidian)
B(-6,22,4,minecraft:obsidian)
B(-6,22,5,minecraft:obsidian)
B(-6,22,6,minecraft:obsidian)
B(-6,22,7,minecraft:obsidian)
B(-6,22,8,minecraft:obsidian)
B(-6,23,-7,minecraft:obsidian)
B(-6,23,-6,minecraft:obsidian)
B(-6,23,-5,minecraft:obsidian)
B(-6,23,-4,minecraft:obsidian)
B(-6,23,-3,minecraft:obsidian)
B(-6,23,-2,minecraft:obsidian)
B(-6,23,-1,minecraft:obsidian)
B(-6,23,0,minecraft:obsidian)
B(-6,23,1,minecraft:obsidian)
B(-6,23,2,minecraft:obsidian)
B(-6,23,3,minecraft:obsidian)
B(-6,23,4,minecraft:obsidian)
B(-6,23,5,minecraft:obsidian)
B(-6,23,6,minecraft:obsidian)
B(-6,23,7,minecraft:obsidian)
B(-6,23,8,minecraft:obsidian)
B(-6,24,-7,minecraft:obsidian)
B(-6,24,-6,minecraft:obsidian)
B(-6,24,-5,minecraft:obsidian)
B(-6,24,-4,minecraft:obsidian)
B(-6,24,-3,minecraft:obsidian)
B(-6,24,-2,minecraft:obsidian)
B(-6,24,-1,minecraft:obsidian)
B(-6,24,0,minecraft:obsidian)
B(-6,24,1,minecraft:obsidian)
B(-6,24,2,minecraft:obsidian)
B(-6,24,3,minecraft:obsidian)
B(-6,24,4,minecraft:obsidian)
B(-6,24,5,minecraft:obsidian)
B(-6,24,6,minecraft:obsidian)
B(-6,24,7,minecraft:obsidian)
B(-6,24,8,minecraft:obsidian)
B(-6,25,-7,minecraft:obsidian)
B(-6,25,-6,minecraft:obsidian)
B(-6,25,-5,minecraft:obsidian)
B(-6,25,-4,minecraft:obsidian)
B(-6,25,-3,minecraft:obsidian)
B(-6,25,-2,minecraft:obsidian)
B(-6,25,-1,minecraft:obsidian)
B(-6,25,0,minecraft:obsidian)
B(-6,25,1,minecraft:obsidian)
B(-6,25,2,minecraft:obsidian)
B(-6,25,3,minecraft:obsidian)
B(-6,25,4,minecraft:obsidian)
B(-6,25,5,minecraft:obsidian)
B(-6,25,6,minecraft:lava)
B(-6,25,7,minecraft:lava)
B(-6,25,8,minecraft:lava)
B(-6,26,-7,minecraft:obsidian)
B(-6,26,-6,minecraft:obsidian)
B(-6,26,-5,minecraft:obsidian)
B(-6,26,-4,minecraft:obsidian)
B(-6,26,-3,minecraft:obsidian)
B(-6,26,-2,minecraft:obsidian)
B(-6,26,-1,minecraft:obsidian)
B(-6,26,0,minecraft:obsidian)
B(-6,26,1,minecraft:obsidian)
B(-6,26,2,minecraft:obsidian)
B(-6,26,3,minecraft:obsidian)
B(-6,26,4,minecraft:diorite)
B(-6,26,5,minecraft:lava)
B(-6,26,6,minecraft:lava)
B(-6,26,7,minecraft:lava)
B(-6,26,8,minecraft:lava)
B(-6,27,-7,minecraft:obsidian)
B(-6,27,-6,minecraft:obsidian)
B(-6,27,-5,minecraft:obsidian)
B(-6,27,-4,minecraft:obsidian)
B(-6,27,-3,minecraft:obsidian)
B(-6,27,-2,minecraft:obsidian)
B(-6,27,-1,minecraft:obsidian)
B(-6,27,0,minecraft:obsidian)
B(-6,27,1,minecraft:obsidian)
B(-6,27,2,minecraft:obsidian)
B(-6,27,3,minecraft:lava)
B(-6,27,4,minecraft:lava)
B(-6,27,5,minecraft:lava)
B(-6,27,6,minecraft:lava)
B(-6,27,7,minecraft:lava)
B(-6,27,8,minecraft:lava)
B(-6,28,-7,minecraft:obsidian)
B(-6,28,-6,minecraft:obsidian)
B(-6,28,-5,minecraft:obsidian)
B(-6,28,-4,minecraft:obsidian)
B(-6,28,-3,minecraft:obsidian)
B(-6,28,-2,minecraft:obsidian)
B(-6,28,-1,minecraft:obsidian)
B(-6,28,0,minecraft:obsidian)
B(-6,28,1,minecraft:obsidian)
B(-6,28,2,minecraft:lava)
B(-6,28,3,minecraft:lava)
B(-6,29,-7,minecraft:obsidian)
B(-6,29,-6,minecraft:obsidian)
B(-6,29,-5,minecraft:obsidian)
B(-6,29,-4,minecraft:obsidian)
B(-6,29,-3,minecraft:obsidian)
B(-6,29,-2,minecraft:obsidian)
B(-6,29,-1,minecraft:obsidian)
B(-6,29,0,minecraft:diorite)
B(-6,29,1,minecraft:lava)
B(-6,29,2,minecraft:lava)
B(-6,30,-7,minecraft:obsidian)
B(-6,30,-6,minecraft:obsidian)
B(-6,30,-5,minecraft:obsidian)
B(-6,30,-4,minecraft:obsidian)
B(-6,30,-3,minecraft:obsidian)
B(-6,30,-2,minecraft:obsidian)
B(-6,30,-1,minecraft:lava)
B(-6,30,0,minecraft:lava)
B(-6,30,1,minecraft:lava)
B(-6,31,-7,minecraft:obsidian)
B(-6,31,-6,minecraft:obsidian)
B(-6,31,-5,minecraft:obsidian)
B(-6,31,-4,minecraft:obsidian)
B(-6,31,-3,minecraft:obsidian)
B(-6,31,-2,minecraft:obsidian)
B(-6,31,-1,minecraft:lava)
B(-6,32,-7,minecraft:obsidian)
B(-6,32,-6,minecraft:obsidian)
B(-6,32,-5,minecraft:lava)
B(-6,32,-4,minecraft:lava)
B(-6,32,-3,minecraft:lava)
B(-6,32,-2,minecraft:lava)
B(-6,33,-7,minecraft:obsidian)
B(-6,33,-6,minecraft:lava)
B(-6,33,-5,minecraft:lava)
B(-6,34,-7,minecraft:obsidian)
B(-6,35,-7,minecraft:obsidian)
B(-6,35,-6,minecraft:obsidian)
B(-6,36,-7,minecraft:obsidian)
B(-6,96,8,minecraft:obsidian)
B(-6,97,7,minecraft:obsidian)
B(-6,97,8,minecraft:obsidian)
B(-6,98,5,minecraft:obsidian)
B(-6,98,6,minecraft:obsidian)
B(-6,98,7,minecraft:obsidian)
B(-6,98,8,minecraft:obsidian)
B(-6,99,5,minecraft:obsidian)
B(-6,99,6,minecraft:obsidian)
B(-6,99,7,minecraft:obsidian)
B(-6,99,8,minecraft:obsidian)
B(-6,100,3,minecraft:obsidian)
B(-6,100,4,minecraft:obsidian)
B(-6,100,5,minecraft:obsidian)
B(-6,100,6,minecraft:obsidian)
B(-6,100,7,minecraft:obsidian)
B(-6,100,8,minecraft:obsidian)
B(-6,101,-2,minecraft:obsidian)
B(-6,101,-1,minecraft:obsidian)
B(-6,101,0,minecraft:obsidian)
B(-6,101,1,minecraft:obsidian)
B(-6,101,2,minecraft:obsidian)
B(-6,101,3,minecraft:obsidian)
B(-6,101,4,minecraft:obsidian)
B(-6,101,5,minecraft:obsidian)
B(-6,101,6,minecraft:obsidian)
B(-6,101,7,minecraft:obsidian)
B(-6,101,8,minecraft:obsidian)
B(-6,102,-4,minecraft:obsidian)
B(-6,102,-3,minecraft:obsidian)
B(-6,102,-2,minecraft:obsidian)
B(-6,102,-1,minecraft:obsidian)
B(-6,102,0,minecraft:obsidian)
B(-6,102,1,minecraft:obsidian)
B(-6,102,2,minecraft:obsidian)
B(-6,102,3,minecraft:obsidian)
B(-6,102,4,minecraft:obsidian)
B(-6,102,5,minecraft:obsidian)
B(-6,102,6,minecraft:obsidian)
B(-6,102,7,minecraft:obsidian)
B(-6,102,8,minecraft:obsidian)
B(-6,103,-5,minecraft:obsidian)
B(-6,103,-4,minecraft:obsidian)
B(-6,103,-3,minecraft:obsidian)
B(-6,103,-2,minecraft:obsidian)
B(-6,103,-1,minecraft:obsidian)
B(-6,103,0,minecraft:obsidian)
B(-6,103,1,minecraft:obsidian)
B(-6,103,2,minecraft:obsidian)
B(-6,103,3,minecraft:obsidian)
B(-6,103,4,minecraft:obsidian)
B(-6,103,5,minecraft:obsidian)
B(-6,103,6,minecraft:obsidian)
B(-6,103,7,minecraft:obsidian)
B(-6,103,8,minecraft:obsidian)
B(-6,104,-4,minecraft:obsidian)
B(-6,104,-3,minecraft:obsidian)
B(-6,104,-2,minecraft:obsidian)
B(-6,104,-1,minecraft:obsidian)
B(-6,104,0,minecraft:obsidian)
B(-6,104,1,minecraft:obsidian)
B(-6,104,2,minecraft:obsidian)
B(-6,104,3,minecraft:obsidian)
B(-6,104,4,minecraft:obsidian)
B(-6,104,5,minecraft:obsidian)
B(-6,104,6,minecraft:obsidian)
B(-6,104,7,minecraft:obsidian)
B(-6,104,8,minecraft:diorite)
B(-6,105,-7,minecraft:obsidian)
B(-6,105,-6,minecraft:obsidian)
B(-6,105,-5,minecraft:obsidian)
B(-6,105,-4,minecraft:obsidian)
B(-6,105,-3,minecraft:obsidian)
B(-6,105,-2,minecraft:obsidian)
B(-6,105,-1,minecraft:obsidian)
B(-6,105,0,minecraft:obsidian)
B(-6,105,1,minecraft:obsidian)
B(-6,105,2,minecraft:obsidian)
B(-6,105,3,minecraft:obsidian)
B(-6,105,4,minecraft:obsidian)
B(-6,105,5,minecraft:obsidian)
B(-6,105,6,minecraft:obsidian)
B(-6,105,7,minecraft:obsidian)
B(-6,105,8,minecraft:diorite)
B(-6,106,-7,minecraft:obsidian)
B(-6,106,-6,minecraft:obsidian)
B(-6,106,-5,minecraft:obsidian)
B(-6,106,-4,minecraft:obsidian)
B(-6,106,-3,minecraft:obsidian)
B(-6,106,-2,minecraft:obsidian)
B(-6,106,-1,minecraft:obsidian)
B(-6,106,0,minecraft:obsidian)
B(-6,106,1,minecraft:obsidian)
B(-6,106,2,minecraft:obsidian)
B(-6,106,3,minecraft:obsidian)
B(-6,106,4,minecraft:obsidian)
B(-6,106,5,minecraft:obsidian)
B(-6,106,6,minecraft:obsidian)
B(-6,106,7,minecraft:obsidian)
B(-6,106,8,minecraft:diorite)
B(-6,107,-7,minecraft:obsidian)
B(-6,107,-6,minecraft:obsidian)
B(-6,107,-5,minecraft:obsidian)
B(-6,107,-4,minecraft:obsidian)
B(-6,107,-3,minecraft:obsidian)
B(-6,107,-2,minecraft:obsidian)
B(-6,107,-1,minecraft:obsidian)
B(-6,107,0,minecraft:obsidian)
B(-6,107,1,minecraft:obsidian)
B(-6,107,2,minecraft:obsidian)
B(-6,107,3,minecraft:obsidian)
B(-6,107,4,minecraft:obsidian)
B(-6,107,5,minecraft:obsidian)
B(-6,107,6,minecraft:obsidian)
B(-6,107,7,minecraft:diorite)
B(-6,107,8,minecraft:diorite)
B(-6,108,-7,minecraft:obsidian)
B(-6,108,-6,minecraft:obsidian)
B(-6,108,-5,minecraft:obsidian)
B(-6,108,-4,minecraft:obsidian)
B(-6,108,-3,minecraft:obsidian)
B(-6,108,-2,minecraft:obsidian)
B(-6,108,-1,minecraft:obsidian)
B(-6,108,0,minecraft:obsidian)
B(-6,108,1,minecraft:obsidian)
B(-6,108,2,minecraft:obsidian)
B(-6,108,3,minecraft:obsidian)
B(-6,108,4,minecraft:obsidian)
B(-6,108,5,minecraft:obsidian)
B(-6,108,6,minecraft:obsidian)
B(-6,108,7,minecraft:diorite)
B(-6,108,8,minecraft:diorite)
B(-6,109,-7,minecraft:obsidian)
B(-6,109,-6,minecraft:obsidian)
B(-6,109,-5,minecraft:obsidian)
B(-6,109,-4,minecraft:obsidian)
B(-6,109,-3,minecraft:obsidian)
B(-6,109,-2,minecraft:obsidian)
B(-6,109,-1,minecraft:obsidian)
B(-6,109,0,minecraft:obsidian)
B(-6,109,1,minecraft:obsidian)
B(-6,109,2,minecraft:obsidian)
B(-6,109,3,minecraft:obsidian)
B(-6,109,4,minecraft:obsidian)
B(-6,109,5,minecraft:obsidian)
B(-6,109,6,minecraft:obsidian)
B(-6,109,7,minecraft:diorite)
B(-6,109,8,minecraft:diorite)
B(-6,110,-7,minecraft:obsidian)
B(-6,110,-6,minecraft:obsidian)
B(-6,110,-5,minecraft:obsidian)
B(-6,110,-4,minecraft:obsidian)
B(-6,110,-3,minecraft:obsidian)
B(-6,110,-2,minecraft:obsidian)
B(-6,110,-1,minecraft:obsidian)
B(-6,110,0,minecraft:obsidian)
B(-6,110,1,minecraft:obsidian)
B(-6,110,2,minecraft:obsidian)
B(-6,110,3,minecraft:obsidian)
B(-6,110,4,minecraft:obsidian)
B(-6,110,5,minecraft:obsidian)
B(-6,110,6,minecraft:diorite)
B(-6,110,7,minecraft:diorite)
B(-6,110,8,minecraft:andesite)
B(-6,111,-7,minecraft:obsidian)
B(-6,111,-6,minecraft:obsidian)
B(-6,111,-5,minecraft:obsidian)
B(-6,111,-4,minecraft:obsidian)
B(-6,111,-3,minecraft:obsidian)
B(-6,111,-2,minecraft:obsidian)
B(-6,111,-1,minecraft:obsidian)
B(-6,111,0,minecraft:obsidian)
B(-6,111,1,minecraft:obsidian)
B(-6,111,2,minecraft:obsidian)
B(-6,111,3,minecraft:obsidian)
B(-6,111,4,minecraft:obsidian)
B(-6,111,5,minecraft:diorite)
B(-6,111,6,minecraft:andesite)
B(-6,111,7,minecraft:andesite)
B(-6,112,-7,minecraft:obsidian)
B(-6,112,-6,minecraft:obsidian)
B(-6,112,-5,minecraft:obsidian)
B(-6,112,-4,minecraft:obsidian)
B(-6,112,-3,minecraft:obsidian)
B(-6,112,-2,minecraft:obsidian)
B(-6,112,-1,minecraft:obsidian)
B(-6,112,0,minecraft:obsidian)
B(-6,112,1,minecraft:obsidian)
B(-6,112,2,minecraft:obsidian)
B(-6,112,3,minecraft:obsidian)
B(-6,112,4,minecraft:diorite)
B(-6,112,5,minecraft:andesite)
B(-6,113,-7,minecraft:obsidian)
B(-6,113,-6,minecraft:obsidian)
B(-6,113,-5,minecraft:obsidian)
B(-6,113,-4,minecraft:obsidian)
B(-6,113,-3,minecraft:obsidian)
B(-6,113,-2,minecraft:obsidian)
B(-6,113,-1,minecraft:obsidian)
B(-6,113,0,minecraft:obsidian)
B(-6,113,1,minecraft:obsidian)
B(-6,113,2,minecraft:obsidian)
B(-6,113,3,minecraft:obsidian)
B(-6,113,4,minecraft:andesite)
B(-6,114,-7,minecraft:obsidian)
B(-6,114,-6,minecraft:obsidian)
B(-6,114,-5,minecraft:obsidian)
B(-6,114,-4,minecraft:andesite)
B(-6,114,-3,minecraft:andesite)
B(-6,114,-2,minecraft:obsidian)
B(-6,114,-1,minecraft:obsidian)
B(-6,114,0,minecraft:obsidian)
B(-6,114,1,minecraft:obsidian)
B(-6,114,2,minecraft:obsidian)
B(-6,114,3,minecraft:andesite)
B(-6,115,-7,minecraft:andesite)
B(-6,115,-6,minecraft:andesite)
B(-6,115,-5,minecraft:andesite)
B(-6,115,-2,minecraft:andesite)
B(-6,115,-1,minecraft:andesite)
B(-6,115,0,minecraft:andesite)
B(-6,115,1,minecraft:andesite)
B(-6,115,2,minecraft:diorite)
B(-5,11,8,minecraft:diorite)
B(-5,12,7,minecraft:diorite)
B(-5,12,8,minecraft:diorite)
B(-5,13,5,minecraft:obsidian)
B(-5,13,6,minecraft:obsidian)
B(-5,13,7,minecraft:diorite)
B(-5,13,8,minecraft:diorite)
B(-5,14,-3,minecraft:obsidian)
B(-5,14,-2,minecraft:obsidian)
B(-5,14,-1,minecraft:magma_block)
B(-5,14,0,minecraft:magma_block)
B(-5,14,1,minecraft:magma_block)
B(-5,14,2,minecraft:magma_block)
B(-5,14,3,minecraft:magma_block)
B(-5,14,4,minecraft:obsidian)
B(-5,14,5,minecraft:obsidian)
B(-5,14,6,minecraft:obsidian)
B(-5,14,7,minecraft:diorite)
B(-5,14,8,minecraft:diorite)
B(-5,15,-7,minecraft:diorite)
B(-5,15,-6,minecraft:diorite)
B(-5,15,-5,minecraft:diorite)
B(-5,15,-4,minecraft:obsidian)
B(-5,15,-3,minecraft:obsidian)
B(-5,15,-2,minecraft:obsidian)
B(-5,15,-1,minecraft:magma_block)
B(-5,15,0,minecraft:magma_block)
B(-5,15,1,minecraft:magma_block)
B(-5,15,2,minecraft:magma_block)
B(-5,15,3,minecraft:magma_block)
B(-5,15,4,minecraft:obsidian)
B(-5,15,5,minecraft:obsidian)
B(-5,15,6,minecraft:obsidian)
B(-5,15,7,minecraft:diorite)
B(-5,15,8,minecraft:diorite)
B(-5,16,-7,minecraft:diorite)
B(-5,16,-6,minecraft:diorite)
B(-5,16,-5,minecraft:diorite)
B(-5,16,-4,minecraft:diorite)
B(-5,16,-3,minecraft:obsidian)
B(-5,16,-2,minecraft:obsidian)
B(-5,16,-1,minecraft:obsidian)
B(-5,16,0,minecraft:magma_block)
B(-5,16,1,minecraft:magma_block)
B(-5,16,2,minecraft:magma_block)
B(-5,16,3,minecraft:obsidian)
B(-5,16,4,minecraft:obsidian)
B(-5,16,5,minecraft:obsidian)
B(-5,16,6,minecraft:diorite)
B(-5,16,7,minecraft:diorite)
B(-5,16,8,minecraft:diorite)
B(-5,17,-7,minecraft:diorite)
B(-5,17,-6,minecraft:diorite)
B(-5,17,-5,minecraft:diorite)
B(-5,17,-4,minecraft:diorite)
B(-5,17,-3,minecraft:obsidian)
B(-5,17,-2,minecraft:obsidian)
B(-5,17,-1,minecraft:obsidian)
B(-5,17,0,minecraft:obsidian)
B(-5,17,1,minecraft:obsidian)
B(-5,17,2,minecraft:obsidian)
B(-5,17,3,minecraft:obsidian)
B(-5,17,4,minecraft:obsidian)
B(-5,17,5,minecraft:obsidian)
B(-5,17,6,minecraft:diorite)
B(-5,17,7,minecraft:diorite)
B(-5,17,8,minecraft:diorite)
B(-5,18,-7,minecraft:diorite)
B(-5,18,-6,minecraft:diorite)
B(-5,18,-5,minecraft:diorite)
B(-5,18,-4,minecraft:diorite)
B(-5,18,-3,minecraft:diorite)
B(-5,18,-2,minecraft:obsidian)
B(-5,18,-1,minecraft:obsidian)
B(-5,18,0,minecraft:obsidian)
B(-5,18,1,minecraft:obsidian)
B(-5,18,2,minecraft:obsidian)
B(-5,18,3,minecraft:obsidian)
B(-5,18,4,minecraft:obsidian)
B(-5,18,5,minecraft:diorite)
B(-5,18,6,minecraft:diorite)
B(-5,18,7,minecraft:diorite)
B(-5,18,8,minecraft:obsidian)
B(-5,19,-7,minecraft:diorite)
B(-5,19,-6,minecraft:diorite)
B(-5,19,-5,minecraft:diorite)
B(-5,19,-4,minecraft:diorite)
B(-5,19,-3,minecraft:diorite)
B(-5,19,-2,minecraft:obsidian)
B(-5,19,-1,minecraft:obsidian)
B(-5,19,0,minecraft:obsidian)
B(-5,19,1,minecraft:obsidian)
B(-5,19,2,minecraft:obsidian)
B(-5,19,3,minecraft:diorite)
B(-5,19,4,minecraft:diorite)
B(-5,19,5,minecraft:diorite)
B(-5,19,6,minecraft:obsidian)
B(-5,19,7,minecraft:obsidian)
B(-5,19,8,minecraft:obsidian)
B(-5,20,-7,minecraft:diorite)
B(-5,20,-6,minecraft:diorite)
B(-5,20,-5,minecraft:diorite)
B(-5,20,-4,minecraft:diorite)
B(-5,20,-3,minecraft:obsidian)
B(-5,20,-2,minecraft:obsidian)
B(-5,20,-1,minecraft:obsidian)
B(-5,20,0,minecraft:obsidian)
B(-5,20,1,minecraft:obsidian)
B(-5,20,2,minecraft:obsidian)
B(-5,20,3,minecraft:obsidian)
B(-5,20,4,minecraft:obsidian)
B(-5,20,5,minecraft:obsidian)
B(-5,20,6,minecraft:obsidian)
B(-5,20,7,minecraft:obsidian)
B(-5,20,8,minecraft:obsidian)
B(-5,21,-7,minecraft:obsidian)
B(-5,21,-6,minecraft:obsidian)
B(-5,21,-5,minecraft:obsidian)
B(-5,21,-4,minecraft:obsidian)
B(-5,21,-3,minecraft:obsidian)
B(-5,21,-2,minecraft:obsidian)
B(-5,21,-1,minecraft:obsidian)
B(-5,21,0,minecraft:obsidian)
B(-5,21,1,minecraft:obsidian)
B(-5,21,2,minecraft:obsidian)
B(-5,21,3,minecraft:obsidian)
B(-5,21,4,minecraft:obsidian)
B(-5,21,5,minecraft:obsidian)
B(-5,21,6,minecraft:obsidian)
B(-5,21,7,minecraft:obsidian)
B(-5,21,8,minecraft:obsidian)
B(-5,22,-7,minecraft:obsidian)
B(-5,22,-6,minecraft:obsidian)
B(-5,22,-5,minecraft:obsidian)
B(-5,22,-4,minecraft:obsidian)
B(-5,22,-3,minecraft:obsidian)
B(-5,22,-2,minecraft:obsidian)
B(-5,22,-1,minecraft:obsidian)
B(-5,22,0,minecraft:obsidian)
B(-5,22,1,minecraft:obsidian)
B(-5,22,2,minecraft:obsidian)
B(-5,22,3,minecraft:obsidian)
B(-5,22,4,minecraft:obsidian)
B(-5,22,5,minecraft:obsidian)
B(-5,22,6,minecraft:obsidian)
B(-5,22,7,minecraft:obsidian)
B(-5,22,8,minecraft:obsidian)
B(-5,23,-7,minecraft:obsidian)
B(-5,23,-6,minecraft:obsidian)
B(-5,23,-5,minecraft:obsidian)
B(-5,23,-4,minecraft:obsidian)
B(-5,23,-3,minecraft:obsidian)
B(-5,23,-2,minecraft:obsidian)
B(-5,23,-1,minecraft:obsidian)
B(-5,23,0,minecraft:obsidian)
B(-5,23,1,minecraft:obsidian)
B(-5,23,2,minecraft:obsidian)
B(-5,23,3,minecraft:obsidian)
B(-5,23,4,minecraft:obsidian)
B(-5,23,5,minecraft:obsidian)
B(-5,23,6,minecraft:obsidian)
B(-5,23,7,minecraft:obsidian)
B(-5,23,8,minecraft:obsidian)
B(-5,24,-7,minecraft:obsidian)
B(-5,24,-6,minecraft:obsidian)
B(-5,24,-5,minecraft:obsidian)
B(-5,24,-4,minecraft:obsidian)
B(-5,24,-3,minecraft:obsidian)
B(-5,24,-2,minecraft:obsidian)
B(-5,24,-1,minecraft:obsidian)
B(-5,24,0,minecraft:obsidian)
B(-5,24,1,minecraft:obsidian)
B(-5,24,2,minecraft:obsidian)
B(-5,24,3,minecraft:obsidian)
B(-5,24,4,minecraft:obsidian)
B(-5,24,5,minecraft:obsidian)
B(-5,24,6,minecraft:obsidian)
B(-5,24,7,minecraft:obsidian)
B(-5,24,8,minecraft:obsidian)
B(-5,25,-7,minecraft:obsidian)
B(-5,25,-6,minecraft:obsidian)
B(-5,25,-5,minecraft:obsidian)
B(-5,25,-4,minecraft:obsidian)
B(-5,25,-3,minecraft:obsidian)
B(-5,25,-2,minecraft:obsidian)
B(-5,25,-1,minecraft:obsidian)
B(-5,25,0,minecraft:obsidian)
B(-5,25,1,minecraft:obsidian)
B(-5,25,2,minecraft:obsidian)
B(-5,25,3,minecraft:obsidian)
B(-5,25,4,minecraft:obsidian)
B(-5,25,5,minecraft:lava)
B(-5,25,6,minecraft:lava)
B(-5,25,7,minecraft:lava)
B(-5,25,8,minecraft:lava)
B(-5,26,-7,minecraft:obsidian)
B(-5,26,-6,minecraft:obsidian)
B(-5,26,-5,minecraft:obsidian)
B(-5,26,-4,minecraft:obsidian)
B(-5,26,-3,minecraft:obsidian)
B(-5,26,-2,minecraft:obsidian)
B(-5,26,-1,minecraft:obsidian)
B(-5,26,0,minecraft:obsidian)
B(-5,26,1,minecraft:obsidian)
B(-5,26,2,minecraft:obsidian)
B(-5,26,3,minecraft:lava)
B(-5,26,4,minecraft:lava)
B(-5,26,5,minecraft:lava)
B(-5,26,6,minecraft:lava)
B(-5,26,7,minecraft:lava)
B(-5,26,8,minecraft:lava)
B(-5,27,-7,minecraft:obsidian)
B(-5,27,-6,minecraft:obsidian)
B(-5,27,-5,minecraft:obsidian)
B(-5,27,-4,minecraft:obsidian)
B(-5,27,-3,minecraft:obsidian)
B(-5,27,-2,minecraft:obsidian)
B(-5,27,-1,minecraft:obsidian)
B(-5,27,0,minecraft:obsidian)
B(-5,27,1,minecraft:obsidian)
B(-5,27,2,minecraft:lava)
B(-5,27,3,minecraft:lava)
B(-5,27,4,minecraft:lava)
B(-5,27,5,minecraft:lava)
B(-5,27,6,minecraft:lava)
B(-5,27,7,minecraft:lava)
B(-5,27,8,minecraft:lava)
B(-5,28,-7,minecraft:obsidian)
B(-5,28,-6,minecraft:obsidian)
B(-5,28,-5,minecraft:obsidian)
B(-5,28,-4,minecraft:obsidian)
B(-5,28,-3,minecraft:obsidian)
B(-5,28,-2,minecraft:obsidian)
B(-5,28,-1,minecraft:obsidian)
B(-5,28,0,minecraft:obsidian)
B(-5,28,1,minecraft:lava)
B(-5,28,2,minecraft:lava)
B(-5,29,-7,minecraft:obsidian)
B(-5,29,-6,minecraft:obsidian)
B(-5,29,-5,minecraft:obsidian)
B(-5,29,-4,minecraft:obsidian)
B(-5,29,-3,minecraft:obsidian)
B(-5,29,-2,minecraft:obsidian)
B(-5,29,-1,minecraft:obsidian)
B(-5,29,0,minecraft:lava)
B(-5,29,1,minecraft:lava)
B(-5,30,-7,minecraft:obsidian)
B(-5,30,-6,minecraft:obsidian)
B(-5,30,-5,minecraft:obsidian)
B(-5,30,-4,minecraft:obsidian)
B(-5,30,-3,minecraft:obsidian)
B(-5,30,-2,minecraft:obsidian)
B(-5,30,-1,minecraft:lava)
B(-5,30,0,minecraft:lava)
B(-5,31,-7,minecraft:obsidian)
B(-5,31,-6,minecraft:obsidian)
B(-5,31,-5,minecraft:obsidian)
B(-5,31,-4,minecraft:obsidian)
B(-5,31,-3,minecraft:obsidian)
B(-5,31,-2,minecraft:obsidian)
B(-5,32,-7,minecraft:obsidian)
B(-5,32,-6,minecraft:obsidian)
B(-5,32,-5,minecraft:obsidian)
B(-5,32,-4,minecraft:obsidian)
B(-5,32,-3,minecraft:obsidian)
B(-5,33,-7,minecraft:obsidian)
B(-5,33,-6,minecraft:obsidian)
B(-5,33,-5,minecraft:obsidian)
B(-5,33,-4,minecraft:obsidian)
B(-5,34,-7,minecraft:obsidian)
B(-5,34,-6,minecraft:obsidian)
B(-5,34,-5,minecraft:obsidian)
B(-5,35,-7,minecraft:obsidian)
B(-5,35,-6,minecraft:obsidian)
B(-5,35,-5,minecraft:obsidian)
B(-5,36,-7,minecraft:obsidian)
B(-5,36,-6,minecraft:obsidian)
B(-5,37,-7,minecraft:obsidian)
B(-5,38,-7,minecraft:obsidian)
B(-5,93,8,minecraft:diorite)
B(-5,97,8,minecraft:obsidian)
B(-5,98,6,minecraft:obsidian)
B(-5,98,7,minecraft:obsidian)
B(-5,98,8,minecraft:obsidian)
B(-5,99,5,minecraft:obsidian)
B(-5,99,6,minecraft:obsidian)
B(-5,99,7,minecraft:obsidian)
B(-5,99,8,minecraft:obsidian)
B(-5,100,3,minecraft:obsidian)
B(-5,100,4,minecraft:obsidian)
B(-5,100,5,minecraft:obsidian)
B(-5,100,6,minecraft:obsidian)
B(-5,100,7,minecraft:obsidian)
B(-5,100,8,minecraft:obsidian)
B(-5,101,0,minecraft:obsidian)
B(-5,101,1,minecraft:obsidian)
B(-5,101,2,minecraft:obsidian)
B(-5,101,3,minecraft:obsidian)
B(-5,101,4,minecraft:obsidian)
B(-5,101,5,minecraft:obsidian)
B(-5,101,6,minecraft:obsidian)
B(-5,101,7,minecraft:obsidian)
B(-5,101,8,minecraft:obsidian)
B(-5,102,-2,minecraft:obsidian)
B(-5,102,-1,minecraft:obsidian)
B(-5,102,0,minecraft:obsidian)
B(-5,102,1,minecraft:obsidian)
B(-5,102,2,minecraft:obsidian)
B(-5,102,3,minecraft:obsidian)
B(-5,102,4,minecraft:obsidian)
B(-5,102,5,minecraft:obsidian)
B(-5,102,6,minecraft:obsidian)
B(-5,102,7,minecraft:obsidian)
B(-5,102,8,minecraft:obsidian)
B(-5,103,-3,minecraft:obsidian)
B(-5,103,-2,minecraft:obsidian)
B(-5,103,-1,minecraft:obsidian)
B(-5,103,0,minecraft:obsidian)
B(-5,103,1,minecraft:obsidian)
B(-5,103,2,minecraft:obsidian)
B(-5,103,3,minecraft:obsidian)
B(-5,103,4,minecraft:obsidian)
B(-5,103,5,minecraft:obsidian)
B(-5,103,6,minecraft:obsidian)
B(-5,103,7,minecraft:obsidian)
B(-5,103,8,minecraft:obsidian)
B(-5,104,-4,minecraft:obsidian)
B(-5,104,-3,minecraft:obsidian)
B(-5,104,-2,minecraft:obsidian)
B(-5,104,-1,minecraft:obsidian)
B(-5,104,0,minecraft:obsidian)
B(-5,104,1,minecraft:obsidian)
B(-5,104,2,minecraft:obsidian)
B(-5,104,3,minecraft:obsidian)
B(-5,104,4,minecraft:obsidian)
B(-5,104,5,minecraft:obsidian)
B(-5,104,6,minecraft:obsidian)
B(-5,104,7,minecraft:obsidian)
B(-5,104,8,minecraft:obsidian)
B(-5,105,-4,minecraft:obsidian)
B(-5,105,-3,minecraft:obsidian)
B(-5,105,-2,minecraft:obsidian)
B(-5,105,-1,minecraft:obsidian)
B(-5,105,0,minecraft:obsidian)
B(-5,105,1,minecraft:obsidian)
B(-5,105,2,minecraft:obsidian)
B(-5,105,3,minecraft:obsidian)
B(-5,105,4,minecraft:obsidian)
B(-5,105,5,minecraft:obsidian)
B(-5,105,6,minecraft:obsidian)
B(-5,105,7,minecraft:obsidian)
B(-5,105,8,minecraft:obsidian)
B(-5,106,-7,minecraft:obsidian)
B(-5,106,-6,minecraft:obsidian)
B(-5,106,-4,minecraft:obsidian)
B(-5,106,-3,minecraft:obsidian)
B(-5,106,-2,minecraft:obsidian)
B(-5,106,-1,minecraft:obsidian)
B(-5,106,0,minecraft:obsidian)
B(-5,106,1,minecraft:obsidian)
B(-5,106,2,minecraft:obsidian)
B(-5,106,3,minecraft:obsidian)
B(-5,106,4,minecraft:obsidian)
B(-5,106,5,minecraft:obsidian)
B(-5,106,6,minecraft:obsidian)
B(-5,106,7,minecraft:obsidian)
B(-5,106,8,minecraft:diorite)
B(-5,107,-7,minecraft:obsidian)
B(-5,107,-6,minecraft:obsidian)
B(-5,107,-5,minecraft:obsidian)
B(-5,107,-4,minecraft:obsidian)
B(-5,107,-3,minecraft:obsidian)
B(-5,107,-2,minecraft:obsidian)
B(-5,107,-1,minecraft:obsidian)
B(-5,107,0,minecraft:obsidian)
B(-5,107,1,minecraft:obsidian)
B(-5,107,2,minecraft:obsidian)
B(-5,107,3,minecraft:obsidian)
B(-5,107,4,minecraft:obsidian)
B(-5,107,5,minecraft:obsidian)
B(-5,107,6,minecraft:obsidian)
B(-5,107,7,minecraft:obsidian)
B(-5,107,8,minecraft:diorite)
B(-5,108,-7,minecraft:obsidian)
B(-5,108,-6,minecraft:obsidian)
B(-5,108,-5,minecraft:obsidian)
B(-5,108,-4,minecraft:obsidian)
B(-5,108,-3,minecraft:obsidian)
B(-5,108,-2,minecraft:obsidian)
B(-5,108,-1,minecraft:obsidian)
B(-5,108,0,minecraft:obsidian)
B(-5,108,1,minecraft:obsidian)
B(-5,108,2,minecraft:obsidian)
B(-5,108,3,minecraft:obsidian)
B(-5,108,4,minecraft:obsidian)
B(-5,108,5,minecraft:obsidian)
B(-5,108,6,minecraft:obsidian)
B(-5,108,7,minecraft:obsidian)
B(-5,108,8,minecraft:diorite)
B(-5,109,-7,minecraft:obsidian)
B(-5,109,-6,minecraft:obsidian)
B(-5,109,-5,minecraft:obsidian)
B(-5,109,-4,minecraft:obsidian)
B(-5,109,-3,minecraft:obsidian)
B(-5,109,-2,minecraft:obsidian)
B(-5,109,-1,minecraft:obsidian)
B(-5,109,0,minecraft:obsidian)
B(-5,109,1,minecraft:obsidian)
B(-5,109,2,minecraft:obsidian)
B(-5,109,3,minecraft:obsidian)
B(-5,109,4,minecraft:obsidian)
B(-5,109,5,minecraft:obsidian)
B(-5,109,6,minecraft:obsidian)
B(-5,109,7,minecraft:obsidian)
B(-5,109,8,minecraft:diorite)
B(-5,110,-7,minecraft:obsidian)
B(-5,110,-6,minecraft:obsidian)
B(-5,110,-5,minecraft:obsidian)
B(-5,110,-4,minecraft:obsidian)
B(-5,110,-3,minecraft:obsidian)
B(-5,110,-2,minecraft:obsidian)
B(-5,110,-1,minecraft:obsidian)
B(-5,110,0,minecraft:obsidian)
B(-5,110,1,minecraft:obsidian)
B(-5,110,2,minecraft:obsidian)
B(-5,110,3,minecraft:obsidian)
B(-5,110,4,minecraft:obsidian)
B(-5,110,5,minecraft:obsidian)
B(-5,110,6,minecraft:obsidian)
B(-5,110,7,minecraft:diorite)
B(-5,110,8,minecraft:diorite)
B(-5,111,-7,minecraft:obsidian)
B(-5,111,-6,minecraft:obsidian)
B(-5,111,-5,minecraft:obsidian)
B(-5,111,-4,minecraft:obsidian)
B(-5,111,-3,minecraft:obsidian)
B(-5,111,-2,minecraft:obsidian)
B(-5,111,-1,minecraft:obsidian)
B(-5,111,0,minecraft:obsidian)
B(-5,111,1,minecraft:obsidian)
B(-5,111,2,minecraft:obsidian)
B(-5,111,3,minecraft:obsidian)
B(-5,111,4,minecraft:obsidian)
B(-5,111,5,minecraft:diorite)
B(-5,111,6,minecraft:diorite)
B(-5,111,7,minecraft:andesite)
B(-5,111,8,minecraft:andesite)
B(-5,112,-7,minecraft:obsidian)
B(-5,112,-6,minecraft:obsidian)
B(-5,112,-5,minecraft:obsidian)
B(-5,112,-4,minecraft:obsidian)
B(-5,112,-3,minecraft:obsidian)
B(-5,112,-2,minecraft:obsidian)
B(-5,112,-1,minecraft:obsidian)
B(-5,112,0,minecraft:obsidian)
B(-5,112,1,minecraft:obsidian)
B(-5,112,2,minecraft:obsidian)
B(-5,112,3,minecraft:obsidian)
B(-5,112,4,minecraft:diorite)
B(-5,112,5,minecraft:andesite)
B(-5,112,6,minecraft:andesite)
B(-5,113,-7,minecraft:obsidian)
B(-5,113,-6,minecraft:obsidian)
B(-5,113,-5,minecraft:obsidian)
B(-5,113,-4,minecraft:obsidian)
B(-5,113,-3,minecraft:obsidian)
B(-5,113,-2,minecraft:obsidian)
B(-5,113,-1,minecraft:obsidian)
B(-5,113,0,minecraft:obsidian)
B(-5,113,1,minecraft:obsidian)
B(-5,113,2,minecraft:obsidian)
B(-5,113,3,minecraft:obsidian)
B(-5,113,4,minecraft:andesite)
B(-5,114,-7,minecraft:obsidian)
B(-5,114,-6,minecraft:obsidian)
B(-5,114,-5,minecraft:obsidian)
B(-5,114,-4,minecraft:andesite)
B(-5,114,-3,minecraft:andesite)
B(-5,114,-2,minecraft:obsidian)
B(-5,114,-1,minecraft:obsidian)
B(-5,114,0,minecraft:obsidian)
B(-5,114,1,minecraft:obsidian)
B(-5,114,2,minecraft:obsidian)
B(-5,114,3,minecraft:andesite)
B(-5,115,-7,minecraft:obsidian)
B(-5,115,-6,minecraft:andesite)
B(-5,115,-5,minecraft:andesite)
B(-5,115,-2,minecraft:andesite)
B(-5,115,-1,minecraft:andesite)
B(-5,115,0,minecraft:andesite)
B(-5,115,1,minecraft:andesite)
B(-5,115,2,minecraft:diorite)
B(-5,116,-7,minecraft:diorite)
B(-4,11,7,minecraft:diorite)
B(-4,11,8,minecraft:diorite)
B(-4,12,5,minecraft:obsidian)
B(-4,12,6,minecraft:obsidian)
B(-4,12,7,minecraft:diorite)
B(-4,12,8,minecraft:diorite)
B(-4,13,4,minecraft:obsidian)
B(-4,13,5,minecraft:obsidian)
B(-4,13,6,minecraft:obsidian)
B(-4,13,7,minecraft:diorite)
B(-4,13,8,minecraft:diorite)
B(-4,14,-2,minecraft:obsidian)
B(-4,14,-1,minecraft:magma_block)
B(-4,14,0,minecraft:magma_block)
B(-4,14,1,minecraft:magma_block)
B(-4,14,2,minecraft:magma_block)
B(-4,14,3,minecraft:magma_block)
B(-4,14,4,minecraft:obsidian)
B(-4,14,5,minecraft:obsidian)
B(-4,14,6,minecraft:obsidian)
B(-4,14,7,minecraft:diorite)
B(-4,14,8,minecraft:diorite)
B(-4,15,-7,minecraft:diorite)
B(-4,15,-6,minecraft:diorite)
B(-4,15,-5,minecraft:diorite)
B(-4,15,-4,minecraft:diorite)
B(-4,15,-3,minecraft:obsidian)
B(-4,15,-2,minecraft:obsidian)
B(-4,15,-1,minecraft:magma_block)
B(-4,15,0,minecraft:magma_block)
B(-4,15,1,minecraft:magma_block)
B(-4,15,2,minecraft:magma_block)
B(-4,15,3,minecraft:magma_block)
B(-4,15,4,minecraft:obsidian)
B(-4,15,5,minecraft:obsidian)
B(-4,15,6,minecraft:obsidian)
B(-4,15,7,minecraft:diorite)
B(-4,15,8,minecraft:diorite)
B(-4,16,-7,minecraft:diorite)
B(-4,16,-6,minecraft:diorite)
B(-4,16,-5,minecraft:diorite)
B(-4,16,-4,minecraft:diorite)
B(-4,16,-3,minecraft:obsidian)
B(-4,16,-2,minecraft:obsidian)
B(-4,16,-1,minecraft:obsidian)
B(-4,16,0,minecraft:magma_block)
B(-4,16,1,minecraft:magma_block)
B(-4,16,2,minecraft:magma_block)
B(-4,16,3,minecraft:obsidian)
B(-4,16,4,minecraft:obsidian)
B(-4,16,5,minecraft:obsidian)
B(-4,16,6,minecraft:diorite)
B(-4,16,7,minecraft:diorite)
B(-4,16,8,minecraft:diorite)
B(-4,17,-7,minecraft:diorite)
B(-4,17,-6,minecraft:diorite)
B(-4,17,-5,minecraft:diorite)
B(-4,17,-4,minecraft:diorite)
B(-4,17,-3,minecraft:diorite)
B(-4,17,-2,minecraft:obsidian)
B(-4,17,-1,minecraft:obsidian)
B(-4,17,0,minecraft:obsidian)
B(-4,17,1,minecraft:obsidian)
B(-4,17,2,minecraft:obsidian)
B(-4,17,3,minecraft:obsidian)
B(-4,17,4,minecraft:obsidian)
B(-4,17,5,minecraft:diorite)
B(-4,17,6,minecraft:diorite)
B(-4,17,7,minecraft:diorite)
B(-4,17,8,minecraft:diorite)
B(-4,18,-7,minecraft:diorite)
B(-4,18,-6,minecraft:diorite)
B(-4,18,-5,minecraft:diorite)
B(-4,18,-4,minecraft:diorite)
B(-4,18,-3,minecraft:diorite)
B(-4,18,-2,minecraft:diorite)
B(-4,18,-1,minecraft:obsidian)
B(-4,18,0,minecraft:obsidian)
B(-4,18,1,minecraft:obsidian)
B(-4,18,2,minecraft:obsidian)
B(-4,18,3,minecraft:obsidian)
B(-4,18,4,minecraft:diorite)
B(-4,18,5,minecraft:diorite)
B(-4,18,6,minecraft:diorite)
B(-4,18,7,minecraft:diorite)
B(-4,18,8,minecraft:obsidian)
B(-4,19,-7,minecraft:diorite)
B(-4,19,-6,minecraft:diorite)
B(-4,19,-5,minecraft:diorite)
B(-4,19,-4,minecraft:diorite)
B(-4,19,-3,minecraft:diorite)
B(-4,19,-2,minecraft:obsidian)
B(-4,19,-1,minecraft:obsidian)
B(-4,19,0,minecraft:obsidian)
B(-4,19,1,minecraft:obsidian)
B(-4,19,2,minecraft:diorite)
B(-4,19,3,minecraft:diorite)
B(-4,19,4,minecraft:diorite)
B(-4,19,5,minecraft:obsidian)
B(-4,19,6,minecraft:obsidian)
B(-4,19,7,minecraft:obsidian)
B(-4,19,8,minecraft:obsidian)
B(-4,20,-7,minecraft:diorite)
B(-4,20,-6,minecraft:diorite)
B(-4,20,-5,minecraft:diorite)
B(-4,20,-4,minecraft:diorite)
B(-4,20,-3,minecraft:obsidian)
B(-4,20,-2,minecraft:obsidian)
B(-4,20,-1,minecraft:obsidian)
B(-4,20,0,minecraft:obsidian)
B(-4,20,1,minecraft:obsidian)
B(-4,20,2,minecraft:obsidian)
B(-4,20,3,minecraft:obsidian)
B(-4,20,4,minecraft:obsidian)
B(-4,20,5,minecraft:obsidian)
B(-4,20,6,minecraft:obsidian)
B(-4,20,7,minecraft:obsidian)
B(-4,20,8,minecraft:obsidian)
B(-4,21,-7,minecraft:obsidian)
B(-4,21,-6,minecraft:obsidian)
B(-4,21,-5,minecraft:obsidian)
B(-4,21,-4,minecraft:obsidian)
B(-4,21,-3,minecraft:obsidian)
B(-4,21,-2,minecraft:obsidian)
B(-4,21,-1,minecraft:obsidian)
B(-4,21,0,minecraft:obsidian)
B(-4,21,1,minecraft:obsidian)
B(-4,21,2,minecraft:obsidian)
B(-4,21,3,minecraft:obsidian)
B(-4,21,4,minecraft:obsidian)
B(-4,21,5,minecraft:obsidian)
B(-4,21,6,minecraft:obsidian)
B(-4,21,7,minecraft:obsidian)
B(-4,21,8,minecraft:obsidian)
B(-4,22,-7,minecraft:obsidian)
B(-4,22,-6,minecraft:obsidian)
B(-4,22,-5,minecraft:obsidian)
B(-4,22,-4,minecraft:obsidian)
B(-4,22,-3,minecraft:obsidian)
B(-4,22,-2,minecraft:obsidian)
B(-4,22,-1,minecraft:obsidian)
B(-4,22,0,minecraft:obsidian)
B(-4,22,1,minecraft:obsidian)
B(-4,22,2,minecraft:obsidian)
B(-4,22,3,minecraft:obsidian)
B(-4,22,4,minecraft:obsidian)
B(-4,22,5,minecraft:obsidian)
B(-4,22,6,minecraft:obsidian)
B(-4,22,7,minecraft:obsidian)
B(-4,22,8,minecraft:obsidian)
B(-4,23,-7,minecraft:obsidian)
B(-4,23,-6,minecraft:obsidian)
B(-4,23,-5,minecraft:obsidian)
B(-4,23,-4,minecraft:obsidian)
B(-4,23,-3,minecraft:obsidian)
B(-4,23,-2,minecraft:obsidian)
B(-4,23,-1,minecraft:obsidian)
B(-4,23,0,minecraft:obsidian)
B(-4,23,1,minecraft:obsidian)
B(-4,23,2,minecraft:obsidian)
B(-4,23,3,minecraft:obsidian)
B(-4,23,4,minecraft:obsidian)
B(-4,23,5,minecraft:obsidian)
B(-4,23,6,minecraft:obsidian)
B(-4,23,7,minecraft:obsidian)
B(-4,23,8,minecraft:obsidian)
B(-4,24,-7,minecraft:obsidian)
B(-4,24,-6,minecraft:obsidian)
B(-4,24,-5,minecraft:obsidian)
B(-4,24,-4,minecraft:obsidian)
B(-4,24,-3,minecraft:obsidian)
B(-4,24,-2,minecraft:obsidian)
B(-4,24,-1,minecraft:obsidian)
B(-4,24,0,minecraft:obsidian)
B(-4,24,1,minecraft:obsidian)
B(-4,24,2,minecraft:obsidian)
B(-4,24,3,minecraft:obsidian)
B(-4,24,4,minecraft:obsidian)
B(-4,24,5,minecraft:obsidian)
B(-4,24,6,minecraft:obsidian)
B(-4,24,7,minecraft:obsidian)
B(-4,24,8,minecraft:obsidian)
B(-4,25,-7,minecraft:obsidian)
B(-4,25,-6,minecraft:obsidian)
B(-4,25,-5,minecraft:obsidian)
B(-4,25,-4,minecraft:obsidian)
B(-4,25,-3,minecraft:obsidian)
B(-4,25,-2,minecraft:obsidian)
B(-4,25,-1,minecraft:obsidian)
B(-4,25,0,minecraft:obsidian)
B(-4,25,1,minecraft:obsidian)
B(-4,25,2,minecraft:obsidian)
B(-4,25,3,minecraft:obsidian)
B(-4,25,4,minecraft:lava)
B(-4,25,5,minecraft:lava)
B(-4,25,6,minecraft:lava)
B(-4,25,7,minecraft:lava)
B(-4,25,8,minecraft:lava)
B(-4,26,-7,minecraft:obsidian)
B(-4,26,-6,minecraft:obsidian)
B(-4,26,-5,minecraft:obsidian)
B(-4,26,-4,minecraft:obsidian)
B(-4,26,-3,minecraft:obsidian)
B(-4,26,-2,minecraft:obsidian)
B(-4,26,-1,minecraft:obsidian)
B(-4,26,0,minecraft:obsidian)
B(-4,26,1,minecraft:obsidian)
B(-4,26,2,minecraft:obsidian)
B(-4,26,3,minecraft:lava)
B(-4,26,4,minecraft:lava)
B(-4,26,5,minecraft:lava)
B(-4,26,6,minecraft:lava)
B(-4,26,7,minecraft:lava)
B(-4,26,8,minecraft:lava)
B(-4,27,-7,minecraft:obsidian)
B(-4,27,-6,minecraft:obsidian)
B(-4,27,-5,minecraft:obsidian)
B(-4,27,-4,minecraft:obsidian)
B(-4,27,-3,minecraft:obsidian)
B(-4,27,-2,minecraft:obsidian)
B(-4,27,-1,minecraft:obsidian)
B(-4,27,0,minecraft:obsidian)
B(-4,27,1,minecraft:obsidian)
B(-4,27,2,minecraft:lava)
B(-4,27,3,minecraft:lava)
B(-4,27,4,minecraft:lava)
B(-4,27,5,minecraft:lava)
B(-4,27,6,minecraft:lava)
B(-4,27,7,minecraft:lava)
B(-4,27,8,minecraft:lava)
B(-4,28,-7,minecraft:obsidian)
B(-4,28,-6,minecraft:obsidian)
B(-4,28,-5,minecraft:obsidian)
B(-4,28,-4,minecraft:obsidian)
B(-4,28,-3,minecraft:obsidian)
B(-4,28,-2,minecraft:obsidian)
B(-4,28,-1,minecraft:obsidian)
B(-4,28,0,minecraft:obsidian)
B(-4,29,-7,minecraft:obsidian)
B(-4,29,-6,minecraft:obsidian)
B(-4,29,-5,minecraft:obsidian)
B(-4,29,-4,minecraft:obsidian)
B(-4,29,-3,minecraft:obsidian)
B(-4,29,-2,minecraft:obsidian)
B(-4,29,-1,minecraft:obsidian)
B(-4,30,-7,minecraft:obsidian)
B(-4,30,-6,minecraft:obsidian)
B(-4,30,-5,minecraft:obsidian)
B(-4,30,-4,minecraft:obsidian)
B(-4,30,-3,minecraft:obsidian)
B(-4,30,-2,minecraft:obsidian)
B(-4,31,-7,minecraft:obsidian)
B(-4,31,-6,minecraft:obsidian)
B(-4,31,-5,minecraft:obsidian)
B(-4,31,-4,minecraft:obsidian)
B(-4,31,-3,minecraft:obsidian)
B(-4,32,-7,minecraft:obsidian)
B(-4,32,-6,minecraft:obsidian)
B(-4,32,-5,minecraft:obsidian)
B(-4,32,-4,minecraft:obsidian)
B(-4,33,-7,minecraft:obsidian)
B(-4,33,-6,minecraft:obsidian)
B(-4,33,-5,minecraft:obsidian)
B(-4,34,-7,minecraft:obsidian)
B(-4,34,-6,minecraft:obsidian)
B(-4,35,-7,minecraft:obsidian)
B(-4,35,-6,minecraft:obsidian)
B(-4,36,-7,minecraft:obsidian)
B(-4,36,-6,minecraft:obsidian)
B(-4,37,-7,minecraft:obsidian)
B(-4,38,-7,minecraft:obsidian)
B(-4,92,8,minecraft:diorite)
B(-4,93,8,minecraft:diorite)
B(-4,94,8,minecraft:diorite)
B(-4,95,8,minecraft:diorite)
B(-4,96,8,minecraft:diorite)
B(-4,97,8,minecraft:obsidian)
B(-4,98,5,minecraft:obsidian)
B(-4,98,6,minecraft:obsidian)
B(-4,98,7,minecraft:obsidian)
B(-4,98,8,minecraft:obsidian)
B(-4,99,4,minecraft:obsidian)
B(-4,99,5,minecraft:obsidian)
B(-4,99,6,minecraft:obsidian)
B(-4,99,7,minecraft:obsidian)
B(-4,99,8,minecraft:obsidian)
B(-4,100,2,minecraft:obsidian)
B(-4,100,3,minecraft:obsidian)
B(-4,100,4,minecraft:obsidian)
B(-4,100,5,minecraft:obsidian)
B(-4,100,6,minecraft:obsidian)
B(-4,100,7,minecraft:obsidian)
B(-4,100,8,minecraft:obsidian)
B(-4,101,0,minecraft:obsidian)
B(-4,101,1,minecraft:obsidian)
B(-4,101,2,minecraft:obsidian)
B(-4,101,3,minecraft:obsidian)
B(-4,101,4,minecraft:obsidian)
B(-4,101,5,minecraft:obsidian)
B(-4,101,6,minecraft:obsidian)
B(-4,101,7,minecraft:obsidian)
B(-4,101,8,minecraft:obsidian)
B(-4,102,-1,minecraft:obsidian)
B(-4,102,0,minecraft:obsidian)
B(-4,102,1,minecraft:obsidian)
B(-4,102,2,minecraft:obsidian)
B(-4,102,3,minecraft:obsidian)
B(-4,102,4,minecraft:obsidian)
B(-4,102,5,minecraft:obsidian)
B(-4,102,6,minecraft:obsidian)
B(-4,102,7,minecraft:obsidian)
B(-4,102,8,minecraft:obsidian)
B(-4,103,-2,minecraft:obsidian)
B(-4,103,-1,minecraft:obsidian)
B(-4,103,0,minecraft:obsidian)
B(-4,103,1,minecraft:obsidian)
B(-4,103,2,minecraft:obsidian)
B(-4,103,3,minecraft:obsidian)
B(-4,103,4,minecraft:obsidian)
B(-4,103,5,minecraft:obsidian)
B(-4,103,6,minecraft:obsidian)
B(-4,103,7,minecraft:obsidian)
B(-4,103,8,minecraft:obsidian)
B(-4,104,-3,minecraft:obsidian)
B(-4,104,-2,minecraft:obsidian)
B(-4,104,-1,minecraft:obsidian)
B(-4,104,0,minecraft:obsidian)
B(-4,104,1,minecraft:obsidian)
B(-4,104,2,minecraft:obsidian)
B(-4,104,3,minecraft:obsidian)
B(-4,104,4,minecraft:obsidian)
B(-4,104,5,minecraft:obsidian)
B(-4,104,6,minecraft:obsidian)
B(-4,104,7,minecraft:obsidian)
B(-4,104,8,minecraft:obsidian)
B(-4,105,-7,minecraft:obsidian)
B(-4,105,-3,minecraft:obsidian)
B(-4,105,-2,minecraft:obsidian)
B(-4,105,-1,minecraft:obsidian)
B(-4,105,0,minecraft:obsidian)
B(-4,105,1,minecraft:obsidian)
B(-4,105,2,minecraft:obsidian)
B(-4,105,3,minecraft:obsidian)
B(-4,105,4,minecraft:obsidian)
B(-4,105,5,minecraft:obsidian)
B(-4,105,6,minecraft:obsidian)
B(-4,105,7,minecraft:obsidian)
B(-4,105,8,minecraft:obsidian)
B(-4,106,-7,minecraft:obsidian)
B(-4,106,-6,minecraft:obsidian)
B(-4,106,-4,minecraft:obsidian)
B(-4,106,-3,minecraft:obsidian)
B(-4,106,-2,minecraft:obsidian)
B(-4,106,-1,minecraft:obsidian)
B(-4,106,0,minecraft:obsidian)
B(-4,106,1,minecraft:obsidian)
B(-4,106,2,minecraft:obsidian)
B(-4,106,3,minecraft:obsidian)
B(-4,106,4,minecraft:obsidian)
B(-4,106,5,minecraft:obsidian)
B(-4,106,6,minecraft:obsidian)
B(-4,106,7,minecraft:obsidian)
B(-4,106,8,minecraft:obsidian)
B(-4,107,-7,minecraft:obsidian)
B(-4,107,-6,minecraft:obsidian)
B(-4,107,-5,minecraft:obsidian)
B(-4,107,-4,minecraft:obsidian)
B(-4,107,-3,minecraft:obsidian)
B(-4,107,-2,minecraft:obsidian)
B(-4,107,-1,minecraft:obsidian)
B(-4,107,0,minecraft:obsidian)
B(-4,107,1,minecraft:obsidian)
B(-4,107,2,minecraft:obsidian)
B(-4,107,3,minecraft:obsidian)
B(-4,107,4,minecraft:obsidian)
B(-4,107,5,minecraft:obsidian)
B(-4,107,6,minecraft:obsidian)
B(-4,107,7,minecraft:obsidian)
B(-4,107,8,minecraft:obsidian)
B(-4,108,-7,minecraft:obsidian)
B(-4,108,-6,minecraft:obsidian)
B(-4,108,-5,minecraft:obsidian)
B(-4,108,-4,minecraft:obsidian)
B(-4,108,-3,minecraft:obsidian)
B(-4,108,-2,minecraft:obsidian)
B(-4,108,-1,minecraft:obsidian)
B(-4,108,0,minecraft:obsidian)
B(-4,108,1,minecraft:obsidian)
B(-4,108,2,minecraft:obsidian)
B(-4,108,3,minecraft:obsidian)
B(-4,108,4,minecraft:obsidian)
B(-4,108,5,minecraft:obsidian)
B(-4,108,6,minecraft:obsidian)
B(-4,108,7,minecraft:obsidian)
B(-4,108,8,minecraft:obsidian)
B(-4,109,-7,minecraft:obsidian)
B(-4,109,-6,minecraft:obsidian)
B(-4,109,-5,minecraft:obsidian)
B(-4,109,-4,minecraft:obsidian)
B(-4,109,-3,minecraft:obsidian)
B(-4,109,-2,minecraft:obsidian)
B(-4,109,-1,minecraft:obsidian)
B(-4,109,0,minecraft:obsidian)
B(-4,109,1,minecraft:obsidian)
B(-4,109,2,minecraft:obsidian)
B(-4,109,3,minecraft:obsidian)
B(-4,109,4,minecraft:obsidian)
B(-4,109,5,minecraft:obsidian)
B(-4,109,6,minecraft:obsidian)
B(-4,109,7,minecraft:obsidian)
B(-4,109,8,minecraft:obsidian)
B(-4,110,-7,minecraft:obsidian)
B(-4,110,-6,minecraft:obsidian)
B(-4,110,-5,minecraft:obsidian)
B(-4,110,-4,minecraft:obsidian)
B(-4,110,-3,minecraft:obsidian)
B(-4,110,-2,minecraft:obsidian)
B(-4,110,-1,minecraft:obsidian)
B(-4,110,0,minecraft:obsidian)
B(-4,110,1,minecraft:obsidian)
B(-4,110,2,minecraft:obsidian)
B(-4,110,3,minecraft:obsidian)
B(-4,110,4,minecraft:obsidian)
B(-4,110,5,minecraft:obsidian)
B(-4,110,6,minecraft:obsidian)
B(-4,110,7,minecraft:obsidian)
B(-4,110,8,minecraft:diorite)
B(-4,111,-7,minecraft:obsidian)
B(-4,111,-6,minecraft:obsidian)
B(-4,111,-5,minecraft:obsidian)
B(-4,111,-4,minecraft:obsidian)
B(-4,111,-3,minecraft:obsidian)
B(-4,111,-2,minecraft:obsidian)
B(-4,111,-1,minecraft:obsidian)
B(-4,111,0,minecraft:obsidian)
B(-4,111,1,minecraft:obsidian)
B(-4,111,2,minecraft:obsidian)
B(-4,111,3,minecraft:obsidian)
B(-4,111,4,minecraft:obsidian)
B(-4,111,5,minecraft:diorite)
B(-4,111,6,minecraft:diorite)
B(-4,111,7,minecraft:diorite)
B(-4,111,8,minecraft:andesite)
B(-4,112,-7,minecraft:obsidian)
B(-4,112,-6,minecraft:obsidian)
B(-4,112,-5,minecraft:obsidian)
B(-4,112,-4,minecraft:obsidian)
B(-4,112,-3,minecraft:obsidian)
B(-4,112,-2,minecraft:obsidian)
B(-4,112,-1,minecraft:obsidian)
B(-4,112,0,minecraft:obsidian)
B(-4,112,1,minecraft:obsidian)
B(-4,112,2,minecraft:obsidian)
B(-4,112,3,minecraft:obsidian)
B(-4,112,4,minecraft:diorite)
B(-4,112,5,minecraft:andesite)
B(-4,112,6,minecraft:andesite)
B(-4,112,7,minecraft:andesite)
B(-4,113,-7,minecraft:obsidian)
B(-4,113,-6,minecraft:obsidian)
B(-4,113,-5,minecraft:obsidian)
B(-4,113,-4,minecraft:obsidian)
B(-4,113,-3,minecraft:obsidian)
B(-4,113,-2,minecraft:obsidian)
B(-4,113,-1,minecraft:obsidian)
B(-4,113,0,minecraft:obsidian)
B(-4,113,1,minecraft:obsidian)
B(-4,113,2,minecraft:obsidian)
B(-4,113,3,minecraft:obsidian)
B(-4,113,4,minecraft:andesite)
B(-4,114,-7,minecraft:obsidian)
B(-4,114,-6,minecraft:obsidian)
B(-4,114,-5,minecraft:andesite)
B(-4,114,-4,minecraft:andesite)
B(-4,114,-3,minecraft:andesite)
B(-4,114,-2,minecraft:obsidian)
B(-4,114,-1,minecraft:obsidian)
B(-4,114,0,minecraft:obsidian)
B(-4,114,1,minecraft:obsidian)
B(-4,114,2,minecraft:obsidian)
B(-4,114,3,minecraft:andesite)
B(-4,115,-7,minecraft:obsidian)
B(-4,115,-6,minecraft:andesite)
B(-4,115,-2,minecraft:andesite)
B(-4,115,-1,minecraft:andesite)
B(-4,115,0,minecraft:andesite)
B(-4,115,1,minecraft:andesite)
B(-4,115,2,minecraft:andesite)
B(-4,116,-7,minecraft:diorite)
B(-3,11,6,minecraft:obsidian)
B(-3,11,7,minecraft:diorite)
B(-3,11,8,minecraft:diorite)
B(-3,12,4,minecraft:obsidian)
B(-3,12,5,minecraft:obsidian)
B(-3,12,6,minecraft:obsidian)
B(-3,12,7,minecraft:obsidian)
B(-3,12,8,minecraft:diorite)
B(-3,13,3,minecraft:magma_block)
B(-3,13,4,minecraft:obsidian)
B(-3,13,5,minecraft:obsidian)
B(-3,13,6,minecraft:obsidian)
B(-3,13,7,minecraft:obsidian)
B(-3,13,8,minecraft:diorite)
B(-3,14,-2,minecraft:obsidian)
B(-3,14,-1,minecraft:magma_block)
B(-3,14,0,minecraft:magma_block)
B(-3,14,1,minecraft:magma_block)
B(-3,14,2,minecraft:magma_block)
B(-3,14,3,minecraft:magma_block)
B(-3,14,4,minecraft:obsidian)
B(-3,14,5,minecraft:obsidian)
B(-3,14,6,minecraft:obsidian)
B(-3,14,7,minecraft:obsidian)
B(-3,14,8,minecraft:diorite)
B(-3,15,-7,minecraft:diorite)
B(-3,15,-6,minecraft:diorite)
B(-3,15,-5,minecraft:diorite)
B(-3,15,-4,minecraft:diorite)
B(-3,15,-3,minecraft:diorite)
B(-3,15,-2,minecraft:obsidian)
B(-3,15,-1,minecraft:magma_block)
B(-3,15,0,minecraft:magma_block)
B(-3,15,1,minecraft:magma_block)
B(-3,15,2,minecraft:magma_block)
B(-3,15,3,minecraft:magma_block)
B(-3,15,4,minecraft:obsidian)
B(-3,15,5,minecraft:obsidian)
B(-3,15,6,minecraft:obsidian)
B(-3,15,7,minecraft:diorite)
B(-3,15,8,minecraft:diorite)
B(-3,16,-7,minecraft:diorite)
B(-3,16,-6,minecraft:diorite)
B(-3,16,-5,minecraft:diorite)
B(-3,16,-4,minecraft:diorite)
B(-3,16,-3,minecraft:diorite)
B(-3,16,-2,minecraft:obsidian)
B(-3,16,-1,minecraft:obsidian)
B(-3,16,0,minecraft:magma_block)
B(-3,16,1,minecraft:magma_block)
B(-3,16,2,minecraft:magma_block)
B(-3,16,3,minecraft:obsidian)
B(-3,16,4,minecraft:obsidian)
B(-3,16,5,minecraft:obsidian)
B(-3,16,6,minecraft:obsidian)
B(-3,16,7,minecraft:diorite)
B(-3,16,8,minecraft:diorite)
B(-3,17,-7,minecraft:diorite)
B(-3,17,-6,minecraft:diorite)
B(-3,17,-5,minecraft:diorite)
B(-3,17,-4,minecraft:diorite)
B(-3,17,-3,minecraft:diorite)
B(-3,17,-2,minecraft:diorite)
B(-3,17,-1,minecraft:obsidian)
B(-3,17,0,minecraft:obsidian)
B(-3,17,1,minecraft:obsidian)
B(-3,17,2,minecraft:obsidian)
B(-3,17,3,minecraft:obsidian)
B(-3,17,4,minecraft:obsidian)
B(-3,17,5,minecraft:obsidian)
B(-3,17,6,minecraft:diorite)
B(-3,17,7,minecraft:diorite)
B(-3,17,8,minecraft:diorite)
B(-3,18,-7,minecraft:diorite)
B(-3,18,-6,minecraft:diorite)
B(-3,18,-5,minecraft:diorite)
B(-3,18,-4,minecraft:diorite)
B(-3,18,-3,minecraft:diorite)
B(-3,18,-2,minecraft:diorite)
B(-3,18,-1,minecraft:obsidian)
B(-3,18,0,minecraft:obsidian)
B(-3,18,1,minecraft:obsidian)
B(-3,18,2,minecraft:obsidian)
B(-3,18,3,minecraft:obsidian)
B(-3,18,4,minecraft:diorite)
B(-3,18,5,minecraft:diorite)
B(-3,18,6,minecraft:diorite)
B(-3,18,7,minecraft:obsidian)
B(-3,18,8,minecraft:obsidian)
B(-3,19,-7,minecraft:diorite)
B(-3,19,-6,minecraft:diorite)
B(-3,19,-5,minecraft:diorite)
B(-3,19,-4,minecraft:diorite)
B(-3,19,-3,minecraft:diorite)
B(-3,19,-2,minecraft:obsidian)
B(-3,19,-1,minecraft:obsidian)
B(-3,19,0,minecraft:obsidian)
B(-3,19,1,minecraft:obsidian)
B(-3,19,2,minecraft:obsidian)
B(-3,19,3,minecraft:obsidian)
B(-3,19,4,minecraft:obsidian)
B(-3,19,5,minecraft:obsidian)
B(-3,19,6,minecraft:obsidian)
B(-3,19,7,minecraft:obsidian)
B(-3,19,8,minecraft:obsidian)
B(-3,20,-7,minecraft:diorite)
B(-3,20,-6,minecraft:diorite)
B(-3,20,-5,minecraft:diorite)
B(-3,20,-4,minecraft:diorite)
B(-3,20,-3,minecraft:obsidian)
B(-3,20,-2,minecraft:obsidian)
B(-3,20,-1,minecraft:obsidian)
B(-3,20,0,minecraft:obsidian)
B(-3,20,1,minecraft:obsidian)
B(-3,20,2,minecraft:obsidian)
B(-3,20,3,minecraft:obsidian)
B(-3,20,4,minecraft:obsidian)
B(-3,20,5,minecraft:obsidian)
B(-3,20,6,minecraft:obsidian)
B(-3,20,7,minecraft:obsidian)
B(-3,20,8,minecraft:obsidian)
B(-3,21,-7,minecraft:obsidian)
B(-3,21,-6,minecraft:obsidian)
B(-3,21,-5,minecraft:obsidian)
B(-3,21,-4,minecraft:obsidian)
B(-3,21,-3,minecraft:obsidian)
B(-3,21,-2,minecraft:obsidian)
B(-3,21,-1,minecraft:obsidian)
B(-3,21,0,minecraft:obsidian)
B(-3,21,1,minecraft:obsidian)
B(-3,21,2,minecraft:obsidian)
B(-3,21,3,minecraft:obsidian)
B(-3,21,4,minecraft:obsidian)
B(-3,21,5,minecraft:obsidian)
B(-3,21,6,minecraft:obsidian)
B(-3,21,7,minecraft:obsidian)
B(-3,21,8,minecraft:obsidian)
B(-3,22,-7,minecraft:obsidian)
B(-3,22,-6,minecraft:obsidian)
B(-3,22,-5,minecraft:obsidian)
B(-3,22,-4,minecraft:obsidian)
B(-3,22,-3,minecraft:obsidian)
B(-3,22,-2,minecraft:obsidian)
B(-3,22,-1,minecraft:obsidian)
B(-3,22,0,minecraft:obsidian)
B(-3,22,1,minecraft:obsidian)
B(-3,22,2,minecraft:obsidian)
B(-3,22,3,minecraft:obsidian)
B(-3,22,4,minecraft:obsidian)
B(-3,22,5,minecraft:obsidian)
B(-3,22,6,minecraft:obsidian)
B(-3,22,7,minecraft:obsidian)
B(-3,22,8,minecraft:obsidian)
B(-3,23,-7,minecraft:obsidian)
B(-3,23,-6,minecraft:obsidian)
B(-3,23,-5,minecraft:obsidian)
B(-3,23,-4,minecraft:obsidian)
B(-3,23,-3,minecraft:obsidian)
B(-3,23,-2,minecraft:obsidian)
B(-3,23,-1,minecraft:obsidian)
B(-3,23,0,minecraft:obsidian)
B(-3,23,1,minecraft:obsidian)
B(-3,23,2,minecraft:obsidian)
B(-3,23,3,minecraft:obsidian)
B(-3,23,4,minecraft:obsidian)
B(-3,23,5,minecraft:obsidian)
B(-3,23,6,minecraft:obsidian)
B(-3,23,7,minecraft:obsidian)
B(-3,23,8,minecraft:obsidian)
B(-3,24,-7,minecraft:obsidian)
B(-3,24,-6,minecraft:obsidian)
B(-3,24,-5,minecraft:obsidian)
B(-3,24,-4,minecraft:obsidian)
B(-3,24,-3,minecraft:obsidian)
B(-3,24,-2,minecraft:obsidian)
B(-3,24,-1,minecraft:obsidian)
B(-3,24,0,minecraft:obsidian)
B(-3,24,1,minecraft:obsidian)
B(-3,24,2,minecraft:obsidian)
B(-3,24,3,minecraft:obsidian)
B(-3,24,4,minecraft:obsidian)
B(-3,24,5,minecraft:obsidian)
B(-3,24,6,minecraft:obsidian)
B(-3,24,7,minecraft:obsidian)
B(-3,24,8,minecraft:obsidian)
B(-3,25,-7,minecraft:obsidian)
B(-3,25,-6,minecraft:obsidian)
B(-3,25,-5,minecraft:obsidian)
B(-3,25,-4,minecraft:obsidian)
B(-3,25,-3,minecraft:obsidian)
B(-3,25,-2,minecraft:obsidian)
B(-3,25,-1,minecraft:obsidian)
B(-3,25,0,minecraft:obsidian)
B(-3,25,1,minecraft:obsidian)
B(-3,25,2,minecraft:obsidian)
B(-3,25,3,minecraft:obsidian)
B(-3,25,4,minecraft:obsidian)
B(-3,25,5,minecraft:lava)
B(-3,25,6,minecraft:lava)
B(-3,25,7,minecraft:lava)
B(-3,25,8,minecraft:lava)
B(-3,26,-7,minecraft:obsidian)
B(-3,26,-6,minecraft:obsidian)
B(-3,26,-5,minecraft:obsidian)
B(-3,26,-4,minecraft:obsidian)
B(-3,26,-3,minecraft:obsidian)
B(-3,26,-2,minecraft:obsidian)
B(-3,26,-1,minecraft:obsidian)
B(-3,26,0,minecraft:obsidian)
B(-3,26,1,minecraft:obsidian)
B(-3,26,2,minecraft:obsidian)
B(-3,26,3,minecraft:obsidian)
B(-3,26,4,minecraft:lava)
B(-3,26,5,minecraft:lava)
B(-3,26,6,minecraft:lava)
B(-3,26,7,minecraft:lava)
B(-3,26,8,minecraft:lava)
B(-3,27,-7,minecraft:obsidian)
B(-3,27,-6,minecraft:obsidian)
B(-3,27,-5,minecraft:obsidian)
B(-3,27,-4,minecraft:obsidian)
B(-3,27,-3,minecraft:obsidian)
B(-3,27,-2,minecraft:obsidian)
B(-3,27,-1,minecraft:obsidian)
B(-3,27,0,minecraft:obsidian)
B(-3,27,1,minecraft:obsidian)
B(-3,27,2,minecraft:lava)
B(-3,27,3,minecraft:lava)
B(-3,27,4,minecraft:lava)
B(-3,27,5,minecraft:lava)
B(-3,27,6,minecraft:lava)
B(-3,27,7,minecraft:lava)
B(-3,27,8,minecraft:lava)
B(-3,28,-7,minecraft:obsidian)
B(-3,28,-6,minecraft:obsidian)
B(-3,28,-5,minecraft:obsidian)
B(-3,28,-4,minecraft:obsidian)
B(-3,28,-3,minecraft:obsidian)
B(-3,28,-2,minecraft:obsidian)
B(-3,28,-1,minecraft:obsidian)
B(-3,28,0,minecraft:obsidian)
B(-3,29,-7,minecraft:obsidian)
B(-3,29,-6,minecraft:obsidian)
B(-3,29,-5,minecraft:obsidian)
B(-3,29,-4,minecraft:obsidian)
B(-3,29,-3,minecraft:obsidian)
B(-3,29,-2,minecraft:obsidian)
B(-3,30,-7,minecraft:obsidian)
B(-3,30,-6,minecraft:obsidian)
B(-3,30,-5,minecraft:obsidian)
B(-3,30,-4,minecraft:obsidian)
B(-3,30,-3,minecraft:obsidian)
B(-3,31,-7,minecraft:obsidian)
B(-3,31,-6,minecraft:obsidian)
B(-3,31,-5,minecraft:obsidian)
B(-3,31,-4,minecraft:obsidian)
B(-3,32,-7,minecraft:obsidian)
B(-3,32,-6,minecraft:obsidian)
B(-3,32,-5,minecraft:obsidian)
B(-3,32,-4,minecraft:obsidian)
B(-3,33,-7,minecraft:obsidian)
B(-3,33,-6,minecraft:obsidian)
B(-3,33,-5,minecraft:obsidian)
B(-3,34,-7,minecraft:obsidian)
B(-3,34,-6,minecraft:obsidian)
B(-3,35,-7,minecraft:obsidian)
B(-3,35,-6,minecraft:obsidian)
B(-3,36,-7,minecraft:obsidian)
B(-3,36,-6,minecraft:obsidian)
B(-3,37,-7,minecraft:obsidian)
B(-3,38,-7,minecraft:obsidian)
B(-3,92,8,minecraft:diorite)
B(-3,93,7,minecraft:diorite)
B(-3,93,8,minecraft:diorite)
B(-3,94,8,minecraft:diorite)
B(-3,95,7,minecraft:diorite)
B(-3,95,8,minecraft:diorite)
B(-3,96,7,minecraft:diorite)
B(-3,96,8,minecraft:diorite)
B(-3,97,7,minecraft:diorite)
B(-3,97,8,minecraft:obsidian)
B(-3,98,4,minecraft:obsidian)
B(-3,98,5,minecraft:obsidian)
B(-3,98,6,minecraft:obsidian)
B(-3,98,7,minecraft:obsidian)
B(-3,98,8,minecraft:obsidian)
B(-3,99,2,minecraft:obsidian)
B(-3,99,3,minecraft:obsidian)
B(-3,99,4,minecraft:obsidian)
B(-3,99,5,minecraft:obsidian)
B(-3,99,6,minecraft:obsidian)
B(-3,99,7,minecraft:obsidian)
B(-3,99,8,minecraft:obsidian)
B(-3,100,1,minecraft:obsidian)
B(-3,100,2,minecraft:obsidian)
B(-3,100,3,minecraft:obsidian)
B(-3,100,4,minecraft:obsidian)
B(-3,100,5,minecraft:obsidian)
B(-3,100,6,minecraft:obsidian)
B(-3,100,7,minecraft:obsidian)
B(-3,100,8,minecraft:obsidian)
B(-3,101,0,minecraft:obsidian)
B(-3,101,1,minecraft:obsidian)
B(-3,101,2,minecraft:obsidian)
B(-3,101,3,minecraft:obsidian)
B(-3,101,4,minecraft:obsidian)
B(-3,101,5,minecraft:obsidian)
B(-3,101,6,minecraft:obsidian)
B(-3,101,7,minecraft:obsidian)
B(-3,101,8,minecraft:obsidian)
B(-3,102,-1,minecraft:obsidian)
B(-3,102,0,minecraft:obsidian)
B(-3,102,1,minecraft:obsidian)
B(-3,102,2,minecraft:obsidian)
B(-3,102,3,minecraft:obsidian)
B(-3,102,4,minecraft:obsidian)
B(-3,102,5,minecraft:obsidian)
B(-3,102,6,minecraft:obsidian)
B(-3,102,7,minecraft:obsidian)
B(-3,102,8,minecraft:obsidian)
B(-3,103,-2,minecraft:obsidian)
B(-3,103,-1,minecraft:obsidian)
B(-3,103,0,minecraft:obsidian)
B(-3,103,1,minecraft:obsidian)
B(-3,103,2,minecraft:obsidian)
B(-3,103,3,minecraft:obsidian)
B(-3,103,4,minecraft:obsidian)
B(-3,103,5,minecraft:obsidian)
B(-3,103,6,minecraft:obsidian)
B(-3,103,7,minecraft:obsidian)
B(-3,103,8,minecraft:obsidian)
B(-3,104,-3,minecraft:obsidian)
B(-3,104,-2,minecraft:obsidian)
B(-3,104,-1,minecraft:obsidian)
B(-3,104,0,minecraft:obsidian)
B(-3,104,1,minecraft:obsidian)
B(-3,104,2,minecraft:obsidian)
B(-3,104,3,minecraft:obsidian)
B(-3,104,4,minecraft:obsidian)
B(-3,104,5,minecraft:obsidian)
B(-3,104,6,minecraft:obsidian)
B(-3,104,7,minecraft:obsidian)
B(-3,104,8,minecraft:obsidian)
B(-3,105,-7,minecraft:obsidian)
B(-3,105,-6,minecraft:obsidian)
B(-3,105,-5,minecraft:obsidian)
B(-3,105,-4,minecraft:obsidian)
B(-3,105,-3,minecraft:obsidian)
B(-3,105,-2,minecraft:obsidian)
B(-3,105,-1,minecraft:obsidian)
B(-3,105,0,minecraft:obsidian)
B(-3,105,1,minecraft:obsidian)
B(-3,105,2,minecraft:obsidian)
B(-3,105,3,minecraft:obsidian)
B(-3,105,4,minecraft:obsidian)
B(-3,105,5,minecraft:obsidian)
B(-3,105,6,minecraft:obsidian)
B(-3,105,7,minecraft:obsidian)
B(-3,105,8,minecraft:obsidian)
B(-3,106,-7,minecraft:obsidian)
B(-3,106,-6,minecraft:obsidian)
B(-3,106,-5,minecraft:obsidian)
B(-3,106,-4,minecraft:obsidian)
B(-3,106,-3,minecraft:obsidian)
B(-3,106,-2,minecraft:obsidian)
B(-3,106,-1,minecraft:obsidian)
B(-3,106,0,minecraft:obsidian)
B(-3,106,1,minecraft:obsidian)
B(-3,106,2,minecraft:obsidian)
B(-3,106,3,minecraft:obsidian)
B(-3,106,4,minecraft:obsidian)
B(-3,106,5,minecraft:obsidian)
B(-3,106,6,minecraft:obsidian)
B(-3,106,7,minecraft:obsidian)
B(-3,106,8,minecraft:obsidian)
B(-3,107,-7,minecraft:obsidian)
B(-3,107,-6,minecraft:obsidian)
B(-3,107,-5,minecraft:obsidian)
B(-3,107,-4,minecraft:obsidian)
B(-3,107,-3,minecraft:obsidian)
B(-3,107,-2,minecraft:obsidian)
B(-3,107,-1,minecraft:obsidian)
B(-3,107,0,minecraft:obsidian)
B(-3,107,1,minecraft:obsidian)
B(-3,107,2,minecraft:obsidian)
B(-3,107,3,minecraft:obsidian)
B(-3,107,4,minecraft:obsidian)
B(-3,107,5,minecraft:obsidian)
B(-3,107,6,minecraft:obsidian)
B(-3,107,7,minecraft:obsidian)
B(-3,107,8,minecraft:obsidian)
B(-3,108,-7,minecraft:obsidian)
B(-3,108,-6,minecraft:obsidian)
B(-3,108,-5,minecraft:obsidian)
B(-3,108,-4,minecraft:obsidian)
B(-3,108,-3,minecraft:obsidian)
B(-3,108,-2,minecraft:obsidian)
B(-3,108,-1,minecraft:obsidian)
B(-3,108,0,minecraft:obsidian)
B(-3,108,1,minecraft:obsidian)
B(-3,108,2,minecraft:obsidian)
B(-3,108,3,minecraft:obsidian)
B(-3,108,4,minecraft:obsidian)
B(-3,108,5,minecraft:obsidian)
B(-3,108,6,minecraft:obsidian)
B(-3,108,7,minecraft:obsidian)
B(-3,108,8,minecraft:obsidian)
B(-3,109,-7,minecraft:obsidian)
B(-3,109,-6,minecraft:obsidian)
B(-3,109,-5,minecraft:obsidian)
B(-3,109,-4,minecraft:obsidian)
B(-3,109,-3,minecraft:obsidian)
B(-3,109,-2,minecraft:obsidian)
B(-3,109,-1,minecraft:obsidian)
B(-3,109,0,minecraft:obsidian)
B(-3,109,1,minecraft:obsidian)
B(-3,109,2,minecraft:obsidian)
B(-3,109,3,minecraft:obsidian)
B(-3,109,4,minecraft:obsidian)
B(-3,109,5,minecraft:obsidian)
B(-3,109,6,minecraft:obsidian)
B(-3,109,7,minecraft:obsidian)
B(-3,109,8,minecraft:obsidian)
B(-3,110,-7,minecraft:obsidian)
B(-3,110,-6,minecraft:obsidian)
B(-3,110,-5,minecraft:obsidian)
B(-3,110,-4,minecraft:obsidian)
B(-3,110,-3,minecraft:obsidian)
B(-3,110,-2,minecraft:obsidian)
B(-3,110,-1,minecraft:obsidian)
B(-3,110,0,minecraft:obsidian)
B(-3,110,1,minecraft:obsidian)
B(-3,110,2,minecraft:obsidian)
B(-3,110,3,minecraft:obsidian)
B(-3,110,4,minecraft:obsidian)
B(-3,110,5,minecraft:obsidian)
B(-3,110,6,minecraft:obsidian)
B(-3,110,7,minecraft:obsidian)
B(-3,110,8,minecraft:diorite)
B(-3,111,-7,minecraft:obsidian)
B(-3,111,-6,minecraft:obsidian)
B(-3,111,-5,minecraft:obsidian)
B(-3,111,-4,minecraft:obsidian)
B(-3,111,-3,minecraft:obsidian)
B(-3,111,-2,minecraft:obsidian)
B(-3,111,-1,minecraft:obsidian)
B(-3,111,0,minecraft:obsidian)
B(-3,111,1,minecraft:obsidian)
B(-3,111,2,minecraft:obsidian)
B(-3,111,3,minecraft:obsidian)
B(-3,111,4,minecraft:obsidian)
B(-3,111,5,minecraft:diorite)
B(-3,111,6,minecraft:diorite)
B(-3,111,7,minecraft:diorite)
B(-3,111,8,minecraft:andesite)
B(-3,112,-7,minecraft:obsidian)
B(-3,112,-6,minecraft:obsidian)
B(-3,112,-5,minecraft:obsidian)
B(-3,112,-4,minecraft:obsidian)
B(-3,112,-3,minecraft:obsidian)
B(-3,112,-2,minecraft:obsidian)
B(-3,112,-1,minecraft:obsidian)
B(-3,112,0,minecraft:obsidian)
B(-3,112,1,minecraft:obsidian)
B(-3,112,2,minecraft:obsidian)
B(-3,112,3,minecraft:obsidian)
B(-3,112,4,minecraft:diorite)
B(-3,112,5,minecraft:andesite)
B(-3,112,6,minecraft:andesite)
B(-3,112,7,minecraft:andesite)
B(-3,113,-7,minecraft:obsidian)
B(-3,113,-6,minecraft:obsidian)
B(-3,113,-5,minecraft:obsidian)
B(-3,113,-4,minecraft:obsidian)
B(-3,113,-3,minecraft:obsidian)
B(-3,113,-2,minecraft:obsidian)
B(-3,113,-1,minecraft:obsidian)
B(-3,113,0,minecraft:obsidian)
B(-3,113,1,minecraft:obsidian)
B(-3,113,2,minecraft:obsidian)
B(-3,113,3,minecraft:obsidian)
B(-3,113,4,minecraft:andesite)
B(-3,114,-7,minecraft:obsidian)
B(-3,114,-6,minecraft:obsidian)
B(-3,114,-5,minecraft:andesite)
B(-3,114,-4,minecraft:andesite)
B(-3,114,-3,minecraft:andesite)
B(-3,114,-2,minecraft:andesite)
B(-3,114,-1,minecraft:obsidian)
B(-3,114,0,minecraft:obsidian)
B(-3,114,1,minecraft:obsidian)
B(-3,114,2,minecraft:andesite)
B(-3,114,3,minecraft:andesite)
B(-3,115,-7,minecraft:obsidian)
B(-3,115,-6,minecraft:andesite)
B(-3,115,-1,minecraft:andesite)
B(-3,115,0,minecraft:andesite)
B(-3,115,1,minecraft:andesite)
B(-3,116,-7,minecraft:diorite)
B(-2,11,5,minecraft:obsidian)
B(-2,11,6,minecraft:obsidian)
B(-2,11,7,minecraft:obsidian)
B(-2,11,8,minecraft:diorite)
B(-2,12,3,minecraft:magma_block)
B(-2,12,4,minecraft:obsidian)
B(-2,12,5,minecraft:obsidian)
B(-2,12,6,minecraft:obsidian)
B(-2,12,7,minecraft:obsidian)
B(-2,12,8,minecraft:diorite)
B(-2,13,2,minecraft:magma_block)
B(-2,13,3,minecraft:magma_block)
B(-2,13,4,minecraft:obsidian)
B(-2,13,5,minecraft:obsidian)
B(-2,13,6,minecraft:obsidian)
B(-2,13,7,minecraft:obsidian)
B(-2,13,8,minecraft:diorite)
B(-2,14,-2,minecraft:obsidian)
B(-2,14,-1,minecraft:magma_block)
B(-2,14,0,minecraft:magma_block)
B(-2,14,1,minecraft:magma_block)
B(-2,14,2,minecraft:magma_block)
B(-2,14,3,minecraft:magma_block)
B(-2,14,4,minecraft:obsidian)
B(-2,14,5,minecraft:obsidian)
B(-2,14,6,minecraft:obsidian)
B(-2,14,7,minecraft:obsidian)
B(-2,14,8,minecraft:diorite)
B(-2,15,-7,minecraft:diorite)
B(-2,15,-6,minecraft:diorite)
B(-2,15,-5,minecraft:diorite)
B(-2,15,-4,minecraft:diorite)
B(-2,15,-3,minecraft:obsidian)
B(-2,15,-2,minecraft:obsidian)
B(-2,15,-1,minecraft:magma_block)
B(-2,15,0,minecraft:magma_block)
B(-2,15,1,minecraft:magma_block)
B(-2,15,2,minecraft:magma_block)
B(-2,15,3,minecraft:magma_block)
B(-2,15,4,minecraft:obsidian)
B(-2,15,5,minecraft:obsidian)
B(-2,15,6,minecraft:obsidian)
B(-2,15,7,minecraft:obsidian)
B(-2,15,8,minecraft:diorite)
B(-2,16,-7,minecraft:diorite)
B(-2,16,-6,minecraft:diorite)
B(-2,16,-5,minecraft:diorite)
B(-2,16,-4,minecraft:diorite)
B(-2,16,-3,minecraft:diorite)
B(-2,16,-2,minecraft:obsidian)
B(-2,16,-1,minecraft:obsidian)
B(-2,16,0,minecraft:magma_block)
B(-2,16,1,minecraft:magma_block)
B(-2,16,2,minecraft:magma_block)
B(-2,16,3,minecraft:obsidian)
B(-2,16,4,minecraft:obsidian)
B(-2,16,5,minecraft:obsidian)
B(-2,16,6,minecraft:obsidian)
B(-2,16,7,minecraft:diorite)
B(-2,16,8,minecraft:diorite)
B(-2,17,-7,minecraft:diorite)
B(-2,17,-6,minecraft:diorite)
B(-2,17,-5,minecraft:diorite)
B(-2,17,-4,minecraft:diorite)
B(-2,17,-3,minecraft:diorite)
B(-2,17,-2,minecraft:diorite)
B(-2,17,-1,minecraft:obsidian)
B(-2,17,0,minecraft:obsidian)
B(-2,17,1,minecraft:obsidian)
B(-2,17,2,minecraft:obsidian)
B(-2,17,3,minecraft:obsidian)
B(-2,17,4,minecraft:obsidian)
B(-2,17,5,minecraft:obsidian)
B(-2,17,6,minecraft:diorite)
B(-2,17,7,minecraft:diorite)
B(-2,17,8,minecraft:obsidian)
B(-2,18,-7,minecraft:diorite)
B(-2,18,-6,minecraft:diorite)
B(-2,18,-5,minecraft:diorite)
B(-2,18,-4,minecraft:diorite)
B(-2,18,-3,minecraft:diorite)
B(-2,18,-2,minecraft:diorite)
B(-2,18,-1,minecraft:obsidian)
B(-2,18,0,minecraft:obsidian)
B(-2,18,1,minecraft:obsidian)
B(-2,18,2,minecraft:obsidian)
B(-2,18,3,minecraft:obsidian)
B(-2,18,4,minecraft:obsidian)
B(-2,18,5,minecraft:obsidian)
B(-2,18,6,minecraft:obsidian)
B(-2,18,7,minecraft:obsidian)
B(-2,18,8,minecraft:obsidian)
B(-2,19,-7,minecraft:diorite)
B(-2,19,-6,minecraft:diorite)
B(-2,19,-5,minecraft:diorite)
B(-2,19,-4,minecraft:diorite)
B(-2,19,-3,minecraft:diorite)
B(-2,19,-2,minecraft:obsidian)
B(-2,19,-1,minecraft:obsidian)
B(-2,19,0,minecraft:obsidian)
B(-2,19,1,minecraft:obsidian)
B(-2,19,2,minecraft:obsidian)
B(-2,19,3,minecraft:obsidian)
B(-2,19,4,minecraft:obsidian)
B(-2,19,5,minecraft:obsidian)
B(-2,19,6,minecraft:obsidian)
B(-2,19,7,minecraft:obsidian)
B(-2,19,8,minecraft:obsidian)
B(-2,20,-7,minecraft:diorite)
B(-2,20,-6,minecraft:diorite)
B(-2,20,-5,minecraft:diorite)
B(-2,20,-4,minecraft:obsidian)
B(-2,20,-3,minecraft:obsidian)
B(-2,20,-2,minecraft:obsidian)
B(-2,20,-1,minecraft:obsidian)
B(-2,20,0,minecraft:obsidian)
B(-2,20,1,minecraft:obsidian)
B(-2,20,2,minecraft:obsidian)
B(-2,20,3,minecraft:obsidian)
B(-2,20,4,minecraft:obsidian)
B(-2,20,5,minecraft:obsidian)
B(-2,20,6,minecraft:obsidian)
B(-2,20,7,minecraft:obsidian)
B(-2,20,8,minecraft:obsidian)
B(-2,21,-7,minecraft:obsidian)
B(-2,21,-6,minecraft:obsidian)
B(-2,21,-5,minecraft:obsidian)
B(-2,21,-4,minecraft:obsidian)
B(-2,21,-3,minecraft:obsidian)
B(-2,21,-2,minecraft:obsidian)
B(-2,21,-1,minecraft:obsidian)
B(-2,21,0,minecraft:obsidian)
B(-2,21,1,minecraft:obsidian)
B(-2,21,2,minecraft:obsidian)
B(-2,21,3,minecraft:obsidian)
B(-2,21,4,minecraft:obsidian)
B(-2,21,5,minecraft:obsidian)
B(-2,21,6,minecraft:obsidian)
B(-2,21,7,minecraft:obsidian)
B(-2,21,8,minecraft:obsidian)
B(-2,22,-7,minecraft:obsidian)
B(-2,22,-6,minecraft:obsidian)
B(-2,22,-5,minecraft:obsidian)
B(-2,22,-4,minecraft:obsidian)
B(-2,22,-3,minecraft:obsidian)
B(-2,22,-2,minecraft:obsidian)
B(-2,22,-1,minecraft:obsidian)
B(-2,22,0,minecraft:obsidian)
B(-2,22,1,minecraft:obsidian)
B(-2,22,2,minecraft:obsidian)
B(-2,22,3,minecraft:obsidian)
B(-2,22,4,minecraft:obsidian)
B(-2,22,5,minecraft:obsidian)
B(-2,22,6,minecraft:obsidian)
B(-2,22,7,minecraft:obsidian)
B(-2,22,8,minecraft:obsidian)
B(-2,23,-7,minecraft:obsidian)
B(-2,23,-6,minecraft:obsidian)
B(-2,23,-5,minecraft:obsidian)
B(-2,23,-4,minecraft:obsidian)
B(-2,23,-3,minecraft:obsidian)
B(-2,23,-2,minecraft:obsidian)
B(-2,23,-1,minecraft:obsidian)
B(-2,23,0,minecraft:obsidian)
B(-2,23,1,minecraft:obsidian)
B(-2,23,2,minecraft:obsidian)
B(-2,23,3,minecraft:obsidian)
B(-2,23,4,minecraft:obsidian)
B(-2,23,5,minecraft:obsidian)
B(-2,23,6,minecraft:obsidian)
B(-2,23,7,minecraft:obsidian)
B(-2,23,8,minecraft:obsidian)
B(-2,24,-7,minecraft:obsidian)
B(-2,24,-6,minecraft:obsidian)
B(-2,24,-5,minecraft:obsidian)
B(-2,24,-4,minecraft:obsidian)
B(-2,24,-3,minecraft:obsidian)
B(-2,24,-2,minecraft:obsidian)
B(-2,24,-1,minecraft:obsidian)
B(-2,24,0,minecraft:obsidian)
B(-2,24,1,minecraft:obsidian)
B(-2,24,2,minecraft:obsidian)
B(-2,24,3,minecraft:obsidian)
B(-2,24,4,minecraft:obsidian)
B(-2,24,5,minecraft:obsidian)
B(-2,24,6,minecraft:obsidian)
B(-2,24,7,minecraft:obsidian)
B(-2,24,8,minecraft:obsidian)
B(-2,25,-7,minecraft:obsidian)
