#######################################################################
# +-----------------------------------------------------------------+ #
# |                            BO3 object                           | #
# +-----------------------------------------------------------------+ #
#######################################################################

Author: Bo3 BulkEdit

Description: Converted Schematic - Modified by Bo3BulkEdit

Version: 3

SettingsMode: WriteDisable

#######################################################################
# +-----------------------------------------------------------------+ #
# |                          Main settings                          | #
# +-----------------------------------------------------------------+ #
#######################################################################



Frequency: 0


SpawnHeight: randomY





##############################
# Height Limits for the BO3. #
##############################

MinHeight: 0
MaxHeight: 256

#######################################################################
# +-----------------------------------------------------------------+ #
# |                      Source block settings                      | #
# +-----------------------------------------------------------------+ #
#######################################################################

CanOverride: true
MaxPercentageOutsideSourceBlock: 100
OutsideSourceBlock: placeAnyway

#######################################################################
# +-----------------------------------------------------------------+ #
# |                               OTG+                              | #
# +-----------------------------------------------------------------+ #
#######################################################################

#######################################################################
# +-----------------------------------------------------------------+ #
# |                              Blocks                             | #
# +-----------------------------------------------------------------+ #
#######################################################################

B(0,750,0,AIR)
B(15,750,15,AIR)
B(14,-2,15,STAINED_GLASS:15)
B(13,-1,14,STAINED_GLASS:15)
B(13,-1,15,STAINED_GLASS:15)
B(14,-1,15,STAINED_GLASS:15)
B(15,-1,15,STAINED_GLASS:15)
B(13,0,13,STAINED_GLASS:15)
B(12,0,14,STAINED_GLASS:15)
B(13,0,14,STAINED_GLASS:15)
B(14,0,14,STAINED_GLASS:15)
B(15,0,14,STAINED_GLASS:15)
B(13,0,15,STAINED_GLASS:15)
B(14,0,15,STAINED_GLASS:15)
B(15,0,15,STAINED_GLASS:15)
B(14,1,12,STAINED_GLASS:15)
B(13,1,13,STAINED_GLASS:11)
B(14,1,13,STAINED_GLASS:15)
B(15,1,13,STAINED_GLASS:15)
B(12,1,14,STAINED_GLASS:11)
B(13,1,14,STAINED_GLASS:15)
B(14,1,14,STAINED_GLASS:15)
B(15,1,14,STAINED_GLASS:15)
B(11,1,15,STAINED_GLASS:11)
B(12,1,15,STAINED_GLASS:11)
B(13,1,15,STAINED_GLASS:15)
B(14,1,15,STAINED_GLASS:11)
B(15,1,15,SEA_LANTERN)
B(14,2,11,STAINED_GLASS:15)
B(15,2,11,STAINED_GLASS:15)
B(13,2,12,STAINED_GLASS:11)
B(14,2,12,STAINED_GLASS:11)
B(15,2,12,STAINED_GLASS:15)
B(12,2,13,STAINED_GLASS:11)
B(13,2,13,STAINED_GLASS:11)
B(14,2,13,STAINED_GLASS:15)
B(15,2,13,STAINED_GLASS:15)
B(11,2,14,STAINED_GLASS:11)
B(12,2,14,STAINED_GLASS:11)
B(13,2,14,STAINED_GLASS:11)
B(14,2,14,SEA_LANTERN)
B(15,2,14,STAINED_GLASS:11)
B(11,2,15,STAINED_GLASS:11)
B(12,2,15,STAINED_GLASS:11)
B(13,2,15,STAINED_GLASS:11)
B(14,2,15,STAINED_GLASS:11)
B(15,2,15,SEA_LANTERN)
B(13,3,11,STAINED_GLASS:11)
B(14,3,11,STAINED_GLASS:11)
B(15,3,11,STAINED_GLASS:15)
B(12,3,12,STAINED_GLASS:11)
B(13,3,12,STAINED_GLASS:11)
B(14,3,12,STAINED_GLASS:11)
B(15,3,12,STAINED_GLASS:15)
B(11,3,13,STAINED_GLASS:11)
B(12,3,13,STAINED_GLASS:11)
B(13,3,13,STAINED_GLASS:11)
B(14,3,13,STAINED_GLASS:11)
B(15,3,13,STAINED_GLASS:11)
B(11,3,14,STAINED_GLASS:11)
B(12,3,14,STAINED_GLASS:11)
B(13,3,14,STAINED_GLASS:11)
B(14,3,14,SEA_LANTERN)
B(15,3,14,SEA_LANTERN)
B(11,3,15,STAINED_GLASS:11)
B(12,3,15,STAINED_GLASS:15)
B(13,3,15,STAINED_GLASS:11)
B(14,3,15,SEA_LANTERN)
B(15,3,15,SEA_LANTERN)
B(14,4,10,STAINED_GLASS:11)
B(13,4,11,STAINED_GLASS:11)
B(14,4,11,STAINED_GLASS:11)
B(15,4,11,STAINED_GLASS:15)
B(12,4,12,STAINED_GLASS:11)
B(13,4,12,STAINED_GLASS:11)
B(14,4,12,STAINED_GLASS:11)
B(15,4,12,STAINED_GLASS:15)
B(11,4,13,STAINED_GLASS:11)
B(12,4,13,STAINED_GLASS:11)
B(13,4,13,STAINED_GLASS:11)
B(14,4,13,STAINED_GLASS:11)
B(15,4,13,SEA_LANTERN)
B(10,4,14,STAINED_GLASS:15)
B(11,4,14,STAINED_GLASS:15)
B(12,4,14,STAINED_GLASS:11)
B(13,4,14,STAINED_GLASS:11)
B(14,4,14,SEA_LANTERN)
B(15,4,14,SEA_LANTERN)
B(11,4,15,STAINED_GLASS:15)
B(12,4,15,STAINED_GLASS:15)
B(13,4,15,SEA_LANTERN)
B(14,4,15,SEA_LANTERN)
B(15,4,15,SEA_LANTERN)
B(13,5,10,STAINED_GLASS:11)
B(14,5,10,STAINED_GLASS:11)
B(12,5,11,STAINED_GLASS:11)
B(13,5,11,STAINED_GLASS:11)
B(14,5,11,STAINED_GLASS:11)
B(15,5,11,STAINED_GLASS:11)
B(11,5,12,STAINED_GLASS:11)
B(12,5,12,STAINED_GLASS:11)
B(13,5,12,STAINED_GLASS:11)
B(14,5,12,STAINED_GLASS:11)
B(15,5,12,STAINED_GLASS:15)
B(10,5,13,STAINED_GLASS:15)
B(11,5,13,STAINED_GLASS:15)
B(12,5,13,STAINED_GLASS:11)
B(13,5,13,SEA_LANTERN)
B(14,5,13,STAINED_GLASS:11)
B(15,5,13,SEA_LANTERN)
B(10,5,14,STAINED_GLASS:15)
B(11,5,14,STAINED_GLASS:15)
B(12,5,14,STAINED_GLASS:11)
B(13,5,14,STAINED_GLASS:11)
B(14,5,14,SEA_LANTERN)
B(15,5,14,STAINED_GLASS:11)
B(11,5,15,STAINED_GLASS:15)
B(12,5,15,STAINED_GLASS:15)
B(13,5,15,SEA_LANTERN)
B(14,5,15,STAINED_GLASS:11)
B(15,5,15,SEA_LANTERN)
B(12,6,10,STAINED_GLASS:15)
B(13,6,10,STAINED_GLASS:11)
B(14,6,10,STAINED_GLASS:11)
B(11,6,11,STAINED_GLASS:15)
B(12,6,11,STAINED_GLASS:15)
B(13,6,11,STAINED_GLASS:15)
B(14,6,11,STAINED_GLASS:11)
B(15,6,11,STAINED_GLASS:15)
B(10,6,12,STAINED_GLASS:15)
B(11,6,12,STAINED_GLASS:15)
B(12,6,12,STAINED_GLASS:11)
B(13,6,12,STAINED_GLASS:11)
B(14,6,12,STAINED_GLASS:11)
B(15,6,12,STAINED_GLASS:11)
B(10,6,13,STAINED_GLASS:15)
B(11,6,13,STAINED_GLASS:15)
B(12,6,13,STAINED_GLASS:11)
B(13,6,13,SEA_LANTERN)
B(14,6,13,SEA_LANTERN)
B(15,6,13,STAINED_GLASS:11)
B(10,6,14,STAINED_GLASS:15)
B(11,6,14,STAINED_GLASS:15)
B(12,6,14,STAINED_GLASS:11)
B(13,6,14,SEA_LANTERN)
B(14,6,14,SEA_LANTERN)
B(15,6,14,STAINED_GLASS:11)
B(11,6,15,STAINED_GLASS:15)
B(12,6,15,STAINED_GLASS:11)
B(13,6,15,STAINED_GLASS:11)
B(14,6,15,STAINED_GLASS:11)
B(15,6,15,STAINED_GLASS:11)
B(13,7,9,STAINED_GLASS:15)
B(12,7,10,STAINED_GLASS:15)
B(13,7,10,STAINED_GLASS:15)
B(14,7,10,STAINED_GLASS:15)
B(11,7,11,STAINED_GLASS:15)
B(12,7,11,STAINED_GLASS:15)
B(13,7,11,STAINED_GLASS:15)
B(14,7,11,STAINED_GLASS:15)
B(15,7,11,STAINED_GLASS:15)
B(10,7,12,STAINED_GLASS:15)
B(11,7,12,STAINED_GLASS:15)
B(12,7,12,STAINED_GLASS:11)
B(13,7,12,STAINED_GLASS:11)
B(14,7,12,SEA_LANTERN)
B(15,7,12,STAINED_GLASS:11)
B(9,7,13,STAINED_GLASS:15)
B(10,7,13,STAINED_GLASS:15)
B(11,7,13,STAINED_GLASS:15)
B(12,7,13,STAINED_GLASS:11)
B(13,7,13,SEA_LANTERN)
B(14,7,13,SEA_LANTERN)
B(15,7,13,STAINED_GLASS:11)
B(10,7,14,STAINED_GLASS:15)
B(11,7,14,STAINED_GLASS:15)
B(12,7,14,SEA_LANTERN)
B(13,7,14,SEA_LANTERN)
B(14,7,14,SEA_LANTERN)
B(15,7,14,STAINED_GLASS:15)
B(11,7,15,STAINED_GLASS:15)
B(12,7,15,STAINED_GLASS:11)
B(13,7,15,STAINED_GLASS:11)
B(14,7,15,STAINED_GLASS:15)
B(15,7,15,STAINED_GLASS:11)
B(12,8,9,STAINED_GLASS:11)
B(13,8,9,STAINED_GLASS:11)
B(11,8,10,STAINED_GLASS:15)
B(12,8,10,STAINED_GLASS:15)
B(13,8,10,STAINED_GLASS:11)
B(14,8,10,STAINED_GLASS:15)
B(10,8,11,STAINED_GLASS:15)
B(11,8,11,STAINED_GLASS:11)
B(12,8,11,STAINED_GLASS:15)
B(13,8,11,STAINED_GLASS:11)
B(14,8,11,STAINED_GLASS:15)
B(15,8,11,STAINED_GLASS:15)
B(9,8,12,STAINED_GLASS:15)
B(10,8,12,STAINED_GLASS:15)
B(11,8,12,STAINED_GLASS:15)
B(12,8,12,SEA_LANTERN)
B(13,8,12,STAINED_GLASS:11)
B(14,8,12,SEA_LANTERN)
B(15,8,12,STAINED_GLASS:15)
B(9,8,13,STAINED_GLASS:15)
B(10,8,13,STAINED_GLASS:15)
B(11,8,13,STAINED_GLASS:11)
B(12,8,13,STAINED_GLASS:11)
B(13,8,13,SEA_LANTERN)
B(14,8,13,STAINED_GLASS:11)
B(15,8,13,STAINED_GLASS:11)
B(10,8,14,STAINED_GLASS:15)
B(11,8,14,STAINED_GLASS:15)
B(12,8,14,SEA_LANTERN)
B(13,8,14,STAINED_GLASS:11)
B(14,8,14,SEA_LANTERN)
B(15,8,14,STAINED_GLASS:15)
B(11,8,15,STAINED_GLASS:15)
B(12,8,15,STAINED_GLASS:15)
B(13,8,15,STAINED_GLASS:11)
B(14,8,15,STAINED_GLASS:11)
B(15,8,15,STAINED_GLASS:11)
B(11,9,9,STAINED_GLASS:15)
B(12,9,9,STAINED_GLASS:11)
B(13,9,9,STAINED_GLASS:11)
B(10,9,10,STAINED_GLASS:15)
B(11,9,10,STAINED_GLASS:15)
B(12,9,10,STAINED_GLASS:11)
B(13,9,10,STAINED_GLASS:11)
B(14,9,10,STAINED_GLASS:11)
B(9,9,11,STAINED_GLASS:15)
B(10,9,11,STAINED_GLASS:15)
B(11,9,11,STAINED_GLASS:11)
B(12,9,11,STAINED_GLASS:11)
B(13,9,11,STAINED_GLASS:11)
B(14,9,11,STAINED_GLASS:11)
B(15,9,11,STAINED_GLASS:15)
B(9,9,12,STAINED_GLASS:15)
B(10,9,12,STAINED_GLASS:15)
B(11,9,12,STAINED_GLASS:11)
B(12,9,12,SEA_LANTERN)
B(13,9,12,SEA_LANTERN)
B(14,9,12,SEA_LANTERN)
B(15,9,12,STAINED_GLASS:15)
B(9,9,13,STAINED_GLASS:15)
B(10,9,13,STAINED_GLASS:15)
B(11,9,13,STAINED_GLASS:11)
B(12,9,13,SEA_LANTERN)
B(13,9,13,SEA_LANTERN)
B(14,9,13,STAINED_GLASS:11)
B(15,9,13,STAINED_GLASS:15)
B(10,9,14,STAINED_GLASS:15)
B(11,9,14,STAINED_GLASS:11)
B(12,9,14,SEA_LANTERN)
B(13,9,14,STAINED_GLASS:11)
B(14,9,14,STAINED_GLASS:11)
B(15,9,14,STAINED_GLASS:15)
B(11,9,15,STAINED_GLASS:15)
B(12,9,15,STAINED_GLASS:15)
B(13,9,15,STAINED_GLASS:15)
B(14,9,15,STAINED_GLASS:11)
B(15,9,15,STAINED_GLASS:11)
B(12,10,8,STAINED_GLASS:11)
B(11,10,9,STAINED_GLASS:15)
B(12,10,9,STAINED_GLASS:11)
B(13,10,9,STAINED_GLASS:11)
B(10,10,10,STAINED_GLASS:15)
B(11,10,10,STAINED_GLASS:15)
B(12,10,10,STAINED_GLASS:11)
B(13,10,10,STAINED_GLASS:11)
B(14,10,10,STAINED_GLASS:11)
B(9,10,11,STAINED_GLASS:15)
B(10,10,11,STAINED_GLASS:15)
B(11,10,11,STAINED_GLASS:11)
B(12,10,11,STAINED_GLASS:11)
B(13,10,11,SEA_LANTERN)
B(14,10,11,STAINED_GLASS:11)
B(15,10,11,STAINED_GLASS:15)
B(8,10,12,STAINED_GLASS:15)
B(9,10,12,STAINED_GLASS:15)
B(10,10,12,STAINED_GLASS:15)
B(11,10,12,STAINED_GLASS:11)
B(12,10,12,SEA_LANTERN)
B(13,10,12,SEA_LANTERN)
B(14,10,12,STAINED_GLASS:11)
B(15,10,12,STAINED_GLASS:15)
B(9,10,13,STAINED_GLASS:15)
B(10,10,13,STAINED_GLASS:15)
B(11,10,13,SEA_LANTERN)
B(12,10,13,SEA_LANTERN)
B(13,10,13,SEA_LANTERN)
B(14,10,13,STAINED_GLASS:15)
B(15,10,13,STAINED_GLASS:15)
B(10,10,14,STAINED_GLASS:15)
B(11,10,14,STAINED_GLASS:11)
B(12,10,14,STAINED_GLASS:11)
B(13,10,14,STAINED_GLASS:15)
B(14,10,14,STAINED_GLASS:11)
B(15,10,14,STAINED_GLASS:15)
B(11,10,15,STAINED_GLASS:15)
B(12,10,15,STAINED_GLASS:15)
B(13,10,15,STAINED_GLASS:11)
B(14,10,15,STAINED_GLASS:11)
B(15,10,15,STAINED_GLASS:11)
B(11,11,8,STAINED_GLASS:15)
B(12,11,8,STAINED_GLASS:11)
B(10,11,9,STAINED_GLASS:15)
B(11,11,9,STAINED_GLASS:15)
B(12,11,9,STAINED_GLASS:11)
B(13,11,9,STAINED_GLASS:11)
B(9,11,10,STAINED_GLASS:15)
B(10,11,10,STAINED_GLASS:15)
B(11,11,10,STAINED_GLASS:15)
B(12,11,10,STAINED_GLASS:11)
B(13,11,10,STAINED_GLASS:11)
B(14,11,10,STAINED_GLASS:11)
B(8,11,11,STAINED_GLASS:15)
B(9,11,11,STAINED_GLASS:15)
B(10,11,11,STAINED_GLASS:15)
B(11,11,11,SEA_LANTERN)
B(12,11,11,STAINED_GLASS:11)
B(13,11,11,SEA_LANTERN)
B(14,11,11,STAINED_GLASS:15)
B(15,11,11,STAINED_GLASS:15)
B(8,11,12,STAINED_GLASS:15)
B(9,11,12,STAINED_GLASS:15)
B(10,11,12,STAINED_GLASS:11)
B(11,11,12,STAINED_GLASS:11)
B(12,11,12,SEA_LANTERN)
B(13,11,12,STAINED_GLASS:11)
B(14,11,12,STAINED_GLASS:11)
B(15,11,12,STAINED_GLASS:15)
B(9,11,13,STAINED_GLASS:15)
B(10,11,13,STAINED_GLASS:15)
B(11,11,13,SEA_LANTERN)
B(12,11,13,STAINED_GLASS:11)
B(13,11,13,SEA_LANTERN)
B(14,11,13,STAINED_GLASS:15)
B(15,11,13,STAINED_GLASS:15)
B(10,11,14,STAINED_GLASS:15)
B(11,11,14,STAINED_GLASS:15)
B(12,11,14,STAINED_GLASS:11)
B(13,11,14,STAINED_GLASS:11)
B(14,11,14,STAINED_GLASS:15)
B(15,11,14,STAINED_GLASS:15)
B(11,11,15,STAINED_GLASS:15)
B(12,11,15,STAINED_GLASS:11)
B(13,11,15,STAINED_GLASS:11)
B(14,11,15,STAINED_GLASS:11)
B(10,12,8,STAINED_GLASS:15)
B(11,12,8,STAINED_GLASS:15)
B(12,12,8,STAINED_GLASS:11)
B(9,12,9,STAINED_GLASS:15)
B(10,12,9,STAINED_GLASS:15)
B(11,12,9,STAINED_GLASS:15)
B(12,12,9,STAINED_GLASS:11)
B(13,12,9,STAINED_GLASS:11)
B(8,12,10,STAINED_GLASS:15)
B(9,12,10,STAINED_GLASS:15)
B(10,12,10,STAINED_GLASS:11)
B(11,12,10,STAINED_GLASS:11)
B(12,12,10,STAINED_GLASS:11)
B(13,12,10,STAINED_GLASS:11)
B(14,12,10,STAINED_GLASS:11)
B(8,12,11,STAINED_GLASS:15)
B(9,12,11,STAINED_GLASS:15)
B(10,12,11,STAINED_GLASS:11)
B(11,12,11,SEA_LANTERN)
B(12,12,11,SEA_LANTERN)
B(13,12,11,SEA_LANTERN)
B(14,12,11,STAINED_GLASS:15)
B(15,12,11,STAINED_GLASS:15)
B(8,12,12,STAINED_GLASS:15)
B(9,12,12,STAINED_GLASS:15)
B(10,12,12,STAINED_GLASS:11)
B(11,12,12,SEA_LANTERN)
B(12,12,12,SEA_LANTERN)
B(13,12,12,STAINED_GLASS:11)
B(14,12,12,STAINED_GLASS:15)
B(15,12,12,STAINED_GLASS:15)
B(9,12,13,STAINED_GLASS:15)
B(10,12,13,STAINED_GLASS:11)
B(11,12,13,SEA_LANTERN)
B(12,12,13,STAINED_GLASS:11)
B(13,12,13,STAINED_GLASS:11)
B(14,12,13,STAINED_GLASS:15)
B(15,12,13,STAINED_GLASS:15)
B(10,12,14,STAINED_GLASS:15)
B(11,12,14,STAINED_GLASS:15)
B(12,12,14,STAINED_GLASS:11)
B(13,12,14,STAINED_GLASS:11)
B(14,12,14,STAINED_GLASS:11)
B(11,12,15,STAINED_GLASS:11)
B(12,12,15,STAINED_GLASS:11)
B(13,12,15,STAINED_GLASS:11)
B(11,13,7,STAINED_GLASS:15)
B(10,13,8,STAINED_GLASS:15)
B(11,13,8,STAINED_GLASS:15)
B(12,13,8,STAINED_GLASS:15)
B(9,13,9,STAINED_GLASS:15)
B(10,13,9,STAINED_GLASS:15)
B(11,13,9,STAINED_GLASS:15)
B(12,13,9,STAINED_GLASS:11)
B(13,13,9,STAINED_GLASS:11)
B(8,13,10,STAINED_GLASS:15)
B(9,13,10,STAINED_GLASS:15)
B(10,13,10,STAINED_GLASS:11)
B(11,13,10,STAINED_GLASS:11)
B(12,13,10,SEA_LANTERN)
B(13,13,10,STAINED_GLASS:11)
B(14,13,10,STAINED_GLASS:11)
B(7,13,11,STAINED_GLASS:15)
B(8,13,11,STAINED_GLASS:15)
B(9,13,11,STAINED_GLASS:15)
B(10,13,11,STAINED_GLASS:11)
B(11,13,11,SEA_LANTERN)
B(12,13,11,SEA_LANTERN)
B(13,13,11,STAINED_GLASS:11)
B(14,13,11,STAINED_GLASS:11)
B(15,13,11,STAINED_GLASS:15)
B(8,13,12,STAINED_GLASS:15)
B(9,13,12,STAINED_GLASS:15)
B(10,13,12,SEA_LANTERN)
B(11,13,12,SEA_LANTERN)
B(12,13,12,SEA_LANTERN)
B(13,13,12,STAINED_GLASS:15)
B(14,13,12,STAINED_GLASS:15)
B(15,13,12,STAINED_GLASS:15)
B(9,13,13,STAINED_GLASS:15)
B(10,13,13,STAINED_GLASS:11)
B(11,13,13,STAINED_GLASS:11)
B(12,13,13,STAINED_GLASS:15)
B(13,13,13,STAINED_GLASS:11)
B(14,13,13,STAINED_GLASS:15)
B(15,13,13,STAINED_GLASS:15)
B(10,13,14,STAINED_GLASS:15)
B(11,13,14,STAINED_GLASS:11)
B(12,13,14,STAINED_GLASS:11)
B(13,13,14,STAINED_GLASS:11)
B(14,13,14,STAINED_GLASS:15)
B(11,13,15,STAINED_GLASS:11)
B(12,13,15,STAINED_GLASS:11)
B(13,13,15,STAINED_GLASS:11)
B(10,14,7,STAINED_GLASS:15)
B(11,14,7,STAINED_GLASS:15)
B(9,14,8,STAINED_GLASS:15)
B(10,14,8,STAINED_GLASS:15)
B(11,14,8,STAINED_GLASS:15)
B(12,14,8,STAINED_GLASS:15)
B(8,14,9,STAINED_GLASS:15)
B(9,14,9,STAINED_GLASS:15)
B(10,14,9,STAINED_GLASS:15)
B(11,14,9,STAINED_GLASS:11)
B(12,14,9,STAINED_GLASS:15)
B(13,14,9,STAINED_GLASS:11)
B(7,14,10,STAINED_GLASS:15)
B(8,14,10,STAINED_GLASS:15)
B(9,14,10,STAINED_GLASS:15)
B(10,14,10,SEA_LANTERN)
B(11,14,10,STAINED_GLASS:11)
B(12,14,10,SEA_LANTERN)
B(13,14,10,STAINED_GLASS:11)
B(14,14,10,STAINED_GLASS:11)
B(7,14,11,STAINED_GLASS:15)
B(8,14,11,STAINED_GLASS:15)
B(9,14,11,STAINED_GLASS:11)
B(10,14,11,STAINED_GLASS:11)
B(11,14,11,SEA_LANTERN)
B(12,14,11,STAINED_GLASS:11)
B(13,14,11,STAINED_GLASS:11)
B(14,14,11,STAINED_GLASS:11)
B(15,14,11,STAINED_GLASS:11)
B(8,14,12,STAINED_GLASS:15)
B(9,14,12,STAINED_GLASS:15)
B(10,14,12,SEA_LANTERN)
B(11,14,12,STAINED_GLASS:11)
B(12,14,12,SEA_LANTERN)
B(13,14,12,STAINED_GLASS:15)
B(14,14,12,STAINED_GLASS:15)
B(15,14,12,STAINED_GLASS:15)
B(9,14,13,STAINED_GLASS:15)
B(10,14,13,STAINED_GLASS:15)
B(11,14,13,STAINED_GLASS:11)
B(12,14,13,STAINED_GLASS:15)
B(13,14,13,STAINED_GLASS:15)
B(14,14,13,STAINED_GLASS:15)
B(10,14,14,STAINED_GLASS:15)
B(11,14,14,STAINED_GLASS:15)
B(12,14,14,STAINED_GLASS:11)
B(13,14,14,STAINED_GLASS:15)
B(11,14,15,STAINED_GLASS:11)
B(12,14,15,STAINED_GLASS:11)
B(9,15,7,STAINED_GLASS:15)
B(10,15,7,STAINED_GLASS:15)
B(11,15,7,STAINED_GLASS:15)
B(8,15,8,STAINED_GLASS:15)
B(9,15,8,STAINED_GLASS:15)
B(10,15,8,STAINED_GLASS:15)
B(11,15,8,STAINED_GLASS:11)
B(12,15,8,STAINED_GLASS:11)
B(7,15,9,STAINED_GLASS:15)
B(8,15,9,STAINED_GLASS:15)
B(9,15,9,STAINED_GLASS:11)
B(10,15,9,STAINED_GLASS:11)
B(11,15,9,STAINED_GLASS:11)
B(12,15,9,STAINED_GLASS:11)
B(13,15,9,STAINED_GLASS:15)
B(7,15,10,STAINED_GLASS:15)
B(8,15,10,STAINED_GLASS:15)
B(9,15,10,STAINED_GLASS:11)
B(10,15,10,SEA_LANTERN)
B(11,15,10,SEA_LANTERN)
B(12,15,10,SEA_LANTERN)
B(13,15,10,STAINED_GLASS:11)
B(14,15,10,STAINED_GLASS:11)
B(7,15,11,STAINED_GLASS:15)
B(8,15,11,STAINED_GLASS:11)
B(9,15,11,STAINED_GLASS:11)
B(10,15,11,SEA_LANTERN)
B(11,15,11,SEA_LANTERN)
B(12,15,11,STAINED_GLASS:11)
B(13,15,11,STAINED_GLASS:15)
B(14,15,11,STAINED_GLASS:11)
B(15,15,11,STAINED_GLASS:15)
B(8,15,12,STAINED_GLASS:11)
B(9,15,12,STAINED_GLASS:11)
B(10,15,12,SEA_LANTERN)
B(11,15,12,STAINED_GLASS:11)
B(12,15,12,STAINED_GLASS:11)
B(13,15,12,STAINED_GLASS:15)
B(14,15,12,STAINED_GLASS:15)
B(9,15,13,STAINED_GLASS:15)
B(10,15,13,STAINED_GLASS:11)
B(11,15,13,STAINED_GLASS:15)
B(12,15,13,STAINED_GLASS:15)
B(13,15,13,STAINED_GLASS:15)
B(10,15,14,STAINED_GLASS:11)
B(11,15,14,STAINED_GLASS:11)
B(12,15,14,STAINED_GLASS:15)
B(11,15,15,STAINED_GLASS:15)
B(10,16,6,STAINED_GLASS:15)
B(9,16,7,STAINED_GLASS:15)
B(10,16,7,STAINED_GLASS:15)
B(11,16,7,STAINED_GLASS:11)
B(8,16,8,STAINED_GLASS:15)
B(9,16,8,STAINED_GLASS:15)
B(10,16,8,STAINED_GLASS:15)
B(11,16,8,STAINED_GLASS:11)
B(12,16,8,STAINED_GLASS:11)
B(7,16,9,STAINED_GLASS:15)
B(8,16,9,STAINED_GLASS:15)
B(9,16,9,STAINED_GLASS:11)
B(10,16,9,STAINED_GLASS:11)
B(11,16,9,SEA_LANTERN)
B(12,16,9,STAINED_GLASS:11)
B(13,16,9,STAINED_GLASS:11)
B(6,16,10,STAINED_GLASS:15)
B(7,16,10,STAINED_GLASS:15)
B(8,16,10,STAINED_GLASS:15)
B(9,16,10,STAINED_GLASS:11)
B(10,16,10,SEA_LANTERN)
B(11,16,10,SEA_LANTERN)
B(12,16,10,STAINED_GLASS:11)
B(13,16,10,STAINED_GLASS:15)
B(14,16,10,STAINED_GLASS:15)
B(7,16,11,STAINED_GLASS:11)
B(8,16,11,STAINED_GLASS:11)
B(9,16,11,SEA_LANTERN)
B(10,16,11,SEA_LANTERN)
B(11,16,11,SEA_LANTERN)
B(12,16,11,STAINED_GLASS:15)
B(13,16,11,STAINED_GLASS:15)
B(14,16,11,STAINED_GLASS:15)
B(8,16,12,STAINED_GLASS:11)
B(9,16,12,STAINED_GLASS:11)
B(10,16,12,STAINED_GLASS:11)
B(11,16,12,STAINED_GLASS:15)
B(12,16,12,STAINED_GLASS:11)
B(13,16,12,STAINED_GLASS:15)
B(14,16,12,STAINED_GLASS:15)
B(9,16,13,STAINED_GLASS:11)
B(10,16,13,STAINED_GLASS:11)
B(11,16,13,STAINED_GLASS:11)
B(12,16,13,STAINED_GLASS:15)
B(13,16,13,STAINED_GLASS:15)
B(10,16,14,STAINED_GLASS:11)
B(11,16,14,STAINED_GLASS:11)
B(12,16,14,STAINED_GLASS:15)
B(9,17,6,STAINED_GLASS:15)
B(10,17,6,STAINED_GLASS:15)
B(8,17,7,STAINED_GLASS:15)
B(9,17,7,STAINED_GLASS:15)
B(10,17,7,STAINED_GLASS:15)
B(11,17,7,STAINED_GLASS:11)
B(7,17,8,STAINED_GLASS:15)
B(8,17,8,STAINED_GLASS:15)
B(9,17,8,STAINED_GLASS:15)
B(10,17,8,STAINED_GLASS:11)
B(11,17,8,STAINED_GLASS:11)
B(12,17,8,STAINED_GLASS:11)
B(6,17,9,STAINED_GLASS:15)
B(7,17,9,STAINED_GLASS:15)
B(8,17,9,STAINED_GLASS:15)
B(9,17,9,SEA_LANTERN)
B(10,17,9,STAINED_GLASS:11)
B(11,17,9,SEA_LANTERN)
B(12,17,9,STAINED_GLASS:11)
B(13,17,9,STAINED_GLASS:11)
B(6,17,10,STAINED_GLASS:15)
B(7,17,10,STAINED_GLASS:15)
B(8,17,10,STAINED_GLASS:11)
B(9,17,10,STAINED_GLASS:11)
B(10,17,10,SEA_LANTERN)
B(11,17,10,STAINED_GLASS:11)
B(12,17,10,STAINED_GLASS:11)
B(13,17,10,STAINED_GLASS:15)
B(14,17,10,STAINED_GLASS:15)
B(7,17,11,STAINED_GLASS:15)
B(8,17,11,STAINED_GLASS:11)
B(9,17,11,SEA_LANTERN)
B(10,17,11,STAINED_GLASS:11)
B(11,17,11,SEA_LANTERN)
B(12,17,11,STAINED_GLASS:15)
B(13,17,11,STAINED_GLASS:15)
B(14,17,11,STAINED_GLASS:15)
B(8,17,12,STAINED_GLASS:11)
B(9,17,12,STAINED_GLASS:11)
B(10,17,12,STAINED_GLASS:11)
B(11,17,12,STAINED_GLASS:15)
B(12,17,12,STAINED_GLASS:15)
B(13,17,12,STAINED_GLASS:15)
B(9,17,13,STAINED_GLASS:15)
B(10,17,13,STAINED_GLASS:11)
B(11,17,13,STAINED_GLASS:15)
B(12,17,13,STAINED_GLASS:15)
B(10,17,14,STAINED_GLASS:11)
B(11,17,14,STAINED_GLASS:11)
B(8,18,6,STAINED_GLASS:15)
B(9,18,6,STAINED_GLASS:15)
B(10,18,6,STAINED_GLASS:15)
B(7,18,7,STAINED_GLASS:15)
B(8,18,7,STAINED_GLASS:15)
B(9,18,7,STAINED_GLASS:15)
B(10,18,7,STAINED_GLASS:15)
B(11,18,7,STAINED_GLASS:15)
B(6,18,8,STAINED_GLASS:15)
B(7,18,8,STAINED_GLASS:15)
B(8,18,8,STAINED_GLASS:11)
B(9,18,8,STAINED_GLASS:11)
B(10,18,8,STAINED_GLASS:11)
B(11,18,8,STAINED_GLASS:11)
B(12,18,8,STAINED_GLASS:11)
B(6,18,9,STAINED_GLASS:15)
B(7,18,9,STAINED_GLASS:15)
B(8,18,9,STAINED_GLASS:11)
B(9,18,9,SEA_LANTERN)
B(10,18,9,SEA_LANTERN)
B(11,18,9,SEA_LANTERN)
B(12,18,9,STAINED_GLASS:11)
B(13,18,9,STAINED_GLASS:15)
B(6,18,10,STAINED_GLASS:15)
B(7,18,10,STAINED_GLASS:15)
B(8,18,10,STAINED_GLASS:11)
B(9,18,10,SEA_LANTERN)
B(10,18,10,SEA_LANTERN)
B(11,18,10,STAINED_GLASS:11)
B(12,18,10,STAINED_GLASS:15)
B(13,18,10,STAINED_GLASS:11)
B(14,18,10,STAINED_GLASS:15)
B(7,18,11,STAINED_GLASS:15)
B(8,18,11,STAINED_GLASS:11)
B(9,18,11,SEA_LANTERN)
B(10,18,11,STAINED_GLASS:11)
B(11,18,11,STAINED_GLASS:11)
B(12,18,11,STAINED_GLASS:11)
B(13,18,11,STAINED_GLASS:11)
B(8,18,12,STAINED_GLASS:15)
B(9,18,12,STAINED_GLASS:15)
B(10,18,12,STAINED_GLASS:15)
B(11,18,12,STAINED_GLASS:15)
B(12,18,12,STAINED_GLASS:15)
B(9,18,13,STAINED_GLASS:15)
B(10,18,13,STAINED_GLASS:15)
B(11,18,13,STAINED_GLASS:15)
B(10,18,14,STAINED_GLASS:15)
B(9,19,5,STAINED_GLASS:15)
B(8,19,6,STAINED_GLASS:15)
B(9,19,6,STAINED_GLASS:15)
B(10,19,6,STAINED_GLASS:15)
B(7,19,7,STAINED_GLASS:15)
B(8,19,7,STAINED_GLASS:15)
B(9,19,7,STAINED_GLASS:15)
B(10,19,7,STAINED_GLASS:15)
B(11,19,7,STAINED_GLASS:15)
B(6,19,8,STAINED_GLASS:15)
B(7,19,8,STAINED_GLASS:15)
B(8,19,8,STAINED_GLASS:11)
B(9,19,8,STAINED_GLASS:11)
B(10,19,8,SEA_LANTERN)
B(11,19,8,STAINED_GLASS:11)
B(12,19,8,STAINED_GLASS:11)
B(5,19,9,STAINED_GLASS:15)
B(6,19,9,STAINED_GLASS:15)
B(7,19,9,STAINED_GLASS:15)
B(8,19,9,STAINED_GLASS:11)
B(9,19,9,SEA_LANTERN)
B(10,19,9,SEA_LANTERN)
B(11,19,9,STAINED_GLASS:11)
B(12,19,9,STAINED_GLASS:11)
B(13,19,9,STAINED_GLASS:11)
B(6,19,10,STAINED_GLASS:15)
B(7,19,10,STAINED_GLASS:11)
B(8,19,10,SEA_LANTERN)
B(9,19,10,SEA_LANTERN)
B(10,19,10,SEA_LANTERN)
B(11,19,10,STAINED_GLASS:15)
B(12,19,10,STAINED_GLASS:11)
B(13,19,10,STAINED_GLASS:11)
B(7,19,11,STAINED_GLASS:11)
B(8,19,11,STAINED_GLASS:11)
B(9,19,11,STAINED_GLASS:11)
B(10,19,11,STAINED_GLASS:15)
B(11,19,11,STAINED_GLASS:11)
B(12,19,11,STAINED_GLASS:11)
B(13,19,11,STAINED_GLASS:11)
B(8,19,12,STAINED_GLASS:11)
B(9,19,12,STAINED_GLASS:11)
B(10,19,12,STAINED_GLASS:15)
B(11,19,12,STAINED_GLASS:15)
B(12,19,12,STAINED_GLASS:11)
B(9,19,13,STAINED_GLASS:15)
B(10,19,13,STAINED_GLASS:15)
B(11,19,13,STAINED_GLASS:15)
B(8,20,5,STAINED_GLASS:15)
B(9,20,5,STAINED_GLASS:15)
B(7,20,6,STAINED_GLASS:15)
B(8,20,6,STAINED_GLASS:15)
B(9,20,6,STAINED_GLASS:15)
B(10,20,6,STAINED_GLASS:15)
B(6,20,7,STAINED_GLASS:15)
B(7,20,7,STAINED_GLASS:15)
B(8,20,7,STAINED_GLASS:15)
B(9,20,7,STAINED_GLASS:11)
B(10,20,7,STAINED_GLASS:15)
B(11,20,7,STAINED_GLASS:11)
B(5,20,8,STAINED_GLASS:11)
B(6,20,8,STAINED_GLASS:15)
B(7,20,8,STAINED_GLASS:15)
B(8,20,8,SEA_LANTERN)
B(9,20,8,STAINED_GLASS:11)
B(10,20,8,SEA_LANTERN)
B(11,20,8,STAINED_GLASS:11)
B(12,20,8,STAINED_GLASS:11)
B(5,20,9,STAINED_GLASS:11)
B(6,20,9,STAINED_GLASS:11)
B(7,20,9,STAINED_GLASS:11)
B(8,20,9,STAINED_GLASS:11)
B(9,20,9,SEA_LANTERN)
B(10,20,9,STAINED_GLASS:11)
B(11,20,9,STAINED_GLASS:11)
B(12,20,9,STAINED_GLASS:11)
B(13,20,9,STAINED_GLASS:11)
B(6,20,10,STAINED_GLASS:11)
B(7,20,10,STAINED_GLASS:11)
B(8,20,10,SEA_LANTERN)
B(9,20,10,STAINED_GLASS:11)
B(10,20,10,SEA_LANTERN)
B(11,20,10,STAINED_GLASS:15)
B(12,20,10,STAINED_GLASS:11)
B(13,20,10,STAINED_GLASS:11)
B(7,20,11,STAINED_GLASS:11)
B(8,20,11,STAINED_GLASS:11)
B(9,20,11,STAINED_GLASS:11)
B(10,20,11,STAINED_GLASS:15)
B(11,20,11,STAINED_GLASS:15)
B(12,20,11,STAINED_GLASS:11)
B(8,20,12,STAINED_GLASS:11)
B(9,20,12,STAINED_GLASS:11)
B(10,20,12,STAINED_GLASS:15)
B(11,20,12,STAINED_GLASS:15)
B(9,20,13,STAINED_GLASS:11)
B(10,20,13,STAINED_GLASS:15)
B(7,21,5,STAINED_GLASS:15)
B(8,21,5,STAINED_GLASS:15)
B(9,21,5,STAINED_GLASS:15)
B(6,21,6,STAINED_GLASS:15)
B(7,21,6,STAINED_GLASS:15)
B(8,21,6,STAINED_GLASS:15)
B(9,21,6,STAINED_GLASS:15)
B(10,21,6,STAINED_GLASS:15)
B(5,21,7,STAINED_GLASS:11)
B(6,21,7,STAINED_GLASS:11)
B(7,21,7,STAINED_GLASS:11)
B(8,21,7,STAINED_GLASS:11)
B(9,21,7,STAINED_GLASS:11)
B(10,21,7,STAINED_GLASS:11)
B(11,21,7,STAINED_GLASS:15)
B(5,21,8,STAINED_GLASS:11)
B(6,21,8,STAINED_GLASS:11)
B(7,21,8,STAINED_GLASS:11)
B(8,21,8,SEA_LANTERN)
B(9,21,8,SEA_LANTERN)
B(10,21,8,SEA_LANTERN)
B(11,21,8,STAINED_GLASS:11)
B(12,21,8,STAINED_GLASS:11)
B(5,21,9,STAINED_GLASS:11)
B(6,21,9,STAINED_GLASS:11)
B(7,21,9,STAINED_GLASS:11)
B(8,21,9,SEA_LANTERN)
B(9,21,9,SEA_LANTERN)
B(10,21,9,STAINED_GLASS:11)
B(11,21,9,STAINED_GLASS:15)
B(12,21,9,STAINED_GLASS:11)
B(13,21,9,STAINED_GLASS:11)
B(6,21,10,STAINED_GLASS:11)
B(7,21,10,STAINED_GLASS:11)
B(8,21,10,SEA_LANTERN)
B(9,21,10,STAINED_GLASS:11)
B(10,21,10,STAINED_GLASS:11)
B(11,21,10,STAINED_GLASS:15)
B(12,21,10,STAINED_GLASS:11)
B(7,21,11,STAINED_GLASS:11)
B(8,21,11,STAINED_GLASS:11)
B(9,21,11,STAINED_GLASS:15)
B(10,21,11,STAINED_GLASS:15)
B(11,21,11,STAINED_GLASS:15)
B(8,21,12,STAINED_GLASS:11)
B(9,21,12,STAINED_GLASS:11)
B(10,21,12,STAINED_GLASS:15)
B(9,21,13,STAINED_GLASS:15)
B(8,22,4,STAINED_GLASS:15)
B(7,22,5,STAINED_GLASS:15)
B(8,22,5,STAINED_GLASS:15)
B(9,22,5,STAINED_GLASS:15)
B(6,22,6,STAINED_GLASS:11)
B(7,22,6,STAINED_GLASS:15)
B(8,22,6,STAINED_GLASS:15)
B(9,22,6,STAINED_GLASS:15)
B(10,22,6,STAINED_GLASS:15)
B(5,22,7,STAINED_GLASS:11)
B(6,22,7,STAINED_GLASS:11)
B(7,22,7,STAINED_GLASS:11)
B(8,22,7,STAINED_GLASS:11)
B(9,22,7,SEA_LANTERN)
B(10,22,7,STAINED_GLASS:11)
B(11,22,7,STAINED_GLASS:15)
B(4,22,8,STAINED_GLASS:11)
B(5,22,8,STAINED_GLASS:11)
B(6,22,8,STAINED_GLASS:11)
B(7,22,8,STAINED_GLASS:11)
B(8,22,8,SEA_LANTERN)
B(9,22,8,SEA_LANTERN)
B(10,22,8,STAINED_GLASS:11)
B(11,22,8,STAINED_GLASS:15)
B(12,22,8,STAINED_GLASS:11)
B(5,22,9,STAINED_GLASS:11)
B(6,22,9,STAINED_GLASS:11)
B(7,22,9,SEA_LANTERN)
B(8,22,9,SEA_LANTERN)
B(9,22,9,SEA_LANTERN)
B(10,22,9,STAINED_GLASS:15)
B(11,22,9,STAINED_GLASS:11)
B(12,22,9,STAINED_GLASS:11)
B(6,22,10,STAINED_GLASS:15)
B(7,22,10,STAINED_GLASS:11)
B(8,22,10,STAINED_GLASS:11)
B(9,22,10,STAINED_GLASS:15)
B(10,22,10,STAINED_GLASS:11)
B(11,22,10,STAINED_GLASS:11)
B(12,22,10,STAINED_GLASS:11)
B(7,22,11,STAINED_GLASS:11)
B(8,22,11,STAINED_GLASS:11)
B(9,22,11,STAINED_GLASS:15)
B(10,22,11,STAINED_GLASS:15)
B(11,22,11,STAINED_GLASS:11)
B(8,22,12,STAINED_GLASS:15)
B(9,22,12,STAINED_GLASS:15)
B(10,22,12,STAINED_GLASS:15)
B(7,23,4,STAINED_GLASS:15)
B(8,23,4,STAINED_GLASS:15)
B(6,23,5,STAINED_GLASS:11)
B(7,23,5,STAINED_GLASS:15)
B(8,23,5,STAINED_GLASS:15)
B(9,23,5,STAINED_GLASS:15)
B(5,23,6,STAINED_GLASS:11)
B(6,23,6,STAINED_GLASS:11)
B(7,23,6,STAINED_GLASS:15)
B(8,23,6,STAINED_GLASS:11)
B(9,23,6,STAINED_GLASS:15)
B(10,23,6,STAINED_GLASS:15)
B(4,23,7,STAINED_GLASS:11)
B(5,23,7,STAINED_GLASS:11)
B(6,23,7,STAINED_GLASS:11)
B(7,23,7,SEA_LANTERN)
B(8,23,7,STAINED_GLASS:11)
B(9,23,7,SEA_LANTERN)
B(10,23,7,STAINED_GLASS:15)
B(11,23,7,STAINED_GLASS:15)
B(4,23,8,STAINED_GLASS:15)
B(5,23,8,STAINED_GLASS:11)
B(6,23,8,STAINED_GLASS:11)
B(7,23,8,STAINED_GLASS:11)
B(8,23,8,SEA_LANTERN)
B(9,23,8,STAINED_GLASS:11)
B(10,23,8,STAINED_GLASS:11)
B(11,23,8,STAINED_GLASS:11)
B(12,23,8,STAINED_GLASS:11)
B(5,23,9,STAINED_GLASS:15)
B(6,23,9,STAINED_GLASS:15)
B(7,23,9,SEA_LANTERN)
B(8,23,9,STAINED_GLASS:11)
B(9,23,9,SEA_LANTERN)
B(10,23,9,STAINED_GLASS:11)
B(11,23,9,STAINED_GLASS:11)
B(12,23,9,STAINED_GLASS:11)
B(6,23,10,STAINED_GLASS:15)
B(7,23,10,STAINED_GLASS:15)
B(8,23,10,STAINED_GLASS:11)
B(9,23,10,STAINED_GLASS:15)
B(10,23,10,STAINED_GLASS:11)
B(11,23,10,STAINED_GLASS:11)
B(7,23,11,STAINED_GLASS:15)
B(8,23,11,STAINED_GLASS:15)
B(9,23,11,STAINED_GLASS:15)
B(10,23,11,STAINED_GLASS:11)
B(8,23,12,STAINED_GLASS:15)
B(9,23,12,STAINED_GLASS:15)
B(6,24,4,STAINED_GLASS:15)
B(7,24,4,STAINED_GLASS:15)
B(8,24,4,STAINED_GLASS:15)
B(5,24,5,STAINED_GLASS:11)
B(6,24,5,STAINED_GLASS:11)
B(7,24,5,STAINED_GLASS:15)
B(8,24,5,STAINED_GLASS:15)
B(9,24,5,STAINED_GLASS:15)
B(4,24,6,STAINED_GLASS:11)
B(5,24,6,STAINED_GLASS:11)
B(6,24,6,STAINED_GLASS:11)
B(7,24,6,STAINED_GLASS:11)
B(8,24,6,STAINED_GLASS:11)
B(9,24,6,STAINED_GLASS:11)
B(10,24,6,STAINED_GLASS:15)
B(4,24,7,STAINED_GLASS:11)
B(5,24,7,STAINED_GLASS:11)
B(6,24,7,STAINED_GLASS:11)
B(7,24,7,SEA_LANTERN)
B(8,24,7,SEA_LANTERN)
B(9,24,7,SEA_LANTERN)
B(10,24,7,STAINED_GLASS:15)
B(11,24,7,STAINED_GLASS:15)
B(4,24,8,STAINED_GLASS:15)
B(5,24,8,STAINED_GLASS:15)
B(6,24,8,STAINED_GLASS:11)
B(7,24,8,SEA_LANTERN)
B(8,24,8,SEA_LANTERN)
B(9,24,8,STAINED_GLASS:11)
B(10,24,8,STAINED_GLASS:15)
B(11,24,8,STAINED_GLASS:15)
B(12,24,8,STAINED_GLASS:11)
B(5,24,9,STAINED_GLASS:15)
B(6,24,9,STAINED_GLASS:11)
B(7,24,9,SEA_LANTERN)
B(8,24,9,STAINED_GLASS:11)
B(9,24,9,STAINED_GLASS:11)
B(10,24,9,STAINED_GLASS:11)
B(11,24,9,STAINED_GLASS:11)
B(6,24,10,STAINED_GLASS:15)
B(7,24,10,STAINED_GLASS:15)
B(8,24,10,STAINED_GLASS:15)
B(9,24,10,STAINED_GLASS:11)
B(10,24,10,STAINED_GLASS:11)
B(7,24,11,STAINED_GLASS:15)
B(8,24,11,STAINED_GLASS:15)
B(9,24,11,STAINED_GLASS:15)
B(8,24,12,STAINED_GLASS:15)
B(7,25,3,STAINED_GLASS:15)
B(6,25,4,STAINED_GLASS:11)
B(7,25,4,STAINED_GLASS:15)
B(8,25,4,STAINED_GLASS:15)
B(5,25,5,STAINED_GLASS:11)
B(6,25,5,STAINED_GLASS:11)
B(7,25,5,STAINED_GLASS:15)
B(8,25,5,STAINED_GLASS:15)
B(9,25,5,STAINED_GLASS:15)
B(4,25,6,STAINED_GLASS:11)
B(5,25,6,STAINED_GLASS:11)
B(6,25,6,STAINED_GLASS:11)
B(7,25,6,STAINED_GLASS:11)
B(8,25,6,SEA_LANTERN)
B(9,25,6,STAINED_GLASS:11)
B(10,25,6,STAINED_GLASS:15)
B(3,25,7,STAINED_GLASS:15)
B(4,25,7,STAINED_GLASS:11)
B(5,25,7,STAINED_GLASS:15)
B(6,25,7,STAINED_GLASS:11)
B(7,25,7,SEA_LANTERN)
B(8,25,7,SEA_LANTERN)
B(9,25,7,STAINED_GLASS:11)
B(10,25,7,STAINED_GLASS:15)
B(11,25,7,STAINED_GLASS:15)
B(4,25,8,STAINED_GLASS:15)
B(5,25,8,STAINED_GLASS:15)
B(6,25,8,SEA_LANTERN)
B(7,25,8,SEA_LANTERN)
B(8,25,8,SEA_LANTERN)
B(9,25,8,STAINED_GLASS:11)
B(10,25,8,STAINED_GLASS:15)
B(11,25,8,STAINED_GLASS:15)
B(5,25,9,STAINED_GLASS:15)
B(6,25,9,STAINED_GLASS:11)
B(7,25,9,STAINED_GLASS:11)
B(8,25,9,STAINED_GLASS:11)
B(9,25,9,STAINED_GLASS:11)
B(10,25,9,STAINED_GLASS:11)
B(11,25,9,STAINED_GLASS:11)
B(6,25,10,STAINED_GLASS:15)
B(7,25,10,STAINED_GLASS:15)
B(8,25,10,STAINED_GLASS:11)
B(9,25,10,STAINED_GLASS:11)
B(10,25,10,STAINED_GLASS:11)
B(7,25,11,STAINED_GLASS:15)
B(8,25,11,STAINED_GLASS:15)
B(9,25,11,STAINED_GLASS:11)
B(6,26,3,STAINED_GLASS:11)
B(7,26,3,STAINED_GLASS:15)
B(5,26,4,STAINED_GLASS:11)
B(6,26,4,STAINED_GLASS:11)
B(7,26,4,STAINED_GLASS:15)
B(8,26,4,STAINED_GLASS:15)
B(4,26,5,STAINED_GLASS:11)
B(5,26,5,STAINED_GLASS:11)
B(6,26,5,STAINED_GLASS:11)
B(7,26,5,STAINED_GLASS:11)
B(8,26,5,STAINED_GLASS:15)
B(9,26,5,STAINED_GLASS:15)
B(3,26,6,STAINED_GLASS:15)
B(4,26,6,STAINED_GLASS:15)
B(5,26,6,STAINED_GLASS:11)
B(6,26,6,SEA_LANTERN)
B(7,26,6,STAINED_GLASS:11)
B(8,26,6,SEA_LANTERN)
B(9,26,6,STAINED_GLASS:15)
B(10,26,6,STAINED_GLASS:15)
B(3,26,7,STAINED_GLASS:15)
B(4,26,7,STAINED_GLASS:15)
B(5,26,7,STAINED_GLASS:11)
B(6,26,7,STAINED_GLASS:11)
B(7,26,7,SEA_LANTERN)
B(8,26,7,STAINED_GLASS:11)
B(9,26,7,STAINED_GLASS:11)
B(10,26,7,STAINED_GLASS:15)
B(11,26,7,STAINED_GLASS:15)
B(4,26,8,STAINED_GLASS:15)
B(5,26,8,STAINED_GLASS:15)
B(6,26,8,SEA_LANTERN)
B(7,26,8,STAINED_GLASS:11)
B(8,26,8,SEA_LANTERN)
B(9,26,8,STAINED_GLASS:15)
B(10,26,8,STAINED_GLASS:15)
B(11,26,8,STAINED_GLASS:15)
B(5,26,9,STAINED_GLASS:15)
B(6,26,9,STAINED_GLASS:15)
B(7,26,9,STAINED_GLASS:11)
B(8,26,9,STAINED_GLASS:11)
B(9,26,9,STAINED_GLASS:11)
B(10,26,9,STAINED_GLASS:11)
B(6,26,10,STAINED_GLASS:15)
B(7,26,10,STAINED_GLASS:15)
B(8,26,10,STAINED_GLASS:11)
B(9,26,10,STAINED_GLASS:11)
B(7,26,11,STAINED_GLASS:15)
B(8,26,11,STAINED_GLASS:11)
B(5,27,3,STAINED_GLASS:11)
B(6,27,3,STAINED_GLASS:11)
B(7,27,3,STAINED_GLASS:15)
B(4,27,4,STAINED_GLASS:11)
B(5,27,4,STAINED_GLASS:11)
B(6,27,4,STAINED_GLASS:11)
B(7,27,4,STAINED_GLASS:15)
B(8,27,4,STAINED_GLASS:15)
B(3,27,5,STAINED_GLASS:15)
B(4,27,5,STAINED_GLASS:15)
B(5,27,5,STAINED_GLASS:11)
B(6,27,5,STAINED_GLASS:15)
B(7,27,5,STAINED_GLASS:11)
B(8,27,5,STAINED_GLASS:11)
B(9,27,5,STAINED_GLASS:15)
B(3,27,6,STAINED_GLASS:15)
B(4,27,6,STAINED_GLASS:15)
B(5,27,6,STAINED_GLASS:15)
B(6,27,6,SEA_LANTERN)
B(7,27,6,SEA_LANTERN)
B(8,27,6,SEA_LANTERN)
B(9,27,6,STAINED_GLASS:15)
B(10,27,6,STAINED_GLASS:15)
B(3,27,7,STAINED_GLASS:15)
B(4,27,7,STAINED_GLASS:15)
B(5,27,7,STAINED_GLASS:11)
B(6,27,7,SEA_LANTERN)
B(7,27,7,SEA_LANTERN)
B(8,27,7,STAINED_GLASS:11)
B(9,27,7,STAINED_GLASS:15)
B(10,27,7,STAINED_GLASS:15)
B(11,27,7,STAINED_GLASS:15)
B(4,27,8,STAINED_GLASS:15)
B(5,27,8,STAINED_GLASS:11)
B(6,27,8,SEA_LANTERN)
B(7,27,8,STAINED_GLASS:11)
B(8,27,8,STAINED_GLASS:11)
B(9,27,8,STAINED_GLASS:15)
B(10,27,8,STAINED_GLASS:15)
B(5,27,9,STAINED_GLASS:15)
B(6,27,9,STAINED_GLASS:15)
B(7,27,9,STAINED_GLASS:11)
B(8,27,9,STAINED_GLASS:15)
B(9,27,9,STAINED_GLASS:11)
B(6,27,10,STAINED_GLASS:11)
B(7,27,10,STAINED_GLASS:11)
B(8,27,10,STAINED_GLASS:11)
B(7,27,11,STAINED_GLASS:11)
B(6,28,2,STAINED_GLASS:11)
B(5,28,3,STAINED_GLASS:11)
B(6,28,3,STAINED_GLASS:11)
B(7,28,3,STAINED_GLASS:11)
B(4,28,4,STAINED_GLASS:15)
B(5,28,4,STAINED_GLASS:11)
B(6,28,4,STAINED_GLASS:15)
B(7,28,4,STAINED_GLASS:11)
B(8,28,4,STAINED_GLASS:15)
B(3,28,5,STAINED_GLASS:15)
B(4,28,5,STAINED_GLASS:15)
B(5,28,5,STAINED_GLASS:11)
B(6,28,5,STAINED_GLASS:11)
B(7,28,5,SEA_LANTERN)
B(8,28,5,STAINED_GLASS:11)
B(9,28,5,STAINED_GLASS:15)
B(2,28,6,STAINED_GLASS:15)
B(3,28,6,STAINED_GLASS:15)
B(4,28,6,STAINED_GLASS:15)
B(5,28,6,STAINED_GLASS:11)
B(6,28,6,SEA_LANTERN)
B(7,28,6,SEA_LANTERN)
B(8,28,6,STAINED_GLASS:11)
B(9,28,6,STAINED_GLASS:15)
B(10,28,6,STAINED_GLASS:15)
B(3,28,7,STAINED_GLASS:15)
B(4,28,7,STAINED_GLASS:15)
B(5,28,7,SEA_LANTERN)
B(6,28,7,SEA_LANTERN)
B(7,28,7,SEA_LANTERN)
B(8,28,7,STAINED_GLASS:11)
B(9,28,7,STAINED_GLASS:15)
B(10,28,7,STAINED_GLASS:15)
B(4,28,8,STAINED_GLASS:15)
B(5,28,8,STAINED_GLASS:11)
B(6,28,8,STAINED_GLASS:11)
B(7,28,8,STAINED_GLASS:11)
B(8,28,8,STAINED_GLASS:11)
B(9,28,8,STAINED_GLASS:15)
B(10,28,8,STAINED_GLASS:15)
B(5,28,9,STAINED_GLASS:15)
B(6,28,9,STAINED_GLASS:11)
B(7,28,9,STAINED_GLASS:11)
B(8,28,9,STAINED_GLASS:11)
B(9,28,9,STAINED_GLASS:15)
B(6,28,10,STAINED_GLASS:11)
B(7,28,10,STAINED_GLASS:11)
B(8,28,10,STAINED_GLASS:11)
B(5,29,2,STAINED_GLASS:11)
B(6,29,2,STAINED_GLASS:11)
B(4,29,3,STAINED_GLASS:15)
B(5,29,3,STAINED_GLASS:11)
B(6,29,3,STAINED_GLASS:11)
B(7,29,3,STAINED_GLASS:11)
B(3,29,4,STAINED_GLASS:15)
B(4,29,4,STAINED_GLASS:15)
B(5,29,4,STAINED_GLASS:15)
B(6,29,4,STAINED_GLASS:11)
B(7,29,4,STAINED_GLASS:11)
B(8,29,4,STAINED_GLASS:11)
B(2,29,5,STAINED_GLASS:15)
B(3,29,5,STAINED_GLASS:15)
B(4,29,5,STAINED_GLASS:15)
B(5,29,5,SEA_LANTERN)
B(6,29,5,STAINED_GLASS:11)
B(7,29,5,SEA_LANTERN)
B(8,29,5,STAINED_GLASS:15)
B(9,29,5,STAINED_GLASS:15)
B(2,29,6,STAINED_GLASS:15)
B(3,29,6,STAINED_GLASS:15)
B(4,29,6,STAINED_GLASS:11)
B(5,29,6,STAINED_GLASS:11)
B(6,29,6,SEA_LANTERN)
B(7,29,6,STAINED_GLASS:11)
B(8,29,6,STAINED_GLASS:11)
B(9,29,6,STAINED_GLASS:15)
B(10,29,6,STAINED_GLASS:15)
B(3,29,7,STAINED_GLASS:15)
B(4,29,7,STAINED_GLASS:11)
B(5,29,7,SEA_LANTERN)
B(6,29,7,STAINED_GLASS:11)
B(7,29,7,SEA_LANTERN)
B(8,29,7,STAINED_GLASS:15)
B(9,29,7,STAINED_GLASS:15)
B(10,29,7,STAINED_GLASS:15)
B(4,29,8,STAINED_GLASS:11)
B(5,29,8,STAINED_GLASS:11)
B(6,29,8,STAINED_GLASS:11)
B(7,29,8,STAINED_GLASS:15)
B(8,29,8,STAINED_GLASS:15)
B(9,29,8,STAINED_GLASS:15)
B(5,29,9,STAINED_GLASS:15)
B(6,29,9,STAINED_GLASS:15)
B(7,29,9,STAINED_GLASS:11)
B(8,29,9,STAINED_GLASS:15)
B(6,29,10,STAINED_GLASS:11)
B(7,29,10,STAINED_GLASS:11)
B(4,30,2,STAINED_GLASS:15)
B(5,30,2,STAINED_GLASS:11)
B(6,30,2,STAINED_GLASS:11)
B(3,30,3,STAINED_GLASS:15)
B(4,30,3,STAINED_GLASS:15)
B(5,30,3,STAINED_GLASS:15)
B(6,30,3,STAINED_GLASS:11)
B(7,30,3,STAINED_GLASS:11)
B(2,30,4,STAINED_GLASS:15)
B(3,30,4,STAINED_GLASS:15)
B(4,30,4,STAINED_GLASS:11)
B(5,30,4,STAINED_GLASS:15)
B(6,30,4,STAINED_GLASS:11)
B(7,30,4,STAINED_GLASS:11)
B(8,30,4,STAINED_GLASS:15)
B(2,30,5,STAINED_GLASS:15)
B(3,30,5,STAINED_GLASS:15)
B(4,30,5,STAINED_GLASS:15)
B(5,30,5,SEA_LANTERN)
B(6,30,5,SEA_LANTERN)
B(7,30,5,SEA_LANTERN)
B(8,30,5,STAINED_GLASS:15)
B(9,30,5,STAINED_GLASS:15)
B(2,30,6,STAINED_GLASS:15)
B(3,30,6,STAINED_GLASS:15)
B(4,30,6,STAINED_GLASS:11)
B(5,30,6,SEA_LANTERN)
B(6,30,6,SEA_LANTERN)
B(7,30,6,STAINED_GLASS:11)
B(8,30,6,STAINED_GLASS:15)
B(9,30,6,STAINED_GLASS:15)
B(10,30,6,STAINED_GLASS:15)
B(3,30,7,STAINED_GLASS:11)
B(4,30,7,STAINED_GLASS:11)
B(5,30,7,SEA_LANTERN)
B(6,30,7,STAINED_GLASS:11)
B(7,30,7,STAINED_GLASS:11)
B(8,30,7,STAINED_GLASS:15)
B(9,30,7,STAINED_GLASS:15)
B(4,30,8,STAINED_GLASS:11)
B(5,30,8,STAINED_GLASS:11)
B(6,30,8,STAINED_GLASS:15)
B(7,30,8,STAINED_GLASS:15)
B(8,30,8,STAINED_GLASS:15)
B(5,30,9,STAINED_GLASS:11)
B(6,30,9,STAINED_GLASS:15)
B(7,30,9,STAINED_GLASS:15)
B(6,30,10,STAINED_GLASS:15)
B(5,31,1,STAINED_GLASS:15)
B(4,31,2,STAINED_GLASS:15)
B(5,31,2,STAINED_GLASS:15)
B(6,31,2,STAINED_GLASS:11)
B(3,31,3,STAINED_GLASS:15)
B(4,31,3,STAINED_GLASS:15)
B(5,31,3,STAINED_GLASS:15)
B(6,31,3,STAINED_GLASS:11)
B(7,31,3,STAINED_GLASS:11)
B(2,31,4,STAINED_GLASS:15)
B(3,31,4,STAINED_GLASS:15)
B(4,31,4,STAINED_GLASS:11)
B(5,31,4,STAINED_GLASS:11)
B(6,31,4,SEA_LANTERN)
B(7,31,4,STAINED_GLASS:11)
B(8,31,4,STAINED_GLASS:11)
B(1,31,5,STAINED_GLASS:15)
B(2,31,5,STAINED_GLASS:15)
B(3,31,5,STAINED_GLASS:15)
B(4,31,5,STAINED_GLASS:11)
B(5,31,5,SEA_LANTERN)
B(6,31,5,SEA_LANTERN)
B(7,31,5,STAINED_GLASS:11)
B(8,31,5,STAINED_GLASS:15)
B(9,31,5,STAINED_GLASS:15)
B(2,31,6,STAINED_GLASS:15)
B(3,31,6,STAINED_GLASS:15)
B(4,31,6,SEA_LANTERN)
B(5,31,6,SEA_LANTERN)
B(6,31,6,SEA_LANTERN)
B(7,31,6,STAINED_GLASS:11)
B(8,31,6,STAINED_GLASS:15)
B(9,31,6,STAINED_GLASS:15)
B(3,31,7,STAINED_GLASS:15)
B(4,31,7,STAINED_GLASS:11)
B(5,31,7,STAINED_GLASS:11)
B(6,31,7,STAINED_GLASS:11)
B(7,31,7,STAINED_GLASS:11)
B(8,31,7,STAINED_GLASS:15)
B(9,31,7,STAINED_GLASS:15)
B(4,31,8,STAINED_GLASS:11)
B(5,31,8,STAINED_GLASS:11)
B(6,31,8,STAINED_GLASS:15)
B(7,31,8,STAINED_GLASS:15)
B(8,31,8,STAINED_GLASS:15)
B(5,31,9,STAINED_GLASS:11)
B(6,31,9,STAINED_GLASS:11)
B(7,31,9,STAINED_GLASS:15)
B(4,32,1,STAINED_GLASS:15)
B(5,32,1,STAINED_GLASS:15)
B(3,32,2,STAINED_GLASS:15)
B(4,32,2,STAINED_GLASS:15)
B(5,32,2,STAINED_GLASS:15)
B(6,32,2,STAINED_GLASS:15)
B(2,32,3,STAINED_GLASS:15)
B(3,32,3,STAINED_GLASS:15)
B(4,32,3,STAINED_GLASS:15)
B(5,32,3,STAINED_GLASS:11)
B(6,32,3,STAINED_GLASS:11)
B(7,32,3,STAINED_GLASS:11)
B(1,32,4,STAINED_GLASS:15)
B(2,32,4,STAINED_GLASS:15)
B(3,32,4,STAINED_GLASS:15)
B(4,32,4,SEA_LANTERN)
B(5,32,4,STAINED_GLASS:11)
B(6,32,4,SEA_LANTERN)
B(7,32,4,STAINED_GLASS:11)
B(8,32,4,STAINED_GLASS:15)
B(1,32,5,STAINED_GLASS:15)
B(2,32,5,STAINED_GLASS:15)
B(3,32,5,STAINED_GLASS:11)
B(4,32,5,STAINED_GLASS:11)
B(5,32,5,SEA_LANTERN)
B(6,32,5,STAINED_GLASS:11)
B(7,32,5,STAINED_GLASS:11)
B(8,32,5,STAINED_GLASS:15)
B(9,32,5,STAINED_GLASS:15)
B(2,32,6,STAINED_GLASS:15)
B(3,32,6,STAINED_GLASS:15)
B(4,32,6,SEA_LANTERN)
B(5,32,6,STAINED_GLASS:11)
B(6,32,6,SEA_LANTERN)
B(7,32,6,STAINED_GLASS:15)
B(8,32,6,STAINED_GLASS:15)
B(9,32,6,STAINED_GLASS:15)
B(3,32,7,STAINED_GLASS:15)
B(4,32,7,STAINED_GLASS:11)
B(5,32,7,STAINED_GLASS:11)
B(6,32,7,STAINED_GLASS:15)
B(7,32,7,STAINED_GLASS:15)
B(8,32,7,STAINED_GLASS:15)
B(4,32,8,STAINED_GLASS:11)
B(5,32,8,STAINED_GLASS:11)
B(6,32,8,STAINED_GLASS:11)
B(7,32,8,STAINED_GLASS:15)
B(5,32,9,STAINED_GLASS:11)
B(6,32,9,STAINED_GLASS:11)
B(3,33,1,STAINED_GLASS:15)
B(4,33,1,STAINED_GLASS:15)
B(5,33,1,STAINED_GLASS:15)
B(2,33,2,STAINED_GLASS:15)
B(3,33,2,STAINED_GLASS:15)
B(4,33,2,STAINED_GLASS:15)
B(5,33,2,STAINED_GLASS:15)
B(6,33,2,STAINED_GLASS:15)
B(1,33,3,STAINED_GLASS:15)
B(2,33,3,STAINED_GLASS:15)
B(3,33,3,STAINED_GLASS:11)
B(4,33,3,STAINED_GLASS:15)
B(5,33,3,STAINED_GLASS:11)
B(6,33,3,STAINED_GLASS:11)
B(7,33,3,STAINED_GLASS:11)
B(1,33,4,STAINED_GLASS:15)
B(2,33,4,STAINED_GLASS:15)
B(3,33,4,STAINED_GLASS:15)
B(4,33,4,SEA_LANTERN)
B(5,33,4,SEA_LANTERN)
B(6,33,4,SEA_LANTERN)
B(7,33,4,STAINED_GLASS:11)
B(8,33,4,STAINED_GLASS:15)
B(1,33,5,STAINED_GLASS:15)
B(2,33,5,STAINED_GLASS:15)
B(3,33,5,STAINED_GLASS:11)
B(4,33,5,SEA_LANTERN)
B(5,33,5,SEA_LANTERN)
B(6,33,5,STAINED_GLASS:11)
B(7,33,5,STAINED_GLASS:15)
B(8,33,5,STAINED_GLASS:15)
B(9,33,5,STAINED_GLASS:15)
B(2,33,6,STAINED_GLASS:15)
B(3,33,6,STAINED_GLASS:11)
B(4,33,6,SEA_LANTERN)
B(5,33,6,STAINED_GLASS:11)
B(6,33,6,STAINED_GLASS:11)
B(7,33,6,STAINED_GLASS:15)
B(8,33,6,STAINED_GLASS:15)
B(3,33,7,STAINED_GLASS:11)
B(4,33,7,STAINED_GLASS:11)
B(5,33,7,STAINED_GLASS:11)
B(6,33,7,STAINED_GLASS:15)
B(7,33,7,STAINED_GLASS:15)
B(4,33,8,STAINED_GLASS:11)
B(5,33,8,STAINED_GLASS:11)
B(6,33,8,STAINED_GLASS:15)
B(5,33,9,STAINED_GLASS:11)
B(4,34,0,STAINED_GLASS:15)
B(3,34,1,STAINED_GLASS:15)
B(4,34,1,STAINED_GLASS:15)
B(5,34,1,STAINED_GLASS:15)
B(2,34,2,STAINED_GLASS:15)
B(3,34,2,STAINED_GLASS:15)
B(4,34,2,STAINED_GLASS:15)
B(5,34,2,STAINED_GLASS:15)
B(6,34,2,STAINED_GLASS:11)
B(1,34,3,STAINED_GLASS:15)
B(2,34,3,STAINED_GLASS:15)
B(3,34,3,STAINED_GLASS:11)
B(4,34,3,STAINED_GLASS:11)
B(5,34,3,SEA_LANTERN)
B(6,34,3,STAINED_GLASS:11)
B(7,34,3,STAINED_GLASS:11)
B(0,34,4,STAINED_GLASS:15)
B(1,34,4,STAINED_GLASS:15)
B(2,34,4,STAINED_GLASS:15)
B(3,34,4,STAINED_GLASS:11)
B(4,34,4,SEA_LANTERN)
B(5,34,4,SEA_LANTERN)
B(6,34,4,STAINED_GLASS:11)
B(7,34,4,STAINED_GLASS:11)
B(8,34,4,STAINED_GLASS:11)
B(1,34,5,STAINED_GLASS:15)
B(2,34,5,STAINED_GLASS:15)
B(3,34,5,SEA_LANTERN)
B(4,34,5,SEA_LANTERN)
B(5,34,5,SEA_LANTERN)
B(6,34,5,STAINED_GLASS:11)
B(7,34,5,STAINED_GLASS:15)
B(8,34,5,STAINED_GLASS:15)
B(2,34,6,STAINED_GLASS:15)
B(3,34,6,STAINED_GLASS:11)
B(4,34,6,STAINED_GLASS:11)
B(5,34,6,STAINED_GLASS:11)
B(6,34,6,STAINED_GLASS:11)
B(7,34,6,STAINED_GLASS:15)
B(8,34,6,STAINED_GLASS:15)
B(3,34,7,STAINED_GLASS:11)
B(4,34,7,STAINED_GLASS:11)
B(5,34,7,STAINED_GLASS:11)
B(6,34,7,STAINED_GLASS:15)
B(7,34,7,STAINED_GLASS:15)
B(4,34,8,STAINED_GLASS:11)
B(5,34,8,STAINED_GLASS:11)
B(6,34,8,STAINED_GLASS:15)
B(3,35,0,STAINED_GLASS:15)
B(4,35,0,STAINED_GLASS:15)
B(2,35,1,STAINED_GLASS:15)
B(3,35,1,STAINED_GLASS:15)
B(4,35,1,STAINED_GLASS:15)
B(5,35,1,STAINED_GLASS:15)
B(1,35,2,STAINED_GLASS:15)
B(2,35,2,STAINED_GLASS:15)
B(3,35,2,STAINED_GLASS:15)
B(4,35,2,STAINED_GLASS:11)
B(5,35,2,STAINED_GLASS:15)
B(6,35,2,STAINED_GLASS:15)
B(0,35,3,STAINED_GLASS:15)
B(1,35,3,STAINED_GLASS:15)
B(2,35,3,STAINED_GLASS:15)
B(3,35,3,SEA_LANTERN)
B(4,35,3,STAINED_GLASS:11)
B(5,35,3,SEA_LANTERN)
B(6,35,3,STAINED_GLASS:11)
B(7,35,3,STAINED_GLASS:11)
B(0,35,4,STAINED_GLASS:15)
B(1,35,4,STAINED_GLASS:11)
B(2,35,4,STAINED_GLASS:11)
B(3,35,4,STAINED_GLASS:11)
B(4,35,4,SEA_LANTERN)
B(5,35,4,STAINED_GLASS:11)
B(6,35,4,STAINED_GLASS:11)
B(7,35,4,STAINED_GLASS:11)
B(8,35,4,STAINED_GLASS:15)
B(1,35,5,STAINED_GLASS:11)
B(2,35,5,STAINED_GLASS:11)
B(3,35,5,SEA_LANTERN)
B(4,35,5,STAINED_GLASS:11)
B(5,35,5,SEA_LANTERN)
B(6,35,5,STAINED_GLASS:15)
B(7,35,5,STAINED_GLASS:15)
B(8,35,5,STAINED_GLASS:15)
B(2,35,6,STAINED_GLASS:11)
B(3,35,6,STAINED_GLASS:11)
B(4,35,6,STAINED_GLASS:11)
B(5,35,6,STAINED_GLASS:15)
B(6,35,6,STAINED_GLASS:15)
B(7,35,6,STAINED_GLASS:15)
B(3,35,7,STAINED_GLASS:11)
B(4,35,7,STAINED_GLASS:11)
B(5,35,7,STAINED_GLASS:11)
B(6,35,7,STAINED_GLASS:15)
B(4,35,8,STAINED_GLASS:11)
B(5,35,8,STAINED_GLASS:15)
B(3,36,0,STAINED_GLASS:15)
B(4,36,0,STAINED_GLASS:15)
B(2,36,1,STAINED_GLASS:15)
B(3,36,1,STAINED_GLASS:15)
B(4,36,1,STAINED_GLASS:15)
B(5,36,1,STAINED_GLASS:15)
B(1,36,2,STAINED_GLASS:15)
B(2,36,2,STAINED_GLASS:11)
B(3,36,2,STAINED_GLASS:15)
B(4,36,2,STAINED_GLASS:11)
B(5,36,2,STAINED_GLASS:11)
B(6,36,2,STAINED_GLASS:11)
B(0,36,3,STAINED_GLASS:15)
B(1,36,3,STAINED_GLASS:15)
B(2,36,3,STAINED_GLASS:15)
B(3,36,3,SEA_LANTERN)
B(4,36,3,SEA_LANTERN)
B(5,36,3,SEA_LANTERN)
B(6,36,3,STAINED_GLASS:11)
B(7,36,3,STAINED_GLASS:15)
B(0,36,4,STAINED_GLASS:11)
B(1,36,4,STAINED_GLASS:11)
B(2,36,4,STAINED_GLASS:11)
B(3,36,4,SEA_LANTERN)
B(4,36,4,SEA_LANTERN)
B(5,36,4,STAINED_GLASS:11)
B(6,36,4,STAINED_GLASS:15)
B(7,36,4,STAINED_GLASS:15)
B(8,36,4,STAINED_GLASS:15)
B(1,36,5,STAINED_GLASS:11)
B(2,36,5,STAINED_GLASS:11)
B(3,36,5,SEA_LANTERN)
B(4,36,5,STAINED_GLASS:11)
B(5,36,5,STAINED_GLASS:11)
B(6,36,5,STAINED_GLASS:15)
B(7,36,5,STAINED_GLASS:15)
B(2,36,6,STAINED_GLASS:11)
B(3,36,6,STAINED_GLASS:11)
B(4,36,6,STAINED_GLASS:15)
B(5,36,6,STAINED_GLASS:15)
B(6,36,6,STAINED_GLASS:15)
B(3,36,7,STAINED_GLASS:11)
B(4,36,7,STAINED_GLASS:11)
B(5,36,7,STAINED_GLASS:15)
B(4,36,8,STAINED_GLASS:15)
B(3,37,0,STAINED_GLASS:15)
B(2,37,1,STAINED_GLASS:15)
B(3,37,1,STAINED_GLASS:15)
B(4,37,1,STAINED_GLASS:15)
B(5,37,1,STAINED_GLASS:11)
B(1,37,2,STAINED_GLASS:15)
B(2,37,2,STAINED_GLASS:11)
B(3,37,2,STAINED_GLASS:11)
B(4,37,2,SEA_LANTERN)
B(5,37,2,STAINED_GLASS:11)
B(6,37,2,STAINED_GLASS:11)
B(0,37,3,STAINED_GLASS:15)
B(1,37,3,STAINED_GLASS:15)
B(2,37,3,STAINED_GLASS:11)
B(3,37,3,SEA_LANTERN)
B(4,37,3,SEA_LANTERN)
B(5,37,3,STAINED_GLASS:11)
B(6,37,3,STAINED_GLASS:11)
B(7,37,3,STAINED_GLASS:11)
B(1,37,4,STAINED_GLASS:11)
B(2,37,4,SEA_LANTERN)
B(3,37,4,SEA_LANTERN)
B(4,37,4,SEA_LANTERN)
B(5,37,4,STAINED_GLASS:11)
B(6,37,4,STAINED_GLASS:15)
B(7,37,4,STAINED_GLASS:15)
B(1,37,5,STAINED_GLASS:11)
B(2,37,5,STAINED_GLASS:11)
B(3,37,5,STAINED_GLASS:11)
B(4,37,5,STAINED_GLASS:11)
B(5,37,5,STAINED_GLASS:11)
B(6,37,5,STAINED_GLASS:15)
B(7,37,5,STAINED_GLASS:15)
B(2,37,6,STAINED_GLASS:11)
B(3,37,6,STAINED_GLASS:15)
B(4,37,6,STAINED_GLASS:15)
B(5,37,6,STAINED_GLASS:15)
B(6,37,6,STAINED_GLASS:15)
B(3,37,7,STAINED_GLASS:15)
B(4,37,7,STAINED_GLASS:15)
B(5,37,7,STAINED_GLASS:15)
B(2,38,0,STAINED_GLASS:15)
B(3,38,0,STAINED_GLASS:15)
B(2,38,1,STAINED_GLASS:15)
B(3,38,1,STAINED_GLASS:15)
B(4,38,1,STAINED_GLASS:11)
B(0,38,2,STAINED_GLASS:15)
B(1,38,2,STAINED_GLASS:11)
B(2,38,2,STAINED_GLASS:11)
B(3,38,2,STAINED_GLASS:15)
B(4,38,2,SEA_LANTERN)
B(5,38,2,STAINED_GLASS:11)
B(6,38,2,STAINED_GLASS:11)
B(0,38,3,STAINED_GLASS:11)
B(1,38,3,STAINED_GLASS:11)
B(2,38,3,STAINED_GLASS:11)
B(3,38,3,SEA_LANTERN)
B(4,38,3,STAINED_GLASS:11)
B(5,38,3,STAINED_GLASS:11)
B(6,38,3,STAINED_GLASS:11)
B(7,38,3,STAINED_GLASS:11)
B(1,38,4,STAINED_GLASS:11)
B(2,38,4,SEA_LANTERN)
B(3,38,4,STAINED_GLASS:11)
B(4,38,4,SEA_LANTERN)
B(5,38,4,STAINED_GLASS:15)
B(6,38,4,STAINED_GLASS:15)
B(7,38,4,STAINED_GLASS:11)
B(2,38,5,STAINED_GLASS:11)
B(3,38,5,STAINED_GLASS:11)
B(4,38,5,STAINED_GLASS:15)
B(5,38,5,STAINED_GLASS:11)
B(6,38,5,STAINED_GLASS:15)
B(2,38,6,STAINED_GLASS:15)
B(3,38,6,STAINED_GLASS:15)
B(4,38,6,STAINED_GLASS:15)
B(5,38,6,STAINED_GLASS:15)
B(3,38,7,STAINED_GLASS:15)
B(4,38,7,STAINED_GLASS:15)
B(2,39,0,STAINED_GLASS:15)
B(1,39,1,STAINED_GLASS:11)
B(2,39,1,STAINED_GLASS:15)
B(3,39,1,STAINED_GLASS:15)
B(4,39,1,STAINED_GLASS:15)
B(0,39,2,STAINED_GLASS:11)
B(1,39,2,STAINED_GLASS:11)
B(2,39,2,STAINED_GLASS:11)
B(3,39,2,STAINED_GLASS:11)
B(4,39,2,STAINED_GLASS:11)
B(5,39,2,STAINED_GLASS:11)
B(1,39,3,STAINED_GLASS:11)
B(2,39,3,STAINED_GLASS:11)
B(3,39,3,SEA_LANTERN)
B(4,39,3,STAINED_GLASS:15)
B(5,39,3,STAINED_GLASS:11)
B(6,39,3,STAINED_GLASS:11)
B(7,39,3,STAINED_GLASS:11)
B(1,39,4,STAINED_GLASS:11)
B(2,39,4,STAINED_GLASS:11)
B(3,39,4,STAINED_GLASS:15)
B(4,39,4,STAINED_GLASS:15)
B(5,39,4,STAINED_GLASS:15)
B(6,39,4,STAINED_GLASS:11)
B(2,39,5,STAINED_GLASS:15)
B(3,39,5,STAINED_GLASS:15)
B(4,39,5,STAINED_GLASS:15)
B(5,39,5,STAINED_GLASS:15)
B(3,39,6,STAINED_GLASS:15)
B(4,39,6,STAINED_GLASS:15)
B(3,39,7,STAINED_GLASS:15)
B(1,40,0,STAINED_GLASS:11)
B(2,40,0,STAINED_GLASS:15)
B(0,40,1,STAINED_GLASS:11)
B(1,40,1,STAINED_GLASS:11)
B(2,40,1,STAINED_GLASS:15)
B(3,40,1,STAINED_GLASS:15)
B(0,40,2,STAINED_GLASS:11)
B(1,40,2,STAINED_GLASS:11)
B(2,40,2,STAINED_GLASS:15)
B(3,40,2,STAINED_GLASS:11)
B(4,40,2,STAINED_GLASS:15)
B(5,40,2,STAINED_GLASS:15)
B(1,40,3,STAINED_GLASS:11)
B(2,40,3,STAINED_GLASS:11)
B(3,40,3,STAINED_GLASS:11)
B(4,40,3,STAINED_GLASS:15)
B(5,40,3,STAINED_GLASS:11)
B(6,40,3,STAINED_GLASS:11)
B(2,40,4,STAINED_GLASS:15)
B(3,40,4,STAINED_GLASS:15)
B(4,40,4,STAINED_GLASS:11)
B(5,40,4,STAINED_GLASS:11)
B(6,40,4,STAINED_GLASS:11)
B(2,40,5,STAINED_GLASS:15)
B(3,40,5,STAINED_GLASS:15)
B(4,40,5,STAINED_GLASS:15)
B(5,40,5,STAINED_GLASS:11)
B(3,40,6,STAINED_GLASS:15)
B(4,40,6,STAINED_GLASS:15)
B(1,41,0,STAINED_GLASS:15)
B(0,41,1,STAINED_GLASS:11)
B(1,41,1,STAINED_GLASS:11)
B(2,41,1,STAINED_GLASS:15)
B(3,41,1,STAINED_GLASS:15)
B(1,41,2,STAINED_GLASS:15)
B(2,41,2,STAINED_GLASS:11)
B(3,41,2,STAINED_GLASS:15)
B(4,41,2,STAINED_GLASS:15)
B(1,41,3,STAINED_GLASS:15)
B(2,41,3,STAINED_GLASS:11)
B(3,41,3,SEA_LANTERN)
B(4,41,3,STAINED_GLASS:11)
B(5,41,3,STAINED_GLASS:11)
B(6,41,3,STAINED_GLASS:11)
B(2,41,4,STAINED_GLASS:11)
B(3,41,4,STAINED_GLASS:11)
B(4,41,4,STAINED_GLASS:11)
B(5,41,4,STAINED_GLASS:11)
B(3,41,5,STAINED_GLASS:15)
B(4,41,5,STAINED_GLASS:11)
B(3,41,6,STAINED_GLASS:15)
B(1,42,0,STAINED_GLASS:15)
B(0,42,1,STAINED_GLASS:15)
B(1,42,1,STAINED_GLASS:15)
B(2,42,1,STAINED_GLASS:15)
B(1,42,2,STAINED_GLASS:15)
B(2,42,2,STAINED_GLASS:15)
B(3,42,2,STAINED_GLASS:15)
B(4,42,2,STAINED_GLASS:15)
B(2,42,3,STAINED_GLASS:11)
B(3,42,3,STAINED_GLASS:11)
B(4,42,3,STAINED_GLASS:11)
B(5,42,3,STAINED_GLASS:11)
B(2,42,4,STAINED_GLASS:11)
B(3,42,4,STAINED_GLASS:11)
B(4,42,4,STAINED_GLASS:11)
B(3,42,5,STAINED_GLASS:11)
B(1,43,0,STAINED_GLASS:15)
B(0,43,1,STAINED_GLASS:15)
B(1,43,1,STAINED_GLASS:15)
B(2,43,1,STAINED_GLASS:15)
B(1,43,2,STAINED_GLASS:15)
B(2,43,2,STAINED_GLASS:11)
B(3,43,2,STAINED_GLASS:15)
B(2,43,3,STAINED_GLASS:11)
B(3,43,3,STAINED_GLASS:11)
B(4,43,3,STAINED_GLASS:11)
B(5,43,3,STAINED_GLASS:15)
B(3,43,4,STAINED_GLASS:11)
B(4,43,4,STAINED_GLASS:11)
B(3,43,5,STAINED_GLASS:11)
B(1,44,0,STAINED_GLASS:15)
B(0,44,1,STAINED_GLASS:15)
B(1,44,1,STAINED_GLASS:11)
B(2,44,1,STAINED_GLASS:15)
B(1,44,2,STAINED_GLASS:11)
B(2,44,2,STAINED_GLASS:11)
B(3,44,2,STAINED_GLASS:11)
B(2,44,3,STAINED_GLASS:11)
B(3,44,3,STAINED_GLASS:15)
B(4,44,3,STAINED_GLASS:15)
B(3,44,4,STAINED_GLASS:11)
B(1,45,0,STAINED_GLASS:15)
B(0,45,1,STAINED_GLASS:11)
B(1,45,1,STAINED_GLASS:11)
B(2,45,1,STAINED_GLASS:11)
B(1,45,2,STAINED_GLASS:11)
B(2,45,2,STAINED_GLASS:11)
B(3,45,2,STAINED_GLASS:15)
B(2,45,3,STAINED_GLASS:11)
B(3,45,3,STAINED_GLASS:15)
B(4,45,3,STAINED_GLASS:15)
B(3,45,4,STAINED_GLASS:15)
B(1,46,1,STAINED_GLASS:11)
B(2,46,1,STAINED_GLASS:11)
B(1,46,2,STAINED_GLASS:11)
B(2,46,2,STAINED_GLASS:11)
B(3,46,2,STAINED_GLASS:11)
B(2,46,3,STAINED_GLASS:11)
B(3,46,3,STAINED_GLASS:15)
B(1,47,1,STAINED_GLASS:11)
B(2,47,2,STAINED_GLASS:11)
B(3,47,2,STAINED_GLASS:11)
B(2,47,3,STAINED_GLASS:11)
B(1,48,1,STAINED_GLASS:11)
B(2,48,2,STAINED_GLASS:11)
B(1,49,1,STAINED_GLASS:11)

#######################################################################
# +-----------------------------------------------------------------+ #
# |                             Branches                            | #
# +-----------------------------------------------------------------+ #
#######################################################################

BR(16,0,0,true,SPIKE-THIN-DIAG-EXTREME-01_1x0,NORTH,100,0)
