
#######################################################################
# +-----------------------------------------------------------------+ #
# |                            BO3 object                           | #
# +-----------------------------------------------------------------+ #
#######################################################################

Author: Bo3 BulkEdit

Description: Converted Schematic - Modified by Bo3BulkEdit

Version: 3

SettingsMode: WriteWithoutComments


#######################################################################
# +-----------------------------------------------------------------+ #
# |                          Main settings                          | #
# +-----------------------------------------------------------------+ #
#######################################################################

Tree: false

Frequency: 1

Rarity: 100.0

RotateRandomly: false

SpawnHeight: randomY

SpawnHeightOffset: 0

SpawnHeightVariance: 0

##############################
# Height Limits for the BO3. #
##############################

MinHeight: 0

MaxHeight: 255

######################
# Extrusion settings #
######################

ExtrudeMode: None

ExtrudeThroughBlocks: minecraft:air

MaxBranchDepth: 20


#######################################################################
# +-----------------------------------------------------------------+ #
# |                      Source block settings                      | #
# +-----------------------------------------------------------------+ #
#######################################################################

SourceBlocks: otg:air

MaxPercentageOutsideSourceBlock: 100

OutsideSourceBlock: placeAnyway

DoReplaceBlocks: true

IsOTGPlus: false


#######################################################################
# +-----------------------------------------------------------------+ #
# |                              Blocks                             | #
# +-----------------------------------------------------------------+ #
#######################################################################

B(-8,10,-7,minecraft:spruce_slab[type=top,waterlogged=false])
B(-7,10,-7,minecraft:spruce_slab[type=double,waterlogged=false])
B(-6,9,-7,minecraft:spruce_slab[type=top,waterlogged=false])
B(-6,10,-7,minecraft:spruce_slab[type=double,waterlogged=false])
B(-6,11,-7,minecraft:oak_fence[east=true,north=false,south=false,waterlogged=false,west=false])
B(-5,9,-7,minecraft:spruce_slab[type=double,waterlogged=false])
B(-5,10,-7,minecraft:spruce_slab)
B(-5,11,-7,minecraft:oak_fence[east=false,north=false,south=false,waterlogged=false,west=true])
B(-5,12,-7,minecraft:oak_fence[east=true,north=false,south=false,waterlogged=false,west=false])
B(-4,8,-7,minecraft:spruce_slab[type=top,waterlogged=false])
B(-4,9,-7,minecraft:spruce_slab[type=double,waterlogged=false])
B(-4,12,-7,minecraft:oak_fence[east=false,north=false,south=false,waterlogged=false,west=true])
B(-4,13,-7,minecraft:oak_fence[east=true,north=false,south=false,waterlogged=false,west=false])
B(-3,8,-7,minecraft:spruce_slab[type=double,waterlogged=false])
B(-3,9,-7,minecraft:spruce_slab)
B(-3,13,-7,minecraft:oak_fence[east=false,north=false,south=false,waterlogged=false,west=true])
B(-3,14,-7,minecraft:oak_fence[east=true,north=false,south=false,waterlogged=false,west=false])
B(-2,7,-7,minecraft:spruce_slab[type=top,waterlogged=false])
B(-2,8,-7,minecraft:spruce_slab[type=double,waterlogged=false])
B(-2,14,-7,minecraft:oak_fence[east=false,north=false,south=false,waterlogged=false,west=true])
B(-2,15,-7,minecraft:oak_fence[east=true,north=false,south=false,waterlogged=false,west=false])
B(-2,4,-6,minecraft:white_wool)
B(-2,3,-5,minecraft:white_wool)
B(-2,4,-5,minecraft:white_wool)
B(-2,3,-4,minecraft:white_wool)
B(-2,4,-4,minecraft:white_wool)
B(-2,5,-4,minecraft:white_wool)
B(-2,2,-3,minecraft:white_wool)
B(-2,3,-3,minecraft:white_wool)
B(-2,4,-3,minecraft:black_wool)
B(-2,5,-3,minecraft:black_wool)
B(-2,1,-2,minecraft:white_wool)
B(-2,2,-2,minecraft:white_wool)
B(-2,1,-1,minecraft:white_wool)
B(-1,3,-8,minecraft:black_wool)
B(-1,4,-8,minecraft:white_wool)
B(-1,5,-8,minecraft:white_wool)
B(-1,3,-7,minecraft:black_wool)
B(-1,4,-7,minecraft:white_wool)
B(-1,5,-7,minecraft:white_wool)
B(-1,7,-7,minecraft:spruce_slab[type=double,waterlogged=false])
B(-1,8,-7,minecraft:spruce_slab)
B(-1,15,-7,minecraft:oak_fence[east=false,north=false,south=false,waterlogged=false,west=true])
B(-1,16,-7,minecraft:oak_fence)
B(-1,3,-6,minecraft:white_wool)
B(-1,5,-6,minecraft:white_wool)
B(-1,2,-5,minecraft:black_wool)
B(-1,5,-5,minecraft:white_wool)
B(-1,6,-5,minecraft:white_wool)
B(-1,2,-4,minecraft:white_wool)
B(-1,6,-4,minecraft:white_wool)
B(-1,6,-3,minecraft:black_wool)
B(-1,6,-2,minecraft:white_wool)
B(-1,1,-1,minecraft:black_wool)

#######################################################################
# +-----------------------------------------------------------------+ #
# |                            BO3 checks                           | #
# +-----------------------------------------------------------------+ #
#######################################################################


#######################################################################
# +-----------------------------------------------------------------+ #
# |                             Branches                            | #
# +-----------------------------------------------------------------+ #
#######################################################################


#######################################################################
# +-----------------------------------------------------------------+ #
# |                             Entities                            | #
# +-----------------------------------------------------------------+ #
#######################################################################

