
#######################################################################
# +-----------------------------------------------------------------+ #
# |                            BO3 object                           | #
# +-----------------------------------------------------------------+ #
#######################################################################

Author: BO3 BulkEdit (by LanToaster)

Description: This Object was Created with BO3_BulkEdit

Version: 3

SettingsMode: WriteDisable


#######################################################################
# +-----------------------------------------------------------------+ #
# |                          Main settings                          | #
# +-----------------------------------------------------------------+ #
#######################################################################

Tree: false

Frequency: 1

Rarity: 100.0

RotateRandomly: false

SpawnHeight: randomY

SpawnHeightOffset: 0

SpawnHeightVariance: 0

##############################
# Height Limits for the BO3. #
##############################

MinHeight: 70

MaxHeight: 75

######################
# Extrusion settings #
######################

ExtrudeMode: None

ExtrudeThroughBlocks: AIR

MaxBranchDepth: 10

ExcludedBiomes: All


#######################################################################
# +-----------------------------------------------------------------+ #
# |                      Source block settings                      | #
# +-----------------------------------------------------------------+ #
#######################################################################

SourceBlocks: Solid

MaxPercentageOutsideSourceBlock: 80

OutsideSourceBlock: placeAnyway

IsOTGPlus: false

InheritBO3: 

InheritBO3Rotation: NORTH

OverrideChildSettings: true

OverrideParentHeight: false

CanOverride: false

BranchFrequency: 0

BranchFrequencyGroup: 

MustBeBelowOther: false

MustBeInside: 

CannotBeInside: 

ReplacesBO3: 

CanSpawnOnWater: true

SpawnOnWaterOnly: false

SpawnUnderWater: false

SpawnAtWaterLevel: false

HeightOffset: 0

RemoveAir: true

ReplaceAbove: 

ReplaceBelow: 

ReplaceWithBiomeBlocks: true

ReplaceWithGroundBlock: DIRT

ReplaceWithSurfaceBlock: GRASS

SmoothRadius: 0

SmoothHeightOffset: 0

SmoothStartTop: false

SmoothStartWood: false

SmoothingSurfaceBlock: 

SmoothingGroundBlock: 

BO3Group: 

IsSpawnPoint: false


#######################################################################
# +-----------------------------------------------------------------+ #
# |                              Blocks                             | #
# +-----------------------------------------------------------------+ #
#######################################################################

Block(-5,3,-7,QUARTZ_STAIRS:6)
Block(-1,3,-7,BONE_BLOCK:0)
B(3,3,-7,BONE_BLOCK:0)
Block(-5,3,-6,BONE_BLOCK:0)
Block(-1,3,-6,BONE_BLOCK:0)
B(3,3,-6,QUARTZ_STAIRS:0)
Block(-5,3,-5,BONE_BLOCK:0)
Block(-1,3,-5,QUARTZ_STAIRS:0)
Block(-5,3,-4,QUARTZ_STAIRS:0)
B(3,3,-2,QUARTZ_STAIRS:2)
Block(-1,3,-1,QUARTZ_STAIRS:2)
B(3,3,-1,BONE_BLOCK:0)
Block(-5,3,0,QUARTZ_STAIRS:2)
Block(-1,3,0,BONE_BLOCK:0)
B(3,3,0,BONE_BLOCK:0)
Block(-5,3,1,BONE_BLOCK:0)
Block(-1,3,1,BONE_BLOCK:0)
B(3,3,1,QUARTZ_STAIRS:7)
Block(-5,3,2,BONE_BLOCK:0)
Block(-1,3,2,QUARTZ_STAIRS:7)
Block(-5,3,3,QUARTZ_STAIRS:7)
Block(-5,4,-7,BONE_BLOCK:0)
Block(-1,4,-7,QUARTZ_STAIRS:0)
B(7,4,-7,BONE_BLOCK:8)
Block(-5,4,-6,QUARTZ_STAIRS:0)
B(7,4,-6,QUARTZ_STAIRS:7)
B(7,4,-2,QUARTZ_STAIRS:6)
B(7,4,-1,BONE_BLOCK:8)
B(3,4,0,QUARTZ_STAIRS:2)
B(7,4,0,QUARTZ_STAIRS:7)
Block(-1,4,1,QUARTZ_STAIRS:2)
B(3,4,1,BONE_BLOCK:0)
Block(-5,4,2,QUARTZ_STAIRS:2)
Block(-1,4,2,BONE_BLOCK:0)
Block(-5,4,3,BONE_BLOCK:0)
Block(-5,5,-7,BONE_BLOCK:8)
B(7,5,-7,QUARTZ_STAIRS:0)
B(7,5,-1,QUARTZ_STAIRS:2)
B(7,5,0,BONE_BLOCK:8)
B(3,5,1,BONE_BLOCK:8)
B(7,5,1,QUARTZ_STAIRS:7)
Block(-1,5,2,BONE_BLOCK:8)
B(3,5,2,QUARTZ_STAIRS:7)
Block(-5,5,3,BONE_BLOCK:8)
Block(-1,5,3,QUARTZ_STAIRS:7)
Block(-5,5,4,QUARTZ_STAIRS:7)
Block(-5,6,-7,QUARTZ_STAIRS:0)
B(7,6,0,QUARTZ_STAIRS:2)
B(3,6,1,QUARTZ_STAIRS:2)
B(7,6,1,BONE_BLOCK:0)
Block(-1,6,2,QUARTZ_STAIRS:2)
B(3,6,2,BONE_BLOCK:0)
Block(-5,6,3,QUARTZ_STAIRS:2)
Block(-1,6,3,BONE_BLOCK:0)
Block(-5,6,4,BONE_BLOCK:0)
Block(-1,6,4,QUARTZ_STAIRS:7)
B(7,7,0,QUARTZ_STAIRS:6)
B(7,7,1,BONE_BLOCK:0)
B(3,7,2,BONE_BLOCK:0)
Block(-1,7,3,BONE_BLOCK:0)
Block(-5,7,4,BONE_BLOCK:0)
B(7,8,0,BONE_BLOCK:0)
B(7,8,1,QUARTZ_STAIRS:0)
B(3,8,2,BONE_BLOCK:0)
Block(-1,8,3,BONE_BLOCK:0)
Block(-5,8,4,BONE_BLOCK:0)
Block(-1,8,4,QUARTZ_STAIRS:0)
Block(-5,9,-7,QUARTZ_STAIRS:7)
B(7,9,-7,QUARTZ_STAIRS:7)
B(7,9,-1,QUARTZ_STAIRS:6)
B(7,9,0,BONE_BLOCK:8)
B(3,9,1,QUARTZ_STAIRS:6)
Block(-1,9,2,QUARTZ_STAIRS:6)
B(3,9,2,QUARTZ_STAIRS:0)
Block(-5,9,3,QUARTZ_STAIRS:6)
Block(-1,9,3,QUARTZ_STAIRS:0)
Block(-5,9,4,QUARTZ_STAIRS:0)
Block(-5,10,-7,QUARTZ_STAIRS:2)
Block(-1,10,-7,BONE_BLOCK:8)
B(3,10,-7,QUARTZ_STAIRS:7)
B(7,10,-7,BONE_BLOCK:8)
Block(-5,10,-6,BONE_BLOCK:8)
Block(-1,10,-6,QUARTZ_STAIRS:7)
B(7,10,-6,BONE_BLOCK:0)
Block(-5,10,-5,QUARTZ_STAIRS:7)
B(7,10,-5,QUARTZ_STAIRS:7)
B(7,10,-3,QUARTZ_STAIRS:6)
B(7,10,-2,BONE_BLOCK:0)
B(3,10,-1,QUARTZ_STAIRS:6)
B(7,10,-1,BONE_BLOCK:8)
Block(-1,10,0,QUARTZ_STAIRS:6)
B(3,10,0,BONE_BLOCK:8)
B(7,10,0,QUARTZ_STAIRS:0)
Block(-5,10,1,QUARTZ_STAIRS:6)
Block(-1,10,1,BONE_BLOCK:8)
B(3,10,1,QUARTZ_STAIRS:0)
Block(-5,10,2,BONE_BLOCK:8)
Block(-1,10,2,QUARTZ_STAIRS:0)
Block(-5,10,3,QUARTZ_STAIRS:0)
Block(-1,11,-7,QUARTZ_STAIRS:2)
B(3,11,-7,BONE_BLOCK:8)
Block(-5,11,-6,QUARTZ_STAIRS:2)
Block(-1,11,-6,BONE_BLOCK:8)
B(3,11,-6,BONE_BLOCK:8)
B(7,11,-6,QUARTZ_STAIRS:2)
Block(-5,11,-5,BONE_BLOCK:8)
Block(-1,11,-5,BONE_BLOCK:8)
B(3,11,-5,BONE_BLOCK:0)
B(7,11,-5,BONE_BLOCK:8)
Block(-5,11,-4,BONE_BLOCK:8)
Block(-1,11,-4,BONE_BLOCK:0)
B(6,11,-4,BONE_BLOCK:0)
B(7,11,-4,BONE_BLOCK)
B(8,11,-4,BONE_BLOCK)
Block(-5,11,-3,BONE_BLOCK:0)
B(3,11,-3,BONE_BLOCK:0)
B(7,11,-3,BONE_BLOCK:8)
Block(-1,11,-2,BONE_BLOCK:0)
B(3,11,-2,BONE_BLOCK:8)
B(7,11,-2,QUARTZ_STAIRS:0)
Block(-5,11,-1,BONE_BLOCK:0)
Block(-1,11,-1,BONE_BLOCK:8)
B(3,11,-1,BONE_BLOCK:8)
Block(-5,11,0,BONE_BLOCK:8)
Block(-1,11,0,BONE_BLOCK:8)
B(3,11,0,QUARTZ_STAIRS:0)
Block(-5,11,1,BONE_BLOCK:8)
Block(-1,11,1,QUARTZ_STAIRS:0)
Block(-5,11,2,QUARTZ_STAIRS:0)
B(3,12,-7,BONE_BLOCK:0)
Block(-1,12,-6,BONE_BLOCK:0)
B(3,12,-6,QUARTZ_STAIRS:2)
Block(-5,12,-5,BONE_BLOCK:0)
Block(-1,12,-5,QUARTZ_STAIRS:2)
B(1,12,-5,QUARTZ_STAIRS:2)
B(3,12,-5,BONE_BLOCK:8)
B(5,12,-5,QUARTZ_STAIRS:2)
Block(-5,12,-4,QUARTZ_STAIRS:2)
Block(-3,12,-4,QUARTZ_STAIRS:2)
Block(-1,12,-4,BONE_BLOCK:8)
B(1,12,-4,BONE_BLOCK:8)
B(2,12,-4,BONE_BLOCK)
B(3,12,-4,BONE_BLOCK)
B(4,12,-4,BONE_BLOCK)
B(5,12,-4,BONE_BLOCK)
B(6,12,-4,BONE_BLOCK)
B(7,12,-4,QUARTZ_STAIRS:1)
Block(-7,12,-3,QUARTZ_STAIRS:2)
Block(-5,12,-3,BONE_BLOCK:8)
Block(-3,12,-3,BONE_BLOCK:8)
Block(-2,12,-3,BONE_BLOCK)
Block(-1,12,-3,BONE_BLOCK)
B(0,12,-3,BONE_BLOCK)
B(1,12,-3,BONE_BLOCK)
B(3,12,-3,BONE_BLOCK:8)
B(5,12,-3,QUARTZ_STAIRS:0)
Block(-7,12,-2,BONE_BLOCK:8)
Block(-6,12,-2,BONE_BLOCK)
Block(-5,12,-2,BONE_BLOCK)
Block(-4,12,-2,BONE_BLOCK)
Block(-3,12,-2,BONE_BLOCK)
Block(-1,12,-2,BONE_BLOCK:8)
B(1,12,-2,QUARTZ_STAIRS:0)
B(3,12,-2,QUARTZ_STAIRS:0)
Block(-7,12,-1,BONE_BLOCK)
Block(-5,12,-1,BONE_BLOCK:8)
Block(-3,12,-1,QUARTZ_STAIRS:0)
Block(-1,12,-1,QUARTZ_STAIRS:0)
B(3,12,-1,BONE_BLOCK:0)
Block(-7,12,0,QUARTZ_STAIRS:0)
Block(-5,12,0,QUARTZ_STAIRS:0)
Block(-1,12,0,BONE_BLOCK:0)
Block(-5,12,1,BONE_BLOCK:0)
B(3,13,-7,QUARTZ_STAIRS:2)
Block(-1,13,-6,QUARTZ_STAIRS:2)
Block(-5,13,-5,QUARTZ_STAIRS:2)
B(3,13,-4,QUARTZ_STAIRS:1)
B(6,13,-4,BONE_BLOCK:0)
Block(-1,13,-3,QUARTZ_STAIRS:1)
Block(-5,13,-2,QUARTZ_STAIRS:1)
B(3,13,-1,QUARTZ_STAIRS:0)
Block(-1,13,0,QUARTZ_STAIRS:0)
Block(-5,13,1,QUARTZ_STAIRS:0)
B(2,14,-4,QUARTZ_STAIRS:4)
B(6,14,-4,QUARTZ_STAIRS:4)
B(8,14,-4,BONE_BLOCK:0)
Block(-2,14,-3,QUARTZ_STAIRS:4)
Block(-6,14,-2,QUARTZ_STAIRS:4)
B(2,15,-5,QUARTZ_STAIRS:2)
B(5,15,-5,QUARTZ_STAIRS:2)
Block(-2,15,-4,QUARTZ_STAIRS:2)
B(0,15,-4,QUARTZ_STAIRS:2)
B(1,15,-4,BONE_BLOCK:8)
B(2,15,-4,BONE_BLOCK)
B(3,15,-4,BONE_BLOCK)
B(4,15,-4,BONE_BLOCK)
B(5,15,-4,BONE_BLOCK)
B(6,15,-4,BONE_BLOCK)
B(7,15,-4,BONE_BLOCK)
B(8,15,-4,BONE_BLOCK)
Block(-6,15,-3,QUARTZ_STAIRS:2)
Block(-4,15,-3,QUARTZ_STAIRS:2)
Block(-3,15,-3,BONE_BLOCK:8)
Block(-2,15,-3,BONE_BLOCK)
Block(-1,15,-3,BONE_BLOCK)
B(0,15,-3,BONE_BLOCK)
B(1,15,-3,BONE_BLOCK)
B(3,15,-3,QUARTZ_STAIRS:0)
B(5,15,-3,QUARTZ_STAIRS:0)
Block(-7,15,-2,BONE_BLOCK:8)
Block(-6,15,-2,BONE_BLOCK)
Block(-5,15,-2,BONE_BLOCK)
Block(-4,15,-2,BONE_BLOCK)
Block(-3,15,-2,BONE_BLOCK)
Block(-1,15,-2,QUARTZ_STAIRS:0)
B(1,15,-2,QUARTZ_STAIRS:0)
Block(-7,15,-1,BONE_BLOCK)
Block(-5,15,-1,QUARTZ_STAIRS:0)
Block(-3,15,-1,QUARTZ_STAIRS:0)
B(2,16,-4,BONE_BLOCK:0)
B(3,16,-4,QUARTZ_STAIRS:1)
B(6,16,-4,BONE_BLOCK:0)
B(7,16,-4,QUARTZ_STAIRS:1)
Block(-2,16,-3,BONE_BLOCK:0)
Block(-1,16,-3,QUARTZ_STAIRS:1)
Block(-6,16,-2,BONE_BLOCK:0)
Block(-5,16,-2,QUARTZ_STAIRS:1)
B(2,17,-4,QUARTZ_STAIRS:1)
B(6,17,-4,QUARTZ_STAIRS:1)
Block(-2,17,-3,QUARTZ_STAIRS:1)
Block(-6,17,-2,QUARTZ_STAIRS:1)

#######################################################################
# +-----------------------------------------------------------------+ #
# |                            BO3 checks                           | #
# +-----------------------------------------------------------------+ #
#######################################################################


#######################################################################
# +-----------------------------------------------------------------+ #
# |                             Branches                            | #
# +-----------------------------------------------------------------+ #
#######################################################################

Branch(16,0,0, Worm_Skeleton_06-01,NORTH,100.0)
Branch(0,0,-16, Worm_Skeleton_05-00,NORTH,100.0)
Branch(0,0,16, Worm_Skeleton_05-02,NORTH,100.0)

#######################################################################
# +-----------------------------------------------------------------+ #
# |                             Entities                            | #
# +-----------------------------------------------------------------+ #
#######################################################################


#######################################################################
# +-----------------------------------------------------------------+ #
# |                            Particles                            | #
# +-----------------------------------------------------------------+ #
#######################################################################


#######################################################################
# +-----------------------------------------------------------------+ #
# |                             Spawners                            | #
# +-----------------------------------------------------------------+ #
#######################################################################


#######################################################################
# +-----------------------------------------------------------------+ #
# |                             ModData                             | #
# +-----------------------------------------------------------------+ #
#######################################################################

