#######################################################################
# +-----------------------------------------------------------------+ #
# |                            BO3 object                           | #
# +-----------------------------------------------------------------+ #
#######################################################################

Author: Bo3 BulkEdit

Description: Converted Schematic - Modified by Bo3BulkEdit

Version: 3

SettingsMode: WriteDisable

#######################################################################
# +-----------------------------------------------------------------+ #
# |                          Main settings                          | #
# +-----------------------------------------------------------------+ #
#######################################################################



Frequency: 0


SpawnHeight: randomY





##############################
# Height Limits for the BO3. #
##############################

MinHeight: 0
MaxHeight: 256

#######################################################################
# +-----------------------------------------------------------------+ #
# |                      Source block settings                      | #
# +-----------------------------------------------------------------+ #
#######################################################################

CanOverride: true
MaxPercentageOutsideSourceBlock: 100
OutsideSourceBlock: placeAnyway

#######################################################################
# +-----------------------------------------------------------------+ #
# |                               OTG+                              | #
# +-----------------------------------------------------------------+ #
#######################################################################

#######################################################################
# +-----------------------------------------------------------------+ #
# |                              Blocks                             | #
# +-----------------------------------------------------------------+ #
#######################################################################

B(0,750,0,AIR)
B(15,750,15,AIR)
B(15,9,15,STAINED_GLASS:15)
B(15,10,13,STAINED_GLASS:15)
B(14,10,14,STAINED_GLASS:15)
B(15,10,14,STAINED_GLASS:15)
B(13,10,15,STAINED_GLASS:15)
B(14,10,15,STAINED_GLASS:15)
B(15,10,15,STAINED_GLASS:15)
B(14,11,12,STAINED_GLASS:15)
B(15,11,12,STAINED_GLASS:6)
B(13,11,13,STAINED_GLASS:15)
B(14,11,13,STAINED_GLASS:15)
B(15,11,13,STAINED_GLASS:10)
B(12,11,14,STAINED_GLASS:15)
B(13,11,14,STAINED_GLASS:15)
B(14,11,14,STAINED_GLASS:15)
B(15,11,14,STAINED_GLASS:10)
B(12,11,15,STAINED_GLASS:15)
B(13,11,15,STAINED_GLASS:10)
B(14,11,15,STAINED_GLASS:10)
B(15,11,15,STAINED_GLASS:15)
B(13,12,11,STAINED_GLASS:15)
B(14,12,11,STAINED_GLASS:6)
B(12,12,12,STAINED_GLASS:15)
B(13,12,12,STAINED_GLASS:15)
B(14,12,12,STAINED_GLASS:10)
B(15,12,12,STAINED_GLASS:6)
B(11,12,13,STAINED_GLASS:15)
B(12,12,13,STAINED_GLASS:15)
B(13,12,13,STAINED_GLASS:15)
B(14,12,13,STAINED_GLASS:10)
B(15,12,13,STAINED_GLASS:10)
B(11,12,14,STAINED_GLASS:15)
B(12,12,14,STAINED_GLASS:10)
B(13,12,14,STAINED_GLASS:10)
B(14,12,14,SEA_LANTERN)
B(15,12,14,SEA_LANTERN)
B(12,12,15,STAINED_GLASS:15)
B(13,12,15,STAINED_GLASS:10)
B(14,12,15,SEA_LANTERN)
B(15,12,15,SEA_LANTERN)
B(12,13,10,STAINED_GLASS:15)
B(13,13,10,STAINED_GLASS:15)
B(11,13,11,STAINED_GLASS:15)
B(12,13,11,STAINED_GLASS:15)
B(13,13,11,STAINED_GLASS:10)
B(14,13,11,STAINED_GLASS:6)
B(10,13,12,STAINED_GLASS:15)
B(11,13,12,STAINED_GLASS:15)
B(12,13,12,STAINED_GLASS:15)
B(13,13,12,STAINED_GLASS:10)
B(14,13,12,STAINED_GLASS:10)
B(15,13,12,STAINED_GLASS:6)
B(10,13,13,STAINED_GLASS:15)
B(11,13,13,STAINED_GLASS:11)
B(12,13,13,STAINED_GLASS:10)
B(13,13,13,SEA_LANTERN)
B(14,13,13,SEA_LANTERN)
B(15,13,13,STAINED_GLASS:15)
B(11,13,14,STAINED_GLASS:15)
B(12,13,14,STAINED_GLASS:10)
B(13,13,14,SEA_LANTERN)
B(14,13,14,SEA_LANTERN)
B(15,13,14,STAINED_GLASS:10)
B(12,13,15,STAINED_GLASS:15)
B(13,13,15,STAINED_GLASS:15)
B(14,13,15,STAINED_GLASS:10)
B(15,13,15,STAINED_GLASS:15)
B(11,14,9,STAINED_GLASS:6)
B(12,14,9,STAINED_GLASS:6)
B(10,14,10,STAINED_GLASS:15)
B(11,14,10,STAINED_GLASS:15)
B(12,14,10,STAINED_GLASS:10)
B(13,14,10,STAINED_GLASS:6)
B(9,14,11,STAINED_GLASS:15)
B(10,14,11,STAINED_GLASS:15)
B(11,14,11,STAINED_GLASS:15)
B(12,14,11,STAINED_GLASS:10)
B(13,14,11,STAINED_GLASS:10)
B(14,14,11,STAINED_GLASS:6)
B(9,14,12,STAINED_GLASS:15)
B(10,14,12,STAINED_GLASS:11)
B(11,14,12,STAINED_GLASS:11)
B(12,14,12,STAINED_GLASS:15)
B(13,14,12,STAINED_GLASS:15)
B(14,14,12,STAINED_GLASS:15)
B(15,14,12,STAINED_GLASS:6)
B(10,14,13,STAINED_GLASS:15)
B(11,14,13,STAINED_GLASS:10)
B(12,14,13,SEA_LANTERN)
B(13,14,13,SEA_LANTERN)
B(14,14,13,STAINED_GLASS:10)
B(15,14,13,STAINED_GLASS:10)
B(11,14,14,STAINED_GLASS:15)
B(12,14,14,STAINED_GLASS:15)
B(13,14,14,STAINED_GLASS:10)
B(14,14,14,STAINED_GLASS:15)
B(15,14,14,STAINED_GLASS:10)
B(12,14,15,STAINED_GLASS:15)
B(13,14,15,STAINED_GLASS:10)
B(14,14,15,STAINED_GLASS:10)
B(15,14,15,STAINED_GLASS:15)
B(10,15,8,STAINED_GLASS:6)
B(11,15,8,STAINED_GLASS:6)
B(9,15,9,STAINED_GLASS:15)
B(10,15,9,STAINED_GLASS:6)
B(11,15,9,STAINED_GLASS:10)
B(12,15,9,STAINED_GLASS:6)
B(8,15,10,STAINED_GLASS:15)
B(9,15,10,STAINED_GLASS:15)
B(10,15,10,STAINED_GLASS:15)
B(11,15,10,STAINED_GLASS:10)
B(12,15,10,STAINED_GLASS:10)
B(13,15,10,STAINED_GLASS:6)
B(8,15,11,STAINED_GLASS:15)
B(9,15,11,STAINED_GLASS:15)
B(10,15,11,STAINED_GLASS:11)
B(11,15,11,STAINED_GLASS:15)
B(12,15,11,STAINED_GLASS:15)
B(13,15,11,STAINED_GLASS:15)
B(14,15,11,STAINED_GLASS:6)
B(9,15,12,STAINED_GLASS:15)
B(10,15,12,STAINED_GLASS:10)
B(11,15,12,STAINED_GLASS:15)
B(12,15,12,SEA_LANTERN)
B(13,15,12,STAINED_GLASS:10)
B(14,15,12,STAINED_GLASS:11)
B(15,15,12,STAINED_GLASS:6)
B(10,15,13,STAINED_GLASS:15)
B(11,15,13,STAINED_GLASS:15)
B(12,15,13,STAINED_GLASS:10)
B(13,15,13,STAINED_GLASS:15)
B(14,15,13,STAINED_GLASS:10)
B(15,15,13,STAINED_GLASS:15)
B(11,15,14,STAINED_GLASS:15)
B(12,15,14,STAINED_GLASS:10)
B(13,15,14,STAINED_GLASS:10)
B(14,15,14,STAINED_GLASS:15)
B(15,15,14,STAINED_GLASS:15)
B(12,15,15,STAINED_GLASS:15)
B(13,15,15,STAINED_GLASS:15)
B(14,15,15,STAINED_GLASS:15)
B(9,16,7,STAINED_GLASS:6)
B(10,16,7,STAINED_GLASS:6)
B(8,16,8,STAINED_GLASS:6)
B(9,16,8,STAINED_GLASS:6)
B(10,16,8,STAINED_GLASS:10)
B(11,16,8,STAINED_GLASS:6)
B(7,16,9,STAINED_GLASS:15)
B(8,16,9,STAINED_GLASS:15)
B(9,16,9,STAINED_GLASS:15)
B(10,16,9,STAINED_GLASS:10)
B(11,16,9,STAINED_GLASS:10)
B(12,16,9,STAINED_GLASS:6)
B(7,16,10,STAINED_GLASS:15)
B(8,16,10,STAINED_GLASS:15)
B(9,16,10,STAINED_GLASS:10)
B(10,16,10,SEA_LANTERN)
B(11,16,10,SEA_LANTERN)
B(12,16,10,STAINED_GLASS:15)
B(13,16,10,STAINED_GLASS:6)
B(8,16,11,STAINED_GLASS:15)
B(9,16,11,STAINED_GLASS:15)
B(10,16,11,STAINED_GLASS:15)
B(11,16,11,SEA_LANTERN)
B(12,16,11,STAINED_GLASS:10)
B(13,16,11,STAINED_GLASS:11)
B(14,16,11,STAINED_GLASS:6)
B(9,16,12,STAINED_GLASS:15)
B(10,16,12,STAINED_GLASS:15)
B(11,16,12,STAINED_GLASS:10)
B(12,16,12,STAINED_GLASS:15)
B(13,16,12,STAINED_GLASS:10)
B(14,16,12,STAINED_GLASS:6)
B(10,16,13,STAINED_GLASS:15)
B(11,16,13,STAINED_GLASS:10)
B(12,16,13,STAINED_GLASS:10)
B(13,16,13,STAINED_GLASS:15)
B(14,16,13,STAINED_GLASS:15)
B(11,16,14,STAINED_GLASS:15)
B(12,16,14,STAINED_GLASS:15)
B(13,16,14,STAINED_GLASS:15)
B(8,17,6,STAINED_GLASS:6)
B(9,17,6,STAINED_GLASS:6)
B(7,17,7,STAINED_GLASS:6)
B(8,17,7,STAINED_GLASS:6)
B(9,17,7,STAINED_GLASS:10)
B(10,17,7,STAINED_GLASS:6)
B(6,17,8,STAINED_GLASS:6)
B(7,17,8,STAINED_GLASS:6)
B(8,17,8,STAINED_GLASS:15)
B(9,17,8,STAINED_GLASS:10)
B(10,17,8,STAINED_GLASS:10)
B(11,17,8,STAINED_GLASS:6)
B(6,17,9,STAINED_GLASS:15)
B(7,17,9,STAINED_GLASS:6)
B(8,17,9,STAINED_GLASS:10)
B(9,17,9,SEA_LANTERN)
B(10,17,9,SEA_LANTERN)
B(11,17,9,STAINED_GLASS:15)
B(12,17,9,STAINED_GLASS:6)
B(7,17,10,STAINED_GLASS:15)
B(8,17,10,STAINED_GLASS:15)
B(9,17,10,STAINED_GLASS:15)
B(10,17,10,SEA_LANTERN)
B(11,17,10,STAINED_GLASS:10)
B(12,17,10,STAINED_GLASS:11)
B(13,17,10,STAINED_GLASS:6)
B(8,17,11,STAINED_GLASS:15)
B(9,17,11,STAINED_GLASS:15)
B(10,17,11,STAINED_GLASS:10)
B(11,17,11,STAINED_GLASS:15)
B(12,17,11,STAINED_GLASS:10)
B(13,17,11,STAINED_GLASS:6)
B(9,17,12,STAINED_GLASS:15)
B(10,17,12,STAINED_GLASS:10)
B(11,17,12,STAINED_GLASS:10)
B(12,17,12,STAINED_GLASS:15)
B(13,17,12,STAINED_GLASS:15)
B(10,17,13,STAINED_GLASS:15)
B(11,17,13,STAINED_GLASS:15)
B(12,17,13,STAINED_GLASS:15)
B(7,18,5,STAINED_GLASS:6)
B(8,18,5,STAINED_GLASS:6)
B(6,18,6,STAINED_GLASS:6)
B(7,18,6,STAINED_GLASS:6)
B(8,18,6,STAINED_GLASS:10)
B(9,18,6,STAINED_GLASS:6)
B(5,18,7,STAINED_GLASS:6)
B(6,18,7,STAINED_GLASS:6)
B(7,18,7,STAINED_GLASS:15)
B(8,18,7,STAINED_GLASS:10)
B(9,18,7,STAINED_GLASS:11)
B(10,18,7,STAINED_GLASS:15)
B(5,18,8,STAINED_GLASS:15)
B(6,18,8,STAINED_GLASS:6)
B(7,18,8,STAINED_GLASS:10)
B(8,18,8,SEA_LANTERN)
B(9,18,8,SEA_LANTERN)
B(10,18,8,STAINED_GLASS:15)
B(11,18,8,STAINED_GLASS:15)
B(6,18,9,STAINED_GLASS:15)
B(7,18,9,STAINED_GLASS:15)
B(8,18,9,STAINED_GLASS:15)
B(9,18,9,SEA_LANTERN)
B(10,18,9,STAINED_GLASS:10)
B(11,18,9,STAINED_GLASS:10)
B(12,18,9,STAINED_GLASS:15)
B(7,18,10,STAINED_GLASS:15)
B(8,18,10,STAINED_GLASS:15)
B(9,18,10,STAINED_GLASS:10)
B(10,18,10,STAINED_GLASS:15)
B(11,18,10,STAINED_GLASS:10)
B(12,18,10,STAINED_GLASS:15)
B(8,18,11,STAINED_GLASS:15)
B(9,18,11,STAINED_GLASS:15)
B(10,18,11,STAINED_GLASS:15)
B(11,18,11,STAINED_GLASS:15)
B(12,18,11,STAINED_GLASS:15)
B(9,18,12,STAINED_GLASS:15)
B(10,18,12,STAINED_GLASS:15)
B(11,18,12,STAINED_GLASS:15)
B(6,19,4,STAINED_GLASS:15)
B(7,19,4,STAINED_GLASS:15)
B(5,19,5,STAINED_GLASS:6)
B(6,19,5,STAINED_GLASS:6)
B(7,19,5,STAINED_GLASS:10)
B(8,19,5,STAINED_GLASS:15)
B(4,19,6,STAINED_GLASS:6)
B(5,19,6,STAINED_GLASS:6)
B(6,19,6,STAINED_GLASS:15)
B(7,19,6,STAINED_GLASS:10)
B(8,19,6,STAINED_GLASS:10)
B(9,19,6,STAINED_GLASS:15)
B(4,19,7,STAINED_GLASS:15)
B(5,19,7,STAINED_GLASS:6)
B(6,19,7,STAINED_GLASS:10)
B(7,19,7,SEA_LANTERN)
B(8,19,7,STAINED_GLASS:15)
B(9,19,7,STAINED_GLASS:15)
B(10,19,7,STAINED_GLASS:15)
B(5,19,8,STAINED_GLASS:15)
B(6,19,8,STAINED_GLASS:15)
B(7,19,8,STAINED_GLASS:15)
B(8,19,8,SEA_LANTERN)
B(9,19,8,STAINED_GLASS:10)
B(10,19,8,STAINED_GLASS:11)
B(11,19,8,STAINED_GLASS:15)
B(6,19,9,STAINED_GLASS:15)
B(7,19,9,STAINED_GLASS:15)
B(8,19,9,STAINED_GLASS:10)
B(9,19,9,STAINED_GLASS:15)
B(10,19,9,STAINED_GLASS:10)
B(11,19,9,STAINED_GLASS:15)
B(7,19,10,STAINED_GLASS:15)
B(8,19,10,STAINED_GLASS:15)
B(9,19,10,STAINED_GLASS:15)
B(10,19,10,STAINED_GLASS:15)
B(11,19,10,STAINED_GLASS:15)
B(8,19,11,STAINED_GLASS:15)
B(9,19,11,STAINED_GLASS:15)
B(10,19,11,STAINED_GLASS:15)
B(5,20,3,STAINED_GLASS:15)
B(6,20,3,STAINED_GLASS:15)
B(4,20,4,STAINED_GLASS:6)
B(5,20,4,STAINED_GLASS:6)
B(6,20,4,STAINED_GLASS:10)
B(7,20,4,STAINED_GLASS:15)
B(3,20,5,STAINED_GLASS:6)
B(4,20,5,STAINED_GLASS:6)
B(5,20,5,STAINED_GLASS:15)
B(6,20,5,STAINED_GLASS:15)
B(7,20,5,STAINED_GLASS:10)
B(8,20,5,STAINED_GLASS:15)
B(3,20,6,STAINED_GLASS:6)
B(4,20,6,STAINED_GLASS:6)
B(5,20,6,STAINED_GLASS:11)
B(6,20,6,SEA_LANTERN)
B(7,20,6,SEA_LANTERN)
B(8,20,6,STAINED_GLASS:15)
B(9,20,6,STAINED_GLASS:15)
B(4,20,7,STAINED_GLASS:6)
B(5,20,7,STAINED_GLASS:15)
B(6,20,7,STAINED_GLASS:15)
B(7,20,7,SEA_LANTERN)
B(8,20,7,STAINED_GLASS:11)
B(9,20,7,STAINED_GLASS:11)
B(10,20,7,STAINED_GLASS:15)
B(5,20,8,STAINED_GLASS:15)
B(6,20,8,STAINED_GLASS:15)
B(7,20,8,STAINED_GLASS:10)
B(8,20,8,STAINED_GLASS:15)
B(9,20,8,STAINED_GLASS:15)
B(10,20,8,STAINED_GLASS:15)
B(6,20,9,STAINED_GLASS:15)
B(7,20,9,STAINED_GLASS:15)
B(8,20,9,STAINED_GLASS:15)
B(9,20,9,STAINED_GLASS:15)
B(10,20,9,STAINED_GLASS:15)
B(7,20,10,STAINED_GLASS:15)
B(8,20,10,STAINED_GLASS:15)
B(9,20,10,STAINED_GLASS:15)
B(4,21,2,STAINED_GLASS:15)
B(5,21,2,STAINED_GLASS:15)
B(3,21,3,STAINED_GLASS:6)
B(4,21,3,STAINED_GLASS:6)
B(5,21,3,STAINED_GLASS:10)
B(6,21,3,STAINED_GLASS:15)
B(2,21,4,STAINED_GLASS:6)
B(3,21,4,STAINED_GLASS:6)
B(4,21,4,STAINED_GLASS:15)
B(5,21,4,STAINED_GLASS:15)
B(6,21,4,STAINED_GLASS:11)
B(7,21,4,STAINED_GLASS:15)
B(2,21,5,STAINED_GLASS:6)
B(3,21,5,STAINED_GLASS:6)
B(4,21,5,STAINED_GLASS:10)
B(5,21,5,SEA_LANTERN)
B(6,21,5,STAINED_GLASS:15)
B(7,21,5,STAINED_GLASS:15)
B(8,21,5,STAINED_GLASS:15)
B(3,21,6,STAINED_GLASS:6)
B(4,21,6,STAINED_GLASS:6)
B(5,21,6,SEA_LANTERN)
B(6,21,6,SEA_LANTERN)
B(7,21,6,STAINED_GLASS:11)
B(8,21,6,STAINED_GLASS:11)
B(9,21,6,STAINED_GLASS:15)
B(4,21,7,STAINED_GLASS:15)
B(5,21,7,STAINED_GLASS:15)
B(6,21,7,STAINED_GLASS:10)
B(7,21,7,STAINED_GLASS:15)
B(8,21,7,STAINED_GLASS:15)
B(9,21,7,STAINED_GLASS:15)
B(5,21,8,STAINED_GLASS:15)
B(6,21,8,STAINED_GLASS:15)
B(7,21,8,STAINED_GLASS:15)
B(8,21,8,STAINED_GLASS:15)
B(9,21,8,STAINED_GLASS:15)
B(6,21,9,STAINED_GLASS:15)
B(7,21,9,STAINED_GLASS:15)
B(8,21,9,STAINED_GLASS:15)
B(3,22,1,STAINED_GLASS:15)
B(4,22,1,STAINED_GLASS:15)
B(2,22,2,STAINED_GLASS:15)
B(3,22,2,STAINED_GLASS:15)
B(4,22,2,STAINED_GLASS:10)
B(5,22,2,STAINED_GLASS:15)
B(1,22,3,STAINED_GLASS:6)
B(2,22,3,STAINED_GLASS:6)
B(3,22,3,STAINED_GLASS:15)
B(4,22,3,STAINED_GLASS:15)
B(5,22,3,STAINED_GLASS:10)
B(6,22,3,STAINED_GLASS:15)
B(1,22,4,STAINED_GLASS:6)
B(2,22,4,STAINED_GLASS:6)
B(3,22,4,STAINED_GLASS:10)
B(4,22,4,SEA_LANTERN)
B(5,22,4,SEA_LANTERN)
B(6,22,4,STAINED_GLASS:15)
B(7,22,4,STAINED_GLASS:15)
B(2,22,5,STAINED_GLASS:6)
B(3,22,5,STAINED_GLASS:6)
B(4,22,5,STAINED_GLASS:15)
B(5,22,5,SEA_LANTERN)
B(6,22,5,STAINED_GLASS:15)
B(7,22,5,STAINED_GLASS:11)
B(8,22,5,STAINED_GLASS:15)
B(3,22,6,STAINED_GLASS:6)
B(4,22,6,STAINED_GLASS:15)
B(5,22,6,STAINED_GLASS:10)
B(6,22,6,STAINED_GLASS:15)
B(7,22,6,STAINED_GLASS:15)
B(8,22,6,STAINED_GLASS:15)
B(4,22,7,STAINED_GLASS:15)
B(5,22,7,STAINED_GLASS:15)
B(6,22,7,STAINED_GLASS:15)
B(7,22,7,STAINED_GLASS:15)
B(8,22,7,STAINED_GLASS:15)
B(5,22,8,STAINED_GLASS:15)
B(6,22,8,STAINED_GLASS:15)
B(7,22,8,STAINED_GLASS:15)
B(3,23,0,STAINED_GLASS:15)
B(2,23,1,STAINED_GLASS:15)
B(3,23,1,STAINED_GLASS:15)
B(4,23,1,STAINED_GLASS:15)
B(1,23,2,STAINED_GLASS:15)
B(2,23,2,STAINED_GLASS:15)
B(3,23,2,STAINED_GLASS:15)
B(4,23,2,STAINED_GLASS:10)
B(5,23,2,STAINED_GLASS:15)
B(0,23,3,STAINED_GLASS:15)
B(1,23,3,STAINED_GLASS:6)
B(2,23,3,STAINED_GLASS:10)
B(3,23,3,SEA_LANTERN)
B(4,23,3,SEA_LANTERN)
B(5,23,3,STAINED_GLASS:15)
B(6,23,3,STAINED_GLASS:15)
B(1,23,4,STAINED_GLASS:6)
B(2,23,4,STAINED_GLASS:6)
B(3,23,4,STAINED_GLASS:15)
B(4,23,4,SEA_LANTERN)
B(5,23,4,STAINED_GLASS:15)
B(6,23,4,STAINED_GLASS:11)
B(7,23,4,STAINED_GLASS:15)
B(2,23,5,STAINED_GLASS:6)
B(3,23,5,STAINED_GLASS:6)
B(4,23,5,STAINED_GLASS:11)
B(5,23,5,STAINED_GLASS:15)
B(6,23,5,STAINED_GLASS:15)
B(7,23,5,STAINED_GLASS:15)
B(3,23,6,STAINED_GLASS:6)
B(4,23,6,STAINED_GLASS:15)
B(5,23,6,STAINED_GLASS:15)
B(6,23,6,STAINED_GLASS:15)
B(7,23,6,STAINED_GLASS:15)
B(4,23,7,STAINED_GLASS:15)
B(5,23,7,STAINED_GLASS:15)
B(6,23,7,STAINED_GLASS:15)
B(2,24,0,STAINED_GLASS:15)
B(3,24,0,STAINED_GLASS:15)
B(1,24,1,STAINED_GLASS:15)
B(2,24,1,STAINED_GLASS:15)
B(3,24,1,STAINED_GLASS:15)
B(4,24,1,STAINED_GLASS:15)
B(0,24,2,STAINED_GLASS:6)
B(1,24,2,STAINED_GLASS:6)
B(2,24,2,STAINED_GLASS:15)
B(3,24,2,STAINED_GLASS:15)
B(4,24,2,STAINED_GLASS:15)
B(5,24,2,STAINED_GLASS:15)
B(0,24,3,STAINED_GLASS:6)
B(1,24,3,STAINED_GLASS:6)
B(2,24,3,STAINED_GLASS:6)
B(3,24,3,SEA_LANTERN)
B(4,24,3,STAINED_GLASS:15)
B(5,24,3,STAINED_GLASS:11)
B(6,24,3,STAINED_GLASS:15)
B(1,24,4,STAINED_GLASS:6)
B(2,24,4,STAINED_GLASS:6)
B(3,24,4,STAINED_GLASS:11)
B(4,24,4,STAINED_GLASS:15)
B(5,24,4,STAINED_GLASS:15)
B(6,24,4,STAINED_GLASS:15)
B(2,24,5,STAINED_GLASS:6)
B(3,24,5,STAINED_GLASS:6)
B(4,24,5,STAINED_GLASS:15)
B(5,24,5,STAINED_GLASS:15)
B(6,24,5,STAINED_GLASS:15)
B(3,24,6,STAINED_GLASS:6)
B(4,24,6,STAINED_GLASS:15)
B(5,24,6,STAINED_GLASS:15)
B(0,25,0,STAINED_GLASS:15)
B(1,25,0,STAINED_GLASS:15)
B(2,25,0,STAINED_GLASS:15)
B(0,25,1,STAINED_GLASS:15)
B(1,25,1,STAINED_GLASS:6)
B(2,25,1,STAINED_GLASS:15)
B(3,25,1,STAINED_GLASS:15)
B(4,25,1,STAINED_GLASS:15)
B(0,25,2,STAINED_GLASS:6)
B(1,25,2,STAINED_GLASS:6)
B(2,25,2,STAINED_GLASS:6)
B(3,25,2,STAINED_GLASS:15)
B(4,25,2,STAINED_GLASS:15)
B(5,25,2,STAINED_GLASS:15)
B(1,25,3,STAINED_GLASS:6)
B(2,25,3,STAINED_GLASS:6)
B(3,25,3,STAINED_GLASS:6)
B(4,25,3,STAINED_GLASS:15)
B(5,25,3,STAINED_GLASS:15)
B(1,25,4,STAINED_GLASS:6)
B(2,25,4,STAINED_GLASS:6)
B(3,25,4,STAINED_GLASS:6)
B(4,25,4,STAINED_GLASS:15)
B(5,25,4,STAINED_GLASS:15)
B(2,25,5,STAINED_GLASS:6)
B(3,25,5,STAINED_GLASS:15)
B(4,25,5,STAINED_GLASS:15)
B(0,26,0,STAINED_GLASS:6)
B(1,26,0,STAINED_GLASS:6)
B(0,26,1,STAINED_GLASS:6)
B(1,26,1,STAINED_GLASS:6)
B(2,26,1,STAINED_GLASS:6)
B(1,26,2,STAINED_GLASS:6)
B(2,26,2,STAINED_GLASS:6)
B(3,26,2,STAINED_GLASS:15)
B(2,26,3,STAINED_GLASS:6)
B(3,26,3,STAINED_GLASS:15)
B(4,26,3,STAINED_GLASS:15)
B(3,26,4,STAINED_GLASS:15)
B(0,27,0,STAINED_GLASS:6)
B(1,27,1,STAINED_GLASS:6)
B(2,27,2,STAINED_GLASS:6)

