#######################################################################
# +-----------------------------------------------------------------+ #
# |                            BO3 object                           | #
# +-----------------------------------------------------------------+ #
#######################################################################

# This is the config file of a custom object.
# If you add this object correctly to your BiomeConfigs, it will spawn in the world.

# This is the creator of this BO3 object
Author: BO3 BulkEdit (by LanToaster)

# A short description of this BO3 object
Description: This Object was Created with BO3_BulkEdit

# The BO3 version, don't change this! It can be used by external applications to do a version check.
Version: 3

# The settings mode, WriteAll, WriteWithoutComments or WriteDisable. See WorldConfig.
SettingsMode: WriteDisable


#######################################################################
# +-----------------------------------------------------------------+ #
# |                          Main settings                          | #
# +-----------------------------------------------------------------+ #
#######################################################################

# This needs to be set to true to spawn the object in the Tree and Sapling resources.
Tree: false

# The frequency of the BO3 from 1 to 200. Tries this many times to spawn this BO3 when using the CustomObject(...) resource.

Frequency: 1

# The rarity of the BO3 from 0 to 100. Each spawn attempt has rarity% chance to succeed when using the CustomObject(...) resource.

Rarity: 100.0

# If you set this to true, the BO3 will be placed with a random rotation.
RotateRandomly: false

# The spawn height of the BO3 - randomY, highestBlock or highestSolidBlock.
SpawnHeight: highestBlock

# The height limits for the BO3.
MinHeight: 0

MaxHeight: 256

# Objects can have other objects attacthed to it: branches. Branches can also
# have branches attached to it, which can also have branches, etc. This is the
# maximum branch depth for this objects.
MaxBranchDepth: 10

# When spawned with the UseWorld keyword, this BO3 should NOT spawn in the following biomes.
# If you writer.write the BO3 name directly in the BiomeConfigs, this will be ignored.
ExcludedBiomes: All


#######################################################################
# +-----------------------------------------------------------------+ #
# |                      Source block settings                      | #
# +-----------------------------------------------------------------+ #
#######################################################################

# The block(s) the BO3 should spawn in.
SourceBlocks: AIR

# The maximum percentage of the BO3 that can be outside the SourceBlock.
# The BO3 won't be placed on a location with more blocks outside the SourceBlock than this percentage.
MaxPercentageOutsideSourceBlock: 100

# What to do when a block is about to be placed outside the SourceBlock? (dontPlace, placeAnyway)
OutsideSourceBlock: placeAnyway


#######################################################################
# +-----------------------------------------------------------------+ #
# |                              Blocks                             | #
# +-----------------------------------------------------------------+ #
#######################################################################

# All the blocks used in the BO3 are listed here. Possible blocks:
# Block(x,y,z,id[.data][,nbtfile.nbt)
# RandomBlock(x,y,z,id[:data][,nbtfile.nbt],chance[,id[:data][,nbtfile.nbt],chance[,...]])
# So RandomBlock(0,0,0,CHEST,chest.nbt,50,CHEST,anotherchest.nbt,100) will spawn a chest at
# the BO3 origin, and give it a 50% chance to have the contents of chest.nbt, or, if that
# fails, a 100% percent chance to have the contents of anotherchest.nbt.
Block(8,9,8,STAINED_GLASS:2)
Block(8,10,7,STAINED_GLASS:2)
Block(7,10,8,STAINED_GLASS:2)
Block(8,10,8,STAINED_GLASS:2)
Block(8,11,5,STAINED_GLASS:15)
Block(7,11,6,STAINED_GLASS:2)
Block(8,11,6,STAINED_GLASS:2)
Block(7,11,7,STAINED_GLASS:2)
Block(8,11,7,STAINED_GLASS:2)
Block(7,11,8,STAINED_GLASS:2)
Block(8,11,8,STAINED_GLASS:2)
Block(8,12,4,STAINED_GLASS:15)
Block(7,12,5,STAINED_GLASS:15)
Block(8,12,5,STAINED_GLASS:15)
Block(7,12,6,STAINED_GLASS:2)
Block(8,12,6,STAINED_GLASS:15)
Block(7,12,7,STAINED_GLASS:2)
Block(8,12,7,STAINED_GLASS:2)
Block(7,12,8,STAINED_GLASS:2)
Block(8,12,8,STAINED_GLASS:2)
Block(8,13,3,STAINED_GLASS:15)
Block(7,13,4,STAINED_GLASS:15)
Block(8,13,4,STAINED_GLASS:15)
Block(6,13,5,STAINED_GLASS:2)
Block(7,13,5,STAINED_GLASS:2)
Block(8,13,5,STAINED_GLASS:15)
Block(6,13,6,STAINED_GLASS:2)
Block(7,13,6,STAINED_GLASS:2)
Block(8,13,6,STAINED_GLASS:15)
Block(7,13,7,STAINED_GLASS:2)
Block(8,13,7,STAINED_GLASS:15)
Block(7,13,8,STAINED_GLASS:15)
Block(8,13,8,STAINED_GLASS:9)
Block(7,14,2,STAINED_GLASS:2)
Block(8,14,2,STAINED_GLASS:15)
Block(6,14,3,STAINED_GLASS:2)
Block(7,14,3,STAINED_GLASS:2)
Block(8,14,3,STAINED_GLASS:15)
Block(5,14,4,STAINED_GLASS:2)
Block(6,14,4,STAINED_GLASS:2)
Block(7,14,4,STAINED_GLASS:2)
Block(8,14,4,STAINED_GLASS:9)
Block(5,14,5,STAINED_GLASS:15)
Block(6,14,5,STAINED_GLASS:2)
Block(7,14,5,STAINED_GLASS:15)
Block(8,14,5,STAINED_GLASS:9)
Block(6,14,6,STAINED_GLASS:2)
Block(7,14,6,STAINED_GLASS:2)
Block(8,14,6,STAINED_GLASS:9)
Block(7,14,7,STAINED_GLASS:15)
Block(8,14,7,STAINED_GLASS:9)
Block(7,14,8,STAINED_GLASS:15)
Block(8,14,8,STAINED_GLASS:15)
Block(8,15,1,STAINED_GLASS:15)
Block(6,15,2,STAINED_GLASS:2)
Block(7,15,2,STAINED_GLASS:15)
Block(8,15,2,STAINED_GLASS:15)
Block(5,15,3,STAINED_GLASS:2)
Block(6,15,3,STAINED_GLASS:2)
Block(7,15,3,STAINED_GLASS:9)
Block(8,15,3,STAINED_GLASS:15)
Block(5,15,4,STAINED_GLASS:2)
Block(6,15,4,STAINED_GLASS:2)
Block(7,15,4,STAINED_GLASS:15)
Block(8,15,4,SEA_LANTERN:0)
Block(5,15,5,STAINED_GLASS:15)
Block(6,15,5,STAINED_GLASS:15)
Block(7,15,5,STAINED_GLASS:9)
Block(8,15,5,STAINED_GLASS:9)
Block(6,15,6,STAINED_GLASS:15)
Block(7,15,6,STAINED_GLASS:15)
Block(8,15,6,SEA_LANTERN:0)
Block(7,15,7,STAINED_GLASS:15)
Block(8,15,7,STAINED_GLASS:14)
Block(7,15,8,STAINED_GLASS:15)
Block(8,15,8,STAINED_GLASS:15)
Block(7,16,0,STAINED_GLASS:2)
Block(8,16,0,STAINED_GLASS:2)
Block(6,16,1,STAINED_GLASS:2)
Block(7,16,1,STAINED_GLASS:2)
Block(8,16,1,STAINED_GLASS:2)
Block(4,16,2,STAINED_GLASS:15)
Block(5,16,2,STAINED_GLASS:2)
Block(6,16,2,STAINED_GLASS:9)
Block(7,16,2,STAINED_GLASS:15)
Block(8,16,2,STAINED_GLASS:9)
Block(4,16,3,STAINED_GLASS:2)
Block(5,16,3,STAINED_GLASS:2)
Block(6,16,3,STAINED_GLASS:2)
Block(7,16,3,SEA_LANTERN:0)
Block(8,16,3,STAINED_GLASS:9)
Block(4,16,4,STAINED_GLASS:15)
Block(5,16,4,STAINED_GLASS:2)
Block(6,16,4,STAINED_GLASS:14)
Block(7,16,4,STAINED_GLASS:9)
Block(8,16,4,SEA_LANTERN:0)
Block(5,16,5,STAINED_GLASS:15)
Block(6,16,5,STAINED_GLASS:15)
Block(7,16,5,SEA_LANTERN:0)
Block(8,16,5,SEA_LANTERN:0)
Block(6,16,6,STAINED_GLASS:15)
Block(7,16,6,STAINED_GLASS:14)
Block(8,16,6,STAINED_GLASS:14)
Block(7,16,7,STAINED_GLASS:15)
Block(8,16,7,STAINED_GLASS:15)
Block(7,16,8,STAINED_GLASS:15)
Block(8,16,8,STAINED_GLASS:15)
Block(7,17,-1,STAINED_GLASS:2)
Block(8,17,-1,STAINED_GLASS:2)
Block(6,17,0,STAINED_GLASS:2)
Block(7,17,0,STAINED_GLASS:2)
Block(8,17,0,STAINED_GLASS:2)
Block(5,17,1,STAINED_GLASS:15)
Block(6,17,1,STAINED_GLASS:15)
Block(7,17,1,STAINED_GLASS:2)
Block(8,17,1,STAINED_GLASS:15)
Block(3,17,2,STAINED_GLASS:15)
Block(4,17,2,STAINED_GLASS:15)
Block(5,17,2,STAINED_GLASS:15)
Block(6,17,2,STAINED_GLASS:9)
Block(7,17,2,STAINED_GLASS:9)
Block(8,17,2,STAINED_GLASS:9)
Block(4,17,3,STAINED_GLASS:15)
Block(5,17,3,STAINED_GLASS:15)
Block(6,17,3,STAINED_GLASS:14)
Block(7,17,3,SEA_LANTERN:0)
Block(8,17,3,SEA_LANTERN:0)
Block(4,17,4,STAINED_GLASS:15)
Block(5,17,4,STAINED_GLASS:15)
Block(6,17,4,STAINED_GLASS:14)
Block(7,17,4,SEA_LANTERN:0)
Block(8,17,4,SEA_LANTERN:0)
Block(5,17,5,STAINED_GLASS:15)
Block(6,17,5,STAINED_GLASS:14)
Block(7,17,5,SEA_LANTERN:0)
Block(8,17,5,STAINED_GLASS:14)
Block(6,17,6,STAINED_GLASS:15)
Block(7,17,6,STAINED_GLASS:15)
Block(8,17,6,STAINED_GLASS:14)
Block(7,17,7,STAINED_GLASS:15)
Block(8,17,7,STAINED_GLASS:15)
Block(7,17,8,STAINED_GLASS:15)
Block(8,17,8,STAINED_GLASS:15)
Block(6,18,-2,STAINED_GLASS:2)
Block(7,18,-2,STAINED_GLASS:2)
Block(5,18,-1,STAINED_GLASS:15)
Block(6,18,-1,STAINED_GLASS:2)
Block(7,18,-1,STAINED_GLASS:2)
Block(8,18,-1,STAINED_GLASS:2)
Block(3,18,0,STAINED_GLASS:15)
Block(4,18,0,STAINED_GLASS:15)
Block(5,18,0,STAINED_GLASS:15)
Block(6,18,0,STAINED_GLASS:15)
Block(7,18,0,STAINED_GLASS:2)
Block(8,18,0,STAINED_GLASS:15)
Block(3,18,1,STAINED_GLASS:15)
Block(4,18,1,STAINED_GLASS:15)
Block(5,18,1,STAINED_GLASS:15)
Block(6,18,1,STAINED_GLASS:9)
Block(7,18,1,STAINED_GLASS:9)
Block(8,18,1,STAINED_GLASS:9)
Block(3,18,2,STAINED_GLASS:15)
Block(4,18,2,STAINED_GLASS:15)
Block(5,18,2,STAINED_GLASS:14)
Block(6,18,2,SEA_LANTERN:0)
Block(7,18,2,SEA_LANTERN:0)
Block(8,18,2,SEA_LANTERN:0)
Block(4,18,3,STAINED_GLASS:15)
Block(5,18,3,STAINED_GLASS:14)
Block(6,18,3,SEA_LANTERN:0)
Block(7,18,3,SEA_LANTERN:0)
Block(8,18,3,STAINED_GLASS:9)
Block(4,18,4,STAINED_GLASS:15)
Block(5,18,4,STAINED_GLASS:14)
Block(6,18,4,SEA_LANTERN:0)
Block(7,18,4,STAINED_GLASS:14)
Block(8,18,4,SEA_LANTERN:0)
Block(5,18,5,STAINED_GLASS:15)
Block(6,18,5,STAINED_GLASS:15)
Block(7,18,5,STAINED_GLASS:14)
Block(8,18,5,STAINED_GLASS:15)
Block(6,18,6,STAINED_GLASS:15)
Block(7,18,6,STAINED_GLASS:15)
Block(8,18,6,STAINED_GLASS:15)
Block(7,18,7,STAINED_GLASS:15)
Block(8,18,7,STAINED_GLASS:15)
Block(5,19,-2,STAINED_GLASS:15)
Block(6,19,-2,STAINED_GLASS:2)
Block(7,19,-2,STAINED_GLASS:2)
Block(3,19,-1,STAINED_GLASS:15)
Block(4,19,-1,STAINED_GLASS:15)
Block(5,19,-1,STAINED_GLASS:15)
Block(6,19,-1,STAINED_GLASS:2)
Block(7,19,-1,STAINED_GLASS:2)
Block(8,19,-1,STAINED_GLASS:2)
Block(3,19,0,STAINED_GLASS:15)
Block(4,19,0,STAINED_GLASS:15)
Block(5,19,0,STAINED_GLASS:9)
Block(6,19,0,STAINED_GLASS:15)
Block(7,19,0,STAINED_GLASS:9)
Block(8,19,0,STAINED_GLASS:15)
Block(3,19,1,STAINED_GLASS:15)
Block(4,19,1,STAINED_GLASS:15)
Block(5,19,1,STAINED_GLASS:15)
Block(6,19,1,SEA_LANTERN:0)
Block(7,19,1,STAINED_GLASS:9)
Block(8,19,1,SEA_LANTERN:0)
Block(3,19,2,STAINED_GLASS:15)
Block(4,19,2,STAINED_GLASS:14)
Block(5,19,2,STAINED_GLASS:14)
Block(6,19,2,SEA_LANTERN:0)
Block(7,19,2,SEA_LANTERN:0)
Block(8,19,2,STAINED_GLASS:9)
Block(4,19,3,STAINED_GLASS:15)
Block(5,19,3,SEA_LANTERN:0)
Block(6,19,3,SEA_LANTERN:0)
Block(7,19,3,SEA_LANTERN:0)
Block(8,19,3,STAINED_GLASS:9)
Block(4,19,4,STAINED_GLASS:15)
Block(5,19,4,STAINED_GLASS:14)
Block(6,19,4,STAINED_GLASS:14)
Block(7,19,4,STAINED_GLASS:14)
Block(8,19,4,STAINED_GLASS:9)
Block(5,19,5,STAINED_GLASS:15)
Block(6,19,5,STAINED_GLASS:15)
Block(7,19,5,STAINED_GLASS:15)
Block(8,19,5,STAINED_GLASS:15)
Block(6,19,6,STAINED_GLASS:15)
Block(7,19,6,STAINED_GLASS:15)
Block(8,19,6,STAINED_GLASS:15)
Block(7,19,7,STAINED_GLASS:15)
Block(8,19,7,STAINED_GLASS:15)
Block(5,20,-3,STAINED_GLASS:2)
Block(6,20,-3,STAINED_GLASS:2)
Block(3,20,-2,STAINED_GLASS:15)
Block(4,20,-2,STAINED_GLASS:15)
Block(5,20,-2,STAINED_GLASS:15)
Block(6,20,-2,STAINED_GLASS:2)
Block(7,20,-2,STAINED_GLASS:2)
Block(2,20,-1,STAINED_GLASS:15)
Block(3,20,-1,STAINED_GLASS:15)
Block(4,20,-1,STAINED_GLASS:15)
Block(5,20,-1,STAINED_GLASS:15)
Block(6,20,-1,STAINED_GLASS:2)
Block(7,20,-1,STAINED_GLASS:2)
Block(8,20,-1,STAINED_GLASS:2)
Block(2,20,0,STAINED_GLASS:15)
Block(3,20,0,STAINED_GLASS:15)
Block(4,20,0,STAINED_GLASS:15)
Block(5,20,0,STAINED_GLASS:9)
Block(6,20,0,STAINED_GLASS:9)
Block(7,20,0,STAINED_GLASS:9)
Block(8,20,0,STAINED_GLASS:9)
Block(3,20,1,STAINED_GLASS:15)
Block(4,20,1,STAINED_GLASS:15)
Block(5,20,1,STAINED_GLASS:14)
Block(6,20,1,SEA_LANTERN:0)
Block(7,20,1,SEA_LANTERN:0)
Block(8,20,1,SEA_LANTERN:0)
Block(3,20,2,STAINED_GLASS:15)
Block(4,20,2,STAINED_GLASS:14)
Block(5,20,2,SEA_LANTERN:0)
Block(6,20,2,SEA_LANTERN:0)
Block(7,20,2,STAINED_GLASS:9)
Block(8,20,2,STAINED_GLASS:9)
Block(4,20,3,STAINED_GLASS:14)
Block(5,20,3,SEA_LANTERN:0)
Block(6,20,3,STAINED_GLASS:9)
Block(7,20,3,SEA_LANTERN:0)
Block(8,20,3,STAINED_GLASS:15)
Block(4,20,4,STAINED_GLASS:15)
Block(5,20,4,STAINED_GLASS:15)
Block(6,20,4,STAINED_GLASS:14)
Block(7,20,4,STAINED_GLASS:15)
Block(8,20,4,STAINED_GLASS:9)
Block(5,20,5,STAINED_GLASS:15)
Block(6,20,5,STAINED_GLASS:15)
Block(7,20,5,STAINED_GLASS:15)
Block(8,20,5,STAINED_GLASS:15)
Block(6,20,6,STAINED_GLASS:15)
Block(7,20,6,STAINED_GLASS:15)
Block(8,20,6,STAINED_GLASS:15)
Block(3,21,-4,STAINED_GLASS:15)
Block(4,21,-4,STAINED_GLASS:15)
Block(5,21,-4,STAINED_GLASS:2)
Block(2,21,-3,STAINED_GLASS:15)
Block(3,21,-3,STAINED_GLASS:15)
Block(4,21,-3,STAINED_GLASS:15)
Block(5,21,-3,STAINED_GLASS:2)
Block(6,21,-3,STAINED_GLASS:2)
Block(1,21,-2,STAINED_GLASS:15)
Block(2,21,-2,STAINED_GLASS:15)
Block(3,21,-2,STAINED_GLASS:15)
Block(4,21,-2,STAINED_GLASS:15)
Block(5,21,-2,STAINED_GLASS:2)
Block(6,21,-2,STAINED_GLASS:2)
Block(7,21,-2,STAINED_GLASS:2)
Block(1,21,-1,STAINED_GLASS:15)
Block(2,21,-1,STAINED_GLASS:15)
Block(3,21,-1,STAINED_GLASS:15)
Block(4,21,-1,STAINED_GLASS:9)
Block(5,21,-1,STAINED_GLASS:9)
Block(6,21,-1,STAINED_GLASS:9)
Block(7,21,-1,STAINED_GLASS:9)
Block(8,21,-1,STAINED_GLASS:15)
Block(2,21,0,STAINED_GLASS:15)
Block(3,21,0,STAINED_GLASS:15)
Block(4,21,0,STAINED_GLASS:14)
Block(5,21,0,SEA_LANTERN:0)
Block(6,21,0,SEA_LANTERN:0)
Block(7,21,0,SEA_LANTERN:0)
Block(8,21,0,STAINED_GLASS:15)
Block(3,21,1,STAINED_GLASS:15)
Block(4,21,1,STAINED_GLASS:14)
Block(5,21,1,SEA_LANTERN:0)
Block(6,21,1,SEA_LANTERN:0)
Block(7,21,1,STAINED_GLASS:9)
Block(8,21,1,STAINED_GLASS:9)
Block(3,21,2,STAINED_GLASS:15)
Block(4,21,2,SEA_LANTERN:0)
Block(5,21,2,STAINED_GLASS:14)
Block(6,21,2,SEA_LANTERN:0)
Block(7,21,2,STAINED_GLASS:15)
Block(8,21,2,STAINED_GLASS:15)
Block(4,21,3,STAINED_GLASS:15)
Block(5,21,3,STAINED_GLASS:14)
Block(6,21,3,STAINED_GLASS:15)
Block(7,21,3,STAINED_GLASS:9)
Block(8,21,3,STAINED_GLASS:15)
Block(4,21,4,STAINED_GLASS:15)
Block(5,21,4,STAINED_GLASS:15)
Block(6,21,4,STAINED_GLASS:15)
Block(7,21,4,STAINED_GLASS:15)
Block(8,21,4,STAINED_GLASS:15)
Block(5,21,5,STAINED_GLASS:15)
Block(6,21,5,STAINED_GLASS:15)
Block(7,21,5,STAINED_GLASS:15)
Block(2,22,-4,STAINED_GLASS:15)
Block(3,22,-4,STAINED_GLASS:15)
Block(4,22,-4,STAINED_GLASS:15)
Block(5,22,-4,STAINED_GLASS:15)
Block(1,22,-3,STAINED_GLASS:15)
Block(2,22,-3,STAINED_GLASS:15)
Block(3,22,-3,STAINED_GLASS:9)
Block(4,22,-3,STAINED_GLASS:15)
Block(5,22,-3,STAINED_GLASS:2)
Block(6,22,-3,STAINED_GLASS:2)
Block(1,22,-2,STAINED_GLASS:15)
Block(2,22,-2,STAINED_GLASS:15)
Block(3,22,-2,STAINED_GLASS:15)
Block(4,22,-2,STAINED_GLASS:15)
Block(5,22,-2,STAINED_GLASS:9)
Block(6,22,-2,STAINED_GLASS:2)
Block(7,22,-2,STAINED_GLASS:15)
Block(1,22,-1,STAINED_GLASS:15)
Block(2,22,-1,STAINED_GLASS:15)
Block(3,22,-1,STAINED_GLASS:14)
Block(4,22,-1,SEA_LANTERN:0)
Block(5,22,-1,STAINED_GLASS:9)
Block(6,22,-1,SEA_LANTERN:0)
Block(7,22,-1,STAINED_GLASS:9)
Block(8,22,-1,STAINED_GLASS:15)
Block(2,22,0,STAINED_GLASS:15)
Block(3,22,0,STAINED_GLASS:15)
Block(4,22,0,STAINED_GLASS:14)
Block(5,22,0,SEA_LANTERN:0)
Block(6,22,0,SEA_LANTERN:0)
Block(7,22,0,STAINED_GLASS:9)
Block(8,22,0,STAINED_GLASS:15)
Block(3,22,1,STAINED_GLASS:15)
Block(4,22,1,SEA_LANTERN:0)
Block(5,22,1,SEA_LANTERN:0)
Block(6,22,1,SEA_LANTERN:0)
Block(7,22,1,STAINED_GLASS:9)
Block(8,22,1,STAINED_GLASS:15)
Block(3,22,2,STAINED_GLASS:15)
Block(4,22,2,STAINED_GLASS:14)
Block(5,22,2,STAINED_GLASS:9)
Block(6,22,2,STAINED_GLASS:9)
Block(7,22,2,STAINED_GLASS:15)
Block(8,22,2,STAINED_GLASS:15)
Block(4,22,3,STAINED_GLASS:15)
Block(5,22,3,STAINED_GLASS:15)
Block(6,22,3,STAINED_GLASS:15)
Block(7,22,3,STAINED_GLASS:15)
Block(8,22,3,STAINED_GLASS:15)
Block(4,22,4,STAINED_GLASS:15)
Block(5,22,4,STAINED_GLASS:15)
Block(6,22,4,STAINED_GLASS:15)
Block(7,22,4,STAINED_GLASS:15)
Block(5,22,5,STAINED_GLASS:15)
Block(6,22,5,STAINED_GLASS:15)
Block(3,23,-6,STAINED_GLASS:15)
Block(2,23,-5,STAINED_GLASS:15)
Block(3,23,-5,STAINED_GLASS:15)
Block(4,23,-5,STAINED_GLASS:15)
Block(5,23,-5,STAINED_GLASS:15)
Block(0,23,-4,STAINED_GLASS:15)
Block(1,23,-4,STAINED_GLASS:15)
Block(2,23,-4,STAINED_GLASS:9)
Block(3,23,-4,STAINED_GLASS:15)
Block(4,23,-4,STAINED_GLASS:15)
Block(5,23,-4,STAINED_GLASS:2)
Block(0,23,-3,STAINED_GLASS:15)
Block(1,23,-3,STAINED_GLASS:15)
Block(2,23,-3,STAINED_GLASS:15)
Block(3,23,-3,SEA_LANTERN:0)
Block(4,23,-3,STAINED_GLASS:9)
Block(5,23,-3,STAINED_GLASS:2)
Block(6,23,-3,STAINED_GLASS:2)
Block(0,23,-2,STAINED_GLASS:15)
Block(1,23,-2,STAINED_GLASS:15)
Block(2,23,-2,STAINED_GLASS:14)
Block(3,23,-2,STAINED_GLASS:14)
Block(4,23,-2,STAINED_GLASS:9)
Block(5,23,-2,SEA_LANTERN:0)
Block(6,23,-2,STAINED_GLASS:9)
Block(7,23,-2,STAINED_GLASS:2)
Block(1,23,-1,STAINED_GLASS:15)
Block(2,23,-1,STAINED_GLASS:15)
Block(3,23,-1,SEA_LANTERN:0)
Block(4,23,-1,SEA_LANTERN:0)
Block(5,23,-1,SEA_LANTERN:0)
Block(6,23,-1,STAINED_GLASS:9)
Block(7,23,-1,STAINED_GLASS:15)
Block(8,23,-1,STAINED_GLASS:15)
Block(2,23,0,STAINED_GLASS:15)
Block(3,23,0,STAINED_GLASS:14)
Block(4,23,0,SEA_LANTERN:0)
Block(5,23,0,SEA_LANTERN:0)
Block(6,23,0,STAINED_GLASS:9)
Block(7,23,0,STAINED_GLASS:15)
Block(8,23,0,STAINED_GLASS:15)
Block(3,23,1,STAINED_GLASS:15)
Block(4,23,1,STAINED_GLASS:14)
Block(5,23,1,STAINED_GLASS:9)
Block(6,23,1,STAINED_GLASS:9)
Block(7,23,1,STAINED_GLASS:15)
Block(8,23,1,STAINED_GLASS:15)
Block(3,23,2,STAINED_GLASS:15)
Block(4,23,2,STAINED_GLASS:15)
Block(5,23,2,STAINED_GLASS:15)
Block(6,23,2,STAINED_GLASS:15)
Block(7,23,2,STAINED_GLASS:15)
Block(4,23,3,STAINED_GLASS:15)
Block(5,23,3,STAINED_GLASS:15)
Block(6,23,3,STAINED_GLASS:15)
Block(4,23,4,STAINED_GLASS:15)
Block(5,23,4,STAINED_GLASS:15)
Block(3,24,-7,STAINED_GLASS:15)
Block(4,24,-7,STAINED_GLASS:15)
Block(2,24,-6,STAINED_GLASS:15)
Block(3,24,-6,STAINED_GLASS:15)
Block(4,24,-6,STAINED_GLASS:15)
Block(1,24,-5,STAINED_GLASS:15)
Block(2,24,-5,STAINED_GLASS:15)
Block(3,24,-5,STAINED_GLASS:15)
Block(4,24,-5,STAINED_GLASS:15)
Block(5,24,-5,STAINED_GLASS:15)
Block(-1,24,-4,STAINED_GLASS:15)
Block(0,24,-4,STAINED_GLASS:15)
Block(1,24,-4,STAINED_GLASS:15)
Block(2,24,-4,STAINED_GLASS:9)
Block(3,24,-4,STAINED_GLASS:9)
Block(4,24,-4,STAINED_GLASS:15)
Block(5,24,-4,STAINED_GLASS:2)
Block(-1,24,-3,STAINED_GLASS:15)
Block(0,24,-3,STAINED_GLASS:15)
Block(1,24,-3,STAINED_GLASS:15)
Block(2,24,-3,STAINED_GLASS:14)
Block(3,24,-3,SEA_LANTERN:0)
Block(4,24,-3,STAINED_GLASS:9)
Block(5,24,-3,STAINED_GLASS:9)
Block(6,24,-3,STAINED_GLASS:2)
Block(0,24,-2,STAINED_GLASS:15)
Block(1,24,-2,STAINED_GLASS:15)
Block(2,24,-2,STAINED_GLASS:14)
Block(3,24,-2,SEA_LANTERN:0)
Block(4,24,-2,SEA_LANTERN:0)
Block(5,24,-2,SEA_LANTERN:0)
Block(6,24,-2,STAINED_GLASS:2)
Block(7,24,-2,STAINED_GLASS:2)
Block(1,24,-1,STAINED_GLASS:15)
Block(2,24,-1,STAINED_GLASS:14)
Block(3,24,-1,SEA_LANTERN:0)
Block(4,24,-1,SEA_LANTERN:0)
Block(5,24,-1,STAINED_GLASS:9)
Block(6,24,-1,STAINED_GLASS:9)
Block(7,24,-1,STAINED_GLASS:15)
Block(8,24,-1,STAINED_GLASS:15)
Block(2,24,0,STAINED_GLASS:15)
Block(3,24,0,STAINED_GLASS:15)
Block(4,24,0,STAINED_GLASS:9)
Block(5,24,0,SEA_LANTERN:0)
Block(6,24,0,STAINED_GLASS:15)
Block(7,24,0,STAINED_GLASS:15)
Block(8,24,0,STAINED_GLASS:15)
Block(3,24,1,STAINED_GLASS:15)
Block(4,24,1,STAINED_GLASS:9)
Block(5,24,1,STAINED_GLASS:15)
Block(6,24,1,STAINED_GLASS:9)
Block(7,24,1,STAINED_GLASS:15)
Block(8,24,1,STAINED_GLASS:15)
Block(3,24,2,STAINED_GLASS:15)
Block(4,24,2,STAINED_GLASS:15)
Block(5,24,2,STAINED_GLASS:15)
Block(6,24,2,STAINED_GLASS:15)
Block(4,24,3,STAINED_GLASS:15)
Block(5,24,3,STAINED_GLASS:15)
Block(2,25,-7,STAINED_GLASS:15)
Block(3,25,-7,STAINED_GLASS:15)
Block(4,25,-7,STAINED_GLASS:15)
Block(1,25,-6,STAINED_GLASS:15)
Block(2,25,-6,STAINED_GLASS:15)
Block(3,25,-6,STAINED_GLASS:15)
Block(4,25,-6,STAINED_GLASS:15)
Block(0,25,-5,STAINED_GLASS:15)
Block(1,25,-5,STAINED_GLASS:15)
Block(2,25,-5,STAINED_GLASS:9)
Block(3,25,-5,STAINED_GLASS:15)
Block(4,25,-5,STAINED_GLASS:15)
Block(5,25,-5,STAINED_GLASS:15)
Block(-1,25,-4,STAINED_GLASS:15)
Block(0,25,-4,STAINED_GLASS:15)
Block(1,25,-4,STAINED_GLASS:15)
Block(2,25,-4,SEA_LANTERN:0)
Block(3,25,-4,STAINED_GLASS:9)
Block(4,25,-4,STAINED_GLASS:2)
Block(5,25,-4,STAINED_GLASS:2)
Block(-1,25,-3,STAINED_GLASS:15)
Block(0,25,-3,STAINED_GLASS:15)
Block(1,25,-3,STAINED_GLASS:14)
Block(2,25,-3,STAINED_GLASS:14)
Block(3,25,-3,SEA_LANTERN:0)
Block(4,25,-3,SEA_LANTERN:0)
Block(5,25,-3,STAINED_GLASS:9)
Block(6,25,-3,STAINED_GLASS:2)
Block(0,25,-2,STAINED_GLASS:15)
Block(1,25,-2,STAINED_GLASS:15)
Block(2,25,-2,SEA_LANTERN:0)
Block(3,25,-2,SEA_LANTERN:0)
Block(4,25,-2,SEA_LANTERN:0)
Block(5,25,-2,STAINED_GLASS:9)
Block(6,25,-2,STAINED_GLASS:2)
Block(7,25,-2,STAINED_GLASS:15)
Block(1,25,-1,STAINED_GLASS:15)
Block(2,25,-1,STAINED_GLASS:14)
Block(3,25,-1,STAINED_GLASS:14)
Block(4,25,-1,SEA_LANTERN:0)
Block(5,25,-1,STAINED_GLASS:9)
Block(6,25,-1,STAINED_GLASS:15)
Block(7,25,-1,STAINED_GLASS:15)
Block(8,25,-1,STAINED_GLASS:15)
Block(2,25,0,STAINED_GLASS:15)
Block(3,25,0,STAINED_GLASS:15)
Block(4,25,0,STAINED_GLASS:9)
Block(5,25,0,STAINED_GLASS:9)
Block(6,25,0,STAINED_GLASS:15)
Block(7,25,0,STAINED_GLASS:15)
Block(8,25,0,STAINED_GLASS:15)
Block(3,25,1,STAINED_GLASS:15)
Block(4,25,1,STAINED_GLASS:15)
Block(5,25,1,STAINED_GLASS:15)
Block(6,25,1,STAINED_GLASS:15)
Block(7,25,1,STAINED_GLASS:15)
Block(3,25,2,STAINED_GLASS:15)
Block(4,25,2,STAINED_GLASS:15)
Block(5,25,2,STAINED_GLASS:15)
Block(4,25,3,STAINED_GLASS:15)
Block(0,26,-7,STAINED_GLASS:15)
Block(1,26,-7,STAINED_GLASS:15)
Block(2,26,-7,STAINED_GLASS:15)
Block(3,26,-7,STAINED_GLASS:15)
Block(4,26,-7,STAINED_GLASS:15)
Block(-1,26,-6,STAINED_GLASS:15)
Block(0,26,-6,STAINED_GLASS:15)
Block(1,26,-6,STAINED_GLASS:14)
Block(2,26,-6,STAINED_GLASS:15)
Block(3,26,-6,STAINED_GLASS:9)
Block(4,26,-6,STAINED_GLASS:15)
Block(-1,26,-5,STAINED_GLASS:15)
Block(0,26,-5,STAINED_GLASS:15)
Block(1,26,-5,STAINED_GLASS:15)
Block(2,26,-5,SEA_LANTERN:0)
Block(3,26,-5,STAINED_GLASS:9)
Block(4,26,-5,STAINED_GLASS:15)
Block(5,26,-5,STAINED_GLASS:2)
Block(-1,26,-4,STAINED_GLASS:15)
Block(0,26,-4,STAINED_GLASS:14)
Block(1,26,-4,STAINED_GLASS:14)
Block(2,26,-4,SEA_LANTERN:0)
Block(3,26,-4,SEA_LANTERN:0)
Block(4,26,-4,STAINED_GLASS:9)
Block(5,26,-4,STAINED_GLASS:2)
Block(-1,26,-3,STAINED_GLASS:15)
Block(0,26,-3,STAINED_GLASS:15)
Block(1,26,-3,SEA_LANTERN:0)
Block(2,26,-3,SEA_LANTERN:0)
Block(3,26,-3,SEA_LANTERN:0)
Block(4,26,-3,STAINED_GLASS:9)
Block(5,26,-3,STAINED_GLASS:2)
Block(6,26,-3,STAINED_GLASS:2)
Block(0,26,-2,STAINED_GLASS:15)
Block(1,26,-2,STAINED_GLASS:14)
Block(2,26,-2,STAINED_GLASS:14)
Block(3,26,-2,STAINED_GLASS:9)
Block(4,26,-2,STAINED_GLASS:9)
Block(5,26,-2,STAINED_GLASS:15)
Block(6,26,-2,STAINED_GLASS:15)
Block(7,26,-2,STAINED_GLASS:15)
Block(1,26,-1,STAINED_GLASS:15)
Block(2,26,-1,STAINED_GLASS:15)
Block(3,26,-1,STAINED_GLASS:15)
Block(4,26,-1,STAINED_GLASS:9)
Block(5,26,-1,STAINED_GLASS:15)
Block(6,26,-1,STAINED_GLASS:15)
Block(7,26,-1,STAINED_GLASS:15)
Block(2,26,0,STAINED_GLASS:15)
Block(3,26,0,STAINED_GLASS:15)
Block(4,26,0,STAINED_GLASS:15)
Block(5,26,0,STAINED_GLASS:15)
Block(6,26,0,STAINED_GLASS:15)
Block(3,26,1,STAINED_GLASS:15)
Block(4,26,1,STAINED_GLASS:15)
Block(5,26,1,STAINED_GLASS:15)
Block(-2,27,-7,STAINED_GLASS:15)
Block(-1,27,-7,STAINED_GLASS:15)
Block(0,27,-7,STAINED_GLASS:15)
Block(1,27,-7,STAINED_GLASS:15)
Block(2,27,-7,STAINED_GLASS:15)
Block(3,27,-7,STAINED_GLASS:15)
Block(4,27,-7,STAINED_GLASS:15)
Block(-2,27,-6,STAINED_GLASS:15)
Block(-1,27,-6,STAINED_GLASS:15)
Block(0,27,-6,STAINED_GLASS:15)
Block(1,27,-6,STAINED_GLASS:14)
Block(2,27,-6,STAINED_GLASS:9)
Block(3,27,-6,STAINED_GLASS:9)
Block(4,27,-6,STAINED_GLASS:15)
Block(-1,27,-5,STAINED_GLASS:15)
Block(0,27,-5,STAINED_GLASS:15)
Block(1,27,-5,STAINED_GLASS:14)
Block(2,27,-5,SEA_LANTERN:0)
Block(3,27,-5,SEA_LANTERN:0)
Block(4,27,-5,STAINED_GLASS:9)
Block(5,27,-5,STAINED_GLASS:2)
Block(-1,27,-4,STAINED_GLASS:15)
Block(0,27,-4,STAINED_GLASS:14)
Block(1,27,-4,SEA_LANTERN:0)
Block(2,27,-4,SEA_LANTERN:0)
Block(3,27,-4,STAINED_GLASS:9)
Block(4,27,-4,STAINED_GLASS:2)
Block(5,27,-4,STAINED_GLASS:2)
Block(-1,27,-3,STAINED_GLASS:15)
Block(0,27,-3,STAINED_GLASS:14)
Block(1,27,-3,SEA_LANTERN:0)
Block(2,27,-3,STAINED_GLASS:9)
Block(3,27,-3,SEA_LANTERN:0)
Block(4,27,-3,STAINED_GLASS:9)
Block(5,27,-3,STAINED_GLASS:2)
Block(6,27,-3,STAINED_GLASS:2)
Block(0,27,-2,STAINED_GLASS:15)
Block(1,27,-2,STAINED_GLASS:15)
Block(2,27,-2,STAINED_GLASS:9)
Block(3,27,-2,STAINED_GLASS:15)
Block(4,27,-2,STAINED_GLASS:15)
Block(5,27,-2,STAINED_GLASS:15)
Block(6,27,-2,STAINED_GLASS:15)
Block(1,27,-1,STAINED_GLASS:15)
Block(2,27,-1,STAINED_GLASS:15)
Block(3,27,-1,STAINED_GLASS:15)
Block(4,27,-1,STAINED_GLASS:9)
Block(5,27,-1,STAINED_GLASS:15)
Block(6,27,-1,STAINED_GLASS:15)
Block(2,27,0,STAINED_GLASS:15)
Block(3,27,0,STAINED_GLASS:15)
Block(4,27,0,STAINED_GLASS:15)
Block(5,27,0,STAINED_GLASS:15)
Block(4,27,1,STAINED_GLASS:15)
Block(-3,28,-7,STAINED_GLASS:15)
Block(-2,28,-7,STAINED_GLASS:15)
Block(-1,28,-7,STAINED_GLASS:15)
Block(0,28,-7,STAINED_GLASS:14)
Block(1,28,-7,STAINED_GLASS:9)
Block(2,28,-7,STAINED_GLASS:9)
Block(3,28,-7,STAINED_GLASS:9)
Block(4,28,-7,STAINED_GLASS:15)
Block(-2,28,-6,STAINED_GLASS:15)
Block(-1,28,-6,STAINED_GLASS:15)
Block(0,28,-6,STAINED_GLASS:14)
Block(1,28,-6,SEA_LANTERN:0)
Block(2,28,-6,SEA_LANTERN:0)
Block(3,28,-6,SEA_LANTERN:0)
Block(4,28,-6,STAINED_GLASS:15)
Block(-1,28,-5,STAINED_GLASS:15)
Block(0,28,-5,STAINED_GLASS:14)
Block(1,28,-5,SEA_LANTERN:0)
Block(2,28,-5,SEA_LANTERN:0)
Block(3,28,-5,STAINED_GLASS:9)
Block(4,28,-5,STAINED_GLASS:15)
Block(5,28,-5,STAINED_GLASS:2)
Block(-1,28,-4,STAINED_GLASS:14)
Block(0,28,-4,SEA_LANTERN:0)
Block(1,28,-4,STAINED_GLASS:9)
Block(2,28,-4,SEA_LANTERN:0)
Block(3,28,-4,STAINED_GLASS:2)
Block(4,28,-4,STAINED_GLASS:2)
Block(5,28,-4,STAINED_GLASS:2)
Block(-1,28,-3,STAINED_GLASS:15)
Block(0,28,-3,STAINED_GLASS:15)
Block(1,28,-3,STAINED_GLASS:9)
Block(2,28,-3,STAINED_GLASS:2)
Block(3,28,-3,STAINED_GLASS:9)
Block(4,28,-3,STAINED_GLASS:2)
Block(5,28,-3,STAINED_GLASS:2)
Block(0,28,-2,STAINED_GLASS:15)
Block(1,28,-2,STAINED_GLASS:15)
Block(2,28,-2,STAINED_GLASS:15)
Block(3,28,-2,STAINED_GLASS:2)
Block(4,28,-2,STAINED_GLASS:2)
Block(5,28,-2,STAINED_GLASS:15)
Block(1,28,-1,STAINED_GLASS:15)
Block(2,28,-1,STAINED_GLASS:15)
Block(3,28,-1,STAINED_GLASS:15)
Block(4,28,-1,STAINED_GLASS:15)
Block(-3,29,-7,STAINED_GLASS:15)
Block(-2,29,-7,STAINED_GLASS:15)
Block(-1,29,-7,STAINED_GLASS:15)
Block(0,29,-7,SEA_LANTERN:0)
Block(1,29,-7,STAINED_GLASS:9)
Block(2,29,-7,SEA_LANTERN:0)
Block(3,29,-7,STAINED_GLASS:9)
Block(4,29,-7,STAINED_GLASS:15)
Block(-2,29,-6,STAINED_GLASS:15)
Block(-1,29,-6,STAINED_GLASS:14)
Block(0,29,-6,STAINED_GLASS:9)
Block(1,29,-6,SEA_LANTERN:0)
Block(2,29,-6,SEA_LANTERN:0)
Block(3,29,-6,STAINED_GLASS:9)
Block(4,29,-6,STAINED_GLASS:15)
Block(-1,29,-5,STAINED_GLASS:15)
Block(0,29,-5,SEA_LANTERN:0)
Block(1,29,-5,SEA_LANTERN:0)
Block(2,29,-5,SEA_LANTERN:0)
Block(3,29,-5,STAINED_GLASS:9)
Block(4,29,-5,STAINED_GLASS:15)
Block(5,29,-5,STAINED_GLASS:15)
Block(-1,29,-4,STAINED_GLASS:9)
Block(0,29,-4,STAINED_GLASS:9)
Block(1,29,-4,STAINED_GLASS:9)
Block(2,29,-4,STAINED_GLASS:9)
Block(3,29,-4,STAINED_GLASS:2)
Block(4,29,-4,STAINED_GLASS:2)
Block(5,29,-4,STAINED_GLASS:2)
Block(-1,29,-3,STAINED_GLASS:15)
Block(0,29,-3,STAINED_GLASS:15)
Block(1,29,-3,STAINED_GLASS:15)
Block(2,29,-3,STAINED_GLASS:2)
Block(3,29,-3,STAINED_GLASS:2)
Block(4,29,-3,STAINED_GLASS:2)
Block(5,29,-3,STAINED_GLASS:2)
Block(0,29,-2,STAINED_GLASS:15)
Block(1,29,-2,STAINED_GLASS:15)
Block(2,29,-2,STAINED_GLASS:2)
Block(3,29,-2,STAINED_GLASS:2)
Block(4,29,-2,STAINED_GLASS:2)
Block(1,29,-1,STAINED_GLASS:15)
Block(2,29,-1,STAINED_GLASS:15)
Block(-3,30,-7,STAINED_GLASS:15)
Block(-2,30,-7,STAINED_GLASS:15)
Block(-1,30,-7,STAINED_GLASS:14)
Block(0,30,-7,SEA_LANTERN:0)
Block(1,30,-7,SEA_LANTERN:0)
Block(2,30,-7,STAINED_GLASS:9)
Block(3,30,-7,STAINED_GLASS:15)
Block(4,30,-7,STAINED_GLASS:15)
Block(-2,30,-6,STAINED_GLASS:15)
Block(-1,30,-6,SEA_LANTERN:0)
Block(0,30,-6,SEA_LANTERN:0)
Block(1,30,-6,SEA_LANTERN:0)
Block(2,30,-6,STAINED_GLASS:9)
Block(3,30,-6,STAINED_GLASS:15)
Block(4,30,-6,STAINED_GLASS:15)
Block(-1,30,-5,STAINED_GLASS:9)
Block(0,30,-5,STAINED_GLASS:9)
Block(1,30,-5,STAINED_GLASS:9)
Block(2,30,-5,STAINED_GLASS:9)
Block(3,30,-5,STAINED_GLASS:2)
Block(4,30,-5,STAINED_GLASS:15)
Block(5,30,-5,STAINED_GLASS:15)
Block(-1,30,-4,STAINED_GLASS:15)
Block(0,30,-4,STAINED_GLASS:15)
Block(1,30,-4,STAINED_GLASS:2)
Block(2,30,-4,STAINED_GLASS:2)
Block(3,30,-4,STAINED_GLASS:2)
Block(4,30,-4,STAINED_GLASS:2)
Block(-1,30,-3,STAINED_GLASS:15)
Block(0,30,-3,STAINED_GLASS:15)
Block(1,30,-3,STAINED_GLASS:15)
Block(2,30,-3,STAINED_GLASS:2)
Block(0,30,-2,STAINED_GLASS:15)
Block(1,30,-2,STAINED_GLASS:15)
Block(-3,31,-7,STAINED_GLASS:15)
Block(-2,31,-7,STAINED_GLASS:9)
Block(-1,31,-7,SEA_LANTERN:0)
Block(0,31,-7,SEA_LANTERN:0)
Block(1,31,-7,STAINED_GLASS:9)
Block(2,31,-7,STAINED_GLASS:9)
Block(3,31,-7,STAINED_GLASS:15)
Block(4,31,-7,STAINED_GLASS:15)
Block(-2,31,-6,STAINED_GLASS:15)
Block(-1,31,-6,SEA_LANTERN:0)
Block(0,31,-6,STAINED_GLASS:9)
Block(1,31,-6,SEA_LANTERN:0)
Block(2,31,-6,STAINED_GLASS:15)
Block(3,31,-6,STAINED_GLASS:15)
Block(4,31,-6,STAINED_GLASS:15)
Block(-1,31,-5,STAINED_GLASS:15)
Block(0,31,-5,STAINED_GLASS:9)
Block(1,31,-5,STAINED_GLASS:15)
Block(2,31,-5,STAINED_GLASS:9)
Block(3,31,-5,STAINED_GLASS:2)
Block(4,31,-5,STAINED_GLASS:15)
Block(-1,31,-4,STAINED_GLASS:15)
Block(0,31,-4,STAINED_GLASS:2)
Block(1,31,-4,STAINED_GLASS:2)
Block(2,31,-4,STAINED_GLASS:2)
Block(-1,31,-3,STAINED_GLASS:15)
Block(0,31,-3,STAINED_GLASS:15)
Block(1,31,-3,STAINED_GLASS:2)
Block(-3,32,-7,STAINED_GLASS:15)
Block(-2,32,-7,STAINED_GLASS:9)
Block(-1,32,-7,SEA_LANTERN:0)
Block(0,32,-7,SEA_LANTERN:0)
Block(1,32,-7,STAINED_GLASS:9)
Block(2,32,-7,STAINED_GLASS:15)
Block(3,32,-7,STAINED_GLASS:15)
Block(4,32,-7,STAINED_GLASS:15)
Block(-2,32,-6,STAINED_GLASS:15)
Block(-1,32,-6,STAINED_GLASS:9)
Block(0,32,-6,STAINED_GLASS:9)
Block(1,32,-6,STAINED_GLASS:9)
Block(2,32,-6,STAINED_GLASS:15)
Block(3,32,-6,STAINED_GLASS:15)
Block(4,32,-6,STAINED_GLASS:15)
Block(-1,32,-5,STAINED_GLASS:2)
Block(0,32,-5,STAINED_GLASS:2)
Block(1,32,-5,STAINED_GLASS:2)
Block(2,32,-5,STAINED_GLASS:2)
Block(3,32,-5,STAINED_GLASS:2)
Block(4,32,-5,STAINED_GLASS:15)
Block(-1,32,-4,STAINED_GLASS:2)
Block(0,32,-4,STAINED_GLASS:2)
Block(1,32,-4,STAINED_GLASS:2)
Block(-1,32,-3,STAINED_GLASS:2)
Block(0,32,-3,STAINED_GLASS:2)
Block(-3,33,-7,STAINED_GLASS:2)
Block(-2,33,-7,STAINED_GLASS:2)
Block(-1,33,-7,STAINED_GLASS:9)
Block(0,33,-7,STAINED_GLASS:9)
Block(1,33,-7,STAINED_GLASS:15)
Block(2,33,-7,STAINED_GLASS:15)
Block(3,33,-7,STAINED_GLASS:15)
Block(-2,33,-6,STAINED_GLASS:2)
Block(-1,33,-6,STAINED_GLASS:15)
Block(0,33,-6,STAINED_GLASS:15)
Block(1,33,-6,STAINED_GLASS:15)
Block(2,33,-6,STAINED_GLASS:15)
Block(-1,33,-5,STAINED_GLASS:2)
Block(0,33,-5,STAINED_GLASS:2)
Block(1,33,-5,STAINED_GLASS:2)
Block(-1,33,-4,STAINED_GLASS:2)
Block(-3,34,-7,STAINED_GLASS:2)
Block(-2,34,-7,STAINED_GLASS:2)
Block(-1,34,-7,STAINED_GLASS:15)
Block(0,34,-7,STAINED_GLASS:9)
Block(1,34,-7,STAINED_GLASS:15)
Block(2,34,-7,STAINED_GLASS:15)
Block(-2,34,-6,STAINED_GLASS:2)
Block(-1,34,-6,STAINED_GLASS:2)
Block(0,34,-6,STAINED_GLASS:15)
Block(1,34,-6,STAINED_GLASS:15)
Block(-1,34,-5,STAINED_GLASS:2)
Block(0,34,-5,STAINED_GLASS:2)
Block(-3,35,-7,STAINED_GLASS:2)
Block(-2,35,-7,STAINED_GLASS:2)
Block(-1,35,-7,STAINED_GLASS:15)
Block(0,35,-7,STAINED_GLASS:15)
Block(-1,35,-6,STAINED_GLASS:15)
Block(-1,36,-7,STAINED_GLASS:15)
Branch(0,0,-16,spike-IL-28_00-00,NORTH,100)
