#######################################################################
# +-----------------------------------------------------------------+ #
# |                            BO3 object                           | #
# +-----------------------------------------------------------------+ #
#######################################################################

# This is the config file of a custom object.
# If you add this object correctly to your BiomeConfigs, it will spawn in the world.

# This is the creator of this BO3 object
Author: BO3 BulkEdit (by LanToaster)

# A short description of this BO3 object
Description: This Object was Created with BO3_BulkEdit

# The BO3 version, don't change this! It can be used by external applications to do a version check.
Version: 3

# The settings mode, WriteAll, WriteWithoutComments or WriteDisable. See WorldConfig.
SettingsMode: WriteDisable


#######################################################################
# +-----------------------------------------------------------------+ #
# |                          Main settings                          | #
# +-----------------------------------------------------------------+ #
#######################################################################

# This needs to be set to true to spawn the object in the Tree and Sapling resources.
Tree: false

# The frequency of the BO3 from 1 to 200. Tries this many times to spawn this BO3 when using the CustomObject(...) resource.

Frequency: 1

# The rarity of the BO3 from 0 to 100. Each spawn attempt has rarity% chance to succeed when using the CustomObject(...) resource.

Rarity: 100.0

# If you set this to true, the BO3 will be placed with a random rotation.
RotateRandomly: false

# The spawn height of the BO3 - randomY, highestBlock or highestSolidBlock.
SpawnHeight: highestBlock

# The height limits for the BO3.
MinHeight: 0

MaxHeight: 256

# Objects can have other objects attacthed to it: branches. Branches can also
# have branches attached to it, which can also have branches, etc. This is the
# maximum branch depth for this objects.
MaxBranchDepth: 10

# When spawned with the UseWorld keyword, this BO3 should NOT spawn in the following biomes.
# If you writer.write the BO3 name directly in the BiomeConfigs, this will be ignored.
ExcludedBiomes: All


#######################################################################
# +-----------------------------------------------------------------+ #
# |                      Source block settings                      | #
# +-----------------------------------------------------------------+ #
#######################################################################

# The block(s) the BO3 should spawn in.
SourceBlocks: AIR

# The maximum percentage of the BO3 that can be outside the SourceBlock.
# The BO3 won't be placed on a location with more blocks outside the SourceBlock than this percentage.
MaxPercentageOutsideSourceBlock: 100

# What to do when a block is about to be placed outside the SourceBlock? (dontPlace, placeAnyway)
OutsideSourceBlock: placeAnyway


#######################################################################
# +-----------------------------------------------------------------+ #
# |                              Blocks                             | #
# +-----------------------------------------------------------------+ #
#######################################################################

# All the blocks used in the BO3 are listed here. Possible blocks:
# Block(x,y,z,id[.data][,nbtfile.nbt)
# RandomBlock(x,y,z,id[:data][,nbtfile.nbt],chance[,id[:data][,nbtfile.nbt],chance[,...]])
# So RandomBlock(0,0,0,CHEST,chest.nbt,50,CHEST,anotherchest.nbt,100) will spawn a chest at
# the BO3 origin, and give it a 50% chance to have the contents of chest.nbt, or, if that
# fails, a 100% percent chance to have the contents of anotherchest.nbt.
Block(-3,10,7,STAINED_GLASS:2)
Block(-2,10,7,STAINED_GLASS:15)
Block(-1,10,7,STAINED_GLASS:15)
Block(0,10,7,STAINED_GLASS:15)
Block(1,10,7,STAINED_GLASS:15)
Block(-4,10,8,STAINED_GLASS:2)
Block(-3,10,8,STAINED_GLASS:2)
Block(-2,10,8,STAINED_GLASS:15)
Block(-1,10,8,STAINED_GLASS:15)
Block(0,10,8,STAINED_GLASS:15)
Block(1,10,8,STAINED_GLASS:15)
Block(-1,11,4,STAINED_GLASS:15)
Block(0,11,4,STAINED_GLASS:15)
Block(-4,11,5,STAINED_GLASS:2)
Block(-3,11,5,STAINED_GLASS:2)
Block(-2,11,5,STAINED_GLASS:15)
Block(-1,11,5,STAINED_GLASS:15)
Block(0,11,5,STAINED_GLASS:15)
Block(1,11,5,STAINED_GLASS:15)
Block(-4,11,6,STAINED_GLASS:2)
Block(-3,11,6,STAINED_GLASS:15)
Block(-2,11,6,STAINED_GLASS:15)
Block(-1,11,6,STAINED_GLASS:15)
Block(0,11,6,STAINED_GLASS:15)
Block(1,11,6,STAINED_GLASS:10)
Block(-5,11,7,STAINED_GLASS:2)
Block(-4,11,7,STAINED_GLASS:2)
Block(-3,11,7,STAINED_GLASS:2)
Block(-2,11,7,STAINED_GLASS:2)
Block(-1,11,7,STAINED_GLASS:15)
Block(0,11,7,STAINED_GLASS:15)
Block(1,11,7,STAINED_GLASS:11)
Block(-4,11,8,STAINED_GLASS:2)
Block(-3,11,8,STAINED_GLASS:2)
Block(-2,11,8,STAINED_GLASS:2)
Block(-1,11,8,STAINED_GLASS:2)
Block(0,11,8,STAINED_GLASS:11)
Block(1,11,8,STAINED_GLASS:10)
Block(-2,12,2,STAINED_GLASS:15)
Block(-4,12,3,STAINED_GLASS:2)
Block(-3,12,3,STAINED_GLASS:2)
Block(-2,12,3,STAINED_GLASS:15)
Block(-1,12,3,STAINED_GLASS:15)
Block(0,12,3,STAINED_GLASS:10)
Block(-5,12,4,STAINED_GLASS:2)
Block(-4,12,4,STAINED_GLASS:2)
Block(-3,12,4,STAINED_GLASS:2)
Block(-2,12,4,STAINED_GLASS:15)
Block(-1,12,4,STAINED_GLASS:15)
Block(0,12,4,STAINED_GLASS:10)
Block(1,12,4,STAINED_GLASS:10)
Block(-4,12,5,STAINED_GLASS:2)
Block(-3,12,5,STAINED_GLASS:2)
Block(-2,12,5,STAINED_GLASS:2)
Block(-1,12,5,STAINED_GLASS:15)
Block(0,12,5,STAINED_GLASS:15)
Block(1,12,5,STAINED_GLASS:10)
Block(-4,12,6,STAINED_GLASS:2)
Block(-3,12,6,STAINED_GLASS:15)
Block(-2,12,6,STAINED_GLASS:15)
Block(-1,12,6,STAINED_GLASS:15)
Block(0,12,6,STAINED_GLASS:10)
Block(1,12,6,STAINED_GLASS:10)
Block(-5,12,7,STAINED_GLASS:2)
Block(-4,12,7,STAINED_GLASS:2)
Block(-3,12,7,STAINED_GLASS:2)
Block(-2,12,7,STAINED_GLASS:15)
Block(-1,12,7,STAINED_GLASS:2)
Block(0,12,7,STAINED_GLASS:2)
Block(1,12,7,STAINED_GLASS:10)
Block(-4,12,8,STAINED_GLASS:2)
Block(-3,12,8,STAINED_GLASS:2)
Block(-2,12,8,STAINED_GLASS:15)
Block(-1,12,8,STAINED_GLASS:15)
Block(0,12,8,STAINED_GLASS:2)
Block(1,12,8,STAINED_GLASS:10)
Block(-3,13,0,STAINED_GLASS:2)
Block(0,13,0,STAINED_GLASS:15)
Block(-5,13,1,STAINED_GLASS:2)
Block(-4,13,1,STAINED_GLASS:2)
Block(-3,13,1,STAINED_GLASS:2)
Block(-2,13,1,STAINED_GLASS:2)
Block(-1,13,1,STAINED_GLASS:15)
Block(0,13,1,STAINED_GLASS:15)
Block(1,13,1,STAINED_GLASS:15)
Block(-4,13,2,STAINED_GLASS:2)
Block(-3,13,2,STAINED_GLASS:2)
Block(-2,13,2,STAINED_GLASS:2)
Block(-1,13,2,STAINED_GLASS:2)
Block(0,13,2,STAINED_GLASS:15)
Block(1,13,2,STAINED_GLASS:10)
Block(-5,13,3,STAINED_GLASS:2)
Block(-4,13,3,STAINED_GLASS:2)
Block(-3,13,3,STAINED_GLASS:2)
Block(-2,13,3,STAINED_GLASS:2)
Block(-1,13,3,STAINED_GLASS:15)
Block(0,13,3,STAINED_GLASS:10)
Block(-5,13,4,STAINED_GLASS:2)
Block(-4,13,4,STAINED_GLASS:2)
Block(-3,13,4,STAINED_GLASS:2)
Block(-2,13,4,STAINED_GLASS:2)
Block(-1,13,4,STAINED_GLASS:2)
Block(0,13,4,STAINED_GLASS:10)
Block(1,13,4,STAINED_GLASS:10)
Block(-4,13,5,STAINED_GLASS:2)
Block(-3,13,5,STAINED_GLASS:2)
Block(-2,13,5,STAINED_GLASS:15)
Block(-1,13,5,STAINED_GLASS:2)
Block(0,13,5,STAINED_GLASS:2)
Block(1,13,5,STAINED_GLASS:10)
Block(-4,13,6,STAINED_GLASS:2)
Block(-3,13,6,STAINED_GLASS:2)
Block(-2,13,6,STAINED_GLASS:2)
Block(-1,13,6,STAINED_GLASS:2)
Block(0,13,6,STAINED_GLASS:10)
Block(1,13,6,STAINED_GLASS:10)
Block(-5,13,7,STAINED_GLASS:2)
Block(-4,13,7,STAINED_GLASS:2)
Block(-3,13,7,STAINED_GLASS:2)
Block(-2,13,7,STAINED_GLASS:15)
Block(-1,13,7,SEA_LANTERN:0)
Block(0,13,7,STAINED_GLASS:2)
Block(1,13,7,STAINED_GLASS:2)
Block(-4,13,8,STAINED_GLASS:2)
Block(-3,13,8,STAINED_GLASS:15)
Block(-2,13,8,SEA_LANTERN:0)
Block(-1,13,8,SEA_LANTERN:0)
Block(0,13,8,STAINED_GLASS:15)
Block(1,13,8,STAINED_GLASS:10)
Block(-4,14,-2,STAINED_GLASS:2)
Block(-2,14,-2,STAINED_GLASS:2)
Block(-1,14,-2,STAINED_GLASS:2)
Block(-4,14,-1,STAINED_GLASS:2)
Block(-3,14,-1,STAINED_GLASS:2)
Block(-2,14,-1,STAINED_GLASS:2)
Block(-1,14,-1,STAINED_GLASS:2)
Block(0,14,-1,STAINED_GLASS:15)
Block(-5,14,0,STAINED_GLASS:2)
Block(-4,14,0,STAINED_GLASS:2)
Block(-3,14,0,STAINED_GLASS:2)
Block(-2,14,0,STAINED_GLASS:2)
Block(-1,14,0,STAINED_GLASS:2)
Block(0,14,0,STAINED_GLASS:15)
Block(-5,14,1,STAINED_GLASS:2)
Block(-4,14,1,STAINED_GLASS:2)
Block(-3,14,1,STAINED_GLASS:2)
Block(-2,14,1,STAINED_GLASS:2)
Block(-1,14,1,STAINED_GLASS:15)
Block(0,14,1,STAINED_GLASS:15)
Block(1,14,1,STAINED_GLASS:15)
Block(-4,14,2,STAINED_GLASS:2)
Block(-3,14,2,STAINED_GLASS:2)
Block(-2,14,2,STAINED_GLASS:15)
Block(-1,14,2,STAINED_GLASS:15)
Block(0,14,2,STAINED_GLASS:15)
Block(1,14,2,STAINED_GLASS:10)
Block(-5,14,3,STAINED_GLASS:2)
Block(-4,14,3,STAINED_GLASS:2)
Block(-3,14,3,STAINED_GLASS:2)
Block(-2,14,3,STAINED_GLASS:15)
Block(-1,14,3,STAINED_GLASS:2)
Block(0,14,3,STAINED_GLASS:10)
Block(-5,14,4,STAINED_GLASS:11)
Block(-4,14,4,STAINED_GLASS:2)
Block(-3,14,4,STAINED_GLASS:10)
Block(-2,14,4,STAINED_GLASS:15)
Block(-1,14,4,STAINED_GLASS:2)
Block(0,14,4,STAINED_GLASS:10)
Block(1,14,4,STAINED_GLASS:10)
Block(-4,14,5,STAINED_GLASS:11)
Block(-3,14,5,STAINED_GLASS:15)
Block(-2,14,5,SEA_LANTERN:0)
Block(-1,14,5,STAINED_GLASS:2)
Block(0,14,5,STAINED_GLASS:15)
Block(1,14,5,STAINED_GLASS:10)
Block(-4,14,6,STAINED_GLASS:2)
Block(-3,14,6,SEA_LANTERN:0)
Block(-2,14,6,SEA_LANTERN:0)
Block(-1,14,6,SEA_LANTERN:0)
Block(0,14,6,STAINED_GLASS:2)
Block(1,14,6,STAINED_GLASS:10)
Block(-5,14,7,STAINED_GLASS:2)
Block(-4,14,7,STAINED_GLASS:2)
Block(-3,14,7,STAINED_GLASS:15)
Block(-2,14,7,SEA_LANTERN:0)
Block(-1,14,7,STAINED_GLASS:2)
Block(0,14,7,STAINED_GLASS:15)
Block(1,14,7,STAINED_GLASS:10)
Block(-4,14,8,STAINED_GLASS:11)
Block(-3,14,8,STAINED_GLASS:2)
Block(-2,14,8,SEA_LANTERN:0)
Block(-1,14,8,SEA_LANTERN:0)
Block(0,14,8,STAINED_GLASS:2)
Block(1,14,8,STAINED_GLASS:10)
Block(-5,15,-4,STAINED_GLASS:11)
Block(-3,15,-4,STAINED_GLASS:2)
Block(-2,15,-4,STAINED_GLASS:2)
Block(-1,15,-4,STAINED_GLASS:2)
Block(0,15,-4,STAINED_GLASS:2)
Block(-5,15,-3,STAINED_GLASS:11)
Block(-4,15,-3,STAINED_GLASS:2)
Block(-3,15,-3,STAINED_GLASS:2)
Block(-2,15,-3,STAINED_GLASS:2)
Block(-1,15,-3,STAINED_GLASS:2)
Block(0,15,-3,STAINED_GLASS:2)
Block(-5,15,-2,STAINED_GLASS:2)
Block(-4,15,-2,STAINED_GLASS:2)
Block(-3,15,-2,STAINED_GLASS:2)
Block(-2,15,-2,STAINED_GLASS:2)
Block(-1,15,-2,STAINED_GLASS:2)
Block(0,15,-2,STAINED_GLASS:15)
Block(1,15,-2,STAINED_GLASS:15)
Block(-5,15,-1,STAINED_GLASS:2)
Block(-4,15,-1,STAINED_GLASS:2)
Block(-3,15,-1,STAINED_GLASS:2)
Block(-2,15,-1,STAINED_GLASS:2)
Block(-1,15,-1,STAINED_GLASS:15)
Block(0,15,-1,STAINED_GLASS:15)
Block(-5,15,0,STAINED_GLASS:11)
Block(-4,15,0,STAINED_GLASS:2)
Block(-3,15,0,STAINED_GLASS:2)
Block(-2,15,0,STAINED_GLASS:2)
Block(-1,15,0,STAINED_GLASS:15)
Block(0,15,0,STAINED_GLASS:15)
Block(-5,15,1,STAINED_GLASS:2)
Block(-4,15,1,STAINED_GLASS:2)
Block(-3,15,1,STAINED_GLASS:2)
Block(-2,15,1,STAINED_GLASS:15)
Block(-1,15,1,STAINED_GLASS:2)
Block(0,15,1,STAINED_GLASS:11)
Block(1,15,1,STAINED_GLASS:15)
Block(-4,15,2,STAINED_GLASS:11)
Block(-3,15,2,STAINED_GLASS:2)
Block(-2,15,2,SEA_LANTERN:0)
Block(-1,15,2,STAINED_GLASS:2)
Block(0,15,2,STAINED_GLASS:11)
Block(1,15,2,STAINED_GLASS:11)
Block(-5,15,3,STAINED_GLASS:11)
Block(-4,15,3,STAINED_GLASS:10)
Block(-3,15,3,SEA_LANTERN:0)
Block(-2,15,3,SEA_LANTERN:0)
Block(-1,15,3,SEA_LANTERN:0)
Block(0,15,3,STAINED_GLASS:2)
Block(-5,15,4,STAINED_GLASS:11)
Block(-4,15,4,STAINED_GLASS:10)
Block(-3,15,4,STAINED_GLASS:15)
Block(-2,15,4,SEA_LANTERN:0)
Block(-1,15,4,SEA_LANTERN:0)
Block(0,15,4,STAINED_GLASS:2)
Block(1,15,4,STAINED_GLASS:10)
Block(-4,15,5,STAINED_GLASS:10)
Block(-3,15,5,STAINED_GLASS:10)
Block(-2,15,5,SEA_LANTERN:0)
Block(-1,15,5,SEA_LANTERN:0)
Block(0,15,5,STAINED_GLASS:2)
Block(1,15,5,STAINED_GLASS:11)
Block(-4,15,6,STAINED_GLASS:11)
Block(-3,15,6,STAINED_GLASS:2)
Block(-2,15,6,STAINED_GLASS:2)
Block(-1,15,6,STAINED_GLASS:2)
Block(0,15,6,STAINED_GLASS:11)
Block(1,15,6,STAINED_GLASS:10)
Block(-5,15,7,STAINED_GLASS:11)
Block(-4,15,7,STAINED_GLASS:11)
Block(-3,15,7,STAINED_GLASS:2)
Block(-2,15,7,STAINED_GLASS:15)
Block(-1,15,7,STAINED_GLASS:15)
Block(0,15,7,STAINED_GLASS:2)
Block(1,15,7,STAINED_GLASS:11)
Block(-4,15,8,STAINED_GLASS:11)
Block(-3,15,8,STAINED_GLASS:11)
Block(-2,15,8,STAINED_GLASS:2)
Block(-1,15,8,STAINED_GLASS:2)
Block(0,15,8,STAINED_GLASS:11)
Block(1,15,8,STAINED_GLASS:10)
Block(-4,16,-6,STAINED_GLASS:15)
Block(-3,16,-6,STAINED_GLASS:15)
Block(-2,16,-6,STAINED_GLASS:2)
Block(-1,16,-6,STAINED_GLASS:2)
Block(-5,16,-5,STAINED_GLASS:11)
Block(-4,16,-5,STAINED_GLASS:11)
Block(-3,16,-5,STAINED_GLASS:15)
Block(-2,16,-5,STAINED_GLASS:2)
Block(-1,16,-5,STAINED_GLASS:2)
Block(0,16,-5,STAINED_GLASS:2)
Block(-5,16,-4,STAINED_GLASS:11)
Block(-4,16,-4,STAINED_GLASS:11)
Block(-3,16,-4,STAINED_GLASS:2)
Block(-2,16,-4,STAINED_GLASS:2)
Block(-1,16,-4,STAINED_GLASS:2)
Block(0,16,-4,STAINED_GLASS:2)
Block(-5,16,-3,STAINED_GLASS:11)
Block(-4,16,-3,STAINED_GLASS:11)
Block(-3,16,-3,STAINED_GLASS:2)
Block(-2,16,-3,STAINED_GLASS:2)
Block(-1,16,-3,STAINED_GLASS:2)
Block(0,16,-3,STAINED_GLASS:2)
Block(-5,16,-2,STAINED_GLASS:11)
Block(-4,16,-2,STAINED_GLASS:2)
Block(-3,16,-2,STAINED_GLASS:11)
Block(-2,16,-2,STAINED_GLASS:15)
Block(-1,16,-2,STAINED_GLASS:2)
Block(0,16,-2,STAINED_GLASS:15)
Block(1,16,-2,STAINED_GLASS:15)
Block(-5,16,-1,STAINED_GLASS:11)
Block(-4,16,-1,STAINED_GLASS:11)
Block(-3,16,-1,STAINED_GLASS:2)
Block(-2,16,-1,STAINED_GLASS:2)
Block(-1,16,-1,STAINED_GLASS:2)
Block(0,16,-1,STAINED_GLASS:15)
Block(-5,16,0,STAINED_GLASS:11)
Block(-4,16,0,STAINED_GLASS:2)
Block(-3,16,0,STAINED_GLASS:2)
Block(-2,16,0,SEA_LANTERN:0)
Block(-1,16,0,STAINED_GLASS:2)
Block(0,16,0,STAINED_GLASS:11)
Block(-5,16,1,STAINED_GLASS:11)
Block(-4,16,1,STAINED_GLASS:15)
Block(-3,16,1,STAINED_GLASS:2)
Block(-2,16,1,SEA_LANTERN:0)
Block(-1,16,1,STAINED_GLASS:15)
Block(0,16,1,STAINED_GLASS:2)
Block(1,16,1,STAINED_GLASS:11)
Block(-4,16,2,STAINED_GLASS:10)
Block(-3,16,2,SEA_LANTERN:0)
Block(-2,16,2,SEA_LANTERN:0)
Block(-1,16,2,SEA_LANTERN:0)
Block(0,16,2,STAINED_GLASS:2)
Block(1,16,2,STAINED_GLASS:11)
Block(-5,16,3,STAINED_GLASS:11)
Block(-4,16,3,STAINED_GLASS:11)
Block(-3,16,3,STAINED_GLASS:2)
Block(-2,16,3,SEA_LANTERN:0)
Block(-1,16,3,STAINED_GLASS:2)
Block(0,16,3,STAINED_GLASS:11)
Block(-5,16,4,STAINED_GLASS:11)
Block(-4,16,4,STAINED_GLASS:11)
Block(-3,16,4,STAINED_GLASS:10)
Block(-2,16,4,STAINED_GLASS:15)
Block(-1,16,4,STAINED_GLASS:2)
Block(0,16,4,STAINED_GLASS:11)
Block(1,16,4,STAINED_GLASS:11)
Block(-4,16,5,STAINED_GLASS:11)
Block(-3,16,5,STAINED_GLASS:11)
Block(-2,16,5,STAINED_GLASS:2)
Block(-1,16,5,STAINED_GLASS:2)
Block(0,16,5,STAINED_GLASS:11)
Block(1,16,5,STAINED_GLASS:11)
Block(-4,16,6,STAINED_GLASS:11)
Block(-3,16,6,STAINED_GLASS:11)
Block(-2,16,6,STAINED_GLASS:11)
Block(-1,16,6,STAINED_GLASS:11)
Block(0,16,6,STAINED_GLASS:11)
Block(1,16,6,STAINED_GLASS:11)
Block(-5,16,7,STAINED_GLASS:11)
Block(-4,16,7,STAINED_GLASS:11)
Block(-3,16,7,STAINED_GLASS:11)
Block(-2,16,7,STAINED_GLASS:2)
Block(-1,16,7,STAINED_GLASS:15)
Block(0,16,7,STAINED_GLASS:11)
Block(1,16,7,STAINED_GLASS:11)
Block(-4,16,8,STAINED_GLASS:11)
Block(-3,16,8,STAINED_GLASS:11)
Block(-2,16,8,STAINED_GLASS:11)
Block(-1,16,8,STAINED_GLASS:11)
Block(0,16,8,STAINED_GLASS:15)
Block(1,16,8,STAINED_GLASS:15)
Block(-6,17,-7,STAINED_GLASS:11)
Block(-5,17,-7,STAINED_GLASS:11)
Block(-4,17,-7,STAINED_GLASS:11)
Block(-3,17,-7,STAINED_GLASS:15)
Block(-2,17,-7,STAINED_GLASS:15)
Block(-1,17,-7,STAINED_GLASS:2)
Block(0,17,-7,STAINED_GLASS:2)
Block(-5,17,-6,STAINED_GLASS:11)
Block(-4,17,-6,STAINED_GLASS:11)
Block(-3,17,-6,STAINED_GLASS:2)
Block(-2,17,-6,STAINED_GLASS:2)
Block(-1,17,-6,STAINED_GLASS:2)
Block(0,17,-6,STAINED_GLASS:2)
Block(-5,17,-5,STAINED_GLASS:11)
Block(-4,17,-5,STAINED_GLASS:11)
Block(-3,17,-5,STAINED_GLASS:15)
Block(-2,17,-5,STAINED_GLASS:2)
Block(-1,17,-5,STAINED_GLASS:2)
Block(0,17,-5,STAINED_GLASS:2)
Block(-5,17,-4,STAINED_GLASS:11)
Block(-4,17,-4,STAINED_GLASS:11)
Block(-3,17,-4,STAINED_GLASS:2)
Block(-2,17,-4,STAINED_GLASS:2)
Block(-1,17,-4,STAINED_GLASS:2)
Block(0,17,-4,STAINED_GLASS:2)
Block(-5,17,-3,STAINED_GLASS:11)
Block(-4,17,-3,STAINED_GLASS:2)
Block(-3,17,-3,STAINED_GLASS:15)
Block(-2,17,-3,STAINED_GLASS:15)
Block(-1,17,-3,STAINED_GLASS:2)
Block(0,17,-3,STAINED_GLASS:11)
Block(-5,17,-2,STAINED_GLASS:11)
Block(-4,17,-2,STAINED_GLASS:2)
Block(-3,17,-2,STAINED_GLASS:2)
Block(-2,17,-2,SEA_LANTERN:0)
Block(-1,17,-2,STAINED_GLASS:2)
Block(0,17,-2,STAINED_GLASS:11)
Block(1,17,-2,STAINED_GLASS:11)
Block(-5,17,-1,STAINED_GLASS:11)
Block(-4,17,-1,STAINED_GLASS:10)
Block(-3,17,-1,SEA_LANTERN:0)
Block(-2,17,-1,SEA_LANTERN:0)
Block(-1,17,-1,STAINED_GLASS:15)
Block(0,17,-1,STAINED_GLASS:2)
Block(-5,17,0,STAINED_GLASS:11)
Block(-4,17,0,STAINED_GLASS:15)
Block(-3,17,0,SEA_LANTERN:0)
Block(-2,17,0,SEA_LANTERN:0)
Block(-1,17,0,STAINED_GLASS:15)
Block(0,17,0,STAINED_GLASS:2)
Block(-5,17,1,STAINED_GLASS:11)
Block(-4,17,1,STAINED_GLASS:10)
Block(-3,17,1,SEA_LANTERN:0)
Block(-2,17,1,SEA_LANTERN:0)
Block(-1,17,1,STAINED_GLASS:2)
Block(0,17,1,STAINED_GLASS:11)
Block(1,17,1,STAINED_GLASS:11)
Block(-4,17,2,STAINED_GLASS:11)
Block(-3,17,2,STAINED_GLASS:2)
Block(-2,17,2,STAINED_GLASS:15)
Block(-1,17,2,STAINED_GLASS:2)
Block(0,17,2,STAINED_GLASS:11)
Block(1,17,2,STAINED_GLASS:11)
Block(-5,17,3,STAINED_GLASS:11)
Block(-4,17,3,STAINED_GLASS:11)
Block(-3,17,3,STAINED_GLASS:11)
Block(-2,17,3,STAINED_GLASS:15)
Block(-1,17,3,STAINED_GLASS:11)
Block(0,17,3,STAINED_GLASS:11)
Block(-5,17,4,STAINED_GLASS:11)
Block(-4,17,4,STAINED_GLASS:11)
Block(-3,17,4,STAINED_GLASS:11)
Block(-2,17,4,STAINED_GLASS:2)
Block(-1,17,4,STAINED_GLASS:11)
Block(0,17,4,STAINED_GLASS:11)
Block(1,17,4,STAINED_GLASS:11)
Block(-4,17,5,STAINED_GLASS:11)
Block(-3,17,5,STAINED_GLASS:11)
Block(-2,17,5,STAINED_GLASS:2)
Block(-1,17,5,STAINED_GLASS:11)
Block(0,17,5,STAINED_GLASS:11)
Block(1,17,5,STAINED_GLASS:11)
Block(-4,17,6,STAINED_GLASS:11)
Block(-3,17,6,STAINED_GLASS:11)
Block(-2,17,6,STAINED_GLASS:11)
Block(-1,17,6,STAINED_GLASS:11)
Block(0,17,6,STAINED_GLASS:11)
Block(1,17,6,STAINED_GLASS:11)
Block(-5,17,7,STAINED_GLASS:11)
Block(-4,17,7,STAINED_GLASS:11)
Block(-3,17,7,STAINED_GLASS:11)
Block(-2,17,7,STAINED_GLASS:11)
Block(-1,17,7,STAINED_GLASS:15)
Block(0,17,7,STAINED_GLASS:15)
Block(1,17,7,STAINED_GLASS:15)
Block(-4,17,8,STAINED_GLASS:11)
Block(-6,18,-7,STAINED_GLASS:11)
Block(-5,18,-7,STAINED_GLASS:11)
Block(-4,18,-7,STAINED_GLASS:11)
Block(-3,18,-7,STAINED_GLASS:2)
Block(-2,18,-7,STAINED_GLASS:15)
Block(-1,18,-7,STAINED_GLASS:2)
Block(0,18,-7,STAINED_GLASS:2)
Block(-5,18,-6,STAINED_GLASS:11)
Block(-4,18,-6,STAINED_GLASS:2)
Block(-3,18,-6,STAINED_GLASS:15)
Block(-2,18,-6,STAINED_GLASS:2)
Block(-1,18,-6,STAINED_GLASS:2)
Block(0,18,-6,STAINED_GLASS:2)
Block(-5,18,-5,STAINED_GLASS:11)
Block(-4,18,-5,STAINED_GLASS:2)
Block(-3,18,-5,STAINED_GLASS:2)
Block(-2,18,-5,STAINED_GLASS:2)
Block(-1,18,-5,STAINED_GLASS:2)
Block(0,18,-5,STAINED_GLASS:2)
Block(-5,18,-4,STAINED_GLASS:11)
Block(-4,18,-4,STAINED_GLASS:2)
Block(-3,18,-4,STAINED_GLASS:2)
Block(-2,18,-4,STAINED_GLASS:2)
Block(-1,18,-4,STAINED_GLASS:11)
Block(0,18,-4,STAINED_GLASS:11)
Block(-5,18,-3,STAINED_GLASS:11)
Block(-4,18,-3,STAINED_GLASS:15)
Block(-3,18,-3,SEA_LANTERN:0)
Block(-2,18,-3,SEA_LANTERN:0)
Block(-1,18,-3,STAINED_GLASS:15)
Block(0,18,-3,STAINED_GLASS:2)
Block(-5,18,-2,STAINED_GLASS:10)
Block(-4,18,-2,STAINED_GLASS:15)
Block(-3,18,-2,SEA_LANTERN:0)
Block(-2,18,-2,SEA_LANTERN:0)
Block(-1,18,-2,STAINED_GLASS:15)
Block(0,18,-2,STAINED_GLASS:11)
Block(1,18,-2,STAINED_GLASS:11)
Block(-5,18,-1,STAINED_GLASS:11)
Block(-4,18,-1,STAINED_GLASS:11)
Block(-3,18,-1,STAINED_GLASS:2)
Block(-2,18,-1,STAINED_GLASS:2)
Block(-1,18,-1,STAINED_GLASS:2)
Block(0,18,-1,STAINED_GLASS:11)
Block(-5,18,0,STAINED_GLASS:11)
Block(-4,18,0,STAINED_GLASS:10)
Block(-3,18,0,STAINED_GLASS:2)
Block(-2,18,0,STAINED_GLASS:15)
Block(-1,18,0,STAINED_GLASS:2)
Block(0,18,0,STAINED_GLASS:11)
Block(-5,18,1,STAINED_GLASS:11)
Block(-4,18,1,STAINED_GLASS:11)
Block(-3,18,1,STAINED_GLASS:2)
Block(-2,18,1,STAINED_GLASS:2)
Block(-1,18,1,STAINED_GLASS:11)
Block(0,18,1,STAINED_GLASS:11)
Block(1,18,1,STAINED_GLASS:11)
Block(-4,18,2,STAINED_GLASS:11)
Block(-3,18,2,STAINED_GLASS:11)
Block(-2,18,2,STAINED_GLASS:10)
Block(-1,18,2,STAINED_GLASS:11)
Block(0,18,2,STAINED_GLASS:11)
Block(1,18,2,STAINED_GLASS:11)
Block(-5,18,3,STAINED_GLASS:11)
Block(-4,18,3,STAINED_GLASS:11)
Block(-3,18,3,STAINED_GLASS:11)
Block(-2,18,3,STAINED_GLASS:10)
Block(-1,18,3,STAINED_GLASS:15)
Block(0,18,3,STAINED_GLASS:11)
Block(-5,18,4,STAINED_GLASS:11)
Block(-4,18,4,STAINED_GLASS:11)
Block(-3,18,4,STAINED_GLASS:11)
Block(-2,18,4,STAINED_GLASS:11)
Block(-1,18,4,STAINED_GLASS:11)
Block(0,18,4,STAINED_GLASS:11)
Block(1,18,4,STAINED_GLASS:11)
Block(-4,18,5,STAINED_GLASS:11)
Block(-3,18,5,STAINED_GLASS:11)
Block(-2,18,5,STAINED_GLASS:11)
Block(-1,18,5,STAINED_GLASS:11)
Block(0,18,5,STAINED_GLASS:15)
Block(-6,19,-7,STAINED_GLASS:11)
Block(-5,19,-7,STAINED_GLASS:11)
Block(-4,19,-7,STAINED_GLASS:2)
Block(-3,19,-7,STAINED_GLASS:15)
Block(-2,19,-7,STAINED_GLASS:2)
Block(-1,19,-7,STAINED_GLASS:2)
Block(0,19,-7,STAINED_GLASS:2)
Block(-5,19,-6,STAINED_GLASS:11)
Block(-4,19,-6,STAINED_GLASS:2)
Block(-3,19,-6,STAINED_GLASS:15)
Block(-2,19,-6,STAINED_GLASS:2)
Block(-1,19,-6,STAINED_GLASS:2)
Block(0,19,-6,STAINED_GLASS:2)
Block(-5,19,-5,STAINED_GLASS:2)
Block(-4,19,-5,STAINED_GLASS:15)
Block(-3,19,-5,SEA_LANTERN:0)
Block(-2,19,-5,SEA_LANTERN:0)
Block(-1,19,-5,STAINED_GLASS:15)
Block(0,19,-5,STAINED_GLASS:2)
Block(-5,19,-4,STAINED_GLASS:10)
Block(-4,19,-4,STAINED_GLASS:15)
Block(-3,19,-4,SEA_LANTERN:0)
Block(-2,19,-4,SEA_LANTERN:0)
Block(-1,19,-4,STAINED_GLASS:2)
Block(0,19,-4,STAINED_GLASS:2)
Block(-5,19,-3,STAINED_GLASS:11)
Block(-4,19,-3,STAINED_GLASS:10)
Block(-3,19,-3,SEA_LANTERN:0)
Block(-2,19,-3,SEA_LANTERN:0)
Block(-1,19,-3,STAINED_GLASS:2)
Block(0,19,-3,STAINED_GLASS:11)
Block(-5,19,-2,STAINED_GLASS:11)
Block(-4,19,-2,STAINED_GLASS:10)
Block(-3,19,-2,STAINED_GLASS:2)
Block(-2,19,-2,STAINED_GLASS:15)
Block(-1,19,-2,STAINED_GLASS:2)
Block(0,19,-2,STAINED_GLASS:11)
Block(1,19,-2,STAINED_GLASS:11)
Block(-5,19,-1,STAINED_GLASS:11)
Block(-4,19,-1,STAINED_GLASS:11)
Block(-3,19,-1,STAINED_GLASS:11)
Block(-2,19,-1,STAINED_GLASS:11)
Block(-1,19,-1,STAINED_GLASS:11)
Block(0,19,-1,STAINED_GLASS:11)
Block(-5,19,0,STAINED_GLASS:11)
Block(-4,19,0,STAINED_GLASS:11)
Block(-3,19,0,STAINED_GLASS:15)
Block(-2,19,0,STAINED_GLASS:2)
Block(-1,19,0,STAINED_GLASS:11)
Block(0,19,0,STAINED_GLASS:11)
Block(-5,19,1,STAINED_GLASS:11)
Block(-4,19,1,STAINED_GLASS:11)
Block(-3,19,1,STAINED_GLASS:15)
Block(-2,19,1,STAINED_GLASS:2)
Block(-1,19,1,STAINED_GLASS:11)
Block(0,19,1,STAINED_GLASS:11)
Block(1,19,1,STAINED_GLASS:11)
Block(-4,19,2,STAINED_GLASS:11)
Block(-3,19,2,STAINED_GLASS:11)
Block(-2,19,2,STAINED_GLASS:11)
Block(-1,19,2,STAINED_GLASS:11)
Block(0,19,2,STAINED_GLASS:11)
Block(1,19,2,STAINED_GLASS:11)
Block(-5,19,3,STAINED_GLASS:11)
Block(-4,19,3,STAINED_GLASS:11)
Block(-3,19,3,STAINED_GLASS:11)
Block(-2,19,3,STAINED_GLASS:11)
Block(-1,19,3,STAINED_GLASS:15)
Block(0,19,3,STAINED_GLASS:11)
Block(-4,19,4,STAINED_GLASS:11)
Block(-6,20,-7,STAINED_GLASS:11)
Block(-5,20,-7,STAINED_GLASS:10)
Block(-4,20,-7,STAINED_GLASS:15)
Block(-3,20,-7,STAINED_GLASS:15)
Block(-2,20,-7,SEA_LANTERN:0)
Block(-1,20,-7,STAINED_GLASS:2)
Block(0,20,-7,STAINED_GLASS:2)
Block(-5,20,-6,STAINED_GLASS:10)
Block(-4,20,-6,STAINED_GLASS:15)
Block(-3,20,-6,SEA_LANTERN:0)
Block(-2,20,-6,STAINED_GLASS:15)
Block(-1,20,-6,STAINED_GLASS:15)
Block(0,20,-6,STAINED_GLASS:2)
Block(-5,20,-5,STAINED_GLASS:11)
Block(-4,20,-5,STAINED_GLASS:10)
Block(-3,20,-5,STAINED_GLASS:2)
Block(-2,20,-5,STAINED_GLASS:2)
Block(-1,20,-5,STAINED_GLASS:2)
Block(0,20,-5,STAINED_GLASS:11)
Block(-5,20,-4,STAINED_GLASS:11)
Block(-4,20,-4,STAINED_GLASS:10)
Block(-3,20,-4,STAINED_GLASS:2)
Block(-2,20,-4,STAINED_GLASS:2)
Block(-1,20,-4,STAINED_GLASS:11)
Block(0,20,-4,STAINED_GLASS:11)
Block(-5,20,-3,STAINED_GLASS:11)
Block(-4,20,-3,STAINED_GLASS:11)
Block(-3,20,-3,STAINED_GLASS:2)
Block(-2,20,-3,STAINED_GLASS:2)
Block(-1,20,-3,STAINED_GLASS:11)
Block(0,20,-3,STAINED_GLASS:11)
Block(-5,20,-2,STAINED_GLASS:11)
Block(-4,20,-2,STAINED_GLASS:11)
Block(-3,20,-2,STAINED_GLASS:11)
Block(-2,20,-2,STAINED_GLASS:2)
Block(-1,20,-2,STAINED_GLASS:11)
Block(0,20,-2,STAINED_GLASS:11)
Block(1,20,-2,STAINED_GLASS:11)
Block(-5,20,-1,STAINED_GLASS:11)
Block(-4,20,-1,STAINED_GLASS:11)
Block(-3,20,-1,STAINED_GLASS:11)
Block(-2,20,-1,STAINED_GLASS:11)
Block(-1,20,-1,STAINED_GLASS:11)
Block(0,20,-1,STAINED_GLASS:11)
Block(-5,20,0,STAINED_GLASS:11)
Block(-4,20,0,STAINED_GLASS:11)
Block(-3,20,0,STAINED_GLASS:15)
Block(-2,20,0,STAINED_GLASS:15)
Block(-1,20,0,STAINED_GLASS:11)
Block(0,20,0,STAINED_GLASS:11)
Block(-4,20,1,STAINED_GLASS:11)
Block(-3,20,1,STAINED_GLASS:15)
Block(-2,20,1,STAINED_GLASS:15)
Block(-1,20,1,STAINED_GLASS:11)
Block(-6,21,-7,STAINED_GLASS:11)
Block(-5,21,-7,STAINED_GLASS:11)
Block(-4,21,-7,STAINED_GLASS:10)
Block(-3,21,-7,SEA_LANTERN:0)
Block(-2,21,-7,STAINED_GLASS:2)
Block(-1,21,-7,STAINED_GLASS:2)
Block(0,21,-7,STAINED_GLASS:2)
Block(-5,21,-6,STAINED_GLASS:11)
Block(-4,21,-6,STAINED_GLASS:10)
Block(-3,21,-6,STAINED_GLASS:15)
Block(-2,21,-6,STAINED_GLASS:2)
Block(-1,21,-6,STAINED_GLASS:2)
Block(0,21,-6,STAINED_GLASS:2)
Block(-5,21,-5,STAINED_GLASS:11)
Block(-4,21,-5,STAINED_GLASS:11)
Block(-3,21,-5,STAINED_GLASS:11)
Block(-2,21,-5,STAINED_GLASS:11)
Block(-1,21,-5,STAINED_GLASS:11)
Block(0,21,-5,STAINED_GLASS:11)
Block(-5,21,-4,STAINED_GLASS:11)
Block(-4,21,-4,STAINED_GLASS:11)
Block(-3,21,-4,STAINED_GLASS:11)
Block(-2,21,-4,STAINED_GLASS:11)
Block(-1,21,-4,STAINED_GLASS:11)
Block(0,21,-4,STAINED_GLASS:11)
Block(-5,21,-3,STAINED_GLASS:11)
Block(-4,21,-3,STAINED_GLASS:11)
Block(-3,21,-3,STAINED_GLASS:2)
Block(-2,21,-3,STAINED_GLASS:2)
Block(-1,21,-3,STAINED_GLASS:11)
Block(0,21,-3,STAINED_GLASS:11)
Block(-5,21,-2,STAINED_GLASS:11)
Block(-4,21,-2,STAINED_GLASS:11)
Block(-3,21,-2,STAINED_GLASS:11)
Block(-2,21,-2,STAINED_GLASS:15)
Block(-1,21,-2,STAINED_GLASS:11)
Block(0,21,-2,STAINED_GLASS:11)
Block(1,21,-2,STAINED_GLASS:11)
Block(-5,21,-1,STAINED_GLASS:11)
Block(-4,21,-1,STAINED_GLASS:11)
Block(-3,21,-1,STAINED_GLASS:11)
Block(-2,21,-1,STAINED_GLASS:15)
Block(0,21,-1,STAINED_GLASS:11)
Block(-6,22,-7,STAINED_GLASS:11)
Block(-5,22,-7,STAINED_GLASS:11)
Block(-4,22,-7,STAINED_GLASS:11)
Block(-3,22,-7,STAINED_GLASS:2)
Block(-2,22,-7,STAINED_GLASS:11)
Block(-1,22,-7,STAINED_GLASS:2)
Block(0,22,-7,STAINED_GLASS:2)
Block(-5,22,-6,STAINED_GLASS:11)
Block(-4,22,-6,STAINED_GLASS:11)
Block(-3,22,-6,STAINED_GLASS:2)
Block(-2,22,-6,STAINED_GLASS:11)
Block(-1,22,-6,STAINED_GLASS:11)
Block(0,22,-6,STAINED_GLASS:2)
Block(-5,22,-5,STAINED_GLASS:11)
Block(-4,22,-5,STAINED_GLASS:11)
Block(-3,22,-5,STAINED_GLASS:11)
Block(-2,22,-5,STAINED_GLASS:11)
Block(-1,22,-5,STAINED_GLASS:11)
Block(0,22,-5,STAINED_GLASS:11)
Block(-5,22,-4,STAINED_GLASS:11)
Block(-4,22,-4,STAINED_GLASS:11)
Block(-3,22,-4,STAINED_GLASS:11)
Block(-2,22,-4,STAINED_GLASS:15)
Block(-1,22,-4,STAINED_GLASS:11)
Block(0,22,-4,STAINED_GLASS:11)
Block(-4,22,-3,STAINED_GLASS:11)
Block(-3,22,-3,STAINED_GLASS:11)
Block(-2,22,-3,STAINED_GLASS:11)
Block(-1,22,-3,STAINED_GLASS:15)
Block(-6,23,-7,STAINED_GLASS:11)
Block(-5,23,-7,STAINED_GLASS:11)
Block(-4,23,-7,STAINED_GLASS:11)
Block(-3,23,-7,STAINED_GLASS:2)
Block(-2,23,-7,STAINED_GLASS:11)
Block(-1,23,-7,STAINED_GLASS:11)
Block(0,23,-7,STAINED_GLASS:2)
Block(-5,23,-6,STAINED_GLASS:11)
Block(-4,23,-6,STAINED_GLASS:11)
Block(-3,23,-6,STAINED_GLASS:11)
Block(-2,23,-6,STAINED_GLASS:11)
Block(-1,23,-6,STAINED_GLASS:11)
Block(0,23,-6,STAINED_GLASS:11)
Block(-5,23,-5,STAINED_GLASS:11)
Block(-3,23,-5,STAINED_GLASS:11)
Block(-2,23,-5,STAINED_GLASS:15)
Block(-4,24,-7,STAINED_GLASS:11)
Block(-3,24,-7,STAINED_GLASS:11)
Branch(0,0,-16,spike-IL-10_00-00,NORTH,100)
